{"_local_timestamp": "2026-01-25T23:34:11.718735+00:00", "data": [{"market": "0x6f688996e47f896351729088a8c2c0fcb7db6f40fd96eed42502e11c9962f744", "asset_id": "63575582870841942383427053084518597975654282758242000155173178759202148848429", "timestamp": "1769383933111", "hash": "630aa56eb046a9398d700f9efdc1bc32b1044f25", "bids": [{"price": "0.001", "size": "6678.99"}, {"price": "0.002", "size": "10770.55"}, {"price": "0.003", "size": "2166"}, {"price": "0.006", "size": "83"}, {"price": "0.01", "size": "180"}, {"price": "0.02", "size": "2000"}, {"price": "0.041", "size": "48"}, {"price": "0.05", "size": "360"}, {"price": "0.051", "size": "39"}, {"price": "0.052", "size": "10"}, {"price": "0.07", "size": "300"}, {"price": "0.1", "size": "860"}, {"price": "0.15", "size": "551.66"}, {"price": "0.151", "size": "40"}, {"price": "0.152", "size": "30"}, {"price": "0.2", "size": "534.99"}, {"price": "0.223", "size": "70"}, {"price": "0.25", "size": "262"}, {"price": "0.251", "size": "156"}, {"price": "0.27", "size": "50"}, {"price": "0.3", "size": "86.66"}, {"price": "0.35", "size": "68.57"}, {"price": "0.4", "size": "175"}, {"price": "0.523", "size": "267"}, {"price": "0.524", "size": "5"}, {"price": "0.723", "size": "152"}, {"price": "0.823", "size": "300"}, {"price": "0.923", "size": "359"}, {"price": "0.98", "size": "125"}, {"price": "0.99", "size": "300"}, {"price": "0.991", "size": "300"}, {"price": "0.992", "size": "206.53"}, {"price": "0.993", "size": "75"}], "asks": [], "event_type": "book", "last_trade_price": "0.001"}, {"market": "0xbb7afda76b33e28e6beca651afcf4ba2c96316330038b37d565311aec7aa80fd", "asset_id": "55048873344980893604077431803703373331531589597253065240792528177019001889497", "timestamp": "1769384043192", "hash": "100bda24c79d9521aeb0387574979dfa45f5c57a", "bids": [{"price": "0.001", "size": "5726.99"}, {"price": "0.002", "size": "314"}, {"price": "0.003", "size": "206.67"}, {"price": "0.004", "size": "200"}, {"price": "0.005", "size": "66.66"}, {"price": "0.006", "size": "5.45"}, {"price": "0.01", "size": "36.39"}, {"price": "0.011", "size": "24.33"}, {"price": "0.013", "size": "11.97"}, {"price": "0.021", "size": "6"}, {"price": "0.022", "size": "66.66"}, {"price": "0.03", "size": "99.99"}, {"price": "0.031", "size": "6"}, {"price": "0.032", "size": "93"}, {"price": "0.037", "size": "6"}, {"price": "0.041", "size": "66.66"}, {"price": "0.042", "size": "125.26"}], "asks": [{"price": "0.999", "size": "5271.99"}, {"price": "0.998", "size": "7.48"}, {"price": "0.997", "size": "1000"}, {"price": "0.996", "size": "4000"}, {"price": "0.995", "size": "16"}, {"price": "0.99", "size": "180"}, {"price": "0.98", "size": "2000"}, {"price": "0.979", "size": "5.11"}, {"price": "0.95", "size": "400"}, {"price": "0.94", "size": "33"}, {"price": "0.934", "size": "20"}, {"price": "0.933", "size": "7.85"}, {"price": "0.93", "size": "300"}, {"price": "0.9", "size": "860"}, {"price": "0.891", "size": "30"}, {"price": "0.89", "size": "60"}, {"price": "0.86", "size": "242.85"}, {"price": "0.859", "size": "575"}, {"price": "0.81", "size": "418.42"}, {"price": "0.809", "size": "6.63"}, {"price": "0.76", "size": "316.66"}, {"price": "0.759", "size": "8"}, {"price": "0.73", "size": "50"}, {"price": "0.71", "size": "89.65"}, {"price": "0.66", "size": "120.58"}, {"price": "0.62", "size": "52.63"}, {"price": "0.61", "size": "75"}, {"price": "0.5", "size": "560"}, {"price": "0.181", "size": "6.51"}, {"price": "0.18", "size": "2831.49"}, {"price": "0.179", "size": "268.43"}, {"price": "0.12", "size": "6.51"}, {"price": "0.068", "size": "50.8"}, {"price": "0.06", "size": "90.42"}, {"price": "0.059", "size": "33.91"}], "event_type": "book", "last_trade_price": "0.940"}, {"market": "0xd25ccd7ec063e97bcdfc4a5c425309786dee7d46cda598eeb056133ecc60a26b", "asset_id": "61363616775934825034538234334948775070821960948072963080826717391882343278521", "timestamp": "1769383932808", "hash": "0183b83eea1845f4628e93fb7b47ac25933842da", "bids": [], "asks": [{"price": "0.999", "size": "9678.99"}, {"price": "0.998", "size": "1250"}, {"price": "0.997", "size": "2166"}, {"price": "0.994", "size": "83"}, {"price": "0.99", "size": "180"}, {"price": "0.98", "size": "2000"}, {"price": "0.959", "size": "48"}, {"price": "0.95", "size": "360"}, {"price": "0.949", "size": "39"}, {"price": "0.948", "size": "10"}, {"price": "0.93", "size": "300"}, {"price": "0.9", "size": "860"}, {"price": "0.887", "size": "10"}, {"price": "0.85", "size": "551.66"}, {"price": "0.849", "size": "40"}, {"price": "0.848", "size": "30"}, {"price": "0.8", "size": "460"}, {"price": "0.777", "size": "70"}, {"price": "0.75", "size": "262"}, {"price": "0.73", "size": "50"}, {"price": "0.7", "size": "86.66"}, {"price": "0.65", "size": "68.57"}, {"price": "0.6", "size": "175"}, {"price": "0.5", "size": "778"}, {"price": "0.477", "size": "216"}, {"price": "0.476", "size": "5"}, {"price": "0.277", "size": "152"}, {"price": "0.177", "size": "300"}, {"price": "0.077", "size": "359"}, {"price": "0.01", "size": "500"}, {"price": "0.004", "size": "734.26"}], "event_type": "book", "last_trade_price": "0.001"}, {"market": "0xf4cbee770d93e6be7c0eeef5fd8d143bf7b6cd05462745a0847aab51b993d406", "asset_id": "75482995474170622849957659966226987317064035398856989789719351907123461611518", "timestamp": "1769383973263", "hash": "6fd3feb2fe65552ac7af85f2ab3ab5aa4d93f53d", "bids": [{"price": "0.001", "size": "6685.99"}, {"price": "0.002", "size": "11082.01"}, {"price": "0.003", "size": "2172.62"}, {"price": "0.006", "size": "83"}, {"price": "0.007", "size": "9.76"}, {"price": "0.01", "size": "180"}, {"price": "0.02", "size": "2000"}, {"price": "0.021", "size": "10.91"}, {"price": "0.041", "size": "48"}, {"price": "0.05", "size": "360"}, {"price": "0.051", "size": "39"}, {"price": "0.052", "size": "10"}, {"price": "0.07", "size": "300"}, {"price": "0.071", "size": "7.07"}, {"price": "0.1", "size": "860"}, {"price": "0.101", "size": "20"}, {"price": "0.15", "size": "551.66"}, {"price": "0.151", "size": "30"}, {"price": "0.152", "size": "40"}, {"price": "0.2", "size": "460"}, {"price": "0.201", "size": "99.99"}, {"price": "0.202", "size": "5.79"}, {"price": "0.223", "size": "69"}, {"price": "0.224", "size": "284"}, {"price": "0.25", "size": "112"}, {"price": "0.27", "size": "50"}, {"price": "0.3", "size": "86.66"}, {"price": "0.35", "size": "68.57"}, {"price": "0.4", "size": "175"}, {"price": "0.523", "size": "362"}, {"price": "0.524", "size": "100"}, {"price": "0.525", "size": "300"}, {"price": "0.526", "size": "205"}, {"price": "0.723", "size": "151"}, {"price": "0.823", "size": "299"}, {"price": "0.923", "size": "240"}, {"price": "0.924", "size": "70"}, {"price": "0.926", "size": "90"}, {"price": "0.927", "size": "100"}, {"price": "0.934", "size": "88"}, {"price": "0.941", "size": "80"}, {"price": "0.951", "size": "65"}, {"price": "0.953", "size": "190"}, {"price": "0.966", "size": "36.69"}, {"price": "0.977", "size": "80"}, {"price": "0.978", "size": "28.69"}, {"price": "0.979", "size": "10"}], "asks": [{"price": "0.999", "size": "8460"}, {"price": "0.996", "size": "144"}], "event_type": "book", "last_trade_price": "0.987"}, {"market": "0x6f688996e47f896351729088a8c2c0fcb7db6f40fd96eed42502e11c9962f744", "asset_id": "1479722737131399761673297933236140450313179902349075711821861456880367927838", "timestamp": "1769383933111", "hash": "9682689434b784e2e02a5f0d5957dd20198e9dd4", "bids": [], "asks": [{"price": "0.999", "size": "6678.99"}, {"price": "0.998", "size": "10770.55"}, {"price": "0.997", "size": "2166"}, {"price": "0.994", "size": "83"}, {"price": "0.99", "size": "180"}, {"price": "0.98", "size": "2000"}, {"price": "0.959", "size": "48"}, {"price": "0.95", "size": "360"}, {"price": "0.949", "size": "39"}, {"price": "0.948", "size": "10"}, {"price": "0.93", "size": "300"}, {"price": "0.9", "size": "860"}, {"price": "0.85", "size": "551.66"}, {"price": "0.849", "size": "40"}, {"price": "0.848", "size": "30"}, {"price": "0.8", "size": "534.99"}, {"price": "0.777", "size": "70"}, {"price": "0.75", "size": "262"}, {"price": "0.749", "size": "156"}, {"price": "0.73", "size": "50"}, {"price": "0.7", "size": "86.66"}, {"price": "0.65", "size": "68.57"}, {"price": "0.6", "size": "175"}, {"price": "0.477", "size": "267"}, {"price": "0.476", "size": "5"}, {"price": "0.277", "size": "152"}, {"price": "0.177", "size": "300"}, {"price": "0.077", "size": "359"}, {"price": "0.02", "size": "125"}, {"price": "0.01", "size": "300"}, {"price": "0.009", "size": "300"}, {"price": "0.008", "size": "206.53"}, {"price": "0.007", "size": "75"}], "event_type": "book", "last_trade_price": "0.001"}, {"market": "0xeaca7fad27f9e7602a07627a1dbb4b01352cd7ad99dd28b0ec09e26e6b12ccab", "asset_id": "76657535986059542453526409873946781453980750888541128603750398128471993423003", "timestamp": "1769383991808", "hash": "5b554da6db937154c28ac497040393ced6f62c6c", "bids": [{"price": "0.001", "size": "7348"}, {"price": "0.002", "size": "1500"}, {"price": "0.003", "size": "250"}, {"price": "0.005", "size": "8.89"}, {"price": "0.007", "size": "148"}, {"price": "0.008", "size": "30"}], "asks": [{"price": "0.999", "size": "6688.99"}, {"price": "0.998", "size": "1250"}, {"price": "0.997", "size": "1172.62"}, {"price": "0.994", "size": "83"}, {"price": "0.993", "size": "9.76"}, {"price": "0.99", "size": "4180"}, {"price": "0.989", "size": "3660"}, {"price": "0.98", "size": "2000"}, {"price": "0.979", "size": "10.79"}, {"price": "0.959", "size": "48"}, {"price": "0.95", "size": "360"}, {"price": "0.949", "size": "39"}, {"price": "0.948", "size": "10"}, {"price": "0.93", "size": "300"}, {"price": "0.929", "size": "7.12"}, {"price": "0.9", "size": "860"}, {"price": "0.898", "size": "30"}, {"price": "0.897", "size": "20"}, {"price": "0.85", "size": "551.66"}, {"price": "0.849", "size": "75"}, {"price": "0.847", "size": "40"}, {"price": "0.8", "size": "460"}, {"price": "0.799", "size": "99.99"}, {"price": "0.798", "size": "5.79"}, {"price": "0.777", "size": "70"}, {"price": "0.75", "size": "262"}, {"price": "0.749", "size": "156"}, {"price": "0.73", "size": "50"}, {"price": "0.7", "size": "86.66"}, {"price": "0.65", "size": "68.57"}, {"price": "0.6", "size": "175"}, {"price": "0.599", "size": "5"}, {"price": "0.477", "size": "123"}, {"price": "0.277", "size": "152"}, {"price": "0.177", "size": "300"}, {"price": "0.173", "size": "300"}, {"price": "0.172", "size": "300"}, {"price": "0.171", "size": "200"}, {"price": "0.17", "size": "100"}, {"price": "0.077", "size": "273"}, {"price": "0.076", "size": "200"}, {"price": "0.074", "size": "180"}, {"price": "0.029", "size": "28"}, {"price": "0.028", "size": "80"}, {"price": "0.026", "size": "87.99"}, {"price": "0.024", "size": "120"}, {"price": "0.023", "size": "201.32"}, {"price": "0.022", "size": "30"}, {"price": "0.021", "size": "50"}], "event_type": "book", "last_trade_price": "0.994"}, {"market": "0x9bcfe6e8f19ff9f8bf329df320eb4d99e5617cbf86322aea27e87243241ddfa9", "asset_id": "78930020687216610592275737264551684416741191072026547466466591111794825522715", "timestamp": "1769383932961", "hash": "4df5b4c76c9f03395dd7e1a7f1f53a180be18bf1", "bids": [{"price": "0.001", "size": "6678.99"}, {"price": "0.002", "size": "1250"}, {"price": "0.003", "size": "1166"}, {"price": "0.004", "size": "7359"}, {"price": "0.006", "size": "83"}, {"price": "0.01", "size": "180"}, {"price": "0.02", "size": "2000"}, {"price": "0.041", "size": "48"}, {"price": "0.05", "size": "360"}, {"price": "0.051", "size": "39"}, {"price": "0.052", "size": "10"}, {"price": "0.07", "size": "300"}, {"price": "0.1", "size": "860"}, {"price": "0.15", "size": "551.66"}, {"price": "0.151", "size": "213"}, {"price": "0.152", "size": "40"}, {"price": "0.153", "size": "30"}, {"price": "0.2", "size": "460"}, {"price": "0.223", "size": "70"}, {"price": "0.25", "size": "262"}, {"price": "0.27", "size": "50"}, {"price": "0.3", "size": "86.66"}, {"price": "0.35", "size": "68.57"}, {"price": "0.4", "size": "175"}, {"price": "0.401", "size": "5"}, {"price": "0.523", "size": "126"}, {"price": "0.723", "size": "152"}, {"price": "0.823", "size": "300"}, {"price": "0.923", "size": "359"}, {"price": "0.99", "size": "400"}, {"price": "0.995", "size": "140"}, {"price": "0.996", "size": "1222.5"}], "asks": [], "event_type": "book", "last_trade_price": "0.004"}, {"market": "0x5bb310c9ec29b1d762c5805810ca1bb864d2352a8f76812a3dca82a6a138ccf7", "asset_id": "62123450528053709565950826485547710951386868966516386574151628295203483034330", "timestamp": "1769383934022", "hash": "75c842a0af4140c9d6a5f89fcde185631c825483", "bids": [{"price": "0.001", "size": "6322.99"}, {"price": "0.002", "size": "439.16"}], "asks": [{"price": "0.999", "size": "6686.2"}, {"price": "0.998", "size": "1250"}, {"price": "0.997", "size": "1172.64"}, {"price": "0.994", "size": "83"}, {"price": "0.993", "size": "10.47"}, {"price": "0.99", "size": "4280"}, {"price": "0.98", "size": "1000"}, {"price": "0.979", "size": "4432.71"}, {"price": "0.978", "size": "10.22"}, {"price": "0.959", "size": "48"}, {"price": "0.95", "size": "360"}, {"price": "0.949", "size": "39"}, {"price": "0.93", "size": "500"}, {"price": "0.929", "size": "6.76"}, {"price": "0.88", "size": "1265"}, {"price": "0.879", "size": "99.99"}, {"price": "0.878", "size": "10"}, {"price": "0.861", "size": "30"}, {"price": "0.86", "size": "40"}, {"price": "0.859", "size": "20"}, {"price": "0.805", "size": "250"}, {"price": "0.804", "size": "6.08"}, {"price": "0.777", "size": "269"}, {"price": "0.772", "size": "10"}, {"price": "0.73", "size": "50"}, {"price": "0.66", "size": "125"}, {"price": "0.659", "size": "5"}, {"price": "0.477", "size": "29"}, {"price": "0.277", "size": "151"}, {"price": "0.177", "size": "303"}, {"price": "0.077", "size": "357"}, {"price": "0.074", "size": "300"}, {"price": "0.073", "size": "369.89"}, {"price": "0.072", "size": "268.4"}, {"price": "0.049", "size": "200"}, {"price": "0.036", "size": "98"}, {"price": "0.034", "size": "88"}, {"price": "0.029", "size": "100"}, {"price": "0.005", "size": "144"}, {"price": "0.004", "size": "44.45"}, {"price": "0.003", "size": "55.55"}], "event_type": "book", "last_trade_price": "0.002"}, {"market": "0xd25ccd7ec063e97bcdfc4a5c425309786dee7d46cda598eeb056133ecc60a26b", "asset_id": "22672567771033630077120686118492403548405141258052518328454061644820946401508", "timestamp": "1769383932808", "hash": "c6a5b40354dba4ec59246adc73365fce236e0ec6", "bids": [{"price": "0.001", "size": "9678.99"}, {"price": "0.002", "size": "1250"}, {"price": "0.003", "size": "2166"}, {"price": "0.006", "size": "83"}, {"price": "0.01", "size": "180"}, {"price": "0.02", "size": "2000"}, {"price": "0.041", "size": "48"}, {"price": "0.05", "size": "360"}, {"price": "0.051", "size": "39"}, {"price": "0.052", "size": "10"}, {"price": "0.07", "size": "300"}, {"price": "0.1", "size": "860"}, {"price": "0.113", "size": "10"}, {"price": "0.15", "size": "551.66"}, {"price": "0.151", "size": "40"}, {"price": "0.152", "size": "30"}, {"price": "0.2", "size": "460"}, {"price": "0.223", "size": "70"}, {"price": "0.25", "size": "262"}, {"price": "0.27", "size": "50"}, {"price": "0.3", "size": "86.66"}, {"price": "0.35", "size": "68.57"}, {"price": "0.4", "size": "175"}, {"price": "0.5", "size": "778"}, {"price": "0.523", "size": "216"}, {"price": "0.524", "size": "5"}, {"price": "0.723", "size": "152"}, {"price": "0.823", "size": "300"}, {"price": "0.923", "size": "359"}, {"price": "0.99", "size": "500"}, {"price": "0.996", "size": "734.26"}], "asks": [], "event_type": "book", "last_trade_price": "0.001"}, {"market": "0xcf37574917d0050d35a7b3ff4e107b9156beda176b038a0bef71b05e68fca566", "asset_id": "57793958151619536355068674589681305458927379368792342045092047893593156845953", "timestamp": "1769383932808", "hash": "add9db3718f375de877cfc126b19f7eae4f2853c", "bids": [{"price": "0.001", "size": "5460"}, {"price": "0.002", "size": "350"}, {"price": "0.003", "size": "246"}, {"price": "0.004", "size": "147"}, {"price": "0.005", "size": "16.08"}], "asks": [{"price": "0.999", "size": "6689.1"}, {"price": "0.998", "size": "1250"}, {"price": "0.997", "size": "1172.38"}, {"price": "0.994", "size": "83"}, {"price": "0.993", "size": "12.8"}, {"price": "0.99", "size": "4180"}, {"price": "0.98", "size": "1000"}, {"price": "0.979", "size": "4899.2"}, {"price": "0.978", "size": "9.81"}, {"price": "0.959", "size": "48"}, {"price": "0.95", "size": "360"}, {"price": "0.949", "size": "39"}, {"price": "0.947", "size": "10"}, {"price": "0.93", "size": "300"}, {"price": "0.929", "size": "6.81"}, {"price": "0.9", "size": "560"}, {"price": "0.899", "size": "20"}, {"price": "0.85", "size": "551.66"}, {"price": "0.849", "size": "100"}, {"price": "0.848", "size": "30"}, {"price": "0.846", "size": "40"}, {"price": "0.8", "size": "460"}, {"price": "0.799", "size": "99.99"}, {"price": "0.798", "size": "5.85"}, {"price": "0.777", "size": "70"}, {"price": "0.75", "size": "262"}, {"price": "0.749", "size": "156"}, {"price": "0.73", "size": "50"}, {"price": "0.7", "size": "86.66"}, {"price": "0.65", "size": "68.57"}, {"price": "0.6", "size": "175"}, {"price": "0.599", "size": "5"}, {"price": "0.477", "size": "66"}, {"price": "0.277", "size": "152"}, {"price": "0.177", "size": "300"}, {"price": "0.077", "size": "359"}, {"price": "0.02", "size": "300"}, {"price": "0.019", "size": "370"}, {"price": "0.018", "size": "197.37"}, {"price": "0.017", "size": "12"}, {"price": "0.015", "size": "100"}, {"price": "0.014", "size": "80"}, {"price": "0.013", "size": "33.07"}], "event_type": "book", "last_trade_price": "0.995"}, {"market": "0x5bb310c9ec29b1d762c5805810ca1bb864d2352a8f76812a3dca82a6a138ccf7", "asset_id": "96698433275460890480977628481467803238308494811045928618542144931124282536955", "timestamp": "1769383934022", "hash": "c100d4950791722ff3bdb2e59a2bd534d04d9b5a", "bids": [{"price": "0.001", "size": "6686.2"}, {"price": "0.002", "size": "1250"}, {"price": "0.003", "size": "1172.64"}, {"price": "0.006", "size": "83"}, {"price": "0.007", "size": "10.47"}, {"price": "0.01", "size": "4280"}, {"price": "0.02", "size": "1000"}, {"price": "0.021", "size": "4432.71"}, {"price": "0.022", "size": "10.22"}, {"price": "0.041", "size": "48"}, {"price": "0.05", "size": "360"}, {"price": "0.051", "size": "39"}, {"price": "0.07", "size": "500"}, {"price": "0.071", "size": "6.76"}, {"price": "0.12", "size": "1265"}, {"price": "0.121", "size": "99.99"}, {"price": "0.122", "size": "10"}, {"price": "0.139", "size": "30"}, {"price": "0.14", "size": "40"}, {"price": "0.141", "size": "20"}, {"price": "0.195", "size": "250"}, {"price": "0.196", "size": "6.08"}, {"price": "0.223", "size": "269"}, {"price": "0.228", "size": "10"}, {"price": "0.27", "size": "50"}, {"price": "0.34", "size": "125"}, {"price": "0.341", "size": "5"}, {"price": "0.523", "size": "29"}, {"price": "0.723", "size": "151"}, {"price": "0.823", "size": "303"}, {"price": "0.923", "size": "357"}, {"price": "0.926", "size": "300"}, {"price": "0.927", "size": "369.89"}, {"price": "0.928", "size": "268.4"}, {"price": "0.951", "size": "200"}, {"price": "0.964", "size": "98"}, {"price": "0.966", "size": "88"}, {"price": "0.971", "size": "100"}, {"price": "0.995", "size": "144"}, {"price": "0.996", "size": "44.45"}, {"price": "0.997", "size": "55.55"}], "asks": [{"price": "0.999", "size": "6322.99"}, {"price": "0.998", "size": "439.16"}], "event_type": "book", "last_trade_price": "0.002"}, {"market": "0xf4cbee770d93e6be7c0eeef5fd8d143bf7b6cd05462745a0847aab51b993d406", "asset_id": "79935592053032469030142243551293799152704805799593114805455402419474295196734", "timestamp": "1769383973263", "hash": "3b76a6c278344af62f63aa54befba59d6ce21203", "bids": [{"price": "0.001", "size": "8460"}, {"price": "0.004", "size": "144"}], "asks": [{"price": "0.999", "size": "6685.99"}, {"price": "0.998", "size": "11082.01"}, {"price": "0.997", "size": "2172.62"}, {"price": "0.994", "size": "83"}, {"price": "0.993", "size": "9.76"}, {"price": "0.99", "size": "180"}, {"price": "0.98", "size": "2000"}, {"price": "0.979", "size": "10.91"}, {"price": "0.959", "size": "48"}, {"price": "0.95", "size": "360"}, {"price": "0.949", "size": "39"}, {"price": "0.948", "size": "10"}, {"price": "0.93", "size": "300"}, {"price": "0.929", "size": "7.07"}, {"price": "0.9", "size": "860"}, {"price": "0.899", "size": "20"}, {"price": "0.85", "size": "551.66"}, {"price": "0.849", "size": "30"}, {"price": "0.848", "size": "40"}, {"price": "0.8", "size": "460"}, {"price": "0.799", "size": "99.99"}, {"price": "0.798", "size": "5.79"}, {"price": "0.777", "size": "69"}, {"price": "0.776", "size": "284"}, {"price": "0.75", "size": "112"}, {"price": "0.73", "size": "50"}, {"price": "0.7", "size": "86.66"}, {"price": "0.65", "size": "68.57"}, {"price": "0.6", "size": "175"}, {"price": "0.477", "size": "362"}, {"price": "0.476", "size": "100"}, {"price": "0.475", "size": "300"}, {"price": "0.474", "size": "205"}, {"price": "0.277", "size": "151"}, {"price": "0.177", "size": "299"}, {"price": "0.077", "size": "240"}, {"price": "0.076", "size": "70"}, {"price": "0.074", "size": "90"}, {"price": "0.073", "size": "100"}, {"price": "0.066", "size": "88"}, {"price": "0.059", "size": "80"}, {"price": "0.049", "size": "65"}, {"price": "0.047", "size": "190"}, {"price": "0.034", "size": "36.69"}, {"price": "0.023", "size": "80"}, {"price": "0.022", "size": "28.69"}, {"price": "0.021", "size": "10"}], "event_type": "book", "last_trade_price": "0.987"}, {"market": "0x9bcfe6e8f19ff9f8bf329df320eb4d99e5617cbf86322aea27e87243241ddfa9", "asset_id": "56608750339220806170661168507381720092486244298206754160755855835789656176414", "timestamp": "1769383932961", "hash": "4a7c6a22924ddc043f759114c0c5f10cef4ac32e", "bids": [], "asks": [{"price": "0.999", "size": "6678.99"}, {"price": "0.998", "size": "1250"}, {"price": "0.997", "size": "1166"}, {"price": "0.996", "size": "7359"}, {"price": "0.994", "size": "83"}, {"price": "0.99", "size": "180"}, {"price": "0.98", "size": "2000"}, {"price": "0.959", "size": "48"}, {"price": "0.95", "size": "360"}, {"price": "0.949", "size": "39"}, {"price": "0.948", "size": "10"}, {"price": "0.93", "size": "300"}, {"price": "0.9", "size": "860"}, {"price": "0.85", "size": "551.66"}, {"price": "0.849", "size": "213"}, {"price": "0.848", "size": "40"}, {"price": "0.847", "size": "30"}, {"price": "0.8", "size": "460"}, {"price": "0.777", "size": "70"}, {"price": "0.75", "size": "262"}, {"price": "0.73", "size": "50"}, {"price": "0.7", "size": "86.66"}, {"price": "0.65", "size": "68.57"}, {"price": "0.6", "size": "175"}, {"price": "0.599", "size": "5"}, {"price": "0.477", "size": "126"}, {"price": "0.277", "size": "152"}, {"price": "0.177", "size": "300"}, {"price": "0.077", "size": "359"}, {"price": "0.01", "size": "400"}, {"price": "0.005", "size": "140"}, {"price": "0.004", "size": "1222.5"}], "event_type": "book", "last_trade_price": "0.004"}, {"market": "0x881092c53fd9b67bdf30869d756e13da558e8642ce13d104f73f648e005e9dbb", "asset_id": "106557923884483990512722312339562147481005985751920958827317376072063768641147", "timestamp": "1769384013548", "hash": "f5fb7955e768edb0d18033c3b2dc7033c2bd086f", "bids": [{"price": "0.001", "size": "9685.99"}, {"price": "0.002", "size": "1250"}, {"price": "0.003", "size": "2172.62"}, {"price": "0.006", "size": "83"}, {"price": "0.007", "size": "9.76"}, {"price": "0.01", "size": "180"}, {"price": "0.02", "size": "2000"}, {"price": "0.021", "size": "10.91"}, {"price": "0.041", "size": "48"}, {"price": "0.05", "size": "360"}, {"price": "0.051", "size": "39"}, {"price": "0.052", "size": "10"}, {"price": "0.07", "size": "300"}, {"price": "0.071", "size": "6.54"}, {"price": "0.1", "size": "860"}, {"price": "0.14", "size": "567.85"}, {"price": "0.143", "size": "30"}, {"price": "0.144", "size": "60"}, {"price": "0.19", "size": "168.42"}, {"price": "0.191", "size": "541.97"}, {"price": "0.192", "size": "6.29"}, {"price": "0.24", "size": "316.66"}, {"price": "0.27", "size": "50"}, {"price": "0.29", "size": "89.65"}, {"price": "0.291", "size": "44"}, {"price": "0.34", "size": "70.58"}, {"price": "0.38", "size": "52.63"}, {"price": "0.382", "size": "175"}, {"price": "0.383", "size": "5"}, {"price": "0.66", "size": "100"}, {"price": "0.802", "size": "98"}, {"price": "0.803", "size": "95"}, {"price": "0.804", "size": "90"}, {"price": "0.877", "size": "97"}, {"price": "0.878", "size": "48"}, {"price": "0.879", "size": "16.6"}, {"price": "0.933", "size": "6"}, {"price": "0.938", "size": "0.96"}], "asks": [{"price": "0.999", "size": "5635.99"}, {"price": "0.998", "size": "1750"}, {"price": "0.997", "size": "300"}, {"price": "0.996", "size": "147"}, {"price": "0.995", "size": "73"}, {"price": "0.993", "size": "148"}, {"price": "0.992", "size": "149.99"}], "event_type": "book", "last_trade_price": "0.062"}, {"market": "0x0e80cd8709ff87e5e8f640f04d56459b6b17f8725dfc45aa41638e864bdd516f", "asset_id": "64190946651851680406639375409936731829956855105844271954263113555549757553710", "timestamp": "1769383932860", "hash": "40d1307f5c35d47022f3eb421871067236de1fe8", "bids": [{"price": "0.001", "size": "2254.99"}, {"price": "0.002", "size": "13.71"}, {"price": "0.01", "size": "30"}, {"price": "0.011", "size": "15"}, {"price": "0.012", "size": "14.38"}, {"price": "0.032", "size": "25"}, {"price": "0.051", "size": "100"}, {"price": "0.059", "size": "16"}, {"price": "0.075", "size": "777"}, {"price": "0.08", "size": "666"}, {"price": "0.081", "size": "200"}, {"price": "0.088", "size": "27.79"}, {"price": "0.1", "size": "225.08"}, {"price": "0.101", "size": "66.66"}, {"price": "0.104", "size": "6"}, {"price": "0.11", "size": "300"}, {"price": "0.113", "size": "6"}, {"price": "0.118", "size": "116.66"}, {"price": "0.123", "size": "6"}, {"price": "0.126", "size": "50"}, {"price": "0.13", "size": "33"}, {"price": "0.131", "size": "6"}, {"price": "0.134", "size": "95.31"}], "asks": [{"price": "0.999", "size": "6259.99"}, {"price": "0.998", "size": "5.64"}, {"price": "0.997", "size": "1000"}, {"price": "0.996", "size": "4000"}, {"price": "0.995", "size": "15.95"}, {"price": "0.99", "size": "180"}, {"price": "0.988", "size": "12.1"}, {"price": "0.987", "size": "20"}, {"price": "0.98", "size": "2000"}, {"price": "0.979", "size": "30"}, {"price": "0.978", "size": "40"}, {"price": "0.959", "size": "48"}, {"price": "0.95", "size": "360"}, {"price": "0.949", "size": "39"}, {"price": "0.948", "size": "11.87"}, {"price": "0.91", "size": "1000"}, {"price": "0.87", "size": "586.53"}, {"price": "0.83", "size": "438.23"}, {"price": "0.8", "size": "20.52"}, {"price": "0.79", "size": "333.33"}, {"price": "0.789", "size": "5.41"}, {"price": "0.779", "size": "113"}, {"price": "0.74", "size": "100"}, {"price": "0.73", "size": "50"}, {"price": "0.7", "size": "80"}, {"price": "0.66", "size": "58.82"}, {"price": "0.639", "size": "425"}, {"price": "0.638", "size": "5"}, {"price": "0.47", "size": "2.91"}, {"price": "0.193", "size": "66"}, {"price": "0.19", "size": "100"}, {"price": "0.189", "size": "120"}, {"price": "0.188", "size": "21.14"}, {"price": "0.179", "size": "20"}, {"price": "0.175", "size": "82.79"}, {"price": "0.174", "size": "90"}, {"price": "0.173", "size": "6"}, {"price": "0.171", "size": "90"}, {"price": "0.169", "size": "40"}, {"price": "0.168", "size": "6"}, {"price": "0.165", "size": "21.14"}, {"price": "0.159", "size": "50"}, {"price": "0.158", "size": "6"}, {"price": "0.149", "size": "40"}, {"price": "0.148", "size": "10.6"}, {"price": "0.147", "size": "6"}, {"price": "0.145", "size": "20"}, {"price": "0.143", "size": "9.47"}], "event_type": "book", "last_trade_price": "0.134"}, {"market": "0xcf37574917d0050d35a7b3ff4e107b9156beda176b038a0bef71b05e68fca566", "asset_id": "115177582201864534628566870447729971283521386185204659694620719760753811796797", "timestamp": "1769383932808", "hash": "00f2b94e3d7eacc23f9fba8c05cdd22d681f7022", "bids": [{"price": "0.001", "size": "6689.1"}, {"price": "0.002", "size": "1250"}, {"price": "0.003", "size": "1172.38"}, {"price": "0.006", "size": "83"}, {"price": "0.007", "size": "12.8"}, {"price": "0.01", "size": "4180"}, {"price": "0.02", "size": "1000"}, {"price": "0.021", "size": "4899.2"}, {"price": "0.022", "size": "9.81"}, {"price": "0.041", "size": "48"}, {"price": "0.05", "size": "360"}, {"price": "0.051", "size": "39"}, {"price": "0.053", "size": "10"}, {"price": "0.07", "size": "300"}, {"price": "0.071", "size": "6.81"}, {"price": "0.1", "size": "560"}, {"price": "0.101", "size": "20"}, {"price": "0.15", "size": "551.66"}, {"price": "0.151", "size": "100"}, {"price": "0.152", "size": "30"}, {"price": "0.154", "size": "40"}, {"price": "0.2", "size": "460"}, {"price": "0.201", "size": "99.99"}, {"price": "0.202", "size": "5.85"}, {"price": "0.223", "size": "70"}, {"price": "0.25", "size": "262"}, {"price": "0.251", "size": "156"}, {"price": "0.27", "size": "50"}, {"price": "0.3", "size": "86.66"}, {"price": "0.35", "size": "68.57"}, {"price": "0.4", "size": "175"}, {"price": "0.401", "size": "5"}, {"price": "0.523", "size": "66"}, {"price": "0.723", "size": "152"}, {"price": "0.823", "size": "300"}, {"price": "0.923", "size": "359"}, {"price": "0.98", "size": "300"}, {"price": "0.981", "size": "370"}, {"price": "0.982", "size": "197.37"}, {"price": "0.983", "size": "12"}, {"price": "0.985", "size": "100"}, {"price": "0.986", "size": "80"}, {"price": "0.987", "size": "33.07"}], "asks": [{"price": "0.999", "size": "5460"}, {"price": "0.998", "size": "350"}, {"price": "0.997", "size": "246"}, {"price": "0.996", "size": "147"}, {"price": "0.995", "size": "16.08"}], "event_type": "book", "last_trade_price": "0.995"}, {"market": "0x0e80cd8709ff87e5e8f640f04d56459b6b17f8725dfc45aa41638e864bdd516f", "asset_id": "31948734631736561994125221293320704077897312273398644786977701161539360085435", "timestamp": "1769383932860", "hash": "d57c7aa51948eedda6b2c9b01e8d9d39ada2152b", "bids": [{"price": "0.001", "size": "6259.99"}, {"price": "0.002", "size": "5.64"}, {"price": "0.003", "size": "1000"}, {"price": "0.004", "size": "4000"}, {"price": "0.005", "size": "15.95"}, {"price": "0.01", "size": "180"}, {"price": "0.012", "size": "12.1"}, {"price": "0.013", "size": "20"}, {"price": "0.02", "size": "2000"}, {"price": "0.021", "size": "30"}, {"price": "0.022", "size": "40"}, {"price": "0.041", "size": "48"}, {"price": "0.05", "size": "360"}, {"price": "0.051", "size": "39"}, {"price": "0.052", "size": "11.87"}, {"price": "0.09", "size": "1000"}, {"price": "0.13", "size": "586.53"}, {"price": "0.17", "size": "438.23"}, {"price": "0.2", "size": "20.52"}, {"price": "0.21", "size": "333.33"}, {"price": "0.211", "size": "5.41"}, {"price": "0.221", "size": "113"}, {"price": "0.26", "size": "100"}, {"price": "0.27", "size": "50"}, {"price": "0.3", "size": "80"}, {"price": "0.34", "size": "58.82"}, {"price": "0.361", "size": "425"}, {"price": "0.362", "size": "5"}, {"price": "0.53", "size": "2.91"}, {"price": "0.807", "size": "66"}, {"price": "0.81", "size": "100"}, {"price": "0.811", "size": "120"}, {"price": "0.812", "size": "21.14"}, {"price": "0.821", "size": "20"}, {"price": "0.825", "size": "82.79"}, {"price": "0.826", "size": "90"}, {"price": "0.827", "size": "6"}, {"price": "0.829", "size": "90"}, {"price": "0.831", "size": "40"}, {"price": "0.832", "size": "6"}, {"price": "0.835", "size": "21.14"}, {"price": "0.841", "size": "50"}, {"price": "0.842", "size": "6"}, {"price": "0.851", "size": "40"}, {"price": "0.852", "size": "10.6"}, {"price": "0.853", "size": "6"}, {"price": "0.855", "size": "20"}, {"price": "0.857", "size": "9.47"}], "asks": [{"price": "0.999", "size": "2254.99"}, {"price": "0.998", "size": "13.71"}, {"price": "0.99", "size": "30"}, {"price": "0.989", "size": "15"}, {"price": "0.988", "size": "14.38"}, {"price": "0.968", "size": "25"}, {"price": "0.949", "size": "100"}, {"price": "0.941", "size": "16"}, {"price": "0.925", "size": "777"}, {"price": "0.92", "size": "666"}, {"price": "0.919", "size": "200"}, {"price": "0.912", "size": "27.79"}, {"price": "0.9", "size": "225.08"}, {"price": "0.899", "size": "66.66"}, {"price": "0.896", "size": "6"}, {"price": "0.89", "size": "300"}, {"price": "0.887", "size": "6"}, {"price": "0.882", "size": "116.66"}, {"price": "0.877", "size": "6"}, {"price": "0.874", "size": "50"}, {"price": "0.87", "size": "33"}, {"price": "0.869", "size": "6"}, {"price": "0.866", "size": "95.31"}], "event_type": "book", "last_trade_price": "0.134"}, {"market": "0xeaca7fad27f9e7602a07627a1dbb4b01352cd7ad99dd28b0ec09e26e6b12ccab", "asset_id": "106496774138546112027406613561717117026755108026255407086336415079048692630377", "timestamp": "1769383991808", "hash": "ee68144890fc36fc83e865153befeffc9334f39b", "bids": [{"price": "0.001", "size": "6688.99"}, {"price": "0.002", "size": "1250"}, {"price": "0.003", "size": "1172.62"}, {"price": "0.006", "size": "83"}, {"price": "0.007", "size": "9.76"}, {"price": "0.01", "size": "4180"}, {"price": "0.011", "size": "3660"}, {"price": "0.02", "size": "2000"}, {"price": "0.021", "size": "10.79"}, {"price": "0.041", "size": "48"}, {"price": "0.05", "size": "360"}, {"price": "0.051", "size": "39"}, {"price": "0.052", "size": "10"}, {"price": "0.07", "size": "300"}, {"price": "0.071", "size": "7.12"}, {"price": "0.1", "size": "860"}, {"price": "0.102", "size": "30"}, {"price": "0.103", "size": "20"}, {"price": "0.15", "size": "551.66"}, {"price": "0.151", "size": "75"}, {"price": "0.153", "size": "40"}, {"price": "0.2", "size": "460"}, {"price": "0.201", "size": "99.99"}, {"price": "0.202", "size": "5.79"}, {"price": "0.223", "size": "70"}, {"price": "0.25", "size": "262"}, {"price": "0.251", "size": "156"}, {"price": "0.27", "size": "50"}, {"price": "0.3", "size": "86.66"}, {"price": "0.35", "size": "68.57"}, {"price": "0.4", "size": "175"}, {"price": "0.401", "size": "5"}, {"price": "0.523", "size": "123"}, {"price": "0.723", "size": "152"}, {"price": "0.823", "size": "300"}, {"price": "0.827", "size": "300"}, {"price": "0.828", "size": "300"}, {"price": "0.829", "size": "200"}, {"price": "0.83", "size": "100"}, {"price": "0.923", "size": "273"}, {"price": "0.924", "size": "200"}, {"price": "0.926", "size": "180"}, {"price": "0.971", "size": "28"}, {"price": "0.972", "size": "80"}, {"price": "0.974", "size": "87.99"}, {"price": "0.976", "size": "120"}, {"price": "0.977", "size": "201.32"}, {"price": "0.978", "size": "30"}, {"price": "0.979", "size": "50"}], "asks": [{"price": "0.999", "size": "7348"}, {"price": "0.998", "size": "1500"}, {"price": "0.997", "size": "250"}, {"price": "0.995", "size": "8.89"}, {"price": "0.993", "size": "148"}, {"price": "0.992", "size": "30"}], "event_type": "book", "last_trade_price": "0.994"}, {"market": "0xbb7afda76b33e28e6beca651afcf4ba2c96316330038b37d565311aec7aa80fd", "asset_id": "115380547880912465734621551138342931070381865195675981110314630607033301257937", "timestamp": "1769384043192", "hash": "18f4057629bb5a62eb1e7bca5cc3fb6326e0edbc", "bids": [{"price": "0.001", "size": "5271.99"}, {"price": "0.002", "size": "7.48"}, {"price": "0.003", "size": "1000"}, {"price": "0.004", "size": "4000"}, {"price": "0.005", "size": "16"}, {"price": "0.01", "size": "180"}, {"price": "0.02", "size": "2000"}, {"price": "0.021", "size": "5.11"}, {"price": "0.05", "size": "400"}, {"price": "0.06", "size": "33"}, {"price": "0.066", "size": "20"}, {"price": "0.067", "size": "7.85"}, {"price": "0.07", "size": "300"}, {"price": "0.1", "size": "860"}, {"price": "0.109", "size": "30"}, {"price": "0.11", "size": "60"}, {"price": "0.14", "size": "242.85"}, {"price": "0.141", "size": "575"}, {"price": "0.19", "size": "418.42"}, {"price": "0.191", "size": "6.63"}, {"price": "0.24", "size": "316.66"}, {"price": "0.241", "size": "8"}, {"price": "0.27", "size": "50"}, {"price": "0.29", "size": "89.65"}, {"price": "0.34", "size": "120.58"}, {"price": "0.38", "size": "52.63"}, {"price": "0.39", "size": "75"}, {"price": "0.5", "size": "560"}, {"price": "0.819", "size": "6.51"}, {"price": "0.82", "size": "2831.49"}, {"price": "0.821", "size": "268.43"}, {"price": "0.88", "size": "6.51"}, {"price": "0.932", "size": "50.8"}, {"price": "0.94", "size": "90.42"}, {"price": "0.941", "size": "33.91"}], "asks": [{"price": "0.999", "size": "5726.99"}, {"price": "0.998", "size": "314"}, {"price": "0.997", "size": "206.67"}, {"price": "0.996", "size": "200"}, {"price": "0.995", "size": "66.66"}, {"price": "0.994", "size": "5.45"}, {"price": "0.99", "size": "36.39"}, {"price": "0.989", "size": "24.33"}, {"price": "0.987", "size": "11.97"}, {"price": "0.979", "size": "6"}, {"price": "0.978", "size": "66.66"}, {"price": "0.97", "size": "99.99"}, {"price": "0.969", "size": "6"}, {"price": "0.968", "size": "93"}, {"price": "0.963", "size": "6"}, {"price": "0.959", "size": "66.66"}, {"price": "0.958", "size": "125.26"}], "event_type": "book", "last_trade_price": "0.940"}, {"market": "0x881092c53fd9b67bdf30869d756e13da558e8642ce13d104f73f648e005e9dbb", "asset_id": "30209161280120374886078524432124760376829393809604890971368528789299616787016", "timestamp": "1769384013548", "hash": "568267d4b42bbd3e60e405f39b168df4e495af7b", "bids": [{"price": "0.001", "size": "5635.99"}, {"price": "0.002", "size": "1750"}, {"price": "0.003", "size": "300"}, {"price": "0.004", "size": "147"}, {"price": "0.005", "size": "73"}, {"price": "0.007", "size": "148"}, {"price": "0.008", "size": "149.99"}], "asks": [{"price": "0.999", "size": "9685.99"}, {"price": "0.998", "size": "1250"}, {"price": "0.997", "size": "2172.62"}, {"price": "0.994", "size": "83"}, {"price": "0.993", "size": "9.76"}, {"price": "0.99", "size": "180"}, {"price": "0.98", "size": "2000"}, {"price": "0.979", "size": "10.91"}, {"price": "0.959", "size": "48"}, {"price": "0.95", "size": "360"}, {"price": "0.949", "size": "39"}, {"price": "0.948", "size": "10"}, {"price": "0.93", "size": "300"}, {"price": "0.929", "size": "6.54"}, {"price": "0.9", "size": "860"}, {"price": "0.86", "size": "567.85"}, {"price": "0.857", "size": "30"}, {"price": "0.856", "size": "60"}, {"price": "0.81", "size": "168.42"}, {"price": "0.809", "size": "541.97"}, {"price": "0.808", "size": "6.29"}, {"price": "0.76", "size": "316.66"}, {"price": "0.73", "size": "50"}, {"price": "0.71", "size": "89.65"}, {"price": "0.709", "size": "44"}, {"price": "0.66", "size": "70.58"}, {"price": "0.62", "size": "52.63"}, {"price": "0.618", "size": "175"}, {"price": "0.617", "size": "5"}, {"price": "0.34", "size": "100"}, {"price": "0.198", "size": "98"}, {"price": "0.197", "size": "95"}, {"price": "0.196", "size": "90"}, {"price": "0.123", "size": "97"}, {"price": "0.122", "size": "48"}, {"price": "0.121", "size": "16.6"}, {"price": "0.067", "size": "6"}, {"price": "0.062", "size": "0.96"}], "event_type": "book", "last_trade_price": "0.062"}]}
{"_local_timestamp": "2026-01-25T23:34:27.772222+00:00", "data": {"market": "0xbb7afda76b33e28e6beca651afcf4ba2c96316330038b37d565311aec7aa80fd", "price_changes": [{"asset_id": "115380547880912465734621551138342931070381865195675981110314630607033301257937", "price": "0.39", "size": "0", "side": "BUY", "hash": "0bc3d96bad9d26fdbde14e2e4e782d2a1ba13958", "best_bid": "0.941", "best_ask": "0.958"}, {"asset_id": "55048873344980893604077431803703373331531589597253065240792528177019001889497", "price": "0.61", "size": "0", "side": "SELL", "hash": "77354688feececc8f1eabb3a862e8a263e079b2c", "best_bid": "0.042", "best_ask": "0.059"}], "timestamp": "1769384067558", "event_type": "price_change"}}
{"_local_timestamp": "2026-01-25T23:34:27.775688+00:00", "data": {"market": "0xbb7afda76b33e28e6beca651afcf4ba2c96316330038b37d565311aec7aa80fd", "price_changes": [{"asset_id": "115380547880912465734621551138342931070381865195675981110314630607033301257937", "price": "0.1", "size": "560", "side": "BUY", "hash": "0bc3d96bad9d26fdbde14e2e4e782d2a1ba13958", "best_bid": "0.941", "best_ask": "0.958"}, {"asset_id": "55048873344980893604077431803703373331531589597253065240792528177019001889497", "price": "0.9", "size": "560", "side": "SELL", "hash": "77354688feececc8f1eabb3a862e8a263e079b2c", "best_bid": "0.042", "best_ask": "0.059"}], "timestamp": "1769384067558", "event_type": "price_change"}}
{"_local_timestamp": "2026-01-25T23:34:28.742553+00:00", "data": {"market": "0xbb7afda76b33e28e6beca651afcf4ba2c96316330038b37d565311aec7aa80fd", "price_changes": [{"asset_id": "115380547880912465734621551138342931070381865195675981110314630607033301257937", "price": "0.38", "size": "127.63", "side": "BUY", "hash": "14704c7625390e761750b802278f51fbf31e4ccf", "best_bid": "0.941", "best_ask": "0.958"}, {"asset_id": "55048873344980893604077431803703373331531589597253065240792528177019001889497", "price": "0.62", "size": "127.63", "side": "SELL", "hash": "17769b490892e4177cd28bc3ce65d94929f89dba", "best_bid": "0.042", "best_ask": "0.059"}], "timestamp": "1769384068156", "event_type": "price_change"}}
{"_local_timestamp": "2026-01-25T23:34:28.843990+00:00", "data": {"market": "0xbb7afda76b33e28e6beca651afcf4ba2c96316330038b37d565311aec7aa80fd", "price_changes": [{"asset_id": "115380547880912465734621551138342931070381865195675981110314630607033301257937", "price": "0.02", "size": "2300", "side": "BUY", "hash": "35a9a75732abe8a6cdd16107417e54bcebe807f7", "best_bid": "0.941", "best_ask": "0.958"}, {"asset_id": "55048873344980893604077431803703373331531589597253065240792528177019001889497", "price": "0.98", "size": "2300", "side": "SELL", "hash": "25aa329f479c9f0bdccedb082ad067691fafee28", "best_bid": "0.042", "best_ask": "0.059"}], "timestamp": "1769384068236", "event_type": "price_change"}}
{"_local_timestamp": "2026-01-25T23:34:33.157343+00:00", "data": {"market": "0xbb7afda76b33e28e6beca651afcf4ba2c96316330038b37d565311aec7aa80fd", "price_changes": [{"asset_id": "55048873344980893604077431803703373331531589597253065240792528177019001889497", "price": "0.032", "size": "0", "side": "BUY", "hash": "bb7536376e4e6bc2673913f0a7aa103d0f0cceb2", "best_bid": "0.042", "best_ask": "0.059"}, {"asset_id": "115380547880912465734621551138342931070381865195675981110314630607033301257937", "price": "0.968", "size": "0", "side": "SELL", "hash": "f5660b70d788c69d2851aa7d2146df5990e80729", "best_bid": "0.941", "best_ask": "0.958"}], "timestamp": "1769384072922", "event_type": "price_change"}}
{"_local_timestamp": "2026-01-25T23:34:33.246758+00:00", "data": {"market": "0xbb7afda76b33e28e6beca651afcf4ba2c96316330038b37d565311aec7aa80fd", "price_changes": [{"asset_id": "55048873344980893604077431803703373331531589597253065240792528177019001889497", "price": "0.042", "size": "196.26", "side": "BUY", "hash": "993f77a0db2b257f49ede78cc73adef4c6933ad6", "best_bid": "0.042", "best_ask": "0.059"}, {"asset_id": "115380547880912465734621551138342931070381865195675981110314630607033301257937", "price": "0.958", "size": "196.26", "side": "SELL", "hash": "53b41ea48afcf2f75c53b94b6654ba843f1d5c74", "best_bid": "0.941", "best_ask": "0.958"}], "timestamp": "1769384073006", "event_type": "price_change"}}
{"_local_timestamp": "2026-01-25T23:34:33.633880+00:00", "data": {"market": "0xbb7afda76b33e28e6beca651afcf4ba2c96316330038b37d565311aec7aa80fd", "price_changes": [{"asset_id": "55048873344980893604077431803703373331531589597253065240792528177019001889497", "price": "0.042", "size": "166.26", "side": "BUY", "hash": "ef85affc399d616b7e908b860bd74d0a1e4b1e97", "best_bid": "0.042", "best_ask": "0.059"}, {"asset_id": "115380547880912465734621551138342931070381865195675981110314630607033301257937", "price": "0.958", "size": "166.26", "side": "SELL", "hash": "e980f7eca164706ab1df72354e3921ee97a476f4", "best_bid": "0.941", "best_ask": "0.958"}], "timestamp": "1769384073399", "event_type": "price_change"}}
{"_local_timestamp": "2026-01-25T23:34:41.863569+00:00", "data": {"market": "0xeaca7fad27f9e7602a07627a1dbb4b01352cd7ad99dd28b0ec09e26e6b12ccab", "price_changes": [{"asset_id": "76657535986059542453526409873946781453980750888541128603750398128471993423003", "price": "0.023", "size": "0", "side": "SELL", "hash": "20b3d38738a679c231a83164b8459ce00c70c066", "best_bid": "0.008", "best_ask": "0.021"}, {"asset_id": "106496774138546112027406613561717117026755108026255407086336415079048692630377", "price": "0.977", "size": "0", "side": "BUY", "hash": "5641313d42cd0b71840ec2667ffced361af77638", "best_bid": "0.979", "best_ask": "0.992"}], "timestamp": "1769384081795", "event_type": "price_change"}}
{"_local_timestamp": "2026-01-25T23:34:41.969212+00:00", "data": {"market": "0xeaca7fad27f9e7602a07627a1dbb4b01352cd7ad99dd28b0ec09e26e6b12ccab", "price_changes": [{"asset_id": "106496774138546112027406613561717117026755108026255407086336415079048692630377", "price": "0.153", "size": "0", "side": "BUY", "hash": "33edfda4fe057ad0c8d6e6d4dfddb1cc0b3af538", "best_bid": "0.979", "best_ask": "0.992"}, {"asset_id": "76657535986059542453526409873946781453980750888541128603750398128471993423003", "price": "0.847", "size": "0", "side": "SELL", "hash": "cac8e2468e3a505c7e73169d449e127a6f47caaa", "best_bid": "0.008", "best_ask": "0.021"}], "timestamp": "1769384081900", "event_type": "price_change"}}
{"_local_timestamp": "2026-01-25T23:34:41.971338+00:00", "data": {"market": "0xd25ccd7ec063e97bcdfc4a5c425309786dee7d46cda598eeb056133ecc60a26b", "price_changes": [{"asset_id": "22672567771033630077120686118492403548405141258052518328454061644820946401508", "price": "0.151", "size": "0", "side": "BUY", "hash": "d5dc9b64031355d3546319e349cb16b4a7fd4d33", "best_bid": "0.996", "best_ask": "1"}, {"asset_id": "61363616775934825034538234334948775070821960948072963080826717391882343278521", "price": "0.849", "size": "0", "side": "SELL", "hash": "8f8a60943ad686171af6723e39baf7b9d4567235", "best_bid": "0", "best_ask": "0.004"}], "timestamp": "1769384081900", "event_type": "price_change"}}
{"_local_timestamp": "2026-01-25T23:34:42.146829+00:00", "data": {"market": "0xd25ccd7ec063e97bcdfc4a5c425309786dee7d46cda598eeb056133ecc60a26b", "price_changes": [{"asset_id": "22672567771033630077120686118492403548405141258052518328454061644820946401508", "price": "0.153", "size": "40", "side": "BUY", "hash": "315f7162e81d8d83176d637f5540367c9cd07843", "best_bid": "0.996", "best_ask": "1"}, {"asset_id": "61363616775934825034538234334948775070821960948072963080826717391882343278521", "price": "0.847", "size": "40", "side": "SELL", "hash": "965268eabc11808006409a3dafeb28a80ec1a2c6", "best_bid": "0", "best_ask": "0.004"}], "timestamp": "1769384082081", "event_type": "price_change"}}
{"_local_timestamp": "2026-01-25T23:34:42.147267+00:00", "data": {"market": "0xeaca7fad27f9e7602a07627a1dbb4b01352cd7ad99dd28b0ec09e26e6b12ccab", "price_changes": [{"asset_id": "106496774138546112027406613561717117026755108026255407086336415079048692630377", "price": "0.104", "size": "40", "side": "BUY", "hash": "2387a535274e2ef95fb0f49b15835119471e4bf5", "best_bid": "0.979", "best_ask": "0.992"}, {"asset_id": "76657535986059542453526409873946781453980750888541128603750398128471993423003", "price": "0.896", "size": "40", "side": "SELL", "hash": "1c68379f0fd72b1d1cbfd6f56f8a8a3259f48dde", "best_bid": "0.008", "best_ask": "0.021"}], "timestamp": "1769384082081", "event_type": "price_change"}}
{"_local_timestamp": "2026-01-25T23:34:42.347899+00:00", "data": {"market": "0xcf37574917d0050d35a7b3ff4e107b9156beda176b038a0bef71b05e68fca566", "price_changes": [{"asset_id": "115177582201864534628566870447729971283521386185204659694620719760753811796797", "price": "0.154", "size": "0", "side": "BUY", "hash": "3d8bdf30d7d58411f376bbbf4c05d4ae9e31f08b", "best_bid": "0.987", "best_ask": "0.995"}, {"asset_id": "57793958151619536355068674589681305458927379368792342045092047893593156845953", "price": "0.846", "size": "0", "side": "SELL", "hash": "94dfdc49cb42eba4fee8bc6bbece2e6863040351", "best_bid": "0.005", "best_ask": "0.013"}], "timestamp": "1769384082259", "event_type": "price_change"}}
{"_local_timestamp": "2026-01-25T23:34:42.453206+00:00", "data": {"market": "0xeaca7fad27f9e7602a07627a1dbb4b01352cd7ad99dd28b0ec09e26e6b12ccab", "price_changes": [{"asset_id": "106496774138546112027406613561717117026755108026255407086336415079048692630377", "price": "0.978", "size": "0", "side": "BUY", "hash": "aad1849f8e1f55df77cd6e5425fb5d9b5756829d", "best_bid": "0.979", "best_ask": "0.992"}, {"asset_id": "76657535986059542453526409873946781453980750888541128603750398128471993423003", "price": "0.022", "size": "0", "side": "SELL", "hash": "2a88e6eba2086380261a3457d4f7bacc0165f7b0", "best_bid": "0.008", "best_ask": "0.021"}], "timestamp": "1769384082388", "event_type": "price_change"}}
{"_local_timestamp": "2026-01-25T23:34:42.473597+00:00", "data": {"market": "0xcf37574917d0050d35a7b3ff4e107b9156beda176b038a0bef71b05e68fca566", "price_changes": [{"asset_id": "115177582201864534628566870447729971283521386185204659694620719760753811796797", "price": "0.153", "size": "40", "side": "BUY", "hash": "ee0e44c9cb16688c2a8331fd6cc6592545a4ef2b", "best_bid": "0.987", "best_ask": "0.995"}, {"asset_id": "57793958151619536355068674589681305458927379368792342045092047893593156845953", "price": "0.847", "size": "40", "side": "SELL", "hash": "7537e1f7dcf014bd64cd658121357dcccd54e5db", "best_bid": "0.005", "best_ask": "0.013"}], "timestamp": "1769384082409", "event_type": "price_change"}}
{"_local_timestamp": "2026-01-25T23:34:42.502263+00:00", "data": {"market": "0x6f688996e47f896351729088a8c2c0fcb7db6f40fd96eed42502e11c9962f744", "price_changes": [{"asset_id": "63575582870841942383427053084518597975654282758242000155173178759202148848429", "price": "0.151", "size": "0", "side": "BUY", "hash": "cf5ae1dbc7aaea914a416b57c0d4ef0df68ae95b", "best_bid": "0.993", "best_ask": "1"}, {"asset_id": "1479722737131399761673297933236140450313179902349075711821861456880367927838", "price": "0.849", "size": "0", "side": "SELL", "hash": "1b6705ab68fb8abc49807592b3e1a30d6a3c07bc", "best_bid": "0", "best_ask": "0.007"}], "timestamp": "1769384082432", "event_type": "price_change"}}
{"_local_timestamp": "2026-01-25T23:34:42.502726+00:00", "data": {"market": "0x9bcfe6e8f19ff9f8bf329df320eb4d99e5617cbf86322aea27e87243241ddfa9", "price_changes": [{"asset_id": "78930020687216610592275737264551684416741191072026547466466591111794825522715", "price": "0.152", "size": "0", "side": "BUY", "hash": "b2bf16192015b61e8f21e528d891719e994f1aeb", "best_bid": "0.996", "best_ask": "1"}, {"asset_id": "56608750339220806170661168507381720092486244298206754160755855835789656176414", "price": "0.848", "size": "0", "side": "SELL", "hash": "bbe75a074289c890de0668d4f7ea0f91629dd737", "best_bid": "0", "best_ask": "0.004"}], "timestamp": "1769384082432", "event_type": "price_change"}}
{"_local_timestamp": "2026-01-25T23:34:42.507089+00:00", "data": {"market": "0xeaca7fad27f9e7602a07627a1dbb4b01352cd7ad99dd28b0ec09e26e6b12ccab", "price_changes": [{"asset_id": "106496774138546112027406613561717117026755108026255407086336415079048692630377", "price": "0.976", "size": "150", "side": "BUY", "hash": "06d62ce381bebda0aae75e584618659c5baf37db", "best_bid": "0.979", "best_ask": "0.992"}, {"asset_id": "76657535986059542453526409873946781453980750888541128603750398128471993423003", "price": "0.024", "size": "150", "side": "SELL", "hash": "c387e93f1f93abb3ffaf7b1a9e1d60716c4cb8bd", "best_bid": "0.008", "best_ask": "0.021"}], "timestamp": "1769384082442", "event_type": "price_change"}}
{"_local_timestamp": "2026-01-25T23:34:42.573552+00:00", "data": {"market": "0xeaca7fad27f9e7602a07627a1dbb4b01352cd7ad99dd28b0ec09e26e6b12ccab", "price_changes": [{"asset_id": "106496774138546112027406613561717117026755108026255407086336415079048692630377", "price": "0.18", "size": "50", "side": "BUY", "hash": "db8991a5371aaebce0b0ff093006cb3453084cc1", "best_bid": "0.979", "best_ask": "0.992"}, {"asset_id": "76657535986059542453526409873946781453980750888541128603750398128471993423003", "price": "0.82", "size": "50", "side": "SELL", "hash": "b4cb617d8e3d186e976626b7b89871747e5aac00", "best_bid": "0.008", "best_ask": "0.021"}], "timestamp": "1769384082503", "event_type": "price_change"}}
{"_local_timestamp": "2026-01-25T23:34:42.591111+00:00", "data": {"market": "0xeaca7fad27f9e7602a07627a1dbb4b01352cd7ad99dd28b0ec09e26e6b12ccab", "price_changes": [{"asset_id": "106496774138546112027406613561717117026755108026255407086336415079048692630377", "price": "0.18", "size": "100", "side": "BUY", "hash": "f0e5aaf3b182936bfaef4899f38985e1fc4872b8", "best_bid": "0.979", "best_ask": "0.992"}, {"asset_id": "76657535986059542453526409873946781453980750888541128603750398128471993423003", "price": "0.82", "size": "100", "side": "SELL", "hash": "49a844a82d1551012e6d3058e245295891d6bd33", "best_bid": "0.008", "best_ask": "0.021"}], "timestamp": "1769384082521", "event_type": "price_change"}}
{"_local_timestamp": "2026-01-25T23:34:42.601649+00:00", "data": {"market": "0xeaca7fad27f9e7602a07627a1dbb4b01352cd7ad99dd28b0ec09e26e6b12ccab", "price_changes": [{"asset_id": "106496774138546112027406613561717117026755108026255407086336415079048692630377", "price": "0.18", "size": "150", "side": "BUY", "hash": "b09074fb40c109a0bfeeee128d586a0d538a7963", "best_bid": "0.979", "best_ask": "0.992"}, {"asset_id": "76657535986059542453526409873946781453980750888541128603750398128471993423003", "price": "0.82", "size": "150", "side": "SELL", "hash": "00a6acfc14b8330a088af1fbb35bdfe7b2f7b0ec", "best_bid": "0.008", "best_ask": "0.021"}], "timestamp": "1769384082531", "event_type": "price_change"}}
{"_local_timestamp": "2026-01-25T23:34:42.633248+00:00", "data": {"market": "0x9bcfe6e8f19ff9f8bf329df320eb4d99e5617cbf86322aea27e87243241ddfa9", "price_changes": [{"asset_id": "78930020687216610592275737264551684416741191072026547466466591111794825522715", "price": "0.154", "size": "40", "side": "BUY", "hash": "93614fc386ab32c264ea40607185af74489dca63", "best_bid": "0.996", "best_ask": "1"}, {"asset_id": "56608750339220806170661168507381720092486244298206754160755855835789656176414", "price": "0.846", "size": "40", "side": "SELL", "hash": "8ae6050b4b888ec171d484caecae49a5424a1cd6", "best_bid": "0", "best_ask": "0.004"}], "timestamp": "1769384082558", "event_type": "price_change"}}
{"_local_timestamp": "2026-01-25T23:34:42.633721+00:00", "data": {"market": "0x6f688996e47f896351729088a8c2c0fcb7db6f40fd96eed42502e11c9962f744", "price_changes": [{"asset_id": "63575582870841942383427053084518597975654282758242000155173178759202148848429", "price": "0.153", "size": "40", "side": "BUY", "hash": "1f6528d60e96c05d0602d2781e3384fe47e9b376", "best_bid": "0.993", "best_ask": "1"}, {"asset_id": "1479722737131399761673297933236140450313179902349075711821861456880367927838", "price": "0.847", "size": "40", "side": "SELL", "hash": "bbcba00384affb9e11e452087789c1b008970435", "best_bid": "0", "best_ask": "0.007"}], "timestamp": "1769384082558", "event_type": "price_change"}}
{"_local_timestamp": "2026-01-25T23:34:42.642006+00:00", "data": {"market": "0xeaca7fad27f9e7602a07627a1dbb4b01352cd7ad99dd28b0ec09e26e6b12ccab", "price_changes": [{"asset_id": "76657535986059542453526409873946781453980750888541128603750398128471993423003", "price": "0.02", "size": "201.32", "side": "SELL", "hash": "37e553dcce8c924ea0ce96786f0cbf3d3b1494b6", "best_bid": "0.008", "best_ask": "0.02"}, {"asset_id": "106496774138546112027406613561717117026755108026255407086336415079048692630377", "price": "0.98", "size": "201.32", "side": "BUY", "hash": "fedffe57d2c9a0b4061b3bec9ca44f575fb1c721", "best_bid": "0.98", "best_ask": "0.992"}], "timestamp": "1769384082569", "event_type": "price_change"}}
{"_local_timestamp": "2026-01-25T23:34:44.621416+00:00", "data": {"market": "0xeaca7fad27f9e7602a07627a1dbb4b01352cd7ad99dd28b0ec09e26e6b12ccab", "price_changes": [{"asset_id": "106496774138546112027406613561717117026755108026255407086336415079048692630377", "price": "0.976", "size": "120", "side": "BUY", "hash": "a5f532a1ce03b05d612c54a0de007ed339401355", "best_bid": "0.98", "best_ask": "0.992"}, {"asset_id": "76657535986059542453526409873946781453980750888541128603750398128471993423003", "price": "0.024", "size": "120", "side": "SELL", "hash": "5d33b692193b4072f4afc9411e7a8f34081c6116", "best_bid": "0.008", "best_ask": "0.02"}], "timestamp": "1769384084545", "event_type": "price_change"}}
{"_local_timestamp": "2026-01-25T23:34:44.672853+00:00", "data": {"market": "0xeaca7fad27f9e7602a07627a1dbb4b01352cd7ad99dd28b0ec09e26e6b12ccab", "price_changes": [{"asset_id": "106496774138546112027406613561717117026755108026255407086336415079048692630377", "price": "0.981", "size": "30", "side": "BUY", "hash": "e16c39adce92e095ade2fcfffc1e3b63802815bb", "best_bid": "0.981", "best_ask": "0.992"}, {"asset_id": "76657535986059542453526409873946781453980750888541128603750398128471993423003", "price": "0.019", "size": "30", "side": "SELL", "hash": "da92d208c1c2ff7d22d40cae20df2d0717164d53", "best_bid": "0.008", "best_ask": "0.019"}], "timestamp": "1769384084603", "event_type": "price_change"}}
{"_local_timestamp": "2026-01-25T23:34:44.698694+00:00", "data": {"market": "0xeaca7fad27f9e7602a07627a1dbb4b01352cd7ad99dd28b0ec09e26e6b12ccab", "price_changes": [{"asset_id": "106496774138546112027406613561717117026755108026255407086336415079048692630377", "price": "0.103", "size": "0", "side": "BUY", "hash": "0ffafcbc311fa54a5ad0fbf8a087fed490142149", "best_bid": "0.981", "best_ask": "0.992"}, {"asset_id": "76657535986059542453526409873946781453980750888541128603750398128471993423003", "price": "0.897", "size": "0", "side": "SELL", "hash": "9153ff3ea7bf0ca3feb017801fd233dc3441f1fc", "best_bid": "0.008", "best_ask": "0.019"}], "timestamp": "1769384084625", "event_type": "price_change"}}
{"_local_timestamp": "2026-01-25T23:34:44.714606+00:00", "data": {"market": "0xeaca7fad27f9e7602a07627a1dbb4b01352cd7ad99dd28b0ec09e26e6b12ccab", "price_changes": [{"asset_id": "106496774138546112027406613561717117026755108026255407086336415079048692630377", "price": "0.18", "size": "100", "side": "BUY", "hash": "040659d9f7c89ec6d13844cdd8f8b0723ad950bd", "best_bid": "0.981", "best_ask": "0.992"}, {"asset_id": "76657535986059542453526409873946781453980750888541128603750398128471993423003", "price": "0.82", "size": "100", "side": "SELL", "hash": "f816828ed02edf44dde273875acac35be452391d", "best_bid": "0.008", "best_ask": "0.019"}], "timestamp": "1769384084647", "event_type": "price_change"}}
{"_local_timestamp": "2026-01-25T23:34:44.715062+00:00", "data": {"market": "0xeaca7fad27f9e7602a07627a1dbb4b01352cd7ad99dd28b0ec09e26e6b12ccab", "price_changes": [{"asset_id": "106496774138546112027406613561717117026755108026255407086336415079048692630377", "price": "0.18", "size": "50", "side": "BUY", "hash": "a2116af926b805fa9939ea75f9206789d30e07bf", "best_bid": "0.981", "best_ask": "0.992"}, {"asset_id": "76657535986059542453526409873946781453980750888541128603750398128471993423003", "price": "0.82", "size": "50", "side": "SELL", "hash": "d7735e01bbede630dd3b43ad13b3489b7242443c", "best_bid": "0.008", "best_ask": "0.019"}], "timestamp": "1769384084650", "event_type": "price_change"}}
{"_local_timestamp": "2026-01-25T23:34:44.722628+00:00", "data": {"market": "0xeaca7fad27f9e7602a07627a1dbb4b01352cd7ad99dd28b0ec09e26e6b12ccab", "price_changes": [{"asset_id": "106496774138546112027406613561717117026755108026255407086336415079048692630377", "price": "0.105", "size": "20", "side": "BUY", "hash": "4bf04c9c6cfe7f9be5b7a55b78e6790c04fe78ca", "best_bid": "0.981", "best_ask": "0.992"}, {"asset_id": "76657535986059542453526409873946781453980750888541128603750398128471993423003", "price": "0.895", "size": "20", "side": "SELL", "hash": "308620cd52a17c30beea469ea44c252204ed6720", "best_bid": "0.008", "best_ask": "0.019"}], "timestamp": "1769384084654", "event_type": "price_change"}}
{"_local_timestamp": "2026-01-25T23:34:44.729851+00:00", "data": {"market": "0xeaca7fad27f9e7602a07627a1dbb4b01352cd7ad99dd28b0ec09e26e6b12ccab", "price_changes": [{"asset_id": "106496774138546112027406613561717117026755108026255407086336415079048692630377", "price": "0.18", "size": "0", "side": "BUY", "hash": "272b73c879cc07b4be9c6b2462956bf1424ada15", "best_bid": "0.981", "best_ask": "0.992"}, {"asset_id": "76657535986059542453526409873946781453980750888541128603750398128471993423003", "price": "0.82", "size": "0", "side": "SELL", "hash": "4a7722d50406208482e57ce6421fc2b79dbe0fe9", "best_bid": "0.008", "best_ask": "0.019"}], "timestamp": "1769384084659", "event_type": "price_change"}}
{"_local_timestamp": "2026-01-25T23:34:49.132726+00:00", "data": {"market": "0xeaca7fad27f9e7602a07627a1dbb4b01352cd7ad99dd28b0ec09e26e6b12ccab", "price_changes": [{"asset_id": "106496774138546112027406613561717117026755108026255407086336415079048692630377", "price": "0.982", "size": "50", "side": "BUY", "hash": "1800788a4b05b53349c854efb04988ec8230b61c", "best_bid": "0.982", "best_ask": "0.992"}, {"asset_id": "76657535986059542453526409873946781453980750888541128603750398128471993423003", "price": "0.018", "size": "50", "side": "SELL", "hash": "cda28ca6718b5a1eb8ddf6d8982f6e61fa3a131a", "best_bid": "0.008", "best_ask": "0.018"}], "timestamp": "1769384089065", "event_type": "price_change"}}
{"_local_timestamp": "2026-01-25T23:34:49.729948+00:00", "data": {"market": "0xeaca7fad27f9e7602a07627a1dbb4b01352cd7ad99dd28b0ec09e26e6b12ccab", "price_changes": [{"asset_id": "106496774138546112027406613561717117026755108026255407086336415079048692630377", "price": "0.979", "size": "0", "side": "BUY", "hash": "d6dd3e901e30cd2c29a38dcc52464fbf3d77d744", "best_bid": "0.982", "best_ask": "0.992"}, {"asset_id": "76657535986059542453526409873946781453980750888541128603750398128471993423003", "price": "0.021", "size": "0", "side": "SELL", "hash": "ee6f21a42a4ec67578109c28f60cd915c3158e43", "best_bid": "0.008", "best_ask": "0.018"}], "timestamp": "1769384089592", "event_type": "price_change"}}
{"_local_timestamp": "2026-01-25T23:34:54.634872+00:00", "data": {"market": "0xbb7afda76b33e28e6beca651afcf4ba2c96316330038b37d565311aec7aa80fd", "price_changes": [{"asset_id": "55048873344980893604077431803703373331531589597253065240792528177019001889497", "price": "0.004", "size": "100", "side": "BUY", "hash": "c71318400ef232f721fa4eea1b592d0294ebc236", "best_bid": "0.042", "best_ask": "0.059"}, {"asset_id": "115380547880912465734621551138342931070381865195675981110314630607033301257937", "price": "0.996", "size": "100", "side": "SELL", "hash": "852f4f1016c13a6c50770ab51397ebea50b6edcf", "best_bid": "0.941", "best_ask": "0.958"}], "timestamp": "1769384094547", "event_type": "price_change"}}
{"_local_timestamp": "2026-01-25T23:34:54.993330+00:00", "data": {"market": "0xbb7afda76b33e28e6beca651afcf4ba2c96316330038b37d565311aec7aa80fd", "price_changes": [{"asset_id": "55048873344980893604077431803703373331531589597253065240792528177019001889497", "price": "0.003", "size": "306.67", "side": "BUY", "hash": "992596d5de6693ede1e77f4027a036f7c9268a09", "best_bid": "0.042", "best_ask": "0.059"}, {"asset_id": "115380547880912465734621551138342931070381865195675981110314630607033301257937", "price": "0.997", "size": "306.67", "side": "SELL", "hash": "3ef6b810e8ed0ff0037f48c047c5698ab4c2e991", "best_bid": "0.941", "best_ask": "0.958"}], "timestamp": "1769384094875", "event_type": "price_change"}}
{"_local_timestamp": "2026-01-25T23:35:03.297155+00:00", "data": {"market": "0xbb7afda76b33e28e6beca651afcf4ba2c96316330038b37d565311aec7aa80fd", "price_changes": [{"asset_id": "55048873344980893604077431803703373331531589597253065240792528177019001889497", "price": "0.042", "size": "95.26", "side": "BUY", "hash": "027b2241acd50599e8908ec546eea3d4d3e2529f", "best_bid": "0.042", "best_ask": "0.059"}, {"asset_id": "115380547880912465734621551138342931070381865195675981110314630607033301257937", "price": "0.958", "size": "95.26", "side": "SELL", "hash": "75a6907cb0024a72b9e537a07ae2051ba1ee8491", "best_bid": "0.941", "best_ask": "0.958"}], "timestamp": "1769384103222", "event_type": "price_change"}}
{"_local_timestamp": "2026-01-25T23:35:03.392432+00:00", "data": {"market": "0xbb7afda76b33e28e6beca651afcf4ba2c96316330038b37d565311aec7aa80fd", "price_changes": [{"asset_id": "55048873344980893604077431803703373331531589597253065240792528177019001889497", "price": "0.032", "size": "93", "side": "BUY", "hash": "2ca86b8d2312cd4ba4a93a32a8103b8c2be36b03", "best_bid": "0.042", "best_ask": "0.059"}, {"asset_id": "115380547880912465734621551138342931070381865195675981110314630607033301257937", "price": "0.968", "size": "93", "side": "SELL", "hash": "e24198dd460ea94e7ab5eacb90128f68c1d05e90", "best_bid": "0.941", "best_ask": "0.958"}], "timestamp": "1769384103312", "event_type": "price_change"}}
{"_local_timestamp": "2026-01-25T23:35:04.053738+00:00", "data": {"market": "0xbb7afda76b33e28e6beca651afcf4ba2c96316330038b37d565311aec7aa80fd", "price_changes": [{"asset_id": "55048873344980893604077431803703373331531589597253065240792528177019001889497", "price": "0.042", "size": "125.26", "side": "BUY", "hash": "74ff714539ee3ab269c368aca3482bd03ee9e5f2", "best_bid": "0.042", "best_ask": "0.059"}, {"asset_id": "115380547880912465734621551138342931070381865195675981110314630607033301257937", "price": "0.958", "size": "125.26", "side": "SELL", "hash": "7e5f5f6b008f8ddee7a4c399a2cdd99924475975", "best_bid": "0.941", "best_ask": "0.958"}], "timestamp": "1769384103977", "event_type": "price_change"}}
{"_local_timestamp": "2026-01-25T23:35:04.865757+00:00", "data": {"market": "0xeaca7fad27f9e7602a07627a1dbb4b01352cd7ad99dd28b0ec09e26e6b12ccab", "price_changes": [{"asset_id": "106496774138546112027406613561717117026755108026255407086336415079048692630377", "price": "0.974", "size": "68.56", "side": "BUY", "hash": "870e263891638dbc8ea420cb2b092e37d3f7f09f", "best_bid": "0.982", "best_ask": "0.992"}, {"asset_id": "76657535986059542453526409873946781453980750888541128603750398128471993423003", "price": "0.026", "size": "68.56", "side": "SELL", "hash": "e3a89fa430e10dd5bb87eee6fd77d5ce557aaa6a", "best_bid": "0.008", "best_ask": "0.018"}], "timestamp": "1769384104797", "event_type": "price_change"}}
{"_local_timestamp": "2026-01-25T23:35:14.131957+00:00", "data": {"market": "0x881092c53fd9b67bdf30869d756e13da558e8642ce13d104f73f648e005e9dbb", "price_changes": [{"asset_id": "106557923884483990512722312339562147481005985751920958827317376072063768641147", "price": "0.88", "size": "45", "side": "BUY", "hash": "b2a3d02072461e7fd64411d0b7c15762fc1c58aa", "best_bid": "0.938", "best_ask": "0.992"}, {"asset_id": "30209161280120374886078524432124760376829393809604890971368528789299616787016", "price": "0.12", "size": "45", "side": "SELL", "hash": "f7f60f53073d80199e5fdd5eb9c37adb299043be", "best_bid": "0.008", "best_ask": "0.062"}], "timestamp": "1769384114051", "event_type": "price_change"}}
{"_local_timestamp": "2026-01-25T23:35:15.546991+00:00", "data": {"market": "0xeaca7fad27f9e7602a07627a1dbb4b01352cd7ad99dd28b0ec09e26e6b12ccab", "price_changes": [{"asset_id": "106496774138546112027406613561717117026755108026255407086336415079048692630377", "price": "0.974", "size": "57.76", "side": "BUY", "hash": "c1dde7cc41d2f994b21fbad0eeef2d3a2d220e18", "best_bid": "0.982", "best_ask": "0.992"}, {"asset_id": "76657535986059542453526409873946781453980750888541128603750398128471993423003", "price": "0.026", "size": "57.76", "side": "SELL", "hash": "ab2220d53feffa2e22743b7145072335ef0890ab", "best_bid": "0.008", "best_ask": "0.018"}], "timestamp": "1769384115476", "event_type": "price_change"}}
{"_local_timestamp": "2026-01-25T23:35:20.201819+00:00", "data": {"market": "0x881092c53fd9b67bdf30869d756e13da558e8642ce13d104f73f648e005e9dbb", "price_changes": [{"asset_id": "106557923884483990512722312339562147481005985751920958827317376072063768641147", "price": "0.881", "size": "50", "side": "BUY", "hash": "93a18b521b3c430d05620ef19dce8be156c5d0c6", "best_bid": "0.938", "best_ask": "0.992"}, {"asset_id": "30209161280120374886078524432124760376829393809604890971368528789299616787016", "price": "0.119", "size": "50", "side": "SELL", "hash": "762ea8a2d86514fe593332e57d03a3953ea6a797", "best_bid": "0.008", "best_ask": "0.062"}], "timestamp": "1769384120123", "event_type": "price_change"}}
{"_local_timestamp": "2026-01-25T23:35:20.697898+00:00", "data": {"market": "0x881092c53fd9b67bdf30869d756e13da558e8642ce13d104f73f648e005e9dbb", "price_changes": [{"asset_id": "106557923884483990512722312339562147481005985751920958827317376072063768641147", "price": "0.879", "size": "6", "side": "BUY", "hash": "9420699daf4ce54525bad4a7fb221bd90687256a", "best_bid": "0.938", "best_ask": "0.992"}, {"asset_id": "30209161280120374886078524432124760376829393809604890971368528789299616787016", "price": "0.121", "size": "6", "side": "SELL", "hash": "1c2a51badf5cfc48c229002205be6d0d2b048dbf", "best_bid": "0.008", "best_ask": "0.062"}], "timestamp": "1769384120620", "event_type": "price_change"}}
{"_local_timestamp": "2026-01-25T23:35:23.970047+00:00", "data": {"market": "0xeaca7fad27f9e7602a07627a1dbb4b01352cd7ad99dd28b0ec09e26e6b12ccab", "price_changes": [{"asset_id": "106496774138546112027406613561717117026755108026255407086336415079048692630377", "price": "0.974", "size": "38.09", "side": "BUY", "hash": "f15056925f9c381874b953f9d7add11b1f5b5f5d", "best_bid": "0.982", "best_ask": "0.992"}, {"asset_id": "76657535986059542453526409873946781453980750888541128603750398128471993423003", "price": "0.026", "size": "38.09", "side": "SELL", "hash": "2d44f42e7d5653f1d54cdcb3d526cf58ed9d7106", "best_bid": "0.008", "best_ask": "0.018"}], "timestamp": "1769384123903", "event_type": "price_change"}}
{"_local_timestamp": "2026-01-25T23:35:27.204269+00:00", "data": {"market": "0xeaca7fad27f9e7602a07627a1dbb4b01352cd7ad99dd28b0ec09e26e6b12ccab", "price_changes": [{"asset_id": "106496774138546112027406613561717117026755108026255407086336415079048692630377", "price": "0.974", "size": "25.11", "side": "BUY", "hash": "a2927c854f915172cbc649cfec6da4c7823b2e05", "best_bid": "0.982", "best_ask": "0.992"}, {"asset_id": "76657535986059542453526409873946781453980750888541128603750398128471993423003", "price": "0.026", "size": "25.11", "side": "SELL", "hash": "fcacf1f8aade96b4d67da05c1cf27805d71ccf08", "best_bid": "0.008", "best_ask": "0.018"}], "timestamp": "1769384126948", "event_type": "price_change"}}
{"_local_timestamp": "2026-01-25T23:35:33.596677+00:00", "data": {"market": "0xbb7afda76b33e28e6beca651afcf4ba2c96316330038b37d565311aec7aa80fd", "price_changes": [{"asset_id": "55048873344980893604077431803703373331531589597253065240792528177019001889497", "price": "0.032", "size": "0", "side": "BUY", "hash": "3e5a1dd1fba9ddb08cc651ef4f0834b0f63ab9ce", "best_bid": "0.042", "best_ask": "0.059"}, {"asset_id": "115380547880912465734621551138342931070381865195675981110314630607033301257937", "price": "0.968", "size": "0", "side": "SELL", "hash": "5e0cb6512e6962c87c7e2a2b6ba0f7b111a8c7d5", "best_bid": "0.941", "best_ask": "0.958"}], "timestamp": "1769384133525", "event_type": "price_change"}}
{"_local_timestamp": "2026-01-25T23:35:33.680870+00:00", "data": {"market": "0xbb7afda76b33e28e6beca651afcf4ba2c96316330038b37d565311aec7aa80fd", "price_changes": [{"asset_id": "55048873344980893604077431803703373331531589597253065240792528177019001889497", "price": "0.042", "size": "196.26", "side": "BUY", "hash": "05e358249988eb93f5dc9e4a29ba864ba5b94ea2", "best_bid": "0.042", "best_ask": "0.059"}, {"asset_id": "115380547880912465734621551138342931070381865195675981110314630607033301257937", "price": "0.958", "size": "196.26", "side": "SELL", "hash": "2100e06cb868cb3dba5a6416f36755fd40008b0a", "best_bid": "0.941", "best_ask": "0.958"}], "timestamp": "1769384133609", "event_type": "price_change"}}
{"_local_timestamp": "2026-01-25T23:35:34.830089+00:00", "data": {"market": "0xbb7afda76b33e28e6beca651afcf4ba2c96316330038b37d565311aec7aa80fd", "price_changes": [{"asset_id": "55048873344980893604077431803703373331531589597253065240792528177019001889497", "price": "0.042", "size": "166.26", "side": "BUY", "hash": "f89ffdeafbf6a4fa759effa5fd74e0da81411930", "best_bid": "0.042", "best_ask": "0.059"}, {"asset_id": "115380547880912465734621551138342931070381865195675981110314630607033301257937", "price": "0.958", "size": "166.26", "side": "SELL", "hash": "5cb36c6fba4b38c5e6fb7db1d494e759cf3aeca3", "best_bid": "0.941", "best_ask": "0.958"}], "timestamp": "1769384134734", "event_type": "price_change"}}
{"_local_timestamp": "2026-01-25T23:35:36.787456+00:00", "data": {"market": "0xeaca7fad27f9e7602a07627a1dbb4b01352cd7ad99dd28b0ec09e26e6b12ccab", "price_changes": [{"asset_id": "106496774138546112027406613561717117026755108026255407086336415079048692630377", "price": "0.974", "size": "0", "side": "BUY", "hash": "cac4cea4539d532a008e7e172ccd20ad7cf6185c", "best_bid": "0.982", "best_ask": "0.992"}, {"asset_id": "76657535986059542453526409873946781453980750888541128603750398128471993423003", "price": "0.026", "size": "0", "side": "SELL", "hash": "8e7acf9e67afa3d6119d0669db7485ee2aac6d22", "best_bid": "0.008", "best_ask": "0.018"}], "timestamp": "1769384136723", "event_type": "price_change"}}
{"_local_timestamp": "2026-01-25T23:36:03.895497+00:00", "data": {"market": "0xbb7afda76b33e28e6beca651afcf4ba2c96316330038b37d565311aec7aa80fd", "price_changes": [{"asset_id": "55048873344980893604077431803703373331531589597253065240792528177019001889497", "price": "0.042", "size": "95.26", "side": "BUY", "hash": "a9823ba7994ec949561a4af145fede3f1e7e40cb", "best_bid": "0.042", "best_ask": "0.059"}, {"asset_id": "115380547880912465734621551138342931070381865195675981110314630607033301257937", "price": "0.958", "size": "95.26", "side": "SELL", "hash": "7e4e84af2ad8647d0de2dd856e340d69d37f29cd", "best_bid": "0.941", "best_ask": "0.958"}], "timestamp": "1769384163822", "event_type": "price_change"}}
{"_local_timestamp": "2026-01-25T23:36:03.977201+00:00", "data": {"market": "0xbb7afda76b33e28e6beca651afcf4ba2c96316330038b37d565311aec7aa80fd", "price_changes": [{"asset_id": "55048873344980893604077431803703373331531589597253065240792528177019001889497", "price": "0.032", "size": "93", "side": "BUY", "hash": "8f8b4c115cee3d4733bc0bd0767481f2e3df10b0", "best_bid": "0.042", "best_ask": "0.059"}, {"asset_id": "115380547880912465734621551138342931070381865195675981110314630607033301257937", "price": "0.968", "size": "93", "side": "SELL", "hash": "107094d1c743acdf35d15c401c24bf53f7ea9acb", "best_bid": "0.941", "best_ask": "0.958"}], "timestamp": "1769384163908", "event_type": "price_change"}}
{"_local_timestamp": "2026-01-25T23:36:04.112184+00:00", "data": {"market": "0xbb7afda76b33e28e6beca651afcf4ba2c96316330038b37d565311aec7aa80fd", "price_changes": [{"asset_id": "55048873344980893604077431803703373331531589597253065240792528177019001889497", "price": "0.042", "size": "125.26", "side": "BUY", "hash": "ade54ed6c925a090f0cf5857c44eab6de53dd424", "best_bid": "0.042", "best_ask": "0.059"}, {"asset_id": "115380547880912465734621551138342931070381865195675981110314630607033301257937", "price": "0.958", "size": "125.26", "side": "SELL", "hash": "8dc63fcd9fd32270046dda5fcb36a2af28046922", "best_bid": "0.941", "best_ask": "0.958"}], "timestamp": "1769384164017", "event_type": "price_change"}}
{"_local_timestamp": "2026-01-25T23:36:05.344778+00:00", "data": {"market": "0xf4cbee770d93e6be7c0eeef5fd8d143bf7b6cd05462745a0847aab51b993d406", "price_changes": [{"asset_id": "79935592053032469030142243551293799152704805799593114805455402419474295196734", "price": "0.005", "size": "239.99", "side": "BUY", "hash": "02b311498376aac0e67f0a700eb31f95c2ceee6a", "best_bid": "0.005", "best_ask": "0.021"}, {"asset_id": "75482995474170622849957659966226987317064035398856989789719351907123461611518", "price": "0.995", "size": "239.99", "side": "SELL", "hash": "b5df3a750c62a521f1683224384e7d41c62ca2fd", "best_bid": "0.979", "best_ask": "0.995"}], "timestamp": "1769384165267", "event_type": "price_change"}}
{"_local_timestamp": "2026-01-25T23:36:06.266717+00:00", "data": {"market": "0x881092c53fd9b67bdf30869d756e13da558e8642ce13d104f73f648e005e9dbb", "price_changes": [{"asset_id": "106557923884483990512722312339562147481005985751920958827317376072063768641147", "price": "0.144", "size": "40", "side": "BUY", "hash": "6b8ece6b2a9aed2afe39e1a76c3c8a87496dc2a2", "best_bid": "0.938", "best_ask": "0.992"}, {"asset_id": "30209161280120374886078524432124760376829393809604890971368528789299616787016", "price": "0.856", "size": "40", "side": "SELL", "hash": "fba6ab3e67fef1348ee36a4dba1a675909c901ff", "best_bid": "0.008", "best_ask": "0.062"}], "timestamp": "1769384166200", "event_type": "price_change"}}
{"_local_timestamp": "2026-01-25T23:36:06.267191+00:00", "data": {"market": "0xbb7afda76b33e28e6beca651afcf4ba2c96316330038b37d565311aec7aa80fd", "price_changes": [{"asset_id": "115380547880912465734621551138342931070381865195675981110314630607033301257937", "price": "0.11", "size": "40", "side": "BUY", "hash": "844aaee2d2074f851208671260f4fa6f770c4ac5", "best_bid": "0.941", "best_ask": "0.958"}, {"asset_id": "55048873344980893604077431803703373331531589597253065240792528177019001889497", "price": "0.89", "size": "40", "side": "SELL", "hash": "b69ba8505c3f54f0401c9ebb44b6439723464007", "best_bid": "0.042", "best_ask": "0.059"}], "timestamp": "1769384166200", "event_type": "price_change"}}
{"_local_timestamp": "2026-01-25T23:36:06.303098+00:00", "data": {"market": "0x881092c53fd9b67bdf30869d756e13da558e8642ce13d104f73f648e005e9dbb", "price_changes": [{"asset_id": "106557923884483990512722312339562147481005985751920958827317376072063768641147", "price": "0.145", "size": "20", "side": "BUY", "hash": "a02796bbb7956c5f28ed0cd179ed1ed1473a9ad8", "best_bid": "0.938", "best_ask": "0.992"}, {"asset_id": "30209161280120374886078524432124760376829393809604890971368528789299616787016", "price": "0.855", "size": "20", "side": "SELL", "hash": "af474376543ba63f3e6e37ab428351c36b299d2b", "best_bid": "0.008", "best_ask": "0.062"}], "timestamp": "1769384166236", "event_type": "price_change"}}
{"_local_timestamp": "2026-01-25T23:36:06.303572+00:00", "data": {"market": "0xbb7afda76b33e28e6beca651afcf4ba2c96316330038b37d565311aec7aa80fd", "price_changes": [{"asset_id": "115380547880912465734621551138342931070381865195675981110314630607033301257937", "price": "0.111", "size": "20", "side": "BUY", "hash": "aff42de52436676c2d1ff8fdd4c7dab7b0346c03", "best_bid": "0.941", "best_ask": "0.958"}, {"asset_id": "55048873344980893604077431803703373331531589597253065240792528177019001889497", "price": "0.889", "size": "20", "side": "SELL", "hash": "2bc58d70875fe5312ad22bdc86da1a060159a5a0", "best_bid": "0.042", "best_ask": "0.059"}], "timestamp": "1769384166236", "event_type": "price_change"}}
{"_local_timestamp": "2026-01-25T23:36:14.210681+00:00", "data": {"market": "0xeaca7fad27f9e7602a07627a1dbb4b01352cd7ad99dd28b0ec09e26e6b12ccab", "price_changes": [{"asset_id": "76657535986059542453526409873946781453980750888541128603750398128471993423003", "price": "0.02", "size": "0", "side": "SELL", "hash": "987f5c3ba72ee92120aa070fc5150098b0be82b2", "best_bid": "0.008", "best_ask": "0.018"}, {"asset_id": "106496774138546112027406613561717117026755108026255407086336415079048692630377", "price": "0.98", "size": "0", "side": "BUY", "hash": "a048da19801f93ab8fadb916933ce15232ee93c2", "best_bid": "0.982", "best_ask": "0.992"}], "timestamp": "1769384174133", "event_type": "price_change"}}
{"_local_timestamp": "2026-01-25T23:36:14.471196+00:00", "data": {"market": "0xeaca7fad27f9e7602a07627a1dbb4b01352cd7ad99dd28b0ec09e26e6b12ccab", "price_changes": [{"asset_id": "106496774138546112027406613561717117026755108026255407086336415079048692630377", "price": "0.981", "size": "0", "side": "BUY", "hash": "86e75811447b373895342303ae40598f782922d1", "best_bid": "0.982", "best_ask": "0.992"}, {"asset_id": "76657535986059542453526409873946781453980750888541128603750398128471993423003", "price": "0.019", "size": "0", "side": "SELL", "hash": "531b38ccbf0c51a2df6da03c5ee4785ab8f63795", "best_bid": "0.008", "best_ask": "0.018"}], "timestamp": "1769384174393", "event_type": "price_change"}}
{"_local_timestamp": "2026-01-25T23:36:14.532213+00:00", "data": {"market": "0xeaca7fad27f9e7602a07627a1dbb4b01352cd7ad99dd28b0ec09e26e6b12ccab", "price_changes": [{"asset_id": "106496774138546112027406613561717117026755108026255407086336415079048692630377", "price": "0.976", "size": "150", "side": "BUY", "hash": "3297975e43aea8e141ac2db15f21edb7428af512", "best_bid": "0.982", "best_ask": "0.992"}, {"asset_id": "76657535986059542453526409873946781453980750888541128603750398128471993423003", "price": "0.024", "size": "150", "side": "SELL", "hash": "2e3bdde1ce9982d76be97b5c19d9284ced10fa09", "best_bid": "0.008", "best_ask": "0.018"}], "timestamp": "1769384174464", "event_type": "price_change"}}
{"_local_timestamp": "2026-01-25T23:36:15.304172+00:00", "data": {"market": "0xeaca7fad27f9e7602a07627a1dbb4b01352cd7ad99dd28b0ec09e26e6b12ccab", "price_changes": [{"asset_id": "76657535986059542453526409873946781453980750888541128603750398128471993423003", "price": "0.017", "size": "201.32", "side": "SELL", "hash": "3d3f4ec12c727873e321ea6925f527dafe81d6ed", "best_bid": "0.008", "best_ask": "0.017"}, {"asset_id": "106496774138546112027406613561717117026755108026255407086336415079048692630377", "price": "0.983", "size": "201.32", "side": "BUY", "hash": "fc3b27532cf3439a40b27d0f10ade8fecd1b2123", "best_bid": "0.983", "best_ask": "0.992"}], "timestamp": "1769384175234", "event_type": "price_change"}}
{"_local_timestamp": "2026-01-25T23:36:16.331287+00:00", "data": {"market": "0xeaca7fad27f9e7602a07627a1dbb4b01352cd7ad99dd28b0ec09e26e6b12ccab", "price_changes": [{"asset_id": "106496774138546112027406613561717117026755108026255407086336415079048692630377", "price": "0.976", "size": "120", "side": "BUY", "hash": "94aa584d19efbe2b7a9ab7b849e7a03b1cfe6742", "best_bid": "0.983", "best_ask": "0.992"}, {"asset_id": "76657535986059542453526409873946781453980750888541128603750398128471993423003", "price": "0.024", "size": "120", "side": "SELL", "hash": "59db819bf5f1ca0da09c712c34635a38d8004212", "best_bid": "0.008", "best_ask": "0.017"}], "timestamp": "1769384176263", "event_type": "price_change"}}
{"_local_timestamp": "2026-01-25T23:36:20.569922+00:00", "data": {"market": "0xf4cbee770d93e6be7c0eeef5fd8d143bf7b6cd05462745a0847aab51b993d406", "price_changes": [{"asset_id": "79935592053032469030142243551293799152704805799593114805455402419474295196734", "price": "0.001", "size": "5460", "side": "BUY", "hash": "146a2f57bab0e3ee916b41d54e546fbf648a7806", "best_bid": "0.005", "best_ask": "0.021"}, {"asset_id": "75482995474170622849957659966226987317064035398856989789719351907123461611518", "price": "0.999", "size": "5460", "side": "SELL", "hash": "203670a2cc261bd0696f359bf51033fc16cf70b5", "best_bid": "0.979", "best_ask": "0.995"}], "timestamp": "1769384180507", "event_type": "price_change"}}
{"_local_timestamp": "2026-01-25T23:36:20.658012+00:00", "data": {"market": "0xf4cbee770d93e6be7c0eeef5fd8d143bf7b6cd05462745a0847aab51b993d406", "price_changes": [{"asset_id": "79935592053032469030142243551293799152704805799593114805455402419474295196734", "price": "0.002", "size": "1500", "side": "BUY", "hash": "8b5c050b1e481c657539c6e9910e5762e53fee0f", "best_bid": "0.005", "best_ask": "0.021"}, {"asset_id": "75482995474170622849957659966226987317064035398856989789719351907123461611518", "price": "0.998", "size": "1500", "side": "SELL", "hash": "afe5c7536a7d9e35888c2ea6d4475b6c762746c9", "best_bid": "0.979", "best_ask": "0.995"}], "timestamp": "1769384180592", "event_type": "price_change"}}
{"_local_timestamp": "2026-01-25T23:36:21.243715+00:00", "data": {"market": "0xeaca7fad27f9e7602a07627a1dbb4b01352cd7ad99dd28b0ec09e26e6b12ccab", "price_changes": [{"asset_id": "106496774138546112027406613561717117026755108026255407086336415079048692630377", "price": "0.982", "size": "0", "side": "BUY", "hash": "127d41a11ccf5e4f395ac204da8d7fda746d91b8", "best_bid": "0.983", "best_ask": "0.992"}, {"asset_id": "76657535986059542453526409873946781453980750888541128603750398128471993423003", "price": "0.018", "size": "0", "side": "SELL", "hash": "ac9cd806ab504fbe22b547b7dc415e73b83d6905", "best_bid": "0.008", "best_ask": "0.017"}], "timestamp": "1769384181175", "event_type": "price_change"}}
{"_local_timestamp": "2026-01-25T23:36:34.272480+00:00", "data": {"market": "0xbb7afda76b33e28e6beca651afcf4ba2c96316330038b37d565311aec7aa80fd", "price_changes": [{"asset_id": "55048873344980893604077431803703373331531589597253065240792528177019001889497", "price": "0.032", "size": "0", "side": "BUY", "hash": "3b907b822f8fd286a226975bff26337e54a8afe9", "best_bid": "0.042", "best_ask": "0.059"}, {"asset_id": "115380547880912465734621551138342931070381865195675981110314630607033301257937", "price": "0.968", "size": "0", "side": "SELL", "hash": "86808b400ba77364ff3d82001e323ca97cade1f7", "best_bid": "0.941", "best_ask": "0.958"}], "timestamp": "1769384194174", "event_type": "price_change"}}
{"_local_timestamp": "2026-01-25T23:36:34.327726+00:00", "data": {"market": "0xbb7afda76b33e28e6beca651afcf4ba2c96316330038b37d565311aec7aa80fd", "price_changes": [{"asset_id": "55048873344980893604077431803703373331531589597253065240792528177019001889497", "price": "0.042", "size": "196.26", "side": "BUY", "hash": "965ffc18ada9b170ebe874ae27bd915e4349d034", "best_bid": "0.042", "best_ask": "0.059"}, {"asset_id": "115380547880912465734621551138342931070381865195675981110314630607033301257937", "price": "0.958", "size": "196.26", "side": "SELL", "hash": "ef9b8eb319be4fa8928560ca4958f8026bdfa97b", "best_bid": "0.941", "best_ask": "0.958"}], "timestamp": "1769384194256", "event_type": "price_change"}}
{"_local_timestamp": "2026-01-25T23:36:34.992809+00:00", "data": {"market": "0x881092c53fd9b67bdf30869d756e13da558e8642ce13d104f73f648e005e9dbb", "price_changes": [{"asset_id": "106557923884483990512722312339562147481005985751920958827317376072063768641147", "price": "0.66", "size": "0", "side": "BUY", "hash": "5c89c2566bd6c84820ec9f277acea019340797d5", "best_bid": "0.938", "best_ask": "0.992"}, {"asset_id": "30209161280120374886078524432124760376829393809604890971368528789299616787016", "price": "0.34", "size": "0", "side": "SELL", "hash": "99a07140182ef2fa874c1b48d5c0c008f363d5d4", "best_bid": "0.008", "best_ask": "0.062"}], "timestamp": "1769384194922", "event_type": "price_change"}}
{"_local_timestamp": "2026-01-25T23:36:34.993533+00:00", "data": {"market": "0x881092c53fd9b67bdf30869d756e13da558e8642ce13d104f73f648e005e9dbb", "price_changes": [{"asset_id": "106557923884483990512722312339562147481005985751920958827317376072063768641147", "price": "0.382", "size": "75", "side": "BUY", "hash": "5c89c2566bd6c84820ec9f277acea019340797d5", "best_bid": "0.938", "best_ask": "0.992"}, {"asset_id": "30209161280120374886078524432124760376829393809604890971368528789299616787016", "price": "0.618", "size": "75", "side": "SELL", "hash": "99a07140182ef2fa874c1b48d5c0c008f363d5d4", "best_bid": "0.008", "best_ask": "0.062"}], "timestamp": "1769384194922", "event_type": "price_change"}}
{"_local_timestamp": "2026-01-25T23:36:35.961878+00:00", "data": {"market": "0x881092c53fd9b67bdf30869d756e13da558e8642ce13d104f73f648e005e9dbb", "price_changes": [{"asset_id": "106557923884483990512722312339562147481005985751920958827317376072063768641147", "price": "0.87", "size": "100", "side": "BUY", "hash": "1eae85a6aadab7e3846869f3fd53abb3f98e5224", "best_bid": "0.938", "best_ask": "0.992"}, {"asset_id": "30209161280120374886078524432124760376829393809604890971368528789299616787016", "price": "0.13", "size": "100", "side": "SELL", "hash": "9d307605da42f35f615a7573e4760dd6f3e01d1b", "best_bid": "0.008", "best_ask": "0.062"}], "timestamp": "1769384195891", "event_type": "price_change"}}
{"_local_timestamp": "2026-01-25T23:36:36.117009+00:00", "data": {"market": "0x881092c53fd9b67bdf30869d756e13da558e8642ce13d104f73f648e005e9dbb", "price_changes": [{"asset_id": "106557923884483990512722312339562147481005985751920958827317376072063768641147", "price": "0.803", "size": "195", "side": "BUY", "hash": "12ca89a418d8e0597d588450119a77a1425c1919", "best_bid": "0.938", "best_ask": "0.992"}, {"asset_id": "30209161280120374886078524432124760376829393809604890971368528789299616787016", "price": "0.197", "size": "195", "side": "SELL", "hash": "004435f5e8c5d7b42046f9d0ba9ece086a06ab86", "best_bid": "0.008", "best_ask": "0.062"}], "timestamp": "1769384196015", "event_type": "price_change"}}
{"_local_timestamp": "2026-01-25T23:36:36.122177+00:00", "data": {"market": "0xeaca7fad27f9e7602a07627a1dbb4b01352cd7ad99dd28b0ec09e26e6b12ccab", "price_changes": [{"asset_id": "106496774138546112027406613561717117026755108026255407086336415079048692630377", "price": "0.927", "size": "100", "side": "BUY", "hash": "6b0c068361827ab48cda23ac35b000085486eae8", "best_bid": "0.983", "best_ask": "0.992"}, {"asset_id": "76657535986059542453526409873946781453980750888541128603750398128471993423003", "price": "0.073", "size": "100", "side": "SELL", "hash": "ab1c79633a3a0b42c0c07c30a7e5e876757c227f", "best_bid": "0.008", "best_ask": "0.017"}], "timestamp": "1769384196020", "event_type": "price_change"}}
{"_local_timestamp": "2026-01-25T23:36:36.123780+00:00", "data": {"market": "0xeaca7fad27f9e7602a07627a1dbb4b01352cd7ad99dd28b0ec09e26e6b12ccab", "price_changes": [{"asset_id": "106496774138546112027406613561717117026755108026255407086336415079048692630377", "price": "0.955", "size": "100", "side": "BUY", "hash": "404c67425dafbac3e1a143dbb3775b6832c6fb54", "best_bid": "0.983", "best_ask": "0.992"}, {"asset_id": "76657535986059542453526409873946781453980750888541128603750398128471993423003", "price": "0.045", "size": "100", "side": "SELL", "hash": "8735a0c753e1836ab3a247c0b36d05ffc1cc9d3a", "best_bid": "0.008", "best_ask": "0.017"}], "timestamp": "1769384196033", "event_type": "price_change"}}
{"_local_timestamp": "2026-01-25T23:36:36.167176+00:00", "data": {"market": "0x0e80cd8709ff87e5e8f640f04d56459b6b17f8725dfc45aa41638e864bdd516f", "price_changes": [{"asset_id": "31948734631736561994125221293320704077897312273398644786977701161539360085435", "price": "0.021", "size": "0", "side": "BUY", "hash": "ddca50e1d61a4aa9b44b5105e16ab30257e68a4b", "best_bid": "0.857", "best_ask": "0.866"}, {"asset_id": "64190946651851680406639375409936731829956855105844271954263113555549757553710", "price": "0.979", "size": "0", "side": "SELL", "hash": "6d471496c98c5d414ec200e58a49f2c89cdbec89", "best_bid": "0.134", "best_ask": "0.143"}], "timestamp": "1769384196092", "event_type": "price_change"}}
{"_local_timestamp": "2026-01-25T23:36:36.220067+00:00", "data": {"market": "0x0e80cd8709ff87e5e8f640f04d56459b6b17f8725dfc45aa41638e864bdd516f", "price_changes": [{"asset_id": "31948734631736561994125221293320704077897312273398644786977701161539360085435", "price": "0.023", "size": "30", "side": "BUY", "hash": "769971815a4fbc49c09d2aa803e13abdd24ac5a3", "best_bid": "0.857", "best_ask": "0.866"}, {"asset_id": "64190946651851680406639375409936731829956855105844271954263113555549757553710", "price": "0.977", "size": "30", "side": "SELL", "hash": "28d135b02c3108ced34fbcd984386bae8ca28930", "best_bid": "0.134", "best_ask": "0.143"}], "timestamp": "1769384196152", "event_type": "price_change"}}
{"_local_timestamp": "2026-01-25T23:36:36.242697+00:00", "data": {"market": "0xbb7afda76b33e28e6beca651afcf4ba2c96316330038b37d565311aec7aa80fd", "price_changes": [{"asset_id": "55048873344980893604077431803703373331531589597253065240792528177019001889497", "price": "0.042", "size": "166.26", "side": "BUY", "hash": "9691adbdaa1afba5b1817b01f4839a5b36d94e87", "best_bid": "0.042", "best_ask": "0.059"}, {"asset_id": "115380547880912465734621551138342931070381865195675981110314630607033301257937", "price": "0.958", "size": "166.26", "side": "SELL", "hash": "a805c6ee05285f4cad88db18f33321046a572441", "best_bid": "0.941", "best_ask": "0.958"}], "timestamp": "1769384196171", "event_type": "price_change"}}
{"_local_timestamp": "2026-01-25T23:36:55.008654+00:00", "data": {"market": "0xbb7afda76b33e28e6beca651afcf4ba2c96316330038b37d565311aec7aa80fd", "price_changes": [{"asset_id": "115380547880912465734621551138342931070381865195675981110314630607033301257937", "price": "0.02", "size": "2000", "side": "BUY", "hash": "f550b3950b5f6c3e72812867baa7ff1c4eb7015a", "best_bid": "0.941", "best_ask": "0.958"}, {"asset_id": "55048873344980893604077431803703373331531589597253065240792528177019001889497", "price": "0.98", "size": "2000", "side": "SELL", "hash": "db14aaf02ce69f71d623e3d94f2978459b6bf70f", "best_bid": "0.042", "best_ask": "0.059"}], "timestamp": "1769384214933", "event_type": "price_change"}}
{"_local_timestamp": "2026-01-25T23:36:55.806873+00:00", "data": {"market": "0xbb7afda76b33e28e6beca651afcf4ba2c96316330038b37d565311aec7aa80fd", "price_changes": [{"asset_id": "115380547880912465734621551138342931070381865195675981110314630607033301257937", "price": "0.1", "size": "860", "side": "BUY", "hash": "1a008fe5ec9acd9ccb0611a80472c0cdf1a9bcfc", "best_bid": "0.941", "best_ask": "0.958"}, {"asset_id": "55048873344980893604077431803703373331531589597253065240792528177019001889497", "price": "0.9", "size": "860", "side": "SELL", "hash": "82d0305d709d797972939e875648e0bdba1f6331", "best_bid": "0.042", "best_ask": "0.059"}], "timestamp": "1769384215618", "event_type": "price_change"}}
{"_local_timestamp": "2026-01-25T23:36:58.246295+00:00", "data": {"market": "0xf4cbee770d93e6be7c0eeef5fd8d143bf7b6cd05462745a0847aab51b993d406", "price_changes": [{"asset_id": "79935592053032469030142243551293799152704805799593114805455402419474295196734", "price": "0.004", "size": "0", "side": "BUY", "hash": "5ad5c7a15ea589c837430feea06ef4e9a386b001", "best_bid": "0.005", "best_ask": "0.021"}, {"asset_id": "75482995474170622849957659966226987317064035398856989789719351907123461611518", "price": "0.996", "size": "0", "side": "SELL", "hash": "dc97b8da2967f097829b70ddb51d8cdb700fbf71", "best_bid": "0.979", "best_ask": "0.995"}], "timestamp": "1769384218088", "event_type": "price_change"}}
{"_local_timestamp": "2026-01-25T23:36:58.524693+00:00", "data": {"market": "0xeaca7fad27f9e7602a07627a1dbb4b01352cd7ad99dd28b0ec09e26e6b12ccab", "price_changes": [{"asset_id": "76657535986059542453526409873946781453980750888541128603750398128471993423003", "price": "0.003", "size": "350", "side": "BUY", "hash": "a63699713ba828f6690a9f6a120ff1e9efe933f3", "best_bid": "0.008", "best_ask": "0.017"}, {"asset_id": "106496774138546112027406613561717117026755108026255407086336415079048692630377", "price": "0.997", "size": "350", "side": "SELL", "hash": "e1500c7859630a4d926165d00f727327c1914cff", "best_bid": "0.983", "best_ask": "0.992"}], "timestamp": "1769384218453", "event_type": "price_change"}}
{"_local_timestamp": "2026-01-25T23:36:58.525267+00:00", "data": {"market": "0xbb7afda76b33e28e6beca651afcf4ba2c96316330038b37d565311aec7aa80fd", "price_changes": [{"asset_id": "55048873344980893604077431803703373331531589597253065240792528177019001889497", "price": "0.002", "size": "414", "side": "BUY", "hash": "6301b30a0045703e761256495c361bc569b256bb", "best_bid": "0.042", "best_ask": "0.059"}, {"asset_id": "115380547880912465734621551138342931070381865195675981110314630607033301257937", "price": "0.998", "size": "414", "side": "SELL", "hash": "c6cbd33a2cfbe367280cd862b1424c316311b6d1", "best_bid": "0.941", "best_ask": "0.958"}], "timestamp": "1769384218453", "event_type": "price_change"}}
{"_local_timestamp": "2026-01-25T23:36:58.525722+00:00", "data": {"market": "0xf4cbee770d93e6be7c0eeef5fd8d143bf7b6cd05462745a0847aab51b993d406", "price_changes": [{"asset_id": "79935592053032469030142243551293799152704805799593114805455402419474295196734", "price": "0.002", "size": "1600", "side": "BUY", "hash": "f13131bc37404a836bf3a65964030336561c5c5f", "best_bid": "0.005", "best_ask": "0.021"}, {"asset_id": "75482995474170622849957659966226987317064035398856989789719351907123461611518", "price": "0.998", "size": "1600", "side": "SELL", "hash": "fa0de9489fdbc0b5f066b0a1dc2bf6cf3a6cb8cd", "best_bid": "0.979", "best_ask": "0.995"}], "timestamp": "1769384218453", "event_type": "price_change"}}
{"_local_timestamp": "2026-01-25T23:37:04.568563+00:00", "data": {"market": "0xbb7afda76b33e28e6beca651afcf4ba2c96316330038b37d565311aec7aa80fd", "price_changes": [{"asset_id": "55048873344980893604077431803703373331531589597253065240792528177019001889497", "price": "0.042", "size": "95.26", "side": "BUY", "hash": "cd1b61c9895d5624c124da6733b92773b0cd5648", "best_bid": "0.042", "best_ask": "0.059"}, {"asset_id": "115380547880912465734621551138342931070381865195675981110314630607033301257937", "price": "0.958", "size": "95.26", "side": "SELL", "hash": "edda2c720462a7dfc72d349e6a51c029d66fab3f", "best_bid": "0.941", "best_ask": "0.958"}], "timestamp": "1769384224501", "event_type": "price_change"}}
{"_local_timestamp": "2026-01-25T23:37:04.654876+00:00", "data": {"market": "0xbb7afda76b33e28e6beca651afcf4ba2c96316330038b37d565311aec7aa80fd", "price_changes": [{"asset_id": "55048873344980893604077431803703373331531589597253065240792528177019001889497", "price": "0.032", "size": "93", "side": "BUY", "hash": "2948ff5a0585d92f58f9b3a0e36c530797b4a5c9", "best_bid": "0.042", "best_ask": "0.059"}, {"asset_id": "115380547880912465734621551138342931070381865195675981110314630607033301257937", "price": "0.968", "size": "93", "side": "SELL", "hash": "789801f79cec0425ae17d4cca0547caa36f225ce", "best_bid": "0.941", "best_ask": "0.958"}], "timestamp": "1769384224585", "event_type": "price_change"}}
{"_local_timestamp": "2026-01-25T23:37:04.722302+00:00", "data": {"market": "0xbb7afda76b33e28e6beca651afcf4ba2c96316330038b37d565311aec7aa80fd", "price_changes": [{"asset_id": "55048873344980893604077431803703373331531589597253065240792528177019001889497", "price": "0.042", "size": "125.26", "side": "BUY", "hash": "676eeab40618a36d3753a17777ea31ac0d52631e", "best_bid": "0.042", "best_ask": "0.059"}, {"asset_id": "115380547880912465734621551138342931070381865195675981110314630607033301257937", "price": "0.958", "size": "125.26", "side": "SELL", "hash": "3aa5a0d0831c66e2e96a3df4d0023e267808a328", "best_bid": "0.941", "best_ask": "0.958"}], "timestamp": "1769384224659", "event_type": "price_change"}}
{"_local_timestamp": "2026-01-25T23:37:12.378311+00:00", "data": {"market": "0xf4cbee770d93e6be7c0eeef5fd8d143bf7b6cd05462745a0847aab51b993d406", "price_changes": [{"asset_id": "79935592053032469030142243551293799152704805799593114805455402419474295196734", "price": "0.005", "size": "387.99", "side": "BUY", "hash": "ffa7444464d791b30e6c2f35d1493b88019263ad", "best_bid": "0.005", "best_ask": "0.021"}, {"asset_id": "75482995474170622849957659966226987317064035398856989789719351907123461611518", "price": "0.995", "size": "387.99", "side": "SELL", "hash": "a84b4fb955e3ef43eef4000d8d1fba63861e82e7", "best_bid": "0.979", "best_ask": "0.995"}], "timestamp": "1769384232313", "event_type": "price_change"}}
{"_local_timestamp": "2026-01-25T23:37:34.856917+00:00", "data": {"market": "0xbb7afda76b33e28e6beca651afcf4ba2c96316330038b37d565311aec7aa80fd", "price_changes": [{"asset_id": "55048873344980893604077431803703373331531589597253065240792528177019001889497", "price": "0.032", "size": "0", "side": "BUY", "hash": "f7cda8c440967c62fc5bb2c2977b88a9d27ac9ec", "best_bid": "0.042", "best_ask": "0.059"}, {"asset_id": "115380547880912465734621551138342931070381865195675981110314630607033301257937", "price": "0.968", "size": "0", "side": "SELL", "hash": "82c7da38f61b66c660866a2ce223839a3ba0bc9e", "best_bid": "0.941", "best_ask": "0.958"}], "timestamp": "1769384254791", "event_type": "price_change"}}
{"_local_timestamp": "2026-01-25T23:37:34.947004+00:00", "data": {"market": "0xbb7afda76b33e28e6beca651afcf4ba2c96316330038b37d565311aec7aa80fd", "price_changes": [{"asset_id": "55048873344980893604077431803703373331531589597253065240792528177019001889497", "price": "0.042", "size": "196.26", "side": "BUY", "hash": "f2b91ebf2bd2eac1a64b55da11be0c770e75d657", "best_bid": "0.042", "best_ask": "0.059"}, {"asset_id": "115380547880912465734621551138342931070381865195675981110314630607033301257937", "price": "0.958", "size": "196.26", "side": "SELL", "hash": "d89d62b9db8af4e7177ac36a00a30564eafb4884", "best_bid": "0.941", "best_ask": "0.958"}], "timestamp": "1769384254884", "event_type": "price_change"}}
{"_local_timestamp": "2026-01-25T23:37:36.156943+00:00", "data": {"market": "0xbb7afda76b33e28e6beca651afcf4ba2c96316330038b37d565311aec7aa80fd", "price_changes": [{"asset_id": "55048873344980893604077431803703373331531589597253065240792528177019001889497", "price": "0.042", "size": "166.26", "side": "BUY", "hash": "8d4f03db860445d042099e017deb946de813c49d", "best_bid": "0.042", "best_ask": "0.059"}, {"asset_id": "115380547880912465734621551138342931070381865195675981110314630607033301257937", "price": "0.958", "size": "166.26", "side": "SELL", "hash": "7ef18c72ea53608b1a602acfcd92bbd89e190690", "best_bid": "0.941", "best_ask": "0.958"}], "timestamp": "1769384256079", "event_type": "price_change"}}
{"_local_timestamp": "2026-01-25T23:37:42.931338+00:00", "data": {"market": "0xf4cbee770d93e6be7c0eeef5fd8d143bf7b6cd05462745a0847aab51b993d406", "price_changes": [{"asset_id": "79935592053032469030142243551293799152704805799593114805455402419474295196734", "price": "0.005", "size": "148", "side": "BUY", "hash": "88eaacaa61301e9a1dc063f3b3938d4d3435a6bd", "best_bid": "0.005", "best_ask": "0.021"}, {"asset_id": "75482995474170622849957659966226987317064035398856989789719351907123461611518", "price": "0.995", "size": "148", "side": "SELL", "hash": "afdbc221e8c7f0a03f569fa89a00261c4b99ede9", "best_bid": "0.979", "best_ask": "0.995"}], "timestamp": "1769384262864", "event_type": "price_change"}}
{"_local_timestamp": "2026-01-25T23:37:45.014912+00:00", "data": {"market": "0xf4cbee770d93e6be7c0eeef5fd8d143bf7b6cd05462745a0847aab51b993d406", "price_changes": [{"asset_id": "79935592053032469030142243551293799152704805799593114805455402419474295196734", "price": "0.003", "size": "399.99", "side": "BUY", "hash": "da1db00cec61ded3a47dfc6c63f335e4886652cd", "best_bid": "0.005", "best_ask": "0.021"}, {"asset_id": "75482995474170622849957659966226987317064035398856989789719351907123461611518", "price": "0.997", "size": "399.99", "side": "SELL", "hash": "923ff1cf681fd121aadb4464f9f717a280e9d04d", "best_bid": "0.979", "best_ask": "0.995"}], "timestamp": "1769384264944", "event_type": "price_change"}}
{"_local_timestamp": "2026-01-25T23:37:50.235551+00:00", "data": {"market": "0xeaca7fad27f9e7602a07627a1dbb4b01352cd7ad99dd28b0ec09e26e6b12ccab", "price_changes": [{"asset_id": "76657535986059542453526409873946781453980750888541128603750398128471993423003", "price": "0.017", "size": "0", "side": "SELL", "hash": "7172fe5bc1da9f36ce287e44d6d6cb545a0a02aa", "best_bid": "0.008", "best_ask": "0.024"}, {"asset_id": "106496774138546112027406613561717117026755108026255407086336415079048692630377", "price": "0.983", "size": "0", "side": "BUY", "hash": "2ff09231c18f1fadf3336eb2962c626e66a8143d", "best_bid": "0.976", "best_ask": "0.992"}], "timestamp": "1769384270160", "event_type": "price_change"}}
{"_local_timestamp": "2026-01-25T23:37:50.958465+00:00", "data": {"market": "0xeaca7fad27f9e7602a07627a1dbb4b01352cd7ad99dd28b0ec09e26e6b12ccab", "price_changes": [{"asset_id": "76657535986059542453526409873946781453980750888541128603750398128471993423003", "price": "0.023", "size": "201.32", "side": "SELL", "hash": "cbe8bea350e66d6df6f7374f39e6dc3cd93a9b75", "best_bid": "0.008", "best_ask": "0.023"}, {"asset_id": "106496774138546112027406613561717117026755108026255407086336415079048692630377", "price": "0.977", "size": "201.32", "side": "BUY", "hash": "270ddfc61ec9aa3b5d2261783514d3ba962feb1a", "best_bid": "0.977", "best_ask": "0.992"}], "timestamp": "1769384270884", "event_type": "price_change"}}
{"_local_timestamp": "2026-01-25T23:37:51.452309+00:00", "data": {"market": "0xeaca7fad27f9e7602a07627a1dbb4b01352cd7ad99dd28b0ec09e26e6b12ccab", "price_changes": [{"asset_id": "106496774138546112027406613561717117026755108026255407086336415079048692630377", "price": "0.977", "size": "251.32", "side": "BUY", "hash": "e4faaccf9c52cf678f16b0d9cee10cb64d1e47f7", "best_bid": "0.977", "best_ask": "0.992"}, {"asset_id": "76657535986059542453526409873946781453980750888541128603750398128471993423003", "price": "0.023", "size": "251.32", "side": "SELL", "hash": "6c612cc286b624a00db782aeaf90764eb09a3e59", "best_bid": "0.008", "best_ask": "0.023"}], "timestamp": "1769384271178", "event_type": "price_change"}}
{"_local_timestamp": "2026-01-25T23:37:56.879771+00:00", "data": {"market": "0xf4cbee770d93e6be7c0eeef5fd8d143bf7b6cd05462745a0847aab51b993d406", "price_changes": [{"asset_id": "79935592053032469030142243551293799152704805799593114805455402419474295196734", "price": "0.002", "size": "1900", "side": "BUY", "hash": "1edeffaef89ff32a3e8dfd7e7a3b1686e443f3ec", "best_bid": "0.005", "best_ask": "0.021"}, {"asset_id": "75482995474170622849957659966226987317064035398856989789719351907123461611518", "price": "0.998", "size": "1900", "side": "SELL", "hash": "890ee90ee4c83cf472d0f6df7e8886b9a2b08010", "best_bid": "0.979", "best_ask": "0.995"}], "timestamp": "1769384276810", "event_type": "price_change"}}
{"_local_timestamp": "2026-01-25T23:38:05.190634+00:00", "data": {"market": "0xbb7afda76b33e28e6beca651afcf4ba2c96316330038b37d565311aec7aa80fd", "price_changes": [{"asset_id": "55048873344980893604077431803703373331531589597253065240792528177019001889497", "price": "0.042", "size": "95.26", "side": "BUY", "hash": "aff010266dd41be3f89a80c221a47fad9cf1f685", "best_bid": "0.042", "best_ask": "0.059"}, {"asset_id": "115380547880912465734621551138342931070381865195675981110314630607033301257937", "price": "0.958", "size": "95.26", "side": "SELL", "hash": "326169be48c3e879dc005f42ee7f1ca551a2b04f", "best_bid": "0.941", "best_ask": "0.958"}], "timestamp": "1769384285119", "event_type": "price_change"}}
{"_local_timestamp": "2026-01-25T23:38:05.279088+00:00", "data": {"market": "0xbb7afda76b33e28e6beca651afcf4ba2c96316330038b37d565311aec7aa80fd", "price_changes": [{"asset_id": "55048873344980893604077431803703373331531589597253065240792528177019001889497", "price": "0.032", "size": "93", "side": "BUY", "hash": "84c068408bb90cb2fe8a87bfc73c9aff761a8e39", "best_bid": "0.042", "best_ask": "0.059"}, {"asset_id": "115380547880912465734621551138342931070381865195675981110314630607033301257937", "price": "0.968", "size": "93", "side": "SELL", "hash": "47f254974d039a2559daba16b0d83b27de7ae2ff", "best_bid": "0.941", "best_ask": "0.958"}], "timestamp": "1769384285213", "event_type": "price_change"}}
{"_local_timestamp": "2026-01-25T23:38:06.103428+00:00", "data": {"market": "0xbb7afda76b33e28e6beca651afcf4ba2c96316330038b37d565311aec7aa80fd", "price_changes": [{"asset_id": "55048873344980893604077431803703373331531589597253065240792528177019001889497", "price": "0.042", "size": "125.26", "side": "BUY", "hash": "b0c8744b85bebd24fd5609e07cad776294bc779b", "best_bid": "0.042", "best_ask": "0.059"}, {"asset_id": "115380547880912465734621551138342931070381865195675981110314630607033301257937", "price": "0.958", "size": "125.26", "side": "SELL", "hash": "50c9c62ceb78f403a23ee7e1bd25c65144d0b853", "best_bid": "0.941", "best_ask": "0.958"}], "timestamp": "1769384286023", "event_type": "price_change"}}
{"_local_timestamp": "2026-01-25T23:38:13.666682+00:00", "data": {"market": "0xeaca7fad27f9e7602a07627a1dbb4b01352cd7ad99dd28b0ec09e26e6b12ccab", "price_changes": [{"asset_id": "106496774138546112027406613561717117026755108026255407086336415079048692630377", "price": "0.983", "size": "18.02", "side": "BUY", "hash": "6c48af929e73b9b23cf19eb8dbc0c82548afdeb0", "best_bid": "0.983", "best_ask": "0.992"}, {"asset_id": "76657535986059542453526409873946781453980750888541128603750398128471993423003", "price": "0.017", "size": "18.02", "side": "SELL", "hash": "2ab6d03e3efc18253b78be83feb2001247b0fcec", "best_bid": "0.008", "best_ask": "0.017"}], "timestamp": "1769384293598", "event_type": "price_change"}}
{"_local_timestamp": "2026-01-25T23:38:19.059774+00:00", "data": {"market": "0x881092c53fd9b67bdf30869d756e13da558e8642ce13d104f73f648e005e9dbb", "price_changes": [{"asset_id": "30209161280120374886078524432124760376829393809604890971368528789299616787016", "price": "0.122", "size": "0", "side": "SELL", "hash": "3c161241c8bbc772ca1aa293743ba2288a966557", "best_bid": "0.008", "best_ask": "0.062"}, {"asset_id": "106557923884483990512722312339562147481005985751920958827317376072063768641147", "price": "0.878", "size": "0", "side": "BUY", "hash": "19595b293e120dbf72af8c5b6685898a0a65cccb", "best_bid": "0.938", "best_ask": "0.992"}], "timestamp": "1769384298991", "event_type": "price_change"}}
{"_local_timestamp": "2026-01-25T23:38:19.208290+00:00", "data": {"market": "0x881092c53fd9b67bdf30869d756e13da558e8642ce13d104f73f648e005e9dbb", "price_changes": [{"asset_id": "30209161280120374886078524432124760376829393809604890971368528789299616787016", "price": "0.118", "size": "25", "side": "SELL", "hash": "4634fb21f7f09df971e47843aba10285ae3832f6", "best_bid": "0.008", "best_ask": "0.062"}, {"asset_id": "106557923884483990512722312339562147481005985751920958827317376072063768641147", "price": "0.882", "size": "25", "side": "BUY", "hash": "6b34e982fbc643666297ecf9510c67f4fd509222", "best_bid": "0.938", "best_ask": "0.992"}], "timestamp": "1769384299140", "event_type": "price_change"}}
{"_local_timestamp": "2026-01-25T23:38:21.316345+00:00", "data": {"market": "0xbb7afda76b33e28e6beca651afcf4ba2c96316330038b37d565311aec7aa80fd", "price_changes": [{"asset_id": "115380547880912465734621551138342931070381865195675981110314630607033301257937", "price": "0.34", "size": "70.58", "side": "BUY", "hash": "3e357f18de0aa4c9911daebb5f0569e499ec5c9d", "best_bid": "0.941", "best_ask": "0.958"}, {"asset_id": "55048873344980893604077431803703373331531589597253065240792528177019001889497", "price": "0.66", "size": "70.58", "side": "SELL", "hash": "80e44bf7478ca826a9b7b990f20b6ec7a03a0f00", "best_bid": "0.042", "best_ask": "0.059"}], "timestamp": "1769384301133", "event_type": "price_change"}}
{"_local_timestamp": "2026-01-25T23:38:21.656062+00:00", "data": {"market": "0xbb7afda76b33e28e6beca651afcf4ba2c96316330038b37d565311aec7aa80fd", "price_changes": [{"asset_id": "115380547880912465734621551138342931070381865195675981110314630607033301257937", "price": "0.38", "size": "177.63", "side": "BUY", "hash": "06c57f3eb6b7a8e17498e62b9f04980ae4d36f11", "best_bid": "0.941", "best_ask": "0.958"}, {"asset_id": "55048873344980893604077431803703373331531589597253065240792528177019001889497", "price": "0.62", "size": "177.63", "side": "SELL", "hash": "c1f409a1730b6e6922ac1294fac4844b9e5664a9", "best_bid": "0.042", "best_ask": "0.059"}], "timestamp": "1769384301478", "event_type": "price_change"}}
{"_local_timestamp": "2026-01-25T23:38:32.355256+00:00", "data": {"market": "0xeaca7fad27f9e7602a07627a1dbb4b01352cd7ad99dd28b0ec09e26e6b12ccab", "price_changes": [{"asset_id": "106496774138546112027406613561717117026755108026255407086336415079048692630377", "price": "0.983", "size": "31.18", "side": "BUY", "hash": "c00017b4efec9d95be3048cf6070275289e68d7e", "best_bid": "0.983", "best_ask": "0.992"}, {"asset_id": "76657535986059542453526409873946781453980750888541128603750398128471993423003", "price": "0.017", "size": "31.18", "side": "SELL", "hash": "b93e3bc51120956c4486290aab33fbd38d0aeeb8", "best_bid": "0.008", "best_ask": "0.017"}], "timestamp": "1769384312286", "event_type": "price_change"}}
{"_local_timestamp": "2026-01-25T23:38:33.832656+00:00", "data": {"market": "0xeaca7fad27f9e7602a07627a1dbb4b01352cd7ad99dd28b0ec09e26e6b12ccab", "price_changes": [{"asset_id": "106496774138546112027406613561717117026755108026255407086336415079048692630377", "price": "0.977", "size": "201.32", "side": "BUY", "hash": "618732f3d7e1a13b4bc1764a4d925a784723f086", "best_bid": "0.983", "best_ask": "0.992"}, {"asset_id": "76657535986059542453526409873946781453980750888541128603750398128471993423003", "price": "0.023", "size": "201.32", "side": "SELL", "hash": "70f5168c0c7208d8e210041902dac462335aa0ab", "best_bid": "0.008", "best_ask": "0.017"}], "timestamp": "1769384313760", "event_type": "price_change"}}
{"_local_timestamp": "2026-01-25T23:38:34.105232+00:00", "data": {"market": "0xeaca7fad27f9e7602a07627a1dbb4b01352cd7ad99dd28b0ec09e26e6b12ccab", "price_changes": [{"asset_id": "106496774138546112027406613561717117026755108026255407086336415079048692630377", "price": "0.983", "size": "51.54", "side": "BUY", "hash": "84417d91eb26e8778f83f8cf6a5872bad4e015c9", "best_bid": "0.983", "best_ask": "0.992"}, {"asset_id": "76657535986059542453526409873946781453980750888541128603750398128471993423003", "price": "0.017", "size": "51.54", "side": "SELL", "hash": "a9289bda6adf0393a50e8e80f018f2aa297c80f9", "best_bid": "0.008", "best_ask": "0.017"}], "timestamp": "1769384314027", "event_type": "price_change"}}
{"_local_timestamp": "2026-01-25T23:38:34.812043+00:00", "data": {"market": "0xeaca7fad27f9e7602a07627a1dbb4b01352cd7ad99dd28b0ec09e26e6b12ccab", "price_changes": [{"asset_id": "106496774138546112027406613561717117026755108026255407086336415079048692630377", "price": "0.983", "size": "72.68", "side": "BUY", "hash": "e97ba1d7c062b9e7bc2f499f8da764978d42a186", "best_bid": "0.983", "best_ask": "0.992"}, {"asset_id": "76657535986059542453526409873946781453980750888541128603750398128471993423003", "price": "0.017", "size": "72.68", "side": "SELL", "hash": "97d293f0da981a6d6dd564c15eaa8c5ae6737767", "best_bid": "0.008", "best_ask": "0.017"}], "timestamp": "1769384314741", "event_type": "price_change"}}
{"_local_timestamp": "2026-01-25T23:38:35.155460+00:00", "data": {"market": "0xeaca7fad27f9e7602a07627a1dbb4b01352cd7ad99dd28b0ec09e26e6b12ccab", "price_changes": [{"asset_id": "106496774138546112027406613561717117026755108026255407086336415079048692630377", "price": "0.983", "size": "91.48", "side": "BUY", "hash": "705f240623886204cc83d09ad0886d0001f9f787", "best_bid": "0.983", "best_ask": "0.992"}, {"asset_id": "76657535986059542453526409873946781453980750888541128603750398128471993423003", "price": "0.017", "size": "91.48", "side": "SELL", "hash": "989df36e2fd49d1c73152bc81bd9c289e764d821", "best_bid": "0.008", "best_ask": "0.017"}], "timestamp": "1769384315071", "event_type": "price_change"}}
{"_local_timestamp": "2026-01-25T23:38:35.506488+00:00", "data": {"market": "0xbb7afda76b33e28e6beca651afcf4ba2c96316330038b37d565311aec7aa80fd", "price_changes": [{"asset_id": "55048873344980893604077431803703373331531589597253065240792528177019001889497", "price": "0.032", "size": "0", "side": "BUY", "hash": "c98b4a775cc8d9bcf35c78e84dd59b84c0e30a16", "best_bid": "0.042", "best_ask": "0.059"}, {"asset_id": "115380547880912465734621551138342931070381865195675981110314630607033301257937", "price": "0.968", "size": "0", "side": "SELL", "hash": "c494ab4842f855969c3a0538ed8990f1f9cdc43e", "best_bid": "0.941", "best_ask": "0.958"}], "timestamp": "1769384315433", "event_type": "price_change"}}
{"_local_timestamp": "2026-01-25T23:38:35.583324+00:00", "data": {"market": "0xbb7afda76b33e28e6beca651afcf4ba2c96316330038b37d565311aec7aa80fd", "price_changes": [{"asset_id": "55048873344980893604077431803703373331531589597253065240792528177019001889497", "price": "0.042", "size": "196.26", "side": "BUY", "hash": "0e16bb9948c5cdc85cb088a05ff09e9129e62787", "best_bid": "0.042", "best_ask": "0.059"}, {"asset_id": "115380547880912465734621551138342931070381865195675981110314630607033301257937", "price": "0.958", "size": "196.26", "side": "SELL", "hash": "b37d7a4a2fef7fba680790aa4fa49bf74e183463", "best_bid": "0.941", "best_ask": "0.958"}], "timestamp": "1769384315516", "event_type": "price_change"}}
{"_local_timestamp": "2026-01-25T23:38:35.673334+00:00", "data": {"market": "0xbb7afda76b33e28e6beca651afcf4ba2c96316330038b37d565311aec7aa80fd", "price_changes": [{"asset_id": "55048873344980893604077431803703373331531589597253065240792528177019001889497", "price": "0.042", "size": "166.26", "side": "BUY", "hash": "07b8d93d84aad52b68c799456f0f6b7eb8c0a9e1", "best_bid": "0.042", "best_ask": "0.059"}, {"asset_id": "115380547880912465734621551138342931070381865195675981110314630607033301257937", "price": "0.958", "size": "166.26", "side": "SELL", "hash": "938e93740654d68f308720f1b9edb5fcccbd6b25", "best_bid": "0.941", "best_ask": "0.958"}], "timestamp": "1769384315605", "event_type": "price_change"}}
{"_local_timestamp": "2026-01-25T23:38:36.207733+00:00", "data": {"market": "0xeaca7fad27f9e7602a07627a1dbb4b01352cd7ad99dd28b0ec09e26e6b12ccab", "price_changes": [{"asset_id": "106496774138546112027406613561717117026755108026255407086336415079048692630377", "price": "0.983", "size": "104.01", "side": "BUY", "hash": "bd56ddbb8c7eff6c16225726f69aa7965fb26b1e", "best_bid": "0.983", "best_ask": "0.992"}, {"asset_id": "76657535986059542453526409873946781453980750888541128603750398128471993423003", "price": "0.017", "size": "104.01", "side": "SELL", "hash": "f90d1f138c61772a8530fbac3e1fcf73ae48a4a9", "best_bid": "0.008", "best_ask": "0.017"}], "timestamp": "1769384316143", "event_type": "price_change"}}
{"_local_timestamp": "2026-01-25T23:38:39.662698+00:00", "data": {"market": "0xeaca7fad27f9e7602a07627a1dbb4b01352cd7ad99dd28b0ec09e26e6b12ccab", "price_changes": [{"asset_id": "106496774138546112027406613561717117026755108026255407086336415079048692630377", "price": "0.983", "size": "119.61", "side": "BUY", "hash": "499ac40d29fc3af57ea278b149be1c42a108a7f7", "best_bid": "0.983", "best_ask": "0.992"}, {"asset_id": "76657535986059542453526409873946781453980750888541128603750398128471993423003", "price": "0.017", "size": "119.61", "side": "SELL", "hash": "713ec7badf93f22b9d86b4d58e1ff4f291638cf4", "best_bid": "0.008", "best_ask": "0.017"}], "timestamp": "1769384319580", "event_type": "price_change"}}
{"_local_timestamp": "2026-01-25T23:39:05.799281+00:00", "data": {"market": "0xbb7afda76b33e28e6beca651afcf4ba2c96316330038b37d565311aec7aa80fd", "price_changes": [{"asset_id": "55048873344980893604077431803703373331531589597253065240792528177019001889497", "price": "0.042", "size": "95.26", "side": "BUY", "hash": "8aabc3c23967a9cae0f824ddbfe59409cfc7fbab", "best_bid": "0.042", "best_ask": "0.059"}, {"asset_id": "115380547880912465734621551138342931070381865195675981110314630607033301257937", "price": "0.958", "size": "95.26", "side": "SELL", "hash": "d39f7dd973f2f10dd1821a9deee6da7109418895", "best_bid": "0.941", "best_ask": "0.958"}], "timestamp": "1769384345730", "event_type": "price_change"}}
{"_local_timestamp": "2026-01-25T23:39:05.885555+00:00", "data": {"market": "0xbb7afda76b33e28e6beca651afcf4ba2c96316330038b37d565311aec7aa80fd", "price_changes": [{"asset_id": "55048873344980893604077431803703373331531589597253065240792528177019001889497", "price": "0.032", "size": "93", "side": "BUY", "hash": "542d98cee2cfa5b21d5413b60bb00635f9eaf370", "best_bid": "0.042", "best_ask": "0.059"}, {"asset_id": "115380547880912465734621551138342931070381865195675981110314630607033301257937", "price": "0.968", "size": "93", "side": "SELL", "hash": "855e48c0745a7e471715b818d879a614eceaa036", "best_bid": "0.941", "best_ask": "0.958"}], "timestamp": "1769384345821", "event_type": "price_change"}}
{"_local_timestamp": "2026-01-25T23:39:06.018245+00:00", "data": {"market": "0xf4cbee770d93e6be7c0eeef5fd8d143bf7b6cd05462745a0847aab51b993d406", "price_changes": [{"asset_id": "75482995474170622849957659966226987317064035398856989789719351907123461611518", "price": "0.052", "size": "0", "side": "BUY", "hash": "1468048e176cef446e4af284bf480a0ad0e42e35", "best_bid": "0.979", "best_ask": "0.995"}, {"asset_id": "79935592053032469030142243551293799152704805799593114805455402419474295196734", "price": "0.948", "size": "0", "side": "SELL", "hash": "98f867df8ec61938948991e0bf1a19190e93a309", "best_bid": "0.005", "best_ask": "0.021"}], "timestamp": "1769384345954", "event_type": "price_change"}}
{"_local_timestamp": "2026-01-25T23:39:06.285864+00:00", "data": {"market": "0xf4cbee770d93e6be7c0eeef5fd8d143bf7b6cd05462745a0847aab51b993d406", "price_changes": [{"asset_id": "75482995474170622849957659966226987317064035398856989789719351907123461611518", "price": "0.153", "size": "20", "side": "BUY", "hash": "9c4ba837611abfda443aa81bbf3554246215b3d1", "best_bid": "0.979", "best_ask": "0.995"}, {"asset_id": "79935592053032469030142243551293799152704805799593114805455402419474295196734", "price": "0.847", "size": "20", "side": "SELL", "hash": "0c366daab0ccadae336298b2f74d05bc9668b890", "best_bid": "0.005", "best_ask": "0.021"}], "timestamp": "1769384346196", "event_type": "price_change"}}
{"_local_timestamp": "2026-01-25T23:39:06.405757+00:00", "data": {"market": "0xbb7afda76b33e28e6beca651afcf4ba2c96316330038b37d565311aec7aa80fd", "price_changes": [{"asset_id": "55048873344980893604077431803703373331531589597253065240792528177019001889497", "price": "0.042", "size": "125.26", "side": "BUY", "hash": "073b8382e94737422f52d589b6ade16fa71470a7", "best_bid": "0.042", "best_ask": "0.059"}, {"asset_id": "115380547880912465734621551138342931070381865195675981110314630607033301257937", "price": "0.958", "size": "125.26", "side": "SELL", "hash": "7770a2e24c03197d35bf5012a79388e37d34bf02", "best_bid": "0.941", "best_ask": "0.958"}], "timestamp": "1769384346335", "event_type": "price_change"}}
{"_local_timestamp": "2026-01-25T23:39:11.261046+00:00", "data": {"market": "0xf4cbee770d93e6be7c0eeef5fd8d143bf7b6cd05462745a0847aab51b993d406", "price_changes": [{"asset_id": "79935592053032469030142243551293799152704805799593114805455402419474295196734", "price": "0.003", "size": "0", "side": "BUY", "hash": "9a5dbff0ed9b2b91f60c13a359bd6175df848f92", "best_bid": "0.005", "best_ask": "0.021"}, {"asset_id": "75482995474170622849957659966226987317064035398856989789719351907123461611518", "price": "0.997", "size": "0", "side": "SELL", "hash": "0be0b95f5b154aacaf324348b6f9e06fa9952c6b", "best_bid": "0.979", "best_ask": "0.995"}], "timestamp": "1769384351195", "event_type": "price_change"}}
{"_local_timestamp": "2026-01-25T23:39:11.485029+00:00", "data": {"market": "0x5bb310c9ec29b1d762c5805810ca1bb864d2352a8f76812a3dca82a6a138ccf7", "price_changes": [{"asset_id": "96698433275460890480977628481467803238308494811045928618542144931124282536955", "price": "0.122", "size": "0", "side": "BUY", "hash": "9aa662b5146f553fc17ce2399a4d857c44f1a4d4", "best_bid": "0.997", "best_ask": "0.998"}, {"asset_id": "62123450528053709565950826485547710951386868966516386574151628295203483034330", "price": "0.878", "size": "0", "side": "SELL", "hash": "4ce66ceb434271e9a06519f0369ccab4f241ea90", "best_bid": "0.002", "best_ask": "0.003"}], "timestamp": "1769384351407", "event_type": "price_change"}}
{"_local_timestamp": "2026-01-25T23:39:11.672343+00:00", "data": {"market": "0x5bb310c9ec29b1d762c5805810ca1bb864d2352a8f76812a3dca82a6a138ccf7", "price_changes": [{"asset_id": "96698433275460890480977628481467803238308494811045928618542144931124282536955", "price": "0.142", "size": "20", "side": "BUY", "hash": "666df85c2d6b68e2cc56a4e9e7872e0ee3ada6f7", "best_bid": "0.997", "best_ask": "0.998"}, {"asset_id": "62123450528053709565950826485547710951386868966516386574151628295203483034330", "price": "0.858", "size": "20", "side": "SELL", "hash": "e4a4d3b53cd91c8987cebee75721fb2af180f67d", "best_bid": "0.002", "best_ask": "0.003"}], "timestamp": "1769384351601", "event_type": "price_change"}}
{"_local_timestamp": "2026-01-25T23:39:12.205440+00:00", "data": {"market": "0xf4cbee770d93e6be7c0eeef5fd8d143bf7b6cd05462745a0847aab51b993d406", "price_changes": [{"asset_id": "79935592053032469030142243551293799152704805799593114805455402419474295196734", "price": "0.006", "size": "199.99", "side": "BUY", "hash": "8dda3a5694d157d5296deb2b1ebce4045aa721ef", "best_bid": "0.006", "best_ask": "0.021"}, {"asset_id": "75482995474170622849957659966226987317064035398856989789719351907123461611518", "price": "0.994", "size": "199.99", "side": "SELL", "hash": "7956362773dd0f0bb40134e6163e2060f306e17b", "best_bid": "0.979", "best_ask": "0.994"}], "timestamp": "1769384351906", "event_type": "price_change"}}
{"_local_timestamp": "2026-01-25T23:39:12.268608+00:00", "data": {"market": "0x5bb310c9ec29b1d762c5805810ca1bb864d2352a8f76812a3dca82a6a138ccf7", "price_changes": [{"asset_id": "96698433275460890480977628481467803238308494811045928618542144931124282536955", "price": "0.141", "size": "0", "side": "BUY", "hash": "79118ad80cc98a42577f09785d0f65049e7d888e", "best_bid": "0.997", "best_ask": "0.998"}, {"asset_id": "62123450528053709565950826485547710951386868966516386574151628295203483034330", "price": "0.859", "size": "0", "side": "SELL", "hash": "b9426724f5265198b63be40eaa21dde68958dabb", "best_bid": "0.002", "best_ask": "0.003"}], "timestamp": "1769384352203", "event_type": "price_change"}}
{"_local_timestamp": "2026-01-25T23:39:12.269314+00:00", "data": {"market": "0x0e80cd8709ff87e5e8f640f04d56459b6b17f8725dfc45aa41638e864bdd516f", "price_changes": [{"asset_id": "31948734631736561994125221293320704077897312273398644786977701161539360085435", "price": "0.013", "size": "0", "side": "BUY", "hash": "2f3b50df397404dd8d01befa398ef63b7df4aa0a", "best_bid": "0.857", "best_ask": "0.866"}, {"asset_id": "64190946651851680406639375409936731829956855105844271954263113555549757553710", "price": "0.987", "size": "0", "side": "SELL", "hash": "b2e4598f65fa8685348e4101397838020f46f66b", "best_bid": "0.134", "best_ask": "0.143"}], "timestamp": "1769384352203", "event_type": "price_change"}}
{"_local_timestamp": "2026-01-25T23:39:12.298510+00:00", "data": {"market": "0x0e80cd8709ff87e5e8f640f04d56459b6b17f8725dfc45aa41638e864bdd516f", "price_changes": [{"asset_id": "31948734631736561994125221293320704077897312273398644786977701161539360085435", "price": "0.02", "size": "2020", "side": "BUY", "hash": "0a825e1c142cec411102e10266f91a91d5c166d0", "best_bid": "0.857", "best_ask": "0.866"}, {"asset_id": "64190946651851680406639375409936731829956855105844271954263113555549757553710", "price": "0.98", "size": "2020", "side": "SELL", "hash": "876dd139c2bd6b30a8dc4fa3a45df556f6b91eb3", "best_bid": "0.134", "best_ask": "0.143"}], "timestamp": "1769384352233", "event_type": "price_change"}}
{"_local_timestamp": "2026-01-25T23:39:12.304959+00:00", "data": {"market": "0x5bb310c9ec29b1d762c5805810ca1bb864d2352a8f76812a3dca82a6a138ccf7", "price_changes": [{"asset_id": "96698433275460890480977628481467803238308494811045928618542144931124282536955", "price": "0.143", "size": "20", "side": "BUY", "hash": "ac28f11709bc7775d6fcdb8ea32f1fc97c86c55f", "best_bid": "0.997", "best_ask": "0.998"}, {"asset_id": "62123450528053709565950826485547710951386868966516386574151628295203483034330", "price": "0.857", "size": "20", "side": "SELL", "hash": "be20feb35a764eb552ff7d3276afceaafb523368", "best_bid": "0.002", "best_ask": "0.003"}], "timestamp": "1769384352233", "event_type": "price_change"}}
{"_local_timestamp": "2026-01-25T23:39:18.828825+00:00", "data": {"market": "0xeaca7fad27f9e7602a07627a1dbb4b01352cd7ad99dd28b0ec09e26e6b12ccab", "price_changes": [{"asset_id": "76657535986059542453526409873946781453980750888541128603750398128471993423003", "price": "0.023", "size": "0", "side": "SELL", "hash": "d62de842c086d88b7069ef03afb7428be4165d68", "best_bid": "0.008", "best_ask": "0.017"}, {"asset_id": "106496774138546112027406613561717117026755108026255407086336415079048692630377", "price": "0.977", "size": "0", "side": "BUY", "hash": "eaee23c2d0e1710365169f9484050e4e8f3292a1", "best_bid": "0.983", "best_ask": "0.992"}], "timestamp": "1769384358762", "event_type": "price_change"}}
{"_local_timestamp": "2026-01-25T23:39:19.655156+00:00", "data": {"market": "0xeaca7fad27f9e7602a07627a1dbb4b01352cd7ad99dd28b0ec09e26e6b12ccab", "price_changes": [{"asset_id": "76657535986059542453526409873946781453980750888541128603750398128471993423003", "price": "0.016", "size": "201.32", "side": "SELL", "hash": "75b131724f11e58000a96537d849c30248f21023", "best_bid": "0.008", "best_ask": "0.016"}, {"asset_id": "106496774138546112027406613561717117026755108026255407086336415079048692630377", "price": "0.984", "size": "201.32", "side": "BUY", "hash": "c16bd9b22e5bed13fdf4b41fe942a66f5c08763c", "best_bid": "0.984", "best_ask": "0.992"}], "timestamp": "1769384359584", "event_type": "price_change"}}
{"_local_timestamp": "2026-01-25T23:39:21.836801+00:00", "data": {"market": "0xeaca7fad27f9e7602a07627a1dbb4b01352cd7ad99dd28b0ec09e26e6b12ccab", "price_changes": [{"asset_id": "106496774138546112027406613561717117026755108026255407086336415079048692630377", "price": "0.955", "size": "0", "side": "BUY", "hash": "2f2743b7d50782781a950cbdc91e5e9ff9fabbbc", "best_bid": "0.984", "best_ask": "0.992"}, {"asset_id": "76657535986059542453526409873946781453980750888541128603750398128471993423003", "price": "0.045", "size": "0", "side": "SELL", "hash": "a45b253da966c1e9360604432d921f4702f37f46", "best_bid": "0.008", "best_ask": "0.016"}], "timestamp": "1769384361763", "event_type": "price_change"}}
{"_local_timestamp": "2026-01-25T23:39:21.837570+00:00", "data": {"market": "0xeaca7fad27f9e7602a07627a1dbb4b01352cd7ad99dd28b0ec09e26e6b12ccab", "price_changes": [{"asset_id": "106496774138546112027406613561717117026755108026255407086336415079048692630377", "price": "0.927", "size": "0", "side": "BUY", "hash": "2f2743b7d50782781a950cbdc91e5e9ff9fabbbc", "best_bid": "0.984", "best_ask": "0.992"}, {"asset_id": "76657535986059542453526409873946781453980750888541128603750398128471993423003", "price": "0.073", "size": "0", "side": "SELL", "hash": "a45b253da966c1e9360604432d921f4702f37f46", "best_bid": "0.008", "best_ask": "0.016"}], "timestamp": "1769384361763", "event_type": "price_change"}}
{"_local_timestamp": "2026-01-25T23:39:22.256705+00:00", "data": {"market": "0x881092c53fd9b67bdf30869d756e13da558e8642ce13d104f73f648e005e9dbb", "price_changes": [{"asset_id": "106557923884483990512722312339562147481005985751920958827317376072063768641147", "price": "0.382", "size": "0", "side": "BUY", "hash": "4bb81ed4750061a4d12c0ec3efb89e95e5f08d68", "best_bid": "0.938", "best_ask": "0.992"}, {"asset_id": "30209161280120374886078524432124760376829393809604890971368528789299616787016", "price": "0.618", "size": "0", "side": "SELL", "hash": "9ab6b412c8eab41981f613d5fdc3d9e7548ecaa9", "best_bid": "0.008", "best_ask": "0.062"}], "timestamp": "1769384362181", "event_type": "price_change"}}
{"_local_timestamp": "2026-01-25T23:39:23.007505+00:00", "data": {"market": "0x881092c53fd9b67bdf30869d756e13da558e8642ce13d104f73f648e005e9dbb", "price_changes": [{"asset_id": "106557923884483990512722312339562147481005985751920958827317376072063768641147", "price": "0.38", "size": "127.63", "side": "BUY", "hash": "614972a603e90feac923a062fc1f8ece57954f6f", "best_bid": "0.938", "best_ask": "0.992"}, {"asset_id": "30209161280120374886078524432124760376829393809604890971368528789299616787016", "price": "0.62", "size": "127.63", "side": "SELL", "hash": "707fd632755cf4a78d1f1e2b805bd5713ce535ed", "best_bid": "0.008", "best_ask": "0.062"}], "timestamp": "1769384362747", "event_type": "price_change"}}
{"_local_timestamp": "2026-01-25T23:39:36.242886+00:00", "data": {"market": "0xbb7afda76b33e28e6beca651afcf4ba2c96316330038b37d565311aec7aa80fd", "price_changes": [{"asset_id": "55048873344980893604077431803703373331531589597253065240792528177019001889497", "price": "0.032", "size": "0", "side": "BUY", "hash": "2ea0d64ea7752a327023052ba27b760062c4b0a4", "best_bid": "0.042", "best_ask": "0.059"}, {"asset_id": "115380547880912465734621551138342931070381865195675981110314630607033301257937", "price": "0.968", "size": "0", "side": "SELL", "hash": "7f97adcb8aedbfa2310e39da93e424f010c8c0fc", "best_bid": "0.941", "best_ask": "0.958"}], "timestamp": "1769384376178", "event_type": "price_change"}}
{"_local_timestamp": "2026-01-25T23:39:36.326795+00:00", "data": {"market": "0xbb7afda76b33e28e6beca651afcf4ba2c96316330038b37d565311aec7aa80fd", "price_changes": [{"asset_id": "55048873344980893604077431803703373331531589597253065240792528177019001889497", "price": "0.042", "size": "196.26", "side": "BUY", "hash": "51221e9c3a97b951b8ae90f7bf8b6747a7672f33", "best_bid": "0.042", "best_ask": "0.059"}, {"asset_id": "115380547880912465734621551138342931070381865195675981110314630607033301257937", "price": "0.958", "size": "196.26", "side": "SELL", "hash": "ad802611a65fa6d9800d278d879e0b0f9313e1a0", "best_bid": "0.941", "best_ask": "0.958"}], "timestamp": "1769384376261", "event_type": "price_change"}}
{"_local_timestamp": "2026-01-25T23:39:37.180081+00:00", "data": {"market": "0xbb7afda76b33e28e6beca651afcf4ba2c96316330038b37d565311aec7aa80fd", "price_changes": [{"asset_id": "55048873344980893604077431803703373331531589597253065240792528177019001889497", "price": "0.042", "size": "166.26", "side": "BUY", "hash": "692b5e855bc0fccbe3131a09083d7263059cba32", "best_bid": "0.042", "best_ask": "0.059"}, {"asset_id": "115380547880912465734621551138342931070381865195675981110314630607033301257937", "price": "0.958", "size": "166.26", "side": "SELL", "hash": "2baeb5cb241e540bd7087ac93c7616a8f3824666", "best_bid": "0.941", "best_ask": "0.958"}], "timestamp": "1769384377111", "event_type": "price_change"}}
{"_local_timestamp": "2026-01-25T23:39:45.813773+00:00", "data": {"market": "0x881092c53fd9b67bdf30869d756e13da558e8642ce13d104f73f648e005e9dbb", "price_changes": [{"asset_id": "106557923884483990512722312339562147481005985751920958827317376072063768641147", "price": "0.88", "size": "0", "side": "BUY", "hash": "9d7508031faa0044eb337f392dfcc4cbf5ec79bf", "best_bid": "0.938", "best_ask": "0.992"}, {"asset_id": "30209161280120374886078524432124760376829393809604890971368528789299616787016", "price": "0.12", "size": "0", "side": "SELL", "hash": "b120dcf341a56c8aed09b62f5fa6dede36f61732", "best_bid": "0.008", "best_ask": "0.062"}], "timestamp": "1769384385724", "event_type": "price_change"}}
{"_local_timestamp": "2026-01-25T23:39:51.698565+00:00", "data": {"market": "0x881092c53fd9b67bdf30869d756e13da558e8642ce13d104f73f648e005e9dbb", "price_changes": [{"asset_id": "106557923884483990512722312339562147481005985751920958827317376072063768641147", "price": "0.878", "size": "50", "side": "BUY", "hash": "0256597c0917168a9cf8dd77fe01693047cc083d", "best_bid": "0.938", "best_ask": "0.992"}, {"asset_id": "30209161280120374886078524432124760376829393809604890971368528789299616787016", "price": "0.122", "size": "50", "side": "SELL", "hash": "a5cfbcbf8eadea6a9629f7832cb854b919de2138", "best_bid": "0.008", "best_ask": "0.062"}], "timestamp": "1769384391627", "event_type": "price_change"}}
{"_local_timestamp": "2026-01-25T23:39:51.794644+00:00", "data": {"market": "0xd25ccd7ec063e97bcdfc4a5c425309786dee7d46cda598eeb056133ecc60a26b", "price_changes": [{"asset_id": "22672567771033630077120686118492403548405141258052518328454061644820946401508", "price": "0.052", "size": "0", "side": "BUY", "hash": "147f287eccf2c9a0e514b01265811785a93921ca", "best_bid": "0.996", "best_ask": "1"}, {"asset_id": "61363616775934825034538234334948775070821960948072963080826717391882343278521", "price": "0.948", "size": "0", "side": "SELL", "hash": "393eadcf7753c038bcea6499f4bff326e1de513f", "best_bid": "0", "best_ask": "0.004"}], "timestamp": "1769384391728", "event_type": "price_change"}}
{"_local_timestamp": "2026-01-25T23:39:51.795380+00:00", "data": {"market": "0x6f688996e47f896351729088a8c2c0fcb7db6f40fd96eed42502e11c9962f744", "price_changes": [{"asset_id": "63575582870841942383427053084518597975654282758242000155173178759202148848429", "price": "0.052", "size": "0", "side": "BUY", "hash": "725ff2f31e6337167e047e30280d9d43445a16ff", "best_bid": "0.993", "best_ask": "1"}, {"asset_id": "1479722737131399761673297933236140450313179902349075711821861456880367927838", "price": "0.948", "size": "0", "side": "SELL", "hash": "b17bb2fb339ee7361c1451931dd76ca114fbc3d2", "best_bid": "0", "best_ask": "0.007"}], "timestamp": "1769384391728", "event_type": "price_change"}}
{"_local_timestamp": "2026-01-25T23:39:51.795967+00:00", "data": {"market": "0x881092c53fd9b67bdf30869d756e13da558e8642ce13d104f73f648e005e9dbb", "price_changes": [{"asset_id": "106557923884483990512722312339562147481005985751920958827317376072063768641147", "price": "0.052", "size": "0", "side": "BUY", "hash": "1f796cd7a10a3066b49c956e46c9c314b269b77b", "best_bid": "0.938", "best_ask": "0.992"}, {"asset_id": "30209161280120374886078524432124760376829393809604890971368528789299616787016", "price": "0.948", "size": "0", "side": "SELL", "hash": "42e6d9617531b9230fa9f03870970ff3a41dc082", "best_bid": "0.008", "best_ask": "0.062"}], "timestamp": "1769384391728", "event_type": "price_change"}}
{"_local_timestamp": "2026-01-25T23:39:51.796525+00:00", "data": {"market": "0xeaca7fad27f9e7602a07627a1dbb4b01352cd7ad99dd28b0ec09e26e6b12ccab", "price_changes": [{"asset_id": "106496774138546112027406613561717117026755108026255407086336415079048692630377", "price": "0.052", "size": "0", "side": "BUY", "hash": "30ebe34d375c37ec22e23c12873dd4364703f59d", "best_bid": "0.984", "best_ask": "0.992"}, {"asset_id": "76657535986059542453526409873946781453980750888541128603750398128471993423003", "price": "0.948", "size": "0", "side": "SELL", "hash": "6c95680b014cf242a9f21ca322eb8a43ffb3361c", "best_bid": "0.008", "best_ask": "0.016"}], "timestamp": "1769384391728", "event_type": "price_change"}}
{"_local_timestamp": "2026-01-25T23:39:52.273496+00:00", "data": {"market": "0x881092c53fd9b67bdf30869d756e13da558e8642ce13d104f73f648e005e9dbb", "price_changes": [{"asset_id": "106557923884483990512722312339562147481005985751920958827317376072063768641147", "price": "0.881", "size": "0", "side": "BUY", "hash": "0c9beebb9a41d82ee4458249a6b60bc6a985e192", "best_bid": "0.938", "best_ask": "0.992"}, {"asset_id": "30209161280120374886078524432124760376829393809604890971368528789299616787016", "price": "0.119", "size": "0", "side": "SELL", "hash": "09769b95cc8074790732f1b1551f901d756bdaf8", "best_bid": "0.008", "best_ask": "0.062"}], "timestamp": "1769384392201", "event_type": "price_change"}}
{"_local_timestamp": "2026-01-25T23:39:52.348355+00:00", "data": {"market": "0xd25ccd7ec063e97bcdfc4a5c425309786dee7d46cda598eeb056133ecc60a26b", "price_changes": [{"asset_id": "22672567771033630077120686118492403548405141258052518328454061644820946401508", "price": "0.071", "size": "20", "side": "BUY", "hash": "ea7de0c94fe9d2fa0e5b99ef26e2e4f22be23b54", "best_bid": "0.996", "best_ask": "1"}, {"asset_id": "61363616775934825034538234334948775070821960948072963080826717391882343278521", "price": "0.929", "size": "20", "side": "SELL", "hash": "5ac2e25a81be159d09df17ba2153ff92daa282a3", "best_bid": "0", "best_ask": "0.004"}], "timestamp": "1769384392280", "event_type": "price_change"}}
{"_local_timestamp": "2026-01-25T23:39:52.349025+00:00", "data": {"market": "0x6f688996e47f896351729088a8c2c0fcb7db6f40fd96eed42502e11c9962f744", "price_changes": [{"asset_id": "63575582870841942383427053084518597975654282758242000155173178759202148848429", "price": "0.052", "size": "20", "side": "BUY", "hash": "d3a1f5a2be5bf6a92ad6c9c9de492396a5512a05", "best_bid": "0.993", "best_ask": "1"}, {"asset_id": "1479722737131399761673297933236140450313179902349075711821861456880367927838", "price": "0.948", "size": "20", "side": "SELL", "hash": "930addc5a7977614681fd7cda8c76fe334aa6d45", "best_bid": "0", "best_ask": "0.007"}], "timestamp": "1769384392280", "event_type": "price_change"}}
{"_local_timestamp": "2026-01-25T23:39:52.349631+00:00", "data": {"market": "0x881092c53fd9b67bdf30869d756e13da558e8642ce13d104f73f648e005e9dbb", "price_changes": [{"asset_id": "106557923884483990512722312339562147481005985751920958827317376072063768641147", "price": "0.052", "size": "20", "side": "BUY", "hash": "b40d915a7934856810ad9e59b7bc987c70498009", "best_bid": "0.938", "best_ask": "0.992"}, {"asset_id": "30209161280120374886078524432124760376829393809604890971368528789299616787016", "price": "0.948", "size": "20", "side": "SELL", "hash": "dbb4216fdfccd9adcad0094be2b391e296123782", "best_bid": "0.008", "best_ask": "0.062"}], "timestamp": "1769384392280", "event_type": "price_change"}}
{"_local_timestamp": "2026-01-25T23:39:52.350348+00:00", "data": {"market": "0xeaca7fad27f9e7602a07627a1dbb4b01352cd7ad99dd28b0ec09e26e6b12ccab", "price_changes": [{"asset_id": "106496774138546112027406613561717117026755108026255407086336415079048692630377", "price": "0.152", "size": "20", "side": "BUY", "hash": "8a40573bc6c919fcebd3bd1345d6c821f320173a", "best_bid": "0.984", "best_ask": "0.992"}, {"asset_id": "76657535986059542453526409873946781453980750888541128603750398128471993423003", "price": "0.848", "size": "20", "side": "SELL", "hash": "8e59b712860186a5179484b2f64acf1ddc50b451", "best_bid": "0.008", "best_ask": "0.016"}], "timestamp": "1769384392280", "event_type": "price_change"}}
{"_local_timestamp": "2026-01-25T23:39:52.466106+00:00", "data": {"market": "0xeaca7fad27f9e7602a07627a1dbb4b01352cd7ad99dd28b0ec09e26e6b12ccab", "price_changes": [{"asset_id": "106496774138546112027406613561717117026755108026255407086336415079048692630377", "price": "0.185", "size": "50", "side": "BUY", "hash": "23b83c800defa6629926cd5dde810747d5d944a3", "best_bid": "0.984", "best_ask": "0.992"}, {"asset_id": "76657535986059542453526409873946781453980750888541128603750398128471993423003", "price": "0.815", "size": "50", "side": "SELL", "hash": "cee897e1ce678f70cc6aacf7ae46eac7d8f49be5", "best_bid": "0.008", "best_ask": "0.016"}], "timestamp": "1769384392391", "event_type": "price_change"}}
{"_local_timestamp": "2026-01-25T23:39:52.479128+00:00", "data": {"market": "0xeaca7fad27f9e7602a07627a1dbb4b01352cd7ad99dd28b0ec09e26e6b12ccab", "price_changes": [{"asset_id": "106496774138546112027406613561717117026755108026255407086336415079048692630377", "price": "0.185", "size": "100", "side": "BUY", "hash": "af3f69146f89cf14064ddd88158833e779b75e1a", "best_bid": "0.984", "best_ask": "0.992"}, {"asset_id": "76657535986059542453526409873946781453980750888541128603750398128471993423003", "price": "0.815", "size": "100", "side": "SELL", "hash": "518503093fdf23837c1ed1cca534b57c5ed3a44a", "best_bid": "0.008", "best_ask": "0.016"}], "timestamp": "1769384392397", "event_type": "price_change"}}
{"_local_timestamp": "2026-01-25T23:39:52.503169+00:00", "data": {"market": "0xeaca7fad27f9e7602a07627a1dbb4b01352cd7ad99dd28b0ec09e26e6b12ccab", "price_changes": [{"asset_id": "106496774138546112027406613561717117026755108026255407086336415079048692630377", "price": "0.185", "size": "150", "side": "BUY", "hash": "80fb6eeb68fe859d1cd611f316d0d08a750d3dfb", "best_bid": "0.984", "best_ask": "0.992"}, {"asset_id": "76657535986059542453526409873946781453980750888541128603750398128471993423003", "price": "0.815", "size": "150", "side": "SELL", "hash": "7bfccabc5b193732a8a46fd2badfd82a7eb2c81b", "best_bid": "0.008", "best_ask": "0.016"}], "timestamp": "1769384392433", "event_type": "price_change"}}
{"_local_timestamp": "2026-01-25T23:40:06.555531+00:00", "data": {"market": "0xbb7afda76b33e28e6beca651afcf4ba2c96316330038b37d565311aec7aa80fd", "price_changes": [{"asset_id": "55048873344980893604077431803703373331531589597253065240792528177019001889497", "price": "0.042", "size": "95.26", "side": "BUY", "hash": "173d612799cccab09307022c0e12ab20fe46f41a", "best_bid": "0.042", "best_ask": "0.059"}, {"asset_id": "115380547880912465734621551138342931070381865195675981110314630607033301257937", "price": "0.958", "size": "95.26", "side": "SELL", "hash": "b905857b591798937b1783e2dce9d3261ac6ffc4", "best_bid": "0.941", "best_ask": "0.958"}], "timestamp": "1769384406480", "event_type": "price_change"}}
{"_local_timestamp": "2026-01-25T23:40:06.643205+00:00", "data": {"market": "0xbb7afda76b33e28e6beca651afcf4ba2c96316330038b37d565311aec7aa80fd", "price_changes": [{"asset_id": "55048873344980893604077431803703373331531589597253065240792528177019001889497", "price": "0.032", "size": "93", "side": "BUY", "hash": "d33207cde41fbf5181c6258c8f2cd9e11b91ed76", "best_bid": "0.042", "best_ask": "0.059"}, {"asset_id": "115380547880912465734621551138342931070381865195675981110314630607033301257937", "price": "0.968", "size": "93", "side": "SELL", "hash": "37b6895b83f43658f01fc23fdf3c7f5986b71ccd", "best_bid": "0.941", "best_ask": "0.958"}], "timestamp": "1769384406575", "event_type": "price_change"}}
{"_local_timestamp": "2026-01-25T23:40:06.651940+00:00", "data": {"market": "0xeaca7fad27f9e7602a07627a1dbb4b01352cd7ad99dd28b0ec09e26e6b12ccab", "price_changes": [{"asset_id": "106496774138546112027406613561717117026755108026255407086336415079048692630377", "price": "0.194", "size": "26", "side": "BUY", "hash": "e595fc1d5a62f3b6cbef6519a06b6da4e3b44f47", "best_bid": "0.984", "best_ask": "0.992"}, {"asset_id": "76657535986059542453526409873946781453980750888541128603750398128471993423003", "price": "0.806", "size": "26", "side": "SELL", "hash": "fc02f6290f4682c18ba40a1a870b5ae28d47d00e", "best_bid": "0.008", "best_ask": "0.016"}], "timestamp": "1769384406587", "event_type": "price_change"}}
{"_local_timestamp": "2026-01-25T23:40:06.701323+00:00", "data": {"market": "0xeaca7fad27f9e7602a07627a1dbb4b01352cd7ad99dd28b0ec09e26e6b12ccab", "price_changes": [{"asset_id": "106496774138546112027406613561717117026755108026255407086336415079048692630377", "price": "0.185", "size": "100", "side": "BUY", "hash": "a7e137a734cac5171f5a11deace3bbe270e372fa", "best_bid": "0.984", "best_ask": "0.992"}, {"asset_id": "76657535986059542453526409873946781453980750888541128603750398128471993423003", "price": "0.815", "size": "100", "side": "SELL", "hash": "8ddbcf342a6d8efaa0a1c25ae9754d43a5cc244b", "best_bid": "0.008", "best_ask": "0.016"}], "timestamp": "1769384406593", "event_type": "price_change"}}
{"_local_timestamp": "2026-01-25T23:40:06.847688+00:00", "data": {"market": "0xeaca7fad27f9e7602a07627a1dbb4b01352cd7ad99dd28b0ec09e26e6b12ccab", "price_changes": [{"asset_id": "106496774138546112027406613561717117026755108026255407086336415079048692630377", "price": "0.194", "size": "52", "side": "BUY", "hash": "f075a7bd6e38ef3080c52a5f3029ed6ff3ae9f43", "best_bid": "0.984", "best_ask": "0.992"}, {"asset_id": "76657535986059542453526409873946781453980750888541128603750398128471993423003", "price": "0.806", "size": "52", "side": "SELL", "hash": "32f494ac9a0b70d7f890569c1b956fe25c7c9e17", "best_bid": "0.008", "best_ask": "0.016"}], "timestamp": "1769384406602", "event_type": "price_change"}}
{"_local_timestamp": "2026-01-25T23:40:06.855683+00:00", "data": {"market": "0xeaca7fad27f9e7602a07627a1dbb4b01352cd7ad99dd28b0ec09e26e6b12ccab", "price_changes": [{"asset_id": "106496774138546112027406613561717117026755108026255407086336415079048692630377", "price": "0.185", "size": "50", "side": "BUY", "hash": "4bda71899bf7dd6e8a0aa113aaaca2e14aae23bc", "best_bid": "0.984", "best_ask": "0.992"}, {"asset_id": "76657535986059542453526409873946781453980750888541128603750398128471993423003", "price": "0.815", "size": "50", "side": "SELL", "hash": "7dddefeed403d62b0932308712f3c429bfebf1d2", "best_bid": "0.008", "best_ask": "0.016"}], "timestamp": "1769384406621", "event_type": "price_change"}}
{"_local_timestamp": "2026-01-25T23:40:06.879022+00:00", "data": {"market": "0xeaca7fad27f9e7602a07627a1dbb4b01352cd7ad99dd28b0ec09e26e6b12ccab", "price_changes": [{"asset_id": "106496774138546112027406613561717117026755108026255407086336415079048692630377", "price": "0.185", "size": "0", "side": "BUY", "hash": "d218677b669a2ca4c7da6e922eedc310684dd711", "best_bid": "0.984", "best_ask": "0.992"}, {"asset_id": "76657535986059542453526409873946781453980750888541128603750398128471993423003", "price": "0.815", "size": "0", "side": "SELL", "hash": "2693c1dca9c05370e074d9db24fbf1d65342170a", "best_bid": "0.008", "best_ask": "0.016"}], "timestamp": "1769384406664", "event_type": "price_change"}}
{"_local_timestamp": "2026-01-25T23:40:07.064970+00:00", "data": {"market": "0xbb7afda76b33e28e6beca651afcf4ba2c96316330038b37d565311aec7aa80fd", "price_changes": [{"asset_id": "55048873344980893604077431803703373331531589597253065240792528177019001889497", "price": "0.042", "size": "125.26", "side": "BUY", "hash": "e38b6e32ce413a092744b397a0fdc56e98959bc8", "best_bid": "0.042", "best_ask": "0.059"}, {"asset_id": "115380547880912465734621551138342931070381865195675981110314630607033301257937", "price": "0.958", "size": "125.26", "side": "SELL", "hash": "a1ecc678ca4d183594ba3372bc3f801b360efb74", "best_bid": "0.941", "best_ask": "0.958"}], "timestamp": "1769384406996", "event_type": "price_change"}}
