{"_local_timestamp": "2026-01-25T23:33:29.187728+00:00", "data": [{"market": "0xe39dbeb302a95a1db7e8ea9d960d938eadf809915d35b010d6b5bdeab9104faa", "asset_id": "17232151154444159837483463581179634092787787010273125825914638704500808010603", "timestamp": "1769383987149", "hash": "b81c9547a39494079512b50aea82196a939f63ad", "bids": [{"price": "0.001", "size": "2819"}, {"price": "0.002", "size": "250"}, {"price": "0.003", "size": "400"}, {"price": "0.006", "size": "200"}, {"price": "0.01", "size": "1410"}, {"price": "0.02", "size": "1150"}, {"price": "0.05", "size": "30"}, {"price": "0.051", "size": "39"}, {"price": "0.059", "size": "2900"}, {"price": "0.08", "size": "500"}, {"price": "0.14", "size": "200"}, {"price": "0.142", "size": "7"}, {"price": "0.143", "size": "13"}, {"price": "0.304", "size": "10"}, {"price": "0.306", "size": "22"}, {"price": "0.308", "size": "30"}, {"price": "0.309", "size": "10"}, {"price": "0.905", "size": "5"}, {"price": "0.91", "size": "1000"}, {"price": "0.911", "size": "15"}], "asks": [{"price": "0.999", "size": "2576"}, {"price": "0.998", "size": "200"}, {"price": "0.997", "size": "100"}, {"price": "0.99", "size": "10"}], "event_type": "book", "last_trade_price": ""}, {"market": "0xedfafd25484c04cfbeaa767022f9eca5bb680918fceece81b36b0611eb3638a6", "asset_id": "69100260301420797247941786085257042358554422352183746124379790103566465901104", "timestamp": "1769384006825", "hash": "f840fc5810a64844151214eed2440a6ae484f3a8", "bids": [{"price": "0.01", "size": "10"}, {"price": "0.05", "size": "30"}, {"price": "0.06", "size": "2033"}, {"price": "0.07", "size": "235"}, {"price": "0.08", "size": "25"}, {"price": "0.1", "size": "11"}, {"price": "0.12", "size": "30"}, {"price": "0.14", "size": "91"}, {"price": "0.15", "size": "20"}, {"price": "0.36", "size": "15"}], "asks": [{"price": "0.99", "size": "10"}], "event_type": "book", "last_trade_price": ""}, {"market": "0x33e09845665c7bcd0b3026cdf8c48f4e4d1ae705e0acd863e03525888a3c01c5", "asset_id": "41365543321762183390531316023268343985794742000187213322174746298305281833286", "timestamp": "1769383985996", "hash": "f4d554ea927958e32f51bace72d609fc6edc45b3", "bids": [{"price": "0.01", "size": "10"}, {"price": "0.02", "size": "150"}], "asks": [{"price": "0.99", "size": "10"}, {"price": "0.98", "size": "150"}, {"price": "0.95", "size": "30"}, {"price": "0.94", "size": "2033"}, {"price": "0.93", "size": "200"}, {"price": "0.92", "size": "25"}, {"price": "0.89", "size": "10"}, {"price": "0.83", "size": "10"}, {"price": "0.7", "size": "40"}, {"price": "0.69", "size": "10"}, {"price": "0.66", "size": "19"}], "event_type": "book", "last_trade_price": ""}, {"market": "0xf281d9254d35ae8355aa5a2aa98fd38c96ba9c604a5526c2cf9e3a2934c1eee3", "asset_id": "9395139935407818232687755250472957071183406150419861658575355254022011268877", "timestamp": "1769383987318", "hash": "8da5239ee5520a7139114520ff97ee76e443e0a1", "bids": [{"price": "0.01", "size": "10"}, {"price": "0.05", "size": "30"}, {"price": "0.06", "size": "2033"}, {"price": "0.07", "size": "200"}, {"price": "0.09", "size": "89"}, {"price": "0.13", "size": "15"}, {"price": "0.22", "size": "15"}, {"price": "0.28", "size": "10"}, {"price": "0.32", "size": "30"}, {"price": "0.33", "size": "10"}], "asks": [{"price": "0.99", "size": "10"}, {"price": "0.98", "size": "200"}], "event_type": "book", "last_trade_price": ""}, {"market": "0xba7bb363782238a06ea70ba7b726292e99d017dd37dd8322a3309b257d5e3a53", "asset_id": "70665643461197636242766365969385844686558838063736166515342466618906333119822", "timestamp": "1769383987149", "hash": "3293350a8b48d93170b25f6d6a262dcedead25a7", "bids": [{"price": "0.001", "size": "2701"}, {"price": "0.002", "size": "250"}, {"price": "0.003", "size": "400"}, {"price": "0.006", "size": "200"}, {"price": "0.01", "size": "10"}, {"price": "0.02", "size": "150"}, {"price": "0.05", "size": "30"}, {"price": "0.051", "size": "39"}, {"price": "0.06", "size": "2000"}, {"price": "0.061", "size": "239"}, {"price": "0.118", "size": "37"}, {"price": "0.156", "size": "12"}, {"price": "0.162", "size": "10"}, {"price": "0.167", "size": "30"}, {"price": "0.168", "size": "19"}, {"price": "0.169", "size": "10"}, {"price": "0.931", "size": "5"}, {"price": "0.932", "size": "15"}], "asks": [{"price": "0.999", "size": "2576"}, {"price": "0.998", "size": "200"}, {"price": "0.996", "size": "50"}, {"price": "0.99", "size": "10"}, {"price": "0.989", "size": "150"}], "event_type": "book", "last_trade_price": ""}, {"market": "0x9ad98d277747a5af33029daa93d8921e20dc48fc43a13444b34abd5db3090419", "asset_id": "84279332923568891895771507663060971052533473524984039519051747621941395607490", "timestamp": "1769384004854", "hash": "411ed9b6732e33b887891f19fc3e61098e1df858", "bids": [{"price": "0.01", "size": "10"}, {"price": "0.05", "size": "2030"}, {"price": "0.06", "size": "256"}, {"price": "0.08", "size": "14"}, {"price": "0.11", "size": "18"}, {"price": "0.2", "size": "10"}, {"price": "0.21", "size": "30"}, {"price": "0.22", "size": "10"}, {"price": "0.34", "size": "15"}], "asks": [{"price": "0.99", "size": "15"}, {"price": "0.98", "size": "100"}, {"price": "0.97", "size": "60"}, {"price": "0.96", "size": "30"}], "event_type": "book", "last_trade_price": ""}, {"market": "0x9ad98d277747a5af33029daa93d8921e20dc48fc43a13444b34abd5db3090419", "asset_id": "13106897552498929473034004606662562096233616324310660731332487169842346464915", "timestamp": "1769384004854", "hash": "4b2e1e735d6c8415ff79a4a54e9c91467b1438d2", "bids": [{"price": "0.01", "size": "15"}, {"price": "0.02", "size": "100"}, {"price": "0.03", "size": "60"}, {"price": "0.04", "size": "30"}], "asks": [{"price": "0.99", "size": "10"}, {"price": "0.95", "size": "2030"}, {"price": "0.94", "size": "256"}, {"price": "0.92", "size": "14"}, {"price": "0.89", "size": "18"}, {"price": "0.8", "size": "10"}, {"price": "0.79", "size": "30"}, {"price": "0.78", "size": "10"}, {"price": "0.66", "size": "15"}], "event_type": "book", "last_trade_price": ""}, {"market": "0x33e09845665c7bcd0b3026cdf8c48f4e4d1ae705e0acd863e03525888a3c01c5", "asset_id": "37989116880087250809590393125454376367717533321300643105365874853772585707501", "timestamp": "1769383985996", "hash": "2f588fb9e9c6f8eb5cf2617fd5c1f962ff8e9705", "bids": [{"price": "0.01", "size": "10"}, {"price": "0.02", "size": "150"}, {"price": "0.05", "size": "30"}, {"price": "0.06", "size": "2033"}, {"price": "0.07", "size": "200"}, {"price": "0.08", "size": "25"}, {"price": "0.11", "size": "10"}, {"price": "0.17", "size": "10"}, {"price": "0.3", "size": "40"}, {"price": "0.31", "size": "10"}, {"price": "0.34", "size": "19"}], "asks": [{"price": "0.99", "size": "10"}, {"price": "0.98", "size": "150"}], "event_type": "book", "last_trade_price": ""}, {"market": "0xf281d9254d35ae8355aa5a2aa98fd38c96ba9c604a5526c2cf9e3a2934c1eee3", "asset_id": "89393743445790167235031936569401282709944557561334382371692027993458014466911", "timestamp": "1769383987318", "hash": "78302e770ca9e83bac56c0196a24725f16a531b0", "bids": [{"price": "0.01", "size": "10"}, {"price": "0.02", "size": "200"}], "asks": [{"price": "0.99", "size": "10"}, {"price": "0.95", "size": "30"}, {"price": "0.94", "size": "2033"}, {"price": "0.93", "size": "200"}, {"price": "0.91", "size": "89"}, {"price": "0.87", "size": "15"}, {"price": "0.78", "size": "15"}, {"price": "0.72", "size": "10"}, {"price": "0.68", "size": "30"}, {"price": "0.67", "size": "10"}], "event_type": "book", "last_trade_price": ""}, {"market": "0xa5dfea726fd2d83ac1a27258772cd48851dcee92bc0b27a4cbfbba3f0ce7cf0c", "asset_id": "4176312783107261224228021331826499988248979157870484532774384638562296270852", "timestamp": "1769384006825", "hash": "a7cea6fd7f9cea834f31d18fc11310ee0549266b", "bids": [{"price": "0.01", "size": "1410"}, {"price": "0.02", "size": "1000"}, {"price": "0.05", "size": "30"}, {"price": "0.06", "size": "2933"}, {"price": "0.1", "size": "500"}, {"price": "0.14", "size": "200"}, {"price": "0.21", "size": "160"}, {"price": "0.22", "size": "15"}, {"price": "0.25", "size": "10"}, {"price": "0.27", "size": "10"}, {"price": "0.29", "size": "30"}, {"price": "0.3", "size": "10"}, {"price": "0.61", "size": "150"}], "asks": [{"price": "0.99", "size": "15"}, {"price": "0.98", "size": "100"}, {"price": "0.97", "size": "20"}, {"price": "0.96", "size": "270"}, {"price": "0.95", "size": "20"}], "event_type": "book", "last_trade_price": ""}, {"market": "0xaa46cd9dfbc750e16e767ab71cdfbaaa9f3bbf68153fcb7e9e21bdad1f9a0e4e", "asset_id": "88155858711031400772451028879251834333349215458844495516447987085254946467393", "timestamp": "1769383987149", "hash": "3bff139df2661aed148dca7f986ee93e9e78a7fb", "bids": [{"price": "0.01", "size": "10"}, {"price": "0.02", "size": "150"}, {"price": "0.03", "size": "100"}, {"price": "0.04", "size": "50"}, {"price": "0.05", "size": "20"}, {"price": "0.06", "size": "17"}], "asks": [{"price": "0.99", "size": "10"}, {"price": "0.98", "size": "150"}, {"price": "0.95", "size": "30"}, {"price": "0.94", "size": "2033"}, {"price": "0.93", "size": "200"}, {"price": "0.92", "size": "25"}, {"price": "0.91", "size": "55"}, {"price": "0.85", "size": "10"}, {"price": "0.84", "size": "25"}, {"price": "0.82", "size": "30"}, {"price": "0.81", "size": "10"}, {"price": "0.7", "size": "10.4"}], "event_type": "book", "last_trade_price": ""}, {"market": "0x9897c870e99bb551bcad54acb866b11ea20f18f6a59307b583d41b87dbd8df9b", "asset_id": "107986170040662440391901604090971190646645008770767885800861483401158985093632", "timestamp": "1769384006825", "hash": "1dba5d6dbfc508533a9ce56fafa2ce09d63cb267", "bids": [{"price": "0.01", "size": "10"}, {"price": "0.02", "size": "150"}, {"price": "0.03", "size": "120"}, {"price": "0.04", "size": "60"}, {"price": "0.05", "size": "20"}, {"price": "0.06", "size": "17"}], "asks": [{"price": "0.99", "size": "10"}, {"price": "0.98", "size": "150"}, {"price": "0.95", "size": "30"}, {"price": "0.94", "size": "33"}, {"price": "0.93", "size": "2000"}, {"price": "0.92", "size": "238"}, {"price": "0.91", "size": "22"}, {"price": "0.9", "size": "11"}, {"price": "0.89", "size": "10"}, {"price": "0.77", "size": "15"}, {"price": "0.76", "size": "30"}, {"price": "0.75", "size": "10"}, {"price": "0.7", "size": "39"}], "event_type": "book", "last_trade_price": ""}, {"market": "0x7dbf290d0d7be090e536936f50e92b9ad6e8775ebb9d699892008ba6881ae1c8", "asset_id": "92370345086558298001609149354927257824272307772020776367874444756353703754849", "timestamp": "1769383987150", "hash": "9ac8cbbe51a17f11f33e2753a2e9b40c13fce946", "bids": [{"price": "0.01", "size": "10"}, {"price": "0.02", "size": "150"}, {"price": "0.05", "size": "30"}, {"price": "0.06", "size": "2033"}, {"price": "0.07", "size": "224"}, {"price": "0.13", "size": "33"}, {"price": "0.14", "size": "42"}, {"price": "0.26", "size": "7"}, {"price": "0.28", "size": "10"}, {"price": "0.3", "size": "40"}, {"price": "0.94", "size": "20"}], "asks": [{"price": "0.99", "size": "95"}, {"price": "0.98", "size": "150"}, {"price": "0.95", "size": "200.2"}], "event_type": "book", "last_trade_price": ""}, {"market": "0x3be55688f3eecd53db101048ec9c372230efc90f004c1c4e3fce8dd1d2c4dada", "asset_id": "25385091870387844891345378992524415372478832284204632642650074498441270262521", "timestamp": "1769384004854", "hash": "dfcd6a960274135379276fa0addd9fbfa565d142", "bids": [{"price": "0.01", "size": "10"}, {"price": "0.02", "size": "150"}], "asks": [{"price": "0.99", "size": "10"}, {"price": "0.98", "size": "150"}, {"price": "0.95", "size": "30"}, {"price": "0.94", "size": "2033"}, {"price": "0.93", "size": "200"}, {"price": "0.91", "size": "59"}, {"price": "0.87", "size": "15"}, {"price": "0.82", "size": "25"}, {"price": "0.8", "size": "10"}, {"price": "0.78", "size": "79.16"}, {"price": "0.76", "size": "30"}, {"price": "0.75", "size": "10"}, {"price": "0.64", "size": "15"}], "event_type": "book", "last_trade_price": ""}, {"market": "0x7dbf290d0d7be090e536936f50e92b9ad6e8775ebb9d699892008ba6881ae1c8", "asset_id": "59497151517604206038820337411152370581522020116814993064690346216716079620001", "timestamp": "1769383987150", "hash": "e6a550732e2abdaa76a1d69c2dbd755ef956709c", "bids": [{"price": "0.01", "size": "95"}, {"price": "0.02", "size": "150"}, {"price": "0.05", "size": "200.2"}], "asks": [{"price": "0.99", "size": "10"}, {"price": "0.98", "size": "150"}, {"price": "0.95", "size": "30"}, {"price": "0.94", "size": "2033"}, {"price": "0.93", "size": "224"}, {"price": "0.87", "size": "33"}, {"price": "0.86", "size": "42"}, {"price": "0.74", "size": "7"}, {"price": "0.72", "size": "10"}, {"price": "0.7", "size": "40"}, {"price": "0.06", "size": "20"}], "event_type": "book", "last_trade_price": ""}, {"market": "0xba7bb363782238a06ea70ba7b726292e99d017dd37dd8322a3309b257d5e3a53", "asset_id": "86624152659324411612488193633471157021628076444264217402058630710804185298932", "timestamp": "1769383987149", "hash": "696f8d18e59448e374f3045e31f726b5df66aa84", "bids": [{"price": "0.001", "size": "2576"}, {"price": "0.002", "size": "200"}, {"price": "0.004", "size": "50"}, {"price": "0.01", "size": "10"}, {"price": "0.011", "size": "150"}], "asks": [{"price": "0.999", "size": "2701"}, {"price": "0.998", "size": "250"}, {"price": "0.997", "size": "400"}, {"price": "0.994", "size": "200"}, {"price": "0.99", "size": "10"}, {"price": "0.98", "size": "150"}, {"price": "0.95", "size": "30"}, {"price": "0.949", "size": "39"}, {"price": "0.94", "size": "2000"}, {"price": "0.939", "size": "239"}, {"price": "0.882", "size": "37"}, {"price": "0.844", "size": "12"}, {"price": "0.838", "size": "10"}, {"price": "0.833", "size": "30"}, {"price": "0.832", "size": "19"}, {"price": "0.831", "size": "10"}, {"price": "0.069", "size": "5"}, {"price": "0.068", "size": "15"}], "event_type": "book", "last_trade_price": ""}, {"market": "0xedfafd25484c04cfbeaa767022f9eca5bb680918fceece81b36b0611eb3638a6", "asset_id": "5193041395342261568372064995546886956660044551128159772340877211907014735905", "timestamp": "1769384006825", "hash": "5a09157ddaf167c2f4367ec8aa6f8e5650dd5cb7", "bids": [{"price": "0.01", "size": "10"}], "asks": [{"price": "0.99", "size": "10"}, {"price": "0.95", "size": "30"}, {"price": "0.94", "size": "2033"}, {"price": "0.93", "size": "235"}, {"price": "0.92", "size": "25"}, {"price": "0.9", "size": "11"}, {"price": "0.88", "size": "30"}, {"price": "0.86", "size": "91"}, {"price": "0.85", "size": "20"}, {"price": "0.64", "size": "15"}], "event_type": "book", "last_trade_price": ""}, {"market": "0xe39dbeb302a95a1db7e8ea9d960d938eadf809915d35b010d6b5bdeab9104faa", "asset_id": "92533496956435761714502061273420732955999521880693708251154668927169781104631", "timestamp": "1769383987149", "hash": "711042c36a1521d26d1116d76b128261a1e56d14", "bids": [{"price": "0.001", "size": "2576"}, {"price": "0.002", "size": "200"}, {"price": "0.003", "size": "100"}, {"price": "0.01", "size": "10"}], "asks": [{"price": "0.999", "size": "2819"}, {"price": "0.998", "size": "250"}, {"price": "0.997", "size": "400"}, {"price": "0.994", "size": "200"}, {"price": "0.99", "size": "1410"}, {"price": "0.98", "size": "1150"}, {"price": "0.95", "size": "30"}, {"price": "0.949", "size": "39"}, {"price": "0.941", "size": "2900"}, {"price": "0.92", "size": "500"}, {"price": "0.86", "size": "200"}, {"price": "0.858", "size": "7"}, {"price": "0.857", "size": "13"}, {"price": "0.696", "size": "10"}, {"price": "0.694", "size": "22"}, {"price": "0.692", "size": "30"}, {"price": "0.691", "size": "10"}, {"price": "0.095", "size": "5"}, {"price": "0.09", "size": "1000"}, {"price": "0.089", "size": "15"}], "event_type": "book", "last_trade_price": ""}, {"market": "0x9897c870e99bb551bcad54acb866b11ea20f18f6a59307b583d41b87dbd8df9b", "asset_id": "83125160625335845669305131102145331159652617545862153009199309232015574885824", "timestamp": "1769384006825", "hash": "1a3fbf2b3957e65fb8377bb6f761dc9eccb5151d", "bids": [{"price": "0.01", "size": "10"}, {"price": "0.02", "size": "150"}, {"price": "0.05", "size": "30"}, {"price": "0.06", "size": "33"}, {"price": "0.07", "size": "2000"}, {"price": "0.08", "size": "238"}, {"price": "0.09", "size": "22"}, {"price": "0.1", "size": "11"}, {"price": "0.11", "size": "10"}, {"price": "0.23", "size": "15"}, {"price": "0.24", "size": "30"}, {"price": "0.25", "size": "10"}, {"price": "0.3", "size": "39"}], "asks": [{"price": "0.99", "size": "10"}, {"price": "0.98", "size": "150"}, {"price": "0.97", "size": "120"}, {"price": "0.96", "size": "60"}, {"price": "0.95", "size": "20"}, {"price": "0.94", "size": "17"}], "event_type": "book", "last_trade_price": ""}, {"market": "0xa5dfea726fd2d83ac1a27258772cd48851dcee92bc0b27a4cbfbba3f0ce7cf0c", "asset_id": "64980057195304605902961943648606034709103501739113681540832298163772674344737", "timestamp": "1769384006825", "hash": "feea72bdb905246284daaabe1644c4f3a99c0d0f", "bids": [{"price": "0.01", "size": "15"}, {"price": "0.02", "size": "100"}, {"price": "0.03", "size": "20"}, {"price": "0.04", "size": "270"}, {"price": "0.05", "size": "20"}], "asks": [{"price": "0.99", "size": "1410"}, {"price": "0.98", "size": "1000"}, {"price": "0.95", "size": "30"}, {"price": "0.94", "size": "2933"}, {"price": "0.9", "size": "500"}, {"price": "0.86", "size": "200"}, {"price": "0.79", "size": "160"}, {"price": "0.78", "size": "15"}, {"price": "0.75", "size": "10"}, {"price": "0.73", "size": "10"}, {"price": "0.71", "size": "30"}, {"price": "0.7", "size": "10"}, {"price": "0.39", "size": "150"}], "event_type": "book", "last_trade_price": ""}, {"market": "0x96449838d7dc6702e356ceb13144a6e53408b728ca363dc96b379320a2552d64", "asset_id": "88669991566060336244616088283363604665361049459599965771564136419124853077521", "timestamp": "1769383987150", "hash": "91ebf6d9fd00a3a06deba453a1f9b08c52e6bf2f", "bids": [{"price": "0.01", "size": "210"}, {"price": "0.02", "size": "150"}, {"price": "0.05", "size": "2030"}, {"price": "0.06", "size": "256"}, {"price": "0.08", "size": "14"}, {"price": "0.09", "size": "10"}, {"price": "0.1", "size": "30"}, {"price": "0.11", "size": "10"}, {"price": "0.31", "size": "54"}], "asks": [{"price": "0.99", "size": "10"}, {"price": "0.98", "size": "150"}, {"price": "0.97", "size": "120"}, {"price": "0.96", "size": "60"}, {"price": "0.95", "size": "20"}], "event_type": "book", "last_trade_price": ""}, {"market": "0x3be55688f3eecd53db101048ec9c372230efc90f004c1c4e3fce8dd1d2c4dada", "asset_id": "85304840619071051396870312932957819961814877219759465827862543288479782634253", "timestamp": "1769384004854", "hash": "1894568d2686db1b1055fa1ed70329fe2c3ff966", "bids": [{"price": "0.01", "size": "10"}, {"price": "0.02", "size": "150"}, {"price": "0.05", "size": "30"}, {"price": "0.06", "size": "2033"}, {"price": "0.07", "size": "200"}, {"price": "0.09", "size": "59"}, {"price": "0.13", "size": "15"}, {"price": "0.18", "size": "25"}, {"price": "0.2", "size": "10"}, {"price": "0.22", "size": "79.16"}, {"price": "0.24", "size": "30"}, {"price": "0.25", "size": "10"}, {"price": "0.36", "size": "15"}], "asks": [{"price": "0.99", "size": "10"}, {"price": "0.98", "size": "150"}], "event_type": "book", "last_trade_price": ""}, {"market": "0xaa46cd9dfbc750e16e767ab71cdfbaaa9f3bbf68153fcb7e9e21bdad1f9a0e4e", "asset_id": "10190047580304467488950735708592587854326252278861442489701414156559786950928", "timestamp": "1769383987149", "hash": "1bcfe795442f03f3836b6ccff8b9e311332a2fea", "bids": [{"price": "0.01", "size": "10"}, {"price": "0.02", "size": "150"}, {"price": "0.05", "size": "30"}, {"price": "0.06", "size": "2033"}, {"price": "0.07", "size": "200"}, {"price": "0.08", "size": "25"}, {"price": "0.09", "size": "55"}, {"price": "0.15", "size": "10"}, {"price": "0.16", "size": "25"}, {"price": "0.18", "size": "30"}, {"price": "0.19", "size": "10"}, {"price": "0.3", "size": "10.4"}], "asks": [{"price": "0.99", "size": "10"}, {"price": "0.98", "size": "150"}, {"price": "0.97", "size": "100"}, {"price": "0.96", "size": "50"}, {"price": "0.95", "size": "20"}, {"price": "0.94", "size": "17"}], "event_type": "book", "last_trade_price": ""}, {"market": "0x96449838d7dc6702e356ceb13144a6e53408b728ca363dc96b379320a2552d64", "asset_id": "98265373238824778819853870879462811197150130214114951682085083828419115905786", "timestamp": "1769383987150", "hash": "8a5c217dfe11a29fa1abac93a7d91d54025f56a9", "bids": [{"price": "0.01", "size": "10"}, {"price": "0.02", "size": "150"}, {"price": "0.03", "size": "120"}, {"price": "0.04", "size": "60"}, {"price": "0.05", "size": "20"}], "asks": [{"price": "0.99", "size": "210"}, {"price": "0.98", "size": "150"}, {"price": "0.95", "size": "2030"}, {"price": "0.94", "size": "256"}, {"price": "0.92", "size": "14"}, {"price": "0.91", "size": "10"}, {"price": "0.9", "size": "30"}, {"price": "0.89", "size": "10"}, {"price": "0.69", "size": "54"}], "event_type": "book", "last_trade_price": ""}]}
{"_local_timestamp": "2026-01-25T23:33:54.215223+00:00", "data": {"market": "0x3be55688f3eecd53db101048ec9c372230efc90f004c1c4e3fce8dd1d2c4dada", "price_changes": [{"asset_id": "85304840619071051396870312932957819961814877219759465827862543288479782634253", "price": "0.22", "size": "0", "side": "BUY", "hash": "3303748302c846def4cf68f8c53b3a78d7721305", "best_bid": "0.36", "best_ask": "0.98"}, {"asset_id": "25385091870387844891345378992524415372478832284204632642650074498441270262521", "price": "0.78", "size": "0", "side": "SELL", "hash": "fae13a8a78bd902e61da24e665efda3fc0281977", "best_bid": "0.02", "best_ask": "0.64"}], "timestamp": "1769384034133", "event_type": "price_change"}}
{"_local_timestamp": "2026-01-25T23:33:54.361291+00:00", "data": {"market": "0x3be55688f3eecd53db101048ec9c372230efc90f004c1c4e3fce8dd1d2c4dada", "price_changes": [{"asset_id": "85304840619071051396870312932957819961814877219759465827862543288479782634253", "price": "0.18", "size": "10", "side": "BUY", "hash": "900321de1c935d4be6dd01f2e71d124e56a7c25b", "best_bid": "0.36", "best_ask": "0.98"}, {"asset_id": "25385091870387844891345378992524415372478832284204632642650074498441270262521", "price": "0.82", "size": "10", "side": "SELL", "hash": "acdaef6543a788d3e43bece8b4f117033fe1b4e3", "best_bid": "0.02", "best_ask": "0.64"}], "timestamp": "1769384034285", "event_type": "price_change"}}
{"_local_timestamp": "2026-01-25T23:34:42.346554+00:00", "data": {"market": "0x96449838d7dc6702e356ceb13144a6e53408b728ca363dc96b379320a2552d64", "price_changes": [{"asset_id": "98265373238824778819853870879462811197150130214114951682085083828419115905786", "price": "0.69", "size": "39", "side": "SELL", "hash": "bdf15c577641d7602ef5e5a2df13fe14223ecb04", "best_bid": "0.05", "best_ask": "0.69"}, {"asset_id": "88669991566060336244616088283363604665361049459599965771564136419124853077521", "price": "0.31", "size": "39", "side": "BUY", "hash": "a7e21240d43957b6007308a763d7c0915a677041", "best_bid": "0.31", "best_ask": "0.95"}], "timestamp": "1769384082282", "event_type": "price_change"}}
{"_local_timestamp": "2026-01-25T23:34:42.347583+00:00", "data": {"market": "0xedfafd25484c04cfbeaa767022f9eca5bb680918fceece81b36b0611eb3638a6", "price_changes": [{"asset_id": "5193041395342261568372064995546886956660044551128159772340877211907014735905", "price": "0.64", "size": "0", "side": "SELL", "hash": "afce4e2f9a5687763b225306cc58ac4f06da21e9", "best_bid": "0.01", "best_ask": "0.85"}, {"asset_id": "69100260301420797247941786085257042358554422352183746124379790103566465901104", "price": "0.36", "size": "0", "side": "BUY", "hash": "01eb4c7d54d56d6dc22ec5d1089e416b088ab09a", "best_bid": "0.15", "best_ask": "0.99"}], "timestamp": "1769384082282", "event_type": "price_change"}}
{"_local_timestamp": "2026-01-25T23:34:42.354025+00:00", "data": {"market": "0x3be55688f3eecd53db101048ec9c372230efc90f004c1c4e3fce8dd1d2c4dada", "price_changes": [{"asset_id": "25385091870387844891345378992524415372478832284204632642650074498441270262521", "price": "0.64", "size": "0", "side": "SELL", "hash": "173d7e78bc2638cfcb572cbce7983a7300d09774", "best_bid": "0.02", "best_ask": "0.75"}, {"asset_id": "85304840619071051396870312932957819961814877219759465827862543288479782634253", "price": "0.36", "size": "0", "side": "BUY", "hash": "eb277fc69d9b0f513b172c46716c0e8ea1ad3808", "best_bid": "0.25", "best_ask": "0.98"}], "timestamp": "1769384082282", "event_type": "price_change"}}
{"_local_timestamp": "2026-01-25T23:34:42.354618+00:00", "data": {"market": "0x9ad98d277747a5af33029daa93d8921e20dc48fc43a13444b34abd5db3090419", "price_changes": [{"asset_id": "13106897552498929473034004606662562096233616324310660731332487169842346464915", "price": "0.66", "size": "0", "side": "SELL", "hash": "6aba55cab671b205a2d080d46c73ed60ddd9eb1b", "best_bid": "0.04", "best_ask": "0.78"}, {"asset_id": "84279332923568891895771507663060971052533473524984039519051747621941395607490", "price": "0.34", "size": "0", "side": "BUY", "hash": "df1e02563efef34e46ddaa4ff8a41cd99d36a124", "best_bid": "0.22", "best_ask": "0.96"}], "timestamp": "1769384082282", "event_type": "price_change"}}
{"_local_timestamp": "2026-01-25T23:34:42.498763+00:00", "data": {"market": "0x3be55688f3eecd53db101048ec9c372230efc90f004c1c4e3fce8dd1d2c4dada", "price_changes": [{"asset_id": "85304840619071051396870312932957819961814877219759465827862543288479782634253", "price": "0.18", "size": "0", "side": "BUY", "hash": "383b3b2f3c2ae501287ff6eb0563aff2a0df4d45", "best_bid": "0.25", "best_ask": "0.98"}, {"asset_id": "25385091870387844891345378992524415372478832284204632642650074498441270262521", "price": "0.82", "size": "0", "side": "SELL", "hash": "cd93ccc8301b2b179fb528fde4400fe60e1fe0fe", "best_bid": "0.02", "best_ask": "0.75"}], "timestamp": "1769384082434", "event_type": "price_change"}}
{"_local_timestamp": "2026-01-25T23:34:42.591100+00:00", "data": {"market": "0x3be55688f3eecd53db101048ec9c372230efc90f004c1c4e3fce8dd1d2c4dada", "price_changes": [{"asset_id": "85304840619071051396870312932957819961814877219759465827862543288479782634253", "price": "0.26", "size": "15", "side": "BUY", "hash": "d13282a80532c254b0c648421fd75bb5399a231f", "best_bid": "0.26", "best_ask": "0.98"}, {"asset_id": "25385091870387844891345378992524415372478832284204632642650074498441270262521", "price": "0.74", "size": "15", "side": "SELL", "hash": "60fe8c0e57900125767abddada5d0a22591a6973", "best_bid": "0.02", "best_ask": "0.74"}], "timestamp": "1769384082526", "event_type": "price_change"}}
{"_local_timestamp": "2026-01-25T23:34:42.591459+00:00", "data": {"market": "0x3be55688f3eecd53db101048ec9c372230efc90f004c1c4e3fce8dd1d2c4dada", "price_changes": [{"asset_id": "85304840619071051396870312932957819961814877219759465827862543288479782634253", "price": "0.26", "size": "25", "side": "BUY", "hash": "64085ec013bd52f994b880901c2385d20970cee5", "best_bid": "0.26", "best_ask": "0.98"}, {"asset_id": "25385091870387844891345378992524415372478832284204632642650074498441270262521", "price": "0.74", "size": "25", "side": "SELL", "hash": "9521634b3b638920e0bb311adf277b61d5d4b254", "best_bid": "0.02", "best_ask": "0.74"}], "timestamp": "1769384082527", "event_type": "price_change"}}
{"_local_timestamp": "2026-01-25T23:34:43.145834+00:00", "data": {"market": "0xedfafd25484c04cfbeaa767022f9eca5bb680918fceece81b36b0611eb3638a6", "price_changes": [{"asset_id": "5193041395342261568372064995546886956660044551128159772340877211907014735905", "price": "0.84", "size": "15", "side": "SELL", "hash": "99fdf5c33ca56737b400459c0a8d977c8466a26e", "best_bid": "0.01", "best_ask": "0.84"}, {"asset_id": "69100260301420797247941786085257042358554422352183746124379790103566465901104", "price": "0.16", "size": "15", "side": "BUY", "hash": "1c5b9a572b6b0c8d59d77f93d8313b32635737b2", "best_bid": "0.16", "best_ask": "0.99"}], "timestamp": "1769384083064", "event_type": "price_change"}}
{"_local_timestamp": "2026-01-25T23:34:43.146566+00:00", "data": {"market": "0x3be55688f3eecd53db101048ec9c372230efc90f004c1c4e3fce8dd1d2c4dada", "price_changes": [{"asset_id": "25385091870387844891345378992524415372478832284204632642650074498441270262521", "price": "0.74", "size": "40", "side": "SELL", "hash": "89cb62af6729945ea8d503ac152385006b1fcd9a", "best_bid": "0.02", "best_ask": "0.74"}, {"asset_id": "85304840619071051396870312932957819961814877219759465827862543288479782634253", "price": "0.26", "size": "40", "side": "BUY", "hash": "acaa26a4f2c52c0bf4d25c4aedeecbe16acc6352", "best_bid": "0.26", "best_ask": "0.98"}], "timestamp": "1769384083064", "event_type": "price_change"}}
{"_local_timestamp": "2026-01-25T23:34:43.147082+00:00", "data": {"market": "0x9ad98d277747a5af33029daa93d8921e20dc48fc43a13444b34abd5db3090419", "price_changes": [{"asset_id": "13106897552498929473034004606662562096233616324310660731332487169842346464915", "price": "0.77", "size": "15", "side": "SELL", "hash": "2de340b54eed5914f77d840e7ca8820879b4de75", "best_bid": "0.04", "best_ask": "0.77"}, {"asset_id": "84279332923568891895771507663060971052533473524984039519051747621941395607490", "price": "0.23", "size": "15", "side": "BUY", "hash": "abb3d8c3c1022ec43419b2476f847559c0047360", "best_bid": "0.23", "best_ask": "0.96"}], "timestamp": "1769384083064", "event_type": "price_change"}}
{"_local_timestamp": "2026-01-25T23:34:43.147434+00:00", "data": {"market": "0x96449838d7dc6702e356ceb13144a6e53408b728ca363dc96b379320a2552d64", "price_changes": [{"asset_id": "98265373238824778819853870879462811197150130214114951682085083828419115905786", "price": "0.88", "size": "15", "side": "SELL", "hash": "0e9a003e7dd05ef2bae33488504c7a105462d3f1", "best_bid": "0.05", "best_ask": "0.69"}, {"asset_id": "88669991566060336244616088283363604665361049459599965771564136419124853077521", "price": "0.12", "size": "15", "side": "BUY", "hash": "5bdbf29c307635c293a46bc6ec52dbf7a3e54f71", "best_bid": "0.31", "best_ask": "0.95"}], "timestamp": "1769384083064", "event_type": "price_change"}}
{"_local_timestamp": "2026-01-25T23:34:47.865232+00:00", "data": {"market": "0xedfafd25484c04cfbeaa767022f9eca5bb680918fceece81b36b0611eb3638a6", "price_changes": [{"asset_id": "69100260301420797247941786085257042358554422352183746124379790103566465901104", "price": "0.15", "size": "0", "side": "BUY", "hash": "b567849bf4372d628403589fded8ea324b96faa7", "best_bid": "0.16", "best_ask": "0.99"}, {"asset_id": "5193041395342261568372064995546886956660044551128159772340877211907014735905", "price": "0.85", "size": "0", "side": "SELL", "hash": "2ddb7789af90d7b47d290ebf7cd03e636e1e8a73", "best_bid": "0.01", "best_ask": "0.84"}], "timestamp": "1769384087800", "event_type": "price_change"}}
{"_local_timestamp": "2026-01-25T23:34:47.865630+00:00", "data": {"market": "0x3be55688f3eecd53db101048ec9c372230efc90f004c1c4e3fce8dd1d2c4dada", "price_changes": [{"asset_id": "85304840619071051396870312932957819961814877219759465827862543288479782634253", "price": "0.25", "size": "0", "side": "BUY", "hash": "73b017cd7dfad2eb6235de27d03d4083654e2f2b", "best_bid": "0.26", "best_ask": "0.98"}, {"asset_id": "25385091870387844891345378992524415372478832284204632642650074498441270262521", "price": "0.75", "size": "0", "side": "SELL", "hash": "35ae17e2ab232658c06e36ccbeda1e904e793599", "best_bid": "0.02", "best_ask": "0.74"}], "timestamp": "1769384087800", "event_type": "price_change"}}
{"_local_timestamp": "2026-01-25T23:34:47.865944+00:00", "data": {"market": "0x9ad98d277747a5af33029daa93d8921e20dc48fc43a13444b34abd5db3090419", "price_changes": [{"asset_id": "84279332923568891895771507663060971052533473524984039519051747621941395607490", "price": "0.22", "size": "0", "side": "BUY", "hash": "479b04412a620676251a7751397d3e47ee5ce1e3", "best_bid": "0.23", "best_ask": "0.96"}, {"asset_id": "13106897552498929473034004606662562096233616324310660731332487169842346464915", "price": "0.78", "size": "0", "side": "SELL", "hash": "4900f083107335ef46a7ec480c23dbf209db103b", "best_bid": "0.04", "best_ask": "0.77"}], "timestamp": "1769384087800", "event_type": "price_change"}}
{"_local_timestamp": "2026-01-25T23:34:47.866235+00:00", "data": {"market": "0x96449838d7dc6702e356ceb13144a6e53408b728ca363dc96b379320a2552d64", "price_changes": [{"asset_id": "88669991566060336244616088283363604665361049459599965771564136419124853077521", "price": "0.11", "size": "0", "side": "BUY", "hash": "d7ef99df37cfd62085594625fa53b13ffaceae1c", "best_bid": "0.31", "best_ask": "0.95"}, {"asset_id": "98265373238824778819853870879462811197150130214114951682085083828419115905786", "price": "0.89", "size": "0", "side": "SELL", "hash": "cd8a801bc664d1c4867b938bd579f038adbe7ecb", "best_bid": "0.05", "best_ask": "0.69"}], "timestamp": "1769384087800", "event_type": "price_change"}}
{"_local_timestamp": "2026-01-25T23:34:47.893150+00:00", "data": {"market": "0x96449838d7dc6702e356ceb13144a6e53408b728ca363dc96b379320a2552d64", "price_changes": [{"asset_id": "88669991566060336244616088283363604665361049459599965771564136419124853077521", "price": "0.13", "size": "10", "side": "BUY", "hash": "68dbf60760d8320bcc068d1ad94e5d02874b5a77", "best_bid": "0.31", "best_ask": "0.95"}, {"asset_id": "98265373238824778819853870879462811197150130214114951682085083828419115905786", "price": "0.87", "size": "10", "side": "SELL", "hash": "cf24773b3321cfb1746a76241070085be7362c26", "best_bid": "0.05", "best_ask": "0.69"}], "timestamp": "1769384087827", "event_type": "price_change"}}
{"_local_timestamp": "2026-01-25T23:34:47.893574+00:00", "data": {"market": "0xedfafd25484c04cfbeaa767022f9eca5bb680918fceece81b36b0611eb3638a6", "price_changes": [{"asset_id": "69100260301420797247941786085257042358554422352183746124379790103566465901104", "price": "0.17", "size": "20", "side": "BUY", "hash": "71ad93c5773f8e54a4e43a2e0fc8c695db391a79", "best_bid": "0.17", "best_ask": "0.99"}, {"asset_id": "5193041395342261568372064995546886956660044551128159772340877211907014735905", "price": "0.83", "size": "20", "side": "SELL", "hash": "1a175ad0f4da44281aff30551dd04f18d8191fb9", "best_bid": "0.01", "best_ask": "0.83"}], "timestamp": "1769384087827", "event_type": "price_change"}}
{"_local_timestamp": "2026-01-25T23:34:47.893874+00:00", "data": {"market": "0x3be55688f3eecd53db101048ec9c372230efc90f004c1c4e3fce8dd1d2c4dada", "price_changes": [{"asset_id": "85304840619071051396870312932957819961814877219759465827862543288479782634253", "price": "0.27", "size": "10", "side": "BUY", "hash": "841bc91e7aea503612cf522a6948fd48692d48bc", "best_bid": "0.27", "best_ask": "0.98"}, {"asset_id": "25385091870387844891345378992524415372478832284204632642650074498441270262521", "price": "0.73", "size": "10", "side": "SELL", "hash": "d79918a560018573b8fed287192ba0247d06e904", "best_bid": "0.02", "best_ask": "0.73"}], "timestamp": "1769384087827", "event_type": "price_change"}}
{"_local_timestamp": "2026-01-25T23:34:47.894244+00:00", "data": {"market": "0x9ad98d277747a5af33029daa93d8921e20dc48fc43a13444b34abd5db3090419", "price_changes": [{"asset_id": "84279332923568891895771507663060971052533473524984039519051747621941395607490", "price": "0.24", "size": "10", "side": "BUY", "hash": "f9f6a6b58490a485aa6169b82facda5da01ec760", "best_bid": "0.24", "best_ask": "0.96"}, {"asset_id": "13106897552498929473034004606662562096233616324310660731332487169842346464915", "price": "0.76", "size": "10", "side": "SELL", "hash": "79182ab4eed2d4c87b8276a76ac804e8a2f20f7a", "best_bid": "0.04", "best_ask": "0.76"}], "timestamp": "1769384087827", "event_type": "price_change"}}
{"_local_timestamp": "2026-01-25T23:35:41.573753+00:00", "data": {"market": "0x9897c870e99bb551bcad54acb866b11ea20f18f6a59307b583d41b87dbd8df9b", "price_changes": [{"asset_id": "83125160625335845669305131102145331159652617545862153009199309232015574885824", "price": "0.26", "size": "39", "side": "BUY", "hash": "13d91bb012441987885dc5e98b6cf1f598ee5863", "best_bid": "0.3", "best_ask": "0.94"}, {"asset_id": "107986170040662440391901604090971190646645008770767885800861483401158985093632", "price": "0.74", "size": "39", "side": "SELL", "hash": "a21955159459ad5ce67045d876ccf74bfc94baa9", "best_bid": "0.06", "best_ask": "0.7"}], "timestamp": "1769384141499", "event_type": "price_change"}}
{"_local_timestamp": "2026-01-25T23:35:41.574555+00:00", "data": {"market": "0x96449838d7dc6702e356ceb13144a6e53408b728ca363dc96b379320a2552d64", "price_changes": [{"asset_id": "88669991566060336244616088283363604665361049459599965771564136419124853077521", "price": "0.14", "size": "79.16", "side": "BUY", "hash": "308348055d05a3e569c5bd4f608092a919b5a62c", "best_bid": "0.31", "best_ask": "0.95"}, {"asset_id": "98265373238824778819853870879462811197150130214114951682085083828419115905786", "price": "0.86", "size": "79.16", "side": "SELL", "hash": "2263bb9351cebfb6e1682882f93bbaffc2e384f3", "best_bid": "0.05", "best_ask": "0.69"}], "timestamp": "1769384141499", "event_type": "price_change"}}
{"_local_timestamp": "2026-01-25T23:35:41.574857+00:00", "data": {"market": "0xaa46cd9dfbc750e16e767ab71cdfbaaa9f3bbf68153fcb7e9e21bdad1f9a0e4e", "price_changes": [{"asset_id": "10190047580304467488950735708592587854326252278861442489701414156559786950928", "price": "0.2", "size": "79.16", "side": "BUY", "hash": "e36be1a3316ac326320a88fbb0dabbd6b262ab18", "best_bid": "0.3", "best_ask": "0.94"}, {"asset_id": "88155858711031400772451028879251834333349215458844495516447987085254946467393", "price": "0.8", "size": "79.16", "side": "SELL", "hash": "414d7571b535240d33caf80db4373fee3d3b778c", "best_bid": "0.06", "best_ask": "0.7"}], "timestamp": "1769384141499", "event_type": "price_change"}}
{"_local_timestamp": "2026-01-25T23:35:41.575185+00:00", "data": {"market": "0xf281d9254d35ae8355aa5a2aa98fd38c96ba9c604a5526c2cf9e3a2934c1eee3", "price_changes": [{"asset_id": "9395139935407818232687755250472957071183406150419861658575355254022011268877", "price": "0.34", "size": "19", "side": "BUY", "hash": "48b504734b673483d53cee59e924c031eff59f1d", "best_bid": "0.34", "best_ask": "0.98"}, {"asset_id": "89393743445790167235031936569401282709944557561334382371692027993458014466911", "price": "0.66", "size": "19", "side": "SELL", "hash": "00e3c90342d1b411d129000de72696b81c42d23b", "best_bid": "0.02", "best_ask": "0.66"}], "timestamp": "1769384141499", "event_type": "price_change"}}
{"_local_timestamp": "2026-01-25T23:35:41.575507+00:00", "data": {"market": "0xedfafd25484c04cfbeaa767022f9eca5bb680918fceece81b36b0611eb3638a6", "price_changes": [{"asset_id": "69100260301420797247941786085257042358554422352183746124379790103566465901104", "price": "0.18", "size": "79.16", "side": "BUY", "hash": "7d6df66abd36c35d8999fcc49e18136b867427d5", "best_bid": "0.18", "best_ask": "0.99"}, {"asset_id": "5193041395342261568372064995546886956660044551128159772340877211907014735905", "price": "0.82", "size": "79.16", "side": "SELL", "hash": "feb54f490fd900b90c0c4f6ac56339ab96aa9a33", "best_bid": "0.01", "best_ask": "0.82"}], "timestamp": "1769384141499", "event_type": "price_change"}}
{"_local_timestamp": "2026-01-25T23:35:41.575806+00:00", "data": {"market": "0x9ad98d277747a5af33029daa93d8921e20dc48fc43a13444b34abd5db3090419", "price_changes": [{"asset_id": "84279332923568891895771507663060971052533473524984039519051747621941395607490", "price": "0.24", "size": "89.16", "side": "BUY", "hash": "1ea9b3e2488fd589bf0f27fb8c8d9ec088d7711d", "best_bid": "0.24", "best_ask": "0.96"}, {"asset_id": "13106897552498929473034004606662562096233616324310660731332487169842346464915", "price": "0.76", "size": "89.16", "side": "SELL", "hash": "719e4ab676e4095e03e7398d811cfb1ce70fd656", "best_bid": "0.04", "best_ask": "0.76"}], "timestamp": "1769384141499", "event_type": "price_change"}}
{"_local_timestamp": "2026-01-25T23:35:41.576114+00:00", "data": {"market": "0xaa46cd9dfbc750e16e767ab71cdfbaaa9f3bbf68153fcb7e9e21bdad1f9a0e4e", "price_changes": [{"asset_id": "10190047580304467488950735708592587854326252278861442489701414156559786950928", "price": "0.31", "size": "19", "side": "BUY", "hash": "e726965b99cdf7b666866382712a7b253ae43e2a", "best_bid": "0.31", "best_ask": "0.94"}, {"asset_id": "88155858711031400772451028879251834333349215458844495516447987085254946467393", "price": "0.69", "size": "19", "side": "SELL", "hash": "dc6187bdb1448eaf800dd16dcee81159f335c174", "best_bid": "0.06", "best_ask": "0.69"}], "timestamp": "1769384141499", "event_type": "price_change"}}
{"_local_timestamp": "2026-01-25T23:35:41.576435+00:00", "data": {"market": "0x9897c870e99bb551bcad54acb866b11ea20f18f6a59307b583d41b87dbd8df9b", "price_changes": [{"asset_id": "83125160625335845669305131102145331159652617545862153009199309232015574885824", "price": "0.25", "size": "89.16", "side": "BUY", "hash": "3a735df522645fb3d1f135bd5b4972e21fddfe24", "best_bid": "0.3", "best_ask": "0.94"}, {"asset_id": "107986170040662440391901604090971190646645008770767885800861483401158985093632", "price": "0.75", "size": "89.16", "side": "SELL", "hash": "13f629e5b8267255f1f0b2e73b02f7cb1105957c", "best_bid": "0.06", "best_ask": "0.7"}], "timestamp": "1769384141500", "event_type": "price_change"}}
{"_local_timestamp": "2026-01-25T23:35:41.576765+00:00", "data": {"market": "0xedfafd25484c04cfbeaa767022f9eca5bb680918fceece81b36b0611eb3638a6", "price_changes": [{"asset_id": "69100260301420797247941786085257042358554422352183746124379790103566465901104", "price": "0.17", "size": "99.16", "side": "BUY", "hash": "1f2821a24556d3a579ff9afd5868f623426b5298", "best_bid": "0.18", "best_ask": "0.99"}, {"asset_id": "5193041395342261568372064995546886956660044551128159772340877211907014735905", "price": "0.83", "size": "99.16", "side": "SELL", "hash": "7529d5c31998e03fc69947b4ce747099ef78e924", "best_bid": "0.01", "best_ask": "0.82"}], "timestamp": "1769384141500", "event_type": "price_change"}}
{"_local_timestamp": "2026-01-25T23:35:41.577692+00:00", "data": {"market": "0x3be55688f3eecd53db101048ec9c372230efc90f004c1c4e3fce8dd1d2c4dada", "price_changes": [{"asset_id": "85304840619071051396870312932957819961814877219759465827862543288479782634253", "price": "0.28", "size": "79.16", "side": "BUY", "hash": "c0e7c9380fe16dd4f287c10fb0bce275fe0399a7", "best_bid": "0.28", "best_ask": "0.98"}, {"asset_id": "25385091870387844891345378992524415372478832284204632642650074498441270262521", "price": "0.72", "size": "79.16", "side": "SELL", "hash": "1539952538be6cbd8b636d42bd5fcec7b8ced387", "best_bid": "0.02", "best_ask": "0.72"}], "timestamp": "1769384141499", "event_type": "price_change"}}
{"_local_timestamp": "2026-01-25T23:35:41.690250+00:00", "data": {"market": "0x96449838d7dc6702e356ceb13144a6e53408b728ca363dc96b379320a2552d64", "price_changes": [{"asset_id": "88669991566060336244616088283363604665361049459599965771564136419124853077521", "price": "0.13", "size": "89.16", "side": "BUY", "hash": "50313b9ee89108eb11fb34879bcf05fae0fd5ab1", "best_bid": "0.31", "best_ask": "0.95"}, {"asset_id": "98265373238824778819853870879462811197150130214114951682085083828419115905786", "price": "0.87", "size": "89.16", "side": "SELL", "hash": "507b33d75e4cff2d1006c25efa208ef09f594585", "best_bid": "0.05", "best_ask": "0.69"}], "timestamp": "1769384141500", "event_type": "price_change"}}
{"_local_timestamp": "2026-01-25T23:35:41.690646+00:00", "data": {"market": "0x9ad98d277747a5af33029daa93d8921e20dc48fc43a13444b34abd5db3090419", "price_changes": [{"asset_id": "84279332923568891895771507663060971052533473524984039519051747621941395607490", "price": "0.25", "size": "79.16", "side": "BUY", "hash": "32178b8840cc99ff0e3c32aeb545f312a5cd554f", "best_bid": "0.25", "best_ask": "0.96"}, {"asset_id": "13106897552498929473034004606662562096233616324310660731332487169842346464915", "price": "0.75", "size": "79.16", "side": "SELL", "hash": "6917a1ac45615a4b79572f0ce7b80a74de5188e9", "best_bid": "0.04", "best_ask": "0.75"}], "timestamp": "1769384141500", "event_type": "price_change"}}
{"_local_timestamp": "2026-01-25T23:35:41.690981+00:00", "data": {"market": "0x3be55688f3eecd53db101048ec9c372230efc90f004c1c4e3fce8dd1d2c4dada", "price_changes": [{"asset_id": "85304840619071051396870312932957819961814877219759465827862543288479782634253", "price": "0.27", "size": "89.16", "side": "BUY", "hash": "2c8f32f0579f5e41aec9b4758ddb96367f40e39a", "best_bid": "0.28", "best_ask": "0.98"}, {"asset_id": "25385091870387844891345378992524415372478832284204632642650074498441270262521", "price": "0.73", "size": "89.16", "side": "SELL", "hash": "e07f978e0e7f4402523e8eb3ac69d5144cc64361", "best_bid": "0.02", "best_ask": "0.72"}], "timestamp": "1769384141500", "event_type": "price_change"}}
{"_local_timestamp": "2026-01-25T23:35:41.691492+00:00", "data": {"market": "0xf281d9254d35ae8355aa5a2aa98fd38c96ba9c604a5526c2cf9e3a2934c1eee3", "price_changes": [{"asset_id": "9395139935407818232687755250472957071183406150419861658575355254022011268877", "price": "0.32", "size": "0", "side": "BUY", "hash": "a4ea8617d7f32205340955b4a03c2b004a7138f7", "best_bid": "0.34", "best_ask": "0.98"}, {"asset_id": "89393743445790167235031936569401282709944557561334382371692027993458014466911", "price": "0.68", "size": "0", "side": "SELL", "hash": "36d6f4f9c3e941a730dd743ba83bc74c86a10859", "best_bid": "0.02", "best_ask": "0.66"}], "timestamp": "1769384141564", "event_type": "price_change"}}
{"_local_timestamp": "2026-01-25T23:35:41.702431+00:00", "data": {"market": "0xedfafd25484c04cfbeaa767022f9eca5bb680918fceece81b36b0611eb3638a6", "price_changes": [{"asset_id": "69100260301420797247941786085257042358554422352183746124379790103566465901104", "price": "0.07", "size": "200", "side": "BUY", "hash": "713ba14e2f795ed01c299d92bc116ddbab29c66f", "best_bid": "0.18", "best_ask": "0.99"}, {"asset_id": "5193041395342261568372064995546886956660044551128159772340877211907014735905", "price": "0.93", "size": "200", "side": "SELL", "hash": "7de31faba9ee77523825f1d7a92645f8365b3533", "best_bid": "0.01", "best_ask": "0.82"}], "timestamp": "1769384141638", "event_type": "price_change"}}
{"_local_timestamp": "2026-01-25T23:35:41.702834+00:00", "data": {"market": "0xaa46cd9dfbc750e16e767ab71cdfbaaa9f3bbf68153fcb7e9e21bdad1f9a0e4e", "price_changes": [{"asset_id": "10190047580304467488950735708592587854326252278861442489701414156559786950928", "price": "0.16", "size": "15", "side": "BUY", "hash": "9d08f07d3cf0ffba5749ea5ee8ef703bdba09c78", "best_bid": "0.31", "best_ask": "0.94"}, {"asset_id": "88155858711031400772451028879251834333349215458844495516447987085254946467393", "price": "0.84", "size": "15", "side": "SELL", "hash": "a67cb4d7b9ce6a9eee8d815b476672abaf11ca99", "best_bid": "0.06", "best_ask": "0.69"}], "timestamp": "1769384141638", "event_type": "price_change"}}
{"_local_timestamp": "2026-01-25T23:35:41.703161+00:00", "data": {"market": "0x9897c870e99bb551bcad54acb866b11ea20f18f6a59307b583d41b87dbd8df9b", "price_changes": [{"asset_id": "83125160625335845669305131102145331159652617545862153009199309232015574885824", "price": "0.23", "size": "0", "side": "BUY", "hash": "3cb19d2a982ddb563e28cc3a8800f898c3dd18b1", "best_bid": "0.3", "best_ask": "0.94"}, {"asset_id": "107986170040662440391901604090971190646645008770767885800861483401158985093632", "price": "0.77", "size": "0", "side": "SELL", "hash": "2b6976b3f1dc4df17434af75025a7925990f7b34", "best_bid": "0.06", "best_ask": "0.7"}], "timestamp": "1769384141638", "event_type": "price_change"}}
{"_local_timestamp": "2026-01-25T23:35:41.708434+00:00", "data": {"market": "0xe39dbeb302a95a1db7e8ea9d960d938eadf809915d35b010d6b5bdeab9104faa", "price_changes": [{"asset_id": "17232151154444159837483463581179634092787787010273125825914638704500808010603", "price": "0.306", "size": "12", "side": "BUY", "hash": "ed58b2cf0ab67c303a349ba58abcf3f42d83c0d6", "best_bid": "0.911", "best_ask": "0.99"}, {"asset_id": "92533496956435761714502061273420732955999521880693708251154668927169781104631", "price": "0.694", "size": "12", "side": "SELL", "hash": "f79db7562536eb35ac5aebce8056298e5b13c24c", "best_bid": "0.01", "best_ask": "0.089"}], "timestamp": "1769384141638", "event_type": "price_change"}}
{"_local_timestamp": "2026-01-25T23:35:41.778390+00:00", "data": {"market": "0xf281d9254d35ae8355aa5a2aa98fd38c96ba9c604a5526c2cf9e3a2934c1eee3", "price_changes": [{"asset_id": "9395139935407818232687755250472957071183406150419861658575355254022011268877", "price": "0.28", "size": "0", "side": "BUY", "hash": "7093da069c5c31083dfd60852bf4f6512b4b55db", "best_bid": "0.34", "best_ask": "0.98"}, {"asset_id": "89393743445790167235031936569401282709944557561334382371692027993458014466911", "price": "0.72", "size": "0", "side": "SELL", "hash": "9c914975800ba8defec93916f0429b886c527786", "best_bid": "0.02", "best_ask": "0.66"}], "timestamp": "1769384141715", "event_type": "price_change"}}
{"_local_timestamp": "2026-01-25T23:35:41.778889+00:00", "data": {"market": "0x7dbf290d0d7be090e536936f50e92b9ad6e8775ebb9d699892008ba6881ae1c8", "price_changes": [{"asset_id": "92370345086558298001609149354927257824272307772020776367874444756353703754849", "price": "0.28", "size": "0", "side": "BUY", "hash": "832b5eba4987a12778c22176c4b7cc55e1b8c956", "best_bid": "0.94", "best_ask": "0.95"}, {"asset_id": "59497151517604206038820337411152370581522020116814993064690346216716079620001", "price": "0.72", "size": "0", "side": "SELL", "hash": "46b8a12237394c3175f8f7013d960fee37123b7a", "best_bid": "0.05", "best_ask": "0.06"}], "timestamp": "1769384141715", "event_type": "price_change"}}
{"_local_timestamp": "2026-01-25T23:35:41.783014+00:00", "data": {"market": "0xedfafd25484c04cfbeaa767022f9eca5bb680918fceece81b36b0611eb3638a6", "price_changes": [{"asset_id": "69100260301420797247941786085257042358554422352183746124379790103566465901104", "price": "0.14", "size": "10", "side": "BUY", "hash": "b6c17121a074d1029234a658a847d185195933d6", "best_bid": "0.18", "best_ask": "0.99"}, {"asset_id": "5193041395342261568372064995546886956660044551128159772340877211907014735905", "price": "0.86", "size": "10", "side": "SELL", "hash": "8c8377601ef016d6cc6fdb666572e10e296d87f9", "best_bid": "0.01", "best_ask": "0.82"}], "timestamp": "1769384141715", "event_type": "price_change"}}
{"_local_timestamp": "2026-01-25T23:35:41.783390+00:00", "data": {"market": "0x9ad98d277747a5af33029daa93d8921e20dc48fc43a13444b34abd5db3090419", "price_changes": [{"asset_id": "84279332923568891895771507663060971052533473524984039519051747621941395607490", "price": "0.2", "size": "0", "side": "BUY", "hash": "d916e25bc8d6d64ddce04984df234086d921e405", "best_bid": "0.25", "best_ask": "0.96"}, {"asset_id": "13106897552498929473034004606662562096233616324310660731332487169842346464915", "price": "0.8", "size": "0", "side": "SELL", "hash": "e2ba15927e13d10ca7ce105c81802c0a61a58b38", "best_bid": "0.04", "best_ask": "0.75"}], "timestamp": "1769384141715", "event_type": "price_change"}}
{"_local_timestamp": "2026-01-25T23:35:41.798532+00:00", "data": {"market": "0xf281d9254d35ae8355aa5a2aa98fd38c96ba9c604a5526c2cf9e3a2934c1eee3", "price_changes": [{"asset_id": "9395139935407818232687755250472957071183406150419861658575355254022011268877", "price": "0.29", "size": "30", "side": "BUY", "hash": "46f7e07348306d52db3ee693f7c661d7709f6def", "best_bid": "0.34", "best_ask": "0.98"}, {"asset_id": "89393743445790167235031936569401282709944557561334382371692027993458014466911", "price": "0.71", "size": "30", "side": "SELL", "hash": "a20ded169131c0633378a893149a4a24c0723409", "best_bid": "0.02", "best_ask": "0.66"}], "timestamp": "1769384141734", "event_type": "price_change"}}
{"_local_timestamp": "2026-01-25T23:35:41.879284+00:00", "data": {"market": "0xe39dbeb302a95a1db7e8ea9d960d938eadf809915d35b010d6b5bdeab9104faa", "price_changes": [{"asset_id": "17232151154444159837483463581179634092787787010273125825914638704500808010603", "price": "0.306", "size": "0", "side": "BUY", "hash": "ec533a1cc09a5317b425c078964f81be537bb742", "best_bid": "0.911", "best_ask": "0.99"}, {"asset_id": "92533496956435761714502061273420732955999521880693708251154668927169781104631", "price": "0.694", "size": "0", "side": "SELL", "hash": "9539b4f4c14594885b20f94dd0f02c50bd53950b", "best_bid": "0.01", "best_ask": "0.089"}], "timestamp": "1769384141814", "event_type": "price_change"}}
{"_local_timestamp": "2026-01-25T23:35:41.904168+00:00", "data": {"market": "0xedfafd25484c04cfbeaa767022f9eca5bb680918fceece81b36b0611eb3638a6", "price_changes": [{"asset_id": "69100260301420797247941786085257042358554422352183746124379790103566465901104", "price": "0.19", "size": "10", "side": "BUY", "hash": "feafd2dfbdc95c99ba3344056291d65ff4efcdc9", "best_bid": "0.19", "best_ask": "0.99"}, {"asset_id": "5193041395342261568372064995546886956660044551128159772340877211907014735905", "price": "0.81", "size": "10", "side": "SELL", "hash": "9a4b753741777beee0feb1768ebcb6e3bb8600a8", "best_bid": "0.01", "best_ask": "0.81"}], "timestamp": "1769384141835", "event_type": "price_change"}}
{"_local_timestamp": "2026-01-25T23:35:41.904595+00:00", "data": {"market": "0xedfafd25484c04cfbeaa767022f9eca5bb680918fceece81b36b0611eb3638a6", "price_changes": [{"asset_id": "69100260301420797247941786085257042358554422352183746124379790103566465901104", "price": "0.19", "size": "25", "side": "BUY", "hash": "b652bf650b08bf4f0d145ea72be47d7c6b8d6863", "best_bid": "0.19", "best_ask": "0.99"}, {"asset_id": "5193041395342261568372064995546886956660044551128159772340877211907014735905", "price": "0.81", "size": "25", "side": "SELL", "hash": "0da07cf16ab4d3b27a6d8cff9412a1c845f045a8", "best_bid": "0.01", "best_ask": "0.81"}], "timestamp": "1769384141836", "event_type": "price_change"}}
{"_local_timestamp": "2026-01-25T23:35:41.904998+00:00", "data": {"market": "0xf281d9254d35ae8355aa5a2aa98fd38c96ba9c604a5526c2cf9e3a2934c1eee3", "price_changes": [{"asset_id": "9395139935407818232687755250472957071183406150419861658575355254022011268877", "price": "0.23", "size": "10", "side": "BUY", "hash": "95465e3bc4e0856745fe5c2591dc00a0e3f31e8f", "best_bid": "0.34", "best_ask": "0.98"}, {"asset_id": "89393743445790167235031936569401282709944557561334382371692027993458014466911", "price": "0.77", "size": "10", "side": "SELL", "hash": "bd447cf2ecf5223b96717164fec3a952b1b86e1a", "best_bid": "0.02", "best_ask": "0.66"}], "timestamp": "1769384141839", "event_type": "price_change"}}
{"_local_timestamp": "2026-01-25T23:35:41.905358+00:00", "data": {"market": "0x7dbf290d0d7be090e536936f50e92b9ad6e8775ebb9d699892008ba6881ae1c8", "price_changes": [{"asset_id": "92370345086558298001609149354927257824272307772020776367874444756353703754849", "price": "0.27", "size": "10", "side": "BUY", "hash": "8259a3b9d26a351c99c554956526aeab60d91da0", "best_bid": "0.94", "best_ask": "0.95"}, {"asset_id": "59497151517604206038820337411152370581522020116814993064690346216716079620001", "price": "0.73", "size": "10", "side": "SELL", "hash": "a4a84518a1e66cf43643ea0439fbef039d507b63", "best_bid": "0.05", "best_ask": "0.06"}], "timestamp": "1769384141839", "event_type": "price_change"}}
{"_local_timestamp": "2026-01-25T23:35:41.905709+00:00", "data": {"market": "0x9ad98d277747a5af33029daa93d8921e20dc48fc43a13444b34abd5db3090419", "price_changes": [{"asset_id": "84279332923568891895771507663060971052533473524984039519051747621941395607490", "price": "0.26", "size": "10", "side": "BUY", "hash": "f896f3682e4ce65bc34d2dc9f3536cac44304921", "best_bid": "0.26", "best_ask": "0.96"}, {"asset_id": "13106897552498929473034004606662562096233616324310660731332487169842346464915", "price": "0.74", "size": "10", "side": "SELL", "hash": "380aefa970b63ab7eb2a8207f3db6c21a0de237d", "best_bid": "0.04", "best_ask": "0.74"}], "timestamp": "1769384141839", "event_type": "price_change"}}
{"_local_timestamp": "2026-01-25T23:35:41.908239+00:00", "data": {"market": "0x7dbf290d0d7be090e536936f50e92b9ad6e8775ebb9d699892008ba6881ae1c8", "price_changes": [{"asset_id": "92370345086558298001609149354927257824272307772020776367874444756353703754849", "price": "0.15", "size": "74", "side": "BUY", "hash": "3c4cbdad07419fae5e48dedee51ef8e5d2a63196", "best_bid": "0.94", "best_ask": "0.95"}, {"asset_id": "59497151517604206038820337411152370581522020116814993064690346216716079620001", "price": "0.85", "size": "74", "side": "SELL", "hash": "9a17e3aa6edebdd48f93c8ce829bce1bb0b77038", "best_bid": "0.05", "best_ask": "0.06"}], "timestamp": "1769384141840", "event_type": "price_change"}}
{"_local_timestamp": "2026-01-25T23:35:42.049171+00:00", "data": {"market": "0xe39dbeb302a95a1db7e8ea9d960d938eadf809915d35b010d6b5bdeab9104faa", "price_changes": [{"asset_id": "17232151154444159837483463581179634092787787010273125825914638704500808010603", "price": "0.31", "size": "12", "side": "BUY", "hash": "c1916a2717bbc2b3fe8fd6431f69bb226853e2ee", "best_bid": "0.911", "best_ask": "0.99"}, {"asset_id": "92533496956435761714502061273420732955999521880693708251154668927169781104631", "price": "0.69", "size": "12", "side": "SELL", "hash": "add4e00b2dcccfc1daaf84158b8564c733cc5d28", "best_bid": "0.01", "best_ask": "0.089"}], "timestamp": "1769384141970", "event_type": "price_change"}}
{"_local_timestamp": "2026-01-25T23:35:42.049697+00:00", "data": {"market": "0xe39dbeb302a95a1db7e8ea9d960d938eadf809915d35b010d6b5bdeab9104faa", "price_changes": [{"asset_id": "17232151154444159837483463581179634092787787010273125825914638704500808010603", "price": "0.31", "size": "22", "side": "BUY", "hash": "b98f6cc688381ed5944d154f8f11dcd1f7ffe5b9", "best_bid": "0.911", "best_ask": "0.99"}, {"asset_id": "92533496956435761714502061273420732955999521880693708251154668927169781104631", "price": "0.69", "size": "22", "side": "SELL", "hash": "3178a310db9cae2bfd55aa228e6789b0fd07cc20", "best_bid": "0.01", "best_ask": "0.089"}], "timestamp": "1769384141971", "event_type": "price_change"}}
{"_local_timestamp": "2026-01-25T23:35:42.057018+00:00", "data": {"market": "0xf281d9254d35ae8355aa5a2aa98fd38c96ba9c604a5526c2cf9e3a2934c1eee3", "price_changes": [{"asset_id": "9395139935407818232687755250472957071183406150419861658575355254022011268877", "price": "0.22", "size": "0", "side": "BUY", "hash": "b9162e992e0d5eb3f93857e8e6b5b2c0977ad064", "best_bid": "0.34", "best_ask": "0.98"}, {"asset_id": "89393743445790167235031936569401282709944557561334382371692027993458014466911", "price": "0.78", "size": "0", "side": "SELL", "hash": "bfdc635f267f8bb85652ad6e3607834f7bc0d150", "best_bid": "0.02", "best_ask": "0.66"}], "timestamp": "1769384141991", "event_type": "price_change"}}
{"_local_timestamp": "2026-01-25T23:35:42.188877+00:00", "data": {"market": "0xf281d9254d35ae8355aa5a2aa98fd38c96ba9c604a5526c2cf9e3a2934c1eee3", "price_changes": [{"asset_id": "9395139935407818232687755250472957071183406150419861658575355254022011268877", "price": "0.3", "size": "10", "side": "BUY", "hash": "78bb7823ef1ba57a9ceb65040a6ab5c7321928f4", "best_bid": "0.34", "best_ask": "0.98"}, {"asset_id": "89393743445790167235031936569401282709944557561334382371692027993458014466911", "price": "0.7", "size": "10", "side": "SELL", "hash": "ce08537701de941f078ab968b8d21a695f877852", "best_bid": "0.02", "best_ask": "0.66"}], "timestamp": "1769384142120", "event_type": "price_change"}}
{"_local_timestamp": "2026-01-25T23:35:42.189396+00:00", "data": {"market": "0xf281d9254d35ae8355aa5a2aa98fd38c96ba9c604a5526c2cf9e3a2934c1eee3", "price_changes": [{"asset_id": "9395139935407818232687755250472957071183406150419861658575355254022011268877", "price": "0.24", "size": "15", "side": "BUY", "hash": "49730d8dedf0c81dc829b614a4a8b3f1873a8416", "best_bid": "0.34", "best_ask": "0.98"}, {"asset_id": "89393743445790167235031936569401282709944557561334382371692027993458014466911", "price": "0.76", "size": "15", "side": "SELL", "hash": "dc102faa3bc01422e9072e74af955bbcb7e04c98", "best_bid": "0.02", "best_ask": "0.66"}], "timestamp": "1769384142121", "event_type": "price_change"}}
{"_local_timestamp": "2026-01-25T23:35:42.238709+00:00", "data": {"market": "0x96449838d7dc6702e356ceb13144a6e53408b728ca363dc96b379320a2552d64", "price_changes": [{"asset_id": "88669991566060336244616088283363604665361049459599965771564136419124853077521", "price": "0.14", "size": "0", "side": "BUY", "hash": "74f2dd56927de742ba8dc1f13488687a3beb6edc", "best_bid": "0.31", "best_ask": "0.95"}, {"asset_id": "98265373238824778819853870879462811197150130214114951682085083828419115905786", "price": "0.86", "size": "0", "side": "SELL", "hash": "42d6d3b55a876fea35c9f6ab826fd9e29e27581a", "best_bid": "0.05", "best_ask": "0.69"}], "timestamp": "1769384142168", "event_type": "price_change"}}
{"_local_timestamp": "2026-01-25T23:35:42.242866+00:00", "data": {"market": "0x9ad98d277747a5af33029daa93d8921e20dc48fc43a13444b34abd5db3090419", "price_changes": [{"asset_id": "84279332923568891895771507663060971052533473524984039519051747621941395607490", "price": "0.25", "size": "0", "side": "BUY", "hash": "53afe9cbf2d13d6647349654493079080d582ed0", "best_bid": "0.26", "best_ask": "0.96"}, {"asset_id": "13106897552498929473034004606662562096233616324310660731332487169842346464915", "price": "0.75", "size": "0", "side": "SELL", "hash": "db3d1ea182d9e92fe39944925d6c67899b89dde6", "best_bid": "0.04", "best_ask": "0.74"}], "timestamp": "1769384142168", "event_type": "price_change"}}
{"_local_timestamp": "2026-01-25T23:35:42.248328+00:00", "data": {"market": "0xaa46cd9dfbc750e16e767ab71cdfbaaa9f3bbf68153fcb7e9e21bdad1f9a0e4e", "price_changes": [{"asset_id": "10190047580304467488950735708592587854326252278861442489701414156559786950928", "price": "0.31", "size": "0", "side": "BUY", "hash": "49ac1c9a629373dee3898a30c6d44f99594e8584", "best_bid": "0.3", "best_ask": "0.94"}, {"asset_id": "88155858711031400772451028879251834333349215458844495516447987085254946467393", "price": "0.69", "size": "0", "side": "SELL", "hash": "633da6f960985a25deeb5ac21c04a76fce39997a", "best_bid": "0.06", "best_ask": "0.7"}], "timestamp": "1769384142169", "event_type": "price_change"}}
{"_local_timestamp": "2026-01-25T23:35:42.248813+00:00", "data": {"market": "0xaa46cd9dfbc750e16e767ab71cdfbaaa9f3bbf68153fcb7e9e21bdad1f9a0e4e", "price_changes": [{"asset_id": "10190047580304467488950735708592587854326252278861442489701414156559786950928", "price": "0.2", "size": "0", "side": "BUY", "hash": "49ac1c9a629373dee3898a30c6d44f99594e8584", "best_bid": "0.3", "best_ask": "0.94"}, {"asset_id": "88155858711031400772451028879251834333349215458844495516447987085254946467393", "price": "0.8", "size": "0", "side": "SELL", "hash": "633da6f960985a25deeb5ac21c04a76fce39997a", "best_bid": "0.06", "best_ask": "0.7"}], "timestamp": "1769384142169", "event_type": "price_change"}}
{"_local_timestamp": "2026-01-25T23:35:42.257045+00:00", "data": {"market": "0xedfafd25484c04cfbeaa767022f9eca5bb680918fceece81b36b0611eb3638a6", "price_changes": [{"asset_id": "69100260301420797247941786085257042358554422352183746124379790103566465901104", "price": "0.18", "size": "0", "side": "BUY", "hash": "6988bbfeb03839dbd08a107a4ae30827a770712d", "best_bid": "0.19", "best_ask": "0.99"}, {"asset_id": "5193041395342261568372064995546886956660044551128159772340877211907014735905", "price": "0.82", "size": "0", "side": "SELL", "hash": "40d3650a644551ed8d5ef0a0b75b920991d81bfb", "best_bid": "0.01", "best_ask": "0.81"}], "timestamp": "1769384142168", "event_type": "price_change"}}
{"_local_timestamp": "2026-01-25T23:35:42.257590+00:00", "data": {"market": "0x3be55688f3eecd53db101048ec9c372230efc90f004c1c4e3fce8dd1d2c4dada", "price_changes": [{"asset_id": "85304840619071051396870312932957819961814877219759465827862543288479782634253", "price": "0.28", "size": "0", "side": "BUY", "hash": "f96f20008b6ad4ca3ec0a02ccdb150ae9373e3a7", "best_bid": "0.27", "best_ask": "0.98"}, {"asset_id": "25385091870387844891345378992524415372478832284204632642650074498441270262521", "price": "0.72", "size": "0", "side": "SELL", "hash": "7d8db1fddec6e791c104f1ac17e146378a6f39a1", "best_bid": "0.02", "best_ask": "0.73"}], "timestamp": "1769384142169", "event_type": "price_change"}}
{"_local_timestamp": "2026-01-25T23:35:42.258400+00:00", "data": {"market": "0x9897c870e99bb551bcad54acb866b11ea20f18f6a59307b583d41b87dbd8df9b", "price_changes": [{"asset_id": "83125160625335845669305131102145331159652617545862153009199309232015574885824", "price": "0.26", "size": "0", "side": "BUY", "hash": "f9f5701ad63c28762fa63eba4eb437f2c71b6a2b", "best_bid": "0.3", "best_ask": "0.94"}, {"asset_id": "107986170040662440391901604090971190646645008770767885800861483401158985093632", "price": "0.74", "size": "0", "side": "SELL", "hash": "5ef6ae22d022890557940c90918fcba2fce34ce7", "best_bid": "0.06", "best_ask": "0.7"}], "timestamp": "1769384142169", "event_type": "price_change"}}
{"_local_timestamp": "2026-01-25T23:35:42.258949+00:00", "data": {"market": "0xf281d9254d35ae8355aa5a2aa98fd38c96ba9c604a5526c2cf9e3a2934c1eee3", "price_changes": [{"asset_id": "9395139935407818232687755250472957071183406150419861658575355254022011268877", "price": "0.34", "size": "0", "side": "BUY", "hash": "0c012fd5850fa9ce8fd886a27409ce5375ab62d6", "best_bid": "0.33", "best_ask": "0.98"}, {"asset_id": "89393743445790167235031936569401282709944557561334382371692027993458014466911", "price": "0.66", "size": "0", "side": "SELL", "hash": "e298b7a26c893fe5d3294ab593597a4fa1806684", "best_bid": "0.02", "best_ask": "0.67"}], "timestamp": "1769384142169", "event_type": "price_change"}}
{"_local_timestamp": "2026-01-25T23:35:42.386625+00:00", "data": {"market": "0x33e09845665c7bcd0b3026cdf8c48f4e4d1ae705e0acd863e03525888a3c01c5", "price_changes": [{"asset_id": "37989116880087250809590393125454376367717533321300643105365874853772585707501", "price": "0.3", "size": "30", "side": "BUY", "hash": "8f4374c57945f9d37ecfb8b088309c5ea34d58aa", "best_bid": "0.34", "best_ask": "0.98"}, {"asset_id": "41365543321762183390531316023268343985794742000187213322174746298305281833286", "price": "0.7", "size": "30", "side": "SELL", "hash": "65f23db0160f9026d6b69e3a095a2248adaa5838", "best_bid": "0.02", "best_ask": "0.66"}], "timestamp": "1769384142319", "event_type": "price_change"}}
{"_local_timestamp": "2026-01-25T23:35:42.387155+00:00", "data": {"market": "0xaa46cd9dfbc750e16e767ab71cdfbaaa9f3bbf68153fcb7e9e21bdad1f9a0e4e", "price_changes": [{"asset_id": "10190047580304467488950735708592587854326252278861442489701414156559786950928", "price": "0.16", "size": "0", "side": "BUY", "hash": "c051376c6b3edd5b553f3b4296f5afd571558731", "best_bid": "0.3", "best_ask": "0.94"}, {"asset_id": "88155858711031400772451028879251834333349215458844495516447987085254946467393", "price": "0.84", "size": "0", "side": "SELL", "hash": "ea57deea8a89070996ba7cfafd91279247f11406", "best_bid": "0.06", "best_ask": "0.7"}], "timestamp": "1769384142319", "event_type": "price_change"}}
{"_local_timestamp": "2026-01-25T23:35:42.443387+00:00", "data": {"market": "0x7dbf290d0d7be090e536936f50e92b9ad6e8775ebb9d699892008ba6881ae1c8", "price_changes": [{"asset_id": "92370345086558298001609149354927257824272307772020776367874444756353703754849", "price": "0.15", "size": "0", "side": "BUY", "hash": "a0a9e42e31042b0cc1c87f7d29f1cf00caec5d1b", "best_bid": "0.94", "best_ask": "0.95"}, {"asset_id": "59497151517604206038820337411152370581522020116814993064690346216716079620001", "price": "0.85", "size": "0", "side": "SELL", "hash": "941b0d77336080591f3edf994a3ff79bb2034326", "best_bid": "0.05", "best_ask": "0.06"}], "timestamp": "1769384142375", "event_type": "price_change"}}
{"_local_timestamp": "2026-01-25T23:35:42.524215+00:00", "data": {"market": "0xaa46cd9dfbc750e16e767ab71cdfbaaa9f3bbf68153fcb7e9e21bdad1f9a0e4e", "price_changes": [{"asset_id": "10190047580304467488950735708592587854326252278861442489701414156559786950928", "price": "0.2", "size": "10", "side": "BUY", "hash": "3bd8348aaa92a66c2ae7e6c252ad333b3478788d", "best_bid": "0.3", "best_ask": "0.94"}, {"asset_id": "88155858711031400772451028879251834333349215458844495516447987085254946467393", "price": "0.8", "size": "10", "side": "SELL", "hash": "981f9a439bb1b7c814dadbbd4017c71f1d254060", "best_bid": "0.06", "best_ask": "0.7"}], "timestamp": "1769384142442", "event_type": "price_change"}}
{"_local_timestamp": "2026-01-25T23:35:42.524755+00:00", "data": {"market": "0x33e09845665c7bcd0b3026cdf8c48f4e4d1ae705e0acd863e03525888a3c01c5", "price_changes": [{"asset_id": "37989116880087250809590393125454376367717533321300643105365874853772585707501", "price": "0.18", "size": "15", "side": "BUY", "hash": "1786cd557d1d8e33270297c836aeda3dd786a8a3", "best_bid": "0.34", "best_ask": "0.98"}, {"asset_id": "41365543321762183390531316023268343985794742000187213322174746298305281833286", "price": "0.82", "size": "15", "side": "SELL", "hash": "0eefae866c14a7beb0a526605173a6ed7d6650ba", "best_bid": "0.02", "best_ask": "0.66"}], "timestamp": "1769384142442", "event_type": "price_change"}}
{"_local_timestamp": "2026-01-25T23:35:42.527120+00:00", "data": {"market": "0x33e09845665c7bcd0b3026cdf8c48f4e4d1ae705e0acd863e03525888a3c01c5", "price_changes": [{"asset_id": "37989116880087250809590393125454376367717533321300643105365874853772585707501", "price": "0.07", "size": "228", "side": "BUY", "hash": "86e98711e153b36a6d77cf40971880e17244251e", "best_bid": "0.34", "best_ask": "0.98"}, {"asset_id": "41365543321762183390531316023268343985794742000187213322174746298305281833286", "price": "0.93", "size": "228", "side": "SELL", "hash": "a2cc39a701da734783befce2c0996a7c1a3da6bc", "best_bid": "0.02", "best_ask": "0.66"}], "timestamp": "1769384142451", "event_type": "price_change"}}
{"_local_timestamp": "2026-01-25T23:35:42.527657+00:00", "data": {"market": "0xaa46cd9dfbc750e16e767ab71cdfbaaa9f3bbf68153fcb7e9e21bdad1f9a0e4e", "price_changes": [{"asset_id": "10190047580304467488950735708592587854326252278861442489701414156559786950928", "price": "0.2", "size": "25", "side": "BUY", "hash": "b6d3e6445dcaa6e386b8306ea7ca4075d24d79ee", "best_bid": "0.3", "best_ask": "0.94"}, {"asset_id": "88155858711031400772451028879251834333349215458844495516447987085254946467393", "price": "0.8", "size": "25", "side": "SELL", "hash": "9e7f647660bc5d34ff977b489ae71f1a6d61b612", "best_bid": "0.06", "best_ask": "0.7"}], "timestamp": "1769384142451", "event_type": "price_change"}}
{"_local_timestamp": "2026-01-25T23:35:42.531208+00:00", "data": {"market": "0x33e09845665c7bcd0b3026cdf8c48f4e4d1ae705e0acd863e03525888a3c01c5", "price_changes": [{"asset_id": "37989116880087250809590393125454376367717533321300643105365874853772585707501", "price": "0.31", "size": "20", "side": "BUY", "hash": "4cc07768853c845642cfa6d44925dcf4359526db", "best_bid": "0.34", "best_ask": "0.98"}, {"asset_id": "41365543321762183390531316023268343985794742000187213322174746298305281833286", "price": "0.69", "size": "20", "side": "SELL", "hash": "1cac8ec7c58f67d6516ae105ee635ffcb8713cc1", "best_bid": "0.02", "best_ask": "0.66"}], "timestamp": "1769384142454", "event_type": "price_change"}}
{"_local_timestamp": "2026-01-25T23:35:42.896909+00:00", "data": {"market": "0x33e09845665c7bcd0b3026cdf8c48f4e4d1ae705e0acd863e03525888a3c01c5", "price_changes": [{"asset_id": "37989116880087250809590393125454376367717533321300643105365874853772585707501", "price": "0.31", "size": "10", "side": "BUY", "hash": "fdacb6d0a4850ffa758c482a3e1250c2d7b5c42e", "best_bid": "0.34", "best_ask": "0.98"}, {"asset_id": "41365543321762183390531316023268343985794742000187213322174746298305281833286", "price": "0.69", "size": "10", "side": "SELL", "hash": "452f365d8b1e006dcd613419e4af67757c16224b", "best_bid": "0.02", "best_ask": "0.66"}], "timestamp": "1769384142829", "event_type": "price_change"}}
{"_local_timestamp": "2026-01-25T23:35:42.897441+00:00", "data": {"market": "0xedfafd25484c04cfbeaa767022f9eca5bb680918fceece81b36b0611eb3638a6", "price_changes": [{"asset_id": "69100260301420797247941786085257042358554422352183746124379790103566465901104", "price": "0.17", "size": "79.16", "side": "BUY", "hash": "a11ecc086c9e856c5b9b6ad10e69a13beb2ba798", "best_bid": "0.19", "best_ask": "0.99"}, {"asset_id": "5193041395342261568372064995546886956660044551128159772340877211907014735905", "price": "0.83", "size": "79.16", "side": "SELL", "hash": "91a17efc83fec320d5aed757ea91e018e19c2e33", "best_bid": "0.01", "best_ask": "0.81"}], "timestamp": "1769384142829", "event_type": "price_change"}}
{"_local_timestamp": "2026-01-25T23:35:42.897891+00:00", "data": {"market": "0x3be55688f3eecd53db101048ec9c372230efc90f004c1c4e3fce8dd1d2c4dada", "price_changes": [{"asset_id": "85304840619071051396870312932957819961814877219759465827862543288479782634253", "price": "0.27", "size": "79.16", "side": "BUY", "hash": "128a05107608a1c346584d9cfcc4172aea84361a", "best_bid": "0.27", "best_ask": "0.98"}, {"asset_id": "25385091870387844891345378992524415372478832284204632642650074498441270262521", "price": "0.73", "size": "79.16", "side": "SELL", "hash": "cbabe3808f14561636a8ea6341c4d73d47f6da18", "best_bid": "0.02", "best_ask": "0.73"}], "timestamp": "1769384142829", "event_type": "price_change"}}
{"_local_timestamp": "2026-01-25T23:35:42.898318+00:00", "data": {"market": "0xaa46cd9dfbc750e16e767ab71cdfbaaa9f3bbf68153fcb7e9e21bdad1f9a0e4e", "price_changes": [{"asset_id": "10190047580304467488950735708592587854326252278861442489701414156559786950928", "price": "0.19", "size": "0", "side": "BUY", "hash": "5511df4fa79d570353a444517fd4f6bc4833d671", "best_bid": "0.3", "best_ask": "0.94"}, {"asset_id": "88155858711031400772451028879251834333349215458844495516447987085254946467393", "price": "0.81", "size": "0", "side": "SELL", "hash": "791ee4a64b38ed946130af8b7cfb4a5970939e09", "best_bid": "0.06", "best_ask": "0.7"}], "timestamp": "1769384142829", "event_type": "price_change"}}
{"_local_timestamp": "2026-01-25T23:35:42.898757+00:00", "data": {"market": "0xf281d9254d35ae8355aa5a2aa98fd38c96ba9c604a5526c2cf9e3a2934c1eee3", "price_changes": [{"asset_id": "9395139935407818232687755250472957071183406150419861658575355254022011268877", "price": "0.33", "size": "0", "side": "BUY", "hash": "2a520e4c4aa2d69592512b2a313caa0c18a3a90c", "best_bid": "0.3", "best_ask": "0.98"}, {"asset_id": "89393743445790167235031936569401282709944557561334382371692027993458014466911", "price": "0.67", "size": "0", "side": "SELL", "hash": "ad9929cc1f636bd953c81dbf3c6e687d81e7fe1a", "best_bid": "0.02", "best_ask": "0.7"}], "timestamp": "1769384142829", "event_type": "price_change"}}
{"_local_timestamp": "2026-01-25T23:35:42.899194+00:00", "data": {"market": "0x9ad98d277747a5af33029daa93d8921e20dc48fc43a13444b34abd5db3090419", "price_changes": [{"asset_id": "84279332923568891895771507663060971052533473524984039519051747621941395607490", "price": "0.24", "size": "79.16", "side": "BUY", "hash": "5479395f319cd9a93912e80a6f4ff0b9ce906fe4", "best_bid": "0.26", "best_ask": "0.96"}, {"asset_id": "13106897552498929473034004606662562096233616324310660731332487169842346464915", "price": "0.76", "size": "79.16", "side": "SELL", "hash": "38d9469d514611c5f58c3bcd3611c20478c39c02", "best_bid": "0.04", "best_ask": "0.74"}], "timestamp": "1769384142829", "event_type": "price_change"}}
{"_local_timestamp": "2026-01-25T23:35:42.899625+00:00", "data": {"market": "0x9897c870e99bb551bcad54acb866b11ea20f18f6a59307b583d41b87dbd8df9b", "price_changes": [{"asset_id": "83125160625335845669305131102145331159652617545862153009199309232015574885824", "price": "0.25", "size": "79.16", "side": "BUY", "hash": "f20a956b4cdc537ba4571ab174208bdeb0c0db95", "best_bid": "0.3", "best_ask": "0.94"}, {"asset_id": "107986170040662440391901604090971190646645008770767885800861483401158985093632", "price": "0.75", "size": "79.16", "side": "SELL", "hash": "b3d06fd92ede230d9e889212bda31aad3994c1af", "best_bid": "0.06", "best_ask": "0.7"}], "timestamp": "1769384142829", "event_type": "price_change"}}
{"_local_timestamp": "2026-01-25T23:35:42.900062+00:00", "data": {"market": "0x96449838d7dc6702e356ceb13144a6e53408b728ca363dc96b379320a2552d64", "price_changes": [{"asset_id": "88669991566060336244616088283363604665361049459599965771564136419124853077521", "price": "0.13", "size": "79.16", "side": "BUY", "hash": "b471d4c68316972a457a6d2f24db92517bdcdceb", "best_bid": "0.31", "best_ask": "0.95"}, {"asset_id": "98265373238824778819853870879462811197150130214114951682085083828419115905786", "price": "0.87", "size": "79.16", "side": "SELL", "hash": "26cad1aa781a37d4a40faee105ad6e5332e72fe4", "best_bid": "0.05", "best_ask": "0.69"}], "timestamp": "1769384142829", "event_type": "price_change"}}
{"_local_timestamp": "2026-01-25T23:35:42.900506+00:00", "data": {"market": "0xe39dbeb302a95a1db7e8ea9d960d938eadf809915d35b010d6b5bdeab9104faa", "price_changes": [{"asset_id": "17232151154444159837483463581179634092787787010273125825914638704500808010603", "price": "0.309", "size": "0", "side": "BUY", "hash": "a71e3a0dec08c5f4d300d59cad833bdc1ff2dc60", "best_bid": "0.911", "best_ask": "0.99"}, {"asset_id": "92533496956435761714502061273420732955999521880693708251154668927169781104631", "price": "0.691", "size": "0", "side": "SELL", "hash": "43b493cbbb7e690ddbce70e8a43f3638a1249cc6", "best_bid": "0.01", "best_ask": "0.089"}], "timestamp": "1769384142829", "event_type": "price_change"}}
{"_local_timestamp": "2026-01-25T23:35:42.933060+00:00", "data": {"market": "0xedfafd25484c04cfbeaa767022f9eca5bb680918fceece81b36b0611eb3638a6", "price_changes": [{"asset_id": "69100260301420797247941786085257042358554422352183746124379790103566465901104", "price": "0.2", "size": "20", "side": "BUY", "hash": "63c54181ee004bb24507123fc8d3b009b534c0d9", "best_bid": "0.2", "best_ask": "0.99"}, {"asset_id": "5193041395342261568372064995546886956660044551128159772340877211907014735905", "price": "0.8", "size": "20", "side": "SELL", "hash": "00cec5c514a6b6d00fca087acb1f1182b3815343", "best_bid": "0.01", "best_ask": "0.8"}], "timestamp": "1769384142866", "event_type": "price_change"}}
{"_local_timestamp": "2026-01-25T23:35:42.937466+00:00", "data": {"market": "0x9897c870e99bb551bcad54acb866b11ea20f18f6a59307b583d41b87dbd8df9b", "price_changes": [{"asset_id": "83125160625335845669305131102145331159652617545862153009199309232015574885824", "price": "0.26", "size": "10", "side": "BUY", "hash": "9717ef385c8a0631a053954c5caa51d72197b5e5", "best_bid": "0.3", "best_ask": "0.94"}, {"asset_id": "107986170040662440391901604090971190646645008770767885800861483401158985093632", "price": "0.74", "size": "10", "side": "SELL", "hash": "e83361e7443407d791a11b5d9b65b5269f86949e", "best_bid": "0.06", "best_ask": "0.7"}], "timestamp": "1769384142866", "event_type": "price_change"}}
{"_local_timestamp": "2026-01-25T23:35:42.947149+00:00", "data": {"market": "0xf281d9254d35ae8355aa5a2aa98fd38c96ba9c604a5526c2cf9e3a2934c1eee3", "price_changes": [{"asset_id": "9395139935407818232687755250472957071183406150419861658575355254022011268877", "price": "0.31", "size": "10", "side": "BUY", "hash": "b0c7a5eed460a293715f616ce483b32c0d41b2b5", "best_bid": "0.31", "best_ask": "0.98"}, {"asset_id": "89393743445790167235031936569401282709944557561334382371692027993458014466911", "price": "0.69", "size": "10", "side": "SELL", "hash": "c07618df955d12ee9aa521a8a14913e45eb1a0ab", "best_bid": "0.02", "best_ask": "0.69"}], "timestamp": "1769384142866", "event_type": "price_change"}}
{"_local_timestamp": "2026-01-25T23:35:42.954024+00:00", "data": {"market": "0x33e09845665c7bcd0b3026cdf8c48f4e4d1ae705e0acd863e03525888a3c01c5", "price_changes": [{"asset_id": "37989116880087250809590393125454376367717533321300643105365874853772585707501", "price": "0.32", "size": "10", "side": "BUY", "hash": "1c0e1d2bf84435e59a11e1e286ad4807ee4226ac", "best_bid": "0.34", "best_ask": "0.98"}, {"asset_id": "41365543321762183390531316023268343985794742000187213322174746298305281833286", "price": "0.68", "size": "10", "side": "SELL", "hash": "db9089089c5ea1a28e57255fe26c0a15f3357dd1", "best_bid": "0.02", "best_ask": "0.66"}], "timestamp": "1769384142866", "event_type": "price_change"}}
{"_local_timestamp": "2026-01-25T23:35:42.959801+00:00", "data": {"market": "0xaa46cd9dfbc750e16e767ab71cdfbaaa9f3bbf68153fcb7e9e21bdad1f9a0e4e", "price_changes": [{"asset_id": "10190047580304467488950735708592587854326252278861442489701414156559786950928", "price": "0.21", "size": "10", "side": "BUY", "hash": "2e343c13b5a193bd0840597eaa0cb7500fa4700f", "best_bid": "0.3", "best_ask": "0.94"}, {"asset_id": "88155858711031400772451028879251834333349215458844495516447987085254946467393", "price": "0.79", "size": "10", "side": "SELL", "hash": "4dd94f0d389a9a60462bdac328118de67ee23cf7", "best_bid": "0.06", "best_ask": "0.7"}], "timestamp": "1769384142867", "event_type": "price_change"}}
{"_local_timestamp": "2026-01-25T23:35:43.024711+00:00", "data": {"market": "0x3be55688f3eecd53db101048ec9c372230efc90f004c1c4e3fce8dd1d2c4dada", "price_changes": [{"asset_id": "85304840619071051396870312932957819961814877219759465827862543288479782634253", "price": "0.28", "size": "10", "side": "BUY", "hash": "0fe69a7ad3c183a70817aa5a9fe11c42fb9194ed", "best_bid": "0.28", "best_ask": "0.98"}, {"asset_id": "25385091870387844891345378992524415372478832284204632642650074498441270262521", "price": "0.72", "size": "10", "side": "SELL", "hash": "7798e365615f77a7cdad233364e3b8b12367d985", "best_bid": "0.02", "best_ask": "0.72"}], "timestamp": "1769384142866", "event_type": "price_change"}}
{"_local_timestamp": "2026-01-25T23:35:43.025304+00:00", "data": {"market": "0xe39dbeb302a95a1db7e8ea9d960d938eadf809915d35b010d6b5bdeab9104faa", "price_changes": [{"asset_id": "17232151154444159837483463581179634092787787010273125825914638704500808010603", "price": "0.311", "size": "10", "side": "BUY", "hash": "0a71171aac8ef2911c36a6125d8cf6e85907b203", "best_bid": "0.911", "best_ask": "0.99"}, {"asset_id": "92533496956435761714502061273420732955999521880693708251154668927169781104631", "price": "0.689", "size": "10", "side": "SELL", "hash": "c3567c12de7ef2adc07dd76f7e3cae61652d89a2", "best_bid": "0.01", "best_ask": "0.089"}], "timestamp": "1769384142867", "event_type": "price_change"}}
{"_local_timestamp": "2026-01-25T23:35:43.025802+00:00", "data": {"market": "0x96449838d7dc6702e356ceb13144a6e53408b728ca363dc96b379320a2552d64", "price_changes": [{"asset_id": "88669991566060336244616088283363604665361049459599965771564136419124853077521", "price": "0.14", "size": "10", "side": "BUY", "hash": "61e55c3d7a4c65969f17d04cb4b08e4e15b8017a", "best_bid": "0.31", "best_ask": "0.95"}, {"asset_id": "98265373238824778819853870879462811197150130214114951682085083828419115905786", "price": "0.86", "size": "10", "side": "SELL", "hash": "f7f101cd9dc3bb1ac44ca51f7ebdbb40c0c491b5", "best_bid": "0.05", "best_ask": "0.69"}], "timestamp": "1769384142866", "event_type": "price_change"}}
{"_local_timestamp": "2026-01-25T23:35:43.026298+00:00", "data": {"market": "0x9ad98d277747a5af33029daa93d8921e20dc48fc43a13444b34abd5db3090419", "price_changes": [{"asset_id": "84279332923568891895771507663060971052533473524984039519051747621941395607490", "price": "0.27", "size": "10", "side": "BUY", "hash": "02babf6965a1073af3d663ea5272b268598efe14", "best_bid": "0.27", "best_ask": "0.96"}, {"asset_id": "13106897552498929473034004606662562096233616324310660731332487169842346464915", "price": "0.73", "size": "10", "side": "SELL", "hash": "60634f3d3346ad5cf18a36aea2ea562833d26e26", "best_bid": "0.04", "best_ask": "0.73"}], "timestamp": "1769384142867", "event_type": "price_change"}}
{"_local_timestamp": "2026-01-25T23:36:14.800044+00:00", "data": {"market": "0x3be55688f3eecd53db101048ec9c372230efc90f004c1c4e3fce8dd1d2c4dada", "price_changes": [{"asset_id": "25385091870387844891345378992524415372478832284204632642650074498441270262521", "price": "0.74", "size": "25", "side": "SELL", "hash": "f0d4db9890a036edee9945f3eadb6def5e595af8", "best_bid": "0.02", "best_ask": "0.72"}, {"asset_id": "85304840619071051396870312932957819961814877219759465827862543288479782634253", "price": "0.26", "size": "25", "side": "BUY", "hash": "c95fe503c057748d22ff928b52031d6671da342f", "best_bid": "0.28", "best_ask": "0.98"}], "timestamp": "1769384174734", "event_type": "price_change"}}
{"_local_timestamp": "2026-01-25T23:36:14.801902+00:00", "data": {"market": "0x9ad98d277747a5af33029daa93d8921e20dc48fc43a13444b34abd5db3090419", "price_changes": [{"asset_id": "13106897552498929473034004606662562096233616324310660731332487169842346464915", "price": "0.77", "size": "0", "side": "SELL", "hash": "905eb85078f25598410064ea2fceafac510a4b69", "best_bid": "0.04", "best_ask": "0.73"}, {"asset_id": "84279332923568891895771507663060971052533473524984039519051747621941395607490", "price": "0.23", "size": "0", "side": "BUY", "hash": "26c82f2087267851f0f942d62d7d5cd6e7065e6e", "best_bid": "0.27", "best_ask": "0.96"}], "timestamp": "1769384174734", "event_type": "price_change"}}
{"_local_timestamp": "2026-01-25T23:36:14.899736+00:00", "data": {"market": "0xedfafd25484c04cfbeaa767022f9eca5bb680918fceece81b36b0611eb3638a6", "price_changes": [{"asset_id": "5193041395342261568372064995546886956660044551128159772340877211907014735905", "price": "0.84", "size": "0", "side": "SELL", "hash": "c7729fb197a35a121ec64bd6f3ec82cf3d13f3d3", "best_bid": "0.01", "best_ask": "0.8"}, {"asset_id": "69100260301420797247941786085257042358554422352183746124379790103566465901104", "price": "0.16", "size": "0", "side": "BUY", "hash": "ca3b7c1fce3717873d865f46aadf48ea7813376f", "best_bid": "0.2", "best_ask": "0.99"}], "timestamp": "1769384174832", "event_type": "price_change"}}
{"_local_timestamp": "2026-01-25T23:36:14.900361+00:00", "data": {"market": "0x96449838d7dc6702e356ceb13144a6e53408b728ca363dc96b379320a2552d64", "price_changes": [{"asset_id": "98265373238824778819853870879462811197150130214114951682085083828419115905786", "price": "0.88", "size": "0", "side": "SELL", "hash": "32fadfc8041be6189fe284cda8c1a6edd47192fa", "best_bid": "0.05", "best_ask": "0.69"}, {"asset_id": "88669991566060336244616088283363604665361049459599965771564136419124853077521", "price": "0.12", "size": "0", "side": "BUY", "hash": "e13007a28d01a7a002c9c5f0ee00dc27fc0fd647", "best_bid": "0.31", "best_ask": "0.95"}], "timestamp": "1769384174832", "event_type": "price_change"}}
{"_local_timestamp": "2026-01-25T23:36:14.931811+00:00", "data": {"market": "0xaa46cd9dfbc750e16e767ab71cdfbaaa9f3bbf68153fcb7e9e21bdad1f9a0e4e", "price_changes": [{"asset_id": "10190047580304467488950735708592587854326252278861442489701414156559786950928", "price": "0.15", "size": "0", "side": "BUY", "hash": "e79e72bdbdacb47aa63d0615d1bc4ddfc5f3f74d", "best_bid": "0.3", "best_ask": "0.94"}, {"asset_id": "88155858711031400772451028879251834333349215458844495516447987085254946467393", "price": "0.85", "size": "0", "side": "SELL", "hash": "623ae617ca0d1dd3bb39b3777b34b0af3ff78c87", "best_bid": "0.06", "best_ask": "0.7"}], "timestamp": "1769384174865", "event_type": "price_change"}}
{"_local_timestamp": "2026-01-25T23:36:15.110346+00:00", "data": {"market": "0xaa46cd9dfbc750e16e767ab71cdfbaaa9f3bbf68153fcb7e9e21bdad1f9a0e4e", "price_changes": [{"asset_id": "10190047580304467488950735708592587854326252278861442489701414156559786950928", "price": "0.1", "size": "46", "side": "BUY", "hash": "d6073ba0cf3548f7d3323900a18035ba84b01785", "best_bid": "0.3", "best_ask": "0.94"}, {"asset_id": "88155858711031400772451028879251834333349215458844495516447987085254946467393", "price": "0.9", "size": "46", "side": "SELL", "hash": "1428bfdb986e953fa6052e42008e7cec3c23ef74", "best_bid": "0.06", "best_ask": "0.7"}], "timestamp": "1769384175024", "event_type": "price_change"}}
{"_local_timestamp": "2026-01-25T23:36:15.111700+00:00", "data": {"market": "0xaa46cd9dfbc750e16e767ab71cdfbaaa9f3bbf68153fcb7e9e21bdad1f9a0e4e", "price_changes": [{"asset_id": "10190047580304467488950735708592587854326252278861442489701414156559786950928", "price": "0.22", "size": "10", "side": "BUY", "hash": "973e50a5f80b4e0aaed6038a67bb91ceb3b17b83", "best_bid": "0.3", "best_ask": "0.94"}, {"asset_id": "88155858711031400772451028879251834333349215458844495516447987085254946467393", "price": "0.78", "size": "10", "side": "SELL", "hash": "a6ce8b88f2feeb1926dccf5dd68199d4b4807920", "best_bid": "0.06", "best_ask": "0.7"}], "timestamp": "1769384175026", "event_type": "price_change"}}
{"_local_timestamp": "2026-01-25T23:36:15.899904+00:00", "data": {"market": "0x3be55688f3eecd53db101048ec9c372230efc90f004c1c4e3fce8dd1d2c4dada", "price_changes": [{"asset_id": "25385091870387844891345378992524415372478832284204632642650074498441270262521", "price": "0.71", "size": "15", "side": "SELL", "hash": "c9f479063e17a412f6f98c9b31b33baa9cf75226", "best_bid": "0.02", "best_ask": "0.71"}, {"asset_id": "85304840619071051396870312932957819961814877219759465827862543288479782634253", "price": "0.29", "size": "15", "side": "BUY", "hash": "d50462d307318d3332b2386ddf3044a9165ca2cb", "best_bid": "0.29", "best_ask": "0.98"}], "timestamp": "1769384175835", "event_type": "price_change"}}
{"_local_timestamp": "2026-01-25T23:36:15.900676+00:00", "data": {"market": "0x9ad98d277747a5af33029daa93d8921e20dc48fc43a13444b34abd5db3090419", "price_changes": [{"asset_id": "13106897552498929473034004606662562096233616324310660731332487169842346464915", "price": "0.72", "size": "15", "side": "SELL", "hash": "8a598e0a77847a8db3cdfd608a75abd88a5b9251", "best_bid": "0.04", "best_ask": "0.72"}, {"asset_id": "84279332923568891895771507663060971052533473524984039519051747621941395607490", "price": "0.28", "size": "15", "side": "BUY", "hash": "6da80606c2dee162053aae32a7eb906ee56cccd1", "best_bid": "0.28", "best_ask": "0.96"}], "timestamp": "1769384175836", "event_type": "price_change"}}
{"_local_timestamp": "2026-01-25T23:36:16.021312+00:00", "data": {"market": "0xedfafd25484c04cfbeaa767022f9eca5bb680918fceece81b36b0611eb3638a6", "price_changes": [{"asset_id": "5193041395342261568372064995546886956660044551128159772340877211907014735905", "price": "0.79", "size": "15", "side": "SELL", "hash": "1af239bb0b89a1f1083f79eb189e357a5c1c9c09", "best_bid": "0.01", "best_ask": "0.79"}, {"asset_id": "69100260301420797247941786085257042358554422352183746124379790103566465901104", "price": "0.21", "size": "15", "side": "BUY", "hash": "58a8fec1405ecbc37a8a3e60433466bc24861525", "best_bid": "0.21", "best_ask": "0.99"}], "timestamp": "1769384175950", "event_type": "price_change"}}
{"_local_timestamp": "2026-01-25T23:36:16.022104+00:00", "data": {"market": "0x96449838d7dc6702e356ceb13144a6e53408b728ca363dc96b379320a2552d64", "price_changes": [{"asset_id": "98265373238824778819853870879462811197150130214114951682085083828419115905786", "price": "0.68", "size": "15", "side": "SELL", "hash": "be979e14d27cd1786119d99150e12a0ab454245a", "best_bid": "0.05", "best_ask": "0.68"}, {"asset_id": "88669991566060336244616088283363604665361049459599965771564136419124853077521", "price": "0.32", "size": "15", "side": "BUY", "hash": "cd6ed7762436419a4a1a870642eb389546f11d01", "best_bid": "0.32", "best_ask": "0.95"}], "timestamp": "1769384175950", "event_type": "price_change"}}
{"_local_timestamp": "2026-01-25T23:36:17.866747+00:00", "data": {"market": "0xaa46cd9dfbc750e16e767ab71cdfbaaa9f3bbf68153fcb7e9e21bdad1f9a0e4e", "price_changes": [{"asset_id": "10190047580304467488950735708592587854326252278861442489701414156559786950928", "price": "0.21", "size": "0", "side": "BUY", "hash": "1917a01ff14f2a0bd53097fc1a09e207014e3d0e", "best_bid": "0.3", "best_ask": "0.94"}, {"asset_id": "88155858711031400772451028879251834333349215458844495516447987085254946467393", "price": "0.79", "size": "0", "side": "SELL", "hash": "2d95062f2b47d249458c290571004c863919c128", "best_bid": "0.06", "best_ask": "0.7"}], "timestamp": "1769384177799", "event_type": "price_change"}}
{"_local_timestamp": "2026-01-25T23:36:17.867386+00:00", "data": {"market": "0x9ad98d277747a5af33029daa93d8921e20dc48fc43a13444b34abd5db3090419", "price_changes": [{"asset_id": "84279332923568891895771507663060971052533473524984039519051747621941395607490", "price": "0.27", "size": "0", "side": "BUY", "hash": "8903e894189ad8569bfecfc8261cc28941569f38", "best_bid": "0.28", "best_ask": "0.96"}, {"asset_id": "13106897552498929473034004606662562096233616324310660731332487169842346464915", "price": "0.73", "size": "0", "side": "SELL", "hash": "a86ca6d1eb81665a40ba170d1e79f48423c73663", "best_bid": "0.04", "best_ask": "0.72"}], "timestamp": "1769384177799", "event_type": "price_change"}}
{"_local_timestamp": "2026-01-25T23:36:17.867908+00:00", "data": {"market": "0xedfafd25484c04cfbeaa767022f9eca5bb680918fceece81b36b0611eb3638a6", "price_changes": [{"asset_id": "69100260301420797247941786085257042358554422352183746124379790103566465901104", "price": "0.2", "size": "0", "side": "BUY", "hash": "7970fcfbf7b375e4214e7f60fafdbd58874cd95c", "best_bid": "0.21", "best_ask": "0.99"}, {"asset_id": "5193041395342261568372064995546886956660044551128159772340877211907014735905", "price": "0.8", "size": "0", "side": "SELL", "hash": "7c0e354f61fd96fae748f7733e9c333f35bddaa0", "best_bid": "0.01", "best_ask": "0.79"}], "timestamp": "1769384177799", "event_type": "price_change"}}
{"_local_timestamp": "2026-01-25T23:36:17.868426+00:00", "data": {"market": "0x3be55688f3eecd53db101048ec9c372230efc90f004c1c4e3fce8dd1d2c4dada", "price_changes": [{"asset_id": "85304840619071051396870312932957819961814877219759465827862543288479782634253", "price": "0.28", "size": "0", "side": "BUY", "hash": "f9639841e85fded7d60417fc43974e2cbd217a55", "best_bid": "0.29", "best_ask": "0.98"}, {"asset_id": "25385091870387844891345378992524415372478832284204632642650074498441270262521", "price": "0.72", "size": "0", "side": "SELL", "hash": "f9e334f4a145730f25ceb8c4eb06ea99816697b7", "best_bid": "0.02", "best_ask": "0.71"}], "timestamp": "1769384177799", "event_type": "price_change"}}
{"_local_timestamp": "2026-01-25T23:36:17.899316+00:00", "data": {"market": "0xaa46cd9dfbc750e16e767ab71cdfbaaa9f3bbf68153fcb7e9e21bdad1f9a0e4e", "price_changes": [{"asset_id": "10190047580304467488950735708592587854326252278861442489701414156559786950928", "price": "0.23", "size": "10", "side": "BUY", "hash": "bf6323380d795bfd66c65c1ac55944bf7c90a99c", "best_bid": "0.3", "best_ask": "0.94"}, {"asset_id": "88155858711031400772451028879251834333349215458844495516447987085254946467393", "price": "0.77", "size": "10", "side": "SELL", "hash": "9dd22d7e08b546a9216eaf51e79982eebdddc29a", "best_bid": "0.06", "best_ask": "0.7"}], "timestamp": "1769384177826", "event_type": "price_change"}}
{"_local_timestamp": "2026-01-25T23:36:17.899925+00:00", "data": {"market": "0xedfafd25484c04cfbeaa767022f9eca5bb680918fceece81b36b0611eb3638a6", "price_changes": [{"asset_id": "69100260301420797247941786085257042358554422352183746124379790103566465901104", "price": "0.22", "size": "20", "side": "BUY", "hash": "2ded097137f9db254217b75aaf04c91d88fed018", "best_bid": "0.22", "best_ask": "0.99"}, {"asset_id": "5193041395342261568372064995546886956660044551128159772340877211907014735905", "price": "0.78", "size": "20", "side": "SELL", "hash": "5ff892c1edb1b884bcaf0929e415da297385a352", "best_bid": "0.01", "best_ask": "0.78"}], "timestamp": "1769384177826", "event_type": "price_change"}}
{"_local_timestamp": "2026-01-25T23:36:17.900460+00:00", "data": {"market": "0x3be55688f3eecd53db101048ec9c372230efc90f004c1c4e3fce8dd1d2c4dada", "price_changes": [{"asset_id": "85304840619071051396870312932957819961814877219759465827862543288479782634253", "price": "0.3", "size": "10", "side": "BUY", "hash": "11ee07e2f64cbe4f6de2b23b3a397f8ef17a7d8e", "best_bid": "0.3", "best_ask": "0.98"}, {"asset_id": "25385091870387844891345378992524415372478832284204632642650074498441270262521", "price": "0.7", "size": "10", "side": "SELL", "hash": "7e37538bf6d77111bee5a40358ba3f94d9ab4cf9", "best_bid": "0.02", "best_ask": "0.7"}], "timestamp": "1769384177826", "event_type": "price_change"}}
{"_local_timestamp": "2026-01-25T23:36:17.900989+00:00", "data": {"market": "0x9ad98d277747a5af33029daa93d8921e20dc48fc43a13444b34abd5db3090419", "price_changes": [{"asset_id": "84279332923568891895771507663060971052533473524984039519051747621941395607490", "price": "0.29", "size": "10", "side": "BUY", "hash": "d62a7ae1db5a77dbe44c23c29c5f368e34a11c40", "best_bid": "0.29", "best_ask": "0.96"}, {"asset_id": "13106897552498929473034004606662562096233616324310660731332487169842346464915", "price": "0.71", "size": "10", "side": "SELL", "hash": "8c7a526b1c85256f95ef2681bb8b3765d01276d3", "best_bid": "0.04", "best_ask": "0.71"}], "timestamp": "1769384177826", "event_type": "price_change"}}
{"_local_timestamp": "2026-01-25T23:36:34.293056+00:00", "data": {"market": "0x96449838d7dc6702e356ceb13144a6e53408b728ca363dc96b379320a2552d64", "price_changes": [{"asset_id": "88669991566060336244616088283363604665361049459599965771564136419124853077521", "price": "0.31", "size": "0", "side": "BUY", "hash": "cce29d5ebda3b5ce3a2aa1d7fda3a6e7ec72afd2", "best_bid": "0.32", "best_ask": "0.95"}, {"asset_id": "98265373238824778819853870879462811197150130214114951682085083828419115905786", "price": "0.69", "size": "0", "side": "SELL", "hash": "1a5a0411168d9f9a598ccdba2e1b077d38fb0c6c", "best_bid": "0.05", "best_ask": "0.68"}], "timestamp": "1769384194231", "event_type": "price_change"}}
{"_local_timestamp": "2026-01-25T23:36:40.491817+00:00", "data": {"market": "0x9ad98d277747a5af33029daa93d8921e20dc48fc43a13444b34abd5db3090419", "price_changes": [{"asset_id": "84279332923568891895771507663060971052533473524984039519051747621941395607490", "price": "0.24", "size": "0", "side": "BUY", "hash": "2b5f97a2bd09c337ca8b1bf8eb27053d89ae92b2", "best_bid": "0.29", "best_ask": "0.96"}, {"asset_id": "13106897552498929473034004606662562096233616324310660731332487169842346464915", "price": "0.76", "size": "0", "side": "SELL", "hash": "4ca787c2a1d9d5f4a66f463b2d35e904865dfc79", "best_bid": "0.04", "best_ask": "0.71"}], "timestamp": "1769384200411", "event_type": "price_change"}}
{"_local_timestamp": "2026-01-25T23:36:40.492571+00:00", "data": {"market": "0x96449838d7dc6702e356ceb13144a6e53408b728ca363dc96b379320a2552d64", "price_changes": [{"asset_id": "88669991566060336244616088283363604665361049459599965771564136419124853077521", "price": "0.13", "size": "0", "side": "BUY", "hash": "2879eb22aa1ebabfa25d33ea9937d11ab831deca", "best_bid": "0.32", "best_ask": "0.95"}, {"asset_id": "98265373238824778819853870879462811197150130214114951682085083828419115905786", "price": "0.87", "size": "0", "side": "SELL", "hash": "b44f4c1d1b4718630e52738d8de5f6d9167b2c22", "best_bid": "0.05", "best_ask": "0.68"}], "timestamp": "1769384200411", "event_type": "price_change"}}
{"_local_timestamp": "2026-01-25T23:36:40.503548+00:00", "data": {"market": "0xedfafd25484c04cfbeaa767022f9eca5bb680918fceece81b36b0611eb3638a6", "price_changes": [{"asset_id": "69100260301420797247941786085257042358554422352183746124379790103566465901104", "price": "0.17", "size": "0", "side": "BUY", "hash": "9f08793f2b1a63caf9f0549c52de5b9b68d0c653", "best_bid": "0.22", "best_ask": "0.99"}, {"asset_id": "5193041395342261568372064995546886956660044551128159772340877211907014735905", "price": "0.83", "size": "0", "side": "SELL", "hash": "6ee063bd4bdb7141e7ec2456d1911d65d2af0d62", "best_bid": "0.01", "best_ask": "0.78"}], "timestamp": "1769384200410", "event_type": "price_change"}}
{"_local_timestamp": "2026-01-25T23:36:44.580881+00:00", "data": {"market": "0x96449838d7dc6702e356ceb13144a6e53408b728ca363dc96b379320a2552d64", "price_changes": [{"asset_id": "88669991566060336244616088283363604665361049459599965771564136419124853077521", "price": "0.14", "size": "0", "side": "BUY", "hash": "c11eaac6fab231fcc00830a288b167c51c903881", "best_bid": "0.32", "best_ask": "0.95"}, {"asset_id": "98265373238824778819853870879462811197150130214114951682085083828419115905786", "price": "0.86", "size": "0", "side": "SELL", "hash": "947a782a19b0e508f18e366fda6955b0f170ffbd", "best_bid": "0.05", "best_ask": "0.68"}], "timestamp": "1769384204518", "event_type": "price_change"}}
{"_local_timestamp": "2026-01-25T23:36:44.605452+00:00", "data": {"market": "0x96449838d7dc6702e356ceb13144a6e53408b728ca363dc96b379320a2552d64", "price_changes": [{"asset_id": "88669991566060336244616088283363604665361049459599965771564136419124853077521", "price": "0.11", "size": "10", "side": "BUY", "hash": "6f7c779186382f2064d9c37988c1285ca3691e7a", "best_bid": "0.32", "best_ask": "0.95"}, {"asset_id": "98265373238824778819853870879462811197150130214114951682085083828419115905786", "price": "0.89", "size": "10", "side": "SELL", "hash": "4d3dee756ca3bd4551046d465dfa92332cca0044", "best_bid": "0.05", "best_ask": "0.68"}], "timestamp": "1769384204543", "event_type": "price_change"}}
{"_local_timestamp": "2026-01-25T23:36:57.782390+00:00", "data": {"market": "0xa5dfea726fd2d83ac1a27258772cd48851dcee92bc0b27a4cbfbba3f0ce7cf0c", "price_changes": [{"asset_id": "4176312783107261224228021331826499988248979157870484532774384638562296270852", "price": "0.21", "size": "9", "side": "BUY", "hash": "354d86c699943acdf6e57acae3e8fa07c73a3a24", "best_bid": "0.61", "best_ask": "0.95"}, {"asset_id": "64980057195304605902961943648606034709103501739113681540832298163772674344737", "price": "0.79", "size": "9", "side": "SELL", "hash": "9e438260952ccefc02920ec8e0aa2873de0eb772", "best_bid": "0.05", "best_ask": "0.39"}], "timestamp": "1769384217258", "event_type": "price_change"}}
{"_local_timestamp": "2026-01-25T23:37:17.797639+00:00", "data": {"market": "0xa5dfea726fd2d83ac1a27258772cd48851dcee92bc0b27a4cbfbba3f0ce7cf0c", "price_changes": [{"asset_id": "4176312783107261224228021331826499988248979157870484532774384638562296270852", "price": "0.23", "size": "7", "side": "BUY", "hash": "a3e8bc73155de0624cc660c1b67d4aba057bc3ae", "best_bid": "0.61", "best_ask": "0.95"}, {"asset_id": "64980057195304605902961943648606034709103501739113681540832298163772674344737", "price": "0.77", "size": "7", "side": "SELL", "hash": "9d7b0cdda2c10e22273e3e68ccd8ac138a281f3a", "best_bid": "0.05", "best_ask": "0.39"}], "timestamp": "1769384237728", "event_type": "price_change"}}
{"_local_timestamp": "2026-01-25T23:37:50.648762+00:00", "data": {"market": "0x96449838d7dc6702e356ceb13144a6e53408b728ca363dc96b379320a2552d64", "price_changes": [{"asset_id": "98265373238824778819853870879462811197150130214114951682085083828419115905786", "price": "0.68", "size": "0", "side": "SELL", "hash": "5c8610620f583afa89d2878c13ab717d6c318982", "best_bid": "0.05", "best_ask": "0.89"}, {"asset_id": "88669991566060336244616088283363604665361049459599965771564136419124853077521", "price": "0.32", "size": "0", "side": "BUY", "hash": "f4186b2d4f6396aa9a7271e0dbbc92a3cbf87576", "best_bid": "0.11", "best_ask": "0.95"}], "timestamp": "1769384270571", "event_type": "price_change"}}
{"_local_timestamp": "2026-01-25T23:37:50.649543+00:00", "data": {"market": "0x3be55688f3eecd53db101048ec9c372230efc90f004c1c4e3fce8dd1d2c4dada", "price_changes": [{"asset_id": "25385091870387844891345378992524415372478832284204632642650074498441270262521", "price": "0.71", "size": "0", "side": "SELL", "hash": "d61489ed215cd919381f84bbb464343213ff4976", "best_bid": "0.02", "best_ask": "0.7"}, {"asset_id": "85304840619071051396870312932957819961814877219759465827862543288479782634253", "price": "0.29", "size": "0", "side": "BUY", "hash": "4fc5cdc59aa7b2f88f86d5d8b4999e38e0573a6d", "best_bid": "0.3", "best_ask": "0.98"}], "timestamp": "1769384270571", "event_type": "price_change"}}
{"_local_timestamp": "2026-01-25T23:37:50.650144+00:00", "data": {"market": "0xedfafd25484c04cfbeaa767022f9eca5bb680918fceece81b36b0611eb3638a6", "price_changes": [{"asset_id": "5193041395342261568372064995546886956660044551128159772340877211907014735905", "price": "0.79", "size": "0", "side": "SELL", "hash": "2dcf072a07a617964d1fed11343b069c1b13ecc8", "best_bid": "0.01", "best_ask": "0.78"}, {"asset_id": "69100260301420797247941786085257042358554422352183746124379790103566465901104", "price": "0.21", "size": "0", "side": "BUY", "hash": "0e9eb9b54a8b1c675424b9ef61a88ec8fcc10592", "best_bid": "0.22", "best_ask": "0.99"}], "timestamp": "1769384270571", "event_type": "price_change"}}
{"_local_timestamp": "2026-01-25T23:37:50.650685+00:00", "data": {"market": "0x9ad98d277747a5af33029daa93d8921e20dc48fc43a13444b34abd5db3090419", "price_changes": [{"asset_id": "13106897552498929473034004606662562096233616324310660731332487169842346464915", "price": "0.72", "size": "0", "side": "SELL", "hash": "92179e78ce375353c7de5b507f638d88fde0d636", "best_bid": "0.04", "best_ask": "0.71"}, {"asset_id": "84279332923568891895771507663060971052533473524984039519051747621941395607490", "price": "0.28", "size": "0", "side": "BUY", "hash": "ef59a0ebcbaa6d8a513a65cf4dcf80d58d29f0c3", "best_bid": "0.29", "best_ask": "0.96"}], "timestamp": "1769384270571", "event_type": "price_change"}}
{"_local_timestamp": "2026-01-25T23:37:50.684147+00:00", "data": {"market": "0xa5dfea726fd2d83ac1a27258772cd48851dcee92bc0b27a4cbfbba3f0ce7cf0c", "price_changes": [{"asset_id": "4176312783107261224228021331826499988248979157870484532774384638562296270852", "price": "0.22", "size": "0", "side": "BUY", "hash": "63052b5308fd98112eb53bef8d1d38463fdea21b", "best_bid": "0.61", "best_ask": "0.95"}, {"asset_id": "64980057195304605902961943648606034709103501739113681540832298163772674344737", "price": "0.78", "size": "0", "side": "SELL", "hash": "b8c33e127c0e706881c56d1cf24bf20ec48217eb", "best_bid": "0.05", "best_ask": "0.39"}], "timestamp": "1769384270616", "event_type": "price_change"}}
{"_local_timestamp": "2026-01-25T23:37:50.685395+00:00", "data": {"market": "0xba7bb363782238a06ea70ba7b726292e99d017dd37dd8322a3309b257d5e3a53", "price_changes": [{"asset_id": "70665643461197636242766365969385844686558838063736166515342466618906333119822", "price": "0.168", "size": "12", "side": "BUY", "hash": "4bd843726252e621f3bdfb7423df50f45349b758", "best_bid": "0.932", "best_ask": "0.989"}, {"asset_id": "86624152659324411612488193633471157021628076444264217402058630710804185298932", "price": "0.832", "size": "12", "side": "SELL", "hash": "65d1d9e9a5916eabb361297766f28c6becf55f34", "best_bid": "0.011", "best_ask": "0.068"}], "timestamp": "1769384270616", "event_type": "price_change"}}
{"_local_timestamp": "2026-01-25T23:37:50.783856+00:00", "data": {"market": "0xba7bb363782238a06ea70ba7b726292e99d017dd37dd8322a3309b257d5e3a53", "price_changes": [{"asset_id": "70665643461197636242766365969385844686558838063736166515342466618906333119822", "price": "0.162", "size": "0", "side": "BUY", "hash": "8f4d2c816f0772e3bbf51b124b2ca48e07926011", "best_bid": "0.932", "best_ask": "0.989"}, {"asset_id": "86624152659324411612488193633471157021628076444264217402058630710804185298932", "price": "0.838", "size": "0", "side": "SELL", "hash": "f4d1e85a556c65000da1e3b68a7732cc27eab702", "best_bid": "0.011", "best_ask": "0.068"}], "timestamp": "1769384270694", "event_type": "price_change"}}
{"_local_timestamp": "2026-01-25T23:37:50.785158+00:00", "data": {"market": "0x96449838d7dc6702e356ceb13144a6e53408b728ca363dc96b379320a2552d64", "price_changes": [{"asset_id": "88669991566060336244616088283363604665361049459599965771564136419124853077521", "price": "0.09", "size": "0", "side": "BUY", "hash": "c5040489db70b79fc93b59076368b016951a1d61", "best_bid": "0.11", "best_ask": "0.95"}, {"asset_id": "98265373238824778819853870879462811197150130214114951682085083828419115905786", "price": "0.91", "size": "0", "side": "SELL", "hash": "bd2853b752dd7ee2c39cdc75ac01b955555b4226", "best_bid": "0.05", "best_ask": "0.89"}], "timestamp": "1769384270694", "event_type": "price_change"}}
{"_local_timestamp": "2026-01-25T23:37:50.884627+00:00", "data": {"market": "0xba7bb363782238a06ea70ba7b726292e99d017dd37dd8322a3309b257d5e3a53", "price_changes": [{"asset_id": "70665643461197636242766365969385844686558838063736166515342466618906333119822", "price": "0.17", "size": "10", "side": "BUY", "hash": "2dd298ecf8425282e78544842ef0b6120a1fda76", "best_bid": "0.932", "best_ask": "0.989"}, {"asset_id": "86624152659324411612488193633471157021628076444264217402058630710804185298932", "price": "0.83", "size": "10", "side": "SELL", "hash": "06fea008a87611eb23da32d68f2c6f8204662bee", "best_bid": "0.011", "best_ask": "0.068"}], "timestamp": "1769384270813", "event_type": "price_change"}}
{"_local_timestamp": "2026-01-25T23:37:50.885888+00:00", "data": {"market": "0x96449838d7dc6702e356ceb13144a6e53408b728ca363dc96b379320a2552d64", "price_changes": [{"asset_id": "88669991566060336244616088283363604665361049459599965771564136419124853077521", "price": "0.12", "size": "100", "side": "BUY", "hash": "daade1d49fdb0e1caa1c413f40d85846d2065471", "best_bid": "0.12", "best_ask": "0.95"}, {"asset_id": "98265373238824778819853870879462811197150130214114951682085083828419115905786", "price": "0.88", "size": "100", "side": "SELL", "hash": "b1fbbd2c4a18dec394f24395c1cb061ad0a46aa0", "best_bid": "0.05", "best_ask": "0.88"}], "timestamp": "1769384270813", "event_type": "price_change"}}
{"_local_timestamp": "2026-01-25T23:37:50.895258+00:00", "data": {"market": "0x96449838d7dc6702e356ceb13144a6e53408b728ca363dc96b379320a2552d64", "price_changes": [{"asset_id": "88669991566060336244616088283363604665361049459599965771564136419124853077521", "price": "0.12", "size": "110", "side": "BUY", "hash": "4bb4a5f1263fa27a2f31049c6f9806fdb8aa7688", "best_bid": "0.12", "best_ask": "0.95"}, {"asset_id": "98265373238824778819853870879462811197150130214114951682085083828419115905786", "price": "0.88", "size": "110", "side": "SELL", "hash": "dcbb85467dfcc36fc39af1de55a797bde5b5b2cf", "best_bid": "0.05", "best_ask": "0.88"}], "timestamp": "1769384270816", "event_type": "price_change"}}
{"_local_timestamp": "2026-01-25T23:37:50.896001+00:00", "data": {"market": "0xba7bb363782238a06ea70ba7b726292e99d017dd37dd8322a3309b257d5e3a53", "price_changes": [{"asset_id": "70665643461197636242766365969385844686558838063736166515342466618906333119822", "price": "0.17", "size": "102", "side": "BUY", "hash": "17938f4062ec836764f9b091a47c94622b87d9ae", "best_bid": "0.932", "best_ask": "0.989"}, {"asset_id": "86624152659324411612488193633471157021628076444264217402058630710804185298932", "price": "0.83", "size": "102", "side": "SELL", "hash": "5928efe29a552f173269d34aa2deb861ee4b7cfa", "best_bid": "0.011", "best_ask": "0.068"}], "timestamp": "1769384270816", "event_type": "price_change"}}
{"_local_timestamp": "2026-01-25T23:37:51.618738+00:00", "data": {"market": "0x9ad98d277747a5af33029daa93d8921e20dc48fc43a13444b34abd5db3090419", "price_changes": [{"asset_id": "13106897552498929473034004606662562096233616324310660731332487169842346464915", "price": "0.7", "size": "15", "side": "SELL", "hash": "7b703f439238ad2823f2cdd8db7ec30ae2e58269", "best_bid": "0.04", "best_ask": "0.7"}, {"asset_id": "84279332923568891895771507663060971052533473524984039519051747621941395607490", "price": "0.3", "size": "15", "side": "BUY", "hash": "c683e67239e13c298a7e941c56bab97e4574b8b6", "best_bid": "0.3", "best_ask": "0.96"}], "timestamp": "1769384271322", "event_type": "price_change"}}
{"_local_timestamp": "2026-01-25T23:37:51.627744+00:00", "data": {"market": "0xedfafd25484c04cfbeaa767022f9eca5bb680918fceece81b36b0611eb3638a6", "price_changes": [{"asset_id": "5193041395342261568372064995546886956660044551128159772340877211907014735905", "price": "0.77", "size": "15", "side": "SELL", "hash": "6e2a3124ba550498525cbc54a1dc681725e6edeb", "best_bid": "0.01", "best_ask": "0.77"}, {"asset_id": "69100260301420797247941786085257042358554422352183746124379790103566465901104", "price": "0.23", "size": "15", "side": "BUY", "hash": "0339d3923c41b2504d42efff695f7fecd7178ee5", "best_bid": "0.23", "best_ask": "0.99"}], "timestamp": "1769384271322", "event_type": "price_change"}}
{"_local_timestamp": "2026-01-25T23:37:51.628417+00:00", "data": {"market": "0x3be55688f3eecd53db101048ec9c372230efc90f004c1c4e3fce8dd1d2c4dada", "price_changes": [{"asset_id": "25385091870387844891345378992524415372478832284204632642650074498441270262521", "price": "0.69", "size": "15", "side": "SELL", "hash": "373f17cf1d1ec87f4eb1400bb5ff8861231dacce", "best_bid": "0.02", "best_ask": "0.69"}, {"asset_id": "85304840619071051396870312932957819961814877219759465827862543288479782634253", "price": "0.31", "size": "15", "side": "BUY", "hash": "c40c173f8d9546a6951b73d020770391b04871f9", "best_bid": "0.31", "best_ask": "0.98"}], "timestamp": "1769384271322", "event_type": "price_change"}}
{"_local_timestamp": "2026-01-25T23:37:51.628993+00:00", "data": {"market": "0x96449838d7dc6702e356ceb13144a6e53408b728ca363dc96b379320a2552d64", "price_changes": [{"asset_id": "98265373238824778819853870879462811197150130214114951682085083828419115905786", "price": "0.88", "size": "125", "side": "SELL", "hash": "10a05e21bb5d876b2a22cb54dbd6a24a5783f115", "best_bid": "0.05", "best_ask": "0.88"}, {"asset_id": "88669991566060336244616088283363604665361049459599965771564136419124853077521", "price": "0.12", "size": "125", "side": "BUY", "hash": "4a58c0082b908fd25d8cf676d46682179cce0221", "best_bid": "0.12", "best_ask": "0.95"}], "timestamp": "1769384271323", "event_type": "price_change"}}
{"_local_timestamp": "2026-01-25T23:37:51.671286+00:00", "data": {"market": "0x96449838d7dc6702e356ceb13144a6e53408b728ca363dc96b379320a2552d64", "price_changes": [{"asset_id": "88669991566060336244616088283363604665361049459599965771564136419124853077521", "price": "0.12", "size": "25", "side": "BUY", "hash": "2378ac09d0b47859820c50d0d89aea4f7c9a8a4a", "best_bid": "0.12", "best_ask": "0.95"}, {"asset_id": "98265373238824778819853870879462811197150130214114951682085083828419115905786", "price": "0.88", "size": "25", "side": "SELL", "hash": "51dc3cc5fda82903696001ab214dd7307e5e1bc2", "best_bid": "0.05", "best_ask": "0.88"}], "timestamp": "1769384271379", "event_type": "price_change"}}
{"_local_timestamp": "2026-01-25T23:37:51.672038+00:00", "data": {"market": "0xba7bb363782238a06ea70ba7b726292e99d017dd37dd8322a3309b257d5e3a53", "price_changes": [{"asset_id": "70665643461197636242766365969385844686558838063736166515342466618906333119822", "price": "0.17", "size": "10", "side": "BUY", "hash": "4ea3a07c9ebc633ace74be2272f6dcb803a323d4", "best_bid": "0.932", "best_ask": "0.989"}, {"asset_id": "86624152659324411612488193633471157021628076444264217402058630710804185298932", "price": "0.83", "size": "10", "side": "SELL", "hash": "0b24b690ee5a86f4dbcf13e0cec3300aa5e3d28f", "best_bid": "0.011", "best_ask": "0.068"}], "timestamp": "1769384271379", "event_type": "price_change"}}
{"_local_timestamp": "2026-01-25T23:37:51.875063+00:00", "data": {"market": "0xa5dfea726fd2d83ac1a27258772cd48851dcee92bc0b27a4cbfbba3f0ce7cf0c", "price_changes": [{"asset_id": "4176312783107261224228021331826499988248979157870484532774384638562296270852", "price": "0.27", "size": "0", "side": "BUY", "hash": "7d8a4539f466ebf83788f5d2d9ee8c6eed3fe15e", "best_bid": "0.61", "best_ask": "0.95"}, {"asset_id": "64980057195304605902961943648606034709103501739113681540832298163772674344737", "price": "0.73", "size": "0", "side": "SELL", "hash": "c8b4a430cb1bf07d022c5af63988424891331e9e", "best_bid": "0.05", "best_ask": "0.39"}], "timestamp": "1769384271808", "event_type": "price_change"}}
{"_local_timestamp": "2026-01-25T23:37:51.882116+00:00", "data": {"market": "0xba7bb363782238a06ea70ba7b726292e99d017dd37dd8322a3309b257d5e3a53", "price_changes": [{"asset_id": "70665643461197636242766365969385844686558838063736166515342466618906333119822", "price": "0.168", "size": "0", "side": "BUY", "hash": "f445d0bad24a693e96631d70c3c713d7630330ea", "best_bid": "0.932", "best_ask": "0.989"}, {"asset_id": "86624152659324411612488193633471157021628076444264217402058630710804185298932", "price": "0.832", "size": "0", "side": "SELL", "hash": "f686ba0635d18059349e5769e05ec45bf7fc4dc3", "best_bid": "0.011", "best_ask": "0.068"}], "timestamp": "1769384271808", "event_type": "price_change"}}
{"_local_timestamp": "2026-01-25T23:37:51.923688+00:00", "data": {"market": "0xa5dfea726fd2d83ac1a27258772cd48851dcee92bc0b27a4cbfbba3f0ce7cf0c", "price_changes": [{"asset_id": "4176312783107261224228021331826499988248979157870484532774384638562296270852", "price": "0.21", "size": "65", "side": "BUY", "hash": "c89127b7936830feadd4c02ed3729c3906c2a529", "best_bid": "0.61", "best_ask": "0.95"}, {"asset_id": "64980057195304605902961943648606034709103501739113681540832298163772674344737", "price": "0.79", "size": "65", "side": "SELL", "hash": "464ed1df6cb4193b31e49b22dcfc5cdb8bd509c1", "best_bid": "0.05", "best_ask": "0.39"}], "timestamp": "1769384271857", "event_type": "price_change"}}
{"_local_timestamp": "2026-01-25T23:37:51.924378+00:00", "data": {"market": "0xba7bb363782238a06ea70ba7b726292e99d017dd37dd8322a3309b257d5e3a53", "price_changes": [{"asset_id": "70665643461197636242766365969385844686558838063736166515342466618906333119822", "price": "0.171", "size": "12", "side": "BUY", "hash": "ac0888ae78efbce14b249d104aa7e032d4371cd3", "best_bid": "0.932", "best_ask": "0.989"}, {"asset_id": "86624152659324411612488193633471157021628076444264217402058630710804185298932", "price": "0.829", "size": "12", "side": "SELL", "hash": "a2f2948e8d72b10d6d80a8dd0b962c47d537dcf6", "best_bid": "0.011", "best_ask": "0.068"}], "timestamp": "1769384271857", "event_type": "price_change"}}
{"_local_timestamp": "2026-01-25T23:37:51.942940+00:00", "data": {"market": "0xa5dfea726fd2d83ac1a27258772cd48851dcee92bc0b27a4cbfbba3f0ce7cf0c", "price_changes": [{"asset_id": "4176312783107261224228021331826499988248979157870484532774384638562296270852", "price": "0.3", "size": "20", "side": "BUY", "hash": "8865a3185edfd26f7d0cdc84f11e3b9070b27b35", "best_bid": "0.61", "best_ask": "0.95"}, {"asset_id": "64980057195304605902961943648606034709103501739113681540832298163772674344737", "price": "0.7", "size": "20", "side": "SELL", "hash": "a166750b14c3c431e2c83ccef35efb4bc26d9f4d", "best_bid": "0.05", "best_ask": "0.39"}], "timestamp": "1769384271859", "event_type": "price_change"}}
{"_local_timestamp": "2026-01-25T23:37:51.943631+00:00", "data": {"market": "0xba7bb363782238a06ea70ba7b726292e99d017dd37dd8322a3309b257d5e3a53", "price_changes": [{"asset_id": "70665643461197636242766365969385844686558838063736166515342466618906333119822", "price": "0.171", "size": "19", "side": "BUY", "hash": "62fab3c45ae98c13afd99558fa0a328704738caf", "best_bid": "0.932", "best_ask": "0.989"}, {"asset_id": "86624152659324411612488193633471157021628076444264217402058630710804185298932", "price": "0.829", "size": "19", "side": "SELL", "hash": "2223430a378448e75503ac33ff2437f92fb505e9", "best_bid": "0.011", "best_ask": "0.068"}], "timestamp": "1769384271861", "event_type": "price_change"}}
{"_local_timestamp": "2026-01-25T23:37:51.944224+00:00", "data": {"market": "0xa5dfea726fd2d83ac1a27258772cd48851dcee92bc0b27a4cbfbba3f0ce7cf0c", "price_changes": [{"asset_id": "4176312783107261224228021331826499988248979157870484532774384638562296270852", "price": "0.24", "size": "15", "side": "BUY", "hash": "56ee70571d3a9de99008354053e90e3787a1c263", "best_bid": "0.61", "best_ask": "0.95"}, {"asset_id": "64980057195304605902961943648606034709103501739113681540832298163772674344737", "price": "0.76", "size": "15", "side": "SELL", "hash": "c317f82aa5f88fe8f92f3720c41c268161e83ad9", "best_bid": "0.05", "best_ask": "0.39"}], "timestamp": "1769384271863", "event_type": "price_change"}}
{"_local_timestamp": "2026-01-25T23:37:52.407449+00:00", "data": {"market": "0xa5dfea726fd2d83ac1a27258772cd48851dcee92bc0b27a4cbfbba3f0ce7cf0c", "price_changes": [{"asset_id": "4176312783107261224228021331826499988248979157870484532774384638562296270852", "price": "0.3", "size": "10", "side": "BUY", "hash": "ea36ec918c4530f5de4e6b60aee4e8deb864b2e7", "best_bid": "0.61", "best_ask": "0.95"}, {"asset_id": "64980057195304605902961943648606034709103501739113681540832298163772674344737", "price": "0.7", "size": "10", "side": "SELL", "hash": "9dacb97d9f119a456dd8a6e62401ae257de23225", "best_bid": "0.05", "best_ask": "0.39"}], "timestamp": "1769384272330", "event_type": "price_change"}}
{"_local_timestamp": "2026-01-25T23:37:52.408085+00:00", "data": {"market": "0xa5dfea726fd2d83ac1a27258772cd48851dcee92bc0b27a4cbfbba3f0ce7cf0c", "price_changes": [{"asset_id": "4176312783107261224228021331826499988248979157870484532774384638562296270852", "price": "0.21", "size": "9", "side": "BUY", "hash": "ea36ec918c4530f5de4e6b60aee4e8deb864b2e7", "best_bid": "0.61", "best_ask": "0.95"}, {"asset_id": "64980057195304605902961943648606034709103501739113681540832298163772674344737", "price": "0.79", "size": "9", "side": "SELL", "hash": "9dacb97d9f119a456dd8a6e62401ae257de23225", "best_bid": "0.05", "best_ask": "0.39"}], "timestamp": "1769384272330", "event_type": "price_change"}}
{"_local_timestamp": "2026-01-25T23:37:52.607511+00:00", "data": {"market": "0xedfafd25484c04cfbeaa767022f9eca5bb680918fceece81b36b0611eb3638a6", "price_changes": [{"asset_id": "69100260301420797247941786085257042358554422352183746124379790103566465901104", "price": "0.22", "size": "0", "side": "BUY", "hash": "f5d353a565ad1de6e34e9d3c490dcd5b05f56cf3", "best_bid": "0.23", "best_ask": "0.99"}, {"asset_id": "5193041395342261568372064995546886956660044551128159772340877211907014735905", "price": "0.78", "size": "0", "side": "SELL", "hash": "e9154842d3f132c30510defc387f85cd80be93a8", "best_bid": "0.01", "best_ask": "0.77"}], "timestamp": "1769384272535", "event_type": "price_change"}}
{"_local_timestamp": "2026-01-25T23:37:52.608194+00:00", "data": {"market": "0x96449838d7dc6702e356ceb13144a6e53408b728ca363dc96b379320a2552d64", "price_changes": [{"asset_id": "88669991566060336244616088283363604665361049459599965771564136419124853077521", "price": "0.11", "size": "0", "side": "BUY", "hash": "63098636b6b05323e720296c0540c69c81286cd3", "best_bid": "0.12", "best_ask": "0.95"}, {"asset_id": "98265373238824778819853870879462811197150130214114951682085083828419115905786", "price": "0.89", "size": "0", "side": "SELL", "hash": "94abf1d78d8e15a58cb641d31d52650ec4d58850", "best_bid": "0.05", "best_ask": "0.88"}], "timestamp": "1769384272535", "event_type": "price_change"}}
{"_local_timestamp": "2026-01-25T23:37:52.608792+00:00", "data": {"market": "0x9ad98d277747a5af33029daa93d8921e20dc48fc43a13444b34abd5db3090419", "price_changes": [{"asset_id": "84279332923568891895771507663060971052533473524984039519051747621941395607490", "price": "0.29", "size": "0", "side": "BUY", "hash": "4a2b8da467336c73c2f139ae81cc583391dd1a27", "best_bid": "0.3", "best_ask": "0.96"}, {"asset_id": "13106897552498929473034004606662562096233616324310660731332487169842346464915", "price": "0.71", "size": "0", "side": "SELL", "hash": "ffbe89a27a07e1327fcb7a9f1c4e0cf791ff3287", "best_bid": "0.04", "best_ask": "0.7"}], "timestamp": "1769384272535", "event_type": "price_change"}}
{"_local_timestamp": "2026-01-25T23:37:52.609378+00:00", "data": {"market": "0xba7bb363782238a06ea70ba7b726292e99d017dd37dd8322a3309b257d5e3a53", "price_changes": [{"asset_id": "70665643461197636242766365969385844686558838063736166515342466618906333119822", "price": "0.169", "size": "0", "side": "BUY", "hash": "a99c535ed5d2866515a5ddbfb4ca1e9208a0df1e", "best_bid": "0.932", "best_ask": "0.989"}, {"asset_id": "86624152659324411612488193633471157021628076444264217402058630710804185298932", "price": "0.831", "size": "0", "side": "SELL", "hash": "fed82489f782b362f22a59b0ec5d3ff9de285e3e", "best_bid": "0.011", "best_ask": "0.068"}], "timestamp": "1769384272535", "event_type": "price_change"}}
{"_local_timestamp": "2026-01-25T23:37:52.609958+00:00", "data": {"market": "0x3be55688f3eecd53db101048ec9c372230efc90f004c1c4e3fce8dd1d2c4dada", "price_changes": [{"asset_id": "85304840619071051396870312932957819961814877219759465827862543288479782634253", "price": "0.3", "size": "0", "side": "BUY", "hash": "5bc905bcf413f3127f86bcd6c95a9fa67668412e", "best_bid": "0.31", "best_ask": "0.98"}, {"asset_id": "25385091870387844891345378992524415372478832284204632642650074498441270262521", "price": "0.7", "size": "0", "side": "SELL", "hash": "2d7fa6572cd4f0c2f8710be60bb0eaf4e96ef7a1", "best_bid": "0.02", "best_ask": "0.69"}], "timestamp": "1769384272535", "event_type": "price_change"}}
{"_local_timestamp": "2026-01-25T23:37:52.631263+00:00", "data": {"market": "0xba7bb363782238a06ea70ba7b726292e99d017dd37dd8322a3309b257d5e3a53", "price_changes": [{"asset_id": "70665643461197636242766365969385844686558838063736166515342466618906333119822", "price": "0.172", "size": "10", "side": "BUY", "hash": "55192e54f581d1a31194472569c61ae75f2ca895", "best_bid": "0.932", "best_ask": "0.989"}, {"asset_id": "86624152659324411612488193633471157021628076444264217402058630710804185298932", "price": "0.828", "size": "10", "side": "SELL", "hash": "82b5c0a42281a31a87c1d0a39efb9558ace4299e", "best_bid": "0.011", "best_ask": "0.068"}], "timestamp": "1769384272564", "event_type": "price_change"}}
{"_local_timestamp": "2026-01-25T23:37:52.631941+00:00", "data": {"market": "0x96449838d7dc6702e356ceb13144a6e53408b728ca363dc96b379320a2552d64", "price_changes": [{"asset_id": "88669991566060336244616088283363604665361049459599965771564136419124853077521", "price": "0.13", "size": "10", "side": "BUY", "hash": "66d2a164e9d5e7feb3ca3f5dfefc8b10974495e4", "best_bid": "0.13", "best_ask": "0.95"}, {"asset_id": "98265373238824778819853870879462811197150130214114951682085083828419115905786", "price": "0.87", "size": "10", "side": "SELL", "hash": "0b4b8e69b397049a536ceff15a106d8132622b62", "best_bid": "0.05", "best_ask": "0.87"}], "timestamp": "1769384272564", "event_type": "price_change"}}
{"_local_timestamp": "2026-01-25T23:37:52.632527+00:00", "data": {"market": "0xedfafd25484c04cfbeaa767022f9eca5bb680918fceece81b36b0611eb3638a6", "price_changes": [{"asset_id": "69100260301420797247941786085257042358554422352183746124379790103566465901104", "price": "0.24", "size": "20", "side": "BUY", "hash": "0d54d16374ee407e4c4ca0bf80e8b074d9c3869c", "best_bid": "0.24", "best_ask": "0.99"}, {"asset_id": "5193041395342261568372064995546886956660044551128159772340877211907014735905", "price": "0.76", "size": "20", "side": "SELL", "hash": "8d15789632735d0b95db9977a412e7ce1ba85ca3", "best_bid": "0.01", "best_ask": "0.76"}], "timestamp": "1769384272564", "event_type": "price_change"}}
{"_local_timestamp": "2026-01-25T23:37:52.633113+00:00", "data": {"market": "0x3be55688f3eecd53db101048ec9c372230efc90f004c1c4e3fce8dd1d2c4dada", "price_changes": [{"asset_id": "85304840619071051396870312932957819961814877219759465827862543288479782634253", "price": "0.32", "size": "10", "side": "BUY", "hash": "b08e942ce3ea8e5073da84e52bc59253735223e5", "best_bid": "0.32", "best_ask": "0.98"}, {"asset_id": "25385091870387844891345378992524415372478832284204632642650074498441270262521", "price": "0.68", "size": "10", "side": "SELL", "hash": "4fe601ef52f0e34eb24b9000c3d98efbdf6c3465", "best_bid": "0.02", "best_ask": "0.68"}], "timestamp": "1769384272564", "event_type": "price_change"}}
{"_local_timestamp": "2026-01-25T23:37:52.633725+00:00", "data": {"market": "0x9ad98d277747a5af33029daa93d8921e20dc48fc43a13444b34abd5db3090419", "price_changes": [{"asset_id": "84279332923568891895771507663060971052533473524984039519051747621941395607490", "price": "0.31", "size": "10", "side": "BUY", "hash": "c8f8128ea4f58155dd23a8e55229aa650eb111ca", "best_bid": "0.31", "best_ask": "0.96"}, {"asset_id": "13106897552498929473034004606662562096233616324310660731332487169842346464915", "price": "0.69", "size": "10", "side": "SELL", "hash": "39392855471b2dfbdf4e026b8167b0a8c008f3d0", "best_bid": "0.04", "best_ask": "0.69"}], "timestamp": "1769384272564", "event_type": "price_change"}}
{"_local_timestamp": "2026-01-25T23:39:19.356419+00:00", "data": {"market": "0x9ad98d277747a5af33029daa93d8921e20dc48fc43a13444b34abd5db3090419", "price_changes": [{"asset_id": "13106897552498929473034004606662562096233616324310660731332487169842346464915", "price": "0.7", "size": "0", "side": "SELL", "hash": "296240f1ed42d451aef1926cd27c2547bd010f81", "best_bid": "0.04", "best_ask": "0.69"}, {"asset_id": "84279332923568891895771507663060971052533473524984039519051747621941395607490", "price": "0.3", "size": "0", "side": "BUY", "hash": "1682a28acd92ca024b9e52918ab61e8b5fbff81e", "best_bid": "0.31", "best_ask": "0.96"}], "timestamp": "1769384359289", "event_type": "price_change"}}
{"_local_timestamp": "2026-01-25T23:39:19.357388+00:00", "data": {"market": "0x96449838d7dc6702e356ceb13144a6e53408b728ca363dc96b379320a2552d64", "price_changes": [{"asset_id": "98265373238824778819853870879462811197150130214114951682085083828419115905786", "price": "0.88", "size": "10", "side": "SELL", "hash": "13775604678b3bdafcc2c99c6e87046addb619b6", "best_bid": "0.05", "best_ask": "0.87"}, {"asset_id": "88669991566060336244616088283363604665361049459599965771564136419124853077521", "price": "0.12", "size": "10", "side": "BUY", "hash": "63f97e41fd9124c549d14f0283bd26fe608e778d", "best_bid": "0.13", "best_ask": "0.95"}], "timestamp": "1769384359289", "event_type": "price_change"}}
{"_local_timestamp": "2026-01-25T23:39:19.358015+00:00", "data": {"market": "0xedfafd25484c04cfbeaa767022f9eca5bb680918fceece81b36b0611eb3638a6", "price_changes": [{"asset_id": "5193041395342261568372064995546886956660044551128159772340877211907014735905", "price": "0.77", "size": "0", "side": "SELL", "hash": "2fad9331a22efb060b8e3f9d894eac8b171bc4c0", "best_bid": "0.01", "best_ask": "0.76"}, {"asset_id": "69100260301420797247941786085257042358554422352183746124379790103566465901104", "price": "0.23", "size": "0", "side": "BUY", "hash": "553f3bfd496c27df69537c76cb655e9cc582dc42", "best_bid": "0.24", "best_ask": "0.99"}], "timestamp": "1769384359289", "event_type": "price_change"}}
{"_local_timestamp": "2026-01-25T23:39:19.358656+00:00", "data": {"market": "0x3be55688f3eecd53db101048ec9c372230efc90f004c1c4e3fce8dd1d2c4dada", "price_changes": [{"asset_id": "25385091870387844891345378992524415372478832284204632642650074498441270262521", "price": "0.69", "size": "0", "side": "SELL", "hash": "81f5682c04461223696fc65256e1e3c2969e0a99", "best_bid": "0.02", "best_ask": "0.68"}, {"asset_id": "85304840619071051396870312932957819961814877219759465827862543288479782634253", "price": "0.31", "size": "0", "side": "BUY", "hash": "e31d8d7af45a711a953e615394e403d1276ea5d9", "best_bid": "0.32", "best_ask": "0.98"}], "timestamp": "1769384359289", "event_type": "price_change"}}
{"_local_timestamp": "2026-01-25T23:39:19.500534+00:00", "data": {"market": "0xedfafd25484c04cfbeaa767022f9eca5bb680918fceece81b36b0611eb3638a6", "price_changes": [{"asset_id": "69100260301420797247941786085257042358554422352183746124379790103566465901104", "price": "0.12", "size": "0", "side": "BUY", "hash": "d176f8e8e4d09a51e779c32862066ce3774e6512", "best_bid": "0.24", "best_ask": "0.99"}, {"asset_id": "5193041395342261568372064995546886956660044551128159772340877211907014735905", "price": "0.88", "size": "0", "side": "SELL", "hash": "3019e55946c880d33bd02b1333484eb8df5dafbe", "best_bid": "0.01", "best_ask": "0.76"}], "timestamp": "1769384359428", "event_type": "price_change"}}
{"_local_timestamp": "2026-01-25T23:39:19.615924+00:00", "data": {"market": "0xedfafd25484c04cfbeaa767022f9eca5bb680918fceece81b36b0611eb3638a6", "price_changes": [{"asset_id": "69100260301420797247941786085257042358554422352183746124379790103566465901104", "price": "0.25", "size": "30", "side": "BUY", "hash": "12c2b397340544cb005af82255d288b6de3ec02a", "best_bid": "0.25", "best_ask": "0.99"}, {"asset_id": "5193041395342261568372064995546886956660044551128159772340877211907014735905", "price": "0.75", "size": "30", "side": "SELL", "hash": "c35798fab394e3643357512f6b3468d49a0191d8", "best_bid": "0.01", "best_ask": "0.75"}], "timestamp": "1769384359552", "event_type": "price_change"}}
{"_local_timestamp": "2026-01-25T23:39:19.861239+00:00", "data": {"market": "0x3be55688f3eecd53db101048ec9c372230efc90f004c1c4e3fce8dd1d2c4dada", "price_changes": [{"asset_id": "85304840619071051396870312932957819961814877219759465827862543288479782634253", "price": "0.26", "size": "15", "side": "BUY", "hash": "4fd3082377d9d7155ad34ca5640ccd81706cce58", "best_bid": "0.32", "best_ask": "0.98"}, {"asset_id": "25385091870387844891345378992524415372478832284204632642650074498441270262521", "price": "0.74", "size": "15", "side": "SELL", "hash": "e90e3768e95ce22329325e577c0ac9b278d83ffa", "best_bid": "0.02", "best_ask": "0.68"}], "timestamp": "1769384359766", "event_type": "price_change"}}
{"_local_timestamp": "2026-01-25T23:39:20.032754+00:00", "data": {"market": "0x3be55688f3eecd53db101048ec9c372230efc90f004c1c4e3fce8dd1d2c4dada", "price_changes": [{"asset_id": "85304840619071051396870312932957819961814877219759465827862543288479782634253", "price": "0.26", "size": "0", "side": "BUY", "hash": "6863df75cf13aa9410b88a494653d5d4a37c72fa", "best_bid": "0.32", "best_ask": "0.98"}, {"asset_id": "25385091870387844891345378992524415372478832284204632642650074498441270262521", "price": "0.74", "size": "0", "side": "SELL", "hash": "034535534af7a385244cb27d664a0aeb2475d7d3", "best_bid": "0.02", "best_ask": "0.68"}], "timestamp": "1769384359937", "event_type": "price_change"}}
{"_local_timestamp": "2026-01-25T23:39:20.144618+00:00", "data": {"market": "0x96449838d7dc6702e356ceb13144a6e53408b728ca363dc96b379320a2552d64", "price_changes": [{"asset_id": "98265373238824778819853870879462811197150130214114951682085083828419115905786", "price": "0.86", "size": "15", "side": "SELL", "hash": "d4b254990b2f735893ac640a99ebe8dcac578340", "best_bid": "0.05", "best_ask": "0.86"}, {"asset_id": "88669991566060336244616088283363604665361049459599965771564136419124853077521", "price": "0.14", "size": "15", "side": "BUY", "hash": "e510c4b70cab122a9521786bedf99767cdfcce80", "best_bid": "0.14", "best_ask": "0.95"}], "timestamp": "1769384360080", "event_type": "price_change"}}
{"_local_timestamp": "2026-01-25T23:39:20.145520+00:00", "data": {"market": "0x9ad98d277747a5af33029daa93d8921e20dc48fc43a13444b34abd5db3090419", "price_changes": [{"asset_id": "13106897552498929473034004606662562096233616324310660731332487169842346464915", "price": "0.68", "size": "15", "side": "SELL", "hash": "be708c8d45f787113e81f9fe4dbea7ba44b22a66", "best_bid": "0.04", "best_ask": "0.68"}, {"asset_id": "84279332923568891895771507663060971052533473524984039519051747621941395607490", "price": "0.32", "size": "15", "side": "BUY", "hash": "b0b263e91d52d4f5440c4917bce2630bbdd824c2", "best_bid": "0.32", "best_ask": "0.96"}], "timestamp": "1769384360080", "event_type": "price_change"}}
{"_local_timestamp": "2026-01-25T23:39:20.155263+00:00", "data": {"market": "0x3be55688f3eecd53db101048ec9c372230efc90f004c1c4e3fce8dd1d2c4dada", "price_changes": [{"asset_id": "25385091870387844891345378992524415372478832284204632642650074498441270262521", "price": "0.67", "size": "15", "side": "SELL", "hash": "b678e686f048ceb42e431c51621c6d02c5df86ba", "best_bid": "0.02", "best_ask": "0.67"}, {"asset_id": "85304840619071051396870312932957819961814877219759465827862543288479782634253", "price": "0.33", "size": "15", "side": "BUY", "hash": "02d87812b984a07bca8c567ab4f8ce9b51ae7af6", "best_bid": "0.33", "best_ask": "0.98"}], "timestamp": "1769384360080", "event_type": "price_change"}}
{"_local_timestamp": "2026-01-25T23:39:20.156013+00:00", "data": {"market": "0xedfafd25484c04cfbeaa767022f9eca5bb680918fceece81b36b0611eb3638a6", "price_changes": [{"asset_id": "5193041395342261568372064995546886956660044551128159772340877211907014735905", "price": "0.75", "size": "45", "side": "SELL", "hash": "90cd726bb0637b92b47a44aeb99c4379a5a934ba", "best_bid": "0.01", "best_ask": "0.75"}, {"asset_id": "69100260301420797247941786085257042358554422352183746124379790103566465901104", "price": "0.25", "size": "45", "side": "BUY", "hash": "353c2b9c2781a81381fbe138b823fcac3beabf92", "best_bid": "0.25", "best_ask": "0.99"}], "timestamp": "1769384360080", "event_type": "price_change"}}
{"_local_timestamp": "2026-01-25T23:39:20.247181+00:00", "data": {"market": "0x3be55688f3eecd53db101048ec9c372230efc90f004c1c4e3fce8dd1d2c4dada", "price_changes": [{"asset_id": "85304840619071051396870312932957819961814877219759465827862543288479782634253", "price": "0.28", "size": "15", "side": "BUY", "hash": "29cad951f11dc1cc810c3cdcf6ffc535a7ea2216", "best_bid": "0.33", "best_ask": "0.98"}, {"asset_id": "25385091870387844891345378992524415372478832284204632642650074498441270262521", "price": "0.72", "size": "15", "side": "SELL", "hash": "3c63c1630ccfcf77a8d0560890e9de438e9315ce", "best_bid": "0.02", "best_ask": "0.67"}], "timestamp": "1769384360142", "event_type": "price_change"}}
{"_local_timestamp": "2026-01-25T23:39:20.247931+00:00", "data": {"market": "0x3be55688f3eecd53db101048ec9c372230efc90f004c1c4e3fce8dd1d2c4dada", "price_changes": [{"asset_id": "85304840619071051396870312932957819961814877219759465827862543288479782634253", "price": "0.28", "size": "25", "side": "BUY", "hash": "59acc91ecb38749ea2c08863571ff9490f7cda28", "best_bid": "0.33", "best_ask": "0.98"}, {"asset_id": "25385091870387844891345378992524415372478832284204632642650074498441270262521", "price": "0.72", "size": "25", "side": "SELL", "hash": "761cbafcc0473fcd3de3e863bb396d35b2beafa5", "best_bid": "0.02", "best_ask": "0.67"}], "timestamp": "1769384360143", "event_type": "price_change"}}
{"_local_timestamp": "2026-01-25T23:39:20.729314+00:00", "data": {"market": "0x3be55688f3eecd53db101048ec9c372230efc90f004c1c4e3fce8dd1d2c4dada", "price_changes": [{"asset_id": "85304840619071051396870312932957819961814877219759465827862543288479782634253", "price": "0.28", "size": "15", "side": "BUY", "hash": "c9ca332633afd9175c9030d6d70a8b6434ea7c14", "best_bid": "0.33", "best_ask": "0.98"}, {"asset_id": "25385091870387844891345378992524415372478832284204632642650074498441270262521", "price": "0.72", "size": "15", "side": "SELL", "hash": "e2400a2b1e9cc3063c9f5aed2f7c9500b1284741", "best_bid": "0.02", "best_ask": "0.67"}], "timestamp": "1769384360620", "event_type": "price_change"}}
{"_local_timestamp": "2026-01-25T23:39:22.163613+00:00", "data": {"market": "0x3be55688f3eecd53db101048ec9c372230efc90f004c1c4e3fce8dd1d2c4dada", "price_changes": [{"asset_id": "85304840619071051396870312932957819961814877219759465827862543288479782634253", "price": "0.32", "size": "0", "side": "BUY", "hash": "01dd3e451d3f0d006f61a4cb9cfc71d1638c84a2", "best_bid": "0.33", "best_ask": "0.98"}, {"asset_id": "25385091870387844891345378992524415372478832284204632642650074498441270262521", "price": "0.68", "size": "0", "side": "SELL", "hash": "7124d037c76c151110972cf769cb79cd1155da1b", "best_bid": "0.02", "best_ask": "0.67"}], "timestamp": "1769384362084", "event_type": "price_change"}}
{"_local_timestamp": "2026-01-25T23:39:22.164475+00:00", "data": {"market": "0x96449838d7dc6702e356ceb13144a6e53408b728ca363dc96b379320a2552d64", "price_changes": [{"asset_id": "88669991566060336244616088283363604665361049459599965771564136419124853077521", "price": "0.13", "size": "0", "side": "BUY", "hash": "5b3c46d5de241297ceff2b6835a716724912f536", "best_bid": "0.14", "best_ask": "0.95"}, {"asset_id": "98265373238824778819853870879462811197150130214114951682085083828419115905786", "price": "0.87", "size": "0", "side": "SELL", "hash": "6525143e1b65f5bb50b8b5c5fb85e9e923898a0f", "best_bid": "0.05", "best_ask": "0.86"}], "timestamp": "1769384362084", "event_type": "price_change"}}
{"_local_timestamp": "2026-01-25T23:39:22.165125+00:00", "data": {"market": "0x9ad98d277747a5af33029daa93d8921e20dc48fc43a13444b34abd5db3090419", "price_changes": [{"asset_id": "84279332923568891895771507663060971052533473524984039519051747621941395607490", "price": "0.31", "size": "0", "side": "BUY", "hash": "c99c0f722457e52083580f70434332ac9b52ac19", "best_bid": "0.32", "best_ask": "0.96"}, {"asset_id": "13106897552498929473034004606662562096233616324310660731332487169842346464915", "price": "0.69", "size": "0", "side": "SELL", "hash": "e0e7805f9ca4a09ff12d9283a10a269accf6e2c2", "best_bid": "0.04", "best_ask": "0.68"}], "timestamp": "1769384362084", "event_type": "price_change"}}
{"_local_timestamp": "2026-01-25T23:39:22.165911+00:00", "data": {"market": "0xedfafd25484c04cfbeaa767022f9eca5bb680918fceece81b36b0611eb3638a6", "price_changes": [{"asset_id": "69100260301420797247941786085257042358554422352183746124379790103566465901104", "price": "0.24", "size": "0", "side": "BUY", "hash": "a55f2bfcab43431e58dbbad63594c327ec1eb26a", "best_bid": "0.25", "best_ask": "0.99"}, {"asset_id": "5193041395342261568372064995546886956660044551128159772340877211907014735905", "price": "0.76", "size": "0", "side": "SELL", "hash": "cffb07ea91b538934af800d77ca7fc4c2164c8de", "best_bid": "0.01", "best_ask": "0.75"}], "timestamp": "1769384362084", "event_type": "price_change"}}
{"_local_timestamp": "2026-01-25T23:39:22.182181+00:00", "data": {"market": "0x9ad98d277747a5af33029daa93d8921e20dc48fc43a13444b34abd5db3090419", "price_changes": [{"asset_id": "84279332923568891895771507663060971052533473524984039519051747621941395607490", "price": "0.27", "size": "10", "side": "BUY", "hash": "5c9c73a346906a4d54e71848f46be8fb42f6b8be", "best_bid": "0.32", "best_ask": "0.96"}, {"asset_id": "13106897552498929473034004606662562096233616324310660731332487169842346464915", "price": "0.73", "size": "10", "side": "SELL", "hash": "e6d45826e2f788cb8bdfa705fb71f2ece0258396", "best_bid": "0.04", "best_ask": "0.68"}], "timestamp": "1769384362114", "event_type": "price_change"}}
{"_local_timestamp": "2026-01-25T23:39:22.183030+00:00", "data": {"market": "0x96449838d7dc6702e356ceb13144a6e53408b728ca363dc96b379320a2552d64", "price_changes": [{"asset_id": "88669991566060336244616088283363604665361049459599965771564136419124853077521", "price": "0.15", "size": "10", "side": "BUY", "hash": "b3abe0027bf1740eb85c79f92d2fda1db03991b1", "best_bid": "0.15", "best_ask": "0.95"}, {"asset_id": "98265373238824778819853870879462811197150130214114951682085083828419115905786", "price": "0.85", "size": "10", "side": "SELL", "hash": "867c4245d960410bea54260104eb773c16d9ac45", "best_bid": "0.05", "best_ask": "0.85"}], "timestamp": "1769384362113", "event_type": "price_change"}}
{"_local_timestamp": "2026-01-25T23:39:22.183852+00:00", "data": {"market": "0x3be55688f3eecd53db101048ec9c372230efc90f004c1c4e3fce8dd1d2c4dada", "price_changes": [{"asset_id": "85304840619071051396870312932957819961814877219759465827862543288479782634253", "price": "0.33", "size": "25", "side": "BUY", "hash": "c8f9d20f34ea7b4e6ba6e3b6a73fefe783886df5", "best_bid": "0.33", "best_ask": "0.98"}, {"asset_id": "25385091870387844891345378992524415372478832284204632642650074498441270262521", "price": "0.67", "size": "25", "side": "SELL", "hash": "0ab360d48fb591625552d33578f8aa83c574183b", "best_bid": "0.02", "best_ask": "0.67"}], "timestamp": "1769384362114", "event_type": "price_change"}}
{"_local_timestamp": "2026-01-25T23:39:22.184528+00:00", "data": {"market": "0xedfafd25484c04cfbeaa767022f9eca5bb680918fceece81b36b0611eb3638a6", "price_changes": [{"asset_id": "69100260301420797247941786085257042358554422352183746124379790103566465901104", "price": "0.26", "size": "20", "side": "BUY", "hash": "1fc322bfe838bb3f5851b386b87cfe08695f95ce", "best_bid": "0.26", "best_ask": "0.99"}, {"asset_id": "5193041395342261568372064995546886956660044551128159772340877211907014735905", "price": "0.74", "size": "20", "side": "SELL", "hash": "903aab6cbb1b0e8baca3f404e8ff1e2dfa084af0", "best_bid": "0.01", "best_ask": "0.74"}], "timestamp": "1769384362114", "event_type": "price_change"}}
{"_local_timestamp": "2026-01-25T23:39:53.356290+00:00", "data": {"market": "0xedfafd25484c04cfbeaa767022f9eca5bb680918fceece81b36b0611eb3638a6", "price_changes": [{"asset_id": "69100260301420797247941786085257042358554422352183746124379790103566465901104", "price": "0.08", "size": "0", "side": "BUY", "hash": "ddb776324dcd308eba83fb6056f199d1cac1f629", "best_bid": "0.26", "best_ask": "0.99"}, {"asset_id": "5193041395342261568372064995546886956660044551128159772340877211907014735905", "price": "0.92", "size": "0", "side": "SELL", "hash": "06bad69b00afffeb3ad7e2cc55bd5a805222e539", "best_bid": "0.01", "best_ask": "0.74"}], "timestamp": "1769384393269", "event_type": "price_change"}}
{"_local_timestamp": "2026-01-25T23:39:53.422330+00:00", "data": {"market": "0xedfafd25484c04cfbeaa767022f9eca5bb680918fceece81b36b0611eb3638a6", "price_changes": [{"asset_id": "69100260301420797247941786085257042358554422352183746124379790103566465901104", "price": "0.01", "size": "210", "side": "BUY", "hash": "88dc07197710c6347c309832afd1a1d7d12dda1f", "best_bid": "0.26", "best_ask": "0.99"}, {"asset_id": "5193041395342261568372064995546886956660044551128159772340877211907014735905", "price": "0.99", "size": "210", "side": "SELL", "hash": "ce24db20d58183e48b6f5aa60c04f3f93c51845f", "best_bid": "0.01", "best_ask": "0.74"}], "timestamp": "1769384393314", "event_type": "price_change"}}
{"_local_timestamp": "2026-01-25T23:39:53.524229+00:00", "data": {"market": "0xe39dbeb302a95a1db7e8ea9d960d938eadf809915d35b010d6b5bdeab9104faa", "price_changes": [{"asset_id": "17232151154444159837483463581179634092787787010273125825914638704500808010603", "price": "0.31", "size": "12", "side": "BUY", "hash": "922c0ffc2c71aafd17ba05739b78044eee33368c", "best_bid": "0.911", "best_ask": "0.99"}, {"asset_id": "92533496956435761714502061273420732955999521880693708251154668927169781104631", "price": "0.69", "size": "12", "side": "SELL", "hash": "3780f58ac6141a58e4d198ccd363a5bb1d67b1a2", "best_bid": "0.01", "best_ask": "0.089"}], "timestamp": "1769384393453", "event_type": "price_change"}}
{"_local_timestamp": "2026-01-25T23:39:53.672306+00:00", "data": {"market": "0xedfafd25484c04cfbeaa767022f9eca5bb680918fceece81b36b0611eb3638a6", "price_changes": [{"asset_id": "69100260301420797247941786085257042358554422352183746124379790103566465901104", "price": "0.14", "size": "0", "side": "BUY", "hash": "644473ed43598d7b17f84054ffc73f23b4ef611f", "best_bid": "0.26", "best_ask": "0.99"}, {"asset_id": "5193041395342261568372064995546886956660044551128159772340877211907014735905", "price": "0.86", "size": "0", "side": "SELL", "hash": "d193a870210318aaf41a3654903c5954ba6b608e", "best_bid": "0.01", "best_ask": "0.74"}], "timestamp": "1769384393600", "event_type": "price_change"}}
{"_local_timestamp": "2026-01-25T23:39:53.695237+00:00", "data": {"market": "0xaa46cd9dfbc750e16e767ab71cdfbaaa9f3bbf68153fcb7e9e21bdad1f9a0e4e", "price_changes": [{"asset_id": "10190047580304467488950735708592587854326252278861442489701414156559786950928", "price": "0.2", "size": "15", "side": "BUY", "hash": "bb2ae6c6d16cde05f85141337f9c4cb9435c2c1d", "best_bid": "0.3", "best_ask": "0.94"}, {"asset_id": "88155858711031400772451028879251834333349215458844495516447987085254946467393", "price": "0.8", "size": "15", "side": "SELL", "hash": "2a29980beb27d8da39b1cd964af338b69b0186f3", "best_bid": "0.06", "best_ask": "0.7"}], "timestamp": "1769384393622", "event_type": "price_change"}}
{"_local_timestamp": "2026-01-25T23:39:53.841081+00:00", "data": {"market": "0xaa46cd9dfbc750e16e767ab71cdfbaaa9f3bbf68153fcb7e9e21bdad1f9a0e4e", "price_changes": [{"asset_id": "10190047580304467488950735708592587854326252278861442489701414156559786950928", "price": "0.1", "size": "0", "side": "BUY", "hash": "d0ddd1dc9ebe490204b695c9a559084ec6af7ea3", "best_bid": "0.3", "best_ask": "0.94"}, {"asset_id": "88155858711031400772451028879251834333349215458844495516447987085254946467393", "price": "0.9", "size": "0", "side": "SELL", "hash": "63c931730c8469aa4525cf149d0d72ad9f238a1b", "best_bid": "0.06", "best_ask": "0.7"}], "timestamp": "1769384393777", "event_type": "price_change"}}
{"_local_timestamp": "2026-01-25T23:39:53.854553+00:00", "data": {"market": "0xedfafd25484c04cfbeaa767022f9eca5bb680918fceece81b36b0611eb3638a6", "price_changes": [{"asset_id": "69100260301420797247941786085257042358554422352183746124379790103566465901104", "price": "0.19", "size": "15", "side": "BUY", "hash": "cc78cfd5cbb5fdbce97c204a2f27a6a2d24b8524", "best_bid": "0.26", "best_ask": "0.99"}, {"asset_id": "5193041395342261568372064995546886956660044551128159772340877211907014735905", "price": "0.81", "size": "15", "side": "SELL", "hash": "1ea734359782db26f5038036e181fe29ae3900dc", "best_bid": "0.01", "best_ask": "0.74"}], "timestamp": "1769384393792", "event_type": "price_change"}}
{"_local_timestamp": "2026-01-25T23:39:53.858829+00:00", "data": {"market": "0xf281d9254d35ae8355aa5a2aa98fd38c96ba9c604a5526c2cf9e3a2934c1eee3", "price_changes": [{"asset_id": "9395139935407818232687755250472957071183406150419861658575355254022011268877", "price": "0.24", "size": "0", "side": "BUY", "hash": "751931b786875772e5b4d1f9587593d818f1d989", "best_bid": "0.31", "best_ask": "0.98"}, {"asset_id": "89393743445790167235031936569401282709944557561334382371692027993458014466911", "price": "0.76", "size": "0", "side": "SELL", "hash": "40b107c1d08cad2a333e75c4b3b44c2e73d28dd6", "best_bid": "0.02", "best_ask": "0.69"}], "timestamp": "1769384393792", "event_type": "price_change"}}
{"_local_timestamp": "2026-01-25T23:39:53.878826+00:00", "data": {"market": "0xedfafd25484c04cfbeaa767022f9eca5bb680918fceece81b36b0611eb3638a6", "price_changes": [{"asset_id": "69100260301420797247941786085257042358554422352183746124379790103566465901104", "price": "0.26", "size": "106", "side": "BUY", "hash": "a50e9cd1b37501fbbf6873bd542120024d844606", "best_bid": "0.26", "best_ask": "0.99"}, {"asset_id": "5193041395342261568372064995546886956660044551128159772340877211907014735905", "price": "0.74", "size": "106", "side": "SELL", "hash": "1ce202102ac4f1fe1a46a6ee12f15c0db5d250bd", "best_bid": "0.01", "best_ask": "0.74"}], "timestamp": "1769384393809", "event_type": "price_change"}}
{"_local_timestamp": "2026-01-25T23:39:53.879689+00:00", "data": {"market": "0xedfafd25484c04cfbeaa767022f9eca5bb680918fceece81b36b0611eb3638a6", "price_changes": [{"asset_id": "69100260301420797247941786085257042358554422352183746124379790103566465901104", "price": "0.27", "size": "10", "side": "BUY", "hash": "d6a09ef9b266baa53542a145829ff7a64829e250", "best_bid": "0.27", "best_ask": "0.99"}, {"asset_id": "5193041395342261568372064995546886956660044551128159772340877211907014735905", "price": "0.73", "size": "10", "side": "SELL", "hash": "3fcb7203eaf8523e1445b1b8ca381ffe2cdcd534", "best_bid": "0.01", "best_ask": "0.73"}], "timestamp": "1769384393810", "event_type": "price_change"}}
{"_local_timestamp": "2026-01-25T23:39:54.029372+00:00", "data": {"market": "0x33e09845665c7bcd0b3026cdf8c48f4e4d1ae705e0acd863e03525888a3c01c5", "price_changes": [{"asset_id": "37989116880087250809590393125454376367717533321300643105365874853772585707501", "price": "0.18", "size": "0", "side": "BUY", "hash": "da1d0571779c9c3852dd21c331d8312ee2cb5320", "best_bid": "0.34", "best_ask": "0.98"}, {"asset_id": "41365543321762183390531316023268343985794742000187213322174746298305281833286", "price": "0.82", "size": "0", "side": "SELL", "hash": "4773afcac502aea64baad0db35910d8920e69356", "best_bid": "0.02", "best_ask": "0.66"}], "timestamp": "1769384393962", "event_type": "price_change"}}
{"_local_timestamp": "2026-01-25T23:39:54.030203+00:00", "data": {"market": "0xaa46cd9dfbc750e16e767ab71cdfbaaa9f3bbf68153fcb7e9e21bdad1f9a0e4e", "price_changes": [{"asset_id": "10190047580304467488950735708592587854326252278861442489701414156559786950928", "price": "0.2", "size": "0", "side": "BUY", "hash": "8da6aff36f7eb62266c05235655edfb1466d849a", "best_bid": "0.3", "best_ask": "0.94"}, {"asset_id": "88155858711031400772451028879251834333349215458844495516447987085254946467393", "price": "0.8", "size": "0", "side": "SELL", "hash": "ced260be2c03db9fc291543d88a8893d226b292e", "best_bid": "0.06", "best_ask": "0.7"}], "timestamp": "1769384393962", "event_type": "price_change"}}
{"_local_timestamp": "2026-01-25T23:39:54.178916+00:00", "data": {"market": "0xaa46cd9dfbc750e16e767ab71cdfbaaa9f3bbf68153fcb7e9e21bdad1f9a0e4e", "price_changes": [{"asset_id": "10190047580304467488950735708592587854326252278861442489701414156559786950928", "price": "0.24", "size": "10", "side": "BUY", "hash": "df649277ca6d707df1120a8b208493b501975628", "best_bid": "0.3", "best_ask": "0.94"}, {"asset_id": "88155858711031400772451028879251834333349215458844495516447987085254946467393", "price": "0.76", "size": "10", "side": "SELL", "hash": "2f819421a9e4cab1945e6e762a63fa8419d40bac", "best_bid": "0.06", "best_ask": "0.7"}], "timestamp": "1769384394061", "event_type": "price_change"}}
{"_local_timestamp": "2026-01-25T23:39:54.179793+00:00", "data": {"market": "0xaa46cd9dfbc750e16e767ab71cdfbaaa9f3bbf68153fcb7e9e21bdad1f9a0e4e", "price_changes": [{"asset_id": "10190047580304467488950735708592587854326252278861442489701414156559786950928", "price": "0.23", "size": "25", "side": "BUY", "hash": "d41e6e13d0f481ec92c2ed6c13f5b509c58dfab4", "best_bid": "0.3", "best_ask": "0.94"}, {"asset_id": "88155858711031400772451028879251834333349215458844495516447987085254946467393", "price": "0.77", "size": "25", "side": "SELL", "hash": "9b59cf60406552be1ac498fef968e89c81353256", "best_bid": "0.06", "best_ask": "0.7"}], "timestamp": "1769384394062", "event_type": "price_change"}}
{"_local_timestamp": "2026-01-25T23:39:54.364193+00:00", "data": {"market": "0xedfafd25484c04cfbeaa767022f9eca5bb680918fceece81b36b0611eb3638a6", "price_changes": [{"asset_id": "69100260301420797247941786085257042358554422352183746124379790103566465901104", "price": "0.26", "size": "20", "side": "BUY", "hash": "b1a97e72ed98210a3f4ab41ad9cf85fa7397095a", "best_bid": "0.27", "best_ask": "0.99"}, {"asset_id": "5193041395342261568372064995546886956660044551128159772340877211907014735905", "price": "0.74", "size": "20", "side": "SELL", "hash": "59408f93c40b8c9a92c3472f8bb6647a07f26e02", "best_bid": "0.01", "best_ask": "0.73"}], "timestamp": "1769384394282", "event_type": "price_change"}}
{"_local_timestamp": "2026-01-25T23:39:55.625071+00:00", "data": {"market": "0xaa46cd9dfbc750e16e767ab71cdfbaaa9f3bbf68153fcb7e9e21bdad1f9a0e4e", "price_changes": [{"asset_id": "10190047580304467488950735708592587854326252278861442489701414156559786950928", "price": "0.23", "size": "15", "side": "BUY", "hash": "aded96d292d30bb04da840b4ef153ef955f61816", "best_bid": "0.3", "best_ask": "0.94"}, {"asset_id": "88155858711031400772451028879251834333349215458844495516447987085254946467393", "price": "0.77", "size": "15", "side": "SELL", "hash": "f2dd09b5472a17d46db892375209c0a0ee1cc922", "best_bid": "0.06", "best_ask": "0.7"}], "timestamp": "1769384395558", "event_type": "price_change"}}
{"_local_timestamp": "2026-01-25T23:39:55.641911+00:00", "data": {"market": "0xedfafd25484c04cfbeaa767022f9eca5bb680918fceece81b36b0611eb3638a6", "price_changes": [{"asset_id": "69100260301420797247941786085257042358554422352183746124379790103566465901104", "price": "0.26", "size": "0", "side": "BUY", "hash": "b5d461466255fb037788f7469f044f3721cc0031", "best_bid": "0.27", "best_ask": "0.99"}, {"asset_id": "5193041395342261568372064995546886956660044551128159772340877211907014735905", "price": "0.74", "size": "0", "side": "SELL", "hash": "70cf3c065eb955796a3d916409dbdc53efc3c651", "best_bid": "0.01", "best_ask": "0.73"}], "timestamp": "1769384395558", "event_type": "price_change"}}
{"_local_timestamp": "2026-01-25T23:39:55.666205+00:00", "data": {"market": "0xedfafd25484c04cfbeaa767022f9eca5bb680918fceece81b36b0611eb3638a6", "price_changes": [{"asset_id": "69100260301420797247941786085257042358554422352183746124379790103566465901104", "price": "0.28", "size": "20", "side": "BUY", "hash": "0810c282a28bf947fefb3121c23ef5db6a219f0b", "best_bid": "0.28", "best_ask": "0.99"}, {"asset_id": "5193041395342261568372064995546886956660044551128159772340877211907014735905", "price": "0.72", "size": "20", "side": "SELL", "hash": "4d44d1623478b998328c55793274a2a5493b8550", "best_bid": "0.01", "best_ask": "0.72"}], "timestamp": "1769384395587", "event_type": "price_change"}}
{"_local_timestamp": "2026-01-25T23:39:55.667003+00:00", "data": {"market": "0xaa46cd9dfbc750e16e767ab71cdfbaaa9f3bbf68153fcb7e9e21bdad1f9a0e4e", "price_changes": [{"asset_id": "10190047580304467488950735708592587854326252278861442489701414156559786950928", "price": "0.25", "size": "10", "side": "BUY", "hash": "e3fb64b30fe722a03abf6c6b46d40f02924d56a1", "best_bid": "0.3", "best_ask": "0.94"}, {"asset_id": "88155858711031400772451028879251834333349215458844495516447987085254946467393", "price": "0.75", "size": "10", "side": "SELL", "hash": "a78580c1f2d55df9eff4fa40d348ad3efe6a5119", "best_bid": "0.06", "best_ask": "0.7"}], "timestamp": "1769384395587", "event_type": "price_change"}}
{"_local_timestamp": "2026-01-25T23:40:11.644482+00:00", "data": {"market": "0xf281d9254d35ae8355aa5a2aa98fd38c96ba9c604a5526c2cf9e3a2934c1eee3", "price_changes": [{"asset_id": "9395139935407818232687755250472957071183406150419861658575355254022011268877", "price": "0.31", "size": "49", "side": "BUY", "hash": "ab9686d600ad135c2b4aee67014fab5b30785d6f", "best_bid": "0.31", "best_ask": "0.98"}, {"asset_id": "89393743445790167235031936569401282709944557561334382371692027993458014466911", "price": "0.69", "size": "49", "side": "SELL", "hash": "f222d52f2cde0fed8cb311a9f28d2ea86f018796", "best_bid": "0.02", "best_ask": "0.69"}], "timestamp": "1769384411578", "event_type": "price_change"}}
{"_local_timestamp": "2026-01-25T23:40:11.645304+00:00", "data": {"market": "0x96449838d7dc6702e356ceb13144a6e53408b728ca363dc96b379320a2552d64", "price_changes": [{"asset_id": "88669991566060336244616088283363604665361049459599965771564136419124853077521", "price": "0.16", "size": "79.16", "side": "BUY", "hash": "b374349904abadcd132f8b67ec30db2a32a242cc", "best_bid": "0.16", "best_ask": "0.95"}, {"asset_id": "98265373238824778819853870879462811197150130214114951682085083828419115905786", "price": "0.84", "size": "79.16", "side": "SELL", "hash": "a416db2b09d1a2c4a96e656311607cc3c97754f8", "best_bid": "0.05", "best_ask": "0.84"}], "timestamp": "1769384411578", "event_type": "price_change"}}
{"_local_timestamp": "2026-01-25T23:40:11.646062+00:00", "data": {"market": "0x3be55688f3eecd53db101048ec9c372230efc90f004c1c4e3fce8dd1d2c4dada", "price_changes": [{"asset_id": "85304840619071051396870312932957819961814877219759465827862543288479782634253", "price": "0.34", "size": "19", "side": "BUY", "hash": "d104f277e8a079133525ea2e907dfdc060ad1df0", "best_bid": "0.34", "best_ask": "0.98"}, {"asset_id": "25385091870387844891345378992524415372478832284204632642650074498441270262521", "price": "0.66", "size": "19", "side": "SELL", "hash": "c670d2d3f5aab96250d5c207ecc41aebea3d1c7c", "best_bid": "0.02", "best_ask": "0.66"}], "timestamp": "1769384411578", "event_type": "price_change"}}
{"_local_timestamp": "2026-01-25T23:40:11.646791+00:00", "data": {"market": "0xedfafd25484c04cfbeaa767022f9eca5bb680918fceece81b36b0611eb3638a6", "price_changes": [{"asset_id": "69100260301420797247941786085257042358554422352183746124379790103566465901104", "price": "0.29", "size": "79.16", "side": "BUY", "hash": "0ccb30cf96b4b2598aa6e218935f22cfc12d8676", "best_bid": "0.29", "best_ask": "0.99"}, {"asset_id": "5193041395342261568372064995546886956660044551128159772340877211907014735905", "price": "0.71", "size": "79.16", "side": "SELL", "hash": "0b679c371af9973f9601e2abb39bb3c29905fc5e", "best_bid": "0.01", "best_ask": "0.71"}], "timestamp": "1769384411578", "event_type": "price_change"}}
{"_local_timestamp": "2026-01-25T23:40:11.647497+00:00", "data": {"market": "0x9897c870e99bb551bcad54acb866b11ea20f18f6a59307b583d41b87dbd8df9b", "price_changes": [{"asset_id": "83125160625335845669305131102145331159652617545862153009199309232015574885824", "price": "0.26", "size": "49", "side": "BUY", "hash": "e9f6b30b7a5130da3fa6d5983ef2923e4cf0940a", "best_bid": "0.3", "best_ask": "0.94"}, {"asset_id": "107986170040662440391901604090971190646645008770767885800861483401158985093632", "price": "0.74", "size": "49", "side": "SELL", "hash": "c0ecc7a16b7675da1a54dc1612b6db517e50cb5e", "best_bid": "0.06", "best_ask": "0.7"}], "timestamp": "1769384411578", "event_type": "price_change"}}
{"_local_timestamp": "2026-01-25T23:40:11.648219+00:00", "data": {"market": "0xaa46cd9dfbc750e16e767ab71cdfbaaa9f3bbf68153fcb7e9e21bdad1f9a0e4e", "price_changes": [{"asset_id": "10190047580304467488950735708592587854326252278861442489701414156559786950928", "price": "0.31", "size": "19", "side": "BUY", "hash": "dc8cf110598f5b83e929e342d190d391f012cbeb", "best_bid": "0.31", "best_ask": "0.94"}, {"asset_id": "88155858711031400772451028879251834333349215458844495516447987085254946467393", "price": "0.69", "size": "19", "side": "SELL", "hash": "d6401dfbceac0ac8107e3666418afdcc5f75e368", "best_bid": "0.06", "best_ask": "0.69"}], "timestamp": "1769384411578", "event_type": "price_change"}}
{"_local_timestamp": "2026-01-25T23:40:11.648894+00:00", "data": {"market": "0x9ad98d277747a5af33029daa93d8921e20dc48fc43a13444b34abd5db3090419", "price_changes": [{"asset_id": "84279332923568891895771507663060971052533473524984039519051747621941395607490", "price": "0.33", "size": "19", "side": "BUY", "hash": "c0007e27d6f42c8aa686dca062227c3b84822174", "best_bid": "0.33", "best_ask": "0.96"}, {"asset_id": "13106897552498929473034004606662562096233616324310660731332487169842346464915", "price": "0.67", "size": "19", "side": "SELL", "hash": "6259065636db5e13a31267ceeb5af70bd1d6b956", "best_bid": "0.04", "best_ask": "0.67"}], "timestamp": "1769384411578", "event_type": "price_change"}}
{"_local_timestamp": "2026-01-25T23:40:11.652481+00:00", "data": {"market": "0x9ad98d277747a5af33029daa93d8921e20dc48fc43a13444b34abd5db3090419", "price_changes": [{"asset_id": "84279332923568891895771507663060971052533473524984039519051747621941395607490", "price": "0.28", "size": "79.16", "side": "BUY", "hash": "f0259e794de51f7b0754182d44cc4020167b9dd6", "best_bid": "0.33", "best_ask": "0.96"}, {"asset_id": "13106897552498929473034004606662562096233616324310660731332487169842346464915", "price": "0.72", "size": "79.16", "side": "SELL", "hash": "f387652eda50f415bfae5833d33bad8276f72d25", "best_bid": "0.04", "best_ask": "0.67"}], "timestamp": "1769384411578", "event_type": "price_change"}}
{"_local_timestamp": "2026-01-25T23:40:11.653315+00:00", "data": {"market": "0x96449838d7dc6702e356ceb13144a6e53408b728ca363dc96b379320a2552d64", "price_changes": [{"asset_id": "88669991566060336244616088283363604665361049459599965771564136419124853077521", "price": "0.15", "size": "89.16", "side": "BUY", "hash": "6a930d63fefdee6db1673071cfb9983d6dfef4b8", "best_bid": "0.16", "best_ask": "0.95"}, {"asset_id": "98265373238824778819853870879462811197150130214114951682085083828419115905786", "price": "0.85", "size": "89.16", "side": "SELL", "hash": "04317edaa5955d84932c627d5f65019164cded58", "best_bid": "0.05", "best_ask": "0.84"}], "timestamp": "1769384411578", "event_type": "price_change"}}
{"_local_timestamp": "2026-01-25T23:40:11.654030+00:00", "data": {"market": "0xf281d9254d35ae8355aa5a2aa98fd38c96ba9c604a5526c2cf9e3a2934c1eee3", "price_changes": [{"asset_id": "9395139935407818232687755250472957071183406150419861658575355254022011268877", "price": "0.32", "size": "39", "side": "BUY", "hash": "9588d5ad4dca1852eaa6ddd9645dfc24de8d53e0", "best_bid": "0.32", "best_ask": "0.98"}, {"asset_id": "89393743445790167235031936569401282709944557561334382371692027993458014466911", "price": "0.68", "size": "39", "side": "SELL", "hash": "ee84e0b244a76382fe9b2fc87e71177cc4354b65", "best_bid": "0.02", "best_ask": "0.68"}], "timestamp": "1769384411578", "event_type": "price_change"}}
{"_local_timestamp": "2026-01-25T23:40:11.654799+00:00", "data": {"market": "0xedfafd25484c04cfbeaa767022f9eca5bb680918fceece81b36b0611eb3638a6", "price_changes": [{"asset_id": "69100260301420797247941786085257042358554422352183746124379790103566465901104", "price": "0.28", "size": "99.16", "side": "BUY", "hash": "8431067022fecaee4a180797f16b3a454205a947", "best_bid": "0.29", "best_ask": "0.99"}, {"asset_id": "5193041395342261568372064995546886956660044551128159772340877211907014735905", "price": "0.72", "size": "99.16", "side": "SELL", "hash": "d25169109e0bcea7dafb6ba5169e690fb6e26240", "best_bid": "0.01", "best_ask": "0.71"}], "timestamp": "1769384411579", "event_type": "price_change"}}
{"_local_timestamp": "2026-01-25T23:40:11.775318+00:00", "data": {"market": "0x3be55688f3eecd53db101048ec9c372230efc90f004c1c4e3fce8dd1d2c4dada", "price_changes": [{"asset_id": "85304840619071051396870312932957819961814877219759465827862543288479782634253", "price": "0.29", "size": "39", "side": "BUY", "hash": "a5c622bb54f6fd6b6f3e30b40eb629e18012d34a", "best_bid": "0.34", "best_ask": "0.98"}, {"asset_id": "25385091870387844891345378992524415372478832284204632642650074498441270262521", "price": "0.71", "size": "39", "side": "SELL", "hash": "c39e238ea4bcdafd9beeee7e38ceba0f01d7fee2", "best_bid": "0.02", "best_ask": "0.66"}], "timestamp": "1769384411578", "event_type": "price_change"}}
{"_local_timestamp": "2026-01-25T23:40:11.776137+00:00", "data": {"market": "0xaa46cd9dfbc750e16e767ab71cdfbaaa9f3bbf68153fcb7e9e21bdad1f9a0e4e", "price_changes": [{"asset_id": "10190047580304467488950735708592587854326252278861442489701414156559786950928", "price": "0.26", "size": "79.16", "side": "BUY", "hash": "7b1ea6cae7f1ae9f92dc7649cef56bcfea70bf7b", "best_bid": "0.31", "best_ask": "0.94"}, {"asset_id": "88155858711031400772451028879251834333349215458844495516447987085254946467393", "price": "0.74", "size": "79.16", "side": "SELL", "hash": "67656509d8c22bf6b14f95e4a8edf8f10e61d2ab", "best_bid": "0.06", "best_ask": "0.69"}], "timestamp": "1769384411579", "event_type": "price_change"}}
{"_local_timestamp": "2026-01-25T23:40:11.784442+00:00", "data": {"market": "0x33e09845665c7bcd0b3026cdf8c48f4e4d1ae705e0acd863e03525888a3c01c5", "price_changes": [{"asset_id": "37989116880087250809590393125454376367717533321300643105365874853772585707501", "price": "0.31", "size": "0", "side": "BUY", "hash": "fdfc88a1a64e6c51726d0d796aadbb86b422a5af", "best_bid": "0.34", "best_ask": "0.98"}, {"asset_id": "41365543321762183390531316023268343985794742000187213322174746298305281833286", "price": "0.69", "size": "0", "side": "SELL", "hash": "c217353585235df94ce08057edcab34f06b1056d", "best_bid": "0.02", "best_ask": "0.66"}], "timestamp": "1769384411669", "event_type": "price_change"}}
{"_local_timestamp": "2026-01-25T23:40:11.785215+00:00", "data": {"market": "0xaa46cd9dfbc750e16e767ab71cdfbaaa9f3bbf68153fcb7e9e21bdad1f9a0e4e", "price_changes": [{"asset_id": "10190047580304467488950735708592587854326252278861442489701414156559786950928", "price": "0.22", "size": "0", "side": "BUY", "hash": "34eb7be7b3a8efe732ce873552a506bffeedcf6d", "best_bid": "0.31", "best_ask": "0.94"}, {"asset_id": "88155858711031400772451028879251834333349215458844495516447987085254946467393", "price": "0.78", "size": "0", "side": "SELL", "hash": "58929312db98afab98c664dde187f3310e16a16d", "best_bid": "0.06", "best_ask": "0.69"}], "timestamp": "1769384411681", "event_type": "price_change"}}
{"_local_timestamp": "2026-01-25T23:40:11.785968+00:00", "data": {"market": "0x9ad98d277747a5af33029daa93d8921e20dc48fc43a13444b34abd5db3090419", "price_changes": [{"asset_id": "84279332923568891895771507663060971052533473524984039519051747621941395607490", "price": "0.26", "size": "0", "side": "BUY", "hash": "ff718bf12689e6f02259e5691ca2f9f267f4fec2", "best_bid": "0.33", "best_ask": "0.96"}, {"asset_id": "13106897552498929473034004606662562096233616324310660731332487169842346464915", "price": "0.74", "size": "0", "side": "SELL", "hash": "c305a9c90344f73df3442486b3f6bc59aed65c8e", "best_bid": "0.04", "best_ask": "0.67"}], "timestamp": "1769384411681", "event_type": "price_change"}}
{"_local_timestamp": "2026-01-25T23:40:11.871838+00:00", "data": {"market": "0xaa46cd9dfbc750e16e767ab71cdfbaaa9f3bbf68153fcb7e9e21bdad1f9a0e4e", "price_changes": [{"asset_id": "10190047580304467488950735708592587854326252278861442489701414156559786950928", "price": "0.19", "size": "10", "side": "BUY", "hash": "61c5be29d9f85ba2eb1c8e8d5575d99f8b0ae802", "best_bid": "0.31", "best_ask": "0.94"}, {"asset_id": "88155858711031400772451028879251834333349215458844495516447987085254946467393", "price": "0.81", "size": "10", "side": "SELL", "hash": "82804eabd0b402697a1d4d3e6300af86e19de482", "best_bid": "0.06", "best_ask": "0.69"}], "timestamp": "1769384411803", "event_type": "price_change"}}
{"_local_timestamp": "2026-01-25T23:40:11.872678+00:00", "data": {"market": "0x9ad98d277747a5af33029daa93d8921e20dc48fc43a13444b34abd5db3090419", "price_changes": [{"asset_id": "84279332923568891895771507663060971052533473524984039519051747621941395607490", "price": "0.22", "size": "10", "side": "BUY", "hash": "8073b45518429ce384e9ea46b9ecca8c882b925a", "best_bid": "0.33", "best_ask": "0.96"}, {"asset_id": "13106897552498929473034004606662562096233616324310660731332487169842346464915", "price": "0.78", "size": "10", "side": "SELL", "hash": "d19195cd2e328766a7f1f0d896cf15d319ae27a5", "best_bid": "0.04", "best_ask": "0.67"}], "timestamp": "1769384411803", "event_type": "price_change"}}
{"_local_timestamp": "2026-01-25T23:40:11.898249+00:00", "data": {"market": "0xf281d9254d35ae8355aa5a2aa98fd38c96ba9c604a5526c2cf9e3a2934c1eee3", "price_changes": [{"asset_id": "9395139935407818232687755250472957071183406150419861658575355254022011268877", "price": "0.3", "size": "0", "side": "BUY", "hash": "65f807f0159c36ee090349ef8df577144ee8f3ff", "best_bid": "0.32", "best_ask": "0.98"}, {"asset_id": "89393743445790167235031936569401282709944557561334382371692027993458014466911", "price": "0.7", "size": "0", "side": "SELL", "hash": "5a603eba3acc6ad8e7d1a08d21a89bd0affe2479", "best_bid": "0.02", "best_ask": "0.68"}], "timestamp": "1769384411834", "event_type": "price_change"}}
{"_local_timestamp": "2026-01-25T23:40:12.043175+00:00", "data": {"market": "0xf281d9254d35ae8355aa5a2aa98fd38c96ba9c604a5526c2cf9e3a2934c1eee3", "price_changes": [{"asset_id": "9395139935407818232687755250472957071183406150419861658575355254022011268877", "price": "0.24", "size": "15", "side": "BUY", "hash": "c3487d44fabc9f9e30dc3e64adbe2719018d0ebe", "best_bid": "0.32", "best_ask": "0.98"}, {"asset_id": "89393743445790167235031936569401282709944557561334382371692027993458014466911", "price": "0.76", "size": "15", "side": "SELL", "hash": "5131ba5d8bca06502309c64406d993c9d8f548e1", "best_bid": "0.02", "best_ask": "0.68"}], "timestamp": "1769384411938", "event_type": "price_change"}}
{"_local_timestamp": "2026-01-25T23:40:12.044032+00:00", "data": {"market": "0xf281d9254d35ae8355aa5a2aa98fd38c96ba9c604a5526c2cf9e3a2934c1eee3", "price_changes": [{"asset_id": "9395139935407818232687755250472957071183406150419861658575355254022011268877", "price": "0.32", "size": "49", "side": "BUY", "hash": "527c32775dfbd9f6fa52f06cfe5a2122737593d2", "best_bid": "0.32", "best_ask": "0.98"}, {"asset_id": "89393743445790167235031936569401282709944557561334382371692027993458014466911", "price": "0.68", "size": "49", "side": "SELL", "hash": "6590b860be613c280dc08772f42f9cdfaa13f3e8", "best_bid": "0.02", "best_ask": "0.68"}], "timestamp": "1769384411938", "event_type": "price_change"}}
{"_local_timestamp": "2026-01-25T23:40:12.884688+00:00", "data": {"market": "0x96449838d7dc6702e356ceb13144a6e53408b728ca363dc96b379320a2552d64", "price_changes": [{"asset_id": "88669991566060336244616088283363604665361049459599965771564136419124853077521", "price": "0.15", "size": "79.16", "side": "BUY", "hash": "a2001660b33fda10918292bfad304913a91c0754", "best_bid": "0.16", "best_ask": "0.95"}, {"asset_id": "98265373238824778819853870879462811197150130214114951682085083828419115905786", "price": "0.85", "size": "79.16", "side": "SELL", "hash": "8588abdee66b01e6963abb32b3b4c8dea5657390", "best_bid": "0.05", "best_ask": "0.84"}], "timestamp": "1769384412817", "event_type": "price_change"}}
{"_local_timestamp": "2026-01-25T23:40:12.885517+00:00", "data": {"market": "0xf281d9254d35ae8355aa5a2aa98fd38c96ba9c604a5526c2cf9e3a2934c1eee3", "price_changes": [{"asset_id": "9395139935407818232687755250472957071183406150419861658575355254022011268877", "price": "0.31", "size": "39", "side": "BUY", "hash": "d63497cdd9783433c1c6715afd067c56938fd2f4", "best_bid": "0.32", "best_ask": "0.98"}, {"asset_id": "89393743445790167235031936569401282709944557561334382371692027993458014466911", "price": "0.69", "size": "39", "side": "SELL", "hash": "58e4e6101fb9db992231625e458cda2a0ffbafbd", "best_bid": "0.02", "best_ask": "0.68"}], "timestamp": "1769384412817", "event_type": "price_change"}}
{"_local_timestamp": "2026-01-25T23:40:12.886277+00:00", "data": {"market": "0x9897c870e99bb551bcad54acb866b11ea20f18f6a59307b583d41b87dbd8df9b", "price_changes": [{"asset_id": "83125160625335845669305131102145331159652617545862153009199309232015574885824", "price": "0.26", "size": "39", "side": "BUY", "hash": "98f1ef84c9fca07c49014d3ac8dd2d941519146a", "best_bid": "0.3", "best_ask": "0.94"}, {"asset_id": "107986170040662440391901604090971190646645008770767885800861483401158985093632", "price": "0.74", "size": "39", "side": "SELL", "hash": "16de7f5a4d0a4e8aa032e14f062eaa8031f48f0f", "best_bid": "0.06", "best_ask": "0.7"}], "timestamp": "1769384412817", "event_type": "price_change"}}
{"_local_timestamp": "2026-01-25T23:40:12.887022+00:00", "data": {"market": "0xaa46cd9dfbc750e16e767ab71cdfbaaa9f3bbf68153fcb7e9e21bdad1f9a0e4e", "price_changes": [{"asset_id": "10190047580304467488950735708592587854326252278861442489701414156559786950928", "price": "0.25", "size": "0", "side": "BUY", "hash": "fd0dec393feb94bd2edb0c20dc3666071d6c61a8", "best_bid": "0.31", "best_ask": "0.94"}, {"asset_id": "88155858711031400772451028879251834333349215458844495516447987085254946467393", "price": "0.75", "size": "0", "side": "SELL", "hash": "16721e0367b88f9ed9170f5ce06a658ad3e21960", "best_bid": "0.06", "best_ask": "0.69"}], "timestamp": "1769384412817", "event_type": "price_change"}}
{"_local_timestamp": "2026-01-25T23:40:12.887829+00:00", "data": {"market": "0x33e09845665c7bcd0b3026cdf8c48f4e4d1ae705e0acd863e03525888a3c01c5", "price_changes": [{"asset_id": "37989116880087250809590393125454376367717533321300643105365874853772585707501", "price": "0.32", "size": "0", "side": "BUY", "hash": "47e4a01386aa8bff77fdda9f0272c94eed88b95b", "best_bid": "0.34", "best_ask": "0.98"}, {"asset_id": "41365543321762183390531316023268343985794742000187213322174746298305281833286", "price": "0.68", "size": "0", "side": "SELL", "hash": "09a428b22fe945fed460f745067d4e4d9f2201b5", "best_bid": "0.02", "best_ask": "0.66"}], "timestamp": "1769384412817", "event_type": "price_change"}}
{"_local_timestamp": "2026-01-25T23:40:12.888563+00:00", "data": {"market": "0xedfafd25484c04cfbeaa767022f9eca5bb680918fceece81b36b0611eb3638a6", "price_changes": [{"asset_id": "69100260301420797247941786085257042358554422352183746124379790103566465901104", "price": "0.28", "size": "79.16", "side": "BUY", "hash": "994096731ce3ab23dcae7228946b64a4db3a1ebf", "best_bid": "0.29", "best_ask": "0.99"}, {"asset_id": "5193041395342261568372064995546886956660044551128159772340877211907014735905", "price": "0.72", "size": "79.16", "side": "SELL", "hash": "0c096ef16c27d6ecca69a7ed623a036d449818d9", "best_bid": "0.01", "best_ask": "0.71"}], "timestamp": "1769384412817", "event_type": "price_change"}}
{"_local_timestamp": "2026-01-25T23:40:12.889297+00:00", "data": {"market": "0x9ad98d277747a5af33029daa93d8921e20dc48fc43a13444b34abd5db3090419", "price_changes": [{"asset_id": "84279332923568891895771507663060971052533473524984039519051747621941395607490", "price": "0.27", "size": "0", "side": "BUY", "hash": "bb97b802dcab0ea59ce7ce9a455ff91f7e8095e2", "best_bid": "0.33", "best_ask": "0.96"}, {"asset_id": "13106897552498929473034004606662562096233616324310660731332487169842346464915", "price": "0.73", "size": "0", "side": "SELL", "hash": "dcc20b2dc4f552bf37cd7c3c27b3a49a490bcc4f", "best_bid": "0.04", "best_ask": "0.67"}], "timestamp": "1769384412817", "event_type": "price_change"}}
{"_local_timestamp": "2026-01-25T23:40:12.914538+00:00", "data": {"market": "0x9897c870e99bb551bcad54acb866b11ea20f18f6a59307b583d41b87dbd8df9b", "price_changes": [{"asset_id": "83125160625335845669305131102145331159652617545862153009199309232015574885824", "price": "0.27", "size": "10", "side": "BUY", "hash": "dc6f5861d71c9c6432aba2282eeece503a7b402b", "best_bid": "0.3", "best_ask": "0.94"}, {"asset_id": "107986170040662440391901604090971190646645008770767885800861483401158985093632", "price": "0.73", "size": "10", "side": "SELL", "hash": "1baa02abe224c761a1300f8b3fc6d6141e7d32bd", "best_bid": "0.06", "best_ask": "0.7"}], "timestamp": "1769384412850", "event_type": "price_change"}}
{"_local_timestamp": "2026-01-25T23:40:12.915446+00:00", "data": {"market": "0xf281d9254d35ae8355aa5a2aa98fd38c96ba9c604a5526c2cf9e3a2934c1eee3", "price_changes": [{"asset_id": "9395139935407818232687755250472957071183406150419861658575355254022011268877", "price": "0.33", "size": "10", "side": "BUY", "hash": "2ab4190b37b989c51166a5c4ccdc8229b9534bd8", "best_bid": "0.33", "best_ask": "0.98"}, {"asset_id": "89393743445790167235031936569401282709944557561334382371692027993458014466911", "price": "0.67", "size": "10", "side": "SELL", "hash": "91370d7f6b6c153dbea93e8835b6193e01115d5b", "best_bid": "0.02", "best_ask": "0.67"}], "timestamp": "1769384412850", "event_type": "price_change"}}
{"_local_timestamp": "2026-01-25T23:40:12.916326+00:00", "data": {"market": "0x33e09845665c7bcd0b3026cdf8c48f4e4d1ae705e0acd863e03525888a3c01c5", "price_changes": [{"asset_id": "37989116880087250809590393125454376367717533321300643105365874853772585707501", "price": "0.31", "size": "10", "side": "BUY", "hash": "fdc0cfbff2f9debaf7e8982c857d33c0ac6c6bc4", "best_bid": "0.34", "best_ask": "0.98"}, {"asset_id": "41365543321762183390531316023268343985794742000187213322174746298305281833286", "price": "0.69", "size": "10", "side": "SELL", "hash": "590440cee2414a28932acf9df5cf03cf9779da01", "best_bid": "0.02", "best_ask": "0.66"}], "timestamp": "1769384412850", "event_type": "price_change"}}
{"_local_timestamp": "2026-01-25T23:40:13.006308+00:00", "data": {"market": "0xaa46cd9dfbc750e16e767ab71cdfbaaa9f3bbf68153fcb7e9e21bdad1f9a0e4e", "price_changes": [{"asset_id": "10190047580304467488950735708592587854326252278861442489701414156559786950928", "price": "0.27", "size": "10", "side": "BUY", "hash": "0b8ed242221b043d439300fd169e6624ce2bf803", "best_bid": "0.31", "best_ask": "0.94"}, {"asset_id": "88155858711031400772451028879251834333349215458844495516447987085254946467393", "price": "0.73", "size": "10", "side": "SELL", "hash": "1e501a8f7464784489b8bd48200319b6c4118024", "best_bid": "0.06", "best_ask": "0.69"}], "timestamp": "1769384412850", "event_type": "price_change"}}
{"_local_timestamp": "2026-01-25T23:40:13.007230+00:00", "data": {"market": "0x96449838d7dc6702e356ceb13144a6e53408b728ca363dc96b379320a2552d64", "price_changes": [{"asset_id": "88669991566060336244616088283363604665361049459599965771564136419124853077521", "price": "0.17", "size": "10", "side": "BUY", "hash": "e56c2a2e5b02a63d6903e6e7a95bcbdcb58852f8", "best_bid": "0.17", "best_ask": "0.95"}, {"asset_id": "98265373238824778819853870879462811197150130214114951682085083828419115905786", "price": "0.83", "size": "10", "side": "SELL", "hash": "985db5ef137c87830b9a23bf3e437e0a27d29d76", "best_bid": "0.05", "best_ask": "0.83"}], "timestamp": "1769384412850", "event_type": "price_change"}}
{"_local_timestamp": "2026-01-25T23:40:13.008064+00:00", "data": {"market": "0xedfafd25484c04cfbeaa767022f9eca5bb680918fceece81b36b0611eb3638a6", "price_changes": [{"asset_id": "69100260301420797247941786085257042358554422352183746124379790103566465901104", "price": "0.3", "size": "20", "side": "BUY", "hash": "4ebec945633f221c7c91a3015f37c7a19e967e91", "best_bid": "0.3", "best_ask": "0.99"}, {"asset_id": "5193041395342261568372064995546886956660044551128159772340877211907014735905", "price": "0.7", "size": "20", "side": "SELL", "hash": "17cec34e803fdab4646a900b697be6381b887ea0", "best_bid": "0.01", "best_ask": "0.7"}], "timestamp": "1769384412850", "event_type": "price_change"}}
{"_local_timestamp": "2026-01-25T23:40:13.008890+00:00", "data": {"market": "0x9ad98d277747a5af33029daa93d8921e20dc48fc43a13444b34abd5db3090419", "price_changes": [{"asset_id": "84279332923568891895771507663060971052533473524984039519051747621941395607490", "price": "0.29", "size": "10", "side": "BUY", "hash": "877bb766f462f345c39ca096a7bd8039bd5c1359", "best_bid": "0.33", "best_ask": "0.96"}, {"asset_id": "13106897552498929473034004606662562096233616324310660731332487169842346464915", "price": "0.71", "size": "10", "side": "SELL", "hash": "dc67acde1f07d89268754cf7e23611f1cb5f0661", "best_bid": "0.04", "best_ask": "0.67"}], "timestamp": "1769384412850", "event_type": "price_change"}}
{"_local_timestamp": "2026-01-25T23:40:13.082754+00:00", "data": {"market": "0xf281d9254d35ae8355aa5a2aa98fd38c96ba9c604a5526c2cf9e3a2934c1eee3", "price_changes": [{"asset_id": "9395139935407818232687755250472957071183406150419861658575355254022011268877", "price": "0.32", "size": "39", "side": "BUY", "hash": "9b8cf52584f7f5ce8bf447f3c266ba603c6760fa", "best_bid": "0.33", "best_ask": "0.98"}, {"asset_id": "89393743445790167235031936569401282709944557561334382371692027993458014466911", "price": "0.68", "size": "39", "side": "SELL", "hash": "d4f189d37411b2d6e8d45ff17e18b889fab2d4bb", "best_bid": "0.02", "best_ask": "0.67"}], "timestamp": "1769384413020", "event_type": "price_change"}}
