{"_local_timestamp": "2026-01-25T23:40:48.085379+00:00", "data": [{"market": "0x98ff544c14009c21ab3ce4032b8e00bfd59bc9ad56a44d0de5b4ff1dacfdce17", "asset_id": "103170603841569241962997570276254035764873486131514246720620193100033545958100", "timestamp": "1769381690809", "hash": "a392dea62604bbaed5ca983a6dce0e3e825468b9", "bids": [{"price": "0.001", "size": "2123.98"}, {"price": "0.002", "size": "200"}, {"price": "0.003", "size": "120"}, {"price": "0.005", "size": "180.83"}], "asks": [{"price": "0.999", "size": "11002827.99"}, {"price": "0.998", "size": "200250"}, {"price": "0.997", "size": "166"}, {"price": "0.994", "size": "83"}, {"price": "0.99", "size": "60"}, {"price": "0.989", "size": "9000"}, {"price": "0.95", "size": "30"}, {"price": "0.949", "size": "12039"}, {"price": "0.849", "size": "900"}, {"price": "0.847", "size": "125"}, {"price": "0.828", "size": "16.68"}, {"price": "0.824", "size": "46.98"}, {"price": "0.823", "size": "11"}, {"price": "0.822", "size": "20"}, {"price": "0.019", "size": "15.63"}, {"price": "0.018", "size": "23"}], "event_type": "book", "last_trade_price": "0.005"}, {"market": "0x5d1e8a08b738d682ce49308c73f0a83ae192476cc9472cb82cc989e4d83a7e7f", "asset_id": "79115303304484490600349903081713351482280993232719554838261202179898129935846", "timestamp": "1769384445614", "hash": "dc664fb2c072acddf98266c170cf4313a1c73039", "bids": [{"price": "0.001", "size": "11003227.99"}, {"price": "0.002", "size": "200250"}, {"price": "0.003", "size": "166"}, {"price": "0.006", "size": "83"}, {"price": "0.01", "size": "60"}, {"price": "0.05", "size": "30"}, {"price": "0.051", "size": "12939"}, {"price": "0.091", "size": "3500"}, {"price": "0.16", "size": "1100"}, {"price": "0.162", "size": "125"}, {"price": "0.163", "size": "12"}, {"price": "0.5", "size": "500"}, {"price": "0.501", "size": "30.51"}, {"price": "0.502", "size": "22.55"}, {"price": "0.645", "size": "21.56"}, {"price": "0.717", "size": "20"}, {"price": "0.718", "size": "20.62"}], "asks": [{"price": "0.999", "size": "564.99"}, {"price": "0.998", "size": "200"}, {"price": "0.993", "size": "300"}, {"price": "0.99", "size": "110"}, {"price": "0.989", "size": "117.61"}, {"price": "0.983", "size": "171.6"}, {"price": "0.98", "size": "96"}], "event_type": "book", "last_trade_price": "0.020"}, {"market": "0x441ff21e100009f038dfc1f6fb4322bd9de329294fab5b08bb117df4b028d4b4", "asset_id": "33811262751283200184699843470248769601054378759861210767978572223993871337654", "timestamp": "1769382800166", "hash": "6280ba75200e5e8401586bc041631fb28a91905a", "bids": [{"price": "0.001", "size": "2329.99"}], "asks": [{"price": "0.999", "size": "11002827.99"}, {"price": "0.998", "size": "450"}, {"price": "0.997", "size": "178.94"}, {"price": "0.994", "size": "83"}, {"price": "0.99", "size": "60"}, {"price": "0.95", "size": "30"}, {"price": "0.949", "size": "67.75"}, {"price": "0.948", "size": "33"}, {"price": "0.947", "size": "37"}, {"price": "0.321", "size": "41.47"}, {"price": "0.32", "size": "20"}, {"price": "0.04", "size": "5"}, {"price": "0.007", "size": "20.62"}, {"price": "0.005", "size": "15"}, {"price": "0.004", "size": "7.76"}], "event_type": "book", "last_trade_price": ""}, {"market": "0x0f68c3a9e26d4c35f15fd26f9a6a049b2f1407261ad8981b98977a8afa9d087b", "asset_id": "1461054050624993235896212005078254719114110436454300529113204898615019158205", "timestamp": "1769381938135", "hash": "b0342fa693d46781ce34ec83d8b95bdd60879a93", "bids": [{"price": "0.001", "size": "615"}, {"price": "0.002", "size": "250"}, {"price": "0.003", "size": "400"}, {"price": "0.004", "size": "200"}, {"price": "0.005", "size": "200"}, {"price": "0.006", "size": "120"}, {"price": "0.01", "size": "105.87"}], "asks": [{"price": "0.999", "size": "2313"}, {"price": "0.997", "size": "166"}, {"price": "0.994", "size": "83"}, {"price": "0.99", "size": "1100450"}, {"price": "0.95", "size": "30"}, {"price": "0.949", "size": "39"}, {"price": "0.94", "size": "20900"}, {"price": "0.92", "size": "500"}, {"price": "0.86", "size": "200"}, {"price": "0.859", "size": "75"}, {"price": "0.5", "size": "500"}, {"price": "0.499", "size": "28.5"}, {"price": "0.498", "size": "5"}, {"price": "0.35", "size": "67.14"}, {"price": "0.349", "size": "20"}, {"price": "0.029", "size": "30.17"}, {"price": "0.028", "size": "20"}], "event_type": "book", "last_trade_price": "0.011"}, {"market": "0xf1d414b578e817dbdd7c1712b03efec6802b7e265dc4d4fceda2ee2c77ea8c3b", "asset_id": "87583589342871462399925934768853512885750968436043677373297047814076793650164", "timestamp": "1769384365716", "hash": "e6b00210b2026ed24d48fdc05f1c302e3a8d8e79", "bids": [{"price": "0.001", "size": "11002827.99"}, {"price": "0.002", "size": "250"}, {"price": "0.003", "size": "20166"}, {"price": "0.006", "size": "83"}, {"price": "0.01", "size": "60"}, {"price": "0.05", "size": "30"}, {"price": "0.051", "size": "12039"}, {"price": "0.151", "size": "3000"}, {"price": "0.152", "size": "250"}, {"price": "0.163", "size": "12"}, {"price": "0.164", "size": "20"}, {"price": "0.915", "size": "47.73"}, {"price": "0.973", "size": "10"}, {"price": "0.974", "size": "5.66"}], "asks": [{"price": "0.999", "size": "1129.99"}, {"price": "0.998", "size": "200"}, {"price": "0.997", "size": "100"}, {"price": "0.99", "size": "84.4"}], "event_type": "book", "last_trade_price": "0.010"}, {"market": "0x893c4cee5898ad4dcd93964ec1d10675233886c13ac1b2d4708e3a32b54a504f", "asset_id": "76437805482471330322978339063891766583283095314899160959950486394571158603531", "timestamp": "1769383662342", "hash": "cc85f1e97d20aa00084ad322e186e25f6406e4f5", "bids": [{"price": "0.001", "size": "2827.99"}, {"price": "0.003", "size": "166"}, {"price": "0.006", "size": "83"}, {"price": "0.01", "size": "1100060"}, {"price": "0.05", "size": "30"}, {"price": "0.051", "size": "39"}, {"price": "0.06", "size": "12000"}, {"price": "0.16", "size": "900"}, {"price": "0.161", "size": "9.6"}, {"price": "0.163", "size": "64"}, {"price": "0.182", "size": "64.61"}, {"price": "0.213", "size": "10.6"}, {"price": "0.214", "size": "9"}, {"price": "0.215", "size": "20"}, {"price": "0.979", "size": "20.62"}, {"price": "0.995", "size": "25"}, {"price": "0.996", "size": "5.66"}], "asks": [{"price": "0.999", "size": "2329.99"}, {"price": "0.998", "size": "199.02"}], "event_type": "book", "last_trade_price": "0.002"}, {"market": "0x2e16b233879131e5ebcef16f3aa4cded867b1d1e935628128828ec75b89389cd", "asset_id": "91531091978001038524553671274344697516032444494833248580195281270430935741212", "timestamp": "1769382523015", "hash": "271012ff6a6d405e715de023d127d6350c1c6128", "bids": [{"price": "0.001", "size": "1615"}, {"price": "0.002", "size": "450"}], "asks": [{"price": "0.999", "size": "2313"}, {"price": "0.997", "size": "166"}, {"price": "0.994", "size": "83"}, {"price": "0.99", "size": "1100060"}, {"price": "0.95", "size": "30"}, {"price": "0.949", "size": "39"}, {"price": "0.94", "size": "12000"}, {"price": "0.84", "size": "3000"}, {"price": "0.839", "size": "16.91"}, {"price": "0.837", "size": "66"}, {"price": "0.796", "size": "12.88"}, {"price": "0.794", "size": "52.14"}, {"price": "0.793", "size": "9"}, {"price": "0.792", "size": "20"}, {"price": "0.038", "size": "16.2"}, {"price": "0.021", "size": "10"}, {"price": "0.02", "size": "25"}], "event_type": "book", "last_trade_price": ""}, {"market": "0x26af59f9de339744d95018516077612a258a48dee86850599ce73abbdc746c89", "asset_id": "14478216664224435514568993577385587670551009147033530072723812207299403011947", "timestamp": "1769383085007", "hash": "d19c617884dcf159c4032d643170442071db7883", "bids": [{"price": "0.001", "size": "2182.99"}, {"price": "0.002", "size": "450"}], "asks": [{"price": "0.999", "size": "11002827.99"}, {"price": "0.998", "size": "250"}, {"price": "0.997", "size": "2166"}, {"price": "0.996", "size": "231.57"}, {"price": "0.994", "size": "83"}, {"price": "0.99", "size": "60"}, {"price": "0.95", "size": "30"}, {"price": "0.949", "size": "39"}, {"price": "0.939", "size": "8"}, {"price": "0.848", "size": "20.88"}, {"price": "0.818", "size": "10"}, {"price": "0.817", "size": "20"}, {"price": "0.103", "size": "78.77"}, {"price": "0.04", "size": "5"}, {"price": "0.009", "size": "20.62"}, {"price": "0.008", "size": "54"}], "event_type": "book", "last_trade_price": "0.003"}, {"market": "0x65bbe9ee978b2e7f99596407bd92599db3600cbd19e0ef6cba303553c5cd3b84", "asset_id": "40553687028357385570012767684841134153932705410424731659907218042194272368471", "timestamp": "1769381828476", "hash": "7b75012607cee884ae2206c1e63f237a071c090d", "bids": [{"price": "0.01", "size": "1100410"}, {"price": "0.05", "size": "9900"}, {"price": "0.11", "size": "15500"}, {"price": "0.15", "size": "700"}, {"price": "0.18", "size": "65"}, {"price": "0.19", "size": "10"}, {"price": "0.3", "size": "100"}, {"price": "0.5", "size": "120"}, {"price": "0.52", "size": "17.28"}, {"price": "0.58", "size": "30.45"}, {"price": "0.6", "size": "20"}], "asks": [{"price": "0.99", "size": "60"}, {"price": "0.98", "size": "1000"}, {"price": "0.97", "size": "200"}, {"price": "0.96", "size": "100"}, {"price": "0.67", "size": "17.37"}], "event_type": "book", "last_trade_price": "0.600"}, {"market": "0x2e16b233879131e5ebcef16f3aa4cded867b1d1e935628128828ec75b89389cd", "asset_id": "56344928349730938381382277214367794888026799086165518377660576206947338355885", "timestamp": "1769382523015", "hash": "6906445be5de46dce2e8931a5a8ba368d8c642c2", "bids": [{"price": "0.001", "size": "2313"}, {"price": "0.003", "size": "166"}, {"price": "0.006", "size": "83"}, {"price": "0.01", "size": "1100060"}, {"price": "0.05", "size": "30"}, {"price": "0.051", "size": "39"}, {"price": "0.06", "size": "12000"}, {"price": "0.16", "size": "3000"}, {"price": "0.161", "size": "16.91"}, {"price": "0.163", "size": "66"}, {"price": "0.204", "size": "12.88"}, {"price": "0.206", "size": "52.14"}, {"price": "0.207", "size": "9"}, {"price": "0.208", "size": "20"}, {"price": "0.962", "size": "16.2"}, {"price": "0.979", "size": "10"}, {"price": "0.98", "size": "25"}], "asks": [{"price": "0.999", "size": "1615"}, {"price": "0.998", "size": "450"}], "event_type": "book", "last_trade_price": ""}, {"market": "0x8ac035f347e31dec359c8167e38e161b8a1a168f31104d2580d21e6e57555ea5", "asset_id": "87247734861341513819506998862670010115958616717316515255174919511011083576350", "timestamp": "1769381758753", "hash": "e905b112b96ccc4eee57003338bf318300431dbe", "bids": [{"price": "0.001", "size": "1182.99"}, {"price": "0.003", "size": "400"}, {"price": "0.004", "size": "240"}, {"price": "0.005", "size": "144"}, {"price": "0.006", "size": "180.83"}], "asks": [{"price": "0.999", "size": "11002827.99"}, {"price": "0.998", "size": "200250"}, {"price": "0.997", "size": "166"}, {"price": "0.994", "size": "83"}, {"price": "0.99", "size": "60"}, {"price": "0.95", "size": "30"}, {"price": "0.949", "size": "12039"}, {"price": "0.849", "size": "3000"}, {"price": "0.846", "size": "62"}, {"price": "0.826", "size": "15.22"}, {"price": "0.796", "size": "49.8"}, {"price": "0.795", "size": "9"}, {"price": "0.794", "size": "20"}, {"price": "0.019", "size": "32.63"}, {"price": "0.018", "size": "10"}, {"price": "0.017", "size": "25"}], "event_type": "book", "last_trade_price": "0.006"}, {"market": "0xbbe03770bba01718c5a9227263f36124c13af4e96bac998f78edc6a9a0d6c8c2", "asset_id": "26139760181457200998453340832790111201409977031297089269619986076158049783896", "timestamp": "1769383126213", "hash": "2e3a4c7c8be394c2a7b03efd86033a53f96c6d33", "bids": [{"price": "0.001", "size": "1129.99"}, {"price": "0.002", "size": "250"}, {"price": "0.004", "size": "500"}, {"price": "0.005", "size": "200"}], "asks": [{"price": "0.999", "size": "11003227.99"}, {"price": "0.998", "size": "200250"}, {"price": "0.997", "size": "166"}, {"price": "0.994", "size": "83"}, {"price": "0.99", "size": "60"}, {"price": "0.959", "size": "12000"}, {"price": "0.95", "size": "30"}, {"price": "0.949", "size": "12939"}, {"price": "0.909", "size": "2500"}, {"price": "0.849", "size": "3200"}, {"price": "0.847", "size": "125"}, {"price": "0.5", "size": "500"}, {"price": "0.499", "size": "89.51"}, {"price": "0.497", "size": "11.39"}, {"price": "0.496", "size": "25"}, {"price": "0.098", "size": "5.69"}, {"price": "0.095", "size": "43.6"}, {"price": "0.05", "size": "5"}, {"price": "0.049", "size": "0.21"}], "event_type": "book", "last_trade_price": "0.005"}, {"market": "0x4f2f23afda0d87b57ed33b08385c13c105f5d4472c168a52db4613c00219e4ab", "asset_id": "35789091543440777808221394349366027271646056402550277025078601102529476083334", "timestamp": "1769382864911", "hash": "bee4c0d87c14d3df159632efedb8268550beb366", "bids": [{"price": "0.001", "size": "11002827.99"}, {"price": "0.002", "size": "250"}, {"price": "0.003", "size": "166"}, {"price": "0.006", "size": "83"}, {"price": "0.01", "size": "60"}, {"price": "0.05", "size": "30"}, {"price": "0.051", "size": "12039"}, {"price": "0.151", "size": "3000"}, {"price": "0.153", "size": "125"}, {"price": "0.154", "size": "12"}, {"price": "0.679", "size": "26.51"}, {"price": "0.681", "size": "21.22"}, {"price": "0.682", "size": "20"}, {"price": "0.95", "size": "6.86"}, {"price": "0.973", "size": "10"}, {"price": "0.974", "size": "5.66"}], "asks": [{"price": "0.999", "size": "564.99"}, {"price": "0.997", "size": "400"}, {"price": "0.996", "size": "200"}, {"price": "0.995", "size": "100"}, {"price": "0.99", "size": "120.4"}, {"price": "0.985", "size": "96"}], "event_type": "book", "last_trade_price": "0.015"}, {"market": "0xbbe03770bba01718c5a9227263f36124c13af4e96bac998f78edc6a9a0d6c8c2", "asset_id": "21751045920714268882598373916080579177919726091657156143553190416206190338871", "timestamp": "1769383126213", "hash": "18c16991444fb3df7ee7f6485978cb0768075883", "bids": [{"price": "0.001", "size": "11003227.99"}, {"price": "0.002", "size": "200250"}, {"price": "0.003", "size": "166"}, {"price": "0.006", "size": "83"}, {"price": "0.01", "size": "60"}, {"price": "0.041", "size": "12000"}, {"price": "0.05", "size": "30"}, {"price": "0.051", "size": "12939"}, {"price": "0.091", "size": "2500"}, {"price": "0.151", "size": "3200"}, {"price": "0.153", "size": "125"}, {"price": "0.5", "size": "500"}, {"price": "0.501", "size": "89.51"}, {"price": "0.503", "size": "11.39"}, {"price": "0.504", "size": "25"}, {"price": "0.902", "size": "5.69"}, {"price": "0.905", "size": "43.6"}, {"price": "0.95", "size": "5"}, {"price": "0.951", "size": "0.21"}], "asks": [{"price": "0.999", "size": "1129.99"}, {"price": "0.998", "size": "250"}, {"price": "0.996", "size": "500"}, {"price": "0.995", "size": "200"}], "event_type": "book", "last_trade_price": "0.005"}, {"market": "0x0f68c3a9e26d4c35f15fd26f9a6a049b2f1407261ad8981b98977a8afa9d087b", "asset_id": "61240240600582938454064457548680517512785777298126011321396572901104696106643", "timestamp": "1769381938135", "hash": "cd8dce5f8238d4f679cbe896227549d1936df819", "bids": [{"price": "0.001", "size": "2313"}, {"price": "0.003", "size": "166"}, {"price": "0.006", "size": "83"}, {"price": "0.01", "size": "1100450"}, {"price": "0.05", "size": "30"}, {"price": "0.051", "size": "39"}, {"price": "0.06", "size": "20900"}, {"price": "0.08", "size": "500"}, {"price": "0.14", "size": "200"}, {"price": "0.141", "size": "75"}, {"price": "0.5", "size": "500"}, {"price": "0.501", "size": "28.5"}, {"price": "0.502", "size": "5"}, {"price": "0.65", "size": "67.14"}, {"price": "0.651", "size": "20"}, {"price": "0.971", "size": "30.17"}, {"price": "0.972", "size": "20"}], "asks": [{"price": "0.999", "size": "615"}, {"price": "0.998", "size": "250"}, {"price": "0.997", "size": "400"}, {"price": "0.996", "size": "200"}, {"price": "0.995", "size": "200"}, {"price": "0.994", "size": "120"}, {"price": "0.99", "size": "105.87"}], "event_type": "book", "last_trade_price": "0.011"}, {"market": "0x441ff21e100009f038dfc1f6fb4322bd9de329294fab5b08bb117df4b028d4b4", "asset_id": "102521185546259033620829812904530935088862629236111086806524951512261463322372", "timestamp": "1769382800166", "hash": "0b4ad0dcfef77edd00c9f30681153e5aca6fa27e", "bids": [{"price": "0.001", "size": "11002827.99"}, {"price": "0.002", "size": "450"}, {"price": "0.003", "size": "178.94"}, {"price": "0.006", "size": "83"}, {"price": "0.01", "size": "60"}, {"price": "0.05", "size": "30"}, {"price": "0.051", "size": "67.75"}, {"price": "0.052", "size": "33"}, {"price": "0.053", "size": "37"}, {"price": "0.679", "size": "41.47"}, {"price": "0.68", "size": "20"}, {"price": "0.96", "size": "5"}, {"price": "0.993", "size": "20.62"}, {"price": "0.995", "size": "15"}, {"price": "0.996", "size": "7.76"}], "asks": [{"price": "0.999", "size": "2329.99"}], "event_type": "book", "last_trade_price": ""}, {"market": "0x6b934e09bcaa5d0cb9405c6dcc101781f3fa14d47dd3fc57eb65c28b7cd0ee80", "asset_id": "55457415255133458104150047886027949296877531855205027106131635208993827875242", "timestamp": "1769383046044", "hash": "d88dfebae34eb7aa67f6a647a1b173c652e37d05", "bids": [{"price": "0.001", "size": "2313"}, {"price": "0.003", "size": "166"}, {"price": "0.006", "size": "83"}, {"price": "0.01", "size": "1100060"}, {"price": "0.03", "size": "12000"}, {"price": "0.05", "size": "30"}, {"price": "0.051", "size": "39"}, {"price": "0.06", "size": "20000"}, {"price": "0.16", "size": "900"}, {"price": "0.163", "size": "62"}, {"price": "0.164", "size": "12"}, {"price": "0.584", "size": "11.97"}, {"price": "0.718", "size": "65.09"}, {"price": "0.719", "size": "20"}, {"price": "0.972", "size": "34"}, {"price": "0.973", "size": "19.6"}], "asks": [{"price": "0.999", "size": "2160.99"}, {"price": "0.998", "size": "250"}, {"price": "0.997", "size": "400"}, {"price": "0.996", "size": "200"}, {"price": "0.995", "size": "100"}, {"price": "0.99", "size": "105.07"}], "event_type": "book", "last_trade_price": "0.010"}, {"market": "0x8ac035f347e31dec359c8167e38e161b8a1a168f31104d2580d21e6e57555ea5", "asset_id": "34173366805116285677478482534186889693655983054128867665074304359078445469824", "timestamp": "1769381758753", "hash": "447e31ed4945d85537adbf1bf012caa97733bc4c", "bids": [{"price": "0.001", "size": "11002827.99"}, {"price": "0.002", "size": "200250"}, {"price": "0.003", "size": "166"}, {"price": "0.006", "size": "83"}, {"price": "0.01", "size": "60"}, {"price": "0.05", "size": "30"}, {"price": "0.051", "size": "12039"}, {"price": "0.151", "size": "3000"}, {"price": "0.154", "size": "62"}, {"price": "0.174", "size": "15.22"}, {"price": "0.204", "size": "49.8"}, {"price": "0.205", "size": "9"}, {"price": "0.206", "size": "20"}, {"price": "0.981", "size": "32.63"}, {"price": "0.982", "size": "10"}, {"price": "0.983", "size": "25"}], "asks": [{"price": "0.999", "size": "1182.99"}, {"price": "0.997", "size": "400"}, {"price": "0.996", "size": "240"}, {"price": "0.995", "size": "144"}, {"price": "0.994", "size": "180.83"}], "event_type": "book", "last_trade_price": "0.006"}, {"market": "0x39b718f6e0a66a3ae5e459e76c74a694b521eaff5f6015857d1d191f1fc03c61", "asset_id": "55794910131918732608143325808731608350538323781799534833013667918954993794053", "timestamp": "1769384445319", "hash": "0ff2d255e3f0cfc7591cf3fcdbbb61f9d9b01ee3", "bids": [{"price": "0.01", "size": "1100460"}, {"price": "0.05", "size": "30"}, {"price": "0.06", "size": "12933"}, {"price": "0.09", "size": "500"}, {"price": "0.16", "size": "1100"}, {"price": "0.18", "size": "125"}, {"price": "0.5", "size": "500"}, {"price": "0.51", "size": "30"}, {"price": "0.52", "size": "5"}, {"price": "0.76", "size": "22.8"}, {"price": "0.77", "size": "20"}, {"price": "0.79", "size": "21"}, {"price": "0.8", "size": "40.77"}], "asks": [{"price": "0.99", "size": "405"}, {"price": "0.98", "size": "260.4"}], "event_type": "book", "last_trade_price": "0.020"}, {"market": "0xf7c252ad31286ada89db99be13597440c560902399c76c38467fa86b0afafc38", "asset_id": "102124581147878849417013974949016966040760828086139587269608936045361043639164", "timestamp": "1769381865131", "hash": "7267b32f585e5dada9f6214a225f8520e67753ba", "bids": [{"price": "0.001", "size": "11002827.99"}, {"price": "0.002", "size": "200250"}, {"price": "0.003", "size": "166"}, {"price": "0.006", "size": "83"}, {"price": "0.01", "size": "60"}, {"price": "0.011", "size": "50000"}, {"price": "0.05", "size": "30"}, {"price": "0.051", "size": "39"}, {"price": "0.06", "size": "20000"}, {"price": "0.1", "size": "3000"}, {"price": "0.16", "size": "900"}, {"price": "0.162", "size": "125"}, {"price": "0.165", "size": "18.33"}, {"price": "0.166", "size": "12"}, {"price": "0.779", "size": "48.81"}, {"price": "0.78", "size": "20"}, {"price": "0.972", "size": "24.48"}, {"price": "0.973", "size": "10"}], "asks": [{"price": "0.999", "size": "1160.99"}, {"price": "0.997", "size": "480"}, {"price": "0.996", "size": "240"}, {"price": "0.995", "size": "120"}, {"price": "0.99", "size": "37.76"}], "event_type": "book", "last_trade_price": "0.010"}, {"market": "0xa7280343bc5ad62d8e5160992fc70874f6818708699336df24a74ba96151ea2c", "asset_id": "54935126197359005865759470122412489520668573958432708236792605627229004170180", "timestamp": "1769381613335", "hash": "2013b0204797c8973b6e1710bb34ca70f274e390", "bids": [{"price": "0.001", "size": "2340.31"}], "asks": [{"price": "0.999", "size": "11002827.99"}, {"price": "0.998", "size": "200250"}, {"price": "0.997", "size": "166"}, {"price": "0.994", "size": "83"}, {"price": "0.99", "size": "60"}, {"price": "0.95", "size": "30"}, {"price": "0.949", "size": "20039"}, {"price": "0.849", "size": "3000"}, {"price": "0.848", "size": "9.6"}, {"price": "0.847", "size": "129"}, {"price": "0.803", "size": "10.87"}, {"price": "0.802", "size": "10"}, {"price": "0.462", "size": "56.05"}, {"price": "0.461", "size": "20"}, {"price": "0.03", "size": "5"}, {"price": "0.006", "size": "20.62"}, {"price": "0.005", "size": "14"}], "event_type": "book", "last_trade_price": ""}, {"market": "0x4f2f23afda0d87b57ed33b08385c13c105f5d4472c168a52db4613c00219e4ab", "asset_id": "56817721501888200995445115014051693037609706113137837700953458395023236061222", "timestamp": "1769382864911", "hash": "c8a13726ab1444a8d522ecbb9775e46aebd494f1", "bids": [{"price": "0.001", "size": "564.99"}, {"price": "0.003", "size": "400"}, {"price": "0.004", "size": "200"}, {"price": "0.005", "size": "100"}, {"price": "0.01", "size": "120.4"}, {"price": "0.015", "size": "96"}], "asks": [{"price": "0.999", "size": "11002827.99"}, {"price": "0.998", "size": "250"}, {"price": "0.997", "size": "166"}, {"price": "0.994", "size": "83"}, {"price": "0.99", "size": "60"}, {"price": "0.95", "size": "30"}, {"price": "0.949", "size": "12039"}, {"price": "0.849", "size": "3000"}, {"price": "0.847", "size": "125"}, {"price": "0.846", "size": "12"}, {"price": "0.321", "size": "26.51"}, {"price": "0.319", "size": "21.22"}, {"price": "0.318", "size": "20"}, {"price": "0.05", "size": "6.86"}, {"price": "0.027", "size": "10"}, {"price": "0.026", "size": "5.66"}], "event_type": "book", "last_trade_price": "0.015"}, {"market": "0x98ff544c14009c21ab3ce4032b8e00bfd59bc9ad56a44d0de5b4ff1dacfdce17", "asset_id": "14097008916194391124162656111229160397374373462461601884192711677939131372373", "timestamp": "1769381690809", "hash": "e7095dbd396e12608e9b1d961f16f24b4a993998", "bids": [{"price": "0.001", "size": "11002827.99"}, {"price": "0.002", "size": "200250"}, {"price": "0.003", "size": "166"}, {"price": "0.006", "size": "83"}, {"price": "0.01", "size": "60"}, {"price": "0.011", "size": "9000"}, {"price": "0.05", "size": "30"}, {"price": "0.051", "size": "12039"}, {"price": "0.151", "size": "900"}, {"price": "0.153", "size": "125"}, {"price": "0.172", "size": "16.68"}, {"price": "0.176", "size": "46.98"}, {"price": "0.177", "size": "11"}, {"price": "0.178", "size": "20"}, {"price": "0.981", "size": "15.63"}, {"price": "0.982", "size": "23"}], "asks": [{"price": "0.999", "size": "2123.98"}, {"price": "0.998", "size": "200"}, {"price": "0.997", "size": "120"}, {"price": "0.995", "size": "180.83"}], "event_type": "book", "last_trade_price": "0.005"}, {"market": "0x9777a1c22720f62ad2f4c6d9f8434d97ca898c53234f13b7b04072e5c29f1335", "asset_id": "63377503142727055564093019056184242393709280801147979425436600414523926785367", "timestamp": "1769382929217", "hash": "afbd1182b6141b233d22528261ee70dc543d7c34", "bids": [{"price": "0.001", "size": "2317"}, {"price": "0.003", "size": "166"}, {"price": "0.006", "size": "83"}, {"price": "0.01", "size": "1100460"}, {"price": "0.05", "size": "30"}, {"price": "0.051", "size": "39"}, {"price": "0.06", "size": "20900"}, {"price": "0.09", "size": "500"}, {"price": "0.16", "size": "1100"}, {"price": "0.162", "size": "125"}, {"price": "0.5", "size": "500"}, {"price": "0.501", "size": "5"}, {"price": "0.69", "size": "21.34"}, {"price": "0.691", "size": "20"}, {"price": "0.814", "size": "22.77"}, {"price": "0.972", "size": "24.48"}, {"price": "0.973", "size": "10"}], "asks": [{"price": "0.999", "size": "1646"}, {"price": "0.998", "size": "450"}, {"price": "0.996", "size": "134.4"}, {"price": "0.995", "size": "120"}, {"price": "0.99", "size": "37.76"}], "event_type": "book", "last_trade_price": "0.010"}, {"market": "0x2212033b5adefa053fe4c71067daa55118aa7e97cd9599f3d31d49bbc5778674", "asset_id": "100773059572910646459952761074943719193478058942609676747915933365140728243302", "timestamp": "1769382923346", "hash": "7eba316a1349be2066ca542d6c14e80162997db3", "bids": [{"price": "0.001", "size": "954"}, {"price": "0.003", "size": "400"}, {"price": "0.004", "size": "200"}, {"price": "0.01", "size": "110"}, {"price": "0.011", "size": "148.43"}, {"price": "0.02", "size": "38"}], "asks": [{"price": "0.999", "size": "11002313"}, {"price": "0.998", "size": "60250"}, {"price": "0.997", "size": "166"}, {"price": "0.994", "size": "83"}, {"price": "0.99", "size": "60"}, {"price": "0.989", "size": "30000"}, {"price": "0.95", "size": "30"}, {"price": "0.949", "size": "39"}, {"price": "0.94", "size": "12000"}, {"price": "0.84", "size": "900"}, {"price": "0.808", "size": "80.99"}, {"price": "0.807", "size": "40"}, {"price": "0.793", "size": "9"}, {"price": "0.792", "size": "20"}, {"price": "0.171", "size": "50.62"}, {"price": "0.113", "size": "32.63"}, {"price": "0.094", "size": "36.34"}, {"price": "0.093", "size": "19.6"}], "event_type": "book", "last_trade_price": "0.020"}, {"market": "0x65bbe9ee978b2e7f99596407bd92599db3600cbd19e0ef6cba303553c5cd3b84", "asset_id": "71827396998946924240056437519949087820352588387051888811942886136688189882272", "timestamp": "1769381828476", "hash": "16fa627210a6006ba2883452adbcf26153bea1e9", "bids": [{"price": "0.01", "size": "60"}, {"price": "0.02", "size": "1000"}, {"price": "0.03", "size": "200"}, {"price": "0.04", "size": "100"}, {"price": "0.33", "size": "17.37"}], "asks": [{"price": "0.99", "size": "1100410"}, {"price": "0.95", "size": "9900"}, {"price": "0.89", "size": "15500"}, {"price": "0.85", "size": "700"}, {"price": "0.82", "size": "65"}, {"price": "0.81", "size": "10"}, {"price": "0.7", "size": "100"}, {"price": "0.5", "size": "120"}, {"price": "0.48", "size": "17.28"}, {"price": "0.42", "size": "30.45"}, {"price": "0.4", "size": "20"}], "event_type": "book", "last_trade_price": "0.600"}, {"market": "0xcf4cf0cf9882b50018054826d561f688e319e6e51de956437fa6dbf642696a40", "asset_id": "9026469324102605102307422463289059933747503876473416458571688189421606447134", "timestamp": "1769383731082", "hash": "4ce93b40ec51f6bc62bfc655fe808fef7830f528", "bids": [{"price": "0.01", "size": "1100460"}, {"price": "0.05", "size": "900"}, {"price": "0.09", "size": "1000"}, {"price": "0.1", "size": "20500"}, {"price": "0.17", "size": "5200"}, {"price": "0.2", "size": "62"}, {"price": "0.21", "size": "9"}, {"price": "0.22", "size": "20"}, {"price": "0.5", "size": "100"}, {"price": "0.51", "size": "42.3"}], "asks": [{"price": "0.99", "size": "60"}, {"price": "0.98", "size": "1000"}, {"price": "0.97", "size": "200"}, {"price": "0.9", "size": "100"}, {"price": "0.89", "size": "50"}, {"price": "0.85", "size": "100"}, {"price": "0.8", "size": "50"}, {"price": "0.65", "size": "35.59"}, {"price": "0.6", "size": "3.72"}], "event_type": "book", "last_trade_price": "0.600"}, {"market": "0x5d1e8a08b738d682ce49308c73f0a83ae192476cc9472cb82cc989e4d83a7e7f", "asset_id": "97425373542541244409279148168035803042084783523795409980290844728581925888286", "timestamp": "1769384445614", "hash": "b0eeeea346964e8cc4d16406f2e7e5a30f84fc36", "bids": [{"price": "0.001", "size": "564.99"}, {"price": "0.002", "size": "200"}, {"price": "0.007", "size": "300"}, {"price": "0.01", "size": "110"}, {"price": "0.011", "size": "117.61"}, {"price": "0.017", "size": "171.6"}, {"price": "0.02", "size": "96"}], "asks": [{"price": "0.999", "size": "11003227.99"}, {"price": "0.998", "size": "200250"}, {"price": "0.997", "size": "166"}, {"price": "0.994", "size": "83"}, {"price": "0.99", "size": "60"}, {"price": "0.95", "size": "30"}, {"price": "0.949", "size": "12939"}, {"price": "0.909", "size": "3500"}, {"price": "0.84", "size": "1100"}, {"price": "0.838", "size": "125"}, {"price": "0.837", "size": "12"}, {"price": "0.5", "size": "500"}, {"price": "0.499", "size": "30.51"}, {"price": "0.498", "size": "22.55"}, {"price": "0.355", "size": "21.56"}, {"price": "0.283", "size": "20"}, {"price": "0.282", "size": "20.62"}], "event_type": "book", "last_trade_price": "0.020"}, {"market": "0xa7280343bc5ad62d8e5160992fc70874f6818708699336df24a74ba96151ea2c", "asset_id": "14090299758584058404594054949667144236575286001215374160796137162943740538736", "timestamp": "1769381613335", "hash": "b85b763f410fee1adf3183506fefd8daf715d478", "bids": [{"price": "0.001", "size": "11002827.99"}, {"price": "0.002", "size": "200250"}, {"price": "0.003", "size": "166"}, {"price": "0.006", "size": "83"}, {"price": "0.01", "size": "60"}, {"price": "0.05", "size": "30"}, {"price": "0.051", "size": "20039"}, {"price": "0.151", "size": "3000"}, {"price": "0.152", "size": "9.6"}, {"price": "0.153", "size": "129"}, {"price": "0.197", "size": "10.87"}, {"price": "0.198", "size": "10"}, {"price": "0.538", "size": "56.05"}, {"price": "0.539", "size": "20"}, {"price": "0.97", "size": "5"}, {"price": "0.994", "size": "20.62"}, {"price": "0.995", "size": "14"}], "asks": [{"price": "0.999", "size": "2340.31"}], "event_type": "book", "last_trade_price": ""}, {"market": "0x15f8f202d13a8bf70566cc9d015331f2b7c4673ce7c0f3bd9274122143da98d7", "asset_id": "6003904135061936547790713762650160287283968685330714568260970794818630572545", "timestamp": "1769384445614", "hash": "90b27a2193ea8be6f534a55eee1692e6c23055a0", "bids": [{"price": "0.001", "size": "564.99"}, {"price": "0.002", "size": "250"}, {"price": "0.01", "size": "1110"}, {"price": "0.011", "size": "200"}, {"price": "0.015", "size": "110.4"}, {"price": "0.02", "size": "116"}, {"price": "0.021", "size": "69.6"}, {"price": "0.025", "size": "46.4"}], "asks": [{"price": "0.999", "size": "11003227.99"}, {"price": "0.998", "size": "250"}, {"price": "0.997", "size": "166"}, {"price": "0.994", "size": "83"}, {"price": "0.99", "size": "60"}, {"price": "0.989", "size": "20000"}, {"price": "0.95", "size": "30"}, {"price": "0.949", "size": "12939"}, {"price": "0.91", "size": "500"}, {"price": "0.849", "size": "3200"}, {"price": "0.847", "size": "125"}, {"price": "0.846", "size": "12"}, {"price": "0.5", "size": "500"}, {"price": "0.332", "size": "27.52"}, {"price": "0.32", "size": "16.59"}, {"price": "0.248", "size": "20"}, {"price": "0.247", "size": "20"}], "event_type": "book", "last_trade_price": "0.027"}, {"market": "0x2212033b5adefa053fe4c71067daa55118aa7e97cd9599f3d31d49bbc5778674", "asset_id": "38136374517243278174498361411140872260412453285694289485466442227027030572659", "timestamp": "1769382923346", "hash": "26e35f393aef91437957f07090e5703eb2fc0988", "bids": [{"price": "0.001", "size": "11002313"}, {"price": "0.002", "size": "60250"}, {"price": "0.003", "size": "166"}, {"price": "0.006", "size": "83"}, {"price": "0.01", "size": "60"}, {"price": "0.011", "size": "30000"}, {"price": "0.05", "size": "30"}, {"price": "0.051", "size": "39"}, {"price": "0.06", "size": "12000"}, {"price": "0.16", "size": "900"}, {"price": "0.192", "size": "80.99"}, {"price": "0.193", "size": "40"}, {"price": "0.207", "size": "9"}, {"price": "0.208", "size": "20"}, {"price": "0.829", "size": "50.62"}, {"price": "0.887", "size": "32.63"}, {"price": "0.906", "size": "36.34"}, {"price": "0.907", "size": "19.6"}], "asks": [{"price": "0.999", "size": "954"}, {"price": "0.997", "size": "400"}, {"price": "0.996", "size": "200"}, {"price": "0.99", "size": "110"}, {"price": "0.989", "size": "148.43"}, {"price": "0.98", "size": "38"}], "event_type": "book", "last_trade_price": "0.020"}, {"market": "0x1e8287101399f3c9c1c135d82f7e53613a4ba421cab14fb7e6b2b1cf8bd83f30", "asset_id": "105266113555482874447692384740183990312049358997159118634356221057644647229583", "timestamp": "1769384445614", "hash": "d990b579608045ede4fe11d2cee080d6de8a0a99", "bids": [{"price": "0.001", "size": "11003227.99"}, {"price": "0.002", "size": "200250"}, {"price": "0.003", "size": "166"}, {"price": "0.006", "size": "83"}, {"price": "0.01", "size": "60"}, {"price": "0.021", "size": "20000"}, {"price": "0.05", "size": "30"}, {"price": "0.051", "size": "9939"}, {"price": "0.09", "size": "500"}, {"price": "0.151", "size": "3200"}, {"price": "0.153", "size": "125"}, {"price": "0.5", "size": "500"}, {"price": "0.501", "size": "5"}, {"price": "0.677", "size": "22.55"}, {"price": "0.687", "size": "21.56"}, {"price": "0.759", "size": "20"}, {"price": "0.76", "size": "20"}], "asks": [{"price": "0.999", "size": "564.99"}, {"price": "0.998", "size": "250"}, {"price": "0.997", "size": "400"}, {"price": "0.996", "size": "200"}, {"price": "0.99", "size": "110"}, {"price": "0.989", "size": "66"}, {"price": "0.98", "size": "61.8"}], "event_type": "book", "last_trade_price": "0.022"}, {"market": "0x60ec73dedf897f7e3d5cdb9c936ef95b518308048710b121b1d78b1faf8b6624", "asset_id": "2570427684668312132235522785122859007771310210696653682158389509086501062668", "timestamp": "1769382931823", "hash": "39d11331d0a13f0d369737b5aeef4f79925a743f", "bids": [{"price": "0.001", "size": "2827.99"}, {"price": "0.003", "size": "166"}, {"price": "0.006", "size": "83"}, {"price": "0.01", "size": "1100460"}, {"price": "0.05", "size": "30"}, {"price": "0.051", "size": "39"}, {"price": "0.06", "size": "12900"}, {"price": "0.09", "size": "500"}, {"price": "0.16", "size": "1100"}, {"price": "0.162", "size": "125"}, {"price": "0.5", "size": "500"}, {"price": "0.501", "size": "27.01"}, {"price": "0.503", "size": "14.67"}, {"price": "0.504", "size": "20"}, {"price": "0.505", "size": "5"}, {"price": "0.868", "size": "80.97"}, {"price": "0.964", "size": "13.37"}, {"price": "0.98", "size": "30.74"}, {"price": "0.981", "size": "25"}], "asks": [{"price": "0.999", "size": "1182.99"}, {"price": "0.998", "size": "240.4"}, {"price": "0.997", "size": "573.6"}, {"price": "0.996", "size": "240"}], "event_type": "book", "last_trade_price": "0.005"}, {"market": "0x60ec73dedf897f7e3d5cdb9c936ef95b518308048710b121b1d78b1faf8b6624", "asset_id": "22673989818673056879622151873081086132207087533435957795006639990431078581262", "timestamp": "1769382931823", "hash": "0cfba3a6430c19f9b4f7d61f29cbb1f42010ef95", "bids": [{"price": "0.001", "size": "1182.99"}, {"price": "0.002", "size": "240.4"}, {"price": "0.003", "size": "573.6"}, {"price": "0.004", "size": "240"}], "asks": [{"price": "0.999", "size": "2827.99"}, {"price": "0.997", "size": "166"}, {"price": "0.994", "size": "83"}, {"price": "0.99", "size": "1100460"}, {"price": "0.95", "size": "30"}, {"price": "0.949", "size": "39"}, {"price": "0.94", "size": "12900"}, {"price": "0.91", "size": "500"}, {"price": "0.84", "size": "1100"}, {"price": "0.838", "size": "125"}, {"price": "0.5", "size": "500"}, {"price": "0.499", "size": "27.01"}, {"price": "0.497", "size": "14.67"}, {"price": "0.496", "size": "20"}, {"price": "0.495", "size": "5"}, {"price": "0.132", "size": "80.97"}, {"price": "0.036", "size": "13.37"}, {"price": "0.02", "size": "30.74"}, {"price": "0.019", "size": "25"}], "event_type": "book", "last_trade_price": "0.005"}, {"market": "0xf7c252ad31286ada89db99be13597440c560902399c76c38467fa86b0afafc38", "asset_id": "32637491402862397548368511721034037439318650587574930074931384532496135682625", "timestamp": "1769381865131", "hash": "6785d438d2c85f2266397a112497a68f3809fbcc", "bids": [{"price": "0.001", "size": "1160.99"}, {"price": "0.003", "size": "480"}, {"price": "0.004", "size": "240"}, {"price": "0.005", "size": "120"}, {"price": "0.01", "size": "37.76"}], "asks": [{"price": "0.999", "size": "11002827.99"}, {"price": "0.998", "size": "200250"}, {"price": "0.997", "size": "166"}, {"price": "0.994", "size": "83"}, {"price": "0.99", "size": "60"}, {"price": "0.989", "size": "50000"}, {"price": "0.95", "size": "30"}, {"price": "0.949", "size": "39"}, {"price": "0.94", "size": "20000"}, {"price": "0.9", "size": "3000"}, {"price": "0.84", "size": "900"}, {"price": "0.838", "size": "125"}, {"price": "0.835", "size": "18.33"}, {"price": "0.834", "size": "12"}, {"price": "0.221", "size": "48.81"}, {"price": "0.22", "size": "20"}, {"price": "0.028", "size": "24.48"}, {"price": "0.027", "size": "10"}], "event_type": "book", "last_trade_price": "0.010"}, {"market": "0xcf4cf0cf9882b50018054826d561f688e319e6e51de956437fa6dbf642696a40", "asset_id": "71401904010247427754329784277924205841820460862761252985878735510347215917540", "timestamp": "1769383731082", "hash": "afba9532b6d34a7126e0062bd6384d7b37d3f19c", "bids": [{"price": "0.01", "size": "60"}, {"price": "0.02", "size": "1000"}, {"price": "0.03", "size": "200"}, {"price": "0.1", "size": "100"}, {"price": "0.11", "size": "50"}, {"price": "0.15", "size": "100"}, {"price": "0.2", "size": "50"}, {"price": "0.35", "size": "35.59"}, {"price": "0.4", "size": "3.72"}], "asks": [{"price": "0.99", "size": "1100460"}, {"price": "0.95", "size": "900"}, {"price": "0.91", "size": "1000"}, {"price": "0.9", "size": "20500"}, {"price": "0.83", "size": "5200"}, {"price": "0.8", "size": "62"}, {"price": "0.79", "size": "9"}, {"price": "0.78", "size": "20"}, {"price": "0.5", "size": "100"}, {"price": "0.49", "size": "42.3"}], "event_type": "book", "last_trade_price": "0.600"}, {"market": "0x9777a1c22720f62ad2f4c6d9f8434d97ca898c53234f13b7b04072e5c29f1335", "asset_id": "57113178010000514385185701112305969142789669701398565067796925894106572110598", "timestamp": "1769382929217", "hash": "c6f6b8498a18f8f165a012fb3d0067e3eb661206", "bids": [{"price": "0.001", "size": "1646"}, {"price": "0.002", "size": "450"}, {"price": "0.004", "size": "134.4"}, {"price": "0.005", "size": "120"}, {"price": "0.01", "size": "37.76"}], "asks": [{"price": "0.999", "size": "2317"}, {"price": "0.997", "size": "166"}, {"price": "0.994", "size": "83"}, {"price": "0.99", "size": "1100460"}, {"price": "0.95", "size": "30"}, {"price": "0.949", "size": "39"}, {"price": "0.94", "size": "20900"}, {"price": "0.91", "size": "500"}, {"price": "0.84", "size": "1100"}, {"price": "0.838", "size": "125"}, {"price": "0.5", "size": "500"}, {"price": "0.499", "size": "5"}, {"price": "0.31", "size": "21.34"}, {"price": "0.309", "size": "20"}, {"price": "0.186", "size": "22.77"}, {"price": "0.028", "size": "24.48"}, {"price": "0.027", "size": "10"}], "event_type": "book", "last_trade_price": "0.010"}, {"market": "0x893c4cee5898ad4dcd93964ec1d10675233886c13ac1b2d4708e3a32b54a504f", "asset_id": "56934214394099289690434527055602741741515158289622898582373335587526407675000", "timestamp": "1769383662342", "hash": "3c52110d38e25ed78df8ff32171255962a96cc9a", "bids": [{"price": "0.001", "size": "2329.99"}, {"price": "0.002", "size": "199.02"}], "asks": [{"price": "0.999", "size": "2827.99"}, {"price": "0.997", "size": "166"}, {"price": "0.994", "size": "83"}, {"price": "0.99", "size": "1100060"}, {"price": "0.95", "size": "30"}, {"price": "0.949", "size": "39"}, {"price": "0.94", "size": "12000"}, {"price": "0.84", "size": "900"}, {"price": "0.839", "size": "9.6"}, {"price": "0.837", "size": "64"}, {"price": "0.818", "size": "64.61"}, {"price": "0.787", "size": "10.6"}, {"price": "0.786", "size": "9"}, {"price": "0.785", "size": "20"}, {"price": "0.021", "size": "20.62"}, {"price": "0.005", "size": "25"}, {"price": "0.004", "size": "5.66"}], "event_type": "book", "last_trade_price": "0.002"}, {"market": "0xf1d414b578e817dbdd7c1712b03efec6802b7e265dc4d4fceda2ee2c77ea8c3b", "asset_id": "35068542126184320724776847815499099473150214106220936464090851244248593778627", "timestamp": "1769384365716", "hash": "93a1abe2537c9e29a989f7f7ea0b8a5c30ca03d1", "bids": [{"price": "0.001", "size": "1129.99"}, {"price": "0.002", "size": "200"}, {"price": "0.003", "size": "100"}, {"price": "0.01", "size": "84.4"}], "asks": [{"price": "0.999", "size": "11002827.99"}, {"price": "0.998", "size": "250"}, {"price": "0.997", "size": "20166"}, {"price": "0.994", "size": "83"}, {"price": "0.99", "size": "60"}, {"price": "0.95", "size": "30"}, {"price": "0.949", "size": "12039"}, {"price": "0.849", "size": "3000"}, {"price": "0.848", "size": "250"}, {"price": "0.837", "size": "12"}, {"price": "0.836", "size": "20"}, {"price": "0.085", "size": "47.73"}, {"price": "0.027", "size": "10"}, {"price": "0.026", "size": "5.66"}], "event_type": "book", "last_trade_price": "0.010"}, {"market": "0x15f8f202d13a8bf70566cc9d015331f2b7c4673ce7c0f3bd9274122143da98d7", "asset_id": "45368672532526393278374326096994364441839328602765138400884696484182735669678", "timestamp": "1769384445614", "hash": "a61f8059d00acd117f537906b89045ce49971d9b", "bids": [{"price": "0.001", "size": "11003227.99"}, {"price": "0.002", "size": "250"}, {"price": "0.003", "size": "166"}, {"price": "0.006", "size": "83"}, {"price": "0.01", "size": "60"}, {"price": "0.011", "size": "20000"}, {"price": "0.05", "size": "30"}, {"price": "0.051", "size": "12939"}, {"price": "0.09", "size": "500"}, {"price": "0.151", "size": "3200"}, {"price": "0.153", "size": "125"}, {"price": "0.154", "size": "12"}, {"price": "0.5", "size": "500"}, {"price": "0.668", "size": "27.52"}, {"price": "0.68", "size": "16.59"}, {"price": "0.752", "size": "20"}, {"price": "0.753", "size": "20"}], "asks": [{"price": "0.999", "size": "564.99"}, {"price": "0.998", "size": "250"}, {"price": "0.99", "size": "1110"}, {"price": "0.989", "size": "200"}, {"price": "0.985", "size": "110.4"}, {"price": "0.98", "size": "116"}, {"price": "0.979", "size": "69.6"}, {"price": "0.975", "size": "46.4"}], "event_type": "book", "last_trade_price": "0.027"}, {"market": "0x1e8287101399f3c9c1c135d82f7e53613a4ba421cab14fb7e6b2b1cf8bd83f30", "asset_id": "73364483172319264394905719398750594214204555040619327864407649701603224821302", "timestamp": "1769384445614", "hash": "247ccf5e5a6d4331164f24226f562cb6a5a9b404", "bids": [{"price": "0.001", "size": "564.99"}, {"price": "0.002", "size": "250"}, {"price": "0.003", "size": "400"}, {"price": "0.004", "size": "200"}, {"price": "0.01", "size": "110"}, {"price": "0.011", "size": "66"}, {"price": "0.02", "size": "61.8"}], "asks": [{"price": "0.999", "size": "11003227.99"}, {"price": "0.998", "size": "200250"}, {"price": "0.997", "size": "166"}, {"price": "0.994", "size": "83"}, {"price": "0.99", "size": "60"}, {"price": "0.979", "size": "20000"}, {"price": "0.95", "size": "30"}, {"price": "0.949", "size": "9939"}, {"price": "0.91", "size": "500"}, {"price": "0.849", "size": "3200"}, {"price": "0.847", "size": "125"}, {"price": "0.5", "size": "500"}, {"price": "0.499", "size": "5"}, {"price": "0.323", "size": "22.55"}, {"price": "0.313", "size": "21.56"}, {"price": "0.241", "size": "20"}, {"price": "0.24", "size": "20"}], "event_type": "book", "last_trade_price": "0.022"}, {"market": "0x6b934e09bcaa5d0cb9405c6dcc101781f3fa14d47dd3fc57eb65c28b7cd0ee80", "asset_id": "63359833366835568021379619837460452264325685679715864476690541477921136823082", "timestamp": "1769383046044", "hash": "ab97e91fe93fcda17a07a09770fcf3201b65217e", "bids": [{"price": "0.001", "size": "2160.99"}, {"price": "0.002", "size": "250"}, {"price": "0.003", "size": "400"}, {"price": "0.004", "size": "200"}, {"price": "0.005", "size": "100"}, {"price": "0.01", "size": "105.07"}], "asks": [{"price": "0.999", "size": "2313"}, {"price": "0.997", "size": "166"}, {"price": "0.994", "size": "83"}, {"price": "0.99", "size": "1100060"}, {"price": "0.97", "size": "12000"}, {"price": "0.95", "size": "30"}, {"price": "0.949", "size": "39"}, {"price": "0.94", "size": "20000"}, {"price": "0.84", "size": "900"}, {"price": "0.837", "size": "62"}, {"price": "0.836", "size": "12"}, {"price": "0.416", "size": "11.97"}, {"price": "0.282", "size": "65.09"}, {"price": "0.281", "size": "20"}, {"price": "0.028", "size": "34"}, {"price": "0.027", "size": "19.6"}], "event_type": "book", "last_trade_price": "0.010"}, {"market": "0x39b718f6e0a66a3ae5e459e76c74a694b521eaff5f6015857d1d191f1fc03c61", "asset_id": "10458098669927883185204828453571065550874636694709643726889899346674533724103", "timestamp": "1769384445319", "hash": "174a4e70d7c3ea456c2dd96b098e784f92a08692", "bids": [{"price": "0.01", "size": "405"}, {"price": "0.02", "size": "260.4"}], "asks": [{"price": "0.99", "size": "1100460"}, {"price": "0.95", "size": "30"}, {"price": "0.94", "size": "12933"}, {"price": "0.91", "size": "500"}, {"price": "0.84", "size": "1100"}, {"price": "0.82", "size": "125"}, {"price": "0.5", "size": "500"}, {"price": "0.49", "size": "30"}, {"price": "0.48", "size": "5"}, {"price": "0.24", "size": "22.8"}, {"price": "0.23", "size": "20"}, {"price": "0.21", "size": "21"}, {"price": "0.2", "size": "40.77"}], "event_type": "book", "last_trade_price": "0.020"}, {"market": "0x26af59f9de339744d95018516077612a258a48dee86850599ce73abbdc746c89", "asset_id": "108836227880692640385085176493445667050068330527634257153686707115842332479492", "timestamp": "1769383085007", "hash": "9a86d9720cd828ffbdca5691ec93ed6c82dd4387", "bids": [{"price": "0.001", "size": "11002827.99"}, {"price": "0.002", "size": "250"}, {"price": "0.003", "size": "2166"}, {"price": "0.004", "size": "231.57"}, {"price": "0.006", "size": "83"}, {"price": "0.01", "size": "60"}, {"price": "0.05", "size": "30"}, {"price": "0.051", "size": "39"}, {"price": "0.061", "size": "8"}, {"price": "0.152", "size": "20.88"}, {"price": "0.182", "size": "10"}, {"price": "0.183", "size": "20"}, {"price": "0.897", "size": "78.77"}, {"price": "0.96", "size": "5"}, {"price": "0.991", "size": "20.62"}, {"price": "0.992", "size": "54"}], "asks": [{"price": "0.999", "size": "2182.99"}, {"price": "0.998", "size": "450"}], "event_type": "book", "last_trade_price": "0.003"}]}
{"_local_timestamp": "2026-01-25T23:40:48.208156+00:00", "data": {"market": "0x5d1e8a08b738d682ce49308c73f0a83ae192476cc9472cb82cc989e4d83a7e7f", "price_changes": [{"asset_id": "79115303304484490600349903081713351482280993232719554838261202179898129935846", "price": "0.717", "size": "0", "side": "BUY", "hash": "dc6784abde79e1080e72a93b58cda5bbcfeea847", "best_bid": "0.718", "best_ask": "0.98"}, {"asset_id": "97425373542541244409279148168035803042084783523795409980290844728581925888286", "price": "0.283", "size": "0", "side": "SELL", "hash": "bae30fd93df66c18923b2777e90346104b0f9a98", "best_bid": "0.02", "best_ask": "0.282"}], "timestamp": "1769384447910", "event_type": "price_change"}}
{"_local_timestamp": "2026-01-25T23:40:48.209161+00:00", "data": {"market": "0x15f8f202d13a8bf70566cc9d015331f2b7c4673ce7c0f3bd9274122143da98d7", "price_changes": [{"asset_id": "45368672532526393278374326096994364441839328602765138400884696484182735669678", "price": "0.752", "size": "0", "side": "BUY", "hash": "74ea822981c29f99731bce2e7c3cfb3db1b64ac9", "best_bid": "0.753", "best_ask": "0.975"}, {"asset_id": "6003904135061936547790713762650160287283968685330714568260970794818630572545", "price": "0.248", "size": "0", "side": "SELL", "hash": "8f52c525fba6677f4106115297ef7229e1a09c23", "best_bid": "0.025", "best_ask": "0.247"}], "timestamp": "1769384447910", "event_type": "price_change"}}
{"_local_timestamp": "2026-01-25T23:40:48.209602+00:00", "data": {"market": "0x1e8287101399f3c9c1c135d82f7e53613a4ba421cab14fb7e6b2b1cf8bd83f30", "price_changes": [{"asset_id": "105266113555482874447692384740183990312049358997159118634356221057644647229583", "price": "0.759", "size": "0", "side": "BUY", "hash": "ef8c74ab7618a34575956e41215720398fb12754", "best_bid": "0.76", "best_ask": "0.98"}, {"asset_id": "73364483172319264394905719398750594214204555040619327864407649701603224821302", "price": "0.241", "size": "0", "side": "SELL", "hash": "5ce4061b88cd7e56d4cc18973fa22d11344572d3", "best_bid": "0.02", "best_ask": "0.24"}], "timestamp": "1769384447910", "event_type": "price_change"}}
{"_local_timestamp": "2026-01-25T23:40:48.210084+00:00", "data": {"market": "0xa7280343bc5ad62d8e5160992fc70874f6818708699336df24a74ba96151ea2c", "price_changes": [{"asset_id": "14090299758584058404594054949667144236575286001215374160796137162943740538736", "price": "0.198", "size": "0", "side": "BUY", "hash": "5d87bb951dbaaccf6c67bd99738db1691f8f7714", "best_bid": "0.995", "best_ask": "0.999"}, {"asset_id": "54935126197359005865759470122412489520668573958432708236792605627229004170180", "price": "0.802", "size": "0", "side": "SELL", "hash": "b918b4a7889c49c38d27fc13e9c17c200b42c511", "best_bid": "0.001", "best_ask": "0.005"}], "timestamp": "1769384447912", "event_type": "price_change"}}
{"_local_timestamp": "2026-01-25T23:40:48.210405+00:00", "data": {"market": "0x1e8287101399f3c9c1c135d82f7e53613a4ba421cab14fb7e6b2b1cf8bd83f30", "price_changes": [{"asset_id": "105266113555482874447692384740183990312049358997159118634356221057644647229583", "price": "0.761", "size": "20", "side": "BUY", "hash": "a09b7a39204f06aa2e48cd3a18b294a1901cbd73", "best_bid": "0.761", "best_ask": "0.98"}, {"asset_id": "73364483172319264394905719398750594214204555040619327864407649701603224821302", "price": "0.239", "size": "20", "side": "SELL", "hash": "d39a621caedc4d65918612f2140c564f3d8eee70", "best_bid": "0.02", "best_ask": "0.239"}], "timestamp": "1769384447947", "event_type": "price_change"}}
{"_local_timestamp": "2026-01-25T23:40:48.211930+00:00", "data": {"market": "0x15f8f202d13a8bf70566cc9d015331f2b7c4673ce7c0f3bd9274122143da98d7", "price_changes": [{"asset_id": "45368672532526393278374326096994364441839328602765138400884696484182735669678", "price": "0.754", "size": "20", "side": "BUY", "hash": "2579c632a5797b92fbef8aadc080af206fcc2e88", "best_bid": "0.754", "best_ask": "0.975"}, {"asset_id": "6003904135061936547790713762650160287283968685330714568260970794818630572545", "price": "0.246", "size": "20", "side": "SELL", "hash": "88c035d961dd3f6f4ca819fc2ed50d06541283a4", "best_bid": "0.025", "best_ask": "0.246"}], "timestamp": "1769384447947", "event_type": "price_change"}}
{"_local_timestamp": "2026-01-25T23:40:48.212526+00:00", "data": {"market": "0x5d1e8a08b738d682ce49308c73f0a83ae192476cc9472cb82cc989e4d83a7e7f", "price_changes": [{"asset_id": "79115303304484490600349903081713351482280993232719554838261202179898129935846", "price": "0.719", "size": "20", "side": "BUY", "hash": "586ba9a586c30cf1ef4cd46652f40af308c93e1b", "best_bid": "0.719", "best_ask": "0.98"}, {"asset_id": "97425373542541244409279148168035803042084783523795409980290844728581925888286", "price": "0.281", "size": "20", "side": "SELL", "hash": "07e9ca2b97388ab434296149b55f5deb344d8955", "best_bid": "0.02", "best_ask": "0.281"}], "timestamp": "1769384447947", "event_type": "price_change"}}
{"_local_timestamp": "2026-01-25T23:40:48.212844+00:00", "data": {"market": "0xa7280343bc5ad62d8e5160992fc70874f6818708699336df24a74ba96151ea2c", "price_changes": [{"asset_id": "14090299758584058404594054949667144236575286001215374160796137162943740538736", "price": "0.198", "size": "10", "side": "BUY", "hash": "205ff938c7820cecc3979b198f4f865342b37332", "best_bid": "0.995", "best_ask": "0.999"}, {"asset_id": "54935126197359005865759470122412489520668573958432708236792605627229004170180", "price": "0.802", "size": "10", "side": "SELL", "hash": "6fc4fbd73078338ae9902ba5e7fecc33dd6953fa", "best_bid": "0.001", "best_ask": "0.005"}], "timestamp": "1769384447961", "event_type": "price_change"}}
{"_local_timestamp": "2026-01-25T23:41:05.154564+00:00", "data": {"market": "0x39b718f6e0a66a3ae5e459e76c74a694b521eaff5f6015857d1d191f1fc03c61", "price_changes": [{"asset_id": "55794910131918732608143325808731608350538323781799534833013667918954993794053", "price": "0.79", "size": "0", "side": "BUY", "hash": "19a33622048a64d05893f9974d2e898287ac9b5e", "best_bid": "0.8", "best_ask": "0.98"}, {"asset_id": "10458098669927883185204828453571065550874636694709643726889899346674533724103", "price": "0.21", "size": "0", "side": "SELL", "hash": "681aae4402c2abb22ceff3618ea6dfebed9e11ec", "best_bid": "0.02", "best_ask": "0.2"}], "timestamp": "1769384465087", "event_type": "price_change"}}
{"_local_timestamp": "2026-01-25T23:42:13.995477+00:00", "data": {"market": "0x39b718f6e0a66a3ae5e459e76c74a694b521eaff5f6015857d1d191f1fc03c61", "price_changes": [{"asset_id": "10458098669927883185204828453571065550874636694709643726889899346674533724103", "price": "0.2", "size": "0", "side": "SELL", "hash": "908f4cea11ebbfef41da8937a01eec41b481d567", "best_bid": "0.02", "best_ask": "0.23"}, {"asset_id": "55794910131918732608143325808731608350538323781799534833013667918954993794053", "price": "0.8", "size": "0", "side": "BUY", "hash": "c91d22aa2c88e34cd6408cf0c3532c66260b2f27", "best_bid": "0.77", "best_ask": "0.98"}], "timestamp": "1769384533930", "event_type": "price_change"}}
{"_local_timestamp": "2026-01-25T23:42:14.291511+00:00", "data": {"market": "0x5d1e8a08b738d682ce49308c73f0a83ae192476cc9472cb82cc989e4d83a7e7f", "price_changes": [{"asset_id": "97425373542541244409279148168035803042084783523795409980290844728581925888286", "price": "0.282", "size": "0", "side": "SELL", "hash": "1999c82a1b142e8afe899f6b21ece902f74ca6b5", "best_bid": "0.02", "best_ask": "0.281"}, {"asset_id": "79115303304484490600349903081713351482280993232719554838261202179898129935846", "price": "0.718", "size": "0", "side": "BUY", "hash": "781ab2d76e4a8a1606fcb053246ce95d32ac21a5", "best_bid": "0.719", "best_ask": "0.98"}], "timestamp": "1769384534222", "event_type": "price_change"}}
{"_local_timestamp": "2026-01-25T23:42:14.291974+00:00", "data": {"market": "0x1e8287101399f3c9c1c135d82f7e53613a4ba421cab14fb7e6b2b1cf8bd83f30", "price_changes": [{"asset_id": "73364483172319264394905719398750594214204555040619327864407649701603224821302", "price": "0.24", "size": "0", "side": "SELL", "hash": "9d300a7567e252aba5e8ff7f497d8960ee46f50c", "best_bid": "0.02", "best_ask": "0.239"}, {"asset_id": "105266113555482874447692384740183990312049358997159118634356221057644647229583", "price": "0.76", "size": "0", "side": "BUY", "hash": "db56bf4e86e0c6c68ed89310fce2dc1aff90d9cd", "best_bid": "0.761", "best_ask": "0.98"}], "timestamp": "1769384534222", "event_type": "price_change"}}
{"_local_timestamp": "2026-01-25T23:42:14.292272+00:00", "data": {"market": "0x15f8f202d13a8bf70566cc9d015331f2b7c4673ce7c0f3bd9274122143da98d7", "price_changes": [{"asset_id": "6003904135061936547790713762650160287283968685330714568260970794818630572545", "price": "0.247", "size": "0", "side": "SELL", "hash": "57f51ea078df5767c09ceea6f715af7f055e7506", "best_bid": "0.025", "best_ask": "0.246"}, {"asset_id": "45368672532526393278374326096994364441839328602765138400884696484182735669678", "price": "0.753", "size": "0", "side": "BUY", "hash": "2fd7d047a6e912d1c6c8017030cc06f4c653465a", "best_bid": "0.754", "best_ask": "0.975"}], "timestamp": "1769384534222", "event_type": "price_change"}}
{"_local_timestamp": "2026-01-25T23:42:14.944198+00:00", "data": {"market": "0x39b718f6e0a66a3ae5e459e76c74a694b521eaff5f6015857d1d191f1fc03c61", "price_changes": [{"asset_id": "10458098669927883185204828453571065550874636694709643726889899346674533724103", "price": "0.22", "size": "40.77", "side": "SELL", "hash": "ba15b5953365faebbae30d8378e9cd855f78a6bd", "best_bid": "0.02", "best_ask": "0.22"}, {"asset_id": "55794910131918732608143325808731608350538323781799534833013667918954993794053", "price": "0.78", "size": "40.77", "side": "BUY", "hash": "44cbb0ce5caa2fcb7ed79f411d313c983460cd3e", "best_bid": "0.78", "best_ask": "0.98"}], "timestamp": "1769384534849", "event_type": "price_change"}}
{"_local_timestamp": "2026-01-25T23:42:15.341385+00:00", "data": {"market": "0x1e8287101399f3c9c1c135d82f7e53613a4ba421cab14fb7e6b2b1cf8bd83f30", "price_changes": [{"asset_id": "73364483172319264394905719398750594214204555040619327864407649701603224821302", "price": "0.238", "size": "20", "side": "SELL", "hash": "a6e45761cf813b3e6286aee91b5175f2549973f9", "best_bid": "0.02", "best_ask": "0.238"}, {"asset_id": "105266113555482874447692384740183990312049358997159118634356221057644647229583", "price": "0.762", "size": "20", "side": "BUY", "hash": "2b32e36a4c05de87a768895b90e2c6f13b7d22b2", "best_bid": "0.762", "best_ask": "0.98"}], "timestamp": "1769384535185", "event_type": "price_change"}}
{"_local_timestamp": "2026-01-25T23:42:15.342390+00:00", "data": {"market": "0x15f8f202d13a8bf70566cc9d015331f2b7c4673ce7c0f3bd9274122143da98d7", "price_changes": [{"asset_id": "6003904135061936547790713762650160287283968685330714568260970794818630572545", "price": "0.245", "size": "20", "side": "SELL", "hash": "d5824da25dccc72f75698d68c872a700a6028ff9", "best_bid": "0.025", "best_ask": "0.245"}, {"asset_id": "45368672532526393278374326096994364441839328602765138400884696484182735669678", "price": "0.755", "size": "20", "side": "BUY", "hash": "529b9fe894d32aaa406889915f0ccebc33b13849", "best_bid": "0.755", "best_ask": "0.975"}], "timestamp": "1769384535185", "event_type": "price_change"}}
{"_local_timestamp": "2026-01-25T23:42:15.346112+00:00", "data": {"market": "0x5d1e8a08b738d682ce49308c73f0a83ae192476cc9472cb82cc989e4d83a7e7f", "price_changes": [{"asset_id": "97425373542541244409279148168035803042084783523795409980290844728581925888286", "price": "0.28", "size": "20.62", "side": "SELL", "hash": "7e01bb92fdced03ea2d9dc2a325cc303bbd3cfdc", "best_bid": "0.02", "best_ask": "0.28"}, {"asset_id": "79115303304484490600349903081713351482280993232719554838261202179898129935846", "price": "0.72", "size": "20.62", "side": "BUY", "hash": "4cc6b48e465a107de7173191937e10d044829707", "best_bid": "0.72", "best_ask": "0.98"}], "timestamp": "1769384535188", "event_type": "price_change"}}
{"_local_timestamp": "2026-01-25T23:42:15.788170+00:00", "data": {"market": "0x5d1e8a08b738d682ce49308c73f0a83ae192476cc9472cb82cc989e4d83a7e7f", "price_changes": [{"asset_id": "79115303304484490600349903081713351482280993232719554838261202179898129935846", "price": "0.719", "size": "0", "side": "BUY", "hash": "be37ab055c40d995ed75487501dde63eb900660b", "best_bid": "0.72", "best_ask": "0.98"}, {"asset_id": "97425373542541244409279148168035803042084783523795409980290844728581925888286", "price": "0.281", "size": "0", "side": "SELL", "hash": "096004ceaaefb44aa8f9faf4e74161ca069d3d12", "best_bid": "0.02", "best_ask": "0.28"}], "timestamp": "1769384535679", "event_type": "price_change"}}
{"_local_timestamp": "2026-01-25T23:42:15.788603+00:00", "data": {"market": "0x1e8287101399f3c9c1c135d82f7e53613a4ba421cab14fb7e6b2b1cf8bd83f30", "price_changes": [{"asset_id": "105266113555482874447692384740183990312049358997159118634356221057644647229583", "price": "0.761", "size": "0", "side": "BUY", "hash": "03a8f7e2cdf1b8e831c5545bb197770c88c663bd", "best_bid": "0.762", "best_ask": "0.98"}, {"asset_id": "73364483172319264394905719398750594214204555040619327864407649701603224821302", "price": "0.239", "size": "0", "side": "SELL", "hash": "45b9a695c637d624e741d2d79f26dbd9a487db9b", "best_bid": "0.02", "best_ask": "0.238"}], "timestamp": "1769384535679", "event_type": "price_change"}}
{"_local_timestamp": "2026-01-25T23:42:15.788934+00:00", "data": {"market": "0x15f8f202d13a8bf70566cc9d015331f2b7c4673ce7c0f3bd9274122143da98d7", "price_changes": [{"asset_id": "45368672532526393278374326096994364441839328602765138400884696484182735669678", "price": "0.754", "size": "0", "side": "BUY", "hash": "a89253d045fced45f1fe4b70a9a50891683c2931", "best_bid": "0.755", "best_ask": "0.975"}, {"asset_id": "6003904135061936547790713762650160287283968685330714568260970794818630572545", "price": "0.246", "size": "0", "side": "SELL", "hash": "13c8a94e2c7e88c90e89aaa8e28fb5c6d5eae932", "best_bid": "0.025", "best_ask": "0.245"}], "timestamp": "1769384535679", "event_type": "price_change"}}
{"_local_timestamp": "2026-01-25T23:42:15.827920+00:00", "data": {"market": "0x15f8f202d13a8bf70566cc9d015331f2b7c4673ce7c0f3bd9274122143da98d7", "price_changes": [{"asset_id": "45368672532526393278374326096994364441839328602765138400884696484182735669678", "price": "0.756", "size": "20", "side": "BUY", "hash": "efdae55452501755289899eadcdca94fb962c0bc", "best_bid": "0.756", "best_ask": "0.975"}, {"asset_id": "6003904135061936547790713762650160287283968685330714568260970794818630572545", "price": "0.244", "size": "20", "side": "SELL", "hash": "94f5b92abd7a56f43efaaa79ae01f9e23ba6e81c", "best_bid": "0.025", "best_ask": "0.244"}], "timestamp": "1769384535715", "event_type": "price_change"}}
{"_local_timestamp": "2026-01-25T23:42:15.828337+00:00", "data": {"market": "0x1e8287101399f3c9c1c135d82f7e53613a4ba421cab14fb7e6b2b1cf8bd83f30", "price_changes": [{"asset_id": "105266113555482874447692384740183990312049358997159118634356221057644647229583", "price": "0.763", "size": "20", "side": "BUY", "hash": "6b385c95ca8a7c027b00e43de6973c22791702fa", "best_bid": "0.763", "best_ask": "0.98"}, {"asset_id": "73364483172319264394905719398750594214204555040619327864407649701603224821302", "price": "0.237", "size": "20", "side": "SELL", "hash": "f3ee7989ca2142ab30d2071fce56d5f77b0c6059", "best_bid": "0.02", "best_ask": "0.237"}], "timestamp": "1769384535715", "event_type": "price_change"}}
{"_local_timestamp": "2026-01-25T23:42:15.828712+00:00", "data": {"market": "0x5d1e8a08b738d682ce49308c73f0a83ae192476cc9472cb82cc989e4d83a7e7f", "price_changes": [{"asset_id": "79115303304484490600349903081713351482280993232719554838261202179898129935846", "price": "0.721", "size": "20", "side": "BUY", "hash": "e670c28c412009b50bacba15baad04be4a1b3c51", "best_bid": "0.721", "best_ask": "0.98"}, {"asset_id": "97425373542541244409279148168035803042084783523795409980290844728581925888286", "price": "0.279", "size": "20", "side": "SELL", "hash": "b4d15c4d93bae1ab92995e52eeadee02636e12b6", "best_bid": "0.02", "best_ask": "0.279"}], "timestamp": "1769384535715", "event_type": "price_change"}}
{"_local_timestamp": "2026-01-25T23:42:17.685363+00:00", "data": {"market": "0x98ff544c14009c21ab3ce4032b8e00bfd59bc9ad56a44d0de5b4ff1dacfdce17", "price_changes": [{"asset_id": "14097008916194391124162656111229160397374373462461601884192711677939131372373", "price": "0.177", "size": "0", "side": "BUY", "hash": "ec044d1d4a3e149fd3b084cef84bdfabb1c9e375", "best_bid": "0.982", "best_ask": "0.995"}, {"asset_id": "103170603841569241962997570276254035764873486131514246720620193100033545958100", "price": "0.823", "size": "0", "side": "SELL", "hash": "d940f55ed88a6750803d684b029503cd2b182a3c", "best_bid": "0.005", "best_ask": "0.018"}], "timestamp": "1769384537570", "event_type": "price_change"}}
{"_local_timestamp": "2026-01-25T23:42:17.741199+00:00", "data": {"market": "0x98ff544c14009c21ab3ce4032b8e00bfd59bc9ad56a44d0de5b4ff1dacfdce17", "price_changes": [{"asset_id": "14097008916194391124162656111229160397374373462461601884192711677939131372373", "price": "0.177", "size": "11", "side": "BUY", "hash": "b9596146eaf87c7773fd3d3d81bb10583bfebf35", "best_bid": "0.982", "best_ask": "0.995"}, {"asset_id": "103170603841569241962997570276254035764873486131514246720620193100033545958100", "price": "0.823", "size": "11", "side": "SELL", "hash": "a799d0323f5d31dd08e3ffadb15f2e2b151bc05b", "best_bid": "0.005", "best_ask": "0.018"}], "timestamp": "1769384537620", "event_type": "price_change"}}
{"_local_timestamp": "2026-01-25T23:43:23.841284+00:00", "data": {"market": "0x8ac035f347e31dec359c8167e38e161b8a1a168f31104d2580d21e6e57555ea5", "price_changes": [{"asset_id": "34173366805116285677478482534186889693655983054128867665074304359078445469824", "price": "0.205", "size": "0", "side": "BUY", "hash": "07fe65308d9930879839035aecaf510400ac6052", "best_bid": "0.983", "best_ask": "0.994"}, {"asset_id": "87247734861341513819506998862670010115958616717316515255174919511011083576350", "price": "0.795", "size": "0", "side": "SELL", "hash": "52c57b55fb316327a07e87b8e4856b2a76cd5a87", "best_bid": "0.006", "best_ask": "0.017"}], "timestamp": "1769384603697", "event_type": "price_change"}}
{"_local_timestamp": "2026-01-25T23:43:23.899651+00:00", "data": {"market": "0x8ac035f347e31dec359c8167e38e161b8a1a168f31104d2580d21e6e57555ea5", "price_changes": [{"asset_id": "34173366805116285677478482534186889693655983054128867665074304359078445469824", "price": "0.205", "size": "9", "side": "BUY", "hash": "d926caa0364e44316a3da25ebd89c19f3ec6ef9f", "best_bid": "0.983", "best_ask": "0.994"}, {"asset_id": "87247734861341513819506998862670010115958616717316515255174919511011083576350", "price": "0.795", "size": "9", "side": "SELL", "hash": "d912e78c506b3ee9c1d53ebfc824ee24dc27128b", "best_bid": "0.006", "best_ask": "0.017"}], "timestamp": "1769384603747", "event_type": "price_change"}}
{"_local_timestamp": "2026-01-25T23:43:23.957345+00:00", "data": {"market": "0x8ac035f347e31dec359c8167e38e161b8a1a168f31104d2580d21e6e57555ea5", "price_changes": [{"asset_id": "34173366805116285677478482534186889693655983054128867665074304359078445469824", "price": "0.206", "size": "0", "side": "BUY", "hash": "eee2fcd9079fde67d1fb25680c59b68381946dec", "best_bid": "0.983", "best_ask": "0.994"}, {"asset_id": "87247734861341513819506998862670010115958616717316515255174919511011083576350", "price": "0.794", "size": "0", "side": "SELL", "hash": "083329293b0769729e186f735ad6049cb4041aa8", "best_bid": "0.006", "best_ask": "0.017"}], "timestamp": "1769384603817", "event_type": "price_change"}}
{"_local_timestamp": "2026-01-25T23:43:23.983421+00:00", "data": {"market": "0x8ac035f347e31dec359c8167e38e161b8a1a168f31104d2580d21e6e57555ea5", "price_changes": [{"asset_id": "34173366805116285677478482534186889693655983054128867665074304359078445469824", "price": "0.205", "size": "29", "side": "BUY", "hash": "7e622949819cf946bedea3f799d29a4fc7662893", "best_bid": "0.983", "best_ask": "0.994"}, {"asset_id": "87247734861341513819506998862670010115958616717316515255174919511011083576350", "price": "0.795", "size": "29", "side": "SELL", "hash": "02e1a7bcd615d405d451064ea3b10c7825166629", "best_bid": "0.006", "best_ask": "0.017"}], "timestamp": "1769384603841", "event_type": "price_change"}}
{"_local_timestamp": "2026-01-25T23:43:24.316567+00:00", "data": {"market": "0x8ac035f347e31dec359c8167e38e161b8a1a168f31104d2580d21e6e57555ea5", "price_changes": [{"asset_id": "34173366805116285677478482534186889693655983054128867665074304359078445469824", "price": "0.205", "size": "9", "side": "BUY", "hash": "150f37aa7be5241ec7019bb0035bb402a5967b3d", "best_bid": "0.983", "best_ask": "0.994"}, {"asset_id": "87247734861341513819506998862670010115958616717316515255174919511011083576350", "price": "0.795", "size": "9", "side": "SELL", "hash": "a0a7ed16e03730fadd0d45ddc72ece0098e01758", "best_bid": "0.006", "best_ask": "0.017"}], "timestamp": "1769384604181", "event_type": "price_change"}}
{"_local_timestamp": "2026-01-25T23:43:24.335662+00:00", "data": {"market": "0x8ac035f347e31dec359c8167e38e161b8a1a168f31104d2580d21e6e57555ea5", "price_changes": [{"asset_id": "34173366805116285677478482534186889693655983054128867665074304359078445469824", "price": "0.206", "size": "20", "side": "BUY", "hash": "ce71d0a99608f7f16e83e89d5571ed4630838af1", "best_bid": "0.983", "best_ask": "0.994"}, {"asset_id": "87247734861341513819506998862670010115958616717316515255174919511011083576350", "price": "0.794", "size": "20", "side": "SELL", "hash": "3d07bb064dfcb9484d0bfd077df6a689c0b102b6", "best_bid": "0.006", "best_ask": "0.017"}], "timestamp": "1769384604210", "event_type": "price_change"}}
{"_local_timestamp": "2026-01-25T23:43:41.788428+00:00", "data": {"market": "0x5d1e8a08b738d682ce49308c73f0a83ae192476cc9472cb82cc989e4d83a7e7f", "price_changes": [{"asset_id": "97425373542541244409279148168035803042084783523795409980290844728581925888286", "price": "0.28", "size": "0", "side": "SELL", "hash": "132e8a9f106880d3d4068e0ea9866b8d59ccad93", "best_bid": "0.02", "best_ask": "0.279"}, {"asset_id": "79115303304484490600349903081713351482280993232719554838261202179898129935846", "price": "0.72", "size": "0", "side": "BUY", "hash": "98d7e65292ac9e1e0bc229eef0b9e52ac0ed343f", "best_bid": "0.721", "best_ask": "0.98"}], "timestamp": "1769384621674", "event_type": "price_change"}}
{"_local_timestamp": "2026-01-25T23:43:41.873259+00:00", "data": {"market": "0x15f8f202d13a8bf70566cc9d015331f2b7c4673ce7c0f3bd9274122143da98d7", "price_changes": [{"asset_id": "6003904135061936547790713762650160287283968685330714568260970794818630572545", "price": "0.245", "size": "0", "side": "SELL", "hash": "28ccc57b577c464595456e90fad0af8e9bf9d4cf", "best_bid": "0.025", "best_ask": "0.244"}, {"asset_id": "45368672532526393278374326096994364441839328602765138400884696484182735669678", "price": "0.755", "size": "0", "side": "BUY", "hash": "359b85303f4ca1bfec4894c42e194d4d7a20297a", "best_bid": "0.756", "best_ask": "0.975"}], "timestamp": "1769384621764", "event_type": "price_change"}}
{"_local_timestamp": "2026-01-25T23:43:41.873786+00:00", "data": {"market": "0x1e8287101399f3c9c1c135d82f7e53613a4ba421cab14fb7e6b2b1cf8bd83f30", "price_changes": [{"asset_id": "73364483172319264394905719398750594214204555040619327864407649701603224821302", "price": "0.238", "size": "0", "side": "SELL", "hash": "464b7a98cac8b5f8a0cc34a9bbd7081a0484efc0", "best_bid": "0.02", "best_ask": "0.237"}, {"asset_id": "105266113555482874447692384740183990312049358997159118634356221057644647229583", "price": "0.762", "size": "0", "side": "BUY", "hash": "e8ce3139eb67c8171c29ca93a97ac79feed41066", "best_bid": "0.763", "best_ask": "0.98"}], "timestamp": "1769384621764", "event_type": "price_change"}}
{"_local_timestamp": "2026-01-25T23:43:42.769427+00:00", "data": {"market": "0x15f8f202d13a8bf70566cc9d015331f2b7c4673ce7c0f3bd9274122143da98d7", "price_changes": [{"asset_id": "6003904135061936547790713762650160287283968685330714568260970794818630572545", "price": "0.243", "size": "20", "side": "SELL", "hash": "53d3fc0c49190508e62d4ab2e662b04fcdb841b7", "best_bid": "0.025", "best_ask": "0.243"}, {"asset_id": "45368672532526393278374326096994364441839328602765138400884696484182735669678", "price": "0.757", "size": "20", "side": "BUY", "hash": "160d1a13a3e6b8b60b67c316afe23760bc54a193", "best_bid": "0.757", "best_ask": "0.975"}], "timestamp": "1769384622448", "event_type": "price_change"}}
{"_local_timestamp": "2026-01-25T23:43:42.772561+00:00", "data": {"market": "0x1e8287101399f3c9c1c135d82f7e53613a4ba421cab14fb7e6b2b1cf8bd83f30", "price_changes": [{"asset_id": "73364483172319264394905719398750594214204555040619327864407649701603224821302", "price": "0.236", "size": "20", "side": "SELL", "hash": "d33f9f8ee0547612efa52314ae906729a75058f7", "best_bid": "0.02", "best_ask": "0.236"}, {"asset_id": "105266113555482874447692384740183990312049358997159118634356221057644647229583", "price": "0.764", "size": "20", "side": "BUY", "hash": "118ea6944cebb8c18a22490e15ad3181949ea813", "best_bid": "0.764", "best_ask": "0.98"}], "timestamp": "1769384622449", "event_type": "price_change"}}
{"_local_timestamp": "2026-01-25T23:43:42.775397+00:00", "data": {"market": "0x5d1e8a08b738d682ce49308c73f0a83ae192476cc9472cb82cc989e4d83a7e7f", "price_changes": [{"asset_id": "97425373542541244409279148168035803042084783523795409980290844728581925888286", "price": "0.278", "size": "20.62", "side": "SELL", "hash": "58d171cd918a5180dc94b32acc9dc5f45cdcafc4", "best_bid": "0.02", "best_ask": "0.278"}, {"asset_id": "79115303304484490600349903081713351482280993232719554838261202179898129935846", "price": "0.722", "size": "20.62", "side": "BUY", "hash": "8a112e55bfbe420645ab56f81f79f425a28f3d4a", "best_bid": "0.722", "best_ask": "0.98"}], "timestamp": "1769384622449", "event_type": "price_change"}}
{"_local_timestamp": "2026-01-25T23:43:42.899531+00:00", "data": {"market": "0x1e8287101399f3c9c1c135d82f7e53613a4ba421cab14fb7e6b2b1cf8bd83f30", "price_changes": [{"asset_id": "105266113555482874447692384740183990312049358997159118634356221057644647229583", "price": "0.763", "size": "0", "side": "BUY", "hash": "e09ffd4c8de28494e168c7c6bbc0de00ecf0dd18", "best_bid": "0.764", "best_ask": "0.98"}, {"asset_id": "73364483172319264394905719398750594214204555040619327864407649701603224821302", "price": "0.237", "size": "0", "side": "SELL", "hash": "f28a86e7fb3981a2cef06882402b0acd712d6426", "best_bid": "0.02", "best_ask": "0.236"}], "timestamp": "1769384622788", "event_type": "price_change"}}
{"_local_timestamp": "2026-01-25T23:43:42.900031+00:00", "data": {"market": "0x15f8f202d13a8bf70566cc9d015331f2b7c4673ce7c0f3bd9274122143da98d7", "price_changes": [{"asset_id": "45368672532526393278374326096994364441839328602765138400884696484182735669678", "price": "0.756", "size": "0", "side": "BUY", "hash": "2318049b26bbf35d15aaa3cad30a112d7014d390", "best_bid": "0.757", "best_ask": "0.975"}, {"asset_id": "6003904135061936547790713762650160287283968685330714568260970794818630572545", "price": "0.244", "size": "0", "side": "SELL", "hash": "caf0f5841e8c026fd990df228853f5101b3528b0", "best_bid": "0.025", "best_ask": "0.243"}], "timestamp": "1769384622788", "event_type": "price_change"}}
{"_local_timestamp": "2026-01-25T23:43:42.900404+00:00", "data": {"market": "0x5d1e8a08b738d682ce49308c73f0a83ae192476cc9472cb82cc989e4d83a7e7f", "price_changes": [{"asset_id": "79115303304484490600349903081713351482280993232719554838261202179898129935846", "price": "0.721", "size": "0", "side": "BUY", "hash": "c49541567b2b274be6991d7369a8f48938ffb1e2", "best_bid": "0.722", "best_ask": "0.98"}, {"asset_id": "97425373542541244409279148168035803042084783523795409980290844728581925888286", "price": "0.279", "size": "0", "side": "SELL", "hash": "7fa3eaaffd4e5676566abe92f301909debe0b7ea", "best_bid": "0.02", "best_ask": "0.278"}], "timestamp": "1769384622788", "event_type": "price_change"}}
{"_local_timestamp": "2026-01-25T23:43:42.925726+00:00", "data": {"market": "0x15f8f202d13a8bf70566cc9d015331f2b7c4673ce7c0f3bd9274122143da98d7", "price_changes": [{"asset_id": "45368672532526393278374326096994364441839328602765138400884696484182735669678", "price": "0.681", "size": "20", "side": "BUY", "hash": "4111d33c2c9eac3169c87a33534737d4326b4c92", "best_bid": "0.757", "best_ask": "0.975"}, {"asset_id": "6003904135061936547790713762650160287283968685330714568260970794818630572545", "price": "0.319", "size": "20", "side": "SELL", "hash": "38ed42ce51c93efa02d53ad61124941066b5185b", "best_bid": "0.025", "best_ask": "0.243"}], "timestamp": "1769384622821", "event_type": "price_change"}}
{"_local_timestamp": "2026-01-25T23:43:42.926219+00:00", "data": {"market": "0x1e8287101399f3c9c1c135d82f7e53613a4ba421cab14fb7e6b2b1cf8bd83f30", "price_changes": [{"asset_id": "105266113555482874447692384740183990312049358997159118634356221057644647229583", "price": "0.688", "size": "20", "side": "BUY", "hash": "23084949982b40e5b1a8679287859b403f2260c6", "best_bid": "0.764", "best_ask": "0.98"}, {"asset_id": "73364483172319264394905719398750594214204555040619327864407649701603224821302", "price": "0.312", "size": "20", "side": "SELL", "hash": "d78229be8a82d9e2b3ce2a447ed53ac113451104", "best_bid": "0.02", "best_ask": "0.236"}], "timestamp": "1769384622822", "event_type": "price_change"}}
{"_local_timestamp": "2026-01-25T23:43:42.935127+00:00", "data": {"market": "0x5d1e8a08b738d682ce49308c73f0a83ae192476cc9472cb82cc989e4d83a7e7f", "price_changes": [{"asset_id": "79115303304484490600349903081713351482280993232719554838261202179898129935846", "price": "0.646", "size": "20", "side": "BUY", "hash": "d43c0621a13f8e3b1abfae5c0b3f61b2795ed6bd", "best_bid": "0.722", "best_ask": "0.98"}, {"asset_id": "97425373542541244409279148168035803042084783523795409980290844728581925888286", "price": "0.354", "size": "20", "side": "SELL", "hash": "4ccff528b48016a94484afd39671fd7df3643f76", "best_bid": "0.02", "best_ask": "0.278"}], "timestamp": "1769384622821", "event_type": "price_change"}}
{"_local_timestamp": "2026-01-25T23:43:44.225580+00:00", "data": {"market": "0x1e8287101399f3c9c1c135d82f7e53613a4ba421cab14fb7e6b2b1cf8bd83f30", "price_changes": [{"asset_id": "105266113555482874447692384740183990312049358997159118634356221057644647229583", "price": "0.688", "size": "0", "side": "BUY", "hash": "47aa82eeea0470ccad4984724937b1963b85843c", "best_bid": "0.764", "best_ask": "0.98"}, {"asset_id": "73364483172319264394905719398750594214204555040619327864407649701603224821302", "price": "0.312", "size": "0", "side": "SELL", "hash": "953120110b17e8e5f7b1a0c2a84459543fe5483e", "best_bid": "0.02", "best_ask": "0.236"}], "timestamp": "1769384624097", "event_type": "price_change"}}
{"_local_timestamp": "2026-01-25T23:43:44.226072+00:00", "data": {"market": "0x5d1e8a08b738d682ce49308c73f0a83ae192476cc9472cb82cc989e4d83a7e7f", "price_changes": [{"asset_id": "79115303304484490600349903081713351482280993232719554838261202179898129935846", "price": "0.646", "size": "0", "side": "BUY", "hash": "a97e0a96f87eee3c315aa89d2cc87944703ad8b5", "best_bid": "0.722", "best_ask": "0.98"}, {"asset_id": "97425373542541244409279148168035803042084783523795409980290844728581925888286", "price": "0.354", "size": "0", "side": "SELL", "hash": "327d10a6a5aa8e13b43f1b36f462c338b2501d44", "best_bid": "0.02", "best_ask": "0.278"}], "timestamp": "1769384624097", "event_type": "price_change"}}
{"_local_timestamp": "2026-01-25T23:43:44.227123+00:00", "data": {"market": "0x15f8f202d13a8bf70566cc9d015331f2b7c4673ce7c0f3bd9274122143da98d7", "price_changes": [{"asset_id": "45368672532526393278374326096994364441839328602765138400884696484182735669678", "price": "0.681", "size": "0", "side": "BUY", "hash": "13be7efe048759277844ced15c02b1f8582d5b34", "best_bid": "0.757", "best_ask": "0.975"}, {"asset_id": "6003904135061936547790713762650160287283968685330714568260970794818630572545", "price": "0.319", "size": "0", "side": "SELL", "hash": "b088dfde07b42ac6c5dc4b9d453cdeef6a06cec4", "best_bid": "0.025", "best_ask": "0.243"}], "timestamp": "1769384624097", "event_type": "price_change"}}
{"_local_timestamp": "2026-01-25T23:43:44.251050+00:00", "data": {"market": "0x5d1e8a08b738d682ce49308c73f0a83ae192476cc9472cb82cc989e4d83a7e7f", "price_changes": [{"asset_id": "79115303304484490600349903081713351482280993232719554838261202179898129935846", "price": "0.723", "size": "20", "side": "BUY", "hash": "d3445784d6d59905b903481d9c518f64fc8daa26", "best_bid": "0.723", "best_ask": "0.98"}, {"asset_id": "97425373542541244409279148168035803042084783523795409980290844728581925888286", "price": "0.277", "size": "20", "side": "SELL", "hash": "cb0b30ba0040e0b0f0331f121de33cb184472f46", "best_bid": "0.02", "best_ask": "0.277"}], "timestamp": "1769384624128", "event_type": "price_change"}}
{"_local_timestamp": "2026-01-25T23:43:44.251562+00:00", "data": {"market": "0x15f8f202d13a8bf70566cc9d015331f2b7c4673ce7c0f3bd9274122143da98d7", "price_changes": [{"asset_id": "45368672532526393278374326096994364441839328602765138400884696484182735669678", "price": "0.758", "size": "20", "side": "BUY", "hash": "847decf5838fb75b3b036fff2084ba31790bdcb5", "best_bid": "0.758", "best_ask": "0.975"}, {"asset_id": "6003904135061936547790713762650160287283968685330714568260970794818630572545", "price": "0.242", "size": "20", "side": "SELL", "hash": "63198e6948f8ddc458e888aa5f2bf8116c8726fd", "best_bid": "0.025", "best_ask": "0.242"}], "timestamp": "1769384624128", "event_type": "price_change"}}
{"_local_timestamp": "2026-01-25T23:43:44.252032+00:00", "data": {"market": "0x1e8287101399f3c9c1c135d82f7e53613a4ba421cab14fb7e6b2b1cf8bd83f30", "price_changes": [{"asset_id": "105266113555482874447692384740183990312049358997159118634356221057644647229583", "price": "0.765", "size": "20", "side": "BUY", "hash": "2c4828f1cbd9c09a8f00a21016b26e25a10228a1", "best_bid": "0.765", "best_ask": "0.98"}, {"asset_id": "73364483172319264394905719398750594214204555040619327864407649701603224821302", "price": "0.235", "size": "20", "side": "SELL", "hash": "3079c4c41af84c75bd610e53ed534f59ae688e87", "best_bid": "0.02", "best_ask": "0.235"}], "timestamp": "1769384624128", "event_type": "price_change"}}
{"_local_timestamp": "2026-01-25T23:44:31.749669+00:00", "data": {"market": "0x65bbe9ee978b2e7f99596407bd92599db3600cbd19e0ef6cba303553c5cd3b84", "price_changes": [{"asset_id": "40553687028357385570012767684841134153932705410424731659907218042194272368471", "price": "0.19", "size": "0", "side": "BUY", "hash": "40f6d4f7125715f929db299bf890b351738571e1", "best_bid": "0.6", "best_ask": "0.67"}, {"asset_id": "71827396998946924240056437519949087820352588387051888811942886136688189882272", "price": "0.81", "size": "0", "side": "SELL", "hash": "34be8677a50fbf3a6f41cb6b9d457daae0ba05ff", "best_bid": "0.33", "best_ask": "0.4"}], "timestamp": "1769384671686", "event_type": "price_change"}}
{"_local_timestamp": "2026-01-25T23:44:31.836022+00:00", "data": {"market": "0x65bbe9ee978b2e7f99596407bd92599db3600cbd19e0ef6cba303553c5cd3b84", "price_changes": [{"asset_id": "40553687028357385570012767684841134153932705410424731659907218042194272368471", "price": "0.19", "size": "10", "side": "BUY", "hash": "7a7248159aa18f41b1e86d13cc6e66acfdd77d81", "best_bid": "0.6", "best_ask": "0.67"}, {"asset_id": "71827396998946924240056437519949087820352588387051888811942886136688189882272", "price": "0.81", "size": "10", "side": "SELL", "hash": "0b936fdec60022dee63e4d3e1cb248fc53d602b3", "best_bid": "0.33", "best_ask": "0.4"}], "timestamp": "1769384671733", "event_type": "price_change"}}
{"_local_timestamp": "2026-01-25T23:45:09.386630+00:00", "data": {"market": "0xf7c252ad31286ada89db99be13597440c560902399c76c38467fa86b0afafc38", "price_changes": [{"asset_id": "102124581147878849417013974949016966040760828086139587269608936045361043639164", "price": "0.166", "size": "0", "side": "BUY", "hash": "6f948469b21544a955b96fd3b08eb9fee8c2a021", "best_bid": "0.973", "best_ask": "0.99"}, {"asset_id": "32637491402862397548368511721034037439318650587574930074931384532496135682625", "price": "0.834", "size": "0", "side": "SELL", "hash": "a25fcaa7e2b47a95f5106528439b778cc15bda77", "best_bid": "0.01", "best_ask": "0.027"}], "timestamp": "1769384709317", "event_type": "price_change"}}
{"_local_timestamp": "2026-01-25T23:45:09.428394+00:00", "data": {"market": "0xf7c252ad31286ada89db99be13597440c560902399c76c38467fa86b0afafc38", "price_changes": [{"asset_id": "102124581147878849417013974949016966040760828086139587269608936045361043639164", "price": "0.166", "size": "12", "side": "BUY", "hash": "33adfcdc6be7b31524f66697c2f4e440c027c9ec", "best_bid": "0.973", "best_ask": "0.99"}, {"asset_id": "32637491402862397548368511721034037439318650587574930074931384532496135682625", "price": "0.834", "size": "12", "side": "SELL", "hash": "39ad9084f800c6f8e42992023936de24c6e56de8", "best_bid": "0.01", "best_ask": "0.027"}], "timestamp": "1769384709362", "event_type": "price_change"}}
{"_local_timestamp": "2026-01-25T23:45:18.815911+00:00", "data": {"market": "0x5d1e8a08b738d682ce49308c73f0a83ae192476cc9472cb82cc989e4d83a7e7f", "price_changes": [{"asset_id": "97425373542541244409279148168035803042084783523795409980290844728581925888286", "price": "0.278", "size": "0", "side": "SELL", "hash": "1bc33bc84f0c64ce45d570c3de241bbb08e39a5e", "best_bid": "0.02", "best_ask": "0.277"}, {"asset_id": "79115303304484490600349903081713351482280993232719554838261202179898129935846", "price": "0.722", "size": "0", "side": "BUY", "hash": "107eb26b8ad2c41f6c034dd6c6462e08ee54103c", "best_bid": "0.723", "best_ask": "0.98"}], "timestamp": "1769384718748", "event_type": "price_change"}}
{"_local_timestamp": "2026-01-25T23:45:18.944407+00:00", "data": {"market": "0x1e8287101399f3c9c1c135d82f7e53613a4ba421cab14fb7e6b2b1cf8bd83f30", "price_changes": [{"asset_id": "73364483172319264394905719398750594214204555040619327864407649701603224821302", "price": "0.236", "size": "0", "side": "SELL", "hash": "351b9a46488c18942958f2283f9f7b8e5e2a0465", "best_bid": "0.02", "best_ask": "0.235"}, {"asset_id": "105266113555482874447692384740183990312049358997159118634356221057644647229583", "price": "0.764", "size": "0", "side": "BUY", "hash": "342a7c02d9f840a458ab25d6f3ce7df532c1f824", "best_bid": "0.765", "best_ask": "0.98"}], "timestamp": "1769384718847", "event_type": "price_change"}}
{"_local_timestamp": "2026-01-25T23:45:18.945100+00:00", "data": {"market": "0x15f8f202d13a8bf70566cc9d015331f2b7c4673ce7c0f3bd9274122143da98d7", "price_changes": [{"asset_id": "6003904135061936547790713762650160287283968685330714568260970794818630572545", "price": "0.243", "size": "0", "side": "SELL", "hash": "2139d0a9c99dc024216b0e5b25a2d4a6258d2a69", "best_bid": "0.025", "best_ask": "0.242"}, {"asset_id": "45368672532526393278374326096994364441839328602765138400884696484182735669678", "price": "0.757", "size": "0", "side": "BUY", "hash": "0d45ebd337d83dbcc2678f594f3ab564ad0aaa7c", "best_bid": "0.758", "best_ask": "0.975"}], "timestamp": "1769384718847", "event_type": "price_change"}}
{"_local_timestamp": "2026-01-25T23:45:19.810811+00:00", "data": {"market": "0x5d1e8a08b738d682ce49308c73f0a83ae192476cc9472cb82cc989e4d83a7e7f", "price_changes": [{"asset_id": "97425373542541244409279148168035803042084783523795409980290844728581925888286", "price": "0.276", "size": "20.62", "side": "SELL", "hash": "8fb2cb912539cebfc27ee48508a4c7a6d9e496f0", "best_bid": "0.02", "best_ask": "0.276"}, {"asset_id": "79115303304484490600349903081713351482280993232719554838261202179898129935846", "price": "0.724", "size": "20.62", "side": "BUY", "hash": "756969522e167c95658dcb92143dbb5af54840e9", "best_bid": "0.724", "best_ask": "0.98"}], "timestamp": "1769384719739", "event_type": "price_change"}}
{"_local_timestamp": "2026-01-25T23:45:19.901378+00:00", "data": {"market": "0x15f8f202d13a8bf70566cc9d015331f2b7c4673ce7c0f3bd9274122143da98d7", "price_changes": [{"asset_id": "6003904135061936547790713762650160287283968685330714568260970794818630572545", "price": "0.241", "size": "20", "side": "SELL", "hash": "9f0b9c543a5c7fc26a0cca600d92d697cd5885f9", "best_bid": "0.025", "best_ask": "0.241"}, {"asset_id": "45368672532526393278374326096994364441839328602765138400884696484182735669678", "price": "0.759", "size": "20", "side": "BUY", "hash": "4c487560c6862d2ed2fb848ff6bac02baae6b144", "best_bid": "0.759", "best_ask": "0.975"}], "timestamp": "1769384719835", "event_type": "price_change"}}
{"_local_timestamp": "2026-01-25T23:45:19.901826+00:00", "data": {"market": "0x1e8287101399f3c9c1c135d82f7e53613a4ba421cab14fb7e6b2b1cf8bd83f30", "price_changes": [{"asset_id": "73364483172319264394905719398750594214204555040619327864407649701603224821302", "price": "0.234", "size": "20", "side": "SELL", "hash": "b0d2f3f77c62be74b15c9a94fa4c5e968c800b7f", "best_bid": "0.02", "best_ask": "0.234"}, {"asset_id": "105266113555482874447692384740183990312049358997159118634356221057644647229583", "price": "0.766", "size": "20", "side": "BUY", "hash": "576e554a6f676e8332b49f7bf21e390bf7427aa2", "best_bid": "0.766", "best_ask": "0.98"}], "timestamp": "1769384719835", "event_type": "price_change"}}
{"_local_timestamp": "2026-01-25T23:45:20.722577+00:00", "data": {"market": "0x1e8287101399f3c9c1c135d82f7e53613a4ba421cab14fb7e6b2b1cf8bd83f30", "price_changes": [{"asset_id": "105266113555482874447692384740183990312049358997159118634356221057644647229583", "price": "0.765", "size": "0", "side": "BUY", "hash": "0a838d1b0bce866273f04c11f0397e5ad90c6651", "best_bid": "0.766", "best_ask": "0.98"}, {"asset_id": "73364483172319264394905719398750594214204555040619327864407649701603224821302", "price": "0.235", "size": "0", "side": "SELL", "hash": "772a4459dd9609f0bd2ab317e6ecd9dfd3155abf", "best_bid": "0.02", "best_ask": "0.234"}], "timestamp": "1769384720653", "event_type": "price_change"}}
{"_local_timestamp": "2026-01-25T23:45:20.723052+00:00", "data": {"market": "0x15f8f202d13a8bf70566cc9d015331f2b7c4673ce7c0f3bd9274122143da98d7", "price_changes": [{"asset_id": "45368672532526393278374326096994364441839328602765138400884696484182735669678", "price": "0.758", "size": "0", "side": "BUY", "hash": "9435b6ac34812e3addffee0bf19fc0d587c7a68d", "best_bid": "0.759", "best_ask": "0.975"}, {"asset_id": "6003904135061936547790713762650160287283968685330714568260970794818630572545", "price": "0.242", "size": "0", "side": "SELL", "hash": "dfd76f0a88053912725e782eb4eefb3263260d3c", "best_bid": "0.025", "best_ask": "0.241"}], "timestamp": "1769384720653", "event_type": "price_change"}}
{"_local_timestamp": "2026-01-25T23:45:20.723465+00:00", "data": {"market": "0x5d1e8a08b738d682ce49308c73f0a83ae192476cc9472cb82cc989e4d83a7e7f", "price_changes": [{"asset_id": "79115303304484490600349903081713351482280993232719554838261202179898129935846", "price": "0.723", "size": "0", "side": "BUY", "hash": "6d0c60d4585d208e3626711dc2da1694aeed2c3f", "best_bid": "0.724", "best_ask": "0.98"}, {"asset_id": "97425373542541244409279148168035803042084783523795409980290844728581925888286", "price": "0.277", "size": "0", "side": "SELL", "hash": "5cedaa8cc7ecdfaef4529f57d65d0444e992ba09", "best_bid": "0.02", "best_ask": "0.276"}], "timestamp": "1769384720653", "event_type": "price_change"}}
{"_local_timestamp": "2026-01-25T23:45:20.762678+00:00", "data": {"market": "0x5d1e8a08b738d682ce49308c73f0a83ae192476cc9472cb82cc989e4d83a7e7f", "price_changes": [{"asset_id": "79115303304484490600349903081713351482280993232719554838261202179898129935846", "price": "0.725", "size": "20", "side": "BUY", "hash": "2c8ac1cb59e0d80aced52594c5a0265daaf3b7b1", "best_bid": "0.725", "best_ask": "0.98"}, {"asset_id": "97425373542541244409279148168035803042084783523795409980290844728581925888286", "price": "0.275", "size": "20", "side": "SELL", "hash": "539169aa401c30b86f975f52eb71d95ab0fb0051", "best_bid": "0.02", "best_ask": "0.275"}], "timestamp": "1769384720694", "event_type": "price_change"}}
{"_local_timestamp": "2026-01-25T23:45:20.763483+00:00", "data": {"market": "0x1e8287101399f3c9c1c135d82f7e53613a4ba421cab14fb7e6b2b1cf8bd83f30", "price_changes": [{"asset_id": "105266113555482874447692384740183990312049358997159118634356221057644647229583", "price": "0.767", "size": "20", "side": "BUY", "hash": "16df6a05f263a145590a3475e1c19a7d32b5e954", "best_bid": "0.767", "best_ask": "0.98"}, {"asset_id": "73364483172319264394905719398750594214204555040619327864407649701603224821302", "price": "0.233", "size": "20", "side": "SELL", "hash": "6ba779cfb6af1ca67d43f36566047898ee1c70cd", "best_bid": "0.02", "best_ask": "0.233"}], "timestamp": "1769384720694", "event_type": "price_change"}}
{"_local_timestamp": "2026-01-25T23:45:20.763973+00:00", "data": {"market": "0x15f8f202d13a8bf70566cc9d015331f2b7c4673ce7c0f3bd9274122143da98d7", "price_changes": [{"asset_id": "45368672532526393278374326096994364441839328602765138400884696484182735669678", "price": "0.76", "size": "20", "side": "BUY", "hash": "9b883e4439c9f4d2e7ebb61f8acdd02e5b1dfc60", "best_bid": "0.76", "best_ask": "0.975"}, {"asset_id": "6003904135061936547790713762650160287283968685330714568260970794818630572545", "price": "0.24", "size": "20", "side": "SELL", "hash": "fbedac9a006db47a26db25fce1b83611481ed477", "best_bid": "0.025", "best_ask": "0.24"}], "timestamp": "1769384720694", "event_type": "price_change"}}
{"_local_timestamp": "2026-01-25T23:46:22.593235+00:00", "data": {"market": "0x0f68c3a9e26d4c35f15fd26f9a6a049b2f1407261ad8981b98977a8afa9d087b", "price_changes": [{"asset_id": "61240240600582938454064457548680517512785777298126011321396572901104696106643", "price": "0.502", "size": "0", "side": "BUY", "hash": "ca5e2811db9a179353ce50c898f0a2223282bac6", "best_bid": "0.972", "best_ask": "0.99"}, {"asset_id": "1461054050624993235896212005078254719114110436454300529113204898615019158205", "price": "0.498", "size": "0", "side": "SELL", "hash": "9a48f26c6856641854f77f25f5625be915f33a29", "best_bid": "0.01", "best_ask": "0.028"}], "timestamp": "1769384782527", "event_type": "price_change"}}
{"_local_timestamp": "2026-01-25T23:46:22.653403+00:00", "data": {"market": "0x0f68c3a9e26d4c35f15fd26f9a6a049b2f1407261ad8981b98977a8afa9d087b", "price_changes": [{"asset_id": "61240240600582938454064457548680517512785777298126011321396572901104696106643", "price": "0.502", "size": "5", "side": "BUY", "hash": "a0beb400d7acce8e855db055548add23dae38dee", "best_bid": "0.972", "best_ask": "0.99"}, {"asset_id": "1461054050624993235896212005078254719114110436454300529113204898615019158205", "price": "0.498", "size": "5", "side": "SELL", "hash": "bc79f5319d41d5aef37cc5d9b09a36affe968b01", "best_bid": "0.01", "best_ask": "0.028"}], "timestamp": "1769384782584", "event_type": "price_change"}}
{"_local_timestamp": "2026-01-25T23:46:55.580353+00:00", "data": {"market": "0x5d1e8a08b738d682ce49308c73f0a83ae192476cc9472cb82cc989e4d83a7e7f", "price_changes": [{"asset_id": "97425373542541244409279148168035803042084783523795409980290844728581925888286", "price": "0.276", "size": "0", "side": "SELL", "hash": "e45949fb0da648ee4d6191ff6f61566d57521d31", "best_bid": "0.02", "best_ask": "0.275"}, {"asset_id": "79115303304484490600349903081713351482280993232719554838261202179898129935846", "price": "0.724", "size": "0", "side": "BUY", "hash": "04b2020850a40159478bec96a294ac45adeea84d", "best_bid": "0.725", "best_ask": "0.98"}], "timestamp": "1769384815508", "event_type": "price_change"}}
{"_local_timestamp": "2026-01-25T23:46:55.581310+00:00", "data": {"market": "0x15f8f202d13a8bf70566cc9d015331f2b7c4673ce7c0f3bd9274122143da98d7", "price_changes": [{"asset_id": "6003904135061936547790713762650160287283968685330714568260970794818630572545", "price": "0.241", "size": "0", "side": "SELL", "hash": "dafe87109fc3443bab90bc9df28337c2eee626d9", "best_bid": "0.025", "best_ask": "0.24"}, {"asset_id": "45368672532526393278374326096994364441839328602765138400884696484182735669678", "price": "0.759", "size": "0", "side": "BUY", "hash": "1bfa82d14a5dfe866f00904e529baf11bfb8747c", "best_bid": "0.76", "best_ask": "0.975"}], "timestamp": "1769384815508", "event_type": "price_change"}}
{"_local_timestamp": "2026-01-25T23:46:55.670930+00:00", "data": {"market": "0x1e8287101399f3c9c1c135d82f7e53613a4ba421cab14fb7e6b2b1cf8bd83f30", "price_changes": [{"asset_id": "73364483172319264394905719398750594214204555040619327864407649701603224821302", "price": "0.234", "size": "0", "side": "SELL", "hash": "3b035241f5291beab62d34eae11decc7c8463fe2", "best_bid": "0.02", "best_ask": "0.233"}, {"asset_id": "105266113555482874447692384740183990312049358997159118634356221057644647229583", "price": "0.766", "size": "0", "side": "BUY", "hash": "0965fb62b7be93c2f3a36f7433524b714e8f9a7b", "best_bid": "0.767", "best_ask": "0.98"}], "timestamp": "1769384815605", "event_type": "price_change"}}
{"_local_timestamp": "2026-01-25T23:46:56.487099+00:00", "data": {"market": "0x15f8f202d13a8bf70566cc9d015331f2b7c4673ce7c0f3bd9274122143da98d7", "price_changes": [{"asset_id": "6003904135061936547790713762650160287283968685330714568260970794818630572545", "price": "0.239", "size": "20", "side": "SELL", "hash": "7b4904b56b908959b0740d0231ee5a0ffd4b9e6b", "best_bid": "0.025", "best_ask": "0.239"}, {"asset_id": "45368672532526393278374326096994364441839328602765138400884696484182735669678", "price": "0.761", "size": "20", "side": "BUY", "hash": "960a0312aca4d40bfceb0af75a907aa4f63d231c", "best_bid": "0.761", "best_ask": "0.975"}], "timestamp": "1769384816414", "event_type": "price_change"}}
{"_local_timestamp": "2026-01-25T23:46:56.487612+00:00", "data": {"market": "0x5d1e8a08b738d682ce49308c73f0a83ae192476cc9472cb82cc989e4d83a7e7f", "price_changes": [{"asset_id": "97425373542541244409279148168035803042084783523795409980290844728581925888286", "price": "0.274", "size": "20.62", "side": "SELL", "hash": "cea99344cc528ce75670f14f95156e6761fc89b8", "best_bid": "0.02", "best_ask": "0.274"}, {"asset_id": "79115303304484490600349903081713351482280993232719554838261202179898129935846", "price": "0.726", "size": "20.62", "side": "BUY", "hash": "5920992440eb882818c85d4467c78fdc559dbd41", "best_bid": "0.726", "best_ask": "0.98"}], "timestamp": "1769384816414", "event_type": "price_change"}}
{"_local_timestamp": "2026-01-25T23:46:56.586676+00:00", "data": {"market": "0x1e8287101399f3c9c1c135d82f7e53613a4ba421cab14fb7e6b2b1cf8bd83f30", "price_changes": [{"asset_id": "73364483172319264394905719398750594214204555040619327864407649701603224821302", "price": "0.232", "size": "20", "side": "SELL", "hash": "1061460815f7ad78c2800d0eae05979265c2a0cf", "best_bid": "0.02", "best_ask": "0.232"}, {"asset_id": "105266113555482874447692384740183990312049358997159118634356221057644647229583", "price": "0.768", "size": "20", "side": "BUY", "hash": "43a2a9a7ec4cf2c9ae70ccffcd8ff9e7224a76a8", "best_bid": "0.768", "best_ask": "0.98"}], "timestamp": "1769384816515", "event_type": "price_change"}}
{"_local_timestamp": "2026-01-25T23:46:59.075579+00:00", "data": {"market": "0x1e8287101399f3c9c1c135d82f7e53613a4ba421cab14fb7e6b2b1cf8bd83f30", "price_changes": [{"asset_id": "105266113555482874447692384740183990312049358997159118634356221057644647229583", "price": "0.767", "size": "0", "side": "BUY", "hash": "3250cfe3a6c5f810f16c5c4abd36a8ff675ba1c1", "best_bid": "0.768", "best_ask": "0.98"}, {"asset_id": "73364483172319264394905719398750594214204555040619327864407649701603224821302", "price": "0.233", "size": "0", "side": "SELL", "hash": "f19619d841c6934a2b40a0d5fd06e9d8e119899b", "best_bid": "0.02", "best_ask": "0.232"}], "timestamp": "1769384818993", "event_type": "price_change"}}
{"_local_timestamp": "2026-01-25T23:46:59.076172+00:00", "data": {"market": "0x15f8f202d13a8bf70566cc9d015331f2b7c4673ce7c0f3bd9274122143da98d7", "price_changes": [{"asset_id": "45368672532526393278374326096994364441839328602765138400884696484182735669678", "price": "0.76", "size": "0", "side": "BUY", "hash": "f82ff7eafb59d42194fe4f286e2405fce989d9b4", "best_bid": "0.761", "best_ask": "0.975"}, {"asset_id": "6003904135061936547790713762650160287283968685330714568260970794818630572545", "price": "0.24", "size": "0", "side": "SELL", "hash": "58c89485d0a38ec2030d540d3cf2d5df18778ebb", "best_bid": "0.025", "best_ask": "0.239"}], "timestamp": "1769384818993", "event_type": "price_change"}}
{"_local_timestamp": "2026-01-25T23:46:59.076673+00:00", "data": {"market": "0x5d1e8a08b738d682ce49308c73f0a83ae192476cc9472cb82cc989e4d83a7e7f", "price_changes": [{"asset_id": "79115303304484490600349903081713351482280993232719554838261202179898129935846", "price": "0.725", "size": "0", "side": "BUY", "hash": "860c916595facbd406ad5d29772f0e1fb8b1dfda", "best_bid": "0.726", "best_ask": "0.98"}, {"asset_id": "97425373542541244409279148168035803042084783523795409980290844728581925888286", "price": "0.275", "size": "0", "side": "SELL", "hash": "67b449d40502521c4fafbbff9fd409528f0b7623", "best_bid": "0.02", "best_ask": "0.274"}], "timestamp": "1769384818993", "event_type": "price_change"}}
{"_local_timestamp": "2026-01-25T23:46:59.115260+00:00", "data": {"market": "0x5d1e8a08b738d682ce49308c73f0a83ae192476cc9472cb82cc989e4d83a7e7f", "price_changes": [{"asset_id": "79115303304484490600349903081713351482280993232719554838261202179898129935846", "price": "0.727", "size": "20", "side": "BUY", "hash": "1a7a1140e5ad9d8941fb6285cb5f4852fc04dd8e", "best_bid": "0.727", "best_ask": "0.98"}, {"asset_id": "97425373542541244409279148168035803042084783523795409980290844728581925888286", "price": "0.273", "size": "20", "side": "SELL", "hash": "025491aafd12bcc33850bb9d5289dfbb64724b65", "best_bid": "0.02", "best_ask": "0.273"}], "timestamp": "1769384819029", "event_type": "price_change"}}
{"_local_timestamp": "2026-01-25T23:46:59.124843+00:00", "data": {"market": "0x15f8f202d13a8bf70566cc9d015331f2b7c4673ce7c0f3bd9274122143da98d7", "price_changes": [{"asset_id": "45368672532526393278374326096994364441839328602765138400884696484182735669678", "price": "0.762", "size": "20", "side": "BUY", "hash": "7aaa7626e622ec4166f0c99aa09f2c2fe7c9a854", "best_bid": "0.762", "best_ask": "0.975"}, {"asset_id": "6003904135061936547790713762650160287283968685330714568260970794818630572545", "price": "0.238", "size": "20", "side": "SELL", "hash": "a688f0faea1914eeecc3499cf09cf848fc28d16d", "best_bid": "0.025", "best_ask": "0.238"}], "timestamp": "1769384819030", "event_type": "price_change"}}
{"_local_timestamp": "2026-01-25T23:46:59.125418+00:00", "data": {"market": "0x1e8287101399f3c9c1c135d82f7e53613a4ba421cab14fb7e6b2b1cf8bd83f30", "price_changes": [{"asset_id": "105266113555482874447692384740183990312049358997159118634356221057644647229583", "price": "0.769", "size": "20", "side": "BUY", "hash": "24bef7a622fc695a6f39353308820ff8f3cd82b8", "best_bid": "0.769", "best_ask": "0.98"}, {"asset_id": "73364483172319264394905719398750594214204555040619327864407649701603224821302", "price": "0.231", "size": "20", "side": "SELL", "hash": "24be390572d0435781747566c338467a5c6b7d53", "best_bid": "0.02", "best_ask": "0.231"}], "timestamp": "1769384819031", "event_type": "price_change"}}
{"_local_timestamp": "2026-01-25T23:47:56.108753+00:00", "data": {"market": "0x1e8287101399f3c9c1c135d82f7e53613a4ba421cab14fb7e6b2b1cf8bd83f30", "price_changes": [{"asset_id": "105266113555482874447692384740183990312049358997159118634356221057644647229583", "price": "0.77", "size": "21", "side": "BUY", "hash": "89f6561bfb8b03d5347324dd3bf15aaa6eea3b69", "best_bid": "0.77", "best_ask": "0.98"}, {"asset_id": "73364483172319264394905719398750594214204555040619327864407649701603224821302", "price": "0.23", "size": "21", "side": "SELL", "hash": "b53d441f339eb6906670aec5c9f9a1f722b2c74f", "best_bid": "0.02", "best_ask": "0.23"}], "timestamp": "1769384875953", "event_type": "price_change"}}
{"_local_timestamp": "2026-01-25T23:47:56.109534+00:00", "data": {"market": "0x39b718f6e0a66a3ae5e459e76c74a694b521eaff5f6015857d1d191f1fc03c61", "price_changes": [{"asset_id": "55794910131918732608143325808731608350538323781799534833013667918954993794053", "price": "0.79", "size": "21", "side": "BUY", "hash": "64f50779673fdd29e176628d13df1aaf845cd2e5", "best_bid": "0.79", "best_ask": "0.98"}, {"asset_id": "10458098669927883185204828453571065550874636694709643726889899346674533724103", "price": "0.21", "size": "21", "side": "SELL", "hash": "14dc2ba577ee51dbd2b16e24c7bd21d3d6ae80a7", "best_bid": "0.02", "best_ask": "0.21"}], "timestamp": "1769384875953", "event_type": "price_change"}}
{"_local_timestamp": "2026-01-25T23:47:56.109994+00:00", "data": {"market": "0x5d1e8a08b738d682ce49308c73f0a83ae192476cc9472cb82cc989e4d83a7e7f", "price_changes": [{"asset_id": "79115303304484490600349903081713351482280993232719554838261202179898129935846", "price": "0.728", "size": "21", "side": "BUY", "hash": "ea552fac736f130fe1c92bec0dc51f880336464b", "best_bid": "0.728", "best_ask": "0.98"}, {"asset_id": "97425373542541244409279148168035803042084783523795409980290844728581925888286", "price": "0.272", "size": "21", "side": "SELL", "hash": "4547e964d991b44497332ddff3de6197cd9fe57b", "best_bid": "0.02", "best_ask": "0.272"}], "timestamp": "1769384875953", "event_type": "price_change"}}
{"_local_timestamp": "2026-01-25T23:47:56.110443+00:00", "data": {"market": "0x15f8f202d13a8bf70566cc9d015331f2b7c4673ce7c0f3bd9274122143da98d7", "price_changes": [{"asset_id": "45368672532526393278374326096994364441839328602765138400884696484182735669678", "price": "0.763", "size": "21", "side": "BUY", "hash": "48dac0cf01b4c24259276f3abcde04ca3d89ea1e", "best_bid": "0.763", "best_ask": "0.975"}, {"asset_id": "6003904135061936547790713762650160287283968685330714568260970794818630572545", "price": "0.237", "size": "21", "side": "SELL", "hash": "166e5b9953ff0fe961f5e54944e5c4cc32529c79", "best_bid": "0.025", "best_ask": "0.237"}], "timestamp": "1769384875953", "event_type": "price_change"}}
{"_local_timestamp": "2026-01-25T23:47:56.521679+00:00", "data": {"market": "0x15f8f202d13a8bf70566cc9d015331f2b7c4673ce7c0f3bd9274122143da98d7", "price_changes": [{"asset_id": "45368672532526393278374326096994364441839328602765138400884696484182735669678", "price": "0.762", "size": "0", "side": "BUY", "hash": "8e2bdc3778a1f02166c7ae3c25e6940b0dfface1", "best_bid": "0.763", "best_ask": "0.975"}, {"asset_id": "6003904135061936547790713762650160287283968685330714568260970794818630572545", "price": "0.238", "size": "0", "side": "SELL", "hash": "f46a919eb1a24bf0a142ae6cfc343d3601302558", "best_bid": "0.025", "best_ask": "0.237"}], "timestamp": "1769384876359", "event_type": "price_change"}}
{"_local_timestamp": "2026-01-25T23:47:56.522229+00:00", "data": {"market": "0x1e8287101399f3c9c1c135d82f7e53613a4ba421cab14fb7e6b2b1cf8bd83f30", "price_changes": [{"asset_id": "105266113555482874447692384740183990312049358997159118634356221057644647229583", "price": "0.769", "size": "0", "side": "BUY", "hash": "719472ad2db6eb64db4c6f273f1abf6112c5b388", "best_bid": "0.77", "best_ask": "0.98"}, {"asset_id": "73364483172319264394905719398750594214204555040619327864407649701603224821302", "price": "0.231", "size": "0", "side": "SELL", "hash": "a2a0f34f35f6d1f25739bb822e88d72cf19d00db", "best_bid": "0.02", "best_ask": "0.23"}], "timestamp": "1769384876359", "event_type": "price_change"}}
{"_local_timestamp": "2026-01-25T23:47:56.522743+00:00", "data": {"market": "0x5d1e8a08b738d682ce49308c73f0a83ae192476cc9472cb82cc989e4d83a7e7f", "price_changes": [{"asset_id": "79115303304484490600349903081713351482280993232719554838261202179898129935846", "price": "0.727", "size": "0", "side": "BUY", "hash": "58d1eead790f874fb8cf230ee6f934a336e86a5f", "best_bid": "0.728", "best_ask": "0.98"}, {"asset_id": "97425373542541244409279148168035803042084783523795409980290844728581925888286", "price": "0.273", "size": "0", "side": "SELL", "hash": "534255580d3fe9f8e5050f0d4e37a5eded6ab839", "best_bid": "0.02", "best_ask": "0.272"}], "timestamp": "1769384876359", "event_type": "price_change"}}
{"_local_timestamp": "2026-01-25T23:47:56.545693+00:00", "data": {"market": "0x5d1e8a08b738d682ce49308c73f0a83ae192476cc9472cb82cc989e4d83a7e7f", "price_changes": [{"asset_id": "79115303304484490600349903081713351482280993232719554838261202179898129935846", "price": "0.729", "size": "20", "side": "BUY", "hash": "63df69fda2b5a04cc9ea50a3a54b3f839c24a41e", "best_bid": "0.729", "best_ask": "0.98"}, {"asset_id": "97425373542541244409279148168035803042084783523795409980290844728581925888286", "price": "0.271", "size": "20", "side": "SELL", "hash": "23a2b0e717a6540bd5e14fe66c45c4ebf7442e9d", "best_bid": "0.02", "best_ask": "0.271"}], "timestamp": "1769384876388", "event_type": "price_change"}}
{"_local_timestamp": "2026-01-25T23:47:56.546270+00:00", "data": {"market": "0x15f8f202d13a8bf70566cc9d015331f2b7c4673ce7c0f3bd9274122143da98d7", "price_changes": [{"asset_id": "45368672532526393278374326096994364441839328602765138400884696484182735669678", "price": "0.764", "size": "20", "side": "BUY", "hash": "f55def04d025beda907b09475192cdff7e847651", "best_bid": "0.764", "best_ask": "0.975"}, {"asset_id": "6003904135061936547790713762650160287283968685330714568260970794818630572545", "price": "0.236", "size": "20", "side": "SELL", "hash": "86842996879be8c1b33526e98e040eb64c44241d", "best_bid": "0.025", "best_ask": "0.236"}], "timestamp": "1769384876388", "event_type": "price_change"}}
{"_local_timestamp": "2026-01-25T23:47:56.553426+00:00", "data": {"market": "0x1e8287101399f3c9c1c135d82f7e53613a4ba421cab14fb7e6b2b1cf8bd83f30", "price_changes": [{"asset_id": "105266113555482874447692384740183990312049358997159118634356221057644647229583", "price": "0.771", "size": "20", "side": "BUY", "hash": "c389a6505db22104d0c249492f40eccf92f14cd3", "best_bid": "0.771", "best_ask": "0.98"}, {"asset_id": "73364483172319264394905719398750594214204555040619327864407649701603224821302", "price": "0.229", "size": "20", "side": "SELL", "hash": "5055394e94460c0027014779d4e436258f570b52", "best_bid": "0.02", "best_ask": "0.229"}], "timestamp": "1769384876388", "event_type": "price_change"}}
{"_local_timestamp": "2026-01-25T23:48:18.406149+00:00", "data": {"market": "0x15f8f202d13a8bf70566cc9d015331f2b7c4673ce7c0f3bd9274122143da98d7", "price_changes": [{"asset_id": "45368672532526393278374326096994364441839328602765138400884696484182735669678", "price": "0.763", "size": "0", "side": "BUY", "hash": "0a856ed35ef1d3e7b854410a45fed86dc378c594", "best_bid": "0.764", "best_ask": "0.975"}, {"asset_id": "6003904135061936547790713762650160287283968685330714568260970794818630572545", "price": "0.237", "size": "0", "side": "SELL", "hash": "240d2248f691f939b3f61663f9407b41d58d2bff", "best_bid": "0.025", "best_ask": "0.236"}], "timestamp": "1769384898136", "event_type": "price_change"}}
{"_local_timestamp": "2026-01-25T23:48:18.407319+00:00", "data": {"market": "0x1e8287101399f3c9c1c135d82f7e53613a4ba421cab14fb7e6b2b1cf8bd83f30", "price_changes": [{"asset_id": "105266113555482874447692384740183990312049358997159118634356221057644647229583", "price": "0.77", "size": "0", "side": "BUY", "hash": "92668c83c419b626d81d738a3a16253eb5459503", "best_bid": "0.771", "best_ask": "0.98"}, {"asset_id": "73364483172319264394905719398750594214204555040619327864407649701603224821302", "price": "0.23", "size": "0", "side": "SELL", "hash": "3fd018a476250c396c602fc1b87fa7e76a12f479", "best_bid": "0.02", "best_ask": "0.229"}], "timestamp": "1769384898136", "event_type": "price_change"}}
{"_local_timestamp": "2026-01-25T23:48:18.407836+00:00", "data": {"market": "0x5d1e8a08b738d682ce49308c73f0a83ae192476cc9472cb82cc989e4d83a7e7f", "price_changes": [{"asset_id": "79115303304484490600349903081713351482280993232719554838261202179898129935846", "price": "0.728", "size": "0", "side": "BUY", "hash": "d318f064ce1d1948db8492aabb9458925559bb17", "best_bid": "0.729", "best_ask": "0.98"}, {"asset_id": "97425373542541244409279148168035803042084783523795409980290844728581925888286", "price": "0.272", "size": "0", "side": "SELL", "hash": "1e501db7ff9032aa25b1c27a04f0a54c94c90839", "best_bid": "0.02", "best_ask": "0.271"}], "timestamp": "1769384898136", "event_type": "price_change"}}
{"_local_timestamp": "2026-01-25T23:48:24.833684+00:00", "data": {"market": "0x39b718f6e0a66a3ae5e459e76c74a694b521eaff5f6015857d1d191f1fc03c61", "price_changes": [{"asset_id": "10458098669927883185204828453571065550874636694709643726889899346674533724103", "price": "0.22", "size": "0", "side": "SELL", "hash": "2a7c9d29baa356a7ef5f6e12d9ae52a479f8bf3a", "best_bid": "0.02", "best_ask": "0.21"}, {"asset_id": "55794910131918732608143325808731608350538323781799534833013667918954993794053", "price": "0.78", "size": "0", "side": "BUY", "hash": "a6e7a39c53df9457d212931f69871255545302ca", "best_bid": "0.79", "best_ask": "0.98"}], "timestamp": "1769384904588", "event_type": "price_change"}}
{"_local_timestamp": "2026-01-25T23:48:25.016660+00:00", "data": {"market": "0x15f8f202d13a8bf70566cc9d015331f2b7c4673ce7c0f3bd9274122143da98d7", "price_changes": [{"asset_id": "6003904135061936547790713762650160287283968685330714568260970794818630572545", "price": "0.239", "size": "0", "side": "SELL", "hash": "3deb6c2416488bec7e9bf289fa17b65b7cfbea99", "best_bid": "0.025", "best_ask": "0.236"}, {"asset_id": "45368672532526393278374326096994364441839328602765138400884696484182735669678", "price": "0.761", "size": "0", "side": "BUY", "hash": "990e4a25b0f26ae2f0d8185f52e392c88f1ff399", "best_bid": "0.764", "best_ask": "0.975"}], "timestamp": "1769384904783", "event_type": "price_change"}}
{"_local_timestamp": "2026-01-25T23:48:25.017255+00:00", "data": {"market": "0x5d1e8a08b738d682ce49308c73f0a83ae192476cc9472cb82cc989e4d83a7e7f", "price_changes": [{"asset_id": "97425373542541244409279148168035803042084783523795409980290844728581925888286", "price": "0.274", "size": "0", "side": "SELL", "hash": "79bea5cc59965b4e44fc644386ba20b50b8ccfb5", "best_bid": "0.02", "best_ask": "0.271"}, {"asset_id": "79115303304484490600349903081713351482280993232719554838261202179898129935846", "price": "0.726", "size": "0", "side": "BUY", "hash": "e6a9f5941486bfb9004cb347378d47fbf1f9244d", "best_bid": "0.729", "best_ask": "0.98"}], "timestamp": "1769384904783", "event_type": "price_change"}}
{"_local_timestamp": "2026-01-25T23:48:25.104607+00:00", "data": {"market": "0x1e8287101399f3c9c1c135d82f7e53613a4ba421cab14fb7e6b2b1cf8bd83f30", "price_changes": [{"asset_id": "73364483172319264394905719398750594214204555040619327864407649701603224821302", "price": "0.232", "size": "0", "side": "SELL", "hash": "de1e36d320427466a1742e19d45c172f131463c7", "best_bid": "0.02", "best_ask": "0.229"}, {"asset_id": "105266113555482874447692384740183990312049358997159118634356221057644647229583", "price": "0.768", "size": "0", "side": "BUY", "hash": "9d5e937b1adf7577776e5b36088bf89e7ebef4f6", "best_bid": "0.771", "best_ask": "0.98"}], "timestamp": "1769384904873", "event_type": "price_change"}}
{"_local_timestamp": "2026-01-25T23:48:25.506298+00:00", "data": {"market": "0x39b718f6e0a66a3ae5e459e76c74a694b521eaff5f6015857d1d191f1fc03c61", "price_changes": [{"asset_id": "10458098669927883185204828453571065550874636694709643726889899346674533724103", "price": "0.2", "size": "40.77", "side": "SELL", "hash": "95a5bfeeae56749a2addab83c7a01fa2604ee4d2", "best_bid": "0.02", "best_ask": "0.2"}, {"asset_id": "55794910131918732608143325808731608350538323781799534833013667918954993794053", "price": "0.8", "size": "40.77", "side": "BUY", "hash": "d89809ac547dc037e0edfd0340c23487aae965e7", "best_bid": "0.8", "best_ask": "0.98"}], "timestamp": "1769384905259", "event_type": "price_change"}}
{"_local_timestamp": "2026-01-25T23:48:25.656185+00:00", "data": {"market": "0x1e8287101399f3c9c1c135d82f7e53613a4ba421cab14fb7e6b2b1cf8bd83f30", "price_changes": [{"asset_id": "105266113555482874447692384740183990312049358997159118634356221057644647229583", "price": "0.771", "size": "0", "side": "BUY", "hash": "800d9d07c6f43debc47e52a5e7b503874f36e612", "best_bid": "0.687", "best_ask": "0.98"}, {"asset_id": "73364483172319264394905719398750594214204555040619327864407649701603224821302", "price": "0.229", "size": "0", "side": "SELL", "hash": "f41e7aa0c4aea318bb8007de01a6ad5085e0439b", "best_bid": "0.02", "best_ask": "0.313"}], "timestamp": "1769384905425", "event_type": "price_change"}}
{"_local_timestamp": "2026-01-25T23:48:25.656925+00:00", "data": {"market": "0x15f8f202d13a8bf70566cc9d015331f2b7c4673ce7c0f3bd9274122143da98d7", "price_changes": [{"asset_id": "45368672532526393278374326096994364441839328602765138400884696484182735669678", "price": "0.764", "size": "0", "side": "BUY", "hash": "01b1cbd07eda3378ddb5bd9f215a1491eb39fe73", "best_bid": "0.68", "best_ask": "0.975"}, {"asset_id": "6003904135061936547790713762650160287283968685330714568260970794818630572545", "price": "0.236", "size": "0", "side": "SELL", "hash": "bf6d83ad67ac5d043b1ff3474f364dfc1aeff7c4", "best_bid": "0.025", "best_ask": "0.32"}], "timestamp": "1769384905425", "event_type": "price_change"}}
{"_local_timestamp": "2026-01-25T23:48:25.657564+00:00", "data": {"market": "0x5d1e8a08b738d682ce49308c73f0a83ae192476cc9472cb82cc989e4d83a7e7f", "price_changes": [{"asset_id": "79115303304484490600349903081713351482280993232719554838261202179898129935846", "price": "0.729", "size": "0", "side": "BUY", "hash": "1aa6c525a1f7cc3b836ddc937073d6c38abb141f", "best_bid": "0.645", "best_ask": "0.98"}, {"asset_id": "97425373542541244409279148168035803042084783523795409980290844728581925888286", "price": "0.271", "size": "0", "side": "SELL", "hash": "92f3ca866b5cf5da59367e2a64546b2df5358cdc", "best_bid": "0.02", "best_ask": "0.355"}], "timestamp": "1769384905425", "event_type": "price_change"}}
{"_local_timestamp": "2026-01-25T23:48:25.675221+00:00", "data": {"market": "0x15f8f202d13a8bf70566cc9d015331f2b7c4673ce7c0f3bd9274122143da98d7", "price_changes": [{"asset_id": "6003904135061936547790713762650160287283968685330714568260970794818630572545", "price": "0.235", "size": "20", "side": "SELL", "hash": "91a49cddbc638335a54a179d861beb155556a311", "best_bid": "0.025", "best_ask": "0.235"}, {"asset_id": "45368672532526393278374326096994364441839328602765138400884696484182735669678", "price": "0.765", "size": "20", "side": "BUY", "hash": "a6294adfb9b13a8856d4ed04564ad35a8609d001", "best_bid": "0.765", "best_ask": "0.975"}], "timestamp": "1769384905449", "event_type": "price_change"}}
{"_local_timestamp": "2026-01-25T23:48:25.677529+00:00", "data": {"market": "0x5d1e8a08b738d682ce49308c73f0a83ae192476cc9472cb82cc989e4d83a7e7f", "price_changes": [{"asset_id": "97425373542541244409279148168035803042084783523795409980290844728581925888286", "price": "0.27", "size": "20.62", "side": "SELL", "hash": "9b6d41234ae2362a278d7999ffb759567298884b", "best_bid": "0.02", "best_ask": "0.27"}, {"asset_id": "79115303304484490600349903081713351482280993232719554838261202179898129935846", "price": "0.73", "size": "20.62", "side": "BUY", "hash": "958266685d649b62c4e56e3515e79cbbdc5b79ba", "best_bid": "0.73", "best_ask": "0.98"}], "timestamp": "1769384905449", "event_type": "price_change"}}
{"_local_timestamp": "2026-01-25T23:48:25.678165+00:00", "data": {"market": "0x5d1e8a08b738d682ce49308c73f0a83ae192476cc9472cb82cc989e4d83a7e7f", "price_changes": [{"asset_id": "79115303304484490600349903081713351482280993232719554838261202179898129935846", "price": "0.646", "size": "20", "side": "BUY", "hash": "008e481d1db6d1c09fd9be724200f6d02225ef11", "best_bid": "0.73", "best_ask": "0.98"}, {"asset_id": "97425373542541244409279148168035803042084783523795409980290844728581925888286", "price": "0.354", "size": "20", "side": "SELL", "hash": "ce2efe24583fa29f6bf9a47000b20ce9fc2b93b8", "best_bid": "0.02", "best_ask": "0.27"}], "timestamp": "1769384905451", "event_type": "price_change"}}
{"_local_timestamp": "2026-01-25T23:48:25.678757+00:00", "data": {"market": "0x15f8f202d13a8bf70566cc9d015331f2b7c4673ce7c0f3bd9274122143da98d7", "price_changes": [{"asset_id": "45368672532526393278374326096994364441839328602765138400884696484182735669678", "price": "0.681", "size": "20", "side": "BUY", "hash": "c2ed99ee6554a4fd9a7f8855c54e8f6cb6adff05", "best_bid": "0.765", "best_ask": "0.975"}, {"asset_id": "6003904135061936547790713762650160287283968685330714568260970794818630572545", "price": "0.319", "size": "20", "side": "SELL", "hash": "0221e24c5446f913c2bd03a83e5bc5bdeb6d86cc", "best_bid": "0.025", "best_ask": "0.235"}], "timestamp": "1769384905451", "event_type": "price_change"}}
{"_local_timestamp": "2026-01-25T23:48:25.679308+00:00", "data": {"market": "0x1e8287101399f3c9c1c135d82f7e53613a4ba421cab14fb7e6b2b1cf8bd83f30", "price_changes": [{"asset_id": "105266113555482874447692384740183990312049358997159118634356221057644647229583", "price": "0.688", "size": "20", "side": "BUY", "hash": "e30cda62f49a04d10aabb6b92d99a93ec5f46258", "best_bid": "0.688", "best_ask": "0.98"}, {"asset_id": "73364483172319264394905719398750594214204555040619327864407649701603224821302", "price": "0.312", "size": "20", "side": "SELL", "hash": "a85d3e8b7511b609ece8409a416aeddc0e554deb", "best_bid": "0.02", "best_ask": "0.312"}], "timestamp": "1769384905451", "event_type": "price_change"}}
{"_local_timestamp": "2026-01-25T23:48:25.782458+00:00", "data": {"market": "0x1e8287101399f3c9c1c135d82f7e53613a4ba421cab14fb7e6b2b1cf8bd83f30", "price_changes": [{"asset_id": "73364483172319264394905719398750594214204555040619327864407649701603224821302", "price": "0.228", "size": "20", "side": "SELL", "hash": "db4582fb4e5fccad4e695ce28a21f5c4faf3e893", "best_bid": "0.02", "best_ask": "0.228"}, {"asset_id": "105266113555482874447692384740183990312049358997159118634356221057644647229583", "price": "0.772", "size": "20", "side": "BUY", "hash": "4dc3b3320ac6265f22853144e0014ec235d4b3fc", "best_bid": "0.772", "best_ask": "0.98"}], "timestamp": "1769384905551", "event_type": "price_change"}}
{"_local_timestamp": "2026-01-25T23:48:29.193059+00:00", "data": {"market": "0x1e8287101399f3c9c1c135d82f7e53613a4ba421cab14fb7e6b2b1cf8bd83f30", "price_changes": [{"asset_id": "105266113555482874447692384740183990312049358997159118634356221057644647229583", "price": "0.688", "size": "0", "side": "BUY", "hash": "a12195a085d6237439176169264ce6d791fc8c61", "best_bid": "0.772", "best_ask": "0.98"}, {"asset_id": "73364483172319264394905719398750594214204555040619327864407649701603224821302", "price": "0.312", "size": "0", "side": "SELL", "hash": "7d968206b33fb3eb3b6112104bc24222cc596cc8", "best_bid": "0.02", "best_ask": "0.228"}], "timestamp": "1769384908945", "event_type": "price_change"}}
{"_local_timestamp": "2026-01-25T23:48:29.193660+00:00", "data": {"market": "0x5d1e8a08b738d682ce49308c73f0a83ae192476cc9472cb82cc989e4d83a7e7f", "price_changes": [{"asset_id": "79115303304484490600349903081713351482280993232719554838261202179898129935846", "price": "0.646", "size": "0", "side": "BUY", "hash": "77c747f75b01f2acc7112bc934d31b8c2c87f0ba", "best_bid": "0.73", "best_ask": "0.98"}, {"asset_id": "97425373542541244409279148168035803042084783523795409980290844728581925888286", "price": "0.354", "size": "0", "side": "SELL", "hash": "b2582822343c018fabbdff2026e68da54b09a876", "best_bid": "0.02", "best_ask": "0.27"}], "timestamp": "1769384908945", "event_type": "price_change"}}
{"_local_timestamp": "2026-01-25T23:48:29.194198+00:00", "data": {"market": "0x15f8f202d13a8bf70566cc9d015331f2b7c4673ce7c0f3bd9274122143da98d7", "price_changes": [{"asset_id": "45368672532526393278374326096994364441839328602765138400884696484182735669678", "price": "0.681", "size": "0", "side": "BUY", "hash": "dda3d2a35a6d1eb10bbd4a2f0048178d884bf444", "best_bid": "0.765", "best_ask": "0.975"}, {"asset_id": "6003904135061936547790713762650160287283968685330714568260970794818630572545", "price": "0.319", "size": "0", "side": "SELL", "hash": "2d1f23402305b6907393ad97fefb4cf0e612b566", "best_bid": "0.025", "best_ask": "0.235"}], "timestamp": "1769384908945", "event_type": "price_change"}}
{"_local_timestamp": "2026-01-25T23:48:29.208541+00:00", "data": {"market": "0x1e8287101399f3c9c1c135d82f7e53613a4ba421cab14fb7e6b2b1cf8bd83f30", "price_changes": [{"asset_id": "105266113555482874447692384740183990312049358997159118634356221057644647229583", "price": "0.773", "size": "20", "side": "BUY", "hash": "7ce50712c8c9a13620bea1735f4a757e61413f4f", "best_bid": "0.773", "best_ask": "0.98"}, {"asset_id": "73364483172319264394905719398750594214204555040619327864407649701603224821302", "price": "0.227", "size": "20", "side": "SELL", "hash": "4957e2af9557ebe3806264ae71772e9c16ce343b", "best_bid": "0.02", "best_ask": "0.227"}], "timestamp": "1769384908974", "event_type": "price_change"}}
{"_local_timestamp": "2026-01-25T23:48:29.209199+00:00", "data": {"market": "0x15f8f202d13a8bf70566cc9d015331f2b7c4673ce7c0f3bd9274122143da98d7", "price_changes": [{"asset_id": "45368672532526393278374326096994364441839328602765138400884696484182735669678", "price": "0.766", "size": "20", "side": "BUY", "hash": "b24b846eaf4e19bfca67b57d0b7dd104343aa6a6", "best_bid": "0.766", "best_ask": "0.975"}, {"asset_id": "6003904135061936547790713762650160287283968685330714568260970794818630572545", "price": "0.234", "size": "20", "side": "SELL", "hash": "6c45e87d786e2d1a2ffe8be144f122ec9f5d2086", "best_bid": "0.025", "best_ask": "0.234"}], "timestamp": "1769384908974", "event_type": "price_change"}}
{"_local_timestamp": "2026-01-25T23:48:29.209751+00:00", "data": {"market": "0x5d1e8a08b738d682ce49308c73f0a83ae192476cc9472cb82cc989e4d83a7e7f", "price_changes": [{"asset_id": "79115303304484490600349903081713351482280993232719554838261202179898129935846", "price": "0.731", "size": "20", "side": "BUY", "hash": "c78feef3fa79af91b87ae6b0ba1d7260b61befb4", "best_bid": "0.731", "best_ask": "0.98"}, {"asset_id": "97425373542541244409279148168035803042084783523795409980290844728581925888286", "price": "0.269", "size": "20", "side": "SELL", "hash": "bc2d602dd85713f547bcebcd88017b822f8ab84c", "best_bid": "0.02", "best_ask": "0.269"}], "timestamp": "1769384908974", "event_type": "price_change"}}
{"_local_timestamp": "2026-01-25T23:48:40.120528+00:00", "data": {"market": "0x39b718f6e0a66a3ae5e459e76c74a694b521eaff5f6015857d1d191f1fc03c61", "price_changes": [{"asset_id": "55794910131918732608143325808731608350538323781799534833013667918954993794053", "price": "0.79", "size": "0", "side": "BUY", "hash": "ec07f246c3480c71adb63a6baa6ad9039c1372d1", "best_bid": "0.8", "best_ask": "0.98"}, {"asset_id": "10458098669927883185204828453571065550874636694709643726889899346674533724103", "price": "0.21", "size": "0", "side": "SELL", "hash": "745de8d16fc1b40901dc0b2f332dca28f6810dea", "best_bid": "0.02", "best_ask": "0.2"}], "timestamp": "1769384919889", "event_type": "price_change"}}
{"_local_timestamp": "2026-01-25T23:49:36.757170+00:00", "data": {"market": "0x15f8f202d13a8bf70566cc9d015331f2b7c4673ce7c0f3bd9274122143da98d7", "price_changes": [{"asset_id": "45368672532526393278374326096994364441839328602765138400884696484182735669678", "price": "0.154", "size": "0", "side": "BUY", "hash": "85b150ac74da2621e15b38d207782f7651ec5830", "best_bid": "0.766", "best_ask": "0.975"}, {"asset_id": "6003904135061936547790713762650160287283968685330714568260970794818630572545", "price": "0.846", "size": "0", "side": "SELL", "hash": "1ae774664ea51854bd15d14b7febd7d3bad17bbe", "best_bid": "0.025", "best_ask": "0.234"}], "timestamp": "1769384976674", "event_type": "price_change"}}
{"_local_timestamp": "2026-01-25T23:49:36.795598+00:00", "data": {"market": "0x15f8f202d13a8bf70566cc9d015331f2b7c4673ce7c0f3bd9274122143da98d7", "price_changes": [{"asset_id": "45368672532526393278374326096994364441839328602765138400884696484182735669678", "price": "0.501", "size": "5", "side": "BUY", "hash": "00c23224ba6e6d784008bfcbb6097da4e41e756e", "best_bid": "0.766", "best_ask": "0.975"}, {"asset_id": "6003904135061936547790713762650160287283968685330714568260970794818630572545", "price": "0.499", "size": "5", "side": "SELL", "hash": "7a17565c008e6f3d5039821093ca130aa35d769f", "best_bid": "0.025", "best_ask": "0.234"}], "timestamp": "1769384976722", "event_type": "price_change"}}
{"_local_timestamp": "2026-01-25T23:49:50.496370+00:00", "data": {"market": "0x39b718f6e0a66a3ae5e459e76c74a694b521eaff5f6015857d1d191f1fc03c61", "price_changes": [{"asset_id": "10458098669927883185204828453571065550874636694709643726889899346674533724103", "price": "0.2", "size": "0", "side": "SELL", "hash": "2315d0fbabd068ddde4c96bad8503e2b2ce9e2cd", "best_bid": "0.02", "best_ask": "0.23"}, {"asset_id": "55794910131918732608143325808731608350538323781799534833013667918954993794053", "price": "0.8", "size": "0", "side": "BUY", "hash": "f06e9ae3a766519c774d3e5b81a940102a9e706d", "best_bid": "0.77", "best_ask": "0.98"}], "timestamp": "1769384990424", "event_type": "price_change"}}
{"_local_timestamp": "2026-01-25T23:49:50.848032+00:00", "data": {"market": "0x5d1e8a08b738d682ce49308c73f0a83ae192476cc9472cb82cc989e4d83a7e7f", "price_changes": [{"asset_id": "97425373542541244409279148168035803042084783523795409980290844728581925888286", "price": "0.27", "size": "0", "side": "SELL", "hash": "e4fc375ee305f8d368f2d40fe7c9509688f82a7b", "best_bid": "0.02", "best_ask": "0.269"}, {"asset_id": "79115303304484490600349903081713351482280993232719554838261202179898129935846", "price": "0.73", "size": "0", "side": "BUY", "hash": "6b1aa39a13be32c27da19dfc66ae8818e18dbe0e", "best_bid": "0.731", "best_ask": "0.98"}], "timestamp": "1769384990760", "event_type": "price_change"}}
{"_local_timestamp": "2026-01-25T23:49:50.848692+00:00", "data": {"market": "0x15f8f202d13a8bf70566cc9d015331f2b7c4673ce7c0f3bd9274122143da98d7", "price_changes": [{"asset_id": "6003904135061936547790713762650160287283968685330714568260970794818630572545", "price": "0.235", "size": "0", "side": "SELL", "hash": "dbbe3e0ca9f4655d89a891c8f15665ae150e606c", "best_bid": "0.025", "best_ask": "0.234"}, {"asset_id": "45368672532526393278374326096994364441839328602765138400884696484182735669678", "price": "0.765", "size": "0", "side": "BUY", "hash": "1b070b7cd6c3a7ace4a51f8a8817cd7ca9b37e9b", "best_bid": "0.766", "best_ask": "0.975"}], "timestamp": "1769384990761", "event_type": "price_change"}}
{"_local_timestamp": "2026-01-25T23:49:50.856124+00:00", "data": {"market": "0x1e8287101399f3c9c1c135d82f7e53613a4ba421cab14fb7e6b2b1cf8bd83f30", "price_changes": [{"asset_id": "73364483172319264394905719398750594214204555040619327864407649701603224821302", "price": "0.228", "size": "0", "side": "SELL", "hash": "5493999eaa5853144ba48733276034199b153ae0", "best_bid": "0.02", "best_ask": "0.227"}, {"asset_id": "105266113555482874447692384740183990312049358997159118634356221057644647229583", "price": "0.772", "size": "0", "side": "BUY", "hash": "7384fe3b22bb45b0932954302a28510d1381a894", "best_bid": "0.773", "best_ask": "0.98"}], "timestamp": "1769384990762", "event_type": "price_change"}}
{"_local_timestamp": "2026-01-25T23:49:51.477623+00:00", "data": {"market": "0x39b718f6e0a66a3ae5e459e76c74a694b521eaff5f6015857d1d191f1fc03c61", "price_changes": [{"asset_id": "10458098669927883185204828453571065550874636694709643726889899346674533724103", "price": "0.22", "size": "40.77", "side": "SELL", "hash": "363c2a3695b4fc23f52899bb68bb380eb46b0f69", "best_bid": "0.02", "best_ask": "0.22"}, {"asset_id": "55794910131918732608143325808731608350538323781799534833013667918954993794053", "price": "0.78", "size": "40.77", "side": "BUY", "hash": "3f5737b66c89f96f402b27774f84c13bcdcb0721", "best_bid": "0.78", "best_ask": "0.98"}], "timestamp": "1769384991361", "event_type": "price_change"}}
{"_local_timestamp": "2026-01-25T23:49:51.735855+00:00", "data": {"market": "0x15f8f202d13a8bf70566cc9d015331f2b7c4673ce7c0f3bd9274122143da98d7", "price_changes": [{"asset_id": "6003904135061936547790713762650160287283968685330714568260970794818630572545", "price": "0.233", "size": "20", "side": "SELL", "hash": "7f955e35301fef275452dd40fca7cb054d6d59c3", "best_bid": "0.025", "best_ask": "0.233"}, {"asset_id": "45368672532526393278374326096994364441839328602765138400884696484182735669678", "price": "0.767", "size": "20", "side": "BUY", "hash": "0aca4307e3d7e54c24142b08e377ef35bd839541", "best_bid": "0.767", "best_ask": "0.975"}], "timestamp": "1769384991663", "event_type": "price_change"}}
{"_local_timestamp": "2026-01-25T23:49:51.736522+00:00", "data": {"market": "0x5d1e8a08b738d682ce49308c73f0a83ae192476cc9472cb82cc989e4d83a7e7f", "price_changes": [{"asset_id": "97425373542541244409279148168035803042084783523795409980290844728581925888286", "price": "0.268", "size": "20.62", "side": "SELL", "hash": "2928d7a744ca990981272421bfae467f323f61d4", "best_bid": "0.02", "best_ask": "0.268"}, {"asset_id": "79115303304484490600349903081713351482280993232719554838261202179898129935846", "price": "0.732", "size": "20.62", "side": "BUY", "hash": "e4768727355aebfa58f695fded8f3d6c53ae02be", "best_bid": "0.732", "best_ask": "0.98"}], "timestamp": "1769384991663", "event_type": "price_change"}}
{"_local_timestamp": "2026-01-25T23:49:51.737136+00:00", "data": {"market": "0x1e8287101399f3c9c1c135d82f7e53613a4ba421cab14fb7e6b2b1cf8bd83f30", "price_changes": [{"asset_id": "73364483172319264394905719398750594214204555040619327864407649701603224821302", "price": "0.226", "size": "20", "side": "SELL", "hash": "fc87f96115316c61885636342b778d7979d856c1", "best_bid": "0.02", "best_ask": "0.226"}, {"asset_id": "105266113555482874447692384740183990312049358997159118634356221057644647229583", "price": "0.774", "size": "20", "side": "BUY", "hash": "ef068d91042e3ceda6487d570a66abcfdd6aaaa5", "best_bid": "0.774", "best_ask": "0.98"}], "timestamp": "1769384991664", "event_type": "price_change"}}
{"_local_timestamp": "2026-01-25T23:49:54.536725+00:00", "data": {"market": "0x1e8287101399f3c9c1c135d82f7e53613a4ba421cab14fb7e6b2b1cf8bd83f30", "price_changes": [{"asset_id": "105266113555482874447692384740183990312049358997159118634356221057644647229583", "price": "0.773", "size": "0", "side": "BUY", "hash": "3273bc6e21a66652575bd143dd0d961e5b2f8d32", "best_bid": "0.774", "best_ask": "0.98"}, {"asset_id": "73364483172319264394905719398750594214204555040619327864407649701603224821302", "price": "0.227", "size": "0", "side": "SELL", "hash": "79812fbb30e1835887677f0def6f5d295b89638f", "best_bid": "0.02", "best_ask": "0.226"}], "timestamp": "1769384994463", "event_type": "price_change"}}
{"_local_timestamp": "2026-01-25T23:49:54.537448+00:00", "data": {"market": "0x5d1e8a08b738d682ce49308c73f0a83ae192476cc9472cb82cc989e4d83a7e7f", "price_changes": [{"asset_id": "79115303304484490600349903081713351482280993232719554838261202179898129935846", "price": "0.731", "size": "0", "side": "BUY", "hash": "2840d2db49bab0d01e96b9a925e01d9a9bdc6345", "best_bid": "0.732", "best_ask": "0.98"}, {"asset_id": "97425373542541244409279148168035803042084783523795409980290844728581925888286", "price": "0.269", "size": "0", "side": "SELL", "hash": "54d19c1dfb4545864a2f6225ebdd26a9e15bfaaa", "best_bid": "0.02", "best_ask": "0.268"}], "timestamp": "1769384994463", "event_type": "price_change"}}
{"_local_timestamp": "2026-01-25T23:49:54.538015+00:00", "data": {"market": "0x15f8f202d13a8bf70566cc9d015331f2b7c4673ce7c0f3bd9274122143da98d7", "price_changes": [{"asset_id": "45368672532526393278374326096994364441839328602765138400884696484182735669678", "price": "0.766", "size": "0", "side": "BUY", "hash": "893472b30cf3f1ebb17a3947a368cec12105e93a", "best_bid": "0.767", "best_ask": "0.975"}, {"asset_id": "6003904135061936547790713762650160287283968685330714568260970794818630572545", "price": "0.234", "size": "0", "side": "SELL", "hash": "72b952dc360dcf9580fd0e6bce563b2ce54dd541", "best_bid": "0.025", "best_ask": "0.233"}], "timestamp": "1769384994463", "event_type": "price_change"}}
{"_local_timestamp": "2026-01-25T23:49:54.580020+00:00", "data": {"market": "0x5d1e8a08b738d682ce49308c73f0a83ae192476cc9472cb82cc989e4d83a7e7f", "price_changes": [{"asset_id": "79115303304484490600349903081713351482280993232719554838261202179898129935846", "price": "0.733", "size": "20", "side": "BUY", "hash": "26ace2112f979e33c3d8c5f3c36c939bf371a523", "best_bid": "0.733", "best_ask": "0.98"}, {"asset_id": "97425373542541244409279148168035803042084783523795409980290844728581925888286", "price": "0.267", "size": "20", "side": "SELL", "hash": "4dc1eac3889af142f6cd4d4255706abb8feceed4", "best_bid": "0.02", "best_ask": "0.267"}], "timestamp": "1769384994493", "event_type": "price_change"}}
{"_local_timestamp": "2026-01-25T23:49:54.580685+00:00", "data": {"market": "0x1e8287101399f3c9c1c135d82f7e53613a4ba421cab14fb7e6b2b1cf8bd83f30", "price_changes": [{"asset_id": "105266113555482874447692384740183990312049358997159118634356221057644647229583", "price": "0.775", "size": "20", "side": "BUY", "hash": "37bd6be6dd95aad41c63b82833a0057a670be7af", "best_bid": "0.775", "best_ask": "0.98"}, {"asset_id": "73364483172319264394905719398750594214204555040619327864407649701603224821302", "price": "0.225", "size": "20", "side": "SELL", "hash": "8a18de9584ed453560b0e942d66651474c5626dc", "best_bid": "0.02", "best_ask": "0.225"}], "timestamp": "1769384994493", "event_type": "price_change"}}
{"_local_timestamp": "2026-01-25T23:49:54.581415+00:00", "data": {"market": "0x15f8f202d13a8bf70566cc9d015331f2b7c4673ce7c0f3bd9274122143da98d7", "price_changes": [{"asset_id": "45368672532526393278374326096994364441839328602765138400884696484182735669678", "price": "0.768", "size": "20", "side": "BUY", "hash": "f2f97624f1917ce8eaf6295d2f361e798017d2e7", "best_bid": "0.768", "best_ask": "0.975"}, {"asset_id": "6003904135061936547790713762650160287283968685330714568260970794818630572545", "price": "0.232", "size": "20", "side": "SELL", "hash": "9526b9c74d759b35083827ad09bdc014537ac5bf", "best_bid": "0.025", "best_ask": "0.232"}], "timestamp": "1769384994493", "event_type": "price_change"}}
{"_local_timestamp": "2026-01-25T23:50:31.527323+00:00", "data": {"market": "0x39b718f6e0a66a3ae5e459e76c74a694b521eaff5f6015857d1d191f1fc03c61", "price_changes": [{"asset_id": "55794910131918732608143325808731608350538323781799534833013667918954993794053", "price": "0.52", "size": "0", "side": "BUY", "hash": "6e2467b6c90bc6e362dfe8f412e61efb2581348a", "best_bid": "0.78", "best_ask": "0.98"}, {"asset_id": "10458098669927883185204828453571065550874636694709643726889899346674533724103", "price": "0.48", "size": "0", "side": "SELL", "hash": "f70642f3a86963c31bdfcdb6bad6ed3f0f1e8cf8", "best_bid": "0.02", "best_ask": "0.22"}], "timestamp": "1769385031448", "event_type": "price_change"}}
{"_local_timestamp": "2026-01-25T23:50:31.564793+00:00", "data": {"market": "0x39b718f6e0a66a3ae5e459e76c74a694b521eaff5f6015857d1d191f1fc03c61", "price_changes": [{"asset_id": "55794910131918732608143325808731608350538323781799534833013667918954993794053", "price": "0.52", "size": "5", "side": "BUY", "hash": "092e4595ec8d6c414c2f04138f9cbae5f88845d9", "best_bid": "0.78", "best_ask": "0.98"}, {"asset_id": "10458098669927883185204828453571065550874636694709643726889899346674533724103", "price": "0.48", "size": "5", "side": "SELL", "hash": "38d93fe2c8e15169d481b8bbc999f0b29b064ebe", "best_bid": "0.02", "best_ask": "0.22"}], "timestamp": "1769385031493", "event_type": "price_change"}}
{"_local_timestamp": "2026-01-25T23:51:18.406636+00:00", "data": {"market": "0x15f8f202d13a8bf70566cc9d015331f2b7c4673ce7c0f3bd9274122143da98d7", "price_changes": [{"asset_id": "6003904135061936547790713762650160287283968685330714568260970794818630572545", "price": "0.233", "size": "0", "side": "SELL", "hash": "0e80bbcc78569006002cbcc17829023bc7fcdc37", "best_bid": "0.025", "best_ask": "0.232"}, {"asset_id": "45368672532526393278374326096994364441839328602765138400884696484182735669678", "price": "0.767", "size": "0", "side": "BUY", "hash": "0ab8079560f3d2d0c0c34b3937812e3017925e4f", "best_bid": "0.768", "best_ask": "0.975"}], "timestamp": "1769385078320", "event_type": "price_change"}}
{"_local_timestamp": "2026-01-25T23:51:18.407502+00:00", "data": {"market": "0x1e8287101399f3c9c1c135d82f7e53613a4ba421cab14fb7e6b2b1cf8bd83f30", "price_changes": [{"asset_id": "73364483172319264394905719398750594214204555040619327864407649701603224821302", "price": "0.226", "size": "0", "side": "SELL", "hash": "8c7b582b9362daf15c09fbc3c35284c0e22d085f", "best_bid": "0.02", "best_ask": "0.225"}, {"asset_id": "105266113555482874447692384740183990312049358997159118634356221057644647229583", "price": "0.774", "size": "0", "side": "BUY", "hash": "5700cb9550deb79fc3271d695b899d64e12c5f4d", "best_bid": "0.775", "best_ask": "0.98"}], "timestamp": "1769385078320", "event_type": "price_change"}}
{"_local_timestamp": "2026-01-25T23:51:18.408099+00:00", "data": {"market": "0x5d1e8a08b738d682ce49308c73f0a83ae192476cc9472cb82cc989e4d83a7e7f", "price_changes": [{"asset_id": "97425373542541244409279148168035803042084783523795409980290844728581925888286", "price": "0.268", "size": "0", "side": "SELL", "hash": "3e0b38655c00db20dbe8b1b30b0f48457fd4c3eb", "best_bid": "0.02", "best_ask": "0.267"}, {"asset_id": "79115303304484490600349903081713351482280993232719554838261202179898129935846", "price": "0.732", "size": "0", "side": "BUY", "hash": "fc9e1b95b620c26f69656a81757fc66b01fa4cfe", "best_bid": "0.733", "best_ask": "0.98"}], "timestamp": "1769385078321", "event_type": "price_change"}}
{"_local_timestamp": "2026-01-25T23:51:19.350667+00:00", "data": {"market": "0x1e8287101399f3c9c1c135d82f7e53613a4ba421cab14fb7e6b2b1cf8bd83f30", "price_changes": [{"asset_id": "73364483172319264394905719398750594214204555040619327864407649701603224821302", "price": "0.224", "size": "20", "side": "SELL", "hash": "d5d053bc27bb5e09581ff862f01643fc3c62bf2e", "best_bid": "0.02", "best_ask": "0.224"}, {"asset_id": "105266113555482874447692384740183990312049358997159118634356221057644647229583", "price": "0.776", "size": "20", "side": "BUY", "hash": "6f9a42bd5c87f7f32e9d8302748a8147b9133b07", "best_bid": "0.776", "best_ask": "0.98"}], "timestamp": "1769385079284", "event_type": "price_change"}}
{"_local_timestamp": "2026-01-25T23:51:19.351383+00:00", "data": {"market": "0x5d1e8a08b738d682ce49308c73f0a83ae192476cc9472cb82cc989e4d83a7e7f", "price_changes": [{"asset_id": "97425373542541244409279148168035803042084783523795409980290844728581925888286", "price": "0.266", "size": "20.62", "side": "SELL", "hash": "b441935f5dba74d84581e3a2e8bbd6b14bbf02ec", "best_bid": "0.02", "best_ask": "0.266"}, {"asset_id": "79115303304484490600349903081713351482280993232719554838261202179898129935846", "price": "0.734", "size": "20.62", "side": "BUY", "hash": "feaa09e187881380e5d17317b863f976c5343db5", "best_bid": "0.734", "best_ask": "0.98"}], "timestamp": "1769385079285", "event_type": "price_change"}}
{"_local_timestamp": "2026-01-25T23:51:19.357831+00:00", "data": {"market": "0x15f8f202d13a8bf70566cc9d015331f2b7c4673ce7c0f3bd9274122143da98d7", "price_changes": [{"asset_id": "6003904135061936547790713762650160287283968685330714568260970794818630572545", "price": "0.231", "size": "20", "side": "SELL", "hash": "de7dc1582deb8f74085d1dbcab67237307ad492e", "best_bid": "0.025", "best_ask": "0.231"}, {"asset_id": "45368672532526393278374326096994364441839328602765138400884696484182735669678", "price": "0.769", "size": "20", "side": "BUY", "hash": "90f83f3047047a8fc0e63459bd0d241e8401cf9e", "best_bid": "0.769", "best_ask": "0.975"}], "timestamp": "1769385079285", "event_type": "price_change"}}
{"_local_timestamp": "2026-01-25T23:51:20.961966+00:00", "data": {"market": "0x15f8f202d13a8bf70566cc9d015331f2b7c4673ce7c0f3bd9274122143da98d7", "price_changes": [{"asset_id": "45368672532526393278374326096994364441839328602765138400884696484182735669678", "price": "0.768", "size": "0", "side": "BUY", "hash": "d6884ad7df1e95b8f41651d72f268a3bc613a115", "best_bid": "0.769", "best_ask": "0.975"}, {"asset_id": "6003904135061936547790713762650160287283968685330714568260970794818630572545", "price": "0.232", "size": "0", "side": "SELL", "hash": "8d6454fbbe8861baf587cf132ba39c878129c25b", "best_bid": "0.025", "best_ask": "0.231"}], "timestamp": "1769385080898", "event_type": "price_change"}}
{"_local_timestamp": "2026-01-25T23:51:20.963233+00:00", "data": {"market": "0x1e8287101399f3c9c1c135d82f7e53613a4ba421cab14fb7e6b2b1cf8bd83f30", "price_changes": [{"asset_id": "105266113555482874447692384740183990312049358997159118634356221057644647229583", "price": "0.775", "size": "0", "side": "BUY", "hash": "d40fff8c727bb1ff8af808f328934e55192c1e3b", "best_bid": "0.776", "best_ask": "0.98"}, {"asset_id": "73364483172319264394905719398750594214204555040619327864407649701603224821302", "price": "0.225", "size": "0", "side": "SELL", "hash": "daa1dbbeed607aabed194a61f3805179d178b124", "best_bid": "0.02", "best_ask": "0.224"}], "timestamp": "1769385080898", "event_type": "price_change"}}
{"_local_timestamp": "2026-01-25T23:51:20.963991+00:00", "data": {"market": "0x5d1e8a08b738d682ce49308c73f0a83ae192476cc9472cb82cc989e4d83a7e7f", "price_changes": [{"asset_id": "79115303304484490600349903081713351482280993232719554838261202179898129935846", "price": "0.733", "size": "0", "side": "BUY", "hash": "52f21e19c3585ebd2a1edb605dffdd4445e13938", "best_bid": "0.734", "best_ask": "0.98"}, {"asset_id": "97425373542541244409279148168035803042084783523795409980290844728581925888286", "price": "0.267", "size": "0", "side": "SELL", "hash": "da40a6f9be3e45bc290be55c00a3fcd4ce2a7453", "best_bid": "0.02", "best_ask": "0.266"}], "timestamp": "1769385080898", "event_type": "price_change"}}
{"_local_timestamp": "2026-01-25T23:51:20.989908+00:00", "data": {"market": "0x1e8287101399f3c9c1c135d82f7e53613a4ba421cab14fb7e6b2b1cf8bd83f30", "price_changes": [{"asset_id": "105266113555482874447692384740183990312049358997159118634356221057644647229583", "price": "0.777", "size": "20", "side": "BUY", "hash": "4704a04c878dbe0acac4dae12f8ade8e8f3863dd", "best_bid": "0.777", "best_ask": "0.98"}, {"asset_id": "73364483172319264394905719398750594214204555040619327864407649701603224821302", "price": "0.223", "size": "20", "side": "SELL", "hash": "f038459bb8ca714d754d317cdd7a775d87d340ed", "best_bid": "0.02", "best_ask": "0.223"}], "timestamp": "1769385080928", "event_type": "price_change"}}
{"_local_timestamp": "2026-01-25T23:51:20.993050+00:00", "data": {"market": "0x15f8f202d13a8bf70566cc9d015331f2b7c4673ce7c0f3bd9274122143da98d7", "price_changes": [{"asset_id": "45368672532526393278374326096994364441839328602765138400884696484182735669678", "price": "0.77", "size": "20", "side": "BUY", "hash": "729cf9d97942c5c608debcd09d47d2985411c834", "best_bid": "0.77", "best_ask": "0.975"}, {"asset_id": "6003904135061936547790713762650160287283968685330714568260970794818630572545", "price": "0.23", "size": "20", "side": "SELL", "hash": "d5b5c46496ab18548422e9a9b43e47f9d9e015fb", "best_bid": "0.025", "best_ask": "0.23"}], "timestamp": "1769385080928", "event_type": "price_change"}}
{"_local_timestamp": "2026-01-25T23:51:21.001954+00:00", "data": {"market": "0x5d1e8a08b738d682ce49308c73f0a83ae192476cc9472cb82cc989e4d83a7e7f", "price_changes": [{"asset_id": "79115303304484490600349903081713351482280993232719554838261202179898129935846", "price": "0.735", "size": "20", "side": "BUY", "hash": "1ff46f21bcba7679462455394ab83d01600859ca", "best_bid": "0.735", "best_ask": "0.98"}, {"asset_id": "97425373542541244409279148168035803042084783523795409980290844728581925888286", "price": "0.265", "size": "20", "side": "SELL", "hash": "93af0420a4e00083fcb98270e601ed17412982e8", "best_bid": "0.02", "best_ask": "0.265"}], "timestamp": "1769385080928", "event_type": "price_change"}}
