{"_local_timestamp": "2026-01-25T23:40:30.114471+00:00", "data": [{"market": "0x4f79d1df3869fea9411ed300b9a548e753a5eff1d3dba7ccc71d94403a516730", "asset_id": "4058613708692092601965760860759243398091398178902937564740140419929508866659", "timestamp": "1769384073814", "hash": "b364192f425752b9b5f6e0f278f652abe31cee48", "bids": [{"price": "0.01", "size": "48.76"}, {"price": "0.02", "size": "5.36"}, {"price": "0.03", "size": "16"}, {"price": "0.04", "size": "12.63"}, {"price": "0.13", "size": "2222"}, {"price": "0.14", "size": "8.5"}, {"price": "0.15", "size": "128"}, {"price": "0.25", "size": "50"}, {"price": "0.27", "size": "40"}, {"price": "0.32", "size": "97.62"}], "asks": [{"price": "0.99", "size": "20.07"}, {"price": "0.98", "size": "1000"}, {"price": "0.97", "size": "7.05"}, {"price": "0.96", "size": "12"}, {"price": "0.94", "size": "200"}, {"price": "0.93", "size": "750"}, {"price": "0.92", "size": "8.59"}, {"price": "0.89", "size": "300"}, {"price": "0.88", "size": "16"}, {"price": "0.87", "size": "8.5"}, {"price": "0.48", "size": "2222"}, {"price": "0.42", "size": "97.61"}], "event_type": "book", "last_trade_price": ""}, {"market": "0xbd9068da0f92022747bdad7a7d522c2f8bec81f0eb61c233eb94b301b3b4c62b", "asset_id": "107726477169398763643300346937218981578070170096670253959564188912978677384086", "timestamp": "1769381743179", "hash": "98c7d4909d09df5bdc7e05846308a3d56a0355d7", "bids": [{"price": "0.01", "size": "20.96"}, {"price": "0.02", "size": "1000"}, {"price": "0.03", "size": "8.72"}, {"price": "0.04", "size": "1700"}, {"price": "0.07", "size": "300"}, {"price": "0.08", "size": "7.85"}, {"price": "0.11", "size": "200"}, {"price": "0.12", "size": "250"}, {"price": "0.14", "size": "100"}, {"price": "0.15", "size": "5100"}, {"price": "0.16", "size": "250"}, {"price": "0.17", "size": "100"}, {"price": "0.18", "size": "8.5"}, {"price": "0.19", "size": "5"}, {"price": "0.29", "size": "51"}, {"price": "0.33", "size": "100"}], "asks": [{"price": "0.99", "size": "31.42"}, {"price": "0.98", "size": "5"}, {"price": "0.96", "size": "2000"}, {"price": "0.95", "size": "250"}, {"price": "0.94", "size": "200"}, {"price": "0.93", "size": "800"}, {"price": "0.92", "size": "8.57"}, {"price": "0.89", "size": "700"}, {"price": "0.84", "size": "250"}, {"price": "0.83", "size": "200"}, {"price": "0.79", "size": "200"}, {"price": "0.74", "size": "150"}, {"price": "0.72", "size": "150.27"}, {"price": "0.71", "size": "6"}, {"price": "0.7", "size": "150"}, {"price": "0.68", "size": "100"}, {"price": "0.66", "size": "100"}, {"price": "0.65", "size": "100"}, {"price": "0.64", "size": "8.5"}, {"price": "0.54", "size": "184.14"}, {"price": "0.46", "size": "5434.3"}, {"price": "0.45", "size": "2221"}, {"price": "0.43", "size": "107.86"}, {"price": "0.42", "size": "16.2"}], "event_type": "book", "last_trade_price": ""}, {"market": "0xe596f80a42391672c0ee629d1e0cdd2c22e7ce10c48d41fe6c077c8b9ebe6450", "asset_id": "112137718731147502310390559685098534923233818767269408035162170801812461954759", "timestamp": "1769384216212", "hash": "95a73f7bb4611c1a5b4e5ce4b696d8263e317ad6", "bids": [{"price": "0.01", "size": "76.25"}, {"price": "0.02", "size": "7.12"}, {"price": "0.04", "size": "35.95"}], "asks": [{"price": "0.99", "size": "19.97"}, {"price": "0.98", "size": "1025"}, {"price": "0.97", "size": "9.33"}, {"price": "0.95", "size": "520"}, {"price": "0.94", "size": "33"}, {"price": "0.91", "size": "450"}, {"price": "0.9", "size": "6.2"}, {"price": "0.82", "size": "5"}, {"price": "0.65", "size": "2232"}, {"price": "0.61", "size": "5"}, {"price": "0.4", "size": "900"}, {"price": "0.39", "size": "774.43"}], "event_type": "book", "last_trade_price": ""}, {"market": "0xb487a276075b688dba579d617391b7dcca5af14c04a6c33d8d03b9248aee0666", "asset_id": "58989659540855401044403336386853959781245409394903503665327101381123074880370", "timestamp": "1769384291759", "hash": "b166e01025d7ce7f5d9b76c0d94fcf767a9c289f", "bids": [{"price": "0.01", "size": "19.69"}, {"price": "0.02", "size": "1000"}, {"price": "0.03", "size": "6.79"}, {"price": "0.04", "size": "12"}, {"price": "0.05", "size": "20"}, {"price": "0.06", "size": "1033"}, {"price": "0.07", "size": "250"}, {"price": "0.08", "size": "8.73"}, {"price": "0.11", "size": "300"}, {"price": "0.12", "size": "16"}, {"price": "0.69", "size": "4201"}, {"price": "0.81", "size": "5"}, {"price": "0.86", "size": "100"}], "asks": [{"price": "0.99", "size": "10015"}, {"price": "0.98", "size": "310.2"}, {"price": "0.97", "size": "256.57"}, {"price": "0.96", "size": "44.34"}], "event_type": "book", "last_trade_price": ""}, {"market": "0xa49ed4d4d076cb71f2075a1a8a6719780b916d2df248943fa3b2380c73448e27", "asset_id": "51899361568906528010110120724978754160108229989334039373517208021434174315281", "timestamp": "1769381470264", "hash": "ec0324396cfa0a9f5ba5dda9dcbff33a6856e06f", "bids": [{"price": "0.01", "size": "69.93"}, {"price": "0.02", "size": "5"}, {"price": "0.04", "size": "12"}, {"price": "0.05", "size": "16.01"}], "asks": [{"price": "0.99", "size": "30.07"}, {"price": "0.98", "size": "7.48"}, {"price": "0.97", "size": "16"}, {"price": "0.95", "size": "20"}, {"price": "0.94", "size": "33"}, {"price": "0.93", "size": "9.28"}, {"price": "0.8", "size": "2222"}, {"price": "0.79", "size": "250"}, {"price": "0.77", "size": "5"}, {"price": "0.75", "size": "5"}, {"price": "0.74", "size": "15"}], "event_type": "book", "last_trade_price": ""}, {"market": "0xe3555dc0c83f3ed522993be9d88b3911ccea50eadf348aedc7d2feb6e131bf7b", "asset_id": "99817858714934748044341796488555563612713307921513659300432008966728516900242", "timestamp": "1769384262837", "hash": "86b029b97c217b5dad20e506a6ce786519c44bb9", "bids": [{"price": "0.001", "size": "2396.2"}, {"price": "0.002", "size": "250"}, {"price": "0.003", "size": "29.16"}, {"price": "0.01", "size": "10"}, {"price": "0.02", "size": "1000"}, {"price": "0.021", "size": "8"}, {"price": "0.03", "size": "16"}, {"price": "0.05", "size": "20"}, {"price": "0.051", "size": "39"}, {"price": "0.06", "size": "700"}, {"price": "0.061", "size": "12.03"}, {"price": "0.14", "size": "5320"}, {"price": "0.141", "size": "14"}, {"price": "0.142", "size": "7"}, {"price": "0.2", "size": "20"}, {"price": "0.22", "size": "20"}, {"price": "0.25", "size": "20"}, {"price": "0.29", "size": "10"}, {"price": "0.31", "size": "10"}, {"price": "0.37", "size": "10"}, {"price": "0.38", "size": "10"}, {"price": "0.39", "size": "10"}, {"price": "0.41", "size": "10"}, {"price": "0.45", "size": "20"}, {"price": "0.71", "size": "500"}, {"price": "0.8", "size": "5000"}, {"price": "0.9", "size": "5000"}, {"price": "0.901", "size": "17.73"}], "asks": [{"price": "0.999", "size": "742.31"}, {"price": "0.998", "size": "328.86"}, {"price": "0.997", "size": "134.97"}, {"price": "0.996", "size": "41"}, {"price": "0.995", "size": "34.17"}, {"price": "0.99", "size": "15"}, {"price": "0.989", "size": "14.2"}, {"price": "0.98", "size": "2"}], "event_type": "book", "last_trade_price": ""}, {"market": "0xa9ba962ede8fd5585244b33cc1bf4591468b71753091fb781a2a5b4257520c33", "asset_id": "18735166815426789203564053069301623175312317531324935825733833117617322984139", "timestamp": "1769383937820", "hash": "455628f78d2023352c8b22e59ec4697ccc551a18", "bids": [{"price": "0.01", "size": "20.92"}, {"price": "0.02", "size": "1000"}, {"price": "0.03", "size": "22.27"}, {"price": "0.05", "size": "20"}, {"price": "0.06", "size": "733"}, {"price": "0.07", "size": "10.03"}, {"price": "0.11", "size": "350"}, {"price": "0.12", "size": "16"}, {"price": "0.4", "size": "1111"}], "asks": [{"price": "0.99", "size": "53.74"}, {"price": "0.98", "size": "5"}, {"price": "0.97", "size": "16"}, {"price": "0.96", "size": "11.56"}, {"price": "0.95", "size": "20"}], "event_type": "book", "last_trade_price": ""}, {"market": "0x5bd45ec765062f8547cf89a0cf000cb08e786c1be086907c3b67cd69871ee561", "asset_id": "63729925394480697831937416134040390542894747506168438462552395726856610029052", "timestamp": "1769384194006", "hash": "159fcc9397517ea9326b750e735c24adbebb362c", "bids": [{"price": "0.01", "size": "20.39"}, {"price": "0.02", "size": "1000"}, {"price": "0.03", "size": "8.53"}, {"price": "0.05", "size": "10"}, {"price": "0.06", "size": "200"}, {"price": "0.07", "size": "750"}, {"price": "0.08", "size": "25"}, {"price": "0.09", "size": "7.11"}, {"price": "0.11", "size": "300"}, {"price": "0.3", "size": "2222"}, {"price": "0.36", "size": "160"}, {"price": "0.47", "size": "1000"}, {"price": "0.49", "size": "260"}], "asks": [{"price": "0.99", "size": "20.6"}, {"price": "0.98", "size": "725"}, {"price": "0.97", "size": "8.7"}, {"price": "0.94", "size": "750"}, {"price": "0.92", "size": "300"}, {"price": "0.91", "size": "7.03"}, {"price": "0.73", "size": "2222"}, {"price": "0.67", "size": "100"}, {"price": "0.6", "size": "91.47"}, {"price": "0.58", "size": "10"}, {"price": "0.56", "size": "289.44"}, {"price": "0.55", "size": "20"}], "event_type": "book", "last_trade_price": "0.480"}, {"market": "0x4ef52f0dbece2a0ed25442d5ed77cab19af52df4cdf227c768f7c8f3947e406b", "asset_id": "49167555939348657534265757608994619596084656361272295462152725746511889531423", "timestamp": "1769384307444", "hash": "c18ae8d860f310214dd3f62f7cbe2f32bdbbe39f", "bids": [{"price": "0.01", "size": "19.75"}, {"price": "0.02", "size": "1000"}, {"price": "0.03", "size": "6.83"}, {"price": "0.05", "size": "10"}, {"price": "0.06", "size": "200"}, {"price": "0.07", "size": "750"}, {"price": "0.08", "size": "8.71"}, {"price": "0.11", "size": "300"}, {"price": "0.12", "size": "16"}, {"price": "0.65", "size": "3222"}, {"price": "0.68", "size": "5"}, {"price": "0.76", "size": "95.83"}], "asks": [{"price": "0.99", "size": "18.62"}, {"price": "0.98", "size": "5.46"}, {"price": "0.97", "size": "16"}, {"price": "0.96", "size": "8.08"}, {"price": "0.95", "size": "1000"}, {"price": "0.94", "size": "200"}, {"price": "0.93", "size": "100"}, {"price": "0.92", "size": "6.01"}, {"price": "0.9", "size": "100"}, {"price": "0.86", "size": "117.14"}], "event_type": "book", "last_trade_price": ""}, {"market": "0x7ef8134ab1be2f211a03465ba713c5aef3b71532db57b5287ef49f217937d05e", "asset_id": "48424805374840164520274023606217266112677374091090941827104443531363822278032", "timestamp": "1769384058725", "hash": "9171fbc41a93c86843f871474d6a36f457c5a647", "bids": [{"price": "0.01", "size": "10019.35"}, {"price": "0.02", "size": "465.88"}, {"price": "0.03", "size": "31.55"}, {"price": "0.04", "size": "7.17"}], "asks": [{"price": "0.99", "size": "19.72"}, {"price": "0.98", "size": "1000"}, {"price": "0.97", "size": "5.58"}, {"price": "0.96", "size": "12"}, {"price": "0.95", "size": "20"}, {"price": "0.94", "size": "733"}, {"price": "0.93", "size": "10.5"}, {"price": "0.89", "size": "200"}, {"price": "0.88", "size": "250"}, {"price": "0.87", "size": "15"}, {"price": "0.17", "size": "2522"}, {"price": "0.14", "size": "100"}], "event_type": "book", "last_trade_price": ""}, {"market": "0xfef0954af0d43ea46c1ac246ac009dbcd0f76d36fd93b78d3586b23b386028ef", "asset_id": "90954386001801116059251303598368900188182195794057114134644084985964418752977", "timestamp": "1769383156396", "hash": "f74e1c6ae3cb01f3e8f1a52501608527463a437e", "bids": [{"price": "0.01", "size": "15.39"}, {"price": "0.02", "size": "5.13"}, {"price": "0.03", "size": "950"}, {"price": "0.04", "size": "21.08"}, {"price": "0.16", "size": "1000"}, {"price": "0.17", "size": "3025"}, {"price": "0.22", "size": "10"}, {"price": "0.25", "size": "398.66"}, {"price": "0.3", "size": "30.44"}, {"price": "0.31", "size": "818.61"}, {"price": "0.32", "size": "34.13"}], "asks": [{"price": "0.99", "size": "19.91"}, {"price": "0.98", "size": "1000"}, {"price": "0.97", "size": "10.35"}, {"price": "0.94", "size": "1050"}, {"price": "0.93", "size": "250"}, {"price": "0.92", "size": "25"}, {"price": "0.9", "size": "200"}, {"price": "0.89", "size": "205.36"}, {"price": "0.85", "size": "300"}, {"price": "0.84", "size": "200"}, {"price": "0.79", "size": "100"}, {"price": "0.76", "size": "100"}, {"price": "0.73", "size": "100"}, {"price": "0.69", "size": "100"}, {"price": "0.65", "size": "100"}, {"price": "0.63", "size": "100"}, {"price": "0.59", "size": "100"}, {"price": "0.57", "size": "100"}, {"price": "0.54", "size": "100"}, {"price": "0.51", "size": "100"}, {"price": "0.45", "size": "2500"}, {"price": "0.44", "size": "2484.42"}, {"price": "0.43", "size": "10"}, {"price": "0.42", "size": "180"}, {"price": "0.34", "size": "6.83"}, {"price": "0.33", "size": "155.4"}], "event_type": "book", "last_trade_price": "0.670"}, {"market": "0xe3555dc0c83f3ed522993be9d88b3911ccea50eadf348aedc7d2feb6e131bf7b", "asset_id": "2593469348981278329352892292616673852174334474712593978205440358029281457607", "timestamp": "1769384262837", "hash": "51e083b7b0e044b8e7a4ac2c0e0864fed6b31d36", "bids": [{"price": "0.001", "size": "742.31"}, {"price": "0.002", "size": "328.86"}, {"price": "0.003", "size": "134.97"}, {"price": "0.004", "size": "41"}, {"price": "0.005", "size": "34.17"}, {"price": "0.01", "size": "15"}, {"price": "0.011", "size": "14.2"}, {"price": "0.02", "size": "2"}], "asks": [{"price": "0.999", "size": "2396.2"}, {"price": "0.998", "size": "250"}, {"price": "0.997", "size": "29.16"}, {"price": "0.99", "size": "10"}, {"price": "0.98", "size": "1000"}, {"price": "0.979", "size": "8"}, {"price": "0.97", "size": "16"}, {"price": "0.95", "size": "20"}, {"price": "0.949", "size": "39"}, {"price": "0.94", "size": "700"}, {"price": "0.939", "size": "12.03"}, {"price": "0.86", "size": "5320"}, {"price": "0.859", "size": "14"}, {"price": "0.858", "size": "7"}, {"price": "0.8", "size": "20"}, {"price": "0.78", "size": "20"}, {"price": "0.75", "size": "20"}, {"price": "0.71", "size": "10"}, {"price": "0.69", "size": "10"}, {"price": "0.63", "size": "10"}, {"price": "0.62", "size": "10"}, {"price": "0.61", "size": "10"}, {"price": "0.59", "size": "10"}, {"price": "0.55", "size": "20"}, {"price": "0.29", "size": "500"}, {"price": "0.2", "size": "5000"}, {"price": "0.1", "size": "5000"}, {"price": "0.099", "size": "17.73"}], "event_type": "book", "last_trade_price": ""}, {"market": "0x3c4e81bb331e949451e021425d83538b6790a9dd4d58c53f71052b393a9d2798", "asset_id": "62121983685275403626792441079844760950089203544339908194955935543359913360196", "timestamp": "1769384077694", "hash": "6c1a3777aa63552b7032540a833200ba2c06fe6a", "bids": [{"price": "0.01", "size": "22.82"}, {"price": "0.02", "size": "700"}, {"price": "0.03", "size": "82"}, {"price": "0.04", "size": "41"}, {"price": "0.05", "size": "17.43"}, {"price": "0.3", "size": "2222"}, {"price": "0.35", "size": "22.93"}, {"price": "0.36", "size": "10"}], "asks": [{"price": "0.99", "size": "21.42"}, {"price": "0.98", "size": "1025"}, {"price": "0.97", "size": "29.52"}, {"price": "0.75", "size": "200"}, {"price": "0.7", "size": "198.57"}, {"price": "0.69", "size": "5"}, {"price": "0.68", "size": "5"}, {"price": "0.67", "size": "12000"}, {"price": "0.66", "size": "4000"}, {"price": "0.65", "size": "30"}], "event_type": "book", "last_trade_price": ""}, {"market": "0x939bffc79d51cc380bd8507a6de7fcc528a4c13c923762fb4115c949045c7ccd", "asset_id": "25826819136806397270713318817364628011366247262413817412590108086611188733725", "timestamp": "1769382189883", "hash": "89acf3852a36756e6afca66091e0c9731a058f7a", "bids": [{"price": "0.01", "size": "19.95"}, {"price": "0.02", "size": "725"}, {"price": "0.03", "size": "7.14"}, {"price": "0.06", "size": "100"}, {"price": "0.07", "size": "9.8"}, {"price": "0.1", "size": "2222"}, {"price": "0.11", "size": "9.19"}, {"price": "0.12", "size": "129"}, {"price": "0.2", "size": "100"}, {"price": "0.21", "size": "5"}, {"price": "0.3", "size": "100"}], "asks": [{"price": "0.99", "size": "20.06"}, {"price": "0.98", "size": "1000"}, {"price": "0.97", "size": "10.49"}, {"price": "0.95", "size": "10"}, {"price": "0.94", "size": "200"}, {"price": "0.93", "size": "750"}, {"price": "0.9", "size": "10"}, {"price": "0.89", "size": "305.31"}, {"price": "0.88", "size": "16"}, {"price": "0.87", "size": "8.5"}, {"price": "0.83", "size": "50"}, {"price": "0.49", "size": "2222"}, {"price": "0.41", "size": "100"}, {"price": "0.4", "size": "5"}], "event_type": "book", "last_trade_price": ""}, {"market": "0xfef0954af0d43ea46c1ac246ac009dbcd0f76d36fd93b78d3586b23b386028ef", "asset_id": "94516923452105222578438916262485145756699194265211313859088449971552829623384", "timestamp": "1769383156396", "hash": "e6aa61f11308e69f6b55ded5078eecc403d68ab0", "bids": [{"price": "0.01", "size": "19.91"}, {"price": "0.02", "size": "1000"}, {"price": "0.03", "size": "10.35"}, {"price": "0.06", "size": "1050"}, {"price": "0.07", "size": "250"}, {"price": "0.08", "size": "25"}, {"price": "0.1", "size": "200"}, {"price": "0.11", "size": "205.36"}, {"price": "0.15", "size": "300"}, {"price": "0.16", "size": "200"}, {"price": "0.21", "size": "100"}, {"price": "0.24", "size": "100"}, {"price": "0.27", "size": "100"}, {"price": "0.31", "size": "100"}, {"price": "0.35", "size": "100"}, {"price": "0.37", "size": "100"}, {"price": "0.41", "size": "100"}, {"price": "0.43", "size": "100"}, {"price": "0.46", "size": "100"}, {"price": "0.49", "size": "100"}, {"price": "0.55", "size": "2500"}, {"price": "0.56", "size": "2484.42"}, {"price": "0.57", "size": "10"}, {"price": "0.58", "size": "180"}, {"price": "0.66", "size": "6.83"}, {"price": "0.67", "size": "155.4"}], "asks": [{"price": "0.99", "size": "15.39"}, {"price": "0.98", "size": "5.13"}, {"price": "0.97", "size": "950"}, {"price": "0.96", "size": "21.08"}, {"price": "0.84", "size": "1000"}, {"price": "0.83", "size": "3025"}, {"price": "0.78", "size": "10"}, {"price": "0.75", "size": "398.66"}, {"price": "0.7", "size": "30.44"}, {"price": "0.69", "size": "818.61"}, {"price": "0.68", "size": "34.13"}], "event_type": "book", "last_trade_price": "0.670"}, {"market": "0xbfe2fa30664135a1c6a23a5946c2e188f983e27070b8ec450902de6467def4fd", "asset_id": "102157694952739615446333482430328400999996179862836129830073806942742116943263", "timestamp": "1769383688258", "hash": "d9a5b9ea94457d9c384cf26b121982d89dcef529", "bids": [{"price": "0.01", "size": "24.9"}, {"price": "0.02", "size": "1000"}, {"price": "0.03", "size": "16"}, {"price": "0.04", "size": "5.09"}, {"price": "0.05", "size": "520"}, {"price": "0.09", "size": "450"}, {"price": "0.1", "size": "6.47"}, {"price": "0.32", "size": "2222"}, {"price": "0.33", "size": "6"}, {"price": "0.54", "size": "100"}], "asks": [{"price": "0.99", "size": "20.93"}, {"price": "0.98", "size": "700"}, {"price": "0.97", "size": "22.28"}, {"price": "0.94", "size": "750"}, {"price": "0.93", "size": "10.03"}, {"price": "0.73", "size": "2222"}, {"price": "0.68", "size": "100"}, {"price": "0.65", "size": "100"}, {"price": "0.64", "size": "50"}], "event_type": "book", "last_trade_price": ""}, {"market": "0x5bd45ec765062f8547cf89a0cf000cb08e786c1be086907c3b67cd69871ee561", "asset_id": "98968621118077424160807608237664655492529057229450409262637485552625745417020", "timestamp": "1769384194006", "hash": "c7a7a719913f30464aa3bfd7ae2e4dd6fe4cbd0f", "bids": [{"price": "0.01", "size": "20.6"}, {"price": "0.02", "size": "725"}, {"price": "0.03", "size": "8.7"}, {"price": "0.06", "size": "750"}, {"price": "0.08", "size": "300"}, {"price": "0.09", "size": "7.03"}, {"price": "0.27", "size": "2222"}, {"price": "0.33", "size": "100"}, {"price": "0.4", "size": "91.47"}, {"price": "0.42", "size": "10"}, {"price": "0.44", "size": "289.44"}, {"price": "0.45", "size": "20"}], "asks": [{"price": "0.99", "size": "20.39"}, {"price": "0.98", "size": "1000"}, {"price": "0.97", "size": "8.53"}, {"price": "0.95", "size": "10"}, {"price": "0.94", "size": "200"}, {"price": "0.93", "size": "750"}, {"price": "0.92", "size": "25"}, {"price": "0.91", "size": "7.11"}, {"price": "0.89", "size": "300"}, {"price": "0.7", "size": "2222"}, {"price": "0.64", "size": "160"}, {"price": "0.53", "size": "1000"}, {"price": "0.51", "size": "260"}], "event_type": "book", "last_trade_price": "0.480"}, {"market": "0x5171f07c753e4ff897ae62d6ba5b64ca86977cb306e43f7d280df842020c369b", "asset_id": "102969531592712049176088251110843863624391494970245314219392371547409554441222", "timestamp": "1769382219147", "hash": "9124ae58f5ab337ce7df0da9d98f733a8b88d486", "bids": [{"price": "0.01", "size": "20.04"}, {"price": "0.02", "size": "9025"}, {"price": "0.03", "size": "5.76"}, {"price": "0.05", "size": "20"}, {"price": "0.06", "size": "733"}, {"price": "0.07", "size": "10.37"}, {"price": "0.12", "size": "1200"}, {"price": "0.13", "size": "350"}, {"price": "0.14", "size": "14"}, {"price": "0.4", "size": "20"}, {"price": "0.5", "size": "2219.7"}, {"price": "0.52", "size": "15"}, {"price": "0.55", "size": "15"}, {"price": "0.56", "size": "4.72"}, {"price": "0.58", "size": "5"}], "asks": [{"price": "0.99", "size": "45.89"}, {"price": "0.98", "size": "30.34"}, {"price": "0.97", "size": "17.8"}, {"price": "0.96", "size": "5"}], "event_type": "book", "last_trade_price": "0.440"}, {"market": "0x3c4e81bb331e949451e021425d83538b6790a9dd4d58c53f71052b393a9d2798", "asset_id": "21879667973342277146722239426252293266968955555129470642380954877694500852533", "timestamp": "1769384077694", "hash": "9af9d9b858e65199c33cc8e577163a82f194c7ac", "bids": [{"price": "0.01", "size": "21.42"}, {"price": "0.02", "size": "1025"}, {"price": "0.03", "size": "29.52"}, {"price": "0.25", "size": "200"}, {"price": "0.3", "size": "198.57"}, {"price": "0.31", "size": "5"}, {"price": "0.32", "size": "5"}, {"price": "0.33", "size": "12000"}, {"price": "0.34", "size": "4000"}, {"price": "0.35", "size": "30"}], "asks": [{"price": "0.99", "size": "22.82"}, {"price": "0.98", "size": "700"}, {"price": "0.97", "size": "82"}, {"price": "0.96", "size": "41"}, {"price": "0.95", "size": "17.43"}, {"price": "0.7", "size": "2222"}, {"price": "0.65", "size": "22.93"}, {"price": "0.64", "size": "10"}], "event_type": "book", "last_trade_price": ""}, {"market": "0x5171f07c753e4ff897ae62d6ba5b64ca86977cb306e43f7d280df842020c369b", "asset_id": "113700150423978789001063875817280301949767254929935453186800269441668395430876", "timestamp": "1769382219147", "hash": "491efde373d23dbd11de2722c6320f424fe831ec", "bids": [{"price": "0.01", "size": "45.89"}, {"price": "0.02", "size": "30.34"}, {"price": "0.03", "size": "17.8"}, {"price": "0.04", "size": "5"}], "asks": [{"price": "0.99", "size": "20.04"}, {"price": "0.98", "size": "9025"}, {"price": "0.97", "size": "5.76"}, {"price": "0.95", "size": "20"}, {"price": "0.94", "size": "733"}, {"price": "0.93", "size": "10.37"}, {"price": "0.88", "size": "1200"}, {"price": "0.87", "size": "350"}, {"price": "0.86", "size": "14"}, {"price": "0.6", "size": "20"}, {"price": "0.5", "size": "2219.7"}, {"price": "0.48", "size": "15"}, {"price": "0.45", "size": "15"}, {"price": "0.44", "size": "4.72"}, {"price": "0.42", "size": "5"}], "event_type": "book", "last_trade_price": "0.440"}, {"market": "0xb487a276075b688dba579d617391b7dcca5af14c04a6c33d8d03b9248aee0666", "asset_id": "64887912227878003694418361710146660729356626547318586348150482369623624366868", "timestamp": "1769384291759", "hash": "fa4211be74bd95b9eb0017f821f1e26529d56f9a", "bids": [{"price": "0.01", "size": "10015"}, {"price": "0.02", "size": "310.2"}, {"price": "0.03", "size": "256.57"}, {"price": "0.04", "size": "44.34"}], "asks": [{"price": "0.99", "size": "19.69"}, {"price": "0.98", "size": "1000"}, {"price": "0.97", "size": "6.79"}, {"price": "0.96", "size": "12"}, {"price": "0.95", "size": "20"}, {"price": "0.94", "size": "1033"}, {"price": "0.93", "size": "250"}, {"price": "0.92", "size": "8.73"}, {"price": "0.89", "size": "300"}, {"price": "0.88", "size": "16"}, {"price": "0.31", "size": "4201"}, {"price": "0.19", "size": "5"}, {"price": "0.14", "size": "100"}], "event_type": "book", "last_trade_price": ""}, {"market": "0x78e63aac57c774f9de7a75bc1d53d1fcd7e2776b9b42d3f6a3e7a616d40aae9a", "asset_id": "36266464758906463413583307984247565892788766363153201844264292172089273988116", "timestamp": "1769382625649", "hash": "706cea9cf94f026f5b22df2da9504557eaa97dc7", "bids": [{"price": "0.01", "size": "18.79"}, {"price": "0.02", "size": "725"}, {"price": "0.03", "size": "11.28"}, {"price": "0.07", "size": "3333"}, {"price": "0.08", "size": "200"}, {"price": "0.09", "size": "6.37"}, {"price": "0.11", "size": "350"}, {"price": "0.24", "size": "100"}, {"price": "0.25", "size": "5"}], "asks": [{"price": "0.99", "size": "19.85"}, {"price": "0.98", "size": "1000"}, {"price": "0.97", "size": "22.9"}, {"price": "0.94", "size": "200"}, {"price": "0.93", "size": "750"}, {"price": "0.92", "size": "8.67"}, {"price": "0.89", "size": "300"}, {"price": "0.88", "size": "16"}, {"price": "0.45", "size": "3232"}, {"price": "0.39", "size": "5"}, {"price": "0.34", "size": "100"}, {"price": "0.32", "size": "5"}], "event_type": "book", "last_trade_price": ""}, {"market": "0xd8c3fff562711af557abca5e7367dbb892b1d79419b039b6f185e49f21ec6f71", "asset_id": "21296624965887450804742516563526632324551397901259017139941826024484477821625", "timestamp": "1769384154502", "hash": "735aaf2b6cfc48b0c045bbc85f44bb58a642f2e8", "bids": [{"price": "0.01", "size": "19.92"}, {"price": "0.02", "size": "700"}, {"price": "0.03", "size": "8.15"}, {"price": "0.05", "size": "1300"}, {"price": "0.07", "size": "2700"}, {"price": "0.08", "size": "250"}, {"price": "0.09", "size": "7.28"}, {"price": "0.11", "size": "200"}, {"price": "0.13", "size": "555.29"}, {"price": "0.15", "size": "237.1"}, {"price": "0.3", "size": "70.75"}, {"price": "0.32", "size": "20"}, {"price": "0.38", "size": "20"}, {"price": "0.46", "size": "100"}, {"price": "0.5", "size": "100"}, {"price": "0.53", "size": "100"}, {"price": "0.56", "size": "50"}, {"price": "0.58", "size": "57.91"}, {"price": "0.6", "size": "987.5"}, {"price": "0.61", "size": "2432.15"}, {"price": "0.62", "size": "90"}, {"price": "0.63", "size": "9.59"}, {"price": "0.64", "size": "1000"}, {"price": "0.65", "size": "347.73"}], "asks": [{"price": "0.99", "size": "34.21"}, {"price": "0.98", "size": "5.51"}, {"price": "0.96", "size": "1500"}, {"price": "0.95", "size": "300"}, {"price": "0.94", "size": "500"}, {"price": "0.93", "size": "400"}, {"price": "0.92", "size": "25"}, {"price": "0.91", "size": "7.19"}, {"price": "0.89", "size": "100"}, {"price": "0.88", "size": "10"}, {"price": "0.85", "size": "182.32"}, {"price": "0.82", "size": "83.77"}, {"price": "0.8", "size": "100"}, {"price": "0.79", "size": "100"}, {"price": "0.78", "size": "77.11"}, {"price": "0.73", "size": "1000"}, {"price": "0.72", "size": "2242"}, {"price": "0.71", "size": "20"}, {"price": "0.7", "size": "500"}, {"price": "0.69", "size": "320"}, {"price": "0.68", "size": "370.25"}, {"price": "0.67", "size": "227.66"}], "event_type": "book", "last_trade_price": "0.650"}, {"market": "0xbfe2fa30664135a1c6a23a5946c2e188f983e27070b8ec450902de6467def4fd", "asset_id": "45033666566761363846884129311530779372676677319083506152806359111882998427382", "timestamp": "1769383688258", "hash": "0271298b5931732c1a5a614cddb6a583876ede85", "bids": [{"price": "0.01", "size": "20.93"}, {"price": "0.02", "size": "700"}, {"price": "0.03", "size": "22.28"}, {"price": "0.06", "size": "750"}, {"price": "0.07", "size": "10.03"}, {"price": "0.27", "size": "2222"}, {"price": "0.32", "size": "100"}, {"price": "0.35", "size": "100"}, {"price": "0.36", "size": "50"}], "asks": [{"price": "0.99", "size": "24.9"}, {"price": "0.98", "size": "1000"}, {"price": "0.97", "size": "16"}, {"price": "0.96", "size": "5.09"}, {"price": "0.95", "size": "520"}, {"price": "0.91", "size": "450"}, {"price": "0.9", "size": "6.47"}, {"price": "0.68", "size": "2222"}, {"price": "0.67", "size": "6"}, {"price": "0.46", "size": "100"}], "event_type": "book", "last_trade_price": ""}, {"market": "0x78e63aac57c774f9de7a75bc1d53d1fcd7e2776b9b42d3f6a3e7a616d40aae9a", "asset_id": "8565838859908118125528602782033946541871477324767971497979292162371296073977", "timestamp": "1769382625649", "hash": "cf22117c369916460d98c995bac291eab0915290", "bids": [{"price": "0.01", "size": "19.85"}, {"price": "0.02", "size": "1000"}, {"price": "0.03", "size": "22.9"}, {"price": "0.06", "size": "200"}, {"price": "0.07", "size": "750"}, {"price": "0.08", "size": "8.67"}, {"price": "0.11", "size": "300"}, {"price": "0.12", "size": "16"}, {"price": "0.55", "size": "3232"}, {"price": "0.61", "size": "5"}, {"price": "0.66", "size": "100"}, {"price": "0.68", "size": "5"}], "asks": [{"price": "0.99", "size": "18.79"}, {"price": "0.98", "size": "725"}, {"price": "0.97", "size": "11.28"}, {"price": "0.93", "size": "3333"}, {"price": "0.92", "size": "200"}, {"price": "0.91", "size": "6.37"}, {"price": "0.89", "size": "350"}, {"price": "0.76", "size": "100"}, {"price": "0.75", "size": "5"}], "event_type": "book", "last_trade_price": ""}, {"market": "0x1acdabfd96a60a3c5e589a338e1e22bb5a8e90becc40e332e3feda869b8e5617", "asset_id": "104689190054046512741440948464420797532285324388555594252882891393383377276938", "timestamp": "1769384074220", "hash": "cd054150b5379db450b984b89421a5b35303e79b", "bids": [{"price": "0.01", "size": "32.24"}, {"price": "0.02", "size": "6.68"}, {"price": "0.03", "size": "16"}, {"price": "0.04", "size": "16.09"}, {"price": "0.1", "size": "500"}, {"price": "0.13", "size": "100"}, {"price": "0.14", "size": "200"}, {"price": "0.16", "size": "23.75"}], "asks": [{"price": "0.99", "size": "19.74"}, {"price": "0.98", "size": "1000"}, {"price": "0.97", "size": "5.59"}, {"price": "0.95", "size": "10"}, {"price": "0.94", "size": "700"}, {"price": "0.93", "size": "10.49"}, {"price": "0.89", "size": "200"}, {"price": "0.88", "size": "250"}, {"price": "0.87", "size": "15"}, {"price": "0.75", "size": "20"}, {"price": "0.7", "size": "30"}, {"price": "0.34", "size": "2222"}, {"price": "0.33", "size": "100"}, {"price": "0.23", "size": "100"}, {"price": "0.22", "size": "50"}], "event_type": "book", "last_trade_price": "0.800"}, {"market": "0xa49ed4d4d076cb71f2075a1a8a6719780b916d2df248943fa3b2380c73448e27", "asset_id": "369453767067034435107982249854106640068170553019035983752288184199742064968", "timestamp": "1769381470264", "hash": "7003b83333d90c3dfc56284bc1e5d61452775f4b", "bids": [{"price": "0.01", "size": "30.07"}, {"price": "0.02", "size": "7.48"}, {"price": "0.03", "size": "16"}, {"price": "0.05", "size": "20"}, {"price": "0.06", "size": "33"}, {"price": "0.07", "size": "9.28"}, {"price": "0.2", "size": "2222"}, {"price": "0.21", "size": "250"}, {"price": "0.23", "size": "5"}, {"price": "0.25", "size": "5"}, {"price": "0.26", "size": "15"}], "asks": [{"price": "0.99", "size": "69.93"}, {"price": "0.98", "size": "5"}, {"price": "0.96", "size": "12"}, {"price": "0.95", "size": "16.01"}], "event_type": "book", "last_trade_price": ""}, {"market": "0x939bffc79d51cc380bd8507a6de7fcc528a4c13c923762fb4115c949045c7ccd", "asset_id": "44214751861001954999444570118407153044381911853601865828800644284059994656536", "timestamp": "1769382189883", "hash": "babb5d133aa377019f2f9adbb836bd733ed7e340", "bids": [{"price": "0.01", "size": "20.06"}, {"price": "0.02", "size": "1000"}, {"price": "0.03", "size": "10.49"}, {"price": "0.05", "size": "10"}, {"price": "0.06", "size": "200"}, {"price": "0.07", "size": "750"}, {"price": "0.1", "size": "10"}, {"price": "0.11", "size": "305.31"}, {"price": "0.12", "size": "16"}, {"price": "0.13", "size": "8.5"}, {"price": "0.17", "size": "50"}, {"price": "0.51", "size": "2222"}, {"price": "0.59", "size": "100"}, {"price": "0.6", "size": "5"}], "asks": [{"price": "0.99", "size": "19.95"}, {"price": "0.98", "size": "725"}, {"price": "0.97", "size": "7.14"}, {"price": "0.94", "size": "100"}, {"price": "0.93", "size": "9.8"}, {"price": "0.9", "size": "2222"}, {"price": "0.89", "size": "9.19"}, {"price": "0.88", "size": "129"}, {"price": "0.8", "size": "100"}, {"price": "0.79", "size": "5"}, {"price": "0.7", "size": "100"}], "event_type": "book", "last_trade_price": ""}, {"market": "0xd637cf70c23d4fff2aed81d325fcba06992a7af70a011bd0fecf0da2ba0b7fa8", "asset_id": "90283996287531057288260474622112140891469566203169628355432573038893863470116", "timestamp": "1769382170437", "hash": "5b0cdfeb9169cb44eb69821ba36f6b96e29effd5", "bids": [{"price": "0.01", "size": "16.11"}, {"price": "0.02", "size": "46.78"}, {"price": "0.03", "size": "10.07"}, {"price": "0.04", "size": "12"}, {"price": "0.05", "size": "10.41"}, {"price": "0.07", "size": "144.2"}], "asks": [{"price": "0.99", "size": "19.69"}, {"price": "0.98", "size": "1000"}, {"price": "0.97", "size": "6.79"}, {"price": "0.96", "size": "12"}, {"price": "0.95", "size": "20"}, {"price": "0.94", "size": "283"}, {"price": "0.93", "size": "750"}, {"price": "0.92", "size": "8.73"}, {"price": "0.89", "size": "300"}, {"price": "0.88", "size": "16"}, {"price": "0.3", "size": "3000"}, {"price": "0.17", "size": "100"}, {"price": "0.15", "size": "5"}, {"price": "0.14", "size": "5"}], "event_type": "book", "last_trade_price": ""}, {"market": "0x2dc87336b7c13391b66a4e1fc5c32e4ccd78fce4af3357d9f51a1ac7ab9ff7d7", "asset_id": "94986644747328021107943358373766839538488524370650238496966362068504684277317", "timestamp": "1769384102888", "hash": "39ebb2b9bf3881f82ee9b7ea8f1c6cfa88338df3", "bids": [{"price": "0.01", "size": "19.7"}, {"price": "0.02", "size": "1000"}, {"price": "0.03", "size": "22.8"}, {"price": "0.05", "size": "20"}, {"price": "0.06", "size": "233"}, {"price": "0.07", "size": "750"}, {"price": "0.08", "size": "8.73"}, {"price": "0.11", "size": "300"}, {"price": "0.12", "size": "16"}, {"price": "0.65", "size": "3333"}, {"price": "0.66", "size": "10.15"}, {"price": "0.67", "size": "5"}, {"price": "0.82", "size": "82.58"}], "asks": [{"price": "0.99", "size": "10010"}, {"price": "0.98", "size": "209.97"}, {"price": "0.97", "size": "248"}, {"price": "0.96", "size": "20.01"}, {"price": "0.92", "size": "107.72"}], "event_type": "book", "last_trade_price": ""}, {"market": "0x4ef52f0dbece2a0ed25442d5ed77cab19af52df4cdf227c768f7c8f3947e406b", "asset_id": "70582633375518822150370908610496491479177080411181309538524226704006701858828", "timestamp": "1769384307444", "hash": "ab2cb938ee75a7b1a21cf02d9f2b2c0aba080b8f", "bids": [{"price": "0.01", "size": "18.62"}, {"price": "0.02", "size": "5.46"}, {"price": "0.03", "size": "16"}, {"price": "0.04", "size": "8.08"}, {"price": "0.05", "size": "1000"}, {"price": "0.06", "size": "200"}, {"price": "0.07", "size": "100"}, {"price": "0.08", "size": "6.01"}, {"price": "0.1", "size": "100"}, {"price": "0.14", "size": "117.14"}], "asks": [{"price": "0.99", "size": "19.75"}, {"price": "0.98", "size": "1000"}, {"price": "0.97", "size": "6.83"}, {"price": "0.95", "size": "10"}, {"price": "0.94", "size": "200"}, {"price": "0.93", "size": "750"}, {"price": "0.92", "size": "8.71"}, {"price": "0.89", "size": "300"}, {"price": "0.88", "size": "16"}, {"price": "0.35", "size": "3222"}, {"price": "0.32", "size": "5"}, {"price": "0.24", "size": "95.83"}], "event_type": "book", "last_trade_price": ""}, {"market": "0x61eb9153c67924f13fd102a324be284f335672ea1fdb07d48af27a8cd03536be", "asset_id": "99703503368997111194608314266540465795915641214072272571967517894792021713802", "timestamp": "1769384066063", "hash": "db13792f345e79a6d155d2f6cba140d3d67a1f49", "bids": [{"price": "0.01", "size": "19.79"}, {"price": "0.02", "size": "300"}, {"price": "0.03", "size": "955.62"}, {"price": "0.06", "size": "700"}, {"price": "0.07", "size": "10.47"}, {"price": "0.11", "size": "200"}, {"price": "0.12", "size": "400"}, {"price": "0.13", "size": "15"}, {"price": "0.16", "size": "200"}, {"price": "0.22", "size": "200"}, {"price": "0.6", "size": "2222"}, {"price": "0.62", "size": "93.99"}, {"price": "0.67", "size": "1284.38"}, {"price": "0.68", "size": "95"}, {"price": "0.69", "size": "145.66"}, {"price": "0.7", "size": "105.21"}, {"price": "0.72", "size": "59"}], "asks": [{"price": "0.99", "size": "34.12"}, {"price": "0.95", "size": "300"}, {"price": "0.94", "size": "300"}, {"price": "0.93", "size": "300"}, {"price": "0.92", "size": "200"}, {"price": "0.91", "size": "108.43"}, {"price": "0.9", "size": "100"}, {"price": "0.87", "size": "3333"}, {"price": "0.85", "size": "100"}, {"price": "0.82", "size": "530"}, {"price": "0.81", "size": "142.33"}, {"price": "0.8", "size": "239.96"}, {"price": "0.79", "size": "6.67"}, {"price": "0.78", "size": "20"}, {"price": "0.76", "size": "56.35"}, {"price": "0.75", "size": "65.75"}], "event_type": "book", "last_trade_price": ""}, {"market": "0x2dc87336b7c13391b66a4e1fc5c32e4ccd78fce4af3357d9f51a1ac7ab9ff7d7", "asset_id": "65021187363943312373356838202897507539840706541265856092454478728726100225923", "timestamp": "1769384102888", "hash": "05e88d86e71bece804350d3680c3443c2a3db1c6", "bids": [{"price": "0.01", "size": "10010"}, {"price": "0.02", "size": "209.97"}, {"price": "0.03", "size": "248"}, {"price": "0.04", "size": "20.01"}, {"price": "0.08", "size": "107.72"}], "asks": [{"price": "0.99", "size": "19.7"}, {"price": "0.98", "size": "1000"}, {"price": "0.97", "size": "22.8"}, {"price": "0.95", "size": "20"}, {"price": "0.94", "size": "233"}, {"price": "0.93", "size": "750"}, {"price": "0.92", "size": "8.73"}, {"price": "0.89", "size": "300"}, {"price": "0.88", "size": "16"}, {"price": "0.35", "size": "3333"}, {"price": "0.34", "size": "10.15"}, {"price": "0.33", "size": "5"}, {"price": "0.18", "size": "82.58"}], "event_type": "book", "last_trade_price": ""}, {"market": "0xacdacd8f35028e3c1bd46aea3f418813c10cdbb4f29598d1c4bcd3c957d200a5", "asset_id": "41904103824966937957312614591189990152010881969838751171095368082844111306104", "timestamp": "1769382900949", "hash": "a27829084178fd51bfc9fec35d3c055608a31932", "bids": [{"price": "0.01", "size": "69.72"}, {"price": "0.02", "size": "1000"}, {"price": "0.03", "size": "6.81"}, {"price": "0.05", "size": "20"}, {"price": "0.06", "size": "233"}, {"price": "0.07", "size": "750"}, {"price": "0.08", "size": "8.72"}, {"price": "0.11", "size": "300"}, {"price": "0.12", "size": "16"}, {"price": "0.7", "size": "3333"}, {"price": "0.81", "size": "5"}, {"price": "0.85", "size": "100"}], "asks": [{"price": "0.99", "size": "10016.09"}, {"price": "0.98", "size": "460.35"}, {"price": "0.97", "size": "12.81"}, {"price": "0.96", "size": "12"}, {"price": "0.95", "size": "32.32"}], "event_type": "book", "last_trade_price": ""}, {"market": "0xd637cf70c23d4fff2aed81d325fcba06992a7af70a011bd0fecf0da2ba0b7fa8", "asset_id": "70232210583057159849426519112788777542688184091820368797117756012503833407972", "timestamp": "1769382170437", "hash": "9784e8fc6518d7eb200040edcd5b44f7d1c2cc78", "bids": [{"price": "0.01", "size": "19.69"}, {"price": "0.02", "size": "1000"}, {"price": "0.03", "size": "6.79"}, {"price": "0.04", "size": "12"}, {"price": "0.05", "size": "20"}, {"price": "0.06", "size": "283"}, {"price": "0.07", "size": "750"}, {"price": "0.08", "size": "8.73"}, {"price": "0.11", "size": "300"}, {"price": "0.12", "size": "16"}, {"price": "0.7", "size": "3000"}, {"price": "0.83", "size": "100"}, {"price": "0.85", "size": "5"}, {"price": "0.86", "size": "5"}], "asks": [{"price": "0.99", "size": "16.11"}, {"price": "0.98", "size": "46.78"}, {"price": "0.97", "size": "10.07"}, {"price": "0.96", "size": "12"}, {"price": "0.95", "size": "10.41"}, {"price": "0.93", "size": "144.2"}], "event_type": "book", "last_trade_price": ""}, {"market": "0x4f79d1df3869fea9411ed300b9a548e753a5eff1d3dba7ccc71d94403a516730", "asset_id": "68703838894982717863263638275451516028706227474005223647821446099405115633483", "timestamp": "1769384073814", "hash": "939cb880cdc7f4902e5e22f7c8e7e1012da451dc", "bids": [{"price": "0.01", "size": "20.07"}, {"price": "0.02", "size": "1000"}, {"price": "0.03", "size": "7.05"}, {"price": "0.04", "size": "12"}, {"price": "0.06", "size": "200"}, {"price": "0.07", "size": "750"}, {"price": "0.08", "size": "8.59"}, {"price": "0.11", "size": "300"}, {"price": "0.12", "size": "16"}, {"price": "0.13", "size": "8.5"}, {"price": "0.52", "size": "2222"}, {"price": "0.58", "size": "97.61"}], "asks": [{"price": "0.99", "size": "48.76"}, {"price": "0.98", "size": "5.36"}, {"price": "0.97", "size": "16"}, {"price": "0.96", "size": "12.63"}, {"price": "0.87", "size": "2222"}, {"price": "0.86", "size": "8.5"}, {"price": "0.85", "size": "128"}, {"price": "0.75", "size": "50"}, {"price": "0.73", "size": "40"}, {"price": "0.68", "size": "97.62"}], "event_type": "book", "last_trade_price": ""}, {"market": "0x61eb9153c67924f13fd102a324be284f335672ea1fdb07d48af27a8cd03536be", "asset_id": "110029858924336699886026160037881747408385035792394181068515946764057130818147", "timestamp": "1769384066063", "hash": "5fc603ac1636f86dc7b4370678e6aeb243522b0d", "bids": [{"price": "0.01", "size": "34.12"}, {"price": "0.05", "size": "300"}, {"price": "0.06", "size": "300"}, {"price": "0.07", "size": "300"}, {"price": "0.08", "size": "200"}, {"price": "0.09", "size": "108.43"}, {"price": "0.1", "size": "100"}, {"price": "0.13", "size": "3333"}, {"price": "0.15", "size": "100"}, {"price": "0.18", "size": "530"}, {"price": "0.19", "size": "142.33"}, {"price": "0.2", "size": "239.96"}, {"price": "0.21", "size": "6.67"}, {"price": "0.22", "size": "20"}, {"price": "0.24", "size": "56.35"}, {"price": "0.25", "size": "65.75"}], "asks": [{"price": "0.99", "size": "19.79"}, {"price": "0.98", "size": "300"}, {"price": "0.97", "size": "955.62"}, {"price": "0.94", "size": "700"}, {"price": "0.93", "size": "10.47"}, {"price": "0.89", "size": "200"}, {"price": "0.88", "size": "400"}, {"price": "0.87", "size": "15"}, {"price": "0.84", "size": "200"}, {"price": "0.78", "size": "200"}, {"price": "0.4", "size": "2222"}, {"price": "0.38", "size": "93.99"}, {"price": "0.33", "size": "1284.38"}, {"price": "0.32", "size": "95"}, {"price": "0.31", "size": "145.66"}, {"price": "0.3", "size": "105.21"}, {"price": "0.28", "size": "59"}], "event_type": "book", "last_trade_price": ""}, {"market": "0xbd9068da0f92022747bdad7a7d522c2f8bec81f0eb61c233eb94b301b3b4c62b", "asset_id": "80511008047143651192857715625240574605223081773209557920997784819412822146093", "timestamp": "1769381743179", "hash": "b508d896d2022fba3ae2f84c4498a5a2850ee1b2", "bids": [{"price": "0.01", "size": "31.42"}, {"price": "0.02", "size": "5"}, {"price": "0.04", "size": "2000"}, {"price": "0.05", "size": "250"}, {"price": "0.06", "size": "200"}, {"price": "0.07", "size": "800"}, {"price": "0.08", "size": "8.57"}, {"price": "0.11", "size": "700"}, {"price": "0.16", "size": "250"}, {"price": "0.17", "size": "200"}, {"price": "0.21", "size": "200"}, {"price": "0.26", "size": "150"}, {"price": "0.28", "size": "150.27"}, {"price": "0.29", "size": "6"}, {"price": "0.3", "size": "150"}, {"price": "0.32", "size": "100"}, {"price": "0.34", "size": "100"}, {"price": "0.35", "size": "100"}, {"price": "0.36", "size": "8.5"}, {"price": "0.46", "size": "184.14"}, {"price": "0.54", "size": "5434.3"}, {"price": "0.55", "size": "2221"}, {"price": "0.57", "size": "107.86"}, {"price": "0.58", "size": "16.2"}], "asks": [{"price": "0.99", "size": "20.96"}, {"price": "0.98", "size": "1000"}, {"price": "0.97", "size": "8.72"}, {"price": "0.96", "size": "1700"}, {"price": "0.93", "size": "300"}, {"price": "0.92", "size": "7.85"}, {"price": "0.89", "size": "200"}, {"price": "0.88", "size": "250"}, {"price": "0.86", "size": "100"}, {"price": "0.85", "size": "5100"}, {"price": "0.84", "size": "250"}, {"price": "0.83", "size": "100"}, {"price": "0.82", "size": "8.5"}, {"price": "0.81", "size": "5"}, {"price": "0.71", "size": "51"}, {"price": "0.67", "size": "100"}], "event_type": "book", "last_trade_price": ""}, {"market": "0x7ef8134ab1be2f211a03465ba713c5aef3b71532db57b5287ef49f217937d05e", "asset_id": "4626635302826736719019052382121946859205373019864096279488493970906294472445", "timestamp": "1769384058725", "hash": "a6d52f40c6f9c2af0355663e5a75f46d3a7c47b7", "bids": [{"price": "0.01", "size": "19.72"}, {"price": "0.02", "size": "1000"}, {"price": "0.03", "size": "5.58"}, {"price": "0.04", "size": "12"}, {"price": "0.05", "size": "20"}, {"price": "0.06", "size": "733"}, {"price": "0.07", "size": "10.5"}, {"price": "0.11", "size": "200"}, {"price": "0.12", "size": "250"}, {"price": "0.13", "size": "15"}, {"price": "0.83", "size": "2522"}, {"price": "0.86", "size": "100"}], "asks": [{"price": "0.99", "size": "10019.35"}, {"price": "0.98", "size": "465.88"}, {"price": "0.97", "size": "31.55"}, {"price": "0.96", "size": "7.17"}], "event_type": "book", "last_trade_price": ""}, {"market": "0xa9ba962ede8fd5585244b33cc1bf4591468b71753091fb781a2a5b4257520c33", "asset_id": "101531377944005143091286062768662193587086824988143184001837742187395666724540", "timestamp": "1769383937820", "hash": "46d2e94ff6083f2b0eb565bae38d9b5d2f042be0", "bids": [{"price": "0.01", "size": "53.74"}, {"price": "0.02", "size": "5"}, {"price": "0.03", "size": "16"}, {"price": "0.04", "size": "11.56"}, {"price": "0.05", "size": "20"}], "asks": [{"price": "0.99", "size": "20.92"}, {"price": "0.98", "size": "1000"}, {"price": "0.97", "size": "22.27"}, {"price": "0.95", "size": "20"}, {"price": "0.94", "size": "733"}, {"price": "0.93", "size": "10.03"}, {"price": "0.89", "size": "350"}, {"price": "0.88", "size": "16"}, {"price": "0.6", "size": "1111"}], "event_type": "book", "last_trade_price": ""}, {"market": "0xe596f80a42391672c0ee629d1e0cdd2c22e7ce10c48d41fe6c077c8b9ebe6450", "asset_id": "43818978408077968881562541827077043343660554037010800188430505666562965869541", "timestamp": "1769384216212", "hash": "e8c45ec6029ddbfd0d6c12906209c640bb4e23e7", "bids": [{"price": "0.01", "size": "19.97"}, {"price": "0.02", "size": "1025"}, {"price": "0.03", "size": "9.33"}, {"price": "0.05", "size": "520"}, {"price": "0.06", "size": "33"}, {"price": "0.09", "size": "450"}, {"price": "0.1", "size": "6.2"}, {"price": "0.18", "size": "5"}, {"price": "0.35", "size": "2232"}, {"price": "0.39", "size": "5"}, {"price": "0.6", "size": "900"}, {"price": "0.61", "size": "774.43"}], "asks": [{"price": "0.99", "size": "76.25"}, {"price": "0.98", "size": "7.12"}, {"price": "0.96", "size": "35.95"}], "event_type": "book", "last_trade_price": ""}, {"market": "0xacdacd8f35028e3c1bd46aea3f418813c10cdbb4f29598d1c4bcd3c957d200a5", "asset_id": "53774683989206716786063379726028127028904963284294860043549323731703943863930", "timestamp": "1769382900949", "hash": "8b92686d1da8928183866e6cb7d23e42926a8ac6", "bids": [{"price": "0.01", "size": "10016.09"}, {"price": "0.02", "size": "460.35"}, {"price": "0.03", "size": "12.81"}, {"price": "0.04", "size": "12"}, {"price": "0.05", "size": "32.32"}], "asks": [{"price": "0.99", "size": "69.72"}, {"price": "0.98", "size": "1000"}, {"price": "0.97", "size": "6.81"}, {"price": "0.95", "size": "20"}, {"price": "0.94", "size": "233"}, {"price": "0.93", "size": "750"}, {"price": "0.92", "size": "8.72"}, {"price": "0.89", "size": "300"}, {"price": "0.88", "size": "16"}, {"price": "0.3", "size": "3333"}, {"price": "0.19", "size": "5"}, {"price": "0.15", "size": "100"}], "event_type": "book", "last_trade_price": ""}, {"market": "0xd8c3fff562711af557abca5e7367dbb892b1d79419b039b6f185e49f21ec6f71", "asset_id": "18548531003403642447433063414362700271595227164711314812182704727637563149074", "timestamp": "1769384154502", "hash": "ac03975fbd2d7928dc50dae0b17e1eefa37977bd", "bids": [{"price": "0.01", "size": "34.21"}, {"price": "0.02", "size": "5.51"}, {"price": "0.04", "size": "1500"}, {"price": "0.05", "size": "300"}, {"price": "0.06", "size": "500"}, {"price": "0.07", "size": "400"}, {"price": "0.08", "size": "25"}, {"price": "0.09", "size": "7.19"}, {"price": "0.11", "size": "100"}, {"price": "0.12", "size": "10"}, {"price": "0.15", "size": "182.32"}, {"price": "0.18", "size": "83.77"}, {"price": "0.2", "size": "100"}, {"price": "0.21", "size": "100"}, {"price": "0.22", "size": "77.11"}, {"price": "0.27", "size": "1000"}, {"price": "0.28", "size": "2242"}, {"price": "0.29", "size": "20"}, {"price": "0.3", "size": "500"}, {"price": "0.31", "size": "320"}, {"price": "0.32", "size": "370.25"}, {"price": "0.33", "size": "227.66"}], "asks": [{"price": "0.99", "size": "19.92"}, {"price": "0.98", "size": "700"}, {"price": "0.97", "size": "8.15"}, {"price": "0.95", "size": "1300"}, {"price": "0.93", "size": "2700"}, {"price": "0.92", "size": "250"}, {"price": "0.91", "size": "7.28"}, {"price": "0.89", "size": "200"}, {"price": "0.87", "size": "555.29"}, {"price": "0.85", "size": "237.1"}, {"price": "0.7", "size": "70.75"}, {"price": "0.68", "size": "20"}, {"price": "0.62", "size": "20"}, {"price": "0.54", "size": "100"}, {"price": "0.5", "size": "100"}, {"price": "0.47", "size": "100"}, {"price": "0.44", "size": "50"}, {"price": "0.42", "size": "57.91"}, {"price": "0.4", "size": "987.5"}, {"price": "0.39", "size": "2432.15"}, {"price": "0.38", "size": "90"}, {"price": "0.37", "size": "9.59"}, {"price": "0.36", "size": "1000"}, {"price": "0.35", "size": "347.73"}], "event_type": "book", "last_trade_price": "0.650"}, {"market": "0x1acdabfd96a60a3c5e589a338e1e22bb5a8e90becc40e332e3feda869b8e5617", "asset_id": "16779787884916686624599578288494431887254271147898904281123161606926848201450", "timestamp": "1769384074220", "hash": "7a976c2d8f96617deb2908128447979da3193977", "bids": [{"price": "0.01", "size": "19.74"}, {"price": "0.02", "size": "1000"}, {"price": "0.03", "size": "5.59"}, {"price": "0.05", "size": "10"}, {"price": "0.06", "size": "700"}, {"price": "0.07", "size": "10.49"}, {"price": "0.11", "size": "200"}, {"price": "0.12", "size": "250"}, {"price": "0.13", "size": "15"}, {"price": "0.25", "size": "20"}, {"price": "0.3", "size": "30"}, {"price": "0.66", "size": "2222"}, {"price": "0.67", "size": "100"}, {"price": "0.77", "size": "100"}, {"price": "0.78", "size": "50"}], "asks": [{"price": "0.99", "size": "32.24"}, {"price": "0.98", "size": "6.68"}, {"price": "0.97", "size": "16"}, {"price": "0.96", "size": "16.09"}, {"price": "0.9", "size": "500"}, {"price": "0.87", "size": "100"}, {"price": "0.86", "size": "200"}, {"price": "0.84", "size": "23.75"}], "event_type": "book", "last_trade_price": "0.800"}]}
{"_local_timestamp": "2026-01-25T23:40:50.637180+00:00", "data": {"market": "0x4f79d1df3869fea9411ed300b9a548e753a5eff1d3dba7ccc71d94403a516730", "price_changes": [{"asset_id": "68703838894982717863263638275451516028706227474005223647821446099405115633483", "price": "0.12", "size": "0", "side": "BUY", "hash": "05a3bc512f8390b872b967489580dde99b31d730", "best_bid": "0.58", "best_ask": "0.68"}, {"asset_id": "4058613708692092601965760860759243398091398178902937564740140419929508866659", "price": "0.88", "size": "0", "side": "SELL", "hash": "8827044876f7df777a0160ff715c4de669ff4326", "best_bid": "0.32", "best_ask": "0.42"}], "timestamp": "1769384450567", "event_type": "price_change"}}
{"_local_timestamp": "2026-01-25T23:40:50.686821+00:00", "data": {"market": "0x4f79d1df3869fea9411ed300b9a548e753a5eff1d3dba7ccc71d94403a516730", "price_changes": [{"asset_id": "68703838894982717863263638275451516028706227474005223647821446099405115633483", "price": "0.12", "size": "16", "side": "BUY", "hash": "5bb1c9dd9bea1d33d6ab331efc98c32b7a1d9c0a", "best_bid": "0.58", "best_ask": "0.68"}, {"asset_id": "4058613708692092601965760860759243398091398178902937564740140419929508866659", "price": "0.88", "size": "16", "side": "SELL", "hash": "d4bb75f59c78b45fccec26b15cf4484178dec731", "best_bid": "0.32", "best_ask": "0.42"}], "timestamp": "1769384450621", "event_type": "price_change"}}
{"_local_timestamp": "2026-01-25T23:40:54.240770+00:00", "data": {"market": "0x7ef8134ab1be2f211a03465ba713c5aef3b71532db57b5287ef49f217937d05e", "price_changes": [{"asset_id": "48424805374840164520274023606217266112677374091090941827104443531363822278032", "price": "0.01", "size": "10010", "side": "BUY", "hash": "b157cfdf2cd3810e9b4abb575cfbe10f8a8a3d62", "best_bid": "0.04", "best_ask": "0.14"}, {"asset_id": "4626635302826736719019052382121946859205373019864096279488493970906294472445", "price": "0.99", "size": "10010", "side": "SELL", "hash": "01908c8a1633a35b40995d922042429512c15fb9", "best_bid": "0.86", "best_ask": "0.96"}], "timestamp": "1769384454170", "event_type": "price_change"}}
{"_local_timestamp": "2026-01-25T23:40:54.241499+00:00", "data": {"market": "0x1acdabfd96a60a3c5e589a338e1e22bb5a8e90becc40e332e3feda869b8e5617", "price_changes": [{"asset_id": "104689190054046512741440948464420797532285324388555594252882891393383377276938", "price": "0.01", "size": "22.63", "side": "BUY", "hash": "0b6d7a71d5299877e16b0f58e1fc2fb9c37c2651", "best_bid": "0.16", "best_ask": "0.22"}, {"asset_id": "16779787884916686624599578288494431887254271147898904281123161606926848201450", "price": "0.99", "size": "22.63", "side": "SELL", "hash": "f914caccdb8773bbc48cf537355ddf1d4ed9981d", "best_bid": "0.78", "best_ask": "0.84"}], "timestamp": "1769384454170", "event_type": "price_change"}}
{"_local_timestamp": "2026-01-25T23:40:54.241821+00:00", "data": {"market": "0x7ef8134ab1be2f211a03465ba713c5aef3b71532db57b5287ef49f217937d05e", "price_changes": [{"asset_id": "48424805374840164520274023606217266112677374091090941827104443531363822278032", "price": "0.02", "size": "450", "side": "BUY", "hash": "b157cfdf2cd3810e9b4abb575cfbe10f8a8a3d62", "best_bid": "0.04", "best_ask": "0.14"}, {"asset_id": "4626635302826736719019052382121946859205373019864096279488493970906294472445", "price": "0.98", "size": "450", "side": "SELL", "hash": "01908c8a1633a35b40995d922042429512c15fb9", "best_bid": "0.86", "best_ask": "0.96"}], "timestamp": "1769384454170", "event_type": "price_change"}}
{"_local_timestamp": "2026-01-25T23:40:54.242129+00:00", "data": {"market": "0x1acdabfd96a60a3c5e589a338e1e22bb5a8e90becc40e332e3feda869b8e5617", "price_changes": [{"asset_id": "104689190054046512741440948464420797532285324388555594252882891393383377276938", "price": "0.04", "size": "5.64", "side": "BUY", "hash": "0b6d7a71d5299877e16b0f58e1fc2fb9c37c2651", "best_bid": "0.16", "best_ask": "0.22"}, {"asset_id": "16779787884916686624599578288494431887254271147898904281123161606926848201450", "price": "0.96", "size": "5.64", "side": "SELL", "hash": "f914caccdb8773bbc48cf537355ddf1d4ed9981d", "best_bid": "0.78", "best_ask": "0.84"}], "timestamp": "1769384454170", "event_type": "price_change"}}
{"_local_timestamp": "2026-01-25T23:40:54.242402+00:00", "data": {"market": "0x7ef8134ab1be2f211a03465ba713c5aef3b71532db57b5287ef49f217937d05e", "price_changes": [{"asset_id": "48424805374840164520274023606217266112677374091090941827104443531363822278032", "price": "0.03", "size": "21.49", "side": "BUY", "hash": "b157cfdf2cd3810e9b4abb575cfbe10f8a8a3d62", "best_bid": "0.04", "best_ask": "0.14"}, {"asset_id": "4626635302826736719019052382121946859205373019864096279488493970906294472445", "price": "0.97", "size": "21.49", "side": "SELL", "hash": "01908c8a1633a35b40995d922042429512c15fb9", "best_bid": "0.86", "best_ask": "0.96"}], "timestamp": "1769384454170", "event_type": "price_change"}}
{"_local_timestamp": "2026-01-25T23:40:57.355967+00:00", "data": {"market": "0x2dc87336b7c13391b66a4e1fc5c32e4ccd78fce4af3357d9f51a1ac7ab9ff7d7", "price_changes": [{"asset_id": "65021187363943312373356838202897507539840706541265856092454478728726100225923", "price": "0.04", "size": "7.34", "side": "BUY", "hash": "72f56461ed35d1029e3e67c0c6c3ed58c19410ad", "best_bid": "0.08", "best_ask": "0.18"}, {"asset_id": "94986644747328021107943358373766839538488524370650238496966362068504684277317", "price": "0.96", "size": "7.34", "side": "SELL", "hash": "b6751eb07a2e3b7695db409d06bd48a997301726", "best_bid": "0.82", "best_ask": "0.92"}], "timestamp": "1769384457282", "event_type": "price_change"}}
{"_local_timestamp": "2026-01-25T23:40:58.312232+00:00", "data": {"market": "0x7ef8134ab1be2f211a03465ba713c5aef3b71532db57b5287ef49f217937d05e", "price_changes": [{"asset_id": "48424805374840164520274023606217266112677374091090941827104443531363822278032", "price": "0.01", "size": "10019.35", "side": "BUY", "hash": "6ea2ca74867322d4e51edd8a7a9a287edbe2cf31", "best_bid": "0.04", "best_ask": "0.14"}, {"asset_id": "4626635302826736719019052382121946859205373019864096279488493970906294472445", "price": "0.99", "size": "10019.35", "side": "SELL", "hash": "8331453b13d239013d105afe85b9c1ac81e016cd", "best_bid": "0.86", "best_ask": "0.96"}], "timestamp": "1769384457739", "event_type": "price_change"}}
{"_local_timestamp": "2026-01-25T23:40:58.366602+00:00", "data": {"market": "0x1acdabfd96a60a3c5e589a338e1e22bb5a8e90becc40e332e3feda869b8e5617", "price_changes": [{"asset_id": "104689190054046512741440948464420797532285324388555594252882891393383377276938", "price": "0.04", "size": "16.09", "side": "BUY", "hash": "0ee12091752759a843d3a490a5bd9f9a4fd6b354", "best_bid": "0.16", "best_ask": "0.22"}, {"asset_id": "16779787884916686624599578288494431887254271147898904281123161606926848201450", "price": "0.96", "size": "16.09", "side": "SELL", "hash": "5d43b99760de496aba4d77198299b66d2ad62bd6", "best_bid": "0.78", "best_ask": "0.84"}], "timestamp": "1769384457739", "event_type": "price_change"}}
{"_local_timestamp": "2026-01-25T23:40:58.367029+00:00", "data": {"market": "0x1acdabfd96a60a3c5e589a338e1e22bb5a8e90becc40e332e3feda869b8e5617", "price_changes": [{"asset_id": "104689190054046512741440948464420797532285324388555594252882891393383377276938", "price": "0.01", "size": "32.24", "side": "BUY", "hash": "39f228c3ba3802337eb3a54387c9715bd75bd3b4", "best_bid": "0.16", "best_ask": "0.22"}, {"asset_id": "16779787884916686624599578288494431887254271147898904281123161606926848201450", "price": "0.99", "size": "32.24", "side": "SELL", "hash": "8da4c3c0cefd1429cbe9cef0255927903277666f", "best_bid": "0.78", "best_ask": "0.84"}], "timestamp": "1769384457740", "event_type": "price_change"}}
{"_local_timestamp": "2026-01-25T23:40:58.367383+00:00", "data": {"market": "0x7ef8134ab1be2f211a03465ba713c5aef3b71532db57b5287ef49f217937d05e", "price_changes": [{"asset_id": "48424805374840164520274023606217266112677374091090941827104443531363822278032", "price": "0.02", "size": "465.88", "side": "BUY", "hash": "55b1a27172140d3fc5ca1736c600a0b8cdc3b7d8", "best_bid": "0.04", "best_ask": "0.14"}, {"asset_id": "4626635302826736719019052382121946859205373019864096279488493970906294472445", "price": "0.98", "size": "465.88", "side": "SELL", "hash": "6a60bf669994c27b6acdda5bd7ddfc827d2e1163", "best_bid": "0.86", "best_ask": "0.96"}], "timestamp": "1769384457740", "event_type": "price_change"}}
{"_local_timestamp": "2026-01-25T23:40:58.367682+00:00", "data": {"market": "0x7ef8134ab1be2f211a03465ba713c5aef3b71532db57b5287ef49f217937d05e", "price_changes": [{"asset_id": "48424805374840164520274023606217266112677374091090941827104443531363822278032", "price": "0.03", "size": "31.55", "side": "BUY", "hash": "abd7bccccf7e8f1c1848bb889d51d2b3ded82e1e", "best_bid": "0.04", "best_ask": "0.14"}, {"asset_id": "4626635302826736719019052382121946859205373019864096279488493970906294472445", "price": "0.97", "size": "31.55", "side": "SELL", "hash": "93c771afc90e10ab39a207f030a4a8221b095a00", "best_bid": "0.86", "best_ask": "0.96"}], "timestamp": "1769384457741", "event_type": "price_change"}}
{"_local_timestamp": "2026-01-25T23:40:58.368028+00:00", "data": {"market": "0x3c4e81bb331e949451e021425d83538b6790a9dd4d58c53f71052b393a9d2798", "price_changes": [{"asset_id": "62121983685275403626792441079844760950089203544339908194955935543359913360196", "price": "0.05", "size": "0", "side": "BUY", "hash": "7383eb9b0ea0c98d3efc47712fef17a25f3ab9b1", "best_bid": "0.36", "best_ask": "0.65"}, {"asset_id": "21879667973342277146722239426252293266968955555129470642380954877694500852533", "price": "0.95", "size": "0", "side": "SELL", "hash": "58004f031953aae6d1dff7f43ff00cf2817f94e8", "best_bid": "0.35", "best_ask": "0.64"}], "timestamp": "1769384458015", "event_type": "price_change"}}
{"_local_timestamp": "2026-01-25T23:40:58.368363+00:00", "data": {"market": "0x4f79d1df3869fea9411ed300b9a548e753a5eff1d3dba7ccc71d94403a516730", "price_changes": [{"asset_id": "4058613708692092601965760860759243398091398178902937564740140419929508866659", "price": "0.01", "size": "19.04", "side": "BUY", "hash": "11a1390df36aa8ed64848dfaec6d04cdad088135", "best_bid": "0.32", "best_ask": "0.42"}, {"asset_id": "68703838894982717863263638275451516028706227474005223647821446099405115633483", "price": "0.99", "size": "19.04", "side": "SELL", "hash": "f88cdc32da28edb9ef4c9488b05c08135bcce62a", "best_bid": "0.58", "best_ask": "0.68"}], "timestamp": "1769384458015", "event_type": "price_change"}}
{"_local_timestamp": "2026-01-25T23:40:58.474645+00:00", "data": {"market": "0x2dc87336b7c13391b66a4e1fc5c32e4ccd78fce4af3357d9f51a1ac7ab9ff7d7", "price_changes": [{"asset_id": "65021187363943312373356838202897507539840706541265856092454478728726100225923", "price": "0.04", "size": "20.01", "side": "BUY", "hash": "bb32eab84b89feef2d25b27ea9bd2f6a869e39cd", "best_bid": "0.08", "best_ask": "0.18"}, {"asset_id": "94986644747328021107943358373766839538488524370650238496966362068504684277317", "price": "0.96", "size": "20.01", "side": "SELL", "hash": "6e1a5dd38fcc4a9cbc81fadb557eff2cfbe752c4", "best_bid": "0.82", "best_ask": "0.92"}], "timestamp": "1769384458412", "event_type": "price_change"}}
{"_local_timestamp": "2026-01-25T23:41:01.185090+00:00", "data": {"market": "0x3c4e81bb331e949451e021425d83538b6790a9dd4d58c53f71052b393a9d2798", "price_changes": [{"asset_id": "62121983685275403626792441079844760950089203544339908194955935543359913360196", "price": "0.06", "size": "14.53", "side": "BUY", "hash": "ed175e70ba9f393edde5cd06c0b4d7e5d8aef52e", "best_bid": "0.36", "best_ask": "0.65"}, {"asset_id": "21879667973342277146722239426252293266968955555129470642380954877694500852533", "price": "0.94", "size": "14.53", "side": "SELL", "hash": "6a6d506cb6b5c3eeb7343f9ff2a9f87bec1a5756", "best_bid": "0.35", "best_ask": "0.64"}], "timestamp": "1769384461118", "event_type": "price_change"}}
{"_local_timestamp": "2026-01-25T23:41:01.186150+00:00", "data": {"market": "0x4f79d1df3869fea9411ed300b9a548e753a5eff1d3dba7ccc71d94403a516730", "price_changes": [{"asset_id": "4058613708692092601965760860759243398091398178902937564740140419929508866659", "price": "0.01", "size": "48.76", "side": "BUY", "hash": "9dd730b709a28aee6c0bfb329b1f2bc25087e1db", "best_bid": "0.32", "best_ask": "0.42"}, {"asset_id": "68703838894982717863263638275451516028706227474005223647821446099405115633483", "price": "0.99", "size": "48.76", "side": "SELL", "hash": "5fde3f7fb9c29c74b5a6bc77f49909c4710bf010", "best_bid": "0.58", "best_ask": "0.68"}], "timestamp": "1769384461119", "event_type": "price_change"}}
{"_local_timestamp": "2026-01-25T23:41:07.406991+00:00", "data": {"market": "0x61eb9153c67924f13fd102a324be284f335672ea1fdb07d48af27a8cd03536be", "price_changes": [{"asset_id": "110029858924336699886026160037881747408385035792394181068515946764057130818147", "price": "0.09", "size": "100", "side": "BUY", "hash": "d4cd22ae3a0d5d78b9c8e2fd45822b5d9aabcd92", "best_bid": "0.25", "best_ask": "0.28"}, {"asset_id": "99703503368997111194608314266540465795915641214072272571967517894792021713802", "price": "0.91", "size": "100", "side": "SELL", "hash": "be6bc6079e238eb9b938e77f057cfc335c53a743", "best_bid": "0.72", "best_ask": "0.75"}], "timestamp": "1769384467327", "event_type": "price_change"}}
{"_local_timestamp": "2026-01-25T23:41:07.957137+00:00", "data": {"market": "0x61eb9153c67924f13fd102a324be284f335672ea1fdb07d48af27a8cd03536be", "price_changes": [{"asset_id": "110029858924336699886026160037881747408385035792394181068515946764057130818147", "price": "0.09", "size": "108.43", "side": "BUY", "hash": "3fa2b7faa8f357b800f4fd2b1a6b28d2ff9227d5", "best_bid": "0.25", "best_ask": "0.28"}, {"asset_id": "99703503368997111194608314266540465795915641214072272571967517894792021713802", "price": "0.91", "size": "108.43", "side": "SELL", "hash": "2acbdbb1c4c0db994cc82b91ebc8277f5361a29e", "best_bid": "0.72", "best_ask": "0.75"}], "timestamp": "1769384467891", "event_type": "price_change"}}
{"_local_timestamp": "2026-01-25T23:41:34.784379+00:00", "data": {"market": "0xe596f80a42391672c0ee629d1e0cdd2c22e7ce10c48d41fe6c077c8b9ebe6450", "price_changes": [{"asset_id": "43818978408077968881562541827077043343660554037010800188430505666562965869541", "price": "0.18", "size": "0", "side": "BUY", "hash": "cc41fa3e48c3044a809eef3fcff5f59b0163c583", "best_bid": "0.61", "best_ask": "0.96"}, {"asset_id": "112137718731147502310390559685098534923233818767269408035162170801812461954759", "price": "0.82", "size": "0", "side": "SELL", "hash": "07f70554600ae8f2d75a5f12b56c4ad0eecc02c0", "best_bid": "0.04", "best_ask": "0.39"}], "timestamp": "1769384494587", "event_type": "price_change"}}
{"_local_timestamp": "2026-01-25T23:41:35.235432+00:00", "data": {"market": "0xe596f80a42391672c0ee629d1e0cdd2c22e7ce10c48d41fe6c077c8b9ebe6450", "price_changes": [{"asset_id": "43818978408077968881562541827077043343660554037010800188430505666562965869541", "price": "0.18", "size": "5", "side": "BUY", "hash": "a986010cabec53de47de298b5d6d45cea0c3a3e0", "best_bid": "0.61", "best_ask": "0.96"}, {"asset_id": "112137718731147502310390559685098534923233818767269408035162170801812461954759", "price": "0.82", "size": "5", "side": "SELL", "hash": "e7afba4dc4ee7c9b8f704637b11a06b9ab936f0b", "best_bid": "0.04", "best_ask": "0.39"}], "timestamp": "1769384495101", "event_type": "price_change"}}
{"_local_timestamp": "2026-01-25T23:41:38.213228+00:00", "data": {"market": "0xb487a276075b688dba579d617391b7dcca5af14c04a6c33d8d03b9248aee0666", "price_changes": [{"asset_id": "58989659540855401044403336386853959781245409394903503665327101381123074880370", "price": "0.81", "size": "0", "side": "BUY", "hash": "992da601e6a108428ffa5af3949e686e4006de74", "best_bid": "0.86", "best_ask": "0.96"}, {"asset_id": "64887912227878003694418361710146660729356626547318586348150482369623624366868", "price": "0.19", "size": "0", "side": "SELL", "hash": "ab206cdffab1077ccd4c9564adb1174be93a0c79", "best_bid": "0.04", "best_ask": "0.14"}], "timestamp": "1769384498085", "event_type": "price_change"}}
{"_local_timestamp": "2026-01-25T23:41:38.605121+00:00", "data": {"market": "0xb487a276075b688dba579d617391b7dcca5af14c04a6c33d8d03b9248aee0666", "price_changes": [{"asset_id": "58989659540855401044403336386853959781245409394903503665327101381123074880370", "price": "0.81", "size": "5", "side": "BUY", "hash": "4b20055781873c1bcd04c1d2d341f868513f7ac7", "best_bid": "0.86", "best_ask": "0.96"}, {"asset_id": "64887912227878003694418361710146660729356626547318586348150482369623624366868", "price": "0.19", "size": "5", "side": "SELL", "hash": "f87374c30e11ef6f895b96dbade72e0ec9151710", "best_bid": "0.04", "best_ask": "0.14"}], "timestamp": "1769384498470", "event_type": "price_change"}}
{"_local_timestamp": "2026-01-25T23:42:01.555846+00:00", "data": {"market": "0xe3555dc0c83f3ed522993be9d88b3911ccea50eadf348aedc7d2feb6e131bf7b", "price_changes": [{"asset_id": "2593469348981278329352892292616673852174334474712593978205440358029281457607", "price": "0.002", "size": "225.94", "side": "BUY", "hash": "ab8b4eb102348499f0fcf475991bb101cddbce09", "best_bid": "0.02", "best_ask": "0.099"}, {"asset_id": "99817858714934748044341796488555563612713307921513659300432008966728516900242", "price": "0.998", "size": "225.94", "side": "SELL", "hash": "f8898188f8e0135aca8e1393a54595b02be846c2", "best_bid": "0.901", "best_ask": "0.98"}], "timestamp": "1769384521479", "event_type": "price_change"}}
{"_local_timestamp": "2026-01-25T23:42:02.383657+00:00", "data": {"market": "0xe3555dc0c83f3ed522993be9d88b3911ccea50eadf348aedc7d2feb6e131bf7b", "price_changes": [{"asset_id": "2593469348981278329352892292616673852174334474712593978205440358029281457607", "price": "0.002", "size": "328.86", "side": "BUY", "hash": "e95a80cb1596c45699cf14182c47b85a0a3e07f6", "best_bid": "0.02", "best_ask": "0.099"}, {"asset_id": "99817858714934748044341796488555563612713307921513659300432008966728516900242", "price": "0.998", "size": "328.86", "side": "SELL", "hash": "2712e903560c1870467673bd79669a1e3026c39a", "best_bid": "0.901", "best_ask": "0.98"}], "timestamp": "1769384522313", "event_type": "price_change"}}
{"_local_timestamp": "2026-01-25T23:42:31.387582+00:00", "data": {"market": "0xe596f80a42391672c0ee629d1e0cdd2c22e7ce10c48d41fe6c077c8b9ebe6450", "price_changes": [{"asset_id": "43818978408077968881562541827077043343660554037010800188430505666562965869541", "price": "0.18", "size": "0", "side": "BUY", "hash": "c95ab535986fcabd6b491479388582ac39367d88", "best_bid": "0.61", "best_ask": "0.96"}, {"asset_id": "112137718731147502310390559685098534923233818767269408035162170801812461954759", "price": "0.82", "size": "0", "side": "SELL", "hash": "1899e0d8e617ceb289d20a587d04d593fe4bb80e", "best_bid": "0.04", "best_ask": "0.39"}], "timestamp": "1769384551323", "event_type": "price_change"}}
{"_local_timestamp": "2026-01-25T23:42:31.722152+00:00", "data": {"market": "0xe596f80a42391672c0ee629d1e0cdd2c22e7ce10c48d41fe6c077c8b9ebe6450", "price_changes": [{"asset_id": "43818978408077968881562541827077043343660554037010800188430505666562965869541", "price": "0.18", "size": "5", "side": "BUY", "hash": "c0b833a8eadbf012730b62c5c2ca4225f7e5b84e", "best_bid": "0.61", "best_ask": "0.96"}, {"asset_id": "112137718731147502310390559685098534923233818767269408035162170801812461954759", "price": "0.82", "size": "5", "side": "SELL", "hash": "03ffc05a8b56856bbe75a0a6d0d07c6eb795404e", "best_bid": "0.04", "best_ask": "0.39"}], "timestamp": "1769384551655", "event_type": "price_change"}}
{"_local_timestamp": "2026-01-25T23:42:35.405493+00:00", "data": {"market": "0xb487a276075b688dba579d617391b7dcca5af14c04a6c33d8d03b9248aee0666", "price_changes": [{"asset_id": "58989659540855401044403336386853959781245409394903503665327101381123074880370", "price": "0.81", "size": "0", "side": "BUY", "hash": "fbefae50943a59c092050fa26425edc12e0f50bc", "best_bid": "0.86", "best_ask": "0.96"}, {"asset_id": "64887912227878003694418361710146660729356626547318586348150482369623624366868", "price": "0.19", "size": "0", "side": "SELL", "hash": "82933478f8c060fb51d174229c007aa61ab27514", "best_bid": "0.04", "best_ask": "0.14"}], "timestamp": "1769384555332", "event_type": "price_change"}}
{"_local_timestamp": "2026-01-25T23:42:36.038552+00:00", "data": {"market": "0xb487a276075b688dba579d617391b7dcca5af14c04a6c33d8d03b9248aee0666", "price_changes": [{"asset_id": "58989659540855401044403336386853959781245409394903503665327101381123074880370", "price": "0.81", "size": "5", "side": "BUY", "hash": "b0626e3e07942ba0e10f4c8df0f2638f9153c1ab", "best_bid": "0.86", "best_ask": "0.96"}, {"asset_id": "64887912227878003694418361710146660729356626547318586348150482369623624366868", "price": "0.19", "size": "5", "side": "SELL", "hash": "2efa6997325d67e50b86622c2c00ccc54cb00c25", "best_bid": "0.04", "best_ask": "0.14"}], "timestamp": "1769384555968", "event_type": "price_change"}}
{"_local_timestamp": "2026-01-25T23:43:08.510531+00:00", "data": {"market": "0xbd9068da0f92022747bdad7a7d522c2f8bec81f0eb61c233eb94b301b3b4c62b", "price_changes": [{"asset_id": "80511008047143651192857715625240574605223081773209557920997784819412822146093", "price": "0.29", "size": "0", "side": "BUY", "hash": "21ae785a52496fecef745db1b98dcdd982ee8f5c", "best_bid": "0.58", "best_ask": "0.67"}, {"asset_id": "107726477169398763643300346937218981578070170096670253959564188912978677384086", "price": "0.71", "size": "0", "side": "SELL", "hash": "d5130c64e9dc93307e1cdc963f463240b9a67431", "best_bid": "0.33", "best_ask": "0.42"}], "timestamp": "1769384588384", "event_type": "price_change"}}
{"_local_timestamp": "2026-01-25T23:43:08.561147+00:00", "data": {"market": "0xbd9068da0f92022747bdad7a7d522c2f8bec81f0eb61c233eb94b301b3b4c62b", "price_changes": [{"asset_id": "80511008047143651192857715625240574605223081773209557920997784819412822146093", "price": "0.29", "size": "6", "side": "BUY", "hash": "d2779c1bd3f5b0b4ed627ad1694cef12b0b9694e", "best_bid": "0.58", "best_ask": "0.67"}, {"asset_id": "107726477169398763643300346937218981578070170096670253959564188912978677384086", "price": "0.71", "size": "6", "side": "SELL", "hash": "9cbc1fcf63662b2572d7901d8b2d4dec2aa0a4b6", "best_bid": "0.33", "best_ask": "0.42"}], "timestamp": "1769384588432", "event_type": "price_change"}}
{"_local_timestamp": "2026-01-25T23:43:19.143223+00:00", "data": {"market": "0xe596f80a42391672c0ee629d1e0cdd2c22e7ce10c48d41fe6c077c8b9ebe6450", "price_changes": [{"asset_id": "43818978408077968881562541827077043343660554037010800188430505666562965869541", "price": "0.18", "size": "0", "side": "BUY", "hash": "6d1ada565ac703189c9e516f848bff54e837b135", "best_bid": "0.61", "best_ask": "0.96"}, {"asset_id": "112137718731147502310390559685098534923233818767269408035162170801812461954759", "price": "0.82", "size": "0", "side": "SELL", "hash": "07a69de006f9c360771626cff2cece5f0622f5f8", "best_bid": "0.04", "best_ask": "0.39"}], "timestamp": "1769384599081", "event_type": "price_change"}}
{"_local_timestamp": "2026-01-25T23:43:19.552667+00:00", "data": {"market": "0xe596f80a42391672c0ee629d1e0cdd2c22e7ce10c48d41fe6c077c8b9ebe6450", "price_changes": [{"asset_id": "43818978408077968881562541827077043343660554037010800188430505666562965869541", "price": "0.18", "size": "5", "side": "BUY", "hash": "1b88dcb1b3794b2b0ee9fa2c9ab92e241f8e26ca", "best_bid": "0.61", "best_ask": "0.96"}, {"asset_id": "112137718731147502310390559685098534923233818767269408035162170801812461954759", "price": "0.82", "size": "5", "side": "SELL", "hash": "88121178a92d42ea5c92aa16e08c7cbee9350abd", "best_bid": "0.04", "best_ask": "0.39"}], "timestamp": "1769384599489", "event_type": "price_change"}}
{"_local_timestamp": "2026-01-25T23:43:25.371143+00:00", "data": {"market": "0xb487a276075b688dba579d617391b7dcca5af14c04a6c33d8d03b9248aee0666", "price_changes": [{"asset_id": "58989659540855401044403336386853959781245409394903503665327101381123074880370", "price": "0.81", "size": "0", "side": "BUY", "hash": "5efb52cfe4b12737c82ac62c1af23969628eb0c3", "best_bid": "0.86", "best_ask": "0.96"}, {"asset_id": "64887912227878003694418361710146660729356626547318586348150482369623624366868", "price": "0.19", "size": "0", "side": "SELL", "hash": "702067f2bf6336e6036c747da093bad23b37ad05", "best_bid": "0.04", "best_ask": "0.14"}], "timestamp": "1769384605310", "event_type": "price_change"}}
{"_local_timestamp": "2026-01-25T23:43:25.615558+00:00", "data": {"market": "0xb487a276075b688dba579d617391b7dcca5af14c04a6c33d8d03b9248aee0666", "price_changes": [{"asset_id": "58989659540855401044403336386853959781245409394903503665327101381123074880370", "price": "0.81", "size": "5", "side": "BUY", "hash": "fdcc51fd37d478aa747ba7bb533112b90087e922", "best_bid": "0.86", "best_ask": "0.96"}, {"asset_id": "64887912227878003694418361710146660729356626547318586348150482369623624366868", "price": "0.19", "size": "5", "side": "SELL", "hash": "79135dafc354df89c08d2e65d10d9bcf17b35d46", "best_bid": "0.04", "best_ask": "0.14"}], "timestamp": "1769384605550", "event_type": "price_change"}}
{"_local_timestamp": "2026-01-25T23:44:06.574100+00:00", "data": {"market": "0xe596f80a42391672c0ee629d1e0cdd2c22e7ce10c48d41fe6c077c8b9ebe6450", "price_changes": [{"asset_id": "43818978408077968881562541827077043343660554037010800188430505666562965869541", "price": "0.18", "size": "0", "side": "BUY", "hash": "18a2ba35ac0a769376e6be121cbbc0abb10cb253", "best_bid": "0.61", "best_ask": "0.96"}, {"asset_id": "112137718731147502310390559685098534923233818767269408035162170801812461954759", "price": "0.82", "size": "0", "side": "SELL", "hash": "676f0082e95507354e5c6977f43cb6e13e64be09", "best_bid": "0.04", "best_ask": "0.39"}], "timestamp": "1769384646510", "event_type": "price_change"}}
{"_local_timestamp": "2026-01-25T23:44:06.867463+00:00", "data": {"market": "0xe596f80a42391672c0ee629d1e0cdd2c22e7ce10c48d41fe6c077c8b9ebe6450", "price_changes": [{"asset_id": "43818978408077968881562541827077043343660554037010800188430505666562965869541", "price": "0.18", "size": "5", "side": "BUY", "hash": "1e83902a427356131038db62f74e9a7adbbb9e80", "best_bid": "0.61", "best_ask": "0.96"}, {"asset_id": "112137718731147502310390559685098534923233818767269408035162170801812461954759", "price": "0.82", "size": "5", "side": "SELL", "hash": "71f14ff0758447cb26ac46eaec61d9aceee488fb", "best_bid": "0.04", "best_ask": "0.39"}], "timestamp": "1769384646765", "event_type": "price_change"}}
{"_local_timestamp": "2026-01-25T23:44:09.248494+00:00", "data": {"market": "0xb487a276075b688dba579d617391b7dcca5af14c04a6c33d8d03b9248aee0666", "price_changes": [{"asset_id": "58989659540855401044403336386853959781245409394903503665327101381123074880370", "price": "0.81", "size": "0", "side": "BUY", "hash": "c99e738ad0172f5d221b8d0306f79d4b7b1dabee", "best_bid": "0.86", "best_ask": "0.96"}, {"asset_id": "64887912227878003694418361710146660729356626547318586348150482369623624366868", "price": "0.19", "size": "0", "side": "SELL", "hash": "10ee180c9c666cca6d97073acb0e0d21591a72ca", "best_bid": "0.04", "best_ask": "0.14"}], "timestamp": "1769384649182", "event_type": "price_change"}}
{"_local_timestamp": "2026-01-25T23:44:09.639941+00:00", "data": {"market": "0xb487a276075b688dba579d617391b7dcca5af14c04a6c33d8d03b9248aee0666", "price_changes": [{"asset_id": "58989659540855401044403336386853959781245409394903503665327101381123074880370", "price": "0.81", "size": "5", "side": "BUY", "hash": "463a2a3a2735912642a8f064b2e4c583b203ebf5", "best_bid": "0.86", "best_ask": "0.96"}, {"asset_id": "64887912227878003694418361710146660729356626547318586348150482369623624366868", "price": "0.19", "size": "5", "side": "SELL", "hash": "209ac4dd8e7efa510df91a8065ac5b6f4c57bf25", "best_bid": "0.04", "best_ask": "0.14"}], "timestamp": "1769384649570", "event_type": "price_change"}}
{"_local_timestamp": "2026-01-25T23:44:16.223602+00:00", "data": {"market": "0x61eb9153c67924f13fd102a324be284f335672ea1fdb07d48af27a8cd03536be", "price_changes": [{"asset_id": "99703503368997111194608314266540465795915641214072272571967517894792021713802", "price": "0.13", "size": "0", "side": "BUY", "hash": "e8308c963ad34d3f71998e2624d321ae6ef0f909", "best_bid": "0.72", "best_ask": "0.75"}, {"asset_id": "110029858924336699886026160037881747408385035792394181068515946764057130818147", "price": "0.87", "size": "0", "side": "SELL", "hash": "3efc4ee0daced9514fc65996d78af9d050f5c111", "best_bid": "0.25", "best_ask": "0.28"}], "timestamp": "1769384656156", "event_type": "price_change"}}
{"_local_timestamp": "2026-01-25T23:44:16.268050+00:00", "data": {"market": "0x61eb9153c67924f13fd102a324be284f335672ea1fdb07d48af27a8cd03536be", "price_changes": [{"asset_id": "99703503368997111194608314266540465795915641214072272571967517894792021713802", "price": "0.13", "size": "15", "side": "BUY", "hash": "a59d1ada2b75da7633e306ad556aab4abb1eb016", "best_bid": "0.72", "best_ask": "0.75"}, {"asset_id": "110029858924336699886026160037881747408385035792394181068515946764057130818147", "price": "0.87", "size": "15", "side": "SELL", "hash": "475f03d1e8b6443a966e1677500a71b347a8b930", "best_bid": "0.25", "best_ask": "0.28"}], "timestamp": "1769384656202", "event_type": "price_change"}}
{"_local_timestamp": "2026-01-25T23:44:50.583210+00:00", "data": {"market": "0xe596f80a42391672c0ee629d1e0cdd2c22e7ce10c48d41fe6c077c8b9ebe6450", "price_changes": [{"asset_id": "43818978408077968881562541827077043343660554037010800188430505666562965869541", "price": "0.18", "size": "0", "side": "BUY", "hash": "d0f9b8202a9f46073b812e25353db35ff522c26c", "best_bid": "0.61", "best_ask": "0.96"}, {"asset_id": "112137718731147502310390559685098534923233818767269408035162170801812461954759", "price": "0.82", "size": "0", "side": "SELL", "hash": "7d73a2ea3d5fb7884170855141461f62457ea0e9", "best_bid": "0.04", "best_ask": "0.39"}], "timestamp": "1769384690285", "event_type": "price_change"}}
{"_local_timestamp": "2026-01-25T23:44:50.708082+00:00", "data": {"market": "0xe596f80a42391672c0ee629d1e0cdd2c22e7ce10c48d41fe6c077c8b9ebe6450", "price_changes": [{"asset_id": "43818978408077968881562541827077043343660554037010800188430505666562965869541", "price": "0.18", "size": "5", "side": "BUY", "hash": "1b6b1d1795364221a5eb03dd78d5bdeeb2a2b819", "best_bid": "0.61", "best_ask": "0.96"}, {"asset_id": "112137718731147502310390559685098534923233818767269408035162170801812461954759", "price": "0.82", "size": "5", "side": "SELL", "hash": "43b3bf0f1867e2e63827e8df22a60b5bb9fd1849", "best_bid": "0.04", "best_ask": "0.39"}], "timestamp": "1769384690641", "event_type": "price_change"}}
{"_local_timestamp": "2026-01-25T23:44:54.819728+00:00", "data": {"market": "0xb487a276075b688dba579d617391b7dcca5af14c04a6c33d8d03b9248aee0666", "price_changes": [{"asset_id": "58989659540855401044403336386853959781245409394903503665327101381123074880370", "price": "0.81", "size": "0", "side": "BUY", "hash": "40907258de84dcfd38a3c8a2cf10260ddd45cefe", "best_bid": "0.86", "best_ask": "0.96"}, {"asset_id": "64887912227878003694418361710146660729356626547318586348150482369623624366868", "price": "0.19", "size": "0", "side": "SELL", "hash": "7bcea36af0d8691b78d8c0c8071b0b0a9e5b73fd", "best_bid": "0.04", "best_ask": "0.14"}], "timestamp": "1769384694740", "event_type": "price_change"}}
{"_local_timestamp": "2026-01-25T23:44:55.573369+00:00", "data": {"market": "0xb487a276075b688dba579d617391b7dcca5af14c04a6c33d8d03b9248aee0666", "price_changes": [{"asset_id": "58989659540855401044403336386853959781245409394903503665327101381123074880370", "price": "0.81", "size": "5", "side": "BUY", "hash": "353d20ebde6225cc970666b5f4f8513ed3fac92b", "best_bid": "0.86", "best_ask": "0.96"}, {"asset_id": "64887912227878003694418361710146660729356626547318586348150482369623624366868", "price": "0.19", "size": "5", "side": "SELL", "hash": "ff0d1c95efbf83f29b337d250b6d5c0ada181014", "best_bid": "0.04", "best_ask": "0.14"}], "timestamp": "1769384695491", "event_type": "price_change"}}
{"_local_timestamp": "2026-01-25T23:44:59.316376+00:00", "data": {"market": "0x1acdabfd96a60a3c5e589a338e1e22bb5a8e90becc40e332e3feda869b8e5617", "price_changes": [{"asset_id": "104689190054046512741440948464420797532285324388555594252882891393383377276938", "price": "0.01", "size": "22.63", "side": "BUY", "hash": "bafee6f793a915f1efa42fbfc7bf6947340e9ee0", "best_bid": "0.16", "best_ask": "0.22"}, {"asset_id": "16779787884916686624599578288494431887254271147898904281123161606926848201450", "price": "0.99", "size": "22.63", "side": "SELL", "hash": "69ba50b14171d1a4b12c67ae2a13ec4e98a10fa2", "best_bid": "0.78", "best_ask": "0.84"}], "timestamp": "1769384699250", "event_type": "price_change"}}
{"_local_timestamp": "2026-01-25T23:44:59.316860+00:00", "data": {"market": "0x1acdabfd96a60a3c5e589a338e1e22bb5a8e90becc40e332e3feda869b8e5617", "price_changes": [{"asset_id": "104689190054046512741440948464420797532285324388555594252882891393383377276938", "price": "0.04", "size": "5.64", "side": "BUY", "hash": "bafee6f793a915f1efa42fbfc7bf6947340e9ee0", "best_bid": "0.16", "best_ask": "0.22"}, {"asset_id": "16779787884916686624599578288494431887254271147898904281123161606926848201450", "price": "0.96", "size": "5.64", "side": "SELL", "hash": "69ba50b14171d1a4b12c67ae2a13ec4e98a10fa2", "best_bid": "0.78", "best_ask": "0.84"}], "timestamp": "1769384699250", "event_type": "price_change"}}
{"_local_timestamp": "2026-01-25T23:45:01.060258+00:00", "data": {"market": "0x1acdabfd96a60a3c5e589a338e1e22bb5a8e90becc40e332e3feda869b8e5617", "price_changes": [{"asset_id": "104689190054046512741440948464420797532285324388555594252882891393383377276938", "price": "0.04", "size": "16.09", "side": "BUY", "hash": "a87d617522a202f057dd368d0404d27e905fd1d2", "best_bid": "0.16", "best_ask": "0.22"}, {"asset_id": "16779787884916686624599578288494431887254271147898904281123161606926848201450", "price": "0.96", "size": "16.09", "side": "SELL", "hash": "814e29a8d4de169aac9adeb3986c048bf2bfdc49", "best_bid": "0.78", "best_ask": "0.84"}], "timestamp": "1769384700993", "event_type": "price_change"}}
{"_local_timestamp": "2026-01-25T23:45:01.060766+00:00", "data": {"market": "0x1acdabfd96a60a3c5e589a338e1e22bb5a8e90becc40e332e3feda869b8e5617", "price_changes": [{"asset_id": "104689190054046512741440948464420797532285324388555594252882891393383377276938", "price": "0.01", "size": "32.24", "side": "BUY", "hash": "4ff2fbcefa6ff74765f5de5caec38e3539bd9b10", "best_bid": "0.16", "best_ask": "0.22"}, {"asset_id": "16779787884916686624599578288494431887254271147898904281123161606926848201450", "price": "0.99", "size": "32.24", "side": "SELL", "hash": "ddc7be60826c580b9dc33c07460448a535742b56", "best_bid": "0.78", "best_ask": "0.84"}], "timestamp": "1769384700994", "event_type": "price_change"}}
{"_local_timestamp": "2026-01-25T23:45:01.216923+00:00", "data": {"market": "0x7ef8134ab1be2f211a03465ba713c5aef3b71532db57b5287ef49f217937d05e", "price_changes": [{"asset_id": "48424805374840164520274023606217266112677374091090941827104443531363822278032", "price": "0.01", "size": "10010", "side": "BUY", "hash": "bbf7333a1026f7063e0afc852eb75454176862ff", "best_bid": "0.04", "best_ask": "0.14"}, {"asset_id": "4626635302826736719019052382121946859205373019864096279488493970906294472445", "price": "0.99", "size": "10010", "side": "SELL", "hash": "31ee37aedd8c745e362c537cf5090f6a73335db3", "best_bid": "0.86", "best_ask": "0.96"}], "timestamp": "1769384701137", "event_type": "price_change"}}
{"_local_timestamp": "2026-01-25T23:45:01.217370+00:00", "data": {"market": "0x7ef8134ab1be2f211a03465ba713c5aef3b71532db57b5287ef49f217937d05e", "price_changes": [{"asset_id": "48424805374840164520274023606217266112677374091090941827104443531363822278032", "price": "0.02", "size": "450", "side": "BUY", "hash": "bbf7333a1026f7063e0afc852eb75454176862ff", "best_bid": "0.04", "best_ask": "0.14"}, {"asset_id": "4626635302826736719019052382121946859205373019864096279488493970906294472445", "price": "0.98", "size": "450", "side": "SELL", "hash": "31ee37aedd8c745e362c537cf5090f6a73335db3", "best_bid": "0.86", "best_ask": "0.96"}], "timestamp": "1769384701137", "event_type": "price_change"}}
{"_local_timestamp": "2026-01-25T23:45:01.217745+00:00", "data": {"market": "0x7ef8134ab1be2f211a03465ba713c5aef3b71532db57b5287ef49f217937d05e", "price_changes": [{"asset_id": "48424805374840164520274023606217266112677374091090941827104443531363822278032", "price": "0.03", "size": "21.49", "side": "BUY", "hash": "bbf7333a1026f7063e0afc852eb75454176862ff", "best_bid": "0.04", "best_ask": "0.14"}, {"asset_id": "4626635302826736719019052382121946859205373019864096279488493970906294472445", "price": "0.97", "size": "21.49", "side": "SELL", "hash": "31ee37aedd8c745e362c537cf5090f6a73335db3", "best_bid": "0.86", "best_ask": "0.96"}], "timestamp": "1769384701137", "event_type": "price_change"}}
{"_local_timestamp": "2026-01-25T23:45:01.798043+00:00", "data": {"market": "0x7ef8134ab1be2f211a03465ba713c5aef3b71532db57b5287ef49f217937d05e", "price_changes": [{"asset_id": "48424805374840164520274023606217266112677374091090941827104443531363822278032", "price": "0.01", "size": "10019.35", "side": "BUY", "hash": "da99cdf778500c7890e2cf92687ef2507895c57d", "best_bid": "0.04", "best_ask": "0.14"}, {"asset_id": "4626635302826736719019052382121946859205373019864096279488493970906294472445", "price": "0.99", "size": "10019.35", "side": "SELL", "hash": "e3fddbd1ffb8e9568553581b16f4fa0f19a15a54", "best_bid": "0.86", "best_ask": "0.96"}], "timestamp": "1769384701726", "event_type": "price_change"}}
{"_local_timestamp": "2026-01-25T23:45:01.798607+00:00", "data": {"market": "0x7ef8134ab1be2f211a03465ba713c5aef3b71532db57b5287ef49f217937d05e", "price_changes": [{"asset_id": "48424805374840164520274023606217266112677374091090941827104443531363822278032", "price": "0.03", "size": "31.55", "side": "BUY", "hash": "85910a28cc7df458d82ac70372e72e4bc4f41b9c", "best_bid": "0.04", "best_ask": "0.14"}, {"asset_id": "4626635302826736719019052382121946859205373019864096279488493970906294472445", "price": "0.97", "size": "31.55", "side": "SELL", "hash": "1aa434d69410fc38426e594a5c9e9e26a0953d80", "best_bid": "0.86", "best_ask": "0.96"}], "timestamp": "1769384701728", "event_type": "price_change"}}
{"_local_timestamp": "2026-01-25T23:45:01.799044+00:00", "data": {"market": "0x7ef8134ab1be2f211a03465ba713c5aef3b71532db57b5287ef49f217937d05e", "price_changes": [{"asset_id": "48424805374840164520274023606217266112677374091090941827104443531363822278032", "price": "0.02", "size": "465.88", "side": "BUY", "hash": "2e1d86fbd0d8cb6a57c63f4cc44619ce521bac02", "best_bid": "0.04", "best_ask": "0.14"}, {"asset_id": "4626635302826736719019052382121946859205373019864096279488493970906294472445", "price": "0.98", "size": "465.88", "side": "SELL", "hash": "e0dba3b050f4ba5b548b727750d520dee63f999f", "best_bid": "0.86", "best_ask": "0.96"}], "timestamp": "1769384701729", "event_type": "price_change"}}
{"_local_timestamp": "2026-01-25T23:45:03.030943+00:00", "data": {"market": "0x4f79d1df3869fea9411ed300b9a548e753a5eff1d3dba7ccc71d94403a516730", "price_changes": [{"asset_id": "4058613708692092601965760860759243398091398178902937564740140419929508866659", "price": "0.01", "size": "19.04", "side": "BUY", "hash": "7f74b9c4f836452a15cce5c7702d6eeb84ebe6be", "best_bid": "0.32", "best_ask": "0.42"}, {"asset_id": "68703838894982717863263638275451516028706227474005223647821446099405115633483", "price": "0.99", "size": "19.04", "side": "SELL", "hash": "04349d387125cbb24f193dff2fa46eed54ba29fa", "best_bid": "0.58", "best_ask": "0.68"}], "timestamp": "1769384702968", "event_type": "price_change"}}
{"_local_timestamp": "2026-01-25T23:45:03.031406+00:00", "data": {"market": "0x2dc87336b7c13391b66a4e1fc5c32e4ccd78fce4af3357d9f51a1ac7ab9ff7d7", "price_changes": [{"asset_id": "65021187363943312373356838202897507539840706541265856092454478728726100225923", "price": "0.04", "size": "7.34", "side": "BUY", "hash": "0b36f4531af1e5780add698708c20e4b4e3707bf", "best_bid": "0.08", "best_ask": "0.18"}, {"asset_id": "94986644747328021107943358373766839538488524370650238496966362068504684277317", "price": "0.96", "size": "7.34", "side": "SELL", "hash": "01acee266bc869271f699a3fc14881852333185d", "best_bid": "0.82", "best_ask": "0.92"}], "timestamp": "1769384702968", "event_type": "price_change"}}
{"_local_timestamp": "2026-01-25T23:45:03.234239+00:00", "data": {"market": "0x2dc87336b7c13391b66a4e1fc5c32e4ccd78fce4af3357d9f51a1ac7ab9ff7d7", "price_changes": [{"asset_id": "65021187363943312373356838202897507539840706541265856092454478728726100225923", "price": "0.04", "size": "20.01", "side": "BUY", "hash": "742cebc9f6dcd84798fc6da09fd118a97e916886", "best_bid": "0.08", "best_ask": "0.18"}, {"asset_id": "94986644747328021107943358373766839538488524370650238496966362068504684277317", "price": "0.96", "size": "20.01", "side": "SELL", "hash": "900a0b425705e4bb105e44529f308f81991fdb0c", "best_bid": "0.82", "best_ask": "0.92"}], "timestamp": "1769384703167", "event_type": "price_change"}}
{"_local_timestamp": "2026-01-25T23:45:03.590978+00:00", "data": {"market": "0x4f79d1df3869fea9411ed300b9a548e753a5eff1d3dba7ccc71d94403a516730", "price_changes": [{"asset_id": "4058613708692092601965760860759243398091398178902937564740140419929508866659", "price": "0.01", "size": "48.76", "side": "BUY", "hash": "975ec5153182dfc8d59e200e2955460b1a794b6e", "best_bid": "0.32", "best_ask": "0.42"}, {"asset_id": "68703838894982717863263638275451516028706227474005223647821446099405115633483", "price": "0.99", "size": "48.76", "side": "SELL", "hash": "c92b307dcbf18c66f1122d792236894097aaabc6", "best_bid": "0.58", "best_ask": "0.68"}], "timestamp": "1769384703529", "event_type": "price_change"}}
{"_local_timestamp": "2026-01-25T23:45:04.197276+00:00", "data": {"market": "0x3c4e81bb331e949451e021425d83538b6790a9dd4d58c53f71052b393a9d2798", "price_changes": [{"asset_id": "62121983685275403626792441079844760950089203544339908194955935543359913360196", "price": "0.06", "size": "0", "side": "BUY", "hash": "9209c9198a13664c5788dec647358d29c52f3446", "best_bid": "0.36", "best_ask": "0.65"}, {"asset_id": "21879667973342277146722239426252293266968955555129470642380954877694500852533", "price": "0.94", "size": "0", "side": "SELL", "hash": "0d1f715aa0458077a1099da2d0158bfa9a4fa87b", "best_bid": "0.35", "best_ask": "0.64"}], "timestamp": "1769384704129", "event_type": "price_change"}}
{"_local_timestamp": "2026-01-25T23:45:05.131915+00:00", "data": {"market": "0x3c4e81bb331e949451e021425d83538b6790a9dd4d58c53f71052b393a9d2798", "price_changes": [{"asset_id": "62121983685275403626792441079844760950089203544339908194955935543359913360196", "price": "0.05", "size": "17.43", "side": "BUY", "hash": "8cf86b4567d02f51545ab792818eb82ade98064a", "best_bid": "0.36", "best_ask": "0.65"}, {"asset_id": "21879667973342277146722239426252293266968955555129470642380954877694500852533", "price": "0.95", "size": "17.43", "side": "SELL", "hash": "3f91131686722df278628cbdd6b264d5b721013b", "best_bid": "0.35", "best_ask": "0.64"}], "timestamp": "1769384705056", "event_type": "price_change"}}
{"_local_timestamp": "2026-01-25T23:45:12.915721+00:00", "data": {"market": "0x61eb9153c67924f13fd102a324be284f335672ea1fdb07d48af27a8cd03536be", "price_changes": [{"asset_id": "110029858924336699886026160037881747408385035792394181068515946764057130818147", "price": "0.09", "size": "100", "side": "BUY", "hash": "33a12b30ce141bce00afa03a9b3a3a00862d8768", "best_bid": "0.25", "best_ask": "0.28"}, {"asset_id": "99703503368997111194608314266540465795915641214072272571967517894792021713802", "price": "0.91", "size": "100", "side": "SELL", "hash": "656fb9afe363ba3905f4903edabf1c399990f6b2", "best_bid": "0.72", "best_ask": "0.75"}], "timestamp": "1769384712847", "event_type": "price_change"}}
{"_local_timestamp": "2026-01-25T23:45:14.098030+00:00", "data": {"market": "0x61eb9153c67924f13fd102a324be284f335672ea1fdb07d48af27a8cd03536be", "price_changes": [{"asset_id": "110029858924336699886026160037881747408385035792394181068515946764057130818147", "price": "0.09", "size": "108.43", "side": "BUY", "hash": "d71bc22bfea5c39684ceb7277d0de65c18dd7c25", "best_bid": "0.25", "best_ask": "0.28"}, {"asset_id": "99703503368997111194608314266540465795915641214072272571967517894792021713802", "price": "0.91", "size": "108.43", "side": "SELL", "hash": "a6f46260577ea39333b2a7d7dccfac3ae46225ca", "best_bid": "0.72", "best_ask": "0.75"}], "timestamp": "1769384714004", "event_type": "price_change"}}
{"_local_timestamp": "2026-01-25T23:45:44.197014+00:00", "data": {"market": "0xe596f80a42391672c0ee629d1e0cdd2c22e7ce10c48d41fe6c077c8b9ebe6450", "price_changes": [{"asset_id": "43818978408077968881562541827077043343660554037010800188430505666562965869541", "price": "0.18", "size": "0", "side": "BUY", "hash": "1baa317b181d380b10aefc507bf937bc6fe3235c", "best_bid": "0.61", "best_ask": "0.96"}, {"asset_id": "112137718731147502310390559685098534923233818767269408035162170801812461954759", "price": "0.82", "size": "0", "side": "SELL", "hash": "c366f51568e3c18c06c3144b00d1fb852467c9af", "best_bid": "0.04", "best_ask": "0.39"}], "timestamp": "1769384744132", "event_type": "price_change"}}
{"_local_timestamp": "2026-01-25T23:45:44.672940+00:00", "data": {"market": "0xe596f80a42391672c0ee629d1e0cdd2c22e7ce10c48d41fe6c077c8b9ebe6450", "price_changes": [{"asset_id": "43818978408077968881562541827077043343660554037010800188430505666562965869541", "price": "0.18", "size": "5", "side": "BUY", "hash": "20b816afe5556656e1bac9023bce9636b497aa14", "best_bid": "0.61", "best_ask": "0.96"}, {"asset_id": "112137718731147502310390559685098534923233818767269408035162170801812461954759", "price": "0.82", "size": "5", "side": "SELL", "hash": "433811033a8cc43312a6b10f3d5fa2a47aa4037c", "best_bid": "0.04", "best_ask": "0.39"}], "timestamp": "1769384744612", "event_type": "price_change"}}
{"_local_timestamp": "2026-01-25T23:45:55.225744+00:00", "data": {"market": "0xb487a276075b688dba579d617391b7dcca5af14c04a6c33d8d03b9248aee0666", "price_changes": [{"asset_id": "58989659540855401044403336386853959781245409394903503665327101381123074880370", "price": "0.81", "size": "0", "side": "BUY", "hash": "74d835373f69488ddd57a6227c0841e0fddb9153", "best_bid": "0.86", "best_ask": "0.96"}, {"asset_id": "64887912227878003694418361710146660729356626547318586348150482369623624366868", "price": "0.19", "size": "0", "side": "SELL", "hash": "ea29f6b9437c612e5244f6881c43bd2874e788fb", "best_bid": "0.04", "best_ask": "0.14"}], "timestamp": "1769384755162", "event_type": "price_change"}}
{"_local_timestamp": "2026-01-25T23:45:55.642207+00:00", "data": {"market": "0xb487a276075b688dba579d617391b7dcca5af14c04a6c33d8d03b9248aee0666", "price_changes": [{"asset_id": "58989659540855401044403336386853959781245409394903503665327101381123074880370", "price": "0.81", "size": "5", "side": "BUY", "hash": "762ccbe81489dbd92c3e7718219e81d937febd22", "best_bid": "0.86", "best_ask": "0.96"}, {"asset_id": "64887912227878003694418361710146660729356626547318586348150482369623624366868", "price": "0.19", "size": "5", "side": "SELL", "hash": "7b7eb48206cf36800f94dac427a5cde52fabb3db", "best_bid": "0.04", "best_ask": "0.14"}], "timestamp": "1769384755571", "event_type": "price_change"}}
{"_local_timestamp": "2026-01-25T23:46:13.961303+00:00", "data": {"market": "0xa9ba962ede8fd5585244b33cc1bf4591468b71753091fb781a2a5b4257520c33", "price_changes": [{"asset_id": "18735166815426789203564053069301623175312317531324935825733833117617322984139", "price": "0.41", "size": "12.19", "side": "BUY", "hash": "43a3f1df54415741232181eb7efa14e447076b43", "best_bid": "0.41", "best_ask": "0.95"}, {"asset_id": "101531377944005143091286062768662193587086824988143184001837742187395666724540", "price": "0.59", "size": "12.19", "side": "SELL", "hash": "b51e11435d614be724bf66ec32104224ccd11c4e", "best_bid": "0.05", "best_ask": "0.59"}], "timestamp": "1769384773895", "event_type": "price_change"}}
{"_local_timestamp": "2026-01-25T23:46:17.224009+00:00", "data": {"market": "0xe3555dc0c83f3ed522993be9d88b3911ccea50eadf348aedc7d2feb6e131bf7b", "price_changes": [{"asset_id": "2593469348981278329352892292616673852174334474712593978205440358029281457607", "price": "0.002", "size": "225.94", "side": "BUY", "hash": "b097415e9d21f89fb46542842e5b40822f1feef7", "best_bid": "0.02", "best_ask": "0.099"}, {"asset_id": "99817858714934748044341796488555563612713307921513659300432008966728516900242", "price": "0.998", "size": "225.94", "side": "SELL", "hash": "4550b34f663c04137319a2e85b00f32a75493ac1", "best_bid": "0.901", "best_ask": "0.98"}], "timestamp": "1769384777155", "event_type": "price_change"}}
{"_local_timestamp": "2026-01-25T23:46:18.446024+00:00", "data": {"market": "0xe3555dc0c83f3ed522993be9d88b3911ccea50eadf348aedc7d2feb6e131bf7b", "price_changes": [{"asset_id": "2593469348981278329352892292616673852174334474712593978205440358029281457607", "price": "0.002", "size": "328.86", "side": "BUY", "hash": "959fd16b96263e2547063e9d4c84ac5392b04ddc", "best_bid": "0.02", "best_ask": "0.099"}, {"asset_id": "99817858714934748044341796488555563612713307921513659300432008966728516900242", "price": "0.998", "size": "328.86", "side": "SELL", "hash": "027a57ab178e82076c45e77c5cd514d7e71c251c", "best_bid": "0.901", "best_ask": "0.98"}], "timestamp": "1769384778383", "event_type": "price_change"}}
{"_local_timestamp": "2026-01-25T23:46:38.504761+00:00", "data": {"market": "0xe596f80a42391672c0ee629d1e0cdd2c22e7ce10c48d41fe6c077c8b9ebe6450", "price_changes": [{"asset_id": "43818978408077968881562541827077043343660554037010800188430505666562965869541", "price": "0.18", "size": "0", "side": "BUY", "hash": "b72bcd0e5d099b55b371bd98a7594c6ab58364af", "best_bid": "0.61", "best_ask": "0.96"}, {"asset_id": "112137718731147502310390559685098534923233818767269408035162170801812461954759", "price": "0.82", "size": "0", "side": "SELL", "hash": "89c1aa8eeb85227acdfa2ea4cf2ecf97c5e77e94", "best_bid": "0.04", "best_ask": "0.39"}], "timestamp": "1769384798241", "event_type": "price_change"}}
{"_local_timestamp": "2026-01-25T23:46:39.007669+00:00", "data": {"market": "0xe596f80a42391672c0ee629d1e0cdd2c22e7ce10c48d41fe6c077c8b9ebe6450", "price_changes": [{"asset_id": "43818978408077968881562541827077043343660554037010800188430505666562965869541", "price": "0.18", "size": "5", "side": "BUY", "hash": "ac2168d7caf920f847f0642bd6d94b3f937e0f65", "best_bid": "0.61", "best_ask": "0.96"}, {"asset_id": "112137718731147502310390559685098534923233818767269408035162170801812461954759", "price": "0.82", "size": "5", "side": "SELL", "hash": "1b98f06da197f53a5e83461c7bcfb7658e2d2f0c", "best_bid": "0.04", "best_ask": "0.39"}], "timestamp": "1769384798752", "event_type": "price_change"}}
{"_local_timestamp": "2026-01-25T23:46:41.766880+00:00", "data": {"market": "0xa9ba962ede8fd5585244b33cc1bf4591468b71753091fb781a2a5b4257520c33", "price_changes": [{"asset_id": "18735166815426789203564053069301623175312317531324935825733833117617322984139", "price": "0.41", "size": "0", "side": "BUY", "hash": "22b5f44358708032c1b40e4d03a4e82b86e08e08", "best_bid": "0.4", "best_ask": "0.95"}, {"asset_id": "101531377944005143091286062768662193587086824988143184001837742187395666724540", "price": "0.59", "size": "0", "side": "SELL", "hash": "318519491c15292fe63284a7faa81aaf6c981500", "best_bid": "0.05", "best_ask": "0.6"}], "timestamp": "1769384801509", "event_type": "price_change"}}
{"_local_timestamp": "2026-01-25T23:46:53.707899+00:00", "data": {"market": "0xb487a276075b688dba579d617391b7dcca5af14c04a6c33d8d03b9248aee0666", "price_changes": [{"asset_id": "58989659540855401044403336386853959781245409394903503665327101381123074880370", "price": "0.81", "size": "0", "side": "BUY", "hash": "3a0a625738bdad09606a39eb62567482fbcde950", "best_bid": "0.86", "best_ask": "0.96"}, {"asset_id": "64887912227878003694418361710146660729356626547318586348150482369623624366868", "price": "0.19", "size": "0", "side": "SELL", "hash": "b498e4bd8529556ce174f7908e3d14cc75ea37a9", "best_bid": "0.04", "best_ask": "0.14"}], "timestamp": "1769384813571", "event_type": "price_change"}}
{"_local_timestamp": "2026-01-25T23:46:53.946394+00:00", "data": {"market": "0xb487a276075b688dba579d617391b7dcca5af14c04a6c33d8d03b9248aee0666", "price_changes": [{"asset_id": "58989659540855401044403336386853959781245409394903503665327101381123074880370", "price": "0.81", "size": "5", "side": "BUY", "hash": "74e6f319ded6e30c6b294a95ffdacca7fa3c6923", "best_bid": "0.86", "best_ask": "0.96"}, {"asset_id": "64887912227878003694418361710146660729356626547318586348150482369623624366868", "price": "0.19", "size": "5", "side": "SELL", "hash": "3271d36b4527bfaa3471d82adabfa7d873386723", "best_bid": "0.04", "best_ask": "0.14"}], "timestamp": "1769384813815", "event_type": "price_change"}}
{"_local_timestamp": "2026-01-25T23:47:37.630747+00:00", "data": {"market": "0xe596f80a42391672c0ee629d1e0cdd2c22e7ce10c48d41fe6c077c8b9ebe6450", "price_changes": [{"asset_id": "43818978408077968881562541827077043343660554037010800188430505666562965869541", "price": "0.18", "size": "0", "side": "BUY", "hash": "2872cbe1658ad0337401036123546ba2916021bc", "best_bid": "0.61", "best_ask": "0.96"}, {"asset_id": "112137718731147502310390559685098534923233818767269408035162170801812461954759", "price": "0.82", "size": "0", "side": "SELL", "hash": "f9628999b4772aeb41f114e92bd628540a3bdb71", "best_bid": "0.04", "best_ask": "0.39"}], "timestamp": "1769384857322", "event_type": "price_change"}}
{"_local_timestamp": "2026-01-25T23:47:38.403855+00:00", "data": {"market": "0xe596f80a42391672c0ee629d1e0cdd2c22e7ce10c48d41fe6c077c8b9ebe6450", "price_changes": [{"asset_id": "43818978408077968881562541827077043343660554037010800188430505666562965869541", "price": "0.18", "size": "5", "side": "BUY", "hash": "120f5a2a55dc3a33b0ade3f32aa1e2c0c4b874c7", "best_bid": "0.61", "best_ask": "0.96"}, {"asset_id": "112137718731147502310390559685098534923233818767269408035162170801812461954759", "price": "0.82", "size": "5", "side": "SELL", "hash": "e235127e936d3da687bd9702bbc12ce00cddd89c", "best_bid": "0.04", "best_ask": "0.39"}], "timestamp": "1769384858165", "event_type": "price_change"}}
{"_local_timestamp": "2026-01-25T23:47:57.504676+00:00", "data": {"market": "0xb487a276075b688dba579d617391b7dcca5af14c04a6c33d8d03b9248aee0666", "price_changes": [{"asset_id": "58989659540855401044403336386853959781245409394903503665327101381123074880370", "price": "0.81", "size": "0", "side": "BUY", "hash": "a2f82d361a941a686462c9e8bcaa183cf7373ba5", "best_bid": "0.86", "best_ask": "0.96"}, {"asset_id": "64887912227878003694418361710146660729356626547318586348150482369623624366868", "price": "0.19", "size": "0", "side": "SELL", "hash": "38e94e900f0051aff5f6694e4d188fda17156a92", "best_bid": "0.04", "best_ask": "0.14"}], "timestamp": "1769384877413", "event_type": "price_change"}}
{"_local_timestamp": "2026-01-25T23:47:57.956959+00:00", "data": {"market": "0xb487a276075b688dba579d617391b7dcca5af14c04a6c33d8d03b9248aee0666", "price_changes": [{"asset_id": "58989659540855401044403336386853959781245409394903503665327101381123074880370", "price": "0.81", "size": "5", "side": "BUY", "hash": "017477bc5d33482f0419315f641028d9431ca677", "best_bid": "0.86", "best_ask": "0.96"}, {"asset_id": "64887912227878003694418361710146660729356626547318586348150482369623624366868", "price": "0.19", "size": "5", "side": "SELL", "hash": "4afd4efeab1065f8191c89bad0c65ac2c36c831f", "best_bid": "0.04", "best_ask": "0.14"}], "timestamp": "1769384877891", "event_type": "price_change"}}
{"_local_timestamp": "2026-01-25T23:48:16.793925+00:00", "data": {"market": "0xe596f80a42391672c0ee629d1e0cdd2c22e7ce10c48d41fe6c077c8b9ebe6450", "price_changes": [{"asset_id": "43818978408077968881562541827077043343660554037010800188430505666562965869541", "price": "0.18", "size": "0", "side": "BUY", "hash": "7634f2dfe235fc60229592ec63b3eff82cd2629b", "best_bid": "0.61", "best_ask": "0.96"}, {"asset_id": "112137718731147502310390559685098534923233818767269408035162170801812461954759", "price": "0.82", "size": "0", "side": "SELL", "hash": "b12b779d1470704ace298f4ff6c41db7328cae6d", "best_bid": "0.04", "best_ask": "0.39"}], "timestamp": "1769384896728", "event_type": "price_change"}}
{"_local_timestamp": "2026-01-25T23:48:17.552911+00:00", "data": {"market": "0xe596f80a42391672c0ee629d1e0cdd2c22e7ce10c48d41fe6c077c8b9ebe6450", "price_changes": [{"asset_id": "43818978408077968881562541827077043343660554037010800188430505666562965869541", "price": "0.18", "size": "5", "side": "BUY", "hash": "f37abbc54e284bbd0c7175161edb4bffc7861ec2", "best_bid": "0.61", "best_ask": "0.96"}, {"asset_id": "112137718731147502310390559685098534923233818767269408035162170801812461954759", "price": "0.82", "size": "5", "side": "SELL", "hash": "685d5dbfeadd471f9cad01dc31b2c26de1dc0c3e", "best_bid": "0.04", "best_ask": "0.39"}], "timestamp": "1769384897486", "event_type": "price_change"}}
{"_local_timestamp": "2026-01-25T23:48:32.661926+00:00", "data": {"market": "0xb487a276075b688dba579d617391b7dcca5af14c04a6c33d8d03b9248aee0666", "price_changes": [{"asset_id": "58989659540855401044403336386853959781245409394903503665327101381123074880370", "price": "0.81", "size": "0", "side": "BUY", "hash": "74fbb53b7636e26233edab4cd0f540acd04d9613", "best_bid": "0.86", "best_ask": "0.96"}, {"asset_id": "64887912227878003694418361710146660729356626547318586348150482369623624366868", "price": "0.19", "size": "0", "side": "SELL", "hash": "2cdcbfb0facac125294831b3109d43fa29f52566", "best_bid": "0.04", "best_ask": "0.14"}], "timestamp": "1769384912589", "event_type": "price_change"}}
{"_local_timestamp": "2026-01-25T23:48:33.036177+00:00", "data": {"market": "0xb487a276075b688dba579d617391b7dcca5af14c04a6c33d8d03b9248aee0666", "price_changes": [{"asset_id": "58989659540855401044403336386853959781245409394903503665327101381123074880370", "price": "0.81", "size": "5", "side": "BUY", "hash": "be76e9264d48853bdaed74c55a03491561ed0202", "best_bid": "0.86", "best_ask": "0.96"}, {"asset_id": "64887912227878003694418361710146660729356626547318586348150482369623624366868", "price": "0.19", "size": "5", "side": "SELL", "hash": "6947d59a20e163dab75164fec9496e5160c7cb52", "best_bid": "0.04", "best_ask": "0.14"}], "timestamp": "1769384912960", "event_type": "price_change"}}
{"_local_timestamp": "2026-01-25T23:48:43.374191+00:00", "data": {"market": "0xe596f80a42391672c0ee629d1e0cdd2c22e7ce10c48d41fe6c077c8b9ebe6450", "price_changes": [{"asset_id": "43818978408077968881562541827077043343660554037010800188430505666562965869541", "price": "0.18", "size": "0", "side": "BUY", "hash": "ef8a3bd732c31f177899590cf467c75f97f0f4d9", "best_bid": "0.61", "best_ask": "0.96"}, {"asset_id": "112137718731147502310390559685098534923233818767269408035162170801812461954759", "price": "0.82", "size": "0", "side": "SELL", "hash": "8a1e1d768ba44fa953ce1b0f1e5d809f77399198", "best_bid": "0.04", "best_ask": "0.39"}], "timestamp": "1769384923307", "event_type": "price_change"}}
{"_local_timestamp": "2026-01-25T23:48:44.177800+00:00", "data": {"market": "0xe596f80a42391672c0ee629d1e0cdd2c22e7ce10c48d41fe6c077c8b9ebe6450", "price_changes": [{"asset_id": "43818978408077968881562541827077043343660554037010800188430505666562965869541", "price": "0.18", "size": "5", "side": "BUY", "hash": "084184cc13e158a1bfcb01108671d6cde3f47d54", "best_bid": "0.61", "best_ask": "0.96"}, {"asset_id": "112137718731147502310390559685098534923233818767269408035162170801812461954759", "price": "0.82", "size": "5", "side": "SELL", "hash": "b9e6dfbe901eb074feed11fd907aedc0c31f0004", "best_bid": "0.04", "best_ask": "0.39"}], "timestamp": "1769384924106", "event_type": "price_change"}}
{"_local_timestamp": "2026-01-25T23:48:52.102102+00:00", "data": {"market": "0x1acdabfd96a60a3c5e589a338e1e22bb5a8e90becc40e332e3feda869b8e5617", "price_changes": [{"asset_id": "104689190054046512741440948464420797532285324388555594252882891393383377276938", "price": "0.01", "size": "22.63", "side": "BUY", "hash": "9390df2f4dd57c41a8c4daa39c10d4d9e34d1b43", "best_bid": "0.16", "best_ask": "0.22"}, {"asset_id": "16779787884916686624599578288494431887254271147898904281123161606926848201450", "price": "0.99", "size": "22.63", "side": "SELL", "hash": "20f5f9896ea23595acd6305857c7b01238428042", "best_bid": "0.78", "best_ask": "0.84"}], "timestamp": "1769384932032", "event_type": "price_change"}}
{"_local_timestamp": "2026-01-25T23:48:52.103058+00:00", "data": {"market": "0x1acdabfd96a60a3c5e589a338e1e22bb5a8e90becc40e332e3feda869b8e5617", "price_changes": [{"asset_id": "104689190054046512741440948464420797532285324388555594252882891393383377276938", "price": "0.04", "size": "5.64", "side": "BUY", "hash": "9390df2f4dd57c41a8c4daa39c10d4d9e34d1b43", "best_bid": "0.16", "best_ask": "0.22"}, {"asset_id": "16779787884916686624599578288494431887254271147898904281123161606926848201450", "price": "0.96", "size": "5.64", "side": "SELL", "hash": "20f5f9896ea23595acd6305857c7b01238428042", "best_bid": "0.78", "best_ask": "0.84"}], "timestamp": "1769384932032", "event_type": "price_change"}}
{"_local_timestamp": "2026-01-25T23:48:52.625240+00:00", "data": {"market": "0x1acdabfd96a60a3c5e589a338e1e22bb5a8e90becc40e332e3feda869b8e5617", "price_changes": [{"asset_id": "104689190054046512741440948464420797532285324388555594252882891393383377276938", "price": "0.05", "size": "10.29", "side": "BUY", "hash": "b3754ff2a9b534675e12cf105a17dfd65752c72d", "best_bid": "0.16", "best_ask": "0.22"}, {"asset_id": "16779787884916686624599578288494431887254271147898904281123161606926848201450", "price": "0.95", "size": "10.29", "side": "SELL", "hash": "6c61e0a53457483ad39ab468e8709d976291bef9", "best_bid": "0.78", "best_ask": "0.84"}], "timestamp": "1769384932553", "event_type": "price_change"}}
{"_local_timestamp": "2026-01-25T23:48:53.014151+00:00", "data": {"market": "0x7ef8134ab1be2f211a03465ba713c5aef3b71532db57b5287ef49f217937d05e", "price_changes": [{"asset_id": "48424805374840164520274023606217266112677374091090941827104443531363822278032", "price": "0.01", "size": "10010", "side": "BUY", "hash": "d7e0ee27e79db3d10c154f879bc9fdc6656b8a16", "best_bid": "0.04", "best_ask": "0.14"}, {"asset_id": "4626635302826736719019052382121946859205373019864096279488493970906294472445", "price": "0.99", "size": "10010", "side": "SELL", "hash": "53e368dac1ed2f6c4ed273a1b2dda660182349bd", "best_bid": "0.86", "best_ask": "0.96"}], "timestamp": "1769384932945", "event_type": "price_change"}}
{"_local_timestamp": "2026-01-25T23:48:53.014740+00:00", "data": {"market": "0x7ef8134ab1be2f211a03465ba713c5aef3b71532db57b5287ef49f217937d05e", "price_changes": [{"asset_id": "48424805374840164520274023606217266112677374091090941827104443531363822278032", "price": "0.02", "size": "450", "side": "BUY", "hash": "d7e0ee27e79db3d10c154f879bc9fdc6656b8a16", "best_bid": "0.04", "best_ask": "0.14"}, {"asset_id": "4626635302826736719019052382121946859205373019864096279488493970906294472445", "price": "0.98", "size": "450", "side": "SELL", "hash": "53e368dac1ed2f6c4ed273a1b2dda660182349bd", "best_bid": "0.86", "best_ask": "0.96"}], "timestamp": "1769384932945", "event_type": "price_change"}}
{"_local_timestamp": "2026-01-25T23:48:53.015223+00:00", "data": {"market": "0x7ef8134ab1be2f211a03465ba713c5aef3b71532db57b5287ef49f217937d05e", "price_changes": [{"asset_id": "48424805374840164520274023606217266112677374091090941827104443531363822278032", "price": "0.03", "size": "21.49", "side": "BUY", "hash": "d7e0ee27e79db3d10c154f879bc9fdc6656b8a16", "best_bid": "0.04", "best_ask": "0.14"}, {"asset_id": "4626635302826736719019052382121946859205373019864096279488493970906294472445", "price": "0.97", "size": "21.49", "side": "SELL", "hash": "53e368dac1ed2f6c4ed273a1b2dda660182349bd", "best_bid": "0.86", "best_ask": "0.96"}], "timestamp": "1769384932945", "event_type": "price_change"}}
{"_local_timestamp": "2026-01-25T23:48:54.033123+00:00", "data": {"market": "0x7ef8134ab1be2f211a03465ba713c5aef3b71532db57b5287ef49f217937d05e", "price_changes": [{"asset_id": "48424805374840164520274023606217266112677374091090941827104443531363822278032", "price": "0.03", "size": "31.55", "side": "BUY", "hash": "3006532a348e2b18dbddb06db6e386d5c69b0cbf", "best_bid": "0.04", "best_ask": "0.14"}, {"asset_id": "4626635302826736719019052382121946859205373019864096279488493970906294472445", "price": "0.97", "size": "31.55", "side": "SELL", "hash": "adc02a496ade3fcbe25ea4acacfc6e656384343f", "best_bid": "0.86", "best_ask": "0.96"}], "timestamp": "1769384933961", "event_type": "price_change"}}
{"_local_timestamp": "2026-01-25T23:48:54.033690+00:00", "data": {"market": "0x7ef8134ab1be2f211a03465ba713c5aef3b71532db57b5287ef49f217937d05e", "price_changes": [{"asset_id": "48424805374840164520274023606217266112677374091090941827104443531363822278032", "price": "0.02", "size": "465.88", "side": "BUY", "hash": "7bf7ec29d9437f1fc21193b81d23580251885b4b", "best_bid": "0.04", "best_ask": "0.14"}, {"asset_id": "4626635302826736719019052382121946859205373019864096279488493970906294472445", "price": "0.98", "size": "465.88", "side": "SELL", "hash": "7199f285dc68f9ea66defb5a969b77f18909a095", "best_bid": "0.86", "best_ask": "0.96"}], "timestamp": "1769384933962", "event_type": "price_change"}}
{"_local_timestamp": "2026-01-25T23:48:54.034181+00:00", "data": {"market": "0x7ef8134ab1be2f211a03465ba713c5aef3b71532db57b5287ef49f217937d05e", "price_changes": [{"asset_id": "48424805374840164520274023606217266112677374091090941827104443531363822278032", "price": "0.01", "size": "10019.35", "side": "BUY", "hash": "0f3cf2456de5aae0d258169897ef09b7aa416064", "best_bid": "0.04", "best_ask": "0.14"}, {"asset_id": "4626635302826736719019052382121946859205373019864096279488493970906294472445", "price": "0.99", "size": "10019.35", "side": "SELL", "hash": "32457786d38bc1e070e4b77a752dc77123953573", "best_bid": "0.86", "best_ask": "0.96"}], "timestamp": "1769384933963", "event_type": "price_change"}}
{"_local_timestamp": "2026-01-25T23:48:57.032734+00:00", "data": {"market": "0x4f79d1df3869fea9411ed300b9a548e753a5eff1d3dba7ccc71d94403a516730", "price_changes": [{"asset_id": "4058613708692092601965760860759243398091398178902937564740140419929508866659", "price": "0.01", "size": "19.04", "side": "BUY", "hash": "a7328ec68e043a220660f341872a681a00ba6520", "best_bid": "0.32", "best_ask": "0.42"}, {"asset_id": "68703838894982717863263638275451516028706227474005223647821446099405115633483", "price": "0.99", "size": "19.04", "side": "SELL", "hash": "91b491aa6a35b9669ddbb5ede2e438f85a290606", "best_bid": "0.58", "best_ask": "0.68"}], "timestamp": "1769384936964", "event_type": "price_change"}}
{"_local_timestamp": "2026-01-25T23:48:57.033455+00:00", "data": {"market": "0x2dc87336b7c13391b66a4e1fc5c32e4ccd78fce4af3357d9f51a1ac7ab9ff7d7", "price_changes": [{"asset_id": "65021187363943312373356838202897507539840706541265856092454478728726100225923", "price": "0.04", "size": "7.34", "side": "BUY", "hash": "1fe57a043ad672b6f4ca44e76b33b5c1306104f5", "best_bid": "0.08", "best_ask": "0.18"}, {"asset_id": "94986644747328021107943358373766839538488524370650238496966362068504684277317", "price": "0.96", "size": "7.34", "side": "SELL", "hash": "7fb407530ed70a3fcd098438d7d35fddc4e1cd56", "best_bid": "0.82", "best_ask": "0.92"}], "timestamp": "1769384936964", "event_type": "price_change"}}
{"_local_timestamp": "2026-01-25T23:48:57.436422+00:00", "data": {"market": "0x4f79d1df3869fea9411ed300b9a548e753a5eff1d3dba7ccc71d94403a516730", "price_changes": [{"asset_id": "4058613708692092601965760860759243398091398178902937564740140419929508866659", "price": "0.01", "size": "48.76", "side": "BUY", "hash": "b42cb85a9ac2caf467af6a1feff446abf62a40a9", "best_bid": "0.32", "best_ask": "0.42"}, {"asset_id": "68703838894982717863263638275451516028706227474005223647821446099405115633483", "price": "0.99", "size": "48.76", "side": "SELL", "hash": "9a042bb5add92848dfdd5e42267ff38b2790fe82", "best_bid": "0.58", "best_ask": "0.68"}], "timestamp": "1769384937362", "event_type": "price_change"}}
{"_local_timestamp": "2026-01-25T23:48:57.437487+00:00", "data": {"market": "0x2dc87336b7c13391b66a4e1fc5c32e4ccd78fce4af3357d9f51a1ac7ab9ff7d7", "price_changes": [{"asset_id": "65021187363943312373356838202897507539840706541265856092454478728726100225923", "price": "0.04", "size": "20.01", "side": "BUY", "hash": "a33b388bf13ebd19b530a5329493c50dfcb8994b", "best_bid": "0.08", "best_ask": "0.18"}, {"asset_id": "94986644747328021107943358373766839538488524370650238496966362068504684277317", "price": "0.96", "size": "20.01", "side": "SELL", "hash": "002c9d9a694deccdb8c759f41a3205b9e48c3539", "best_bid": "0.82", "best_ask": "0.92"}], "timestamp": "1769384937362", "event_type": "price_change"}}
{"_local_timestamp": "2026-01-25T23:48:58.702248+00:00", "data": {"market": "0x3c4e81bb331e949451e021425d83538b6790a9dd4d58c53f71052b393a9d2798", "price_changes": [{"asset_id": "62121983685275403626792441079844760950089203544339908194955935543359913360196", "price": "0.05", "size": "0", "side": "BUY", "hash": "593c81547ff14147de8d7595e9a196105b9b42eb", "best_bid": "0.36", "best_ask": "0.65"}, {"asset_id": "21879667973342277146722239426252293266968955555129470642380954877694500852533", "price": "0.95", "size": "0", "side": "SELL", "hash": "f3df91386bcc4638cf3d9fea4119e31a61cdc95d", "best_bid": "0.35", "best_ask": "0.64"}], "timestamp": "1769384938634", "event_type": "price_change"}}
{"_local_timestamp": "2026-01-25T23:48:59.473417+00:00", "data": {"market": "0x3c4e81bb331e949451e021425d83538b6790a9dd4d58c53f71052b393a9d2798", "price_changes": [{"asset_id": "62121983685275403626792441079844760950089203544339908194955935543359913360196", "price": "0.05", "size": "17.43", "side": "BUY", "hash": "db045e9b8470fd8d42874163e89197bc04ce6b4a", "best_bid": "0.36", "best_ask": "0.65"}, {"asset_id": "21879667973342277146722239426252293266968955555129470642380954877694500852533", "price": "0.95", "size": "17.43", "side": "SELL", "hash": "618bf1597425aac122e832f3bb85c2aa19365622", "best_bid": "0.35", "best_ask": "0.64"}], "timestamp": "1769384939404", "event_type": "price_change"}}
{"_local_timestamp": "2026-01-25T23:49:00.470109+00:00", "data": {"market": "0xa9ba962ede8fd5585244b33cc1bf4591468b71753091fb781a2a5b4257520c33", "price_changes": [{"asset_id": "18735166815426789203564053069301623175312317531324935825733833117617322984139", "price": "0.41", "size": "12.19", "side": "BUY", "hash": "44535c1f8439598c02b1ceac34a0ad8ee97d347c", "best_bid": "0.41", "best_ask": "0.95"}, {"asset_id": "101531377944005143091286062768662193587086824988143184001837742187395666724540", "price": "0.59", "size": "12.19", "side": "SELL", "hash": "9214a1c83699a2adc23ff5c1df3eab81c6ba4854", "best_bid": "0.05", "best_ask": "0.59"}], "timestamp": "1769384940390", "event_type": "price_change"}}
{"_local_timestamp": "2026-01-25T23:49:04.024984+00:00", "data": {"market": "0xb487a276075b688dba579d617391b7dcca5af14c04a6c33d8d03b9248aee0666", "price_changes": [{"asset_id": "58989659540855401044403336386853959781245409394903503665327101381123074880370", "price": "0.81", "size": "0", "side": "BUY", "hash": "4c0f1952a6430f1d3537144d6ef6da030a94407a", "best_bid": "0.86", "best_ask": "0.96"}, {"asset_id": "64887912227878003694418361710146660729356626547318586348150482369623624366868", "price": "0.19", "size": "0", "side": "SELL", "hash": "b0d641e7df9a8ed2c2b71734f07a884e8e4bb238", "best_bid": "0.04", "best_ask": "0.14"}], "timestamp": "1769384943958", "event_type": "price_change"}}
{"_local_timestamp": "2026-01-25T23:49:04.443373+00:00", "data": {"market": "0xb487a276075b688dba579d617391b7dcca5af14c04a6c33d8d03b9248aee0666", "price_changes": [{"asset_id": "58989659540855401044403336386853959781245409394903503665327101381123074880370", "price": "0.81", "size": "5", "side": "BUY", "hash": "fe34bd4e2ba1124992d33ece4464e9cf9d85ea12", "best_bid": "0.86", "best_ask": "0.96"}, {"asset_id": "64887912227878003694418361710146660729356626547318586348150482369623624366868", "price": "0.19", "size": "5", "side": "SELL", "hash": "723a074399a1947862b6801175caa26126aa2511", "best_bid": "0.04", "best_ask": "0.14"}], "timestamp": "1769384944368", "event_type": "price_change"}}
{"_local_timestamp": "2026-01-25T23:49:05.916073+00:00", "data": {"market": "0x61eb9153c67924f13fd102a324be284f335672ea1fdb07d48af27a8cd03536be", "price_changes": [{"asset_id": "110029858924336699886026160037881747408385035792394181068515946764057130818147", "price": "0.09", "size": "100", "side": "BUY", "hash": "fb70b1d75583a1120eed1527cd2277fac9773aee", "best_bid": "0.25", "best_ask": "0.28"}, {"asset_id": "99703503368997111194608314266540465795915641214072272571967517894792021713802", "price": "0.91", "size": "100", "side": "SELL", "hash": "32099c667044162e5ccfef71f3245df6cc0ab83a", "best_bid": "0.72", "best_ask": "0.75"}], "timestamp": "1769384945840", "event_type": "price_change"}}
{"_local_timestamp": "2026-01-25T23:49:06.862751+00:00", "data": {"market": "0x61eb9153c67924f13fd102a324be284f335672ea1fdb07d48af27a8cd03536be", "price_changes": [{"asset_id": "110029858924336699886026160037881747408385035792394181068515946764057130818147", "price": "0.09", "size": "108.43", "side": "BUY", "hash": "9672915fef06e0f9aa6c36d14b32d9ac7faf183a", "best_bid": "0.25", "best_ask": "0.28"}, {"asset_id": "99703503368997111194608314266540465795915641214072272571967517894792021713802", "price": "0.91", "size": "108.43", "side": "SELL", "hash": "8845e12fd493fdb7e944557ece7e3e8af0db19a2", "best_bid": "0.72", "best_ask": "0.75"}], "timestamp": "1769384946793", "event_type": "price_change"}}
{"_local_timestamp": "2026-01-25T23:49:16.396297+00:00", "data": {"market": "0xe596f80a42391672c0ee629d1e0cdd2c22e7ce10c48d41fe6c077c8b9ebe6450", "price_changes": [{"asset_id": "43818978408077968881562541827077043343660554037010800188430505666562965869541", "price": "0.18", "size": "0", "side": "BUY", "hash": "696dcdb4f39c7477d52fd68d52a6258bc58c4ee6", "best_bid": "0.61", "best_ask": "0.96"}, {"asset_id": "112137718731147502310390559685098534923233818767269408035162170801812461954759", "price": "0.82", "size": "0", "side": "SELL", "hash": "23e9f13acad842e6086e6d5d2c6012879f3abd40", "best_bid": "0.04", "best_ask": "0.39"}], "timestamp": "1769384956329", "event_type": "price_change"}}
{"_local_timestamp": "2026-01-25T23:49:17.152311+00:00", "data": {"market": "0xe596f80a42391672c0ee629d1e0cdd2c22e7ce10c48d41fe6c077c8b9ebe6450", "price_changes": [{"asset_id": "43818978408077968881562541827077043343660554037010800188430505666562965869541", "price": "0.18", "size": "5", "side": "BUY", "hash": "6e43ccbb80be42fbac8667a8227fbd65cd0496ad", "best_bid": "0.61", "best_ask": "0.96"}, {"asset_id": "112137718731147502310390559685098534923233818767269408035162170801812461954759", "price": "0.82", "size": "5", "side": "SELL", "hash": "3bef64ea94520fb2dc0166362ff73a049e68e86e", "best_bid": "0.04", "best_ask": "0.39"}], "timestamp": "1769384957084", "event_type": "price_change"}}
{"_local_timestamp": "2026-01-25T23:49:27.821389+00:00", "data": {"market": "0xa9ba962ede8fd5585244b33cc1bf4591468b71753091fb781a2a5b4257520c33", "price_changes": [{"asset_id": "18735166815426789203564053069301623175312317531324935825733833117617322984139", "price": "0.41", "size": "0", "side": "BUY", "hash": "80f5ed20d27f85df1036f4c40ff0d0b3e4b3fea9", "best_bid": "0.4", "best_ask": "0.95"}, {"asset_id": "101531377944005143091286062768662193587086824988143184001837742187395666724540", "price": "0.59", "size": "0", "side": "SELL", "hash": "33ee9af68897451f2624d08cdcfb49519804c0e1", "best_bid": "0.05", "best_ask": "0.6"}], "timestamp": "1769384967755", "event_type": "price_change"}}
{"_local_timestamp": "2026-01-25T23:49:32.963931+00:00", "data": {"market": "0xfef0954af0d43ea46c1ac246ac009dbcd0f76d36fd93b78d3586b23b386028ef", "price_changes": [{"asset_id": "90954386001801116059251303598368900188182195794057114134644084985964418752977", "price": "0.34", "size": "0", "side": "SELL", "hash": "7493e77935982dd3f8b7956667966c68312d29f4", "best_bid": "0.32", "best_ask": "0.33"}, {"asset_id": "94516923452105222578438916262485145756699194265211313859088449971552829623384", "price": "0.66", "size": "0", "side": "BUY", "hash": "2b0a95fecdff57f1bc529208007f171815ae2523", "best_bid": "0.67", "best_ask": "0.68"}], "timestamp": "1769384972899", "event_type": "price_change"}}
{"_local_timestamp": "2026-01-25T23:49:34.794275+00:00", "data": {"market": "0xb487a276075b688dba579d617391b7dcca5af14c04a6c33d8d03b9248aee0666", "price_changes": [{"asset_id": "58989659540855401044403336386853959781245409394903503665327101381123074880370", "price": "0.81", "size": "0", "side": "BUY", "hash": "894961c25008a6949324e32bbeb8bd2f034d25e1", "best_bid": "0.86", "best_ask": "0.96"}, {"asset_id": "64887912227878003694418361710146660729356626547318586348150482369623624366868", "price": "0.19", "size": "0", "side": "SELL", "hash": "e26741d6e2d328145dfdc751a8c5d3a82e11185f", "best_bid": "0.04", "best_ask": "0.14"}], "timestamp": "1769384974707", "event_type": "price_change"}}
{"_local_timestamp": "2026-01-25T23:49:35.136035+00:00", "data": {"market": "0xb487a276075b688dba579d617391b7dcca5af14c04a6c33d8d03b9248aee0666", "price_changes": [{"asset_id": "58989659540855401044403336386853959781245409394903503665327101381123074880370", "price": "0.81", "size": "5", "side": "BUY", "hash": "330db9ca3ec0065230b1ad5c8e0938ca45570d27", "best_bid": "0.86", "best_ask": "0.96"}, {"asset_id": "64887912227878003694418361710146660729356626547318586348150482369623624366868", "price": "0.19", "size": "5", "side": "SELL", "hash": "43cb4297c339b63fa6f91c463725a6f5fdf51bab", "best_bid": "0.04", "best_ask": "0.14"}], "timestamp": "1769384975072", "event_type": "price_change"}}
{"_local_timestamp": "2026-01-25T23:49:45.815902+00:00", "data": {"market": "0xe596f80a42391672c0ee629d1e0cdd2c22e7ce10c48d41fe6c077c8b9ebe6450", "price_changes": [{"asset_id": "43818978408077968881562541827077043343660554037010800188430505666562965869541", "price": "0.18", "size": "0", "side": "BUY", "hash": "9b9d9648002a360dfeb93dc46070187ed3c6eeae", "best_bid": "0.61", "best_ask": "0.96"}, {"asset_id": "112137718731147502310390559685098534923233818767269408035162170801812461954759", "price": "0.82", "size": "0", "side": "SELL", "hash": "795f2db6428efd979f93d10fcb85670b2a7d5042", "best_bid": "0.04", "best_ask": "0.39"}], "timestamp": "1769384985746", "event_type": "price_change"}}
{"_local_timestamp": "2026-01-25T23:49:46.163317+00:00", "data": {"market": "0xe596f80a42391672c0ee629d1e0cdd2c22e7ce10c48d41fe6c077c8b9ebe6450", "price_changes": [{"asset_id": "43818978408077968881562541827077043343660554037010800188430505666562965869541", "price": "0.18", "size": "5", "side": "BUY", "hash": "2474ad9ffd8d782d533dbb93e35737eb9369b000", "best_bid": "0.61", "best_ask": "0.96"}, {"asset_id": "112137718731147502310390559685098534923233818767269408035162170801812461954759", "price": "0.82", "size": "5", "side": "SELL", "hash": "6568f38ad8de190865ce05244a41f5e4ca4a83d9", "best_bid": "0.04", "best_ask": "0.39"}], "timestamp": "1769384986097", "event_type": "price_change"}}
{"_local_timestamp": "2026-01-25T23:49:47.508373+00:00", "data": {"market": "0xfef0954af0d43ea46c1ac246ac009dbcd0f76d36fd93b78d3586b23b386028ef", "price_changes": [{"asset_id": "90954386001801116059251303598368900188182195794057114134644084985964418752977", "price": "0.34", "size": "6.83", "side": "SELL", "hash": "7390003e7866972620f2df38e40f2a04af4a224e", "best_bid": "0.32", "best_ask": "0.33"}, {"asset_id": "94516923452105222578438916262485145756699194265211313859088449971552829623384", "price": "0.66", "size": "6.83", "side": "BUY", "hash": "925bb0b9aed66af6b49f8b3c8186a220910ccda9", "best_bid": "0.67", "best_ask": "0.68"}], "timestamp": "1769384987440", "event_type": "price_change"}}
{"_local_timestamp": "2026-01-25T23:49:59.502846+00:00", "data": {"market": "0xd637cf70c23d4fff2aed81d325fcba06992a7af70a011bd0fecf0da2ba0b7fa8", "price_changes": [{"asset_id": "70232210583057159849426519112788777542688184091820368797117756012503833407972", "price": "0.12", "size": "0", "side": "BUY", "hash": "5e6c5020efb9827fb1c805f8a5a8d4ee5adb389f", "best_bid": "0.86", "best_ask": "0.93"}, {"asset_id": "90283996287531057288260474622112140891469566203169628355432573038893863470116", "price": "0.88", "size": "0", "side": "SELL", "hash": "348014e627b872f6a0364385de0850c012cc3751", "best_bid": "0.07", "best_ask": "0.14"}], "timestamp": "1769384999421", "event_type": "price_change"}}
{"_local_timestamp": "2026-01-25T23:49:59.536006+00:00", "data": {"market": "0xd637cf70c23d4fff2aed81d325fcba06992a7af70a011bd0fecf0da2ba0b7fa8", "price_changes": [{"asset_id": "70232210583057159849426519112788777542688184091820368797117756012503833407972", "price": "0.12", "size": "16", "side": "BUY", "hash": "651b69cded0e9c02ce88591389d72b6ffbbaf5b2", "best_bid": "0.86", "best_ask": "0.93"}, {"asset_id": "90283996287531057288260474622112140891469566203169628355432573038893863470116", "price": "0.88", "size": "16", "side": "SELL", "hash": "46af5ef213ec5c2e794f1244c450a7ee1c8bab9f", "best_bid": "0.07", "best_ask": "0.14"}], "timestamp": "1769384999468", "event_type": "price_change"}}
{"_local_timestamp": "2026-01-25T23:50:03.284070+00:00", "data": {"market": "0xb487a276075b688dba579d617391b7dcca5af14c04a6c33d8d03b9248aee0666", "price_changes": [{"asset_id": "58989659540855401044403336386853959781245409394903503665327101381123074880370", "price": "0.81", "size": "0", "side": "BUY", "hash": "f38d76238155d81a0a55b1a6c4d2a5ebedec8184", "best_bid": "0.86", "best_ask": "0.96"}, {"asset_id": "64887912227878003694418361710146660729356626547318586348150482369623624366868", "price": "0.19", "size": "0", "side": "SELL", "hash": "01ca728c04c0ca4998ab9b9b3533bb6e45be9734", "best_bid": "0.04", "best_ask": "0.14"}], "timestamp": "1769385002881", "event_type": "price_change"}}
{"_local_timestamp": "2026-01-25T23:50:03.371432+00:00", "data": {"market": "0xb487a276075b688dba579d617391b7dcca5af14c04a6c33d8d03b9248aee0666", "price_changes": [{"asset_id": "58989659540855401044403336386853959781245409394903503665327101381123074880370", "price": "0.81", "size": "5", "side": "BUY", "hash": "0dbceea11f93c6244157af6feb5abf649f4bf408", "best_bid": "0.86", "best_ask": "0.96"}, {"asset_id": "64887912227878003694418361710146660729356626547318586348150482369623624366868", "price": "0.19", "size": "5", "side": "SELL", "hash": "788cc53e6e88955369223f2978dda2ae50489119", "best_bid": "0.04", "best_ask": "0.14"}], "timestamp": "1769385003215", "event_type": "price_change"}}
{"_local_timestamp": "2026-01-25T23:50:14.236526+00:00", "data": {"market": "0xe3555dc0c83f3ed522993be9d88b3911ccea50eadf348aedc7d2feb6e131bf7b", "price_changes": [{"asset_id": "2593469348981278329352892292616673852174334474712593978205440358029281457607", "price": "0.002", "size": "225.94", "side": "BUY", "hash": "e217fbc23b1920ef6990f5c614ccebf67ad8112d", "best_bid": "0.02", "best_ask": "0.099"}, {"asset_id": "99817858714934748044341796488555563612713307921513659300432008966728516900242", "price": "0.998", "size": "225.94", "side": "SELL", "hash": "c0d348b0f6709a9525a5d0ebe3ee7063e274a43f", "best_bid": "0.901", "best_ask": "0.98"}], "timestamp": "1769385014160", "event_type": "price_change"}}
{"_local_timestamp": "2026-01-25T23:50:14.740682+00:00", "data": {"market": "0xe3555dc0c83f3ed522993be9d88b3911ccea50eadf348aedc7d2feb6e131bf7b", "price_changes": [{"asset_id": "2593469348981278329352892292616673852174334474712593978205440358029281457607", "price": "0.002", "size": "328.86", "side": "BUY", "hash": "b703ef67ea9b841b65d9691787579716f8a55e63", "best_bid": "0.02", "best_ask": "0.099"}, {"asset_id": "99817858714934748044341796488555563612713307921513659300432008966728516900242", "price": "0.998", "size": "328.86", "side": "SELL", "hash": "12b1d4c793ed3ffcc1ee34792a4576f2ccc7734d", "best_bid": "0.901", "best_ask": "0.98"}], "timestamp": "1769385014673", "event_type": "price_change"}}
{"_local_timestamp": "2026-01-25T23:50:17.886735+00:00", "data": {"market": "0xe596f80a42391672c0ee629d1e0cdd2c22e7ce10c48d41fe6c077c8b9ebe6450", "price_changes": [{"asset_id": "43818978408077968881562541827077043343660554037010800188430505666562965869541", "price": "0.18", "size": "0", "side": "BUY", "hash": "7d433b6c9665a913990d1eb887d3bc6cb67fe465", "best_bid": "0.61", "best_ask": "0.96"}, {"asset_id": "112137718731147502310390559685098534923233818767269408035162170801812461954759", "price": "0.82", "size": "0", "side": "SELL", "hash": "ad82e44985c817d30898c1c978ccb4af4f991719", "best_bid": "0.04", "best_ask": "0.39"}], "timestamp": "1769385017818", "event_type": "price_change"}}
{"_local_timestamp": "2026-01-25T23:50:18.174109+00:00", "data": {"market": "0xe596f80a42391672c0ee629d1e0cdd2c22e7ce10c48d41fe6c077c8b9ebe6450", "price_changes": [{"asset_id": "43818978408077968881562541827077043343660554037010800188430505666562965869541", "price": "0.18", "size": "5", "side": "BUY", "hash": "787966d954437a34846319694f30c6f036f4b360", "best_bid": "0.61", "best_ask": "0.96"}, {"asset_id": "112137718731147502310390559685098534923233818767269408035162170801812461954759", "price": "0.82", "size": "5", "side": "SELL", "hash": "4b6ef219ab7cccd1abaa58a550934570c3b4e267", "best_bid": "0.04", "best_ask": "0.39"}], "timestamp": "1769385018087", "event_type": "price_change"}}
{"_local_timestamp": "2026-01-25T23:50:18.467077+00:00", "data": {"market": "0x939bffc79d51cc380bd8507a6de7fcc528a4c13c923762fb4115c949045c7ccd", "price_changes": [{"asset_id": "44214751861001954999444570118407153044381911853601865828800644284059994656536", "price": "0.12", "size": "0", "side": "BUY", "hash": "e93d7fca3607ad12d3b148926b5f5d70e66da439", "best_bid": "0.6", "best_ask": "0.7"}, {"asset_id": "25826819136806397270713318817364628011366247262413817412590108086611188733725", "price": "0.88", "size": "0", "side": "SELL", "hash": "3e38aa05dac07769af463dab13d4af7db240c3b8", "best_bid": "0.3", "best_ask": "0.4"}], "timestamp": "1769385018400", "event_type": "price_change"}}
{"_local_timestamp": "2026-01-25T23:50:18.525699+00:00", "data": {"market": "0x939bffc79d51cc380bd8507a6de7fcc528a4c13c923762fb4115c949045c7ccd", "price_changes": [{"asset_id": "44214751861001954999444570118407153044381911853601865828800644284059994656536", "price": "0.12", "size": "16", "side": "BUY", "hash": "7109b8c86a108d390ceb8f18540cafc8244c46a3", "best_bid": "0.6", "best_ask": "0.7"}, {"asset_id": "25826819136806397270713318817364628011366247262413817412590108086611188733725", "price": "0.88", "size": "16", "side": "SELL", "hash": "113d5c414d71e848a7d347da5e671029062050bc", "best_bid": "0.3", "best_ask": "0.4"}], "timestamp": "1769385018455", "event_type": "price_change"}}
{"_local_timestamp": "2026-01-25T23:50:38.285671+00:00", "data": {"market": "0xb487a276075b688dba579d617391b7dcca5af14c04a6c33d8d03b9248aee0666", "price_changes": [{"asset_id": "58989659540855401044403336386853959781245409394903503665327101381123074880370", "price": "0.81", "size": "0", "side": "BUY", "hash": "bd4f3b645f7d6d1e56210ba829a71348baf6fcb0", "best_bid": "0.86", "best_ask": "0.96"}, {"asset_id": "64887912227878003694418361710146660729356626547318586348150482369623624366868", "price": "0.19", "size": "0", "side": "SELL", "hash": "c759ae7b8ed5ae16248d90228cbe63d18f29df1e", "best_bid": "0.04", "best_ask": "0.14"}], "timestamp": "1769385038207", "event_type": "price_change"}}
{"_local_timestamp": "2026-01-25T23:50:38.578393+00:00", "data": {"market": "0xb487a276075b688dba579d617391b7dcca5af14c04a6c33d8d03b9248aee0666", "price_changes": [{"asset_id": "58989659540855401044403336386853959781245409394903503665327101381123074880370", "price": "0.81", "size": "5", "side": "BUY", "hash": "53e6b4f932c4ed72fcab74d32e541f7b87528a27", "best_bid": "0.86", "best_ask": "0.96"}, {"asset_id": "64887912227878003694418361710146660729356626547318586348150482369623624366868", "price": "0.19", "size": "5", "side": "SELL", "hash": "ac356f1d96677239eb8340085e8ebe77dbeea8d5", "best_bid": "0.04", "best_ask": "0.14"}], "timestamp": "1769385038502", "event_type": "price_change"}}
{"_local_timestamp": "2026-01-25T23:50:46.461631+00:00", "data": {"market": "0x5171f07c753e4ff897ae62d6ba5b64ca86977cb306e43f7d280df842020c369b", "price_changes": [{"asset_id": "102969531592712049176088251110843863624391494970245314219392371547409554441222", "price": "0.14", "size": "0", "side": "BUY", "hash": "d85700ffc9934811bca7921205797751e7a31b0d", "best_bid": "0.58", "best_ask": "0.96"}, {"asset_id": "113700150423978789001063875817280301949767254929935453186800269441668395430876", "price": "0.86", "size": "0", "side": "SELL", "hash": "372e101fea846816999a7aeb0d2525b67c800932", "best_bid": "0.04", "best_ask": "0.42"}], "timestamp": "1769385046354", "event_type": "price_change"}}
{"_local_timestamp": "2026-01-25T23:50:46.477083+00:00", "data": {"market": "0x5171f07c753e4ff897ae62d6ba5b64ca86977cb306e43f7d280df842020c369b", "price_changes": [{"asset_id": "102969531592712049176088251110843863624391494970245314219392371547409554441222", "price": "0.14", "size": "14", "side": "BUY", "hash": "9a1d12d4989f2e0edf2080efba548609fb13b4a2", "best_bid": "0.58", "best_ask": "0.96"}, {"asset_id": "113700150423978789001063875817280301949767254929935453186800269441668395430876", "price": "0.86", "size": "14", "side": "SELL", "hash": "9f15bc501d782bb18a9665e13ee8fc387f6f7fbf", "best_bid": "0.04", "best_ask": "0.42"}], "timestamp": "1769385046400", "event_type": "price_change"}}
{"_local_timestamp": "2026-01-25T23:50:49.551694+00:00", "data": {"market": "0xe596f80a42391672c0ee629d1e0cdd2c22e7ce10c48d41fe6c077c8b9ebe6450", "price_changes": [{"asset_id": "43818978408077968881562541827077043343660554037010800188430505666562965869541", "price": "0.18", "size": "0", "side": "BUY", "hash": "fa8db4207f5eba22b18bee4d3b88b8098635edb3", "best_bid": "0.61", "best_ask": "0.96"}, {"asset_id": "112137718731147502310390559685098534923233818767269408035162170801812461954759", "price": "0.82", "size": "0", "side": "SELL", "hash": "abcf602ef1fa367438d897685c1fc092c59ca698", "best_bid": "0.04", "best_ask": "0.39"}], "timestamp": "1769385049482", "event_type": "price_change"}}
{"_local_timestamp": "2026-01-25T23:50:49.983423+00:00", "data": {"market": "0xe596f80a42391672c0ee629d1e0cdd2c22e7ce10c48d41fe6c077c8b9ebe6450", "price_changes": [{"asset_id": "43818978408077968881562541827077043343660554037010800188430505666562965869541", "price": "0.18", "size": "5", "side": "BUY", "hash": "b61dc132f02a75067237d82efb5c6cca26020b0e", "best_bid": "0.61", "best_ask": "0.96"}, {"asset_id": "112137718731147502310390559685098534923233818767269408035162170801812461954759", "price": "0.82", "size": "5", "side": "SELL", "hash": "1fd04105cd8305fb8ad65d6f391c961817fce735", "best_bid": "0.04", "best_ask": "0.39"}], "timestamp": "1769385049910", "event_type": "price_change"}}
