{"_local_timestamp": "2026-01-25T23:40:47.184306+00:00", "data": [{"market": "0xc8e2cb0f8baff17af693d88804003de9b96c84daf4abb1b55890f5c2825a8a47", "asset_id": "77159431891699383466672221717979188818354345198749135542768242998311451180645", "timestamp": "1769384417465", "hash": "7b0e6c04f42b0ca3c49c87d3663f6bdaa398b266", "bids": [{"price": "0.001", "size": "888"}, {"price": "0.002", "size": "506.54"}, {"price": "0.003", "size": "40.56"}, {"price": "0.004", "size": "57"}, {"price": "0.005", "size": "46.2"}, {"price": "0.025", "size": "1281.31"}, {"price": "0.026", "size": "50"}, {"price": "0.031", "size": "20"}, {"price": "0.032", "size": "9.84"}, {"price": "0.054", "size": "870"}, {"price": "0.055", "size": "5.8"}, {"price": "0.062", "size": "758"}, {"price": "0.063", "size": "12.19"}, {"price": "0.065", "size": "1161.62"}, {"price": "0.069", "size": "186"}, {"price": "0.07", "size": "1866"}, {"price": "0.071", "size": "315"}, {"price": "0.072", "size": "200"}, {"price": "0.084", "size": "100"}, {"price": "0.085", "size": "110"}, {"price": "0.086", "size": "134"}, {"price": "0.096", "size": "5.05"}], "asks": [{"price": "0.999", "size": "22143.1"}, {"price": "0.998", "size": "1923.57"}, {"price": "0.997", "size": "1400"}, {"price": "0.996", "size": "2500"}, {"price": "0.995", "size": "6.9"}, {"price": "0.994", "size": "200"}, {"price": "0.99", "size": "105350"}, {"price": "0.989", "size": "5.87"}, {"price": "0.988", "size": "1000"}, {"price": "0.98", "size": "4000"}, {"price": "0.979", "size": "2500"}, {"price": "0.976", "size": "500"}, {"price": "0.975", "size": "7.46"}, {"price": "0.95", "size": "330"}, {"price": "0.949", "size": "39"}, {"price": "0.929", "size": "2300"}, {"price": "0.928", "size": "9.64"}, {"price": "0.88", "size": "500"}, {"price": "0.86", "size": "200"}, {"price": "0.85", "size": "1325"}, {"price": "0.84", "size": "200"}, {"price": "0.821", "size": "1142"}, {"price": "0.75", "size": "250"}, {"price": "0.749", "size": "1872"}, {"price": "0.72", "size": "250"}, {"price": "0.7", "size": "300"}, {"price": "0.66", "size": "125"}, {"price": "0.4", "size": "10"}, {"price": "0.38", "size": "5"}, {"price": "0.3", "size": "5"}, {"price": "0.25", "size": "20"}, {"price": "0.2", "size": "15"}, {"price": "0.167", "size": "1096.27"}, {"price": "0.163", "size": "500"}, {"price": "0.162", "size": "200"}, {"price": "0.15", "size": "5"}, {"price": "0.13", "size": "400"}, {"price": "0.124", "size": "100"}, {"price": "0.121", "size": "300"}, {"price": "0.12", "size": "74.42"}, {"price": "0.119", "size": "43.24"}, {"price": "0.118", "size": "498.49"}, {"price": "0.115", "size": "1143.81"}, {"price": "0.114", "size": "10.63"}, {"price": "0.113", "size": "68.01"}], "event_type": "book", "last_trade_price": "0.114"}, {"market": "0x0b6072d0211619124606d4a1fbfe719654f93d44a275d4b20f5a82a8e7a140dc", "asset_id": "43515368755702423981051690629883247758860778201528671372907379948136148128501", "timestamp": "1769384445502", "hash": "ec8c902b4dc94291d53aad14bbde5f302f0d9464", "bids": [{"price": "0.01", "size": "1550"}, {"price": "0.02", "size": "2362.9"}, {"price": "0.03", "size": "1000"}, {"price": "0.04", "size": "5.71"}, {"price": "0.06", "size": "1083"}, {"price": "0.08", "size": "6.41"}, {"price": "0.13", "size": "700"}, {"price": "0.15", "size": "9.09"}, {"price": "0.16", "size": "5"}, {"price": "0.17", "size": "10"}, {"price": "0.19", "size": "113.61"}, {"price": "0.2", "size": "65.86"}, {"price": "0.21", "size": "40"}], "asks": [{"price": "0.99", "size": "5009.97"}, {"price": "0.98", "size": "4300"}, {"price": "0.97", "size": "6.96"}, {"price": "0.95", "size": "300"}, {"price": "0.93", "size": "500"}, {"price": "0.92", "size": "8.64"}, {"price": "0.85", "size": "325"}, {"price": "0.84", "size": "1000"}, {"price": "0.83", "size": "2720"}, {"price": "0.8", "size": "5"}, {"price": "0.75", "size": "3225"}, {"price": "0.74", "size": "250"}, {"price": "0.73", "size": "50"}, {"price": "0.72", "size": "7"}, {"price": "0.66", "size": "125"}, {"price": "0.5", "size": "200"}, {"price": "0.36", "size": "10"}, {"price": "0.33", "size": "10"}, {"price": "0.3", "size": "15"}, {"price": "0.29", "size": "230"}, {"price": "0.28", "size": "110.09"}, {"price": "0.27", "size": "110"}, {"price": "0.26", "size": "177.66"}, {"price": "0.24", "size": "95.25"}], "event_type": "book", "last_trade_price": "0.770"}, {"market": "0x0b6072d0211619124606d4a1fbfe719654f93d44a275d4b20f5a82a8e7a140dc", "asset_id": "34085962263761623546918537130347047402005997515702608792930465133090904504788", "timestamp": "1769384445502", "hash": "17f2d3713ffa2a556c14be6e2b786b121861751c", "bids": [{"price": "0.01", "size": "5009.97"}, {"price": "0.02", "size": "4300"}, {"price": "0.03", "size": "6.96"}, {"price": "0.05", "size": "300"}, {"price": "0.07", "size": "500"}, {"price": "0.08", "size": "8.64"}, {"price": "0.15", "size": "325"}, {"price": "0.16", "size": "1000"}, {"price": "0.17", "size": "2720"}, {"price": "0.2", "size": "5"}, {"price": "0.25", "size": "3225"}, {"price": "0.26", "size": "250"}, {"price": "0.27", "size": "50"}, {"price": "0.28", "size": "7"}, {"price": "0.34", "size": "125"}, {"price": "0.5", "size": "200"}, {"price": "0.64", "size": "10"}, {"price": "0.67", "size": "10"}, {"price": "0.7", "size": "15"}, {"price": "0.71", "size": "230"}, {"price": "0.72", "size": "110.09"}, {"price": "0.73", "size": "110"}, {"price": "0.74", "size": "177.66"}, {"price": "0.76", "size": "95.25"}], "asks": [{"price": "0.99", "size": "1550"}, {"price": "0.98", "size": "2362.9"}, {"price": "0.97", "size": "1000"}, {"price": "0.96", "size": "5.71"}, {"price": "0.94", "size": "1083"}, {"price": "0.92", "size": "6.41"}, {"price": "0.87", "size": "700"}, {"price": "0.85", "size": "9.09"}, {"price": "0.84", "size": "5"}, {"price": "0.83", "size": "10"}, {"price": "0.81", "size": "113.61"}, {"price": "0.8", "size": "65.86"}, {"price": "0.79", "size": "40"}], "event_type": "book", "last_trade_price": "0.770"}, {"market": "0xc8e2cb0f8baff17af693d88804003de9b96c84daf4abb1b55890f5c2825a8a47", "asset_id": "109795652739025079448476330308998645447360337373320102224771115367539440420835", "timestamp": "1769384417465", "hash": "618c220a8031ff7c32316bd21840a69ad67c3926", "bids": [{"price": "0.001", "size": "22143.1"}, {"price": "0.002", "size": "1923.57"}, {"price": "0.003", "size": "1400"}, {"price": "0.004", "size": "2500"}, {"price": "0.005", "size": "6.9"}, {"price": "0.006", "size": "200"}, {"price": "0.01", "size": "105350"}, {"price": "0.011", "size": "5.87"}, {"price": "0.012", "size": "1000"}, {"price": "0.02", "size": "4000"}, {"price": "0.021", "size": "2500"}, {"price": "0.024", "size": "500"}, {"price": "0.025", "size": "7.46"}, {"price": "0.05", "size": "330"}, {"price": "0.051", "size": "39"}, {"price": "0.071", "size": "2300"}, {"price": "0.072", "size": "9.64"}, {"price": "0.12", "size": "500"}, {"price": "0.14", "size": "200"}, {"price": "0.15", "size": "1325"}, {"price": "0.16", "size": "200"}, {"price": "0.179", "size": "1142"}, {"price": "0.25", "size": "250"}, {"price": "0.251", "size": "1872"}, {"price": "0.28", "size": "250"}, {"price": "0.3", "size": "300"}, {"price": "0.34", "size": "125"}, {"price": "0.6", "size": "10"}, {"price": "0.62", "size": "5"}, {"price": "0.7", "size": "5"}, {"price": "0.75", "size": "20"}, {"price": "0.8", "size": "15"}, {"price": "0.833", "size": "1096.27"}, {"price": "0.837", "size": "500"}, {"price": "0.838", "size": "200"}, {"price": "0.85", "size": "5"}, {"price": "0.87", "size": "400"}, {"price": "0.876", "size": "100"}, {"price": "0.879", "size": "300"}, {"price": "0.88", "size": "74.42"}, {"price": "0.881", "size": "43.24"}, {"price": "0.882", "size": "498.49"}, {"price": "0.885", "size": "1143.81"}, {"price": "0.886", "size": "10.63"}, {"price": "0.887", "size": "68.01"}], "asks": [{"price": "0.999", "size": "888"}, {"price": "0.998", "size": "506.54"}, {"price": "0.997", "size": "40.56"}, {"price": "0.996", "size": "57"}, {"price": "0.995", "size": "46.2"}, {"price": "0.975", "size": "1281.31"}, {"price": "0.974", "size": "50"}, {"price": "0.969", "size": "20"}, {"price": "0.968", "size": "9.84"}, {"price": "0.946", "size": "870"}, {"price": "0.945", "size": "5.8"}, {"price": "0.938", "size": "758"}, {"price": "0.937", "size": "12.19"}, {"price": "0.935", "size": "1161.62"}, {"price": "0.931", "size": "186"}, {"price": "0.93", "size": "1866"}, {"price": "0.929", "size": "315"}, {"price": "0.928", "size": "200"}, {"price": "0.916", "size": "100"}, {"price": "0.915", "size": "110"}, {"price": "0.914", "size": "134"}, {"price": "0.904", "size": "5.05"}], "event_type": "book", "last_trade_price": "0.114"}]}
{"_local_timestamp": "2026-01-25T23:40:47.471042+00:00", "data": {"market": "0x0b6072d0211619124606d4a1fbfe719654f93d44a275d4b20f5a82a8e7a140dc", "price_changes": [{"asset_id": "34085962263761623546918537130347047402005997515702608792930465133090904504788", "price": "0.77", "size": "19.98", "side": "BUY", "hash": "a0a8b77dd3f36dbc1ad1a466fc6a7bbab0c5d2eb", "best_bid": "0.77", "best_ask": "0.79"}, {"asset_id": "43515368755702423981051690629883247758860778201528671372907379948136148128501", "price": "0.23", "size": "19.98", "side": "SELL", "hash": "569ae198da7ba2c1759c933dc456f328b073acc3", "best_bid": "0.21", "best_ask": "0.23"}], "timestamp": "1769384447401", "event_type": "price_change"}}
{"_local_timestamp": "2026-01-25T23:40:48.439017+00:00", "data": {"market": "0x0b6072d0211619124606d4a1fbfe719654f93d44a275d4b20f5a82a8e7a140dc", "price_changes": [{"asset_id": "34085962263761623546918537130347047402005997515702608792930465133090904504788", "price": "0.73", "size": "10", "side": "BUY", "hash": "5034487d1ac0a8f3f74d5b05f7f1277854dd8f8d", "best_bid": "0.77", "best_ask": "0.79"}, {"asset_id": "43515368755702423981051690629883247758860778201528671372907379948136148128501", "price": "0.27", "size": "10", "side": "SELL", "hash": "3acc3a5be8267b1ff89213a7c4e7c4f61dfd70c2", "best_bid": "0.21", "best_ask": "0.23"}], "timestamp": "1769384448366", "event_type": "price_change"}}
{"_local_timestamp": "2026-01-25T23:40:52.033664+00:00", "data": {"market": "0x0b6072d0211619124606d4a1fbfe719654f93d44a275d4b20f5a82a8e7a140dc", "price_changes": [{"asset_id": "34085962263761623546918537130347047402005997515702608792930465133090904504788", "price": "0.74", "size": "277.66", "side": "BUY", "hash": "aa7db388aadfbf62dbcfa0aed37a19f9826605da", "best_bid": "0.77", "best_ask": "0.79"}, {"asset_id": "43515368755702423981051690629883247758860778201528671372907379948136148128501", "price": "0.26", "size": "277.66", "side": "SELL", "hash": "ffcc7411689640e3c5ab257511aef0df8254ddf6", "best_bid": "0.21", "best_ask": "0.23"}], "timestamp": "1769384451958", "event_type": "price_change"}}
{"_local_timestamp": "2026-01-25T23:40:52.034111+00:00", "data": {"market": "0x0b6072d0211619124606d4a1fbfe719654f93d44a275d4b20f5a82a8e7a140dc", "price_changes": [{"asset_id": "34085962263761623546918537130347047402005997515702608792930465133090904504788", "price": "0.76", "size": "28.59", "side": "BUY", "hash": "5ea5c9e939c600c4971714f13ce866fbfb254a12", "best_bid": "0.77", "best_ask": "0.79"}, {"asset_id": "43515368755702423981051690629883247758860778201528671372907379948136148128501", "price": "0.24", "size": "28.59", "side": "SELL", "hash": "d39e662312230c3743fbff2e191f81aeafa348d7", "best_bid": "0.21", "best_ask": "0.23"}], "timestamp": "1769384451958", "event_type": "price_change"}}
{"_local_timestamp": "2026-01-25T23:40:52.034436+00:00", "data": {"market": "0x0b6072d0211619124606d4a1fbfe719654f93d44a275d4b20f5a82a8e7a140dc", "price_changes": [{"asset_id": "34085962263761623546918537130347047402005997515702608792930465133090904504788", "price": "0.74", "size": "211", "side": "BUY", "hash": "5ea5c9e939c600c4971714f13ce866fbfb254a12", "best_bid": "0.77", "best_ask": "0.79"}, {"asset_id": "43515368755702423981051690629883247758860778201528671372907379948136148128501", "price": "0.26", "size": "211", "side": "SELL", "hash": "d39e662312230c3743fbff2e191f81aeafa348d7", "best_bid": "0.21", "best_ask": "0.23"}], "timestamp": "1769384451958", "event_type": "price_change"}}
{"_local_timestamp": "2026-01-25T23:40:52.034749+00:00", "data": {"market": "0x0b6072d0211619124606d4a1fbfe719654f93d44a275d4b20f5a82a8e7a140dc", "price_changes": [{"asset_id": "34085962263761623546918537130347047402005997515702608792930465133090904504788", "price": "0.72", "size": "43.43", "side": "BUY", "hash": "5ea5c9e939c600c4971714f13ce866fbfb254a12", "best_bid": "0.77", "best_ask": "0.79"}, {"asset_id": "43515368755702423981051690629883247758860778201528671372907379948136148128501", "price": "0.28", "size": "43.43", "side": "SELL", "hash": "d39e662312230c3743fbff2e191f81aeafa348d7", "best_bid": "0.21", "best_ask": "0.23"}], "timestamp": "1769384451958", "event_type": "price_change"}}
{"_local_timestamp": "2026-01-25T23:40:52.735854+00:00", "data": {"market": "0x0b6072d0211619124606d4a1fbfe719654f93d44a275d4b20f5a82a8e7a140dc", "price_changes": [{"asset_id": "34085962263761623546918537130347047402005997515702608792930465133090904504788", "price": "0.64", "size": "110", "side": "BUY", "hash": "1f6a216c9e396850ff1cb682caa480dc5ae372d4", "best_bid": "0.77", "best_ask": "0.79"}, {"asset_id": "43515368755702423981051690629883247758860778201528671372907379948136148128501", "price": "0.36", "size": "110", "side": "SELL", "hash": "a5200f707749f278ac1bea5ee0d8802eff5b6119", "best_bid": "0.21", "best_ask": "0.23"}], "timestamp": "1769384452664", "event_type": "price_change"}}
{"_local_timestamp": "2026-01-25T23:40:52.982393+00:00", "data": {"market": "0x0b6072d0211619124606d4a1fbfe719654f93d44a275d4b20f5a82a8e7a140dc", "price_changes": [{"asset_id": "34085962263761623546918537130347047402005997515702608792930465133090904504788", "price": "0.51", "size": "100", "side": "BUY", "hash": "7d00e664e0eba853b28c45c2de23fc7c88275da4", "best_bid": "0.77", "best_ask": "0.79"}, {"asset_id": "43515368755702423981051690629883247758860778201528671372907379948136148128501", "price": "0.49", "size": "100", "side": "SELL", "hash": "75e869379fe6fd3d5d7575b8615cd076d99fd2b6", "best_bid": "0.21", "best_ask": "0.23"}], "timestamp": "1769384452916", "event_type": "price_change"}}
{"_local_timestamp": "2026-01-25T23:40:54.021900+00:00", "data": {"market": "0x0b6072d0211619124606d4a1fbfe719654f93d44a275d4b20f5a82a8e7a140dc", "price_changes": [{"asset_id": "34085962263761623546918537130347047402005997515702608792930465133090904504788", "price": "0.77", "size": "0", "side": "BUY", "hash": "3e7df5818ee7035880362959a19e6a341ef4b7b2", "best_bid": "0.76", "best_ask": "0.79"}, {"asset_id": "43515368755702423981051690629883247758860778201528671372907379948136148128501", "price": "0.23", "size": "0", "side": "SELL", "hash": "b972a330c78b157d11311c4cf2dd2774131954ff", "best_bid": "0.21", "best_ask": "0.24"}], "timestamp": "1769384453954", "event_type": "price_change"}}
{"_local_timestamp": "2026-01-25T23:40:55.182916+00:00", "data": {"market": "0x0b6072d0211619124606d4a1fbfe719654f93d44a275d4b20f5a82a8e7a140dc", "price_changes": [{"asset_id": "34085962263761623546918537130347047402005997515702608792930465133090904504788", "price": "0.74", "size": "111", "side": "BUY", "hash": "89f6ae906d2ef7b953ab2b207558255de59d0b50", "best_bid": "0.76", "best_ask": "0.79"}, {"asset_id": "43515368755702423981051690629883247758860778201528671372907379948136148128501", "price": "0.26", "size": "111", "side": "SELL", "hash": "b5091ea365e82ba353f3519599c7f1da47957f92", "best_bid": "0.21", "best_ask": "0.24"}], "timestamp": "1769384455101", "event_type": "price_change"}}
{"_local_timestamp": "2026-01-25T23:40:56.163979+00:00", "data": {"market": "0x0b6072d0211619124606d4a1fbfe719654f93d44a275d4b20f5a82a8e7a140dc", "price_changes": [{"asset_id": "34085962263761623546918537130347047402005997515702608792930465133090904504788", "price": "0.75", "size": "100", "side": "BUY", "hash": "482e7544616e76a1fd972ea48c16e85eeb229c7e", "best_bid": "0.76", "best_ask": "0.79"}, {"asset_id": "43515368755702423981051690629883247758860778201528671372907379948136148128501", "price": "0.25", "size": "100", "side": "SELL", "hash": "48a3778e415024a48e935c47a7b8bfb63b3c8de6", "best_bid": "0.21", "best_ask": "0.24"}], "timestamp": "1769384456078", "event_type": "price_change"}}
{"_local_timestamp": "2026-01-25T23:40:58.638267+00:00", "data": {"market": "0x0b6072d0211619124606d4a1fbfe719654f93d44a275d4b20f5a82a8e7a140dc", "price_changes": [{"asset_id": "34085962263761623546918537130347047402005997515702608792930465133090904504788", "price": "0.74", "size": "211", "side": "BUY", "hash": "75876e36d03e37ea23f29dacc8fe16548d09f495", "best_bid": "0.76", "best_ask": "0.79"}, {"asset_id": "43515368755702423981051690629883247758860778201528671372907379948136148128501", "price": "0.26", "size": "211", "side": "SELL", "hash": "1e4d3f276b4190120c5cf9bb7874ad48813fb610", "best_bid": "0.21", "best_ask": "0.24"}], "timestamp": "1769384458573", "event_type": "price_change"}}
{"_local_timestamp": "2026-01-25T23:41:45.690470+00:00", "data": {"market": "0x0b6072d0211619124606d4a1fbfe719654f93d44a275d4b20f5a82a8e7a140dc", "price_changes": [{"asset_id": "34085962263761623546918537130347047402005997515702608792930465133090904504788", "price": "0.74", "size": "201", "side": "BUY", "hash": "7c7b805638b69cc87118115c58a0edd33e7da476", "best_bid": "0.76", "best_ask": "0.79"}, {"asset_id": "43515368755702423981051690629883247758860778201528671372907379948136148128501", "price": "0.26", "size": "201", "side": "SELL", "hash": "ceccdd9cd410030389d425f139154ec548ff05d9", "best_bid": "0.21", "best_ask": "0.24"}], "timestamp": "1769384505620", "event_type": "price_change"}}
{"_local_timestamp": "2026-01-25T23:41:45.795573+00:00", "data": {"market": "0x0b6072d0211619124606d4a1fbfe719654f93d44a275d4b20f5a82a8e7a140dc", "price_changes": [{"asset_id": "34085962263761623546918537130347047402005997515702608792930465133090904504788", "price": "0.73", "size": "20", "side": "BUY", "hash": "874cfac00932222b8035681da614c0593d16f887", "best_bid": "0.76", "best_ask": "0.79"}, {"asset_id": "43515368755702423981051690629883247758860778201528671372907379948136148128501", "price": "0.27", "size": "20", "side": "SELL", "hash": "0391830d38f4bc98119d2b06784a7d7d9545a88a", "best_bid": "0.21", "best_ask": "0.24"}], "timestamp": "1769384505725", "event_type": "price_change"}}
{"_local_timestamp": "2026-01-25T23:43:05.165296+00:00", "data": {"market": "0xc8e2cb0f8baff17af693d88804003de9b96c84daf4abb1b55890f5c2825a8a47", "price_changes": [{"asset_id": "109795652739025079448476330308998645447360337373320102224771115367539440420835", "price": "0.876", "size": "0", "side": "BUY", "hash": "a01422bb242c7dabe9ff0abf694abdc45b15c926", "best_bid": "0.887", "best_ask": "0.904"}, {"asset_id": "77159431891699383466672221717979188818354345198749135542768242998311451180645", "price": "0.124", "size": "0", "side": "SELL", "hash": "20f8f549f8e6b6cf603b16b6dcdf8854b07fb8c5", "best_bid": "0.096", "best_ask": "0.113"}], "timestamp": "1769384585000", "event_type": "price_change"}}
{"_local_timestamp": "2026-01-25T23:43:05.226010+00:00", "data": {"market": "0xc8e2cb0f8baff17af693d88804003de9b96c84daf4abb1b55890f5c2825a8a47", "price_changes": [{"asset_id": "77159431891699383466672221717979188818354345198749135542768242998311451180645", "price": "0.085", "size": "10", "side": "BUY", "hash": "fc42358fc327729791b3a73c8b0e1dafeba1acc0", "best_bid": "0.096", "best_ask": "0.113"}, {"asset_id": "109795652739025079448476330308998645447360337373320102224771115367539440420835", "price": "0.915", "size": "10", "side": "SELL", "hash": "29a7fe31567c910e4d280099264aa06bf040a09a", "best_bid": "0.887", "best_ask": "0.904"}], "timestamp": "1769384585005", "event_type": "price_change"}}
{"_local_timestamp": "2026-01-25T23:43:05.674415+00:00", "data": {"market": "0x0b6072d0211619124606d4a1fbfe719654f93d44a275d4b20f5a82a8e7a140dc", "price_changes": [{"asset_id": "43515368755702423981051690629883247758860778201528671372907379948136148128501", "price": "0.21", "size": "27.6", "side": "BUY", "hash": "139a7019c9289ed4f936afd9b04d3b4de2d550a7", "best_bid": "0.21", "best_ask": "0.24"}, {"asset_id": "34085962263761623546918537130347047402005997515702608792930465133090904504788", "price": "0.79", "size": "27.6", "side": "SELL", "hash": "41cbf4843258b945f87ae64090df181e39a5d2ba", "best_bid": "0.76", "best_ask": "0.79"}], "timestamp": "1769384585533", "event_type": "price_change"}}
{"_local_timestamp": "2026-01-25T23:43:05.675005+00:00", "data": {"market": "0x0b6072d0211619124606d4a1fbfe719654f93d44a275d4b20f5a82a8e7a140dc", "asset_id": "43515368755702423981051690629883247758860778201528671372907379948136148128501", "bids": [{"price": "0.01", "size": "1550"}, {"price": "0.02", "size": "2362.9"}, {"price": "0.03", "size": "1000"}, {"price": "0.04", "size": "5.71"}, {"price": "0.06", "size": "1083"}, {"price": "0.08", "size": "6.41"}, {"price": "0.13", "size": "700"}, {"price": "0.15", "size": "9.09"}, {"price": "0.16", "size": "5"}, {"price": "0.17", "size": "10"}, {"price": "0.19", "size": "113.61"}, {"price": "0.2", "size": "65.86"}, {"price": "0.21", "size": "27.6"}], "asks": [{"price": "0.99", "size": "5009.97"}, {"price": "0.98", "size": "4300"}, {"price": "0.97", "size": "6.96"}, {"price": "0.95", "size": "300"}, {"price": "0.93", "size": "500"}, {"price": "0.92", "size": "8.64"}, {"price": "0.85", "size": "325"}, {"price": "0.84", "size": "1000"}, {"price": "0.83", "size": "2720"}, {"price": "0.8", "size": "5"}, {"price": "0.75", "size": "3225"}, {"price": "0.74", "size": "250"}, {"price": "0.73", "size": "50"}, {"price": "0.72", "size": "7"}, {"price": "0.66", "size": "125"}, {"price": "0.5", "size": "200"}, {"price": "0.49", "size": "100"}, {"price": "0.36", "size": "110"}, {"price": "0.33", "size": "10"}, {"price": "0.3", "size": "15"}, {"price": "0.29", "size": "230"}, {"price": "0.28", "size": "43.43"}, {"price": "0.27", "size": "20"}, {"price": "0.26", "size": "201"}, {"price": "0.25", "size": "100"}, {"price": "0.24", "size": "28.59"}], "hash": "139a7019c9289ed4f936afd9b04d3b4de2d550a7", "timestamp": "1769384585533", "event_type": "book"}}
{"_local_timestamp": "2026-01-25T23:43:05.675464+00:00", "data": {"market": "0x0b6072d0211619124606d4a1fbfe719654f93d44a275d4b20f5a82a8e7a140dc", "asset_id": "34085962263761623546918537130347047402005997515702608792930465133090904504788", "bids": [{"price": "0.01", "size": "5009.97"}, {"price": "0.02", "size": "4300"}, {"price": "0.03", "size": "6.96"}, {"price": "0.05", "size": "300"}, {"price": "0.07", "size": "500"}, {"price": "0.08", "size": "8.64"}, {"price": "0.15", "size": "325"}, {"price": "0.16", "size": "1000"}, {"price": "0.17", "size": "2720"}, {"price": "0.2", "size": "5"}, {"price": "0.25", "size": "3225"}, {"price": "0.26", "size": "250"}, {"price": "0.27", "size": "50"}, {"price": "0.28", "size": "7"}, {"price": "0.34", "size": "125"}, {"price": "0.5", "size": "200"}, {"price": "0.51", "size": "100"}, {"price": "0.64", "size": "110"}, {"price": "0.67", "size": "10"}, {"price": "0.7", "size": "15"}, {"price": "0.71", "size": "230"}, {"price": "0.72", "size": "43.43"}, {"price": "0.73", "size": "20"}, {"price": "0.74", "size": "201"}, {"price": "0.75", "size": "100"}, {"price": "0.76", "size": "28.59"}], "asks": [{"price": "0.99", "size": "1550"}, {"price": "0.98", "size": "2362.9"}, {"price": "0.97", "size": "1000"}, {"price": "0.96", "size": "5.71"}, {"price": "0.94", "size": "1083"}, {"price": "0.92", "size": "6.41"}, {"price": "0.87", "size": "700"}, {"price": "0.85", "size": "9.09"}, {"price": "0.84", "size": "5"}, {"price": "0.83", "size": "10"}, {"price": "0.81", "size": "113.61"}, {"price": "0.8", "size": "65.86"}, {"price": "0.79", "size": "27.6"}], "hash": "41cbf4843258b945f87ae64090df181e39a5d2ba", "timestamp": "1769384585533", "event_type": "book"}}
{"_local_timestamp": "2026-01-25T23:43:05.702300+00:00", "data": {"market": "0x0b6072d0211619124606d4a1fbfe719654f93d44a275d4b20f5a82a8e7a140dc", "asset_id": "34085962263761623546918537130347047402005997515702608792930465133090904504788", "price": "0.79", "size": "12.392404", "fee_rate_bps": "0", "side": "BUY", "timestamp": "1769384585561", "event_type": "last_trade_price", "transaction_hash": "0xb38ff6b391eac35a810151ed169e6ee8336e338720b87649da81ffc9e10c5341"}}
{"_local_timestamp": "2026-01-25T23:43:25.474726+00:00", "data": {"market": "0x0b6072d0211619124606d4a1fbfe719654f93d44a275d4b20f5a82a8e7a140dc", "price_changes": [{"asset_id": "43515368755702423981051690629883247758860778201528671372907379948136148128501", "price": "0.02", "size": "2350", "side": "BUY", "hash": "df77d241a6bfc4741ad989c962a94aaaaf1f3995", "best_bid": "0.21", "best_ask": "0.24"}, {"asset_id": "34085962263761623546918537130347047402005997515702608792930465133090904504788", "price": "0.98", "size": "2350", "side": "SELL", "hash": "903c218d9011ee2e944e0bf9f4b4564d77e4adc8", "best_bid": "0.76", "best_ask": "0.79"}], "timestamp": "1769384605333", "event_type": "price_change"}}
{"_local_timestamp": "2026-01-25T23:43:25.475225+00:00", "data": {"market": "0x0b6072d0211619124606d4a1fbfe719654f93d44a275d4b20f5a82a8e7a140dc", "price_changes": [{"asset_id": "43515368755702423981051690629883247758860778201528671372907379948136148128501", "price": "0.04", "size": "0", "side": "BUY", "hash": "df77d241a6bfc4741ad989c962a94aaaaf1f3995", "best_bid": "0.21", "best_ask": "0.24"}, {"asset_id": "34085962263761623546918537130347047402005997515702608792930465133090904504788", "price": "0.96", "size": "0", "side": "SELL", "hash": "903c218d9011ee2e944e0bf9f4b4564d77e4adc8", "best_bid": "0.76", "best_ask": "0.79"}], "timestamp": "1769384605333", "event_type": "price_change"}}
{"_local_timestamp": "2026-01-25T23:43:25.475554+00:00", "data": {"market": "0x0b6072d0211619124606d4a1fbfe719654f93d44a275d4b20f5a82a8e7a140dc", "price_changes": [{"asset_id": "43515368755702423981051690629883247758860778201528671372907379948136148128501", "price": "0.08", "size": "0", "side": "BUY", "hash": "df77d241a6bfc4741ad989c962a94aaaaf1f3995", "best_bid": "0.21", "best_ask": "0.24"}, {"asset_id": "34085962263761623546918537130347047402005997515702608792930465133090904504788", "price": "0.92", "size": "0", "side": "SELL", "hash": "903c218d9011ee2e944e0bf9f4b4564d77e4adc8", "best_bid": "0.76", "best_ask": "0.79"}], "timestamp": "1769384605333", "event_type": "price_change"}}
{"_local_timestamp": "2026-01-25T23:43:25.825835+00:00", "data": {"market": "0x0b6072d0211619124606d4a1fbfe719654f93d44a275d4b20f5a82a8e7a140dc", "price_changes": [{"asset_id": "43515368755702423981051690629883247758860778201528671372907379948136148128501", "price": "0.03", "size": "1009.18", "side": "BUY", "hash": "b2b29750e49d347c24519328bbe498d7c3d88c4a", "best_bid": "0.21", "best_ask": "0.24"}, {"asset_id": "34085962263761623546918537130347047402005997515702608792930465133090904504788", "price": "0.97", "size": "1009.18", "side": "SELL", "hash": "52515f6e87e31f7d6b5415761b036aca17c35bd7", "best_bid": "0.76", "best_ask": "0.79"}], "timestamp": "1769384605685", "event_type": "price_change"}}
{"_local_timestamp": "2026-01-25T23:43:25.828318+00:00", "data": {"market": "0x0b6072d0211619124606d4a1fbfe719654f93d44a275d4b20f5a82a8e7a140dc", "price_changes": [{"asset_id": "43515368755702423981051690629883247758860778201528671372907379948136148128501", "price": "0.07", "size": "9.24", "side": "BUY", "hash": "b9aedb3089ed124bcecb4f35888d59cf7f1e311e", "best_bid": "0.21", "best_ask": "0.24"}, {"asset_id": "34085962263761623546918537130347047402005997515702608792930465133090904504788", "price": "0.93", "size": "9.24", "side": "SELL", "hash": "1a9b151535c56963e3fa0ad58ca8101c868dba3f", "best_bid": "0.76", "best_ask": "0.79"}], "timestamp": "1769384605685", "event_type": "price_change"}}
{"_local_timestamp": "2026-01-25T23:43:25.828833+00:00", "data": {"market": "0x0b6072d0211619124606d4a1fbfe719654f93d44a275d4b20f5a82a8e7a140dc", "price_changes": [{"asset_id": "43515368755702423981051690629883247758860778201528671372907379948136148128501", "price": "0.01", "size": "1557.71", "side": "BUY", "hash": "9b82cade445a0ef58149d9b9a254f03a088a9daa", "best_bid": "0.21", "best_ask": "0.24"}, {"asset_id": "34085962263761623546918537130347047402005997515702608792930465133090904504788", "price": "0.99", "size": "1557.71", "side": "SELL", "hash": "864e08e09a32dd061ba8d5da81b430b0124bbb60", "best_bid": "0.76", "best_ask": "0.79"}], "timestamp": "1769384605686", "event_type": "price_change"}}
{"_local_timestamp": "2026-01-25T23:43:28.990672+00:00", "data": {"market": "0xc8e2cb0f8baff17af693d88804003de9b96c84daf4abb1b55890f5c2825a8a47", "price_changes": [{"asset_id": "77159431891699383466672221717979188818354345198749135542768242998311451180645", "price": "0.086", "size": "30", "side": "BUY", "hash": "b712f27f8c475b1fceb5866c094a27d1ef9107a8", "best_bid": "0.096", "best_ask": "0.113"}, {"asset_id": "109795652739025079448476330308998645447360337373320102224771115367539440420835", "price": "0.914", "size": "30", "side": "SELL", "hash": "4eb597c3e9c0ccdf5f34c96af3ae98b70aae4dcc", "best_bid": "0.887", "best_ask": "0.904"}], "timestamp": "1769384608783", "event_type": "price_change"}}
{"_local_timestamp": "2026-01-25T23:43:30.618336+00:00", "data": {"market": "0x0b6072d0211619124606d4a1fbfe719654f93d44a275d4b20f5a82a8e7a140dc", "price_changes": [{"asset_id": "34085962263761623546918537130347047402005997515702608792930465133090904504788", "price": "0.64", "size": "10", "side": "BUY", "hash": "10ac4e603d57349b472a3ca0dabeb882d9f6aa85", "best_bid": "0.76", "best_ask": "0.79"}, {"asset_id": "43515368755702423981051690629883247758860778201528671372907379948136148128501", "price": "0.36", "size": "10", "side": "SELL", "hash": "91d4926229a419f6ffc8539053e81b880f062ac0", "best_bid": "0.21", "best_ask": "0.24"}], "timestamp": "1769384610487", "event_type": "price_change"}}
{"_local_timestamp": "2026-01-25T23:43:30.619138+00:00", "data": {"market": "0x0b6072d0211619124606d4a1fbfe719654f93d44a275d4b20f5a82a8e7a140dc", "price_changes": [{"asset_id": "34085962263761623546918537130347047402005997515702608792930465133090904504788", "price": "0.51", "size": "0", "side": "BUY", "hash": "10ac4e603d57349b472a3ca0dabeb882d9f6aa85", "best_bid": "0.76", "best_ask": "0.79"}, {"asset_id": "43515368755702423981051690629883247758860778201528671372907379948136148128501", "price": "0.49", "size": "0", "side": "SELL", "hash": "91d4926229a419f6ffc8539053e81b880f062ac0", "best_bid": "0.21", "best_ask": "0.24"}], "timestamp": "1769384610487", "event_type": "price_change"}}
{"_local_timestamp": "2026-01-25T23:43:31.244389+00:00", "data": {"market": "0xc8e2cb0f8baff17af693d88804003de9b96c84daf4abb1b55890f5c2825a8a47", "price_changes": [{"asset_id": "77159431891699383466672221717979188818354345198749135542768242998311451180645", "price": "0.073", "size": "123", "side": "BUY", "hash": "f628dca73bd8fdfd1f36876373dccf1b568685e5", "best_bid": "0.096", "best_ask": "0.113"}, {"asset_id": "109795652739025079448476330308998645447360337373320102224771115367539440420835", "price": "0.927", "size": "123", "side": "SELL", "hash": "4405430ade30393e96549f85d4fa0b146a77d9d5", "best_bid": "0.887", "best_ask": "0.904"}], "timestamp": "1769384611109", "event_type": "price_change"}}
{"_local_timestamp": "2026-01-25T23:43:31.278795+00:00", "data": {"market": "0x0b6072d0211619124606d4a1fbfe719654f93d44a275d4b20f5a82a8e7a140dc", "price_changes": [{"asset_id": "34085962263761623546918537130347047402005997515702608792930465133090904504788", "price": "0.77", "size": "66.66", "side": "BUY", "hash": "839e50c7f11a2229fd96f1d37f83c87892d65cf6", "best_bid": "0.77", "best_ask": "0.79"}, {"asset_id": "43515368755702423981051690629883247758860778201528671372907379948136148128501", "price": "0.23", "size": "66.66", "side": "SELL", "hash": "9e440dbc2df7436e62b5cb897293731a63959a43", "best_bid": "0.21", "best_ask": "0.23"}], "timestamp": "1769384611155", "event_type": "price_change"}}
{"_local_timestamp": "2026-01-25T23:43:31.502410+00:00", "data": {"market": "0x0b6072d0211619124606d4a1fbfe719654f93d44a275d4b20f5a82a8e7a140dc", "price_changes": [{"asset_id": "34085962263761623546918537130347047402005997515702608792930465133090904504788", "price": "0.74", "size": "267.66", "side": "BUY", "hash": "e2725bc586c27090b4f8ffc60a06e9dd16f8f5d8", "best_bid": "0.77", "best_ask": "0.79"}, {"asset_id": "43515368755702423981051690629883247758860778201528671372907379948136148128501", "price": "0.26", "size": "267.66", "side": "SELL", "hash": "940306901fb1bdc9fd761220e08e054b48a32ac9", "best_bid": "0.21", "best_ask": "0.23"}], "timestamp": "1769384611378", "event_type": "price_change"}}
{"_local_timestamp": "2026-01-25T23:43:31.631745+00:00", "data": {"market": "0x0b6072d0211619124606d4a1fbfe719654f93d44a275d4b20f5a82a8e7a140dc", "price_changes": [{"asset_id": "34085962263761623546918537130347047402005997515702608792930465133090904504788", "price": "0.72", "size": "110.09", "side": "BUY", "hash": "f014bb6273dc4580a9dd22671025893abd11d6ed", "best_bid": "0.77", "best_ask": "0.79"}, {"asset_id": "43515368755702423981051690629883247758860778201528671372907379948136148128501", "price": "0.28", "size": "110.09", "side": "SELL", "hash": "ba368b217714b9593ae308bfd5bfc18450938044", "best_bid": "0.21", "best_ask": "0.23"}], "timestamp": "1769384611504", "event_type": "price_change"}}
{"_local_timestamp": "2026-01-25T23:43:32.417477+00:00", "data": {"market": "0x0b6072d0211619124606d4a1fbfe719654f93d44a275d4b20f5a82a8e7a140dc", "price_changes": [{"asset_id": "34085962263761623546918537130347047402005997515702608792930465133090904504788", "price": "0.74", "size": "167.66", "side": "BUY", "hash": "74b8b7a75c0daa7cd1f0e7c398b6a1a998eb3eab", "best_bid": "0.77", "best_ask": "0.79"}, {"asset_id": "43515368755702423981051690629883247758860778201528671372907379948136148128501", "price": "0.26", "size": "167.66", "side": "SELL", "hash": "32071ec2505d0a51de6c53531abf5dcb1cb9c7d9", "best_bid": "0.21", "best_ask": "0.23"}], "timestamp": "1769384612301", "event_type": "price_change"}}
{"_local_timestamp": "2026-01-25T23:43:32.630197+00:00", "data": {"market": "0xc8e2cb0f8baff17af693d88804003de9b96c84daf4abb1b55890f5c2825a8a47", "price_changes": [{"asset_id": "77159431891699383466672221717979188818354345198749135542768242998311451180645", "price": "0.086", "size": "0", "side": "BUY", "hash": "2c6c908ffd0ae009704ebb21343db3ab847a3c7b", "best_bid": "0.096", "best_ask": "0.113"}, {"asset_id": "109795652739025079448476330308998645447360337373320102224771115367539440420835", "price": "0.914", "size": "0", "side": "SELL", "hash": "eba60f057131060a666787cc0ee4b362c5f2bbe9", "best_bid": "0.887", "best_ask": "0.904"}], "timestamp": "1769384612499", "event_type": "price_change"}}
{"_local_timestamp": "2026-01-25T23:43:32.674944+00:00", "data": {"market": "0xc8e2cb0f8baff17af693d88804003de9b96c84daf4abb1b55890f5c2825a8a47", "price_changes": [{"asset_id": "77159431891699383466672221717979188818354345198749135542768242998311451180645", "price": "0.085", "size": "40", "side": "BUY", "hash": "2bbbd8e5c9086247b88db2fa66d5aa5c34cd2af9", "best_bid": "0.096", "best_ask": "0.113"}, {"asset_id": "109795652739025079448476330308998645447360337373320102224771115367539440420835", "price": "0.915", "size": "40", "side": "SELL", "hash": "dc6a248440e8d4d976a7650399ecaabf1828be4a", "best_bid": "0.887", "best_ask": "0.904"}], "timestamp": "1769384612550", "event_type": "price_change"}}
{"_local_timestamp": "2026-01-25T23:43:32.978753+00:00", "data": {"market": "0xc8e2cb0f8baff17af693d88804003de9b96c84daf4abb1b55890f5c2825a8a47", "price_changes": [{"asset_id": "77159431891699383466672221717979188818354345198749135542768242998311451180645", "price": "0.07", "size": "1766", "side": "BUY", "hash": "86c4653b42d37050d9921135ed8cee4962ba8ebb", "best_bid": "0.096", "best_ask": "0.113"}, {"asset_id": "109795652739025079448476330308998645447360337373320102224771115367539440420835", "price": "0.93", "size": "1766", "side": "SELL", "hash": "d99b2ec8eb54c4ddd777b3e3556b1bf31b113800", "best_bid": "0.887", "best_ask": "0.904"}], "timestamp": "1769384612859", "event_type": "price_change"}}
{"_local_timestamp": "2026-01-25T23:43:35.950952+00:00", "data": {"market": "0x0b6072d0211619124606d4a1fbfe719654f93d44a275d4b20f5a82a8e7a140dc", "price_changes": [{"asset_id": "34085962263761623546918537130347047402005997515702608792930465133090904504788", "price": "0.75", "size": "0", "side": "BUY", "hash": "015801288607325dc0e567a38ed8251f6442d2c3", "best_bid": "0.77", "best_ask": "0.79"}, {"asset_id": "43515368755702423981051690629883247758860778201528671372907379948136148128501", "price": "0.25", "size": "0", "side": "SELL", "hash": "64daf251e3bcbbac82267a17557aa69e168b9467", "best_bid": "0.21", "best_ask": "0.23"}], "timestamp": "1769384615801", "event_type": "price_change"}}
{"_local_timestamp": "2026-01-25T23:43:36.257601+00:00", "data": {"market": "0x0b6072d0211619124606d4a1fbfe719654f93d44a275d4b20f5a82a8e7a140dc", "price_changes": [{"asset_id": "34085962263761623546918537130347047402005997515702608792930465133090904504788", "price": "0.75", "size": "100", "side": "BUY", "hash": "26caf88d2dead2a9f9a0a58737e3ca92d3ef0d05", "best_bid": "0.77", "best_ask": "0.79"}, {"asset_id": "43515368755702423981051690629883247758860778201528671372907379948136148128501", "price": "0.25", "size": "100", "side": "SELL", "hash": "8d54a53f5adcd572f6e38973757136de23b000a1", "best_bid": "0.21", "best_ask": "0.23"}], "timestamp": "1769384616131", "event_type": "price_change"}}
{"_local_timestamp": "2026-01-25T23:43:36.522019+00:00", "data": {"market": "0xc8e2cb0f8baff17af693d88804003de9b96c84daf4abb1b55890f5c2825a8a47", "price_changes": [{"asset_id": "77159431891699383466672221717979188818354345198749135542768242998311451180645", "price": "0.07", "size": "1866", "side": "BUY", "hash": "4d6c11af7cd10ef438fdcefa304179dae706d6ce", "best_bid": "0.096", "best_ask": "0.113"}, {"asset_id": "109795652739025079448476330308998645447360337373320102224771115367539440420835", "price": "0.93", "size": "1866", "side": "SELL", "hash": "d13b2a8c1a7e8ad6c5c7ee442cce6b9fe83694f0", "best_bid": "0.887", "best_ask": "0.904"}], "timestamp": "1769384616381", "event_type": "price_change"}}
{"_local_timestamp": "2026-01-25T23:43:51.495420+00:00", "data": {"market": "0x0b6072d0211619124606d4a1fbfe719654f93d44a275d4b20f5a82a8e7a140dc", "price_changes": [{"asset_id": "34085962263761623546918537130347047402005997515702608792930465133090904504788", "price": "0.73", "size": "10", "side": "BUY", "hash": "f2003f0ede1322265845e4338f47ffb3782ce2d4", "best_bid": "0.77", "best_ask": "0.79"}, {"asset_id": "43515368755702423981051690629883247758860778201528671372907379948136148128501", "price": "0.27", "size": "10", "side": "SELL", "hash": "5bd367864813f3b8f9c8a02c2c065f8a2ebabf38", "best_bid": "0.21", "best_ask": "0.23"}], "timestamp": "1769384631242", "event_type": "price_change"}}
{"_local_timestamp": "2026-01-25T23:43:51.575927+00:00", "data": {"market": "0x0b6072d0211619124606d4a1fbfe719654f93d44a275d4b20f5a82a8e7a140dc", "price_changes": [{"asset_id": "34085962263761623546918537130347047402005997515702608792930465133090904504788", "price": "0.74", "size": "177.66", "side": "BUY", "hash": "6aa91defeb39da560cb65667aa7d96c999e96000", "best_bid": "0.77", "best_ask": "0.79"}, {"asset_id": "43515368755702423981051690629883247758860778201528671372907379948136148128501", "price": "0.26", "size": "177.66", "side": "SELL", "hash": "2938b207c5f36ba9155b29294948590384d23e67", "best_bid": "0.21", "best_ask": "0.23"}], "timestamp": "1769384631326", "event_type": "price_change"}}
{"_local_timestamp": "2026-01-25T23:44:03.762902+00:00", "data": {"market": "0xc8e2cb0f8baff17af693d88804003de9b96c84daf4abb1b55890f5c2825a8a47", "price_changes": [{"asset_id": "77159431891699383466672221717979188818354345198749135542768242998311451180645", "price": "0.085", "size": "30", "side": "BUY", "hash": "8045f724af96bfa44efd2aee717f9217156a15b9", "best_bid": "0.096", "best_ask": "0.113"}, {"asset_id": "109795652739025079448476330308998645447360337373320102224771115367539440420835", "price": "0.915", "size": "30", "side": "SELL", "hash": "3f7a45b3e505164796e51a94266cbbdb56239a3d", "best_bid": "0.887", "best_ask": "0.904"}], "timestamp": "1769384643478", "event_type": "price_change"}}
{"_local_timestamp": "2026-01-25T23:44:03.885045+00:00", "data": {"market": "0xc8e2cb0f8baff17af693d88804003de9b96c84daf4abb1b55890f5c2825a8a47", "price_changes": [{"asset_id": "77159431891699383466672221717979188818354345198749135542768242998311451180645", "price": "0.084", "size": "110", "side": "BUY", "hash": "9bb61da145d649e169ad5f44dbf3cbcba326924f", "best_bid": "0.096", "best_ask": "0.113"}, {"asset_id": "109795652739025079448476330308998645447360337373320102224771115367539440420835", "price": "0.916", "size": "110", "side": "SELL", "hash": "477f32b85981415819b2ef1c487acc054f89038d", "best_bid": "0.887", "best_ask": "0.904"}], "timestamp": "1769384643585", "event_type": "price_change"}}
{"_local_timestamp": "2026-01-25T23:45:22.851097+00:00", "data": {"market": "0x0b6072d0211619124606d4a1fbfe719654f93d44a275d4b20f5a82a8e7a140dc", "price_changes": [{"asset_id": "34085962263761623546918537130347047402005997515702608792930465133090904504788", "price": "0.75", "size": "0", "side": "BUY", "hash": "c87bfacf5fbfc1e5cbe84160d0e239ad2c507763", "best_bid": "0.77", "best_ask": "0.79"}, {"asset_id": "43515368755702423981051690629883247758860778201528671372907379948136148128501", "price": "0.25", "size": "0", "side": "SELL", "hash": "f2d072eab94a56635c5cb63f4b51e80e6c3759a0", "best_bid": "0.21", "best_ask": "0.23"}], "timestamp": "1769384722772", "event_type": "price_change"}}
{"_local_timestamp": "2026-01-25T23:45:22.852100+00:00", "data": {"market": "0x0b6072d0211619124606d4a1fbfe719654f93d44a275d4b20f5a82a8e7a140dc", "price_changes": [{"asset_id": "43515368755702423981051690629883247758860778201528671372907379948136148128501", "price": "0.19", "size": "13.61", "side": "BUY", "hash": "a457030a8583a1562f2686f083633df1c57cae9e", "best_bid": "0.21", "best_ask": "0.23"}, {"asset_id": "34085962263761623546918537130347047402005997515702608792930465133090904504788", "price": "0.81", "size": "13.61", "side": "SELL", "hash": "666dfa6c88b40ce39200d7656af6c91c20986d88", "best_bid": "0.77", "best_ask": "0.79"}], "timestamp": "1769384722773", "event_type": "price_change"}}
{"_local_timestamp": "2026-01-25T23:45:38.294473+00:00", "data": {"market": "0x0b6072d0211619124606d4a1fbfe719654f93d44a275d4b20f5a82a8e7a140dc", "price_changes": [{"asset_id": "34085962263761623546918537130347047402005997515702608792930465133090904504788", "price": "0.74", "size": "277.66", "side": "BUY", "hash": "628a942c6e06dd4bf87898801b49bf8d62342a1f", "best_bid": "0.77", "best_ask": "0.79"}, {"asset_id": "43515368755702423981051690629883247758860778201528671372907379948136148128501", "price": "0.26", "size": "277.66", "side": "SELL", "hash": "d460fc9a5e87fc324a5137281c0773bfdb3b0004", "best_bid": "0.21", "best_ask": "0.23"}], "timestamp": "1769384738228", "event_type": "price_change"}}
{"_local_timestamp": "2026-01-25T23:45:41.587346+00:00", "data": {"market": "0x0b6072d0211619124606d4a1fbfe719654f93d44a275d4b20f5a82a8e7a140dc", "price_changes": [{"asset_id": "43515368755702423981051690629883247758860778201528671372907379948136148128501", "price": "0.19", "size": "113.61", "side": "BUY", "hash": "3c07f01f11b9f6699c2f166ef15a2db77546fd25", "best_bid": "0.21", "best_ask": "0.23"}, {"asset_id": "34085962263761623546918537130347047402005997515702608792930465133090904504788", "price": "0.81", "size": "113.61", "side": "SELL", "hash": "0f94e1f2c806f29661b75a6fabc4d9bcf9c98fb7", "best_bid": "0.77", "best_ask": "0.79"}], "timestamp": "1769384741512", "event_type": "price_change"}}
{"_local_timestamp": "2026-01-25T23:45:56.410352+00:00", "data": {"market": "0x0b6072d0211619124606d4a1fbfe719654f93d44a275d4b20f5a82a8e7a140dc", "price_changes": [{"asset_id": "43515368755702423981051690629883247758860778201528671372907379948136148128501", "price": "0.06", "size": "783", "side": "BUY", "hash": "2970a74b0489fa35ce4d286f49f6a7dffaaaf1ac", "best_bid": "0.21", "best_ask": "0.23"}, {"asset_id": "34085962263761623546918537130347047402005997515702608792930465133090904504788", "price": "0.94", "size": "783", "side": "SELL", "hash": "c38abd19126b1e720522c2ec02050a8899ebcfcb", "best_bid": "0.77", "best_ask": "0.79"}], "timestamp": "1769384756077", "event_type": "price_change"}}
{"_local_timestamp": "2026-01-25T23:46:22.305383+00:00", "data": {"market": "0x0b6072d0211619124606d4a1fbfe719654f93d44a275d4b20f5a82a8e7a140dc", "price_changes": [{"asset_id": "43515368755702423981051690629883247758860778201528671372907379948136148128501", "price": "0.07", "size": "309.24", "side": "BUY", "hash": "0bdb19ab4bbbf261ca7150b1bb96ec3ecc91869c", "best_bid": "0.21", "best_ask": "0.23"}, {"asset_id": "34085962263761623546918537130347047402005997515702608792930465133090904504788", "price": "0.93", "size": "309.24", "side": "SELL", "hash": "802b7eac550592fd51fd8c867abb8019b9bb3b9d", "best_bid": "0.77", "best_ask": "0.79"}], "timestamp": "1769384782228", "event_type": "price_change"}}
{"_local_timestamp": "2026-01-25T23:46:28.868639+00:00", "data": {"market": "0xc8e2cb0f8baff17af693d88804003de9b96c84daf4abb1b55890f5c2825a8a47", "price_changes": [{"asset_id": "77159431891699383466672221717979188818354345198749135542768242998311451180645", "price": "0.073", "size": "0", "side": "BUY", "hash": "cb6a7634c18c6b228995dbe88737b851421af345", "best_bid": "0.096", "best_ask": "0.113"}, {"asset_id": "109795652739025079448476330308998645447360337373320102224771115367539440420835", "price": "0.927", "size": "0", "side": "SELL", "hash": "e70c289ad21ffef4f41164b1f8c3445464272261", "best_bid": "0.887", "best_ask": "0.904"}], "timestamp": "1769384788744", "event_type": "price_change"}}
{"_local_timestamp": "2026-01-25T23:46:29.867272+00:00", "data": {"market": "0xc8e2cb0f8baff17af693d88804003de9b96c84daf4abb1b55890f5c2825a8a47", "price_changes": [{"asset_id": "77159431891699383466672221717979188818354345198749135542768242998311451180645", "price": "0.07", "size": "1766", "side": "BUY", "hash": "a8c8850c108dad885e3c645dcb39c775d2521b12", "best_bid": "0.096", "best_ask": "0.113"}, {"asset_id": "109795652739025079448476330308998645447360337373320102224771115367539440420835", "price": "0.93", "size": "1766", "side": "SELL", "hash": "fba1be0ce1ce00a5bc51da186af452c091ede713", "best_bid": "0.887", "best_ask": "0.904"}], "timestamp": "1769384789760", "event_type": "price_change"}}
{"_local_timestamp": "2026-01-25T23:46:31.448556+00:00", "data": {"market": "0xc8e2cb0f8baff17af693d88804003de9b96c84daf4abb1b55890f5c2825a8a47", "price_changes": [{"asset_id": "77159431891699383466672221717979188818354345198749135542768242998311451180645", "price": "0.085", "size": "135", "side": "BUY", "hash": "99228a9cce70a84eff9fd59da3296c9c22c05c44", "best_bid": "0.096", "best_ask": "0.113"}, {"asset_id": "109795652739025079448476330308998645447360337373320102224771115367539440420835", "price": "0.915", "size": "135", "side": "SELL", "hash": "f7e205b2d43fb11f88b27b0e01b5cb13e7a84c9c", "best_bid": "0.887", "best_ask": "0.904"}], "timestamp": "1769384791368", "event_type": "price_change"}}
{"_local_timestamp": "2026-01-25T23:46:33.339795+00:00", "data": {"market": "0xc8e2cb0f8baff17af693d88804003de9b96c84daf4abb1b55890f5c2825a8a47", "price_changes": [{"asset_id": "77159431891699383466672221717979188818354345198749135542768242998311451180645", "price": "0.069", "size": "286", "side": "BUY", "hash": "78570c667290edffb6dd1b1eccad4567d4c58128", "best_bid": "0.096", "best_ask": "0.113"}, {"asset_id": "109795652739025079448476330308998645447360337373320102224771115367539440420835", "price": "0.931", "size": "286", "side": "SELL", "hash": "ed27b3783701953a67ff85457ac0bc8ac1a903cf", "best_bid": "0.887", "best_ask": "0.904"}], "timestamp": "1769384793260", "event_type": "price_change"}}
{"_local_timestamp": "2026-01-25T23:46:41.862546+00:00", "data": {"market": "0xc8e2cb0f8baff17af693d88804003de9b96c84daf4abb1b55890f5c2825a8a47", "price_changes": [{"asset_id": "77159431891699383466672221717979188818354345198749135542768242998311451180645", "price": "0.069", "size": "186", "side": "BUY", "hash": "b5b3489fc689f3ed122ae1fcaf3d227e59e038e0", "best_bid": "0.096", "best_ask": "0.113"}, {"asset_id": "109795652739025079448476330308998645447360337373320102224771115367539440420835", "price": "0.931", "size": "186", "side": "SELL", "hash": "dcb89d8106318d63ba4a19cffbf88181172a1d4e", "best_bid": "0.887", "best_ask": "0.904"}], "timestamp": "1769384801762", "event_type": "price_change"}}
{"_local_timestamp": "2026-01-25T23:46:41.871493+00:00", "data": {"market": "0xc8e2cb0f8baff17af693d88804003de9b96c84daf4abb1b55890f5c2825a8a47", "price_changes": [{"asset_id": "109795652739025079448476330308998645447360337373320102224771115367539440420835", "price": "0.879", "size": "200", "side": "BUY", "hash": "d227ed999d2c2e88b1a3665065ed217daeeee1b8", "best_bid": "0.887", "best_ask": "0.904"}, {"asset_id": "77159431891699383466672221717979188818354345198749135542768242998311451180645", "price": "0.121", "size": "200", "side": "SELL", "hash": "e81897dc2d1211fbd027ac7af7fb4f84830bf3c0", "best_bid": "0.096", "best_ask": "0.113"}], "timestamp": "1769384801763", "event_type": "price_change"}}
{"_local_timestamp": "2026-01-25T23:46:44.566892+00:00", "data": {"market": "0xc8e2cb0f8baff17af693d88804003de9b96c84daf4abb1b55890f5c2825a8a47", "price_changes": [{"asset_id": "109795652739025079448476330308998645447360337373320102224771115367539440420835", "price": "0.879", "size": "300", "side": "BUY", "hash": "e27fb3c732b75c37f3dfef3fb3f673828eb64ef5", "best_bid": "0.887", "best_ask": "0.904"}, {"asset_id": "77159431891699383466672221717979188818354345198749135542768242998311451180645", "price": "0.121", "size": "300", "side": "SELL", "hash": "8aa6ec82b66a33f633dc50eb1908867117ee5475", "best_bid": "0.096", "best_ask": "0.113"}], "timestamp": "1769384804495", "event_type": "price_change"}}
{"_local_timestamp": "2026-01-25T23:46:51.569070+00:00", "data": {"market": "0x0b6072d0211619124606d4a1fbfe719654f93d44a275d4b20f5a82a8e7a140dc", "price_changes": [{"asset_id": "34085962263761623546918537130347047402005997515702608792930465133090904504788", "price": "0.5", "size": "260", "side": "BUY", "hash": "352cec141835a99379b96c68732970b8a82d72e5", "best_bid": "0.77", "best_ask": "0.79"}, {"asset_id": "43515368755702423981051690629883247758860778201528671372907379948136148128501", "price": "0.5", "size": "260", "side": "SELL", "hash": "850ed8a478627b06aa212d7b7104e9fd9e51aa97", "best_bid": "0.21", "best_ask": "0.23"}], "timestamp": "1769384811223", "event_type": "price_change"}}
{"_local_timestamp": "2026-01-25T23:47:03.204264+00:00", "data": {"market": "0x0b6072d0211619124606d4a1fbfe719654f93d44a275d4b20f5a82a8e7a140dc", "price_changes": [{"asset_id": "43515368755702423981051690629883247758860778201528671372907379948136148128501", "price": "0.01", "size": "1550", "side": "BUY", "hash": "0be0ffd7eb604ead6f9d20765a5d5f5d4f0fa0ad", "best_bid": "0.21", "best_ask": "0.23"}, {"asset_id": "34085962263761623546918537130347047402005997515702608792930465133090904504788", "price": "0.99", "size": "1550", "side": "SELL", "hash": "47d1bf76f0620c847833b2174c559845c70b3d0c", "best_bid": "0.77", "best_ask": "0.79"}], "timestamp": "1769384823129", "event_type": "price_change"}}
{"_local_timestamp": "2026-01-25T23:47:03.204805+00:00", "data": {"market": "0x0b6072d0211619124606d4a1fbfe719654f93d44a275d4b20f5a82a8e7a140dc", "price_changes": [{"asset_id": "43515368755702423981051690629883247758860778201528671372907379948136148128501", "price": "0.03", "size": "1000", "side": "BUY", "hash": "0be0ffd7eb604ead6f9d20765a5d5f5d4f0fa0ad", "best_bid": "0.21", "best_ask": "0.23"}, {"asset_id": "34085962263761623546918537130347047402005997515702608792930465133090904504788", "price": "0.97", "size": "1000", "side": "SELL", "hash": "47d1bf76f0620c847833b2174c559845c70b3d0c", "best_bid": "0.77", "best_ask": "0.79"}], "timestamp": "1769384823129", "event_type": "price_change"}}
{"_local_timestamp": "2026-01-25T23:47:03.213848+00:00", "data": {"market": "0x0b6072d0211619124606d4a1fbfe719654f93d44a275d4b20f5a82a8e7a140dc", "price_changes": [{"asset_id": "43515368755702423981051690629883247758860778201528671372907379948136148128501", "price": "0.07", "size": "300", "side": "BUY", "hash": "0be0ffd7eb604ead6f9d20765a5d5f5d4f0fa0ad", "best_bid": "0.21", "best_ask": "0.23"}, {"asset_id": "34085962263761623546918537130347047402005997515702608792930465133090904504788", "price": "0.93", "size": "300", "side": "SELL", "hash": "47d1bf76f0620c847833b2174c559845c70b3d0c", "best_bid": "0.77", "best_ask": "0.79"}], "timestamp": "1769384823129", "event_type": "price_change"}}
{"_local_timestamp": "2026-01-25T23:47:03.726276+00:00", "data": {"market": "0x0b6072d0211619124606d4a1fbfe719654f93d44a275d4b20f5a82a8e7a140dc", "price_changes": [{"asset_id": "43515368755702423981051690629883247758860778201528671372907379948136148128501", "price": "0.08", "size": "7.17", "side": "BUY", "hash": "5c0ae44b29a0db901018603e06d44d2e21716f4a", "best_bid": "0.21", "best_ask": "0.23"}, {"asset_id": "34085962263761623546918537130347047402005997515702608792930465133090904504788", "price": "0.92", "size": "7.17", "side": "SELL", "hash": "93f09bb61d1019db2d591e2b8aca3062d97d415c", "best_bid": "0.77", "best_ask": "0.79"}], "timestamp": "1769384823657", "event_type": "price_change"}}
{"_local_timestamp": "2026-01-25T23:47:03.727183+00:00", "data": {"market": "0x0b6072d0211619124606d4a1fbfe719654f93d44a275d4b20f5a82a8e7a140dc", "price_changes": [{"asset_id": "43515368755702423981051690629883247758860778201528671372907379948136148128501", "price": "0.02", "size": "2357.84", "side": "BUY", "hash": "7b4c5587445a6b52ee0d104b3541f0b40c10751f", "best_bid": "0.21", "best_ask": "0.23"}, {"asset_id": "34085962263761623546918537130347047402005997515702608792930465133090904504788", "price": "0.98", "size": "2357.84", "side": "SELL", "hash": "04ff0e0b5bf33ae5446f853bb87e7744a9d5a65e", "best_bid": "0.77", "best_ask": "0.79"}], "timestamp": "1769384823657", "event_type": "price_change"}}
{"_local_timestamp": "2026-01-25T23:47:03.727733+00:00", "data": {"market": "0x0b6072d0211619124606d4a1fbfe719654f93d44a275d4b20f5a82a8e7a140dc", "price_changes": [{"asset_id": "43515368755702423981051690629883247758860778201528671372907379948136148128501", "price": "0.04", "size": "6.73", "side": "BUY", "hash": "c55e60e38283435d8d0906764da689dc4050dedc", "best_bid": "0.21", "best_ask": "0.23"}, {"asset_id": "34085962263761623546918537130347047402005997515702608792930465133090904504788", "price": "0.96", "size": "6.73", "side": "SELL", "hash": "c66760d175ab3a33fdebeee0a3bdb0be8ea8ca82", "best_bid": "0.77", "best_ask": "0.79"}], "timestamp": "1769384823658", "event_type": "price_change"}}
{"_local_timestamp": "2026-01-25T23:47:04.581814+00:00", "data": {"market": "0xc8e2cb0f8baff17af693d88804003de9b96c84daf4abb1b55890f5c2825a8a47", "price_changes": [{"asset_id": "77159431891699383466672221717979188818354345198749135542768242998311451180645", "price": "0.069", "size": "286", "side": "BUY", "hash": "872c264e12c892568093e340e831be7a27d7d39a", "best_bid": "0.096", "best_ask": "0.113"}, {"asset_id": "109795652739025079448476330308998645447360337373320102224771115367539440420835", "price": "0.931", "size": "286", "side": "SELL", "hash": "a2f2371fd6c665f25ac432a96acccfea0bf3a44f", "best_bid": "0.887", "best_ask": "0.904"}], "timestamp": "1769384824504", "event_type": "price_change"}}
