{"_local_timestamp": "2026-01-25T23:40:31.188375+00:00", "data": [{"market": "0xb4c6f7991dc5d1e110abb1404c629deb7bbc4b07ff19bb4672ff41801824490e", "asset_id": "12726823989557107952268342942906206381973799399453895205022550590946554841098", "timestamp": "1769384404948", "hash": "68e1cfdf53340d5b2508e902e9a536b6cfa78989", "bids": [{"price": "0.01", "size": "6309.71"}, {"price": "0.02", "size": "2450"}, {"price": "0.03", "size": "250"}, {"price": "0.04", "size": "7.61"}, {"price": "0.05", "size": "30"}, {"price": "0.06", "size": "983"}, {"price": "0.1", "size": "360"}, {"price": "0.11", "size": "5.44"}, {"price": "0.14", "size": "242.85"}, {"price": "0.15", "size": "550"}, {"price": "0.16", "size": "1450"}, {"price": "0.19", "size": "168.42"}, {"price": "0.23", "size": "794"}, {"price": "0.24", "size": "116.66"}, {"price": "0.25", "size": "150"}, {"price": "0.29", "size": "189.65"}, {"price": "0.3", "size": "1400"}, {"price": "0.34", "size": "70.58"}, {"price": "0.35", "size": "1814"}, {"price": "0.36", "size": "4545"}, {"price": "0.38", "size": "127.63"}, {"price": "0.48", "size": "60"}, {"price": "0.49", "size": "5"}, {"price": "0.61", "size": "232.92"}, {"price": "0.73", "size": "200"}, {"price": "0.79", "size": "50"}, {"price": "0.8", "size": "50"}, {"price": "0.81", "size": "50"}, {"price": "0.82", "size": "50"}, {"price": "0.83", "size": "50"}, {"price": "0.84", "size": "50"}, {"price": "0.85", "size": "50"}, {"price": "0.86", "size": "50"}, {"price": "0.87", "size": "250"}, {"price": "0.88", "size": "10"}, {"price": "0.92", "size": "1307.13"}, {"price": "0.93", "size": "1706.99"}, {"price": "0.94", "size": "1550.29"}], "asks": [{"price": "0.99", "size": "2510"}, {"price": "0.98", "size": "25843.62"}, {"price": "0.97", "size": "24028.39"}, {"price": "0.96", "size": "724.14"}], "event_type": "book", "last_trade_price": "0.040"}, {"market": "0xb4c6f7991dc5d1e110abb1404c629deb7bbc4b07ff19bb4672ff41801824490e", "asset_id": "48577451271083670981595797636824300354923632195069165655560061059665286147100", "timestamp": "1769384404948", "hash": "b6d46c207847615738965e09d0bc8424fb7e26f0", "bids": [{"price": "0.01", "size": "2510"}, {"price": "0.02", "size": "25843.62"}, {"price": "0.03", "size": "24028.39"}, {"price": "0.04", "size": "724.14"}], "asks": [{"price": "0.99", "size": "6309.71"}, {"price": "0.98", "size": "2450"}, {"price": "0.97", "size": "250"}, {"price": "0.96", "size": "7.61"}, {"price": "0.95", "size": "30"}, {"price": "0.94", "size": "983"}, {"price": "0.9", "size": "360"}, {"price": "0.89", "size": "5.44"}, {"price": "0.86", "size": "242.85"}, {"price": "0.85", "size": "550"}, {"price": "0.84", "size": "1450"}, {"price": "0.81", "size": "168.42"}, {"price": "0.77", "size": "794"}, {"price": "0.76", "size": "116.66"}, {"price": "0.75", "size": "150"}, {"price": "0.71", "size": "189.65"}, {"price": "0.7", "size": "1400"}, {"price": "0.66", "size": "70.58"}, {"price": "0.65", "size": "1814"}, {"price": "0.64", "size": "4545"}, {"price": "0.62", "size": "127.63"}, {"price": "0.52", "size": "60"}, {"price": "0.51", "size": "5"}, {"price": "0.39", "size": "232.92"}, {"price": "0.27", "size": "200"}, {"price": "0.21", "size": "50"}, {"price": "0.2", "size": "50"}, {"price": "0.19", "size": "50"}, {"price": "0.18", "size": "50"}, {"price": "0.17", "size": "50"}, {"price": "0.16", "size": "50"}, {"price": "0.15", "size": "50"}, {"price": "0.14", "size": "50"}, {"price": "0.13", "size": "250"}, {"price": "0.12", "size": "10"}, {"price": "0.08", "size": "1307.13"}, {"price": "0.07", "size": "1706.99"}, {"price": "0.06", "size": "1550.29"}], "event_type": "book", "last_trade_price": "0.040"}]}
{"_local_timestamp": "2026-01-25T23:40:31.720901+00:00", "data": {"market": "0xb4c6f7991dc5d1e110abb1404c629deb7bbc4b07ff19bb4672ff41801824490e", "price_changes": [{"asset_id": "12726823989557107952268342942906206381973799399453895205022550590946554841098", "price": "0.29", "size": "139.65", "side": "BUY", "hash": "ea716eb11df85a8d02932106dadb038d2cc93926", "best_bid": "0.94", "best_ask": "0.96"}, {"asset_id": "48577451271083670981595797636824300354923632195069165655560061059665286147100", "price": "0.71", "size": "139.65", "side": "SELL", "hash": "6be0b982ad98cfc437c513ee0c1edf3c37580944", "best_bid": "0.04", "best_ask": "0.06"}], "timestamp": "1769384431631", "event_type": "price_change"}}
{"_local_timestamp": "2026-01-25T23:40:31.962119+00:00", "data": {"market": "0xb4c6f7991dc5d1e110abb1404c629deb7bbc4b07ff19bb4672ff41801824490e", "price_changes": [{"asset_id": "12726823989557107952268342942906206381973799399453895205022550590946554841098", "price": "0.3", "size": "1450", "side": "BUY", "hash": "39644450280704f24198f5924d1d68411dabfd01", "best_bid": "0.94", "best_ask": "0.96"}, {"asset_id": "48577451271083670981595797636824300354923632195069165655560061059665286147100", "price": "0.7", "size": "1450", "side": "SELL", "hash": "fe393eda8857e2d6bdd7940106110494b501a1a1", "best_bid": "0.04", "best_ask": "0.06"}], "timestamp": "1769384431890", "event_type": "price_change"}}
{"_local_timestamp": "2026-01-25T23:40:42.079154+00:00", "data": {"market": "0xb4c6f7991dc5d1e110abb1404c629deb7bbc4b07ff19bb4672ff41801824490e", "price_changes": [{"asset_id": "48577451271083670981595797636824300354923632195069165655560061059665286147100", "price": "0.02", "size": "25593.62", "side": "BUY", "hash": "c225b7873524ae2341b4d697872eaf887d9b0aaf", "best_bid": "0.04", "best_ask": "0.06"}, {"asset_id": "12726823989557107952268342942906206381973799399453895205022550590946554841098", "price": "0.98", "size": "25593.62", "side": "SELL", "hash": "b7850acc7b85f06dc48d9bae6384cc34a409a47f", "best_bid": "0.94", "best_ask": "0.96"}], "timestamp": "1769384442001", "event_type": "price_change"}}
{"_local_timestamp": "2026-01-25T23:40:42.081519+00:00", "data": {"market": "0xb4c6f7991dc5d1e110abb1404c629deb7bbc4b07ff19bb4672ff41801824490e", "price_changes": [{"asset_id": "48577451271083670981595797636824300354923632195069165655560061059665286147100", "price": "0.01", "size": "510", "side": "BUY", "hash": "4f0cde22056ad3483abca1a83a0777c24c4b9427", "best_bid": "0.04", "best_ask": "0.06"}, {"asset_id": "12726823989557107952268342942906206381973799399453895205022550590946554841098", "price": "0.99", "size": "510", "side": "SELL", "hash": "0c16631b90084e7bbdb55bacc73418eec268582c", "best_bid": "0.94", "best_ask": "0.96"}], "timestamp": "1769384442002", "event_type": "price_change"}}
{"_local_timestamp": "2026-01-25T23:41:14.654926+00:00", "data": {"market": "0xb4c6f7991dc5d1e110abb1404c629deb7bbc4b07ff19bb4672ff41801824490e", "price_changes": [{"asset_id": "12726823989557107952268342942906206381973799399453895205022550590946554841098", "price": "0.3", "size": "50", "side": "BUY", "hash": "037210ea4818256dbf064902cd3401e900137a79", "best_bid": "0.94", "best_ask": "0.96"}, {"asset_id": "48577451271083670981595797636824300354923632195069165655560061059665286147100", "price": "0.7", "size": "50", "side": "SELL", "hash": "fdb804d0f9e0c278899aebe10e022b68df8419f6", "best_bid": "0.04", "best_ask": "0.06"}], "timestamp": "1769384474530", "event_type": "price_change"}}
{"_local_timestamp": "2026-01-25T23:41:43.046778+00:00", "data": {"market": "0xb4c6f7991dc5d1e110abb1404c629deb7bbc4b07ff19bb4672ff41801824490e", "price_changes": [{"asset_id": "12726823989557107952268342942906206381973799399453895205022550590946554841098", "price": "0.26", "size": "1614", "side": "BUY", "hash": "847731020637e3aeb3892101b69a881078ce9f4a", "best_bid": "0.94", "best_ask": "0.96"}, {"asset_id": "48577451271083670981595797636824300354923632195069165655560061059665286147100", "price": "0.74", "size": "1614", "side": "SELL", "hash": "d0f1552f382ae72bf020bfcddbc1e0154bc22042", "best_bid": "0.04", "best_ask": "0.06"}], "timestamp": "1769384502973", "event_type": "price_change"}}
{"_local_timestamp": "2026-01-25T23:41:49.476996+00:00", "data": {"market": "0xb4c6f7991dc5d1e110abb1404c629deb7bbc4b07ff19bb4672ff41801824490e", "price_changes": [{"asset_id": "12726823989557107952268342942906206381973799399453895205022550590946554841098", "price": "0.3", "size": "0", "side": "BUY", "hash": "ad775856a8003275f8f556a01896f5a34e975aed", "best_bid": "0.94", "best_ask": "0.96"}, {"asset_id": "48577451271083670981595797636824300354923632195069165655560061059665286147100", "price": "0.7", "size": "0", "side": "SELL", "hash": "493277596fa5da9dba37c71cd8bbd26f28b71596", "best_bid": "0.04", "best_ask": "0.06"}], "timestamp": "1769384509399", "event_type": "price_change"}}
{"_local_timestamp": "2026-01-25T23:41:49.746917+00:00", "data": {"market": "0xb4c6f7991dc5d1e110abb1404c629deb7bbc4b07ff19bb4672ff41801824490e", "price_changes": [{"asset_id": "12726823989557107952268342942906206381973799399453895205022550590946554841098", "price": "0.29", "size": "189.65", "side": "BUY", "hash": "60928045d8194c9ff2a973d6d063ccd5d4787dec", "best_bid": "0.94", "best_ask": "0.96"}, {"asset_id": "48577451271083670981595797636824300354923632195069165655560061059665286147100", "price": "0.71", "size": "189.65", "side": "SELL", "hash": "b9f54eeb13dd7bb5a059b0d377b1e6bc6fa4bc85", "best_bid": "0.04", "best_ask": "0.06"}], "timestamp": "1769384509659", "event_type": "price_change"}}
{"_local_timestamp": "2026-01-25T23:41:50.951864+00:00", "data": {"market": "0xb4c6f7991dc5d1e110abb1404c629deb7bbc4b07ff19bb4672ff41801824490e", "price_changes": [{"asset_id": "12726823989557107952268342942906206381973799399453895205022550590946554841098", "price": "0.25", "size": "50", "side": "BUY", "hash": "72230e2dbf1d2677419a9ca967f62e0e4a3fa53a", "best_bid": "0.94", "best_ask": "0.96"}, {"asset_id": "48577451271083670981595797636824300354923632195069165655560061059665286147100", "price": "0.75", "size": "50", "side": "SELL", "hash": "8324213a6e413fd18b3bc5a7eb209bbcd72b7f8e", "best_bid": "0.04", "best_ask": "0.06"}], "timestamp": "1769384510769", "event_type": "price_change"}}
{"_local_timestamp": "2026-01-25T23:41:52.832245+00:00", "data": {"market": "0xb4c6f7991dc5d1e110abb1404c629deb7bbc4b07ff19bb4672ff41801824490e", "price_changes": [{"asset_id": "12726823989557107952268342942906206381973799399453895205022550590946554841098", "price": "0.23", "size": "894", "side": "BUY", "hash": "9d60ba9e008af23412f89a4a810c63dd509ac7ac", "best_bid": "0.94", "best_ask": "0.96"}, {"asset_id": "48577451271083670981595797636824300354923632195069165655560061059665286147100", "price": "0.77", "size": "894", "side": "SELL", "hash": "a88237660f7a33eeba516d6f4066378f52a89ca7", "best_bid": "0.04", "best_ask": "0.06"}], "timestamp": "1769384511811", "event_type": "price_change"}}
{"_local_timestamp": "2026-01-25T23:42:25.074884+00:00", "data": {"market": "0xb4c6f7991dc5d1e110abb1404c629deb7bbc4b07ff19bb4672ff41801824490e", "price_changes": [{"asset_id": "12726823989557107952268342942906206381973799399453895205022550590946554841098", "price": "0.29", "size": "139.65", "side": "BUY", "hash": "1c7a107449e30ef4a1215a3427eb004c9caf292b", "best_bid": "0.94", "best_ask": "0.96"}, {"asset_id": "48577451271083670981595797636824300354923632195069165655560061059665286147100", "price": "0.71", "size": "139.65", "side": "SELL", "hash": "11cd784fae8474e7b9bf3f6f4bd30f3cd21487a6", "best_bid": "0.04", "best_ask": "0.06"}], "timestamp": "1769384544872", "event_type": "price_change"}}
{"_local_timestamp": "2026-01-25T23:42:25.352777+00:00", "data": {"market": "0xb4c6f7991dc5d1e110abb1404c629deb7bbc4b07ff19bb4672ff41801824490e", "price_changes": [{"asset_id": "12726823989557107952268342942906206381973799399453895205022550590946554841098", "price": "0.26", "size": "1664", "side": "BUY", "hash": "5ec042c69dc91a1b296682642e342c077d989926", "best_bid": "0.94", "best_ask": "0.96"}, {"asset_id": "48577451271083670981595797636824300354923632195069165655560061059665286147100", "price": "0.74", "size": "1664", "side": "SELL", "hash": "5905301797c51bf872569a53ed8031937b48304e", "best_bid": "0.04", "best_ask": "0.06"}], "timestamp": "1769384545150", "event_type": "price_change"}}
{"_local_timestamp": "2026-01-25T23:42:29.517787+00:00", "data": {"market": "0xb4c6f7991dc5d1e110abb1404c629deb7bbc4b07ff19bb4672ff41801824490e", "price_changes": [{"asset_id": "48577451271083670981595797636824300354923632195069165655560061059665286147100", "price": "0.01", "size": "2510", "side": "BUY", "hash": "3a402344ed4e2054659669cf308db608826c0c67", "best_bid": "0.04", "best_ask": "0.06"}, {"asset_id": "12726823989557107952268342942906206381973799399453895205022550590946554841098", "price": "0.99", "size": "2510", "side": "SELL", "hash": "30518a76ee12e5e5e9e3aad7d26e286beb11f97f", "best_bid": "0.94", "best_ask": "0.96"}], "timestamp": "1769384549349", "event_type": "price_change"}}
{"_local_timestamp": "2026-01-25T23:42:29.518455+00:00", "data": {"market": "0xb4c6f7991dc5d1e110abb1404c629deb7bbc4b07ff19bb4672ff41801824490e", "price_changes": [{"asset_id": "48577451271083670981595797636824300354923632195069165655560061059665286147100", "price": "0.02", "size": "25843.62", "side": "BUY", "hash": "ac1fde1b799e6f68559712b8a6a4afef4c5b4070", "best_bid": "0.04", "best_ask": "0.06"}, {"asset_id": "12726823989557107952268342942906206381973799399453895205022550590946554841098", "price": "0.98", "size": "25843.62", "side": "SELL", "hash": "496423f79be4e461921ee38abd9834550419d791", "best_bid": "0.94", "best_ask": "0.96"}], "timestamp": "1769384549349", "event_type": "price_change"}}
{"_local_timestamp": "2026-01-25T23:42:44.707477+00:00", "data": {"market": "0xb4c6f7991dc5d1e110abb1404c629deb7bbc4b07ff19bb4672ff41801824490e", "price_changes": [{"asset_id": "12726823989557107952268342942906206381973799399453895205022550590946554841098", "price": "0.35", "size": "1764", "side": "BUY", "hash": "3fbe0a9820ab499b71869da78325b42a43dcdee2", "best_bid": "0.94", "best_ask": "0.96"}, {"asset_id": "48577451271083670981595797636824300354923632195069165655560061059665286147100", "price": "0.65", "size": "1764", "side": "SELL", "hash": "33c26cbbb47c6dff5841078d6af57c13b4bf75e7", "best_bid": "0.04", "best_ask": "0.06"}], "timestamp": "1769384564589", "event_type": "price_change"}}
{"_local_timestamp": "2026-01-25T23:42:44.708059+00:00", "data": {"market": "0xb4c6f7991dc5d1e110abb1404c629deb7bbc4b07ff19bb4672ff41801824490e", "price_changes": [{"asset_id": "12726823989557107952268342942906206381973799399453895205022550590946554841098", "price": "0.29", "size": "89.65", "side": "BUY", "hash": "3fbe0a9820ab499b71869da78325b42a43dcdee2", "best_bid": "0.94", "best_ask": "0.96"}, {"asset_id": "48577451271083670981595797636824300354923632195069165655560061059665286147100", "price": "0.71", "size": "89.65", "side": "SELL", "hash": "33c26cbbb47c6dff5841078d6af57c13b4bf75e7", "best_bid": "0.04", "best_ask": "0.06"}], "timestamp": "1769384564589", "event_type": "price_change"}}
{"_local_timestamp": "2026-01-25T23:42:44.708440+00:00", "data": {"market": "0xb4c6f7991dc5d1e110abb1404c629deb7bbc4b07ff19bb4672ff41801824490e", "price_changes": [{"asset_id": "12726823989557107952268342942906206381973799399453895205022550590946554841098", "price": "0.25", "size": "0", "side": "BUY", "hash": "3fbe0a9820ab499b71869da78325b42a43dcdee2", "best_bid": "0.94", "best_ask": "0.96"}, {"asset_id": "48577451271083670981595797636824300354923632195069165655560061059665286147100", "price": "0.75", "size": "0", "side": "SELL", "hash": "33c26cbbb47c6dff5841078d6af57c13b4bf75e7", "best_bid": "0.04", "best_ask": "0.06"}], "timestamp": "1769384564589", "event_type": "price_change"}}
{"_local_timestamp": "2026-01-25T23:42:45.775948+00:00", "data": {"market": "0xb4c6f7991dc5d1e110abb1404c629deb7bbc4b07ff19bb4672ff41801824490e", "price_changes": [{"asset_id": "12726823989557107952268342942906206381973799399453895205022550590946554841098", "price": "0.3", "size": "50", "side": "BUY", "hash": "0eff7241e19f5842b5cfb2bc68ec0b77fe2011ce", "best_bid": "0.94", "best_ask": "0.96"}, {"asset_id": "48577451271083670981595797636824300354923632195069165655560061059665286147100", "price": "0.7", "size": "50", "side": "SELL", "hash": "3beee98487424a91dc3e8e4d5e1b0374866eb4ef", "best_bid": "0.04", "best_ask": "0.06"}], "timestamp": "1769384565608", "event_type": "price_change"}}
{"_local_timestamp": "2026-01-25T23:42:45.805223+00:00", "data": {"market": "0xb4c6f7991dc5d1e110abb1404c629deb7bbc4b07ff19bb4672ff41801824490e", "price_changes": [{"asset_id": "12726823989557107952268342942906206381973799399453895205022550590946554841098", "price": "0.36", "size": "4595", "side": "BUY", "hash": "547a9873d6c704b2929e8e378308cbc7780c0782", "best_bid": "0.94", "best_ask": "0.96"}, {"asset_id": "48577451271083670981595797636824300354923632195069165655560061059665286147100", "price": "0.64", "size": "4595", "side": "SELL", "hash": "87a2d757d965ffc8dd951c77d456d0741b80c15a", "best_bid": "0.04", "best_ask": "0.06"}], "timestamp": "1769384565630", "event_type": "price_change"}}
{"_local_timestamp": "2026-01-25T23:42:45.808326+00:00", "data": {"market": "0xb4c6f7991dc5d1e110abb1404c629deb7bbc4b07ff19bb4672ff41801824490e", "price_changes": [{"asset_id": "12726823989557107952268342942906206381973799399453895205022550590946554841098", "price": "0.23", "size": "944", "side": "BUY", "hash": "780e39a0d3e57037fb90b294e28bf4b087456451", "best_bid": "0.94", "best_ask": "0.96"}, {"asset_id": "48577451271083670981595797636824300354923632195069165655560061059665286147100", "price": "0.77", "size": "944", "side": "SELL", "hash": "53d9060389008726d9ee490e031350453943fcc5", "best_bid": "0.04", "best_ask": "0.06"}], "timestamp": "1769384565636", "event_type": "price_change"}}
{"_local_timestamp": "2026-01-25T23:42:47.163705+00:00", "data": {"market": "0xb4c6f7991dc5d1e110abb1404c629deb7bbc4b07ff19bb4672ff41801824490e", "price_changes": [{"asset_id": "12726823989557107952268342942906206381973799399453895205022550590946554841098", "price": "0.26", "size": "50", "side": "BUY", "hash": "0d5d60454a7e7c57fe20ea2604f456a74528d968", "best_bid": "0.94", "best_ask": "0.96"}, {"asset_id": "48577451271083670981595797636824300354923632195069165655560061059665286147100", "price": "0.74", "size": "50", "side": "SELL", "hash": "90e0be7d23448cae5dd95e8c568fc4efc8c33236", "best_bid": "0.04", "best_ask": "0.06"}], "timestamp": "1769384566990", "event_type": "price_change"}}
{"_local_timestamp": "2026-01-25T23:42:52.163820+00:00", "data": {"market": "0xb4c6f7991dc5d1e110abb1404c629deb7bbc4b07ff19bb4672ff41801824490e", "price_changes": [{"asset_id": "48577451271083670981595797636824300354923632195069165655560061059665286147100", "price": "0.02", "size": "25818", "side": "BUY", "hash": "d1d01f22191423ce93123872389d63ef21405ff6", "best_bid": "0.04", "best_ask": "0.06"}, {"asset_id": "12726823989557107952268342942906206381973799399453895205022550590946554841098", "price": "0.98", "size": "25818", "side": "SELL", "hash": "8e80934a191979b0248dd6d40b8aadc8440509c3", "best_bid": "0.94", "best_ask": "0.96"}], "timestamp": "1769384572028", "event_type": "price_change"}}
{"_local_timestamp": "2026-01-25T23:42:52.164378+00:00", "data": {"market": "0xb4c6f7991dc5d1e110abb1404c629deb7bbc4b07ff19bb4672ff41801824490e", "price_changes": [{"asset_id": "48577451271083670981595797636824300354923632195069165655560061059665286147100", "price": "0.03", "size": "24012.14", "side": "BUY", "hash": "d1d01f22191423ce93123872389d63ef21405ff6", "best_bid": "0.04", "best_ask": "0.06"}, {"asset_id": "12726823989557107952268342942906206381973799399453895205022550590946554841098", "price": "0.97", "size": "24012.14", "side": "SELL", "hash": "8e80934a191979b0248dd6d40b8aadc8440509c3", "best_bid": "0.94", "best_ask": "0.96"}], "timestamp": "1769384572028", "event_type": "price_change"}}
{"_local_timestamp": "2026-01-25T23:42:52.531740+00:00", "data": {"market": "0xb4c6f7991dc5d1e110abb1404c629deb7bbc4b07ff19bb4672ff41801824490e", "price_changes": [{"asset_id": "48577451271083670981595797636824300354923632195069165655560061059665286147100", "price": "0.02", "size": "25843.62", "side": "BUY", "hash": "33c7b093ee135db389721a870d7e5a2322dcd42f", "best_bid": "0.04", "best_ask": "0.06"}, {"asset_id": "12726823989557107952268342942906206381973799399453895205022550590946554841098", "price": "0.98", "size": "25843.62", "side": "SELL", "hash": "a4ccb694baf03f422ef051df685e2d49b6433bcd", "best_bid": "0.94", "best_ask": "0.96"}], "timestamp": "1769384572426", "event_type": "price_change"}}
{"_local_timestamp": "2026-01-25T23:42:52.532262+00:00", "data": {"market": "0xb4c6f7991dc5d1e110abb1404c629deb7bbc4b07ff19bb4672ff41801824490e", "price_changes": [{"asset_id": "48577451271083670981595797636824300354923632195069165655560061059665286147100", "price": "0.03", "size": "24028.39", "side": "BUY", "hash": "d57aef749e0ffc40216e028b2c13a010017379b4", "best_bid": "0.04", "best_ask": "0.06"}, {"asset_id": "12726823989557107952268342942906206381973799399453895205022550590946554841098", "price": "0.97", "size": "24028.39", "side": "SELL", "hash": "c9d968cf659f1ac54a58f29112c3366e7ffc8f62", "best_bid": "0.94", "best_ask": "0.96"}], "timestamp": "1769384572428", "event_type": "price_change"}}
{"_local_timestamp": "2026-01-25T23:43:38.532244+00:00", "data": {"market": "0xb4c6f7991dc5d1e110abb1404c629deb7bbc4b07ff19bb4672ff41801824490e", "price_changes": [{"asset_id": "12726823989557107952268342942906206381973799399453895205022550590946554841098", "price": "0.26", "size": "0", "side": "BUY", "hash": "96081ff8c2a3dde3940ae0704ec9ae03538ac19b", "best_bid": "0.94", "best_ask": "0.96"}, {"asset_id": "48577451271083670981595797636824300354923632195069165655560061059665286147100", "price": "0.74", "size": "0", "side": "SELL", "hash": "a477d8106b399fbe63e23d16429479af4da6c35e", "best_bid": "0.04", "best_ask": "0.06"}], "timestamp": "1769384618453", "event_type": "price_change"}}
{"_local_timestamp": "2026-01-25T23:43:38.824938+00:00", "data": {"market": "0xb4c6f7991dc5d1e110abb1404c629deb7bbc4b07ff19bb4672ff41801824490e", "price_changes": [{"asset_id": "12726823989557107952268342942906206381973799399453895205022550590946554841098", "price": "0.29", "size": "139.65", "side": "BUY", "hash": "e6a040f024a247c86566355ccc0d3449b78d748e", "best_bid": "0.94", "best_ask": "0.96"}, {"asset_id": "48577451271083670981595797636824300354923632195069165655560061059665286147100", "price": "0.71", "size": "139.65", "side": "SELL", "hash": "52156df4d74b63f895a60ab1e8cbc9ba00094f86", "best_bid": "0.04", "best_ask": "0.06"}], "timestamp": "1769384618722", "event_type": "price_change"}}
{"_local_timestamp": "2026-01-25T23:44:02.866091+00:00", "data": {"market": "0xb4c6f7991dc5d1e110abb1404c629deb7bbc4b07ff19bb4672ff41801824490e", "price_changes": [{"asset_id": "12726823989557107952268342942906206381973799399453895205022550590946554841098", "price": "0.3", "size": "1450", "side": "BUY", "hash": "9bb90bb754e207848072e4836cd53d4797ddcc6f", "best_bid": "0.94", "best_ask": "0.96"}, {"asset_id": "48577451271083670981595797636824300354923632195069165655560061059665286147100", "price": "0.7", "size": "1450", "side": "SELL", "hash": "9674800727d7287ce0ffc14bc7e54c8b7acf4767", "best_bid": "0.04", "best_ask": "0.06"}], "timestamp": "1769384642596", "event_type": "price_change"}}
{"_local_timestamp": "2026-01-25T23:44:20.934723+00:00", "data": {"market": "0xb4c6f7991dc5d1e110abb1404c629deb7bbc4b07ff19bb4672ff41801824490e", "price_changes": [{"asset_id": "12726823989557107952268342942906206381973799399453895205022550590946554841098", "price": "0.48", "size": "0", "side": "BUY", "hash": "756ca0260d39556485331fcc7c7ca67d3c4306a1", "best_bid": "0.94", "best_ask": "0.96"}, {"asset_id": "48577451271083670981595797636824300354923632195069165655560061059665286147100", "price": "0.52", "size": "0", "side": "SELL", "hash": "98e1e3ee67cdfcb1038c09f0692e41ea735a507a", "best_bid": "0.04", "best_ask": "0.06"}], "timestamp": "1769384660495", "event_type": "price_change"}}
{"_local_timestamp": "2026-01-25T23:44:21.033773+00:00", "data": {"market": "0xb4c6f7991dc5d1e110abb1404c629deb7bbc4b07ff19bb4672ff41801824490e", "price_changes": [{"asset_id": "12726823989557107952268342942906206381973799399453895205022550590946554841098", "price": "0.23", "size": "844", "side": "BUY", "hash": "756ca0260d39556485331fcc7c7ca67d3c4306a1", "best_bid": "0.94", "best_ask": "0.96"}, {"asset_id": "48577451271083670981595797636824300354923632195069165655560061059665286147100", "price": "0.77", "size": "844", "side": "SELL", "hash": "98e1e3ee67cdfcb1038c09f0692e41ea735a507a", "best_bid": "0.04", "best_ask": "0.06"}], "timestamp": "1769384660495", "event_type": "price_change"}}
{"_local_timestamp": "2026-01-25T23:44:21.493188+00:00", "data": {"market": "0xb4c6f7991dc5d1e110abb1404c629deb7bbc4b07ff19bb4672ff41801824490e", "price_changes": [{"asset_id": "12726823989557107952268342942906206381973799399453895205022550590946554841098", "price": "0.26", "size": "100", "side": "BUY", "hash": "6271dd4b52fad414174d5855ab0cb2d0071a9b50", "best_bid": "0.94", "best_ask": "0.96"}, {"asset_id": "48577451271083670981595797636824300354923632195069165655560061059665286147100", "price": "0.74", "size": "100", "side": "SELL", "hash": "35ca932ba7ccd846cc657744e56254bfee1a4a3e", "best_bid": "0.04", "best_ask": "0.06"}], "timestamp": "1769384660899", "event_type": "price_change"}}
{"_local_timestamp": "2026-01-25T23:44:32.456149+00:00", "data": {"market": "0xb4c6f7991dc5d1e110abb1404c629deb7bbc4b07ff19bb4672ff41801824490e", "price_changes": [{"asset_id": "12726823989557107952268342942906206381973799399453895205022550590946554841098", "price": "0.3", "size": "50", "side": "BUY", "hash": "6d5cfdabb00207fe510c5c087fcdb1bca9ce8434", "best_bid": "0.94", "best_ask": "0.96"}, {"asset_id": "48577451271083670981595797636824300354923632195069165655560061059665286147100", "price": "0.7", "size": "50", "side": "SELL", "hash": "fbe109791023e2280abf293060b9ea204e301457", "best_bid": "0.04", "best_ask": "0.06"}], "timestamp": "1769384672296", "event_type": "price_change"}}
{"_local_timestamp": "2026-01-25T23:44:55.447744+00:00", "data": {"market": "0xb4c6f7991dc5d1e110abb1404c629deb7bbc4b07ff19bb4672ff41801824490e", "price_changes": [{"asset_id": "12726823989557107952268342942906206381973799399453895205022550590946554841098", "price": "0.24", "size": "1864.66", "side": "BUY", "hash": "57e170bdf4f58485a1ec62eb8109f780491bbc5b", "best_bid": "0.94", "best_ask": "0.96"}, {"asset_id": "48577451271083670981595797636824300354923632195069165655560061059665286147100", "price": "0.76", "size": "1864.66", "side": "SELL", "hash": "b26da1205bf02153d54b4dc0aaa5a17a3e9fa506", "best_bid": "0.04", "best_ask": "0.06"}], "timestamp": "1769384695384", "event_type": "price_change"}}
{"_local_timestamp": "2026-01-25T23:44:57.521255+00:00", "data": {"market": "0xb4c6f7991dc5d1e110abb1404c629deb7bbc4b07ff19bb4672ff41801824490e", "price_changes": [{"asset_id": "12726823989557107952268342942906206381973799399453895205022550590946554841098", "price": "0.29", "size": "89.65", "side": "BUY", "hash": "bc732fe21ff4f73dcd5aa0f499d1787cd200129f", "best_bid": "0.94", "best_ask": "0.96"}, {"asset_id": "48577451271083670981595797636824300354923632195069165655560061059665286147100", "price": "0.71", "size": "89.65", "side": "SELL", "hash": "8d645ab5b2275e53f5f4615b64edd8dc860a6eb9", "best_bid": "0.04", "best_ask": "0.06"}], "timestamp": "1769384697451", "event_type": "price_change"}}
{"_local_timestamp": "2026-01-25T23:44:57.688457+00:00", "data": {"market": "0xb4c6f7991dc5d1e110abb1404c629deb7bbc4b07ff19bb4672ff41801824490e", "price_changes": [{"asset_id": "12726823989557107952268342942906206381973799399453895205022550590946554841098", "price": "0.3", "size": "0", "side": "BUY", "hash": "0a5ee25c3f15dbeb11112c632b944f8cdc524a67", "best_bid": "0.94", "best_ask": "0.96"}, {"asset_id": "48577451271083670981595797636824300354923632195069165655560061059665286147100", "price": "0.7", "size": "0", "side": "SELL", "hash": "cbc7dab7a1af74d26e195f452f4709d46f326575", "best_bid": "0.04", "best_ask": "0.06"}], "timestamp": "1769384697618", "event_type": "price_change"}}
{"_local_timestamp": "2026-01-25T23:44:57.799873+00:00", "data": {"market": "0xb4c6f7991dc5d1e110abb1404c629deb7bbc4b07ff19bb4672ff41801824490e", "price_changes": [{"asset_id": "12726823989557107952268342942906206381973799399453895205022550590946554841098", "price": "0.3", "size": "50", "side": "BUY", "hash": "deac4a4e2534bcee7cc943e9e2689851c402ec7c", "best_bid": "0.94", "best_ask": "0.96"}, {"asset_id": "48577451271083670981595797636824300354923632195069165655560061059665286147100", "price": "0.7", "size": "50", "side": "SELL", "hash": "22f9a5af9de02d9428659b0577f8a83b45e76dca", "best_bid": "0.04", "best_ask": "0.06"}], "timestamp": "1769384697724", "event_type": "price_change"}}
{"_local_timestamp": "2026-01-25T23:44:58.339350+00:00", "data": {"market": "0xb4c6f7991dc5d1e110abb1404c629deb7bbc4b07ff19bb4672ff41801824490e", "price_changes": [{"asset_id": "12726823989557107952268342942906206381973799399453895205022550590946554841098", "price": "0.27", "size": "50", "side": "BUY", "hash": "77d7af1fb306b913be014a120578c006808a926a", "best_bid": "0.94", "best_ask": "0.96"}, {"asset_id": "48577451271083670981595797636824300354923632195069165655560061059665286147100", "price": "0.73", "size": "50", "side": "SELL", "hash": "7dcb6940e010d68c9fba5cea3814065139cc8d0a", "best_bid": "0.04", "best_ask": "0.06"}], "timestamp": "1769384698221", "event_type": "price_change"}}
{"_local_timestamp": "2026-01-25T23:45:38.879005+00:00", "data": {"market": "0xb4c6f7991dc5d1e110abb1404c629deb7bbc4b07ff19bb4672ff41801824490e", "price_changes": [{"asset_id": "12726823989557107952268342942906206381973799399453895205022550590946554841098", "price": "0.23", "size": "744", "side": "BUY", "hash": "c67e7462b299c02a334115a571aea3973186150e", "best_bid": "0.94", "best_ask": "0.96"}, {"asset_id": "48577451271083670981595797636824300354923632195069165655560061059665286147100", "price": "0.77", "size": "744", "side": "SELL", "hash": "cc1079c3acf71889d91e9da320bbe56bfc7c8214", "best_bid": "0.04", "best_ask": "0.06"}], "timestamp": "1769384738807", "event_type": "price_change"}}
{"_local_timestamp": "2026-01-25T23:45:38.879903+00:00", "data": {"market": "0xb4c6f7991dc5d1e110abb1404c629deb7bbc4b07ff19bb4672ff41801824490e", "price_changes": [{"asset_id": "12726823989557107952268342942906206381973799399453895205022550590946554841098", "price": "0.3", "size": "0", "side": "BUY", "hash": "c67e7462b299c02a334115a571aea3973186150e", "best_bid": "0.94", "best_ask": "0.96"}, {"asset_id": "48577451271083670981595797636824300354923632195069165655560061059665286147100", "price": "0.7", "size": "0", "side": "SELL", "hash": "cc1079c3acf71889d91e9da320bbe56bfc7c8214", "best_bid": "0.04", "best_ask": "0.06"}], "timestamp": "1769384738807", "event_type": "price_change"}}
{"_local_timestamp": "2026-01-25T23:45:39.189900+00:00", "data": {"market": "0xb4c6f7991dc5d1e110abb1404c629deb7bbc4b07ff19bb4672ff41801824490e", "price_changes": [{"asset_id": "12726823989557107952268342942906206381973799399453895205022550590946554841098", "price": "0.24", "size": "1964.66", "side": "BUY", "hash": "237b5034aaefa8e992e235c8bb895bebae52fe26", "best_bid": "0.94", "best_ask": "0.96"}, {"asset_id": "48577451271083670981595797636824300354923632195069165655560061059665286147100", "price": "0.76", "size": "1964.66", "side": "SELL", "hash": "9f65bba39619061ab09f76c7ceba2071f36eacf8", "best_bid": "0.04", "best_ask": "0.06"}], "timestamp": "1769384739084", "event_type": "price_change"}}
{"_local_timestamp": "2026-01-25T23:45:39.225705+00:00", "data": {"market": "0xb4c6f7991dc5d1e110abb1404c629deb7bbc4b07ff19bb4672ff41801824490e", "price_changes": [{"asset_id": "12726823989557107952268342942906206381973799399453895205022550590946554841098", "price": "0.26", "size": "150", "side": "BUY", "hash": "b77b5ae0b599d3c08fb324ad4a6fd8e190663a89", "best_bid": "0.94", "best_ask": "0.96"}, {"asset_id": "48577451271083670981595797636824300354923632195069165655560061059665286147100", "price": "0.74", "size": "150", "side": "SELL", "hash": "c10d836242ca0ae1090c70d566bc88a3c4726f10", "best_bid": "0.04", "best_ask": "0.06"}], "timestamp": "1769384739091", "event_type": "price_change"}}
{"_local_timestamp": "2026-01-25T23:45:48.425988+00:00", "data": {"market": "0xb4c6f7991dc5d1e110abb1404c629deb7bbc4b07ff19bb4672ff41801824490e", "price_changes": [{"asset_id": "12726823989557107952268342942906206381973799399453895205022550590946554841098", "price": "0.92", "size": "1257.13", "side": "BUY", "hash": "9c6760815f5ef6e146fbcf5f5335cbc937a70819", "best_bid": "0.94", "best_ask": "0.96"}, {"asset_id": "48577451271083670981595797636824300354923632195069165655560061059665286147100", "price": "0.08", "size": "1257.13", "side": "SELL", "hash": "4a7e387cd7ab41820a788cd86e7438407b8d96d2", "best_bid": "0.04", "best_ask": "0.06"}], "timestamp": "1769384748352", "event_type": "price_change"}}
{"_local_timestamp": "2026-01-25T23:45:48.458150+00:00", "data": {"market": "0xb4c6f7991dc5d1e110abb1404c629deb7bbc4b07ff19bb4672ff41801824490e", "price_changes": [{"asset_id": "48577451271083670981595797636824300354923632195069165655560061059665286147100", "price": "0.02", "size": "25793.62", "side": "BUY", "hash": "592360aac3cdeed3f7470dd3abd50131335ef133", "best_bid": "0.04", "best_ask": "0.06"}, {"asset_id": "12726823989557107952268342942906206381973799399453895205022550590946554841098", "price": "0.98", "size": "25793.62", "side": "SELL", "hash": "c30e115f5b001a1bffa683cc41a4e5443d33e5c0", "best_bid": "0.94", "best_ask": "0.96"}], "timestamp": "1769384748353", "event_type": "price_change"}}
{"_local_timestamp": "2026-01-25T23:45:49.697266+00:00", "data": {"market": "0xb4c6f7991dc5d1e110abb1404c629deb7bbc4b07ff19bb4672ff41801824490e", "price_changes": [{"asset_id": "48577451271083670981595797636824300354923632195069165655560061059665286147100", "price": "0.03", "size": "23506.39", "side": "BUY", "hash": "fa5b12dba5ec3197a0200f90c2c6cfb76f96cdcc", "best_bid": "0.04", "best_ask": "0.06"}, {"asset_id": "12726823989557107952268342942906206381973799399453895205022550590946554841098", "price": "0.97", "size": "23506.39", "side": "SELL", "hash": "031143beb162c99c42214a38d302547c6f877cc0", "best_bid": "0.94", "best_ask": "0.96"}], "timestamp": "1769384749633", "event_type": "price_change"}}
{"_local_timestamp": "2026-01-25T23:45:49.958861+00:00", "data": {"market": "0xb4c6f7991dc5d1e110abb1404c629deb7bbc4b07ff19bb4672ff41801824490e", "price_changes": [{"asset_id": "48577451271083670981595797636824300354923632195069165655560061059665286147100", "price": "0.03", "size": "24008.39", "side": "BUY", "hash": "10bd38222e01afe3c9d8372742ffbca2ad7d3548", "best_bid": "0.04", "best_ask": "0.06"}, {"asset_id": "12726823989557107952268342942906206381973799399453895205022550590946554841098", "price": "0.97", "size": "24008.39", "side": "SELL", "hash": "e88f0769011f1cea26e68fba0b432f590ee1705f", "best_bid": "0.94", "best_ask": "0.96"}], "timestamp": "1769384749894", "event_type": "price_change"}}
{"_local_timestamp": "2026-01-25T23:45:50.448424+00:00", "data": {"market": "0xb4c6f7991dc5d1e110abb1404c629deb7bbc4b07ff19bb4672ff41801824490e", "price_changes": [{"asset_id": "12726823989557107952268342942906206381973799399453895205022550590946554841098", "price": "0.93", "size": "1184.99", "side": "BUY", "hash": "ad3171bc0583fae09ad646da6c33c12117d16540", "best_bid": "0.94", "best_ask": "0.96"}, {"asset_id": "48577451271083670981595797636824300354923632195069165655560061059665286147100", "price": "0.07", "size": "1184.99", "side": "SELL", "hash": "8c042157af81a95419eb49758993b1c7ec56c7a2", "best_bid": "0.04", "best_ask": "0.06"}], "timestamp": "1769384750382", "event_type": "price_change"}}
{"_local_timestamp": "2026-01-25T23:45:50.721132+00:00", "data": {"market": "0xb4c6f7991dc5d1e110abb1404c629deb7bbc4b07ff19bb4672ff41801824490e", "price_changes": [{"asset_id": "12726823989557107952268342942906206381973799399453895205022550590946554841098", "price": "0.93", "size": "1686.99", "side": "BUY", "hash": "b2fac0bd01fe59c23aeb48c7638badb3a36eae8a", "best_bid": "0.94", "best_ask": "0.96"}, {"asset_id": "48577451271083670981595797636824300354923632195069165655560061059665286147100", "price": "0.07", "size": "1686.99", "side": "SELL", "hash": "484bf970bf459267eee2f126dd8cef37452371bb", "best_bid": "0.04", "best_ask": "0.06"}], "timestamp": "1769384750655", "event_type": "price_change"}}
{"_local_timestamp": "2026-01-25T23:45:56.223027+00:00", "data": {"market": "0xb4c6f7991dc5d1e110abb1404c629deb7bbc4b07ff19bb4672ff41801824490e", "price_changes": [{"asset_id": "12726823989557107952268342942906206381973799399453895205022550590946554841098", "price": "0.03", "size": "0", "side": "BUY", "hash": "1943ac4132e033129192cbdf289ef4ca74f2187d", "best_bid": "0.94", "best_ask": "0.96"}, {"asset_id": "48577451271083670981595797636824300354923632195069165655560061059665286147100", "price": "0.97", "size": "0", "side": "SELL", "hash": "d39b8f6a838e8438c185f035658b68a119b6c8e1", "best_bid": "0.04", "best_ask": "0.06"}], "timestamp": "1769384756073", "event_type": "price_change"}}
{"_local_timestamp": "2026-01-25T23:45:57.272611+00:00", "data": {"market": "0xb4c6f7991dc5d1e110abb1404c629deb7bbc4b07ff19bb4672ff41801824490e", "price_changes": [{"asset_id": "12726823989557107952268342942906206381973799399453895205022550590946554841098", "price": "0.92", "size": "1307.13", "side": "BUY", "hash": "0e69ae77f6b334a6bc1e3f5ac3b909acf31a96cb", "best_bid": "0.94", "best_ask": "0.96"}, {"asset_id": "48577451271083670981595797636824300354923632195069165655560061059665286147100", "price": "0.08", "size": "1307.13", "side": "SELL", "hash": "333e2b421ac5095236672db050fe4d934bdc4817", "best_bid": "0.04", "best_ask": "0.06"}], "timestamp": "1769384756880", "event_type": "price_change"}}
{"_local_timestamp": "2026-01-25T23:45:59.985919+00:00", "data": {"market": "0xb4c6f7991dc5d1e110abb1404c629deb7bbc4b07ff19bb4672ff41801824490e", "price_changes": [{"asset_id": "48577451271083670981595797636824300354923632195069165655560061059665286147100", "price": "0.03", "size": "23506.39", "side": "BUY", "hash": "4664eec9137ef79996364a80e94f913ce61f09f0", "best_bid": "0.04", "best_ask": "0.06"}, {"asset_id": "12726823989557107952268342942906206381973799399453895205022550590946554841098", "price": "0.97", "size": "23506.39", "side": "SELL", "hash": "a370438403e87fca0b8feffb9a9804d4be9603ca", "best_bid": "0.94", "best_ask": "0.96"}], "timestamp": "1769384759916", "event_type": "price_change"}}
{"_local_timestamp": "2026-01-25T23:46:00.090789+00:00", "data": {"market": "0xb4c6f7991dc5d1e110abb1404c629deb7bbc4b07ff19bb4672ff41801824490e", "price_changes": [{"asset_id": "48577451271083670981595797636824300354923632195069165655560061059665286147100", "price": "0.04", "size": "674.14", "side": "BUY", "hash": "0a496bc21f214caf4bf1b6ae68b9318b9e7db666", "best_bid": "0.04", "best_ask": "0.06"}, {"asset_id": "12726823989557107952268342942906206381973799399453895205022550590946554841098", "price": "0.96", "size": "674.14", "side": "SELL", "hash": "3a3ef9ed3edf4bf17d158e23f29b2ec5ce39e8c4", "best_bid": "0.94", "best_ask": "0.96"}], "timestamp": "1769384760001", "event_type": "price_change"}}
{"_local_timestamp": "2026-01-25T23:46:00.091397+00:00", "data": {"market": "0xb4c6f7991dc5d1e110abb1404c629deb7bbc4b07ff19bb4672ff41801824490e", "price_changes": [{"asset_id": "48577451271083670981595797636824300354923632195069165655560061059665286147100", "price": "0.06", "size": "1500.29", "side": "SELL", "hash": "f13c0fe808f57ad7a244fc16df7f27d354237649", "best_bid": "0.04", "best_ask": "0.06"}, {"asset_id": "12726823989557107952268342942906206381973799399453895205022550590946554841098", "price": "0.94", "size": "1500.29", "side": "BUY", "hash": "43f1d41d9cbf4496fa523d14c70780297ae9fbcd", "best_bid": "0.94", "best_ask": "0.96"}], "timestamp": "1769384760003", "event_type": "price_change"}}
{"_local_timestamp": "2026-01-25T23:46:00.372540+00:00", "data": {"market": "0xb4c6f7991dc5d1e110abb1404c629deb7bbc4b07ff19bb4672ff41801824490e", "price_changes": [{"asset_id": "48577451271083670981595797636824300354923632195069165655560061059665286147100", "price": "0.03", "size": "24028.39", "side": "BUY", "hash": "c1824341ce119874c5c9b6224a85c340385706af", "best_bid": "0.04", "best_ask": "0.06"}, {"asset_id": "12726823989557107952268342942906206381973799399453895205022550590946554841098", "price": "0.97", "size": "24028.39", "side": "SELL", "hash": "0a9129ff8c9426e4976e0c3785843e9fe686f9e7", "best_bid": "0.94", "best_ask": "0.96"}], "timestamp": "1769384760299", "event_type": "price_change"}}
{"_local_timestamp": "2026-01-25T23:46:00.592142+00:00", "data": {"market": "0xb4c6f7991dc5d1e110abb1404c629deb7bbc4b07ff19bb4672ff41801824490e", "price_changes": [{"asset_id": "12726823989557107952268342942906206381973799399453895205022550590946554841098", "price": "0.93", "size": "1184.99", "side": "BUY", "hash": "4bc709eff6bd430bb990c897f9a363ab531adbcb", "best_bid": "0.94", "best_ask": "0.96"}, {"asset_id": "48577451271083670981595797636824300354923632195069165655560061059665286147100", "price": "0.07", "size": "1184.99", "side": "SELL", "hash": "43f5ab4439bd6f8ae010529a43160bd43b3de979", "best_bid": "0.04", "best_ask": "0.06"}], "timestamp": "1769384760513", "event_type": "price_change"}}
{"_local_timestamp": "2026-01-25T23:46:00.837337+00:00", "data": {"market": "0xb4c6f7991dc5d1e110abb1404c629deb7bbc4b07ff19bb4672ff41801824490e", "price_changes": [{"asset_id": "12726823989557107952268342942906206381973799399453895205022550590946554841098", "price": "0.93", "size": "1706.99", "side": "BUY", "hash": "5f57b58067d361d42e3afbb37bc879111d777db8", "best_bid": "0.94", "best_ask": "0.96"}, {"asset_id": "48577451271083670981595797636824300354923632195069165655560061059665286147100", "price": "0.07", "size": "1706.99", "side": "SELL", "hash": "a5bf183fae112ce808bad30732f476b127eac691", "best_bid": "0.04", "best_ask": "0.06"}], "timestamp": "1769384760766", "event_type": "price_change"}}
{"_local_timestamp": "2026-01-25T23:46:03.693436+00:00", "data": {"market": "0xb4c6f7991dc5d1e110abb1404c629deb7bbc4b07ff19bb4672ff41801824490e", "price_changes": [{"asset_id": "12726823989557107952268342942906206381973799399453895205022550590946554841098", "price": "0.37", "size": "300", "side": "BUY", "hash": "da67fec05602eebedbeb3a9b909f7cb65d6c1fed", "best_bid": "0.94", "best_ask": "0.96"}, {"asset_id": "48577451271083670981595797636824300354923632195069165655560061059665286147100", "price": "0.63", "size": "300", "side": "SELL", "hash": "604762977cfe680d16762ac3163bc515eb595dc6", "best_bid": "0.04", "best_ask": "0.06"}], "timestamp": "1769384763628", "event_type": "price_change"}}
{"_local_timestamp": "2026-01-25T23:46:03.921763+00:00", "data": {"market": "0xb4c6f7991dc5d1e110abb1404c629deb7bbc4b07ff19bb4672ff41801824490e", "price_changes": [{"asset_id": "48577451271083670981595797636824300354923632195069165655560061059665286147100", "price": "0.02", "size": "25843.62", "side": "BUY", "hash": "3aa436690c021328fddee52ea6bc67d793757116", "best_bid": "0.04", "best_ask": "0.06"}, {"asset_id": "12726823989557107952268342942906206381973799399453895205022550590946554841098", "price": "0.98", "size": "25843.62", "side": "SELL", "hash": "88dc08d6f6eba1dc925baa41bce340a7d3223c13", "best_bid": "0.94", "best_ask": "0.96"}], "timestamp": "1769384763852", "event_type": "price_change"}}
{"_local_timestamp": "2026-01-25T23:46:08.639774+00:00", "data": {"market": "0xb4c6f7991dc5d1e110abb1404c629deb7bbc4b07ff19bb4672ff41801824490e", "price_changes": [{"asset_id": "48577451271083670981595797636824300354923632195069165655560061059665286147100", "price": "0.06", "size": "1550.29", "side": "SELL", "hash": "b119751592e5ac5e0d126e62caa24725e6d2f109", "best_bid": "0.04", "best_ask": "0.06"}, {"asset_id": "12726823989557107952268342942906206381973799399453895205022550590946554841098", "price": "0.94", "size": "1550.29", "side": "BUY", "hash": "cf066e0abe0d5e21b17c43f2c4a63fda1035ed6d", "best_bid": "0.94", "best_ask": "0.96"}], "timestamp": "1769384768576", "event_type": "price_change"}}
{"_local_timestamp": "2026-01-25T23:46:08.650086+00:00", "data": {"market": "0xb4c6f7991dc5d1e110abb1404c629deb7bbc4b07ff19bb4672ff41801824490e", "price_changes": [{"asset_id": "48577451271083670981595797636824300354923632195069165655560061059665286147100", "price": "0.04", "size": "724.14", "side": "BUY", "hash": "3e3ce9d51882ee20a121c7f8f33bd84770e5b295", "best_bid": "0.04", "best_ask": "0.06"}, {"asset_id": "12726823989557107952268342942906206381973799399453895205022550590946554841098", "price": "0.96", "size": "724.14", "side": "SELL", "hash": "dde57514224be80b554a10b63ea8aaba9df47763", "best_bid": "0.94", "best_ask": "0.96"}], "timestamp": "1769384768577", "event_type": "price_change"}}
{"_local_timestamp": "2026-01-25T23:46:10.622610+00:00", "data": {"market": "0xb4c6f7991dc5d1e110abb1404c629deb7bbc4b07ff19bb4672ff41801824490e", "price_changes": [{"asset_id": "12726823989557107952268342942906206381973799399453895205022550590946554841098", "price": "0.24", "size": "216.66", "side": "BUY", "hash": "ad4443a66d7f35351d5d04e144289f19126a8630", "best_bid": "0.94", "best_ask": "0.96"}, {"asset_id": "48577451271083670981595797636824300354923632195069165655560061059665286147100", "price": "0.76", "size": "216.66", "side": "SELL", "hash": "579a2fea5e4b4f4ca1c3267597811eeae4981634", "best_bid": "0.04", "best_ask": "0.06"}], "timestamp": "1769384770467", "event_type": "price_change"}}
{"_local_timestamp": "2026-01-25T23:46:50.998672+00:00", "data": {"market": "0xb4c6f7991dc5d1e110abb1404c629deb7bbc4b07ff19bb4672ff41801824490e", "price_changes": [{"asset_id": "12726823989557107952268342942906206381973799399453895205022550590946554841098", "price": "0.26", "size": "50", "side": "BUY", "hash": "2c9e821d11e3b0d2326b4a17eaeb26ab724fba79", "best_bid": "0.94", "best_ask": "0.96"}, {"asset_id": "48577451271083670981595797636824300354923632195069165655560061059665286147100", "price": "0.74", "size": "50", "side": "SELL", "hash": "36caee1bb7d29a3c7007386e818c49385c1e5e61", "best_bid": "0.04", "best_ask": "0.06"}], "timestamp": "1769384810683", "event_type": "price_change"}}
{"_local_timestamp": "2026-01-25T23:46:51.488498+00:00", "data": {"market": "0xb4c6f7991dc5d1e110abb1404c629deb7bbc4b07ff19bb4672ff41801824490e", "price_changes": [{"asset_id": "12726823989557107952268342942906206381973799399453895205022550590946554841098", "price": "0.3", "size": "100", "side": "BUY", "hash": "8607631b777749358ebf1f804606f32657779766", "best_bid": "0.94", "best_ask": "0.96"}, {"asset_id": "48577451271083670981595797636824300354923632195069165655560061059665286147100", "price": "0.7", "size": "100", "side": "SELL", "hash": "e8617e8d7d9f5f96f52cad630abe2cc9087b1312", "best_bid": "0.04", "best_ask": "0.06"}], "timestamp": "1769384811189", "event_type": "price_change"}}
{"_local_timestamp": "2026-01-25T23:46:54.338004+00:00", "data": {"market": "0xb4c6f7991dc5d1e110abb1404c629deb7bbc4b07ff19bb4672ff41801824490e", "price_changes": [{"asset_id": "12726823989557107952268342942906206381973799399453895205022550590946554841098", "price": "0.04", "size": "0", "side": "BUY", "hash": "f63c64e30994cd262e4432d09ea439581ec4fcf5", "best_bid": "0.94", "best_ask": "0.96"}, {"asset_id": "48577451271083670981595797636824300354923632195069165655560061059665286147100", "price": "0.96", "size": "0", "side": "SELL", "hash": "9faf1089aece843b6f53821c8f7215c6ac93795d", "best_bid": "0.04", "best_ask": "0.06"}], "timestamp": "1769384814262", "event_type": "price_change"}}
{"_local_timestamp": "2026-01-25T23:46:55.197380+00:00", "data": {"market": "0xb4c6f7991dc5d1e110abb1404c629deb7bbc4b07ff19bb4672ff41801824490e", "price_changes": [{"asset_id": "12726823989557107952268342942906206381973799399453895205022550590946554841098", "price": "0.03", "size": "10.15", "side": "BUY", "hash": "770958187447f5550dbf22b563e15b467e6b0055", "best_bid": "0.94", "best_ask": "0.96"}, {"asset_id": "48577451271083670981595797636824300354923632195069165655560061059665286147100", "price": "0.97", "size": "10.15", "side": "SELL", "hash": "44dc9d36cdbe2c8f33931abfc87d0a08af30f10d", "best_bid": "0.04", "best_ask": "0.06"}], "timestamp": "1769384815129", "event_type": "price_change"}}
{"_local_timestamp": "2026-01-25T23:46:55.505568+00:00", "data": {"market": "0xb4c6f7991dc5d1e110abb1404c629deb7bbc4b07ff19bb4672ff41801824490e", "price_changes": [{"asset_id": "48577451271083670981595797636824300354923632195069165655560061059665286147100", "price": "0.02", "size": "25818", "side": "BUY", "hash": "e4f3a29101fc7ecfb569a6cafeb2841b2b40095c", "best_bid": "0.04", "best_ask": "0.06"}, {"asset_id": "12726823989557107952268342942906206381973799399453895205022550590946554841098", "price": "0.98", "size": "25818", "side": "SELL", "hash": "0b03fb83e29e359bfd01f11acfdc92f6149880fa", "best_bid": "0.94", "best_ask": "0.96"}], "timestamp": "1769384815438", "event_type": "price_change"}}
{"_local_timestamp": "2026-01-25T23:46:55.513017+00:00", "data": {"market": "0xb4c6f7991dc5d1e110abb1404c629deb7bbc4b07ff19bb4672ff41801824490e", "price_changes": [{"asset_id": "48577451271083670981595797636824300354923632195069165655560061059665286147100", "price": "0.03", "size": "24012.14", "side": "BUY", "hash": "e4f3a29101fc7ecfb569a6cafeb2841b2b40095c", "best_bid": "0.04", "best_ask": "0.06"}, {"asset_id": "12726823989557107952268342942906206381973799399453895205022550590946554841098", "price": "0.97", "size": "24012.14", "side": "SELL", "hash": "0b03fb83e29e359bfd01f11acfdc92f6149880fa", "best_bid": "0.94", "best_ask": "0.96"}], "timestamp": "1769384815438", "event_type": "price_change"}}
{"_local_timestamp": "2026-01-25T23:46:56.059579+00:00", "data": {"market": "0xb4c6f7991dc5d1e110abb1404c629deb7bbc4b07ff19bb4672ff41801824490e", "price_changes": [{"asset_id": "48577451271083670981595797636824300354923632195069165655560061059665286147100", "price": "0.02", "size": "25843.62", "side": "BUY", "hash": "51daf600e4379db0639d3790a199d115bd2e05b0", "best_bid": "0.04", "best_ask": "0.06"}, {"asset_id": "12726823989557107952268342942906206381973799399453895205022550590946554841098", "price": "0.98", "size": "25843.62", "side": "SELL", "hash": "1cd5834e776dc6cc32011ac4378cf320e81da49e", "best_bid": "0.94", "best_ask": "0.96"}], "timestamp": "1769384815985", "event_type": "price_change"}}
{"_local_timestamp": "2026-01-25T23:46:56.060184+00:00", "data": {"market": "0xb4c6f7991dc5d1e110abb1404c629deb7bbc4b07ff19bb4672ff41801824490e", "price_changes": [{"asset_id": "48577451271083670981595797636824300354923632195069165655560061059665286147100", "price": "0.03", "size": "24028.39", "side": "BUY", "hash": "fe5eafd3f12b07389605fd6a3ee5488d22352a51", "best_bid": "0.04", "best_ask": "0.06"}, {"asset_id": "12726823989557107952268342942906206381973799399453895205022550590946554841098", "price": "0.97", "size": "24028.39", "side": "SELL", "hash": "7b93e28bbb30ef82a22fadd80e275735d967ecc0", "best_bid": "0.94", "best_ask": "0.96"}], "timestamp": "1769384815986", "event_type": "price_change"}}
{"_local_timestamp": "2026-01-25T23:46:58.931382+00:00", "data": {"market": "0xb4c6f7991dc5d1e110abb1404c629deb7bbc4b07ff19bb4672ff41801824490e", "price_changes": [{"asset_id": "12726823989557107952268342942906206381973799399453895205022550590946554841098", "price": "0.24", "size": "116.66", "side": "BUY", "hash": "93da392ebec3b0770d464bd35475f7240f42a4cf", "best_bid": "0.94", "best_ask": "0.96"}, {"asset_id": "48577451271083670981595797636824300354923632195069165655560061059665286147100", "price": "0.76", "size": "116.66", "side": "SELL", "hash": "edd746bfdee82e578bbbb2d61c22d1335a9ab3a0", "best_bid": "0.04", "best_ask": "0.06"}], "timestamp": "1769384818843", "event_type": "price_change"}}
{"_local_timestamp": "2026-01-25T23:46:59.321426+00:00", "data": {"market": "0xb4c6f7991dc5d1e110abb1404c629deb7bbc4b07ff19bb4672ff41801824490e", "price_changes": [{"asset_id": "12726823989557107952268342942906206381973799399453895205022550590946554841098", "price": "0.23", "size": "844", "side": "BUY", "hash": "4450fe3738038acc2c39576f0065230210c8d36f", "best_bid": "0.94", "best_ask": "0.96"}, {"asset_id": "48577451271083670981595797636824300354923632195069165655560061059665286147100", "price": "0.77", "size": "844", "side": "SELL", "hash": "5d6e7c99262095718359182a950f576fd6519a10", "best_bid": "0.04", "best_ask": "0.06"}], "timestamp": "1769384819188", "event_type": "price_change"}}
{"_local_timestamp": "2026-01-25T23:47:23.414064+00:00", "data": {"market": "0xb4c6f7991dc5d1e110abb1404c629deb7bbc4b07ff19bb4672ff41801824490e", "price_changes": [{"asset_id": "12726823989557107952268342942906206381973799399453895205022550590946554841098", "price": "0.23", "size": "794", "side": "BUY", "hash": "a115bbd78edeabafa8f93b1f132dcce8e339464f", "best_bid": "0.94", "best_ask": "0.96"}, {"asset_id": "48577451271083670981595797636824300354923632195069165655560061059665286147100", "price": "0.77", "size": "794", "side": "SELL", "hash": "4cdf414d891814f1d68110ddcee9c021e4a1e079", "best_bid": "0.04", "best_ask": "0.06"}], "timestamp": "1769384843336", "event_type": "price_change"}}
{"_local_timestamp": "2026-01-25T23:47:23.925837+00:00", "data": {"market": "0xb4c6f7991dc5d1e110abb1404c629deb7bbc4b07ff19bb4672ff41801824490e", "price_changes": [{"asset_id": "12726823989557107952268342942906206381973799399453895205022550590946554841098", "price": "0.24", "size": "166.66", "side": "BUY", "hash": "d04f7a97125fb1f00d456d41dcb2753f67d0d2d6", "best_bid": "0.94", "best_ask": "0.96"}, {"asset_id": "48577451271083670981595797636824300354923632195069165655560061059665286147100", "price": "0.76", "size": "166.66", "side": "SELL", "hash": "20c1943904cbc3260c0a7aac4175d7666c069567", "best_bid": "0.04", "best_ask": "0.06"}], "timestamp": "1769384843816", "event_type": "price_change"}}
{"_local_timestamp": "2026-01-25T23:47:24.612058+00:00", "data": {"market": "0xb4c6f7991dc5d1e110abb1404c629deb7bbc4b07ff19bb4672ff41801824490e", "price_changes": [{"asset_id": "12726823989557107952268342942906206381973799399453895205022550590946554841098", "price": "0.27", "size": "1604", "side": "BUY", "hash": "312b650d5a15aa8d2f0ddf329cd3a9ec844c2f09", "best_bid": "0.94", "best_ask": "0.96"}, {"asset_id": "48577451271083670981595797636824300354923632195069165655560061059665286147100", "price": "0.73", "size": "1604", "side": "SELL", "hash": "bc8768d841b1ef6abe520338884b33c3a0cf4cfd", "best_bid": "0.04", "best_ask": "0.06"}], "timestamp": "1769384844543", "event_type": "price_change"}}
{"_local_timestamp": "2026-01-25T23:47:37.356020+00:00", "data": {"market": "0xb4c6f7991dc5d1e110abb1404c629deb7bbc4b07ff19bb4672ff41801824490e", "price_changes": [{"asset_id": "12726823989557107952268342942906206381973799399453895205022550590946554841098", "price": "0.26", "size": "0", "side": "BUY", "hash": "21ea9f556600fa7be968476a81f9e644170bb681", "best_bid": "0.94", "best_ask": "0.96"}, {"asset_id": "48577451271083670981595797636824300354923632195069165655560061059665286147100", "price": "0.74", "size": "0", "side": "SELL", "hash": "c97b368bcedf9b67a09794d387cd303fc0ec89a0", "best_bid": "0.04", "best_ask": "0.06"}], "timestamp": "1769384857286", "event_type": "price_change"}}
{"_local_timestamp": "2026-01-25T23:47:37.899495+00:00", "data": {"market": "0xb4c6f7991dc5d1e110abb1404c629deb7bbc4b07ff19bb4672ff41801824490e", "price_changes": [{"asset_id": "12726823989557107952268342942906206381973799399453895205022550590946554841098", "price": "0.3", "size": "150", "side": "BUY", "hash": "356e26680d6dfaa72d8994f3159205616a6acc4f", "best_bid": "0.94", "best_ask": "0.96"}, {"asset_id": "48577451271083670981595797636824300354923632195069165655560061059665286147100", "price": "0.7", "size": "150", "side": "SELL", "hash": "55f44448d13b6d3842714c8df9db7b9a0af7921e", "best_bid": "0.04", "best_ask": "0.06"}], "timestamp": "1769384857597", "event_type": "price_change"}}
{"_local_timestamp": "2026-01-25T23:47:55.592422+00:00", "data": {"market": "0xb4c6f7991dc5d1e110abb1404c629deb7bbc4b07ff19bb4672ff41801824490e", "price_changes": [{"asset_id": "12726823989557107952268342942906206381973799399453895205022550590946554841098", "price": "0.27", "size": "50", "side": "BUY", "hash": "29a0d01adba097db57551ab887d053323b8280bd", "best_bid": "0.94", "best_ask": "0.96"}, {"asset_id": "48577451271083670981595797636824300354923632195069165655560061059665286147100", "price": "0.73", "size": "50", "side": "SELL", "hash": "4f3bb7eab19150e1b0424a290996ece3ca4d0032", "best_bid": "0.04", "best_ask": "0.06"}], "timestamp": "1769384875410", "event_type": "price_change"}}
{"_local_timestamp": "2026-01-25T23:48:11.650526+00:00", "data": {"market": "0xb4c6f7991dc5d1e110abb1404c629deb7bbc4b07ff19bb4672ff41801824490e", "price_changes": [{"asset_id": "12726823989557107952268342942906206381973799399453895205022550590946554841098", "price": "0.3", "size": "100", "side": "BUY", "hash": "c4e27d2518822a59dbf5851fb9d18ceb0b7b3764", "best_bid": "0.94", "best_ask": "0.96"}, {"asset_id": "48577451271083670981595797636824300354923632195069165655560061059665286147100", "price": "0.7", "size": "100", "side": "SELL", "hash": "1a323c308ac55b1bb483196c44ffc42f9dc4fc40", "best_bid": "0.04", "best_ask": "0.06"}], "timestamp": "1769384891435", "event_type": "price_change"}}
{"_local_timestamp": "2026-01-25T23:48:11.934912+00:00", "data": {"market": "0xb4c6f7991dc5d1e110abb1404c629deb7bbc4b07ff19bb4672ff41801824490e", "price_changes": [{"asset_id": "12726823989557107952268342942906206381973799399453895205022550590946554841098", "price": "0.27", "size": "100", "side": "BUY", "hash": "a62d51714558c3eb821b626af674416136930c36", "best_bid": "0.94", "best_ask": "0.96"}, {"asset_id": "48577451271083670981595797636824300354923632195069165655560061059665286147100", "price": "0.73", "size": "100", "side": "SELL", "hash": "474806c9154b8b4413bccccc589be9702148958a", "best_bid": "0.04", "best_ask": "0.06"}], "timestamp": "1769384891675", "event_type": "price_change"}}
{"_local_timestamp": "2026-01-25T23:48:48.544112+00:00", "data": {"market": "0xb4c6f7991dc5d1e110abb1404c629deb7bbc4b07ff19bb4672ff41801824490e", "price_changes": [{"asset_id": "12726823989557107952268342942906206381973799399453895205022550590946554841098", "price": "0.27", "size": "50", "side": "BUY", "hash": "ef1d0f9a1d84e2d9ab00395f7d01c86de2ed93b0", "best_bid": "0.94", "best_ask": "0.96"}, {"asset_id": "48577451271083670981595797636824300354923632195069165655560061059665286147100", "price": "0.73", "size": "50", "side": "SELL", "hash": "ce324e48df3d9a40177d4d6662d127cb13846aed", "best_bid": "0.04", "best_ask": "0.06"}], "timestamp": "1769384928464", "event_type": "price_change"}}
{"_local_timestamp": "2026-01-25T23:48:48.954560+00:00", "data": {"market": "0xb4c6f7991dc5d1e110abb1404c629deb7bbc4b07ff19bb4672ff41801824490e", "price_changes": [{"asset_id": "12726823989557107952268342942906206381973799399453895205022550590946554841098", "price": "0.3", "size": "150", "side": "BUY", "hash": "7cba5fe883ca51da10f6367e79b585e699dcc53c", "best_bid": "0.94", "best_ask": "0.96"}, {"asset_id": "48577451271083670981595797636824300354923632195069165655560061059665286147100", "price": "0.7", "size": "150", "side": "SELL", "hash": "05babc884a1e155d41dd23c46c55dec41aca32d0", "best_bid": "0.04", "best_ask": "0.06"}], "timestamp": "1769384928852", "event_type": "price_change"}}
{"_local_timestamp": "2026-01-25T23:49:18.529912+00:00", "data": {"market": "0xb4c6f7991dc5d1e110abb1404c629deb7bbc4b07ff19bb4672ff41801824490e", "price_changes": [{"asset_id": "12726823989557107952268342942906206381973799399453895205022550590946554841098", "price": "0.25", "size": "1680", "side": "BUY", "hash": "68c3170faab4f97270855a9cbe91086c14baba2d", "best_bid": "0.94", "best_ask": "0.96"}, {"asset_id": "48577451271083670981595797636824300354923632195069165655560061059665286147100", "price": "0.75", "size": "1680", "side": "SELL", "hash": "b1d0af886b1c2981e211dd8ff8fe5dfbb336bebd", "best_bid": "0.04", "best_ask": "0.06"}], "timestamp": "1769384958460", "event_type": "price_change"}}
{"_local_timestamp": "2026-01-25T23:49:30.413541+00:00", "data": {"market": "0xb4c6f7991dc5d1e110abb1404c629deb7bbc4b07ff19bb4672ff41801824490e", "price_changes": [{"asset_id": "12726823989557107952268342942906206381973799399453895205022550590946554841098", "price": "0.3", "size": "50", "side": "BUY", "hash": "f32f0dd908b6d72053974200b5d15c87918313cc", "best_bid": "0.94", "best_ask": "0.96"}, {"asset_id": "48577451271083670981595797636824300354923632195069165655560061059665286147100", "price": "0.7", "size": "50", "side": "SELL", "hash": "e2a68fb7e3a36416848c021ab7f08d28876688bc", "best_bid": "0.04", "best_ask": "0.06"}], "timestamp": "1769384970078", "event_type": "price_change"}}
{"_local_timestamp": "2026-01-25T23:49:31.104385+00:00", "data": {"market": "0xb4c6f7991dc5d1e110abb1404c629deb7bbc4b07ff19bb4672ff41801824490e", "price_changes": [{"asset_id": "12726823989557107952268342942906206381973799399453895205022550590946554841098", "price": "0.23", "size": "894", "side": "BUY", "hash": "96a3b5cf1561d6fd4583569751e072dac4536587", "best_bid": "0.94", "best_ask": "0.96"}, {"asset_id": "48577451271083670981595797636824300354923632195069165655560061059665286147100", "price": "0.77", "size": "894", "side": "SELL", "hash": "3f450afe2a4d1ac7175cc9873334d8f468026a68", "best_bid": "0.04", "best_ask": "0.06"}], "timestamp": "1769384970677", "event_type": "price_change"}}
{"_local_timestamp": "2026-01-25T23:49:41.652195+00:00", "data": {"market": "0xb4c6f7991dc5d1e110abb1404c629deb7bbc4b07ff19bb4672ff41801824490e", "price_changes": [{"asset_id": "12726823989557107952268342942906206381973799399453895205022550590946554841098", "price": "0.24", "size": "116.66", "side": "BUY", "hash": "52f0d888c551728000cd4fd0049d32d40b11a8cb", "best_bid": "0.94", "best_ask": "0.96"}, {"asset_id": "48577451271083670981595797636824300354923632195069165655560061059665286147100", "price": "0.76", "size": "116.66", "side": "SELL", "hash": "dc457b8310bd02d122799d8fddd117ba79d71d9b", "best_bid": "0.04", "best_ask": "0.06"}], "timestamp": "1769384981587", "event_type": "price_change"}}
{"_local_timestamp": "2026-01-25T23:49:42.396640+00:00", "data": {"market": "0xb4c6f7991dc5d1e110abb1404c629deb7bbc4b07ff19bb4672ff41801824490e", "price_changes": [{"asset_id": "12726823989557107952268342942906206381973799399453895205022550590946554841098", "price": "0.23", "size": "944", "side": "BUY", "hash": "e9744112b04a6aef940c0b643da86df5fcc42c98", "best_bid": "0.94", "best_ask": "0.96"}, {"asset_id": "48577451271083670981595797636824300354923632195069165655560061059665286147100", "price": "0.77", "size": "944", "side": "SELL", "hash": "10a528faf3e90ea87a26bf3b39fc79949683e320", "best_bid": "0.04", "best_ask": "0.06"}], "timestamp": "1769384982224", "event_type": "price_change"}}
{"_local_timestamp": "2026-01-25T23:50:02.813605+00:00", "data": {"market": "0xb4c6f7991dc5d1e110abb1404c629deb7bbc4b07ff19bb4672ff41801824490e", "price_changes": [{"asset_id": "12726823989557107952268342942906206381973799399453895205022550590946554841098", "price": "0.23", "size": "250", "side": "BUY", "hash": "3a0a94e0d1f7813d35286a2d8a912272e10dd815", "best_bid": "0.94", "best_ask": "0.96"}, {"asset_id": "48577451271083670981595797636824300354923632195069165655560061059665286147100", "price": "0.77", "size": "250", "side": "SELL", "hash": "175c69b6d173878b5e45acf445aa0a7f36a07d01", "best_bid": "0.04", "best_ask": "0.06"}], "timestamp": "1769385002277", "event_type": "price_change"}}
{"_local_timestamp": "2026-01-25T23:50:02.969822+00:00", "data": {"market": "0xb4c6f7991dc5d1e110abb1404c629deb7bbc4b07ff19bb4672ff41801824490e", "price_changes": [{"asset_id": "12726823989557107952268342942906206381973799399453895205022550590946554841098", "price": "0.35", "size": "50", "side": "BUY", "hash": "192fd29564b8a93ad6ee7262736d653956acb6eb", "best_bid": "0.94", "best_ask": "0.96"}, {"asset_id": "48577451271083670981595797636824300354923632195069165655560061059665286147100", "price": "0.65", "size": "50", "side": "SELL", "hash": "de9b5be858ee25c99afc07612f4c724f5da96b70", "best_bid": "0.04", "best_ask": "0.06"}], "timestamp": "1769385002368", "event_type": "price_change"}}
{"_local_timestamp": "2026-01-25T23:50:03.197366+00:00", "data": {"market": "0xb4c6f7991dc5d1e110abb1404c629deb7bbc4b07ff19bb4672ff41801824490e", "price_changes": [{"asset_id": "12726823989557107952268342942906206381973799399453895205022550590946554841098", "price": "0.16", "size": "450", "side": "BUY", "hash": "c1c13e821e12bad08d1f779b38c09d517d9f9d1a", "best_bid": "0.94", "best_ask": "0.96"}, {"asset_id": "48577451271083670981595797636824300354923632195069165655560061059665286147100", "price": "0.84", "size": "450", "side": "SELL", "hash": "33452575c9e7ccff3d3c9ce10b53c665166536de", "best_bid": "0.04", "best_ask": "0.06"}], "timestamp": "1769385002729", "event_type": "price_change"}}
{"_local_timestamp": "2026-01-25T23:50:05.536570+00:00", "data": {"market": "0xb4c6f7991dc5d1e110abb1404c629deb7bbc4b07ff19bb4672ff41801824490e", "price_changes": [{"asset_id": "12726823989557107952268342942906206381973799399453895205022550590946554841098", "price": "0.23", "size": "150", "side": "BUY", "hash": "84734b272516e2bfd30c5ddbed36bf57888f8e79", "best_bid": "0.94", "best_ask": "0.96"}, {"asset_id": "48577451271083670981595797636824300354923632195069165655560061059665286147100", "price": "0.77", "size": "150", "side": "SELL", "hash": "68b4a0c6abadb60e7f4fd276cb7f4ae77ea3b073", "best_bid": "0.04", "best_ask": "0.06"}], "timestamp": "1769385005446", "event_type": "price_change"}}
{"_local_timestamp": "2026-01-25T23:50:05.538081+00:00", "data": {"market": "0xb4c6f7991dc5d1e110abb1404c629deb7bbc4b07ff19bb4672ff41801824490e", "price_changes": [{"asset_id": "12726823989557107952268342942906206381973799399453895205022550590946554841098", "price": "0.3", "size": "0", "side": "BUY", "hash": "84734b272516e2bfd30c5ddbed36bf57888f8e79", "best_bid": "0.94", "best_ask": "0.96"}, {"asset_id": "48577451271083670981595797636824300354923632195069165655560061059665286147100", "price": "0.7", "size": "0", "side": "SELL", "hash": "68b4a0c6abadb60e7f4fd276cb7f4ae77ea3b073", "best_bid": "0.04", "best_ask": "0.06"}], "timestamp": "1769385005446", "event_type": "price_change"}}
{"_local_timestamp": "2026-01-25T23:50:05.802050+00:00", "data": {"market": "0xb4c6f7991dc5d1e110abb1404c629deb7bbc4b07ff19bb4672ff41801824490e", "price_changes": [{"asset_id": "12726823989557107952268342942906206381973799399453895205022550590946554841098", "price": "0.29", "size": "139.65", "side": "BUY", "hash": "361dc81399100661c929a0363503802cf99579b8", "best_bid": "0.94", "best_ask": "0.96"}, {"asset_id": "48577451271083670981595797636824300354923632195069165655560061059665286147100", "price": "0.71", "size": "139.65", "side": "SELL", "hash": "82afebf23971307fe2bf0638073685046cd4ab68", "best_bid": "0.04", "best_ask": "0.06"}], "timestamp": "1769385005713", "event_type": "price_change"}}
{"_local_timestamp": "2026-01-25T23:50:05.831026+00:00", "data": {"market": "0xb4c6f7991dc5d1e110abb1404c629deb7bbc4b07ff19bb4672ff41801824490e", "price_changes": [{"asset_id": "12726823989557107952268342942906206381973799399453895205022550590946554841098", "price": "0.25", "size": "1780", "side": "BUY", "hash": "8882e163ef09aafba67be01677670bc9fe06c7a2", "best_bid": "0.94", "best_ask": "0.96"}, {"asset_id": "48577451271083670981595797636824300354923632195069165655560061059665286147100", "price": "0.75", "size": "1780", "side": "SELL", "hash": "07447d9ff3b456e1319414153775dfbdbe9c7805", "best_bid": "0.04", "best_ask": "0.06"}], "timestamp": "1769385005725", "event_type": "price_change"}}
{"_local_timestamp": "2026-01-25T23:50:20.178652+00:00", "data": {"market": "0xb4c6f7991dc5d1e110abb1404c629deb7bbc4b07ff19bb4672ff41801824490e", "price_changes": [{"asset_id": "48577451271083670981595797636824300354923632195069165655560061059665286147100", "price": "0.02", "size": "25818", "side": "BUY", "hash": "dc1c66155e02c347069541ce3ba3f61fe53f6cae", "best_bid": "0.04", "best_ask": "0.06"}, {"asset_id": "12726823989557107952268342942906206381973799399453895205022550590946554841098", "price": "0.98", "size": "25818", "side": "SELL", "hash": "5273a2c1eff5b9bd9d05461c53330bfa20ae25ec", "best_bid": "0.94", "best_ask": "0.96"}], "timestamp": "1769385020104", "event_type": "price_change"}}
{"_local_timestamp": "2026-01-25T23:50:20.179413+00:00", "data": {"market": "0xb4c6f7991dc5d1e110abb1404c629deb7bbc4b07ff19bb4672ff41801824490e", "price_changes": [{"asset_id": "48577451271083670981595797636824300354923632195069165655560061059665286147100", "price": "0.03", "size": "24012.14", "side": "BUY", "hash": "dc1c66155e02c347069541ce3ba3f61fe53f6cae", "best_bid": "0.04", "best_ask": "0.06"}, {"asset_id": "12726823989557107952268342942906206381973799399453895205022550590946554841098", "price": "0.97", "size": "24012.14", "side": "SELL", "hash": "5273a2c1eff5b9bd9d05461c53330bfa20ae25ec", "best_bid": "0.94", "best_ask": "0.96"}], "timestamp": "1769385020104", "event_type": "price_change"}}
{"_local_timestamp": "2026-01-25T23:50:20.524591+00:00", "data": {"market": "0xb4c6f7991dc5d1e110abb1404c629deb7bbc4b07ff19bb4672ff41801824490e", "price_changes": [{"asset_id": "48577451271083670981595797636824300354923632195069165655560061059665286147100", "price": "0.03", "size": "24028.39", "side": "BUY", "hash": "87438837fea1169cbcf8c1a780cf80de72cc2f8a", "best_bid": "0.04", "best_ask": "0.06"}, {"asset_id": "12726823989557107952268342942906206381973799399453895205022550590946554841098", "price": "0.97", "size": "24028.39", "side": "SELL", "hash": "2eb98ffaa18815b1d18a82f0d25f41355e48bd38", "best_bid": "0.94", "best_ask": "0.96"}], "timestamp": "1769385020414", "event_type": "price_change"}}
{"_local_timestamp": "2026-01-25T23:50:20.525242+00:00", "data": {"market": "0xb4c6f7991dc5d1e110abb1404c629deb7bbc4b07ff19bb4672ff41801824490e", "price_changes": [{"asset_id": "48577451271083670981595797636824300354923632195069165655560061059665286147100", "price": "0.02", "size": "25843.62", "side": "BUY", "hash": "b6ca26c0644d00125ffb98b2bd765dcf15bef4fe", "best_bid": "0.04", "best_ask": "0.06"}, {"asset_id": "12726823989557107952268342942906206381973799399453895205022550590946554841098", "price": "0.98", "size": "25843.62", "side": "SELL", "hash": "1b93cd5d1423089ce8172159e72e3fd2d04f1c77", "best_bid": "0.94", "best_ask": "0.96"}], "timestamp": "1769385020415", "event_type": "price_change"}}
{"_local_timestamp": "2026-01-25T23:51:12.878457+00:00", "data": {"market": "0xb4c6f7991dc5d1e110abb1404c629deb7bbc4b07ff19bb4672ff41801824490e", "price_changes": [{"asset_id": "12726823989557107952268342942906206381973799399453895205022550590946554841098", "price": "0.39", "size": "1538", "side": "BUY", "hash": "6faa937a0780d6d7995e2d0ee3622a778d3c702e", "best_bid": "0.94", "best_ask": "0.96"}, {"asset_id": "48577451271083670981595797636824300354923632195069165655560061059665286147100", "price": "0.61", "size": "1538", "side": "SELL", "hash": "a9fcefcc06c284937e20734f3b0f71b4888db874", "best_bid": "0.04", "best_ask": "0.06"}], "timestamp": "1769385072814", "event_type": "price_change"}}
{"_local_timestamp": "2026-01-25T23:51:19.999889+00:00", "data": {"market": "0xb4c6f7991dc5d1e110abb1404c629deb7bbc4b07ff19bb4672ff41801824490e", "price_changes": [{"asset_id": "12726823989557107952268342942906206381973799399453895205022550590946554841098", "price": "0.93", "size": "1756.99", "side": "BUY", "hash": "96e887c68073da326e2587444583e64f0d9f91d9", "best_bid": "0.94", "best_ask": "0.96"}, {"asset_id": "48577451271083670981595797636824300354923632195069165655560061059665286147100", "price": "0.07", "size": "1756.99", "side": "SELL", "hash": "b8b4990528d1b219db8c1200394658defdfdd1e1", "best_bid": "0.04", "best_ask": "0.06"}], "timestamp": "1769385079926", "event_type": "price_change"}}
{"_local_timestamp": "2026-01-25T23:51:20.004697+00:00", "data": {"market": "0xb4c6f7991dc5d1e110abb1404c629deb7bbc4b07ff19bb4672ff41801824490e", "price_changes": [{"asset_id": "48577451271083670981595797636824300354923632195069165655560061059665286147100", "price": "0.03", "size": "24078.39", "side": "BUY", "hash": "e574ab74a5fc1a926c1b19b6be0a1cbc8d215764", "best_bid": "0.04", "best_ask": "0.06"}, {"asset_id": "12726823989557107952268342942906206381973799399453895205022550590946554841098", "price": "0.97", "size": "24078.39", "side": "SELL", "hash": "7ecccb8072e19ef46513f77d721806f3084d1412", "best_bid": "0.94", "best_ask": "0.96"}], "timestamp": "1769385079927", "event_type": "price_change"}}
{"_local_timestamp": "2026-01-25T23:51:25.698595+00:00", "data": {"market": "0xb4c6f7991dc5d1e110abb1404c629deb7bbc4b07ff19bb4672ff41801824490e", "price_changes": [{"asset_id": "12726823989557107952268342942906206381973799399453895205022550590946554841098", "price": "0.16", "size": "400", "side": "BUY", "hash": "ac9b0f28d378633d382e2e3513064482d8d55ac8", "best_bid": "0.94", "best_ask": "0.96"}, {"asset_id": "48577451271083670981595797636824300354923632195069165655560061059665286147100", "price": "0.84", "size": "400", "side": "SELL", "hash": "b9bdd95bbdb67b87fc0a1a6c5503ef04cc030a1b", "best_bid": "0.04", "best_ask": "0.06"}], "timestamp": "1769385085598", "event_type": "price_change"}}
{"_local_timestamp": "2026-01-25T23:51:26.059676+00:00", "data": {"market": "0xb4c6f7991dc5d1e110abb1404c629deb7bbc4b07ff19bb4672ff41801824490e", "price_changes": [{"asset_id": "12726823989557107952268342942906206381973799399453895205022550590946554841098", "price": "0.15", "size": "600", "side": "BUY", "hash": "6d46f5bbfe6b77f88fe650ea7c2fe8b530aa6b0f", "best_bid": "0.94", "best_ask": "0.96"}, {"asset_id": "48577451271083670981595797636824300354923632195069165655560061059665286147100", "price": "0.85", "size": "600", "side": "SELL", "hash": "b354c0570a2fa77344b71a4e8c68bd7e3800f453", "best_bid": "0.04", "best_ask": "0.06"}], "timestamp": "1769385085995", "event_type": "price_change"}}
