{"_local_timestamp": "2026-01-25T23:34:20.443506+00:00", "data": [{"market": "0x1c5bd9f56545c13743da28ddec8e45c6bea8a01ac7e166dce4286afd32b65a62", "asset_id": "100472786165319671267181139302646376200338928621290031353672051075785849864574", "timestamp": "1769384044448", "hash": "14bdb9d0100d78363a64ec3c5eb8ec6907fe188d", "bids": [{"price": "0.01", "size": "100"}, {"price": "0.02", "size": "25"}, {"price": "0.07", "size": "105.47"}], "asks": [{"price": "0.99", "size": "81.64"}, {"price": "0.98", "size": "19.7"}, {"price": "0.97", "size": "100"}, {"price": "0.96", "size": "7.24"}, {"price": "0.95", "size": "1000"}], "event_type": "book", "last_trade_price": "0.390"}, {"market": "0xdd3915ab9de231a4f8d1b6989b9d28c81a39d3372fc2f5e5d5e09c5c36bd15e0", "asset_id": "73772444484179123398639028358181122166565249885455240318019005512648163832892", "timestamp": "1769384058003", "hash": "db3888da333e396d76e9347b649887a9789569bf", "bids": [{"price": "0.01", "size": "50"}, {"price": "0.02", "size": "6.07"}, {"price": "0.04", "size": "121.96"}, {"price": "0.3", "size": "1342"}, {"price": "0.31", "size": "2123"}, {"price": "0.32", "size": "2080"}], "asks": [{"price": "0.99", "size": "55.08"}, {"price": "0.98", "size": "14.64"}, {"price": "0.97", "size": "100"}, {"price": "0.92", "size": "100"}, {"price": "0.91", "size": "7.29"}, {"price": "0.86", "size": "50"}, {"price": "0.8", "size": "200"}, {"price": "0.73", "size": "200"}, {"price": "0.66", "size": "100"}, {"price": "0.51", "size": "1002"}, {"price": "0.5", "size": "2381.98"}, {"price": "0.39", "size": "1600"}, {"price": "0.38", "size": "2073"}, {"price": "0.37", "size": "2231"}, {"price": "0.35", "size": "1760.27"}, {"price": "0.34", "size": "17.09"}], "event_type": "book", "last_trade_price": "0.340"}, {"market": "0x1c5bd9f56545c13743da28ddec8e45c6bea8a01ac7e166dce4286afd32b65a62", "asset_id": "53348317672088212419127100072810163057811272329172845337073296220682545739487", "timestamp": "1769384044448", "hash": "c73b8d511afe70cfed5dfc0056dbff473e3be3bb", "bids": [{"price": "0.01", "size": "81.64"}, {"price": "0.02", "size": "19.7"}, {"price": "0.03", "size": "100"}, {"price": "0.04", "size": "7.24"}, {"price": "0.05", "size": "1000"}], "asks": [{"price": "0.99", "size": "100"}, {"price": "0.98", "size": "25"}, {"price": "0.93", "size": "105.47"}], "event_type": "book", "last_trade_price": "0.390"}, {"market": "0xaeb02ced23cf66b235fb864ed82bdf7f7144c38cb0c7466e5f6c255a5c6015cc", "asset_id": "16066315103031518578542990703395510559372655158819085950817958432162905570385", "timestamp": "1769384058408", "hash": "391c32dcb6e2ff490c3c5ed4c97911616ac4944d", "bids": [{"price": "0.001", "size": "901.07"}, {"price": "0.002", "size": "29.44"}, {"price": "0.01", "size": "74.59"}, {"price": "0.011", "size": "146"}, {"price": "0.013", "size": "152.47"}, {"price": "0.014", "size": "66.86"}, {"price": "0.18", "size": "200"}, {"price": "0.978", "size": "25"}, {"price": "0.979", "size": "5.47"}, {"price": "0.98", "size": "13.1"}, {"price": "0.982", "size": "26.22"}, {"price": "0.983", "size": "24.69"}], "asks": [{"price": "0.999", "size": "1696"}, {"price": "0.998", "size": "49.62"}], "event_type": "book", "last_trade_price": "0.002"}, {"market": "0x2739442c42042c672a419495ab65e9848f55e242a7a861bdb7273ae0ef9a28f0", "asset_id": "113020337348480764985560929631101637916268975813754345808964023186640777084797", "timestamp": "1769383979211", "hash": "63a28e24d25c5b11d0e21efb56418e0b479d3281", "bids": [{"price": "0.01", "size": "70.64"}, {"price": "0.02", "size": "24.63"}], "asks": [{"price": "0.99", "size": "79.06"}, {"price": "0.98", "size": "25.21"}, {"price": "0.97", "size": "1000"}], "event_type": "book", "last_trade_price": ""}, {"market": "0x27d685bdad61bf2f35948bcff8ddf673c14b72a6f4e9cf1a9d867be231f6a610", "asset_id": "82614941921461618729202933946512372479181705578801351216657431603405116134694", "timestamp": "1769384058900", "hash": "c4a194e3d10aefcbf247bd60b881c8a31ec53c47", "bids": [{"price": "0.01", "size": "57.79"}, {"price": "0.02", "size": "105.14"}, {"price": "0.03", "size": "14.06"}, {"price": "0.04", "size": "9.93"}, {"price": "0.31", "size": "1404"}, {"price": "0.32", "size": "2093"}], "asks": [{"price": "0.99", "size": "64.55"}, {"price": "0.97", "size": "100"}, {"price": "0.96", "size": "5.82"}, {"price": "0.91", "size": "100"}, {"price": "0.9", "size": "6.21"}, {"price": "0.86", "size": "50"}, {"price": "0.8", "size": "200"}, {"price": "0.51", "size": "1002"}, {"price": "0.5", "size": "1000"}, {"price": "0.38", "size": "318"}], "event_type": "book", "last_trade_price": ""}, {"market": "0x27d685bdad61bf2f35948bcff8ddf673c14b72a6f4e9cf1a9d867be231f6a610", "asset_id": "32476227489805089000687418984234668312982619103362138837681249693289694597075", "timestamp": "1769384058900", "hash": "41f22322a3a0bb62653eb07fff462027b7339c61", "bids": [{"price": "0.01", "size": "64.55"}, {"price": "0.03", "size": "100"}, {"price": "0.04", "size": "5.82"}, {"price": "0.09", "size": "100"}, {"price": "0.1", "size": "6.21"}, {"price": "0.14", "size": "50"}, {"price": "0.2", "size": "200"}, {"price": "0.49", "size": "1002"}, {"price": "0.5", "size": "1000"}, {"price": "0.62", "size": "318"}], "asks": [{"price": "0.99", "size": "57.79"}, {"price": "0.98", "size": "105.14"}, {"price": "0.97", "size": "14.06"}, {"price": "0.96", "size": "9.93"}, {"price": "0.69", "size": "1404"}, {"price": "0.68", "size": "2093"}], "event_type": "book", "last_trade_price": ""}, {"market": "0x242266c50482ad4f243610f7546b60089eadc1d81d4ef408c787f67aa3ef5e7c", "asset_id": "28263250326920700075422198100613476697802143744104502510886484761449393244656", "timestamp": "1769384058004", "hash": "8349beac23fa1d4d61a29ccdba18d4990e660ea4", "bids": [{"price": "0.01", "size": "65.04"}, {"price": "0.03", "size": "100"}, {"price": "0.04", "size": "5.14"}, {"price": "0.08", "size": "100"}, {"price": "0.09", "size": "7.15"}, {"price": "0.14", "size": "50"}, {"price": "0.2", "size": "200"}, {"price": "0.49", "size": "1002"}, {"price": "0.5", "size": "1035.99"}, {"price": "0.51", "size": "1471"}], "asks": [{"price": "0.99", "size": "55.31"}, {"price": "0.98", "size": "5.03"}, {"price": "0.97", "size": "100"}, {"price": "0.96", "size": "5.29"}, {"price": "0.92", "size": "100"}, {"price": "0.91", "size": "7.04"}, {"price": "0.85", "size": "50"}, {"price": "0.57", "size": "3123"}, {"price": "0.56", "size": "2958"}, {"price": "0.55", "size": "5.87"}], "event_type": "book", "last_trade_price": "0.440"}, {"market": "0x54b69275ee145425f1a0dce69faef15f729f1ab3ec41bc2996a6c6c70e8aec0b", "asset_id": "106447080412815954453539138762045278580988736678171840293222199861758175727534", "timestamp": "1769384058005", "hash": "65280343777bf9b312ee575ff160c59ffb39d968", "bids": [{"price": "0.01", "size": "65.3"}, {"price": "0.03", "size": "100"}, {"price": "0.04", "size": "5.2"}, {"price": "0.08", "size": "100"}, {"price": "0.09", "size": "7.1"}, {"price": "0.15", "size": "50"}, {"price": "0.45", "size": "2078"}, {"price": "0.46", "size": "2925"}], "asks": [{"price": "0.99", "size": "65.24"}, {"price": "0.97", "size": "100"}, {"price": "0.96", "size": "5.2"}, {"price": "0.92", "size": "100"}, {"price": "0.91", "size": "7.1"}, {"price": "0.85", "size": "50"}, {"price": "0.52", "size": "3158"}, {"price": "0.51", "size": "1773"}], "event_type": "book", "last_trade_price": "0.480"}, {"market": "0x6e5e9c218d780a8ff8b516cae97604958f7323ffd75b525d810fb804e727ad78", "asset_id": "4929915665740215533077513370523570724508699505795913150073424458746805119832", "timestamp": "1769384058002", "hash": "3e67b2168cdf458c3b4788a8562f56e952a37c02", "bids": [{"price": "0.01", "size": "50"}, {"price": "0.02", "size": "15.13"}, {"price": "0.03", "size": "100"}, {"price": "0.08", "size": "100"}, {"price": "0.09", "size": "7.74"}, {"price": "0.14", "size": "50"}, {"price": "0.2", "size": "200"}, {"price": "0.27", "size": "200"}, {"price": "0.34", "size": "100"}, {"price": "0.49", "size": "1002"}, {"price": "0.5", "size": "1664.83"}, {"price": "0.78", "size": "1346"}], "asks": [{"price": "0.99", "size": "92.71"}, {"price": "0.98", "size": "28.64"}, {"price": "0.83", "size": "1370"}, {"price": "0.82", "size": "3004"}, {"price": "0.79", "size": "48"}], "event_type": "book", "last_trade_price": "0.190"}, {"market": "0x54b69275ee145425f1a0dce69faef15f729f1ab3ec41bc2996a6c6c70e8aec0b", "asset_id": "44494068166094207162801090520618289188991411103177309101619626920967990930514", "timestamp": "1769384058005", "hash": "c537390b4bd3ed599de464cdb01b9513d6dd8ae0", "bids": [{"price": "0.01", "size": "65.24"}, {"price": "0.03", "size": "100"}, {"price": "0.04", "size": "5.2"}, {"price": "0.08", "size": "100"}, {"price": "0.09", "size": "7.1"}, {"price": "0.15", "size": "50"}, {"price": "0.48", "size": "3158"}, {"price": "0.49", "size": "1773"}], "asks": [{"price": "0.99", "size": "65.3"}, {"price": "0.97", "size": "100"}, {"price": "0.96", "size": "5.2"}, {"price": "0.92", "size": "100"}, {"price": "0.91", "size": "7.1"}, {"price": "0.85", "size": "50"}, {"price": "0.55", "size": "2078"}, {"price": "0.54", "size": "2925"}], "event_type": "book", "last_trade_price": "0.480"}, {"market": "0x242266c50482ad4f243610f7546b60089eadc1d81d4ef408c787f67aa3ef5e7c", "asset_id": "96533933355712544390418613060156510030240147080751769428940162257378106436404", "timestamp": "1769384058004", "hash": "05c70c22eacace691b19f4c3db5443568e530c5c", "bids": [{"price": "0.01", "size": "55.31"}, {"price": "0.02", "size": "5.03"}, {"price": "0.03", "size": "100"}, {"price": "0.04", "size": "5.29"}, {"price": "0.08", "size": "100"}, {"price": "0.09", "size": "7.04"}, {"price": "0.15", "size": "50"}, {"price": "0.43", "size": "3123"}, {"price": "0.44", "size": "2958"}, {"price": "0.45", "size": "5.87"}], "asks": [{"price": "0.99", "size": "65.04"}, {"price": "0.97", "size": "100"}, {"price": "0.96", "size": "5.14"}, {"price": "0.92", "size": "100"}, {"price": "0.91", "size": "7.15"}, {"price": "0.86", "size": "50"}, {"price": "0.8", "size": "200"}, {"price": "0.51", "size": "1002"}, {"price": "0.5", "size": "1035.99"}, {"price": "0.49", "size": "1471"}], "event_type": "book", "last_trade_price": "0.440"}, {"market": "0xdc6daed612fa869c874ad32851b78d9734521495e3d690e8c461f9bf7d832853", "asset_id": "52466361244355331872258867551623723655468496127390662381658208879315243737145", "timestamp": "1769383550414", "hash": "25a7e60abd8a80589625ae541300903185989123", "bids": [{"price": "0.01", "size": "100"}, {"price": "0.02", "size": "30.46"}, {"price": "0.08", "size": "100"}], "asks": [{"price": "0.99", "size": "69.93"}, {"price": "0.98", "size": "25.01"}, {"price": "0.96", "size": "100"}, {"price": "0.95", "size": "11.48"}], "event_type": "book", "last_trade_price": ""}, {"market": "0x7573b38aa3d3d387be05d7e2b3fa5c397c6cbf1fbfbb5ccbe1d82816b901e9d1", "asset_id": "47900911198961041897125947140815317810676260067603694036981412378636602096971", "timestamp": "1769384058004", "hash": "e755d34719bad9a5d2c0c0bd66450878bdba6d06", "bids": [{"price": "0.01", "size": "440.4"}, {"price": "0.02", "size": "125.14"}, {"price": "0.03", "size": "1100"}, {"price": "0.04", "size": "7.22"}, {"price": "0.05", "size": "8.1"}, {"price": "0.08", "size": "600"}, {"price": "0.1", "size": "10"}, {"price": "0.11", "size": "5.06"}, {"price": "0.14", "size": "250"}, {"price": "0.29", "size": "4496"}, {"price": "0.3", "size": "10"}, {"price": "0.31", "size": "10"}, {"price": "0.32", "size": "3552.25"}, {"price": "0.35", "size": "2671.66"}, {"price": "0.36", "size": "10"}, {"price": "0.38", "size": "2734"}, {"price": "0.4", "size": "100"}, {"price": "0.41", "size": "1751"}, {"price": "0.42", "size": "7716"}, {"price": "0.43", "size": "8264"}, {"price": "0.44", "size": "19972.76"}, {"price": "0.45", "size": "20"}], "asks": [{"price": "0.99", "size": "464.98"}, {"price": "0.97", "size": "100"}, {"price": "0.96", "size": "6.83"}, {"price": "0.95", "size": "900"}, {"price": "0.92", "size": "100"}, {"price": "0.9", "size": "509.44"}, {"price": "0.89", "size": "5.24"}, {"price": "0.86", "size": "50"}, {"price": "0.8", "size": "400"}, {"price": "0.64", "size": "4244"}, {"price": "0.61", "size": "3386.5"}, {"price": "0.58", "size": "2567.5"}, {"price": "0.55", "size": "1781.25"}, {"price": "0.52", "size": "1005"}, {"price": "0.51", "size": "1002"}, {"price": "0.5", "size": "1100"}, {"price": "0.49", "size": "6033"}, {"price": "0.48", "size": "7054"}, {"price": "0.47", "size": "12425"}, {"price": "0.46", "size": "9913.35"}], "event_type": "book", "last_trade_price": "0.550"}, {"market": "0xcf18b8f0901452013dcdf957badd6bfb71a9935c6dd9dd2566dc5bb7f795c1a0", "asset_id": "13301686528282766867573623232056946130992514687837926123264639755941579360230", "timestamp": "1769384058004", "hash": "85c707db2cc3f9eb2d31db400932d1757c555186", "bids": [{"price": "0.01", "size": "64.65"}, {"price": "0.03", "size": "100"}, {"price": "0.04", "size": "5"}, {"price": "0.08", "size": "100"}, {"price": "0.09", "size": "7.25"}, {"price": "0.14", "size": "50"}, {"price": "0.2", "size": "200"}, {"price": "0.27", "size": "200"}, {"price": "0.49", "size": "1002"}, {"price": "0.5", "size": "1000"}, {"price": "0.59", "size": "1335"}], "asks": [{"price": "0.99", "size": "50"}, {"price": "0.98", "size": "5.65"}, {"price": "0.96", "size": "100"}, {"price": "0.94", "size": "14.78"}, {"price": "0.65", "size": "1068"}, {"price": "0.64", "size": "2519"}, {"price": "0.63", "size": "49.73"}], "event_type": "book", "last_trade_price": "0.580"}, {"market": "0x6ac594337fbd762ec04471e8d65806ff9ff78c33ed9dca4826c7bd2969475251", "asset_id": "79880305123726971124937075515339490140944001374542290672889526459108541617627", "timestamp": "1769384058004", "hash": "581c762feb49ad148ab4521499f93f10ade6eff1", "bids": [{"price": "0.01", "size": "50"}, {"price": "0.02", "size": "15.12"}, {"price": "0.03", "size": "100"}, {"price": "0.08", "size": "100"}, {"price": "0.09", "size": "7.75"}, {"price": "0.14", "size": "50"}, {"price": "0.2", "size": "200"}, {"price": "0.49", "size": "1002"}, {"price": "0.5", "size": "1000"}, {"price": "0.81", "size": "463"}], "asks": [{"price": "0.99", "size": "74.66"}, {"price": "0.98", "size": "37.66"}, {"price": "0.88", "size": "1625"}, {"price": "0.87", "size": "1991"}, {"price": "0.86", "size": "976"}], "event_type": "book", "last_trade_price": "0.150"}, {"market": "0x6ac594337fbd762ec04471e8d65806ff9ff78c33ed9dca4826c7bd2969475251", "asset_id": "115162358394175336212249289650926294268751651827332730207583087521345129280038", "timestamp": "1769384058004", "hash": "c0fc2c8fad643d845e1343e2257035aa0cf2b89b", "bids": [{"price": "0.01", "size": "74.66"}, {"price": "0.02", "size": "37.66"}, {"price": "0.12", "size": "1625"}, {"price": "0.13", "size": "1991"}, {"price": "0.14", "size": "976"}], "asks": [{"price": "0.99", "size": "50"}, {"price": "0.98", "size": "15.12"}, {"price": "0.97", "size": "100"}, {"price": "0.92", "size": "100"}, {"price": "0.91", "size": "7.75"}, {"price": "0.86", "size": "50"}, {"price": "0.8", "size": "200"}, {"price": "0.51", "size": "1002"}, {"price": "0.5", "size": "1000"}, {"price": "0.19", "size": "463"}], "event_type": "book", "last_trade_price": "0.150"}, {"market": "0x7573b38aa3d3d387be05d7e2b3fa5c397c6cbf1fbfbb5ccbe1d82816b901e9d1", "asset_id": "45963563720386640986457133827320203891928335132800978095470889439601833791792", "timestamp": "1769384058004", "hash": "3f40a7a76ee2c0615cc7e9e8441d03c483cdc0ab", "bids": [{"price": "0.01", "size": "464.98"}, {"price": "0.03", "size": "100"}, {"price": "0.04", "size": "6.83"}, {"price": "0.05", "size": "900"}, {"price": "0.08", "size": "100"}, {"price": "0.1", "size": "509.44"}, {"price": "0.11", "size": "5.24"}, {"price": "0.14", "size": "50"}, {"price": "0.2", "size": "400"}, {"price": "0.36", "size": "4244"}, {"price": "0.39", "size": "3386.5"}, {"price": "0.42", "size": "2567.5"}, {"price": "0.45", "size": "1781.25"}, {"price": "0.48", "size": "1005"}, {"price": "0.49", "size": "1002"}, {"price": "0.5", "size": "1100"}, {"price": "0.51", "size": "6033"}, {"price": "0.52", "size": "7054"}, {"price": "0.53", "size": "12425"}, {"price": "0.54", "size": "9913.35"}], "asks": [{"price": "0.99", "size": "440.4"}, {"price": "0.98", "size": "125.14"}, {"price": "0.97", "size": "1100"}, {"price": "0.96", "size": "7.22"}, {"price": "0.95", "size": "8.1"}, {"price": "0.92", "size": "600"}, {"price": "0.9", "size": "10"}, {"price": "0.89", "size": "5.06"}, {"price": "0.86", "size": "250"}, {"price": "0.71", "size": "4496"}, {"price": "0.7", "size": "10"}, {"price": "0.69", "size": "10"}, {"price": "0.68", "size": "3552.25"}, {"price": "0.65", "size": "2671.66"}, {"price": "0.64", "size": "10"}, {"price": "0.62", "size": "2734"}, {"price": "0.6", "size": "100"}, {"price": "0.59", "size": "1751"}, {"price": "0.58", "size": "7716"}, {"price": "0.57", "size": "8264"}, {"price": "0.56", "size": "19972.76"}, {"price": "0.55", "size": "20"}], "event_type": "book", "last_trade_price": "0.550"}, {"market": "0xdc6daed612fa869c874ad32851b78d9734521495e3d690e8c461f9bf7d832853", "asset_id": "45483717755025715616218880974042350616014220906545869078686592268159794063677", "timestamp": "1769383550414", "hash": "b52690c604c12c1b198737cea15f4186e2d89a4b", "bids": [{"price": "0.01", "size": "69.93"}, {"price": "0.02", "size": "25.01"}, {"price": "0.04", "size": "100"}, {"price": "0.05", "size": "11.48"}], "asks": [{"price": "0.99", "size": "100"}, {"price": "0.98", "size": "30.46"}, {"price": "0.92", "size": "100"}], "event_type": "book", "last_trade_price": ""}, {"market": "0x2739442c42042c672a419495ab65e9848f55e242a7a861bdb7273ae0ef9a28f0", "asset_id": "65198543161610672911645425360781565981236467927336501037693358120183411770638", "timestamp": "1769383979211", "hash": "9c3baee39149825581adf16915c0f79eb1eb8fcc", "bids": [{"price": "0.01", "size": "79.06"}, {"price": "0.02", "size": "25.21"}, {"price": "0.03", "size": "1000"}], "asks": [{"price": "0.99", "size": "70.64"}, {"price": "0.98", "size": "24.63"}], "event_type": "book", "last_trade_price": ""}, {"market": "0xaeb02ced23cf66b235fb864ed82bdf7f7144c38cb0c7466e5f6c255a5c6015cc", "asset_id": "38866550321267038434460376745002272171027672578638559578882849128491520813825", "timestamp": "1769384058408", "hash": "4b34cf6ac0d73d7dcb6e0dcbaafd75d4ac6f0dbe", "bids": [{"price": "0.001", "size": "1696"}, {"price": "0.002", "size": "49.62"}], "asks": [{"price": "0.999", "size": "901.07"}, {"price": "0.998", "size": "29.44"}, {"price": "0.99", "size": "74.59"}, {"price": "0.989", "size": "146"}, {"price": "0.987", "size": "152.47"}, {"price": "0.986", "size": "66.86"}, {"price": "0.82", "size": "200"}, {"price": "0.022", "size": "25"}, {"price": "0.021", "size": "5.47"}, {"price": "0.02", "size": "13.1"}, {"price": "0.018", "size": "26.22"}, {"price": "0.017", "size": "24.69"}], "event_type": "book", "last_trade_price": "0.002"}, {"market": "0xdd3915ab9de231a4f8d1b6989b9d28c81a39d3372fc2f5e5d5e09c5c36bd15e0", "asset_id": "64912974742020396457447321385468313243213302286888804044150787878568707049629", "timestamp": "1769384058003", "hash": "5816a6eef5d2085a61f847f0e066972529716bc2", "bids": [{"price": "0.01", "size": "55.08"}, {"price": "0.02", "size": "14.64"}, {"price": "0.03", "size": "100"}, {"price": "0.08", "size": "100"}, {"price": "0.09", "size": "7.29"}, {"price": "0.14", "size": "50"}, {"price": "0.2", "size": "200"}, {"price": "0.27", "size": "200"}, {"price": "0.34", "size": "100"}, {"price": "0.49", "size": "1002"}, {"price": "0.5", "size": "2381.98"}, {"price": "0.61", "size": "1600"}, {"price": "0.62", "size": "2073"}, {"price": "0.63", "size": "2231"}, {"price": "0.65", "size": "1760.27"}, {"price": "0.66", "size": "17.09"}], "asks": [{"price": "0.99", "size": "50"}, {"price": "0.98", "size": "6.07"}, {"price": "0.96", "size": "121.96"}, {"price": "0.7", "size": "1342"}, {"price": "0.69", "size": "2123"}, {"price": "0.68", "size": "2080"}], "event_type": "book", "last_trade_price": "0.340"}, {"market": "0x6e5e9c218d780a8ff8b516cae97604958f7323ffd75b525d810fb804e727ad78", "asset_id": "66190026636022120219272454910747143264277679901831317594304438527297253363875", "timestamp": "1769384058002", "hash": "004f58da1e51e6feed3997f09e276e666786b230", "bids": [{"price": "0.01", "size": "92.71"}, {"price": "0.02", "size": "28.64"}, {"price": "0.17", "size": "1370"}, {"price": "0.18", "size": "3004"}, {"price": "0.21", "size": "48"}], "asks": [{"price": "0.99", "size": "50"}, {"price": "0.98", "size": "15.13"}, {"price": "0.97", "size": "100"}, {"price": "0.92", "size": "100"}, {"price": "0.91", "size": "7.74"}, {"price": "0.86", "size": "50"}, {"price": "0.8", "size": "200"}, {"price": "0.73", "size": "200"}, {"price": "0.66", "size": "100"}, {"price": "0.51", "size": "1002"}, {"price": "0.5", "size": "1664.83"}, {"price": "0.22", "size": "1346"}], "event_type": "book", "last_trade_price": "0.190"}, {"market": "0xcf18b8f0901452013dcdf957badd6bfb71a9935c6dd9dd2566dc5bb7f795c1a0", "asset_id": "86867607300025136841054177922135303037165603316339117668930743822611084804074", "timestamp": "1769384058004", "hash": "6f4401305c374d420ac7a403e75e9f6082698b76", "bids": [{"price": "0.01", "size": "50"}, {"price": "0.02", "size": "5.65"}, {"price": "0.04", "size": "100"}, {"price": "0.06", "size": "14.78"}, {"price": "0.35", "size": "1068"}, {"price": "0.36", "size": "2519"}, {"price": "0.37", "size": "49.73"}], "asks": [{"price": "0.99", "size": "64.65"}, {"price": "0.97", "size": "100"}, {"price": "0.96", "size": "5"}, {"price": "0.92", "size": "100"}, {"price": "0.91", "size": "7.25"}, {"price": "0.86", "size": "50"}, {"price": "0.8", "size": "200"}, {"price": "0.73", "size": "200"}, {"price": "0.51", "size": "1002"}, {"price": "0.5", "size": "1000"}, {"price": "0.41", "size": "1335"}], "event_type": "book", "last_trade_price": "0.580"}]}
{"_local_timestamp": "2026-01-25T23:34:20.444830+00:00", "data": {"market": "0xaeb02ced23cf66b235fb864ed82bdf7f7144c38cb0c7466e5f6c255a5c6015cc", "price_changes": [{"asset_id": "38866550321267038434460376745002272171027672578638559578882849128491520813825", "price": "0.018", "size": "13.11", "side": "SELL", "hash": "e772fc78eb0bb9f882430c223c93e1b0cb0152fa", "best_bid": "0.002", "best_ask": "0.017"}, {"asset_id": "16066315103031518578542990703395510559372655158819085950817958432162905570385", "price": "0.982", "size": "13.11", "side": "BUY", "hash": "43d269669dc3e7a9fbe7ef0ca25b5517160f8b9a", "best_bid": "0.983", "best_ask": "0.998"}], "timestamp": "1769384060149", "event_type": "price_change"}}
{"_local_timestamp": "2026-01-25T23:34:20.445638+00:00", "data": {"market": "0xaeb02ced23cf66b235fb864ed82bdf7f7144c38cb0c7466e5f6c255a5c6015cc", "price_changes": [{"asset_id": "38866550321267038434460376745002272171027672578638559578882849128491520813825", "price": "0.02", "size": "0", "side": "SELL", "hash": "e772fc78eb0bb9f882430c223c93e1b0cb0152fa", "best_bid": "0.002", "best_ask": "0.017"}, {"asset_id": "16066315103031518578542990703395510559372655158819085950817958432162905570385", "price": "0.98", "size": "0", "side": "BUY", "hash": "43d269669dc3e7a9fbe7ef0ca25b5517160f8b9a", "best_bid": "0.983", "best_ask": "0.998"}], "timestamp": "1769384060149", "event_type": "price_change"}}
{"_local_timestamp": "2026-01-25T23:34:20.688188+00:00", "data": {"market": "0xaeb02ced23cf66b235fb864ed82bdf7f7144c38cb0c7466e5f6c255a5c6015cc", "price_changes": [{"asset_id": "38866550321267038434460376745002272171027672578638559578882849128491520813825", "price": "0.016", "size": "13.1", "side": "SELL", "hash": "f4cfc4cc90727a5ae2187a690688d461e763601e", "best_bid": "0.002", "best_ask": "0.016"}, {"asset_id": "16066315103031518578542990703395510559372655158819085950817958432162905570385", "price": "0.984", "size": "13.1", "side": "BUY", "hash": "f69b0b4f18099948b14ca7f165cafad58b96612e", "best_bid": "0.984", "best_ask": "0.998"}], "timestamp": "1769384060453", "event_type": "price_change"}}
{"_local_timestamp": "2026-01-25T23:34:20.688632+00:00", "data": {"market": "0xaeb02ced23cf66b235fb864ed82bdf7f7144c38cb0c7466e5f6c255a5c6015cc", "price_changes": [{"asset_id": "38866550321267038434460376745002272171027672578638559578882849128491520813825", "price": "0.016", "size": "26.2", "side": "SELL", "hash": "4382efdd12ba3dabd4e1a5513a0cb02ec74783d5", "best_bid": "0.002", "best_ask": "0.016"}, {"asset_id": "16066315103031518578542990703395510559372655158819085950817958432162905570385", "price": "0.984", "size": "26.2", "side": "BUY", "hash": "48851a873f6ccafc418e03ed7b89dab99dca1d95", "best_bid": "0.984", "best_ask": "0.998"}], "timestamp": "1769384060454", "event_type": "price_change"}}
{"_local_timestamp": "2026-01-25T23:34:20.813964+00:00", "data": {"market": "0x27d685bdad61bf2f35948bcff8ddf673c14b72a6f4e9cf1a9d867be231f6a610", "price_changes": [{"asset_id": "82614941921461618729202933946512372479181705578801351216657431603405116134694", "price": "0.02", "size": "100", "side": "BUY", "hash": "7c4b3bbdc9e7f41f357eee94c4ae1e4075c76ebf", "best_bid": "0.32", "best_ask": "0.38"}, {"asset_id": "32476227489805089000687418984234668312982619103362138837681249693289694597075", "price": "0.98", "size": "100", "side": "SELL", "hash": "8d8f989467ef42844bb14a0c502538fae750ba89", "best_bid": "0.62", "best_ask": "0.68"}], "timestamp": "1769384060578", "event_type": "price_change"}}
{"_local_timestamp": "2026-01-25T23:34:20.816690+00:00", "data": {"market": "0x27d685bdad61bf2f35948bcff8ddf673c14b72a6f4e9cf1a9d867be231f6a610", "price_changes": [{"asset_id": "82614941921461618729202933946512372479181705578801351216657431603405116134694", "price": "0.04", "size": "0", "side": "BUY", "hash": "7c4b3bbdc9e7f41f357eee94c4ae1e4075c76ebf", "best_bid": "0.32", "best_ask": "0.38"}, {"asset_id": "32476227489805089000687418984234668312982619103362138837681249693289694597075", "price": "0.96", "size": "0", "side": "SELL", "hash": "8d8f989467ef42844bb14a0c502538fae750ba89", "best_bid": "0.62", "best_ask": "0.68"}], "timestamp": "1769384060578", "event_type": "price_change"}}
{"_local_timestamp": "2026-01-25T23:34:21.093949+00:00", "data": {"market": "0xaeb02ced23cf66b235fb864ed82bdf7f7144c38cb0c7466e5f6c255a5c6015cc", "price_changes": [{"asset_id": "38866550321267038434460376745002272171027672578638559578882849128491520813825", "price": "0.017", "size": "0", "side": "SELL", "hash": "88a585df35893bd2461cebea2cbecbe6636dd3d7", "best_bid": "0.002", "best_ask": "0.016"}, {"asset_id": "16066315103031518578542990703395510559372655158819085950817958432162905570385", "price": "0.983", "size": "0", "side": "BUY", "hash": "f51212e751e7bb6e71a256001f462f6cc679b98f", "best_bid": "0.984", "best_ask": "0.998"}], "timestamp": "1769384060857", "event_type": "price_change"}}
{"_local_timestamp": "2026-01-25T23:34:21.113635+00:00", "data": {"market": "0x27d685bdad61bf2f35948bcff8ddf673c14b72a6f4e9cf1a9d867be231f6a610", "price_changes": [{"asset_id": "82614941921461618729202933946512372479181705578801351216657431603405116134694", "price": "0.03", "size": "22.39", "side": "BUY", "hash": "8d1d8de09e27ef2575e7cc10e2c3c82d5809979c", "best_bid": "0.32", "best_ask": "0.38"}, {"asset_id": "32476227489805089000687418984234668312982619103362138837681249693289694597075", "price": "0.97", "size": "22.39", "side": "SELL", "hash": "6b401c84c90b4d9857e0f9940c5d8c5c86b8935b", "best_bid": "0.62", "best_ask": "0.68"}], "timestamp": "1769384060890", "event_type": "price_change"}}
{"_local_timestamp": "2026-01-25T23:34:21.114084+00:00", "data": {"market": "0x27d685bdad61bf2f35948bcff8ddf673c14b72a6f4e9cf1a9d867be231f6a610", "price_changes": [{"asset_id": "82614941921461618729202933946512372479181705578801351216657431603405116134694", "price": "0.03", "size": "30.72", "side": "BUY", "hash": "df1d29eab6333f1c134d86a6b740cc9908e9befd", "best_bid": "0.32", "best_ask": "0.38"}, {"asset_id": "32476227489805089000687418984234668312982619103362138837681249693289694597075", "price": "0.97", "size": "30.72", "side": "SELL", "hash": "15d9a7718de9efb5433ec1a11408aeff3cf54fcd", "best_bid": "0.62", "best_ask": "0.68"}], "timestamp": "1769384060890", "event_type": "price_change"}}
{"_local_timestamp": "2026-01-25T23:34:21.115640+00:00", "data": {"market": "0xaeb02ced23cf66b235fb864ed82bdf7f7144c38cb0c7466e5f6c255a5c6015cc", "price_changes": [{"asset_id": "38866550321267038434460376745002272171027672578638559578882849128491520813825", "price": "0.015", "size": "24.69", "side": "SELL", "hash": "1939686663b36ac67637829f74b246b4777efd29", "best_bid": "0.002", "best_ask": "0.015"}, {"asset_id": "16066315103031518578542990703395510559372655158819085950817958432162905570385", "price": "0.985", "size": "24.69", "side": "BUY", "hash": "71c189b92eb45856c4ce810e9cde4ff54ded0843", "best_bid": "0.985", "best_ask": "0.998"}], "timestamp": "1769384060892", "event_type": "price_change"}}
{"_local_timestamp": "2026-01-25T23:34:22.569328+00:00", "data": {"market": "0xdd3915ab9de231a4f8d1b6989b9d28c81a39d3372fc2f5e5d5e09c5c36bd15e0", "price_changes": [{"asset_id": "73772444484179123398639028358181122166565249885455240318019005512648163832892", "price": "0.04", "size": "21.96", "side": "BUY", "hash": "0e109c94ab35ddf958c96f7b567b23a4869311c2", "best_bid": "0.32", "best_ask": "0.34"}, {"asset_id": "64912974742020396457447321385468313243213302286888804044150787878568707049629", "price": "0.96", "size": "21.96", "side": "SELL", "hash": "697385b952b5ba8fc3f6c37b7e35a16b091d9f1e", "best_bid": "0.66", "best_ask": "0.68"}], "timestamp": "1769384062336", "event_type": "price_change"}}
{"_local_timestamp": "2026-01-25T23:34:22.569736+00:00", "data": {"market": "0x54b69275ee145425f1a0dce69faef15f729f1ab3ec41bc2996a6c6c70e8aec0b", "price_changes": [{"asset_id": "44494068166094207162801090520618289188991411103177309101619626920967990930514", "price": "0.15", "size": "0", "side": "BUY", "hash": "11d3f7b56a444fcdfa0ab89483a01814fa42c49a", "best_bid": "0.49", "best_ask": "0.54"}, {"asset_id": "106447080412815954453539138762045278580988736678171840293222199861758175727534", "price": "0.85", "size": "0", "side": "SELL", "hash": "52ccca3ab2309aca53f16cb90a66773ecd3028ac", "best_bid": "0.46", "best_ask": "0.51"}], "timestamp": "1769384062336", "event_type": "price_change"}}
{"_local_timestamp": "2026-01-25T23:34:22.570038+00:00", "data": {"market": "0x27d685bdad61bf2f35948bcff8ddf673c14b72a6f4e9cf1a9d867be231f6a610", "price_changes": [{"asset_id": "82614941921461618729202933946512372479181705578801351216657431603405116134694", "price": "0.02", "size": "0", "side": "BUY", "hash": "95d9b63d49bcbec18994ee6ceb8b49906532e2b9", "best_bid": "0.32", "best_ask": "0.38"}, {"asset_id": "32476227489805089000687418984234668312982619103362138837681249693289694597075", "price": "0.98", "size": "0", "side": "SELL", "hash": "fb5689adfc5cc1c7bebebe29e3e30e56e4c2ea79", "best_bid": "0.62", "best_ask": "0.68"}], "timestamp": "1769384062337", "event_type": "price_change"}}
{"_local_timestamp": "2026-01-25T23:34:22.570546+00:00", "data": {"market": "0x242266c50482ad4f243610f7546b60089eadc1d81d4ef408c787f67aa3ef5e7c", "price_changes": [{"asset_id": "96533933355712544390418613060156510030240147080751769428940162257378106436404", "price": "0.15", "size": "0", "side": "BUY", "hash": "d95ba121aa40135f0e61e1bcc90ee4b8bc0daf59", "best_bid": "0.45", "best_ask": "0.49"}, {"asset_id": "28263250326920700075422198100613476697802143744104502510886484761449393244656", "price": "0.85", "size": "0", "side": "SELL", "hash": "ffe2c7bb0b306955b4f9884a4e446052103ab5fc", "best_bid": "0.51", "best_ask": "0.55"}], "timestamp": "1769384062337", "event_type": "price_change"}}
{"_local_timestamp": "2026-01-25T23:34:22.570897+00:00", "data": {"market": "0xcf18b8f0901452013dcdf957badd6bfb71a9935c6dd9dd2566dc5bb7f795c1a0", "price_changes": [{"asset_id": "86867607300025136841054177922135303037165603316339117668930743822611084804074", "price": "0.04", "size": "0", "side": "BUY", "hash": "cb0d6105f78ea558629858ee3b1a2a3f5b6e8d10", "best_bid": "0.37", "best_ask": "0.41"}, {"asset_id": "13301686528282766867573623232056946130992514687837926123264639755941579360230", "price": "0.96", "size": "0", "side": "SELL", "hash": "817892e103e2f876a97586996341eaba5803cee6", "best_bid": "0.59", "best_ask": "0.63"}], "timestamp": "1769384062337", "event_type": "price_change"}}
{"_local_timestamp": "2026-01-25T23:34:22.571201+00:00", "data": {"market": "0x54b69275ee145425f1a0dce69faef15f729f1ab3ec41bc2996a6c6c70e8aec0b", "price_changes": [{"asset_id": "106447080412815954453539138762045278580988736678171840293222199861758175727534", "price": "0.15", "size": "0", "side": "BUY", "hash": "27b2b35eb13dbdd3f0fe7d65a6614696b65e7e0f", "best_bid": "0.46", "best_ask": "0.51"}, {"asset_id": "44494068166094207162801090520618289188991411103177309101619626920967990930514", "price": "0.85", "size": "0", "side": "SELL", "hash": "d92f9d181fb04e91bdcc9237c444e17f2625a6e2", "best_bid": "0.49", "best_ask": "0.54"}], "timestamp": "1769384062337", "event_type": "price_change"}}
{"_local_timestamp": "2026-01-25T23:34:22.571575+00:00", "data": {"market": "0x27d685bdad61bf2f35948bcff8ddf673c14b72a6f4e9cf1a9d867be231f6a610", "price_changes": [{"asset_id": "32476227489805089000687418984234668312982619103362138837681249693289694597075", "price": "0.09", "size": "0", "side": "BUY", "hash": "2ea0f4e586767001fdbdac6fbf81d3a8d44ca673", "best_bid": "0.62", "best_ask": "0.68"}, {"asset_id": "82614941921461618729202933946512372479181705578801351216657431603405116134694", "price": "0.91", "size": "0", "side": "SELL", "hash": "c2d4f3c9afd94b61111845fa59e02ff9064fcf66", "best_bid": "0.32", "best_ask": "0.38"}], "timestamp": "1769384062337", "event_type": "price_change"}}
{"_local_timestamp": "2026-01-25T23:34:22.863932+00:00", "data": {"market": "0xaeb02ced23cf66b235fb864ed82bdf7f7144c38cb0c7466e5f6c255a5c6015cc", "price_changes": [{"asset_id": "38866550321267038434460376745002272171027672578638559578882849128491520813825", "price": "0.016", "size": "13.1", "side": "SELL", "hash": "08e77e81df3c54e3410e6419cceed1619612f270", "best_bid": "0.002", "best_ask": "0.015"}, {"asset_id": "16066315103031518578542990703395510559372655158819085950817958432162905570385", "price": "0.984", "size": "13.1", "side": "BUY", "hash": "218e18d4355ab69ced49c3e9ca4a25ae545c0426", "best_bid": "0.985", "best_ask": "0.998"}], "timestamp": "1769384062642", "event_type": "price_change"}}
{"_local_timestamp": "2026-01-25T23:34:22.864396+00:00", "data": {"market": "0xaeb02ced23cf66b235fb864ed82bdf7f7144c38cb0c7466e5f6c255a5c6015cc", "price_changes": [{"asset_id": "38866550321267038434460376745002272171027672578638559578882849128491520813825", "price": "0.018", "size": "0", "side": "SELL", "hash": "08e77e81df3c54e3410e6419cceed1619612f270", "best_bid": "0.002", "best_ask": "0.015"}, {"asset_id": "16066315103031518578542990703395510559372655158819085950817958432162905570385", "price": "0.982", "size": "0", "side": "BUY", "hash": "218e18d4355ab69ced49c3e9ca4a25ae545c0426", "best_bid": "0.985", "best_ask": "0.998"}], "timestamp": "1769384062642", "event_type": "price_change"}}
{"_local_timestamp": "2026-01-25T23:34:22.898194+00:00", "data": {"market": "0x242266c50482ad4f243610f7546b60089eadc1d81d4ef408c787f67aa3ef5e7c", "price_changes": [{"asset_id": "96533933355712544390418613060156510030240147080751769428940162257378106436404", "price": "0.14", "size": "50", "side": "BUY", "hash": "7d59a3fe1b7840f621169f2c565ff609afe6c6f0", "best_bid": "0.45", "best_ask": "0.49"}, {"asset_id": "28263250326920700075422198100613476697802143744104502510886484761449393244656", "price": "0.86", "size": "50", "side": "SELL", "hash": "6f006435223e9e9c92328c644fbbf32692086daa", "best_bid": "0.51", "best_ask": "0.55"}], "timestamp": "1769384062655", "event_type": "price_change"}}
{"_local_timestamp": "2026-01-25T23:34:22.899322+00:00", "data": {"market": "0x27d685bdad61bf2f35948bcff8ddf673c14b72a6f4e9cf1a9d867be231f6a610", "price_changes": [{"asset_id": "32476227489805089000687418984234668312982619103362138837681249693289694597075", "price": "0.08", "size": "100", "side": "BUY", "hash": "20e382688612599b63baddc0bacb19445d1f258b", "best_bid": "0.62", "best_ask": "0.68"}, {"asset_id": "82614941921461618729202933946512372479181705578801351216657431603405116134694", "price": "0.92", "size": "100", "side": "SELL", "hash": "a34d89cb3d982ad7009d2ce93f9986e120acc70e", "best_bid": "0.32", "best_ask": "0.38"}], "timestamp": "1769384062655", "event_type": "price_change"}}
{"_local_timestamp": "2026-01-25T23:34:22.899688+00:00", "data": {"market": "0xcf18b8f0901452013dcdf957badd6bfb71a9935c6dd9dd2566dc5bb7f795c1a0", "price_changes": [{"asset_id": "86867607300025136841054177922135303037165603316339117668930743822611084804074", "price": "0.03", "size": "100", "side": "BUY", "hash": "6f1760b1e584b3a1f5dfb7c60f9f5036c7fcfc62", "best_bid": "0.37", "best_ask": "0.41"}, {"asset_id": "13301686528282766867573623232056946130992514687837926123264639755941579360230", "price": "0.97", "size": "100", "side": "SELL", "hash": "d05b053370fbe5f157c0f1eef9bf6951c6d58f84", "best_bid": "0.59", "best_ask": "0.63"}], "timestamp": "1769384062655", "event_type": "price_change"}}
{"_local_timestamp": "2026-01-25T23:34:22.905285+00:00", "data": {"market": "0x54b69275ee145425f1a0dce69faef15f729f1ab3ec41bc2996a6c6c70e8aec0b", "price_changes": [{"asset_id": "44494068166094207162801090520618289188991411103177309101619626920967990930514", "price": "0.14", "size": "50", "side": "BUY", "hash": "6cdf742169693a92437494567c3683a0ad4b5680", "best_bid": "0.49", "best_ask": "0.54"}, {"asset_id": "106447080412815954453539138762045278580988736678171840293222199861758175727534", "price": "0.86", "size": "50", "side": "SELL", "hash": "80a0f4e1ab07c4494b9f94b37d353a4fbe67e2be", "best_bid": "0.46", "best_ask": "0.51"}], "timestamp": "1769384062655", "event_type": "price_change"}}
{"_local_timestamp": "2026-01-25T23:34:22.905999+00:00", "data": {"market": "0x54b69275ee145425f1a0dce69faef15f729f1ab3ec41bc2996a6c6c70e8aec0b", "price_changes": [{"asset_id": "106447080412815954453539138762045278580988736678171840293222199861758175727534", "price": "0.14", "size": "50", "side": "BUY", "hash": "19f57b84eb0ac7515bac5a750b4b09dc081ed0fe", "best_bid": "0.46", "best_ask": "0.51"}, {"asset_id": "44494068166094207162801090520618289188991411103177309101619626920967990930514", "price": "0.86", "size": "50", "side": "SELL", "hash": "cb8b090105aa29984483884223012c53bfa874a9", "best_bid": "0.49", "best_ask": "0.54"}], "timestamp": "1769384062657", "event_type": "price_change"}}
{"_local_timestamp": "2026-01-25T23:34:23.134236+00:00", "data": {"market": "0xaeb02ced23cf66b235fb864ed82bdf7f7144c38cb0c7466e5f6c255a5c6015cc", "price_changes": [{"asset_id": "38866550321267038434460376745002272171027672578638559578882849128491520813825", "price": "0.014", "size": "13.11", "side": "SELL", "hash": "fa284b6cbf0f59a1359c58fa7a0c866db012f500", "best_bid": "0.002", "best_ask": "0.014"}, {"asset_id": "16066315103031518578542990703395510559372655158819085950817958432162905570385", "price": "0.986", "size": "13.11", "side": "BUY", "hash": "18a0b7f15beea21d590616f5ca176815a599cfda", "best_bid": "0.986", "best_ask": "0.998"}], "timestamp": "1769384062901", "event_type": "price_change"}}
{"_local_timestamp": "2026-01-25T23:34:23.134738+00:00", "data": {"market": "0xaeb02ced23cf66b235fb864ed82bdf7f7144c38cb0c7466e5f6c255a5c6015cc", "price_changes": [{"asset_id": "38866550321267038434460376745002272171027672578638559578882849128491520813825", "price": "0.014", "size": "26.22", "side": "SELL", "hash": "83ebcc461e4ab75f489afabf2a107e174e1ef576", "best_bid": "0.002", "best_ask": "0.014"}, {"asset_id": "16066315103031518578542990703395510559372655158819085950817958432162905570385", "price": "0.986", "size": "26.22", "side": "BUY", "hash": "1666d2f94732316950af6828e567f08bd8cb5956", "best_bid": "0.986", "best_ask": "0.998"}], "timestamp": "1769384062901", "event_type": "price_change"}}
{"_local_timestamp": "2026-01-25T23:34:23.522263+00:00", "data": {"market": "0xaeb02ced23cf66b235fb864ed82bdf7f7144c38cb0c7466e5f6c255a5c6015cc", "price_changes": [{"asset_id": "38866550321267038434460376745002272171027672578638559578882849128491520813825", "price": "0.015", "size": "0", "side": "SELL", "hash": "8a46c2a4da2328a55a65bad872a93111d00b77ad", "best_bid": "0.002", "best_ask": "0.014"}, {"asset_id": "16066315103031518578542990703395510559372655158819085950817958432162905570385", "price": "0.985", "size": "0", "side": "BUY", "hash": "195a90f172ff25a612b1e310e5f9c62cbe349ecb", "best_bid": "0.986", "best_ask": "0.998"}], "timestamp": "1769384063298", "event_type": "price_change"}}
{"_local_timestamp": "2026-01-25T23:34:23.550987+00:00", "data": {"market": "0xaeb02ced23cf66b235fb864ed82bdf7f7144c38cb0c7466e5f6c255a5c6015cc", "price_changes": [{"asset_id": "38866550321267038434460376745002272171027672578638559578882849128491520813825", "price": "0.014", "size": "50.91", "side": "SELL", "hash": "096109ab2ddad9c7d7964efcc30f106e6cdbc93d", "best_bid": "0.002", "best_ask": "0.014"}, {"asset_id": "16066315103031518578542990703395510559372655158819085950817958432162905570385", "price": "0.986", "size": "50.91", "side": "BUY", "hash": "ea3ddf37bd6f4ce690d19be56f8c435fcbea4d72", "best_bid": "0.986", "best_ask": "0.998"}], "timestamp": "1769384063327", "event_type": "price_change"}}
{"_local_timestamp": "2026-01-25T23:34:24.113186+00:00", "data": {"market": "0x27d685bdad61bf2f35948bcff8ddf673c14b72a6f4e9cf1a9d867be231f6a610", "price_changes": [{"asset_id": "82614941921461618729202933946512372479181705578801351216657431603405116134694", "price": "0.03", "size": "7.03", "side": "BUY", "hash": "c98fc8de742c73e5792a7dfb5c4c58cac773b66f", "best_bid": "0.32", "best_ask": "0.38"}, {"asset_id": "32476227489805089000687418984234668312982619103362138837681249693289694597075", "price": "0.97", "size": "7.03", "side": "SELL", "hash": "adfc83ebf19acef263faf01fef1b0f24584f7ca9", "best_bid": "0.62", "best_ask": "0.68"}], "timestamp": "1769384063887", "event_type": "price_change"}}
{"_local_timestamp": "2026-01-25T23:34:24.379805+00:00", "data": {"market": "0x27d685bdad61bf2f35948bcff8ddf673c14b72a6f4e9cf1a9d867be231f6a610", "price_changes": [{"asset_id": "82614941921461618729202933946512372479181705578801351216657431603405116134694", "price": "0.02", "size": "11.08", "side": "BUY", "hash": "a8af7e5cb0eb20d88782fb66b5f5e80179779b58", "best_bid": "0.32", "best_ask": "0.38"}, {"asset_id": "32476227489805089000687418984234668312982619103362138837681249693289694597075", "price": "0.98", "size": "11.08", "side": "SELL", "hash": "586c0fa97127b5920b719c710730be1c7cd5b1df", "best_bid": "0.62", "best_ask": "0.68"}], "timestamp": "1769384064126", "event_type": "price_change"}}
{"_local_timestamp": "2026-01-25T23:34:24.380430+00:00", "data": {"market": "0x27d685bdad61bf2f35948bcff8ddf673c14b72a6f4e9cf1a9d867be231f6a610", "price_changes": [{"asset_id": "82614941921461618729202933946512372479181705578801351216657431603405116134694", "price": "0.02", "size": "22.16", "side": "BUY", "hash": "8716e92b3fd9e113ff811a87d8fbc619bcbdb76d", "best_bid": "0.32", "best_ask": "0.38"}, {"asset_id": "32476227489805089000687418984234668312982619103362138837681249693289694597075", "price": "0.98", "size": "22.16", "side": "SELL", "hash": "b3d0b9d9b622f283a86b6b64d764436d0e5f28a9", "best_bid": "0.62", "best_ask": "0.68"}], "timestamp": "1769384064127", "event_type": "price_change"}}
{"_local_timestamp": "2026-01-25T23:34:24.380772+00:00", "data": {"market": "0x27d685bdad61bf2f35948bcff8ddf673c14b72a6f4e9cf1a9d867be231f6a610", "price_changes": [{"asset_id": "82614941921461618729202933946512372479181705578801351216657431603405116134694", "price": "0.01", "size": "71.18", "side": "BUY", "hash": "db376ae5ee55d80463952187bf54bb4882b27faa", "best_bid": "0.32", "best_ask": "0.38"}, {"asset_id": "32476227489805089000687418984234668312982619103362138837681249693289694597075", "price": "0.99", "size": "71.18", "side": "SELL", "hash": "05dc0759150f9949fb814fb1b7bbb3d64532ee3d", "best_bid": "0.62", "best_ask": "0.68"}], "timestamp": "1769384064127", "event_type": "price_change"}}
{"_local_timestamp": "2026-01-25T23:34:24.381087+00:00", "data": {"market": "0x27d685bdad61bf2f35948bcff8ddf673c14b72a6f4e9cf1a9d867be231f6a610", "price_changes": [{"asset_id": "82614941921461618729202933946512372479181705578801351216657431603405116134694", "price": "0.01", "size": "84.57", "side": "BUY", "hash": "bdc69b4385c3a58d3402315db91be4a65cc3f7cf", "best_bid": "0.32", "best_ask": "0.38"}, {"asset_id": "32476227489805089000687418984234668312982619103362138837681249693289694597075", "price": "0.99", "size": "84.57", "side": "SELL", "hash": "d4daa00230c6503d641810e522cbb9d47dc3ee46", "best_bid": "0.62", "best_ask": "0.68"}], "timestamp": "1769384064128", "event_type": "price_change"}}
{"_local_timestamp": "2026-01-25T23:34:24.992455+00:00", "data": {"market": "0x1c5bd9f56545c13743da28ddec8e45c6bea8a01ac7e166dce4286afd32b65a62", "price_changes": [{"asset_id": "53348317672088212419127100072810163057811272329172845337073296220682545739487", "price": "0.01", "size": "74.9", "side": "BUY", "hash": "e23dea2388c8e675ac851bab9613d92c1128059f", "best_bid": "0.05", "best_ask": "0.93"}, {"asset_id": "100472786165319671267181139302646376200338928621290031353672051075785849864574", "price": "0.99", "size": "74.9", "side": "SELL", "hash": "fae156f095680029359c89b0a3b0e6f405bf02c3", "best_bid": "0.07", "best_ask": "0.95"}], "timestamp": "1769384064743", "event_type": "price_change"}}
{"_local_timestamp": "2026-01-25T23:34:25.338728+00:00", "data": {"market": "0x6ac594337fbd762ec04471e8d65806ff9ff78c33ed9dca4826c7bd2969475251", "price_changes": [{"asset_id": "79880305123726971124937075515339490140944001374542290672889526459108541617627", "price": "0.51", "size": "392", "side": "BUY", "hash": "11f9a262e53663d940ff7409d1aeb6580d01329e", "best_bid": "0.81", "best_ask": "0.86"}, {"asset_id": "115162358394175336212249289650926294268751651827332730207583087521345129280038", "price": "0.49", "size": "392", "side": "SELL", "hash": "d8959ef1bb03e51b6d2023a231c9fd3e4be2ad09", "best_bid": "0.14", "best_ask": "0.19"}], "timestamp": "1769384064802", "event_type": "price_change"}}
{"_local_timestamp": "2026-01-25T23:34:25.340614+00:00", "data": {"market": "0xcf18b8f0901452013dcdf957badd6bfb71a9935c6dd9dd2566dc5bb7f795c1a0", "price_changes": [{"asset_id": "13301686528282766867573623232056946130992514687837926123264639755941579360230", "price": "0.28", "size": "714", "side": "BUY", "hash": "bc845b03114c6e72e855960550e2ff51a8a87f78", "best_bid": "0.59", "best_ask": "0.63"}, {"asset_id": "86867607300025136841054177922135303037165603316339117668930743822611084804074", "price": "0.72", "size": "714", "side": "SELL", "hash": "de2ad300a8f532d7fbf1fc8915efaa915a741f02", "best_bid": "0.37", "best_ask": "0.41"}], "timestamp": "1769384064802", "event_type": "price_change"}}
{"_local_timestamp": "2026-01-25T23:34:25.342765+00:00", "data": {"market": "0x54b69275ee145425f1a0dce69faef15f729f1ab3ec41bc2996a6c6c70e8aec0b", "price_changes": [{"asset_id": "106447080412815954453539138762045278580988736678171840293222199861758175727534", "price": "0.16", "size": "1250", "side": "BUY", "hash": "b78446db0edd07793d7cf4ee7608c3c2922fbddd", "best_bid": "0.46", "best_ask": "0.51"}, {"asset_id": "44494068166094207162801090520618289188991411103177309101619626920967990930514", "price": "0.84", "size": "1250", "side": "SELL", "hash": "95c206cfc2ffcbea75e6b7b87221facd1a97a825", "best_bid": "0.49", "best_ask": "0.54"}], "timestamp": "1769384064802", "event_type": "price_change"}}
{"_local_timestamp": "2026-01-25T23:34:25.343444+00:00", "data": {"market": "0x7573b38aa3d3d387be05d7e2b3fa5c397c6cbf1fbfbb5ccbe1d82816b901e9d1", "price_changes": [{"asset_id": "45963563720386640986457133827320203891928335132800978095470889439601833791792", "price": "0.4", "size": "500", "side": "BUY", "hash": "047326df7f8d8595dfe25f0056221be83e4a0e95", "best_bid": "0.54", "best_ask": "0.55"}, {"asset_id": "47900911198961041897125947140815317810676260067603694036981412378636602096971", "price": "0.6", "size": "500", "side": "SELL", "hash": "4a385b1ef750d64dfc3af049cf438170bc4ced42", "best_bid": "0.45", "best_ask": "0.46"}], "timestamp": "1769384064802", "event_type": "price_change"}}
{"_local_timestamp": "2026-01-25T23:34:25.344761+00:00", "data": {"market": "0x6e5e9c218d780a8ff8b516cae97604958f7323ffd75b525d810fb804e727ad78", "price_changes": [{"asset_id": "4929915665740215533077513370523570724508699505795913150073424458746805119832", "price": "0.51", "size": "392", "side": "BUY", "hash": "2a9ef976a773e3b3227bb787fdee06a15facd5a7", "best_bid": "0.78", "best_ask": "0.79"}, {"asset_id": "66190026636022120219272454910747143264277679901831317594304438527297253363875", "price": "0.49", "size": "392", "side": "SELL", "hash": "17ac6a4138a1ea6f0ab0b23a357ef9181eb38258", "best_bid": "0.21", "best_ask": "0.22"}], "timestamp": "1769384064803", "event_type": "price_change"}}
{"_local_timestamp": "2026-01-25T23:34:25.345507+00:00", "data": {"market": "0xdd3915ab9de231a4f8d1b6989b9d28c81a39d3372fc2f5e5d5e09c5c36bd15e0", "price_changes": [{"asset_id": "73772444484179123398639028358181122166565249885455240318019005512648163832892", "price": "0.05", "size": "4000", "side": "BUY", "hash": "dbbe6a3d3b0aa1b3e74ed6a9cda3b1d9861c45bf", "best_bid": "0.32", "best_ask": "0.34"}, {"asset_id": "64912974742020396457447321385468313243213302286888804044150787878568707049629", "price": "0.95", "size": "4000", "side": "SELL", "hash": "b0b2e892a04e6c953162d93cb2c8d35ad5975d26", "best_bid": "0.66", "best_ask": "0.68"}], "timestamp": "1769384064803", "event_type": "price_change"}}
{"_local_timestamp": "2026-01-25T23:34:25.346451+00:00", "data": {"market": "0x54b69275ee145425f1a0dce69faef15f729f1ab3ec41bc2996a6c6c70e8aec0b", "price_changes": [{"asset_id": "44494068166094207162801090520618289188991411103177309101619626920967990930514", "price": "0.16", "size": "1250", "side": "BUY", "hash": "a66ef7456acc4b3b0eb3fb71eb43f615b79ff5a1", "best_bid": "0.49", "best_ask": "0.54"}, {"asset_id": "106447080412815954453539138762045278580988736678171840293222199861758175727534", "price": "0.84", "size": "1250", "side": "SELL", "hash": "b4c717c335e3eacb9dfa7d11c8cde062ab3f6982", "best_bid": "0.46", "best_ask": "0.51"}], "timestamp": "1769384064803", "event_type": "price_change"}}
{"_local_timestamp": "2026-01-25T23:34:25.346890+00:00", "data": {"market": "0x6ac594337fbd762ec04471e8d65806ff9ff78c33ed9dca4826c7bd2969475251", "price_changes": [{"asset_id": "115162358394175336212249289650926294268751651827332730207583087521345129280038", "price": "0.03", "size": "6666", "side": "BUY", "hash": "d832f33084d53db15e9f96a77d2a34f8077108a3", "best_bid": "0.14", "best_ask": "0.19"}, {"asset_id": "79880305123726971124937075515339490140944001374542290672889526459108541617627", "price": "0.97", "size": "6666", "side": "SELL", "hash": "c17ac026c5758a78ddfb65422f3f434b257f80e5", "best_bid": "0.81", "best_ask": "0.86"}], "timestamp": "1769384064803", "event_type": "price_change"}}
{"_local_timestamp": "2026-01-25T23:34:25.347257+00:00", "data": {"market": "0x7573b38aa3d3d387be05d7e2b3fa5c397c6cbf1fbfbb5ccbe1d82816b901e9d1", "price_changes": [{"asset_id": "47900911198961041897125947140815317810676260067603694036981412378636602096971", "price": "0.33", "size": "606", "side": "BUY", "hash": "eb4877593b48375725326822c34b8257b7e7ba84", "best_bid": "0.45", "best_ask": "0.46"}, {"asset_id": "45963563720386640986457133827320203891928335132800978095470889439601833791792", "price": "0.67", "size": "606", "side": "SELL", "hash": "bda5fa0458084a2f91f2ecce32b73257b772608e", "best_bid": "0.54", "best_ask": "0.55"}], "timestamp": "1769384064803", "event_type": "price_change"}}
{"_local_timestamp": "2026-01-25T23:34:25.347797+00:00", "data": {"market": "0x242266c50482ad4f243610f7546b60089eadc1d81d4ef408c787f67aa3ef5e7c", "price_changes": [{"asset_id": "28263250326920700075422198100613476697802143744104502510886484761449393244656", "price": "0.21", "size": "952", "side": "BUY", "hash": "1023a12809a95d6b63a2bd87d128aa1c4ca2ee1e", "best_bid": "0.51", "best_ask": "0.55"}, {"asset_id": "96533933355712544390418613060156510030240147080751769428940162257378106436404", "price": "0.79", "size": "952", "side": "SELL", "hash": "d1b666c616d305bd97c4a3c408f7b6eafad9d419", "best_bid": "0.45", "best_ask": "0.49"}], "timestamp": "1769384065042", "event_type": "price_change"}}
{"_local_timestamp": "2026-01-25T23:34:25.348184+00:00", "data": {"market": "0x27d685bdad61bf2f35948bcff8ddf673c14b72a6f4e9cf1a9d867be231f6a610", "price_changes": [{"asset_id": "82614941921461618729202933946512372479181705578801351216657431603405116134694", "price": "0.03", "size": "6673.03", "side": "BUY", "hash": "03355f9a26fba8cf42bac4ff17911abb3c43b258", "best_bid": "0.32", "best_ask": "0.38"}, {"asset_id": "32476227489805089000687418984234668312982619103362138837681249693289694597075", "price": "0.97", "size": "6673.03", "side": "SELL", "hash": "d84d4cbc968aafd8537e308e4c9a2c1b8d501a3a", "best_bid": "0.62", "best_ask": "0.68"}], "timestamp": "1769384065042", "event_type": "price_change"}}
{"_local_timestamp": "2026-01-25T23:34:25.348543+00:00", "data": {"market": "0xdd3915ab9de231a4f8d1b6989b9d28c81a39d3372fc2f5e5d5e09c5c36bd15e0", "price_changes": [{"asset_id": "64912974742020396457447321385468313243213302286888804044150787878568707049629", "price": "0.35", "size": "571", "side": "BUY", "hash": "dffc5ab06c6f79dc0919ce01b67092dd4af715b9", "best_bid": "0.66", "best_ask": "0.68"}, {"asset_id": "73772444484179123398639028358181122166565249885455240318019005512648163832892", "price": "0.65", "size": "571", "side": "SELL", "hash": "0f0e8c2d1d5da7a5db77efff904c8ceef4312267", "best_bid": "0.32", "best_ask": "0.34"}], "timestamp": "1769384065042", "event_type": "price_change"}}
{"_local_timestamp": "2026-01-25T23:34:25.348973+00:00", "data": {"market": "0x6e5e9c218d780a8ff8b516cae97604958f7323ffd75b525d810fb804e727ad78", "price_changes": [{"asset_id": "66190026636022120219272454910747143264277679901831317594304438527297253363875", "price": "0.02", "size": "10028.64", "side": "BUY", "hash": "f43143e6f98ae985c85d1e6c1d9a042738ee1f58", "best_bid": "0.21", "best_ask": "0.22"}, {"asset_id": "4929915665740215533077513370523570724508699505795913150073424458746805119832", "price": "0.98", "size": "10028.64", "side": "SELL", "hash": "b8cf2e4e1e3223c399b4beb99c7f8a0cc2c3c835", "best_bid": "0.78", "best_ask": "0.79"}], "timestamp": "1769384065042", "event_type": "price_change"}}
{"_local_timestamp": "2026-01-25T23:34:25.349349+00:00", "data": {"market": "0xcf18b8f0901452013dcdf957badd6bfb71a9935c6dd9dd2566dc5bb7f795c1a0", "price_changes": [{"asset_id": "86867607300025136841054177922135303037165603316339117668930743822611084804074", "price": "0.05", "size": "4000", "side": "BUY", "hash": "cfac7662da1b5b7a44315e19c7403ff0a27dd159", "best_bid": "0.37", "best_ask": "0.41"}, {"asset_id": "13301686528282766867573623232056946130992514687837926123264639755941579360230", "price": "0.95", "size": "4000", "side": "SELL", "hash": "f02ad576841aba05548ee3fbb0b564fe40144472", "best_bid": "0.59", "best_ask": "0.63"}], "timestamp": "1769384065042", "event_type": "price_change"}}
{"_local_timestamp": "2026-01-25T23:34:25.349718+00:00", "data": {"market": "0xaeb02ced23cf66b235fb864ed82bdf7f7144c38cb0c7466e5f6c255a5c6015cc", "price_changes": [{"asset_id": "16066315103031518578542990703395510559372655158819085950817958432162905570385", "price": "0.015", "size": "13333", "side": "BUY", "hash": "3a38f54e02e4c6c3099455b74d2883ec050aac41", "best_bid": "0.986", "best_ask": "0.998"}, {"asset_id": "38866550321267038434460376745002272171027672578638559578882849128491520813825", "price": "0.985", "size": "13333", "side": "SELL", "hash": "64b674084622380a59ca4c8023b3f21353a2b338", "best_bid": "0.002", "best_ask": "0.014"}], "timestamp": "1769384065042", "event_type": "price_change"}}
{"_local_timestamp": "2026-01-25T23:34:25.350067+00:00", "data": {"market": "0x242266c50482ad4f243610f7546b60089eadc1d81d4ef408c787f67aa3ef5e7c", "price_changes": [{"asset_id": "96533933355712544390418613060156510030240147080751769428940162257378106436404", "price": "0.16", "size": "1250", "side": "BUY", "hash": "aff86f14b6e43b43538fd31ca17764f229ea6bb5", "best_bid": "0.45", "best_ask": "0.49"}, {"asset_id": "28263250326920700075422198100613476697802143744104502510886484761449393244656", "price": "0.84", "size": "1250", "side": "SELL", "hash": "0b9084af0bc343282a670b51fa40a3f5eca73d7f", "best_bid": "0.51", "best_ask": "0.55"}], "timestamp": "1769384065043", "event_type": "price_change"}}
{"_local_timestamp": "2026-01-25T23:34:25.350453+00:00", "data": {"market": "0x27d685bdad61bf2f35948bcff8ddf673c14b72a6f4e9cf1a9d867be231f6a610", "price_changes": [{"asset_id": "32476227489805089000687418984234668312982619103362138837681249693289694597075", "price": "0.21", "size": "952", "side": "BUY", "hash": "a3ca5817e0f5c736e2272da677d5aaf3bb5ce453", "best_bid": "0.62", "best_ask": "0.68"}, {"asset_id": "82614941921461618729202933946512372479181705578801351216657431603405116134694", "price": "0.79", "size": "952", "side": "SELL", "hash": "30f9611b51c7f2e79b739a29e331e07b610ce3d1", "best_bid": "0.32", "best_ask": "0.38"}], "timestamp": "1769384065043", "event_type": "price_change"}}
{"_local_timestamp": "2026-01-25T23:34:25.409618+00:00", "data": {"market": "0xaeb02ced23cf66b235fb864ed82bdf7f7144c38cb0c7466e5f6c255a5c6015cc", "price_changes": [{"asset_id": "38866550321267038434460376745002272171027672578638559578882849128491520813825", "price": "0.014", "size": "37.8", "side": "SELL", "hash": "074239ded26f13be9238e323995cacba327723ed", "best_bid": "0.002", "best_ask": "0.014"}, {"asset_id": "16066315103031518578542990703395510559372655158819085950817958432162905570385", "price": "0.986", "size": "37.8", "side": "BUY", "hash": "1ac9a80c5b5ab5c6a94960a45d29e3e3354183c2", "best_bid": "0.986", "best_ask": "0.998"}], "timestamp": "1769384065170", "event_type": "price_change"}}
{"_local_timestamp": "2026-01-25T23:34:25.412307+00:00", "data": {"market": "0xaeb02ced23cf66b235fb864ed82bdf7f7144c38cb0c7466e5f6c255a5c6015cc", "price_changes": [{"asset_id": "38866550321267038434460376745002272171027672578638559578882849128491520813825", "price": "0.016", "size": "0", "side": "SELL", "hash": "074239ded26f13be9238e323995cacba327723ed", "best_bid": "0.002", "best_ask": "0.014"}, {"asset_id": "16066315103031518578542990703395510559372655158819085950817958432162905570385", "price": "0.984", "size": "0", "side": "BUY", "hash": "1ac9a80c5b5ab5c6a94960a45d29e3e3354183c2", "best_bid": "0.986", "best_ask": "0.998"}], "timestamp": "1769384065170", "event_type": "price_change"}}
{"_local_timestamp": "2026-01-25T23:34:25.740204+00:00", "data": {"market": "0xaeb02ced23cf66b235fb864ed82bdf7f7144c38cb0c7466e5f6c255a5c6015cc", "price_changes": [{"asset_id": "38866550321267038434460376745002272171027672578638559578882849128491520813825", "price": "0.013", "size": "13.1", "side": "SELL", "hash": "9715dad018747bd4fb0b120e2e01d7e1a599a9bf", "best_bid": "0.002", "best_ask": "0.013"}, {"asset_id": "16066315103031518578542990703395510559372655158819085950817958432162905570385", "price": "0.987", "size": "13.1", "side": "BUY", "hash": "06640c3bd9713d50f9a003c1636eec531238caf7", "best_bid": "0.987", "best_ask": "0.998"}], "timestamp": "1769384065501", "event_type": "price_change"}}
{"_local_timestamp": "2026-01-25T23:34:25.741490+00:00", "data": {"market": "0xaeb02ced23cf66b235fb864ed82bdf7f7144c38cb0c7466e5f6c255a5c6015cc", "price_changes": [{"asset_id": "38866550321267038434460376745002272171027672578638559578882849128491520813825", "price": "0.013", "size": "26.2", "side": "SELL", "hash": "1cc4e4cbd7be9f4cc345046b3c40a587371cbbb8", "best_bid": "0.002", "best_ask": "0.013"}, {"asset_id": "16066315103031518578542990703395510559372655158819085950817958432162905570385", "price": "0.987", "size": "26.2", "side": "BUY", "hash": "4637d21e47cbc5e0f264a379fcbc72de8921a4e0", "best_bid": "0.987", "best_ask": "0.998"}], "timestamp": "1769384065501", "event_type": "price_change"}}
{"_local_timestamp": "2026-01-25T23:34:25.846008+00:00", "data": {"market": "0x27d685bdad61bf2f35948bcff8ddf673c14b72a6f4e9cf1a9d867be231f6a610", "price_changes": [{"asset_id": "82614941921461618729202933946512372479181705578801351216657431603405116134694", "price": "0.01", "size": "57.79", "side": "BUY", "hash": "7caf7d69612e811e46c5d4e175053b0bab00db8d", "best_bid": "0.32", "best_ask": "0.38"}, {"asset_id": "32476227489805089000687418984234668312982619103362138837681249693289694597075", "price": "0.99", "size": "57.79", "side": "SELL", "hash": "4b1e3a58dfad2e601688d705141f5048d7eb2830", "best_bid": "0.62", "best_ask": "0.68"}], "timestamp": "1769384065608", "event_type": "price_change"}}
{"_local_timestamp": "2026-01-25T23:34:25.848002+00:00", "data": {"market": "0x27d685bdad61bf2f35948bcff8ddf673c14b72a6f4e9cf1a9d867be231f6a610", "price_changes": [{"asset_id": "82614941921461618729202933946512372479181705578801351216657431603405116134694", "price": "0.02", "size": "11.08", "side": "BUY", "hash": "7caf7d69612e811e46c5d4e175053b0bab00db8d", "best_bid": "0.32", "best_ask": "0.38"}, {"asset_id": "32476227489805089000687418984234668312982619103362138837681249693289694597075", "price": "0.98", "size": "11.08", "side": "SELL", "hash": "4b1e3a58dfad2e601688d705141f5048d7eb2830", "best_bid": "0.62", "best_ask": "0.68"}], "timestamp": "1769384065608", "event_type": "price_change"}}
{"_local_timestamp": "2026-01-25T23:34:25.849075+00:00", "data": {"market": "0x27d685bdad61bf2f35948bcff8ddf673c14b72a6f4e9cf1a9d867be231f6a610", "price_changes": [{"asset_id": "82614941921461618729202933946512372479181705578801351216657431603405116134694", "price": "0.03", "size": "6666", "side": "BUY", "hash": "7caf7d69612e811e46c5d4e175053b0bab00db8d", "best_bid": "0.32", "best_ask": "0.38"}, {"asset_id": "32476227489805089000687418984234668312982619103362138837681249693289694597075", "price": "0.97", "size": "6666", "side": "SELL", "hash": "4b1e3a58dfad2e601688d705141f5048d7eb2830", "best_bid": "0.62", "best_ask": "0.68"}], "timestamp": "1769384065608", "event_type": "price_change"}}
{"_local_timestamp": "2026-01-25T23:34:25.975590+00:00", "data": {"market": "0xaeb02ced23cf66b235fb864ed82bdf7f7144c38cb0c7466e5f6c255a5c6015cc", "price_changes": [{"asset_id": "38866550321267038434460376745002272171027672578638559578882849128491520813825", "price": "0.014", "size": "13.11", "side": "SELL", "hash": "62493bf39f93e4096f5e83f9101de89e89fc5777", "best_bid": "0.002", "best_ask": "0.013"}, {"asset_id": "16066315103031518578542990703395510559372655158819085950817958432162905570385", "price": "0.986", "size": "13.11", "side": "BUY", "hash": "21e9a6cb8e33edc6c557f187c871a2c9fd83f9de", "best_bid": "0.987", "best_ask": "0.998"}], "timestamp": "1769384065728", "event_type": "price_change"}}
{"_local_timestamp": "2026-01-25T23:34:26.021596+00:00", "data": {"market": "0xaeb02ced23cf66b235fb864ed82bdf7f7144c38cb0c7466e5f6c255a5c6015cc", "price_changes": [{"asset_id": "38866550321267038434460376745002272171027672578638559578882849128491520813825", "price": "0.012", "size": "24.69", "side": "SELL", "hash": "0d11f884bbbc6a2523957a1684e7d4402d60a0e2", "best_bid": "0.002", "best_ask": "0.012"}, {"asset_id": "16066315103031518578542990703395510559372655158819085950817958432162905570385", "price": "0.988", "size": "24.69", "side": "BUY", "hash": "d3960112a9aed55579484aedd4b2695bf80723ed", "best_bid": "0.988", "best_ask": "0.998"}], "timestamp": "1769384065759", "event_type": "price_change"}}
{"_local_timestamp": "2026-01-25T23:34:26.188219+00:00", "data": {"market": "0x27d685bdad61bf2f35948bcff8ddf673c14b72a6f4e9cf1a9d867be231f6a610", "price_changes": [{"asset_id": "82614941921461618729202933946512372479181705578801351216657431603405116134694", "price": "0.04", "size": "8.75", "side": "BUY", "hash": "ead7433787593549c2b7227ff2e293be7c0184ab", "best_bid": "0.32", "best_ask": "0.38"}, {"asset_id": "32476227489805089000687418984234668312982619103362138837681249693289694597075", "price": "0.96", "size": "8.75", "side": "SELL", "hash": "0fce60d817245841878e48b64c512281eba5ccd5", "best_bid": "0.62", "best_ask": "0.68"}], "timestamp": "1769384065958", "event_type": "price_change"}}
{"_local_timestamp": "2026-01-25T23:34:26.189454+00:00", "data": {"market": "0x27d685bdad61bf2f35948bcff8ddf673c14b72a6f4e9cf1a9d867be231f6a610", "price_changes": [{"asset_id": "82614941921461618729202933946512372479181705578801351216657431603405116134694", "price": "0.04", "size": "17.5", "side": "BUY", "hash": "362486c1c464749691a3a0c39db83ae7879f5824", "best_bid": "0.32", "best_ask": "0.38"}, {"asset_id": "32476227489805089000687418984234668312982619103362138837681249693289694597075", "price": "0.96", "size": "17.5", "side": "SELL", "hash": "c8bbb5d42f13846dd715b817291e0f4c6da85cb3", "best_bid": "0.62", "best_ask": "0.68"}], "timestamp": "1769384065960", "event_type": "price_change"}}
{"_local_timestamp": "2026-01-25T23:34:27.534786+00:00", "data": {"market": "0x27d685bdad61bf2f35948bcff8ddf673c14b72a6f4e9cf1a9d867be231f6a610", "price_changes": [{"asset_id": "82614941921461618729202933946512372479181705578801351216657431603405116134694", "price": "0.01", "size": "50", "side": "BUY", "hash": "e9a83e281f7f346b708f93451adc8e2097cbf0f5", "best_bid": "0.32", "best_ask": "0.38"}, {"asset_id": "32476227489805089000687418984234668312982619103362138837681249693289694597075", "price": "0.99", "size": "50", "side": "SELL", "hash": "0b4338aaed2da1c43f57b7be095d7a58e61265c3", "best_bid": "0.62", "best_ask": "0.68"}], "timestamp": "1769384067305", "event_type": "price_change"}}
{"_local_timestamp": "2026-01-25T23:34:27.536141+00:00", "data": {"market": "0x27d685bdad61bf2f35948bcff8ddf673c14b72a6f4e9cf1a9d867be231f6a610", "price_changes": [{"asset_id": "82614941921461618729202933946512372479181705578801351216657431603405116134694", "price": "0.02", "size": "0", "side": "BUY", "hash": "e9a83e281f7f346b708f93451adc8e2097cbf0f5", "best_bid": "0.32", "best_ask": "0.38"}, {"asset_id": "32476227489805089000687418984234668312982619103362138837681249693289694597075", "price": "0.98", "size": "0", "side": "SELL", "hash": "0b4338aaed2da1c43f57b7be095d7a58e61265c3", "best_bid": "0.62", "best_ask": "0.68"}], "timestamp": "1769384067305", "event_type": "price_change"}}
{"_local_timestamp": "2026-01-25T23:34:27.536927+00:00", "data": {"market": "0xaeb02ced23cf66b235fb864ed82bdf7f7144c38cb0c7466e5f6c255a5c6015cc", "price_changes": [{"asset_id": "38866550321267038434460376745002272171027672578638559578882849128491520813825", "price": "0.013", "size": "13.1", "side": "SELL", "hash": "490899aac90720e97361434e748e7aaaeb0aad0a", "best_bid": "0.002", "best_ask": "0.012"}, {"asset_id": "16066315103031518578542990703395510559372655158819085950817958432162905570385", "price": "0.987", "size": "13.1", "side": "BUY", "hash": "da3dbdf8f47a335dbaa55fc38acb5a12980b0eed", "best_bid": "0.988", "best_ask": "0.998"}], "timestamp": "1769384067305", "event_type": "price_change"}}
{"_local_timestamp": "2026-01-25T23:34:27.537423+00:00", "data": {"market": "0xaeb02ced23cf66b235fb864ed82bdf7f7144c38cb0c7466e5f6c255a5c6015cc", "price_changes": [{"asset_id": "38866550321267038434460376745002272171027672578638559578882849128491520813825", "price": "0.014", "size": "0", "side": "SELL", "hash": "490899aac90720e97361434e748e7aaaeb0aad0a", "best_bid": "0.002", "best_ask": "0.012"}, {"asset_id": "16066315103031518578542990703395510559372655158819085950817958432162905570385", "price": "0.986", "size": "0", "side": "BUY", "hash": "da3dbdf8f47a335dbaa55fc38acb5a12980b0eed", "best_bid": "0.988", "best_ask": "0.998"}], "timestamp": "1769384067305", "event_type": "price_change"}}
{"_local_timestamp": "2026-01-25T23:34:28.051695+00:00", "data": {"market": "0x27d685bdad61bf2f35948bcff8ddf673c14b72a6f4e9cf1a9d867be231f6a610", "price_changes": [{"asset_id": "82614941921461618729202933946512372479181705578801351216657431603405116134694", "price": "0.02", "size": "7.49", "side": "BUY", "hash": "470727714be63562f249cea55d294d509ed81f6d", "best_bid": "0.32", "best_ask": "0.38"}, {"asset_id": "32476227489805089000687418984234668312982619103362138837681249693289694597075", "price": "0.98", "size": "7.49", "side": "SELL", "hash": "331d6494dca2321f8ae8ecd61a5a14ffd80f7cda", "best_bid": "0.62", "best_ask": "0.68"}], "timestamp": "1769384067655", "event_type": "price_change"}}
{"_local_timestamp": "2026-01-25T23:34:28.053645+00:00", "data": {"market": "0x27d685bdad61bf2f35948bcff8ddf673c14b72a6f4e9cf1a9d867be231f6a610", "price_changes": [{"asset_id": "82614941921461618729202933946512372479181705578801351216657431603405116134694", "price": "0.02", "size": "14.98", "side": "BUY", "hash": "0c1bbb057354d10d4b32e9e2b268bfc66a7e2df5", "best_bid": "0.32", "best_ask": "0.38"}, {"asset_id": "32476227489805089000687418984234668312982619103362138837681249693289694597075", "price": "0.98", "size": "14.98", "side": "SELL", "hash": "4c70a5d99ae60918fe398772ec7f20066ce81445", "best_bid": "0.62", "best_ask": "0.68"}], "timestamp": "1769384067656", "event_type": "price_change"}}
{"_local_timestamp": "2026-01-25T23:34:28.067526+00:00", "data": {"market": "0xaeb02ced23cf66b235fb864ed82bdf7f7144c38cb0c7466e5f6c255a5c6015cc", "price_changes": [{"asset_id": "38866550321267038434460376745002272171027672578638559578882849128491520813825", "price": "0.011", "size": "13.11", "side": "SELL", "hash": "3437b0ee29cb91d988ac7ca91c5dd84276c9db99", "best_bid": "0.002", "best_ask": "0.011"}, {"asset_id": "16066315103031518578542990703395510559372655158819085950817958432162905570385", "price": "0.989", "size": "13.11", "side": "BUY", "hash": "89ccc0742baf5cbdf71c72063e85e0c4f560d428", "best_bid": "0.989", "best_ask": "0.998"}], "timestamp": "1769384067655", "event_type": "price_change"}}
{"_local_timestamp": "2026-01-25T23:34:28.074374+00:00", "data": {"market": "0xaeb02ced23cf66b235fb864ed82bdf7f7144c38cb0c7466e5f6c255a5c6015cc", "price_changes": [{"asset_id": "38866550321267038434460376745002272171027672578638559578882849128491520813825", "price": "0.011", "size": "26.22", "side": "SELL", "hash": "e1fcdacfdfc32d79da06940a98652c69cef6bdb9", "best_bid": "0.002", "best_ask": "0.011"}, {"asset_id": "16066315103031518578542990703395510559372655158819085950817958432162905570385", "price": "0.989", "size": "26.22", "side": "BUY", "hash": "2c45a79f074b6febbb9a8992c9d8189c4126ac07", "best_bid": "0.989", "best_ask": "0.998"}], "timestamp": "1769384067656", "event_type": "price_change"}}
{"_local_timestamp": "2026-01-25T23:34:28.397776+00:00", "data": {"market": "0x1c5bd9f56545c13743da28ddec8e45c6bea8a01ac7e166dce4286afd32b65a62", "price_changes": [{"asset_id": "53348317672088212419127100072810163057811272329172845337073296220682545739487", "price": "0.01", "size": "68.16", "side": "BUY", "hash": "9813ddd0a10143ee2f831eb1fd32a6c9eaebb242", "best_bid": "0.05", "best_ask": "0.93"}, {"asset_id": "100472786165319671267181139302646376200338928621290031353672051075785849864574", "price": "0.99", "size": "68.16", "side": "SELL", "hash": "71ca2a89bd2b939c1925f0f0111ffef3c5fb11f9", "best_bid": "0.07", "best_ask": "0.95"}], "timestamp": "1769384068158", "event_type": "price_change"}}
{"_local_timestamp": "2026-01-25T23:34:28.410834+00:00", "data": {"market": "0xaeb02ced23cf66b235fb864ed82bdf7f7144c38cb0c7466e5f6c255a5c6015cc", "price_changes": [{"asset_id": "38866550321267038434460376745002272171027672578638559578882849128491520813825", "price": "0.012", "size": "0", "side": "SELL", "hash": "7c164f214e0be2ad6e8b5eff2781e83179d6e695", "best_bid": "0.002", "best_ask": "0.011"}, {"asset_id": "16066315103031518578542990703395510559372655158819085950817958432162905570385", "price": "0.988", "size": "0", "side": "BUY", "hash": "2c8f8a1c127857e6934c8a6733fa5c6dc07a0fcd", "best_bid": "0.989", "best_ask": "0.998"}], "timestamp": "1769384068170", "event_type": "price_change"}}
{"_local_timestamp": "2026-01-25T23:34:28.582975+00:00", "data": {"market": "0xaeb02ced23cf66b235fb864ed82bdf7f7144c38cb0c7466e5f6c255a5c6015cc", "price_changes": [{"asset_id": "38866550321267038434460376745002272171027672578638559578882849128491520813825", "price": "0.011", "size": "50.91", "side": "SELL", "hash": "84a5e8185bba55ed6836fa4f830d33a0f05e0c13", "best_bid": "0.002", "best_ask": "0.011"}, {"asset_id": "16066315103031518578542990703395510559372655158819085950817958432162905570385", "price": "0.989", "size": "50.91", "side": "BUY", "hash": "8a338875d01841314f763d4233e6f61292442fa2", "best_bid": "0.989", "best_ask": "0.998"}], "timestamp": "1769384068207", "event_type": "price_change"}}
{"_local_timestamp": "2026-01-25T23:34:29.013354+00:00", "data": {"market": "0x1c5bd9f56545c13743da28ddec8e45c6bea8a01ac7e166dce4286afd32b65a62", "price_changes": [{"asset_id": "53348317672088212419127100072810163057811272329172845337073296220682545739487", "price": "0.01", "size": "74.9", "side": "BUY", "hash": "42dc9e29c7d19d2373861f9c900b3d381a83b8fe", "best_bid": "0.05", "best_ask": "0.93"}, {"asset_id": "100472786165319671267181139302646376200338928621290031353672051075785849864574", "price": "0.99", "size": "74.9", "side": "SELL", "hash": "c9e5cd189143f34f73d376f3486e58cfa3586ff0", "best_bid": "0.07", "best_ask": "0.95"}], "timestamp": "1769384068418", "event_type": "price_change"}}
{"_local_timestamp": "2026-01-25T23:34:29.014586+00:00", "data": {"market": "0x1c5bd9f56545c13743da28ddec8e45c6bea8a01ac7e166dce4286afd32b65a62", "price_changes": [{"asset_id": "53348317672088212419127100072810163057811272329172845337073296220682545739487", "price": "0.01", "size": "81.64", "side": "BUY", "hash": "c659e04aac263fd1f6d927b43e7c2518d564ce2f", "best_bid": "0.05", "best_ask": "0.93"}, {"asset_id": "100472786165319671267181139302646376200338928621290031353672051075785849864574", "price": "0.99", "size": "81.64", "side": "SELL", "hash": "b138d2e47265dbac09cb6e0e009b817366269621", "best_bid": "0.07", "best_ask": "0.95"}], "timestamp": "1769384068419", "event_type": "price_change"}}
{"_local_timestamp": "2026-01-25T23:34:29.354991+00:00", "data": {"market": "0xdd3915ab9de231a4f8d1b6989b9d28c81a39d3372fc2f5e5d5e09c5c36bd15e0", "price_changes": [{"asset_id": "73772444484179123398639028358181122166565249885455240318019005512648163832892", "price": "0.04", "size": "0", "side": "BUY", "hash": "fdfaaa5f9c6b954ff646f31ca29f6224b3ea9c5c", "best_bid": "0.32", "best_ask": "0.34"}, {"asset_id": "64912974742020396457447321385468313243213302286888804044150787878568707049629", "price": "0.96", "size": "0", "side": "SELL", "hash": "be9652652f7928ed52617c6420cc82604490515d", "best_bid": "0.66", "best_ask": "0.68"}], "timestamp": "1769384069016", "event_type": "price_change"}}
{"_local_timestamp": "2026-01-25T23:34:29.539237+00:00", "data": {"market": "0xdd3915ab9de231a4f8d1b6989b9d28c81a39d3372fc2f5e5d5e09c5c36bd15e0", "price_changes": [{"asset_id": "73772444484179123398639028358181122166565249885455240318019005512648163832892", "price": "0.02", "size": "11.31", "side": "BUY", "hash": "9308ba95d9842edc7e658ad94ef64af4fe4217be", "best_bid": "0.32", "best_ask": "0.34"}, {"asset_id": "64912974742020396457447321385468313243213302286888804044150787878568707049629", "price": "0.98", "size": "11.31", "side": "SELL", "hash": "0455f525bb2883798c7e363b16dfcc903816546f", "best_bid": "0.66", "best_ask": "0.68"}], "timestamp": "1769384069310", "event_type": "price_change"}}
{"_local_timestamp": "2026-01-25T23:34:29.545485+00:00", "data": {"market": "0xdd3915ab9de231a4f8d1b6989b9d28c81a39d3372fc2f5e5d5e09c5c36bd15e0", "price_changes": [{"asset_id": "73772444484179123398639028358181122166565249885455240318019005512648163832892", "price": "0.06", "size": "12.89", "side": "BUY", "hash": "128bc1147b7fc9d2a0982bee2dc34c34549e29df", "best_bid": "0.32", "best_ask": "0.34"}, {"asset_id": "64912974742020396457447321385468313243213302286888804044150787878568707049629", "price": "0.94", "size": "12.89", "side": "SELL", "hash": "b0b45c726c6c92ee4ccf0013e0c369ac01c4d139", "best_bid": "0.66", "best_ask": "0.68"}], "timestamp": "1769384069311", "event_type": "price_change"}}
{"_local_timestamp": "2026-01-25T23:34:30.215618+00:00", "data": {"market": "0xaeb02ced23cf66b235fb864ed82bdf7f7144c38cb0c7466e5f6c255a5c6015cc", "price_changes": [{"asset_id": "38866550321267038434460376745002272171027672578638559578882849128491520813825", "price": "0.011", "size": "37.8", "side": "SELL", "hash": "8c298dd7b2a8e446fb619e7f02d412e70162b77e", "best_bid": "0.002", "best_ask": "0.011"}, {"asset_id": "16066315103031518578542990703395510559372655158819085950817958432162905570385", "price": "0.989", "size": "37.8", "side": "BUY", "hash": "f9dae6522cce06781153766e41d9c3bce1163781", "best_bid": "0.989", "best_ask": "0.998"}], "timestamp": "1769384069867", "event_type": "price_change"}}
{"_local_timestamp": "2026-01-25T23:34:30.218426+00:00", "data": {"market": "0xaeb02ced23cf66b235fb864ed82bdf7f7144c38cb0c7466e5f6c255a5c6015cc", "price_changes": [{"asset_id": "38866550321267038434460376745002272171027672578638559578882849128491520813825", "price": "0.013", "size": "0", "side": "SELL", "hash": "8c298dd7b2a8e446fb619e7f02d412e70162b77e", "best_bid": "0.002", "best_ask": "0.011"}, {"asset_id": "16066315103031518578542990703395510559372655158819085950817958432162905570385", "price": "0.987", "size": "0", "side": "BUY", "hash": "f9dae6522cce06781153766e41d9c3bce1163781", "best_bid": "0.989", "best_ask": "0.998"}], "timestamp": "1769384069867", "event_type": "price_change"}}
{"_local_timestamp": "2026-01-25T23:34:30.577758+00:00", "data": {"market": "0xaeb02ced23cf66b235fb864ed82bdf7f7144c38cb0c7466e5f6c255a5c6015cc", "price_changes": [{"asset_id": "38866550321267038434460376745002272171027672578638559578882849128491520813825", "price": "0.01", "size": "13.1", "side": "SELL", "hash": "bc80a015ebf4d66e4331ce84f14fd2e20d1f4ee0", "best_bid": "0.002", "best_ask": "0.01"}, {"asset_id": "16066315103031518578542990703395510559372655158819085950817958432162905570385", "price": "0.99", "size": "13.1", "side": "BUY", "hash": "8ea0be847f757c07706c0afe61ad951733180944", "best_bid": "0.99", "best_ask": "0.998"}], "timestamp": "1769384070234", "event_type": "price_change"}}
{"_local_timestamp": "2026-01-25T23:34:30.580570+00:00", "data": {"market": "0xaeb02ced23cf66b235fb864ed82bdf7f7144c38cb0c7466e5f6c255a5c6015cc", "price_changes": [{"asset_id": "38866550321267038434460376745002272171027672578638559578882849128491520813825", "price": "0.01", "size": "26.2", "side": "SELL", "hash": "0f2eee52adbff4e45eb492e0477240f19987cc45", "best_bid": "0.002", "best_ask": "0.01"}, {"asset_id": "16066315103031518578542990703395510559372655158819085950817958432162905570385", "price": "0.99", "size": "26.2", "side": "BUY", "hash": "c96c92135103f5c2270d752c4a51eb8714ac0746", "best_bid": "0.99", "best_ask": "0.998"}], "timestamp": "1769384070234", "event_type": "price_change"}}
{"_local_timestamp": "2026-01-25T23:34:30.882680+00:00", "data": {"market": "0xaeb02ced23cf66b235fb864ed82bdf7f7144c38cb0c7466e5f6c255a5c6015cc", "price_changes": [{"asset_id": "38866550321267038434460376745002272171027672578638559578882849128491520813825", "price": "0.011", "size": "13.11", "side": "SELL", "hash": "c07ac541a095e0865046ec5fa83c4b76df3029b8", "best_bid": "0.002", "best_ask": "0.01"}, {"asset_id": "16066315103031518578542990703395510559372655158819085950817958432162905570385", "price": "0.989", "size": "13.11", "side": "BUY", "hash": "32135377642060ec1aefd1a490e4c55cf06f5ecf", "best_bid": "0.99", "best_ask": "0.998"}], "timestamp": "1769384070621", "event_type": "price_change"}}
{"_local_timestamp": "2026-01-25T23:34:30.887696+00:00", "data": {"market": "0xaeb02ced23cf66b235fb864ed82bdf7f7144c38cb0c7466e5f6c255a5c6015cc", "price_changes": [{"asset_id": "38866550321267038434460376745002272171027672578638559578882849128491520813825", "price": "0.021", "size": "30.16", "side": "SELL", "hash": "6cad51a21659f42d76fac5398819bbb33de97e13", "best_bid": "0.002", "best_ask": "0.01"}, {"asset_id": "16066315103031518578542990703395510559372655158819085950817958432162905570385", "price": "0.979", "size": "30.16", "side": "BUY", "hash": "2f55ea7fb849cb990dbb67909dcf46ff63b9525c", "best_bid": "0.99", "best_ask": "0.998"}], "timestamp": "1769384070648", "event_type": "price_change"}}
{"_local_timestamp": "2026-01-25T23:34:30.902038+00:00", "data": {"market": "0x27d685bdad61bf2f35948bcff8ddf673c14b72a6f4e9cf1a9d867be231f6a610", "price_changes": [{"asset_id": "82614941921461618729202933946512372479181705578801351216657431603405116134694", "price": "0.02", "size": "7.49", "side": "BUY", "hash": "67b3dc93719514a77fecc19a7aabfaa966e43744", "best_bid": "0.32", "best_ask": "0.38"}, {"asset_id": "32476227489805089000687418984234668312982619103362138837681249693289694597075", "price": "0.98", "size": "7.49", "side": "SELL", "hash": "8f6a63c69e995654d59817c5f9cbea339152ab59", "best_bid": "0.62", "best_ask": "0.68"}], "timestamp": "1769384070698", "event_type": "price_change"}}
{"_local_timestamp": "2026-01-25T23:34:31.230563+00:00", "data": {"market": "0x242266c50482ad4f243610f7546b60089eadc1d81d4ef408c787f67aa3ef5e7c", "price_changes": [{"asset_id": "28263250326920700075422198100613476697802143744104502510886484761449393244656", "price": "0.21", "size": "0", "side": "BUY", "hash": "cc69c3847540d3ab6013822678ed8f9b8aae4d3f", "best_bid": "0.51", "best_ask": "0.55"}, {"asset_id": "96533933355712544390418613060156510030240147080751769428940162257378106436404", "price": "0.79", "size": "0", "side": "SELL", "hash": "1b71e0d693df9f27233aa260dd5a0c257e60bbc1", "best_bid": "0.45", "best_ask": "0.49"}], "timestamp": "1769384071000", "event_type": "price_change"}}
{"_local_timestamp": "2026-01-25T23:34:31.235998+00:00", "data": {"market": "0x242266c50482ad4f243610f7546b60089eadc1d81d4ef408c787f67aa3ef5e7c", "price_changes": [{"asset_id": "96533933355712544390418613060156510030240147080751769428940162257378106436404", "price": "0.16", "size": "0", "side": "BUY", "hash": "5203e0255e433863746e10665fae2ab782cfa2db", "best_bid": "0.45", "best_ask": "0.49"}, {"asset_id": "28263250326920700075422198100613476697802143744104502510886484761449393244656", "price": "0.84", "size": "0", "side": "SELL", "hash": "f30d7917e8dd2f02a010084a881c915ad0cd8a82", "best_bid": "0.51", "best_ask": "0.55"}], "timestamp": "1769384071000", "event_type": "price_change"}}
{"_local_timestamp": "2026-01-25T23:34:31.236581+00:00", "data": {"market": "0x54b69275ee145425f1a0dce69faef15f729f1ab3ec41bc2996a6c6c70e8aec0b", "price_changes": [{"asset_id": "106447080412815954453539138762045278580988736678171840293222199861758175727534", "price": "0.16", "size": "0", "side": "BUY", "hash": "bf9f0ba451bca550ca01dc1860e188aad14b8178", "best_bid": "0.46", "best_ask": "0.51"}, {"asset_id": "44494068166094207162801090520618289188991411103177309101619626920967990930514", "price": "0.84", "size": "0", "side": "SELL", "hash": "9c96119442b043ad095cbc61f807d2fc3f3b4261", "best_bid": "0.49", "best_ask": "0.54"}], "timestamp": "1769384071000", "event_type": "price_change"}}
{"_local_timestamp": "2026-01-25T23:34:31.237091+00:00", "data": {"market": "0x6e5e9c218d780a8ff8b516cae97604958f7323ffd75b525d810fb804e727ad78", "price_changes": [{"asset_id": "66190026636022120219272454910747143264277679901831317594304438527297253363875", "price": "0.02", "size": "28.64", "side": "BUY", "hash": "d47fb3e1531729fdf2f75926688eda2f943afffc", "best_bid": "0.21", "best_ask": "0.22"}, {"asset_id": "4929915665740215533077513370523570724508699505795913150073424458746805119832", "price": "0.98", "size": "28.64", "side": "SELL", "hash": "70f19a48615468e1b483887ea20d3d7214ddb0b2", "best_bid": "0.78", "best_ask": "0.79"}], "timestamp": "1769384071000", "event_type": "price_change"}}
{"_local_timestamp": "2026-01-25T23:34:31.239023+00:00", "data": {"market": "0x6e5e9c218d780a8ff8b516cae97604958f7323ffd75b525d810fb804e727ad78", "price_changes": [{"asset_id": "4929915665740215533077513370523570724508699505795913150073424458746805119832", "price": "0.51", "size": "0", "side": "BUY", "hash": "e69184d9c2659541cda6733132e7da656eae8935", "best_bid": "0.78", "best_ask": "0.79"}, {"asset_id": "66190026636022120219272454910747143264277679901831317594304438527297253363875", "price": "0.49", "size": "0", "side": "SELL", "hash": "df223f41e0f368d7251fd5aefb834ed16323a154", "best_bid": "0.21", "best_ask": "0.22"}], "timestamp": "1769384071001", "event_type": "price_change"}}
{"_local_timestamp": "2026-01-25T23:34:31.241957+00:00", "data": {"market": "0x54b69275ee145425f1a0dce69faef15f729f1ab3ec41bc2996a6c6c70e8aec0b", "price_changes": [{"asset_id": "44494068166094207162801090520618289188991411103177309101619626920967990930514", "price": "0.16", "size": "0", "side": "BUY", "hash": "51f7a43b8eb05e940d3a1b2c3888664fda9fc338", "best_bid": "0.49", "best_ask": "0.54"}, {"asset_id": "106447080412815954453539138762045278580988736678171840293222199861758175727534", "price": "0.84", "size": "0", "side": "SELL", "hash": "78fad1a6eaa2f2ea30702ba1024162cf17bf0357", "best_bid": "0.46", "best_ask": "0.51"}], "timestamp": "1769384071001", "event_type": "price_change"}}
{"_local_timestamp": "2026-01-25T23:34:31.242521+00:00", "data": {"market": "0xaeb02ced23cf66b235fb864ed82bdf7f7144c38cb0c7466e5f6c255a5c6015cc", "price_changes": [{"asset_id": "16066315103031518578542990703395510559372655158819085950817958432162905570385", "price": "0.015", "size": "0", "side": "BUY", "hash": "c780bbef3dfcb04e7bd0ad9e39ab0d1e220d188b", "best_bid": "0.99", "best_ask": "0.998"}, {"asset_id": "38866550321267038434460376745002272171027672578638559578882849128491520813825", "price": "0.985", "size": "0", "side": "SELL", "hash": "a640293c133210d475685f3c7c3a81f4c4fa58e6", "best_bid": "0.002", "best_ask": "0.01"}], "timestamp": "1769384071000", "event_type": "price_change"}}
{"_local_timestamp": "2026-01-25T23:34:31.243138+00:00", "data": {"market": "0x7573b38aa3d3d387be05d7e2b3fa5c397c6cbf1fbfbb5ccbe1d82816b901e9d1", "price_changes": [{"asset_id": "47900911198961041897125947140815317810676260067603694036981412378636602096971", "price": "0.33", "size": "0", "side": "BUY", "hash": "4ba04c7d91e9e00484fcdcc124a6e6d73474e71a", "best_bid": "0.45", "best_ask": "0.46"}, {"asset_id": "45963563720386640986457133827320203891928335132800978095470889439601833791792", "price": "0.67", "size": "0", "side": "SELL", "hash": "0ed431f76fe6c4c7c94cd6f00bed0ee7242ae720", "best_bid": "0.54", "best_ask": "0.55"}], "timestamp": "1769384071001", "event_type": "price_change"}}
{"_local_timestamp": "2026-01-25T23:34:31.518339+00:00", "data": {"market": "0x6ac594337fbd762ec04471e8d65806ff9ff78c33ed9dca4826c7bd2969475251", "price_changes": [{"asset_id": "79880305123726971124937075515339490140944001374542290672889526459108541617627", "price": "0.51", "size": "0", "side": "BUY", "hash": "edb5f3af1c65555029f52e987202d1135ea10f75", "best_bid": "0.81", "best_ask": "0.86"}, {"asset_id": "115162358394175336212249289650926294268751651827332730207583087521345129280038", "price": "0.49", "size": "0", "side": "SELL", "hash": "94b9f9e19c4761ef4141cc62cba452ada59a5567", "best_bid": "0.14", "best_ask": "0.19"}], "timestamp": "1769384071000", "event_type": "price_change"}}
{"_local_timestamp": "2026-01-25T23:34:31.520139+00:00", "data": {"market": "0x6ac594337fbd762ec04471e8d65806ff9ff78c33ed9dca4826c7bd2969475251", "price_changes": [{"asset_id": "115162358394175336212249289650926294268751651827332730207583087521345129280038", "price": "0.03", "size": "0", "side": "BUY", "hash": "b69d9e601215da7b975bee96e827206f98954d4f", "best_bid": "0.14", "best_ask": "0.19"}, {"asset_id": "79880305123726971124937075515339490140944001374542290672889526459108541617627", "price": "0.97", "size": "0", "side": "SELL", "hash": "69614e43f6f8bab7e2f519643c33c046a8e3b409", "best_bid": "0.81", "best_ask": "0.86"}], "timestamp": "1769384071003", "event_type": "price_change"}}
{"_local_timestamp": "2026-01-25T23:34:31.524680+00:00", "data": {"market": "0xcf18b8f0901452013dcdf957badd6bfb71a9935c6dd9dd2566dc5bb7f795c1a0", "price_changes": [{"asset_id": "86867607300025136841054177922135303037165603316339117668930743822611084804074", "price": "0.05", "size": "0", "side": "BUY", "hash": "b4953fefeca638e220bc5c568171e7a1797e1bba", "best_bid": "0.37", "best_ask": "0.41"}, {"asset_id": "13301686528282766867573623232056946130992514687837926123264639755941579360230", "price": "0.95", "size": "0", "side": "SELL", "hash": "117357b737306c34fcd5d174057cdb251ff11e1a", "best_bid": "0.59", "best_ask": "0.63"}], "timestamp": "1769384071000", "event_type": "price_change"}}
{"_local_timestamp": "2026-01-25T23:34:31.525241+00:00", "data": {"market": "0x27d685bdad61bf2f35948bcff8ddf673c14b72a6f4e9cf1a9d867be231f6a610", "price_changes": [{"asset_id": "32476227489805089000687418984234668312982619103362138837681249693289694597075", "price": "0.21", "size": "0", "side": "BUY", "hash": "41b7f59a8db8d273b7d49c1d10beb4189a88a732", "best_bid": "0.62", "best_ask": "0.68"}, {"asset_id": "82614941921461618729202933946512372479181705578801351216657431603405116134694", "price": "0.79", "size": "0", "side": "SELL", "hash": "53fb501026b943b364daf347be283c71d4d884a8", "best_bid": "0.32", "best_ask": "0.38"}], "timestamp": "1769384071000", "event_type": "price_change"}}
{"_local_timestamp": "2026-01-25T23:34:31.529671+00:00", "data": {"market": "0xcf18b8f0901452013dcdf957badd6bfb71a9935c6dd9dd2566dc5bb7f795c1a0", "price_changes": [{"asset_id": "13301686528282766867573623232056946130992514687837926123264639755941579360230", "price": "0.28", "size": "0", "side": "BUY", "hash": "f3444ab6bffb0943d5ff674849ad3075727a5dc9", "best_bid": "0.59", "best_ask": "0.63"}, {"asset_id": "86867607300025136841054177922135303037165603316339117668930743822611084804074", "price": "0.72", "size": "0", "side": "SELL", "hash": "76c1550838e354bca11583dd12ee8e4b644dc016", "best_bid": "0.37", "best_ask": "0.41"}], "timestamp": "1769384071003", "event_type": "price_change"}}
{"_local_timestamp": "2026-01-25T23:34:31.530495+00:00", "data": {"market": "0x27d685bdad61bf2f35948bcff8ddf673c14b72a6f4e9cf1a9d867be231f6a610", "price_changes": [{"asset_id": "82614941921461618729202933946512372479181705578801351216657431603405116134694", "price": "0.03", "size": "0", "side": "BUY", "hash": "2e5bae01fa3c3b5056c234949b9c9b3c9929a51a", "best_bid": "0.32", "best_ask": "0.38"}, {"asset_id": "32476227489805089000687418984234668312982619103362138837681249693289694597075", "price": "0.97", "size": "0", "side": "SELL", "hash": "1af0bb7b84ba76319099493dc0603c04a114dea1", "best_bid": "0.62", "best_ask": "0.68"}], "timestamp": "1769384071004", "event_type": "price_change"}}
{"_local_timestamp": "2026-01-25T23:34:31.531853+00:00", "data": {"market": "0xdd3915ab9de231a4f8d1b6989b9d28c81a39d3372fc2f5e5d5e09c5c36bd15e0", "price_changes": [{"asset_id": "73772444484179123398639028358181122166565249885455240318019005512648163832892", "price": "0.05", "size": "0", "side": "BUY", "hash": "17b22c4a33018e18b750e2ea608c5b37ad87b641", "best_bid": "0.32", "best_ask": "0.34"}, {"asset_id": "64912974742020396457447321385468313243213302286888804044150787878568707049629", "price": "0.95", "size": "0", "side": "SELL", "hash": "7995d0163892c025a8ea5e8537ac7c0e1b98c1b1", "best_bid": "0.66", "best_ask": "0.68"}], "timestamp": "1769384071001", "event_type": "price_change"}}
{"_local_timestamp": "2026-01-25T23:34:31.536158+00:00", "data": {"market": "0x7573b38aa3d3d387be05d7e2b3fa5c397c6cbf1fbfbb5ccbe1d82816b901e9d1", "price_changes": [{"asset_id": "45963563720386640986457133827320203891928335132800978095470889439601833791792", "price": "0.4", "size": "0", "side": "BUY", "hash": "98866445b2a4e024d0b87c4e40185578d041167c", "best_bid": "0.54", "best_ask": "0.55"}, {"asset_id": "47900911198961041897125947140815317810676260067603694036981412378636602096971", "price": "0.6", "size": "0", "side": "SELL", "hash": "63790da447585270deaffe6427853b270d101d45", "best_bid": "0.45", "best_ask": "0.46"}], "timestamp": "1769384071004", "event_type": "price_change"}}
{"_local_timestamp": "2026-01-25T23:34:31.538510+00:00", "data": {"market": "0xdd3915ab9de231a4f8d1b6989b9d28c81a39d3372fc2f5e5d5e09c5c36bd15e0", "price_changes": [{"asset_id": "64912974742020396457447321385468313243213302286888804044150787878568707049629", "price": "0.35", "size": "0", "side": "BUY", "hash": "fc3b160ec315ee8a2745283e2a1dfae68a99db6d", "best_bid": "0.66", "best_ask": "0.68"}, {"asset_id": "73772444484179123398639028358181122166565249885455240318019005512648163832892", "price": "0.65", "size": "0", "side": "SELL", "hash": "5e19ba69cdba649a97fef8330ec12f65dc8bf677", "best_bid": "0.32", "best_ask": "0.34"}], "timestamp": "1769384071004", "event_type": "price_change"}}
{"_local_timestamp": "2026-01-25T23:34:31.756353+00:00", "data": {"market": "0x6e5e9c218d780a8ff8b516cae97604958f7323ffd75b525d810fb804e727ad78", "price_changes": [{"asset_id": "66190026636022120219272454910747143264277679901831317594304438527297253363875", "price": "0.01", "size": "50", "side": "BUY", "hash": "ee70e24dae513526e240751fe7a42c2ec48f1c74", "best_bid": "0.21", "best_ask": "0.22"}, {"asset_id": "4929915665740215533077513370523570724508699505795913150073424458746805119832", "price": "0.99", "size": "50", "side": "SELL", "hash": "c9bc5295c0fb399ad96fa0bb0887b7d9c46f1a90", "best_bid": "0.78", "best_ask": "0.79"}], "timestamp": "1769384071541", "event_type": "price_change"}}
{"_local_timestamp": "2026-01-25T23:34:31.763912+00:00", "data": {"market": "0x6e5e9c218d780a8ff8b516cae97604958f7323ffd75b525d810fb804e727ad78", "price_changes": [{"asset_id": "66190026636022120219272454910747143264277679901831317594304438527297253363875", "price": "0.02", "size": "7.51", "side": "BUY", "hash": "ee70e24dae513526e240751fe7a42c2ec48f1c74", "best_bid": "0.21", "best_ask": "0.22"}, {"asset_id": "4929915665740215533077513370523570724508699505795913150073424458746805119832", "price": "0.98", "size": "7.51", "side": "SELL", "hash": "c9bc5295c0fb399ad96fa0bb0887b7d9c46f1a90", "best_bid": "0.78", "best_ask": "0.79"}], "timestamp": "1769384071541", "event_type": "price_change"}}
{"_local_timestamp": "2026-01-25T23:34:31.978130+00:00", "data": {"market": "0x6e5e9c218d780a8ff8b516cae97604958f7323ffd75b525d810fb804e727ad78", "price_changes": [{"asset_id": "66190026636022120219272454910747143264277679901831317594304438527297253363875", "price": "0.01", "size": "82.81", "side": "BUY", "hash": "bfe4393addcb179e466662240da58a790b8b3439", "best_bid": "0.21", "best_ask": "0.22"}, {"asset_id": "4929915665740215533077513370523570724508699505795913150073424458746805119832", "price": "0.99", "size": "82.81", "side": "SELL", "hash": "05bee5df3e54cb851c748aa8b0f753f8202b4c4e", "best_bid": "0.78", "best_ask": "0.79"}], "timestamp": "1769384071758", "event_type": "price_change"}}
{"_local_timestamp": "2026-01-25T23:34:31.981532+00:00", "data": {"market": "0x6e5e9c218d780a8ff8b516cae97604958f7323ffd75b525d810fb804e727ad78", "price_changes": [{"asset_id": "66190026636022120219272454910747143264277679901831317594304438527297253363875", "price": "0.02", "size": "33.59", "side": "BUY", "hash": "f545e82b62726e4ecf6afef301ec9e0b308ac174", "best_bid": "0.21", "best_ask": "0.22"}, {"asset_id": "4929915665740215533077513370523570724508699505795913150073424458746805119832", "price": "0.98", "size": "33.59", "side": "SELL", "hash": "974fe38285f0548134a5d8ecdff48ca82ba94077", "best_bid": "0.78", "best_ask": "0.79"}], "timestamp": "1769384071759", "event_type": "price_change"}}
{"_local_timestamp": "2026-01-25T23:34:32.332666+00:00", "data": {"market": "0xaeb02ced23cf66b235fb864ed82bdf7f7144c38cb0c7466e5f6c255a5c6015cc", "price_changes": [{"asset_id": "38866550321267038434460376745002272171027672578638559578882849128491520813825", "price": "0.01", "size": "13.1", "side": "SELL", "hash": "5879cd59998ffa011f86b1dc16ea7e1425abb5c0", "best_bid": "0.002", "best_ask": "0.01"}, {"asset_id": "16066315103031518578542990703395510559372655158819085950817958432162905570385", "price": "0.99", "size": "13.1", "side": "BUY", "hash": "d07c37dabefe5c2fe6a71f78c791708d6da87956", "best_bid": "0.99", "best_ask": "0.998"}], "timestamp": "1769384072083", "event_type": "price_change"}}
{"_local_timestamp": "2026-01-25T23:34:32.334029+00:00", "data": {"market": "0xaeb02ced23cf66b235fb864ed82bdf7f7144c38cb0c7466e5f6c255a5c6015cc", "price_changes": [{"asset_id": "38866550321267038434460376745002272171027672578638559578882849128491520813825", "price": "0.011", "size": "0", "side": "SELL", "hash": "5879cd59998ffa011f86b1dc16ea7e1425abb5c0", "best_bid": "0.002", "best_ask": "0.01"}, {"asset_id": "16066315103031518578542990703395510559372655158819085950817958432162905570385", "price": "0.989", "size": "0", "side": "BUY", "hash": "d07c37dabefe5c2fe6a71f78c791708d6da87956", "best_bid": "0.99", "best_ask": "0.998"}], "timestamp": "1769384072083", "event_type": "price_change"}}
{"_local_timestamp": "2026-01-25T23:34:32.588438+00:00", "data": {"market": "0xaeb02ced23cf66b235fb864ed82bdf7f7144c38cb0c7466e5f6c255a5c6015cc", "price_changes": [{"asset_id": "38866550321267038434460376745002272171027672578638559578882849128491520813825", "price": "0.02", "size": "13.11", "side": "SELL", "hash": "05bf7b5f2886dd01dbbc32d6630a117d6f7c746e", "best_bid": "0.002", "best_ask": "0.01"}, {"asset_id": "16066315103031518578542990703395510559372655158819085950817958432162905570385", "price": "0.98", "size": "13.11", "side": "BUY", "hash": "d9271d1998e529eada608eb66c3285a29af2b79e", "best_bid": "0.99", "best_ask": "0.998"}], "timestamp": "1769384072365", "event_type": "price_change"}}
{"_local_timestamp": "2026-01-25T23:34:32.595064+00:00", "data": {"market": "0xaeb02ced23cf66b235fb864ed82bdf7f7144c38cb0c7466e5f6c255a5c6015cc", "price_changes": [{"asset_id": "38866550321267038434460376745002272171027672578638559578882849128491520813825", "price": "0.02", "size": "26.22", "side": "SELL", "hash": "996517bcc0f7d28409d9ca9db47eff9bcad0f086", "best_bid": "0.002", "best_ask": "0.01"}, {"asset_id": "16066315103031518578542990703395510559372655158819085950817958432162905570385", "price": "0.98", "size": "26.22", "side": "BUY", "hash": "6153c21e143e84070df46e0513ef2dcac8626af3", "best_bid": "0.99", "best_ask": "0.998"}], "timestamp": "1769384072367", "event_type": "price_change"}}
{"_local_timestamp": "2026-01-25T23:34:33.675814+00:00", "data": {"market": "0x27d685bdad61bf2f35948bcff8ddf673c14b72a6f4e9cf1a9d867be231f6a610", "price_changes": [{"asset_id": "82614941921461618729202933946512372479181705578801351216657431603405116134694", "price": "0.04", "size": "8.75", "side": "BUY", "hash": "2725e044244abfd5e65c0d2a74ca6ce7cb3c8388", "best_bid": "0.32", "best_ask": "0.38"}, {"asset_id": "32476227489805089000687418984234668312982619103362138837681249693289694597075", "price": "0.96", "size": "8.75", "side": "SELL", "hash": "5a79dbcab7bcdb766b9db005b89a187550aade2b", "best_bid": "0.62", "best_ask": "0.68"}], "timestamp": "1769384072959", "event_type": "price_change"}}
{"_local_timestamp": "2026-01-25T23:34:33.677992+00:00", "data": {"market": "0xaeb02ced23cf66b235fb864ed82bdf7f7144c38cb0c7466e5f6c255a5c6015cc", "price_changes": [{"asset_id": "38866550321267038434460376745002272171027672578638559578882849128491520813825", "price": "0.021", "size": "5.47", "side": "SELL", "hash": "d955033b9d14cf7a104d469d1fc3f7d83335f2a4", "best_bid": "0.002", "best_ask": "0.01"}, {"asset_id": "16066315103031518578542990703395510559372655158819085950817958432162905570385", "price": "0.979", "size": "5.47", "side": "BUY", "hash": "14a0b6e7746ce291a9b2ea282bb74b7ab2e6f90e", "best_bid": "0.99", "best_ask": "0.998"}], "timestamp": "1769384073143", "event_type": "price_change"}}
{"_local_timestamp": "2026-01-25T23:34:33.680171+00:00", "data": {"market": "0xaeb02ced23cf66b235fb864ed82bdf7f7144c38cb0c7466e5f6c255a5c6015cc", "price_changes": [{"asset_id": "38866550321267038434460376745002272171027672578638559578882849128491520813825", "price": "0.019", "size": "24.69", "side": "SELL", "hash": "8f58f03b04598e7d7b0050dcba1e06701d155ae9", "best_bid": "0.002", "best_ask": "0.01"}, {"asset_id": "16066315103031518578542990703395510559372655158819085950817958432162905570385", "price": "0.981", "size": "24.69", "side": "BUY", "hash": "a53fc82df637c6f70bb7a30201b6dc8342289622", "best_bid": "0.99", "best_ask": "0.998"}], "timestamp": "1769384073186", "event_type": "price_change"}}
{"_local_timestamp": "2026-01-25T23:34:33.680764+00:00", "data": {"market": "0x27d685bdad61bf2f35948bcff8ddf673c14b72a6f4e9cf1a9d867be231f6a610", "price_changes": [{"asset_id": "82614941921461618729202933946512372479181705578801351216657431603405116134694", "price": "0.02", "size": "13.48", "side": "BUY", "hash": "dc62d434cf87ba5f6ca6231f31d1870e514fc0a1", "best_bid": "0.32", "best_ask": "0.38"}, {"asset_id": "32476227489805089000687418984234668312982619103362138837681249693289694597075", "price": "0.98", "size": "13.48", "side": "SELL", "hash": "76f5ffc1a2fe24aa0a969d5aeab9025de3d3cd3a", "best_bid": "0.62", "best_ask": "0.68"}], "timestamp": "1769384073291", "event_type": "price_change"}}
{"_local_timestamp": "2026-01-25T23:34:33.682319+00:00", "data": {"market": "0x27d685bdad61bf2f35948bcff8ddf673c14b72a6f4e9cf1a9d867be231f6a610", "price_changes": [{"asset_id": "82614941921461618729202933946512372479181705578801351216657431603405116134694", "price": "0.01", "size": "63.01", "side": "BUY", "hash": "3d5dd56d78eccb24cc86e3658dc2345f00bfea38", "best_bid": "0.32", "best_ask": "0.38"}, {"asset_id": "32476227489805089000687418984234668312982619103362138837681249693289694597075", "price": "0.99", "size": "63.01", "side": "SELL", "hash": "66d510d35ae6e1063dcd4dfb28d4a4f92c13acfe", "best_bid": "0.62", "best_ask": "0.68"}], "timestamp": "1769384073292", "event_type": "price_change"}}
{"_local_timestamp": "2026-01-25T23:34:33.683178+00:00", "data": {"market": "0x27d685bdad61bf2f35948bcff8ddf673c14b72a6f4e9cf1a9d867be231f6a610", "price_changes": [{"asset_id": "82614941921461618729202933946512372479181705578801351216657431603405116134694", "price": "0.01", "size": "76.02", "side": "BUY", "hash": "110ea0f5fd1b4869bafecf5a02cbe292c8197480", "best_bid": "0.32", "best_ask": "0.38"}, {"asset_id": "32476227489805089000687418984234668312982619103362138837681249693289694597075", "price": "0.99", "size": "76.02", "side": "SELL", "hash": "f94e1d69611f6553e7372041928e23c8b43e87ce", "best_bid": "0.62", "best_ask": "0.68"}], "timestamp": "1769384073294", "event_type": "price_change"}}
{"_local_timestamp": "2026-01-25T23:34:33.684945+00:00", "data": {"market": "0x27d685bdad61bf2f35948bcff8ddf673c14b72a6f4e9cf1a9d867be231f6a610", "price_changes": [{"asset_id": "82614941921461618729202933946512372479181705578801351216657431603405116134694", "price": "0.02", "size": "19.47", "side": "BUY", "hash": "09620f2a0cac7ad9ae2325878e3acf6b5e86b90f", "best_bid": "0.32", "best_ask": "0.38"}, {"asset_id": "32476227489805089000687418984234668312982619103362138837681249693289694597075", "price": "0.98", "size": "19.47", "side": "SELL", "hash": "34fdb180b08c90b1b26297b892c01461a38ed234", "best_bid": "0.62", "best_ask": "0.68"}], "timestamp": "1769384073295", "event_type": "price_change"}}
{"_local_timestamp": "2026-01-25T23:34:34.457873+00:00", "data": {"market": "0x27d685bdad61bf2f35948bcff8ddf673c14b72a6f4e9cf1a9d867be231f6a610", "price_changes": [{"asset_id": "82614941921461618729202933946512372479181705578801351216657431603405116134694", "price": "0.04", "size": "0", "side": "BUY", "hash": "241ea6e6b44a22003b3803c89f70931c91be670c", "best_bid": "0.32", "best_ask": "0.38"}, {"asset_id": "32476227489805089000687418984234668312982619103362138837681249693289694597075", "price": "0.96", "size": "0", "side": "SELL", "hash": "da765c9464dee630e6c7e49c2cc66764d0b53f37", "best_bid": "0.62", "best_ask": "0.68"}], "timestamp": "1769384074244", "event_type": "price_change"}}
{"_local_timestamp": "2026-01-25T23:34:34.458558+00:00", "data": {"market": "0xaeb02ced23cf66b235fb864ed82bdf7f7144c38cb0c7466e5f6c255a5c6015cc", "price_changes": [{"asset_id": "38866550321267038434460376745002272171027672578638559578882849128491520813825", "price": "0.01", "size": "0", "side": "SELL", "hash": "8e2707fd4e5ef17e7fc29d6e019f7f4190184a77", "best_bid": "0.002", "best_ask": "0.019"}, {"asset_id": "16066315103031518578542990703395510559372655158819085950817958432162905570385", "price": "0.99", "size": "0", "side": "BUY", "hash": "1de847b4ea357eba455ee8bf05fc7a3eef73b7f4", "best_bid": "0.981", "best_ask": "0.998"}], "timestamp": "1769384074244", "event_type": "price_change"}}
{"_local_timestamp": "2026-01-25T23:34:34.459137+00:00", "data": {"market": "0xaeb02ced23cf66b235fb864ed82bdf7f7144c38cb0c7466e5f6c255a5c6015cc", "price_changes": [{"asset_id": "38866550321267038434460376745002272171027672578638559578882849128491520813825", "price": "0.02", "size": "13.11", "side": "SELL", "hash": "8e2707fd4e5ef17e7fc29d6e019f7f4190184a77", "best_bid": "0.002", "best_ask": "0.019"}, {"asset_id": "16066315103031518578542990703395510559372655158819085950817958432162905570385", "price": "0.98", "size": "13.11", "side": "BUY", "hash": "1de847b4ea357eba455ee8bf05fc7a3eef73b7f4", "best_bid": "0.981", "best_ask": "0.998"}], "timestamp": "1769384074244", "event_type": "price_change"}}
{"_local_timestamp": "2026-01-25T23:34:34.547519+00:00", "data": {"market": "0xaeb02ced23cf66b235fb864ed82bdf7f7144c38cb0c7466e5f6c255a5c6015cc", "price_changes": [{"asset_id": "38866550321267038434460376745002272171027672578638559578882849128491520813825", "price": "0.019", "size": "0", "side": "SELL", "hash": "1b181190ee35a46318f9343f5313ea05c035a452", "best_bid": "0.002", "best_ask": "0.02"}, {"asset_id": "16066315103031518578542990703395510559372655158819085950817958432162905570385", "price": "0.981", "size": "0", "side": "BUY", "hash": "31b3d93b768b9f381cb6565853f58e80b12be5bb", "best_bid": "0.98", "best_ask": "0.998"}], "timestamp": "1769384074337", "event_type": "price_change"}}
{"_local_timestamp": "2026-01-25T23:34:34.583726+00:00", "data": {"market": "0xaeb02ced23cf66b235fb864ed82bdf7f7144c38cb0c7466e5f6c255a5c6015cc", "price_changes": [{"asset_id": "38866550321267038434460376745002272171027672578638559578882849128491520813825", "price": "0.021", "size": "30.16", "side": "SELL", "hash": "b2e1510c5242bfdaca0a0f527b02e2c6e7d5a3ce", "best_bid": "0.002", "best_ask": "0.02"}, {"asset_id": "16066315103031518578542990703395510559372655158819085950817958432162905570385", "price": "0.979", "size": "30.16", "side": "BUY", "hash": "3875faeb1a48d58a450d6a9b879e90083d53fb96", "best_bid": "0.98", "best_ask": "0.998"}], "timestamp": "1769384074373", "event_type": "price_change"}}
{"_local_timestamp": "2026-01-25T23:34:34.735773+00:00", "data": {"market": "0x27d685bdad61bf2f35948bcff8ddf673c14b72a6f4e9cf1a9d867be231f6a610", "price_changes": [{"asset_id": "82614941921461618729202933946512372479181705578801351216657431603405116134694", "price": "0.02", "size": "27.88", "side": "BUY", "hash": "c7f7532a583aca45a03d7d113fd0c416e032ccc2", "best_bid": "0.32", "best_ask": "0.38"}, {"asset_id": "32476227489805089000687418984234668312982619103362138837681249693289694597075", "price": "0.98", "size": "27.88", "side": "SELL", "hash": "7172e70127b6adf91b7edaac999c0e68a8dedd76", "best_bid": "0.62", "best_ask": "0.68"}], "timestamp": "1769384074536", "event_type": "price_change"}}
{"_local_timestamp": "2026-01-25T23:34:34.738675+00:00", "data": {"market": "0x27d685bdad61bf2f35948bcff8ddf673c14b72a6f4e9cf1a9d867be231f6a610", "price_changes": [{"asset_id": "82614941921461618729202933946512372479181705578801351216657431603405116134694", "price": "0.01", "size": "85.12", "side": "BUY", "hash": "28445b14233d6a25c479a5e9f8d767200eab5e62", "best_bid": "0.32", "best_ask": "0.38"}, {"asset_id": "32476227489805089000687418984234668312982619103362138837681249693289694597075", "price": "0.99", "size": "85.12", "side": "SELL", "hash": "d6099c2dcff64bbcc467ccf4008dc7478005aa57", "best_bid": "0.62", "best_ask": "0.68"}], "timestamp": "1769384074536", "event_type": "price_change"}}
{"_local_timestamp": "2026-01-25T23:34:34.739775+00:00", "data": {"market": "0x27d685bdad61bf2f35948bcff8ddf673c14b72a6f4e9cf1a9d867be231f6a610", "price_changes": [{"asset_id": "82614941921461618729202933946512372479181705578801351216657431603405116134694", "price": "0.01", "size": "94.22", "side": "BUY", "hash": "58b0b48c740d95eadd54f00773ea3be16fa929c4", "best_bid": "0.32", "best_ask": "0.38"}, {"asset_id": "32476227489805089000687418984234668312982619103362138837681249693289694597075", "price": "0.99", "size": "94.22", "side": "SELL", "hash": "32adeae90f1804b6a1dbabdb07b5d060d9f6b82e", "best_bid": "0.62", "best_ask": "0.68"}], "timestamp": "1769384074537", "event_type": "price_change"}}
{"_local_timestamp": "2026-01-25T23:34:34.740398+00:00", "data": {"market": "0xaeb02ced23cf66b235fb864ed82bdf7f7144c38cb0c7466e5f6c255a5c6015cc", "price_changes": [{"asset_id": "38866550321267038434460376745002272171027672578638559578882849128491520813825", "price": "0.018", "size": "13.1", "side": "SELL", "hash": "084457f934b5f4b4840703f97f24d7a0604bf35d", "best_bid": "0.002", "best_ask": "0.018"}, {"asset_id": "16066315103031518578542990703395510559372655158819085950817958432162905570385", "price": "0.982", "size": "13.1", "side": "BUY", "hash": "e3dca64ee491d87fe4af9429c1b2eeb55f3a9f1f", "best_bid": "0.982", "best_ask": "0.998"}], "timestamp": "1769384074535", "event_type": "price_change"}}
{"_local_timestamp": "2026-01-25T23:34:34.741073+00:00", "data": {"market": "0xaeb02ced23cf66b235fb864ed82bdf7f7144c38cb0c7466e5f6c255a5c6015cc", "price_changes": [{"asset_id": "38866550321267038434460376745002272171027672578638559578882849128491520813825", "price": "0.018", "size": "26.2", "side": "SELL", "hash": "5a29fd22f826c5e84fe678c5dae841a090731b6a", "best_bid": "0.002", "best_ask": "0.018"}, {"asset_id": "16066315103031518578542990703395510559372655158819085950817958432162905570385", "price": "0.982", "size": "26.2", "side": "BUY", "hash": "647a6e0f0f12437e3692c4c5bac70f4b22eee6d1", "best_bid": "0.982", "best_ask": "0.998"}], "timestamp": "1769384074536", "event_type": "price_change"}}
{"_local_timestamp": "2026-01-25T23:34:35.734915+00:00", "data": {"market": "0xaeb02ced23cf66b235fb864ed82bdf7f7144c38cb0c7466e5f6c255a5c6015cc", "price_changes": [{"asset_id": "38866550321267038434460376745002272171027672578638559578882849128491520813825", "price": "0.021", "size": "5.47", "side": "SELL", "hash": "54d6a7c895741d3f9164d2ebad72126a483477ed", "best_bid": "0.002", "best_ask": "0.018"}, {"asset_id": "16066315103031518578542990703395510559372655158819085950817958432162905570385", "price": "0.979", "size": "5.47", "side": "BUY", "hash": "6bd537e1e17bd95590bb8ae8c5573b9595445f06", "best_bid": "0.982", "best_ask": "0.998"}], "timestamp": "1769384075493", "event_type": "price_change"}}
{"_local_timestamp": "2026-01-25T23:34:35.753199+00:00", "data": {"market": "0xaeb02ced23cf66b235fb864ed82bdf7f7144c38cb0c7466e5f6c255a5c6015cc", "price_changes": [{"asset_id": "38866550321267038434460376745002272171027672578638559578882849128491520813825", "price": "0.017", "size": "24.69", "side": "SELL", "hash": "5f11c20dd8532f5149c56aef1976e6a09df71f78", "best_bid": "0.002", "best_ask": "0.017"}, {"asset_id": "16066315103031518578542990703395510559372655158819085950817958432162905570385", "price": "0.983", "size": "24.69", "side": "BUY", "hash": "05227405bd7ab53cf3dd081db9484e816f63e508", "best_bid": "0.983", "best_ask": "0.998"}], "timestamp": "1769384075523", "event_type": "price_change"}}
{"_local_timestamp": "2026-01-25T23:34:36.158546+00:00", "data": {"market": "0x27d685bdad61bf2f35948bcff8ddf673c14b72a6f4e9cf1a9d867be231f6a610", "price_changes": [{"asset_id": "32476227489805089000687418984234668312982619103362138837681249693289694597075", "price": "0.01", "size": "55.09", "side": "BUY", "hash": "0a5e38a0715503e8471df095b90b0358e8e7b523", "best_bid": "0.62", "best_ask": "0.68"}, {"asset_id": "82614941921461618729202933946512372479181705578801351216657431603405116134694", "price": "0.99", "size": "55.09", "side": "SELL", "hash": "320b9dc209307479dc1e4398626a35f93f16d7d1", "best_bid": "0.32", "best_ask": "0.38"}], "timestamp": "1769384075925", "event_type": "price_change"}}
{"_local_timestamp": "2026-01-25T23:34:36.159257+00:00", "data": {"market": "0xaeb02ced23cf66b235fb864ed82bdf7f7144c38cb0c7466e5f6c255a5c6015cc", "price_changes": [{"asset_id": "38866550321267038434460376745002272171027672578638559578882849128491520813825", "price": "0.018", "size": "13.1", "side": "SELL", "hash": "4e505f012407c9e446526a4ca25b2c16ac268541", "best_bid": "0.002", "best_ask": "0.017"}, {"asset_id": "16066315103031518578542990703395510559372655158819085950817958432162905570385", "price": "0.982", "size": "13.1", "side": "BUY", "hash": "347e3f0fcd9b2341b6264e35dbf059dd81e7b066", "best_bid": "0.983", "best_ask": "0.998"}], "timestamp": "1769384075925", "event_type": "price_change"}}
{"_local_timestamp": "2026-01-25T23:34:36.159858+00:00", "data": {"market": "0x27d685bdad61bf2f35948bcff8ddf673c14b72a6f4e9cf1a9d867be231f6a610", "price_changes": [{"asset_id": "32476227489805089000687418984234668312982619103362138837681249693289694597075", "price": "0.04", "size": "0", "side": "BUY", "hash": "0a5e38a0715503e8471df095b90b0358e8e7b523", "best_bid": "0.62", "best_ask": "0.68"}, {"asset_id": "82614941921461618729202933946512372479181705578801351216657431603405116134694", "price": "0.96", "size": "0", "side": "SELL", "hash": "320b9dc209307479dc1e4398626a35f93f16d7d1", "best_bid": "0.32", "best_ask": "0.38"}], "timestamp": "1769384075925", "event_type": "price_change"}}
{"_local_timestamp": "2026-01-25T23:34:36.160594+00:00", "data": {"market": "0xaeb02ced23cf66b235fb864ed82bdf7f7144c38cb0c7466e5f6c255a5c6015cc", "price_changes": [{"asset_id": "38866550321267038434460376745002272171027672578638559578882849128491520813825", "price": "0.02", "size": "0", "side": "SELL", "hash": "4e505f012407c9e446526a4ca25b2c16ac268541", "best_bid": "0.002", "best_ask": "0.017"}, {"asset_id": "16066315103031518578542990703395510559372655158819085950817958432162905570385", "price": "0.98", "size": "0", "side": "BUY", "hash": "347e3f0fcd9b2341b6264e35dbf059dd81e7b066", "best_bid": "0.983", "best_ask": "0.998"}], "timestamp": "1769384075925", "event_type": "price_change"}}
{"_local_timestamp": "2026-01-25T23:34:36.161202+00:00", "data": {"market": "0x27d685bdad61bf2f35948bcff8ddf673c14b72a6f4e9cf1a9d867be231f6a610", "price_changes": [{"asset_id": "32476227489805089000687418984234668312982619103362138837681249693289694597075", "price": "0.1", "size": "0", "side": "BUY", "hash": "0a5e38a0715503e8471df095b90b0358e8e7b523", "best_bid": "0.62", "best_ask": "0.68"}, {"asset_id": "82614941921461618729202933946512372479181705578801351216657431603405116134694", "price": "0.9", "size": "0", "side": "SELL", "hash": "320b9dc209307479dc1e4398626a35f93f16d7d1", "best_bid": "0.32", "best_ask": "0.38"}], "timestamp": "1769384075925", "event_type": "price_change"}}
{"_local_timestamp": "2026-01-25T23:34:36.422834+00:00", "data": {"market": "0x27d685bdad61bf2f35948bcff8ddf673c14b72a6f4e9cf1a9d867be231f6a610", "price_changes": [{"asset_id": "32476227489805089000687418984234668312982619103362138837681249693289694597075", "price": "0.09", "size": "7.28", "side": "BUY", "hash": "6f6e7735ff11d4f865a1203e7d5b5a43d5eb1986", "best_bid": "0.62", "best_ask": "0.68"}, {"asset_id": "82614941921461618729202933946512372479181705578801351216657431603405116134694", "price": "0.91", "size": "7.28", "side": "SELL", "hash": "36900606d1ba83675bbcb4e48ef25b76f6f30ca7", "best_bid": "0.32", "best_ask": "0.38"}], "timestamp": "1769384076190", "event_type": "price_change"}}
{"_local_timestamp": "2026-01-25T23:34:36.423642+00:00", "data": {"market": "0xaeb02ced23cf66b235fb864ed82bdf7f7144c38cb0c7466e5f6c255a5c6015cc", "price_changes": [{"asset_id": "38866550321267038434460376745002272171027672578638559578882849128491520813825", "price": "0.016", "size": "13.11", "side": "SELL", "hash": "29b04da154758d2ca408d6720c461e021591402b", "best_bid": "0.002", "best_ask": "0.016"}, {"asset_id": "16066315103031518578542990703395510559372655158819085950817958432162905570385", "price": "0.984", "size": "13.11", "side": "BUY", "hash": "e2cc92a527bfa8f54c3cff321acc2bf07fc33a4a", "best_bid": "0.984", "best_ask": "0.998"}], "timestamp": "1769384076190", "event_type": "price_change"}}
{"_local_timestamp": "2026-01-25T23:34:36.424306+00:00", "data": {"market": "0x27d685bdad61bf2f35948bcff8ddf673c14b72a6f4e9cf1a9d867be231f6a610", "price_changes": [{"asset_id": "32476227489805089000687418984234668312982619103362138837681249693289694597075", "price": "0.02", "size": "14.67", "side": "BUY", "hash": "58a8532b5eb8a8e4f8af6830c7c4d172ddb6ec73", "best_bid": "0.62", "best_ask": "0.68"}, {"asset_id": "82614941921461618729202933946512372479181705578801351216657431603405116134694", "price": "0.98", "size": "14.67", "side": "SELL", "hash": "f9a1aaf3fbfda9e5919c85ca84bf3b9f7673c3ef", "best_bid": "0.32", "best_ask": "0.38"}], "timestamp": "1769384076191", "event_type": "price_change"}}
{"_local_timestamp": "2026-01-25T23:34:36.437352+00:00", "data": {"market": "0xaeb02ced23cf66b235fb864ed82bdf7f7144c38cb0c7466e5f6c255a5c6015cc", "price_changes": [{"asset_id": "38866550321267038434460376745002272171027672578638559578882849128491520813825", "price": "0.016", "size": "26.22", "side": "SELL", "hash": "e5752c756aa958b4609af11c86573abd7f0cd7f7", "best_bid": "0.002", "best_ask": "0.016"}, {"asset_id": "16066315103031518578542990703395510559372655158819085950817958432162905570385", "price": "0.984", "size": "26.22", "side": "BUY", "hash": "b3632967733ba88bd659a4a52828cb5dc487f657", "best_bid": "0.984", "best_ask": "0.998"}], "timestamp": "1769384076191", "event_type": "price_change"}}
{"_local_timestamp": "2026-01-25T23:34:36.986132+00:00", "data": {"market": "0xaeb02ced23cf66b235fb864ed82bdf7f7144c38cb0c7466e5f6c255a5c6015cc", "price_changes": [{"asset_id": "38866550321267038434460376745002272171027672578638559578882849128491520813825", "price": "0.017", "size": "0", "side": "SELL", "hash": "fd9a18cab00f28cc5f35309dc1af87473b2bdce1", "best_bid": "0.002", "best_ask": "0.016"}, {"asset_id": "16066315103031518578542990703395510559372655158819085950817958432162905570385", "price": "0.983", "size": "0", "side": "BUY", "hash": "4ec708cd202a4648a97eb05284f480f22112126e", "best_bid": "0.984", "best_ask": "0.998"}], "timestamp": "1769384076746", "event_type": "price_change"}}
{"_local_timestamp": "2026-01-25T23:34:37.010839+00:00", "data": {"market": "0xaeb02ced23cf66b235fb864ed82bdf7f7144c38cb0c7466e5f6c255a5c6015cc", "price_changes": [{"asset_id": "38866550321267038434460376745002272171027672578638559578882849128491520813825", "price": "0.021", "size": "30.16", "side": "SELL", "hash": "65b200df1ed2db65cfd776b155217e0e80338264", "best_bid": "0.002", "best_ask": "0.016"}, {"asset_id": "16066315103031518578542990703395510559372655158819085950817958432162905570385", "price": "0.979", "size": "30.16", "side": "BUY", "hash": "22775d6cceea41ec2d58cc3874445ecefd219bea", "best_bid": "0.984", "best_ask": "0.998"}], "timestamp": "1769384076778", "event_type": "price_change"}}
{"_local_timestamp": "2026-01-25T23:34:37.413224+00:00", "data": {"market": "0x27d685bdad61bf2f35948bcff8ddf673c14b72a6f4e9cf1a9d867be231f6a610", "price_changes": [{"asset_id": "82614941921461618729202933946512372479181705578801351216657431603405116134694", "price": "0.01", "size": "81.21", "side": "BUY", "hash": "239e94da24da145759f11124ef3db97a19581f37", "best_bid": "0.32", "best_ask": "0.38"}, {"asset_id": "32476227489805089000687418984234668312982619103362138837681249693289694597075", "price": "0.99", "size": "81.21", "side": "SELL", "hash": "d409d9644a3eba3da6a9bfc64dcbae279fa61af1", "best_bid": "0.62", "best_ask": "0.68"}], "timestamp": "1769384077201", "event_type": "price_change"}}
{"_local_timestamp": "2026-01-25T23:34:37.415743+00:00", "data": {"market": "0x27d685bdad61bf2f35948bcff8ddf673c14b72a6f4e9cf1a9d867be231f6a610", "price_changes": [{"asset_id": "82614941921461618729202933946512372479181705578801351216657431603405116134694", "price": "0.02", "size": "19.47", "side": "BUY", "hash": "239e94da24da145759f11124ef3db97a19581f37", "best_bid": "0.32", "best_ask": "0.38"}, {"asset_id": "32476227489805089000687418984234668312982619103362138837681249693289694597075", "price": "0.98", "size": "19.47", "side": "SELL", "hash": "d409d9644a3eba3da6a9bfc64dcbae279fa61af1", "best_bid": "0.62", "best_ask": "0.68"}], "timestamp": "1769384077201", "event_type": "price_change"}}
{"_local_timestamp": "2026-01-25T23:34:37.584528+00:00", "data": {"market": "0x27d685bdad61bf2f35948bcff8ddf673c14b72a6f4e9cf1a9d867be231f6a610", "price_changes": [{"asset_id": "82614941921461618729202933946512372479181705578801351216657431603405116134694", "price": "0.01", "size": "86.88", "side": "BUY", "hash": "aa9c586429ec62af633baca4734f647a45b81e43", "best_bid": "0.32", "best_ask": "0.38"}, {"asset_id": "32476227489805089000687418984234668312982619103362138837681249693289694597075", "price": "0.99", "size": "86.88", "side": "SELL", "hash": "1085ef62ad7f2218d4421a4722d4f57dc97f5acd", "best_bid": "0.62", "best_ask": "0.68"}], "timestamp": "1769384077420", "event_type": "price_change"}}
{"_local_timestamp": "2026-01-25T23:34:37.589807+00:00", "data": {"market": "0x27d685bdad61bf2f35948bcff8ddf673c14b72a6f4e9cf1a9d867be231f6a610", "price_changes": [{"asset_id": "82614941921461618729202933946512372479181705578801351216657431603405116134694", "price": "0.02", "size": "28.71", "side": "BUY", "hash": "77d35f44c1a62fcafc41498a565548cde1cd8d76", "best_bid": "0.32", "best_ask": "0.38"}, {"asset_id": "32476227489805089000687418984234668312982619103362138837681249693289694597075", "price": "0.98", "size": "28.71", "side": "SELL", "hash": "a233eaba0165ac915f380d489c18b7604f2726ed", "best_bid": "0.62", "best_ask": "0.68"}], "timestamp": "1769384077421", "event_type": "price_change"}}
{"_local_timestamp": "2026-01-25T23:34:37.590465+00:00", "data": {"market": "0x27d685bdad61bf2f35948bcff8ddf673c14b72a6f4e9cf1a9d867be231f6a610", "price_changes": [{"asset_id": "82614941921461618729202933946512372479181705578801351216657431603405116134694", "price": "0.01", "size": "92.55", "side": "BUY", "hash": "99038db17ae66f8780d30e2397b361debcff0d53", "best_bid": "0.32", "best_ask": "0.38"}, {"asset_id": "32476227489805089000687418984234668312982619103362138837681249693289694597075", "price": "0.99", "size": "92.55", "side": "SELL", "hash": "dbb403ea1ca3991edbc111e5ecf211b0335072dd", "best_bid": "0.62", "best_ask": "0.68"}], "timestamp": "1769384077422", "event_type": "price_change"}}
{"_local_timestamp": "2026-01-25T23:34:37.971756+00:00", "data": {"market": "0xaeb02ced23cf66b235fb864ed82bdf7f7144c38cb0c7466e5f6c255a5c6015cc", "price_changes": [{"asset_id": "38866550321267038434460376745002272171027672578638559578882849128491520813825", "price": "0.021", "size": "5.47", "side": "SELL", "hash": "4a79378c4d7ef32370afc531c58179b2c83470f8", "best_bid": "0.002", "best_ask": "0.016"}, {"asset_id": "16066315103031518578542990703395510559372655158819085950817958432162905570385", "price": "0.979", "size": "5.47", "side": "BUY", "hash": "4391c1c0a7b1ec249e4b4821aafe3c582124bd15", "best_bid": "0.984", "best_ask": "0.998"}], "timestamp": "1769384077904", "event_type": "price_change"}}
{"_local_timestamp": "2026-01-25T23:34:37.997833+00:00", "data": {"market": "0x6ac594337fbd762ec04471e8d65806ff9ff78c33ed9dca4826c7bd2969475251", "price_changes": [{"asset_id": "79880305123726971124937075515339490140944001374542290672889526459108541617627", "price": "0.51", "size": "392", "side": "BUY", "hash": "d88ff16ced167313f6ae7b6119bcb5abeccc5566", "best_bid": "0.81", "best_ask": "0.86"}, {"asset_id": "115162358394175336212249289650926294268751651827332730207583087521345129280038", "price": "0.49", "size": "392", "side": "SELL", "hash": "07496d9f527ade3ab0111165060fbc6e1b5110c3", "best_bid": "0.14", "best_ask": "0.19"}], "timestamp": "1769384077926", "event_type": "price_change"}}
{"_local_timestamp": "2026-01-25T23:34:37.998646+00:00", "data": {"market": "0x54b69275ee145425f1a0dce69faef15f729f1ab3ec41bc2996a6c6c70e8aec0b", "price_changes": [{"asset_id": "44494068166094207162801090520618289188991411103177309101619626920967990930514", "price": "0.15", "size": "1333", "side": "BUY", "hash": "f908946b6fec444d32a50c91e75dbaef31bb18c3", "best_bid": "0.49", "best_ask": "0.54"}, {"asset_id": "106447080412815954453539138762045278580988736678171840293222199861758175727534", "price": "0.85", "size": "1333", "side": "SELL", "hash": "7a5c3ad35ba676c4c0a8a6d5bcc166726eaaef90", "best_bid": "0.46", "best_ask": "0.51"}], "timestamp": "1769384077926", "event_type": "price_change"}}
{"_local_timestamp": "2026-01-25T23:34:37.999492+00:00", "data": {"market": "0x242266c50482ad4f243610f7546b60089eadc1d81d4ef408c787f67aa3ef5e7c", "price_changes": [{"asset_id": "96533933355712544390418613060156510030240147080751769428940162257378106436404", "price": "0.15", "size": "1333", "side": "BUY", "hash": "40f84a4a4a1ecba4462990da55cda2fc8a497f41", "best_bid": "0.45", "best_ask": "0.49"}, {"asset_id": "28263250326920700075422198100613476697802143744104502510886484761449393244656", "price": "0.85", "size": "1333", "side": "SELL", "hash": "74ea44f9a687ab803c907e7493fedf924305c572", "best_bid": "0.51", "best_ask": "0.55"}], "timestamp": "1769384077926", "event_type": "price_change"}}
{"_local_timestamp": "2026-01-25T23:34:38.000275+00:00", "data": {"market": "0x6e5e9c218d780a8ff8b516cae97604958f7323ffd75b525d810fb804e727ad78", "price_changes": [{"asset_id": "4929915665740215533077513370523570724508699505795913150073424458746805119832", "price": "0.51", "size": "392", "side": "BUY", "hash": "ffb48c4dc707df5fd123be3a20ff1be356994d17", "best_bid": "0.78", "best_ask": "0.79"}, {"asset_id": "66190026636022120219272454910747143264277679901831317594304438527297253363875", "price": "0.49", "size": "392", "side": "SELL", "hash": "87ad624091808c4f5a4f9036a03e5e56bcde08cd", "best_bid": "0.21", "best_ask": "0.22"}], "timestamp": "1769384077926", "event_type": "price_change"}}
{"_local_timestamp": "2026-01-25T23:34:38.000987+00:00", "data": {"market": "0xcf18b8f0901452013dcdf957badd6bfb71a9935c6dd9dd2566dc5bb7f795c1a0", "price_changes": [{"asset_id": "86867607300025136841054177922135303037165603316339117668930743822611084804074", "price": "0.04", "size": "5000", "side": "BUY", "hash": "5131d9d053957ab0499fab98703c3ae76555abee", "best_bid": "0.37", "best_ask": "0.41"}, {"asset_id": "13301686528282766867573623232056946130992514687837926123264639755941579360230", "price": "0.96", "size": "5000", "side": "SELL", "hash": "8bc97aa73ff5fff839f219215b46e82f9b340f93", "best_bid": "0.59", "best_ask": "0.63"}], "timestamp": "1769384077926", "event_type": "price_change"}}
{"_local_timestamp": "2026-01-25T23:34:38.001745+00:00", "data": {"market": "0xdd3915ab9de231a4f8d1b6989b9d28c81a39d3372fc2f5e5d5e09c5c36bd15e0", "price_changes": [{"asset_id": "73772444484179123398639028358181122166565249885455240318019005512648163832892", "price": "0.02", "size": "10011.31", "side": "BUY", "hash": "8971b9685b3d6530b987277dae74eabfa82419a4", "best_bid": "0.32", "best_ask": "0.34"}, {"asset_id": "64912974742020396457447321385468313243213302286888804044150787878568707049629", "price": "0.98", "size": "10011.31", "side": "SELL", "hash": "9d3d73087636f6cb4b8de35cd6fe85f72867174b", "best_bid": "0.66", "best_ask": "0.68"}], "timestamp": "1769384077926", "event_type": "price_change"}}
{"_local_timestamp": "2026-01-25T23:34:38.002651+00:00", "data": {"market": "0x6ac594337fbd762ec04471e8d65806ff9ff78c33ed9dca4826c7bd2969475251", "price_changes": [{"asset_id": "115162358394175336212249289650926294268751651827332730207583087521345129280038", "price": "0.03", "size": "6666", "side": "BUY", "hash": "ae5b9e01581afaa0c2f5828cb50bbbf43606d883", "best_bid": "0.14", "best_ask": "0.19"}, {"asset_id": "79880305123726971124937075515339490140944001374542290672889526459108541617627", "price": "0.97", "size": "6666", "side": "SELL", "hash": "13db678fc4f760d65dfa28ba4f8a089b40adfd5a", "best_bid": "0.81", "best_ask": "0.86"}], "timestamp": "1769384077927", "event_type": "price_change"}}
{"_local_timestamp": "2026-01-25T23:34:38.003398+00:00", "data": {"market": "0x54b69275ee145425f1a0dce69faef15f729f1ab3ec41bc2996a6c6c70e8aec0b", "price_changes": [{"asset_id": "106447080412815954453539138762045278580988736678171840293222199861758175727534", "price": "0.15", "size": "1333", "side": "BUY", "hash": "37b09701868fd33aa36d10b3840aed290e7c3dc4", "best_bid": "0.46", "best_ask": "0.51"}, {"asset_id": "44494068166094207162801090520618289188991411103177309101619626920967990930514", "price": "0.85", "size": "1333", "side": "SELL", "hash": "03f7859e217d0b6bbec4c659dda5d1dce7ce1f64", "best_bid": "0.49", "best_ask": "0.54"}], "timestamp": "1769384077927", "event_type": "price_change"}}
{"_local_timestamp": "2026-01-25T23:34:38.102907+00:00", "data": {"market": "0xcf18b8f0901452013dcdf957badd6bfb71a9935c6dd9dd2566dc5bb7f795c1a0", "price_changes": [{"asset_id": "13301686528282766867573623232056946130992514687837926123264639755941579360230", "price": "0.28", "size": "714", "side": "BUY", "hash": "d4109d2571fefd0ec2594e4e58d3b1235cf325cf", "best_bid": "0.59", "best_ask": "0.63"}, {"asset_id": "86867607300025136841054177922135303037165603316339117668930743822611084804074", "price": "0.72", "size": "714", "side": "SELL", "hash": "a1bc86b98437a64c80bc65707c6f1a40a6e139f8", "best_bid": "0.37", "best_ask": "0.41"}], "timestamp": "1769384077927", "event_type": "price_change"}}
{"_local_timestamp": "2026-01-25T23:34:38.103632+00:00", "data": {"market": "0x242266c50482ad4f243610f7546b60089eadc1d81d4ef408c787f67aa3ef5e7c", "price_changes": [{"asset_id": "28263250326920700075422198100613476697802143744104502510886484761449393244656", "price": "0.21", "size": "952", "side": "BUY", "hash": "bcf9a1ab7ab34e1464a851383d4e44640c90d8c3", "best_bid": "0.51", "best_ask": "0.55"}, {"asset_id": "96533933355712544390418613060156510030240147080751769428940162257378106436404", "price": "0.79", "size": "952", "side": "SELL", "hash": "3fab67cde4e1ebc8c9f3201710322a2c33fcd746", "best_bid": "0.45", "best_ask": "0.49"}], "timestamp": "1769384077927", "event_type": "price_change"}}
{"_local_timestamp": "2026-01-25T23:34:38.122109+00:00", "data": {"market": "0xaeb02ced23cf66b235fb864ed82bdf7f7144c38cb0c7466e5f6c255a5c6015cc", "price_changes": [{"asset_id": "38866550321267038434460376745002272171027672578638559578882849128491520813825", "price": "0.015", "size": "24.69", "side": "SELL", "hash": "63ab68f32279221071aeb39b9ee272a4803aa0fd", "best_bid": "0.002", "best_ask": "0.015"}, {"asset_id": "16066315103031518578542990703395510559372655158819085950817958432162905570385", "price": "0.985", "size": "24.69", "side": "BUY", "hash": "e653da6c6a91d789b457ed19b21a75b154f6fcb0", "best_bid": "0.985", "best_ask": "0.998"}], "timestamp": "1769384077935", "event_type": "price_change"}}
{"_local_timestamp": "2026-01-25T23:34:38.122868+00:00", "data": {"market": "0xaeb02ced23cf66b235fb864ed82bdf7f7144c38cb0c7466e5f6c255a5c6015cc", "price_changes": [{"asset_id": "38866550321267038434460376745002272171027672578638559578882849128491520813825", "price": "0.016", "size": "13.11", "side": "SELL", "hash": "9f91190b694f7bf19f1f4b5b86c36f4e548f8b8c", "best_bid": "0.002", "best_ask": "0.015"}, {"asset_id": "16066315103031518578542990703395510559372655158819085950817958432162905570385", "price": "0.984", "size": "13.11", "side": "BUY", "hash": "6080a78ef1f5f52f64f8d010a31d8891bf78a8a0", "best_bid": "0.985", "best_ask": "0.998"}], "timestamp": "1769384078036", "event_type": "price_change"}}
{"_local_timestamp": "2026-01-25T23:34:38.123600+00:00", "data": {"market": "0xaeb02ced23cf66b235fb864ed82bdf7f7144c38cb0c7466e5f6c255a5c6015cc", "price_changes": [{"asset_id": "38866550321267038434460376745002272171027672578638559578882849128491520813825", "price": "0.018", "size": "0", "side": "SELL", "hash": "9f91190b694f7bf19f1f4b5b86c36f4e548f8b8c", "best_bid": "0.002", "best_ask": "0.015"}, {"asset_id": "16066315103031518578542990703395510559372655158819085950817958432162905570385", "price": "0.982", "size": "0", "side": "BUY", "hash": "6080a78ef1f5f52f64f8d010a31d8891bf78a8a0", "best_bid": "0.985", "best_ask": "0.998"}], "timestamp": "1769384078036", "event_type": "price_change"}}
{"_local_timestamp": "2026-01-25T23:34:38.241369+00:00", "data": {"market": "0x7573b38aa3d3d387be05d7e2b3fa5c397c6cbf1fbfbb5ccbe1d82816b901e9d1", "price_changes": [{"asset_id": "45963563720386640986457133827320203891928335132800978095470889439601833791792", "price": "0.4", "size": "500", "side": "BUY", "hash": "1f018fbf873c19b30b6e3b20644bca6fa533798c", "best_bid": "0.54", "best_ask": "0.55"}, {"asset_id": "47900911198961041897125947140815317810676260067603694036981412378636602096971", "price": "0.6", "size": "500", "side": "SELL", "hash": "d1afaf7c659efd76ab5734c79c959273315a9e02", "best_bid": "0.45", "best_ask": "0.46"}], "timestamp": "1769384078175", "event_type": "price_change"}}
{"_local_timestamp": "2026-01-25T23:34:38.242097+00:00", "data": {"market": "0x27d685bdad61bf2f35948bcff8ddf673c14b72a6f4e9cf1a9d867be231f6a610", "price_changes": [{"asset_id": "32476227489805089000687418984234668312982619103362138837681249693289694597075", "price": "0.21", "size": "952", "side": "BUY", "hash": "3887fa79f8261281954b639c3a71fb9818b11d85", "best_bid": "0.62", "best_ask": "0.68"}, {"asset_id": "82614941921461618729202933946512372479181705578801351216657431603405116134694", "price": "0.79", "size": "952", "side": "SELL", "hash": "b06f9c1b40ab2f395a1c9daf29d07df9989cae18", "best_bid": "0.32", "best_ask": "0.38"}], "timestamp": "1769384078175", "event_type": "price_change"}}
{"_local_timestamp": "2026-01-25T23:34:38.242748+00:00", "data": {"market": "0xdd3915ab9de231a4f8d1b6989b9d28c81a39d3372fc2f5e5d5e09c5c36bd15e0", "price_changes": [{"asset_id": "64912974742020396457447321385468313243213302286888804044150787878568707049629", "price": "0.35", "size": "571", "side": "BUY", "hash": "e8eec5c1609153f4b82ac90b0b3e0f9e62699346", "best_bid": "0.66", "best_ask": "0.68"}, {"asset_id": "73772444484179123398639028358181122166565249885455240318019005512648163832892", "price": "0.65", "size": "571", "side": "SELL", "hash": "278ea6667c05d058dbb4450141427a5c34145493", "best_bid": "0.32", "best_ask": "0.34"}], "timestamp": "1769384078175", "event_type": "price_change"}}
{"_local_timestamp": "2026-01-25T23:34:38.243382+00:00", "data": {"market": "0x6e5e9c218d780a8ff8b516cae97604958f7323ffd75b525d810fb804e727ad78", "price_changes": [{"asset_id": "66190026636022120219272454910747143264277679901831317594304438527297253363875", "price": "0.03", "size": "6666", "side": "BUY", "hash": "c96f5caa79698caf579a32114a167a76d31718e9", "best_bid": "0.21", "best_ask": "0.22"}, {"asset_id": "4929915665740215533077513370523570724508699505795913150073424458746805119832", "price": "0.97", "size": "6666", "side": "SELL", "hash": "0e30e90fed7c54fb5954c386dc5d56c20b109dd3", "best_bid": "0.78", "best_ask": "0.79"}], "timestamp": "1769384078176", "event_type": "price_change"}}
{"_local_timestamp": "2026-01-25T23:34:38.244143+00:00", "data": {"market": "0x7573b38aa3d3d387be05d7e2b3fa5c397c6cbf1fbfbb5ccbe1d82816b901e9d1", "price_changes": [{"asset_id": "47900911198961041897125947140815317810676260067603694036981412378636602096971", "price": "0.33", "size": "606", "side": "BUY", "hash": "132501aab41f567099fffb48a856794f7025b6a3", "best_bid": "0.45", "best_ask": "0.46"}, {"asset_id": "45963563720386640986457133827320203891928335132800978095470889439601833791792", "price": "0.67", "size": "606", "side": "SELL", "hash": "26e6c1c683a5e0d37f63855d30571c117784edc5", "best_bid": "0.54", "best_ask": "0.55"}], "timestamp": "1769384078176", "event_type": "price_change"}}
{"_local_timestamp": "2026-01-25T23:34:38.244765+00:00", "data": {"market": "0xaeb02ced23cf66b235fb864ed82bdf7f7144c38cb0c7466e5f6c255a5c6015cc", "price_changes": [{"asset_id": "16066315103031518578542990703395510559372655158819085950817958432162905570385", "price": "0.181", "size": "1104", "side": "BUY", "hash": "b773c7fecd554829b18f7e7db8a014355500e96a", "best_bid": "0.985", "best_ask": "0.998"}, {"asset_id": "38866550321267038434460376745002272171027672578638559578882849128491520813825", "price": "0.819", "size": "1104", "side": "SELL", "hash": "df51728341f9bf44aedd92484397503167714c95", "best_bid": "0.002", "best_ask": "0.015"}], "timestamp": "1769384078176", "event_type": "price_change"}}
{"_local_timestamp": "2026-01-25T23:34:38.257000+00:00", "data": {"market": "0x27d685bdad61bf2f35948bcff8ddf673c14b72a6f4e9cf1a9d867be231f6a610", "price_changes": [{"asset_id": "82614941921461618729202933946512372479181705578801351216657431603405116134694", "price": "0.02", "size": "10028.71", "side": "BUY", "hash": "84af263cdbf8148dcbc4d14521bd21fda43fb9b9", "best_bid": "0.32", "best_ask": "0.38"}, {"asset_id": "32476227489805089000687418984234668312982619103362138837681249693289694597075", "price": "0.98", "size": "10028.71", "side": "SELL", "hash": "a04fc81f537905b3598ea2bc81d4236756b99fb3", "best_bid": "0.62", "best_ask": "0.68"}], "timestamp": "1769384078176", "event_type": "price_change"}}
{"_local_timestamp": "2026-01-25T23:34:38.410073+00:00", "data": {"market": "0xaeb02ced23cf66b235fb864ed82bdf7f7144c38cb0c7466e5f6c255a5c6015cc", "price_changes": [{"asset_id": "38866550321267038434460376745002272171027672578638559578882849128491520813825", "price": "0.014", "size": "13.1", "side": "SELL", "hash": "65811e6a2ef49a312ca30a6d7d29fb736e7e338c", "best_bid": "0.002", "best_ask": "0.014"}, {"asset_id": "16066315103031518578542990703395510559372655158819085950817958432162905570385", "price": "0.986", "size": "13.1", "side": "BUY", "hash": "79c1affa336f793ecb011f74bf8586fb384e09b3", "best_bid": "0.986", "best_ask": "0.998"}], "timestamp": "1769384078347", "event_type": "price_change"}}
{"_local_timestamp": "2026-01-25T23:34:38.410944+00:00", "data": {"market": "0xaeb02ced23cf66b235fb864ed82bdf7f7144c38cb0c7466e5f6c255a5c6015cc", "price_changes": [{"asset_id": "38866550321267038434460376745002272171027672578638559578882849128491520813825", "price": "0.014", "size": "26.2", "side": "SELL", "hash": "026546ab1a4cc6037e98af0817d9ca14777d2fa3", "best_bid": "0.002", "best_ask": "0.014"}, {"asset_id": "16066315103031518578542990703395510559372655158819085950817958432162905570385", "price": "0.986", "size": "26.2", "side": "BUY", "hash": "475618d73786425930ce2a6af19fe60f6c7714b9", "best_bid": "0.986", "best_ask": "0.998"}], "timestamp": "1769384078347", "event_type": "price_change"}}
{"_local_timestamp": "2026-01-25T23:34:38.980376+00:00", "data": {"market": "0x27d685bdad61bf2f35948bcff8ddf673c14b72a6f4e9cf1a9d867be231f6a610", "price_changes": [{"asset_id": "82614941921461618729202933946512372479181705578801351216657431603405116134694", "price": "0.01", "size": "70.44", "side": "BUY", "hash": "d8502026c61b0522a76858702e50d55186e36003", "best_bid": "0.32", "best_ask": "0.38"}, {"asset_id": "32476227489805089000687418984234668312982619103362138837681249693289694597075", "price": "0.99", "size": "70.44", "side": "SELL", "hash": "1454468092afc1fa3082e130dcf9a1aede6052c0", "best_bid": "0.62", "best_ask": "0.68"}], "timestamp": "1769384078903", "event_type": "price_change"}}
{"_local_timestamp": "2026-01-25T23:34:38.981880+00:00", "data": {"market": "0x27d685bdad61bf2f35948bcff8ddf673c14b72a6f4e9cf1a9d867be231f6a610", "price_changes": [{"asset_id": "82614941921461618729202933946512372479181705578801351216657431603405116134694", "price": "0.02", "size": "10005.99", "side": "BUY", "hash": "d8502026c61b0522a76858702e50d55186e36003", "best_bid": "0.32", "best_ask": "0.38"}, {"asset_id": "32476227489805089000687418984234668312982619103362138837681249693289694597075", "price": "0.98", "size": "10005.99", "side": "SELL", "hash": "1454468092afc1fa3082e130dcf9a1aede6052c0", "best_bid": "0.62", "best_ask": "0.68"}], "timestamp": "1769384078903", "event_type": "price_change"}}
{"_local_timestamp": "2026-01-25T23:34:39.248902+00:00", "data": {"market": "0x27d685bdad61bf2f35948bcff8ddf673c14b72a6f4e9cf1a9d867be231f6a610", "price_changes": [{"asset_id": "82614941921461618729202933946512372479181705578801351216657431603405116134694", "price": "0.03", "size": "11.26", "side": "BUY", "hash": "e51f16f9556f2d20b89a0d5b7ec66d54d3868293", "best_bid": "0.32", "best_ask": "0.38"}, {"asset_id": "32476227489805089000687418984234668312982619103362138837681249693289694597075", "price": "0.97", "size": "11.26", "side": "SELL", "hash": "97509db816dae2a7c926e95a17f208e9cccd8b01", "best_bid": "0.62", "best_ask": "0.68"}], "timestamp": "1769384079140", "event_type": "price_change"}}
{"_local_timestamp": "2026-01-25T23:34:39.249776+00:00", "data": {"market": "0x27d685bdad61bf2f35948bcff8ddf673c14b72a6f4e9cf1a9d867be231f6a610", "price_changes": [{"asset_id": "82614941921461618729202933946512372479181705578801351216657431603405116134694", "price": "0.03", "size": "22.52", "side": "BUY", "hash": "1976592a624ea6aea0493474c2779dbc758f5d12", "best_bid": "0.32", "best_ask": "0.38"}, {"asset_id": "32476227489805089000687418984234668312982619103362138837681249693289694597075", "price": "0.97", "size": "22.52", "side": "SELL", "hash": "fa995acd402c4de222bf52214d5e0cf3227ebe25", "best_bid": "0.62", "best_ask": "0.68"}], "timestamp": "1769384079142", "event_type": "price_change"}}
{"_local_timestamp": "2026-01-25T23:34:39.280926+00:00", "data": {"market": "0xaeb02ced23cf66b235fb864ed82bdf7f7144c38cb0c7466e5f6c255a5c6015cc", "price_changes": [{"asset_id": "38866550321267038434460376745002272171027672578638559578882849128491520813825", "price": "0.015", "size": "0", "side": "SELL", "hash": "0b7998a7d53dce47d34a5be9d0b8fe086c93db91", "best_bid": "0.002", "best_ask": "0.014"}, {"asset_id": "16066315103031518578542990703395510559372655158819085950817958432162905570385", "price": "0.985", "size": "0", "side": "BUY", "hash": "9a0daa7d5a50877c5b65f887cc39ee86f4960337", "best_bid": "0.986", "best_ask": "0.998"}], "timestamp": "1769384079172", "event_type": "price_change"}}
{"_local_timestamp": "2026-01-25T23:34:39.347146+00:00", "data": {"market": "0xaeb02ced23cf66b235fb864ed82bdf7f7144c38cb0c7466e5f6c255a5c6015cc", "price_changes": [{"asset_id": "38866550321267038434460376745002272171027672578638559578882849128491520813825", "price": "0.021", "size": "30.16", "side": "SELL", "hash": "c52552c3cdd78b0c27e5fabba75dc7f85a0623ed", "best_bid": "0.002", "best_ask": "0.014"}, {"asset_id": "16066315103031518578542990703395510559372655158819085950817958432162905570385", "price": "0.979", "size": "30.16", "side": "BUY", "hash": "3ced2fbbf89580f8889c7c9d1a406516a7323da3", "best_bid": "0.986", "best_ask": "0.998"}], "timestamp": "1769384079212", "event_type": "price_change"}}
{"_local_timestamp": "2026-01-25T23:34:39.818959+00:00", "data": {"market": "0x6ac594337fbd762ec04471e8d65806ff9ff78c33ed9dca4826c7bd2969475251", "price_changes": [{"asset_id": "115162358394175336212249289650926294268751651827332730207583087521345129280038", "price": "0.01", "size": "50", "side": "BUY", "hash": "9aafdcdcbbae4c5d43c897d8faf8d410c7a6e55e", "best_bid": "0.14", "best_ask": "0.19"}, {"asset_id": "79880305123726971124937075515339490140944001374542290672889526459108541617627", "price": "0.99", "size": "50", "side": "SELL", "hash": "192a28ef18fba10d472f2961f9731633dcdce56f", "best_bid": "0.81", "best_ask": "0.86"}], "timestamp": "1769384079747", "event_type": "price_change"}}
{"_local_timestamp": "2026-01-25T23:34:39.819785+00:00", "data": {"market": "0x6ac594337fbd762ec04471e8d65806ff9ff78c33ed9dca4826c7bd2969475251", "price_changes": [{"asset_id": "115162358394175336212249289650926294268751651827332730207583087521345129280038", "price": "0.02", "size": "0", "side": "BUY", "hash": "9aafdcdcbbae4c5d43c897d8faf8d410c7a6e55e", "best_bid": "0.14", "best_ask": "0.19"}, {"asset_id": "79880305123726971124937075515339490140944001374542290672889526459108541617627", "price": "0.98", "size": "0", "side": "SELL", "hash": "192a28ef18fba10d472f2961f9731633dcdce56f", "best_bid": "0.81", "best_ask": "0.86"}], "timestamp": "1769384079747", "event_type": "price_change"}}
{"_local_timestamp": "2026-01-25T23:34:40.219125+00:00", "data": {"market": "0x6ac594337fbd762ec04471e8d65806ff9ff78c33ed9dca4826c7bd2969475251", "price_changes": [{"asset_id": "115162358394175336212249289650926294268751651827332730207583087521345129280038", "price": "0.04", "size": "20.27", "side": "BUY", "hash": "5e090702033b39eebe67b0958cdfd44c4c51bd43", "best_bid": "0.14", "best_ask": "0.19"}, {"asset_id": "79880305123726971124937075515339490140944001374542290672889526459108541617627", "price": "0.96", "size": "20.27", "side": "SELL", "hash": "ef376cb4a40b332bd47234ec8eaed96f40a8211d", "best_bid": "0.81", "best_ask": "0.86"}], "timestamp": "1769384080045", "event_type": "price_change"}}
{"_local_timestamp": "2026-01-25T23:34:40.220146+00:00", "data": {"market": "0x6ac594337fbd762ec04471e8d65806ff9ff78c33ed9dca4826c7bd2969475251", "price_changes": [{"asset_id": "115162358394175336212249289650926294268751651827332730207583087521345129280038", "price": "0.02", "size": "9.45", "side": "BUY", "hash": "d6e9c85f023985b51baee31b027433a6c3052b1f", "best_bid": "0.14", "best_ask": "0.19"}, {"asset_id": "79880305123726971124937075515339490140944001374542290672889526459108541617627", "price": "0.98", "size": "9.45", "side": "SELL", "hash": "d060c371650253a95c179e53facaf2c4eb743ea3", "best_bid": "0.81", "best_ask": "0.86"}], "timestamp": "1769384080047", "event_type": "price_change"}}
{"_local_timestamp": "2026-01-25T23:34:40.334568+00:00", "data": {"market": "0xaeb02ced23cf66b235fb864ed82bdf7f7144c38cb0c7466e5f6c255a5c6015cc", "price_changes": [{"asset_id": "38866550321267038434460376745002272171027672578638559578882849128491520813825", "price": "0.014", "size": "13.1", "side": "SELL", "hash": "ffa54e571893e2f3c3e9af1d2d84b6708174cddb", "best_bid": "0.002", "best_ask": "0.014"}, {"asset_id": "16066315103031518578542990703395510559372655158819085950817958432162905570385", "price": "0.986", "size": "13.1", "side": "BUY", "hash": "b461695174eabbd7c4e74a325010912cea462193", "best_bid": "0.986", "best_ask": "0.998"}], "timestamp": "1769384080173", "event_type": "price_change"}}
{"_local_timestamp": "2026-01-25T23:34:40.335430+00:00", "data": {"market": "0xaeb02ced23cf66b235fb864ed82bdf7f7144c38cb0c7466e5f6c255a5c6015cc", "price_changes": [{"asset_id": "38866550321267038434460376745002272171027672578638559578882849128491520813825", "price": "0.016", "size": "0", "side": "SELL", "hash": "ffa54e571893e2f3c3e9af1d2d84b6708174cddb", "best_bid": "0.002", "best_ask": "0.014"}, {"asset_id": "16066315103031518578542990703395510559372655158819085950817958432162905570385", "price": "0.984", "size": "0", "side": "BUY", "hash": "b461695174eabbd7c4e74a325010912cea462193", "best_bid": "0.986", "best_ask": "0.998"}], "timestamp": "1769384080173", "event_type": "price_change"}}
{"_local_timestamp": "2026-01-25T23:34:40.711221+00:00", "data": {"market": "0xaeb02ced23cf66b235fb864ed82bdf7f7144c38cb0c7466e5f6c255a5c6015cc", "price_changes": [{"asset_id": "38866550321267038434460376745002272171027672578638559578882849128491520813825", "price": "0.013", "size": "6.55", "side": "SELL", "hash": "06449740667288b67cdb8314ed45b76cec03a4b4", "best_bid": "0.002", "best_ask": "0.013"}, {"asset_id": "16066315103031518578542990703395510559372655158819085950817958432162905570385", "price": "0.987", "size": "6.55", "side": "BUY", "hash": "368d744091eebd1d534a9ba431ca1fada55204d9", "best_bid": "0.987", "best_ask": "0.998"}], "timestamp": "1769384080585", "event_type": "price_change"}}
{"_local_timestamp": "2026-01-25T23:34:40.712105+00:00", "data": {"market": "0xaeb02ced23cf66b235fb864ed82bdf7f7144c38cb0c7466e5f6c255a5c6015cc", "price_changes": [{"asset_id": "38866550321267038434460376745002272171027672578638559578882849128491520813825", "price": "0.015", "size": "6.56", "side": "SELL", "hash": "ca4968c872ce3ced25e38b94671a12c6f5311b97", "best_bid": "0.002", "best_ask": "0.013"}, {"asset_id": "16066315103031518578542990703395510559372655158819085950817958432162905570385", "price": "0.985", "size": "6.56", "side": "BUY", "hash": "f27266c92525ddf911ab7d72fc7b8b5d5d99c32d", "best_bid": "0.987", "best_ask": "0.998"}], "timestamp": "1769384080586", "event_type": "price_change"}}
{"_local_timestamp": "2026-01-25T23:34:40.712799+00:00", "data": {"market": "0xaeb02ced23cf66b235fb864ed82bdf7f7144c38cb0c7466e5f6c255a5c6015cc", "price_changes": [{"asset_id": "38866550321267038434460376745002272171027672578638559578882849128491520813825", "price": "0.013", "size": "13.1", "side": "SELL", "hash": "aa9fe84a4bc61ed78adca547c0025d405b452db4", "best_bid": "0.002", "best_ask": "0.013"}, {"asset_id": "16066315103031518578542990703395510559372655158819085950817958432162905570385", "price": "0.987", "size": "13.1", "side": "BUY", "hash": "fe71d669ebc5407f7ea01e7c0c0828989baa0589", "best_bid": "0.987", "best_ask": "0.998"}], "timestamp": "1769384080587", "event_type": "price_change"}}
{"_local_timestamp": "2026-01-25T23:34:40.713552+00:00", "data": {"market": "0xaeb02ced23cf66b235fb864ed82bdf7f7144c38cb0c7466e5f6c255a5c6015cc", "price_changes": [{"asset_id": "38866550321267038434460376745002272171027672578638559578882849128491520813825", "price": "0.015", "size": "13.12", "side": "SELL", "hash": "92584e377395e9ef1bceb3ec38b2d5e1e4bfab69", "best_bid": "0.002", "best_ask": "0.013"}, {"asset_id": "16066315103031518578542990703395510559372655158819085950817958432162905570385", "price": "0.985", "size": "13.12", "side": "BUY", "hash": "4275f170c95b083fd3c040518eadccb81075392d", "best_bid": "0.987", "best_ask": "0.998"}], "timestamp": "1769384080587", "event_type": "price_change"}}
{"_local_timestamp": "2026-01-25T23:34:40.723375+00:00", "data": {"market": "0x27d685bdad61bf2f35948bcff8ddf673c14b72a6f4e9cf1a9d867be231f6a610", "price_changes": [{"asset_id": "82614941921461618729202933946512372479181705578801351216657431603405116134694", "price": "0.01", "size": "61.34", "side": "BUY", "hash": "00447b21c630927b5e3a2173043f618fb793a811", "best_bid": "0.32", "best_ask": "0.38"}, {"asset_id": "32476227489805089000687418984234668312982619103362138837681249693289694597075", "price": "0.99", "size": "61.34", "side": "SELL", "hash": "454e10cc4385f8a56d02521039323472f6d756c4", "best_bid": "0.62", "best_ask": "0.68"}], "timestamp": "1769384080604", "event_type": "price_change"}}
{"_local_timestamp": "2026-01-25T23:34:40.724176+00:00", "data": {"market": "0x27d685bdad61bf2f35948bcff8ddf673c14b72a6f4e9cf1a9d867be231f6a610", "price_changes": [{"asset_id": "82614941921461618729202933946512372479181705578801351216657431603405116134694", "price": "0.02", "size": "10000", "side": "BUY", "hash": "00447b21c630927b5e3a2173043f618fb793a811", "best_bid": "0.32", "best_ask": "0.38"}, {"asset_id": "32476227489805089000687418984234668312982619103362138837681249693289694597075", "price": "0.98", "size": "10000", "side": "SELL", "hash": "454e10cc4385f8a56d02521039323472f6d756c4", "best_bid": "0.62", "best_ask": "0.68"}], "timestamp": "1769384080604", "event_type": "price_change"}}
{"_local_timestamp": "2026-01-25T23:34:40.935446+00:00", "data": {"market": "0xcf18b8f0901452013dcdf957badd6bfb71a9935c6dd9dd2566dc5bb7f795c1a0", "price_changes": [{"asset_id": "86867607300025136841054177922135303037165603316339117668930743822611084804074", "price": "0.03", "size": "0", "side": "BUY", "hash": "00957b94510406031fea32b152fdf09b15a6a24a", "best_bid": "0.37", "best_ask": "0.41"}, {"asset_id": "13301686528282766867573623232056946130992514687837926123264639755941579360230", "price": "0.97", "size": "0", "side": "SELL", "hash": "0fee2a2a01a06ecb98de7e2500d7483cf796f5ed", "best_bid": "0.59", "best_ask": "0.63"}], "timestamp": "1769384080852", "event_type": "price_change"}}
{"_local_timestamp": "2026-01-25T23:34:40.939258+00:00", "data": {"market": "0x54b69275ee145425f1a0dce69faef15f729f1ab3ec41bc2996a6c6c70e8aec0b", "price_changes": [{"asset_id": "106447080412815954453539138762045278580988736678171840293222199861758175727534", "price": "0.14", "size": "0", "side": "BUY", "hash": "67ba6400f6482733e282715c7b4709b4a1516f7d", "best_bid": "0.46", "best_ask": "0.51"}, {"asset_id": "44494068166094207162801090520618289188991411103177309101619626920967990930514", "price": "0.86", "size": "0", "side": "SELL", "hash": "8eaaba7837eba779b1b0745c22a2682fd2516188", "best_bid": "0.49", "best_ask": "0.54"}], "timestamp": "1769384080853", "event_type": "price_change"}}
{"_local_timestamp": "2026-01-25T23:34:40.939993+00:00", "data": {"market": "0x242266c50482ad4f243610f7546b60089eadc1d81d4ef408c787f67aa3ef5e7c", "price_changes": [{"asset_id": "96533933355712544390418613060156510030240147080751769428940162257378106436404", "price": "0.14", "size": "0", "side": "BUY", "hash": "79c0a525a805825f45f3faa7ca07f59390c63aae", "best_bid": "0.45", "best_ask": "0.49"}, {"asset_id": "28263250326920700075422198100613476697802143744104502510886484761449393244656", "price": "0.86", "size": "0", "side": "SELL", "hash": "e9b2655ec1cf47920b8afb83b3816a9870da1a1f", "best_bid": "0.51", "best_ask": "0.55"}], "timestamp": "1769384080852", "event_type": "price_change"}}
{"_local_timestamp": "2026-01-25T23:34:41.098026+00:00", "data": {"market": "0x27d685bdad61bf2f35948bcff8ddf673c14b72a6f4e9cf1a9d867be231f6a610", "price_changes": [{"asset_id": "82614941921461618729202933946512372479181705578801351216657431603405116134694", "price": "0.03", "size": "29.55", "side": "BUY", "hash": "81507829fe23b61d41cf40f2d41da5882987fcd4", "best_bid": "0.32", "best_ask": "0.38"}, {"asset_id": "32476227489805089000687418984234668312982619103362138837681249693289694597075", "price": "0.97", "size": "29.55", "side": "SELL", "hash": "0d22102b01a69e94fde966b17f2d0d0eb096d160", "best_bid": "0.62", "best_ask": "0.68"}], "timestamp": "1769384081025", "event_type": "price_change"}}
{"_local_timestamp": "2026-01-25T23:34:41.230828+00:00", "data": {"market": "0x27d685bdad61bf2f35948bcff8ddf673c14b72a6f4e9cf1a9d867be231f6a610", "price_changes": [{"asset_id": "82614941921461618729202933946512372479181705578801351216657431603405116134694", "price": "0.03", "size": "129.55", "side": "BUY", "hash": "0a7ee71931b2fa6bd06f3c88079445a26f7cddc4", "best_bid": "0.32", "best_ask": "0.38"}, {"asset_id": "32476227489805089000687418984234668312982619103362138837681249693289694597075", "price": "0.97", "size": "129.55", "side": "SELL", "hash": "22bf3b94a7fbb37e3f06c30e4049ea1984a2dfd2", "best_bid": "0.62", "best_ask": "0.68"}], "timestamp": "1769384081146", "event_type": "price_change"}}
{"_local_timestamp": "2026-01-25T23:34:41.231564+00:00", "data": {"market": "0xcf18b8f0901452013dcdf957badd6bfb71a9935c6dd9dd2566dc5bb7f795c1a0", "price_changes": [{"asset_id": "86867607300025136841054177922135303037165603316339117668930743822611084804074", "price": "0.05", "size": "100", "side": "BUY", "hash": "4190b7b71acbeae9dc32c5dfdadc58b7ff46e3cb", "best_bid": "0.37", "best_ask": "0.41"}, {"asset_id": "13301686528282766867573623232056946130992514687837926123264639755941579360230", "price": "0.95", "size": "100", "side": "SELL", "hash": "6c9a2c510aa0005fd4e10f0ba111c1bf3215ddb2", "best_bid": "0.59", "best_ask": "0.63"}], "timestamp": "1769384081146", "event_type": "price_change"}}
{"_local_timestamp": "2026-01-25T23:34:41.232256+00:00", "data": {"market": "0xdd3915ab9de231a4f8d1b6989b9d28c81a39d3372fc2f5e5d5e09c5c36bd15e0", "price_changes": [{"asset_id": "73772444484179123398639028358181122166565249885455240318019005512648163832892", "price": "0.05", "size": "100", "side": "BUY", "hash": "caa3801554124973d1c6a18474baa9676ae17526", "best_bid": "0.32", "best_ask": "0.34"}, {"asset_id": "64912974742020396457447321385468313243213302286888804044150787878568707049629", "price": "0.95", "size": "100", "side": "SELL", "hash": "6357679baef88e725c95cc459f8bc17c8fda6a04", "best_bid": "0.66", "best_ask": "0.68"}], "timestamp": "1769384081146", "event_type": "price_change"}}
{"_local_timestamp": "2026-01-25T23:34:41.232916+00:00", "data": {"market": "0x54b69275ee145425f1a0dce69faef15f729f1ab3ec41bc2996a6c6c70e8aec0b", "price_changes": [{"asset_id": "106447080412815954453539138762045278580988736678171840293222199861758175727534", "price": "0.16", "size": "50", "side": "BUY", "hash": "79ac3728e6073a8cd460283da4be8b6225031ad4", "best_bid": "0.46", "best_ask": "0.51"}, {"asset_id": "44494068166094207162801090520618289188991411103177309101619626920967990930514", "price": "0.84", "size": "50", "side": "SELL", "hash": "b9858e8c59ef0673f18eb04ebcfb649d98def35c", "best_bid": "0.49", "best_ask": "0.54"}], "timestamp": "1769384081146", "event_type": "price_change"}}
{"_local_timestamp": "2026-01-25T23:34:41.233587+00:00", "data": {"market": "0x242266c50482ad4f243610f7546b60089eadc1d81d4ef408c787f67aa3ef5e7c", "price_changes": [{"asset_id": "96533933355712544390418613060156510030240147080751769428940162257378106436404", "price": "0.16", "size": "50", "side": "BUY", "hash": "66fc44fd1afb0916659f25aa8c228184df0d0686", "best_bid": "0.45", "best_ask": "0.49"}, {"asset_id": "28263250326920700075422198100613476697802143744104502510886484761449393244656", "price": "0.84", "size": "50", "side": "SELL", "hash": "117f8d1556eb6da31d5a0dcae8699bbe74b9ddf3", "best_bid": "0.51", "best_ask": "0.55"}], "timestamp": "1769384081146", "event_type": "price_change"}}
{"_local_timestamp": "2026-01-25T23:34:42.409288+00:00", "data": {"market": "0x54b69275ee145425f1a0dce69faef15f729f1ab3ec41bc2996a6c6c70e8aec0b", "price_changes": [{"asset_id": "106447080412815954453539138762045278580988736678171840293222199861758175727534", "price": "0.01", "size": "50", "side": "BUY", "hash": "8c2676dda454b06b5b09f760e9f096ccb0a149ef", "best_bid": "0.46", "best_ask": "0.51"}, {"asset_id": "44494068166094207162801090520618289188991411103177309101619626920967990930514", "price": "0.99", "size": "50", "side": "SELL", "hash": "a4863db7b271fa501cdc906c3511b5d5b38eeb37", "best_bid": "0.49", "best_ask": "0.54"}], "timestamp": "1769384082342", "event_type": "price_change"}}
{"_local_timestamp": "2026-01-25T23:34:42.651001+00:00", "data": {"market": "0x54b69275ee145425f1a0dce69faef15f729f1ab3ec41bc2996a6c6c70e8aec0b", "price_changes": [{"asset_id": "106447080412815954453539138762045278580988736678171840293222199861758175727534", "price": "0.01", "size": "65.3", "side": "BUY", "hash": "4381ec06979c9614aac65d79edc659bfc90e1c3d", "best_bid": "0.46", "best_ask": "0.51"}, {"asset_id": "44494068166094207162801090520618289188991411103177309101619626920967990930514", "price": "0.99", "size": "65.3", "side": "SELL", "hash": "0acd60b7fec4203d9de5cd5ee754e1d184dc4cf6", "best_bid": "0.49", "best_ask": "0.54"}], "timestamp": "1769384082583", "event_type": "price_change"}}
{"_local_timestamp": "2026-01-25T23:34:42.833927+00:00", "data": {"market": "0xaeb02ced23cf66b235fb864ed82bdf7f7144c38cb0c7466e5f6c255a5c6015cc", "price_changes": [{"asset_id": "38866550321267038434460376745002272171027672578638559578882849128491520813825", "price": "0.013", "size": "6.55", "side": "SELL", "hash": "43240beaab00bc6f491596bc6a067355ad42bd9f", "best_bid": "0.002", "best_ask": "0.013"}, {"asset_id": "16066315103031518578542990703395510559372655158819085950817958432162905570385", "price": "0.987", "size": "6.55", "side": "BUY", "hash": "13764e3db9e656725a510fd22fa14ecd3e79d827", "best_bid": "0.987", "best_ask": "0.998"}], "timestamp": "1769384082766", "event_type": "price_change"}}
{"_local_timestamp": "2026-01-25T23:34:42.834686+00:00", "data": {"market": "0xaeb02ced23cf66b235fb864ed82bdf7f7144c38cb0c7466e5f6c255a5c6015cc", "price_changes": [{"asset_id": "38866550321267038434460376745002272171027672578638559578882849128491520813825", "price": "0.014", "size": "0", "side": "SELL", "hash": "43240beaab00bc6f491596bc6a067355ad42bd9f", "best_bid": "0.002", "best_ask": "0.013"}, {"asset_id": "16066315103031518578542990703395510559372655158819085950817958432162905570385", "price": "0.986", "size": "0", "side": "BUY", "hash": "13764e3db9e656725a510fd22fa14ecd3e79d827", "best_bid": "0.987", "best_ask": "0.998"}], "timestamp": "1769384082766", "event_type": "price_change"}}
{"_local_timestamp": "2026-01-25T23:34:42.835364+00:00", "data": {"market": "0xaeb02ced23cf66b235fb864ed82bdf7f7144c38cb0c7466e5f6c255a5c6015cc", "price_changes": [{"asset_id": "38866550321267038434460376745002272171027672578638559578882849128491520813825", "price": "0.015", "size": "6.56", "side": "SELL", "hash": "43240beaab00bc6f491596bc6a067355ad42bd9f", "best_bid": "0.002", "best_ask": "0.013"}, {"asset_id": "16066315103031518578542990703395510559372655158819085950817958432162905570385", "price": "0.985", "size": "6.56", "side": "BUY", "hash": "13764e3db9e656725a510fd22fa14ecd3e79d827", "best_bid": "0.987", "best_ask": "0.998"}], "timestamp": "1769384082766", "event_type": "price_change"}}
{"_local_timestamp": "2026-01-25T23:34:43.126505+00:00", "data": {"market": "0xaeb02ced23cf66b235fb864ed82bdf7f7144c38cb0c7466e5f6c255a5c6015cc", "price_changes": [{"asset_id": "38866550321267038434460376745002272171027672578638559578882849128491520813825", "price": "0.02", "size": "13.1", "side": "SELL", "hash": "2b86034ed0f230a0889c72bad2534f6e28078066", "best_bid": "0.002", "best_ask": "0.013"}, {"asset_id": "16066315103031518578542990703395510559372655158819085950817958432162905570385", "price": "0.98", "size": "13.1", "side": "BUY", "hash": "09c168cf7a93afbb702626f73a8fa4f4e2779a5d", "best_bid": "0.987", "best_ask": "0.998"}], "timestamp": "1769384083023", "event_type": "price_change"}}
{"_local_timestamp": "2026-01-25T23:34:43.127413+00:00", "data": {"market": "0xaeb02ced23cf66b235fb864ed82bdf7f7144c38cb0c7466e5f6c255a5c6015cc", "price_changes": [{"asset_id": "38866550321267038434460376745002272171027672578638559578882849128491520813825", "price": "0.02", "size": "26.2", "side": "SELL", "hash": "3aa1fd396aaae73d7e5e6fd976c4636e0642727c", "best_bid": "0.002", "best_ask": "0.013"}, {"asset_id": "16066315103031518578542990703395510559372655158819085950817958432162905570385", "price": "0.98", "size": "26.2", "side": "BUY", "hash": "5924a40a57a01800425d256c6e751b9590f4eea9", "best_bid": "0.987", "best_ask": "0.998"}], "timestamp": "1769384083023", "event_type": "price_change"}}
{"_local_timestamp": "2026-01-25T23:34:43.678961+00:00", "data": {"market": "0x27d685bdad61bf2f35948bcff8ddf673c14b72a6f4e9cf1a9d867be231f6a610", "price_changes": [{"asset_id": "82614941921461618729202933946512372479181705578801351216657431603405116134694", "price": "0.01", "size": "55.67", "side": "BUY", "hash": "779cfe90a90de75bd2a150805554f7a7bcfc7033", "best_bid": "0.32", "best_ask": "0.38"}, {"asset_id": "32476227489805089000687418984234668312982619103362138837681249693289694597075", "price": "0.99", "size": "55.67", "side": "SELL", "hash": "6cf53528d4b2f746a36460814694968fae8af056", "best_bid": "0.62", "best_ask": "0.68"}], "timestamp": "1769384083613", "event_type": "price_change"}}
{"_local_timestamp": "2026-01-25T23:34:43.679912+00:00", "data": {"market": "0x27d685bdad61bf2f35948bcff8ddf673c14b72a6f4e9cf1a9d867be231f6a610", "price_changes": [{"asset_id": "82614941921461618729202933946512372479181705578801351216657431603405116134694", "price": "0.03", "size": "107.03", "side": "BUY", "hash": "779cfe90a90de75bd2a150805554f7a7bcfc7033", "best_bid": "0.32", "best_ask": "0.38"}, {"asset_id": "32476227489805089000687418984234668312982619103362138837681249693289694597075", "price": "0.97", "size": "107.03", "side": "SELL", "hash": "6cf53528d4b2f746a36460814694968fae8af056", "best_bid": "0.62", "best_ask": "0.68"}], "timestamp": "1769384083613", "event_type": "price_change"}}
{"_local_timestamp": "2026-01-25T23:34:44.015072+00:00", "data": {"market": "0x27d685bdad61bf2f35948bcff8ddf673c14b72a6f4e9cf1a9d867be231f6a610", "price_changes": [{"asset_id": "82614941921461618729202933946512372479181705578801351216657431603405116134694", "price": "0.04", "size": "9.15", "side": "BUY", "hash": "e65b95f9db47d6590e7e1d7866316a8679d56565", "best_bid": "0.32", "best_ask": "0.38"}, {"asset_id": "32476227489805089000687418984234668312982619103362138837681249693289694597075", "price": "0.96", "size": "9.15", "side": "SELL", "hash": "cc97570f8ec93a97e3d3dffa6abd11ddb1cadb53", "best_bid": "0.62", "best_ask": "0.68"}], "timestamp": "1769384083941", "event_type": "price_change"}}
{"_local_timestamp": "2026-01-25T23:34:44.015903+00:00", "data": {"market": "0x27d685bdad61bf2f35948bcff8ddf673c14b72a6f4e9cf1a9d867be231f6a610", "price_changes": [{"asset_id": "82614941921461618729202933946512372479181705578801351216657431603405116134694", "price": "0.04", "size": "18.3", "side": "BUY", "hash": "9cffcac6e34755fe021a694703a14b31026f963b", "best_bid": "0.32", "best_ask": "0.38"}, {"asset_id": "32476227489805089000687418984234668312982619103362138837681249693289694597075", "price": "0.96", "size": "18.3", "side": "SELL", "hash": "e2c4f2d5f5fe7dcb24b68cc58be8b72d6a405f73", "best_bid": "0.62", "best_ask": "0.68"}], "timestamp": "1769384083942", "event_type": "price_change"}}
{"_local_timestamp": "2026-01-25T23:34:44.071604+00:00", "data": {"market": "0xcf18b8f0901452013dcdf957badd6bfb71a9935c6dd9dd2566dc5bb7f795c1a0", "price_changes": [{"asset_id": "13301686528282766867573623232056946130992514687837926123264639755941579360230", "price": "0.28", "size": "0", "side": "BUY", "hash": "6ad3cf6740cf50b515779d366fed2ab5e1da899b", "best_bid": "0.59", "best_ask": "0.63"}, {"asset_id": "86867607300025136841054177922135303037165603316339117668930743822611084804074", "price": "0.72", "size": "0", "side": "SELL", "hash": "7f287c44e36dcce10dc23a4028caf1eb0f1a6015", "best_bid": "0.37", "best_ask": "0.41"}], "timestamp": "1769384084000", "event_type": "price_change"}}
{"_local_timestamp": "2026-01-25T23:34:44.072448+00:00", "data": {"market": "0xdd3915ab9de231a4f8d1b6989b9d28c81a39d3372fc2f5e5d5e09c5c36bd15e0", "price_changes": [{"asset_id": "73772444484179123398639028358181122166565249885455240318019005512648163832892", "price": "0.02", "size": "11.31", "side": "BUY", "hash": "08fe7bd14745ac0276d4e2b2e2a171a7fa2fb8ae", "best_bid": "0.32", "best_ask": "0.34"}, {"asset_id": "64912974742020396457447321385468313243213302286888804044150787878568707049629", "price": "0.98", "size": "11.31", "side": "SELL", "hash": "89c72865ed253c132c55901bf0d68e4db0e2bea9", "best_bid": "0.66", "best_ask": "0.68"}], "timestamp": "1769384084001", "event_type": "price_change"}}
{"_local_timestamp": "2026-01-25T23:34:44.073177+00:00", "data": {"market": "0x54b69275ee145425f1a0dce69faef15f729f1ab3ec41bc2996a6c6c70e8aec0b", "price_changes": [{"asset_id": "106447080412815954453539138762045278580988736678171840293222199861758175727534", "price": "0.15", "size": "0", "side": "BUY", "hash": "91207c169ede1eeb87168664ccceea92dbad6d14", "best_bid": "0.46", "best_ask": "0.51"}, {"asset_id": "44494068166094207162801090520618289188991411103177309101619626920967990930514", "price": "0.85", "size": "0", "side": "SELL", "hash": "bc41cedc39d1c0f3b837fc1e074b4b4f53bd1ea2", "best_bid": "0.49", "best_ask": "0.54"}], "timestamp": "1769384084000", "event_type": "price_change"}}
{"_local_timestamp": "2026-01-25T23:34:44.083459+00:00", "data": {"market": "0x54b69275ee145425f1a0dce69faef15f729f1ab3ec41bc2996a6c6c70e8aec0b", "price_changes": [{"asset_id": "44494068166094207162801090520618289188991411103177309101619626920967990930514", "price": "0.15", "size": "0", "side": "BUY", "hash": "a33464f71a47ec9baa606edc9b275462272f4ff6", "best_bid": "0.49", "best_ask": "0.54"}, {"asset_id": "106447080412815954453539138762045278580988736678171840293222199861758175727534", "price": "0.85", "size": "0", "side": "SELL", "hash": "ca6a7dcad5a0c2d86e3b080f1c506be57becdad2", "best_bid": "0.46", "best_ask": "0.51"}], "timestamp": "1769384084001", "event_type": "price_change"}}
{"_local_timestamp": "2026-01-25T23:34:44.084291+00:00", "data": {"market": "0xcf18b8f0901452013dcdf957badd6bfb71a9935c6dd9dd2566dc5bb7f795c1a0", "price_changes": [{"asset_id": "86867607300025136841054177922135303037165603316339117668930743822611084804074", "price": "0.04", "size": "0", "side": "BUY", "hash": "5d6d2d9ada8d9e22ebb59ec0c9880015a34268db", "best_bid": "0.37", "best_ask": "0.41"}, {"asset_id": "13301686528282766867573623232056946130992514687837926123264639755941579360230", "price": "0.96", "size": "0", "side": "SELL", "hash": "1b7e145e1b137510441bf42c74dbcfc22af0083d", "best_bid": "0.59", "best_ask": "0.63"}], "timestamp": "1769384084001", "event_type": "price_change"}}
{"_local_timestamp": "2026-01-25T23:34:44.085004+00:00", "data": {"market": "0x242266c50482ad4f243610f7546b60089eadc1d81d4ef408c787f67aa3ef5e7c", "price_changes": [{"asset_id": "28263250326920700075422198100613476697802143744104502510886484761449393244656", "price": "0.21", "size": "0", "side": "BUY", "hash": "b96c84baab9e1f309fb2ad0d67751ac276f68845", "best_bid": "0.51", "best_ask": "0.55"}, {"asset_id": "96533933355712544390418613060156510030240147080751769428940162257378106436404", "price": "0.79", "size": "0", "side": "SELL", "hash": "d54b5befd3df6e0f3a8b2fad04c63cde3e906c29", "best_bid": "0.45", "best_ask": "0.49"}], "timestamp": "1769384084002", "event_type": "price_change"}}
{"_local_timestamp": "2026-01-25T23:34:44.144076+00:00", "data": {"market": "0x6e5e9c218d780a8ff8b516cae97604958f7323ffd75b525d810fb804e727ad78", "price_changes": [{"asset_id": "4929915665740215533077513370523570724508699505795913150073424458746805119832", "price": "0.51", "size": "0", "side": "BUY", "hash": "44870a32b1cfec57c0d0723b35fd6705f4fbcb03", "best_bid": "0.78", "best_ask": "0.79"}, {"asset_id": "66190026636022120219272454910747143264277679901831317594304438527297253363875", "price": "0.49", "size": "0", "side": "SELL", "hash": "2e935f1c741fcee2a5cc8d28f00ee691c06154b6", "best_bid": "0.21", "best_ask": "0.22"}], "timestamp": "1769384084002", "event_type": "price_change"}}
{"_local_timestamp": "2026-01-25T23:34:44.145727+00:00", "data": {"market": "0x7573b38aa3d3d387be05d7e2b3fa5c397c6cbf1fbfbb5ccbe1d82816b901e9d1", "price_changes": [{"asset_id": "47900911198961041897125947140815317810676260067603694036981412378636602096971", "price": "0.33", "size": "0", "side": "BUY", "hash": "1086e860900af75af3e3adc2a4f43405e9068f2d", "best_bid": "0.45", "best_ask": "0.46"}, {"asset_id": "45963563720386640986457133827320203891928335132800978095470889439601833791792", "price": "0.67", "size": "0", "side": "SELL", "hash": "d8449b66f7666a39d8e61ce49a607e834fb487bb", "best_bid": "0.54", "best_ask": "0.55"}], "timestamp": "1769384084002", "event_type": "price_change"}}
{"_local_timestamp": "2026-01-25T23:34:44.146855+00:00", "data": {"market": "0xaeb02ced23cf66b235fb864ed82bdf7f7144c38cb0c7466e5f6c255a5c6015cc", "price_changes": [{"asset_id": "16066315103031518578542990703395510559372655158819085950817958432162905570385", "price": "0.181", "size": "0", "side": "BUY", "hash": "cada98df1278a71d75daba4421342add0a6aa38a", "best_bid": "0.987", "best_ask": "0.998"}, {"asset_id": "38866550321267038434460376745002272171027672578638559578882849128491520813825", "price": "0.819", "size": "0", "side": "SELL", "hash": "7c0c170d9cc1a7b87b55d86188d510a3b1f553e6", "best_bid": "0.002", "best_ask": "0.013"}], "timestamp": "1769384084003", "event_type": "price_change"}}
{"_local_timestamp": "2026-01-25T23:34:44.147669+00:00", "data": {"market": "0x27d685bdad61bf2f35948bcff8ddf673c14b72a6f4e9cf1a9d867be231f6a610", "price_changes": [{"asset_id": "82614941921461618729202933946512372479181705578801351216657431603405116134694", "price": "0.02", "size": "0", "side": "BUY", "hash": "4b52a73777dc5757112daddd4b90854de34ba9be", "best_bid": "0.32", "best_ask": "0.38"}, {"asset_id": "32476227489805089000687418984234668312982619103362138837681249693289694597075", "price": "0.98", "size": "0", "side": "SELL", "hash": "8db9806ac3ec67e28072fd1f2ea948266aa78378", "best_bid": "0.62", "best_ask": "0.68"}], "timestamp": "1769384084001", "event_type": "price_change"}}
{"_local_timestamp": "2026-01-25T23:34:44.176460+00:00", "data": {"market": "0x6ac594337fbd762ec04471e8d65806ff9ff78c33ed9dca4826c7bd2969475251", "price_changes": [{"asset_id": "79880305123726971124937075515339490140944001374542290672889526459108541617627", "price": "0.51", "size": "0", "side": "BUY", "hash": "644b21a85d8da2a6b278d76aaee36412aa7b02ad", "best_bid": "0.81", "best_ask": "0.86"}, {"asset_id": "115162358394175336212249289650926294268751651827332730207583087521345129280038", "price": "0.49", "size": "0", "side": "SELL", "hash": "a0814a61ba6bd5fbf5c877a59ed9f3294453747a", "best_bid": "0.14", "best_ask": "0.19"}], "timestamp": "1769384084004", "event_type": "price_change"}}
{"_local_timestamp": "2026-01-25T23:34:44.177318+00:00", "data": {"market": "0xdd3915ab9de231a4f8d1b6989b9d28c81a39d3372fc2f5e5d5e09c5c36bd15e0", "price_changes": [{"asset_id": "64912974742020396457447321385468313243213302286888804044150787878568707049629", "price": "0.35", "size": "0", "side": "BUY", "hash": "07362780739731f36f219e577e7ae822fb58bb5c", "best_bid": "0.66", "best_ask": "0.68"}, {"asset_id": "73772444484179123398639028358181122166565249885455240318019005512648163832892", "price": "0.65", "size": "0", "side": "SELL", "hash": "c6d5e24f94aaf56841cba5bf7428e3819973d33d", "best_bid": "0.32", "best_ask": "0.34"}], "timestamp": "1769384084004", "event_type": "price_change"}}
{"_local_timestamp": "2026-01-25T23:34:44.178186+00:00", "data": {"market": "0x6ac594337fbd762ec04471e8d65806ff9ff78c33ed9dca4826c7bd2969475251", "price_changes": [{"asset_id": "115162358394175336212249289650926294268751651827332730207583087521345129280038", "price": "0.03", "size": "0", "side": "BUY", "hash": "9f68c263a79853ac84aace59de0fb5c51635b7af", "best_bid": "0.14", "best_ask": "0.19"}, {"asset_id": "79880305123726971124937075515339490140944001374542290672889526459108541617627", "price": "0.97", "size": "0", "side": "SELL", "hash": "c4f57a5cfebf6923aa17a17452d0e347f9aa45ed", "best_bid": "0.81", "best_ask": "0.86"}], "timestamp": "1769384084005", "event_type": "price_change"}}
{"_local_timestamp": "2026-01-25T23:34:44.199934+00:00", "data": {"market": "0x242266c50482ad4f243610f7546b60089eadc1d81d4ef408c787f67aa3ef5e7c", "price_changes": [{"asset_id": "96533933355712544390418613060156510030240147080751769428940162257378106436404", "price": "0.15", "size": "0", "side": "BUY", "hash": "19c787d55f5812ddcf00ae31640895ed42b4673e", "best_bid": "0.45", "best_ask": "0.49"}, {"asset_id": "28263250326920700075422198100613476697802143744104502510886484761449393244656", "price": "0.85", "size": "0", "side": "SELL", "hash": "6f03785f388c4a82884ca3b8444b27d3b3ad5d7c", "best_bid": "0.51", "best_ask": "0.55"}], "timestamp": "1769384084005", "event_type": "price_change"}}
{"_local_timestamp": "2026-01-25T23:34:44.200841+00:00", "data": {"market": "0x27d685bdad61bf2f35948bcff8ddf673c14b72a6f4e9cf1a9d867be231f6a610", "price_changes": [{"asset_id": "32476227489805089000687418984234668312982619103362138837681249693289694597075", "price": "0.21", "size": "0", "side": "BUY", "hash": "6f1edde2d09cd4c62cef99e4617669834b59eae6", "best_bid": "0.62", "best_ask": "0.68"}, {"asset_id": "82614941921461618729202933946512372479181705578801351216657431603405116134694", "price": "0.79", "size": "0", "side": "SELL", "hash": "6ea9eb9128cbac2e382c7c9be45906e8f1216864", "best_bid": "0.32", "best_ask": "0.38"}], "timestamp": "1769384084005", "event_type": "price_change"}}
{"_local_timestamp": "2026-01-25T23:34:44.207067+00:00", "data": {"market": "0x6e5e9c218d780a8ff8b516cae97604958f7323ffd75b525d810fb804e727ad78", "price_changes": [{"asset_id": "66190026636022120219272454910747143264277679901831317594304438527297253363875", "price": "0.03", "size": "0", "side": "BUY", "hash": "773ffc4e1dbfb7eadf40b30bb8f9679bce764bb4", "best_bid": "0.21", "best_ask": "0.22"}, {"asset_id": "4929915665740215533077513370523570724508699505795913150073424458746805119832", "price": "0.97", "size": "0", "side": "SELL", "hash": "4de49bb436ef97c9345fdaa475c3a6237763a207", "best_bid": "0.78", "best_ask": "0.79"}], "timestamp": "1769384084004", "event_type": "price_change"}}
{"_local_timestamp": "2026-01-25T23:34:44.207972+00:00", "data": {"market": "0x7573b38aa3d3d387be05d7e2b3fa5c397c6cbf1fbfbb5ccbe1d82816b901e9d1", "price_changes": [{"asset_id": "45963563720386640986457133827320203891928335132800978095470889439601833791792", "price": "0.4", "size": "0", "side": "BUY", "hash": "4a0b812594fddea37625e6d464d2aa2dc48fd7c0", "best_bid": "0.54", "best_ask": "0.55"}, {"asset_id": "47900911198961041897125947140815317810676260067603694036981412378636602096971", "price": "0.6", "size": "0", "side": "SELL", "hash": "992a4695523195140ce4eca0fc5aa1e9c4206ed6", "best_bid": "0.45", "best_ask": "0.46"}], "timestamp": "1769384084006", "event_type": "price_change"}}
{"_local_timestamp": "2026-01-25T23:34:44.208749+00:00", "data": {"market": "0xaeb02ced23cf66b235fb864ed82bdf7f7144c38cb0c7466e5f6c255a5c6015cc", "price_changes": [{"asset_id": "38866550321267038434460376745002272171027672578638559578882849128491520813825", "price": "0.021", "size": "5.47", "side": "SELL", "hash": "749c3ae4365f23607a1ee74c63f39ab86d81d0cc", "best_bid": "0.002", "best_ask": "0.013"}, {"asset_id": "16066315103031518578542990703395510559372655158819085950817958432162905570385", "price": "0.979", "size": "5.47", "side": "BUY", "hash": "f346caf1d38cae8059cc1abae7dc40403b7deafc", "best_bid": "0.987", "best_ask": "0.998"}], "timestamp": "1769384084106", "event_type": "price_change"}}
{"_local_timestamp": "2026-01-25T23:34:44.211462+00:00", "data": {"market": "0xaeb02ced23cf66b235fb864ed82bdf7f7144c38cb0c7466e5f6c255a5c6015cc", "price_changes": [{"asset_id": "38866550321267038434460376745002272171027672578638559578882849128491520813825", "price": "0.019", "size": "24.69", "side": "SELL", "hash": "1755519327a74808d89293e3df1a36c5e59e1874", "best_bid": "0.002", "best_ask": "0.013"}, {"asset_id": "16066315103031518578542990703395510559372655158819085950817958432162905570385", "price": "0.981", "size": "24.69", "side": "BUY", "hash": "8ccd8e46ca5583cec02fb5801da1d3db9297d40f", "best_bid": "0.987", "best_ask": "0.998"}], "timestamp": "1769384084139", "event_type": "price_change"}}
{"_local_timestamp": "2026-01-25T23:34:44.401327+00:00", "data": {"market": "0xaeb02ced23cf66b235fb864ed82bdf7f7144c38cb0c7466e5f6c255a5c6015cc", "price_changes": [{"asset_id": "38866550321267038434460376745002272171027672578638559578882849128491520813825", "price": "0.013", "size": "0", "side": "SELL", "hash": "3039363ea810e7878c6c1e8b1c97cbdfc00821b4", "best_bid": "0.002", "best_ask": "0.019"}, {"asset_id": "16066315103031518578542990703395510559372655158819085950817958432162905570385", "price": "0.987", "size": "0", "side": "BUY", "hash": "edf89144258bbb54a13fb5dda610287975090178", "best_bid": "0.981", "best_ask": "0.998"}], "timestamp": "1769384084332", "event_type": "price_change"}}
{"_local_timestamp": "2026-01-25T23:34:44.402314+00:00", "data": {"market": "0xaeb02ced23cf66b235fb864ed82bdf7f7144c38cb0c7466e5f6c255a5c6015cc", "price_changes": [{"asset_id": "38866550321267038434460376745002272171027672578638559578882849128491520813825", "price": "0.015", "size": "0", "side": "SELL", "hash": "3039363ea810e7878c6c1e8b1c97cbdfc00821b4", "best_bid": "0.002", "best_ask": "0.019"}, {"asset_id": "16066315103031518578542990703395510559372655158819085950817958432162905570385", "price": "0.985", "size": "0", "side": "BUY", "hash": "edf89144258bbb54a13fb5dda610287975090178", "best_bid": "0.981", "best_ask": "0.998"}], "timestamp": "1769384084332", "event_type": "price_change"}}
{"_local_timestamp": "2026-01-25T23:34:44.648555+00:00", "data": {"market": "0xaeb02ced23cf66b235fb864ed82bdf7f7144c38cb0c7466e5f6c255a5c6015cc", "price_changes": [{"asset_id": "38866550321267038434460376745002272171027672578638559578882849128491520813825", "price": "0.018", "size": "6.56", "side": "SELL", "hash": "321d589d50e364f9dd79a575986fd7cfdeb403e9", "best_bid": "0.002", "best_ask": "0.018"}, {"asset_id": "16066315103031518578542990703395510559372655158819085950817958432162905570385", "price": "0.982", "size": "6.56", "side": "BUY", "hash": "bfc197870fc677ccbea245a92562ecacd0ae21fb", "best_bid": "0.982", "best_ask": "0.998"}], "timestamp": "1769384084575", "event_type": "price_change"}}
{"_local_timestamp": "2026-01-25T23:34:44.649549+00:00", "data": {"market": "0xaeb02ced23cf66b235fb864ed82bdf7f7144c38cb0c7466e5f6c255a5c6015cc", "price_changes": [{"asset_id": "38866550321267038434460376745002272171027672578638559578882849128491520813825", "price": "0.018", "size": "13.12", "side": "SELL", "hash": "e34e3d4e1695990a1a11949d1a120aab76cbaea7", "best_bid": "0.002", "best_ask": "0.018"}, {"asset_id": "16066315103031518578542990703395510559372655158819085950817958432162905570385", "price": "0.982", "size": "13.12", "side": "BUY", "hash": "be8de3a9f770547613be54f335d78804de28ca8e", "best_bid": "0.982", "best_ask": "0.998"}], "timestamp": "1769384084576", "event_type": "price_change"}}
{"_local_timestamp": "2026-01-25T23:34:44.806371+00:00", "data": {"market": "0x27d685bdad61bf2f35948bcff8ddf673c14b72a6f4e9cf1a9d867be231f6a610", "price_changes": [{"asset_id": "82614941921461618729202933946512372479181705578801351216657431603405116134694", "price": "0.01", "size": "50", "side": "BUY", "hash": "1cef9ac2b771dca044311eb14d52c54236df02e9", "best_bid": "0.32", "best_ask": "0.38"}, {"asset_id": "32476227489805089000687418984234668312982619103362138837681249693289694597075", "price": "0.99", "size": "50", "side": "SELL", "hash": "9620706b2db4a3466a552ef8762c43d61ae45b14", "best_bid": "0.62", "best_ask": "0.68"}], "timestamp": "1769384084740", "event_type": "price_change"}}
{"_local_timestamp": "2026-01-25T23:34:44.807289+00:00", "data": {"market": "0x27d685bdad61bf2f35948bcff8ddf673c14b72a6f4e9cf1a9d867be231f6a610", "price_changes": [{"asset_id": "82614941921461618729202933946512372479181705578801351216657431603405116134694", "price": "0.03", "size": "100", "side": "BUY", "hash": "1cef9ac2b771dca044311eb14d52c54236df02e9", "best_bid": "0.32", "best_ask": "0.38"}, {"asset_id": "32476227489805089000687418984234668312982619103362138837681249693289694597075", "price": "0.97", "size": "100", "side": "SELL", "hash": "9620706b2db4a3466a552ef8762c43d61ae45b14", "best_bid": "0.62", "best_ask": "0.68"}], "timestamp": "1769384084740", "event_type": "price_change"}}
{"_local_timestamp": "2026-01-25T23:34:45.164869+00:00", "data": {"market": "0x27d685bdad61bf2f35948bcff8ddf673c14b72a6f4e9cf1a9d867be231f6a610", "price_changes": [{"asset_id": "82614941921461618729202933946512372479181705578801351216657431603405116134694", "price": "0.02", "size": "6.69", "side": "BUY", "hash": "efcae90d49ca85319209d794c01e4b73a66970f4", "best_bid": "0.32", "best_ask": "0.38"}, {"asset_id": "32476227489805089000687418984234668312982619103362138837681249693289694597075", "price": "0.98", "size": "6.69", "side": "SELL", "hash": "4bc089310ad0fbaf752e3a402d81da6918ed321b", "best_bid": "0.62", "best_ask": "0.68"}], "timestamp": "1769384085049", "event_type": "price_change"}}
{"_local_timestamp": "2026-01-25T23:34:45.166084+00:00", "data": {"market": "0x27d685bdad61bf2f35948bcff8ddf673c14b72a6f4e9cf1a9d867be231f6a610", "price_changes": [{"asset_id": "82614941921461618729202933946512372479181705578801351216657431603405116134694", "price": "0.02", "size": "13.38", "side": "BUY", "hash": "4aa1cb7468cbcb8714451e66810501c554fbe5f3", "best_bid": "0.32", "best_ask": "0.38"}, {"asset_id": "32476227489805089000687418984234668312982619103362138837681249693289694597075", "price": "0.98", "size": "13.38", "side": "SELL", "hash": "3a36ec47857f01bc22cf1e7e3c79b38ce219073b", "best_bid": "0.62", "best_ask": "0.68"}], "timestamp": "1769384085050", "event_type": "price_change"}}
{"_local_timestamp": "2026-01-25T23:34:46.068634+00:00", "data": {"market": "0xdd3915ab9de231a4f8d1b6989b9d28c81a39d3372fc2f5e5d5e09c5c36bd15e0", "price_changes": [{"asset_id": "73772444484179123398639028358181122166565249885455240318019005512648163832892", "price": "0.31", "size": "1102", "side": "BUY", "hash": "8062f2be72971be7d0739502ee6e48cc7601effe", "best_bid": "0.32", "best_ask": "0.34"}, {"asset_id": "64912974742020396457447321385468313243213302286888804044150787878568707049629", "price": "0.69", "size": "1102", "side": "SELL", "hash": "ba84b089b83c9919a3bb827f6012a8b529ba6bf4", "best_bid": "0.66", "best_ask": "0.68"}], "timestamp": "1769384086000", "event_type": "price_change"}}
{"_local_timestamp": "2026-01-25T23:34:46.069626+00:00", "data": {"market": "0x242266c50482ad4f243610f7546b60089eadc1d81d4ef408c787f67aa3ef5e7c", "price_changes": [{"asset_id": "96533933355712544390418613060156510030240147080751769428940162257378106436404", "price": "0.44", "size": "2211", "side": "BUY", "hash": "5f6c838102a3d3bec168e5501cc6136f5ce1ab79", "best_bid": "0.45", "best_ask": "0.49"}, {"asset_id": "28263250326920700075422198100613476697802143744104502510886484761449393244656", "price": "0.56", "size": "2211", "side": "SELL", "hash": "02917b0c3cc25ac1e6c40fd3ba3b8854daf5c380", "best_bid": "0.51", "best_ask": "0.55"}], "timestamp": "1769384086000", "event_type": "price_change"}}
{"_local_timestamp": "2026-01-25T23:34:46.070499+00:00", "data": {"market": "0x54b69275ee145425f1a0dce69faef15f729f1ab3ec41bc2996a6c6c70e8aec0b", "price_changes": [{"asset_id": "44494068166094207162801090520618289188991411103177309101619626920967990930514", "price": "0.48", "size": "2099", "side": "BUY", "hash": "7e0aa43293ee333b928de115b30a6312fafb6e3f", "best_bid": "0.49", "best_ask": "0.54"}, {"asset_id": "106447080412815954453539138762045278580988736678171840293222199861758175727534", "price": "0.52", "size": "2099", "side": "SELL", "hash": "7ffb6bccced1d6631e34d417738b56bb43874439", "best_bid": "0.46", "best_ask": "0.51"}], "timestamp": "1769384086000", "event_type": "price_change"}}
{"_local_timestamp": "2026-01-25T23:34:46.073079+00:00", "data": {"market": "0x54b69275ee145425f1a0dce69faef15f729f1ab3ec41bc2996a6c6c70e8aec0b", "price_changes": [{"asset_id": "106447080412815954453539138762045278580988736678171840293222199861758175727534", "price": "0.46", "size": "2152", "side": "BUY", "hash": "3c0845d44bdc9cacc82c197a6d40bb5a72a5486d", "best_bid": "0.46", "best_ask": "0.51"}, {"asset_id": "44494068166094207162801090520618289188991411103177309101619626920967990930514", "price": "0.54", "size": "2152", "side": "SELL", "hash": "34d71aa28db6e47d50d0762125b29271d355cd32", "best_bid": "0.49", "best_ask": "0.54"}], "timestamp": "1769384086002", "event_type": "price_change"}}
{"_local_timestamp": "2026-01-25T23:34:46.083255+00:00", "data": {"market": "0x54b69275ee145425f1a0dce69faef15f729f1ab3ec41bc2996a6c6c70e8aec0b", "price_changes": [{"asset_id": "106447080412815954453539138762045278580988736678171840293222199861758175727534", "price": "0.45", "size": "1015", "side": "BUY", "hash": "3c0845d44bdc9cacc82c197a6d40bb5a72a5486d", "best_bid": "0.46", "best_ask": "0.51"}, {"asset_id": "44494068166094207162801090520618289188991411103177309101619626920967990930514", "price": "0.55", "size": "1015", "side": "SELL", "hash": "34d71aa28db6e47d50d0762125b29271d355cd32", "best_bid": "0.49", "best_ask": "0.54"}], "timestamp": "1769384086002", "event_type": "price_change"}}
{"_local_timestamp": "2026-01-25T23:34:46.084206+00:00", "data": {"market": "0x242266c50482ad4f243610f7546b60089eadc1d81d4ef408c787f67aa3ef5e7c", "price_changes": [{"asset_id": "96533933355712544390418613060156510030240147080751769428940162257378106436404", "price": "0.43", "size": "2022", "side": "BUY", "hash": "2717f31f22b25b1cfc082678e6dcd027c0aef92a", "best_bid": "0.45", "best_ask": "0.49"}, {"asset_id": "28263250326920700075422198100613476697802143744104502510886484761449393244656", "price": "0.57", "size": "2022", "side": "SELL", "hash": "e5cd1ffd98d57f44ea9eeba91cc164bd92b6ad3d", "best_bid": "0.51", "best_ask": "0.55"}], "timestamp": "1769384086002", "event_type": "price_change"}}
{"_local_timestamp": "2026-01-25T23:34:46.085040+00:00", "data": {"market": "0x54b69275ee145425f1a0dce69faef15f729f1ab3ec41bc2996a6c6c70e8aec0b", "price_changes": [{"asset_id": "44494068166094207162801090520618289188991411103177309101619626920967990930514", "price": "0.49", "size": "1002", "side": "BUY", "hash": "02ece0f3d0fc9758b6e1065d0f57a6a5ade8c9a9", "best_bid": "0.49", "best_ask": "0.54"}, {"asset_id": "106447080412815954453539138762045278580988736678171840293222199861758175727534", "price": "0.51", "size": "1002", "side": "SELL", "hash": "1af1cbda25c6b4b40ee6deec131a3a7f131bca52", "best_bid": "0.46", "best_ask": "0.51"}], "timestamp": "1769384086003", "event_type": "price_change"}}
{"_local_timestamp": "2026-01-25T23:34:46.085855+00:00", "data": {"market": "0xdd3915ab9de231a4f8d1b6989b9d28c81a39d3372fc2f5e5d5e09c5c36bd15e0", "price_changes": [{"asset_id": "64912974742020396457447321385468313243213302286888804044150787878568707049629", "price": "0.62", "size": "800", "side": "BUY", "hash": "4fa4e73f1ad05f60d3fde3f36077a70ebe42240d", "best_bid": "0.66", "best_ask": "0.68"}, {"asset_id": "73772444484179123398639028358181122166565249885455240318019005512648163832892", "price": "0.38", "size": "800", "side": "SELL", "hash": "c5b4647726cb4b190b78c53c5f2038894152dd03", "best_bid": "0.32", "best_ask": "0.34"}], "timestamp": "1769384086001", "event_type": "price_change"}}
{"_local_timestamp": "2026-01-25T23:34:46.086726+00:00", "data": {"market": "0xdd3915ab9de231a4f8d1b6989b9d28c81a39d3372fc2f5e5d5e09c5c36bd15e0", "price_changes": [{"asset_id": "73772444484179123398639028358181122166565249885455240318019005512648163832892", "price": "0.3", "size": "0", "side": "BUY", "hash": "0468955dae6cb56b966fa8685bbeab324ef71b2e", "best_bid": "0.32", "best_ask": "0.34"}, {"asset_id": "64912974742020396457447321385468313243213302286888804044150787878568707049629", "price": "0.7", "size": "0", "side": "SELL", "hash": "9beb57b2e2525574cbae3b4bf9b198d864593d8f", "best_bid": "0.66", "best_ask": "0.68"}], "timestamp": "1769384086003", "event_type": "price_change"}}
{"_local_timestamp": "2026-01-25T23:34:46.196966+00:00", "data": {"market": "0xdd3915ab9de231a4f8d1b6989b9d28c81a39d3372fc2f5e5d5e09c5c36bd15e0", "price_changes": [{"asset_id": "64912974742020396457447321385468313243213302286888804044150787878568707049629", "price": "0.63", "size": "1250", "side": "BUY", "hash": "6d3a5a6a4e6ec9edd2b0239a6840e7cc6983c2eb", "best_bid": "0.66", "best_ask": "0.68"}, {"asset_id": "73772444484179123398639028358181122166565249885455240318019005512648163832892", "price": "0.37", "size": "1250", "side": "SELL", "hash": "57922a802c884308e9057f1741dba8303a4dc120", "best_bid": "0.32", "best_ask": "0.34"}], "timestamp": "1769384086004", "event_type": "price_change"}}
{"_local_timestamp": "2026-01-25T23:34:46.197945+00:00", "data": {"market": "0xcf18b8f0901452013dcdf957badd6bfb71a9935c6dd9dd2566dc5bb7f795c1a0", "price_changes": [{"asset_id": "86867607300025136841054177922135303037165603316339117668930743822611084804074", "price": "0.06", "size": "0", "side": "BUY", "hash": "42595f6c9e24b665b663ed9f6e79673817e0022a", "best_bid": "0.37", "best_ask": "0.41"}, {"asset_id": "13301686528282766867573623232056946130992514687837926123264639755941579360230", "price": "0.94", "size": "0", "side": "SELL", "hash": "583eb4a7845b77cd223e34d09a264617f1a4c00a", "best_bid": "0.59", "best_ask": "0.63"}], "timestamp": "1769384086030", "event_type": "price_change"}}
{"_local_timestamp": "2026-01-25T23:34:46.313236+00:00", "data": {"market": "0xcf18b8f0901452013dcdf957badd6bfb71a9935c6dd9dd2566dc5bb7f795c1a0", "price_changes": [{"asset_id": "86867607300025136841054177922135303037165603316339117668930743822611084804074", "price": "0.06", "size": "14.78", "side": "BUY", "hash": "68117fa02725cc6f962518d029ac3c0d9088f223", "best_bid": "0.37", "best_ask": "0.41"}, {"asset_id": "13301686528282766867573623232056946130992514687837926123264639755941579360230", "price": "0.94", "size": "14.78", "side": "SELL", "hash": "4f0ee434268476562a9934af96d3030873b6065a", "best_bid": "0.59", "best_ask": "0.63"}], "timestamp": "1769384086239", "event_type": "price_change"}}
{"_local_timestamp": "2026-01-25T23:34:47.992775+00:00", "data": {"market": "0x27d685bdad61bf2f35948bcff8ddf673c14b72a6f4e9cf1a9d867be231f6a610", "price_changes": [{"asset_id": "82614941921461618729202933946512372479181705578801351216657431603405116134694", "price": "0.02", "size": "6.69", "side": "BUY", "hash": "17ceef59d61bc871058ea0f9264a3ce43385185a", "best_bid": "0.32", "best_ask": "0.38"}, {"asset_id": "32476227489805089000687418984234668312982619103362138837681249693289694597075", "price": "0.98", "size": "6.69", "side": "SELL", "hash": "eb7a52d0cc92accde7004e007efc3fb4d2af726d", "best_bid": "0.62", "best_ask": "0.68"}], "timestamp": "1769384087928", "event_type": "price_change"}}
{"_local_timestamp": "2026-01-25T23:34:47.993748+00:00", "data": {"market": "0xaeb02ced23cf66b235fb864ed82bdf7f7144c38cb0c7466e5f6c255a5c6015cc", "price_changes": [{"asset_id": "38866550321267038434460376745002272171027672578638559578882849128491520813825", "price": "0.02", "size": "13.1", "side": "SELL", "hash": "90400d2d3ad7ee3479c9a884fd209f89163b86cb", "best_bid": "0.002", "best_ask": "0.018"}, {"asset_id": "16066315103031518578542990703395510559372655158819085950817958432162905570385", "price": "0.98", "size": "13.1", "side": "BUY", "hash": "11d16853338f58531c822fbe05df662ee2d716bf", "best_bid": "0.982", "best_ask": "0.998"}], "timestamp": "1769384087928", "event_type": "price_change"}}
{"_local_timestamp": "2026-01-25T23:34:48.385835+00:00", "data": {"market": "0xaeb02ced23cf66b235fb864ed82bdf7f7144c38cb0c7466e5f6c255a5c6015cc", "price_changes": [{"asset_id": "38866550321267038434460376745002272171027672578638559578882849128491520813825", "price": "0.018", "size": "19.67", "side": "SELL", "hash": "e12873693d38d7c971442a0f22d5a075b41ecdb3", "best_bid": "0.002", "best_ask": "0.018"}, {"asset_id": "16066315103031518578542990703395510559372655158819085950817958432162905570385", "price": "0.982", "size": "19.67", "side": "BUY", "hash": "af5180c9aa13f66e8a1a09ffe76a2aa25f61dad8", "best_bid": "0.982", "best_ask": "0.998"}], "timestamp": "1769384088317", "event_type": "price_change"}}
{"_local_timestamp": "2026-01-25T23:34:48.386849+00:00", "data": {"market": "0xaeb02ced23cf66b235fb864ed82bdf7f7144c38cb0c7466e5f6c255a5c6015cc", "price_changes": [{"asset_id": "38866550321267038434460376745002272171027672578638559578882849128491520813825", "price": "0.018", "size": "26.22", "side": "SELL", "hash": "250b431a4e510f4395fc773e3c424fef61f16484", "best_bid": "0.002", "best_ask": "0.018"}, {"asset_id": "16066315103031518578542990703395510559372655158819085950817958432162905570385", "price": "0.982", "size": "26.22", "side": "BUY", "hash": "dfa29cb0f1f82b36d44a5b607347fe5881be3d17", "best_bid": "0.982", "best_ask": "0.998"}], "timestamp": "1769384088318", "event_type": "price_change"}}
{"_local_timestamp": "2026-01-25T23:34:48.881606+00:00", "data": {"market": "0x1c5bd9f56545c13743da28ddec8e45c6bea8a01ac7e166dce4286afd32b65a62", "price_changes": [{"asset_id": "53348317672088212419127100072810163057811272329172845337073296220682545739487", "price": "0.01", "size": "74.9", "side": "BUY", "hash": "5648001c3e3a32ba99083731218f2169947f673b", "best_bid": "0.05", "best_ask": "0.93"}, {"asset_id": "100472786165319671267181139302646376200338928621290031353672051075785849864574", "price": "0.99", "size": "74.9", "side": "SELL", "hash": "c86820d722eca9d9c0d61f0c31d5d2a6c15db32b", "best_bid": "0.07", "best_ask": "0.95"}], "timestamp": "1769384088797", "event_type": "price_change"}}
{"_local_timestamp": "2026-01-25T23:34:48.975077+00:00", "data": {"market": "0xaeb02ced23cf66b235fb864ed82bdf7f7144c38cb0c7466e5f6c255a5c6015cc", "price_changes": [{"asset_id": "38866550321267038434460376745002272171027672578638559578882849128491520813825", "price": "0.019", "size": "0", "side": "SELL", "hash": "afb07285746b913d03413bd7256d8088e73d400a", "best_bid": "0.002", "best_ask": "0.018"}, {"asset_id": "16066315103031518578542990703395510559372655158819085950817958432162905570385", "price": "0.981", "size": "0", "side": "BUY", "hash": "cffd3e6427a427e9ff73a3cd2630adc318f3d8e0", "best_bid": "0.982", "best_ask": "0.998"}], "timestamp": "1769384088905", "event_type": "price_change"}}
{"_local_timestamp": "2026-01-25T23:34:49.013583+00:00", "data": {"market": "0xaeb02ced23cf66b235fb864ed82bdf7f7144c38cb0c7466e5f6c255a5c6015cc", "price_changes": [{"asset_id": "38866550321267038434460376745002272171027672578638559578882849128491520813825", "price": "0.017", "size": "24.69", "side": "SELL", "hash": "71b14c9eb4fed5ea08ea6b48699ffb04faf821b5", "best_bid": "0.002", "best_ask": "0.017"}, {"asset_id": "16066315103031518578542990703395510559372655158819085950817958432162905570385", "price": "0.983", "size": "24.69", "side": "BUY", "hash": "7e9aabc0c744ed850420f0e426fac44948737c4d", "best_bid": "0.983", "best_ask": "0.998"}], "timestamp": "1769384088943", "event_type": "price_change"}}
{"_local_timestamp": "2026-01-25T23:34:49.304506+00:00", "data": {"market": "0xaeb02ced23cf66b235fb864ed82bdf7f7144c38cb0c7466e5f6c255a5c6015cc", "price_changes": [{"asset_id": "38866550321267038434460376745002272171027672578638559578882849128491520813825", "price": "0.018", "size": "6.55", "side": "SELL", "hash": "d7205d6f4030da294ee18af800a44338210561be", "best_bid": "0.002", "best_ask": "0.017"}, {"asset_id": "16066315103031518578542990703395510559372655158819085950817958432162905570385", "price": "0.982", "size": "6.55", "side": "BUY", "hash": "ef7569079f099a669c0ef5586117a9847fa2b01a", "best_bid": "0.983", "best_ask": "0.998"}], "timestamp": "1769384089228", "event_type": "price_change"}}
{"_local_timestamp": "2026-01-25T23:34:49.306704+00:00", "data": {"market": "0xaeb02ced23cf66b235fb864ed82bdf7f7144c38cb0c7466e5f6c255a5c6015cc", "price_changes": [{"asset_id": "38866550321267038434460376745002272171027672578638559578882849128491520813825", "price": "0.02", "size": "0", "side": "SELL", "hash": "d7205d6f4030da294ee18af800a44338210561be", "best_bid": "0.002", "best_ask": "0.017"}, {"asset_id": "16066315103031518578542990703395510559372655158819085950817958432162905570385", "price": "0.98", "size": "0", "side": "BUY", "hash": "ef7569079f099a669c0ef5586117a9847fa2b01a", "best_bid": "0.983", "best_ask": "0.998"}], "timestamp": "1769384089228", "event_type": "price_change"}}
{"_local_timestamp": "2026-01-25T23:34:49.484759+00:00", "data": {"market": "0x7573b38aa3d3d387be05d7e2b3fa5c397c6cbf1fbfbb5ccbe1d82816b901e9d1", "price_changes": [{"asset_id": "47900911198961041897125947140815317810676260067603694036981412378636602096971", "price": "0.28", "size": "4544", "side": "BUY", "hash": "5f6aeb4644c83fe7c14d11796b168d4d7d5ff2b7", "best_bid": "0.45", "best_ask": "0.46"}, {"asset_id": "45963563720386640986457133827320203891928335132800978095470889439601833791792", "price": "0.72", "size": "4544", "side": "SELL", "hash": "e5a701ec140d284ef77026705e543147d8a89cda", "best_bid": "0.54", "best_ask": "0.55"}], "timestamp": "1769384089386", "event_type": "price_change"}}
