{"_local_timestamp": "2026-01-25T23:41:22.585528+00:00", "data": [{"market": "0x4341cc0ee3f6c33d5d14114804adbc56745ba69849a62ce33ba01f0f5fcb992d", "asset_id": "103859159453183957891244689604385927345314190615024118584206363782908647975749", "timestamp": "1769384482219", "hash": "769cba94b467bf30322552e4069b15cfdc328730", "bids": [], "asks": [{"price": "0.999", "size": "100918"}, {"price": "0.998", "size": "55000"}, {"price": "0.992", "size": "155"}, {"price": "0.99", "size": "17000"}, {"price": "0.989", "size": "55710"}, {"price": "0.98", "size": "1000"}, {"price": "0.969", "size": "10100"}, {"price": "0.96", "size": "2000"}, {"price": "0.92", "size": "155"}, {"price": "0.903", "size": "100"}, {"price": "0.901", "size": "100"}, {"price": "0.9", "size": "500"}, {"price": "0.899", "size": "10000"}, {"price": "0.898", "size": "5000"}, {"price": "0.89", "size": "3000"}, {"price": "0.889", "size": "4500"}, {"price": "0.86", "size": "50"}, {"price": "0.8", "size": "200"}, {"price": "0.777", "size": "31"}, {"price": "0.73", "size": "200"}, {"price": "0.66", "size": "100"}, {"price": "0.53", "size": "100"}, {"price": "0.51", "size": "100"}, {"price": "0.503", "size": "100"}, {"price": "0.501", "size": "500"}, {"price": "0.5", "size": "440"}, {"price": "0.477", "size": "398"}, {"price": "0.277", "size": "126"}, {"price": "0.25", "size": "60"}, {"price": "0.233", "size": "60"}, {"price": "0.232", "size": "350"}, {"price": "0.231", "size": "60"}, {"price": "0.23", "size": "60"}, {"price": "0.177", "size": "203"}, {"price": "0.077", "size": "350"}, {"price": "0.076", "size": "144"}, {"price": "0.075", "size": "12.43"}, {"price": "0.021", "size": "5.47"}, {"price": "0.01", "size": "25"}, {"price": "0.009", "size": "500"}, {"price": "0.005", "size": "292"}, {"price": "0.001", "size": "87933.34"}], "event_type": "book", "last_trade_price": "0.001"}, {"market": "0x05f99811bde90f48244ad16f03170506b2e949b38b504cc8a44c6e48ebe1702e", "asset_id": "104672182191593174875004906973935726924864992137789800398429529123634830971717", "timestamp": "1769384457719", "hash": "6487ee177dfd5186025348058f8cf01ab2535087", "bids": [{"price": "0.001", "size": "101032"}, {"price": "0.002", "size": "55000"}, {"price": "0.008", "size": "155"}, {"price": "0.009", "size": "148"}, {"price": "0.01", "size": "17000"}, {"price": "0.011", "size": "55710"}, {"price": "0.02", "size": "1000"}, {"price": "0.031", "size": "10000"}, {"price": "0.04", "size": "2000"}, {"price": "0.06", "size": "5.47"}, {"price": "0.07", "size": "5.47"}, {"price": "0.08", "size": "155"}, {"price": "0.097", "size": "100"}, {"price": "0.099", "size": "100"}, {"price": "0.1", "size": "500"}, {"price": "0.101", "size": "10000"}, {"price": "0.102", "size": "5000"}, {"price": "0.11", "size": "3000"}, {"price": "0.111", "size": "4400"}, {"price": "0.223", "size": "44"}, {"price": "0.47", "size": "100"}, {"price": "0.49", "size": "100"}, {"price": "0.497", "size": "100"}, {"price": "0.499", "size": "500"}, {"price": "0.5", "size": "440"}, {"price": "0.723", "size": "141"}, {"price": "0.75", "size": "60"}, {"price": "0.767", "size": "60"}, {"price": "0.768", "size": "53"}, {"price": "0.769", "size": "60"}, {"price": "0.77", "size": "60"}, {"price": "0.771", "size": "65"}, {"price": "0.923", "size": "310"}, {"price": "0.924", "size": "14.3"}, {"price": "0.99", "size": "25"}, {"price": "0.991", "size": "500"}, {"price": "0.992", "size": "5.47"}], "asks": [{"price": "0.999", "size": "314"}], "event_type": "book", "last_trade_price": "0.001"}, {"market": "0x43d906123758b44e9b41f460d8619e290954186d3fe3a0544319216c30d2be24", "asset_id": "15126910918760844641806927476005282998778904719663987971332027436874715278711", "timestamp": "1769384482219", "hash": "867b67fb8df08968c26fcbda7b5fc6b69d9ddfed", "bids": [{"price": "0.001", "size": "101032"}, {"price": "0.002", "size": "55000"}, {"price": "0.008", "size": "155"}, {"price": "0.01", "size": "17000"}, {"price": "0.011", "size": "55858"}, {"price": "0.02", "size": "1000"}, {"price": "0.031", "size": "10000"}, {"price": "0.04", "size": "2000"}, {"price": "0.06", "size": "5.47"}, {"price": "0.07", "size": "5.47"}, {"price": "0.08", "size": "155"}, {"price": "0.097", "size": "100"}, {"price": "0.099", "size": "100"}, {"price": "0.1", "size": "500"}, {"price": "0.101", "size": "10000"}, {"price": "0.102", "size": "5000"}, {"price": "0.11", "size": "3000"}, {"price": "0.111", "size": "4400"}, {"price": "0.223", "size": "44"}, {"price": "0.47", "size": "100"}, {"price": "0.49", "size": "100"}, {"price": "0.497", "size": "100"}, {"price": "0.499", "size": "500"}, {"price": "0.5", "size": "440"}, {"price": "0.723", "size": "141"}, {"price": "0.75", "size": "60"}, {"price": "0.767", "size": "60"}, {"price": "0.768", "size": "53"}, {"price": "0.769", "size": "60"}, {"price": "0.77", "size": "60"}, {"price": "0.923", "size": "271"}, {"price": "0.99", "size": "25"}, {"price": "0.991", "size": "610"}, {"price": "0.992", "size": "44.82"}, {"price": "0.995", "size": "5.47"}], "asks": [{"price": "0.999", "size": "352.74"}], "event_type": "book", "last_trade_price": "0.001"}, {"market": "0xbadbd44eab1006c3823fc2ee131bd6208182caad0eded048fe8912bee99f4f3c", "asset_id": "5196657230325088045531675116644215103600042490546214663989988661649301404833", "timestamp": "1769384428449", "hash": "e71d29fde439038179cedd6ac4cfe64e2b10145a", "bids": [], "asks": [{"price": "0.999", "size": "100918"}, {"price": "0.998", "size": "55000"}, {"price": "0.992", "size": "155"}, {"price": "0.99", "size": "17000"}, {"price": "0.989", "size": "55710"}, {"price": "0.98", "size": "1000"}, {"price": "0.969", "size": "10100"}, {"price": "0.96", "size": "2000"}, {"price": "0.93", "size": "10.94"}, {"price": "0.92", "size": "155"}, {"price": "0.903", "size": "100"}, {"price": "0.901", "size": "100"}, {"price": "0.9", "size": "500"}, {"price": "0.899", "size": "10000"}, {"price": "0.898", "size": "5000"}, {"price": "0.89", "size": "3000"}, {"price": "0.889", "size": "4500"}, {"price": "0.86", "size": "50"}, {"price": "0.8", "size": "200"}, {"price": "0.777", "size": "31"}, {"price": "0.73", "size": "200"}, {"price": "0.66", "size": "100"}, {"price": "0.53", "size": "100"}, {"price": "0.51", "size": "100"}, {"price": "0.503", "size": "100"}, {"price": "0.501", "size": "500"}, {"price": "0.5", "size": "540"}, {"price": "0.477", "size": "398"}, {"price": "0.277", "size": "126"}, {"price": "0.25", "size": "60"}, {"price": "0.233", "size": "60"}, {"price": "0.232", "size": "350"}, {"price": "0.231", "size": "60"}, {"price": "0.23", "size": "60"}, {"price": "0.177", "size": "203"}, {"price": "0.077", "size": "350"}, {"price": "0.076", "size": "144"}, {"price": "0.075", "size": "14.3"}, {"price": "0.01", "size": "25"}, {"price": "0.009", "size": "500"}, {"price": "0.008", "size": "10.47"}, {"price": "0.001", "size": "87845.01"}], "event_type": "book", "last_trade_price": "0.001"}, {"market": "0xaaf07b81d091318fc50eea80f8c9848a45c901dbdd49a3291b3c4ec32669f4f6", "asset_id": "76470301286950624198649364496103459585378536165660664290615779124087725034055", "timestamp": "1769384481993", "hash": "6ed917cbd62bbb8e2b7f95abf0e056d6dfde151c", "bids": [], "asks": [{"price": "0.999", "size": "100918"}, {"price": "0.998", "size": "55000"}, {"price": "0.992", "size": "155"}, {"price": "0.99", "size": "17000"}, {"price": "0.989", "size": "55710"}, {"price": "0.98", "size": "1000"}, {"price": "0.969", "size": "10100"}, {"price": "0.96", "size": "2000"}, {"price": "0.92", "size": "155"}, {"price": "0.903", "size": "100"}, {"price": "0.901", "size": "100"}, {"price": "0.9", "size": "500"}, {"price": "0.899", "size": "10000"}, {"price": "0.898", "size": "5000"}, {"price": "0.89", "size": "3000"}, {"price": "0.889", "size": "4500"}, {"price": "0.86", "size": "50"}, {"price": "0.8", "size": "200"}, {"price": "0.777", "size": "31"}, {"price": "0.73", "size": "200"}, {"price": "0.66", "size": "100"}, {"price": "0.53", "size": "100"}, {"price": "0.51", "size": "100"}, {"price": "0.503", "size": "100"}, {"price": "0.501", "size": "500"}, {"price": "0.5", "size": "540"}, {"price": "0.477", "size": "398"}, {"price": "0.277", "size": "126"}, {"price": "0.25", "size": "60"}, {"price": "0.233", "size": "60"}, {"price": "0.232", "size": "350"}, {"price": "0.231", "size": "60"}, {"price": "0.23", "size": "60"}, {"price": "0.177", "size": "203"}, {"price": "0.077", "size": "350"}, {"price": "0.076", "size": "144"}, {"price": "0.01", "size": "25"}, {"price": "0.009", "size": "500"}, {"price": "0.008", "size": "86.15"}, {"price": "0.006", "size": "11.83"}, {"price": "0.005", "size": "10.47"}, {"price": "0.001", "size": "87928.78"}], "event_type": "book", "last_trade_price": "0.001"}, {"market": "0xaaf07b81d091318fc50eea80f8c9848a45c901dbdd49a3291b3c4ec32669f4f6", "asset_id": "77725644515863814306743026513820299582079276775056525666400499082315809995002", "timestamp": "1769384481993", "hash": "973e47bd060a48bad2e44a6568d4823fcfa69504", "bids": [{"price": "0.001", "size": "100918"}, {"price": "0.002", "size": "55000"}, {"price": "0.008", "size": "155"}, {"price": "0.01", "size": "17000"}, {"price": "0.011", "size": "55710"}, {"price": "0.02", "size": "1000"}, {"price": "0.031", "size": "10100"}, {"price": "0.04", "size": "2000"}, {"price": "0.08", "size": "155"}, {"price": "0.097", "size": "100"}, {"price": "0.099", "size": "100"}, {"price": "0.1", "size": "500"}, {"price": "0.101", "size": "10000"}, {"price": "0.102", "size": "5000"}, {"price": "0.11", "size": "3000"}, {"price": "0.111", "size": "4500"}, {"price": "0.14", "size": "50"}, {"price": "0.2", "size": "200"}, {"price": "0.223", "size": "31"}, {"price": "0.27", "size": "200"}, {"price": "0.34", "size": "100"}, {"price": "0.47", "size": "100"}, {"price": "0.49", "size": "100"}, {"price": "0.497", "size": "100"}, {"price": "0.499", "size": "500"}, {"price": "0.5", "size": "540"}, {"price": "0.523", "size": "398"}, {"price": "0.723", "size": "126"}, {"price": "0.75", "size": "60"}, {"price": "0.767", "size": "60"}, {"price": "0.768", "size": "350"}, {"price": "0.769", "size": "60"}, {"price": "0.77", "size": "60"}, {"price": "0.823", "size": "203"}, {"price": "0.923", "size": "350"}, {"price": "0.924", "size": "144"}, {"price": "0.99", "size": "25"}, {"price": "0.991", "size": "500"}, {"price": "0.992", "size": "86.15"}, {"price": "0.994", "size": "11.83"}, {"price": "0.995", "size": "10.47"}, {"price": "0.999", "size": "87928.78"}], "asks": [], "event_type": "book", "last_trade_price": "0.001"}, {"market": "0xf9f3fc33b0eeb216cc800d8d8f814514e164e1187f144c8c63d421902ab5053f", "asset_id": "36765945687120137952983322694010676429142987736619362116357065987252271463661", "timestamp": "1769384409976", "hash": "191a6eb1bca359f950dcf9365261dab51845a2a4", "bids": [{"price": "0.001", "size": "101031"}, {"price": "0.002", "size": "55000"}, {"price": "0.008", "size": "155"}, {"price": "0.01", "size": "17000"}, {"price": "0.011", "size": "55710"}, {"price": "0.02", "size": "1000"}, {"price": "0.031", "size": "10000"}, {"price": "0.04", "size": "2000"}, {"price": "0.05", "size": "5.47"}, {"price": "0.07", "size": "5.47"}, {"price": "0.08", "size": "155"}, {"price": "0.097", "size": "100"}, {"price": "0.099", "size": "100"}, {"price": "0.1", "size": "500"}, {"price": "0.101", "size": "10000"}, {"price": "0.102", "size": "5000"}, {"price": "0.11", "size": "3000"}, {"price": "0.111", "size": "4400"}, {"price": "0.47", "size": "100"}, {"price": "0.49", "size": "100"}, {"price": "0.497", "size": "100"}, {"price": "0.499", "size": "500"}, {"price": "0.5", "size": "440"}, {"price": "0.75", "size": "60"}, {"price": "0.767", "size": "60"}, {"price": "0.768", "size": "53"}, {"price": "0.769", "size": "60"}, {"price": "0.77", "size": "60"}, {"price": "0.823", "size": "214"}, {"price": "0.824", "size": "144"}, {"price": "0.825", "size": "14.3"}, {"price": "0.99", "size": "25"}, {"price": "0.991", "size": "500"}, {"price": "0.992", "size": "10.47"}, {"price": "0.999", "size": "5.1"}], "asks": [], "event_type": "book", "last_trade_price": "0.001"}, {"market": "0xf9f3fc33b0eeb216cc800d8d8f814514e164e1187f144c8c63d421902ab5053f", "asset_id": "111724860888605889497991946656766850366186546480549896659441786557263722631442", "timestamp": "1769384409976", "hash": "39319fce3cf2924b74ce9768d12cce20585a96e3", "bids": [], "asks": [{"price": "0.999", "size": "101031"}, {"price": "0.998", "size": "55000"}, {"price": "0.992", "size": "155"}, {"price": "0.99", "size": "17000"}, {"price": "0.989", "size": "55710"}, {"price": "0.98", "size": "1000"}, {"price": "0.969", "size": "10000"}, {"price": "0.96", "size": "2000"}, {"price": "0.95", "size": "5.47"}, {"price": "0.93", "size": "5.47"}, {"price": "0.92", "size": "155"}, {"price": "0.903", "size": "100"}, {"price": "0.901", "size": "100"}, {"price": "0.9", "size": "500"}, {"price": "0.899", "size": "10000"}, {"price": "0.898", "size": "5000"}, {"price": "0.89", "size": "3000"}, {"price": "0.889", "size": "4400"}, {"price": "0.53", "size": "100"}, {"price": "0.51", "size": "100"}, {"price": "0.503", "size": "100"}, {"price": "0.501", "size": "500"}, {"price": "0.5", "size": "440"}, {"price": "0.25", "size": "60"}, {"price": "0.233", "size": "60"}, {"price": "0.232", "size": "53"}, {"price": "0.231", "size": "60"}, {"price": "0.23", "size": "60"}, {"price": "0.177", "size": "214"}, {"price": "0.176", "size": "144"}, {"price": "0.175", "size": "14.3"}, {"price": "0.01", "size": "25"}, {"price": "0.009", "size": "500"}, {"price": "0.008", "size": "10.47"}, {"price": "0.001", "size": "5.1"}], "event_type": "book", "last_trade_price": "0.001"}, {"market": "0x60d31be668659012a5f83ee259c9b4eee3053c71dd68abe4d277f54722cd017f", "asset_id": "42488602124923334991804541582064494050024109479561101679507993012554771196517", "timestamp": "1769384482219", "hash": "f37055bc5f7c11b78cd149235b3097c7014f478f", "bids": [{"price": "0.001", "size": "352.75"}], "asks": [{"price": "0.999", "size": "101032"}, {"price": "0.998", "size": "55000"}, {"price": "0.992", "size": "155"}, {"price": "0.99", "size": "17000"}, {"price": "0.989", "size": "55858"}, {"price": "0.98", "size": "1000"}, {"price": "0.969", "size": "10000"}, {"price": "0.96", "size": "2000"}, {"price": "0.93", "size": "5.47"}, {"price": "0.92", "size": "155"}, {"price": "0.903", "size": "100"}, {"price": "0.901", "size": "100"}, {"price": "0.9", "size": "500"}, {"price": "0.899", "size": "10000"}, {"price": "0.898", "size": "5000"}, {"price": "0.89", "size": "3000"}, {"price": "0.889", "size": "4400"}, {"price": "0.777", "size": "44"}, {"price": "0.53", "size": "100"}, {"price": "0.51", "size": "100"}, {"price": "0.503", "size": "100"}, {"price": "0.501", "size": "500"}, {"price": "0.5", "size": "440"}, {"price": "0.277", "size": "141"}, {"price": "0.25", "size": "60"}, {"price": "0.233", "size": "60"}, {"price": "0.232", "size": "53"}, {"price": "0.231", "size": "60"}, {"price": "0.23", "size": "60"}, {"price": "0.077", "size": "271"}, {"price": "0.01", "size": "25"}, {"price": "0.009", "size": "610"}, {"price": "0.008", "size": "44.83"}, {"price": "0.005", "size": "5.47"}], "event_type": "book", "last_trade_price": "0.001"}, {"market": "0xbadbd44eab1006c3823fc2ee131bd6208182caad0eded048fe8912bee99f4f3c", "asset_id": "40808098430716430535441235562064062343735166921796267991078590393515663038927", "timestamp": "1769384428449", "hash": "d0dcd7324ee25b81e7f6605e8088a4396c409192", "bids": [{"price": "0.001", "size": "100918"}, {"price": "0.002", "size": "55000"}, {"price": "0.008", "size": "155"}, {"price": "0.01", "size": "17000"}, {"price": "0.011", "size": "55710"}, {"price": "0.02", "size": "1000"}, {"price": "0.031", "size": "10100"}, {"price": "0.04", "size": "2000"}, {"price": "0.07", "size": "10.94"}, {"price": "0.08", "size": "155"}, {"price": "0.097", "size": "100"}, {"price": "0.099", "size": "100"}, {"price": "0.1", "size": "500"}, {"price": "0.101", "size": "10000"}, {"price": "0.102", "size": "5000"}, {"price": "0.11", "size": "3000"}, {"price": "0.111", "size": "4500"}, {"price": "0.14", "size": "50"}, {"price": "0.2", "size": "200"}, {"price": "0.223", "size": "31"}, {"price": "0.27", "size": "200"}, {"price": "0.34", "size": "100"}, {"price": "0.47", "size": "100"}, {"price": "0.49", "size": "100"}, {"price": "0.497", "size": "100"}, {"price": "0.499", "size": "500"}, {"price": "0.5", "size": "540"}, {"price": "0.523", "size": "398"}, {"price": "0.723", "size": "126"}, {"price": "0.75", "size": "60"}, {"price": "0.767", "size": "60"}, {"price": "0.768", "size": "350"}, {"price": "0.769", "size": "60"}, {"price": "0.77", "size": "60"}, {"price": "0.823", "size": "203"}, {"price": "0.923", "size": "350"}, {"price": "0.924", "size": "144"}, {"price": "0.925", "size": "14.3"}, {"price": "0.99", "size": "25"}, {"price": "0.991", "size": "500"}, {"price": "0.992", "size": "10.47"}, {"price": "0.999", "size": "87845.01"}], "asks": [], "event_type": "book", "last_trade_price": "0.001"}, {"market": "0x66e8b5b9ab91a1cddf5dfc49f0a2ec1498924e109e93d10483f0d79306be313f", "asset_id": "684453561338864560956997457099047232393906048398755908200467037856574658987", "timestamp": "1769384465699", "hash": "738d10b7623036f1b8861182f1ac01173341b477", "bids": [], "asks": [{"price": "0.999", "size": "100921"}, {"price": "0.998", "size": "55000"}, {"price": "0.992", "size": "155"}, {"price": "0.99", "size": "17000"}, {"price": "0.989", "size": "55710"}, {"price": "0.98", "size": "1000"}, {"price": "0.969", "size": "10100"}, {"price": "0.96", "size": "2000"}, {"price": "0.93", "size": "5.47"}, {"price": "0.92", "size": "155"}, {"price": "0.903", "size": "100"}, {"price": "0.901", "size": "100"}, {"price": "0.9", "size": "500"}, {"price": "0.899", "size": "10100"}, {"price": "0.898", "size": "5000"}, {"price": "0.89", "size": "3000"}, {"price": "0.889", "size": "4400"}, {"price": "0.86", "size": "50"}, {"price": "0.798", "size": "200"}, {"price": "0.73", "size": "200"}, {"price": "0.66", "size": "100"}, {"price": "0.53", "size": "100"}, {"price": "0.51", "size": "100"}, {"price": "0.503", "size": "100"}, {"price": "0.501", "size": "500"}, {"price": "0.5", "size": "440"}, {"price": "0.477", "size": "200"}, {"price": "0.277", "size": "126"}, {"price": "0.25", "size": "60"}, {"price": "0.233", "size": "60"}, {"price": "0.232", "size": "176"}, {"price": "0.231", "size": "60"}, {"price": "0.23", "size": "60"}, {"price": "0.177", "size": "204"}, {"price": "0.077", "size": "702"}, {"price": "0.076", "size": "144"}, {"price": "0.075", "size": "14.3"}, {"price": "0.01", "size": "25"}, {"price": "0.009", "size": "500"}, {"price": "0.008", "size": "15.47"}, {"price": "0.001", "size": "87769.66"}], "event_type": "book", "last_trade_price": "0.001"}, {"market": "0x19333e72b03352d15e6d7086466fef3da026191b52795a9236c847e8c3f251ce", "asset_id": "13526274136898830846416670193737235577570452854736881540230125799910228943463", "timestamp": "1769384419986", "hash": "7483c722c85080f9ee7ba91cd55371aebbee2a96", "bids": [{"price": "0.001", "size": "100892"}, {"price": "0.002", "size": "55000"}, {"price": "0.008", "size": "155"}, {"price": "0.01", "size": "17400"}, {"price": "0.011", "size": "55710"}, {"price": "0.02", "size": "1000"}, {"price": "0.031", "size": "11000"}, {"price": "0.04", "size": "2000"}, {"price": "0.08", "size": "155"}, {"price": "0.097", "size": "100"}, {"price": "0.099", "size": "100"}, {"price": "0.1", "size": "500"}, {"price": "0.101", "size": "10500"}, {"price": "0.102", "size": "5000"}, {"price": "0.11", "size": "3000"}, {"price": "0.111", "size": "4400"}, {"price": "0.14", "size": "200"}, {"price": "0.223", "size": "34"}, {"price": "0.47", "size": "100"}, {"price": "0.49", "size": "100"}, {"price": "0.497", "size": "100"}, {"price": "0.499", "size": "500"}, {"price": "0.5", "size": "440"}, {"price": "0.523", "size": "251"}, {"price": "0.723", "size": "96"}, {"price": "0.75", "size": "60"}, {"price": "0.767", "size": "60"}, {"price": "0.768", "size": "221"}, {"price": "0.769", "size": "60"}, {"price": "0.77", "size": "60"}, {"price": "0.823", "size": "171"}, {"price": "0.848", "size": "46.96"}, {"price": "0.851", "size": "6.55"}, {"price": "0.853", "size": "6.56"}, {"price": "0.923", "size": "250"}, {"price": "0.935", "size": "144"}, {"price": "0.936", "size": "75"}, {"price": "0.937", "size": "10.94"}, {"price": "0.991", "size": "500"}, {"price": "0.995", "size": "167"}, {"price": "0.999", "size": "17.96"}], "asks": [], "event_type": "book", "last_trade_price": "0.001"}, {"market": "0x4341cc0ee3f6c33d5d14114804adbc56745ba69849a62ce33ba01f0f5fcb992d", "asset_id": "87105071850972641214581759809593758129422200795386115503863798159438712941487", "timestamp": "1769384482219", "hash": "8ba3af523d1d6d515769370b73eacc40e9fbe4cf", "bids": [{"price": "0.001", "size": "100918"}, {"price": "0.002", "size": "55000"}, {"price": "0.008", "size": "155"}, {"price": "0.01", "size": "17000"}, {"price": "0.011", "size": "55710"}, {"price": "0.02", "size": "1000"}, {"price": "0.031", "size": "10100"}, {"price": "0.04", "size": "2000"}, {"price": "0.08", "size": "155"}, {"price": "0.097", "size": "100"}, {"price": "0.099", "size": "100"}, {"price": "0.1", "size": "500"}, {"price": "0.101", "size": "10000"}, {"price": "0.102", "size": "5000"}, {"price": "0.11", "size": "3000"}, {"price": "0.111", "size": "4500"}, {"price": "0.14", "size": "50"}, {"price": "0.2", "size": "200"}, {"price": "0.223", "size": "31"}, {"price": "0.27", "size": "200"}, {"price": "0.34", "size": "100"}, {"price": "0.47", "size": "100"}, {"price": "0.49", "size": "100"}, {"price": "0.497", "size": "100"}, {"price": "0.499", "size": "500"}, {"price": "0.5", "size": "440"}, {"price": "0.523", "size": "398"}, {"price": "0.723", "size": "126"}, {"price": "0.75", "size": "60"}, {"price": "0.767", "size": "60"}, {"price": "0.768", "size": "350"}, {"price": "0.769", "size": "60"}, {"price": "0.77", "size": "60"}, {"price": "0.823", "size": "203"}, {"price": "0.923", "size": "350"}, {"price": "0.924", "size": "144"}, {"price": "0.925", "size": "12.43"}, {"price": "0.979", "size": "5.47"}, {"price": "0.99", "size": "25"}, {"price": "0.991", "size": "500"}, {"price": "0.995", "size": "292"}, {"price": "0.999", "size": "87933.34"}], "asks": [], "event_type": "book", "last_trade_price": "0.001"}, {"market": "0x05f99811bde90f48244ad16f03170506b2e949b38b504cc8a44c6e48ebe1702e", "asset_id": "36488786194543599561987515498496523553655318415436626702612953440782293472547", "timestamp": "1769384457719", "hash": "16b6f8e8ba11fd6c01612e81f6b2e05b009b2365", "bids": [{"price": "0.001", "size": "314"}], "asks": [{"price": "0.999", "size": "101032"}, {"price": "0.998", "size": "55000"}, {"price": "0.992", "size": "155"}, {"price": "0.991", "size": "148"}, {"price": "0.99", "size": "17000"}, {"price": "0.989", "size": "55710"}, {"price": "0.98", "size": "1000"}, {"price": "0.969", "size": "10000"}, {"price": "0.96", "size": "2000"}, {"price": "0.94", "size": "5.47"}, {"price": "0.93", "size": "5.47"}, {"price": "0.92", "size": "155"}, {"price": "0.903", "size": "100"}, {"price": "0.901", "size": "100"}, {"price": "0.9", "size": "500"}, {"price": "0.899", "size": "10000"}, {"price": "0.898", "size": "5000"}, {"price": "0.89", "size": "3000"}, {"price": "0.889", "size": "4400"}, {"price": "0.777", "size": "44"}, {"price": "0.53", "size": "100"}, {"price": "0.51", "size": "100"}, {"price": "0.503", "size": "100"}, {"price": "0.501", "size": "500"}, {"price": "0.5", "size": "440"}, {"price": "0.277", "size": "141"}, {"price": "0.25", "size": "60"}, {"price": "0.233", "size": "60"}, {"price": "0.232", "size": "53"}, {"price": "0.231", "size": "60"}, {"price": "0.23", "size": "60"}, {"price": "0.229", "size": "65"}, {"price": "0.077", "size": "310"}, {"price": "0.076", "size": "14.3"}, {"price": "0.01", "size": "25"}, {"price": "0.009", "size": "500"}, {"price": "0.008", "size": "5.47"}], "event_type": "book", "last_trade_price": "0.001"}, {"market": "0x60d31be668659012a5f83ee259c9b4eee3053c71dd68abe4d277f54722cd017f", "asset_id": "102579243304231960045442519614514577865920600108882084366671276216059100139841", "timestamp": "1769384482219", "hash": "49ce6338a6d2d633a381c5459ba6975978649f2f", "bids": [{"price": "0.001", "size": "101032"}, {"price": "0.002", "size": "55000"}, {"price": "0.008", "size": "155"}, {"price": "0.01", "size": "17000"}, {"price": "0.011", "size": "55858"}, {"price": "0.02", "size": "1000"}, {"price": "0.031", "size": "10000"}, {"price": "0.04", "size": "2000"}, {"price": "0.07", "size": "5.47"}, {"price": "0.08", "size": "155"}, {"price": "0.097", "size": "100"}, {"price": "0.099", "size": "100"}, {"price": "0.1", "size": "500"}, {"price": "0.101", "size": "10000"}, {"price": "0.102", "size": "5000"}, {"price": "0.11", "size": "3000"}, {"price": "0.111", "size": "4400"}, {"price": "0.223", "size": "44"}, {"price": "0.47", "size": "100"}, {"price": "0.49", "size": "100"}, {"price": "0.497", "size": "100"}, {"price": "0.499", "size": "500"}, {"price": "0.5", "size": "440"}, {"price": "0.723", "size": "141"}, {"price": "0.75", "size": "60"}, {"price": "0.767", "size": "60"}, {"price": "0.768", "size": "53"}, {"price": "0.769", "size": "60"}, {"price": "0.77", "size": "60"}, {"price": "0.923", "size": "271"}, {"price": "0.99", "size": "25"}, {"price": "0.991", "size": "610"}, {"price": "0.992", "size": "44.83"}, {"price": "0.995", "size": "5.47"}], "asks": [{"price": "0.999", "size": "352.75"}], "event_type": "book", "last_trade_price": "0.001"}, {"market": "0x66e8b5b9ab91a1cddf5dfc49f0a2ec1498924e109e93d10483f0d79306be313f", "asset_id": "71091790036166637976632521335546321470982289495437175848831608936100180919258", "timestamp": "1769384465699", "hash": "bceda98481c43481edf6737081996df62888ded7", "bids": [{"price": "0.001", "size": "100921"}, {"price": "0.002", "size": "55000"}, {"price": "0.008", "size": "155"}, {"price": "0.01", "size": "17000"}, {"price": "0.011", "size": "55710"}, {"price": "0.02", "size": "1000"}, {"price": "0.031", "size": "10100"}, {"price": "0.04", "size": "2000"}, {"price": "0.07", "size": "5.47"}, {"price": "0.08", "size": "155"}, {"price": "0.097", "size": "100"}, {"price": "0.099", "size": "100"}, {"price": "0.1", "size": "500"}, {"price": "0.101", "size": "10100"}, {"price": "0.102", "size": "5000"}, {"price": "0.11", "size": "3000"}, {"price": "0.111", "size": "4400"}, {"price": "0.14", "size": "50"}, {"price": "0.202", "size": "200"}, {"price": "0.27", "size": "200"}, {"price": "0.34", "size": "100"}, {"price": "0.47", "size": "100"}, {"price": "0.49", "size": "100"}, {"price": "0.497", "size": "100"}, {"price": "0.499", "size": "500"}, {"price": "0.5", "size": "440"}, {"price": "0.523", "size": "200"}, {"price": "0.723", "size": "126"}, {"price": "0.75", "size": "60"}, {"price": "0.767", "size": "60"}, {"price": "0.768", "size": "176"}, {"price": "0.769", "size": "60"}, {"price": "0.77", "size": "60"}, {"price": "0.823", "size": "204"}, {"price": "0.923", "size": "702"}, {"price": "0.924", "size": "144"}, {"price": "0.925", "size": "14.3"}, {"price": "0.99", "size": "25"}, {"price": "0.991", "size": "500"}, {"price": "0.992", "size": "15.47"}, {"price": "0.999", "size": "87769.66"}], "asks": [], "event_type": "book", "last_trade_price": "0.001"}, {"market": "0x43d906123758b44e9b41f460d8619e290954186d3fe3a0544319216c30d2be24", "asset_id": "8986753851227051304286293461908502563978603715241747497243698980934689505938", "timestamp": "1769384482219", "hash": "7245c919c422d93d1e6ce5468e757fe8d442b816", "bids": [{"price": "0.001", "size": "352.74"}], "asks": [{"price": "0.999", "size": "101032"}, {"price": "0.998", "size": "55000"}, {"price": "0.992", "size": "155"}, {"price": "0.99", "size": "17000"}, {"price": "0.989", "size": "55858"}, {"price": "0.98", "size": "1000"}, {"price": "0.969", "size": "10000"}, {"price": "0.96", "size": "2000"}, {"price": "0.94", "size": "5.47"}, {"price": "0.93", "size": "5.47"}, {"price": "0.92", "size": "155"}, {"price": "0.903", "size": "100"}, {"price": "0.901", "size": "100"}, {"price": "0.9", "size": "500"}, {"price": "0.899", "size": "10000"}, {"price": "0.898", "size": "5000"}, {"price": "0.89", "size": "3000"}, {"price": "0.889", "size": "4400"}, {"price": "0.777", "size": "44"}, {"price": "0.53", "size": "100"}, {"price": "0.51", "size": "100"}, {"price": "0.503", "size": "100"}, {"price": "0.501", "size": "500"}, {"price": "0.5", "size": "440"}, {"price": "0.277", "size": "141"}, {"price": "0.25", "size": "60"}, {"price": "0.233", "size": "60"}, {"price": "0.232", "size": "53"}, {"price": "0.231", "size": "60"}, {"price": "0.23", "size": "60"}, {"price": "0.077", "size": "271"}, {"price": "0.01", "size": "25"}, {"price": "0.009", "size": "610"}, {"price": "0.008", "size": "44.82"}, {"price": "0.005", "size": "5.47"}], "event_type": "book", "last_trade_price": "0.001"}, {"market": "0x19333e72b03352d15e6d7086466fef3da026191b52795a9236c847e8c3f251ce", "asset_id": "91804004031333211529795808161284854640666805283619450552970198233562531861589", "timestamp": "1769384419986", "hash": "7374499d07ac2e9b2dc5e70068a4b21d2caa5f56", "bids": [], "asks": [{"price": "0.999", "size": "100892"}, {"price": "0.998", "size": "55000"}, {"price": "0.992", "size": "155"}, {"price": "0.99", "size": "17400"}, {"price": "0.989", "size": "55710"}, {"price": "0.98", "size": "1000"}, {"price": "0.969", "size": "11000"}, {"price": "0.96", "size": "2000"}, {"price": "0.92", "size": "155"}, {"price": "0.903", "size": "100"}, {"price": "0.901", "size": "100"}, {"price": "0.9", "size": "500"}, {"price": "0.899", "size": "10500"}, {"price": "0.898", "size": "5000"}, {"price": "0.89", "size": "3000"}, {"price": "0.889", "size": "4400"}, {"price": "0.86", "size": "200"}, {"price": "0.777", "size": "34"}, {"price": "0.53", "size": "100"}, {"price": "0.51", "size": "100"}, {"price": "0.503", "size": "100"}, {"price": "0.501", "size": "500"}, {"price": "0.5", "size": "440"}, {"price": "0.477", "size": "251"}, {"price": "0.277", "size": "96"}, {"price": "0.25", "size": "60"}, {"price": "0.233", "size": "60"}, {"price": "0.232", "size": "221"}, {"price": "0.231", "size": "60"}, {"price": "0.23", "size": "60"}, {"price": "0.177", "size": "171"}, {"price": "0.152", "size": "46.96"}, {"price": "0.149", "size": "6.55"}, {"price": "0.147", "size": "6.56"}, {"price": "0.077", "size": "250"}, {"price": "0.065", "size": "144"}, {"price": "0.064", "size": "75"}, {"price": "0.063", "size": "10.94"}, {"price": "0.009", "size": "500"}, {"price": "0.005", "size": "167"}, {"price": "0.001", "size": "17.96"}], "event_type": "book", "last_trade_price": "0.001"}]}
{"_local_timestamp": "2026-01-25T23:41:22.730004+00:00", "data": {"market": "0x43d906123758b44e9b41f460d8619e290954186d3fe3a0544319216c30d2be24", "price_changes": [{"asset_id": "8986753851227051304286293461908502563978603715241747497243698980934689505938", "price": "0.008", "size": "53.03", "side": "SELL", "hash": "82b4cef0c6282cae42d8d419d6d65111321bc26b", "best_bid": "0.001", "best_ask": "0.005"}, {"asset_id": "15126910918760844641806927476005282998778904719663987971332027436874715278711", "price": "0.992", "size": "53.03", "side": "BUY", "hash": "33a13418d3e7761f738d60eee4304cdf972a1caa", "best_bid": "0.995", "best_ask": "0.999"}], "timestamp": "1769384482604", "event_type": "price_change"}}
{"_local_timestamp": "2026-01-25T23:41:22.731838+00:00", "data": {"market": "0x60d31be668659012a5f83ee259c9b4eee3053c71dd68abe4d277f54722cd017f", "price_changes": [{"asset_id": "42488602124923334991804541582064494050024109479561101679507993012554771196517", "price": "0.008", "size": "53.05", "side": "SELL", "hash": "aa93fea7b557061c25769f1d823579bc6f987eb8", "best_bid": "0.001", "best_ask": "0.005"}, {"asset_id": "102579243304231960045442519614514577865920600108882084366671276216059100139841", "price": "0.992", "size": "53.05", "side": "BUY", "hash": "3463a1782dcb40576cb0d15fc4173af59f8c8ef4", "best_bid": "0.995", "best_ask": "0.999"}], "timestamp": "1769384482604", "event_type": "price_change"}}
{"_local_timestamp": "2026-01-25T23:41:22.732150+00:00", "data": {"market": "0x4341cc0ee3f6c33d5d14114804adbc56745ba69849a62ce33ba01f0f5fcb992d", "price_changes": [{"asset_id": "103859159453183957891244689604385927345314190615024118584206363782908647975749", "price": "0.02", "size": "8.21", "side": "SELL", "hash": "0dc133a4266c9e2e6be834bea0039ea2f7f0bd93", "best_bid": "0", "best_ask": "0.001"}, {"asset_id": "87105071850972641214581759809593758129422200795386115503863798159438712941487", "price": "0.98", "size": "8.21", "side": "BUY", "hash": "8f45072e6b9c34d126cb5e7b7c17175560d5713b", "best_bid": "0.999", "best_ask": "1"}], "timestamp": "1769384482604", "event_type": "price_change"}}
{"_local_timestamp": "2026-01-25T23:41:22.769914+00:00", "data": {"market": "0xaaf07b81d091318fc50eea80f8c9848a45c901dbdd49a3291b3c4ec32669f4f6", "price_changes": [{"asset_id": "76470301286950624198649364496103459585378536165660664290615779124087725034055", "price": "0.006", "size": "5.86", "side": "SELL", "hash": "1dce5c10a2a3cfc220e507eed5cf5fdf7d6c4a0e", "best_bid": "0", "best_ask": "0.001"}, {"asset_id": "77725644515863814306743026513820299582079276775056525666400499082315809995002", "price": "0.994", "size": "5.86", "side": "BUY", "hash": "62757c2668415ea75feffd0c7da26cc19cc6986b", "best_bid": "0.999", "best_ask": "1"}], "timestamp": "1769384482649", "event_type": "price_change"}}
{"_local_timestamp": "2026-01-25T23:41:23.042148+00:00", "data": {"market": "0xaaf07b81d091318fc50eea80f8c9848a45c901dbdd49a3291b3c4ec32669f4f6", "price_changes": [{"asset_id": "76470301286950624198649364496103459585378536165660664290615779124087725034055", "price": "0.004", "size": "5.97", "side": "SELL", "hash": "7a18be8830e2e9dcebde518c7e43359898d83758", "best_bid": "0", "best_ask": "0.001"}, {"asset_id": "77725644515863814306743026513820299582079276775056525666400499082315809995002", "price": "0.996", "size": "5.97", "side": "BUY", "hash": "09b6732fcca3b31d7968d1a54d48563d2d46f2cf", "best_bid": "0.999", "best_ask": "1"}], "timestamp": "1769384482912", "event_type": "price_change"}}
{"_local_timestamp": "2026-01-25T23:41:23.594735+00:00", "data": {"market": "0xaaf07b81d091318fc50eea80f8c9848a45c901dbdd49a3291b3c4ec32669f4f6", "price_changes": [{"asset_id": "76470301286950624198649364496103459585378536165660664290615779124087725034055", "price": "0.006", "size": "0", "side": "SELL", "hash": "aed0e04bc4eda8520497cc29decbf3bf546fb153", "best_bid": "0", "best_ask": "0.001"}, {"asset_id": "77725644515863814306743026513820299582079276775056525666400499082315809995002", "price": "0.994", "size": "0", "side": "BUY", "hash": "56cb60b57484d734527c979802710dacd891f264", "best_bid": "0.999", "best_ask": "1"}], "timestamp": "1769384483486", "event_type": "price_change"}}
{"_local_timestamp": "2026-01-25T23:41:23.610889+00:00", "data": {"market": "0x60d31be668659012a5f83ee259c9b4eee3053c71dd68abe4d277f54722cd017f", "price_changes": [{"asset_id": "42488602124923334991804541582064494050024109479561101679507993012554771196517", "price": "0.005", "size": "0", "side": "SELL", "hash": "0f301cb240f5c1f6228ff6580ccc22f11ec50e66", "best_bid": "0.001", "best_ask": "0.008"}, {"asset_id": "102579243304231960045442519614514577865920600108882084366671276216059100139841", "price": "0.995", "size": "0", "side": "BUY", "hash": "d8616c95c2da2eb2288c17ba781929f4b1ff2129", "best_bid": "0.992", "best_ask": "0.999"}], "timestamp": "1769384483491", "event_type": "price_change"}}
{"_local_timestamp": "2026-01-25T23:41:23.613380+00:00", "data": {"market": "0xaaf07b81d091318fc50eea80f8c9848a45c901dbdd49a3291b3c4ec32669f4f6", "price_changes": [{"asset_id": "76470301286950624198649364496103459585378536165660664290615779124087725034055", "price": "0.005", "size": "0", "side": "SELL", "hash": "8853cfbde92718cc020d494648983c1a0869df45", "best_bid": "0", "best_ask": "0.001"}, {"asset_id": "77725644515863814306743026513820299582079276775056525666400499082315809995002", "price": "0.995", "size": "0", "side": "BUY", "hash": "1efb953a5e9b2f5aad0b4b0e97b76fa592fc7f6a", "best_bid": "0.999", "best_ask": "1"}], "timestamp": "1769384483491", "event_type": "price_change"}}
{"_local_timestamp": "2026-01-25T23:41:23.616926+00:00", "data": {"market": "0x43d906123758b44e9b41f460d8619e290954186d3fe3a0544319216c30d2be24", "price_changes": [{"asset_id": "8986753851227051304286293461908502563978603715241747497243698980934689505938", "price": "0.005", "size": "0", "side": "SELL", "hash": "c4e761852d602f4876b211d3f7fda2e657c7a50e", "best_bid": "0.001", "best_ask": "0.008"}, {"asset_id": "15126910918760844641806927476005282998778904719663987971332027436874715278711", "price": "0.995", "size": "0", "side": "BUY", "hash": "ee593aa2eaffc5da2ab6d3961aadd17f2de2ad21", "best_bid": "0.992", "best_ask": "0.999"}], "timestamp": "1769384483491", "event_type": "price_change"}}
{"_local_timestamp": "2026-01-25T23:41:23.621646+00:00", "data": {"market": "0x4341cc0ee3f6c33d5d14114804adbc56745ba69849a62ce33ba01f0f5fcb992d", "price_changes": [{"asset_id": "103859159453183957891244689604385927345314190615024118584206363782908647975749", "price": "0.021", "size": "0", "side": "SELL", "hash": "60152e672868fe4ecf034d2de102224211c4a38c", "best_bid": "0", "best_ask": "0.001"}, {"asset_id": "87105071850972641214581759809593758129422200795386115503863798159438712941487", "price": "0.979", "size": "0", "side": "BUY", "hash": "0aa6c46ee871c09bf1ad62cfe528ce38f0439456", "best_bid": "0.999", "best_ask": "1"}], "timestamp": "1769384483491", "event_type": "price_change"}}
{"_local_timestamp": "2026-01-25T23:41:23.671937+00:00", "data": {"market": "0xaaf07b81d091318fc50eea80f8c9848a45c901dbdd49a3291b3c4ec32669f4f6", "price_changes": [{"asset_id": "76470301286950624198649364496103459585378536165660664290615779124087725034055", "price": "0.003", "size": "10.47", "side": "SELL", "hash": "42bb4d157bb52ec179861db6ef2ed495354f90ef", "best_bid": "0", "best_ask": "0.001"}, {"asset_id": "77725644515863814306743026513820299582079276775056525666400499082315809995002", "price": "0.997", "size": "10.47", "side": "BUY", "hash": "29253e6d84c10b0497212fdfb07586a60ed2aaf5", "best_bid": "0.999", "best_ask": "1"}], "timestamp": "1769384483562", "event_type": "price_change"}}
{"_local_timestamp": "2026-01-25T23:41:23.672517+00:00", "data": {"market": "0x4341cc0ee3f6c33d5d14114804adbc56745ba69849a62ce33ba01f0f5fcb992d", "price_changes": [{"asset_id": "103859159453183957891244689604385927345314190615024118584206363782908647975749", "price": "0.074", "size": "5.47", "side": "SELL", "hash": "97931c505024e7406dcb372fad7d4c5020693d13", "best_bid": "0", "best_ask": "0.001"}, {"asset_id": "87105071850972641214581759809593758129422200795386115503863798159438712941487", "price": "0.926", "size": "5.47", "side": "BUY", "hash": "8fddf9900adc0c97ba4bd66605e05bf87d9191cc", "best_bid": "0.999", "best_ask": "1"}], "timestamp": "1769384483562", "event_type": "price_change"}}
{"_local_timestamp": "2026-01-25T23:41:23.708802+00:00", "data": {"market": "0x60d31be668659012a5f83ee259c9b4eee3053c71dd68abe4d277f54722cd017f", "price_changes": [{"asset_id": "42488602124923334991804541582064494050024109479561101679507993012554771196517", "price": "0.007", "size": "5.47", "side": "SELL", "hash": "011a47f2fe5d90b3d96aef9170322c76bcb8d256", "best_bid": "0.001", "best_ask": "0.007"}, {"asset_id": "102579243304231960045442519614514577865920600108882084366671276216059100139841", "price": "0.993", "size": "5.47", "side": "BUY", "hash": "0678896bddd952593343244dc670fb1e5f18d544", "best_bid": "0.993", "best_ask": "0.999"}], "timestamp": "1769384483598", "event_type": "price_change"}}
{"_local_timestamp": "2026-01-25T23:41:23.711053+00:00", "data": {"market": "0x43d906123758b44e9b41f460d8619e290954186d3fe3a0544319216c30d2be24", "price_changes": [{"asset_id": "8986753851227051304286293461908502563978603715241747497243698980934689505938", "price": "0.007", "size": "5.47", "side": "SELL", "hash": "01ee6e7ea073fb26ab795a4be8ee5726bdfc62ba", "best_bid": "0.001", "best_ask": "0.007"}, {"asset_id": "15126910918760844641806927476005282998778904719663987971332027436874715278711", "price": "0.993", "size": "5.47", "side": "BUY", "hash": "163d0b45b0b1d5dc6521d86dcca77b29bac1ee33", "best_bid": "0.993", "best_ask": "0.999"}], "timestamp": "1769384483598", "event_type": "price_change"}}
{"_local_timestamp": "2026-01-25T23:41:23.883263+00:00", "data": {"market": "0xaaf07b81d091318fc50eea80f8c9848a45c901dbdd49a3291b3c4ec32669f4f6", "price_changes": [{"asset_id": "76470301286950624198649364496103459585378536165660664290615779124087725034055", "price": "0.008", "size": "92.01", "side": "SELL", "hash": "4efab8873a2babaa02ca15efe5975b083ec526b5", "best_bid": "0", "best_ask": "0.001"}, {"asset_id": "77725644515863814306743026513820299582079276775056525666400499082315809995002", "price": "0.992", "size": "92.01", "side": "BUY", "hash": "94cb74f865c1bb90d5fb0c39a8029a17328dc00b", "best_bid": "0.999", "best_ask": "1"}], "timestamp": "1769384483776", "event_type": "price_change"}}
{"_local_timestamp": "2026-01-25T23:41:23.997881+00:00", "data": {"market": "0x60d31be668659012a5f83ee259c9b4eee3053c71dd68abe4d277f54722cd017f", "price_changes": [{"asset_id": "42488602124923334991804541582064494050024109479561101679507993012554771196517", "price": "0.008", "size": "44.83", "side": "SELL", "hash": "2740f9eed3c3fceb4b8be50b5ef53ccd65d18554", "best_bid": "0.001", "best_ask": "0.007"}, {"asset_id": "102579243304231960045442519614514577865920600108882084366671276216059100139841", "price": "0.992", "size": "44.83", "side": "BUY", "hash": "9112d1fea91ad865a2c784fafecbcdeec2815d2a", "best_bid": "0.993", "best_ask": "0.999"}], "timestamp": "1769384483897", "event_type": "price_change"}}
{"_local_timestamp": "2026-01-25T23:41:23.998207+00:00", "data": {"market": "0x4341cc0ee3f6c33d5d14114804adbc56745ba69849a62ce33ba01f0f5fcb992d", "price_changes": [{"asset_id": "103859159453183957891244689604385927345314190615024118584206363782908647975749", "price": "0.02", "size": "0", "side": "SELL", "hash": "0042680a15c02e7b1fe963997aa42e3beff4f1fc", "best_bid": "0", "best_ask": "0.001"}, {"asset_id": "87105071850972641214581759809593758129422200795386115503863798159438712941487", "price": "0.98", "size": "0", "side": "BUY", "hash": "cdf4b5bbecc871d8236ef43bd4f440826e635841", "best_bid": "0.999", "best_ask": "1"}], "timestamp": "1769384483897", "event_type": "price_change"}}
{"_local_timestamp": "2026-01-25T23:41:24.387893+00:00", "data": {"market": "0x4341cc0ee3f6c33d5d14114804adbc56745ba69849a62ce33ba01f0f5fcb992d", "price_changes": [{"asset_id": "103859159453183957891244689604385927345314190615024118584206363782908647975749", "price": "0.073", "size": "8.21", "side": "SELL", "hash": "99051bfa8b2072f6ef631f34de983086fa0fa675", "best_bid": "0", "best_ask": "0.001"}, {"asset_id": "87105071850972641214581759809593758129422200795386115503863798159438712941487", "price": "0.927", "size": "8.21", "side": "BUY", "hash": "5fc878f5461f222e37a38c94e0e928239be3cc98", "best_bid": "0.999", "best_ask": "1"}], "timestamp": "1769384484279", "event_type": "price_change"}}
{"_local_timestamp": "2026-01-25T23:41:24.388244+00:00", "data": {"market": "0x60d31be668659012a5f83ee259c9b4eee3053c71dd68abe4d277f54722cd017f", "price_changes": [{"asset_id": "42488602124923334991804541582064494050024109479561101679507993012554771196517", "price": "0.006", "size": "8.22", "side": "SELL", "hash": "30702ec120ed9ab86129c6bae4d5879a3bf3d9a3", "best_bid": "0.001", "best_ask": "0.006"}, {"asset_id": "102579243304231960045442519614514577865920600108882084366671276216059100139841", "price": "0.994", "size": "8.22", "side": "BUY", "hash": "04e438d7ee0d29748a41bddd365672acd726a667", "best_bid": "0.994", "best_ask": "0.999"}], "timestamp": "1769384484280", "event_type": "price_change"}}
{"_local_timestamp": "2026-01-25T23:41:24.462735+00:00", "data": {"market": "0x43d906123758b44e9b41f460d8619e290954186d3fe3a0544319216c30d2be24", "price_changes": [{"asset_id": "8986753851227051304286293461908502563978603715241747497243698980934689505938", "price": "0.008", "size": "44.82", "side": "SELL", "hash": "b1103e268db17a74684c953b19d18425ddba7874", "best_bid": "0.001", "best_ask": "0.007"}, {"asset_id": "15126910918760844641806927476005282998778904719663987971332027436874715278711", "price": "0.992", "size": "44.82", "side": "BUY", "hash": "43c6790740158d1723c41a9591fbc9579050f7c5", "best_bid": "0.993", "best_ask": "0.999"}], "timestamp": "1769384484332", "event_type": "price_change"}}
{"_local_timestamp": "2026-01-25T23:41:24.656438+00:00", "data": {"market": "0x43d906123758b44e9b41f460d8619e290954186d3fe3a0544319216c30d2be24", "price_changes": [{"asset_id": "8986753851227051304286293461908502563978603715241747497243698980934689505938", "price": "0.006", "size": "8.21", "side": "SELL", "hash": "5b9e991f94e7842d6de55088363d7ecd1ce943ab", "best_bid": "0.001", "best_ask": "0.006"}, {"asset_id": "15126910918760844641806927476005282998778904719663987971332027436874715278711", "price": "0.994", "size": "8.21", "side": "BUY", "hash": "11643fa6acc9774379dcc7aefda59189ece76870", "best_bid": "0.994", "best_ask": "0.999"}], "timestamp": "1769384484569", "event_type": "price_change"}}
{"_local_timestamp": "2026-01-25T23:41:24.865191+00:00", "data": {"market": "0xaaf07b81d091318fc50eea80f8c9848a45c901dbdd49a3291b3c4ec32669f4f6", "price_changes": [{"asset_id": "76470301286950624198649364496103459585378536165660664290615779124087725034055", "price": "0.004", "size": "0", "side": "SELL", "hash": "8bcec05c2f45f42e4a79ff4544027c12db7b7ff1", "best_bid": "0", "best_ask": "0.001"}, {"asset_id": "77725644515863814306743026513820299582079276775056525666400499082315809995002", "price": "0.996", "size": "0", "side": "BUY", "hash": "935c6913b13022ed2d4107eac10df484e943dfde", "best_bid": "0.999", "best_ask": "1"}], "timestamp": "1769384484771", "event_type": "price_change"}}
{"_local_timestamp": "2026-01-25T23:41:24.980986+00:00", "data": {"market": "0x60d31be668659012a5f83ee259c9b4eee3053c71dd68abe4d277f54722cd017f", "price_changes": [{"asset_id": "42488602124923334991804541582064494050024109479561101679507993012554771196517", "price": "0.007", "size": "0", "side": "SELL", "hash": "5c820a9e23b1ec6989efadd2c2d982d3243240ba", "best_bid": "0.001", "best_ask": "0.006"}, {"asset_id": "102579243304231960045442519614514577865920600108882084366671276216059100139841", "price": "0.993", "size": "0", "side": "BUY", "hash": "8af7296759645da16ef3a455a29036858dd7bfe0", "best_bid": "0.994", "best_ask": "0.999"}], "timestamp": "1769384484889", "event_type": "price_change"}}
{"_local_timestamp": "2026-01-25T23:41:24.982220+00:00", "data": {"market": "0x4341cc0ee3f6c33d5d14114804adbc56745ba69849a62ce33ba01f0f5fcb992d", "price_changes": [{"asset_id": "103859159453183957891244689604385927345314190615024118584206363782908647975749", "price": "0.074", "size": "0", "side": "SELL", "hash": "10401223bb27845fba55a49f58ddf0bf547b83eb", "best_bid": "0", "best_ask": "0.001"}, {"asset_id": "87105071850972641214581759809593758129422200795386115503863798159438712941487", "price": "0.926", "size": "0", "side": "BUY", "hash": "c59c47dfbda10ce72799ea8ae1e604ff110a86e5", "best_bid": "0.999", "best_ask": "1"}], "timestamp": "1769384484889", "event_type": "price_change"}}
{"_local_timestamp": "2026-01-25T23:41:24.982553+00:00", "data": {"market": "0x43d906123758b44e9b41f460d8619e290954186d3fe3a0544319216c30d2be24", "price_changes": [{"asset_id": "8986753851227051304286293461908502563978603715241747497243698980934689505938", "price": "0.007", "size": "0", "side": "SELL", "hash": "d0a292179b54eedc154c9a2379f24dc47dd79711", "best_bid": "0.001", "best_ask": "0.006"}, {"asset_id": "15126910918760844641806927476005282998778904719663987971332027436874715278711", "price": "0.993", "size": "0", "side": "BUY", "hash": "b8a621879406125752ce73471e1c507908c245ff", "best_bid": "0.994", "best_ask": "0.999"}], "timestamp": "1769384484889", "event_type": "price_change"}}
{"_local_timestamp": "2026-01-25T23:41:25.039178+00:00", "data": {"market": "0x4341cc0ee3f6c33d5d14114804adbc56745ba69849a62ce33ba01f0f5fcb992d", "price_changes": [{"asset_id": "103859159453183957891244689604385927345314190615024118584206363782908647975749", "price": "0.072", "size": "5.47", "side": "SELL", "hash": "8b6f44e5f180eafb286d86d73720b7b9dedd0d42", "best_bid": "0", "best_ask": "0.001"}, {"asset_id": "87105071850972641214581759809593758129422200795386115503863798159438712941487", "price": "0.928", "size": "5.47", "side": "BUY", "hash": "00cdd93a7b193633028b0045321924b52abb7c71", "best_bid": "0.999", "best_ask": "1"}], "timestamp": "1769384484938", "event_type": "price_change"}}
{"_local_timestamp": "2026-01-25T23:41:25.072264+00:00", "data": {"market": "0x43d906123758b44e9b41f460d8619e290954186d3fe3a0544319216c30d2be24", "price_changes": [{"asset_id": "8986753851227051304286293461908502563978603715241747497243698980934689505938", "price": "0.005", "size": "5.47", "side": "SELL", "hash": "dd82da5ee2542658c1dcbfe1f683c6acefe30969", "best_bid": "0.001", "best_ask": "0.005"}, {"asset_id": "15126910918760844641806927476005282998778904719663987971332027436874715278711", "price": "0.995", "size": "5.47", "side": "BUY", "hash": "c69f36754a8140b14eb540619db5c4f9f8272d93", "best_bid": "0.995", "best_ask": "0.999"}], "timestamp": "1769384484982", "event_type": "price_change"}}
{"_local_timestamp": "2026-01-25T23:41:25.072746+00:00", "data": {"market": "0x60d31be668659012a5f83ee259c9b4eee3053c71dd68abe4d277f54722cd017f", "price_changes": [{"asset_id": "42488602124923334991804541582064494050024109479561101679507993012554771196517", "price": "0.005", "size": "5.47", "side": "SELL", "hash": "02176dd219019a70aaa8aced501189dd240d0073", "best_bid": "0.001", "best_ask": "0.005"}, {"asset_id": "102579243304231960045442519614514577865920600108882084366671276216059100139841", "price": "0.995", "size": "5.47", "side": "BUY", "hash": "f8d2d61cec20a7ed28bb7283cde23645276b519c", "best_bid": "0.995", "best_ask": "0.999"}], "timestamp": "1769384484982", "event_type": "price_change"}}
{"_local_timestamp": "2026-01-25T23:41:25.151905+00:00", "data": {"market": "0xaaf07b81d091318fc50eea80f8c9848a45c901dbdd49a3291b3c4ec32669f4f6", "price_changes": [{"asset_id": "76470301286950624198649364496103459585378536165660664290615779124087725034055", "price": "0.008", "size": "97.98", "side": "SELL", "hash": "02d50bc0eb2c95142a797fa0bf0d867b67b0c39d", "best_bid": "0", "best_ask": "0.001"}, {"asset_id": "77725644515863814306743026513820299582079276775056525666400499082315809995002", "price": "0.992", "size": "97.98", "side": "BUY", "hash": "0ca6d2d8bf185dbc4bd5a930dcb40fc568a443d1", "best_bid": "0.999", "best_ask": "1"}], "timestamp": "1769384485054", "event_type": "price_change"}}
{"_local_timestamp": "2026-01-25T23:41:25.247985+00:00", "data": {"market": "0xbadbd44eab1006c3823fc2ee131bd6208182caad0eded048fe8912bee99f4f3c", "price_changes": [{"asset_id": "40808098430716430535441235562064062343735166921796267991078590393515663038927", "price": "0.201", "size": "4400", "side": "BUY", "hash": "292e44c7772bd1be944277e388f982230fd1d42c", "best_bid": "0.999", "best_ask": "1"}, {"asset_id": "5196657230325088045531675116644215103600042490546214663989988661649301404833", "price": "0.799", "size": "4400", "side": "SELL", "hash": "0b67f043263f4a2fbda29c9750c6d1e4027da011", "best_bid": "0", "best_ask": "0.001"}], "timestamp": "1769384485146", "event_type": "price_change"}}
{"_local_timestamp": "2026-01-25T23:41:25.296683+00:00", "data": {"market": "0x60d31be668659012a5f83ee259c9b4eee3053c71dd68abe4d277f54722cd017f", "price_changes": [{"asset_id": "42488602124923334991804541582064494050024109479561101679507993012554771196517", "price": "0.006", "size": "0", "side": "SELL", "hash": "83f68c593888655d9f7c49ed4414bc00def4abb4", "best_bid": "0.001", "best_ask": "0.005"}, {"asset_id": "102579243304231960045442519614514577865920600108882084366671276216059100139841", "price": "0.994", "size": "0", "side": "BUY", "hash": "649c0572a5878e06c775a164de9ef6de157371f9", "best_bid": "0.995", "best_ask": "0.999"}], "timestamp": "1769384485199", "event_type": "price_change"}}
{"_local_timestamp": "2026-01-25T23:41:25.298038+00:00", "data": {"market": "0x43d906123758b44e9b41f460d8619e290954186d3fe3a0544319216c30d2be24", "price_changes": [{"asset_id": "8986753851227051304286293461908502563978603715241747497243698980934689505938", "price": "0.006", "size": "0", "side": "SELL", "hash": "8fead2538b0a85116cd64db6305bac2cddb5efb1", "best_bid": "0.001", "best_ask": "0.005"}, {"asset_id": "15126910918760844641806927476005282998778904719663987971332027436874715278711", "price": "0.994", "size": "0", "side": "BUY", "hash": "738009f1bdec337c05601fe38b25b9ece1cf9d22", "best_bid": "0.995", "best_ask": "0.999"}], "timestamp": "1769384485199", "event_type": "price_change"}}
{"_local_timestamp": "2026-01-25T23:41:25.299261+00:00", "data": {"market": "0x4341cc0ee3f6c33d5d14114804adbc56745ba69849a62ce33ba01f0f5fcb992d", "price_changes": [{"asset_id": "103859159453183957891244689604385927345314190615024118584206363782908647975749", "price": "0.073", "size": "0", "side": "SELL", "hash": "30e807a00d90f5ac251c7822c6858c7873cb2b56", "best_bid": "0", "best_ask": "0.001"}, {"asset_id": "87105071850972641214581759809593758129422200795386115503863798159438712941487", "price": "0.927", "size": "0", "side": "BUY", "hash": "195b6bd31862f21c56d4792ba1f143e2414710f4", "best_bid": "0.999", "best_ask": "1"}], "timestamp": "1769384485199", "event_type": "price_change"}}
{"_local_timestamp": "2026-01-25T23:41:25.372726+00:00", "data": {"market": "0x66e8b5b9ab91a1cddf5dfc49f0a2ec1498924e109e93d10483f0d79306be313f", "price_changes": [{"asset_id": "71091790036166637976632521335546321470982289495437175848831608936100180919258", "price": "0.101", "size": "10000", "side": "BUY", "hash": "7fd55ec3b1f193209875f3874b2b3b43092afedc", "best_bid": "0.999", "best_ask": "1"}, {"asset_id": "684453561338864560956997457099047232393906048398755908200467037856574658987", "price": "0.899", "size": "10000", "side": "SELL", "hash": "86432abb4c7475cae9c6d4ed123b5732f767cea4", "best_bid": "0", "best_ask": "0.001"}], "timestamp": "1769384485269", "event_type": "price_change"}}
{"_local_timestamp": "2026-01-25T23:41:25.656437+00:00", "data": {"market": "0x66e8b5b9ab91a1cddf5dfc49f0a2ec1498924e109e93d10483f0d79306be313f", "price_changes": [{"asset_id": "71091790036166637976632521335546321470982289495437175848831608936100180919258", "price": "0.111", "size": "4500", "side": "BUY", "hash": "006af2acf181917ef2156cd9164e3cd3fabb3504", "best_bid": "0.999", "best_ask": "1"}, {"asset_id": "684453561338864560956997457099047232393906048398755908200467037856574658987", "price": "0.889", "size": "4500", "side": "SELL", "hash": "6cc2a6b3dadab9c269d59ca7ce4109d4559b03b2", "best_bid": "0", "best_ask": "0.001"}], "timestamp": "1769384485546", "event_type": "price_change"}}
{"_local_timestamp": "2026-01-25T23:41:25.657296+00:00", "data": {"market": "0x43d906123758b44e9b41f460d8619e290954186d3fe3a0544319216c30d2be24", "price_changes": [{"asset_id": "8986753851227051304286293461908502563978603715241747497243698980934689505938", "price": "0.008", "size": "53.03", "side": "SELL", "hash": "a5167034ffc117cda8201f3765913b6e6f2739da", "best_bid": "0.001", "best_ask": "0.005"}, {"asset_id": "15126910918760844641806927476005282998778904719663987971332027436874715278711", "price": "0.992", "size": "53.03", "side": "BUY", "hash": "7cfa01e4efbb4e5833444bf9033d8345a5dc8d02", "best_bid": "0.995", "best_ask": "0.999"}], "timestamp": "1769384485551", "event_type": "price_change"}}
{"_local_timestamp": "2026-01-25T23:41:25.657679+00:00", "data": {"market": "0x4341cc0ee3f6c33d5d14114804adbc56745ba69849a62ce33ba01f0f5fcb992d", "price_changes": [{"asset_id": "103859159453183957891244689604385927345314190615024118584206363782908647975749", "price": "0.071", "size": "8.21", "side": "SELL", "hash": "daa9f82a1f367ba40cb096ba87744a77e00095cc", "best_bid": "0", "best_ask": "0.001"}, {"asset_id": "87105071850972641214581759809593758129422200795386115503863798159438712941487", "price": "0.929", "size": "8.21", "side": "BUY", "hash": "330c927d134b1dbd934d16aa28813e9e17df5745", "best_bid": "0.999", "best_ask": "1"}], "timestamp": "1769384485551", "event_type": "price_change"}}
{"_local_timestamp": "2026-01-25T23:41:25.658451+00:00", "data": {"market": "0x60d31be668659012a5f83ee259c9b4eee3053c71dd68abe4d277f54722cd017f", "price_changes": [{"asset_id": "42488602124923334991804541582064494050024109479561101679507993012554771196517", "price": "0.008", "size": "53.05", "side": "SELL", "hash": "0d460a89e2afbe499ffa2d9f4d1cd3b2e651b2ea", "best_bid": "0.001", "best_ask": "0.005"}, {"asset_id": "102579243304231960045442519614514577865920600108882084366671276216059100139841", "price": "0.992", "size": "53.05", "side": "BUY", "hash": "49e66febc8d5692d2e95ff91f1e66ecc65ccbf8f", "best_bid": "0.995", "best_ask": "0.999"}], "timestamp": "1769384485551", "event_type": "price_change"}}
{"_local_timestamp": "2026-01-25T23:41:25.693541+00:00", "data": {"market": "0x05f99811bde90f48244ad16f03170506b2e949b38b504cc8a44c6e48ebe1702e", "price_changes": [{"asset_id": "36488786194543599561987515498496523553655318415436626702612953440782293472547", "price": "0.177", "size": "212", "side": "SELL", "hash": "d862cb459160a06933158046d6aed32d67bfe320", "best_bid": "0.001", "best_ask": "0.008"}, {"asset_id": "104672182191593174875004906973935726924864992137789800398429529123634830971717", "price": "0.823", "size": "212", "side": "BUY", "hash": "8889dcd4489db4bedd8bb9b40da8f2497a3db950", "best_bid": "0.992", "best_ask": "0.999"}], "timestamp": "1769384485595", "event_type": "price_change"}}
{"_local_timestamp": "2026-01-25T23:41:26.193162+00:00", "data": {"market": "0x60d31be668659012a5f83ee259c9b4eee3053c71dd68abe4d277f54722cd017f", "price_changes": [{"asset_id": "42488602124923334991804541582064494050024109479561101679507993012554771196517", "price": "0.177", "size": "212", "side": "SELL", "hash": "e8a7b20a0caf6b6f8d8ee0128c5dfdbde65ccd9a", "best_bid": "0.001", "best_ask": "0.005"}, {"asset_id": "102579243304231960045442519614514577865920600108882084366671276216059100139841", "price": "0.823", "size": "212", "side": "BUY", "hash": "7c6c2fa81bc3bc0d42aa5112694943f460a38f0b", "best_bid": "0.995", "best_ask": "0.999"}], "timestamp": "1769384486089", "event_type": "price_change"}}
{"_local_timestamp": "2026-01-25T23:41:26.237722+00:00", "data": {"market": "0xbadbd44eab1006c3823fc2ee131bd6208182caad0eded048fe8912bee99f4f3c", "price_changes": [{"asset_id": "40808098430716430535441235562064062343735166921796267991078590393515663038927", "price": "0.111", "size": "100", "side": "BUY", "hash": "f9d78efbdf8e69ab82735f6ebe74a978825dca2c", "best_bid": "0.999", "best_ask": "1"}, {"asset_id": "5196657230325088045531675116644215103600042490546214663989988661649301404833", "price": "0.889", "size": "100", "side": "SELL", "hash": "8633601d9d8762eff3e0b554928435cf010c3723", "best_bid": "0", "best_ask": "0.001"}], "timestamp": "1769384486129", "event_type": "price_change"}}
{"_local_timestamp": "2026-01-25T23:41:26.499046+00:00", "data": {"market": "0xaaf07b81d091318fc50eea80f8c9848a45c901dbdd49a3291b3c4ec32669f4f6", "price_changes": [{"asset_id": "76470301286950624198649364496103459585378536165660664290615779124087725034055", "price": "0.003", "size": "0", "side": "SELL", "hash": "1745a135eae5938954939c1c4f50eda686ae365d", "best_bid": "0", "best_ask": "0.001"}, {"asset_id": "77725644515863814306743026513820299582079276775056525666400499082315809995002", "price": "0.997", "size": "0", "side": "BUY", "hash": "3f143b9857fe3c61a243eb08a958d1c0c7a4eaf7", "best_bid": "0.999", "best_ask": "1"}], "timestamp": "1769384486380", "event_type": "price_change"}}
{"_local_timestamp": "2026-01-25T23:41:26.499398+00:00", "data": {"market": "0x60d31be668659012a5f83ee259c9b4eee3053c71dd68abe4d277f54722cd017f", "price_changes": [{"asset_id": "42488602124923334991804541582064494050024109479561101679507993012554771196517", "price": "0.005", "size": "0", "side": "SELL", "hash": "9a5d319b30b5f9a5c25e8c0047412b9879b6792a", "best_bid": "0.001", "best_ask": "0.008"}, {"asset_id": "102579243304231960045442519614514577865920600108882084366671276216059100139841", "price": "0.995", "size": "0", "side": "BUY", "hash": "9da205e157e16b631a8fe52517c6c5946fa0852c", "best_bid": "0.992", "best_ask": "0.999"}], "timestamp": "1769384486380", "event_type": "price_change"}}
{"_local_timestamp": "2026-01-25T23:41:26.499668+00:00", "data": {"market": "0x4341cc0ee3f6c33d5d14114804adbc56745ba69849a62ce33ba01f0f5fcb992d", "price_changes": [{"asset_id": "103859159453183957891244689604385927345314190615024118584206363782908647975749", "price": "0.072", "size": "0", "side": "SELL", "hash": "2faf6db307ae5b66f7ae3a95d83e91ec0b870d2a", "best_bid": "0", "best_ask": "0.001"}, {"asset_id": "87105071850972641214581759809593758129422200795386115503863798159438712941487", "price": "0.928", "size": "0", "side": "BUY", "hash": "75015609af82377a076e5f29664df5f38fdd4d12", "best_bid": "0.999", "best_ask": "1"}], "timestamp": "1769384486380", "event_type": "price_change"}}
{"_local_timestamp": "2026-01-25T23:41:26.505490+00:00", "data": {"market": "0x43d906123758b44e9b41f460d8619e290954186d3fe3a0544319216c30d2be24", "price_changes": [{"asset_id": "8986753851227051304286293461908502563978603715241747497243698980934689505938", "price": "0.005", "size": "0", "side": "SELL", "hash": "4a0e6447d536b08fedf986d9f649678e54f9c8c5", "best_bid": "0.001", "best_ask": "0.008"}, {"asset_id": "15126910918760844641806927476005282998778904719663987971332027436874715278711", "price": "0.995", "size": "0", "side": "BUY", "hash": "0005d8e9982bf6fe17a30773a856aad4226fd781", "best_bid": "0.992", "best_ask": "0.999"}], "timestamp": "1769384486380", "event_type": "price_change"}}
{"_local_timestamp": "2026-01-25T23:41:26.584461+00:00", "data": {"market": "0x4341cc0ee3f6c33d5d14114804adbc56745ba69849a62ce33ba01f0f5fcb992d", "price_changes": [{"asset_id": "103859159453183957891244689604385927345314190615024118584206363782908647975749", "price": "0.07", "size": "5.47", "side": "SELL", "hash": "2983c14a75bd5e26d6358769a725f2eabf52bc3a", "best_bid": "0", "best_ask": "0.001"}, {"asset_id": "87105071850972641214581759809593758129422200795386115503863798159438712941487", "price": "0.93", "size": "5.47", "side": "BUY", "hash": "5ae451987f5cd70bf2ef20e6436a39f42f2835b4", "best_bid": "0.999", "best_ask": "1"}], "timestamp": "1769384486441", "event_type": "price_change"}}
{"_local_timestamp": "2026-01-25T23:41:26.585611+00:00", "data": {"market": "0xaaf07b81d091318fc50eea80f8c9848a45c901dbdd49a3291b3c4ec32669f4f6", "price_changes": [{"asset_id": "76470301286950624198649364496103459585378536165660664290615779124087725034055", "price": "0.007", "size": "10.47", "side": "SELL", "hash": "1030cbf54ebea095fca6b23d30522636d667fa5b", "best_bid": "0", "best_ask": "0.001"}, {"asset_id": "77725644515863814306743026513820299582079276775056525666400499082315809995002", "price": "0.993", "size": "10.47", "side": "BUY", "hash": "7e214a0e044a9b0e9b6a2dfc1343e773ff92cbcf", "best_bid": "0.999", "best_ask": "1"}], "timestamp": "1769384486441", "event_type": "price_change"}}
{"_local_timestamp": "2026-01-25T23:41:26.622782+00:00", "data": {"market": "0x60d31be668659012a5f83ee259c9b4eee3053c71dd68abe4d277f54722cd017f", "price_changes": [{"asset_id": "42488602124923334991804541582064494050024109479561101679507993012554771196517", "price": "0.007", "size": "5.47", "side": "SELL", "hash": "6648fa316f64189754fa940cc28e30ee2c44afb2", "best_bid": "0.001", "best_ask": "0.007"}, {"asset_id": "102579243304231960045442519614514577865920600108882084366671276216059100139841", "price": "0.993", "size": "5.47", "side": "BUY", "hash": "13a0a2eebf6211fd0de82a0d1133ae13dab1ebe6", "best_bid": "0.993", "best_ask": "0.999"}], "timestamp": "1769384486492", "event_type": "price_change"}}
{"_local_timestamp": "2026-01-25T23:41:26.652710+00:00", "data": {"market": "0x43d906123758b44e9b41f460d8619e290954186d3fe3a0544319216c30d2be24", "price_changes": [{"asset_id": "8986753851227051304286293461908502563978603715241747497243698980934689505938", "price": "0.007", "size": "5.47", "side": "SELL", "hash": "147ddc51261171363a4df8ae66908278e5ad1b98", "best_bid": "0.001", "best_ask": "0.007"}, {"asset_id": "15126910918760844641806927476005282998778904719663987971332027436874715278711", "price": "0.993", "size": "5.47", "side": "BUY", "hash": "8c502783573e3fc2011ee31eb9f114c2ac302a81", "best_bid": "0.993", "best_ask": "0.999"}], "timestamp": "1769384486530", "event_type": "price_change"}}
{"_local_timestamp": "2026-01-25T23:41:26.681670+00:00", "data": {"market": "0x43d906123758b44e9b41f460d8619e290954186d3fe3a0544319216c30d2be24", "price_changes": [{"asset_id": "8986753851227051304286293461908502563978603715241747497243698980934689505938", "price": "0.177", "size": "212", "side": "SELL", "hash": "48c8549ae573451f5f1bd3bf17aea6acb31b1e43", "best_bid": "0.001", "best_ask": "0.007"}, {"asset_id": "15126910918760844641806927476005282998778904719663987971332027436874715278711", "price": "0.823", "size": "212", "side": "BUY", "hash": "3ef300fbad9d4ccd1de0f1313409f396097ec48a", "best_bid": "0.993", "best_ask": "0.999"}], "timestamp": "1769384486566", "event_type": "price_change"}}
{"_local_timestamp": "2026-01-25T23:41:27.025836+00:00", "data": {"market": "0x43d906123758b44e9b41f460d8619e290954186d3fe3a0544319216c30d2be24", "price_changes": [{"asset_id": "8986753851227051304286293461908502563978603715241747497243698980934689505938", "price": "0.008", "size": "44.82", "side": "SELL", "hash": "8b4dfaa5bbdb27370c4b753441f1e60d01a93a8e", "best_bid": "0.001", "best_ask": "0.007"}, {"asset_id": "15126910918760844641806927476005282998778904719663987971332027436874715278711", "price": "0.992", "size": "44.82", "side": "BUY", "hash": "c9762db2cb5b370795dd7efa3610a01d09b58cf8", "best_bid": "0.993", "best_ask": "0.999"}], "timestamp": "1769384486885", "event_type": "price_change"}}
{"_local_timestamp": "2026-01-25T23:41:27.047885+00:00", "data": {"market": "0x60d31be668659012a5f83ee259c9b4eee3053c71dd68abe4d277f54722cd017f", "price_changes": [{"asset_id": "42488602124923334991804541582064494050024109479561101679507993012554771196517", "price": "0.008", "size": "44.83", "side": "SELL", "hash": "68723a6b49abd1ba1e171a2867096136b15bf20b", "best_bid": "0.001", "best_ask": "0.007"}, {"asset_id": "102579243304231960045442519614514577865920600108882084366671276216059100139841", "price": "0.992", "size": "44.83", "side": "BUY", "hash": "97a7f15f9f088024aaff9292240f70d29285b3a0", "best_bid": "0.993", "best_ask": "0.999"}], "timestamp": "1769384486885", "event_type": "price_change"}}
{"_local_timestamp": "2026-01-25T23:41:27.052022+00:00", "data": {"market": "0x4341cc0ee3f6c33d5d14114804adbc56745ba69849a62ce33ba01f0f5fcb992d", "price_changes": [{"asset_id": "103859159453183957891244689604385927345314190615024118584206363782908647975749", "price": "0.071", "size": "0", "side": "SELL", "hash": "0457dd6c997e355929e47924eebd205804a7c72e", "best_bid": "0", "best_ask": "0.001"}, {"asset_id": "87105071850972641214581759809593758129422200795386115503863798159438712941487", "price": "0.929", "size": "0", "side": "BUY", "hash": "e94085be32f1d2b7eec366ad459054d8478c2fb5", "best_bid": "0.999", "best_ask": "1"}], "timestamp": "1769384486885", "event_type": "price_change"}}
{"_local_timestamp": "2026-01-25T23:41:27.055828+00:00", "data": {"market": "0xaaf07b81d091318fc50eea80f8c9848a45c901dbdd49a3291b3c4ec32669f4f6", "price_changes": [{"asset_id": "76470301286950624198649364496103459585378536165660664290615779124087725034055", "price": "0.008", "size": "92.01", "side": "SELL", "hash": "8e3dd4df8680e0c3578c5e15857fe5b0ecdb9c13", "best_bid": "0", "best_ask": "0.001"}, {"asset_id": "77725644515863814306743026513820299582079276775056525666400499082315809995002", "price": "0.992", "size": "92.01", "side": "BUY", "hash": "15ba89dee36cd095ffa68d6150f7549c93a2fb71", "best_bid": "0.999", "best_ask": "1"}], "timestamp": "1769384486885", "event_type": "price_change"}}
{"_local_timestamp": "2026-01-25T23:41:27.191081+00:00", "data": {"market": "0x4341cc0ee3f6c33d5d14114804adbc56745ba69849a62ce33ba01f0f5fcb992d", "price_changes": [{"asset_id": "103859159453183957891244689604385927345314190615024118584206363782908647975749", "price": "0.069", "size": "8.21", "side": "SELL", "hash": "5bfd517aa05b0d291ebb3d0fe0dda13e3d509304", "best_bid": "0", "best_ask": "0.001"}, {"asset_id": "87105071850972641214581759809593758129422200795386115503863798159438712941487", "price": "0.931", "size": "8.21", "side": "BUY", "hash": "483dd4f1db95915604183b5fe09b08a3538bb050", "best_bid": "0.999", "best_ask": "1"}], "timestamp": "1769384487095", "event_type": "price_change"}}
{"_local_timestamp": "2026-01-25T23:41:27.192041+00:00", "data": {"market": "0x60d31be668659012a5f83ee259c9b4eee3053c71dd68abe4d277f54722cd017f", "price_changes": [{"asset_id": "42488602124923334991804541582064494050024109479561101679507993012554771196517", "price": "0.006", "size": "8.22", "side": "SELL", "hash": "cdf9f437ce5b198d905374df5cc35722c759909e", "best_bid": "0.001", "best_ask": "0.006"}, {"asset_id": "102579243304231960045442519614514577865920600108882084366671276216059100139841", "price": "0.994", "size": "8.22", "side": "BUY", "hash": "aecaa6ca44f8bd4355613295f37a153f08bedcb5", "best_bid": "0.994", "best_ask": "0.999"}], "timestamp": "1769384487095", "event_type": "price_change"}}
{"_local_timestamp": "2026-01-25T23:41:27.307765+00:00", "data": {"market": "0xaaf07b81d091318fc50eea80f8c9848a45c901dbdd49a3291b3c4ec32669f4f6", "price_changes": [{"asset_id": "76470301286950624198649364496103459585378536165660664290615779124087725034055", "price": "0.006", "size": "5.97", "side": "SELL", "hash": "25b8c5507d5f0ab4bad000b08d254e5c673bf48f", "best_bid": "0", "best_ask": "0.001"}, {"asset_id": "77725644515863814306743026513820299582079276775056525666400499082315809995002", "price": "0.994", "size": "5.97", "side": "BUY", "hash": "2ef7ca24ffa11280650b09b50c2ce97e665eb6a3", "best_bid": "0.999", "best_ask": "1"}], "timestamp": "1769384487198", "event_type": "price_change"}}
{"_local_timestamp": "2026-01-25T23:41:27.308116+00:00", "data": {"market": "0x43d906123758b44e9b41f460d8619e290954186d3fe3a0544319216c30d2be24", "price_changes": [{"asset_id": "8986753851227051304286293461908502563978603715241747497243698980934689505938", "price": "0.006", "size": "8.21", "side": "SELL", "hash": "7d382626562b2856880bc0da74793ac9494054ac", "best_bid": "0.001", "best_ask": "0.006"}, {"asset_id": "15126910918760844641806927476005282998778904719663987971332027436874715278711", "price": "0.994", "size": "8.21", "side": "BUY", "hash": "818216a1613122759dbbedc9a3fca98d6d940e9c", "best_bid": "0.994", "best_ask": "0.999"}], "timestamp": "1769384487198", "event_type": "price_change"}}
{"_local_timestamp": "2026-01-25T23:41:27.716801+00:00", "data": {"market": "0xaaf07b81d091318fc50eea80f8c9848a45c901dbdd49a3291b3c4ec32669f4f6", "price_changes": [{"asset_id": "76470301286950624198649364496103459585378536165660664290615779124087725034055", "price": "0.008", "size": "86.15", "side": "SELL", "hash": "bad7158088e0bdf881725e5cd7abe5e984d6eadc", "best_bid": "0", "best_ask": "0.001"}, {"asset_id": "77725644515863814306743026513820299582079276775056525666400499082315809995002", "price": "0.992", "size": "86.15", "side": "BUY", "hash": "7d86c852b2659c3b530d7286a249cda23ef687cc", "best_bid": "0.999", "best_ask": "1"}], "timestamp": "1769384487606", "event_type": "price_change"}}
{"_local_timestamp": "2026-01-25T23:41:27.874996+00:00", "data": {"market": "0x60d31be668659012a5f83ee259c9b4eee3053c71dd68abe4d277f54722cd017f", "price_changes": [{"asset_id": "42488602124923334991804541582064494050024109479561101679507993012554771196517", "price": "0.007", "size": "0", "side": "SELL", "hash": "581c1f6756a9e5b62a38b3b9581556c027828fb7", "best_bid": "0.001", "best_ask": "0.006"}, {"asset_id": "102579243304231960045442519614514577865920600108882084366671276216059100139841", "price": "0.993", "size": "0", "side": "BUY", "hash": "8b87ed3d813681e89663c8127c69eaf872e98b9e", "best_bid": "0.994", "best_ask": "0.999"}], "timestamp": "1769384487760", "event_type": "price_change"}}
{"_local_timestamp": "2026-01-25T23:41:27.876544+00:00", "data": {"market": "0xaaf07b81d091318fc50eea80f8c9848a45c901dbdd49a3291b3c4ec32669f4f6", "price_changes": [{"asset_id": "76470301286950624198649364496103459585378536165660664290615779124087725034055", "price": "0.007", "size": "0", "side": "SELL", "hash": "35a7d662765f9f19a3b26c009ebaab416080fb47", "best_bid": "0", "best_ask": "0.001"}, {"asset_id": "77725644515863814306743026513820299582079276775056525666400499082315809995002", "price": "0.993", "size": "0", "side": "BUY", "hash": "fcd7146094efd6634c4dd9962a7cc5965dfe2ac0", "best_bid": "0.999", "best_ask": "1"}], "timestamp": "1769384487761", "event_type": "price_change"}}
{"_local_timestamp": "2026-01-25T23:41:27.876909+00:00", "data": {"market": "0x43d906123758b44e9b41f460d8619e290954186d3fe3a0544319216c30d2be24", "price_changes": [{"asset_id": "8986753851227051304286293461908502563978603715241747497243698980934689505938", "price": "0.007", "size": "0", "side": "SELL", "hash": "dd2e095634903b625555481dc3553a3e3b8e7a1c", "best_bid": "0.001", "best_ask": "0.006"}, {"asset_id": "15126910918760844641806927476005282998778904719663987971332027436874715278711", "price": "0.993", "size": "0", "side": "BUY", "hash": "f64140b9c28db8bbd53d5258ea0a82e2fb537d12", "best_bid": "0.994", "best_ask": "0.999"}], "timestamp": "1769384487760", "event_type": "price_change"}}
{"_local_timestamp": "2026-01-25T23:41:27.877603+00:00", "data": {"market": "0x4341cc0ee3f6c33d5d14114804adbc56745ba69849a62ce33ba01f0f5fcb992d", "price_changes": [{"asset_id": "103859159453183957891244689604385927345314190615024118584206363782908647975749", "price": "0.07", "size": "0", "side": "SELL", "hash": "82df8ec806340a8c32cdd2371ad564fd2ed5535b", "best_bid": "0", "best_ask": "0.001"}, {"asset_id": "87105071850972641214581759809593758129422200795386115503863798159438712941487", "price": "0.93", "size": "0", "side": "BUY", "hash": "ac590714b0180809671bec8bed93bc1259d93a5f", "best_bid": "0.999", "best_ask": "1"}], "timestamp": "1769384487761", "event_type": "price_change"}}
{"_local_timestamp": "2026-01-25T23:41:27.910963+00:00", "data": {"market": "0xaaf07b81d091318fc50eea80f8c9848a45c901dbdd49a3291b3c4ec32669f4f6", "price_changes": [{"asset_id": "76470301286950624198649364496103459585378536165660664290615779124087725034055", "price": "0.005", "size": "10.47", "side": "SELL", "hash": "c3d68295633949f5c5df2fda98cdf76470827f8d", "best_bid": "0", "best_ask": "0.001"}, {"asset_id": "77725644515863814306743026513820299582079276775056525666400499082315809995002", "price": "0.995", "size": "10.47", "side": "BUY", "hash": "a18d31f91c333965d56f7c2bfc48c0a2fb8cb472", "best_bid": "0.999", "best_ask": "1"}], "timestamp": "1769384487815", "event_type": "price_change"}}
{"_local_timestamp": "2026-01-25T23:41:27.964935+00:00", "data": {"market": "0xaaf07b81d091318fc50eea80f8c9848a45c901dbdd49a3291b3c4ec32669f4f6", "price_changes": [{"asset_id": "76470301286950624198649364496103459585378536165660664290615779124087725034055", "price": "0.006", "size": "11.83", "side": "SELL", "hash": "050dedc3f7797dc8cc42799de8957b67538da4c3", "best_bid": "0", "best_ask": "0.001"}, {"asset_id": "77725644515863814306743026513820299582079276775056525666400499082315809995002", "price": "0.994", "size": "11.83", "side": "BUY", "hash": "266b4f0d01f8aeab7476c59a89a2a73fd7be5063", "best_bid": "0.999", "best_ask": "1"}], "timestamp": "1769384487852", "event_type": "price_change"}}
{"_local_timestamp": "2026-01-25T23:41:27.981403+00:00", "data": {"market": "0x60d31be668659012a5f83ee259c9b4eee3053c71dd68abe4d277f54722cd017f", "price_changes": [{"asset_id": "42488602124923334991804541582064494050024109479561101679507993012554771196517", "price": "0.005", "size": "5.47", "side": "SELL", "hash": "a8c98f5cf9db7838bb34c4fe549671fca4a8858f", "best_bid": "0.001", "best_ask": "0.005"}, {"asset_id": "102579243304231960045442519614514577865920600108882084366671276216059100139841", "price": "0.995", "size": "5.47", "side": "BUY", "hash": "c3a9540c198693f7297369ae1fc3655e09a14baf", "best_bid": "0.995", "best_ask": "0.999"}], "timestamp": "1769384487879", "event_type": "price_change"}}
{"_local_timestamp": "2026-01-25T23:41:27.986161+00:00", "data": {"market": "0x4341cc0ee3f6c33d5d14114804adbc56745ba69849a62ce33ba01f0f5fcb992d", "price_changes": [{"asset_id": "103859159453183957891244689604385927345314190615024118584206363782908647975749", "price": "0.068", "size": "5.47", "side": "SELL", "hash": "675c595d41e8f924a33ef254b54e7ff83d0d5aff", "best_bid": "0", "best_ask": "0.001"}, {"asset_id": "87105071850972641214581759809593758129422200795386115503863798159438712941487", "price": "0.932", "size": "5.47", "side": "BUY", "hash": "0bc1bb6ac3bb8f51e9a9d7fa3963a4b4180579b1", "best_bid": "0.999", "best_ask": "1"}], "timestamp": "1769384487879", "event_type": "price_change"}}
{"_local_timestamp": "2026-01-25T23:41:28.017273+00:00", "data": {"market": "0x43d906123758b44e9b41f460d8619e290954186d3fe3a0544319216c30d2be24", "price_changes": [{"asset_id": "8986753851227051304286293461908502563978603715241747497243698980934689505938", "price": "0.005", "size": "5.47", "side": "SELL", "hash": "0474239649a333874f754687304dcd751a8ea948", "best_bid": "0.001", "best_ask": "0.005"}, {"asset_id": "15126910918760844641806927476005282998778904719663987971332027436874715278711", "price": "0.995", "size": "5.47", "side": "BUY", "hash": "f74c24eb0119a83115bb690360c71372ed78a416", "best_bid": "0.995", "best_ask": "0.999"}], "timestamp": "1769384487919", "event_type": "price_change"}}
{"_local_timestamp": "2026-01-25T23:41:28.135888+00:00", "data": {"market": "0x4341cc0ee3f6c33d5d14114804adbc56745ba69849a62ce33ba01f0f5fcb992d", "price_changes": [{"asset_id": "103859159453183957891244689604385927345314190615024118584206363782908647975749", "price": "0.069", "size": "0", "side": "SELL", "hash": "3f131f4507c5e9aecbbaef0231d56525716a58a5", "best_bid": "0", "best_ask": "0.001"}, {"asset_id": "87105071850972641214581759809593758129422200795386115503863798159438712941487", "price": "0.931", "size": "0", "side": "BUY", "hash": "192e2fe074f0920f9d37b953c21d8398cd7354bb", "best_bid": "0.999", "best_ask": "1"}], "timestamp": "1769384488027", "event_type": "price_change"}}
{"_local_timestamp": "2026-01-25T23:41:28.137687+00:00", "data": {"market": "0x43d906123758b44e9b41f460d8619e290954186d3fe3a0544319216c30d2be24", "price_changes": [{"asset_id": "8986753851227051304286293461908502563978603715241747497243698980934689505938", "price": "0.006", "size": "0", "side": "SELL", "hash": "df644f9aad8a336b86bd7c1ec60a33a23350b382", "best_bid": "0.001", "best_ask": "0.005"}, {"asset_id": "15126910918760844641806927476005282998778904719663987971332027436874715278711", "price": "0.994", "size": "0", "side": "BUY", "hash": "10204b425d5f408a35f4dcb72d647cc07334e5cd", "best_bid": "0.995", "best_ask": "0.999"}], "timestamp": "1769384488028", "event_type": "price_change"}}
{"_local_timestamp": "2026-01-25T23:41:28.138029+00:00", "data": {"market": "0x60d31be668659012a5f83ee259c9b4eee3053c71dd68abe4d277f54722cd017f", "price_changes": [{"asset_id": "42488602124923334991804541582064494050024109479561101679507993012554771196517", "price": "0.006", "size": "0", "side": "SELL", "hash": "f1e00ec370342886bd28d0b6b828ea58c94849af", "best_bid": "0.001", "best_ask": "0.005"}, {"asset_id": "102579243304231960045442519614514577865920600108882084366671276216059100139841", "price": "0.994", "size": "0", "side": "BUY", "hash": "c4ace3f312154449cd8d6e01c8b41cb143e5d300", "best_bid": "0.995", "best_ask": "0.999"}], "timestamp": "1769384488027", "event_type": "price_change"}}
{"_local_timestamp": "2026-01-25T23:41:28.412944+00:00", "data": {"market": "0x4341cc0ee3f6c33d5d14114804adbc56745ba69849a62ce33ba01f0f5fcb992d", "price_changes": [{"asset_id": "103859159453183957891244689604385927345314190615024118584206363782908647975749", "price": "0.067", "size": "8.21", "side": "SELL", "hash": "640750cf8a33fcab27f3f0570eb013a2b762a341", "best_bid": "0", "best_ask": "0.001"}, {"asset_id": "87105071850972641214581759809593758129422200795386115503863798159438712941487", "price": "0.933", "size": "8.21", "side": "BUY", "hash": "6aef67d00edb91a36681ce22650edb8c60e5f0ce", "best_bid": "0.999", "best_ask": "1"}], "timestamp": "1769384488311", "event_type": "price_change"}}
{"_local_timestamp": "2026-01-25T23:41:28.414381+00:00", "data": {"market": "0x43d906123758b44e9b41f460d8619e290954186d3fe3a0544319216c30d2be24", "price_changes": [{"asset_id": "8986753851227051304286293461908502563978603715241747497243698980934689505938", "price": "0.008", "size": "53.03", "side": "SELL", "hash": "b8cac0c88092cc048ce984cb395422c96e197886", "best_bid": "0.001", "best_ask": "0.005"}, {"asset_id": "15126910918760844641806927476005282998778904719663987971332027436874715278711", "price": "0.992", "size": "53.03", "side": "BUY", "hash": "1f2e41a6775c0563d15b25dc87016821db63ac24", "best_bid": "0.995", "best_ask": "0.999"}], "timestamp": "1769384488312", "event_type": "price_change"}}
{"_local_timestamp": "2026-01-25T23:41:28.415599+00:00", "data": {"market": "0x60d31be668659012a5f83ee259c9b4eee3053c71dd68abe4d277f54722cd017f", "price_changes": [{"asset_id": "42488602124923334991804541582064494050024109479561101679507993012554771196517", "price": "0.008", "size": "53.05", "side": "SELL", "hash": "f0c77072c8afbc91f85232fc6fa497518268cb0e", "best_bid": "0.001", "best_ask": "0.005"}, {"asset_id": "102579243304231960045442519614514577865920600108882084366671276216059100139841", "price": "0.992", "size": "53.05", "side": "BUY", "hash": "6ce372cc9e75463a3daa0ab911245b860a7fbd7b", "best_bid": "0.995", "best_ask": "0.999"}], "timestamp": "1769384488311", "event_type": "price_change"}}
{"_local_timestamp": "2026-01-25T23:41:28.562682+00:00", "data": {"market": "0xaaf07b81d091318fc50eea80f8c9848a45c901dbdd49a3291b3c4ec32669f4f6", "price_changes": [{"asset_id": "76470301286950624198649364496103459585378536165660664290615779124087725034055", "price": "0.006", "size": "5.86", "side": "SELL", "hash": "5863c88265f798a70d124bda2f1ad2be3cd4bf42", "best_bid": "0", "best_ask": "0.001"}, {"asset_id": "77725644515863814306743026513820299582079276775056525666400499082315809995002", "price": "0.994", "size": "5.86", "side": "BUY", "hash": "eda35bfe33db3842e8b11e5d503ccf8447b4a7b7", "best_bid": "0.999", "best_ask": "1"}], "timestamp": "1769384488453", "event_type": "price_change"}}
{"_local_timestamp": "2026-01-25T23:41:28.720149+00:00", "data": {"market": "0xaaf07b81d091318fc50eea80f8c9848a45c901dbdd49a3291b3c4ec32669f4f6", "price_changes": [{"asset_id": "76470301286950624198649364496103459585378536165660664290615779124087725034055", "price": "0.004", "size": "5.97", "side": "SELL", "hash": "ce279001b818c64347b730585875a07b46de7fbd", "best_bid": "0", "best_ask": "0.001"}, {"asset_id": "77725644515863814306743026513820299582079276775056525666400499082315809995002", "price": "0.996", "size": "5.97", "side": "BUY", "hash": "42e7316c779e0b52cfac25db6fb663bb8cbc02d8", "best_bid": "0.999", "best_ask": "1"}], "timestamp": "1769384488611", "event_type": "price_change"}}
{"_local_timestamp": "2026-01-25T23:41:28.978213+00:00", "data": {"market": "0xaaf07b81d091318fc50eea80f8c9848a45c901dbdd49a3291b3c4ec32669f4f6", "price_changes": [{"asset_id": "76470301286950624198649364496103459585378536165660664290615779124087725034055", "price": "0.006", "size": "0", "side": "SELL", "hash": "a0d697d1ee10f756ef0dd24128745239de9a2c24", "best_bid": "0", "best_ask": "0.001"}, {"asset_id": "77725644515863814306743026513820299582079276775056525666400499082315809995002", "price": "0.994", "size": "0", "side": "BUY", "hash": "5ed4d75b80fe58d0bd7778461d098defb9c132ce", "best_bid": "0.999", "best_ask": "1"}], "timestamp": "1769384488878", "event_type": "price_change"}}
{"_local_timestamp": "2026-01-25T23:41:29.201274+00:00", "data": {"market": "0xaaf07b81d091318fc50eea80f8c9848a45c901dbdd49a3291b3c4ec32669f4f6", "price_changes": [{"asset_id": "76470301286950624198649364496103459585378536165660664290615779124087725034055", "price": "0.004", "size": "11.83", "side": "SELL", "hash": "a91925321e5bf7a0c428bebfee8178a71c987ea9", "best_bid": "0", "best_ask": "0.001"}, {"asset_id": "77725644515863814306743026513820299582079276775056525666400499082315809995002", "price": "0.996", "size": "11.83", "side": "BUY", "hash": "3459a501b197dfa8467e01588cd6744bbf9dacdf", "best_bid": "0.999", "best_ask": "1"}], "timestamp": "1769384489110", "event_type": "price_change"}}
{"_local_timestamp": "2026-01-25T23:41:29.476425+00:00", "data": {"market": "0x43d906123758b44e9b41f460d8619e290954186d3fe3a0544319216c30d2be24", "price_changes": [{"asset_id": "8986753851227051304286293461908502563978603715241747497243698980934689505938", "price": "0.005", "size": "0", "side": "SELL", "hash": "7347020263f247d5575c0581915dfd4796dd6ec0", "best_bid": "0.001", "best_ask": "0.008"}, {"asset_id": "15126910918760844641806927476005282998778904719663987971332027436874715278711", "price": "0.995", "size": "0", "side": "BUY", "hash": "64bdec1e7b028cbb1d7047d500487b960bc69767", "best_bid": "0.992", "best_ask": "0.999"}], "timestamp": "1769384489373", "event_type": "price_change"}}
{"_local_timestamp": "2026-01-25T23:41:29.484930+00:00", "data": {"market": "0xaaf07b81d091318fc50eea80f8c9848a45c901dbdd49a3291b3c4ec32669f4f6", "price_changes": [{"asset_id": "76470301286950624198649364496103459585378536165660664290615779124087725034055", "price": "0.005", "size": "0", "side": "SELL", "hash": "dec1a9971fb70df5b3af7dcbde647ae546488df3", "best_bid": "0", "best_ask": "0.001"}, {"asset_id": "77725644515863814306743026513820299582079276775056525666400499082315809995002", "price": "0.995", "size": "0", "side": "BUY", "hash": "0081d6a948291ba2e5f9a447e085deec642f3894", "best_bid": "0.999", "best_ask": "1"}], "timestamp": "1769384489373", "event_type": "price_change"}}
{"_local_timestamp": "2026-01-25T23:41:29.497163+00:00", "data": {"market": "0x4341cc0ee3f6c33d5d14114804adbc56745ba69849a62ce33ba01f0f5fcb992d", "price_changes": [{"asset_id": "103859159453183957891244689604385927345314190615024118584206363782908647975749", "price": "0.068", "size": "0", "side": "SELL", "hash": "20072fac09e368b73c68534f68ac1a29167ba8b2", "best_bid": "0", "best_ask": "0.001"}, {"asset_id": "87105071850972641214581759809593758129422200795386115503863798159438712941487", "price": "0.932", "size": "0", "side": "BUY", "hash": "9a8ecc66b5b57b453872183ad858e2d997579311", "best_bid": "0.999", "best_ask": "1"}], "timestamp": "1769384489373", "event_type": "price_change"}}
{"_local_timestamp": "2026-01-25T23:41:29.498460+00:00", "data": {"market": "0x60d31be668659012a5f83ee259c9b4eee3053c71dd68abe4d277f54722cd017f", "price_changes": [{"asset_id": "42488602124923334991804541582064494050024109479561101679507993012554771196517", "price": "0.005", "size": "0", "side": "SELL", "hash": "90df327e3fd8f70f82686680bacb2a3bb250c82c", "best_bid": "0.001", "best_ask": "0.008"}, {"asset_id": "102579243304231960045442519614514577865920600108882084366671276216059100139841", "price": "0.995", "size": "0", "side": "BUY", "hash": "6658ab08ed45cd8a2da988ea51864d8b3a663cf8", "best_bid": "0.992", "best_ask": "0.999"}], "timestamp": "1769384489373", "event_type": "price_change"}}
{"_local_timestamp": "2026-01-25T23:41:29.526507+00:00", "data": {"market": "0xaaf07b81d091318fc50eea80f8c9848a45c901dbdd49a3291b3c4ec32669f4f6", "price_changes": [{"asset_id": "76470301286950624198649364496103459585378536165660664290615779124087725034055", "price": "0.003", "size": "10.47", "side": "SELL", "hash": "f14dd04616f2b923db91412233ce5171b1c15659", "best_bid": "0", "best_ask": "0.001"}, {"asset_id": "77725644515863814306743026513820299582079276775056525666400499082315809995002", "price": "0.997", "size": "10.47", "side": "BUY", "hash": "e81ce4a39b34e82bdacd68b0f6982a6509613739", "best_bid": "0.999", "best_ask": "1"}], "timestamp": "1769384489422", "event_type": "price_change"}}
{"_local_timestamp": "2026-01-25T23:41:29.527281+00:00", "data": {"market": "0x4341cc0ee3f6c33d5d14114804adbc56745ba69849a62ce33ba01f0f5fcb992d", "price_changes": [{"asset_id": "103859159453183957891244689604385927345314190615024118584206363782908647975749", "price": "0.066", "size": "5.47", "side": "SELL", "hash": "9a32256d3f79ef91cb2e008bb7dd98d813811345", "best_bid": "0", "best_ask": "0.001"}, {"asset_id": "87105071850972641214581759809593758129422200795386115503863798159438712941487", "price": "0.934", "size": "5.47", "side": "BUY", "hash": "055335b44b0f7c94c83f246e0661fa6794753475", "best_bid": "0.999", "best_ask": "1"}], "timestamp": "1769384489422", "event_type": "price_change"}}
{"_local_timestamp": "2026-01-25T23:41:29.573129+00:00", "data": {"market": "0x60d31be668659012a5f83ee259c9b4eee3053c71dd68abe4d277f54722cd017f", "price_changes": [{"asset_id": "42488602124923334991804541582064494050024109479561101679507993012554771196517", "price": "0.007", "size": "5.47", "side": "SELL", "hash": "bd9c5db385a378551cb2d49eafbc3d50c8852fc6", "best_bid": "0.001", "best_ask": "0.007"}, {"asset_id": "102579243304231960045442519614514577865920600108882084366671276216059100139841", "price": "0.993", "size": "5.47", "side": "BUY", "hash": "f88f9daebfa77387a6eb14e384ee4d935fde219f", "best_bid": "0.993", "best_ask": "0.999"}], "timestamp": "1769384489463", "event_type": "price_change"}}
{"_local_timestamp": "2026-01-25T23:41:29.606719+00:00", "data": {"market": "0x43d906123758b44e9b41f460d8619e290954186d3fe3a0544319216c30d2be24", "price_changes": [{"asset_id": "8986753851227051304286293461908502563978603715241747497243698980934689505938", "price": "0.007", "size": "5.47", "side": "SELL", "hash": "dd8cc980b06db64ae474fec21221a79e44e5ee30", "best_bid": "0.001", "best_ask": "0.007"}, {"asset_id": "15126910918760844641806927476005282998778904719663987971332027436874715278711", "price": "0.993", "size": "5.47", "side": "BUY", "hash": "6798f21f77d26e534c0f4ed25942a649f3c41edc", "best_bid": "0.993", "best_ask": "0.999"}], "timestamp": "1769384489494", "event_type": "price_change"}}
{"_local_timestamp": "2026-01-25T23:41:30.002263+00:00", "data": {"market": "0x60d31be668659012a5f83ee259c9b4eee3053c71dd68abe4d277f54722cd017f", "price_changes": [{"asset_id": "42488602124923334991804541582064494050024109479561101679507993012554771196517", "price": "0.008", "size": "44.83", "side": "SELL", "hash": "706699bd44b5d5bb82b2aacff1d95c53a7c70e7b", "best_bid": "0.001", "best_ask": "0.007"}, {"asset_id": "102579243304231960045442519614514577865920600108882084366671276216059100139841", "price": "0.992", "size": "44.83", "side": "BUY", "hash": "f017e8a47606823f33b73712a72f8b365e9abac6", "best_bid": "0.993", "best_ask": "0.999"}], "timestamp": "1769384489878", "event_type": "price_change"}}
{"_local_timestamp": "2026-01-25T23:41:30.002687+00:00", "data": {"market": "0x4341cc0ee3f6c33d5d14114804adbc56745ba69849a62ce33ba01f0f5fcb992d", "price_changes": [{"asset_id": "103859159453183957891244689604385927345314190615024118584206363782908647975749", "price": "0.067", "size": "0", "side": "SELL", "hash": "e4b726fb29744e7ccda3726e5e1269ac0f4ad580", "best_bid": "0", "best_ask": "0.001"}, {"asset_id": "87105071850972641214581759809593758129422200795386115503863798159438712941487", "price": "0.933", "size": "0", "side": "BUY", "hash": "c3f954603c1ba7cb79c8baa75bbdf2d3d5ea9d80", "best_bid": "0.999", "best_ask": "1"}], "timestamp": "1769384489878", "event_type": "price_change"}}
{"_local_timestamp": "2026-01-25T23:41:30.003097+00:00", "data": {"market": "0xaaf07b81d091318fc50eea80f8c9848a45c901dbdd49a3291b3c4ec32669f4f6", "price_changes": [{"asset_id": "76470301286950624198649364496103459585378536165660664290615779124087725034055", "price": "0.004", "size": "5.86", "side": "SELL", "hash": "149422d6b15076ec446101a2bb7c1544ca5adadb", "best_bid": "0", "best_ask": "0.001"}, {"asset_id": "77725644515863814306743026513820299582079276775056525666400499082315809995002", "price": "0.996", "size": "5.86", "side": "BUY", "hash": "755bd6244c58bbce81b53d33705077a11dcda9b2", "best_bid": "0.999", "best_ask": "1"}], "timestamp": "1769384489878", "event_type": "price_change"}}
{"_local_timestamp": "2026-01-25T23:41:30.362763+00:00", "data": {"market": "0xaaf07b81d091318fc50eea80f8c9848a45c901dbdd49a3291b3c4ec32669f4f6", "price_changes": [{"asset_id": "76470301286950624198649364496103459585378536165660664290615779124087725034055", "price": "0.008", "size": "92.12", "side": "SELL", "hash": "359573399b435b1dab30d881cfce1f5661461fcc", "best_bid": "0", "best_ask": "0.001"}, {"asset_id": "77725644515863814306743026513820299582079276775056525666400499082315809995002", "price": "0.992", "size": "92.12", "side": "BUY", "hash": "46ea5837b997c5af32980f2e387a626fa211b194", "best_bid": "0.999", "best_ask": "1"}], "timestamp": "1769384490218", "event_type": "price_change"}}
{"_local_timestamp": "2026-01-25T23:41:30.363223+00:00", "data": {"market": "0x60d31be668659012a5f83ee259c9b4eee3053c71dd68abe4d277f54722cd017f", "price_changes": [{"asset_id": "42488602124923334991804541582064494050024109479561101679507993012554771196517", "price": "0.006", "size": "8.22", "side": "SELL", "hash": "eaa0a1919d64cc602b7846475875344c8c931366", "best_bid": "0.001", "best_ask": "0.006"}, {"asset_id": "102579243304231960045442519614514577865920600108882084366671276216059100139841", "price": "0.994", "size": "8.22", "side": "BUY", "hash": "69a81848efb7e3da151cc48a8e1ded27d55dc979", "best_bid": "0.994", "best_ask": "0.999"}], "timestamp": "1769384490218", "event_type": "price_change"}}
{"_local_timestamp": "2026-01-25T23:41:30.363528+00:00", "data": {"market": "0x4341cc0ee3f6c33d5d14114804adbc56745ba69849a62ce33ba01f0f5fcb992d", "price_changes": [{"asset_id": "103859159453183957891244689604385927345314190615024118584206363782908647975749", "price": "0.065", "size": "8.21", "side": "SELL", "hash": "f74ff18e07b00f84a2443c4e6ef0858ea390bd39", "best_bid": "0", "best_ask": "0.001"}, {"asset_id": "87105071850972641214581759809593758129422200795386115503863798159438712941487", "price": "0.935", "size": "8.21", "side": "BUY", "hash": "46d30cc1c866ca5f398876288c498c96978edd81", "best_bid": "0.999", "best_ask": "1"}], "timestamp": "1769384490218", "event_type": "price_change"}}
{"_local_timestamp": "2026-01-25T23:41:30.432769+00:00", "data": {"market": "0x43d906123758b44e9b41f460d8619e290954186d3fe3a0544319216c30d2be24", "price_changes": [{"asset_id": "8986753851227051304286293461908502563978603715241747497243698980934689505938", "price": "0.008", "size": "44.82", "side": "SELL", "hash": "7d7ddfdbbd3cf4c25c387c736969d2be57af581e", "best_bid": "0.001", "best_ask": "0.007"}, {"asset_id": "15126910918760844641806927476005282998778904719663987971332027436874715278711", "price": "0.992", "size": "44.82", "side": "BUY", "hash": "0e3cb49b3581853d35044de4eb34029082cee029", "best_bid": "0.993", "best_ask": "0.999"}], "timestamp": "1769384490293", "event_type": "price_change"}}
{"_local_timestamp": "2026-01-25T23:41:30.733509+00:00", "data": {"market": "0x43d906123758b44e9b41f460d8619e290954186d3fe3a0544319216c30d2be24", "price_changes": [{"asset_id": "8986753851227051304286293461908502563978603715241747497243698980934689505938", "price": "0.006", "size": "8.21", "side": "SELL", "hash": "23585b3a3779ed318f08bb23ab3915e4e5af63da", "best_bid": "0.001", "best_ask": "0.006"}, {"asset_id": "15126910918760844641806927476005282998778904719663987971332027436874715278711", "price": "0.994", "size": "8.21", "side": "BUY", "hash": "7febe11d166cf594064d33f0618e4e8dbb534650", "best_bid": "0.994", "best_ask": "0.999"}], "timestamp": "1769384490599", "event_type": "price_change"}}
{"_local_timestamp": "2026-01-25T23:41:30.851308+00:00", "data": {"market": "0xaaf07b81d091318fc50eea80f8c9848a45c901dbdd49a3291b3c4ec32669f4f6", "price_changes": [{"asset_id": "76470301286950624198649364496103459585378536165660664290615779124087725034055", "price": "0.004", "size": "0", "side": "SELL", "hash": "9702d315e40bacee00a10b09ec5d6ebc37627c18", "best_bid": "0", "best_ask": "0.001"}, {"asset_id": "77725644515863814306743026513820299582079276775056525666400499082315809995002", "price": "0.996", "size": "0", "side": "BUY", "hash": "535ebd9972cc57f982282f2097a7f3e89f357ca3", "best_bid": "0.999", "best_ask": "1"}], "timestamp": "1769384490712", "event_type": "price_change"}}
{"_local_timestamp": "2026-01-25T23:41:30.903834+00:00", "data": {"market": "0x43d906123758b44e9b41f460d8619e290954186d3fe3a0544319216c30d2be24", "price_changes": [{"asset_id": "8986753851227051304286293461908502563978603715241747497243698980934689505938", "price": "0.007", "size": "0", "side": "SELL", "hash": "c3e02bab2e92473ebf19cbb241fa34b05e54ff0c", "best_bid": "0.001", "best_ask": "0.006"}, {"asset_id": "15126910918760844641806927476005282998778904719663987971332027436874715278711", "price": "0.993", "size": "0", "side": "BUY", "hash": "87099e8e032737e9f3aa2324758c25a6786d022c", "best_bid": "0.994", "best_ask": "0.999"}], "timestamp": "1769384490758", "event_type": "price_change"}}
{"_local_timestamp": "2026-01-25T23:41:30.904166+00:00", "data": {"market": "0x60d31be668659012a5f83ee259c9b4eee3053c71dd68abe4d277f54722cd017f", "price_changes": [{"asset_id": "42488602124923334991804541582064494050024109479561101679507993012554771196517", "price": "0.007", "size": "0", "side": "SELL", "hash": "d4dadfaa387d240514069a892357db6f66c20791", "best_bid": "0.001", "best_ask": "0.006"}, {"asset_id": "102579243304231960045442519614514577865920600108882084366671276216059100139841", "price": "0.993", "size": "0", "side": "BUY", "hash": "0c2d89b7f6584a14524dae6503456298caf90c77", "best_bid": "0.994", "best_ask": "0.999"}], "timestamp": "1769384490758", "event_type": "price_change"}}
{"_local_timestamp": "2026-01-25T23:41:30.904430+00:00", "data": {"market": "0x4341cc0ee3f6c33d5d14114804adbc56745ba69849a62ce33ba01f0f5fcb992d", "price_changes": [{"asset_id": "103859159453183957891244689604385927345314190615024118584206363782908647975749", "price": "0.066", "size": "0", "side": "SELL", "hash": "3542e0b893b593fd33ca90915ac7b8a7e21058af", "best_bid": "0", "best_ask": "0.001"}, {"asset_id": "87105071850972641214581759809593758129422200795386115503863798159438712941487", "price": "0.934", "size": "0", "side": "BUY", "hash": "593134648a4051c51c5a84880bd76d92af70aef1", "best_bid": "0.999", "best_ask": "1"}], "timestamp": "1769384490758", "event_type": "price_change"}}
{"_local_timestamp": "2026-01-25T23:41:30.958563+00:00", "data": {"market": "0x4341cc0ee3f6c33d5d14114804adbc56745ba69849a62ce33ba01f0f5fcb992d", "price_changes": [{"asset_id": "103859159453183957891244689604385927345314190615024118584206363782908647975749", "price": "0.064", "size": "5.47", "side": "SELL", "hash": "ad77ab125fd1ae9143e23b4bbb2ddc71c0fab51b", "best_bid": "0", "best_ask": "0.001"}, {"asset_id": "87105071850972641214581759809593758129422200795386115503863798159438712941487", "price": "0.936", "size": "5.47", "side": "BUY", "hash": "294646319f6c950773be70c358f914eae810e925", "best_bid": "0.999", "best_ask": "1"}], "timestamp": "1769384490808", "event_type": "price_change"}}
{"_local_timestamp": "2026-01-25T23:41:31.006463+00:00", "data": {"market": "0x60d31be668659012a5f83ee259c9b4eee3053c71dd68abe4d277f54722cd017f", "price_changes": [{"asset_id": "42488602124923334991804541582064494050024109479561101679507993012554771196517", "price": "0.005", "size": "5.47", "side": "SELL", "hash": "1bcaabbf0a4359c2739dff8018d64b00be0420ca", "best_bid": "0.001", "best_ask": "0.005"}, {"asset_id": "102579243304231960045442519614514577865920600108882084366671276216059100139841", "price": "0.995", "size": "5.47", "side": "BUY", "hash": "6387ac0daadc8b9ea3e7eda51e2f6f7c449bc16f", "best_bid": "0.995", "best_ask": "0.999"}], "timestamp": "1769384490862", "event_type": "price_change"}}
{"_local_timestamp": "2026-01-25T23:41:31.008513+00:00", "data": {"market": "0x43d906123758b44e9b41f460d8619e290954186d3fe3a0544319216c30d2be24", "price_changes": [{"asset_id": "8986753851227051304286293461908502563978603715241747497243698980934689505938", "price": "0.005", "size": "5.47", "side": "SELL", "hash": "b90b02e04d3f7033edd88c0f4f352ef6414671b3", "best_bid": "0.001", "best_ask": "0.005"}, {"asset_id": "15126910918760844641806927476005282998778904719663987971332027436874715278711", "price": "0.995", "size": "5.47", "side": "BUY", "hash": "edc25d3e399c4db413e4bbc483276930274b2652", "best_bid": "0.995", "best_ask": "0.999"}], "timestamp": "1769384490863", "event_type": "price_change"}}
{"_local_timestamp": "2026-01-25T23:41:31.137193+00:00", "data": {"market": "0xaaf07b81d091318fc50eea80f8c9848a45c901dbdd49a3291b3c4ec32669f4f6", "price_changes": [{"asset_id": "76470301286950624198649364496103459585378536165660664290615779124087725034055", "price": "0.008", "size": "97.98", "side": "SELL", "hash": "0903636fcf368016f174810bf4521523951b22c0", "best_bid": "0", "best_ask": "0.001"}, {"asset_id": "77725644515863814306743026513820299582079276775056525666400499082315809995002", "price": "0.992", "size": "97.98", "side": "BUY", "hash": "296612010dbe2da6de2aa401cabd46b421fab165", "best_bid": "0.999", "best_ask": "1"}], "timestamp": "1769384490992", "event_type": "price_change"}}
{"_local_timestamp": "2026-01-25T23:41:31.285228+00:00", "data": {"market": "0x43d906123758b44e9b41f460d8619e290954186d3fe3a0544319216c30d2be24", "price_changes": [{"asset_id": "8986753851227051304286293461908502563978603715241747497243698980934689505938", "price": "0.006", "size": "0", "side": "SELL", "hash": "fa0a174fb222c67a75a44bc0249624ba3bef94ab", "best_bid": "0.001", "best_ask": "0.005"}, {"asset_id": "15126910918760844641806927476005282998778904719663987971332027436874715278711", "price": "0.994", "size": "0", "side": "BUY", "hash": "1f119aca804e143b7abbbd48b4f693b855e3479f", "best_bid": "0.995", "best_ask": "0.999"}], "timestamp": "1769384491143", "event_type": "price_change"}}
{"_local_timestamp": "2026-01-25T23:41:31.286111+00:00", "data": {"market": "0x60d31be668659012a5f83ee259c9b4eee3053c71dd68abe4d277f54722cd017f", "price_changes": [{"asset_id": "42488602124923334991804541582064494050024109479561101679507993012554771196517", "price": "0.006", "size": "0", "side": "SELL", "hash": "bc32823944f8673e073a31259ccad8f85b187431", "best_bid": "0.001", "best_ask": "0.005"}, {"asset_id": "102579243304231960045442519614514577865920600108882084366671276216059100139841", "price": "0.994", "size": "0", "side": "BUY", "hash": "3f63786bd340234b7a1e6a4d4cfaf5d2b00514ab", "best_bid": "0.995", "best_ask": "0.999"}], "timestamp": "1769384491143", "event_type": "price_change"}}
{"_local_timestamp": "2026-01-25T23:41:31.290697+00:00", "data": {"market": "0x4341cc0ee3f6c33d5d14114804adbc56745ba69849a62ce33ba01f0f5fcb992d", "price_changes": [{"asset_id": "103859159453183957891244689604385927345314190615024118584206363782908647975749", "price": "0.065", "size": "0", "side": "SELL", "hash": "7da80aced9413a57ff6bb8aa5e909b7baa4a0f3c", "best_bid": "0", "best_ask": "0.001"}, {"asset_id": "87105071850972641214581759809593758129422200795386115503863798159438712941487", "price": "0.935", "size": "0", "side": "BUY", "hash": "56a9a8f595fdfac31de8835b14e676aa92cecb93", "best_bid": "0.999", "best_ask": "1"}], "timestamp": "1769384491143", "event_type": "price_change"}}
{"_local_timestamp": "2026-01-25T23:41:31.745491+00:00", "data": {"market": "0x43d906123758b44e9b41f460d8619e290954186d3fe3a0544319216c30d2be24", "price_changes": [{"asset_id": "8986753851227051304286293461908502563978603715241747497243698980934689505938", "price": "0.008", "size": "53.03", "side": "SELL", "hash": "af7cde6c0bfb7ec43fdd99d080f3526219309531", "best_bid": "0.001", "best_ask": "0.005"}, {"asset_id": "15126910918760844641806927476005282998778904719663987971332027436874715278711", "price": "0.992", "size": "53.03", "side": "BUY", "hash": "98ba18eb65e2a799c3949f0999b2fff353166fb0", "best_bid": "0.995", "best_ask": "0.999"}], "timestamp": "1769384491582", "event_type": "price_change"}}
{"_local_timestamp": "2026-01-25T23:41:31.747424+00:00", "data": {"market": "0x4341cc0ee3f6c33d5d14114804adbc56745ba69849a62ce33ba01f0f5fcb992d", "price_changes": [{"asset_id": "103859159453183957891244689604385927345314190615024118584206363782908647975749", "price": "0.063", "size": "8.21", "side": "SELL", "hash": "de01665ce15a41b445f4aeee08c87edfeb472d25", "best_bid": "0", "best_ask": "0.001"}, {"asset_id": "87105071850972641214581759809593758129422200795386115503863798159438712941487", "price": "0.937", "size": "8.21", "side": "BUY", "hash": "c749f69f8c3ab83f70b2b3224a9426cdecb01b70", "best_bid": "0.999", "best_ask": "1"}], "timestamp": "1769384491582", "event_type": "price_change"}}
{"_local_timestamp": "2026-01-25T23:41:31.747880+00:00", "data": {"market": "0x60d31be668659012a5f83ee259c9b4eee3053c71dd68abe4d277f54722cd017f", "price_changes": [{"asset_id": "42488602124923334991804541582064494050024109479561101679507993012554771196517", "price": "0.008", "size": "53.05", "side": "SELL", "hash": "3c7cac79388e3f3797f97c8d3dd02666913e1db7", "best_bid": "0.001", "best_ask": "0.005"}, {"asset_id": "102579243304231960045442519614514577865920600108882084366671276216059100139841", "price": "0.992", "size": "53.05", "side": "BUY", "hash": "c41bf5a5f6a31b2e2b169c57c3d0e6c3e0c1620a", "best_bid": "0.995", "best_ask": "0.999"}], "timestamp": "1769384491582", "event_type": "price_change"}}
{"_local_timestamp": "2026-01-25T23:41:32.679239+00:00", "data": {"market": "0xaaf07b81d091318fc50eea80f8c9848a45c901dbdd49a3291b3c4ec32669f4f6", "price_changes": [{"asset_id": "76470301286950624198649364496103459585378536165660664290615779124087725034055", "price": "0.003", "size": "0", "side": "SELL", "hash": "9ba8f53b39e99a9d0238e50244aa646717bc5a98", "best_bid": "0", "best_ask": "0.001"}, {"asset_id": "77725644515863814306743026513820299582079276775056525666400499082315809995002", "price": "0.997", "size": "0", "side": "BUY", "hash": "7374f8cf324a649c57fdb2ee6a2c0e901f100653", "best_bid": "0.999", "best_ask": "1"}], "timestamp": "1769384492513", "event_type": "price_change"}}
{"_local_timestamp": "2026-01-25T23:41:32.748356+00:00", "data": {"market": "0xaaf07b81d091318fc50eea80f8c9848a45c901dbdd49a3291b3c4ec32669f4f6", "price_changes": [{"asset_id": "76470301286950624198649364496103459585378536165660664290615779124087725034055", "price": "0.007", "size": "10.47", "side": "SELL", "hash": "77e3469bfccdcbc2469b25a2db1b61dd0c66968c", "best_bid": "0", "best_ask": "0.001"}, {"asset_id": "77725644515863814306743026513820299582079276775056525666400499082315809995002", "price": "0.993", "size": "10.47", "side": "BUY", "hash": "cfad5b272bae60acd4ca9e6e901a24ee82a8ae58", "best_bid": "0.999", "best_ask": "1"}], "timestamp": "1769384492573", "event_type": "price_change"}}
{"_local_timestamp": "2026-01-25T23:41:33.209993+00:00", "data": {"market": "0xaaf07b81d091318fc50eea80f8c9848a45c901dbdd49a3291b3c4ec32669f4f6", "price_changes": [{"asset_id": "76470301286950624198649364496103459585378536165660664290615779124087725034055", "price": "0.008", "size": "92.01", "side": "SELL", "hash": "f85e4f653d3d26ed4e93526d82b49291f9892b34", "best_bid": "0", "best_ask": "0.001"}, {"asset_id": "77725644515863814306743026513820299582079276775056525666400499082315809995002", "price": "0.992", "size": "92.01", "side": "BUY", "hash": "f89bd0d7fccbe7ae93a2b35c75691b876a6339d2", "best_bid": "0.999", "best_ask": "1"}], "timestamp": "1769384493059", "event_type": "price_change"}}
{"_local_timestamp": "2026-01-25T23:41:33.490544+00:00", "data": {"market": "0xaaf07b81d091318fc50eea80f8c9848a45c901dbdd49a3291b3c4ec32669f4f6", "price_changes": [{"asset_id": "76470301286950624198649364496103459585378536165660664290615779124087725034055", "price": "0.006", "size": "5.97", "side": "SELL", "hash": "b34fef5f2df333dbdd22e566c6a6225f2f0e073a", "best_bid": "0", "best_ask": "0.001"}, {"asset_id": "77725644515863814306743026513820299582079276775056525666400499082315809995002", "price": "0.994", "size": "5.97", "side": "BUY", "hash": "da21b2ea90a730dee7adfd066b7d46c3270ba595", "best_bid": "0.999", "best_ask": "1"}], "timestamp": "1769384493321", "event_type": "price_change"}}
{"_local_timestamp": "2026-01-25T23:41:33.924608+00:00", "data": {"market": "0xaaf07b81d091318fc50eea80f8c9848a45c901dbdd49a3291b3c4ec32669f4f6", "price_changes": [{"asset_id": "76470301286950624198649364496103459585378536165660664290615779124087725034055", "price": "0.008", "size": "86.15", "side": "SELL", "hash": "c6d477dc3f164874daa5070979e7251d487c06d5", "best_bid": "0", "best_ask": "0.001"}, {"asset_id": "77725644515863814306743026513820299582079276775056525666400499082315809995002", "price": "0.992", "size": "86.15", "side": "BUY", "hash": "cc9b373e176244c8319f6888849860d6262a44ee", "best_bid": "0.999", "best_ask": "1"}], "timestamp": "1769384493781", "event_type": "price_change"}}
{"_local_timestamp": "2026-01-25T23:41:34.139743+00:00", "data": {"market": "0x60d31be668659012a5f83ee259c9b4eee3053c71dd68abe4d277f54722cd017f", "price_changes": [{"asset_id": "42488602124923334991804541582064494050024109479561101679507993012554771196517", "price": "0.005", "size": "0", "side": "SELL", "hash": "7a78b6fc51b61a5a37ed496d6e791e06a76b1bee", "best_bid": "0.001", "best_ask": "0.008"}, {"asset_id": "102579243304231960045442519614514577865920600108882084366671276216059100139841", "price": "0.995", "size": "0", "side": "BUY", "hash": "e7bb0bcc425f3f14a6ab186924581ad97d2b5be7", "best_bid": "0.992", "best_ask": "0.999"}], "timestamp": "1769384493991", "event_type": "price_change"}}
{"_local_timestamp": "2026-01-25T23:41:34.140100+00:00", "data": {"market": "0xaaf07b81d091318fc50eea80f8c9848a45c901dbdd49a3291b3c4ec32669f4f6", "price_changes": [{"asset_id": "76470301286950624198649364496103459585378536165660664290615779124087725034055", "price": "0.007", "size": "0", "side": "SELL", "hash": "f4e7121400b88c6a9462a5641dc0178de0056312", "best_bid": "0", "best_ask": "0.001"}, {"asset_id": "77725644515863814306743026513820299582079276775056525666400499082315809995002", "price": "0.993", "size": "0", "side": "BUY", "hash": "76d85bfb141c248b11539e0a89aa8789cc56f48a", "best_bid": "0.999", "best_ask": "1"}], "timestamp": "1769384493991", "event_type": "price_change"}}
{"_local_timestamp": "2026-01-25T23:41:34.140348+00:00", "data": {"market": "0x4341cc0ee3f6c33d5d14114804adbc56745ba69849a62ce33ba01f0f5fcb992d", "price_changes": [{"asset_id": "103859159453183957891244689604385927345314190615024118584206363782908647975749", "price": "0.064", "size": "0", "side": "SELL", "hash": "a72d67c424effec69269bf7ab10c2688a6234d38", "best_bid": "0", "best_ask": "0.001"}, {"asset_id": "87105071850972641214581759809593758129422200795386115503863798159438712941487", "price": "0.936", "size": "0", "side": "BUY", "hash": "e41026411786f1bbb43f00e0f52e85e093dc8fa0", "best_bid": "0.999", "best_ask": "1"}], "timestamp": "1769384493991", "event_type": "price_change"}}
{"_local_timestamp": "2026-01-25T23:41:34.140613+00:00", "data": {"market": "0x43d906123758b44e9b41f460d8619e290954186d3fe3a0544319216c30d2be24", "price_changes": [{"asset_id": "8986753851227051304286293461908502563978603715241747497243698980934689505938", "price": "0.005", "size": "0", "side": "SELL", "hash": "04b125b57e22a28ceed12a2868102168c0455d9f", "best_bid": "0.001", "best_ask": "0.008"}, {"asset_id": "15126910918760844641806927476005282998778904719663987971332027436874715278711", "price": "0.995", "size": "0", "side": "BUY", "hash": "a4da8e4d5d77d339827d6eb8111dc01cd67b95ac", "best_bid": "0.992", "best_ask": "0.999"}], "timestamp": "1769384493991", "event_type": "price_change"}}
{"_local_timestamp": "2026-01-25T23:41:34.168986+00:00", "data": {"market": "0xaaf07b81d091318fc50eea80f8c9848a45c901dbdd49a3291b3c4ec32669f4f6", "price_changes": [{"asset_id": "76470301286950624198649364496103459585378536165660664290615779124087725034055", "price": "0.006", "size": "11.83", "side": "SELL", "hash": "1fb6dea7c8f24be6a4304f4525abd22dc918cdf3", "best_bid": "0", "best_ask": "0.001"}, {"asset_id": "77725644515863814306743026513820299582079276775056525666400499082315809995002", "price": "0.994", "size": "11.83", "side": "BUY", "hash": "3648607503dfd9737578ba04e42483c633442728", "best_bid": "0.999", "best_ask": "1"}], "timestamp": "1769384494014", "event_type": "price_change"}}
{"_local_timestamp": "2026-01-25T23:41:34.192768+00:00", "data": {"market": "0x4341cc0ee3f6c33d5d14114804adbc56745ba69849a62ce33ba01f0f5fcb992d", "price_changes": [{"asset_id": "103859159453183957891244689604385927345314190615024118584206363782908647975749", "price": "0.062", "size": "5.47", "side": "SELL", "hash": "a3dc9798ab97c797376c279d2b539d4eb55cb6b5", "best_bid": "0", "best_ask": "0.001"}, {"asset_id": "87105071850972641214581759809593758129422200795386115503863798159438712941487", "price": "0.938", "size": "5.47", "side": "BUY", "hash": "60e50f6e83352b3138a552a17ca150f235966e66", "best_bid": "0.999", "best_ask": "1"}], "timestamp": "1769384494042", "event_type": "price_change"}}
{"_local_timestamp": "2026-01-25T23:41:34.194382+00:00", "data": {"market": "0xaaf07b81d091318fc50eea80f8c9848a45c901dbdd49a3291b3c4ec32669f4f6", "price_changes": [{"asset_id": "76470301286950624198649364496103459585378536165660664290615779124087725034055", "price": "0.005", "size": "10.47", "side": "SELL", "hash": "7b4ef1f2fc769d2e028a98cabe64c2c1d5f5fe0f", "best_bid": "0", "best_ask": "0.001"}, {"asset_id": "77725644515863814306743026513820299582079276775056525666400499082315809995002", "price": "0.995", "size": "10.47", "side": "BUY", "hash": "1eb7d5d1b26d2b75488ee922fb157606fdd70cdb", "best_bid": "0.999", "best_ask": "1"}], "timestamp": "1769384494042", "event_type": "price_change"}}
{"_local_timestamp": "2026-01-25T23:41:34.230617+00:00", "data": {"market": "0x60d31be668659012a5f83ee259c9b4eee3053c71dd68abe4d277f54722cd017f", "price_changes": [{"asset_id": "42488602124923334991804541582064494050024109479561101679507993012554771196517", "price": "0.007", "size": "5.47", "side": "SELL", "hash": "87e371902de42ce7b9e3ef89e69f399868043566", "best_bid": "0.001", "best_ask": "0.007"}, {"asset_id": "102579243304231960045442519614514577865920600108882084366671276216059100139841", "price": "0.993", "size": "5.47", "side": "BUY", "hash": "fdb290c67f4cbddcf277fb88f8a279a8179ee713", "best_bid": "0.993", "best_ask": "0.999"}], "timestamp": "1769384494081", "event_type": "price_change"}}
{"_local_timestamp": "2026-01-25T23:41:34.231042+00:00", "data": {"market": "0x43d906123758b44e9b41f460d8619e290954186d3fe3a0544319216c30d2be24", "price_changes": [{"asset_id": "8986753851227051304286293461908502563978603715241747497243698980934689505938", "price": "0.007", "size": "5.47", "side": "SELL", "hash": "fb619eb3a7c252ab19baa58fc6a0d1fef0c7be55", "best_bid": "0.001", "best_ask": "0.007"}, {"asset_id": "15126910918760844641806927476005282998778904719663987971332027436874715278711", "price": "0.993", "size": "5.47", "side": "BUY", "hash": "b45487e321c84a3b00e064a9a916ed88e6450ff5", "best_bid": "0.993", "best_ask": "0.999"}], "timestamp": "1769384494081", "event_type": "price_change"}}
{"_local_timestamp": "2026-01-25T23:41:34.362902+00:00", "data": {"market": "0x4341cc0ee3f6c33d5d14114804adbc56745ba69849a62ce33ba01f0f5fcb992d", "price_changes": [{"asset_id": "103859159453183957891244689604385927345314190615024118584206363782908647975749", "price": "0.063", "size": "0", "side": "SELL", "hash": "e191c39ee0995469665a5a762183b2ae4f5ff930", "best_bid": "0", "best_ask": "0.001"}, {"asset_id": "87105071850972641214581759809593758129422200795386115503863798159438712941487", "price": "0.937", "size": "0", "side": "BUY", "hash": "0d19b94687d2431e494c4fa4ac0df0686186eb0b", "best_bid": "0.999", "best_ask": "1"}], "timestamp": "1769384494209", "event_type": "price_change"}}
{"_local_timestamp": "2026-01-25T23:41:34.671475+00:00", "data": {"market": "0x4341cc0ee3f6c33d5d14114804adbc56745ba69849a62ce33ba01f0f5fcb992d", "price_changes": [{"asset_id": "103859159453183957891244689604385927345314190615024118584206363782908647975749", "price": "0.061", "size": "8.21", "side": "SELL", "hash": "60fd78db5b630e8fd54e0629068297055935c589", "best_bid": "0", "best_ask": "0.001"}, {"asset_id": "87105071850972641214581759809593758129422200795386115503863798159438712941487", "price": "0.939", "size": "8.21", "side": "BUY", "hash": "c61147718b7e904b1a8477cbe14035d50a6d6d99", "best_bid": "0.999", "best_ask": "1"}], "timestamp": "1769384494494", "event_type": "price_change"}}
{"_local_timestamp": "2026-01-25T23:41:34.804772+00:00", "data": {"market": "0x43d906123758b44e9b41f460d8619e290954186d3fe3a0544319216c30d2be24", "price_changes": [{"asset_id": "8986753851227051304286293461908502563978603715241747497243698980934689505938", "price": "0.008", "size": "44.82", "side": "SELL", "hash": "0bfda410d1090eae00e4fe30a71a475bdaabbd42", "best_bid": "0.001", "best_ask": "0.007"}, {"asset_id": "15126910918760844641806927476005282998778904719663987971332027436874715278711", "price": "0.992", "size": "44.82", "side": "BUY", "hash": "5d46e1a05201849e1ffeba8f4b408ab81a97c136", "best_bid": "0.993", "best_ask": "0.999"}], "timestamp": "1769384494633", "event_type": "price_change"}}
{"_local_timestamp": "2026-01-25T23:41:34.805282+00:00", "data": {"market": "0xaaf07b81d091318fc50eea80f8c9848a45c901dbdd49a3291b3c4ec32669f4f6", "price_changes": [{"asset_id": "76470301286950624198649364496103459585378536165660664290615779124087725034055", "price": "0.006", "size": "5.86", "side": "SELL", "hash": "8dc587936bd186f09c9d0ab8a3c34df0425efa0a", "best_bid": "0", "best_ask": "0.001"}, {"asset_id": "77725644515863814306743026513820299582079276775056525666400499082315809995002", "price": "0.994", "size": "5.86", "side": "BUY", "hash": "bb1b3c61702402843c1d3b648e25efe08678dc46", "best_bid": "0.999", "best_ask": "1"}], "timestamp": "1769384494633", "event_type": "price_change"}}
{"_local_timestamp": "2026-01-25T23:41:34.805562+00:00", "data": {"market": "0x60d31be668659012a5f83ee259c9b4eee3053c71dd68abe4d277f54722cd017f", "price_changes": [{"asset_id": "42488602124923334991804541582064494050024109479561101679507993012554771196517", "price": "0.008", "size": "44.83", "side": "SELL", "hash": "0b25e0b97954927b5cc8d8a95396b1cd55408b00", "best_bid": "0.001", "best_ask": "0.007"}, {"asset_id": "102579243304231960045442519614514577865920600108882084366671276216059100139841", "price": "0.992", "size": "44.83", "side": "BUY", "hash": "3cca6f81b8d9d41661a47b49b3828050f0658ecb", "best_bid": "0.993", "best_ask": "0.999"}], "timestamp": "1769384494633", "event_type": "price_change"}}
{"_local_timestamp": "2026-01-25T23:41:35.085987+00:00", "data": {"market": "0x60d31be668659012a5f83ee259c9b4eee3053c71dd68abe4d277f54722cd017f", "price_changes": [{"asset_id": "42488602124923334991804541582064494050024109479561101679507993012554771196517", "price": "0.002", "size": "5", "side": "BUY", "hash": "cf36d391d0340dc30e6bbf333fd13051d7613736", "best_bid": "0.002", "best_ask": "0.007"}, {"asset_id": "102579243304231960045442519614514577865920600108882084366671276216059100139841", "price": "0.998", "size": "5", "side": "SELL", "hash": "3f0d121785f86ecdc3c94bd67fbbee8136661874", "best_bid": "0.993", "best_ask": "0.998"}], "timestamp": "1769384494928", "event_type": "price_change"}}
{"_local_timestamp": "2026-01-25T23:41:35.087484+00:00", "data": {"market": "0x43d906123758b44e9b41f460d8619e290954186d3fe3a0544319216c30d2be24", "price_changes": [{"asset_id": "8986753851227051304286293461908502563978603715241747497243698980934689505938", "price": "0.002", "size": "5", "side": "BUY", "hash": "f8a617180a8c3b989c8e3d7b6907b6dab5635145", "best_bid": "0.002", "best_ask": "0.007"}, {"asset_id": "15126910918760844641806927476005282998778904719663987971332027436874715278711", "price": "0.998", "size": "5", "side": "SELL", "hash": "56bcf04456782b664c9a4f53152e8fb630c2b163", "best_bid": "0.993", "best_ask": "0.998"}], "timestamp": "1769384494928", "event_type": "price_change"}}
{"_local_timestamp": "2026-01-25T23:41:35.114526+00:00", "data": {"market": "0xaaf07b81d091318fc50eea80f8c9848a45c901dbdd49a3291b3c4ec32669f4f6", "price_changes": [{"asset_id": "76470301286950624198649364496103459585378536165660664290615779124087725034055", "price": "0.004", "size": "5.97", "side": "SELL", "hash": "353c95fe09d0d72189bf15c956f108e9f937ab1f", "best_bid": "0", "best_ask": "0.001"}, {"asset_id": "77725644515863814306743026513820299582079276775056525666400499082315809995002", "price": "0.996", "size": "5.97", "side": "BUY", "hash": "8b13b6c029183d9f062829d0bbf2f32fbc0f3e6a", "best_bid": "0.999", "best_ask": "1"}], "timestamp": "1769384494959", "event_type": "price_change"}}
{"_local_timestamp": "2026-01-25T23:41:35.114884+00:00", "data": {"market": "0x43d906123758b44e9b41f460d8619e290954186d3fe3a0544319216c30d2be24", "price_changes": [{"asset_id": "8986753851227051304286293461908502563978603715241747497243698980934689505938", "price": "0.006", "size": "8.21", "side": "SELL", "hash": "6ef0813eda004f75ce6fe62ba4abe3a5838cc629", "best_bid": "0.002", "best_ask": "0.006"}, {"asset_id": "15126910918760844641806927476005282998778904719663987971332027436874715278711", "price": "0.994", "size": "8.21", "side": "BUY", "hash": "06f52ce940ac9ccf28a2fb2c1e50113e6936c282", "best_bid": "0.994", "best_ask": "0.998"}], "timestamp": "1769384494959", "event_type": "price_change"}}
{"_local_timestamp": "2026-01-25T23:41:35.115145+00:00", "data": {"market": "0x60d31be668659012a5f83ee259c9b4eee3053c71dd68abe4d277f54722cd017f", "price_changes": [{"asset_id": "42488602124923334991804541582064494050024109479561101679507993012554771196517", "price": "0.006", "size": "8.22", "side": "SELL", "hash": "86c619a7bb6d45bfbcaedaef5fd4995edf66a4a3", "best_bid": "0.002", "best_ask": "0.006"}, {"asset_id": "102579243304231960045442519614514577865920600108882084366671276216059100139841", "price": "0.994", "size": "8.22", "side": "BUY", "hash": "047e8861844d6696eac751fc119d67424e3f3f53", "best_bid": "0.994", "best_ask": "0.998"}], "timestamp": "1769384494959", "event_type": "price_change"}}
{"_local_timestamp": "2026-01-25T23:41:35.615628+00:00", "data": {"market": "0xaaf07b81d091318fc50eea80f8c9848a45c901dbdd49a3291b3c4ec32669f4f6", "price_changes": [{"asset_id": "76470301286950624198649364496103459585378536165660664290615779124087725034055", "price": "0.006", "size": "0", "side": "SELL", "hash": "d17aa93b74ab3b61fe05a573463a95472ac350e7", "best_bid": "0", "best_ask": "0.001"}, {"asset_id": "77725644515863814306743026513820299582079276775056525666400499082315809995002", "price": "0.994", "size": "0", "side": "BUY", "hash": "fc93cf8a0ccb8bad0dcf6e878510956117424fcc", "best_bid": "0.999", "best_ask": "1"}], "timestamp": "1769384495488", "event_type": "price_change"}}
{"_local_timestamp": "2026-01-25T23:41:35.707488+00:00", "data": {"market": "0xaaf07b81d091318fc50eea80f8c9848a45c901dbdd49a3291b3c4ec32669f4f6", "price_changes": [{"asset_id": "76470301286950624198649364496103459585378536165660664290615779124087725034055", "price": "0.005", "size": "0", "side": "SELL", "hash": "9492854ebbc7453572cc29ba3e5a12a85e1ca545", "best_bid": "0", "best_ask": "0.001"}, {"asset_id": "77725644515863814306743026513820299582079276775056525666400499082315809995002", "price": "0.995", "size": "0", "side": "BUY", "hash": "61defa1c3cede29d37a08601069aeac0e285309c", "best_bid": "0.999", "best_ask": "1"}], "timestamp": "1769384495582", "event_type": "price_change"}}
{"_local_timestamp": "2026-01-25T23:41:35.716415+00:00", "data": {"market": "0x43d906123758b44e9b41f460d8619e290954186d3fe3a0544319216c30d2be24", "price_changes": [{"asset_id": "8986753851227051304286293461908502563978603715241747497243698980934689505938", "price": "0.007", "size": "0", "side": "SELL", "hash": "feddebf64b6bf01de662210e547331b078e6eb8d", "best_bid": "0.002", "best_ask": "0.006"}, {"asset_id": "15126910918760844641806927476005282998778904719663987971332027436874715278711", "price": "0.993", "size": "0", "side": "BUY", "hash": "b1902852368448d9144f421e7bd27eec3482c1e1", "best_bid": "0.994", "best_ask": "0.998"}], "timestamp": "1769384495582", "event_type": "price_change"}}
{"_local_timestamp": "2026-01-25T23:41:35.716823+00:00", "data": {"market": "0x60d31be668659012a5f83ee259c9b4eee3053c71dd68abe4d277f54722cd017f", "price_changes": [{"asset_id": "42488602124923334991804541582064494050024109479561101679507993012554771196517", "price": "0.007", "size": "0", "side": "SELL", "hash": "72cad8947c694c5f7422362d4eb0549736942976", "best_bid": "0.002", "best_ask": "0.006"}, {"asset_id": "102579243304231960045442519614514577865920600108882084366671276216059100139841", "price": "0.993", "size": "0", "side": "BUY", "hash": "3544e76e5650fa4788687cfab19c2d2d5519d47f", "best_bid": "0.994", "best_ask": "0.998"}], "timestamp": "1769384495582", "event_type": "price_change"}}
{"_local_timestamp": "2026-01-25T23:41:35.717404+00:00", "data": {"market": "0x4341cc0ee3f6c33d5d14114804adbc56745ba69849a62ce33ba01f0f5fcb992d", "price_changes": [{"asset_id": "103859159453183957891244689604385927345314190615024118584206363782908647975749", "price": "0.062", "size": "0", "side": "SELL", "hash": "738d878666561643cca76201f8c5fa22a34a10bc", "best_bid": "0", "best_ask": "0.001"}, {"asset_id": "87105071850972641214581759809593758129422200795386115503863798159438712941487", "price": "0.938", "size": "0", "side": "BUY", "hash": "9242ff3fe2a7af2557748349ecf20e00a4e102a9", "best_bid": "0.999", "best_ask": "1"}], "timestamp": "1769384495582", "event_type": "price_change"}}
{"_local_timestamp": "2026-01-25T23:41:35.758376+00:00", "data": {"market": "0x4341cc0ee3f6c33d5d14114804adbc56745ba69849a62ce33ba01f0f5fcb992d", "price_changes": [{"asset_id": "103859159453183957891244689604385927345314190615024118584206363782908647975749", "price": "0.06", "size": "5.47", "side": "SELL", "hash": "1b499db4472cac765911b2b152fbe46a6251b5f3", "best_bid": "0", "best_ask": "0.001"}, {"asset_id": "87105071850972641214581759809593758129422200795386115503863798159438712941487", "price": "0.94", "size": "5.47", "side": "BUY", "hash": "affc5dfe76d10d126359aa448cfe109f1be91353", "best_bid": "0.999", "best_ask": "1"}], "timestamp": "1769384495631", "event_type": "price_change"}}
{"_local_timestamp": "2026-01-25T23:41:35.764332+00:00", "data": {"market": "0xaaf07b81d091318fc50eea80f8c9848a45c901dbdd49a3291b3c4ec32669f4f6", "price_changes": [{"asset_id": "76470301286950624198649364496103459585378536165660664290615779124087725034055", "price": "0.003", "size": "10.47", "side": "SELL", "hash": "9e5f9f0844b38dd35e801d5a3f373a9fbf9027c8", "best_bid": "0", "best_ask": "0.001"}, {"asset_id": "77725644515863814306743026513820299582079276775056525666400499082315809995002", "price": "0.997", "size": "10.47", "side": "BUY", "hash": "e3d4d035e6f02ef34849204c03191cad15d69341", "best_bid": "0.999", "best_ask": "1"}], "timestamp": "1769384495632", "event_type": "price_change"}}
{"_local_timestamp": "2026-01-25T23:41:35.804594+00:00", "data": {"market": "0x60d31be668659012a5f83ee259c9b4eee3053c71dd68abe4d277f54722cd017f", "price_changes": [{"asset_id": "42488602124923334991804541582064494050024109479561101679507993012554771196517", "price": "0.005", "size": "5.47", "side": "SELL", "hash": "cffb1a0d4f23b4372ba76a827b2a6eb306e5d7f3", "best_bid": "0.002", "best_ask": "0.005"}, {"asset_id": "102579243304231960045442519614514577865920600108882084366671276216059100139841", "price": "0.995", "size": "5.47", "side": "BUY", "hash": "a542064b744f500969d7b3dfd3d31a8c675f7345", "best_bid": "0.995", "best_ask": "0.998"}], "timestamp": "1769384495674", "event_type": "price_change"}}
{"_local_timestamp": "2026-01-25T23:41:35.841650+00:00", "data": {"market": "0x43d906123758b44e9b41f460d8619e290954186d3fe3a0544319216c30d2be24", "price_changes": [{"asset_id": "8986753851227051304286293461908502563978603715241747497243698980934689505938", "price": "0.005", "size": "5.47", "side": "SELL", "hash": "4b82622ff469b90105a0adbc59e00003af6ec0e0", "best_bid": "0.002", "best_ask": "0.005"}, {"asset_id": "15126910918760844641806927476005282998778904719663987971332027436874715278711", "price": "0.995", "size": "5.47", "side": "BUY", "hash": "f8cf66d2511e0065b67917aaf154f0035535ae82", "best_bid": "0.995", "best_ask": "0.998"}], "timestamp": "1769384495708", "event_type": "price_change"}}
{"_local_timestamp": "2026-01-25T23:41:35.869040+00:00", "data": {"market": "0xaaf07b81d091318fc50eea80f8c9848a45c901dbdd49a3291b3c4ec32669f4f6", "price_changes": [{"asset_id": "76470301286950624198649364496103459585378536165660664290615779124087725034055", "price": "0.004", "size": "11.83", "side": "SELL", "hash": "58f185045d9871795e812f4f7ccfe169f59250a0", "best_bid": "0", "best_ask": "0.001"}, {"asset_id": "77725644515863814306743026513820299582079276775056525666400499082315809995002", "price": "0.996", "size": "11.83", "side": "BUY", "hash": "2eb2325fbbb9523980d67376c3ea125b82eabbfc", "best_bid": "0.999", "best_ask": "1"}], "timestamp": "1769384495744", "event_type": "price_change"}}
{"_local_timestamp": "2026-01-25T23:41:36.035028+00:00", "data": {"market": "0x4341cc0ee3f6c33d5d14114804adbc56745ba69849a62ce33ba01f0f5fcb992d", "price_changes": [{"asset_id": "103859159453183957891244689604385927345314190615024118584206363782908647975749", "price": "0.061", "size": "0", "side": "SELL", "hash": "dccfe690917bcd32ce25b95c3b3b50e1e15db149", "best_bid": "0", "best_ask": "0.001"}, {"asset_id": "87105071850972641214581759809593758129422200795386115503863798159438712941487", "price": "0.939", "size": "0", "side": "BUY", "hash": "e4ede716ef8af1b8f13c666d67b83bd12089c246", "best_bid": "0.999", "best_ask": "1"}], "timestamp": "1769384495907", "event_type": "price_change"}}
{"_local_timestamp": "2026-01-25T23:41:36.388679+00:00", "data": {"market": "0x4341cc0ee3f6c33d5d14114804adbc56745ba69849a62ce33ba01f0f5fcb992d", "price_changes": [{"asset_id": "103859159453183957891244689604385927345314190615024118584206363782908647975749", "price": "0.059", "size": "8.21", "side": "SELL", "hash": "804bedca7e6b75fc036977bbe2d0931bceefecf6", "best_bid": "0", "best_ask": "0.001"}, {"asset_id": "87105071850972641214581759809593758129422200795386115503863798159438712941487", "price": "0.941", "size": "8.21", "side": "BUY", "hash": "62a9e2a908e6263c6055df3ca8e2cce4484e2130", "best_bid": "0.999", "best_ask": "1"}], "timestamp": "1769384496238", "event_type": "price_change"}}
{"_local_timestamp": "2026-01-25T23:41:36.463901+00:00", "data": {"market": "0x60d31be668659012a5f83ee259c9b4eee3053c71dd68abe4d277f54722cd017f", "price_changes": [{"asset_id": "42488602124923334991804541582064494050024109479561101679507993012554771196517", "price": "0.006", "size": "0", "side": "SELL", "hash": "c3cdebc5fee6a2d3d98df7fe1de6cc45f028ca7c", "best_bid": "0.002", "best_ask": "0.005"}, {"asset_id": "102579243304231960045442519614514577865920600108882084366671276216059100139841", "price": "0.994", "size": "0", "side": "BUY", "hash": "0aca1649be7dcf9d055f2591d59e26b561bf87d6", "best_bid": "0.995", "best_ask": "0.998"}], "timestamp": "1769384496325", "event_type": "price_change"}}
{"_local_timestamp": "2026-01-25T23:41:36.464371+00:00", "data": {"market": "0xaaf07b81d091318fc50eea80f8c9848a45c901dbdd49a3291b3c4ec32669f4f6", "price_changes": [{"asset_id": "76470301286950624198649364496103459585378536165660664290615779124087725034055", "price": "0.004", "size": "5.86", "side": "SELL", "hash": "14203bd513c9c29b11879ef54266c018b4aeace3", "best_bid": "0", "best_ask": "0.001"}, {"asset_id": "77725644515863814306743026513820299582079276775056525666400499082315809995002", "price": "0.996", "size": "5.86", "side": "BUY", "hash": "7e003dd9c6196572180a29398baf5a5946eb0638", "best_bid": "0.999", "best_ask": "1"}], "timestamp": "1769384496325", "event_type": "price_change"}}
{"_local_timestamp": "2026-01-25T23:41:36.464649+00:00", "data": {"market": "0x43d906123758b44e9b41f460d8619e290954186d3fe3a0544319216c30d2be24", "price_changes": [{"asset_id": "8986753851227051304286293461908502563978603715241747497243698980934689505938", "price": "0.006", "size": "0", "side": "SELL", "hash": "b497430c5054432d379b3b421ed3198f44d1b9ad", "best_bid": "0.002", "best_ask": "0.005"}, {"asset_id": "15126910918760844641806927476005282998778904719663987971332027436874715278711", "price": "0.994", "size": "0", "side": "BUY", "hash": "7b163e6d69923bc45bc1220e765cc334da2ad329", "best_bid": "0.995", "best_ask": "0.998"}], "timestamp": "1769384496325", "event_type": "price_change"}}
{"_local_timestamp": "2026-01-25T23:41:36.815240+00:00", "data": {"market": "0x43d906123758b44e9b41f460d8619e290954186d3fe3a0544319216c30d2be24", "price_changes": [{"asset_id": "8986753851227051304286293461908502563978603715241747497243698980934689505938", "price": "0.008", "size": "53.03", "side": "SELL", "hash": "120a653724a381a4e219082a2013ae31bfd5a01e", "best_bid": "0.002", "best_ask": "0.005"}, {"asset_id": "15126910918760844641806927476005282998778904719663987971332027436874715278711", "price": "0.992", "size": "53.03", "side": "BUY", "hash": "4eaea825375f874022d820864c58179c961172c4", "best_bid": "0.995", "best_ask": "0.998"}], "timestamp": "1769384496678", "event_type": "price_change"}}
{"_local_timestamp": "2026-01-25T23:41:36.815690+00:00", "data": {"market": "0x60d31be668659012a5f83ee259c9b4eee3053c71dd68abe4d277f54722cd017f", "price_changes": [{"asset_id": "42488602124923334991804541582064494050024109479561101679507993012554771196517", "price": "0.008", "size": "53.05", "side": "SELL", "hash": "ee65907d2972958147105961ad5f83a17f21ac4f", "best_bid": "0.002", "best_ask": "0.005"}, {"asset_id": "102579243304231960045442519614514577865920600108882084366671276216059100139841", "price": "0.992", "size": "53.05", "side": "BUY", "hash": "991ee544bf67ee8a102222c53a14700cd656b475", "best_bid": "0.995", "best_ask": "0.998"}], "timestamp": "1769384496678", "event_type": "price_change"}}
{"_local_timestamp": "2026-01-25T23:41:36.815951+00:00", "data": {"market": "0xaaf07b81d091318fc50eea80f8c9848a45c901dbdd49a3291b3c4ec32669f4f6", "price_changes": [{"asset_id": "76470301286950624198649364496103459585378536165660664290615779124087725034055", "price": "0.008", "size": "92.12", "side": "SELL", "hash": "a2051b564cf59ef19511a74263997ab3188a79ec", "best_bid": "0", "best_ask": "0.001"}, {"asset_id": "77725644515863814306743026513820299582079276775056525666400499082315809995002", "price": "0.992", "size": "92.12", "side": "BUY", "hash": "3b5294e084d0fb3d536294cfa3703dab56a59d28", "best_bid": "0.999", "best_ask": "1"}], "timestamp": "1769384496678", "event_type": "price_change"}}
{"_local_timestamp": "2026-01-25T23:41:37.175061+00:00", "data": {"market": "0x4341cc0ee3f6c33d5d14114804adbc56745ba69849a62ce33ba01f0f5fcb992d", "price_changes": [{"asset_id": "103859159453183957891244689604385927345314190615024118584206363782908647975749", "price": "0.06", "size": "0", "side": "SELL", "hash": "5e945e0208a986eb545f38b90e7d0e89ebc35389", "best_bid": "0", "best_ask": "0.001"}, {"asset_id": "87105071850972641214581759809593758129422200795386115503863798159438712941487", "price": "0.94", "size": "0", "side": "BUY", "hash": "cb8b0189aa0654cac08ff1d971b7d24ff038b9b9", "best_bid": "0.999", "best_ask": "1"}], "timestamp": "1769384497004", "event_type": "price_change"}}
{"_local_timestamp": "2026-01-25T23:41:37.177284+00:00", "data": {"market": "0x43d906123758b44e9b41f460d8619e290954186d3fe3a0544319216c30d2be24", "price_changes": [{"asset_id": "8986753851227051304286293461908502563978603715241747497243698980934689505938", "price": "0.005", "size": "0", "side": "SELL", "hash": "07457a83f747f7f82da08d5cfc521cd269d5d355", "best_bid": "0.002", "best_ask": "0.008"}, {"asset_id": "15126910918760844641806927476005282998778904719663987971332027436874715278711", "price": "0.995", "size": "0", "side": "BUY", "hash": "a81cec2a4c2915aef9d992234238eda03462a358", "best_bid": "0.992", "best_ask": "0.998"}], "timestamp": "1769384497004", "event_type": "price_change"}}
{"_local_timestamp": "2026-01-25T23:41:37.177653+00:00", "data": {"market": "0x60d31be668659012a5f83ee259c9b4eee3053c71dd68abe4d277f54722cd017f", "price_changes": [{"asset_id": "42488602124923334991804541582064494050024109479561101679507993012554771196517", "price": "0.005", "size": "0", "side": "SELL", "hash": "8518769cbdd0aede477ebb7479942d210713fef7", "best_bid": "0.002", "best_ask": "0.008"}, {"asset_id": "102579243304231960045442519614514577865920600108882084366671276216059100139841", "price": "0.995", "size": "0", "side": "BUY", "hash": "41554c466d18e545d2426f5a6e3439e9e820f6c7", "best_bid": "0.992", "best_ask": "0.998"}], "timestamp": "1769384497004", "event_type": "price_change"}}
{"_local_timestamp": "2026-01-25T23:41:37.205675+00:00", "data": {"market": "0x4341cc0ee3f6c33d5d14114804adbc56745ba69849a62ce33ba01f0f5fcb992d", "price_changes": [{"asset_id": "103859159453183957891244689604385927345314190615024118584206363782908647975749", "price": "0.058", "size": "5.47", "side": "SELL", "hash": "6b2646e08526a012fef94ed3080c775998c3e869", "best_bid": "0", "best_ask": "0.001"}, {"asset_id": "87105071850972641214581759809593758129422200795386115503863798159438712941487", "price": "0.942", "size": "5.47", "side": "BUY", "hash": "68f71fae94fa0f51e0e772fd428b932eaafd17b0", "best_bid": "0.999", "best_ask": "1"}], "timestamp": "1769384497055", "event_type": "price_change"}}
{"_local_timestamp": "2026-01-25T23:41:37.230066+00:00", "data": {"market": "0x60d31be668659012a5f83ee259c9b4eee3053c71dd68abe4d277f54722cd017f", "price_changes": [{"asset_id": "42488602124923334991804541582064494050024109479561101679507993012554771196517", "price": "0.007", "size": "5.47", "side": "SELL", "hash": "b110d01e397c6015141c1ce7829baef6ca1671c7", "best_bid": "0.002", "best_ask": "0.007"}, {"asset_id": "102579243304231960045442519614514577865920600108882084366671276216059100139841", "price": "0.993", "size": "5.47", "side": "BUY", "hash": "3d1acf7719c3236cf3abfac6fb5b5f675d28e5bd", "best_bid": "0.993", "best_ask": "0.998"}], "timestamp": "1769384497094", "event_type": "price_change"}}
{"_local_timestamp": "2026-01-25T23:41:37.230502+00:00", "data": {"market": "0x43d906123758b44e9b41f460d8619e290954186d3fe3a0544319216c30d2be24", "price_changes": [{"asset_id": "8986753851227051304286293461908502563978603715241747497243698980934689505938", "price": "0.007", "size": "5.47", "side": "SELL", "hash": "6d28e6c4ad7ff3bfc04e132aa940a921332500e0", "best_bid": "0.002", "best_ask": "0.007"}, {"asset_id": "15126910918760844641806927476005282998778904719663987971332027436874715278711", "price": "0.993", "size": "5.47", "side": "BUY", "hash": "460c85651c025e1f54a2d2cbf0a9defb27e27f0d", "best_bid": "0.993", "best_ask": "0.998"}], "timestamp": "1769384497094", "event_type": "price_change"}}
{"_local_timestamp": "2026-01-25T23:41:37.326351+00:00", "data": {"market": "0xaaf07b81d091318fc50eea80f8c9848a45c901dbdd49a3291b3c4ec32669f4f6", "price_changes": [{"asset_id": "76470301286950624198649364496103459585378536165660664290615779124087725034055", "price": "0.004", "size": "0", "side": "SELL", "hash": "a7cf006930c27c076632872affe74622f07129d4", "best_bid": "0", "best_ask": "0.001"}, {"asset_id": "77725644515863814306743026513820299582079276775056525666400499082315809995002", "price": "0.996", "size": "0", "side": "BUY", "hash": "c8fc0dc64201f991ba121daa90045c32aed1dba8", "best_bid": "0.999", "best_ask": "1"}], "timestamp": "1769384497175", "event_type": "price_change"}}
{"_local_timestamp": "2026-01-25T23:41:37.556696+00:00", "data": {"market": "0xaaf07b81d091318fc50eea80f8c9848a45c901dbdd49a3291b3c4ec32669f4f6", "price_changes": [{"asset_id": "76470301286950624198649364496103459585378536165660664290615779124087725034055", "price": "0.008", "size": "97.98", "side": "SELL", "hash": "952d9dc990d7d2f2b6f4e6138e2c645ef626795a", "best_bid": "0", "best_ask": "0.001"}, {"asset_id": "77725644515863814306743026513820299582079276775056525666400499082315809995002", "price": "0.992", "size": "97.98", "side": "BUY", "hash": "ab2c3a7e7e0af4796591f486d56ba03b53716e37", "best_bid": "0.999", "best_ask": "1"}], "timestamp": "1769384497419", "event_type": "price_change"}}
{"_local_timestamp": "2026-01-25T23:41:37.742144+00:00", "data": {"market": "0x43d906123758b44e9b41f460d8619e290954186d3fe3a0544319216c30d2be24", "price_changes": [{"asset_id": "8986753851227051304286293461908502563978603715241747497243698980934689505938", "price": "0.008", "size": "44.82", "side": "SELL", "hash": "3015c58a48002adbcb4582bd06670edeba23f3a0", "best_bid": "0.002", "best_ask": "0.007"}, {"asset_id": "15126910918760844641806927476005282998778904719663987971332027436874715278711", "price": "0.992", "size": "44.82", "side": "BUY", "hash": "d4104adc89c6e117536c68f4ce2464b9c8f19a12", "best_bid": "0.993", "best_ask": "0.998"}], "timestamp": "1769384497605", "event_type": "price_change"}}
{"_local_timestamp": "2026-01-25T23:41:37.742652+00:00", "data": {"market": "0x60d31be668659012a5f83ee259c9b4eee3053c71dd68abe4d277f54722cd017f", "price_changes": [{"asset_id": "42488602124923334991804541582064494050024109479561101679507993012554771196517", "price": "0.008", "size": "44.83", "side": "SELL", "hash": "f25638ace7bc2943efa651cfdabccf3900c1216d", "best_bid": "0.002", "best_ask": "0.007"}, {"asset_id": "102579243304231960045442519614514577865920600108882084366671276216059100139841", "price": "0.992", "size": "44.83", "side": "BUY", "hash": "debdc375b545ddcf068d0766ebd2dd9df8a2cef0", "best_bid": "0.993", "best_ask": "0.998"}], "timestamp": "1769384497605", "event_type": "price_change"}}
{"_local_timestamp": "2026-01-25T23:41:38.053275+00:00", "data": {"market": "0x60d31be668659012a5f83ee259c9b4eee3053c71dd68abe4d277f54722cd017f", "price_changes": [{"asset_id": "42488602124923334991804541582064494050024109479561101679507993012554771196517", "price": "0.006", "size": "8.22", "side": "SELL", "hash": "282b31f208fdd7b0dc9fe6657876e268a1bc4f32", "best_bid": "0.002", "best_ask": "0.006"}, {"asset_id": "102579243304231960045442519614514577865920600108882084366671276216059100139841", "price": "0.994", "size": "8.22", "side": "BUY", "hash": "f932894a9c1ff4bb6bb9e160aa078a01e171b160", "best_bid": "0.994", "best_ask": "0.998"}], "timestamp": "1769384497916", "event_type": "price_change"}}
{"_local_timestamp": "2026-01-25T23:41:38.053737+00:00", "data": {"market": "0x43d906123758b44e9b41f460d8619e290954186d3fe3a0544319216c30d2be24", "price_changes": [{"asset_id": "8986753851227051304286293461908502563978603715241747497243698980934689505938", "price": "0.006", "size": "8.21", "side": "SELL", "hash": "de49c76a61389ecebae91042132d2ef63abaf4c5", "best_bid": "0.002", "best_ask": "0.006"}, {"asset_id": "15126910918760844641806927476005282998778904719663987971332027436874715278711", "price": "0.994", "size": "8.21", "side": "BUY", "hash": "c5f034c8b903c7efe58825debef74bddec554f1a", "best_bid": "0.994", "best_ask": "0.998"}], "timestamp": "1769384497916", "event_type": "price_change"}}
{"_local_timestamp": "2026-01-25T23:41:38.247479+00:00", "data": {"market": "0x4341cc0ee3f6c33d5d14114804adbc56745ba69849a62ce33ba01f0f5fcb992d", "price_changes": [{"asset_id": "103859159453183957891244689604385927345314190615024118584206363782908647975749", "price": "0.059", "size": "0", "side": "SELL", "hash": "290d06d7ccaa5e26f6fbb55158c3c010a80b1c41", "best_bid": "0", "best_ask": "0.001"}, {"asset_id": "87105071850972641214581759809593758129422200795386115503863798159438712941487", "price": "0.941", "size": "0", "side": "BUY", "hash": "12d3afa8eaf7a578840b762ab095370a9438dba4", "best_bid": "0.999", "best_ask": "1"}], "timestamp": "1769384498023", "event_type": "price_change"}}
{"_local_timestamp": "2026-01-25T23:41:38.247889+00:00", "data": {"market": "0x66e8b5b9ab91a1cddf5dfc49f0a2ec1498924e109e93d10483f0d79306be313f", "price_changes": [{"asset_id": "71091790036166637976632521335546321470982289495437175848831608936100180919258", "price": "0.202", "size": "0", "side": "BUY", "hash": "59ce37af9293ae10acaa8d33c9345519735b40eb", "best_bid": "0.999", "best_ask": "1"}, {"asset_id": "684453561338864560956997457099047232393906048398755908200467037856574658987", "price": "0.798", "size": "0", "side": "SELL", "hash": "8c4b7c63a224a1b4c751830ecaf715a3ab768ec4", "best_bid": "0", "best_ask": "0.001"}], "timestamp": "1769384498030", "event_type": "price_change"}}
{"_local_timestamp": "2026-01-25T23:41:38.276112+00:00", "data": {"market": "0x60d31be668659012a5f83ee259c9b4eee3053c71dd68abe4d277f54722cd017f", "price_changes": [{"asset_id": "42488602124923334991804541582064494050024109479561101679507993012554771196517", "price": "0.002", "size": "0", "side": "BUY", "hash": "f6d1e5049d2a698bf15dac867fdb8fbf194ff5a5", "best_bid": "0.001", "best_ask": "0.006"}, {"asset_id": "102579243304231960045442519614514577865920600108882084366671276216059100139841", "price": "0.998", "size": "0", "side": "SELL", "hash": "e40a7f763c3e24e06d83165efbeb8e353cf4f503", "best_bid": "0.994", "best_ask": "0.999"}], "timestamp": "1769384498145", "event_type": "price_change"}}
{"_local_timestamp": "2026-01-25T23:41:38.276517+00:00", "data": {"market": "0x43d906123758b44e9b41f460d8619e290954186d3fe3a0544319216c30d2be24", "price_changes": [{"asset_id": "8986753851227051304286293461908502563978603715241747497243698980934689505938", "price": "0.002", "size": "0", "side": "BUY", "hash": "62950ce2f35d80aa66c3026cec0fb13972dbf892", "best_bid": "0.001", "best_ask": "0.006"}, {"asset_id": "15126910918760844641806927476005282998778904719663987971332027436874715278711", "price": "0.998", "size": "0", "side": "SELL", "hash": "c8be32fc0195b5960588d3fb0d969eed7d8eb443", "best_bid": "0.994", "best_ask": "0.999"}], "timestamp": "1769384498145", "event_type": "price_change"}}
{"_local_timestamp": "2026-01-25T23:41:38.299707+00:00", "data": {"market": "0x05f99811bde90f48244ad16f03170506b2e949b38b504cc8a44c6e48ebe1702e", "price_changes": [{"asset_id": "36488786194543599561987515498496523553655318415436626702612953440782293472547", "price": "0.002", "size": "5", "side": "BUY", "hash": "5d26b2bff5b19df168b3740935f0970947a49582", "best_bid": "0.002", "best_ask": "0.008"}, {"asset_id": "104672182191593174875004906973935726924864992137789800398429529123634830971717", "price": "0.998", "size": "5", "side": "SELL", "hash": "0b265b2efba7f80157a8425b482e240195c969f6", "best_bid": "0.992", "best_ask": "0.998"}], "timestamp": "1769384498176", "event_type": "price_change"}}
{"_local_timestamp": "2026-01-25T23:41:38.451933+00:00", "data": {"market": "0x4341cc0ee3f6c33d5d14114804adbc56745ba69849a62ce33ba01f0f5fcb992d", "price_changes": [{"asset_id": "103859159453183957891244689604385927345314190615024118584206363782908647975749", "price": "0.057", "size": "8.21", "side": "SELL", "hash": "c41d845ae0efafc59f047650e27b1edc32305415", "best_bid": "0", "best_ask": "0.001"}, {"asset_id": "87105071850972641214581759809593758129422200795386115503863798159438712941487", "price": "0.943", "size": "8.21", "side": "BUY", "hash": "58a494b7939a8a96608e3f8448750fa787862d4d", "best_bid": "0.999", "best_ask": "1"}], "timestamp": "1769384498318", "event_type": "price_change"}}
{"_local_timestamp": "2026-01-25T23:41:38.457250+00:00", "data": {"market": "0x66e8b5b9ab91a1cddf5dfc49f0a2ec1498924e109e93d10483f0d79306be313f", "price_changes": [{"asset_id": "71091790036166637976632521335546321470982289495437175848831608936100180919258", "price": "0.2", "size": "200", "side": "BUY", "hash": "ddc4bbbdef962a9d751e2acee421a449964ca040", "best_bid": "0.999", "best_ask": "1"}, {"asset_id": "684453561338864560956997457099047232393906048398755908200467037856574658987", "price": "0.8", "size": "200", "side": "SELL", "hash": "85e4dabcd6195de167fdcc509aa2d457ac80685e", "best_bid": "0", "best_ask": "0.001"}], "timestamp": "1769384498331", "event_type": "price_change"}}
{"_local_timestamp": "2026-01-25T23:41:38.835455+00:00", "data": {"market": "0x60d31be668659012a5f83ee259c9b4eee3053c71dd68abe4d277f54722cd017f", "price_changes": [{"asset_id": "42488602124923334991804541582064494050024109479561101679507993012554771196517", "price": "0.007", "size": "0", "side": "SELL", "hash": "83cc1e9035ccca4a34a1ff639e2644e81b6cd942", "best_bid": "0.001", "best_ask": "0.006"}, {"asset_id": "102579243304231960045442519614514577865920600108882084366671276216059100139841", "price": "0.993", "size": "0", "side": "BUY", "hash": "ed3c0193f3d216c45b2ef527e29e7219fac89317", "best_bid": "0.994", "best_ask": "0.999"}], "timestamp": "1769384498684", "event_type": "price_change"}}
{"_local_timestamp": "2026-01-25T23:41:38.836121+00:00", "data": {"market": "0xaaf07b81d091318fc50eea80f8c9848a45c901dbdd49a3291b3c4ec32669f4f6", "price_changes": [{"asset_id": "76470301286950624198649364496103459585378536165660664290615779124087725034055", "price": "0.003", "size": "0", "side": "SELL", "hash": "7b74d3e9c3781ca0994a01ba1412a4142df4141b", "best_bid": "0", "best_ask": "0.001"}, {"asset_id": "77725644515863814306743026513820299582079276775056525666400499082315809995002", "price": "0.997", "size": "0", "side": "BUY", "hash": "457136a51a7c70018d0e88606f1d93066b317b5e", "best_bid": "0.999", "best_ask": "1"}], "timestamp": "1769384498685", "event_type": "price_change"}}
{"_local_timestamp": "2026-01-25T23:41:38.836396+00:00", "data": {"market": "0x43d906123758b44e9b41f460d8619e290954186d3fe3a0544319216c30d2be24", "price_changes": [{"asset_id": "8986753851227051304286293461908502563978603715241747497243698980934689505938", "price": "0.007", "size": "0", "side": "SELL", "hash": "bd79fdad489168d09f865fb96d0046cb4f4ce0df", "best_bid": "0.001", "best_ask": "0.006"}, {"asset_id": "15126910918760844641806927476005282998778904719663987971332027436874715278711", "price": "0.993", "size": "0", "side": "BUY", "hash": "6c00b990ab39b97d52c41e6c6894fc8cec9a7af0", "best_bid": "0.994", "best_ask": "0.999"}], "timestamp": "1769384498685", "event_type": "price_change"}}
{"_local_timestamp": "2026-01-25T23:41:38.836631+00:00", "data": {"market": "0x4341cc0ee3f6c33d5d14114804adbc56745ba69849a62ce33ba01f0f5fcb992d", "price_changes": [{"asset_id": "103859159453183957891244689604385927345314190615024118584206363782908647975749", "price": "0.058", "size": "0", "side": "SELL", "hash": "827d1014d5034a5c0c4b1ed80d006b9cebaa9fa4", "best_bid": "0", "best_ask": "0.001"}, {"asset_id": "87105071850972641214581759809593758129422200795386115503863798159438712941487", "price": "0.942", "size": "0", "side": "BUY", "hash": "fdb5621a49d4036aab2a98e5b5d15063762e9ca1", "best_bid": "0.999", "best_ask": "1"}], "timestamp": "1769384498684", "event_type": "price_change"}}
{"_local_timestamp": "2026-01-25T23:41:38.910367+00:00", "data": {"market": "0xaaf07b81d091318fc50eea80f8c9848a45c901dbdd49a3291b3c4ec32669f4f6", "price_changes": [{"asset_id": "76470301286950624198649364496103459585378536165660664290615779124087725034055", "price": "0.007", "size": "10.47", "side": "SELL", "hash": "08b62ebe88c58514c7f51d3e248fe83e4decd0b0", "best_bid": "0", "best_ask": "0.001"}, {"asset_id": "77725644515863814306743026513820299582079276775056525666400499082315809995002", "price": "0.993", "size": "10.47", "side": "BUY", "hash": "5f3c37694b62380fc9ae13c4cc6e94ed1567b276", "best_bid": "0.999", "best_ask": "1"}], "timestamp": "1769384498748", "event_type": "price_change"}}
{"_local_timestamp": "2026-01-25T23:41:38.911126+00:00", "data": {"market": "0x4341cc0ee3f6c33d5d14114804adbc56745ba69849a62ce33ba01f0f5fcb992d", "price_changes": [{"asset_id": "103859159453183957891244689604385927345314190615024118584206363782908647975749", "price": "0.056", "size": "5.47", "side": "SELL", "hash": "702f77203dd9c7d7c6758fbfcb322f97641cbaa3", "best_bid": "0", "best_ask": "0.001"}, {"asset_id": "87105071850972641214581759809593758129422200795386115503863798159438712941487", "price": "0.944", "size": "5.47", "side": "BUY", "hash": "716c6401a3ed68a5c2c491b4b3255a2d3f280433", "best_bid": "0.999", "best_ask": "1"}], "timestamp": "1769384498748", "event_type": "price_change"}}
{"_local_timestamp": "2026-01-25T23:41:38.967228+00:00", "data": {"market": "0x60d31be668659012a5f83ee259c9b4eee3053c71dd68abe4d277f54722cd017f", "price_changes": [{"asset_id": "42488602124923334991804541582064494050024109479561101679507993012554771196517", "price": "0.005", "size": "5.47", "side": "SELL", "hash": "9660ecf27aee17d262976df5136e43b03b482d4c", "best_bid": "0.001", "best_ask": "0.005"}, {"asset_id": "102579243304231960045442519614514577865920600108882084366671276216059100139841", "price": "0.995", "size": "5.47", "side": "BUY", "hash": "9fd58a0cc7c454cdf64de5a69587590e7495f19b", "best_bid": "0.995", "best_ask": "0.999"}], "timestamp": "1769384498791", "event_type": "price_change"}}
{"_local_timestamp": "2026-01-25T23:41:38.986099+00:00", "data": {"market": "0x43d906123758b44e9b41f460d8619e290954186d3fe3a0544319216c30d2be24", "price_changes": [{"asset_id": "8986753851227051304286293461908502563978603715241747497243698980934689505938", "price": "0.005", "size": "5.47", "side": "SELL", "hash": "6650c55adec19b3449a0b674dd1c16a9907478e0", "best_bid": "0.001", "best_ask": "0.005"}, {"asset_id": "15126910918760844641806927476005282998778904719663987971332027436874715278711", "price": "0.995", "size": "5.47", "side": "BUY", "hash": "e4e4902ea458812974b19b8b15d8901b3fc083f3", "best_bid": "0.995", "best_ask": "0.999"}], "timestamp": "1769384498823", "event_type": "price_change"}}
{"_local_timestamp": "2026-01-25T23:41:39.311740+00:00", "data": {"market": "0x60d31be668659012a5f83ee259c9b4eee3053c71dd68abe4d277f54722cd017f", "price_changes": [{"asset_id": "42488602124923334991804541582064494050024109479561101679507993012554771196517", "price": "0.006", "size": "0", "side": "SELL", "hash": "9cc41259628f263c87678778e022461b791fc08a", "best_bid": "0.001", "best_ask": "0.005"}, {"asset_id": "102579243304231960045442519614514577865920600108882084366671276216059100139841", "price": "0.994", "size": "0", "side": "BUY", "hash": "7702e29f200028ae0c8ef453d43e640485035b4c", "best_bid": "0.995", "best_ask": "0.999"}], "timestamp": "1769384499170", "event_type": "price_change"}}
{"_local_timestamp": "2026-01-25T23:41:39.312211+00:00", "data": {"market": "0x43d906123758b44e9b41f460d8619e290954186d3fe3a0544319216c30d2be24", "price_changes": [{"asset_id": "8986753851227051304286293461908502563978603715241747497243698980934689505938", "price": "0.006", "size": "0", "side": "SELL", "hash": "496f2e8870854251640d52b888be468ecaaab7a1", "best_bid": "0.001", "best_ask": "0.005"}, {"asset_id": "15126910918760844641806927476005282998778904719663987971332027436874715278711", "price": "0.994", "size": "0", "side": "BUY", "hash": "613c1e0de0a7abe25ccae41dc4edd4b10e539300", "best_bid": "0.995", "best_ask": "0.999"}], "timestamp": "1769384499170", "event_type": "price_change"}}
{"_local_timestamp": "2026-01-25T23:41:39.314701+00:00", "data": {"market": "0xaaf07b81d091318fc50eea80f8c9848a45c901dbdd49a3291b3c4ec32669f4f6", "price_changes": [{"asset_id": "76470301286950624198649364496103459585378536165660664290615779124087725034055", "price": "0.008", "size": "92.01", "side": "SELL", "hash": "843f9b05a1e4004b4c4b13c971033ec5079b099c", "best_bid": "0", "best_ask": "0.001"}, {"asset_id": "77725644515863814306743026513820299582079276775056525666400499082315809995002", "price": "0.992", "size": "92.01", "side": "BUY", "hash": "c92c84ae691797e2176b9ddfbb02f7fcfaec726e", "best_bid": "0.999", "best_ask": "1"}], "timestamp": "1769384499170", "event_type": "price_change"}}
{"_local_timestamp": "2026-01-25T23:41:39.315062+00:00", "data": {"market": "0x4341cc0ee3f6c33d5d14114804adbc56745ba69849a62ce33ba01f0f5fcb992d", "price_changes": [{"asset_id": "103859159453183957891244689604385927345314190615024118584206363782908647975749", "price": "0.057", "size": "0", "side": "SELL", "hash": "5d30d25086e82e698390404431e547dd2446b2e3", "best_bid": "0", "best_ask": "0.001"}, {"asset_id": "87105071850972641214581759809593758129422200795386115503863798159438712941487", "price": "0.943", "size": "0", "side": "BUY", "hash": "de0f9c9d9c63d88c2d4eadda400564d346a21ba6", "best_bid": "0.999", "best_ask": "1"}], "timestamp": "1769384499170", "event_type": "price_change"}}
{"_local_timestamp": "2026-01-25T23:41:39.572482+00:00", "data": {"market": "0x43d906123758b44e9b41f460d8619e290954186d3fe3a0544319216c30d2be24", "price_changes": [{"asset_id": "8986753851227051304286293461908502563978603715241747497243698980934689505938", "price": "0.008", "size": "53.03", "side": "SELL", "hash": "74e53b7f5b35b989f32e0175de399be35be716d3", "best_bid": "0.001", "best_ask": "0.005"}, {"asset_id": "15126910918760844641806927476005282998778904719663987971332027436874715278711", "price": "0.992", "size": "53.03", "side": "BUY", "hash": "f4fef2ea2e01e9fad003c80d1b6a2eaad702f5d5", "best_bid": "0.995", "best_ask": "0.999"}], "timestamp": "1769384499434", "event_type": "price_change"}}
{"_local_timestamp": "2026-01-25T23:41:39.572869+00:00", "data": {"market": "0x60d31be668659012a5f83ee259c9b4eee3053c71dd68abe4d277f54722cd017f", "price_changes": [{"asset_id": "42488602124923334991804541582064494050024109479561101679507993012554771196517", "price": "0.008", "size": "53.05", "side": "SELL", "hash": "e8a3bebf9212e5ccf5e729608cc5c66f05589e26", "best_bid": "0.001", "best_ask": "0.005"}, {"asset_id": "102579243304231960045442519614514577865920600108882084366671276216059100139841", "price": "0.992", "size": "53.05", "side": "BUY", "hash": "e7553041185ec9e175fd1f613f8f22fef487003e", "best_bid": "0.995", "best_ask": "0.999"}], "timestamp": "1769384499434", "event_type": "price_change"}}
{"_local_timestamp": "2026-01-25T23:41:39.573115+00:00", "data": {"market": "0xaaf07b81d091318fc50eea80f8c9848a45c901dbdd49a3291b3c4ec32669f4f6", "price_changes": [{"asset_id": "76470301286950624198649364496103459585378536165660664290615779124087725034055", "price": "0.006", "size": "5.97", "side": "SELL", "hash": "7fd368913a201daef979d4363f9aa30c2c55625f", "best_bid": "0", "best_ask": "0.001"}, {"asset_id": "77725644515863814306743026513820299582079276775056525666400499082315809995002", "price": "0.994", "size": "5.97", "side": "BUY", "hash": "bfc0a730282c57c723d48c2401a4e30c32c0964e", "best_bid": "0.999", "best_ask": "1"}], "timestamp": "1769384499434", "event_type": "price_change"}}
{"_local_timestamp": "2026-01-25T23:41:39.573402+00:00", "data": {"market": "0x4341cc0ee3f6c33d5d14114804adbc56745ba69849a62ce33ba01f0f5fcb992d", "price_changes": [{"asset_id": "103859159453183957891244689604385927345314190615024118584206363782908647975749", "price": "0.055", "size": "8.21", "side": "SELL", "hash": "ffd446aa95ba8714e202d90a4f546ca546d3c472", "best_bid": "0", "best_ask": "0.001"}, {"asset_id": "87105071850972641214581759809593758129422200795386115503863798159438712941487", "price": "0.945", "size": "8.21", "side": "BUY", "hash": "8892cba180ec36df808b0d2f41cf843906eb8e65", "best_bid": "0.999", "best_ask": "1"}], "timestamp": "1769384499434", "event_type": "price_change"}}
{"_local_timestamp": "2026-01-25T23:41:40.008531+00:00", "data": {"market": "0xaaf07b81d091318fc50eea80f8c9848a45c901dbdd49a3291b3c4ec32669f4f6", "price_changes": [{"asset_id": "76470301286950624198649364496103459585378536165660664290615779124087725034055", "price": "0.008", "size": "86.15", "side": "SELL", "hash": "7fcf2c2132fa250c6a9b68ef5b2227abcefc2f5d", "best_bid": "0", "best_ask": "0.001"}, {"asset_id": "77725644515863814306743026513820299582079276775056525666400499082315809995002", "price": "0.992", "size": "86.15", "side": "BUY", "hash": "91a0fcd6b0e530b458b76985f9665654de653ad8", "best_bid": "0.999", "best_ask": "1"}], "timestamp": "1769384499887", "event_type": "price_change"}}
{"_local_timestamp": "2026-01-25T23:41:40.186967+00:00", "data": {"market": "0x43d906123758b44e9b41f460d8619e290954186d3fe3a0544319216c30d2be24", "price_changes": [{"asset_id": "8986753851227051304286293461908502563978603715241747497243698980934689505938", "price": "0.005", "size": "0", "side": "SELL", "hash": "59c877de10c67f453bde2ba2b9d0889942c78107", "best_bid": "0.001", "best_ask": "0.008"}, {"asset_id": "15126910918760844641806927476005282998778904719663987971332027436874715278711", "price": "0.995", "size": "0", "side": "BUY", "hash": "ed938543d529dbf32b4a0f9b31073d006d0b0418", "best_bid": "0.992", "best_ask": "0.999"}], "timestamp": "1769384500120", "event_type": "price_change"}}
{"_local_timestamp": "2026-01-25T23:41:40.187293+00:00", "data": {"market": "0x60d31be668659012a5f83ee259c9b4eee3053c71dd68abe4d277f54722cd017f", "price_changes": [{"asset_id": "42488602124923334991804541582064494050024109479561101679507993012554771196517", "price": "0.005", "size": "0", "side": "SELL", "hash": "42b1d4083114f22d91ac687bcf64c3e23c11ffcf", "best_bid": "0.001", "best_ask": "0.008"}, {"asset_id": "102579243304231960045442519614514577865920600108882084366671276216059100139841", "price": "0.995", "size": "0", "side": "BUY", "hash": "91786a86d84fa6bf4163d9617333793db5edf66f", "best_bid": "0.992", "best_ask": "0.999"}], "timestamp": "1769384500120", "event_type": "price_change"}}
{"_local_timestamp": "2026-01-25T23:41:40.197502+00:00", "data": {"market": "0x4341cc0ee3f6c33d5d14114804adbc56745ba69849a62ce33ba01f0f5fcb992d", "price_changes": [{"asset_id": "103859159453183957891244689604385927345314190615024118584206363782908647975749", "price": "0.056", "size": "0", "side": "SELL", "hash": "ef8a1e832f8e9eab026c11eec24800cb7aeff5b5", "best_bid": "0", "best_ask": "0.001"}, {"asset_id": "87105071850972641214581759809593758129422200795386115503863798159438712941487", "price": "0.944", "size": "0", "side": "BUY", "hash": "d9feea5667b6a2c30392315acc1b67e678aadcb8", "best_bid": "0.999", "best_ask": "1"}], "timestamp": "1769384500120", "event_type": "price_change"}}
{"_local_timestamp": "2026-01-25T23:41:40.197833+00:00", "data": {"market": "0xaaf07b81d091318fc50eea80f8c9848a45c901dbdd49a3291b3c4ec32669f4f6", "price_changes": [{"asset_id": "76470301286950624198649364496103459585378536165660664290615779124087725034055", "price": "0.007", "size": "0", "side": "SELL", "hash": "547ce25b1709599ceabc1a8fbbf063f8b5dba9c8", "best_bid": "0", "best_ask": "0.001"}, {"asset_id": "77725644515863814306743026513820299582079276775056525666400499082315809995002", "price": "0.993", "size": "0", "side": "BUY", "hash": "b7f5236a9e91f4a026718f00262ca1a82727c902", "best_bid": "0.999", "best_ask": "1"}], "timestamp": "1769384500121", "event_type": "price_change"}}
{"_local_timestamp": "2026-01-25T23:41:40.273728+00:00", "data": {"market": "0xaaf07b81d091318fc50eea80f8c9848a45c901dbdd49a3291b3c4ec32669f4f6", "price_changes": [{"asset_id": "76470301286950624198649364496103459585378536165660664290615779124087725034055", "price": "0.006", "size": "11.83", "side": "SELL", "hash": "a1645e389e1db7bdc10750cb09c143a48490bc77", "best_bid": "0", "best_ask": "0.001"}, {"asset_id": "77725644515863814306743026513820299582079276775056525666400499082315809995002", "price": "0.994", "size": "11.83", "side": "BUY", "hash": "71620be57d7b3365db310350906184733c2088fe", "best_bid": "0.999", "best_ask": "1"}], "timestamp": "1769384500183", "event_type": "price_change"}}
{"_local_timestamp": "2026-01-25T23:41:40.282070+00:00", "data": {"market": "0xaaf07b81d091318fc50eea80f8c9848a45c901dbdd49a3291b3c4ec32669f4f6", "price_changes": [{"asset_id": "76470301286950624198649364496103459585378536165660664290615779124087725034055", "price": "0.005", "size": "10.47", "side": "SELL", "hash": "69bd47cc2c35ed93ef6c81459113bc94441d0635", "best_bid": "0", "best_ask": "0.001"}, {"asset_id": "77725644515863814306743026513820299582079276775056525666400499082315809995002", "price": "0.995", "size": "10.47", "side": "BUY", "hash": "058b517a6d845a99208635c53751445fa0dbc445", "best_bid": "0.999", "best_ask": "1"}], "timestamp": "1769384500187", "event_type": "price_change"}}
{"_local_timestamp": "2026-01-25T23:41:40.282411+00:00", "data": {"market": "0x4341cc0ee3f6c33d5d14114804adbc56745ba69849a62ce33ba01f0f5fcb992d", "price_changes": [{"asset_id": "103859159453183957891244689604385927345314190615024118584206363782908647975749", "price": "0.054", "size": "5.47", "side": "SELL", "hash": "7d82223d2876653f2c5ae3a9f8e7035c7f0dc076", "best_bid": "0", "best_ask": "0.001"}, {"asset_id": "87105071850972641214581759809593758129422200795386115503863798159438712941487", "price": "0.946", "size": "5.47", "side": "BUY", "hash": "95e556db4d6724ed753dba217381d66733e50fad", "best_bid": "0.999", "best_ask": "1"}], "timestamp": "1769384500187", "event_type": "price_change"}}
{"_local_timestamp": "2026-01-25T23:41:40.353761+00:00", "data": {"market": "0x60d31be668659012a5f83ee259c9b4eee3053c71dd68abe4d277f54722cd017f", "price_changes": [{"asset_id": "42488602124923334991804541582064494050024109479561101679507993012554771196517", "price": "0.007", "size": "5.47", "side": "SELL", "hash": "eda7b0b8eb7513c6da90406885b0f221ca05025c", "best_bid": "0.001", "best_ask": "0.007"}, {"asset_id": "102579243304231960045442519614514577865920600108882084366671276216059100139841", "price": "0.993", "size": "5.47", "side": "BUY", "hash": "a2c03e114170ad872d5181f4b3c5fd0e30a23e38", "best_bid": "0.993", "best_ask": "0.999"}], "timestamp": "1769384500230", "event_type": "price_change"}}
{"_local_timestamp": "2026-01-25T23:41:40.354186+00:00", "data": {"market": "0x43d906123758b44e9b41f460d8619e290954186d3fe3a0544319216c30d2be24", "price_changes": [{"asset_id": "8986753851227051304286293461908502563978603715241747497243698980934689505938", "price": "0.007", "size": "5.47", "side": "SELL", "hash": "459ae96eb78fe6db972a1a60ad840cae343cf5bd", "best_bid": "0.001", "best_ask": "0.007"}, {"asset_id": "15126910918760844641806927476005282998778904719663987971332027436874715278711", "price": "0.993", "size": "5.47", "side": "BUY", "hash": "8b7872881bf13d6d70837076d1261d23e7a25948", "best_bid": "0.993", "best_ask": "0.999"}], "timestamp": "1769384500230", "event_type": "price_change"}}
{"_local_timestamp": "2026-01-25T23:41:40.777593+00:00", "data": {"market": "0x60d31be668659012a5f83ee259c9b4eee3053c71dd68abe4d277f54722cd017f", "price_changes": [{"asset_id": "42488602124923334991804541582064494050024109479561101679507993012554771196517", "price": "0.008", "size": "44.83", "side": "SELL", "hash": "ae853cf64c59b07330dca3d7007abb180326691a", "best_bid": "0.001", "best_ask": "0.007"}, {"asset_id": "102579243304231960045442519614514577865920600108882084366671276216059100139841", "price": "0.992", "size": "44.83", "side": "BUY", "hash": "e73f4b6f941b308e3fcd51307ef9f7fb44ca06f0", "best_bid": "0.993", "best_ask": "0.999"}], "timestamp": "1769384500709", "event_type": "price_change"}}
{"_local_timestamp": "2026-01-25T23:41:40.777933+00:00", "data": {"market": "0xaaf07b81d091318fc50eea80f8c9848a45c901dbdd49a3291b3c4ec32669f4f6", "price_changes": [{"asset_id": "76470301286950624198649364496103459585378536165660664290615779124087725034055", "price": "0.006", "size": "5.86", "side": "SELL", "hash": "4fa4f4de52d5954b8711ff9dc50ff84afa63f638", "best_bid": "0", "best_ask": "0.001"}, {"asset_id": "77725644515863814306743026513820299582079276775056525666400499082315809995002", "price": "0.994", "size": "5.86", "side": "BUY", "hash": "009614b29149a73ddde171992571fd30d4123ee1", "best_bid": "0.999", "best_ask": "1"}], "timestamp": "1769384500709", "event_type": "price_change"}}
{"_local_timestamp": "2026-01-25T23:41:40.778184+00:00", "data": {"market": "0x4341cc0ee3f6c33d5d14114804adbc56745ba69849a62ce33ba01f0f5fcb992d", "price_changes": [{"asset_id": "103859159453183957891244689604385927345314190615024118584206363782908647975749", "price": "0.055", "size": "0", "side": "SELL", "hash": "e647e132c8f9024e79ef9a2e7b50f87df6067a45", "best_bid": "0", "best_ask": "0.001"}, {"asset_id": "87105071850972641214581759809593758129422200795386115503863798159438712941487", "price": "0.945", "size": "0", "side": "BUY", "hash": "269df0ae021da316db2f4e970d5d8485fef56c0b", "best_bid": "0.999", "best_ask": "1"}], "timestamp": "1769384500709", "event_type": "price_change"}}
{"_local_timestamp": "2026-01-25T23:41:41.034742+00:00", "data": {"market": "0x4341cc0ee3f6c33d5d14114804adbc56745ba69849a62ce33ba01f0f5fcb992d", "price_changes": [{"asset_id": "103859159453183957891244689604385927345314190615024118584206363782908647975749", "price": "0.053", "size": "8.21", "side": "SELL", "hash": "2f43b9ca13fec5e789e1d9e4329e7d67695bf11d", "best_bid": "0", "best_ask": "0.001"}, {"asset_id": "87105071850972641214581759809593758129422200795386115503863798159438712941487", "price": "0.947", "size": "8.21", "side": "BUY", "hash": "19b674964547a2d3dd85228d75becff4bf8b0359", "best_bid": "0.999", "best_ask": "1"}], "timestamp": "1769384500960", "event_type": "price_change"}}
{"_local_timestamp": "2026-01-25T23:41:41.042578+00:00", "data": {"market": "0xaaf07b81d091318fc50eea80f8c9848a45c901dbdd49a3291b3c4ec32669f4f6", "price_changes": [{"asset_id": "76470301286950624198649364496103459585378536165660664290615779124087725034055", "price": "0.004", "size": "5.97", "side": "SELL", "hash": "f5db5e9aa69148fb87887bc2dc3aa5659b00822b", "best_bid": "0", "best_ask": "0.001"}, {"asset_id": "77725644515863814306743026513820299582079276775056525666400499082315809995002", "price": "0.996", "size": "5.97", "side": "BUY", "hash": "9a54bcf68cac6dd78a4942384d4f44a2b1c38e94", "best_bid": "0.999", "best_ask": "1"}], "timestamp": "1769384500960", "event_type": "price_change"}}
{"_local_timestamp": "2026-01-25T23:41:41.043818+00:00", "data": {"market": "0x60d31be668659012a5f83ee259c9b4eee3053c71dd68abe4d277f54722cd017f", "price_changes": [{"asset_id": "42488602124923334991804541582064494050024109479561101679507993012554771196517", "price": "0.006", "size": "8.22", "side": "SELL", "hash": "856b52d788fe1271811733b19e2e801af44fbb4a", "best_bid": "0.001", "best_ask": "0.006"}, {"asset_id": "102579243304231960045442519614514577865920600108882084366671276216059100139841", "price": "0.994", "size": "8.22", "side": "BUY", "hash": "38751fae134535bb1a685cd910845dbf921e804f", "best_bid": "0.994", "best_ask": "0.999"}], "timestamp": "1769384500960", "event_type": "price_change"}}
{"_local_timestamp": "2026-01-25T23:41:41.207231+00:00", "data": {"market": "0x43d906123758b44e9b41f460d8619e290954186d3fe3a0544319216c30d2be24", "price_changes": [{"asset_id": "8986753851227051304286293461908502563978603715241747497243698980934689505938", "price": "0.008", "size": "44.82", "side": "SELL", "hash": "ffd348b8fe276a798bc470559e7b39a8a6e2bf0d", "best_bid": "0.001", "best_ask": "0.007"}, {"asset_id": "15126910918760844641806927476005282998778904719663987971332027436874715278711", "price": "0.992", "size": "44.82", "side": "BUY", "hash": "7c887cad5e6f1aa97896d98e36b2a22fd5b89383", "best_bid": "0.993", "best_ask": "0.999"}], "timestamp": "1769384501136", "event_type": "price_change"}}
{"_local_timestamp": "2026-01-25T23:41:41.470152+00:00", "data": {"market": "0x43d906123758b44e9b41f460d8619e290954186d3fe3a0544319216c30d2be24", "price_changes": [{"asset_id": "8986753851227051304286293461908502563978603715241747497243698980934689505938", "price": "0.006", "size": "8.21", "side": "SELL", "hash": "f6e0b2e966bf5f0e3066c2af82fbe1d16f37c2a7", "best_bid": "0.001", "best_ask": "0.006"}, {"asset_id": "15126910918760844641806927476005282998778904719663987971332027436874715278711", "price": "0.994", "size": "8.21", "side": "BUY", "hash": "e7f79b3b7110d468c8ff96af427b485f5aeaf75f", "best_bid": "0.994", "best_ask": "0.999"}], "timestamp": "1769384501398", "event_type": "price_change"}}
{"_local_timestamp": "2026-01-25T23:41:41.486545+00:00", "data": {"market": "0x05f99811bde90f48244ad16f03170506b2e949b38b504cc8a44c6e48ebe1702e", "price_changes": [{"asset_id": "36488786194543599561987515498496523553655318415436626702612953440782293472547", "price": "0.002", "size": "0", "side": "BUY", "hash": "fe6dc7ca0b221b8fe02ac1c6b6bbb7c5fedcfe74", "best_bid": "0.001", "best_ask": "0.008"}, {"asset_id": "104672182191593174875004906973935726924864992137789800398429529123634830971717", "price": "0.998", "size": "0", "side": "SELL", "hash": "bb8ff49fd2e33a318810e66a590a7b977c4855e2", "best_bid": "0.992", "best_ask": "0.999"}], "timestamp": "1769384501417", "event_type": "price_change"}}
{"_local_timestamp": "2026-01-25T23:41:41.642676+00:00", "data": {"market": "0xaaf07b81d091318fc50eea80f8c9848a45c901dbdd49a3291b3c4ec32669f4f6", "price_changes": [{"asset_id": "76470301286950624198649364496103459585378536165660664290615779124087725034055", "price": "0.006", "size": "0", "side": "SELL", "hash": "bb8de328b208af9a1d070d2742c6444aad30d723", "best_bid": "0", "best_ask": "0.001"}, {"asset_id": "77725644515863814306743026513820299582079276775056525666400499082315809995002", "price": "0.994", "size": "0", "side": "BUY", "hash": "57ca05a8bb21050e247755e9f3501ca6541d3a84", "best_bid": "0.999", "best_ask": "1"}], "timestamp": "1769384501564", "event_type": "price_change"}}
{"_local_timestamp": "2026-01-25T23:41:41.658583+00:00", "data": {"market": "0xaaf07b81d091318fc50eea80f8c9848a45c901dbdd49a3291b3c4ec32669f4f6", "price_changes": [{"asset_id": "76470301286950624198649364496103459585378536165660664290615779124087725034055", "price": "0.005", "size": "0", "side": "SELL", "hash": "07c36cb193b03fdcdcbe4b26162d17e08704b8d8", "best_bid": "0", "best_ask": "0.001"}, {"asset_id": "77725644515863814306743026513820299582079276775056525666400499082315809995002", "price": "0.995", "size": "0", "side": "BUY", "hash": "3dec451e3963971aaec9ae7b62d35f93e1fadf22", "best_bid": "0.999", "best_ask": "1"}], "timestamp": "1769384501590", "event_type": "price_change"}}
{"_local_timestamp": "2026-01-25T23:41:41.658966+00:00", "data": {"market": "0x60d31be668659012a5f83ee259c9b4eee3053c71dd68abe4d277f54722cd017f", "price_changes": [{"asset_id": "42488602124923334991804541582064494050024109479561101679507993012554771196517", "price": "0.007", "size": "0", "side": "SELL", "hash": "3d4572a4cc31e01bfd3e191efb716872ce1d66fb", "best_bid": "0.001", "best_ask": "0.006"}, {"asset_id": "102579243304231960045442519614514577865920600108882084366671276216059100139841", "price": "0.993", "size": "0", "side": "BUY", "hash": "8e2fef7065909bb4357895defde70acdbb018b92", "best_bid": "0.994", "best_ask": "0.999"}], "timestamp": "1769384501590", "event_type": "price_change"}}
{"_local_timestamp": "2026-01-25T23:41:41.662443+00:00", "data": {"market": "0x43d906123758b44e9b41f460d8619e290954186d3fe3a0544319216c30d2be24", "price_changes": [{"asset_id": "8986753851227051304286293461908502563978603715241747497243698980934689505938", "price": "0.007", "size": "0", "side": "SELL", "hash": "3db8bc2275ceeda5bf188f9b4dc33e7f4a2f6711", "best_bid": "0.001", "best_ask": "0.006"}, {"asset_id": "15126910918760844641806927476005282998778904719663987971332027436874715278711", "price": "0.993", "size": "0", "side": "BUY", "hash": "16261b2c96ac4fc4737a07c457b4175afcaa57c4", "best_bid": "0.994", "best_ask": "0.999"}], "timestamp": "1769384501590", "event_type": "price_change"}}
{"_local_timestamp": "2026-01-25T23:41:41.662829+00:00", "data": {"market": "0x4341cc0ee3f6c33d5d14114804adbc56745ba69849a62ce33ba01f0f5fcb992d", "price_changes": [{"asset_id": "103859159453183957891244689604385927345314190615024118584206363782908647975749", "price": "0.054", "size": "0", "side": "SELL", "hash": "90f46c123492c2fe4c1b6efa6471c8ad5312aab0", "best_bid": "0", "best_ask": "0.001"}, {"asset_id": "87105071850972641214581759809593758129422200795386115503863798159438712941487", "price": "0.946", "size": "0", "side": "BUY", "hash": "b6c5832aecb390104045160e925438c4c7e9bcf6", "best_bid": "0.999", "best_ask": "1"}], "timestamp": "1769384501591", "event_type": "price_change"}}
{"_local_timestamp": "2026-01-25T23:41:41.715495+00:00", "data": {"market": "0x4341cc0ee3f6c33d5d14114804adbc56745ba69849a62ce33ba01f0f5fcb992d", "price_changes": [{"asset_id": "103859159453183957891244689604385927345314190615024118584206363782908647975749", "price": "0.052", "size": "5.47", "side": "SELL", "hash": "6f84d3af3f6ea8eb3a623562f0308fa78c4ed86e", "best_bid": "0", "best_ask": "0.001"}, {"asset_id": "87105071850972641214581759809593758129422200795386115503863798159438712941487", "price": "0.948", "size": "5.47", "side": "BUY", "hash": "3b330a17e60835aae3ebaf3ddfa414d80bf831a8", "best_bid": "0.999", "best_ask": "1"}], "timestamp": "1769384501649", "event_type": "price_change"}}
{"_local_timestamp": "2026-01-25T23:41:41.729886+00:00", "data": {"market": "0xaaf07b81d091318fc50eea80f8c9848a45c901dbdd49a3291b3c4ec32669f4f6", "price_changes": [{"asset_id": "76470301286950624198649364496103459585378536165660664290615779124087725034055", "price": "0.003", "size": "10.47", "side": "SELL", "hash": "8a0437e11c6df5544750ff50152ccf3940fa8f7d", "best_bid": "0", "best_ask": "0.001"}, {"asset_id": "77725644515863814306743026513820299582079276775056525666400499082315809995002", "price": "0.997", "size": "10.47", "side": "BUY", "hash": "c3b106a598c4e40b230cf597ea0238c461df09ce", "best_bid": "0.999", "best_ask": "1"}], "timestamp": "1769384501649", "event_type": "price_change"}}
{"_local_timestamp": "2026-01-25T23:41:41.785713+00:00", "data": {"market": "0x60d31be668659012a5f83ee259c9b4eee3053c71dd68abe4d277f54722cd017f", "price_changes": [{"asset_id": "42488602124923334991804541582064494050024109479561101679507993012554771196517", "price": "0.005", "size": "5.47", "side": "SELL", "hash": "8a67201d681bc60fd25fd040beb4281c13610512", "best_bid": "0.001", "best_ask": "0.005"}, {"asset_id": "102579243304231960045442519614514577865920600108882084366671276216059100139841", "price": "0.995", "size": "5.47", "side": "BUY", "hash": "f86f108997cfd75855a7481aaa0268b433cfa09f", "best_bid": "0.995", "best_ask": "0.999"}], "timestamp": "1769384501703", "event_type": "price_change"}}
{"_local_timestamp": "2026-01-25T23:41:41.786097+00:00", "data": {"market": "0x43d906123758b44e9b41f460d8619e290954186d3fe3a0544319216c30d2be24", "price_changes": [{"asset_id": "8986753851227051304286293461908502563978603715241747497243698980934689505938", "price": "0.005", "size": "5.47", "side": "SELL", "hash": "2519d46589526f0ea7225aeca3ee5de5392b7ebf", "best_bid": "0.001", "best_ask": "0.005"}, {"asset_id": "15126910918760844641806927476005282998778904719663987971332027436874715278711", "price": "0.995", "size": "5.47", "side": "BUY", "hash": "3bd69b2ed136e7452df524792ade3aeafc02ecb6", "best_bid": "0.995", "best_ask": "0.999"}], "timestamp": "1769384501703", "event_type": "price_change"}}
{"_local_timestamp": "2026-01-25T23:41:41.913995+00:00", "data": {"market": "0xaaf07b81d091318fc50eea80f8c9848a45c901dbdd49a3291b3c4ec32669f4f6", "price_changes": [{"asset_id": "76470301286950624198649364496103459585378536165660664290615779124087725034055", "price": "0.004", "size": "11.83", "side": "SELL", "hash": "2544af456c9a1251e9a6f4b520aca76f5091b767", "best_bid": "0", "best_ask": "0.001"}, {"asset_id": "77725644515863814306743026513820299582079276775056525666400499082315809995002", "price": "0.996", "size": "11.83", "side": "BUY", "hash": "9b4751b8cb6dd248bcc927f5a8cf7c0d64d11bc7", "best_bid": "0.999", "best_ask": "1"}], "timestamp": "1769384501843", "event_type": "price_change"}}
{"_local_timestamp": "2026-01-25T23:41:42.045457+00:00", "data": {"market": "0x60d31be668659012a5f83ee259c9b4eee3053c71dd68abe4d277f54722cd017f", "price_changes": [{"asset_id": "42488602124923334991804541582064494050024109479561101679507993012554771196517", "price": "0.006", "size": "0", "side": "SELL", "hash": "8ef9a52dc23645fc20041fb44de4e0d28eca459f", "best_bid": "0.001", "best_ask": "0.005"}, {"asset_id": "102579243304231960045442519614514577865920600108882084366671276216059100139841", "price": "0.994", "size": "0", "side": "BUY", "hash": "85a33b0d35e25dcd4b09cf3cbc6162b2e03e95a2", "best_bid": "0.995", "best_ask": "0.999"}], "timestamp": "1769384501975", "event_type": "price_change"}}
{"_local_timestamp": "2026-01-25T23:41:42.045916+00:00", "data": {"market": "0x43d906123758b44e9b41f460d8619e290954186d3fe3a0544319216c30d2be24", "price_changes": [{"asset_id": "8986753851227051304286293461908502563978603715241747497243698980934689505938", "price": "0.006", "size": "0", "side": "SELL", "hash": "b71ffa58308d0d35865eff1fea57dc2b40e1c254", "best_bid": "0.001", "best_ask": "0.005"}, {"asset_id": "15126910918760844641806927476005282998778904719663987971332027436874715278711", "price": "0.994", "size": "0", "side": "BUY", "hash": "fc7f1765a6209312312adb855cfe08052373fba4", "best_bid": "0.995", "best_ask": "0.999"}], "timestamp": "1769384501975", "event_type": "price_change"}}
{"_local_timestamp": "2026-01-25T23:41:42.046277+00:00", "data": {"market": "0x4341cc0ee3f6c33d5d14114804adbc56745ba69849a62ce33ba01f0f5fcb992d", "price_changes": [{"asset_id": "103859159453183957891244689604385927345314190615024118584206363782908647975749", "price": "0.053", "size": "0", "side": "SELL", "hash": "4c0a051f9499fbb1137d27ce8349b28f3bcaec0a", "best_bid": "0", "best_ask": "0.001"}, {"asset_id": "87105071850972641214581759809593758129422200795386115503863798159438712941487", "price": "0.947", "size": "0", "side": "BUY", "hash": "d7d6ba591fd47fbafff635a1305a801f279afe7c", "best_bid": "0.999", "best_ask": "1"}], "timestamp": "1769384501975", "event_type": "price_change"}}
{"_local_timestamp": "2026-01-25T23:41:42.407939+00:00", "data": {"market": "0x43d906123758b44e9b41f460d8619e290954186d3fe3a0544319216c30d2be24", "price_changes": [{"asset_id": "8986753851227051304286293461908502563978603715241747497243698980934689505938", "price": "0.008", "size": "53.03", "side": "SELL", "hash": "709301a6d6923ab193dda32b872f546d036fbb2e", "best_bid": "0.001", "best_ask": "0.005"}, {"asset_id": "15126910918760844641806927476005282998778904719663987971332027436874715278711", "price": "0.992", "size": "53.03", "side": "BUY", "hash": "717b0975d76d8872d31d87e66fcc9ed1d14a4c39", "best_bid": "0.995", "best_ask": "0.999"}], "timestamp": "1769384502335", "event_type": "price_change"}}
{"_local_timestamp": "2026-01-25T23:41:42.408353+00:00", "data": {"market": "0x4341cc0ee3f6c33d5d14114804adbc56745ba69849a62ce33ba01f0f5fcb992d", "price_changes": [{"asset_id": "103859159453183957891244689604385927345314190615024118584206363782908647975749", "price": "0.051", "size": "8.21", "side": "SELL", "hash": "10fb884c125938fbb5ec5db31a1942a19c5d1604", "best_bid": "0", "best_ask": "0.001"}, {"asset_id": "87105071850972641214581759809593758129422200795386115503863798159438712941487", "price": "0.949", "size": "8.21", "side": "BUY", "hash": "fdd6e40625488e673d8c025f2274d2f9349d4698", "best_bid": "0.999", "best_ask": "1"}], "timestamp": "1769384502335", "event_type": "price_change"}}
{"_local_timestamp": "2026-01-25T23:41:42.408600+00:00", "data": {"market": "0x60d31be668659012a5f83ee259c9b4eee3053c71dd68abe4d277f54722cd017f", "price_changes": [{"asset_id": "42488602124923334991804541582064494050024109479561101679507993012554771196517", "price": "0.008", "size": "53.05", "side": "SELL", "hash": "292ac4fac02606502641f57ceba861df6f24b213", "best_bid": "0.001", "best_ask": "0.005"}, {"asset_id": "102579243304231960045442519614514577865920600108882084366671276216059100139841", "price": "0.992", "size": "53.05", "side": "BUY", "hash": "93f514604a1b0dc61c26588c30d22613ef5e94c3", "best_bid": "0.995", "best_ask": "0.999"}], "timestamp": "1769384502335", "event_type": "price_change"}}
{"_local_timestamp": "2026-01-25T23:41:42.878084+00:00", "data": {"market": "0xaaf07b81d091318fc50eea80f8c9848a45c901dbdd49a3291b3c4ec32669f4f6", "price_changes": [{"asset_id": "76470301286950624198649364496103459585378536165660664290615779124087725034055", "price": "0.004", "size": "5.86", "side": "SELL", "hash": "a8aa12faafa3c9c786f72db8fefa643633fdb3be", "best_bid": "0", "best_ask": "0.001"}, {"asset_id": "77725644515863814306743026513820299582079276775056525666400499082315809995002", "price": "0.996", "size": "5.86", "side": "BUY", "hash": "ef801780d032af933d4c495a11de75fa52373633", "best_bid": "0.999", "best_ask": "1"}], "timestamp": "1769384502811", "event_type": "price_change"}}
{"_local_timestamp": "2026-01-25T23:41:43.039708+00:00", "data": {"market": "0x4341cc0ee3f6c33d5d14114804adbc56745ba69849a62ce33ba01f0f5fcb992d", "price_changes": [{"asset_id": "103859159453183957891244689604385927345314190615024118584206363782908647975749", "price": "0.052", "size": "0", "side": "SELL", "hash": "0f03f175e74304ba1b067a7fe98546d088c42910", "best_bid": "0", "best_ask": "0.001"}, {"asset_id": "87105071850972641214581759809593758129422200795386115503863798159438712941487", "price": "0.948", "size": "0", "side": "BUY", "hash": "c00b97b5e916b460fafac316cc9481d7df805d58", "best_bid": "0.999", "best_ask": "1"}], "timestamp": "1769384502969", "event_type": "price_change"}}
{"_local_timestamp": "2026-01-25T23:41:43.040034+00:00", "data": {"market": "0x43d906123758b44e9b41f460d8619e290954186d3fe3a0544319216c30d2be24", "price_changes": [{"asset_id": "8986753851227051304286293461908502563978603715241747497243698980934689505938", "price": "0.005", "size": "0", "side": "SELL", "hash": "8212556c0ecfd64c7a3f7ef26ae94e407183cc08", "best_bid": "0.001", "best_ask": "0.008"}, {"asset_id": "15126910918760844641806927476005282998778904719663987971332027436874715278711", "price": "0.995", "size": "0", "side": "BUY", "hash": "6043a12ecfccfb724f2ebb971a162df53c46165b", "best_bid": "0.992", "best_ask": "0.999"}], "timestamp": "1769384502969", "event_type": "price_change"}}
{"_local_timestamp": "2026-01-25T23:41:43.040273+00:00", "data": {"market": "0x60d31be668659012a5f83ee259c9b4eee3053c71dd68abe4d277f54722cd017f", "price_changes": [{"asset_id": "42488602124923334991804541582064494050024109479561101679507993012554771196517", "price": "0.005", "size": "0", "side": "SELL", "hash": "1f665a178a22992626fc27c81e6b1708ca000c0a", "best_bid": "0.001", "best_ask": "0.008"}, {"asset_id": "102579243304231960045442519614514577865920600108882084366671276216059100139841", "price": "0.995", "size": "0", "side": "BUY", "hash": "d2778f88060bc4c6c7912dd4ef9985ca18c32e20", "best_bid": "0.992", "best_ask": "0.999"}], "timestamp": "1769384502969", "event_type": "price_change"}}
{"_local_timestamp": "2026-01-25T23:41:43.126547+00:00", "data": {"market": "0x4341cc0ee3f6c33d5d14114804adbc56745ba69849a62ce33ba01f0f5fcb992d", "price_changes": [{"asset_id": "103859159453183957891244689604385927345314190615024118584206363782908647975749", "price": "0.05", "size": "5.47", "side": "SELL", "hash": "bfa37926e4e3997a31b7092bf2c045c4d9eb653a", "best_bid": "0", "best_ask": "0.001"}, {"asset_id": "87105071850972641214581759809593758129422200795386115503863798159438712941487", "price": "0.95", "size": "5.47", "side": "BUY", "hash": "9ce736473beb9150442f6f600f634e59528c20e6", "best_bid": "0.999", "best_ask": "1"}], "timestamp": "1769384503042", "event_type": "price_change"}}
{"_local_timestamp": "2026-01-25T23:41:43.165437+00:00", "data": {"market": "0x60d31be668659012a5f83ee259c9b4eee3053c71dd68abe4d277f54722cd017f", "price_changes": [{"asset_id": "42488602124923334991804541582064494050024109479561101679507993012554771196517", "price": "0.007", "size": "5.47", "side": "SELL", "hash": "ace9b4d412448c75bca554f7e5722779726bd1e5", "best_bid": "0.001", "best_ask": "0.007"}, {"asset_id": "102579243304231960045442519614514577865920600108882084366671276216059100139841", "price": "0.993", "size": "5.47", "side": "BUY", "hash": "e5afb577ec0f64afc436b66624c98f3260e569d4", "best_bid": "0.993", "best_ask": "0.999"}], "timestamp": "1769384503090", "event_type": "price_change"}}
{"_local_timestamp": "2026-01-25T23:41:43.165816+00:00", "data": {"market": "0x43d906123758b44e9b41f460d8619e290954186d3fe3a0544319216c30d2be24", "price_changes": [{"asset_id": "8986753851227051304286293461908502563978603715241747497243698980934689505938", "price": "0.007", "size": "5.47", "side": "SELL", "hash": "f5e5f5ce21aa66d2d24338538b296f5c2651de2c", "best_bid": "0.001", "best_ask": "0.007"}, {"asset_id": "15126910918760844641806927476005282998778904719663987971332027436874715278711", "price": "0.993", "size": "5.47", "side": "BUY", "hash": "5b2282f1fccb436cc226bb9c4556a15561d2f15f", "best_bid": "0.993", "best_ask": "0.999"}], "timestamp": "1769384503090", "event_type": "price_change"}}
{"_local_timestamp": "2026-01-25T23:41:43.310228+00:00", "data": {"market": "0x4341cc0ee3f6c33d5d14114804adbc56745ba69849a62ce33ba01f0f5fcb992d", "price_changes": [{"asset_id": "103859159453183957891244689604385927345314190615024118584206363782908647975749", "price": "0.051", "size": "0", "side": "SELL", "hash": "898690ba270efc6bd7d7ce58d75638e336e29aa3", "best_bid": "0", "best_ask": "0.001"}, {"asset_id": "87105071850972641214581759809593758129422200795386115503863798159438712941487", "price": "0.949", "size": "0", "side": "BUY", "hash": "872f99de60f8de4102a37ac106201f6655624a5b", "best_bid": "0.999", "best_ask": "1"}], "timestamp": "1769384503240", "event_type": "price_change"}}
{"_local_timestamp": "2026-01-25T23:41:43.326652+00:00", "data": {"market": "0xaaf07b81d091318fc50eea80f8c9848a45c901dbdd49a3291b3c4ec32669f4f6", "price_changes": [{"asset_id": "76470301286950624198649364496103459585378536165660664290615779124087725034055", "price": "0.008", "size": "92.12", "side": "SELL", "hash": "a3dbc73b343a7f550ea130704b69eb809a8539b0", "best_bid": "0", "best_ask": "0.001"}, {"asset_id": "77725644515863814306743026513820299582079276775056525666400499082315809995002", "price": "0.992", "size": "92.12", "side": "BUY", "hash": "80a19406b6e6fe660fa9f4858fc3d3a4137892da", "best_bid": "0.999", "best_ask": "1"}], "timestamp": "1769384503254", "event_type": "price_change"}}
{"_local_timestamp": "2026-01-25T23:41:43.610985+00:00", "data": {"market": "0x4341cc0ee3f6c33d5d14114804adbc56745ba69849a62ce33ba01f0f5fcb992d", "price_changes": [{"asset_id": "103859159453183957891244689604385927345314190615024118584206363782908647975749", "price": "0.049", "size": "8.21", "side": "SELL", "hash": "0878338e1bb6fcfe9b67b0b9d666597775d261e4", "best_bid": "0", "best_ask": "0.001"}, {"asset_id": "87105071850972641214581759809593758129422200795386115503863798159438712941487", "price": "0.951", "size": "8.21", "side": "BUY", "hash": "1be27c61fa17f248366ffabda51afc8d5ca2f30a", "best_bid": "0.999", "best_ask": "1"}], "timestamp": "1769384503542", "event_type": "price_change"}}
{"_local_timestamp": "2026-01-25T23:41:43.738777+00:00", "data": {"market": "0x60d31be668659012a5f83ee259c9b4eee3053c71dd68abe4d277f54722cd017f", "price_changes": [{"asset_id": "42488602124923334991804541582064494050024109479561101679507993012554771196517", "price": "0.008", "size": "44.83", "side": "SELL", "hash": "907b27aadb6ac6c5c9650a9f29a747c546ffa30c", "best_bid": "0.001", "best_ask": "0.007"}, {"asset_id": "102579243304231960045442519614514577865920600108882084366671276216059100139841", "price": "0.992", "size": "44.83", "side": "BUY", "hash": "6f80ea16f12783a8b0e732b88cc2e392ccdad447", "best_bid": "0.993", "best_ask": "0.999"}], "timestamp": "1769384503666", "event_type": "price_change"}}
{"_local_timestamp": "2026-01-25T23:41:43.739263+00:00", "data": {"market": "0x43d906123758b44e9b41f460d8619e290954186d3fe3a0544319216c30d2be24", "price_changes": [{"asset_id": "8986753851227051304286293461908502563978603715241747497243698980934689505938", "price": "0.008", "size": "44.82", "side": "SELL", "hash": "14a5e0bfde7fa37c13d72f686414583cf7a0694a", "best_bid": "0.001", "best_ask": "0.007"}, {"asset_id": "15126910918760844641806927476005282998778904719663987971332027436874715278711", "price": "0.992", "size": "44.82", "side": "BUY", "hash": "66f0d73599e10b6a32ebf4b9c5290d794ccb517a", "best_bid": "0.993", "best_ask": "0.999"}], "timestamp": "1769384503666", "event_type": "price_change"}}
{"_local_timestamp": "2026-01-25T23:41:43.739632+00:00", "data": {"market": "0xaaf07b81d091318fc50eea80f8c9848a45c901dbdd49a3291b3c4ec32669f4f6", "price_changes": [{"asset_id": "76470301286950624198649364496103459585378536165660664290615779124087725034055", "price": "0.004", "size": "0", "side": "SELL", "hash": "87999f705a450a9c446985c32ba2449a1403e587", "best_bid": "0", "best_ask": "0.001"}, {"asset_id": "77725644515863814306743026513820299582079276775056525666400499082315809995002", "price": "0.996", "size": "0", "side": "BUY", "hash": "4c96f4e547025f7dd51d2a0f96f42619d3aece40", "best_bid": "0.999", "best_ask": "1"}], "timestamp": "1769384503666", "event_type": "price_change"}}
{"_local_timestamp": "2026-01-25T23:41:43.777276+00:00", "data": {"market": "0x05f99811bde90f48244ad16f03170506b2e949b38b504cc8a44c6e48ebe1702e", "price_changes": [{"asset_id": "36488786194543599561987515498496523553655318415436626702612953440782293472547", "price": "0.477", "size": "281", "side": "SELL", "hash": "cee070cc826c33bcafa58ef743546c78207a0946", "best_bid": "0.001", "best_ask": "0.008"}, {"asset_id": "104672182191593174875004906973935726924864992137789800398429529123634830971717", "price": "0.523", "size": "281", "side": "BUY", "hash": "345689c1ac6bc8081b457572e8be33cdb177d77f", "best_bid": "0.992", "best_ask": "0.999"}], "timestamp": "1769384503704", "event_type": "price_change"}}
{"_local_timestamp": "2026-01-25T23:41:44.085256+00:00", "data": {"market": "0x43d906123758b44e9b41f460d8619e290954186d3fe3a0544319216c30d2be24", "price_changes": [{"asset_id": "8986753851227051304286293461908502563978603715241747497243698980934689505938", "price": "0.006", "size": "8.21", "side": "SELL", "hash": "2732b6f6fcea43b1ffcafcbeccbfc540901ec636", "best_bid": "0.001", "best_ask": "0.006"}, {"asset_id": "15126910918760844641806927476005282998778904719663987971332027436874715278711", "price": "0.994", "size": "8.21", "side": "BUY", "hash": "1cf68ec6b8ebd0fec50ca9951ca236a5ab27846b", "best_bid": "0.994", "best_ask": "0.999"}], "timestamp": "1769384504000", "event_type": "price_change"}}
{"_local_timestamp": "2026-01-25T23:41:44.085616+00:00", "data": {"market": "0xaaf07b81d091318fc50eea80f8c9848a45c901dbdd49a3291b3c4ec32669f4f6", "price_changes": [{"asset_id": "76470301286950624198649364496103459585378536165660664290615779124087725034055", "price": "0.008", "size": "97.98", "side": "SELL", "hash": "7b242638e4858b2ab2db5f8b30ea7ea5dcaaa97a", "best_bid": "0", "best_ask": "0.001"}, {"asset_id": "77725644515863814306743026513820299582079276775056525666400499082315809995002", "price": "0.992", "size": "97.98", "side": "BUY", "hash": "952ca15064fd51448bc5b2ee76a388b21aeeb6e0", "best_bid": "0.999", "best_ask": "1"}], "timestamp": "1769384504000", "event_type": "price_change"}}
{"_local_timestamp": "2026-01-25T23:41:44.086104+00:00", "data": {"market": "0x60d31be668659012a5f83ee259c9b4eee3053c71dd68abe4d277f54722cd017f", "price_changes": [{"asset_id": "42488602124923334991804541582064494050024109479561101679507993012554771196517", "price": "0.006", "size": "8.22", "side": "SELL", "hash": "0fbf4e3ee9ba1b50085cbf461566e604b604a2ad", "best_bid": "0.001", "best_ask": "0.006"}, {"asset_id": "102579243304231960045442519614514577865920600108882084366671276216059100139841", "price": "0.994", "size": "8.22", "side": "BUY", "hash": "a54f8ec464ce2368f2f35bb79f529627178cad40", "best_bid": "0.994", "best_ask": "0.999"}], "timestamp": "1769384504000", "event_type": "price_change"}}
{"_local_timestamp": "2026-01-25T23:41:44.250248+00:00", "data": {"market": "0x60d31be668659012a5f83ee259c9b4eee3053c71dd68abe4d277f54722cd017f", "price_changes": [{"asset_id": "42488602124923334991804541582064494050024109479561101679507993012554771196517", "price": "0.477", "size": "281", "side": "SELL", "hash": "a9486b71e0d254a7d97d87bc5f16cde12c11b8b6", "best_bid": "0.001", "best_ask": "0.006"}, {"asset_id": "102579243304231960045442519614514577865920600108882084366671276216059100139841", "price": "0.523", "size": "281", "side": "BUY", "hash": "9d0dbb4ba7d43d860e472104b2c0fe18049c5128", "best_bid": "0.994", "best_ask": "0.999"}], "timestamp": "1769384504185", "event_type": "price_change"}}
{"_local_timestamp": "2026-01-25T23:41:44.608919+00:00", "data": {"market": "0xbadbd44eab1006c3823fc2ee131bd6208182caad0eded048fe8912bee99f4f3c", "price_changes": [{"asset_id": "40808098430716430535441235562064062343735166921796267991078590393515663038927", "price": "0.111", "size": "0", "side": "BUY", "hash": "511c3e452e5a8997a5eab981a2b631f08ce1c878", "best_bid": "0.999", "best_ask": "1"}, {"asset_id": "5196657230325088045531675116644215103600042490546214663989988661649301404833", "price": "0.889", "size": "0", "side": "SELL", "hash": "6c5869f67d3e8791f219ad953f9d3446a878ec1e", "best_bid": "0", "best_ask": "0.001"}], "timestamp": "1769384504525", "event_type": "price_change"}}
{"_local_timestamp": "2026-01-25T23:41:44.712071+00:00", "data": {"market": "0x60d31be668659012a5f83ee259c9b4eee3053c71dd68abe4d277f54722cd017f", "price_changes": [{"asset_id": "42488602124923334991804541582064494050024109479561101679507993012554771196517", "price": "0.007", "size": "0", "side": "SELL", "hash": "642f3f5bcbcf0a7cb4a93542a52b7623dbcf3d67", "best_bid": "0.001", "best_ask": "0.006"}, {"asset_id": "102579243304231960045442519614514577865920600108882084366671276216059100139841", "price": "0.993", "size": "0", "side": "BUY", "hash": "e060d00c2d575845d25ab999d8e81c3d0307fa73", "best_bid": "0.994", "best_ask": "0.999"}], "timestamp": "1769384504640", "event_type": "price_change"}}
{"_local_timestamp": "2026-01-25T23:41:44.712553+00:00", "data": {"market": "0x43d906123758b44e9b41f460d8619e290954186d3fe3a0544319216c30d2be24", "price_changes": [{"asset_id": "8986753851227051304286293461908502563978603715241747497243698980934689505938", "price": "0.007", "size": "0", "side": "SELL", "hash": "64adb399b94fb53e8659dda653fa67013773db23", "best_bid": "0.001", "best_ask": "0.006"}, {"asset_id": "15126910918760844641806927476005282998778904719663987971332027436874715278711", "price": "0.993", "size": "0", "side": "BUY", "hash": "c71eabae80982f84494faa974edde65e69881d3f", "best_bid": "0.994", "best_ask": "0.999"}], "timestamp": "1769384504640", "event_type": "price_change"}}
{"_local_timestamp": "2026-01-25T23:41:44.716142+00:00", "data": {"market": "0xaaf07b81d091318fc50eea80f8c9848a45c901dbdd49a3291b3c4ec32669f4f6", "price_changes": [{"asset_id": "76470301286950624198649364496103459585378536165660664290615779124087725034055", "price": "0.003", "size": "0", "side": "SELL", "hash": "1bf218a43976016cf417f8a13c7954f7729a2986", "best_bid": "0", "best_ask": "0.001"}, {"asset_id": "77725644515863814306743026513820299582079276775056525666400499082315809995002", "price": "0.997", "size": "0", "side": "BUY", "hash": "618290b40c1174533a3a069473ecf93b01b9e06a", "best_bid": "0.999", "best_ask": "1"}], "timestamp": "1769384504640", "event_type": "price_change"}}
