{"_local_timestamp": "2026-01-25T23:40:41.641001+00:00", "data": [{"market": "0x3f85b0d93db11c449ff2b38687dcd1eacde59f87237c15815af3fa1b5b8e1cf3", "asset_id": "105348778318527990745805132520856699619712448389399495051215018454082596094957", "timestamp": "1769384440622", "hash": "b289978bd14297fff579c52b588a9a9f98a3be26", "bids": [{"price": "0.001", "size": "6692.36"}, {"price": "0.002", "size": "5.05"}, {"price": "0.003", "size": "1000"}, {"price": "0.004", "size": "20.47"}, {"price": "0.01", "size": "5750"}, {"price": "0.02", "size": "2500"}, {"price": "0.021", "size": "14.34"}, {"price": "0.05", "size": "330"}, {"price": "0.051", "size": "39"}, {"price": "0.09", "size": "500"}, {"price": "0.093", "size": "3724"}, {"price": "0.094", "size": "6.4"}, {"price": "0.14", "size": "242.85"}, {"price": "0.141", "size": "1459"}, {"price": "0.19", "size": "168.42"}, {"price": "0.2", "size": "1050"}, {"price": "0.24", "size": "216.66"}, {"price": "0.242", "size": "1834"}, {"price": "0.27", "size": "50"}, {"price": "0.28", "size": "92.85"}, {"price": "0.33", "size": "72.72"}, {"price": "0.34", "size": "50"}, {"price": "0.38", "size": "52.63"}, {"price": "0.429", "size": "1398"}, {"price": "0.43", "size": "3311"}, {"price": "0.432", "size": "185"}, {"price": "0.72", "size": "5"}, {"price": "0.861", "size": "5"}, {"price": "0.876", "size": "185.45"}, {"price": "0.906", "size": "54.07"}, {"price": "0.907", "size": "200"}, {"price": "0.919", "size": "106"}, {"price": "0.92", "size": "200"}, {"price": "0.921", "size": "36.3"}, {"price": "0.922", "size": "23.1"}, {"price": "0.923", "size": "6.47"}], "asks": [{"price": "0.999", "size": "6084.99"}, {"price": "0.998", "size": "1756.13"}, {"price": "0.997", "size": "32"}, {"price": "0.99", "size": "1955.98"}, {"price": "0.989", "size": "11.44"}, {"price": "0.98", "size": "1200"}, {"price": "0.979", "size": "250"}, {"price": "0.978", "size": "7.31"}, {"price": "0.975", "size": "100"}, {"price": "0.97", "size": "1072.37"}, {"price": "0.969", "size": "100"}, {"price": "0.966", "size": "229.87"}, {"price": "0.965", "size": "170.37"}, {"price": "0.964", "size": "6.74"}, {"price": "0.96", "size": "239.02"}, {"price": "0.959", "size": "244"}, {"price": "0.941", "size": "207.28"}, {"price": "0.94", "size": "1.39"}], "event_type": "book", "last_trade_price": "0.060"}, {"market": "0x3f85b0d93db11c449ff2b38687dcd1eacde59f87237c15815af3fa1b5b8e1cf3", "asset_id": "71147528580947670980523166500223986349995999092566261733258219373243679868890", "timestamp": "1769384440622", "hash": "fe09b377f64291686ea444346aafcdc9891eae09", "bids": [{"price": "0.001", "size": "6084.99"}, {"price": "0.002", "size": "1756.13"}, {"price": "0.003", "size": "32"}, {"price": "0.01", "size": "1955.98"}, {"price": "0.011", "size": "11.44"}, {"price": "0.02", "size": "1200"}, {"price": "0.021", "size": "250"}, {"price": "0.022", "size": "7.31"}, {"price": "0.025", "size": "100"}, {"price": "0.03", "size": "1072.37"}, {"price": "0.031", "size": "100"}, {"price": "0.034", "size": "229.87"}, {"price": "0.035", "size": "170.37"}, {"price": "0.036", "size": "6.74"}, {"price": "0.04", "size": "239.02"}, {"price": "0.041", "size": "244"}, {"price": "0.059", "size": "207.28"}, {"price": "0.06", "size": "1.39"}], "asks": [{"price": "0.999", "size": "6692.36"}, {"price": "0.998", "size": "5.05"}, {"price": "0.997", "size": "1000"}, {"price": "0.996", "size": "20.47"}, {"price": "0.99", "size": "5750"}, {"price": "0.98", "size": "2500"}, {"price": "0.979", "size": "14.34"}, {"price": "0.95", "size": "330"}, {"price": "0.949", "size": "39"}, {"price": "0.91", "size": "500"}, {"price": "0.907", "size": "3724"}, {"price": "0.906", "size": "6.4"}, {"price": "0.86", "size": "242.85"}, {"price": "0.859", "size": "1459"}, {"price": "0.81", "size": "168.42"}, {"price": "0.8", "size": "1050"}, {"price": "0.76", "size": "216.66"}, {"price": "0.758", "size": "1834"}, {"price": "0.73", "size": "50"}, {"price": "0.72", "size": "92.85"}, {"price": "0.67", "size": "72.72"}, {"price": "0.66", "size": "50"}, {"price": "0.62", "size": "52.63"}, {"price": "0.571", "size": "1398"}, {"price": "0.57", "size": "3311"}, {"price": "0.568", "size": "185"}, {"price": "0.28", "size": "5"}, {"price": "0.139", "size": "5"}, {"price": "0.124", "size": "185.45"}, {"price": "0.094", "size": "54.07"}, {"price": "0.093", "size": "200"}, {"price": "0.081", "size": "106"}, {"price": "0.08", "size": "200"}, {"price": "0.079", "size": "36.3"}, {"price": "0.078", "size": "23.1"}, {"price": "0.077", "size": "6.47"}], "event_type": "book", "last_trade_price": "0.060"}]}
{"_local_timestamp": "2026-01-25T23:41:14.613557+00:00", "data": {"market": "0x3f85b0d93db11c449ff2b38687dcd1eacde59f87237c15815af3fa1b5b8e1cf3", "price_changes": [{"asset_id": "105348778318527990745805132520856699619712448389399495051215018454082596094957", "price": "0.242", "size": "100", "side": "BUY", "hash": "052e8877bdc8ee85ad9954ebfb63f62464ec6184", "best_bid": "0.923", "best_ask": "0.94"}, {"asset_id": "71147528580947670980523166500223986349995999092566261733258219373243679868890", "price": "0.758", "size": "100", "side": "SELL", "hash": "eaeed64fd229f5a5cdb663a1566263fe2294a27f", "best_bid": "0.06", "best_ask": "0.077"}], "timestamp": "1769384474530", "event_type": "price_change"}}
{"_local_timestamp": "2026-01-25T23:41:17.056712+00:00", "data": {"market": "0x3f85b0d93db11c449ff2b38687dcd1eacde59f87237c15815af3fa1b5b8e1cf3", "price_changes": [{"asset_id": "105348778318527990745805132520856699619712448389399495051215018454082596094957", "price": "0.241", "size": "1742", "side": "BUY", "hash": "e45ab5af8035b381bcb3adb86b2a5f3abaaa1852", "best_bid": "0.923", "best_ask": "0.94"}, {"asset_id": "71147528580947670980523166500223986349995999092566261733258219373243679868890", "price": "0.759", "size": "1742", "side": "SELL", "hash": "0ec79a7bf5c2546f298c473e632f45ecc7246dfd", "best_bid": "0.06", "best_ask": "0.077"}], "timestamp": "1769384476987", "event_type": "price_change"}}
{"_local_timestamp": "2026-01-25T23:41:50.927141+00:00", "data": {"market": "0x3f85b0d93db11c449ff2b38687dcd1eacde59f87237c15815af3fa1b5b8e1cf3", "price_changes": [{"asset_id": "105348778318527990745805132520856699619712448389399495051215018454082596094957", "price": "0.43", "size": "3251", "side": "BUY", "hash": "4ad7860cbf7a180b60f45d7e30bb76532238e3dc", "best_bid": "0.923", "best_ask": "0.94"}, {"asset_id": "71147528580947670980523166500223986349995999092566261733258219373243679868890", "price": "0.57", "size": "3251", "side": "SELL", "hash": "bfa56357121eb0ead45201dd834907633f10b550", "best_bid": "0.06", "best_ask": "0.077"}], "timestamp": "1769384510753", "event_type": "price_change"}}
{"_local_timestamp": "2026-01-25T23:41:50.929272+00:00", "data": {"market": "0x3f85b0d93db11c449ff2b38687dcd1eacde59f87237c15815af3fa1b5b8e1cf3", "price_changes": [{"asset_id": "105348778318527990745805132520856699619712448389399495051215018454082596094957", "price": "0.24", "size": "116.66", "side": "BUY", "hash": "4ad7860cbf7a180b60f45d7e30bb76532238e3dc", "best_bid": "0.923", "best_ask": "0.94"}, {"asset_id": "71147528580947670980523166500223986349995999092566261733258219373243679868890", "price": "0.76", "size": "116.66", "side": "SELL", "hash": "bfa56357121eb0ead45201dd834907633f10b550", "best_bid": "0.06", "best_ask": "0.077"}], "timestamp": "1769384510753", "event_type": "price_change"}}
{"_local_timestamp": "2026-01-25T23:41:52.015134+00:00", "data": {"market": "0x3f85b0d93db11c449ff2b38687dcd1eacde59f87237c15815af3fa1b5b8e1cf3", "price_changes": [{"asset_id": "105348778318527990745805132520856699619712448389399495051215018454082596094957", "price": "0.432", "size": "245", "side": "BUY", "hash": "73ee141ac250c33cd9754c5a2543495088a9a9d7", "best_bid": "0.923", "best_ask": "0.94"}, {"asset_id": "71147528580947670980523166500223986349995999092566261733258219373243679868890", "price": "0.568", "size": "245", "side": "SELL", "hash": "1a2833f67311238e938119ac3212838507d34add", "best_bid": "0.06", "best_ask": "0.077"}], "timestamp": "1769384511699", "event_type": "price_change"}}
{"_local_timestamp": "2026-01-25T23:41:52.927391+00:00", "data": {"market": "0x3f85b0d93db11c449ff2b38687dcd1eacde59f87237c15815af3fa1b5b8e1cf3", "price_changes": [{"asset_id": "105348778318527990745805132520856699619712448389399495051215018454082596094957", "price": "0.242", "size": "200", "side": "BUY", "hash": "651b374abab63c2b74b3b7fb991d2f270872e30d", "best_bid": "0.923", "best_ask": "0.94"}, {"asset_id": "71147528580947670980523166500223986349995999092566261733258219373243679868890", "price": "0.758", "size": "200", "side": "SELL", "hash": "16782449ad5537226a0fb149bd5cf5b457da2e0f", "best_bid": "0.06", "best_ask": "0.077"}], "timestamp": "1769384511946", "event_type": "price_change"}}
{"_local_timestamp": "2026-01-25T23:42:47.196434+00:00", "data": {"market": "0x3f85b0d93db11c449ff2b38687dcd1eacde59f87237c15815af3fa1b5b8e1cf3", "price_changes": [{"asset_id": "105348778318527990745805132520856699619712448389399495051215018454082596094957", "price": "0.241", "size": "0", "side": "BUY", "hash": "c42a7557c72482e2fc464416cad552f804af6a67", "best_bid": "0.923", "best_ask": "0.94"}, {"asset_id": "71147528580947670980523166500223986349995999092566261733258219373243679868890", "price": "0.759", "size": "0", "side": "SELL", "hash": "d68e3712cd3e423187e73c9ea9e984963f972eda", "best_bid": "0.06", "best_ask": "0.077"}], "timestamp": "1769384566989", "event_type": "price_change"}}
{"_local_timestamp": "2026-01-25T23:43:12.502028+00:00", "data": {"market": "0x3f85b0d93db11c449ff2b38687dcd1eacde59f87237c15815af3fa1b5b8e1cf3", "price_changes": [{"asset_id": "105348778318527990745805132520856699619712448389399495051215018454082596094957", "price": "0.243", "size": "1728", "side": "BUY", "hash": "90ef57aff08a49a9af59ba4fea35e02a881c0947", "best_bid": "0.923", "best_ask": "0.94"}, {"asset_id": "71147528580947670980523166500223986349995999092566261733258219373243679868890", "price": "0.757", "size": "1728", "side": "SELL", "hash": "519c1a622789f87828f584edd388b700e122445a", "best_bid": "0.06", "best_ask": "0.077"}], "timestamp": "1769384592369", "event_type": "price_change"}}
{"_local_timestamp": "2026-01-25T23:44:08.723028+00:00", "data": {"market": "0x3f85b0d93db11c449ff2b38687dcd1eacde59f87237c15815af3fa1b5b8e1cf3", "price_changes": [{"asset_id": "105348778318527990745805132520856699619712448389399495051215018454082596094957", "price": "0.242", "size": "150", "side": "BUY", "hash": "9db8eccb00de603672e1a7988efc9aeba7cfd2a7", "best_bid": "0.923", "best_ask": "0.94"}, {"asset_id": "71147528580947670980523166500223986349995999092566261733258219373243679868890", "price": "0.758", "size": "150", "side": "SELL", "hash": "c337c1b67f3d7e758415d4e7e0944c94db625758", "best_bid": "0.06", "best_ask": "0.077"}], "timestamp": "1769384648436", "event_type": "price_change"}}
{"_local_timestamp": "2026-01-25T23:44:09.041962+00:00", "data": {"market": "0x3f85b0d93db11c449ff2b38687dcd1eacde59f87237c15815af3fa1b5b8e1cf3", "price_changes": [{"asset_id": "105348778318527990745805132520856699619712448389399495051215018454082596094957", "price": "0.241", "size": "50", "side": "BUY", "hash": "94b8946db3b191dfb21517e1112aee95eeb45544", "best_bid": "0.923", "best_ask": "0.94"}, {"asset_id": "71147528580947670980523166500223986349995999092566261733258219373243679868890", "price": "0.759", "size": "50", "side": "SELL", "hash": "64befc3b72de143dc01ba4a49f02a3f159f4d424", "best_bid": "0.06", "best_ask": "0.077"}], "timestamp": "1769384648741", "event_type": "price_change"}}
{"_local_timestamp": "2026-01-25T23:44:20.858981+00:00", "data": {"market": "0x3f85b0d93db11c449ff2b38687dcd1eacde59f87237c15815af3fa1b5b8e1cf3", "price_changes": [{"asset_id": "105348778318527990745805132520856699619712448389399495051215018454082596094957", "price": "0.242", "size": "50", "side": "BUY", "hash": "8be6e123eb06657ad2628a3917a87f23e866d850", "best_bid": "0.923", "best_ask": "0.94"}, {"asset_id": "71147528580947670980523166500223986349995999092566261733258219373243679868890", "price": "0.758", "size": "50", "side": "SELL", "hash": "3fb1f1422486a273a93d8247db76d2016aa3cf00", "best_bid": "0.06", "best_ask": "0.077"}], "timestamp": "1769384660480", "event_type": "price_change"}}
{"_local_timestamp": "2026-01-25T23:44:21.453463+00:00", "data": {"market": "0x3f85b0d93db11c449ff2b38687dcd1eacde59f87237c15815af3fa1b5b8e1cf3", "price_changes": [{"asset_id": "105348778318527990745805132520856699619712448389399495051215018454082596094957", "price": "0.241", "size": "150", "side": "BUY", "hash": "b5aaee2a4706696d78517ff496186599efd75197", "best_bid": "0.923", "best_ask": "0.94"}, {"asset_id": "71147528580947670980523166500223986349995999092566261733258219373243679868890", "price": "0.759", "size": "150", "side": "SELL", "hash": "32791600fccb697c49ea6da46337bb83b7b5e361", "best_bid": "0.06", "best_ask": "0.077"}], "timestamp": "1769384660846", "event_type": "price_change"}}
{"_local_timestamp": "2026-01-25T23:44:23.237817+00:00", "data": {"market": "0x3f85b0d93db11c449ff2b38687dcd1eacde59f87237c15815af3fa1b5b8e1cf3", "price_changes": [{"asset_id": "71147528580947670980523166500223986349995999092566261733258219373243679868890", "price": "0.049", "size": "100", "side": "BUY", "hash": "be9fadbf21aad96bb2b6857a8d1d76d8f9ab86c4", "best_bid": "0.06", "best_ask": "0.077"}, {"asset_id": "105348778318527990745805132520856699619712448389399495051215018454082596094957", "price": "0.951", "size": "100", "side": "SELL", "hash": "4fec4d2f4127cfb0183effc17352b07533643b7a", "best_bid": "0.923", "best_ask": "0.94"}], "timestamp": "1769384662993", "event_type": "price_change"}}
{"_local_timestamp": "2026-01-25T23:44:23.254505+00:00", "data": {"market": "0x3f85b0d93db11c449ff2b38687dcd1eacde59f87237c15815af3fa1b5b8e1cf3", "price_changes": [{"asset_id": "105348778318527990745805132520856699619712448389399495051215018454082596094957", "price": "0.912", "size": "100", "side": "BUY", "hash": "a844e7b8e9c64f45a34935c4f01dc31045608965", "best_bid": "0.923", "best_ask": "0.94"}, {"asset_id": "71147528580947670980523166500223986349995999092566261733258219373243679868890", "price": "0.088", "size": "100", "side": "SELL", "hash": "7869cd564c49bc7f4353e4463d663e5a5ee5a41d", "best_bid": "0.06", "best_ask": "0.077"}], "timestamp": "1769384662994", "event_type": "price_change"}}
{"_local_timestamp": "2026-01-25T23:44:23.276269+00:00", "data": {"market": "0x3f85b0d93db11c449ff2b38687dcd1eacde59f87237c15815af3fa1b5b8e1cf3", "price_changes": [{"asset_id": "71147528580947670980523166500223986349995999092566261733258219373243679868890", "price": "0.041", "size": "0", "side": "BUY", "hash": "5d9c28400e582013c5074d85aa456b248327b719", "best_bid": "0.06", "best_ask": "0.077"}, {"asset_id": "105348778318527990745805132520856699619712448389399495051215018454082596094957", "price": "0.959", "size": "0", "side": "SELL", "hash": "dfffdb5e957e38a2caeb02168fa7208f3d7c84b7", "best_bid": "0.923", "best_ask": "0.94"}], "timestamp": "1769384663019", "event_type": "price_change"}}
{"_local_timestamp": "2026-01-25T23:44:23.294575+00:00", "data": {"market": "0x3f85b0d93db11c449ff2b38687dcd1eacde59f87237c15815af3fa1b5b8e1cf3", "price_changes": [{"asset_id": "71147528580947670980523166500223986349995999092566261733258219373243679868890", "price": "0.06", "size": "236.39", "side": "BUY", "hash": "85f2cbe02abe583124d32377d4e20fcab949b517", "best_bid": "0.06", "best_ask": "0.077"}, {"asset_id": "105348778318527990745805132520856699619712448389399495051215018454082596094957", "price": "0.94", "size": "236.39", "side": "SELL", "hash": "8a94485a114d45ebd1e9fdc864914d6b2516671d", "best_bid": "0.923", "best_ask": "0.94"}], "timestamp": "1769384663047", "event_type": "price_change"}}
{"_local_timestamp": "2026-01-25T23:44:57.812876+00:00", "data": {"market": "0x3f85b0d93db11c449ff2b38687dcd1eacde59f87237c15815af3fa1b5b8e1cf3", "price_changes": [{"asset_id": "105348778318527990745805132520856699619712448389399495051215018454082596094957", "price": "0.242", "size": "0", "side": "BUY", "hash": "f9adc7e4109fad8fc98794daeebeb56556e566d9", "best_bid": "0.923", "best_ask": "0.94"}, {"asset_id": "71147528580947670980523166500223986349995999092566261733258219373243679868890", "price": "0.758", "size": "0", "side": "SELL", "hash": "52328bd59ecf91a73783e72fe9c5a614ae9983d6", "best_bid": "0.06", "best_ask": "0.077"}], "timestamp": "1769384697722", "event_type": "price_change"}}
{"_local_timestamp": "2026-01-25T23:44:58.388047+00:00", "data": {"market": "0x3f85b0d93db11c449ff2b38687dcd1eacde59f87237c15815af3fa1b5b8e1cf3", "price_changes": [{"asset_id": "105348778318527990745805132520856699619712448389399495051215018454082596094957", "price": "0.2", "size": "1100", "side": "BUY", "hash": "a3f178378df1012d474e250ff750964182cc836c", "best_bid": "0.923", "best_ask": "0.94"}, {"asset_id": "71147528580947670980523166500223986349995999092566261733258219373243679868890", "price": "0.8", "size": "1100", "side": "SELL", "hash": "4cf449859729e280546daf85ee4392deccc89112", "best_bid": "0.06", "best_ask": "0.077"}], "timestamp": "1769384698227", "event_type": "price_change"}}
{"_local_timestamp": "2026-01-25T23:45:53.205203+00:00", "data": {"market": "0x3f85b0d93db11c449ff2b38687dcd1eacde59f87237c15815af3fa1b5b8e1cf3", "price_changes": [{"asset_id": "105348778318527990745805132520856699619712448389399495051215018454082596094957", "price": "0.241", "size": "100", "side": "BUY", "hash": "a4393b79af6dbf8fe23f20c8afd2361e8b78eac8", "best_bid": "0.923", "best_ask": "0.94"}, {"asset_id": "71147528580947670980523166500223986349995999092566261733258219373243679868890", "price": "0.759", "size": "100", "side": "SELL", "hash": "21d1a64eaefbef75646ae6928c117a4642aaaf05", "best_bid": "0.06", "best_ask": "0.077"}], "timestamp": "1769384753014", "event_type": "price_change"}}
{"_local_timestamp": "2026-01-25T23:45:53.755013+00:00", "data": {"market": "0x3f85b0d93db11c449ff2b38687dcd1eacde59f87237c15815af3fa1b5b8e1cf3", "price_changes": [{"asset_id": "105348778318527990745805132520856699619712448389399495051215018454082596094957", "price": "0.243", "size": "1778", "side": "BUY", "hash": "80d85771edecf67f1f239c1a80e307defd566118", "best_bid": "0.923", "best_ask": "0.94"}, {"asset_id": "71147528580947670980523166500223986349995999092566261733258219373243679868890", "price": "0.757", "size": "1778", "side": "SELL", "hash": "bd3e99d2353f75e3da30d7c851947a4c3935f20e", "best_bid": "0.06", "best_ask": "0.077"}], "timestamp": "1769384753536", "event_type": "price_change"}}
{"_local_timestamp": "2026-01-25T23:46:10.636315+00:00", "data": {"market": "0x3f85b0d93db11c449ff2b38687dcd1eacde59f87237c15815af3fa1b5b8e1cf3", "price_changes": [{"asset_id": "105348778318527990745805132520856699619712448389399495051215018454082596094957", "price": "0.243", "size": "50", "side": "BUY", "hash": "bca2b53c5714cfa3f9a07d09f43058b602e1db72", "best_bid": "0.923", "best_ask": "0.94"}, {"asset_id": "71147528580947670980523166500223986349995999092566261733258219373243679868890", "price": "0.757", "size": "50", "side": "SELL", "hash": "4436e8aa0f875eee03d7fbda389853990c5ed0af", "best_bid": "0.06", "best_ask": "0.077"}], "timestamp": "1769384770462", "event_type": "price_change"}}
{"_local_timestamp": "2026-01-25T23:46:13.112859+00:00", "data": {"market": "0x3f85b0d93db11c449ff2b38687dcd1eacde59f87237c15815af3fa1b5b8e1cf3", "price_changes": [{"asset_id": "105348778318527990745805132520856699619712448389399495051215018454082596094957", "price": "0.242", "size": "1734", "side": "BUY", "hash": "0f109f3b11bdbe7cda92629266ec0d8ce101ab6b", "best_bid": "0.923", "best_ask": "0.94"}, {"asset_id": "71147528580947670980523166500223986349995999092566261733258219373243679868890", "price": "0.758", "size": "1734", "side": "SELL", "hash": "842a32c32ad94b095664d570dc856636d823d65f", "best_bid": "0.06", "best_ask": "0.077"}], "timestamp": "1769384773038", "event_type": "price_change"}}
{"_local_timestamp": "2026-01-25T23:46:51.121205+00:00", "data": {"market": "0x3f85b0d93db11c449ff2b38687dcd1eacde59f87237c15815af3fa1b5b8e1cf3", "price_changes": [{"asset_id": "105348778318527990745805132520856699619712448389399495051215018454082596094957", "price": "0.241", "size": "0", "side": "BUY", "hash": "12864c87b8112dd67a11c3b27b46efc6eccab801", "best_bid": "0.923", "best_ask": "0.94"}, {"asset_id": "71147528580947670980523166500223986349995999092566261733258219373243679868890", "price": "0.759", "size": "0", "side": "SELL", "hash": "79b2d87b7052551f0f535723e53dfa472f320ff3", "best_bid": "0.06", "best_ask": "0.077"}], "timestamp": "1769384810847", "event_type": "price_change"}}
{"_local_timestamp": "2026-01-25T23:46:51.515455+00:00", "data": {"market": "0x3f85b0d93db11c449ff2b38687dcd1eacde59f87237c15815af3fa1b5b8e1cf3", "price_changes": [{"asset_id": "105348778318527990745805132520856699619712448389399495051215018454082596094957", "price": "0.243", "size": "150", "side": "BUY", "hash": "087ca6d155e4f02325d224046e36b527d3f08001", "best_bid": "0.923", "best_ask": "0.94"}, {"asset_id": "71147528580947670980523166500223986349995999092566261733258219373243679868890", "price": "0.757", "size": "150", "side": "SELL", "hash": "d4cad8d59263398794288542138d05b60d928d77", "best_bid": "0.06", "best_ask": "0.077"}], "timestamp": "1769384811205", "event_type": "price_change"}}
{"_local_timestamp": "2026-01-25T23:47:23.531954+00:00", "data": {"market": "0x3f85b0d93db11c449ff2b38687dcd1eacde59f87237c15815af3fa1b5b8e1cf3", "price_changes": [{"asset_id": "105348778318527990745805132520856699619712448389399495051215018454082596094957", "price": "0.2", "size": "1050", "side": "BUY", "hash": "920157d524d64224f49061fd834fac02bf716d67", "best_bid": "0.923", "best_ask": "0.94"}, {"asset_id": "71147528580947670980523166500223986349995999092566261733258219373243679868890", "price": "0.8", "size": "1050", "side": "SELL", "hash": "a39f89924d154eadac61f6971487c925f64954b5", "best_bid": "0.06", "best_ask": "0.077"}], "timestamp": "1769384843395", "event_type": "price_change"}}
{"_local_timestamp": "2026-01-25T23:47:23.930782+00:00", "data": {"market": "0x3f85b0d93db11c449ff2b38687dcd1eacde59f87237c15815af3fa1b5b8e1cf3", "price_changes": [{"asset_id": "105348778318527990745805132520856699619712448389399495051215018454082596094957", "price": "0.243", "size": "200", "side": "BUY", "hash": "e0680024e5588d54fdd0a0565258e8ca41a662cc", "best_bid": "0.923", "best_ask": "0.94"}, {"asset_id": "71147528580947670980523166500223986349995999092566261733258219373243679868890", "price": "0.757", "size": "200", "side": "SELL", "hash": "654d85df66668961d1c566916b9082a45ccbe373", "best_bid": "0.06", "best_ask": "0.077"}], "timestamp": "1769384843824", "event_type": "price_change"}}
{"_local_timestamp": "2026-01-25T23:47:55.651931+00:00", "data": {"market": "0x3f85b0d93db11c449ff2b38687dcd1eacde59f87237c15815af3fa1b5b8e1cf3", "price_changes": [{"asset_id": "105348778318527990745805132520856699619712448389399495051215018454082596094957", "price": "0.242", "size": "0", "side": "BUY", "hash": "7310169fb63bee42586e8ce4f0ab8bc4e5baa873", "best_bid": "0.923", "best_ask": "0.94"}, {"asset_id": "71147528580947670980523166500223986349995999092566261733258219373243679868890", "price": "0.758", "size": "0", "side": "SELL", "hash": "7bb262c9c101d4e68e87ca41c221b4f45f0f5e12", "best_bid": "0.06", "best_ask": "0.077"}], "timestamp": "1769384875422", "event_type": "price_change"}}
{"_local_timestamp": "2026-01-25T23:48:19.142811+00:00", "data": {"market": "0x3f85b0d93db11c449ff2b38687dcd1eacde59f87237c15815af3fa1b5b8e1cf3", "price_changes": [{"asset_id": "105348778318527990745805132520856699619712448389399495051215018454082596094957", "price": "0.244", "size": "1720", "side": "BUY", "hash": "7e51bf57db50d2ebe8f11a01eaece0c53265bd21", "best_bid": "0.923", "best_ask": "0.94"}, {"asset_id": "71147528580947670980523166500223986349995999092566261733258219373243679868890", "price": "0.756", "size": "1720", "side": "SELL", "hash": "495c42bfd0a26786ace20ebc8b13925c65e124ce", "best_bid": "0.06", "best_ask": "0.077"}], "timestamp": "1769384899074", "event_type": "price_change"}}
{"_local_timestamp": "2026-01-25T23:49:18.828857+00:00", "data": {"market": "0x3f85b0d93db11c449ff2b38687dcd1eacde59f87237c15815af3fa1b5b8e1cf3", "price_changes": [{"asset_id": "105348778318527990745805132520856699619712448389399495051215018454082596094957", "price": "0.43", "size": "0", "side": "BUY", "hash": "d4e5899745319402df8cffa70c7a2b4a7bc510de", "best_bid": "0.923", "best_ask": "0.94"}, {"asset_id": "71147528580947670980523166500223986349995999092566261733258219373243679868890", "price": "0.57", "size": "0", "side": "SELL", "hash": "9846d6a88f390d897bd4f5e019779b666b8bc4b0", "best_bid": "0.06", "best_ask": "0.077"}], "timestamp": "1769384958760", "event_type": "price_change"}}
{"_local_timestamp": "2026-01-25T23:49:18.998039+00:00", "data": {"market": "0x3f85b0d93db11c449ff2b38687dcd1eacde59f87237c15815af3fa1b5b8e1cf3", "price_changes": [{"asset_id": "105348778318527990745805132520856699619712448389399495051215018454082596094957", "price": "0.433", "size": "3225", "side": "BUY", "hash": "fc806d8f2657aa060661a8f8e288949852c42ebb", "best_bid": "0.923", "best_ask": "0.94"}, {"asset_id": "71147528580947670980523166500223986349995999092566261733258219373243679868890", "price": "0.567", "size": "3225", "side": "SELL", "hash": "3672c781f0556445d57a8fd3bed976c346ee40d3", "best_bid": "0.06", "best_ask": "0.077"}], "timestamp": "1769384958933", "event_type": "price_change"}}
{"_local_timestamp": "2026-01-25T23:49:25.570590+00:00", "data": {"market": "0x3f85b0d93db11c449ff2b38687dcd1eacde59f87237c15815af3fa1b5b8e1cf3", "price_changes": [{"asset_id": "105348778318527990745805132520856699619712448389399495051215018454082596094957", "price": "0.243", "size": "150", "side": "BUY", "hash": "63af36edee2bdce9d905d5b5b623fd86b958f4af", "best_bid": "0.923", "best_ask": "0.94"}, {"asset_id": "71147528580947670980523166500223986349995999092566261733258219373243679868890", "price": "0.757", "size": "150", "side": "SELL", "hash": "3162a40bc8af4ee9aee5dec568c2493adb2d2d88", "best_bid": "0.06", "best_ask": "0.077"}], "timestamp": "1769384965494", "event_type": "price_change"}}
{"_local_timestamp": "2026-01-25T23:49:25.835609+00:00", "data": {"market": "0x3f85b0d93db11c449ff2b38687dcd1eacde59f87237c15815af3fa1b5b8e1cf3", "price_changes": [{"asset_id": "105348778318527990745805132520856699619712448389399495051215018454082596094957", "price": "0.242", "size": "50", "side": "BUY", "hash": "386c394fdb2276d9d004227fab2e0570a3ab4b4f", "best_bid": "0.923", "best_ask": "0.94"}, {"asset_id": "71147528580947670980523166500223986349995999092566261733258219373243679868890", "price": "0.758", "size": "50", "side": "SELL", "hash": "bb4625a1dcd5f4d5456578cc75543afc5703e639", "best_bid": "0.06", "best_ask": "0.077"}], "timestamp": "1769384965762", "event_type": "price_change"}}
{"_local_timestamp": "2026-01-25T23:49:30.458808+00:00", "data": {"market": "0x3f85b0d93db11c449ff2b38687dcd1eacde59f87237c15815af3fa1b5b8e1cf3", "price_changes": [{"asset_id": "105348778318527990745805132520856699619712448389399495051215018454082596094957", "price": "0.243", "size": "50", "side": "BUY", "hash": "2d0d5b99d3c75c386b69e1cb8f5ea3632b3dc4a8", "best_bid": "0.923", "best_ask": "0.94"}, {"asset_id": "71147528580947670980523166500223986349995999092566261733258219373243679868890", "price": "0.757", "size": "50", "side": "SELL", "hash": "db809b618f78cbc67c04d4fb348dad1d9b26b07a", "best_bid": "0.06", "best_ask": "0.077"}], "timestamp": "1769384970076", "event_type": "price_change"}}
{"_local_timestamp": "2026-01-25T23:49:31.171989+00:00", "data": {"market": "0x3f85b0d93db11c449ff2b38687dcd1eacde59f87237c15815af3fa1b5b8e1cf3", "price_changes": [{"asset_id": "105348778318527990745805132520856699619712448389399495051215018454082596094957", "price": "0.242", "size": "150", "side": "BUY", "hash": "bae76f6a0f11498db47c1b806f2393b2e795611e", "best_bid": "0.923", "best_ask": "0.94"}, {"asset_id": "71147528580947670980523166500223986349995999092566261733258219373243679868890", "price": "0.758", "size": "150", "side": "SELL", "hash": "f6f7163e33743d586e37431bb76c421e4496f488", "best_bid": "0.06", "best_ask": "0.077"}], "timestamp": "1769384970800", "event_type": "price_change"}}
{"_local_timestamp": "2026-01-25T23:49:41.779258+00:00", "data": {"market": "0x3f85b0d93db11c449ff2b38687dcd1eacde59f87237c15815af3fa1b5b8e1cf3", "price_changes": [{"asset_id": "105348778318527990745805132520856699619712448389399495051215018454082596094957", "price": "0.243", "size": "0", "side": "BUY", "hash": "bf562eb3273fb1762e8c62ed15c0d584e629dd4e", "best_bid": "0.923", "best_ask": "0.94"}, {"asset_id": "71147528580947670980523166500223986349995999092566261733258219373243679868890", "price": "0.757", "size": "0", "side": "SELL", "hash": "23c43721bc82d108e0aebeaaca83db39f55b87af", "best_bid": "0.06", "best_ask": "0.077"}], "timestamp": "1769384981653", "event_type": "price_change"}}
{"_local_timestamp": "2026-01-25T23:49:42.398271+00:00", "data": {"market": "0x3f85b0d93db11c449ff2b38687dcd1eacde59f87237c15815af3fa1b5b8e1cf3", "price_changes": [{"asset_id": "105348778318527990745805132520856699619712448389399495051215018454082596094957", "price": "0.242", "size": "200", "side": "BUY", "hash": "83e58e3854e657fff1b1e1422c1f482c523a4d23", "best_bid": "0.923", "best_ask": "0.94"}, {"asset_id": "71147528580947670980523166500223986349995999092566261733258219373243679868890", "price": "0.758", "size": "200", "side": "SELL", "hash": "7ef8700cb791df0eb4e6bf4388a6e8d8d9129d16", "best_bid": "0.06", "best_ask": "0.077"}], "timestamp": "1769384982229", "event_type": "price_change"}}
{"_local_timestamp": "2026-01-25T23:50:02.618061+00:00", "data": {"market": "0x3f85b0d93db11c449ff2b38687dcd1eacde59f87237c15815af3fa1b5b8e1cf3", "price_changes": [{"asset_id": "105348778318527990745805132520856699619712448389399495051215018454082596094957", "price": "0.2", "size": "250", "side": "BUY", "hash": "4c4abd66379739b24b687f6987972a03828b1e58", "best_bid": "0.923", "best_ask": "0.94"}, {"asset_id": "71147528580947670980523166500223986349995999092566261733258219373243679868890", "price": "0.8", "size": "250", "side": "SELL", "hash": "5c05c27c2ff2d3f5d73474986982e6604db2d7d2", "best_bid": "0.06", "best_ask": "0.077"}], "timestamp": "1769385002283", "event_type": "price_change"}}
{"_local_timestamp": "2026-01-25T23:50:02.958103+00:00", "data": {"market": "0x3f85b0d93db11c449ff2b38687dcd1eacde59f87237c15815af3fa1b5b8e1cf3", "price_changes": [{"asset_id": "105348778318527990745805132520856699619712448389399495051215018454082596094957", "price": "0.429", "size": "0", "side": "BUY", "hash": "4d20b0ff20a140bcbeb655df068401152e95d720", "best_bid": "0.923", "best_ask": "0.94"}, {"asset_id": "71147528580947670980523166500223986349995999092566261733258219373243679868890", "price": "0.571", "size": "0", "side": "SELL", "hash": "0810fbf0b9be7f20a0e67eaf73bac8063e11a2c3", "best_bid": "0.06", "best_ask": "0.077"}], "timestamp": "1769385002367", "event_type": "price_change"}}
{"_local_timestamp": "2026-01-25T23:50:03.202133+00:00", "data": {"market": "0x3f85b0d93db11c449ff2b38687dcd1eacde59f87237c15815af3fa1b5b8e1cf3", "price_changes": [{"asset_id": "105348778318527990745805132520856699619712448389399495051215018454082596094957", "price": "0.141", "size": "325", "side": "BUY", "hash": "7cd939c5ee09fdeddbf901b51b949f17ad4b94e4", "best_bid": "0.923", "best_ask": "0.94"}, {"asset_id": "71147528580947670980523166500223986349995999092566261733258219373243679868890", "price": "0.859", "size": "325", "side": "SELL", "hash": "ca95d0ca7f7df2758e9725076b0d43968783520e", "best_bid": "0.06", "best_ask": "0.077"}], "timestamp": "1769385002725", "event_type": "price_change"}}
{"_local_timestamp": "2026-01-25T23:50:03.252116+00:00", "data": {"market": "0x3f85b0d93db11c449ff2b38687dcd1eacde59f87237c15815af3fa1b5b8e1cf3", "price_changes": [{"asset_id": "105348778318527990745805132520856699619712448389399495051215018454082596094957", "price": "0.093", "size": "500", "side": "BUY", "hash": "501033fa28269c87c4b7b18fb915a3c81b0a25dc", "best_bid": "0.923", "best_ask": "0.94"}, {"asset_id": "71147528580947670980523166500223986349995999092566261733258219373243679868890", "price": "0.907", "size": "500", "side": "SELL", "hash": "7989042e96949c12d5bb081fc198682b18d1db01", "best_bid": "0.06", "best_ask": "0.077"}], "timestamp": "1769385002855", "event_type": "price_change"}}
{"_local_timestamp": "2026-01-25T23:50:17.914411+00:00", "data": {"market": "0x3f85b0d93db11c449ff2b38687dcd1eacde59f87237c15815af3fa1b5b8e1cf3", "price_changes": [{"asset_id": "105348778318527990745805132520856699619712448389399495051215018454082596094957", "price": "0.094", "size": "3196.4", "side": "BUY", "hash": "908e6f0695ee2a840ae27b6abeb71476599365f3", "best_bid": "0.923", "best_ask": "0.94"}, {"asset_id": "71147528580947670980523166500223986349995999092566261733258219373243679868890", "price": "0.906", "size": "3196.4", "side": "SELL", "hash": "ce16f1710269962590019bd309e4e9625c6b9a3f", "best_bid": "0.06", "best_ask": "0.077"}], "timestamp": "1769385017816", "event_type": "price_change"}}
{"_local_timestamp": "2026-01-25T23:50:18.746930+00:00", "data": {"market": "0x3f85b0d93db11c449ff2b38687dcd1eacde59f87237c15815af3fa1b5b8e1cf3", "price_changes": [{"asset_id": "105348778318527990745805132520856699619712448389399495051215018454082596094957", "price": "0.142", "size": "1126", "side": "BUY", "hash": "7403caf69a43cafe8f34ac3caa6ed063cf1c9a5b", "best_bid": "0.923", "best_ask": "0.94"}, {"asset_id": "71147528580947670980523166500223986349995999092566261733258219373243679868890", "price": "0.858", "size": "1126", "side": "SELL", "hash": "6d56161b44c8ce838aa5b6bf09a2b19b58137198", "best_bid": "0.06", "best_ask": "0.077"}], "timestamp": "1769385018650", "event_type": "price_change"}}
{"_local_timestamp": "2026-01-25T23:50:37.987902+00:00", "data": {"market": "0x3f85b0d93db11c449ff2b38687dcd1eacde59f87237c15815af3fa1b5b8e1cf3", "price_changes": [{"asset_id": "105348778318527990745805132520856699619712448389399495051215018454082596094957", "price": "0.094", "size": "3190", "side": "BUY", "hash": "9b3ccf32f80fc139b29a8078a85e34ca0f6429f6", "best_bid": "0.923", "best_ask": "0.94"}, {"asset_id": "71147528580947670980523166500223986349995999092566261733258219373243679868890", "price": "0.906", "size": "3190", "side": "SELL", "hash": "0d0c5176e5b55598d5c984b6e5cf456d9e1c1fb9", "best_bid": "0.06", "best_ask": "0.077"}], "timestamp": "1769385037741", "event_type": "price_change"}}
{"_local_timestamp": "2026-01-25T23:50:38.877263+00:00", "data": {"market": "0x3f85b0d93db11c449ff2b38687dcd1eacde59f87237c15815af3fa1b5b8e1cf3", "price_changes": [{"asset_id": "105348778318527990745805132520856699619712448389399495051215018454082596094957", "price": "0.095", "size": "6.33", "side": "BUY", "hash": "f24f99440ad6e45840847be132c48bd7f1ec1176", "best_bid": "0.923", "best_ask": "0.94"}, {"asset_id": "71147528580947670980523166500223986349995999092566261733258219373243679868890", "price": "0.905", "size": "6.33", "side": "SELL", "hash": "dd601641cbece7cf325851f377a1f97ca0b46775", "best_bid": "0.06", "best_ask": "0.077"}], "timestamp": "1769385038671", "event_type": "price_change"}}
{"_local_timestamp": "2026-01-25T23:51:05.523515+00:00", "data": {"market": "0x3f85b0d93db11c449ff2b38687dcd1eacde59f87237c15815af3fa1b5b8e1cf3", "price_changes": [{"asset_id": "105348778318527990745805132520856699619712448389399495051215018454082596094957", "price": "0.242", "size": "150", "side": "BUY", "hash": "a1f17723c7f71108b09a1ec4e2533f6b58d2e23d", "best_bid": "0.923", "best_ask": "0.94"}, {"asset_id": "71147528580947670980523166500223986349995999092566261733258219373243679868890", "price": "0.758", "size": "150", "side": "SELL", "hash": "d501ed409a418632c107c1f1922601d38a58892b", "best_bid": "0.06", "best_ask": "0.077"}], "timestamp": "1769385065414", "event_type": "price_change"}}
{"_local_timestamp": "2026-01-25T23:51:06.054387+00:00", "data": {"market": "0x3f85b0d93db11c449ff2b38687dcd1eacde59f87237c15815af3fa1b5b8e1cf3", "price_changes": [{"asset_id": "105348778318527990745805132520856699619712448389399495051215018454082596094957", "price": "0.244", "size": "1770", "side": "BUY", "hash": "d5398d247d08956cd63d19127cdd94163cba1c13", "best_bid": "0.923", "best_ask": "0.94"}, {"asset_id": "71147528580947670980523166500223986349995999092566261733258219373243679868890", "price": "0.756", "size": "1770", "side": "SELL", "hash": "0e1f104420e3a80af1352abbd93c87c2a6e82863", "best_bid": "0.06", "best_ask": "0.077"}], "timestamp": "1769385065800", "event_type": "price_change"}}
{"_local_timestamp": "2026-01-25T23:51:11.175934+00:00", "data": {"market": "0x3f85b0d93db11c449ff2b38687dcd1eacde59f87237c15815af3fa1b5b8e1cf3", "price_changes": [{"asset_id": "105348778318527990745805132520856699619712448389399495051215018454082596094957", "price": "0.434", "size": "1382", "side": "BUY", "hash": "219aae871b97ab3199057b20d9123301d3448a3c", "best_bid": "0.923", "best_ask": "0.94"}, {"asset_id": "71147528580947670980523166500223986349995999092566261733258219373243679868890", "price": "0.566", "size": "1382", "side": "SELL", "hash": "36a9816d880793fdec1a5556fe0be77eb91751b0", "best_bid": "0.06", "best_ask": "0.077"}], "timestamp": "1769385071100", "event_type": "price_change"}}
