{"_local_timestamp": "2026-01-25T23:40:53.122600+00:00", "data": [{"market": "0x57907f477d6295cee2b169859b8606644a4d71d0ec6128372b0c9db9913bcd93", "asset_id": "101193316906353661596667021454376162656427957280783485056984469355545526109216", "timestamp": "1769384364409", "hash": "0f0f8040be9032f89ab1693b056cb91a78efcba5", "bids": [{"price": "0.01", "size": "233.74"}, {"price": "0.02", "size": "100"}, {"price": "0.03", "size": "66.66"}, {"price": "0.05", "size": "46"}, {"price": "0.06", "size": "83.26"}], "asks": [{"price": "0.99", "size": "3362.86"}, {"price": "0.98", "size": "1756.09"}, {"price": "0.97", "size": "6.25"}, {"price": "0.96", "size": "1000"}, {"price": "0.95", "size": "330"}, {"price": "0.94", "size": "349.66"}, {"price": "0.93", "size": "300"}, {"price": "0.92", "size": "200"}, {"price": "0.91", "size": "6.29"}, {"price": "0.9", "size": "6"}, {"price": "0.89", "size": "5.69"}, {"price": "0.85", "size": "66.66"}, {"price": "0.84", "size": "20"}, {"price": "0.81", "size": "66.66"}, {"price": "0.8", "size": "79"}], "event_type": "book", "last_trade_price": ""}, {"market": "0xbc2006687eb6ab0081379a56ada7381b6b3b865ffb574e08a7a3e859a7434b7c", "asset_id": "63583217354653742103033975957525643306323589776872901149499294038892138077829", "timestamp": "1769384364408", "hash": "865993917ec1f4b105c40ac4d20917ba996ca29a", "bids": [{"price": "0.01", "size": "3364.08"}, {"price": "0.02", "size": "1755.51"}, {"price": "0.03", "size": "12.93"}, {"price": "0.04", "size": "1000"}, {"price": "0.05", "size": "330"}, {"price": "0.06", "size": "388.32"}, {"price": "0.07", "size": "300"}, {"price": "0.08", "size": "166.66"}, {"price": "0.09", "size": "11.57"}, {"price": "0.1", "size": "5"}, {"price": "0.14", "size": "66.66"}, {"price": "0.16", "size": "66.66"}, {"price": "0.17", "size": "20"}, {"price": "0.18", "size": "158.33"}], "asks": [{"price": "0.99", "size": "233.74"}, {"price": "0.98", "size": "100"}, {"price": "0.97", "size": "66.66"}, {"price": "0.95", "size": "46"}, {"price": "0.94", "size": "66.66"}], "event_type": "book", "last_trade_price": ""}, {"market": "0xbb5745a78307d6434215753ec4aed95ec3eb3272f92d32d9832754c04c35f08c", "asset_id": "51786810938584713265589072330718248037720929244183431852537036646815091958237", "timestamp": "1769384359950", "hash": "3886618ea4ee9cb1b38a8a45e6fc49ab8806b2e8", "bids": [{"price": "0.01", "size": "233.74"}, {"price": "0.02", "size": "100"}, {"price": "0.03", "size": "66.66"}, {"price": "0.05", "size": "46"}, {"price": "0.06", "size": "76.66"}], "asks": [{"price": "0.99", "size": "3350"}, {"price": "0.98", "size": "1750"}, {"price": "0.96", "size": "1000"}, {"price": "0.95", "size": "330"}, {"price": "0.94", "size": "349.66"}, {"price": "0.93", "size": "300"}, {"price": "0.92", "size": "200"}, {"price": "0.91", "size": "100"}, {"price": "0.86", "size": "66.66"}, {"price": "0.85", "size": "20"}, {"price": "0.81", "size": "66.66"}, {"price": "0.8", "size": "79"}], "event_type": "book", "last_trade_price": ""}, {"market": "0xbb5745a78307d6434215753ec4aed95ec3eb3272f92d32d9832754c04c35f08c", "asset_id": "24067803523094369652482608318472371337596458082523423062803274427732809099156", "timestamp": "1769384359950", "hash": "d39f3517600c7dcd3d237fe136fcdcf09d1fd320", "bids": [{"price": "0.01", "size": "3350"}, {"price": "0.02", "size": "1750"}, {"price": "0.04", "size": "1000"}, {"price": "0.05", "size": "330"}, {"price": "0.06", "size": "349.66"}, {"price": "0.07", "size": "300"}, {"price": "0.08", "size": "200"}, {"price": "0.09", "size": "100"}, {"price": "0.14", "size": "66.66"}, {"price": "0.15", "size": "20"}, {"price": "0.19", "size": "66.66"}, {"price": "0.2", "size": "79"}], "asks": [{"price": "0.99", "size": "233.74"}, {"price": "0.98", "size": "100"}, {"price": "0.97", "size": "66.66"}, {"price": "0.95", "size": "46"}, {"price": "0.94", "size": "76.66"}], "event_type": "book", "last_trade_price": ""}, {"market": "0x521ab5d3c24af074bb5496a9e8e83d85b520c08e6333ab21b617f122a564615a", "asset_id": "7528388713228609060142081103391244635491832722831643514084973789304836742854", "timestamp": "1769383877230", "hash": "b8cae6d4814ed23207da749d066b7bb5f78e9d7b", "bids": [{"price": "0.01", "size": "0.56"}], "asks": [{"price": "0.99", "size": "4435.9"}, {"price": "0.98", "size": "1750"}, {"price": "0.97", "size": "8.04"}, {"price": "0.96", "size": "1700"}, {"price": "0.95", "size": "130"}, {"price": "0.94", "size": "483"}, {"price": "0.93", "size": "100"}, {"price": "0.92", "size": "100"}, {"price": "0.91", "size": "6.71"}, {"price": "0.87", "size": "325"}, {"price": "0.81", "size": "250"}, {"price": "0.8", "size": "5.11"}, {"price": "0.77", "size": "75"}, {"price": "0.76", "size": "8"}, {"price": "0.53", "size": "66.66"}, {"price": "0.45", "size": "10.6"}, {"price": "0.08", "size": "66.66"}, {"price": "0.07", "size": "12.18"}], "event_type": "book", "last_trade_price": ""}, {"market": "0x57907f477d6295cee2b169859b8606644a4d71d0ec6128372b0c9db9913bcd93", "asset_id": "38193498706916382331735817582375344137760715410898207845843641476007403461254", "timestamp": "1769384364409", "hash": "ccc997b82314f1753e5edceb7aa8b09fd99e919c", "bids": [{"price": "0.01", "size": "3362.86"}, {"price": "0.02", "size": "1756.09"}, {"price": "0.03", "size": "6.25"}, {"price": "0.04", "size": "1000"}, {"price": "0.05", "size": "330"}, {"price": "0.06", "size": "349.66"}, {"price": "0.07", "size": "300"}, {"price": "0.08", "size": "200"}, {"price": "0.09", "size": "6.29"}, {"price": "0.1", "size": "6"}, {"price": "0.11", "size": "5.69"}, {"price": "0.15", "size": "66.66"}, {"price": "0.16", "size": "20"}, {"price": "0.19", "size": "66.66"}, {"price": "0.2", "size": "79"}], "asks": [{"price": "0.99", "size": "233.74"}, {"price": "0.98", "size": "100"}, {"price": "0.97", "size": "66.66"}, {"price": "0.95", "size": "46"}, {"price": "0.94", "size": "83.26"}], "event_type": "book", "last_trade_price": ""}, {"market": "0x521ab5d3c24af074bb5496a9e8e83d85b520c08e6333ab21b617f122a564615a", "asset_id": "86263889844673834773808760288478764459004352959184601356498789028474786900980", "timestamp": "1769383877230", "hash": "09e568d529aa6642c2132170dd0d9445bc39ed6e", "bids": [{"price": "0.01", "size": "4435.9"}, {"price": "0.02", "size": "1750"}, {"price": "0.03", "size": "8.04"}, {"price": "0.04", "size": "1700"}, {"price": "0.05", "size": "130"}, {"price": "0.06", "size": "483"}, {"price": "0.07", "size": "100"}, {"price": "0.08", "size": "100"}, {"price": "0.09", "size": "6.71"}, {"price": "0.13", "size": "325"}, {"price": "0.19", "size": "250"}, {"price": "0.2", "size": "5.11"}, {"price": "0.23", "size": "75"}, {"price": "0.24", "size": "8"}, {"price": "0.47", "size": "66.66"}, {"price": "0.55", "size": "10.6"}, {"price": "0.92", "size": "66.66"}, {"price": "0.93", "size": "12.18"}], "asks": [{"price": "0.99", "size": "0.56"}], "event_type": "book", "last_trade_price": ""}, {"market": "0xe2cfb3b48c35d28faaecf28e296d6f672188c90cfdf08c07a6e6a824e1bc7539", "asset_id": "40768718081882153418959955243994854330146531826408459920832464833723436741424", "timestamp": "1769384359950", "hash": "5893e4c26758e7d1e2ea1c1f0ad15dd467535c9a", "bids": [{"price": "0.01", "size": "233.74"}, {"price": "0.02", "size": "100"}, {"price": "0.03", "size": "66.66"}, {"price": "0.05", "size": "46"}, {"price": "0.06", "size": "66.66"}], "asks": [{"price": "0.99", "size": "3363.37"}, {"price": "0.98", "size": "1756.33"}, {"price": "0.97", "size": "10.96"}, {"price": "0.96", "size": "1000"}, {"price": "0.95", "size": "330"}, {"price": "0.94", "size": "355.33"}, {"price": "0.93", "size": "300"}, {"price": "0.92", "size": "200"}, {"price": "0.91", "size": "11.89"}, {"price": "0.89", "size": "5"}, {"price": "0.84", "size": "66.66"}, {"price": "0.83", "size": "20"}, {"price": "0.81", "size": "66.66"}, {"price": "0.8", "size": "79"}], "event_type": "book", "last_trade_price": ""}, {"market": "0xc0fe594181536c195b49e7b48526a24740f0913ffc90a77eb41b214f31a822b4", "asset_id": "113723988771241090253785053680072264720020982848328850292346167980912533825960", "timestamp": "1769384344623", "hash": "1a5ff504400b36af006db104b7563a9bbe414a41", "bids": [{"price": "0.01", "size": "183.33"}, {"price": "0.02", "size": "166.66"}, {"price": "0.03", "size": "66.66"}, {"price": "0.04", "size": "176"}, {"price": "0.05", "size": "76.66"}], "asks": [{"price": "0.99", "size": "3363.1"}, {"price": "0.98", "size": "1756.18"}, {"price": "0.97", "size": "17.37"}, {"price": "0.96", "size": "1000"}, {"price": "0.95", "size": "230"}, {"price": "0.94", "size": "383"}, {"price": "0.93", "size": "306.49"}, {"price": "0.92", "size": "266.66"}, {"price": "0.9", "size": "18"}, {"price": "0.89", "size": "7"}, {"price": "0.87", "size": "66.66"}, {"price": "0.86", "size": "20"}, {"price": "0.8", "size": "150.66"}], "event_type": "book", "last_trade_price": ""}, {"market": "0xbc2006687eb6ab0081379a56ada7381b6b3b865ffb574e08a7a3e859a7434b7c", "asset_id": "68019269343969765341171874525368745169647714153650196737363227760382767964183", "timestamp": "1769384364408", "hash": "2a57d827d2f45596d93b72d817123228e5de9c1e", "bids": [{"price": "0.01", "size": "233.74"}, {"price": "0.02", "size": "100"}, {"price": "0.03", "size": "66.66"}, {"price": "0.05", "size": "46"}, {"price": "0.06", "size": "66.66"}], "asks": [{"price": "0.99", "size": "3364.08"}, {"price": "0.98", "size": "1755.51"}, {"price": "0.97", "size": "12.93"}, {"price": "0.96", "size": "1000"}, {"price": "0.95", "size": "330"}, {"price": "0.94", "size": "388.32"}, {"price": "0.93", "size": "300"}, {"price": "0.92", "size": "166.66"}, {"price": "0.91", "size": "11.57"}, {"price": "0.9", "size": "5"}, {"price": "0.86", "size": "66.66"}, {"price": "0.84", "size": "66.66"}, {"price": "0.83", "size": "20"}, {"price": "0.82", "size": "158.33"}], "event_type": "book", "last_trade_price": ""}, {"market": "0xe2cfb3b48c35d28faaecf28e296d6f672188c90cfdf08c07a6e6a824e1bc7539", "asset_id": "114856070891915179881203224601555438788948422405426418879020114548029044261628", "timestamp": "1769384359950", "hash": "0adcf5ee1737674913ea30b79ca41f3cfba08751", "bids": [{"price": "0.01", "size": "3363.37"}, {"price": "0.02", "size": "1756.33"}, {"price": "0.03", "size": "10.96"}, {"price": "0.04", "size": "1000"}, {"price": "0.05", "size": "330"}, {"price": "0.06", "size": "355.33"}, {"price": "0.07", "size": "300"}, {"price": "0.08", "size": "200"}, {"price": "0.09", "size": "11.89"}, {"price": "0.11", "size": "5"}, {"price": "0.16", "size": "66.66"}, {"price": "0.17", "size": "20"}, {"price": "0.19", "size": "66.66"}, {"price": "0.2", "size": "79"}], "asks": [{"price": "0.99", "size": "233.74"}, {"price": "0.98", "size": "100"}, {"price": "0.97", "size": "66.66"}, {"price": "0.95", "size": "46"}, {"price": "0.94", "size": "66.66"}], "event_type": "book", "last_trade_price": ""}, {"market": "0xc0fe594181536c195b49e7b48526a24740f0913ffc90a77eb41b214f31a822b4", "asset_id": "29141447781503863865336566062510441196981840569949260694480394604049274435905", "timestamp": "1769384344623", "hash": "89eea2a97393aa111dfcc8583b1a4b4e005ef000", "bids": [{"price": "0.01", "size": "3363.1"}, {"price": "0.02", "size": "1756.18"}, {"price": "0.03", "size": "17.37"}, {"price": "0.04", "size": "1000"}, {"price": "0.05", "size": "230"}, {"price": "0.06", "size": "383"}, {"price": "0.07", "size": "306.49"}, {"price": "0.08", "size": "266.66"}, {"price": "0.1", "size": "18"}, {"price": "0.11", "size": "7"}, {"price": "0.13", "size": "66.66"}, {"price": "0.14", "size": "20"}, {"price": "0.2", "size": "150.66"}], "asks": [{"price": "0.99", "size": "183.33"}, {"price": "0.98", "size": "166.66"}, {"price": "0.97", "size": "66.66"}, {"price": "0.96", "size": "176"}, {"price": "0.95", "size": "76.66"}], "event_type": "book", "last_trade_price": ""}]}
{"_local_timestamp": "2026-01-25T23:41:05.323091+00:00", "data": {"market": "0xbb5745a78307d6434215753ec4aed95ec3eb3272f92d32d9832754c04c35f08c", "price_changes": [{"asset_id": "24067803523094369652482608318472371337596458082523423062803274427732809099156", "price": "0.19", "size": "0", "side": "BUY", "hash": "57a30cc0bbb1a05c3e8f4982824775b51a3d8f85", "best_bid": "0.2", "best_ask": "0.94"}, {"asset_id": "51786810938584713265589072330718248037720929244183431852537036646815091958237", "price": "0.81", "size": "0", "side": "SELL", "hash": "1469f55b0dbca4b28f560230df4b03b317f3f981", "best_bid": "0.06", "best_ask": "0.8"}], "timestamp": "1769384465258", "event_type": "price_change"}}
{"_local_timestamp": "2026-01-25T23:41:05.331745+00:00", "data": {"market": "0xe2cfb3b48c35d28faaecf28e296d6f672188c90cfdf08c07a6e6a824e1bc7539", "price_changes": [{"asset_id": "114856070891915179881203224601555438788948422405426418879020114548029044261628", "price": "0.19", "size": "0", "side": "BUY", "hash": "55c48fa6d7f63b8aa95c4d3fb0b0c6ffb7ab16cf", "best_bid": "0.2", "best_ask": "0.94"}, {"asset_id": "40768718081882153418959955243994854330146531826408459920832464833723436741424", "price": "0.81", "size": "0", "side": "SELL", "hash": "07320b818a60c57b513c1b915df62e3313a16ba3", "best_bid": "0.06", "best_ask": "0.8"}], "timestamp": "1769384465258", "event_type": "price_change"}}
{"_local_timestamp": "2026-01-25T23:41:05.332564+00:00", "data": {"market": "0xbc2006687eb6ab0081379a56ada7381b6b3b865ffb574e08a7a3e859a7434b7c", "price_changes": [{"asset_id": "63583217354653742103033975957525643306323589776872901149499294038892138077829", "price": "0.16", "size": "0", "side": "BUY", "hash": "4d5037ea60e55a63b0b5645766989a69e437d35d", "best_bid": "0.18", "best_ask": "0.94"}, {"asset_id": "68019269343969765341171874525368745169647714153650196737363227760382767964183", "price": "0.84", "size": "0", "side": "SELL", "hash": "958b3820777fea31f672c7f903b91ae866d3b948", "best_bid": "0.06", "best_ask": "0.82"}], "timestamp": "1769384465258", "event_type": "price_change"}}
{"_local_timestamp": "2026-01-25T23:41:05.333856+00:00", "data": {"market": "0x57907f477d6295cee2b169859b8606644a4d71d0ec6128372b0c9db9913bcd93", "price_changes": [{"asset_id": "38193498706916382331735817582375344137760715410898207845843641476007403461254", "price": "0.19", "size": "0", "side": "BUY", "hash": "d02c9ed8ff8e89f15d2a6cb7d3a0b2b65ce1f197", "best_bid": "0.2", "best_ask": "0.94"}, {"asset_id": "101193316906353661596667021454376162656427957280783485056984469355545526109216", "price": "0.81", "size": "0", "side": "SELL", "hash": "f4fa5a6c4ea85da64bdb29870151825c24b4b334", "best_bid": "0.06", "best_ask": "0.8"}], "timestamp": "1769384465258", "event_type": "price_change"}}
{"_local_timestamp": "2026-01-25T23:41:06.592106+00:00", "data": {"market": "0xbc2006687eb6ab0081379a56ada7381b6b3b865ffb574e08a7a3e859a7434b7c", "price_changes": [{"asset_id": "63583217354653742103033975957525643306323589776872901149499294038892138077829", "price": "0.19", "size": "66.66", "side": "BUY", "hash": "0be8e85749bda7185cdc7561b7920f76a11751b1", "best_bid": "0.19", "best_ask": "0.94"}, {"asset_id": "68019269343969765341171874525368745169647714153650196737363227760382767964183", "price": "0.81", "size": "66.66", "side": "SELL", "hash": "8b9971469bf1c520fca2aa14026ad0f25754013b", "best_bid": "0.06", "best_ask": "0.81"}], "timestamp": "1769384466520", "event_type": "price_change"}}
{"_local_timestamp": "2026-01-25T23:41:06.673988+00:00", "data": {"market": "0x57907f477d6295cee2b169859b8606644a4d71d0ec6128372b0c9db9913bcd93", "price_changes": [{"asset_id": "38193498706916382331735817582375344137760715410898207845843641476007403461254", "price": "0.21", "size": "66.66", "side": "BUY", "hash": "c81031de1f73cdd8040e54b98c8ea9ec63a855ea", "best_bid": "0.21", "best_ask": "0.94"}, {"asset_id": "101193316906353661596667021454376162656427957280783485056984469355545526109216", "price": "0.79", "size": "66.66", "side": "SELL", "hash": "34742719933b7caf1e690819b2c4911f1006d1b1", "best_bid": "0.06", "best_ask": "0.79"}], "timestamp": "1769384466608", "event_type": "price_change"}}
{"_local_timestamp": "2026-01-25T23:41:06.944762+00:00", "data": {"market": "0xbb5745a78307d6434215753ec4aed95ec3eb3272f92d32d9832754c04c35f08c", "price_changes": [{"asset_id": "24067803523094369652482608318472371337596458082523423062803274427732809099156", "price": "0.21", "size": "66.66", "side": "BUY", "hash": "0afc89d83e5600cfabca003ebbe457fede8f4a99", "best_bid": "0.21", "best_ask": "0.94"}, {"asset_id": "51786810938584713265589072330718248037720929244183431852537036646815091958237", "price": "0.79", "size": "66.66", "side": "SELL", "hash": "8d793bed49e3b3fa746a0ea1d58d8480f61ea1e4", "best_bid": "0.06", "best_ask": "0.79"}], "timestamp": "1769384466747", "event_type": "price_change"}}
{"_local_timestamp": "2026-01-25T23:41:06.945930+00:00", "data": {"market": "0xe2cfb3b48c35d28faaecf28e296d6f672188c90cfdf08c07a6e6a824e1bc7539", "price_changes": [{"asset_id": "114856070891915179881203224601555438788948422405426418879020114548029044261628", "price": "0.21", "size": "66.66", "side": "BUY", "hash": "dc8ff9d6aefb6d15bf450cfcfca548d3a0e7c7dc", "best_bid": "0.21", "best_ask": "0.94"}, {"asset_id": "40768718081882153418959955243994854330146531826408459920832464833723436741424", "price": "0.79", "size": "66.66", "side": "SELL", "hash": "710834c80c0f311f2fcccc6724862ace246ad418", "best_bid": "0.06", "best_ask": "0.79"}], "timestamp": "1769384466775", "event_type": "price_change"}}
{"_local_timestamp": "2026-01-25T23:41:11.446040+00:00", "data": {"market": "0xbc2006687eb6ab0081379a56ada7381b6b3b865ffb574e08a7a3e859a7434b7c", "price_changes": [{"asset_id": "63583217354653742103033975957525643306323589776872901149499294038892138077829", "price": "0.17", "size": "0", "side": "BUY", "hash": "c009169fe5dd173be774f0fbe79a6c1d3491974b", "best_bid": "0.19", "best_ask": "0.94"}, {"asset_id": "68019269343969765341171874525368745169647714153650196737363227760382767964183", "price": "0.83", "size": "0", "side": "SELL", "hash": "b55540eadb2f1f77156b8ea29360ec8322284be0", "best_bid": "0.06", "best_ask": "0.81"}], "timestamp": "1769384471334", "event_type": "price_change"}}
{"_local_timestamp": "2026-01-25T23:41:11.458754+00:00", "data": {"market": "0xbc2006687eb6ab0081379a56ada7381b6b3b865ffb574e08a7a3e859a7434b7c", "price_changes": [{"asset_id": "63583217354653742103033975957525643306323589776872901149499294038892138077829", "price": "0.15", "size": "20", "side": "BUY", "hash": "ad8dee0480c7bebcf7d825a3ccef637502a8044f", "best_bid": "0.19", "best_ask": "0.94"}, {"asset_id": "68019269343969765341171874525368745169647714153650196737363227760382767964183", "price": "0.85", "size": "20", "side": "SELL", "hash": "205fd542b1dce0974d7d6584cb8f167fa25f8dda", "best_bid": "0.06", "best_ask": "0.81"}], "timestamp": "1769384471367", "event_type": "price_change"}}
{"_local_timestamp": "2026-01-25T23:41:23.301147+00:00", "data": {"market": "0xbb5745a78307d6434215753ec4aed95ec3eb3272f92d32d9832754c04c35f08c", "price_changes": [{"asset_id": "24067803523094369652482608318472371337596458082523423062803274427732809099156", "price": "0.2", "size": "0", "side": "BUY", "hash": "cf2da1e65be4befee814607e9d039ef6665d9d8c", "best_bid": "0.21", "best_ask": "0.94"}, {"asset_id": "51786810938584713265589072330718248037720929244183431852537036646815091958237", "price": "0.8", "size": "0", "side": "SELL", "hash": "90fc01ac3a10e5b5b5cef4ba1017caca134a0536", "best_bid": "0.06", "best_ask": "0.79"}], "timestamp": "1769384483197", "event_type": "price_change"}}
{"_local_timestamp": "2026-01-25T23:41:23.303193+00:00", "data": {"market": "0xbc2006687eb6ab0081379a56ada7381b6b3b865ffb574e08a7a3e859a7434b7c", "price_changes": [{"asset_id": "63583217354653742103033975957525643306323589776872901149499294038892138077829", "price": "0.18", "size": "0", "side": "BUY", "hash": "b3cc8ddd4d50aaa19d1a07932a0b7d9cb65ef7a3", "best_bid": "0.19", "best_ask": "0.94"}, {"asset_id": "68019269343969765341171874525368745169647714153650196737363227760382767964183", "price": "0.82", "size": "0", "side": "SELL", "hash": "43eee0919654dab39d01fcdacf6a21b5110528e2", "best_bid": "0.06", "best_ask": "0.81"}], "timestamp": "1769384483197", "event_type": "price_change"}}
{"_local_timestamp": "2026-01-25T23:41:23.303783+00:00", "data": {"market": "0xe2cfb3b48c35d28faaecf28e296d6f672188c90cfdf08c07a6e6a824e1bc7539", "price_changes": [{"asset_id": "114856070891915179881203224601555438788948422405426418879020114548029044261628", "price": "0.2", "size": "0", "side": "BUY", "hash": "e4a7b923f259a6863feac980ebb42c446f1ab0c6", "best_bid": "0.21", "best_ask": "0.94"}, {"asset_id": "40768718081882153418959955243994854330146531826408459920832464833723436741424", "price": "0.8", "size": "0", "side": "SELL", "hash": "13ca8bf47707bbcb0e4bf7a11ff7f4fba4d78fd1", "best_bid": "0.06", "best_ask": "0.79"}], "timestamp": "1769384483197", "event_type": "price_change"}}
{"_local_timestamp": "2026-01-25T23:41:23.304251+00:00", "data": {"market": "0x57907f477d6295cee2b169859b8606644a4d71d0ec6128372b0c9db9913bcd93", "price_changes": [{"asset_id": "38193498706916382331735817582375344137760715410898207845843641476007403461254", "price": "0.2", "size": "0", "side": "BUY", "hash": "dcf277ed8c9a7278362289cc0f6d8f95eab4984c", "best_bid": "0.21", "best_ask": "0.94"}, {"asset_id": "101193316906353661596667021454376162656427957280783485056984469355545526109216", "price": "0.8", "size": "0", "side": "SELL", "hash": "91afdd51fb3dde71d1313ed890ee9dff1c148fb5", "best_bid": "0.06", "best_ask": "0.79"}], "timestamp": "1769384483197", "event_type": "price_change"}}
{"_local_timestamp": "2026-01-25T23:42:52.060810+00:00", "data": {"market": "0x521ab5d3c24af074bb5496a9e8e83d85b520c08e6333ab21b617f122a564615a", "price_changes": [{"asset_id": "86263889844673834773808760288478764459004352959184601356498789028474786900980", "price": "0.24", "size": "0", "side": "BUY", "hash": "27fbad6e9112598506b9de72393f6d48703feafb", "best_bid": "0.93", "best_ask": "0.99"}, {"asset_id": "7528388713228609060142081103391244635491832722831643514084973789304836742854", "price": "0.76", "size": "0", "side": "SELL", "hash": "0e15cb85098d0d4cc5f014c75720f8a4ac67f484", "best_bid": "0.01", "best_ask": "0.07"}], "timestamp": "1769384571872", "event_type": "price_change"}}
{"_local_timestamp": "2026-01-25T23:42:52.114428+00:00", "data": {"market": "0x521ab5d3c24af074bb5496a9e8e83d85b520c08e6333ab21b617f122a564615a", "price_changes": [{"asset_id": "86263889844673834773808760288478764459004352959184601356498789028474786900980", "price": "0.24", "size": "8", "side": "BUY", "hash": "f15e5763070816aa9fae920adb9951688f98c8e0", "best_bid": "0.93", "best_ask": "0.99"}, {"asset_id": "7528388713228609060142081103391244635491832722831643514084973789304836742854", "price": "0.76", "size": "8", "side": "SELL", "hash": "eb0cf24495a071f565ad90410c6ff9d0f7d9e7f3", "best_bid": "0.01", "best_ask": "0.07"}], "timestamp": "1769384571924", "event_type": "price_change"}}
{"_local_timestamp": "2026-01-25T23:43:22.659898+00:00", "data": {"market": "0xbc2006687eb6ab0081379a56ada7381b6b3b865ffb574e08a7a3e859a7434b7c", "price_changes": [{"asset_id": "63583217354653742103033975957525643306323589776872901149499294038892138077829", "price": "0.19", "size": "105.66", "side": "BUY", "hash": "11b7775ab2893803f99fb234936d77eb42255892", "best_bid": "0.19", "best_ask": "0.94"}, {"asset_id": "68019269343969765341171874525368745169647714153650196737363227760382767964183", "price": "0.81", "size": "105.66", "side": "SELL", "hash": "07643917198882f9ed36169d9b281b06a9329e78", "best_bid": "0.06", "best_ask": "0.81"}], "timestamp": "1769384602591", "event_type": "price_change"}}
{"_local_timestamp": "2026-01-25T23:43:22.660721+00:00", "data": {"market": "0xbb5745a78307d6434215753ec4aed95ec3eb3272f92d32d9832754c04c35f08c", "price_changes": [{"asset_id": "24067803523094369652482608318472371337596458082523423062803274427732809099156", "price": "0.16", "size": "79", "side": "BUY", "hash": "d3067f5482bdcd9174c970448634c596f2e6bf80", "best_bid": "0.21", "best_ask": "0.94"}, {"asset_id": "51786810938584713265589072330718248037720929244183431852537036646815091958237", "price": "0.84", "size": "79", "side": "SELL", "hash": "59bdef7be3849482633892849169af2abb4dfe96", "best_bid": "0.06", "best_ask": "0.79"}], "timestamp": "1769384602591", "event_type": "price_change"}}
{"_local_timestamp": "2026-01-25T23:43:22.661203+00:00", "data": {"market": "0xbc2006687eb6ab0081379a56ada7381b6b3b865ffb574e08a7a3e859a7434b7c", "price_changes": [{"asset_id": "63583217354653742103033975957525643306323589776872901149499294038892138077829", "price": "0.2", "size": "79", "side": "BUY", "hash": "915cc34fae91ec3c7c5fd1f0ff4ea26af9156fe3", "best_bid": "0.2", "best_ask": "0.94"}, {"asset_id": "68019269343969765341171874525368745169647714153650196737363227760382767964183", "price": "0.8", "size": "79", "side": "SELL", "hash": "f9029177e04b9b41042a416b08c5824174708243", "best_bid": "0.06", "best_ask": "0.8"}], "timestamp": "1769384602591", "event_type": "price_change"}}
{"_local_timestamp": "2026-01-25T23:43:22.661627+00:00", "data": {"market": "0x57907f477d6295cee2b169859b8606644a4d71d0ec6128372b0c9db9913bcd93", "price_changes": [{"asset_id": "38193498706916382331735817582375344137760715410898207845843641476007403461254", "price": "0.22", "size": "79", "side": "BUY", "hash": "940b25187f543a1a52b8eb7aa6ccd6c24315de6a", "best_bid": "0.22", "best_ask": "0.94"}, {"asset_id": "101193316906353661596667021454376162656427957280783485056984469355545526109216", "price": "0.78", "size": "79", "side": "SELL", "hash": "83955aa37e06bad1e6cc941b9b73e724167617b7", "best_bid": "0.06", "best_ask": "0.78"}], "timestamp": "1769384602591", "event_type": "price_change"}}
{"_local_timestamp": "2026-01-25T23:43:22.662007+00:00", "data": {"market": "0xbb5745a78307d6434215753ec4aed95ec3eb3272f92d32d9832754c04c35f08c", "price_changes": [{"asset_id": "24067803523094369652482608318472371337596458082523423062803274427732809099156", "price": "0.22", "size": "79", "side": "BUY", "hash": "29af494fda3fcb133d91fff90d34ed46511e89da", "best_bid": "0.22", "best_ask": "0.94"}, {"asset_id": "51786810938584713265589072330718248037720929244183431852537036646815091958237", "price": "0.78", "size": "79", "side": "SELL", "hash": "a571766fb21a99cc534f21bdfa6daca3ca54cb36", "best_bid": "0.06", "best_ask": "0.78"}], "timestamp": "1769384602592", "event_type": "price_change"}}
{"_local_timestamp": "2026-01-25T23:43:22.662398+00:00", "data": {"market": "0xe2cfb3b48c35d28faaecf28e296d6f672188c90cfdf08c07a6e6a824e1bc7539", "price_changes": [{"asset_id": "114856070891915179881203224601555438788948422405426418879020114548029044261628", "price": "0.22", "size": "79", "side": "BUY", "hash": "36081410cf3a2c1c32d613538dd96bfce2989071", "best_bid": "0.22", "best_ask": "0.94"}, {"asset_id": "40768718081882153418959955243994854330146531826408459920832464833723436741424", "price": "0.78", "size": "79", "side": "SELL", "hash": "ce48701f0e49d46df48784de929dc244ce248b39", "best_bid": "0.06", "best_ask": "0.78"}], "timestamp": "1769384602591", "event_type": "price_change"}}
{"_local_timestamp": "2026-01-25T23:43:22.662887+00:00", "data": {"market": "0x57907f477d6295cee2b169859b8606644a4d71d0ec6128372b0c9db9913bcd93", "price_changes": [{"asset_id": "38193498706916382331735817582375344137760715410898207845843641476007403461254", "price": "0.17", "size": "39", "side": "BUY", "hash": "6d4827c09b38dca8086730a878ed80f06fd448a8", "best_bid": "0.22", "best_ask": "0.94"}, {"asset_id": "101193316906353661596667021454376162656427957280783485056984469355545526109216", "price": "0.83", "size": "39", "side": "SELL", "hash": "4cecf2256c0c21628353e531d1b34a283e53bea7", "best_bid": "0.06", "best_ask": "0.78"}], "timestamp": "1769384602592", "event_type": "price_change"}}
{"_local_timestamp": "2026-01-25T23:43:22.663315+00:00", "data": {"market": "0xe2cfb3b48c35d28faaecf28e296d6f672188c90cfdf08c07a6e6a824e1bc7539", "price_changes": [{"asset_id": "114856070891915179881203224601555438788948422405426418879020114548029044261628", "price": "0.18", "size": "39", "side": "BUY", "hash": "0df95670fb567e7abbe9feaca9773a3b70c737e1", "best_bid": "0.22", "best_ask": "0.94"}, {"asset_id": "40768718081882153418959955243994854330146531826408459920832464833723436741424", "price": "0.82", "size": "39", "side": "SELL", "hash": "4d39d89aa8afa11d39e8ff1c875ea730d77a8a0d", "best_bid": "0.06", "best_ask": "0.78"}], "timestamp": "1769384602592", "event_type": "price_change"}}
{"_local_timestamp": "2026-01-25T23:43:23.927595+00:00", "data": {"market": "0xbb5745a78307d6434215753ec4aed95ec3eb3272f92d32d9832754c04c35f08c", "price_changes": [{"asset_id": "24067803523094369652482608318472371337596458082523423062803274427732809099156", "price": "0.15", "size": "0", "side": "BUY", "hash": "fda814a85246f3551e837ebda4065127e6f11ded", "best_bid": "0.22", "best_ask": "0.94"}, {"asset_id": "51786810938584713265589072330718248037720929244183431852537036646815091958237", "price": "0.85", "size": "0", "side": "SELL", "hash": "7eb72780b0d28e7b6f4519950d07ca7ce365c2d8", "best_bid": "0.06", "best_ask": "0.78"}], "timestamp": "1769384603864", "event_type": "price_change"}}
{"_local_timestamp": "2026-01-25T23:43:23.928204+00:00", "data": {"market": "0x57907f477d6295cee2b169859b8606644a4d71d0ec6128372b0c9db9913bcd93", "price_changes": [{"asset_id": "38193498706916382331735817582375344137760715410898207845843641476007403461254", "price": "0.16", "size": "0", "side": "BUY", "hash": "78db35b0e08ed42d2fd3cd667785dd2b48e1762f", "best_bid": "0.22", "best_ask": "0.94"}, {"asset_id": "101193316906353661596667021454376162656427957280783485056984469355545526109216", "price": "0.84", "size": "0", "side": "SELL", "hash": "c3d34c43573000db184703ea1aab3392307b82cf", "best_bid": "0.06", "best_ask": "0.78"}], "timestamp": "1769384603864", "event_type": "price_change"}}
{"_local_timestamp": "2026-01-25T23:43:23.952378+00:00", "data": {"market": "0xbb5745a78307d6434215753ec4aed95ec3eb3272f92d32d9832754c04c35f08c", "price_changes": [{"asset_id": "24067803523094369652482608318472371337596458082523423062803274427732809099156", "price": "0.17", "size": "20", "side": "BUY", "hash": "cf78f8d98e0c83a560e5c94dd42e8685d6e8359b", "best_bid": "0.22", "best_ask": "0.94"}, {"asset_id": "51786810938584713265589072330718248037720929244183431852537036646815091958237", "price": "0.83", "size": "20", "side": "SELL", "hash": "25b41e5a4ad967abf273c019646f7f0815daeb2f", "best_bid": "0.06", "best_ask": "0.78"}], "timestamp": "1769384603890", "event_type": "price_change"}}
{"_local_timestamp": "2026-01-25T23:43:23.952901+00:00", "data": {"market": "0x57907f477d6295cee2b169859b8606644a4d71d0ec6128372b0c9db9913bcd93", "price_changes": [{"asset_id": "38193498706916382331735817582375344137760715410898207845843641476007403461254", "price": "0.18", "size": "20", "side": "BUY", "hash": "31158b4d0cab811ac618c609ee22ab0ff6a8c5ee", "best_bid": "0.22", "best_ask": "0.94"}, {"asset_id": "101193316906353661596667021454376162656427957280783485056984469355545526109216", "price": "0.82", "size": "20", "side": "SELL", "hash": "41be3aca165bb0599e1c9d37770b85fe771e3e93", "best_bid": "0.06", "best_ask": "0.78"}], "timestamp": "1769384603890", "event_type": "price_change"}}
{"_local_timestamp": "2026-01-25T23:43:36.805137+00:00", "data": {"market": "0x57907f477d6295cee2b169859b8606644a4d71d0ec6128372b0c9db9913bcd93", "price_changes": [{"asset_id": "38193498706916382331735817582375344137760715410898207845843641476007403461254", "price": "0.17", "size": "0", "side": "BUY", "hash": "6d42536550597170a01b21f1f620008fad5b6cab", "best_bid": "0.22", "best_ask": "0.94"}, {"asset_id": "101193316906353661596667021454376162656427957280783485056984469355545526109216", "price": "0.83", "size": "0", "side": "SELL", "hash": "6fb0eda156cfbb8bf49c1af615e49ec9f3a9afb9", "best_bid": "0.06", "best_ask": "0.78"}], "timestamp": "1769384616740", "event_type": "price_change"}}
{"_local_timestamp": "2026-01-25T23:43:36.812766+00:00", "data": {"market": "0xbc2006687eb6ab0081379a56ada7381b6b3b865ffb574e08a7a3e859a7434b7c", "price_changes": [{"asset_id": "63583217354653742103033975957525643306323589776872901149499294038892138077829", "price": "0.2", "size": "0", "side": "BUY", "hash": "39e4bc2d7f6220cda606cacfe6148bbd9c5f1a91", "best_bid": "0.19", "best_ask": "0.94"}, {"asset_id": "68019269343969765341171874525368745169647714153650196737363227760382767964183", "price": "0.8", "size": "0", "side": "SELL", "hash": "7cc3a4d569349183a2b1b5d87ecc48df1ae4dbbd", "best_bid": "0.06", "best_ask": "0.81"}], "timestamp": "1769384616740", "event_type": "price_change"}}
{"_local_timestamp": "2026-01-25T23:43:36.820674+00:00", "data": {"market": "0xbb5745a78307d6434215753ec4aed95ec3eb3272f92d32d9832754c04c35f08c", "price_changes": [{"asset_id": "24067803523094369652482608318472371337596458082523423062803274427732809099156", "price": "0.16", "size": "0", "side": "BUY", "hash": "6792371bacaa9c78da864a9c92bbabdde497ee74", "best_bid": "0.22", "best_ask": "0.94"}, {"asset_id": "51786810938584713265589072330718248037720929244183431852537036646815091958237", "price": "0.84", "size": "0", "side": "SELL", "hash": "c49ac9774a72eff4bf2556a96c784b6d3db1f3bc", "best_bid": "0.06", "best_ask": "0.78"}], "timestamp": "1769384616741", "event_type": "price_change"}}
{"_local_timestamp": "2026-01-25T23:43:39.663787+00:00", "data": {"market": "0x57907f477d6295cee2b169859b8606644a4d71d0ec6128372b0c9db9913bcd93", "price_changes": [{"asset_id": "38193498706916382331735817582375344137760715410898207845843641476007403461254", "price": "0.18", "size": "0", "side": "BUY", "hash": "3f03549d026274ba2cc9ba950cf2f6712413784e", "best_bid": "0.22", "best_ask": "0.94"}, {"asset_id": "101193316906353661596667021454376162656427957280783485056984469355545526109216", "price": "0.82", "size": "0", "side": "SELL", "hash": "f39c4018704f45e289d860c810aba646476438ac", "best_bid": "0.06", "best_ask": "0.78"}], "timestamp": "1769384619591", "event_type": "price_change"}}
{"_local_timestamp": "2026-01-25T23:43:39.664269+00:00", "data": {"market": "0xbb5745a78307d6434215753ec4aed95ec3eb3272f92d32d9832754c04c35f08c", "price_changes": [{"asset_id": "24067803523094369652482608318472371337596458082523423062803274427732809099156", "price": "0.17", "size": "0", "side": "BUY", "hash": "98a4ee6755305606002336ef8b0a050b2af280d5", "best_bid": "0.22", "best_ask": "0.94"}, {"asset_id": "51786810938584713265589072330718248037720929244183431852537036646815091958237", "price": "0.83", "size": "0", "side": "SELL", "hash": "5795e58c2e040c249b0aba9d5621cf20caf0b65c", "best_bid": "0.06", "best_ask": "0.78"}], "timestamp": "1769384619591", "event_type": "price_change"}}
{"_local_timestamp": "2026-01-25T23:43:39.689735+00:00", "data": {"market": "0x57907f477d6295cee2b169859b8606644a4d71d0ec6128372b0c9db9913bcd93", "price_changes": [{"asset_id": "38193498706916382331735817582375344137760715410898207845843641476007403461254", "price": "0.16", "size": "20", "side": "BUY", "hash": "83237beb1fbc7b3a14f71da1d0fb8eae248e5971", "best_bid": "0.22", "best_ask": "0.94"}, {"asset_id": "101193316906353661596667021454376162656427957280783485056984469355545526109216", "price": "0.84", "size": "20", "side": "SELL", "hash": "9378a4ead08fe1db7111c1370409534fc58f165d", "best_bid": "0.06", "best_ask": "0.78"}], "timestamp": "1769384619620", "event_type": "price_change"}}
{"_local_timestamp": "2026-01-25T23:43:39.690215+00:00", "data": {"market": "0xbb5745a78307d6434215753ec4aed95ec3eb3272f92d32d9832754c04c35f08c", "price_changes": [{"asset_id": "24067803523094369652482608318472371337596458082523423062803274427732809099156", "price": "0.15", "size": "20", "side": "BUY", "hash": "0e506aab7010b6002352cad64ebbe2283402c271", "best_bid": "0.22", "best_ask": "0.94"}, {"asset_id": "51786810938584713265589072330718248037720929244183431852537036646815091958237", "price": "0.85", "size": "20", "side": "SELL", "hash": "ced2548f5ea790b57567643ccf0f8a07050b97b2", "best_bid": "0.06", "best_ask": "0.78"}], "timestamp": "1769384619620", "event_type": "price_change"}}
{"_local_timestamp": "2026-01-25T23:43:40.216881+00:00", "data": {"market": "0xe2cfb3b48c35d28faaecf28e296d6f672188c90cfdf08c07a6e6a824e1bc7539", "price_changes": [{"asset_id": "114856070891915179881203224601555438788948422405426418879020114548029044261628", "price": "0.18", "size": "0", "side": "BUY", "hash": "3029c783b15a6c3c231280892b779e5f59f47307", "best_bid": "0.22", "best_ask": "0.94"}, {"asset_id": "40768718081882153418959955243994854330146531826408459920832464833723436741424", "price": "0.82", "size": "0", "side": "SELL", "hash": "1698fbb62313f9487c57e887d451f6608311e174", "best_bid": "0.06", "best_ask": "0.78"}], "timestamp": "1769384620136", "event_type": "price_change"}}
{"_local_timestamp": "2026-01-25T23:43:44.301551+00:00", "data": {"market": "0xbb5745a78307d6434215753ec4aed95ec3eb3272f92d32d9832754c04c35f08c", "price_changes": [{"asset_id": "24067803523094369652482608318472371337596458082523423062803274427732809099156", "price": "0.21", "size": "0", "side": "BUY", "hash": "7bd326c3daba6b313c6cb58f5ed5c7fa05e44239", "best_bid": "0.22", "best_ask": "0.94"}, {"asset_id": "51786810938584713265589072330718248037720929244183431852537036646815091958237", "price": "0.79", "size": "0", "side": "SELL", "hash": "f754109f8ca338cb27bd28b73cdd946d36cf3617", "best_bid": "0.06", "best_ask": "0.78"}], "timestamp": "1769384624236", "event_type": "price_change"}}
{"_local_timestamp": "2026-01-25T23:43:44.310374+00:00", "data": {"market": "0x57907f477d6295cee2b169859b8606644a4d71d0ec6128372b0c9db9913bcd93", "price_changes": [{"asset_id": "38193498706916382331735817582375344137760715410898207845843641476007403461254", "price": "0.21", "size": "0", "side": "BUY", "hash": "6bc79f11a1a98ecabe25565482870621625edbbe", "best_bid": "0.22", "best_ask": "0.94"}, {"asset_id": "101193316906353661596667021454376162656427957280783485056984469355545526109216", "price": "0.79", "size": "0", "side": "SELL", "hash": "12737c1f6c54db23bc4a5ca2a2e18a38c57bfcc5", "best_bid": "0.06", "best_ask": "0.78"}], "timestamp": "1769384624237", "event_type": "price_change"}}
{"_local_timestamp": "2026-01-25T23:43:44.310874+00:00", "data": {"market": "0xe2cfb3b48c35d28faaecf28e296d6f672188c90cfdf08c07a6e6a824e1bc7539", "price_changes": [{"asset_id": "114856070891915179881203224601555438788948422405426418879020114548029044261628", "price": "0.21", "size": "0", "side": "BUY", "hash": "93570e1e2d7bc90e99bc10ca50b28ddf744976fb", "best_bid": "0.22", "best_ask": "0.94"}, {"asset_id": "40768718081882153418959955243994854330146531826408459920832464833723436741424", "price": "0.79", "size": "0", "side": "SELL", "hash": "e88d626e21ab5012734755e02751eca6cd85a219", "best_bid": "0.06", "best_ask": "0.78"}], "timestamp": "1769384624237", "event_type": "price_change"}}
{"_local_timestamp": "2026-01-25T23:43:45.967228+00:00", "data": {"market": "0xbb5745a78307d6434215753ec4aed95ec3eb3272f92d32d9832754c04c35f08c", "price_changes": [{"asset_id": "24067803523094369652482608318472371337596458082523423062803274427732809099156", "price": "0.23", "size": "66.66", "side": "BUY", "hash": "97c898b840b960113a7dfd373c6f65a2a974b1fc", "best_bid": "0.23", "best_ask": "0.94"}, {"asset_id": "51786810938584713265589072330718248037720929244183431852537036646815091958237", "price": "0.77", "size": "66.66", "side": "SELL", "hash": "6ab538023e5537dacb8858f831075b661b032816", "best_bid": "0.06", "best_ask": "0.77"}], "timestamp": "1769384625899", "event_type": "price_change"}}
{"_local_timestamp": "2026-01-25T23:43:45.988805+00:00", "data": {"market": "0x57907f477d6295cee2b169859b8606644a4d71d0ec6128372b0c9db9913bcd93", "price_changes": [{"asset_id": "38193498706916382331735817582375344137760715410898207845843641476007403461254", "price": "0.23", "size": "66.66", "side": "BUY", "hash": "6812416d2664711b4a795f0e9f98cd4a29758984", "best_bid": "0.23", "best_ask": "0.94"}, {"asset_id": "101193316906353661596667021454376162656427957280783485056984469355545526109216", "price": "0.77", "size": "66.66", "side": "SELL", "hash": "842ca3e186f252fe1da428b244c8e8685c65106a", "best_bid": "0.06", "best_ask": "0.77"}], "timestamp": "1769384625922", "event_type": "price_change"}}
{"_local_timestamp": "2026-01-25T23:43:46.043638+00:00", "data": {"market": "0xe2cfb3b48c35d28faaecf28e296d6f672188c90cfdf08c07a6e6a824e1bc7539", "price_changes": [{"asset_id": "114856070891915179881203224601555438788948422405426418879020114548029044261628", "price": "0.23", "size": "66.66", "side": "BUY", "hash": "20b9961bcaf6ac06fc5bf04ab556959dd8d9916c", "best_bid": "0.23", "best_ask": "0.94"}, {"asset_id": "40768718081882153418959955243994854330146531826408459920832464833723436741424", "price": "0.77", "size": "66.66", "side": "SELL", "hash": "bb989f25201342cfb870aeb52b363237a081f924", "best_bid": "0.06", "best_ask": "0.77"}], "timestamp": "1769384625968", "event_type": "price_change"}}
{"_local_timestamp": "2026-01-25T23:44:07.858128+00:00", "data": {"market": "0xbb5745a78307d6434215753ec4aed95ec3eb3272f92d32d9832754c04c35f08c", "price_changes": [{"asset_id": "24067803523094369652482608318472371337596458082523423062803274427732809099156", "price": "0.22", "size": "0", "side": "BUY", "hash": "dfe432979e6d53cdec6b723df2dd6ede4c74a07e", "best_bid": "0.23", "best_ask": "0.94"}, {"asset_id": "51786810938584713265589072330718248037720929244183431852537036646815091958237", "price": "0.78", "size": "0", "side": "SELL", "hash": "4c22dd309fd23805acd1953ce3ac37ac915b6c95", "best_bid": "0.06", "best_ask": "0.77"}], "timestamp": "1769384647788", "event_type": "price_change"}}
{"_local_timestamp": "2026-01-25T23:44:07.858642+00:00", "data": {"market": "0x57907f477d6295cee2b169859b8606644a4d71d0ec6128372b0c9db9913bcd93", "price_changes": [{"asset_id": "38193498706916382331735817582375344137760715410898207845843641476007403461254", "price": "0.22", "size": "0", "side": "BUY", "hash": "3b067cb1947a18aa6a27d5e41b5095fb0947ab80", "best_bid": "0.23", "best_ask": "0.94"}, {"asset_id": "101193316906353661596667021454376162656427957280783485056984469355545526109216", "price": "0.78", "size": "0", "side": "SELL", "hash": "3b0241fe1994ca883fa5838f6138743d30a70fa2", "best_bid": "0.06", "best_ask": "0.77"}], "timestamp": "1769384647789", "event_type": "price_change"}}
{"_local_timestamp": "2026-01-25T23:44:07.859133+00:00", "data": {"market": "0xe2cfb3b48c35d28faaecf28e296d6f672188c90cfdf08c07a6e6a824e1bc7539", "price_changes": [{"asset_id": "114856070891915179881203224601555438788948422405426418879020114548029044261628", "price": "0.22", "size": "0", "side": "BUY", "hash": "0c4457e80e5ff403d5c3e653c70e06791192ec85", "best_bid": "0.23", "best_ask": "0.94"}, {"asset_id": "40768718081882153418959955243994854330146531826408459920832464833723436741424", "price": "0.78", "size": "0", "side": "SELL", "hash": "77295702d60d350a0dcbeaeb509759c7678dc88e", "best_bid": "0.06", "best_ask": "0.77"}], "timestamp": "1769384647788", "event_type": "price_change"}}
{"_local_timestamp": "2026-01-25T23:45:02.526316+00:00", "data": {"market": "0xe2cfb3b48c35d28faaecf28e296d6f672188c90cfdf08c07a6e6a824e1bc7539", "price_changes": [{"asset_id": "114856070891915179881203224601555438788948422405426418879020114548029044261628", "price": "0.03", "size": "5.43", "side": "BUY", "hash": "86dbf05e939580cceab5585d31b45a126202a8d6", "best_bid": "0.23", "best_ask": "0.94"}, {"asset_id": "40768718081882153418959955243994854330146531826408459920832464833723436741424", "price": "0.97", "size": "5.43", "side": "SELL", "hash": "e95fec70c92b3ad14cf3ab5c56fa4275c3b4c9c0", "best_bid": "0.06", "best_ask": "0.77"}], "timestamp": "1769384702422", "event_type": "price_change"}}
{"_local_timestamp": "2026-01-25T23:45:02.527236+00:00", "data": {"market": "0xe2cfb3b48c35d28faaecf28e296d6f672188c90cfdf08c07a6e6a824e1bc7539", "price_changes": [{"asset_id": "114856070891915179881203224601555438788948422405426418879020114548029044261628", "price": "0.06", "size": "349.66", "side": "BUY", "hash": "86dbf05e939580cceab5585d31b45a126202a8d6", "best_bid": "0.23", "best_ask": "0.94"}, {"asset_id": "40768718081882153418959955243994854330146531826408459920832464833723436741424", "price": "0.94", "size": "349.66", "side": "SELL", "hash": "e95fec70c92b3ad14cf3ab5c56fa4275c3b4c9c0", "best_bid": "0.06", "best_ask": "0.77"}], "timestamp": "1769384702422", "event_type": "price_change"}}
{"_local_timestamp": "2026-01-25T23:45:03.291137+00:00", "data": {"market": "0xbb5745a78307d6434215753ec4aed95ec3eb3272f92d32d9832754c04c35f08c", "price_changes": [{"asset_id": "24067803523094369652482608318472371337596458082523423062803274427732809099156", "price": "0.02", "size": "1755.47", "side": "BUY", "hash": "d80ce3205c12ad87676276f996f5ce7e44c099a7", "best_bid": "0.23", "best_ask": "0.94"}, {"asset_id": "51786810938584713265589072330718248037720929244183431852537036646815091958237", "price": "0.98", "size": "1755.47", "side": "SELL", "hash": "ec8ee247a946e217eb2bd1166aba4ac46c4621de", "best_bid": "0.06", "best_ask": "0.77"}], "timestamp": "1769384703224", "event_type": "price_change"}}
{"_local_timestamp": "2026-01-25T23:45:03.291605+00:00", "data": {"market": "0xbb5745a78307d6434215753ec4aed95ec3eb3272f92d32d9832754c04c35f08c", "price_changes": [{"asset_id": "24067803523094369652482608318472371337596458082523423062803274427732809099156", "price": "0.06", "size": "355.93", "side": "BUY", "hash": "144679ab84849fe67d9b83e146bac09006b361b7", "best_bid": "0.23", "best_ask": "0.94"}, {"asset_id": "51786810938584713265589072330718248037720929244183431852537036646815091958237", "price": "0.94", "size": "355.93", "side": "SELL", "hash": "804ea76ef12375a0382b49506dd1dc46b34b7a5b", "best_bid": "0.06", "best_ask": "0.77"}], "timestamp": "1769384703225", "event_type": "price_change"}}
{"_local_timestamp": "2026-01-25T23:45:03.292044+00:00", "data": {"market": "0xbb5745a78307d6434215753ec4aed95ec3eb3272f92d32d9832754c04c35f08c", "price_changes": [{"asset_id": "24067803523094369652482608318472371337596458082523423062803274427732809099156", "price": "0.01", "size": "3361.26", "side": "BUY", "hash": "b9a51ca8cc83918424c348e24fd69a6eb4c6375a", "best_bid": "0.23", "best_ask": "0.94"}, {"asset_id": "51786810938584713265589072330718248037720929244183431852537036646815091958237", "price": "0.99", "size": "3361.26", "side": "SELL", "hash": "b01501ab6bebbd7399559011dae4b923a5ad4cf7", "best_bid": "0.06", "best_ask": "0.77"}], "timestamp": "1769384703226", "event_type": "price_change"}}
{"_local_timestamp": "2026-01-25T23:45:03.292416+00:00", "data": {"market": "0xbb5745a78307d6434215753ec4aed95ec3eb3272f92d32d9832754c04c35f08c", "price_changes": [{"asset_id": "24067803523094369652482608318472371337596458082523423062803274427732809099156", "price": "0.03", "size": "10.36", "side": "BUY", "hash": "df7a84214627a5572ba3b9b094bd3a199895ca38", "best_bid": "0.23", "best_ask": "0.94"}, {"asset_id": "51786810938584713265589072330718248037720929244183431852537036646815091958237", "price": "0.97", "size": "10.36", "side": "SELL", "hash": "43031e54d36072ff31e3799066c1b007fd791845", "best_bid": "0.06", "best_ask": "0.77"}], "timestamp": "1769384703228", "event_type": "price_change"}}
{"_local_timestamp": "2026-01-25T23:45:03.299267+00:00", "data": {"market": "0xbb5745a78307d6434215753ec4aed95ec3eb3272f92d32d9832754c04c35f08c", "price_changes": [{"asset_id": "24067803523094369652482608318472371337596458082523423062803274427732809099156", "price": "0.1", "size": "10.9", "side": "BUY", "hash": "3d24fd875194dd8768ec90d0831085944ec11d77", "best_bid": "0.23", "best_ask": "0.94"}, {"asset_id": "51786810938584713265589072330718248037720929244183431852537036646815091958237", "price": "0.9", "size": "10.9", "side": "SELL", "hash": "ba495cefc6d47f2745f3a492e6fc4adc29e725f8", "best_bid": "0.06", "best_ask": "0.77"}], "timestamp": "1769384703229", "event_type": "price_change"}}
{"_local_timestamp": "2026-01-25T23:45:05.928148+00:00", "data": {"market": "0xe2cfb3b48c35d28faaecf28e296d6f672188c90cfdf08c07a6e6a824e1bc7539", "price_changes": [{"asset_id": "114856070891915179881203224601555438788948422405426418879020114548029044261628", "price": "0.05", "size": "340.13", "side": "BUY", "hash": "854235dd9bbea777768ca60b7501cb509054ae9d", "best_bid": "0.23", "best_ask": "0.94"}, {"asset_id": "40768718081882153418959955243994854330146531826408459920832464833723436741424", "price": "0.95", "size": "340.13", "side": "SELL", "hash": "5e34cf3a8e3bc36c20c9e3356c7dc914e0c4ecdd", "best_bid": "0.06", "best_ask": "0.77"}], "timestamp": "1769384705858", "event_type": "price_change"}}
{"_local_timestamp": "2026-01-25T23:45:11.920188+00:00", "data": {"market": "0x57907f477d6295cee2b169859b8606644a4d71d0ec6128372b0c9db9913bcd93", "price_changes": [{"asset_id": "38193498706916382331735817582375344137760715410898207845843641476007403461254", "price": "0.05", "size": "337.4", "side": "BUY", "hash": "c025b7757f6f7d51cb70364b149f8db8cc8c49f7", "best_bid": "0.23", "best_ask": "0.94"}, {"asset_id": "101193316906353661596667021454376162656427957280783485056984469355545526109216", "price": "0.95", "size": "337.4", "side": "SELL", "hash": "718975afd5061e13342d31b45a9e89c4f952ca4a", "best_bid": "0.06", "best_ask": "0.77"}], "timestamp": "1769384711848", "event_type": "price_change"}}
{"_local_timestamp": "2026-01-25T23:45:34.987602+00:00", "data": {"market": "0xbc2006687eb6ab0081379a56ada7381b6b3b865ffb574e08a7a3e859a7434b7c", "price_changes": [{"asset_id": "63583217354653742103033975957525643306323589776872901149499294038892138077829", "price": "0.06", "size": "288.32", "side": "BUY", "hash": "0fa63dc710f76cd6394b6cb115acf531c9b82b43", "best_bid": "0.19", "best_ask": "0.94"}, {"asset_id": "68019269343969765341171874525368745169647714153650196737363227760382767964183", "price": "0.94", "size": "288.32", "side": "SELL", "hash": "8baa0c954e9491625f261feee6b7606d400ab332", "best_bid": "0.06", "best_ask": "0.81"}], "timestamp": "1769384734916", "event_type": "price_change"}}
{"_local_timestamp": "2026-01-25T23:45:35.254731+00:00", "data": {"market": "0xbc2006687eb6ab0081379a56ada7381b6b3b865ffb574e08a7a3e859a7434b7c", "price_changes": [{"asset_id": "63583217354653742103033975957525643306323589776872901149499294038892138077829", "price": "0.08", "size": "266.66", "side": "BUY", "hash": "97065a81b8e6cc22dd738838c936ffc22884a2be", "best_bid": "0.19", "best_ask": "0.94"}, {"asset_id": "68019269343969765341171874525368745169647714153650196737363227760382767964183", "price": "0.92", "size": "266.66", "side": "SELL", "hash": "cb1509228922bc5553a6ff52a61c71c4ebf01518", "best_bid": "0.06", "best_ask": "0.81"}], "timestamp": "1769384735172", "event_type": "price_change"}}
{"_local_timestamp": "2026-01-25T23:46:29.796719+00:00", "data": {"market": "0xe2cfb3b48c35d28faaecf28e296d6f672188c90cfdf08c07a6e6a824e1bc7539", "price_changes": [{"asset_id": "114856070891915179881203224601555438788948422405426418879020114548029044261628", "price": "0.23", "size": "0", "side": "BUY", "hash": "e84c1c9b8185f46499888b445181688514c693cc", "best_bid": "0.17", "best_ask": "0.94"}, {"asset_id": "40768718081882153418959955243994854330146531826408459920832464833723436741424", "price": "0.77", "size": "0", "side": "SELL", "hash": "2f3c124ff3b87f4dbf229e7fa46151894e27e507", "best_bid": "0.06", "best_ask": "0.83"}], "timestamp": "1769384789679", "event_type": "price_change"}}
{"_local_timestamp": "2026-01-25T23:46:29.797399+00:00", "data": {"market": "0xbb5745a78307d6434215753ec4aed95ec3eb3272f92d32d9832754c04c35f08c", "price_changes": [{"asset_id": "24067803523094369652482608318472371337596458082523423062803274427732809099156", "price": "0.23", "size": "0", "side": "BUY", "hash": "b32dba3c1ffcf8de52286e944ae649f8ec5389ca", "best_bid": "0.15", "best_ask": "0.94"}, {"asset_id": "51786810938584713265589072330718248037720929244183431852537036646815091958237", "price": "0.77", "size": "0", "side": "SELL", "hash": "215aaf12d3c8e4be2e40fe1ec8060d7c54c1ae7e", "best_bid": "0.06", "best_ask": "0.85"}], "timestamp": "1769384789679", "event_type": "price_change"}}
{"_local_timestamp": "2026-01-25T23:46:29.797777+00:00", "data": {"market": "0x57907f477d6295cee2b169859b8606644a4d71d0ec6128372b0c9db9913bcd93", "price_changes": [{"asset_id": "38193498706916382331735817582375344137760715410898207845843641476007403461254", "price": "0.23", "size": "0", "side": "BUY", "hash": "68c55c3a7e4ca57f4a96bc98be23b9672d09b516", "best_bid": "0.16", "best_ask": "0.94"}, {"asset_id": "101193316906353661596667021454376162656427957280783485056984469355545526109216", "price": "0.77", "size": "0", "side": "SELL", "hash": "daefa289a0b66706dc660f5f955f6f5107109bda", "best_bid": "0.06", "best_ask": "0.84"}], "timestamp": "1769384789679", "event_type": "price_change"}}
{"_local_timestamp": "2026-01-25T23:46:30.982748+00:00", "data": {"market": "0x57907f477d6295cee2b169859b8606644a4d71d0ec6128372b0c9db9913bcd93", "price_changes": [{"asset_id": "38193498706916382331735817582375344137760715410898207845843641476007403461254", "price": "0.17", "size": "66.66", "side": "BUY", "hash": "2b61bc8213e98e90f543639c634a594249d787d7", "best_bid": "0.17", "best_ask": "0.94"}, {"asset_id": "101193316906353661596667021454376162656427957280783485056984469355545526109216", "price": "0.83", "size": "66.66", "side": "SELL", "hash": "14ba806cd61898175de6d9bfc6598f970c4fa813", "best_bid": "0.06", "best_ask": "0.83"}], "timestamp": "1769384790820", "event_type": "price_change"}}
{"_local_timestamp": "2026-01-25T23:46:31.051840+00:00", "data": {"market": "0xe2cfb3b48c35d28faaecf28e296d6f672188c90cfdf08c07a6e6a824e1bc7539", "price_changes": [{"asset_id": "114856070891915179881203224601555438788948422405426418879020114548029044261628", "price": "0.18", "size": "66.66", "side": "BUY", "hash": "3befaa8fcc4f58196918b0b5c85f142a502b436e", "best_bid": "0.18", "best_ask": "0.94"}, {"asset_id": "40768718081882153418959955243994854330146531826408459920832464833723436741424", "price": "0.82", "size": "66.66", "side": "SELL", "hash": "e6508af5e1a2fbf0c72aa834c0df852b61d77511", "best_bid": "0.06", "best_ask": "0.82"}], "timestamp": "1769384790897", "event_type": "price_change"}}
{"_local_timestamp": "2026-01-25T23:46:31.063506+00:00", "data": {"market": "0xbb5745a78307d6434215753ec4aed95ec3eb3272f92d32d9832754c04c35f08c", "price_changes": [{"asset_id": "24067803523094369652482608318472371337596458082523423062803274427732809099156", "price": "0.16", "size": "66.66", "side": "BUY", "hash": "574fe0cf4d44b2f72a518bbd2d9593a0517bc130", "best_bid": "0.16", "best_ask": "0.94"}, {"asset_id": "51786810938584713265589072330718248037720929244183431852537036646815091958237", "price": "0.84", "size": "66.66", "side": "SELL", "hash": "16fef1d5041ee31b64baf52aeeb83aa5598f130c", "best_bid": "0.06", "best_ask": "0.84"}], "timestamp": "1769384790908", "event_type": "price_change"}}
{"_local_timestamp": "2026-01-25T23:46:34.784534+00:00", "data": {"market": "0x57907f477d6295cee2b169859b8606644a4d71d0ec6128372b0c9db9913bcd93", "price_changes": [{"asset_id": "38193498706916382331735817582375344137760715410898207845843641476007403461254", "price": "0.16", "size": "0", "side": "BUY", "hash": "0e05095482447fab4c9fab15bdafd4ec1175083e", "best_bid": "0.17", "best_ask": "0.94"}, {"asset_id": "101193316906353661596667021454376162656427957280783485056984469355545526109216", "price": "0.84", "size": "0", "side": "SELL", "hash": "bb3775c0fde2ab648fc01e9f8f7b7a3bfcfb23bb", "best_bid": "0.06", "best_ask": "0.83"}], "timestamp": "1769384794557", "event_type": "price_change"}}
{"_local_timestamp": "2026-01-25T23:46:34.785012+00:00", "data": {"market": "0xbb5745a78307d6434215753ec4aed95ec3eb3272f92d32d9832754c04c35f08c", "price_changes": [{"asset_id": "24067803523094369652482608318472371337596458082523423062803274427732809099156", "price": "0.15", "size": "0", "side": "BUY", "hash": "b8ce1aab3c369579a08dbcae04cd1d408b8554aa", "best_bid": "0.16", "best_ask": "0.94"}, {"asset_id": "51786810938584713265589072330718248037720929244183431852537036646815091958237", "price": "0.85", "size": "0", "side": "SELL", "hash": "9068689437ba51dbedd1986427301c7f3e3af4c6", "best_bid": "0.06", "best_ask": "0.84"}], "timestamp": "1769384794557", "event_type": "price_change"}}
{"_local_timestamp": "2026-01-25T23:46:34.814760+00:00", "data": {"market": "0xbb5745a78307d6434215753ec4aed95ec3eb3272f92d32d9832754c04c35f08c", "price_changes": [{"asset_id": "24067803523094369652482608318472371337596458082523423062803274427732809099156", "price": "0.17", "size": "20", "side": "BUY", "hash": "ba1b8e54ffafd29145045b20fc1c52c46e9d2868", "best_bid": "0.17", "best_ask": "0.94"}, {"asset_id": "51786810938584713265589072330718248037720929244183431852537036646815091958237", "price": "0.83", "size": "20", "side": "SELL", "hash": "6535ddb1323b093ed0e3af1c8309500a2e889ef3", "best_bid": "0.06", "best_ask": "0.83"}], "timestamp": "1769384794588", "event_type": "price_change"}}
{"_local_timestamp": "2026-01-25T23:46:34.815224+00:00", "data": {"market": "0x57907f477d6295cee2b169859b8606644a4d71d0ec6128372b0c9db9913bcd93", "price_changes": [{"asset_id": "38193498706916382331735817582375344137760715410898207845843641476007403461254", "price": "0.18", "size": "20", "side": "BUY", "hash": "b776eb0d7db96927f9fe11fabcba65e266a89675", "best_bid": "0.18", "best_ask": "0.94"}, {"asset_id": "101193316906353661596667021454376162656427957280783485056984469355545526109216", "price": "0.82", "size": "20", "side": "SELL", "hash": "ae2d6b768bc9e429ef9e96d8bf62a42c3b959646", "best_bid": "0.06", "best_ask": "0.82"}], "timestamp": "1769384794588", "event_type": "price_change"}}
{"_local_timestamp": "2026-01-25T23:47:33.586680+00:00", "data": {"market": "0xbc2006687eb6ab0081379a56ada7381b6b3b865ffb574e08a7a3e859a7434b7c", "price_changes": [{"asset_id": "63583217354653742103033975957525643306323589776872901149499294038892138077829", "price": "0.2", "size": "79", "side": "BUY", "hash": "49d09908ac9230a208ba139ae7db5e5ebd84cf95", "best_bid": "0.2", "best_ask": "0.94"}, {"asset_id": "68019269343969765341171874525368745169647714153650196737363227760382767964183", "price": "0.8", "size": "79", "side": "SELL", "hash": "4d220b368773cccbdcb4b387762f7ddd458753d1", "best_bid": "0.06", "best_ask": "0.8"}], "timestamp": "1769384853363", "event_type": "price_change"}}
{"_local_timestamp": "2026-01-25T23:47:33.588172+00:00", "data": {"market": "0x57907f477d6295cee2b169859b8606644a4d71d0ec6128372b0c9db9913bcd93", "price_changes": [{"asset_id": "38193498706916382331735817582375344137760715410898207845843641476007403461254", "price": "0.19", "size": "79", "side": "BUY", "hash": "68bf08f918a9b60e5b668ce35393576a98165076", "best_bid": "0.19", "best_ask": "0.94"}, {"asset_id": "101193316906353661596667021454376162656427957280783485056984469355545526109216", "price": "0.81", "size": "79", "side": "SELL", "hash": "d9fcf593c84207691bd2549d95524a47a5f6edcc", "best_bid": "0.06", "best_ask": "0.81"}], "timestamp": "1769384853363", "event_type": "price_change"}}
{"_local_timestamp": "2026-01-25T23:47:33.588606+00:00", "data": {"market": "0xbb5745a78307d6434215753ec4aed95ec3eb3272f92d32d9832754c04c35f08c", "price_changes": [{"asset_id": "24067803523094369652482608318472371337596458082523423062803274427732809099156", "price": "0.18", "size": "158.33", "side": "BUY", "hash": "2fe6fdcbd133f094867d45fc9ba9ddbaf16e136c", "best_bid": "0.18", "best_ask": "0.94"}, {"asset_id": "51786810938584713265589072330718248037720929244183431852537036646815091958237", "price": "0.82", "size": "158.33", "side": "SELL", "hash": "03aa3eccfb45bfecacb7d9b5400198de9913cbaa", "best_bid": "0.06", "best_ask": "0.82"}], "timestamp": "1769384853363", "event_type": "price_change"}}
{"_local_timestamp": "2026-01-25T23:47:33.589018+00:00", "data": {"market": "0xe2cfb3b48c35d28faaecf28e296d6f672188c90cfdf08c07a6e6a824e1bc7539", "price_changes": [{"asset_id": "114856070891915179881203224601555438788948422405426418879020114548029044261628", "price": "0.18", "size": "105.66", "side": "BUY", "hash": "77208346ec108850035e22c0eeee3a094656c0d1", "best_bid": "0.18", "best_ask": "0.94"}, {"asset_id": "40768718081882153418959955243994854330146531826408459920832464833723436741424", "price": "0.82", "size": "105.66", "side": "SELL", "hash": "e980357ce7958a730bb8870a38f00d23dd51e482", "best_bid": "0.06", "best_ask": "0.82"}], "timestamp": "1769384853363", "event_type": "price_change"}}
{"_local_timestamp": "2026-01-25T23:47:33.589391+00:00", "data": {"market": "0xbb5745a78307d6434215753ec4aed95ec3eb3272f92d32d9832754c04c35f08c", "price_changes": [{"asset_id": "24067803523094369652482608318472371337596458082523423062803274427732809099156", "price": "0.17", "size": "178.33", "side": "BUY", "hash": "1e0b426023476c6af937fcce7ab7a51711903353", "best_bid": "0.18", "best_ask": "0.94"}, {"asset_id": "51786810938584713265589072330718248037720929244183431852537036646815091958237", "price": "0.83", "size": "178.33", "side": "SELL", "hash": "e791a9a5c391b88fe1c4f0864193f61138e86305", "best_bid": "0.06", "best_ask": "0.82"}], "timestamp": "1769384853363", "event_type": "price_change"}}
{"_local_timestamp": "2026-01-25T23:47:33.593977+00:00", "data": {"market": "0x57907f477d6295cee2b169859b8606644a4d71d0ec6128372b0c9db9913bcd93", "price_changes": [{"asset_id": "38193498706916382331735817582375344137760715410898207845843641476007403461254", "price": "0.18", "size": "99", "side": "BUY", "hash": "307ca6e5318728ad73f0613000ff4dc1375d76e6", "best_bid": "0.19", "best_ask": "0.94"}, {"asset_id": "101193316906353661596667021454376162656427957280783485056984469355545526109216", "price": "0.82", "size": "99", "side": "SELL", "hash": "b5f1916309040f221a3b58c9eba75ee9dc5b54e1", "best_bid": "0.06", "best_ask": "0.81"}], "timestamp": "1769384853363", "event_type": "price_change"}}
{"_local_timestamp": "2026-01-25T23:47:33.594445+00:00", "data": {"market": "0xe2cfb3b48c35d28faaecf28e296d6f672188c90cfdf08c07a6e6a824e1bc7539", "price_changes": [{"asset_id": "114856070891915179881203224601555438788948422405426418879020114548029044261628", "price": "0.19", "size": "158.33", "side": "BUY", "hash": "d37f9a6c434a5dfca1edb8ef720e286958b77631", "best_bid": "0.19", "best_ask": "0.94"}, {"asset_id": "40768718081882153418959955243994854330146531826408459920832464833723436741424", "price": "0.81", "size": "158.33", "side": "SELL", "hash": "3a04341406ad4b2dd1a0241fb243e5b0aea14fbf", "best_bid": "0.06", "best_ask": "0.81"}], "timestamp": "1769384853363", "event_type": "price_change"}}
{"_local_timestamp": "2026-01-25T23:47:36.727317+00:00", "data": {"market": "0xbb5745a78307d6434215753ec4aed95ec3eb3272f92d32d9832754c04c35f08c", "price_changes": [{"asset_id": "24067803523094369652482608318472371337596458082523423062803274427732809099156", "price": "0.17", "size": "158.33", "side": "BUY", "hash": "78c095262067d6c689cbd238c1499dbe172fdb8b", "best_bid": "0.18", "best_ask": "0.94"}, {"asset_id": "51786810938584713265589072330718248037720929244183431852537036646815091958237", "price": "0.83", "size": "158.33", "side": "SELL", "hash": "fdacfee91506ba1c533f43ca21ea37c2aacb8a3e", "best_bid": "0.06", "best_ask": "0.82"}], "timestamp": "1769384856452", "event_type": "price_change"}}
{"_local_timestamp": "2026-01-25T23:47:36.772825+00:00", "data": {"market": "0xbb5745a78307d6434215753ec4aed95ec3eb3272f92d32d9832754c04c35f08c", "price_changes": [{"asset_id": "24067803523094369652482608318472371337596458082523423062803274427732809099156", "price": "0.18", "size": "178.33", "side": "BUY", "hash": "0bc8706d49da367190e02e0b61186fb478fb491e", "best_bid": "0.18", "best_ask": "0.94"}, {"asset_id": "51786810938584713265589072330718248037720929244183431852537036646815091958237", "price": "0.82", "size": "178.33", "side": "SELL", "hash": "1d92aa4cd51fffd8f2f6e2bd43f38cb317f22b3e", "best_bid": "0.06", "best_ask": "0.82"}], "timestamp": "1769384856486", "event_type": "price_change"}}
{"_local_timestamp": "2026-01-25T23:47:50.542212+00:00", "data": {"market": "0xbb5745a78307d6434215753ec4aed95ec3eb3272f92d32d9832754c04c35f08c", "price_changes": [{"asset_id": "24067803523094369652482608318472371337596458082523423062803274427732809099156", "price": "0.17", "size": "0", "side": "BUY", "hash": "8e83dea5be7c306a50d0e268d1d9c2ad715ccb10", "best_bid": "0.18", "best_ask": "0.94"}, {"asset_id": "51786810938584713265589072330718248037720929244183431852537036646815091958237", "price": "0.83", "size": "0", "side": "SELL", "hash": "21d0bce62d6c2c962b195d22462145304af2ac71", "best_bid": "0.06", "best_ask": "0.82"}], "timestamp": "1769384870471", "event_type": "price_change"}}
{"_local_timestamp": "2026-01-25T23:47:50.542784+00:00", "data": {"market": "0x57907f477d6295cee2b169859b8606644a4d71d0ec6128372b0c9db9913bcd93", "price_changes": [{"asset_id": "38193498706916382331735817582375344137760715410898207845843641476007403461254", "price": "0.18", "size": "20", "side": "BUY", "hash": "76ff04e636c71d03e3a363667e2c31f3787736eb", "best_bid": "0.19", "best_ask": "0.94"}, {"asset_id": "101193316906353661596667021454376162656427957280783485056984469355545526109216", "price": "0.82", "size": "20", "side": "SELL", "hash": "77e67b632a7778e20ede34d3e09a39317ecc7e60", "best_bid": "0.06", "best_ask": "0.81"}], "timestamp": "1769384870471", "event_type": "price_change"}}
{"_local_timestamp": "2026-01-25T23:47:50.543198+00:00", "data": {"market": "0xbc2006687eb6ab0081379a56ada7381b6b3b865ffb574e08a7a3e859a7434b7c", "price_changes": [{"asset_id": "63583217354653742103033975957525643306323589776872901149499294038892138077829", "price": "0.19", "size": "66.66", "side": "BUY", "hash": "938fec2e7e604f7cbde22371e80ee517aa05f86e", "best_bid": "0.2", "best_ask": "0.94"}, {"asset_id": "68019269343969765341171874525368745169647714153650196737363227760382767964183", "price": "0.81", "size": "66.66", "side": "SELL", "hash": "c448bf415c8fc13f250905bd0201ed6d17e88b19", "best_bid": "0.06", "best_ask": "0.8"}], "timestamp": "1769384870471", "event_type": "price_change"}}
{"_local_timestamp": "2026-01-25T23:47:51.409569+00:00", "data": {"market": "0xbb5745a78307d6434215753ec4aed95ec3eb3272f92d32d9832754c04c35f08c", "price_changes": [{"asset_id": "24067803523094369652482608318472371337596458082523423062803274427732809099156", "price": "0.18", "size": "158.33", "side": "BUY", "hash": "1b692beb5ad5ff5694946c202bdc5ee5c08a07ae", "best_bid": "0.18", "best_ask": "0.94"}, {"asset_id": "51786810938584713265589072330718248037720929244183431852537036646815091958237", "price": "0.82", "size": "158.33", "side": "SELL", "hash": "911433694f6075385b0f5378c45831edb0611617", "best_bid": "0.06", "best_ask": "0.82"}], "timestamp": "1769384871345", "event_type": "price_change"}}
{"_local_timestamp": "2026-01-25T23:47:51.445412+00:00", "data": {"market": "0xbb5745a78307d6434215753ec4aed95ec3eb3272f92d32d9832754c04c35f08c", "price_changes": [{"asset_id": "24067803523094369652482608318472371337596458082523423062803274427732809099156", "price": "0.17", "size": "20", "side": "BUY", "hash": "51920d04b3c36e6e6f944bf966c89f5b1fe5fce6", "best_bid": "0.18", "best_ask": "0.94"}, {"asset_id": "51786810938584713265589072330718248037720929244183431852537036646815091958237", "price": "0.83", "size": "20", "side": "SELL", "hash": "2c57a3db1bf3d919006c92d3abf3d6959418c100", "best_bid": "0.06", "best_ask": "0.82"}], "timestamp": "1769384871374", "event_type": "price_change"}}
{"_local_timestamp": "2026-01-25T23:48:18.665949+00:00", "data": {"market": "0xe2cfb3b48c35d28faaecf28e296d6f672188c90cfdf08c07a6e6a824e1bc7539", "price_changes": [{"asset_id": "114856070891915179881203224601555438788948422405426418879020114548029044261628", "price": "0.19", "size": "0", "side": "BUY", "hash": "9999d8bb3ee88544801f37c7c9993cafc152b840", "best_bid": "0.18", "best_ask": "0.94"}, {"asset_id": "40768718081882153418959955243994854330146531826408459920832464833723436741424", "price": "0.81", "size": "0", "side": "SELL", "hash": "119575876ee035906265b16380f7cc527b0b59ae", "best_bid": "0.06", "best_ask": "0.82"}], "timestamp": "1769384898597", "event_type": "price_change"}}
{"_local_timestamp": "2026-01-25T23:48:40.596985+00:00", "data": {"market": "0xe2cfb3b48c35d28faaecf28e296d6f672188c90cfdf08c07a6e6a824e1bc7539", "price_changes": [{"asset_id": "40768718081882153418959955243994854330146531826408459920832464833723436741424", "price": "0.02", "size": "108.12", "side": "BUY", "hash": "fc1aa150d6c21f342aa8ecebd074e3c783268242", "best_bid": "0.06", "best_ask": "0.82"}, {"asset_id": "114856070891915179881203224601555438788948422405426418879020114548029044261628", "price": "0.98", "size": "108.12", "side": "SELL", "hash": "452351bf405e2affd1d436a16c81a4ec9da76348", "best_bid": "0.18", "best_ask": "0.94"}], "timestamp": "1769384920521", "event_type": "price_change"}}
{"_local_timestamp": "2026-01-25T23:48:40.860827+00:00", "data": {"market": "0xbc2006687eb6ab0081379a56ada7381b6b3b865ffb574e08a7a3e859a7434b7c", "price_changes": [{"asset_id": "68019269343969765341171874525368745169647714153650196737363227760382767964183", "price": "0.02", "size": "108.12", "side": "BUY", "hash": "4761c1ffa218aca43e89585bf62c8d2a2c12a36e", "best_bid": "0.06", "best_ask": "0.8"}, {"asset_id": "63583217354653742103033975957525643306323589776872901149499294038892138077829", "price": "0.98", "size": "108.12", "side": "SELL", "hash": "52e778dab4c84c506a7855590a52670bac063b76", "best_bid": "0.2", "best_ask": "0.94"}], "timestamp": "1769384920787", "event_type": "price_change"}}
{"_local_timestamp": "2026-01-25T23:48:41.848409+00:00", "data": {"market": "0xc0fe594181536c195b49e7b48526a24740f0913ffc90a77eb41b214f31a822b4", "price_changes": [{"asset_id": "113723988771241090253785053680072264720020982848328850292346167980912533825960", "price": "0.01", "size": "150", "side": "BUY", "hash": "f0ccdbaff0f8426ab4e7c3ea47aaa41f6ef0ba0d", "best_bid": "0.05", "best_ask": "0.8"}, {"asset_id": "29141447781503863865336566062510441196981840569949260694480394604049274435905", "price": "0.99", "size": "150", "side": "SELL", "hash": "432973b1a8f39a10cae1ba5c4bb35b5a62dcdace", "best_bid": "0.2", "best_ask": "0.95"}], "timestamp": "1769384921779", "event_type": "price_change"}}
{"_local_timestamp": "2026-01-25T23:48:43.482251+00:00", "data": {"market": "0xc0fe594181536c195b49e7b48526a24740f0913ffc90a77eb41b214f31a822b4", "price_changes": [{"asset_id": "113723988771241090253785053680072264720020982848328850292346167980912533825960", "price": "0.01", "size": "183.33", "side": "BUY", "hash": "c893b9bf339613d0b24b10a4feb0f68af04a3bd0", "best_bid": "0.05", "best_ask": "0.8"}, {"asset_id": "29141447781503863865336566062510441196981840569949260694480394604049274435905", "price": "0.99", "size": "183.33", "side": "SELL", "hash": "6563d4b5eb032bfe5a9add1c5c35b387d8d39a55", "best_bid": "0.2", "best_ask": "0.95"}], "timestamp": "1769384923408", "event_type": "price_change"}}
{"_local_timestamp": "2026-01-25T23:48:43.768681+00:00", "data": {"market": "0x57907f477d6295cee2b169859b8606644a4d71d0ec6128372b0c9db9913bcd93", "price_changes": [{"asset_id": "101193316906353661596667021454376162656427957280783485056984469355545526109216", "price": "0.02", "size": "108.12", "side": "BUY", "hash": "d3ebd50739cce0b211e98c9fd3b2d5058c1bd2dc", "best_bid": "0.06", "best_ask": "0.81"}, {"asset_id": "38193498706916382331735817582375344137760715410898207845843641476007403461254", "price": "0.98", "size": "108.12", "side": "SELL", "hash": "8caf274ca17c917c70895d60ff6581f7601bfd36", "best_bid": "0.19", "best_ask": "0.94"}], "timestamp": "1769384923678", "event_type": "price_change"}}
{"_local_timestamp": "2026-01-25T23:48:43.769201+00:00", "data": {"market": "0xbb5745a78307d6434215753ec4aed95ec3eb3272f92d32d9832754c04c35f08c", "price_changes": [{"asset_id": "51786810938584713265589072330718248037720929244183431852537036646815091958237", "price": "0.02", "size": "108.12", "side": "BUY", "hash": "cdc1b70750b366d497f32893028d38e2bb0dc1d2", "best_bid": "0.06", "best_ask": "0.82"}, {"asset_id": "24067803523094369652482608318472371337596458082523423062803274427732809099156", "price": "0.98", "size": "108.12", "side": "SELL", "hash": "5d8c9f669099963939384538ffae39aea302e2d8", "best_bid": "0.18", "best_ask": "0.94"}], "timestamp": "1769384923678", "event_type": "price_change"}}
{"_local_timestamp": "2026-01-25T23:48:51.559717+00:00", "data": {"market": "0xe2cfb3b48c35d28faaecf28e296d6f672188c90cfdf08c07a6e6a824e1bc7539", "price_changes": [{"asset_id": "40768718081882153418959955243994854330146531826408459920832464833723436741424", "price": "0.02", "size": "100", "side": "BUY", "hash": "f7cbef592964801ccf12f301ee6ea00f370d9a34", "best_bid": "0.06", "best_ask": "0.82"}, {"asset_id": "114856070891915179881203224601555438788948422405426418879020114548029044261628", "price": "0.98", "size": "100", "side": "SELL", "hash": "9bb8402294b385f5c87aad97543fe0a18be2ffaf", "best_bid": "0.18", "best_ask": "0.94"}], "timestamp": "1769384931489", "event_type": "price_change"}}
{"_local_timestamp": "2026-01-25T23:48:51.560224+00:00", "data": {"market": "0xbc2006687eb6ab0081379a56ada7381b6b3b865ffb574e08a7a3e859a7434b7c", "price_changes": [{"asset_id": "68019269343969765341171874525368745169647714153650196737363227760382767964183", "price": "0.02", "size": "100", "side": "BUY", "hash": "a626ab434f2df17f1b50879368a7d7e2a73643c0", "best_bid": "0.06", "best_ask": "0.8"}, {"asset_id": "63583217354653742103033975957525643306323589776872901149499294038892138077829", "price": "0.98", "size": "100", "side": "SELL", "hash": "4d7cf5d819fc5628a3b7e5749a85fa9a20be7ff2", "best_bid": "0.2", "best_ask": "0.94"}], "timestamp": "1769384931489", "event_type": "price_change"}}
{"_local_timestamp": "2026-01-25T23:48:51.560680+00:00", "data": {"market": "0xbb5745a78307d6434215753ec4aed95ec3eb3272f92d32d9832754c04c35f08c", "price_changes": [{"asset_id": "51786810938584713265589072330718248037720929244183431852537036646815091958237", "price": "0.02", "size": "100", "side": "BUY", "hash": "e3407321c3e6e438a69209d26f33508a014b95ae", "best_bid": "0.06", "best_ask": "0.82"}, {"asset_id": "24067803523094369652482608318472371337596458082523423062803274427732809099156", "price": "0.98", "size": "100", "side": "SELL", "hash": "aab2c2abd78cdc627a2c699ba651fd1a2df07d75", "best_bid": "0.18", "best_ask": "0.94"}], "timestamp": "1769384931489", "event_type": "price_change"}}
{"_local_timestamp": "2026-01-25T23:48:51.561439+00:00", "data": {"market": "0x57907f477d6295cee2b169859b8606644a4d71d0ec6128372b0c9db9913bcd93", "price_changes": [{"asset_id": "101193316906353661596667021454376162656427957280783485056984469355545526109216", "price": "0.02", "size": "100", "side": "BUY", "hash": "9d101479f9cf7453d6372e502ed4b845f9beccfc", "best_bid": "0.06", "best_ask": "0.81"}, {"asset_id": "38193498706916382331735817582375344137760715410898207845843641476007403461254", "price": "0.98", "size": "100", "side": "SELL", "hash": "2e30bbcd1c9e828b1292a212de288cf8ea61b7fa", "best_bid": "0.19", "best_ask": "0.94"}], "timestamp": "1769384931489", "event_type": "price_change"}}
{"_local_timestamp": "2026-01-25T23:49:06.160447+00:00", "data": {"market": "0xbb5745a78307d6434215753ec4aed95ec3eb3272f92d32d9832754c04c35f08c", "price_changes": [{"asset_id": "24067803523094369652482608318472371337596458082523423062803274427732809099156", "price": "0.16", "size": "0", "side": "BUY", "hash": "09af6c6260c1fbde2eefdb9423246eb18cae7cf1", "best_bid": "0.18", "best_ask": "0.94"}, {"asset_id": "51786810938584713265589072330718248037720929244183431852537036646815091958237", "price": "0.84", "size": "0", "side": "SELL", "hash": "d30c1e1701b45708d1a3551e67500c7a5a3d95c2", "best_bid": "0.06", "best_ask": "0.82"}], "timestamp": "1769384946088", "event_type": "price_change"}}
{"_local_timestamp": "2026-01-25T23:49:06.161318+00:00", "data": {"market": "0xbc2006687eb6ab0081379a56ada7381b6b3b865ffb574e08a7a3e859a7434b7c", "price_changes": [{"asset_id": "63583217354653742103033975957525643306323589776872901149499294038892138077829", "price": "0.19", "size": "0", "side": "BUY", "hash": "73cfb49a8f4937c85cac96eae0e74b06b506d48c", "best_bid": "0.2", "best_ask": "0.94"}, {"asset_id": "68019269343969765341171874525368745169647714153650196737363227760382767964183", "price": "0.81", "size": "0", "side": "SELL", "hash": "5c2d0b682fb413d1f75d57ed12ecf700e0825d09", "best_bid": "0.06", "best_ask": "0.8"}], "timestamp": "1769384946088", "event_type": "price_change"}}
{"_local_timestamp": "2026-01-25T23:49:06.162034+00:00", "data": {"market": "0x57907f477d6295cee2b169859b8606644a4d71d0ec6128372b0c9db9913bcd93", "price_changes": [{"asset_id": "38193498706916382331735817582375344137760715410898207845843641476007403461254", "price": "0.17", "size": "0", "side": "BUY", "hash": "756378e08e85bfde8c31ecacd8b92c19718bdddd", "best_bid": "0.19", "best_ask": "0.94"}, {"asset_id": "101193316906353661596667021454376162656427957280783485056984469355545526109216", "price": "0.83", "size": "0", "side": "SELL", "hash": "e6e8ff349493f1cca4a18146bcff468afda15487", "best_bid": "0.06", "best_ask": "0.81"}], "timestamp": "1769384946088", "event_type": "price_change"}}
{"_local_timestamp": "2026-01-25T23:49:07.305346+00:00", "data": {"market": "0x57907f477d6295cee2b169859b8606644a4d71d0ec6128372b0c9db9913bcd93", "price_changes": [{"asset_id": "38193498706916382331735817582375344137760715410898207845843641476007403461254", "price": "0.2", "size": "66.66", "side": "BUY", "hash": "5c53b15e712a1d5d0b6c5685e3762b6ac310f4c1", "best_bid": "0.2", "best_ask": "0.94"}, {"asset_id": "101193316906353661596667021454376162656427957280783485056984469355545526109216", "price": "0.8", "size": "66.66", "side": "SELL", "hash": "039a25bd146aa6033a3668d7ba6a281f98567a34", "best_bid": "0.06", "best_ask": "0.8"}], "timestamp": "1769384947235", "event_type": "price_change"}}
{"_local_timestamp": "2026-01-25T23:49:07.395979+00:00", "data": {"market": "0xbc2006687eb6ab0081379a56ada7381b6b3b865ffb574e08a7a3e859a7434b7c", "price_changes": [{"asset_id": "63583217354653742103033975957525643306323589776872901149499294038892138077829", "price": "0.21", "size": "66.66", "side": "BUY", "hash": "496b28d53725cf0a18dd0e3b92de512331124033", "best_bid": "0.21", "best_ask": "0.94"}, {"asset_id": "68019269343969765341171874525368745169647714153650196737363227760382767964183", "price": "0.79", "size": "66.66", "side": "SELL", "hash": "c77a0a4695cd75a5f9b2cd1437d834d5daa3d12f", "best_bid": "0.06", "best_ask": "0.79"}], "timestamp": "1769384947331", "event_type": "price_change"}}
{"_local_timestamp": "2026-01-25T23:49:07.444306+00:00", "data": {"market": "0xbb5745a78307d6434215753ec4aed95ec3eb3272f92d32d9832754c04c35f08c", "price_changes": [{"asset_id": "24067803523094369652482608318472371337596458082523423062803274427732809099156", "price": "0.19", "size": "66.66", "side": "BUY", "hash": "ae34ba3c699d4fae9bb8cf79a6f6d7d04bb868d2", "best_bid": "0.19", "best_ask": "0.94"}, {"asset_id": "51786810938584713265589072330718248037720929244183431852537036646815091958237", "price": "0.81", "size": "66.66", "side": "SELL", "hash": "ec5a0ef1db058e1f0ced96a86136dfc85c4a1432", "best_bid": "0.06", "best_ask": "0.81"}], "timestamp": "1769384947375", "event_type": "price_change"}}
{"_local_timestamp": "2026-01-25T23:49:07.784122+00:00", "data": {"market": "0x57907f477d6295cee2b169859b8606644a4d71d0ec6128372b0c9db9913bcd93", "price_changes": [{"asset_id": "38193498706916382331735817582375344137760715410898207845843641476007403461254", "price": "0.18", "size": "0", "side": "BUY", "hash": "6e3c536246f5eaee170c3f806e7a2aa8b16427ad", "best_bid": "0.2", "best_ask": "0.94"}, {"asset_id": "101193316906353661596667021454376162656427957280783485056984469355545526109216", "price": "0.82", "size": "0", "side": "SELL", "hash": "46e87f5cfd9e244226151f4dbca639a2225c7354", "best_bid": "0.06", "best_ask": "0.8"}], "timestamp": "1769384947715", "event_type": "price_change"}}
{"_local_timestamp": "2026-01-25T23:49:07.784777+00:00", "data": {"market": "0xbb5745a78307d6434215753ec4aed95ec3eb3272f92d32d9832754c04c35f08c", "price_changes": [{"asset_id": "24067803523094369652482608318472371337596458082523423062803274427732809099156", "price": "0.17", "size": "0", "side": "BUY", "hash": "7937dcbdef16fe566f5b6ef616531543da48eaaf", "best_bid": "0.19", "best_ask": "0.94"}, {"asset_id": "51786810938584713265589072330718248037720929244183431852537036646815091958237", "price": "0.83", "size": "0", "side": "SELL", "hash": "988358e2edb120cc6f3aa6b8018d6d6e2b6bbbd8", "best_bid": "0.06", "best_ask": "0.81"}], "timestamp": "1769384947715", "event_type": "price_change"}}
{"_local_timestamp": "2026-01-25T23:49:07.817613+00:00", "data": {"market": "0xbb5745a78307d6434215753ec4aed95ec3eb3272f92d32d9832754c04c35f08c", "price_changes": [{"asset_id": "24067803523094369652482608318472371337596458082523423062803274427732809099156", "price": "0.15", "size": "20", "side": "BUY", "hash": "df5a3abb558209b22222d9faee84831d8fa65a47", "best_bid": "0.19", "best_ask": "0.94"}, {"asset_id": "51786810938584713265589072330718248037720929244183431852537036646815091958237", "price": "0.85", "size": "20", "side": "SELL", "hash": "d6b9f4a73194449dfd72182c2397c161f587ad23", "best_bid": "0.06", "best_ask": "0.81"}], "timestamp": "1769384947744", "event_type": "price_change"}}
{"_local_timestamp": "2026-01-25T23:49:07.818958+00:00", "data": {"market": "0x57907f477d6295cee2b169859b8606644a4d71d0ec6128372b0c9db9913bcd93", "price_changes": [{"asset_id": "38193498706916382331735817582375344137760715410898207845843641476007403461254", "price": "0.16", "size": "20", "side": "BUY", "hash": "9ec27d690cb6c6baa5a8b88d8ae85a57e606830f", "best_bid": "0.2", "best_ask": "0.94"}, {"asset_id": "101193316906353661596667021454376162656427957280783485056984469355545526109216", "price": "0.84", "size": "20", "side": "SELL", "hash": "00d5752a079d6ec1e4e23d92cc88a31ee5301ad7", "best_bid": "0.06", "best_ask": "0.8"}], "timestamp": "1769384947744", "event_type": "price_change"}}
{"_local_timestamp": "2026-01-25T23:49:27.030308+00:00", "data": {"market": "0x57907f477d6295cee2b169859b8606644a4d71d0ec6128372b0c9db9913bcd93", "price_changes": [{"asset_id": "38193498706916382331735817582375344137760715410898207845843641476007403461254", "price": "0.19", "size": "0", "side": "BUY", "hash": "080bc13414fd8fe8016eb6eab96e0b969eb9fa5b", "best_bid": "0.2", "best_ask": "0.94"}, {"asset_id": "101193316906353661596667021454376162656427957280783485056984469355545526109216", "price": "0.81", "size": "0", "side": "SELL", "hash": "eda9f3305202c3b7fa95c0ed214d83a5a75b1780", "best_bid": "0.06", "best_ask": "0.8"}], "timestamp": "1769384966936", "event_type": "price_change"}}
{"_local_timestamp": "2026-01-25T23:49:27.037517+00:00", "data": {"market": "0xbb5745a78307d6434215753ec4aed95ec3eb3272f92d32d9832754c04c35f08c", "price_changes": [{"asset_id": "24067803523094369652482608318472371337596458082523423062803274427732809099156", "price": "0.18", "size": "0", "side": "BUY", "hash": "920e5f81de6361fbb4e044c53352c89343ddbc01", "best_bid": "0.19", "best_ask": "0.94"}, {"asset_id": "51786810938584713265589072330718248037720929244183431852537036646815091958237", "price": "0.82", "size": "0", "side": "SELL", "hash": "6d3e9ea91a6725bf644d015ee849ebdc7e977975", "best_bid": "0.06", "best_ask": "0.81"}], "timestamp": "1769384966936", "event_type": "price_change"}}
{"_local_timestamp": "2026-01-25T23:49:27.044452+00:00", "data": {"market": "0xbc2006687eb6ab0081379a56ada7381b6b3b865ffb574e08a7a3e859a7434b7c", "price_changes": [{"asset_id": "63583217354653742103033975957525643306323589776872901149499294038892138077829", "price": "0.2", "size": "0", "side": "BUY", "hash": "7af21e9f51b381d8d7e6179c2dcbfee45a025010", "best_bid": "0.21", "best_ask": "0.94"}, {"asset_id": "68019269343969765341171874525368745169647714153650196737363227760382767964183", "price": "0.8", "size": "0", "side": "SELL", "hash": "b2363956fa16858993e4261a6f698b240ed2a15b", "best_bid": "0.06", "best_ask": "0.79"}], "timestamp": "1769384966936", "event_type": "price_change"}}
{"_local_timestamp": "2026-01-25T23:49:41.673502+00:00", "data": {"market": "0x521ab5d3c24af074bb5496a9e8e83d85b520c08e6333ab21b617f122a564615a", "price_changes": [{"asset_id": "86263889844673834773808760288478764459004352959184601356498789028474786900980", "price": "0.09", "size": "0", "side": "BUY", "hash": "ddb40cf8896549115a80016808b6179ed4050b26", "best_bid": "0.93", "best_ask": "0.99"}, {"asset_id": "7528388713228609060142081103391244635491832722831643514084973789304836742854", "price": "0.91", "size": "0", "side": "SELL", "hash": "139cb577dce757980899d157b347c4bc96abba06", "best_bid": "0.01", "best_ask": "0.07"}], "timestamp": "1769384981603", "event_type": "price_change"}}
