{"_local_timestamp": "2026-01-25T23:33:44.709342+00:00", "data": [{"market": "0x2bec0b2b3562bfcde13572021ee5567bc938f4b6a883accdb3c44c9fb7c93de5", "asset_id": "67549588035777013004185630772872416152611090585479410333854543423443737102097", "timestamp": "1769382522799", "hash": "c894dba26982e69eac82d20690c8918bdcf50b47", "bids": [{"price": "0.01", "size": "3431.64"}, {"price": "0.02", "size": "1750"}, {"price": "0.03", "size": "7.1"}, {"price": "0.04", "size": "1000"}, {"price": "0.05", "size": "330"}, {"price": "0.06", "size": "388.61"}, {"price": "0.07", "size": "300"}, {"price": "0.08", "size": "100"}, {"price": "0.09", "size": "22"}, {"price": "0.1", "size": "13"}, {"price": "0.11", "size": "11.81"}, {"price": "0.18", "size": "66.66"}, {"price": "0.19", "size": "20"}, {"price": "0.34", "size": "5.5"}, {"price": "0.35", "size": "11"}, {"price": "0.36", "size": "71.66"}], "asks": [{"price": "0.99", "size": "116.66"}, {"price": "0.98", "size": "50"}, {"price": "0.97", "size": "16.66"}, {"price": "0.95", "size": "0.03"}, {"price": "0.94", "size": "49.66"}], "event_type": "book", "last_trade_price": ""}, {"market": "0xc612823cb31b05616a21cccb759208907407c35df6bc569f2d0b7cca24b32a79", "asset_id": "27850200924917452779525076978818364368393998746365953803788220678381853982397", "timestamp": "1769383149801", "hash": "e08f4ac46a909e040307c680a26ba557086282d6", "bids": [{"price": "0.01", "size": "150"}], "asks": [{"price": "0.99", "size": "4429.54"}, {"price": "0.98", "size": "1750"}, {"price": "0.97", "size": "5.77"}, {"price": "0.96", "size": "1700"}, {"price": "0.95", "size": "330"}, {"price": "0.94", "size": "389.49"}, {"price": "0.93", "size": "300"}, {"price": "0.92", "size": "100"}, {"price": "0.91", "size": "22"}, {"price": "0.9", "size": "13"}, {"price": "0.89", "size": "11.89"}, {"price": "0.77", "size": "66.66"}, {"price": "0.73", "size": "46.14"}, {"price": "0.71", "size": "80.83"}, {"price": "0.7", "size": "20"}, {"price": "0.61", "size": "21.4"}, {"price": "0.6", "size": "11.8"}, {"price": "0.54", "size": "71.66"}], "event_type": "book", "last_trade_price": ""}, {"market": "0xe85baf2d19b31992225c1a85bf7449aa2cfd4a4bb1f28f4c3e4bb29db3b7f875", "asset_id": "42804374308926637512138626004807193961451331812554996198443523509803582210982", "timestamp": "1769383938300", "hash": "02b3b8f8289d43761c20478bd511e80346fc687a", "bids": [{"price": "0.01", "size": "166.66"}, {"price": "0.02", "size": "100"}, {"price": "0.03", "size": "66.66"}, {"price": "0.04", "size": "50"}, {"price": "0.05", "size": "66.66"}], "asks": [{"price": "0.99", "size": "4423.8"}, {"price": "0.98", "size": "1760.51"}, {"price": "0.96", "size": "1700"}, {"price": "0.95", "size": "335.21"}, {"price": "0.94", "size": "383"}, {"price": "0.93", "size": "100"}, {"price": "0.92", "size": "100"}, {"price": "0.91", "size": "200"}, {"price": "0.9", "size": "34.57"}, {"price": "0.8", "size": "66.66"}, {"price": "0.79", "size": "33"}, {"price": "0.74", "size": "38.93"}, {"price": "0.73", "size": "20"}, {"price": "0.67", "size": "59.79"}, {"price": "0.61", "size": "71.66"}], "event_type": "book", "last_trade_price": ""}, {"market": "0x19806c2aa819b06cd6112367c68a86cfcd04a5daf5e471977ea8310f241d0b25", "asset_id": "108953599859488748640167315424223285692135226463528980107326118523345159966905", "timestamp": "1769383810574", "hash": "56187dcf78437ed60b2374ead183064356d93dbb", "bids": [{"price": "0.01", "size": "4429.96"}, {"price": "0.02", "size": "1750"}, {"price": "0.03", "size": "6.31"}, {"price": "0.04", "size": "1400"}, {"price": "0.05", "size": "330"}, {"price": "0.06", "size": "383"}, {"price": "0.07", "size": "6.51"}, {"price": "0.09", "size": "100"}, {"price": "0.1", "size": "520"}, {"price": "0.11", "size": "10"}, {"price": "0.13", "size": "9.39"}, {"price": "0.23", "size": "66.66"}, {"price": "0.28", "size": "33.23"}, {"price": "0.29", "size": "20"}, {"price": "0.35", "size": "59.79"}, {"price": "0.46", "size": "71.66"}], "asks": [{"price": "0.99", "size": "114.51"}, {"price": "0.98", "size": "165.74"}, {"price": "0.97", "size": "17.74"}], "event_type": "book", "last_trade_price": ""}, {"market": "0x17f82e3b0e0c8a89c94db772bdae69e847829166d6dc669bc810dd9c3e887e7d", "asset_id": "113577032080692176917483189160049505493244580061534385093277932638888639958742", "timestamp": "1769383977265", "hash": "5dda936920544f386cc8f946b2537c820359c5b0", "bids": [{"price": "0.01", "size": "122.28"}, {"price": "0.02", "size": "150"}, {"price": "0.03", "size": "11.14"}], "asks": [{"price": "0.99", "size": "3464.72"}, {"price": "0.98", "size": "1750"}, {"price": "0.97", "size": "6.98"}, {"price": "0.96", "size": "1000"}, {"price": "0.95", "size": "330"}, {"price": "0.94", "size": "388.72"}, {"price": "0.93", "size": "300"}, {"price": "0.92", "size": "100"}, {"price": "0.91", "size": "22"}, {"price": "0.9", "size": "13"}, {"price": "0.89", "size": "11.81"}, {"price": "0.8", "size": "100"}, {"price": "0.79", "size": "20"}, {"price": "0.64", "size": "8.6"}, {"price": "0.63", "size": "16.3"}], "event_type": "book", "last_trade_price": ""}, {"market": "0x91dd8dbe75a5347f14455ca880070ebcf3356bfd7df8caf19478e881bb483efb", "asset_id": "30112939078428479271380004766658148462656808495063824079473460276372582172087", "timestamp": "1769384003863", "hash": "724b466718217593f959ce0acc8b90821580fedd", "bids": [{"price": "0.01", "size": "3367.76"}, {"price": "0.02", "size": "1750"}, {"price": "0.03", "size": "5.46"}, {"price": "0.04", "size": "1000"}, {"price": "0.05", "size": "336.48"}, {"price": "0.06", "size": "449.66"}, {"price": "0.07", "size": "300"}, {"price": "0.08", "size": "100"}, {"price": "0.09", "size": "55.65"}, {"price": "0.13", "size": "66.66"}, {"price": "0.16", "size": "5.16"}, {"price": "0.2", "size": "66.66"}, {"price": "0.21", "size": "20"}], "asks": [{"price": "0.99", "size": "166.66"}, {"price": "0.98", "size": "100"}, {"price": "0.96", "size": "66.66"}, {"price": "0.94", "size": "175"}, {"price": "0.92", "size": "10"}, {"price": "0.91", "size": "66.66"}], "event_type": "book", "last_trade_price": ""}, {"market": "0x91dd8dbe75a5347f14455ca880070ebcf3356bfd7df8caf19478e881bb483efb", "asset_id": "23125627318359544367614218401841961178939444671222355150077267933985277277448", "timestamp": "1769384003863", "hash": "17e77e9cf7bb0b4c2e4d3b41a0ca9d57e25fffdc", "bids": [{"price": "0.01", "size": "166.66"}, {"price": "0.02", "size": "100"}, {"price": "0.04", "size": "66.66"}, {"price": "0.06", "size": "175"}, {"price": "0.08", "size": "10"}, {"price": "0.09", "size": "66.66"}], "asks": [{"price": "0.99", "size": "3367.76"}, {"price": "0.98", "size": "1750"}, {"price": "0.97", "size": "5.46"}, {"price": "0.96", "size": "1000"}, {"price": "0.95", "size": "336.48"}, {"price": "0.94", "size": "449.66"}, {"price": "0.93", "size": "300"}, {"price": "0.92", "size": "100"}, {"price": "0.91", "size": "55.65"}, {"price": "0.87", "size": "66.66"}, {"price": "0.84", "size": "5.16"}, {"price": "0.8", "size": "66.66"}, {"price": "0.79", "size": "20"}], "event_type": "book", "last_trade_price": ""}, {"market": "0xeef43874b81cc0757ba626b32f26f9996b46dae4eba80f5f3a6d844d3d9d9c72", "asset_id": "48021162790402851216178343019771947189732554762782810353642610100613247118491", "timestamp": "1769383620458", "hash": "abf7cda28042b95fa3c0378ef0ebb2c34acff648", "bids": [{"price": "0.01", "size": "3424.18"}, {"price": "0.02", "size": "1760.83"}, {"price": "0.04", "size": "1000"}, {"price": "0.05", "size": "335.37"}, {"price": "0.06", "size": "383"}, {"price": "0.07", "size": "300"}, {"price": "0.08", "size": "100"}, {"price": "0.09", "size": "22"}, {"price": "0.1", "size": "6.39"}, {"price": "0.11", "size": "7"}, {"price": "0.12", "size": "6.66"}, {"price": "0.19", "size": "66.66"}, {"price": "0.29", "size": "36.97"}, {"price": "0.3", "size": "20"}, {"price": "0.38", "size": "71.66"}], "asks": [{"price": "0.99", "size": "100"}, {"price": "0.98", "size": "150"}], "event_type": "book", "last_trade_price": ""}, {"market": "0x19806c2aa819b06cd6112367c68a86cfcd04a5daf5e471977ea8310f241d0b25", "asset_id": "95224365708745593619811400419827796915292296641493778634960081360586269890047", "timestamp": "1769383810574", "hash": "3403b37c35871f3868dfe0151e933a8a608f8c86", "bids": [{"price": "0.01", "size": "114.51"}, {"price": "0.02", "size": "165.74"}, {"price": "0.03", "size": "17.74"}], "asks": [{"price": "0.99", "size": "4429.96"}, {"price": "0.98", "size": "1750"}, {"price": "0.97", "size": "6.31"}, {"price": "0.96", "size": "1400"}, {"price": "0.95", "size": "330"}, {"price": "0.94", "size": "383"}, {"price": "0.93", "size": "6.51"}, {"price": "0.91", "size": "100"}, {"price": "0.9", "size": "520"}, {"price": "0.89", "size": "10"}, {"price": "0.87", "size": "9.39"}, {"price": "0.77", "size": "66.66"}, {"price": "0.72", "size": "33.23"}, {"price": "0.71", "size": "20"}, {"price": "0.65", "size": "59.79"}, {"price": "0.54", "size": "71.66"}], "event_type": "book", "last_trade_price": ""}, {"market": "0x2bec0b2b3562bfcde13572021ee5567bc938f4b6a883accdb3c44c9fb7c93de5", "asset_id": "22621900385203545572961259607481335836574764520983045149819679201843742949126", "timestamp": "1769382522799", "hash": "dc89e7f4a67860e1d5d3d16bf5e81e31159e38d8", "bids": [{"price": "0.01", "size": "116.66"}, {"price": "0.02", "size": "50"}, {"price": "0.03", "size": "16.66"}, {"price": "0.05", "size": "0.03"}, {"price": "0.06", "size": "49.66"}], "asks": [{"price": "0.99", "size": "3431.64"}, {"price": "0.98", "size": "1750"}, {"price": "0.97", "size": "7.1"}, {"price": "0.96", "size": "1000"}, {"price": "0.95", "size": "330"}, {"price": "0.94", "size": "388.61"}, {"price": "0.93", "size": "300"}, {"price": "0.92", "size": "100"}, {"price": "0.91", "size": "22"}, {"price": "0.9", "size": "13"}, {"price": "0.89", "size": "11.81"}, {"price": "0.82", "size": "66.66"}, {"price": "0.81", "size": "20"}, {"price": "0.66", "size": "5.5"}, {"price": "0.65", "size": "11"}, {"price": "0.64", "size": "71.66"}], "event_type": "book", "last_trade_price": ""}, {"market": "0x5d7fc002c8fbc73a1c18dbb111d96f0ca54e02ae1aa2a6a98ca8d62000f31526", "asset_id": "92027124758235029160948120350916378905334564613489667041482264435793489339845", "timestamp": "1769383857965", "hash": "d8aeca02c09d0286ade51018f0d7b2fe290a9bbe", "bids": [{"price": "0.01", "size": "3465.53"}, {"price": "0.02", "size": "1750"}, {"price": "0.03", "size": "9.72"}, {"price": "0.04", "size": "1000"}, {"price": "0.05", "size": "330"}, {"price": "0.06", "size": "383"}, {"price": "0.07", "size": "306.47"}, {"price": "0.08", "size": "100"}, {"price": "0.09", "size": "22"}, {"price": "0.1", "size": "11"}, {"price": "0.11", "size": "9.99"}, {"price": "0.19", "size": "100"}, {"price": "0.2", "size": "20"}, {"price": "0.35", "size": "41.97"}], "asks": [{"price": "0.99", "size": "166.66"}, {"price": "0.98", "size": "100"}, {"price": "0.97", "size": "166.66"}, {"price": "0.95", "size": "66.66"}], "event_type": "book", "last_trade_price": ""}, {"market": "0x6712272d366398ce29061852de0d2c0491e9d7e8ea99a19d19ff3efd4598d2a8", "asset_id": "56178066173451150343685984219274047856395361836845239123599784229709110987097", "timestamp": "1769384004279", "hash": "d3f20aeaf920a9de54f8c2515682e305561b2ecd", "bids": [{"price": "0.01", "size": "3457.3"}, {"price": "0.02", "size": "1760.51"}, {"price": "0.04", "size": "1000"}, {"price": "0.05", "size": "335.21"}, {"price": "0.06", "size": "383"}, {"price": "0.07", "size": "200"}, {"price": "0.08", "size": "200"}, {"price": "0.09", "size": "22"}, {"price": "0.1", "size": "6.4"}, {"price": "0.11", "size": "7"}, {"price": "0.12", "size": "6.79"}, {"price": "0.19", "size": "100"}, {"price": "0.2", "size": "20"}, {"price": "0.35", "size": "8.76"}, {"price": "0.36", "size": "11.2"}], "asks": [{"price": "0.99", "size": "122.28"}, {"price": "0.98", "size": "150"}, {"price": "0.97", "size": "11.14"}], "event_type": "book", "last_trade_price": ""}, {"market": "0xeef43874b81cc0757ba626b32f26f9996b46dae4eba80f5f3a6d844d3d9d9c72", "asset_id": "16555962920456115566193796591494783460704222042973319196133524975798294457096", "timestamp": "1769383620458", "hash": "3066555d15d886c86da607d73e81efd75b34e725", "bids": [{"price": "0.01", "size": "100"}, {"price": "0.02", "size": "150"}], "asks": [{"price": "0.99", "size": "3424.18"}, {"price": "0.98", "size": "1760.83"}, {"price": "0.96", "size": "1000"}, {"price": "0.95", "size": "335.37"}, {"price": "0.94", "size": "383"}, {"price": "0.93", "size": "300"}, {"price": "0.92", "size": "100"}, {"price": "0.91", "size": "22"}, {"price": "0.9", "size": "6.39"}, {"price": "0.89", "size": "7"}, {"price": "0.88", "size": "6.66"}, {"price": "0.81", "size": "66.66"}, {"price": "0.71", "size": "36.97"}, {"price": "0.7", "size": "20"}, {"price": "0.62", "size": "71.66"}], "event_type": "book", "last_trade_price": ""}, {"market": "0xc612823cb31b05616a21cccb759208907407c35df6bc569f2d0b7cca24b32a79", "asset_id": "32953922581609206145174885766715609822292106660331499258910541650680032752892", "timestamp": "1769383149801", "hash": "6dc89448b7577e5317325970c79775dadd285e07", "bids": [{"price": "0.01", "size": "4429.54"}, {"price": "0.02", "size": "1750"}, {"price": "0.03", "size": "5.77"}, {"price": "0.04", "size": "1700"}, {"price": "0.05", "size": "330"}, {"price": "0.06", "size": "389.49"}, {"price": "0.07", "size": "300"}, {"price": "0.08", "size": "100"}, {"price": "0.09", "size": "22"}, {"price": "0.1", "size": "13"}, {"price": "0.11", "size": "11.89"}, {"price": "0.23", "size": "66.66"}, {"price": "0.27", "size": "46.14"}, {"price": "0.29", "size": "80.83"}, {"price": "0.3", "size": "20"}, {"price": "0.39", "size": "21.4"}, {"price": "0.4", "size": "11.8"}, {"price": "0.46", "size": "71.66"}], "asks": [{"price": "0.99", "size": "150"}], "event_type": "book", "last_trade_price": ""}, {"market": "0x4dd25c542ccc7bacaa13852b65789e3bf860f47e5b6b8a4b63251a82dc351343", "asset_id": "40449888288677466161407105025909896534729388261656969948429208198635959052386", "timestamp": "1769383808664", "hash": "24daf1bc4a618fb9fdcc9cb1c919d2dcb3987164", "bids": [{"price": "0.01", "size": "133.32"}, {"price": "0.02", "size": "50"}, {"price": "0.03", "size": "16.66"}], "asks": [{"price": "0.99", "size": "3424.02"}, {"price": "0.98", "size": "1760.6"}, {"price": "0.96", "size": "1000"}, {"price": "0.95", "size": "335.26"}, {"price": "0.94", "size": "383"}, {"price": "0.93", "size": "200"}, {"price": "0.92", "size": "200"}, {"price": "0.91", "size": "27.18"}, {"price": "0.89", "size": "36.02"}, {"price": "0.84", "size": "19.65"}, {"price": "0.83", "size": "5.79"}, {"price": "0.8", "size": "124.66"}, {"price": "0.79", "size": "20"}, {"price": "0.65", "size": "5.33"}, {"price": "0.64", "size": "11.2"}, {"price": "0.61", "size": "71.66"}], "event_type": "book", "last_trade_price": ""}, {"market": "0x6712272d366398ce29061852de0d2c0491e9d7e8ea99a19d19ff3efd4598d2a8", "asset_id": "66557211105864080610543279993701525059396563696536665254648897603357354477813", "timestamp": "1769384004279", "hash": "23a34c65ba7394b9d0920c07e7dbfd9b0e817e2d", "bids": [{"price": "0.01", "size": "122.28"}, {"price": "0.02", "size": "150"}, {"price": "0.03", "size": "11.14"}], "asks": [{"price": "0.99", "size": "3457.3"}, {"price": "0.98", "size": "1760.51"}, {"price": "0.96", "size": "1000"}, {"price": "0.95", "size": "335.21"}, {"price": "0.94", "size": "383"}, {"price": "0.93", "size": "200"}, {"price": "0.92", "size": "200"}, {"price": "0.91", "size": "22"}, {"price": "0.9", "size": "6.4"}, {"price": "0.89", "size": "7"}, {"price": "0.88", "size": "6.79"}, {"price": "0.81", "size": "100"}, {"price": "0.8", "size": "20"}, {"price": "0.65", "size": "8.76"}, {"price": "0.64", "size": "11.2"}], "event_type": "book", "last_trade_price": ""}, {"market": "0x17f82e3b0e0c8a89c94db772bdae69e847829166d6dc669bc810dd9c3e887e7d", "asset_id": "7029339265071828454381282976374049811411143787209307871045939933169945390178", "timestamp": "1769383977265", "hash": "79e899278fec7eaad65ff5893ab39d1b651b2c9e", "bids": [{"price": "0.01", "size": "3464.72"}, {"price": "0.02", "size": "1750"}, {"price": "0.03", "size": "6.98"}, {"price": "0.04", "size": "1000"}, {"price": "0.05", "size": "330"}, {"price": "0.06", "size": "388.72"}, {"price": "0.07", "size": "300"}, {"price": "0.08", "size": "100"}, {"price": "0.09", "size": "22"}, {"price": "0.1", "size": "13"}, {"price": "0.11", "size": "11.81"}, {"price": "0.2", "size": "100"}, {"price": "0.21", "size": "20"}, {"price": "0.36", "size": "8.6"}, {"price": "0.37", "size": "16.3"}], "asks": [{"price": "0.99", "size": "122.28"}, {"price": "0.98", "size": "150"}, {"price": "0.97", "size": "11.14"}], "event_type": "book", "last_trade_price": ""}, {"market": "0x5d7fc002c8fbc73a1c18dbb111d96f0ca54e02ae1aa2a6a98ca8d62000f31526", "asset_id": "49246609416501398794937573302498657712519224305673745144194417177683023634127", "timestamp": "1769383857965", "hash": "1f35775be3bfb60352637b4c91ce094d99a7f4c8", "bids": [{"price": "0.01", "size": "166.66"}, {"price": "0.02", "size": "100"}, {"price": "0.03", "size": "166.66"}, {"price": "0.05", "size": "66.66"}], "asks": [{"price": "0.99", "size": "3465.53"}, {"price": "0.98", "size": "1750"}, {"price": "0.97", "size": "9.72"}, {"price": "0.96", "size": "1000"}, {"price": "0.95", "size": "330"}, {"price": "0.94", "size": "383"}, {"price": "0.93", "size": "306.47"}, {"price": "0.92", "size": "100"}, {"price": "0.91", "size": "22"}, {"price": "0.9", "size": "11"}, {"price": "0.89", "size": "9.99"}, {"price": "0.81", "size": "100"}, {"price": "0.8", "size": "20"}, {"price": "0.65", "size": "41.97"}], "event_type": "book", "last_trade_price": ""}, {"market": "0x4dd25c542ccc7bacaa13852b65789e3bf860f47e5b6b8a4b63251a82dc351343", "asset_id": "69940668700050123184332060950192865871206736155068150467256714825915478178996", "timestamp": "1769383808664", "hash": "894c9c35cc7a815eda8d2e35f408fd6ef7b23b97", "bids": [{"price": "0.01", "size": "3424.02"}, {"price": "0.02", "size": "1760.6"}, {"price": "0.04", "size": "1000"}, {"price": "0.05", "size": "335.26"}, {"price": "0.06", "size": "383"}, {"price": "0.07", "size": "200"}, {"price": "0.08", "size": "200"}, {"price": "0.09", "size": "27.18"}, {"price": "0.11", "size": "36.02"}, {"price": "0.16", "size": "19.65"}, {"price": "0.17", "size": "5.79"}, {"price": "0.2", "size": "124.66"}, {"price": "0.21", "size": "20"}, {"price": "0.35", "size": "5.33"}, {"price": "0.36", "size": "11.2"}, {"price": "0.39", "size": "71.66"}], "asks": [{"price": "0.99", "size": "133.32"}, {"price": "0.98", "size": "50"}, {"price": "0.97", "size": "16.66"}], "event_type": "book", "last_trade_price": ""}, {"market": "0xe85baf2d19b31992225c1a85bf7449aa2cfd4a4bb1f28f4c3e4bb29db3b7f875", "asset_id": "83097217665829663259227348996700236731863115053371148291567024695813446800824", "timestamp": "1769383938300", "hash": "83b8c5b0ed53838abf635e9b5762b325ed8fbe81", "bids": [{"price": "0.01", "size": "4423.8"}, {"price": "0.02", "size": "1760.51"}, {"price": "0.04", "size": "1700"}, {"price": "0.05", "size": "335.21"}, {"price": "0.06", "size": "383"}, {"price": "0.07", "size": "100"}, {"price": "0.08", "size": "100"}, {"price": "0.09", "size": "200"}, {"price": "0.1", "size": "34.57"}, {"price": "0.2", "size": "66.66"}, {"price": "0.21", "size": "33"}, {"price": "0.26", "size": "38.93"}, {"price": "0.27", "size": "20"}, {"price": "0.33", "size": "59.79"}, {"price": "0.39", "size": "71.66"}], "asks": [{"price": "0.99", "size": "166.66"}, {"price": "0.98", "size": "100"}, {"price": "0.97", "size": "66.66"}, {"price": "0.96", "size": "50"}, {"price": "0.95", "size": "66.66"}], "event_type": "book", "last_trade_price": ""}]}
{"_local_timestamp": "2026-01-25T23:34:04.014822+00:00", "data": {"market": "0x91dd8dbe75a5347f14455ca880070ebcf3356bfd7df8caf19478e881bb483efb", "price_changes": [{"asset_id": "23125627318359544367614218401841961178939444671222355150077267933985277277448", "price": "0.79", "size": "25", "side": "SELL", "hash": "b68546781a74dbd73e28a70077fdc719a2b11a09", "best_bid": "0.09", "best_ask": "0.79"}, {"asset_id": "30112939078428479271380004766658148462656808495063824079473460276372582172087", "price": "0.21", "size": "25", "side": "BUY", "hash": "12b50bfdeb82a6900244231638e1fda200105550", "best_bid": "0.21", "best_ask": "0.91"}], "timestamp": "1769384043947", "event_type": "price_change"}}
{"_local_timestamp": "2026-01-25T23:34:04.462508+00:00", "data": {"market": "0x6712272d366398ce29061852de0d2c0491e9d7e8ea99a19d19ff3efd4598d2a8", "price_changes": [{"asset_id": "66557211105864080610543279993701525059396563696536665254648897603357354477813", "price": "0.64", "size": "16.2", "side": "SELL", "hash": "80434fb79a97913d14e2e4c1ea99409f30daa785", "best_bid": "0.03", "best_ask": "0.64"}, {"asset_id": "56178066173451150343685984219274047856395361836845239123599784229709110987097", "price": "0.36", "size": "16.2", "side": "BUY", "hash": "3ed1990b6bea7b08b074f0c26d01fa4f2fa5057b", "best_bid": "0.36", "best_ask": "0.97"}], "timestamp": "1769384044393", "event_type": "price_change"}}
{"_local_timestamp": "2026-01-25T23:34:12.924217+00:00", "data": {"market": "0xe85baf2d19b31992225c1a85bf7449aa2cfd4a4bb1f28f4c3e4bb29db3b7f875", "price_changes": [{"asset_id": "83097217665829663259227348996700236731863115053371148291567024695813446800824", "price": "0.08", "size": "0", "side": "BUY", "hash": "df7108d8ba9affbb2eda33dea957889a0f6b0636", "best_bid": "0.39", "best_ask": "0.95"}, {"asset_id": "42804374308926637512138626004807193961451331812554996198443523509803582210982", "price": "0.92", "size": "0", "side": "SELL", "hash": "f049ce9a5c25ec52e975768a748d1c2a786e8874", "best_bid": "0.05", "best_ask": "0.61"}], "timestamp": "1769384052803", "event_type": "price_change"}}
{"_local_timestamp": "2026-01-25T23:34:12.949693+00:00", "data": {"market": "0x19806c2aa819b06cd6112367c68a86cfcd04a5daf5e471977ea8310f241d0b25", "price_changes": [{"asset_id": "108953599859488748640167315424223285692135226463528980107326118523345159966905", "price": "0.09", "size": "0", "side": "BUY", "hash": "4edfd82f326cebae52c50be96e2f435251ee5e89", "best_bid": "0.46", "best_ask": "0.97"}, {"asset_id": "95224365708745593619811400419827796915292296641493778634960081360586269890047", "price": "0.91", "size": "0", "side": "SELL", "hash": "d9a5f10b479f6636be838317d894d29455c606c5", "best_bid": "0.03", "best_ask": "0.54"}], "timestamp": "1769384052803", "event_type": "price_change"}}
{"_local_timestamp": "2026-01-25T23:34:13.417356+00:00", "data": {"market": "0xe85baf2d19b31992225c1a85bf7449aa2cfd4a4bb1f28f4c3e4bb29db3b7f875", "price_changes": [{"asset_id": "83097217665829663259227348996700236731863115053371148291567024695813446800824", "price": "0.07", "size": "200", "side": "BUY", "hash": "744c771cc6238855616296da429d313110fbb335", "best_bid": "0.39", "best_ask": "0.95"}, {"asset_id": "42804374308926637512138626004807193961451331812554996198443523509803582210982", "price": "0.93", "size": "200", "side": "SELL", "hash": "4a45817fb8482fa01464c2c822b7edb3c5ec5022", "best_bid": "0.05", "best_ask": "0.61"}], "timestamp": "1769384053271", "event_type": "price_change"}}
{"_local_timestamp": "2026-01-25T23:34:34.052538+00:00", "data": {"market": "0x91dd8dbe75a5347f14455ca880070ebcf3356bfd7df8caf19478e881bb483efb", "price_changes": [{"asset_id": "30112939078428479271380004766658148462656808495063824079473460276372582172087", "price": "0.21", "size": "120", "side": "BUY", "hash": "2e9fd707a05ebd6d5e0cf11438a1db175f34e243", "best_bid": "0.21", "best_ask": "0.91"}, {"asset_id": "23125627318359544367614218401841961178939444671222355150077267933985277277448", "price": "0.79", "size": "120", "side": "SELL", "hash": "612429d8c35b2687e93a333d742974efb6d1a3be", "best_bid": "0.09", "best_ask": "0.79"}], "timestamp": "1769384073961", "event_type": "price_change"}}
{"_local_timestamp": "2026-01-25T23:34:34.065866+00:00", "data": {"market": "0x5d7fc002c8fbc73a1c18dbb111d96f0ca54e02ae1aa2a6a98ca8d62000f31526", "price_changes": [{"asset_id": "92027124758235029160948120350916378905334564613489667041482264435793489339845", "price": "0.21", "size": "95", "side": "BUY", "hash": "55dfd53e38e6e70c8321fb1f8c8bc0f704e97b34", "best_bid": "0.35", "best_ask": "0.95"}, {"asset_id": "49246609416501398794937573302498657712519224305673745144194417177683023634127", "price": "0.79", "size": "95", "side": "SELL", "hash": "a1900775e6e0574b94dd90dd26e48e21a4160498", "best_bid": "0.05", "best_ask": "0.65"}], "timestamp": "1769384073961", "event_type": "price_change"}}
{"_local_timestamp": "2026-01-25T23:34:34.070899+00:00", "data": {"market": "0x5d7fc002c8fbc73a1c18dbb111d96f0ca54e02ae1aa2a6a98ca8d62000f31526", "price_changes": [{"asset_id": "92027124758235029160948120350916378905334564613489667041482264435793489339845", "price": "0.2", "size": "115", "side": "BUY", "hash": "0e9a53da0b856430e09faf0ec0ed368609d2123d", "best_bid": "0.35", "best_ask": "0.95"}, {"asset_id": "49246609416501398794937573302498657712519224305673745144194417177683023634127", "price": "0.8", "size": "115", "side": "SELL", "hash": "b22ca23f8f1537f9078f96da8da06b4b13274ef8", "best_bid": "0.05", "best_ask": "0.65"}], "timestamp": "1769384073962", "event_type": "price_change"}}
{"_local_timestamp": "2026-01-25T23:34:34.075903+00:00", "data": {"market": "0x91dd8dbe75a5347f14455ca880070ebcf3356bfd7df8caf19478e881bb483efb", "price_changes": [{"asset_id": "30112939078428479271380004766658148462656808495063824079473460276372582172087", "price": "0.22", "size": "95", "side": "BUY", "hash": "b6e9a3562c2ffe14abc3dca6bd6227a41315e8f2", "best_bid": "0.22", "best_ask": "0.91"}, {"asset_id": "23125627318359544367614218401841961178939444671222355150077267933985277277448", "price": "0.78", "size": "95", "side": "SELL", "hash": "4855dc2823b5c0e6437ba1a2b740d8a60a8c8da8", "best_bid": "0.09", "best_ask": "0.78"}], "timestamp": "1769384073962", "event_type": "price_change"}}
{"_local_timestamp": "2026-01-25T23:34:35.172983+00:00", "data": {"market": "0x4dd25c542ccc7bacaa13852b65789e3bf860f47e5b6b8a4b63251a82dc351343", "price_changes": [{"asset_id": "40449888288677466161407105025909896534729388261656969948429208198635959052386", "price": "0.04", "size": "29.99", "side": "BUY", "hash": "72406c66aecb8d63c92988d0316941c0096d36cd", "best_bid": "0.04", "best_ask": "0.61"}, {"asset_id": "69940668700050123184332060950192865871206736155068150467256714825915478178996", "price": "0.96", "size": "29.99", "side": "SELL", "hash": "41b3105e20ca249f58037f648811388eb4c06e4a", "best_bid": "0.39", "best_ask": "0.96"}], "timestamp": "1769384075082", "event_type": "price_change"}}
{"_local_timestamp": "2026-01-25T23:34:36.615716+00:00", "data": {"market": "0x5d7fc002c8fbc73a1c18dbb111d96f0ca54e02ae1aa2a6a98ca8d62000f31526", "price_changes": [{"asset_id": "92027124758235029160948120350916378905334564613489667041482264435793489339845", "price": "0.2", "size": "95", "side": "BUY", "hash": "f4b16b9d01da3facd5af44f6619c45acc7365e30", "best_bid": "0.35", "best_ask": "0.95"}, {"asset_id": "49246609416501398794937573302498657712519224305673745144194417177683023634127", "price": "0.8", "size": "95", "side": "SELL", "hash": "59d6a12e745055f35e3f6f1831ecbc4e9326a755", "best_bid": "0.05", "best_ask": "0.65"}], "timestamp": "1769384076548", "event_type": "price_change"}}
{"_local_timestamp": "2026-01-25T23:34:36.616189+00:00", "data": {"market": "0x91dd8dbe75a5347f14455ca880070ebcf3356bfd7df8caf19478e881bb483efb", "price_changes": [{"asset_id": "30112939078428479271380004766658148462656808495063824079473460276372582172087", "price": "0.21", "size": "100", "side": "BUY", "hash": "6d786235e0217b8b74501c1b7d85ce3d32421b6b", "best_bid": "0.22", "best_ask": "0.91"}, {"asset_id": "23125627318359544367614218401841961178939444671222355150077267933985277277448", "price": "0.79", "size": "100", "side": "SELL", "hash": "f7471c2ea49eb2afa6a316c685b6ed4e21129517", "best_bid": "0.09", "best_ask": "0.78"}], "timestamp": "1769384076548", "event_type": "price_change"}}
{"_local_timestamp": "2026-01-25T23:34:36.636875+00:00", "data": {"market": "0x5d7fc002c8fbc73a1c18dbb111d96f0ca54e02ae1aa2a6a98ca8d62000f31526", "price_changes": [{"asset_id": "92027124758235029160948120350916378905334564613489667041482264435793489339845", "price": "0.22", "size": "20", "side": "BUY", "hash": "a10cbb256d89d647196e5f79ae0d1411c5a6186f", "best_bid": "0.35", "best_ask": "0.95"}, {"asset_id": "49246609416501398794937573302498657712519224305673745144194417177683023634127", "price": "0.78", "size": "20", "side": "SELL", "hash": "706fbf6a63641fb483fcbea384c4a81a964eacee", "best_bid": "0.05", "best_ask": "0.65"}], "timestamp": "1769384076574", "event_type": "price_change"}}
{"_local_timestamp": "2026-01-25T23:34:36.647231+00:00", "data": {"market": "0x91dd8dbe75a5347f14455ca880070ebcf3356bfd7df8caf19478e881bb483efb", "price_changes": [{"asset_id": "30112939078428479271380004766658148462656808495063824079473460276372582172087", "price": "0.23", "size": "20", "side": "BUY", "hash": "875b9819527aee0a1e07e7a6450fc321e4865642", "best_bid": "0.23", "best_ask": "0.91"}, {"asset_id": "23125627318359544367614218401841961178939444671222355150077267933985277277448", "price": "0.77", "size": "20", "side": "SELL", "hash": "fec2ad274bc370b00f4978b26b488b86832d77a3", "best_bid": "0.09", "best_ask": "0.77"}], "timestamp": "1769384076574", "event_type": "price_change"}}
{"_local_timestamp": "2026-01-25T23:34:54.635580+00:00", "data": {"market": "0x91dd8dbe75a5347f14455ca880070ebcf3356bfd7df8caf19478e881bb483efb", "price_changes": [{"asset_id": "30112939078428479271380004766658148462656808495063824079473460276372582172087", "price": "0.06", "size": "349.66", "side": "BUY", "hash": "62a02fba1d5b82543f0dd370821f7ce098935245", "best_bid": "0.23", "best_ask": "0.91"}, {"asset_id": "23125627318359544367614218401841961178939444671222355150077267933985277277448", "price": "0.94", "size": "349.66", "side": "SELL", "hash": "8d9f3ea8430a88161b1c8468813075f6f2708968", "best_bid": "0.09", "best_ask": "0.77"}], "timestamp": "1769384094550", "event_type": "price_change"}}
{"_local_timestamp": "2026-01-25T23:34:54.636585+00:00", "data": {"market": "0x2bec0b2b3562bfcde13572021ee5567bc938f4b6a883accdb3c44c9fb7c93de5", "price_changes": [{"asset_id": "67549588035777013004185630772872416152611090585479410333854543423443737102097", "price": "0.06", "size": "288.61", "side": "BUY", "hash": "fddaf20c912ce2928f0ffcfb97e85484535ab8ce", "best_bid": "0.36", "best_ask": "0.94"}, {"asset_id": "22621900385203545572961259607481335836574764520983045149819679201843742949126", "price": "0.94", "size": "288.61", "side": "SELL", "hash": "f4bee6942c532e7032de40297a0f3138f947b7ff", "best_bid": "0.06", "best_ask": "0.64"}], "timestamp": "1769384094550", "event_type": "price_change"}}
{"_local_timestamp": "2026-01-25T23:34:54.636926+00:00", "data": {"market": "0x4dd25c542ccc7bacaa13852b65789e3bf860f47e5b6b8a4b63251a82dc351343", "price_changes": [{"asset_id": "69940668700050123184332060950192865871206736155068150467256714825915478178996", "price": "0.08", "size": "100", "side": "BUY", "hash": "28147feb21326c921da0014984769f4d91aeff26", "best_bid": "0.39", "best_ask": "0.96"}, {"asset_id": "40449888288677466161407105025909896534729388261656969948429208198635959052386", "price": "0.92", "size": "100", "side": "SELL", "hash": "1844ccbfdb41c37ee4568f5ab16c325f42155741", "best_bid": "0.04", "best_ask": "0.61"}], "timestamp": "1769384094550", "event_type": "price_change"}}
{"_local_timestamp": "2026-01-25T23:34:54.637438+00:00", "data": {"market": "0xeef43874b81cc0757ba626b32f26f9996b46dae4eba80f5f3a6d844d3d9d9c72", "price_changes": [{"asset_id": "48021162790402851216178343019771947189732554762782810353642610100613247118491", "price": "0.06", "size": "283", "side": "BUY", "hash": "61701c350976fe9e01fdc5c9311e47bdb06b570f", "best_bid": "0.38", "best_ask": "0.98"}, {"asset_id": "16555962920456115566193796591494783460704222042973319196133524975798294457096", "price": "0.94", "size": "283", "side": "SELL", "hash": "0750cef19304b19eafce0c109f10793eb3593722", "best_bid": "0.02", "best_ask": "0.62"}], "timestamp": "1769384094550", "event_type": "price_change"}}
{"_local_timestamp": "2026-01-25T23:34:54.638826+00:00", "data": {"market": "0x6712272d366398ce29061852de0d2c0491e9d7e8ea99a19d19ff3efd4598d2a8", "price_changes": [{"asset_id": "56178066173451150343685984219274047856395361836845239123599784229709110987097", "price": "0.08", "size": "100", "side": "BUY", "hash": "95c8360c13bf2b6c12d3d0d7fb12056e50d6a295", "best_bid": "0.36", "best_ask": "0.97"}, {"asset_id": "66557211105864080610543279993701525059396563696536665254648897603357354477813", "price": "0.92", "size": "100", "side": "SELL", "hash": "6f16959536da4d3d04981084eb7d077e34222239", "best_bid": "0.03", "best_ask": "0.64"}], "timestamp": "1769384094552", "event_type": "price_change"}}
{"_local_timestamp": "2026-01-25T23:34:54.647245+00:00", "data": {"market": "0xc612823cb31b05616a21cccb759208907407c35df6bc569f2d0b7cca24b32a79", "price_changes": [{"asset_id": "32953922581609206145174885766715609822292106660331499258910541650680032752892", "price": "0.06", "size": "289.49", "side": "BUY", "hash": "74e4a124a6b98e7f32163263d0ce2a48379cdea8", "best_bid": "0.46", "best_ask": "0.99"}, {"asset_id": "27850200924917452779525076978818364368393998746365953803788220678381853982397", "price": "0.94", "size": "289.49", "side": "SELL", "hash": "39dec036ae796d832ea919b2e6fe95c95eadbf4a", "best_bid": "0.01", "best_ask": "0.54"}], "timestamp": "1769384094551", "event_type": "price_change"}}
{"_local_timestamp": "2026-01-25T23:34:54.957706+00:00", "data": {"market": "0xeef43874b81cc0757ba626b32f26f9996b46dae4eba80f5f3a6d844d3d9d9c72", "price_changes": [{"asset_id": "48021162790402851216178343019771947189732554762782810353642610100613247118491", "price": "0.08", "size": "200", "side": "BUY", "hash": "b109d8d1e2d28e0b29cdac358062d802831f1d48", "best_bid": "0.38", "best_ask": "0.98"}, {"asset_id": "16555962920456115566193796591494783460704222042973319196133524975798294457096", "price": "0.92", "size": "200", "side": "SELL", "hash": "fdd7b566eaae2ddebf0723e534876977fa48463f", "best_bid": "0.02", "best_ask": "0.62"}], "timestamp": "1769384094886", "event_type": "price_change"}}
{"_local_timestamp": "2026-01-25T23:34:54.966352+00:00", "data": {"market": "0x91dd8dbe75a5347f14455ca880070ebcf3356bfd7df8caf19478e881bb483efb", "price_changes": [{"asset_id": "30112939078428479271380004766658148462656808495063824079473460276372582172087", "price": "0.08", "size": "200", "side": "BUY", "hash": "ecf9bedbbdc4c3b8f1f6736eccc31e50d6719bff", "best_bid": "0.23", "best_ask": "0.91"}, {"asset_id": "23125627318359544367614218401841961178939444671222355150077267933985277277448", "price": "0.92", "size": "200", "side": "SELL", "hash": "7bde3720217714a3f975f61635ad576fa1d81120", "best_bid": "0.09", "best_ask": "0.77"}], "timestamp": "1769384094886", "event_type": "price_change"}}
{"_local_timestamp": "2026-01-25T23:34:54.970439+00:00", "data": {"market": "0x4dd25c542ccc7bacaa13852b65789e3bf860f47e5b6b8a4b63251a82dc351343", "price_changes": [{"asset_id": "69940668700050123184332060950192865871206736155068150467256714825915478178996", "price": "0.07", "size": "300", "side": "BUY", "hash": "e363105ced0c44162f26fd26e3aff2dc5de76ac2", "best_bid": "0.39", "best_ask": "0.96"}, {"asset_id": "40449888288677466161407105025909896534729388261656969948429208198635959052386", "price": "0.93", "size": "300", "side": "SELL", "hash": "dc3b52a7a78e721474cd156b8322a944098d39b5", "best_bid": "0.04", "best_ask": "0.61"}], "timestamp": "1769384094881", "event_type": "price_change"}}
{"_local_timestamp": "2026-01-25T23:34:54.971353+00:00", "data": {"market": "0x6712272d366398ce29061852de0d2c0491e9d7e8ea99a19d19ff3efd4598d2a8", "price_changes": [{"asset_id": "56178066173451150343685984219274047856395361836845239123599784229709110987097", "price": "0.07", "size": "300", "side": "BUY", "hash": "9e45fe95ae7a46a3a799d007afc354eefba280c5", "best_bid": "0.36", "best_ask": "0.97"}, {"asset_id": "66557211105864080610543279993701525059396563696536665254648897603357354477813", "price": "0.93", "size": "300", "side": "SELL", "hash": "f90b6ca04e44a54fb6d32e2c5585debf06ecd9e7", "best_bid": "0.03", "best_ask": "0.64"}], "timestamp": "1769384094881", "event_type": "price_change"}}
{"_local_timestamp": "2026-01-25T23:34:54.978791+00:00", "data": {"market": "0x2bec0b2b3562bfcde13572021ee5567bc938f4b6a883accdb3c44c9fb7c93de5", "price_changes": [{"asset_id": "67549588035777013004185630772872416152611090585479410333854543423443737102097", "price": "0.08", "size": "200", "side": "BUY", "hash": "8539dbf78551c90d5930a6489004ad01dede3f37", "best_bid": "0.36", "best_ask": "0.94"}, {"asset_id": "22621900385203545572961259607481335836574764520983045149819679201843742949126", "price": "0.92", "size": "200", "side": "SELL", "hash": "08b6a757fcbc43b8840a75080849e0d0dea20c65", "best_bid": "0.06", "best_ask": "0.64"}], "timestamp": "1769384094885", "event_type": "price_change"}}
{"_local_timestamp": "2026-01-25T23:34:54.979470+00:00", "data": {"market": "0xc612823cb31b05616a21cccb759208907407c35df6bc569f2d0b7cca24b32a79", "price_changes": [{"asset_id": "32953922581609206145174885766715609822292106660331499258910541650680032752892", "price": "0.08", "size": "200", "side": "BUY", "hash": "9b2de1b1e7b25680b2d510202f8b32f13aa4ec48", "best_bid": "0.46", "best_ask": "0.99"}, {"asset_id": "27850200924917452779525076978818364368393998746365953803788220678381853982397", "price": "0.92", "size": "200", "side": "SELL", "hash": "7afeb63990b6c31dc0db5e6610f0e42b404ff031", "best_bid": "0.01", "best_ask": "0.54"}], "timestamp": "1769384094884", "event_type": "price_change"}}
{"_local_timestamp": "2026-01-25T23:34:55.354572+00:00", "data": {"market": "0x5d7fc002c8fbc73a1c18dbb111d96f0ca54e02ae1aa2a6a98ca8d62000f31526", "price_changes": [{"asset_id": "92027124758235029160948120350916378905334564613489667041482264435793489339845", "price": "0.2", "size": "0", "side": "BUY", "hash": "09ff14d06e2f6debbc57649705bfe3163d693b93", "best_bid": "0.35", "best_ask": "0.95"}, {"asset_id": "49246609416501398794937573302498657712519224305673745144194417177683023634127", "price": "0.8", "size": "0", "side": "SELL", "hash": "2454cd4a236978e3f33a68cb073614f0a3784317", "best_bid": "0.05", "best_ask": "0.65"}], "timestamp": "1769384095233", "event_type": "price_change"}}
{"_local_timestamp": "2026-01-25T23:34:55.364816+00:00", "data": {"market": "0x91dd8dbe75a5347f14455ca880070ebcf3356bfd7df8caf19478e881bb483efb", "price_changes": [{"asset_id": "30112939078428479271380004766658148462656808495063824079473460276372582172087", "price": "0.21", "size": "5", "side": "BUY", "hash": "760ad0af2f80327a862a56b02452ee5dfdf011d2", "best_bid": "0.23", "best_ask": "0.91"}, {"asset_id": "23125627318359544367614218401841961178939444671222355150077267933985277277448", "price": "0.79", "size": "5", "side": "SELL", "hash": "53320b8f2a1b0314f7a31a8b30993248ddac3bff", "best_bid": "0.09", "best_ask": "0.77"}], "timestamp": "1769384095233", "event_type": "price_change"}}
{"_local_timestamp": "2026-01-25T23:35:16.593256+00:00", "data": {"market": "0x91dd8dbe75a5347f14455ca880070ebcf3356bfd7df8caf19478e881bb483efb", "price_changes": [{"asset_id": "23125627318359544367614218401841961178939444671222355150077267933985277277448", "price": "0.79", "size": "0", "side": "SELL", "hash": "4db7e03e59f44ffaa86099c6c1af9f3059083de7", "best_bid": "0.09", "best_ask": "0.77"}, {"asset_id": "30112939078428479271380004766658148462656808495063824079473460276372582172087", "price": "0.21", "size": "0", "side": "BUY", "hash": "91f3f5d896c603c65fd50a5ce7f5655364732bc8", "best_bid": "0.23", "best_ask": "0.91"}], "timestamp": "1769384116370", "event_type": "price_change"}}
{"_local_timestamp": "2026-01-25T23:35:40.251327+00:00", "data": {"market": "0x4dd25c542ccc7bacaa13852b65789e3bf860f47e5b6b8a4b63251a82dc351343", "price_changes": [{"asset_id": "40449888288677466161407105025909896534729388261656969948429208198635959052386", "price": "0.01", "size": "116.66", "side": "BUY", "hash": "4c690e60687a91da2de5a892e3bfa25ce49a8a67", "best_bid": "0.04", "best_ask": "0.61"}, {"asset_id": "69940668700050123184332060950192865871206736155068150467256714825915478178996", "price": "0.99", "size": "116.66", "side": "SELL", "hash": "63d9b3bf2a0e313d0ab7fe9e1661d5979afb9a02", "best_bid": "0.39", "best_ask": "0.96"}], "timestamp": "1769384140179", "event_type": "price_change"}}
{"_local_timestamp": "2026-01-25T23:35:40.252281+00:00", "data": {"market": "0x5d7fc002c8fbc73a1c18dbb111d96f0ca54e02ae1aa2a6a98ca8d62000f31526", "price_changes": [{"asset_id": "92027124758235029160948120350916378905334564613489667041482264435793489339845", "price": "0.19", "size": "0", "side": "BUY", "hash": "4465652af702ed71a1d66be6b11a97514267c782", "best_bid": "0.35", "best_ask": "0.95"}, {"asset_id": "49246609416501398794937573302498657712519224305673745144194417177683023634127", "price": "0.81", "size": "0", "side": "SELL", "hash": "8f1058f1ca93696be18282408d42420c7da8d898", "best_bid": "0.05", "best_ask": "0.65"}], "timestamp": "1769384140179", "event_type": "price_change"}}
{"_local_timestamp": "2026-01-25T23:35:40.253189+00:00", "data": {"market": "0x91dd8dbe75a5347f14455ca880070ebcf3356bfd7df8caf19478e881bb483efb", "price_changes": [{"asset_id": "30112939078428479271380004766658148462656808495063824079473460276372582172087", "price": "0.2", "size": "0", "side": "BUY", "hash": "901d0c23ef20c3f305c635d8c98a53e33efb25f7", "best_bid": "0.23", "best_ask": "0.91"}, {"asset_id": "23125627318359544367614218401841961178939444671222355150077267933985277277448", "price": "0.8", "size": "0", "side": "SELL", "hash": "5b4dc5e1ab14fd110651aef8d7a23676fed049b9", "best_bid": "0.09", "best_ask": "0.77"}], "timestamp": "1769384140179", "event_type": "price_change"}}
{"_local_timestamp": "2026-01-25T23:35:40.253521+00:00", "data": {"market": "0x6712272d366398ce29061852de0d2c0491e9d7e8ea99a19d19ff3efd4598d2a8", "price_changes": [{"asset_id": "56178066173451150343685984219274047856395361836845239123599784229709110987097", "price": "0.19", "size": "0", "side": "BUY", "hash": "7131c0d8eeba20e21ab3f5b096415801a04f5c9c", "best_bid": "0.36", "best_ask": "0.97"}, {"asset_id": "66557211105864080610543279993701525059396563696536665254648897603357354477813", "price": "0.81", "size": "0", "side": "SELL", "hash": "3da7c3915203f0bd957c5d7224ec479114306ea3", "best_bid": "0.03", "best_ask": "0.64"}], "timestamp": "1769384140179", "event_type": "price_change"}}
{"_local_timestamp": "2026-01-25T23:35:40.253843+00:00", "data": {"market": "0x5d7fc002c8fbc73a1c18dbb111d96f0ca54e02ae1aa2a6a98ca8d62000f31526", "price_changes": [{"asset_id": "92027124758235029160948120350916378905334564613489667041482264435793489339845", "price": "0.01", "size": "3365.53", "side": "BUY", "hash": "4465652af702ed71a1d66be6b11a97514267c782", "best_bid": "0.35", "best_ask": "0.95"}, {"asset_id": "49246609416501398794937573302498657712519224305673745144194417177683023634127", "price": "0.99", "size": "3365.53", "side": "SELL", "hash": "8f1058f1ca93696be18282408d42420c7da8d898", "best_bid": "0.05", "best_ask": "0.65"}], "timestamp": "1769384140179", "event_type": "price_change"}}
{"_local_timestamp": "2026-01-25T23:35:40.254249+00:00", "data": {"market": "0x6712272d366398ce29061852de0d2c0491e9d7e8ea99a19d19ff3efd4598d2a8", "price_changes": [{"asset_id": "56178066173451150343685984219274047856395361836845239123599784229709110987097", "price": "0.01", "size": "3357.3", "side": "BUY", "hash": "7131c0d8eeba20e21ab3f5b096415801a04f5c9c", "best_bid": "0.36", "best_ask": "0.97"}, {"asset_id": "66557211105864080610543279993701525059396563696536665254648897603357354477813", "price": "0.99", "size": "3357.3", "side": "SELL", "hash": "3da7c3915203f0bd957c5d7224ec479114306ea3", "best_bid": "0.03", "best_ask": "0.64"}], "timestamp": "1769384140179", "event_type": "price_change"}}
{"_local_timestamp": "2026-01-25T23:35:41.315243+00:00", "data": {"market": "0x4dd25c542ccc7bacaa13852b65789e3bf860f47e5b6b8a4b63251a82dc351343", "price_changes": [{"asset_id": "40449888288677466161407105025909896534729388261656969948429208198635959052386", "price": "0.05", "size": "16.66", "side": "BUY", "hash": "967e782a29bced6daa6f01a4c56686b73a74ffd2", "best_bid": "0.05", "best_ask": "0.61"}, {"asset_id": "69940668700050123184332060950192865871206736155068150467256714825915478178996", "price": "0.95", "size": "16.66", "side": "SELL", "hash": "352929d2daf2a536801e931da1f6636d3c4ee852", "best_bid": "0.39", "best_ask": "0.95"}], "timestamp": "1769384141250", "event_type": "price_change"}}
{"_local_timestamp": "2026-01-25T23:35:41.355444+00:00", "data": {"market": "0x91dd8dbe75a5347f14455ca880070ebcf3356bfd7df8caf19478e881bb483efb", "price_changes": [{"asset_id": "30112939078428479271380004766658148462656808495063824079473460276372582172087", "price": "0.24", "size": "66.66", "side": "BUY", "hash": "086aa3eb2a39450b3ed3ea11d4ca173e55fbe2e7", "best_bid": "0.24", "best_ask": "0.91"}, {"asset_id": "23125627318359544367614218401841961178939444671222355150077267933985277277448", "price": "0.76", "size": "66.66", "side": "SELL", "hash": "fd3d39f88af784b6797a394644b4c7e9bcda0f70", "best_bid": "0.09", "best_ask": "0.76"}], "timestamp": "1769384141289", "event_type": "price_change"}}
{"_local_timestamp": "2026-01-25T23:35:41.475616+00:00", "data": {"market": "0x6712272d366398ce29061852de0d2c0491e9d7e8ea99a19d19ff3efd4598d2a8", "price_changes": [{"asset_id": "56178066173451150343685984219274047856395361836845239123599784229709110987097", "price": "0.19", "size": "66.66", "side": "BUY", "hash": "146faaf0a73fa6e83796248d1980646b5094fad2", "best_bid": "0.36", "best_ask": "0.97"}, {"asset_id": "66557211105864080610543279993701525059396563696536665254648897603357354477813", "price": "0.81", "size": "66.66", "side": "SELL", "hash": "fbcf02c66836f8ba5e0e6fd260038f6540370bfc", "best_bid": "0.03", "best_ask": "0.64"}], "timestamp": "1769384141408", "event_type": "price_change"}}
{"_local_timestamp": "2026-01-25T23:35:41.514789+00:00", "data": {"market": "0x6712272d366398ce29061852de0d2c0491e9d7e8ea99a19d19ff3efd4598d2a8", "price_changes": [{"asset_id": "56178066173451150343685984219274047856395361836845239123599784229709110987097", "price": "0.37", "size": "66.66", "side": "BUY", "hash": "cee20651cb2a65e10974dda1de441621eb0c370b", "best_bid": "0.37", "best_ask": "0.97"}, {"asset_id": "66557211105864080610543279993701525059396563696536665254648897603357354477813", "price": "0.63", "size": "66.66", "side": "SELL", "hash": "2d054a513cd958c1e6a68e9ab47337ddb799270a", "best_bid": "0.03", "best_ask": "0.63"}], "timestamp": "1769384141446", "event_type": "price_change"}}
{"_local_timestamp": "2026-01-25T23:35:41.548589+00:00", "data": {"market": "0x5d7fc002c8fbc73a1c18dbb111d96f0ca54e02ae1aa2a6a98ca8d62000f31526", "price_changes": [{"asset_id": "92027124758235029160948120350916378905334564613489667041482264435793489339845", "price": "0.18", "size": "66.66", "side": "BUY", "hash": "ccb7f084ac3249118de58cee9d1ef93687515035", "best_bid": "0.35", "best_ask": "0.95"}, {"asset_id": "49246609416501398794937573302498657712519224305673745144194417177683023634127", "price": "0.82", "size": "66.66", "side": "SELL", "hash": "6ed160ac779aa39f7849c95c8fdee98801edabb1", "best_bid": "0.05", "best_ask": "0.65"}], "timestamp": "1769384141480", "event_type": "price_change"}}
{"_local_timestamp": "2026-01-25T23:35:41.684297+00:00", "data": {"market": "0x5d7fc002c8fbc73a1c18dbb111d96f0ca54e02ae1aa2a6a98ca8d62000f31526", "price_changes": [{"asset_id": "92027124758235029160948120350916378905334564613489667041482264435793489339845", "price": "0.01", "size": "3432.19", "side": "BUY", "hash": "83f7d60b0f32e29049fadf5412267dbf02e8e9bc", "best_bid": "0.35", "best_ask": "0.95"}, {"asset_id": "49246609416501398794937573302498657712519224305673745144194417177683023634127", "price": "0.99", "size": "3432.19", "side": "SELL", "hash": "3d52039eb2c78ccb72afa7177654e7bc4f950992", "best_bid": "0.05", "best_ask": "0.65"}], "timestamp": "1769384141616", "event_type": "price_change"}}
{"_local_timestamp": "2026-01-25T23:35:41.710461+00:00", "data": {"market": "0x5d7fc002c8fbc73a1c18dbb111d96f0ca54e02ae1aa2a6a98ca8d62000f31526", "price_changes": [{"asset_id": "92027124758235029160948120350916378905334564613489667041482264435793489339845", "price": "0.36", "size": "66.66", "side": "BUY", "hash": "7e34c904d311318e4de5230d0190fea6857ef2e8", "best_bid": "0.36", "best_ask": "0.95"}, {"asset_id": "49246609416501398794937573302498657712519224305673745144194417177683023634127", "price": "0.64", "size": "66.66", "side": "SELL", "hash": "4cbb81b695357183ff982796d2b372ba939320a0", "best_bid": "0.05", "best_ask": "0.64"}], "timestamp": "1769384141640", "event_type": "price_change"}}
{"_local_timestamp": "2026-01-25T23:35:41.788304+00:00", "data": {"market": "0x6712272d366398ce29061852de0d2c0491e9d7e8ea99a19d19ff3efd4598d2a8", "price_changes": [{"asset_id": "56178066173451150343685984219274047856395361836845239123599784229709110987097", "price": "0.01", "size": "3423.96", "side": "BUY", "hash": "87b650984e7a5dc36d180368f2f25bce271db73e", "best_bid": "0.37", "best_ask": "0.97"}, {"asset_id": "66557211105864080610543279993701525059396563696536665254648897603357354477813", "price": "0.99", "size": "3423.96", "side": "SELL", "hash": "48e58718fe108b84542eec00dc1bf3c350282b0a", "best_bid": "0.03", "best_ask": "0.63"}], "timestamp": "1769384141717", "event_type": "price_change"}}
{"_local_timestamp": "2026-01-25T23:35:42.226866+00:00", "data": {"market": "0x91dd8dbe75a5347f14455ca880070ebcf3356bfd7df8caf19478e881bb483efb", "price_changes": [{"asset_id": "30112939078428479271380004766658148462656808495063824079473460276372582172087", "price": "0.23", "size": "0", "side": "BUY", "hash": "b915186a740fa00d811adb6490bf10e9d41390d3", "best_bid": "0.24", "best_ask": "0.91"}, {"asset_id": "23125627318359544367614218401841961178939444671222355150077267933985277277448", "price": "0.77", "size": "0", "side": "SELL", "hash": "ec211487877ab2e79718b95499c036a25cb95dbc", "best_bid": "0.09", "best_ask": "0.76"}], "timestamp": "1769384142165", "event_type": "price_change"}}
{"_local_timestamp": "2026-01-25T23:35:42.272478+00:00", "data": {"market": "0x91dd8dbe75a5347f14455ca880070ebcf3356bfd7df8caf19478e881bb483efb", "price_changes": [{"asset_id": "30112939078428479271380004766658148462656808495063824079473460276372582172087", "price": "0.25", "size": "20", "side": "BUY", "hash": "383952d2518be38c6f02c1388f1ac80353bed4fb", "best_bid": "0.25", "best_ask": "0.91"}, {"asset_id": "23125627318359544367614218401841961178939444671222355150077267933985277277448", "price": "0.75", "size": "20", "side": "SELL", "hash": "56b1b99d599255da7f5d6560d6b29e602761417b", "best_bid": "0.09", "best_ask": "0.75"}], "timestamp": "1769384142187", "event_type": "price_change"}}
{"_local_timestamp": "2026-01-25T23:35:55.731335+00:00", "data": {"market": "0x91dd8dbe75a5347f14455ca880070ebcf3356bfd7df8caf19478e881bb483efb", "price_changes": [{"asset_id": "23125627318359544367614218401841961178939444671222355150077267933985277277448", "price": "0.75", "size": "25", "side": "SELL", "hash": "ed6cfe8d9540c4730a06efca930d29e4565c7c2d", "best_bid": "0.09", "best_ask": "0.75"}, {"asset_id": "30112939078428479271380004766658148462656808495063824079473460276372582172087", "price": "0.25", "size": "25", "side": "BUY", "hash": "ddd09203d1bd3b24838bd300c66ff089f0eabf00", "best_bid": "0.25", "best_ask": "0.91"}], "timestamp": "1769384155665", "event_type": "price_change"}}
{"_local_timestamp": "2026-01-25T23:35:56.012151+00:00", "data": {"market": "0x5d7fc002c8fbc73a1c18dbb111d96f0ca54e02ae1aa2a6a98ca8d62000f31526", "price_changes": [{"asset_id": "49246609416501398794937573302498657712519224305673745144194417177683023634127", "price": "0.65", "size": "36.97", "side": "SELL", "hash": "5fd17447e5de776496349cd031ae5138ad4e7ec2", "best_bid": "0.05", "best_ask": "0.64"}, {"asset_id": "92027124758235029160948120350916378905334564613489667041482264435793489339845", "price": "0.35", "size": "36.97", "side": "BUY", "hash": "e0a09c8e0e6200914f191ffb8604353cc113d65a", "best_bid": "0.36", "best_ask": "0.95"}], "timestamp": "1769384155946", "event_type": "price_change"}}
{"_local_timestamp": "2026-01-25T23:35:56.120234+00:00", "data": {"market": "0x6712272d366398ce29061852de0d2c0491e9d7e8ea99a19d19ff3efd4598d2a8", "price_changes": [{"asset_id": "66557211105864080610543279993701525059396563696536665254648897603357354477813", "price": "0.64", "size": "11.2", "side": "SELL", "hash": "c4607d1592e542c75b07671208f8e57e348892ca", "best_bid": "0.03", "best_ask": "0.63"}, {"asset_id": "56178066173451150343685984219274047856395361836845239123599784229709110987097", "price": "0.36", "size": "11.2", "side": "BUY", "hash": "7569034faff2eeac589e11efa8ca9617d8d54ca7", "best_bid": "0.37", "best_ask": "0.97"}], "timestamp": "1769384156053", "event_type": "price_change"}}
{"_local_timestamp": "2026-01-25T23:36:04.150834+00:00", "data": {"market": "0x4dd25c542ccc7bacaa13852b65789e3bf860f47e5b6b8a4b63251a82dc351343", "price_changes": [{"asset_id": "40449888288677466161407105025909896534729388261656969948429208198635959052386", "price": "0.04", "size": "0", "side": "BUY", "hash": "cb43b0bd05733376b44d47ea64cba8603610d04b", "best_bid": "0.05", "best_ask": "0.61"}, {"asset_id": "69940668700050123184332060950192865871206736155068150467256714825915478178996", "price": "0.96", "size": "0", "side": "SELL", "hash": "156741c10f25809a44f1df8fb27c9663c2ebd602", "best_bid": "0.39", "best_ask": "0.95"}], "timestamp": "1769384164080", "event_type": "price_change"}}
{"_local_timestamp": "2026-01-25T23:36:07.762873+00:00", "data": {"market": "0x91dd8dbe75a5347f14455ca880070ebcf3356bfd7df8caf19478e881bb483efb", "price_changes": [{"asset_id": "30112939078428479271380004766658148462656808495063824079473460276372582172087", "price": "0.22", "size": "0", "side": "BUY", "hash": "01ee4adbf3b2dc36e73a0a3215849cb441ac370c", "best_bid": "0.25", "best_ask": "0.91"}, {"asset_id": "23125627318359544367614218401841961178939444671222355150077267933985277277448", "price": "0.78", "size": "0", "side": "SELL", "hash": "582cc9b725e836dbe0991580eae7b067ccc4f04f", "best_bid": "0.09", "best_ask": "0.75"}], "timestamp": "1769384167688", "event_type": "price_change"}}
{"_local_timestamp": "2026-01-25T23:36:07.763375+00:00", "data": {"market": "0x5d7fc002c8fbc73a1c18dbb111d96f0ca54e02ae1aa2a6a98ca8d62000f31526", "price_changes": [{"asset_id": "92027124758235029160948120350916378905334564613489667041482264435793489339845", "price": "0.21", "size": "0", "side": "BUY", "hash": "d988d514f06fdb08057e16d98f13e0c3417063ba", "best_bid": "0.36", "best_ask": "0.95"}, {"asset_id": "49246609416501398794937573302498657712519224305673745144194417177683023634127", "price": "0.79", "size": "0", "side": "SELL", "hash": "c5f584a125343e97378b0f00bad294cb2b809a87", "best_bid": "0.05", "best_ask": "0.64"}], "timestamp": "1769384167688", "event_type": "price_change"}}
{"_local_timestamp": "2026-01-25T23:36:11.683919+00:00", "data": {"market": "0x5d7fc002c8fbc73a1c18dbb111d96f0ca54e02ae1aa2a6a98ca8d62000f31526", "price_changes": [{"asset_id": "92027124758235029160948120350916378905334564613489667041482264435793489339845", "price": "0.22", "size": "0", "side": "BUY", "hash": "c3d30ad581c5f67bd2d24abe3bba9a47f8389fa7", "best_bid": "0.36", "best_ask": "0.95"}, {"asset_id": "49246609416501398794937573302498657712519224305673745144194417177683023634127", "price": "0.78", "size": "0", "side": "SELL", "hash": "6010dc476ed461eeb98f95b3caea40470a280110", "best_bid": "0.05", "best_ask": "0.64"}], "timestamp": "1769384171616", "event_type": "price_change"}}
{"_local_timestamp": "2026-01-25T23:36:11.707343+00:00", "data": {"market": "0x5d7fc002c8fbc73a1c18dbb111d96f0ca54e02ae1aa2a6a98ca8d62000f31526", "price_changes": [{"asset_id": "92027124758235029160948120350916378905334564613489667041482264435793489339845", "price": "0.19", "size": "20", "side": "BUY", "hash": "3a599469a53073ea17e929ee1531c91287c85ffa", "best_bid": "0.36", "best_ask": "0.95"}, {"asset_id": "49246609416501398794937573302498657712519224305673745144194417177683023634127", "price": "0.81", "size": "20", "side": "SELL", "hash": "bf753227736574101954b6b52c1b1551024c1e48", "best_bid": "0.05", "best_ask": "0.64"}], "timestamp": "1769384171639", "event_type": "price_change"}}
{"_local_timestamp": "2026-01-25T23:36:30.696647+00:00", "data": {"market": "0x6712272d366398ce29061852de0d2c0491e9d7e8ea99a19d19ff3efd4598d2a8", "price_changes": [{"asset_id": "56178066173451150343685984219274047856395361836845239123599784229709110987097", "price": "0.09", "size": "0", "side": "BUY", "hash": "58d15023c6522d50e346f07c52cb9bd88a247936", "best_bid": "0.37", "best_ask": "0.97"}, {"asset_id": "66557211105864080610543279993701525059396563696536665254648897603357354477813", "price": "0.91", "size": "0", "side": "SELL", "hash": "48f495a9904465f8e4461277963332b636bef96f", "best_bid": "0.03", "best_ask": "0.63"}], "timestamp": "1769384190628", "event_type": "price_change"}}
{"_local_timestamp": "2026-01-25T23:36:30.757510+00:00", "data": {"market": "0x6712272d366398ce29061852de0d2c0491e9d7e8ea99a19d19ff3efd4598d2a8", "price_changes": [{"asset_id": "56178066173451150343685984219274047856395361836845239123599784229709110987097", "price": "0.09", "size": "22", "side": "BUY", "hash": "95a00dc19cba923d2a737ca4c9e7b0d79da550c3", "best_bid": "0.37", "best_ask": "0.97"}, {"asset_id": "66557211105864080610543279993701525059396563696536665254648897603357354477813", "price": "0.91", "size": "22", "side": "SELL", "hash": "a4b8748be28355b0703b8054403046d8b9b0f8c3", "best_bid": "0.03", "best_ask": "0.63"}], "timestamp": "1769384190680", "event_type": "price_change"}}
{"_local_timestamp": "2026-01-25T23:36:34.614571+00:00", "data": {"market": "0x5d7fc002c8fbc73a1c18dbb111d96f0ca54e02ae1aa2a6a98ca8d62000f31526", "price_changes": [{"asset_id": "49246609416501398794937573302498657712519224305673745144194417177683023634127", "price": "0.64", "size": "71.66", "side": "SELL", "hash": "3d258f51b5d88ae5563270feef8179e0fc2a0ef7", "best_bid": "0.05", "best_ask": "0.64"}, {"asset_id": "92027124758235029160948120350916378905334564613489667041482264435793489339845", "price": "0.36", "size": "71.66", "side": "BUY", "hash": "2eb774ca855f4b0d5ea1b4d24efd5075ba56da4a", "best_bid": "0.36", "best_ask": "0.95"}], "timestamp": "1769384194545", "event_type": "price_change"}}
{"_local_timestamp": "2026-01-25T23:36:34.733506+00:00", "data": {"market": "0x6712272d366398ce29061852de0d2c0491e9d7e8ea99a19d19ff3efd4598d2a8", "price_changes": [{"asset_id": "66557211105864080610543279993701525059396563696536665254648897603357354477813", "price": "0.63", "size": "71.66", "side": "SELL", "hash": "7b2e65b6652c4132e5bcb58ee0b149a2b704e399", "best_bid": "0.03", "best_ask": "0.63"}, {"asset_id": "56178066173451150343685984219274047856395361836845239123599784229709110987097", "price": "0.37", "size": "71.66", "side": "BUY", "hash": "46a3b7d58d7ad9bca2afbbd7739ab596c2209c4c", "best_bid": "0.37", "best_ask": "0.97"}], "timestamp": "1769384194666", "event_type": "price_change"}}
{"_local_timestamp": "2026-01-25T23:37:44.512367+00:00", "data": {"market": "0x17f82e3b0e0c8a89c94db772bdae69e847829166d6dc669bc810dd9c3e887e7d", "price_changes": [{"asset_id": "113577032080692176917483189160049505493244580061534385093277932638888639958742", "price": "0.04", "size": "29.99", "side": "BUY", "hash": "f14a2757cada6b9317c812de17c981630439d143", "best_bid": "0.04", "best_ask": "0.63"}, {"asset_id": "7029339265071828454381282976374049811411143787209307871045939933169945390178", "price": "0.96", "size": "29.99", "side": "SELL", "hash": "197e35f3e0d16c0c6ce55499d7090c22cf6a8bab", "best_bid": "0.37", "best_ask": "0.96"}], "timestamp": "1769384264439", "event_type": "price_change"}}
{"_local_timestamp": "2026-01-25T23:38:26.325864+00:00", "data": {"market": "0x17f82e3b0e0c8a89c94db772bdae69e847829166d6dc669bc810dd9c3e887e7d", "price_changes": [{"asset_id": "113577032080692176917483189160049505493244580061534385093277932638888639958742", "price": "0.01", "size": "111.14", "side": "BUY", "hash": "0bf1895a7eb729b76ab8282e3c12be19c3b2dca2", "best_bid": "0.04", "best_ask": "0.63"}, {"asset_id": "7029339265071828454381282976374049811411143787209307871045939933169945390178", "price": "0.99", "size": "111.14", "side": "SELL", "hash": "35c0c80c0408e3305750944140f9210975924724", "best_bid": "0.37", "best_ask": "0.96"}], "timestamp": "1769384306260", "event_type": "price_change"}}
{"_local_timestamp": "2026-01-25T23:38:26.345241+00:00", "data": {"market": "0x91dd8dbe75a5347f14455ca880070ebcf3356bfd7df8caf19478e881bb483efb", "price_changes": [{"asset_id": "30112939078428479271380004766658148462656808495063824079473460276372582172087", "price": "0.24", "size": "0", "side": "BUY", "hash": "1bc562dd6406edd762c3ee630f2954ef122317d9", "best_bid": "0.25", "best_ask": "0.91"}, {"asset_id": "23125627318359544367614218401841961178939444671222355150077267933985277277448", "price": "0.76", "size": "0", "side": "SELL", "hash": "d1596b748cafec8f2bc222540849acf750d736cf", "best_bid": "0.09", "best_ask": "0.75"}], "timestamp": "1769384306260", "event_type": "price_change"}}
{"_local_timestamp": "2026-01-25T23:38:26.345778+00:00", "data": {"market": "0x91dd8dbe75a5347f14455ca880070ebcf3356bfd7df8caf19478e881bb483efb", "price_changes": [{"asset_id": "30112939078428479271380004766658148462656808495063824079473460276372582172087", "price": "0.13", "size": "0", "side": "BUY", "hash": "1bc562dd6406edd762c3ee630f2954ef122317d9", "best_bid": "0.25", "best_ask": "0.91"}, {"asset_id": "23125627318359544367614218401841961178939444671222355150077267933985277277448", "price": "0.87", "size": "0", "side": "SELL", "hash": "d1596b748cafec8f2bc222540849acf750d736cf", "best_bid": "0.09", "best_ask": "0.75"}], "timestamp": "1769384306260", "event_type": "price_change"}}
{"_local_timestamp": "2026-01-25T23:38:26.346262+00:00", "data": {"market": "0x6712272d366398ce29061852de0d2c0491e9d7e8ea99a19d19ff3efd4598d2a8", "price_changes": [{"asset_id": "56178066173451150343685984219274047856395361836845239123599784229709110987097", "price": "0.37", "size": "5", "side": "BUY", "hash": "1ab1df1edb7a5d4daf672d855c1824970d659fc3", "best_bid": "0.37", "best_ask": "0.97"}, {"asset_id": "66557211105864080610543279993701525059396563696536665254648897603357354477813", "price": "0.63", "size": "5", "side": "SELL", "hash": "2423abfa4f5d3236be1a034c1f0ec11ae6a89d86", "best_bid": "0.03", "best_ask": "0.63"}], "timestamp": "1769384306260", "event_type": "price_change"}}
{"_local_timestamp": "2026-01-25T23:38:26.346661+00:00", "data": {"market": "0x6712272d366398ce29061852de0d2c0491e9d7e8ea99a19d19ff3efd4598d2a8", "price_changes": [{"asset_id": "56178066173451150343685984219274047856395361836845239123599784229709110987097", "price": "0.19", "size": "0", "side": "BUY", "hash": "1ab1df1edb7a5d4daf672d855c1824970d659fc3", "best_bid": "0.37", "best_ask": "0.97"}, {"asset_id": "66557211105864080610543279993701525059396563696536665254648897603357354477813", "price": "0.81", "size": "0", "side": "SELL", "hash": "2423abfa4f5d3236be1a034c1f0ec11ae6a89d86", "best_bid": "0.03", "best_ask": "0.63"}], "timestamp": "1769384306260", "event_type": "price_change"}}
{"_local_timestamp": "2026-01-25T23:38:26.347060+00:00", "data": {"market": "0x5d7fc002c8fbc73a1c18dbb111d96f0ca54e02ae1aa2a6a98ca8d62000f31526", "price_changes": [{"asset_id": "92027124758235029160948120350916378905334564613489667041482264435793489339845", "price": "0.36", "size": "5", "side": "BUY", "hash": "80d69788adcb506f79f11d29a8a5cb289dbb0156", "best_bid": "0.36", "best_ask": "0.95"}, {"asset_id": "49246609416501398794937573302498657712519224305673745144194417177683023634127", "price": "0.64", "size": "5", "side": "SELL", "hash": "e1265d74df755bc120981940f806150a600916d3", "best_bid": "0.05", "best_ask": "0.64"}], "timestamp": "1769384306260", "event_type": "price_change"}}
{"_local_timestamp": "2026-01-25T23:38:26.347483+00:00", "data": {"market": "0x4dd25c542ccc7bacaa13852b65789e3bf860f47e5b6b8a4b63251a82dc351343", "price_changes": [{"asset_id": "40449888288677466161407105025909896534729388261656969948429208198635959052386", "price": "0.05", "size": "0", "side": "BUY", "hash": "f9a051c4f1de5e69f6e0a7715b1bc100eabbf2ea", "best_bid": "0.03", "best_ask": "0.61"}, {"asset_id": "69940668700050123184332060950192865871206736155068150467256714825915478178996", "price": "0.95", "size": "0", "side": "SELL", "hash": "9235f786c671775ecd6ebb6c659f0cca5117bf55", "best_bid": "0.39", "best_ask": "0.97"}], "timestamp": "1769384306260", "event_type": "price_change"}}
{"_local_timestamp": "2026-01-25T23:38:26.347900+00:00", "data": {"market": "0x6712272d366398ce29061852de0d2c0491e9d7e8ea99a19d19ff3efd4598d2a8", "price_changes": [{"asset_id": "56178066173451150343685984219274047856395361836845239123599784229709110987097", "price": "0.01", "size": "3357.3", "side": "BUY", "hash": "1ab1df1edb7a5d4daf672d855c1824970d659fc3", "best_bid": "0.37", "best_ask": "0.97"}, {"asset_id": "66557211105864080610543279993701525059396563696536665254648897603357354477813", "price": "0.99", "size": "3357.3", "side": "SELL", "hash": "2423abfa4f5d3236be1a034c1f0ec11ae6a89d86", "best_bid": "0.03", "best_ask": "0.63"}], "timestamp": "1769384306260", "event_type": "price_change"}}
{"_local_timestamp": "2026-01-25T23:38:26.348337+00:00", "data": {"market": "0x5d7fc002c8fbc73a1c18dbb111d96f0ca54e02ae1aa2a6a98ca8d62000f31526", "price_changes": [{"asset_id": "92027124758235029160948120350916378905334564613489667041482264435793489339845", "price": "0.18", "size": "0", "side": "BUY", "hash": "80d69788adcb506f79f11d29a8a5cb289dbb0156", "best_bid": "0.36", "best_ask": "0.95"}, {"asset_id": "49246609416501398794937573302498657712519224305673745144194417177683023634127", "price": "0.82", "size": "0", "side": "SELL", "hash": "e1265d74df755bc120981940f806150a600916d3", "best_bid": "0.05", "best_ask": "0.64"}], "timestamp": "1769384306260", "event_type": "price_change"}}
{"_local_timestamp": "2026-01-25T23:38:26.348734+00:00", "data": {"market": "0x5d7fc002c8fbc73a1c18dbb111d96f0ca54e02ae1aa2a6a98ca8d62000f31526", "price_changes": [{"asset_id": "92027124758235029160948120350916378905334564613489667041482264435793489339845", "price": "0.01", "size": "3365.53", "side": "BUY", "hash": "80d69788adcb506f79f11d29a8a5cb289dbb0156", "best_bid": "0.36", "best_ask": "0.95"}, {"asset_id": "49246609416501398794937573302498657712519224305673745144194417177683023634127", "price": "0.99", "size": "3365.53", "side": "SELL", "hash": "e1265d74df755bc120981940f806150a600916d3", "best_bid": "0.05", "best_ask": "0.64"}], "timestamp": "1769384306260", "event_type": "price_change"}}
{"_local_timestamp": "2026-01-25T23:38:27.385388+00:00", "data": {"market": "0x4dd25c542ccc7bacaa13852b65789e3bf860f47e5b6b8a4b63251a82dc351343", "price_changes": [{"asset_id": "40449888288677466161407105025909896534729388261656969948429208198635959052386", "price": "0.01", "size": "133.32", "side": "BUY", "hash": "32d5243bfa8b51a6f3f358f5afb0802e97a73772", "best_bid": "0.03", "best_ask": "0.61"}, {"asset_id": "69940668700050123184332060950192865871206736155068150467256714825915478178996", "price": "0.99", "size": "133.32", "side": "SELL", "hash": "9a80a539cd1169c1a4752e5c25795d8e96aa734d", "best_bid": "0.39", "best_ask": "0.97"}], "timestamp": "1769384307316", "event_type": "price_change"}}
{"_local_timestamp": "2026-01-25T23:38:27.432559+00:00", "data": {"market": "0x5d7fc002c8fbc73a1c18dbb111d96f0ca54e02ae1aa2a6a98ca8d62000f31526", "price_changes": [{"asset_id": "92027124758235029160948120350916378905334564613489667041482264435793489339845", "price": "0.19", "size": "120", "side": "BUY", "hash": "c344c16a6e9bfeaacd6ed68086175a4b060ebdd6", "best_bid": "0.36", "best_ask": "0.95"}, {"asset_id": "49246609416501398794937573302498657712519224305673745144194417177683023634127", "price": "0.81", "size": "120", "side": "SELL", "hash": "7795d46e6c0109227b145beb3f52a32fe0bcb6c1", "best_bid": "0.05", "best_ask": "0.64"}], "timestamp": "1769384307360", "event_type": "price_change"}}
{"_local_timestamp": "2026-01-25T23:38:27.475681+00:00", "data": {"market": "0x5d7fc002c8fbc73a1c18dbb111d96f0ca54e02ae1aa2a6a98ca8d62000f31526", "price_changes": [{"asset_id": "92027124758235029160948120350916378905334564613489667041482264435793489339845", "price": "0.01", "size": "3465.53", "side": "BUY", "hash": "b6682b19f88135700a25f5d498f7de4739b8e0f1", "best_bid": "0.36", "best_ask": "0.95"}, {"asset_id": "49246609416501398794937573302498657712519224305673745144194417177683023634127", "price": "0.99", "size": "3465.53", "side": "SELL", "hash": "d585b93f0a058eba21f939dfbb605dde476be7d2", "best_bid": "0.05", "best_ask": "0.64"}], "timestamp": "1769384307402", "event_type": "price_change"}}
{"_local_timestamp": "2026-01-25T23:38:27.552834+00:00", "data": {"market": "0x6712272d366398ce29061852de0d2c0491e9d7e8ea99a19d19ff3efd4598d2a8", "price_changes": [{"asset_id": "56178066173451150343685984219274047856395361836845239123599784229709110987097", "price": "0.19", "size": "100", "side": "BUY", "hash": "aa3cfc09adae69100c53a18162e18a08f57492d0", "best_bid": "0.37", "best_ask": "0.97"}, {"asset_id": "66557211105864080610543279993701525059396563696536665254648897603357354477813", "price": "0.81", "size": "100", "side": "SELL", "hash": "6ab9bd7826c5b360074422312c16f00805a994a4", "best_bid": "0.03", "best_ask": "0.63"}], "timestamp": "1769384307475", "event_type": "price_change"}}
{"_local_timestamp": "2026-01-25T23:38:27.553390+00:00", "data": {"market": "0x91dd8dbe75a5347f14455ca880070ebcf3356bfd7df8caf19478e881bb483efb", "price_changes": [{"asset_id": "30112939078428479271380004766658148462656808495063824079473460276372582172087", "price": "0.26", "size": "66.66", "side": "BUY", "hash": "a27a3af9784f51fe355ef646b816156e6544570f", "best_bid": "0.26", "best_ask": "0.91"}, {"asset_id": "23125627318359544367614218401841961178939444671222355150077267933985277277448", "price": "0.74", "size": "66.66", "side": "SELL", "hash": "e28c683aa6bcca58fce865f5e4a494726dfb2144", "best_bid": "0.09", "best_ask": "0.74"}], "timestamp": "1769384307480", "event_type": "price_change"}}
{"_local_timestamp": "2026-01-25T23:38:27.585161+00:00", "data": {"market": "0x91dd8dbe75a5347f14455ca880070ebcf3356bfd7df8caf19478e881bb483efb", "price_changes": [{"asset_id": "30112939078428479271380004766658148462656808495063824079473460276372582172087", "price": "0.17", "size": "66.66", "side": "BUY", "hash": "bc22f2e4f08b563dd36456d8dabdc8bf7dc40bee", "best_bid": "0.26", "best_ask": "0.91"}, {"asset_id": "23125627318359544367614218401841961178939444671222355150077267933985277277448", "price": "0.83", "size": "66.66", "side": "SELL", "hash": "e80c1d366cf69f96095edaa98864f0f90f52de9d", "best_bid": "0.09", "best_ask": "0.74"}], "timestamp": "1769384307516", "event_type": "price_change"}}
{"_local_timestamp": "2026-01-25T23:38:27.645465+00:00", "data": {"market": "0x17f82e3b0e0c8a89c94db772bdae69e847829166d6dc669bc810dd9c3e887e7d", "price_changes": [{"asset_id": "113577032080692176917483189160049505493244580061534385093277932638888639958742", "price": "0.05", "size": "11.14", "side": "BUY", "hash": "b1c11a41dd8eea3a69ce9a2338796bf89b9b1531", "best_bid": "0.05", "best_ask": "0.63"}, {"asset_id": "7029339265071828454381282976374049811411143787209307871045939933169945390178", "price": "0.95", "size": "11.14", "side": "SELL", "hash": "62781dfd0ad394fe1ea8c7f0e1bbdb82d2bf7839", "best_bid": "0.37", "best_ask": "0.95"}], "timestamp": "1769384307577", "event_type": "price_change"}}
{"_local_timestamp": "2026-01-25T23:38:27.689648+00:00", "data": {"market": "0x6712272d366398ce29061852de0d2c0491e9d7e8ea99a19d19ff3efd4598d2a8", "price_changes": [{"asset_id": "56178066173451150343685984219274047856395361836845239123599784229709110987097", "price": "0.01", "size": "3457.3", "side": "BUY", "hash": "a63ed7d00ffc9f3f55c72f0c9ea6755607738f3d", "best_bid": "0.37", "best_ask": "0.97"}, {"asset_id": "66557211105864080610543279993701525059396563696536665254648897603357354477813", "price": "0.99", "size": "3457.3", "side": "SELL", "hash": "df538779045b6e0ef0a3530d4e0b1e24389eabb3", "best_bid": "0.03", "best_ask": "0.63"}], "timestamp": "1769384307615", "event_type": "price_change"}}
{"_local_timestamp": "2026-01-25T23:38:28.064026+00:00", "data": {"market": "0x91dd8dbe75a5347f14455ca880070ebcf3356bfd7df8caf19478e881bb483efb", "price_changes": [{"asset_id": "23125627318359544367614218401841961178939444671222355150077267933985277277448", "price": "0.75", "size": "20", "side": "SELL", "hash": "058fd8cb4cd3b493d5e9362509ea4c91870d246e", "best_bid": "0.09", "best_ask": "0.74"}, {"asset_id": "30112939078428479271380004766658148462656808495063824079473460276372582172087", "price": "0.25", "size": "20", "side": "BUY", "hash": "0330b2655264160a6414506674b019f88642454d", "best_bid": "0.26", "best_ask": "0.91"}], "timestamp": "1769384307998", "event_type": "price_change"}}
{"_local_timestamp": "2026-01-25T23:38:28.382980+00:00", "data": {"market": "0x5d7fc002c8fbc73a1c18dbb111d96f0ca54e02ae1aa2a6a98ca8d62000f31526", "price_changes": [{"asset_id": "49246609416501398794937573302498657712519224305673745144194417177683023634127", "price": "0.64", "size": "0", "side": "SELL", "hash": "30a4d15b073dfb455b9a9abb3f110f0ae2611dcf", "best_bid": "0.05", "best_ask": "0.65"}, {"asset_id": "92027124758235029160948120350916378905334564613489667041482264435793489339845", "price": "0.36", "size": "0", "side": "BUY", "hash": "fee6222ad1256779127f67d1942973714de37e28", "best_bid": "0.35", "best_ask": "0.95"}], "timestamp": "1769384308319", "event_type": "price_change"}}
{"_local_timestamp": "2026-01-25T23:38:28.499589+00:00", "data": {"market": "0x6712272d366398ce29061852de0d2c0491e9d7e8ea99a19d19ff3efd4598d2a8", "price_changes": [{"asset_id": "66557211105864080610543279993701525059396563696536665254648897603357354477813", "price": "0.63", "size": "0", "side": "SELL", "hash": "693cd7915bc79c50bc5a84e403de2342aa2dadad", "best_bid": "0.03", "best_ask": "0.64"}, {"asset_id": "56178066173451150343685984219274047856395361836845239123599784229709110987097", "price": "0.37", "size": "0", "side": "BUY", "hash": "4d172532cf409562ba76ed247540fa564a634887", "best_bid": "0.36", "best_ask": "0.97"}], "timestamp": "1769384308429", "event_type": "price_change"}}
{"_local_timestamp": "2026-01-25T23:38:29.605564+00:00", "data": {"market": "0x91dd8dbe75a5347f14455ca880070ebcf3356bfd7df8caf19478e881bb483efb", "price_changes": [{"asset_id": "30112939078428479271380004766658148462656808495063824079473460276372582172087", "price": "0.25", "size": "0", "side": "BUY", "hash": "c1cc9fcbc5e7821e4e9aaf47b318eedfd58694c6", "best_bid": "0.26", "best_ask": "0.91"}, {"asset_id": "23125627318359544367614218401841961178939444671222355150077267933985277277448", "price": "0.75", "size": "0", "side": "SELL", "hash": "7140ca26b536d5d10a028af2b1656aa16dbb4477", "best_bid": "0.09", "best_ask": "0.74"}], "timestamp": "1769384309532", "event_type": "price_change"}}
{"_local_timestamp": "2026-01-25T23:38:29.606294+00:00", "data": {"market": "0x5d7fc002c8fbc73a1c18dbb111d96f0ca54e02ae1aa2a6a98ca8d62000f31526", "price_changes": [{"asset_id": "92027124758235029160948120350916378905334564613489667041482264435793489339845", "price": "0.19", "size": "100", "side": "BUY", "hash": "f8ff815ea161332177a1a37d4f1a57f0cc36128c", "best_bid": "0.35", "best_ask": "0.95"}, {"asset_id": "49246609416501398794937573302498657712519224305673745144194417177683023634127", "price": "0.81", "size": "100", "side": "SELL", "hash": "98df0d85c391fd2a947ad246403b523840d7e421", "best_bid": "0.05", "best_ask": "0.65"}], "timestamp": "1769384309532", "event_type": "price_change"}}
{"_local_timestamp": "2026-01-25T23:38:29.629809+00:00", "data": {"market": "0x5d7fc002c8fbc73a1c18dbb111d96f0ca54e02ae1aa2a6a98ca8d62000f31526", "price_changes": [{"asset_id": "92027124758235029160948120350916378905334564613489667041482264435793489339845", "price": "0.2", "size": "20", "side": "BUY", "hash": "0d7162ef83989a3c693d291d47f1adbaaea976ec", "best_bid": "0.35", "best_ask": "0.95"}, {"asset_id": "49246609416501398794937573302498657712519224305673745144194417177683023634127", "price": "0.8", "size": "20", "side": "SELL", "hash": "4018eea5e9271285770bf525824b9682ea7bdcae", "best_bid": "0.05", "best_ask": "0.65"}], "timestamp": "1769384309560", "event_type": "price_change"}}
{"_local_timestamp": "2026-01-25T23:38:29.630425+00:00", "data": {"market": "0x91dd8dbe75a5347f14455ca880070ebcf3356bfd7df8caf19478e881bb483efb", "price_changes": [{"asset_id": "30112939078428479271380004766658148462656808495063824079473460276372582172087", "price": "0.26", "size": "86.66", "side": "BUY", "hash": "35ed49fe5d256aa83c824467a7921b75b77099e5", "best_bid": "0.26", "best_ask": "0.91"}, {"asset_id": "23125627318359544367614218401841961178939444671222355150077267933985277277448", "price": "0.74", "size": "86.66", "side": "SELL", "hash": "351a18127da721a2ec1271212fd29134eca76741", "best_bid": "0.09", "best_ask": "0.74"}], "timestamp": "1769384309560", "event_type": "price_change"}}
{"_local_timestamp": "2026-01-25T23:38:51.170420+00:00", "data": {"market": "0x5d7fc002c8fbc73a1c18dbb111d96f0ca54e02ae1aa2a6a98ca8d62000f31526", "price_changes": [{"asset_id": "92027124758235029160948120350916378905334564613489667041482264435793489339845", "price": "0.2", "size": "115", "side": "BUY", "hash": "5805ea61ae3663cf5f53dc84719c2b9f452026b7", "best_bid": "0.35", "best_ask": "0.95"}, {"asset_id": "49246609416501398794937573302498657712519224305673745144194417177683023634127", "price": "0.8", "size": "115", "side": "SELL", "hash": "35d73b62a10d0676717d430d7db2e36786c8af85", "best_bid": "0.05", "best_ask": "0.65"}], "timestamp": "1769384331063", "event_type": "price_change"}}
{"_local_timestamp": "2026-01-25T23:38:51.170976+00:00", "data": {"market": "0x5d7fc002c8fbc73a1c18dbb111d96f0ca54e02ae1aa2a6a98ca8d62000f31526", "price_changes": [{"asset_id": "92027124758235029160948120350916378905334564613489667041482264435793489339845", "price": "0.21", "size": "95", "side": "BUY", "hash": "acdb11d3299c058648bfb065bdd2c2e9826c29e0", "best_bid": "0.35", "best_ask": "0.95"}, {"asset_id": "49246609416501398794937573302498657712519224305673745144194417177683023634127", "price": "0.79", "size": "95", "side": "SELL", "hash": "3ba9d4bff80de06232b7d9cd929cc33f211673bb", "best_bid": "0.05", "best_ask": "0.65"}], "timestamp": "1769384331064", "event_type": "price_change"}}
{"_local_timestamp": "2026-01-25T23:38:51.171461+00:00", "data": {"market": "0x91dd8dbe75a5347f14455ca880070ebcf3356bfd7df8caf19478e881bb483efb", "price_changes": [{"asset_id": "30112939078428479271380004766658148462656808495063824079473460276372582172087", "price": "0.27", "size": "47", "side": "BUY", "hash": "9188b0f7800313442882ed2bacda47365fc00fa8", "best_bid": "0.27", "best_ask": "0.91"}, {"asset_id": "23125627318359544367614218401841961178939444671222355150077267933985277277448", "price": "0.73", "size": "47", "side": "SELL", "hash": "7e81e57f9e8adaf7e651eb40173b10c27c270151", "best_bid": "0.09", "best_ask": "0.73"}], "timestamp": "1769384331063", "event_type": "price_change"}}
{"_local_timestamp": "2026-01-25T23:38:53.453054+00:00", "data": {"market": "0x5d7fc002c8fbc73a1c18dbb111d96f0ca54e02ae1aa2a6a98ca8d62000f31526", "price_changes": [{"asset_id": "92027124758235029160948120350916378905334564613489667041482264435793489339845", "price": "0.2", "size": "95", "side": "BUY", "hash": "0f6e3259cfeb7bc8a2db685979a9aa5ad18a7866", "best_bid": "0.35", "best_ask": "0.95"}, {"asset_id": "49246609416501398794937573302498657712519224305673745144194417177683023634127", "price": "0.8", "size": "95", "side": "SELL", "hash": "ac4e7a21481666cf6b09398d089add8907169e44", "best_bid": "0.05", "best_ask": "0.65"}], "timestamp": "1769384333387", "event_type": "price_change"}}
{"_local_timestamp": "2026-01-25T23:38:53.475644+00:00", "data": {"market": "0x5d7fc002c8fbc73a1c18dbb111d96f0ca54e02ae1aa2a6a98ca8d62000f31526", "price_changes": [{"asset_id": "92027124758235029160948120350916378905334564613489667041482264435793489339845", "price": "0.22", "size": "20", "side": "BUY", "hash": "ec2d2b72a988068ebbe90feb748fe30835a8aa08", "best_bid": "0.35", "best_ask": "0.95"}, {"asset_id": "49246609416501398794937573302498657712519224305673745144194417177683023634127", "price": "0.78", "size": "20", "side": "SELL", "hash": "e8af89d514c9c8c22a22a724650cdbf9b3b60d29", "best_bid": "0.05", "best_ask": "0.65"}], "timestamp": "1769384333411", "event_type": "price_change"}}
{"_local_timestamp": "2026-01-25T23:39:03.446232+00:00", "data": {"market": "0x91dd8dbe75a5347f14455ca880070ebcf3356bfd7df8caf19478e881bb483efb", "price_changes": [{"asset_id": "23125627318359544367614218401841961178939444671222355150077267933985277277448", "price": "0.73", "size": "52", "side": "SELL", "hash": "5917de9bace44a0a868a8e089ac094282e8e81b3", "best_bid": "0.09", "best_ask": "0.73"}, {"asset_id": "30112939078428479271380004766658148462656808495063824079473460276372582172087", "price": "0.27", "size": "52", "side": "BUY", "hash": "7a03fb158453061d33da2b456c3d48b940d3473e", "best_bid": "0.27", "best_ask": "0.91"}], "timestamp": "1769384343372", "event_type": "price_change"}}
{"_local_timestamp": "2026-01-25T23:39:03.704084+00:00", "data": {"market": "0x5d7fc002c8fbc73a1c18dbb111d96f0ca54e02ae1aa2a6a98ca8d62000f31526", "price_changes": [{"asset_id": "49246609416501398794937573302498657712519224305673745144194417177683023634127", "price": "0.65", "size": "41.97", "side": "SELL", "hash": "0f586c65aec3d4594c967c8e0d2285027612b161", "best_bid": "0.05", "best_ask": "0.65"}, {"asset_id": "92027124758235029160948120350916378905334564613489667041482264435793489339845", "price": "0.35", "size": "41.97", "side": "BUY", "hash": "18b02fa95848e7dbdacfbaae789f9ef513d13af9", "best_bid": "0.35", "best_ask": "0.95"}], "timestamp": "1769384343630", "event_type": "price_change"}}
{"_local_timestamp": "2026-01-25T23:39:03.800840+00:00", "data": {"market": "0x6712272d366398ce29061852de0d2c0491e9d7e8ea99a19d19ff3efd4598d2a8", "price_changes": [{"asset_id": "66557211105864080610543279993701525059396563696536665254648897603357354477813", "price": "0.64", "size": "16.2", "side": "SELL", "hash": "3c408782389ed72edf3392cd08221c7e32972227", "best_bid": "0.03", "best_ask": "0.64"}, {"asset_id": "56178066173451150343685984219274047856395361836845239123599784229709110987097", "price": "0.36", "size": "16.2", "side": "BUY", "hash": "a3940939510c25df8b265a9a15ba98a62100035c", "best_bid": "0.36", "best_ask": "0.97"}], "timestamp": "1769384343736", "event_type": "price_change"}}
{"_local_timestamp": "2026-01-25T23:39:10.796950+00:00", "data": {"market": "0x17f82e3b0e0c8a89c94db772bdae69e847829166d6dc669bc810dd9c3e887e7d", "price_changes": [{"asset_id": "113577032080692176917483189160049505493244580061534385093277932638888639958742", "price": "0.04", "size": "0", "side": "BUY", "hash": "9bf622688280bc85ac7b30b4112dae345f4fba68", "best_bid": "0.05", "best_ask": "0.63"}, {"asset_id": "7029339265071828454381282976374049811411143787209307871045939933169945390178", "price": "0.96", "size": "0", "side": "SELL", "hash": "5c277ce0165f4b03f2eebeb844f44c614a0fba84", "best_bid": "0.37", "best_ask": "0.95"}], "timestamp": "1769384350710", "event_type": "price_change"}}
{"_local_timestamp": "2026-01-25T23:39:11.468497+00:00", "data": {"market": "0x4dd25c542ccc7bacaa13852b65789e3bf860f47e5b6b8a4b63251a82dc351343", "price_changes": [{"asset_id": "40449888288677466161407105025909896534729388261656969948429208198635959052386", "price": "0.04", "size": "29.99", "side": "BUY", "hash": "f55738886081cc7a27386423fc943faac3723bde", "best_bid": "0.04", "best_ask": "0.61"}, {"asset_id": "69940668700050123184332060950192865871206736155068150467256714825915478178996", "price": "0.96", "size": "29.99", "side": "SELL", "hash": "16e17b5182f6daeda052d5e9ec7e35c52234850c", "best_bid": "0.39", "best_ask": "0.96"}], "timestamp": "1769384351397", "event_type": "price_change"}}
{"_local_timestamp": "2026-01-25T23:39:12.289974+00:00", "data": {"market": "0x91dd8dbe75a5347f14455ca880070ebcf3356bfd7df8caf19478e881bb483efb", "price_changes": [{"asset_id": "30112939078428479271380004766658148462656808495063824079473460276372582172087", "price": "0.26", "size": "66.66", "side": "BUY", "hash": "afc51111f9219b55f7849be6aa4997162c2740d8", "best_bid": "0.27", "best_ask": "0.91"}, {"asset_id": "23125627318359544367614218401841961178939444671222355150077267933985277277448", "price": "0.74", "size": "66.66", "side": "SELL", "hash": "ff43ea1fc85d28148b5ee30ea66bcbed45c2b6cb", "best_bid": "0.09", "best_ask": "0.73"}], "timestamp": "1769384352208", "event_type": "price_change"}}
{"_local_timestamp": "2026-01-25T23:39:12.317691+00:00", "data": {"market": "0x91dd8dbe75a5347f14455ca880070ebcf3356bfd7df8caf19478e881bb483efb", "price_changes": [{"asset_id": "30112939078428479271380004766658148462656808495063824079473460276372582172087", "price": "0.27", "size": "72", "side": "BUY", "hash": "39a9717d54f18a741e8717986cd5676390a808e4", "best_bid": "0.27", "best_ask": "0.91"}, {"asset_id": "23125627318359544367614218401841961178939444671222355150077267933985277277448", "price": "0.73", "size": "72", "side": "SELL", "hash": "164fc9ec8eeeebbc74187f54b01fbe9fe91fb6a3", "best_bid": "0.09", "best_ask": "0.73"}], "timestamp": "1769384352244", "event_type": "price_change"}}
{"_local_timestamp": "2026-01-25T23:39:18.058350+00:00", "data": {"market": "0x5d7fc002c8fbc73a1c18dbb111d96f0ca54e02ae1aa2a6a98ca8d62000f31526", "price_changes": [{"asset_id": "92027124758235029160948120350916378905334564613489667041482264435793489339845", "price": "0.2", "size": "0", "side": "BUY", "hash": "fb6c4aa50e3b21918f3871178640bcb222112c66", "best_bid": "0.35", "best_ask": "0.95"}, {"asset_id": "49246609416501398794937573302498657712519224305673745144194417177683023634127", "price": "0.8", "size": "0", "side": "SELL", "hash": "84a53d880245ef2febb7b1252bb101f598873bb5", "best_bid": "0.05", "best_ask": "0.65"}], "timestamp": "1769384357987", "event_type": "price_change"}}
