{"_local_timestamp": "2026-01-25T23:40:53.418542+00:00", "data": [{"market": "0x1fed6d1346b04331b1ba1188525e560094040cbf3bbd84700c2dddb5241b2402", "asset_id": "38855512439706823591548373609888890731724800742290402025988926984750840280976", "timestamp": "1769384445320", "hash": "7b3c16bf4c5baf3363d5ae86128c1c56f16620ff", "bids": [{"price": "0.001", "size": "3054.01"}, {"price": "0.002", "size": "1255"}, {"price": "0.003", "size": "1000"}, {"price": "0.004", "size": "20.88"}, {"price": "0.01", "size": "4350"}, {"price": "0.02", "size": "1750"}, {"price": "0.021", "size": "8.84"}, {"price": "0.04", "size": "1700"}, {"price": "0.041", "size": "100"}, {"price": "0.05", "size": "30"}, {"price": "0.051", "size": "39"}, {"price": "0.06", "size": "450"}, {"price": "0.061", "size": "100"}, {"price": "0.062", "size": "8.84"}, {"price": "0.13", "size": "200"}, {"price": "0.15", "size": "125"}, {"price": "0.17", "size": "150"}, {"price": "0.2", "size": "100"}, {"price": "0.202", "size": "125.78"}, {"price": "0.21", "size": "100"}, {"price": "0.25", "size": "50"}, {"price": "0.421", "size": "60"}, {"price": "0.424", "size": "32"}, {"price": "0.518", "size": "10.6"}, {"price": "0.557", "size": "100"}, {"price": "0.558", "size": "5"}, {"price": "0.83", "size": "150"}, {"price": "0.832", "size": "45"}, {"price": "0.91", "size": "50"}, {"price": "0.911", "size": "39.87"}], "asks": [{"price": "0.999", "size": "2348.99"}, {"price": "0.998", "size": "550"}, {"price": "0.997", "size": "300"}, {"price": "0.996", "size": "200"}, {"price": "0.995", "size": "122.67"}, {"price": "0.993", "size": "64"}, {"price": "0.991", "size": "22.67"}, {"price": "0.989", "size": "22.67"}], "event_type": "book", "last_trade_price": ""}, {"market": "0xc65ebe3378903b9f672868b4ad157b12f8d5b801303c224e2b9627c1de6e1bb4", "asset_id": "100153647768819913478482487007469803840833665951037785527037226522546628635049", "timestamp": "1769384421411", "hash": "3c55547528135adef31c90602d065471d5896787", "bids": [{"price": "0.01", "size": "3429.48"}, {"price": "0.02", "size": "1750"}, {"price": "0.03", "size": "10.33"}, {"price": "0.04", "size": "1000"}, {"price": "0.05", "size": "130"}, {"price": "0.06", "size": "250"}, {"price": "0.07", "size": "134.03"}, {"price": "0.12", "size": "66.66"}, {"price": "0.16", "size": "145"}, {"price": "0.17", "size": "6.7"}, {"price": "0.22", "size": "6"}, {"price": "0.23", "size": "66.66"}, {"price": "0.24", "size": "29.34"}], "asks": [{"price": "0.99", "size": "190"}, {"price": "0.98", "size": "117"}, {"price": "0.97", "size": "6"}, {"price": "0.96", "size": "6.25"}, {"price": "0.95", "size": "15"}], "event_type": "book", "last_trade_price": "0.060"}, {"market": "0x105658ed412868eff64622ff122b425042797cb1886ac13bba10627cb395b3a0", "asset_id": "42623828760560956825816893329368389610613334458449432332189049581423522261963", "timestamp": "1769384323387", "hash": "1026efe7b8c96c135f24224cd21905a63661a490", "bids": [{"price": "0.001", "size": "4409.99"}, {"price": "0.002", "size": "400"}, {"price": "0.006", "size": "356.66"}, {"price": "0.007", "size": "230"}, {"price": "0.008", "size": "294.02"}, {"price": "0.009", "size": "220"}], "asks": [{"price": "0.999", "size": "2120.09"}, {"price": "0.998", "size": "1250"}, {"price": "0.997", "size": "29.93"}, {"price": "0.99", "size": "4350"}, {"price": "0.98", "size": "1750"}, {"price": "0.979", "size": "8.87"}, {"price": "0.96", "size": "1700"}, {"price": "0.95", "size": "30"}, {"price": "0.949", "size": "39"}, {"price": "0.94", "size": "250"}, {"price": "0.939", "size": "9.04"}, {"price": "0.9", "size": "560"}, {"price": "0.85", "size": "551.66"}, {"price": "0.8", "size": "160"}, {"price": "0.799", "size": "20"}, {"price": "0.798", "size": "5.75"}, {"price": "0.75", "size": "112"}, {"price": "0.7", "size": "86.66"}, {"price": "0.651", "size": "200"}, {"price": "0.65", "size": "68.57"}, {"price": "0.6", "size": "50"}, {"price": "0.58", "size": "150"}, {"price": "0.579", "size": "220"}, {"price": "0.577", "size": "130"}, {"price": "0.576", "size": "5"}, {"price": "0.031", "size": "13"}, {"price": "0.03", "size": "66"}], "event_type": "book", "last_trade_price": ""}, {"market": "0x77e024fc3dac13c1404f30a42d8df3b32a62978c63f82b36f62df830604471a0", "asset_id": "71885734107267615372441598160876793410818281961487005825293143068106970826321", "timestamp": "1769384440649", "hash": "bd7801035d267860438af43f8381600c5028209a", "bids": [{"price": "0.001", "size": "3558.01"}, {"price": "0.002", "size": "1257.53"}, {"price": "0.005", "size": "15.76"}, {"price": "0.01", "size": "4350"}, {"price": "0.02", "size": "1750"}, {"price": "0.021", "size": "8.84"}, {"price": "0.04", "size": "1700"}, {"price": "0.05", "size": "30"}, {"price": "0.051", "size": "39"}, {"price": "0.06", "size": "250"}, {"price": "0.061", "size": "9.02"}, {"price": "0.1", "size": "560"}, {"price": "0.15", "size": "551.66"}, {"price": "0.2", "size": "260"}, {"price": "0.201", "size": "220"}, {"price": "0.202", "size": "20"}, {"price": "0.203", "size": "5.74"}, {"price": "0.25", "size": "112"}, {"price": "0.3", "size": "236.66"}, {"price": "0.35", "size": "68.57"}, {"price": "0.4", "size": "50"}, {"price": "0.402", "size": "10"}, {"price": "0.43", "size": "150"}, {"price": "0.431", "size": "75"}, {"price": "0.432", "size": "5"}, {"price": "0.636", "size": "100"}, {"price": "0.97", "size": "58.75"}, {"price": "0.971", "size": "10"}], "asks": [{"price": "0.999", "size": "2352.99"}, {"price": "0.998", "size": "400"}, {"price": "0.997", "size": "300"}, {"price": "0.996", "size": "126.67"}, {"price": "0.995", "size": "185.67"}, {"price": "0.994", "size": "26.67"}], "event_type": "book", "last_trade_price": ""}, {"market": "0xd3aa6ab9adcf1d7189a287e6a86dd2ae378fa7a635863f7d249ce70a1f28395e", "asset_id": "5525740420504230154399891807905567389393779493359335912984255288237335578501", "timestamp": "1769384308758", "hash": "c989d4edbd9aaa6935899c37462e0cc1790b1901", "bids": [{"price": "0.001", "size": "1867.99"}, {"price": "0.002", "size": "400"}, {"price": "0.003", "size": "300"}, {"price": "0.004", "size": "216.66"}, {"price": "0.005", "size": "161.66"}, {"price": "0.006", "size": "16.66"}], "asks": [{"price": "0.999", "size": "3073.04"}, {"price": "0.998", "size": "1255.13"}, {"price": "0.997", "size": "1000"}, {"price": "0.996", "size": "21.41"}, {"price": "0.99", "size": "4350"}, {"price": "0.98", "size": "1750"}, {"price": "0.979", "size": "8.88"}, {"price": "0.96", "size": "1700"}, {"price": "0.95", "size": "30"}, {"price": "0.949", "size": "39"}, {"price": "0.94", "size": "250"}, {"price": "0.939", "size": "9"}, {"price": "0.9", "size": "560"}, {"price": "0.85", "size": "551.66"}, {"price": "0.849", "size": "89.49"}, {"price": "0.8", "size": "160"}, {"price": "0.799", "size": "20"}, {"price": "0.798", "size": "5.76"}, {"price": "0.75", "size": "112"}, {"price": "0.749", "size": "100"}, {"price": "0.7", "size": "86.66"}, {"price": "0.65", "size": "68.57"}, {"price": "0.6", "size": "50"}, {"price": "0.58", "size": "150"}, {"price": "0.579", "size": "75"}, {"price": "0.578", "size": "5"}, {"price": "0.39", "size": "100"}, {"price": "0.066", "size": "6.75"}, {"price": "0.04", "size": "25"}, {"price": "0.033", "size": "10"}, {"price": "0.032", "size": "10"}], "event_type": "book", "last_trade_price": ""}, {"market": "0xc65ebe3378903b9f672868b4ad157b12f8d5b801303c224e2b9627c1de6e1bb4", "asset_id": "68287553062600224636928508192555401721388367384589206235766778752053103462686", "timestamp": "1769384421411", "hash": "3da6f90e8e261d83442974fe58ed0735d8db821f", "bids": [{"price": "0.01", "size": "190"}, {"price": "0.02", "size": "117"}, {"price": "0.03", "size": "6"}, {"price": "0.04", "size": "6.25"}, {"price": "0.05", "size": "15"}], "asks": [{"price": "0.99", "size": "3429.48"}, {"price": "0.98", "size": "1750"}, {"price": "0.97", "size": "10.33"}, {"price": "0.96", "size": "1000"}, {"price": "0.95", "size": "130"}, {"price": "0.94", "size": "250"}, {"price": "0.93", "size": "134.03"}, {"price": "0.88", "size": "66.66"}, {"price": "0.84", "size": "145"}, {"price": "0.83", "size": "6.7"}, {"price": "0.78", "size": "6"}, {"price": "0.77", "size": "66.66"}, {"price": "0.76", "size": "29.34"}], "event_type": "book", "last_trade_price": "0.060"}, {"market": "0xbf6fbc35082962002b61f17e26820db124930ac43175934864e34a415ee40620", "asset_id": "42674776176570186449325309200969258771704155869979743437343764984621699243894", "timestamp": "1769384410328", "hash": "6b3b49d3a8e6a09ea7cc01e0d5958c58590b0dbe", "bids": [{"price": "0.01", "size": "4429.14"}, {"price": "0.02", "size": "1750"}, {"price": "0.03", "size": "5.7"}, {"price": "0.04", "size": "1700"}, {"price": "0.05", "size": "30"}, {"price": "0.06", "size": "283"}, {"price": "0.13", "size": "152.35"}, {"price": "0.14", "size": "76"}, {"price": "0.15", "size": "20"}, {"price": "0.16", "size": "7.19"}, {"price": "0.26", "size": "66.66"}, {"price": "0.28", "size": "15"}, {"price": "0.34", "size": "700"}, {"price": "0.35", "size": "150"}, {"price": "0.36", "size": "5"}, {"price": "0.5", "size": "20"}, {"price": "0.55", "size": "66.66"}], "asks": [{"price": "0.99", "size": "66.66"}, {"price": "0.98", "size": "50"}, {"price": "0.97", "size": "66.66"}, {"price": "0.94", "size": "89.66"}], "event_type": "book", "last_trade_price": ""}, {"market": "0xa04889441513194066b992c25607750d9ad9beda073baa231b7d6c0d296f3db4", "asset_id": "4927715355597512197888285947791839404212602020821540571091074384909522708343", "timestamp": "1769384445917", "hash": "ecefd9e296bd4764ac634abeb808cf1dbc24def1", "bids": [{"price": "0.001", "size": "6300.02"}, {"price": "0.002", "size": "1256.4"}, {"price": "0.003", "size": "1000"}, {"price": "0.004", "size": "11.09"}, {"price": "0.01", "size": "4350"}, {"price": "0.011", "size": "5.65"}, {"price": "0.02", "size": "1750"}, {"price": "0.021", "size": "8.85"}, {"price": "0.04", "size": "1700"}, {"price": "0.05", "size": "130"}, {"price": "0.051", "size": "39"}, {"price": "0.06", "size": "450"}, {"price": "0.061", "size": "100"}, {"price": "0.07", "size": "100"}, {"price": "0.071", "size": "6.33"}, {"price": "0.11", "size": "325"}, {"price": "0.16", "size": "250"}, {"price": "0.161", "size": "100"}, {"price": "0.162", "size": "7.65"}, {"price": "0.163", "size": "20"}, {"price": "0.21", "size": "100"}, {"price": "0.223", "size": "9.52"}, {"price": "0.372", "size": "50"}, {"price": "0.41", "size": "150"}, {"price": "0.511", "size": "100"}, {"price": "0.512", "size": "5"}, {"price": "0.86", "size": "50"}, {"price": "0.861", "size": "10"}], "asks": [{"price": "0.999", "size": "2694.61"}, {"price": "0.998", "size": "266.06"}, {"price": "0.997", "size": "21.25"}, {"price": "0.996", "size": "500"}, {"price": "0.995", "size": "406.32"}, {"price": "0.994", "size": "277.13"}, {"price": "0.993", "size": "100"}, {"price": "0.989", "size": "66.66"}, {"price": "0.988", "size": "56"}, {"price": "0.986", "size": "200"}, {"price": "0.985", "size": "66.66"}], "event_type": "book", "last_trade_price": ""}, {"market": "0x77e024fc3dac13c1404f30a42d8df3b32a62978c63f82b36f62df830604471a0", "asset_id": "87132914336773401193105961480278292749054879702172274912936083065312455895521", "timestamp": "1769384440649", "hash": "de8237576ea27b92ff36f4e2c545bd659d684fa3", "bids": [{"price": "0.001", "size": "2352.99"}, {"price": "0.002", "size": "400"}, {"price": "0.003", "size": "300"}, {"price": "0.004", "size": "126.67"}, {"price": "0.005", "size": "185.67"}, {"price": "0.006", "size": "26.67"}], "asks": [{"price": "0.999", "size": "3558.01"}, {"price": "0.998", "size": "1257.53"}, {"price": "0.995", "size": "15.76"}, {"price": "0.99", "size": "4350"}, {"price": "0.98", "size": "1750"}, {"price": "0.979", "size": "8.84"}, {"price": "0.96", "size": "1700"}, {"price": "0.95", "size": "30"}, {"price": "0.949", "size": "39"}, {"price": "0.94", "size": "250"}, {"price": "0.939", "size": "9.02"}, {"price": "0.9", "size": "560"}, {"price": "0.85", "size": "551.66"}, {"price": "0.8", "size": "260"}, {"price": "0.799", "size": "220"}, {"price": "0.798", "size": "20"}, {"price": "0.797", "size": "5.74"}, {"price": "0.75", "size": "112"}, {"price": "0.7", "size": "236.66"}, {"price": "0.65", "size": "68.57"}, {"price": "0.6", "size": "50"}, {"price": "0.598", "size": "10"}, {"price": "0.57", "size": "150"}, {"price": "0.569", "size": "75"}, {"price": "0.568", "size": "5"}, {"price": "0.364", "size": "100"}, {"price": "0.03", "size": "58.75"}, {"price": "0.029", "size": "10"}], "event_type": "book", "last_trade_price": ""}, {"market": "0xa04889441513194066b992c25607750d9ad9beda073baa231b7d6c0d296f3db4", "asset_id": "38098642543471813014855148341368026538917449780662028630830591144684505089593", "timestamp": "1769384445917", "hash": "93311b4d033541cfc22a36ad087d7c256b5b29dd", "bids": [{"price": "0.001", "size": "2694.61"}, {"price": "0.002", "size": "266.06"}, {"price": "0.003", "size": "21.25"}, {"price": "0.004", "size": "500"}, {"price": "0.005", "size": "406.32"}, {"price": "0.006", "size": "277.13"}, {"price": "0.007", "size": "100"}, {"price": "0.011", "size": "66.66"}, {"price": "0.012", "size": "56"}, {"price": "0.014", "size": "200"}, {"price": "0.015", "size": "66.66"}], "asks": [{"price": "0.999", "size": "6300.02"}, {"price": "0.998", "size": "1256.4"}, {"price": "0.997", "size": "1000"}, {"price": "0.996", "size": "11.09"}, {"price": "0.99", "size": "4350"}, {"price": "0.989", "size": "5.65"}, {"price": "0.98", "size": "1750"}, {"price": "0.979", "size": "8.85"}, {"price": "0.96", "size": "1700"}, {"price": "0.95", "size": "130"}, {"price": "0.949", "size": "39"}, {"price": "0.94", "size": "450"}, {"price": "0.939", "size": "100"}, {"price": "0.93", "size": "100"}, {"price": "0.929", "size": "6.33"}, {"price": "0.89", "size": "325"}, {"price": "0.84", "size": "250"}, {"price": "0.839", "size": "100"}, {"price": "0.838", "size": "7.65"}, {"price": "0.837", "size": "20"}, {"price": "0.79", "size": "100"}, {"price": "0.777", "size": "9.52"}, {"price": "0.628", "size": "50"}, {"price": "0.59", "size": "150"}, {"price": "0.489", "size": "100"}, {"price": "0.488", "size": "5"}, {"price": "0.14", "size": "50"}, {"price": "0.139", "size": "10"}], "event_type": "book", "last_trade_price": ""}, {"market": "0xbf6fbc35082962002b61f17e26820db124930ac43175934864e34a415ee40620", "asset_id": "98673773007855046568692125013481059419674479536813359840428477180250006155633", "timestamp": "1769384410328", "hash": "d783731b8244355b611f90a96e6cac0f9005c668", "bids": [{"price": "0.01", "size": "66.66"}, {"price": "0.02", "size": "50"}, {"price": "0.03", "size": "66.66"}, {"price": "0.06", "size": "89.66"}], "asks": [{"price": "0.99", "size": "4429.14"}, {"price": "0.98", "size": "1750"}, {"price": "0.97", "size": "5.7"}, {"price": "0.96", "size": "1700"}, {"price": "0.95", "size": "30"}, {"price": "0.94", "size": "283"}, {"price": "0.87", "size": "152.35"}, {"price": "0.86", "size": "76"}, {"price": "0.85", "size": "20"}, {"price": "0.84", "size": "7.19"}, {"price": "0.74", "size": "66.66"}, {"price": "0.72", "size": "15"}, {"price": "0.66", "size": "700"}, {"price": "0.65", "size": "150"}, {"price": "0.64", "size": "5"}, {"price": "0.5", "size": "20"}, {"price": "0.45", "size": "66.66"}], "event_type": "book", "last_trade_price": ""}, {"market": "0x105658ed412868eff64622ff122b425042797cb1886ac13bba10627cb395b3a0", "asset_id": "62389192985532225428000072411944560217557819885493029090152096982024014976363", "timestamp": "1769384323387", "hash": "71f5e90e4992755f332500130a25d31f6a8854bf", "bids": [{"price": "0.001", "size": "2120.09"}, {"price": "0.002", "size": "1250"}, {"price": "0.003", "size": "29.93"}, {"price": "0.01", "size": "4350"}, {"price": "0.02", "size": "1750"}, {"price": "0.021", "size": "8.87"}, {"price": "0.04", "size": "1700"}, {"price": "0.05", "size": "30"}, {"price": "0.051", "size": "39"}, {"price": "0.06", "size": "250"}, {"price": "0.061", "size": "9.04"}, {"price": "0.1", "size": "560"}, {"price": "0.15", "size": "551.66"}, {"price": "0.2", "size": "160"}, {"price": "0.201", "size": "20"}, {"price": "0.202", "size": "5.75"}, {"price": "0.25", "size": "112"}, {"price": "0.3", "size": "86.66"}, {"price": "0.349", "size": "200"}, {"price": "0.35", "size": "68.57"}, {"price": "0.4", "size": "50"}, {"price": "0.42", "size": "150"}, {"price": "0.421", "size": "220"}, {"price": "0.423", "size": "130"}, {"price": "0.424", "size": "5"}, {"price": "0.969", "size": "13"}, {"price": "0.97", "size": "66"}], "asks": [{"price": "0.999", "size": "4409.99"}, {"price": "0.998", "size": "400"}, {"price": "0.994", "size": "356.66"}, {"price": "0.993", "size": "230"}, {"price": "0.992", "size": "294.02"}, {"price": "0.991", "size": "220"}], "event_type": "book", "last_trade_price": ""}, {"market": "0xe1730ddaa88ffb2fb360af9f5b58c9e427f61c30712578b1701408911e3f655d", "asset_id": "37042473221634168250099193554902520956898907103252140530642497138603218091624", "timestamp": "1769384404025", "hash": "e6cb03c853b6a50bf413bcfb53220b00ee580f94", "bids": [{"price": "0.01", "size": "3379.46"}, {"price": "0.02", "size": "1756.25"}, {"price": "0.03", "size": "15.77"}, {"price": "0.04", "size": "1700"}, {"price": "0.05", "size": "230"}, {"price": "0.06", "size": "383"}, {"price": "0.07", "size": "306.17"}, {"price": "0.08", "size": "200"}, {"price": "0.1", "size": "99.66"}, {"price": "0.11", "size": "7.64"}, {"price": "0.12", "size": "20"}, {"price": "0.18", "size": "121.66"}], "asks": [{"price": "0.99", "size": "166.66"}, {"price": "0.98", "size": "100"}, {"price": "0.97", "size": "66.66"}, {"price": "0.95", "size": "20"}, {"price": "0.93", "size": "33"}, {"price": "0.91", "size": "102.21"}], "event_type": "book", "last_trade_price": ""}, {"market": "0xe1730ddaa88ffb2fb360af9f5b58c9e427f61c30712578b1701408911e3f655d", "asset_id": "81699282895973617782040895594229616523859617972840387954210064871270448792972", "timestamp": "1769384404025", "hash": "6e0596e30e0129131df9a4883a8421a382c46891", "bids": [{"price": "0.01", "size": "166.66"}, {"price": "0.02", "size": "100"}, {"price": "0.03", "size": "66.66"}, {"price": "0.05", "size": "20"}, {"price": "0.07", "size": "33"}, {"price": "0.09", "size": "102.21"}], "asks": [{"price": "0.99", "size": "3379.46"}, {"price": "0.98", "size": "1756.25"}, {"price": "0.97", "size": "15.77"}, {"price": "0.96", "size": "1700"}, {"price": "0.95", "size": "230"}, {"price": "0.94", "size": "383"}, {"price": "0.93", "size": "306.17"}, {"price": "0.92", "size": "200"}, {"price": "0.9", "size": "99.66"}, {"price": "0.89", "size": "7.64"}, {"price": "0.88", "size": "20"}, {"price": "0.82", "size": "121.66"}], "event_type": "book", "last_trade_price": ""}, {"market": "0xadf6a02ac5b93901c17197de47e9c0afcc9449c6d85dec96448fa8cc90090490", "asset_id": "75870434740998190734966085726451060764959387741262916639210627595656112930617", "timestamp": "1769384440615", "hash": "11ae0b63bcb2574bcbcf81ec9dfda686c5e3f6da", "bids": [{"price": "0.001", "size": "2208.99"}, {"price": "0.002", "size": "400"}, {"price": "0.003", "size": "300"}, {"price": "0.004", "size": "155.87"}, {"price": "0.005", "size": "129.67"}, {"price": "0.007", "size": "26.67"}], "asks": [{"price": "0.999", "size": "3914.05"}, {"price": "0.998", "size": "1255.05"}, {"price": "0.997", "size": "1000"}, {"price": "0.996", "size": "21.06"}, {"price": "0.99", "size": "4350"}, {"price": "0.98", "size": "1750"}, {"price": "0.979", "size": "8.9"}, {"price": "0.96", "size": "1700"}, {"price": "0.95", "size": "30"}, {"price": "0.949", "size": "39"}, {"price": "0.94", "size": "250"}, {"price": "0.939", "size": "9.07"}, {"price": "0.9", "size": "560"}, {"price": "0.85", "size": "551.66"}, {"price": "0.8", "size": "410"}, {"price": "0.799", "size": "220"}, {"price": "0.798", "size": "20"}, {"price": "0.797", "size": "5.71"}, {"price": "0.75", "size": "212"}, {"price": "0.7", "size": "236.66"}, {"price": "0.65", "size": "68.57"}, {"price": "0.6", "size": "50"}, {"price": "0.599", "size": "5"}, {"price": "0.579", "size": "60"}, {"price": "0.576", "size": "65"}, {"price": "0.364", "size": "100"}, {"price": "0.17", "size": "150"}, {"price": "0.03", "size": "66"}, {"price": "0.029", "size": "10"}], "event_type": "book", "last_trade_price": ""}, {"market": "0x1fed6d1346b04331b1ba1188525e560094040cbf3bbd84700c2dddb5241b2402", "asset_id": "71341306129608304129076187431040953407253993378796751066411893382443918679197", "timestamp": "1769384445320", "hash": "4161ead8211f97e42206f3a49462c35e95605327", "bids": [{"price": "0.001", "size": "2348.99"}, {"price": "0.002", "size": "550"}, {"price": "0.003", "size": "300"}, {"price": "0.004", "size": "200"}, {"price": "0.005", "size": "122.67"}, {"price": "0.007", "size": "64"}, {"price": "0.009", "size": "22.67"}, {"price": "0.011", "size": "22.67"}], "asks": [{"price": "0.999", "size": "3054.01"}, {"price": "0.998", "size": "1255"}, {"price": "0.997", "size": "1000"}, {"price": "0.996", "size": "20.88"}, {"price": "0.99", "size": "4350"}, {"price": "0.98", "size": "1750"}, {"price": "0.979", "size": "8.84"}, {"price": "0.96", "size": "1700"}, {"price": "0.959", "size": "100"}, {"price": "0.95", "size": "30"}, {"price": "0.949", "size": "39"}, {"price": "0.94", "size": "450"}, {"price": "0.939", "size": "100"}, {"price": "0.938", "size": "8.84"}, {"price": "0.87", "size": "200"}, {"price": "0.85", "size": "125"}, {"price": "0.83", "size": "150"}, {"price": "0.8", "size": "100"}, {"price": "0.798", "size": "125.78"}, {"price": "0.79", "size": "100"}, {"price": "0.75", "size": "50"}, {"price": "0.579", "size": "60"}, {"price": "0.576", "size": "32"}, {"price": "0.482", "size": "10.6"}, {"price": "0.443", "size": "100"}, {"price": "0.442", "size": "5"}, {"price": "0.17", "size": "150"}, {"price": "0.168", "size": "45"}, {"price": "0.09", "size": "50"}, {"price": "0.089", "size": "39.87"}], "event_type": "book", "last_trade_price": ""}, {"market": "0xd3aa6ab9adcf1d7189a287e6a86dd2ae378fa7a635863f7d249ce70a1f28395e", "asset_id": "17621949038627205799005149654166056280336330529029840823213885378726883921449", "timestamp": "1769384308758", "hash": "25b2dbb4c3cf022dc748d667e72675e3c1d70637", "bids": [{"price": "0.001", "size": "3073.04"}, {"price": "0.002", "size": "1255.13"}, {"price": "0.003", "size": "1000"}, {"price": "0.004", "size": "21.41"}, {"price": "0.01", "size": "4350"}, {"price": "0.02", "size": "1750"}, {"price": "0.021", "size": "8.88"}, {"price": "0.04", "size": "1700"}, {"price": "0.05", "size": "30"}, {"price": "0.051", "size": "39"}, {"price": "0.06", "size": "250"}, {"price": "0.061", "size": "9"}, {"price": "0.1", "size": "560"}, {"price": "0.15", "size": "551.66"}, {"price": "0.151", "size": "89.49"}, {"price": "0.2", "size": "160"}, {"price": "0.201", "size": "20"}, {"price": "0.202", "size": "5.76"}, {"price": "0.25", "size": "112"}, {"price": "0.251", "size": "100"}, {"price": "0.3", "size": "86.66"}, {"price": "0.35", "size": "68.57"}, {"price": "0.4", "size": "50"}, {"price": "0.42", "size": "150"}, {"price": "0.421", "size": "75"}, {"price": "0.422", "size": "5"}, {"price": "0.61", "size": "100"}, {"price": "0.934", "size": "6.75"}, {"price": "0.96", "size": "25"}, {"price": "0.967", "size": "10"}, {"price": "0.968", "size": "10"}], "asks": [{"price": "0.999", "size": "1867.99"}, {"price": "0.998", "size": "400"}, {"price": "0.997", "size": "300"}, {"price": "0.996", "size": "216.66"}, {"price": "0.995", "size": "161.66"}, {"price": "0.994", "size": "16.66"}], "event_type": "book", "last_trade_price": ""}, {"market": "0x5edebf3eb73ed300d47dd35e4c3938a6997cdbf3fa3b3ca086bdd7afa3e227cc", "asset_id": "47977478528993701917993634313399360833217034323739582269237365313563183735835", "timestamp": "1769384445917", "hash": "833349d5953e1fddb2d2e95a4760991a60e574b9", "bids": [{"price": "0.001", "size": "2097.08"}, {"price": "0.002", "size": "476.86"}, {"price": "0.003", "size": "317.81"}, {"price": "0.004", "size": "279.95"}, {"price": "0.008", "size": "66.66"}, {"price": "0.009", "size": "53"}, {"price": "0.011", "size": "200"}, {"price": "0.012", "size": "66.66"}], "asks": [{"price": "0.999", "size": "6296.03"}, {"price": "0.998", "size": "1256.78"}, {"price": "0.997", "size": "1000"}, {"price": "0.996", "size": "24.17"}, {"price": "0.99", "size": "4350"}, {"price": "0.98", "size": "1750"}, {"price": "0.979", "size": "6.78"}, {"price": "0.96", "size": "1700"}, {"price": "0.95", "size": "30"}, {"price": "0.949", "size": "39"}, {"price": "0.94", "size": "450"}, {"price": "0.939", "size": "10.2"}, {"price": "0.89", "size": "200"}, {"price": "0.84", "size": "150"}, {"price": "0.839", "size": "200"}, {"price": "0.838", "size": "20"}, {"price": "0.79", "size": "100"}, {"price": "0.788", "size": "5.28"}, {"price": "0.772", "size": "9.58"}, {"price": "0.771", "size": "8"}, {"price": "0.618", "size": "50"}, {"price": "0.13", "size": "50"}, {"price": "0.129", "size": "10"}], "event_type": "book", "last_trade_price": ""}, {"market": "0x5edebf3eb73ed300d47dd35e4c3938a6997cdbf3fa3b3ca086bdd7afa3e227cc", "asset_id": "48973293128569491311605281174826846182724783049607561423479481850292050544724", "timestamp": "1769384445917", "hash": "8afac773011079db2cea85fd878164ca27ec5bfe", "bids": [{"price": "0.001", "size": "6296.03"}, {"price": "0.002", "size": "1256.78"}, {"price": "0.003", "size": "1000"}, {"price": "0.004", "size": "24.17"}, {"price": "0.01", "size": "4350"}, {"price": "0.02", "size": "1750"}, {"price": "0.021", "size": "6.78"}, {"price": "0.04", "size": "1700"}, {"price": "0.05", "size": "30"}, {"price": "0.051", "size": "39"}, {"price": "0.06", "size": "450"}, {"price": "0.061", "size": "10.2"}, {"price": "0.11", "size": "200"}, {"price": "0.16", "size": "150"}, {"price": "0.161", "size": "200"}, {"price": "0.162", "size": "20"}, {"price": "0.21", "size": "100"}, {"price": "0.212", "size": "5.28"}, {"price": "0.228", "size": "9.58"}, {"price": "0.229", "size": "8"}, {"price": "0.382", "size": "50"}, {"price": "0.87", "size": "50"}, {"price": "0.871", "size": "10"}], "asks": [{"price": "0.999", "size": "2097.08"}, {"price": "0.998", "size": "476.86"}, {"price": "0.997", "size": "317.81"}, {"price": "0.996", "size": "279.95"}, {"price": "0.992", "size": "66.66"}, {"price": "0.991", "size": "53"}, {"price": "0.989", "size": "200"}, {"price": "0.988", "size": "66.66"}], "event_type": "book", "last_trade_price": ""}, {"market": "0xadf6a02ac5b93901c17197de47e9c0afcc9449c6d85dec96448fa8cc90090490", "asset_id": "107911337214497912248693530548658782366601738149965815249360222958641298955539", "timestamp": "1769384440615", "hash": "24b5a4c2d71823c3680d34583cd7ae5d8a3f5d15", "bids": [{"price": "0.001", "size": "3914.05"}, {"price": "0.002", "size": "1255.05"}, {"price": "0.003", "size": "1000"}, {"price": "0.004", "size": "21.06"}, {"price": "0.01", "size": "4350"}, {"price": "0.02", "size": "1750"}, {"price": "0.021", "size": "8.9"}, {"price": "0.04", "size": "1700"}, {"price": "0.05", "size": "30"}, {"price": "0.051", "size": "39"}, {"price": "0.06", "size": "250"}, {"price": "0.061", "size": "9.07"}, {"price": "0.1", "size": "560"}, {"price": "0.15", "size": "551.66"}, {"price": "0.2", "size": "410"}, {"price": "0.201", "size": "220"}, {"price": "0.202", "size": "20"}, {"price": "0.203", "size": "5.71"}, {"price": "0.25", "size": "212"}, {"price": "0.3", "size": "236.66"}, {"price": "0.35", "size": "68.57"}, {"price": "0.4", "size": "50"}, {"price": "0.401", "size": "5"}, {"price": "0.421", "size": "60"}, {"price": "0.424", "size": "65"}, {"price": "0.636", "size": "100"}, {"price": "0.83", "size": "150"}, {"price": "0.97", "size": "66"}, {"price": "0.971", "size": "10"}], "asks": [{"price": "0.999", "size": "2208.99"}, {"price": "0.998", "size": "400"}, {"price": "0.997", "size": "300"}, {"price": "0.996", "size": "155.87"}, {"price": "0.995", "size": "129.67"}, {"price": "0.993", "size": "26.67"}], "event_type": "book", "last_trade_price": ""}]}
{"_local_timestamp": "2026-01-25T23:40:59.195922+00:00", "data": {"market": "0x5edebf3eb73ed300d47dd35e4c3938a6997cdbf3fa3b3ca086bdd7afa3e227cc", "price_changes": [{"asset_id": "48973293128569491311605281174826846182724783049607561423479481850292050544724", "price": "0.04", "size": "1300", "side": "BUY", "hash": "d2e1d58d513aaf132db0040f8337999cd14a3cfe", "best_bid": "0.871", "best_ask": "0.988"}, {"asset_id": "47977478528993701917993634313399360833217034323739582269237365313563183735835", "price": "0.96", "size": "1300", "side": "SELL", "hash": "e104b8b31b5ce5a179ac34146d29d2ca27f08959", "best_bid": "0.012", "best_ask": "0.129"}], "timestamp": "1769384459095", "event_type": "price_change"}}
{"_local_timestamp": "2026-01-25T23:40:59.199264+00:00", "data": {"market": "0x5edebf3eb73ed300d47dd35e4c3938a6997cdbf3fa3b3ca086bdd7afa3e227cc", "price_changes": [{"asset_id": "48973293128569491311605281174826846182724783049607561423479481850292050544724", "price": "0.01", "size": "3350", "side": "BUY", "hash": "d2e1d58d513aaf132db0040f8337999cd14a3cfe", "best_bid": "0.871", "best_ask": "0.988"}, {"asset_id": "47977478528993701917993634313399360833217034323739582269237365313563183735835", "price": "0.99", "size": "3350", "side": "SELL", "hash": "e104b8b31b5ce5a179ac34146d29d2ca27f08959", "best_bid": "0.012", "best_ask": "0.129"}], "timestamp": "1769384459095", "event_type": "price_change"}}
{"_local_timestamp": "2026-01-25T23:40:59.200113+00:00", "data": {"market": "0x5edebf3eb73ed300d47dd35e4c3938a6997cdbf3fa3b3ca086bdd7afa3e227cc", "price_changes": [{"asset_id": "48973293128569491311605281174826846182724783049607561423479481850292050544724", "price": "0.06", "size": "250", "side": "BUY", "hash": "d2e1d58d513aaf132db0040f8337999cd14a3cfe", "best_bid": "0.871", "best_ask": "0.988"}, {"asset_id": "47977478528993701917993634313399360833217034323739582269237365313563183735835", "price": "0.94", "size": "250", "side": "SELL", "hash": "e104b8b31b5ce5a179ac34146d29d2ca27f08959", "best_bid": "0.012", "best_ask": "0.129"}], "timestamp": "1769384459095", "event_type": "price_change"}}
{"_local_timestamp": "2026-01-25T23:41:06.730756+00:00", "data": {"market": "0x105658ed412868eff64622ff122b425042797cb1886ac13bba10627cb395b3a0", "price_changes": [{"asset_id": "42623828760560956825816893329368389610613334458449432332189049581423522261963", "price": "0.002", "size": "300", "side": "BUY", "hash": "99494c269200d49941ab3780d2d8b934457a50e5", "best_bid": "0.009", "best_ask": "0.03"}, {"asset_id": "62389192985532225428000072411944560217557819885493029090152096982024014976363", "price": "0.998", "size": "300", "side": "SELL", "hash": "519074553fdc6830485f79680fd36a5776ff0628", "best_bid": "0.97", "best_ask": "0.991"}], "timestamp": "1769384466638", "event_type": "price_change"}}
{"_local_timestamp": "2026-01-25T23:41:06.751617+00:00", "data": {"market": "0xa04889441513194066b992c25607750d9ad9beda073baa231b7d6c0d296f3db4", "price_changes": [{"asset_id": "38098642543471813014855148341368026538917449780662028630830591144684505089593", "price": "0.005", "size": "306.32", "side": "BUY", "hash": "f26c10709c1a60e1a92832d9bec9f755ffd1c133", "best_bid": "0.015", "best_ask": "0.139"}, {"asset_id": "4927715355597512197888285947791839404212602020821540571091074384909522708343", "price": "0.995", "size": "306.32", "side": "SELL", "hash": "1bafa50d5db20aeade75470d16eb70cf217b29e1", "best_bid": "0.861", "best_ask": "0.985"}], "timestamp": "1769384466642", "event_type": "price_change"}}
{"_local_timestamp": "2026-01-25T23:41:06.753710+00:00", "data": {"market": "0xd3aa6ab9adcf1d7189a287e6a86dd2ae378fa7a635863f7d249ce70a1f28395e", "price_changes": [{"asset_id": "5525740420504230154399891807905567389393779493359335912984255288237335578501", "price": "0.002", "size": "300", "side": "BUY", "hash": "c1071d110a33b89d9114f21e9e3d6c00a12db691", "best_bid": "0.006", "best_ask": "0.032"}, {"asset_id": "17621949038627205799005149654166056280336330529029840823213885378726883921449", "price": "0.998", "size": "300", "side": "SELL", "hash": "9c1f187c3a46445258f4af5813dd68ed33ccace8", "best_bid": "0.968", "best_ask": "0.994"}], "timestamp": "1769384466644", "event_type": "price_change"}}
{"_local_timestamp": "2026-01-25T23:41:06.797368+00:00", "data": {"market": "0xadf6a02ac5b93901c17197de47e9c0afcc9449c6d85dec96448fa8cc90090490", "price_changes": [{"asset_id": "75870434740998190734966085726451060764959387741262916639210627595656112930617", "price": "0.002", "size": "300", "side": "BUY", "hash": "91c9df9dbd2377b32e4972a475ae8105349b3d25", "best_bid": "0.007", "best_ask": "0.029"}, {"asset_id": "107911337214497912248693530548658782366601738149965815249360222958641298955539", "price": "0.998", "size": "300", "side": "SELL", "hash": "765fdddce1630edfe1ffef52b091610d59c70577", "best_bid": "0.971", "best_ask": "0.993"}], "timestamp": "1769384466645", "event_type": "price_change"}}
{"_local_timestamp": "2026-01-25T23:41:06.838390+00:00", "data": {"market": "0x77e024fc3dac13c1404f30a42d8df3b32a62978c63f82b36f62df830604471a0", "price_changes": [{"asset_id": "87132914336773401193105961480278292749054879702172274912936083065312455895521", "price": "0.002", "size": "300", "side": "BUY", "hash": "bdea9487c04a9764a4b4995d2f2e7a20693d47e6", "best_bid": "0.006", "best_ask": "0.029"}, {"asset_id": "71885734107267615372441598160876793410818281961487005825293143068106970826321", "price": "0.998", "size": "300", "side": "SELL", "hash": "2816c6b83fb4d7090efa070984f8996d6ae7bcf1", "best_bid": "0.971", "best_ask": "0.994"}], "timestamp": "1769384466645", "event_type": "price_change"}}
{"_local_timestamp": "2026-01-25T23:41:06.839272+00:00", "data": {"market": "0x1fed6d1346b04331b1ba1188525e560094040cbf3bbd84700c2dddb5241b2402", "price_changes": [{"asset_id": "71341306129608304129076187431040953407253993378796751066411893382443918679197", "price": "0.002", "size": "450", "side": "BUY", "hash": "1f2e90322174abb7e5aced3bf04d77dd59a69301", "best_bid": "0.011", "best_ask": "0.089"}, {"asset_id": "38855512439706823591548373609888890731724800742290402025988926984750840280976", "price": "0.998", "size": "450", "side": "SELL", "hash": "7dafbc007e6504f983b0ecfcbf0c703288f1d22c", "best_bid": "0.911", "best_ask": "0.989"}], "timestamp": "1769384466641", "event_type": "price_change"}}
{"_local_timestamp": "2026-01-25T23:41:06.894382+00:00", "data": {"market": "0x5edebf3eb73ed300d47dd35e4c3938a6997cdbf3fa3b3ca086bdd7afa3e227cc", "price_changes": [{"asset_id": "47977478528993701917993634313399360833217034323739582269237365313563183735835", "price": "0.002", "size": "376.86", "side": "BUY", "hash": "1834d978a0aaa7d3a7ddbdc401da83be8d8503e6", "best_bid": "0.012", "best_ask": "0.129"}, {"asset_id": "48973293128569491311605281174826846182724783049607561423479481850292050544724", "price": "0.998", "size": "376.86", "side": "SELL", "hash": "e2cab824f10ee3fc221aaf0cbc94195eaf25c7e1", "best_bid": "0.871", "best_ask": "0.988"}], "timestamp": "1769384466657", "event_type": "price_change"}}
{"_local_timestamp": "2026-01-25T23:41:08.472190+00:00", "data": {"market": "0xbf6fbc35082962002b61f17e26820db124930ac43175934864e34a415ee40620", "price_changes": [{"asset_id": "42674776176570186449325309200969258771704155869979743437343764984621699243894", "price": "0.55", "size": "0", "side": "BUY", "hash": "b9f64c93ac5ac4901c55a873c7f26a195b8296f6", "best_bid": "0.5", "best_ask": "0.94"}, {"asset_id": "98673773007855046568692125013481059419674479536813359840428477180250006155633", "price": "0.45", "size": "0", "side": "SELL", "hash": "a1aa1cd7a8c1e41ee4d56d486b957dc9be4da03d", "best_bid": "0.06", "best_ask": "0.5"}], "timestamp": "1769384468403", "event_type": "price_change"}}
{"_local_timestamp": "2026-01-25T23:41:08.473571+00:00", "data": {"market": "0xc65ebe3378903b9f672868b4ad157b12f8d5b801303c224e2b9627c1de6e1bb4", "price_changes": [{"asset_id": "100153647768819913478482487007469803840833665951037785527037226522546628635049", "price": "0.23", "size": "0", "side": "BUY", "hash": "c3a36f09c693fdda9d324cbd88159213791e2758", "best_bid": "0.24", "best_ask": "0.95"}, {"asset_id": "68287553062600224636928508192555401721388367384589206235766778752053103462686", "price": "0.77", "size": "0", "side": "SELL", "hash": "8375ad2b213bf39f2ac764a7f21e0564ecea9657", "best_bid": "0.05", "best_ask": "0.76"}], "timestamp": "1769384468403", "event_type": "price_change"}}
{"_local_timestamp": "2026-01-25T23:41:08.474551+00:00", "data": {"market": "0x5edebf3eb73ed300d47dd35e4c3938a6997cdbf3fa3b3ca086bdd7afa3e227cc", "price_changes": [{"asset_id": "48973293128569491311605281174826846182724783049607561423479481850292050544724", "price": "0.161", "size": "0", "side": "BUY", "hash": "46dd096bc39769bd7a69bcc439b4e4489132f0e1", "best_bid": "0.871", "best_ask": "0.988"}, {"asset_id": "47977478528993701917993634313399360833217034323739582269237365313563183735835", "price": "0.839", "size": "0", "side": "SELL", "hash": "28f7fa07f431b4c1271d522ecfd9995bfc0bf971", "best_bid": "0.012", "best_ask": "0.129"}], "timestamp": "1769384468403", "event_type": "price_change"}}
{"_local_timestamp": "2026-01-25T23:41:08.477509+00:00", "data": {"market": "0x1fed6d1346b04331b1ba1188525e560094040cbf3bbd84700c2dddb5241b2402", "price_changes": [{"asset_id": "38855512439706823591548373609888890731724800742290402025988926984750840280976", "price": "0.557", "size": "0", "side": "BUY", "hash": "86875ca1cc9f3a1eb1f9a559bd06b4d80d42369c", "best_bid": "0.911", "best_ask": "0.989"}, {"asset_id": "71341306129608304129076187431040953407253993378796751066411893382443918679197", "price": "0.443", "size": "0", "side": "SELL", "hash": "228d8ac21b82f400940b6fd89db41273ffd9369f", "best_bid": "0.011", "best_ask": "0.089"}], "timestamp": "1769384468403", "event_type": "price_change"}}
{"_local_timestamp": "2026-01-25T23:41:08.479837+00:00", "data": {"market": "0x1fed6d1346b04331b1ba1188525e560094040cbf3bbd84700c2dddb5241b2402", "price_changes": [{"asset_id": "38855512439706823591548373609888890731724800742290402025988926984750840280976", "price": "0.202", "size": "25.78", "side": "BUY", "hash": "86875ca1cc9f3a1eb1f9a559bd06b4d80d42369c", "best_bid": "0.911", "best_ask": "0.989"}, {"asset_id": "71341306129608304129076187431040953407253993378796751066411893382443918679197", "price": "0.798", "size": "25.78", "side": "SELL", "hash": "228d8ac21b82f400940b6fd89db41273ffd9369f", "best_bid": "0.011", "best_ask": "0.089"}], "timestamp": "1769384468403", "event_type": "price_change"}}
{"_local_timestamp": "2026-01-25T23:41:08.480584+00:00", "data": {"market": "0x105658ed412868eff64622ff122b425042797cb1886ac13bba10627cb395b3a0", "price_changes": [{"asset_id": "62389192985532225428000072411944560217557819885493029090152096982024014976363", "price": "0.349", "size": "0", "side": "BUY", "hash": "913c98207ef5d86752b0d8286a50f1c329eeb078", "best_bid": "0.97", "best_ask": "0.991"}, {"asset_id": "42623828760560956825816893329368389610613334458449432332189049581423522261963", "price": "0.651", "size": "0", "side": "SELL", "hash": "a4516cefcc8cfd2aebb0b3b9ef1cd441747754fc", "best_bid": "0.009", "best_ask": "0.03"}], "timestamp": "1769384468403", "event_type": "price_change"}}
{"_local_timestamp": "2026-01-25T23:41:08.481925+00:00", "data": {"market": "0x1fed6d1346b04331b1ba1188525e560094040cbf3bbd84700c2dddb5241b2402", "price_changes": [{"asset_id": "71341306129608304129076187431040953407253993378796751066411893382443918679197", "price": "0.011", "size": "0", "side": "BUY", "hash": "0f57fbe78a8f9d11f65681e55961b7e2c2223c22", "best_bid": "0.009", "best_ask": "0.089"}, {"asset_id": "38855512439706823591548373609888890731724800742290402025988926984750840280976", "price": "0.989", "size": "0", "side": "SELL", "hash": "eccbd44c1c2b5ab17e6dc477e6e801bde73023fb", "best_bid": "0.911", "best_ask": "0.991"}], "timestamp": "1769384468404", "event_type": "price_change"}}
{"_local_timestamp": "2026-01-25T23:41:08.576920+00:00", "data": {"market": "0x1fed6d1346b04331b1ba1188525e560094040cbf3bbd84700c2dddb5241b2402", "price_changes": [{"asset_id": "38855512439706823591548373609888890731724800742290402025988926984750840280976", "price": "0.4", "size": "50", "side": "BUY", "hash": "be4ea5b4c97d14ffb01e8d802427ebb1a84de844", "best_bid": "0.911", "best_ask": "0.991"}, {"asset_id": "71341306129608304129076187431040953407253993378796751066411893382443918679197", "price": "0.6", "size": "50", "side": "SELL", "hash": "057ecf381558162e596c448c1d93d3756c541e67", "best_bid": "0.009", "best_ask": "0.089"}], "timestamp": "1769384468508", "event_type": "price_change"}}
{"_local_timestamp": "2026-01-25T23:41:08.637213+00:00", "data": {"market": "0x1fed6d1346b04331b1ba1188525e560094040cbf3bbd84700c2dddb5241b2402", "price_changes": [{"asset_id": "38855512439706823591548373609888890731724800742290402025988926984750840280976", "price": "0.35", "size": "68.57", "side": "BUY", "hash": "1c6f6e4b8d878ff05f39c4a1535a7b8d0deb5c2d", "best_bid": "0.911", "best_ask": "0.991"}, {"asset_id": "71341306129608304129076187431040953407253993378796751066411893382443918679197", "price": "0.65", "size": "68.57", "side": "SELL", "hash": "866336389dd88ffa54e79f6c841e2f0e1ef4d6bd", "best_bid": "0.009", "best_ask": "0.089"}], "timestamp": "1769384468565", "event_type": "price_change"}}
{"_local_timestamp": "2026-01-25T23:41:08.698865+00:00", "data": {"market": "0x1fed6d1346b04331b1ba1188525e560094040cbf3bbd84700c2dddb5241b2402", "price_changes": [{"asset_id": "38855512439706823591548373609888890731724800742290402025988926984750840280976", "price": "0.3", "size": "86.66", "side": "BUY", "hash": "6fe67b5f871cec05593cf5d78da2bc7a7d973497", "best_bid": "0.911", "best_ask": "0.991"}, {"asset_id": "71341306129608304129076187431040953407253993378796751066411893382443918679197", "price": "0.7", "size": "86.66", "side": "SELL", "hash": "99b64ccfb2b536ea316ef552c403a01b0de7360e", "best_bid": "0.009", "best_ask": "0.089"}], "timestamp": "1769384468634", "event_type": "price_change"}}
{"_local_timestamp": "2026-01-25T23:41:08.749997+00:00", "data": {"market": "0x1fed6d1346b04331b1ba1188525e560094040cbf3bbd84700c2dddb5241b2402", "price_changes": [{"asset_id": "38855512439706823591548373609888890731724800742290402025988926984750840280976", "price": "0.25", "size": "162", "side": "BUY", "hash": "adcdee2496678ea881551f254df5370e54179290", "best_bid": "0.911", "best_ask": "0.991"}, {"asset_id": "71341306129608304129076187431040953407253993378796751066411893382443918679197", "price": "0.75", "size": "162", "side": "SELL", "hash": "a885c92610b8b686d7326af4d50a7ee3a1cda0b8", "best_bid": "0.009", "best_ask": "0.089"}], "timestamp": "1769384468679", "event_type": "price_change"}}
{"_local_timestamp": "2026-01-25T23:41:08.792246+00:00", "data": {"market": "0x1fed6d1346b04331b1ba1188525e560094040cbf3bbd84700c2dddb5241b2402", "price_changes": [{"asset_id": "38855512439706823591548373609888890731724800742290402025988926984750840280976", "price": "0.2", "size": "260", "side": "BUY", "hash": "7853e9b1b7dda7fabadedd0c725489aed95bd2b5", "best_bid": "0.911", "best_ask": "0.991"}, {"asset_id": "71341306129608304129076187431040953407253993378796751066411893382443918679197", "price": "0.8", "size": "260", "side": "SELL", "hash": "d5f6fabe1bef4b4523c5260519f2e1d20d7d301d", "best_bid": "0.009", "best_ask": "0.089"}], "timestamp": "1769384468723", "event_type": "price_change"}}
{"_local_timestamp": "2026-01-25T23:41:08.837367+00:00", "data": {"market": "0x1fed6d1346b04331b1ba1188525e560094040cbf3bbd84700c2dddb5241b2402", "price_changes": [{"asset_id": "38855512439706823591548373609888890731724800742290402025988926984750840280976", "price": "0.15", "size": "351.66", "side": "BUY", "hash": "87a942c098291001f97ff3a432ff5ed26e295e3d", "best_bid": "0.911", "best_ask": "0.991"}, {"asset_id": "71341306129608304129076187431040953407253993378796751066411893382443918679197", "price": "0.85", "size": "351.66", "side": "SELL", "hash": "b1483fea32ad4add1226366f445087aa345027fe", "best_bid": "0.009", "best_ask": "0.089"}], "timestamp": "1769384468770", "event_type": "price_change"}}
{"_local_timestamp": "2026-01-25T23:41:08.880456+00:00", "data": {"market": "0x1fed6d1346b04331b1ba1188525e560094040cbf3bbd84700c2dddb5241b2402", "price_changes": [{"asset_id": "38855512439706823591548373609888890731724800742290402025988926984750840280976", "price": "0.1", "size": "360", "side": "BUY", "hash": "b682e00d3e4c957c0a734477a34ce4e1cf421aa7", "best_bid": "0.911", "best_ask": "0.991"}, {"asset_id": "71341306129608304129076187431040953407253993378796751066411893382443918679197", "price": "0.9", "size": "360", "side": "SELL", "hash": "1d99fe0a489db0c3b50ede4df9acd46de8e62893", "best_bid": "0.009", "best_ask": "0.089"}], "timestamp": "1769384468816", "event_type": "price_change"}}
{"_local_timestamp": "2026-01-25T23:41:09.208957+00:00", "data": {"market": "0x1fed6d1346b04331b1ba1188525e560094040cbf3bbd84700c2dddb5241b2402", "price_changes": [{"asset_id": "38855512439706823591548373609888890731724800742290402025988926984750840280976", "price": "0.561", "size": "100", "side": "BUY", "hash": "f7d3c31e6c10a98a7e6456f3c6dfeba254f9a5ef", "best_bid": "0.911", "best_ask": "0.991"}, {"asset_id": "71341306129608304129076187431040953407253993378796751066411893382443918679197", "price": "0.439", "size": "100", "side": "SELL", "hash": "7ce24c3d65c64c67cfcfb5562ce5eaee02a16855", "best_bid": "0.009", "best_ask": "0.089"}], "timestamp": "1769384469139", "event_type": "price_change"}}
{"_local_timestamp": "2026-01-25T23:41:09.233398+00:00", "data": {"market": "0x5edebf3eb73ed300d47dd35e4c3938a6997cdbf3fa3b3ca086bdd7afa3e227cc", "price_changes": [{"asset_id": "48973293128569491311605281174826846182724783049607561423479481850292050544724", "price": "0.491", "size": "100", "side": "BUY", "hash": "1949bbb51fa25dce53c8d7767f566df3ce3251d1", "best_bid": "0.871", "best_ask": "0.988"}, {"asset_id": "47977478528993701917993634313399360833217034323739582269237365313563183735835", "price": "0.509", "size": "100", "side": "SELL", "hash": "a2755ca79e4ea0b0a9b817c2503f478424ea252f", "best_bid": "0.012", "best_ask": "0.129"}], "timestamp": "1769384469159", "event_type": "price_change"}}
{"_local_timestamp": "2026-01-25T23:41:09.244070+00:00", "data": {"market": "0x5edebf3eb73ed300d47dd35e4c3938a6997cdbf3fa3b3ca086bdd7afa3e227cc", "price_changes": [{"asset_id": "48973293128569491311605281174826846182724783049607561423479481850292050544724", "price": "0.11", "size": "300", "side": "BUY", "hash": "037f4eead0777daf4777746713ff2b94024290af", "best_bid": "0.871", "best_ask": "0.988"}, {"asset_id": "47977478528993701917993634313399360833217034323739582269237365313563183735835", "price": "0.89", "size": "300", "side": "SELL", "hash": "68f4e2822b60d00f1b5a3f1a4488b027023ddad2", "best_bid": "0.012", "best_ask": "0.129"}], "timestamp": "1769384469180", "event_type": "price_change"}}
{"_local_timestamp": "2026-01-25T23:41:09.271901+00:00", "data": {"market": "0x105658ed412868eff64622ff122b425042797cb1886ac13bba10627cb395b3a0", "price_changes": [{"asset_id": "62389192985532225428000072411944560217557819885493029090152096982024014976363", "price": "0.42", "size": "350", "side": "BUY", "hash": "9a5f134c4b176c72e4d188e4409bce009795fe49", "best_bid": "0.97", "best_ask": "0.991"}, {"asset_id": "42623828760560956825816893329368389610613334458449432332189049581423522261963", "price": "0.58", "size": "350", "side": "SELL", "hash": "8033f059b3694dcaa180726db7440f0955dba299", "best_bid": "0.009", "best_ask": "0.03"}], "timestamp": "1769384469199", "event_type": "price_change"}}
{"_local_timestamp": "2026-01-25T23:41:09.311543+00:00", "data": {"market": "0xc65ebe3378903b9f672868b4ad157b12f8d5b801303c224e2b9627c1de6e1bb4", "price_changes": [{"asset_id": "100153647768819913478482487007469803840833665951037785527037226522546628635049", "price": "0.25", "size": "66.66", "side": "BUY", "hash": "fc9bfef5b8edd3a0b272dbaee2c1eea6cc56e562", "best_bid": "0.25", "best_ask": "0.95"}, {"asset_id": "68287553062600224636928508192555401721388367384589206235766778752053103462686", "price": "0.75", "size": "66.66", "side": "SELL", "hash": "2207816e9c3241486b5cca5bfd7b4655c53a4535", "best_bid": "0.05", "best_ask": "0.75"}], "timestamp": "1769384469242", "event_type": "price_change"}}
{"_local_timestamp": "2026-01-25T23:41:09.394875+00:00", "data": {"market": "0xbf6fbc35082962002b61f17e26820db124930ac43175934864e34a415ee40620", "price_changes": [{"asset_id": "42674776176570186449325309200969258771704155869979743437343764984621699243894", "price": "0.51", "size": "66.66", "side": "BUY", "hash": "b871493a1746c19a01f3927f11de8b494d3bedb8", "best_bid": "0.51", "best_ask": "0.94"}, {"asset_id": "98673773007855046568692125013481059419674479536813359840428477180250006155633", "price": "0.49", "size": "66.66", "side": "SELL", "hash": "af48b44d1cfb3b5e15cf2dd6cd241da5ba29119a", "best_bid": "0.06", "best_ask": "0.49"}], "timestamp": "1769384469326", "event_type": "price_change"}}
{"_local_timestamp": "2026-01-25T23:41:09.426424+00:00", "data": {"market": "0x1fed6d1346b04331b1ba1188525e560094040cbf3bbd84700c2dddb5241b2402", "price_changes": [{"asset_id": "71341306129608304129076187431040953407253993378796751066411893382443918679197", "price": "0.004", "size": "222.67", "side": "BUY", "hash": "1a6e5ad64b59c44b9d69ef5a72526053970e3607", "best_bid": "0.009", "best_ask": "0.089"}, {"asset_id": "38855512439706823591548373609888890731724800742290402025988926984750840280976", "price": "0.996", "size": "222.67", "side": "SELL", "hash": "51cbbd9f493c7047fd71a4caa88358ce6f660466", "best_bid": "0.911", "best_ask": "0.991"}], "timestamp": "1769384469361", "event_type": "price_change"}}
{"_local_timestamp": "2026-01-25T23:41:09.455404+00:00", "data": {"market": "0xc65ebe3378903b9f672868b4ad157b12f8d5b801303c224e2b9627c1de6e1bb4", "price_changes": [{"asset_id": "68287553062600224636928508192555401721388367384589206235766778752053103462686", "price": "0.76", "size": "0", "side": "SELL", "hash": "e1d19dd907c672f430a8ef1d54da934dfa5c9d79", "best_bid": "0.05", "best_ask": "0.75"}, {"asset_id": "100153647768819913478482487007469803840833665951037785527037226522546628635049", "price": "0.24", "size": "0", "side": "BUY", "hash": "20c9c3da4bcce35751e3964c127cd9938341e977", "best_bid": "0.25", "best_ask": "0.95"}], "timestamp": "1769384469392", "event_type": "price_change"}}
{"_local_timestamp": "2026-01-25T23:41:09.525395+00:00", "data": {"market": "0xc65ebe3378903b9f672868b4ad157b12f8d5b801303c224e2b9627c1de6e1bb4", "price_changes": [{"asset_id": "68287553062600224636928508192555401721388367384589206235766778752053103462686", "price": "0.83", "size": "36.04", "side": "SELL", "hash": "39cf523a5fc648648e952d8052ff1734eaae852b", "best_bid": "0.05", "best_ask": "0.75"}, {"asset_id": "100153647768819913478482487007469803840833665951037785527037226522546628635049", "price": "0.17", "size": "36.04", "side": "BUY", "hash": "c8714bbd252c79894e4ef9401f472fb9f405ce2a", "best_bid": "0.25", "best_ask": "0.95"}], "timestamp": "1769384469459", "event_type": "price_change"}}
{"_local_timestamp": "2026-01-25T23:41:09.577683+00:00", "data": {"market": "0x1fed6d1346b04331b1ba1188525e560094040cbf3bbd84700c2dddb5241b2402", "price_changes": [{"asset_id": "38855512439706823591548373609888890731724800742290402025988926984750840280976", "price": "0.21", "size": "200", "side": "BUY", "hash": "81c616cad0d5413cc44d7b71e7c9d0fbd8dc942c", "best_bid": "0.911", "best_ask": "0.991"}, {"asset_id": "71341306129608304129076187431040953407253993378796751066411893382443918679197", "price": "0.79", "size": "200", "side": "SELL", "hash": "3f1804b82df8d81b83b42475e0f5c317ba5c2467", "best_bid": "0.009", "best_ask": "0.089"}], "timestamp": "1769384469508", "event_type": "price_change"}}
{"_local_timestamp": "2026-01-25T23:41:10.716919+00:00", "data": {"market": "0x1fed6d1346b04331b1ba1188525e560094040cbf3bbd84700c2dddb5241b2402", "price_changes": [{"asset_id": "38855512439706823591548373609888890731724800742290402025988926984750840280976", "price": "0.202", "size": "5.78", "side": "BUY", "hash": "a27a37b3581f7b3070b579401a6bcf1e419a6a9c", "best_bid": "0.911", "best_ask": "0.991"}, {"asset_id": "71341306129608304129076187431040953407253993378796751066411893382443918679197", "price": "0.798", "size": "5.78", "side": "SELL", "hash": "e0ec273ff3ee3091812b5b85817a3a596b6f07df", "best_bid": "0.009", "best_ask": "0.089"}], "timestamp": "1769384470647", "event_type": "price_change"}}
{"_local_timestamp": "2026-01-25T23:41:10.718469+00:00", "data": {"market": "0x5edebf3eb73ed300d47dd35e4c3938a6997cdbf3fa3b3ca086bdd7afa3e227cc", "price_changes": [{"asset_id": "48973293128569491311605281174826846182724783049607561423479481850292050544724", "price": "0.162", "size": "0", "side": "BUY", "hash": "4d59dd6e7f635e481c527e3254dcfbd88b06893f", "best_bid": "0.871", "best_ask": "0.988"}, {"asset_id": "47977478528993701917993634313399360833217034323739582269237365313563183735835", "price": "0.838", "size": "0", "side": "SELL", "hash": "d51155577de77c52f491cc1d6271b3e8a5dd6ea6", "best_bid": "0.012", "best_ask": "0.129"}], "timestamp": "1769384470647", "event_type": "price_change"}}
{"_local_timestamp": "2026-01-25T23:41:10.745629+00:00", "data": {"market": "0x5edebf3eb73ed300d47dd35e4c3938a6997cdbf3fa3b3ca086bdd7afa3e227cc", "price_changes": [{"asset_id": "48973293128569491311605281174826846182724783049607561423479481850292050544724", "price": "0.161", "size": "20", "side": "BUY", "hash": "4f0a2c430f02157876148a509b5f7b7db6f82f0d", "best_bid": "0.871", "best_ask": "0.988"}, {"asset_id": "47977478528993701917993634313399360833217034323739582269237365313563183735835", "price": "0.839", "size": "20", "side": "SELL", "hash": "250c173cbce1281736ac6647e140f05275b7ee25", "best_bid": "0.012", "best_ask": "0.129"}], "timestamp": "1769384470677", "event_type": "price_change"}}
{"_local_timestamp": "2026-01-25T23:41:10.746520+00:00", "data": {"market": "0x1fed6d1346b04331b1ba1188525e560094040cbf3bbd84700c2dddb5241b2402", "price_changes": [{"asset_id": "38855512439706823591548373609888890731724800742290402025988926984750840280976", "price": "0.201", "size": "20", "side": "BUY", "hash": "b420da389d847c8a3d2bd00326dd681edb30e408", "best_bid": "0.911", "best_ask": "0.991"}, {"asset_id": "71341306129608304129076187431040953407253993378796751066411893382443918679197", "price": "0.799", "size": "20", "side": "SELL", "hash": "64e795fba5e9710428ce05286dea9bfe12b271a2", "best_bid": "0.009", "best_ask": "0.089"}], "timestamp": "1769384470677", "event_type": "price_change"}}
{"_local_timestamp": "2026-01-25T23:41:10.963668+00:00", "data": {"market": "0xc65ebe3378903b9f672868b4ad157b12f8d5b801303c224e2b9627c1de6e1bb4", "price_changes": [{"asset_id": "68287553062600224636928508192555401721388367384589206235766778752053103462686", "price": "0.83", "size": "6.7", "side": "SELL", "hash": "f041d77434b297a03b13157f3b4c68cbc1ae01ec", "best_bid": "0.05", "best_ask": "0.75"}, {"asset_id": "100153647768819913478482487007469803840833665951037785527037226522546628635049", "price": "0.17", "size": "6.7", "side": "BUY", "hash": "c5ea5f6e24e0f4e619eb7b8129c79354504f0fe5", "best_bid": "0.25", "best_ask": "0.95"}], "timestamp": "1769384470892", "event_type": "price_change"}}
{"_local_timestamp": "2026-01-25T23:41:11.025212+00:00", "data": {"market": "0xc65ebe3378903b9f672868b4ad157b12f8d5b801303c224e2b9627c1de6e1bb4", "price_changes": [{"asset_id": "68287553062600224636928508192555401721388367384589206235766778752053103462686", "price": "0.74", "size": "29.34", "side": "SELL", "hash": "7402928e5c485a06bd1b46c530b78225cfcc7113", "best_bid": "0.05", "best_ask": "0.74"}, {"asset_id": "100153647768819913478482487007469803840833665951037785527037226522546628635049", "price": "0.26", "size": "29.34", "side": "BUY", "hash": "08ac862873f8cfc58b02597d9bc78a21e5fc0a81", "best_bid": "0.26", "best_ask": "0.95"}], "timestamp": "1769384470947", "event_type": "price_change"}}
{"_local_timestamp": "2026-01-25T23:41:50.878317+00:00", "data": {"market": "0x5edebf3eb73ed300d47dd35e4c3938a6997cdbf3fa3b3ca086bdd7afa3e227cc", "price_changes": [{"asset_id": "48973293128569491311605281174826846182724783049607561423479481850292050544724", "price": "0.11", "size": "100", "side": "BUY", "hash": "717262fc1b80ebd9a600810b98769dd620c27745", "best_bid": "0.871", "best_ask": "0.988"}, {"asset_id": "47977478528993701917993634313399360833217034323739582269237365313563183735835", "price": "0.89", "size": "100", "side": "SELL", "hash": "13f21aededdca2211759f3014b1472d25926a5b1", "best_bid": "0.012", "best_ask": "0.129"}], "timestamp": "1769384510744", "event_type": "price_change"}}
{"_local_timestamp": "2026-01-25T23:41:50.883568+00:00", "data": {"market": "0x5edebf3eb73ed300d47dd35e4c3938a6997cdbf3fa3b3ca086bdd7afa3e227cc", "price_changes": [{"asset_id": "48973293128569491311605281174826846182724783049607561423479481850292050544724", "price": "0.04", "size": "1000", "side": "BUY", "hash": "717262fc1b80ebd9a600810b98769dd620c27745", "best_bid": "0.871", "best_ask": "0.988"}, {"asset_id": "47977478528993701917993634313399360833217034323739582269237365313563183735835", "price": "0.96", "size": "1000", "side": "SELL", "hash": "13f21aededdca2211759f3014b1472d25926a5b1", "best_bid": "0.012", "best_ask": "0.129"}], "timestamp": "1769384510744", "event_type": "price_change"}}
{"_local_timestamp": "2026-01-25T23:41:50.884502+00:00", "data": {"market": "0x5edebf3eb73ed300d47dd35e4c3938a6997cdbf3fa3b3ca086bdd7afa3e227cc", "price_changes": [{"asset_id": "48973293128569491311605281174826846182724783049607561423479481850292050544724", "price": "0.21", "size": "0", "side": "BUY", "hash": "717262fc1b80ebd9a600810b98769dd620c27745", "best_bid": "0.871", "best_ask": "0.988"}, {"asset_id": "47977478528993701917993634313399360833217034323739582269237365313563183735835", "price": "0.79", "size": "0", "side": "SELL", "hash": "13f21aededdca2211759f3014b1472d25926a5b1", "best_bid": "0.012", "best_ask": "0.129"}], "timestamp": "1769384510744", "event_type": "price_change"}}
{"_local_timestamp": "2026-01-25T23:41:50.886127+00:00", "data": {"market": "0x5edebf3eb73ed300d47dd35e4c3938a6997cdbf3fa3b3ca086bdd7afa3e227cc", "price_changes": [{"asset_id": "48973293128569491311605281174826846182724783049607561423479481850292050544724", "price": "0.16", "size": "0", "side": "BUY", "hash": "717262fc1b80ebd9a600810b98769dd620c27745", "best_bid": "0.871", "best_ask": "0.988"}, {"asset_id": "47977478528993701917993634313399360833217034323739582269237365313563183735835", "price": "0.84", "size": "0", "side": "SELL", "hash": "13f21aededdca2211759f3014b1472d25926a5b1", "best_bid": "0.012", "best_ask": "0.129"}], "timestamp": "1769384510744", "event_type": "price_change"}}
{"_local_timestamp": "2026-01-25T23:41:50.887165+00:00", "data": {"market": "0xa04889441513194066b992c25607750d9ad9beda073baa231b7d6c0d296f3db4", "price_changes": [{"asset_id": "4927715355597512197888285947791839404212602020821540571091074384909522708343", "price": "0.21", "size": "0", "side": "BUY", "hash": "b8b9c441c04b52173fd300cc403a8f327e93ff01", "best_bid": "0.861", "best_ask": "0.985"}, {"asset_id": "38098642543471813014855148341368026538917449780662028630830591144684505089593", "price": "0.79", "size": "0", "side": "SELL", "hash": "e96934c12453a4251b56a01147067d5ac83bc19b", "best_bid": "0.015", "best_ask": "0.139"}], "timestamp": "1769384510744", "event_type": "price_change"}}
{"_local_timestamp": "2026-01-25T23:41:50.889406+00:00", "data": {"market": "0xa04889441513194066b992c25607750d9ad9beda073baa231b7d6c0d296f3db4", "price_changes": [{"asset_id": "4927715355597512197888285947791839404212602020821540571091074384909522708343", "price": "0.16", "size": "100", "side": "BUY", "hash": "0eb8258ba71b4f5be056fe5d5985c6865102b88d", "best_bid": "0.861", "best_ask": "0.985"}, {"asset_id": "38098642543471813014855148341368026538917449780662028630830591144684505089593", "price": "0.84", "size": "100", "side": "SELL", "hash": "6f16e3ce36caff7c0948496265653a333725f213", "best_bid": "0.015", "best_ask": "0.139"}], "timestamp": "1769384510748", "event_type": "price_change"}}
{"_local_timestamp": "2026-01-25T23:41:50.924250+00:00", "data": {"market": "0xadf6a02ac5b93901c17197de47e9c0afcc9449c6d85dec96448fa8cc90090490", "price_changes": [{"asset_id": "107911337214497912248693530548658782366601738149965815249360222958641298955539", "price": "0.25", "size": "112", "side": "BUY", "hash": "4d7bba7e8b377db4b0ee50391bedf6dc1fabd4b3", "best_bid": "0.971", "best_ask": "0.993"}, {"asset_id": "75870434740998190734966085726451060764959387741262916639210627595656112930617", "price": "0.75", "size": "112", "side": "SELL", "hash": "f86d961b67d764224768364078a5f06fcbc00d95", "best_bid": "0.007", "best_ask": "0.029"}], "timestamp": "1769384510749", "event_type": "price_change"}}
{"_local_timestamp": "2026-01-25T23:41:50.926894+00:00", "data": {"market": "0xadf6a02ac5b93901c17197de47e9c0afcc9449c6d85dec96448fa8cc90090490", "price_changes": [{"asset_id": "107911337214497912248693530548658782366601738149965815249360222958641298955539", "price": "0.421", "size": "0", "side": "BUY", "hash": "4d7bba7e8b377db4b0ee50391bedf6dc1fabd4b3", "best_bid": "0.971", "best_ask": "0.993"}, {"asset_id": "75870434740998190734966085726451060764959387741262916639210627595656112930617", "price": "0.579", "size": "0", "side": "SELL", "hash": "f86d961b67d764224768364078a5f06fcbc00d95", "best_bid": "0.007", "best_ask": "0.029"}], "timestamp": "1769384510749", "event_type": "price_change"}}
{"_local_timestamp": "2026-01-25T23:41:50.927733+00:00", "data": {"market": "0x1fed6d1346b04331b1ba1188525e560094040cbf3bbd84700c2dddb5241b2402", "price_changes": [{"asset_id": "38855512439706823591548373609888890731724800742290402025988926984750840280976", "price": "0.421", "size": "0", "side": "BUY", "hash": "1bd55e36b1ee39371ba4b7e9e1263edb8ae4dfe3", "best_bid": "0.911", "best_ask": "0.991"}, {"asset_id": "71341306129608304129076187431040953407253993378796751066411893382443918679197", "price": "0.579", "size": "0", "side": "SELL", "hash": "ee12a62fcbdc6d0ed9883cadb2eafb7a928b203d", "best_bid": "0.009", "best_ask": "0.089"}], "timestamp": "1769384510749", "event_type": "price_change"}}
{"_local_timestamp": "2026-01-25T23:41:50.928529+00:00", "data": {"market": "0x1fed6d1346b04331b1ba1188525e560094040cbf3bbd84700c2dddb5241b2402", "price_changes": [{"asset_id": "38855512439706823591548373609888890731724800742290402025988926984750840280976", "price": "0.17", "size": "0", "side": "BUY", "hash": "1bd55e36b1ee39371ba4b7e9e1263edb8ae4dfe3", "best_bid": "0.911", "best_ask": "0.991"}, {"asset_id": "71341306129608304129076187431040953407253993378796751066411893382443918679197", "price": "0.83", "size": "0", "side": "SELL", "hash": "ee12a62fcbdc6d0ed9883cadb2eafb7a928b203d", "best_bid": "0.009", "best_ask": "0.089"}], "timestamp": "1769384510749", "event_type": "price_change"}}
{"_local_timestamp": "2026-01-25T23:41:50.929319+00:00", "data": {"market": "0x1fed6d1346b04331b1ba1188525e560094040cbf3bbd84700c2dddb5241b2402", "price_changes": [{"asset_id": "38855512439706823591548373609888890731724800742290402025988926984750840280976", "price": "0.13", "size": "0", "side": "BUY", "hash": "1bd55e36b1ee39371ba4b7e9e1263edb8ae4dfe3", "best_bid": "0.911", "best_ask": "0.991"}, {"asset_id": "71341306129608304129076187431040953407253993378796751066411893382443918679197", "price": "0.87", "size": "0", "side": "SELL", "hash": "ee12a62fcbdc6d0ed9883cadb2eafb7a928b203d", "best_bid": "0.009", "best_ask": "0.089"}], "timestamp": "1769384510749", "event_type": "price_change"}}
{"_local_timestamp": "2026-01-25T23:41:50.930404+00:00", "data": {"market": "0x1fed6d1346b04331b1ba1188525e560094040cbf3bbd84700c2dddb5241b2402", "price_changes": [{"asset_id": "38855512439706823591548373609888890731724800742290402025988926984750840280976", "price": "0.21", "size": "100", "side": "BUY", "hash": "1bd55e36b1ee39371ba4b7e9e1263edb8ae4dfe3", "best_bid": "0.911", "best_ask": "0.991"}, {"asset_id": "71341306129608304129076187431040953407253993378796751066411893382443918679197", "price": "0.79", "size": "100", "side": "SELL", "hash": "ee12a62fcbdc6d0ed9883cadb2eafb7a928b203d", "best_bid": "0.009", "best_ask": "0.089"}], "timestamp": "1769384510749", "event_type": "price_change"}}
{"_local_timestamp": "2026-01-25T23:41:52.726601+00:00", "data": {"market": "0xadf6a02ac5b93901c17197de47e9c0afcc9449c6d85dec96448fa8cc90090490", "price_changes": [{"asset_id": "107911337214497912248693530548658782366601738149965815249360222958641298955539", "price": "0.3", "size": "336.66", "side": "BUY", "hash": "d8fbaaa2892c861b208e653ff9c07249e4d6ad94", "best_bid": "0.971", "best_ask": "0.993"}, {"asset_id": "75870434740998190734966085726451060764959387741262916639210627595656112930617", "price": "0.7", "size": "336.66", "side": "SELL", "hash": "2dd36745a3dfb8960e643c1a69d9439c4ffaff1c", "best_bid": "0.007", "best_ask": "0.029"}], "timestamp": "1769384511764", "event_type": "price_change"}}
{"_local_timestamp": "2026-01-25T23:41:52.733958+00:00", "data": {"market": "0xadf6a02ac5b93901c17197de47e9c0afcc9449c6d85dec96448fa8cc90090490", "price_changes": [{"asset_id": "107911337214497912248693530548658782366601738149965815249360222958641298955539", "price": "0.424", "size": "125", "side": "BUY", "hash": "21bf5ff85fc1dd0715fb909ea40884e50adb3f8d", "best_bid": "0.971", "best_ask": "0.993"}, {"asset_id": "75870434740998190734966085726451060764959387741262916639210627595656112930617", "price": "0.576", "size": "125", "side": "SELL", "hash": "1c4510f442f226b35413c1d99d5191701578a340", "best_bid": "0.007", "best_ask": "0.029"}], "timestamp": "1769384512642", "event_type": "price_change"}}
{"_local_timestamp": "2026-01-25T23:41:52.790499+00:00", "data": {"market": "0x77e024fc3dac13c1404f30a42d8df3b32a62978c63f82b36f62df830604471a0", "price_changes": [{"asset_id": "71885734107267615372441598160876793410818281961487005825293143068106970826321", "price": "0.3", "size": "336.66", "side": "BUY", "hash": "63e263ae54537bd8b39969dca910e5b4ddfd0fd6", "best_bid": "0.971", "best_ask": "0.994"}, {"asset_id": "87132914336773401193105961480278292749054879702172274912936083065312455895521", "price": "0.7", "size": "336.66", "side": "SELL", "hash": "5741730be0f0a3fb69aead04796bca562bf80fa4", "best_bid": "0.006", "best_ask": "0.029"}], "timestamp": "1769384511799", "event_type": "price_change"}}
{"_local_timestamp": "2026-01-25T23:41:52.870981+00:00", "data": {"market": "0x1fed6d1346b04331b1ba1188525e560094040cbf3bbd84700c2dddb5241b2402", "price_changes": [{"asset_id": "38855512439706823591548373609888890731724800742290402025988926984750840280976", "price": "0.2", "size": "410", "side": "BUY", "hash": "59d15575ba30e81b27c0575a5c9c067eded0f730", "best_bid": "0.911", "best_ask": "0.991"}, {"asset_id": "71341306129608304129076187431040953407253993378796751066411893382443918679197", "price": "0.8", "size": "410", "side": "SELL", "hash": "4011d786a4ffe77641ff23b30537a6a496698bda", "best_bid": "0.009", "best_ask": "0.089"}], "timestamp": "1769384511816", "event_type": "price_change"}}
{"_local_timestamp": "2026-01-25T23:41:52.984628+00:00", "data": {"market": "0x77e024fc3dac13c1404f30a42d8df3b32a62978c63f82b36f62df830604471a0", "price_changes": [{"asset_id": "71885734107267615372441598160876793410818281961487005825293143068106970826321", "price": "0.2", "size": "410", "side": "BUY", "hash": "6d81c1beae79a5ab65a1c1fe22e9dc81eef0b508", "best_bid": "0.971", "best_ask": "0.994"}, {"asset_id": "87132914336773401193105961480278292749054879702172274912936083065312455895521", "price": "0.8", "size": "410", "side": "SELL", "hash": "d679a63f65e0af32a112307ee88ea5667f171422", "best_bid": "0.006", "best_ask": "0.029"}], "timestamp": "1769384512657", "event_type": "price_change"}}
{"_local_timestamp": "2026-01-25T23:41:53.000195+00:00", "data": {"market": "0x1fed6d1346b04331b1ba1188525e560094040cbf3bbd84700c2dddb5241b2402", "price_changes": [{"asset_id": "38855512439706823591548373609888890731724800742290402025988926984750840280976", "price": "0.15", "size": "551.66", "side": "BUY", "hash": "6f9b007026fc872bfbcb9dc4a17f90ebe465cae3", "best_bid": "0.911", "best_ask": "0.991"}, {"asset_id": "71341306129608304129076187431040953407253993378796751066411893382443918679197", "price": "0.85", "size": "551.66", "side": "SELL", "hash": "2973d38135ad13c1e02092382120b472b4acfd49", "best_bid": "0.009", "best_ask": "0.089"}], "timestamp": "1769384512669", "event_type": "price_change"}}
{"_local_timestamp": "2026-01-25T23:41:53.038464+00:00", "data": {"market": "0x1fed6d1346b04331b1ba1188525e560094040cbf3bbd84700c2dddb5241b2402", "price_changes": [{"asset_id": "38855512439706823591548373609888890731724800742290402025988926984750840280976", "price": "0.25", "size": "262", "side": "BUY", "hash": "d0545136f9fa62d7b43d5bd0cd53865bb20e8f99", "best_bid": "0.911", "best_ask": "0.991"}, {"asset_id": "71341306129608304129076187431040953407253993378796751066411893382443918679197", "price": "0.75", "size": "262", "side": "SELL", "hash": "3de42c081121e2e12a7f73a23f8bbab533b36271", "best_bid": "0.009", "best_ask": "0.089"}], "timestamp": "1769384512690", "event_type": "price_change"}}
{"_local_timestamp": "2026-01-25T23:41:55.382932+00:00", "data": {"market": "0x5edebf3eb73ed300d47dd35e4c3938a6997cdbf3fa3b3ca086bdd7afa3e227cc", "price_changes": [{"asset_id": "48973293128569491311605281174826846182724783049607561423479481850292050544724", "price": "0.161", "size": "0", "side": "BUY", "hash": "190916512f2fd63311a6b0ef655eb3072c249cae", "best_bid": "0.871", "best_ask": "0.988"}, {"asset_id": "47977478528993701917993634313399360833217034323739582269237365313563183735835", "price": "0.839", "size": "0", "side": "SELL", "hash": "a33fc319eb96afd203c5395ffc048270dce181d9", "best_bid": "0.012", "best_ask": "0.129"}], "timestamp": "1769384515309", "event_type": "price_change"}}
{"_local_timestamp": "2026-01-25T23:41:55.403512+00:00", "data": {"market": "0x5edebf3eb73ed300d47dd35e4c3938a6997cdbf3fa3b3ca086bdd7afa3e227cc", "price_changes": [{"asset_id": "48973293128569491311605281174826846182724783049607561423479481850292050544724", "price": "0.111", "size": "20", "side": "BUY", "hash": "2674947126516a73b2e2264792d7a63904bb7044", "best_bid": "0.871", "best_ask": "0.988"}, {"asset_id": "47977478528993701917993634313399360833217034323739582269237365313563183735835", "price": "0.889", "size": "20", "side": "SELL", "hash": "63b2048fd7f799946db84036e99dfe19d163ec49", "best_bid": "0.012", "best_ask": "0.129"}], "timestamp": "1769384515337", "event_type": "price_change"}}
{"_local_timestamp": "2026-01-25T23:42:24.750266+00:00", "data": {"market": "0x1fed6d1346b04331b1ba1188525e560094040cbf3bbd84700c2dddb5241b2402", "price_changes": [{"asset_id": "38855512439706823591548373609888890731724800742290402025988926984750840280976", "price": "0.25", "size": "212", "side": "BUY", "hash": "488195e8134dfc7d6179de52594a6b9dc8fd5be5", "best_bid": "0.911", "best_ask": "0.991"}, {"asset_id": "71341306129608304129076187431040953407253993378796751066411893382443918679197", "price": "0.75", "size": "212", "side": "SELL", "hash": "c066f08ba4905f4c2f95c053b2451d7f2b0c241f", "best_bid": "0.009", "best_ask": "0.089"}], "timestamp": "1769384544488", "event_type": "price_change"}}
{"_local_timestamp": "2026-01-25T23:42:24.754341+00:00", "data": {"market": "0x1fed6d1346b04331b1ba1188525e560094040cbf3bbd84700c2dddb5241b2402", "price_changes": [{"asset_id": "38855512439706823591548373609888890731724800742290402025988926984750840280976", "price": "0.2", "size": "310", "side": "BUY", "hash": "488195e8134dfc7d6179de52594a6b9dc8fd5be5", "best_bid": "0.911", "best_ask": "0.991"}, {"asset_id": "71341306129608304129076187431040953407253993378796751066411893382443918679197", "price": "0.8", "size": "310", "side": "SELL", "hash": "c066f08ba4905f4c2f95c053b2451d7f2b0c241f", "best_bid": "0.009", "best_ask": "0.089"}], "timestamp": "1769384544488", "event_type": "price_change"}}
{"_local_timestamp": "2026-01-25T23:42:24.755910+00:00", "data": {"market": "0x1fed6d1346b04331b1ba1188525e560094040cbf3bbd84700c2dddb5241b2402", "price_changes": [{"asset_id": "38855512439706823591548373609888890731724800742290402025988926984750840280976", "price": "0.15", "size": "426.66", "side": "BUY", "hash": "488195e8134dfc7d6179de52594a6b9dc8fd5be5", "best_bid": "0.911", "best_ask": "0.991"}, {"asset_id": "71341306129608304129076187431040953407253993378796751066411893382443918679197", "price": "0.85", "size": "426.66", "side": "SELL", "hash": "c066f08ba4905f4c2f95c053b2451d7f2b0c241f", "best_bid": "0.009", "best_ask": "0.089"}], "timestamp": "1769384544488", "event_type": "price_change"}}
{"_local_timestamp": "2026-01-25T23:42:25.149011+00:00", "data": {"market": "0x1fed6d1346b04331b1ba1188525e560094040cbf3bbd84700c2dddb5241b2402", "price_changes": [{"asset_id": "38855512439706823591548373609888890731724800742290402025988926984750840280976", "price": "0.21", "size": "150", "side": "BUY", "hash": "4da09da96008351b50ba38cc3bd788c377c0e3c6", "best_bid": "0.911", "best_ask": "0.991"}, {"asset_id": "71341306129608304129076187431040953407253993378796751066411893382443918679197", "price": "0.79", "size": "150", "side": "SELL", "hash": "9a42c90a559197aeceeb811443452fd6246a3aa3", "best_bid": "0.009", "best_ask": "0.089"}], "timestamp": "1769384544935", "event_type": "price_change"}}
{"_local_timestamp": "2026-01-25T23:42:25.156412+00:00", "data": {"market": "0x5edebf3eb73ed300d47dd35e4c3938a6997cdbf3fa3b3ca086bdd7afa3e227cc", "price_changes": [{"asset_id": "48973293128569491311605281174826846182724783049607561423479481850292050544724", "price": "0.11", "size": "225", "side": "BUY", "hash": "ad9a7f46627181103bba10c3c05c57f57b8e7709", "best_bid": "0.871", "best_ask": "0.988"}, {"asset_id": "47977478528993701917993634313399360833217034323739582269237365313563183735835", "price": "0.89", "size": "225", "side": "SELL", "hash": "0d37d71ade47d0908e3c9235a67087665d3df639", "best_bid": "0.012", "best_ask": "0.129"}], "timestamp": "1769384544936", "event_type": "price_change"}}
{"_local_timestamp": "2026-01-25T23:42:25.164962+00:00", "data": {"market": "0xa04889441513194066b992c25607750d9ad9beda073baa231b7d6c0d296f3db4", "price_changes": [{"asset_id": "4927715355597512197888285947791839404212602020821540571091074384909522708343", "price": "0.21", "size": "50", "side": "BUY", "hash": "161f3fab6e8d1354a0303d5256c904c40941248e", "best_bid": "0.861", "best_ask": "0.985"}, {"asset_id": "38098642543471813014855148341368026538917449780662028630830591144684505089593", "price": "0.79", "size": "50", "side": "SELL", "hash": "e7c705a5ae352be4e15faed3854eeebbbb5e2408", "best_bid": "0.015", "best_ask": "0.139"}], "timestamp": "1769384544938", "event_type": "price_change"}}
{"_local_timestamp": "2026-01-25T23:42:25.174380+00:00", "data": {"market": "0x1fed6d1346b04331b1ba1188525e560094040cbf3bbd84700c2dddb5241b2402", "price_changes": [{"asset_id": "38855512439706823591548373609888890731724800742290402025988926984750840280976", "price": "0.17", "size": "100", "side": "BUY", "hash": "0d53af5d02bd5edabe7184f46b9c42d42b26de58", "best_bid": "0.911", "best_ask": "0.991"}, {"asset_id": "71341306129608304129076187431040953407253993378796751066411893382443918679197", "price": "0.83", "size": "100", "side": "SELL", "hash": "cb00a6706736822a60640b06d195c59b18a09bee", "best_bid": "0.009", "best_ask": "0.089"}], "timestamp": "1769384544957", "event_type": "price_change"}}
{"_local_timestamp": "2026-01-25T23:42:25.181277+00:00", "data": {"market": "0x1fed6d1346b04331b1ba1188525e560094040cbf3bbd84700c2dddb5241b2402", "price_changes": [{"asset_id": "38855512439706823591548373609888890731724800742290402025988926984750840280976", "price": "0.13", "size": "125", "side": "BUY", "hash": "962e13fec381a11f05ffcd32dbdca0238bd79229", "best_bid": "0.911", "best_ask": "0.991"}, {"asset_id": "71341306129608304129076187431040953407253993378796751066411893382443918679197", "price": "0.87", "size": "125", "side": "SELL", "hash": "ab7ad832d82ce977b315e32e07228114e7a8a3d1", "best_bid": "0.009", "best_ask": "0.089"}], "timestamp": "1769384544963", "event_type": "price_change"}}
{"_local_timestamp": "2026-01-25T23:42:39.822664+00:00", "data": {"market": "0x1fed6d1346b04331b1ba1188525e560094040cbf3bbd84700c2dddb5241b2402", "price_changes": [{"asset_id": "38855512439706823591548373609888890731724800742290402025988926984750840280976", "price": "0.06", "size": "250", "side": "BUY", "hash": "f20cd704080217e4ca795f82e7271472f37d7004", "best_bid": "0.911", "best_ask": "0.991"}, {"asset_id": "71341306129608304129076187431040953407253993378796751066411893382443918679197", "price": "0.94", "size": "250", "side": "SELL", "hash": "da4465a8bf58b9ebbf3b2c27b92e465cb07ad516", "best_bid": "0.009", "best_ask": "0.089"}], "timestamp": "1769384559618", "event_type": "price_change"}}
{"_local_timestamp": "2026-01-25T23:42:40.114204+00:00", "data": {"market": "0x1fed6d1346b04331b1ba1188525e560094040cbf3bbd84700c2dddb5241b2402", "price_changes": [{"asset_id": "38855512439706823591548373609888890731724800742290402025988926984750840280976", "price": "0.1", "size": "560", "side": "BUY", "hash": "3a564745751a9194bf32af32bb9fdd57820a91c8", "best_bid": "0.911", "best_ask": "0.991"}, {"asset_id": "71341306129608304129076187431040953407253993378796751066411893382443918679197", "price": "0.9", "size": "560", "side": "SELL", "hash": "a17c50f2bf39e69626121804edefaedf6424e3c4", "best_bid": "0.009", "best_ask": "0.089"}], "timestamp": "1769384559909", "event_type": "price_change"}}
{"_local_timestamp": "2026-01-25T23:42:40.178953+00:00", "data": {"market": "0x5edebf3eb73ed300d47dd35e4c3938a6997cdbf3fa3b3ca086bdd7afa3e227cc", "price_changes": [{"asset_id": "48973293128569491311605281174826846182724783049607561423479481850292050544724", "price": "0.06", "size": "450", "side": "BUY", "hash": "2d914b0f229b7f233e0c5b739271ea27cfdd6a24", "best_bid": "0.871", "best_ask": "0.988"}, {"asset_id": "47977478528993701917993634313399360833217034323739582269237365313563183735835", "price": "0.94", "size": "450", "side": "SELL", "hash": "7c14a88c102d9bb40245d4f67554327f1fcd127f", "best_bid": "0.012", "best_ask": "0.129"}], "timestamp": "1769384559935", "event_type": "price_change"}}
{"_local_timestamp": "2026-01-25T23:42:40.219443+00:00", "data": {"market": "0x5edebf3eb73ed300d47dd35e4c3938a6997cdbf3fa3b3ca086bdd7afa3e227cc", "price_changes": [{"asset_id": "48973293128569491311605281174826846182724783049607561423479481850292050544724", "price": "0.01", "size": "4350", "side": "BUY", "hash": "aa103c90f4d666304bdfc0f5665ef49aa61ee820", "best_bid": "0.871", "best_ask": "0.988"}, {"asset_id": "47977478528993701917993634313399360833217034323739582269237365313563183735835", "price": "0.99", "size": "4350", "side": "SELL", "hash": "45e12107246633583247a94e4327503c31f8eb52", "best_bid": "0.012", "best_ask": "0.129"}], "timestamp": "1769384559985", "event_type": "price_change"}}
{"_local_timestamp": "2026-01-25T23:42:40.259903+00:00", "data": {"market": "0x5edebf3eb73ed300d47dd35e4c3938a6997cdbf3fa3b3ca086bdd7afa3e227cc", "price_changes": [{"asset_id": "48973293128569491311605281174826846182724783049607561423479481850292050544724", "price": "0.04", "size": "1400", "side": "BUY", "hash": "e6bdc965e49586966904627c4020bc1da38739f3", "best_bid": "0.871", "best_ask": "0.988"}, {"asset_id": "47977478528993701917993634313399360833217034323739582269237365313563183735835", "price": "0.96", "size": "1400", "side": "SELL", "hash": "a56daeb498c69cfb967201886bea9599caf21a5e", "best_bid": "0.012", "best_ask": "0.129"}], "timestamp": "1769384560006", "event_type": "price_change"}}
{"_local_timestamp": "2026-01-25T23:42:40.742735+00:00", "data": {"market": "0x5edebf3eb73ed300d47dd35e4c3938a6997cdbf3fa3b3ca086bdd7afa3e227cc", "price_changes": [{"asset_id": "48973293128569491311605281174826846182724783049607561423479481850292050544724", "price": "0.003", "size": "0", "side": "BUY", "hash": "add453c3050756c57933ea216eb77358d4bc6016", "best_bid": "0.871", "best_ask": "0.988"}, {"asset_id": "47977478528993701917993634313399360833217034323739582269237365313563183735835", "price": "0.997", "size": "0", "side": "SELL", "hash": "07f34ebba066fd93fe7629c863d4bef152b8873a", "best_bid": "0.012", "best_ask": "0.129"}], "timestamp": "1769384560604", "event_type": "price_change"}}
{"_local_timestamp": "2026-01-25T23:42:41.025511+00:00", "data": {"market": "0x77e024fc3dac13c1404f30a42d8df3b32a62978c63f82b36f62df830604471a0", "price_changes": [{"asset_id": "71885734107267615372441598160876793410818281961487005825293143068106970826321", "price": "0.003", "size": "1000", "side": "BUY", "hash": "7fc827268a5f542c69cada8758698f607ab00d1f", "best_bid": "0.971", "best_ask": "0.994"}, {"asset_id": "87132914336773401193105961480278292749054879702172274912936083065312455895521", "price": "0.997", "size": "1000", "side": "SELL", "hash": "8f09cf0792b05fec2463c925b1b280b0443eaaf5", "best_bid": "0.006", "best_ask": "0.029"}], "timestamp": "1769384560869", "event_type": "price_change"}}
{"_local_timestamp": "2026-01-25T23:42:42.161996+00:00", "data": {"market": "0xa04889441513194066b992c25607750d9ad9beda073baa231b7d6c0d296f3db4", "price_changes": [{"asset_id": "4927715355597512197888285947791839404212602020821540571091074384909522708343", "price": "0.011", "size": "0", "side": "BUY", "hash": "57dbeb4d91d251675c9724d5ef5d0ee7f71c48cb", "best_bid": "0.861", "best_ask": "0.985"}, {"asset_id": "38098642543471813014855148341368026538917449780662028630830591144684505089593", "price": "0.989", "size": "0", "side": "SELL", "hash": "53a6bcb7e62cab988fbea46f3f6701a8a1e63bb0", "best_bid": "0.015", "best_ask": "0.139"}], "timestamp": "1769384562018", "event_type": "price_change"}}
{"_local_timestamp": "2026-01-25T23:42:42.165226+00:00", "data": {"market": "0xa04889441513194066b992c25607750d9ad9beda073baa231b7d6c0d296f3db4", "price_changes": [{"asset_id": "4927715355597512197888285947791839404212602020821540571091074384909522708343", "price": "0.162", "size": "0", "side": "BUY", "hash": "57dbeb4d91d251675c9724d5ef5d0ee7f71c48cb", "best_bid": "0.861", "best_ask": "0.985"}, {"asset_id": "38098642543471813014855148341368026538917449780662028630830591144684505089593", "price": "0.838", "size": "0", "side": "SELL", "hash": "53a6bcb7e62cab988fbea46f3f6701a8a1e63bb0", "best_bid": "0.015", "best_ask": "0.139"}], "timestamp": "1769384562018", "event_type": "price_change"}}
{"_local_timestamp": "2026-01-25T23:42:42.797693+00:00", "data": {"market": "0xa04889441513194066b992c25607750d9ad9beda073baa231b7d6c0d296f3db4", "price_changes": [{"asset_id": "4927715355597512197888285947791839404212602020821540571091074384909522708343", "price": "0.211", "size": "5.96", "side": "BUY", "hash": "fe9408a5e9907b187bf16ca14203a4f893c54aa0", "best_bid": "0.861", "best_ask": "0.985"}, {"asset_id": "38098642543471813014855148341368026538917449780662028630830591144684505089593", "price": "0.789", "size": "5.96", "side": "SELL", "hash": "bab73eaefcd2693c032e9e70e80c3d223b23c39d", "best_bid": "0.015", "best_ask": "0.139"}], "timestamp": "1769384562665", "event_type": "price_change"}}
{"_local_timestamp": "2026-01-25T23:42:42.810221+00:00", "data": {"market": "0xa04889441513194066b992c25607750d9ad9beda073baa231b7d6c0d296f3db4", "price_changes": [{"asset_id": "4927715355597512197888285947791839404212602020821540571091074384909522708343", "price": "0.004", "size": "21.93", "side": "BUY", "hash": "9a2d5d5eec7135e63237c7ef8d14625de507b4ed", "best_bid": "0.861", "best_ask": "0.985"}, {"asset_id": "38098642543471813014855148341368026538917449780662028630830591144684505089593", "price": "0.996", "size": "21.93", "side": "SELL", "hash": "25c3d4416b28595e460b6a8b2f42966397ab5ae7", "best_bid": "0.015", "best_ask": "0.139"}], "timestamp": "1769384562667", "event_type": "price_change"}}
{"_local_timestamp": "2026-01-25T23:42:43.657666+00:00", "data": {"market": "0xa04889441513194066b992c25607750d9ad9beda073baa231b7d6c0d296f3db4", "price_changes": [{"asset_id": "4927715355597512197888285947791839404212602020821540571091074384909522708343", "price": "0.163", "size": "0", "side": "BUY", "hash": "37a182c2f5c4be2687284b4a9cdabe23bbe7802d", "best_bid": "0.861", "best_ask": "0.985"}, {"asset_id": "38098642543471813014855148341368026538917449780662028630830591144684505089593", "price": "0.837", "size": "0", "side": "SELL", "hash": "6802b46271ebaf93a776c2fb86fe9967ad3c6bd6", "best_bid": "0.015", "best_ask": "0.139"}], "timestamp": "1769384563523", "event_type": "price_change"}}
{"_local_timestamp": "2026-01-25T23:42:43.694149+00:00", "data": {"market": "0xa04889441513194066b992c25607750d9ad9beda073baa231b7d6c0d296f3db4", "price_changes": [{"asset_id": "4927715355597512197888285947791839404212602020821540571091074384909522708343", "price": "0.162", "size": "20", "side": "BUY", "hash": "b57ea48a653de09ebf12e21d60beb2ccca329ee9", "best_bid": "0.861", "best_ask": "0.985"}, {"asset_id": "38098642543471813014855148341368026538917449780662028630830591144684505089593", "price": "0.838", "size": "20", "side": "SELL", "hash": "b967d3e95f4055a1f5cdc63ad0fbc468889b5447", "best_bid": "0.015", "best_ask": "0.139"}], "timestamp": "1769384563551", "event_type": "price_change"}}
{"_local_timestamp": "2026-01-25T23:42:43.910927+00:00", "data": {"market": "0x77e024fc3dac13c1404f30a42d8df3b32a62978c63f82b36f62df830604471a0", "price_changes": [{"asset_id": "71885734107267615372441598160876793410818281961487005825293143068106970826321", "price": "0.002", "size": "1250", "side": "BUY", "hash": "d7a6fa9e98f8dd1d0575fcf2d440fa63d2ba875a", "best_bid": "0.971", "best_ask": "0.994"}, {"asset_id": "87132914336773401193105961480278292749054879702172274912936083065312455895521", "price": "0.998", "size": "1250", "side": "SELL", "hash": "07ec85cc5fdf6558f131f941ebf704642d5362ee", "best_bid": "0.006", "best_ask": "0.029"}], "timestamp": "1769384563781", "event_type": "price_change"}}
{"_local_timestamp": "2026-01-25T23:42:43.911933+00:00", "data": {"market": "0x77e024fc3dac13c1404f30a42d8df3b32a62978c63f82b36f62df830604471a0", "price_changes": [{"asset_id": "71885734107267615372441598160876793410818281961487005825293143068106970826321", "price": "0.005", "size": "0", "side": "BUY", "hash": "d7a6fa9e98f8dd1d0575fcf2d440fa63d2ba875a", "best_bid": "0.971", "best_ask": "0.994"}, {"asset_id": "87132914336773401193105961480278292749054879702172274912936083065312455895521", "price": "0.995", "size": "0", "side": "SELL", "hash": "07ec85cc5fdf6558f131f941ebf704642d5362ee", "best_bid": "0.006", "best_ask": "0.029"}], "timestamp": "1769384563781", "event_type": "price_change"}}
{"_local_timestamp": "2026-01-25T23:42:44.607125+00:00", "data": {"market": "0x77e024fc3dac13c1404f30a42d8df3b32a62978c63f82b36f62df830604471a0", "price_changes": [{"asset_id": "71885734107267615372441598160876793410818281961487005825293143068106970826321", "price": "0.004", "size": "20.96", "side": "BUY", "hash": "4c97e2d0997a7fc6f993eff032692d6e9892c746", "best_bid": "0.971", "best_ask": "0.994"}, {"asset_id": "87132914336773401193105961480278292749054879702172274912936083065312455895521", "price": "0.996", "size": "20.96", "side": "SELL", "hash": "8ee744ea2b05646ec53055aadc22ba427f26bb75", "best_bid": "0.006", "best_ask": "0.029"}], "timestamp": "1769384564477", "event_type": "price_change"}}
{"_local_timestamp": "2026-01-25T23:42:44.609971+00:00", "data": {"market": "0x77e024fc3dac13c1404f30a42d8df3b32a62978c63f82b36f62df830604471a0", "price_changes": [{"asset_id": "71885734107267615372441598160876793410818281961487005825293143068106970826321", "price": "0.002", "size": "1255.02", "side": "BUY", "hash": "9a44470f175023c285bd21b820c4cfa799c39254", "best_bid": "0.971", "best_ask": "0.994"}, {"asset_id": "87132914336773401193105961480278292749054879702172274912936083065312455895521", "price": "0.998", "size": "1255.02", "side": "SELL", "hash": "c5c11621e5d2f0de2a022b1640eca5969fb10d87", "best_bid": "0.006", "best_ask": "0.029"}], "timestamp": "1769384564480", "event_type": "price_change"}}
{"_local_timestamp": "2026-01-25T23:42:44.963012+00:00", "data": {"market": "0x5edebf3eb73ed300d47dd35e4c3938a6997cdbf3fa3b3ca086bdd7afa3e227cc", "price_changes": [{"asset_id": "48973293128569491311605281174826846182724783049607561423479481850292050544724", "price": "0.002", "size": "1250", "side": "BUY", "hash": "c012da708af00d0981b139efc580c18fd1c195eb", "best_bid": "0.871", "best_ask": "0.988"}, {"asset_id": "47977478528993701917993634313399360833217034323739582269237365313563183735835", "price": "0.998", "size": "1250", "side": "SELL", "hash": "3973c6a7757c6e40517d51b84ea2552701a81b24", "best_bid": "0.012", "best_ask": "0.129"}], "timestamp": "1769384564826", "event_type": "price_change"}}
{"_local_timestamp": "2026-01-25T23:42:44.964044+00:00", "data": {"market": "0x5edebf3eb73ed300d47dd35e4c3938a6997cdbf3fa3b3ca086bdd7afa3e227cc", "price_changes": [{"asset_id": "48973293128569491311605281174826846182724783049607561423479481850292050544724", "price": "0.004", "size": "0", "side": "BUY", "hash": "c012da708af00d0981b139efc580c18fd1c195eb", "best_bid": "0.871", "best_ask": "0.988"}, {"asset_id": "47977478528993701917993634313399360833217034323739582269237365313563183735835", "price": "0.996", "size": "0", "side": "SELL", "hash": "3973c6a7757c6e40517d51b84ea2552701a81b24", "best_bid": "0.012", "best_ask": "0.129"}], "timestamp": "1769384564826", "event_type": "price_change"}}
{"_local_timestamp": "2026-01-25T23:42:44.965964+00:00", "data": {"market": "0x5edebf3eb73ed300d47dd35e4c3938a6997cdbf3fa3b3ca086bdd7afa3e227cc", "price_changes": [{"asset_id": "48973293128569491311605281174826846182724783049607561423479481850292050544724", "price": "0.061", "size": "0", "side": "BUY", "hash": "c012da708af00d0981b139efc580c18fd1c195eb", "best_bid": "0.871", "best_ask": "0.988"}, {"asset_id": "47977478528993701917993634313399360833217034323739582269237365313563183735835", "price": "0.939", "size": "0", "side": "SELL", "hash": "3973c6a7757c6e40517d51b84ea2552701a81b24", "best_bid": "0.012", "best_ask": "0.129"}], "timestamp": "1769384564826", "event_type": "price_change"}}
{"_local_timestamp": "2026-01-25T23:42:44.966875+00:00", "data": {"market": "0x5edebf3eb73ed300d47dd35e4c3938a6997cdbf3fa3b3ca086bdd7afa3e227cc", "price_changes": [{"asset_id": "48973293128569491311605281174826846182724783049607561423479481850292050544724", "price": "0.212", "size": "0", "side": "BUY", "hash": "c012da708af00d0981b139efc580c18fd1c195eb", "best_bid": "0.871", "best_ask": "0.988"}, {"asset_id": "47977478528993701917993634313399360833217034323739582269237365313563183735835", "price": "0.788", "size": "0", "side": "SELL", "hash": "3973c6a7757c6e40517d51b84ea2552701a81b24", "best_bid": "0.012", "best_ask": "0.129"}], "timestamp": "1769384564826", "event_type": "price_change"}}
{"_local_timestamp": "2026-01-25T23:42:45.718901+00:00", "data": {"market": "0x5edebf3eb73ed300d47dd35e4c3938a6997cdbf3fa3b3ca086bdd7afa3e227cc", "price_changes": [{"asset_id": "48973293128569491311605281174826846182724783049607561423479481850292050544724", "price": "0.112", "size": "13.37", "side": "BUY", "hash": "0ba17a30640dc2869e2adb28acd0b594672a8032", "best_bid": "0.871", "best_ask": "0.988"}, {"asset_id": "47977478528993701917993634313399360833217034323739582269237365313563183735835", "price": "0.888", "size": "13.37", "side": "SELL", "hash": "f1127be6ca722dcc0a15ff6fc7c597aba85c62fe", "best_bid": "0.012", "best_ask": "0.129"}], "timestamp": "1769384565576", "event_type": "price_change"}}
{"_local_timestamp": "2026-01-25T23:42:45.720437+00:00", "data": {"market": "0x5edebf3eb73ed300d47dd35e4c3938a6997cdbf3fa3b3ca086bdd7afa3e227cc", "price_changes": [{"asset_id": "48973293128569491311605281174826846182724783049607561423479481850292050544724", "price": "0.001", "size": "6301.05", "side": "BUY", "hash": "8c9e8045def48d2034e06a95a9b4339ec83dabd1", "best_bid": "0.871", "best_ask": "0.988"}, {"asset_id": "47977478528993701917993634313399360833217034323739582269237365313563183735835", "price": "0.999", "size": "6301.05", "side": "SELL", "hash": "9970cc5ab94360c0518f29b9ba0498751331f71a", "best_bid": "0.012", "best_ask": "0.129"}], "timestamp": "1769384565577", "event_type": "price_change"}}
{"_local_timestamp": "2026-01-25T23:42:45.721749+00:00", "data": {"market": "0x5edebf3eb73ed300d47dd35e4c3938a6997cdbf3fa3b3ca086bdd7afa3e227cc", "price_changes": [{"asset_id": "48973293128569491311605281174826846182724783049607561423479481850292050544724", "price": "0.051", "size": "44.12", "side": "BUY", "hash": "21ea49b48f79ffde3a6ceda6e33ab1cdce28e0bb", "best_bid": "0.871", "best_ask": "0.988"}, {"asset_id": "47977478528993701917993634313399360833217034323739582269237365313563183735835", "price": "0.949", "size": "44.12", "side": "SELL", "hash": "7b1efbf4a2c22505f1ee5eb47f03aa06b3749f49", "best_bid": "0.012", "best_ask": "0.129"}], "timestamp": "1769384565579", "event_type": "price_change"}}
{"_local_timestamp": "2026-01-25T23:42:45.722857+00:00", "data": {"market": "0x5edebf3eb73ed300d47dd35e4c3938a6997cdbf3fa3b3ca086bdd7afa3e227cc", "price_changes": [{"asset_id": "48973293128569491311605281174826846182724783049607561423479481850292050544724", "price": "0.003", "size": "29.56", "side": "BUY", "hash": "591041edb276523e46be96a78cd091c6e697f704", "best_bid": "0.871", "best_ask": "0.988"}, {"asset_id": "47977478528993701917993634313399360833217034323739582269237365313563183735835", "price": "0.997", "size": "29.56", "side": "SELL", "hash": "ac985e98ba3d8bc3bf9901fadb979a836cce70ca", "best_bid": "0.012", "best_ask": "0.129"}], "timestamp": "1769384565580", "event_type": "price_change"}}
{"_local_timestamp": "2026-01-25T23:42:45.965293+00:00", "data": {"market": "0x1fed6d1346b04331b1ba1188525e560094040cbf3bbd84700c2dddb5241b2402", "price_changes": [{"asset_id": "38855512439706823591548373609888890731724800742290402025988926984750840280976", "price": "0.202", "size": "0", "side": "BUY", "hash": "b40e4354c66602a015e39e96bcc2f854a3da81f8", "best_bid": "0.911", "best_ask": "0.991"}, {"asset_id": "71341306129608304129076187431040953407253993378796751066411893382443918679197", "price": "0.798", "size": "0", "side": "SELL", "hash": "9c36e0e92c9b6a4cae032871fa2f382bc0dd86f7", "best_bid": "0.009", "best_ask": "0.089"}], "timestamp": "1769384565849", "event_type": "price_change"}}
{"_local_timestamp": "2026-01-25T23:42:46.665647+00:00", "data": {"market": "0x1fed6d1346b04331b1ba1188525e560094040cbf3bbd84700c2dddb5241b2402", "price_changes": [{"asset_id": "38855512439706823591548373609888890731724800742290402025988926984750840280976", "price": "0.211", "size": "5.53", "side": "BUY", "hash": "6a44256e105477fbe4ac847295c2d0115a66aa10", "best_bid": "0.911", "best_ask": "0.991"}, {"asset_id": "71341306129608304129076187431040953407253993378796751066411893382443918679197", "price": "0.789", "size": "5.53", "side": "SELL", "hash": "13b3a5bc2a4e09e4e864f98801a86789558ffacf", "best_bid": "0.009", "best_ask": "0.089"}], "timestamp": "1769384566537", "event_type": "price_change"}}
{"_local_timestamp": "2026-01-25T23:42:48.985385+00:00", "data": {"market": "0x5edebf3eb73ed300d47dd35e4c3938a6997cdbf3fa3b3ca086bdd7afa3e227cc", "price_changes": [{"asset_id": "48973293128569491311605281174826846182724783049607561423479481850292050544724", "price": "0.111", "size": "0", "side": "BUY", "hash": "7cffa287ed54b8e695fab33c4ec99f9beeddcde8", "best_bid": "0.871", "best_ask": "0.988"}, {"asset_id": "47977478528993701917993634313399360833217034323739582269237365313563183735835", "price": "0.889", "size": "0", "side": "SELL", "hash": "c7bc6f6067f2299bbca49657b883516fca136e42", "best_bid": "0.012", "best_ask": "0.129"}], "timestamp": "1769384568870", "event_type": "price_change"}}
{"_local_timestamp": "2026-01-25T23:42:49.018172+00:00", "data": {"market": "0x5edebf3eb73ed300d47dd35e4c3938a6997cdbf3fa3b3ca086bdd7afa3e227cc", "price_changes": [{"asset_id": "48973293128569491311605281174826846182724783049607561423479481850292050544724", "price": "0.113", "size": "20", "side": "BUY", "hash": "6e71ed1dd99e4d98a154c5ffb989bfcee54c63bc", "best_bid": "0.871", "best_ask": "0.988"}, {"asset_id": "47977478528993701917993634313399360833217034323739582269237365313563183735835", "price": "0.887", "size": "20", "side": "SELL", "hash": "6784a6a7cbdb6e07226c4630e42e7becdcc0a122", "best_bid": "0.012", "best_ask": "0.129"}], "timestamp": "1769384568899", "event_type": "price_change"}}
{"_local_timestamp": "2026-01-25T23:43:02.136087+00:00", "data": {"market": "0xbf6fbc35082962002b61f17e26820db124930ac43175934864e34a415ee40620", "price_changes": [{"asset_id": "42674776176570186449325309200969258771704155869979743437343764984621699243894", "price": "0.07", "size": "7.91", "side": "BUY", "hash": "94c36927d828e401c667e3916c137b53509336ad", "best_bid": "0.51", "best_ask": "0.94"}, {"asset_id": "98673773007855046568692125013481059419674479536813359840428477180250006155633", "price": "0.93", "size": "7.91", "side": "SELL", "hash": "1cb3c3943efebb692441f73095253b89131845d7", "best_bid": "0.06", "best_ask": "0.49"}], "timestamp": "1769384581991", "event_type": "price_change"}}
{"_local_timestamp": "2026-01-25T23:43:13.512491+00:00", "data": {"market": "0x1fed6d1346b04331b1ba1188525e560094040cbf3bbd84700c2dddb5241b2402", "price_changes": [{"asset_id": "38855512439706823591548373609888890731724800742290402025988926984750840280976", "price": "0.061", "size": "200", "side": "BUY", "hash": "db53bdd2f89dfe1cf6254b83aa55d42079cdae53", "best_bid": "0.911", "best_ask": "0.991"}, {"asset_id": "71341306129608304129076187431040953407253993378796751066411893382443918679197", "price": "0.939", "size": "200", "side": "SELL", "hash": "6dcaca5f634125df548af7d2ed4dd9c33a50ba23", "best_bid": "0.009", "best_ask": "0.089"}], "timestamp": "1769384593155", "event_type": "price_change"}}
{"_local_timestamp": "2026-01-25T23:43:28.195595+00:00", "data": {"market": "0xc65ebe3378903b9f672868b4ad157b12f8d5b801303c224e2b9627c1de6e1bb4", "price_changes": [{"asset_id": "100153647768819913478482487007469803840833665951037785527037226522546628635049", "price": "0.17", "size": "0", "side": "BUY", "hash": "f0595a743426774e427b227c842fc46c6aa027b3", "best_bid": "0.26", "best_ask": "0.95"}, {"asset_id": "68287553062600224636928508192555401721388367384589206235766778752053103462686", "price": "0.83", "size": "0", "side": "SELL", "hash": "9f8c9f84ec622bab5774f524fa9df9bc8756c23a", "best_bid": "0.05", "best_ask": "0.74"}], "timestamp": "1769384608106", "event_type": "price_change"}}
{"_local_timestamp": "2026-01-25T23:43:28.877689+00:00", "data": {"market": "0xc65ebe3378903b9f672868b4ad157b12f8d5b801303c224e2b9627c1de6e1bb4", "price_changes": [{"asset_id": "100153647768819913478482487007469803840833665951037785527037226522546628635049", "price": "0.01", "size": "3436.57", "side": "BUY", "hash": "49f5620dcbaa7d0443bf971326f22c9354ba6456", "best_bid": "0.26", "best_ask": "0.95"}, {"asset_id": "68287553062600224636928508192555401721388367384589206235766778752053103462686", "price": "0.99", "size": "3436.57", "side": "SELL", "hash": "2e1ca3925188f92a4e799f4e013adca1dc42abe9", "best_bid": "0.05", "best_ask": "0.74"}], "timestamp": "1769384608751", "event_type": "price_change"}}
{"_local_timestamp": "2026-01-25T23:43:28.885711+00:00", "data": {"market": "0xc65ebe3378903b9f672868b4ad157b12f8d5b801303c224e2b9627c1de6e1bb4", "price_changes": [{"asset_id": "100153647768819913478482487007469803840833665951037785527037226522546628635049", "price": "0.13", "size": "8.22", "side": "BUY", "hash": "c0910675914edee0a215130250d1e8dd38a2d158", "best_bid": "0.26", "best_ask": "0.95"}, {"asset_id": "68287553062600224636928508192555401721388367384589206235766778752053103462686", "price": "0.87", "size": "8.22", "side": "SELL", "hash": "3feb35c5cfbf4b9d7815ce18428a230559c992cf", "best_bid": "0.05", "best_ask": "0.74"}], "timestamp": "1769384608761", "event_type": "price_change"}}
{"_local_timestamp": "2026-01-25T23:43:47.696992+00:00", "data": {"market": "0x5edebf3eb73ed300d47dd35e4c3938a6997cdbf3fa3b3ca086bdd7afa3e227cc", "price_changes": [{"asset_id": "48973293128569491311605281174826846182724783049607561423479481850292050544724", "price": "0.491", "size": "0", "side": "BUY", "hash": "057bd091df8f77ea924c37f9cdcbe2324a05d106", "best_bid": "0.871", "best_ask": "0.988"}, {"asset_id": "47977478528993701917993634313399360833217034323739582269237365313563183735835", "price": "0.509", "size": "0", "side": "SELL", "hash": "86ec5992ec0c824e1e50bf35b02a3d0c6366285d", "best_bid": "0.012", "best_ask": "0.129"}], "timestamp": "1769384627629", "event_type": "price_change"}}
{"_local_timestamp": "2026-01-25T23:43:47.698044+00:00", "data": {"market": "0xc65ebe3378903b9f672868b4ad157b12f8d5b801303c224e2b9627c1de6e1bb4", "price_changes": [{"asset_id": "100153647768819913478482487007469803840833665951037785527037226522546628635049", "price": "0.25", "size": "0", "side": "BUY", "hash": "a50f18f85be06fb8ba6cf2a462828a14392171a7", "best_bid": "0.26", "best_ask": "0.95"}, {"asset_id": "68287553062600224636928508192555401721388367384589206235766778752053103462686", "price": "0.75", "size": "0", "side": "SELL", "hash": "e7a5a39458859c0d73391ddddbd11eebc7e1edcc", "best_bid": "0.05", "best_ask": "0.74"}], "timestamp": "1769384627629", "event_type": "price_change"}}
{"_local_timestamp": "2026-01-25T23:43:47.698934+00:00", "data": {"market": "0x5edebf3eb73ed300d47dd35e4c3938a6997cdbf3fa3b3ca086bdd7afa3e227cc", "price_changes": [{"asset_id": "48973293128569491311605281174826846182724783049607561423479481850292050544724", "price": "0.11", "size": "125", "side": "BUY", "hash": "057bd091df8f77ea924c37f9cdcbe2324a05d106", "best_bid": "0.871", "best_ask": "0.988"}, {"asset_id": "47977478528993701917993634313399360833217034323739582269237365313563183735835", "price": "0.89", "size": "125", "side": "SELL", "hash": "86ec5992ec0c824e1e50bf35b02a3d0c6366285d", "best_bid": "0.012", "best_ask": "0.129"}], "timestamp": "1769384627629", "event_type": "price_change"}}
{"_local_timestamp": "2026-01-25T23:43:47.708292+00:00", "data": {"market": "0x1fed6d1346b04331b1ba1188525e560094040cbf3bbd84700c2dddb5241b2402", "price_changes": [{"asset_id": "38855512439706823591548373609888890731724800742290402025988926984750840280976", "price": "0.561", "size": "0", "side": "BUY", "hash": "956a20ceb7d82abc089cf76830df83660ae7db2c", "best_bid": "0.911", "best_ask": "0.991"}, {"asset_id": "71341306129608304129076187431040953407253993378796751066411893382443918679197", "price": "0.439", "size": "0", "side": "SELL", "hash": "37fc254bbf0656de24808f8bef343a592d13bccc", "best_bid": "0.009", "best_ask": "0.089"}], "timestamp": "1769384627629", "event_type": "price_change"}}
{"_local_timestamp": "2026-01-25T23:43:47.709240+00:00", "data": {"market": "0x1fed6d1346b04331b1ba1188525e560094040cbf3bbd84700c2dddb5241b2402", "price_changes": [{"asset_id": "38855512439706823591548373609888890731724800742290402025988926984750840280976", "price": "0.21", "size": "50", "side": "BUY", "hash": "956a20ceb7d82abc089cf76830df83660ae7db2c", "best_bid": "0.911", "best_ask": "0.991"}, {"asset_id": "71341306129608304129076187431040953407253993378796751066411893382443918679197", "price": "0.79", "size": "50", "side": "SELL", "hash": "37fc254bbf0656de24808f8bef343a592d13bccc", "best_bid": "0.009", "best_ask": "0.089"}], "timestamp": "1769384627629", "event_type": "price_change"}}
{"_local_timestamp": "2026-01-25T23:43:47.710159+00:00", "data": {"market": "0xa04889441513194066b992c25607750d9ad9beda073baa231b7d6c0d296f3db4", "price_changes": [{"asset_id": "4927715355597512197888285947791839404212602020821540571091074384909522708343", "price": "0.511", "size": "0", "side": "BUY", "hash": "2ea633fee589d9c61db75c9a4ce8d68312c028d0", "best_bid": "0.861", "best_ask": "0.985"}, {"asset_id": "38098642543471813014855148341368026538917449780662028630830591144684505089593", "price": "0.489", "size": "0", "side": "SELL", "hash": "037e569136d2806603d352bddb60947c3150803a", "best_bid": "0.015", "best_ask": "0.139"}], "timestamp": "1769384627629", "event_type": "price_change"}}
{"_local_timestamp": "2026-01-25T23:43:47.711024+00:00", "data": {"market": "0xa04889441513194066b992c25607750d9ad9beda073baa231b7d6c0d296f3db4", "price_changes": [{"asset_id": "4927715355597512197888285947791839404212602020821540571091074384909522708343", "price": "0.161", "size": "0", "side": "BUY", "hash": "2ea633fee589d9c61db75c9a4ce8d68312c028d0", "best_bid": "0.861", "best_ask": "0.985"}, {"asset_id": "38098642543471813014855148341368026538917449780662028630830591144684505089593", "price": "0.839", "size": "0", "side": "SELL", "hash": "037e569136d2806603d352bddb60947c3150803a", "best_bid": "0.015", "best_ask": "0.139"}], "timestamp": "1769384627629", "event_type": "price_change"}}
{"_local_timestamp": "2026-01-25T23:43:48.246263+00:00", "data": {"market": "0xa04889441513194066b992c25607750d9ad9beda073baa231b7d6c0d296f3db4", "price_changes": [{"asset_id": "4927715355597512197888285947791839404212602020821540571091074384909522708343", "price": "0.486", "size": "100", "side": "BUY", "hash": "10055cf24615022b4fee2e5a2ba88b5f1bb810bb", "best_bid": "0.861", "best_ask": "0.985"}, {"asset_id": "38098642543471813014855148341368026538917449780662028630830591144684505089593", "price": "0.514", "size": "100", "side": "SELL", "hash": "b303b8779af98d4e1217ccb8bb8a0f49da651cbd", "best_bid": "0.015", "best_ask": "0.139"}], "timestamp": "1769384628173", "event_type": "price_change"}}
{"_local_timestamp": "2026-01-25T23:43:48.269907+00:00", "data": {"market": "0x5edebf3eb73ed300d47dd35e4c3938a6997cdbf3fa3b3ca086bdd7afa3e227cc", "price_changes": [{"asset_id": "48973293128569491311605281174826846182724783049607561423479481850292050544724", "price": "0.061", "size": "100", "side": "BUY", "hash": "193e9021b81f7c0df4641446f0a473ffaecaaed3", "best_bid": "0.871", "best_ask": "0.988"}, {"asset_id": "47977478528993701917993634313399360833217034323739582269237365313563183735835", "price": "0.939", "size": "100", "side": "SELL", "hash": "be8af7b32f43275b75ec068646e8a1a61cbcc842", "best_bid": "0.012", "best_ask": "0.129"}], "timestamp": "1769384628205", "event_type": "price_change"}}
{"_local_timestamp": "2026-01-25T23:43:48.294846+00:00", "data": {"market": "0x5edebf3eb73ed300d47dd35e4c3938a6997cdbf3fa3b3ca086bdd7afa3e227cc", "price_changes": [{"asset_id": "48973293128569491311605281174826846182724783049607561423479481850292050544724", "price": "0.466", "size": "100", "side": "BUY", "hash": "7c2012ce2b9a92b3044b29d749492b2eeaafbae2", "best_bid": "0.871", "best_ask": "0.988"}, {"asset_id": "47977478528993701917993634313399360833217034323739582269237365313563183735835", "price": "0.534", "size": "100", "side": "SELL", "hash": "ee5ba7de1567183edbccf11ef61d3d2a7ac25eb2", "best_bid": "0.012", "best_ask": "0.129"}], "timestamp": "1769384628226", "event_type": "price_change"}}
{"_local_timestamp": "2026-01-25T23:43:48.312025+00:00", "data": {"market": "0xc65ebe3378903b9f672868b4ad157b12f8d5b801303c224e2b9627c1de6e1bb4", "price_changes": [{"asset_id": "68287553062600224636928508192555401721388367384589206235766778752053103462686", "price": "0.74", "size": "0", "side": "SELL", "hash": "0811ad940933e46b5d5d5b5b2847b574ae7f7fff", "best_bid": "0.05", "best_ask": "0.78"}, {"asset_id": "100153647768819913478482487007469803840833665951037785527037226522546628635049", "price": "0.26", "size": "0", "side": "BUY", "hash": "50dcfaa009c99075036223a3caff1925c62c4258", "best_bid": "0.22", "best_ask": "0.95"}], "timestamp": "1769384628237", "event_type": "price_change"}}
{"_local_timestamp": "2026-01-25T23:43:48.627290+00:00", "data": {"market": "0x1fed6d1346b04331b1ba1188525e560094040cbf3bbd84700c2dddb5241b2402", "price_changes": [{"asset_id": "38855512439706823591548373609888890731724800742290402025988926984750840280976", "price": "0.606", "size": "100", "side": "BUY", "hash": "69d4d2d2e6cc90b187b7da107bd1c6e27a8154d5", "best_bid": "0.911", "best_ask": "0.991"}, {"asset_id": "71341306129608304129076187431040953407253993378796751066411893382443918679197", "price": "0.394", "size": "100", "side": "SELL", "hash": "43092d7fe957af34970615e769d7224a5faa1351", "best_bid": "0.009", "best_ask": "0.089"}], "timestamp": "1769384628565", "event_type": "price_change"}}
{"_local_timestamp": "2026-01-25T23:43:48.632929+00:00", "data": {"market": "0x1fed6d1346b04331b1ba1188525e560094040cbf3bbd84700c2dddb5241b2402", "price_changes": [{"asset_id": "38855512439706823591548373609888890731724800742290402025988926984750840280976", "price": "0.301", "size": "100", "side": "BUY", "hash": "f5be4a46bf2c38722c1f9d0fdf0a713ef1867397", "best_bid": "0.911", "best_ask": "0.991"}, {"asset_id": "71341306129608304129076187431040953407253993378796751066411893382443918679197", "price": "0.699", "size": "100", "side": "SELL", "hash": "c5caad664577ef12a5b868f0aa6413a53d2c68f9", "best_bid": "0.009", "best_ask": "0.089"}], "timestamp": "1769384628567", "event_type": "price_change"}}
{"_local_timestamp": "2026-01-25T23:43:48.641448+00:00", "data": {"market": "0xc65ebe3378903b9f672868b4ad157b12f8d5b801303c224e2b9627c1de6e1bb4", "price_changes": [{"asset_id": "100153647768819913478482487007469803840833665951037785527037226522546628635049", "price": "0.27", "size": "66.66", "side": "BUY", "hash": "ac3f8d03058bdbaa07e3f9ec8a2652a4997cc3ae", "best_bid": "0.27", "best_ask": "0.95"}, {"asset_id": "68287553062600224636928508192555401721388367384589206235766778752053103462686", "price": "0.73", "size": "66.66", "side": "SELL", "hash": "118a9b56dbf8f4ef4e994c6747ea6bb8c0d2fe85", "best_bid": "0.05", "best_ask": "0.73"}], "timestamp": "1769384628575", "event_type": "price_change"}}
{"_local_timestamp": "2026-01-25T23:43:48.704967+00:00", "data": {"market": "0xa04889441513194066b992c25607750d9ad9beda073baa231b7d6c0d296f3db4", "price_changes": [{"asset_id": "4927715355597512197888285947791839404212602020821540571091074384909522708343", "price": "0.11", "size": "425", "side": "BUY", "hash": "15a2f4b150318c0518341ee3d516521b7c1ea985", "best_bid": "0.861", "best_ask": "0.985"}, {"asset_id": "38098642543471813014855148341368026538917449780662028630830591144684505089593", "price": "0.89", "size": "425", "side": "SELL", "hash": "faba88c07f9b0c56362e3cb666fdd2be3efcb99c", "best_bid": "0.015", "best_ask": "0.139"}], "timestamp": "1769384628633", "event_type": "price_change"}}
{"_local_timestamp": "2026-01-25T23:43:49.268200+00:00", "data": {"market": "0xc65ebe3378903b9f672868b4ad157b12f8d5b801303c224e2b9627c1de6e1bb4", "price_changes": [{"asset_id": "68287553062600224636928508192555401721388367384589206235766778752053103462686", "price": "0.72", "size": "29.34", "side": "SELL", "hash": "a6d13acc61d3e5fb9f2cbf7ecc59d192882903e8", "best_bid": "0.05", "best_ask": "0.72"}, {"asset_id": "100153647768819913478482487007469803840833665951037785527037226522546628635049", "price": "0.28", "size": "29.34", "side": "BUY", "hash": "638edaa622f21352a99b30e4a708891e2e88cc44", "best_bid": "0.28", "best_ask": "0.95"}], "timestamp": "1769384629196", "event_type": "price_change"}}
{"_local_timestamp": "2026-01-25T23:43:52.840619+00:00", "data": {"market": "0xa04889441513194066b992c25607750d9ad9beda073baa231b7d6c0d296f3db4", "price_changes": [{"asset_id": "4927715355597512197888285947791839404212602020821540571091074384909522708343", "price": "0.162", "size": "0", "side": "BUY", "hash": "243cb0d06ac98a525071b5ce1e1aa1667a610719", "best_bid": "0.861", "best_ask": "0.985"}, {"asset_id": "38098642543471813014855148341368026538917449780662028630830591144684505089593", "price": "0.838", "size": "0", "side": "SELL", "hash": "6a9ef4b2e9b9ed0a6606a5a5215fedab71f95006", "best_bid": "0.015", "best_ask": "0.139"}], "timestamp": "1769384632703", "event_type": "price_change"}}
{"_local_timestamp": "2026-01-25T23:43:52.872967+00:00", "data": {"market": "0xa04889441513194066b992c25607750d9ad9beda073baa231b7d6c0d296f3db4", "price_changes": [{"asset_id": "4927715355597512197888285947791839404212602020821540571091074384909522708343", "price": "0.161", "size": "20", "side": "BUY", "hash": "4c75948aa459dd9a1751de879809614183e432a2", "best_bid": "0.861", "best_ask": "0.985"}, {"asset_id": "38098642543471813014855148341368026538917449780662028630830591144684505089593", "price": "0.839", "size": "20", "side": "SELL", "hash": "bfc8572033673c319c717c97f96161dfed1c8ee1", "best_bid": "0.015", "best_ask": "0.139"}], "timestamp": "1769384632731", "event_type": "price_change"}}
{"_local_timestamp": "2026-01-25T23:43:54.150129+00:00", "data": {"market": "0xa04889441513194066b992c25607750d9ad9beda073baa231b7d6c0d296f3db4", "price_changes": [{"asset_id": "4927715355597512197888285947791839404212602020821540571091074384909522708343", "price": "0.86", "size": "0", "side": "BUY", "hash": "2f7438dd2a787625a2837d4322422f0009fa1eec", "best_bid": "0.861", "best_ask": "0.985"}, {"asset_id": "38098642543471813014855148341368026538917449780662028630830591144684505089593", "price": "0.14", "size": "0", "side": "SELL", "hash": "ff1a2302a6f2447a07cf6b6280f0d32b437b84d0", "best_bid": "0.015", "best_ask": "0.139"}], "timestamp": "1769384634000", "event_type": "price_change"}}
{"_local_timestamp": "2026-01-25T23:43:54.152024+00:00", "data": {"market": "0x1fed6d1346b04331b1ba1188525e560094040cbf3bbd84700c2dddb5241b2402", "price_changes": [{"asset_id": "38855512439706823591548373609888890731724800742290402025988926984750840280976", "price": "0.91", "size": "0", "side": "BUY", "hash": "632c25b6def6e35b1657fa535fce35951c8c9b8b", "best_bid": "0.911", "best_ask": "0.991"}, {"asset_id": "71341306129608304129076187431040953407253993378796751066411893382443918679197", "price": "0.09", "size": "0", "side": "SELL", "hash": "9b44824dba848fbf9b228ab7f2c9bf894d0ad215", "best_bid": "0.009", "best_ask": "0.089"}], "timestamp": "1769384634000", "event_type": "price_change"}}
{"_local_timestamp": "2026-01-25T23:43:54.167528+00:00", "data": {"market": "0xe1730ddaa88ffb2fb360af9f5b58c9e427f61c30712578b1701408911e3f655d", "price_changes": [{"asset_id": "37042473221634168250099193554902520956898907103252140530642497138603218091624", "price": "0.18", "size": "71.66", "side": "BUY", "hash": "7dab44ba196a3150d9095d2e39b2f752f6ada3aa", "best_bid": "0.18", "best_ask": "0.91"}, {"asset_id": "81699282895973617782040895594229616523859617972840387954210064871270448792972", "price": "0.82", "size": "71.66", "side": "SELL", "hash": "d120c4f14be4852de502545215f001ff2c214b40", "best_bid": "0.09", "best_ask": "0.82"}], "timestamp": "1769384634002", "event_type": "price_change"}}
{"_local_timestamp": "2026-01-25T23:43:54.173352+00:00", "data": {"market": "0x5edebf3eb73ed300d47dd35e4c3938a6997cdbf3fa3b3ca086bdd7afa3e227cc", "price_changes": [{"asset_id": "48973293128569491311605281174826846182724783049607561423479481850292050544724", "price": "0.87", "size": "0", "side": "BUY", "hash": "64b28e9ea4187ae5f77c6397059f7008d1c9305d", "best_bid": "0.871", "best_ask": "0.988"}, {"asset_id": "47977478528993701917993634313399360833217034323739582269237365313563183735835", "price": "0.13", "size": "0", "side": "SELL", "hash": "a3fc7af6de2613a97f25156ed22ba9b8589e2be9", "best_bid": "0.012", "best_ask": "0.129"}], "timestamp": "1769384634002", "event_type": "price_change"}}
{"_local_timestamp": "2026-01-25T23:44:03.304110+00:00", "data": {"market": "0xc65ebe3378903b9f672868b4ad157b12f8d5b801303c224e2b9627c1de6e1bb4", "price_changes": [{"asset_id": "100153647768819913478482487007469803840833665951037785527037226522546628635049", "price": "0.07", "size": "34.03", "side": "BUY", "hash": "da351f4145f2d8bcd8c8c70a24c156983787dba5", "best_bid": "0.28", "best_ask": "0.95"}, {"asset_id": "68287553062600224636928508192555401721388367384589206235766778752053103462686", "price": "0.93", "size": "34.03", "side": "SELL", "hash": "c721e08c2e22a645820cf8a00c9b1bcdbd3e4c0d", "best_bid": "0.05", "best_ask": "0.72"}], "timestamp": "1769384643163", "event_type": "price_change"}}
{"_local_timestamp": "2026-01-25T23:44:03.564803+00:00", "data": {"market": "0xc65ebe3378903b9f672868b4ad157b12f8d5b801303c224e2b9627c1de6e1bb4", "price_changes": [{"asset_id": "100153647768819913478482487007469803840833665951037785527037226522546628635049", "price": "0.05", "size": "230", "side": "BUY", "hash": "0c3bd9550d518cfe7add19e75f797507f82b0301", "best_bid": "0.28", "best_ask": "0.95"}, {"asset_id": "68287553062600224636928508192555401721388367384589206235766778752053103462686", "price": "0.95", "size": "230", "side": "SELL", "hash": "09051cb0628fa5c2e11ca9d89169db61a07eb302", "best_bid": "0.05", "best_ask": "0.72"}], "timestamp": "1769384643414", "event_type": "price_change"}}
{"_local_timestamp": "2026-01-25T23:44:03.582649+00:00", "data": {"market": "0x5edebf3eb73ed300d47dd35e4c3938a6997cdbf3fa3b3ca086bdd7afa3e227cc", "price_changes": [{"asset_id": "48973293128569491311605281174826846182724783049607561423479481850292050544724", "price": "0.07", "size": "100", "side": "BUY", "hash": "0362a61cc7691cd4e9e7ade8916dc9ae903fbd58", "best_bid": "0.871", "best_ask": "0.988"}, {"asset_id": "47977478528993701917993634313399360833217034323739582269237365313563183735835", "price": "0.93", "size": "100", "side": "SELL", "hash": "81fb99d5f0ead49797830b9ef574d52f57e10ef0", "best_bid": "0.012", "best_ask": "0.129"}], "timestamp": "1769384643414", "event_type": "price_change"}}
{"_local_timestamp": "2026-01-25T23:44:08.668610+00:00", "data": {"market": "0xa04889441513194066b992c25607750d9ad9beda073baa231b7d6c0d296f3db4", "price_changes": [{"asset_id": "4927715355597512197888285947791839404212602020821540571091074384909522708343", "price": "0.16", "size": "0", "side": "BUY", "hash": "ffd6db956b90f0f00e2d3cc7d60d6fbc7caec7c4", "best_bid": "0.861", "best_ask": "0.985"}, {"asset_id": "38098642543471813014855148341368026538917449780662028630830591144684505089593", "price": "0.84", "size": "0", "side": "SELL", "hash": "5a7be829f1a9b32ceffed44dc54b33b0d816740d", "best_bid": "0.015", "best_ask": "0.139"}], "timestamp": "1769384648425", "event_type": "price_change"}}
{"_local_timestamp": "2026-01-25T23:44:08.669695+00:00", "data": {"market": "0x1fed6d1346b04331b1ba1188525e560094040cbf3bbd84700c2dddb5241b2402", "price_changes": [{"asset_id": "38855512439706823591548373609888890731724800742290402025988926984750840280976", "price": "0.21", "size": "0", "side": "BUY", "hash": "145a29e63bb32c89ebb34652f4e31bb44d1ebf1e", "best_bid": "0.911", "best_ask": "0.991"}, {"asset_id": "71341306129608304129076187431040953407253993378796751066411893382443918679197", "price": "0.79", "size": "0", "side": "SELL", "hash": "a6a405befb1e3f0b599694cc1aeeb81131c1e654", "best_bid": "0.009", "best_ask": "0.089"}], "timestamp": "1769384648424", "event_type": "price_change"}}
{"_local_timestamp": "2026-01-25T23:44:08.670738+00:00", "data": {"market": "0x1fed6d1346b04331b1ba1188525e560094040cbf3bbd84700c2dddb5241b2402", "price_changes": [{"asset_id": "38855512439706823591548373609888890731724800742290402025988926984750840280976", "price": "0.17", "size": "0", "side": "BUY", "hash": "145a29e63bb32c89ebb34652f4e31bb44d1ebf1e", "best_bid": "0.911", "best_ask": "0.991"}, {"asset_id": "71341306129608304129076187431040953407253993378796751066411893382443918679197", "price": "0.83", "size": "0", "side": "SELL", "hash": "a6a405befb1e3f0b599694cc1aeeb81131c1e654", "best_bid": "0.009", "best_ask": "0.089"}], "timestamp": "1769384648424", "event_type": "price_change"}}
{"_local_timestamp": "2026-01-25T23:44:08.671709+00:00", "data": {"market": "0x1fed6d1346b04331b1ba1188525e560094040cbf3bbd84700c2dddb5241b2402", "price_changes": [{"asset_id": "38855512439706823591548373609888890731724800742290402025988926984750840280976", "price": "0.13", "size": "0", "side": "BUY", "hash": "145a29e63bb32c89ebb34652f4e31bb44d1ebf1e", "best_bid": "0.911", "best_ask": "0.991"}, {"asset_id": "71341306129608304129076187431040953407253993378796751066411893382443918679197", "price": "0.87", "size": "0", "side": "SELL", "hash": "a6a405befb1e3f0b599694cc1aeeb81131c1e654", "best_bid": "0.009", "best_ask": "0.089"}], "timestamp": "1769384648424", "event_type": "price_change"}}
{"_local_timestamp": "2026-01-25T23:44:09.000181+00:00", "data": {"market": "0x5edebf3eb73ed300d47dd35e4c3938a6997cdbf3fa3b3ca086bdd7afa3e227cc", "price_changes": [{"asset_id": "48973293128569491311605281174826846182724783049607561423479481850292050544724", "price": "0.16", "size": "100", "side": "BUY", "hash": "b60c9261efb95caaf89fd66a7ec88070a7d71ddc", "best_bid": "0.871", "best_ask": "0.988"}, {"asset_id": "47977478528993701917993634313399360833217034323739582269237365313563183735835", "price": "0.84", "size": "100", "side": "SELL", "hash": "3117128365208eebfcdef14aa96298bff6331be4", "best_bid": "0.012", "best_ask": "0.129"}], "timestamp": "1769384648721", "event_type": "price_change"}}
{"_local_timestamp": "2026-01-25T23:44:09.012358+00:00", "data": {"market": "0xa04889441513194066b992c25607750d9ad9beda073baa231b7d6c0d296f3db4", "price_changes": [{"asset_id": "4927715355597512197888285947791839404212602020821540571091074384909522708343", "price": "0.161", "size": "120", "side": "BUY", "hash": "dcdc6865af8c5b3831f09c55e353f60d0b571ebb", "best_bid": "0.861", "best_ask": "0.985"}, {"asset_id": "38098642543471813014855148341368026538917449780662028630830591144684505089593", "price": "0.839", "size": "120", "side": "SELL", "hash": "2be0ba81e546f8eaccb693125deba19224308246", "best_bid": "0.015", "best_ask": "0.139"}], "timestamp": "1769384648722", "event_type": "price_change"}}
{"_local_timestamp": "2026-01-25T23:44:09.016611+00:00", "data": {"market": "0x1fed6d1346b04331b1ba1188525e560094040cbf3bbd84700c2dddb5241b2402", "price_changes": [{"asset_id": "38855512439706823591548373609888890731724800742290402025988926984750840280976", "price": "0.25", "size": "262", "side": "BUY", "hash": "ed66733cae5ee9c9a039c3ea8d3135742dddbd51", "best_bid": "0.911", "best_ask": "0.991"}, {"asset_id": "71341306129608304129076187431040953407253993378796751066411893382443918679197", "price": "0.75", "size": "262", "side": "SELL", "hash": "90380e2f1c766029344d8d6f43305f8724fdb34d", "best_bid": "0.009", "best_ask": "0.089"}], "timestamp": "1769384648725", "event_type": "price_change"}}
{"_local_timestamp": "2026-01-25T23:44:09.120185+00:00", "data": {"market": "0x1fed6d1346b04331b1ba1188525e560094040cbf3bbd84700c2dddb5241b2402", "price_changes": [{"asset_id": "38855512439706823591548373609888890731724800742290402025988926984750840280976", "price": "0.15", "size": "551.66", "side": "BUY", "hash": "e72b7ebcacbba1fd15bc40b2bfc1ea31b4ca5e5e", "best_bid": "0.911", "best_ask": "0.991"}, {"asset_id": "71341306129608304129076187431040953407253993378796751066411893382443918679197", "price": "0.85", "size": "551.66", "side": "SELL", "hash": "7d849ed919910f7f6e0082b17f152d7558477173", "best_bid": "0.009", "best_ask": "0.089"}], "timestamp": "1769384648819", "event_type": "price_change"}}
{"_local_timestamp": "2026-01-25T23:44:09.161875+00:00", "data": {"market": "0x1fed6d1346b04331b1ba1188525e560094040cbf3bbd84700c2dddb5241b2402", "price_changes": [{"asset_id": "38855512439706823591548373609888890731724800742290402025988926984750840280976", "price": "0.2", "size": "410", "side": "BUY", "hash": "424c61dfd98e4062a3a30c0022ebb781a8e940ec", "best_bid": "0.911", "best_ask": "0.991"}, {"asset_id": "71341306129608304129076187431040953407253993378796751066411893382443918679197", "price": "0.8", "size": "410", "side": "SELL", "hash": "2ac63604c9f66963249e7f60ab7c6588d4be4fc9", "best_bid": "0.009", "best_ask": "0.089"}], "timestamp": "1769384648887", "event_type": "price_change"}}
{"_local_timestamp": "2026-01-25T23:44:10.761699+00:00", "data": {"market": "0x1fed6d1346b04331b1ba1188525e560094040cbf3bbd84700c2dddb5241b2402", "price_changes": [{"asset_id": "71341306129608304129076187431040953407253993378796751066411893382443918679197", "price": "0.01", "size": "148", "side": "BUY", "hash": "112b3c861eaefc44bab3697a652ed29b95b08e89", "best_bid": "0.01", "best_ask": "0.089"}, {"asset_id": "38855512439706823591548373609888890731724800742290402025988926984750840280976", "price": "0.99", "size": "148", "side": "SELL", "hash": "d91992c493ad66bc20fb0d2e7932924182871b96", "best_bid": "0.911", "best_ask": "0.99"}], "timestamp": "1769384650642", "event_type": "price_change"}}
{"_local_timestamp": "2026-01-25T23:44:13.632368+00:00", "data": {"market": "0x5edebf3eb73ed300d47dd35e4c3938a6997cdbf3fa3b3ca086bdd7afa3e227cc", "price_changes": [{"asset_id": "48973293128569491311605281174826846182724783049607561423479481850292050544724", "price": "0.113", "size": "0", "side": "BUY", "hash": "0bf2be54093eb1450cff1d992513f1657c75b009", "best_bid": "0.871", "best_ask": "0.988"}, {"asset_id": "47977478528993701917993634313399360833217034323739582269237365313563183735835", "price": "0.887", "size": "0", "side": "SELL", "hash": "08ed9b3c81aa93046edb70a34512bc4606865884", "best_bid": "0.012", "best_ask": "0.129"}], "timestamp": "1769384653489", "event_type": "price_change"}}
{"_local_timestamp": "2026-01-25T23:44:13.633527+00:00", "data": {"market": "0xa04889441513194066b992c25607750d9ad9beda073baa231b7d6c0d296f3db4", "price_changes": [{"asset_id": "4927715355597512197888285947791839404212602020821540571091074384909522708343", "price": "0.161", "size": "100", "side": "BUY", "hash": "16c75ecea9d58c68456b9ff59c6b852863a0b070", "best_bid": "0.861", "best_ask": "0.985"}, {"asset_id": "38098642543471813014855148341368026538917449780662028630830591144684505089593", "price": "0.839", "size": "100", "side": "SELL", "hash": "681e05adc320d27f50ee0557633f977fd3c4d3d6", "best_bid": "0.015", "best_ask": "0.139"}], "timestamp": "1769384653489", "event_type": "price_change"}}
{"_local_timestamp": "2026-01-25T23:44:13.664860+00:00", "data": {"market": "0x5edebf3eb73ed300d47dd35e4c3938a6997cdbf3fa3b3ca086bdd7afa3e227cc", "price_changes": [{"asset_id": "48973293128569491311605281174826846182724783049607561423479481850292050544724", "price": "0.161", "size": "20", "side": "BUY", "hash": "49a25e4fd585050720dc3eb9947dc6d15ba86c16", "best_bid": "0.871", "best_ask": "0.988"}, {"asset_id": "47977478528993701917993634313399360833217034323739582269237365313563183735835", "price": "0.839", "size": "20", "side": "SELL", "hash": "35c5a8e6832ed63b6829edfd4b265638d1f452fc", "best_bid": "0.012", "best_ask": "0.129"}], "timestamp": "1769384653520", "event_type": "price_change"}}
{"_local_timestamp": "2026-01-25T23:44:13.665991+00:00", "data": {"market": "0xa04889441513194066b992c25607750d9ad9beda073baa231b7d6c0d296f3db4", "price_changes": [{"asset_id": "4927715355597512197888285947791839404212602020821540571091074384909522708343", "price": "0.162", "size": "20", "side": "BUY", "hash": "a2610c1aeeb6136918ef36fbc974ac30e2eb897e", "best_bid": "0.861", "best_ask": "0.985"}, {"asset_id": "38098642543471813014855148341368026538917449780662028630830591144684505089593", "price": "0.838", "size": "20", "side": "SELL", "hash": "1663f236f9f14d58c1fede28d80936adfd2ea9ba", "best_bid": "0.015", "best_ask": "0.139"}], "timestamp": "1769384653520", "event_type": "price_change"}}
{"_local_timestamp": "2026-01-25T23:44:21.533846+00:00", "data": {"market": "0x5edebf3eb73ed300d47dd35e4c3938a6997cdbf3fa3b3ca086bdd7afa3e227cc", "price_changes": [{"asset_id": "48973293128569491311605281174826846182724783049607561423479481850292050544724", "price": "0.04", "size": "1700", "side": "BUY", "hash": "fa6e08633ef46d85002e308ae993c3c20fdaad5d", "best_bid": "0.871", "best_ask": "0.988"}, {"asset_id": "47977478528993701917993634313399360833217034323739582269237365313563183735835", "price": "0.96", "size": "1700", "side": "SELL", "hash": "174750f45b138c231f2a67a5a8af75a90905624d", "best_bid": "0.012", "best_ask": "0.129"}], "timestamp": "1769384660839", "event_type": "price_change"}}
{"_local_timestamp": "2026-01-25T23:44:21.610749+00:00", "data": {"market": "0x1fed6d1346b04331b1ba1188525e560094040cbf3bbd84700c2dddb5241b2402", "price_changes": [{"asset_id": "38855512439706823591548373609888890731724800742290402025988926984750840280976", "price": "0.4", "size": "125", "side": "BUY", "hash": "57df6ed3c7ce731fe15ab67c6584fa838c023de9", "best_bid": "0.911", "best_ask": "0.99"}, {"asset_id": "71341306129608304129076187431040953407253993378796751066411893382443918679197", "price": "0.6", "size": "125", "side": "SELL", "hash": "b656b751f9355e577a076d60d98beb9465a63702", "best_bid": "0.01", "best_ask": "0.089"}], "timestamp": "1769384660850", "event_type": "price_change"}}
{"_local_timestamp": "2026-01-25T23:44:21.646246+00:00", "data": {"market": "0xa04889441513194066b992c25607750d9ad9beda073baa231b7d6c0d296f3db4", "price_changes": [{"asset_id": "4927715355597512197888285947791839404212602020821540571091074384909522708343", "price": "0.21", "size": "150", "side": "BUY", "hash": "7020167003a8dbe6b70cd9a344997a7c4bfa06af", "best_bid": "0.861", "best_ask": "0.985"}, {"asset_id": "38098642543471813014855148341368026538917449780662028630830591144684505089593", "price": "0.79", "size": "150", "side": "SELL", "hash": "69b13a7cba5d86837d5a6a5181ab757cf630214b", "best_bid": "0.015", "best_ask": "0.139"}], "timestamp": "1769384660847", "event_type": "price_change"}}
{"_local_timestamp": "2026-01-25T23:44:21.652279+00:00", "data": {"market": "0xa04889441513194066b992c25607750d9ad9beda073baa231b7d6c0d296f3db4", "price_changes": [{"asset_id": "4927715355597512197888285947791839404212602020821540571091074384909522708343", "price": "0.161", "size": "250", "side": "BUY", "hash": "d6910e624aff778007c7e96bfb0cf9b0823d46a6", "best_bid": "0.861", "best_ask": "0.985"}, {"asset_id": "38098642543471813014855148341368026538917449780662028630830591144684505089593", "price": "0.839", "size": "250", "side": "SELL", "hash": "e2c523cd13f585d70f46796c5ead527160ccd6c0", "best_bid": "0.015", "best_ask": "0.139"}], "timestamp": "1769384660950", "event_type": "price_change"}}
{"_local_timestamp": "2026-01-25T23:44:21.655827+00:00", "data": {"market": "0x5edebf3eb73ed300d47dd35e4c3938a6997cdbf3fa3b3ca086bdd7afa3e227cc", "price_changes": [{"asset_id": "48973293128569491311605281174826846182724783049607561423479481850292050544724", "price": "0.11", "size": "325", "side": "BUY", "hash": "36c311e8578fdfb14ba36c4feb0e0ed70664ed2e", "best_bid": "0.871", "best_ask": "0.988"}, {"asset_id": "47977478528993701917993634313399360833217034323739582269237365313563183735835", "price": "0.89", "size": "325", "side": "SELL", "hash": "468bc5253220aa7b0b592e443325e897781e8a15", "best_bid": "0.012", "best_ask": "0.129"}], "timestamp": "1769384660933", "event_type": "price_change"}}
{"_local_timestamp": "2026-01-25T23:44:21.659634+00:00", "data": {"market": "0x5edebf3eb73ed300d47dd35e4c3938a6997cdbf3fa3b3ca086bdd7afa3e227cc", "price_changes": [{"asset_id": "48973293128569491311605281174826846182724783049607561423479481850292050544724", "price": "0.21", "size": "100", "side": "BUY", "hash": "1b052c0d260e737989fe61c42deb49f05a6c1ebc", "best_bid": "0.871", "best_ask": "0.988"}, {"asset_id": "47977478528993701917993634313399360833217034323739582269237365313563183735835", "price": "0.79", "size": "100", "side": "SELL", "hash": "1afa2115e72b985a67e11cdf29d5ea3071791d4e", "best_bid": "0.012", "best_ask": "0.129"}], "timestamp": "1769384660971", "event_type": "price_change"}}
{"_local_timestamp": "2026-01-25T23:44:21.664796+00:00", "data": {"market": "0x5edebf3eb73ed300d47dd35e4c3938a6997cdbf3fa3b3ca086bdd7afa3e227cc", "price_changes": [{"asset_id": "48973293128569491311605281174826846182724783049607561423479481850292050544724", "price": "0.16", "size": "250", "side": "BUY", "hash": "f8c450acb48b1995ce81a6a7d10676ddf6d827da", "best_bid": "0.871", "best_ask": "0.988"}, {"asset_id": "47977478528993701917993634313399360833217034323739582269237365313563183735835", "price": "0.84", "size": "250", "side": "SELL", "hash": "6f383d9e5689d38c608514868087e46ba0d5ac25", "best_bid": "0.012", "best_ask": "0.129"}], "timestamp": "1769384660976", "event_type": "price_change"}}
{"_local_timestamp": "2026-01-25T23:44:47.631784+00:00", "data": {"market": "0x1fed6d1346b04331b1ba1188525e560094040cbf3bbd84700c2dddb5241b2402", "price_changes": [{"asset_id": "38855512439706823591548373609888890731724800742290402025988926984750840280976", "price": "0.832", "size": "0", "side": "BUY", "hash": "a66a16749d3173ea6bc768b10cc6b80f05a589bf", "best_bid": "0.911", "best_ask": "0.99"}, {"asset_id": "71341306129608304129076187431040953407253993378796751066411893382443918679197", "price": "0.168", "size": "0", "side": "SELL", "hash": "10d38881fdda967ae0fa4a7a8cff924618fd67aa", "best_bid": "0.01", "best_ask": "0.089"}], "timestamp": "1769384687469", "event_type": "price_change"}}
{"_local_timestamp": "2026-01-25T23:45:11.302460+00:00", "data": {"market": "0x77e024fc3dac13c1404f30a42d8df3b32a62978c63f82b36f62df830604471a0", "price_changes": [{"asset_id": "87132914336773401193105961480278292749054879702172274912936083065312455895521", "price": "0.002", "size": "400", "side": "BUY", "hash": "3512a9437b364e5cfbedd6bb74ae34219a453558", "best_bid": "0.006", "best_ask": "0.029"}, {"asset_id": "71885734107267615372441598160876793410818281961487005825293143068106970826321", "price": "0.998", "size": "400", "side": "SELL", "hash": "1a9b32305cd395222d9760afd48e9acc5b1af560", "best_bid": "0.971", "best_ask": "0.994"}], "timestamp": "1769384711174", "event_type": "price_change"}}
{"_local_timestamp": "2026-01-25T23:45:11.349076+00:00", "data": {"market": "0xadf6a02ac5b93901c17197de47e9c0afcc9449c6d85dec96448fa8cc90090490", "price_changes": [{"asset_id": "75870434740998190734966085726451060764959387741262916639210627595656112930617", "price": "0.002", "size": "400", "side": "BUY", "hash": "a4a5279b9cf086b25479bd5371d24fab3a46f166", "best_bid": "0.007", "best_ask": "0.029"}, {"asset_id": "107911337214497912248693530548658782366601738149965815249360222958641298955539", "price": "0.998", "size": "400", "side": "SELL", "hash": "a2433b1a787109b805039d6a724454862e92bb0b", "best_bid": "0.971", "best_ask": "0.993"}], "timestamp": "1769384711199", "event_type": "price_change"}}
{"_local_timestamp": "2026-01-25T23:45:11.353788+00:00", "data": {"market": "0x1fed6d1346b04331b1ba1188525e560094040cbf3bbd84700c2dddb5241b2402", "price_changes": [{"asset_id": "71341306129608304129076187431040953407253993378796751066411893382443918679197", "price": "0.002", "size": "550", "side": "BUY", "hash": "74fa27c8c84baaf164092a935b9d878957eed746", "best_bid": "0.01", "best_ask": "0.089"}, {"asset_id": "38855512439706823591548373609888890731724800742290402025988926984750840280976", "price": "0.998", "size": "550", "side": "SELL", "hash": "7b2ab84a615f5acf34df65b937447b861c6e4f43", "best_bid": "0.911", "best_ask": "0.99"}], "timestamp": "1769384711196", "event_type": "price_change"}}
{"_local_timestamp": "2026-01-25T23:45:11.356383+00:00", "data": {"market": "0x105658ed412868eff64622ff122b425042797cb1886ac13bba10627cb395b3a0", "price_changes": [{"asset_id": "42623828760560956825816893329368389610613334458449432332189049581423522261963", "price": "0.002", "size": "400", "side": "BUY", "hash": "0ee39647cc0246c881e9c3730b8f29c682cbfb06", "best_bid": "0.009", "best_ask": "0.03"}, {"asset_id": "62389192985532225428000072411944560217557819885493029090152096982024014976363", "price": "0.998", "size": "400", "side": "SELL", "hash": "c4253a0b9025ec36c991d5d6690ac94fc245da9b", "best_bid": "0.97", "best_ask": "0.991"}], "timestamp": "1769384711191", "event_type": "price_change"}}
{"_local_timestamp": "2026-01-25T23:45:11.360126+00:00", "data": {"market": "0xd3aa6ab9adcf1d7189a287e6a86dd2ae378fa7a635863f7d249ce70a1f28395e", "price_changes": [{"asset_id": "5525740420504230154399891807905567389393779493359335912984255288237335578501", "price": "0.002", "size": "400", "side": "BUY", "hash": "0f27c8000aee97080d05ff0accfee88c2674053f", "best_bid": "0.006", "best_ask": "0.032"}, {"asset_id": "17621949038627205799005149654166056280336330529029840823213885378726883921449", "price": "0.998", "size": "400", "side": "SELL", "hash": "7f36836207cb5619b7ed32c6a7f1308ee4f36981", "best_bid": "0.968", "best_ask": "0.994"}], "timestamp": "1769384711199", "event_type": "price_change"}}
{"_local_timestamp": "2026-01-25T23:45:11.361750+00:00", "data": {"market": "0x5edebf3eb73ed300d47dd35e4c3938a6997cdbf3fa3b3ca086bdd7afa3e227cc", "price_changes": [{"asset_id": "47977478528993701917993634313399360833217034323739582269237365313563183735835", "price": "0.002", "size": "476.86", "side": "BUY", "hash": "aec01011fa19f6dbba89a7b58759b53db3493777", "best_bid": "0.012", "best_ask": "0.129"}, {"asset_id": "48973293128569491311605281174826846182724783049607561423479481850292050544724", "price": "0.998", "size": "476.86", "side": "SELL", "hash": "77ce4fcfbb3e77514fe1a193da36cc0bceef86a6", "best_bid": "0.871", "best_ask": "0.988"}], "timestamp": "1769384711199", "event_type": "price_change"}}
{"_local_timestamp": "2026-01-25T23:45:18.613636+00:00", "data": {"market": "0x1fed6d1346b04331b1ba1188525e560094040cbf3bbd84700c2dddb5241b2402", "price_changes": [{"asset_id": "71341306129608304129076187431040953407253993378796751066411893382443918679197", "price": "0.089", "size": "0", "side": "SELL", "hash": "b19391faaecff54d24dd0fdf1eab4589311a2516", "best_bid": "0.01", "best_ask": "0.17"}, {"asset_id": "38855512439706823591548373609888890731724800742290402025988926984750840280976", "price": "0.911", "size": "0", "side": "BUY", "hash": "e4485e567ab67f8cd1c3753b4a95e51c02289a71", "best_bid": "0.83", "best_ask": "0.99"}], "timestamp": "1769384718543", "event_type": "price_change"}}
{"_local_timestamp": "2026-01-25T23:45:19.130898+00:00", "data": {"market": "0x5edebf3eb73ed300d47dd35e4c3938a6997cdbf3fa3b3ca086bdd7afa3e227cc", "price_changes": [{"asset_id": "47977478528993701917993634313399360833217034323739582269237365313563183735835", "price": "0.129", "size": "0", "side": "SELL", "hash": "c5a4295a9a540d1f3a443f33d1083a04d827ca95", "best_bid": "0.012", "best_ask": "0.534"}, {"asset_id": "48973293128569491311605281174826846182724783049607561423479481850292050544724", "price": "0.871", "size": "0", "side": "BUY", "hash": "46508747a7fb8000b1c7c483bdddfd01e11f1548", "best_bid": "0.466", "best_ask": "0.988"}], "timestamp": "1769384719032", "event_type": "price_change"}}
{"_local_timestamp": "2026-01-25T23:45:19.138076+00:00", "data": {"market": "0xa04889441513194066b992c25607750d9ad9beda073baa231b7d6c0d296f3db4", "price_changes": [{"asset_id": "38098642543471813014855148341368026538917449780662028630830591144684505089593", "price": "0.139", "size": "0", "side": "SELL", "hash": "5623ee4e453b4eeb36e06919ef34fc6fbc28a286", "best_bid": "0.015", "best_ask": "0.488"}, {"asset_id": "4927715355597512197888285947791839404212602020821540571091074384909522708343", "price": "0.861", "size": "0", "side": "BUY", "hash": "9bd323d44b011315bb947df5ccb11ca272f4bee7", "best_bid": "0.512", "best_ask": "0.985"}], "timestamp": "1769384719032", "event_type": "price_change"}}
{"_local_timestamp": "2026-01-25T23:45:19.162723+00:00", "data": {"market": "0x1fed6d1346b04331b1ba1188525e560094040cbf3bbd84700c2dddb5241b2402", "price_changes": [{"asset_id": "38855512439706823591548373609888890731724800742290402025988926984750840280976", "price": "0.3", "size": "0", "side": "BUY", "hash": "7f8879fb45412e5662ad4d5d1e736acb9f1ddf16", "best_bid": "0.83", "best_ask": "0.99"}, {"asset_id": "71341306129608304129076187431040953407253993378796751066411893382443918679197", "price": "0.7", "size": "0", "side": "SELL", "hash": "5c09297b69c6c415d6d8d543a315de4e73d4ceb4", "best_bid": "0.01", "best_ask": "0.17"}], "timestamp": "1769384719063", "event_type": "price_change"}}
{"_local_timestamp": "2026-01-25T23:45:19.163780+00:00", "data": {"market": "0x1fed6d1346b04331b1ba1188525e560094040cbf3bbd84700c2dddb5241b2402", "price_changes": [{"asset_id": "38855512439706823591548373609888890731724800742290402025988926984750840280976", "price": "0.35", "size": "0", "side": "BUY", "hash": "7f8879fb45412e5662ad4d5d1e736acb9f1ddf16", "best_bid": "0.83", "best_ask": "0.99"}, {"asset_id": "71341306129608304129076187431040953407253993378796751066411893382443918679197", "price": "0.65", "size": "0", "side": "SELL", "hash": "5c09297b69c6c415d6d8d543a315de4e73d4ceb4", "best_bid": "0.01", "best_ask": "0.17"}], "timestamp": "1769384719063", "event_type": "price_change"}}
{"_local_timestamp": "2026-01-25T23:45:19.164799+00:00", "data": {"market": "0x1fed6d1346b04331b1ba1188525e560094040cbf3bbd84700c2dddb5241b2402", "price_changes": [{"asset_id": "38855512439706823591548373609888890731724800742290402025988926984750840280976", "price": "0.2", "size": "250", "side": "BUY", "hash": "7f8879fb45412e5662ad4d5d1e736acb9f1ddf16", "best_bid": "0.83", "best_ask": "0.99"}, {"asset_id": "71341306129608304129076187431040953407253993378796751066411893382443918679197", "price": "0.8", "size": "250", "side": "SELL", "hash": "5c09297b69c6c415d6d8d543a315de4e73d4ceb4", "best_bid": "0.01", "best_ask": "0.17"}], "timestamp": "1769384719063", "event_type": "price_change"}}
{"_local_timestamp": "2026-01-25T23:45:19.172405+00:00", "data": {"market": "0x1fed6d1346b04331b1ba1188525e560094040cbf3bbd84700c2dddb5241b2402", "price_changes": [{"asset_id": "38855512439706823591548373609888890731724800742290402025988926984750840280976", "price": "0.1", "size": "200", "side": "BUY", "hash": "7f8879fb45412e5662ad4d5d1e736acb9f1ddf16", "best_bid": "0.83", "best_ask": "0.99"}, {"asset_id": "71341306129608304129076187431040953407253993378796751066411893382443918679197", "price": "0.9", "size": "200", "side": "SELL", "hash": "5c09297b69c6c415d6d8d543a315de4e73d4ceb4", "best_bid": "0.01", "best_ask": "0.17"}], "timestamp": "1769384719063", "event_type": "price_change"}}
{"_local_timestamp": "2026-01-25T23:45:19.173464+00:00", "data": {"market": "0x1fed6d1346b04331b1ba1188525e560094040cbf3bbd84700c2dddb5241b2402", "price_changes": [{"asset_id": "38855512439706823591548373609888890731724800742290402025988926984750840280976", "price": "0.15", "size": "325", "side": "BUY", "hash": "7f8879fb45412e5662ad4d5d1e736acb9f1ddf16", "best_bid": "0.83", "best_ask": "0.99"}, {"asset_id": "71341306129608304129076187431040953407253993378796751066411893382443918679197", "price": "0.85", "size": "325", "side": "SELL", "hash": "5c09297b69c6c415d6d8d543a315de4e73d4ceb4", "best_bid": "0.01", "best_ask": "0.17"}], "timestamp": "1769384719063", "event_type": "price_change"}}
{"_local_timestamp": "2026-01-25T23:45:19.174561+00:00", "data": {"market": "0x1fed6d1346b04331b1ba1188525e560094040cbf3bbd84700c2dddb5241b2402", "price_changes": [{"asset_id": "38855512439706823591548373609888890731724800742290402025988926984750840280976", "price": "0.4", "size": "75", "side": "BUY", "hash": "7f8879fb45412e5662ad4d5d1e736acb9f1ddf16", "best_bid": "0.83", "best_ask": "0.99"}, {"asset_id": "71341306129608304129076187431040953407253993378796751066411893382443918679197", "price": "0.6", "size": "75", "side": "SELL", "hash": "5c09297b69c6c415d6d8d543a315de4e73d4ceb4", "best_bid": "0.01", "best_ask": "0.17"}], "timestamp": "1769384719063", "event_type": "price_change"}}
{"_local_timestamp": "2026-01-25T23:45:19.175548+00:00", "data": {"market": "0x1fed6d1346b04331b1ba1188525e560094040cbf3bbd84700c2dddb5241b2402", "price_changes": [{"asset_id": "38855512439706823591548373609888890731724800742290402025988926984750840280976", "price": "0.25", "size": "150", "side": "BUY", "hash": "7f8879fb45412e5662ad4d5d1e736acb9f1ddf16", "best_bid": "0.83", "best_ask": "0.99"}, {"asset_id": "71341306129608304129076187431040953407253993378796751066411893382443918679197", "price": "0.75", "size": "150", "side": "SELL", "hash": "5c09297b69c6c415d6d8d543a315de4e73d4ceb4", "best_bid": "0.01", "best_ask": "0.17"}], "timestamp": "1769384719063", "event_type": "price_change"}}
{"_local_timestamp": "2026-01-25T23:45:19.186972+00:00", "data": {"market": "0x1fed6d1346b04331b1ba1188525e560094040cbf3bbd84700c2dddb5241b2402", "price_changes": [{"asset_id": "38855512439706823591548373609888890731724800742290402025988926984750840280976", "price": "0.302", "size": "45", "side": "BUY", "hash": "df975e605f839a326026b0e7dc8418d90ae640cd", "best_bid": "0.83", "best_ask": "0.99"}, {"asset_id": "71341306129608304129076187431040953407253993378796751066411893382443918679197", "price": "0.698", "size": "45", "side": "SELL", "hash": "e3706da776f0916804c24173e95954aa4c4c6895", "best_bid": "0.01", "best_ask": "0.17"}], "timestamp": "1769384719112", "event_type": "price_change"}}
{"_local_timestamp": "2026-01-25T23:45:19.622276+00:00", "data": {"market": "0x1fed6d1346b04331b1ba1188525e560094040cbf3bbd84700c2dddb5241b2402", "price_changes": [{"asset_id": "71341306129608304129076187431040953407253993378796751066411893382443918679197", "price": "0.169", "size": "39.87", "side": "SELL", "hash": "2a8fb9669fa411cde31f374a51bc481a81d937cb", "best_bid": "0.01", "best_ask": "0.169"}, {"asset_id": "38855512439706823591548373609888890731724800742290402025988926984750840280976", "price": "0.831", "size": "39.87", "side": "BUY", "hash": "4b424f1766048426dc414ab2afdd443e7b596594", "best_bid": "0.831", "best_ask": "0.99"}], "timestamp": "1769384719546", "event_type": "price_change"}}
{"_local_timestamp": "2026-01-25T23:45:20.118491+00:00", "data": {"market": "0x5edebf3eb73ed300d47dd35e4c3938a6997cdbf3fa3b3ca086bdd7afa3e227cc", "price_changes": [{"asset_id": "47977478528993701917993634313399360833217034323739582269237365313563183735835", "price": "0.533", "size": "10", "side": "SELL", "hash": "ff93b0bf901707359624f9e33f3098d26645b6c2", "best_bid": "0.012", "best_ask": "0.533"}, {"asset_id": "48973293128569491311605281174826846182724783049607561423479481850292050544724", "price": "0.467", "size": "10", "side": "BUY", "hash": "1905a8de09fec730cd854e5c7e9894ebb31c5290", "best_bid": "0.467", "best_ask": "0.988"}], "timestamp": "1769384720033", "event_type": "price_change"}}
{"_local_timestamp": "2026-01-25T23:45:20.119843+00:00", "data": {"market": "0xa04889441513194066b992c25607750d9ad9beda073baa231b7d6c0d296f3db4", "price_changes": [{"asset_id": "38098642543471813014855148341368026538917449780662028630830591144684505089593", "price": "0.487", "size": "10", "side": "SELL", "hash": "dc3853121e75e83b2f5e4b709a4fc47e9e1126f3", "best_bid": "0.015", "best_ask": "0.487"}, {"asset_id": "4927715355597512197888285947791839404212602020821540571091074384909522708343", "price": "0.513", "size": "10", "side": "BUY", "hash": "8bdcf9344f2c6a1f78b8c45c12e75fa1d1fc4b6e", "best_bid": "0.513", "best_ask": "0.985"}], "timestamp": "1769384720033", "event_type": "price_change"}}
{"_local_timestamp": "2026-01-25T23:45:25.351601+00:00", "data": {"market": "0x1fed6d1346b04331b1ba1188525e560094040cbf3bbd84700c2dddb5241b2402", "price_changes": [{"asset_id": "38855512439706823591548373609888890731724800742290402025988926984750840280976", "price": "0.302", "size": "0", "side": "BUY", "hash": "3486f6500c6ff1bcbb9bd34f40fc519110111624", "best_bid": "0.831", "best_ask": "0.99"}, {"asset_id": "71341306129608304129076187431040953407253993378796751066411893382443918679197", "price": "0.698", "size": "0", "side": "SELL", "hash": "77d33fffdb84795a58b77cdf1448b2765343abc1", "best_bid": "0.01", "best_ask": "0.169"}], "timestamp": "1769384725277", "event_type": "price_change"}}
{"_local_timestamp": "2026-01-25T23:45:33.342633+00:00", "data": {"market": "0x5edebf3eb73ed300d47dd35e4c3938a6997cdbf3fa3b3ca086bdd7afa3e227cc", "price_changes": [{"asset_id": "48973293128569491311605281174826846182724783049607561423479481850292050544724", "price": "0.07", "size": "200", "side": "BUY", "hash": "d7299a6dfae7f63cfdf93613bad24f4938efb53e", "best_bid": "0.467", "best_ask": "0.988"}, {"asset_id": "47977478528993701917993634313399360833217034323739582269237365313563183735835", "price": "0.93", "size": "200", "side": "SELL", "hash": "7de4ff8d04de29c8bc1a307b939151ed7999210a", "best_bid": "0.012", "best_ask": "0.533"}], "timestamp": "1769384733268", "event_type": "price_change"}}
{"_local_timestamp": "2026-01-25T23:45:34.987997+00:00", "data": {"market": "0x105658ed412868eff64622ff122b425042797cb1886ac13bba10627cb395b3a0", "price_changes": [{"asset_id": "42623828760560956825816893329368389610613334458449432332189049581423522261963", "price": "0.009", "size": "120", "side": "BUY", "hash": "be3679a283eb24976a0cd22641426040b2a317ed", "best_bid": "0.009", "best_ask": "0.03"}, {"asset_id": "62389192985532225428000072411944560217557819885493029090152096982024014976363", "price": "0.991", "size": "120", "side": "SELL", "hash": "b7fec101a37ea2f4993a366ba4beab4dd6fa7a51", "best_bid": "0.97", "best_ask": "0.991"}], "timestamp": "1769384734917", "event_type": "price_change"}}
{"_local_timestamp": "2026-01-25T23:45:35.255022+00:00", "data": {"market": "0x105658ed412868eff64622ff122b425042797cb1886ac13bba10627cb395b3a0", "price_changes": [{"asset_id": "42623828760560956825816893329368389610613334458449432332189049581423522261963", "price": "0.007", "size": "330", "side": "BUY", "hash": "76c5715fd78ba33fa960753cd8ad634c489edcc9", "best_bid": "0.009", "best_ask": "0.03"}, {"asset_id": "62389192985532225428000072411944560217557819885493029090152096982024014976363", "price": "0.993", "size": "330", "side": "SELL", "hash": "b4f6e0b0c7ec6d2778d084a6bdbcd2466a927efa", "best_bid": "0.97", "best_ask": "0.991"}], "timestamp": "1769384735173", "event_type": "price_change"}}
{"_local_timestamp": "2026-01-25T23:45:37.343206+00:00", "data": {"market": "0xe1730ddaa88ffb2fb360af9f5b58c9e427f61c30712578b1701408911e3f655d", "price_changes": [{"asset_id": "37042473221634168250099193554902520956898907103252140530642497138603218091624", "price": "0.18", "size": "121.66", "side": "BUY", "hash": "e9221a86c1e69be559615818e17bfc690522a025", "best_bid": "0.18", "best_ask": "0.91"}, {"asset_id": "81699282895973617782040895594229616523859617972840387954210064871270448792972", "price": "0.82", "size": "121.66", "side": "SELL", "hash": "905f381b7d27af97255499ae617d38b7630ef1d4", "best_bid": "0.09", "best_ask": "0.82"}], "timestamp": "1769384737270", "event_type": "price_change"}}
{"_local_timestamp": "2026-01-25T23:45:39.299320+00:00", "data": {"market": "0xa04889441513194066b992c25607750d9ad9beda073baa231b7d6c0d296f3db4", "price_changes": [{"asset_id": "4927715355597512197888285947791839404212602020821540571091074384909522708343", "price": "0.86", "size": "50", "side": "BUY", "hash": "9d086ca864f5690b5799513410964e92cba6d140", "best_bid": "0.86", "best_ask": "0.985"}, {"asset_id": "38098642543471813014855148341368026538917449780662028630830591144684505089593", "price": "0.14", "size": "50", "side": "SELL", "hash": "d13d6c28180eeaa80b330e4afdacc2bfc4f0f32b", "best_bid": "0.015", "best_ask": "0.14"}], "timestamp": "1769384739204", "event_type": "price_change"}}
{"_local_timestamp": "2026-01-25T23:45:39.300424+00:00", "data": {"market": "0x5edebf3eb73ed300d47dd35e4c3938a6997cdbf3fa3b3ca086bdd7afa3e227cc", "price_changes": [{"asset_id": "48973293128569491311605281174826846182724783049607561423479481850292050544724", "price": "0.87", "size": "50", "side": "BUY", "hash": "14146473896a6808b3eab4f8dfea1fafccb0fd34", "best_bid": "0.87", "best_ask": "0.988"}, {"asset_id": "47977478528993701917993634313399360833217034323739582269237365313563183735835", "price": "0.13", "size": "50", "side": "SELL", "hash": "333d6ad2f677737274bc9cb2c1ff8f0fa8ec7fd3", "best_bid": "0.012", "best_ask": "0.13"}], "timestamp": "1769384739204", "event_type": "price_change"}}
{"_local_timestamp": "2026-01-25T23:45:39.301428+00:00", "data": {"market": "0x1fed6d1346b04331b1ba1188525e560094040cbf3bbd84700c2dddb5241b2402", "price_changes": [{"asset_id": "38855512439706823591548373609888890731724800742290402025988926984750840280976", "price": "0.91", "size": "50", "side": "BUY", "hash": "8614ee05d7d26eaac079603ebf87478009119d8b", "best_bid": "0.91", "best_ask": "0.99"}, {"asset_id": "71341306129608304129076187431040953407253993378796751066411893382443918679197", "price": "0.09", "size": "50", "side": "SELL", "hash": "8e44837fdd650c9a660522c48f654b8d16b1a78f", "best_bid": "0.01", "best_ask": "0.09"}], "timestamp": "1769384739204", "event_type": "price_change"}}
{"_local_timestamp": "2026-01-25T23:45:46.274926+00:00", "data": {"market": "0xbf6fbc35082962002b61f17e26820db124930ac43175934864e34a415ee40620", "price_changes": [{"asset_id": "42674776176570186449325309200969258771704155869979743437343764984621699243894", "price": "0.52", "size": "9.61", "side": "BUY", "hash": "bb08d34078cdc2672109ed4a79b6aabcd3e96b54", "best_bid": "0.52", "best_ask": "0.94"}, {"asset_id": "98673773007855046568692125013481059419674479536813359840428477180250006155633", "price": "0.48", "size": "9.61", "side": "SELL", "hash": "d9a64654962779a55bdf643c26169931ea6601ce", "best_bid": "0.06", "best_ask": "0.48"}], "timestamp": "1769384746209", "event_type": "price_change"}}
{"_local_timestamp": "2026-01-25T23:45:53.196619+00:00", "data": {"market": "0x5edebf3eb73ed300d47dd35e4c3938a6997cdbf3fa3b3ca086bdd7afa3e227cc", "price_changes": [{"asset_id": "48973293128569491311605281174826846182724783049607561423479481850292050544724", "price": "0.16", "size": "150", "side": "BUY", "hash": "932eb867b571cc0a54e8772309cabe150a3f4915", "best_bid": "0.87", "best_ask": "0.988"}, {"asset_id": "47977478528993701917993634313399360833217034323739582269237365313563183735835", "price": "0.84", "size": "150", "side": "SELL", "hash": "9c139140948db84f748c5ddc64e120bc11c11721", "best_bid": "0.012", "best_ask": "0.13"}], "timestamp": "1769384753012", "event_type": "price_change"}}
{"_local_timestamp": "2026-01-25T23:45:53.205219+00:00", "data": {"market": "0xa04889441513194066b992c25607750d9ad9beda073baa231b7d6c0d296f3db4", "price_changes": [{"asset_id": "4927715355597512197888285947791839404212602020821540571091074384909522708343", "price": "0.21", "size": "100", "side": "BUY", "hash": "01b31c5385cdc55c82fb5489a0466ee72a4df754", "best_bid": "0.86", "best_ask": "0.985"}, {"asset_id": "38098642543471813014855148341368026538917449780662028630830591144684505089593", "price": "0.79", "size": "100", "side": "SELL", "hash": "929f2ae03d98ee7e94ddda936122b003800ad971", "best_bid": "0.015", "best_ask": "0.14"}], "timestamp": "1769384753013", "event_type": "price_change"}}
{"_local_timestamp": "2026-01-25T23:45:53.206257+00:00", "data": {"market": "0xa04889441513194066b992c25607750d9ad9beda073baa231b7d6c0d296f3db4", "price_changes": [{"asset_id": "4927715355597512197888285947791839404212602020821540571091074384909522708343", "price": "0.161", "size": "150", "side": "BUY", "hash": "01b31c5385cdc55c82fb5489a0466ee72a4df754", "best_bid": "0.86", "best_ask": "0.985"}, {"asset_id": "38098642543471813014855148341368026538917449780662028630830591144684505089593", "price": "0.839", "size": "150", "side": "SELL", "hash": "929f2ae03d98ee7e94ddda936122b003800ad971", "best_bid": "0.015", "best_ask": "0.14"}], "timestamp": "1769384753013", "event_type": "price_change"}}
{"_local_timestamp": "2026-01-25T23:45:56.306242+00:00", "data": {"market": "0x5edebf3eb73ed300d47dd35e4c3938a6997cdbf3fa3b3ca086bdd7afa3e227cc", "price_changes": [{"asset_id": "48973293128569491311605281174826846182724783049607561423479481850292050544724", "price": "0.382", "size": "0", "side": "BUY", "hash": "2b50742719872a240cdf9d4b1d7c0df7b36be4c9", "best_bid": "0.87", "best_ask": "0.988"}, {"asset_id": "47977478528993701917993634313399360833217034323739582269237365313563183735835", "price": "0.618", "size": "0", "side": "SELL", "hash": "2e9e80bde02c9621fc6cf6b4caff276f1791fcb4", "best_bid": "0.012", "best_ask": "0.13"}], "timestamp": "1769384756074", "event_type": "price_change"}}
{"_local_timestamp": "2026-01-25T23:45:56.747745+00:00", "data": {"market": "0x1fed6d1346b04331b1ba1188525e560094040cbf3bbd84700c2dddb5241b2402", "price_changes": [{"asset_id": "38855512439706823591548373609888890731724800742290402025988926984750840280976", "price": "0.424", "size": "0", "side": "BUY", "hash": "e9a20eea4c20a634be92a7b21217e14325e487a4", "best_bid": "0.91", "best_ask": "0.99"}, {"asset_id": "71341306129608304129076187431040953407253993378796751066411893382443918679197", "price": "0.576", "size": "0", "side": "SELL", "hash": "50ec747f75cf888f227a5869ebfbe6e941bc56ba", "best_bid": "0.01", "best_ask": "0.09"}], "timestamp": "1769384756096", "event_type": "price_change"}}
{"_local_timestamp": "2026-01-25T23:45:56.773774+00:00", "data": {"market": "0xadf6a02ac5b93901c17197de47e9c0afcc9449c6d85dec96448fa8cc90090490", "price_changes": [{"asset_id": "107911337214497912248693530548658782366601738149965815249360222958641298955539", "price": "0.424", "size": "60", "side": "BUY", "hash": "4699151a7a62c6da4a6a03d9860321bfd76ea484", "best_bid": "0.971", "best_ask": "0.993"}, {"asset_id": "75870434740998190734966085726451060764959387741262916639210627595656112930617", "price": "0.576", "size": "60", "side": "SELL", "hash": "3ffe8ca66fe98aa16f03cf40526584eac2239031", "best_bid": "0.007", "best_ask": "0.029"}], "timestamp": "1769384756097", "event_type": "price_change"}}
{"_local_timestamp": "2026-01-25T23:46:28.565479+00:00", "data": {"market": "0xadf6a02ac5b93901c17197de47e9c0afcc9449c6d85dec96448fa8cc90090490", "price_changes": [{"asset_id": "107911337214497912248693530548658782366601738149965815249360222958641298955539", "price": "0.301", "size": "168", "side": "BUY", "hash": "bd362f4e4f1fe008f12a4e0d78229e5334e8716f", "best_bid": "0.971", "best_ask": "0.993"}, {"asset_id": "75870434740998190734966085726451060764959387741262916639210627595656112930617", "price": "0.699", "size": "168", "side": "SELL", "hash": "ffd5b9200a4676d3c14e167fa4c0aaa184387177", "best_bid": "0.007", "best_ask": "0.029"}], "timestamp": "1769384788486", "event_type": "price_change"}}
{"_local_timestamp": "2026-01-25T23:46:28.571893+00:00", "data": {"market": "0x1fed6d1346b04331b1ba1188525e560094040cbf3bbd84700c2dddb5241b2402", "price_changes": [{"asset_id": "38855512439706823591548373609888890731724800742290402025988926984750840280976", "price": "0.302", "size": "50", "side": "BUY", "hash": "bf67f1e4476d814bf5ee1ad01e48d4a892fa3da7", "best_bid": "0.91", "best_ask": "0.99"}, {"asset_id": "71341306129608304129076187431040953407253993378796751066411893382443918679197", "price": "0.698", "size": "50", "side": "SELL", "hash": "7e7b4bb8243d6d26cbdea36f09db8c194281441a", "best_bid": "0.01", "best_ask": "0.09"}], "timestamp": "1769384788488", "event_type": "price_change"}}
{"_local_timestamp": "2026-01-25T23:46:28.573590+00:00", "data": {"market": "0x5edebf3eb73ed300d47dd35e4c3938a6997cdbf3fa3b3ca086bdd7afa3e227cc", "price_changes": [{"asset_id": "48973293128569491311605281174826846182724783049607561423479481850292050544724", "price": "0.211", "size": "50", "side": "BUY", "hash": "820ef788e85c132ab0b94f6c19a3591133459b85", "best_bid": "0.87", "best_ask": "0.988"}, {"asset_id": "47977478528993701917993634313399360833217034323739582269237365313563183735835", "price": "0.789", "size": "50", "side": "SELL", "hash": "a75fbfcda85470a353c4167179d5b8390116d17a", "best_bid": "0.012", "best_ask": "0.13"}], "timestamp": "1769384788489", "event_type": "price_change"}}
{"_local_timestamp": "2026-01-25T23:46:32.728684+00:00", "data": {"market": "0xa04889441513194066b992c25607750d9ad9beda073baa231b7d6c0d296f3db4", "price_changes": [{"asset_id": "4927715355597512197888285947791839404212602020821540571091074384909522708343", "price": "0.486", "size": "0", "side": "BUY", "hash": "44d1c810c643097d529af6e1a9a1f820cc348e45", "best_bid": "0.86", "best_ask": "0.985"}, {"asset_id": "38098642543471813014855148341368026538917449780662028630830591144684505089593", "price": "0.514", "size": "0", "side": "SELL", "hash": "73055e665491e72c7a3dbcf9dc5c10d042f4cfda", "best_bid": "0.015", "best_ask": "0.14"}], "timestamp": "1769384792651", "event_type": "price_change"}}
{"_local_timestamp": "2026-01-25T23:46:32.729787+00:00", "data": {"market": "0xa04889441513194066b992c25607750d9ad9beda073baa231b7d6c0d296f3db4", "price_changes": [{"asset_id": "4927715355597512197888285947791839404212602020821540571091074384909522708343", "price": "0.11", "size": "325", "side": "BUY", "hash": "44d1c810c643097d529af6e1a9a1f820cc348e45", "best_bid": "0.86", "best_ask": "0.985"}, {"asset_id": "38098642543471813014855148341368026538917449780662028630830591144684505089593", "price": "0.89", "size": "325", "side": "SELL", "hash": "73055e665491e72c7a3dbcf9dc5c10d042f4cfda", "best_bid": "0.015", "best_ask": "0.14"}], "timestamp": "1769384792651", "event_type": "price_change"}}
{"_local_timestamp": "2026-01-25T23:46:32.730812+00:00", "data": {"market": "0x5edebf3eb73ed300d47dd35e4c3938a6997cdbf3fa3b3ca086bdd7afa3e227cc", "price_changes": [{"asset_id": "48973293128569491311605281174826846182724783049607561423479481850292050544724", "price": "0.466", "size": "0", "side": "BUY", "hash": "53ac41d0c5d9f5acc3a9597cbe04a1a0a4992910", "best_bid": "0.87", "best_ask": "0.988"}, {"asset_id": "47977478528993701917993634313399360833217034323739582269237365313563183735835", "price": "0.534", "size": "0", "side": "SELL", "hash": "a65357b1918708bf8904f55bb9a2fa90c9a4ffa5", "best_bid": "0.012", "best_ask": "0.13"}], "timestamp": "1769384792651", "event_type": "price_change"}}
{"_local_timestamp": "2026-01-25T23:46:32.731796+00:00", "data": {"market": "0xbf6fbc35082962002b61f17e26820db124930ac43175934864e34a415ee40620", "price_changes": [{"asset_id": "42674776176570186449325309200969258771704155869979743437343764984621699243894", "price": "0.51", "size": "0", "side": "BUY", "hash": "7139afe5742bb4585d6f070c00affc9da5002980", "best_bid": "0.52", "best_ask": "0.94"}, {"asset_id": "98673773007855046568692125013481059419674479536813359840428477180250006155633", "price": "0.49", "size": "0", "side": "SELL", "hash": "6baa98082a7711d11e88f61bc661200fe9485baf", "best_bid": "0.06", "best_ask": "0.48"}], "timestamp": "1769384792651", "event_type": "price_change"}}
{"_local_timestamp": "2026-01-25T23:46:32.732794+00:00", "data": {"market": "0x5edebf3eb73ed300d47dd35e4c3938a6997cdbf3fa3b3ca086bdd7afa3e227cc", "price_changes": [{"asset_id": "48973293128569491311605281174826846182724783049607561423479481850292050544724", "price": "0.061", "size": "0", "side": "BUY", "hash": "53ac41d0c5d9f5acc3a9597cbe04a1a0a4992910", "best_bid": "0.87", "best_ask": "0.988"}, {"asset_id": "47977478528993701917993634313399360833217034323739582269237365313563183735835", "price": "0.939", "size": "0", "side": "SELL", "hash": "a65357b1918708bf8904f55bb9a2fa90c9a4ffa5", "best_bid": "0.012", "best_ask": "0.13"}], "timestamp": "1769384792651", "event_type": "price_change"}}
{"_local_timestamp": "2026-01-25T23:46:32.733773+00:00", "data": {"market": "0x1fed6d1346b04331b1ba1188525e560094040cbf3bbd84700c2dddb5241b2402", "price_changes": [{"asset_id": "38855512439706823591548373609888890731724800742290402025988926984750840280976", "price": "0.606", "size": "0", "side": "BUY", "hash": "122786955de93914c3757ffbd967310d95cd5a46", "best_bid": "0.91", "best_ask": "0.99"}, {"asset_id": "71341306129608304129076187431040953407253993378796751066411893382443918679197", "price": "0.394", "size": "0", "side": "SELL", "hash": "ceb38402d70892a02b537b0147d19216d4479e9f", "best_bid": "0.01", "best_ask": "0.09"}], "timestamp": "1769384792652", "event_type": "price_change"}}
{"_local_timestamp": "2026-01-25T23:46:32.734754+00:00", "data": {"market": "0x1fed6d1346b04331b1ba1188525e560094040cbf3bbd84700c2dddb5241b2402", "price_changes": [{"asset_id": "38855512439706823591548373609888890731724800742290402025988926984750840280976", "price": "0.301", "size": "0", "side": "BUY", "hash": "122786955de93914c3757ffbd967310d95cd5a46", "best_bid": "0.91", "best_ask": "0.99"}, {"asset_id": "71341306129608304129076187431040953407253993378796751066411893382443918679197", "price": "0.699", "size": "0", "side": "SELL", "hash": "ceb38402d70892a02b537b0147d19216d4479e9f", "best_bid": "0.01", "best_ask": "0.09"}], "timestamp": "1769384792652", "event_type": "price_change"}}
{"_local_timestamp": "2026-01-25T23:46:32.735778+00:00", "data": {"market": "0x1fed6d1346b04331b1ba1188525e560094040cbf3bbd84700c2dddb5241b2402", "price_changes": [{"asset_id": "71341306129608304129076187431040953407253993378796751066411893382443918679197", "price": "0.004", "size": "200", "side": "BUY", "hash": "7f526f7541e062cd3e3c1070c85dd989d73bfe6c", "best_bid": "0.01", "best_ask": "0.09"}, {"asset_id": "38855512439706823591548373609888890731724800742290402025988926984750840280976", "price": "0.996", "size": "200", "side": "SELL", "hash": "8e3e1757f2e002cb0d262fc6a3d2b84c01390e3a", "best_bid": "0.91", "best_ask": "0.99"}], "timestamp": "1769384792652", "event_type": "price_change"}}
{"_local_timestamp": "2026-01-25T23:46:33.496003+00:00", "data": {"market": "0x1fed6d1346b04331b1ba1188525e560094040cbf3bbd84700c2dddb5241b2402", "price_changes": [{"asset_id": "38855512439706823591548373609888890731724800742290402025988926984750840280976", "price": "0.251", "size": "100", "side": "BUY", "hash": "4301c13c3eb0f4027cb56fc0e81172bb94b37c46", "best_bid": "0.91", "best_ask": "0.99"}, {"asset_id": "71341306129608304129076187431040953407253993378796751066411893382443918679197", "price": "0.749", "size": "100", "side": "SELL", "hash": "0459d6b94d396404f1b8cc4c5e3e30647b67c1f0", "best_bid": "0.01", "best_ask": "0.09"}], "timestamp": "1769384793290", "event_type": "price_change"}}
{"_local_timestamp": "2026-01-25T23:46:33.497249+00:00", "data": {"market": "0xa04889441513194066b992c25607750d9ad9beda073baa231b7d6c0d296f3db4", "price_changes": [{"asset_id": "4927715355597512197888285947791839404212602020821540571091074384909522708343", "price": "0.511", "size": "100", "side": "BUY", "hash": "36f23533f19f482575cb9f3a6553bf5ecbf03da2", "best_bid": "0.86", "best_ask": "0.985"}, {"asset_id": "38098642543471813014855148341368026538917449780662028630830591144684505089593", "price": "0.489", "size": "100", "side": "SELL", "hash": "d658d54efba90645d1f412566c26e69c4fde286e", "best_bid": "0.015", "best_ask": "0.14"}], "timestamp": "1769384793345", "event_type": "price_change"}}
{"_local_timestamp": "2026-01-25T23:46:33.498747+00:00", "data": {"market": "0xbf6fbc35082962002b61f17e26820db124930ac43175934864e34a415ee40620", "price_changes": [{"asset_id": "42674776176570186449325309200969258771704155869979743437343764984621699243894", "price": "0.53", "size": "66.66", "side": "BUY", "hash": "43c220e85b1ffe5b36b4c80cceab76735bbcfbaa", "best_bid": "0.53", "best_ask": "0.94"}, {"asset_id": "98673773007855046568692125013481059419674479536813359840428477180250006155633", "price": "0.47", "size": "66.66", "side": "SELL", "hash": "feddd955358964cc8e6a886d18b73a9a39037adc", "best_bid": "0.06", "best_ask": "0.47"}], "timestamp": "1769384793351", "event_type": "price_change"}}
{"_local_timestamp": "2026-01-25T23:46:33.547639+00:00", "data": {"market": "0x5edebf3eb73ed300d47dd35e4c3938a6997cdbf3fa3b3ca086bdd7afa3e227cc", "price_changes": [{"asset_id": "48973293128569491311605281174826846182724783049607561423479481850292050544724", "price": "0.11", "size": "425", "side": "BUY", "hash": "a4bd04d79854e6dbbd85b1bec5b9a7a86d12ba63", "best_bid": "0.87", "best_ask": "0.988"}, {"asset_id": "47977478528993701917993634313399360833217034323739582269237365313563183735835", "price": "0.89", "size": "425", "side": "SELL", "hash": "7bb0ab9b6e4998c97a41ae0c53f3240889f88198", "best_bid": "0.012", "best_ask": "0.13"}], "timestamp": "1769384793425", "event_type": "price_change"}}
{"_local_timestamp": "2026-01-25T23:46:33.602864+00:00", "data": {"market": "0x5edebf3eb73ed300d47dd35e4c3938a6997cdbf3fa3b3ca086bdd7afa3e227cc", "price_changes": [{"asset_id": "48973293128569491311605281174826846182724783049607561423479481850292050544724", "price": "0.491", "size": "100", "side": "BUY", "hash": "9a487a93f419fd00461d999bedb30c7794276c34", "best_bid": "0.87", "best_ask": "0.988"}, {"asset_id": "47977478528993701917993634313399360833217034323739582269237365313563183735835", "price": "0.509", "size": "100", "side": "SELL", "hash": "2dc4b9fd63dfd0884d5a500d351a2deaa751669e", "best_bid": "0.012", "best_ask": "0.13"}], "timestamp": "1769384793527", "event_type": "price_change"}}
{"_local_timestamp": "2026-01-25T23:46:33.630710+00:00", "data": {"market": "0x1fed6d1346b04331b1ba1188525e560094040cbf3bbd84700c2dddb5241b2402", "price_changes": [{"asset_id": "38855512439706823591548373609888890731724800742290402025988926984750840280976", "price": "0.581", "size": "100", "side": "BUY", "hash": "c5bd561a10371aae06c9874b8abbd175357fdd08", "best_bid": "0.91", "best_ask": "0.99"}, {"asset_id": "71341306129608304129076187431040953407253993378796751066411893382443918679197", "price": "0.419", "size": "100", "side": "SELL", "hash": "6d97093828cce4c818c49a2d5937a503d35717e7", "best_bid": "0.01", "best_ask": "0.09"}], "timestamp": "1769384793558", "event_type": "price_change"}}
{"_local_timestamp": "2026-01-25T23:46:33.690976+00:00", "data": {"market": "0xa04889441513194066b992c25607750d9ad9beda073baa231b7d6c0d296f3db4", "price_changes": [{"asset_id": "4927715355597512197888285947791839404212602020821540571091074384909522708343", "price": "0.162", "size": "120", "side": "BUY", "hash": "77124284e6b5ce2b9c071853c895b9f45a534146", "best_bid": "0.86", "best_ask": "0.985"}, {"asset_id": "38098642543471813014855148341368026538917449780662028630830591144684505089593", "price": "0.838", "size": "120", "side": "SELL", "hash": "b997a89a832df3d30e35ee98ffa76807f96feb42", "best_bid": "0.015", "best_ask": "0.14"}], "timestamp": "1769384793614", "event_type": "price_change"}}
{"_local_timestamp": "2026-01-25T23:46:33.700951+00:00", "data": {"market": "0x1fed6d1346b04331b1ba1188525e560094040cbf3bbd84700c2dddb5241b2402", "price_changes": [{"asset_id": "71341306129608304129076187431040953407253993378796751066411893382443918679197", "price": "0.011", "size": "22.67", "side": "BUY", "hash": "376f60c80ff9dbcba4fc972962ddc4d132a12d66", "best_bid": "0.011", "best_ask": "0.09"}, {"asset_id": "38855512439706823591548373609888890731724800742290402025988926984750840280976", "price": "0.989", "size": "22.67", "side": "SELL", "hash": "34eb95f4ff4886cbd6d6e5b8c17e82fdf6788444", "best_bid": "0.91", "best_ask": "0.989"}], "timestamp": "1769384793628", "event_type": "price_change"}}
{"_local_timestamp": "2026-01-25T23:46:33.782841+00:00", "data": {"market": "0x1fed6d1346b04331b1ba1188525e560094040cbf3bbd84700c2dddb5241b2402", "price_changes": [{"asset_id": "38855512439706823591548373609888890731724800742290402025988926984750840280976", "price": "0.4", "size": "125", "side": "BUY", "hash": "7024af50fa926b0056d80b21eb8747a3b3aeca72", "best_bid": "0.91", "best_ask": "0.989"}, {"asset_id": "71341306129608304129076187431040953407253993378796751066411893382443918679197", "price": "0.6", "size": "125", "side": "SELL", "hash": "07feb70bb2eb9fc0cb8f9d53739288dd5f9022a1", "best_bid": "0.011", "best_ask": "0.09"}], "timestamp": "1769384793712", "event_type": "price_change"}}
{"_local_timestamp": "2026-01-25T23:46:33.835184+00:00", "data": {"market": "0x1fed6d1346b04331b1ba1188525e560094040cbf3bbd84700c2dddb5241b2402", "price_changes": [{"asset_id": "38855512439706823591548373609888890731724800742290402025988926984750840280976", "price": "0.35", "size": "68.57", "side": "BUY", "hash": "ed89539ab777ed38b5d309684c2729cec3046b6f", "best_bid": "0.91", "best_ask": "0.989"}, {"asset_id": "71341306129608304129076187431040953407253993378796751066411893382443918679197", "price": "0.65", "size": "68.57", "side": "SELL", "hash": "43e78dd9aeb712100f4d90f2e7d1af7329ba584e", "best_bid": "0.011", "best_ask": "0.09"}], "timestamp": "1769384793762", "event_type": "price_change"}}
{"_local_timestamp": "2026-01-25T23:46:33.883075+00:00", "data": {"market": "0x1fed6d1346b04331b1ba1188525e560094040cbf3bbd84700c2dddb5241b2402", "price_changes": [{"asset_id": "38855512439706823591548373609888890731724800742290402025988926984750840280976", "price": "0.3", "size": "86.66", "side": "BUY", "hash": "38cda9a87d5b9643d13274b1a7c7cdb8f0007006", "best_bid": "0.91", "best_ask": "0.989"}, {"asset_id": "71341306129608304129076187431040953407253993378796751066411893382443918679197", "price": "0.7", "size": "86.66", "side": "SELL", "hash": "2ba173f0557f943ba279a304fcdae8e2e0b1c174", "best_bid": "0.011", "best_ask": "0.09"}], "timestamp": "1769384793811", "event_type": "price_change"}}
{"_local_timestamp": "2026-01-25T23:46:33.935017+00:00", "data": {"market": "0x1fed6d1346b04331b1ba1188525e560094040cbf3bbd84700c2dddb5241b2402", "price_changes": [{"asset_id": "38855512439706823591548373609888890731724800742290402025988926984750840280976", "price": "0.25", "size": "262", "side": "BUY", "hash": "fff01727c8c1208a7369478ed7a3c3ee9ae26436", "best_bid": "0.91", "best_ask": "0.989"}, {"asset_id": "71341306129608304129076187431040953407253993378796751066411893382443918679197", "price": "0.75", "size": "262", "side": "SELL", "hash": "7f107d70699b5619356de94835f7547b7d6b6672", "best_bid": "0.011", "best_ask": "0.09"}], "timestamp": "1769384793861", "event_type": "price_change"}}
{"_local_timestamp": "2026-01-25T23:46:34.035153+00:00", "data": {"market": "0x1fed6d1346b04331b1ba1188525e560094040cbf3bbd84700c2dddb5241b2402", "price_changes": [{"asset_id": "38855512439706823591548373609888890731724800742290402025988926984750840280976", "price": "0.2", "size": "410", "side": "BUY", "hash": "a897fce3d5cac1631dda45e2b9efa26f2b6c706c", "best_bid": "0.91", "best_ask": "0.989"}, {"asset_id": "71341306129608304129076187431040953407253993378796751066411893382443918679197", "price": "0.8", "size": "410", "side": "SELL", "hash": "b2d874bdd9602c603f01b1572854a5293773a8fb", "best_bid": "0.011", "best_ask": "0.09"}], "timestamp": "1769384793958", "event_type": "price_change"}}
{"_local_timestamp": "2026-01-25T23:46:34.111212+00:00", "data": {"market": "0x1fed6d1346b04331b1ba1188525e560094040cbf3bbd84700c2dddb5241b2402", "price_changes": [{"asset_id": "38855512439706823591548373609888890731724800742290402025988926984750840280976", "price": "0.15", "size": "551.66", "side": "BUY", "hash": "2563ef69920c0aaa11296113cbaa4227abcbe2de", "best_bid": "0.91", "best_ask": "0.989"}, {"asset_id": "71341306129608304129076187431040953407253993378796751066411893382443918679197", "price": "0.85", "size": "551.66", "side": "SELL", "hash": "621f4fdf28459045ad74b0d5e6ae3061de8dec7d", "best_bid": "0.011", "best_ask": "0.09"}], "timestamp": "1769384794013", "event_type": "price_change"}}
{"_local_timestamp": "2026-01-25T23:46:34.140214+00:00", "data": {"market": "0x1fed6d1346b04331b1ba1188525e560094040cbf3bbd84700c2dddb5241b2402", "price_changes": [{"asset_id": "38855512439706823591548373609888890731724800742290402025988926984750840280976", "price": "0.1", "size": "560", "side": "BUY", "hash": "25811a28cbbd5f5b214fed4b49a56b76747bb458", "best_bid": "0.91", "best_ask": "0.989"}, {"asset_id": "71341306129608304129076187431040953407253993378796751066411893382443918679197", "price": "0.9", "size": "560", "side": "SELL", "hash": "dce9e4a11905c04a0b0d1e672f407f4c945e47fd", "best_bid": "0.011", "best_ask": "0.09"}], "timestamp": "1769384794064", "event_type": "price_change"}}
{"_local_timestamp": "2026-01-25T23:46:36.948101+00:00", "data": {"market": "0xa04889441513194066b992c25607750d9ad9beda073baa231b7d6c0d296f3db4", "price_changes": [{"asset_id": "4927715355597512197888285947791839404212602020821540571091074384909522708343", "price": "0.162", "size": "100", "side": "BUY", "hash": "fea3ac00e26f66d196f65aa303cfe4b0b070c888", "best_bid": "0.86", "best_ask": "0.985"}, {"asset_id": "38098642543471813014855148341368026538917449780662028630830591144684505089593", "price": "0.838", "size": "100", "side": "SELL", "hash": "a3f1a8b373e2f88785dcfe35ed2e56405ff85694", "best_bid": "0.015", "best_ask": "0.14"}], "timestamp": "1769384796872", "event_type": "price_change"}}
{"_local_timestamp": "2026-01-25T23:46:36.977404+00:00", "data": {"market": "0xa04889441513194066b992c25607750d9ad9beda073baa231b7d6c0d296f3db4", "price_changes": [{"asset_id": "4927715355597512197888285947791839404212602020821540571091074384909522708343", "price": "0.163", "size": "20", "side": "BUY", "hash": "8c6a5d6e5e053448dba404ffa66b0e9ca6491c64", "best_bid": "0.86", "best_ask": "0.985"}, {"asset_id": "38098642543471813014855148341368026538917449780662028630830591144684505089593", "price": "0.837", "size": "20", "side": "SELL", "hash": "6b453fd739ada548e5175f9b492d323fcb11ef48", "best_bid": "0.015", "best_ask": "0.14"}], "timestamp": "1769384796903", "event_type": "price_change"}}
{"_local_timestamp": "2026-01-25T23:46:41.556209+00:00", "data": {"market": "0xbf6fbc35082962002b61f17e26820db124930ac43175934864e34a415ee40620", "price_changes": [{"asset_id": "42674776176570186449325309200969258771704155869979743437343764984621699243894", "price": "0.52", "size": "0", "side": "BUY", "hash": "fae02efd657f3dade4e131d6c11a44b7cade04d3", "best_bid": "0.53", "best_ask": "0.94"}, {"asset_id": "98673773007855046568692125013481059419674479536813359840428477180250006155633", "price": "0.48", "size": "0", "side": "SELL", "hash": "26a35212d7c908bb839bfd29f841613514f85d72", "best_bid": "0.06", "best_ask": "0.47"}], "timestamp": "1769384801475", "event_type": "price_change"}}
{"_local_timestamp": "2026-01-25T23:46:41.654317+00:00", "data": {"market": "0xbf6fbc35082962002b61f17e26820db124930ac43175934864e34a415ee40620", "price_changes": [{"asset_id": "42674776176570186449325309200969258771704155869979743437343764984621699243894", "price": "0.54", "size": "9.25", "side": "BUY", "hash": "cb10248680ea45313ed93d80f464b1fadf8af889", "best_bid": "0.54", "best_ask": "0.94"}, {"asset_id": "98673773007855046568692125013481059419674479536813359840428477180250006155633", "price": "0.46", "size": "9.25", "side": "SELL", "hash": "acf1363c35fe6c3a1f113430903008f81f872149", "best_bid": "0.06", "best_ask": "0.46"}], "timestamp": "1769384801571", "event_type": "price_change"}}
{"_local_timestamp": "2026-01-25T23:46:50.886654+00:00", "data": {"market": "0xa04889441513194066b992c25607750d9ad9beda073baa231b7d6c0d296f3db4", "price_changes": [{"asset_id": "4927715355597512197888285947791839404212602020821540571091074384909522708343", "price": "0.21", "size": "0", "side": "BUY", "hash": "8bbd0adecd7020dd1847f04e6789cb178bddbe8f", "best_bid": "0.86", "best_ask": "0.985"}, {"asset_id": "38098642543471813014855148341368026538917449780662028630830591144684505089593", "price": "0.79", "size": "0", "side": "SELL", "hash": "14b2d5f7b3b6260e2d5d0539a32e8cd5d2d38874", "best_bid": "0.015", "best_ask": "0.14"}], "timestamp": "1769384810661", "event_type": "price_change"}}
{"_local_timestamp": "2026-01-25T23:46:50.897286+00:00", "data": {"market": "0xa04889441513194066b992c25607750d9ad9beda073baa231b7d6c0d296f3db4", "price_changes": [{"asset_id": "4927715355597512197888285947791839404212602020821540571091074384909522708343", "price": "0.161", "size": "0", "side": "BUY", "hash": "8bbd0adecd7020dd1847f04e6789cb178bddbe8f", "best_bid": "0.86", "best_ask": "0.985"}, {"asset_id": "38098642543471813014855148341368026538917449780662028630830591144684505089593", "price": "0.839", "size": "0", "side": "SELL", "hash": "14b2d5f7b3b6260e2d5d0539a32e8cd5d2d38874", "best_bid": "0.015", "best_ask": "0.14"}], "timestamp": "1769384810661", "event_type": "price_change"}}
{"_local_timestamp": "2026-01-25T23:46:50.898439+00:00", "data": {"market": "0x5edebf3eb73ed300d47dd35e4c3938a6997cdbf3fa3b3ca086bdd7afa3e227cc", "price_changes": [{"asset_id": "48973293128569491311605281174826846182724783049607561423479481850292050544724", "price": "0.21", "size": "0", "side": "BUY", "hash": "6105a0943ac404845b170e9b0ee4f80db53223e7", "best_bid": "0.87", "best_ask": "0.988"}, {"asset_id": "47977478528993701917993634313399360833217034323739582269237365313563183735835", "price": "0.79", "size": "0", "side": "SELL", "hash": "9d8a1b503c27de2e89aa8316cef8471976f8a7c1", "best_bid": "0.012", "best_ask": "0.13"}], "timestamp": "1769384810663", "event_type": "price_change"}}
{"_local_timestamp": "2026-01-25T23:46:50.899594+00:00", "data": {"market": "0x5edebf3eb73ed300d47dd35e4c3938a6997cdbf3fa3b3ca086bdd7afa3e227cc", "price_changes": [{"asset_id": "48973293128569491311605281174826846182724783049607561423479481850292050544724", "price": "0.16", "size": "0", "side": "BUY", "hash": "6105a0943ac404845b170e9b0ee4f80db53223e7", "best_bid": "0.87", "best_ask": "0.988"}, {"asset_id": "47977478528993701917993634313399360833217034323739582269237365313563183735835", "price": "0.84", "size": "0", "side": "SELL", "hash": "9d8a1b503c27de2e89aa8316cef8471976f8a7c1", "best_bid": "0.012", "best_ask": "0.13"}], "timestamp": "1769384810663", "event_type": "price_change"}}
{"_local_timestamp": "2026-01-25T23:46:50.908370+00:00", "data": {"market": "0x1fed6d1346b04331b1ba1188525e560094040cbf3bbd84700c2dddb5241b2402", "price_changes": [{"asset_id": "38855512439706823591548373609888890731724800742290402025988926984750840280976", "price": "0.4", "size": "50", "side": "BUY", "hash": "c266895fb9aa6306bcc2b9c6c291e9c30ff61cb4", "best_bid": "0.91", "best_ask": "0.989"}, {"asset_id": "71341306129608304129076187431040953407253993378796751066411893382443918679197", "price": "0.6", "size": "50", "side": "SELL", "hash": "a11dc2b6d981ee55ad2d23e61ed75514e6681277", "best_bid": "0.011", "best_ask": "0.09"}], "timestamp": "1769384810660", "event_type": "price_change"}}
{"_local_timestamp": "2026-01-25T23:46:53.546402+00:00", "data": {"market": "0x5edebf3eb73ed300d47dd35e4c3938a6997cdbf3fa3b3ca086bdd7afa3e227cc", "price_changes": [{"asset_id": "48973293128569491311605281174826846182724783049607561423479481850292050544724", "price": "0.161", "size": "0", "side": "BUY", "hash": "fe1dc7b980c1247968f531bbcd3e4a1d2c792f35", "best_bid": "0.87", "best_ask": "0.988"}, {"asset_id": "47977478528993701917993634313399360833217034323739582269237365313563183735835", "price": "0.839", "size": "0", "side": "SELL", "hash": "dc05dae3853a87256d7676f6e77c717dfea4c25d", "best_bid": "0.012", "best_ask": "0.13"}], "timestamp": "1769384813475", "event_type": "price_change"}}
{"_local_timestamp": "2026-01-25T23:46:53.573562+00:00", "data": {"market": "0x5edebf3eb73ed300d47dd35e4c3938a6997cdbf3fa3b3ca086bdd7afa3e227cc", "price_changes": [{"asset_id": "48973293128569491311605281174826846182724783049607561423479481850292050544724", "price": "0.113", "size": "20", "side": "BUY", "hash": "a6d62a60b4210478fc0bbededc189ed77cde484d", "best_bid": "0.87", "best_ask": "0.988"}, {"asset_id": "47977478528993701917993634313399360833217034323739582269237365313563183735835", "price": "0.887", "size": "20", "side": "SELL", "hash": "f4a327bd453cc9bf807c45367c59aae688aefec0", "best_bid": "0.012", "best_ask": "0.13"}], "timestamp": "1769384813503", "event_type": "price_change"}}
{"_local_timestamp": "2026-01-25T23:46:55.365622+00:00", "data": {"market": "0x1fed6d1346b04331b1ba1188525e560094040cbf3bbd84700c2dddb5241b2402", "price_changes": [{"asset_id": "71341306129608304129076187431040953407253993378796751066411893382443918679197", "price": "0.169", "size": "0", "side": "SELL", "hash": "e975ca6b80f19b060cc8e87d75f6eae417bf3604", "best_bid": "0.011", "best_ask": "0.09"}, {"asset_id": "38855512439706823591548373609888890731724800742290402025988926984750840280976", "price": "0.831", "size": "0", "side": "BUY", "hash": "83674b5028ccf1249700ad1f919bb9fdc2ca2892", "best_bid": "0.91", "best_ask": "0.989"}], "timestamp": "1769384815300", "event_type": "price_change"}}
{"_local_timestamp": "2026-01-25T23:46:55.890387+00:00", "data": {"market": "0x5edebf3eb73ed300d47dd35e4c3938a6997cdbf3fa3b3ca086bdd7afa3e227cc", "price_changes": [{"asset_id": "47977478528993701917993634313399360833217034323739582269237365313563183735835", "price": "0.533", "size": "0", "side": "SELL", "hash": "d22e45ee84e3e2704677f21f5389b71ff00db7cd", "best_bid": "0.012", "best_ask": "0.13"}, {"asset_id": "48973293128569491311605281174826846182724783049607561423479481850292050544724", "price": "0.467", "size": "0", "side": "BUY", "hash": "669f9dd02e81d27fdf71bf43d8c2db2569943d5d", "best_bid": "0.87", "best_ask": "0.988"}], "timestamp": "1769384815822", "event_type": "price_change"}}
{"_local_timestamp": "2026-01-25T23:46:55.899496+00:00", "data": {"market": "0xa04889441513194066b992c25607750d9ad9beda073baa231b7d6c0d296f3db4", "price_changes": [{"asset_id": "38098642543471813014855148341368026538917449780662028630830591144684505089593", "price": "0.487", "size": "0", "side": "SELL", "hash": "4573b92b6e03a2dca8e17e888e14cfd62c53acab", "best_bid": "0.015", "best_ask": "0.14"}, {"asset_id": "4927715355597512197888285947791839404212602020821540571091074384909522708343", "price": "0.513", "size": "0", "side": "BUY", "hash": "eb7435f53df0f863334f3d6509f3044e0b56ec12", "best_bid": "0.86", "best_ask": "0.985"}], "timestamp": "1769384815822", "event_type": "price_change"}}
{"_local_timestamp": "2026-01-25T23:46:56.299657+00:00", "data": {"market": "0x1fed6d1346b04331b1ba1188525e560094040cbf3bbd84700c2dddb5241b2402", "price_changes": [{"asset_id": "71341306129608304129076187431040953407253993378796751066411893382443918679197", "price": "0.089", "size": "39.87", "side": "SELL", "hash": "e828b1100e7076be9eb40cb37013b2f351f348cd", "best_bid": "0.011", "best_ask": "0.089"}, {"asset_id": "38855512439706823591548373609888890731724800742290402025988926984750840280976", "price": "0.911", "size": "39.87", "side": "BUY", "hash": "a8f326ee75021b4613209dbe60b2748b37c395da", "best_bid": "0.911", "best_ask": "0.989"}], "timestamp": "1769384816214", "event_type": "price_change"}}
{"_local_timestamp": "2026-01-25T23:46:56.794878+00:00", "data": {"market": "0x5edebf3eb73ed300d47dd35e4c3938a6997cdbf3fa3b3ca086bdd7afa3e227cc", "price_changes": [{"asset_id": "47977478528993701917993634313399360833217034323739582269237365313563183735835", "price": "0.129", "size": "10", "side": "SELL", "hash": "bd6cc232619c111331516128401999b5a50a4e6b", "best_bid": "0.012", "best_ask": "0.129"}, {"asset_id": "48973293128569491311605281174826846182724783049607561423479481850292050544724", "price": "0.871", "size": "10", "side": "BUY", "hash": "b1bed0e165d249fbb2b62c2a6216bd8e46ab91a1", "best_bid": "0.871", "best_ask": "0.988"}], "timestamp": "1769384816721", "event_type": "price_change"}}
{"_local_timestamp": "2026-01-25T23:46:56.796052+00:00", "data": {"market": "0xa04889441513194066b992c25607750d9ad9beda073baa231b7d6c0d296f3db4", "price_changes": [{"asset_id": "38098642543471813014855148341368026538917449780662028630830591144684505089593", "price": "0.139", "size": "10", "side": "SELL", "hash": "49745b96b07483b19e35a1eeea4bfb7ca715d802", "best_bid": "0.015", "best_ask": "0.139"}, {"asset_id": "4927715355597512197888285947791839404212602020821540571091074384909522708343", "price": "0.861", "size": "10", "side": "BUY", "hash": "fd6ac5083278efdf76c2486a0498f27cb8f97195", "best_bid": "0.861", "best_ask": "0.985"}], "timestamp": "1769384816721", "event_type": "price_change"}}
{"_local_timestamp": "2026-01-25T23:47:26.376156+00:00", "data": {"market": "0xa04889441513194066b992c25607750d9ad9beda073baa231b7d6c0d296f3db4", "price_changes": [{"asset_id": "4927715355597512197888285947791839404212602020821540571091074384909522708343", "price": "0.061", "size": "0", "side": "BUY", "hash": "0de36d6d803504c92cbf69aaeb2498ae957a2b7a", "best_bid": "0.861", "best_ask": "0.985"}, {"asset_id": "38098642543471813014855148341368026538917449780662028630830591144684505089593", "price": "0.939", "size": "0", "side": "SELL", "hash": "9f0f3f54304c57d8fc589a177d165c61f2b5e894", "best_bid": "0.015", "best_ask": "0.139"}], "timestamp": "1769384846297", "event_type": "price_change"}}
{"_local_timestamp": "2026-01-25T23:47:26.653498+00:00", "data": {"market": "0x5edebf3eb73ed300d47dd35e4c3938a6997cdbf3fa3b3ca086bdd7afa3e227cc", "price_changes": [{"asset_id": "48973293128569491311605281174826846182724783049607561423479481850292050544724", "price": "0.061", "size": "100", "side": "BUY", "hash": "94e57aa83a2fdaa410636f4dd3971140bc70af53", "best_bid": "0.871", "best_ask": "0.988"}, {"asset_id": "47977478528993701917993634313399360833217034323739582269237365313563183735835", "price": "0.939", "size": "100", "side": "SELL", "hash": "ba3e63f09787a205d297ff9a43afd0232bafa7d6", "best_bid": "0.012", "best_ask": "0.129"}], "timestamp": "1769384846583", "event_type": "price_change"}}
{"_local_timestamp": "2026-01-25T23:47:37.752536+00:00", "data": {"market": "0x1fed6d1346b04331b1ba1188525e560094040cbf3bbd84700c2dddb5241b2402", "price_changes": [{"asset_id": "38855512439706823591548373609888890731724800742290402025988926984750840280976", "price": "0.25", "size": "212", "side": "BUY", "hash": "50036b7b24cf3a34f51662e52e47b86188975a02", "best_bid": "0.911", "best_ask": "0.989"}, {"asset_id": "71341306129608304129076187431040953407253993378796751066411893382443918679197", "price": "0.75", "size": "212", "side": "SELL", "hash": "6a29ab46c20963fa5c18ca6d74139cd392937f51", "best_bid": "0.011", "best_ask": "0.089"}], "timestamp": "1769384857544", "event_type": "price_change"}}
{"_local_timestamp": "2026-01-25T23:47:38.250075+00:00", "data": {"market": "0x5edebf3eb73ed300d47dd35e4c3938a6997cdbf3fa3b3ca086bdd7afa3e227cc", "price_changes": [{"asset_id": "48973293128569491311605281174826846182724783049607561423479481850292050544724", "price": "0.16", "size": "100", "side": "BUY", "hash": "8c9fc629f4c016c258ad5cdbffcc80a22dad8008", "best_bid": "0.871", "best_ask": "0.988"}, {"asset_id": "47977478528993701917993634313399360833217034323739582269237365313563183735835", "price": "0.84", "size": "100", "side": "SELL", "hash": "3084bd24f96a197738fa8924123162591276535b", "best_bid": "0.012", "best_ask": "0.129"}], "timestamp": "1769384858105", "event_type": "price_change"}}
{"_local_timestamp": "2026-01-25T23:47:38.318956+00:00", "data": {"market": "0xa04889441513194066b992c25607750d9ad9beda073baa231b7d6c0d296f3db4", "price_changes": [{"asset_id": "4927715355597512197888285947791839404212602020821540571091074384909522708343", "price": "0.161", "size": "100", "side": "BUY", "hash": "b02cb78aefb6fca58e69edd48320fab536f02695", "best_bid": "0.861", "best_ask": "0.985"}, {"asset_id": "38098642543471813014855148341368026538917449780662028630830591144684505089593", "price": "0.839", "size": "100", "side": "SELL", "hash": "df83efb5dcf2c646a939c527f097b5a521384823", "best_bid": "0.015", "best_ask": "0.139"}], "timestamp": "1769384858063", "event_type": "price_change"}}
{"_local_timestamp": "2026-01-25T23:47:38.460328+00:00", "data": {"market": "0x1fed6d1346b04331b1ba1188525e560094040cbf3bbd84700c2dddb5241b2402", "price_changes": [{"asset_id": "38855512439706823591548373609888890731724800742290402025988926984750840280976", "price": "0.301", "size": "50", "side": "BUY", "hash": "6fbbb02a906460f1bbe070641ea9c167a6cae892", "best_bid": "0.911", "best_ask": "0.989"}, {"asset_id": "71341306129608304129076187431040953407253993378796751066411893382443918679197", "price": "0.699", "size": "50", "side": "SELL", "hash": "64341691d380258a095372f80151d5332e7692fc", "best_bid": "0.011", "best_ask": "0.089"}], "timestamp": "1769384858105", "event_type": "price_change"}}
{"_local_timestamp": "2026-01-25T23:47:41.505608+00:00", "data": {"market": "0x5edebf3eb73ed300d47dd35e4c3938a6997cdbf3fa3b3ca086bdd7afa3e227cc", "price_changes": [{"asset_id": "48973293128569491311605281174826846182724783049607561423479481850292050544724", "price": "0.113", "size": "0", "side": "BUY", "hash": "e4fdb143d287fb37b3e77c76cbe41909b036738e", "best_bid": "0.871", "best_ask": "0.988"}, {"asset_id": "47977478528993701917993634313399360833217034323739582269237365313563183735835", "price": "0.887", "size": "0", "side": "SELL", "hash": "105f09c3b230708bfa44404393a830dcbe3b194e", "best_bid": "0.012", "best_ask": "0.129"}], "timestamp": "1769384861435", "event_type": "price_change"}}
{"_local_timestamp": "2026-01-25T23:47:41.531946+00:00", "data": {"market": "0x5edebf3eb73ed300d47dd35e4c3938a6997cdbf3fa3b3ca086bdd7afa3e227cc", "price_changes": [{"asset_id": "48973293128569491311605281174826846182724783049607561423479481850292050544724", "price": "0.161", "size": "20", "side": "BUY", "hash": "154cc715a0957f8daa53dabaaec1875e573688a5", "best_bid": "0.871", "best_ask": "0.988"}, {"asset_id": "47977478528993701917993634313399360833217034323739582269237365313563183735835", "price": "0.839", "size": "20", "side": "SELL", "hash": "73ee0901bb5acbd7a2943cd383c8a609412bac4e", "best_bid": "0.012", "best_ask": "0.129"}], "timestamp": "1769384861464", "event_type": "price_change"}}
{"_local_timestamp": "2026-01-25T23:47:42.932135+00:00", "data": {"market": "0xa04889441513194066b992c25607750d9ad9beda073baa231b7d6c0d296f3db4", "price_changes": [{"asset_id": "4927715355597512197888285947791839404212602020821540571091074384909522708343", "price": "0.003", "size": "0", "side": "BUY", "hash": "c0a0c3e4e5a464c55cc3b73da8e0696c8c1352b2", "best_bid": "0.861", "best_ask": "0.985"}, {"asset_id": "38098642543471813014855148341368026538917449780662028630830591144684505089593", "price": "0.997", "size": "0", "side": "SELL", "hash": "f70648648a6afc57b1f89fe8f7f9472cf3abf9ea", "best_bid": "0.015", "best_ask": "0.139"}], "timestamp": "1769384862867", "event_type": "price_change"}}
{"_local_timestamp": "2026-01-25T23:48:02.534975+00:00", "data": {"market": "0x1fed6d1346b04331b1ba1188525e560094040cbf3bbd84700c2dddb5241b2402", "price_changes": [{"asset_id": "38855512439706823591548373609888890731724800742290402025988926984750840280976", "price": "0.1", "size": "360", "side": "BUY", "hash": "309d1996ed0d183fc2c1ef02662f1889c044cb7c", "best_bid": "0.911", "best_ask": "0.989"}, {"asset_id": "71341306129608304129076187431040953407253993378796751066411893382443918679197", "price": "0.9", "size": "360", "side": "SELL", "hash": "254aa0b7cea0b48b3a7107e355f994a52079270b", "best_bid": "0.011", "best_ask": "0.089"}], "timestamp": "1769384882444", "event_type": "price_change"}}
{"_local_timestamp": "2026-01-25T23:48:03.024763+00:00", "data": {"market": "0x1fed6d1346b04331b1ba1188525e560094040cbf3bbd84700c2dddb5241b2402", "price_changes": [{"asset_id": "38855512439706823591548373609888890731724800742290402025988926984750840280976", "price": "0.06", "size": "450", "side": "BUY", "hash": "c0cedcdfddab9f42392ab6a0c94758bd763c03a4", "best_bid": "0.911", "best_ask": "0.989"}, {"asset_id": "71341306129608304129076187431040953407253993378796751066411893382443918679197", "price": "0.94", "size": "450", "side": "SELL", "hash": "bb60a8211d752aea3d0687ff8955110620d7fa3d", "best_bid": "0.011", "best_ask": "0.089"}], "timestamp": "1769384882868", "event_type": "price_change"}}
{"_local_timestamp": "2026-01-25T23:49:04.527104+00:00", "data": {"market": "0x5edebf3eb73ed300d47dd35e4c3938a6997cdbf3fa3b3ca086bdd7afa3e227cc", "price_changes": [{"asset_id": "47977478528993701917993634313399360833217034323739582269237365313563183735835", "price": "0.001", "size": "2080.99", "side": "BUY", "hash": "176db288fe4a8f8ecf7de5e92d0f10c238cc4605", "best_bid": "0.012", "best_ask": "0.129"}, {"asset_id": "48973293128569491311605281174826846182724783049607561423479481850292050544724", "price": "0.999", "size": "2080.99", "side": "SELL", "hash": "83cdb340e56ab52e4eb6bc86cafd4cbe5d6aa98c", "best_bid": "0.871", "best_ask": "0.988"}], "timestamp": "1769384944451", "event_type": "price_change"}}
{"_local_timestamp": "2026-01-25T23:49:05.017149+00:00", "data": {"market": "0xe1730ddaa88ffb2fb360af9f5b58c9e427f61c30712578b1701408911e3f655d", "price_changes": [{"asset_id": "81699282895973617782040895594229616523859617972840387954210064871270448792972", "price": "0.01", "size": "186.66", "side": "BUY", "hash": "fbf47f78f13a93da88b1cd394cac2fa61849bdef", "best_bid": "0.09", "best_ask": "0.82"}, {"asset_id": "37042473221634168250099193554902520956898907103252140530642497138603218091624", "price": "0.99", "size": "186.66", "side": "SELL", "hash": "6f36f3f6ddc8daa9fa18fa52a46bc433b4c6dae2", "best_bid": "0.18", "best_ask": "0.91"}], "timestamp": "1769384944952", "event_type": "price_change"}}
{"_local_timestamp": "2026-01-25T23:49:06.266900+00:00", "data": {"market": "0x5edebf3eb73ed300d47dd35e4c3938a6997cdbf3fa3b3ca086bdd7afa3e227cc", "price_changes": [{"asset_id": "47977478528993701917993634313399360833217034323739582269237365313563183735835", "price": "0.001", "size": "2120.68", "side": "BUY", "hash": "9514f0a7736abf0a026cf5f23a025f26b4af89d9", "best_bid": "0.012", "best_ask": "0.129"}, {"asset_id": "48973293128569491311605281174826846182724783049607561423479481850292050544724", "price": "0.999", "size": "2120.68", "side": "SELL", "hash": "4f4b30442c1370d3bb6f9a28739c3bb48aca96bb", "best_bid": "0.871", "best_ask": "0.988"}], "timestamp": "1769384946201", "event_type": "price_change"}}
{"_local_timestamp": "2026-01-25T23:49:08.737863+00:00", "data": {"market": "0xa04889441513194066b992c25607750d9ad9beda073baa231b7d6c0d296f3db4", "price_changes": [{"asset_id": "4927715355597512197888285947791839404212602020821540571091074384909522708343", "price": "0.511", "size": "0", "side": "BUY", "hash": "1e26c702bc97f6228775bb6b4c5966f23109a052", "best_bid": "0.861", "best_ask": "0.985"}, {"asset_id": "38098642543471813014855148341368026538917449780662028630830591144684505089593", "price": "0.489", "size": "0", "side": "SELL", "hash": "d39b2f4d541b06564a0b800a82013afe3a27e6f5", "best_bid": "0.015", "best_ask": "0.139"}], "timestamp": "1769384948665", "event_type": "price_change"}}
{"_local_timestamp": "2026-01-25T23:49:08.739147+00:00", "data": {"market": "0xa04889441513194066b992c25607750d9ad9beda073baa231b7d6c0d296f3db4", "price_changes": [{"asset_id": "4927715355597512197888285947791839404212602020821540571091074384909522708343", "price": "0.162", "size": "0", "side": "BUY", "hash": "1e26c702bc97f6228775bb6b4c5966f23109a052", "best_bid": "0.861", "best_ask": "0.985"}, {"asset_id": "38098642543471813014855148341368026538917449780662028630830591144684505089593", "price": "0.838", "size": "0", "side": "SELL", "hash": "d39b2f4d541b06564a0b800a82013afe3a27e6f5", "best_bid": "0.015", "best_ask": "0.139"}], "timestamp": "1769384948665", "event_type": "price_change"}}
{"_local_timestamp": "2026-01-25T23:49:08.740634+00:00", "data": {"market": "0xe1730ddaa88ffb2fb360af9f5b58c9e427f61c30712578b1701408911e3f655d", "price_changes": [{"asset_id": "37042473221634168250099193554902520956898907103252140530642497138603218091624", "price": "0.01", "size": "3312.8", "side": "BUY", "hash": "9e720ec0d0e714efddb8c0a4115b1dda6bf190d1", "best_bid": "0.18", "best_ask": "0.91"}, {"asset_id": "81699282895973617782040895594229616523859617972840387954210064871270448792972", "price": "0.99", "size": "3312.8", "side": "SELL", "hash": "8c689caa88a652ce186aeaa37e0ec03a94e70eba", "best_bid": "0.09", "best_ask": "0.82"}], "timestamp": "1769384948666", "event_type": "price_change"}}
{"_local_timestamp": "2026-01-25T23:49:08.741762+00:00", "data": {"market": "0xbf6fbc35082962002b61f17e26820db124930ac43175934864e34a415ee40620", "price_changes": [{"asset_id": "42674776176570186449325309200969258771704155869979743437343764984621699243894", "price": "0.53", "size": "0", "side": "BUY", "hash": "71c8855327d2735989a48a65f5f0cdf5270bcf61", "best_bid": "0.54", "best_ask": "0.94"}, {"asset_id": "98673773007855046568692125013481059419674479536813359840428477180250006155633", "price": "0.47", "size": "0", "side": "SELL", "hash": "cd404ed756e0fda360f5874336ab5370b65d077c", "best_bid": "0.06", "best_ask": "0.46"}], "timestamp": "1769384948666", "event_type": "price_change"}}
