{"_local_timestamp": "2026-01-25T23:40:37.313942+00:00", "data": [{"market": "0x4cf117dc50b3fe236db04d89e20fb082c253a5429132d2196933a12126fdd20f", "asset_id": "57183160858289786175926294655907942210215921501992035952262533576686097730156", "timestamp": "1769384434795", "hash": "b03232f12fc7539a00cf35733ef036dbb66d37c0", "bids": [{"price": "0.01", "size": "14510"}, {"price": "0.02", "size": "3807.19"}, {"price": "0.03", "size": "500"}, {"price": "0.04", "size": "7.53"}, {"price": "0.05", "size": "1010"}, {"price": "0.06", "size": "500"}, {"price": "0.08", "size": "300"}, {"price": "0.09", "size": "206.16"}, {"price": "0.1", "size": "351"}, {"price": "0.15", "size": "201.23"}, {"price": "0.16", "size": "800"}, {"price": "0.17", "size": "76.47"}, {"price": "0.18", "size": "61.11"}, {"price": "0.21", "size": "5"}, {"price": "0.22", "size": "2300"}, {"price": "0.24", "size": "100"}, {"price": "0.25", "size": "252.36"}], "asks": [{"price": "0.99", "size": "5009.95"}, {"price": "0.98", "size": "2700"}, {"price": "0.97", "size": "6.95"}, {"price": "0.93", "size": "1414.28"}, {"price": "0.92", "size": "8.64"}, {"price": "0.89", "size": "634.09"}, {"price": "0.85", "size": "213.33"}, {"price": "0.84", "size": "1000"}, {"price": "0.83", "size": "2770"}, {"price": "0.81", "size": "147.36"}, {"price": "0.77", "size": "5156.04"}, {"price": "0.76", "size": "300"}, {"price": "0.74", "size": "92.3"}, {"price": "0.73", "size": "50"}, {"price": "0.7", "size": "66.66"}, {"price": "0.65", "size": "258.2"}, {"price": "0.63", "size": "5"}, {"price": "0.42", "size": "100"}, {"price": "0.37", "size": "300"}, {"price": "0.36", "size": "17.18"}, {"price": "0.34", "size": "19.69"}, {"price": "0.29", "size": "2100"}, {"price": "0.28", "size": "300"}, {"price": "0.27", "size": "175"}], "event_type": "book", "last_trade_price": "0.750"}, {"market": "0x4cf117dc50b3fe236db04d89e20fb082c253a5429132d2196933a12126fdd20f", "asset_id": "23527488931458270373542522838879642337196546203685403538870425011196572389776", "timestamp": "1769384434795", "hash": "edaccc31a02b52f201063127963edf3c3f771ad9", "bids": [{"price": "0.01", "size": "5009.95"}, {"price": "0.02", "size": "2700"}, {"price": "0.03", "size": "6.95"}, {"price": "0.07", "size": "1414.28"}, {"price": "0.08", "size": "8.64"}, {"price": "0.11", "size": "634.09"}, {"price": "0.15", "size": "213.33"}, {"price": "0.16", "size": "1000"}, {"price": "0.17", "size": "2770"}, {"price": "0.19", "size": "147.36"}, {"price": "0.23", "size": "5156.04"}, {"price": "0.24", "size": "300"}, {"price": "0.26", "size": "92.3"}, {"price": "0.27", "size": "50"}, {"price": "0.3", "size": "66.66"}, {"price": "0.35", "size": "258.2"}, {"price": "0.37", "size": "5"}, {"price": "0.58", "size": "100"}, {"price": "0.63", "size": "300"}, {"price": "0.64", "size": "17.18"}, {"price": "0.66", "size": "19.69"}, {"price": "0.71", "size": "2100"}, {"price": "0.72", "size": "300"}, {"price": "0.73", "size": "175"}], "asks": [{"price": "0.99", "size": "14510"}, {"price": "0.98", "size": "3807.19"}, {"price": "0.97", "size": "500"}, {"price": "0.96", "size": "7.53"}, {"price": "0.95", "size": "1010"}, {"price": "0.94", "size": "500"}, {"price": "0.92", "size": "300"}, {"price": "0.91", "size": "206.16"}, {"price": "0.9", "size": "351"}, {"price": "0.85", "size": "201.23"}, {"price": "0.84", "size": "800"}, {"price": "0.83", "size": "76.47"}, {"price": "0.82", "size": "61.11"}, {"price": "0.79", "size": "5"}, {"price": "0.78", "size": "2300"}, {"price": "0.76", "size": "100"}, {"price": "0.75", "size": "252.36"}], "event_type": "book", "last_trade_price": "0.750"}]}
{"_local_timestamp": "2026-01-25T23:42:39.061259+00:00", "data": {"market": "0x4cf117dc50b3fe236db04d89e20fb082c253a5429132d2196933a12126fdd20f", "price_changes": [{"asset_id": "57183160858289786175926294655907942210215921501992035952262533576686097730156", "price": "0.23", "size": "100", "side": "BUY", "hash": "c92cb6f29c97d8fdda51f7e413094642a07ae583", "best_bid": "0.25", "best_ask": "0.27"}, {"asset_id": "23527488931458270373542522838879642337196546203685403538870425011196572389776", "price": "0.77", "size": "100", "side": "SELL", "hash": "352d4a770d31579730557161b277b169f5787927", "best_bid": "0.73", "best_ask": "0.75"}], "timestamp": "1769384558987", "event_type": "price_change"}}
{"_local_timestamp": "2026-01-25T23:42:39.098589+00:00", "data": {"market": "0x4cf117dc50b3fe236db04d89e20fb082c253a5429132d2196933a12126fdd20f", "price_changes": [{"asset_id": "23527488931458270373542522838879642337196546203685403538870425011196572389776", "price": "0.74", "size": "27.49", "side": "BUY", "hash": "5d04965217ca9d8060924ef7355300893dee9e86", "best_bid": "0.74", "best_ask": "0.75"}, {"asset_id": "57183160858289786175926294655907942210215921501992035952262533576686097730156", "price": "0.26", "size": "27.49", "side": "SELL", "hash": "440ba0d6c71db3f1f69d6b87b0423756ee0b1575", "best_bid": "0.25", "best_ask": "0.26"}], "timestamp": "1769384559014", "event_type": "price_change"}}
{"_local_timestamp": "2026-01-25T23:42:39.138647+00:00", "data": {"market": "0x4cf117dc50b3fe236db04d89e20fb082c253a5429132d2196933a12126fdd20f", "price_changes": [{"asset_id": "57183160858289786175926294655907942210215921501992035952262533576686097730156", "price": "0.24", "size": "200", "side": "BUY", "hash": "4b447fcc796c0273dc321766a32cf20d979c1dad", "best_bid": "0.25", "best_ask": "0.26"}, {"asset_id": "23527488931458270373542522838879642337196546203685403538870425011196572389776", "price": "0.76", "size": "200", "side": "SELL", "hash": "081fe099fd67bf627ff9884c0c65f26bea7003d9", "best_bid": "0.74", "best_ask": "0.75"}], "timestamp": "1769384559063", "event_type": "price_change"}}
{"_local_timestamp": "2026-01-25T23:42:39.170591+00:00", "data": {"market": "0x4cf117dc50b3fe236db04d89e20fb082c253a5429132d2196933a12126fdd20f", "price_changes": [{"asset_id": "23527488931458270373542522838879642337196546203685403538870425011196572389776", "price": "0.72", "size": "327.49", "side": "BUY", "hash": "efa129e65bb4831dcc087999eb520d78e5087113", "best_bid": "0.74", "best_ask": "0.75"}, {"asset_id": "57183160858289786175926294655907942210215921501992035952262533576686097730156", "price": "0.28", "size": "327.49", "side": "SELL", "hash": "79493d90a6f82ad67cf36cb3319b6fd93b49290f", "best_bid": "0.25", "best_ask": "0.26"}], "timestamp": "1769384559090", "event_type": "price_change"}}
{"_local_timestamp": "2026-01-25T23:42:39.170989+00:00", "data": {"market": "0x4cf117dc50b3fe236db04d89e20fb082c253a5429132d2196933a12126fdd20f", "price_changes": [{"asset_id": "23527488931458270373542522838879642337196546203685403538870425011196572389776", "price": "0.73", "size": "202.49", "side": "BUY", "hash": "5ab9be9d24fc4cbbe6d6eec4cc4a2eb59ef5cd9e", "best_bid": "0.74", "best_ask": "0.75"}, {"asset_id": "57183160858289786175926294655907942210215921501992035952262533576686097730156", "price": "0.27", "size": "202.49", "side": "SELL", "hash": "f6a35c124e96ebb8754c7e2195782c82660db22a", "best_bid": "0.25", "best_ask": "0.26"}], "timestamp": "1769384559096", "event_type": "price_change"}}
{"_local_timestamp": "2026-01-25T23:42:41.944288+00:00", "data": {"market": "0x4cf117dc50b3fe236db04d89e20fb082c253a5429132d2196933a12126fdd20f", "price_changes": [{"asset_id": "57183160858289786175926294655907942210215921501992035952262533576686097730156", "price": "0.22", "size": "2200", "side": "BUY", "hash": "c9293b8d54295c9b0bf81b157a1821e14f40414c", "best_bid": "0.25", "best_ask": "0.26"}, {"asset_id": "23527488931458270373542522838879642337196546203685403538870425011196572389776", "price": "0.78", "size": "2200", "side": "SELL", "hash": "f2539d39d2900416f5c8febf21087f1eec9921b0", "best_bid": "0.74", "best_ask": "0.75"}], "timestamp": "1769384561866", "event_type": "price_change"}}
{"_local_timestamp": "2026-01-25T23:42:41.944744+00:00", "data": {"market": "0x4cf117dc50b3fe236db04d89e20fb082c253a5429132d2196933a12126fdd20f", "price_changes": [{"asset_id": "23527488931458270373542522838879642337196546203685403538870425011196572389776", "price": "0.71", "size": "2000", "side": "BUY", "hash": "d8fe64466682427f6c495ecd2c44705ac688abc0", "best_bid": "0.74", "best_ask": "0.75"}, {"asset_id": "57183160858289786175926294655907942210215921501992035952262533576686097730156", "price": "0.29", "size": "2000", "side": "SELL", "hash": "ea6998e6fa82946c917d920fc71c12ee75f36f5d", "best_bid": "0.25", "best_ask": "0.26"}], "timestamp": "1769384561866", "event_type": "price_change"}}
{"_local_timestamp": "2026-01-25T23:42:45.113070+00:00", "data": {"market": "0x4cf117dc50b3fe236db04d89e20fb082c253a5429132d2196933a12126fdd20f", "price_changes": [{"asset_id": "23527488931458270373542522838879642337196546203685403538870425011196572389776", "price": "0.72", "size": "427.49", "side": "BUY", "hash": "aa032574c33c399a5d968646fd42fa35c59f5d52", "best_bid": "0.74", "best_ask": "0.75"}, {"asset_id": "57183160858289786175926294655907942210215921501992035952262533576686097730156", "price": "0.28", "size": "427.49", "side": "SELL", "hash": "e4b4a29f5526fb1e12f7fd4b3f365ba6e858ebb7", "best_bid": "0.25", "best_ask": "0.26"}], "timestamp": "1769384564967", "event_type": "price_change"}}
{"_local_timestamp": "2026-01-25T23:42:45.115184+00:00", "data": {"market": "0x4cf117dc50b3fe236db04d89e20fb082c253a5429132d2196933a12126fdd20f", "price_changes": [{"asset_id": "57183160858289786175926294655907942210215921501992035952262533576686097730156", "price": "0.23", "size": "200", "side": "BUY", "hash": "65fdb84c42a17c5b5b35c58f94be08ef45d42673", "best_bid": "0.25", "best_ask": "0.26"}, {"asset_id": "23527488931458270373542522838879642337196546203685403538870425011196572389776", "price": "0.77", "size": "200", "side": "SELL", "hash": "1902decee17a74c438b7fe0ead5785dd8a9cd347", "best_bid": "0.74", "best_ask": "0.75"}], "timestamp": "1769384564968", "event_type": "price_change"}}
{"_local_timestamp": "2026-01-25T23:43:01.243116+00:00", "data": {"market": "0x4cf117dc50b3fe236db04d89e20fb082c253a5429132d2196933a12126fdd20f", "price_changes": [{"asset_id": "23527488931458270373542522838879642337196546203685403538870425011196572389776", "price": "0.73", "size": "102.49", "side": "BUY", "hash": "26754f60c2151fcede46f154103b18cc951d02ef", "best_bid": "0.74", "best_ask": "0.75"}, {"asset_id": "57183160858289786175926294655907942210215921501992035952262533576686097730156", "price": "0.27", "size": "102.49", "side": "SELL", "hash": "14f93158aab9c5816c8e1e0f3b71cb47036e2b63", "best_bid": "0.25", "best_ask": "0.26"}], "timestamp": "1769384581001", "event_type": "price_change"}}
{"_local_timestamp": "2026-01-25T23:43:01.246444+00:00", "data": {"market": "0x4cf117dc50b3fe236db04d89e20fb082c253a5429132d2196933a12126fdd20f", "price_changes": [{"asset_id": "57183160858289786175926294655907942210215921501992035952262533576686097730156", "price": "0.24", "size": "100", "side": "BUY", "hash": "91446beefaa98340ba18724cd6ac8c14df8ae6d2", "best_bid": "0.25", "best_ask": "0.26"}, {"asset_id": "23527488931458270373542522838879642337196546203685403538870425011196572389776", "price": "0.76", "size": "100", "side": "SELL", "hash": "5afb1105caaf1688b29308fbe8fa191fe5972d8a", "best_bid": "0.74", "best_ask": "0.75"}], "timestamp": "1769384581005", "event_type": "price_change"}}
{"_local_timestamp": "2026-01-25T23:44:18.826704+00:00", "data": {"market": "0x4cf117dc50b3fe236db04d89e20fb082c253a5429132d2196933a12126fdd20f", "price_changes": [{"asset_id": "57183160858289786175926294655907942210215921501992035952262533576686097730156", "price": "0.24", "size": "200", "side": "BUY", "hash": "7d9d86589d002688599f1a15aa60c91639dc9a2a", "best_bid": "0.25", "best_ask": "0.26"}, {"asset_id": "23527488931458270373542522838879642337196546203685403538870425011196572389776", "price": "0.76", "size": "200", "side": "SELL", "hash": "5881204112848b7b9fe31a282ba9b77f263dba72", "best_bid": "0.74", "best_ask": "0.75"}], "timestamp": "1769384658754", "event_type": "price_change"}}
{"_local_timestamp": "2026-01-25T23:44:19.015078+00:00", "data": {"market": "0x4cf117dc50b3fe236db04d89e20fb082c253a5429132d2196933a12126fdd20f", "price_changes": [{"asset_id": "23527488931458270373542522838879642337196546203685403538870425011196572389776", "price": "0.73", "size": "202.49", "side": "BUY", "hash": "c15fd97df5ff5029edba99fa6c6de94159a4eb7e", "best_bid": "0.74", "best_ask": "0.75"}, {"asset_id": "57183160858289786175926294655907942210215921501992035952262533576686097730156", "price": "0.27", "size": "202.49", "side": "SELL", "hash": "39f62480411627c9a612198211254df952e2bdf6", "best_bid": "0.25", "best_ask": "0.26"}], "timestamp": "1769384658938", "event_type": "price_change"}}
{"_local_timestamp": "2026-01-25T23:45:25.190832+00:00", "data": {"market": "0x4cf117dc50b3fe236db04d89e20fb082c253a5429132d2196933a12126fdd20f", "price_changes": [{"asset_id": "57183160858289786175926294655907942210215921501992035952262533576686097730156", "price": "0.24", "size": "100", "side": "BUY", "hash": "54e192f0af589cd4e0d66fffd3cddf3eaf45ba82", "best_bid": "0.25", "best_ask": "0.26"}, {"asset_id": "23527488931458270373542522838879642337196546203685403538870425011196572389776", "price": "0.76", "size": "100", "side": "SELL", "hash": "c073311a3174c54591cee92c3f9faa9271b0d614", "best_bid": "0.74", "best_ask": "0.75"}], "timestamp": "1769384725122", "event_type": "price_change"}}
{"_local_timestamp": "2026-01-25T23:45:25.198116+00:00", "data": {"market": "0x4cf117dc50b3fe236db04d89e20fb082c253a5429132d2196933a12126fdd20f", "price_changes": [{"asset_id": "57183160858289786175926294655907942210215921501992035952262533576686097730156", "price": "0.23", "size": "100", "side": "BUY", "hash": "54e192f0af589cd4e0d66fffd3cddf3eaf45ba82", "best_bid": "0.25", "best_ask": "0.26"}, {"asset_id": "23527488931458270373542522838879642337196546203685403538870425011196572389776", "price": "0.77", "size": "100", "side": "SELL", "hash": "c073311a3174c54591cee92c3f9faa9271b0d614", "best_bid": "0.74", "best_ask": "0.75"}], "timestamp": "1769384725122", "event_type": "price_change"}}
{"_local_timestamp": "2026-01-25T23:45:25.208396+00:00", "data": {"market": "0x4cf117dc50b3fe236db04d89e20fb082c253a5429132d2196933a12126fdd20f", "price_changes": [{"asset_id": "23527488931458270373542522838879642337196546203685403538870425011196572389776", "price": "0.74", "size": "0", "side": "BUY", "hash": "1ca60433a7c1ecc73387323bfffda29a8c373390", "best_bid": "0.73", "best_ask": "0.75"}, {"asset_id": "57183160858289786175926294655907942210215921501992035952262533576686097730156", "price": "0.26", "size": "0", "side": "SELL", "hash": "dac7c54b8f68a37672e9b2dbd825deededda6a3a", "best_bid": "0.25", "best_ask": "0.27"}], "timestamp": "1769384725122", "event_type": "price_change"}}
{"_local_timestamp": "2026-01-25T23:45:25.208720+00:00", "data": {"market": "0x4cf117dc50b3fe236db04d89e20fb082c253a5429132d2196933a12126fdd20f", "price_changes": [{"asset_id": "23527488931458270373542522838879642337196546203685403538870425011196572389776", "price": "0.73", "size": "175", "side": "BUY", "hash": "1ca60433a7c1ecc73387323bfffda29a8c373390", "best_bid": "0.73", "best_ask": "0.75"}, {"asset_id": "57183160858289786175926294655907942210215921501992035952262533576686097730156", "price": "0.27", "size": "175", "side": "SELL", "hash": "dac7c54b8f68a37672e9b2dbd825deededda6a3a", "best_bid": "0.25", "best_ask": "0.27"}], "timestamp": "1769384725122", "event_type": "price_change"}}
{"_local_timestamp": "2026-01-25T23:45:25.209100+00:00", "data": {"market": "0x4cf117dc50b3fe236db04d89e20fb082c253a5429132d2196933a12126fdd20f", "price_changes": [{"asset_id": "23527488931458270373542522838879642337196546203685403538870425011196572389776", "price": "0.72", "size": "400", "side": "BUY", "hash": "1ca60433a7c1ecc73387323bfffda29a8c373390", "best_bid": "0.73", "best_ask": "0.75"}, {"asset_id": "57183160858289786175926294655907942210215921501992035952262533576686097730156", "price": "0.28", "size": "400", "side": "SELL", "hash": "dac7c54b8f68a37672e9b2dbd825deededda6a3a", "best_bid": "0.25", "best_ask": "0.27"}], "timestamp": "1769384725122", "event_type": "price_change"}}
{"_local_timestamp": "2026-01-25T23:45:25.843780+00:00", "data": {"market": "0x4cf117dc50b3fe236db04d89e20fb082c253a5429132d2196933a12126fdd20f", "price_changes": [{"asset_id": "57183160858289786175926294655907942210215921501992035952262533576686097730156", "price": "0.23", "size": "166.66", "side": "BUY", "hash": "63761a0635bf4e1fcc10d8b6eac58295f0f28439", "best_bid": "0.25", "best_ask": "0.27"}, {"asset_id": "23527488931458270373542522838879642337196546203685403538870425011196572389776", "price": "0.77", "size": "166.66", "side": "SELL", "hash": "7f8df5186a8c46465d49d0c2e4f94bd0c2c17f1c", "best_bid": "0.73", "best_ask": "0.75"}], "timestamp": "1769384725772", "event_type": "price_change"}}
{"_local_timestamp": "2026-01-25T23:45:25.903494+00:00", "data": {"market": "0x4cf117dc50b3fe236db04d89e20fb082c253a5429132d2196933a12126fdd20f", "price_changes": [{"asset_id": "57183160858289786175926294655907942210215921501992035952262533576686097730156", "price": "0.25", "size": "319.02", "side": "BUY", "hash": "fa875de98f4b8dd9caf8734be8e4882accefbdc3", "best_bid": "0.25", "best_ask": "0.27"}, {"asset_id": "23527488931458270373542522838879642337196546203685403538870425011196572389776", "price": "0.75", "size": "319.02", "side": "SELL", "hash": "23b09f97ea30ae54a1513fe57ab2b6db32eec61d", "best_bid": "0.73", "best_ask": "0.75"}], "timestamp": "1769384725833", "event_type": "price_change"}}
{"_local_timestamp": "2026-01-25T23:45:25.950452+00:00", "data": {"market": "0x4cf117dc50b3fe236db04d89e20fb082c253a5429132d2196933a12126fdd20f", "price_changes": [{"asset_id": "57183160858289786175926294655907942210215921501992035952262533576686097730156", "price": "0.24", "size": "166.66", "side": "BUY", "hash": "b862bd8ad472bbe6a75fcfb713b2d3f84b629707", "best_bid": "0.25", "best_ask": "0.27"}, {"asset_id": "23527488931458270373542522838879642337196546203685403538870425011196572389776", "price": "0.76", "size": "166.66", "side": "SELL", "hash": "fff0a0662e1f63b9a8f1229a7332152a5f2593c6", "best_bid": "0.73", "best_ask": "0.75"}], "timestamp": "1769384725881", "event_type": "price_change"}}
{"_local_timestamp": "2026-01-25T23:45:26.406495+00:00", "data": {"market": "0x4cf117dc50b3fe236db04d89e20fb082c253a5429132d2196933a12126fdd20f", "price_changes": [{"asset_id": "23527488931458270373542522838879642337196546203685403538870425011196572389776", "price": "0.72", "size": "300", "side": "BUY", "hash": "915a288d7a424ba4eb3a122b31bbde5e5e05bbd3", "best_bid": "0.73", "best_ask": "0.75"}, {"asset_id": "57183160858289786175926294655907942210215921501992035952262533576686097730156", "price": "0.28", "size": "300", "side": "SELL", "hash": "8f4feccfe65e80af9dd00f9e3cfbb5e65342102b", "best_bid": "0.25", "best_ask": "0.27"}], "timestamp": "1769384726332", "event_type": "price_change"}}
{"_local_timestamp": "2026-01-25T23:45:29.593935+00:00", "data": {"market": "0x4cf117dc50b3fe236db04d89e20fb082c253a5429132d2196933a12126fdd20f", "price_changes": [{"asset_id": "23527488931458270373542522838879642337196546203685403538870425011196572389776", "price": "0.71", "size": "2100", "side": "BUY", "hash": "5b3cff2722caff4c30fdd0e1de65b739e24d0a56", "best_bid": "0.73", "best_ask": "0.75"}, {"asset_id": "57183160858289786175926294655907942210215921501992035952262533576686097730156", "price": "0.29", "size": "2100", "side": "SELL", "hash": "6b399f65837ebb68eb36b5638e7a4338631b3f91", "best_bid": "0.25", "best_ask": "0.27"}], "timestamp": "1769384729527", "event_type": "price_change"}}
{"_local_timestamp": "2026-01-25T23:45:48.431039+00:00", "data": {"market": "0x4cf117dc50b3fe236db04d89e20fb082c253a5429132d2196933a12126fdd20f", "price_changes": [{"asset_id": "57183160858289786175926294655907942210215921501992035952262533576686097730156", "price": "0.23", "size": "66.66", "side": "BUY", "hash": "6c4e19d6834ab28bf61791c08da12b74fd85d237", "best_bid": "0.25", "best_ask": "0.27"}, {"asset_id": "23527488931458270373542522838879642337196546203685403538870425011196572389776", "price": "0.77", "size": "66.66", "side": "SELL", "hash": "9604f97b0e665494df394cc1fa229270810c0bab", "best_bid": "0.73", "best_ask": "0.75"}], "timestamp": "1769384748352", "event_type": "price_change"}}
{"_local_timestamp": "2026-01-25T23:45:48.449722+00:00", "data": {"market": "0x4cf117dc50b3fe236db04d89e20fb082c253a5429132d2196933a12126fdd20f", "price_changes": [{"asset_id": "23527488931458270373542522838879642337196546203685403538870425011196572389776", "price": "0.71", "size": "2000", "side": "BUY", "hash": "07872bdbfe5383caaf2f3bfb8043aad9a5719135", "best_bid": "0.73", "best_ask": "0.75"}, {"asset_id": "57183160858289786175926294655907942210215921501992035952262533576686097730156", "price": "0.29", "size": "2000", "side": "SELL", "hash": "196686c91f84741aa98deabf719374391c15c765", "best_bid": "0.25", "best_ask": "0.27"}], "timestamp": "1769384748354", "event_type": "price_change"}}
{"_local_timestamp": "2026-01-25T23:46:00.724714+00:00", "data": {"market": "0x4cf117dc50b3fe236db04d89e20fb082c253a5429132d2196933a12126fdd20f", "price_changes": [{"asset_id": "23527488931458270373542522838879642337196546203685403538870425011196572389776", "price": "0.71", "size": "2100", "side": "BUY", "hash": "147e3b2b7d7032aaa6b585eea6c71f9665d26991", "best_bid": "0.73", "best_ask": "0.75"}, {"asset_id": "57183160858289786175926294655907942210215921501992035952262533576686097730156", "price": "0.29", "size": "2100", "side": "SELL", "hash": "7b838878d5430a5340e9dd28daafa488bfdeebbd", "best_bid": "0.25", "best_ask": "0.27"}], "timestamp": "1769384760654", "event_type": "price_change"}}
{"_local_timestamp": "2026-01-25T23:46:05.471205+00:00", "data": {"market": "0x4cf117dc50b3fe236db04d89e20fb082c253a5429132d2196933a12126fdd20f", "price_changes": [{"asset_id": "57183160858289786175926294655907942210215921501992035952262533576686097730156", "price": "0.23", "size": "166.66", "side": "BUY", "hash": "c85555d5d9901101e56f5c2fead1b1feaa8a8d4d", "best_bid": "0.25", "best_ask": "0.27"}, {"asset_id": "23527488931458270373542522838879642337196546203685403538870425011196572389776", "price": "0.77", "size": "166.66", "side": "SELL", "hash": "3d5375e814664e8d0963e29d076d2d4036a7dab8", "best_bid": "0.73", "best_ask": "0.75"}], "timestamp": "1769384765395", "event_type": "price_change"}}
{"_local_timestamp": "2026-01-25T23:47:14.427128+00:00", "data": {"market": "0x4cf117dc50b3fe236db04d89e20fb082c253a5429132d2196933a12126fdd20f", "price_changes": [{"asset_id": "57183160858289786175926294655907942210215921501992035952262533576686097730156", "price": "0.26", "size": "250", "side": "BUY", "hash": "e9aedc111ab48b2d265b2f32131058d03a31afbd", "best_bid": "0.26", "best_ask": "0.27"}, {"asset_id": "23527488931458270373542522838879642337196546203685403538870425011196572389776", "price": "0.74", "size": "250", "side": "SELL", "hash": "8b90e4b60d508b271b48cb6e43aaca73683ba338", "best_bid": "0.73", "best_ask": "0.74"}], "timestamp": "1769384834287", "event_type": "price_change"}}
{"_local_timestamp": "2026-01-25T23:47:15.896240+00:00", "data": {"market": "0x4cf117dc50b3fe236db04d89e20fb082c253a5429132d2196933a12126fdd20f", "price_changes": [{"asset_id": "57183160858289786175926294655907942210215921501992035952262533576686097730156", "price": "0.23", "size": "66.66", "side": "BUY", "hash": "39b04481dedf8addb972ea8e4d7a9b401cf9cfc2", "best_bid": "0.26", "best_ask": "0.27"}, {"asset_id": "23527488931458270373542522838879642337196546203685403538870425011196572389776", "price": "0.77", "size": "66.66", "side": "SELL", "hash": "5610e2ace0f18b90a057be96f15b81613126b5e5", "best_bid": "0.73", "best_ask": "0.74"}], "timestamp": "1769384835728", "event_type": "price_change"}}
{"_local_timestamp": "2026-01-25T23:47:18.937233+00:00", "data": {"market": "0x4cf117dc50b3fe236db04d89e20fb082c253a5429132d2196933a12126fdd20f", "price_changes": [{"asset_id": "57183160858289786175926294655907942210215921501992035952262533576686097730156", "price": "0.24", "size": "266.66", "side": "BUY", "hash": "996f9cb97c47b04efb144dcc4bc12b0b71251a03", "best_bid": "0.26", "best_ask": "0.27"}, {"asset_id": "23527488931458270373542522838879642337196546203685403538870425011196572389776", "price": "0.76", "size": "266.66", "side": "SELL", "hash": "78338aa32eeb1e60d354a4bab7d09b679eefed5e", "best_bid": "0.73", "best_ask": "0.74"}], "timestamp": "1769384838748", "event_type": "price_change"}}
{"_local_timestamp": "2026-01-25T23:47:42.813172+00:00", "data": {"market": "0x4cf117dc50b3fe236db04d89e20fb082c253a5429132d2196933a12126fdd20f", "price_changes": [{"asset_id": "23527488931458270373542522838879642337196546203685403538870425011196572389776", "price": "0.23", "size": "313.04", "side": "BUY", "hash": "ba06cf371728a428ffcfa338455d6646f2296406", "best_bid": "0.73", "best_ask": "0.74"}, {"asset_id": "57183160858289786175926294655907942210215921501992035952262533576686097730156", "price": "0.77", "size": "313.04", "side": "SELL", "hash": "8dc27a12eb64139f7a7425ddd5c1fa0b6eb5725b", "best_bid": "0.26", "best_ask": "0.27"}], "timestamp": "1769384862743", "event_type": "price_change"}}
{"_local_timestamp": "2026-01-25T23:47:42.981308+00:00", "data": {"market": "0x4cf117dc50b3fe236db04d89e20fb082c253a5429132d2196933a12126fdd20f", "price_changes": [{"asset_id": "23527488931458270373542522838879642337196546203685403538870425011196572389776", "price": "0.36", "size": "3115", "side": "BUY", "hash": "bdffa63b2741f3f5e6472b524f848facf82a91f2", "best_bid": "0.73", "best_ask": "0.74"}, {"asset_id": "57183160858289786175926294655907942210215921501992035952262533576686097730156", "price": "0.64", "size": "3115", "side": "SELL", "hash": "036e895c4bc95c0e7acd29af3675a6861289faba", "best_bid": "0.26", "best_ask": "0.27"}], "timestamp": "1769384862912", "event_type": "price_change"}}
{"_local_timestamp": "2026-01-25T23:48:02.838020+00:00", "data": {"market": "0x4cf117dc50b3fe236db04d89e20fb082c253a5429132d2196933a12126fdd20f", "price_changes": [{"asset_id": "57183160858289786175926294655907942210215921501992035952262533576686097730156", "price": "0.25", "size": "252.36", "side": "BUY", "hash": "f7f5e22fba2863389285ceb08f101d3326c1dd27", "best_bid": "0.26", "best_ask": "0.27"}, {"asset_id": "23527488931458270373542522838879642337196546203685403538870425011196572389776", "price": "0.75", "size": "252.36", "side": "SELL", "hash": "dcc4996d79eca9d7d6ab43e651c308d048e878f1", "best_bid": "0.73", "best_ask": "0.74"}], "timestamp": "1769384882764", "event_type": "price_change"}}
{"_local_timestamp": "2026-01-25T23:48:02.838724+00:00", "data": {"market": "0x4cf117dc50b3fe236db04d89e20fb082c253a5429132d2196933a12126fdd20f", "price_changes": [{"asset_id": "57183160858289786175926294655907942210215921501992035952262533576686097730156", "price": "0.24", "size": "200", "side": "BUY", "hash": "f7f5e22fba2863389285ceb08f101d3326c1dd27", "best_bid": "0.26", "best_ask": "0.27"}, {"asset_id": "23527488931458270373542522838879642337196546203685403538870425011196572389776", "price": "0.76", "size": "200", "side": "SELL", "hash": "dcc4996d79eca9d7d6ab43e651c308d048e878f1", "best_bid": "0.73", "best_ask": "0.74"}], "timestamp": "1769384882764", "event_type": "price_change"}}
{"_local_timestamp": "2026-01-25T23:48:02.839051+00:00", "data": {"market": "0x4cf117dc50b3fe236db04d89e20fb082c253a5429132d2196933a12126fdd20f", "price_changes": [{"asset_id": "57183160858289786175926294655907942210215921501992035952262533576686097730156", "price": "0.23", "size": "0", "side": "BUY", "hash": "f7f5e22fba2863389285ceb08f101d3326c1dd27", "best_bid": "0.26", "best_ask": "0.27"}, {"asset_id": "23527488931458270373542522838879642337196546203685403538870425011196572389776", "price": "0.77", "size": "0", "side": "SELL", "hash": "dcc4996d79eca9d7d6ab43e651c308d048e878f1", "best_bid": "0.73", "best_ask": "0.74"}], "timestamp": "1769384882764", "event_type": "price_change"}}
{"_local_timestamp": "2026-01-25T23:49:13.240600+00:00", "data": {"market": "0x4cf117dc50b3fe236db04d89e20fb082c253a5429132d2196933a12126fdd20f", "price_changes": [{"asset_id": "23527488931458270373542522838879642337196546203685403538870425011196572389776", "price": "0.37", "size": "0", "side": "BUY", "hash": "49b3930d523ed325199ef704d3237d385ea6c9f3", "best_bid": "0.73", "best_ask": "0.74"}, {"asset_id": "57183160858289786175926294655907942210215921501992035952262533576686097730156", "price": "0.63", "size": "0", "side": "SELL", "hash": "c03932e3f92bbfd760d5b30bb25d85b77603db87", "best_bid": "0.26", "best_ask": "0.27"}], "timestamp": "1769384953151", "event_type": "price_change"}}
{"_local_timestamp": "2026-01-25T23:49:13.292185+00:00", "data": {"market": "0x4cf117dc50b3fe236db04d89e20fb082c253a5429132d2196933a12126fdd20f", "price_changes": [{"asset_id": "23527488931458270373542522838879642337196546203685403538870425011196572389776", "price": "0.37", "size": "5", "side": "BUY", "hash": "d09efc94f4fddaccf9045aaaac9a25a56cf81196", "best_bid": "0.73", "best_ask": "0.74"}, {"asset_id": "57183160858289786175926294655907942210215921501992035952262533576686097730156", "price": "0.63", "size": "5", "side": "SELL", "hash": "52b5d6ac39b59d4cd0128c04d63b1ca6bd297f11", "best_bid": "0.26", "best_ask": "0.27"}], "timestamp": "1769384953199", "event_type": "price_change"}}
{"_local_timestamp": "2026-01-25T23:49:25.483964+00:00", "data": {"market": "0x4cf117dc50b3fe236db04d89e20fb082c253a5429132d2196933a12126fdd20f", "price_changes": [{"asset_id": "23527488931458270373542522838879642337196546203685403538870425011196572389776", "price": "0.23", "size": "263.04", "side": "BUY", "hash": "853eb58dbf5400cbb929126cb537e1000405b2c7", "best_bid": "0.73", "best_ask": "0.74"}, {"asset_id": "57183160858289786175926294655907942210215921501992035952262533576686097730156", "price": "0.77", "size": "263.04", "side": "SELL", "hash": "fe509b51e222d6cd35595f1c0d789d34955e3fac", "best_bid": "0.26", "best_ask": "0.27"}], "timestamp": "1769384965293", "event_type": "price_change"}}
{"_local_timestamp": "2026-01-25T23:49:25.903640+00:00", "data": {"market": "0x4cf117dc50b3fe236db04d89e20fb082c253a5429132d2196933a12126fdd20f", "price_changes": [{"asset_id": "23527488931458270373542522838879642337196546203685403538870425011196572389776", "price": "0.35", "size": "308.2", "side": "BUY", "hash": "d4b4acdc82f0188167a2d39b635a9f9a636ae9c8", "best_bid": "0.73", "best_ask": "0.74"}, {"asset_id": "57183160858289786175926294655907942210215921501992035952262533576686097730156", "price": "0.65", "size": "308.2", "side": "SELL", "hash": "ed5d10f758dc01db88ab5f7febb8e6fd16c3d204", "best_bid": "0.26", "best_ask": "0.27"}], "timestamp": "1769384965770", "event_type": "price_change"}}
{"_local_timestamp": "2026-01-25T23:49:41.781843+00:00", "data": {"market": "0x4cf117dc50b3fe236db04d89e20fb082c253a5429132d2196933a12126fdd20f", "price_changes": [{"asset_id": "23527488931458270373542522838879642337196546203685403538870425011196572389776", "price": "0.35", "size": "258.2", "side": "BUY", "hash": "86a19dcc3ab42a0ed66fb8c3790af11612133688", "best_bid": "0.73", "best_ask": "0.74"}, {"asset_id": "57183160858289786175926294655907942210215921501992035952262533576686097730156", "price": "0.65", "size": "258.2", "side": "SELL", "hash": "e4bbff18f6bd7543c22868a2785b6ac56489d942", "best_bid": "0.26", "best_ask": "0.27"}], "timestamp": "1769384981655", "event_type": "price_change"}}
{"_local_timestamp": "2026-01-25T23:49:41.783057+00:00", "data": {"market": "0x4cf117dc50b3fe236db04d89e20fb082c253a5429132d2196933a12126fdd20f", "price_changes": [{"asset_id": "23527488931458270373542522838879642337196546203685403538870425011196572389776", "price": "0.23", "size": "213.04", "side": "BUY", "hash": "86a19dcc3ab42a0ed66fb8c3790af11612133688", "best_bid": "0.73", "best_ask": "0.74"}, {"asset_id": "57183160858289786175926294655907942210215921501992035952262533576686097730156", "price": "0.77", "size": "213.04", "side": "SELL", "hash": "e4bbff18f6bd7543c22868a2785b6ac56489d942", "best_bid": "0.26", "best_ask": "0.27"}], "timestamp": "1769384981655", "event_type": "price_change"}}
{"_local_timestamp": "2026-01-25T23:49:42.412698+00:00", "data": {"market": "0x4cf117dc50b3fe236db04d89e20fb082c253a5429132d2196933a12126fdd20f", "price_changes": [{"asset_id": "23527488931458270373542522838879642337196546203685403538870425011196572389776", "price": "0.36", "size": "3165", "side": "BUY", "hash": "e0aa0bc3b2de96f122aa323ec6164f0e8a645ea5", "best_bid": "0.73", "best_ask": "0.74"}, {"asset_id": "57183160858289786175926294655907942210215921501992035952262533576686097730156", "price": "0.64", "size": "3165", "side": "SELL", "hash": "a897805906ac515c40567ed40467fb13471da629", "best_bid": "0.26", "best_ask": "0.27"}], "timestamp": "1769384982231", "event_type": "price_change"}}
{"_local_timestamp": "2026-01-25T23:49:42.416588+00:00", "data": {"market": "0x4cf117dc50b3fe236db04d89e20fb082c253a5429132d2196933a12126fdd20f", "price_changes": [{"asset_id": "23527488931458270373542522838879642337196546203685403538870425011196572389776", "price": "0.24", "size": "350", "side": "BUY", "hash": "6171c81e42d19b841c82345483cdd0a1cc39e4bb", "best_bid": "0.73", "best_ask": "0.74"}, {"asset_id": "57183160858289786175926294655907942210215921501992035952262533576686097730156", "price": "0.76", "size": "350", "side": "SELL", "hash": "812f13b8e2ad325394c29e72a5d4b9c5040a9374", "best_bid": "0.26", "best_ask": "0.27"}], "timestamp": "1769384982256", "event_type": "price_change"}}
{"_local_timestamp": "2026-01-25T23:50:02.705744+00:00", "data": {"market": "0x4cf117dc50b3fe236db04d89e20fb082c253a5429132d2196933a12126fdd20f", "price_changes": [{"asset_id": "23527488931458270373542522838879642337196546203685403538870425011196572389776", "price": "0.16", "size": "0", "side": "BUY", "hash": "73b8b97b04bee14b13accb95b69ca453726d2e6d", "best_bid": "0.73", "best_ask": "0.74"}, {"asset_id": "57183160858289786175926294655907942210215921501992035952262533576686097730156", "price": "0.84", "size": "0", "side": "SELL", "hash": "4184d49adecc2c1887fc5cbb7dfd33f66ff98e93", "best_bid": "0.26", "best_ask": "0.27"}], "timestamp": "1769385002289", "event_type": "price_change"}}
{"_local_timestamp": "2026-01-25T23:50:13.965709+00:00", "data": {"market": "0x4cf117dc50b3fe236db04d89e20fb082c253a5429132d2196933a12126fdd20f", "price_changes": [{"asset_id": "23527488931458270373542522838879642337196546203685403538870425011196572389776", "price": "0.76", "size": "520.39", "side": "SELL", "hash": "ebad1b0e64b89ab8d1a4af4f75553c5ca1fa3dc8", "best_bid": "0.73", "best_ask": "0.74"}, {"asset_id": "57183160858289786175926294655907942210215921501992035952262533576686097730156", "price": "0.24", "size": "520.39", "side": "BUY", "hash": "3289ccf277b3ae66a19e97ff222cb4ec931cb622", "best_bid": "0.26", "best_ask": "0.27"}], "timestamp": "1769385013897", "event_type": "price_change"}}
