{"_local_timestamp": "2026-01-25T23:40:30.675196+00:00", "data": [{"market": "0xe3864657b2cdf2e5a411c7337221289921f8b3a2c0bdd27ebc25474d704a13f8", "asset_id": "97007404868873890591146763837023614399323754161304727997920406219617464294000", "timestamp": "1769384285144", "hash": "9026c01b698248fb25f5dda7e91f1bd0c70ec05c", "bids": [{"price": "0.001", "size": "1102747.09"}, {"price": "0.002", "size": "250"}, {"price": "0.003", "size": "30400"}, {"price": "0.004", "size": "8.67"}, {"price": "0.006", "size": "200"}, {"price": "0.01", "size": "10"}, {"price": "0.011", "size": "5.3"}, {"price": "0.02", "size": "79.47"}, {"price": "0.021", "size": "20700"}, {"price": "0.022", "size": "311.68"}, {"price": "0.023", "size": "11.81"}, {"price": "0.05", "size": "30"}, {"price": "0.051", "size": "39"}, {"price": "0.052", "size": "631.86"}, {"price": "0.08", "size": "300"}, {"price": "0.082", "size": "83.62"}, {"price": "0.083", "size": "6.07"}, {"price": "0.158", "size": "38"}, {"price": "0.159", "size": "43.12"}, {"price": "0.217", "size": "31.59"}, {"price": "0.218", "size": "5.13"}, {"price": "0.55", "size": "421.71"}, {"price": "0.551", "size": "5"}, {"price": "0.552", "size": "12.42"}, {"price": "0.644", "size": "10.64"}, {"price": "0.645", "size": "20"}, {"price": "0.895", "size": "6.66"}, {"price": "0.896", "size": "6"}, {"price": "0.951", "size": "5"}, {"price": "0.996", "size": "11.84"}, {"price": "0.997", "size": "179.24"}], "asks": [{"price": "0.999", "size": "1426.58"}], "event_type": "book", "last_trade_price": ""}, {"market": "0x67eb32405b2ad24182b8575eb560b3b087baa20340302a079bb8138637ed1b47", "asset_id": "91614728309695910310598383443496140750308657331105979804609645991161575447633", "timestamp": "1769383567552", "hash": "53490ab0cba967ea04dd8abe69a2ed7407e6e1b7", "bids": [{"price": "0.001", "size": "1104251.99"}, {"price": "0.002", "size": "250"}, {"price": "0.003", "size": "30400"}, {"price": "0.004", "size": "8.65"}, {"price": "0.006", "size": "200"}, {"price": "0.01", "size": "10"}, {"price": "0.011", "size": "5.73"}, {"price": "0.021", "size": "12700"}, {"price": "0.026", "size": "461.53"}, {"price": "0.027", "size": "5.17"}, {"price": "0.05", "size": "30"}, {"price": "0.051", "size": "39"}, {"price": "0.056", "size": "714.28"}, {"price": "0.057", "size": "5.78"}, {"price": "0.08", "size": "300"}, {"price": "0.128", "size": "5"}, {"price": "0.135", "size": "88.88"}, {"price": "0.136", "size": "10.42"}, {"price": "0.223", "size": "10"}, {"price": "0.241", "size": "8"}, {"price": "0.242", "size": "49.58"}, {"price": "0.718", "size": "6.66"}, {"price": "0.719", "size": "26"}, {"price": "0.995", "size": "34"}, {"price": "0.997", "size": "48.13"}, {"price": "0.998", "size": "545.53"}], "asks": [{"price": "0.999", "size": "1401.8"}], "event_type": "book", "last_trade_price": ""}, {"market": "0xc2208ae9f51a9ff504d662c822859251191fcdc92564076a9c71e56ec8745898", "asset_id": "63686700482070758333025925354048148730451881595309572583934588980314675544376", "timestamp": "1769383866729", "hash": "36ca862ca6d523b39388de52bdf8a54c7b96fe33", "bids": [{"price": "0.001", "size": "1104252.67"}, {"price": "0.002", "size": "250"}, {"price": "0.003", "size": "30400"}, {"price": "0.004", "size": "5.33"}, {"price": "0.006", "size": "200"}, {"price": "0.01", "size": "10"}, {"price": "0.011", "size": "6.3"}, {"price": "0.021", "size": "12700"}, {"price": "0.025", "size": "320"}, {"price": "0.026", "size": "7.5"}, {"price": "0.05", "size": "30"}, {"price": "0.051", "size": "39"}, {"price": "0.066", "size": "100"}, {"price": "0.067", "size": "719.4"}, {"price": "0.068", "size": "7.07"}, {"price": "0.08", "size": "300"}, {"price": "0.081", "size": "98.76"}, {"price": "0.158", "size": "30"}, {"price": "0.176", "size": "45.45"}, {"price": "0.177", "size": "6.77"}, {"price": "0.223", "size": "24"}, {"price": "0.224", "size": "35.71"}, {"price": "0.281", "size": "28.46"}, {"price": "0.282", "size": "7"}, {"price": "0.823", "size": "39"}, {"price": "0.824", "size": "20"}, {"price": "0.894", "size": "6.66"}, {"price": "0.895", "size": "6"}, {"price": "0.996", "size": "55.04"}, {"price": "0.997", "size": "351.92"}, {"price": "0.998", "size": "57.1"}], "asks": [{"price": "0.999", "size": "1261.99"}], "event_type": "book", "last_trade_price": "0.001"}, {"market": "0x489bfb9597099df16b34140399d2a1517e0a89623dabe94a3fccd4b48cab8bd3", "asset_id": "33913946998395403271106619237556153568227311613585470108892083199366217498076", "timestamp": "1769384246570", "hash": "040bcab0742be29429e4614ee9c09baf9e09c6f1", "bids": [{"price": "0.001", "size": "4452.8"}, {"price": "0.002", "size": "526.54"}, {"price": "0.003", "size": "134.82"}, {"price": "0.004", "size": "177.97"}, {"price": "0.005", "size": "143.67"}, {"price": "0.008", "size": "20"}, {"price": "0.009", "size": "17.02"}, {"price": "0.01", "size": "10"}, {"price": "0.011", "size": "5.92"}, {"price": "0.038", "size": "177.96"}, {"price": "0.04", "size": "22.03"}, {"price": "0.041", "size": "55.78"}], "asks": [{"price": "0.999", "size": "513144"}, {"price": "0.998", "size": "250"}, {"price": "0.997", "size": "400"}, {"price": "0.994", "size": "200"}, {"price": "0.99", "size": "110010"}, {"price": "0.989", "size": "8.65"}, {"price": "0.979", "size": "1026.53"}, {"price": "0.95", "size": "30"}, {"price": "0.949", "size": "673.45"}, {"price": "0.886", "size": "3100"}, {"price": "0.885", "size": "59.62"}, {"price": "0.854", "size": "23"}, {"price": "0.853", "size": "46.64"}, {"price": "0.5", "size": "93.71"}, {"price": "0.499", "size": "300"}, {"price": "0.4", "size": "211.42"}, {"price": "0.399", "size": "11.4"}, {"price": "0.2", "size": "200"}, {"price": "0.13", "size": "6.3"}, {"price": "0.106", "size": "60.24"}, {"price": "0.098", "size": "200"}, {"price": "0.095", "size": "88.49"}], "event_type": "book", "last_trade_price": "0.905"}, {"market": "0x0d9cd522b589469a0ff19c75d5bbc716b6ed5e0d2613de17222467f25e585f33", "asset_id": "112165380855456462124754420066042767550882650348002066410809452589696171922898", "timestamp": "1769383881519", "hash": "58cb3054ab6c77573b6d2121548b3619d4fc79d9", "bids": [{"price": "0.001", "size": "1102759.34"}, {"price": "0.002", "size": "250"}, {"price": "0.003", "size": "20400"}, {"price": "0.004", "size": "8.87"}, {"price": "0.006", "size": "200"}, {"price": "0.01", "size": "10"}, {"price": "0.011", "size": "5.42"}, {"price": "0.022", "size": "1063.63"}, {"price": "0.023", "size": "6.02"}, {"price": "0.05", "size": "30"}, {"price": "0.051", "size": "39"}, {"price": "0.052", "size": "5.08"}, {"price": "0.054", "size": "24.53"}, {"price": "0.056", "size": "100"}, {"price": "0.057", "size": "100"}, {"price": "0.058", "size": "637.93"}, {"price": "0.08", "size": "300"}, {"price": "0.081", "size": "98.76"}, {"price": "0.116", "size": "17"}, {"price": "0.118", "size": "67.79"}, {"price": "0.119", "size": "6"}, {"price": "0.12", "size": "6"}, {"price": "0.121", "size": "6.38"}, {"price": "0.523", "size": "81"}, {"price": "0.524", "size": "15.26"}, {"price": "0.699", "size": "11.44"}, {"price": "0.7", "size": "20"}, {"price": "0.93", "size": "25"}, {"price": "0.951", "size": "10"}, {"price": "0.995", "size": "104"}, {"price": "0.996", "size": "17.14"}], "asks": [{"price": "0.999", "size": "4628.08"}], "event_type": "book", "last_trade_price": ""}, {"market": "0x80909e3487a955ccc8aab8b13f33d92dc8ac1159d4678ad620d7df16860221b9", "asset_id": "31657781766585052745291759349392870581850746686763378395917155836133268961392", "timestamp": "1769383970518", "hash": "b3fbf487c4f80f84bbc82964872c1c26dcb9ea3b", "bids": [{"price": "0.001", "size": "1104254.02"}, {"price": "0.002", "size": "250"}, {"price": "0.003", "size": "400"}, {"price": "0.004", "size": "8.68"}, {"price": "0.006", "size": "200"}, {"price": "0.01", "size": "10"}, {"price": "0.011", "size": "5.74"}, {"price": "0.021", "size": "6700"}, {"price": "0.025", "size": "384"}, {"price": "0.026", "size": "5.38"}, {"price": "0.05", "size": "30"}, {"price": "0.051", "size": "39"}, {"price": "0.054", "size": "700"}, {"price": "0.055", "size": "174.54"}, {"price": "0.056", "size": "8.1"}, {"price": "0.084", "size": "414.28"}, {"price": "0.156", "size": "25"}, {"price": "0.167", "size": "57.48"}, {"price": "0.168", "size": "7.72"}, {"price": "0.249", "size": "38.55"}, {"price": "0.25", "size": "8"}, {"price": "0.877", "size": "390"}, {"price": "0.878", "size": "14.53"}, {"price": "0.879", "size": "20"}, {"price": "0.892", "size": "137.15"}, {"price": "0.951", "size": "10"}, {"price": "0.995", "size": "37.71"}, {"price": "0.996", "size": "43.74"}], "asks": [{"price": "0.999", "size": "1341.08"}], "event_type": "book", "last_trade_price": "0.001"}, {"market": "0x6a72f5b1d7edf1261156080ddc026da3d80a78834c12925a7bfea4a8aa5b8fb8", "asset_id": "18638298170773700688520436893150989158645425879508160426041188051588302722446", "timestamp": "1769383608986", "hash": "0b11190e7afdaa63be979a8460c184cfe85e4d0e", "bids": [{"price": "0.001", "size": "1102634.49"}, {"price": "0.002", "size": "250"}, {"price": "0.003", "size": "20400"}, {"price": "0.004", "size": "9.56"}, {"price": "0.006", "size": "200"}, {"price": "0.01", "size": "10"}, {"price": "0.011", "size": "5.83"}, {"price": "0.02", "size": "79.47"}, {"price": "0.024", "size": "1100"}, {"price": "0.025", "size": "8.57"}, {"price": "0.05", "size": "530"}, {"price": "0.051", "size": "39"}, {"price": "0.071", "size": "200"}, {"price": "0.072", "size": "138.45"}, {"price": "0.081", "size": "418.51"}, {"price": "0.146", "size": "27"}, {"price": "0.164", "size": "58.53"}, {"price": "0.165", "size": "7.87"}, {"price": "0.259", "size": "37.06"}, {"price": "0.26", "size": "7"}, {"price": "0.887", "size": "6.66"}, {"price": "0.888", "size": "26"}, {"price": "0.951", "size": "5"}, {"price": "0.996", "size": "14.06"}, {"price": "0.997", "size": "191.91"}], "asks": [{"price": "0.999", "size": "1440.57"}], "event_type": "book", "last_trade_price": ""}, {"market": "0x67eb32405b2ad24182b8575eb560b3b087baa20340302a079bb8138637ed1b47", "asset_id": "23177234539005086745924487565572514732873310188830333623513053312024465699839", "timestamp": "1769383567552", "hash": "8bde8575cce73763eebf6b9e23b25b0bda10b1ca", "bids": [{"price": "0.001", "size": "1401.8"}], "asks": [{"price": "0.999", "size": "1104251.99"}, {"price": "0.998", "size": "250"}, {"price": "0.997", "size": "30400"}, {"price": "0.996", "size": "8.65"}, {"price": "0.994", "size": "200"}, {"price": "0.99", "size": "10"}, {"price": "0.989", "size": "5.73"}, {"price": "0.979", "size": "12700"}, {"price": "0.974", "size": "461.53"}, {"price": "0.973", "size": "5.17"}, {"price": "0.95", "size": "30"}, {"price": "0.949", "size": "39"}, {"price": "0.944", "size": "714.28"}, {"price": "0.943", "size": "5.78"}, {"price": "0.92", "size": "300"}, {"price": "0.872", "size": "5"}, {"price": "0.865", "size": "88.88"}, {"price": "0.864", "size": "10.42"}, {"price": "0.777", "size": "10"}, {"price": "0.759", "size": "8"}, {"price": "0.758", "size": "49.58"}, {"price": "0.282", "size": "6.66"}, {"price": "0.281", "size": "26"}, {"price": "0.005", "size": "34"}, {"price": "0.003", "size": "48.13"}, {"price": "0.002", "size": "545.53"}], "event_type": "book", "last_trade_price": ""}, {"market": "0xe3864657b2cdf2e5a411c7337221289921f8b3a2c0bdd27ebc25474d704a13f8", "asset_id": "10134904388540700634522656115458142735286617187949700358160575419238829110702", "timestamp": "1769384285144", "hash": "7e1c66b205ec19b6ebd1245f0253c6d74473967b", "bids": [{"price": "0.001", "size": "1426.58"}], "asks": [{"price": "0.999", "size": "1102747.09"}, {"price": "0.998", "size": "250"}, {"price": "0.997", "size": "30400"}, {"price": "0.996", "size": "8.67"}, {"price": "0.994", "size": "200"}, {"price": "0.99", "size": "10"}, {"price": "0.989", "size": "5.3"}, {"price": "0.98", "size": "79.47"}, {"price": "0.979", "size": "20700"}, {"price": "0.978", "size": "311.68"}, {"price": "0.977", "size": "11.81"}, {"price": "0.95", "size": "30"}, {"price": "0.949", "size": "39"}, {"price": "0.948", "size": "631.86"}, {"price": "0.92", "size": "300"}, {"price": "0.918", "size": "83.62"}, {"price": "0.917", "size": "6.07"}, {"price": "0.842", "size": "38"}, {"price": "0.841", "size": "43.12"}, {"price": "0.783", "size": "31.59"}, {"price": "0.782", "size": "5.13"}, {"price": "0.45", "size": "421.71"}, {"price": "0.449", "size": "5"}, {"price": "0.448", "size": "12.42"}, {"price": "0.356", "size": "10.64"}, {"price": "0.355", "size": "20"}, {"price": "0.105", "size": "6.66"}, {"price": "0.104", "size": "6"}, {"price": "0.049", "size": "5"}, {"price": "0.004", "size": "11.84"}, {"price": "0.003", "size": "179.24"}], "event_type": "book", "last_trade_price": ""}, {"market": "0x6f3819aefa464a63c3a54d9e079ad59ba194b015de3f4dae4f16d822eeb5dd2e", "asset_id": "88141572307574703189103808906541737578361491725632656938888428716809889579606", "timestamp": "1769384382654", "hash": "7fe1608f72c7d83ba9598594e4dcd6bfe8d8a649", "bids": [{"price": "0.001", "size": "4371.47"}], "asks": [{"price": "0.999", "size": "1104252.01"}, {"price": "0.998", "size": "250"}, {"price": "0.997", "size": "30400"}, {"price": "0.996", "size": "8.67"}, {"price": "0.994", "size": "200"}, {"price": "0.99", "size": "10"}, {"price": "0.989", "size": "39.5"}, {"price": "0.974", "size": "1007.69"}, {"price": "0.973", "size": "7.98"}, {"price": "0.95", "size": "30"}, {"price": "0.949", "size": "639"}, {"price": "0.929", "size": "100"}, {"price": "0.928", "size": "411.11"}, {"price": "0.92", "size": "300"}, {"price": "0.919", "size": "98.76"}, {"price": "0.846", "size": "26"}, {"price": "0.833", "size": "47.9"}, {"price": "0.832", "size": "7.74"}, {"price": "0.774", "size": "8"}, {"price": "0.773", "size": "35.24"}, {"price": "0.477", "size": "56"}, {"price": "0.476", "size": "15.26"}, {"price": "0.177", "size": "74"}, {"price": "0.14", "size": "13.33"}, {"price": "0.139", "size": "13.33"}, {"price": "0.138", "size": "13.33"}, {"price": "0.137", "size": "20"}, {"price": "0.003", "size": "10.77"}, {"price": "0.002", "size": "324.75"}], "event_type": "book", "last_trade_price": "0.001"}, {"market": "0x1c621820bae34fb023564d9b54a27b7c45ca41fdc4c6cb3aee5a6d5b6ade5e17", "asset_id": "21106275077955042781625146107573621674469940262636359280368889204114942709475", "timestamp": "1769384339345", "hash": "cf186294fc887bdfc77f59627eb458e1298768ab", "bids": [{"price": "0.001", "size": "1104251.99"}, {"price": "0.002", "size": "60250"}, {"price": "0.003", "size": "400"}, {"price": "0.004", "size": "8.65"}, {"price": "0.006", "size": "200"}, {"price": "0.01", "size": "10"}, {"price": "0.011", "size": "21000"}, {"price": "0.012", "size": "5.65"}, {"price": "0.022", "size": "12700"}, {"price": "0.033", "size": "207.79"}, {"price": "0.034", "size": "6.07"}, {"price": "0.05", "size": "530"}, {"price": "0.051", "size": "39"}, {"price": "0.071", "size": "3000"}, {"price": "0.072", "size": "309.76"}, {"price": "0.078", "size": "87.91"}, {"price": "0.079", "size": "6.4"}, {"price": "0.13", "size": "52.74"}, {"price": "0.132", "size": "217"}, {"price": "0.207", "size": "9"}, {"price": "0.209", "size": "32.8"}, {"price": "0.21", "size": "5.57"}, {"price": "0.523", "size": "91"}, {"price": "0.524", "size": "13.08"}, {"price": "0.622", "size": "11.02"}, {"price": "0.623", "size": "20"}, {"price": "0.895", "size": "174.1"}, {"price": "0.898", "size": "6.66"}, {"price": "0.899", "size": "6"}, {"price": "0.951", "size": "5"}, {"price": "0.995", "size": "62.73"}, {"price": "0.996", "size": "95.46"}], "asks": [{"price": "0.999", "size": "1013"}, {"price": "0.998", "size": "5"}], "event_type": "book", "last_trade_price": ""}, {"market": "0xc2208ae9f51a9ff504d662c822859251191fcdc92564076a9c71e56ec8745898", "asset_id": "93167397740879213220913668801256024250509018532336830527062786853329354974190", "timestamp": "1769383866729", "hash": "44110b852d52951cc29ab08cf29f557d3faea5d1", "bids": [{"price": "0.001", "size": "1261.99"}], "asks": [{"price": "0.999", "size": "1104252.67"}, {"price": "0.998", "size": "250"}, {"price": "0.997", "size": "30400"}, {"price": "0.996", "size": "5.33"}, {"price": "0.994", "size": "200"}, {"price": "0.99", "size": "10"}, {"price": "0.989", "size": "6.3"}, {"price": "0.979", "size": "12700"}, {"price": "0.975", "size": "320"}, {"price": "0.974", "size": "7.5"}, {"price": "0.95", "size": "30"}, {"price": "0.949", "size": "39"}, {"price": "0.934", "size": "100"}, {"price": "0.933", "size": "719.4"}, {"price": "0.932", "size": "7.07"}, {"price": "0.92", "size": "300"}, {"price": "0.919", "size": "98.76"}, {"price": "0.842", "size": "30"}, {"price": "0.824", "size": "45.45"}, {"price": "0.823", "size": "6.77"}, {"price": "0.777", "size": "24"}, {"price": "0.776", "size": "35.71"}, {"price": "0.719", "size": "28.46"}, {"price": "0.718", "size": "7"}, {"price": "0.177", "size": "39"}, {"price": "0.176", "size": "20"}, {"price": "0.106", "size": "6.66"}, {"price": "0.105", "size": "6"}, {"price": "0.004", "size": "55.04"}, {"price": "0.003", "size": "351.92"}, {"price": "0.002", "size": "57.1"}], "event_type": "book", "last_trade_price": "0.001"}, {"market": "0x55d7602157ad134b7668cc486bb9c85096356c0dbd055c61344426b2d8c8291a", "asset_id": "7048930749192506070218770660352360569449638501759983423471267709999373115496", "timestamp": "1769384421420", "hash": "43814d8f905f0a54d741d9eb132d9ec73257b736", "bids": [{"price": "0.001", "size": "1104242.26"}, {"price": "0.002", "size": "30250"}, {"price": "0.003", "size": "406.69"}, {"price": "0.006", "size": "200"}, {"price": "0.007", "size": "10.55"}, {"price": "0.01", "size": "10"}, {"price": "0.011", "size": "12000"}, {"price": "0.021", "size": "12700"}, {"price": "0.022", "size": "6.42"}, {"price": "0.025", "size": "320"}, {"price": "0.05", "size": "30"}, {"price": "0.051", "size": "39"}, {"price": "0.052", "size": "5.15"}, {"price": "0.056", "size": "142.85"}, {"price": "0.057", "size": "600"}, {"price": "0.058", "size": "100"}, {"price": "0.08", "size": "300"}, {"price": "0.081", "size": "98.76"}, {"price": "0.117", "size": "68.37"}, {"price": "0.118", "size": "6.53"}, {"price": "0.119", "size": "6"}, {"price": "0.12", "size": "6"}, {"price": "0.226", "size": "8"}, {"price": "0.227", "size": "35.24"}, {"price": "0.699", "size": "11.44"}, {"price": "0.7", "size": "20"}, {"price": "0.919", "size": "13"}, {"price": "0.92", "size": "13"}, {"price": "0.922", "size": "13"}, {"price": "0.924", "size": "13"}, {"price": "0.925", "size": "21"}, {"price": "0.927", "size": "30"}, {"price": "0.929", "size": "23"}, {"price": "0.99", "size": "21"}, {"price": "0.994", "size": "101.18"}], "asks": [{"price": "0.999", "size": "1206"}, {"price": "0.998", "size": "5"}, {"price": "0.997", "size": "13835"}], "event_type": "book", "last_trade_price": ""}, {"market": "0x720db82e6ae3132de241c4190b7f72585d5fc2f1364519e814d51f3ec29bf8c6", "asset_id": "7359117152396849276912471939244269631176254624751482772547064208568026511810", "timestamp": "1769383822640", "hash": "9cdd79d8e5448c1ea2197de123554d1fea7b165a", "bids": [{"price": "0.001", "size": "1104287"}, {"price": "0.002", "size": "250"}, {"price": "0.003", "size": "30406.62"}, {"price": "0.006", "size": "200"}, {"price": "0.007", "size": "16.15"}, {"price": "0.01", "size": "10"}, {"price": "0.011", "size": "9.09"}, {"price": "0.033", "size": "12700"}, {"price": "0.034", "size": "352.94"}, {"price": "0.05", "size": "530"}, {"price": "0.051", "size": "39"}, {"price": "0.052", "size": "8.1"}, {"price": "0.071", "size": "9000"}, {"price": "0.072", "size": "466.66"}, {"price": "0.08", "size": "300"}, {"price": "0.153", "size": "26"}, {"price": "0.16", "size": "75"}, {"price": "0.161", "size": "8.29"}, {"price": "0.319", "size": "6"}, {"price": "0.32", "size": "37.5"}, {"price": "0.702", "size": "6.66"}, {"price": "0.703", "size": "26"}, {"price": "0.995", "size": "34"}, {"price": "0.997", "size": "49.53"}, {"price": "0.998", "size": "529.54"}], "asks": [{"price": "0.999", "size": "912.62"}], "event_type": "book", "last_trade_price": ""}, {"market": "0x23e13d00bf97cf1f66a9cc9c73b0d9122ffdcaa00391dcbcf7c194920d2c637a", "asset_id": "76314120704895570216363719360303120994834914074725880204393164758332011771623", "timestamp": "1769384424953", "hash": "6fff2990519a30f77a6d5c4352f1d51ed0dc0ca3", "bids": [{"price": "0.001", "size": "1329.73"}], "asks": [{"price": "0.999", "size": "1104251.99"}, {"price": "0.998", "size": "30250"}, {"price": "0.997", "size": "400"}, {"price": "0.996", "size": "8.65"}, {"price": "0.994", "size": "200"}, {"price": "0.99", "size": "10"}, {"price": "0.989", "size": "12000"}, {"price": "0.988", "size": "5.25"}, {"price": "0.978", "size": "12700"}, {"price": "0.974", "size": "263.73"}, {"price": "0.973", "size": "5.5"}, {"price": "0.95", "size": "30"}, {"price": "0.949", "size": "39"}, {"price": "0.945", "size": "100"}, {"price": "0.942", "size": "118.22"}, {"price": "0.941", "size": "605.04"}, {"price": "0.92", "size": "300"}, {"price": "0.919", "size": "84.65"}, {"price": "0.871", "size": "53.15"}, {"price": "0.87", "size": "11.08"}, {"price": "0.869", "size": "5"}, {"price": "0.771", "size": "29.94"}, {"price": "0.77", "size": "8"}, {"price": "0.5", "size": "13.71"}, {"price": "0.499", "size": "22.79"}, {"price": "0.498", "size": "13"}, {"price": "0.497", "size": "20"}, {"price": "0.049", "size": "10"}, {"price": "0.005", "size": "30.1"}, {"price": "0.004", "size": "257.39"}], "event_type": "book", "last_trade_price": ""}, {"market": "0x6a9f415ad545be1c9cf415435342c14da265aeeacef95493796e7c52f15559a6", "asset_id": "406305149379915345389298401162324736691782279339208895249045774408374182351", "timestamp": "1769384170570", "hash": "4e3f0d070092aaf340371b7dcd542fbf53af8b2e", "bids": [{"price": "0.001", "size": "1104251.99"}, {"price": "0.002", "size": "250"}, {"price": "0.003", "size": "30400"}, {"price": "0.004", "size": "8.65"}, {"price": "0.006", "size": "200"}, {"price": "0.01", "size": "10"}, {"price": "0.011", "size": "5.29"}, {"price": "0.021", "size": "12700"}, {"price": "0.03", "size": "266.66"}, {"price": "0.031", "size": "8.65"}, {"price": "0.05", "size": "30"}, {"price": "0.051", "size": "639"}, {"price": "0.071", "size": "100"}, {"price": "0.072", "size": "411.11"}, {"price": "0.08", "size": "300"}, {"price": "0.089", "size": "89.88"}, {"price": "0.09", "size": "5.3"}, {"price": "0.145", "size": "33"}, {"price": "0.146", "size": "54.79"}, {"price": "0.215", "size": "46.2"}, {"price": "0.216", "size": "5.31"}, {"price": "0.441", "size": "30.23"}, {"price": "0.442", "size": "13"}, {"price": "0.443", "size": "20"}, {"price": "0.992", "size": "351"}, {"price": "0.995", "size": "311.57"}, {"price": "0.996", "size": "37.57"}], "asks": [{"price": "0.999", "size": "1378.45"}, {"price": "0.998", "size": "5"}, {"price": "0.997", "size": "12498.99"}], "event_type": "book", "last_trade_price": "0.003"}, {"market": "0xdebb4d098d4382cebf6566acb3749226508e70e048e3a41a7fc44e94c6d0182a", "asset_id": "36753444559858254839802198257676788026485866301122066720655639390168841744924", "timestamp": "1769383650770", "hash": "67a6bd6c64ef1bdbd5b483683191d041fa17e7c1", "bids": [{"price": "0.001", "size": "1104242.02"}, {"price": "0.002", "size": "255.01"}, {"price": "0.003", "size": "30400"}, {"price": "0.004", "size": "8.69"}, {"price": "0.006", "size": "200"}, {"price": "0.01", "size": "10"}, {"price": "0.011", "size": "5.75"}, {"price": "0.021", "size": "12700"}, {"price": "0.023", "size": "260.86"}, {"price": "0.024", "size": "6.01"}, {"price": "0.05", "size": "30"}, {"price": "0.051", "size": "39"}, {"price": "0.054", "size": "611.11"}, {"price": "0.055", "size": "11.58"}, {"price": "0.095", "size": "200"}, {"price": "0.096", "size": "500"}, {"price": "0.097", "size": "61.85"}, {"price": "0.144", "size": "41.66"}, {"price": "0.145", "size": "41.37"}, {"price": "0.146", "size": "20"}, {"price": "0.22", "size": "27.27"}, {"price": "0.221", "size": "5"}, {"price": "0.523", "size": "124"}, {"price": "0.542", "size": "5"}, {"price": "0.543", "size": "11.04"}, {"price": "0.699", "size": "8.58"}, {"price": "0.7", "size": "20"}, {"price": "0.954", "size": "78.1"}, {"price": "0.976", "size": "21.8"}, {"price": "0.977", "size": "109.09"}], "asks": [{"price": "0.999", "size": "846.08"}, {"price": "0.997", "size": "125"}, {"price": "0.989", "size": "130.9"}], "event_type": "book", "last_trade_price": ""}, {"market": "0x80909e3487a955ccc8aab8b13f33d92dc8ac1159d4678ad620d7df16860221b9", "asset_id": "7888861096717092470560466121984594720392856066405453400763940107686287865082", "timestamp": "1769383970518", "hash": "c1679d6487b2dd5707f7b91731d1e7a4cb7c1570", "bids": [{"price": "0.001", "size": "1341.08"}], "asks": [{"price": "0.999", "size": "1104254.02"}, {"price": "0.998", "size": "250"}, {"price": "0.997", "size": "400"}, {"price": "0.996", "size": "8.68"}, {"price": "0.994", "size": "200"}, {"price": "0.99", "size": "10"}, {"price": "0.989", "size": "5.74"}, {"price": "0.979", "size": "6700"}, {"price": "0.975", "size": "384"}, {"price": "0.974", "size": "5.38"}, {"price": "0.95", "size": "30"}, {"price": "0.949", "size": "39"}, {"price": "0.946", "size": "700"}, {"price": "0.945", "size": "174.54"}, {"price": "0.944", "size": "8.1"}, {"price": "0.916", "size": "414.28"}, {"price": "0.844", "size": "25"}, {"price": "0.833", "size": "57.48"}, {"price": "0.832", "size": "7.72"}, {"price": "0.751", "size": "38.55"}, {"price": "0.75", "size": "8"}, {"price": "0.123", "size": "390"}, {"price": "0.122", "size": "14.53"}, {"price": "0.121", "size": "20"}, {"price": "0.108", "size": "137.15"}, {"price": "0.049", "size": "10"}, {"price": "0.005", "size": "37.71"}, {"price": "0.004", "size": "43.74"}], "event_type": "book", "last_trade_price": "0.001"}, {"market": "0x6f3819aefa464a63c3a54d9e079ad59ba194b015de3f4dae4f16d822eeb5dd2e", "asset_id": "82873337478696874311026595893708524418275224909062608016173074343863041369337", "timestamp": "1769384382654", "hash": "ffff8fe789b0f930ff6c52f1bfdef2a90357b8b3", "bids": [{"price": "0.001", "size": "1104252.01"}, {"price": "0.002", "size": "250"}, {"price": "0.003", "size": "30400"}, {"price": "0.004", "size": "8.67"}, {"price": "0.006", "size": "200"}, {"price": "0.01", "size": "10"}, {"price": "0.011", "size": "39.5"}, {"price": "0.026", "size": "1007.69"}, {"price": "0.027", "size": "7.98"}, {"price": "0.05", "size": "30"}, {"price": "0.051", "size": "639"}, {"price": "0.071", "size": "100"}, {"price": "0.072", "size": "411.11"}, {"price": "0.08", "size": "300"}, {"price": "0.081", "size": "98.76"}, {"price": "0.154", "size": "26"}, {"price": "0.167", "size": "47.9"}, {"price": "0.168", "size": "7.74"}, {"price": "0.226", "size": "8"}, {"price": "0.227", "size": "35.24"}, {"price": "0.523", "size": "56"}, {"price": "0.524", "size": "15.26"}, {"price": "0.823", "size": "74"}, {"price": "0.86", "size": "13.33"}, {"price": "0.861", "size": "13.33"}, {"price": "0.862", "size": "13.33"}, {"price": "0.863", "size": "20"}, {"price": "0.997", "size": "10.77"}, {"price": "0.998", "size": "324.75"}], "asks": [{"price": "0.999", "size": "4371.47"}], "event_type": "book", "last_trade_price": "0.001"}, {"market": "0x0d9cd522b589469a0ff19c75d5bbc716b6ed5e0d2613de17222467f25e585f33", "asset_id": "43833651780965158851163300043127463472147134401838564791175946042179880465250", "timestamp": "1769383881519", "hash": "3f3c9a81c603a7f08b3fe92d2aeb7d7a3fb95c19", "bids": [{"price": "0.001", "size": "4628.08"}], "asks": [{"price": "0.999", "size": "1102759.34"}, {"price": "0.998", "size": "250"}, {"price": "0.997", "size": "20400"}, {"price": "0.996", "size": "8.87"}, {"price": "0.994", "size": "200"}, {"price": "0.99", "size": "10"}, {"price": "0.989", "size": "5.42"}, {"price": "0.978", "size": "1063.63"}, {"price": "0.977", "size": "6.02"}, {"price": "0.95", "size": "30"}, {"price": "0.949", "size": "39"}, {"price": "0.948", "size": "5.08"}, {"price": "0.946", "size": "24.53"}, {"price": "0.944", "size": "100"}, {"price": "0.943", "size": "100"}, {"price": "0.942", "size": "637.93"}, {"price": "0.92", "size": "300"}, {"price": "0.919", "size": "98.76"}, {"price": "0.884", "size": "17"}, {"price": "0.882", "size": "67.79"}, {"price": "0.881", "size": "6"}, {"price": "0.88", "size": "6"}, {"price": "0.879", "size": "6.38"}, {"price": "0.477", "size": "81"}, {"price": "0.476", "size": "15.26"}, {"price": "0.301", "size": "11.44"}, {"price": "0.3", "size": "20"}, {"price": "0.07", "size": "25"}, {"price": "0.049", "size": "10"}, {"price": "0.005", "size": "104"}, {"price": "0.004", "size": "17.14"}], "event_type": "book", "last_trade_price": ""}, {"market": "0x469709d3554c9e9d26e8dea2516f8373669a9881ce505d57d75bff59fc58db75", "asset_id": "71216154792191030083354473461386899246245242196096601702705023997087404907586", "timestamp": "1769384382654", "hash": "460cd40eaca4e8b3098cb0286fde90b2fb343772", "bids": [{"price": "0.001", "size": "5017.05"}], "asks": [{"price": "0.999", "size": "1104251.99"}, {"price": "0.998", "size": "250"}, {"price": "0.997", "size": "33400"}, {"price": "0.996", "size": "8.66"}, {"price": "0.994", "size": "200"}, {"price": "0.99", "size": "10"}, {"price": "0.989", "size": "5.73"}, {"price": "0.979", "size": "12700"}, {"price": "0.977", "size": "521.73"}, {"price": "0.976", "size": "5.43"}, {"price": "0.95", "size": "30"}, {"price": "0.949", "size": "39"}, {"price": "0.948", "size": "5.53"}, {"price": "0.946", "size": "219.53"}, {"price": "0.945", "size": "718.18"}, {"price": "0.881", "size": "200.84"}, {"price": "0.88", "size": "5.38"}, {"price": "0.879", "size": "6"}, {"price": "0.878", "size": "6.75"}, {"price": "0.776", "size": "8"}, {"price": "0.775", "size": "53.33"}, {"price": "0.12", "size": "99"}, {"price": "0.119", "size": "20"}, {"price": "0.104", "size": "13.33"}, {"price": "0.103", "size": "13.33"}, {"price": "0.049", "size": "10"}, {"price": "0.005", "size": "19.63"}, {"price": "0.004", "size": "245.96"}], "event_type": "book", "last_trade_price": ""}, {"market": "0x812210ddb6555e27507d9400297225a3f1d60981de7cb66d6c25ad29dfb38d04", "asset_id": "54329595038133145577519568384351459887428825578495995657981138893910948687059", "timestamp": "1769383850083", "hash": "2740ce22af9e3a699e8ea235476e5cd13ce444f5", "bids": [{"price": "0.001", "size": "4995.68"}], "asks": [{"price": "0.999", "size": "1104247"}, {"price": "0.998", "size": "250"}, {"price": "0.997", "size": "30400"}, {"price": "0.996", "size": "8.67"}, {"price": "0.994", "size": "200"}, {"price": "0.99", "size": "10"}, {"price": "0.989", "size": "7.05"}, {"price": "0.979", "size": "12700"}, {"price": "0.974", "size": "307.69"}, {"price": "0.973", "size": "5.14"}, {"price": "0.95", "size": "30"}, {"price": "0.949", "size": "39"}, {"price": "0.944", "size": "642.85"}, {"price": "0.943", "size": "8.59"}, {"price": "0.92", "size": "300"}, {"price": "0.919", "size": "98.76"}, {"price": "0.85", "size": "32"}, {"price": "0.821", "size": "44.69"}, {"price": "0.82", "size": "6.93"}, {"price": "0.765", "size": "8"}, {"price": "0.764", "size": "33.89"}, {"price": "0.595", "size": "19.75"}, {"price": "0.594", "size": "20"}, {"price": "0.105", "size": "6"}, {"price": "0.101", "size": "6.66"}, {"price": "0.1", "size": "6"}, {"price": "0.003", "size": "51.31"}, {"price": "0.002", "size": "475.84"}], "event_type": "book", "last_trade_price": "0.001"}, {"market": "0x768a10a2ba796df7c565166c61f1b708a7674565add5559f03bd1297d4997ac7", "asset_id": "52154086410665277054252505344124616126874295244982327401005145100880544734445", "timestamp": "1769384339344", "hash": "62a1766633a3588717e9cc3503c2572a58d931f8", "bids": [{"price": "0.001", "size": "1102752.01"}, {"price": "0.002", "size": "250"}, {"price": "0.003", "size": "30400"}, {"price": "0.004", "size": "8.68"}, {"price": "0.006", "size": "200"}, {"price": "0.01", "size": "10"}, {"price": "0.011", "size": "5.31"}, {"price": "0.028", "size": "1042.85"}, {"price": "0.029", "size": "6.98"}, {"price": "0.05", "size": "530"}, {"price": "0.051", "size": "39"}, {"price": "0.072", "size": "133.33"}, {"price": "0.073", "size": "6"}, {"price": "0.09", "size": "109.53"}, {"price": "0.091", "size": "205.49"}, {"price": "0.093", "size": "501"}, {"price": "0.183", "size": "52.45"}, {"price": "0.184", "size": "6.79"}, {"price": "0.257", "size": "37.35"}, {"price": "0.258", "size": "7"}, {"price": "0.88", "size": "99"}, {"price": "0.884", "size": "6.66"}, {"price": "0.885", "size": "26"}, {"price": "0.993", "size": "21.53"}, {"price": "0.994", "size": "88.55"}, {"price": "0.995", "size": "185.62"}], "asks": [{"price": "0.999", "size": "1349"}, {"price": "0.998", "size": "5"}, {"price": "0.997", "size": "5"}], "event_type": "book", "last_trade_price": ""}, {"market": "0x768a10a2ba796df7c565166c61f1b708a7674565add5559f03bd1297d4997ac7", "asset_id": "102376165613363136742721000249129649340591318769760895202636036152231642180566", "timestamp": "1769384339344", "hash": "61f0a403522c07d416dda927c302a54fd3372082", "bids": [{"price": "0.001", "size": "1349"}, {"price": "0.002", "size": "5"}, {"price": "0.003", "size": "5"}], "asks": [{"price": "0.999", "size": "1102752.01"}, {"price": "0.998", "size": "250"}, {"price": "0.997", "size": "30400"}, {"price": "0.996", "size": "8.68"}, {"price": "0.994", "size": "200"}, {"price": "0.99", "size": "10"}, {"price": "0.989", "size": "5.31"}, {"price": "0.972", "size": "1042.85"}, {"price": "0.971", "size": "6.98"}, {"price": "0.95", "size": "530"}, {"price": "0.949", "size": "39"}, {"price": "0.928", "size": "133.33"}, {"price": "0.927", "size": "6"}, {"price": "0.91", "size": "109.53"}, {"price": "0.909", "size": "205.49"}, {"price": "0.907", "size": "501"}, {"price": "0.817", "size": "52.45"}, {"price": "0.816", "size": "6.79"}, {"price": "0.743", "size": "37.35"}, {"price": "0.742", "size": "7"}, {"price": "0.12", "size": "99"}, {"price": "0.116", "size": "6.66"}, {"price": "0.115", "size": "26"}, {"price": "0.007", "size": "21.53"}, {"price": "0.006", "size": "88.55"}, {"price": "0.005", "size": "185.62"}], "event_type": "book", "last_trade_price": ""}, {"market": "0x7e2664fd56bdb98dfe10fc702d40c7bb34bbd173b4e1a4ace956e8bee3a15ed3", "asset_id": "8013350309980067752092467553989532032941595361116376915087772932251249070671", "timestamp": "1769383797349", "hash": "362bef4ecbe758b6f3de786d5863d3ad0bb2d9ce", "bids": [{"price": "0.001", "size": "1459.97"}], "asks": [{"price": "0.999", "size": "1104242.23"}, {"price": "0.998", "size": "250"}, {"price": "0.997", "size": "20406.64"}, {"price": "0.994", "size": "200"}, {"price": "0.993", "size": "10.48"}, {"price": "0.99", "size": "10"}, {"price": "0.979", "size": "12700"}, {"price": "0.978", "size": "6.58"}, {"price": "0.975", "size": "480"}, {"price": "0.95", "size": "30"}, {"price": "0.949", "size": "39"}, {"price": "0.948", "size": "730.76"}, {"price": "0.947", "size": "7.18"}, {"price": "0.92", "size": "300"}, {"price": "0.875", "size": "5"}, {"price": "0.856", "size": "83.33"}, {"price": "0.855", "size": "9.49"}, {"price": "0.769", "size": "51.94"}, {"price": "0.768", "size": "8"}, {"price": "0.12", "size": "390"}, {"price": "0.119", "size": "20"}, {"price": "0.107", "size": "6"}, {"price": "0.106", "size": "6.66"}, {"price": "0.105", "size": "6"}, {"price": "0.003", "size": "54.41"}, {"price": "0.002", "size": "468.52"}], "event_type": "book", "last_trade_price": ""}, {"market": "0x6a9f415ad545be1c9cf415435342c14da265aeeacef95493796e7c52f15559a6", "asset_id": "73011059187166137733275983046150182784910493074367934212798853099948144842604", "timestamp": "1769384170570", "hash": "54fb54efebba389d0abdcc69b566b2db87427537", "bids": [{"price": "0.001", "size": "1378.45"}, {"price": "0.002", "size": "5"}, {"price": "0.003", "size": "12498.99"}], "asks": [{"price": "0.999", "size": "1104251.99"}, {"price": "0.998", "size": "250"}, {"price": "0.997", "size": "30400"}, {"price": "0.996", "size": "8.65"}, {"price": "0.994", "size": "200"}, {"price": "0.99", "size": "10"}, {"price": "0.989", "size": "5.29"}, {"price": "0.979", "size": "12700"}, {"price": "0.97", "size": "266.66"}, {"price": "0.969", "size": "8.65"}, {"price": "0.95", "size": "30"}, {"price": "0.949", "size": "639"}, {"price": "0.929", "size": "100"}, {"price": "0.928", "size": "411.11"}, {"price": "0.92", "size": "300"}, {"price": "0.911", "size": "89.88"}, {"price": "0.91", "size": "5.3"}, {"price": "0.855", "size": "33"}, {"price": "0.854", "size": "54.79"}, {"price": "0.785", "size": "46.2"}, {"price": "0.784", "size": "5.31"}, {"price": "0.559", "size": "30.23"}, {"price": "0.558", "size": "13"}, {"price": "0.557", "size": "20"}, {"price": "0.008", "size": "351"}, {"price": "0.005", "size": "311.57"}, {"price": "0.004", "size": "37.57"}], "event_type": "book", "last_trade_price": "0.003"}, {"market": "0x55d7602157ad134b7668cc486bb9c85096356c0dbd055c61344426b2d8c8291a", "asset_id": "41208351236397166328872550854608550552314297451342384956165441312617513020672", "timestamp": "1769384421420", "hash": "4ae349d018294efd4d81db062f91cb2396ad4ac0", "bids": [{"price": "0.001", "size": "1206"}, {"price": "0.002", "size": "5"}, {"price": "0.003", "size": "13835"}], "asks": [{"price": "0.999", "size": "1104242.26"}, {"price": "0.998", "size": "30250"}, {"price": "0.997", "size": "406.69"}, {"price": "0.994", "size": "200"}, {"price": "0.993", "size": "10.55"}, {"price": "0.99", "size": "10"}, {"price": "0.989", "size": "12000"}, {"price": "0.979", "size": "12700"}, {"price": "0.978", "size": "6.42"}, {"price": "0.975", "size": "320"}, {"price": "0.95", "size": "30"}, {"price": "0.949", "size": "39"}, {"price": "0.948", "size": "5.15"}, {"price": "0.944", "size": "142.85"}, {"price": "0.943", "size": "600"}, {"price": "0.942", "size": "100"}, {"price": "0.92", "size": "300"}, {"price": "0.919", "size": "98.76"}, {"price": "0.883", "size": "68.37"}, {"price": "0.882", "size": "6.53"}, {"price": "0.881", "size": "6"}, {"price": "0.88", "size": "6"}, {"price": "0.774", "size": "8"}, {"price": "0.773", "size": "35.24"}, {"price": "0.301", "size": "11.44"}, {"price": "0.3", "size": "20"}, {"price": "0.081", "size": "13"}, {"price": "0.08", "size": "13"}, {"price": "0.078", "size": "13"}, {"price": "0.076", "size": "13"}, {"price": "0.075", "size": "21"}, {"price": "0.073", "size": "30"}, {"price": "0.071", "size": "23"}, {"price": "0.01", "size": "21"}, {"price": "0.006", "size": "101.18"}], "event_type": "book", "last_trade_price": ""}, {"market": "0x7e2664fd56bdb98dfe10fc702d40c7bb34bbd173b4e1a4ace956e8bee3a15ed3", "asset_id": "32585257541944296536919042049344155455892911573822808260948030619026984605016", "timestamp": "1769383797349", "hash": "7d676b12728c0d41e1296936bf666370a831004b", "bids": [{"price": "0.001", "size": "1104242.23"}, {"price": "0.002", "size": "250"}, {"price": "0.003", "size": "20406.64"}, {"price": "0.006", "size": "200"}, {"price": "0.007", "size": "10.48"}, {"price": "0.01", "size": "10"}, {"price": "0.021", "size": "12700"}, {"price": "0.022", "size": "6.58"}, {"price": "0.025", "size": "480"}, {"price": "0.05", "size": "30"}, {"price": "0.051", "size": "39"}, {"price": "0.052", "size": "730.76"}, {"price": "0.053", "size": "7.18"}, {"price": "0.08", "size": "300"}, {"price": "0.125", "size": "5"}, {"price": "0.144", "size": "83.33"}, {"price": "0.145", "size": "9.49"}, {"price": "0.231", "size": "51.94"}, {"price": "0.232", "size": "8"}, {"price": "0.88", "size": "390"}, {"price": "0.881", "size": "20"}, {"price": "0.893", "size": "6"}, {"price": "0.894", "size": "6.66"}, {"price": "0.895", "size": "6"}, {"price": "0.997", "size": "54.41"}, {"price": "0.998", "size": "468.52"}], "asks": [{"price": "0.999", "size": "1459.97"}], "event_type": "book", "last_trade_price": ""}, {"market": "0x1c621820bae34fb023564d9b54a27b7c45ca41fdc4c6cb3aee5a6d5b6ade5e17", "asset_id": "44741888338419906404486954459719474606346125085587394073603483706523243052500", "timestamp": "1769384339345", "hash": "5f3686441ea43961ffb6d38bebd8e4d69f07acad", "bids": [{"price": "0.001", "size": "1013"}, {"price": "0.002", "size": "5"}], "asks": [{"price": "0.999", "size": "1104251.99"}, {"price": "0.998", "size": "60250"}, {"price": "0.997", "size": "400"}, {"price": "0.996", "size": "8.65"}, {"price": "0.994", "size": "200"}, {"price": "0.99", "size": "10"}, {"price": "0.989", "size": "21000"}, {"price": "0.988", "size": "5.65"}, {"price": "0.978", "size": "12700"}, {"price": "0.967", "size": "207.79"}, {"price": "0.966", "size": "6.07"}, {"price": "0.95", "size": "530"}, {"price": "0.949", "size": "39"}, {"price": "0.929", "size": "3000"}, {"price": "0.928", "size": "309.76"}, {"price": "0.922", "size": "87.91"}, {"price": "0.921", "size": "6.4"}, {"price": "0.87", "size": "52.74"}, {"price": "0.868", "size": "217"}, {"price": "0.793", "size": "9"}, {"price": "0.791", "size": "32.8"}, {"price": "0.79", "size": "5.57"}, {"price": "0.477", "size": "91"}, {"price": "0.476", "size": "13.08"}, {"price": "0.378", "size": "11.02"}, {"price": "0.377", "size": "20"}, {"price": "0.105", "size": "174.1"}, {"price": "0.102", "size": "6.66"}, {"price": "0.101", "size": "6"}, {"price": "0.049", "size": "5"}, {"price": "0.005", "size": "62.73"}, {"price": "0.004", "size": "95.46"}], "event_type": "book", "last_trade_price": ""}, {"market": "0x53030dd48b4acd0572c611a81fade4d1214d45cfa9725434f625ff9443bbf58e", "asset_id": "28013675818699191456107309488671219297858376503082476267618031773906710101322", "timestamp": "1769383639201", "hash": "41f1064a939e64ea1c67c26f4de7f42c5dc2a02d", "bids": [{"price": "0.001", "size": "1102752.01"}, {"price": "0.002", "size": "250"}, {"price": "0.003", "size": "30400"}, {"price": "0.004", "size": "10.12"}, {"price": "0.006", "size": "200"}, {"price": "0.01", "size": "10"}, {"price": "0.011", "size": "9.11"}, {"price": "0.021", "size": "12700"}, {"price": "0.034", "size": "282.35"}, {"price": "0.035", "size": "6.15"}, {"price": "0.05", "size": "30"}, {"price": "0.051", "size": "39"}, {"price": "0.052", "size": "684.61"}, {"price": "0.082", "size": "417.07"}, {"price": "0.083", "size": "5.69"}, {"price": "0.151", "size": "53"}, {"price": "0.152", "size": "63.15"}, {"price": "0.203", "size": "9"}, {"price": "0.207", "size": "46.37"}, {"price": "0.208", "size": "5.55"}, {"price": "0.88", "size": "390"}, {"price": "0.881", "size": "20"}, {"price": "0.895", "size": "6"}, {"price": "0.923", "size": "7"}, {"price": "0.995", "size": "55"}, {"price": "0.997", "size": "52.47"}, {"price": "0.998", "size": "453.04"}], "asks": [{"price": "0.999", "size": "1331"}], "event_type": "book", "last_trade_price": ""}, {"market": "0x469709d3554c9e9d26e8dea2516f8373669a9881ce505d57d75bff59fc58db75", "asset_id": "109460219863240579381274910433788899162940504407535154043224726152849933944106", "timestamp": "1769384382654", "hash": "938ef0bc382f98146c86cea4c35562973a05a9d3", "bids": [{"price": "0.001", "size": "1104251.99"}, {"price": "0.002", "size": "250"}, {"price": "0.003", "size": "33400"}, {"price": "0.004", "size": "8.66"}, {"price": "0.006", "size": "200"}, {"price": "0.01", "size": "10"}, {"price": "0.011", "size": "5.73"}, {"price": "0.021", "size": "12700"}, {"price": "0.023", "size": "521.73"}, {"price": "0.024", "size": "5.43"}, {"price": "0.05", "size": "30"}, {"price": "0.051", "size": "39"}, {"price": "0.052", "size": "5.53"}, {"price": "0.054", "size": "219.53"}, {"price": "0.055", "size": "718.18"}, {"price": "0.119", "size": "200.84"}, {"price": "0.12", "size": "5.38"}, {"price": "0.121", "size": "6"}, {"price": "0.122", "size": "6.75"}, {"price": "0.224", "size": "8"}, {"price": "0.225", "size": "53.33"}, {"price": "0.88", "size": "99"}, {"price": "0.881", "size": "20"}, {"price": "0.896", "size": "13.33"}, {"price": "0.897", "size": "13.33"}, {"price": "0.951", "size": "10"}, {"price": "0.995", "size": "19.63"}, {"price": "0.996", "size": "245.96"}], "asks": [{"price": "0.999", "size": "5017.05"}], "event_type": "book", "last_trade_price": ""}, {"market": "0x720db82e6ae3132de241c4190b7f72585d5fc2f1364519e814d51f3ec29bf8c6", "asset_id": "38966153695292251303244152044268630330033580269266738868503907046849339108583", "timestamp": "1769383822640", "hash": "d2f90b0b08b4c77a64067380af950e75f97053b6", "bids": [{"price": "0.001", "size": "912.62"}], "asks": [{"price": "0.999", "size": "1104287"}, {"price": "0.998", "size": "250"}, {"price": "0.997", "size": "30406.62"}, {"price": "0.994", "size": "200"}, {"price": "0.993", "size": "16.15"}, {"price": "0.99", "size": "10"}, {"price": "0.989", "size": "9.09"}, {"price": "0.967", "size": "12700"}, {"price": "0.966", "size": "352.94"}, {"price": "0.95", "size": "530"}, {"price": "0.949", "size": "39"}, {"price": "0.948", "size": "8.1"}, {"price": "0.929", "size": "9000"}, {"price": "0.928", "size": "466.66"}, {"price": "0.92", "size": "300"}, {"price": "0.847", "size": "26"}, {"price": "0.84", "size": "75"}, {"price": "0.839", "size": "8.29"}, {"price": "0.681", "size": "6"}, {"price": "0.68", "size": "37.5"}, {"price": "0.298", "size": "6.66"}, {"price": "0.297", "size": "26"}, {"price": "0.005", "size": "34"}, {"price": "0.003", "size": "49.53"}, {"price": "0.002", "size": "529.54"}], "event_type": "book", "last_trade_price": ""}, {"market": "0x812210ddb6555e27507d9400297225a3f1d60981de7cb66d6c25ad29dfb38d04", "asset_id": "44866125854906444448306343930089554704027573886545859149588284387791471079764", "timestamp": "1769383850083", "hash": "0a40d52938a1c8c8ee57519fabb93461c07eafa7", "bids": [{"price": "0.001", "size": "1104247"}, {"price": "0.002", "size": "250"}, {"price": "0.003", "size": "30400"}, {"price": "0.004", "size": "8.67"}, {"price": "0.006", "size": "200"}, {"price": "0.01", "size": "10"}, {"price": "0.011", "size": "7.05"}, {"price": "0.021", "size": "12700"}, {"price": "0.026", "size": "307.69"}, {"price": "0.027", "size": "5.14"}, {"price": "0.05", "size": "30"}, {"price": "0.051", "size": "39"}, {"price": "0.056", "size": "642.85"}, {"price": "0.057", "size": "8.59"}, {"price": "0.08", "size": "300"}, {"price": "0.081", "size": "98.76"}, {"price": "0.15", "size": "32"}, {"price": "0.179", "size": "44.69"}, {"price": "0.18", "size": "6.93"}, {"price": "0.235", "size": "8"}, {"price": "0.236", "size": "33.89"}, {"price": "0.405", "size": "19.75"}, {"price": "0.406", "size": "20"}, {"price": "0.895", "size": "6"}, {"price": "0.899", "size": "6.66"}, {"price": "0.9", "size": "6"}, {"price": "0.997", "size": "51.31"}, {"price": "0.998", "size": "475.84"}], "asks": [{"price": "0.999", "size": "4995.68"}], "event_type": "book", "last_trade_price": "0.001"}, {"market": "0xdebb4d098d4382cebf6566acb3749226508e70e048e3a41a7fc44e94c6d0182a", "asset_id": "102436772013076156944295871423877161254159297346169261958329577570286200792258", "timestamp": "1769383650770", "hash": "3be5e9aa4ef39edccda211cd73c7f66aac2db9b1", "bids": [{"price": "0.001", "size": "846.08"}, {"price": "0.003", "size": "125"}, {"price": "0.011", "size": "130.9"}], "asks": [{"price": "0.999", "size": "1104242.02"}, {"price": "0.998", "size": "255.01"}, {"price": "0.997", "size": "30400"}, {"price": "0.996", "size": "8.69"}, {"price": "0.994", "size": "200"}, {"price": "0.99", "size": "10"}, {"price": "0.989", "size": "5.75"}, {"price": "0.979", "size": "12700"}, {"price": "0.977", "size": "260.86"}, {"price": "0.976", "size": "6.01"}, {"price": "0.95", "size": "30"}, {"price": "0.949", "size": "39"}, {"price": "0.946", "size": "611.11"}, {"price": "0.945", "size": "11.58"}, {"price": "0.905", "size": "200"}, {"price": "0.904", "size": "500"}, {"price": "0.903", "size": "61.85"}, {"price": "0.856", "size": "41.66"}, {"price": "0.855", "size": "41.37"}, {"price": "0.854", "size": "20"}, {"price": "0.78", "size": "27.27"}, {"price": "0.779", "size": "5"}, {"price": "0.477", "size": "124"}, {"price": "0.458", "size": "5"}, {"price": "0.457", "size": "11.04"}, {"price": "0.301", "size": "8.58"}, {"price": "0.3", "size": "20"}, {"price": "0.046", "size": "78.1"}, {"price": "0.024", "size": "21.8"}, {"price": "0.023", "size": "109.09"}], "event_type": "book", "last_trade_price": ""}, {"market": "0x7d06087c987916fcdd813c298ea61fe8154fbe186872cf416bad99c2abe1e28b", "asset_id": "53184392184731073294596377638963528940590267478279064727563854235726442195657", "timestamp": "1769383807212", "hash": "66e1861449eacce48fd8e3ee00096737abfeaade", "bids": [{"price": "0.001", "size": "1765"}, {"price": "0.002", "size": "5"}, {"price": "0.003", "size": "10339.4"}], "asks": [{"price": "0.999", "size": "1104247.67"}, {"price": "0.998", "size": "30250"}, {"price": "0.997", "size": "400"}, {"price": "0.996", "size": "9.95"}, {"price": "0.994", "size": "200"}, {"price": "0.99", "size": "10"}, {"price": "0.989", "size": "8.96"}, {"price": "0.968", "size": "1000"}, {"price": "0.967", "size": "6.35"}, {"price": "0.95", "size": "30"}, {"price": "0.949", "size": "639"}, {"price": "0.929", "size": "100"}, {"price": "0.928", "size": "133.33"}, {"price": "0.927", "size": "5.55"}, {"price": "0.919", "size": "418.51"}, {"price": "0.852", "size": "6"}, {"price": "0.823", "size": "54.23"}, {"price": "0.822", "size": "6.94"}, {"price": "0.709", "size": "32.98"}, {"price": "0.708", "size": "6"}, {"price": "0.156", "size": "6"}, {"price": "0.153", "size": "6.66"}, {"price": "0.152", "size": "26"}, {"price": "0.005", "size": "163.81"}, {"price": "0.004", "size": "357.02"}], "event_type": "book", "last_trade_price": "0.003"}, {"market": "0x23e13d00bf97cf1f66a9cc9c73b0d9122ffdcaa00391dcbcf7c194920d2c637a", "asset_id": "71097957014663900449430016744507587046826310681746179766837847959835251978939", "timestamp": "1769384424953", "hash": "ab085af64930e3e786bab7bc8fcf0a5348d9fd55", "bids": [{"price": "0.001", "size": "1104251.99"}, {"price": "0.002", "size": "30250"}, {"price": "0.003", "size": "400"}, {"price": "0.004", "size": "8.65"}, {"price": "0.006", "size": "200"}, {"price": "0.01", "size": "10"}, {"price": "0.011", "size": "12000"}, {"price": "0.012", "size": "5.25"}, {"price": "0.022", "size": "12700"}, {"price": "0.026", "size": "263.73"}, {"price": "0.027", "size": "5.5"}, {"price": "0.05", "size": "30"}, {"price": "0.051", "size": "39"}, {"price": "0.055", "size": "100"}, {"price": "0.058", "size": "118.22"}, {"price": "0.059", "size": "605.04"}, {"price": "0.08", "size": "300"}, {"price": "0.081", "size": "84.65"}, {"price": "0.129", "size": "53.15"}, {"price": "0.13", "size": "11.08"}, {"price": "0.131", "size": "5"}, {"price": "0.229", "size": "29.94"}, {"price": "0.23", "size": "8"}, {"price": "0.5", "size": "13.71"}, {"price": "0.501", "size": "22.79"}, {"price": "0.502", "size": "13"}, {"price": "0.503", "size": "20"}, {"price": "0.951", "size": "10"}, {"price": "0.995", "size": "30.1"}, {"price": "0.996", "size": "257.39"}], "asks": [{"price": "0.999", "size": "1329.73"}], "event_type": "book", "last_trade_price": ""}, {"market": "0x53030dd48b4acd0572c611a81fade4d1214d45cfa9725434f625ff9443bbf58e", "asset_id": "93601737054928362372096738986263364737270540163712701982280468693583918706009", "timestamp": "1769383639201", "hash": "94fd00955b16e8364b4f4f33470ebd124340d3b7", "bids": [{"price": "0.001", "size": "1331"}], "asks": [{"price": "0.999", "size": "1102752.01"}, {"price": "0.998", "size": "250"}, {"price": "0.997", "size": "30400"}, {"price": "0.996", "size": "10.12"}, {"price": "0.994", "size": "200"}, {"price": "0.99", "size": "10"}, {"price": "0.989", "size": "9.11"}, {"price": "0.979", "size": "12700"}, {"price": "0.966", "size": "282.35"}, {"price": "0.965", "size": "6.15"}, {"price": "0.95", "size": "30"}, {"price": "0.949", "size": "39"}, {"price": "0.948", "size": "684.61"}, {"price": "0.918", "size": "417.07"}, {"price": "0.917", "size": "5.69"}, {"price": "0.849", "size": "53"}, {"price": "0.848", "size": "63.15"}, {"price": "0.797", "size": "9"}, {"price": "0.793", "size": "46.37"}, {"price": "0.792", "size": "5.55"}, {"price": "0.12", "size": "390"}, {"price": "0.119", "size": "20"}, {"price": "0.105", "size": "6"}, {"price": "0.077", "size": "7"}, {"price": "0.005", "size": "55"}, {"price": "0.003", "size": "52.47"}, {"price": "0.002", "size": "453.04"}], "event_type": "book", "last_trade_price": ""}, {"market": "0x6a72f5b1d7edf1261156080ddc026da3d80a78834c12925a7bfea4a8aa5b8fb8", "asset_id": "56323539615651816818267229259150871177627322204823867354832755297469690554470", "timestamp": "1769383608986", "hash": "be477696c3e797f37d7033669fb53ad91843498e", "bids": [{"price": "0.001", "size": "1440.57"}], "asks": [{"price": "0.999", "size": "1102634.49"}, {"price": "0.998", "size": "250"}, {"price": "0.997", "size": "20400"}, {"price": "0.996", "size": "9.56"}, {"price": "0.994", "size": "200"}, {"price": "0.99", "size": "10"}, {"price": "0.989", "size": "5.83"}, {"price": "0.98", "size": "79.47"}, {"price": "0.976", "size": "1100"}, {"price": "0.975", "size": "8.57"}, {"price": "0.95", "size": "530"}, {"price": "0.949", "size": "39"}, {"price": "0.929", "size": "200"}, {"price": "0.928", "size": "138.45"}, {"price": "0.919", "size": "418.51"}, {"price": "0.854", "size": "27"}, {"price": "0.836", "size": "58.53"}, {"price": "0.835", "size": "7.87"}, {"price": "0.741", "size": "37.06"}, {"price": "0.74", "size": "7"}, {"price": "0.113", "size": "6.66"}, {"price": "0.112", "size": "26"}, {"price": "0.049", "size": "5"}, {"price": "0.004", "size": "14.06"}, {"price": "0.003", "size": "191.91"}], "event_type": "book", "last_trade_price": ""}, {"market": "0x489bfb9597099df16b34140399d2a1517e0a89623dabe94a3fccd4b48cab8bd3", "asset_id": "87569871218748662090769146890327376821466803212836644352988286023370072840603", "timestamp": "1769384246570", "hash": "27aa18b021c4818c65a4f862264f12b0fc94d559", "bids": [{"price": "0.001", "size": "513144"}, {"price": "0.002", "size": "250"}, {"price": "0.003", "size": "400"}, {"price": "0.006", "size": "200"}, {"price": "0.01", "size": "110010"}, {"price": "0.011", "size": "8.65"}, {"price": "0.021", "size": "1026.53"}, {"price": "0.05", "size": "30"}, {"price": "0.051", "size": "673.45"}, {"price": "0.114", "size": "3100"}, {"price": "0.115", "size": "59.62"}, {"price": "0.146", "size": "23"}, {"price": "0.147", "size": "46.64"}, {"price": "0.5", "size": "93.71"}, {"price": "0.501", "size": "300"}, {"price": "0.6", "size": "211.42"}, {"price": "0.601", "size": "11.4"}, {"price": "0.8", "size": "200"}, {"price": "0.87", "size": "6.3"}, {"price": "0.894", "size": "60.24"}, {"price": "0.902", "size": "200"}, {"price": "0.905", "size": "88.49"}], "asks": [{"price": "0.999", "size": "4452.8"}, {"price": "0.998", "size": "526.54"}, {"price": "0.997", "size": "134.82"}, {"price": "0.996", "size": "177.97"}, {"price": "0.995", "size": "143.67"}, {"price": "0.992", "size": "20"}, {"price": "0.991", "size": "17.02"}, {"price": "0.99", "size": "10"}, {"price": "0.989", "size": "5.92"}, {"price": "0.962", "size": "177.96"}, {"price": "0.96", "size": "22.03"}, {"price": "0.959", "size": "55.78"}], "event_type": "book", "last_trade_price": "0.905"}, {"market": "0xf3962aae4f208e8c819166ae325ae23c09568ecbb700a100f9d6ccc74d736c33", "asset_id": "17894486650861626009546140548377727528082135718961181457040583083959483688175", "timestamp": "1769383800423", "hash": "725b1812ee59c9c6027600a72053c4b02f8100ee", "bids": [{"price": "0.001", "size": "1104251.99"}, {"price": "0.002", "size": "250"}, {"price": "0.003", "size": "400"}, {"price": "0.004", "size": "8.66"}, {"price": "0.006", "size": "200"}, {"price": "0.01", "size": "10"}, {"price": "0.011", "size": "5.29"}, {"price": "0.021", "size": "12700"}, {"price": "0.032", "size": "214.28"}, {"price": "0.033", "size": "7.48"}, {"price": "0.05", "size": "30"}, {"price": "0.051", "size": "39"}, {"price": "0.052", "size": "631.86"}, {"price": "0.08", "size": "300"}, {"price": "0.086", "size": "79.73"}, {"price": "0.087", "size": "5.65"}, {"price": "0.153", "size": "22"}, {"price": "0.154", "size": "44.52"}, {"price": "0.215", "size": "31.89"}, {"price": "0.216", "size": "5.33"}, {"price": "0.55", "size": "425.04"}, {"price": "0.551", "size": "19.53"}, {"price": "0.57", "size": "12.03"}, {"price": "0.571", "size": "5"}, {"price": "0.668", "size": "18.02"}, {"price": "0.669", "size": "10.24"}, {"price": "0.702", "size": "13.33"}, {"price": "0.703", "size": "13.33"}, {"price": "0.704", "size": "20"}, {"price": "0.951", "size": "10"}, {"price": "0.995", "size": "30"}, {"price": "0.996", "size": "17.53"}], "asks": [{"price": "0.999", "size": "5028.09"}], "event_type": "book", "last_trade_price": "0.001"}, {"market": "0x7d06087c987916fcdd813c298ea61fe8154fbe186872cf416bad99c2abe1e28b", "asset_id": "67302540724762161307896112522088102200482553778240942791214901770569400222178", "timestamp": "1769383807212", "hash": "77cce5c2465079b6273e6179ff60ebb910accc49", "bids": [{"price": "0.001", "size": "1104247.67"}, {"price": "0.002", "size": "30250"}, {"price": "0.003", "size": "400"}, {"price": "0.004", "size": "9.95"}, {"price": "0.006", "size": "200"}, {"price": "0.01", "size": "10"}, {"price": "0.011", "size": "8.96"}, {"price": "0.032", "size": "1000"}, {"price": "0.033", "size": "6.35"}, {"price": "0.05", "size": "30"}, {"price": "0.051", "size": "639"}, {"price": "0.071", "size": "100"}, {"price": "0.072", "size": "133.33"}, {"price": "0.073", "size": "5.55"}, {"price": "0.081", "size": "418.51"}, {"price": "0.148", "size": "6"}, {"price": "0.177", "size": "54.23"}, {"price": "0.178", "size": "6.94"}, {"price": "0.291", "size": "32.98"}, {"price": "0.292", "size": "6"}, {"price": "0.844", "size": "6"}, {"price": "0.847", "size": "6.66"}, {"price": "0.848", "size": "26"}, {"price": "0.995", "size": "163.81"}, {"price": "0.996", "size": "357.02"}], "asks": [{"price": "0.999", "size": "1765"}, {"price": "0.998", "size": "5"}, {"price": "0.997", "size": "10339.4"}], "event_type": "book", "last_trade_price": "0.003"}, {"market": "0xf3962aae4f208e8c819166ae325ae23c09568ecbb700a100f9d6ccc74d736c33", "asset_id": "32676499383400665200746037279217737558284937536223714873506426202539097902762", "timestamp": "1769383800423", "hash": "f2222c6a2c3d52782199f83d0119ce09fdfcd95d", "bids": [{"price": "0.001", "size": "5028.09"}], "asks": [{"price": "0.999", "size": "1104251.99"}, {"price": "0.998", "size": "250"}, {"price": "0.997", "size": "400"}, {"price": "0.996", "size": "8.66"}, {"price": "0.994", "size": "200"}, {"price": "0.99", "size": "10"}, {"price": "0.989", "size": "5.29"}, {"price": "0.979", "size": "12700"}, {"price": "0.968", "size": "214.28"}, {"price": "0.967", "size": "7.48"}, {"price": "0.95", "size": "30"}, {"price": "0.949", "size": "39"}, {"price": "0.948", "size": "631.86"}, {"price": "0.92", "size": "300"}, {"price": "0.914", "size": "79.73"}, {"price": "0.913", "size": "5.65"}, {"price": "0.847", "size": "22"}, {"price": "0.846", "size": "44.52"}, {"price": "0.785", "size": "31.89"}, {"price": "0.784", "size": "5.33"}, {"price": "0.45", "size": "425.04"}, {"price": "0.449", "size": "19.53"}, {"price": "0.43", "size": "12.03"}, {"price": "0.429", "size": "5"}, {"price": "0.332", "size": "18.02"}, {"price": "0.331", "size": "10.24"}, {"price": "0.298", "size": "13.33"}, {"price": "0.297", "size": "13.33"}, {"price": "0.296", "size": "20"}, {"price": "0.049", "size": "10"}, {"price": "0.005", "size": "30"}, {"price": "0.004", "size": "17.53"}], "event_type": "book", "last_trade_price": "0.001"}]}
{"_local_timestamp": "2026-01-25T23:40:57.294020+00:00", "data": {"market": "0x53030dd48b4acd0572c611a81fade4d1214d45cfa9725434f625ff9443bbf58e", "price_changes": [{"asset_id": "28013675818699191456107309488671219297858376503082476267618031773906710101322", "price": "0.203", "size": "0", "side": "BUY", "hash": "fbc5d9a002cfafeb3f3f255fc2c6e4236cc61f40", "best_bid": "0.998", "best_ask": "0.999"}, {"asset_id": "93601737054928362372096738986263364737270540163712701982280468693583918706009", "price": "0.797", "size": "0", "side": "SELL", "hash": "332a324251e7e49aa4d472869c9fb285c22e6e64", "best_bid": "0.001", "best_ask": "0.002"}], "timestamp": "1769384457224", "event_type": "price_change"}}
{"_local_timestamp": "2026-01-25T23:40:57.342006+00:00", "data": {"market": "0x53030dd48b4acd0572c611a81fade4d1214d45cfa9725434f625ff9443bbf58e", "price_changes": [{"asset_id": "28013675818699191456107309488671219297858376503082476267618031773906710101322", "price": "0.209", "size": "9", "side": "BUY", "hash": "628de8b37629ce5032d2cfb3af03b7d408be195a", "best_bid": "0.998", "best_ask": "0.999"}, {"asset_id": "93601737054928362372096738986263364737270540163712701982280468693583918706009", "price": "0.791", "size": "9", "side": "SELL", "hash": "6ff9dc870799a4d18f008dac6f0ac496d09c6b5b", "best_bid": "0.001", "best_ask": "0.002"}], "timestamp": "1769384457271", "event_type": "price_change"}}
{"_local_timestamp": "2026-01-25T23:41:51.058995+00:00", "data": {"market": "0x489bfb9597099df16b34140399d2a1517e0a89623dabe94a3fccd4b48cab8bd3", "price_changes": [{"asset_id": "33913946998395403271106619237556153568227311613585470108892083199366217498076", "price": "0.002", "size": "283.78", "side": "BUY", "hash": "8c3e02cdf38876d9eb50632378ed09e762e6fc78", "best_bid": "0.041", "best_ask": "0.095"}, {"asset_id": "87569871218748662090769146890327376821466803212836644352988286023370072840603", "price": "0.998", "size": "283.78", "side": "SELL", "hash": "067b0156b6504d3b1deba25d98f0dc0c6639fe2c", "best_bid": "0.905", "best_ask": "0.959"}], "timestamp": "1769384510981", "event_type": "price_change"}}
{"_local_timestamp": "2026-01-25T23:41:51.499490+00:00", "data": {"market": "0x489bfb9597099df16b34140399d2a1517e0a89623dabe94a3fccd4b48cab8bd3", "price_changes": [{"asset_id": "33913946998395403271106619237556153568227311613585470108892083199366217498076", "price": "0.003", "size": "296.66", "side": "BUY", "hash": "f5758e50ccef49a7cf693875abe81beabd792905", "best_bid": "0.041", "best_ask": "0.095"}, {"asset_id": "87569871218748662090769146890327376821466803212836644352988286023370072840603", "price": "0.997", "size": "296.66", "side": "SELL", "hash": "54b9765ebf693c2b10add6c04d99c868f85611bc", "best_bid": "0.905", "best_ask": "0.959"}], "timestamp": "1769384511432", "event_type": "price_change"}}
{"_local_timestamp": "2026-01-25T23:41:53.113048+00:00", "data": {"market": "0x55d7602157ad134b7668cc486bb9c85096356c0dbd055c61344426b2d8c8291a", "price_changes": [{"asset_id": "7048930749192506070218770660352360569449638501759983423471267709999373115496", "price": "0.057", "size": "100", "side": "BUY", "hash": "2e4a91abd269eed689a05adfbae8f6117f6198a3", "best_bid": "0.994", "best_ask": "0.997"}, {"asset_id": "41208351236397166328872550854608550552314297451342384956165441312617513020672", "price": "0.943", "size": "100", "side": "SELL", "hash": "3f3c0536c7c62023484b5f66aef387ff57d7915b", "best_bid": "0.003", "best_ask": "0.006"}], "timestamp": "1769384512803", "event_type": "price_change"}}
{"_local_timestamp": "2026-01-25T23:41:53.336997+00:00", "data": {"market": "0x55d7602157ad134b7668cc486bb9c85096356c0dbd055c61344426b2d8c8291a", "price_changes": [{"asset_id": "7048930749192506070218770660352360569449638501759983423471267709999373115496", "price": "0.058", "size": "600", "side": "BUY", "hash": "f3814d1acfbaa5302e5a49367f1a134e1f5c3fc1", "best_bid": "0.994", "best_ask": "0.997"}, {"asset_id": "41208351236397166328872550854608550552314297451342384956165441312617513020672", "price": "0.942", "size": "600", "side": "SELL", "hash": "cf37c144ec88ea2e3808f1c82f98aacac659fa63", "best_bid": "0.003", "best_ask": "0.006"}], "timestamp": "1769384513268", "event_type": "price_change"}}
{"_local_timestamp": "2026-01-25T23:42:52.602922+00:00", "data": {"market": "0xdebb4d098d4382cebf6566acb3749226508e70e048e3a41a7fc44e94c6d0182a", "price_changes": [{"asset_id": "36753444559858254839802198257676788026485866301122066720655639390168841744924", "price": "0.542", "size": "0", "side": "BUY", "hash": "b6ed118291d02c9845b9c26e8926377a9b009a14", "best_bid": "0.977", "best_ask": "0.989"}, {"asset_id": "102436772013076156944295871423877161254159297346169261958329577570286200792258", "price": "0.458", "size": "0", "side": "SELL", "hash": "e46c809c72fc7c462f24d151613f36ef06f35121", "best_bid": "0.011", "best_ask": "0.023"}], "timestamp": "1769384572502", "event_type": "price_change"}}
{"_local_timestamp": "2026-01-25T23:42:52.649595+00:00", "data": {"market": "0xdebb4d098d4382cebf6566acb3749226508e70e048e3a41a7fc44e94c6d0182a", "price_changes": [{"asset_id": "36753444559858254839802198257676788026485866301122066720655639390168841744924", "price": "0.524", "size": "5", "side": "BUY", "hash": "5e296c2cebb58bb8a7b9b36aa8ba8941e783c639", "best_bid": "0.977", "best_ask": "0.989"}, {"asset_id": "102436772013076156944295871423877161254159297346169261958329577570286200792258", "price": "0.476", "size": "5", "side": "SELL", "hash": "e65d2e85843cbe1f9f9319ae2bafab28d4c16e6a", "best_bid": "0.011", "best_ask": "0.023"}], "timestamp": "1769384572553", "event_type": "price_change"}}
{"_local_timestamp": "2026-01-25T23:42:58.334506+00:00", "data": {"market": "0x67eb32405b2ad24182b8575eb560b3b087baa20340302a079bb8138637ed1b47", "price_changes": [{"asset_id": "91614728309695910310598383443496140750308657331105979804609645991161575447633", "price": "0.135", "size": "0", "side": "BUY", "hash": "c49f3e195f074fb0148f0efb9156c0bd14fad7b1", "best_bid": "0.998", "best_ask": "0.999"}, {"asset_id": "23177234539005086745924487565572514732873310188830333623513053312024465699839", "price": "0.865", "size": "0", "side": "SELL", "hash": "a95e48486ac185acbf547dbca873a7ba4005b3cd", "best_bid": "0.001", "best_ask": "0.002"}], "timestamp": "1769384578230", "event_type": "price_change"}}
{"_local_timestamp": "2026-01-25T23:42:58.529761+00:00", "data": {"market": "0x67eb32405b2ad24182b8575eb560b3b087baa20340302a079bb8138637ed1b47", "price_changes": [{"asset_id": "91614728309695910310598383443496140750308657331105979804609645991161575447633", "price": "0.056", "size": "500", "side": "BUY", "hash": "5cecdb95c10fba7aba385af63df29ddae91c66d9", "best_bid": "0.998", "best_ask": "0.999"}, {"asset_id": "23177234539005086745924487565572514732873310188830333623513053312024465699839", "price": "0.944", "size": "500", "side": "SELL", "hash": "4fb8ea594a596d02430b61620acef0e40a577cfd", "best_bid": "0.001", "best_ask": "0.002"}], "timestamp": "1769384578423", "event_type": "price_change"}}
{"_local_timestamp": "2026-01-25T23:42:58.733961+00:00", "data": {"market": "0x67eb32405b2ad24182b8575eb560b3b087baa20340302a079bb8138637ed1b47", "price_changes": [{"asset_id": "91614728309695910310598383443496140750308657331105979804609645991161575447633", "price": "0.026", "size": "0", "side": "BUY", "hash": "07a892613b82b7ffb18abe2bcdd498d8b45adbb8", "best_bid": "0.998", "best_ask": "0.999"}, {"asset_id": "23177234539005086745924487565572514732873310188830333623513053312024465699839", "price": "0.974", "size": "0", "side": "SELL", "hash": "5f61ecd81291cdea057556070229a0eae1d4d6e8", "best_bid": "0.001", "best_ask": "0.002"}], "timestamp": "1769384578629", "event_type": "price_change"}}
{"_local_timestamp": "2026-01-25T23:42:58.952196+00:00", "data": {"market": "0x67eb32405b2ad24182b8575eb560b3b087baa20340302a079bb8138637ed1b47", "price_changes": [{"asset_id": "91614728309695910310598383443496140750308657331105979804609645991161575447633", "price": "0.028", "size": "342.85", "side": "BUY", "hash": "db37186ec3c9c8cb45e91f79b60fbeaeef8dd861", "best_bid": "0.998", "best_ask": "0.999"}, {"asset_id": "23177234539005086745924487565572514732873310188830333623513053312024465699839", "price": "0.972", "size": "342.85", "side": "SELL", "hash": "7859c41594fa8eb3794e5b86a4a8b7238a619a7c", "best_bid": "0.001", "best_ask": "0.002"}], "timestamp": "1769384578847", "event_type": "price_change"}}
{"_local_timestamp": "2026-01-25T23:42:59.177584+00:00", "data": {"market": "0x67eb32405b2ad24182b8575eb560b3b087baa20340302a079bb8138637ed1b47", "price_changes": [{"asset_id": "91614728309695910310598383443496140750308657331105979804609645991161575447633", "price": "0.058", "size": "165.51", "side": "BUY", "hash": "23393a410f12185a7391c72b2e2b3434fc7a9930", "best_bid": "0.998", "best_ask": "0.999"}, {"asset_id": "23177234539005086745924487565572514732873310188830333623513053312024465699839", "price": "0.942", "size": "165.51", "side": "SELL", "hash": "bb79bb080efaa14dda4ba284428b1f20af5c6e89", "best_bid": "0.001", "best_ask": "0.002"}], "timestamp": "1769384579058", "event_type": "price_change"}}
{"_local_timestamp": "2026-01-25T23:42:59.372743+00:00", "data": {"market": "0x67eb32405b2ad24182b8575eb560b3b087baa20340302a079bb8138637ed1b47", "price_changes": [{"asset_id": "91614728309695910310598383443496140750308657331105979804609645991161575447633", "price": "0.081", "size": "118.51", "side": "BUY", "hash": "040a6cf4992492f83e47efc4b330f82492d75984", "best_bid": "0.998", "best_ask": "0.999"}, {"asset_id": "23177234539005086745924487565572514732873310188830333623513053312024465699839", "price": "0.919", "size": "118.51", "side": "SELL", "hash": "3ccf29821957968c49b726d2ab4cd23d4952244b", "best_bid": "0.001", "best_ask": "0.002"}], "timestamp": "1769384579271", "event_type": "price_change"}}
{"_local_timestamp": "2026-01-25T23:42:59.580907+00:00", "data": {"market": "0x67eb32405b2ad24182b8575eb560b3b087baa20340302a079bb8138637ed1b47", "price_changes": [{"asset_id": "91614728309695910310598383443496140750308657331105979804609645991161575447633", "price": "0.137", "size": "70.07", "side": "BUY", "hash": "9038dc6232a2896db943276fee2e7904673dfcce", "best_bid": "0.998", "best_ask": "0.999"}, {"asset_id": "23177234539005086745924487565572514732873310188830333623513053312024465699839", "price": "0.863", "size": "70.07", "side": "SELL", "hash": "b6ebe70a15b3d7d67e0fc27db6e8c480d509bf0d", "best_bid": "0.001", "best_ask": "0.002"}], "timestamp": "1769384579474", "event_type": "price_change"}}
{"_local_timestamp": "2026-01-25T23:42:59.786021+00:00", "data": {"market": "0x67eb32405b2ad24182b8575eb560b3b087baa20340302a079bb8138637ed1b47", "price_changes": [{"asset_id": "91614728309695910310598383443496140750308657331105979804609645991161575447633", "price": "0.242", "size": "0", "side": "BUY", "hash": "df35f992d820f040d9731f4541d60c2eb43f1a36", "best_bid": "0.998", "best_ask": "0.999"}, {"asset_id": "23177234539005086745924487565572514732873310188830333623513053312024465699839", "price": "0.758", "size": "0", "side": "SELL", "hash": "ab74bdaa5e3f8c82e12d8d90e15e95584ee776fc", "best_bid": "0.001", "best_ask": "0.002"}], "timestamp": "1769384579679", "event_type": "price_change"}}
{"_local_timestamp": "2026-01-25T23:43:00.005707+00:00", "data": {"market": "0x67eb32405b2ad24182b8575eb560b3b087baa20340302a079bb8138637ed1b47", "price_changes": [{"asset_id": "91614728309695910310598383443496140750308657331105979804609645991161575447633", "price": "0.242", "size": "39.66", "side": "BUY", "hash": "70915305d39d70c7cdcd9001adafc8969b78dd5a", "best_bid": "0.998", "best_ask": "0.999"}, {"asset_id": "23177234539005086745924487565572514732873310188830333623513053312024465699839", "price": "0.758", "size": "39.66", "side": "SELL", "hash": "69b4fd0fae70b590ea7104035bdbffda501bf53d", "best_bid": "0.001", "best_ask": "0.002"}], "timestamp": "1769384579887", "event_type": "price_change"}}
{"_local_timestamp": "2026-01-25T23:43:01.822006+00:00", "data": {"market": "0x7e2664fd56bdb98dfe10fc702d40c7bb34bbd173b4e1a4ace956e8bee3a15ed3", "price_changes": [{"asset_id": "32585257541944296536919042049344155455892911573822808260948030619026984605016", "price": "0.231", "size": "0", "side": "BUY", "hash": "4036df12c11101b07b80ff2c303bbb6a03840338", "best_bid": "0.998", "best_ask": "0.999"}, {"asset_id": "8013350309980067752092467553989532032941595361116376915087772932251249070671", "price": "0.769", "size": "0", "side": "SELL", "hash": "cd583e8b08d987f59f9716da01a0393ead8c6839", "best_bid": "0.001", "best_ask": "0.002"}], "timestamp": "1769384581731", "event_type": "price_change"}}
{"_local_timestamp": "2026-01-25T23:43:02.076929+00:00", "data": {"market": "0x7e2664fd56bdb98dfe10fc702d40c7bb34bbd173b4e1a4ace956e8bee3a15ed3", "price_changes": [{"asset_id": "32585257541944296536919042049344155455892911573822808260948030619026984605016", "price": "0.144", "size": "0", "side": "BUY", "hash": "b9723f1216862769d16419d9007da415e1e9ed22", "best_bid": "0.998", "best_ask": "0.999"}, {"asset_id": "8013350309980067752092467553989532032941595361116376915087772932251249070671", "price": "0.856", "size": "0", "side": "SELL", "hash": "b7c5e59de66b131061622d664afd21f70e6a0e9e", "best_bid": "0.001", "best_ask": "0.002"}], "timestamp": "1769384581971", "event_type": "price_change"}}
{"_local_timestamp": "2026-01-25T23:43:02.315952+00:00", "data": {"market": "0x7e2664fd56bdb98dfe10fc702d40c7bb34bbd173b4e1a4ace956e8bee3a15ed3", "price_changes": [{"asset_id": "32585257541944296536919042049344155455892911573822808260948030619026984605016", "price": "0.052", "size": "500", "side": "BUY", "hash": "626949dcfa75c2c853dbe02e55de11a06759d95c", "best_bid": "0.998", "best_ask": "0.999"}, {"asset_id": "8013350309980067752092467553989532032941595361116376915087772932251249070671", "price": "0.948", "size": "500", "side": "SELL", "hash": "126810bf55a277c66b85feea4c138538b4513ae1", "best_bid": "0.001", "best_ask": "0.002"}], "timestamp": "1769384582188", "event_type": "price_change"}}
{"_local_timestamp": "2026-01-25T23:43:02.472710+00:00", "data": {"market": "0x7e2664fd56bdb98dfe10fc702d40c7bb34bbd173b4e1a4ace956e8bee3a15ed3", "price_changes": [{"asset_id": "32585257541944296536919042049344155455892911573822808260948030619026984605016", "price": "0.025", "size": "0", "side": "BUY", "hash": "fa92940159ddd1b3656be890546933fadb5d083b", "best_bid": "0.998", "best_ask": "0.999"}, {"asset_id": "8013350309980067752092467553989532032941595361116376915087772932251249070671", "price": "0.975", "size": "0", "side": "SELL", "hash": "b5daec927c1eda61fe57838115733e215afc81f9", "best_bid": "0.001", "best_ask": "0.002"}], "timestamp": "1769384582374", "event_type": "price_change"}}
{"_local_timestamp": "2026-01-25T23:43:02.704785+00:00", "data": {"market": "0x7e2664fd56bdb98dfe10fc702d40c7bb34bbd173b4e1a4ace956e8bee3a15ed3", "price_changes": [{"asset_id": "32585257541944296536919042049344155455892911573822808260948030619026984605016", "price": "0.023", "size": "347.82", "side": "BUY", "hash": "f9109b469fad82e12ca615e796adad30bc0b8c7f", "best_bid": "0.998", "best_ask": "0.999"}, {"asset_id": "8013350309980067752092467553989532032941595361116376915087772932251249070671", "price": "0.977", "size": "347.82", "side": "SELL", "hash": "9bf055a8bcc8d4df06eb3efbfb09ea1b38141ff2", "best_bid": "0.001", "best_ask": "0.002"}], "timestamp": "1769384582606", "event_type": "price_change"}}
{"_local_timestamp": "2026-01-25T23:43:02.911185+00:00", "data": {"market": "0x7e2664fd56bdb98dfe10fc702d40c7bb34bbd173b4e1a4ace956e8bee3a15ed3", "price_changes": [{"asset_id": "32585257541944296536919042049344155455892911573822808260948030619026984605016", "price": "0.054", "size": "148.14", "side": "BUY", "hash": "35e40149c1afcc755be980636e24d59082351115", "best_bid": "0.998", "best_ask": "0.999"}, {"asset_id": "8013350309980067752092467553989532032941595361116376915087772932251249070671", "price": "0.946", "size": "148.14", "side": "SELL", "hash": "12f225f4cb6a2e21ad58a2246987e7db62572714", "best_bid": "0.001", "best_ask": "0.002"}], "timestamp": "1769384582810", "event_type": "price_change"}}
{"_local_timestamp": "2026-01-25T23:43:03.176600+00:00", "data": {"market": "0x7e2664fd56bdb98dfe10fc702d40c7bb34bbd173b4e1a4ace956e8bee3a15ed3", "price_changes": [{"asset_id": "32585257541944296536919042049344155455892911573822808260948030619026984605016", "price": "0.081", "size": "98.76", "side": "BUY", "hash": "1185b3c72f7d63f878a0e0bedf1a99b2d85b796b", "best_bid": "0.998", "best_ask": "0.999"}, {"asset_id": "8013350309980067752092467553989532032941595361116376915087772932251249070671", "price": "0.919", "size": "98.76", "side": "SELL", "hash": "22da00e1fa63c6699eb7fd489411052383bd7d8f", "best_bid": "0.001", "best_ask": "0.002"}], "timestamp": "1769384583033", "event_type": "price_change"}}
{"_local_timestamp": "2026-01-25T23:43:03.370934+00:00", "data": {"market": "0x7e2664fd56bdb98dfe10fc702d40c7bb34bbd173b4e1a4ace956e8bee3a15ed3", "price_changes": [{"asset_id": "32585257541944296536919042049344155455892911573822808260948030619026984605016", "price": "0.126", "size": "63.49", "side": "BUY", "hash": "e0d6ead3296ddbe52f4fee7e920c00336c36d416", "best_bid": "0.998", "best_ask": "0.999"}, {"asset_id": "8013350309980067752092467553989532032941595361116376915087772932251249070671", "price": "0.874", "size": "63.49", "side": "SELL", "hash": "14ecfc161f40522b7fbf8b024d447cd67784c034", "best_bid": "0.001", "best_ask": "0.002"}], "timestamp": "1769384583275", "event_type": "price_change"}}
{"_local_timestamp": "2026-01-25T23:43:03.577727+00:00", "data": {"market": "0x7e2664fd56bdb98dfe10fc702d40c7bb34bbd173b4e1a4ace956e8bee3a15ed3", "price_changes": [{"asset_id": "32585257541944296536919042049344155455892911573822808260948030619026984605016", "price": "0.146", "size": "54.79", "side": "BUY", "hash": "9b090876bf7c8f4f693e430203b837097114289c", "best_bid": "0.998", "best_ask": "0.999"}, {"asset_id": "8013350309980067752092467553989532032941595361116376915087772932251249070671", "price": "0.854", "size": "54.79", "side": "SELL", "hash": "f21ecf434aee8a485af3744db052e3ab6cb79df2", "best_bid": "0.001", "best_ask": "0.002"}], "timestamp": "1769384583483", "event_type": "price_change"}}
{"_local_timestamp": "2026-01-25T23:43:03.789747+00:00", "data": {"market": "0x7e2664fd56bdb98dfe10fc702d40c7bb34bbd173b4e1a4ace956e8bee3a15ed3", "price_changes": [{"asset_id": "32585257541944296536919042049344155455892911573822808260948030619026984605016", "price": "0.233", "size": "34.33", "side": "BUY", "hash": "afd785fd4a400c88ae4f4bed173c4b1893dc8f6d", "best_bid": "0.998", "best_ask": "0.999"}, {"asset_id": "8013350309980067752092467553989532032941595361116376915087772932251249070671", "price": "0.767", "size": "34.33", "side": "SELL", "hash": "4f61f5634a4d28523fc6902d0f270a06d4a23c3d", "best_bid": "0.001", "best_ask": "0.002"}], "timestamp": "1769384583691", "event_type": "price_change"}}
{"_local_timestamp": "2026-01-25T23:43:21.797883+00:00", "data": {"market": "0x469709d3554c9e9d26e8dea2516f8373669a9881ce505d57d75bff59fc58db75", "price_changes": [{"asset_id": "109460219863240579381274910433788899162940504407535154043224726152849933944106", "price": "0.224", "size": "0", "side": "BUY", "hash": "c86fc85b6df4ff0487706a510a76f81f20aa1410", "best_bid": "0.996", "best_ask": "0.999"}, {"asset_id": "71216154792191030083354473461386899246245242196096601702705023997087404907586", "price": "0.776", "size": "0", "side": "SELL", "hash": "83507079f54eae4a2f8f1686c4b94ac499c52fe5", "best_bid": "0.001", "best_ask": "0.004"}], "timestamp": "1769384601658", "event_type": "price_change"}}
{"_local_timestamp": "2026-01-25T23:43:21.853203+00:00", "data": {"market": "0x469709d3554c9e9d26e8dea2516f8373669a9881ce505d57d75bff59fc58db75", "price_changes": [{"asset_id": "109460219863240579381274910433788899162940504407535154043224726152849933944106", "price": "0.226", "size": "8", "side": "BUY", "hash": "ca9b357292379695a2c8f65be2bc2005537753a0", "best_bid": "0.996", "best_ask": "0.999"}, {"asset_id": "71216154792191030083354473461386899246245242196096601702705023997087404907586", "price": "0.774", "size": "8", "side": "SELL", "hash": "a259ec161efcf1c03db763dc3cb141ccaa4e4214", "best_bid": "0.001", "best_ask": "0.004"}], "timestamp": "1769384601718", "event_type": "price_change"}}
{"_local_timestamp": "2026-01-25T23:43:22.109798+00:00", "data": {"market": "0x768a10a2ba796df7c565166c61f1b708a7674565add5559f03bd1297d4997ac7", "price_changes": [{"asset_id": "52154086410665277054252505344124616126874295244982327401005145100880544734445", "price": "0.257", "size": "0", "side": "BUY", "hash": "e9b52b517e4a30b432155b14d64fc1e0885036d5", "best_bid": "0.995", "best_ask": "0.997"}, {"asset_id": "102376165613363136742721000249129649340591318769760895202636036152231642180566", "price": "0.743", "size": "0", "side": "SELL", "hash": "d3d9075fc7d6f1635dd9c782e8acde167de47502", "best_bid": "0.003", "best_ask": "0.005"}], "timestamp": "1769384601965", "event_type": "price_change"}}
{"_local_timestamp": "2026-01-25T23:43:22.297232+00:00", "data": {"market": "0x768a10a2ba796df7c565166c61f1b708a7674565add5559f03bd1297d4997ac7", "price_changes": [{"asset_id": "52154086410665277054252505344124616126874295244982327401005145100880544734445", "price": "0.183", "size": "0", "side": "BUY", "hash": "f438f95c1fcf5156697919de1b5f3a7093b746c4", "best_bid": "0.995", "best_ask": "0.997"}, {"asset_id": "102376165613363136742721000249129649340591318769760895202636036152231642180566", "price": "0.817", "size": "0", "side": "SELL", "hash": "94c41b147e20ef50685e6c58478ff885fefa005b", "best_bid": "0.003", "best_ask": "0.005"}], "timestamp": "1769384602163", "event_type": "price_change"}}
{"_local_timestamp": "2026-01-25T23:43:22.493616+00:00", "data": {"market": "0x768a10a2ba796df7c565166c61f1b708a7674565add5559f03bd1297d4997ac7", "price_changes": [{"asset_id": "52154086410665277054252505344124616126874295244982327401005145100880544734445", "price": "0.091", "size": "100", "side": "BUY", "hash": "4da57ab3bc6112836b9d1cdc6fac5e180a1399fa", "best_bid": "0.995", "best_ask": "0.997"}, {"asset_id": "102376165613363136742721000249129649340591318769760895202636036152231642180566", "price": "0.909", "size": "100", "side": "SELL", "hash": "abbc20ead32eb6d76034e216dcd8c16575a4daa9", "best_bid": "0.003", "best_ask": "0.005"}], "timestamp": "1769384602360", "event_type": "price_change"}}
{"_local_timestamp": "2026-01-25T23:43:22.679562+00:00", "data": {"market": "0x768a10a2ba796df7c565166c61f1b708a7674565add5559f03bd1297d4997ac7", "price_changes": [{"asset_id": "52154086410665277054252505344124616126874295244982327401005145100880544734445", "price": "0.072", "size": "0", "side": "BUY", "hash": "e8fdbab9d96d50df65c10de44ce9902b3cd38207", "best_bid": "0.995", "best_ask": "0.997"}, {"asset_id": "102376165613363136742721000249129649340591318769760895202636036152231642180566", "price": "0.928", "size": "0", "side": "SELL", "hash": "c099d1b382a3c8c2f8d6697278cccd32d3e759e4", "best_bid": "0.003", "best_ask": "0.005"}], "timestamp": "1769384602554", "event_type": "price_change"}}
{"_local_timestamp": "2026-01-25T23:43:22.911948+00:00", "data": {"market": "0x768a10a2ba796df7c565166c61f1b708a7674565add5559f03bd1297d4997ac7", "price_changes": [{"asset_id": "52154086410665277054252505344124616126874295244982327401005145100880544734445", "price": "0.028", "size": "700", "side": "BUY", "hash": "c0b2cdafa515396219262e738823ab7f83eb11a4", "best_bid": "0.995", "best_ask": "0.997"}, {"asset_id": "102376165613363136742721000249129649340591318769760895202636036152231642180566", "price": "0.972", "size": "700", "side": "SELL", "hash": "427ed226e0a07554fee2dbf41d8bc0624626220e", "best_bid": "0.003", "best_ask": "0.005"}], "timestamp": "1769384602742", "event_type": "price_change"}}
{"_local_timestamp": "2026-01-25T23:43:23.069152+00:00", "data": {"market": "0x768a10a2ba796df7c565166c61f1b708a7674565add5559f03bd1297d4997ac7", "price_changes": [{"asset_id": "52154086410665277054252505344124616126874295244982327401005145100880544734445", "price": "0.03", "size": "320", "side": "BUY", "hash": "ab093cc5f8ff9e8d5cefd28bcdfca6fd2d209d83", "best_bid": "0.995", "best_ask": "0.997"}, {"asset_id": "102376165613363136742721000249129649340591318769760895202636036152231642180566", "price": "0.97", "size": "320", "side": "SELL", "hash": "54e972c66f3232334de81c5ea186aa0c28b86031", "best_bid": "0.003", "best_ask": "0.005"}], "timestamp": "1769384602935", "event_type": "price_change"}}
{"_local_timestamp": "2026-01-25T23:43:23.244767+00:00", "data": {"market": "0x768a10a2ba796df7c565166c61f1b708a7674565add5559f03bd1297d4997ac7", "price_changes": [{"asset_id": "52154086410665277054252505344124616126874295244982327401005145100880544734445", "price": "0.052", "size": "184.61", "side": "BUY", "hash": "a8aeacfaeb97299c5da37241b32a982450f204f7", "best_bid": "0.995", "best_ask": "0.997"}, {"asset_id": "102376165613363136742721000249129649340591318769760895202636036152231642180566", "price": "0.948", "size": "184.61", "side": "SELL", "hash": "3632906f142b0cbbf3da028a7bda22c2064e92e8", "best_bid": "0.003", "best_ask": "0.005"}], "timestamp": "1769384603136", "event_type": "price_change"}}
{"_local_timestamp": "2026-01-25T23:43:23.452452+00:00", "data": {"market": "0x768a10a2ba796df7c565166c61f1b708a7674565add5559f03bd1297d4997ac7", "price_changes": [{"asset_id": "52154086410665277054252505344124616126874295244982327401005145100880544734445", "price": "0.093", "size": "604.22", "side": "BUY", "hash": "4dccf0cac14db7a66b80d9b1b8a32f81e67a38dc", "best_bid": "0.995", "best_ask": "0.997"}, {"asset_id": "102376165613363136742721000249129649340591318769760895202636036152231642180566", "price": "0.907", "size": "604.22", "side": "SELL", "hash": "f756bdae8b9cfa48578e14d8ac548aa1cfa11d67", "best_bid": "0.003", "best_ask": "0.005"}], "timestamp": "1769384603346", "event_type": "price_change"}}
{"_local_timestamp": "2026-01-25T23:43:23.688986+00:00", "data": {"market": "0x768a10a2ba796df7c565166c61f1b708a7674565add5559f03bd1297d4997ac7", "price_changes": [{"asset_id": "52154086410665277054252505344124616126874295244982327401005145100880544734445", "price": "0.185", "size": "51.89", "side": "BUY", "hash": "1b41002299c4390c3454c6a7f4e1a696f6046ee1", "best_bid": "0.995", "best_ask": "0.997"}, {"asset_id": "102376165613363136742721000249129649340591318769760895202636036152231642180566", "price": "0.815", "size": "51.89", "side": "SELL", "hash": "3cfec537d5e8c0ddb15b5c67f3f38d99c67aaeb8", "best_bid": "0.003", "best_ask": "0.005"}], "timestamp": "1769384603571", "event_type": "price_change"}}
{"_local_timestamp": "2026-01-25T23:43:23.892479+00:00", "data": {"market": "0x768a10a2ba796df7c565166c61f1b708a7674565add5559f03bd1297d4997ac7", "price_changes": [{"asset_id": "52154086410665277054252505344124616126874295244982327401005145100880544734445", "price": "0.259", "size": "37.06", "side": "BUY", "hash": "97ccbd1cbb260a620071dfef5f24ef7098beda67", "best_bid": "0.995", "best_ask": "0.997"}, {"asset_id": "102376165613363136742721000249129649340591318769760895202636036152231642180566", "price": "0.741", "size": "37.06", "side": "SELL", "hash": "b435f96566d8136ec06eb82d91c2a5fe7d6f921b", "best_bid": "0.003", "best_ask": "0.005"}], "timestamp": "1769384603780", "event_type": "price_change"}}
{"_local_timestamp": "2026-01-25T23:43:25.319678+00:00", "data": {"market": "0x489bfb9597099df16b34140399d2a1517e0a89623dabe94a3fccd4b48cab8bd3", "price_changes": [{"asset_id": "87569871218748662090769146890327376821466803212836644352988286023370072840603", "price": "0.601", "size": "0", "side": "BUY", "hash": "5baeb74a3772a1115ee2a711c5e9c8eda85b88ba", "best_bid": "0.905", "best_ask": "0.959"}, {"asset_id": "33913946998395403271106619237556153568227311613585470108892083199366217498076", "price": "0.399", "size": "0", "side": "SELL", "hash": "845f41b54628559378ce4d63b91ee21e7c504407", "best_bid": "0.041", "best_ask": "0.095"}], "timestamp": "1769384605201", "event_type": "price_change"}}
{"_local_timestamp": "2026-01-25T23:43:25.495607+00:00", "data": {"market": "0x489bfb9597099df16b34140399d2a1517e0a89623dabe94a3fccd4b48cab8bd3", "price_changes": [{"asset_id": "87569871218748662090769146890327376821466803212836644352988286023370072840603", "price": "0.6", "size": "200", "side": "BUY", "hash": "e74dafe86cbb2a5989741fceb75833c51f72d136", "best_bid": "0.905", "best_ask": "0.959"}, {"asset_id": "33913946998395403271106619237556153568227311613585470108892083199366217498076", "price": "0.4", "size": "200", "side": "SELL", "hash": "5b829064c3ce70ef5b1b2050e46bf230c6fb8e65", "best_bid": "0.041", "best_ask": "0.095"}], "timestamp": "1769384605376", "event_type": "price_change"}}
{"_local_timestamp": "2026-01-25T23:43:25.692186+00:00", "data": {"market": "0x489bfb9597099df16b34140399d2a1517e0a89623dabe94a3fccd4b48cab8bd3", "price_changes": [{"asset_id": "87569871218748662090769146890327376821466803212836644352988286023370072840603", "price": "0.5", "size": "80", "side": "BUY", "hash": "23e44ce938efdf268ed8654020cbbff5c37ac79c", "best_bid": "0.905", "best_ask": "0.959"}, {"asset_id": "33913946998395403271106619237556153568227311613585470108892083199366217498076", "price": "0.5", "size": "80", "side": "SELL", "hash": "d695f4d689132df1488e693861d5effdb07eb735", "best_bid": "0.041", "best_ask": "0.095"}], "timestamp": "1769384605579", "event_type": "price_change"}}
{"_local_timestamp": "2026-01-25T23:43:25.893399+00:00", "data": {"market": "0x489bfb9597099df16b34140399d2a1517e0a89623dabe94a3fccd4b48cab8bd3", "price_changes": [{"asset_id": "87569871218748662090769146890327376821466803212836644352988286023370072840603", "price": "0.021", "size": "700", "side": "BUY", "hash": "342da5092dc4dc41ac7da3ee37fb0ae54ee27900", "best_bid": "0.905", "best_ask": "0.959"}, {"asset_id": "33913946998395403271106619237556153568227311613585470108892083199366217498076", "price": "0.979", "size": "700", "side": "SELL", "hash": "acaa8bc4e329e7611167719d28491a1c5a6d3c8d", "best_bid": "0.041", "best_ask": "0.095"}], "timestamp": "1769384605785", "event_type": "price_change"}}
{"_local_timestamp": "2026-01-25T23:43:26.148255+00:00", "data": {"market": "0x489bfb9597099df16b34140399d2a1517e0a89623dabe94a3fccd4b48cab8bd3", "price_changes": [{"asset_id": "87569871218748662090769146890327376821466803212836644352988286023370072840603", "price": "0.012", "size": "800", "side": "BUY", "hash": "f198ce2afb372822b835f06e8e916558e553b64c", "best_bid": "0.905", "best_ask": "0.959"}, {"asset_id": "33913946998395403271106619237556153568227311613585470108892083199366217498076", "price": "0.988", "size": "800", "side": "SELL", "hash": "47a7b8c795d49165abc7e7838a6aa4562a07d8ad", "best_bid": "0.041", "best_ask": "0.095"}], "timestamp": "1769384606005", "event_type": "price_change"}}
{"_local_timestamp": "2026-01-25T23:43:26.307429+00:00", "data": {"market": "0x489bfb9597099df16b34140399d2a1517e0a89623dabe94a3fccd4b48cab8bd3", "price_changes": [{"asset_id": "87569871218748662090769146890327376821466803212836644352988286023370072840603", "price": "0.051", "size": "539", "side": "BUY", "hash": "a11a96ef58d4b046238bb156ac032c6b8a93e631", "best_bid": "0.905", "best_ask": "0.959"}, {"asset_id": "33913946998395403271106619237556153568227311613585470108892083199366217498076", "price": "0.949", "size": "539", "side": "SELL", "hash": "0db0ec77f3860690ca4ce824ee36a6dcd7828fff", "best_bid": "0.041", "best_ask": "0.095"}], "timestamp": "1769384606212", "event_type": "price_change"}}
{"_local_timestamp": "2026-01-25T23:43:26.519566+00:00", "data": {"market": "0x489bfb9597099df16b34140399d2a1517e0a89623dabe94a3fccd4b48cab8bd3", "price_changes": [{"asset_id": "87569871218748662090769146890327376821466803212836644352988286023370072840603", "price": "0.051", "size": "727.23", "side": "BUY", "hash": "e77d5f683fc165faa73b9777c72f0d4900e36e2c", "best_bid": "0.905", "best_ask": "0.959"}, {"asset_id": "33913946998395403271106619237556153568227311613585470108892083199366217498076", "price": "0.949", "size": "727.23", "side": "SELL", "hash": "81396828912b727ba88753c9d64738d58dd7599a", "best_bid": "0.041", "best_ask": "0.095"}], "timestamp": "1769384606421", "event_type": "price_change"}}
{"_local_timestamp": "2026-01-25T23:43:26.720828+00:00", "data": {"market": "0x489bfb9597099df16b34140399d2a1517e0a89623dabe94a3fccd4b48cab8bd3", "price_changes": [{"asset_id": "87569871218748662090769146890327376821466803212836644352988286023370072840603", "price": "0.115", "size": "0", "side": "BUY", "hash": "39126f4b4c52e4734216df262f409a0826ad31b2", "best_bid": "0.905", "best_ask": "0.959"}, {"asset_id": "33913946998395403271106619237556153568227311613585470108892083199366217498076", "price": "0.885", "size": "0", "side": "SELL", "hash": "d988c20a8f1f1bd59ed6fe1386f31c04e55ef509", "best_bid": "0.041", "best_ask": "0.095"}], "timestamp": "1769384606618", "event_type": "price_change"}}
{"_local_timestamp": "2026-01-25T23:43:26.909284+00:00", "data": {"market": "0x489bfb9597099df16b34140399d2a1517e0a89623dabe94a3fccd4b48cab8bd3", "price_changes": [{"asset_id": "87569871218748662090769146890327376821466803212836644352988286023370072840603", "price": "0.115", "size": "83.47", "side": "BUY", "hash": "719bc04e800b9070a8f62d4bfe235758fe3a42ea", "best_bid": "0.905", "best_ask": "0.959"}, {"asset_id": "33913946998395403271106619237556153568227311613585470108892083199366217498076", "price": "0.885", "size": "83.47", "side": "SELL", "hash": "3c2a87a60da8f50e5f981c9eb36bf1f91b2cab3d", "best_bid": "0.041", "best_ask": "0.095"}], "timestamp": "1769384606810", "event_type": "price_change"}}
{"_local_timestamp": "2026-01-25T23:43:27.153180+00:00", "data": {"market": "0x489bfb9597099df16b34140399d2a1517e0a89623dabe94a3fccd4b48cab8bd3", "price_changes": [{"asset_id": "87569871218748662090769146890327376821466803212836644352988286023370072840603", "price": "0.147", "size": "0", "side": "BUY", "hash": "d8819d9b4d2567ecdacda7e7a7df656e34da1335", "best_bid": "0.905", "best_ask": "0.959"}, {"asset_id": "33913946998395403271106619237556153568227311613585470108892083199366217498076", "price": "0.853", "size": "0", "side": "SELL", "hash": "8be7a67232720d14c6c5b01c26c0a0d0368ac001", "best_bid": "0.041", "best_ask": "0.095"}], "timestamp": "1769384607020", "event_type": "price_change"}}
{"_local_timestamp": "2026-01-25T23:43:27.324594+00:00", "data": {"market": "0x489bfb9597099df16b34140399d2a1517e0a89623dabe94a3fccd4b48cab8bd3", "price_changes": [{"asset_id": "87569871218748662090769146890327376821466803212836644352988286023370072840603", "price": "0.147", "size": "65.3", "side": "BUY", "hash": "235eb07541d5f3666bba648e8c4283747b61fab9", "best_bid": "0.905", "best_ask": "0.959"}, {"asset_id": "33913946998395403271106619237556153568227311613585470108892083199366217498076", "price": "0.853", "size": "65.3", "side": "SELL", "hash": "1951099d24406e7872cab860ec1c7027124bd0a6", "best_bid": "0.041", "best_ask": "0.095"}], "timestamp": "1769384607232", "event_type": "price_change"}}
{"_local_timestamp": "2026-01-25T23:43:27.559113+00:00", "data": {"market": "0x489bfb9597099df16b34140399d2a1517e0a89623dabe94a3fccd4b48cab8bd3", "price_changes": [{"asset_id": "87569871218748662090769146890327376821466803212836644352988286023370072840603", "price": "0.502", "size": "19.12", "side": "BUY", "hash": "b3db456ee7f1a1798ed07e7635026090bde92be0", "best_bid": "0.905", "best_ask": "0.959"}, {"asset_id": "33913946998395403271106619237556153568227311613585470108892083199366217498076", "price": "0.498", "size": "19.12", "side": "SELL", "hash": "9fd275cf360dc875d02fac30c7e628fc404338f4", "best_bid": "0.041", "best_ask": "0.095"}], "timestamp": "1769384607460", "event_type": "price_change"}}
{"_local_timestamp": "2026-01-25T23:43:31.614330+00:00", "data": {"market": "0x469709d3554c9e9d26e8dea2516f8373669a9881ce505d57d75bff59fc58db75", "price_changes": [{"asset_id": "109460219863240579381274910433788899162940504407535154043224726152849933944106", "price": "0.119", "size": "100", "side": "BUY", "hash": "49f583f37c7f5d3441c8c667b83dea443d1842da", "best_bid": "0.996", "best_ask": "0.999"}, {"asset_id": "71216154792191030083354473461386899246245242196096601702705023997087404907586", "price": "0.881", "size": "100", "side": "SELL", "hash": "8cdf25fc930accb019a02787919e62ebb81281ea", "best_bid": "0.001", "best_ask": "0.004"}], "timestamp": "1769384611511", "event_type": "price_change"}}
{"_local_timestamp": "2026-01-25T23:43:31.802707+00:00", "data": {"market": "0x469709d3554c9e9d26e8dea2516f8373669a9881ce505d57d75bff59fc58db75", "price_changes": [{"asset_id": "109460219863240579381274910433788899162940504407535154043224726152849933944106", "price": "0.023", "size": "0", "side": "BUY", "hash": "65a522c948d8729e11df9aeb89ccd09e23085538", "best_bid": "0.996", "best_ask": "0.999"}, {"asset_id": "71216154792191030083354473461386899246245242196096601702705023997087404907586", "price": "0.977", "size": "0", "side": "SELL", "hash": "f24db74adeaf8f60a257548e49d27a75b619ffb9", "best_bid": "0.001", "best_ask": "0.004"}], "timestamp": "1769384611708", "event_type": "price_change"}}
{"_local_timestamp": "2026-01-25T23:43:32.022085+00:00", "data": {"market": "0x469709d3554c9e9d26e8dea2516f8373669a9881ce505d57d75bff59fc58db75", "price_changes": [{"asset_id": "109460219863240579381274910433788899162940504407535154043224726152849933944106", "price": "0.025", "size": "480", "side": "BUY", "hash": "fbac8ad0d0c3f22bcc55abd18bc8ab6c39412a78", "best_bid": "0.996", "best_ask": "0.999"}, {"asset_id": "71216154792191030083354473461386899246245242196096601702705023997087404907586", "price": "0.975", "size": "480", "side": "SELL", "hash": "e83085e65dee54fdc246faa9db078da8e2f85f63", "best_bid": "0.001", "best_ask": "0.004"}], "timestamp": "1769384611929", "event_type": "price_change"}}
{"_local_timestamp": "2026-01-25T23:43:32.240024+00:00", "data": {"market": "0x469709d3554c9e9d26e8dea2516f8373669a9881ce505d57d75bff59fc58db75", "price_changes": [{"asset_id": "109460219863240579381274910433788899162940504407535154043224726152849933944106", "price": "0.121", "size": "105.17", "side": "BUY", "hash": "a9f492fc70db0f6a00d6bc775e4b08370fa3d08a", "best_bid": "0.996", "best_ask": "0.999"}, {"asset_id": "71216154792191030083354473461386899246245242196096601702705023997087404907586", "price": "0.879", "size": "105.17", "side": "SELL", "hash": "4cbe1c9d266ad33495f11c0d91bb4539252a6cd2", "best_bid": "0.001", "best_ask": "0.004"}], "timestamp": "1769384612143", "event_type": "price_change"}}
{"_local_timestamp": "2026-01-25T23:43:35.878982+00:00", "data": {"market": "0x7d06087c987916fcdd813c298ea61fe8154fbe186872cf416bad99c2abe1e28b", "price_changes": [{"asset_id": "67302540724762161307896112522088102200482553778240942791214901770569400222178", "price": "0.291", "size": "0", "side": "BUY", "hash": "bb824230086622f3eba32a78a9f1c2a65171d0e3", "best_bid": "0.996", "best_ask": "0.997"}, {"asset_id": "53184392184731073294596377638963528940590267478279064727563854235726442195657", "price": "0.709", "size": "0", "side": "SELL", "hash": "b3dff252a46c268e3288453c7167b7fb336a0664", "best_bid": "0.003", "best_ask": "0.004"}], "timestamp": "1769384615768", "event_type": "price_change"}}
{"_local_timestamp": "2026-01-25T23:43:36.031270+00:00", "data": {"market": "0x7d06087c987916fcdd813c298ea61fe8154fbe186872cf416bad99c2abe1e28b", "price_changes": [{"asset_id": "67302540724762161307896112522088102200482553778240942791214901770569400222178", "price": "0.177", "size": "0", "side": "BUY", "hash": "de6e138b20d9f6b65abb6bad43b0fb151422ba7e", "best_bid": "0.996", "best_ask": "0.997"}, {"asset_id": "53184392184731073294596377638963528940590267478279064727563854235726442195657", "price": "0.823", "size": "0", "side": "SELL", "hash": "22b9416cb9e32003e085ceef105caa401cc4bf4b", "best_bid": "0.003", "best_ask": "0.004"}], "timestamp": "1769384615939", "event_type": "price_change"}}
{"_local_timestamp": "2026-01-25T23:43:36.227955+00:00", "data": {"market": "0x7d06087c987916fcdd813c298ea61fe8154fbe186872cf416bad99c2abe1e28b", "price_changes": [{"asset_id": "67302540724762161307896112522088102200482553778240942791214901770569400222178", "price": "0.081", "size": "300", "side": "BUY", "hash": "231d6da9c51ba7d8c115b045328455903864f4d7", "best_bid": "0.996", "best_ask": "0.997"}, {"asset_id": "53184392184731073294596377638963528940590267478279064727563854235726442195657", "price": "0.919", "size": "300", "side": "SELL", "hash": "f50a9249faae35feae4ad7050dc8b31acc8d8f63", "best_bid": "0.003", "best_ask": "0.004"}], "timestamp": "1769384616137", "event_type": "price_change"}}
{"_local_timestamp": "2026-01-25T23:43:36.417804+00:00", "data": {"market": "0x7d06087c987916fcdd813c298ea61fe8154fbe186872cf416bad99c2abe1e28b", "price_changes": [{"asset_id": "67302540724762161307896112522088102200482553778240942791214901770569400222178", "price": "0.032", "size": "700", "side": "BUY", "hash": "e4ce97094f6146b6bc748047431736cb4f8aecee", "best_bid": "0.996", "best_ask": "0.997"}, {"asset_id": "53184392184731073294596377638963528940590267478279064727563854235726442195657", "price": "0.968", "size": "700", "side": "SELL", "hash": "d6fd65637c0a358874b94686b25ccc939a399acb", "best_bid": "0.003", "best_ask": "0.004"}], "timestamp": "1769384616336", "event_type": "price_change"}}
{"_local_timestamp": "2026-01-25T23:43:36.637278+00:00", "data": {"market": "0x7d06087c987916fcdd813c298ea61fe8154fbe186872cf416bad99c2abe1e28b", "price_changes": [{"asset_id": "67302540724762161307896112522088102200482553778240942791214901770569400222178", "price": "0.034", "size": "282.35", "side": "BUY", "hash": "74068b0b84ae8688f04b8389731c91c9a2af7fc5", "best_bid": "0.996", "best_ask": "0.997"}, {"asset_id": "53184392184731073294596377638963528940590267478279064727563854235726442195657", "price": "0.966", "size": "282.35", "side": "SELL", "hash": "274eee3ca75fa888185d15688a73e47fd31a177c", "best_bid": "0.003", "best_ask": "0.004"}], "timestamp": "1769384616558", "event_type": "price_change"}}
{"_local_timestamp": "2026-01-25T23:43:36.864653+00:00", "data": {"market": "0x7d06087c987916fcdd813c298ea61fe8154fbe186872cf416bad99c2abe1e28b", "price_changes": [{"asset_id": "67302540724762161307896112522088102200482553778240942791214901770569400222178", "price": "0.074", "size": "129.72", "side": "BUY", "hash": "2311368ccfd3aff1d66e9af4957bea4454b636ea", "best_bid": "0.996", "best_ask": "0.997"}, {"asset_id": "53184392184731073294596377638963528940590267478279064727563854235726442195657", "price": "0.926", "size": "129.72", "side": "SELL", "hash": "97f4b2da27fdac24f1eb59eb36edceb9c346d9c0", "best_bid": "0.003", "best_ask": "0.004"}], "timestamp": "1769384616779", "event_type": "price_change"}}
{"_local_timestamp": "2026-01-25T23:43:37.124343+00:00", "data": {"market": "0x7d06087c987916fcdd813c298ea61fe8154fbe186872cf416bad99c2abe1e28b", "price_changes": [{"asset_id": "67302540724762161307896112522088102200482553778240942791214901770569400222178", "price": "0.179", "size": "53.63", "side": "BUY", "hash": "bee908fb0bb88db574287a7d231ccbf8d73ee817", "best_bid": "0.996", "best_ask": "0.997"}, {"asset_id": "53184392184731073294596377638963528940590267478279064727563854235726442195657", "price": "0.821", "size": "53.63", "side": "SELL", "hash": "2064790d10a92aac8ada826784b4633654446b9d", "best_bid": "0.003", "best_ask": "0.004"}], "timestamp": "1769384617018", "event_type": "price_change"}}
{"_local_timestamp": "2026-01-25T23:43:37.310000+00:00", "data": {"market": "0x7d06087c987916fcdd813c298ea61fe8154fbe186872cf416bad99c2abe1e28b", "price_changes": [{"asset_id": "67302540724762161307896112522088102200482553778240942791214901770569400222178", "price": "0.293", "size": "32.76", "side": "BUY", "hash": "1d6c0f5c57030dc5e27fe5ab4be5eecb9c2949e3", "best_bid": "0.996", "best_ask": "0.997"}, {"asset_id": "53184392184731073294596377638963528940590267478279064727563854235726442195657", "price": "0.707", "size": "32.76", "side": "SELL", "hash": "e38a1e40f9836251852f6cb540f92af606552882", "best_bid": "0.003", "best_ask": "0.004"}], "timestamp": "1769384617237", "event_type": "price_change"}}
{"_local_timestamp": "2026-01-25T23:43:37.519224+00:00", "data": {"market": "0x6a72f5b1d7edf1261156080ddc026da3d80a78834c12925a7bfea4a8aa5b8fb8", "price_changes": [{"asset_id": "18638298170773700688520436893150989158645425879508160426041188051588302722446", "price": "0.259", "size": "0", "side": "BUY", "hash": "995f86a6e35bc64d318b65c5f3289e2b51227dcd", "best_bid": "0.997", "best_ask": "0.999"}, {"asset_id": "56323539615651816818267229259150871177627322204823867354832755297469690554470", "price": "0.741", "size": "0", "side": "SELL", "hash": "591bb94136fec8575dddbebb4a4f88d84de4c01b", "best_bid": "0.001", "best_ask": "0.003"}], "timestamp": "1769384617448", "event_type": "price_change"}}
{"_local_timestamp": "2026-01-25T23:43:37.743625+00:00", "data": {"market": "0x6a72f5b1d7edf1261156080ddc026da3d80a78834c12925a7bfea4a8aa5b8fb8", "price_changes": [{"asset_id": "18638298170773700688520436893150989158645425879508160426041188051588302722446", "price": "0.164", "size": "0", "side": "BUY", "hash": "5c35558f20f76ec0dcab866f7d71e56c39e73fd5", "best_bid": "0.997", "best_ask": "0.999"}, {"asset_id": "56323539615651816818267229259150871177627322204823867354832755297469690554470", "price": "0.836", "size": "0", "side": "SELL", "hash": "3f716534b70f70e93f47dab3267b20113e16bc2c", "best_bid": "0.001", "best_ask": "0.003"}], "timestamp": "1769384617648", "event_type": "price_change"}}
{"_local_timestamp": "2026-01-25T23:43:37.893995+00:00", "data": {"market": "0x6a72f5b1d7edf1261156080ddc026da3d80a78834c12925a7bfea4a8aa5b8fb8", "price_changes": [{"asset_id": "18638298170773700688520436893150989158645425879508160426041188051588302722446", "price": "0.081", "size": "300", "side": "BUY", "hash": "a245be79f4945859d7afa6861032d4886a609654", "best_bid": "0.997", "best_ask": "0.999"}, {"asset_id": "56323539615651816818267229259150871177627322204823867354832755297469690554470", "price": "0.919", "size": "300", "side": "SELL", "hash": "d7593bfa3b3cadcb99c45eeef5a6068a49617440", "best_bid": "0.001", "best_ask": "0.003"}], "timestamp": "1769384617827", "event_type": "price_change"}}
{"_local_timestamp": "2026-01-25T23:43:38.116164+00:00", "data": {"market": "0x6a72f5b1d7edf1261156080ddc026da3d80a78834c12925a7bfea4a8aa5b8fb8", "price_changes": [{"asset_id": "18638298170773700688520436893150989158645425879508160426041188051588302722446", "price": "0.024", "size": "700", "side": "BUY", "hash": "cef0eb65e64d0811202e7191bee1c08ddafdcbf9", "best_bid": "0.997", "best_ask": "0.999"}, {"asset_id": "56323539615651816818267229259150871177627322204823867354832755297469690554470", "price": "0.976", "size": "700", "side": "SELL", "hash": "0936a20885775921993234a6be6708d397740a26", "best_bid": "0.001", "best_ask": "0.003"}], "timestamp": "1769384618019", "event_type": "price_change"}}
{"_local_timestamp": "2026-01-25T23:43:38.302426+00:00", "data": {"market": "0x6a72f5b1d7edf1261156080ddc026da3d80a78834c12925a7bfea4a8aa5b8fb8", "price_changes": [{"asset_id": "18638298170773700688520436893150989158645425879508160426041188051588302722446", "price": "0.026", "size": "461.53", "side": "BUY", "hash": "f194bbb763b480921dc43d761e8c09def45d9d7e", "best_bid": "0.997", "best_ask": "0.999"}, {"asset_id": "56323539615651816818267229259150871177627322204823867354832755297469690554470", "price": "0.974", "size": "461.53", "side": "SELL", "hash": "b3e7fd0d8f3afcfded5d65282df22448b164a0ab", "best_bid": "0.001", "best_ask": "0.003"}], "timestamp": "1769384618237", "event_type": "price_change"}}
{"_local_timestamp": "2026-01-25T23:43:38.524042+00:00", "data": {"market": "0x6a72f5b1d7edf1261156080ddc026da3d80a78834c12925a7bfea4a8aa5b8fb8", "price_changes": [{"asset_id": "18638298170773700688520436893150989158645425879508160426041188051588302722446", "price": "0.072", "size": "5.12", "side": "BUY", "hash": "458d718ca3f32f3de45eff3363c490831bdd3ad0", "best_bid": "0.997", "best_ask": "0.999"}, {"asset_id": "56323539615651816818267229259150871177627322204823867354832755297469690554470", "price": "0.928", "size": "5.12", "side": "SELL", "hash": "e1dbc71815bd56100cb1edbed8b7518f60f091bb", "best_bid": "0.001", "best_ask": "0.003"}], "timestamp": "1769384618452", "event_type": "price_change"}}
{"_local_timestamp": "2026-01-25T23:43:38.736366+00:00", "data": {"market": "0x6a72f5b1d7edf1261156080ddc026da3d80a78834c12925a7bfea4a8aa5b8fb8", "price_changes": [{"asset_id": "18638298170773700688520436893150989158645425879508160426041188051588302722446", "price": "0.072", "size": "171.78", "side": "BUY", "hash": "591f59c8e46208f43c5479f72fecb4ad0eabe373", "best_bid": "0.997", "best_ask": "0.999"}, {"asset_id": "56323539615651816818267229259150871177627322204823867354832755297469690554470", "price": "0.928", "size": "171.78", "side": "SELL", "hash": "ae1193f8ea46b5a60a3e05a9f19d77f4e337b63b", "best_bid": "0.001", "best_ask": "0.003"}], "timestamp": "1769384618661", "event_type": "price_change"}}
{"_local_timestamp": "2026-01-25T23:43:38.751329+00:00", "data": {"market": "0x768a10a2ba796df7c565166c61f1b708a7674565add5559f03bd1297d4997ac7", "price_changes": [{"asset_id": "52154086410665277054252505344124616126874295244982327401005145100880544734445", "price": "0.001", "size": "1102747", "side": "BUY", "hash": "35d906c11fcf2485040bea39bbedfef35f3e3552", "best_bid": "0.995", "best_ask": "0.997"}, {"asset_id": "102376165613363136742721000249129649340591318769760895202636036152231642180566", "price": "0.999", "size": "1102747", "side": "SELL", "hash": "eb384f3bbcea4e85530fdae149be29c0d6e24a8b", "best_bid": "0.003", "best_ask": "0.005"}], "timestamp": "1769384618672", "event_type": "price_change"}}
{"_local_timestamp": "2026-01-25T23:43:38.751908+00:00", "data": {"market": "0x768a10a2ba796df7c565166c61f1b708a7674565add5559f03bd1297d4997ac7", "price_changes": [{"asset_id": "52154086410665277054252505344124616126874295244982327401005145100880544734445", "price": "0.004", "size": "0", "side": "BUY", "hash": "35d906c11fcf2485040bea39bbedfef35f3e3552", "best_bid": "0.995", "best_ask": "0.997"}, {"asset_id": "102376165613363136742721000249129649340591318769760895202636036152231642180566", "price": "0.996", "size": "0", "side": "SELL", "hash": "eb384f3bbcea4e85530fdae149be29c0d6e24a8b", "best_bid": "0.003", "best_ask": "0.005"}], "timestamp": "1769384618672", "event_type": "price_change"}}
{"_local_timestamp": "2026-01-25T23:43:38.752360+00:00", "data": {"market": "0x768a10a2ba796df7c565166c61f1b708a7674565add5559f03bd1297d4997ac7", "price_changes": [{"asset_id": "52154086410665277054252505344124616126874295244982327401005145100880544734445", "price": "0.029", "size": "0", "side": "BUY", "hash": "35d906c11fcf2485040bea39bbedfef35f3e3552", "best_bid": "0.995", "best_ask": "0.997"}, {"asset_id": "102376165613363136742721000249129649340591318769760895202636036152231642180566", "price": "0.971", "size": "0", "side": "SELL", "hash": "eb384f3bbcea4e85530fdae149be29c0d6e24a8b", "best_bid": "0.003", "best_ask": "0.005"}], "timestamp": "1769384618672", "event_type": "price_change"}}
{"_local_timestamp": "2026-01-25T23:43:38.752784+00:00", "data": {"market": "0x768a10a2ba796df7c565166c61f1b708a7674565add5559f03bd1297d4997ac7", "price_changes": [{"asset_id": "52154086410665277054252505344124616126874295244982327401005145100880544734445", "price": "0.073", "size": "0", "side": "BUY", "hash": "35d906c11fcf2485040bea39bbedfef35f3e3552", "best_bid": "0.995", "best_ask": "0.997"}, {"asset_id": "102376165613363136742721000249129649340591318769760895202636036152231642180566", "price": "0.927", "size": "0", "side": "SELL", "hash": "eb384f3bbcea4e85530fdae149be29c0d6e24a8b", "best_bid": "0.003", "best_ask": "0.005"}], "timestamp": "1769384618672", "event_type": "price_change"}}
{"_local_timestamp": "2026-01-25T23:43:38.753195+00:00", "data": {"market": "0x768a10a2ba796df7c565166c61f1b708a7674565add5559f03bd1297d4997ac7", "price_changes": [{"asset_id": "52154086410665277054252505344124616126874295244982327401005145100880544734445", "price": "0.184", "size": "0", "side": "BUY", "hash": "35d906c11fcf2485040bea39bbedfef35f3e3552", "best_bid": "0.995", "best_ask": "0.997"}, {"asset_id": "102376165613363136742721000249129649340591318769760895202636036152231642180566", "price": "0.816", "size": "0", "side": "SELL", "hash": "eb384f3bbcea4e85530fdae149be29c0d6e24a8b", "best_bid": "0.003", "best_ask": "0.005"}], "timestamp": "1769384618672", "event_type": "price_change"}}
{"_local_timestamp": "2026-01-25T23:43:39.001624+00:00", "data": {"market": "0x6a72f5b1d7edf1261156080ddc026da3d80a78834c12925a7bfea4a8aa5b8fb8", "price_changes": [{"asset_id": "18638298170773700688520436893150989158645425879508160426041188051588302722446", "price": "0.166", "size": "72.28", "side": "BUY", "hash": "95d42cfbf758513985fb7d98f365d7c69079fe88", "best_bid": "0.997", "best_ask": "0.999"}, {"asset_id": "56323539615651816818267229259150871177627322204823867354832755297469690554470", "price": "0.834", "size": "72.28", "side": "SELL", "hash": "208ecfc391a06459f0b2c02744d2f3bc0499bf00", "best_bid": "0.001", "best_ask": "0.003"}], "timestamp": "1769384618892", "event_type": "price_change"}}
{"_local_timestamp": "2026-01-25T23:43:39.166742+00:00", "data": {"market": "0x6a72f5b1d7edf1261156080ddc026da3d80a78834c12925a7bfea4a8aa5b8fb8", "price_changes": [{"asset_id": "18638298170773700688520436893150989158645425879508160426041188051588302722446", "price": "0.261", "size": "45.97", "side": "BUY", "hash": "7e861c4421c6fa5b17532ffee0f28719b504d3a1", "best_bid": "0.997", "best_ask": "0.999"}, {"asset_id": "56323539615651816818267229259150871177627322204823867354832755297469690554470", "price": "0.739", "size": "45.97", "side": "SELL", "hash": "c6088b4b26dfb64dc8dcf568500ac7e41c00adf5", "best_bid": "0.001", "best_ask": "0.003"}], "timestamp": "1769384619100", "event_type": "price_change"}}
{"_local_timestamp": "2026-01-25T23:43:39.181512+00:00", "data": {"market": "0x6a72f5b1d7edf1261156080ddc026da3d80a78834c12925a7bfea4a8aa5b8fb8", "price_changes": [{"asset_id": "18638298170773700688520436893150989158645425879508160426041188051588302722446", "price": "0.025", "size": "0", "side": "BUY", "hash": "a603118769ec4be17355969a515f3312d3fa23cf", "best_bid": "0.997", "best_ask": "0.999"}, {"asset_id": "56323539615651816818267229259150871177627322204823867354832755297469690554470", "price": "0.975", "size": "0", "side": "SELL", "hash": "593c79ba0ab7baae90131429b83d20851d81e15a", "best_bid": "0.001", "best_ask": "0.003"}], "timestamp": "1769384619110", "event_type": "price_change"}}
{"_local_timestamp": "2026-01-25T23:43:39.182115+00:00", "data": {"market": "0x6f3819aefa464a63c3a54d9e079ad59ba194b015de3f4dae4f16d822eeb5dd2e", "price_changes": [{"asset_id": "82873337478696874311026595893708524418275224909062608016173074343863041369337", "price": "0.011", "size": "5.3", "side": "BUY", "hash": "fdfffc3dc3023d1f41e3a657c3d5f83e6ef2fd86", "best_bid": "0.998", "best_ask": "0.999"}, {"asset_id": "88141572307574703189103808906541737578361491725632656938888428716809889579606", "price": "0.989", "size": "5.3", "side": "SELL", "hash": "186021306e706889abf3a3246ef849dbeae89034", "best_bid": "0.001", "best_ask": "0.002"}], "timestamp": "1769384619110", "event_type": "price_change"}}
{"_local_timestamp": "2026-01-25T23:43:39.182599+00:00", "data": {"market": "0x6a72f5b1d7edf1261156080ddc026da3d80a78834c12925a7bfea4a8aa5b8fb8", "price_changes": [{"asset_id": "18638298170773700688520436893150989158645425879508160426041188051588302722446", "price": "0.072", "size": "166.66", "side": "BUY", "hash": "a603118769ec4be17355969a515f3312d3fa23cf", "best_bid": "0.997", "best_ask": "0.999"}, {"asset_id": "56323539615651816818267229259150871177627322204823867354832755297469690554470", "price": "0.928", "size": "166.66", "side": "SELL", "hash": "593c79ba0ab7baae90131429b83d20851d81e15a", "best_bid": "0.001", "best_ask": "0.003"}], "timestamp": "1769384619110", "event_type": "price_change"}}
{"_local_timestamp": "2026-01-25T23:43:39.183049+00:00", "data": {"market": "0x469709d3554c9e9d26e8dea2516f8373669a9881ce505d57d75bff59fc58db75", "price_changes": [{"asset_id": "109460219863240579381274910433788899162940504407535154043224726152849933944106", "price": "0.024", "size": "0", "side": "BUY", "hash": "4b2d5104e0734ec88d74d57a8ab4d63b1cd343cd", "best_bid": "0.996", "best_ask": "0.999"}, {"asset_id": "71216154792191030083354473461386899246245242196096601702705023997087404907586", "price": "0.976", "size": "0", "side": "SELL", "hash": "87d37131d5307e1bc60f683fb23a38f3dd16798b", "best_bid": "0.001", "best_ask": "0.004"}], "timestamp": "1769384619110", "event_type": "price_change"}}
{"_local_timestamp": "2026-01-25T23:43:39.183490+00:00", "data": {"market": "0x6a72f5b1d7edf1261156080ddc026da3d80a78834c12925a7bfea4a8aa5b8fb8", "price_changes": [{"asset_id": "18638298170773700688520436893150989158645425879508160426041188051588302722446", "price": "0.165", "size": "0", "side": "BUY", "hash": "a603118769ec4be17355969a515f3312d3fa23cf", "best_bid": "0.997", "best_ask": "0.999"}, {"asset_id": "56323539615651816818267229259150871177627322204823867354832755297469690554470", "price": "0.835", "size": "0", "side": "SELL", "hash": "593c79ba0ab7baae90131429b83d20851d81e15a", "best_bid": "0.001", "best_ask": "0.003"}], "timestamp": "1769384619110", "event_type": "price_change"}}
{"_local_timestamp": "2026-01-25T23:43:39.183983+00:00", "data": {"market": "0x469709d3554c9e9d26e8dea2516f8373669a9881ce505d57d75bff59fc58db75", "price_changes": [{"asset_id": "109460219863240579381274910433788899162940504407535154043224726152849933944106", "price": "0.052", "size": "0", "side": "BUY", "hash": "4b2d5104e0734ec88d74d57a8ab4d63b1cd343cd", "best_bid": "0.996", "best_ask": "0.999"}, {"asset_id": "71216154792191030083354473461386899246245242196096601702705023997087404907586", "price": "0.948", "size": "0", "side": "SELL", "hash": "87d37131d5307e1bc60f683fb23a38f3dd16798b", "best_bid": "0.001", "best_ask": "0.004"}], "timestamp": "1769384619110", "event_type": "price_change"}}
{"_local_timestamp": "2026-01-25T23:43:39.184446+00:00", "data": {"market": "0x7d06087c987916fcdd813c298ea61fe8154fbe186872cf416bad99c2abe1e28b", "price_changes": [{"asset_id": "67302540724762161307896112522088102200482553778240942791214901770569400222178", "price": "0.033", "size": "0", "side": "BUY", "hash": "d92a1ecd5e8588061e6ce311e5e31b1af40784a1", "best_bid": "0.996", "best_ask": "0.997"}, {"asset_id": "53184392184731073294596377638963528940590267478279064727563854235726442195657", "price": "0.967", "size": "0", "side": "SELL", "hash": "3592f7fb7182015939eb6bc7b309b91791cf065f", "best_bid": "0.003", "best_ask": "0.004"}], "timestamp": "1769384619110", "event_type": "price_change"}}
{"_local_timestamp": "2026-01-25T23:43:39.184898+00:00", "data": {"market": "0x67eb32405b2ad24182b8575eb560b3b087baa20340302a079bb8138637ed1b47", "price_changes": [{"asset_id": "91614728309695910310598383443496140750308657331105979804609645991161575447633", "price": "0.001", "size": "1104242.02", "side": "BUY", "hash": "4246c7401631c40587828bf05425a43f08f83cbb", "best_bid": "0.998", "best_ask": "0.999"}, {"asset_id": "23177234539005086745924487565572514732873310188830333623513053312024465699839", "price": "0.999", "size": "1104242.02", "side": "SELL", "hash": "3de5bc5eaf4bbba51dd74f16141877fc700cad2f", "best_bid": "0.001", "best_ask": "0.002"}], "timestamp": "1769384619111", "event_type": "price_change"}}
{"_local_timestamp": "2026-01-25T23:43:39.185334+00:00", "data": {"market": "0x469709d3554c9e9d26e8dea2516f8373669a9881ce505d57d75bff59fc58db75", "price_changes": [{"asset_id": "109460219863240579381274910433788899162940504407535154043224726152849933944106", "price": "0.12", "size": "0", "side": "BUY", "hash": "4b2d5104e0734ec88d74d57a8ab4d63b1cd343cd", "best_bid": "0.996", "best_ask": "0.999"}, {"asset_id": "71216154792191030083354473461386899246245242196096601702705023997087404907586", "price": "0.88", "size": "0", "side": "SELL", "hash": "87d37131d5307e1bc60f683fb23a38f3dd16798b", "best_bid": "0.001", "best_ask": "0.004"}], "timestamp": "1769384619110", "event_type": "price_change"}}
{"_local_timestamp": "2026-01-25T23:43:39.185777+00:00", "data": {"market": "0x7d06087c987916fcdd813c298ea61fe8154fbe186872cf416bad99c2abe1e28b", "price_changes": [{"asset_id": "67302540724762161307896112522088102200482553778240942791214901770569400222178", "price": "0.073", "size": "0", "side": "BUY", "hash": "d92a1ecd5e8588061e6ce311e5e31b1af40784a1", "best_bid": "0.996", "best_ask": "0.997"}, {"asset_id": "53184392184731073294596377638963528940590267478279064727563854235726442195657", "price": "0.927", "size": "0", "side": "SELL", "hash": "3592f7fb7182015939eb6bc7b309b91791cf065f", "best_bid": "0.003", "best_ask": "0.004"}], "timestamp": "1769384619110", "event_type": "price_change"}}
{"_local_timestamp": "2026-01-25T23:43:39.186214+00:00", "data": {"market": "0x67eb32405b2ad24182b8575eb560b3b087baa20340302a079bb8138637ed1b47", "price_changes": [{"asset_id": "91614728309695910310598383443496140750308657331105979804609645991161575447633", "price": "0.004", "size": "0", "side": "BUY", "hash": "4246c7401631c40587828bf05425a43f08f83cbb", "best_bid": "0.998", "best_ask": "0.999"}, {"asset_id": "23177234539005086745924487565572514732873310188830333623513053312024465699839", "price": "0.996", "size": "0", "side": "SELL", "hash": "3de5bc5eaf4bbba51dd74f16141877fc700cad2f", "best_bid": "0.001", "best_ask": "0.002"}], "timestamp": "1769384619111", "event_type": "price_change"}}
{"_local_timestamp": "2026-01-25T23:43:39.296463+00:00", "data": {"market": "0x7d06087c987916fcdd813c298ea61fe8154fbe186872cf416bad99c2abe1e28b", "price_changes": [{"asset_id": "67302540724762161307896112522088102200482553778240942791214901770569400222178", "price": "0.178", "size": "0", "side": "BUY", "hash": "d92a1ecd5e8588061e6ce311e5e31b1af40784a1", "best_bid": "0.996", "best_ask": "0.997"}, {"asset_id": "53184392184731073294596377638963528940590267478279064727563854235726442195657", "price": "0.822", "size": "0", "side": "SELL", "hash": "3592f7fb7182015939eb6bc7b309b91791cf065f", "best_bid": "0.003", "best_ask": "0.004"}], "timestamp": "1769384619110", "event_type": "price_change"}}
{"_local_timestamp": "2026-01-25T23:43:39.297084+00:00", "data": {"market": "0x67eb32405b2ad24182b8575eb560b3b087baa20340302a079bb8138637ed1b47", "price_changes": [{"asset_id": "91614728309695910310598383443496140750308657331105979804609645991161575447633", "price": "0.011", "size": "0", "side": "BUY", "hash": "4246c7401631c40587828bf05425a43f08f83cbb", "best_bid": "0.998", "best_ask": "0.999"}, {"asset_id": "23177234539005086745924487565572514732873310188830333623513053312024465699839", "price": "0.989", "size": "0", "side": "SELL", "hash": "3de5bc5eaf4bbba51dd74f16141877fc700cad2f", "best_bid": "0.001", "best_ask": "0.002"}], "timestamp": "1769384619111", "event_type": "price_change"}}
{"_local_timestamp": "2026-01-25T23:43:39.297613+00:00", "data": {"market": "0x67eb32405b2ad24182b8575eb560b3b087baa20340302a079bb8138637ed1b47", "price_changes": [{"asset_id": "91614728309695910310598383443496140750308657331105979804609645991161575447633", "price": "0.027", "size": "0", "side": "BUY", "hash": "4246c7401631c40587828bf05425a43f08f83cbb", "best_bid": "0.998", "best_ask": "0.999"}, {"asset_id": "23177234539005086745924487565572514732873310188830333623513053312024465699839", "price": "0.973", "size": "0", "side": "SELL", "hash": "3de5bc5eaf4bbba51dd74f16141877fc700cad2f", "best_bid": "0.001", "best_ask": "0.002"}], "timestamp": "1769384619111", "event_type": "price_change"}}
{"_local_timestamp": "2026-01-25T23:43:39.298079+00:00", "data": {"market": "0x67eb32405b2ad24182b8575eb560b3b087baa20340302a079bb8138637ed1b47", "price_changes": [{"asset_id": "91614728309695910310598383443496140750308657331105979804609645991161575447633", "price": "0.057", "size": "0", "side": "BUY", "hash": "4246c7401631c40587828bf05425a43f08f83cbb", "best_bid": "0.998", "best_ask": "0.999"}, {"asset_id": "23177234539005086745924487565572514732873310188830333623513053312024465699839", "price": "0.943", "size": "0", "side": "SELL", "hash": "3de5bc5eaf4bbba51dd74f16141877fc700cad2f", "best_bid": "0.001", "best_ask": "0.002"}], "timestamp": "1769384619111", "event_type": "price_change"}}
{"_local_timestamp": "2026-01-25T23:43:39.303248+00:00", "data": {"market": "0x67eb32405b2ad24182b8575eb560b3b087baa20340302a079bb8138637ed1b47", "price_changes": [{"asset_id": "91614728309695910310598383443496140750308657331105979804609645991161575447633", "price": "0.136", "size": "0", "side": "BUY", "hash": "4246c7401631c40587828bf05425a43f08f83cbb", "best_bid": "0.998", "best_ask": "0.999"}, {"asset_id": "23177234539005086745924487565572514732873310188830333623513053312024465699839", "price": "0.864", "size": "0", "side": "SELL", "hash": "3de5bc5eaf4bbba51dd74f16141877fc700cad2f", "best_bid": "0.001", "best_ask": "0.002"}], "timestamp": "1769384619111", "event_type": "price_change"}}
{"_local_timestamp": "2026-01-25T23:43:39.488009+00:00", "data": {"market": "0x768a10a2ba796df7c565166c61f1b708a7674565add5559f03bd1297d4997ac7", "price_changes": [{"asset_id": "52154086410665277054252505344124616126874295244982327401005145100880544734445", "price": "0.031", "size": "6.38", "side": "BUY", "hash": "01b0f6bb93120ba3a067a955dcc6214aa456ec02", "best_bid": "0.995", "best_ask": "0.997"}, {"asset_id": "102376165613363136742721000249129649340591318769760895202636036152231642180566", "price": "0.969", "size": "6.38", "side": "SELL", "hash": "085c209e096d352034b1b5fa7afb30088fb951e3", "best_bid": "0.003", "best_ask": "0.005"}], "timestamp": "1769384619423", "event_type": "price_change"}}
{"_local_timestamp": "2026-01-25T23:43:39.490176+00:00", "data": {"market": "0x768a10a2ba796df7c565166c61f1b708a7674565add5559f03bd1297d4997ac7", "price_changes": [{"asset_id": "52154086410665277054252505344124616126874295244982327401005145100880544734445", "price": "0.186", "size": "6.69", "side": "BUY", "hash": "f09e8dbeb47b9dc0a68c0cf20bfa761713cb9a21", "best_bid": "0.995", "best_ask": "0.997"}, {"asset_id": "102376165613363136742721000249129649340591318769760895202636036152231642180566", "price": "0.814", "size": "6.69", "side": "SELL", "hash": "d4e974b0d4901ac1417d8e193a47a52b843eabe2", "best_bid": "0.003", "best_ask": "0.005"}], "timestamp": "1769384619424", "event_type": "price_change"}}
{"_local_timestamp": "2026-01-25T23:43:39.490693+00:00", "data": {"market": "0x768a10a2ba796df7c565166c61f1b708a7674565add5559f03bd1297d4997ac7", "price_changes": [{"asset_id": "52154086410665277054252505344124616126874295244982327401005145100880544734445", "price": "0.005", "size": "6.03", "side": "BUY", "hash": "14e3954ca14e9e3b0ed85aef042efe355c6cfb7f", "best_bid": "0.995", "best_ask": "0.997"}, {"asset_id": "102376165613363136742721000249129649340591318769760895202636036152231642180566", "price": "0.995", "size": "6.03", "side": "SELL", "hash": "289d8187920abe02f57f07e4e5cc8b8af101c790", "best_bid": "0.003", "best_ask": "0.005"}], "timestamp": "1769384619425", "event_type": "price_change"}}
{"_local_timestamp": "2026-01-25T23:43:39.491197+00:00", "data": {"market": "0x768a10a2ba796df7c565166c61f1b708a7674565add5559f03bd1297d4997ac7", "price_changes": [{"asset_id": "52154086410665277054252505344124616126874295244982327401005145100880544734445", "price": "0.002", "size": "257.61", "side": "BUY", "hash": "abc76e511208735e97bdf944d74e4ea9b392f991", "best_bid": "0.995", "best_ask": "0.997"}, {"asset_id": "102376165613363136742721000249129649340591318769760895202636036152231642180566", "price": "0.998", "size": "257.61", "side": "SELL", "hash": "8c994f54b6ef9e64d4070ad5ac556b1683af7254", "best_bid": "0.003", "best_ask": "0.005"}], "timestamp": "1769384619426", "event_type": "price_change"}}
{"_local_timestamp": "2026-01-25T23:43:39.491710+00:00", "data": {"market": "0x768a10a2ba796df7c565166c61f1b708a7674565add5559f03bd1297d4997ac7", "price_changes": [{"asset_id": "52154086410665277054252505344124616126874295244982327401005145100880544734445", "price": "0.074", "size": "5.97", "side": "BUY", "hash": "f198822dcf1f769a031498d49392a4ee807076e5", "best_bid": "0.995", "best_ask": "0.997"}, {"asset_id": "102376165613363136742721000249129649340591318769760895202636036152231642180566", "price": "0.926", "size": "5.97", "side": "SELL", "hash": "84b4f98a59b780e13c3316cbeb2d5ffff0cb5241", "best_bid": "0.003", "best_ask": "0.005"}], "timestamp": "1769384619427", "event_type": "price_change"}}
{"_local_timestamp": "2026-01-25T23:43:39.918755+00:00", "data": {"market": "0x53030dd48b4acd0572c611a81fade4d1214d45cfa9725434f625ff9443bbf58e", "price_changes": [{"asset_id": "28013675818699191456107309488671219297858376503082476267618031773906710101322", "price": "0.208", "size": "0", "side": "BUY", "hash": "4bcc877801298cf9027f4a98b796423389d8f059", "best_bid": "0.998", "best_ask": "0.999"}, {"asset_id": "93601737054928362372096738986263364737270540163712701982280468693583918706009", "price": "0.792", "size": "0", "side": "SELL", "hash": "9f599a9bc6005bcd0cd0251c4f39af6c002c6472", "best_bid": "0.001", "best_ask": "0.002"}], "timestamp": "1769384619843", "event_type": "price_change"}}
{"_local_timestamp": "2026-01-25T23:43:39.919460+00:00", "data": {"market": "0x7e2664fd56bdb98dfe10fc702d40c7bb34bbd173b4e1a4ace956e8bee3a15ed3", "price_changes": [{"asset_id": "32585257541944296536919042049344155455892911573822808260948030619026984605016", "price": "0.003", "size": "20400", "side": "BUY", "hash": "eecfe89a70b5d31c18e9e4beecac25d6f26c203f", "best_bid": "0.998", "best_ask": "0.999"}, {"asset_id": "8013350309980067752092467553989532032941595361116376915087772932251249070671", "price": "0.997", "size": "20400", "side": "SELL", "hash": "4c21688c5fad5293b162e5b4c8974dd56bddef12", "best_bid": "0.001", "best_ask": "0.002"}], "timestamp": "1769384619843", "event_type": "price_change"}}
{"_local_timestamp": "2026-01-25T23:43:39.920040+00:00", "data": {"market": "0x7e2664fd56bdb98dfe10fc702d40c7bb34bbd173b4e1a4ace956e8bee3a15ed3", "price_changes": [{"asset_id": "32585257541944296536919042049344155455892911573822808260948030619026984605016", "price": "0.007", "size": "0", "side": "BUY", "hash": "eecfe89a70b5d31c18e9e4beecac25d6f26c203f", "best_bid": "0.998", "best_ask": "0.999"}, {"asset_id": "8013350309980067752092467553989532032941595361116376915087772932251249070671", "price": "0.993", "size": "0", "side": "SELL", "hash": "4c21688c5fad5293b162e5b4c8974dd56bddef12", "best_bid": "0.001", "best_ask": "0.002"}], "timestamp": "1769384619843", "event_type": "price_change"}}
{"_local_timestamp": "2026-01-25T23:43:39.920593+00:00", "data": {"market": "0x7e2664fd56bdb98dfe10fc702d40c7bb34bbd173b4e1a4ace956e8bee3a15ed3", "price_changes": [{"asset_id": "32585257541944296536919042049344155455892911573822808260948030619026984605016", "price": "0.022", "size": "0", "side": "BUY", "hash": "eecfe89a70b5d31c18e9e4beecac25d6f26c203f", "best_bid": "0.998", "best_ask": "0.999"}, {"asset_id": "8013350309980067752092467553989532032941595361116376915087772932251249070671", "price": "0.978", "size": "0", "side": "SELL", "hash": "4c21688c5fad5293b162e5b4c8974dd56bddef12", "best_bid": "0.001", "best_ask": "0.002"}], "timestamp": "1769384619843", "event_type": "price_change"}}
{"_local_timestamp": "2026-01-25T23:43:39.921115+00:00", "data": {"market": "0x7e2664fd56bdb98dfe10fc702d40c7bb34bbd173b4e1a4ace956e8bee3a15ed3", "price_changes": [{"asset_id": "32585257541944296536919042049344155455892911573822808260948030619026984605016", "price": "0.053", "size": "0", "side": "BUY", "hash": "eecfe89a70b5d31c18e9e4beecac25d6f26c203f", "best_bid": "0.998", "best_ask": "0.999"}, {"asset_id": "8013350309980067752092467553989532032941595361116376915087772932251249070671", "price": "0.947", "size": "0", "side": "SELL", "hash": "4c21688c5fad5293b162e5b4c8974dd56bddef12", "best_bid": "0.001", "best_ask": "0.002"}], "timestamp": "1769384619843", "event_type": "price_change"}}
{"_local_timestamp": "2026-01-25T23:43:39.921651+00:00", "data": {"market": "0x7e2664fd56bdb98dfe10fc702d40c7bb34bbd173b4e1a4ace956e8bee3a15ed3", "price_changes": [{"asset_id": "32585257541944296536919042049344155455892911573822808260948030619026984605016", "price": "0.145", "size": "0", "side": "BUY", "hash": "eecfe89a70b5d31c18e9e4beecac25d6f26c203f", "best_bid": "0.998", "best_ask": "0.999"}, {"asset_id": "8013350309980067752092467553989532032941595361116376915087772932251249070671", "price": "0.855", "size": "0", "side": "SELL", "hash": "4c21688c5fad5293b162e5b4c8974dd56bddef12", "best_bid": "0.001", "best_ask": "0.002"}], "timestamp": "1769384619843", "event_type": "price_change"}}
{"_local_timestamp": "2026-01-25T23:43:40.802951+00:00", "data": {"market": "0x67eb32405b2ad24182b8575eb560b3b087baa20340302a079bb8138637ed1b47", "price_changes": [{"asset_id": "91614728309695910310598383443496140750308657331105979804609645991161575447633", "price": "0.007", "size": "10.48", "side": "BUY", "hash": "57a227c12b430008414d43f11a27c5f71af6ee88", "best_bid": "0.998", "best_ask": "0.999"}, {"asset_id": "23177234539005086745924487565572514732873310188830333623513053312024465699839", "price": "0.993", "size": "10.48", "side": "SELL", "hash": "e4dc677224ea754231e87c53a1914c75b8f91d75", "best_bid": "0.001", "best_ask": "0.002"}], "timestamp": "1769384620729", "event_type": "price_change"}}
{"_local_timestamp": "2026-01-25T23:43:40.803605+00:00", "data": {"market": "0x7d06087c987916fcdd813c298ea61fe8154fbe186872cf416bad99c2abe1e28b", "price_changes": [{"asset_id": "67302540724762161307896112522088102200482553778240942791214901770569400222178", "price": "0.075", "size": "5.5", "side": "BUY", "hash": "90d5da3253ea4aa4c6a78d03287953c0acd42692", "best_bid": "0.996", "best_ask": "0.997"}, {"asset_id": "53184392184731073294596377638963528940590267478279064727563854235726442195657", "price": "0.925", "size": "5.5", "side": "SELL", "hash": "5b0b746a12e83a5f80e8388f0e2af555bc73ab32", "best_bid": "0.003", "best_ask": "0.004"}], "timestamp": "1769384620729", "event_type": "price_change"}}
{"_local_timestamp": "2026-01-25T23:43:40.804195+00:00", "data": {"market": "0x469709d3554c9e9d26e8dea2516f8373669a9881ce505d57d75bff59fc58db75", "price_changes": [{"asset_id": "109460219863240579381274910433788899162940504407535154043224726152849933944106", "price": "0.026", "size": "5.21", "side": "BUY", "hash": "e80e054190070fc9f274704611840c9153d37099", "best_bid": "0.996", "best_ask": "0.999"}, {"asset_id": "71216154792191030083354473461386899246245242196096601702705023997087404907586", "price": "0.974", "size": "5.21", "side": "SELL", "hash": "2b8ff0c27fbef06b8d0ef77755ac1d36eac855e3", "best_bid": "0.001", "best_ask": "0.004"}], "timestamp": "1769384620729", "event_type": "price_change"}}
{"_local_timestamp": "2026-01-25T23:43:40.804739+00:00", "data": {"market": "0x6a72f5b1d7edf1261156080ddc026da3d80a78834c12925a7bfea4a8aa5b8fb8", "price_changes": [{"asset_id": "18638298170773700688520436893150989158645425879508160426041188051588302722446", "price": "0.073", "size": "5.12", "side": "BUY", "hash": "1ebe28bfcdea79ea8e13c0c1104a9962dae7c845", "best_bid": "0.997", "best_ask": "0.999"}, {"asset_id": "56323539615651816818267229259150871177627322204823867354832755297469690554470", "price": "0.927", "size": "5.12", "side": "SELL", "hash": "8555bec3922479eb30e8aba62f885b1703ed37e3", "best_bid": "0.001", "best_ask": "0.003"}], "timestamp": "1769384620729", "event_type": "price_change"}}
{"_local_timestamp": "2026-01-25T23:43:40.805268+00:00", "data": {"market": "0x6f3819aefa464a63c3a54d9e079ad59ba194b015de3f4dae4f16d822eeb5dd2e", "price_changes": [{"asset_id": "82873337478696874311026595893708524418275224909062608016173074343863041369337", "price": "0.011", "size": "39.5", "side": "BUY", "hash": "6e82c35791a8ee5cd605273e66e6410fcd61a808", "best_bid": "0.998", "best_ask": "0.999"}, {"asset_id": "88141572307574703189103808906541737578361491725632656938888428716809889579606", "price": "0.989", "size": "39.5", "side": "SELL", "hash": "859bb88d155e951397e58bfae79d42070b28bb41", "best_bid": "0.001", "best_ask": "0.002"}], "timestamp": "1769384620729", "event_type": "price_change"}}
{"_local_timestamp": "2026-01-25T23:43:40.805814+00:00", "data": {"market": "0x6a72f5b1d7edf1261156080ddc026da3d80a78834c12925a7bfea4a8aa5b8fb8", "price_changes": [{"asset_id": "18638298170773700688520436893150989158645425879508160426041188051588302722446", "price": "0.167", "size": "7.77", "side": "BUY", "hash": "6784e2174a0bdde0e3fefa01ea70578f278bf8fb", "best_bid": "0.997", "best_ask": "0.999"}, {"asset_id": "56323539615651816818267229259150871177627322204823867354832755297469690554470", "price": "0.833", "size": "7.77", "side": "SELL", "hash": "3c6e586a53f80853e016580078658a2b00c564f4", "best_bid": "0.001", "best_ask": "0.003"}], "timestamp": "1769384620731", "event_type": "price_change"}}
{"_local_timestamp": "2026-01-25T23:43:40.806339+00:00", "data": {"market": "0x469709d3554c9e9d26e8dea2516f8373669a9881ce505d57d75bff59fc58db75", "price_changes": [{"asset_id": "109460219863240579381274910433788899162940504407535154043224726152849933944106", "price": "0.122", "size": "12.02", "side": "BUY", "hash": "492014cab4812070b0b74a5bbcb3e4618e616c85", "best_bid": "0.996", "best_ask": "0.999"}, {"asset_id": "71216154792191030083354473461386899246245242196096601702705023997087404907586", "price": "0.878", "size": "12.02", "side": "SELL", "hash": "e6fe6c4a8a1d266617e4fbefca58b8f001a9ce73", "best_bid": "0.001", "best_ask": "0.004"}], "timestamp": "1769384620730", "event_type": "price_change"}}
{"_local_timestamp": "2026-01-25T23:43:40.806885+00:00", "data": {"market": "0x7d06087c987916fcdd813c298ea61fe8154fbe186872cf416bad99c2abe1e28b", "price_changes": [{"asset_id": "67302540724762161307896112522088102200482553778240942791214901770569400222178", "price": "0.18", "size": "6.98", "side": "BUY", "hash": "96e0a3dd6b104d5961ee0e8b992e6d7d808a1d71", "best_bid": "0.996", "best_ask": "0.997"}, {"asset_id": "53184392184731073294596377638963528940590267478279064727563854235726442195657", "price": "0.82", "size": "6.98", "side": "SELL", "hash": "5cc905e04b9437c9052498312d37fc117d965079", "best_bid": "0.003", "best_ask": "0.004"}], "timestamp": "1769384620731", "event_type": "price_change"}}
{"_local_timestamp": "2026-01-25T23:43:40.814492+00:00", "data": {"market": "0x67eb32405b2ad24182b8575eb560b3b087baa20340302a079bb8138637ed1b47", "price_changes": [{"asset_id": "91614728309695910310598383443496140750308657331105979804609645991161575447633", "price": "0.059", "size": "5.54", "side": "BUY", "hash": "0ec2d5c63e7fb0d6575363df8e3471d9e588df29", "best_bid": "0.998", "best_ask": "0.999"}, {"asset_id": "23177234539005086745924487565572514732873310188830333623513053312024465699839", "price": "0.941", "size": "5.54", "side": "SELL", "hash": "ab9f13548debca02e7940a788ad38621ce46120a", "best_bid": "0.001", "best_ask": "0.002"}], "timestamp": "1769384620731", "event_type": "price_change"}}
{"_local_timestamp": "2026-01-25T23:43:40.815083+00:00", "data": {"market": "0x469709d3554c9e9d26e8dea2516f8373669a9881ce505d57d75bff59fc58db75", "price_changes": [{"asset_id": "109460219863240579381274910433788899162940504407535154043224726152849933944106", "price": "0.055", "size": "723.35", "side": "BUY", "hash": "549e2f94203d81c7ea8265079862649ebae86df6", "best_bid": "0.996", "best_ask": "0.999"}, {"asset_id": "71216154792191030083354473461386899246245242196096601702705023997087404907586", "price": "0.945", "size": "723.35", "side": "SELL", "hash": "be0479c1db940f9e9de3a64fec2d4d5c4371fc79", "best_bid": "0.001", "best_ask": "0.004"}], "timestamp": "1769384620732", "event_type": "price_change"}}
{"_local_timestamp": "2026-01-25T23:43:40.947455+00:00", "data": {"market": "0x6a72f5b1d7edf1261156080ddc026da3d80a78834c12925a7bfea4a8aa5b8fb8", "price_changes": [{"asset_id": "18638298170773700688520436893150989158645425879508160426041188051588302722446", "price": "0.027", "size": "7.78", "side": "BUY", "hash": "f10de7b6439f9111dea07ed2520ae1a9f7f15ea9", "best_bid": "0.997", "best_ask": "0.999"}, {"asset_id": "56323539615651816818267229259150871177627322204823867354832755297469690554470", "price": "0.973", "size": "7.78", "side": "SELL", "hash": "0ddea7b45be605f9c5d690ab20ac48018927a505", "best_bid": "0.001", "best_ask": "0.003"}], "timestamp": "1769384620732", "event_type": "price_change"}}
{"_local_timestamp": "2026-01-25T23:43:40.948121+00:00", "data": {"market": "0x7d06087c987916fcdd813c298ea61fe8154fbe186872cf416bad99c2abe1e28b", "price_changes": [{"asset_id": "67302540724762161307896112522088102200482553778240942791214901770569400222178", "price": "0.035", "size": "5.18", "side": "BUY", "hash": "b85b59942209e6190a7674108670d4aebb58581f", "best_bid": "0.996", "best_ask": "0.997"}, {"asset_id": "53184392184731073294596377638963528940590267478279064727563854235726442195657", "price": "0.965", "size": "5.18", "side": "SELL", "hash": "0e612c3e25a9fbd86247b1e77f5f7fade2714aab", "best_bid": "0.003", "best_ask": "0.004"}], "timestamp": "1769384620732", "event_type": "price_change"}}
{"_local_timestamp": "2026-01-25T23:43:40.948675+00:00", "data": {"market": "0x67eb32405b2ad24182b8575eb560b3b087baa20340302a079bb8138637ed1b47", "price_changes": [{"asset_id": "91614728309695910310598383443496140750308657331105979804609645991161575447633", "price": "0.138", "size": "10.16", "side": "BUY", "hash": "957a7aa1e385437d848e20780def5eb54dfe51ce", "best_bid": "0.998", "best_ask": "0.999"}, {"asset_id": "23177234539005086745924487565572514732873310188830333623513053312024465699839", "price": "0.862", "size": "10.16", "side": "SELL", "hash": "3b0189cf604ebcfc5d306ea8f0f2fa25497c20d8", "best_bid": "0.001", "best_ask": "0.002"}], "timestamp": "1769384620732", "event_type": "price_change"}}
{"_local_timestamp": "2026-01-25T23:43:40.949199+00:00", "data": {"market": "0x67eb32405b2ad24182b8575eb560b3b087baa20340302a079bb8138637ed1b47", "price_changes": [{"asset_id": "91614728309695910310598383443496140750308657331105979804609645991161575447633", "price": "0.003", "size": "30406.64", "side": "BUY", "hash": "678439b4d098069ceacc14256991490874be240d", "best_bid": "0.998", "best_ask": "0.999"}, {"asset_id": "23177234539005086745924487565572514732873310188830333623513053312024465699839", "price": "0.997", "size": "30406.64", "side": "SELL", "hash": "1a98413cedd57fbec685c42e058b3a3d34d80357", "best_bid": "0.001", "best_ask": "0.002"}], "timestamp": "1769384620733", "event_type": "price_change"}}
{"_local_timestamp": "2026-01-25T23:43:40.949756+00:00", "data": {"market": "0x67eb32405b2ad24182b8575eb560b3b087baa20340302a079bb8138637ed1b47", "price_changes": [{"asset_id": "91614728309695910310598383443496140750308657331105979804609645991161575447633", "price": "0.022", "size": "7.81", "side": "BUY", "hash": "709a6773aa86910293f5cba3edca8e1cd76c3b1c", "best_bid": "0.998", "best_ask": "0.999"}, {"asset_id": "23177234539005086745924487565572514732873310188830333623513053312024465699839", "price": "0.978", "size": "7.81", "side": "SELL", "hash": "fbbde5e61086400a78fba69bc1c5c94c238ceead", "best_bid": "0.001", "best_ask": "0.002"}], "timestamp": "1769384620735", "event_type": "price_change"}}
{"_local_timestamp": "2026-01-25T23:43:42.157967+00:00", "data": {"market": "0x7e2664fd56bdb98dfe10fc702d40c7bb34bbd173b4e1a4ace956e8bee3a15ed3", "price_changes": [{"asset_id": "32585257541944296536919042049344155455892911573822808260948030619026984605016", "price": "0.024", "size": "5.99", "side": "BUY", "hash": "d19cba4a63ec2fd3d4a63b4a9b30733e3fec44b0", "best_bid": "0.998", "best_ask": "0.999"}, {"asset_id": "8013350309980067752092467553989532032941595361116376915087772932251249070671", "price": "0.976", "size": "5.99", "side": "SELL", "hash": "1172ea4c629a4ae3d6ea87b5cfa56c3bca3531d4", "best_bid": "0.001", "best_ask": "0.002"}], "timestamp": "1769384622071", "event_type": "price_change"}}
{"_local_timestamp": "2026-01-25T23:43:42.159305+00:00", "data": {"market": "0x53030dd48b4acd0572c611a81fade4d1214d45cfa9725434f625ff9443bbf58e", "price_changes": [{"asset_id": "28013675818699191456107309488671219297858376503082476267618031773906710101322", "price": "0.21", "size": "5.5", "side": "BUY", "hash": "72def006a5707624b8fafd904aacbb1be49a95a9", "best_bid": "0.998", "best_ask": "0.999"}, {"asset_id": "93601737054928362372096738986263364737270540163712701982280468693583918706009", "price": "0.79", "size": "5.5", "side": "SELL", "hash": "08a9f5cc8702422805612313fa592d38aef4034a", "best_bid": "0.001", "best_ask": "0.002"}], "timestamp": "1769384622071", "event_type": "price_change"}}
{"_local_timestamp": "2026-01-25T23:43:42.159952+00:00", "data": {"market": "0x7e2664fd56bdb98dfe10fc702d40c7bb34bbd173b4e1a4ace956e8bee3a15ed3", "price_changes": [{"asset_id": "32585257541944296536919042049344155455892911573822808260948030619026984605016", "price": "0.055", "size": "6.87", "side": "BUY", "hash": "a5225b38f72bd2463703a1449f4bacc03aecdc7c", "best_bid": "0.998", "best_ask": "0.999"}, {"asset_id": "8013350309980067752092467553989532032941595361116376915087772932251249070671", "price": "0.945", "size": "6.87", "side": "SELL", "hash": "e0ee8b5047275e47266130d5128fcf53a56394ca", "best_bid": "0.001", "best_ask": "0.002"}], "timestamp": "1769384622076", "event_type": "price_change"}}
{"_local_timestamp": "2026-01-25T23:43:42.160553+00:00", "data": {"market": "0x7e2664fd56bdb98dfe10fc702d40c7bb34bbd173b4e1a4ace956e8bee3a15ed3", "price_changes": [{"asset_id": "32585257541944296536919042049344155455892911573822808260948030619026984605016", "price": "0.001", "size": "1104251.99", "side": "BUY", "hash": "37507d0319bea21521223d98dbf12e2a1b129259", "best_bid": "0.998", "best_ask": "0.999"}, {"asset_id": "8013350309980067752092467553989532032941595361116376915087772932251249070671", "price": "0.999", "size": "1104251.99", "side": "SELL", "hash": "893dd1e40d0d8319b1071bbefc442338eca8f36b", "best_bid": "0.001", "best_ask": "0.002"}], "timestamp": "1769384622082", "event_type": "price_change"}}
{"_local_timestamp": "2026-01-25T23:43:42.163847+00:00", "data": {"market": "0x7e2664fd56bdb98dfe10fc702d40c7bb34bbd173b4e1a4ace956e8bee3a15ed3", "price_changes": [{"asset_id": "32585257541944296536919042049344155455892911573822808260948030619026984605016", "price": "0.147", "size": "9.28", "side": "BUY", "hash": "0fabd4a2602f4a8b22f8e4ce15b1eca4965ebd98", "best_bid": "0.998", "best_ask": "0.999"}, {"asset_id": "8013350309980067752092467553989532032941595361116376915087772932251249070671", "price": "0.853", "size": "9.28", "side": "SELL", "hash": "66bfca398e3e538c930bad7b01a075c4505a6038", "best_bid": "0.001", "best_ask": "0.002"}], "timestamp": "1769384622090", "event_type": "price_change"}}
{"_local_timestamp": "2026-01-25T23:43:42.164553+00:00", "data": {"market": "0x7e2664fd56bdb98dfe10fc702d40c7bb34bbd173b4e1a4ace956e8bee3a15ed3", "price_changes": [{"asset_id": "32585257541944296536919042049344155455892911573822808260948030619026984605016", "price": "0.011", "size": "5.73", "side": "BUY", "hash": "975e92c4eb0819d634e783d8f3c34220205cb9d5", "best_bid": "0.998", "best_ask": "0.999"}, {"asset_id": "8013350309980067752092467553989532032941595361116376915087772932251249070671", "price": "0.989", "size": "5.73", "side": "SELL", "hash": "cd5812d86f986b3b3c71fbbb564ec65d127724fc", "best_bid": "0.001", "best_ask": "0.002"}], "timestamp": "1769384622094", "event_type": "price_change"}}
{"_local_timestamp": "2026-01-25T23:43:42.169157+00:00", "data": {"market": "0x7e2664fd56bdb98dfe10fc702d40c7bb34bbd173b4e1a4ace956e8bee3a15ed3", "price_changes": [{"asset_id": "32585257541944296536919042049344155455892911573822808260948030619026984605016", "price": "0.004", "size": "8.65", "side": "BUY", "hash": "52ae07ce12fddeda98d3d68c26dab38b8224835f", "best_bid": "0.998", "best_ask": "0.999"}, {"asset_id": "8013350309980067752092467553989532032941595361116376915087772932251249070671", "price": "0.996", "size": "8.65", "side": "SELL", "hash": "47118da78f90afcc37bc0cb54c58f7693e5192b0", "best_bid": "0.001", "best_ask": "0.002"}], "timestamp": "1769384622098", "event_type": "price_change"}}
{"_local_timestamp": "2026-01-25T23:43:53.951668+00:00", "data": {"market": "0x720db82e6ae3132de241c4190b7f72585d5fc2f1364519e814d51f3ec29bf8c6", "price_changes": [{"asset_id": "7359117152396849276912471939244269631176254624751482772547064208568026511810", "price": "0.16", "size": "0", "side": "BUY", "hash": "7d73654e276344f2857632c65631fe87e85a9607", "best_bid": "0.998", "best_ask": "0.999"}, {"asset_id": "38966153695292251303244152044268630330033580269266738868503907046849339108583", "price": "0.84", "size": "0", "side": "SELL", "hash": "66dcbfa7ae2b26aaf917eb10e3fd354d805b5383", "best_bid": "0.001", "best_ask": "0.002"}], "timestamp": "1769384633717", "event_type": "price_change"}}
{"_local_timestamp": "2026-01-25T23:43:54.135780+00:00", "data": {"market": "0x720db82e6ae3132de241c4190b7f72585d5fc2f1364519e814d51f3ec29bf8c6", "price_changes": [{"asset_id": "7359117152396849276912471939244269631176254624751482772547064208568026511810", "price": "0.034", "size": "0", "side": "BUY", "hash": "a8b3dbb33ed545108685c167bb35d22c8421c9d5", "best_bid": "0.998", "best_ask": "0.999"}, {"asset_id": "38966153695292251303244152044268630330033580269266738868503907046849339108583", "price": "0.966", "size": "0", "side": "SELL", "hash": "11f50a0c6f367fd6a89449fdd4ccd14326747ea3", "best_bid": "0.001", "best_ask": "0.002"}], "timestamp": "1769384633906", "event_type": "price_change"}}
{"_local_timestamp": "2026-01-25T23:43:54.364845+00:00", "data": {"market": "0x720db82e6ae3132de241c4190b7f72585d5fc2f1364519e814d51f3ec29bf8c6", "price_changes": [{"asset_id": "7359117152396849276912471939244269631176254624751482772547064208568026511810", "price": "0.034", "size": "282.35", "side": "BUY", "hash": "03ddc82588a8a31a3a04af65199be542ae6ef172", "best_bid": "0.998", "best_ask": "0.999"}, {"asset_id": "38966153695292251303244152044268630330033580269266738868503907046849339108583", "price": "0.966", "size": "282.35", "side": "SELL", "hash": "ef07f19bc026266d2895b9d2f9ea8ba646e22721", "best_bid": "0.001", "best_ask": "0.002"}], "timestamp": "1769384634128", "event_type": "price_change"}}
{"_local_timestamp": "2026-01-25T23:43:54.560618+00:00", "data": {"market": "0x720db82e6ae3132de241c4190b7f72585d5fc2f1364519e814d51f3ec29bf8c6", "price_changes": [{"asset_id": "7359117152396849276912471939244269631176254624751482772547064208568026511810", "price": "0.072", "size": "300", "side": "BUY", "hash": "fd67ef8abdb16ae765c659ecd6aaef845551e848", "best_bid": "0.998", "best_ask": "0.999"}, {"asset_id": "38966153695292251303244152044268630330033580269266738868503907046849339108583", "price": "0.928", "size": "300", "side": "SELL", "hash": "d2e6015e6db3e12575428bfbf800347e770c6fa6", "best_bid": "0.001", "best_ask": "0.002"}], "timestamp": "1769384634330", "event_type": "price_change"}}
{"_local_timestamp": "2026-01-25T23:43:54.804101+00:00", "data": {"market": "0x720db82e6ae3132de241c4190b7f72585d5fc2f1364519e814d51f3ec29bf8c6", "price_changes": [{"asset_id": "7359117152396849276912471939244269631176254624751482772547064208568026511810", "price": "0.072", "size": "433.33", "side": "BUY", "hash": "98354c3142d36580a3a7a9e07372763889185143", "best_bid": "0.998", "best_ask": "0.999"}, {"asset_id": "38966153695292251303244152044268630330033580269266738868503907046849339108583", "price": "0.928", "size": "433.33", "side": "SELL", "hash": "b336abc03c28ca37b22bd80cc9e2a55f4e3ef6bf", "best_bid": "0.001", "best_ask": "0.002"}], "timestamp": "1769384634579", "event_type": "price_change"}}
{"_local_timestamp": "2026-01-25T23:43:54.997936+00:00", "data": {"market": "0x720db82e6ae3132de241c4190b7f72585d5fc2f1364519e814d51f3ec29bf8c6", "price_changes": [{"asset_id": "7359117152396849276912471939244269631176254624751482772547064208568026511810", "price": "0.081", "size": "118.51", "side": "BUY", "hash": "96030e7f6c0b54de8bb737580c0c95916496e988", "best_bid": "0.998", "best_ask": "0.999"}, {"asset_id": "38966153695292251303244152044268630330033580269266738868503907046849339108583", "price": "0.919", "size": "118.51", "side": "SELL", "hash": "95db087fff69f09486a005457ce57aff646380f1", "best_bid": "0.001", "best_ask": "0.002"}], "timestamp": "1769384634788", "event_type": "price_change"}}
{"_local_timestamp": "2026-01-25T23:43:55.222444+00:00", "data": {"market": "0x720db82e6ae3132de241c4190b7f72585d5fc2f1364519e814d51f3ec29bf8c6", "price_changes": [{"asset_id": "7359117152396849276912471939244269631176254624751482772547064208568026511810", "price": "0.162", "size": "59.25", "side": "BUY", "hash": "c46127c6740998310f42cd39b690ace6191675be", "best_bid": "0.998", "best_ask": "0.999"}, {"asset_id": "38966153695292251303244152044268630330033580269266738868503907046849339108583", "price": "0.838", "size": "59.25", "side": "SELL", "hash": "1209be1eb7440660ed55e410bbbf6c38d30377b7", "best_bid": "0.001", "best_ask": "0.002"}], "timestamp": "1769384634995", "event_type": "price_change"}}
{"_local_timestamp": "2026-01-25T23:43:55.401325+00:00", "data": {"market": "0x720db82e6ae3132de241c4190b7f72585d5fc2f1364519e814d51f3ec29bf8c6", "price_changes": [{"asset_id": "7359117152396849276912471939244269631176254624751482772547064208568026511810", "price": "0.32", "size": "0", "side": "BUY", "hash": "291ff6eb927a63301b31f9f5b4bf538bf35c3a15", "best_bid": "0.998", "best_ask": "0.999"}, {"asset_id": "38966153695292251303244152044268630330033580269266738868503907046849339108583", "price": "0.68", "size": "0", "side": "SELL", "hash": "9bb4cc492cd88a586407a469c1f765779a7930f8", "best_bid": "0.001", "best_ask": "0.002"}], "timestamp": "1769384635177", "event_type": "price_change"}}
{"_local_timestamp": "2026-01-25T23:43:55.537119+00:00", "data": {"market": "0x720db82e6ae3132de241c4190b7f72585d5fc2f1364519e814d51f3ec29bf8c6", "price_changes": [{"asset_id": "7359117152396849276912471939244269631176254624751482772547064208568026511810", "price": "0.161", "size": "0", "side": "BUY", "hash": "ef156ba44ff4950e5dae1a96aaae4633cdbd767e", "best_bid": "0.998", "best_ask": "0.999"}, {"asset_id": "38966153695292251303244152044268630330033580269266738868503907046849339108583", "price": "0.839", "size": "0", "side": "SELL", "hash": "dfc8bb512851354027c5167471ae4e3e89ea08a2", "best_bid": "0.001", "best_ask": "0.002"}], "timestamp": "1769384635318", "event_type": "price_change"}}
{"_local_timestamp": "2026-01-25T23:43:55.612072+00:00", "data": {"market": "0x720db82e6ae3132de241c4190b7f72585d5fc2f1364519e814d51f3ec29bf8c6", "price_changes": [{"asset_id": "7359117152396849276912471939244269631176254624751482772547064208568026511810", "price": "0.32", "size": "30", "side": "BUY", "hash": "3d4fd2ca9cb43b3d2713dab8fea7776fdfc29e26", "best_bid": "0.998", "best_ask": "0.999"}, {"asset_id": "38966153695292251303244152044268630330033580269266738868503907046849339108583", "price": "0.68", "size": "30", "side": "SELL", "hash": "d7ec38340ac490fab45feea66ebbbd7ae029f033", "best_bid": "0.001", "best_ask": "0.002"}], "timestamp": "1769384635396", "event_type": "price_change"}}
{"_local_timestamp": "2026-01-25T23:43:57.162928+00:00", "data": {"market": "0x720db82e6ae3132de241c4190b7f72585d5fc2f1364519e814d51f3ec29bf8c6", "price_changes": [{"asset_id": "7359117152396849276912471939244269631176254624751482772547064208568026511810", "price": "0.004", "size": "11.13", "side": "BUY", "hash": "ca23366943ac716a51d84486a335b6d32e5734b4", "best_bid": "0.998", "best_ask": "0.999"}, {"asset_id": "38966153695292251303244152044268630330033580269266738868503907046849339108583", "price": "0.996", "size": "11.13", "side": "SELL", "hash": "3653d9cfe48031f71d698221a453c612ff5d8a06", "best_bid": "0.001", "best_ask": "0.002"}], "timestamp": "1769384636923", "event_type": "price_change"}}
{"_local_timestamp": "2026-01-25T23:43:57.170760+00:00", "data": {"market": "0x720db82e6ae3132de241c4190b7f72585d5fc2f1364519e814d51f3ec29bf8c6", "price_changes": [{"asset_id": "7359117152396849276912471939244269631176254624751482772547064208568026511810", "price": "0.163", "size": "7.92", "side": "BUY", "hash": "80e78da9683981df34eececd80cb69dfca4802b8", "best_bid": "0.998", "best_ask": "0.999"}, {"asset_id": "38966153695292251303244152044268630330033580269266738868503907046849339108583", "price": "0.837", "size": "7.92", "side": "SELL", "hash": "55fa1f49356a8d536dcb8b3afe03eda5f9fd9f02", "best_bid": "0.001", "best_ask": "0.002"}], "timestamp": "1769384636931", "event_type": "price_change"}}
{"_local_timestamp": "2026-01-25T23:44:03.465442+00:00", "data": {"market": "0x768a10a2ba796df7c565166c61f1b708a7674565add5559f03bd1297d4997ac7", "price_changes": [{"asset_id": "52154086410665277054252505344124616126874295244982327401005145100880544734445", "price": "0.09", "size": "9.53", "side": "BUY", "hash": "467fcc6d3f3e04b7ac6445f04c9fbd78fa5a7f9c", "best_bid": "0.995", "best_ask": "0.997"}, {"asset_id": "102376165613363136742721000249129649340591318769760895202636036152231642180566", "price": "0.91", "size": "9.53", "side": "SELL", "hash": "d3a72cbf97e8a06289d857e7c96835dc737ae4dd", "best_bid": "0.003", "best_ask": "0.005"}], "timestamp": "1769384643171", "event_type": "price_change"}}
{"_local_timestamp": "2026-01-25T23:44:03.466172+00:00", "data": {"market": "0x6a72f5b1d7edf1261156080ddc026da3d80a78834c12925a7bfea4a8aa5b8fb8", "price_changes": [{"asset_id": "18638298170773700688520436893150989158645425879508160426041188051588302722446", "price": "0.071", "size": "100", "side": "BUY", "hash": "a5eb1af3f12f55e4d86c0157125b7c92dfbfcf3d", "best_bid": "0.997", "best_ask": "0.999"}, {"asset_id": "56323539615651816818267229259150871177627322204823867354832755297469690554470", "price": "0.929", "size": "100", "side": "SELL", "hash": "f5773400d011764e0522d59fb7ab4df68a0cc006", "best_bid": "0.001", "best_ask": "0.003"}], "timestamp": "1769384643171", "event_type": "price_change"}}
{"_local_timestamp": "2026-01-25T23:44:03.466870+00:00", "data": {"market": "0xdebb4d098d4382cebf6566acb3749226508e70e048e3a41a7fc44e94c6d0182a", "price_changes": [{"asset_id": "102436772013076156944295871423877161254159297346169261958329577570286200792258", "price": "0.905", "size": "100", "side": "SELL", "hash": "aac202f2996c98f773354b30474f110969ef2c88", "best_bid": "0.011", "best_ask": "0.023"}, {"asset_id": "36753444559858254839802198257676788026485866301122066720655639390168841744924", "price": "0.095", "size": "100", "side": "BUY", "hash": "9df33c32d9ced86df9bbd51ebb634c1311986e54", "best_bid": "0.977", "best_ask": "0.989"}], "timestamp": "1769384643171", "event_type": "price_change"}}
{"_local_timestamp": "2026-01-25T23:44:03.709619+00:00", "data": {"market": "0xdebb4d098d4382cebf6566acb3749226508e70e048e3a41a7fc44e94c6d0182a", "price_changes": [{"asset_id": "102436772013076156944295871423877161254159297346169261958329577570286200792258", "price": "0.903", "size": "161.85", "side": "SELL", "hash": "8d4ad397b4e3820f5e837198a053f4640d692e4d", "best_bid": "0.011", "best_ask": "0.023"}, {"asset_id": "36753444559858254839802198257676788026485866301122066720655639390168841744924", "price": "0.097", "size": "161.85", "side": "BUY", "hash": "bb1ba5612b765bc189969390453eda0f649d5bc9", "best_bid": "0.977", "best_ask": "0.989"}], "timestamp": "1769384643413", "event_type": "price_change"}}
{"_local_timestamp": "2026-01-25T23:44:03.726391+00:00", "data": {"market": "0x6a72f5b1d7edf1261156080ddc026da3d80a78834c12925a7bfea4a8aa5b8fb8", "price_changes": [{"asset_id": "18638298170773700688520436893150989158645425879508160426041188051588302722446", "price": "0.082", "size": "100", "side": "BUY", "hash": "39dd3a212fff06dc16f425a666df72891e78ff78", "best_bid": "0.997", "best_ask": "0.999"}, {"asset_id": "56323539615651816818267229259150871177627322204823867354832755297469690554470", "price": "0.918", "size": "100", "side": "SELL", "hash": "7fe55461b708c53a3d300cee1a5c3e083e6e467b", "best_bid": "0.001", "best_ask": "0.003"}], "timestamp": "1769384643419", "event_type": "price_change"}}
{"_local_timestamp": "2026-01-25T23:44:03.727004+00:00", "data": {"market": "0x768a10a2ba796df7c565166c61f1b708a7674565add5559f03bd1297d4997ac7", "price_changes": [{"asset_id": "52154086410665277054252505344124616126874295244982327401005145100880544734445", "price": "0.051", "size": "139", "side": "BUY", "hash": "f6826127130d3d3a05b6d11c0e8f197a3759f97b", "best_bid": "0.995", "best_ask": "0.997"}, {"asset_id": "102376165613363136742721000249129649340591318769760895202636036152231642180566", "price": "0.949", "size": "139", "side": "SELL", "hash": "7dbbcccb29b580fead86413fd5a6c193d7b67936", "best_bid": "0.003", "best_ask": "0.005"}], "timestamp": "1769384643419", "event_type": "price_change"}}
{"_local_timestamp": "2026-01-25T23:44:21.535608+00:00", "data": {"market": "0xc2208ae9f51a9ff504d662c822859251191fcdc92564076a9c71e56ec8745898", "price_changes": [{"asset_id": "63686700482070758333025925354048148730451881595309572583934588980314675544376", "price": "0.176", "size": "0", "side": "BUY", "hash": "3bdea4cf1477787f89c25f2d18cb0d32fc608bb5", "best_bid": "0.998", "best_ask": "0.999"}, {"asset_id": "93167397740879213220913668801256024250509018532336830527062786853329354974190", "price": "0.824", "size": "0", "side": "SELL", "hash": "71868113e8be5a4074ecc526a546222a4138a02b", "best_bid": "0.001", "best_ask": "0.002"}], "timestamp": "1769384660965", "event_type": "price_change"}}
{"_local_timestamp": "2026-01-25T23:44:21.564365+00:00", "data": {"market": "0xc2208ae9f51a9ff504d662c822859251191fcdc92564076a9c71e56ec8745898", "price_changes": [{"asset_id": "63686700482070758333025925354048148730451881595309572583934588980314675544376", "price": "0.067", "size": "600", "side": "BUY", "hash": "e55158ee739b17bd100e4a373e7501d6b9289368", "best_bid": "0.998", "best_ask": "0.999"}, {"asset_id": "93167397740879213220913668801256024250509018532336830527062786853329354974190", "price": "0.933", "size": "600", "side": "SELL", "hash": "dc2ee2529e0adf09f36f21734629ce3b7dafa8c0", "best_bid": "0.001", "best_ask": "0.002"}], "timestamp": "1769384661169", "event_type": "price_change"}}
{"_local_timestamp": "2026-01-25T23:44:21.594759+00:00", "data": {"market": "0xc2208ae9f51a9ff504d662c822859251191fcdc92564076a9c71e56ec8745898", "price_changes": [{"asset_id": "63686700482070758333025925354048148730451881595309572583934588980314675544376", "price": "0.025", "size": "0", "side": "BUY", "hash": "0a503792ff2072203caf24909745de8012b3e44b", "best_bid": "0.998", "best_ask": "0.999"}, {"asset_id": "93167397740879213220913668801256024250509018532336830527062786853329354974190", "price": "0.975", "size": "0", "side": "SELL", "hash": "7cee8b059e1c01aad3982cf742ba1d0d5555481b", "best_bid": "0.001", "best_ask": "0.002"}], "timestamp": "1769384661358", "event_type": "price_change"}}
{"_local_timestamp": "2026-01-25T23:44:21.637875+00:00", "data": {"market": "0xc2208ae9f51a9ff504d662c822859251191fcdc92564076a9c71e56ec8745898", "price_changes": [{"asset_id": "63686700482070758333025925354048148730451881595309572583934588980314675544376", "price": "0.281", "size": "0", "side": "BUY", "hash": "b17608c7d0db366cbf52b9f2c9d3053aa66986b4", "best_bid": "0.998", "best_ask": "0.999"}, {"asset_id": "93167397740879213220913668801256024250509018532336830527062786853329354974190", "price": "0.719", "size": "0", "side": "SELL", "hash": "e04fb934a59dfe2a0ce83681a09c6d89739b3fb8", "best_bid": "0.001", "best_ask": "0.002"}], "timestamp": "1769384661547", "event_type": "price_change"}}
{"_local_timestamp": "2026-01-25T23:44:21.827738+00:00", "data": {"market": "0xc2208ae9f51a9ff504d662c822859251191fcdc92564076a9c71e56ec8745898", "price_changes": [{"asset_id": "63686700482070758333025925354048148730451881595309572583934588980314675544376", "price": "0.027", "size": "296.29", "side": "BUY", "hash": "e507aa4f664cf4c1013641fbfdee9a3f377bef20", "best_bid": "0.998", "best_ask": "0.999"}, {"asset_id": "93167397740879213220913668801256024250509018532336830527062786853329354974190", "price": "0.973", "size": "296.29", "side": "SELL", "hash": "dfb4b03c2d928d872e17aed6742ee4faf9f520af", "best_bid": "0.001", "best_ask": "0.002"}], "timestamp": "1769384661759", "event_type": "price_change"}}
{"_local_timestamp": "2026-01-25T23:44:22.052138+00:00", "data": {"market": "0xc2208ae9f51a9ff504d662c822859251191fcdc92564076a9c71e56ec8745898", "price_changes": [{"asset_id": "63686700482070758333025925354048148730451881595309572583934588980314675544376", "price": "0.069", "size": "115.94", "side": "BUY", "hash": "b587c1115d6b013be49da92ad47d8eb4703214e7", "best_bid": "0.998", "best_ask": "0.999"}, {"asset_id": "93167397740879213220913668801256024250509018532336830527062786853329354974190", "price": "0.931", "size": "115.94", "side": "SELL", "hash": "c05c7faa8d488b9c95e104a6a517d7d93cd80462", "best_bid": "0.001", "best_ask": "0.002"}], "timestamp": "1769384661982", "event_type": "price_change"}}
{"_local_timestamp": "2026-01-25T23:44:22.304699+00:00", "data": {"market": "0xc2208ae9f51a9ff504d662c822859251191fcdc92564076a9c71e56ec8745898", "price_changes": [{"asset_id": "63686700482070758333025925354048148730451881595309572583934588980314675544376", "price": "0.178", "size": "44.94", "side": "BUY", "hash": "20d0e60aef39ce4df16694e63fdeb3737283ecb0", "best_bid": "0.998", "best_ask": "0.999"}, {"asset_id": "93167397740879213220913668801256024250509018532336830527062786853329354974190", "price": "0.822", "size": "44.94", "side": "SELL", "hash": "44c12e0749e6b0bcec59414e1419890ec3cb82be", "best_bid": "0.001", "best_ask": "0.002"}], "timestamp": "1769384662223", "event_type": "price_change"}}
{"_local_timestamp": "2026-01-25T23:44:22.547727+00:00", "data": {"market": "0xc2208ae9f51a9ff504d662c822859251191fcdc92564076a9c71e56ec8745898", "price_changes": [{"asset_id": "63686700482070758333025925354048148730451881595309572583934588980314675544376", "price": "0.283", "size": "28.26", "side": "BUY", "hash": "d7ca12893ec6b675708ba740d864f01cc9c9611e", "best_bid": "0.998", "best_ask": "0.999"}, {"asset_id": "93167397740879213220913668801256024250509018532336830527062786853329354974190", "price": "0.717", "size": "28.26", "side": "SELL", "hash": "042862cb3cbfcf5a5a0c008f478db194dbf3bfa7", "best_bid": "0.001", "best_ask": "0.002"}], "timestamp": "1769384662474", "event_type": "price_change"}}
{"_local_timestamp": "2026-01-25T23:44:22.934297+00:00", "data": {"market": "0xc2208ae9f51a9ff504d662c822859251191fcdc92564076a9c71e56ec8745898", "price_changes": [{"asset_id": "63686700482070758333025925354048148730451881595309572583934588980314675544376", "price": "0.026", "size": "0", "side": "BUY", "hash": "5f4c243c339a7a5129ff4a0f079d2b14d6b4fb74", "best_bid": "0.998", "best_ask": "0.999"}, {"asset_id": "93167397740879213220913668801256024250509018532336830527062786853329354974190", "price": "0.974", "size": "0", "side": "SELL", "hash": "14e19d89390f793b2e69b718a4937e1597804543", "best_bid": "0.001", "best_ask": "0.002"}], "timestamp": "1769384662856", "event_type": "price_change"}}
{"_local_timestamp": "2026-01-25T23:44:22.938095+00:00", "data": {"market": "0xc2208ae9f51a9ff504d662c822859251191fcdc92564076a9c71e56ec8745898", "price_changes": [{"asset_id": "63686700482070758333025925354048148730451881595309572583934588980314675544376", "price": "0.068", "size": "0", "side": "BUY", "hash": "5f4c243c339a7a5129ff4a0f079d2b14d6b4fb74", "best_bid": "0.998", "best_ask": "0.999"}, {"asset_id": "93167397740879213220913668801256024250509018532336830527062786853329354974190", "price": "0.932", "size": "0", "side": "SELL", "hash": "14e19d89390f793b2e69b718a4937e1597804543", "best_bid": "0.001", "best_ask": "0.002"}], "timestamp": "1769384662856", "event_type": "price_change"}}
{"_local_timestamp": "2026-01-25T23:44:22.950607+00:00", "data": {"market": "0xc2208ae9f51a9ff504d662c822859251191fcdc92564076a9c71e56ec8745898", "price_changes": [{"asset_id": "63686700482070758333025925354048148730451881595309572583934588980314675544376", "price": "0.177", "size": "0", "side": "BUY", "hash": "5f4c243c339a7a5129ff4a0f079d2b14d6b4fb74", "best_bid": "0.998", "best_ask": "0.999"}, {"asset_id": "93167397740879213220913668801256024250509018532336830527062786853329354974190", "price": "0.823", "size": "0", "side": "SELL", "hash": "14e19d89390f793b2e69b718a4937e1597804543", "best_bid": "0.001", "best_ask": "0.002"}], "timestamp": "1769384662856", "event_type": "price_change"}}
{"_local_timestamp": "2026-01-25T23:44:23.628711+00:00", "data": {"market": "0xc2208ae9f51a9ff504d662c822859251191fcdc92564076a9c71e56ec8745898", "price_changes": [{"asset_id": "63686700482070758333025925354048148730451881595309572583934588980314675544376", "price": "0.179", "size": "7.07", "side": "BUY", "hash": "f2515dc0df4a70504c04866a9d80a7df4bc2fe0a", "best_bid": "0.998", "best_ask": "0.999"}, {"asset_id": "93167397740879213220913668801256024250509018532336830527062786853329354974190", "price": "0.821", "size": "7.07", "side": "SELL", "hash": "62a352db8eecec7da8ec6ad465cfd388d4a04233", "best_bid": "0.001", "best_ask": "0.002"}], "timestamp": "1769384663561", "event_type": "price_change"}}
{"_local_timestamp": "2026-01-25T23:44:23.631072+00:00", "data": {"market": "0xc2208ae9f51a9ff504d662c822859251191fcdc92564076a9c71e56ec8745898", "price_changes": [{"asset_id": "63686700482070758333025925354048148730451881595309572583934588980314675544376", "price": "0.028", "size": "6.92", "side": "BUY", "hash": "dfb2687906c3f7ac6582dc7722e4cd92f6928a35", "best_bid": "0.998", "best_ask": "0.999"}, {"asset_id": "93167397740879213220913668801256024250509018532336830527062786853329354974190", "price": "0.972", "size": "6.92", "side": "SELL", "hash": "d1cc8e2a7ff7492d4be829c930eaa124591ee18a", "best_bid": "0.001", "best_ask": "0.002"}], "timestamp": "1769384663562", "event_type": "price_change"}}
{"_local_timestamp": "2026-01-25T23:44:23.632582+00:00", "data": {"market": "0xc2208ae9f51a9ff504d662c822859251191fcdc92564076a9c71e56ec8745898", "price_changes": [{"asset_id": "63686700482070758333025925354048148730451881595309572583934588980314675544376", "price": "0.07", "size": "6.19", "side": "BUY", "hash": "4e987b26b683133d7777311a1f284372d290c71b", "best_bid": "0.998", "best_ask": "0.999"}, {"asset_id": "93167397740879213220913668801256024250509018532336830527062786853329354974190", "price": "0.93", "size": "6.19", "side": "SELL", "hash": "e4a1743fa7c8f460bef3202dd785c5e13fe2f574", "best_bid": "0.001", "best_ask": "0.002"}], "timestamp": "1769384663563", "event_type": "price_change"}}
{"_local_timestamp": "2026-01-25T23:44:24.531286+00:00", "data": {"market": "0x812210ddb6555e27507d9400297225a3f1d60981de7cb66d6c25ad29dfb38d04", "price_changes": [{"asset_id": "44866125854906444448306343930089554704027573886545859149588284387791471079764", "price": "0.405", "size": "0", "side": "BUY", "hash": "cae5ced62177262322540d79aedf6957340605e4", "best_bid": "0.998", "best_ask": "0.999"}, {"asset_id": "54329595038133145577519568384351459887428825578495995657981138893910948687059", "price": "0.595", "size": "0", "side": "SELL", "hash": "1bda9daac5701939b84bb3f1c1e2d80756ef083c", "best_bid": "0.001", "best_ask": "0.002"}], "timestamp": "1769384664459", "event_type": "price_change"}}
{"_local_timestamp": "2026-01-25T23:44:24.774091+00:00", "data": {"market": "0x812210ddb6555e27507d9400297225a3f1d60981de7cb66d6c25ad29dfb38d04", "price_changes": [{"asset_id": "44866125854906444448306343930089554704027573886545859149588284387791471079764", "price": "0.179", "size": "0", "side": "BUY", "hash": "fbe67c2d4897abb9839b3fa6529702f38cd05eb4", "best_bid": "0.998", "best_ask": "0.999"}, {"asset_id": "54329595038133145577519568384351459887428825578495995657981138893910948687059", "price": "0.821", "size": "0", "side": "SELL", "hash": "f7935db613c497cdc2d356d97a83b705d0ccf54f", "best_bid": "0.001", "best_ask": "0.002"}], "timestamp": "1769384664699", "event_type": "price_change"}}
{"_local_timestamp": "2026-01-25T23:44:24.955054+00:00", "data": {"market": "0x812210ddb6555e27507d9400297225a3f1d60981de7cb66d6c25ad29dfb38d04", "price_changes": [{"asset_id": "44866125854906444448306343930089554704027573886545859149588284387791471079764", "price": "0.056", "size": "500", "side": "BUY", "hash": "bffaa9df215caf6a1dbb0c390fb3fb6fc027bd0f", "best_bid": "0.998", "best_ask": "0.999"}, {"asset_id": "54329595038133145577519568384351459887428825578495995657981138893910948687059", "price": "0.944", "size": "500", "side": "SELL", "hash": "d8cf1559276f3496c9c2886de1258340df375d75", "best_bid": "0.001", "best_ask": "0.002"}], "timestamp": "1769384664887", "event_type": "price_change"}}
{"_local_timestamp": "2026-01-25T23:44:25.170584+00:00", "data": {"market": "0x812210ddb6555e27507d9400297225a3f1d60981de7cb66d6c25ad29dfb38d04", "price_changes": [{"asset_id": "44866125854906444448306343930089554704027573886545859149588284387791471079764", "price": "0.026", "size": "0", "side": "BUY", "hash": "10ea72fe5e4cf68cb45d4997ef6e25d21d0d8a69", "best_bid": "0.998", "best_ask": "0.999"}, {"asset_id": "54329595038133145577519568384351459887428825578495995657981138893910948687059", "price": "0.974", "size": "0", "side": "SELL", "hash": "66ec451624393768ee56510747f38d32c05d40c7", "best_bid": "0.001", "best_ask": "0.002"}], "timestamp": "1769384665098", "event_type": "price_change"}}
{"_local_timestamp": "2026-01-25T23:44:25.183373+00:00", "data": {"market": "0x812210ddb6555e27507d9400297225a3f1d60981de7cb66d6c25ad29dfb38d04", "price_changes": [{"asset_id": "44866125854906444448306343930089554704027573886545859149588284387791471079764", "price": "0.406", "size": "0", "side": "BUY", "hash": "3baf9e64d1af8c42677c811d391ae40906309ce4", "best_bid": "0.998", "best_ask": "0.999"}, {"asset_id": "54329595038133145577519568384351459887428825578495995657981138893910948687059", "price": "0.594", "size": "0", "side": "SELL", "hash": "65e1c05f87552ecbcd2065a17b032ac34fad1713", "best_bid": "0.001", "best_ask": "0.002"}], "timestamp": "1769384665115", "event_type": "price_change"}}
{"_local_timestamp": "2026-01-25T23:44:25.214099+00:00", "data": {"market": "0x812210ddb6555e27507d9400297225a3f1d60981de7cb66d6c25ad29dfb38d04", "price_changes": [{"asset_id": "44866125854906444448306343930089554704027573886545859149588284387791471079764", "price": "0.237", "size": "20", "side": "BUY", "hash": "bdb18f24c9090d11ffdfafe24768ed3c037e4eaa", "best_bid": "0.998", "best_ask": "0.999"}, {"asset_id": "54329595038133145577519568384351459887428825578495995657981138893910948687059", "price": "0.763", "size": "20", "side": "SELL", "hash": "c8073b20fba3a3cb39b9e7bb6c6720d14ffd6be2", "best_bid": "0.001", "best_ask": "0.002"}], "timestamp": "1769384665145", "event_type": "price_change"}}
{"_local_timestamp": "2026-01-25T23:44:25.366811+00:00", "data": {"market": "0x812210ddb6555e27507d9400297225a3f1d60981de7cb66d6c25ad29dfb38d04", "price_changes": [{"asset_id": "44866125854906444448306343930089554704027573886545859149588284387791471079764", "price": "0.028", "size": "244.89", "side": "BUY", "hash": "309929ffa3664be5c477c8db91df886a083b1c33", "best_bid": "0.998", "best_ask": "0.999"}, {"asset_id": "54329595038133145577519568384351459887428825578495995657981138893910948687059", "price": "0.972", "size": "244.89", "side": "SELL", "hash": "e649ae5241197db18f3e5085b3ad75f1bc96d74e", "best_bid": "0.001", "best_ask": "0.002"}], "timestamp": "1769384665300", "event_type": "price_change"}}
{"_local_timestamp": "2026-01-25T23:44:25.587503+00:00", "data": {"market": "0x812210ddb6555e27507d9400297225a3f1d60981de7cb66d6c25ad29dfb38d04", "price_changes": [{"asset_id": "44866125854906444448306343930089554704027573886545859149588284387791471079764", "price": "0.058", "size": "118.22", "side": "BUY", "hash": "abd7e5dab346f505d723eafe5a210b8a85b67191", "best_bid": "0.998", "best_ask": "0.999"}, {"asset_id": "54329595038133145577519568384351459887428825578495995657981138893910948687059", "price": "0.942", "size": "118.22", "side": "SELL", "hash": "33b7eeffc8bfb392e2bed52d4b99f484599b0e85", "best_bid": "0.001", "best_ask": "0.002"}], "timestamp": "1769384665517", "event_type": "price_change"}}
{"_local_timestamp": "2026-01-25T23:44:25.806572+00:00", "data": {"market": "0x812210ddb6555e27507d9400297225a3f1d60981de7cb66d6c25ad29dfb38d04", "price_changes": [{"asset_id": "44866125854906444448306343930089554704027573886545859149588284387791471079764", "price": "0.081", "size": "0", "side": "BUY", "hash": "f2147ac7e88a0daed6eb904a5a5915392d84b7a0", "best_bid": "0.998", "best_ask": "0.999"}, {"asset_id": "54329595038133145577519568384351459887428825578495995657981138893910948687059", "price": "0.919", "size": "0", "side": "SELL", "hash": "57a56d4060b2de83b3499a08ce5cefd3813e0f6b", "best_bid": "0.001", "best_ask": "0.002"}], "timestamp": "1769384665723", "event_type": "price_change"}}
{"_local_timestamp": "2026-01-25T23:44:25.995892+00:00", "data": {"market": "0x812210ddb6555e27507d9400297225a3f1d60981de7cb66d6c25ad29dfb38d04", "price_changes": [{"asset_id": "44866125854906444448306343930089554704027573886545859149588284387791471079764", "price": "0.081", "size": "84.65", "side": "BUY", "hash": "bcd96f55803fa1542f968989db6fd7616b94d240", "best_bid": "0.998", "best_ask": "0.999"}, {"asset_id": "54329595038133145577519568384351459887428825578495995657981138893910948687059", "price": "0.919", "size": "84.65", "side": "SELL", "hash": "b89846e99d9dc578d2d5450d6330af6690de1561", "best_bid": "0.001", "best_ask": "0.002"}], "timestamp": "1769384665925", "event_type": "price_change"}}
{"_local_timestamp": "2026-01-25T23:44:26.136234+00:00", "data": {"market": "0x812210ddb6555e27507d9400297225a3f1d60981de7cb66d6c25ad29dfb38d04", "price_changes": [{"asset_id": "44866125854906444448306343930089554704027573886545859149588284387791471079764", "price": "0.004", "size": "0", "side": "BUY", "hash": "2907702f2646961329c963ef51ceaba01c64ccdb", "best_bid": "0.998", "best_ask": "0.999"}, {"asset_id": "54329595038133145577519568384351459887428825578495995657981138893910948687059", "price": "0.996", "size": "0", "side": "SELL", "hash": "715f1c34d88cb7558a5c070a303e435c35e23909", "best_bid": "0.001", "best_ask": "0.002"}], "timestamp": "1769384666067", "event_type": "price_change"}}
{"_local_timestamp": "2026-01-25T23:44:26.136935+00:00", "data": {"market": "0x812210ddb6555e27507d9400297225a3f1d60981de7cb66d6c25ad29dfb38d04", "price_changes": [{"asset_id": "44866125854906444448306343930089554704027573886545859149588284387791471079764", "price": "0.011", "size": "0", "side": "BUY", "hash": "2907702f2646961329c963ef51ceaba01c64ccdb", "best_bid": "0.998", "best_ask": "0.999"}, {"asset_id": "54329595038133145577519568384351459887428825578495995657981138893910948687059", "price": "0.989", "size": "0", "side": "SELL", "hash": "715f1c34d88cb7558a5c070a303e435c35e23909", "best_bid": "0.001", "best_ask": "0.002"}], "timestamp": "1769384666067", "event_type": "price_change"}}
{"_local_timestamp": "2026-01-25T23:44:26.137554+00:00", "data": {"market": "0x812210ddb6555e27507d9400297225a3f1d60981de7cb66d6c25ad29dfb38d04", "price_changes": [{"asset_id": "44866125854906444448306343930089554704027573886545859149588284387791471079764", "price": "0.027", "size": "0", "side": "BUY", "hash": "2907702f2646961329c963ef51ceaba01c64ccdb", "best_bid": "0.998", "best_ask": "0.999"}, {"asset_id": "54329595038133145577519568384351459887428825578495995657981138893910948687059", "price": "0.973", "size": "0", "side": "SELL", "hash": "715f1c34d88cb7558a5c070a303e435c35e23909", "best_bid": "0.001", "best_ask": "0.002"}], "timestamp": "1769384666067", "event_type": "price_change"}}
{"_local_timestamp": "2026-01-25T23:44:26.138173+00:00", "data": {"market": "0x812210ddb6555e27507d9400297225a3f1d60981de7cb66d6c25ad29dfb38d04", "price_changes": [{"asset_id": "44866125854906444448306343930089554704027573886545859149588284387791471079764", "price": "0.057", "size": "0", "side": "BUY", "hash": "2907702f2646961329c963ef51ceaba01c64ccdb", "best_bid": "0.998", "best_ask": "0.999"}, {"asset_id": "54329595038133145577519568384351459887428825578495995657981138893910948687059", "price": "0.943", "size": "0", "side": "SELL", "hash": "715f1c34d88cb7558a5c070a303e435c35e23909", "best_bid": "0.001", "best_ask": "0.002"}], "timestamp": "1769384666067", "event_type": "price_change"}}
{"_local_timestamp": "2026-01-25T23:44:26.138814+00:00", "data": {"market": "0x812210ddb6555e27507d9400297225a3f1d60981de7cb66d6c25ad29dfb38d04", "price_changes": [{"asset_id": "44866125854906444448306343930089554704027573886545859149588284387791471079764", "price": "0.18", "size": "0", "side": "BUY", "hash": "2907702f2646961329c963ef51ceaba01c64ccdb", "best_bid": "0.998", "best_ask": "0.999"}, {"asset_id": "54329595038133145577519568384351459887428825578495995657981138893910948687059", "price": "0.82", "size": "0", "side": "SELL", "hash": "715f1c34d88cb7558a5c070a303e435c35e23909", "best_bid": "0.001", "best_ask": "0.002"}], "timestamp": "1769384666067", "event_type": "price_change"}}
{"_local_timestamp": "2026-01-25T23:44:26.230357+00:00", "data": {"market": "0x812210ddb6555e27507d9400297225a3f1d60981de7cb66d6c25ad29dfb38d04", "price_changes": [{"asset_id": "44866125854906444448306343930089554704027573886545859149588284387791471079764", "price": "0.151", "size": "45.41", "side": "BUY", "hash": "4dbfcd0d96e8e61558a68c989467bf5f772380a1", "best_bid": "0.998", "best_ask": "0.999"}, {"asset_id": "54329595038133145577519568384351459887428825578495995657981138893910948687059", "price": "0.849", "size": "45.41", "side": "SELL", "hash": "dad306d531e61c7cfdc09f666354f9e02b535396", "best_bid": "0.001", "best_ask": "0.002"}], "timestamp": "1769384666166", "event_type": "price_change"}}
{"_local_timestamp": "2026-01-25T23:44:26.446710+00:00", "data": {"market": "0x812210ddb6555e27507d9400297225a3f1d60981de7cb66d6c25ad29dfb38d04", "price_changes": [{"asset_id": "44866125854906444448306343930089554704027573886545859149588284387791471079764", "price": "0.181", "size": "37.88", "side": "BUY", "hash": "fdd25f6d2e51e758e5d339c85bf2e15689a608ce", "best_bid": "0.998", "best_ask": "0.999"}, {"asset_id": "54329595038133145577519568384351459887428825578495995657981138893910948687059", "price": "0.819", "size": "37.88", "side": "SELL", "hash": "e0b3e6cf9697924a42a172bfd659a71cdc202883", "best_bid": "0.001", "best_ask": "0.002"}], "timestamp": "1769384666380", "event_type": "price_change"}}
{"_local_timestamp": "2026-01-25T23:44:26.643923+00:00", "data": {"market": "0x812210ddb6555e27507d9400297225a3f1d60981de7cb66d6c25ad29dfb38d04", "price_changes": [{"asset_id": "44866125854906444448306343930089554704027573886545859149588284387791471079764", "price": "0.236", "size": "0", "side": "BUY", "hash": "bc029849e9cd272a77adc41d39bbd292515717ce", "best_bid": "0.998", "best_ask": "0.999"}, {"asset_id": "54329595038133145577519568384351459887428825578495995657981138893910948687059", "price": "0.764", "size": "0", "side": "SELL", "hash": "5a73d18f465f4082bec0b6e65adda4f2400adb50", "best_bid": "0.001", "best_ask": "0.002"}], "timestamp": "1769384666573", "event_type": "price_change"}}
{"_local_timestamp": "2026-01-25T23:44:26.836343+00:00", "data": {"market": "0x812210ddb6555e27507d9400297225a3f1d60981de7cb66d6c25ad29dfb38d04", "price_changes": [{"asset_id": "44866125854906444448306343930089554704027573886545859149588284387791471079764", "price": "0.181", "size": "44.74", "side": "BUY", "hash": "39f19e953712b63a6c8d1f77213680d08851957f", "best_bid": "0.998", "best_ask": "0.999"}, {"asset_id": "54329595038133145577519568384351459887428825578495995657981138893910948687059", "price": "0.819", "size": "44.74", "side": "SELL", "hash": "a4bfb414974e1ac072ebf3120b018f46e21642d0", "best_bid": "0.001", "best_ask": "0.002"}], "timestamp": "1769384666767", "event_type": "price_change"}}
{"_local_timestamp": "2026-01-25T23:44:26.837193+00:00", "data": {"market": "0x812210ddb6555e27507d9400297225a3f1d60981de7cb66d6c25ad29dfb38d04", "price_changes": [{"asset_id": "44866125854906444448306343930089554704027573886545859149588284387791471079764", "price": "0.022", "size": "7.79", "side": "BUY", "hash": "ace24e0e6a90baddd98c19b40d9d3801f9a546de", "best_bid": "0.998", "best_ask": "0.999"}, {"asset_id": "54329595038133145577519568384351459887428825578495995657981138893910948687059", "price": "0.978", "size": "7.79", "side": "SELL", "hash": "7097098a6f0148b9b066dc5146bc7e78d401066d", "best_bid": "0.001", "best_ask": "0.002"}], "timestamp": "1769384666768", "event_type": "price_change"}}
{"_local_timestamp": "2026-01-25T23:44:26.837921+00:00", "data": {"market": "0x812210ddb6555e27507d9400297225a3f1d60981de7cb66d6c25ad29dfb38d04", "price_changes": [{"asset_id": "44866125854906444448306343930089554704027573886545859149588284387791471079764", "price": "0.007", "size": "10.45", "side": "BUY", "hash": "5a321225c2b6ccf2fb2032331d70193df3985eb3", "best_bid": "0.998", "best_ask": "0.999"}, {"asset_id": "54329595038133145577519568384351459887428825578495995657981138893910948687059", "price": "0.993", "size": "10.45", "side": "SELL", "hash": "837a192bc5a41064f29934994ade7976ef8aa806", "best_bid": "0.001", "best_ask": "0.002"}], "timestamp": "1769384666769", "event_type": "price_change"}}
{"_local_timestamp": "2026-01-25T23:44:26.838629+00:00", "data": {"market": "0x812210ddb6555e27507d9400297225a3f1d60981de7cb66d6c25ad29dfb38d04", "price_changes": [{"asset_id": "44866125854906444448306343930089554704027573886545859149588284387791471079764", "price": "0.003", "size": "30406.62", "side": "BUY", "hash": "0e11f1a16658c7ee715af6a48cfaea94d10e78db", "best_bid": "0.998", "best_ask": "0.999"}, {"asset_id": "54329595038133145577519568384351459887428825578495995657981138893910948687059", "price": "0.997", "size": "30406.62", "side": "SELL", "hash": "7a405b66a6d0abeaef5f3fcebe3ff8174e09966a", "best_bid": "0.001", "best_ask": "0.002"}], "timestamp": "1769384666770", "event_type": "price_change"}}
{"_local_timestamp": "2026-01-25T23:44:26.839342+00:00", "data": {"market": "0x812210ddb6555e27507d9400297225a3f1d60981de7cb66d6c25ad29dfb38d04", "price_changes": [{"asset_id": "44866125854906444448306343930089554704027573886545859149588284387791471079764", "price": "0.059", "size": "8.18", "side": "BUY", "hash": "228c8ecccbc2ba2d0c11a77d4a629c9a809103ca", "best_bid": "0.998", "best_ask": "0.999"}, {"asset_id": "54329595038133145577519568384351459887428825578495995657981138893910948687059", "price": "0.941", "size": "8.18", "side": "SELL", "hash": "9d5a6dc6704e7fb7740a7c4c834e079de901d488", "best_bid": "0.001", "best_ask": "0.002"}], "timestamp": "1769384666771", "event_type": "price_change"}}
{"_local_timestamp": "2026-01-25T23:44:26.855511+00:00", "data": {"market": "0x812210ddb6555e27507d9400297225a3f1d60981de7cb66d6c25ad29dfb38d04", "price_changes": [{"asset_id": "44866125854906444448306343930089554704027573886545859149588284387791471079764", "price": "0.236", "size": "29.05", "side": "BUY", "hash": "2366fd55751630f653802904e1a5659291b1e65f", "best_bid": "0.998", "best_ask": "0.999"}, {"asset_id": "54329595038133145577519568384351459887428825578495995657981138893910948687059", "price": "0.764", "size": "29.05", "side": "SELL", "hash": "51bc7921df90aeea83db7c868715b0788891c45b", "best_bid": "0.001", "best_ask": "0.002"}], "timestamp": "1769384666775", "event_type": "price_change"}}
{"_local_timestamp": "2026-01-25T23:44:27.077749+00:00", "data": {"market": "0x812210ddb6555e27507d9400297225a3f1d60981de7cb66d6c25ad29dfb38d04", "price_changes": [{"asset_id": "44866125854906444448306343930089554704027573886545859149588284387791471079764", "price": "0.407", "size": "16.84", "side": "BUY", "hash": "141257f51957b355e2146f69f0b9e33c520274af", "best_bid": "0.998", "best_ask": "0.999"}, {"asset_id": "54329595038133145577519568384351459887428825578495995657981138893910948687059", "price": "0.593", "size": "16.84", "side": "SELL", "hash": "8ecb40b89462499dec4cc0f00305e26599a0cda2", "best_bid": "0.001", "best_ask": "0.002"}], "timestamp": "1769384666984", "event_type": "price_change"}}
{"_local_timestamp": "2026-01-25T23:44:28.054350+00:00", "data": {"market": "0x812210ddb6555e27507d9400297225a3f1d60981de7cb66d6c25ad29dfb38d04", "price_changes": [{"asset_id": "44866125854906444448306343930089554704027573886545859149588284387791471079764", "price": "0.237", "size": "0", "side": "BUY", "hash": "38e2d5f1c1ce4683f91f1f484978c1fcb63c45b0", "best_bid": "0.998", "best_ask": "0.999"}, {"asset_id": "54329595038133145577519568384351459887428825578495995657981138893910948687059", "price": "0.763", "size": "0", "side": "SELL", "hash": "1f9204222593d340972c9399a77159dac8ff3a46", "best_bid": "0.001", "best_ask": "0.002"}], "timestamp": "1769384667987", "event_type": "price_change"}}
{"_local_timestamp": "2026-01-25T23:44:28.090480+00:00", "data": {"market": "0x812210ddb6555e27507d9400297225a3f1d60981de7cb66d6c25ad29dfb38d04", "price_changes": [{"asset_id": "44866125854906444448306343930089554704027573886545859149588284387791471079764", "price": "0.408", "size": "20", "side": "BUY", "hash": "a340604cad4ba9d4d0e076673e9b574841047064", "best_bid": "0.998", "best_ask": "0.999"}, {"asset_id": "54329595038133145577519568384351459887428825578495995657981138893910948687059", "price": "0.592", "size": "20", "side": "SELL", "hash": "2787c379e8f7b0af5a4fd6438477656c43bb56e1", "best_bid": "0.001", "best_ask": "0.002"}], "timestamp": "1769384668011", "event_type": "price_change"}}
{"_local_timestamp": "2026-01-25T23:44:32.909776+00:00", "data": {"market": "0x768a10a2ba796df7c565166c61f1b708a7674565add5559f03bd1297d4997ac7", "price_changes": [{"asset_id": "52154086410665277054252505344124616126874295244982327401005145100880544734445", "price": "0.05", "size": "30", "side": "BUY", "hash": "fa751c0a8eae23767325db78c6adaa6210b7b3bb", "best_bid": "0.995", "best_ask": "0.997"}, {"asset_id": "102376165613363136742721000249129649340591318769760895202636036152231642180566", "price": "0.95", "size": "30", "side": "SELL", "hash": "f308a804e7b3cf516b05cb50b678be3d3de43177", "best_bid": "0.003", "best_ask": "0.005"}], "timestamp": "1769384672844", "event_type": "price_change"}}
{"_local_timestamp": "2026-01-25T23:44:32.910606+00:00", "data": {"market": "0x768a10a2ba796df7c565166c61f1b708a7674565add5559f03bd1297d4997ac7", "price_changes": [{"asset_id": "52154086410665277054252505344124616126874295244982327401005145100880544734445", "price": "0.028", "size": "0", "side": "BUY", "hash": "fa751c0a8eae23767325db78c6adaa6210b7b3bb", "best_bid": "0.995", "best_ask": "0.997"}, {"asset_id": "102376165613363136742721000249129649340591318769760895202636036152231642180566", "price": "0.972", "size": "0", "side": "SELL", "hash": "f308a804e7b3cf516b05cb50b678be3d3de43177", "best_bid": "0.003", "best_ask": "0.005"}], "timestamp": "1769384672844", "event_type": "price_change"}}
{"_local_timestamp": "2026-01-25T23:44:32.911328+00:00", "data": {"market": "0x7e2664fd56bdb98dfe10fc702d40c7bb34bbd173b4e1a4ace956e8bee3a15ed3", "price_changes": [{"asset_id": "32585257541944296536919042049344155455892911573822808260948030619026984605016", "price": "0.052", "size": "0", "side": "BUY", "hash": "497c179c6ddbc8a0e3271b848dd07f73f176a431", "best_bid": "0.998", "best_ask": "0.999"}, {"asset_id": "8013350309980067752092467553989532032941595361116376915087772932251249070671", "price": "0.948", "size": "0", "side": "SELL", "hash": "13aaf66d3050fbca12d21905181e3660fe02c130", "best_bid": "0.001", "best_ask": "0.002"}], "timestamp": "1769384672845", "event_type": "price_change"}}
{"_local_timestamp": "2026-01-25T23:44:32.917229+00:00", "data": {"market": "0x67eb32405b2ad24182b8575eb560b3b087baa20340302a079bb8138637ed1b47", "price_changes": [{"asset_id": "91614728309695910310598383443496140750308657331105979804609645991161575447633", "price": "0.08", "size": "0", "side": "BUY", "hash": "7dfa1b2b96257bceed6e868485dbbec0604fb02d", "best_bid": "0.998", "best_ask": "0.999"}, {"asset_id": "23177234539005086745924487565572514732873310188830333623513053312024465699839", "price": "0.92", "size": "0", "side": "SELL", "hash": "2f57742f0a4e08566b4caf23383d8e7e0620fc3f", "best_bid": "0.001", "best_ask": "0.002"}], "timestamp": "1769384672845", "event_type": "price_change"}}
{"_local_timestamp": "2026-01-25T23:44:32.918003+00:00", "data": {"market": "0x67eb32405b2ad24182b8575eb560b3b087baa20340302a079bb8138637ed1b47", "price_changes": [{"asset_id": "91614728309695910310598383443496140750308657331105979804609645991161575447633", "price": "0.056", "size": "0", "side": "BUY", "hash": "7dfa1b2b96257bceed6e868485dbbec0604fb02d", "best_bid": "0.998", "best_ask": "0.999"}, {"asset_id": "23177234539005086745924487565572514732873310188830333623513053312024465699839", "price": "0.944", "size": "0", "side": "SELL", "hash": "2f57742f0a4e08566b4caf23383d8e7e0620fc3f", "best_bid": "0.001", "best_ask": "0.002"}], "timestamp": "1769384672845", "event_type": "price_change"}}
{"_local_timestamp": "2026-01-25T23:44:33.215698+00:00", "data": {"market": "0x67eb32405b2ad24182b8575eb560b3b087baa20340302a079bb8138637ed1b47", "price_changes": [{"asset_id": "91614728309695910310598383443496140750308657331105979804609645991161575447633", "price": "0.081", "size": "418.51", "side": "BUY", "hash": "ccf297c2436fa79dfb5e7859a3b7f274b4d483e2", "best_bid": "0.998", "best_ask": "0.999"}, {"asset_id": "23177234539005086745924487565572514732873310188830333623513053312024465699839", "price": "0.919", "size": "418.51", "side": "SELL", "hash": "4f606c3075ac75d026461fc69b2f6a47deeda003", "best_bid": "0.001", "best_ask": "0.002"}], "timestamp": "1769384673141", "event_type": "price_change"}}
{"_local_timestamp": "2026-01-25T23:44:33.216531+00:00", "data": {"market": "0x7e2664fd56bdb98dfe10fc702d40c7bb34bbd173b4e1a4ace956e8bee3a15ed3", "price_changes": [{"asset_id": "32585257541944296536919042049344155455892911573822808260948030619026984605016", "price": "0.054", "size": "648.14", "side": "BUY", "hash": "40487d301cb279f347bb45427e8dddf7aa5faeb0", "best_bid": "0.998", "best_ask": "0.999"}, {"asset_id": "8013350309980067752092467553989532032941595361116376915087772932251249070671", "price": "0.946", "size": "648.14", "side": "SELL", "hash": "7eadff586ee2f3bcbc67b72d19408571124cca72", "best_bid": "0.001", "best_ask": "0.002"}], "timestamp": "1769384673141", "event_type": "price_change"}}
{"_local_timestamp": "2026-01-25T23:44:33.222340+00:00", "data": {"market": "0x768a10a2ba796df7c565166c61f1b708a7674565add5559f03bd1297d4997ac7", "price_changes": [{"asset_id": "52154086410665277054252505344124616126874295244982327401005145100880544734445", "price": "0.03", "size": "1020", "side": "BUY", "hash": "01c3364562d735dccdc2f9b6bca3e97bce39d228", "best_bid": "0.995", "best_ask": "0.997"}, {"asset_id": "102376165613363136742721000249129649340591318769760895202636036152231642180566", "price": "0.97", "size": "1020", "side": "SELL", "hash": "63b9716d6e9f5688990fb630dd8f8340aa116336", "best_bid": "0.003", "best_ask": "0.005"}], "timestamp": "1769384673141", "event_type": "price_change"}}
{"_local_timestamp": "2026-01-25T23:44:33.223084+00:00", "data": {"market": "0x67eb32405b2ad24182b8575eb560b3b087baa20340302a079bb8138637ed1b47", "price_changes": [{"asset_id": "91614728309695910310598383443496140750308657331105979804609645991161575447633", "price": "0.058", "size": "665.51", "side": "BUY", "hash": "384c04838e1af3afcc3dbddc58f74c56daca9c68", "best_bid": "0.998", "best_ask": "0.999"}, {"asset_id": "23177234539005086745924487565572514732873310188830333623513053312024465699839", "price": "0.942", "size": "665.51", "side": "SELL", "hash": "e50aaa017ba95d98b0bdb84e5f070a1a112deb70", "best_bid": "0.001", "best_ask": "0.002"}], "timestamp": "1769384673142", "event_type": "price_change"}}
{"_local_timestamp": "2026-01-25T23:44:33.223800+00:00", "data": {"market": "0x768a10a2ba796df7c565166c61f1b708a7674565add5559f03bd1297d4997ac7", "price_changes": [{"asset_id": "52154086410665277054252505344124616126874295244982327401005145100880544734445", "price": "0.052", "size": "684.61", "side": "BUY", "hash": "845bbe27f2324663a15b807d239ec41e59e412b0", "best_bid": "0.995", "best_ask": "0.997"}, {"asset_id": "102376165613363136742721000249129649340591318769760895202636036152231642180566", "price": "0.948", "size": "684.61", "side": "SELL", "hash": "9a641d6116a3ad1c755afa43e3a720642873f4d2", "best_bid": "0.003", "best_ask": "0.005"}], "timestamp": "1769384673143", "event_type": "price_change"}}
{"_local_timestamp": "2026-01-25T23:44:36.056973+00:00", "data": {"market": "0x23e13d00bf97cf1f66a9cc9c73b0d9122ffdcaa00391dcbcf7c194920d2c637a", "price_changes": [{"asset_id": "71097957014663900449430016744507587046826310681746179766837847959835251978939", "price": "0.501", "size": "9.11", "side": "BUY", "hash": "6e5722a018a83c7f6cf0260a792a793d75acf500", "best_bid": "0.996", "best_ask": "0.999"}, {"asset_id": "76314120704895570216363719360303120994834914074725880204393164758332011771623", "price": "0.499", "size": "9.11", "side": "SELL", "hash": "5754e9b33ca9192695c22707737623687af3e3bd", "best_bid": "0.001", "best_ask": "0.004"}], "timestamp": "1769384675992", "event_type": "price_change"}}
{"_local_timestamp": "2026-01-25T23:44:36.244368+00:00", "data": {"market": "0x23e13d00bf97cf1f66a9cc9c73b0d9122ffdcaa00391dcbcf7c194920d2c637a", "price_changes": [{"asset_id": "71097957014663900449430016744507587046826310681746179766837847959835251978939", "price": "0.5", "size": "0", "side": "BUY", "hash": "35b08d09f082b75cf0e7ce7143f6e763bd512a56", "best_bid": "0.996", "best_ask": "0.999"}, {"asset_id": "76314120704895570216363719360303120994834914074725880204393164758332011771623", "price": "0.5", "size": "0", "side": "SELL", "hash": "28662ef1098e2b727a46ec4e5a8675fa7607ef1a", "best_bid": "0.001", "best_ask": "0.004"}], "timestamp": "1769384676176", "event_type": "price_change"}}
{"_local_timestamp": "2026-01-25T23:44:36.431034+00:00", "data": {"market": "0x23e13d00bf97cf1f66a9cc9c73b0d9122ffdcaa00391dcbcf7c194920d2c637a", "price_changes": [{"asset_id": "71097957014663900449430016744507587046826310681746179766837847959835251978939", "price": "0.229", "size": "0", "side": "BUY", "hash": "9e7d8b0f08b497695668acd20eb8dfc658170a6d", "best_bid": "0.996", "best_ask": "0.999"}, {"asset_id": "76314120704895570216363719360303120994834914074725880204393164758332011771623", "price": "0.771", "size": "0", "side": "SELL", "hash": "974979a614e0ef71db69e75e4a5832b76c84098d", "best_bid": "0.001", "best_ask": "0.004"}], "timestamp": "1769384676353", "event_type": "price_change"}}
{"_local_timestamp": "2026-01-25T23:44:36.622621+00:00", "data": {"market": "0x23e13d00bf97cf1f66a9cc9c73b0d9122ffdcaa00391dcbcf7c194920d2c637a", "price_changes": [{"asset_id": "71097957014663900449430016744507587046826310681746179766837847959835251978939", "price": "0.129", "size": "0", "side": "BUY", "hash": "9d15ffa8c5c21f4c31c1008cb72592146b7a5fb4", "best_bid": "0.996", "best_ask": "0.999"}, {"asset_id": "76314120704895570216363719360303120994834914074725880204393164758332011771623", "price": "0.871", "size": "0", "side": "SELL", "hash": "f2804b8827cb9d258713897da22e2b43b2d9fc64", "best_bid": "0.001", "best_ask": "0.004"}], "timestamp": "1769384676550", "event_type": "price_change"}}
{"_local_timestamp": "2026-01-25T23:44:36.867033+00:00", "data": {"market": "0x23e13d00bf97cf1f66a9cc9c73b0d9122ffdcaa00391dcbcf7c194920d2c637a", "price_changes": [{"asset_id": "71097957014663900449430016744507587046826310681746179766837847959835251978939", "price": "0.058", "size": "0", "side": "BUY", "hash": "8f59de2d289de25d9db6152da0507d2dbba42f33", "best_bid": "0.996", "best_ask": "0.999"}, {"asset_id": "76314120704895570216363719360303120994834914074725880204393164758332011771623", "price": "0.942", "size": "0", "side": "SELL", "hash": "4036082b78c785dfdc30c0ad9d67422e1c25eeee", "best_bid": "0.001", "best_ask": "0.004"}], "timestamp": "1769384676798", "event_type": "price_change"}}
