{"_local_timestamp": "2026-01-25T23:33:54.954892+00:00", "data": [{"market": "0x576804ee9df3fb32ac1fe25764c84fdf2a6eb28b4fe66a9801460f44ecb98bc5", "asset_id": "75377239927867306094237568544414168929541339145556678680059452627231461835789", "timestamp": "1769384016174", "hash": "34d34a90a912bb63640457ab25b8375bffca31b4", "bids": [], "asks": [{"price": "0.999", "size": "105.21"}, {"price": "0.99", "size": "1800"}, {"price": "0.98", "size": "1500"}, {"price": "0.979", "size": "12.11"}, {"price": "0.94", "size": "1300"}, {"price": "0.92", "size": "400"}, {"price": "0.919", "size": "7.9"}, {"price": "0.86", "size": "600"}, {"price": "0.5", "size": "20"}, {"price": "0.2", "size": "599.15"}, {"price": "0.19", "size": "500"}, {"price": "0.05", "size": "1000"}, {"price": "0.049", "size": "65"}, {"price": "0.024", "size": "10"}], "event_type": "book", "last_trade_price": ""}, {"market": "0x576804ee9df3fb32ac1fe25764c84fdf2a6eb28b4fe66a9801460f44ecb98bc5", "asset_id": "12775633294453699059014727298399105802336328278612201057647301831500756764380", "timestamp": "1769384016174", "hash": "9a16fd96ae4d7109462f793c32dccd8e61b6c1ff", "bids": [{"price": "0.001", "size": "105.21"}, {"price": "0.01", "size": "1800"}, {"price": "0.02", "size": "1500"}, {"price": "0.021", "size": "12.11"}, {"price": "0.06", "size": "1300"}, {"price": "0.08", "size": "400"}, {"price": "0.081", "size": "7.9"}, {"price": "0.14", "size": "600"}, {"price": "0.5", "size": "20"}, {"price": "0.8", "size": "599.15"}, {"price": "0.81", "size": "500"}, {"price": "0.95", "size": "1000"}, {"price": "0.951", "size": "65"}, {"price": "0.976", "size": "10"}], "asks": [], "event_type": "book", "last_trade_price": ""}]}
{"_local_timestamp": "2026-01-25T23:33:58.212024+00:00", "data": {"market": "0x576804ee9df3fb32ac1fe25764c84fdf2a6eb28b4fe66a9801460f44ecb98bc5", "price_changes": [{"asset_id": "75377239927867306094237568544414168929541339145556678680059452627231461835789", "price": "0.024", "size": "0", "side": "SELL", "hash": "5a4a97cf564dfdf72147d59ba2da57dab2dc1c8b", "best_bid": "0", "best_ask": "0.049"}, {"asset_id": "12775633294453699059014727298399105802336328278612201057647301831500756764380", "price": "0.976", "size": "0", "side": "BUY", "hash": "8b0b37949c6d423173917d255124855efe3e34a5", "best_bid": "0.951", "best_ask": "1"}], "timestamp": "1769384038136", "event_type": "price_change"}}
{"_local_timestamp": "2026-01-25T23:33:58.661348+00:00", "data": {"market": "0x576804ee9df3fb32ac1fe25764c84fdf2a6eb28b4fe66a9801460f44ecb98bc5", "price_changes": [{"asset_id": "75377239927867306094237568544414168929541339145556678680059452627231461835789", "price": "0.023", "size": "10", "side": "SELL", "hash": "9370657e03ccc592500788d2235b9003712bef5e", "best_bid": "0", "best_ask": "0.023"}, {"asset_id": "12775633294453699059014727298399105802336328278612201057647301831500756764380", "price": "0.977", "size": "10", "side": "BUY", "hash": "168c3b2fece804c2e3b77dacce8788dac11e7f19", "best_bid": "0.977", "best_ask": "1"}], "timestamp": "1769384038585", "event_type": "price_change"}}
{"_local_timestamp": "2026-01-25T23:34:17.998831+00:00", "data": {"market": "0x576804ee9df3fb32ac1fe25764c84fdf2a6eb28b4fe66a9801460f44ecb98bc5", "price_changes": [{"asset_id": "12775633294453699059014727298399105802336328278612201057647301831500756764380", "price": "0.081", "size": "0", "side": "BUY", "hash": "4728c9e755d4bc6100bba2b2162ec30161d4f6ac", "best_bid": "0.977", "best_ask": "1"}, {"asset_id": "75377239927867306094237568544414168929541339145556678680059452627231461835789", "price": "0.919", "size": "0", "side": "SELL", "hash": "46a136ee394130f03ad32f7139fc2443a24702e1", "best_bid": "0", "best_ask": "0.023"}], "timestamp": "1769384057757", "event_type": "price_change"}}
{"_local_timestamp": "2026-01-25T23:34:17.999780+00:00", "data": {"market": "0x576804ee9df3fb32ac1fe25764c84fdf2a6eb28b4fe66a9801460f44ecb98bc5", "price_changes": [{"asset_id": "12775633294453699059014727298399105802336328278612201057647301831500756764380", "price": "0.001", "size": "0", "side": "BUY", "hash": "4728c9e755d4bc6100bba2b2162ec30161d4f6ac", "best_bid": "0.977", "best_ask": "1"}, {"asset_id": "75377239927867306094237568544414168929541339145556678680059452627231461835789", "price": "0.999", "size": "0", "side": "SELL", "hash": "46a136ee394130f03ad32f7139fc2443a24702e1", "best_bid": "0", "best_ask": "0.023"}], "timestamp": "1769384057757", "event_type": "price_change"}}
{"_local_timestamp": "2026-01-25T23:34:18.000210+00:00", "data": {"market": "0x576804ee9df3fb32ac1fe25764c84fdf2a6eb28b4fe66a9801460f44ecb98bc5", "price_changes": [{"asset_id": "12775633294453699059014727298399105802336328278612201057647301831500756764380", "price": "0.021", "size": "0", "side": "BUY", "hash": "4728c9e755d4bc6100bba2b2162ec30161d4f6ac", "best_bid": "0.977", "best_ask": "1"}, {"asset_id": "75377239927867306094237568544414168929541339145556678680059452627231461835789", "price": "0.979", "size": "0", "side": "SELL", "hash": "46a136ee394130f03ad32f7139fc2443a24702e1", "best_bid": "0", "best_ask": "0.023"}], "timestamp": "1769384057757", "event_type": "price_change"}}
{"_local_timestamp": "2026-01-25T23:34:19.276053+00:00", "data": {"market": "0x576804ee9df3fb32ac1fe25764c84fdf2a6eb28b4fe66a9801460f44ecb98bc5", "price_changes": [{"asset_id": "75377239927867306094237568544414168929541339145556678680059452627231461835789", "price": "0.023", "size": "0", "side": "SELL", "hash": "6c139ee7cf40a97574ab7203da9b32cca8545bbb", "best_bid": "0", "best_ask": "0.049"}, {"asset_id": "12775633294453699059014727298399105802336328278612201057647301831500756764380", "price": "0.977", "size": "0", "side": "BUY", "hash": "e32ee6da187882da6ae91fcfc44b00becd961f3d", "best_bid": "0.951", "best_ask": "1"}], "timestamp": "1769384059024", "event_type": "price_change"}}
{"_local_timestamp": "2026-01-25T23:34:19.688676+00:00", "data": {"market": "0x576804ee9df3fb32ac1fe25764c84fdf2a6eb28b4fe66a9801460f44ecb98bc5", "price_changes": [{"asset_id": "75377239927867306094237568544414168929541339145556678680059452627231461835789", "price": "0.022", "size": "10", "side": "SELL", "hash": "70d73f4c812b6642082d48cb5fa24067bb55fe1f", "best_bid": "0", "best_ask": "0.022"}, {"asset_id": "12775633294453699059014727298399105802336328278612201057647301831500756764380", "price": "0.978", "size": "10", "side": "BUY", "hash": "18df9f1af11dfb949ca983a5c037039c4de1b9d2", "best_bid": "0.978", "best_ask": "1"}], "timestamp": "1769384059472", "event_type": "price_change"}}
{"_local_timestamp": "2026-01-25T23:34:40.099261+00:00", "data": {"market": "0x576804ee9df3fb32ac1fe25764c84fdf2a6eb28b4fe66a9801460f44ecb98bc5", "price_changes": [{"asset_id": "75377239927867306094237568544414168929541339145556678680059452627231461835789", "price": "0.022", "size": "0", "side": "SELL", "hash": "2673655c080dbbbdf2621f94048dd862512126fb", "best_bid": "0", "best_ask": "0.049"}, {"asset_id": "12775633294453699059014727298399105802336328278612201057647301831500756764380", "price": "0.978", "size": "0", "side": "BUY", "hash": "c875ae68eb583655ede4b64019808020cc6c4f12", "best_bid": "0.951", "best_ask": "1"}], "timestamp": "1769384079961", "event_type": "price_change"}}
{"_local_timestamp": "2026-01-25T23:34:40.601114+00:00", "data": {"market": "0x576804ee9df3fb32ac1fe25764c84fdf2a6eb28b4fe66a9801460f44ecb98bc5", "price_changes": [{"asset_id": "75377239927867306094237568544414168929541339145556678680059452627231461835789", "price": "0.021", "size": "10", "side": "SELL", "hash": "7a74090516a19e891f8f7826f38a906dad77e918", "best_bid": "0", "best_ask": "0.021"}, {"asset_id": "12775633294453699059014727298399105802336328278612201057647301831500756764380", "price": "0.979", "size": "10", "side": "BUY", "hash": "fcb46bad42acdadab226d4a4393dc6d17f6a0f7d", "best_bid": "0.979", "best_ask": "1"}], "timestamp": "1769384080415", "event_type": "price_change"}}
{"_local_timestamp": "2026-01-25T23:35:03.275435+00:00", "data": {"market": "0x576804ee9df3fb32ac1fe25764c84fdf2a6eb28b4fe66a9801460f44ecb98bc5", "price_changes": [{"asset_id": "75377239927867306094237568544414168929541339145556678680059452627231461835789", "price": "0.021", "size": "0", "side": "SELL", "hash": "6024aba1a8f7f4001470285ad03c041daa7a1dbb", "best_bid": "0", "best_ask": "0.049"}, {"asset_id": "12775633294453699059014727298399105802336328278612201057647301831500756764380", "price": "0.979", "size": "0", "side": "BUY", "hash": "7c098a655c611d17631648750113f58be25b22e7", "best_bid": "0.951", "best_ask": "1"}], "timestamp": "1769384103196", "event_type": "price_change"}}
{"_local_timestamp": "2026-01-25T23:35:03.685223+00:00", "data": {"market": "0x576804ee9df3fb32ac1fe25764c84fdf2a6eb28b4fe66a9801460f44ecb98bc5", "price_changes": [{"asset_id": "75377239927867306094237568544414168929541339145556678680059452627231461835789", "price": "0.02", "size": "10", "side": "SELL", "hash": "1f5fe49e63c71995379e1d9d0e6c72ea16de1171", "best_bid": "0", "best_ask": "0.02"}, {"asset_id": "12775633294453699059014727298399105802336328278612201057647301831500756764380", "price": "0.98", "size": "10", "side": "BUY", "hash": "d8d46fe39250ae95e051f35b8c8ab35c2f911003", "best_bid": "0.98", "best_ask": "1"}], "timestamp": "1769384103613", "event_type": "price_change"}}
{"_local_timestamp": "2026-01-25T23:35:25.399646+00:00", "data": {"market": "0x576804ee9df3fb32ac1fe25764c84fdf2a6eb28b4fe66a9801460f44ecb98bc5", "price_changes": [{"asset_id": "75377239927867306094237568544414168929541339145556678680059452627231461835789", "price": "0.02", "size": "0", "side": "SELL", "hash": "56e01581749847d0e67e6cd5f6c84def60ce4f2e", "best_bid": "0", "best_ask": "0.049"}, {"asset_id": "12775633294453699059014727298399105802336328278612201057647301831500756764380", "price": "0.98", "size": "0", "side": "BUY", "hash": "9150efded828298ec5e284621f2f28c7a47a118a", "best_bid": "0.951", "best_ask": "1"}], "timestamp": "1769384125333", "event_type": "price_change"}}
{"_local_timestamp": "2026-01-25T23:35:25.847072+00:00", "data": {"market": "0x576804ee9df3fb32ac1fe25764c84fdf2a6eb28b4fe66a9801460f44ecb98bc5", "price_changes": [{"asset_id": "75377239927867306094237568544414168929541339145556678680059452627231461835789", "price": "0.019", "size": "10", "side": "SELL", "hash": "08b4966b9d3fbdd7e057ab1d5295d8bc33ccdd39", "best_bid": "0", "best_ask": "0.019"}, {"asset_id": "12775633294453699059014727298399105802336328278612201057647301831500756764380", "price": "0.981", "size": "10", "side": "BUY", "hash": "70c8eee8c4ff0885dd8e909168f6c2a9a888917f", "best_bid": "0.981", "best_ask": "1"}], "timestamp": "1769384125777", "event_type": "price_change"}}
{"_local_timestamp": "2026-01-25T23:35:48.463178+00:00", "data": {"market": "0x576804ee9df3fb32ac1fe25764c84fdf2a6eb28b4fe66a9801460f44ecb98bc5", "price_changes": [{"asset_id": "75377239927867306094237568544414168929541339145556678680059452627231461835789", "price": "0.019", "size": "0", "side": "SELL", "hash": "883247a70e9590c492fd59a1e0e0af4c95dc749e", "best_bid": "0", "best_ask": "0.049"}, {"asset_id": "12775633294453699059014727298399105802336328278612201057647301831500756764380", "price": "0.981", "size": "0", "side": "BUY", "hash": "07d0e5c576b98ef17490a934aa6435ac26f3fd2f", "best_bid": "0.951", "best_ask": "1"}], "timestamp": "1769384148398", "event_type": "price_change"}}
{"_local_timestamp": "2026-01-25T23:35:48.942708+00:00", "data": {"market": "0x576804ee9df3fb32ac1fe25764c84fdf2a6eb28b4fe66a9801460f44ecb98bc5", "price_changes": [{"asset_id": "75377239927867306094237568544414168929541339145556678680059452627231461835789", "price": "0.018", "size": "10", "side": "SELL", "hash": "c858953c535b3b5574ab9749a8748126d353bc26", "best_bid": "0", "best_ask": "0.018"}, {"asset_id": "12775633294453699059014727298399105802336328278612201057647301831500756764380", "price": "0.982", "size": "10", "side": "BUY", "hash": "73f32a86823274dd5cbdc4299ae0d955d492d626", "best_bid": "0.982", "best_ask": "1"}], "timestamp": "1769384148870", "event_type": "price_change"}}
{"_local_timestamp": "2026-01-25T23:36:12.778572+00:00", "data": {"market": "0x576804ee9df3fb32ac1fe25764c84fdf2a6eb28b4fe66a9801460f44ecb98bc5", "price_changes": [{"asset_id": "12775633294453699059014727298399105802336328278612201057647301831500756764380", "price": "0.001", "size": "105.26", "side": "BUY", "hash": "501add0feed102400ff22256fcd3d0da0b9f636e", "best_bid": "0.982", "best_ask": "1"}, {"asset_id": "75377239927867306094237568544414168929541339145556678680059452627231461835789", "price": "0.999", "size": "105.26", "side": "SELL", "hash": "016fb66139b18f12378433a052ebc342190de388", "best_bid": "0", "best_ask": "0.018"}], "timestamp": "1769384172715", "event_type": "price_change"}}
{"_local_timestamp": "2026-01-25T23:36:12.782813+00:00", "data": {"market": "0x576804ee9df3fb32ac1fe25764c84fdf2a6eb28b4fe66a9801460f44ecb98bc5", "price_changes": [{"asset_id": "12775633294453699059014727298399105802336328278612201057647301831500756764380", "price": "0.021", "size": "12.12", "side": "BUY", "hash": "eaa0167b720d36bad61b300b78a8d9025bfa5421", "best_bid": "0.982", "best_ask": "1"}, {"asset_id": "75377239927867306094237568544414168929541339145556678680059452627231461835789", "price": "0.979", "size": "12.12", "side": "SELL", "hash": "f34c01b628088650fc9310a4a439d06044bbbce7", "best_bid": "0", "best_ask": "0.018"}], "timestamp": "1769384172716", "event_type": "price_change"}}
{"_local_timestamp": "2026-01-25T23:36:12.783718+00:00", "data": {"market": "0x576804ee9df3fb32ac1fe25764c84fdf2a6eb28b4fe66a9801460f44ecb98bc5", "price_changes": [{"asset_id": "12775633294453699059014727298399105802336328278612201057647301831500756764380", "price": "0.081", "size": "7.9", "side": "BUY", "hash": "9c58c2b9e65196b62facf754cee414f366358e5d", "best_bid": "0.982", "best_ask": "1"}, {"asset_id": "75377239927867306094237568544414168929541339145556678680059452627231461835789", "price": "0.919", "size": "7.9", "side": "SELL", "hash": "78311fa4894baf0a31f0f39c9dd047eb4946f6a5", "best_bid": "0", "best_ask": "0.018"}], "timestamp": "1769384172717", "event_type": "price_change"}}
{"_local_timestamp": "2026-01-25T23:36:13.603563+00:00", "data": {"market": "0x576804ee9df3fb32ac1fe25764c84fdf2a6eb28b4fe66a9801460f44ecb98bc5", "price_changes": [{"asset_id": "75377239927867306094237568544414168929541339145556678680059452627231461835789", "price": "0.018", "size": "0", "side": "SELL", "hash": "98a6fb298db68229f1ebefdda46889b354ca1498", "best_bid": "0", "best_ask": "0.049"}, {"asset_id": "12775633294453699059014727298399105802336328278612201057647301831500756764380", "price": "0.982", "size": "0", "side": "BUY", "hash": "1226e95915dfe190a6ae4aebfd41c1486dbd82d8", "best_bid": "0.951", "best_ask": "1"}], "timestamp": "1769384173534", "event_type": "price_change"}}
{"_local_timestamp": "2026-01-25T23:36:14.048181+00:00", "data": {"market": "0x576804ee9df3fb32ac1fe25764c84fdf2a6eb28b4fe66a9801460f44ecb98bc5", "price_changes": [{"asset_id": "75377239927867306094237568544414168929541339145556678680059452627231461835789", "price": "0.017", "size": "10", "side": "SELL", "hash": "da9003ede0d9fed4450228126f194199477e58e0", "best_bid": "0", "best_ask": "0.017"}, {"asset_id": "12775633294453699059014727298399105802336328278612201057647301831500756764380", "price": "0.983", "size": "10", "side": "BUY", "hash": "a17c2270e15e54e0f3368740dc90abf26eb7be60", "best_bid": "0.983", "best_ask": "1"}], "timestamp": "1769384173972", "event_type": "price_change"}}
{"_local_timestamp": "2026-01-25T23:36:34.411541+00:00", "data": {"market": "0x576804ee9df3fb32ac1fe25764c84fdf2a6eb28b4fe66a9801460f44ecb98bc5", "price_changes": [{"asset_id": "75377239927867306094237568544414168929541339145556678680059452627231461835789", "price": "0.017", "size": "0", "side": "SELL", "hash": "065d0e7dcd4f0d7fa290274b7b9267772f60cfb0", "best_bid": "0", "best_ask": "0.049"}, {"asset_id": "12775633294453699059014727298399105802336328278612201057647301831500756764380", "price": "0.983", "size": "0", "side": "BUY", "hash": "2f7dd1d81c219a287bdb42d9329d002ce111bb21", "best_bid": "0.951", "best_ask": "1"}], "timestamp": "1769384194344", "event_type": "price_change"}}
{"_local_timestamp": "2026-01-25T23:36:34.866448+00:00", "data": {"market": "0x576804ee9df3fb32ac1fe25764c84fdf2a6eb28b4fe66a9801460f44ecb98bc5", "price_changes": [{"asset_id": "75377239927867306094237568544414168929541339145556678680059452627231461835789", "price": "0.016", "size": "10", "side": "SELL", "hash": "0b74e53e14b16e70bbb4849a4f6e2499a776cae7", "best_bid": "0", "best_ask": "0.016"}, {"asset_id": "12775633294453699059014727298399105802336328278612201057647301831500756764380", "price": "0.984", "size": "10", "side": "BUY", "hash": "578c40b5d35ff4154412b10ec0a71c7711661323", "best_bid": "0.984", "best_ask": "1"}], "timestamp": "1769384194796", "event_type": "price_change"}}
{"_local_timestamp": "2026-01-25T23:36:59.033808+00:00", "data": {"market": "0x576804ee9df3fb32ac1fe25764c84fdf2a6eb28b4fe66a9801460f44ecb98bc5", "price_changes": [{"asset_id": "75377239927867306094237568544414168929541339145556678680059452627231461835789", "price": "0.016", "size": "0", "side": "SELL", "hash": "1b350fbe6c5f7c53a6b0030170d6d442d522b43b", "best_bid": "0", "best_ask": "0.049"}, {"asset_id": "12775633294453699059014727298399105802336328278612201057647301831500756764380", "price": "0.984", "size": "0", "side": "BUY", "hash": "11a46166a3a5a5dfde9bbc400e2b7dab9f8c8b75", "best_bid": "0.951", "best_ask": "1"}], "timestamp": "1769384218803", "event_type": "price_change"}}
{"_local_timestamp": "2026-01-25T23:36:59.293180+00:00", "data": {"market": "0x576804ee9df3fb32ac1fe25764c84fdf2a6eb28b4fe66a9801460f44ecb98bc5", "price_changes": [{"asset_id": "75377239927867306094237568544414168929541339145556678680059452627231461835789", "price": "0.015", "size": "10", "side": "SELL", "hash": "48cfab8837d5238d7f610a4aa87d35e7deec15df", "best_bid": "0", "best_ask": "0.015"}, {"asset_id": "12775633294453699059014727298399105802336328278612201057647301831500756764380", "price": "0.985", "size": "10", "side": "BUY", "hash": "c35d00a904d19361fc5e6f97f8b93695f33e84d6", "best_bid": "0.985", "best_ask": "1"}], "timestamp": "1769384219215", "event_type": "price_change"}}
{"_local_timestamp": "2026-01-25T23:37:22.986590+00:00", "data": {"market": "0x576804ee9df3fb32ac1fe25764c84fdf2a6eb28b4fe66a9801460f44ecb98bc5", "price_changes": [{"asset_id": "75377239927867306094237568544414168929541339145556678680059452627231461835789", "price": "0.015", "size": "0", "side": "SELL", "hash": "e849644e41f63b654bcd02e8e8c8b078b5d98ad6", "best_bid": "0", "best_ask": "0.049"}, {"asset_id": "12775633294453699059014727298399105802336328278612201057647301831500756764380", "price": "0.985", "size": "0", "side": "BUY", "hash": "7084749d7fab164e7ed6d80d3abba816bfeabac8", "best_bid": "0.951", "best_ask": "1"}], "timestamp": "1769384242918", "event_type": "price_change"}}
{"_local_timestamp": "2026-01-25T23:37:23.475510+00:00", "data": {"market": "0x576804ee9df3fb32ac1fe25764c84fdf2a6eb28b4fe66a9801460f44ecb98bc5", "price_changes": [{"asset_id": "75377239927867306094237568544414168929541339145556678680059452627231461835789", "price": "0.014", "size": "10", "side": "SELL", "hash": "e2675a30e16625115ad039e60cbd88fe175535e2", "best_bid": "0", "best_ask": "0.014"}, {"asset_id": "12775633294453699059014727298399105802336328278612201057647301831500756764380", "price": "0.986", "size": "10", "side": "BUY", "hash": "d64658f930fe23968236910aed948896bc953fbb", "best_bid": "0.986", "best_ask": "1"}], "timestamp": "1769384243399", "event_type": "price_change"}}
{"_local_timestamp": "2026-01-25T23:37:45.135580+00:00", "data": {"market": "0x576804ee9df3fb32ac1fe25764c84fdf2a6eb28b4fe66a9801460f44ecb98bc5", "price_changes": [{"asset_id": "75377239927867306094237568544414168929541339145556678680059452627231461835789", "price": "0.014", "size": "0", "side": "SELL", "hash": "e3ce3e012ff403dfd92e003209067caee300b899", "best_bid": "0", "best_ask": "0.049"}, {"asset_id": "12775633294453699059014727298399105802336328278612201057647301831500756764380", "price": "0.986", "size": "0", "side": "BUY", "hash": "9638ab7d299403a9d6d035a8194a80c2c4271f06", "best_bid": "0.951", "best_ask": "1"}], "timestamp": "1769384265049", "event_type": "price_change"}}
{"_local_timestamp": "2026-01-25T23:37:45.557798+00:00", "data": {"market": "0x576804ee9df3fb32ac1fe25764c84fdf2a6eb28b4fe66a9801460f44ecb98bc5", "price_changes": [{"asset_id": "75377239927867306094237568544414168929541339145556678680059452627231461835789", "price": "0.013", "size": "10", "side": "SELL", "hash": "8d845ca04be9c3664d1d946189832b2ec1d116b9", "best_bid": "0", "best_ask": "0.013"}, {"asset_id": "12775633294453699059014727298399105802336328278612201057647301831500756764380", "price": "0.987", "size": "10", "side": "BUY", "hash": "93fd2187372559ce2eb22f2e31f62de11f6a2b99", "best_bid": "0.987", "best_ask": "1"}], "timestamp": "1769384265475", "event_type": "price_change"}}
{"_local_timestamp": "2026-01-25T23:38:06.898633+00:00", "data": {"market": "0x576804ee9df3fb32ac1fe25764c84fdf2a6eb28b4fe66a9801460f44ecb98bc5", "price_changes": [{"asset_id": "75377239927867306094237568544414168929541339145556678680059452627231461835789", "price": "0.013", "size": "0", "side": "SELL", "hash": "d80c322540720c0864fe595226f963e8bd46db2a", "best_bid": "0", "best_ask": "0.049"}, {"asset_id": "12775633294453699059014727298399105802336328278612201057647301831500756764380", "price": "0.987", "size": "0", "side": "BUY", "hash": "de6a07e1c20fabd8679735f1bd43dcde30c53962", "best_bid": "0.951", "best_ask": "1"}], "timestamp": "1769384286826", "event_type": "price_change"}}
{"_local_timestamp": "2026-01-25T23:38:07.311858+00:00", "data": {"market": "0x576804ee9df3fb32ac1fe25764c84fdf2a6eb28b4fe66a9801460f44ecb98bc5", "price_changes": [{"asset_id": "75377239927867306094237568544414168929541339145556678680059452627231461835789", "price": "0.012", "size": "10", "side": "SELL", "hash": "b863999d2f7e2815bbe3dc7c1199ec3d66377386", "best_bid": "0", "best_ask": "0.012"}, {"asset_id": "12775633294453699059014727298399105802336328278612201057647301831500756764380", "price": "0.988", "size": "10", "side": "BUY", "hash": "fec2cf95adcd6cdc880504d487abc91227e5f5f2", "best_bid": "0.988", "best_ask": "1"}], "timestamp": "1769384287238", "event_type": "price_change"}}
{"_local_timestamp": "2026-01-25T23:38:27.831974+00:00", "data": {"market": "0x576804ee9df3fb32ac1fe25764c84fdf2a6eb28b4fe66a9801460f44ecb98bc5", "price_changes": [{"asset_id": "75377239927867306094237568544414168929541339145556678680059452627231461835789", "price": "0.012", "size": "0", "side": "SELL", "hash": "902cf3b4a542388e1186ce3c1beb222a129051fd", "best_bid": "0", "best_ask": "0.049"}, {"asset_id": "12775633294453699059014727298399105802336328278612201057647301831500756764380", "price": "0.988", "size": "0", "side": "BUY", "hash": "a9fa7d57791e777d85d2563988be18d5078ddf9a", "best_bid": "0.951", "best_ask": "1"}], "timestamp": "1769384307762", "event_type": "price_change"}}
{"_local_timestamp": "2026-01-25T23:38:28.239692+00:00", "data": {"market": "0x576804ee9df3fb32ac1fe25764c84fdf2a6eb28b4fe66a9801460f44ecb98bc5", "price_changes": [{"asset_id": "75377239927867306094237568544414168929541339145556678680059452627231461835789", "price": "0.999", "size": "115.26", "side": "SELL", "hash": "c8fac0c7b6c7fda6c44f4124f5de2d112c1c9bce", "best_bid": "0", "best_ask": "0.049"}, {"asset_id": "12775633294453699059014727298399105802336328278612201057647301831500756764380", "price": "0.001", "size": "115.26", "side": "BUY", "hash": "cb55064c05a0bb08f2e4f6eb02984e0ef5405f5f", "best_bid": "0.951", "best_ask": "1"}], "timestamp": "1769384308168", "event_type": "price_change"}}
{"_local_timestamp": "2026-01-25T23:38:51.306421+00:00", "data": {"market": "0x576804ee9df3fb32ac1fe25764c84fdf2a6eb28b4fe66a9801460f44ecb98bc5", "price_changes": [{"asset_id": "75377239927867306094237568544414168929541339145556678680059452627231461835789", "price": "0.999", "size": "105.26", "side": "SELL", "hash": "a2c313edfeabf55743697512d9a2c6651c84c410", "best_bid": "0", "best_ask": "0.049"}, {"asset_id": "12775633294453699059014727298399105802336328278612201057647301831500756764380", "price": "0.001", "size": "105.26", "side": "BUY", "hash": "611ee91ff3ed930f4c2c46d522a08bd8e5d2ad25", "best_bid": "0.951", "best_ask": "1"}], "timestamp": "1769384331231", "event_type": "price_change"}}
{"_local_timestamp": "2026-01-25T23:38:51.796541+00:00", "data": {"market": "0x576804ee9df3fb32ac1fe25764c84fdf2a6eb28b4fe66a9801460f44ecb98bc5", "price_changes": [{"asset_id": "75377239927867306094237568544414168929541339145556678680059452627231461835789", "price": "0.048", "size": "10", "side": "SELL", "hash": "2d266101b2e253ada3033d98ee3946cc4daa6f47", "best_bid": "0", "best_ask": "0.048"}, {"asset_id": "12775633294453699059014727298399105802336328278612201057647301831500756764380", "price": "0.952", "size": "10", "side": "BUY", "hash": "f9bd9d6ed624f5d1f25aa1874409445f600d98d1", "best_bid": "0.952", "best_ask": "1"}], "timestamp": "1769384331712", "event_type": "price_change"}}
{"_local_timestamp": "2026-01-25T23:39:12.850117+00:00", "data": {"market": "0x576804ee9df3fb32ac1fe25764c84fdf2a6eb28b4fe66a9801460f44ecb98bc5", "price_changes": [{"asset_id": "75377239927867306094237568544414168929541339145556678680059452627231461835789", "price": "0.048", "size": "0", "side": "SELL", "hash": "e528c7784ad0fe09b6966195d3ded19579626bdd", "best_bid": "0", "best_ask": "0.049"}, {"asset_id": "12775633294453699059014727298399105802336328278612201057647301831500756764380", "price": "0.952", "size": "0", "side": "BUY", "hash": "6caa6d3dfa7c5457b69c0e33310744354cb09505", "best_bid": "0.951", "best_ask": "1"}], "timestamp": "1769384352777", "event_type": "price_change"}}
{"_local_timestamp": "2026-01-25T23:39:13.284330+00:00", "data": {"market": "0x576804ee9df3fb32ac1fe25764c84fdf2a6eb28b4fe66a9801460f44ecb98bc5", "price_changes": [{"asset_id": "75377239927867306094237568544414168929541339145556678680059452627231461835789", "price": "0.047", "size": "10", "side": "SELL", "hash": "a41596dd8e52d30fac4eae9fe71796414e3cc1dc", "best_bid": "0", "best_ask": "0.047"}, {"asset_id": "12775633294453699059014727298399105802336328278612201057647301831500756764380", "price": "0.953", "size": "10", "side": "BUY", "hash": "3c4ea345a3b3b35c605fa98c00fe579564c78565", "best_bid": "0.953", "best_ask": "1"}], "timestamp": "1769384353219", "event_type": "price_change"}}
{"_local_timestamp": "2026-01-25T23:39:31.988642+00:00", "data": {"market": "0x576804ee9df3fb32ac1fe25764c84fdf2a6eb28b4fe66a9801460f44ecb98bc5", "price_changes": [{"asset_id": "75377239927867306094237568544414168929541339145556678680059452627231461835789", "price": "0.047", "size": "0", "side": "SELL", "hash": "bd0a50d7adaee5fcd521219659ead1de92616e72", "best_bid": "0", "best_ask": "0.049"}, {"asset_id": "12775633294453699059014727298399105802336328278612201057647301831500756764380", "price": "0.953", "size": "0", "side": "BUY", "hash": "499521916dbe9aaf7ecee6bba8c923761f41e773", "best_bid": "0.951", "best_ask": "1"}], "timestamp": "1769384371909", "event_type": "price_change"}}
{"_local_timestamp": "2026-01-25T23:39:32.418168+00:00", "data": {"market": "0x576804ee9df3fb32ac1fe25764c84fdf2a6eb28b4fe66a9801460f44ecb98bc5", "price_changes": [{"asset_id": "75377239927867306094237568544414168929541339145556678680059452627231461835789", "price": "0.046", "size": "10", "side": "SELL", "hash": "0caa9266c15b0cc29438adb144618957caf74da6", "best_bid": "0", "best_ask": "0.046"}, {"asset_id": "12775633294453699059014727298399105802336328278612201057647301831500756764380", "price": "0.954", "size": "10", "side": "BUY", "hash": "b12240363b891573430e0b07bc3fa16170009c03", "best_bid": "0.954", "best_ask": "1"}], "timestamp": "1769384372343", "event_type": "price_change"}}
{"_local_timestamp": "2026-01-25T23:39:54.637735+00:00", "data": {"market": "0x576804ee9df3fb32ac1fe25764c84fdf2a6eb28b4fe66a9801460f44ecb98bc5", "price_changes": [{"asset_id": "75377239927867306094237568544414168929541339145556678680059452627231461835789", "price": "0.046", "size": "0", "side": "SELL", "hash": "ab573a5ee8fceed42e0d10e2d4f5d169903e8ff4", "best_bid": "0", "best_ask": "0.049"}, {"asset_id": "12775633294453699059014727298399105802336328278612201057647301831500756764380", "price": "0.954", "size": "0", "side": "BUY", "hash": "649c8947a96f622719b4ee188941f5125a9feab2", "best_bid": "0.951", "best_ask": "1"}], "timestamp": "1769384394568", "event_type": "price_change"}}
{"_local_timestamp": "2026-01-25T23:39:55.194605+00:00", "data": {"market": "0x576804ee9df3fb32ac1fe25764c84fdf2a6eb28b4fe66a9801460f44ecb98bc5", "price_changes": [{"asset_id": "75377239927867306094237568544414168929541339145556678680059452627231461835789", "price": "0.045", "size": "10", "side": "SELL", "hash": "de2533dcdb4e30e7f8af11239f7de7529a8296bd", "best_bid": "0", "best_ask": "0.045"}, {"asset_id": "12775633294453699059014727298399105802336328278612201057647301831500756764380", "price": "0.955", "size": "10", "side": "BUY", "hash": "f36b42bc1a736d9a6a1db0c493bfb0fa6832a034", "best_bid": "0.955", "best_ask": "1"}], "timestamp": "1769384395123", "event_type": "price_change"}}
