{"_local_timestamp": "2026-01-25T23:33:35.657087+00:00", "data": [{"market": "0xca76faf001d267c0fc809c1f39b801f95e2bcb45ebc6f5ba489630c0acd05059", "asset_id": "22883281051100193685236025657268856534873448228400701464864171575150378577088", "timestamp": "1769384012751", "hash": "97eb06e0ebac9caf1484f6b94123f31cc367402e", "bids": [{"price": "0.001", "size": "100049"}, {"price": "0.002", "size": "55000"}, {"price": "0.008", "size": "155"}, {"price": "0.01", "size": "27048"}, {"price": "0.011", "size": "55710"}, {"price": "0.08", "size": "155"}, {"price": "0.097", "size": "100"}, {"price": "0.099", "size": "100"}, {"price": "0.1", "size": "3500"}, {"price": "0.101", "size": "10000"}, {"price": "0.47", "size": "100"}, {"price": "0.49", "size": "100"}, {"price": "0.497", "size": "200"}, {"price": "0.499", "size": "100"}, {"price": "0.5", "size": "176"}, {"price": "0.75", "size": "60"}, {"price": "0.767", "size": "60"}, {"price": "0.768", "size": "777"}, {"price": "0.769", "size": "60"}, {"price": "0.77", "size": "60"}, {"price": "0.771", "size": "53"}, {"price": "0.772", "size": "19.68"}, {"price": "0.773", "size": "5.32"}, {"price": "0.991", "size": "500"}, {"price": "0.999", "size": "113303"}], "asks": [], "event_type": "book", "last_trade_price": ""}, {"market": "0xca76faf001d267c0fc809c1f39b801f95e2bcb45ebc6f5ba489630c0acd05059", "asset_id": "18066679137160239835833186135441870746243656504791377368093305126991522725800", "timestamp": "1769384012751", "hash": "61e4ab0d71855ab8210f37b1e88700a702f32d98", "bids": [], "asks": [{"price": "0.999", "size": "100049"}, {"price": "0.998", "size": "55000"}, {"price": "0.992", "size": "155"}, {"price": "0.99", "size": "27048"}, {"price": "0.989", "size": "55710"}, {"price": "0.92", "size": "155"}, {"price": "0.903", "size": "100"}, {"price": "0.901", "size": "100"}, {"price": "0.9", "size": "3500"}, {"price": "0.899", "size": "10000"}, {"price": "0.53", "size": "100"}, {"price": "0.51", "size": "100"}, {"price": "0.503", "size": "200"}, {"price": "0.501", "size": "100"}, {"price": "0.5", "size": "176"}, {"price": "0.25", "size": "60"}, {"price": "0.233", "size": "60"}, {"price": "0.232", "size": "777"}, {"price": "0.231", "size": "60"}, {"price": "0.23", "size": "60"}, {"price": "0.229", "size": "53"}, {"price": "0.228", "size": "19.68"}, {"price": "0.227", "size": "5.32"}, {"price": "0.009", "size": "500"}, {"price": "0.001", "size": "113303"}], "event_type": "book", "last_trade_price": ""}]}
{"_local_timestamp": "2026-01-25T23:33:45.903816+00:00", "data": {"market": "0xca76faf001d267c0fc809c1f39b801f95e2bcb45ebc6f5ba489630c0acd05059", "price_changes": [{"asset_id": "22883281051100193685236025657268856534873448228400701464864171575150378577088", "price": "0.999", "size": "100005", "side": "BUY", "hash": "48f8ada0d1a61688d8f909b189e4ef10e66c0a26", "best_bid": "0.999", "best_ask": "1"}, {"asset_id": "18066679137160239835833186135441870746243656504791377368093305126991522725800", "price": "0.001", "size": "100005", "side": "SELL", "hash": "108080cbc7f1ef21cad8b28bf232d5d3ff0ffb71", "best_bid": "0", "best_ask": "0.001"}], "timestamp": "1769384025812", "event_type": "price_change"}}
{"_local_timestamp": "2026-01-25T23:33:47.575758+00:00", "data": {"market": "0xca76faf001d267c0fc809c1f39b801f95e2bcb45ebc6f5ba489630c0acd05059", "price_changes": [{"asset_id": "22883281051100193685236025657268856534873448228400701464864171575150378577088", "price": "0.999", "size": "102502", "side": "BUY", "hash": "e50a89b8b08329470d6071c953e42140fbd275fb", "best_bid": "0.999", "best_ask": "1"}, {"asset_id": "18066679137160239835833186135441870746243656504791377368093305126991522725800", "price": "0.001", "size": "102502", "side": "SELL", "hash": "a42756fbf896668e2fa59f93dd3ee6506e0a5951", "best_bid": "0", "best_ask": "0.001"}], "timestamp": "1769384027504", "event_type": "price_change"}}
{"_local_timestamp": "2026-01-25T23:33:47.995469+00:00", "data": {"market": "0xca76faf001d267c0fc809c1f39b801f95e2bcb45ebc6f5ba489630c0acd05059", "price_changes": [{"asset_id": "22883281051100193685236025657268856534873448228400701464864171575150378577088", "price": "0.999", "size": "104998", "side": "BUY", "hash": "bdece70e969e744e00c30416fed6ba0ccc028661", "best_bid": "0.999", "best_ask": "1"}, {"asset_id": "18066679137160239835833186135441870746243656504791377368093305126991522725800", "price": "0.001", "size": "104998", "side": "SELL", "hash": "714bf2821963e5bc79983b2a85039d46e6d0efde", "best_bid": "0", "best_ask": "0.001"}], "timestamp": "1769384027913", "event_type": "price_change"}}
{"_local_timestamp": "2026-01-25T23:33:48.510945+00:00", "data": {"market": "0xca76faf001d267c0fc809c1f39b801f95e2bcb45ebc6f5ba489630c0acd05059", "price_changes": [{"asset_id": "22883281051100193685236025657268856534873448228400701464864171575150378577088", "price": "0.999", "size": "107493", "side": "BUY", "hash": "7eadf94d5b1e3c62b9b843cb093447437eccd56e", "best_bid": "0.999", "best_ask": "1"}, {"asset_id": "18066679137160239835833186135441870746243656504791377368093305126991522725800", "price": "0.001", "size": "107493", "side": "SELL", "hash": "c2340dd7ab7c28d206332491dad9b2142a91add0", "best_bid": "0", "best_ask": "0.001"}], "timestamp": "1769384028430", "event_type": "price_change"}}
{"_local_timestamp": "2026-01-25T23:33:49.327967+00:00", "data": {"market": "0xca76faf001d267c0fc809c1f39b801f95e2bcb45ebc6f5ba489630c0acd05059", "price_changes": [{"asset_id": "22883281051100193685236025657268856534873448228400701464864171575150378577088", "price": "0.999", "size": "108116", "side": "BUY", "hash": "f0bd74fd0ddcfed77b963825f6f34dc98ef9ea6a", "best_bid": "0.999", "best_ask": "1"}, {"asset_id": "18066679137160239835833186135441870746243656504791377368093305126991522725800", "price": "0.001", "size": "108116", "side": "SELL", "hash": "e8d345c509aa8ff5abc127d509f2c96b84601dda", "best_bid": "0", "best_ask": "0.001"}], "timestamp": "1769384029237", "event_type": "price_change"}}
{"_local_timestamp": "2026-01-25T23:33:49.807640+00:00", "data": {"market": "0xca76faf001d267c0fc809c1f39b801f95e2bcb45ebc6f5ba489630c0acd05059", "price_changes": [{"asset_id": "22883281051100193685236025657268856534873448228400701464864171575150378577088", "price": "0.999", "size": "108738", "side": "BUY", "hash": "c19ee710731c108adaf6d5636f02805b2e3c0fde", "best_bid": "0.999", "best_ask": "1"}, {"asset_id": "18066679137160239835833186135441870746243656504791377368093305126991522725800", "price": "0.001", "size": "108738", "side": "SELL", "hash": "dc433eaadd2a9b4609993935fd3df4012ca7b1d0", "best_bid": "0", "best_ask": "0.001"}], "timestamp": "1769384029724", "event_type": "price_change"}}
{"_local_timestamp": "2026-01-25T23:33:51.637083+00:00", "data": {"market": "0xca76faf001d267c0fc809c1f39b801f95e2bcb45ebc6f5ba489630c0acd05059", "price_changes": [{"asset_id": "22883281051100193685236025657268856534873448228400701464864171575150378577088", "price": "0.999", "size": "108893", "side": "BUY", "hash": "39021632033662b66062300be86c3f7f6c797af1", "best_bid": "0.999", "best_ask": "1"}, {"asset_id": "18066679137160239835833186135441870746243656504791377368093305126991522725800", "price": "0.001", "size": "108893", "side": "SELL", "hash": "84a1483f9d06f2693cbd9a30e0a5e2e5a6bd37f6", "best_bid": "0", "best_ask": "0.001"}], "timestamp": "1769384031552", "event_type": "price_change"}}
{"_local_timestamp": "2026-01-25T23:33:52.610695+00:00", "data": {"market": "0xca76faf001d267c0fc809c1f39b801f95e2bcb45ebc6f5ba489630c0acd05059", "price_changes": [{"asset_id": "22883281051100193685236025657268856534873448228400701464864171575150378577088", "price": "0.999", "size": "109047", "side": "BUY", "hash": "f1c3f6318874f0dc3a28b261f1ea4c235d416b55", "best_bid": "0.999", "best_ask": "1"}, {"asset_id": "18066679137160239835833186135441870746243656504791377368093305126991522725800", "price": "0.001", "size": "109047", "side": "SELL", "hash": "7d3995c1335c064c4cb0d5a8dcda4704559bbcb0", "best_bid": "0", "best_ask": "0.001"}], "timestamp": "1769384032533", "event_type": "price_change"}}
{"_local_timestamp": "2026-01-25T23:33:52.992087+00:00", "data": {"market": "0xca76faf001d267c0fc809c1f39b801f95e2bcb45ebc6f5ba489630c0acd05059", "price_changes": [{"asset_id": "22883281051100193685236025657268856534873448228400701464864171575150378577088", "price": "0.999", "size": "109200", "side": "BUY", "hash": "92e27d1eabe608ab1b7750c90cd30f39d8d57b34", "best_bid": "0.999", "best_ask": "1"}, {"asset_id": "18066679137160239835833186135441870746243656504791377368093305126991522725800", "price": "0.001", "size": "109200", "side": "SELL", "hash": "dab256e7e955122b475c0c578779e917cd8b18a5", "best_bid": "0", "best_ask": "0.001"}], "timestamp": "1769384032904", "event_type": "price_change"}}
{"_local_timestamp": "2026-01-25T23:33:54.556479+00:00", "data": {"market": "0xca76faf001d267c0fc809c1f39b801f95e2bcb45ebc6f5ba489630c0acd05059", "price_changes": [{"asset_id": "22883281051100193685236025657268856534873448228400701464864171575150378577088", "price": "0.999", "size": "109237", "side": "BUY", "hash": "8fa0ea894661c2749943b78fcaf18c702e51945b", "best_bid": "0.999", "best_ask": "1"}, {"asset_id": "18066679137160239835833186135441870746243656504791377368093305126991522725800", "price": "0.001", "size": "109237", "side": "SELL", "hash": "2484e316ed2e52bab866698368da7aa01ec82f06", "best_bid": "0", "best_ask": "0.001"}], "timestamp": "1769384034484", "event_type": "price_change"}}
{"_local_timestamp": "2026-01-25T23:33:55.236238+00:00", "data": {"market": "0xca76faf001d267c0fc809c1f39b801f95e2bcb45ebc6f5ba489630c0acd05059", "price_changes": [{"asset_id": "22883281051100193685236025657268856534873448228400701464864171575150378577088", "price": "0.999", "size": "109273", "side": "BUY", "hash": "3c881f3457972f27af1efb1a326c0e38c559d8f6", "best_bid": "0.999", "best_ask": "1"}, {"asset_id": "18066679137160239835833186135441870746243656504791377368093305126991522725800", "price": "0.001", "size": "109273", "side": "SELL", "hash": "e458d66201ec469690c0cb1062dda352f4765e08", "best_bid": "0", "best_ask": "0.001"}], "timestamp": "1769384035140", "event_type": "price_change"}}
{"_local_timestamp": "2026-01-25T23:33:55.631560+00:00", "data": {"market": "0xca76faf001d267c0fc809c1f39b801f95e2bcb45ebc6f5ba489630c0acd05059", "price_changes": [{"asset_id": "22883281051100193685236025657268856534873448228400701464864171575150378577088", "price": "0.999", "size": "109308", "side": "BUY", "hash": "4b89369245b9c323a4a3046b221022f43d7d03b7", "best_bid": "0.999", "best_ask": "1"}, {"asset_id": "18066679137160239835833186135441870746243656504791377368093305126991522725800", "price": "0.001", "size": "109308", "side": "SELL", "hash": "bcc105743dd38dfcf000ef8b0495fda06d78fb37", "best_bid": "0", "best_ask": "0.001"}], "timestamp": "1769384035536", "event_type": "price_change"}}
{"_local_timestamp": "2026-01-25T23:34:07.982471+00:00", "data": {"market": "0xca76faf001d267c0fc809c1f39b801f95e2bcb45ebc6f5ba489630c0acd05059", "price_changes": [{"asset_id": "22883281051100193685236025657268856534873448228400701464864171575150378577088", "price": "0.999", "size": "104998", "side": "BUY", "hash": "59e3789cba0cbb1f5d5c9ff0b99128bef6e5ee65", "best_bid": "0.999", "best_ask": "1"}, {"asset_id": "18066679137160239835833186135441870746243656504791377368093305126991522725800", "price": "0.001", "size": "104998", "side": "SELL", "hash": "178c56c395b0813bd4317360ba333b17f8c973f8", "best_bid": "0", "best_ask": "0.001"}], "timestamp": "1769384047889", "event_type": "price_change"}}
{"_local_timestamp": "2026-01-25T23:34:08.677036+00:00", "data": {"market": "0xca76faf001d267c0fc809c1f39b801f95e2bcb45ebc6f5ba489630c0acd05059", "price_changes": [{"asset_id": "22883281051100193685236025657268856534873448228400701464864171575150378577088", "price": "0.999", "size": "100005", "side": "BUY", "hash": "191c915b3a1d0806eb7bb98ee19a6d3839697095", "best_bid": "0.999", "best_ask": "1"}, {"asset_id": "18066679137160239835833186135441870746243656504791377368093305126991522725800", "price": "0.001", "size": "100005", "side": "SELL", "hash": "ea155d95809de05fa8e2ffd5f44cdb30bd79be05", "best_bid": "0", "best_ask": "0.001"}], "timestamp": "1769384048563", "event_type": "price_change"}}
{"_local_timestamp": "2026-01-25T23:34:09.284516+00:00", "data": {"market": "0xca76faf001d267c0fc809c1f39b801f95e2bcb45ebc6f5ba489630c0acd05059", "price_changes": [{"asset_id": "22883281051100193685236025657268856534873448228400701464864171575150378577088", "price": "0.999", "size": "90005", "side": "BUY", "hash": "695b308375225ff653c434fc96cba5907d0dd345", "best_bid": "0.999", "best_ask": "1"}, {"asset_id": "18066679137160239835833186135441870746243656504791377368093305126991522725800", "price": "0.001", "size": "90005", "side": "SELL", "hash": "c923ab3177b53db7acee03de01edacc41c1926a7", "best_bid": "0", "best_ask": "0.001"}], "timestamp": "1769384049208", "event_type": "price_change"}}
{"_local_timestamp": "2026-01-25T23:34:11.209777+00:00", "data": {"market": "0xca76faf001d267c0fc809c1f39b801f95e2bcb45ebc6f5ba489630c0acd05059", "price_changes": [{"asset_id": "22883281051100193685236025657268856534873448228400701464864171575150378577088", "price": "0.999", "size": "92505", "side": "BUY", "hash": "af574bcfc2c1907ec2306f60c07375b6b422e86f", "best_bid": "0.999", "best_ask": "1"}, {"asset_id": "18066679137160239835833186135441870746243656504791377368093305126991522725800", "price": "0.001", "size": "92505", "side": "SELL", "hash": "a10ae6b042b1c7a35220a812f886264529e67509", "best_bid": "0", "best_ask": "0.001"}], "timestamp": "1769384051120", "event_type": "price_change"}}
{"_local_timestamp": "2026-01-25T23:34:12.442746+00:00", "data": {"market": "0xca76faf001d267c0fc809c1f39b801f95e2bcb45ebc6f5ba489630c0acd05059", "price_changes": [{"asset_id": "22883281051100193685236025657268856534873448228400701464864171575150378577088", "price": "0.999", "size": "93129", "side": "BUY", "hash": "8a1e3b35dfc4495b60835fe35a659a2d53a810ae", "best_bid": "0.999", "best_ask": "1"}, {"asset_id": "18066679137160239835833186135441870746243656504791377368093305126991522725800", "price": "0.001", "size": "93129", "side": "SELL", "hash": "6f84a45a6a0252d183c3fa8e9df2fa46c5d98b49", "best_bid": "0", "best_ask": "0.001"}], "timestamp": "1769384052359", "event_type": "price_change"}}
{"_local_timestamp": "2026-01-25T23:34:13.574898+00:00", "data": {"market": "0xca76faf001d267c0fc809c1f39b801f95e2bcb45ebc6f5ba489630c0acd05059", "price_changes": [{"asset_id": "22883281051100193685236025657268856534873448228400701464864171575150378577088", "price": "0.999", "size": "93284", "side": "BUY", "hash": "b916b2143cf768660b6a5d7fa999bc8f09114296", "best_bid": "0.999", "best_ask": "1"}, {"asset_id": "18066679137160239835833186135441870746243656504791377368093305126991522725800", "price": "0.001", "size": "93284", "side": "SELL", "hash": "e9befcae4133a7059844d9e5c3cab78f92ce41b5", "best_bid": "0", "best_ask": "0.001"}], "timestamp": "1769384053419", "event_type": "price_change"}}
{"_local_timestamp": "2026-01-25T23:34:25.498166+00:00", "data": {"market": "0xca76faf001d267c0fc809c1f39b801f95e2bcb45ebc6f5ba489630c0acd05059", "price_changes": [{"asset_id": "22883281051100193685236025657268856534873448228400701464864171575150378577088", "price": "0.999", "size": "80005", "side": "BUY", "hash": "4301eb849773228d52ccde3f374746b6c3c3c9a7", "best_bid": "0.999", "best_ask": "1"}, {"asset_id": "18066679137160239835833186135441870746243656504791377368093305126991522725800", "price": "0.001", "size": "80005", "side": "SELL", "hash": "08283bce98987fec579fb898b56ef51d3341279e", "best_bid": "0", "best_ask": "0.001"}], "timestamp": "1769384065338", "event_type": "price_change"}}
{"_local_timestamp": "2026-01-25T23:34:26.284215+00:00", "data": {"market": "0xca76faf001d267c0fc809c1f39b801f95e2bcb45ebc6f5ba489630c0acd05059", "price_changes": [{"asset_id": "22883281051100193685236025657268856534873448228400701464864171575150378577088", "price": "0.999", "size": "80630", "side": "BUY", "hash": "025a449c56e34ec1aa128f3d8e63c1093379a9a0", "best_bid": "0.999", "best_ask": "1"}, {"asset_id": "18066679137160239835833186135441870746243656504791377368093305126991522725800", "price": "0.001", "size": "80630", "side": "SELL", "hash": "86a267a0111b61598ebb8c538a8e0facfcd97552", "best_bid": "0", "best_ask": "0.001"}], "timestamp": "1769384066210", "event_type": "price_change"}}
{"_local_timestamp": "2026-01-25T23:34:26.665064+00:00", "data": {"market": "0xca76faf001d267c0fc809c1f39b801f95e2bcb45ebc6f5ba489630c0acd05059", "price_changes": [{"asset_id": "22883281051100193685236025657268856534873448228400701464864171575150378577088", "price": "0.999", "size": "81254", "side": "BUY", "hash": "40cb28cc06b2684b0dfdf588a6161ab69f806d61", "best_bid": "0.999", "best_ask": "1"}, {"asset_id": "18066679137160239835833186135441870746243656504791377368093305126991522725800", "price": "0.001", "size": "81254", "side": "SELL", "hash": "0e89e6e3a75a75d90ba9b2ed505c2d28469fb4c2", "best_bid": "0", "best_ask": "0.001"}], "timestamp": "1769384066564", "event_type": "price_change"}}
{"_local_timestamp": "2026-01-25T23:34:27.921741+00:00", "data": {"market": "0xca76faf001d267c0fc809c1f39b801f95e2bcb45ebc6f5ba489630c0acd05059", "price_changes": [{"asset_id": "22883281051100193685236025657268856534873448228400701464864171575150378577088", "price": "0.999", "size": "81409", "side": "BUY", "hash": "2729b9114d9ece1b6a45b4476d545c5d6debc393", "best_bid": "0.999", "best_ask": "1"}, {"asset_id": "18066679137160239835833186135441870746243656504791377368093305126991522725800", "price": "0.001", "size": "81409", "side": "SELL", "hash": "88a415a042e74ebcc4cc6544a0ea9556c1aa210f", "best_bid": "0", "best_ask": "0.001"}], "timestamp": "1769384067743", "event_type": "price_change"}}
{"_local_timestamp": "2026-01-25T23:34:28.278162+00:00", "data": {"market": "0xca76faf001d267c0fc809c1f39b801f95e2bcb45ebc6f5ba489630c0acd05059", "price_changes": [{"asset_id": "22883281051100193685236025657268856534873448228400701464864171575150378577088", "price": "0.999", "size": "81563", "side": "BUY", "hash": "de8c6aa47e928f16c5afc3c9ecfd917d1d3c38c6", "best_bid": "0.999", "best_ask": "1"}, {"asset_id": "18066679137160239835833186135441870746243656504791377368093305126991522725800", "price": "0.001", "size": "81563", "side": "SELL", "hash": "8c800ac21b70335b3aab8fe4fa0c8e1cf816bf66", "best_bid": "0", "best_ask": "0.001"}], "timestamp": "1769384068179", "event_type": "price_change"}}
{"_local_timestamp": "2026-01-25T23:34:29.353271+00:00", "data": {"market": "0xca76faf001d267c0fc809c1f39b801f95e2bcb45ebc6f5ba489630c0acd05059", "price_changes": [{"asset_id": "22883281051100193685236025657268856534873448228400701464864171575150378577088", "price": "0.999", "size": "81716", "side": "BUY", "hash": "37387f80fac3e0a62e25455127dcacfd1bbf0e40", "best_bid": "0.999", "best_ask": "1"}, {"asset_id": "18066679137160239835833186135441870746243656504791377368093305126991522725800", "price": "0.001", "size": "81716", "side": "SELL", "hash": "3e6e0f7c22839a1f7119dc9e10c8cb3b0c6a78f4", "best_bid": "0", "best_ask": "0.001"}], "timestamp": "1769384069278", "event_type": "price_change"}}
{"_local_timestamp": "2026-01-25T23:34:29.780631+00:00", "data": {"market": "0xca76faf001d267c0fc809c1f39b801f95e2bcb45ebc6f5ba489630c0acd05059", "price_changes": [{"asset_id": "22883281051100193685236025657268856534873448228400701464864171575150378577088", "price": "0.999", "size": "81868", "side": "BUY", "hash": "576d0c5d14fa0bedb6bea3bff281fa744603fb45", "best_bid": "0.999", "best_ask": "1"}, {"asset_id": "18066679137160239835833186135441870746243656504791377368093305126991522725800", "price": "0.001", "size": "81868", "side": "SELL", "hash": "c61659ae4a9f0cc38101e76d96ed0dfefcd999ab", "best_bid": "0", "best_ask": "0.001"}], "timestamp": "1769384069641", "event_type": "price_change"}}
{"_local_timestamp": "2026-01-25T23:34:30.383001+00:00", "data": {"market": "0xca76faf001d267c0fc809c1f39b801f95e2bcb45ebc6f5ba489630c0acd05059", "price_changes": [{"asset_id": "22883281051100193685236025657268856534873448228400701464864171575150378577088", "price": "0.999", "size": "82019", "side": "BUY", "hash": "80745c984219f6944b4d8c104812cea9b7941626", "best_bid": "0.999", "best_ask": "1"}, {"asset_id": "18066679137160239835833186135441870746243656504791377368093305126991522725800", "price": "0.001", "size": "82019", "side": "SELL", "hash": "15e28c22469f990db680f03f4d5cf8598f29e42c", "best_bid": "0", "best_ask": "0.001"}], "timestamp": "1769384070204", "event_type": "price_change"}}
{"_local_timestamp": "2026-01-25T23:34:30.695259+00:00", "data": {"market": "0xca76faf001d267c0fc809c1f39b801f95e2bcb45ebc6f5ba489630c0acd05059", "price_changes": [{"asset_id": "22883281051100193685236025657268856534873448228400701464864171575150378577088", "price": "0.999", "size": "82056", "side": "BUY", "hash": "3727e59d9cc629bb06e1e61ef02f1e6522842234", "best_bid": "0.999", "best_ask": "1"}, {"asset_id": "18066679137160239835833186135441870746243656504791377368093305126991522725800", "price": "0.001", "size": "82056", "side": "SELL", "hash": "e3a77f61023ef9feaaaad1dad16d88aea3bd359f", "best_bid": "0", "best_ask": "0.001"}], "timestamp": "1769384070574", "event_type": "price_change"}}
{"_local_timestamp": "2026-01-25T23:34:31.006471+00:00", "data": {"market": "0xca76faf001d267c0fc809c1f39b801f95e2bcb45ebc6f5ba489630c0acd05059", "price_changes": [{"asset_id": "22883281051100193685236025657268856534873448228400701464864171575150378577088", "price": "0.999", "size": "82092", "side": "BUY", "hash": "9e64dcf9e4ae7f3ea5cd8b34955929e38836c29f", "best_bid": "0.999", "best_ask": "1"}, {"asset_id": "18066679137160239835833186135441870746243656504791377368093305126991522725800", "price": "0.001", "size": "82092", "side": "SELL", "hash": "83ed960ccd500675e8fcad1d5babdae4724500de", "best_bid": "0", "best_ask": "0.001"}], "timestamp": "1769384070923", "event_type": "price_change"}}
{"_local_timestamp": "2026-01-25T23:34:32.267163+00:00", "data": {"market": "0xca76faf001d267c0fc809c1f39b801f95e2bcb45ebc6f5ba489630c0acd05059", "price_changes": [{"asset_id": "22883281051100193685236025657268856534873448228400701464864171575150378577088", "price": "0.999", "size": "82127", "side": "BUY", "hash": "f964767ba7aea592e390ad41bedeb4bcb98c3836", "best_bid": "0.999", "best_ask": "1"}, {"asset_id": "18066679137160239835833186135441870746243656504791377368093305126991522725800", "price": "0.001", "size": "82127", "side": "SELL", "hash": "bc0a2eeb25e2a1ef114b4c290c55b7ebd9d3586b", "best_bid": "0", "best_ask": "0.001"}], "timestamp": "1769384072107", "event_type": "price_change"}}
{"_local_timestamp": "2026-01-25T23:34:32.678620+00:00", "data": {"market": "0xca76faf001d267c0fc809c1f39b801f95e2bcb45ebc6f5ba489630c0acd05059", "price_changes": [{"asset_id": "22883281051100193685236025657268856534873448228400701464864171575150378577088", "price": "0.999", "size": "82161", "side": "BUY", "hash": "3f9d3731984ce1c878c3393b714f910af4a43e26", "best_bid": "0.999", "best_ask": "1"}, {"asset_id": "18066679137160239835833186135441870746243656504791377368093305126991522725800", "price": "0.001", "size": "82161", "side": "SELL", "hash": "6fa15cb1abf87ed21eb87475690d1170667599fc", "best_bid": "0", "best_ask": "0.001"}], "timestamp": "1769384072583", "event_type": "price_change"}}
{"_local_timestamp": "2026-01-25T23:34:33.442939+00:00", "data": {"market": "0xca76faf001d267c0fc809c1f39b801f95e2bcb45ebc6f5ba489630c0acd05059", "price_changes": [{"asset_id": "22883281051100193685236025657268856534873448228400701464864171575150378577088", "price": "0.999", "size": "82194", "side": "BUY", "hash": "cc5fafc5972d0ca0626f97ad98687bc2abeb3598", "best_bid": "0.999", "best_ask": "1"}, {"asset_id": "18066679137160239835833186135441870746243656504791377368093305126991522725800", "price": "0.001", "size": "82194", "side": "SELL", "hash": "b28a3b6f2082837456e0df353bf40bacd02cb71f", "best_bid": "0", "best_ask": "0.001"}], "timestamp": "1769384073354", "event_type": "price_change"}}
{"_local_timestamp": "2026-01-25T23:34:36.158629+00:00", "data": {"market": "0xca76faf001d267c0fc809c1f39b801f95e2bcb45ebc6f5ba489630c0acd05059", "price_changes": [{"asset_id": "22883281051100193685236025657268856534873448228400701464864171575150378577088", "price": "0.999", "size": "84694", "side": "BUY", "hash": "d773f30d50cf683ad74ab25a9aed0cbc6db774ac", "best_bid": "0.999", "best_ask": "1"}, {"asset_id": "18066679137160239835833186135441870746243656504791377368093305126991522725800", "price": "0.001", "size": "84694", "side": "SELL", "hash": "1f782e20c759a5c30ee8eb0cd0936538edade507", "best_bid": "0", "best_ask": "0.001"}], "timestamp": "1769384076057", "event_type": "price_change"}}
{"_local_timestamp": "2026-01-25T23:34:38.531463+00:00", "data": {"market": "0xca76faf001d267c0fc809c1f39b801f95e2bcb45ebc6f5ba489630c0acd05059", "price_changes": [{"asset_id": "22883281051100193685236025657268856534873448228400701464864171575150378577088", "price": "0.999", "size": "84849", "side": "BUY", "hash": "7bce3d81f48ebf39cd74ada1417645ea31b0c881", "best_bid": "0.999", "best_ask": "1"}, {"asset_id": "18066679137160239835833186135441870746243656504791377368093305126991522725800", "price": "0.001", "size": "84849", "side": "SELL", "hash": "65e75b086d79728c5232e71faf62a9b68c9b1840", "best_bid": "0", "best_ask": "0.001"}], "timestamp": "1769384078439", "event_type": "price_change"}}
{"_local_timestamp": "2026-01-25T23:34:38.854092+00:00", "data": {"market": "0xca76faf001d267c0fc809c1f39b801f95e2bcb45ebc6f5ba489630c0acd05059", "price_changes": [{"asset_id": "22883281051100193685236025657268856534873448228400701464864171575150378577088", "price": "0.999", "size": "85003", "side": "BUY", "hash": "2a02141d1a4b50b4f0736cc46178e9405fb7ef89", "best_bid": "0.999", "best_ask": "1"}, {"asset_id": "18066679137160239835833186135441870746243656504791377368093305126991522725800", "price": "0.001", "size": "85003", "side": "SELL", "hash": "12aab899fbd9e5c0437c2658ff56ee335c92033f", "best_bid": "0", "best_ask": "0.001"}], "timestamp": "1769384078785", "event_type": "price_change"}}
{"_local_timestamp": "2026-01-25T23:34:40.198531+00:00", "data": {"market": "0xca76faf001d267c0fc809c1f39b801f95e2bcb45ebc6f5ba489630c0acd05059", "price_changes": [{"asset_id": "22883281051100193685236025657268856534873448228400701464864171575150378577088", "price": "0.999", "size": "85156", "side": "BUY", "hash": "33e19693fd3aeecfed675a2e9c2e4687e6c21d39", "best_bid": "0.999", "best_ask": "1"}, {"asset_id": "18066679137160239835833186135441870746243656504791377368093305126991522725800", "price": "0.001", "size": "85156", "side": "SELL", "hash": "b84131c3e2275bb6de026d6cf2a0de43e938b46f", "best_bid": "0", "best_ask": "0.001"}], "timestamp": "1769384080021", "event_type": "price_change"}}
{"_local_timestamp": "2026-01-25T23:34:40.669425+00:00", "data": {"market": "0xca76faf001d267c0fc809c1f39b801f95e2bcb45ebc6f5ba489630c0acd05059", "price_changes": [{"asset_id": "22883281051100193685236025657268856534873448228400701464864171575150378577088", "price": "0.999", "size": "85308", "side": "BUY", "hash": "e0a17ce28f57a88716959cde5cfaa51ae4e4f07a", "best_bid": "0.999", "best_ask": "1"}, {"asset_id": "18066679137160239835833186135441870746243656504791377368093305126991522725800", "price": "0.001", "size": "85308", "side": "SELL", "hash": "d35bd8f2937bf4cfebc8d876897dafbf99554f0d", "best_bid": "0", "best_ask": "0.001"}], "timestamp": "1769384080491", "event_type": "price_change"}}
{"_local_timestamp": "2026-01-25T23:35:07.611653+00:00", "data": {"market": "0xca76faf001d267c0fc809c1f39b801f95e2bcb45ebc6f5ba489630c0acd05059", "price_changes": [{"asset_id": "22883281051100193685236025657268856534873448228400701464864171575150378577088", "price": "0.999", "size": "80005", "side": "BUY", "hash": "a5599d8abf6fcf330bae42247060745a337f3d33", "best_bid": "0.999", "best_ask": "1"}, {"asset_id": "18066679137160239835833186135441870746243656504791377368093305126991522725800", "price": "0.001", "size": "80005", "side": "SELL", "hash": "d5feddec7e649561a5103cc478745756c7c31629", "best_bid": "0", "best_ask": "0.001"}], "timestamp": "1769384107392", "event_type": "price_change"}}
{"_local_timestamp": "2026-01-25T23:35:07.873144+00:00", "data": {"market": "0xca76faf001d267c0fc809c1f39b801f95e2bcb45ebc6f5ba489630c0acd05059", "price_changes": [{"asset_id": "22883281051100193685236025657268856534873448228400701464864171575150378577088", "price": "0.999", "size": "80044", "side": "BUY", "hash": "9dae6ef3d1f867b91965cc92e9acca0c7f45cfa3", "best_bid": "0.999", "best_ask": "1"}, {"asset_id": "18066679137160239835833186135441870746243656504791377368093305126991522725800", "price": "0.001", "size": "80044", "side": "SELL", "hash": "38d243d2c5bc5477926b62dde443f11a259313a5", "best_bid": "0", "best_ask": "0.001"}], "timestamp": "1769384107619", "event_type": "price_change"}}
{"_local_timestamp": "2026-01-25T23:35:08.176316+00:00", "data": {"market": "0xca76faf001d267c0fc809c1f39b801f95e2bcb45ebc6f5ba489630c0acd05059", "price_changes": [{"asset_id": "22883281051100193685236025657268856534873448228400701464864171575150378577088", "price": "0.999", "size": "80082", "side": "BUY", "hash": "d9b25d2084ed390a09e91026e3910fa0f6393407", "best_bid": "0.999", "best_ask": "1"}, {"asset_id": "18066679137160239835833186135441870746243656504791377368093305126991522725800", "price": "0.001", "size": "80082", "side": "SELL", "hash": "dfd906dc5ca2266b610d423c4db0ba5566bc0c40", "best_bid": "0", "best_ask": "0.001"}], "timestamp": "1769384107941", "event_type": "price_change"}}
{"_local_timestamp": "2026-01-25T23:35:08.671841+00:00", "data": {"market": "0xca76faf001d267c0fc809c1f39b801f95e2bcb45ebc6f5ba489630c0acd05059", "price_changes": [{"asset_id": "22883281051100193685236025657268856534873448228400701464864171575150378577088", "price": "0.999", "size": "80119", "side": "BUY", "hash": "1d2390852be61a822a2145c67f383b52a153d11e", "best_bid": "0.999", "best_ask": "1"}, {"asset_id": "18066679137160239835833186135441870746243656504791377368093305126991522725800", "price": "0.001", "size": "80119", "side": "SELL", "hash": "a67f9b6898fa4c5a720b58e2813e351a2f2b1412", "best_bid": "0", "best_ask": "0.001"}], "timestamp": "1769384108370", "event_type": "price_change"}}
{"_local_timestamp": "2026-01-25T23:35:09.030716+00:00", "data": {"market": "0xca76faf001d267c0fc809c1f39b801f95e2bcb45ebc6f5ba489630c0acd05059", "price_changes": [{"asset_id": "22883281051100193685236025657268856534873448228400701464864171575150378577088", "price": "0.999", "size": "80155", "side": "BUY", "hash": "75c08f6568cdb87d95fe600afb081b684c795f18", "best_bid": "0.999", "best_ask": "1"}, {"asset_id": "18066679137160239835833186135441870746243656504791377368093305126991522725800", "price": "0.001", "size": "80155", "side": "SELL", "hash": "ff93f433019bb71c25a462126aabbc385cd355d3", "best_bid": "0", "best_ask": "0.001"}], "timestamp": "1769384108822", "event_type": "price_change"}}
{"_local_timestamp": "2026-01-25T23:35:09.366253+00:00", "data": {"market": "0xca76faf001d267c0fc809c1f39b801f95e2bcb45ebc6f5ba489630c0acd05059", "price_changes": [{"asset_id": "22883281051100193685236025657268856534873448228400701464864171575150378577088", "price": "0.999", "size": "80190", "side": "BUY", "hash": "bbf587cede27d49aafaa24de375a9d9408edafb6", "best_bid": "0.999", "best_ask": "1"}, {"asset_id": "18066679137160239835833186135441870746243656504791377368093305126991522725800", "price": "0.001", "size": "80190", "side": "SELL", "hash": "3b92c0bd7c47e4d121dec9c81f98ae7f9e326c18", "best_bid": "0", "best_ask": "0.001"}], "timestamp": "1769384109162", "event_type": "price_change"}}
{"_local_timestamp": "2026-01-25T23:35:12.263602+00:00", "data": {"market": "0xca76faf001d267c0fc809c1f39b801f95e2bcb45ebc6f5ba489630c0acd05059", "price_changes": [{"asset_id": "22883281051100193685236025657268856534873448228400701464864171575150378577088", "price": "0.999", "size": "80814", "side": "BUY", "hash": "b1988a72f137a80f00e08498c04c4821db365de3", "best_bid": "0.999", "best_ask": "1"}, {"asset_id": "18066679137160239835833186135441870746243656504791377368093305126991522725800", "price": "0.001", "size": "80814", "side": "SELL", "hash": "7baa797c40f5ef711a88f01e1798786bb87bc5df", "best_bid": "0", "best_ask": "0.001"}], "timestamp": "1769384112043", "event_type": "price_change"}}
{"_local_timestamp": "2026-01-25T23:35:14.253823+00:00", "data": {"market": "0xca76faf001d267c0fc809c1f39b801f95e2bcb45ebc6f5ba489630c0acd05059", "price_changes": [{"asset_id": "22883281051100193685236025657268856534873448228400701464864171575150378577088", "price": "0.999", "size": "80969", "side": "BUY", "hash": "9bbcf2817b858d4a62901fc2a7932cd6bb77e9cb", "best_bid": "0.999", "best_ask": "1"}, {"asset_id": "18066679137160239835833186135441870746243656504791377368093305126991522725800", "price": "0.001", "size": "80969", "side": "SELL", "hash": "7f86dd8f8bcbf9be6a45454958f584e869e9c839", "best_bid": "0", "best_ask": "0.001"}], "timestamp": "1769384114046", "event_type": "price_change"}}
{"_local_timestamp": "2026-01-25T23:35:14.704489+00:00", "data": {"market": "0xca76faf001d267c0fc809c1f39b801f95e2bcb45ebc6f5ba489630c0acd05059", "price_changes": [{"asset_id": "22883281051100193685236025657268856534873448228400701464864171575150378577088", "price": "0.999", "size": "81123", "side": "BUY", "hash": "df76a3ac9e42bb8b650d78cc095954e9d9b7bb1a", "best_bid": "0.999", "best_ask": "1"}, {"asset_id": "18066679137160239835833186135441870746243656504791377368093305126991522725800", "price": "0.001", "size": "81123", "side": "SELL", "hash": "da8f52c857b884ed4be1a571f623e9c8437d4683", "best_bid": "0", "best_ask": "0.001"}], "timestamp": "1769384114485", "event_type": "price_change"}}
{"_local_timestamp": "2026-01-25T23:35:15.333041+00:00", "data": {"market": "0xca76faf001d267c0fc809c1f39b801f95e2bcb45ebc6f5ba489630c0acd05059", "price_changes": [{"asset_id": "22883281051100193685236025657268856534873448228400701464864171575150378577088", "price": "0.999", "size": "81276", "side": "BUY", "hash": "477939a3bda2d768d978cfd8102c6e038cf5a097", "best_bid": "0.999", "best_ask": "1"}, {"asset_id": "18066679137160239835833186135441870746243656504791377368093305126991522725800", "price": "0.001", "size": "81276", "side": "SELL", "hash": "cfa7aacd465d769b2974d9f0e8ff623a3eff2403", "best_bid": "0", "best_ask": "0.001"}], "timestamp": "1769384115110", "event_type": "price_change"}}
{"_local_timestamp": "2026-01-25T23:35:18.098858+00:00", "data": {"market": "0xca76faf001d267c0fc809c1f39b801f95e2bcb45ebc6f5ba489630c0acd05059", "price_changes": [{"asset_id": "22883281051100193685236025657268856534873448228400701464864171575150378577088", "price": "0.999", "size": "81310", "side": "BUY", "hash": "46d12a2404e21d4fdb544885cecff5ac7d4e72da", "best_bid": "0.999", "best_ask": "1"}, {"asset_id": "18066679137160239835833186135441870746243656504791377368093305126991522725800", "price": "0.001", "size": "81310", "side": "SELL", "hash": "c606cc2d36d35410b7a6a56bf7d1bc20c39320e1", "best_bid": "0", "best_ask": "0.001"}], "timestamp": "1769384117849", "event_type": "price_change"}}
