{"_local_timestamp": "2026-01-25T23:33:31.781748+00:00", "data": [{"market": "0x76151c30f23ef5ee963e2f73fa49d5433b4db34839c39383bee4989cb270b639", "asset_id": "23504259219851075832272877441883189669703359970946991544021206156288112345254", "timestamp": "1769383999322", "hash": "c42dcaa10be00ad454ab7807154d56ecd15cd5d8", "bids": [{"price": "0.01", "size": "20.16"}, {"price": "0.02", "size": "1000"}, {"price": "0.03", "size": "5.79"}, {"price": "0.05", "size": "10"}, {"price": "0.06", "size": "700"}, {"price": "0.07", "size": "10.35"}, {"price": "0.08", "size": "5"}, {"price": "0.15", "size": "1366"}, {"price": "0.16", "size": "2624"}, {"price": "0.29", "size": "10.48"}, {"price": "0.3", "size": "3726"}, {"price": "0.31", "size": "300"}, {"price": "0.32", "size": "6"}, {"price": "0.47", "size": "50"}, {"price": "0.64", "size": "1308.55"}, {"price": "0.67", "size": "265"}, {"price": "0.78", "size": "1225"}, {"price": "0.79", "size": "227.49"}, {"price": "0.8", "size": "391"}], "asks": [{"price": "0.99", "size": "29.14"}, {"price": "0.98", "size": "6.84"}, {"price": "0.96", "size": "99"}, {"price": "0.93", "size": "238"}, {"price": "0.92", "size": "107.86"}, {"price": "0.85", "size": "5.56"}, {"price": "0.83", "size": "105.56"}], "event_type": "book", "last_trade_price": "0.200"}, {"market": "0x76151c30f23ef5ee963e2f73fa49d5433b4db34839c39383bee4989cb270b639", "asset_id": "92714767158282519723247724560387828941593726179269759014514785099742463503662", "timestamp": "1769383999322", "hash": "ba211c190ddfa805a0468fdd43aaf4a58c9f27f4", "bids": [{"price": "0.01", "size": "29.14"}, {"price": "0.02", "size": "6.84"}, {"price": "0.04", "size": "99"}, {"price": "0.07", "size": "238"}, {"price": "0.08", "size": "107.86"}, {"price": "0.15", "size": "5.56"}, {"price": "0.17", "size": "105.56"}], "asks": [{"price": "0.99", "size": "20.16"}, {"price": "0.98", "size": "1000"}, {"price": "0.97", "size": "5.79"}, {"price": "0.95", "size": "10"}, {"price": "0.94", "size": "700"}, {"price": "0.93", "size": "10.35"}, {"price": "0.92", "size": "5"}, {"price": "0.85", "size": "1366"}, {"price": "0.84", "size": "2624"}, {"price": "0.71", "size": "10.48"}, {"price": "0.7", "size": "3726"}, {"price": "0.69", "size": "300"}, {"price": "0.68", "size": "6"}, {"price": "0.53", "size": "50"}, {"price": "0.36", "size": "1308.55"}, {"price": "0.33", "size": "265"}, {"price": "0.22", "size": "1225"}, {"price": "0.21", "size": "227.49"}, {"price": "0.2", "size": "391"}], "event_type": "book", "last_trade_price": "0.200"}]}
{"_local_timestamp": "2026-01-25T23:33:55.105563+00:00", "data": {"market": "0x76151c30f23ef5ee963e2f73fa49d5433b4db34839c39383bee4989cb270b639", "price_changes": [{"asset_id": "23504259219851075832272877441883189669703359970946991544021206156288112345254", "price": "0.8", "size": "291", "side": "BUY", "hash": "7513bb7b228d4553b537061ccd9eca3d1103e4a8", "best_bid": "0.8", "best_ask": "0.83"}, {"asset_id": "92714767158282519723247724560387828941593726179269759014514785099742463503662", "price": "0.2", "size": "291", "side": "SELL", "hash": "d38d6b0af2279ead5835cce7c5e7637637288b98", "best_bid": "0.17", "best_ask": "0.2"}], "timestamp": "1769384035001", "event_type": "price_change"}}
{"_local_timestamp": "2026-01-25T23:33:55.106452+00:00", "data": {"market": "0x76151c30f23ef5ee963e2f73fa49d5433b4db34839c39383bee4989cb270b639", "price_changes": [{"asset_id": "92714767158282519723247724560387828941593726179269759014514785099742463503662", "price": "0.17", "size": "5.56", "side": "BUY", "hash": "e2a8ed0d915a147b1f1386ad233456182145209e", "best_bid": "0.17", "best_ask": "0.2"}, {"asset_id": "23504259219851075832272877441883189669703359970946991544021206156288112345254", "price": "0.83", "size": "5.56", "side": "SELL", "hash": "74c37fed476658a682dd44bdf15a68c5d203ad6f", "best_bid": "0.8", "best_ask": "0.83"}], "timestamp": "1769384035004", "event_type": "price_change"}}
{"_local_timestamp": "2026-01-25T23:33:55.135885+00:00", "data": {"market": "0x76151c30f23ef5ee963e2f73fa49d5433b4db34839c39383bee4989cb270b639", "price_changes": [{"asset_id": "23504259219851075832272877441883189669703359970946991544021206156288112345254", "price": "0.93", "size": "0", "side": "SELL", "hash": "38ba93850ee4a6249619a311b8da099cb8748196", "best_bid": "0.8", "best_ask": "0.83"}, {"asset_id": "92714767158282519723247724560387828941593726179269759014514785099742463503662", "price": "0.07", "size": "0", "side": "BUY", "hash": "1297f7e9c0808f52d1d292f86cb19ff1ce30a4f3", "best_bid": "0.17", "best_ask": "0.2"}], "timestamp": "1769384035057", "event_type": "price_change"}}
{"_local_timestamp": "2026-01-25T23:33:55.204067+00:00", "data": {"market": "0x76151c30f23ef5ee963e2f73fa49d5433b4db34839c39383bee4989cb270b639", "price_changes": [{"asset_id": "23504259219851075832272877441883189669703359970946991544021206156288112345254", "price": "0.95", "size": "246", "side": "SELL", "hash": "2f0a74c3a59c1cfdc520b7f47c1800b135bb27ea", "best_bid": "0.8", "best_ask": "0.83"}, {"asset_id": "92714767158282519723247724560387828941593726179269759014514785099742463503662", "price": "0.05", "size": "246", "side": "BUY", "hash": "e16ed1b09d9a4ba55edc79b5de27c5cab33c531c", "best_bid": "0.17", "best_ask": "0.2"}], "timestamp": "1769384035130", "event_type": "price_change"}}
{"_local_timestamp": "2026-01-25T23:33:57.918903+00:00", "data": {"market": "0x76151c30f23ef5ee963e2f73fa49d5433b4db34839c39383bee4989cb270b639", "price_changes": [{"asset_id": "92714767158282519723247724560387828941593726179269759014514785099742463503662", "price": "0.08", "size": "7.86", "side": "BUY", "hash": "f89e630a38e94a046ca0a6d776f12796e5b67d17", "best_bid": "0.17", "best_ask": "0.2"}, {"asset_id": "23504259219851075832272877441883189669703359970946991544021206156288112345254", "price": "0.92", "size": "7.86", "side": "SELL", "hash": "4752aad2e3d265b558488885471d2c868573b8a3", "best_bid": "0.8", "best_ask": "0.83"}], "timestamp": "1769384037849", "event_type": "price_change"}}
{"_local_timestamp": "2026-01-25T23:33:57.941522+00:00", "data": {"market": "0x76151c30f23ef5ee963e2f73fa49d5433b4db34839c39383bee4989cb270b639", "price_changes": [{"asset_id": "23504259219851075832272877441883189669703359970946991544021206156288112345254", "price": "0.95", "size": "0", "side": "SELL", "hash": "9d35bad99841b1ea5aa7af2c7b727d04d35c933e", "best_bid": "0.8", "best_ask": "0.83"}, {"asset_id": "92714767158282519723247724560387828941593726179269759014514785099742463503662", "price": "0.05", "size": "0", "side": "BUY", "hash": "9aa4a309cedef6052f042f24f2bb68a93bcdc62c", "best_bid": "0.17", "best_ask": "0.2"}], "timestamp": "1769384037877", "event_type": "price_change"}}
{"_local_timestamp": "2026-01-25T23:33:57.941881+00:00", "data": {"market": "0x76151c30f23ef5ee963e2f73fa49d5433b4db34839c39383bee4989cb270b639", "price_changes": [{"asset_id": "23504259219851075832272877441883189669703359970946991544021206156288112345254", "price": "0.67", "size": "200", "side": "BUY", "hash": "9d35bad99841b1ea5aa7af2c7b727d04d35c933e", "best_bid": "0.8", "best_ask": "0.83"}, {"asset_id": "92714767158282519723247724560387828941593726179269759014514785099742463503662", "price": "0.33", "size": "200", "side": "SELL", "hash": "9aa4a309cedef6052f042f24f2bb68a93bcdc62c", "best_bid": "0.17", "best_ask": "0.2"}], "timestamp": "1769384037877", "event_type": "price_change"}}
{"_local_timestamp": "2026-01-25T23:33:58.687523+00:00", "data": {"market": "0x76151c30f23ef5ee963e2f73fa49d5433b4db34839c39383bee4989cb270b639", "price_changes": [{"asset_id": "92714767158282519723247724560387828941593726179269759014514785099742463503662", "price": "0.06", "size": "100", "side": "BUY", "hash": "94344593cc918f72939fe9d9fc70b67b36dd7d58", "best_bid": "0.17", "best_ask": "0.2"}, {"asset_id": "23504259219851075832272877441883189669703359970946991544021206156288112345254", "price": "0.94", "size": "100", "side": "SELL", "hash": "64acbe171705b1c2caeb45f4b9ae4872dd9b9549", "best_bid": "0.8", "best_ask": "0.83"}], "timestamp": "1769384038611", "event_type": "price_change"}}
{"_local_timestamp": "2026-01-25T23:33:58.719998+00:00", "data": {"market": "0x76151c30f23ef5ee963e2f73fa49d5433b4db34839c39383bee4989cb270b639", "price_changes": [{"asset_id": "23504259219851075832272877441883189669703359970946991544021206156288112345254", "price": "0.93", "size": "234", "side": "SELL", "hash": "4061bab99f93ad548876c07506cb456db6355a16", "best_bid": "0.8", "best_ask": "0.83"}, {"asset_id": "92714767158282519723247724560387828941593726179269759014514785099742463503662", "price": "0.07", "size": "234", "side": "BUY", "hash": "e51b5f7a8c14af5466a7d62c909b5af17bece748", "best_bid": "0.17", "best_ask": "0.2"}], "timestamp": "1769384038640", "event_type": "price_change"}}
{"_local_timestamp": "2026-01-25T23:33:58.721593+00:00", "data": {"market": "0x76151c30f23ef5ee963e2f73fa49d5433b4db34839c39383bee4989cb270b639", "price_changes": [{"asset_id": "23504259219851075832272877441883189669703359970946991544021206156288112345254", "price": "0.67", "size": "265", "side": "BUY", "hash": "506a9590881082efb9bb98f0c6ccbf277ef0293d", "best_bid": "0.8", "best_ask": "0.83"}, {"asset_id": "92714767158282519723247724560387828941593726179269759014514785099742463503662", "price": "0.33", "size": "265", "side": "SELL", "hash": "f98628d7d4fec5d6a4e635bc11a15f5124e78c20", "best_bid": "0.17", "best_ask": "0.2"}], "timestamp": "1769384038643", "event_type": "price_change"}}
{"_local_timestamp": "2026-01-25T23:34:00.678793+00:00", "data": {"market": "0x76151c30f23ef5ee963e2f73fa49d5433b4db34839c39383bee4989cb270b639", "price_changes": [{"asset_id": "92714767158282519723247724560387828941593726179269759014514785099742463503662", "price": "0.12", "size": "100", "side": "BUY", "hash": "ce8c85e99ead6a604aeea5cfad47e59ed9ab1107", "best_bid": "0.17", "best_ask": "0.2"}, {"asset_id": "23504259219851075832272877441883189669703359970946991544021206156288112345254", "price": "0.88", "size": "100", "side": "SELL", "hash": "bedb945c774a02c67599bc59b9a7aff31c50c90a", "best_bid": "0.8", "best_ask": "0.83"}], "timestamp": "1769384040606", "event_type": "price_change"}}
{"_local_timestamp": "2026-01-25T23:34:00.699053+00:00", "data": {"market": "0x76151c30f23ef5ee963e2f73fa49d5433b4db34839c39383bee4989cb270b639", "price_changes": [{"asset_id": "23504259219851075832272877441883189669703359970946991544021206156288112345254", "price": "0.93", "size": "0", "side": "SELL", "hash": "f175f586d72de460c0bec21ca4fef08f986c94c4", "best_bid": "0.8", "best_ask": "0.83"}, {"asset_id": "92714767158282519723247724560387828941593726179269759014514785099742463503662", "price": "0.07", "size": "0", "side": "BUY", "hash": "e7ca5b17f1527b9d6125a8e47b7cb81eb8e94c27", "best_bid": "0.17", "best_ask": "0.2"}], "timestamp": "1769384040632", "event_type": "price_change"}}
{"_local_timestamp": "2026-01-25T23:34:02.487532+00:00", "data": {"market": "0x76151c30f23ef5ee963e2f73fa49d5433b4db34839c39383bee4989cb270b639", "price_changes": [{"asset_id": "92714767158282519723247724560387828941593726179269759014514785099742463503662", "price": "0.06", "size": "0", "side": "BUY", "hash": "9d92c57d2b4ec585d8e8664968a504c39f58e01b", "best_bid": "0.17", "best_ask": "0.2"}, {"asset_id": "23504259219851075832272877441883189669703359970946991544021206156288112345254", "price": "0.94", "size": "0", "side": "SELL", "hash": "b3053a5e631eed6b5c674f5eb4ae2e72738d1624", "best_bid": "0.8", "best_ask": "0.83"}], "timestamp": "1769384042406", "event_type": "price_change"}}
{"_local_timestamp": "2026-01-25T23:34:03.237949+00:00", "data": {"market": "0x76151c30f23ef5ee963e2f73fa49d5433b4db34839c39383bee4989cb270b639", "price_changes": [{"asset_id": "92714767158282519723247724560387828941593726179269759014514785099742463503662", "price": "0.05", "size": "100", "side": "BUY", "hash": "0a2082c1a7efba1462114e1a6de00015880ff0d1", "best_bid": "0.17", "best_ask": "0.2"}, {"asset_id": "23504259219851075832272877441883189669703359970946991544021206156288112345254", "price": "0.95", "size": "100", "side": "SELL", "hash": "0ea6084a2d170a6bf59da9b24ec621a09f14ac9f", "best_bid": "0.8", "best_ask": "0.83"}], "timestamp": "1769384043168", "event_type": "price_change"}}
{"_local_timestamp": "2026-01-25T23:35:09.672693+00:00", "data": {"market": "0x76151c30f23ef5ee963e2f73fa49d5433b4db34839c39383bee4989cb270b639", "price_changes": [{"asset_id": "23504259219851075832272877441883189669703359970946991544021206156288112345254", "price": "0.08", "size": "0", "side": "BUY", "hash": "17568a07d08f63396aeff34637eb21e26f9d0dbb", "best_bid": "0.8", "best_ask": "0.83"}, {"asset_id": "92714767158282519723247724560387828941593726179269759014514785099742463503662", "price": "0.92", "size": "0", "side": "SELL", "hash": "0d13d7e94033b68c50a8c810642bc95cb9082438", "best_bid": "0.17", "best_ask": "0.2"}], "timestamp": "1769384109466", "event_type": "price_change"}}
{"_local_timestamp": "2026-01-25T23:35:09.925197+00:00", "data": {"market": "0x76151c30f23ef5ee963e2f73fa49d5433b4db34839c39383bee4989cb270b639", "price_changes": [{"asset_id": "23504259219851075832272877441883189669703359970946991544021206156288112345254", "price": "0.08", "size": "5", "side": "BUY", "hash": "b7a47a095c13ef427b53b71934dee9e61e8aee8a", "best_bid": "0.8", "best_ask": "0.83"}, {"asset_id": "92714767158282519723247724560387828941593726179269759014514785099742463503662", "price": "0.92", "size": "5", "side": "SELL", "hash": "cca76dd73f0fcd0e30c0b67913cf10af5476cf3d", "best_bid": "0.17", "best_ask": "0.2"}], "timestamp": "1769384109729", "event_type": "price_change"}}
{"_local_timestamp": "2026-01-25T23:35:57.396932+00:00", "data": {"market": "0x76151c30f23ef5ee963e2f73fa49d5433b4db34839c39383bee4989cb270b639", "price_changes": [{"asset_id": "92714767158282519723247724560387828941593726179269759014514785099742463503662", "price": "0.01", "size": "17.16", "side": "BUY", "hash": "a5633bb566817eebb7642ae8d10ccdace96183bf", "best_bid": "0.17", "best_ask": "0.2"}, {"asset_id": "23504259219851075832272877441883189669703359970946991544021206156288112345254", "price": "0.99", "size": "17.16", "side": "SELL", "hash": "167e1450e596790c66e756f17d7fa87769634693", "best_bid": "0.8", "best_ask": "0.83"}], "timestamp": "1769384157310", "event_type": "price_change"}}
{"_local_timestamp": "2026-01-25T23:35:57.398020+00:00", "data": {"market": "0x76151c30f23ef5ee963e2f73fa49d5433b4db34839c39383bee4989cb270b639", "price_changes": [{"asset_id": "92714767158282519723247724560387828941593726179269759014514785099742463503662", "price": "0.08", "size": "0", "side": "BUY", "hash": "a5633bb566817eebb7642ae8d10ccdace96183bf", "best_bid": "0.17", "best_ask": "0.2"}, {"asset_id": "23504259219851075832272877441883189669703359970946991544021206156288112345254", "price": "0.92", "size": "0", "side": "SELL", "hash": "167e1450e596790c66e756f17d7fa87769634693", "best_bid": "0.8", "best_ask": "0.83"}], "timestamp": "1769384157310", "event_type": "price_change"}}
{"_local_timestamp": "2026-01-25T23:35:57.402723+00:00", "data": {"market": "0x76151c30f23ef5ee963e2f73fa49d5433b4db34839c39383bee4989cb270b639", "price_changes": [{"asset_id": "23504259219851075832272877441883189669703359970946991544021206156288112345254", "price": "0.95", "size": "336", "side": "SELL", "hash": "b33303be1a5713fc9cddb4cce90cb5694d591558", "best_bid": "0.8", "best_ask": "0.83"}, {"asset_id": "92714767158282519723247724560387828941593726179269759014514785099742463503662", "price": "0.05", "size": "336", "side": "BUY", "hash": "4a5fe15a4446b0942ba4d35068aaea1c594bf685", "best_bid": "0.17", "best_ask": "0.2"}], "timestamp": "1769384157338", "event_type": "price_change"}}
{"_local_timestamp": "2026-01-25T23:35:57.694628+00:00", "data": {"market": "0x76151c30f23ef5ee963e2f73fa49d5433b4db34839c39383bee4989cb270b639", "price_changes": [{"asset_id": "92714767158282519723247724560387828941593726179269759014514785099742463503662", "price": "0.06", "size": "12.47", "side": "BUY", "hash": "d0bd824484d4cb17902634e648048770465544ff", "best_bid": "0.17", "best_ask": "0.2"}, {"asset_id": "23504259219851075832272877441883189669703359970946991544021206156288112345254", "price": "0.94", "size": "12.47", "side": "SELL", "hash": "37e13711fb03e75fcdcb88b5f87edf5e713cbdc8", "best_bid": "0.8", "best_ask": "0.83"}], "timestamp": "1769384157620", "event_type": "price_change"}}
{"_local_timestamp": "2026-01-25T23:35:58.505267+00:00", "data": {"market": "0x76151c30f23ef5ee963e2f73fa49d5433b4db34839c39383bee4989cb270b639", "price_changes": [{"asset_id": "23504259219851075832272877441883189669703359970946991544021206156288112345254", "price": "0.95", "size": "100", "side": "SELL", "hash": "56669bccec2762cbb7e13339540748c64a750c2e", "best_bid": "0.8", "best_ask": "0.83"}, {"asset_id": "92714767158282519723247724560387828941593726179269759014514785099742463503662", "price": "0.05", "size": "100", "side": "BUY", "hash": "b40127ca80e9732abf55633389eb413b2d5957b3", "best_bid": "0.17", "best_ask": "0.2"}], "timestamp": "1769384158436", "event_type": "price_change"}}
{"_local_timestamp": "2026-01-25T23:35:58.529339+00:00", "data": {"market": "0x76151c30f23ef5ee963e2f73fa49d5433b4db34839c39383bee4989cb270b639", "price_changes": [{"asset_id": "23504259219851075832272877441883189669703359970946991544021206156288112345254", "price": "0.93", "size": "225", "side": "SELL", "hash": "453e5d55193a711b89f0d42e1766f8e052726e14", "best_bid": "0.8", "best_ask": "0.83"}, {"asset_id": "92714767158282519723247724560387828941593726179269759014514785099742463503662", "price": "0.07", "size": "225", "side": "BUY", "hash": "3a94da217094b05ef32bc06b022bbd972aa23ead", "best_bid": "0.17", "best_ask": "0.2"}], "timestamp": "1769384158463", "event_type": "price_change"}}
{"_local_timestamp": "2026-01-25T23:35:59.530685+00:00", "data": {"market": "0x76151c30f23ef5ee963e2f73fa49d5433b4db34839c39383bee4989cb270b639", "price_changes": [{"asset_id": "92714767158282519723247724560387828941593726179269759014514785099742463503662", "price": "0.05", "size": "0", "side": "BUY", "hash": "13cce80920d6172cba2e8d5261f80633e4f0f777", "best_bid": "0.17", "best_ask": "0.2"}, {"asset_id": "23504259219851075832272877441883189669703359970946991544021206156288112345254", "price": "0.95", "size": "0", "side": "SELL", "hash": "3efeed164ab28d1699c78c94591387ee5b23742a", "best_bid": "0.8", "best_ask": "0.83"}], "timestamp": "1769384159453", "event_type": "price_change"}}
{"_local_timestamp": "2026-01-25T23:36:00.200730+00:00", "data": {"market": "0x76151c30f23ef5ee963e2f73fa49d5433b4db34839c39383bee4989cb270b639", "price_changes": [{"asset_id": "92714767158282519723247724560387828941593726179269759014514785099742463503662", "price": "0.08", "size": "100", "side": "BUY", "hash": "e778178e713d77140a5908831c52d0772729ba76", "best_bid": "0.17", "best_ask": "0.2"}, {"asset_id": "23504259219851075832272877441883189669703359970946991544021206156288112345254", "price": "0.92", "size": "100", "side": "SELL", "hash": "06653c2cecc00a0a192568a55ebc45cdfab8a3c1", "best_bid": "0.8", "best_ask": "0.83"}], "timestamp": "1769384160111", "event_type": "price_change"}}
{"_local_timestamp": "2026-01-25T23:36:00.229392+00:00", "data": {"market": "0x76151c30f23ef5ee963e2f73fa49d5433b4db34839c39383bee4989cb270b639", "price_changes": [{"asset_id": "23504259219851075832272877441883189669703359970946991544021206156288112345254", "price": "0.93", "size": "0", "side": "SELL", "hash": "e9897e4cef464e2d3b3e234ac4ed3eed0f89b36e", "best_bid": "0.8", "best_ask": "0.83"}, {"asset_id": "92714767158282519723247724560387828941593726179269759014514785099742463503662", "price": "0.07", "size": "0", "side": "BUY", "hash": "8906a686c4b504f6660fd3bf56b3ece772e2dc49", "best_bid": "0.17", "best_ask": "0.2"}], "timestamp": "1769384160158", "event_type": "price_change"}}
{"_local_timestamp": "2026-01-25T23:36:03.838899+00:00", "data": {"market": "0x76151c30f23ef5ee963e2f73fa49d5433b4db34839c39383bee4989cb270b639", "price_changes": [{"asset_id": "92714767158282519723247724560387828941593726179269759014514785099742463503662", "price": "0.08", "size": "0", "side": "BUY", "hash": "698aabcf0f4d2fa944ec639eaa4a2ab72b3181de", "best_bid": "0.17", "best_ask": "0.2"}, {"asset_id": "23504259219851075832272877441883189669703359970946991544021206156288112345254", "price": "0.92", "size": "0", "side": "SELL", "hash": "53c1a27f2a9d9f2b8589a4913721421d744e8547", "best_bid": "0.8", "best_ask": "0.83"}], "timestamp": "1769384163770", "event_type": "price_change"}}
{"_local_timestamp": "2026-01-25T23:36:04.358498+00:00", "data": {"market": "0x76151c30f23ef5ee963e2f73fa49d5433b4db34839c39383bee4989cb270b639", "price_changes": [{"asset_id": "92714767158282519723247724560387828941593726179269759014514785099742463503662", "price": "0.05", "size": "100", "side": "BUY", "hash": "0e409a2c424fbe182cde9c3146020d77b89e8761", "best_bid": "0.17", "best_ask": "0.2"}, {"asset_id": "23504259219851075832272877441883189669703359970946991544021206156288112345254", "price": "0.95", "size": "100", "side": "SELL", "hash": "0da1ac05aa4d50fe9e5ed4262729183975b9df3a", "best_bid": "0.8", "best_ask": "0.83"}], "timestamp": "1769384164280", "event_type": "price_change"}}
{"_local_timestamp": "2026-01-25T23:36:04.378482+00:00", "data": {"market": "0x76151c30f23ef5ee963e2f73fa49d5433b4db34839c39383bee4989cb270b639", "price_changes": [{"asset_id": "23504259219851075832272877441883189669703359970946991544021206156288112345254", "price": "0.94", "size": "237.47", "side": "SELL", "hash": "5b4dc1382039b91550b48a947a19ff7fa7a71e07", "best_bid": "0.8", "best_ask": "0.83"}, {"asset_id": "92714767158282519723247724560387828941593726179269759014514785099742463503662", "price": "0.06", "size": "237.47", "side": "BUY", "hash": "0a5299e2d3a3478889f364e22060e7db10e3624e", "best_bid": "0.17", "best_ask": "0.2"}], "timestamp": "1769384164311", "event_type": "price_change"}}
{"_local_timestamp": "2026-01-25T23:36:08.014754+00:00", "data": {"market": "0x76151c30f23ef5ee963e2f73fa49d5433b4db34839c39383bee4989cb270b639", "price_changes": [{"asset_id": "92714767158282519723247724560387828941593726179269759014514785099742463503662", "price": "0.05", "size": "0", "side": "BUY", "hash": "c8f524ccb466a8ced9bd15dd3e62ec1cabf27918", "best_bid": "0.17", "best_ask": "0.2"}, {"asset_id": "23504259219851075832272877441883189669703359970946991544021206156288112345254", "price": "0.95", "size": "0", "side": "SELL", "hash": "f7f25e292780e4fe4a5457937cdc72e918bde3bf", "best_bid": "0.8", "best_ask": "0.83"}], "timestamp": "1769384167947", "event_type": "price_change"}}
{"_local_timestamp": "2026-01-25T23:36:08.634633+00:00", "data": {"market": "0x76151c30f23ef5ee963e2f73fa49d5433b4db34839c39383bee4989cb270b639", "price_changes": [{"asset_id": "92714767158282519723247724560387828941593726179269759014514785099742463503662", "price": "0.07", "size": "100", "side": "BUY", "hash": "dfd1a9d006c194db316c31a48410b4f59fc1c855", "best_bid": "0.17", "best_ask": "0.2"}, {"asset_id": "23504259219851075832272877441883189669703359970946991544021206156288112345254", "price": "0.93", "size": "100", "side": "SELL", "hash": "9945e2158eaa9048151db95367f719eb75627f73", "best_bid": "0.8", "best_ask": "0.83"}], "timestamp": "1769384168567", "event_type": "price_change"}}
{"_local_timestamp": "2026-01-25T23:36:08.666531+00:00", "data": {"market": "0x76151c30f23ef5ee963e2f73fa49d5433b4db34839c39383bee4989cb270b639", "price_changes": [{"asset_id": "23504259219851075832272877441883189669703359970946991544021206156288112345254", "price": "0.94", "size": "12.47", "side": "SELL", "hash": "d9bcc95678b95bdfafc3ed3bafeb4847f1aab5fe", "best_bid": "0.8", "best_ask": "0.83"}, {"asset_id": "92714767158282519723247724560387828941593726179269759014514785099742463503662", "price": "0.06", "size": "12.47", "side": "BUY", "hash": "d36b2fc01419d92d2b4f4b34c6e7104ee0b02f42", "best_bid": "0.17", "best_ask": "0.2"}], "timestamp": "1769384168600", "event_type": "price_change"}}
{"_local_timestamp": "2026-01-25T23:36:08.688930+00:00", "data": {"market": "0x76151c30f23ef5ee963e2f73fa49d5433b4db34839c39383bee4989cb270b639", "price_changes": [{"asset_id": "23504259219851075832272877441883189669703359970946991544021206156288112345254", "price": "0.92", "size": "225", "side": "SELL", "hash": "498c21835ce9df956e85fb114c7809a24e545527", "best_bid": "0.8", "best_ask": "0.83"}, {"asset_id": "92714767158282519723247724560387828941593726179269759014514785099742463503662", "price": "0.08", "size": "225", "side": "BUY", "hash": "6b69ff77a9b3fb72893651c2790fe34b2666fb97", "best_bid": "0.17", "best_ask": "0.2"}], "timestamp": "1769384168624", "event_type": "price_change"}}
{"_local_timestamp": "2026-01-25T23:36:12.360108+00:00", "data": {"market": "0x76151c30f23ef5ee963e2f73fa49d5433b4db34839c39383bee4989cb270b639", "price_changes": [{"asset_id": "92714767158282519723247724560387828941593726179269759014514785099742463503662", "price": "0.07", "size": "0", "side": "BUY", "hash": "6947e2c26b39cf2701871acc0a225116f5b5b376", "best_bid": "0.17", "best_ask": "0.2"}, {"asset_id": "23504259219851075832272877441883189669703359970946991544021206156288112345254", "price": "0.93", "size": "0", "side": "SELL", "hash": "00aa8d06967c311f8d2ae63c6bc8ebd4a4d67446", "best_bid": "0.8", "best_ask": "0.83"}], "timestamp": "1769384172292", "event_type": "price_change"}}
{"_local_timestamp": "2026-01-25T23:36:12.386982+00:00", "data": {"market": "0x76151c30f23ef5ee963e2f73fa49d5433b4db34839c39383bee4989cb270b639", "price_changes": [{"asset_id": "23504259219851075832272877441883189669703359970946991544021206156288112345254", "price": "0.92", "size": "0", "side": "SELL", "hash": "bd88f2b698c055407859f82c4b26b515943c6472", "best_bid": "0.8", "best_ask": "0.83"}, {"asset_id": "92714767158282519723247724560387828941593726179269759014514785099742463503662", "price": "0.08", "size": "0", "side": "BUY", "hash": "aa1c95c66e53e0f4d786dab104f84c3f98ec554d", "best_bid": "0.17", "best_ask": "0.2"}], "timestamp": "1769384172320", "event_type": "price_change"}}
{"_local_timestamp": "2026-01-25T23:36:12.941339+00:00", "data": {"market": "0x76151c30f23ef5ee963e2f73fa49d5433b4db34839c39383bee4989cb270b639", "price_changes": [{"asset_id": "92714767158282519723247724560387828941593726179269759014514785099742463503662", "price": "0.05", "size": "100", "side": "BUY", "hash": "0b4b91c9a6914173d7b5bda8e76fb1d98de42506", "best_bid": "0.17", "best_ask": "0.2"}, {"asset_id": "23504259219851075832272877441883189669703359970946991544021206156288112345254", "price": "0.95", "size": "100", "side": "SELL", "hash": "5d6bea8514135b27c88cb7a52fa34a0e6b61f580", "best_bid": "0.8", "best_ask": "0.83"}], "timestamp": "1769384172867", "event_type": "price_change"}}
{"_local_timestamp": "2026-01-25T23:36:12.961338+00:00", "data": {"market": "0x76151c30f23ef5ee963e2f73fa49d5433b4db34839c39383bee4989cb270b639", "price_changes": [{"asset_id": "23504259219851075832272877441883189669703359970946991544021206156288112345254", "price": "0.94", "size": "237.47", "side": "SELL", "hash": "802e2a150c31cf44e888ee4a1d342f9e97a95c9c", "best_bid": "0.8", "best_ask": "0.83"}, {"asset_id": "92714767158282519723247724560387828941593726179269759014514785099742463503662", "price": "0.06", "size": "237.47", "side": "BUY", "hash": "1d0b59b2e744390e87920ccd33c84defa696092f", "best_bid": "0.17", "best_ask": "0.2"}], "timestamp": "1769384172890", "event_type": "price_change"}}
{"_local_timestamp": "2026-01-25T23:36:16.607893+00:00", "data": {"market": "0x76151c30f23ef5ee963e2f73fa49d5433b4db34839c39383bee4989cb270b639", "price_changes": [{"asset_id": "92714767158282519723247724560387828941593726179269759014514785099742463503662", "price": "0.05", "size": "0", "side": "BUY", "hash": "0681587962f54b8e8c1f8bad20b1c39a5dc99629", "best_bid": "0.17", "best_ask": "0.2"}, {"asset_id": "23504259219851075832272877441883189669703359970946991544021206156288112345254", "price": "0.95", "size": "0", "side": "SELL", "hash": "8dbe55aa6cd5082791bf774f10debe245d85bc85", "best_bid": "0.8", "best_ask": "0.83"}], "timestamp": "1769384176526", "event_type": "price_change"}}
{"_local_timestamp": "2026-01-25T23:36:17.088443+00:00", "data": {"market": "0x76151c30f23ef5ee963e2f73fa49d5433b4db34839c39383bee4989cb270b639", "price_changes": [{"asset_id": "92714767158282519723247724560387828941593726179269759014514785099742463503662", "price": "0.07", "size": "100", "side": "BUY", "hash": "7cbb3fedb0333cf615ae26215593a389ae225641", "best_bid": "0.17", "best_ask": "0.2"}, {"asset_id": "23504259219851075832272877441883189669703359970946991544021206156288112345254", "price": "0.93", "size": "100", "side": "SELL", "hash": "f7f14b8e9b594a4f15142010cc2c06427428d459", "best_bid": "0.8", "best_ask": "0.83"}], "timestamp": "1769384177013", "event_type": "price_change"}}
{"_local_timestamp": "2026-01-25T23:36:17.114557+00:00", "data": {"market": "0x76151c30f23ef5ee963e2f73fa49d5433b4db34839c39383bee4989cb270b639", "price_changes": [{"asset_id": "23504259219851075832272877441883189669703359970946991544021206156288112345254", "price": "0.94", "size": "12.47", "side": "SELL", "hash": "cec8311cff89c4a9bdcdf6ac9cec57f24377b6d6", "best_bid": "0.8", "best_ask": "0.83"}, {"asset_id": "92714767158282519723247724560387828941593726179269759014514785099742463503662", "price": "0.06", "size": "12.47", "side": "BUY", "hash": "d00a5781fa9aee7cf37c7dee9ff46759e5875e85", "best_bid": "0.17", "best_ask": "0.2"}], "timestamp": "1769384177042", "event_type": "price_change"}}
{"_local_timestamp": "2026-01-25T23:36:17.135018+00:00", "data": {"market": "0x76151c30f23ef5ee963e2f73fa49d5433b4db34839c39383bee4989cb270b639", "price_changes": [{"asset_id": "23504259219851075832272877441883189669703359970946991544021206156288112345254", "price": "0.92", "size": "225", "side": "SELL", "hash": "93bc1b5b2032389b9e7b55f889a2c4611e5597b6", "best_bid": "0.8", "best_ask": "0.83"}, {"asset_id": "92714767158282519723247724560387828941593726179269759014514785099742463503662", "price": "0.08", "size": "225", "side": "BUY", "hash": "624e22d1e0384090af51217da4290edd7be07763", "best_bid": "0.17", "best_ask": "0.2"}], "timestamp": "1769384177068", "event_type": "price_change"}}
{"_local_timestamp": "2026-01-25T23:36:20.787409+00:00", "data": {"market": "0x76151c30f23ef5ee963e2f73fa49d5433b4db34839c39383bee4989cb270b639", "price_changes": [{"asset_id": "92714767158282519723247724560387828941593726179269759014514785099742463503662", "price": "0.07", "size": "0", "side": "BUY", "hash": "60e0d9c895a83974fa5aa711caac873fb5754841", "best_bid": "0.17", "best_ask": "0.2"}, {"asset_id": "23504259219851075832272877441883189669703359970946991544021206156288112345254", "price": "0.93", "size": "0", "side": "SELL", "hash": "86e162b08c73db73fc54d5230c47752ff885e041", "best_bid": "0.8", "best_ask": "0.83"}], "timestamp": "1769384180719", "event_type": "price_change"}}
{"_local_timestamp": "2026-01-25T23:36:20.814066+00:00", "data": {"market": "0x76151c30f23ef5ee963e2f73fa49d5433b4db34839c39383bee4989cb270b639", "price_changes": [{"asset_id": "23504259219851075832272877441883189669703359970946991544021206156288112345254", "price": "0.92", "size": "0", "side": "SELL", "hash": "c36c0b3d07c0d9787623fa5d5b122e27f8f35ac7", "best_bid": "0.8", "best_ask": "0.83"}, {"asset_id": "92714767158282519723247724560387828941593726179269759014514785099742463503662", "price": "0.08", "size": "0", "side": "BUY", "hash": "4f1df2597a2369af107f74c37d741c184cc06e34", "best_bid": "0.17", "best_ask": "0.2"}], "timestamp": "1769384180749", "event_type": "price_change"}}
{"_local_timestamp": "2026-01-25T23:36:21.252302+00:00", "data": {"market": "0x76151c30f23ef5ee963e2f73fa49d5433b4db34839c39383bee4989cb270b639", "price_changes": [{"asset_id": "92714767158282519723247724560387828941593726179269759014514785099742463503662", "price": "0.05", "size": "100", "side": "BUY", "hash": "c766f7b3a164834c29ddb755f5160299bcd37016", "best_bid": "0.17", "best_ask": "0.2"}, {"asset_id": "23504259219851075832272877441883189669703359970946991544021206156288112345254", "price": "0.95", "size": "100", "side": "SELL", "hash": "3511eff85797e0eb9f0e45c4c442f1ec4e5313b3", "best_bid": "0.8", "best_ask": "0.83"}], "timestamp": "1769384181184", "event_type": "price_change"}}
{"_local_timestamp": "2026-01-25T23:36:21.275731+00:00", "data": {"market": "0x76151c30f23ef5ee963e2f73fa49d5433b4db34839c39383bee4989cb270b639", "price_changes": [{"asset_id": "23504259219851075832272877441883189669703359970946991544021206156288112345254", "price": "0.94", "size": "237.47", "side": "SELL", "hash": "859c8398473a6e5419d8373ddd1f8adb07c458dd", "best_bid": "0.8", "best_ask": "0.83"}, {"asset_id": "92714767158282519723247724560387828941593726179269759014514785099742463503662", "price": "0.06", "size": "237.47", "side": "BUY", "hash": "b5c29bfba41906a88af60615c82080bec77a76f9", "best_bid": "0.17", "best_ask": "0.2"}], "timestamp": "1769384181208", "event_type": "price_change"}}
{"_local_timestamp": "2026-01-25T23:36:24.803321+00:00", "data": {"market": "0x76151c30f23ef5ee963e2f73fa49d5433b4db34839c39383bee4989cb270b639", "price_changes": [{"asset_id": "92714767158282519723247724560387828941593726179269759014514785099742463503662", "price": "0.05", "size": "0", "side": "BUY", "hash": "df9d505b3f57ff34bc56db73c2272e9d1be4af52", "best_bid": "0.17", "best_ask": "0.2"}, {"asset_id": "23504259219851075832272877441883189669703359970946991544021206156288112345254", "price": "0.95", "size": "0", "side": "SELL", "hash": "a8929de989d8dee65d19f79b5fb4862453b1ac23", "best_bid": "0.8", "best_ask": "0.83"}], "timestamp": "1769384184734", "event_type": "price_change"}}
{"_local_timestamp": "2026-01-25T23:36:25.320702+00:00", "data": {"market": "0x76151c30f23ef5ee963e2f73fa49d5433b4db34839c39383bee4989cb270b639", "price_changes": [{"asset_id": "92714767158282519723247724560387828941593726179269759014514785099742463503662", "price": "0.07", "size": "100", "side": "BUY", "hash": "1b0aeba18cc901c30f876403c076fce04b63e4e5", "best_bid": "0.17", "best_ask": "0.2"}, {"asset_id": "23504259219851075832272877441883189669703359970946991544021206156288112345254", "price": "0.93", "size": "100", "side": "SELL", "hash": "e7ae1d06c0c540d51a64ce04b5d9b931f12227ed", "best_bid": "0.8", "best_ask": "0.83"}], "timestamp": "1769384185237", "event_type": "price_change"}}
{"_local_timestamp": "2026-01-25T23:36:25.335426+00:00", "data": {"market": "0x76151c30f23ef5ee963e2f73fa49d5433b4db34839c39383bee4989cb270b639", "price_changes": [{"asset_id": "23504259219851075832272877441883189669703359970946991544021206156288112345254", "price": "0.94", "size": "12.47", "side": "SELL", "hash": "6c5814f835cdee35766487476429543abbd7d09b", "best_bid": "0.8", "best_ask": "0.83"}, {"asset_id": "92714767158282519723247724560387828941593726179269759014514785099742463503662", "price": "0.06", "size": "12.47", "side": "BUY", "hash": "e67532ac23219b264e9599e2b8387290bd746204", "best_bid": "0.17", "best_ask": "0.2"}], "timestamp": "1769384185266", "event_type": "price_change"}}
{"_local_timestamp": "2026-01-25T23:36:25.359805+00:00", "data": {"market": "0x76151c30f23ef5ee963e2f73fa49d5433b4db34839c39383bee4989cb270b639", "price_changes": [{"asset_id": "23504259219851075832272877441883189669703359970946991544021206156288112345254", "price": "0.92", "size": "225", "side": "SELL", "hash": "875ead8ecb675413da31d8b7cf11a594809f3930", "best_bid": "0.8", "best_ask": "0.83"}, {"asset_id": "92714767158282519723247724560387828941593726179269759014514785099742463503662", "price": "0.08", "size": "225", "side": "BUY", "hash": "d440398e193054e5f3ee36190165b688be7462d1", "best_bid": "0.17", "best_ask": "0.2"}], "timestamp": "1769384185293", "event_type": "price_change"}}
{"_local_timestamp": "2026-01-25T23:36:29.042752+00:00", "data": {"market": "0x76151c30f23ef5ee963e2f73fa49d5433b4db34839c39383bee4989cb270b639", "price_changes": [{"asset_id": "92714767158282519723247724560387828941593726179269759014514785099742463503662", "price": "0.07", "size": "0", "side": "BUY", "hash": "2d4b8bd7362a7a3709c3613bedbd54db6d32e374", "best_bid": "0.17", "best_ask": "0.2"}, {"asset_id": "23504259219851075832272877441883189669703359970946991544021206156288112345254", "price": "0.93", "size": "0", "side": "SELL", "hash": "520d8ca372c298349e63c634c18cac09e33f0a4e", "best_bid": "0.8", "best_ask": "0.83"}], "timestamp": "1769384188923", "event_type": "price_change"}}
{"_local_timestamp": "2026-01-25T23:36:29.116208+00:00", "data": {"market": "0x76151c30f23ef5ee963e2f73fa49d5433b4db34839c39383bee4989cb270b639", "price_changes": [{"asset_id": "23504259219851075832272877441883189669703359970946991544021206156288112345254", "price": "0.92", "size": "0", "side": "SELL", "hash": "40f4d4ffa87c7592b08c032c93755e9f529f594b", "best_bid": "0.8", "best_ask": "0.83"}, {"asset_id": "92714767158282519723247724560387828941593726179269759014514785099742463503662", "price": "0.08", "size": "0", "side": "BUY", "hash": "7f024e512216b71f5919c2255d2dc5a786cb1362", "best_bid": "0.17", "best_ask": "0.2"}], "timestamp": "1769384188996", "event_type": "price_change"}}
{"_local_timestamp": "2026-01-25T23:36:29.593766+00:00", "data": {"market": "0x76151c30f23ef5ee963e2f73fa49d5433b4db34839c39383bee4989cb270b639", "price_changes": [{"asset_id": "92714767158282519723247724560387828941593726179269759014514785099742463503662", "price": "0.05", "size": "100", "side": "BUY", "hash": "d9e8e0612fc7412cacf91e0c0a8ea9766d498dd9", "best_bid": "0.17", "best_ask": "0.2"}, {"asset_id": "23504259219851075832272877441883189669703359970946991544021206156288112345254", "price": "0.95", "size": "100", "side": "SELL", "hash": "11cdebe0d616225439d52d3e0b0dd36ffebbdbca", "best_bid": "0.8", "best_ask": "0.83"}], "timestamp": "1769384189524", "event_type": "price_change"}}
{"_local_timestamp": "2026-01-25T23:36:29.624650+00:00", "data": {"market": "0x76151c30f23ef5ee963e2f73fa49d5433b4db34839c39383bee4989cb270b639", "price_changes": [{"asset_id": "23504259219851075832272877441883189669703359970946991544021206156288112345254", "price": "0.94", "size": "237.47", "side": "SELL", "hash": "05529aee90139856e5171f7518092c3588db385f", "best_bid": "0.8", "best_ask": "0.83"}, {"asset_id": "92714767158282519723247724560387828941593726179269759014514785099742463503662", "price": "0.06", "size": "237.47", "side": "BUY", "hash": "bbc99bcb03d4ca4b56af9980d5bd60cb621aaa03", "best_bid": "0.17", "best_ask": "0.2"}], "timestamp": "1769384189552", "event_type": "price_change"}}
{"_local_timestamp": "2026-01-25T23:36:33.361428+00:00", "data": {"market": "0x76151c30f23ef5ee963e2f73fa49d5433b4db34839c39383bee4989cb270b639", "price_changes": [{"asset_id": "92714767158282519723247724560387828941593726179269759014514785099742463503662", "price": "0.05", "size": "0", "side": "BUY", "hash": "42211c2fe662d571dc0b4e2481c1f70f0009387a", "best_bid": "0.17", "best_ask": "0.2"}, {"asset_id": "23504259219851075832272877441883189669703359970946991544021206156288112345254", "price": "0.95", "size": "0", "side": "SELL", "hash": "664d2112e5a181c321e2915cd5c1d211145489f1", "best_bid": "0.8", "best_ask": "0.83"}], "timestamp": "1769384193285", "event_type": "price_change"}}
{"_local_timestamp": "2026-01-25T23:36:34.076704+00:00", "data": {"market": "0x76151c30f23ef5ee963e2f73fa49d5433b4db34839c39383bee4989cb270b639", "price_changes": [{"asset_id": "92714767158282519723247724560387828941593726179269759014514785099742463503662", "price": "0.07", "size": "100", "side": "BUY", "hash": "8afd4af13b109bc168758c9634fda3a75f8a18e0", "best_bid": "0.17", "best_ask": "0.2"}, {"asset_id": "23504259219851075832272877441883189669703359970946991544021206156288112345254", "price": "0.93", "size": "100", "side": "SELL", "hash": "eb85e7345f8efeec256c2df770132c87f16b5309", "best_bid": "0.8", "best_ask": "0.83"}], "timestamp": "1769384194001", "event_type": "price_change"}}
{"_local_timestamp": "2026-01-25T23:36:34.101041+00:00", "data": {"market": "0x76151c30f23ef5ee963e2f73fa49d5433b4db34839c39383bee4989cb270b639", "price_changes": [{"asset_id": "92714767158282519723247724560387828941593726179269759014514785099742463503662", "price": "0.13", "size": "69", "side": "BUY", "hash": "a2a1857aac0a64f13d5b3ee4cec834f0b9b58953", "best_bid": "0.17", "best_ask": "0.2"}, {"asset_id": "23504259219851075832272877441883189669703359970946991544021206156288112345254", "price": "0.87", "size": "69", "side": "SELL", "hash": "0bcee441c73ac1ce199645fd6f8038cf67c31800", "best_bid": "0.8", "best_ask": "0.83"}], "timestamp": "1769384194004", "event_type": "price_change"}}
{"_local_timestamp": "2026-01-25T23:36:34.151102+00:00", "data": {"market": "0x76151c30f23ef5ee963e2f73fa49d5433b4db34839c39383bee4989cb270b639", "price_changes": [{"asset_id": "23504259219851075832272877441883189669703359970946991544021206156288112345254", "price": "0.94", "size": "12.47", "side": "SELL", "hash": "1ce423e5969a628db80f8235a8efc65eaf18b10b", "best_bid": "0.8", "best_ask": "0.83"}, {"asset_id": "92714767158282519723247724560387828941593726179269759014514785099742463503662", "price": "0.06", "size": "12.47", "side": "BUY", "hash": "91c15a0dcb26acc6ba85d68d354f50231dfe314e", "best_bid": "0.17", "best_ask": "0.2"}], "timestamp": "1769384194030", "event_type": "price_change"}}
{"_local_timestamp": "2026-01-25T23:36:37.793300+00:00", "data": {"market": "0x76151c30f23ef5ee963e2f73fa49d5433b4db34839c39383bee4989cb270b639", "price_changes": [{"asset_id": "92714767158282519723247724560387828941593726179269759014514785099742463503662", "price": "0.07", "size": "0", "side": "BUY", "hash": "d5cf7b508b9cb2ee07db67ee1c240ff848b9fbb0", "best_bid": "0.17", "best_ask": "0.2"}, {"asset_id": "23504259219851075832272877441883189669703359970946991544021206156288112345254", "price": "0.93", "size": "0", "side": "SELL", "hash": "75c9fa1b837753b0669117d45a2cc9df3a0c87b9", "best_bid": "0.8", "best_ask": "0.83"}], "timestamp": "1769384197712", "event_type": "price_change"}}
{"_local_timestamp": "2026-01-25T23:36:38.385649+00:00", "data": {"market": "0x76151c30f23ef5ee963e2f73fa49d5433b4db34839c39383bee4989cb270b639", "price_changes": [{"asset_id": "92714767158282519723247724560387828941593726179269759014514785099742463503662", "price": "0.14", "size": "100", "side": "BUY", "hash": "0a00e5e6188403c14bd6e0c11a5412de5b8a82c5", "best_bid": "0.17", "best_ask": "0.2"}, {"asset_id": "23504259219851075832272877441883189669703359970946991544021206156288112345254", "price": "0.86", "size": "100", "side": "SELL", "hash": "fc7294af8d188b8229d9e08d1c550ea1cc2550c8", "best_bid": "0.8", "best_ask": "0.83"}], "timestamp": "1769384198311", "event_type": "price_change"}}
{"_local_timestamp": "2026-01-25T23:36:43.728631+00:00", "data": {"market": "0x76151c30f23ef5ee963e2f73fa49d5433b4db34839c39383bee4989cb270b639", "price_changes": [{"asset_id": "92714767158282519723247724560387828941593726179269759014514785099742463503662", "price": "0.14", "size": "200", "side": "BUY", "hash": "adc9734e45d45412193fbc7c747fcfe0db8ab9ec", "best_bid": "0.17", "best_ask": "0.2"}, {"asset_id": "23504259219851075832272877441883189669703359970946991544021206156288112345254", "price": "0.86", "size": "200", "side": "SELL", "hash": "0103881e5c09f14e803bd7cbbbbb375b920ccaee", "best_bid": "0.8", "best_ask": "0.83"}], "timestamp": "1769384203642", "event_type": "price_change"}}
{"_local_timestamp": "2026-01-25T23:36:46.369280+00:00", "data": {"market": "0x76151c30f23ef5ee963e2f73fa49d5433b4db34839c39383bee4989cb270b639", "price_changes": [{"asset_id": "92714767158282519723247724560387828941593726179269759014514785099742463503662", "price": "0.14", "size": "100", "side": "BUY", "hash": "8c9a31eb9088f68e712f30c73a279f9d46bbadce", "best_bid": "0.17", "best_ask": "0.2"}, {"asset_id": "23504259219851075832272877441883189669703359970946991544021206156288112345254", "price": "0.86", "size": "100", "side": "SELL", "hash": "90c4c5886916d30654a2d08ada9ff77cc98aad93", "best_bid": "0.8", "best_ask": "0.83"}], "timestamp": "1769384206258", "event_type": "price_change"}}
{"_local_timestamp": "2026-01-25T23:36:46.865483+00:00", "data": {"market": "0x76151c30f23ef5ee963e2f73fa49d5433b4db34839c39383bee4989cb270b639", "price_changes": [{"asset_id": "92714767158282519723247724560387828941593726179269759014514785099742463503662", "price": "0.15", "size": "105.56", "side": "BUY", "hash": "bccd2a9b7c5ae12938c7aadc9d50c485e71f5ecc", "best_bid": "0.17", "best_ask": "0.2"}, {"asset_id": "23504259219851075832272877441883189669703359970946991544021206156288112345254", "price": "0.85", "size": "105.56", "side": "SELL", "hash": "bd91006180d191f38f7dffc7c4cd832be4793ca7", "best_bid": "0.8", "best_ask": "0.83"}], "timestamp": "1769384206801", "event_type": "price_change"}}
{"_local_timestamp": "2026-01-25T23:36:59.873060+00:00", "data": {"market": "0x76151c30f23ef5ee963e2f73fa49d5433b4db34839c39383bee4989cb270b639", "price_changes": [{"asset_id": "92714767158282519723247724560387828941593726179269759014514785099742463503662", "price": "0.06", "size": "0", "side": "BUY", "hash": "29137715e7b7ae925b178d370243b279bc7b1594", "best_bid": "0.17", "best_ask": "0.2"}, {"asset_id": "23504259219851075832272877441883189669703359970946991544021206156288112345254", "price": "0.94", "size": "0", "side": "SELL", "hash": "b6f7dbce34cca247c629a096355178a67e511588", "best_bid": "0.8", "best_ask": "0.83"}], "timestamp": "1769384219804", "event_type": "price_change"}}
{"_local_timestamp": "2026-01-25T23:36:59.880240+00:00", "data": {"market": "0x76151c30f23ef5ee963e2f73fa49d5433b4db34839c39383bee4989cb270b639", "price_changes": [{"asset_id": "23504259219851075832272877441883189669703359970946991544021206156288112345254", "price": "0.08", "size": "0", "side": "BUY", "hash": "a46f4caf8e56ca55c2b5a5560d07ba56badc38b2", "best_bid": "0.8", "best_ask": "0.83"}, {"asset_id": "92714767158282519723247724560387828941593726179269759014514785099742463503662", "price": "0.92", "size": "0", "side": "SELL", "hash": "f4830908d0c717255a191dd5905b513214553f95", "best_bid": "0.17", "best_ask": "0.2"}], "timestamp": "1769384219805", "event_type": "price_change"}}
{"_local_timestamp": "2026-01-25T23:37:02.274930+00:00", "data": {"market": "0x76151c30f23ef5ee963e2f73fa49d5433b4db34839c39383bee4989cb270b639", "price_changes": [{"asset_id": "23504259219851075832272877441883189669703359970946991544021206156288112345254", "price": "0.08", "size": "5", "side": "BUY", "hash": "ce36c261c34e346fa560a2a44ac58cd8cf54c5d4", "best_bid": "0.8", "best_ask": "0.83"}, {"asset_id": "92714767158282519723247724560387828941593726179269759014514785099742463503662", "price": "0.92", "size": "5", "side": "SELL", "hash": "4ae779d8e24ef6cb00b137e6450bce6b81156f39", "best_bid": "0.17", "best_ask": "0.2"}], "timestamp": "1769384222203", "event_type": "price_change"}}
{"_local_timestamp": "2026-01-25T23:37:02.275518+00:00", "data": {"market": "0x76151c30f23ef5ee963e2f73fa49d5433b4db34839c39383bee4989cb270b639", "price_changes": [{"asset_id": "92714767158282519723247724560387828941593726179269759014514785099742463503662", "price": "0.05", "size": "14.97", "side": "BUY", "hash": "f806120e0204c05d4236875d965c5192fe54e150", "best_bid": "0.17", "best_ask": "0.2"}, {"asset_id": "23504259219851075832272877441883189669703359970946991544021206156288112345254", "price": "0.95", "size": "14.97", "side": "SELL", "hash": "4c215e41ed840e006efe17beb955d4b3c517952e", "best_bid": "0.8", "best_ask": "0.83"}], "timestamp": "1769384222205", "event_type": "price_change"}}
