{"_local_timestamp": "2026-01-25T23:40:43.465846+00:00", "data": [{"market": "0x02d056b4ecb79134657b5437bcdd964a7b4008def9f7623e8e1c3a2652996390", "asset_id": "75662091824125558301238389247455078817972039140363353111649504086477915930016", "timestamp": "1769384428730", "hash": "0dd2d148b1e4c0fd024740a10185581d18265979", "bids": [{"price": "0.01", "size": "19.72"}, {"price": "0.02", "size": "5.47"}], "asks": [{"price": "0.99", "size": "79.48"}, {"price": "0.97", "size": "50"}], "event_type": "book", "last_trade_price": "0.730"}, {"market": "0x8e8d315038e54eb4b3b7108ebfc48986e286dd3a53408a293263c73bb64040be", "asset_id": "45695296729134875133282986964941962331716131780439753949097910486621574361250", "timestamp": "1769384410811", "hash": "9e945b85ff77580fd3eca750be13302ba3d42e72", "bids": [{"price": "0.01", "size": "19.71"}, {"price": "0.02", "size": "5.47"}], "asks": [{"price": "0.99", "size": "58.97"}, {"price": "0.98", "size": "5.47"}], "event_type": "book", "last_trade_price": "0.520"}, {"market": "0xe4088389ccc112ce566307b0535326b545db27823876138c37abc36aa80f01b6", "asset_id": "111535201652442500376681045716896114819862357479074857390925141208753505497603", "timestamp": "1769384442610", "hash": "76bb08bd0bbb179dbe100ac9fcaf6162856b8343", "bids": [{"price": "0.001", "size": "856.14"}, {"price": "0.002", "size": "359.24"}, {"price": "0.01", "size": "10000"}, {"price": "0.05", "size": "5.47"}, {"price": "0.051", "size": "5.36"}, {"price": "0.85", "size": "16.99"}, {"price": "0.91", "size": "559"}, {"price": "0.911", "size": "30"}, {"price": "0.912", "size": "5.47"}, {"price": "0.98", "size": "244.94"}, {"price": "0.99", "size": "274"}], "asks": [{"price": "0.999", "size": "969"}], "event_type": "book", "last_trade_price": "0.010"}, {"market": "0x1172a9379540e31c463e178f08c87f67eb0011ba0deadcd67f78f0028d27f41a", "asset_id": "96693063570682405603148415870765547887123700438364743392828151015298561276130", "timestamp": "1769384442778", "hash": "bf5e7ff40d453fe8f8779b261ef0988512e13869", "bids": [{"price": "0.001", "size": "851"}, {"price": "0.002", "size": "192.3"}, {"price": "0.01", "size": "163.22"}], "asks": [{"price": "0.999", "size": "1256.4"}, {"price": "0.998", "size": "173.3"}, {"price": "0.99", "size": "800"}, {"price": "0.98", "size": "800"}, {"price": "0.95", "size": "1500"}, {"price": "0.92", "size": "600"}, {"price": "0.919", "size": "8"}, {"price": "0.86", "size": "1009"}, {"price": "0.859", "size": "30"}, {"price": "0.7", "size": "21.11"}, {"price": "0.46", "size": "26.69"}, {"price": "0.37", "size": "17.79"}, {"price": "0.2", "size": "30.83"}, {"price": "0.19", "size": "20"}, {"price": "0.17", "size": "123.72"}, {"price": "0.15", "size": "10"}, {"price": "0.14", "size": "6.67"}, {"price": "0.05", "size": "275.86"}], "event_type": "book", "last_trade_price": "0.950"}, {"market": "0x45c806ae01123f47e7f24fea279b8658a4112cdaa11eee2f9924838a8948bc98", "asset_id": "32694948455525029678981577699677214621056167573486416032284086638717669535526", "timestamp": "1769384438571", "hash": "3e085328fe43bacea98e0e01dcf48c284d658519", "bids": [{"price": "0.001", "size": "921"}], "asks": [{"price": "0.999", "size": "909.85"}, {"price": "0.998", "size": "470.57"}, {"price": "0.93", "size": "100"}, {"price": "0.929", "size": "91.79"}, {"price": "0.911", "size": "8.2"}, {"price": "0.91", "size": "5.47"}], "event_type": "book", "last_trade_price": "0.990"}, {"market": "0xe40aca7194b6ed6c98d54fcd1338d41c30d5265d68d7468fdb3afcca62e8d6c3", "asset_id": "82306081970048077348294633861982165617205411236349395805461913184457941025697", "timestamp": "1769384419099", "hash": "136a1d91ec8252816c193dba378a48030d526b5a", "bids": [{"price": "0.01", "size": "20"}, {"price": "0.02", "size": "5.47"}], "asks": [{"price": "0.99", "size": "38.46"}], "event_type": "book", "last_trade_price": ""}, {"market": "0xe40aca7194b6ed6c98d54fcd1338d41c30d5265d68d7468fdb3afcca62e8d6c3", "asset_id": "21516192838799393436877283935602059956906510510942747966420810813105259210660", "timestamp": "1769384419099", "hash": "10f63b36a8a7a6c17e4f0843669310edca98169d", "bids": [{"price": "0.01", "size": "38.46"}], "asks": [{"price": "0.99", "size": "20"}, {"price": "0.98", "size": "5.47"}], "event_type": "book", "last_trade_price": ""}, {"market": "0xe4088389ccc112ce566307b0535326b545db27823876138c37abc36aa80f01b6", "asset_id": "68036185336858618606129914327232954729196470841777365764843049597359907094650", "timestamp": "1769384442610", "hash": "f0d5bf079928063bfe377f9aa7993c2251a2e870", "bids": [{"price": "0.001", "size": "969"}], "asks": [{"price": "0.999", "size": "856.14"}, {"price": "0.998", "size": "359.24"}, {"price": "0.99", "size": "10000"}, {"price": "0.95", "size": "5.47"}, {"price": "0.949", "size": "5.36"}, {"price": "0.15", "size": "16.99"}, {"price": "0.09", "size": "559"}, {"price": "0.089", "size": "30"}, {"price": "0.088", "size": "5.47"}, {"price": "0.02", "size": "244.94"}, {"price": "0.01", "size": "274"}], "event_type": "book", "last_trade_price": "0.010"}, {"market": "0x4d351854a5011cdb0c141ef8d87a8321213d1e0a3b258a3745c03d34dd85d7a7", "asset_id": "89397257210211231854366309279840798542964120041524548078365395989129276413393", "timestamp": "1769384417723", "hash": "4a4a73ae7596c6e2a74efce1faa511d395bbfb4e", "bids": [{"price": "0.01", "size": "20"}, {"price": "0.02", "size": "5.47"}], "asks": [{"price": "0.99", "size": "38.46"}], "event_type": "book", "last_trade_price": ""}, {"market": "0x45c806ae01123f47e7f24fea279b8658a4112cdaa11eee2f9924838a8948bc98", "asset_id": "56387091315659274606744882547186473603552761496368462985420229575757384495074", "timestamp": "1769384438571", "hash": "4099144d5de1afbdb1b781fb9fab3b8ed20bc21b", "bids": [{"price": "0.001", "size": "909.85"}, {"price": "0.002", "size": "470.57"}, {"price": "0.07", "size": "100"}, {"price": "0.071", "size": "91.79"}, {"price": "0.089", "size": "8.2"}, {"price": "0.09", "size": "5.47"}], "asks": [{"price": "0.999", "size": "921"}], "event_type": "book", "last_trade_price": "0.990"}, {"market": "0x4d351854a5011cdb0c141ef8d87a8321213d1e0a3b258a3745c03d34dd85d7a7", "asset_id": "30230407831690929960155342999106742333605054613110743527797581940998715084536", "timestamp": "1769384417723", "hash": "fc816cdd9637e1a340d265537c100d63a4d6ec82", "bids": [{"price": "0.01", "size": "38.46"}], "asks": [{"price": "0.99", "size": "20"}, {"price": "0.98", "size": "5.47"}], "event_type": "book", "last_trade_price": ""}, {"market": "0x1034c0e02d8dfd2ab20e470f52ca04b68522fae5d494fc572ca5d3590b02835f", "asset_id": "109653806991348106381704906477880080588164300975962366805991276498248359611032", "timestamp": "1769382581557", "hash": "dd067fdeb4e652e2ace1137dcba48d1fa9b62a03", "bids": [{"price": "0.01", "size": "20"}, {"price": "0.02", "size": "5.47"}], "asks": [{"price": "0.99", "size": "14.3"}], "event_type": "book", "last_trade_price": ""}, {"market": "0x1172a9379540e31c463e178f08c87f67eb0011ba0deadcd67f78f0028d27f41a", "asset_id": "108433110821297511084165806800149498872896490798393090117171505493034184915983", "timestamp": "1769384442778", "hash": "c156f9e9af181d7d2b974df61ca6c59fcc4a4f95", "bids": [{"price": "0.001", "size": "1256.4"}, {"price": "0.002", "size": "173.3"}, {"price": "0.01", "size": "800"}, {"price": "0.02", "size": "800"}, {"price": "0.05", "size": "1500"}, {"price": "0.08", "size": "600"}, {"price": "0.081", "size": "8"}, {"price": "0.14", "size": "1009"}, {"price": "0.141", "size": "30"}, {"price": "0.3", "size": "21.11"}, {"price": "0.54", "size": "26.69"}, {"price": "0.63", "size": "17.79"}, {"price": "0.8", "size": "30.83"}, {"price": "0.81", "size": "20"}, {"price": "0.83", "size": "123.72"}, {"price": "0.85", "size": "10"}, {"price": "0.86", "size": "6.67"}, {"price": "0.95", "size": "275.86"}], "asks": [{"price": "0.999", "size": "851"}, {"price": "0.998", "size": "192.3"}, {"price": "0.99", "size": "163.22"}], "event_type": "book", "last_trade_price": "0.950"}, {"market": "0x1034c0e02d8dfd2ab20e470f52ca04b68522fae5d494fc572ca5d3590b02835f", "asset_id": "19434406161610449353542690506540715576604788497292816963861301483950307829394", "timestamp": "1769382581557", "hash": "9b4a00dab337ef704c611793adfcbff41d02b5c2", "bids": [{"price": "0.01", "size": "14.3"}], "asks": [{"price": "0.99", "size": "20"}, {"price": "0.98", "size": "5.47"}], "event_type": "book", "last_trade_price": ""}, {"market": "0x8e8d315038e54eb4b3b7108ebfc48986e286dd3a53408a293263c73bb64040be", "asset_id": "73877455263924215947237673601962666377355671254828449751196120845554792983538", "timestamp": "1769384410811", "hash": "e90601bedd6ea1f54437a831bd19ac0bef39af86", "bids": [{"price": "0.01", "size": "58.97"}, {"price": "0.02", "size": "5.47"}], "asks": [{"price": "0.99", "size": "19.71"}, {"price": "0.98", "size": "5.47"}], "event_type": "book", "last_trade_price": "0.520"}, {"market": "0x02d056b4ecb79134657b5437bcdd964a7b4008def9f7623e8e1c3a2652996390", "asset_id": "75572739037384917026708802532724608493252666334200100326455332920422495907885", "timestamp": "1769384428730", "hash": "fff4f60479c37a8f358c6227408df8926c277a0c", "bids": [{"price": "0.01", "size": "79.48"}, {"price": "0.03", "size": "50"}], "asks": [{"price": "0.99", "size": "19.72"}, {"price": "0.98", "size": "5.47"}], "event_type": "book", "last_trade_price": "0.730"}]}
{"_local_timestamp": "2026-01-25T23:40:43.811349+00:00", "data": {"market": "0x1172a9379540e31c463e178f08c87f67eb0011ba0deadcd67f78f0028d27f41a", "price_changes": [{"asset_id": "108433110821297511084165806800149498872896490798393090117171505493034184915983", "price": "0.83", "size": "23.72", "side": "BUY", "hash": "b2c9e2333d2ad00c99566525789f20e99c4fc36f", "best_bid": "0.95", "best_ask": "0.99"}, {"asset_id": "96693063570682405603148415870765547887123700438364743392828151015298561276130", "price": "0.17", "size": "23.72", "side": "SELL", "hash": "ab135dc474bdd7de8396f0ad8347e512518bcb47", "best_bid": "0.01", "best_ask": "0.05"}], "timestamp": "1769384443724", "event_type": "price_change"}}
{"_local_timestamp": "2026-01-25T23:40:43.850677+00:00", "data": {"market": "0x1172a9379540e31c463e178f08c87f67eb0011ba0deadcd67f78f0028d27f41a", "price_changes": [{"asset_id": "108433110821297511084165806800149498872896490798393090117171505493034184915983", "price": "0.83", "size": "123.72", "side": "BUY", "hash": "475ada3985b5de3070f262c27643af42486c4536", "best_bid": "0.95", "best_ask": "0.99"}, {"asset_id": "96693063570682405603148415870765547887123700438364743392828151015298561276130", "price": "0.17", "size": "123.72", "side": "SELL", "hash": "6e1514b1f621b56fed653c7476b5568b31515886", "best_bid": "0.01", "best_ask": "0.05"}], "timestamp": "1769384443775", "event_type": "price_change"}}
{"_local_timestamp": "2026-01-25T23:40:43.976392+00:00", "data": {"market": "0xe4088389ccc112ce566307b0535326b545db27823876138c37abc36aa80f01b6", "price_changes": [{"asset_id": "111535201652442500376681045716896114819862357479074857390925141208753505497603", "price": "0.002", "size": "30.08", "side": "BUY", "hash": "f7818201dce028e116eeabd6124a08ee3d0c1282", "best_bid": "0.99", "best_ask": "0.999"}, {"asset_id": "68036185336858618606129914327232954729196470841777365764843049597359907094650", "price": "0.998", "size": "30.08", "side": "SELL", "hash": "04b7eb88809cf246aaad6ed384cc751a61dba9a4", "best_bid": "0.001", "best_ask": "0.01"}], "timestamp": "1769384443910", "event_type": "price_change"}}
{"_local_timestamp": "2026-01-25T23:40:44.157275+00:00", "data": {"market": "0xe4088389ccc112ce566307b0535326b545db27823876138c37abc36aa80f01b6", "price_changes": [{"asset_id": "111535201652442500376681045716896114819862357479074857390925141208753505497603", "price": "0.011", "size": "29.92", "side": "BUY", "hash": "023e01ba7022e2f142ed981c91b965ced71025cd", "best_bid": "0.99", "best_ask": "0.999"}, {"asset_id": "68036185336858618606129914327232954729196470841777365764843049597359907094650", "price": "0.989", "size": "29.92", "side": "SELL", "hash": "0addc4d5bdbc8e85b4ac80fa6d6026b32d3ce5ae", "best_bid": "0.001", "best_ask": "0.01"}], "timestamp": "1769384444083", "event_type": "price_change"}}
{"_local_timestamp": "2026-01-25T23:40:44.159592+00:00", "data": {"market": "0xe4088389ccc112ce566307b0535326b545db27823876138c37abc36aa80f01b6", "price_changes": [{"asset_id": "111535201652442500376681045716896114819862357479074857390925141208753505497603", "price": "0.011", "size": "59.84", "side": "BUY", "hash": "669bb7d2bfee60f10d79ac494800ef53cf937b87", "best_bid": "0.99", "best_ask": "0.999"}, {"asset_id": "68036185336858618606129914327232954729196470841777365764843049597359907094650", "price": "0.989", "size": "59.84", "side": "SELL", "hash": "21d1560b28aa44b0f40d3f8bfaead78987a1b57c", "best_bid": "0.001", "best_ask": "0.01"}], "timestamp": "1769384444084", "event_type": "price_change"}}
{"_local_timestamp": "2026-01-25T23:40:45.759541+00:00", "data": {"market": "0x1172a9379540e31c463e178f08c87f67eb0011ba0deadcd67f78f0028d27f41a", "price_changes": [{"asset_id": "108433110821297511084165806800149498872896490798393090117171505493034184915983", "price": "0.002", "size": "23.63", "side": "BUY", "hash": "b8b36a836816e8cf458c0d46a571794cbcac6ad0", "best_bid": "0.95", "best_ask": "0.99"}, {"asset_id": "96693063570682405603148415870765547887123700438364743392828151015298561276130", "price": "0.998", "size": "23.63", "side": "SELL", "hash": "0f6a97e50aef559c8c8ae4df4b5b8020349a4657", "best_bid": "0.01", "best_ask": "0.05"}], "timestamp": "1769384445684", "event_type": "price_change"}}
{"_local_timestamp": "2026-01-25T23:40:46.565962+00:00", "data": {"market": "0x1172a9379540e31c463e178f08c87f67eb0011ba0deadcd67f78f0028d27f41a", "price_changes": [{"asset_id": "108433110821297511084165806800149498872896490798393090117171505493034184915983", "price": "0.002", "size": "48.55", "side": "BUY", "hash": "0d25442ecd0ea7edc8f9260697ad68090c0b5a3d", "best_bid": "0.95", "best_ask": "0.99"}, {"asset_id": "96693063570682405603148415870765547887123700438364743392828151015298561276130", "price": "0.998", "size": "48.55", "side": "SELL", "hash": "cd7ef40b2a6a441d40b621a8d1bda31e0e7e2d3c", "best_bid": "0.01", "best_ask": "0.05"}], "timestamp": "1769384446498", "event_type": "price_change"}}
{"_local_timestamp": "2026-01-25T23:40:46.566503+00:00", "data": {"market": "0x1172a9379540e31c463e178f08c87f67eb0011ba0deadcd67f78f0028d27f41a", "price_changes": [{"asset_id": "108433110821297511084165806800149498872896490798393090117171505493034184915983", "price": "0.021", "size": "11.88", "side": "BUY", "hash": "1fdc84ea6c16d2211b2719b4994736b265375415", "best_bid": "0.95", "best_ask": "0.99"}, {"asset_id": "96693063570682405603148415870765547887123700438364743392828151015298561276130", "price": "0.979", "size": "11.88", "side": "SELL", "hash": "70b8f242783d5dbc0b79fd2d050c1ff37e26cd65", "best_bid": "0.01", "best_ask": "0.05"}], "timestamp": "1769384446499", "event_type": "price_change"}}
{"_local_timestamp": "2026-01-25T23:40:46.797327+00:00", "data": {"market": "0x1172a9379540e31c463e178f08c87f67eb0011ba0deadcd67f78f0028d27f41a", "price_changes": [{"asset_id": "96693063570682405603148415870765547887123700438364743392828151015298561276130", "price": "0.002", "size": "144.23", "side": "BUY", "hash": "759f55ef58716c56015f72102b7f2823c5a18e33", "best_bid": "0.01", "best_ask": "0.05"}, {"asset_id": "108433110821297511084165806800149498872896490798393090117171505493034184915983", "price": "0.998", "size": "144.23", "side": "SELL", "hash": "d24b26cbbb5425e238ea01cc9e907188c151fd44", "best_bid": "0.95", "best_ask": "0.99"}], "timestamp": "1769384446730", "event_type": "price_change"}}
{"_local_timestamp": "2026-01-25T23:40:47.084472+00:00", "data": {"market": "0x1172a9379540e31c463e178f08c87f67eb0011ba0deadcd67f78f0028d27f41a", "price_changes": [{"asset_id": "108433110821297511084165806800149498872896490798393090117171505493034184915983", "price": "0.14", "size": "300", "side": "BUY", "hash": "c1d49872e9f518dbfd0140dc3e1cf5f8418a766c", "best_bid": "0.95", "best_ask": "0.99"}, {"asset_id": "96693063570682405603148415870765547887123700438364743392828151015298561276130", "price": "0.86", "size": "300", "side": "SELL", "hash": "18655c6a364de26c4d69d04a259bc2f05ea9e919", "best_bid": "0.01", "best_ask": "0.05"}], "timestamp": "1769384447001", "event_type": "price_change"}}
{"_local_timestamp": "2026-01-25T23:40:47.106925+00:00", "data": {"market": "0xe4088389ccc112ce566307b0535326b545db27823876138c37abc36aa80f01b6", "price_changes": [{"asset_id": "111535201652442500376681045716896114819862357479074857390925141208753505497603", "price": "0.01", "size": "0", "side": "BUY", "hash": "0e6a244ff30f2d7abfd10d6ed7651a05dfeffb7c", "best_bid": "0.99", "best_ask": "0.999"}, {"asset_id": "68036185336858618606129914327232954729196470841777365764843049597359907094650", "price": "0.99", "size": "0", "side": "SELL", "hash": "bba227d275402b6c53334c1e04a5fb494e909034", "best_bid": "0.001", "best_ask": "0.01"}], "timestamp": "1769384447001", "event_type": "price_change"}}
{"_local_timestamp": "2026-01-25T23:40:47.115803+00:00", "data": {"market": "0x1172a9379540e31c463e178f08c87f67eb0011ba0deadcd67f78f0028d27f41a", "price_changes": [{"asset_id": "96693063570682405603148415870765547887123700438364743392828151015298561276130", "price": "0.002", "size": "192.3", "side": "BUY", "hash": "c33a339d4a4e09fdce99502599c95202538e4b75", "best_bid": "0.01", "best_ask": "0.05"}, {"asset_id": "108433110821297511084165806800149498872896490798393090117171505493034184915983", "price": "0.998", "size": "192.3", "side": "SELL", "hash": "0beea4a4cb228b36a2384848c9af7974e0769700", "best_bid": "0.95", "best_ask": "0.99"}], "timestamp": "1769384447021", "event_type": "price_change"}}
{"_local_timestamp": "2026-01-25T23:40:47.661407+00:00", "data": {"market": "0x1172a9379540e31c463e178f08c87f67eb0011ba0deadcd67f78f0028d27f41a", "price_changes": [{"asset_id": "96693063570682405603148415870765547887123700438364743392828151015298561276130", "price": "0.011", "size": "5.47", "side": "BUY", "hash": "8ba5d2474c5693c829f7417eb1132de286a3285b", "best_bid": "0.011", "best_ask": "0.05"}, {"asset_id": "108433110821297511084165806800149498872896490798393090117171505493034184915983", "price": "0.989", "size": "5.47", "side": "SELL", "hash": "fb6ecb24a5d7e9a5226855d9585afb9eb2b72118", "best_bid": "0.95", "best_ask": "0.989"}], "timestamp": "1769384447587", "event_type": "price_change"}}
{"_local_timestamp": "2026-01-25T23:40:47.681565+00:00", "data": {"market": "0xe4088389ccc112ce566307b0535326b545db27823876138c37abc36aa80f01b6", "price_changes": [{"asset_id": "111535201652442500376681045716896114819862357479074857390925141208753505497603", "price": "0.002", "size": "22.33", "side": "BUY", "hash": "bcdacac96282e3f8591407b1ef187dead59858cd", "best_bid": "0.99", "best_ask": "0.999"}, {"asset_id": "68036185336858618606129914327232954729196470841777365764843049597359907094650", "price": "0.998", "size": "22.33", "side": "SELL", "hash": "25a7e8b828216a0dea0fe21c14a7e9589500b36a", "best_bid": "0.001", "best_ask": "0.01"}], "timestamp": "1769384447606", "event_type": "price_change"}}
{"_local_timestamp": "2026-01-25T23:40:47.970335+00:00", "data": {"market": "0xe4088389ccc112ce566307b0535326b545db27823876138c37abc36aa80f01b6", "price_changes": [{"asset_id": "111535201652442500376681045716896114819862357479074857390925141208753505497603", "price": "0.002", "size": "30.13", "side": "BUY", "hash": "83b251fefc3d525c92627bb95ee9db71f1458be2", "best_bid": "0.99", "best_ask": "0.999"}, {"asset_id": "68036185336858618606129914327232954729196470841777365764843049597359907094650", "price": "0.998", "size": "30.13", "side": "SELL", "hash": "80d3e9399ca72c8857adcff832d8c59f6529d785", "best_bid": "0.001", "best_ask": "0.01"}], "timestamp": "1769384447899", "event_type": "price_change"}}
{"_local_timestamp": "2026-01-25T23:40:48.276523+00:00", "data": {"market": "0xe4088389ccc112ce566307b0535326b545db27823876138c37abc36aa80f01b6", "price_changes": [{"asset_id": "111535201652442500376681045716896114819862357479074857390925141208753505497603", "price": "0.01", "size": "8333", "side": "BUY", "hash": "9cc4730ec9b779fdc4d8286639f4293b8c2e6309", "best_bid": "0.99", "best_ask": "0.999"}, {"asset_id": "68036185336858618606129914327232954729196470841777365764843049597359907094650", "price": "0.99", "size": "8333", "side": "SELL", "hash": "bf19422bfdd5193570b8172ad9a4261b82a871a3", "best_bid": "0.001", "best_ask": "0.01"}], "timestamp": "1769384448205", "event_type": "price_change"}}
{"_local_timestamp": "2026-01-25T23:40:48.276983+00:00", "data": {"market": "0x1172a9379540e31c463e178f08c87f67eb0011ba0deadcd67f78f0028d27f41a", "price_changes": [{"asset_id": "108433110821297511084165806800149498872896490798393090117171505493034184915983", "price": "0.14", "size": "1009", "side": "BUY", "hash": "891c93c8a7c134a42c40090a31656c70b0733a8a", "best_bid": "0.95", "best_ask": "0.989"}, {"asset_id": "96693063570682405603148415870765547887123700438364743392828151015298561276130", "price": "0.86", "size": "1009", "side": "SELL", "hash": "6ca836cd5c0b298de6b813eadb6e05cc0b6cb3e8", "best_bid": "0.011", "best_ask": "0.05"}], "timestamp": "1769384448205", "event_type": "price_change"}}
{"_local_timestamp": "2026-01-25T23:40:48.528326+00:00", "data": {"market": "0x45c806ae01123f47e7f24fea279b8658a4112cdaa11eee2f9924838a8948bc98", "price_changes": [{"asset_id": "32694948455525029678981577699677214621056167573486416032284086638717669535526", "price": "0.911", "size": "0", "side": "SELL", "hash": "3d3b5c8884fcfd0fedc608c840cb9d2c3a5b1bc5", "best_bid": "0.001", "best_ask": "0.91"}, {"asset_id": "56387091315659274606744882547186473603552761496368462985420229575757384495074", "price": "0.089", "size": "0", "side": "BUY", "hash": "c5e5b8938d847030faef7f1183e726fa42541c95", "best_bid": "0.09", "best_ask": "0.999"}], "timestamp": "1769384448450", "event_type": "price_change"}}
{"_local_timestamp": "2026-01-25T23:40:48.528846+00:00", "data": {"market": "0xe4088389ccc112ce566307b0535326b545db27823876138c37abc36aa80f01b6", "price_changes": [{"asset_id": "111535201652442500376681045716896114819862357479074857390925141208753505497603", "price": "0.011", "size": "29.92", "side": "BUY", "hash": "42cbcd78a1271c850c54caf0eb8b4131b4f0358e", "best_bid": "0.99", "best_ask": "0.999"}, {"asset_id": "68036185336858618606129914327232954729196470841777365764843049597359907094650", "price": "0.989", "size": "29.92", "side": "SELL", "hash": "7f5fee3e00d93c954e525bbc0ed83fbd1bf317b9", "best_bid": "0.001", "best_ask": "0.01"}], "timestamp": "1769384448450", "event_type": "price_change"}}
{"_local_timestamp": "2026-01-25T23:40:48.689846+00:00", "data": {"market": "0x1172a9379540e31c463e178f08c87f67eb0011ba0deadcd67f78f0028d27f41a", "price_changes": [{"asset_id": "108433110821297511084165806800149498872896490798393090117171505493034184915983", "price": "0.83", "size": "23.72", "side": "BUY", "hash": "04c543ef3a72d70a3c00310d11a2e7d3839927b5", "best_bid": "0.95", "best_ask": "0.989"}, {"asset_id": "96693063570682405603148415870765547887123700438364743392828151015298561276130", "price": "0.17", "size": "23.72", "side": "SELL", "hash": "472b9fce4682c40917be87d4a9c8dc7810e5f688", "best_bid": "0.011", "best_ask": "0.05"}], "timestamp": "1769384448614", "event_type": "price_change"}}
{"_local_timestamp": "2026-01-25T23:40:48.789449+00:00", "data": {"market": "0xe4088389ccc112ce566307b0535326b545db27823876138c37abc36aa80f01b6", "price_changes": [{"asset_id": "111535201652442500376681045716896114819862357479074857390925141208753505497603", "price": "0.011", "size": "44.88", "side": "BUY", "hash": "4f67f3dd3ba5c697e5bba338a26bcaa95d7286b8", "best_bid": "0.99", "best_ask": "0.999"}, {"asset_id": "68036185336858618606129914327232954729196470841777365764843049597359907094650", "price": "0.989", "size": "44.88", "side": "SELL", "hash": "0818325f18d9120a0adebf30cce0da48d0dac052", "best_bid": "0.001", "best_ask": "0.01"}], "timestamp": "1769384448710", "event_type": "price_change"}}
{"_local_timestamp": "2026-01-25T23:40:48.789955+00:00", "data": {"market": "0x45c806ae01123f47e7f24fea279b8658a4112cdaa11eee2f9924838a8948bc98", "price_changes": [{"asset_id": "32694948455525029678981577699677214621056167573486416032284086638717669535526", "price": "0.909", "size": "8.2", "side": "SELL", "hash": "12a46a785e5923d9144c761f98938051f5f7efe1", "best_bid": "0.001", "best_ask": "0.909"}, {"asset_id": "56387091315659274606744882547186473603552761496368462985420229575757384495074", "price": "0.091", "size": "8.2", "side": "BUY", "hash": "bba976d9483c01d52559d5c1b2cd58fb26fa1c31", "best_bid": "0.091", "best_ask": "0.999"}], "timestamp": "1769384448710", "event_type": "price_change"}}
{"_local_timestamp": "2026-01-25T23:40:48.793864+00:00", "data": {"market": "0xe4088389ccc112ce566307b0535326b545db27823876138c37abc36aa80f01b6", "price_changes": [{"asset_id": "111535201652442500376681045716896114819862357479074857390925141208753505497603", "price": "0.011", "size": "59.84", "side": "BUY", "hash": "f96228165d10fc5c7209bd61c47e138db27cc3a0", "best_bid": "0.99", "best_ask": "0.999"}, {"asset_id": "68036185336858618606129914327232954729196470841777365764843049597359907094650", "price": "0.989", "size": "59.84", "side": "SELL", "hash": "b6963d1f87311871cf4bba8347ad7d5708b72a9a", "best_bid": "0.001", "best_ask": "0.01"}], "timestamp": "1769384448711", "event_type": "price_change"}}
{"_local_timestamp": "2026-01-25T23:40:48.828314+00:00", "data": {"market": "0x1172a9379540e31c463e178f08c87f67eb0011ba0deadcd67f78f0028d27f41a", "price_changes": [{"asset_id": "108433110821297511084165806800149498872896490798393090117171505493034184915983", "price": "0.84", "size": "100", "side": "BUY", "hash": "0b679fe80909cab9e7fc84358ec8b43c42b3f4f7", "best_bid": "0.95", "best_ask": "0.989"}, {"asset_id": "96693063570682405603148415870765547887123700438364743392828151015298561276130", "price": "0.16", "size": "100", "side": "SELL", "hash": "629f8447d6ba82697a4831c5aa20bdd411c5d91c", "best_bid": "0.011", "best_ask": "0.05"}], "timestamp": "1769384448753", "event_type": "price_change"}}
{"_local_timestamp": "2026-01-25T23:40:48.947125+00:00", "data": {"market": "0x1172a9379540e31c463e178f08c87f67eb0011ba0deadcd67f78f0028d27f41a", "price_changes": [{"asset_id": "108433110821297511084165806800149498872896490798393090117171505493034184915983", "price": "0.84", "size": "0", "side": "BUY", "hash": "6b36bb59676f84824c9d3ead04a41e19755861ab", "best_bid": "0.95", "best_ask": "0.989"}, {"asset_id": "96693063570682405603148415870765547887123700438364743392828151015298561276130", "price": "0.16", "size": "0", "side": "SELL", "hash": "509f3aad5715c5396e81c21d8c486bdd01ce7e4a", "best_bid": "0.011", "best_ask": "0.05"}], "timestamp": "1769384448876", "event_type": "price_change"}}
{"_local_timestamp": "2026-01-25T23:40:48.991646+00:00", "data": {"market": "0x1172a9379540e31c463e178f08c87f67eb0011ba0deadcd67f78f0028d27f41a", "price_changes": [{"asset_id": "108433110821297511084165806800149498872896490798393090117171505493034184915983", "price": "0.83", "size": "123.72", "side": "BUY", "hash": "96d847f5a45fbcf8906c380c6b71512a36ee5d45", "best_bid": "0.95", "best_ask": "0.989"}, {"asset_id": "96693063570682405603148415870765547887123700438364743392828151015298561276130", "price": "0.17", "size": "123.72", "side": "SELL", "hash": "57ccb766eadb70d5c11ea54b256b9a4a7f85a8b8", "best_bid": "0.011", "best_ask": "0.05"}], "timestamp": "1769384448916", "event_type": "price_change"}}
{"_local_timestamp": "2026-01-25T23:40:49.021084+00:00", "data": {"market": "0x1172a9379540e31c463e178f08c87f67eb0011ba0deadcd67f78f0028d27f41a", "price_changes": [{"asset_id": "108433110821297511084165806800149498872896490798393090117171505493034184915983", "price": "0.83", "size": "23.72", "side": "BUY", "hash": "82669b15a9d72dc4f1bb1b93709606ef3d2e3a8b", "best_bid": "0.95", "best_ask": "0.989"}, {"asset_id": "96693063570682405603148415870765547887123700438364743392828151015298561276130", "price": "0.17", "size": "23.72", "side": "SELL", "hash": "ea5b5ddb381d154c496ce69b40ff44c27fe3558b", "best_bid": "0.011", "best_ask": "0.05"}], "timestamp": "1769384448951", "event_type": "price_change"}}
{"_local_timestamp": "2026-01-25T23:40:49.384965+00:00", "data": {"market": "0xe4088389ccc112ce566307b0535326b545db27823876138c37abc36aa80f01b6", "price_changes": [{"asset_id": "111535201652442500376681045716896114819862357479074857390925141208753505497603", "price": "0.002", "size": "22.33", "side": "BUY", "hash": "55031f9293d85f9bbcfb1bb022998c77e18407a7", "best_bid": "0.99", "best_ask": "0.999"}, {"asset_id": "68036185336858618606129914327232954729196470841777365764843049597359907094650", "price": "0.998", "size": "22.33", "side": "SELL", "hash": "ed2fdfb1dd7807c2da0f34b7ef4c5172b83ac203", "best_bid": "0.001", "best_ask": "0.01"}], "timestamp": "1769384449316", "event_type": "price_change"}}
{"_local_timestamp": "2026-01-25T23:40:49.513373+00:00", "data": {"market": "0x45c806ae01123f47e7f24fea279b8658a4112cdaa11eee2f9924838a8948bc98", "price_changes": [{"asset_id": "32694948455525029678981577699677214621056167573486416032284086638717669535526", "price": "0.91", "size": "0", "side": "SELL", "hash": "6fbd9da0d75b0e022beb9e1c8b19405ba5b5f279", "best_bid": "0.001", "best_ask": "0.909"}, {"asset_id": "56387091315659274606744882547186473603552761496368462985420229575757384495074", "price": "0.09", "size": "0", "side": "BUY", "hash": "5c50642000fd8ee18650365a10db4b07729828a2", "best_bid": "0.091", "best_ask": "0.999"}], "timestamp": "1769384449440", "event_type": "price_change"}}
{"_local_timestamp": "2026-01-25T23:40:49.617653+00:00", "data": {"market": "0x45c806ae01123f47e7f24fea279b8658a4112cdaa11eee2f9924838a8948bc98", "price_changes": [{"asset_id": "32694948455525029678981577699677214621056167573486416032284086638717669535526", "price": "0.908", "size": "5.47", "side": "SELL", "hash": "e971b07b6f4277e4f3b888bd34b3a76414780510", "best_bid": "0.001", "best_ask": "0.908"}, {"asset_id": "56387091315659274606744882547186473603552761496368462985420229575757384495074", "price": "0.092", "size": "5.47", "side": "BUY", "hash": "f6bb4e3241290d0893efff56dba8942005382b65", "best_bid": "0.092", "best_ask": "0.999"}], "timestamp": "1769384449538", "event_type": "price_change"}}
{"_local_timestamp": "2026-01-25T23:40:49.619385+00:00", "data": {"market": "0xe4088389ccc112ce566307b0535326b545db27823876138c37abc36aa80f01b6", "price_changes": [{"asset_id": "111535201652442500376681045716896114819862357479074857390925141208753505497603", "price": "0.002", "size": "30.13", "side": "BUY", "hash": "943ebda374bffc116442719e069ef849a3e33fee", "best_bid": "0.99", "best_ask": "0.999"}, {"asset_id": "68036185336858618606129914327232954729196470841777365764843049597359907094650", "price": "0.998", "size": "30.13", "side": "SELL", "hash": "2558ac4a9e21aabb863af8291140e4206d46d734", "best_bid": "0.001", "best_ask": "0.01"}], "timestamp": "1769384449546", "event_type": "price_change"}}
{"_local_timestamp": "2026-01-25T23:40:49.811714+00:00", "data": {"market": "0x8e8d315038e54eb4b3b7108ebfc48986e286dd3a53408a293263c73bb64040be", "price_changes": [{"asset_id": "73877455263924215947237673601962666377355671254828449751196120845554792983538", "price": "0.01", "size": "19.31", "side": "BUY", "hash": "bf578a680a886740163e20718e2b9e783806ee8f", "best_bid": "0.02", "best_ask": "0.98"}, {"asset_id": "45695296729134875133282986964941962331716131780439753949097910486621574361250", "price": "0.99", "size": "19.31", "side": "SELL", "hash": "2cdaa42c02d5bcbc7de148ca04d9b7557b88e833", "best_bid": "0.02", "best_ask": "0.98"}], "timestamp": "1769384449742", "event_type": "price_change"}}
{"_local_timestamp": "2026-01-25T23:40:50.088432+00:00", "data": {"market": "0x8e8d315038e54eb4b3b7108ebfc48986e286dd3a53408a293263c73bb64040be", "price_changes": [{"asset_id": "73877455263924215947237673601962666377355671254828449751196120845554792983538", "price": "0.01", "size": "58.97", "side": "BUY", "hash": "5ac283b3ab0c2361b6aba35767fd0d34439d8591", "best_bid": "0.02", "best_ask": "0.98"}, {"asset_id": "45695296729134875133282986964941962331716131780439753949097910486621574361250", "price": "0.99", "size": "58.97", "side": "SELL", "hash": "b0c9f0dc93d9f9ad3e6e7ceb131804a9b0a06ecd", "best_bid": "0.02", "best_ask": "0.98"}], "timestamp": "1769384449974", "event_type": "price_change"}}
{"_local_timestamp": "2026-01-25T23:40:50.133925+00:00", "data": {"market": "0x02d056b4ecb79134657b5437bcdd964a7b4008def9f7623e8e1c3a2652996390", "price_changes": [{"asset_id": "75572739037384917026708802532724608493252666334200100326455332920422495907885", "price": "0.03", "size": "0", "side": "BUY", "hash": "1a2588f8323e77f281418c3c96270daa7bca8ca8", "best_bid": "0.01", "best_ask": "0.98"}, {"asset_id": "75662091824125558301238389247455078817972039140363353111649504086477915930016", "price": "0.97", "size": "0", "side": "SELL", "hash": "59ad2217053fb061bc2ed491637dc66071ff02aa", "best_bid": "0.02", "best_ask": "0.99"}], "timestamp": "1769384450001", "event_type": "price_change"}}
{"_local_timestamp": "2026-01-25T23:40:51.105450+00:00", "data": {"market": "0xe4088389ccc112ce566307b0535326b545db27823876138c37abc36aa80f01b6", "price_changes": [{"asset_id": "111535201652442500376681045716896114819862357479074857390925141208753505497603", "price": "0.002", "size": "22.33", "side": "BUY", "hash": "cdf1efac34079961de3bb3cf0769f719328249ec", "best_bid": "0.99", "best_ask": "0.999"}, {"asset_id": "68036185336858618606129914327232954729196470841777365764843049597359907094650", "price": "0.998", "size": "22.33", "side": "SELL", "hash": "98288d50f8b7b4e25d67503ad0b654a920d54060", "best_bid": "0.001", "best_ask": "0.01"}], "timestamp": "1769384451017", "event_type": "price_change"}}
{"_local_timestamp": "2026-01-25T23:40:51.363459+00:00", "data": {"market": "0xe4088389ccc112ce566307b0535326b545db27823876138c37abc36aa80f01b6", "price_changes": [{"asset_id": "111535201652442500376681045716896114819862357479074857390925141208753505497603", "price": "0.002", "size": "30.13", "side": "BUY", "hash": "7a7b9c8a3eea9ac0118cbc4eac2345842c70965e", "best_bid": "0.99", "best_ask": "0.999"}, {"asset_id": "68036185336858618606129914327232954729196470841777365764843049597359907094650", "price": "0.998", "size": "30.13", "side": "SELL", "hash": "d0e84a0fe999ef49866e223b9721572ddfb573a5", "best_bid": "0.001", "best_ask": "0.01"}], "timestamp": "1769384451290", "event_type": "price_change"}}
{"_local_timestamp": "2026-01-25T23:40:52.060290+00:00", "data": {"market": "0x02d056b4ecb79134657b5437bcdd964a7b4008def9f7623e8e1c3a2652996390", "price_changes": [{"asset_id": "75572739037384917026708802532724608493252666334200100326455332920422495907885", "price": "0.03", "size": "50", "side": "BUY", "hash": "2f71483c2cb55bb8809532e2b667ed682b109955", "best_bid": "0.03", "best_ask": "0.98"}, {"asset_id": "75662091824125558301238389247455078817972039140363353111649504086477915930016", "price": "0.97", "size": "50", "side": "SELL", "hash": "add7ad38b435f199e17f5160d7ab230d5466f93a", "best_bid": "0.02", "best_ask": "0.97"}], "timestamp": "1769384451982", "event_type": "price_change"}}
{"_local_timestamp": "2026-01-25T23:40:52.389136+00:00", "data": {"market": "0xe4088389ccc112ce566307b0535326b545db27823876138c37abc36aa80f01b6", "price_changes": [{"asset_id": "111535201652442500376681045716896114819862357479074857390925141208753505497603", "price": "0.002", "size": "22.33", "side": "BUY", "hash": "632fe490fd2081f1b387f26220d945d628044749", "best_bid": "0.99", "best_ask": "0.999"}, {"asset_id": "68036185336858618606129914327232954729196470841777365764843049597359907094650", "price": "0.998", "size": "22.33", "side": "SELL", "hash": "36edc24186eb86eb490b6216181db46f0a2d2fab", "best_bid": "0.001", "best_ask": "0.01"}], "timestamp": "1769384452320", "event_type": "price_change"}}
{"_local_timestamp": "2026-01-25T23:40:53.028353+00:00", "data": {"market": "0xe4088389ccc112ce566307b0535326b545db27823876138c37abc36aa80f01b6", "price_changes": [{"asset_id": "111535201652442500376681045716896114819862357479074857390925141208753505497603", "price": "0.002", "size": "30.13", "side": "BUY", "hash": "246b2de81d0d992caa5d3a653966f5fbeccf103c", "best_bid": "0.99", "best_ask": "0.999"}, {"asset_id": "68036185336858618606129914327232954729196470841777365764843049597359907094650", "price": "0.998", "size": "30.13", "side": "SELL", "hash": "e9fa39fa553fd1dc38c429a6debf48e5db405e1d", "best_bid": "0.001", "best_ask": "0.01"}], "timestamp": "1769384452946", "event_type": "price_change"}}
{"_local_timestamp": "2026-01-25T23:40:53.080667+00:00", "data": {"market": "0xe4088389ccc112ce566307b0535326b545db27823876138c37abc36aa80f01b6", "price_changes": [{"asset_id": "111535201652442500376681045716896114819862357479074857390925141208753505497603", "price": "0.01", "size": "0", "side": "BUY", "hash": "dade69aad8ace68757acddadc3a02e3e12db7548", "best_bid": "0.99", "best_ask": "0.999"}, {"asset_id": "68036185336858618606129914327232954729196470841777365764843049597359907094650", "price": "0.99", "size": "0", "side": "SELL", "hash": "b6dab1dcfb5ef7a6eae0d9452fa65f27a1488f1c", "best_bid": "0.001", "best_ask": "0.01"}], "timestamp": "1769384453001", "event_type": "price_change"}}
{"_local_timestamp": "2026-01-25T23:40:53.095577+00:00", "data": {"market": "0x1172a9379540e31c463e178f08c87f67eb0011ba0deadcd67f78f0028d27f41a", "price_changes": [{"asset_id": "108433110821297511084165806800149498872896490798393090117171505493034184915983", "price": "0.14", "size": "300", "side": "BUY", "hash": "79a56d859dd9606500bd48e85fdf44ec00f90438", "best_bid": "0.95", "best_ask": "0.989"}, {"asset_id": "96693063570682405603148415870765547887123700438364743392828151015298561276130", "price": "0.86", "size": "300", "side": "SELL", "hash": "3118a879b8d79834e6f889103c04340e1a64c797", "best_bid": "0.011", "best_ask": "0.05"}], "timestamp": "1769384453002", "event_type": "price_change"}}
{"_local_timestamp": "2026-01-25T23:40:53.416745+00:00", "data": {"market": "0x4d351854a5011cdb0c141ef8d87a8321213d1e0a3b258a3745c03d34dd85d7a7", "price_changes": [{"asset_id": "30230407831690929960155342999106742333605054613110743527797581940998715084536", "price": "0.01", "size": "11.24", "side": "BUY", "hash": "2ee284d2e2cf8086e35f78d497d46bef53858600", "best_bid": "0.01", "best_ask": "0.98"}, {"asset_id": "89397257210211231854366309279840798542964120041524548078365395989129276413393", "price": "0.99", "size": "11.24", "side": "SELL", "hash": "e940d4857fbd8cd889ec31392e7889e7211495da", "best_bid": "0.02", "best_ask": "0.99"}], "timestamp": "1769384453347", "event_type": "price_change"}}
{"_local_timestamp": "2026-01-25T23:40:53.670977+00:00", "data": {"market": "0x1172a9379540e31c463e178f08c87f67eb0011ba0deadcd67f78f0028d27f41a", "price_changes": [{"asset_id": "108433110821297511084165806800149498872896490798393090117171505493034184915983", "price": "0.14", "size": "1009", "side": "BUY", "hash": "84c361017cf9ed6eac164147d427e3f2e5495489", "best_bid": "0.95", "best_ask": "0.989"}, {"asset_id": "96693063570682405603148415870765547887123700438364743392828151015298561276130", "price": "0.86", "size": "1009", "side": "SELL", "hash": "be87ce0d79e167c2e59fecaec8e91e3e3578744b", "best_bid": "0.011", "best_ask": "0.05"}], "timestamp": "1769384453598", "event_type": "price_change"}}
{"_local_timestamp": "2026-01-25T23:40:53.671554+00:00", "data": {"market": "0xe4088389ccc112ce566307b0535326b545db27823876138c37abc36aa80f01b6", "price_changes": [{"asset_id": "111535201652442500376681045716896114819862357479074857390925141208753505497603", "price": "0.01", "size": "8333", "side": "BUY", "hash": "32ce1eeccde9d0e0d750db2c7acc553e9ecaa0f2", "best_bid": "0.99", "best_ask": "0.999"}, {"asset_id": "68036185336858618606129914327232954729196470841777365764843049597359907094650", "price": "0.99", "size": "8333", "side": "SELL", "hash": "3d17dfde213b51fb156330f6089335bc31be65ea", "best_bid": "0.001", "best_ask": "0.01"}], "timestamp": "1769384453598", "event_type": "price_change"}}
{"_local_timestamp": "2026-01-25T23:40:53.677731+00:00", "data": {"market": "0x4d351854a5011cdb0c141ef8d87a8321213d1e0a3b258a3745c03d34dd85d7a7", "price_changes": [{"asset_id": "30230407831690929960155342999106742333605054613110743527797581940998715084536", "price": "0.01", "size": "38.46", "side": "BUY", "hash": "7a856cc49a35da0aa879054631f648d203ba3412", "best_bid": "0.01", "best_ask": "0.98"}, {"asset_id": "89397257210211231854366309279840798542964120041524548078365395989129276413393", "price": "0.99", "size": "38.46", "side": "SELL", "hash": "67b262d10904cd4dc4c0a4e0bde9e41b5d75e84d", "best_bid": "0.02", "best_ask": "0.99"}], "timestamp": "1769384453600", "event_type": "price_change"}}
{"_local_timestamp": "2026-01-25T23:40:55.176524+00:00", "data": {"market": "0x45c806ae01123f47e7f24fea279b8658a4112cdaa11eee2f9924838a8948bc98", "price_changes": [{"asset_id": "56387091315659274606744882547186473603552761496368462985420229575757384495074", "price": "0.002", "size": "285", "side": "BUY", "hash": "2312911d47b47ece682396ba56657ec46f13f8d8", "best_bid": "0.092", "best_ask": "0.999"}, {"asset_id": "32694948455525029678981577699677214621056167573486416032284086638717669535526", "price": "0.998", "size": "285", "side": "SELL", "hash": "d2e78ca17f78fff53a98660cc79edb5c21c6a713", "best_bid": "0.001", "best_ask": "0.908"}], "timestamp": "1769384455099", "event_type": "price_change"}}
{"_local_timestamp": "2026-01-25T23:40:55.478320+00:00", "data": {"market": "0x45c806ae01123f47e7f24fea279b8658a4112cdaa11eee2f9924838a8948bc98", "price_changes": [{"asset_id": "56387091315659274606744882547186473603552761496368462985420229575757384495074", "price": "0.07", "size": "0", "side": "BUY", "hash": "7315e39f8a57e06e097fcc8a5ad4b1dc2b648ac0", "best_bid": "0.092", "best_ask": "0.999"}, {"asset_id": "32694948455525029678981577699677214621056167573486416032284086638717669535526", "price": "0.93", "size": "0", "side": "SELL", "hash": "93c16170dba60a2848115eaacddbc64d8e85be68", "best_bid": "0.001", "best_ask": "0.908"}], "timestamp": "1769384455404", "event_type": "price_change"}}
{"_local_timestamp": "2026-01-25T23:40:55.553029+00:00", "data": {"market": "0x45c806ae01123f47e7f24fea279b8658a4112cdaa11eee2f9924838a8948bc98", "price_changes": [{"asset_id": "56387091315659274606744882547186473603552761496368462985420229575757384495074", "price": "0.001", "size": "1000", "side": "BUY", "hash": "875fbf2730d5319c4bc51c9cece0c3b0f9a78330", "best_bid": "0.092", "best_ask": "0.999"}, {"asset_id": "32694948455525029678981577699677214621056167573486416032284086638717669535526", "price": "0.999", "size": "1000", "side": "SELL", "hash": "aeb24b1011676506abe17b857ebe03d0cf92a3a8", "best_bid": "0.001", "best_ask": "0.908"}], "timestamp": "1769384455481", "event_type": "price_change"}}
{"_local_timestamp": "2026-01-25T23:40:55.559565+00:00", "data": {"market": "0x45c806ae01123f47e7f24fea279b8658a4112cdaa11eee2f9924838a8948bc98", "price_changes": [{"asset_id": "56387091315659274606744882547186473603552761496368462985420229575757384495074", "price": "0.002", "size": "425.49", "side": "BUY", "hash": "c0ffbce570605e98ce4bb76119e4dbf1c138bea4", "best_bid": "0.092", "best_ask": "0.999"}, {"asset_id": "32694948455525029678981577699677214621056167573486416032284086638717669535526", "price": "0.998", "size": "425.49", "side": "SELL", "hash": "693a7dbc74cde429a20b4a9e0c6f099b6c0bfa19", "best_bid": "0.001", "best_ask": "0.908"}], "timestamp": "1769384455482", "event_type": "price_change"}}
{"_local_timestamp": "2026-01-25T23:40:56.476513+00:00", "data": {"market": "0x45c806ae01123f47e7f24fea279b8658a4112cdaa11eee2f9924838a8948bc98", "price_changes": [{"asset_id": "32694948455525029678981577699677214621056167573486416032284086638717669535526", "price": "0.909", "size": "0", "side": "SELL", "hash": "abde35214f9cb781904a12c1c6a8d2e3550ed550", "best_bid": "0.001", "best_ask": "0.908"}, {"asset_id": "56387091315659274606744882547186473603552761496368462985420229575757384495074", "price": "0.091", "size": "0", "side": "BUY", "hash": "100d98976d149473bc57eccf80fef0d0831043ba", "best_bid": "0.092", "best_ask": "0.999"}], "timestamp": "1769384456400", "event_type": "price_change"}}
{"_local_timestamp": "2026-01-25T23:40:56.477703+00:00", "data": {"market": "0x45c806ae01123f47e7f24fea279b8658a4112cdaa11eee2f9924838a8948bc98", "price_changes": [{"asset_id": "32694948455525029678981577699677214621056167573486416032284086638717669535526", "price": "0.929", "size": "0", "side": "SELL", "hash": "abde35214f9cb781904a12c1c6a8d2e3550ed550", "best_bid": "0.001", "best_ask": "0.908"}, {"asset_id": "56387091315659274606744882547186473603552761496368462985420229575757384495074", "price": "0.071", "size": "0", "side": "BUY", "hash": "100d98976d149473bc57eccf80fef0d0831043ba", "best_bid": "0.092", "best_ask": "0.999"}], "timestamp": "1769384456400", "event_type": "price_change"}}
{"_local_timestamp": "2026-01-25T23:40:56.744729+00:00", "data": {"market": "0x45c806ae01123f47e7f24fea279b8658a4112cdaa11eee2f9924838a8948bc98", "price_changes": [{"asset_id": "32694948455525029678981577699677214621056167573486416032284086638717669535526", "price": "0.998", "size": "517.28", "side": "SELL", "hash": "2ff15dc55486ea0632addbe2837cc41fc482bead", "best_bid": "0.001", "best_ask": "0.908"}, {"asset_id": "56387091315659274606744882547186473603552761496368462985420229575757384495074", "price": "0.002", "size": "517.28", "side": "BUY", "hash": "c81f8b17ee6efc108d690f668f7bd945541af88f", "best_bid": "0.092", "best_ask": "0.999"}], "timestamp": "1769384456676", "event_type": "price_change"}}
{"_local_timestamp": "2026-01-25T23:40:56.745317+00:00", "data": {"market": "0x45c806ae01123f47e7f24fea279b8658a4112cdaa11eee2f9924838a8948bc98", "price_changes": [{"asset_id": "32694948455525029678981577699677214621056167573486416032284086638717669535526", "price": "0.907", "size": "8.2", "side": "SELL", "hash": "bd5f7374ebe5417ae4baffd9b83a5a18058b60a3", "best_bid": "0.001", "best_ask": "0.907"}, {"asset_id": "56387091315659274606744882547186473603552761496368462985420229575757384495074", "price": "0.093", "size": "8.2", "side": "BUY", "hash": "b51212757702536e7b6939905c901af0a16d2092", "best_bid": "0.093", "best_ask": "0.999"}], "timestamp": "1769384456677", "event_type": "price_change"}}
{"_local_timestamp": "2026-01-25T23:40:56.910318+00:00", "data": {"market": "0xe4088389ccc112ce566307b0535326b545db27823876138c37abc36aa80f01b6", "price_changes": [{"asset_id": "111535201652442500376681045716896114819862357479074857390925141208753505497603", "price": "0.002", "size": "22.33", "side": "BUY", "hash": "d292ace9735d798da05e3e624c429cd9ede17674", "best_bid": "0.99", "best_ask": "0.999"}, {"asset_id": "68036185336858618606129914327232954729196470841777365764843049597359907094650", "price": "0.998", "size": "22.33", "side": "SELL", "hash": "8d1be8369a5576d8d1e8cf1a2dd9960c116c634d", "best_bid": "0.001", "best_ask": "0.01"}], "timestamp": "1769384456838", "event_type": "price_change"}}
{"_local_timestamp": "2026-01-25T23:40:57.189246+00:00", "data": {"market": "0xe4088389ccc112ce566307b0535326b545db27823876138c37abc36aa80f01b6", "price_changes": [{"asset_id": "111535201652442500376681045716896114819862357479074857390925141208753505497603", "price": "0.002", "size": "30.13", "side": "BUY", "hash": "227b8424e729a6f413dd2c4499f26aac21dacd45", "best_bid": "0.99", "best_ask": "0.999"}, {"asset_id": "68036185336858618606129914327232954729196470841777365764843049597359907094650", "price": "0.998", "size": "30.13", "side": "SELL", "hash": "ad8f91f377fb0cb7a37b961a4a685adc958b7546", "best_bid": "0.001", "best_ask": "0.01"}], "timestamp": "1769384457107", "event_type": "price_change"}}
{"_local_timestamp": "2026-01-25T23:40:59.075501+00:00", "data": {"market": "0x45c806ae01123f47e7f24fea279b8658a4112cdaa11eee2f9924838a8948bc98", "price_changes": [{"asset_id": "56387091315659274606744882547186473603552761496368462985420229575757384495074", "price": "0.09", "size": "100", "side": "BUY", "hash": "c2499907bd7c663791151c73ea54ecba0be15f72", "best_bid": "0.093", "best_ask": "0.999"}, {"asset_id": "32694948455525029678981577699677214621056167573486416032284086638717669535526", "price": "0.91", "size": "100", "side": "SELL", "hash": "b4252c137ccaaec3804507b7b48cb55e4991be02", "best_bid": "0.001", "best_ask": "0.907"}], "timestamp": "1769384457996", "event_type": "price_change"}}
{"_local_timestamp": "2026-01-25T23:40:59.076076+00:00", "data": {"market": "0xe4088389ccc112ce566307b0535326b545db27823876138c37abc36aa80f01b6", "price_changes": [{"asset_id": "111535201652442500376681045716896114819862357479074857390925141208753505497603", "price": "0.01", "size": "0", "side": "BUY", "hash": "8ec6a2bd8c3aa3dc9a622a9e236a18311a4c489a", "best_bid": "0.99", "best_ask": "0.999"}, {"asset_id": "68036185336858618606129914327232954729196470841777365764843049597359907094650", "price": "0.99", "size": "0", "side": "SELL", "hash": "ff8a5a1e150c77ac3456863ad3955bc8eb3fefd0", "best_bid": "0.001", "best_ask": "0.01"}], "timestamp": "1769384458002", "event_type": "price_change"}}
{"_local_timestamp": "2026-01-25T23:40:59.076531+00:00", "data": {"market": "0x1172a9379540e31c463e178f08c87f67eb0011ba0deadcd67f78f0028d27f41a", "price_changes": [{"asset_id": "108433110821297511084165806800149498872896490798393090117171505493034184915983", "price": "0.14", "size": "300", "side": "BUY", "hash": "80a306e14b9d196426e6fcee5025d996985008c2", "best_bid": "0.95", "best_ask": "0.989"}, {"asset_id": "96693063570682405603148415870765547887123700438364743392828151015298561276130", "price": "0.86", "size": "300", "side": "SELL", "hash": "f665dba0ad9eeeda037e755fb2f78748fff377fc", "best_bid": "0.011", "best_ask": "0.05"}], "timestamp": "1769384458002", "event_type": "price_change"}}
{"_local_timestamp": "2026-01-25T23:40:59.076935+00:00", "data": {"market": "0x1172a9379540e31c463e178f08c87f67eb0011ba0deadcd67f78f0028d27f41a", "price_changes": [{"asset_id": "108433110821297511084165806800149498872896490798393090117171505493034184915983", "price": "0.84", "size": "100", "side": "BUY", "hash": "abfbe7c98cb44ce056668f13890aaf6cfcb464b9", "best_bid": "0.95", "best_ask": "0.989"}, {"asset_id": "96693063570682405603148415870765547887123700438364743392828151015298561276130", "price": "0.16", "size": "100", "side": "SELL", "hash": "7ca1c8bdd5179d27017247b12026e94222a08f00", "best_bid": "0.011", "best_ask": "0.05"}], "timestamp": "1769384458771", "event_type": "price_change"}}
{"_local_timestamp": "2026-01-25T23:40:59.077330+00:00", "data": {"market": "0x1172a9379540e31c463e178f08c87f67eb0011ba0deadcd67f78f0028d27f41a", "price_changes": [{"asset_id": "108433110821297511084165806800149498872896490798393090117171505493034184915983", "price": "0.84", "size": "0", "side": "BUY", "hash": "ed5351235c125fd1a8e86121a755d5326ce7af1c", "best_bid": "0.95", "best_ask": "0.989"}, {"asset_id": "96693063570682405603148415870765547887123700438364743392828151015298561276130", "price": "0.16", "size": "0", "side": "SELL", "hash": "74c88953fddbfd04b595b04c5b1c23068508cac3", "best_bid": "0.011", "best_ask": "0.05"}], "timestamp": "1769384458911", "event_type": "price_change"}}
{"_local_timestamp": "2026-01-25T23:40:59.077787+00:00", "data": {"market": "0x1172a9379540e31c463e178f08c87f67eb0011ba0deadcd67f78f0028d27f41a", "price_changes": [{"asset_id": "108433110821297511084165806800149498872896490798393090117171505493034184915983", "price": "0.83", "size": "123.72", "side": "BUY", "hash": "f83ef5d0cf003fa1f4efe9b9e074d3ae87486de3", "best_bid": "0.95", "best_ask": "0.989"}, {"asset_id": "96693063570682405603148415870765547887123700438364743392828151015298561276130", "price": "0.17", "size": "123.72", "side": "SELL", "hash": "e36ad10b493b414485754cf63e54cfbba6ce7b88", "best_bid": "0.011", "best_ask": "0.05"}], "timestamp": "1769384458962", "event_type": "price_change"}}
{"_local_timestamp": "2026-01-25T23:40:59.120972+00:00", "data": {"market": "0x1172a9379540e31c463e178f08c87f67eb0011ba0deadcd67f78f0028d27f41a", "price_changes": [{"asset_id": "108433110821297511084165806800149498872896490798393090117171505493034184915983", "price": "0.83", "size": "23.72", "side": "BUY", "hash": "3639f4fac12fb5f56ae9655440ef965383ed621e", "best_bid": "0.95", "best_ask": "0.989"}, {"asset_id": "96693063570682405603148415870765547887123700438364743392828151015298561276130", "price": "0.17", "size": "23.72", "side": "SELL", "hash": "8173e5ca13ce9eb8b2aba201c37da3859461cecd", "best_bid": "0.011", "best_ask": "0.05"}], "timestamp": "1769384459038", "event_type": "price_change"}}
{"_local_timestamp": "2026-01-25T23:40:59.141305+00:00", "data": {"market": "0x1172a9379540e31c463e178f08c87f67eb0011ba0deadcd67f78f0028d27f41a", "price_changes": [{"asset_id": "108433110821297511084165806800149498872896490798393090117171505493034184915983", "price": "0.14", "size": "1009", "side": "BUY", "hash": "fca425344b1bdba50c1aff861ef4fbbad6b55782", "best_bid": "0.95", "best_ask": "0.989"}, {"asset_id": "96693063570682405603148415870765547887123700438364743392828151015298561276130", "price": "0.86", "size": "1009", "side": "SELL", "hash": "11f551700022f1b24afd76f3dba936104cdda405", "best_bid": "0.011", "best_ask": "0.05"}], "timestamp": "1769384459069", "event_type": "price_change"}}
{"_local_timestamp": "2026-01-25T23:40:59.143534+00:00", "data": {"market": "0xe4088389ccc112ce566307b0535326b545db27823876138c37abc36aa80f01b6", "price_changes": [{"asset_id": "111535201652442500376681045716896114819862357479074857390925141208753505497603", "price": "0.01", "size": "8333", "side": "BUY", "hash": "678d41f1b0d391dbd4b9a6d13dafe6dd4e7753c9", "best_bid": "0.99", "best_ask": "0.999"}, {"asset_id": "68036185336858618606129914327232954729196470841777365764843049597359907094650", "price": "0.99", "size": "8333", "side": "SELL", "hash": "86777e0ca7b091f43256385e8ca344bcca679803", "best_bid": "0.001", "best_ask": "0.01"}], "timestamp": "1769384459069", "event_type": "price_change"}}
{"_local_timestamp": "2026-01-25T23:40:59.228533+00:00", "data": {"market": "0x1172a9379540e31c463e178f08c87f67eb0011ba0deadcd67f78f0028d27f41a", "price_changes": [{"asset_id": "108433110821297511084165806800149498872896490798393090117171505493034184915983", "price": "0.83", "size": "123.72", "side": "BUY", "hash": "ba656bb36ad60f62871c683f792b66829dfa1977", "best_bid": "0.95", "best_ask": "0.989"}, {"asset_id": "96693063570682405603148415870765547887123700438364743392828151015298561276130", "price": "0.17", "size": "123.72", "side": "SELL", "hash": "7cb990568c4b05cbca375617845aa2254c45021b", "best_bid": "0.011", "best_ask": "0.05"}], "timestamp": "1769384459126", "event_type": "price_change"}}
{"_local_timestamp": "2026-01-25T23:40:59.330069+00:00", "data": {"market": "0x1172a9379540e31c463e178f08c87f67eb0011ba0deadcd67f78f0028d27f41a", "price_changes": [{"asset_id": "108433110821297511084165806800149498872896490798393090117171505493034184915983", "price": "0.83", "size": "23.72", "side": "BUY", "hash": "42d7b4f93517ddca29af0e1740240553f7bcdd9a", "best_bid": "0.95", "best_ask": "0.989"}, {"asset_id": "96693063570682405603148415870765547887123700438364743392828151015298561276130", "price": "0.17", "size": "23.72", "side": "SELL", "hash": "f4a8ed89eb401de51b23463e4e96aa6064b84ac2", "best_bid": "0.011", "best_ask": "0.05"}], "timestamp": "1769384459256", "event_type": "price_change"}}
{"_local_timestamp": "2026-01-25T23:40:59.545503+00:00", "data": {"market": "0xe40aca7194b6ed6c98d54fcd1338d41c30d5265d68d7468fdb3afcca62e8d6c3", "price_changes": [{"asset_id": "21516192838799393436877283935602059956906510510942747966420810813105259210660", "price": "0.01", "size": "9.85", "side": "BUY", "hash": "5e9fdd342d71b4e1834099d4ee89831a088b2e69", "best_bid": "0.01", "best_ask": "0.98"}, {"asset_id": "82306081970048077348294633861982165617205411236349395805461913184457941025697", "price": "0.99", "size": "9.85", "side": "SELL", "hash": "ace5725cfc000d28be4f157c2dcd473a92bbee6d", "best_bid": "0.02", "best_ask": "0.99"}], "timestamp": "1769384459445", "event_type": "price_change"}}
{"_local_timestamp": "2026-01-25T23:40:59.736692+00:00", "data": {"market": "0xe40aca7194b6ed6c98d54fcd1338d41c30d5265d68d7468fdb3afcca62e8d6c3", "price_changes": [{"asset_id": "21516192838799393436877283935602059956906510510942747966420810813105259210660", "price": "0.01", "size": "38.46", "side": "BUY", "hash": "07bd4584d9eca2bca15441a796dbb08c02ee7ff1", "best_bid": "0.01", "best_ask": "0.98"}, {"asset_id": "82306081970048077348294633861982165617205411236349395805461913184457941025697", "price": "0.99", "size": "38.46", "side": "SELL", "hash": "0a9629af6dd0c8f0701eaabf13db6cf78ef876af", "best_bid": "0.02", "best_ask": "0.99"}], "timestamp": "1769384459663", "event_type": "price_change"}}
{"_local_timestamp": "2026-01-25T23:40:59.948030+00:00", "data": {"market": "0xe4088389ccc112ce566307b0535326b545db27823876138c37abc36aa80f01b6", "price_changes": [{"asset_id": "111535201652442500376681045716896114819862357479074857390925141208753505497603", "price": "0.002", "size": "22.33", "side": "BUY", "hash": "b884284355cb587cf8b1e8bd70da7b76458276f5", "best_bid": "0.99", "best_ask": "0.999"}, {"asset_id": "68036185336858618606129914327232954729196470841777365764843049597359907094650", "price": "0.998", "size": "22.33", "side": "SELL", "hash": "5515e5733c05ac4df0c16ac9a5c63de3d09a4236", "best_bid": "0.001", "best_ask": "0.01"}], "timestamp": "1769384459868", "event_type": "price_change"}}
{"_local_timestamp": "2026-01-25T23:41:00.179318+00:00", "data": {"market": "0xe4088389ccc112ce566307b0535326b545db27823876138c37abc36aa80f01b6", "price_changes": [{"asset_id": "111535201652442500376681045716896114819862357479074857390925141208753505497603", "price": "0.002", "size": "30.13", "side": "BUY", "hash": "97afca1960be6a763d5b122336c8d38b31ba2c4b", "best_bid": "0.99", "best_ask": "0.999"}, {"asset_id": "68036185336858618606129914327232954729196470841777365764843049597359907094650", "price": "0.998", "size": "30.13", "side": "SELL", "hash": "12ecc1ee69514038b740c9b2a62a00bf9ad42506", "best_bid": "0.001", "best_ask": "0.01"}], "timestamp": "1769384460096", "event_type": "price_change"}}
{"_local_timestamp": "2026-01-25T23:41:00.328755+00:00", "data": {"market": "0x45c806ae01123f47e7f24fea279b8658a4112cdaa11eee2f9924838a8948bc98", "price_changes": [{"asset_id": "32694948455525029678981577699677214621056167573486416032284086638717669535526", "price": "0.908", "size": "0", "side": "SELL", "hash": "e3d9f4487f8d6edacd8f8f7749c7f0a94eb21bf5", "best_bid": "0.001", "best_ask": "0.907"}, {"asset_id": "56387091315659274606744882547186473603552761496368462985420229575757384495074", "price": "0.092", "size": "0", "side": "BUY", "hash": "bc2b253400a84748a4ce589c4db044c9a6a3edd6", "best_bid": "0.093", "best_ask": "0.999"}], "timestamp": "1769384460257", "event_type": "price_change"}}
{"_local_timestamp": "2026-01-25T23:41:00.462728+00:00", "data": {"market": "0x45c806ae01123f47e7f24fea279b8658a4112cdaa11eee2f9924838a8948bc98", "price_changes": [{"asset_id": "32694948455525029678981577699677214621056167573486416032284086638717669535526", "price": "0.906", "size": "5.47", "side": "SELL", "hash": "03d05004c71c573ad2be5c6dd406d3e56532f27a", "best_bid": "0.001", "best_ask": "0.906"}, {"asset_id": "56387091315659274606744882547186473603552761496368462985420229575757384495074", "price": "0.094", "size": "5.47", "side": "BUY", "hash": "4cba49e8dbbc763e1775ab10b8f08597b4c41e6c", "best_bid": "0.094", "best_ask": "0.999"}], "timestamp": "1769384460384", "event_type": "price_change"}}
{"_local_timestamp": "2026-01-25T23:41:00.787717+00:00", "data": {"market": "0x45c806ae01123f47e7f24fea279b8658a4112cdaa11eee2f9924838a8948bc98", "price_changes": [{"asset_id": "32694948455525029678981577699677214621056167573486416032284086638717669535526", "price": "0.998", "size": "425.49", "side": "SELL", "hash": "2371797c33ae20345d952a29a8f78b9d9e01bf1e", "best_bid": "0.001", "best_ask": "0.906"}, {"asset_id": "56387091315659274606744882547186473603552761496368462985420229575757384495074", "price": "0.002", "size": "425.49", "side": "BUY", "hash": "d06739d37b20040510b66bcc1320fcce11360c39", "best_bid": "0.094", "best_ask": "0.999"}], "timestamp": "1769384460714", "event_type": "price_change"}}
{"_local_timestamp": "2026-01-25T23:41:01.027426+00:00", "data": {"market": "0x45c806ae01123f47e7f24fea279b8658a4112cdaa11eee2f9924838a8948bc98", "price_changes": [{"asset_id": "32694948455525029678981577699677214621056167573486416032284086638717669535526", "price": "0.909", "size": "84.26", "side": "SELL", "hash": "110c0acc232ef23114d7511e2420def248fe3c71", "best_bid": "0.001", "best_ask": "0.906"}, {"asset_id": "56387091315659274606744882547186473603552761496368462985420229575757384495074", "price": "0.091", "size": "84.26", "side": "BUY", "hash": "2cdcbf36e2f3bb57e9a7726ef84542e134532683", "best_bid": "0.094", "best_ask": "0.999"}], "timestamp": "1769384460956", "event_type": "price_change"}}
{"_local_timestamp": "2026-01-25T23:41:01.028094+00:00", "data": {"market": "0x45c806ae01123f47e7f24fea279b8658a4112cdaa11eee2f9924838a8948bc98", "price_changes": [{"asset_id": "32694948455525029678981577699677214621056167573486416032284086638717669535526", "price": "0.905", "size": "7.53", "side": "SELL", "hash": "df97f91b483fe67bb66616462a50dedd88610dc7", "best_bid": "0.001", "best_ask": "0.905"}, {"asset_id": "56387091315659274606744882547186473603552761496368462985420229575757384495074", "price": "0.095", "size": "7.53", "side": "BUY", "hash": "20c2bee2b38773542d08418d240fea60dd4c9ded", "best_bid": "0.095", "best_ask": "0.999"}], "timestamp": "1769384460957", "event_type": "price_change"}}
{"_local_timestamp": "2026-01-25T23:41:02.115389+00:00", "data": {"market": "0x45c806ae01123f47e7f24fea279b8658a4112cdaa11eee2f9924838a8948bc98", "price_changes": [{"asset_id": "32694948455525029678981577699677214621056167573486416032284086638717669535526", "price": "0.906", "size": "0", "side": "SELL", "hash": "c0804327c3439dde925e7eb8082cdb50c6dfedb2", "best_bid": "0.001", "best_ask": "0.905"}, {"asset_id": "56387091315659274606744882547186473603552761496368462985420229575757384495074", "price": "0.094", "size": "0", "side": "BUY", "hash": "cfe0c96cc644564f326417412b47f194f42a8d22", "best_bid": "0.095", "best_ask": "0.999"}], "timestamp": "1769384462035", "event_type": "price_change"}}
{"_local_timestamp": "2026-01-25T23:41:02.219050+00:00", "data": {"market": "0x45c806ae01123f47e7f24fea279b8658a4112cdaa11eee2f9924838a8948bc98", "price_changes": [{"asset_id": "32694948455525029678981577699677214621056167573486416032284086638717669535526", "price": "0.904", "size": "5.47", "side": "SELL", "hash": "2a7f9d18c0ec19cede0971e26319a577f418b21a", "best_bid": "0.001", "best_ask": "0.904"}, {"asset_id": "56387091315659274606744882547186473603552761496368462985420229575757384495074", "price": "0.096", "size": "5.47", "side": "BUY", "hash": "c2ff914bd959e5dba04e416982b71fde3bd3c1a5", "best_bid": "0.096", "best_ask": "0.999"}], "timestamp": "1769384462143", "event_type": "price_change"}}
{"_local_timestamp": "2026-01-25T23:41:02.923062+00:00", "data": {"market": "0xe4088389ccc112ce566307b0535326b545db27823876138c37abc36aa80f01b6", "price_changes": [{"asset_id": "111535201652442500376681045716896114819862357479074857390925141208753505497603", "price": "0.002", "size": "22.33", "side": "BUY", "hash": "3ba5233c6386b02a31d3d5aaa58706ea57a071e9", "best_bid": "0.99", "best_ask": "0.999"}, {"asset_id": "68036185336858618606129914327232954729196470841777365764843049597359907094650", "price": "0.998", "size": "22.33", "side": "SELL", "hash": "39246e5b9499ec243308853918624e7c48974190", "best_bid": "0.001", "best_ask": "0.01"}], "timestamp": "1769384462845", "event_type": "price_change"}}
{"_local_timestamp": "2026-01-25T23:41:03.070490+00:00", "data": {"market": "0xe4088389ccc112ce566307b0535326b545db27823876138c37abc36aa80f01b6", "price_changes": [{"asset_id": "111535201652442500376681045716896114819862357479074857390925141208753505497603", "price": "0.01", "size": "0", "side": "BUY", "hash": "b49208a6efef9f99e756345625812b4bda474439", "best_bid": "0.99", "best_ask": "0.999"}, {"asset_id": "68036185336858618606129914327232954729196470841777365764843049597359907094650", "price": "0.99", "size": "0", "side": "SELL", "hash": "fba97e6773bf3366ab0e7609d2c555c2c6b3c1ff", "best_bid": "0.001", "best_ask": "0.01"}], "timestamp": "1769384463001", "event_type": "price_change"}}
{"_local_timestamp": "2026-01-25T23:41:03.084082+00:00", "data": {"market": "0x1172a9379540e31c463e178f08c87f67eb0011ba0deadcd67f78f0028d27f41a", "price_changes": [{"asset_id": "108433110821297511084165806800149498872896490798393090117171505493034184915983", "price": "0.14", "size": "300", "side": "BUY", "hash": "a19e62dc66491261bfdfaa9747536a749dd35d69", "best_bid": "0.95", "best_ask": "0.989"}, {"asset_id": "96693063570682405603148415870765547887123700438364743392828151015298561276130", "price": "0.86", "size": "300", "side": "SELL", "hash": "032f020f2993adfb28fb054b8faa32190b8bef12", "best_bid": "0.011", "best_ask": "0.05"}], "timestamp": "1769384463003", "event_type": "price_change"}}
{"_local_timestamp": "2026-01-25T23:41:03.299421+00:00", "data": {"market": "0xe4088389ccc112ce566307b0535326b545db27823876138c37abc36aa80f01b6", "price_changes": [{"asset_id": "111535201652442500376681045716896114819862357479074857390925141208753505497603", "price": "0.002", "size": "30.13", "side": "BUY", "hash": "37e68e24f718546ae1784ace099cb49b9ced81bd", "best_bid": "0.99", "best_ask": "0.999"}, {"asset_id": "68036185336858618606129914327232954729196470841777365764843049597359907094650", "price": "0.998", "size": "30.13", "side": "SELL", "hash": "4d3f7ecf3658649ff6fdd019cd8e3227fad3bb14", "best_bid": "0.001", "best_ask": "0.01"}], "timestamp": "1769384463214", "event_type": "price_change"}}
{"_local_timestamp": "2026-01-25T23:41:04.659339+00:00", "data": {"market": "0xe4088389ccc112ce566307b0535326b545db27823876138c37abc36aa80f01b6", "price_changes": [{"asset_id": "111535201652442500376681045716896114819862357479074857390925141208753505497603", "price": "0.01", "size": "8333", "side": "BUY", "hash": "8a4147be1b57ed4812dbfbf9f1b7f856c0fddb73", "best_bid": "0.99", "best_ask": "0.999"}, {"asset_id": "68036185336858618606129914327232954729196470841777365764843049597359907094650", "price": "0.99", "size": "8333", "side": "SELL", "hash": "7e78da3d11dc063f57c2b0e77c52c63b4556e954", "best_bid": "0.001", "best_ask": "0.01"}], "timestamp": "1769384464567", "event_type": "price_change"}}
{"_local_timestamp": "2026-01-25T23:41:04.806482+00:00", "data": {"market": "0x1172a9379540e31c463e178f08c87f67eb0011ba0deadcd67f78f0028d27f41a", "price_changes": [{"asset_id": "108433110821297511084165806800149498872896490798393090117171505493034184915983", "price": "0.14", "size": "1009", "side": "BUY", "hash": "1f582cbf74f9986d63ea0a4b25cd4cf9a26a9489", "best_bid": "0.95", "best_ask": "0.989"}, {"asset_id": "96693063570682405603148415870765547887123700438364743392828151015298561276130", "price": "0.86", "size": "1009", "side": "SELL", "hash": "700b0ca514c6f55f4b2932b0f51a0c0645af3a59", "best_bid": "0.011", "best_ask": "0.05"}], "timestamp": "1769384464737", "event_type": "price_change"}}
{"_local_timestamp": "2026-01-25T23:41:06.944616+00:00", "data": {"market": "0xe4088389ccc112ce566307b0535326b545db27823876138c37abc36aa80f01b6", "price_changes": [{"asset_id": "111535201652442500376681045716896114819862357479074857390925141208753505497603", "price": "0.002", "size": "22.33", "side": "BUY", "hash": "1fa05c68d90b7331ddfb2524f92ee78be8f3e4cd", "best_bid": "0.99", "best_ask": "0.999"}, {"asset_id": "68036185336858618606129914327232954729196470841777365764843049597359907094650", "price": "0.998", "size": "22.33", "side": "SELL", "hash": "2a05dfaf61860809c35255134c788afae7084c77", "best_bid": "0.001", "best_ask": "0.01"}], "timestamp": "1769384466797", "event_type": "price_change"}}
{"_local_timestamp": "2026-01-25T23:41:07.193049+00:00", "data": {"market": "0xe4088389ccc112ce566307b0535326b545db27823876138c37abc36aa80f01b6", "price_changes": [{"asset_id": "111535201652442500376681045716896114819862357479074857390925141208753505497603", "price": "0.002", "size": "30.13", "side": "BUY", "hash": "6887c672e729adb089d462b663434e9bc1bd2f0d", "best_bid": "0.99", "best_ask": "0.999"}, {"asset_id": "68036185336858618606129914327232954729196470841777365764843049597359907094650", "price": "0.998", "size": "30.13", "side": "SELL", "hash": "3cee254d7f10b1a54ab7e30632e47aa22bd7963e", "best_bid": "0.001", "best_ask": "0.01"}], "timestamp": "1769384467118", "event_type": "price_change"}}
{"_local_timestamp": "2026-01-25T23:41:09.084124+00:00", "data": {"market": "0xe4088389ccc112ce566307b0535326b545db27823876138c37abc36aa80f01b6", "price_changes": [{"asset_id": "111535201652442500376681045716896114819862357479074857390925141208753505497603", "price": "0.01", "size": "0", "side": "BUY", "hash": "9e1c7d18fb8740f1468fcf604262ca165f7076db", "best_bid": "0.99", "best_ask": "0.999"}, {"asset_id": "68036185336858618606129914327232954729196470841777365764843049597359907094650", "price": "0.99", "size": "0", "side": "SELL", "hash": "6783e039253914458e6810032819ec2e13a27194", "best_bid": "0.001", "best_ask": "0.01"}], "timestamp": "1769384469001", "event_type": "price_change"}}
{"_local_timestamp": "2026-01-25T23:41:09.084780+00:00", "data": {"market": "0x1172a9379540e31c463e178f08c87f67eb0011ba0deadcd67f78f0028d27f41a", "price_changes": [{"asset_id": "108433110821297511084165806800149498872896490798393090117171505493034184915983", "price": "0.14", "size": "300", "side": "BUY", "hash": "63a69191f7cdd541a5892bc10d418fb22accd220", "best_bid": "0.95", "best_ask": "0.989"}, {"asset_id": "96693063570682405603148415870765547887123700438364743392828151015298561276130", "price": "0.86", "size": "300", "side": "SELL", "hash": "1218eb9ca62ea0dd03281edc2ab2e2b75ca90233", "best_bid": "0.011", "best_ask": "0.05"}], "timestamp": "1769384469002", "event_type": "price_change"}}
{"_local_timestamp": "2026-01-25T23:41:09.381837+00:00", "data": {"market": "0x1172a9379540e31c463e178f08c87f67eb0011ba0deadcd67f78f0028d27f41a", "price_changes": [{"asset_id": "108433110821297511084165806800149498872896490798393090117171505493034184915983", "price": "0.08", "size": "500", "side": "BUY", "hash": "3e5f7ef4dc9c651a3e609a2e4da819b6e84aafca", "best_bid": "0.95", "best_ask": "0.989"}, {"asset_id": "96693063570682405603148415870765547887123700438364743392828151015298561276130", "price": "0.92", "size": "500", "side": "SELL", "hash": "f488c9f723010a4ff164c7ca74195f92a0064e76", "best_bid": "0.011", "best_ask": "0.05"}], "timestamp": "1769384469302", "event_type": "price_change"}}
{"_local_timestamp": "2026-01-25T23:41:09.382696+00:00", "data": {"market": "0x1172a9379540e31c463e178f08c87f67eb0011ba0deadcd67f78f0028d27f41a", "price_changes": [{"asset_id": "108433110821297511084165806800149498872896490798393090117171505493034184915983", "price": "0.001", "size": "856.4", "side": "BUY", "hash": "3e5f7ef4dc9c651a3e609a2e4da819b6e84aafca", "best_bid": "0.95", "best_ask": "0.989"}, {"asset_id": "96693063570682405603148415870765547887123700438364743392828151015298561276130", "price": "0.999", "size": "856.4", "side": "SELL", "hash": "f488c9f723010a4ff164c7ca74195f92a0064e76", "best_bid": "0.011", "best_ask": "0.05"}], "timestamp": "1769384469302", "event_type": "price_change"}}
{"_local_timestamp": "2026-01-25T23:41:09.690650+00:00", "data": {"market": "0x1172a9379540e31c463e178f08c87f67eb0011ba0deadcd67f78f0028d27f41a", "price_changes": [{"asset_id": "108433110821297511084165806800149498872896490798393090117171505493034184915983", "price": "0.14", "size": "400", "side": "BUY", "hash": "3ca98e2d469b033fcf27acc12da4b6bbcda6d0bb", "best_bid": "0.95", "best_ask": "0.989"}, {"asset_id": "96693063570682405603148415870765547887123700438364743392828151015298561276130", "price": "0.86", "size": "400", "side": "SELL", "hash": "0ea403697063738a90b9e4046570c62f396da37f", "best_bid": "0.011", "best_ask": "0.05"}], "timestamp": "1769384469599", "event_type": "price_change"}}
{"_local_timestamp": "2026-01-25T23:41:09.695617+00:00", "data": {"market": "0x1172a9379540e31c463e178f08c87f67eb0011ba0deadcd67f78f0028d27f41a", "price_changes": [{"asset_id": "108433110821297511084165806800149498872896490798393090117171505493034184915983", "price": "0.01", "size": "1200", "side": "BUY", "hash": "ec8f11936b28dc2fcc354c3f2037ea31facd0e18", "best_bid": "0.95", "best_ask": "0.989"}, {"asset_id": "96693063570682405603148415870765547887123700438364743392828151015298561276130", "price": "0.99", "size": "1200", "side": "SELL", "hash": "a18112536c90909ff615a8e42715b48b52f6e3d4", "best_bid": "0.011", "best_ask": "0.05"}], "timestamp": "1769384469600", "event_type": "price_change"}}
{"_local_timestamp": "2026-01-25T23:41:10.025031+00:00", "data": {"market": "0x1172a9379540e31c463e178f08c87f67eb0011ba0deadcd67f78f0028d27f41a", "price_changes": [{"asset_id": "108433110821297511084165806800149498872896490798393090117171505493034184915983", "price": "0.83", "size": "123.72", "side": "BUY", "hash": "26f1f4855b136e22c553d8d1bba36a66a9299f42", "best_bid": "0.95", "best_ask": "0.989"}, {"asset_id": "96693063570682405603148415870765547887123700438364743392828151015298561276130", "price": "0.17", "size": "123.72", "side": "SELL", "hash": "af1848cc72274a3365eccfadf58b400d6238672a", "best_bid": "0.011", "best_ask": "0.05"}], "timestamp": "1769384469956", "event_type": "price_change"}}
{"_local_timestamp": "2026-01-25T23:41:10.049369+00:00", "data": {"market": "0x45c806ae01123f47e7f24fea279b8658a4112cdaa11eee2f9924838a8948bc98", "price_changes": [{"asset_id": "32694948455525029678981577699677214621056167573486416032284086638717669535526", "price": "0.905", "size": "0", "side": "SELL", "hash": "514a7620dbc2650110e1e0c4bc0fe47379e57e9b", "best_bid": "0.001", "best_ask": "0.904"}, {"asset_id": "56387091315659274606744882547186473603552761496368462985420229575757384495074", "price": "0.095", "size": "0", "side": "BUY", "hash": "c8d788273b00135d7f880b10b3ceb00da80bb645", "best_bid": "0.096", "best_ask": "0.999"}], "timestamp": "1769384469978", "event_type": "price_change"}}
{"_local_timestamp": "2026-01-25T23:41:10.050008+00:00", "data": {"market": "0x45c806ae01123f47e7f24fea279b8658a4112cdaa11eee2f9924838a8948bc98", "price_changes": [{"asset_id": "32694948455525029678981577699677214621056167573486416032284086638717669535526", "price": "0.907", "size": "0", "side": "SELL", "hash": "514a7620dbc2650110e1e0c4bc0fe47379e57e9b", "best_bid": "0.001", "best_ask": "0.904"}, {"asset_id": "56387091315659274606744882547186473603552761496368462985420229575757384495074", "price": "0.093", "size": "0", "side": "BUY", "hash": "c8d788273b00135d7f880b10b3ceb00da80bb645", "best_bid": "0.096", "best_ask": "0.999"}], "timestamp": "1769384469978", "event_type": "price_change"}}
{"_local_timestamp": "2026-01-25T23:41:10.228076+00:00", "data": {"market": "0xe4088389ccc112ce566307b0535326b545db27823876138c37abc36aa80f01b6", "price_changes": [{"asset_id": "111535201652442500376681045716896114819862357479074857390925141208753505497603", "price": "0.01", "size": "8333", "side": "BUY", "hash": "a23a00b4758fe55ffcbe0ee30eae9a7c7002ca69", "best_bid": "0.99", "best_ask": "0.999"}, {"asset_id": "68036185336858618606129914327232954729196470841777365764843049597359907094650", "price": "0.99", "size": "8333", "side": "SELL", "hash": "697bcda71972c1f255751e115c6c51be85d65799", "best_bid": "0.001", "best_ask": "0.01"}], "timestamp": "1769384470146", "event_type": "price_change"}}
{"_local_timestamp": "2026-01-25T23:41:10.293778+00:00", "data": {"market": "0x1172a9379540e31c463e178f08c87f67eb0011ba0deadcd67f78f0028d27f41a", "price_changes": [{"asset_id": "108433110821297511084165806800149498872896490798393090117171505493034184915983", "price": "0.83", "size": "23.72", "side": "BUY", "hash": "93e6e0c08a78450749b4eba34275068ee6327977", "best_bid": "0.95", "best_ask": "0.989"}, {"asset_id": "96693063570682405603148415870765547887123700438364743392828151015298561276130", "price": "0.17", "size": "23.72", "side": "SELL", "hash": "db104b41e44e2b861e3980bc921818f746a265db", "best_bid": "0.011", "best_ask": "0.05"}], "timestamp": "1769384470217", "event_type": "price_change"}}
{"_local_timestamp": "2026-01-25T23:41:10.318769+00:00", "data": {"market": "0x1172a9379540e31c463e178f08c87f67eb0011ba0deadcd67f78f0028d27f41a", "price_changes": [{"asset_id": "108433110821297511084165806800149498872896490798393090117171505493034184915983", "price": "0.84", "size": "100", "side": "BUY", "hash": "185f22e5000f0fa614b7ce90b0317e09e519ffa8", "best_bid": "0.95", "best_ask": "0.989"}, {"asset_id": "96693063570682405603148415870765547887123700438364743392828151015298561276130", "price": "0.16", "size": "100", "side": "SELL", "hash": "f0ab9d38ae89c138297a600f448b6a6f882e820e", "best_bid": "0.011", "best_ask": "0.05"}], "timestamp": "1769384470252", "event_type": "price_change"}}
{"_local_timestamp": "2026-01-25T23:41:10.340694+00:00", "data": {"market": "0x45c806ae01123f47e7f24fea279b8658a4112cdaa11eee2f9924838a8948bc98", "price_changes": [{"asset_id": "32694948455525029678981577699677214621056167573486416032284086638717669535526", "price": "0.903", "size": "8.2", "side": "SELL", "hash": "87e393393deee3d0bd4c051d0a85d95344ccd438", "best_bid": "0.001", "best_ask": "0.903"}, {"asset_id": "56387091315659274606744882547186473603552761496368462985420229575757384495074", "price": "0.097", "size": "8.2", "side": "BUY", "hash": "af46a7fcd1797d41aa4e0c3c3fc6945028af5b49", "best_bid": "0.097", "best_ask": "0.999"}], "timestamp": "1769384470270", "event_type": "price_change"}}
{"_local_timestamp": "2026-01-25T23:41:10.341433+00:00", "data": {"market": "0x45c806ae01123f47e7f24fea279b8658a4112cdaa11eee2f9924838a8948bc98", "price_changes": [{"asset_id": "32694948455525029678981577699677214621056167573486416032284086638717669535526", "price": "0.909", "size": "91.79", "side": "SELL", "hash": "83ab5d397686840ceeac40a2fc62ac291412c670", "best_bid": "0.001", "best_ask": "0.903"}, {"asset_id": "56387091315659274606744882547186473603552761496368462985420229575757384495074", "price": "0.091", "size": "91.79", "side": "BUY", "hash": "8ba94f8cb165c81a74cd85f392c3187e74e0fab8", "best_bid": "0.097", "best_ask": "0.999"}], "timestamp": "1769384470271", "event_type": "price_change"}}
{"_local_timestamp": "2026-01-25T23:41:10.412327+00:00", "data": {"market": "0x1172a9379540e31c463e178f08c87f67eb0011ba0deadcd67f78f0028d27f41a", "price_changes": [{"asset_id": "108433110821297511084165806800149498872896490798393090117171505493034184915983", "price": "0.14", "size": "1109", "side": "BUY", "hash": "5c9e0949e7fc196a55ca045e6c74d97b1029821f", "best_bid": "0.95", "best_ask": "0.989"}, {"asset_id": "96693063570682405603148415870765547887123700438364743392828151015298561276130", "price": "0.86", "size": "1109", "side": "SELL", "hash": "633bb59046cbd3094e3178caf451f0e0933475ff", "best_bid": "0.011", "best_ask": "0.05"}], "timestamp": "1769384470342", "event_type": "price_change"}}
{"_local_timestamp": "2026-01-25T23:41:10.480604+00:00", "data": {"market": "0x02d056b4ecb79134657b5437bcdd964a7b4008def9f7623e8e1c3a2652996390", "price_changes": [{"asset_id": "75572739037384917026708802532724608493252666334200100326455332920422495907885", "price": "0.01", "size": "21.43", "side": "BUY", "hash": "8b92d09fc543a26e628111668297e0ab228d5f16", "best_bid": "0.03", "best_ask": "0.98"}, {"asset_id": "75662091824125558301238389247455078817972039140363353111649504086477915930016", "price": "0.99", "size": "21.43", "side": "SELL", "hash": "dd7bc27820bba4298679bfa4abc65c6ccdf7962d", "best_bid": "0.02", "best_ask": "0.97"}], "timestamp": "1769384470410", "event_type": "price_change"}}
{"_local_timestamp": "2026-01-25T23:41:10.770487+00:00", "data": {"market": "0x02d056b4ecb79134657b5437bcdd964a7b4008def9f7623e8e1c3a2652996390", "price_changes": [{"asset_id": "75572739037384917026708802532724608493252666334200100326455332920422495907885", "price": "0.01", "size": "79.48", "side": "BUY", "hash": "7597ac245734c78882edc417179ca4360eff741c", "best_bid": "0.03", "best_ask": "0.98"}, {"asset_id": "75662091824125558301238389247455078817972039140363353111649504086477915930016", "price": "0.99", "size": "79.48", "side": "SELL", "hash": "39df830f4cb47526e6d883341a1f20eb8af1265a", "best_bid": "0.02", "best_ask": "0.97"}], "timestamp": "1769384470697", "event_type": "price_change"}}
{"_local_timestamp": "2026-01-25T23:41:10.904925+00:00", "data": {"market": "0x45c806ae01123f47e7f24fea279b8658a4112cdaa11eee2f9924838a8948bc98", "price_changes": [{"asset_id": "32694948455525029678981577699677214621056167573486416032284086638717669535526", "price": "0.904", "size": "0", "side": "SELL", "hash": "76080f7fdb9d7a02c972a3c5f0065e02e7f437cf", "best_bid": "0.001", "best_ask": "0.903"}, {"asset_id": "56387091315659274606744882547186473603552761496368462985420229575757384495074", "price": "0.096", "size": "0", "side": "BUY", "hash": "4cd56f7bf8e8ed72555b0a7e262ae656ef22df18", "best_bid": "0.097", "best_ask": "0.999"}], "timestamp": "1769384470820", "event_type": "price_change"}}
{"_local_timestamp": "2026-01-25T23:41:10.905655+00:00", "data": {"market": "0xe4088389ccc112ce566307b0535326b545db27823876138c37abc36aa80f01b6", "price_changes": [{"asset_id": "111535201652442500376681045716896114819862357479074857390925141208753505497603", "price": "0.002", "size": "22.33", "side": "BUY", "hash": "7704dc1b039fa71a92af418b236474938543b2ed", "best_bid": "0.99", "best_ask": "0.999"}, {"asset_id": "68036185336858618606129914327232954729196470841777365764843049597359907094650", "price": "0.998", "size": "22.33", "side": "SELL", "hash": "d21056cfa9fbc02f4a83bd50c64c93056e7d36c9", "best_bid": "0.001", "best_ask": "0.01"}], "timestamp": "1769384470836", "event_type": "price_change"}}
{"_local_timestamp": "2026-01-25T23:41:11.004952+00:00", "data": {"market": "0x45c806ae01123f47e7f24fea279b8658a4112cdaa11eee2f9924838a8948bc98", "price_changes": [{"asset_id": "32694948455525029678981577699677214621056167573486416032284086638717669535526", "price": "0.902", "size": "5.47", "side": "SELL", "hash": "2d7a88f53705af993f4a9bd7ec7cf1bbcaa98839", "best_bid": "0.001", "best_ask": "0.902"}, {"asset_id": "56387091315659274606744882547186473603552761496368462985420229575757384495074", "price": "0.098", "size": "5.47", "side": "BUY", "hash": "f6f5fd4fdfe1b3930e70f17785326931acf20b0d", "best_bid": "0.098", "best_ask": "0.999"}], "timestamp": "1769384470893", "event_type": "price_change"}}
{"_local_timestamp": "2026-01-25T23:41:11.310797+00:00", "data": {"market": "0xe4088389ccc112ce566307b0535326b545db27823876138c37abc36aa80f01b6", "price_changes": [{"asset_id": "111535201652442500376681045716896114819862357479074857390925141208753505497603", "price": "0.002", "size": "30.13", "side": "BUY", "hash": "3556ade8f38f2909f25de78facf0a14cba3409f2", "best_bid": "0.99", "best_ask": "0.999"}, {"asset_id": "68036185336858618606129914327232954729196470841777365764843049597359907094650", "price": "0.998", "size": "30.13", "side": "SELL", "hash": "3c523db98d1466c59fd88707d8fbbe8801d4bb8d", "best_bid": "0.001", "best_ask": "0.01"}], "timestamp": "1769384471160", "event_type": "price_change"}}
{"_local_timestamp": "2026-01-25T23:41:13.340545+00:00", "data": {"market": "0x1172a9379540e31c463e178f08c87f67eb0011ba0deadcd67f78f0028d27f41a", "price_changes": [{"asset_id": "108433110821297511084165806800149498872896490798393090117171505493034184915983", "price": "0.08", "size": "400", "side": "BUY", "hash": "0c74cd7d1f8d55020aa4259e5765aa4aa00857de", "best_bid": "0.95", "best_ask": "0.989"}, {"asset_id": "96693063570682405603148415870765547887123700438364743392828151015298561276130", "price": "0.92", "size": "400", "side": "SELL", "hash": "4eebaee8ea50f1262de1f1b9c61da0ce9605bb4c", "best_bid": "0.011", "best_ask": "0.05"}], "timestamp": "1769384473267", "event_type": "price_change"}}
{"_local_timestamp": "2026-01-25T23:41:13.613036+00:00", "data": {"market": "0x1172a9379540e31c463e178f08c87f67eb0011ba0deadcd67f78f0028d27f41a", "price_changes": [{"asset_id": "108433110821297511084165806800149498872896490798393090117171505493034184915983", "price": "0.14", "size": "1209", "side": "BUY", "hash": "acd0185875ccb25e34bc5721210d626ab812675a", "best_bid": "0.95", "best_ask": "0.989"}, {"asset_id": "96693063570682405603148415870765547887123700438364743392828151015298561276130", "price": "0.86", "size": "1209", "side": "SELL", "hash": "edd1ec5b08642068a2705e4b4b2d30d750b2d468", "best_bid": "0.011", "best_ask": "0.05"}], "timestamp": "1769384473540", "event_type": "price_change"}}
{"_local_timestamp": "2026-01-25T23:41:14.081008+00:00", "data": {"market": "0xe4088389ccc112ce566307b0535326b545db27823876138c37abc36aa80f01b6", "price_changes": [{"asset_id": "111535201652442500376681045716896114819862357479074857390925141208753505497603", "price": "0.01", "size": "0", "side": "BUY", "hash": "db751ad76cd6519fffdd575b4c028bed2a516558", "best_bid": "0.99", "best_ask": "0.999"}, {"asset_id": "68036185336858618606129914327232954729196470841777365764843049597359907094650", "price": "0.99", "size": "0", "side": "SELL", "hash": "ecda04e8d261d319d2b7fb7ef77b512426a04397", "best_bid": "0.001", "best_ask": "0.01"}], "timestamp": "1769384474000", "event_type": "price_change"}}
{"_local_timestamp": "2026-01-25T23:41:14.382910+00:00", "data": {"market": "0xe4088389ccc112ce566307b0535326b545db27823876138c37abc36aa80f01b6", "price_changes": [{"asset_id": "111535201652442500376681045716896114819862357479074857390925141208753505497603", "price": "0.002", "size": "22.33", "side": "BUY", "hash": "d17768a2502fd5baf14a8c519a12b7f517a6f200", "best_bid": "0.99", "best_ask": "0.999"}, {"asset_id": "68036185336858618606129914327232954729196470841777365764843049597359907094650", "price": "0.998", "size": "22.33", "side": "SELL", "hash": "cc1b800c7f6373ba5a5368d1cbaf1ec5dc7bbd8e", "best_bid": "0.001", "best_ask": "0.01"}], "timestamp": "1769384474306", "event_type": "price_change"}}
{"_local_timestamp": "2026-01-25T23:41:14.473376+00:00", "data": {"market": "0xe4088389ccc112ce566307b0535326b545db27823876138c37abc36aa80f01b6", "price_changes": [{"asset_id": "111535201652442500376681045716896114819862357479074857390925141208753505497603", "price": "0.001", "size": "1068.14", "side": "BUY", "hash": "8c81ba5b6d91abec91f9b08bf1f1ef09c6c787df", "best_bid": "0.99", "best_ask": "0.999"}, {"asset_id": "68036185336858618606129914327232954729196470841777365764843049597359907094650", "price": "0.999", "size": "1068.14", "side": "SELL", "hash": "28e7905a9c4db5d2d98c7ad001cc11b3ebac3708", "best_bid": "0.001", "best_ask": "0.01"}], "timestamp": "1769384474396", "event_type": "price_change"}}
{"_local_timestamp": "2026-01-25T23:41:14.820568+00:00", "data": {"market": "0xe4088389ccc112ce566307b0535326b545db27823876138c37abc36aa80f01b6", "price_changes": [{"asset_id": "111535201652442500376681045716896114819862357479074857390925141208753505497603", "price": "0.002", "size": "30.13", "side": "BUY", "hash": "09f4f1e4c9e88a782f4871bd2e223004d696ca37", "best_bid": "0.99", "best_ask": "0.999"}, {"asset_id": "68036185336858618606129914327232954729196470841777365764843049597359907094650", "price": "0.998", "size": "30.13", "side": "SELL", "hash": "79ce7849c3a071a189f3f7577e56b96da763629e", "best_bid": "0.001", "best_ask": "0.01"}], "timestamp": "1769384474640", "event_type": "price_change"}}
{"_local_timestamp": "2026-01-25T23:41:15.086337+00:00", "data": {"market": "0x1172a9379540e31c463e178f08c87f67eb0011ba0deadcd67f78f0028d27f41a", "price_changes": [{"asset_id": "108433110821297511084165806800149498872896490798393090117171505493034184915983", "price": "0.14", "size": "500", "side": "BUY", "hash": "adeb08709190c88099087ef1860025bbe3b6f389", "best_bid": "0.95", "best_ask": "0.989"}, {"asset_id": "96693063570682405603148415870765547887123700438364743392828151015298561276130", "price": "0.86", "size": "500", "side": "SELL", "hash": "8a7d9041dc10bc3226d23ea7339855750bb885b6", "best_bid": "0.011", "best_ask": "0.05"}], "timestamp": "1769384475001", "event_type": "price_change"}}
{"_local_timestamp": "2026-01-25T23:41:15.130976+00:00", "data": {"market": "0x45c806ae01123f47e7f24fea279b8658a4112cdaa11eee2f9924838a8948bc98", "price_changes": [{"asset_id": "32694948455525029678981577699677214621056167573486416032284086638717669535526", "price": "0.903", "size": "0", "side": "SELL", "hash": "11d4c9c25ec65b4b6b55c87b5278673487e051b7", "best_bid": "0.001", "best_ask": "0.902"}, {"asset_id": "56387091315659274606744882547186473603552761496368462985420229575757384495074", "price": "0.097", "size": "0", "side": "BUY", "hash": "a89fa5047c606f4132efe86422f597cfd44e36d7", "best_bid": "0.098", "best_ask": "0.999"}], "timestamp": "1769384475054", "event_type": "price_change"}}
{"_local_timestamp": "2026-01-25T23:41:15.384285+00:00", "data": {"market": "0x45c806ae01123f47e7f24fea279b8658a4112cdaa11eee2f9924838a8948bc98", "price_changes": [{"asset_id": "32694948455525029678981577699677214621056167573486416032284086638717669535526", "price": "0.901", "size": "8.2", "side": "SELL", "hash": "b7072e04860bb1506ad74f48207365652dc4a641", "best_bid": "0.001", "best_ask": "0.901"}, {"asset_id": "56387091315659274606744882547186473603552761496368462985420229575757384495074", "price": "0.099", "size": "8.2", "side": "BUY", "hash": "4eb2fa61ad38844a5243f23783903a2a179d58ac", "best_bid": "0.099", "best_ask": "0.999"}], "timestamp": "1769384475301", "event_type": "price_change"}}
{"_local_timestamp": "2026-01-25T23:41:15.465234+00:00", "data": {"market": "0xe4088389ccc112ce566307b0535326b545db27823876138c37abc36aa80f01b6", "price_changes": [{"asset_id": "68036185336858618606129914327232954729196470841777365764843049597359907094650", "price": "0.001", "size": "1181", "side": "BUY", "hash": "0dd75993f0ff41d5b3148fd6220666199b3484de", "best_bid": "0.001", "best_ask": "0.01"}, {"asset_id": "111535201652442500376681045716896114819862357479074857390925141208753505497603", "price": "0.999", "size": "1181", "side": "SELL", "hash": "7554551e988f33dde768b625eadc8a168557e704", "best_bid": "0.99", "best_ask": "0.999"}], "timestamp": "1769384475393", "event_type": "price_change"}}
{"_local_timestamp": "2026-01-25T23:41:15.647072+00:00", "data": {"market": "0x45c806ae01123f47e7f24fea279b8658a4112cdaa11eee2f9924838a8948bc98", "price_changes": [{"asset_id": "32694948455525029678981577699677214621056167573486416032284086638717669535526", "price": "0.902", "size": "0", "side": "SELL", "hash": "d94fc75c7917dedc809e9508df5cc433cc0724af", "best_bid": "0.001", "best_ask": "0.901"}, {"asset_id": "56387091315659274606744882547186473603552761496368462985420229575757384495074", "price": "0.098", "size": "0", "side": "BUY", "hash": "5c09e5128272773d4b4c9fe7e69b6993b7c8375d", "best_bid": "0.099", "best_ask": "0.999"}], "timestamp": "1769384475575", "event_type": "price_change"}}
{"_local_timestamp": "2026-01-25T23:41:15.741703+00:00", "data": {"market": "0x45c806ae01123f47e7f24fea279b8658a4112cdaa11eee2f9924838a8948bc98", "price_changes": [{"asset_id": "32694948455525029678981577699677214621056167573486416032284086638717669535526", "price": "0.9", "size": "5.47", "side": "SELL", "hash": "ddfc63010d604432560728dc811c3e4b9db03b6b", "best_bid": "0.001", "best_ask": "0.9"}, {"asset_id": "56387091315659274606744882547186473603552761496368462985420229575757384495074", "price": "0.1", "size": "5.47", "side": "BUY", "hash": "e36b01e664d54ababc2c6d215bae91c34a65c168", "best_bid": "0.1", "best_ask": "0.999"}], "timestamp": "1769384475670", "event_type": "price_change"}}
{"_local_timestamp": "2026-01-25T23:41:15.749750+00:00", "data": {"market": "0x1172a9379540e31c463e178f08c87f67eb0011ba0deadcd67f78f0028d27f41a", "price_changes": [{"asset_id": "108433110821297511084165806800149498872896490798393090117171505493034184915983", "price": "0.14", "size": "1209", "side": "BUY", "hash": "341164e48bc883c818ca05e11ca9f7cca5ad9e21", "best_bid": "0.95", "best_ask": "0.989"}, {"asset_id": "96693063570682405603148415870765547887123700438364743392828151015298561276130", "price": "0.86", "size": "1209", "side": "SELL", "hash": "0d79a2b52097f29f79773898b1a429b4e7883660", "best_bid": "0.011", "best_ask": "0.05"}], "timestamp": "1769384475677", "event_type": "price_change"}}
{"_local_timestamp": "2026-01-25T23:41:15.750662+00:00", "data": {"market": "0xe4088389ccc112ce566307b0535326b545db27823876138c37abc36aa80f01b6", "price_changes": [{"asset_id": "111535201652442500376681045716896114819862357479074857390925141208753505497603", "price": "0.01", "size": "8333", "side": "BUY", "hash": "54a9e8d025babeac168d6134a683a1c91cadfe41", "best_bid": "0.99", "best_ask": "0.999"}, {"asset_id": "68036185336858618606129914327232954729196470841777365764843049597359907094650", "price": "0.99", "size": "8333", "side": "SELL", "hash": "589bf64c2da774040cd94b8287977eb4bc27c40b", "best_bid": "0.001", "best_ask": "0.01"}], "timestamp": "1769384475677", "event_type": "price_change"}}
{"_local_timestamp": "2026-01-25T23:41:16.504025+00:00", "data": {"market": "0x45c806ae01123f47e7f24fea279b8658a4112cdaa11eee2f9924838a8948bc98", "price_changes": [{"asset_id": "56387091315659274606744882547186473603552761496368462985420229575757384495074", "price": "0.001", "size": "1212", "side": "BUY", "hash": "55286eecc3bd44a14aae3c5f3afb58068899ae78", "best_bid": "0.1", "best_ask": "0.999"}, {"asset_id": "32694948455525029678981577699677214621056167573486416032284086638717669535526", "price": "0.999", "size": "1212", "side": "SELL", "hash": "c3b2789fb74747b0d88712ab3b89906ae5f380ed", "best_bid": "0.001", "best_ask": "0.9"}], "timestamp": "1769384476438", "event_type": "price_change"}}
{"_local_timestamp": "2026-01-25T23:41:17.529237+00:00", "data": {"market": "0x45c806ae01123f47e7f24fea279b8658a4112cdaa11eee2f9924838a8948bc98", "price_changes": [{"asset_id": "32694948455525029678981577699677214621056167573486416032284086638717669535526", "price": "0.001", "size": "1133", "side": "BUY", "hash": "85654a29d9e03a6cd4fb93f22e6ca96a8971e84b", "best_bid": "0.001", "best_ask": "0.9"}, {"asset_id": "56387091315659274606744882547186473603552761496368462985420229575757384495074", "price": "0.999", "size": "1133", "side": "SELL", "hash": "a7b4747fe25abaef732cbbcfb28f45f8a3a57d95", "best_bid": "0.1", "best_ask": "0.999"}], "timestamp": "1769384477455", "event_type": "price_change"}}
{"_local_timestamp": "2026-01-25T23:41:18.103199+00:00", "data": {"market": "0xe4088389ccc112ce566307b0535326b545db27823876138c37abc36aa80f01b6", "price_changes": [{"asset_id": "111535201652442500376681045716896114819862357479074857390925141208753505497603", "price": "0.002", "size": "22.33", "side": "BUY", "hash": "e201c57349dbcdccae6361bbbe3bfee7f386501c", "best_bid": "0.99", "best_ask": "0.999"}, {"asset_id": "68036185336858618606129914327232954729196470841777365764843049597359907094650", "price": "0.998", "size": "22.33", "side": "SELL", "hash": "88d33d0e108a0d55f48a94fed502a4084b2b762c", "best_bid": "0.001", "best_ask": "0.01"}], "timestamp": "1769384477987", "event_type": "price_change"}}
{"_local_timestamp": "2026-01-25T23:41:18.254713+00:00", "data": {"market": "0xe4088389ccc112ce566307b0535326b545db27823876138c37abc36aa80f01b6", "price_changes": [{"asset_id": "111535201652442500376681045716896114819862357479074857390925141208753505497603", "price": "0.003", "size": "5.2", "side": "BUY", "hash": "9821ead6c86882a14aa713f27c7c581bb62fadd3", "best_bid": "0.99", "best_ask": "0.999"}, {"asset_id": "68036185336858618606129914327232954729196470841777365764843049597359907094650", "price": "0.997", "size": "5.2", "side": "SELL", "hash": "fafffc87f619a23856fc8519812b1fc5c6a8ae68", "best_bid": "0.001", "best_ask": "0.01"}], "timestamp": "1769384478142", "event_type": "price_change"}}
{"_local_timestamp": "2026-01-25T23:41:18.548847+00:00", "data": {"market": "0x1172a9379540e31c463e178f08c87f67eb0011ba0deadcd67f78f0028d27f41a", "price_changes": [{"asset_id": "108433110821297511084165806800149498872896490798393090117171505493034184915983", "price": "0.001", "size": "1068.4", "side": "BUY", "hash": "9b88040ff2d203bceb145e2ff903ceaa524b9aba", "best_bid": "0.95", "best_ask": "0.989"}, {"asset_id": "96693063570682405603148415870765547887123700438364743392828151015298561276130", "price": "0.999", "size": "1068.4", "side": "SELL", "hash": "666e28534b9ad7f18d174a4d9298007fe2ec5e66", "best_bid": "0.011", "best_ask": "0.05"}], "timestamp": "1769384478458", "event_type": "price_change"}}
{"_local_timestamp": "2026-01-25T23:41:18.728662+00:00", "data": {"market": "0x1172a9379540e31c463e178f08c87f67eb0011ba0deadcd67f78f0028d27f41a", "price_changes": [{"asset_id": "108433110821297511084165806800149498872896490798393090117171505493034184915983", "price": "0.84", "size": "0", "side": "BUY", "hash": "8eed69cd2d54b615035ce7faffe2576ade70ac4d", "best_bid": "0.95", "best_ask": "0.989"}, {"asset_id": "96693063570682405603148415870765547887123700438364743392828151015298561276130", "price": "0.16", "size": "0", "side": "SELL", "hash": "849dd2060991e0492a4e5f9711daee31ab80cb0c", "best_bid": "0.011", "best_ask": "0.05"}], "timestamp": "1769384478658", "event_type": "price_change"}}
{"_local_timestamp": "2026-01-25T23:41:18.880253+00:00", "data": {"market": "0x1172a9379540e31c463e178f08c87f67eb0011ba0deadcd67f78f0028d27f41a", "price_changes": [{"asset_id": "108433110821297511084165806800149498872896490798393090117171505493034184915983", "price": "0.84", "size": "100", "side": "BUY", "hash": "0304b90707cf9f99b27252b69811d8630c097c6b", "best_bid": "0.95", "best_ask": "0.989"}, {"asset_id": "96693063570682405603148415870765547887123700438364743392828151015298561276130", "price": "0.16", "size": "100", "side": "SELL", "hash": "443ac36fa64c870130f4c826a2c169815346dc55", "best_bid": "0.011", "best_ask": "0.05"}], "timestamp": "1769384478804", "event_type": "price_change"}}
{"_local_timestamp": "2026-01-25T23:41:19.421604+00:00", "data": {"market": "0x1172a9379540e31c463e178f08c87f67eb0011ba0deadcd67f78f0028d27f41a", "price_changes": [{"asset_id": "96693063570682405603148415870765547887123700438364743392828151015298561276130", "price": "0.001", "size": "1063", "side": "BUY", "hash": "2391f0278743c283dad95d710abb583b972717cc", "best_bid": "0.011", "best_ask": "0.05"}, {"asset_id": "108433110821297511084165806800149498872896490798393090117171505493034184915983", "price": "0.999", "size": "1063", "side": "SELL", "hash": "c4fcc411161ffda17c7fa9bd4406449e7f09bec0", "best_bid": "0.95", "best_ask": "0.989"}], "timestamp": "1769384479347", "event_type": "price_change"}}
{"_local_timestamp": "2026-01-25T23:41:20.075161+00:00", "data": {"market": "0xe4088389ccc112ce566307b0535326b545db27823876138c37abc36aa80f01b6", "price_changes": [{"asset_id": "111535201652442500376681045716896114819862357479074857390925141208753505497603", "price": "0.01", "size": "0", "side": "BUY", "hash": "e5deb7d023d8077929145a553788cc52f10a4358", "best_bid": "0.99", "best_ask": "0.999"}, {"asset_id": "68036185336858618606129914327232954729196470841777365764843049597359907094650", "price": "0.99", "size": "0", "side": "SELL", "hash": "b92946c3d6929985b97ad15060930689b3dbbd35", "best_bid": "0.001", "best_ask": "0.01"}], "timestamp": "1769384480000", "event_type": "price_change"}}
{"_local_timestamp": "2026-01-25T23:41:20.099226+00:00", "data": {"market": "0x1172a9379540e31c463e178f08c87f67eb0011ba0deadcd67f78f0028d27f41a", "price_changes": [{"asset_id": "108433110821297511084165806800149498872896490798393090117171505493034184915983", "price": "0.14", "size": "500", "side": "BUY", "hash": "c6be8684fc32d2c35e66dc951f34f921fb2d04fa", "best_bid": "0.95", "best_ask": "0.989"}, {"asset_id": "96693063570682405603148415870765547887123700438364743392828151015298561276130", "price": "0.86", "size": "500", "side": "SELL", "hash": "d141e1968291fbdc81098b24f540f01a5133eb42", "best_bid": "0.011", "best_ask": "0.05"}], "timestamp": "1769384480001", "event_type": "price_change"}}
{"_local_timestamp": "2026-01-25T23:41:20.121869+00:00", "data": {"market": "0x45c806ae01123f47e7f24fea279b8658a4112cdaa11eee2f9924838a8948bc98", "price_changes": [{"asset_id": "32694948455525029678981577699677214621056167573486416032284086638717669535526", "price": "0.901", "size": "0", "side": "SELL", "hash": "7b9d594d79497241864f4d0012d70f38570295de", "best_bid": "0.001", "best_ask": "0.9"}, {"asset_id": "56387091315659274606744882547186473603552761496368462985420229575757384495074", "price": "0.099", "size": "0", "side": "BUY", "hash": "dbc3bb8211929f6a5173cd089ec7bbec9b916457", "best_bid": "0.1", "best_ask": "0.999"}], "timestamp": "1769384480012", "event_type": "price_change"}}
{"_local_timestamp": "2026-01-25T23:41:20.283761+00:00", "data": {"market": "0x45c806ae01123f47e7f24fea279b8658a4112cdaa11eee2f9924838a8948bc98", "price_changes": [{"asset_id": "32694948455525029678981577699677214621056167573486416032284086638717669535526", "price": "0.899", "size": "8.2", "side": "SELL", "hash": "68104031d7780e4840bba2b9a88e05d7cb02937f", "best_bid": "0.001", "best_ask": "0.899"}, {"asset_id": "56387091315659274606744882547186473603552761496368462985420229575757384495074", "price": "0.101", "size": "8.2", "side": "BUY", "hash": "446184bf9e94d65f1e9f8bfc5d4e27b41d176150", "best_bid": "0.101", "best_ask": "0.999"}], "timestamp": "1769384480217", "event_type": "price_change"}}
{"_local_timestamp": "2026-01-25T23:41:21.058825+00:00", "data": {"market": "0x1172a9379540e31c463e178f08c87f67eb0011ba0deadcd67f78f0028d27f41a", "price_changes": [{"asset_id": "96693063570682405603148415870765547887123700438364743392828151015298561276130", "price": "0.002", "size": "144.23", "side": "BUY", "hash": "ebad8520b4b9b1ea4872d8565baa53304f4d3e81", "best_bid": "0.011", "best_ask": "0.05"}, {"asset_id": "108433110821297511084165806800149498872896490798393090117171505493034184915983", "price": "0.998", "size": "144.23", "side": "SELL", "hash": "04b5d73e33451a995ec864845a94e2dab8dc6baa", "best_bid": "0.95", "best_ask": "0.989"}], "timestamp": "1769384480988", "event_type": "price_change"}}
{"_local_timestamp": "2026-01-25T23:41:21.285941+00:00", "data": {"market": "0xe4088389ccc112ce566307b0535326b545db27823876138c37abc36aa80f01b6", "price_changes": [{"asset_id": "111535201652442500376681045716896114819862357479074857390925141208753505497603", "price": "0.01", "size": "8333", "side": "BUY", "hash": "7d6b40daf5d322b72a300a69d0fd00a0463c9d3f", "best_bid": "0.99", "best_ask": "0.999"}, {"asset_id": "68036185336858618606129914327232954729196470841777365764843049597359907094650", "price": "0.99", "size": "8333", "side": "SELL", "hash": "fa36939d3b0533df4ee645f6fed3d1c328c8a6b5", "best_bid": "0.001", "best_ask": "0.01"}], "timestamp": "1769384481213", "event_type": "price_change"}}
{"_local_timestamp": "2026-01-25T23:41:21.291605+00:00", "data": {"market": "0x1172a9379540e31c463e178f08c87f67eb0011ba0deadcd67f78f0028d27f41a", "price_changes": [{"asset_id": "108433110821297511084165806800149498872896490798393090117171505493034184915983", "price": "0.14", "size": "1209", "side": "BUY", "hash": "b994cefff18757dc54d734906dcbe1d4b9b0f8ee", "best_bid": "0.95", "best_ask": "0.989"}, {"asset_id": "96693063570682405603148415870765547887123700438364743392828151015298561276130", "price": "0.86", "size": "1209", "side": "SELL", "hash": "dadcee2d3351f0244d99ab437bbbd2302ba930de", "best_bid": "0.011", "best_ask": "0.05"}], "timestamp": "1769384481213", "event_type": "price_change"}}
{"_local_timestamp": "2026-01-25T23:41:21.326016+00:00", "data": {"market": "0x1172a9379540e31c463e178f08c87f67eb0011ba0deadcd67f78f0028d27f41a", "price_changes": [{"asset_id": "96693063570682405603148415870765547887123700438364743392828151015298561276130", "price": "0.002", "size": "155.74", "side": "BUY", "hash": "b83b8e731af3433f72fd8f4c9dcb3261e6012b2a", "best_bid": "0.011", "best_ask": "0.05"}, {"asset_id": "108433110821297511084165806800149498872896490798393090117171505493034184915983", "price": "0.998", "size": "155.74", "side": "SELL", "hash": "00324796d1db9022942ead7ffd913f7abd21cce5", "best_bid": "0.95", "best_ask": "0.989"}], "timestamp": "1769384481258", "event_type": "price_change"}}
{"_local_timestamp": "2026-01-25T23:41:21.333012+00:00", "data": {"market": "0x1172a9379540e31c463e178f08c87f67eb0011ba0deadcd67f78f0028d27f41a", "price_changes": [{"asset_id": "96693063570682405603148415870765547887123700438364743392828151015298561276130", "price": "0.011", "size": "13.98", "side": "BUY", "hash": "3d017c18d3ec1bb24965474ca94eaa1a969ab8c7", "best_bid": "0.011", "best_ask": "0.05"}, {"asset_id": "108433110821297511084165806800149498872896490798393090117171505493034184915983", "price": "0.989", "size": "13.98", "side": "SELL", "hash": "503cdcdaa55ae2dc38de083506d6e1784f63cbdb", "best_bid": "0.95", "best_ask": "0.989"}], "timestamp": "1769384481259", "event_type": "price_change"}}
{"_local_timestamp": "2026-01-25T23:41:22.006458+00:00", "data": {"market": "0x45c806ae01123f47e7f24fea279b8658a4112cdaa11eee2f9924838a8948bc98", "price_changes": [{"asset_id": "32694948455525029678981577699677214621056167573486416032284086638717669535526", "price": "0.9", "size": "0", "side": "SELL", "hash": "0045fd1c610660ba6e0b7b4825e52a90a1050970", "best_bid": "0.001", "best_ask": "0.899"}, {"asset_id": "56387091315659274606744882547186473603552761496368462985420229575757384495074", "price": "0.1", "size": "0", "side": "BUY", "hash": "e9c55636ae342cfc2d3515d07c6cadcff437318b", "best_bid": "0.101", "best_ask": "0.999"}], "timestamp": "1769384481933", "event_type": "price_change"}}
{"_local_timestamp": "2026-01-25T23:41:22.148796+00:00", "data": {"market": "0x45c806ae01123f47e7f24fea279b8658a4112cdaa11eee2f9924838a8948bc98", "price_changes": [{"asset_id": "32694948455525029678981577699677214621056167573486416032284086638717669535526", "price": "0.898", "size": "5.47", "side": "SELL", "hash": "5c530c651e3f0e610cbb59ff7e069e67635446aa", "best_bid": "0.001", "best_ask": "0.898"}, {"asset_id": "56387091315659274606744882547186473603552761496368462985420229575757384495074", "price": "0.102", "size": "5.47", "side": "BUY", "hash": "04175b976073fd585cdb6ff70c205dade9b7e395", "best_bid": "0.102", "best_ask": "0.999"}], "timestamp": "1769384482050", "event_type": "price_change"}}
{"_local_timestamp": "2026-01-25T23:41:23.089082+00:00", "data": {"market": "0x1172a9379540e31c463e178f08c87f67eb0011ba0deadcd67f78f0028d27f41a", "price_changes": [{"asset_id": "108433110821297511084165806800149498872896490798393090117171505493034184915983", "price": "0.84", "size": "0", "side": "BUY", "hash": "3a51e5daa5f42b1a97cfd6e2072108f9e17220fe", "best_bid": "0.95", "best_ask": "0.989"}, {"asset_id": "96693063570682405603148415870765547887123700438364743392828151015298561276130", "price": "0.16", "size": "0", "side": "SELL", "hash": "0308a639be4d3fdf8f374108865bef65a83207a3", "best_bid": "0.011", "best_ask": "0.05"}], "timestamp": "1769384483001", "event_type": "price_change"}}
{"_local_timestamp": "2026-01-25T23:41:23.153999+00:00", "data": {"market": "0x1172a9379540e31c463e178f08c87f67eb0011ba0deadcd67f78f0028d27f41a", "price_changes": [{"asset_id": "108433110821297511084165806800149498872896490798393090117171505493034184915983", "price": "0.83", "size": "123.72", "side": "BUY", "hash": "0f5fc84e43efdbee5f56050f0f93d87c6c9bbc2e", "best_bid": "0.95", "best_ask": "0.989"}, {"asset_id": "96693063570682405603148415870765547887123700438364743392828151015298561276130", "price": "0.17", "size": "123.72", "side": "SELL", "hash": "8a244613bd376fa7603cd62c672f68c6da4bbe20", "best_bid": "0.011", "best_ask": "0.05"}], "timestamp": "1769384483046", "event_type": "price_change"}}
{"_local_timestamp": "2026-01-25T23:41:23.197173+00:00", "data": {"market": "0x1172a9379540e31c463e178f08c87f67eb0011ba0deadcd67f78f0028d27f41a", "price_changes": [{"asset_id": "108433110821297511084165806800149498872896490798393090117171505493034184915983", "price": "0.81", "size": "0", "side": "BUY", "hash": "f6d7fdf0f5bf34313f437b758b0bf16f95153e3e", "best_bid": "0.95", "best_ask": "0.989"}, {"asset_id": "96693063570682405603148415870765547887123700438364743392828151015298561276130", "price": "0.19", "size": "0", "side": "SELL", "hash": "3cc2e4ab08c8cc18476cfe752fd2944085be5d67", "best_bid": "0.011", "best_ask": "0.05"}], "timestamp": "1769384483095", "event_type": "price_change"}}
{"_local_timestamp": "2026-01-25T23:41:23.202802+00:00", "data": {"market": "0x1172a9379540e31c463e178f08c87f67eb0011ba0deadcd67f78f0028d27f41a", "price_changes": [{"asset_id": "108433110821297511084165806800149498872896490798393090117171505493034184915983", "price": "0.83", "size": "23.72", "side": "BUY", "hash": "4ebe398afc02e890e4f5758482f24484a3fadaba", "best_bid": "0.95", "best_ask": "0.989"}, {"asset_id": "96693063570682405603148415870765547887123700438364743392828151015298561276130", "price": "0.17", "size": "23.72", "side": "SELL", "hash": "fe82b1c53e99448364ae39a7e96b70032af4cf4c", "best_bid": "0.011", "best_ask": "0.05"}], "timestamp": "1769384483114", "event_type": "price_change"}}
{"_local_timestamp": "2026-01-25T23:41:23.269826+00:00", "data": {"market": "0x1172a9379540e31c463e178f08c87f67eb0011ba0deadcd67f78f0028d27f41a", "price_changes": [{"asset_id": "108433110821297511084165806800149498872896490798393090117171505493034184915983", "price": "0.84", "size": "100", "side": "BUY", "hash": "e1d16cf99aabb7d463a07ea2758548f91f724e51", "best_bid": "0.95", "best_ask": "0.989"}, {"asset_id": "96693063570682405603148415870765547887123700438364743392828151015298561276130", "price": "0.16", "size": "100", "side": "SELL", "hash": "599c7777fe04465cea201d36bcbff93c679ca7a3", "best_bid": "0.011", "best_ask": "0.05"}], "timestamp": "1769384483191", "event_type": "price_change"}}
{"_local_timestamp": "2026-01-25T23:41:23.297704+00:00", "data": {"market": "0x1172a9379540e31c463e178f08c87f67eb0011ba0deadcd67f78f0028d27f41a", "price_changes": [{"asset_id": "108433110821297511084165806800149498872896490798393090117171505493034184915983", "price": "0.82", "size": "20", "side": "BUY", "hash": "a09cc9f70d5f54a86e62bc1a688b0bc603dae4a1", "best_bid": "0.95", "best_ask": "0.989"}, {"asset_id": "96693063570682405603148415870765547887123700438364743392828151015298561276130", "price": "0.18", "size": "20", "side": "SELL", "hash": "ab645551c58f0e7d92e7e0d0fe962bc0a1a57feb", "best_bid": "0.011", "best_ask": "0.05"}], "timestamp": "1769384483218", "event_type": "price_change"}}
{"_local_timestamp": "2026-01-25T23:41:23.298503+00:00", "data": {"market": "0x1172a9379540e31c463e178f08c87f67eb0011ba0deadcd67f78f0028d27f41a", "price_changes": [{"asset_id": "108433110821297511084165806800149498872896490798393090117171505493034184915983", "price": "0.84", "size": "0", "side": "BUY", "hash": "7a6897e60b4a9b6dabf07181ea1c87e2a07e2490", "best_bid": "0.95", "best_ask": "0.989"}, {"asset_id": "96693063570682405603148415870765547887123700438364743392828151015298561276130", "price": "0.16", "size": "0", "side": "SELL", "hash": "3857fb12aeffef3a231858562486dd52a65da0f1", "best_bid": "0.011", "best_ask": "0.05"}], "timestamp": "1769384483221", "event_type": "price_change"}}
{"_local_timestamp": "2026-01-25T23:41:23.473095+00:00", "data": {"market": "0x1172a9379540e31c463e178f08c87f67eb0011ba0deadcd67f78f0028d27f41a", "price_changes": [{"asset_id": "108433110821297511084165806800149498872896490798393090117171505493034184915983", "price": "0.84", "size": "62", "side": "BUY", "hash": "6c295e221f58b0a0374b15ed0f041ea9f2cde107", "best_bid": "0.95", "best_ask": "0.989"}, {"asset_id": "96693063570682405603148415870765547887123700438364743392828151015298561276130", "price": "0.16", "size": "62", "side": "SELL", "hash": "a0d7654216007ced00d64a376596c6e0cdc921bf", "best_bid": "0.011", "best_ask": "0.05"}], "timestamp": "1769384483398", "event_type": "price_change"}}
{"_local_timestamp": "2026-01-25T23:41:23.474766+00:00", "data": {"market": "0x1172a9379540e31c463e178f08c87f67eb0011ba0deadcd67f78f0028d27f41a", "price_changes": [{"asset_id": "108433110821297511084165806800149498872896490798393090117171505493034184915983", "price": "0.84", "size": "0", "side": "BUY", "hash": "cee58b7acb300afff5d628f3f43b5604d0fcc4d1", "best_bid": "0.95", "best_ask": "0.989"}, {"asset_id": "96693063570682405603148415870765547887123700438364743392828151015298561276130", "price": "0.16", "size": "0", "side": "SELL", "hash": "437d6423967ef529f1e91055847222d61e5d724f", "best_bid": "0.011", "best_ask": "0.05"}], "timestamp": "1769384483403", "event_type": "price_change"}}
{"_local_timestamp": "2026-01-25T23:41:23.626089+00:00", "data": {"market": "0x1172a9379540e31c463e178f08c87f67eb0011ba0deadcd67f78f0028d27f41a", "price_changes": [{"asset_id": "108433110821297511084165806800149498872896490798393090117171505493034184915983", "price": "0.8", "size": "130.83", "side": "BUY", "hash": "b4cec45fb418c254124d24dcb8b37cc5b865a901", "best_bid": "0.95", "best_ask": "0.989"}, {"asset_id": "96693063570682405603148415870765547887123700438364743392828151015298561276130", "price": "0.2", "size": "130.83", "side": "SELL", "hash": "430a4b8ab7bb0f9aac39e136ad8f6391c287da6e", "best_bid": "0.011", "best_ask": "0.05"}], "timestamp": "1769384483557", "event_type": "price_change"}}
{"_local_timestamp": "2026-01-25T23:41:23.771448+00:00", "data": {"market": "0x1172a9379540e31c463e178f08c87f67eb0011ba0deadcd67f78f0028d27f41a", "price_changes": [{"asset_id": "108433110821297511084165806800149498872896490798393090117171505493034184915983", "price": "0.82", "size": "0", "side": "BUY", "hash": "3ebcf8bf5a8cff4685e845703d4ec808b8c092c8", "best_bid": "0.95", "best_ask": "0.989"}, {"asset_id": "96693063570682405603148415870765547887123700438364743392828151015298561276130", "price": "0.18", "size": "0", "side": "SELL", "hash": "be80d251eae9ffd1f6671a872f5e237c3da9031f", "best_bid": "0.011", "best_ask": "0.05"}], "timestamp": "1769384483697", "event_type": "price_change"}}
{"_local_timestamp": "2026-01-25T23:41:23.783556+00:00", "data": {"market": "0x1172a9379540e31c463e178f08c87f67eb0011ba0deadcd67f78f0028d27f41a", "price_changes": [{"asset_id": "108433110821297511084165806800149498872896490798393090117171505493034184915983", "price": "0.8", "size": "30.83", "side": "BUY", "hash": "5088976e95115cfaadec7d237c8c6eb77c71ea0b", "best_bid": "0.95", "best_ask": "0.989"}, {"asset_id": "96693063570682405603148415870765547887123700438364743392828151015298561276130", "price": "0.2", "size": "30.83", "side": "SELL", "hash": "2cbd0173cb1f28d988868ab20a617560fed8939a", "best_bid": "0.011", "best_ask": "0.05"}], "timestamp": "1769384483713", "event_type": "price_change"}}
{"_local_timestamp": "2026-01-25T23:41:23.899271+00:00", "data": {"market": "0x1172a9379540e31c463e178f08c87f67eb0011ba0deadcd67f78f0028d27f41a", "price_changes": [{"asset_id": "108433110821297511084165806800149498872896490798393090117171505493034184915983", "price": "0.81", "size": "62", "side": "BUY", "hash": "129946dab5b5c35eff80fd347fd7a83d066238f8", "best_bid": "0.95", "best_ask": "0.989"}, {"asset_id": "96693063570682405603148415870765547887123700438364743392828151015298561276130", "price": "0.19", "size": "62", "side": "SELL", "hash": "e8bca51de5ed8bbb684ca589bfac36286d8a973f", "best_bid": "0.011", "best_ask": "0.05"}], "timestamp": "1769384483771", "event_type": "price_change"}}
{"_local_timestamp": "2026-01-25T23:41:24.119129+00:00", "data": {"market": "0x45c806ae01123f47e7f24fea279b8658a4112cdaa11eee2f9924838a8948bc98", "price_changes": [{"asset_id": "56387091315659274606744882547186473603552761496368462985420229575757384495074", "price": "0.09", "size": "0", "side": "BUY", "hash": "e28d27f39c44d75c667608f7ae146bda05034ec8", "best_bid": "0.102", "best_ask": "0.999"}, {"asset_id": "32694948455525029678981577699677214621056167573486416032284086638717669535526", "price": "0.91", "size": "0", "side": "SELL", "hash": "aaa5a9472b5e77bdc4bf75a50ff0e33b744bb050", "best_bid": "0.001", "best_ask": "0.898"}], "timestamp": "1769384484041", "event_type": "price_change"}}
{"_local_timestamp": "2026-01-25T23:41:24.300853+00:00", "data": {"market": "0xe4088389ccc112ce566307b0535326b545db27823876138c37abc36aa80f01b6", "price_changes": [{"asset_id": "111535201652442500376681045716896114819862357479074857390925141208753505497603", "price": "0.003", "size": "0", "side": "BUY", "hash": "e1394ddc4fcc7f268c4e4d5422f76db5b42746fe", "best_bid": "0.99", "best_ask": "0.999"}, {"asset_id": "68036185336858618606129914327232954729196470841777365764843049597359907094650", "price": "0.997", "size": "0", "side": "SELL", "hash": "8e3bacca8843f582444cf809455f5e9bd09ff422", "best_bid": "0.001", "best_ask": "0.01"}], "timestamp": "1769384484231", "event_type": "price_change"}}
{"_local_timestamp": "2026-01-25T23:41:24.554628+00:00", "data": {"market": "0xe4088389ccc112ce566307b0535326b545db27823876138c37abc36aa80f01b6", "price_changes": [{"asset_id": "111535201652442500376681045716896114819862357479074857390925141208753505497603", "price": "0.002", "size": "30.13", "side": "BUY", "hash": "abff23120f545fc219165d2e729ccc3796ece6d9", "best_bid": "0.99", "best_ask": "0.999"}, {"asset_id": "68036185336858618606129914327232954729196470841777365764843049597359907094650", "price": "0.998", "size": "30.13", "side": "SELL", "hash": "91e3bc7fe72051e690374317454ac167e3f75220", "best_bid": "0.001", "best_ask": "0.01"}], "timestamp": "1769384484487", "event_type": "price_change"}}
{"_local_timestamp": "2026-01-25T23:41:26.072047+00:00", "data": {"market": "0xe4088389ccc112ce566307b0535326b545db27823876138c37abc36aa80f01b6", "price_changes": [{"asset_id": "111535201652442500376681045716896114819862357479074857390925141208753505497603", "price": "0.01", "size": "0", "side": "BUY", "hash": "7ae0b60d57e56b01749de0e735969054a49cd857", "best_bid": "0.99", "best_ask": "0.999"}, {"asset_id": "68036185336858618606129914327232954729196470841777365764843049597359907094650", "price": "0.99", "size": "0", "side": "SELL", "hash": "3c15366d6e284cb6643f48e0c82c2b7edd248744", "best_bid": "0.001", "best_ask": "0.01"}], "timestamp": "1769384486000", "event_type": "price_change"}}
{"_local_timestamp": "2026-01-25T23:41:26.077312+00:00", "data": {"market": "0x1172a9379540e31c463e178f08c87f67eb0011ba0deadcd67f78f0028d27f41a", "price_changes": [{"asset_id": "108433110821297511084165806800149498872896490798393090117171505493034184915983", "price": "0.14", "size": "500", "side": "BUY", "hash": "046016ad061f8becfc9a50e533a4093746c41b85", "best_bid": "0.95", "best_ask": "0.989"}, {"asset_id": "96693063570682405603148415870765547887123700438364743392828151015298561276130", "price": "0.86", "size": "500", "side": "SELL", "hash": "a30217b753216a00f9b8f34d0574604a11bfdd4d", "best_bid": "0.011", "best_ask": "0.05"}], "timestamp": "1769384486001", "event_type": "price_change"}}
{"_local_timestamp": "2026-01-25T23:41:26.399588+00:00", "data": {"market": "0x45c806ae01123f47e7f24fea279b8658a4112cdaa11eee2f9924838a8948bc98", "price_changes": [{"asset_id": "56387091315659274606744882547186473603552761496368462985420229575757384495074", "price": "0.1", "size": "100", "side": "BUY", "hash": "0eeae6acf704ecb2abef54c194339cd15ff7d345", "best_bid": "0.102", "best_ask": "0.999"}, {"asset_id": "32694948455525029678981577699677214621056167573486416032284086638717669535526", "price": "0.9", "size": "100", "side": "SELL", "hash": "9f3d91b79f2e03150fd6d543d8da4537fd026982", "best_bid": "0.001", "best_ask": "0.898"}], "timestamp": "1769384486318", "event_type": "price_change"}}
{"_local_timestamp": "2026-01-25T23:41:26.653182+00:00", "data": {"market": "0x45c806ae01123f47e7f24fea279b8658a4112cdaa11eee2f9924838a8948bc98", "price_changes": [{"asset_id": "32694948455525029678981577699677214621056167573486416032284086638717669535526", "price": "0.899", "size": "0", "side": "SELL", "hash": "0ef72e4dbc2d3d07d0990df7f86bb375c280d605", "best_bid": "0.001", "best_ask": "0.898"}, {"asset_id": "56387091315659274606744882547186473603552761496368462985420229575757384495074", "price": "0.101", "size": "0", "side": "BUY", "hash": "01b57d84896e7a7ec258c4b33e088356a4c7bd81", "best_bid": "0.102", "best_ask": "0.999"}], "timestamp": "1769384486581", "event_type": "price_change"}}
{"_local_timestamp": "2026-01-25T23:41:26.653984+00:00", "data": {"market": "0x45c806ae01123f47e7f24fea279b8658a4112cdaa11eee2f9924838a8948bc98", "price_changes": [{"asset_id": "32694948455525029678981577699677214621056167573486416032284086638717669535526", "price": "0.909", "size": "0", "side": "SELL", "hash": "0ef72e4dbc2d3d07d0990df7f86bb375c280d605", "best_bid": "0.001", "best_ask": "0.898"}, {"asset_id": "56387091315659274606744882547186473603552761496368462985420229575757384495074", "price": "0.091", "size": "0", "side": "BUY", "hash": "01b57d84896e7a7ec258c4b33e088356a4c7bd81", "best_bid": "0.102", "best_ask": "0.999"}], "timestamp": "1769384486581", "event_type": "price_change"}}
{"_local_timestamp": "2026-01-25T23:41:26.779945+00:00", "data": {"market": "0xe4088389ccc112ce566307b0535326b545db27823876138c37abc36aa80f01b6", "price_changes": [{"asset_id": "111535201652442500376681045716896114819862357479074857390925141208753505497603", "price": "0.01", "size": "8333", "side": "BUY", "hash": "c5323d4db968cc591ea25a78f46ff8dc10791c47", "best_bid": "0.99", "best_ask": "0.999"}, {"asset_id": "68036185336858618606129914327232954729196470841777365764843049597359907094650", "price": "0.99", "size": "8333", "side": "SELL", "hash": "cea8b51cb8d6eead0cd7a0befdc15f531c3ba4fd", "best_bid": "0.001", "best_ask": "0.01"}], "timestamp": "1769384486703", "event_type": "price_change"}}
{"_local_timestamp": "2026-01-25T23:41:26.912556+00:00", "data": {"market": "0x45c806ae01123f47e7f24fea279b8658a4112cdaa11eee2f9924838a8948bc98", "price_changes": [{"asset_id": "32694948455525029678981577699677214621056167573486416032284086638717669535526", "price": "0.897", "size": "8.2", "side": "SELL", "hash": "7bcb5a3270a017105353ffb5cd82890ceedb379e", "best_bid": "0.001", "best_ask": "0.897"}, {"asset_id": "56387091315659274606744882547186473603552761496368462985420229575757384495074", "price": "0.103", "size": "8.2", "side": "BUY", "hash": "56c2d231c374e755201ec973bf0e6c7656135f83", "best_bid": "0.103", "best_ask": "0.999"}], "timestamp": "1769384486835", "event_type": "price_change"}}
{"_local_timestamp": "2026-01-25T23:41:26.913986+00:00", "data": {"market": "0x45c806ae01123f47e7f24fea279b8658a4112cdaa11eee2f9924838a8948bc98", "price_changes": [{"asset_id": "32694948455525029678981577699677214621056167573486416032284086638717669535526", "price": "0.899", "size": "91.79", "side": "SELL", "hash": "ef83bb5b5c36b324c8624d9c9098d063abb97fbe", "best_bid": "0.001", "best_ask": "0.897"}, {"asset_id": "56387091315659274606744882547186473603552761496368462985420229575757384495074", "price": "0.101", "size": "91.79", "side": "BUY", "hash": "ce774b066883fc5ec87e0546596dd9f5b4c41920", "best_bid": "0.103", "best_ask": "0.999"}], "timestamp": "1769384486836", "event_type": "price_change"}}
{"_local_timestamp": "2026-01-25T23:41:26.933998+00:00", "data": {"market": "0x1172a9379540e31c463e178f08c87f67eb0011ba0deadcd67f78f0028d27f41a", "price_changes": [{"asset_id": "108433110821297511084165806800149498872896490798393090117171505493034184915983", "price": "0.14", "size": "1209", "side": "BUY", "hash": "2ea37bafd5db3c5f45141ffd5d704e919090ac3e", "best_bid": "0.95", "best_ask": "0.989"}, {"asset_id": "96693063570682405603148415870765547887123700438364743392828151015298561276130", "price": "0.86", "size": "1209", "side": "SELL", "hash": "d96191ec8a47a4d012e4d3181da1cea8e555bb11", "best_bid": "0.011", "best_ask": "0.05"}], "timestamp": "1769384486857", "event_type": "price_change"}}
{"_local_timestamp": "2026-01-25T23:41:27.112061+00:00", "data": {"market": "0xe4088389ccc112ce566307b0535326b545db27823876138c37abc36aa80f01b6", "price_changes": [{"asset_id": "111535201652442500376681045716896114819862357479074857390925141208753505497603", "price": "0.002", "size": "22.33", "side": "BUY", "hash": "415d09f4250b88f490ef1a8f7eeeb0a19a043192", "best_bid": "0.99", "best_ask": "0.999"}, {"asset_id": "68036185336858618606129914327232954729196470841777365764843049597359907094650", "price": "0.998", "size": "22.33", "side": "SELL", "hash": "4dfaee5f36e97ea062382410f1387a00fb4cbb7f", "best_bid": "0.001", "best_ask": "0.01"}], "timestamp": "1769384487023", "event_type": "price_change"}}
{"_local_timestamp": "2026-01-25T23:41:27.374920+00:00", "data": {"market": "0xe4088389ccc112ce566307b0535326b545db27823876138c37abc36aa80f01b6", "price_changes": [{"asset_id": "111535201652442500376681045716896114819862357479074857390925141208753505497603", "price": "0.002", "size": "30.13", "side": "BUY", "hash": "6a360ea23fcda91af1f62f0ffd6ee70a172b599d", "best_bid": "0.99", "best_ask": "0.999"}, {"asset_id": "68036185336858618606129914327232954729196470841777365764843049597359907094650", "price": "0.998", "size": "30.13", "side": "SELL", "hash": "6466c694395aa9e93b96776ab307d0168b33862b", "best_bid": "0.001", "best_ask": "0.01"}], "timestamp": "1769384487305", "event_type": "price_change"}}
{"_local_timestamp": "2026-01-25T23:41:27.839164+00:00", "data": {"market": "0x45c806ae01123f47e7f24fea279b8658a4112cdaa11eee2f9924838a8948bc98", "price_changes": [{"asset_id": "32694948455525029678981577699677214621056167573486416032284086638717669535526", "price": "0.898", "size": "0", "side": "SELL", "hash": "5966bd258c56eb791aa4ec4d2fb9bac02651e419", "best_bid": "0.001", "best_ask": "0.897"}, {"asset_id": "56387091315659274606744882547186473603552761496368462985420229575757384495074", "price": "0.102", "size": "0", "side": "BUY", "hash": "e65763a19e1edcb47bfc8fe9eda3bf3fc0b25f3a", "best_bid": "0.103", "best_ask": "0.999"}], "timestamp": "1769384487761", "event_type": "price_change"}}
{"_local_timestamp": "2026-01-25T23:41:27.957576+00:00", "data": {"market": "0x45c806ae01123f47e7f24fea279b8658a4112cdaa11eee2f9924838a8948bc98", "price_changes": [{"asset_id": "32694948455525029678981577699677214621056167573486416032284086638717669535526", "price": "0.896", "size": "5.47", "side": "SELL", "hash": "8572fa0a45bbf405932b299ca502236c503855af", "best_bid": "0.001", "best_ask": "0.896"}, {"asset_id": "56387091315659274606744882547186473603552761496368462985420229575757384495074", "price": "0.104", "size": "5.47", "side": "BUY", "hash": "e50cb0984438bdf9f0b535188ad12107393f6499", "best_bid": "0.104", "best_ask": "0.999"}], "timestamp": "1769384487879", "event_type": "price_change"}}
{"_local_timestamp": "2026-01-25T23:41:28.555284+00:00", "data": {"market": "0x8e8d315038e54eb4b3b7108ebfc48986e286dd3a53408a293263c73bb64040be", "price_changes": [{"asset_id": "73877455263924215947237673601962666377355671254828449751196120845554792983538", "price": "0.01", "size": "19.31", "side": "BUY", "hash": "97e6e95de1cc20ef5ac94305def36514c1b5dff3", "best_bid": "0.02", "best_ask": "0.98"}, {"asset_id": "45695296729134875133282986964941962331716131780439753949097910486621574361250", "price": "0.99", "size": "19.31", "side": "SELL", "hash": "e78a7e05a06c31666db56096643a2919dc5a88b3", "best_bid": "0.02", "best_ask": "0.98"}], "timestamp": "1769384488482", "event_type": "price_change"}}
{"_local_timestamp": "2026-01-25T23:41:28.752862+00:00", "data": {"market": "0x8e8d315038e54eb4b3b7108ebfc48986e286dd3a53408a293263c73bb64040be", "price_changes": [{"asset_id": "73877455263924215947237673601962666377355671254828449751196120845554792983538", "price": "0.01", "size": "58.97", "side": "BUY", "hash": "b8db402a842d8f1237d39d565ad9514f42e59dcf", "best_bid": "0.02", "best_ask": "0.98"}, {"asset_id": "45695296729134875133282986964941962331716131780439753949097910486621574361250", "price": "0.99", "size": "58.97", "side": "SELL", "hash": "34bf938a2eeb16808cc76f789a518d79ce8c3e7e", "best_bid": "0.02", "best_ask": "0.98"}], "timestamp": "1769384488683", "event_type": "price_change"}}
{"_local_timestamp": "2026-01-25T23:41:29.060970+00:00", "data": {"market": "0x45c806ae01123f47e7f24fea279b8658a4112cdaa11eee2f9924838a8948bc98", "price_changes": [{"asset_id": "56387091315659274606744882547186473603552761496368462985420229575757384495074", "price": "0.1", "size": "0", "side": "BUY", "hash": "91abaa5958de1d7c4fe4e09fc439bbabef44ea2b", "best_bid": "0.104", "best_ask": "0.999"}, {"asset_id": "32694948455525029678981577699677214621056167573486416032284086638717669535526", "price": "0.9", "size": "0", "side": "SELL", "hash": "c67cdc8dff9e08858b911a960813cfce00e1566f", "best_bid": "0.001", "best_ask": "0.896"}], "timestamp": "1769384488988", "event_type": "price_change"}}
{"_local_timestamp": "2026-01-25T23:41:30.011246+00:00", "data": {"market": "0xe4088389ccc112ce566307b0535326b545db27823876138c37abc36aa80f01b6", "price_changes": [{"asset_id": "111535201652442500376681045716896114819862357479074857390925141208753505497603", "price": "0.002", "size": "22.33", "side": "BUY", "hash": "ca5c16edf1714edca0eddd0bd7f42f0de691db03", "best_bid": "0.99", "best_ask": "0.999"}, {"asset_id": "68036185336858618606129914327232954729196470841777365764843049597359907094650", "price": "0.998", "size": "22.33", "side": "SELL", "hash": "bb64e807a0708b0533f4ad85fd36681c404ae2a3", "best_bid": "0.001", "best_ask": "0.01"}], "timestamp": "1769384489938", "event_type": "price_change"}}
{"_local_timestamp": "2026-01-25T23:41:30.423467+00:00", "data": {"market": "0xe4088389ccc112ce566307b0535326b545db27823876138c37abc36aa80f01b6", "price_changes": [{"asset_id": "111535201652442500376681045716896114819862357479074857390925141208753505497603", "price": "0.002", "size": "30.13", "side": "BUY", "hash": "f03742332fb8bc17cd8ee020e54594d073a621cf", "best_bid": "0.99", "best_ask": "0.999"}, {"asset_id": "68036185336858618606129914327232954729196470841777365764843049597359907094650", "price": "0.998", "size": "30.13", "side": "SELL", "hash": "e630c951236805cf4d92d7526e8f64e8ed698100", "best_bid": "0.001", "best_ask": "0.01"}], "timestamp": "1769384490349", "event_type": "price_change"}}
{"_local_timestamp": "2026-01-25T23:41:31.080426+00:00", "data": {"market": "0x1172a9379540e31c463e178f08c87f67eb0011ba0deadcd67f78f0028d27f41a", "price_changes": [{"asset_id": "108433110821297511084165806800149498872896490798393090117171505493034184915983", "price": "0.14", "size": "500", "side": "BUY", "hash": "d6d133e86e37503aedb0c590878e967244bf8bf8", "best_bid": "0.95", "best_ask": "0.989"}, {"asset_id": "96693063570682405603148415870765547887123700438364743392828151015298561276130", "price": "0.86", "size": "500", "side": "SELL", "hash": "ccc9c871c29b3512eba10733b31d21570955a41b", "best_bid": "0.011", "best_ask": "0.05"}], "timestamp": "1769384491000", "event_type": "price_change"}}
{"_local_timestamp": "2026-01-25T23:41:31.094293+00:00", "data": {"market": "0xe4088389ccc112ce566307b0535326b545db27823876138c37abc36aa80f01b6", "price_changes": [{"asset_id": "111535201652442500376681045716896114819862357479074857390925141208753505497603", "price": "0.01", "size": "0", "side": "BUY", "hash": "19f4e1d64bfad1161537e963733945460abe3967", "best_bid": "0.99", "best_ask": "0.999"}, {"asset_id": "68036185336858618606129914327232954729196470841777365764843049597359907094650", "price": "0.99", "size": "0", "side": "SELL", "hash": "6fd4028db70f0cc3601b4a8272b0193b2b9cf560", "best_bid": "0.001", "best_ask": "0.01"}], "timestamp": "1769384491001", "event_type": "price_change"}}
{"_local_timestamp": "2026-01-25T23:41:31.762204+00:00", "data": {"market": "0x45c806ae01123f47e7f24fea279b8658a4112cdaa11eee2f9924838a8948bc98", "price_changes": [{"asset_id": "56387091315659274606744882547186473603552761496368462985420229575757384495074", "price": "0.1", "size": "100", "side": "BUY", "hash": "f4e34e79bdfbf4e26c1705ee6c322ad6740e714f", "best_bid": "0.104", "best_ask": "0.999"}, {"asset_id": "32694948455525029678981577699677214621056167573486416032284086638717669535526", "price": "0.9", "size": "100", "side": "SELL", "hash": "59594da33a6c0883ee0b5511b7ded3102d1a45ff", "best_bid": "0.001", "best_ask": "0.896"}], "timestamp": "1769384491691", "event_type": "price_change"}}
{"_local_timestamp": "2026-01-25T23:41:32.418238+00:00", "data": {"market": "0x1172a9379540e31c463e178f08c87f67eb0011ba0deadcd67f78f0028d27f41a", "price_changes": [{"asset_id": "108433110821297511084165806800149498872896490798393090117171505493034184915983", "price": "0.14", "size": "1209", "side": "BUY", "hash": "ae73d18b87c6b9f2d554b993642e90c7721e8fa5", "best_bid": "0.95", "best_ask": "0.989"}, {"asset_id": "96693063570682405603148415870765547887123700438364743392828151015298561276130", "price": "0.86", "size": "1209", "side": "SELL", "hash": "bb40bca1691bf05fa46d9c8974e2822eae862d52", "best_bid": "0.011", "best_ask": "0.05"}], "timestamp": "1769384492342", "event_type": "price_change"}}
{"_local_timestamp": "2026-01-25T23:41:32.526127+00:00", "data": {"market": "0x4d351854a5011cdb0c141ef8d87a8321213d1e0a3b258a3745c03d34dd85d7a7", "price_changes": [{"asset_id": "30230407831690929960155342999106742333605054613110743527797581940998715084536", "price": "0.01", "size": "11.24", "side": "BUY", "hash": "c81211af697d3243e9164982539212eab0aa80a5", "best_bid": "0.01", "best_ask": "0.98"}, {"asset_id": "89397257210211231854366309279840798542964120041524548078365395989129276413393", "price": "0.99", "size": "11.24", "side": "SELL", "hash": "e333e661e28632dfc0ea65bffc550bece793de99", "best_bid": "0.02", "best_ask": "0.99"}], "timestamp": "1769384492453", "event_type": "price_change"}}
{"_local_timestamp": "2026-01-25T23:41:32.622844+00:00", "data": {"market": "0xe4088389ccc112ce566307b0535326b545db27823876138c37abc36aa80f01b6", "price_changes": [{"asset_id": "111535201652442500376681045716896114819862357479074857390925141208753505497603", "price": "0.01", "size": "8333", "side": "BUY", "hash": "fa9d088432c68960194b28f83fcac51e1077e5f5", "best_bid": "0.99", "best_ask": "0.999"}, {"asset_id": "68036185336858618606129914327232954729196470841777365764843049597359907094650", "price": "0.99", "size": "8333", "side": "SELL", "hash": "24fdbf93eee82fb130a97c491ba90a1281ab58d2", "best_bid": "0.001", "best_ask": "0.01"}], "timestamp": "1769384492553", "event_type": "price_change"}}
{"_local_timestamp": "2026-01-25T23:41:32.850546+00:00", "data": {"market": "0x4d351854a5011cdb0c141ef8d87a8321213d1e0a3b258a3745c03d34dd85d7a7", "price_changes": [{"asset_id": "30230407831690929960155342999106742333605054613110743527797581940998715084536", "price": "0.01", "size": "38.46", "side": "BUY", "hash": "fd2b905de6e18b7cee6c6798f31882fc6b18b42d", "best_bid": "0.01", "best_ask": "0.98"}, {"asset_id": "89397257210211231854366309279840798542964120041524548078365395989129276413393", "price": "0.99", "size": "38.46", "side": "SELL", "hash": "76f502c6038418a97d220d2ec7fe732703d8f601", "best_bid": "0.02", "best_ask": "0.99"}], "timestamp": "1769384492782", "event_type": "price_change"}}
{"_local_timestamp": "2026-01-25T23:41:34.141487+00:00", "data": {"market": "0xe4088389ccc112ce566307b0535326b545db27823876138c37abc36aa80f01b6", "price_changes": [{"asset_id": "111535201652442500376681045716896114819862357479074857390925141208753505497603", "price": "0.002", "size": "22.33", "side": "BUY", "hash": "e947780d174c9708c72bf98b764592bf606af4be", "best_bid": "0.99", "best_ask": "0.999"}, {"asset_id": "68036185336858618606129914327232954729196470841777365764843049597359907094650", "price": "0.998", "size": "22.33", "side": "SELL", "hash": "d7f5dafce53cf86fbbeecb70c8baa29c5f8af83c", "best_bid": "0.001", "best_ask": "0.01"}], "timestamp": "1769384494049", "event_type": "price_change"}}
{"_local_timestamp": "2026-01-25T23:41:34.670808+00:00", "data": {"market": "0xe4088389ccc112ce566307b0535326b545db27823876138c37abc36aa80f01b6", "price_changes": [{"asset_id": "111535201652442500376681045716896114819862357479074857390925141208753505497603", "price": "0.002", "size": "30.13", "side": "BUY", "hash": "d9b0a5afe8b6a875600e063a0c8ecbaae9cf9a51", "best_bid": "0.99", "best_ask": "0.999"}, {"asset_id": "68036185336858618606129914327232954729196470841777365764843049597359907094650", "price": "0.998", "size": "30.13", "side": "SELL", "hash": "48f91b7291dba02533fc794458baf0e24a0f7778", "best_bid": "0.001", "best_ask": "0.01"}], "timestamp": "1769384494590", "event_type": "price_change"}}
{"_local_timestamp": "2026-01-25T23:41:35.152866+00:00", "data": {"market": "0x45c806ae01123f47e7f24fea279b8658a4112cdaa11eee2f9924838a8948bc98", "price_changes": [{"asset_id": "56387091315659274606744882547186473603552761496368462985420229575757384495074", "price": "0.001", "size": "1063", "side": "BUY", "hash": "29f8d2ece1f149d2384995d0b6051de836dc3da7", "best_bid": "0.104", "best_ask": "0.999"}, {"asset_id": "32694948455525029678981577699677214621056167573486416032284086638717669535526", "price": "0.999", "size": "1063", "side": "SELL", "hash": "d99dbae8eb166d76fa6006517ad7f978e624e97b", "best_bid": "0.001", "best_ask": "0.896"}], "timestamp": "1769384495084", "event_type": "price_change"}}
{"_local_timestamp": "2026-01-25T23:41:35.623898+00:00", "data": {"market": "0x45c806ae01123f47e7f24fea279b8658a4112cdaa11eee2f9924838a8948bc98", "price_changes": [{"asset_id": "56387091315659274606744882547186473603552761496368462985420229575757384495074", "price": "0.002", "size": "493.77", "side": "BUY", "hash": "1b09fa4bd3f453b451d79331bb2dbdabdfe948e3", "best_bid": "0.104", "best_ask": "0.999"}, {"asset_id": "32694948455525029678981577699677214621056167573486416032284086638717669535526", "price": "0.998", "size": "493.77", "side": "SELL", "hash": "2bf11837b056743258ea436217c2b9ca2eddc56f", "best_bid": "0.001", "best_ask": "0.896"}], "timestamp": "1769384495549", "event_type": "price_change"}}
{"_local_timestamp": "2026-01-25T23:41:35.626126+00:00", "data": {"market": "0x45c806ae01123f47e7f24fea279b8658a4112cdaa11eee2f9924838a8948bc98", "price_changes": [{"asset_id": "56387091315659274606744882547186473603552761496368462985420229575757384495074", "price": "0.001", "size": "1075.44", "side": "BUY", "hash": "59bc0b31a0c59188f2b4a971691c02a093c588fe", "best_bid": "0.104", "best_ask": "0.999"}, {"asset_id": "32694948455525029678981577699677214621056167573486416032284086638717669535526", "price": "0.999", "size": "1075.44", "side": "SELL", "hash": "d7c9fd00c2889e2e10c36283aa58995edd234268", "best_bid": "0.001", "best_ask": "0.896"}], "timestamp": "1769384495550", "event_type": "price_change"}}
{"_local_timestamp": "2026-01-25T23:41:35.948174+00:00", "data": {"market": "0x45c806ae01123f47e7f24fea279b8658a4112cdaa11eee2f9924838a8948bc98", "price_changes": [{"asset_id": "32694948455525029678981577699677214621056167573486416032284086638717669535526", "price": "0.897", "size": "0", "side": "SELL", "hash": "3946dd3bf092077985fd651556a6944058ad6a53", "best_bid": "0.001", "best_ask": "0.896"}, {"asset_id": "56387091315659274606744882547186473603552761496368462985420229575757384495074", "price": "0.103", "size": "0", "side": "BUY", "hash": "bc4be72b6cd6eaa2a330335e2b86ea2403f38f86", "best_bid": "0.104", "best_ask": "0.999"}], "timestamp": "1769384495872", "event_type": "price_change"}}
{"_local_timestamp": "2026-01-25T23:41:35.950745+00:00", "data": {"market": "0xe4088389ccc112ce566307b0535326b545db27823876138c37abc36aa80f01b6", "price_changes": [{"asset_id": "111535201652442500376681045716896114819862357479074857390925141208753505497603", "price": "0.002", "size": "22.33", "side": "BUY", "hash": "5cc67b46f85c709cf4b298b8c96da55e2095aa5f", "best_bid": "0.99", "best_ask": "0.999"}, {"asset_id": "68036185336858618606129914327232954729196470841777365764843049597359907094650", "price": "0.998", "size": "22.33", "side": "SELL", "hash": "bf650c748dd2acb4ca50a16121dda1d78a9bff92", "best_bid": "0.001", "best_ask": "0.01"}], "timestamp": "1769384495872", "event_type": "price_change"}}
{"_local_timestamp": "2026-01-25T23:41:36.357836+00:00", "data": {"market": "0xe4088389ccc112ce566307b0535326b545db27823876138c37abc36aa80f01b6", "price_changes": [{"asset_id": "111535201652442500376681045716896114819862357479074857390925141208753505497603", "price": "0.002", "size": "30.13", "side": "BUY", "hash": "f6bdf05d86ff3e5103f4b37d56e6e0c0fa36c6ac", "best_bid": "0.99", "best_ask": "0.999"}, {"asset_id": "68036185336858618606129914327232954729196470841777365764843049597359907094650", "price": "0.998", "size": "30.13", "side": "SELL", "hash": "0b717ac322b679bae2df4442d01e13762c8c038a", "best_bid": "0.001", "best_ask": "0.01"}], "timestamp": "1769384496287", "event_type": "price_change"}}
{"_local_timestamp": "2026-01-25T23:41:36.358756+00:00", "data": {"market": "0x45c806ae01123f47e7f24fea279b8658a4112cdaa11eee2f9924838a8948bc98", "price_changes": [{"asset_id": "32694948455525029678981577699677214621056167573486416032284086638717669535526", "price": "0.895", "size": "8.2", "side": "SELL", "hash": "03075b3812bc77c3dc2fb49faa3898f0eb56f26e", "best_bid": "0.001", "best_ask": "0.895"}, {"asset_id": "56387091315659274606744882547186473603552761496368462985420229575757384495074", "price": "0.105", "size": "8.2", "side": "BUY", "hash": "48ffd64872d893714048fb1b15335b1e2d99b1ea", "best_bid": "0.105", "best_ask": "0.999"}], "timestamp": "1769384496287", "event_type": "price_change"}}
{"_local_timestamp": "2026-01-25T23:41:36.668435+00:00", "data": {"market": "0xe40aca7194b6ed6c98d54fcd1338d41c30d5265d68d7468fdb3afcca62e8d6c3", "price_changes": [{"asset_id": "21516192838799393436877283935602059956906510510942747966420810813105259210660", "price": "0.01", "size": "9.85", "side": "BUY", "hash": "346dac9bb902aea41a57aa1608bbacd233f70261", "best_bid": "0.01", "best_ask": "0.98"}, {"asset_id": "82306081970048077348294633861982165617205411236349395805461913184457941025697", "price": "0.99", "size": "9.85", "side": "SELL", "hash": "aa3c21879a6b345a714dd33f1023fefe842e735b", "best_bid": "0.02", "best_ask": "0.99"}], "timestamp": "1769384496601", "event_type": "price_change"}}
{"_local_timestamp": "2026-01-25T23:41:36.998021+00:00", "data": {"market": "0xe40aca7194b6ed6c98d54fcd1338d41c30d5265d68d7468fdb3afcca62e8d6c3", "price_changes": [{"asset_id": "21516192838799393436877283935602059956906510510942747966420810813105259210660", "price": "0.01", "size": "38.46", "side": "BUY", "hash": "59ebc58d42aa4962dadab241c13c2767d5e4b002", "best_bid": "0.01", "best_ask": "0.98"}, {"asset_id": "82306081970048077348294633861982165617205411236349395805461913184457941025697", "price": "0.99", "size": "38.46", "side": "SELL", "hash": "bae4e5133d2e187c579e9134218fd60ff3332ed7", "best_bid": "0.02", "best_ask": "0.99"}], "timestamp": "1769384496926", "event_type": "price_change"}}
{"_local_timestamp": "2026-01-25T23:41:37.078249+00:00", "data": {"market": "0x1172a9379540e31c463e178f08c87f67eb0011ba0deadcd67f78f0028d27f41a", "price_changes": [{"asset_id": "108433110821297511084165806800149498872896490798393090117171505493034184915983", "price": "0.14", "size": "500", "side": "BUY", "hash": "5b5cf9f4da55e76370a84358d2bb312ea4a0d38d", "best_bid": "0.95", "best_ask": "0.989"}, {"asset_id": "96693063570682405603148415870765547887123700438364743392828151015298561276130", "price": "0.86", "size": "500", "side": "SELL", "hash": "33e8370ba6f8dc9d5b5cbf2d7590046c627ae004", "best_bid": "0.011", "best_ask": "0.05"}], "timestamp": "1769384497000", "event_type": "price_change"}}
{"_local_timestamp": "2026-01-25T23:41:37.083057+00:00", "data": {"market": "0xe4088389ccc112ce566307b0535326b545db27823876138c37abc36aa80f01b6", "price_changes": [{"asset_id": "111535201652442500376681045716896114819862357479074857390925141208753505497603", "price": "0.01", "size": "0", "side": "BUY", "hash": "ebdf02a6a9b32970dd147a85751ed518a4bfcc4c", "best_bid": "0.99", "best_ask": "0.999"}, {"asset_id": "68036185336858618606129914327232954729196470841777365764843049597359907094650", "price": "0.99", "size": "0", "side": "SELL", "hash": "55d755f5184e530e03250fc9a17051d650f0de2e", "best_bid": "0.001", "best_ask": "0.01"}], "timestamp": "1769384497001", "event_type": "price_change"}}
{"_local_timestamp": "2026-01-25T23:41:37.120636+00:00", "data": {"market": "0x45c806ae01123f47e7f24fea279b8658a4112cdaa11eee2f9924838a8948bc98", "price_changes": [{"asset_id": "32694948455525029678981577699677214621056167573486416032284086638717669535526", "price": "0.896", "size": "0", "side": "SELL", "hash": "799dbe962b0abdf34642358da2451235a57da04e", "best_bid": "0.001", "best_ask": "0.895"}, {"asset_id": "56387091315659274606744882547186473603552761496368462985420229575757384495074", "price": "0.104", "size": "0", "side": "BUY", "hash": "30b3710713c480b99c1b33eaa10bde4eb4d4be0c", "best_bid": "0.105", "best_ask": "0.999"}], "timestamp": "1769384497004", "event_type": "price_change"}}
{"_local_timestamp": "2026-01-25T23:41:37.167586+00:00", "data": {"market": "0x45c806ae01123f47e7f24fea279b8658a4112cdaa11eee2f9924838a8948bc98", "price_changes": [{"asset_id": "32694948455525029678981577699677214621056167573486416032284086638717669535526", "price": "0.894", "size": "5.47", "side": "SELL", "hash": "a63780d944885b610872cf33085d9aa77c2cbf53", "best_bid": "0.001", "best_ask": "0.894"}, {"asset_id": "56387091315659274606744882547186473603552761496368462985420229575757384495074", "price": "0.106", "size": "5.47", "side": "BUY", "hash": "ab49cb72e10ec4c1cbbe11ca4bd94da39aa2c589", "best_bid": "0.106", "best_ask": "0.999"}], "timestamp": "1769384497094", "event_type": "price_change"}}
{"_local_timestamp": "2026-01-25T23:41:38.010615+00:00", "data": {"market": "0xe4088389ccc112ce566307b0535326b545db27823876138c37abc36aa80f01b6", "price_changes": [{"asset_id": "111535201652442500376681045716896114819862357479074857390925141208753505497603", "price": "0.01", "size": "8333", "side": "BUY", "hash": "8c0738eed35ede595510c8a2b65b88d51ebaeed4", "best_bid": "0.99", "best_ask": "0.999"}, {"asset_id": "68036185336858618606129914327232954729196470841777365764843049597359907094650", "price": "0.99", "size": "8333", "side": "SELL", "hash": "45ad4c36465ea2ca39e6c6bf63ac843b49a4e222", "best_bid": "0.001", "best_ask": "0.01"}], "timestamp": "1769384497930", "event_type": "price_change"}}
{"_local_timestamp": "2026-01-25T23:41:38.014234+00:00", "data": {"market": "0x1172a9379540e31c463e178f08c87f67eb0011ba0deadcd67f78f0028d27f41a", "price_changes": [{"asset_id": "108433110821297511084165806800149498872896490798393090117171505493034184915983", "price": "0.14", "size": "1209", "side": "BUY", "hash": "a69735b0710c1fce3ba981da877ef57de744427b", "best_bid": "0.95", "best_ask": "0.989"}, {"asset_id": "96693063570682405603148415870765547887123700438364743392828151015298561276130", "price": "0.86", "size": "1209", "side": "SELL", "hash": "082d12db37de1dbcd97df29f87c4d2c3bae8bdb0", "best_bid": "0.011", "best_ask": "0.05"}], "timestamp": "1769384497930", "event_type": "price_change"}}
{"_local_timestamp": "2026-01-25T23:41:38.157512+00:00", "data": {"market": "0xe4088389ccc112ce566307b0535326b545db27823876138c37abc36aa80f01b6", "price_changes": [{"asset_id": "111535201652442500376681045716896114819862357479074857390925141208753505497603", "price": "0.011", "size": "14.96", "side": "BUY", "hash": "6d3683ba61d56427201e18917a7381f8eac3634f", "best_bid": "0.99", "best_ask": "0.999"}, {"asset_id": "68036185336858618606129914327232954729196470841777365764843049597359907094650", "price": "0.989", "size": "14.96", "side": "SELL", "hash": "574626f2ac9d6cb82f181885ddd65a4c82af2e0c", "best_bid": "0.001", "best_ask": "0.01"}], "timestamp": "1769384498076", "event_type": "price_change"}}
{"_local_timestamp": "2026-01-25T23:41:38.331928+00:00", "data": {"market": "0xe4088389ccc112ce566307b0535326b545db27823876138c37abc36aa80f01b6", "price_changes": [{"asset_id": "111535201652442500376681045716896114819862357479074857390925141208753505497603", "price": "0.011", "size": "37.4", "side": "BUY", "hash": "aa6a0f350094b3b01dc8bbd4661fd5328ddb37e6", "best_bid": "0.99", "best_ask": "0.999"}, {"asset_id": "68036185336858618606129914327232954729196470841777365764843049597359907094650", "price": "0.989", "size": "37.4", "side": "SELL", "hash": "0cb8ff46a4ccaf2753565075c9034538e50651d9", "best_bid": "0.001", "best_ask": "0.01"}], "timestamp": "1769384498254", "event_type": "price_change"}}
{"_local_timestamp": "2026-01-25T23:41:38.338103+00:00", "data": {"market": "0xe4088389ccc112ce566307b0535326b545db27823876138c37abc36aa80f01b6", "price_changes": [{"asset_id": "111535201652442500376681045716896114819862357479074857390925141208753505497603", "price": "0.011", "size": "59.84", "side": "BUY", "hash": "32af114ff2f479b5d40d0bd86c382d46af7498e0", "best_bid": "0.99", "best_ask": "0.999"}, {"asset_id": "68036185336858618606129914327232954729196470841777365764843049597359907094650", "price": "0.989", "size": "59.84", "side": "SELL", "hash": "44b422c7703af64c69733f51816c8ba58a663202", "best_bid": "0.001", "best_ask": "0.01"}], "timestamp": "1769384498255", "event_type": "price_change"}}
{"_local_timestamp": "2026-01-25T23:41:38.659489+00:00", "data": {"market": "0x1172a9379540e31c463e178f08c87f67eb0011ba0deadcd67f78f0028d27f41a", "price_changes": [{"asset_id": "96693063570682405603148415870765547887123700438364743392828151015298561276130", "price": "0.14", "size": "199.66", "side": "SELL", "hash": "e54a0025d5863c8710e94e1a791eb210180e3790", "best_bid": "0.011", "best_ask": "0.05"}, {"asset_id": "108433110821297511084165806800149498872896490798393090117171505493034184915983", "price": "0.86", "size": "199.66", "side": "BUY", "hash": "bc93178f886ae43f6fbad6328a4b7382b4fa92cd", "best_bid": "0.95", "best_ask": "0.989"}], "timestamp": "1769384498586", "event_type": "price_change"}}
{"_local_timestamp": "2026-01-25T23:41:39.002027+00:00", "data": {"market": "0x45c806ae01123f47e7f24fea279b8658a4112cdaa11eee2f9924838a8948bc98", "price_changes": [{"asset_id": "32694948455525029678981577699677214621056167573486416032284086638717669535526", "price": "0.895", "size": "0", "side": "SELL", "hash": "9fef96e093578d72a73ddb467a4d8b12f5bf2b2f", "best_bid": "0.001", "best_ask": "0.894"}, {"asset_id": "56387091315659274606744882547186473603552761496368462985420229575757384495074", "price": "0.105", "size": "0", "side": "BUY", "hash": "30457798b5218ff94426587f94cbaa5ff10bf2e7", "best_bid": "0.106", "best_ask": "0.999"}], "timestamp": "1769384498927", "event_type": "price_change"}}
{"_local_timestamp": "2026-01-25T23:41:39.174348+00:00", "data": {"market": "0x45c806ae01123f47e7f24fea279b8658a4112cdaa11eee2f9924838a8948bc98", "price_changes": [{"asset_id": "32694948455525029678981577699677214621056167573486416032284086638717669535526", "price": "0.893", "size": "8.2", "side": "SELL", "hash": "12bbd63e3d1a3c6cc54632a826ef925fe8a0dc85", "best_bid": "0.001", "best_ask": "0.893"}, {"asset_id": "56387091315659274606744882547186473603552761496368462985420229575757384495074", "price": "0.107", "size": "8.2", "side": "BUY", "hash": "2d1960223e6443f655cee285f2660558e490b217", "best_bid": "0.107", "best_ask": "0.999"}], "timestamp": "1769384499099", "event_type": "price_change"}}
{"_local_timestamp": "2026-01-25T23:41:39.309646+00:00", "data": {"market": "0x1172a9379540e31c463e178f08c87f67eb0011ba0deadcd67f78f0028d27f41a", "price_changes": [{"asset_id": "108433110821297511084165806800149498872896490798393090117171505493034184915983", "price": "0.81", "size": "0", "side": "BUY", "hash": "ca54a1a2c6721417306802572335dbd957a0745d", "best_bid": "0.95", "best_ask": "0.989"}, {"asset_id": "96693063570682405603148415870765547887123700438364743392828151015298561276130", "price": "0.19", "size": "0", "side": "SELL", "hash": "dcf95939d620fc509ac9eba336a58cb104d1b5bd", "best_bid": "0.011", "best_ask": "0.05"}], "timestamp": "1769384499234", "event_type": "price_change"}}
{"_local_timestamp": "2026-01-25T23:41:39.424595+00:00", "data": {"market": "0x1172a9379540e31c463e178f08c87f67eb0011ba0deadcd67f78f0028d27f41a", "price_changes": [{"asset_id": "108433110821297511084165806800149498872896490798393090117171505493034184915983", "price": "0.83", "size": "43.72", "side": "BUY", "hash": "d4a2af59783bacf475b372080abede5c1ec8657f", "best_bid": "0.95", "best_ask": "0.989"}, {"asset_id": "96693063570682405603148415870765547887123700438364743392828151015298561276130", "price": "0.17", "size": "43.72", "side": "SELL", "hash": "d292eb41face9f6fa03d0e2e4de6c88cb64cd72b", "best_bid": "0.011", "best_ask": "0.05"}], "timestamp": "1769384499341", "event_type": "price_change"}}
{"_local_timestamp": "2026-01-25T23:41:39.610056+00:00", "data": {"market": "0x1172a9379540e31c463e178f08c87f67eb0011ba0deadcd67f78f0028d27f41a", "price_changes": [{"asset_id": "108433110821297511084165806800149498872896490798393090117171505493034184915983", "price": "0.86", "size": "299.66", "side": "BUY", "hash": "bef3aa68e465bc62b5cd8e27a0797163744b6573", "best_bid": "0.95", "best_ask": "0.989"}, {"asset_id": "96693063570682405603148415870765547887123700438364743392828151015298561276130", "price": "0.14", "size": "299.66", "side": "SELL", "hash": "53aa1c7fa8201d316bcd7b113b92fc81e4e8a1cc", "best_bid": "0.011", "best_ask": "0.05"}], "timestamp": "1769384499521", "event_type": "price_change"}}
{"_local_timestamp": "2026-01-25T23:41:39.611567+00:00", "data": {"market": "0x1172a9379540e31c463e178f08c87f67eb0011ba0deadcd67f78f0028d27f41a", "price_changes": [{"asset_id": "108433110821297511084165806800149498872896490798393090117171505493034184915983", "price": "0.86", "size": "199.66", "side": "BUY", "hash": "d3dab702cb38d5c212c27544a416e146376d9cff", "best_bid": "0.95", "best_ask": "0.989"}, {"asset_id": "96693063570682405603148415870765547887123700438364743392828151015298561276130", "price": "0.14", "size": "199.66", "side": "SELL", "hash": "a494ff7418dbe7175b7f55e94f5d56fd4cddf631", "best_bid": "0.011", "best_ask": "0.05"}], "timestamp": "1769384499523", "event_type": "price_change"}}
{"_local_timestamp": "2026-01-25T23:41:39.624984+00:00", "data": {"market": "0x1172a9379540e31c463e178f08c87f67eb0011ba0deadcd67f78f0028d27f41a", "price_changes": [{"asset_id": "108433110821297511084165806800149498872896490798393090117171505493034184915983", "price": "0.83", "size": "23.72", "side": "BUY", "hash": "14ff1745a1ddcd137b794130fdf387774942842c", "best_bid": "0.95", "best_ask": "0.989"}, {"asset_id": "96693063570682405603148415870765547887123700438364743392828151015298561276130", "price": "0.17", "size": "23.72", "side": "SELL", "hash": "1b5fdd6f49e0b2e4ec96a872b17aa55ae06e084e", "best_bid": "0.011", "best_ask": "0.05"}], "timestamp": "1769384499532", "event_type": "price_change"}}
{"_local_timestamp": "2026-01-25T23:41:39.730321+00:00", "data": {"market": "0x1172a9379540e31c463e178f08c87f67eb0011ba0deadcd67f78f0028d27f41a", "price_changes": [{"asset_id": "108433110821297511084165806800149498872896490798393090117171505493034184915983", "price": "0.9", "size": "20", "side": "BUY", "hash": "048a7a6d66ca50d6036c6ffc19307bf7fefcc5d0", "best_bid": "0.95", "best_ask": "0.989"}, {"asset_id": "96693063570682405603148415870765547887123700438364743392828151015298561276130", "price": "0.1", "size": "20", "side": "SELL", "hash": "36219516fdf337e48d6b072b768d0be3e660b9df", "best_bid": "0.011", "best_ask": "0.05"}], "timestamp": "1769384499657", "event_type": "price_change"}}
{"_local_timestamp": "2026-01-25T23:41:39.745171+00:00", "data": {"market": "0x1172a9379540e31c463e178f08c87f67eb0011ba0deadcd67f78f0028d27f41a", "price_changes": [{"asset_id": "108433110821297511084165806800149498872896490798393090117171505493034184915983", "price": "0.92", "size": "100", "side": "BUY", "hash": "2efc4cdf02dbc5998e0571e94fd827b3ef577081", "best_bid": "0.95", "best_ask": "0.989"}, {"asset_id": "96693063570682405603148415870765547887123700438364743392828151015298561276130", "price": "0.08", "size": "100", "side": "SELL", "hash": "aefb1716724db66284004c4d391d7596f7182e2d", "best_bid": "0.011", "best_ask": "0.05"}], "timestamp": "1769384499669", "event_type": "price_change"}}
{"_local_timestamp": "2026-01-25T23:41:40.197562+00:00", "data": {"market": "0x45c806ae01123f47e7f24fea279b8658a4112cdaa11eee2f9924838a8948bc98", "price_changes": [{"asset_id": "32694948455525029678981577699677214621056167573486416032284086638717669535526", "price": "0.894", "size": "0", "side": "SELL", "hash": "962ac868019b020e49da58e70d6f5d128c1ef2d8", "best_bid": "0.001", "best_ask": "0.893"}, {"asset_id": "56387091315659274606744882547186473603552761496368462985420229575757384495074", "price": "0.106", "size": "0", "side": "BUY", "hash": "c35bbc362a9117f906d2b2c7096e72d8acbab331", "best_bid": "0.107", "best_ask": "0.999"}], "timestamp": "1769384500121", "event_type": "price_change"}}
{"_local_timestamp": "2026-01-25T23:41:40.282230+00:00", "data": {"market": "0x45c806ae01123f47e7f24fea279b8658a4112cdaa11eee2f9924838a8948bc98", "price_changes": [{"asset_id": "32694948455525029678981577699677214621056167573486416032284086638717669535526", "price": "0.892", "size": "5.47", "side": "SELL", "hash": "39b7a9d5877fc7f4ae83f4aa9d1ec19a0c7afe1f", "best_bid": "0.001", "best_ask": "0.892"}, {"asset_id": "56387091315659274606744882547186473603552761496368462985420229575757384495074", "price": "0.108", "size": "5.47", "side": "BUY", "hash": "ca99eecb5fd92b938987a7e2f7118aad343d6efc", "best_bid": "0.108", "best_ask": "0.999"}], "timestamp": "1769384500188", "event_type": "price_change"}}
{"_local_timestamp": "2026-01-25T23:41:40.826250+00:00", "data": {"market": "0xe4088389ccc112ce566307b0535326b545db27823876138c37abc36aa80f01b6", "price_changes": [{"asset_id": "111535201652442500376681045716896114819862357479074857390925141208753505497603", "price": "0.002", "size": "22.33", "side": "BUY", "hash": "724e6a539504c4dcd91034867565f5cc5d715dfc", "best_bid": "0.99", "best_ask": "0.999"}, {"asset_id": "68036185336858618606129914327232954729196470841777365764843049597359907094650", "price": "0.998", "size": "22.33", "side": "SELL", "hash": "442270c4874788210511dcfb768a75b80d7cdb7e", "best_bid": "0.001", "best_ask": "0.01"}], "timestamp": "1769384500752", "event_type": "price_change"}}
{"_local_timestamp": "2026-01-25T23:41:41.066822+00:00", "data": {"market": "0xe4088389ccc112ce566307b0535326b545db27823876138c37abc36aa80f01b6", "price_changes": [{"asset_id": "111535201652442500376681045716896114819862357479074857390925141208753505497603", "price": "0.002", "size": "30.13", "side": "BUY", "hash": "b8d19846d6fcdfaf68227367bd27f6e9ac1198bc", "best_bid": "0.99", "best_ask": "0.999"}, {"asset_id": "68036185336858618606129914327232954729196470841777365764843049597359907094650", "price": "0.998", "size": "30.13", "side": "SELL", "hash": "ac193bf096c2ff1c9dc0419df1ea84711e2f1ded", "best_bid": "0.001", "best_ask": "0.01"}], "timestamp": "1769384500994", "event_type": "price_change"}}
{"_local_timestamp": "2026-01-25T23:41:41.258532+00:00", "data": {"market": "0x45c806ae01123f47e7f24fea279b8658a4112cdaa11eee2f9924838a8948bc98", "price_changes": [{"asset_id": "32694948455525029678981577699677214621056167573486416032284086638717669535526", "price": "0.893", "size": "0", "side": "SELL", "hash": "ebc56decd5886b6d5c4700be48cd8ef66a047b00", "best_bid": "0.001", "best_ask": "0.892"}, {"asset_id": "56387091315659274606744882547186473603552761496368462985420229575757384495074", "price": "0.107", "size": "0", "side": "BUY", "hash": "91e642b9733440d39d0baa0abadf95738baddc43", "best_bid": "0.108", "best_ask": "0.999"}], "timestamp": "1769384501181", "event_type": "price_change"}}
{"_local_timestamp": "2026-01-25T23:41:41.486617+00:00", "data": {"market": "0x45c806ae01123f47e7f24fea279b8658a4112cdaa11eee2f9924838a8948bc98", "price_changes": [{"asset_id": "32694948455525029678981577699677214621056167573486416032284086638717669535526", "price": "0.891", "size": "8.2", "side": "SELL", "hash": "c5be50c6fcd211f99e1c0c3f5a9426007030a149", "best_bid": "0.001", "best_ask": "0.891"}, {"asset_id": "56387091315659274606744882547186473603552761496368462985420229575757384495074", "price": "0.109", "size": "8.2", "side": "BUY", "hash": "28553b8f77e082d4086c270b8aa48d497082447a", "best_bid": "0.109", "best_ask": "0.999"}], "timestamp": "1769384501407", "event_type": "price_change"}}
{"_local_timestamp": "2026-01-25T23:41:41.503333+00:00", "data": {"market": "0x1172a9379540e31c463e178f08c87f67eb0011ba0deadcd67f78f0028d27f41a", "price_changes": [{"asset_id": "108433110821297511084165806800149498872896490798393090117171505493034184915983", "price": "0.92", "size": "0", "side": "BUY", "hash": "bb044fbb9e1ef4f2d18afd27d96763ee3b8e6d1d", "best_bid": "0.95", "best_ask": "0.989"}, {"asset_id": "96693063570682405603148415870765547887123700438364743392828151015298561276130", "price": "0.08", "size": "0", "side": "SELL", "hash": "cd6e6238340a1a2d9df2788861ff50f847a04048", "best_bid": "0.011", "best_ask": "0.05"}], "timestamp": "1769384501428", "event_type": "price_change"}}
{"_local_timestamp": "2026-01-25T23:41:41.662603+00:00", "data": {"market": "0x45c806ae01123f47e7f24fea279b8658a4112cdaa11eee2f9924838a8948bc98", "price_changes": [{"asset_id": "32694948455525029678981577699677214621056167573486416032284086638717669535526", "price": "0.892", "size": "0", "side": "SELL", "hash": "71f506e8230ead217b86fd8e13a54dd85d598320", "best_bid": "0.001", "best_ask": "0.891"}, {"asset_id": "56387091315659274606744882547186473603552761496368462985420229575757384495074", "price": "0.108", "size": "0", "side": "BUY", "hash": "fdd8320f99db8689d259519a37462be038b62a78", "best_bid": "0.109", "best_ask": "0.999"}], "timestamp": "1769384501590", "event_type": "price_change"}}
{"_local_timestamp": "2026-01-25T23:41:41.729894+00:00", "data": {"market": "0xe4088389ccc112ce566307b0535326b545db27823876138c37abc36aa80f01b6", "price_changes": [{"asset_id": "111535201652442500376681045716896114819862357479074857390925141208753505497603", "price": "0.002", "size": "22.33", "side": "BUY", "hash": "8a3a7a63b3cc9e728f715cf31f00cc059ff3c40a", "best_bid": "0.99", "best_ask": "0.999"}, {"asset_id": "68036185336858618606129914327232954729196470841777365764843049597359907094650", "price": "0.998", "size": "22.33", "side": "SELL", "hash": "089f5c89a8c0d922a0d607c61d2aca3b9bd1893d", "best_bid": "0.001", "best_ask": "0.01"}], "timestamp": "1769384501639", "event_type": "price_change"}}
{"_local_timestamp": "2026-01-25T23:41:41.785715+00:00", "data": {"market": "0x45c806ae01123f47e7f24fea279b8658a4112cdaa11eee2f9924838a8948bc98", "price_changes": [{"asset_id": "32694948455525029678981577699677214621056167573486416032284086638717669535526", "price": "0.89", "size": "5.47", "side": "SELL", "hash": "1d0acc941e68ea4fb51e2add74172f1d3dcaf633", "best_bid": "0.001", "best_ask": "0.89"}, {"asset_id": "56387091315659274606744882547186473603552761496368462985420229575757384495074", "price": "0.11", "size": "5.47", "side": "BUY", "hash": "ea2f32108598f6928e4c7450f94fa8090dbfed40", "best_bid": "0.11", "best_ask": "0.999"}], "timestamp": "1769384501703", "event_type": "price_change"}}
{"_local_timestamp": "2026-01-25T23:41:41.905000+00:00", "data": {"market": "0xe4088389ccc112ce566307b0535326b545db27823876138c37abc36aa80f01b6", "price_changes": [{"asset_id": "111535201652442500376681045716896114819862357479074857390925141208753505497603", "price": "0.002", "size": "30.13", "side": "BUY", "hash": "71552f1d287bd33618e97d3d58fa6fce6058ccb4", "best_bid": "0.99", "best_ask": "0.999"}, {"asset_id": "68036185336858618606129914327232954729196470841777365764843049597359907094650", "price": "0.998", "size": "30.13", "side": "SELL", "hash": "3251be3d8d201f16d5b82ad193fcc29b031a65b2", "best_bid": "0.001", "best_ask": "0.01"}], "timestamp": "1769384501838", "event_type": "price_change"}}
{"_local_timestamp": "2026-01-25T23:41:42.080601+00:00", "data": {"market": "0x1172a9379540e31c463e178f08c87f67eb0011ba0deadcd67f78f0028d27f41a", "price_changes": [{"asset_id": "108433110821297511084165806800149498872896490798393090117171505493034184915983", "price": "0.14", "size": "500", "side": "BUY", "hash": "05f8ab1661ba03b89eeead1176ea743d483d51f3", "best_bid": "0.95", "best_ask": "0.989"}, {"asset_id": "96693063570682405603148415870765547887123700438364743392828151015298561276130", "price": "0.86", "size": "500", "side": "SELL", "hash": "484bb6db510cda2a0040ed4132303755302474d4", "best_bid": "0.011", "best_ask": "0.05"}], "timestamp": "1769384502001", "event_type": "price_change"}}
{"_local_timestamp": "2026-01-25T23:41:42.085298+00:00", "data": {"market": "0xe4088389ccc112ce566307b0535326b545db27823876138c37abc36aa80f01b6", "price_changes": [{"asset_id": "111535201652442500376681045716896114819862357479074857390925141208753505497603", "price": "0.01", "size": "0", "side": "BUY", "hash": "7124158f17d4922ee6bb4c6ef68ff35ac9c666ba", "best_bid": "0.99", "best_ask": "0.999"}, {"asset_id": "68036185336858618606129914327232954729196470841777365764843049597359907094650", "price": "0.99", "size": "0", "side": "SELL", "hash": "c5ef25377edcae7e5f43bfbd6c72d65bad163aaf", "best_bid": "0.001", "best_ask": "0.01"}], "timestamp": "1769384502002", "event_type": "price_change"}}
{"_local_timestamp": "2026-01-25T23:41:43.474821+00:00", "data": {"market": "0xe4088389ccc112ce566307b0535326b545db27823876138c37abc36aa80f01b6", "price_changes": [{"asset_id": "111535201652442500376681045716896114819862357479074857390925141208753505497603", "price": "0.011", "size": "14.96", "side": "BUY", "hash": "4ac2b2451df30df467b387cd20b73607e31c2a29", "best_bid": "0.99", "best_ask": "0.999"}, {"asset_id": "68036185336858618606129914327232954729196470841777365764843049597359907094650", "price": "0.989", "size": "14.96", "side": "SELL", "hash": "19d0f1b167d65c419be947aaa4f07565794b57ec", "best_bid": "0.001", "best_ask": "0.01"}], "timestamp": "1769384503387", "event_type": "price_change"}}
{"_local_timestamp": "2026-01-25T23:41:43.551354+00:00", "data": {"market": "0x1172a9379540e31c463e178f08c87f67eb0011ba0deadcd67f78f0028d27f41a", "price_changes": [{"asset_id": "108433110821297511084165806800149498872896490798393090117171505493034184915983", "price": "0.14", "size": "1209", "side": "BUY", "hash": "74b7ddeefc91e854bd25730bafba07d791cf2b0f", "best_bid": "0.95", "best_ask": "0.989"}, {"asset_id": "96693063570682405603148415870765547887123700438364743392828151015298561276130", "price": "0.86", "size": "1209", "side": "SELL", "hash": "163b35f8a65911c4c167270d04f8ce4606217f11", "best_bid": "0.011", "best_ask": "0.05"}], "timestamp": "1769384503474", "event_type": "price_change"}}
{"_local_timestamp": "2026-01-25T23:41:43.691319+00:00", "data": {"market": "0xe4088389ccc112ce566307b0535326b545db27823876138c37abc36aa80f01b6", "price_changes": [{"asset_id": "111535201652442500376681045716896114819862357479074857390925141208753505497603", "price": "0.002", "size": "153.54", "side": "BUY", "hash": "1199e49b7a75fa04cd71cc1d61d3a81afbc05607", "best_bid": "0.99", "best_ask": "0.999"}, {"asset_id": "68036185336858618606129914327232954729196470841777365764843049597359907094650", "price": "0.998", "size": "153.54", "side": "SELL", "hash": "73f05805cd932f819efc6cad9a78b8a9c8d584c9", "best_bid": "0.001", "best_ask": "0.01"}], "timestamp": "1769384503617", "event_type": "price_change"}}
{"_local_timestamp": "2026-01-25T23:41:43.692426+00:00", "data": {"market": "0xe4088389ccc112ce566307b0535326b545db27823876138c37abc36aa80f01b6", "price_changes": [{"asset_id": "111535201652442500376681045716896114819862357479074857390925141208753505497603", "price": "0.002", "size": "276.95", "side": "BUY", "hash": "b0ec2e5f107ad863c9f6306e0e9772438f775ab5", "best_bid": "0.99", "best_ask": "0.999"}, {"asset_id": "68036185336858618606129914327232954729196470841777365764843049597359907094650", "price": "0.998", "size": "276.95", "side": "SELL", "hash": "48bf2ddc63d6a6db2f76a29f3af9e289a52a0a1a", "best_bid": "0.001", "best_ask": "0.01"}], "timestamp": "1769384503617", "event_type": "price_change"}}
{"_local_timestamp": "2026-01-25T23:41:43.722684+00:00", "data": {"market": "0xe4088389ccc112ce566307b0535326b545db27823876138c37abc36aa80f01b6", "price_changes": [{"asset_id": "111535201652442500376681045716896114819862357479074857390925141208753505497603", "price": "0.01", "size": "8333", "side": "BUY", "hash": "93c9a788c5959fc87d3559580356a9dcede2b5e3", "best_bid": "0.99", "best_ask": "0.999"}, {"asset_id": "68036185336858618606129914327232954729196470841777365764843049597359907094650", "price": "0.99", "size": "8333", "side": "SELL", "hash": "9a3f4045bbcbacb4e16ebaf84f16c0e97af45c8b", "best_bid": "0.001", "best_ask": "0.01"}], "timestamp": "1769384503650", "event_type": "price_change"}}
{"_local_timestamp": "2026-01-25T23:41:43.889991+00:00", "data": {"market": "0x45c806ae01123f47e7f24fea279b8658a4112cdaa11eee2f9924838a8948bc98", "price_changes": [{"asset_id": "32694948455525029678981577699677214621056167573486416032284086638717669535526", "price": "0.891", "size": "0", "side": "SELL", "hash": "785976562c2de3c18fe9a880fe728befe39586e9", "best_bid": "0.001", "best_ask": "0.89"}, {"asset_id": "56387091315659274606744882547186473603552761496368462985420229575757384495074", "price": "0.109", "size": "0", "side": "BUY", "hash": "c6b054a997b6c7b0fabbd974652e913e88fc4a33", "best_bid": "0.11", "best_ask": "0.999"}], "timestamp": "1769384503815", "event_type": "price_change"}}
{"_local_timestamp": "2026-01-25T23:41:44.126423+00:00", "data": {"market": "0x45c806ae01123f47e7f24fea279b8658a4112cdaa11eee2f9924838a8948bc98", "price_changes": [{"asset_id": "32694948455525029678981577699677214621056167573486416032284086638717669535526", "price": "0.889", "size": "8.2", "side": "SELL", "hash": "b3120439858b009e04127dc22d4fbc327ed1cfbb", "best_bid": "0.001", "best_ask": "0.889"}, {"asset_id": "56387091315659274606744882547186473603552761496368462985420229575757384495074", "price": "0.111", "size": "8.2", "side": "BUY", "hash": "e971a690d229d9af960a3daa0635c07a6a134d31", "best_bid": "0.111", "best_ask": "0.999"}], "timestamp": "1769384504058", "event_type": "price_change"}}
{"_local_timestamp": "2026-01-25T23:41:44.310560+00:00", "data": {"market": "0x02d056b4ecb79134657b5437bcdd964a7b4008def9f7623e8e1c3a2652996390", "price_changes": [{"asset_id": "75572739037384917026708802532724608493252666334200100326455332920422495907885", "price": "0.01", "size": "21.43", "side": "BUY", "hash": "4cddb11fc5762d2f9e7fbc62346d90c29a0d7d5e", "best_bid": "0.03", "best_ask": "0.98"}, {"asset_id": "75662091824125558301238389247455078817972039140363353111649504086477915930016", "price": "0.99", "size": "21.43", "side": "SELL", "hash": "3068e9a9176d3a647d3e4c437ddc351212850b70", "best_bid": "0.02", "best_ask": "0.97"}], "timestamp": "1769384504239", "event_type": "price_change"}}
{"_local_timestamp": "2026-01-25T23:41:44.580504+00:00", "data": {"market": "0x02d056b4ecb79134657b5437bcdd964a7b4008def9f7623e8e1c3a2652996390", "price_changes": [{"asset_id": "75572739037384917026708802532724608493252666334200100326455332920422495907885", "price": "0.01", "size": "79.48", "side": "BUY", "hash": "39f242f68164726ffeb03685847b6f930929d211", "best_bid": "0.03", "best_ask": "0.98"}, {"asset_id": "75662091824125558301238389247455078817972039140363353111649504086477915930016", "price": "0.99", "size": "79.48", "side": "SELL", "hash": "9270a853733870f08ebd3473d302efbdb29eb536", "best_bid": "0.02", "best_ask": "0.97"}], "timestamp": "1769384504513", "event_type": "price_change"}}
{"_local_timestamp": "2026-01-25T23:41:44.716235+00:00", "data": {"market": "0x45c806ae01123f47e7f24fea279b8658a4112cdaa11eee2f9924838a8948bc98", "price_changes": [{"asset_id": "32694948455525029678981577699677214621056167573486416032284086638717669535526", "price": "0.89", "size": "0", "side": "SELL", "hash": "1c7bbb187e2fb72d874265e709ea54a84c6f6f53", "best_bid": "0.001", "best_ask": "0.889"}, {"asset_id": "56387091315659274606744882547186473603552761496368462985420229575757384495074", "price": "0.11", "size": "0", "side": "BUY", "hash": "6bb8409e075d57013c46e8b9c77cd76f6b2f83ad", "best_bid": "0.111", "best_ask": "0.999"}], "timestamp": "1769384504640", "event_type": "price_change"}}
{"_local_timestamp": "2026-01-25T23:41:44.835541+00:00", "data": {"market": "0x45c806ae01123f47e7f24fea279b8658a4112cdaa11eee2f9924838a8948bc98", "price_changes": [{"asset_id": "32694948455525029678981577699677214621056167573486416032284086638717669535526", "price": "0.888", "size": "5.47", "side": "SELL", "hash": "ce329ca22b66697c925d6b1b3569237bd077c1e9", "best_bid": "0.001", "best_ask": "0.888"}, {"asset_id": "56387091315659274606744882547186473603552761496368462985420229575757384495074", "price": "0.112", "size": "5.47", "side": "BUY", "hash": "b695956097009338ebd76dfcc856811a04b0041c", "best_bid": "0.112", "best_ask": "0.999"}], "timestamp": "1769384504760", "event_type": "price_change"}}
{"_local_timestamp": "2026-01-25T23:41:46.510693+00:00", "data": {"market": "0x1172a9379540e31c463e178f08c87f67eb0011ba0deadcd67f78f0028d27f41a", "price_changes": [{"asset_id": "108433110821297511084165806800149498872896490798393090117171505493034184915983", "price": "0.901", "size": "30", "side": "BUY", "hash": "0b8e91bd329f65cb85e1ddc89437a5e0778e8925", "best_bid": "0.95", "best_ask": "0.989"}, {"asset_id": "96693063570682405603148415870765547887123700438364743392828151015298561276130", "price": "0.099", "size": "30", "side": "SELL", "hash": "888c8980b152ab16ba7fc06ecc2cdc62a620d533", "best_bid": "0.011", "best_ask": "0.05"}], "timestamp": "1769384506437", "event_type": "price_change"}}
{"_local_timestamp": "2026-01-25T23:41:46.535919+00:00", "data": {"market": "0x1172a9379540e31c463e178f08c87f67eb0011ba0deadcd67f78f0028d27f41a", "price_changes": [{"asset_id": "108433110821297511084165806800149498872896490798393090117171505493034184915983", "price": "0.902", "size": "30", "side": "BUY", "hash": "2225645ef7e1ed683a2129b895727b7e3f745e34", "best_bid": "0.95", "best_ask": "0.989"}, {"asset_id": "96693063570682405603148415870765547887123700438364743392828151015298561276130", "price": "0.098", "size": "30", "side": "SELL", "hash": "4d202a3dc9a4a548d8ca8c41b5abb8290cdadd30", "best_bid": "0.011", "best_ask": "0.05"}], "timestamp": "1769384506462", "event_type": "price_change"}}
{"_local_timestamp": "2026-01-25T23:41:46.552754+00:00", "data": {"market": "0x1172a9379540e31c463e178f08c87f67eb0011ba0deadcd67f78f0028d27f41a", "price_changes": [{"asset_id": "108433110821297511084165806800149498872896490798393090117171505493034184915983", "price": "0.903", "size": "30", "side": "BUY", "hash": "0d2f7048a3183eb855fe41f32934c741d98dbe20", "best_bid": "0.95", "best_ask": "0.989"}, {"asset_id": "96693063570682405603148415870765547887123700438364743392828151015298561276130", "price": "0.097", "size": "30", "side": "SELL", "hash": "81f4d9d310b0b9ec6e409c9f9522f3b62bc22d04", "best_bid": "0.011", "best_ask": "0.05"}], "timestamp": "1769384506485", "event_type": "price_change"}}
{"_local_timestamp": "2026-01-25T23:41:46.559520+00:00", "data": {"market": "0x1172a9379540e31c463e178f08c87f67eb0011ba0deadcd67f78f0028d27f41a", "price_changes": [{"asset_id": "108433110821297511084165806800149498872896490798393090117171505493034184915983", "price": "0.901", "size": "0", "side": "BUY", "hash": "40ce1b4f2cc5364c9f3f69a6d3b0fc1e355b2a6d", "best_bid": "0.95", "best_ask": "0.989"}, {"asset_id": "96693063570682405603148415870765547887123700438364743392828151015298561276130", "price": "0.099", "size": "0", "side": "SELL", "hash": "28a0f297249cb3d89d0f18fb5bdde7381c6cb44c", "best_bid": "0.011", "best_ask": "0.05"}], "timestamp": "1769384506489", "event_type": "price_change"}}
{"_local_timestamp": "2026-01-25T23:41:46.583095+00:00", "data": {"market": "0x1172a9379540e31c463e178f08c87f67eb0011ba0deadcd67f78f0028d27f41a", "price_changes": [{"asset_id": "108433110821297511084165806800149498872896490798393090117171505493034184915983", "price": "0.902", "size": "0", "side": "BUY", "hash": "c9ffcb56cefc1e879874fcbc502a40f1e39f05f5", "best_bid": "0.95", "best_ask": "0.989"}, {"asset_id": "96693063570682405603148415870765547887123700438364743392828151015298561276130", "price": "0.098", "size": "0", "side": "SELL", "hash": "94b5cf76ec28002072bfefa8397d1bc846acb0c2", "best_bid": "0.011", "best_ask": "0.05"}], "timestamp": "1769384506509", "event_type": "price_change"}}
{"_local_timestamp": "2026-01-25T23:41:46.583945+00:00", "data": {"market": "0x1172a9379540e31c463e178f08c87f67eb0011ba0deadcd67f78f0028d27f41a", "price_changes": [{"asset_id": "108433110821297511084165806800149498872896490798393090117171505493034184915983", "price": "0.904", "size": "30", "side": "BUY", "hash": "61c45232c5e98394d157de4a0f3f48ce69a20477", "best_bid": "0.95", "best_ask": "0.989"}, {"asset_id": "96693063570682405603148415870765547887123700438364743392828151015298561276130", "price": "0.096", "size": "30", "side": "SELL", "hash": "67a0dc6420f8501cb58ee2b34e6d212d93961605", "best_bid": "0.011", "best_ask": "0.05"}], "timestamp": "1769384506510", "event_type": "price_change"}}
{"_local_timestamp": "2026-01-25T23:41:46.614622+00:00", "data": {"market": "0x1172a9379540e31c463e178f08c87f67eb0011ba0deadcd67f78f0028d27f41a", "price_changes": [{"asset_id": "108433110821297511084165806800149498872896490798393090117171505493034184915983", "price": "0.905", "size": "30", "side": "BUY", "hash": "3153184471e6db9793c1ba961947408867324fb4", "best_bid": "0.95", "best_ask": "0.989"}, {"asset_id": "96693063570682405603148415870765547887123700438364743392828151015298561276130", "price": "0.095", "size": "30", "side": "SELL", "hash": "adbfd7be4c8e119b983d11d6777a71f36deebab5", "best_bid": "0.011", "best_ask": "0.05"}], "timestamp": "1769384506541", "event_type": "price_change"}}
{"_local_timestamp": "2026-01-25T23:41:46.615627+00:00", "data": {"market": "0x1172a9379540e31c463e178f08c87f67eb0011ba0deadcd67f78f0028d27f41a", "price_changes": [{"asset_id": "108433110821297511084165806800149498872896490798393090117171505493034184915983", "price": "0.903", "size": "0", "side": "BUY", "hash": "14d41deaaf8551e088dfba346913ccc6de201b0f", "best_bid": "0.95", "best_ask": "0.989"}, {"asset_id": "96693063570682405603148415870765547887123700438364743392828151015298561276130", "price": "0.097", "size": "0", "side": "SELL", "hash": "318d28a0108313a077a6797080363c7e5da5f5e6", "best_bid": "0.011", "best_ask": "0.05"}], "timestamp": "1769384506546", "event_type": "price_change"}}
{"_local_timestamp": "2026-01-25T23:41:46.630920+00:00", "data": {"market": "0x1172a9379540e31c463e178f08c87f67eb0011ba0deadcd67f78f0028d27f41a", "price_changes": [{"asset_id": "108433110821297511084165806800149498872896490798393090117171505493034184915983", "price": "0.904", "size": "0", "side": "BUY", "hash": "4498db0a8459c9c4c91faa9f30157a321a6390b7", "best_bid": "0.95", "best_ask": "0.989"}, {"asset_id": "96693063570682405603148415870765547887123700438364743392828151015298561276130", "price": "0.096", "size": "0", "side": "SELL", "hash": "1bb9474d308b5350488b3477dfaf233daf61c42a", "best_bid": "0.011", "best_ask": "0.05"}], "timestamp": "1769384506561", "event_type": "price_change"}}
{"_local_timestamp": "2026-01-25T23:41:46.643561+00:00", "data": {"market": "0x1172a9379540e31c463e178f08c87f67eb0011ba0deadcd67f78f0028d27f41a", "price_changes": [{"asset_id": "108433110821297511084165806800149498872896490798393090117171505493034184915983", "price": "0.906", "size": "30", "side": "BUY", "hash": "dc974695769ff3f3fef7372d89ae1c442de7a94d", "best_bid": "0.95", "best_ask": "0.989"}, {"asset_id": "96693063570682405603148415870765547887123700438364743392828151015298561276130", "price": "0.094", "size": "30", "side": "SELL", "hash": "8507fe8acf7775dfd8dab80cc82dbe578202bf76", "best_bid": "0.011", "best_ask": "0.05"}], "timestamp": "1769384506567", "event_type": "price_change"}}
{"_local_timestamp": "2026-01-25T23:41:46.658797+00:00", "data": {"market": "0x1172a9379540e31c463e178f08c87f67eb0011ba0deadcd67f78f0028d27f41a", "price_changes": [{"asset_id": "108433110821297511084165806800149498872896490798393090117171505493034184915983", "price": "0.907", "size": "30", "side": "BUY", "hash": "e78952a7d108797a7b38b545b6819c19bebf5bd5", "best_bid": "0.95", "best_ask": "0.989"}, {"asset_id": "96693063570682405603148415870765547887123700438364743392828151015298561276130", "price": "0.093", "size": "30", "side": "SELL", "hash": "3093210d76774791f75740e57e3d0deeba6a010a", "best_bid": "0.011", "best_ask": "0.05"}], "timestamp": "1769384506591", "event_type": "price_change"}}
{"_local_timestamp": "2026-01-25T23:41:46.666586+00:00", "data": {"market": "0x1172a9379540e31c463e178f08c87f67eb0011ba0deadcd67f78f0028d27f41a", "price_changes": [{"asset_id": "108433110821297511084165806800149498872896490798393090117171505493034184915983", "price": "0.905", "size": "0", "side": "BUY", "hash": "f2e83d2a1fda78739020ad0171252f68eb5a7cea", "best_bid": "0.95", "best_ask": "0.989"}, {"asset_id": "96693063570682405603148415870765547887123700438364743392828151015298561276130", "price": "0.095", "size": "0", "side": "SELL", "hash": "22064d68c1c7730c0dafeda0b47dbad38bf7ea86", "best_bid": "0.011", "best_ask": "0.05"}], "timestamp": "1769384506597", "event_type": "price_change"}}
{"_local_timestamp": "2026-01-25T23:41:46.682678+00:00", "data": {"market": "0x1172a9379540e31c463e178f08c87f67eb0011ba0deadcd67f78f0028d27f41a", "price_changes": [{"asset_id": "108433110821297511084165806800149498872896490798393090117171505493034184915983", "price": "0.906", "size": "0", "side": "BUY", "hash": "e0e0a350b5305c688722d42ce06accad46b0586f", "best_bid": "0.95", "best_ask": "0.989"}, {"asset_id": "96693063570682405603148415870765547887123700438364743392828151015298561276130", "price": "0.094", "size": "0", "side": "SELL", "hash": "3bce9a27c08e51baab50ecb164310a9a618612d0", "best_bid": "0.011", "best_ask": "0.05"}], "timestamp": "1769384506613", "event_type": "price_change"}}
{"_local_timestamp": "2026-01-25T23:41:46.690824+00:00", "data": {"market": "0x1172a9379540e31c463e178f08c87f67eb0011ba0deadcd67f78f0028d27f41a", "price_changes": [{"asset_id": "108433110821297511084165806800149498872896490798393090117171505493034184915983", "price": "0.908", "size": "30", "side": "BUY", "hash": "54f248eff312125b70bf20bb879e236b21126cd8", "best_bid": "0.95", "best_ask": "0.989"}, {"asset_id": "96693063570682405603148415870765547887123700438364743392828151015298561276130", "price": "0.092", "size": "30", "side": "SELL", "hash": "7ae2308523865a18fac0b8d9c50e4849e6e330dd", "best_bid": "0.011", "best_ask": "0.05"}], "timestamp": "1769384506617", "event_type": "price_change"}}
{"_local_timestamp": "2026-01-25T23:41:46.714239+00:00", "data": {"market": "0x1172a9379540e31c463e178f08c87f67eb0011ba0deadcd67f78f0028d27f41a", "price_changes": [{"asset_id": "108433110821297511084165806800149498872896490798393090117171505493034184915983", "price": "0.909", "size": "30", "side": "BUY", "hash": "c3681b42e5910ec25edf7f42265ddf53a4725824", "best_bid": "0.95", "best_ask": "0.989"}, {"asset_id": "96693063570682405603148415870765547887123700438364743392828151015298561276130", "price": "0.091", "size": "30", "side": "SELL", "hash": "9308f7be6c0f27dfdc946f6b6fbb928034d27c92", "best_bid": "0.011", "best_ask": "0.05"}], "timestamp": "1769384506647", "event_type": "price_change"}}
{"_local_timestamp": "2026-01-25T23:41:46.718585+00:00", "data": {"market": "0x1172a9379540e31c463e178f08c87f67eb0011ba0deadcd67f78f0028d27f41a", "price_changes": [{"asset_id": "108433110821297511084165806800149498872896490798393090117171505493034184915983", "price": "0.907", "size": "0", "side": "BUY", "hash": "f74c1c6852bd6c4161b746bbc08d7d6c7b286f4f", "best_bid": "0.95", "best_ask": "0.989"}, {"asset_id": "96693063570682405603148415870765547887123700438364743392828151015298561276130", "price": "0.093", "size": "0", "side": "SELL", "hash": "28c5f11a9b42be135bdb449ee6b30bc4bb583ddd", "best_bid": "0.011", "best_ask": "0.05"}], "timestamp": "1769384506647", "event_type": "price_change"}}
{"_local_timestamp": "2026-01-25T23:41:46.746637+00:00", "data": {"market": "0x1172a9379540e31c463e178f08c87f67eb0011ba0deadcd67f78f0028d27f41a", "price_changes": [{"asset_id": "108433110821297511084165806800149498872896490798393090117171505493034184915983", "price": "0.908", "size": "0", "side": "BUY", "hash": "ccdb0b31aeb828b4d8935691e869d6310ec74e6c", "best_bid": "0.95", "best_ask": "0.989"}, {"asset_id": "96693063570682405603148415870765547887123700438364743392828151015298561276130", "price": "0.092", "size": "0", "side": "SELL", "hash": "14499e6125094f18c8d306cba6385b2a4e09808e", "best_bid": "0.011", "best_ask": "0.05"}], "timestamp": "1769384506670", "event_type": "price_change"}}
{"_local_timestamp": "2026-01-25T23:41:46.747717+00:00", "data": {"market": "0x1172a9379540e31c463e178f08c87f67eb0011ba0deadcd67f78f0028d27f41a", "price_changes": [{"asset_id": "108433110821297511084165806800149498872896490798393090117171505493034184915983", "price": "0.91", "size": "30", "side": "BUY", "hash": "9d30de4853d50f0f6fc38f0721339084cc661097", "best_bid": "0.95", "best_ask": "0.989"}, {"asset_id": "96693063570682405603148415870765547887123700438364743392828151015298561276130", "price": "0.09", "size": "30", "side": "SELL", "hash": "b94754e830b55dc64720177eb6e46813ee96d645", "best_bid": "0.011", "best_ask": "0.05"}], "timestamp": "1769384506679", "event_type": "price_change"}}
{"_local_timestamp": "2026-01-25T23:41:46.778445+00:00", "data": {"market": "0x1172a9379540e31c463e178f08c87f67eb0011ba0deadcd67f78f0028d27f41a", "price_changes": [{"asset_id": "108433110821297511084165806800149498872896490798393090117171505493034184915983", "price": "0.911", "size": "30", "side": "BUY", "hash": "68f9b0f4503a029635b9d2941108271a46635fa4", "best_bid": "0.95", "best_ask": "0.989"}, {"asset_id": "96693063570682405603148415870765547887123700438364743392828151015298561276130", "price": "0.089", "size": "30", "side": "SELL", "hash": "44d0067781cb02353be6df0e362b55ab3a2fce41", "best_bid": "0.011", "best_ask": "0.05"}], "timestamp": "1769384506703", "event_type": "price_change"}}
{"_local_timestamp": "2026-01-25T23:41:46.779431+00:00", "data": {"market": "0x1172a9379540e31c463e178f08c87f67eb0011ba0deadcd67f78f0028d27f41a", "price_changes": [{"asset_id": "108433110821297511084165806800149498872896490798393090117171505493034184915983", "price": "0.909", "size": "0", "side": "BUY", "hash": "76e873d5b54578ede8ddfd851d6141cc479f8b3a", "best_bid": "0.95", "best_ask": "0.989"}, {"asset_id": "96693063570682405603148415870765547887123700438364743392828151015298561276130", "price": "0.091", "size": "0", "side": "SELL", "hash": "b022b9f873c430fa2c3f909c3917c2cf6d8c2865", "best_bid": "0.011", "best_ask": "0.05"}], "timestamp": "1769384506708", "event_type": "price_change"}}
{"_local_timestamp": "2026-01-25T23:41:46.818475+00:00", "data": {"market": "0x1172a9379540e31c463e178f08c87f67eb0011ba0deadcd67f78f0028d27f41a", "price_changes": [{"asset_id": "108433110821297511084165806800149498872896490798393090117171505493034184915983", "price": "0.912", "size": "30", "side": "BUY", "hash": "070aa1b9779e10597f24afcd3328c9627d244a0a", "best_bid": "0.95", "best_ask": "0.989"}, {"asset_id": "96693063570682405603148415870765547887123700438364743392828151015298561276130", "price": "0.088", "size": "30", "side": "SELL", "hash": "c8649ce22b240f796313554a26fe25e224eb8da3", "best_bid": "0.011", "best_ask": "0.05"}], "timestamp": "1769384506746", "event_type": "price_change"}}
{"_local_timestamp": "2026-01-25T23:41:46.819436+00:00", "data": {"market": "0x1172a9379540e31c463e178f08c87f67eb0011ba0deadcd67f78f0028d27f41a", "price_changes": [{"asset_id": "108433110821297511084165806800149498872896490798393090117171505493034184915983", "price": "0.91", "size": "0", "side": "BUY", "hash": "63a3cba96ddc7b9d49083d5900ec88a0af8641c6", "best_bid": "0.95", "best_ask": "0.989"}, {"asset_id": "96693063570682405603148415870765547887123700438364743392828151015298561276130", "price": "0.09", "size": "0", "side": "SELL", "hash": "c55fab773893ab746953a110393f10188e0bb423", "best_bid": "0.011", "best_ask": "0.05"}], "timestamp": "1769384506748", "event_type": "price_change"}}
{"_local_timestamp": "2026-01-25T23:41:46.834442+00:00", "data": {"market": "0x1172a9379540e31c463e178f08c87f67eb0011ba0deadcd67f78f0028d27f41a", "price_changes": [{"asset_id": "108433110821297511084165806800149498872896490798393090117171505493034184915983", "price": "0.911", "size": "0", "side": "BUY", "hash": "09325962defbd988cce9ec7bbade07896b126093", "best_bid": "0.95", "best_ask": "0.989"}, {"asset_id": "96693063570682405603148415870765547887123700438364743392828151015298561276130", "price": "0.089", "size": "0", "side": "SELL", "hash": "616d1b20bade06d0e8fb1607d7d0a8938287ddd8", "best_bid": "0.011", "best_ask": "0.05"}], "timestamp": "1769384506767", "event_type": "price_change"}}
{"_local_timestamp": "2026-01-25T23:41:46.842887+00:00", "data": {"market": "0x1172a9379540e31c463e178f08c87f67eb0011ba0deadcd67f78f0028d27f41a", "price_changes": [{"asset_id": "108433110821297511084165806800149498872896490798393090117171505493034184915983", "price": "0.913", "size": "30", "side": "BUY", "hash": "e4412b1f542ff27dc5200d175d3356752f88d3d2", "best_bid": "0.95", "best_ask": "0.989"}, {"asset_id": "96693063570682405603148415870765547887123700438364743392828151015298561276130", "price": "0.087", "size": "30", "side": "SELL", "hash": "560fb2f164488a5091ba247119cdb66fe0d8d355", "best_bid": "0.011", "best_ask": "0.05"}], "timestamp": "1769384506771", "event_type": "price_change"}}
{"_local_timestamp": "2026-01-25T23:41:46.860774+00:00", "data": {"market": "0x1172a9379540e31c463e178f08c87f67eb0011ba0deadcd67f78f0028d27f41a", "price_changes": [{"asset_id": "108433110821297511084165806800149498872896490798393090117171505493034184915983", "price": "0.914", "size": "30", "side": "BUY", "hash": "332e11a25719d8380730a4db334796fd6feb410a", "best_bid": "0.95", "best_ask": "0.989"}, {"asset_id": "96693063570682405603148415870765547887123700438364743392828151015298561276130", "price": "0.086", "size": "30", "side": "SELL", "hash": "18462b14c9fe548dcd8fdfcdeac365a0d033c54a", "best_bid": "0.011", "best_ask": "0.05"}], "timestamp": "1769384506795", "event_type": "price_change"}}
{"_local_timestamp": "2026-01-25T23:41:46.865307+00:00", "data": {"market": "0x1172a9379540e31c463e178f08c87f67eb0011ba0deadcd67f78f0028d27f41a", "price_changes": [{"asset_id": "108433110821297511084165806800149498872896490798393090117171505493034184915983", "price": "0.912", "size": "0", "side": "BUY", "hash": "c66f4633658d010947428b045d21aa03dc6e7b59", "best_bid": "0.95", "best_ask": "0.989"}, {"asset_id": "96693063570682405603148415870765547887123700438364743392828151015298561276130", "price": "0.088", "size": "0", "side": "SELL", "hash": "02a41e25ac9e7661f02eebc2b6cf333a53adcbf7", "best_bid": "0.011", "best_ask": "0.05"}], "timestamp": "1769384506798", "event_type": "price_change"}}
{"_local_timestamp": "2026-01-25T23:41:46.883271+00:00", "data": {"market": "0x1172a9379540e31c463e178f08c87f67eb0011ba0deadcd67f78f0028d27f41a", "price_changes": [{"asset_id": "108433110821297511084165806800149498872896490798393090117171505493034184915983", "price": "0.913", "size": "0", "side": "BUY", "hash": "fafea775cd351d753500273cc6c7a2a187068b60", "best_bid": "0.95", "best_ask": "0.989"}, {"asset_id": "96693063570682405603148415870765547887123700438364743392828151015298561276130", "price": "0.087", "size": "0", "side": "SELL", "hash": "5cd8b4029e760e74c4ea0849d3702d16b1903043", "best_bid": "0.011", "best_ask": "0.05"}], "timestamp": "1769384506816", "event_type": "price_change"}}
{"_local_timestamp": "2026-01-25T23:41:46.890365+00:00", "data": {"market": "0x1172a9379540e31c463e178f08c87f67eb0011ba0deadcd67f78f0028d27f41a", "price_changes": [{"asset_id": "108433110821297511084165806800149498872896490798393090117171505493034184915983", "price": "0.915", "size": "30", "side": "BUY", "hash": "17b6db461cea23599a219c86a0fb0faa0aea6f9d", "best_bid": "0.95", "best_ask": "0.989"}, {"asset_id": "96693063570682405603148415870765547887123700438364743392828151015298561276130", "price": "0.085", "size": "30", "side": "SELL", "hash": "0ec85f77559dae4bed56a8080d5a162ee0651754", "best_bid": "0.011", "best_ask": "0.05"}], "timestamp": "1769384506820", "event_type": "price_change"}}
{"_local_timestamp": "2026-01-25T23:41:46.922999+00:00", "data": {"market": "0x1172a9379540e31c463e178f08c87f67eb0011ba0deadcd67f78f0028d27f41a", "price_changes": [{"asset_id": "108433110821297511084165806800149498872896490798393090117171505493034184915983", "price": "0.916", "size": "30", "side": "BUY", "hash": "bf30316d5afeb390830a044154997b77fb89d7b0", "best_bid": "0.95", "best_ask": "0.989"}, {"asset_id": "96693063570682405603148415870765547887123700438364743392828151015298561276130", "price": "0.084", "size": "30", "side": "SELL", "hash": "6f7f292192b04e79c3469f105b3d4313f24c7798", "best_bid": "0.011", "best_ask": "0.05"}], "timestamp": "1769384506847", "event_type": "price_change"}}
{"_local_timestamp": "2026-01-25T23:41:46.924068+00:00", "data": {"market": "0x1172a9379540e31c463e178f08c87f67eb0011ba0deadcd67f78f0028d27f41a", "price_changes": [{"asset_id": "108433110821297511084165806800149498872896490798393090117171505493034184915983", "price": "0.914", "size": "0", "side": "BUY", "hash": "36cedf38a78c7134c2f41be81a657c64b532fd73", "best_bid": "0.95", "best_ask": "0.989"}, {"asset_id": "96693063570682405603148415870765547887123700438364743392828151015298561276130", "price": "0.086", "size": "0", "side": "SELL", "hash": "0a372825ab5fddd2891958e0f984a4f36c517b66", "best_bid": "0.011", "best_ask": "0.05"}], "timestamp": "1769384506848", "event_type": "price_change"}}
{"_local_timestamp": "2026-01-25T23:41:46.945974+00:00", "data": {"market": "0x1172a9379540e31c463e178f08c87f67eb0011ba0deadcd67f78f0028d27f41a", "price_changes": [{"asset_id": "108433110821297511084165806800149498872896490798393090117171505493034184915983", "price": "0.917", "size": "30", "side": "BUY", "hash": "048c6809502627b5410c12cabc0fd140c549d9ef", "best_bid": "0.95", "best_ask": "0.989"}, {"asset_id": "96693063570682405603148415870765547887123700438364743392828151015298561276130", "price": "0.083", "size": "30", "side": "SELL", "hash": "b23895adedfb3df72c0e81693b2aeea94e7604d8", "best_bid": "0.011", "best_ask": "0.05"}], "timestamp": "1769384506873", "event_type": "price_change"}}
{"_local_timestamp": "2026-01-25T23:41:46.950483+00:00", "data": {"market": "0x1172a9379540e31c463e178f08c87f67eb0011ba0deadcd67f78f0028d27f41a", "price_changes": [{"asset_id": "108433110821297511084165806800149498872896490798393090117171505493034184915983", "price": "0.915", "size": "0", "side": "BUY", "hash": "7be82882c035c9cfdeee97604a65a3b0eab93195", "best_bid": "0.95", "best_ask": "0.989"}, {"asset_id": "96693063570682405603148415870765547887123700438364743392828151015298561276130", "price": "0.085", "size": "0", "side": "SELL", "hash": "5e5914f3dc597676aa6bdcd6950657a6f418f2d7", "best_bid": "0.011", "best_ask": "0.05"}], "timestamp": "1769384506879", "event_type": "price_change"}}
{"_local_timestamp": "2026-01-25T23:41:46.966013+00:00", "data": {"market": "0x1172a9379540e31c463e178f08c87f67eb0011ba0deadcd67f78f0028d27f41a", "price_changes": [{"asset_id": "108433110821297511084165806800149498872896490798393090117171505493034184915983", "price": "0.918", "size": "30", "side": "BUY", "hash": "bf1be42a6c356572cf37920a7065cd8e756c2502", "best_bid": "0.95", "best_ask": "0.989"}, {"asset_id": "96693063570682405603148415870765547887123700438364743392828151015298561276130", "price": "0.082", "size": "30", "side": "SELL", "hash": "8852202ce4473a4022db8e3f30f2dd523bd629f5", "best_bid": "0.011", "best_ask": "0.05"}], "timestamp": "1769384506899", "event_type": "price_change"}}
{"_local_timestamp": "2026-01-25T23:41:46.967116+00:00", "data": {"market": "0x1172a9379540e31c463e178f08c87f67eb0011ba0deadcd67f78f0028d27f41a", "price_changes": [{"asset_id": "108433110821297511084165806800149498872896490798393090117171505493034184915983", "price": "0.916", "size": "0", "side": "BUY", "hash": "72d0cb78ec8885e18c1915b8df649e90eb6ea695", "best_bid": "0.95", "best_ask": "0.989"}, {"asset_id": "96693063570682405603148415870765547887123700438364743392828151015298561276130", "price": "0.084", "size": "0", "side": "SELL", "hash": "d66f814df18dcceedd09db18b868fab9ac120eaf", "best_bid": "0.011", "best_ask": "0.05"}], "timestamp": "1769384506899", "event_type": "price_change"}}
{"_local_timestamp": "2026-01-25T23:41:46.989348+00:00", "data": {"market": "0x1172a9379540e31c463e178f08c87f67eb0011ba0deadcd67f78f0028d27f41a", "price_changes": [{"asset_id": "108433110821297511084165806800149498872896490798393090117171505493034184915983", "price": "0.919", "size": "30", "side": "BUY", "hash": "82fdd9c0c82be5e5fc0ff4b166e9936f3df3a098", "best_bid": "0.95", "best_ask": "0.989"}, {"asset_id": "96693063570682405603148415870765547887123700438364743392828151015298561276130", "price": "0.081", "size": "30", "side": "SELL", "hash": "ecb7ab3a73cbb24a9fedaba43bccc94c9a93fd4f", "best_bid": "0.011", "best_ask": "0.05"}], "timestamp": "1769384506921", "event_type": "price_change"}}
{"_local_timestamp": "2026-01-25T23:41:47.014303+00:00", "data": {"market": "0x1172a9379540e31c463e178f08c87f67eb0011ba0deadcd67f78f0028d27f41a", "price_changes": [{"asset_id": "108433110821297511084165806800149498872896490798393090117171505493034184915983", "price": "0.917", "size": "0", "side": "BUY", "hash": "35ac4a89d9fcb621af4a20eee8025dd733f82957", "best_bid": "0.95", "best_ask": "0.989"}, {"asset_id": "96693063570682405603148415870765547887123700438364743392828151015298561276130", "price": "0.083", "size": "0", "side": "SELL", "hash": "7ce51b07b818a350c0c190ffd6c2edfcd4e9f319", "best_bid": "0.011", "best_ask": "0.05"}], "timestamp": "1769384506947", "event_type": "price_change"}}
{"_local_timestamp": "2026-01-25T23:41:47.016961+00:00", "data": {"market": "0x1172a9379540e31c463e178f08c87f67eb0011ba0deadcd67f78f0028d27f41a", "price_changes": [{"asset_id": "108433110821297511084165806800149498872896490798393090117171505493034184915983", "price": "0.92", "size": "30", "side": "BUY", "hash": "a6fe3224e7a7d6c801f7571aeeb3fbc826b7699d", "best_bid": "0.95", "best_ask": "0.989"}, {"asset_id": "96693063570682405603148415870765547887123700438364743392828151015298561276130", "price": "0.08", "size": "30", "side": "SELL", "hash": "a7e4b90551170dbdc8af52dc27c322c343dac983", "best_bid": "0.011", "best_ask": "0.05"}], "timestamp": "1769384506948", "event_type": "price_change"}}
{"_local_timestamp": "2026-01-25T23:41:47.017861+00:00", "data": {"market": "0x1172a9379540e31c463e178f08c87f67eb0011ba0deadcd67f78f0028d27f41a", "price_changes": [{"asset_id": "108433110821297511084165806800149498872896490798393090117171505493034184915983", "price": "0.918", "size": "0", "side": "BUY", "hash": "74229505afc3408dc40b82afcbe02bd2527fe931", "best_bid": "0.95", "best_ask": "0.989"}, {"asset_id": "96693063570682405603148415870765547887123700438364743392828151015298561276130", "price": "0.082", "size": "0", "side": "SELL", "hash": "246690fdd738f0ceb4c7130c51fee460e349a9d9", "best_bid": "0.011", "best_ask": "0.05"}], "timestamp": "1769384506950", "event_type": "price_change"}}
