{"_local_timestamp": "2026-01-25T23:34:13.283578+00:00", "data": [{"market": "0x780c042865b2018eeb8ddcdec110c6839c6f27a8062b37dded79501920250afe", "asset_id": "79287164977737814011242460177248792416483317253936439908020481835936787513608", "timestamp": "1769383976056", "hash": "6865c12bee25d613dd3b718380ea98dc2ddcc580", "bids": [{"price": "0.01", "size": "100"}, {"price": "0.02", "size": "33.33"}, {"price": "0.03", "size": "5.47"}], "asks": [{"price": "0.99", "size": "199.99"}, {"price": "0.98", "size": "50"}, {"price": "0.97", "size": "200"}], "event_type": "book", "last_trade_price": "0.820"}, {"market": "0xdbe51bbd40ca77053fd794ac247cd2d07a150921accdd624f9f345fbc63db48b", "asset_id": "87345926905556212316847105466061439969543894768822947485860245095466364170902", "timestamp": "1769383979019", "hash": "483b1286ef337b0ea00642d666818fc641f84a4b", "bids": [{"price": "0.01", "size": "100"}, {"price": "0.33", "size": "165"}], "asks": [{"price": "0.99", "size": "100"}, {"price": "0.73", "size": "234"}], "event_type": "book", "last_trade_price": "0.260"}, {"market": "0xdbe51bbd40ca77053fd794ac247cd2d07a150921accdd624f9f345fbc63db48b", "asset_id": "36448007855605050896824786938032039502111327633212361142790079215548046414522", "timestamp": "1769383979019", "hash": "748fa0390f481516af0acc9eed938a4cc6f2d52e", "bids": [{"price": "0.01", "size": "100"}, {"price": "0.27", "size": "234"}], "asks": [{"price": "0.99", "size": "100"}, {"price": "0.67", "size": "165"}], "event_type": "book", "last_trade_price": "0.260"}, {"market": "0x1feaf4097b273ee90aea00fdc5afa9ec6e14b518caf2ddbc421851bef1bdc168", "asset_id": "18882795016423351779855047017846676160725151167446687947380948164302842014020", "timestamp": "1769383985914", "hash": "0f80362ce720eb4dff86a5c266f2a1c780aaf565", "bids": [{"price": "0.01", "size": "150"}, {"price": "0.02", "size": "166"}, {"price": "0.03", "size": "5.47"}], "asks": [{"price": "0.99", "size": "200"}, {"price": "0.98", "size": "5.47"}, {"price": "0.56", "size": "430"}], "event_type": "book", "last_trade_price": "0.420"}, {"market": "0x780c042865b2018eeb8ddcdec110c6839c6f27a8062b37dded79501920250afe", "asset_id": "96548263188568861225971459083251184634804319351377359745128053937517313229246", "timestamp": "1769383976056", "hash": "9b80333212f183f4f5742bd864da2554e2e46e4e", "bids": [{"price": "0.01", "size": "199.99"}, {"price": "0.02", "size": "50"}, {"price": "0.03", "size": "200"}], "asks": [{"price": "0.99", "size": "100"}, {"price": "0.98", "size": "33.33"}, {"price": "0.97", "size": "5.47"}], "event_type": "book", "last_trade_price": "0.820"}, {"market": "0x1feaf4097b273ee90aea00fdc5afa9ec6e14b518caf2ddbc421851bef1bdc168", "asset_id": "22033330904498269999207988435951609926608006932357150385292796096528006231715", "timestamp": "1769383985914", "hash": "947aeca49c76d883cfc01fdbd5ec77f0c15fdfd5", "bids": [{"price": "0.01", "size": "200"}, {"price": "0.02", "size": "5.47"}, {"price": "0.44", "size": "430"}], "asks": [{"price": "0.99", "size": "150"}, {"price": "0.98", "size": "166"}, {"price": "0.97", "size": "5.47"}], "event_type": "book", "last_trade_price": "0.420"}]}
{"_local_timestamp": "2026-01-25T23:34:55.125702+00:00", "data": {"market": "0x1feaf4097b273ee90aea00fdc5afa9ec6e14b518caf2ddbc421851bef1bdc168", "price_changes": [{"asset_id": "22033330904498269999207988435951609926608006932357150385292796096528006231715", "price": "0.44", "size": "222", "side": "BUY", "hash": "851176ee76be34f91930239944daa178388af9dd", "best_bid": "0.44", "best_ask": "0.97"}, {"asset_id": "18882795016423351779855047017846676160725151167446687947380948164302842014020", "price": "0.56", "size": "222", "side": "SELL", "hash": "420bef6c76e4d49133165051be253be003372cc9", "best_bid": "0.03", "best_ask": "0.56"}], "timestamp": "1769384095025", "event_type": "price_change"}}
{"_local_timestamp": "2026-01-25T23:34:55.325729+00:00", "data": {"market": "0x1feaf4097b273ee90aea00fdc5afa9ec6e14b518caf2ddbc421851bef1bdc168", "price_changes": [{"asset_id": "22033330904498269999207988435951609926608006932357150385292796096528006231715", "price": "0.43", "size": "189", "side": "BUY", "hash": "cf30160048c9ba0470fb6ea9bab7e52b718c75d2", "best_bid": "0.44", "best_ask": "0.97"}, {"asset_id": "18882795016423351779855047017846676160725151167446687947380948164302842014020", "price": "0.57", "size": "189", "side": "SELL", "hash": "26da492a8a1cc233847cd8a78c56926e1ef077b0", "best_bid": "0.03", "best_ask": "0.56"}], "timestamp": "1769384095226", "event_type": "price_change"}}
{"_local_timestamp": "2026-01-25T23:34:58.194748+00:00", "data": {"market": "0x1feaf4097b273ee90aea00fdc5afa9ec6e14b518caf2ddbc421851bef1bdc168", "price_changes": [{"asset_id": "22033330904498269999207988435951609926608006932357150385292796096528006231715", "price": "0.43", "size": "0", "side": "BUY", "hash": "d3211e51339750c7f6d95cb87a24f27e60f34eee", "best_bid": "0.44", "best_ask": "0.97"}, {"asset_id": "18882795016423351779855047017846676160725151167446687947380948164302842014020", "price": "0.57", "size": "0", "side": "SELL", "hash": "e8b3ca340e8d0004891593a9d5b7a0ae42479bd5", "best_bid": "0.03", "best_ask": "0.56"}], "timestamp": "1769384098117", "event_type": "price_change"}}
{"_local_timestamp": "2026-01-25T23:34:58.213391+00:00", "data": {"market": "0x1feaf4097b273ee90aea00fdc5afa9ec6e14b518caf2ddbc421851bef1bdc168", "price_changes": [{"asset_id": "22033330904498269999207988435951609926608006932357150385292796096528006231715", "price": "0.44", "size": "256", "side": "BUY", "hash": "6500a8bb64807829f08885f180825b00c8c22dbc", "best_bid": "0.44", "best_ask": "0.97"}, {"asset_id": "18882795016423351779855047017846676160725151167446687947380948164302842014020", "price": "0.56", "size": "256", "side": "SELL", "hash": "757f47e74df159e7f43af9281b5ece01c679a49b", "best_bid": "0.03", "best_ask": "0.56"}], "timestamp": "1769384098151", "event_type": "price_change"}}
{"_local_timestamp": "2026-01-25T23:35:26.781939+00:00", "data": {"market": "0x1feaf4097b273ee90aea00fdc5afa9ec6e14b518caf2ddbc421851bef1bdc168", "price_changes": [{"asset_id": "22033330904498269999207988435951609926608006932357150385292796096528006231715", "price": "0.44", "size": "222", "side": "BUY", "hash": "70d0a8352beb0831dd54bf6dcfbc3ae2d9b94412", "best_bid": "0.44", "best_ask": "0.97"}, {"asset_id": "18882795016423351779855047017846676160725151167446687947380948164302842014020", "price": "0.56", "size": "222", "side": "SELL", "hash": "73f29917b8284d2bee64e0d3760a20d2e4b5caa1", "best_bid": "0.03", "best_ask": "0.56"}], "timestamp": "1769384126582", "event_type": "price_change"}}
{"_local_timestamp": "2026-01-25T23:35:26.803332+00:00", "data": {"market": "0x1feaf4097b273ee90aea00fdc5afa9ec6e14b518caf2ddbc421851bef1bdc168", "price_changes": [{"asset_id": "22033330904498269999207988435951609926608006932357150385292796096528006231715", "price": "0.43", "size": "211", "side": "BUY", "hash": "282a09329fd0b3642d8333dbddf0b414dd94cd15", "best_bid": "0.44", "best_ask": "0.97"}, {"asset_id": "18882795016423351779855047017846676160725151167446687947380948164302842014020", "price": "0.57", "size": "211", "side": "SELL", "hash": "06d55b513fea8b29ab73f753ff5ce2bf3eb3b197", "best_bid": "0.03", "best_ask": "0.56"}], "timestamp": "1769384126610", "event_type": "price_change"}}
{"_local_timestamp": "2026-01-25T23:35:44.846901+00:00", "data": {"market": "0x1feaf4097b273ee90aea00fdc5afa9ec6e14b518caf2ddbc421851bef1bdc168", "price_changes": [{"asset_id": "22033330904498269999207988435951609926608006932357150385292796096528006231715", "price": "0.43", "size": "0", "side": "BUY", "hash": "bd616b1711f391e42eff4b56c2eebb551ec24865", "best_bid": "0.44", "best_ask": "0.97"}, {"asset_id": "18882795016423351779855047017846676160725151167446687947380948164302842014020", "price": "0.57", "size": "0", "side": "SELL", "hash": "71818ca8eaf5404a23082bcc8d998838c88edaf0", "best_bid": "0.03", "best_ask": "0.56"}], "timestamp": "1769384144783", "event_type": "price_change"}}
{"_local_timestamp": "2026-01-25T23:35:44.874454+00:00", "data": {"market": "0x1feaf4097b273ee90aea00fdc5afa9ec6e14b518caf2ddbc421851bef1bdc168", "price_changes": [{"asset_id": "22033330904498269999207988435951609926608006932357150385292796096528006231715", "price": "0.42", "size": "228", "side": "BUY", "hash": "8e4035b6a08dc8537bd3931170580109598240d0", "best_bid": "0.44", "best_ask": "0.97"}, {"asset_id": "18882795016423351779855047017846676160725151167446687947380948164302842014020", "price": "0.58", "size": "228", "side": "SELL", "hash": "10214d104150b7e6cc2288c372c011b4abe35d38", "best_bid": "0.03", "best_ask": "0.56"}], "timestamp": "1769384144811", "event_type": "price_change"}}
{"_local_timestamp": "2026-01-25T23:36:10.711705+00:00", "data": {"market": "0xdbe51bbd40ca77053fd794ac247cd2d07a150921accdd624f9f345fbc63db48b", "price_changes": [{"asset_id": "87345926905556212316847105466061439969543894768822947485860245095466364170902", "price": "0.02", "size": "50", "side": "BUY", "hash": "572837e6ef518758dbbe33db5b5069a38c78134b", "best_bid": "0.33", "best_ask": "0.73"}, {"asset_id": "36448007855605050896824786938032039502111327633212361142790079215548046414522", "price": "0.98", "size": "50", "side": "SELL", "hash": "bb08df8beec176d43da25d972fb7ba9040b3c66a", "best_bid": "0.27", "best_ask": "0.67"}], "timestamp": "1769384170646", "event_type": "price_change"}}
{"_local_timestamp": "2026-01-25T23:36:10.712437+00:00", "data": {"market": "0xdbe51bbd40ca77053fd794ac247cd2d07a150921accdd624f9f345fbc63db48b", "price_changes": [{"asset_id": "87345926905556212316847105466061439969543894768822947485860245095466364170902", "price": "0.01", "size": "199.99", "side": "BUY", "hash": "58b523d5010aaf1ceb85821abf48f089d1439063", "best_bid": "0.33", "best_ask": "0.73"}, {"asset_id": "36448007855605050896824786938032039502111327633212361142790079215548046414522", "price": "0.99", "size": "199.99", "side": "SELL", "hash": "859c27683fb5c11a8c4f1bf072d8b81dbdb4d55e", "best_bid": "0.27", "best_ask": "0.67"}], "timestamp": "1769384170648", "event_type": "price_change"}}
{"_local_timestamp": "2026-01-25T23:36:31.110954+00:00", "data": {"market": "0x1feaf4097b273ee90aea00fdc5afa9ec6e14b518caf2ddbc421851bef1bdc168", "price_changes": [{"asset_id": "22033330904498269999207988435951609926608006932357150385292796096528006231715", "price": "0.42", "size": "0", "side": "BUY", "hash": "134cbd0e0bf3cdfd7a67ebe0732084ea24fd5b78", "best_bid": "0.44", "best_ask": "0.97"}, {"asset_id": "18882795016423351779855047017846676160725151167446687947380948164302842014020", "price": "0.58", "size": "0", "side": "SELL", "hash": "ca956dc714d288b54a8db07195fc58576c7d8f6c", "best_bid": "0.03", "best_ask": "0.56"}], "timestamp": "1769384191044", "event_type": "price_change"}}
{"_local_timestamp": "2026-01-25T23:36:31.169211+00:00", "data": {"market": "0x1feaf4097b273ee90aea00fdc5afa9ec6e14b518caf2ddbc421851bef1bdc168", "price_changes": [{"asset_id": "22033330904498269999207988435951609926608006932357150385292796096528006231715", "price": "0.41", "size": "199", "side": "BUY", "hash": "92b38fe8978f316971069f2e3b804618d69d664b", "best_bid": "0.44", "best_ask": "0.97"}, {"asset_id": "18882795016423351779855047017846676160725151167446687947380948164302842014020", "price": "0.59", "size": "199", "side": "SELL", "hash": "1686935042fc8caf01b87990e57a26f5a647c398", "best_bid": "0.03", "best_ask": "0.56"}], "timestamp": "1769384191099", "event_type": "price_change"}}
{"_local_timestamp": "2026-01-25T23:36:32.434985+00:00", "data": {"market": "0x1feaf4097b273ee90aea00fdc5afa9ec6e14b518caf2ddbc421851bef1bdc168", "price_changes": [{"asset_id": "22033330904498269999207988435951609926608006932357150385292796096528006231715", "price": "0.41", "size": "0", "side": "BUY", "hash": "ec3546ce8610d59d3ee9cf38467c638926de9e4a", "best_bid": "0.44", "best_ask": "0.97"}, {"asset_id": "18882795016423351779855047017846676160725151167446687947380948164302842014020", "price": "0.59", "size": "0", "side": "SELL", "hash": "487eb66700fc4bdd422ab9b9bb79d5c538a67f99", "best_bid": "0.03", "best_ask": "0.56"}], "timestamp": "1769384192366", "event_type": "price_change"}}
{"_local_timestamp": "2026-01-25T23:36:32.484209+00:00", "data": {"market": "0x1feaf4097b273ee90aea00fdc5afa9ec6e14b518caf2ddbc421851bef1bdc168", "price_changes": [{"asset_id": "22033330904498269999207988435951609926608006932357150385292796096528006231715", "price": "0.42", "size": "134", "side": "BUY", "hash": "b6a98a26c99632a091a3e78b93a2f895fe22d20e", "best_bid": "0.44", "best_ask": "0.97"}, {"asset_id": "18882795016423351779855047017846676160725151167446687947380948164302842014020", "price": "0.58", "size": "134", "side": "SELL", "hash": "f98bb6cb7e18d7db6cd4fd8a890b6820b4e8ab55", "best_bid": "0.03", "best_ask": "0.56"}], "timestamp": "1769384192417", "event_type": "price_change"}}
{"_local_timestamp": "2026-01-25T23:36:37.482275+00:00", "data": {"market": "0x1feaf4097b273ee90aea00fdc5afa9ec6e14b518caf2ddbc421851bef1bdc168", "price_changes": [{"asset_id": "22033330904498269999207988435951609926608006932357150385292796096528006231715", "price": "0.42", "size": "0", "side": "BUY", "hash": "5c9b3b3b12ac82197376b4a7cc86d22685222b18", "best_bid": "0.44", "best_ask": "0.97"}, {"asset_id": "18882795016423351779855047017846676160725151167446687947380948164302842014020", "price": "0.58", "size": "0", "side": "SELL", "hash": "69eb9a66511914348e3d7e5813f3db4f2b10faf9", "best_bid": "0.03", "best_ask": "0.56"}], "timestamp": "1769384197418", "event_type": "price_change"}}
{"_local_timestamp": "2026-01-25T23:36:37.522106+00:00", "data": {"market": "0x1feaf4097b273ee90aea00fdc5afa9ec6e14b518caf2ddbc421851bef1bdc168", "price_changes": [{"asset_id": "22033330904498269999207988435951609926608006932357150385292796096528006231715", "price": "0.41", "size": "229", "side": "BUY", "hash": "6c02fb05f62e1909240b31948783da0720844304", "best_bid": "0.44", "best_ask": "0.97"}, {"asset_id": "18882795016423351779855047017846676160725151167446687947380948164302842014020", "price": "0.59", "size": "229", "side": "SELL", "hash": "2f55e233e69a62d3e7fbc2024f79ff055f05c0f7", "best_bid": "0.03", "best_ask": "0.56"}], "timestamp": "1769384197448", "event_type": "price_change"}}
{"_local_timestamp": "2026-01-25T23:37:03.596931+00:00", "data": {"market": "0x1feaf4097b273ee90aea00fdc5afa9ec6e14b518caf2ddbc421851bef1bdc168", "price_changes": [{"asset_id": "22033330904498269999207988435951609926608006932357150385292796096528006231715", "price": "0.41", "size": "0", "side": "BUY", "hash": "58de3a8cac263176d4fd8dc6ddc6f95a492c22e0", "best_bid": "0.44", "best_ask": "0.97"}, {"asset_id": "18882795016423351779855047017846676160725151167446687947380948164302842014020", "price": "0.59", "size": "0", "side": "SELL", "hash": "8c8fd269d6709ac5ff88a09afe1c012513712508", "best_bid": "0.03", "best_ask": "0.56"}], "timestamp": "1769384223415", "event_type": "price_change"}}
{"_local_timestamp": "2026-01-25T23:37:04.118450+00:00", "data": {"market": "0xdbe51bbd40ca77053fd794ac247cd2d07a150921accdd624f9f345fbc63db48b", "price_changes": [{"asset_id": "36448007855605050896824786938032039502111327633212361142790079215548046414522", "price": "0.27", "size": "0", "side": "BUY", "hash": "0eb20ffdd7aa70283d6bec8897f637ee859cb3f3", "best_bid": "0.01", "best_ask": "0.67"}, {"asset_id": "87345926905556212316847105466061439969543894768822947485860245095466364170902", "price": "0.73", "size": "0", "side": "SELL", "hash": "f4db533bc591409e320aa4414b25f6b9e10cc342", "best_bid": "0.33", "best_ask": "0.99"}], "timestamp": "1769384223936", "event_type": "price_change"}}
{"_local_timestamp": "2026-01-25T23:37:04.140313+00:00", "data": {"market": "0xdbe51bbd40ca77053fd794ac247cd2d07a150921accdd624f9f345fbc63db48b", "price_changes": [{"asset_id": "87345926905556212316847105466061439969543894768822947485860245095466364170902", "price": "0.33", "size": "0", "side": "BUY", "hash": "e08eba86c543f7711032f556ad4e89c6871b4ccb", "best_bid": "0.02", "best_ask": "0.99"}, {"asset_id": "36448007855605050896824786938032039502111327633212361142790079215548046414522", "price": "0.67", "size": "0", "side": "SELL", "hash": "ada581412e2dd4d982f559081609c4dcc404c68b", "best_bid": "0.01", "best_ask": "0.98"}], "timestamp": "1769384223946", "event_type": "price_change"}}
{"_local_timestamp": "2026-01-25T23:37:06.924058+00:00", "data": {"market": "0xdbe51bbd40ca77053fd794ac247cd2d07a150921accdd624f9f345fbc63db48b", "price_changes": [{"asset_id": "87345926905556212316847105466061439969543894768822947485860245095466364170902", "price": "0.01", "size": "100", "side": "BUY", "hash": "aa8220ee28592234dadaef5bc74e505f6fb4ba4d", "best_bid": "0.01", "best_ask": "0.99"}, {"asset_id": "36448007855605050896824786938032039502111327633212361142790079215548046414522", "price": "0.99", "size": "100", "side": "SELL", "hash": "8b04be4d375503019f57f848e8a1f029b9eebb23", "best_bid": "0.01", "best_ask": "0.99"}], "timestamp": "1769384226710", "event_type": "price_change"}}
{"_local_timestamp": "2026-01-25T23:37:06.924525+00:00", "data": {"market": "0xdbe51bbd40ca77053fd794ac247cd2d07a150921accdd624f9f345fbc63db48b", "price_changes": [{"asset_id": "87345926905556212316847105466061439969543894768822947485860245095466364170902", "price": "0.02", "size": "0", "side": "BUY", "hash": "aa8220ee28592234dadaef5bc74e505f6fb4ba4d", "best_bid": "0.01", "best_ask": "0.99"}, {"asset_id": "36448007855605050896824786938032039502111327633212361142790079215548046414522", "price": "0.98", "size": "0", "side": "SELL", "hash": "8b04be4d375503019f57f848e8a1f029b9eebb23", "best_bid": "0.01", "best_ask": "0.99"}], "timestamp": "1769384226710", "event_type": "price_change"}}
{"_local_timestamp": "2026-01-25T23:37:06.973319+00:00", "data": {"market": "0xdbe51bbd40ca77053fd794ac247cd2d07a150921accdd624f9f345fbc63db48b", "price_changes": [{"asset_id": "36448007855605050896824786938032039502111327633212361142790079215548046414522", "price": "0.02", "size": "5.47", "side": "BUY", "hash": "038f778bca97724e2b4f6ff734ef6325e01f65d7", "best_bid": "0.02", "best_ask": "0.99"}, {"asset_id": "87345926905556212316847105466061439969543894768822947485860245095466364170902", "price": "0.98", "size": "5.47", "side": "SELL", "hash": "1706e4e372cd7a2cf8270b21958c479bed2c685e", "best_bid": "0.01", "best_ask": "0.98"}], "timestamp": "1769384226771", "event_type": "price_change"}}
{"_local_timestamp": "2026-01-25T23:37:38.056288+00:00", "data": {"market": "0x1feaf4097b273ee90aea00fdc5afa9ec6e14b518caf2ddbc421851bef1bdc168", "price_changes": [{"asset_id": "18882795016423351779855047017846676160725151167446687947380948164302842014020", "price": "0.01", "size": "191.9", "side": "BUY", "hash": "5b8d342d6bc666b9b3a26a5e369bfb25b153934c", "best_bid": "0.03", "best_ask": "0.56"}, {"asset_id": "22033330904498269999207988435951609926608006932357150385292796096528006231715", "price": "0.99", "size": "191.9", "side": "SELL", "hash": "86717a867c4750b9002d486dfdab99c393b32191", "best_bid": "0.44", "best_ask": "0.97"}], "timestamp": "1769384257989", "event_type": "price_change"}}
{"_local_timestamp": "2026-01-25T23:37:38.056724+00:00", "data": {"market": "0x1feaf4097b273ee90aea00fdc5afa9ec6e14b518caf2ddbc421851bef1bdc168", "price_changes": [{"asset_id": "18882795016423351779855047017846676160725151167446687947380948164302842014020", "price": "0.03", "size": "31.01", "side": "BUY", "hash": "59d579a350b7a82bbe9b54fd0dee22b63ed355b2", "best_bid": "0.03", "best_ask": "0.56"}, {"asset_id": "22033330904498269999207988435951609926608006932357150385292796096528006231715", "price": "0.97", "size": "31.01", "side": "SELL", "hash": "9933baedae431c15ad2fdd7cbcb4f61f6dd5dfe4", "best_bid": "0.44", "best_ask": "0.97"}], "timestamp": "1769384257991", "event_type": "price_change"}}
{"_local_timestamp": "2026-01-25T23:37:38.057061+00:00", "data": {"market": "0x1feaf4097b273ee90aea00fdc5afa9ec6e14b518caf2ddbc421851bef1bdc168", "price_changes": [{"asset_id": "18882795016423351779855047017846676160725151167446687947380948164302842014020", "price": "0.02", "size": "186.21", "side": "BUY", "hash": "7b6f6935e5493426ea7ed8bc9beaa3318f52b42f", "best_bid": "0.03", "best_ask": "0.56"}, {"asset_id": "22033330904498269999207988435951609926608006932357150385292796096528006231715", "price": "0.98", "size": "186.21", "side": "SELL", "hash": "be6e5968fb6b38f260b98931da7c339cadfb1290", "best_bid": "0.44", "best_ask": "0.97"}], "timestamp": "1769384257993", "event_type": "price_change"}}
{"_local_timestamp": "2026-01-25T23:37:54.591062+00:00", "data": {"market": "0xdbe51bbd40ca77053fd794ac247cd2d07a150921accdd624f9f345fbc63db48b", "price_changes": [{"asset_id": "36448007855605050896824786938032039502111327633212361142790079215548046414522", "price": "0.03", "size": "56", "side": "BUY", "hash": "ceadd55de1dd0798e0aca8b33c6cf89b51bc6099", "best_bid": "0.03", "best_ask": "0.99"}, {"asset_id": "87345926905556212316847105466061439969543894768822947485860245095466364170902", "price": "0.97", "size": "56", "side": "SELL", "hash": "6959cc71eeff20a139d8e5e0bde0be7ce34fca1d", "best_bid": "0.01", "best_ask": "0.97"}], "timestamp": "1769384274464", "event_type": "price_change"}}
{"_local_timestamp": "2026-01-25T23:37:55.859552+00:00", "data": {"market": "0x780c042865b2018eeb8ddcdec110c6839c6f27a8062b37dded79501920250afe", "price_changes": [{"asset_id": "79287164977737814011242460177248792416483317253936439908020481835936787513608", "price": "0.12", "size": "217", "side": "BUY", "hash": "5fd413ff58996bc12bed0655c41ba40ca7278263", "best_bid": "0.12", "best_ask": "0.97"}, {"asset_id": "96548263188568861225971459083251184634804319351377359745128053937517313229246", "price": "0.88", "size": "217", "side": "SELL", "hash": "06d8b139db33f6be3d5d397bb31b9e874cb38372", "best_bid": "0.03", "best_ask": "0.88"}], "timestamp": "1769384275741", "event_type": "price_change"}}
{"_local_timestamp": "2026-01-25T23:37:56.116268+00:00", "data": {"market": "0xdbe51bbd40ca77053fd794ac247cd2d07a150921accdd624f9f345fbc63db48b", "price_changes": [{"asset_id": "87345926905556212316847105466061439969543894768822947485860245095466364170902", "price": "0.06", "size": "36", "side": "BUY", "hash": "2cf2ad722bd00dc9e062310c3b3fd935b70e1388", "best_bid": "0.06", "best_ask": "0.97"}, {"asset_id": "36448007855605050896824786938032039502111327633212361142790079215548046414522", "price": "0.94", "size": "36", "side": "SELL", "hash": "2c33c3fd8d2b525bbd32e96f64a2aed286b9faf4", "best_bid": "0.03", "best_ask": "0.94"}], "timestamp": "1769384275994", "event_type": "price_change"}}
{"_local_timestamp": "2026-01-25T23:37:56.408270+00:00", "data": {"market": "0x1feaf4097b273ee90aea00fdc5afa9ec6e14b518caf2ddbc421851bef1bdc168", "price_changes": [{"asset_id": "22033330904498269999207988435951609926608006932357150385292796096528006231715", "price": "0.39", "size": "176", "side": "BUY", "hash": "4a7d3289b662facc066eab598f14cb8b899329b9", "best_bid": "0.44", "best_ask": "0.97"}, {"asset_id": "18882795016423351779855047017846676160725151167446687947380948164302842014020", "price": "0.61", "size": "176", "side": "SELL", "hash": "528511cd13c72b0e09d316b6e7034f8b2ad7cc8f", "best_bid": "0.03", "best_ask": "0.56"}], "timestamp": "1769384276281", "event_type": "price_change"}}
{"_local_timestamp": "2026-01-25T23:37:56.703439+00:00", "data": {"market": "0x1feaf4097b273ee90aea00fdc5afa9ec6e14b518caf2ddbc421851bef1bdc168", "price_changes": [{"asset_id": "22033330904498269999207988435951609926608006932357150385292796096528006231715", "price": "0.39", "size": "0", "side": "BUY", "hash": "24e9e21ff3b3e273edb9236fe511c8400099113b", "best_bid": "0.44", "best_ask": "0.97"}, {"asset_id": "18882795016423351779855047017846676160725151167446687947380948164302842014020", "price": "0.61", "size": "0", "side": "SELL", "hash": "ce6a593c446bb9afa7ab2b4d2cdcfdd9f87716e5", "best_bid": "0.03", "best_ask": "0.56"}], "timestamp": "1769384276572", "event_type": "price_change"}}
{"_local_timestamp": "2026-01-25T23:37:56.757287+00:00", "data": {"market": "0xdbe51bbd40ca77053fd794ac247cd2d07a150921accdd624f9f345fbc63db48b", "price_changes": [{"asset_id": "87345926905556212316847105466061439969543894768822947485860245095466364170902", "price": "0.06", "size": "0", "side": "BUY", "hash": "b35e073133239f88d15e3c65238a2ff229e0fadc", "best_bid": "0.01", "best_ask": "0.97"}, {"asset_id": "36448007855605050896824786938032039502111327633212361142790079215548046414522", "price": "0.94", "size": "0", "side": "SELL", "hash": "6c4936c222a91525972a36cad694d350bfe1dafc", "best_bid": "0.03", "best_ask": "0.99"}], "timestamp": "1769384276623", "event_type": "price_change"}}
{"_local_timestamp": "2026-01-25T23:37:56.960521+00:00", "data": {"market": "0xdbe51bbd40ca77053fd794ac247cd2d07a150921accdd624f9f345fbc63db48b", "price_changes": [{"asset_id": "36448007855605050896824786938032039502111327633212361142790079215548046414522", "price": "0.02", "size": "0", "side": "BUY", "hash": "51160b5054f7e89f5b5a2392ddb03a87705a3e91", "best_bid": "0.03", "best_ask": "0.99"}, {"asset_id": "87345926905556212316847105466061439969543894768822947485860245095466364170902", "price": "0.98", "size": "0", "side": "SELL", "hash": "bf262748f1f67b15e2dca57d9f8f363bf17f8b69", "best_bid": "0.01", "best_ask": "0.97"}], "timestamp": "1769384276819", "event_type": "price_change"}}
{"_local_timestamp": "2026-01-25T23:37:57.040461+00:00", "data": {"market": "0xdbe51bbd40ca77053fd794ac247cd2d07a150921accdd624f9f345fbc63db48b", "price_changes": [{"asset_id": "36448007855605050896824786938032039502111327633212361142790079215548046414522", "price": "0.04", "size": "5.47", "side": "BUY", "hash": "cc7f463750904967674f5f2e5ec31408347f31f2", "best_bid": "0.04", "best_ask": "0.99"}, {"asset_id": "87345926905556212316847105466061439969543894768822947485860245095466364170902", "price": "0.96", "size": "5.47", "side": "SELL", "hash": "dcc49241d77874d566bcef62205cb89ff7aa511d", "best_bid": "0.01", "best_ask": "0.96"}], "timestamp": "1769384276870", "event_type": "price_change"}}
{"_local_timestamp": "2026-01-25T23:37:58.462556+00:00", "data": {"market": "0xdbe51bbd40ca77053fd794ac247cd2d07a150921accdd624f9f345fbc63db48b", "price_changes": [{"asset_id": "87345926905556212316847105466061439969543894768822947485860245095466364170902", "price": "0.3", "size": "91", "side": "BUY", "hash": "88eb2a1082596c44d76b61056a79f6dcdbedb4a5", "best_bid": "0.3", "best_ask": "0.96"}, {"asset_id": "36448007855605050896824786938032039502111327633212361142790079215548046414522", "price": "0.7", "size": "91", "side": "SELL", "hash": "ebd5e5db2ecd5a875913699ab794cec5a9674b5a", "best_bid": "0.04", "best_ask": "0.7"}], "timestamp": "1769384278344", "event_type": "price_change"}}
{"_local_timestamp": "2026-01-25T23:38:03.761989+00:00", "data": {"market": "0xdbe51bbd40ca77053fd794ac247cd2d07a150921accdd624f9f345fbc63db48b", "price_changes": [{"asset_id": "87345926905556212316847105466061439969543894768822947485860245095466364170902", "price": "0.3", "size": "0", "side": "BUY", "hash": "be505559744b28e2ef6523ff1e8e9687ae8b6dbc", "best_bid": "0.01", "best_ask": "0.96"}, {"asset_id": "36448007855605050896824786938032039502111327633212361142790079215548046414522", "price": "0.7", "size": "0", "side": "SELL", "hash": "d7080e841c4949f0f0607839caf50c2c32bf58be", "best_bid": "0.04", "best_ask": "0.99"}], "timestamp": "1769384283626", "event_type": "price_change"}}
{"_local_timestamp": "2026-01-25T23:38:03.772922+00:00", "data": {"market": "0x780c042865b2018eeb8ddcdec110c6839c6f27a8062b37dded79501920250afe", "price_changes": [{"asset_id": "79287164977737814011242460177248792416483317253936439908020481835936787513608", "price": "0.12", "size": "0", "side": "BUY", "hash": "7ec499ab5c6c101186631d1f41b1459aae3684b6", "best_bid": "0.03", "best_ask": "0.97"}, {"asset_id": "96548263188568861225971459083251184634804319351377359745128053937517313229246", "price": "0.88", "size": "0", "side": "SELL", "hash": "385952b15a4c5673ce75874b5c1f5dbe7f7e786e", "best_bid": "0.03", "best_ask": "0.97"}], "timestamp": "1769384283631", "event_type": "price_change"}}
{"_local_timestamp": "2026-01-25T23:38:03.773402+00:00", "data": {"market": "0x1feaf4097b273ee90aea00fdc5afa9ec6e14b518caf2ddbc421851bef1bdc168", "price_changes": [{"asset_id": "18882795016423351779855047017846676160725151167446687947380948164302842014020", "price": "0.02", "size": "20.21", "side": "BUY", "hash": "2347c1b51fa8fc2d04661329ff49a591a9e51786", "best_bid": "0.03", "best_ask": "0.56"}, {"asset_id": "22033330904498269999207988435951609926608006932357150385292796096528006231715", "price": "0.98", "size": "20.21", "side": "SELL", "hash": "bd84e0bb72e26b20d441b112588a1f21029627c4", "best_bid": "0.44", "best_ask": "0.97"}], "timestamp": "1769384283633", "event_type": "price_change"}}
{"_local_timestamp": "2026-01-25T23:38:03.774419+00:00", "data": {"market": "0x780c042865b2018eeb8ddcdec110c6839c6f27a8062b37dded79501920250afe", "price_changes": [{"asset_id": "96548263188568861225971459083251184634804319351377359745128053937517313229246", "price": "0.03", "size": "0", "side": "BUY", "hash": "8d1ac7d3dfc1a43a1259a0c3bf1193b0134469ff", "best_bid": "0.02", "best_ask": "0.97"}, {"asset_id": "79287164977737814011242460177248792416483317253936439908020481835936787513608", "price": "0.97", "size": "0", "side": "SELL", "hash": "86cf7fc35c5c2ba074e1e68b8900391de889a135", "best_bid": "0.03", "best_ask": "0.98"}], "timestamp": "1769384283635", "event_type": "price_change"}}
{"_local_timestamp": "2026-01-25T23:38:03.798017+00:00", "data": {"market": "0xdbe51bbd40ca77053fd794ac247cd2d07a150921accdd624f9f345fbc63db48b", "price_changes": [{"asset_id": "36448007855605050896824786938032039502111327633212361142790079215548046414522", "price": "0.03", "size": "0", "side": "BUY", "hash": "112820613889c6573b4f4ae36c10b0db66ab92bb", "best_bid": "0.04", "best_ask": "0.99"}, {"asset_id": "87345926905556212316847105466061439969543894768822947485860245095466364170902", "price": "0.97", "size": "0", "side": "SELL", "hash": "7727826b121e546f859a8ebdda5f2f71735df386", "best_bid": "0.01", "best_ask": "0.96"}], "timestamp": "1769384283655", "event_type": "price_change"}}
{"_local_timestamp": "2026-01-25T23:38:03.805375+00:00", "data": {"market": "0x780c042865b2018eeb8ddcdec110c6839c6f27a8062b37dded79501920250afe", "price_changes": [{"asset_id": "79287164977737814011242460177248792416483317253936439908020481835936787513608", "price": "0.12", "size": "171", "side": "BUY", "hash": "48d1dcf11b3f145205eb86e3cc18a5721414cd6a", "best_bid": "0.12", "best_ask": "0.98"}, {"asset_id": "96548263188568861225971459083251184634804319351377359745128053937517313229246", "price": "0.88", "size": "171", "side": "SELL", "hash": "605019dc65946a9350602cd2af3e362b1529573f", "best_bid": "0.02", "best_ask": "0.88"}], "timestamp": "1769384283659", "event_type": "price_change"}}
{"_local_timestamp": "2026-01-25T23:38:03.967282+00:00", "data": {"market": "0x780c042865b2018eeb8ddcdec110c6839c6f27a8062b37dded79501920250afe", "price_changes": [{"asset_id": "79287164977737814011242460177248792416483317253936439908020481835936787513608", "price": "0.12", "size": "0", "side": "BUY", "hash": "691d4e1154e97dd263045930248c59fa23eb42c7", "best_bid": "0.03", "best_ask": "0.98"}, {"asset_id": "96548263188568861225971459083251184634804319351377359745128053937517313229246", "price": "0.88", "size": "0", "side": "SELL", "hash": "b30742781a12df522deb0ce190c412cf555b43ae", "best_bid": "0.02", "best_ask": "0.97"}], "timestamp": "1769384283817", "event_type": "price_change"}}
{"_local_timestamp": "2026-01-25T23:38:04.895342+00:00", "data": {"market": "0x780c042865b2018eeb8ddcdec110c6839c6f27a8062b37dded79501920250afe", "price_changes": [{"asset_id": "79287164977737814011242460177248792416483317253936439908020481835936787513608", "price": "0.22", "size": "105", "side": "BUY", "hash": "2bc587ba8bfaf61aa36115400c38c57361594e0b", "best_bid": "0.22", "best_ask": "0.98"}, {"asset_id": "96548263188568861225971459083251184634804319351377359745128053937517313229246", "price": "0.78", "size": "105", "side": "SELL", "hash": "85bd4dac7f534ad4a73fdc91c0063bc7daeb5bc1", "best_bid": "0.02", "best_ask": "0.78"}], "timestamp": "1769384284738", "event_type": "price_change"}}
{"_local_timestamp": "2026-01-25T23:38:05.182619+00:00", "data": {"market": "0x780c042865b2018eeb8ddcdec110c6839c6f27a8062b37dded79501920250afe", "price_changes": [{"asset_id": "79287164977737814011242460177248792416483317253936439908020481835936787513608", "price": "0.11", "size": "26", "side": "BUY", "hash": "210c32dbe2a44c413f9e42cf4bc365efd876889a", "best_bid": "0.22", "best_ask": "0.98"}, {"asset_id": "96548263188568861225971459083251184634804319351377359745128053937517313229246", "price": "0.89", "size": "26", "side": "SELL", "hash": "027538a9e0cee497feeed0f37ca8ce3f573d4b64", "best_bid": "0.02", "best_ask": "0.78"}], "timestamp": "1769384285021", "event_type": "price_change"}}
{"_local_timestamp": "2026-01-25T23:38:05.269203+00:00", "data": {"market": "0x780c042865b2018eeb8ddcdec110c6839c6f27a8062b37dded79501920250afe", "price_changes": [{"asset_id": "79287164977737814011242460177248792416483317253936439908020481835936787513608", "price": "0.11", "size": "0", "side": "BUY", "hash": "4be5d71aa1716b47e5e30928f6dad146e497be82", "best_bid": "0.22", "best_ask": "0.98"}, {"asset_id": "96548263188568861225971459083251184634804319351377359745128053937517313229246", "price": "0.89", "size": "0", "side": "SELL", "hash": "61427b2455a5e9fd8b94a2f30258d18c1653d583", "best_bid": "0.02", "best_ask": "0.78"}], "timestamp": "1769384285124", "event_type": "price_change"}}
{"_local_timestamp": "2026-01-25T23:38:07.119311+00:00", "data": {"market": "0xdbe51bbd40ca77053fd794ac247cd2d07a150921accdd624f9f345fbc63db48b", "price_changes": [{"asset_id": "36448007855605050896824786938032039502111327633212361142790079215548046414522", "price": "0.04", "size": "0", "side": "BUY", "hash": "a91565ef9c600f5c021f5d3139e1055cf74192de", "best_bid": "0.01", "best_ask": "0.99"}, {"asset_id": "87345926905556212316847105466061439969543894768822947485860245095466364170902", "price": "0.96", "size": "0", "side": "SELL", "hash": "ffbadba36052fb53e71f7c4d5ce764ee5751ac6b", "best_bid": "0.01", "best_ask": "0.99"}], "timestamp": "1769384286978", "event_type": "price_change"}}
{"_local_timestamp": "2026-01-25T23:38:07.135906+00:00", "data": {"market": "0x780c042865b2018eeb8ddcdec110c6839c6f27a8062b37dded79501920250afe", "price_changes": [{"asset_id": "79287164977737814011242460177248792416483317253936439908020481835936787513608", "price": "0.22", "size": "0", "side": "BUY", "hash": "370a40a5a72aef5b90a3e0541a11f4df6378c882", "best_bid": "0.03", "best_ask": "0.98"}, {"asset_id": "96548263188568861225971459083251184634804319351377359745128053937517313229246", "price": "0.78", "size": "0", "side": "SELL", "hash": "1e517c178a3ab671cf6ad3894cb63afa1471e7d8", "best_bid": "0.02", "best_ask": "0.97"}], "timestamp": "1769384287000", "event_type": "price_change"}}
{"_local_timestamp": "2026-01-25T23:38:07.150315+00:00", "data": {"market": "0xdbe51bbd40ca77053fd794ac247cd2d07a150921accdd624f9f345fbc63db48b", "price_changes": [{"asset_id": "36448007855605050896824786938032039502111327633212361142790079215548046414522", "price": "0.02", "size": "5.47", "side": "BUY", "hash": "c87ed00f4bfc80529040e97bc711e550d1884e79", "best_bid": "0.02", "best_ask": "0.99"}, {"asset_id": "87345926905556212316847105466061439969543894768822947485860245095466364170902", "price": "0.98", "size": "5.47", "side": "SELL", "hash": "b2322e79576938ee95548ba6d4b16e31f217a814", "best_bid": "0.01", "best_ask": "0.98"}], "timestamp": "1769384287019", "event_type": "price_change"}}
{"_local_timestamp": "2026-01-25T23:38:08.017460+00:00", "data": {"market": "0x780c042865b2018eeb8ddcdec110c6839c6f27a8062b37dded79501920250afe", "price_changes": [{"asset_id": "79287164977737814011242460177248792416483317253936439908020481835936787513608", "price": "0.22", "size": "105", "side": "BUY", "hash": "889c6a72863a31829dfef76dab8a673457778abe", "best_bid": "0.22", "best_ask": "0.98"}, {"asset_id": "96548263188568861225971459083251184634804319351377359745128053937517313229246", "price": "0.78", "size": "105", "side": "SELL", "hash": "46895a9a8439fbcb5d7d4a4d0adabbf60e325a36", "best_bid": "0.02", "best_ask": "0.78"}], "timestamp": "1769384287901", "event_type": "price_change"}}
{"_local_timestamp": "2026-01-25T23:38:11.071144+00:00", "data": {"market": "0x780c042865b2018eeb8ddcdec110c6839c6f27a8062b37dded79501920250afe", "price_changes": [{"asset_id": "79287164977737814011242460177248792416483317253936439908020481835936787513608", "price": "0.22", "size": "0", "side": "BUY", "hash": "3efe5e6a90695210611c94e62314e40c2a25bd1c", "best_bid": "0.03", "best_ask": "0.98"}, {"asset_id": "96548263188568861225971459083251184634804319351377359745128053937517313229246", "price": "0.78", "size": "0", "side": "SELL", "hash": "3700843d7f88b7c09c8a28a91cdf272d419c254e", "best_bid": "0.02", "best_ask": "0.97"}], "timestamp": "1769384291000", "event_type": "price_change"}}
{"_local_timestamp": "2026-01-25T23:38:13.904398+00:00", "data": {"market": "0x780c042865b2018eeb8ddcdec110c6839c6f27a8062b37dded79501920250afe", "price_changes": [{"asset_id": "79287164977737814011242460177248792416483317253936439908020481835936787513608", "price": "0.08", "size": "160", "side": "BUY", "hash": "d77774a80b4cce3d4ef7d30456f5863e88be6a88", "best_bid": "0.08", "best_ask": "0.98"}, {"asset_id": "96548263188568861225971459083251184634804319351377359745128053937517313229246", "price": "0.92", "size": "160", "side": "SELL", "hash": "dda3e28d21f628f4c0fc0ab8c1c449b9a2d27d84", "best_bid": "0.02", "best_ask": "0.92"}], "timestamp": "1769384293839", "event_type": "price_change"}}
{"_local_timestamp": "2026-01-25T23:38:14.788333+00:00", "data": {"market": "0x1feaf4097b273ee90aea00fdc5afa9ec6e14b518caf2ddbc421851bef1bdc168", "price_changes": [{"asset_id": "22033330904498269999207988435951609926608006932357150385292796096528006231715", "price": "0.1", "size": "65", "side": "BUY", "hash": "41cf818a25ace7485af486d2fdbbfdbdbfe27a85", "best_bid": "0.44", "best_ask": "0.97"}, {"asset_id": "18882795016423351779855047017846676160725151167446687947380948164302842014020", "price": "0.9", "size": "65", "side": "SELL", "hash": "08e18c6aa08602acb2934f7ed216a63889aeaaa0", "best_bid": "0.03", "best_ask": "0.56"}], "timestamp": "1769384294720", "event_type": "price_change"}}
{"_local_timestamp": "2026-01-25T23:38:15.173705+00:00", "data": {"market": "0x1feaf4097b273ee90aea00fdc5afa9ec6e14b518caf2ddbc421851bef1bdc168", "price_changes": [{"asset_id": "18882795016423351779855047017846676160725151167446687947380948164302842014020", "price": "0.38", "size": "160", "side": "BUY", "hash": "1004bfce4c9033e2b5488576ff27700b5b3db19b", "best_bid": "0.38", "best_ask": "0.56"}, {"asset_id": "22033330904498269999207988435951609926608006932357150385292796096528006231715", "price": "0.62", "size": "160", "side": "SELL", "hash": "f233b2db30358005c7d4a78be4afaa1c63d67339", "best_bid": "0.44", "best_ask": "0.62"}], "timestamp": "1769384295103", "event_type": "price_change"}}
{"_local_timestamp": "2026-01-25T23:38:15.479110+00:00", "data": {"market": "0xdbe51bbd40ca77053fd794ac247cd2d07a150921accdd624f9f345fbc63db48b", "price_changes": [{"asset_id": "36448007855605050896824786938032039502111327633212361142790079215548046414522", "price": "0.03", "size": "52", "side": "BUY", "hash": "ba985ecdfd701fabba99a285ce2301c3c7f58db9", "best_bid": "0.03", "best_ask": "0.99"}, {"asset_id": "87345926905556212316847105466061439969543894768822947485860245095466364170902", "price": "0.97", "size": "52", "side": "SELL", "hash": "39f89529a69a9d001b15465d3cf9f9b1afc9f21d", "best_bid": "0.01", "best_ask": "0.97"}], "timestamp": "1769384295407", "event_type": "price_change"}}
{"_local_timestamp": "2026-01-25T23:38:15.969375+00:00", "data": {"market": "0x780c042865b2018eeb8ddcdec110c6839c6f27a8062b37dded79501920250afe", "price_changes": [{"asset_id": "96548263188568861225971459083251184634804319351377359745128053937517313229246", "price": "0.01", "size": "100", "side": "BUY", "hash": "00b049b7c8064e95aadb75374f52a190786b0db6", "best_bid": "0.01", "best_ask": "0.92"}, {"asset_id": "79287164977737814011242460177248792416483317253936439908020481835936787513608", "price": "0.99", "size": "100", "side": "SELL", "hash": "edcb85fe180953f6bcec1c6c895cc6a3abfb4fe1", "best_bid": "0.08", "best_ask": "0.99"}], "timestamp": "1769384295900", "event_type": "price_change"}}
{"_local_timestamp": "2026-01-25T23:38:15.969898+00:00", "data": {"market": "0x780c042865b2018eeb8ddcdec110c6839c6f27a8062b37dded79501920250afe", "price_changes": [{"asset_id": "96548263188568861225971459083251184634804319351377359745128053937517313229246", "price": "0.02", "size": "0", "side": "BUY", "hash": "00b049b7c8064e95aadb75374f52a190786b0db6", "best_bid": "0.01", "best_ask": "0.92"}, {"asset_id": "79287164977737814011242460177248792416483317253936439908020481835936787513608", "price": "0.98", "size": "0", "side": "SELL", "hash": "edcb85fe180953f6bcec1c6c895cc6a3abfb4fe1", "best_bid": "0.08", "best_ask": "0.99"}], "timestamp": "1769384295900", "event_type": "price_change"}}
{"_local_timestamp": "2026-01-25T23:38:16.244280+00:00", "data": {"market": "0x780c042865b2018eeb8ddcdec110c6839c6f27a8062b37dded79501920250afe", "price_changes": [{"asset_id": "96548263188568861225971459083251184634804319351377359745128053937517313229246", "price": "0.03", "size": "208", "side": "BUY", "hash": "40aa414ce5f4d8d47f866e6d2f32c4e646960c7a", "best_bid": "0.03", "best_ask": "0.92"}, {"asset_id": "79287164977737814011242460177248792416483317253936439908020481835936787513608", "price": "0.97", "size": "208", "side": "SELL", "hash": "0262835a40baea298a33ad25eaa50b9d1c657fe0", "best_bid": "0.08", "best_ask": "0.97"}], "timestamp": "1769384296178", "event_type": "price_change"}}
{"_local_timestamp": "2026-01-25T23:38:16.924412+00:00", "data": {"market": "0x1feaf4097b273ee90aea00fdc5afa9ec6e14b518caf2ddbc421851bef1bdc168", "price_changes": [{"asset_id": "18882795016423351779855047017846676160725151167446687947380948164302842014020", "price": "0.03", "size": "25.54", "side": "BUY", "hash": "e070cd40ed90cc95be8b587df023969f76c123e3", "best_bid": "0.38", "best_ask": "0.56"}, {"asset_id": "22033330904498269999207988435951609926608006932357150385292796096528006231715", "price": "0.97", "size": "25.54", "side": "SELL", "hash": "f6d2cde48ab4cbf39a97fd3ceef7a8432cae6cbd", "best_bid": "0.44", "best_ask": "0.62"}], "timestamp": "1769384296853", "event_type": "price_change"}}
{"_local_timestamp": "2026-01-25T23:38:16.928382+00:00", "data": {"market": "0xdbe51bbd40ca77053fd794ac247cd2d07a150921accdd624f9f345fbc63db48b", "price_changes": [{"asset_id": "36448007855605050896824786938032039502111327633212361142790079215548046414522", "price": "0.02", "size": "0", "side": "BUY", "hash": "833da16ed0f4894b6c40bfe0bb1feca4cfd548e6", "best_bid": "0.03", "best_ask": "0.99"}, {"asset_id": "87345926905556212316847105466061439969543894768822947485860245095466364170902", "price": "0.98", "size": "0", "side": "SELL", "hash": "8f8f42dab1c57a2efe402d9f546bd7b0ada0a4c6", "best_bid": "0.01", "best_ask": "0.97"}], "timestamp": "1769384296853", "event_type": "price_change"}}
{"_local_timestamp": "2026-01-25T23:38:16.933479+00:00", "data": {"market": "0x1feaf4097b273ee90aea00fdc5afa9ec6e14b518caf2ddbc421851bef1bdc168", "price_changes": [{"asset_id": "22033330904498269999207988435951609926608006932357150385292796096528006231715", "price": "0.02", "size": "0", "side": "BUY", "hash": "ceb7e8832535fec8ac2f30346e527c669f5b0db6", "best_bid": "0.44", "best_ask": "0.62"}, {"asset_id": "18882795016423351779855047017846676160725151167446687947380948164302842014020", "price": "0.98", "size": "0", "side": "SELL", "hash": "214775817b0b268fec77790cb44bbdfd631404e8", "best_bid": "0.38", "best_ask": "0.56"}], "timestamp": "1769384296853", "event_type": "price_change"}}
{"_local_timestamp": "2026-01-25T23:38:16.971795+00:00", "data": {"market": "0xdbe51bbd40ca77053fd794ac247cd2d07a150921accdd624f9f345fbc63db48b", "price_changes": [{"asset_id": "36448007855605050896824786938032039502111327633212361142790079215548046414522", "price": "0.04", "size": "5.47", "side": "BUY", "hash": "68beb74f007390fecddd5b5d1611be7df2ae2de6", "best_bid": "0.04", "best_ask": "0.99"}, {"asset_id": "87345926905556212316847105466061439969543894768822947485860245095466364170902", "price": "0.96", "size": "5.47", "side": "SELL", "hash": "a7ab02a59369f306eb9fe8e39a3b82529ebcfd89", "best_bid": "0.01", "best_ask": "0.96"}], "timestamp": "1769384296903", "event_type": "price_change"}}
{"_local_timestamp": "2026-01-25T23:38:18.499518+00:00", "data": {"market": "0x780c042865b2018eeb8ddcdec110c6839c6f27a8062b37dded79501920250afe", "price_changes": [{"asset_id": "96548263188568861225971459083251184634804319351377359745128053937517313229246", "price": "0.03", "size": "0", "side": "BUY", "hash": "e3c9fd850d32dec91dd55d6b6e167f99957a7120", "best_bid": "0.01", "best_ask": "0.92"}, {"asset_id": "79287164977737814011242460177248792416483317253936439908020481835936787513608", "price": "0.97", "size": "0", "side": "SELL", "hash": "aedb2fc8ba44a45aa3003e0c508ebd176f656881", "best_bid": "0.08", "best_ask": "0.99"}], "timestamp": "1769384298430", "event_type": "price_change"}}
{"_local_timestamp": "2026-01-25T23:38:18.528906+00:00", "data": {"market": "0x780c042865b2018eeb8ddcdec110c6839c6f27a8062b37dded79501920250afe", "price_changes": [{"asset_id": "96548263188568861225971459083251184634804319351377359745128053937517313229246", "price": "0.02", "size": "159", "side": "BUY", "hash": "a33d500178a370c73b51d37cb50624ee2bc47753", "best_bid": "0.02", "best_ask": "0.92"}, {"asset_id": "79287164977737814011242460177248792416483317253936439908020481835936787513608", "price": "0.98", "size": "159", "side": "SELL", "hash": "fc58555585db3d32cac99f076ecaa196ce33c811", "best_bid": "0.08", "best_ask": "0.98"}], "timestamp": "1769384298460", "event_type": "price_change"}}
{"_local_timestamp": "2026-01-25T23:38:18.772046+00:00", "data": {"market": "0xdbe51bbd40ca77053fd794ac247cd2d07a150921accdd624f9f345fbc63db48b", "price_changes": [{"asset_id": "36448007855605050896824786938032039502111327633212361142790079215548046414522", "price": "0.03", "size": "0", "side": "BUY", "hash": "0a0a6034f1cd055b75589f320e6f6edb953a0e71", "best_bid": "0.04", "best_ask": "0.99"}, {"asset_id": "87345926905556212316847105466061439969543894768822947485860245095466364170902", "price": "0.97", "size": "0", "side": "SELL", "hash": "ef9eb4a38f8d8ce16dcfe16601336ee72df05109", "best_bid": "0.01", "best_ask": "0.96"}], "timestamp": "1769384298698", "event_type": "price_change"}}
{"_local_timestamp": "2026-01-25T23:38:19.829049+00:00", "data": {"market": "0x780c042865b2018eeb8ddcdec110c6839c6f27a8062b37dded79501920250afe", "price_changes": [{"asset_id": "96548263188568861225971459083251184634804319351377359745128053937517313229246", "price": "0.02", "size": "0", "side": "BUY", "hash": "12a55d3ca2bdc589b1a8cd918d3e6a5ad6044260", "best_bid": "0.01", "best_ask": "0.92"}, {"asset_id": "79287164977737814011242460177248792416483317253936439908020481835936787513608", "price": "0.98", "size": "0", "side": "SELL", "hash": "8d5d8b0ee4b6c5c07e33c666fd579fd482f0277c", "best_bid": "0.08", "best_ask": "0.99"}], "timestamp": "1769384299758", "event_type": "price_change"}}
{"_local_timestamp": "2026-01-25T23:38:19.829569+00:00", "data": {"market": "0x1feaf4097b273ee90aea00fdc5afa9ec6e14b518caf2ddbc421851bef1bdc168", "price_changes": [{"asset_id": "22033330904498269999207988435951609926608006932357150385292796096528006231715", "price": "0.1", "size": "0", "side": "BUY", "hash": "24a401399afa2c22c5af78d95442d5ba613e3e3f", "best_bid": "0.44", "best_ask": "0.62"}, {"asset_id": "18882795016423351779855047017846676160725151167446687947380948164302842014020", "price": "0.9", "size": "0", "side": "SELL", "hash": "b6c5da5f1041f293c9bc1c6961d1c6e20fcc729f", "best_bid": "0.38", "best_ask": "0.56"}], "timestamp": "1769384299759", "event_type": "price_change"}}
{"_local_timestamp": "2026-01-25T23:38:19.830012+00:00", "data": {"market": "0x1feaf4097b273ee90aea00fdc5afa9ec6e14b518caf2ddbc421851bef1bdc168", "price_changes": [{"asset_id": "18882795016423351779855047017846676160725151167446687947380948164302842014020", "price": "0.38", "size": "0", "side": "BUY", "hash": "f4589e47934129b8788a051774d40c98bb8b1be9", "best_bid": "0.03", "best_ask": "0.56"}, {"asset_id": "22033330904498269999207988435951609926608006932357150385292796096528006231715", "price": "0.62", "size": "0", "side": "SELL", "hash": "3fb0f2241698b399aa41173ed5dc55763027e374", "best_bid": "0.44", "best_ask": "0.97"}], "timestamp": "1769384299760", "event_type": "price_change"}}
{"_local_timestamp": "2026-01-25T23:38:19.833238+00:00", "data": {"market": "0x780c042865b2018eeb8ddcdec110c6839c6f27a8062b37dded79501920250afe", "price_changes": [{"asset_id": "79287164977737814011242460177248792416483317253936439908020481835936787513608", "price": "0.08", "size": "0", "side": "BUY", "hash": "093cd42a09e9d5fa576ce84a5246597a6e59a0a2", "best_bid": "0.03", "best_ask": "0.99"}, {"asset_id": "96548263188568861225971459083251184634804319351377359745128053937517313229246", "price": "0.92", "size": "0", "side": "SELL", "hash": "1743c7312fb4c5b10468ee77da0ce690d0260717", "best_bid": "0.01", "best_ask": "0.97"}], "timestamp": "1769384299765", "event_type": "price_change"}}
{"_local_timestamp": "2026-01-25T23:38:19.876326+00:00", "data": {"market": "0x1feaf4097b273ee90aea00fdc5afa9ec6e14b518caf2ddbc421851bef1bdc168", "price_changes": [{"asset_id": "22033330904498269999207988435951609926608006932357150385292796096528006231715", "price": "0.1", "size": "35", "side": "BUY", "hash": "00d9f739ca3ea91005fb21ff19d5568e71c677d9", "best_bid": "0.44", "best_ask": "0.97"}, {"asset_id": "18882795016423351779855047017846676160725151167446687947380948164302842014020", "price": "0.9", "size": "35", "side": "SELL", "hash": "f58a1d46dbf246bdc8762e713713c18079e709c8", "best_bid": "0.03", "best_ask": "0.56"}], "timestamp": "1769384299812", "event_type": "price_change"}}
{"_local_timestamp": "2026-01-25T23:38:20.263234+00:00", "data": {"market": "0xdbe51bbd40ca77053fd794ac247cd2d07a150921accdd624f9f345fbc63db48b", "price_changes": [{"asset_id": "36448007855605050896824786938032039502111327633212361142790079215548046414522", "price": "0.04", "size": "30.47", "side": "BUY", "hash": "32dd8e23dba9975db467e58e25f9c5f785cb7788", "best_bid": "0.04", "best_ask": "0.99"}, {"asset_id": "87345926905556212316847105466061439969543894768822947485860245095466364170902", "price": "0.96", "size": "30.47", "side": "SELL", "hash": "9f87288e75190a5247bc532c0371c1871d885a14", "best_bid": "0.01", "best_ask": "0.96"}], "timestamp": "1769384300195", "event_type": "price_change"}}
{"_local_timestamp": "2026-01-25T23:38:20.368753+00:00", "data": {"market": "0xdbe51bbd40ca77053fd794ac247cd2d07a150921accdd624f9f345fbc63db48b", "price_changes": [{"asset_id": "36448007855605050896824786938032039502111327633212361142790079215548046414522", "price": "0.04", "size": "25", "side": "BUY", "hash": "d3216ed52a4e5da07acc21e3a8a1dfd19149f2c0", "best_bid": "0.04", "best_ask": "0.99"}, {"asset_id": "87345926905556212316847105466061439969543894768822947485860245095466364170902", "price": "0.96", "size": "25", "side": "SELL", "hash": "47695d85c6972e75811686715799656df4bf8237", "best_bid": "0.01", "best_ask": "0.96"}], "timestamp": "1769384300301", "event_type": "price_change"}}
{"_local_timestamp": "2026-01-25T23:38:20.411202+00:00", "data": {"market": "0xdbe51bbd40ca77053fd794ac247cd2d07a150921accdd624f9f345fbc63db48b", "price_changes": [{"asset_id": "36448007855605050896824786938032039502111327633212361142790079215548046414522", "price": "0.02", "size": "5.47", "side": "BUY", "hash": "68ea7e91fb612baed91f90cc80fc6f2e3526016f", "best_bid": "0.04", "best_ask": "0.99"}, {"asset_id": "87345926905556212316847105466061439969543894768822947485860245095466364170902", "price": "0.98", "size": "5.47", "side": "SELL", "hash": "a77285c97ba8f610ce0b99d24815ccd69c43ea72", "best_bid": "0.01", "best_ask": "0.96"}], "timestamp": "1769384300336", "event_type": "price_change"}}
{"_local_timestamp": "2026-01-25T23:38:20.628075+00:00", "data": {"market": "0x1feaf4097b273ee90aea00fdc5afa9ec6e14b518caf2ddbc421851bef1bdc168", "price_changes": [{"asset_id": "18882795016423351779855047017846676160725151167446687947380948164302842014020", "price": "0.55", "size": "176", "side": "BUY", "hash": "57e99ff6f975cf1231f6853f0b5165984ce35d52", "best_bid": "0.55", "best_ask": "0.56"}, {"asset_id": "22033330904498269999207988435951609926608006932357150385292796096528006231715", "price": "0.45", "size": "176", "side": "SELL", "hash": "4cf1f6ac1ecbd1e3364f5ada18a3ee7ccfd211de", "best_bid": "0.44", "best_ask": "0.45"}], "timestamp": "1769384300552", "event_type": "price_change"}}
{"_local_timestamp": "2026-01-25T23:38:21.772241+00:00", "data": {"market": "0x1feaf4097b273ee90aea00fdc5afa9ec6e14b518caf2ddbc421851bef1bdc168", "price_changes": [{"asset_id": "22033330904498269999207988435951609926608006932357150385292796096528006231715", "price": "0.1", "size": "0", "side": "BUY", "hash": "90d64670ff712167a4b761aa8528bff417556ae3", "best_bid": "0.44", "best_ask": "0.45"}, {"asset_id": "18882795016423351779855047017846676160725151167446687947380948164302842014020", "price": "0.9", "size": "0", "side": "SELL", "hash": "17d84620e49b72d2773192b9000e84ec8e9654ff", "best_bid": "0.55", "best_ask": "0.56"}], "timestamp": "1769384301704", "event_type": "price_change"}}
{"_local_timestamp": "2026-01-25T23:38:21.796702+00:00", "data": {"market": "0x1feaf4097b273ee90aea00fdc5afa9ec6e14b518caf2ddbc421851bef1bdc168", "price_changes": [{"asset_id": "22033330904498269999207988435951609926608006932357150385292796096528006231715", "price": "0.15", "size": "65", "side": "BUY", "hash": "c96965b5289280266ab5e0dbf66cc66f4e8ad35a", "best_bid": "0.44", "best_ask": "0.45"}, {"asset_id": "18882795016423351779855047017846676160725151167446687947380948164302842014020", "price": "0.85", "size": "65", "side": "SELL", "hash": "0170190ad823e28b30efc1d60dbe1d2ed82e6518", "best_bid": "0.55", "best_ask": "0.56"}], "timestamp": "1769384301733", "event_type": "price_change"}}
{"_local_timestamp": "2026-01-25T23:38:21.841149+00:00", "data": {"market": "0x1feaf4097b273ee90aea00fdc5afa9ec6e14b518caf2ddbc421851bef1bdc168", "price_changes": [{"asset_id": "22033330904498269999207988435951609926608006932357150385292796096528006231715", "price": "0.15", "size": "0", "side": "BUY", "hash": "257d6c33090d66442bf324864130e8c7c8a2768d", "best_bid": "0.44", "best_ask": "0.45"}, {"asset_id": "18882795016423351779855047017846676160725151167446687947380948164302842014020", "price": "0.85", "size": "0", "side": "SELL", "hash": "b6614ad930ba9910ce9e61be244c577ca5b507f9", "best_bid": "0.55", "best_ask": "0.56"}], "timestamp": "1769384301764", "event_type": "price_change"}}
{"_local_timestamp": "2026-01-25T23:38:21.996773+00:00", "data": {"market": "0xdbe51bbd40ca77053fd794ac247cd2d07a150921accdd624f9f345fbc63db48b", "price_changes": [{"asset_id": "87345926905556212316847105466061439969543894768822947485860245095466364170902", "price": "0.01", "size": "200", "side": "BUY", "hash": "65337729be2a00daea7aefc5192e4d60cf4a08a5", "best_bid": "0.01", "best_ask": "0.96"}, {"asset_id": "36448007855605050896824786938032039502111327633212361142790079215548046414522", "price": "0.99", "size": "200", "side": "SELL", "hash": "9d5f030e77747f563ed2fe743c236e97f4c13e0d", "best_bid": "0.04", "best_ask": "0.99"}], "timestamp": "1769384301931", "event_type": "price_change"}}
{"_local_timestamp": "2026-01-25T23:38:23.277753+00:00", "data": {"market": "0x1feaf4097b273ee90aea00fdc5afa9ec6e14b518caf2ddbc421851bef1bdc168", "price_changes": [{"asset_id": "22033330904498269999207988435951609926608006932357150385292796096528006231715", "price": "0.14", "size": "232", "side": "BUY", "hash": "156eb0fb6ca4232435aba55a62bf778572cc7868", "best_bid": "0.44", "best_ask": "0.45"}, {"asset_id": "18882795016423351779855047017846676160725151167446687947380948164302842014020", "price": "0.86", "size": "232", "side": "SELL", "hash": "e581c77862c3f66d7f47b8acb94c7083cc0e04b2", "best_bid": "0.55", "best_ask": "0.56"}], "timestamp": "1769384303211", "event_type": "price_change"}}
{"_local_timestamp": "2026-01-25T23:38:23.507456+00:00", "data": {"market": "0xdbe51bbd40ca77053fd794ac247cd2d07a150921accdd624f9f345fbc63db48b", "price_changes": [{"asset_id": "36448007855605050896824786938032039502111327633212361142790079215548046414522", "price": "0.02", "size": "0", "side": "BUY", "hash": "5ff01e3e5d21f53726841059fe067df1aa06d01c", "best_bid": "0.04", "best_ask": "0.99"}, {"asset_id": "87345926905556212316847105466061439969543894768822947485860245095466364170902", "price": "0.98", "size": "0", "side": "SELL", "hash": "dcf13ab664c06f602f0b125f8210d39199c87576", "best_bid": "0.01", "best_ask": "0.96"}], "timestamp": "1769384303442", "event_type": "price_change"}}
{"_local_timestamp": "2026-01-25T23:38:23.540260+00:00", "data": {"market": "0xdbe51bbd40ca77053fd794ac247cd2d07a150921accdd624f9f345fbc63db48b", "price_changes": [{"asset_id": "36448007855605050896824786938032039502111327633212361142790079215548046414522", "price": "0.05", "size": "5.47", "side": "BUY", "hash": "d412c130a9f1d40187898d96f5624c6ea1fd2ae8", "best_bid": "0.05", "best_ask": "0.99"}, {"asset_id": "87345926905556212316847105466061439969543894768822947485860245095466364170902", "price": "0.95", "size": "5.47", "side": "SELL", "hash": "896536e3a720be59e1ef6c0717dce28a98de2c49", "best_bid": "0.01", "best_ask": "0.95"}], "timestamp": "1769384303476", "event_type": "price_change"}}
{"_local_timestamp": "2026-01-25T23:38:23.775224+00:00", "data": {"market": "0x1feaf4097b273ee90aea00fdc5afa9ec6e14b518caf2ddbc421851bef1bdc168", "price_changes": [{"asset_id": "22033330904498269999207988435951609926608006932357150385292796096528006231715", "price": "0.14", "size": "0", "side": "BUY", "hash": "2912edd9b0ecd5ed2cb0907e4a90aae7d8b916eb", "best_bid": "0.44", "best_ask": "0.45"}, {"asset_id": "18882795016423351779855047017846676160725151167446687947380948164302842014020", "price": "0.86", "size": "0", "side": "SELL", "hash": "e3dd202bff26d70a6510ccd6ce381c580f9d9cb0", "best_bid": "0.55", "best_ask": "0.56"}], "timestamp": "1769384303702", "event_type": "price_change"}}
{"_local_timestamp": "2026-01-25T23:38:23.801496+00:00", "data": {"market": "0x780c042865b2018eeb8ddcdec110c6839c6f27a8062b37dded79501920250afe", "price_changes": [{"asset_id": "79287164977737814011242460177248792416483317253936439908020481835936787513608", "price": "0.2", "size": "170", "side": "BUY", "hash": "09c320bc10ae47b2f657f3500832e468f491e06f", "best_bid": "0.2", "best_ask": "0.99"}, {"asset_id": "96548263188568861225971459083251184634804319351377359745128053937517313229246", "price": "0.8", "size": "170", "side": "SELL", "hash": "313a60cfca47009dda6f0f643432eb954a5e4cbb", "best_bid": "0.01", "best_ask": "0.8"}], "timestamp": "1769384303733", "event_type": "price_change"}}
{"_local_timestamp": "2026-01-25T23:38:24.097271+00:00", "data": {"market": "0x1feaf4097b273ee90aea00fdc5afa9ec6e14b518caf2ddbc421851bef1bdc168", "price_changes": [{"asset_id": "22033330904498269999207988435951609926608006932357150385292796096528006231715", "price": "0.16", "size": "90", "side": "BUY", "hash": "c5fe81fbad4bd153ed178d20a25e42d44b2d5519", "best_bid": "0.44", "best_ask": "0.45"}, {"asset_id": "18882795016423351779855047017846676160725151167446687947380948164302842014020", "price": "0.84", "size": "90", "side": "SELL", "hash": "24fe54a325a945263a6e0134335f6ca07fde4d72", "best_bid": "0.55", "best_ask": "0.56"}], "timestamp": "1769384304030", "event_type": "price_change"}}
{"_local_timestamp": "2026-01-25T23:38:24.245454+00:00", "data": {"market": "0x780c042865b2018eeb8ddcdec110c6839c6f27a8062b37dded79501920250afe", "price_changes": [{"asset_id": "79287164977737814011242460177248792416483317253936439908020481835936787513608", "price": "0.03", "size": "38.47", "side": "BUY", "hash": "2a4693b9813ee8b3822248950e9afaa833fc9c1d", "best_bid": "0.2", "best_ask": "0.99"}, {"asset_id": "96548263188568861225971459083251184634804319351377359745128053937517313229246", "price": "0.97", "size": "38.47", "side": "SELL", "hash": "df7c83029dc5dce1608aca7ba5276e7eddb524ea", "best_bid": "0.01", "best_ask": "0.8"}], "timestamp": "1769384304172", "event_type": "price_change"}}
{"_local_timestamp": "2026-01-25T23:38:24.405284+00:00", "data": {"market": "0x780c042865b2018eeb8ddcdec110c6839c6f27a8062b37dded79501920250afe", "price_changes": [{"asset_id": "96548263188568861225971459083251184634804319351377359745128053937517313229246", "price": "0.23", "size": "183", "side": "BUY", "hash": "1fe127a36f70830c14e97e923b9b020b152158d2", "best_bid": "0.23", "best_ask": "0.8"}, {"asset_id": "79287164977737814011242460177248792416483317253936439908020481835936787513608", "price": "0.77", "size": "183", "side": "SELL", "hash": "5275825df83eb530f0f55082a27dd873b5995337", "best_bid": "0.2", "best_ask": "0.77"}], "timestamp": "1769384304327", "event_type": "price_change"}}
{"_local_timestamp": "2026-01-25T23:38:24.592891+00:00", "data": {"market": "0x1feaf4097b273ee90aea00fdc5afa9ec6e14b518caf2ddbc421851bef1bdc168", "price_changes": [{"asset_id": "22033330904498269999207988435951609926608006932357150385292796096528006231715", "price": "0.16", "size": "0", "side": "BUY", "hash": "b27a4bae61dced2d1e8856a0800d6cc40d0de79f", "best_bid": "0.44", "best_ask": "0.45"}, {"asset_id": "18882795016423351779855047017846676160725151167446687947380948164302842014020", "price": "0.84", "size": "0", "side": "SELL", "hash": "c2201cc515db53a92154675572b07c2899caab8c", "best_bid": "0.55", "best_ask": "0.56"}], "timestamp": "1769384304522", "event_type": "price_change"}}
{"_local_timestamp": "2026-01-25T23:38:24.624127+00:00", "data": {"market": "0x1feaf4097b273ee90aea00fdc5afa9ec6e14b518caf2ddbc421851bef1bdc168", "price_changes": [{"asset_id": "22033330904498269999207988435951609926608006932357150385292796096528006231715", "price": "0.17", "size": "55", "side": "BUY", "hash": "20ef69f74591c07dcd07ada877c00aaa5fa6c1db", "best_bid": "0.44", "best_ask": "0.45"}, {"asset_id": "18882795016423351779855047017846676160725151167446687947380948164302842014020", "price": "0.83", "size": "55", "side": "SELL", "hash": "3b931bcd86f783f322dd8a56cd14cf750a4efe32", "best_bid": "0.55", "best_ask": "0.56"}], "timestamp": "1769384304561", "event_type": "price_change"}}
{"_local_timestamp": "2026-01-25T23:38:24.812427+00:00", "data": {"market": "0x1feaf4097b273ee90aea00fdc5afa9ec6e14b518caf2ddbc421851bef1bdc168", "price_changes": [{"asset_id": "22033330904498269999207988435951609926608006932357150385292796096528006231715", "price": "0.17", "size": "0", "side": "BUY", "hash": "6640c60872fa1cad0694a3fe99c2c2d5fbb5a59a", "best_bid": "0.44", "best_ask": "0.45"}, {"asset_id": "18882795016423351779855047017846676160725151167446687947380948164302842014020", "price": "0.83", "size": "0", "side": "SELL", "hash": "49bbad157a8ff35458a92fc9d2eb99d1fa871d5c", "best_bid": "0.55", "best_ask": "0.56"}], "timestamp": "1769384304740", "event_type": "price_change"}}
{"_local_timestamp": "2026-01-25T23:38:24.840108+00:00", "data": {"market": "0xdbe51bbd40ca77053fd794ac247cd2d07a150921accdd624f9f345fbc63db48b", "price_changes": [{"asset_id": "36448007855605050896824786938032039502111327633212361142790079215548046414522", "price": "0.06", "size": "35", "side": "BUY", "hash": "3bad37217e5223c19b2f42c78dfa546109520d1e", "best_bid": "0.06", "best_ask": "0.99"}, {"asset_id": "87345926905556212316847105466061439969543894768822947485860245095466364170902", "price": "0.94", "size": "35", "side": "SELL", "hash": "1f59259b987edc8b8f31eefb469a38eb8cf7d8eb", "best_bid": "0.01", "best_ask": "0.94"}], "timestamp": "1769384304769", "event_type": "price_change"}}
{"_local_timestamp": "2026-01-25T23:38:25.837601+00:00", "data": {"market": "0x780c042865b2018eeb8ddcdec110c6839c6f27a8062b37dded79501920250afe", "price_changes": [{"asset_id": "96548263188568861225971459083251184634804319351377359745128053937517313229246", "price": "0.01", "size": "200", "side": "BUY", "hash": "4271075f5ea29152266cceaf7d150aa9321f7bc7", "best_bid": "0.23", "best_ask": "0.8"}, {"asset_id": "79287164977737814011242460177248792416483317253936439908020481835936787513608", "price": "0.99", "size": "200", "side": "SELL", "hash": "f189f072136031dd4eb633a111d3c68e0e9ec541", "best_bid": "0.2", "best_ask": "0.77"}], "timestamp": "1769384305769", "event_type": "price_change"}}
{"_local_timestamp": "2026-01-25T23:38:27.689647+00:00", "data": {"market": "0x1feaf4097b273ee90aea00fdc5afa9ec6e14b518caf2ddbc421851bef1bdc168", "price_changes": [{"asset_id": "22033330904498269999207988435951609926608006932357150385292796096528006231715", "price": "0.18", "size": "67", "side": "BUY", "hash": "01dec61eefed39c4ce2fc2e84e41c7e80d685896", "best_bid": "0.44", "best_ask": "0.45"}, {"asset_id": "18882795016423351779855047017846676160725151167446687947380948164302842014020", "price": "0.82", "size": "67", "side": "SELL", "hash": "b9915b7f6dab288af703a9ded3365307ab70c89d", "best_bid": "0.55", "best_ask": "0.56"}], "timestamp": "1769384307617", "event_type": "price_change"}}
{"_local_timestamp": "2026-01-25T23:38:29.731683+00:00", "data": {"market": "0xdbe51bbd40ca77053fd794ac247cd2d07a150921accdd624f9f345fbc63db48b", "price_changes": [{"asset_id": "36448007855605050896824786938032039502111327633212361142790079215548046414522", "price": "0.05", "size": "0", "side": "BUY", "hash": "761a9775fe53e4fbc3b7c10ef72a8a3fa313533b", "best_bid": "0.06", "best_ask": "0.99"}, {"asset_id": "87345926905556212316847105466061439969543894768822947485860245095466364170902", "price": "0.95", "size": "0", "side": "SELL", "hash": "d58f2da1c85c1c12be5be93981158e24b92593c6", "best_bid": "0.01", "best_ask": "0.94"}], "timestamp": "1769384309666", "event_type": "price_change"}}
{"_local_timestamp": "2026-01-25T23:38:29.777682+00:00", "data": {"market": "0xdbe51bbd40ca77053fd794ac247cd2d07a150921accdd624f9f345fbc63db48b", "price_changes": [{"asset_id": "36448007855605050896824786938032039502111327633212361142790079215548046414522", "price": "0.06", "size": "40.47", "side": "BUY", "hash": "f3732dc121faca42ac1f31c5ac8a21dbf09220fc", "best_bid": "0.06", "best_ask": "0.99"}, {"asset_id": "87345926905556212316847105466061439969543894768822947485860245095466364170902", "price": "0.94", "size": "40.47", "side": "SELL", "hash": "1e4193ed879bfb7b2efd88558829a1df2b48842f", "best_bid": "0.01", "best_ask": "0.94"}], "timestamp": "1769384309710", "event_type": "price_change"}}
{"_local_timestamp": "2026-01-25T23:38:39.376189+00:00", "data": {"market": "0x1feaf4097b273ee90aea00fdc5afa9ec6e14b518caf2ddbc421851bef1bdc168", "price_changes": [{"asset_id": "22033330904498269999207988435951609926608006932357150385292796096528006231715", "price": "0.18", "size": "0", "side": "BUY", "hash": "75ebdfda54d76dd58cd8f4fe8373ddf717454acb", "best_bid": "0.44", "best_ask": "0.45"}, {"asset_id": "18882795016423351779855047017846676160725151167446687947380948164302842014020", "price": "0.82", "size": "0", "side": "SELL", "hash": "24ca47b94ac27f6270336fdcdd520d129373d799", "best_bid": "0.55", "best_ask": "0.56"}], "timestamp": "1769384319309", "event_type": "price_change"}}
{"_local_timestamp": "2026-01-25T23:38:39.440102+00:00", "data": {"market": "0x1feaf4097b273ee90aea00fdc5afa9ec6e14b518caf2ddbc421851bef1bdc168", "price_changes": [{"asset_id": "22033330904498269999207988435951609926608006932357150385292796096528006231715", "price": "0.17", "size": "107", "side": "BUY", "hash": "4753e43a924adc9439f3784b4dd2d66c624e154b", "best_bid": "0.44", "best_ask": "0.45"}, {"asset_id": "18882795016423351779855047017846676160725151167446687947380948164302842014020", "price": "0.83", "size": "107", "side": "SELL", "hash": "44aa3c11ec1fff064750750c443cad89edf6eefb", "best_bid": "0.55", "best_ask": "0.56"}], "timestamp": "1769384319376", "event_type": "price_change"}}
{"_local_timestamp": "2026-01-25T23:38:43.305108+00:00", "data": {"market": "0xdbe51bbd40ca77053fd794ac247cd2d07a150921accdd624f9f345fbc63db48b", "price_changes": [{"asset_id": "87345926905556212316847105466061439969543894768822947485860245095466364170902", "price": "0.16", "size": "5", "side": "BUY", "hash": "13c27b3447745d31ffb872c4e7e9b8ecfe6b144b", "best_bid": "0.16", "best_ask": "0.94"}, {"asset_id": "36448007855605050896824786938032039502111327633212361142790079215548046414522", "price": "0.84", "size": "5", "side": "SELL", "hash": "a23481ee0ef9d55a137d8224f74503c1c8a11495", "best_bid": "0.06", "best_ask": "0.84"}], "timestamp": "1769384323235", "event_type": "price_change"}}
{"_local_timestamp": "2026-01-25T23:38:43.716634+00:00", "data": {"market": "0xdbe51bbd40ca77053fd794ac247cd2d07a150921accdd624f9f345fbc63db48b", "price_changes": [{"asset_id": "87345926905556212316847105466061439969543894768822947485860245095466364170902", "price": "0.16", "size": "0", "side": "BUY", "hash": "3f6b79f0523d0481da26d41f544ef9ae7d0c7561", "best_bid": "0.01", "best_ask": "0.94"}, {"asset_id": "36448007855605050896824786938032039502111327633212361142790079215548046414522", "price": "0.84", "size": "0", "side": "SELL", "hash": "8e9c170995bf539b4523dc6f1127c28344beb2e9", "best_bid": "0.06", "best_ask": "0.99"}], "timestamp": "1769384323641", "event_type": "price_change"}}
{"_local_timestamp": "2026-01-25T23:38:43.924156+00:00", "data": {"market": "0xdbe51bbd40ca77053fd794ac247cd2d07a150921accdd624f9f345fbc63db48b", "price_changes": [{"asset_id": "87345926905556212316847105466061439969543894768822947485860245095466364170902", "price": "0.24", "size": "5", "side": "BUY", "hash": "8c32386577fd0c5335a998e498a90b074540889f", "best_bid": "0.24", "best_ask": "0.94"}, {"asset_id": "36448007855605050896824786938032039502111327633212361142790079215548046414522", "price": "0.76", "size": "5", "side": "SELL", "hash": "55b6fc995459080e05f27f516eb739b55469a064", "best_bid": "0.06", "best_ask": "0.76"}], "timestamp": "1769384323853", "event_type": "price_change"}}
{"_local_timestamp": "2026-01-25T23:38:44.116576+00:00", "data": {"market": "0xdbe51bbd40ca77053fd794ac247cd2d07a150921accdd624f9f345fbc63db48b", "price_changes": [{"asset_id": "87345926905556212316847105466061439969543894768822947485860245095466364170902", "price": "0.24", "size": "0", "side": "BUY", "hash": "fc927571c7ce7a71160d731b47dbc5e38550ff38", "best_bid": "0.01", "best_ask": "0.94"}, {"asset_id": "36448007855605050896824786938032039502111327633212361142790079215548046414522", "price": "0.76", "size": "0", "side": "SELL", "hash": "2738fc7f23afdd6eb53c03771bcd51f1de616094", "best_bid": "0.06", "best_ask": "0.99"}], "timestamp": "1769384324051", "event_type": "price_change"}}
{"_local_timestamp": "2026-01-25T23:38:44.284791+00:00", "data": {"market": "0x1feaf4097b273ee90aea00fdc5afa9ec6e14b518caf2ddbc421851bef1bdc168", "price_changes": [{"asset_id": "22033330904498269999207988435951609926608006932357150385292796096528006231715", "price": "0.17", "size": "0", "side": "BUY", "hash": "33267506d1d9176f6e9101cb256776a0e9cda3be", "best_bid": "0.44", "best_ask": "0.45"}, {"asset_id": "18882795016423351779855047017846676160725151167446687947380948164302842014020", "price": "0.83", "size": "0", "side": "SELL", "hash": "d4bca9797d0370524c6f44f97c0837953972f923", "best_bid": "0.55", "best_ask": "0.56"}], "timestamp": "1769384324210", "event_type": "price_change"}}
{"_local_timestamp": "2026-01-25T23:38:44.327789+00:00", "data": {"market": "0x1feaf4097b273ee90aea00fdc5afa9ec6e14b518caf2ddbc421851bef1bdc168", "price_changes": [{"asset_id": "22033330904498269999207988435951609926608006932357150385292796096528006231715", "price": "0.18", "size": "42", "side": "BUY", "hash": "c190f893e8f2a17d09120fc2f747112744a333c2", "best_bid": "0.44", "best_ask": "0.45"}, {"asset_id": "18882795016423351779855047017846676160725151167446687947380948164302842014020", "price": "0.82", "size": "42", "side": "SELL", "hash": "e2846f7ff407fc5e85c3356e5104eecd0e1e9532", "best_bid": "0.55", "best_ask": "0.56"}], "timestamp": "1769384324252", "event_type": "price_change"}}
{"_local_timestamp": "2026-01-25T23:38:45.913191+00:00", "data": {"market": "0x1feaf4097b273ee90aea00fdc5afa9ec6e14b518caf2ddbc421851bef1bdc168", "price_changes": [{"asset_id": "22033330904498269999207988435951609926608006932357150385292796096528006231715", "price": "0.18", "size": "0", "side": "BUY", "hash": "6f5b583a0029c0b6f6a8c5cde6f45072f96934d0", "best_bid": "0.44", "best_ask": "0.45"}, {"asset_id": "18882795016423351779855047017846676160725151167446687947380948164302842014020", "price": "0.82", "size": "0", "side": "SELL", "hash": "72ed2943cfc37bae3d25ac14f21f7692b0434750", "best_bid": "0.55", "best_ask": "0.56"}], "timestamp": "1769384325847", "event_type": "price_change"}}
{"_local_timestamp": "2026-01-25T23:38:45.972246+00:00", "data": {"market": "0x1feaf4097b273ee90aea00fdc5afa9ec6e14b518caf2ddbc421851bef1bdc168", "price_changes": [{"asset_id": "22033330904498269999207988435951609926608006932357150385292796096528006231715", "price": "0.19", "size": "36", "side": "BUY", "hash": "1bc00f995c71249cff3f978029b578a872755945", "best_bid": "0.44", "best_ask": "0.45"}, {"asset_id": "18882795016423351779855047017846676160725151167446687947380948164302842014020", "price": "0.81", "size": "36", "side": "SELL", "hash": "4009128b55ebdb8225c60a7e271d58416d0b43dd", "best_bid": "0.55", "best_ask": "0.56"}], "timestamp": "1769384325890", "event_type": "price_change"}}
{"_local_timestamp": "2026-01-25T23:38:47.923194+00:00", "data": {"market": "0xdbe51bbd40ca77053fd794ac247cd2d07a150921accdd624f9f345fbc63db48b", "price_changes": [{"asset_id": "87345926905556212316847105466061439969543894768822947485860245095466364170902", "price": "0.26", "size": "55", "side": "BUY", "hash": "17a39d45a942246769a66a11d948474e193e7856", "best_bid": "0.26", "best_ask": "0.94"}, {"asset_id": "36448007855605050896824786938032039502111327633212361142790079215548046414522", "price": "0.74", "size": "55", "side": "SELL", "hash": "b0a128596fcb965541e764b92afb9830b579d1d6", "best_bid": "0.06", "best_ask": "0.74"}], "timestamp": "1769384327854", "event_type": "price_change"}}
{"_local_timestamp": "2026-01-25T23:39:01.017702+00:00", "data": {"market": "0xdbe51bbd40ca77053fd794ac247cd2d07a150921accdd624f9f345fbc63db48b", "price_changes": [{"asset_id": "36448007855605050896824786938032039502111327633212361142790079215548046414522", "price": "0.06", "size": "5.47", "side": "BUY", "hash": "3a736f276bdb11006ccfa1cf60f29b10afe03b83", "best_bid": "0.06", "best_ask": "0.74"}, {"asset_id": "87345926905556212316847105466061439969543894768822947485860245095466364170902", "price": "0.94", "size": "5.47", "side": "SELL", "hash": "c0969e7e675e45eacf88fd9eafbfc838348adf89", "best_bid": "0.26", "best_ask": "0.94"}], "timestamp": "1769384340951", "event_type": "price_change"}}
{"_local_timestamp": "2026-01-25T23:39:01.021583+00:00", "data": {"market": "0xdbe51bbd40ca77053fd794ac247cd2d07a150921accdd624f9f345fbc63db48b", "price_changes": [{"asset_id": "87345926905556212316847105466061439969543894768822947485860245095466364170902", "price": "0.26", "size": "0", "side": "BUY", "hash": "02c434f277c42cada12f913b45ecb597d0b47295", "best_bid": "0.01", "best_ask": "0.94"}, {"asset_id": "36448007855605050896824786938032039502111327633212361142790079215548046414522", "price": "0.74", "size": "0", "side": "SELL", "hash": "dfc96097368675cd47d27cece005f524f2ecc371", "best_bid": "0.06", "best_ask": "0.99"}], "timestamp": "1769384340955", "event_type": "price_change"}}
{"_local_timestamp": "2026-01-25T23:39:02.411107+00:00", "data": {"market": "0x1feaf4097b273ee90aea00fdc5afa9ec6e14b518caf2ddbc421851bef1bdc168", "price_changes": [{"asset_id": "22033330904498269999207988435951609926608006932357150385292796096528006231715", "price": "0.19", "size": "0", "side": "BUY", "hash": "efc0b5b56ae3c822eac0bfb38bab9d5bca3c7c23", "best_bid": "0.44", "best_ask": "0.45"}, {"asset_id": "18882795016423351779855047017846676160725151167446687947380948164302842014020", "price": "0.81", "size": "0", "side": "SELL", "hash": "adfec8a4aec0ac78239423cc9369654e600d1f9c", "best_bid": "0.55", "best_ask": "0.56"}], "timestamp": "1769384342339", "event_type": "price_change"}}
{"_local_timestamp": "2026-01-25T23:39:03.498362+00:00", "data": {"market": "0x780c042865b2018eeb8ddcdec110c6839c6f27a8062b37dded79501920250afe", "price_changes": [{"asset_id": "96548263188568861225971459083251184634804319351377359745128053937517313229246", "price": "0.23", "size": "0", "side": "BUY", "hash": "ff9c6b5fa8aeae763be1cbc7f1538b3686b6ddd3", "best_bid": "0.01", "best_ask": "0.8"}, {"asset_id": "79287164977737814011242460177248792416483317253936439908020481835936787513608", "price": "0.77", "size": "0", "side": "SELL", "hash": "682733c68134e77ce8835c61035337d646283206", "best_bid": "0.2", "best_ask": "0.99"}], "timestamp": "1769384343426", "event_type": "price_change"}}
{"_local_timestamp": "2026-01-25T23:39:04.862112+00:00", "data": {"market": "0xdbe51bbd40ca77053fd794ac247cd2d07a150921accdd624f9f345fbc63db48b", "price_changes": [{"asset_id": "36448007855605050896824786938032039502111327633212361142790079215548046414522", "price": "0.06", "size": "0", "side": "BUY", "hash": "8e16fc91a895950b7cb9cf13f4a77cc225558a51", "best_bid": "0.04", "best_ask": "0.99"}, {"asset_id": "87345926905556212316847105466061439969543894768822947485860245095466364170902", "price": "0.94", "size": "0", "side": "SELL", "hash": "599f8ed3d8454d3182b0aa4ecc0a1ef3842bc51c", "best_bid": "0.01", "best_ask": "0.96"}], "timestamp": "1769384344768", "event_type": "price_change"}}
{"_local_timestamp": "2026-01-25T23:39:04.880241+00:00", "data": {"market": "0xdbe51bbd40ca77053fd794ac247cd2d07a150921accdd624f9f345fbc63db48b", "price_changes": [{"asset_id": "36448007855605050896824786938032039502111327633212361142790079215548046414522", "price": "0.05", "size": "5.47", "side": "BUY", "hash": "4cb643e70b8cc1d59a88ced2c7e38b0cda37ab4a", "best_bid": "0.05", "best_ask": "0.99"}, {"asset_id": "87345926905556212316847105466061439969543894768822947485860245095466364170902", "price": "0.95", "size": "5.47", "side": "SELL", "hash": "9171359c9cb8bca45c66e3eb8fa1a86c62ad5dde", "best_bid": "0.01", "best_ask": "0.95"}], "timestamp": "1769384344802", "event_type": "price_change"}}
{"_local_timestamp": "2026-01-25T23:39:33.349424+00:00", "data": {"market": "0x1feaf4097b273ee90aea00fdc5afa9ec6e14b518caf2ddbc421851bef1bdc168", "price_changes": [{"asset_id": "22033330904498269999207988435951609926608006932357150385292796096528006231715", "price": "0.2", "size": "228", "side": "BUY", "hash": "c71683189be15e933b56b141cb38bbb666a209d1", "best_bid": "0.44", "best_ask": "0.45"}, {"asset_id": "18882795016423351779855047017846676160725151167446687947380948164302842014020", "price": "0.8", "size": "228", "side": "SELL", "hash": "a2bde732198d89cfae84c61c0f7824ecb136594b", "best_bid": "0.55", "best_ask": "0.56"}], "timestamp": "1769384373283", "event_type": "price_change"}}
{"_local_timestamp": "2026-01-25T23:39:34.054396+00:00", "data": {"market": "0xdbe51bbd40ca77053fd794ac247cd2d07a150921accdd624f9f345fbc63db48b", "price_changes": [{"asset_id": "87345926905556212316847105466061439969543894768822947485860245095466364170902", "price": "0.26", "size": "38", "side": "BUY", "hash": "2e17cb6db85d43891a5e287a4719260810a69b07", "best_bid": "0.26", "best_ask": "0.95"}, {"asset_id": "36448007855605050896824786938032039502111327633212361142790079215548046414522", "price": "0.74", "size": "38", "side": "SELL", "hash": "865be340d04a742a8799c9b749bf5d22b83b2f20", "best_bid": "0.05", "best_ask": "0.74"}], "timestamp": "1769384373983", "event_type": "price_change"}}
{"_local_timestamp": "2026-01-25T23:39:34.420885+00:00", "data": {"market": "0x780c042865b2018eeb8ddcdec110c6839c6f27a8062b37dded79501920250afe", "price_changes": [{"asset_id": "96548263188568861225971459083251184634804319351377359745128053937517313229246", "price": "0.03", "size": "211", "side": "BUY", "hash": "d21ddc461499c48c57a863308740548f2be28760", "best_bid": "0.03", "best_ask": "0.8"}, {"asset_id": "79287164977737814011242460177248792416483317253936439908020481835936787513608", "price": "0.97", "size": "211", "side": "SELL", "hash": "f40b02a3c7ce283bc1fa7de64a9d3f66491a0574", "best_bid": "0.2", "best_ask": "0.97"}], "timestamp": "1769384374352", "event_type": "price_change"}}
{"_local_timestamp": "2026-01-25T23:39:37.458806+00:00", "data": {"market": "0xdbe51bbd40ca77053fd794ac247cd2d07a150921accdd624f9f345fbc63db48b", "price_changes": [{"asset_id": "87345926905556212316847105466061439969543894768822947485860245095466364170902", "price": "0.26", "size": "0", "side": "BUY", "hash": "a33d4b7172ac89cc39b3e3debba1625f35dca94a", "best_bid": "0.01", "best_ask": "0.95"}, {"asset_id": "36448007855605050896824786938032039502111327633212361142790079215548046414522", "price": "0.74", "size": "0", "side": "SELL", "hash": "bcc5a188ca4d3ec548ce64c754812eee20f6e355", "best_bid": "0.05", "best_ask": "0.99"}], "timestamp": "1769384377387", "event_type": "price_change"}}
{"_local_timestamp": "2026-01-25T23:39:42.190485+00:00", "data": {"market": "0xdbe51bbd40ca77053fd794ac247cd2d07a150921accdd624f9f345fbc63db48b", "price_changes": [{"asset_id": "36448007855605050896824786938032039502111327633212361142790079215548046414522", "price": "0.15", "size": "22", "side": "BUY", "hash": "f24fc1947728b6ea224903c5a8675f9c36d13876", "best_bid": "0.15", "best_ask": "0.99"}, {"asset_id": "87345926905556212316847105466061439969543894768822947485860245095466364170902", "price": "0.85", "size": "22", "side": "SELL", "hash": "1130337445c583793056d0bff25a32a30f7bb9b9", "best_bid": "0.01", "best_ask": "0.85"}], "timestamp": "1769384382120", "event_type": "price_change"}}
{"_local_timestamp": "2026-01-25T23:39:42.441640+00:00", "data": {"market": "0xdbe51bbd40ca77053fd794ac247cd2d07a150921accdd624f9f345fbc63db48b", "price_changes": [{"asset_id": "36448007855605050896824786938032039502111327633212361142790079215548046414522", "price": "0.15", "size": "0", "side": "BUY", "hash": "063973d996ebc2b0ce1b58c0c919cfe9f3178384", "best_bid": "0.05", "best_ask": "0.99"}, {"asset_id": "87345926905556212316847105466061439969543894768822947485860245095466364170902", "price": "0.85", "size": "0", "side": "SELL", "hash": "d9639300218dbbfc25b921cc061d2e5add6d6565", "best_bid": "0.01", "best_ask": "0.95"}], "timestamp": "1769384382377", "event_type": "price_change"}}
{"_local_timestamp": "2026-01-25T23:39:42.457526+00:00", "data": {"market": "0xdbe51bbd40ca77053fd794ac247cd2d07a150921accdd624f9f345fbc63db48b", "price_changes": [{"asset_id": "87345926905556212316847105466061439969543894768822947485860245095466364170902", "price": "0.26", "size": "43", "side": "BUY", "hash": "ecc5f889fa3e007489c73e41a337f5deaa34aabd", "best_bid": "0.26", "best_ask": "0.95"}, {"asset_id": "36448007855605050896824786938032039502111327633212361142790079215548046414522", "price": "0.74", "size": "43", "side": "SELL", "hash": "85e3c394c6d26aa4e2c93905f972daa20cb7eeed", "best_bid": "0.05", "best_ask": "0.74"}], "timestamp": "1769384382393", "event_type": "price_change"}}
{"_local_timestamp": "2026-01-25T23:39:42.646266+00:00", "data": {"market": "0xdbe51bbd40ca77053fd794ac247cd2d07a150921accdd624f9f345fbc63db48b", "price_changes": [{"asset_id": "87345926905556212316847105466061439969543894768822947485860245095466364170902", "price": "0.26", "size": "0", "side": "BUY", "hash": "596a8f6b180018340812e5f238ed4f157c5b6304", "best_bid": "0.01", "best_ask": "0.95"}, {"asset_id": "36448007855605050896824786938032039502111327633212361142790079215548046414522", "price": "0.74", "size": "0", "side": "SELL", "hash": "8521d43e016434d5d6c01342bdaaeac6d926e87d", "best_bid": "0.05", "best_ask": "0.99"}], "timestamp": "1769384382578", "event_type": "price_change"}}
{"_local_timestamp": "2026-01-25T23:39:43.582987+00:00", "data": {"market": "0xdbe51bbd40ca77053fd794ac247cd2d07a150921accdd624f9f345fbc63db48b", "price_changes": [{"asset_id": "87345926905556212316847105466061439969543894768822947485860245095466364170902", "price": "0.34", "size": "162", "side": "BUY", "hash": "3e4b807dd429a9d14b65369956f1558cb1b3ee87", "best_bid": "0.34", "best_ask": "0.95"}, {"asset_id": "36448007855605050896824786938032039502111327633212361142790079215548046414522", "price": "0.66", "size": "162", "side": "SELL", "hash": "d9602435ad47fd9a305b344eb57eec450180efae", "best_bid": "0.05", "best_ask": "0.66"}], "timestamp": "1769384383514", "event_type": "price_change"}}
{"_local_timestamp": "2026-01-25T23:39:43.890603+00:00", "data": {"market": "0xdbe51bbd40ca77053fd794ac247cd2d07a150921accdd624f9f345fbc63db48b", "price_changes": [{"asset_id": "36448007855605050896824786938032039502111327633212361142790079215548046414522", "price": "0.16", "size": "162", "side": "BUY", "hash": "963cfc3a419ba47a4eb840845e31d12c1d7c1ea8", "best_bid": "0.16", "best_ask": "0.66"}, {"asset_id": "87345926905556212316847105466061439969543894768822947485860245095466364170902", "price": "0.84", "size": "162", "side": "SELL", "hash": "fb42b1ea9a91ea7c7ed71ab4b2c6a7ec2d560d81", "best_bid": "0.34", "best_ask": "0.84"}], "timestamp": "1769384383829", "event_type": "price_change"}}
{"_local_timestamp": "2026-01-25T23:39:45.022709+00:00", "data": {"market": "0x1feaf4097b273ee90aea00fdc5afa9ec6e14b518caf2ddbc421851bef1bdc168", "price_changes": [{"asset_id": "22033330904498269999207988435951609926608006932357150385292796096528006231715", "price": "0.2", "size": "0", "side": "BUY", "hash": "1b700667c61604f522f1ec7f504d6d83f066837e", "best_bid": "0.44", "best_ask": "0.45"}, {"asset_id": "18882795016423351779855047017846676160725151167446687947380948164302842014020", "price": "0.8", "size": "0", "side": "SELL", "hash": "e2a3e3e3a21163dadac6fc730691d4856dc5fc5a", "best_bid": "0.55", "best_ask": "0.56"}], "timestamp": "1769384384956", "event_type": "price_change"}}
{"_local_timestamp": "2026-01-25T23:39:45.050563+00:00", "data": {"market": "0x1feaf4097b273ee90aea00fdc5afa9ec6e14b518caf2ddbc421851bef1bdc168", "price_changes": [{"asset_id": "22033330904498269999207988435951609926608006932357150385292796096528006231715", "price": "0.2", "size": "98", "side": "BUY", "hash": "01585e7e01a28c299f4e569bed4fb1346aa3c359", "best_bid": "0.44", "best_ask": "0.45"}, {"asset_id": "18882795016423351779855047017846676160725151167446687947380948164302842014020", "price": "0.8", "size": "98", "side": "SELL", "hash": "c55cc7de473c653a8dc995adf6a482cf33e306c5", "best_bid": "0.55", "best_ask": "0.56"}], "timestamp": "1769384384983", "event_type": "price_change"}}
{"_local_timestamp": "2026-01-25T23:39:45.075293+00:00", "data": {"market": "0x1feaf4097b273ee90aea00fdc5afa9ec6e14b518caf2ddbc421851bef1bdc168", "price_changes": [{"asset_id": "22033330904498269999207988435951609926608006932357150385292796096528006231715", "price": "0.2", "size": "0", "side": "BUY", "hash": "3548f9ec56d1a668b4165e1b24e695d2970171fa", "best_bid": "0.44", "best_ask": "0.45"}, {"asset_id": "18882795016423351779855047017846676160725151167446687947380948164302842014020", "price": "0.8", "size": "0", "side": "SELL", "hash": "bca3a8f3a4b846cf01d63807be1a37e4517216a0", "best_bid": "0.55", "best_ask": "0.56"}], "timestamp": "1769384385008", "event_type": "price_change"}}
{"_local_timestamp": "2026-01-25T23:39:45.450193+00:00", "data": {"market": "0x1feaf4097b273ee90aea00fdc5afa9ec6e14b518caf2ddbc421851bef1bdc168", "price_changes": [{"asset_id": "22033330904498269999207988435951609926608006932357150385292796096528006231715", "price": "0.19", "size": "177", "side": "BUY", "hash": "7b1c29e4349f787f00d332886af44b6748374319", "best_bid": "0.44", "best_ask": "0.45"}, {"asset_id": "18882795016423351779855047017846676160725151167446687947380948164302842014020", "price": "0.81", "size": "177", "side": "SELL", "hash": "ca25a375d1f11c91c50db14c2df1acd8166d5707", "best_bid": "0.55", "best_ask": "0.56"}], "timestamp": "1769384385381", "event_type": "price_change"}}
{"_local_timestamp": "2026-01-25T23:39:46.051760+00:00", "data": {"market": "0x1feaf4097b273ee90aea00fdc5afa9ec6e14b518caf2ddbc421851bef1bdc168", "price_changes": [{"asset_id": "22033330904498269999207988435951609926608006932357150385292796096528006231715", "price": "0.19", "size": "0", "side": "BUY", "hash": "023f07595f7f13e93c0ebb25b6efdf58a186958b", "best_bid": "0.44", "best_ask": "0.45"}, {"asset_id": "18882795016423351779855047017846676160725151167446687947380948164302842014020", "price": "0.81", "size": "0", "side": "SELL", "hash": "c889c6eacae4de6b52f608b98891a84b59b29f62", "best_bid": "0.55", "best_ask": "0.56"}], "timestamp": "1769384385979", "event_type": "price_change"}}
{"_local_timestamp": "2026-01-25T23:39:50.170117+00:00", "data": {"market": "0x1feaf4097b273ee90aea00fdc5afa9ec6e14b518caf2ddbc421851bef1bdc168", "price_changes": [{"asset_id": "22033330904498269999207988435951609926608006932357150385292796096528006231715", "price": "0.2", "size": "195", "side": "BUY", "hash": "186690d6dd63ec91299d238e0b9aff2db1c1b5bf", "best_bid": "0.44", "best_ask": "0.45"}, {"asset_id": "18882795016423351779855047017846676160725151167446687947380948164302842014020", "price": "0.8", "size": "195", "side": "SELL", "hash": "f1a7bb5e03427bb955f4c868f0e020b569500fe3", "best_bid": "0.55", "best_ask": "0.56"}], "timestamp": "1769384390104", "event_type": "price_change"}}
{"_local_timestamp": "2026-01-25T23:40:03.104552+00:00", "data": {"market": "0x780c042865b2018eeb8ddcdec110c6839c6f27a8062b37dded79501920250afe", "price_changes": [{"asset_id": "79287164977737814011242460177248792416483317253936439908020481835936787513608", "price": "0.2", "size": "164.45", "side": "BUY", "hash": "1aa1b4c362671bf6f5e8c74df1f392d4beb02d6e", "best_bid": "0.2", "best_ask": "0.97"}, {"asset_id": "96548263188568861225971459083251184634804319351377359745128053937517313229246", "price": "0.8", "size": "164.45", "side": "SELL", "hash": "7e10e7f945a3b907cf4ce057b31660840159098f", "best_bid": "0.03", "best_ask": "0.8"}], "timestamp": "1769384403005", "event_type": "price_change"}}
{"_local_timestamp": "2026-01-25T23:40:03.105394+00:00", "data": {"market": "0x780c042865b2018eeb8ddcdec110c6839c6f27a8062b37dded79501920250afe", "asset_id": "79287164977737814011242460177248792416483317253936439908020481835936787513608", "price": "0.2", "size": "5.55", "fee_rate_bps": "0", "side": "SELL", "timestamp": "1769384403033", "event_type": "last_trade_price", "transaction_hash": "0x2d7d03f8bd5bc4b3e2393b4b9dbd9f5369ce2e37a722d71ade925791fdc3c706"}}
{"_local_timestamp": "2026-01-25T23:40:03.105956+00:00", "data": {"market": "0x780c042865b2018eeb8ddcdec110c6839c6f27a8062b37dded79501920250afe", "asset_id": "79287164977737814011242460177248792416483317253936439908020481835936787513608", "bids": [{"price": "0.01", "size": "100"}, {"price": "0.02", "size": "33.33"}, {"price": "0.03", "size": "38.47"}, {"price": "0.2", "size": "164.45"}], "asks": [{"price": "0.99", "size": "200"}, {"price": "0.97", "size": "211"}], "hash": "1aa1b4c362671bf6f5e8c74df1f392d4beb02d6e", "timestamp": "1769384403005", "event_type": "book"}}
{"_local_timestamp": "2026-01-25T23:40:03.106533+00:00", "data": {"market": "0x780c042865b2018eeb8ddcdec110c6839c6f27a8062b37dded79501920250afe", "asset_id": "96548263188568861225971459083251184634804319351377359745128053937517313229246", "bids": [{"price": "0.01", "size": "200"}, {"price": "0.03", "size": "211"}], "asks": [{"price": "0.99", "size": "100"}, {"price": "0.98", "size": "33.33"}, {"price": "0.97", "size": "38.47"}, {"price": "0.8", "size": "164.45"}], "hash": "7e10e7f945a3b907cf4ce057b31660840159098f", "timestamp": "1769384403005", "event_type": "book"}}
