{"_local_timestamp": "2026-01-25T23:40:39.041144+00:00", "data": [{"market": "0x08e4cea3c55ded3bb7d1ab771bb6c14d3963fac75fefd5b59c4f52dce6019a62", "asset_id": "71154843059994247237624760034811568192562173240459827423146270067147035272157", "timestamp": "1769384433126", "hash": "aaf03073d33b746f9d7911b4a62e96f8d126ae61", "bids": [{"price": "0.01", "size": "12.6"}, {"price": "0.02", "size": "20"}, {"price": "0.03", "size": "15.29"}, {"price": "0.04", "size": "305"}, {"price": "0.05", "size": "10.2"}, {"price": "0.06", "size": "150.33"}, {"price": "0.07", "size": "12.92"}, {"price": "0.08", "size": "55"}, {"price": "0.09", "size": "106.19"}, {"price": "0.1", "size": "260.99"}, {"price": "0.11", "size": "275"}, {"price": "0.12", "size": "933.33"}], "asks": [{"price": "0.99", "size": "8809.74"}, {"price": "0.98", "size": "2200"}, {"price": "0.97", "size": "9.1"}, {"price": "0.95", "size": "30"}, {"price": "0.94", "size": "33"}, {"price": "0.93", "size": "500"}, {"price": "0.91", "size": "900"}, {"price": "0.9", "size": "6.29"}, {"price": "0.86", "size": "242.85"}, {"price": "0.85", "size": "550"}, {"price": "0.84", "size": "1450"}, {"price": "0.82", "size": "177.77"}, {"price": "0.79", "size": "760"}, {"price": "0.78", "size": "2058"}, {"price": "0.77", "size": "121.73"}, {"price": "0.73", "size": "96.29"}, {"price": "0.71", "size": "3366"}, {"price": "0.69", "size": "400"}, {"price": "0.68", "size": "300"}, {"price": "0.64", "size": "180.55"}, {"price": "0.61", "size": "8.55"}, {"price": "0.54", "size": "10"}, {"price": "0.52", "size": "10"}, {"price": "0.37", "size": "245"}, {"price": "0.36", "size": "100"}, {"price": "0.25", "size": "200"}, {"price": "0.15", "size": "325"}, {"price": "0.14", "size": "50"}, {"price": "0.13", "size": "5.53"}], "event_type": "book", "last_trade_price": ""}, {"market": "0x29271437572fd58353539701b2f2d7717cb27098be8f2d61ac68097ee1a904e2", "asset_id": "102979187600939812579181707251830214545859759571297676718971996931510245907237", "timestamp": "1769384431896", "hash": "b6f879270bd88ae6da5f855987bbf10bfa81419e", "bids": [{"price": "0.01", "size": "3000"}, {"price": "0.02", "size": "269.77"}, {"price": "0.03", "size": "20.14"}, {"price": "0.05", "size": "300"}, {"price": "0.06", "size": "305"}, {"price": "0.07", "size": "1428.49"}], "asks": [{"price": "0.99", "size": "5516.05"}, {"price": "0.98", "size": "2200"}, {"price": "0.97", "size": "9.5"}, {"price": "0.95", "size": "30"}, {"price": "0.94", "size": "33"}, {"price": "0.93", "size": "6.41"}, {"price": "0.91", "size": "1200"}, {"price": "0.86", "size": "842.85"}, {"price": "0.85", "size": "7.37"}, {"price": "0.81", "size": "168.42"}, {"price": "0.8", "size": "400"}, {"price": "0.78", "size": "776"}, {"price": "0.77", "size": "2047.73"}, {"price": "0.72", "size": "92.85"}, {"price": "0.71", "size": "200"}, {"price": "0.67", "size": "72.72"}, {"price": "0.66", "size": "1764"}, {"price": "0.65", "size": "4070"}, {"price": "0.64", "size": "300"}, {"price": "0.63", "size": "129.05"}, {"price": "0.53", "size": "5"}, {"price": "0.25", "size": "100"}, {"price": "0.24", "size": "20"}, {"price": "0.14", "size": "365.83"}, {"price": "0.11", "size": "200"}, {"price": "0.1", "size": "160"}, {"price": "0.09", "size": "361.61"}, {"price": "0.08", "size": "255.1"}], "event_type": "book", "last_trade_price": ""}, {"market": "0x29271437572fd58353539701b2f2d7717cb27098be8f2d61ac68097ee1a904e2", "asset_id": "102079907506920911172638618936058182844332853810504026717141669988902032059766", "timestamp": "1769384431896", "hash": "bc9e371603fcd9dcf08733293ccf0678a5a4f73e", "bids": [{"price": "0.01", "size": "5516.05"}, {"price": "0.02", "size": "2200"}, {"price": "0.03", "size": "9.5"}, {"price": "0.05", "size": "30"}, {"price": "0.06", "size": "33"}, {"price": "0.07", "size": "6.41"}, {"price": "0.09", "size": "1200"}, {"price": "0.14", "size": "842.85"}, {"price": "0.15", "size": "7.37"}, {"price": "0.19", "size": "168.42"}, {"price": "0.2", "size": "400"}, {"price": "0.22", "size": "776"}, {"price": "0.23", "size": "2047.73"}, {"price": "0.28", "size": "92.85"}, {"price": "0.29", "size": "200"}, {"price": "0.33", "size": "72.72"}, {"price": "0.34", "size": "1764"}, {"price": "0.35", "size": "4070"}, {"price": "0.36", "size": "300"}, {"price": "0.37", "size": "129.05"}, {"price": "0.47", "size": "5"}, {"price": "0.75", "size": "100"}, {"price": "0.76", "size": "20"}, {"price": "0.86", "size": "365.83"}, {"price": "0.89", "size": "200"}, {"price": "0.9", "size": "160"}, {"price": "0.91", "size": "361.61"}, {"price": "0.92", "size": "255.1"}], "asks": [{"price": "0.99", "size": "3000"}, {"price": "0.98", "size": "269.77"}, {"price": "0.97", "size": "20.14"}, {"price": "0.95", "size": "300"}, {"price": "0.94", "size": "305"}, {"price": "0.93", "size": "1428.49"}], "event_type": "book", "last_trade_price": ""}, {"market": "0x08e4cea3c55ded3bb7d1ab771bb6c14d3963fac75fefd5b59c4f52dce6019a62", "asset_id": "108394778822564022837882134264212554176350354267790900487346083741419834749031", "timestamp": "1769384433126", "hash": "c78db1a6006bc0fdec9edf86e8b743c7ede57bcf", "bids": [{"price": "0.01", "size": "8809.74"}, {"price": "0.02", "size": "2200"}, {"price": "0.03", "size": "9.1"}, {"price": "0.05", "size": "30"}, {"price": "0.06", "size": "33"}, {"price": "0.07", "size": "500"}, {"price": "0.09", "size": "900"}, {"price": "0.1", "size": "6.29"}, {"price": "0.14", "size": "242.85"}, {"price": "0.15", "size": "550"}, {"price": "0.16", "size": "1450"}, {"price": "0.18", "size": "177.77"}, {"price": "0.21", "size": "760"}, {"price": "0.22", "size": "2058"}, {"price": "0.23", "size": "121.73"}, {"price": "0.27", "size": "96.29"}, {"price": "0.29", "size": "3366"}, {"price": "0.31", "size": "400"}, {"price": "0.32", "size": "300"}, {"price": "0.36", "size": "180.55"}, {"price": "0.39", "size": "8.55"}, {"price": "0.46", "size": "10"}, {"price": "0.48", "size": "10"}, {"price": "0.63", "size": "245"}, {"price": "0.64", "size": "100"}, {"price": "0.75", "size": "200"}, {"price": "0.85", "size": "325"}, {"price": "0.86", "size": "50"}, {"price": "0.87", "size": "5.53"}], "asks": [{"price": "0.99", "size": "12.6"}, {"price": "0.98", "size": "20"}, {"price": "0.97", "size": "15.29"}, {"price": "0.96", "size": "305"}, {"price": "0.95", "size": "10.2"}, {"price": "0.94", "size": "150.33"}, {"price": "0.93", "size": "12.92"}, {"price": "0.92", "size": "55"}, {"price": "0.91", "size": "106.19"}, {"price": "0.9", "size": "260.99"}, {"price": "0.89", "size": "275"}, {"price": "0.88", "size": "933.33"}], "event_type": "book", "last_trade_price": ""}]}
{"_local_timestamp": "2026-01-25T23:41:06.442095+00:00", "data": {"market": "0x29271437572fd58353539701b2f2d7717cb27098be8f2d61ac68097ee1a904e2", "price_changes": [{"asset_id": "102079907506920911172638618936058182844332853810504026717141669988902032059766", "price": "0.9", "size": "110", "side": "BUY", "hash": "4f9988140f39331fc10cab4378995cd6a9d24544", "best_bid": "0.92", "best_ask": "0.93"}, {"asset_id": "102979187600939812579181707251830214545859759571297676718971996931510245907237", "price": "0.1", "size": "110", "side": "SELL", "hash": "671ca872981b9e015c2f94f7fde2497b9548be90", "best_bid": "0.07", "best_ask": "0.08"}], "timestamp": "1769384466195", "event_type": "price_change"}}
{"_local_timestamp": "2026-01-25T23:41:06.546760+00:00", "data": {"market": "0x29271437572fd58353539701b2f2d7717cb27098be8f2d61ac68097ee1a904e2", "price_changes": [{"asset_id": "102979187600939812579181707251830214545859759571297676718971996931510245907237", "price": "0.05", "size": "250", "side": "BUY", "hash": "90e767b63fa66c03134571b59918a7ffc4b94e11", "best_bid": "0.07", "best_ask": "0.08"}, {"asset_id": "102079907506920911172638618936058182844332853810504026717141669988902032059766", "price": "0.95", "size": "250", "side": "SELL", "hash": "2f7ee6e3cba930c809f216b7ae350868347d720d", "best_bid": "0.92", "best_ask": "0.93"}], "timestamp": "1769384466196", "event_type": "price_change"}}
{"_local_timestamp": "2026-01-25T23:41:09.782707+00:00", "data": {"market": "0x29271437572fd58353539701b2f2d7717cb27098be8f2d61ac68097ee1a904e2", "price_changes": [{"asset_id": "102079907506920911172638618936058182844332853810504026717141669988902032059766", "price": "0.9", "size": "160", "side": "BUY", "hash": "6f4922573b701171ec9d624094e5dd7422644a70", "best_bid": "0.92", "best_ask": "0.93"}, {"asset_id": "102979187600939812579181707251830214545859759571297676718971996931510245907237", "price": "0.1", "size": "160", "side": "SELL", "hash": "33fa1c03051b5b975786864e42b2c380c8f3ca04", "best_bid": "0.07", "best_ask": "0.08"}], "timestamp": "1769384469696", "event_type": "price_change"}}
{"_local_timestamp": "2026-01-25T23:41:11.251209+00:00", "data": {"market": "0x29271437572fd58353539701b2f2d7717cb27098be8f2d61ac68097ee1a904e2", "price_changes": [{"asset_id": "102979187600939812579181707251830214545859759571297676718971996931510245907237", "price": "0.05", "size": "300", "side": "BUY", "hash": "41d0c2f19e179bc81214b52b8910d73171f51a0f", "best_bid": "0.07", "best_ask": "0.08"}, {"asset_id": "102079907506920911172638618936058182844332853810504026717141669988902032059766", "price": "0.95", "size": "300", "side": "SELL", "hash": "e5f023bc8350149d30fa8dbcb1d5ae547362e0d8", "best_bid": "0.92", "best_ask": "0.93"}], "timestamp": "1769384471093", "event_type": "price_change"}}
{"_local_timestamp": "2026-01-25T23:41:50.917393+00:00", "data": {"market": "0x29271437572fd58353539701b2f2d7717cb27098be8f2d61ac68097ee1a904e2", "price_changes": [{"asset_id": "102079907506920911172638618936058182844332853810504026717141669988902032059766", "price": "0.29", "size": "100", "side": "BUY", "hash": "b44ebc522ea354d1360429c62761f800b9300688", "best_bid": "0.92", "best_ask": "0.93"}, {"asset_id": "102979187600939812579181707251830214545859759571297676718971996931510245907237", "price": "0.71", "size": "100", "side": "SELL", "hash": "5ef54460303542eaa79681ac0806eddef047b33a", "best_bid": "0.07", "best_ask": "0.08"}], "timestamp": "1769384510757", "event_type": "price_change"}}
{"_local_timestamp": "2026-01-25T23:41:52.894530+00:00", "data": {"market": "0x29271437572fd58353539701b2f2d7717cb27098be8f2d61ac68097ee1a904e2", "price_changes": [{"asset_id": "102079907506920911172638618936058182844332853810504026717141669988902032059766", "price": "0.23", "size": "2147.73", "side": "BUY", "hash": "f2e8e1808812694691fa4064edb21d558b651c93", "best_bid": "0.92", "best_ask": "0.93"}, {"asset_id": "102979187600939812579181707251830214545859759571297676718971996931510245907237", "price": "0.77", "size": "2147.73", "side": "SELL", "hash": "c936a20ac7ffe86ecc9fdf5720cec768b0793c4a", "best_bid": "0.07", "best_ask": "0.08"}], "timestamp": "1769384511843", "event_type": "price_change"}}
{"_local_timestamp": "2026-01-25T23:42:07.624877+00:00", "data": {"market": "0x08e4cea3c55ded3bb7d1ab771bb6c14d3963fac75fefd5b59c4f52dce6019a62", "price_changes": [{"asset_id": "71154843059994247237624760034811568192562173240459827423146270067147035272157", "price": "0.05", "size": "0", "side": "BUY", "hash": "511403ccff721703a85c3239cd5c9bdecd33bf6d", "best_bid": "0.12", "best_ask": "0.13"}, {"asset_id": "108394778822564022837882134264212554176350354267790900487346083741419834749031", "price": "0.95", "size": "0", "side": "SELL", "hash": "d70ab612b4b4f440d3756d7508b5d52f042880ba", "best_bid": "0.87", "best_ask": "0.88"}], "timestamp": "1769384527540", "event_type": "price_change"}}
{"_local_timestamp": "2026-01-25T23:42:07.637825+00:00", "data": {"market": "0x08e4cea3c55ded3bb7d1ab771bb6c14d3963fac75fefd5b59c4f52dce6019a62", "price_changes": [{"asset_id": "71154843059994247237624760034811568192562173240459827423146270067147035272157", "price": "0.07", "size": "0", "side": "BUY", "hash": "511403ccff721703a85c3239cd5c9bdecd33bf6d", "best_bid": "0.12", "best_ask": "0.13"}, {"asset_id": "108394778822564022837882134264212554176350354267790900487346083741419834749031", "price": "0.93", "size": "0", "side": "SELL", "hash": "d70ab612b4b4f440d3756d7508b5d52f042880ba", "best_bid": "0.87", "best_ask": "0.88"}], "timestamp": "1769384527540", "event_type": "price_change"}}
{"_local_timestamp": "2026-01-25T23:42:09.891521+00:00", "data": {"market": "0x08e4cea3c55ded3bb7d1ab771bb6c14d3963fac75fefd5b59c4f52dce6019a62", "price_changes": [{"asset_id": "71154843059994247237624760034811568192562173240459827423146270067147035272157", "price": "0.08", "size": "64.58", "side": "BUY", "hash": "397f7a89c61f2ad1ceda445a6975c4017e53051b", "best_bid": "0.12", "best_ask": "0.13"}, {"asset_id": "108394778822564022837882134264212554176350354267790900487346083741419834749031", "price": "0.92", "size": "64.58", "side": "SELL", "hash": "44da1f7daba1894e199e6197b5059948edd2bb74", "best_bid": "0.87", "best_ask": "0.88"}], "timestamp": "1769384529813", "event_type": "price_change"}}
{"_local_timestamp": "2026-01-25T23:42:09.892764+00:00", "data": {"market": "0x08e4cea3c55ded3bb7d1ab771bb6c14d3963fac75fefd5b59c4f52dce6019a62", "price_changes": [{"asset_id": "71154843059994247237624760034811568192562173240459827423146270067147035272157", "price": "0.01", "size": "20.9", "side": "BUY", "hash": "4ba4da4ba7989018f277e1b202ad2f0abdd9bb06", "best_bid": "0.12", "best_ask": "0.13"}, {"asset_id": "108394778822564022837882134264212554176350354267790900487346083741419834749031", "price": "0.99", "size": "20.9", "side": "SELL", "hash": "3ddb0d2741a288fd723151aa80bff1bb8c7e3529", "best_bid": "0.87", "best_ask": "0.88"}], "timestamp": "1769384529814", "event_type": "price_change"}}
{"_local_timestamp": "2026-01-25T23:42:09.893856+00:00", "data": {"market": "0x08e4cea3c55ded3bb7d1ab771bb6c14d3963fac75fefd5b59c4f52dce6019a62", "price_changes": [{"asset_id": "71154843059994247237624760034811568192562173240459827423146270067147035272157", "price": "0.06", "size": "159.75", "side": "BUY", "hash": "0c0c5fbc4d00b6546b6247652be9d294481e2ed8", "best_bid": "0.12", "best_ask": "0.13"}, {"asset_id": "108394778822564022837882134264212554176350354267790900487346083741419834749031", "price": "0.94", "size": "159.75", "side": "SELL", "hash": "9c0495b1991f9d74df823f35b6b6853a6a9278d4", "best_bid": "0.87", "best_ask": "0.88"}], "timestamp": "1769384529815", "event_type": "price_change"}}
{"_local_timestamp": "2026-01-25T23:42:24.957460+00:00", "data": {"market": "0x29271437572fd58353539701b2f2d7717cb27098be8f2d61ac68097ee1a904e2", "price_changes": [{"asset_id": "102079907506920911172638618936058182844332853810504026717141669988902032059766", "price": "0.29", "size": "50", "side": "BUY", "hash": "3f512f474f7c11190f6d083e5b0755943ee5b07d", "best_bid": "0.92", "best_ask": "0.93"}, {"asset_id": "102979187600939812579181707251830214545859759571297676718971996931510245907237", "price": "0.71", "size": "50", "side": "SELL", "hash": "133df85c0d9cfa31bcdf23885eca1aa0aa85fe4f", "best_bid": "0.07", "best_ask": "0.08"}], "timestamp": "1769384544880", "event_type": "price_change"}}
{"_local_timestamp": "2026-01-25T23:42:25.233042+00:00", "data": {"market": "0x29271437572fd58353539701b2f2d7717cb27098be8f2d61ac68097ee1a904e2", "price_changes": [{"asset_id": "102079907506920911172638618936058182844332853810504026717141669988902032059766", "price": "0.28", "size": "142.85", "side": "BUY", "hash": "53a74fb9cb5889521d37c3802cc0fce22dc21516", "best_bid": "0.92", "best_ask": "0.93"}, {"asset_id": "102979187600939812579181707251830214545859759571297676718971996931510245907237", "price": "0.72", "size": "142.85", "side": "SELL", "hash": "209a9883c9dc9290a0e2d643214672effa2b150b", "best_bid": "0.07", "best_ask": "0.08"}], "timestamp": "1769384545151", "event_type": "price_change"}}
{"_local_timestamp": "2026-01-25T23:42:30.474481+00:00", "data": {"market": "0x29271437572fd58353539701b2f2d7717cb27098be8f2d61ac68097ee1a904e2", "price_changes": [{"asset_id": "102979187600939812579181707251830214545859759571297676718971996931510245907237", "price": "0.02", "size": "250", "side": "BUY", "hash": "a08d19fb5e9af765016c0c343662e6256adbcb50", "best_bid": "0.07", "best_ask": "0.08"}, {"asset_id": "102079907506920911172638618936058182844332853810504026717141669988902032059766", "price": "0.98", "size": "250", "side": "SELL", "hash": "f23df697407d26924a0d8fa90dfccdcb3c7a7562", "best_bid": "0.92", "best_ask": "0.93"}], "timestamp": "1769384550404", "event_type": "price_change"}}
{"_local_timestamp": "2026-01-25T23:42:30.474840+00:00", "data": {"market": "0x29271437572fd58353539701b2f2d7717cb27098be8f2d61ac68097ee1a904e2", "price_changes": [{"asset_id": "102979187600939812579181707251830214545859759571297676718971996931510245907237", "price": "0.03", "size": "7.93", "side": "BUY", "hash": "a08d19fb5e9af765016c0c343662e6256adbcb50", "best_bid": "0.07", "best_ask": "0.08"}, {"asset_id": "102079907506920911172638618936058182844332853810504026717141669988902032059766", "price": "0.97", "size": "7.93", "side": "SELL", "hash": "f23df697407d26924a0d8fa90dfccdcb3c7a7562", "best_bid": "0.92", "best_ask": "0.93"}], "timestamp": "1769384550404", "event_type": "price_change"}}
{"_local_timestamp": "2026-01-25T23:42:32.865425+00:00", "data": {"market": "0x29271437572fd58353539701b2f2d7717cb27098be8f2d61ac68097ee1a904e2", "price_changes": [{"asset_id": "102979187600939812579181707251830214545859759571297676718971996931510245907237", "price": "0.03", "size": "20.14", "side": "BUY", "hash": "db6a4fa2b469b6c573898594d9ea2d2b0e1257c5", "best_bid": "0.07", "best_ask": "0.08"}, {"asset_id": "102079907506920911172638618936058182844332853810504026717141669988902032059766", "price": "0.97", "size": "20.14", "side": "SELL", "hash": "b0a5292c6f07ccc1b44b5221c9d0b8ade68bec76", "best_bid": "0.92", "best_ask": "0.93"}], "timestamp": "1769384552799", "event_type": "price_change"}}
{"_local_timestamp": "2026-01-25T23:42:32.865827+00:00", "data": {"market": "0x29271437572fd58353539701b2f2d7717cb27098be8f2d61ac68097ee1a904e2", "price_changes": [{"asset_id": "102979187600939812579181707251830214545859759571297676718971996931510245907237", "price": "0.02", "size": "269.77", "side": "BUY", "hash": "bf137cf1ec237c145d68a41e3bf418fe929ab756", "best_bid": "0.07", "best_ask": "0.08"}, {"asset_id": "102079907506920911172638618936058182844332853810504026717141669988902032059766", "price": "0.98", "size": "269.77", "side": "SELL", "hash": "44f78a7b981fbeec997c4027bb54f9d6826595e2", "best_bid": "0.92", "best_ask": "0.93"}], "timestamp": "1769384552800", "event_type": "price_change"}}
{"_local_timestamp": "2026-01-25T23:42:45.395522+00:00", "data": {"market": "0x29271437572fd58353539701b2f2d7717cb27098be8f2d61ac68097ee1a904e2", "price_changes": [{"asset_id": "102079907506920911172638618936058182844332853810504026717141669988902032059766", "price": "0.22", "size": "726", "side": "BUY", "hash": "bfbffc5064fc0463df786b956fb81b52ecf7fc3d", "best_bid": "0.92", "best_ask": "0.93"}, {"asset_id": "102979187600939812579181707251830214545859759571297676718971996931510245907237", "price": "0.78", "size": "726", "side": "SELL", "hash": "d78caac876b1da5e35b75ce35ac9f3bdbcc5aca7", "best_bid": "0.07", "best_ask": "0.08"}], "timestamp": "1769384565210", "event_type": "price_change"}}
{"_local_timestamp": "2026-01-25T23:42:45.831922+00:00", "data": {"market": "0x29271437572fd58353539701b2f2d7717cb27098be8f2d61ac68097ee1a904e2", "price_changes": [{"asset_id": "102079907506920911172638618936058182844332853810504026717141669988902032059766", "price": "0.23", "size": "2197.73", "side": "BUY", "hash": "7fafa4fb4336129511ce08d0b5f73456fcde9a67", "best_bid": "0.92", "best_ask": "0.93"}, {"asset_id": "102979187600939812579181707251830214545859759571297676718971996931510245907237", "price": "0.77", "size": "2197.73", "side": "SELL", "hash": "c881be4c117807dd30f61f97fd5d1024453b79ce", "best_bid": "0.07", "best_ask": "0.08"}], "timestamp": "1769384565618", "event_type": "price_change"}}
{"_local_timestamp": "2026-01-25T23:43:06.203083+00:00", "data": {"market": "0x29271437572fd58353539701b2f2d7717cb27098be8f2d61ac68097ee1a904e2", "price_changes": [{"asset_id": "102979187600939812579181707251830214545859759571297676718971996931510245907237", "price": "0.06", "size": "255", "side": "BUY", "hash": "18f3ec66d56cd82f712715e5412b06a515cb17d5", "best_bid": "0.07", "best_ask": "0.08"}, {"asset_id": "102079907506920911172638618936058182844332853810504026717141669988902032059766", "price": "0.94", "size": "255", "side": "SELL", "hash": "9f5da2b99e31b4e2e30fa3fe3349693199eb98c2", "best_bid": "0.92", "best_ask": "0.93"}], "timestamp": "1769384586000", "event_type": "price_change"}}
{"_local_timestamp": "2026-01-25T23:43:06.209118+00:00", "data": {"market": "0x29271437572fd58353539701b2f2d7717cb27098be8f2d61ac68097ee1a904e2", "price_changes": [{"asset_id": "102079907506920911172638618936058182844332853810504026717141669988902032059766", "price": "0.91", "size": "311.61", "side": "BUY", "hash": "7dbce660add891b847efd55d2b1ac5cb2120f647", "best_bid": "0.92", "best_ask": "0.93"}, {"asset_id": "102979187600939812579181707251830214545859759571297676718971996931510245907237", "price": "0.09", "size": "311.61", "side": "SELL", "hash": "89dc2cc0c5c61441a2bc7128f7a7131b16e5d55b", "best_bid": "0.07", "best_ask": "0.08"}], "timestamp": "1769384586001", "event_type": "price_change"}}
{"_local_timestamp": "2026-01-25T23:43:12.931802+00:00", "data": {"market": "0x08e4cea3c55ded3bb7d1ab771bb6c14d3963fac75fefd5b59c4f52dce6019a62", "price_changes": [{"asset_id": "71154843059994247237624760034811568192562173240459827423146270067147035272157", "price": "0.61", "size": "0", "side": "SELL", "hash": "d1bfac3be8c0d34dc781cae45ef9940af2351568", "best_bid": "0.12", "best_ask": "0.13"}, {"asset_id": "108394778822564022837882134264212554176350354267790900487346083741419834749031", "price": "0.39", "size": "0", "side": "BUY", "hash": "e56d47126aeaade5127c4f96fd8b1a467e51d5da", "best_bid": "0.87", "best_ask": "0.88"}], "timestamp": "1769384592867", "event_type": "price_change"}}
{"_local_timestamp": "2026-01-25T23:43:13.414496+00:00", "data": {"market": "0x08e4cea3c55ded3bb7d1ab771bb6c14d3963fac75fefd5b59c4f52dce6019a62", "price_changes": [{"asset_id": "71154843059994247237624760034811568192562173240459827423146270067147035272157", "price": "0.14", "size": "58.55", "side": "SELL", "hash": "d5cb4fa067f371fafed80e6a5bbcdd003d98bd85", "best_bid": "0.12", "best_ask": "0.13"}, {"asset_id": "108394778822564022837882134264212554176350354267790900487346083741419834749031", "price": "0.86", "size": "58.55", "side": "BUY", "hash": "5956eb416e26bb15e382f7637523cb6a32e3bb64", "best_bid": "0.87", "best_ask": "0.88"}], "timestamp": "1769384593150", "event_type": "price_change"}}
{"_local_timestamp": "2026-01-25T23:43:22.080595+00:00", "data": {"market": "0x08e4cea3c55ded3bb7d1ab771bb6c14d3963fac75fefd5b59c4f52dce6019a62", "price_changes": [{"asset_id": "71154843059994247237624760034811568192562173240459827423146270067147035272157", "price": "0.12", "size": "883.33", "side": "BUY", "hash": "c6ef9ae44d3fd7dfe50f9e715c17f11a0e5d4981", "best_bid": "0.12", "best_ask": "0.13"}, {"asset_id": "108394778822564022837882134264212554176350354267790900487346083741419834749031", "price": "0.88", "size": "883.33", "side": "SELL", "hash": "e7b6ba4da7ebee7359661a90acfec80628b3f59f", "best_bid": "0.87", "best_ask": "0.88"}], "timestamp": "1769384602000", "event_type": "price_change"}}
{"_local_timestamp": "2026-01-25T23:44:29.006764+00:00", "data": {"market": "0x29271437572fd58353539701b2f2d7717cb27098be8f2d61ac68097ee1a904e2", "price_changes": [{"asset_id": "102079907506920911172638618936058182844332853810504026717141669988902032059766", "price": "0.91", "size": "361.61", "side": "BUY", "hash": "851200445115975cc2812a6d947281a5b81e9656", "best_bid": "0.92", "best_ask": "0.93"}, {"asset_id": "102979187600939812579181707251830214545859759571297676718971996931510245907237", "price": "0.09", "size": "361.61", "side": "SELL", "hash": "db9eebccc1a3edf7981355d73f88f0be001a0c7c", "best_bid": "0.07", "best_ask": "0.08"}], "timestamp": "1769384668937", "event_type": "price_change"}}
{"_local_timestamp": "2026-01-25T23:44:29.007696+00:00", "data": {"market": "0x29271437572fd58353539701b2f2d7717cb27098be8f2d61ac68097ee1a904e2", "price_changes": [{"asset_id": "102979187600939812579181707251830214545859759571297676718971996931510245907237", "price": "0.06", "size": "305", "side": "BUY", "hash": "5dad6f63a253d80f1c2ad4eec8c9419ad3e08c1d", "best_bid": "0.07", "best_ask": "0.08"}, {"asset_id": "102079907506920911172638618936058182844332853810504026717141669988902032059766", "price": "0.94", "size": "305", "side": "SELL", "hash": "80c23dc72275bb6e47ed22520fc2d485a9e3bd2c", "best_bid": "0.92", "best_ask": "0.93"}], "timestamp": "1769384668937", "event_type": "price_change"}}
{"_local_timestamp": "2026-01-25T23:44:57.717652+00:00", "data": {"market": "0x29271437572fd58353539701b2f2d7717cb27098be8f2d61ac68097ee1a904e2", "price_changes": [{"asset_id": "102079907506920911172638618936058182844332853810504026717141669988902032059766", "price": "0.29", "size": "0", "side": "BUY", "hash": "9b03300d78863bcb11b3a1ad8830b1b571b6c77d", "best_bid": "0.92", "best_ask": "0.93"}, {"asset_id": "102979187600939812579181707251830214545859759571297676718971996931510245907237", "price": "0.71", "size": "0", "side": "SELL", "hash": "2bace5f202bcd62dcd7d299ce6b9071802111176", "best_bid": "0.07", "best_ask": "0.08"}], "timestamp": "1769384697644", "event_type": "price_change"}}
{"_local_timestamp": "2026-01-25T23:44:58.336475+00:00", "data": {"market": "0x29271437572fd58353539701b2f2d7717cb27098be8f2d61ac68097ee1a904e2", "price_changes": [{"asset_id": "102079907506920911172638618936058182844332853810504026717141669988902032059766", "price": "0.28", "size": "192.85", "side": "BUY", "hash": "82acde10b6ee739a3b29da8dc4975ded10e760da", "best_bid": "0.92", "best_ask": "0.93"}, {"asset_id": "102979187600939812579181707251830214545859759571297676718971996931510245907237", "price": "0.72", "size": "192.85", "side": "SELL", "hash": "ed8fa5705e1ba20e40a9fceec3c54a3e5d84074e", "best_bid": "0.07", "best_ask": "0.08"}], "timestamp": "1769384698221", "event_type": "price_change"}}
{"_local_timestamp": "2026-01-25T23:45:22.866535+00:00", "data": {"market": "0x08e4cea3c55ded3bb7d1ab771bb6c14d3963fac75fefd5b59c4f52dce6019a62", "price_changes": [{"asset_id": "71154843059994247237624760034811568192562173240459827423146270067147035272157", "price": "0.1", "size": "210.99", "side": "BUY", "hash": "e965a7e88d33861407212defc048e7101aec472a", "best_bid": "0.12", "best_ask": "0.13"}, {"asset_id": "108394778822564022837882134264212554176350354267790900487346083741419834749031", "price": "0.9", "size": "210.99", "side": "SELL", "hash": "373e06fb1bab1ccd0a137127c15436989f85c7bc", "best_bid": "0.87", "best_ask": "0.88"}], "timestamp": "1769384722772", "event_type": "price_change"}}
{"_local_timestamp": "2026-01-25T23:45:22.867113+00:00", "data": {"market": "0x08e4cea3c55ded3bb7d1ab771bb6c14d3963fac75fefd5b59c4f52dce6019a62", "price_changes": [{"asset_id": "108394778822564022837882134264212554176350354267790900487346083741419834749031", "price": "0.85", "size": "275", "side": "BUY", "hash": "cbd41131e4171e2ef6a22b4849f42cce4682029c", "best_bid": "0.87", "best_ask": "0.88"}, {"asset_id": "71154843059994247237624760034811568192562173240459827423146270067147035272157", "price": "0.15", "size": "275", "side": "SELL", "hash": "4037d8e59ec146083c612cc2886dc1eb932909aa", "best_bid": "0.12", "best_ask": "0.13"}], "timestamp": "1769384722776", "event_type": "price_change"}}
{"_local_timestamp": "2026-01-25T23:45:27.959679+00:00", "data": {"market": "0x08e4cea3c55ded3bb7d1ab771bb6c14d3963fac75fefd5b59c4f52dce6019a62", "price_changes": [{"asset_id": "108394778822564022837882134264212554176350354267790900487346083741419834749031", "price": "0.85", "size": "325", "side": "BUY", "hash": "eecf1b5e38a91cf311373f69e3b85b10c93f1848", "best_bid": "0.87", "best_ask": "0.88"}, {"asset_id": "71154843059994247237624760034811568192562173240459827423146270067147035272157", "price": "0.15", "size": "325", "side": "SELL", "hash": "de79d439e372a864703f1dbaae63b1ad407e1f81", "best_bid": "0.12", "best_ask": "0.13"}], "timestamp": "1769384727887", "event_type": "price_change"}}
{"_local_timestamp": "2026-01-25T23:45:49.815070+00:00", "data": {"market": "0x08e4cea3c55ded3bb7d1ab771bb6c14d3963fac75fefd5b59c4f52dce6019a62", "price_changes": [{"asset_id": "71154843059994247237624760034811568192562173240459827423146270067147035272157", "price": "0.1", "size": "260.99", "side": "BUY", "hash": "4a6f91cc572a4a94852226716f45e29f97396bcf", "best_bid": "0.12", "best_ask": "0.13"}, {"asset_id": "108394778822564022837882134264212554176350354267790900487346083741419834749031", "price": "0.9", "size": "260.99", "side": "SELL", "hash": "7478e1ac5e16c19b3cc99f1fe12aee0ab7c85113", "best_bid": "0.87", "best_ask": "0.88"}], "timestamp": "1769384749746", "event_type": "price_change"}}
{"_local_timestamp": "2026-01-25T23:46:10.548428+00:00", "data": {"market": "0x29271437572fd58353539701b2f2d7717cb27098be8f2d61ac68097ee1a904e2", "price_changes": [{"asset_id": "102079907506920911172638618936058182844332853810504026717141669988902032059766", "price": "0.23", "size": "371.73", "side": "BUY", "hash": "2759a16fb7670b09aaf7bdfb09b6bdbfd38cb8f3", "best_bid": "0.92", "best_ask": "0.93"}, {"asset_id": "102979187600939812579181707251830214545859759571297676718971996931510245907237", "price": "0.77", "size": "371.73", "side": "SELL", "hash": "f94b7fa3b427d93d7aa0e14f3d1bdfdb2c0c7296", "best_bid": "0.07", "best_ask": "0.08"}], "timestamp": "1769384770459", "event_type": "price_change"}}
{"_local_timestamp": "2026-01-25T23:46:36.705009+00:00", "data": {"market": "0x08e4cea3c55ded3bb7d1ab771bb6c14d3963fac75fefd5b59c4f52dce6019a62", "price_changes": [{"asset_id": "71154843059994247237624760034811568192562173240459827423146270067147035272157", "price": "0.01", "size": "12.6", "side": "BUY", "hash": "01d0b9a562950c384523edf2649d7ce591e7369b", "best_bid": "0.12", "best_ask": "0.13"}, {"asset_id": "108394778822564022837882134264212554176350354267790900487346083741419834749031", "price": "0.99", "size": "12.6", "side": "SELL", "hash": "3f4bb537c9a708cbe3dba236f8de43bcb20dc9d5", "best_bid": "0.87", "best_ask": "0.88"}], "timestamp": "1769384796460", "event_type": "price_change"}}
{"_local_timestamp": "2026-01-25T23:46:36.705890+00:00", "data": {"market": "0x08e4cea3c55ded3bb7d1ab771bb6c14d3963fac75fefd5b59c4f52dce6019a62", "price_changes": [{"asset_id": "71154843059994247237624760034811568192562173240459827423146270067147035272157", "price": "0.06", "size": "150.33", "side": "BUY", "hash": "01d0b9a562950c384523edf2649d7ce591e7369b", "best_bid": "0.12", "best_ask": "0.13"}, {"asset_id": "108394778822564022837882134264212554176350354267790900487346083741419834749031", "price": "0.94", "size": "150.33", "side": "SELL", "hash": "3f4bb537c9a708cbe3dba236f8de43bcb20dc9d5", "best_bid": "0.87", "best_ask": "0.88"}], "timestamp": "1769384796460", "event_type": "price_change"}}
{"_local_timestamp": "2026-01-25T23:46:36.706176+00:00", "data": {"market": "0x08e4cea3c55ded3bb7d1ab771bb6c14d3963fac75fefd5b59c4f52dce6019a62", "price_changes": [{"asset_id": "71154843059994247237624760034811568192562173240459827423146270067147035272157", "price": "0.08", "size": "55", "side": "BUY", "hash": "01d0b9a562950c384523edf2649d7ce591e7369b", "best_bid": "0.12", "best_ask": "0.13"}, {"asset_id": "108394778822564022837882134264212554176350354267790900487346083741419834749031", "price": "0.92", "size": "55", "side": "SELL", "hash": "3f4bb537c9a708cbe3dba236f8de43bcb20dc9d5", "best_bid": "0.87", "best_ask": "0.88"}], "timestamp": "1769384796460", "event_type": "price_change"}}
{"_local_timestamp": "2026-01-25T23:46:37.491577+00:00", "data": {"market": "0x08e4cea3c55ded3bb7d1ab771bb6c14d3963fac75fefd5b59c4f52dce6019a62", "price_changes": [{"asset_id": "71154843059994247237624760034811568192562173240459827423146270067147035272157", "price": "0.07", "size": "12.92", "side": "BUY", "hash": "e3b5f5452ed53a49023184b4eca6b449da735d74", "best_bid": "0.12", "best_ask": "0.13"}, {"asset_id": "108394778822564022837882134264212554176350354267790900487346083741419834749031", "price": "0.93", "size": "12.92", "side": "SELL", "hash": "eae6c273ca9165390d7d5e0e562b19c96f0e8f6d", "best_bid": "0.87", "best_ask": "0.88"}], "timestamp": "1769384797232", "event_type": "price_change"}}
{"_local_timestamp": "2026-01-25T23:46:37.506628+00:00", "data": {"market": "0x08e4cea3c55ded3bb7d1ab771bb6c14d3963fac75fefd5b59c4f52dce6019a62", "price_changes": [{"asset_id": "71154843059994247237624760034811568192562173240459827423146270067147035272157", "price": "0.05", "size": "10.2", "side": "BUY", "hash": "0dd17f8a1f66f906647647f0b3acbb91ef202e50", "best_bid": "0.12", "best_ask": "0.13"}, {"asset_id": "108394778822564022837882134264212554176350354267790900487346083741419834749031", "price": "0.95", "size": "10.2", "side": "SELL", "hash": "fdc3fe9fc15c67dce6bdaacce6296c631d698764", "best_bid": "0.87", "best_ask": "0.88"}], "timestamp": "1769384797246", "event_type": "price_change"}}
{"_local_timestamp": "2026-01-25T23:46:53.995221+00:00", "data": {"market": "0x29271437572fd58353539701b2f2d7717cb27098be8f2d61ac68097ee1a904e2", "price_changes": [{"asset_id": "102979187600939812579181707251830214545859759571297676718971996931510245907237", "price": "0.02", "size": "250", "side": "BUY", "hash": "475e20e75f1ef848d8016212a9ebb87467ba7088", "best_bid": "0.07", "best_ask": "0.08"}, {"asset_id": "102079907506920911172638618936058182844332853810504026717141669988902032059766", "price": "0.98", "size": "250", "side": "SELL", "hash": "5f76a4286c18b0ea2de8ccae72b8b0d13343f880", "best_bid": "0.92", "best_ask": "0.93"}], "timestamp": "1769384813868", "event_type": "price_change"}}
{"_local_timestamp": "2026-01-25T23:46:53.995694+00:00", "data": {"market": "0x29271437572fd58353539701b2f2d7717cb27098be8f2d61ac68097ee1a904e2", "price_changes": [{"asset_id": "102979187600939812579181707251830214545859759571297676718971996931510245907237", "price": "0.03", "size": "7.93", "side": "BUY", "hash": "475e20e75f1ef848d8016212a9ebb87467ba7088", "best_bid": "0.07", "best_ask": "0.08"}, {"asset_id": "102079907506920911172638618936058182844332853810504026717141669988902032059766", "price": "0.97", "size": "7.93", "side": "SELL", "hash": "5f76a4286c18b0ea2de8ccae72b8b0d13343f880", "best_bid": "0.92", "best_ask": "0.93"}], "timestamp": "1769384813868", "event_type": "price_change"}}
{"_local_timestamp": "2026-01-25T23:46:54.389066+00:00", "data": {"market": "0x29271437572fd58353539701b2f2d7717cb27098be8f2d61ac68097ee1a904e2", "price_changes": [{"asset_id": "102979187600939812579181707251830214545859759571297676718971996931510245907237", "price": "0.02", "size": "270", "side": "BUY", "hash": "28ed46ae5745b31b5ad5ca855cd5f98e0ead88fe", "best_bid": "0.07", "best_ask": "0.08"}, {"asset_id": "102079907506920911172638618936058182844332853810504026717141669988902032059766", "price": "0.98", "size": "270", "side": "SELL", "hash": "16cde2f1715275f811b42ac3bb7f9595b085e1e6", "best_bid": "0.92", "best_ask": "0.93"}], "timestamp": "1769384814269", "event_type": "price_change"}}
{"_local_timestamp": "2026-01-25T23:46:54.389356+00:00", "data": {"market": "0x29271437572fd58353539701b2f2d7717cb27098be8f2d61ac68097ee1a904e2", "price_changes": [{"asset_id": "102979187600939812579181707251830214545859759571297676718971996931510245907237", "price": "0.04", "size": "9.05", "side": "BUY", "hash": "9a516f35fde03cff47b506cf81f6fcb2a37a3bc1", "best_bid": "0.07", "best_ask": "0.08"}, {"asset_id": "102079907506920911172638618936058182844332853810504026717141669988902032059766", "price": "0.96", "size": "9.05", "side": "SELL", "hash": "1aa779bc2a4188969523b3b5f661bdd2b5c5181b", "best_bid": "0.92", "best_ask": "0.93"}], "timestamp": "1769384814270", "event_type": "price_change"}}
{"_local_timestamp": "2026-01-25T23:46:59.023020+00:00", "data": {"market": "0x29271437572fd58353539701b2f2d7717cb27098be8f2d61ac68097ee1a904e2", "price_changes": [{"asset_id": "102079907506920911172638618936058182844332853810504026717141669988902032059766", "price": "0.23", "size": "271.73", "side": "BUY", "hash": "7e32f97b22ca5a8c7b847a9f7580fca7e8dc73ed", "best_bid": "0.92", "best_ask": "0.93"}, {"asset_id": "102979187600939812579181707251830214545859759571297676718971996931510245907237", "price": "0.77", "size": "271.73", "side": "SELL", "hash": "8bbcea093b9b46ffe711df610b75d576bfe75487", "best_bid": "0.07", "best_ask": "0.08"}], "timestamp": "1769384818857", "event_type": "price_change"}}
{"_local_timestamp": "2026-01-25T23:46:59.354768+00:00", "data": {"market": "0x29271437572fd58353539701b2f2d7717cb27098be8f2d61ac68097ee1a904e2", "price_changes": [{"asset_id": "102079907506920911172638618936058182844332853810504026717141669988902032059766", "price": "0.22", "size": "826", "side": "BUY", "hash": "0ac02cc8800917fb776ba4aebdb6902a5dd0b8b6", "best_bid": "0.92", "best_ask": "0.93"}, {"asset_id": "102979187600939812579181707251830214545859759571297676718971996931510245907237", "price": "0.78", "size": "826", "side": "SELL", "hash": "155eae7247167bb88d64d8b04feb12705f7adc9c", "best_bid": "0.07", "best_ask": "0.08"}], "timestamp": "1769384819159", "event_type": "price_change"}}
{"_local_timestamp": "2026-01-25T23:47:08.790278+00:00", "data": {"market": "0x29271437572fd58353539701b2f2d7717cb27098be8f2d61ac68097ee1a904e2", "price_changes": [{"asset_id": "102079907506920911172638618936058182844332853810504026717141669988902032059766", "price": "0.29", "size": "1448", "side": "BUY", "hash": "14907e6eb3c7fd9cc5a85c2c875faa00b344a798", "best_bid": "0.92", "best_ask": "0.93"}, {"asset_id": "102979187600939812579181707251830214545859759571297676718971996931510245907237", "price": "0.71", "size": "1448", "side": "SELL", "hash": "92ac0d08c2b6398eabf24eb6c7314f9aab7ac3fd", "best_bid": "0.07", "best_ask": "0.08"}], "timestamp": "1769384828677", "event_type": "price_change"}}
{"_local_timestamp": "2026-01-25T23:48:11.520729+00:00", "data": {"market": "0x29271437572fd58353539701b2f2d7717cb27098be8f2d61ac68097ee1a904e2", "price_changes": [{"asset_id": "102079907506920911172638618936058182844332853810504026717141669988902032059766", "price": "0.28", "size": "142.85", "side": "BUY", "hash": "52c7e2787ee4838c859846d1ad77143881c6321d", "best_bid": "0.92", "best_ask": "0.93"}, {"asset_id": "102979187600939812579181707251830214545859759571297676718971996931510245907237", "price": "0.72", "size": "142.85", "side": "SELL", "hash": "51a49208bac767c14030558f8f1ae82ced142083", "best_bid": "0.07", "best_ask": "0.08"}], "timestamp": "1769384891442", "event_type": "price_change"}}
{"_local_timestamp": "2026-01-25T23:48:11.773318+00:00", "data": {"market": "0x29271437572fd58353539701b2f2d7717cb27098be8f2d61ac68097ee1a904e2", "price_changes": [{"asset_id": "102079907506920911172638618936058182844332853810504026717141669988902032059766", "price": "0.29", "size": "1498", "side": "BUY", "hash": "02627fe241485dbab1e35bb902f9c96e65feb406", "best_bid": "0.92", "best_ask": "0.93"}, {"asset_id": "102979187600939812579181707251830214545859759571297676718971996931510245907237", "price": "0.71", "size": "1498", "side": "SELL", "hash": "97736c16746982f640a2df864f13d3c37c66c681", "best_bid": "0.07", "best_ask": "0.08"}], "timestamp": "1769384891689", "event_type": "price_change"}}
{"_local_timestamp": "2026-01-25T23:48:18.122518+00:00", "data": {"market": "0x08e4cea3c55ded3bb7d1ab771bb6c14d3963fac75fefd5b59c4f52dce6019a62", "price_changes": [{"asset_id": "71154843059994247237624760034811568192562173240459827423146270067147035272157", "price": "0.06", "size": "130.33", "side": "BUY", "hash": "b288367538bd916b0d79fb325282411a742308d7", "best_bid": "0.12", "best_ask": "0.13"}, {"asset_id": "108394778822564022837882134264212554176350354267790900487346083741419834749031", "price": "0.94", "size": "130.33", "side": "SELL", "hash": "a57f9989740226e57bb1e0221d0f9d890de5bf21", "best_bid": "0.87", "best_ask": "0.88"}], "timestamp": "1769384898008", "event_type": "price_change"}}
{"_local_timestamp": "2026-01-25T23:48:18.172699+00:00", "data": {"market": "0x08e4cea3c55ded3bb7d1ab771bb6c14d3963fac75fefd5b59c4f52dce6019a62", "price_changes": [{"asset_id": "71154843059994247237624760034811568192562173240459827423146270067147035272157", "price": "0.06", "size": "150.33", "side": "BUY", "hash": "aff8ea5902914bba94ce7a56b65f72fe059bdaeb", "best_bid": "0.12", "best_ask": "0.13"}, {"asset_id": "108394778822564022837882134264212554176350354267790900487346083741419834749031", "price": "0.94", "size": "150.33", "side": "SELL", "hash": "d3320296cfe8ec9d5636219bee294411f9e1b619", "best_bid": "0.87", "best_ask": "0.88"}], "timestamp": "1769384898073", "event_type": "price_change"}}
{"_local_timestamp": "2026-01-25T23:49:30.397118+00:00", "data": {"market": "0x29271437572fd58353539701b2f2d7717cb27098be8f2d61ac68097ee1a904e2", "price_changes": [{"asset_id": "102079907506920911172638618936058182844332853810504026717141669988902032059766", "price": "0.23", "size": "171.73", "side": "BUY", "hash": "2abddedc3bee159165c2dbdc450cae1d9fce14e7", "best_bid": "0.92", "best_ask": "0.93"}, {"asset_id": "102979187600939812579181707251830214545859759571297676718971996931510245907237", "price": "0.77", "size": "171.73", "side": "SELL", "hash": "bc46cde9f032ee2707809dced87dc949ee7cadd2", "best_bid": "0.07", "best_ask": "0.08"}], "timestamp": "1769384970077", "event_type": "price_change"}}
{"_local_timestamp": "2026-01-25T23:49:30.904217+00:00", "data": {"market": "0x29271437572fd58353539701b2f2d7717cb27098be8f2d61ac68097ee1a904e2", "price_changes": [{"asset_id": "102079907506920911172638618936058182844332853810504026717141669988902032059766", "price": "0.22", "size": "926", "side": "BUY", "hash": "5758af65ff09e8d6f456f227d10db2a7c25c91f3", "best_bid": "0.92", "best_ask": "0.93"}, {"asset_id": "102979187600939812579181707251830214545859759571297676718971996931510245907237", "price": "0.78", "size": "926", "side": "SELL", "hash": "2ff6c9bf86c41ae1b4bb520d396078aef27e7324", "best_bid": "0.07", "best_ask": "0.08"}], "timestamp": "1769384970597", "event_type": "price_change"}}
{"_local_timestamp": "2026-01-25T23:49:41.705616+00:00", "data": {"market": "0x29271437572fd58353539701b2f2d7717cb27098be8f2d61ac68097ee1a904e2", "price_changes": [{"asset_id": "102079907506920911172638618936058182844332853810504026717141669988902032059766", "price": "0.23", "size": "121.73", "side": "BUY", "hash": "75c31d7fd58bf2bc2056dc87154f00a5119ccb7c", "best_bid": "0.92", "best_ask": "0.93"}, {"asset_id": "102979187600939812579181707251830214545859759571297676718971996931510245907237", "price": "0.77", "size": "121.73", "side": "SELL", "hash": "4dc60450c8b450c48b38675f4f64fabd88c45dad", "best_bid": "0.07", "best_ask": "0.08"}], "timestamp": "1769384981637", "event_type": "price_change"}}
{"_local_timestamp": "2026-01-25T23:49:41.705989+00:00", "data": {"market": "0x29271437572fd58353539701b2f2d7717cb27098be8f2d61ac68097ee1a904e2", "price_changes": [{"asset_id": "102079907506920911172638618936058182844332853810504026717141669988902032059766", "price": "0.28", "size": "92.85", "side": "BUY", "hash": "75c31d7fd58bf2bc2056dc87154f00a5119ccb7c", "best_bid": "0.92", "best_ask": "0.93"}, {"asset_id": "102979187600939812579181707251830214545859759571297676718971996931510245907237", "price": "0.72", "size": "92.85", "side": "SELL", "hash": "4dc60450c8b450c48b38675f4f64fabd88c45dad", "best_bid": "0.07", "best_ask": "0.08"}], "timestamp": "1769384981637", "event_type": "price_change"}}
{"_local_timestamp": "2026-01-25T23:49:42.424270+00:00", "data": {"market": "0x29271437572fd58353539701b2f2d7717cb27098be8f2d61ac68097ee1a904e2", "price_changes": [{"asset_id": "102079907506920911172638618936058182844332853810504026717141669988902032059766", "price": "0.22", "size": "976", "side": "BUY", "hash": "64d8eb315f035bdf610add655c4724c0e9ba6221", "best_bid": "0.92", "best_ask": "0.93"}, {"asset_id": "102979187600939812579181707251830214545859759571297676718971996931510245907237", "price": "0.78", "size": "976", "side": "SELL", "hash": "1a2b517b7d5a0d706165ad8a479b130f4f6da3d6", "best_bid": "0.07", "best_ask": "0.08"}], "timestamp": "1769384982238", "event_type": "price_change"}}
{"_local_timestamp": "2026-01-25T23:49:42.439915+00:00", "data": {"market": "0x29271437572fd58353539701b2f2d7717cb27098be8f2d61ac68097ee1a904e2", "price_changes": [{"asset_id": "102079907506920911172638618936058182844332853810504026717141669988902032059766", "price": "0.29", "size": "1548", "side": "BUY", "hash": "c7c0ee57fb4b42b642b0c298dd73b5887458d18d", "best_bid": "0.92", "best_ask": "0.93"}, {"asset_id": "102979187600939812579181707251830214545859759571297676718971996931510245907237", "price": "0.71", "size": "1548", "side": "SELL", "hash": "e804c8fbf5ca3e9a8a22b7c0b5c49309dce6d138", "best_bid": "0.07", "best_ask": "0.08"}], "timestamp": "1769384982264", "event_type": "price_change"}}
{"_local_timestamp": "2026-01-25T23:49:51.205687+00:00", "data": {"market": "0x29271437572fd58353539701b2f2d7717cb27098be8f2d61ac68097ee1a904e2", "price_changes": [{"asset_id": "102079907506920911172638618936058182844332853810504026717141669988902032059766", "price": "0.29", "size": "100", "side": "BUY", "hash": "e5a21819d7f085ac7d09b1beb68dbc442b64e7a7", "best_bid": "0.92", "best_ask": "0.93"}, {"asset_id": "102979187600939812579181707251830214545859759571297676718971996931510245907237", "price": "0.71", "size": "100", "side": "SELL", "hash": "2dea019517b1cd5efc41dade985bc07e1685e3bd", "best_bid": "0.07", "best_ask": "0.08"}], "timestamp": "1769384991039", "event_type": "price_change"}}
{"_local_timestamp": "2026-01-25T23:49:55.079747+00:00", "data": {"market": "0x29271437572fd58353539701b2f2d7717cb27098be8f2d61ac68097ee1a904e2", "price_changes": [{"asset_id": "102979187600939812579181707251830214545859759571297676718971996931510245907237", "price": "0.06", "size": "255", "side": "BUY", "hash": "ccf28733c04dc2a21ef190ae8aaeff7e5ba9dda2", "best_bid": "0.07", "best_ask": "0.08"}, {"asset_id": "102079907506920911172638618936058182844332853810504026717141669988902032059766", "price": "0.94", "size": "255", "side": "SELL", "hash": "c6b7df6186792f89520cac1a45d2198df7dd2450", "best_bid": "0.92", "best_ask": "0.93"}], "timestamp": "1769384995001", "event_type": "price_change"}}
{"_local_timestamp": "2026-01-25T23:49:55.097730+00:00", "data": {"market": "0x29271437572fd58353539701b2f2d7717cb27098be8f2d61ac68097ee1a904e2", "price_changes": [{"asset_id": "102979187600939812579181707251830214545859759571297676718971996931510245907237", "price": "0.09", "size": "311.61", "side": "SELL", "hash": "7de82945d526bc8cdd6b87da38ddc8c43afb756d", "best_bid": "0.07", "best_ask": "0.08"}, {"asset_id": "102079907506920911172638618936058182844332853810504026717141669988902032059766", "price": "0.91", "size": "311.61", "side": "BUY", "hash": "eee0b0db8f71d963331c643eb74ff47e4d79c8bf", "best_bid": "0.92", "best_ask": "0.93"}], "timestamp": "1769384995004", "event_type": "price_change"}}
{"_local_timestamp": "2026-01-25T23:50:02.664010+00:00", "data": {"market": "0x29271437572fd58353539701b2f2d7717cb27098be8f2d61ac68097ee1a904e2", "price_changes": [{"asset_id": "102079907506920911172638618936058182844332853810504026717141669988902032059766", "price": "0.22", "size": "250", "side": "BUY", "hash": "18869a247c50751ed3252534846e218176c4fa66", "best_bid": "0.92", "best_ask": "0.93"}, {"asset_id": "102979187600939812579181707251830214545859759571297676718971996931510245907237", "price": "0.78", "size": "250", "side": "SELL", "hash": "ab201e10be2d864f2fdbc663f70d9622fd9e1def", "best_bid": "0.07", "best_ask": "0.08"}], "timestamp": "1769385002277", "event_type": "price_change"}}
{"_local_timestamp": "2026-01-25T23:50:02.678973+00:00", "data": {"market": "0x29271437572fd58353539701b2f2d7717cb27098be8f2d61ac68097ee1a904e2", "price_changes": [{"asset_id": "102979187600939812579181707251830214545859759571297676718971996931510245907237", "price": "0.09", "size": "361.61", "side": "SELL", "hash": "b2b37129da050834d463872dff98c5bf7cdd1593", "best_bid": "0.07", "best_ask": "0.08"}, {"asset_id": "102079907506920911172638618936058182844332853810504026717141669988902032059766", "price": "0.91", "size": "361.61", "side": "BUY", "hash": "ef2c576f8bd560901a090c42e13bbc84fea8deaa", "best_bid": "0.92", "best_ask": "0.93"}], "timestamp": "1769385002312", "event_type": "price_change"}}
{"_local_timestamp": "2026-01-25T23:50:02.693607+00:00", "data": {"market": "0x29271437572fd58353539701b2f2d7717cb27098be8f2d61ac68097ee1a904e2", "price_changes": [{"asset_id": "102979187600939812579181707251830214545859759571297676718971996931510245907237", "price": "0.06", "size": "305", "side": "BUY", "hash": "5c6c8ac472ac8f6d7ae20bbcd0608b8ba7fe77d2", "best_bid": "0.07", "best_ask": "0.08"}, {"asset_id": "102079907506920911172638618936058182844332853810504026717141669988902032059766", "price": "0.94", "size": "305", "side": "SELL", "hash": "e39ca60eb9626227ca10c1682ebd000eded8edaf", "best_bid": "0.92", "best_ask": "0.93"}], "timestamp": "1769385002313", "event_type": "price_change"}}
{"_local_timestamp": "2026-01-25T23:50:02.813549+00:00", "data": {"market": "0x08e4cea3c55ded3bb7d1ab771bb6c14d3963fac75fefd5b59c4f52dce6019a62", "price_changes": [{"asset_id": "108394778822564022837882134264212554176350354267790900487346083741419834749031", "price": "0.21", "size": "0", "side": "BUY", "hash": "9acda526c8111aacdf93b17a89bf5b74a1e2a32e", "best_bid": "0.87", "best_ask": "0.88"}, {"asset_id": "71154843059994247237624760034811568192562173240459827423146270067147035272157", "price": "0.79", "size": "0", "side": "SELL", "hash": "0a457b71377f2bbab3a9fa01469b591ea839493d", "best_bid": "0.12", "best_ask": "0.13"}], "timestamp": "1769385002284", "event_type": "price_change"}}
{"_local_timestamp": "2026-01-25T23:50:02.907672+00:00", "data": {"market": "0x29271437572fd58353539701b2f2d7717cb27098be8f2d61ac68097ee1a904e2", "price_changes": [{"asset_id": "102079907506920911172638618936058182844332853810504026717141669988902032059766", "price": "0.34", "size": "0", "side": "BUY", "hash": "ea6dc3891b4c568c470f206cbb12e79991e44f18", "best_bid": "0.92", "best_ask": "0.93"}, {"asset_id": "102979187600939812579181707251830214545859759571297676718971996931510245907237", "price": "0.66", "size": "0", "side": "SELL", "hash": "04111ab4c43ff323e1c6d2c5fb36fa678b90aed4", "best_bid": "0.07", "best_ask": "0.08"}], "timestamp": "1769385002361", "event_type": "price_change"}}
{"_local_timestamp": "2026-01-25T23:50:03.194884+00:00", "data": {"market": "0x08e4cea3c55ded3bb7d1ab771bb6c14d3963fac75fefd5b59c4f52dce6019a62", "price_changes": [{"asset_id": "108394778822564022837882134264212554176350354267790900487346083741419834749031", "price": "0.16", "size": "450", "side": "BUY", "hash": "66fce6cef7d8c9838b7075a116c841ffa4a74543", "best_bid": "0.87", "best_ask": "0.88"}, {"asset_id": "71154843059994247237624760034811568192562173240459827423146270067147035272157", "price": "0.84", "size": "450", "side": "SELL", "hash": "f4c34178b3e32886c185903c74866966705b864d", "best_bid": "0.12", "best_ask": "0.13"}], "timestamp": "1769385002726", "event_type": "price_change"}}
{"_local_timestamp": "2026-01-25T23:50:03.843960+00:00", "data": {"market": "0x29271437572fd58353539701b2f2d7717cb27098be8f2d61ac68097ee1a904e2", "price_changes": [{"asset_id": "102079907506920911172638618936058182844332853810504026717141669988902032059766", "price": "0.24", "size": "1748", "side": "BUY", "hash": "6a0bcdfe5d716df7d1eb8f37119800e66529f796", "best_bid": "0.92", "best_ask": "0.93"}, {"asset_id": "102979187600939812579181707251830214545859759571297676718971996931510245907237", "price": "0.76", "size": "1748", "side": "SELL", "hash": "e144df94c5c11e215e6cf581270da09b03931c25", "best_bid": "0.07", "best_ask": "0.08"}], "timestamp": "1769385003766", "event_type": "price_change"}}
{"_local_timestamp": "2026-01-25T23:50:46.376818+00:00", "data": {"market": "0x29271437572fd58353539701b2f2d7717cb27098be8f2d61ac68097ee1a904e2", "price_changes": [{"asset_id": "102079907506920911172638618936058182844332853810504026717141669988902032059766", "price": "0.22", "size": "150", "side": "BUY", "hash": "0d08ba9624781ab8d8d75f64bba39c4b34ff4832", "best_bid": "0.92", "best_ask": "0.93"}, {"asset_id": "102979187600939812579181707251830214545859759571297676718971996931510245907237", "price": "0.78", "size": "150", "side": "SELL", "hash": "3e3c16f4b7e2eeb894bdac1b1228272088a4092d", "best_bid": "0.07", "best_ask": "0.08"}], "timestamp": "1769385046268", "event_type": "price_change"}}
{"_local_timestamp": "2026-01-25T23:50:46.381372+00:00", "data": {"market": "0x29271437572fd58353539701b2f2d7717cb27098be8f2d61ac68097ee1a904e2", "price_changes": [{"asset_id": "102079907506920911172638618936058182844332853810504026717141669988902032059766", "price": "0.29", "size": "50", "side": "BUY", "hash": "0d08ba9624781ab8d8d75f64bba39c4b34ff4832", "best_bid": "0.92", "best_ask": "0.93"}, {"asset_id": "102979187600939812579181707251830214545859759571297676718971996931510245907237", "price": "0.71", "size": "50", "side": "SELL", "hash": "3e3c16f4b7e2eeb894bdac1b1228272088a4092d", "best_bid": "0.07", "best_ask": "0.08"}], "timestamp": "1769385046268", "event_type": "price_change"}}
{"_local_timestamp": "2026-01-25T23:50:46.736727+00:00", "data": {"market": "0x29271437572fd58353539701b2f2d7717cb27098be8f2d61ac68097ee1a904e2", "price_changes": [{"asset_id": "102079907506920911172638618936058182844332853810504026717141669988902032059766", "price": "0.24", "size": "1848", "side": "BUY", "hash": "6385f2f671ad424ca723b2ec07dc6d00f0df9aa5", "best_bid": "0.92", "best_ask": "0.93"}, {"asset_id": "102979187600939812579181707251830214545859759571297676718971996931510245907237", "price": "0.76", "size": "1848", "side": "SELL", "hash": "218a21b306631a2c00f628e17ee33aebfb4e6976", "best_bid": "0.07", "best_ask": "0.08"}], "timestamp": "1769385046628", "event_type": "price_change"}}
{"_local_timestamp": "2026-01-25T23:50:46.814480+00:00", "data": {"market": "0x29271437572fd58353539701b2f2d7717cb27098be8f2d61ac68097ee1a904e2", "price_changes": [{"asset_id": "102079907506920911172638618936058182844332853810504026717141669988902032059766", "price": "0.28", "size": "142.85", "side": "BUY", "hash": "eceb06c29e18fded97eac5838187f23e7266a5e5", "best_bid": "0.92", "best_ask": "0.93"}, {"asset_id": "102979187600939812579181707251830214545859759571297676718971996931510245907237", "price": "0.72", "size": "142.85", "side": "SELL", "hash": "b7db0eb5f3e6a285dad693c89185887ff3ddf932", "best_bid": "0.07", "best_ask": "0.08"}], "timestamp": "1769385046649", "event_type": "price_change"}}
{"_local_timestamp": "2026-01-25T23:51:13.546671+00:00", "data": {"market": "0x29271437572fd58353539701b2f2d7717cb27098be8f2d61ac68097ee1a904e2", "price_changes": [{"asset_id": "102079907506920911172638618936058182844332853810504026717141669988902032059766", "price": "0.38", "size": "1578", "side": "BUY", "hash": "ce9f1c823bdc1b42cbf50730ae764fa1e47db48b", "best_bid": "0.92", "best_ask": "0.93"}, {"asset_id": "102979187600939812579181707251830214545859759571297676718971996931510245907237", "price": "0.62", "size": "1578", "side": "SELL", "hash": "57e5c53fd727f533abcee5e7d2fed7d131c06e22", "best_bid": "0.07", "best_ask": "0.08"}], "timestamp": "1769385073477", "event_type": "price_change"}}
{"_local_timestamp": "2026-01-25T23:51:25.718388+00:00", "data": {"market": "0x08e4cea3c55ded3bb7d1ab771bb6c14d3963fac75fefd5b59c4f52dce6019a62", "price_changes": [{"asset_id": "108394778822564022837882134264212554176350354267790900487346083741419834749031", "price": "0.16", "size": "400", "side": "BUY", "hash": "df60ac25ab82f98060b8709505cb6564670a8de6", "best_bid": "0.87", "best_ask": "0.88"}, {"asset_id": "71154843059994247237624760034811568192562173240459827423146270067147035272157", "price": "0.84", "size": "400", "side": "SELL", "hash": "4364b6d34e931f08e677073fefa56e50aedda580", "best_bid": "0.12", "best_ask": "0.13"}], "timestamp": "1769385085600", "event_type": "price_change"}}
{"_local_timestamp": "2026-01-25T23:51:26.070210+00:00", "data": {"market": "0x08e4cea3c55ded3bb7d1ab771bb6c14d3963fac75fefd5b59c4f52dce6019a62", "price_changes": [{"asset_id": "108394778822564022837882134264212554176350354267790900487346083741419834749031", "price": "0.15", "size": "600", "side": "BUY", "hash": "02c3d8c77ef5c39e45c05d713bbd08d4460c7eda", "best_bid": "0.87", "best_ask": "0.88"}, {"asset_id": "71154843059994247237624760034811568192562173240459827423146270067147035272157", "price": "0.85", "size": "600", "side": "SELL", "hash": "9f2c086363ca4d6cf7720861ac428a86c645af51", "best_bid": "0.12", "best_ask": "0.13"}], "timestamp": "1769385085999", "event_type": "price_change"}}
