{"_local_timestamp": "2026-01-25T23:41:01.115396+00:00", "data": [{"market": "0x618f90d78c70081e7dd7d422c3e2299e4a77d35edb8e4258ae0297ddfab14e17", "asset_id": "88493938041191305708637957243458880188207866339223186442772420759619853972732", "timestamp": "1769384437952", "hash": "d61c13d7f4989ee87df5f6186c255e387211a603", "bids": [{"price": "0.01", "size": "67.05"}, {"price": "0.02", "size": "182.48"}, {"price": "0.03", "size": "18.99"}, {"price": "0.04", "size": "5.47"}], "asks": [{"price": "0.99", "size": "62.05"}, {"price": "0.98", "size": "190.48"}, {"price": "0.97", "size": "18.99"}, {"price": "0.96", "size": "29.99"}], "event_type": "book", "last_trade_price": ""}, {"market": "0xf066a50b6de706e77d817e30bb1d8434e431865118f86a812fd6e7be76777adc", "asset_id": "94985517151039391288188805066699758322494139690669466067493670205558702001120", "timestamp": "1769382720239", "hash": "fe0122c9b67e0c8b9cfcd33783d8e255f251779a", "bids": [{"price": "0.01", "size": "59.79"}, {"price": "0.02", "size": "159.39"}, {"price": "0.03", "size": "80.95"}, {"price": "0.04", "size": "12.13"}, {"price": "0.05", "size": "15.47"}], "asks": [{"price": "0.99", "size": "62.05"}, {"price": "0.98", "size": "190.48"}, {"price": "0.97", "size": "18.99"}, {"price": "0.96", "size": "42.49"}], "event_type": "book", "last_trade_price": ""}, {"market": "0x9e546f5bd8aaa57b741386967b6f0cb83ba70ff12cf399a3b104f5ded3e01c33", "asset_id": "52384449694849030011952391984862607032268821842864420008617516574964644205640", "timestamp": "1769384437952", "hash": "65685dda2e5cb45d80e15c82fe6b6b6956547db7", "bids": [{"price": "0.01", "size": "62.05"}, {"price": "0.02", "size": "190.48"}, {"price": "0.03", "size": "18.99"}, {"price": "0.04", "size": "29.99"}], "asks": [{"price": "0.99", "size": "67.61"}, {"price": "0.98", "size": "180.95"}, {"price": "0.97", "size": "19.83"}, {"price": "0.96", "size": "5.47"}], "event_type": "book", "last_trade_price": ""}, {"market": "0xc794d53782d2a57779c1bd1d7fe4e1012cd63daa340d6733478b04e43c779bb2", "asset_id": "65285709653207321996387925181629862243682185841555542627225011614554527757803", "timestamp": "1769384437952", "hash": "7083dadcb1eb69f9feb187b569ea5d165c06fe08", "bids": [{"price": "0.01", "size": "62.05"}, {"price": "0.02", "size": "190.48"}, {"price": "0.03", "size": "18.99"}, {"price": "0.04", "size": "29.99"}], "asks": [{"price": "0.99", "size": "67.61"}, {"price": "0.98", "size": "180.95"}, {"price": "0.97", "size": "19.83"}, {"price": "0.96", "size": "5.47"}], "event_type": "book", "last_trade_price": ""}, {"market": "0x5bb085cf19c81e4c5e288ee70965fd061fb463199a1db6aa73c289c8b5d5b576", "asset_id": "3869270757164855312650371225248655982559601630752717256310586548174182218377", "timestamp": "1769384447685", "hash": "6e2427f452094b15a603ffc4e2d1437172a00886", "bids": [{"price": "0.01", "size": "162.05"}, {"price": "0.02", "size": "240.48"}, {"price": "0.03", "size": "18.99"}, {"price": "0.04", "size": "29.99"}], "asks": [{"price": "0.99", "size": "164.87"}, {"price": "0.98", "size": "232.77"}, {"price": "0.97", "size": "19.52"}, {"price": "0.95", "size": "23.99"}, {"price": "0.94", "size": "5.47"}], "event_type": "book", "last_trade_price": ""}, {"market": "0x180cee3cb165e04b5556b5f54f156aecdfac62a7f99de19cb6e54247f046d80d", "asset_id": "41518792079540460126973298251922654758525254450148908246351858650533815863785", "timestamp": "1769384447685", "hash": "2b98a65e73641fc7c764c53106aea63787cb1625", "bids": [{"price": "0.01", "size": "111.05"}, {"price": "0.02", "size": "214.48"}, {"price": "0.03", "size": "18.99"}, {"price": "0.04", "size": "29.99"}], "asks": [{"price": "0.99", "size": "117.55"}, {"price": "0.98", "size": "204.03"}, {"price": "0.97", "size": "20.79"}, {"price": "0.95", "size": "23.99"}, {"price": "0.94", "size": "5.47"}], "event_type": "book", "last_trade_price": ""}, {"market": "0x4d9b924e07c1868f1ae0a71542c5e2945c86c14a04bd846bfe2f0bb95848a67e", "asset_id": "26562265211720931675265155047873360108835400286939832140681489066284406369537", "timestamp": "1769384447685", "hash": "58ca465ff6900cb618f7076168471de960521211", "bids": [{"price": "0.01", "size": "212.04"}, {"price": "0.02", "size": "222.48"}, {"price": "0.03", "size": "18.99"}, {"price": "0.04", "size": "29.99"}], "asks": [{"price": "0.99", "size": "212.04"}, {"price": "0.98", "size": "255.48"}, {"price": "0.97", "size": "18.99"}, {"price": "0.95", "size": "23.99"}, {"price": "0.94", "size": "5.47"}], "event_type": "book", "last_trade_price": ""}, {"market": "0xca6684a2f5b699b04e9da70003381b45faa1a7807748abc7fbca1d689eede3dd", "asset_id": "67923079595575445284641976004414570715798135735376672166638592297910878774957", "timestamp": "1769384355353", "hash": "b129f8e718e23100e05c8c1ef5aa1221adf08c1e", "bids": [{"price": "0.01", "size": "112.04"}, {"price": "0.02", "size": "215.48"}, {"price": "0.03", "size": "18.99"}, {"price": "0.04", "size": "29.99"}], "asks": [{"price": "0.99", "size": "109.66"}, {"price": "0.98", "size": "200.63"}, {"price": "0.97", "size": "8.61"}, {"price": "0.96", "size": "10.81"}, {"price": "0.95", "size": "5.47"}], "event_type": "book", "last_trade_price": ""}, {"market": "0x8126b48144a3a336f16d34371f1243ed5cf2f43bf52280d7d77809099971a218", "asset_id": "27338257294745890265669696323699086994150404532171297238603912881944696902194", "timestamp": "1769382949939", "hash": "51475e83d1c39b659f862b0b904cf34112fcc64f", "bids": [{"price": "0.01", "size": "3755.38"}, {"price": "0.02", "size": "2100"}, {"price": "0.03", "size": "10.25"}, {"price": "0.05", "size": "1700"}, {"price": "0.09", "size": "700"}, {"price": "0.1", "size": "55.88"}, {"price": "0.17", "size": "300"}, {"price": "0.19", "size": "200"}, {"price": "0.2", "size": "125"}, {"price": "0.22", "size": "75"}, {"price": "0.28", "size": "10"}, {"price": "0.4", "size": "200"}, {"price": "0.43", "size": "135"}, {"price": "0.44", "size": "500"}, {"price": "0.45", "size": "198"}], "asks": [{"price": "0.99", "size": "3750.56"}, {"price": "0.98", "size": "2100"}, {"price": "0.97", "size": "8.61"}, {"price": "0.95", "size": "1700"}, {"price": "0.92", "size": "700"}, {"price": "0.91", "size": "7.06"}, {"price": "0.86", "size": "200"}, {"price": "0.79", "size": "2000"}, {"price": "0.77", "size": "125"}, {"price": "0.73", "size": "300"}, {"price": "0.69", "size": "200"}, {"price": "0.67", "size": "125"}, {"price": "0.64", "size": "75"}, {"price": "0.52", "size": "150"}, {"price": "0.5", "size": "30"}, {"price": "0.47", "size": "61.87"}, {"price": "0.46", "size": "412"}], "event_type": "book", "last_trade_price": "0.540"}, {"market": "0xe2522c3113503fa3310842e464c988b3ee1791790d74e3bbf01ba7abeb25c80f", "asset_id": "34396356694568550365415333424976689315210304285798066025980709860841157649078", "timestamp": "1769384447685", "hash": "a709bb7b50a25fa940d8f9d8a91b6423f005f3e4", "bids": [{"price": "0.01", "size": "169.65"}, {"price": "0.02", "size": "227.66"}, {"price": "0.03", "size": "21.34"}, {"price": "0.05", "size": "23.99"}, {"price": "0.06", "size": "5.47"}], "asks": [{"price": "0.99", "size": "162.05"}, {"price": "0.98", "size": "240.48"}, {"price": "0.97", "size": "18.99"}, {"price": "0.96", "size": "29.99"}], "event_type": "book", "last_trade_price": ""}, {"market": "0x644991b60a94b272357e6f68d1615680703601accb15d7302f499b737d4a0db0", "asset_id": "80482043625015601757240447150279689188946061800550924069274579383544776374468", "timestamp": "1769384437952", "hash": "edcaf159a14e99876e1ca1c4e89dec032aa5570b", "bids": [{"price": "0.01", "size": "67.61"}, {"price": "0.02", "size": "180.95"}, {"price": "0.03", "size": "19.83"}, {"price": "0.04", "size": "5.47"}], "asks": [{"price": "0.99", "size": "62.05"}, {"price": "0.98", "size": "190.48"}, {"price": "0.97", "size": "18.99"}, {"price": "0.96", "size": "29.99"}], "event_type": "book", "last_trade_price": ""}, {"market": "0x9e546f5bd8aaa57b741386967b6f0cb83ba70ff12cf399a3b104f5ded3e01c33", "asset_id": "98748914400722920263495947114807262573236269758480928212643590321888570153891", "timestamp": "1769384437952", "hash": "2d5972612b5751c93f49d8f3391109c286a4c8b0", "bids": [{"price": "0.01", "size": "67.61"}, {"price": "0.02", "size": "180.95"}, {"price": "0.03", "size": "19.83"}, {"price": "0.04", "size": "5.47"}], "asks": [{"price": "0.99", "size": "62.05"}, {"price": "0.98", "size": "190.48"}, {"price": "0.97", "size": "18.99"}, {"price": "0.96", "size": "29.99"}], "event_type": "book", "last_trade_price": ""}, {"market": "0x5bb085cf19c81e4c5e288ee70965fd061fb463199a1db6aa73c289c8b5d5b576", "asset_id": "94028695263980919862424407658493739709000655590831556337575886476241764379188", "timestamp": "1769384447685", "hash": "f0e0978062f8270fbb08780bd3953fa9c0a4328d", "bids": [{"price": "0.01", "size": "164.87"}, {"price": "0.02", "size": "232.77"}, {"price": "0.03", "size": "19.52"}, {"price": "0.05", "size": "23.99"}, {"price": "0.06", "size": "5.47"}], "asks": [{"price": "0.99", "size": "162.05"}, {"price": "0.98", "size": "240.48"}, {"price": "0.97", "size": "18.99"}, {"price": "0.96", "size": "29.99"}], "event_type": "book", "last_trade_price": ""}, {"market": "0x66aa8a28579a59742b541d7d89f185231e24127d8d54e207d92e66213ed909ef", "asset_id": "29482259799705002124566483090977991712914260860257479165135371688038751642644", "timestamp": "1769384447685", "hash": "11f36a15f4815579e8104161ec2ecf4f791b5667", "bids": [{"price": "0.01", "size": "62.05"}, {"price": "0.02", "size": "190.48"}, {"price": "0.03", "size": "18.99"}, {"price": "0.04", "size": "29.99"}], "asks": [{"price": "0.99", "size": "68.73"}, {"price": "0.98", "size": "179.03"}, {"price": "0.97", "size": "20.73"}, {"price": "0.95", "size": "23.99"}, {"price": "0.94", "size": "5.47"}], "event_type": "book", "last_trade_price": ""}, {"market": "0x618f90d78c70081e7dd7d422c3e2299e4a77d35edb8e4258ae0297ddfab14e17", "asset_id": "630142824528014601903526077196303536591995171166379784723107847019383910560", "timestamp": "1769384437952", "hash": "bc807e5b86a1e342272a25e386eefcf9306799ba", "bids": [{"price": "0.01", "size": "62.05"}, {"price": "0.02", "size": "190.48"}, {"price": "0.03", "size": "18.99"}, {"price": "0.04", "size": "29.99"}], "asks": [{"price": "0.99", "size": "67.05"}, {"price": "0.98", "size": "182.48"}, {"price": "0.97", "size": "18.99"}, {"price": "0.96", "size": "5.47"}], "event_type": "book", "last_trade_price": ""}, {"market": "0x66aa8a28579a59742b541d7d89f185231e24127d8d54e207d92e66213ed909ef", "asset_id": "91423736259203636828645539448680117024524087071143750679349605058506199161826", "timestamp": "1769384447685", "hash": "060862cbf746cc5e2b56dedfb142ed1f7f0dfcba", "bids": [{"price": "0.01", "size": "68.73"}, {"price": "0.02", "size": "179.03"}, {"price": "0.03", "size": "20.73"}, {"price": "0.05", "size": "23.99"}, {"price": "0.06", "size": "5.47"}], "asks": [{"price": "0.99", "size": "62.05"}, {"price": "0.98", "size": "190.48"}, {"price": "0.97", "size": "18.99"}, {"price": "0.96", "size": "29.99"}], "event_type": "book", "last_trade_price": ""}, {"market": "0x180cee3cb165e04b5556b5f54f156aecdfac62a7f99de19cb6e54247f046d80d", "asset_id": "45832756093987475477292835259287296516281710171095995001873781080428505369867", "timestamp": "1769384447685", "hash": "0c9d9c7cbd62a637995954b2cc3285643acb3dab", "bids": [{"price": "0.01", "size": "117.55"}, {"price": "0.02", "size": "204.03"}, {"price": "0.03", "size": "20.79"}, {"price": "0.05", "size": "23.99"}, {"price": "0.06", "size": "5.47"}], "asks": [{"price": "0.99", "size": "111.05"}, {"price": "0.98", "size": "214.48"}, {"price": "0.97", "size": "18.99"}, {"price": "0.96", "size": "29.99"}], "event_type": "book", "last_trade_price": ""}, {"market": "0xdae2149f65e89818c56124e772eee704f55f1a411482755dba026d4c727af0e4", "asset_id": "108539949567612627196500132085967459870136452742815448382213013024762772569343", "timestamp": "1769384437952", "hash": "f4036476f452c5e3e06e80e58a3f39643f9830bd", "bids": [{"price": "0.01", "size": "62.05"}, {"price": "0.02", "size": "190.48"}, {"price": "0.03", "size": "18.99"}, {"price": "0.04", "size": "29.99"}], "asks": [{"price": "0.99", "size": "67.61"}, {"price": "0.98", "size": "180.95"}, {"price": "0.97", "size": "19.83"}, {"price": "0.96", "size": "5.47"}], "event_type": "book", "last_trade_price": ""}, {"market": "0xf066a50b6de706e77d817e30bb1d8434e431865118f86a812fd6e7be76777adc", "asset_id": "113213868385473316562386771713870955656830042806999599274371686723779894332046", "timestamp": "1769382720239", "hash": "04e82615b36e2d06cf48a196cf4e3eba7de5028b", "bids": [{"price": "0.01", "size": "62.05"}, {"price": "0.02", "size": "190.48"}, {"price": "0.03", "size": "18.99"}, {"price": "0.04", "size": "42.49"}], "asks": [{"price": "0.99", "size": "59.79"}, {"price": "0.98", "size": "159.39"}, {"price": "0.97", "size": "80.95"}, {"price": "0.96", "size": "12.13"}, {"price": "0.95", "size": "15.47"}], "event_type": "book", "last_trade_price": ""}, {"market": "0x4d9b924e07c1868f1ae0a71542c5e2945c86c14a04bd846bfe2f0bb95848a67e", "asset_id": "75455801274299235341355169587755995541707405613253743917596982094560194111298", "timestamp": "1769384447685", "hash": "8601a82d4baef737953bbfd176e6c7bea87b5746", "bids": [{"price": "0.01", "size": "212.04"}, {"price": "0.02", "size": "255.48"}, {"price": "0.03", "size": "18.99"}, {"price": "0.05", "size": "23.99"}, {"price": "0.06", "size": "5.47"}], "asks": [{"price": "0.99", "size": "212.04"}, {"price": "0.98", "size": "222.48"}, {"price": "0.97", "size": "18.99"}, {"price": "0.96", "size": "29.99"}], "event_type": "book", "last_trade_price": ""}, {"market": "0xdae2149f65e89818c56124e772eee704f55f1a411482755dba026d4c727af0e4", "asset_id": "5731740857323119517691200242442035314690159130302063918637002279721289590857", "timestamp": "1769384437952", "hash": "767d6f349755d122c1f580c40c76deb8a3dcc12c", "bids": [{"price": "0.01", "size": "67.61"}, {"price": "0.02", "size": "180.95"}, {"price": "0.03", "size": "19.83"}, {"price": "0.04", "size": "5.47"}], "asks": [{"price": "0.99", "size": "62.05"}, {"price": "0.98", "size": "190.48"}, {"price": "0.97", "size": "18.99"}, {"price": "0.96", "size": "29.99"}], "event_type": "book", "last_trade_price": ""}, {"market": "0xc794d53782d2a57779c1bd1d7fe4e1012cd63daa340d6733478b04e43c779bb2", "asset_id": "29850745557425233278441255217116778127787897972791369065729373689355832286173", "timestamp": "1769384437952", "hash": "00565c00e1e561b1fac2c3c5868a634fd7f3a6d5", "bids": [{"price": "0.01", "size": "67.61"}, {"price": "0.02", "size": "180.95"}, {"price": "0.03", "size": "19.83"}, {"price": "0.04", "size": "5.47"}], "asks": [{"price": "0.99", "size": "62.05"}, {"price": "0.98", "size": "190.48"}, {"price": "0.97", "size": "18.99"}, {"price": "0.96", "size": "29.99"}], "event_type": "book", "last_trade_price": ""}, {"market": "0xe2522c3113503fa3310842e464c988b3ee1791790d74e3bbf01ba7abeb25c80f", "asset_id": "58029788945233188177055776782641910265995378981338051319950769448049549823705", "timestamp": "1769384447685", "hash": "9ac404eb7ecd73694655d2bb308088a54e485c6c", "bids": [{"price": "0.01", "size": "162.05"}, {"price": "0.02", "size": "240.48"}, {"price": "0.03", "size": "18.99"}, {"price": "0.04", "size": "29.99"}], "asks": [{"price": "0.99", "size": "169.65"}, {"price": "0.98", "size": "227.66"}, {"price": "0.97", "size": "21.34"}, {"price": "0.95", "size": "23.99"}, {"price": "0.94", "size": "5.47"}], "event_type": "book", "last_trade_price": ""}, {"market": "0x8126b48144a3a336f16d34371f1243ed5cf2f43bf52280d7d77809099971a218", "asset_id": "1008929119197621738578745497318299441163170876973616595128366220594937454664", "timestamp": "1769382949939", "hash": "2cee5ab94642f743fe66da17763fe5995d2c9b4c", "bids": [{"price": "0.01", "size": "3750.56"}, {"price": "0.02", "size": "2100"}, {"price": "0.03", "size": "8.61"}, {"price": "0.05", "size": "1700"}, {"price": "0.08", "size": "700"}, {"price": "0.09", "size": "7.06"}, {"price": "0.14", "size": "200"}, {"price": "0.21", "size": "2000"}, {"price": "0.23", "size": "125"}, {"price": "0.27", "size": "300"}, {"price": "0.31", "size": "200"}, {"price": "0.33", "size": "125"}, {"price": "0.36", "size": "75"}, {"price": "0.48", "size": "150"}, {"price": "0.5", "size": "30"}, {"price": "0.53", "size": "61.87"}, {"price": "0.54", "size": "412"}], "asks": [{"price": "0.99", "size": "3755.38"}, {"price": "0.98", "size": "2100"}, {"price": "0.97", "size": "10.25"}, {"price": "0.95", "size": "1700"}, {"price": "0.91", "size": "700"}, {"price": "0.9", "size": "55.88"}, {"price": "0.83", "size": "300"}, {"price": "0.81", "size": "200"}, {"price": "0.8", "size": "125"}, {"price": "0.78", "size": "75"}, {"price": "0.72", "size": "10"}, {"price": "0.6", "size": "200"}, {"price": "0.57", "size": "135"}, {"price": "0.56", "size": "500"}, {"price": "0.55", "size": "198"}], "event_type": "book", "last_trade_price": "0.540"}, {"market": "0xca6684a2f5b699b04e9da70003381b45faa1a7807748abc7fbca1d689eede3dd", "asset_id": "75435923675834590025716428375190789880766798597634661131343729919797820504690", "timestamp": "1769384355353", "hash": "bf24d5ef7d9a067c2b524d52bbb032127449bce1", "bids": [{"price": "0.01", "size": "109.66"}, {"price": "0.02", "size": "200.63"}, {"price": "0.03", "size": "8.61"}, {"price": "0.04", "size": "10.81"}, {"price": "0.05", "size": "5.47"}], "asks": [{"price": "0.99", "size": "112.04"}, {"price": "0.98", "size": "215.48"}, {"price": "0.97", "size": "18.99"}, {"price": "0.96", "size": "29.99"}], "event_type": "book", "last_trade_price": ""}, {"market": "0x644991b60a94b272357e6f68d1615680703601accb15d7302f499b737d4a0db0", "asset_id": "107742164566063298345228923210014891131960841481018710120513126758098443996397", "timestamp": "1769384437952", "hash": "25e63d68ddf62c7256fa310401c98a80ae8a9ce5", "bids": [{"price": "0.01", "size": "62.05"}, {"price": "0.02", "size": "190.48"}, {"price": "0.03", "size": "18.99"}, {"price": "0.04", "size": "29.99"}], "asks": [{"price": "0.99", "size": "67.61"}, {"price": "0.98", "size": "180.95"}, {"price": "0.97", "size": "19.83"}, {"price": "0.96", "size": "5.47"}], "event_type": "book", "last_trade_price": ""}]}
{"_local_timestamp": "2026-01-25T23:41:27.143936+00:00", "data": {"market": "0x180cee3cb165e04b5556b5f54f156aecdfac62a7f99de19cb6e54247f046d80d", "price_changes": [{"asset_id": "41518792079540460126973298251922654758525254450148908246351858650533815863785", "price": "0.02", "size": "64.48", "side": "BUY", "hash": "b4b62deac670abd6819f28539372d29b15ebdfb6", "best_bid": "0.04", "best_ask": "0.94"}, {"asset_id": "45832756093987475477292835259287296516281710171095995001873781080428505369867", "price": "0.98", "size": "64.48", "side": "SELL", "hash": "a9dbb044dc70575036e1c6c71b9b300880ffb0f9", "best_bid": "0.06", "best_ask": "0.96"}], "timestamp": "1769384487000", "event_type": "price_change"}}
{"_local_timestamp": "2026-01-25T23:41:27.185842+00:00", "data": {"market": "0xc794d53782d2a57779c1bd1d7fe4e1012cd63daa340d6733478b04e43c779bb2", "price_changes": [{"asset_id": "65285709653207321996387925181629862243682185841555542627225011614554527757803", "price": "0.02", "size": "40.48", "side": "BUY", "hash": "da9496e10ab9f1387079314e1274c6b9314426ce", "best_bid": "0.04", "best_ask": "0.96"}, {"asset_id": "29850745557425233278441255217116778127787897972791369065729373689355832286173", "price": "0.98", "size": "40.48", "side": "SELL", "hash": "29351301ea08c8aab7037d59f487e292b0ebeb09", "best_bid": "0.04", "best_ask": "0.96"}], "timestamp": "1769384487000", "event_type": "price_change"}}
{"_local_timestamp": "2026-01-25T23:41:27.187042+00:00", "data": {"market": "0xc794d53782d2a57779c1bd1d7fe4e1012cd63daa340d6733478b04e43c779bb2", "price_changes": [{"asset_id": "29850745557425233278441255217116778127787897972791369065729373689355832286173", "price": "0.02", "size": "30.95", "side": "BUY", "hash": "5cd4dc030984054cbcf481679152481a976e0c86", "best_bid": "0.04", "best_ask": "0.96"}, {"asset_id": "65285709653207321996387925181629862243682185841555542627225011614554527757803", "price": "0.98", "size": "30.95", "side": "SELL", "hash": "841ad6446e5f43fee0767627fce2a849ec7c006f", "best_bid": "0.04", "best_ask": "0.96"}], "timestamp": "1769384487000", "event_type": "price_change"}}
{"_local_timestamp": "2026-01-25T23:41:33.878702+00:00", "data": {"market": "0x180cee3cb165e04b5556b5f54f156aecdfac62a7f99de19cb6e54247f046d80d", "price_changes": [{"asset_id": "41518792079540460126973298251922654758525254450148908246351858650533815863785", "price": "0.02", "size": "214.48", "side": "BUY", "hash": "01f80eb6faea9ed3883afd1ec0ba57a8cc4e1589", "best_bid": "0.04", "best_ask": "0.94"}, {"asset_id": "45832756093987475477292835259287296516281710171095995001873781080428505369867", "price": "0.98", "size": "214.48", "side": "SELL", "hash": "39f866b29b62d5f1296b9baf3c5ed962d431f358", "best_bid": "0.06", "best_ask": "0.96"}], "timestamp": "1769384493754", "event_type": "price_change"}}
{"_local_timestamp": "2026-01-25T23:41:33.888431+00:00", "data": {"market": "0xc794d53782d2a57779c1bd1d7fe4e1012cd63daa340d6733478b04e43c779bb2", "price_changes": [{"asset_id": "29850745557425233278441255217116778127787897972791369065729373689355832286173", "price": "0.02", "size": "180.95", "side": "BUY", "hash": "7db8a8733ee237a77a0de714e56df1beb568792c", "best_bid": "0.04", "best_ask": "0.96"}, {"asset_id": "65285709653207321996387925181629862243682185841555542627225011614554527757803", "price": "0.98", "size": "180.95", "side": "SELL", "hash": "5fc95dbd4799c98ff4832666f3506bcabac5ab73", "best_bid": "0.04", "best_ask": "0.96"}], "timestamp": "1769384493754", "event_type": "price_change"}}
{"_local_timestamp": "2026-01-25T23:41:33.889087+00:00", "data": {"market": "0xc794d53782d2a57779c1bd1d7fe4e1012cd63daa340d6733478b04e43c779bb2", "price_changes": [{"asset_id": "65285709653207321996387925181629862243682185841555542627225011614554527757803", "price": "0.02", "size": "190.48", "side": "BUY", "hash": "475000e01b1b67855915a8bc3863388eae8ae0f3", "best_bid": "0.04", "best_ask": "0.96"}, {"asset_id": "29850745557425233278441255217116778127787897972791369065729373689355832286173", "price": "0.98", "size": "190.48", "side": "SELL", "hash": "244d3d52e64f0f4aa22ef3a9f31238a4fac8212e", "best_bid": "0.04", "best_ask": "0.96"}], "timestamp": "1769384493755", "event_type": "price_change"}}
{"_local_timestamp": "2026-01-25T23:42:06.444683+00:00", "data": {"market": "0x5bb085cf19c81e4c5e288ee70965fd061fb463199a1db6aa73c289c8b5d5b576", "price_changes": [{"asset_id": "94028695263980919862424407658493739709000655590831556337575886476241764379188", "price": "0.05", "size": "0", "side": "BUY", "hash": "298aeba8f397c7e31ea11dea65e4db4486a91ed6", "best_bid": "0.06", "best_ask": "0.96"}, {"asset_id": "3869270757164855312650371225248655982559601630752717256310586548174182218377", "price": "0.95", "size": "0", "side": "SELL", "hash": "b095fef20d248c804ca67d72afe829cba71b5966", "best_bid": "0.04", "best_ask": "0.94"}], "timestamp": "1769384526376", "event_type": "price_change"}}
{"_local_timestamp": "2026-01-25T23:42:06.540043+00:00", "data": {"market": "0xe2522c3113503fa3310842e464c988b3ee1791790d74e3bbf01ba7abeb25c80f", "price_changes": [{"asset_id": "34396356694568550365415333424976689315210304285798066025980709860841157649078", "price": "0.05", "size": "0", "side": "BUY", "hash": "caebcfe8778d7e16202895a21d848b6c7cd74620", "best_bid": "0.06", "best_ask": "0.96"}, {"asset_id": "58029788945233188177055776782641910265995378981338051319950769448049549823705", "price": "0.95", "size": "0", "side": "SELL", "hash": "69ca1a28f638f1c5ca2df62346c6384114695d1d", "best_bid": "0.04", "best_ask": "0.94"}], "timestamp": "1769384526475", "event_type": "price_change"}}
{"_local_timestamp": "2026-01-25T23:42:06.540455+00:00", "data": {"market": "0x180cee3cb165e04b5556b5f54f156aecdfac62a7f99de19cb6e54247f046d80d", "price_changes": [{"asset_id": "45832756093987475477292835259287296516281710171095995001873781080428505369867", "price": "0.05", "size": "0", "side": "BUY", "hash": "2af5e42095a190615dec65635aa52378fe9866a7", "best_bid": "0.06", "best_ask": "0.96"}, {"asset_id": "41518792079540460126973298251922654758525254450148908246351858650533815863785", "price": "0.95", "size": "0", "side": "SELL", "hash": "353e15c6467c35490bc9a0acfedbff9a295234a6", "best_bid": "0.04", "best_ask": "0.94"}], "timestamp": "1769384526475", "event_type": "price_change"}}
{"_local_timestamp": "2026-01-25T23:42:06.540771+00:00", "data": {"market": "0x66aa8a28579a59742b541d7d89f185231e24127d8d54e207d92e66213ed909ef", "price_changes": [{"asset_id": "91423736259203636828645539448680117024524087071143750679349605058506199161826", "price": "0.05", "size": "0", "side": "BUY", "hash": "026b6fdbf3f524d6d6222fab85c90f9e1a30cf88", "best_bid": "0.06", "best_ask": "0.96"}, {"asset_id": "29482259799705002124566483090977991712914260860257479165135371688038751642644", "price": "0.95", "size": "0", "side": "SELL", "hash": "dc729f1bd555e940c8d415b0bd620e71feb000ba", "best_bid": "0.04", "best_ask": "0.94"}], "timestamp": "1769384526475", "event_type": "price_change"}}
{"_local_timestamp": "2026-01-25T23:42:06.636978+00:00", "data": {"market": "0x4d9b924e07c1868f1ae0a71542c5e2945c86c14a04bd846bfe2f0bb95848a67e", "price_changes": [{"asset_id": "75455801274299235341355169587755995541707405613253743917596982094560194111298", "price": "0.05", "size": "0", "side": "BUY", "hash": "33fb6eddff59922202badc155d1b9afc89b6b6ce", "best_bid": "0.06", "best_ask": "0.96"}, {"asset_id": "26562265211720931675265155047873360108835400286939832140681489066284406369537", "price": "0.95", "size": "0", "side": "SELL", "hash": "d8c22cda6ab6b8c803ca775fd1956cdf8e45a75f", "best_bid": "0.04", "best_ask": "0.94"}], "timestamp": "1769384526567", "event_type": "price_change"}}
{"_local_timestamp": "2026-01-25T23:42:07.740984+00:00", "data": {"market": "0xdae2149f65e89818c56124e772eee704f55f1a411482755dba026d4c727af0e4", "price_changes": [{"asset_id": "5731740857323119517691200242442035314690159130302063918637002279721289590857", "price": "0.05", "size": "23.99", "side": "BUY", "hash": "a25adb2394eb233a53b47fcbfa29267fa1b72ec2", "best_bid": "0.05", "best_ask": "0.96"}, {"asset_id": "108539949567612627196500132085967459870136452742815448382213013024762772569343", "price": "0.95", "size": "23.99", "side": "SELL", "hash": "f5ee868b2c1932bf5408caf0a636889432c7612a", "best_bid": "0.04", "best_ask": "0.95"}], "timestamp": "1769384527672", "event_type": "price_change"}}
{"_local_timestamp": "2026-01-25T23:42:07.741509+00:00", "data": {"market": "0x9e546f5bd8aaa57b741386967b6f0cb83ba70ff12cf399a3b104f5ded3e01c33", "price_changes": [{"asset_id": "98748914400722920263495947114807262573236269758480928212643590321888570153891", "price": "0.05", "size": "23.99", "side": "BUY", "hash": "5955e529d3a1265091fe6ee0338a5df59b6798d2", "best_bid": "0.05", "best_ask": "0.96"}, {"asset_id": "52384449694849030011952391984862607032268821842864420008617516574964644205640", "price": "0.95", "size": "23.99", "side": "SELL", "hash": "2091bfa26af5e896f85235aeb9ca633eb02ac08b", "best_bid": "0.04", "best_ask": "0.95"}], "timestamp": "1769384527672", "event_type": "price_change"}}
{"_local_timestamp": "2026-01-25T23:42:07.741905+00:00", "data": {"market": "0x644991b60a94b272357e6f68d1615680703601accb15d7302f499b737d4a0db0", "price_changes": [{"asset_id": "80482043625015601757240447150279689188946061800550924069274579383544776374468", "price": "0.05", "size": "23.99", "side": "BUY", "hash": "8f8858c77b116a31b90ee44b2d631ad89b69f11d", "best_bid": "0.05", "best_ask": "0.96"}, {"asset_id": "107742164566063298345228923210014891131960841481018710120513126758098443996397", "price": "0.95", "size": "23.99", "side": "SELL", "hash": "b6b88404d8674a9558db7cfa5035681a52a927ec", "best_bid": "0.04", "best_ask": "0.95"}], "timestamp": "1769384527672", "event_type": "price_change"}}
{"_local_timestamp": "2026-01-25T23:42:07.742189+00:00", "data": {"market": "0x618f90d78c70081e7dd7d422c3e2299e4a77d35edb8e4258ae0297ddfab14e17", "price_changes": [{"asset_id": "88493938041191305708637957243458880188207866339223186442772420759619853972732", "price": "0.05", "size": "23.99", "side": "BUY", "hash": "3e311aa72fbbc47b617c9a346c402902bc6c4edb", "best_bid": "0.05", "best_ask": "0.96"}, {"asset_id": "630142824528014601903526077196303536591995171166379784723107847019383910560", "price": "0.95", "size": "23.99", "side": "SELL", "hash": "c1b697985ae0a34bd88e850ac13b661be6f8b67f", "best_bid": "0.04", "best_ask": "0.95"}], "timestamp": "1769384527672", "event_type": "price_change"}}
{"_local_timestamp": "2026-01-25T23:42:07.742535+00:00", "data": {"market": "0xc794d53782d2a57779c1bd1d7fe4e1012cd63daa340d6733478b04e43c779bb2", "price_changes": [{"asset_id": "29850745557425233278441255217116778127787897972791369065729373689355832286173", "price": "0.05", "size": "23.99", "side": "BUY", "hash": "206a5b0065610aa3ff832992614607eac6656033", "best_bid": "0.05", "best_ask": "0.96"}, {"asset_id": "65285709653207321996387925181629862243682185841555542627225011614554527757803", "price": "0.95", "size": "23.99", "side": "SELL", "hash": "79c2602e2b3d2746367b0cd351f16cc9be839b90", "best_bid": "0.04", "best_ask": "0.95"}], "timestamp": "1769384527672", "event_type": "price_change"}}
{"_local_timestamp": "2026-01-25T23:42:10.826849+00:00", "data": {"market": "0x66aa8a28579a59742b541d7d89f185231e24127d8d54e207d92e66213ed909ef", "price_changes": [{"asset_id": "91423736259203636828645539448680117024524087071143750679349605058506199161826", "price": "0.06", "size": "0", "side": "BUY", "hash": "eebe10f5eeb8616414be232291c941b36b90b0ec", "best_bid": "0.03", "best_ask": "0.96"}, {"asset_id": "29482259799705002124566483090977991712914260860257479165135371688038751642644", "price": "0.94", "size": "0", "side": "SELL", "hash": "a0943f3ec5a6af017820c3fab8dd15480ac1332c", "best_bid": "0.04", "best_ask": "0.97"}], "timestamp": "1769384530760", "event_type": "price_change"}}
{"_local_timestamp": "2026-01-25T23:42:10.828598+00:00", "data": {"market": "0x618f90d78c70081e7dd7d422c3e2299e4a77d35edb8e4258ae0297ddfab14e17", "price_changes": [{"asset_id": "88493938041191305708637957243458880188207866339223186442772420759619853972732", "price": "0.04", "size": "0", "side": "BUY", "hash": "1d075a28f6c03ea756a9357b0449866f1ce2dd16", "best_bid": "0.05", "best_ask": "0.96"}, {"asset_id": "630142824528014601903526077196303536591995171166379784723107847019383910560", "price": "0.96", "size": "0", "side": "SELL", "hash": "60b512ae5a36a1d82f0329430c453d620a011da7", "best_bid": "0.04", "best_ask": "0.95"}], "timestamp": "1769384530760", "event_type": "price_change"}}
{"_local_timestamp": "2026-01-25T23:42:10.831921+00:00", "data": {"market": "0xe2522c3113503fa3310842e464c988b3ee1791790d74e3bbf01ba7abeb25c80f", "price_changes": [{"asset_id": "34396356694568550365415333424976689315210304285798066025980709860841157649078", "price": "0.06", "size": "0", "side": "BUY", "hash": "5406c966417005012b5e902b4121a01832dfaa73", "best_bid": "0.03", "best_ask": "0.96"}, {"asset_id": "58029788945233188177055776782641910265995378981338051319950769448049549823705", "price": "0.94", "size": "0", "side": "SELL", "hash": "76e65f708b32970722d7386183561ed769a3a8d4", "best_bid": "0.04", "best_ask": "0.97"}], "timestamp": "1769384530760", "event_type": "price_change"}}
{"_local_timestamp": "2026-01-25T23:42:10.832472+00:00", "data": {"market": "0x5bb085cf19c81e4c5e288ee70965fd061fb463199a1db6aa73c289c8b5d5b576", "price_changes": [{"asset_id": "94028695263980919862424407658493739709000655590831556337575886476241764379188", "price": "0.06", "size": "0", "side": "BUY", "hash": "fdd94f6f5393e71a0e7c7f86f4914fac990d27e1", "best_bid": "0.03", "best_ask": "0.96"}, {"asset_id": "3869270757164855312650371225248655982559601630752717256310586548174182218377", "price": "0.94", "size": "0", "side": "SELL", "hash": "54dd1c64c728f152966dbb013fc0e0216c8a0c77", "best_bid": "0.04", "best_ask": "0.97"}], "timestamp": "1769384530760", "event_type": "price_change"}}
{"_local_timestamp": "2026-01-25T23:42:10.833117+00:00", "data": {"market": "0x9e546f5bd8aaa57b741386967b6f0cb83ba70ff12cf399a3b104f5ded3e01c33", "price_changes": [{"asset_id": "98748914400722920263495947114807262573236269758480928212643590321888570153891", "price": "0.04", "size": "0", "side": "BUY", "hash": "c77354e82674d057af33bba134fdd94db3c7411c", "best_bid": "0.05", "best_ask": "0.96"}, {"asset_id": "52384449694849030011952391984862607032268821842864420008617516574964644205640", "price": "0.96", "size": "0", "side": "SELL", "hash": "88713d1d40755babf2fd32eb725649229656833e", "best_bid": "0.04", "best_ask": "0.95"}], "timestamp": "1769384530760", "event_type": "price_change"}}
{"_local_timestamp": "2026-01-25T23:42:10.833632+00:00", "data": {"market": "0x180cee3cb165e04b5556b5f54f156aecdfac62a7f99de19cb6e54247f046d80d", "price_changes": [{"asset_id": "45832756093987475477292835259287296516281710171095995001873781080428505369867", "price": "0.06", "size": "0", "side": "BUY", "hash": "29b269423f24c6c897da5a944447b20428e1c279", "best_bid": "0.03", "best_ask": "0.96"}, {"asset_id": "41518792079540460126973298251922654758525254450148908246351858650533815863785", "price": "0.94", "size": "0", "side": "SELL", "hash": "ed6d171c4c3cc26186e3a65a0ecb8d99e4cc9c92", "best_bid": "0.04", "best_ask": "0.97"}], "timestamp": "1769384530760", "event_type": "price_change"}}
{"_local_timestamp": "2026-01-25T23:42:10.835798+00:00", "data": {"market": "0xc794d53782d2a57779c1bd1d7fe4e1012cd63daa340d6733478b04e43c779bb2", "price_changes": [{"asset_id": "29850745557425233278441255217116778127787897972791369065729373689355832286173", "price": "0.04", "size": "0", "side": "BUY", "hash": "dbe29351d8320e77fbf9f0cdd8c8c45502cef78d", "best_bid": "0.05", "best_ask": "0.96"}, {"asset_id": "65285709653207321996387925181629862243682185841555542627225011614554527757803", "price": "0.96", "size": "0", "side": "SELL", "hash": "97b0679e816054263b6c49b0efcf1abcb34859d5", "best_bid": "0.04", "best_ask": "0.95"}], "timestamp": "1769384530761", "event_type": "price_change"}}
{"_local_timestamp": "2026-01-25T23:42:10.845082+00:00", "data": {"market": "0xdae2149f65e89818c56124e772eee704f55f1a411482755dba026d4c727af0e4", "price_changes": [{"asset_id": "5731740857323119517691200242442035314690159130302063918637002279721289590857", "price": "0.04", "size": "0", "side": "BUY", "hash": "8f6475383368c1385b1d59aa0e653aad6e72d426", "best_bid": "0.05", "best_ask": "0.96"}, {"asset_id": "108539949567612627196500132085967459870136452742815448382213013024762772569343", "price": "0.96", "size": "0", "side": "SELL", "hash": "22ff67e453d7c6a7e8392ac6510b9d1aef5be0ef", "best_bid": "0.04", "best_ask": "0.95"}], "timestamp": "1769384530760", "event_type": "price_change"}}
{"_local_timestamp": "2026-01-25T23:42:10.851895+00:00", "data": {"market": "0x4d9b924e07c1868f1ae0a71542c5e2945c86c14a04bd846bfe2f0bb95848a67e", "price_changes": [{"asset_id": "75455801274299235341355169587755995541707405613253743917596982094560194111298", "price": "0.06", "size": "0", "side": "BUY", "hash": "2b1fb3de2bf387b814eea1dd02c5efa331fcf787", "best_bid": "0.03", "best_ask": "0.96"}, {"asset_id": "26562265211720931675265155047873360108835400286939832140681489066284406369537", "price": "0.94", "size": "0", "side": "SELL", "hash": "179776f2a29463000e1f300e5635f990b951c350", "best_bid": "0.04", "best_ask": "0.97"}], "timestamp": "1769384530761", "event_type": "price_change"}}
{"_local_timestamp": "2026-01-25T23:42:10.861315+00:00", "data": {"market": "0x644991b60a94b272357e6f68d1615680703601accb15d7302f499b737d4a0db0", "price_changes": [{"asset_id": "80482043625015601757240447150279689188946061800550924069274579383544776374468", "price": "0.04", "size": "0", "side": "BUY", "hash": "d3ef7ef5673950b0b91543f8d1de93a9ec0bdbe4", "best_bid": "0.05", "best_ask": "0.96"}, {"asset_id": "107742164566063298345228923210014891131960841481018710120513126758098443996397", "price": "0.96", "size": "0", "side": "SELL", "hash": "2b6bcdf41d33ef02a1f96ce47afe22711a1047dc", "best_bid": "0.04", "best_ask": "0.95"}], "timestamp": "1769384530761", "event_type": "price_change"}}
{"_local_timestamp": "2026-01-25T23:42:11.053052+00:00", "data": {"market": "0xdae2149f65e89818c56124e772eee704f55f1a411482755dba026d4c727af0e4", "price_changes": [{"asset_id": "5731740857323119517691200242442035314690159130302063918637002279721289590857", "price": "0.06", "size": "5.47", "side": "BUY", "hash": "8ade62451b7c55f6734b0875fafe3597886b4d3c", "best_bid": "0.06", "best_ask": "0.96"}, {"asset_id": "108539949567612627196500132085967459870136452742815448382213013024762772569343", "price": "0.94", "size": "5.47", "side": "SELL", "hash": "0eff89ef11de0a62da3ab37b3feb1db643b23a21", "best_bid": "0.04", "best_ask": "0.94"}], "timestamp": "1769384530985", "event_type": "price_change"}}
{"_local_timestamp": "2026-01-25T23:42:11.053642+00:00", "data": {"market": "0x644991b60a94b272357e6f68d1615680703601accb15d7302f499b737d4a0db0", "price_changes": [{"asset_id": "80482043625015601757240447150279689188946061800550924069274579383544776374468", "price": "0.06", "size": "5.47", "side": "BUY", "hash": "53a50c7906030bd8856298ec39f4a580ebcdd4da", "best_bid": "0.06", "best_ask": "0.96"}, {"asset_id": "107742164566063298345228923210014891131960841481018710120513126758098443996397", "price": "0.94", "size": "5.47", "side": "SELL", "hash": "1bd8f21c6ae82ae1c83784e4b0b720ea23951aeb", "best_bid": "0.04", "best_ask": "0.94"}], "timestamp": "1769384530985", "event_type": "price_change"}}
{"_local_timestamp": "2026-01-25T23:42:11.054103+00:00", "data": {"market": "0x618f90d78c70081e7dd7d422c3e2299e4a77d35edb8e4258ae0297ddfab14e17", "price_changes": [{"asset_id": "88493938041191305708637957243458880188207866339223186442772420759619853972732", "price": "0.06", "size": "5.47", "side": "BUY", "hash": "cdcc2dc2851dd91376fb4cb979ede9057b897e76", "best_bid": "0.06", "best_ask": "0.96"}, {"asset_id": "630142824528014601903526077196303536591995171166379784723107847019383910560", "price": "0.94", "size": "5.47", "side": "SELL", "hash": "6bc7251a76ee09cd9974d40b8a05b0b27e3c1bfc", "best_bid": "0.04", "best_ask": "0.94"}], "timestamp": "1769384530985", "event_type": "price_change"}}
{"_local_timestamp": "2026-01-25T23:42:11.054497+00:00", "data": {"market": "0xe2522c3113503fa3310842e464c988b3ee1791790d74e3bbf01ba7abeb25c80f", "price_changes": [{"asset_id": "34396356694568550365415333424976689315210304285798066025980709860841157649078", "price": "0.04", "size": "5.47", "side": "BUY", "hash": "019b43a314a3c4cb3f1851059f5d61ae2ee37a6d", "best_bid": "0.04", "best_ask": "0.96"}, {"asset_id": "58029788945233188177055776782641910265995378981338051319950769448049549823705", "price": "0.96", "size": "5.47", "side": "SELL", "hash": "f8152ec5dc5397faa82fca7fb288662987551f51", "best_bid": "0.04", "best_ask": "0.96"}], "timestamp": "1769384530985", "event_type": "price_change"}}
{"_local_timestamp": "2026-01-25T23:42:11.055403+00:00", "data": {"market": "0xc794d53782d2a57779c1bd1d7fe4e1012cd63daa340d6733478b04e43c779bb2", "price_changes": [{"asset_id": "29850745557425233278441255217116778127787897972791369065729373689355832286173", "price": "0.06", "size": "5.47", "side": "BUY", "hash": "2af0ed1cba379816ff169c2f2e8f09e250e6be63", "best_bid": "0.06", "best_ask": "0.96"}, {"asset_id": "65285709653207321996387925181629862243682185841555542627225011614554527757803", "price": "0.94", "size": "5.47", "side": "SELL", "hash": "afdd5516cfbbd32014de3855c2625cd9f9407e78", "best_bid": "0.04", "best_ask": "0.94"}], "timestamp": "1769384530985", "event_type": "price_change"}}
{"_local_timestamp": "2026-01-25T23:42:11.055748+00:00", "data": {"market": "0x180cee3cb165e04b5556b5f54f156aecdfac62a7f99de19cb6e54247f046d80d", "price_changes": [{"asset_id": "45832756093987475477292835259287296516281710171095995001873781080428505369867", "price": "0.04", "size": "5.47", "side": "BUY", "hash": "37c4535ce35d2dc5c2f1b475c74c3d55102ee0d1", "best_bid": "0.04", "best_ask": "0.96"}, {"asset_id": "41518792079540460126973298251922654758525254450148908246351858650533815863785", "price": "0.96", "size": "5.47", "side": "SELL", "hash": "51bfa93ec0bfc0f156c0749fb96cbc9628305962", "best_bid": "0.04", "best_ask": "0.96"}], "timestamp": "1769384530985", "event_type": "price_change"}}
{"_local_timestamp": "2026-01-25T23:42:11.056142+00:00", "data": {"market": "0x5bb085cf19c81e4c5e288ee70965fd061fb463199a1db6aa73c289c8b5d5b576", "price_changes": [{"asset_id": "94028695263980919862424407658493739709000655590831556337575886476241764379188", "price": "0.04", "size": "5.47", "side": "BUY", "hash": "661e53e1f8b81bcadf79fbefbd8ff0253c747913", "best_bid": "0.04", "best_ask": "0.96"}, {"asset_id": "3869270757164855312650371225248655982559601630752717256310586548174182218377", "price": "0.96", "size": "5.47", "side": "SELL", "hash": "285c2660d4e3762eae8c1e9f066e3a2c8a5bc689", "best_bid": "0.04", "best_ask": "0.96"}], "timestamp": "1769384530985", "event_type": "price_change"}}
{"_local_timestamp": "2026-01-25T23:42:11.060277+00:00", "data": {"market": "0x9e546f5bd8aaa57b741386967b6f0cb83ba70ff12cf399a3b104f5ded3e01c33", "price_changes": [{"asset_id": "98748914400722920263495947114807262573236269758480928212643590321888570153891", "price": "0.06", "size": "5.47", "side": "BUY", "hash": "95443f8b9431afc7fe6b23016d8718eee5e00d94", "best_bid": "0.06", "best_ask": "0.96"}, {"asset_id": "52384449694849030011952391984862607032268821842864420008617516574964644205640", "price": "0.94", "size": "5.47", "side": "SELL", "hash": "5b5fec99e13203d0e092668f9e9bc699b0859d2e", "best_bid": "0.04", "best_ask": "0.94"}], "timestamp": "1769384530985", "event_type": "price_change"}}
{"_local_timestamp": "2026-01-25T23:42:11.091895+00:00", "data": {"market": "0x66aa8a28579a59742b541d7d89f185231e24127d8d54e207d92e66213ed909ef", "price_changes": [{"asset_id": "91423736259203636828645539448680117024524087071143750679349605058506199161826", "price": "0.04", "size": "5.47", "side": "BUY", "hash": "3445e287a46856fff8ea365860d8f9a9d6a42249", "best_bid": "0.04", "best_ask": "0.96"}, {"asset_id": "29482259799705002124566483090977991712914260860257479165135371688038751642644", "price": "0.96", "size": "5.47", "side": "SELL", "hash": "b36b716b8e179f06a77dd9234d6979b1178a6c3f", "best_bid": "0.04", "best_ask": "0.96"}], "timestamp": "1769384531024", "event_type": "price_change"}}
{"_local_timestamp": "2026-01-25T23:42:11.100981+00:00", "data": {"market": "0x4d9b924e07c1868f1ae0a71542c5e2945c86c14a04bd846bfe2f0bb95848a67e", "price_changes": [{"asset_id": "75455801274299235341355169587755995541707405613253743917596982094560194111298", "price": "0.04", "size": "5.47", "side": "BUY", "hash": "d24368f8123a20ba1f51977ed0cf48ac98b8d27a", "best_bid": "0.04", "best_ask": "0.96"}, {"asset_id": "26562265211720931675265155047873360108835400286939832140681489066284406369537", "price": "0.96", "size": "5.47", "side": "SELL", "hash": "c0d665854ab34a89f3dc82491f33f64f44806efb", "best_bid": "0.04", "best_ask": "0.96"}], "timestamp": "1769384531024", "event_type": "price_change"}}
{"_local_timestamp": "2026-01-25T23:43:02.993809+00:00", "data": {"market": "0x618f90d78c70081e7dd7d422c3e2299e4a77d35edb8e4258ae0297ddfab14e17", "price_changes": [{"asset_id": "88493938041191305708637957243458880188207866339223186442772420759619853972732", "price": "0.01", "size": "51.41", "side": "BUY", "hash": "c9ef4c153d8348d48139ba4e276b217a25862363", "best_bid": "0.06", "best_ask": "0.96"}, {"asset_id": "630142824528014601903526077196303536591995171166379784723107847019383910560", "price": "0.99", "size": "51.41", "side": "SELL", "hash": "a0eab29beaf28926b9086fa29bae7e01f195ae56", "best_bid": "0.04", "best_ask": "0.94"}], "timestamp": "1769384582881", "event_type": "price_change"}}
{"_local_timestamp": "2026-01-25T23:43:02.994923+00:00", "data": {"market": "0x618f90d78c70081e7dd7d422c3e2299e4a77d35edb8e4258ae0297ddfab14e17", "price_changes": [{"asset_id": "88493938041191305708637957243458880188207866339223186442772420759619853972732", "price": "0.02", "size": "177.05", "side": "BUY", "hash": "c9ef4c153d8348d48139ba4e276b217a25862363", "best_bid": "0.06", "best_ask": "0.96"}, {"asset_id": "630142824528014601903526077196303536591995171166379784723107847019383910560", "price": "0.98", "size": "177.05", "side": "SELL", "hash": "a0eab29beaf28926b9086fa29bae7e01f195ae56", "best_bid": "0.04", "best_ask": "0.94"}], "timestamp": "1769384582881", "event_type": "price_change"}}
{"_local_timestamp": "2026-01-25T23:43:02.995340+00:00", "data": {"market": "0x618f90d78c70081e7dd7d422c3e2299e4a77d35edb8e4258ae0297ddfab14e17", "price_changes": [{"asset_id": "88493938041191305708637957243458880188207866339223186442772420759619853972732", "price": "0.03", "size": "8.97", "side": "BUY", "hash": "c9ef4c153d8348d48139ba4e276b217a25862363", "best_bid": "0.06", "best_ask": "0.96"}, {"asset_id": "630142824528014601903526077196303536591995171166379784723107847019383910560", "price": "0.97", "size": "8.97", "side": "SELL", "hash": "a0eab29beaf28926b9086fa29bae7e01f195ae56", "best_bid": "0.04", "best_ask": "0.94"}], "timestamp": "1769384582881", "event_type": "price_change"}}
{"_local_timestamp": "2026-01-25T23:43:03.661688+00:00", "data": {"market": "0x618f90d78c70081e7dd7d422c3e2299e4a77d35edb8e4258ae0297ddfab14e17", "price_changes": [{"asset_id": "88493938041191305708637957243458880188207866339223186442772420759619853972732", "price": "0.06", "size": "12.98", "side": "BUY", "hash": "62e2116db432a6f64f9183c05250601d0069023e", "best_bid": "0.06", "best_ask": "0.96"}, {"asset_id": "630142824528014601903526077196303536591995171166379784723107847019383910560", "price": "0.94", "size": "12.98", "side": "SELL", "hash": "b2a6f678c1078a2aa3973469005f7519fc21e702", "best_bid": "0.04", "best_ask": "0.94"}], "timestamp": "1769384583556", "event_type": "price_change"}}
{"_local_timestamp": "2026-01-25T23:43:03.669914+00:00", "data": {"market": "0x618f90d78c70081e7dd7d422c3e2299e4a77d35edb8e4258ae0297ddfab14e17", "price_changes": [{"asset_id": "88493938041191305708637957243458880188207866339223186442772420759619853972732", "price": "0.01", "size": "62.9", "side": "BUY", "hash": "db4ca9c02466418c3ddea2d76ee1c9e201c92493", "best_bid": "0.06", "best_ask": "0.96"}, {"asset_id": "630142824528014601903526077196303536591995171166379784723107847019383910560", "price": "0.99", "size": "62.9", "side": "SELL", "hash": "694674ba75cbf0da5033140fdca81add3238b50f", "best_bid": "0.04", "best_ask": "0.94"}], "timestamp": "1769384583562", "event_type": "price_change"}}
{"_local_timestamp": "2026-01-25T23:43:03.998834+00:00", "data": {"market": "0xdae2149f65e89818c56124e772eee704f55f1a411482755dba026d4c727af0e4", "price_changes": [{"asset_id": "5731740857323119517691200242442035314690159130302063918637002279721289590857", "price": "0.01", "size": "51.47", "side": "BUY", "hash": "f2a8ad972bc87721522222d5b962ec223978bd98", "best_bid": "0.06", "best_ask": "0.96"}, {"asset_id": "108539949567612627196500132085967459870136452742815448382213013024762772569343", "price": "0.99", "size": "51.47", "side": "SELL", "hash": "5b68bb9efdb2420c6cd21eb612cb39c5d166af48", "best_bid": "0.04", "best_ask": "0.94"}], "timestamp": "1769384583904", "event_type": "price_change"}}
{"_local_timestamp": "2026-01-25T23:43:03.999328+00:00", "data": {"market": "0x644991b60a94b272357e6f68d1615680703601accb15d7302f499b737d4a0db0", "price_changes": [{"asset_id": "80482043625015601757240447150279689188946061800550924069274579383544776374468", "price": "0.01", "size": "51.47", "side": "BUY", "hash": "645b08fb00dfe77f8ff41e91cc50c522f3383c24", "best_bid": "0.06", "best_ask": "0.96"}, {"asset_id": "107742164566063298345228923210014891131960841481018710120513126758098443996397", "price": "0.99", "size": "51.47", "side": "SELL", "hash": "1e4a2b0b4b509671df2f49182ece1e553d4faf0a", "best_bid": "0.04", "best_ask": "0.94"}], "timestamp": "1769384583904", "event_type": "price_change"}}
{"_local_timestamp": "2026-01-25T23:43:03.999709+00:00", "data": {"market": "0xdae2149f65e89818c56124e772eee704f55f1a411482755dba026d4c727af0e4", "price_changes": [{"asset_id": "5731740857323119517691200242442035314690159130302063918637002279721289590857", "price": "0.03", "size": "9.81", "side": "BUY", "hash": "f2a8ad972bc87721522222d5b962ec223978bd98", "best_bid": "0.06", "best_ask": "0.96"}, {"asset_id": "108539949567612627196500132085967459870136452742815448382213013024762772569343", "price": "0.97", "size": "9.81", "side": "SELL", "hash": "5b68bb9efdb2420c6cd21eb612cb39c5d166af48", "best_bid": "0.04", "best_ask": "0.94"}], "timestamp": "1769384583904", "event_type": "price_change"}}
{"_local_timestamp": "2026-01-25T23:43:04.000359+00:00", "data": {"market": "0x644991b60a94b272357e6f68d1615680703601accb15d7302f499b737d4a0db0", "price_changes": [{"asset_id": "80482043625015601757240447150279689188946061800550924069274579383544776374468", "price": "0.03", "size": "9.81", "side": "BUY", "hash": "645b08fb00dfe77f8ff41e91cc50c522f3383c24", "best_bid": "0.06", "best_ask": "0.96"}, {"asset_id": "107742164566063298345228923210014891131960841481018710120513126758098443996397", "price": "0.97", "size": "9.81", "side": "SELL", "hash": "1e4a2b0b4b509671df2f49182ece1e553d4faf0a", "best_bid": "0.04", "best_ask": "0.94"}], "timestamp": "1769384583904", "event_type": "price_change"}}
{"_local_timestamp": "2026-01-25T23:43:05.191283+00:00", "data": {"market": "0xdae2149f65e89818c56124e772eee704f55f1a411482755dba026d4c727af0e4", "price_changes": [{"asset_id": "5731740857323119517691200242442035314690159130302063918637002279721289590857", "price": "0.01", "size": "60.8", "side": "BUY", "hash": "81dcbcffbd4df612f9764d3eb2eedaa036161116", "best_bid": "0.06", "best_ask": "0.96"}, {"asset_id": "108539949567612627196500132085967459870136452742815448382213013024762772569343", "price": "0.99", "size": "60.8", "side": "SELL", "hash": "b12047e71b9b79b29023c4e1abbbb91ff6183986", "best_bid": "0.04", "best_ask": "0.94"}], "timestamp": "1769384585050", "event_type": "price_change"}}
{"_local_timestamp": "2026-01-25T23:43:05.191812+00:00", "data": {"market": "0x644991b60a94b272357e6f68d1615680703601accb15d7302f499b737d4a0db0", "price_changes": [{"asset_id": "80482043625015601757240447150279689188946061800550924069274579383544776374468", "price": "0.01", "size": "60.8", "side": "BUY", "hash": "df617b6af6ddb4d146ab7548dd75a2a75494de13", "best_bid": "0.06", "best_ask": "0.96"}, {"asset_id": "107742164566063298345228923210014891131960841481018710120513126758098443996397", "price": "0.99", "size": "60.8", "side": "SELL", "hash": "e3afc2a4d11e2e879680c28b580786ba1e86fc3d", "best_bid": "0.04", "best_ask": "0.94"}], "timestamp": "1769384585050", "event_type": "price_change"}}
{"_local_timestamp": "2026-01-25T23:43:05.193226+00:00", "data": {"market": "0xdae2149f65e89818c56124e772eee704f55f1a411482755dba026d4c727af0e4", "price_changes": [{"asset_id": "5731740857323119517691200242442035314690159130302063918637002279721289590857", "price": "0.06", "size": "11.61", "side": "BUY", "hash": "9225329044b14a38872464124513ebdd00017483", "best_bid": "0.06", "best_ask": "0.96"}, {"asset_id": "108539949567612627196500132085967459870136452742815448382213013024762772569343", "price": "0.94", "size": "11.61", "side": "SELL", "hash": "973d8a5fead1dfe481f79790fee657d75769e200", "best_bid": "0.04", "best_ask": "0.94"}], "timestamp": "1769384585051", "event_type": "price_change"}}
{"_local_timestamp": "2026-01-25T23:43:05.193687+00:00", "data": {"market": "0x644991b60a94b272357e6f68d1615680703601accb15d7302f499b737d4a0db0", "price_changes": [{"asset_id": "80482043625015601757240447150279689188946061800550924069274579383544776374468", "price": "0.06", "size": "11.61", "side": "BUY", "hash": "665f392058da3270b166f3710808a4a27111334b", "best_bid": "0.06", "best_ask": "0.96"}, {"asset_id": "107742164566063298345228923210014891131960841481018710120513126758098443996397", "price": "0.94", "size": "11.61", "side": "SELL", "hash": "6492582ec64c2ec477b20da08a954c5b8cff4fd9", "best_bid": "0.04", "best_ask": "0.94"}], "timestamp": "1769384585051", "event_type": "price_change"}}
{"_local_timestamp": "2026-01-25T23:43:06.411945+00:00", "data": {"market": "0x9e546f5bd8aaa57b741386967b6f0cb83ba70ff12cf399a3b104f5ded3e01c33", "price_changes": [{"asset_id": "98748914400722920263495947114807262573236269758480928212643590321888570153891", "price": "0.01", "size": "51.46", "side": "BUY", "hash": "039fbb152ce8dd1416059d5a1795a10735d11cda", "best_bid": "0.06", "best_ask": "0.96"}, {"asset_id": "52384449694849030011952391984862607032268821842864420008617516574964644205640", "price": "0.99", "size": "51.46", "side": "SELL", "hash": "d3fc13004845ad2644245a2ae4b16e5e35ba10d9", "best_bid": "0.04", "best_ask": "0.94"}], "timestamp": "1769384586317", "event_type": "price_change"}}
{"_local_timestamp": "2026-01-25T23:43:06.412413+00:00", "data": {"market": "0x9e546f5bd8aaa57b741386967b6f0cb83ba70ff12cf399a3b104f5ded3e01c33", "price_changes": [{"asset_id": "98748914400722920263495947114807262573236269758480928212643590321888570153891", "price": "0.03", "size": "9.81", "side": "BUY", "hash": "039fbb152ce8dd1416059d5a1795a10735d11cda", "best_bid": "0.06", "best_ask": "0.96"}, {"asset_id": "52384449694849030011952391984862607032268821842864420008617516574964644205640", "price": "0.97", "size": "9.81", "side": "SELL", "hash": "d3fc13004845ad2644245a2ae4b16e5e35ba10d9", "best_bid": "0.04", "best_ask": "0.94"}], "timestamp": "1769384586317", "event_type": "price_change"}}
{"_local_timestamp": "2026-01-25T23:43:07.043261+00:00", "data": {"market": "0x9e546f5bd8aaa57b741386967b6f0cb83ba70ff12cf399a3b104f5ded3e01c33", "price_changes": [{"asset_id": "98748914400722920263495947114807262573236269758480928212643590321888570153891", "price": "0.01", "size": "60.47", "side": "BUY", "hash": "d48ada40313a24b50a2974d532558acf6ae1a863", "best_bid": "0.06", "best_ask": "0.96"}, {"asset_id": "52384449694849030011952391984862607032268821842864420008617516574964644205640", "price": "0.99", "size": "60.47", "side": "SELL", "hash": "97331c25b3be06948c1485a98644b7282fc7ce24", "best_bid": "0.04", "best_ask": "0.94"}], "timestamp": "1769384586955", "event_type": "price_change"}}
{"_local_timestamp": "2026-01-25T23:43:07.043761+00:00", "data": {"market": "0x9e546f5bd8aaa57b741386967b6f0cb83ba70ff12cf399a3b104f5ded3e01c33", "price_changes": [{"asset_id": "98748914400722920263495947114807262573236269758480928212643590321888570153891", "price": "0.04", "size": "6.71", "side": "BUY", "hash": "6881719c8d510cc4d6ff5d070b7aa08f7b5bad1d", "best_bid": "0.06", "best_ask": "0.96"}, {"asset_id": "52384449694849030011952391984862607032268821842864420008617516574964644205640", "price": "0.96", "size": "6.71", "side": "SELL", "hash": "31fa92ed3aa6589068c342cb704a7c830dd0529d", "best_bid": "0.04", "best_ask": "0.94"}], "timestamp": "1769384586956", "event_type": "price_change"}}
{"_local_timestamp": "2026-01-25T23:43:07.044324+00:00", "data": {"market": "0x9e546f5bd8aaa57b741386967b6f0cb83ba70ff12cf399a3b104f5ded3e01c33", "price_changes": [{"asset_id": "98748914400722920263495947114807262573236269758480928212643590321888570153891", "price": "0.02", "size": "186.11", "side": "BUY", "hash": "4185e92dc466290889390be2724766e2e1df393f", "best_bid": "0.06", "best_ask": "0.96"}, {"asset_id": "52384449694849030011952391984862607032268821842864420008617516574964644205640", "price": "0.98", "size": "186.11", "side": "SELL", "hash": "93c0665071fe5d9ec07871528945bc0fd2bbbe35", "best_bid": "0.04", "best_ask": "0.94"}], "timestamp": "1769384586956", "event_type": "price_change"}}
{"_local_timestamp": "2026-01-25T23:43:12.972421+00:00", "data": {"market": "0xc794d53782d2a57779c1bd1d7fe4e1012cd63daa340d6733478b04e43c779bb2", "price_changes": [{"asset_id": "29850745557425233278441255217116778127787897972791369065729373689355832286173", "price": "0.01", "size": "51.47", "side": "BUY", "hash": "7a5c4746d80fe0c69ac1feef04d9f474acd453b1", "best_bid": "0.06", "best_ask": "0.96"}, {"asset_id": "65285709653207321996387925181629862243682185841555542627225011614554527757803", "price": "0.99", "size": "51.47", "side": "SELL", "hash": "2707805e88e30295a87a932b8fd969cd30d878a2", "best_bid": "0.04", "best_ask": "0.94"}], "timestamp": "1769384592843", "event_type": "price_change"}}
{"_local_timestamp": "2026-01-25T23:43:12.972964+00:00", "data": {"market": "0xc794d53782d2a57779c1bd1d7fe4e1012cd63daa340d6733478b04e43c779bb2", "price_changes": [{"asset_id": "29850745557425233278441255217116778127787897972791369065729373689355832286173", "price": "0.03", "size": "9.81", "side": "BUY", "hash": "7a5c4746d80fe0c69ac1feef04d9f474acd453b1", "best_bid": "0.06", "best_ask": "0.96"}, {"asset_id": "65285709653207321996387925181629862243682185841555542627225011614554527757803", "price": "0.97", "size": "9.81", "side": "SELL", "hash": "2707805e88e30295a87a932b8fd969cd30d878a2", "best_bid": "0.04", "best_ask": "0.94"}], "timestamp": "1769384592843", "event_type": "price_change"}}
{"_local_timestamp": "2026-01-25T23:43:13.665655+00:00", "data": {"market": "0xc794d53782d2a57779c1bd1d7fe4e1012cd63daa340d6733478b04e43c779bb2", "price_changes": [{"asset_id": "29850745557425233278441255217116778127787897972791369065729373689355832286173", "price": "0.01", "size": "60.8", "side": "BUY", "hash": "d90eda3fba1fb8bfa4eda38219c22b0e6d356483", "best_bid": "0.06", "best_ask": "0.96"}, {"asset_id": "65285709653207321996387925181629862243682185841555542627225011614554527757803", "price": "0.99", "size": "60.8", "side": "SELL", "hash": "6219e2146811df2e7188734e7b993af477907a56", "best_bid": "0.04", "best_ask": "0.94"}], "timestamp": "1769384593513", "event_type": "price_change"}}
{"_local_timestamp": "2026-01-25T23:43:13.666153+00:00", "data": {"market": "0xc794d53782d2a57779c1bd1d7fe4e1012cd63daa340d6733478b04e43c779bb2", "price_changes": [{"asset_id": "29850745557425233278441255217116778127787897972791369065729373689355832286173", "price": "0.06", "size": "11.61", "side": "BUY", "hash": "1679b2846cbf0cb72124899e98a399c13812039a", "best_bid": "0.06", "best_ask": "0.96"}, {"asset_id": "65285709653207321996387925181629862243682185841555542627225011614554527757803", "price": "0.94", "size": "11.61", "side": "SELL", "hash": "def6b3fa77a7a385b983b89db43f8c00bd8cd15b", "best_bid": "0.04", "best_ask": "0.94"}], "timestamp": "1769384593514", "event_type": "price_change"}}
{"_local_timestamp": "2026-01-25T23:43:15.320888+00:00", "data": {"market": "0xe2522c3113503fa3310842e464c988b3ee1791790d74e3bbf01ba7abeb25c80f", "price_changes": [{"asset_id": "34396356694568550365415333424976689315210304285798066025980709860841157649078", "price": "0.01", "size": "156.93", "side": "BUY", "hash": "d8bfbb220c5918af42e7781eee2179188065bcef", "best_bid": "0.04", "best_ask": "0.96"}, {"asset_id": "58029788945233188177055776782641910265995378981338051319950769448049549823705", "price": "0.99", "size": "156.93", "side": "SELL", "hash": "3f40449b16b9b31834bd70074f0c741f872a14dc", "best_bid": "0.04", "best_ask": "0.96"}], "timestamp": "1769384595183", "event_type": "price_change"}}
{"_local_timestamp": "2026-01-25T23:43:15.668983+00:00", "data": {"market": "0xe2522c3113503fa3310842e464c988b3ee1791790d74e3bbf01ba7abeb25c80f", "price_changes": [{"asset_id": "34396356694568550365415333424976689315210304285798066025980709860841157649078", "price": "0.01", "size": "169.65", "side": "BUY", "hash": "994c5f9d81987f28ffca762e27f6fcd703fa795b", "best_bid": "0.04", "best_ask": "0.96"}, {"asset_id": "58029788945233188177055776782641910265995378981338051319950769448049549823705", "price": "0.99", "size": "169.65", "side": "SELL", "hash": "87321846d9c1cd42e81acc4a7e71b5d30ea7c0f7", "best_bid": "0.04", "best_ask": "0.96"}], "timestamp": "1769384595533", "event_type": "price_change"}}
{"_local_timestamp": "2026-01-25T23:43:22.645433+00:00", "data": {"market": "0xca6684a2f5b699b04e9da70003381b45faa1a7807748abc7fbca1d689eede3dd", "price_changes": [{"asset_id": "75435923675834590025716428375190789880766798597634661131343729919797820504690", "price": "0.04", "size": "0", "side": "BUY", "hash": "e19d3e69204932fca0e27a30750458d0d583eb1d", "best_bid": "0.05", "best_ask": "0.96"}, {"asset_id": "67923079595575445284641976004414570715798135735376672166638592297910878774957", "price": "0.96", "size": "0", "side": "SELL", "hash": "bd8a931f0e4b5655d5235f1ee7332aeae4f13afd", "best_bid": "0.04", "best_ask": "0.95"}], "timestamp": "1769384602516", "event_type": "price_change"}}
{"_local_timestamp": "2026-01-25T23:43:22.903281+00:00", "data": {"market": "0xca6684a2f5b699b04e9da70003381b45faa1a7807748abc7fbca1d689eede3dd", "price_changes": [{"asset_id": "75435923675834590025716428375190789880766798597634661131343729919797820504690", "price": "0.03", "size": "23.02", "side": "BUY", "hash": "deaa904039ff907cf2a71de760c12501fad8a98e", "best_bid": "0.05", "best_ask": "0.96"}, {"asset_id": "67923079595575445284641976004414570715798135735376672166638592297910878774957", "price": "0.97", "size": "23.02", "side": "SELL", "hash": "f5805c5cd82d46d34992d6d218653dc334b2e187", "best_bid": "0.04", "best_ask": "0.95"}], "timestamp": "1769384602767", "event_type": "price_change"}}
{"_local_timestamp": "2026-01-25T23:43:27.259447+00:00", "data": {"market": "0xca6684a2f5b699b04e9da70003381b45faa1a7807748abc7fbca1d689eede3dd", "price_changes": [{"asset_id": "75435923675834590025716428375190789880766798597634661131343729919797820504690", "price": "0.05", "size": "0", "side": "BUY", "hash": "43410a373e44d5b76e01d8182b0f4381b47beb52", "best_bid": "0.03", "best_ask": "0.96"}, {"asset_id": "67923079595575445284641976004414570715798135735376672166638592297910878774957", "price": "0.95", "size": "0", "side": "SELL", "hash": "431ad9b41eb3f1e2016e50e4263d181790b7f353", "best_bid": "0.04", "best_ask": "0.97"}], "timestamp": "1769384607118", "event_type": "price_change"}}
{"_local_timestamp": "2026-01-25T23:43:27.293660+00:00", "data": {"market": "0xca6684a2f5b699b04e9da70003381b45faa1a7807748abc7fbca1d689eede3dd", "price_changes": [{"asset_id": "75435923675834590025716428375190789880766798597634661131343729919797820504690", "price": "0.04", "size": "5.47", "side": "BUY", "hash": "93b16389143eab63dec1007e3218c8b2768b8333", "best_bid": "0.04", "best_ask": "0.96"}, {"asset_id": "67923079595575445284641976004414570715798135735376672166638592297910878774957", "price": "0.96", "size": "5.47", "side": "SELL", "hash": "68fdb0c935d86be783df09141c2ff8fcfbbf0516", "best_bid": "0.04", "best_ask": "0.96"}], "timestamp": "1769384607152", "event_type": "price_change"}}
{"_local_timestamp": "2026-01-25T23:43:35.046656+00:00", "data": {"market": "0xdae2149f65e89818c56124e772eee704f55f1a411482755dba026d4c727af0e4", "price_changes": [{"asset_id": "5731740857323119517691200242442035314690159130302063918637002279721289590857", "price": "0.05", "size": "0", "side": "BUY", "hash": "4e854acaa8cda40258711973ab9ee9cbea36c6a2", "best_bid": "0.06", "best_ask": "0.96"}, {"asset_id": "108539949567612627196500132085967459870136452742815448382213013024762772569343", "price": "0.95", "size": "0", "side": "SELL", "hash": "f53ae3c1d502e6966b19db06ddaf60fa23e99501", "best_bid": "0.04", "best_ask": "0.94"}], "timestamp": "1769384614926", "event_type": "price_change"}}
{"_local_timestamp": "2026-01-25T23:43:35.048048+00:00", "data": {"market": "0x644991b60a94b272357e6f68d1615680703601accb15d7302f499b737d4a0db0", "price_changes": [{"asset_id": "80482043625015601757240447150279689188946061800550924069274579383544776374468", "price": "0.05", "size": "0", "side": "BUY", "hash": "4651105a69c27d48cd62532af66f0628857614ab", "best_bid": "0.06", "best_ask": "0.96"}, {"asset_id": "107742164566063298345228923210014891131960841481018710120513126758098443996397", "price": "0.95", "size": "0", "side": "SELL", "hash": "c41ca668b13835a3f65eb215845d2f8df03e151a", "best_bid": "0.04", "best_ask": "0.94"}], "timestamp": "1769384614926", "event_type": "price_change"}}
{"_local_timestamp": "2026-01-25T23:43:35.048726+00:00", "data": {"market": "0x9e546f5bd8aaa57b741386967b6f0cb83ba70ff12cf399a3b104f5ded3e01c33", "price_changes": [{"asset_id": "98748914400722920263495947114807262573236269758480928212643590321888570153891", "price": "0.05", "size": "0", "side": "BUY", "hash": "30617f1127e7fd2f1109be649de6fa2c4013ebc0", "best_bid": "0.06", "best_ask": "0.96"}, {"asset_id": "52384449694849030011952391984862607032268821842864420008617516574964644205640", "price": "0.95", "size": "0", "side": "SELL", "hash": "4e4ff6d607d3f6360639d6f03fe4cd70f2141709", "best_bid": "0.04", "best_ask": "0.94"}], "timestamp": "1769384614926", "event_type": "price_change"}}
{"_local_timestamp": "2026-01-25T23:43:35.052161+00:00", "data": {"market": "0x618f90d78c70081e7dd7d422c3e2299e4a77d35edb8e4258ae0297ddfab14e17", "price_changes": [{"asset_id": "88493938041191305708637957243458880188207866339223186442772420759619853972732", "price": "0.05", "size": "0", "side": "BUY", "hash": "4416f01f7341376c171d60d630588f69e0c3e745", "best_bid": "0.06", "best_ask": "0.96"}, {"asset_id": "630142824528014601903526077196303536591995171166379784723107847019383910560", "price": "0.95", "size": "0", "side": "SELL", "hash": "456571adce8e02da1e559294464163c6ee5ebd07", "best_bid": "0.04", "best_ask": "0.94"}], "timestamp": "1769384614926", "event_type": "price_change"}}
{"_local_timestamp": "2026-01-25T23:43:35.146091+00:00", "data": {"market": "0xc794d53782d2a57779c1bd1d7fe4e1012cd63daa340d6733478b04e43c779bb2", "price_changes": [{"asset_id": "29850745557425233278441255217116778127787897972791369065729373689355832286173", "price": "0.05", "size": "0", "side": "BUY", "hash": "bd295dc8b5aad0a2ca244f54e8af352dd2c2359d", "best_bid": "0.06", "best_ask": "0.96"}, {"asset_id": "65285709653207321996387925181629862243682185841555542627225011614554527757803", "price": "0.95", "size": "0", "side": "SELL", "hash": "2c7b8c09d0c340430aa8e6d4eb0a186257e037a6", "best_bid": "0.04", "best_ask": "0.94"}], "timestamp": "1769384615027", "event_type": "price_change"}}
{"_local_timestamp": "2026-01-25T23:43:35.830309+00:00", "data": {"market": "0xe2522c3113503fa3310842e464c988b3ee1791790d74e3bbf01ba7abeb25c80f", "price_changes": [{"asset_id": "34396356694568550365415333424976689315210304285798066025980709860841157649078", "price": "0.05", "size": "23.99", "side": "BUY", "hash": "6f83ccae967fa4a34ad36f5cfda86072999d6138", "best_bid": "0.05", "best_ask": "0.96"}, {"asset_id": "58029788945233188177055776782641910265995378981338051319950769448049549823705", "price": "0.95", "size": "23.99", "side": "SELL", "hash": "209f763c3750da9e240ab394a7537f983a7a4007", "best_bid": "0.04", "best_ask": "0.95"}], "timestamp": "1769384615698", "event_type": "price_change"}}
{"_local_timestamp": "2026-01-25T23:43:35.830843+00:00", "data": {"market": "0x5bb085cf19c81e4c5e288ee70965fd061fb463199a1db6aa73c289c8b5d5b576", "price_changes": [{"asset_id": "94028695263980919862424407658493739709000655590831556337575886476241764379188", "price": "0.05", "size": "23.99", "side": "BUY", "hash": "55e63cc69a885aa1c57a153345a3f37aa128c456", "best_bid": "0.05", "best_ask": "0.96"}, {"asset_id": "3869270757164855312650371225248655982559601630752717256310586548174182218377", "price": "0.95", "size": "23.99", "side": "SELL", "hash": "e912d9a29456e0af633f37509a8528ef456a9f56", "best_bid": "0.04", "best_ask": "0.95"}], "timestamp": "1769384615698", "event_type": "price_change"}}
{"_local_timestamp": "2026-01-25T23:43:35.831280+00:00", "data": {"market": "0x66aa8a28579a59742b541d7d89f185231e24127d8d54e207d92e66213ed909ef", "price_changes": [{"asset_id": "91423736259203636828645539448680117024524087071143750679349605058506199161826", "price": "0.05", "size": "23.99", "side": "BUY", "hash": "becba304e2792c0de7c13378428ecaf183ddd105", "best_bid": "0.05", "best_ask": "0.96"}, {"asset_id": "29482259799705002124566483090977991712914260860257479165135371688038751642644", "price": "0.95", "size": "23.99", "side": "SELL", "hash": "aefed87561ce042b7dd0df03e80b83ae5a7e25ba", "best_bid": "0.04", "best_ask": "0.95"}], "timestamp": "1769384615698", "event_type": "price_change"}}
{"_local_timestamp": "2026-01-25T23:43:35.942356+00:00", "data": {"market": "0x180cee3cb165e04b5556b5f54f156aecdfac62a7f99de19cb6e54247f046d80d", "price_changes": [{"asset_id": "45832756093987475477292835259287296516281710171095995001873781080428505369867", "price": "0.05", "size": "23.99", "side": "BUY", "hash": "0cf13f4298fe7cd6d3bdc02298d872d62b836076", "best_bid": "0.05", "best_ask": "0.96"}, {"asset_id": "41518792079540460126973298251922654758525254450148908246351858650533815863785", "price": "0.95", "size": "23.99", "side": "SELL", "hash": "2a197dfa128bbcded63d969929c209dd4cd3870c", "best_bid": "0.04", "best_ask": "0.95"}], "timestamp": "1769384615799", "event_type": "price_change"}}
{"_local_timestamp": "2026-01-25T23:43:36.031323+00:00", "data": {"market": "0x4d9b924e07c1868f1ae0a71542c5e2945c86c14a04bd846bfe2f0bb95848a67e", "price_changes": [{"asset_id": "75455801274299235341355169587755995541707405613253743917596982094560194111298", "price": "0.05", "size": "23.99", "side": "BUY", "hash": "1a39a57f00b96dd76b31eeda0d61edbd42bd4e91", "best_bid": "0.05", "best_ask": "0.96"}, {"asset_id": "26562265211720931675265155047873360108835400286939832140681489066284406369537", "price": "0.95", "size": "23.99", "side": "SELL", "hash": "726ef209ef4c1388ca507138fa73bf95768cd165", "best_bid": "0.04", "best_ask": "0.95"}], "timestamp": "1769384615895", "event_type": "price_change"}}
{"_local_timestamp": "2026-01-25T23:43:39.925136+00:00", "data": {"market": "0x4d9b924e07c1868f1ae0a71542c5e2945c86c14a04bd846bfe2f0bb95848a67e", "price_changes": [{"asset_id": "75455801274299235341355169587755995541707405613253743917596982094560194111298", "price": "0.04", "size": "0", "side": "BUY", "hash": "c1be102e52fac7de7728e78fb88c83509487ea58", "best_bid": "0.05", "best_ask": "0.96"}, {"asset_id": "26562265211720931675265155047873360108835400286939832140681489066284406369537", "price": "0.96", "size": "0", "side": "SELL", "hash": "d93df44ea3130a1568253893a1dffa82d3cf6862", "best_bid": "0.04", "best_ask": "0.95"}], "timestamp": "1769384619812", "event_type": "price_change"}}
{"_local_timestamp": "2026-01-25T23:43:39.939041+00:00", "data": {"market": "0x5bb085cf19c81e4c5e288ee70965fd061fb463199a1db6aa73c289c8b5d5b576", "price_changes": [{"asset_id": "94028695263980919862424407658493739709000655590831556337575886476241764379188", "price": "0.04", "size": "0", "side": "BUY", "hash": "b195ae06ba7232c6561fd7de124586e26e137785", "best_bid": "0.05", "best_ask": "0.96"}, {"asset_id": "3869270757164855312650371225248655982559601630752717256310586548174182218377", "price": "0.96", "size": "0", "side": "SELL", "hash": "8a3b26e4930e7c719b217e6eda552ab2375c7da9", "best_bid": "0.04", "best_ask": "0.95"}], "timestamp": "1769384619812", "event_type": "price_change"}}
{"_local_timestamp": "2026-01-25T23:43:39.939615+00:00", "data": {"market": "0x180cee3cb165e04b5556b5f54f156aecdfac62a7f99de19cb6e54247f046d80d", "price_changes": [{"asset_id": "45832756093987475477292835259287296516281710171095995001873781080428505369867", "price": "0.04", "size": "0", "side": "BUY", "hash": "3559d30bea639eb2998329770680db96006a15af", "best_bid": "0.05", "best_ask": "0.96"}, {"asset_id": "41518792079540460126973298251922654758525254450148908246351858650533815863785", "price": "0.96", "size": "0", "side": "SELL", "hash": "95e10cdb41e7db9dfc0604decd56843ffc9a7a70", "best_bid": "0.04", "best_ask": "0.95"}], "timestamp": "1769384619812", "event_type": "price_change"}}
{"_local_timestamp": "2026-01-25T23:43:39.942617+00:00", "data": {"market": "0x9e546f5bd8aaa57b741386967b6f0cb83ba70ff12cf399a3b104f5ded3e01c33", "price_changes": [{"asset_id": "98748914400722920263495947114807262573236269758480928212643590321888570153891", "price": "0.06", "size": "0", "side": "BUY", "hash": "98bf4bd455b49366d2ea9e1ea68b144302f8a1ec", "best_bid": "0.04", "best_ask": "0.96"}, {"asset_id": "52384449694849030011952391984862607032268821842864420008617516574964644205640", "price": "0.94", "size": "0", "side": "SELL", "hash": "3c4eded41bce433032cc3a64281ee7a72ba718a8", "best_bid": "0.04", "best_ask": "0.96"}], "timestamp": "1769384619812", "event_type": "price_change"}}
{"_local_timestamp": "2026-01-25T23:43:39.947294+00:00", "data": {"market": "0x66aa8a28579a59742b541d7d89f185231e24127d8d54e207d92e66213ed909ef", "price_changes": [{"asset_id": "91423736259203636828645539448680117024524087071143750679349605058506199161826", "price": "0.04", "size": "0", "side": "BUY", "hash": "61f05faeb2c6a85ed9cf3d1564891ff28471efb3", "best_bid": "0.05", "best_ask": "0.96"}, {"asset_id": "29482259799705002124566483090977991712914260860257479165135371688038751642644", "price": "0.96", "size": "0", "side": "SELL", "hash": "8ffadcb03fe72154245bbdb01b66d18656b8884a", "best_bid": "0.04", "best_ask": "0.95"}], "timestamp": "1769384619812", "event_type": "price_change"}}
{"_local_timestamp": "2026-01-25T23:43:39.947845+00:00", "data": {"market": "0xe2522c3113503fa3310842e464c988b3ee1791790d74e3bbf01ba7abeb25c80f", "price_changes": [{"asset_id": "34396356694568550365415333424976689315210304285798066025980709860841157649078", "price": "0.04", "size": "0", "side": "BUY", "hash": "7b01a615f5d269d14e3660b148355dc0528b54bf", "best_bid": "0.05", "best_ask": "0.96"}, {"asset_id": "58029788945233188177055776782641910265995378981338051319950769448049549823705", "price": "0.96", "size": "0", "side": "SELL", "hash": "dd3b6398b529b4f9fde3aa1dcef51895f02e2019", "best_bid": "0.04", "best_ask": "0.95"}], "timestamp": "1769384619812", "event_type": "price_change"}}
{"_local_timestamp": "2026-01-25T23:43:40.190673+00:00", "data": {"market": "0x66aa8a28579a59742b541d7d89f185231e24127d8d54e207d92e66213ed909ef", "price_changes": [{"asset_id": "91423736259203636828645539448680117024524087071143750679349605058506199161826", "price": "0.06", "size": "5.47", "side": "BUY", "hash": "1f8aa547def657a262ebc676e17cbc8aa92f874e", "best_bid": "0.06", "best_ask": "0.96"}, {"asset_id": "29482259799705002124566483090977991712914260860257479165135371688038751642644", "price": "0.94", "size": "5.47", "side": "SELL", "hash": "aa9712da7b2c7977f59bd68ad89f9038c2dbbc09", "best_bid": "0.04", "best_ask": "0.94"}], "timestamp": "1769384620029", "event_type": "price_change"}}
{"_local_timestamp": "2026-01-25T23:43:40.191397+00:00", "data": {"market": "0x9e546f5bd8aaa57b741386967b6f0cb83ba70ff12cf399a3b104f5ded3e01c33", "price_changes": [{"asset_id": "98748914400722920263495947114807262573236269758480928212643590321888570153891", "price": "0.05", "size": "5.47", "side": "BUY", "hash": "6bce2a709b530fd443f117cf571a8ca5870dc663", "best_bid": "0.05", "best_ask": "0.96"}, {"asset_id": "52384449694849030011952391984862607032268821842864420008617516574964644205640", "price": "0.95", "size": "5.47", "side": "SELL", "hash": "7b1e107581b19a3c9d632a3ad6d3a3058bd183d2", "best_bid": "0.04", "best_ask": "0.95"}], "timestamp": "1769384620028", "event_type": "price_change"}}
{"_local_timestamp": "2026-01-25T23:43:40.191917+00:00", "data": {"market": "0x180cee3cb165e04b5556b5f54f156aecdfac62a7f99de19cb6e54247f046d80d", "price_changes": [{"asset_id": "45832756093987475477292835259287296516281710171095995001873781080428505369867", "price": "0.06", "size": "5.47", "side": "BUY", "hash": "1aa260e06f3140c00834251e0ae66df27d5f2e88", "best_bid": "0.06", "best_ask": "0.96"}, {"asset_id": "41518792079540460126973298251922654758525254450148908246351858650533815863785", "price": "0.94", "size": "5.47", "side": "SELL", "hash": "f425288806d7ea99e41c3e6d144ae5b5948fd965", "best_bid": "0.04", "best_ask": "0.94"}], "timestamp": "1769384620028", "event_type": "price_change"}}
{"_local_timestamp": "2026-01-25T23:43:40.207133+00:00", "data": {"market": "0xe2522c3113503fa3310842e464c988b3ee1791790d74e3bbf01ba7abeb25c80f", "price_changes": [{"asset_id": "34396356694568550365415333424976689315210304285798066025980709860841157649078", "price": "0.06", "size": "5.47", "side": "BUY", "hash": "24fe052060b3f9d28c0f557a73ebddb3f4483ea7", "best_bid": "0.06", "best_ask": "0.96"}, {"asset_id": "58029788945233188177055776782641910265995378981338051319950769448049549823705", "price": "0.94", "size": "5.47", "side": "SELL", "hash": "ed8e3214d28c4cddab377e2baeca9950cfaec909", "best_bid": "0.04", "best_ask": "0.94"}], "timestamp": "1769384620028", "event_type": "price_change"}}
{"_local_timestamp": "2026-01-25T23:43:40.209236+00:00", "data": {"market": "0x5bb085cf19c81e4c5e288ee70965fd061fb463199a1db6aa73c289c8b5d5b576", "price_changes": [{"asset_id": "94028695263980919862424407658493739709000655590831556337575886476241764379188", "price": "0.06", "size": "5.47", "side": "BUY", "hash": "6af81a310f5ce0e4f3b29315b62bd35b7d968b89", "best_bid": "0.06", "best_ask": "0.96"}, {"asset_id": "3869270757164855312650371225248655982559601630752717256310586548174182218377", "price": "0.94", "size": "5.47", "side": "SELL", "hash": "fb87eef1d1676cb62e6d2e57fb8b1d3244fe6236", "best_bid": "0.04", "best_ask": "0.94"}], "timestamp": "1769384620029", "event_type": "price_change"}}
{"_local_timestamp": "2026-01-25T23:43:40.209875+00:00", "data": {"market": "0x4d9b924e07c1868f1ae0a71542c5e2945c86c14a04bd846bfe2f0bb95848a67e", "price_changes": [{"asset_id": "75455801274299235341355169587755995541707405613253743917596982094560194111298", "price": "0.06", "size": "5.47", "side": "BUY", "hash": "6dedec8fd7ad40af3ca05b1d45f54451e1648056", "best_bid": "0.06", "best_ask": "0.96"}, {"asset_id": "26562265211720931675265155047873360108835400286939832140681489066284406369537", "price": "0.94", "size": "5.47", "side": "SELL", "hash": "f72384260c339a4a711898c625f1954729b0dce7", "best_bid": "0.04", "best_ask": "0.94"}], "timestamp": "1769384620029", "event_type": "price_change"}}
{"_local_timestamp": "2026-01-25T23:44:13.144128+00:00", "data": {"market": "0x4d9b924e07c1868f1ae0a71542c5e2945c86c14a04bd846bfe2f0bb95848a67e", "price_changes": [{"asset_id": "75455801274299235341355169587755995541707405613253743917596982094560194111298", "price": "0.02", "size": "105.48", "side": "BUY", "hash": "d5236f3192e03232a5b05a38c94af1c45929683d", "best_bid": "0.06", "best_ask": "0.96"}, {"asset_id": "26562265211720931675265155047873360108835400286939832140681489066284406369537", "price": "0.98", "size": "105.48", "side": "SELL", "hash": "8c46c6bded028832eef714416fae8d7edb4f3e15", "best_bid": "0.04", "best_ask": "0.94"}], "timestamp": "1769384653000", "event_type": "price_change"}}
{"_local_timestamp": "2026-01-25T23:44:13.152229+00:00", "data": {"market": "0xdae2149f65e89818c56124e772eee704f55f1a411482755dba026d4c727af0e4", "price_changes": [{"asset_id": "108539949567612627196500132085967459870136452742815448382213013024762772569343", "price": "0.02", "size": "40.48", "side": "BUY", "hash": "21b2f78805d58d97116f479dce5efd2854d86559", "best_bid": "0.04", "best_ask": "0.94"}, {"asset_id": "5731740857323119517691200242442035314690159130302063918637002279721289590857", "price": "0.98", "size": "40.48", "side": "SELL", "hash": "dc77b8b3e595f0750c2b63c5fb34fbdc853cbd67", "best_bid": "0.06", "best_ask": "0.96"}], "timestamp": "1769384653000", "event_type": "price_change"}}
{"_local_timestamp": "2026-01-25T23:44:13.152960+00:00", "data": {"market": "0x4d9b924e07c1868f1ae0a71542c5e2945c86c14a04bd846bfe2f0bb95848a67e", "price_changes": [{"asset_id": "26562265211720931675265155047873360108835400286939832140681489066284406369537", "price": "0.02", "size": "72.48", "side": "BUY", "hash": "b8b38da4c07aad5cae414f39cdde634722ad82d0", "best_bid": "0.04", "best_ask": "0.94"}, {"asset_id": "75455801274299235341355169587755995541707405613253743917596982094560194111298", "price": "0.98", "size": "72.48", "side": "SELL", "hash": "bf03f0dc21b32ab9a18db5e6de7b4667510fa8ba", "best_bid": "0.06", "best_ask": "0.96"}], "timestamp": "1769384653001", "event_type": "price_change"}}
{"_local_timestamp": "2026-01-25T23:44:13.168778+00:00", "data": {"market": "0xdae2149f65e89818c56124e772eee704f55f1a411482755dba026d4c727af0e4", "price_changes": [{"asset_id": "5731740857323119517691200242442035314690159130302063918637002279721289590857", "price": "0.02", "size": "30.95", "side": "BUY", "hash": "7fac9158b528a029b4a8f426e70f16b27ab6fbc5", "best_bid": "0.06", "best_ask": "0.96"}, {"asset_id": "108539949567612627196500132085967459870136452742815448382213013024762772569343", "price": "0.98", "size": "30.95", "side": "SELL", "hash": "b685c558a70195e7d9d2bdca8ba80df7a255759c", "best_bid": "0.04", "best_ask": "0.94"}], "timestamp": "1769384653002", "event_type": "price_change"}}
{"_local_timestamp": "2026-01-25T23:44:13.200158+00:00", "data": {"market": "0x8126b48144a3a336f16d34371f1243ed5cf2f43bf52280d7d77809099971a218", "price_changes": [{"asset_id": "1008929119197621738578745497318299441163170876973616595128366220594937454664", "price": "0.53", "size": "47.87", "side": "BUY", "hash": "41c1a30f7d0885a0cbd1d5070a697ebdd9a90dd3", "best_bid": "0.54", "best_ask": "0.55"}, {"asset_id": "27338257294745890265669696323699086994150404532171297238603912881944696902194", "price": "0.47", "size": "47.87", "side": "SELL", "hash": "4888c72193f8f0108cc4062b537f4b3742ac267b", "best_bid": "0.45", "best_ask": "0.46"}], "timestamp": "1769384653001", "event_type": "price_change"}}
{"_local_timestamp": "2026-01-25T23:44:18.116765+00:00", "data": {"market": "0xdae2149f65e89818c56124e772eee704f55f1a411482755dba026d4c727af0e4", "price_changes": [{"asset_id": "108539949567612627196500132085967459870136452742815448382213013024762772569343", "price": "0.02", "size": "190.48", "side": "BUY", "hash": "57f690743f3cbee8d44dac3c5352662745b4568c", "best_bid": "0.04", "best_ask": "0.94"}, {"asset_id": "5731740857323119517691200242442035314690159130302063918637002279721289590857", "price": "0.98", "size": "190.48", "side": "SELL", "hash": "35a7c576a0045028f40f3b070a2f25917a9828aa", "best_bid": "0.06", "best_ask": "0.96"}], "timestamp": "1769384657868", "event_type": "price_change"}}
{"_local_timestamp": "2026-01-25T23:44:18.117356+00:00", "data": {"market": "0xdae2149f65e89818c56124e772eee704f55f1a411482755dba026d4c727af0e4", "price_changes": [{"asset_id": "5731740857323119517691200242442035314690159130302063918637002279721289590857", "price": "0.02", "size": "180.95", "side": "BUY", "hash": "3a3de1d86d62251c5ebe2aa4fb8a58e670e8a5c4", "best_bid": "0.06", "best_ask": "0.96"}, {"asset_id": "108539949567612627196500132085967459870136452742815448382213013024762772569343", "price": "0.98", "size": "180.95", "side": "SELL", "hash": "6b4a8f71ab06174a0145a57969734093e79b74d3", "best_bid": "0.04", "best_ask": "0.94"}], "timestamp": "1769384657869", "event_type": "price_change"}}
{"_local_timestamp": "2026-01-25T23:44:18.146152+00:00", "data": {"market": "0x4d9b924e07c1868f1ae0a71542c5e2945c86c14a04bd846bfe2f0bb95848a67e", "price_changes": [{"asset_id": "26562265211720931675265155047873360108835400286939832140681489066284406369537", "price": "0.02", "size": "222.48", "side": "BUY", "hash": "964b694c7edc4e81e89f436bb05a8202eeccec6a", "best_bid": "0.04", "best_ask": "0.94"}, {"asset_id": "75455801274299235341355169587755995541707405613253743917596982094560194111298", "price": "0.98", "size": "222.48", "side": "SELL", "hash": "82dea9cb226746708158b6f26fce5d98e59b6dac", "best_bid": "0.06", "best_ask": "0.96"}], "timestamp": "1769384657897", "event_type": "price_change"}}
{"_local_timestamp": "2026-01-25T23:44:18.147464+00:00", "data": {"market": "0x4d9b924e07c1868f1ae0a71542c5e2945c86c14a04bd846bfe2f0bb95848a67e", "price_changes": [{"asset_id": "75455801274299235341355169587755995541707405613253743917596982094560194111298", "price": "0.02", "size": "255.48", "side": "BUY", "hash": "baac04ca05200644387aec4d0a0b354458b45b24", "best_bid": "0.06", "best_ask": "0.96"}, {"asset_id": "26562265211720931675265155047873360108835400286939832140681489066284406369537", "price": "0.98", "size": "255.48", "side": "SELL", "hash": "14f5c22e2bb7bb5ea9d11e8f9b67690807eba4e2", "best_bid": "0.04", "best_ask": "0.94"}], "timestamp": "1769384657898", "event_type": "price_change"}}
{"_local_timestamp": "2026-01-25T23:44:19.983438+00:00", "data": {"market": "0x8126b48144a3a336f16d34371f1243ed5cf2f43bf52280d7d77809099971a218", "price_changes": [{"asset_id": "1008929119197621738578745497318299441163170876973616595128366220594937454664", "price": "0.53", "size": "61.87", "side": "BUY", "hash": "f016917c9d7bb14223cfe62d7b118483a265ca04", "best_bid": "0.54", "best_ask": "0.55"}, {"asset_id": "27338257294745890265669696323699086994150404532171297238603912881944696902194", "price": "0.47", "size": "61.87", "side": "SELL", "hash": "d6f3699065dc18e226824590e48f765cfece11fe", "best_bid": "0.45", "best_ask": "0.46"}], "timestamp": "1769384659679", "event_type": "price_change"}}
{"_local_timestamp": "2026-01-25T23:45:09.636897+00:00", "data": {"market": "0x66aa8a28579a59742b541d7d89f185231e24127d8d54e207d92e66213ed909ef", "price_changes": [{"asset_id": "91423736259203636828645539448680117024524087071143750679349605058506199161826", "price": "0.05", "size": "0", "side": "BUY", "hash": "2ce1b84d5e284db97e0bdaf7d45c6ec0605c21b7", "best_bid": "0.06", "best_ask": "0.96"}, {"asset_id": "29482259799705002124566483090977991712914260860257479165135371688038751642644", "price": "0.95", "size": "0", "side": "SELL", "hash": "2d657a0ad008e8ee92ce49b6f8ff20840b0fe1f4", "best_bid": "0.04", "best_ask": "0.94"}], "timestamp": "1769384709563", "event_type": "price_change"}}
{"_local_timestamp": "2026-01-25T23:45:09.637984+00:00", "data": {"market": "0x180cee3cb165e04b5556b5f54f156aecdfac62a7f99de19cb6e54247f046d80d", "price_changes": [{"asset_id": "45832756093987475477292835259287296516281710171095995001873781080428505369867", "price": "0.05", "size": "0", "side": "BUY", "hash": "7a2e4477b5af97ee46d75d9fa028a9d0f48039c5", "best_bid": "0.06", "best_ask": "0.96"}, {"asset_id": "41518792079540460126973298251922654758525254450148908246351858650533815863785", "price": "0.95", "size": "0", "side": "SELL", "hash": "0d1408b572ae524ad37e2e9c8e4ecac0110b6df4", "best_bid": "0.04", "best_ask": "0.94"}], "timestamp": "1769384709563", "event_type": "price_change"}}
{"_local_timestamp": "2026-01-25T23:45:09.730136+00:00", "data": {"market": "0x5bb085cf19c81e4c5e288ee70965fd061fb463199a1db6aa73c289c8b5d5b576", "price_changes": [{"asset_id": "94028695263980919862424407658493739709000655590831556337575886476241764379188", "price": "0.05", "size": "0", "side": "BUY", "hash": "e0137d6ef23db824e5252c6fbc4df22259b81d2e", "best_bid": "0.06", "best_ask": "0.96"}, {"asset_id": "3869270757164855312650371225248655982559601630752717256310586548174182218377", "price": "0.95", "size": "0", "side": "SELL", "hash": "92444ec5bc0022731ab3ae5d50c55dfc6414ee2d", "best_bid": "0.04", "best_ask": "0.94"}], "timestamp": "1769384709664", "event_type": "price_change"}}
{"_local_timestamp": "2026-01-25T23:45:09.739811+00:00", "data": {"market": "0xe2522c3113503fa3310842e464c988b3ee1791790d74e3bbf01ba7abeb25c80f", "price_changes": [{"asset_id": "34396356694568550365415333424976689315210304285798066025980709860841157649078", "price": "0.05", "size": "0", "side": "BUY", "hash": "b0643326c54157cd0ff1bfc772f3a8dbfe9b27dc", "best_bid": "0.06", "best_ask": "0.96"}, {"asset_id": "58029788945233188177055776782641910265995378981338051319950769448049549823705", "price": "0.95", "size": "0", "side": "SELL", "hash": "cde1a75361128c026f6d4e2026158200569a6004", "best_bid": "0.04", "best_ask": "0.94"}], "timestamp": "1769384709664", "event_type": "price_change"}}
{"_local_timestamp": "2026-01-25T23:45:09.828501+00:00", "data": {"market": "0x4d9b924e07c1868f1ae0a71542c5e2945c86c14a04bd846bfe2f0bb95848a67e", "price_changes": [{"asset_id": "75455801274299235341355169587755995541707405613253743917596982094560194111298", "price": "0.05", "size": "0", "side": "BUY", "hash": "d31486ff1bfd551aa92d53f25a7fbc5d1289dcc1", "best_bid": "0.06", "best_ask": "0.96"}, {"asset_id": "26562265211720931675265155047873360108835400286939832140681489066284406369537", "price": "0.95", "size": "0", "side": "SELL", "hash": "919092ae7c39b844b4e6d19486406d14523abed2", "best_bid": "0.04", "best_ask": "0.94"}], "timestamp": "1769384709760", "event_type": "price_change"}}
{"_local_timestamp": "2026-01-25T23:45:11.856715+00:00", "data": {"market": "0x4d9b924e07c1868f1ae0a71542c5e2945c86c14a04bd846bfe2f0bb95848a67e", "price_changes": [{"asset_id": "75455801274299235341355169587755995541707405613253743917596982094560194111298", "price": "0.06", "size": "0", "side": "BUY", "hash": "b3a7985f9075dd7099ffcb9addac17db85d8ec2d", "best_bid": "0.03", "best_ask": "0.96"}, {"asset_id": "26562265211720931675265155047873360108835400286939832140681489066284406369537", "price": "0.94", "size": "0", "side": "SELL", "hash": "14109758ee0b63b83de56c4057ad9d2ee3d824d1", "best_bid": "0.04", "best_ask": "0.97"}], "timestamp": "1769384711772", "event_type": "price_change"}}
{"_local_timestamp": "2026-01-25T23:45:11.857381+00:00", "data": {"market": "0xe2522c3113503fa3310842e464c988b3ee1791790d74e3bbf01ba7abeb25c80f", "price_changes": [{"asset_id": "34396356694568550365415333424976689315210304285798066025980709860841157649078", "price": "0.06", "size": "0", "side": "BUY", "hash": "b6efd09ffd6c47ec2db578e649bd5ba2469ff6ab", "best_bid": "0.03", "best_ask": "0.96"}, {"asset_id": "58029788945233188177055776782641910265995378981338051319950769448049549823705", "price": "0.94", "size": "0", "side": "SELL", "hash": "12deaef1982ee1a43a0a97d9931a8567ca36302b", "best_bid": "0.04", "best_ask": "0.97"}], "timestamp": "1769384711771", "event_type": "price_change"}}
{"_local_timestamp": "2026-01-25T23:45:11.857894+00:00", "data": {"market": "0x180cee3cb165e04b5556b5f54f156aecdfac62a7f99de19cb6e54247f046d80d", "price_changes": [{"asset_id": "45832756093987475477292835259287296516281710171095995001873781080428505369867", "price": "0.06", "size": "0", "side": "BUY", "hash": "eacc10d380c45e6a3f8388d7f01ee389a2c447ce", "best_bid": "0.03", "best_ask": "0.96"}, {"asset_id": "41518792079540460126973298251922654758525254450148908246351858650533815863785", "price": "0.94", "size": "0", "side": "SELL", "hash": "05d76fef39823c1549b864f5f34d7de634a3dd30", "best_bid": "0.04", "best_ask": "0.97"}], "timestamp": "1769384711771", "event_type": "price_change"}}
{"_local_timestamp": "2026-01-25T23:45:11.863789+00:00", "data": {"market": "0x5bb085cf19c81e4c5e288ee70965fd061fb463199a1db6aa73c289c8b5d5b576", "price_changes": [{"asset_id": "94028695263980919862424407658493739709000655590831556337575886476241764379188", "price": "0.06", "size": "0", "side": "BUY", "hash": "a0ccd49d991cb11972a43ac91268b8052e0df4f3", "best_bid": "0.03", "best_ask": "0.96"}, {"asset_id": "3869270757164855312650371225248655982559601630752717256310586548174182218377", "price": "0.94", "size": "0", "side": "SELL", "hash": "9812821bb70e8b8321f88412741021a1ff3d5279", "best_bid": "0.04", "best_ask": "0.97"}], "timestamp": "1769384711772", "event_type": "price_change"}}
{"_local_timestamp": "2026-01-25T23:45:11.866509+00:00", "data": {"market": "0x66aa8a28579a59742b541d7d89f185231e24127d8d54e207d92e66213ed909ef", "price_changes": [{"asset_id": "91423736259203636828645539448680117024524087071143750679349605058506199161826", "price": "0.06", "size": "0", "side": "BUY", "hash": "805c1ccbda08adcd1fa25c78c0068dc8f7f9f67f", "best_bid": "0.03", "best_ask": "0.96"}, {"asset_id": "29482259799705002124566483090977991712914260860257479165135371688038751642644", "price": "0.94", "size": "0", "side": "SELL", "hash": "e02e716408de0711c3ad2f37ad2617e841457a82", "best_bid": "0.04", "best_ask": "0.97"}], "timestamp": "1769384711771", "event_type": "price_change"}}
{"_local_timestamp": "2026-01-25T23:45:12.045770+00:00", "data": {"market": "0xe2522c3113503fa3310842e464c988b3ee1791790d74e3bbf01ba7abeb25c80f", "price_changes": [{"asset_id": "34396356694568550365415333424976689315210304285798066025980709860841157649078", "price": "0.04", "size": "5.47", "side": "BUY", "hash": "1a2a8e69e9a597fc182c1392c421aca21ad61b34", "best_bid": "0.04", "best_ask": "0.96"}, {"asset_id": "58029788945233188177055776782641910265995378981338051319950769448049549823705", "price": "0.96", "size": "5.47", "side": "SELL", "hash": "40362db556287023c544857983077d4ffe3f1dd7", "best_bid": "0.04", "best_ask": "0.96"}], "timestamp": "1769384711972", "event_type": "price_change"}}
{"_local_timestamp": "2026-01-25T23:45:12.046609+00:00", "data": {"market": "0x66aa8a28579a59742b541d7d89f185231e24127d8d54e207d92e66213ed909ef", "price_changes": [{"asset_id": "91423736259203636828645539448680117024524087071143750679349605058506199161826", "price": "0.04", "size": "5.47", "side": "BUY", "hash": "a7a6debb8d3b3394fe731ebc98e745ddb086fdc1", "best_bid": "0.04", "best_ask": "0.96"}, {"asset_id": "29482259799705002124566483090977991712914260860257479165135371688038751642644", "price": "0.96", "size": "5.47", "side": "SELL", "hash": "4ded38492c586d117c00ec56661daaf628e79b93", "best_bid": "0.04", "best_ask": "0.96"}], "timestamp": "1769384711973", "event_type": "price_change"}}
{"_local_timestamp": "2026-01-25T23:45:12.047178+00:00", "data": {"market": "0x5bb085cf19c81e4c5e288ee70965fd061fb463199a1db6aa73c289c8b5d5b576", "price_changes": [{"asset_id": "94028695263980919862424407658493739709000655590831556337575886476241764379188", "price": "0.04", "size": "5.47", "side": "BUY", "hash": "50e22785184676e65da0edf68509e0449776be49", "best_bid": "0.04", "best_ask": "0.96"}, {"asset_id": "3869270757164855312650371225248655982559601630752717256310586548174182218377", "price": "0.96", "size": "5.47", "side": "SELL", "hash": "4b7a4adfa9cacf5f84760c0d67a29ff08453786d", "best_bid": "0.04", "best_ask": "0.96"}], "timestamp": "1769384711973", "event_type": "price_change"}}
{"_local_timestamp": "2026-01-25T23:45:12.062744+00:00", "data": {"market": "0x180cee3cb165e04b5556b5f54f156aecdfac62a7f99de19cb6e54247f046d80d", "price_changes": [{"asset_id": "45832756093987475477292835259287296516281710171095995001873781080428505369867", "price": "0.04", "size": "5.47", "side": "BUY", "hash": "30b782d0374317275a576c0979e38b6b3381086c", "best_bid": "0.04", "best_ask": "0.96"}, {"asset_id": "41518792079540460126973298251922654758525254450148908246351858650533815863785", "price": "0.96", "size": "5.47", "side": "SELL", "hash": "30ce43206c502608dc50deb43941ac436c39ea63", "best_bid": "0.04", "best_ask": "0.96"}], "timestamp": "1769384711973", "event_type": "price_change"}}
{"_local_timestamp": "2026-01-25T23:45:12.064655+00:00", "data": {"market": "0x4d9b924e07c1868f1ae0a71542c5e2945c86c14a04bd846bfe2f0bb95848a67e", "price_changes": [{"asset_id": "75455801274299235341355169587755995541707405613253743917596982094560194111298", "price": "0.04", "size": "5.47", "side": "BUY", "hash": "51c24ceeb9b2f5edc71dedb0331e81a4da7f15e7", "best_bid": "0.04", "best_ask": "0.96"}, {"asset_id": "26562265211720931675265155047873360108835400286939832140681489066284406369537", "price": "0.96", "size": "5.47", "side": "SELL", "hash": "ff20096ac31bb4f48d9801a8523d2f7275c342d5", "best_bid": "0.04", "best_ask": "0.96"}], "timestamp": "1769384711973", "event_type": "price_change"}}
{"_local_timestamp": "2026-01-25T23:45:53.326111+00:00", "data": {"market": "0x644991b60a94b272357e6f68d1615680703601accb15d7302f499b737d4a0db0", "price_changes": [{"asset_id": "80482043625015601757240447150279689188946061800550924069274579383544776374468", "price": "0.06", "size": "5.47", "side": "BUY", "hash": "344a0a70b71f2c3e26adf29f8371b56bc7d32801", "best_bid": "0.06", "best_ask": "0.96"}, {"asset_id": "107742164566063298345228923210014891131960841481018710120513126758098443996397", "price": "0.94", "size": "5.47", "side": "SELL", "hash": "6d2dffb3a11f7706d75f2fc1922c3b8a4a329142", "best_bid": "0.04", "best_ask": "0.94"}], "timestamp": "1769384753113", "event_type": "price_change"}}
{"_local_timestamp": "2026-01-25T23:45:53.326946+00:00", "data": {"market": "0xdae2149f65e89818c56124e772eee704f55f1a411482755dba026d4c727af0e4", "price_changes": [{"asset_id": "5731740857323119517691200242442035314690159130302063918637002279721289590857", "price": "0.06", "size": "5.47", "side": "BUY", "hash": "bcb320dfb8acaac0f279fb290b989d13036bc853", "best_bid": "0.06", "best_ask": "0.96"}, {"asset_id": "108539949567612627196500132085967459870136452742815448382213013024762772569343", "price": "0.94", "size": "5.47", "side": "SELL", "hash": "62f81c13b780e066730af058ccc883de89feb8b1", "best_bid": "0.04", "best_ask": "0.94"}], "timestamp": "1769384753113", "event_type": "price_change"}}
{"_local_timestamp": "2026-01-25T23:45:54.110193+00:00", "data": {"market": "0xdae2149f65e89818c56124e772eee704f55f1a411482755dba026d4c727af0e4", "price_changes": [{"asset_id": "5731740857323119517691200242442035314690159130302063918637002279721289590857", "price": "0.03", "size": "22.1", "side": "BUY", "hash": "c2e433d6fe6cf6a338d276c1347c923c061bcb25", "best_bid": "0.06", "best_ask": "0.96"}, {"asset_id": "108539949567612627196500132085967459870136452742815448382213013024762772569343", "price": "0.97", "size": "22.1", "side": "SELL", "hash": "0589ca5b4e1dc6551aea80be43e5c6989a7ab560", "best_bid": "0.04", "best_ask": "0.94"}], "timestamp": "1769384754030", "event_type": "price_change"}}
{"_local_timestamp": "2026-01-25T23:45:55.144795+00:00", "data": {"market": "0x644991b60a94b272357e6f68d1615680703601accb15d7302f499b737d4a0db0", "price_changes": [{"asset_id": "80482043625015601757240447150279689188946061800550924069274579383544776374468", "price": "0.03", "size": "22.1", "side": "BUY", "hash": "f50b504e050ab964289b9383dc43c73a048e8967", "best_bid": "0.06", "best_ask": "0.96"}, {"asset_id": "107742164566063298345228923210014891131960841481018710120513126758098443996397", "price": "0.97", "size": "22.1", "side": "SELL", "hash": "a26a2da65437184adee584ebcff7e65d384e3119", "best_bid": "0.04", "best_ask": "0.94"}], "timestamp": "1769384755077", "event_type": "price_change"}}
{"_local_timestamp": "2026-01-25T23:45:55.285803+00:00", "data": {"market": "0x618f90d78c70081e7dd7d422c3e2299e4a77d35edb8e4258ae0297ddfab14e17", "price_changes": [{"asset_id": "88493938041191305708637957243458880188207866339223186442772420759619853972732", "price": "0.01", "size": "51.41", "side": "BUY", "hash": "fa44048670a1f0e1a41d1c17e4ea9df2e16ecf70", "best_bid": "0.06", "best_ask": "0.96"}, {"asset_id": "630142824528014601903526077196303536591995171166379784723107847019383910560", "price": "0.99", "size": "51.41", "side": "SELL", "hash": "91575806263a2cdb560efc2eff964159eec745bf", "best_bid": "0.04", "best_ask": "0.94"}], "timestamp": "1769384755221", "event_type": "price_change"}}
{"_local_timestamp": "2026-01-25T23:45:55.286431+00:00", "data": {"market": "0x618f90d78c70081e7dd7d422c3e2299e4a77d35edb8e4258ae0297ddfab14e17", "price_changes": [{"asset_id": "88493938041191305708637957243458880188207866339223186442772420759619853972732", "price": "0.06", "size": "5.47", "side": "BUY", "hash": "fa44048670a1f0e1a41d1c17e4ea9df2e16ecf70", "best_bid": "0.06", "best_ask": "0.96"}, {"asset_id": "630142824528014601903526077196303536591995171166379784723107847019383910560", "price": "0.94", "size": "5.47", "side": "SELL", "hash": "91575806263a2cdb560efc2eff964159eec745bf", "best_bid": "0.04", "best_ask": "0.94"}], "timestamp": "1769384755221", "event_type": "price_change"}}
{"_local_timestamp": "2026-01-25T23:45:55.286983+00:00", "data": {"market": "0xe2522c3113503fa3310842e464c988b3ee1791790d74e3bbf01ba7abeb25c80f", "price_changes": [{"asset_id": "34396356694568550365415333424976689315210304285798066025980709860841157649078", "price": "0.01", "size": "156.93", "side": "BUY", "hash": "874ecda5b3ac0dd5dd9377fb678582231fcf35b8", "best_bid": "0.04", "best_ask": "0.96"}, {"asset_id": "58029788945233188177055776782641910265995378981338051319950769448049549823705", "price": "0.99", "size": "156.93", "side": "SELL", "hash": "74163f1794d8c3ca0397e0db968bed5e62736378", "best_bid": "0.04", "best_ask": "0.96"}], "timestamp": "1769384755221", "event_type": "price_change"}}
{"_local_timestamp": "2026-01-25T23:45:55.718752+00:00", "data": {"market": "0xc794d53782d2a57779c1bd1d7fe4e1012cd63daa340d6733478b04e43c779bb2", "price_changes": [{"asset_id": "29850745557425233278441255217116778127787897972791369065729373689355832286173", "price": "0.06", "size": "5.47", "side": "BUY", "hash": "c6f5446148e798631a0d996131c9d9b054b63e14", "best_bid": "0.06", "best_ask": "0.96"}, {"asset_id": "65285709653207321996387925181629862243682185841555542627225011614554527757803", "price": "0.94", "size": "5.47", "side": "SELL", "hash": "780f30be1654865efcbcbf3c5b6ef2517b2a183d", "best_bid": "0.04", "best_ask": "0.94"}], "timestamp": "1769384755655", "event_type": "price_change"}}
{"_local_timestamp": "2026-01-25T23:45:55.719396+00:00", "data": {"market": "0x9e546f5bd8aaa57b741386967b6f0cb83ba70ff12cf399a3b104f5ded3e01c33", "price_changes": [{"asset_id": "98748914400722920263495947114807262573236269758480928212643590321888570153891", "price": "0.02", "size": "177.16", "side": "BUY", "hash": "de9fefd4301eccd57b2b2ba2d5f573bc73fc92de", "best_bid": "0.05", "best_ask": "0.96"}, {"asset_id": "52384449694849030011952391984862607032268821842864420008617516574964644205640", "price": "0.98", "size": "177.16", "side": "SELL", "hash": "33e806145dd75f63f25ab720ff8772807a6ffc52", "best_bid": "0.04", "best_ask": "0.95"}], "timestamp": "1769384755655", "event_type": "price_change"}}
{"_local_timestamp": "2026-01-25T23:45:55.719954+00:00", "data": {"market": "0x9e546f5bd8aaa57b741386967b6f0cb83ba70ff12cf399a3b104f5ded3e01c33", "price_changes": [{"asset_id": "98748914400722920263495947114807262573236269758480928212643590321888570153891", "price": "0.04", "size": "0", "side": "BUY", "hash": "de9fefd4301eccd57b2b2ba2d5f573bc73fc92de", "best_bid": "0.05", "best_ask": "0.96"}, {"asset_id": "52384449694849030011952391984862607032268821842864420008617516574964644205640", "price": "0.96", "size": "0", "side": "SELL", "hash": "33e806145dd75f63f25ab720ff8772807a6ffc52", "best_bid": "0.04", "best_ask": "0.95"}], "timestamp": "1769384755655", "event_type": "price_change"}}
{"_local_timestamp": "2026-01-25T23:45:55.848941+00:00", "data": {"market": "0xdae2149f65e89818c56124e772eee704f55f1a411482755dba026d4c727af0e4", "price_changes": [{"asset_id": "5731740857323119517691200242442035314690159130302063918637002279721289590857", "price": "0.06", "size": "0", "side": "BUY", "hash": "8d22a8d830d768c1db3dafb066a923b2793f0bc0", "best_bid": "0.03", "best_ask": "0.96"}, {"asset_id": "108539949567612627196500132085967459870136452742815448382213013024762772569343", "price": "0.94", "size": "0", "side": "SELL", "hash": "0343a5558af05c5117271c6b7cac5b839d8d4a88", "best_bid": "0.04", "best_ask": "0.97"}], "timestamp": "1769384755783", "event_type": "price_change"}}
{"_local_timestamp": "2026-01-25T23:45:55.849596+00:00", "data": {"market": "0x644991b60a94b272357e6f68d1615680703601accb15d7302f499b737d4a0db0", "price_changes": [{"asset_id": "80482043625015601757240447150279689188946061800550924069274579383544776374468", "price": "0.06", "size": "0", "side": "BUY", "hash": "633c8995ffab4d037831cbe1af919e291da3bebb", "best_bid": "0.03", "best_ask": "0.96"}, {"asset_id": "107742164566063298345228923210014891131960841481018710120513126758098443996397", "price": "0.94", "size": "0", "side": "SELL", "hash": "89f4f25681a79dd8c3c85fafda0d47d24325b5b9", "best_bid": "0.04", "best_ask": "0.97"}], "timestamp": "1769384755783", "event_type": "price_change"}}
{"_local_timestamp": "2026-01-25T23:45:55.886999+00:00", "data": {"market": "0x644991b60a94b272357e6f68d1615680703601accb15d7302f499b737d4a0db0", "price_changes": [{"asset_id": "80482043625015601757240447150279689188946061800550924069274579383544776374468", "price": "0.04", "size": "5.47", "side": "BUY", "hash": "7ebd10cd93f1f763ed73a4085332dc23fba3d2c9", "best_bid": "0.04", "best_ask": "0.96"}, {"asset_id": "107742164566063298345228923210014891131960841481018710120513126758098443996397", "price": "0.96", "size": "5.47", "side": "SELL", "hash": "21a8c049943dba2f7b12416367ed0482fece0230", "best_bid": "0.04", "best_ask": "0.96"}], "timestamp": "1769384755821", "event_type": "price_change"}}
{"_local_timestamp": "2026-01-25T23:45:55.887633+00:00", "data": {"market": "0xdae2149f65e89818c56124e772eee704f55f1a411482755dba026d4c727af0e4", "price_changes": [{"asset_id": "5731740857323119517691200242442035314690159130302063918637002279721289590857", "price": "0.04", "size": "5.47", "side": "BUY", "hash": "dd660d423de1b08a546616235973751d411de8a0", "best_bid": "0.04", "best_ask": "0.96"}, {"asset_id": "108539949567612627196500132085967459870136452742815448382213013024762772569343", "price": "0.96", "size": "5.47", "side": "SELL", "hash": "c08162999f335736606571a207f776d5105253e6", "best_bid": "0.04", "best_ask": "0.96"}], "timestamp": "1769384755821", "event_type": "price_change"}}
{"_local_timestamp": "2026-01-25T23:45:57.544144+00:00", "data": {"market": "0xc794d53782d2a57779c1bd1d7fe4e1012cd63daa340d6733478b04e43c779bb2", "price_changes": [{"asset_id": "29850745557425233278441255217116778127787897972791369065729373689355832286173", "price": "0.03", "size": "22.1", "side": "BUY", "hash": "1af4c29ba50450236302e893c56954dc5b9bbf64", "best_bid": "0.06", "best_ask": "0.96"}, {"asset_id": "65285709653207321996387925181629862243682185841555542627225011614554527757803", "price": "0.97", "size": "22.1", "side": "SELL", "hash": "8e2b589733821a13e486fcb30f15dfec5aedd460", "best_bid": "0.04", "best_ask": "0.94"}], "timestamp": "1769384757483", "event_type": "price_change"}}
{"_local_timestamp": "2026-01-25T23:45:57.544799+00:00", "data": {"market": "0x9e546f5bd8aaa57b741386967b6f0cb83ba70ff12cf399a3b104f5ded3e01c33", "price_changes": [{"asset_id": "98748914400722920263495947114807262573236269758480928212643590321888570153891", "price": "0.03", "size": "24.73", "side": "BUY", "hash": "b6c9cfcb14f2f5e2b2006c4e0786169ca85372e1", "best_bid": "0.05", "best_ask": "0.96"}, {"asset_id": "52384449694849030011952391984862607032268821842864420008617516574964644205640", "price": "0.97", "size": "24.73", "side": "SELL", "hash": "f66f27c1af68b7e0b252827cfc7dc03a6b18cb93", "best_bid": "0.04", "best_ask": "0.95"}], "timestamp": "1769384757483", "event_type": "price_change"}}
{"_local_timestamp": "2026-01-25T23:45:57.854589+00:00", "data": {"market": "0xe2522c3113503fa3310842e464c988b3ee1791790d74e3bbf01ba7abeb25c80f", "price_changes": [{"asset_id": "34396356694568550365415333424976689315210304285798066025980709860841157649078", "price": "0.01", "size": "169.65", "side": "BUY", "hash": "06ffc6485f4af023b14e5f562f25aea5fa825e7e", "best_bid": "0.04", "best_ask": "0.96"}, {"asset_id": "58029788945233188177055776782641910265995378981338051319950769448049549823705", "price": "0.99", "size": "169.65", "side": "SELL", "hash": "647dc5a41a4591cbc81b996100e6704dd512ca34", "best_bid": "0.04", "best_ask": "0.96"}], "timestamp": "1769384757781", "event_type": "price_change"}}
{"_local_timestamp": "2026-01-25T23:45:57.855247+00:00", "data": {"market": "0x618f90d78c70081e7dd7d422c3e2299e4a77d35edb8e4258ae0297ddfab14e17", "price_changes": [{"asset_id": "88493938041191305708637957243458880188207866339223186442772420759619853972732", "price": "0.01", "size": "60.42", "side": "BUY", "hash": "37ef81ecf9dd618629e3e2683713bf69f38cce84", "best_bid": "0.06", "best_ask": "0.96"}, {"asset_id": "630142824528014601903526077196303536591995171166379784723107847019383910560", "price": "0.99", "size": "60.42", "side": "SELL", "hash": "0bf2ea62417ecd2d4e698a018716a11bf4b88ec4", "best_bid": "0.04", "best_ask": "0.94"}], "timestamp": "1769384757781", "event_type": "price_change"}}
{"_local_timestamp": "2026-01-25T23:45:57.855824+00:00", "data": {"market": "0x618f90d78c70081e7dd7d422c3e2299e4a77d35edb8e4258ae0297ddfab14e17", "price_changes": [{"asset_id": "88493938041191305708637957243458880188207866339223186442772420759619853972732", "price": "0.03", "size": "24.82", "side": "BUY", "hash": "7f083ab231031dc04a4389ee1288d79d83d871d4", "best_bid": "0.06", "best_ask": "0.96"}, {"asset_id": "630142824528014601903526077196303536591995171166379784723107847019383910560", "price": "0.97", "size": "24.82", "side": "SELL", "hash": "4499c3e5d97b57b2550882e8d44b8fd02e707438", "best_bid": "0.04", "best_ask": "0.94"}], "timestamp": "1769384757782", "event_type": "price_change"}}
{"_local_timestamp": "2026-01-25T23:45:57.980125+00:00", "data": {"market": "0xca6684a2f5b699b04e9da70003381b45faa1a7807748abc7fbca1d689eede3dd", "price_changes": [{"asset_id": "75435923675834590025716428375190789880766798597634661131343729919797820504690", "price": "0.03", "size": "8.61", "side": "BUY", "hash": "14de2ba81356741e9df51bbd5b2f6d2cfe1bc693", "best_bid": "0.04", "best_ask": "0.96"}, {"asset_id": "67923079595575445284641976004414570715798135735376672166638592297910878774957", "price": "0.97", "size": "8.61", "side": "SELL", "hash": "ce79938d70dca74b7182fa13571010fab8863097", "best_bid": "0.04", "best_ask": "0.96"}], "timestamp": "1769384757907", "event_type": "price_change"}}
{"_local_timestamp": "2026-01-25T23:45:59.137290+00:00", "data": {"market": "0x9e546f5bd8aaa57b741386967b6f0cb83ba70ff12cf399a3b104f5ded3e01c33", "price_changes": [{"asset_id": "98748914400722920263495947114807262573236269758480928212643590321888570153891", "price": "0.05", "size": "0", "side": "BUY", "hash": "9ffe5dd8fc09734715d0234c4db0cc373ad59baa", "best_bid": "0.03", "best_ask": "0.96"}, {"asset_id": "52384449694849030011952391984862607032268821842864420008617516574964644205640", "price": "0.95", "size": "0", "side": "SELL", "hash": "b5abe2106915b44a0b895967ca6e3640786ab76a", "best_bid": "0.04", "best_ask": "0.97"}], "timestamp": "1769384759038", "event_type": "price_change"}}
{"_local_timestamp": "2026-01-25T23:45:59.137925+00:00", "data": {"market": "0x618f90d78c70081e7dd7d422c3e2299e4a77d35edb8e4258ae0297ddfab14e17", "price_changes": [{"asset_id": "88493938041191305708637957243458880188207866339223186442772420759619853972732", "price": "0.06", "size": "0", "side": "BUY", "hash": "95860da600b2f0449c75a752ff9c55670b489437", "best_bid": "0.03", "best_ask": "0.96"}, {"asset_id": "630142824528014601903526077196303536591995171166379784723107847019383910560", "price": "0.94", "size": "0", "side": "SELL", "hash": "b38f5c3a5dca75d099896e18d88cae9124ea81a3", "best_bid": "0.04", "best_ask": "0.97"}], "timestamp": "1769384759038", "event_type": "price_change"}}
{"_local_timestamp": "2026-01-25T23:45:59.138483+00:00", "data": {"market": "0xc794d53782d2a57779c1bd1d7fe4e1012cd63daa340d6733478b04e43c779bb2", "price_changes": [{"asset_id": "29850745557425233278441255217116778127787897972791369065729373689355832286173", "price": "0.06", "size": "0", "side": "BUY", "hash": "2f1e45aad39f37bcc07f3e4c0f89bb7a9e9a0f2a", "best_bid": "0.03", "best_ask": "0.96"}, {"asset_id": "65285709653207321996387925181629862243682185841555542627225011614554527757803", "price": "0.94", "size": "0", "side": "SELL", "hash": "32e7f04a32376c27d049471e1a6efed7c8e2fb18", "best_bid": "0.04", "best_ask": "0.97"}], "timestamp": "1769384759038", "event_type": "price_change"}}
{"_local_timestamp": "2026-01-25T23:45:59.163752+00:00", "data": {"market": "0x618f90d78c70081e7dd7d422c3e2299e4a77d35edb8e4258ae0297ddfab14e17", "price_changes": [{"asset_id": "88493938041191305708637957243458880188207866339223186442772420759619853972732", "price": "0.04", "size": "5.47", "side": "BUY", "hash": "727c765da02ed978418afc676e894a9d96cc849a", "best_bid": "0.04", "best_ask": "0.96"}, {"asset_id": "630142824528014601903526077196303536591995171166379784723107847019383910560", "price": "0.96", "size": "5.47", "side": "SELL", "hash": "7c180a2b28d46394a3be63377812f02aebed34d6", "best_bid": "0.04", "best_ask": "0.96"}], "timestamp": "1769384759076", "event_type": "price_change"}}
{"_local_timestamp": "2026-01-25T23:45:59.164361+00:00", "data": {"market": "0xc794d53782d2a57779c1bd1d7fe4e1012cd63daa340d6733478b04e43c779bb2", "price_changes": [{"asset_id": "29850745557425233278441255217116778127787897972791369065729373689355832286173", "price": "0.04", "size": "5.47", "side": "BUY", "hash": "f510dd02e63bb217ae20025516c557f71451dd39", "best_bid": "0.04", "best_ask": "0.96"}, {"asset_id": "65285709653207321996387925181629862243682185841555542627225011614554527757803", "price": "0.96", "size": "5.47", "side": "SELL", "hash": "1595422e76f7490c8b54841a56e78c956f0da62c", "best_bid": "0.04", "best_ask": "0.96"}], "timestamp": "1769384759076", "event_type": "price_change"}}
{"_local_timestamp": "2026-01-25T23:45:59.164946+00:00", "data": {"market": "0x9e546f5bd8aaa57b741386967b6f0cb83ba70ff12cf399a3b104f5ded3e01c33", "price_changes": [{"asset_id": "98748914400722920263495947114807262573236269758480928212643590321888570153891", "price": "0.04", "size": "5.47", "side": "BUY", "hash": "949f188514b7db4c60daa9de28ff9b3bd2ed29a8", "best_bid": "0.04", "best_ask": "0.96"}, {"asset_id": "52384449694849030011952391984862607032268821842864420008617516574964644205640", "price": "0.96", "size": "5.47", "side": "SELL", "hash": "f2edf0fd1f3a8bb748692654b54463dd63f2e64a", "best_bid": "0.04", "best_ask": "0.96"}], "timestamp": "1769384759076", "event_type": "price_change"}}
{"_local_timestamp": "2026-01-25T23:45:59.785849+00:00", "data": {"market": "0xca6684a2f5b699b04e9da70003381b45faa1a7807748abc7fbca1d689eede3dd", "price_changes": [{"asset_id": "75435923675834590025716428375190789880766798597634661131343729919797820504690", "price": "0.03", "size": "23.02", "side": "BUY", "hash": "2dc97477407e2f95255b0ca9eb0cab6bb990d180", "best_bid": "0.04", "best_ask": "0.96"}, {"asset_id": "67923079595575445284641976004414570715798135735376672166638592297910878774957", "price": "0.97", "size": "23.02", "side": "SELL", "hash": "998f97db7d3008a5cc161fd7f28faa78aefb5568", "best_bid": "0.04", "best_ask": "0.96"}], "timestamp": "1769384759718", "event_type": "price_change"}}
{"_local_timestamp": "2026-01-25T23:46:48.889291+00:00", "data": {"market": "0x180cee3cb165e04b5556b5f54f156aecdfac62a7f99de19cb6e54247f046d80d", "price_changes": [{"asset_id": "45832756093987475477292835259287296516281710171095995001873781080428505369867", "price": "0.05", "size": "23.99", "side": "BUY", "hash": "af1d8a19225ecf5426630411accb961f334414d3", "best_bid": "0.05", "best_ask": "0.96"}, {"asset_id": "41518792079540460126973298251922654758525254450148908246351858650533815863785", "price": "0.95", "size": "23.99", "side": "SELL", "hash": "799d4aac054d4b0167a6c49081f47958e717718b", "best_bid": "0.04", "best_ask": "0.95"}], "timestamp": "1769384808638", "event_type": "price_change"}}
{"_local_timestamp": "2026-01-25T23:46:48.890102+00:00", "data": {"market": "0x4d9b924e07c1868f1ae0a71542c5e2945c86c14a04bd846bfe2f0bb95848a67e", "price_changes": [{"asset_id": "75455801274299235341355169587755995541707405613253743917596982094560194111298", "price": "0.05", "size": "23.99", "side": "BUY", "hash": "c805289105c9c3dd44598a9b3196713442418b4c", "best_bid": "0.05", "best_ask": "0.96"}, {"asset_id": "26562265211720931675265155047873360108835400286939832140681489066284406369537", "price": "0.95", "size": "23.99", "side": "SELL", "hash": "a4f33b10d3b0f4ce7682bb376250cb3ae3ad545c", "best_bid": "0.04", "best_ask": "0.95"}], "timestamp": "1769384808734", "event_type": "price_change"}}
{"_local_timestamp": "2026-01-25T23:46:48.890788+00:00", "data": {"market": "0x66aa8a28579a59742b541d7d89f185231e24127d8d54e207d92e66213ed909ef", "price_changes": [{"asset_id": "91423736259203636828645539448680117024524087071143750679349605058506199161826", "price": "0.05", "size": "23.99", "side": "BUY", "hash": "4986028d763f217793e6039ca510ba5f2237b3a4", "best_bid": "0.05", "best_ask": "0.96"}, {"asset_id": "29482259799705002124566483090977991712914260860257479165135371688038751642644", "price": "0.95", "size": "23.99", "side": "SELL", "hash": "3047174f6bd4afc970a8c52a5c2b0a3a18faa9aa", "best_bid": "0.04", "best_ask": "0.95"}], "timestamp": "1769384808734", "event_type": "price_change"}}
{"_local_timestamp": "2026-01-25T23:46:48.891374+00:00", "data": {"market": "0x5bb085cf19c81e4c5e288ee70965fd061fb463199a1db6aa73c289c8b5d5b576", "price_changes": [{"asset_id": "94028695263980919862424407658493739709000655590831556337575886476241764379188", "price": "0.05", "size": "23.99", "side": "BUY", "hash": "eef795277a12c112458baaba18503691b6a1f251", "best_bid": "0.05", "best_ask": "0.96"}, {"asset_id": "3869270757164855312650371225248655982559601630752717256310586548174182218377", "price": "0.95", "size": "23.99", "side": "SELL", "hash": "09cf9e4bf702385ac360a8163e597fb8d7a8741b", "best_bid": "0.04", "best_ask": "0.95"}], "timestamp": "1769384808734", "event_type": "price_change"}}
{"_local_timestamp": "2026-01-25T23:46:48.891962+00:00", "data": {"market": "0xe2522c3113503fa3310842e464c988b3ee1791790d74e3bbf01ba7abeb25c80f", "price_changes": [{"asset_id": "34396356694568550365415333424976689315210304285798066025980709860841157649078", "price": "0.05", "size": "23.99", "side": "BUY", "hash": "aa102d9f35bca154251f71238317ba393d7aba86", "best_bid": "0.05", "best_ask": "0.96"}, {"asset_id": "58029788945233188177055776782641910265995378981338051319950769448049549823705", "price": "0.95", "size": "23.99", "side": "SELL", "hash": "265a1010c747a0d465a90823b4f5402c75a24616", "best_bid": "0.04", "best_ask": "0.95"}], "timestamp": "1769384808734", "event_type": "price_change"}}
{"_local_timestamp": "2026-01-25T23:46:54.006189+00:00", "data": {"market": "0x5bb085cf19c81e4c5e288ee70965fd061fb463199a1db6aa73c289c8b5d5b576", "price_changes": [{"asset_id": "94028695263980919862424407658493739709000655590831556337575886476241764379188", "price": "0.04", "size": "0", "side": "BUY", "hash": "191dd285a5a7dda10e7b5ab3eec15a1c35810bd8", "best_bid": "0.05", "best_ask": "0.96"}, {"asset_id": "3869270757164855312650371225248655982559601630752717256310586548174182218377", "price": "0.96", "size": "0", "side": "SELL", "hash": "3a7b6fdb54de7a56d6f44aae8d9ccbaa824efafe", "best_bid": "0.04", "best_ask": "0.95"}], "timestamp": "1769384813939", "event_type": "price_change"}}
{"_local_timestamp": "2026-01-25T23:46:54.006887+00:00", "data": {"market": "0xe2522c3113503fa3310842e464c988b3ee1791790d74e3bbf01ba7abeb25c80f", "price_changes": [{"asset_id": "34396356694568550365415333424976689315210304285798066025980709860841157649078", "price": "0.04", "size": "0", "side": "BUY", "hash": "0ca47eae3e279ae62162632f4911a45180622cdc", "best_bid": "0.05", "best_ask": "0.96"}, {"asset_id": "58029788945233188177055776782641910265995378981338051319950769448049549823705", "price": "0.96", "size": "0", "side": "SELL", "hash": "11d1c5d973bc433a30bda42e5c39e2258f3130f2", "best_bid": "0.04", "best_ask": "0.95"}], "timestamp": "1769384813939", "event_type": "price_change"}}
{"_local_timestamp": "2026-01-25T23:46:54.007476+00:00", "data": {"market": "0x4d9b924e07c1868f1ae0a71542c5e2945c86c14a04bd846bfe2f0bb95848a67e", "price_changes": [{"asset_id": "75455801274299235341355169587755995541707405613253743917596982094560194111298", "price": "0.04", "size": "0", "side": "BUY", "hash": "9feaba9462feaa479d841737467250973c464278", "best_bid": "0.05", "best_ask": "0.96"}, {"asset_id": "26562265211720931675265155047873360108835400286939832140681489066284406369537", "price": "0.96", "size": "0", "side": "SELL", "hash": "14c0c4ed999bcdd52258d7453bb8826a5e0a87e0", "best_bid": "0.04", "best_ask": "0.95"}], "timestamp": "1769384813939", "event_type": "price_change"}}
{"_local_timestamp": "2026-01-25T23:46:54.010703+00:00", "data": {"market": "0x66aa8a28579a59742b541d7d89f185231e24127d8d54e207d92e66213ed909ef", "price_changes": [{"asset_id": "91423736259203636828645539448680117024524087071143750679349605058506199161826", "price": "0.04", "size": "0", "side": "BUY", "hash": "fb90869dc12b791afceecf659b2f95ed39fcfa71", "best_bid": "0.05", "best_ask": "0.96"}, {"asset_id": "29482259799705002124566483090977991712914260860257479165135371688038751642644", "price": "0.96", "size": "0", "side": "SELL", "hash": "ed7fa833bc8d77a4493bda2f7853e2abc72bf6fb", "best_bid": "0.04", "best_ask": "0.95"}], "timestamp": "1769384813939", "event_type": "price_change"}}
{"_local_timestamp": "2026-01-25T23:46:54.011283+00:00", "data": {"market": "0x180cee3cb165e04b5556b5f54f156aecdfac62a7f99de19cb6e54247f046d80d", "price_changes": [{"asset_id": "45832756093987475477292835259287296516281710171095995001873781080428505369867", "price": "0.04", "size": "0", "side": "BUY", "hash": "af4c0b5485189dff88fc2f519ee9792a0d8a8c6d", "best_bid": "0.05", "best_ask": "0.96"}, {"asset_id": "41518792079540460126973298251922654758525254450148908246351858650533815863785", "price": "0.96", "size": "0", "side": "SELL", "hash": "567b6d436cd7f521c8ccb0097d2f733bdec69eac", "best_bid": "0.04", "best_ask": "0.95"}], "timestamp": "1769384813939", "event_type": "price_change"}}
{"_local_timestamp": "2026-01-25T23:46:54.190185+00:00", "data": {"market": "0xe2522c3113503fa3310842e464c988b3ee1791790d74e3bbf01ba7abeb25c80f", "price_changes": [{"asset_id": "34396356694568550365415333424976689315210304285798066025980709860841157649078", "price": "0.06", "size": "5.47", "side": "BUY", "hash": "cfec2fafe00b78f9e89027733347e0dc99a6872e", "best_bid": "0.06", "best_ask": "0.96"}, {"asset_id": "58029788945233188177055776782641910265995378981338051319950769448049549823705", "price": "0.94", "size": "5.47", "side": "SELL", "hash": "5b7a4da50183bc3d0a0609cc7230088d073de308", "best_bid": "0.04", "best_ask": "0.94"}], "timestamp": "1769384814116", "event_type": "price_change"}}
{"_local_timestamp": "2026-01-25T23:46:54.190853+00:00", "data": {"market": "0x66aa8a28579a59742b541d7d89f185231e24127d8d54e207d92e66213ed909ef", "price_changes": [{"asset_id": "91423736259203636828645539448680117024524087071143750679349605058506199161826", "price": "0.06", "size": "5.47", "side": "BUY", "hash": "2bf457fa564e207f109df8f155b04f5cd49abc7d", "best_bid": "0.06", "best_ask": "0.96"}, {"asset_id": "29482259799705002124566483090977991712914260860257479165135371688038751642644", "price": "0.94", "size": "5.47", "side": "SELL", "hash": "d38fe3c5913a0cc92f39fb3214d82cc10d781ed4", "best_bid": "0.04", "best_ask": "0.94"}], "timestamp": "1769384814116", "event_type": "price_change"}}
{"_local_timestamp": "2026-01-25T23:46:54.191490+00:00", "data": {"market": "0x180cee3cb165e04b5556b5f54f156aecdfac62a7f99de19cb6e54247f046d80d", "price_changes": [{"asset_id": "45832756093987475477292835259287296516281710171095995001873781080428505369867", "price": "0.06", "size": "5.47", "side": "BUY", "hash": "c0edc66008084dd7a5692957120e65a4f2c1461f", "best_bid": "0.06", "best_ask": "0.96"}, {"asset_id": "41518792079540460126973298251922654758525254450148908246351858650533815863785", "price": "0.94", "size": "5.47", "side": "SELL", "hash": "fa8350cc76820aef9993653c2c5c5ab2c50d8c21", "best_bid": "0.04", "best_ask": "0.94"}], "timestamp": "1769384814116", "event_type": "price_change"}}
{"_local_timestamp": "2026-01-25T23:46:54.192098+00:00", "data": {"market": "0x5bb085cf19c81e4c5e288ee70965fd061fb463199a1db6aa73c289c8b5d5b576", "price_changes": [{"asset_id": "94028695263980919862424407658493739709000655590831556337575886476241764379188", "price": "0.06", "size": "5.47", "side": "BUY", "hash": "34b63d788b1058e9bf15ecd971f00580f22223ae", "best_bid": "0.06", "best_ask": "0.96"}, {"asset_id": "3869270757164855312650371225248655982559601630752717256310586548174182218377", "price": "0.94", "size": "5.47", "side": "SELL", "hash": "797c6f5a2b4f341711a2b237d3865a7f871487ea", "best_bid": "0.04", "best_ask": "0.94"}], "timestamp": "1769384814116", "event_type": "price_change"}}
{"_local_timestamp": "2026-01-25T23:46:54.230252+00:00", "data": {"market": "0x4d9b924e07c1868f1ae0a71542c5e2945c86c14a04bd846bfe2f0bb95848a67e", "price_changes": [{"asset_id": "75455801274299235341355169587755995541707405613253743917596982094560194111298", "price": "0.06", "size": "5.47", "side": "BUY", "hash": "8184bd19ab3e6c3563bdf22959f345c3139d7870", "best_bid": "0.06", "best_ask": "0.96"}, {"asset_id": "26562265211720931675265155047873360108835400286939832140681489066284406369537", "price": "0.94", "size": "5.47", "side": "SELL", "hash": "ee468b324be7db0e89d8f657aa36a6e333ddf45b", "best_bid": "0.04", "best_ask": "0.94"}], "timestamp": "1769384814159", "event_type": "price_change"}}
{"_local_timestamp": "2026-01-25T23:48:17.681332+00:00", "data": {"market": "0xe2522c3113503fa3310842e464c988b3ee1791790d74e3bbf01ba7abeb25c80f", "price_changes": [{"asset_id": "34396356694568550365415333424976689315210304285798066025980709860841157649078", "price": "0.05", "size": "0", "side": "BUY", "hash": "e82fdba69af806de64f4b021bdee055204313f94", "best_bid": "0.06", "best_ask": "0.96"}, {"asset_id": "58029788945233188177055776782641910265995378981338051319950769448049549823705", "price": "0.95", "size": "0", "side": "SELL", "hash": "36b414e9a08ca6d0512fd159cfc90a372b1a3e58", "best_bid": "0.04", "best_ask": "0.94"}], "timestamp": "1769384897618", "event_type": "price_change"}}
{"_local_timestamp": "2026-01-25T23:48:17.685726+00:00", "data": {"market": "0x5bb085cf19c81e4c5e288ee70965fd061fb463199a1db6aa73c289c8b5d5b576", "price_changes": [{"asset_id": "94028695263980919862424407658493739709000655590831556337575886476241764379188", "price": "0.05", "size": "0", "side": "BUY", "hash": "22a8f87ce59b621d1422cfc6d42201bf9fcaf71f", "best_bid": "0.06", "best_ask": "0.96"}, {"asset_id": "3869270757164855312650371225248655982559601630752717256310586548174182218377", "price": "0.95", "size": "0", "side": "SELL", "hash": "70a33a71f9ae2e58247781b2fb3b81702acaa64b", "best_bid": "0.04", "best_ask": "0.94"}], "timestamp": "1769384897618", "event_type": "price_change"}}
{"_local_timestamp": "2026-01-25T23:48:17.776295+00:00", "data": {"market": "0x180cee3cb165e04b5556b5f54f156aecdfac62a7f99de19cb6e54247f046d80d", "price_changes": [{"asset_id": "45832756093987475477292835259287296516281710171095995001873781080428505369867", "price": "0.05", "size": "0", "side": "BUY", "hash": "2def01d10e2e821fdae330d8a58684f6ec85d6e7", "best_bid": "0.06", "best_ask": "0.96"}, {"asset_id": "41518792079540460126973298251922654758525254450148908246351858650533815863785", "price": "0.95", "size": "0", "side": "SELL", "hash": "ceffdc55cbfb7993ddebd215f6b2ed9446087346", "best_bid": "0.04", "best_ask": "0.94"}], "timestamp": "1769384897713", "event_type": "price_change"}}
{"_local_timestamp": "2026-01-25T23:48:17.776963+00:00", "data": {"market": "0x66aa8a28579a59742b541d7d89f185231e24127d8d54e207d92e66213ed909ef", "price_changes": [{"asset_id": "91423736259203636828645539448680117024524087071143750679349605058506199161826", "price": "0.05", "size": "0", "side": "BUY", "hash": "88699ba9506219ba5b52980da63f05ebcf0ef48a", "best_bid": "0.06", "best_ask": "0.96"}, {"asset_id": "29482259799705002124566483090977991712914260860257479165135371688038751642644", "price": "0.95", "size": "0", "side": "SELL", "hash": "31a4abbee9cb040e1a4e4a4eacd0a0fd59a860b0", "best_bid": "0.04", "best_ask": "0.94"}], "timestamp": "1769384897713", "event_type": "price_change"}}
{"_local_timestamp": "2026-01-25T23:48:17.870353+00:00", "data": {"market": "0x4d9b924e07c1868f1ae0a71542c5e2945c86c14a04bd846bfe2f0bb95848a67e", "price_changes": [{"asset_id": "75455801274299235341355169587755995541707405613253743917596982094560194111298", "price": "0.05", "size": "0", "side": "BUY", "hash": "156ffd1a13fc8e9dfb25815659a5de14443248dc", "best_bid": "0.06", "best_ask": "0.96"}, {"asset_id": "26562265211720931675265155047873360108835400286939832140681489066284406369537", "price": "0.95", "size": "0", "side": "SELL", "hash": "312f90f7ee71fd70eb568e0efcfc15fc212836b4", "best_bid": "0.04", "best_ask": "0.94"}], "timestamp": "1769384897807", "event_type": "price_change"}}
{"_local_timestamp": "2026-01-25T23:48:18.877625+00:00", "data": {"market": "0xca6684a2f5b699b04e9da70003381b45faa1a7807748abc7fbca1d689eede3dd", "price_changes": [{"asset_id": "75435923675834590025716428375190789880766798597634661131343729919797820504690", "price": "0.05", "size": "23.99", "side": "BUY", "hash": "149f3cad9d02d3fbe5b0f1629bb1562c307c13e7", "best_bid": "0.05", "best_ask": "0.96"}, {"asset_id": "67923079595575445284641976004414570715798135735376672166638592297910878774957", "price": "0.95", "size": "23.99", "side": "SELL", "hash": "d5469b5dc6d0f74325bad64d9d3b8cafd6c021d3", "best_bid": "0.04", "best_ask": "0.95"}], "timestamp": "1769384898757", "event_type": "price_change"}}
{"_local_timestamp": "2026-01-25T23:48:21.717919+00:00", "data": {"market": "0x180cee3cb165e04b5556b5f54f156aecdfac62a7f99de19cb6e54247f046d80d", "price_changes": [{"asset_id": "45832756093987475477292835259287296516281710171095995001873781080428505369867", "price": "0.06", "size": "0", "side": "BUY", "hash": "c0d241d88820fddb98184bf3a459f777cb0a6a4a", "best_bid": "0.03", "best_ask": "0.96"}, {"asset_id": "41518792079540460126973298251922654758525254450148908246351858650533815863785", "price": "0.94", "size": "0", "side": "SELL", "hash": "179d3710fbe584f62b6f390c1366e8055db45d53", "best_bid": "0.04", "best_ask": "0.97"}], "timestamp": "1769384901647", "event_type": "price_change"}}
{"_local_timestamp": "2026-01-25T23:48:21.721667+00:00", "data": {"market": "0xe2522c3113503fa3310842e464c988b3ee1791790d74e3bbf01ba7abeb25c80f", "price_changes": [{"asset_id": "34396356694568550365415333424976689315210304285798066025980709860841157649078", "price": "0.06", "size": "0", "side": "BUY", "hash": "e0f799a2bf3b204f61f9ceb189c96f429479372e", "best_bid": "0.03", "best_ask": "0.96"}, {"asset_id": "58029788945233188177055776782641910265995378981338051319950769448049549823705", "price": "0.94", "size": "0", "side": "SELL", "hash": "1900a031a6c3ca2dfa961fbe9e5306808a6a820c", "best_bid": "0.04", "best_ask": "0.97"}], "timestamp": "1769384901648", "event_type": "price_change"}}
{"_local_timestamp": "2026-01-25T23:48:21.722320+00:00", "data": {"market": "0x66aa8a28579a59742b541d7d89f185231e24127d8d54e207d92e66213ed909ef", "price_changes": [{"asset_id": "91423736259203636828645539448680117024524087071143750679349605058506199161826", "price": "0.06", "size": "0", "side": "BUY", "hash": "20829827433163252a6470bde4476c412d52a62e", "best_bid": "0.03", "best_ask": "0.96"}, {"asset_id": "29482259799705002124566483090977991712914260860257479165135371688038751642644", "price": "0.94", "size": "0", "side": "SELL", "hash": "ed482d676e6afbb7b0e66b83112adef186bb1b3f", "best_bid": "0.04", "best_ask": "0.97"}], "timestamp": "1769384901648", "event_type": "price_change"}}
{"_local_timestamp": "2026-01-25T23:48:21.729785+00:00", "data": {"market": "0x4d9b924e07c1868f1ae0a71542c5e2945c86c14a04bd846bfe2f0bb95848a67e", "price_changes": [{"asset_id": "75455801274299235341355169587755995541707405613253743917596982094560194111298", "price": "0.06", "size": "0", "side": "BUY", "hash": "e5597f51d7147b99b63764b07860101cf3131fa3", "best_bid": "0.03", "best_ask": "0.96"}, {"asset_id": "26562265211720931675265155047873360108835400286939832140681489066284406369537", "price": "0.94", "size": "0", "side": "SELL", "hash": "e7133192d29d975d56ca67aa2d048939fd9154e1", "best_bid": "0.04", "best_ask": "0.97"}], "timestamp": "1769384901647", "event_type": "price_change"}}
{"_local_timestamp": "2026-01-25T23:48:21.730632+00:00", "data": {"market": "0x5bb085cf19c81e4c5e288ee70965fd061fb463199a1db6aa73c289c8b5d5b576", "price_changes": [{"asset_id": "94028695263980919862424407658493739709000655590831556337575886476241764379188", "price": "0.06", "size": "0", "side": "BUY", "hash": "77d82fe7f513d89697a41e5b532fca3232135112", "best_bid": "0.03", "best_ask": "0.96"}, {"asset_id": "3869270757164855312650371225248655982559601630752717256310586548174182218377", "price": "0.94", "size": "0", "side": "SELL", "hash": "246b48ddcd8a0b558fb971c9781f5df8916c102d", "best_bid": "0.04", "best_ask": "0.97"}], "timestamp": "1769384901648", "event_type": "price_change"}}
{"_local_timestamp": "2026-01-25T23:48:21.731245+00:00", "data": {"market": "0xca6684a2f5b699b04e9da70003381b45faa1a7807748abc7fbca1d689eede3dd", "price_changes": [{"asset_id": "75435923675834590025716428375190789880766798597634661131343729919797820504690", "price": "0.04", "size": "0", "side": "BUY", "hash": "792115962d44727d5610de4cb8ee15a8fe4de5aa", "best_bid": "0.05", "best_ask": "0.96"}, {"asset_id": "67923079595575445284641976004414570715798135735376672166638592297910878774957", "price": "0.96", "size": "0", "side": "SELL", "hash": "f8c7479f40cd3670acd5299b8abaa41162b36156", "best_bid": "0.04", "best_ask": "0.95"}], "timestamp": "1769384901648", "event_type": "price_change"}}
{"_local_timestamp": "2026-01-25T23:48:21.968763+00:00", "data": {"market": "0x5bb085cf19c81e4c5e288ee70965fd061fb463199a1db6aa73c289c8b5d5b576", "price_changes": [{"asset_id": "94028695263980919862424407658493739709000655590831556337575886476241764379188", "price": "0.04", "size": "5.47", "side": "BUY", "hash": "3adeee9d9bc0f7459ad456e9ef5d0cf57e29dd57", "best_bid": "0.04", "best_ask": "0.96"}, {"asset_id": "3869270757164855312650371225248655982559601630752717256310586548174182218377", "price": "0.96", "size": "5.47", "side": "SELL", "hash": "7507bce950dfb964ccfd1d43344f1c31e7b9dd93", "best_bid": "0.04", "best_ask": "0.96"}], "timestamp": "1769384901904", "event_type": "price_change"}}
{"_local_timestamp": "2026-01-25T23:48:21.975268+00:00", "data": {"market": "0xe2522c3113503fa3310842e464c988b3ee1791790d74e3bbf01ba7abeb25c80f", "price_changes": [{"asset_id": "34396356694568550365415333424976689315210304285798066025980709860841157649078", "price": "0.04", "size": "5.47", "side": "BUY", "hash": "86b95a09563c7a16a748825792e29b6455e1afa6", "best_bid": "0.04", "best_ask": "0.96"}, {"asset_id": "58029788945233188177055776782641910265995378981338051319950769448049549823705", "price": "0.96", "size": "5.47", "side": "SELL", "hash": "43cf7e8760d35b966035721823ee33184f6b4104", "best_bid": "0.04", "best_ask": "0.96"}], "timestamp": "1769384901904", "event_type": "price_change"}}
{"_local_timestamp": "2026-01-25T23:48:21.975971+00:00", "data": {"market": "0x66aa8a28579a59742b541d7d89f185231e24127d8d54e207d92e66213ed909ef", "price_changes": [{"asset_id": "91423736259203636828645539448680117024524087071143750679349605058506199161826", "price": "0.04", "size": "5.47", "side": "BUY", "hash": "5575eae80fbdd0ef3aa03f078d0c6e13ef380aa2", "best_bid": "0.04", "best_ask": "0.96"}, {"asset_id": "29482259799705002124566483090977991712914260860257479165135371688038751642644", "price": "0.96", "size": "5.47", "side": "SELL", "hash": "9433205608810247635530e92e518794dc414482", "best_bid": "0.04", "best_ask": "0.96"}], "timestamp": "1769384901904", "event_type": "price_change"}}
{"_local_timestamp": "2026-01-25T23:48:21.976699+00:00", "data": {"market": "0x180cee3cb165e04b5556b5f54f156aecdfac62a7f99de19cb6e54247f046d80d", "price_changes": [{"asset_id": "45832756093987475477292835259287296516281710171095995001873781080428505369867", "price": "0.04", "size": "5.47", "side": "BUY", "hash": "4417d926846d3639868eea83991d5e3e5e5ed002", "best_bid": "0.04", "best_ask": "0.96"}, {"asset_id": "41518792079540460126973298251922654758525254450148908246351858650533815863785", "price": "0.96", "size": "5.47", "side": "SELL", "hash": "0e68ff1742b705ae47e418728b8491fa2da3175d", "best_bid": "0.04", "best_ask": "0.96"}], "timestamp": "1769384901904", "event_type": "price_change"}}
{"_local_timestamp": "2026-01-25T23:48:21.977392+00:00", "data": {"market": "0xca6684a2f5b699b04e9da70003381b45faa1a7807748abc7fbca1d689eede3dd", "price_changes": [{"asset_id": "75435923675834590025716428375190789880766798597634661131343729919797820504690", "price": "0.06", "size": "5.47", "side": "BUY", "hash": "f8d443b9a46eeb4b4d22534a5a60d154db7006b4", "best_bid": "0.06", "best_ask": "0.96"}, {"asset_id": "67923079595575445284641976004414570715798135735376672166638592297910878774957", "price": "0.94", "size": "5.47", "side": "SELL", "hash": "e25957c7e4ac128a66d556c5f5bdb19ab0dd3613", "best_bid": "0.04", "best_ask": "0.94"}], "timestamp": "1769384901904", "event_type": "price_change"}}
{"_local_timestamp": "2026-01-25T23:48:21.978046+00:00", "data": {"market": "0x4d9b924e07c1868f1ae0a71542c5e2945c86c14a04bd846bfe2f0bb95848a67e", "price_changes": [{"asset_id": "75455801274299235341355169587755995541707405613253743917596982094560194111298", "price": "0.04", "size": "5.47", "side": "BUY", "hash": "4ee2a631083a70465fff7063db5fa54e8547752e", "best_bid": "0.04", "best_ask": "0.96"}, {"asset_id": "26562265211720931675265155047873360108835400286939832140681489066284406369537", "price": "0.96", "size": "5.47", "side": "SELL", "hash": "2ec7ddfde731ab81dc3e32aa680459ffdf93c340", "best_bid": "0.04", "best_ask": "0.96"}], "timestamp": "1769384901904", "event_type": "price_change"}}
{"_local_timestamp": "2026-01-25T23:49:42.912053+00:00", "data": {"market": "0xca6684a2f5b699b04e9da70003381b45faa1a7807748abc7fbca1d689eede3dd", "price_changes": [{"asset_id": "75435923675834590025716428375190789880766798597634661131343729919797820504690", "price": "0.05", "size": "0", "side": "BUY", "hash": "e35f51a995d2289784217e59b7b1ac3867e747df", "best_bid": "0.06", "best_ask": "0.96"}, {"asset_id": "67923079595575445284641976004414570715798135735376672166638592297910878774957", "price": "0.95", "size": "0", "side": "SELL", "hash": "3e43a317d88c8e2fc1dbc8bffeda32a64cbf072b", "best_bid": "0.04", "best_ask": "0.94"}], "timestamp": "1769384982838", "event_type": "price_change"}}
{"_local_timestamp": "2026-01-25T23:49:43.087354+00:00", "data": {"market": "0x66aa8a28579a59742b541d7d89f185231e24127d8d54e207d92e66213ed909ef", "price_changes": [{"asset_id": "91423736259203636828645539448680117024524087071143750679349605058506199161826", "price": "0.02", "size": "29.03", "side": "BUY", "hash": "aaeef2e70811ba98feddc921e3e6a129b0e1ca01", "best_bid": "0.04", "best_ask": "0.96"}, {"asset_id": "29482259799705002124566483090977991712914260860257479165135371688038751642644", "price": "0.98", "size": "29.03", "side": "SELL", "hash": "637ce80506794bf75396a73a29af0aed330f076a", "best_bid": "0.04", "best_ask": "0.96"}], "timestamp": "1769384983001", "event_type": "price_change"}}
{"_local_timestamp": "2026-01-25T23:49:43.131568+00:00", "data": {"market": "0x66aa8a28579a59742b541d7d89f185231e24127d8d54e207d92e66213ed909ef", "price_changes": [{"asset_id": "29482259799705002124566483090977991712914260860257479165135371688038751642644", "price": "0.02", "size": "40.48", "side": "BUY", "hash": "f3da0b702f8cf510c40426560e5478d95d399506", "best_bid": "0.04", "best_ask": "0.96"}, {"asset_id": "91423736259203636828645539448680117024524087071143750679349605058506199161826", "price": "0.98", "size": "40.48", "side": "SELL", "hash": "87420ba7fe094826fe4e9781b9afbb41b421d74b", "best_bid": "0.04", "best_ask": "0.96"}], "timestamp": "1769384983003", "event_type": "price_change"}}
{"_local_timestamp": "2026-01-25T23:49:43.990759+00:00", "data": {"market": "0x4d9b924e07c1868f1ae0a71542c5e2945c86c14a04bd846bfe2f0bb95848a67e", "price_changes": [{"asset_id": "75455801274299235341355169587755995541707405613253743917596982094560194111298", "price": "0.05", "size": "23.99", "side": "BUY", "hash": "ddb6bb07970784c7e63f0907fa7ad74f3da351db", "best_bid": "0.05", "best_ask": "0.96"}, {"asset_id": "26562265211720931675265155047873360108835400286939832140681489066284406369537", "price": "0.95", "size": "23.99", "side": "SELL", "hash": "83da8ff6af13f1d3119ac4d7ab4980c997585ce3", "best_bid": "0.04", "best_ask": "0.95"}], "timestamp": "1769384983921", "event_type": "price_change"}}
{"_local_timestamp": "2026-01-25T23:49:44.624396+00:00", "data": {"market": "0x66aa8a28579a59742b541d7d89f185231e24127d8d54e207d92e66213ed909ef", "price_changes": [{"asset_id": "91423736259203636828645539448680117024524087071143750679349605058506199161826", "price": "0.02", "size": "179.03", "side": "BUY", "hash": "e2cd73f60079cbdb7d61f157d51b54cc9760859b", "best_bid": "0.04", "best_ask": "0.96"}, {"asset_id": "29482259799705002124566483090977991712914260860257479165135371688038751642644", "price": "0.98", "size": "179.03", "side": "SELL", "hash": "d2a1c5d0a9378de587c0ef106ef50aeb83bc07a1", "best_bid": "0.04", "best_ask": "0.96"}], "timestamp": "1769384984554", "event_type": "price_change"}}
{"_local_timestamp": "2026-01-25T23:49:44.625238+00:00", "data": {"market": "0x66aa8a28579a59742b541d7d89f185231e24127d8d54e207d92e66213ed909ef", "price_changes": [{"asset_id": "29482259799705002124566483090977991712914260860257479165135371688038751642644", "price": "0.02", "size": "190.48", "side": "BUY", "hash": "a4aa5dff0b520d944d74ab446604a7bb7e094dd8", "best_bid": "0.04", "best_ask": "0.96"}, {"asset_id": "91423736259203636828645539448680117024524087071143750679349605058506199161826", "price": "0.98", "size": "190.48", "side": "SELL", "hash": "21f141047cec95fed4ebc6ff3d0fb8c7b402e3b0", "best_bid": "0.04", "best_ask": "0.96"}], "timestamp": "1769384984555", "event_type": "price_change"}}
{"_local_timestamp": "2026-01-25T23:49:46.655776+00:00", "data": {"market": "0xca6684a2f5b699b04e9da70003381b45faa1a7807748abc7fbca1d689eede3dd", "price_changes": [{"asset_id": "75435923675834590025716428375190789880766798597634661131343729919797820504690", "price": "0.06", "size": "0", "side": "BUY", "hash": "d8579070bf881241d3eb9579eca94cdf5aab9a9c", "best_bid": "0.03", "best_ask": "0.96"}, {"asset_id": "67923079595575445284641976004414570715798135735376672166638592297910878774957", "price": "0.94", "size": "0", "side": "SELL", "hash": "42b4789128bccb3e18721216cca05be91f9606d6", "best_bid": "0.04", "best_ask": "0.97"}], "timestamp": "1769384986576", "event_type": "price_change"}}
{"_local_timestamp": "2026-01-25T23:49:46.658826+00:00", "data": {"market": "0x4d9b924e07c1868f1ae0a71542c5e2945c86c14a04bd846bfe2f0bb95848a67e", "price_changes": [{"asset_id": "75455801274299235341355169587755995541707405613253743917596982094560194111298", "price": "0.04", "size": "0", "side": "BUY", "hash": "0722b6a7844ae815f7e1b9a3d0b81e47f43237f8", "best_bid": "0.05", "best_ask": "0.96"}, {"asset_id": "26562265211720931675265155047873360108835400286939832140681489066284406369537", "price": "0.96", "size": "0", "side": "SELL", "hash": "18eed0fbffc61dcee24295b7ec9031fc1a0c1139", "best_bid": "0.04", "best_ask": "0.95"}], "timestamp": "1769384986576", "event_type": "price_change"}}
{"_local_timestamp": "2026-01-25T23:49:46.775172+00:00", "data": {"market": "0x4d9b924e07c1868f1ae0a71542c5e2945c86c14a04bd846bfe2f0bb95848a67e", "price_changes": [{"asset_id": "75455801274299235341355169587755995541707405613253743917596982094560194111298", "price": "0.06", "size": "5.47", "side": "BUY", "hash": "aa8123b14f6b2e211092281e6b768021a67c6be5", "best_bid": "0.06", "best_ask": "0.96"}, {"asset_id": "26562265211720931675265155047873360108835400286939832140681489066284406369537", "price": "0.94", "size": "5.47", "side": "SELL", "hash": "6f89ecf5638ca39df937a4a269097510328f489e", "best_bid": "0.04", "best_ask": "0.94"}], "timestamp": "1769384986703", "event_type": "price_change"}}
{"_local_timestamp": "2026-01-25T23:49:46.775996+00:00", "data": {"market": "0xca6684a2f5b699b04e9da70003381b45faa1a7807748abc7fbca1d689eede3dd", "price_changes": [{"asset_id": "75435923675834590025716428375190789880766798597634661131343729919797820504690", "price": "0.04", "size": "5.47", "side": "BUY", "hash": "7c67733c621c4e46b1332c1b905d58ee5d84e359", "best_bid": "0.04", "best_ask": "0.96"}, {"asset_id": "67923079595575445284641976004414570715798135735376672166638592297910878774957", "price": "0.96", "size": "5.47", "side": "SELL", "hash": "a27e446c77bfed17df7cdefc72fa12210afaf450", "best_bid": "0.04", "best_ask": "0.96"}], "timestamp": "1769384986703", "event_type": "price_change"}}
{"_local_timestamp": "2026-01-25T23:50:01.848756+00:00", "data": {"market": "0x644991b60a94b272357e6f68d1615680703601accb15d7302f499b737d4a0db0", "price_changes": [{"asset_id": "80482043625015601757240447150279689188946061800550924069274579383544776374468", "price": "0.03", "size": "9.81", "side": "BUY", "hash": "bc81ca974f074b03205eace800cdb0dc90231d2e", "best_bid": "0.04", "best_ask": "0.96"}, {"asset_id": "107742164566063298345228923210014891131960841481018710120513126758098443996397", "price": "0.97", "size": "9.81", "side": "SELL", "hash": "c5a4a1961dbfe71c411daa4e0e5a962b067089e1", "best_bid": "0.04", "best_ask": "0.96"}], "timestamp": "1769385001773", "event_type": "price_change"}}
{"_local_timestamp": "2026-01-25T23:50:02.113039+00:00", "data": {"market": "0x644991b60a94b272357e6f68d1615680703601accb15d7302f499b737d4a0db0", "price_changes": [{"asset_id": "80482043625015601757240447150279689188946061800550924069274579383544776374468", "price": "0.03", "size": "19.82", "side": "BUY", "hash": "d7c244b98bbf7451bb10a4bff659636bd90156b3", "best_bid": "0.04", "best_ask": "0.96"}, {"asset_id": "107742164566063298345228923210014891131960841481018710120513126758098443996397", "price": "0.97", "size": "19.82", "side": "SELL", "hash": "aebf7fb8aa382dc3622248e8c04aa28b25eb122c", "best_bid": "0.04", "best_ask": "0.96"}], "timestamp": "1769385002011", "event_type": "price_change"}}
{"_local_timestamp": "2026-01-25T23:50:02.114102+00:00", "data": {"market": "0x644991b60a94b272357e6f68d1615680703601accb15d7302f499b737d4a0db0", "price_changes": [{"asset_id": "80482043625015601757240447150279689188946061800550924069274579383544776374468", "price": "0.01", "size": "67.61", "side": "BUY", "hash": "df6b16da9b391056f5924c7a9c70d3656c7b1d36", "best_bid": "0.04", "best_ask": "0.96"}, {"asset_id": "107742164566063298345228923210014891131960841481018710120513126758098443996397", "price": "0.99", "size": "67.61", "side": "SELL", "hash": "3ff8c73a9461fc296d621bb9865f5627e3f9cee4", "best_bid": "0.04", "best_ask": "0.96"}], "timestamp": "1769385002012", "event_type": "price_change"}}
{"_local_timestamp": "2026-01-25T23:50:03.353521+00:00", "data": {"market": "0x4d9b924e07c1868f1ae0a71542c5e2945c86c14a04bd846bfe2f0bb95848a67e", "price_changes": [{"asset_id": "75455801274299235341355169587755995541707405613253743917596982094560194111298", "price": "0.01", "size": "203.03", "side": "BUY", "hash": "1384bba837586a46f82768f46b864fded409dcc2", "best_bid": "0.06", "best_ask": "0.96"}, {"asset_id": "26562265211720931675265155047873360108835400286939832140681489066284406369537", "price": "0.99", "size": "203.03", "side": "SELL", "hash": "33d8b2041da8cf955dbbe0c3583447bffeaea572", "best_bid": "0.04", "best_ask": "0.94"}], "timestamp": "1769385003228", "event_type": "price_change"}}
{"_local_timestamp": "2026-01-25T23:50:03.354428+00:00", "data": {"market": "0x4d9b924e07c1868f1ae0a71542c5e2945c86c14a04bd846bfe2f0bb95848a67e", "price_changes": [{"asset_id": "75455801274299235341355169587755995541707405613253743917596982094560194111298", "price": "0.02", "size": "250.06", "side": "BUY", "hash": "1384bba837586a46f82768f46b864fded409dcc2", "best_bid": "0.06", "best_ask": "0.96"}, {"asset_id": "26562265211720931675265155047873360108835400286939832140681489066284406369537", "price": "0.98", "size": "250.06", "side": "SELL", "hash": "33d8b2041da8cf955dbbe0c3583447bffeaea572", "best_bid": "0.04", "best_ask": "0.94"}], "timestamp": "1769385003228", "event_type": "price_change"}}
{"_local_timestamp": "2026-01-25T23:50:03.355113+00:00", "data": {"market": "0x4d9b924e07c1868f1ae0a71542c5e2945c86c14a04bd846bfe2f0bb95848a67e", "price_changes": [{"asset_id": "75455801274299235341355169587755995541707405613253743917596982094560194111298", "price": "0.03", "size": "8.96", "side": "BUY", "hash": "1384bba837586a46f82768f46b864fded409dcc2", "best_bid": "0.06", "best_ask": "0.96"}, {"asset_id": "26562265211720931675265155047873360108835400286939832140681489066284406369537", "price": "0.97", "size": "8.96", "side": "SELL", "hash": "33d8b2041da8cf955dbbe0c3583447bffeaea572", "best_bid": "0.04", "best_ask": "0.94"}], "timestamp": "1769385003228", "event_type": "price_change"}}
{"_local_timestamp": "2026-01-25T23:50:03.362670+00:00", "data": {"market": "0xdae2149f65e89818c56124e772eee704f55f1a411482755dba026d4c727af0e4", "price_changes": [{"asset_id": "5731740857323119517691200242442035314690159130302063918637002279721289590857", "price": "0.03", "size": "9.81", "side": "BUY", "hash": "331521cdba7f589d75df3f23afc36c35330be987", "best_bid": "0.04", "best_ask": "0.96"}, {"asset_id": "108539949567612627196500132085967459870136452742815448382213013024762772569343", "price": "0.97", "size": "9.81", "side": "SELL", "hash": "66010e5deff04149869887fb6f58ef9eb4c6e9c6", "best_bid": "0.04", "best_ask": "0.96"}], "timestamp": "1769385003228", "event_type": "price_change"}}
{"_local_timestamp": "2026-01-25T23:50:04.166603+00:00", "data": {"market": "0xdae2149f65e89818c56124e772eee704f55f1a411482755dba026d4c727af0e4", "price_changes": [{"asset_id": "5731740857323119517691200242442035314690159130302063918637002279721289590857", "price": "0.03", "size": "19.82", "side": "BUY", "hash": "11ef80db2fa49fc916a6ee159901f5c674c846b7", "best_bid": "0.04", "best_ask": "0.96"}, {"asset_id": "108539949567612627196500132085967459870136452742815448382213013024762772569343", "price": "0.97", "size": "19.82", "side": "SELL", "hash": "edb71ca74c5e9e1a4459bc64b5f898f096a5a23d", "best_bid": "0.04", "best_ask": "0.96"}], "timestamp": "1769385004068", "event_type": "price_change"}}
{"_local_timestamp": "2026-01-25T23:50:04.168426+00:00", "data": {"market": "0x4d9b924e07c1868f1ae0a71542c5e2945c86c14a04bd846bfe2f0bb95848a67e", "price_changes": [{"asset_id": "75455801274299235341355169587755995541707405613253743917596982094560194111298", "price": "0.02", "size": "260.32", "side": "BUY", "hash": "a54141627b1ed1f8fc3103c52f4eec7659719159", "best_bid": "0.06", "best_ask": "0.96"}, {"asset_id": "26562265211720931675265155047873360108835400286939832140681489066284406369537", "price": "0.98", "size": "260.32", "side": "SELL", "hash": "1214860d622239941c78e77e6bd75eedcf241fa4", "best_bid": "0.04", "best_ask": "0.94"}], "timestamp": "1769385004068", "event_type": "price_change"}}
{"_local_timestamp": "2026-01-25T23:50:04.170348+00:00", "data": {"market": "0xdae2149f65e89818c56124e772eee704f55f1a411482755dba026d4c727af0e4", "price_changes": [{"asset_id": "5731740857323119517691200242442035314690159130302063918637002279721289590857", "price": "0.01", "size": "67.61", "side": "BUY", "hash": "71f32ee99498cc986094ade2688976e5cdf08cdd", "best_bid": "0.04", "best_ask": "0.96"}, {"asset_id": "108539949567612627196500132085967459870136452742815448382213013024762772569343", "price": "0.99", "size": "67.61", "side": "SELL", "hash": "9e82b9bffef4461bc10c7ac808d33316d290edd0", "best_bid": "0.04", "best_ask": "0.96"}], "timestamp": "1769385004071", "event_type": "price_change"}}
{"_local_timestamp": "2026-01-25T23:50:04.171093+00:00", "data": {"market": "0x4d9b924e07c1868f1ae0a71542c5e2945c86c14a04bd846bfe2f0bb95848a67e", "price_changes": [{"asset_id": "75455801274299235341355169587755995541707405613253743917596982094560194111298", "price": "0.04", "size": "7.35", "side": "BUY", "hash": "d6290913ffc0b4eebc24ae4ebb07fe223844945c", "best_bid": "0.06", "best_ask": "0.96"}, {"asset_id": "26562265211720931675265155047873360108835400286939832140681489066284406369537", "price": "0.96", "size": "7.35", "side": "SELL", "hash": "20e269ac76d53c589b002e7c859b17b2713bc7fa", "best_bid": "0.04", "best_ask": "0.94"}], "timestamp": "1769385004072", "event_type": "price_change"}}
{"_local_timestamp": "2026-01-25T23:50:06.688718+00:00", "data": {"market": "0xe2522c3113503fa3310842e464c988b3ee1791790d74e3bbf01ba7abeb25c80f", "price_changes": [{"asset_id": "34396356694568550365415333424976689315210304285798066025980709860841157649078", "price": "0.01", "size": "156.93", "side": "BUY", "hash": "5d441886005be2bb3a9151b4269c3862d8c07339", "best_bid": "0.04", "best_ask": "0.96"}, {"asset_id": "58029788945233188177055776782641910265995378981338051319950769448049549823705", "price": "0.99", "size": "156.93", "side": "SELL", "hash": "8e41b04bb79c0749e1b8f7d2e335a0084e40a9bd", "best_bid": "0.04", "best_ask": "0.96"}], "timestamp": "1769385006614", "event_type": "price_change"}}
{"_local_timestamp": "2026-01-25T23:50:06.985853+00:00", "data": {"market": "0xe2522c3113503fa3310842e464c988b3ee1791790d74e3bbf01ba7abeb25c80f", "price_changes": [{"asset_id": "34396356694568550365415333424976689315210304285798066025980709860841157649078", "price": "0.01", "size": "169.65", "side": "BUY", "hash": "0ef72df682098fbf060aad579a4f83310ae70d08", "best_bid": "0.04", "best_ask": "0.96"}, {"asset_id": "58029788945233188177055776782641910265995378981338051319950769448049549823705", "price": "0.99", "size": "169.65", "side": "SELL", "hash": "a1fd8bf51a4a92899f99d54066b2828c2a04ded3", "best_bid": "0.04", "best_ask": "0.96"}], "timestamp": "1769385006915", "event_type": "price_change"}}
{"_local_timestamp": "2026-01-25T23:50:07.996690+00:00", "data": {"market": "0x618f90d78c70081e7dd7d422c3e2299e4a77d35edb8e4258ae0297ddfab14e17", "price_changes": [{"asset_id": "88493938041191305708637957243458880188207866339223186442772420759619853972732", "price": "0.03", "size": "8.97", "side": "BUY", "hash": "5f443b0d85b531208a9393d66438ec3e5d0416d5", "best_bid": "0.04", "best_ask": "0.96"}, {"asset_id": "630142824528014601903526077196303536591995171166379784723107847019383910560", "price": "0.97", "size": "8.97", "side": "SELL", "hash": "7fbdd53dbd7f8ab07850d06084ccef47436bf2d8", "best_bid": "0.04", "best_ask": "0.96"}], "timestamp": "1769385007920", "event_type": "price_change"}}
{"_local_timestamp": "2026-01-25T23:50:08.421583+00:00", "data": {"market": "0xc794d53782d2a57779c1bd1d7fe4e1012cd63daa340d6733478b04e43c779bb2", "price_changes": [{"asset_id": "29850745557425233278441255217116778127787897972791369065729373689355832286173", "price": "0.03", "size": "9.81", "side": "BUY", "hash": "21bbfe0e95395e506deb083e77cf68708804526e", "best_bid": "0.04", "best_ask": "0.96"}, {"asset_id": "65285709653207321996387925181629862243682185841555542627225011614554527757803", "price": "0.97", "size": "9.81", "side": "SELL", "hash": "d3c3dbe41ce1b7c8aa9cc7516571f5cb9caa61dc", "best_bid": "0.04", "best_ask": "0.96"}], "timestamp": "1769385008350", "event_type": "price_change"}}
{"_local_timestamp": "2026-01-25T23:50:08.863636+00:00", "data": {"market": "0xc794d53782d2a57779c1bd1d7fe4e1012cd63daa340d6733478b04e43c779bb2", "price_changes": [{"asset_id": "29850745557425233278441255217116778127787897972791369065729373689355832286173", "price": "0.03", "size": "19.82", "side": "BUY", "hash": "f54e47ab1d486f53a28bdd785aef7e839c018ede", "best_bid": "0.04", "best_ask": "0.96"}, {"asset_id": "65285709653207321996387925181629862243682185841555542627225011614554527757803", "price": "0.97", "size": "19.82", "side": "SELL", "hash": "3c4c2554b742ab3e0c9e748bf2ff994ee790c925", "best_bid": "0.04", "best_ask": "0.96"}], "timestamp": "1769385008788", "event_type": "price_change"}}
{"_local_timestamp": "2026-01-25T23:50:08.864489+00:00", "data": {"market": "0xc794d53782d2a57779c1bd1d7fe4e1012cd63daa340d6733478b04e43c779bb2", "price_changes": [{"asset_id": "29850745557425233278441255217116778127787897972791369065729373689355832286173", "price": "0.01", "size": "67.61", "side": "BUY", "hash": "9da33a662c0573ee1d2133a0770fbbc2870683b7", "best_bid": "0.04", "best_ask": "0.96"}, {"asset_id": "65285709653207321996387925181629862243682185841555542627225011614554527757803", "price": "0.99", "size": "67.61", "side": "SELL", "hash": "5c55296dae316e69cd649c11885c4c8830798d15", "best_bid": "0.04", "best_ask": "0.96"}], "timestamp": "1769385008789", "event_type": "price_change"}}
{"_local_timestamp": "2026-01-25T23:50:08.883950+00:00", "data": {"market": "0x618f90d78c70081e7dd7d422c3e2299e4a77d35edb8e4258ae0297ddfab14e17", "price_changes": [{"asset_id": "88493938041191305708637957243458880188207866339223186442772420759619853972732", "price": "0.01", "size": "67.05", "side": "BUY", "hash": "73fc7437c2807784f3453f7fbd51bd86de8e5209", "best_bid": "0.04", "best_ask": "0.96"}, {"asset_id": "630142824528014601903526077196303536591995171166379784723107847019383910560", "price": "0.99", "size": "67.05", "side": "SELL", "hash": "0aa42a988fbf8d08e13e0a610a2f5254c87347b6", "best_bid": "0.04", "best_ask": "0.96"}], "timestamp": "1769385008814", "event_type": "price_change"}}
{"_local_timestamp": "2026-01-25T23:50:08.884823+00:00", "data": {"market": "0x618f90d78c70081e7dd7d422c3e2299e4a77d35edb8e4258ae0297ddfab14e17", "price_changes": [{"asset_id": "88493938041191305708637957243458880188207866339223186442772420759619853972732", "price": "0.03", "size": "18.99", "side": "BUY", "hash": "c801c2131c971f2a9bc119b368e66db45be2d66e", "best_bid": "0.04", "best_ask": "0.96"}, {"asset_id": "630142824528014601903526077196303536591995171166379784723107847019383910560", "price": "0.97", "size": "18.99", "side": "SELL", "hash": "91bb2a5bbd38905872446b0250284d18565461a7", "best_bid": "0.04", "best_ask": "0.96"}], "timestamp": "1769385008815", "event_type": "price_change"}}
{"_local_timestamp": "2026-01-25T23:50:08.893449+00:00", "data": {"market": "0x618f90d78c70081e7dd7d422c3e2299e4a77d35edb8e4258ae0297ddfab14e17", "price_changes": [{"asset_id": "88493938041191305708637957243458880188207866339223186442772420759619853972732", "price": "0.02", "size": "182.48", "side": "BUY", "hash": "57be2b523e311dd96ef80e3a8fb800a3a28cd4b0", "best_bid": "0.04", "best_ask": "0.96"}, {"asset_id": "630142824528014601903526077196303536591995171166379784723107847019383910560", "price": "0.98", "size": "182.48", "side": "SELL", "hash": "ffbb4c1626996d870a078e8068a19ab5d83995e7", "best_bid": "0.04", "best_ask": "0.96"}], "timestamp": "1769385008816", "event_type": "price_change"}}
{"_local_timestamp": "2026-01-25T23:50:09.144360+00:00", "data": {"market": "0x9e546f5bd8aaa57b741386967b6f0cb83ba70ff12cf399a3b104f5ded3e01c33", "price_changes": [{"asset_id": "98748914400722920263495947114807262573236269758480928212643590321888570153891", "price": "0.03", "size": "9.81", "side": "BUY", "hash": "f210f4d98c9fd0a5310622a85aa773c98aa39119", "best_bid": "0.04", "best_ask": "0.96"}, {"asset_id": "52384449694849030011952391984862607032268821842864420008617516574964644205640", "price": "0.97", "size": "9.81", "side": "SELL", "hash": "339e1df604a9aee2463b6e06c8f86cc6c70d7f8d", "best_bid": "0.04", "best_ask": "0.96"}], "timestamp": "1769385009075", "event_type": "price_change"}}
{"_local_timestamp": "2026-01-25T23:50:09.632952+00:00", "data": {"market": "0x9e546f5bd8aaa57b741386967b6f0cb83ba70ff12cf399a3b104f5ded3e01c33", "price_changes": [{"asset_id": "98748914400722920263495947114807262573236269758480928212643590321888570153891", "price": "0.02", "size": "182.48", "side": "BUY", "hash": "514e32f035b2ade275cbfded609a39dd951c7f53", "best_bid": "0.04", "best_ask": "0.96"}, {"asset_id": "52384449694849030011952391984862607032268821842864420008617516574964644205640", "price": "0.98", "size": "182.48", "side": "SELL", "hash": "4be5d1296295d2b205cbb9e5c4c6bdb9374f1417", "best_bid": "0.04", "best_ask": "0.96"}], "timestamp": "1769385009557", "event_type": "price_change"}}
{"_local_timestamp": "2026-01-25T23:50:09.633778+00:00", "data": {"market": "0x9e546f5bd8aaa57b741386967b6f0cb83ba70ff12cf399a3b104f5ded3e01c33", "price_changes": [{"asset_id": "98748914400722920263495947114807262573236269758480928212643590321888570153891", "price": "0.03", "size": "18.99", "side": "BUY", "hash": "2477e489a997036ded2919a6fb24e5731317e53d", "best_bid": "0.04", "best_ask": "0.96"}, {"asset_id": "52384449694849030011952391984862607032268821842864420008617516574964644205640", "price": "0.97", "size": "18.99", "side": "SELL", "hash": "69fb712cdcb0a06e8714ad6f3a3e3416e7844c2d", "best_bid": "0.04", "best_ask": "0.96"}], "timestamp": "1769385009558", "event_type": "price_change"}}
{"_local_timestamp": "2026-01-25T23:50:09.634543+00:00", "data": {"market": "0x9e546f5bd8aaa57b741386967b6f0cb83ba70ff12cf399a3b104f5ded3e01c33", "price_changes": [{"asset_id": "98748914400722920263495947114807262573236269758480928212643590321888570153891", "price": "0.01", "size": "67.05", "side": "BUY", "hash": "8819c5d6b9f035d60ad9163ff6ea654005708290", "best_bid": "0.04", "best_ask": "0.96"}, {"asset_id": "52384449694849030011952391984862607032268821842864420008617516574964644205640", "price": "0.99", "size": "67.05", "side": "SELL", "hash": "1cd37770da2791a94ed7d8345d5b811d7b93e607", "best_bid": "0.04", "best_ask": "0.96"}], "timestamp": "1769385009559", "event_type": "price_change"}}
{"_local_timestamp": "2026-01-25T23:50:10.160489+00:00", "data": {"market": "0xca6684a2f5b699b04e9da70003381b45faa1a7807748abc7fbca1d689eede3dd", "price_changes": [{"asset_id": "75435923675834590025716428375190789880766798597634661131343729919797820504690", "price": "0.03", "size": "8.61", "side": "BUY", "hash": "094113e4808d4c0f2d7b373b7c9af93dff0d815e", "best_bid": "0.04", "best_ask": "0.96"}, {"asset_id": "67923079595575445284641976004414570715798135735376672166638592297910878774957", "price": "0.97", "size": "8.61", "side": "SELL", "hash": "22b2e6bfc088ecd0571d8bf21aa3e7ec82bd0040", "best_bid": "0.04", "best_ask": "0.96"}], "timestamp": "1769385010086", "event_type": "price_change"}}
{"_local_timestamp": "2026-01-25T23:50:10.397340+00:00", "data": {"market": "0xca6684a2f5b699b04e9da70003381b45faa1a7807748abc7fbca1d689eede3dd", "price_changes": [{"asset_id": "75435923675834590025716428375190789880766798597634661131343729919797820504690", "price": "0.03", "size": "23.02", "side": "BUY", "hash": "98481fef71704b24e03cbda2ede520ad0b0932c3", "best_bid": "0.04", "best_ask": "0.96"}, {"asset_id": "67923079595575445284641976004414570715798135735376672166638592297910878774957", "price": "0.97", "size": "23.02", "side": "SELL", "hash": "c0bdbe6906987ff960afd8d5b347263abf45498a", "best_bid": "0.04", "best_ask": "0.96"}], "timestamp": "1769385010325", "event_type": "price_change"}}
{"_local_timestamp": "2026-01-25T23:51:10.128724+00:00", "data": {"market": "0x4d9b924e07c1868f1ae0a71542c5e2945c86c14a04bd846bfe2f0bb95848a67e", "price_changes": [{"asset_id": "75455801274299235341355169587755995541707405613253743917596982094560194111298", "price": "0.05", "size": "0", "side": "BUY", "hash": "cd9536b2d34538e28b3eff80e86c24396766b855", "best_bid": "0.06", "best_ask": "0.96"}, {"asset_id": "26562265211720931675265155047873360108835400286939832140681489066284406369537", "price": "0.95", "size": "0", "side": "SELL", "hash": "ec603d19088c8e15542da85d52078f94106a34d5", "best_bid": "0.04", "best_ask": "0.94"}], "timestamp": "1769385070046", "event_type": "price_change"}}
{"_local_timestamp": "2026-01-25T23:51:11.494496+00:00", "data": {"market": "0x644991b60a94b272357e6f68d1615680703601accb15d7302f499b737d4a0db0", "price_changes": [{"asset_id": "80482043625015601757240447150279689188946061800550924069274579383544776374468", "price": "0.05", "size": "23.99", "side": "BUY", "hash": "79a22d12cee97ea33190ad45551e2e3640213fd5", "best_bid": "0.05", "best_ask": "0.96"}, {"asset_id": "107742164566063298345228923210014891131960841481018710120513126758098443996397", "price": "0.95", "size": "23.99", "side": "SELL", "hash": "ca39809bafb8ac1a935c6027e41c95e94616f716", "best_bid": "0.04", "best_ask": "0.95"}], "timestamp": "1769385071423", "event_type": "price_change"}}
{"_local_timestamp": "2026-01-25T23:51:11.495345+00:00", "data": {"market": "0x180cee3cb165e04b5556b5f54f156aecdfac62a7f99de19cb6e54247f046d80d", "price_changes": [{"asset_id": "45832756093987475477292835259287296516281710171095995001873781080428505369867", "price": "0.05", "size": "23.99", "side": "BUY", "hash": "9dc9f3f08f85466836c4f07f91c69d337ba989b4", "best_bid": "0.05", "best_ask": "0.96"}, {"asset_id": "41518792079540460126973298251922654758525254450148908246351858650533815863785", "price": "0.95", "size": "23.99", "side": "SELL", "hash": "164b935c04cfa9d72fa8c7d0384c502593286bea", "best_bid": "0.04", "best_ask": "0.95"}], "timestamp": "1769385071423", "event_type": "price_change"}}
{"_local_timestamp": "2026-01-25T23:51:11.496095+00:00", "data": {"market": "0xe2522c3113503fa3310842e464c988b3ee1791790d74e3bbf01ba7abeb25c80f", "price_changes": [{"asset_id": "34396356694568550365415333424976689315210304285798066025980709860841157649078", "price": "0.05", "size": "23.99", "side": "BUY", "hash": "93e968c4d4e8a918c017d1b4ddfabcbbfb658c55", "best_bid": "0.05", "best_ask": "0.96"}, {"asset_id": "58029788945233188177055776782641910265995378981338051319950769448049549823705", "price": "0.95", "size": "23.99", "side": "SELL", "hash": "559c59c021ff1a3c646c8356ea2608e272ec183f", "best_bid": "0.04", "best_ask": "0.95"}], "timestamp": "1769385071423", "event_type": "price_change"}}
{"_local_timestamp": "2026-01-25T23:51:11.496781+00:00", "data": {"market": "0x66aa8a28579a59742b541d7d89f185231e24127d8d54e207d92e66213ed909ef", "price_changes": [{"asset_id": "91423736259203636828645539448680117024524087071143750679349605058506199161826", "price": "0.05", "size": "23.99", "side": "BUY", "hash": "3bcb1e3e8b6541a402b467c504c06d3855b59427", "best_bid": "0.05", "best_ask": "0.96"}, {"asset_id": "29482259799705002124566483090977991712914260860257479165135371688038751642644", "price": "0.95", "size": "23.99", "side": "SELL", "hash": "6d890b3085123196095d0e5b0fc88f009c72c7c1", "best_bid": "0.04", "best_ask": "0.95"}], "timestamp": "1769385071424", "event_type": "price_change"}}
{"_local_timestamp": "2026-01-25T23:51:11.497472+00:00", "data": {"market": "0xdae2149f65e89818c56124e772eee704f55f1a411482755dba026d4c727af0e4", "price_changes": [{"asset_id": "5731740857323119517691200242442035314690159130302063918637002279721289590857", "price": "0.05", "size": "23.99", "side": "BUY", "hash": "1a8df91b15e9e3eaaa6f00c01207b514e40a4f5a", "best_bid": "0.05", "best_ask": "0.96"}, {"asset_id": "108539949567612627196500132085967459870136452742815448382213013024762772569343", "price": "0.95", "size": "23.99", "side": "SELL", "hash": "75097d9020c4ece6146723db2e4d8edee5b602a9", "best_bid": "0.04", "best_ask": "0.95"}], "timestamp": "1769385071424", "event_type": "price_change"}}
{"_local_timestamp": "2026-01-25T23:51:11.498217+00:00", "data": {"market": "0x5bb085cf19c81e4c5e288ee70965fd061fb463199a1db6aa73c289c8b5d5b576", "price_changes": [{"asset_id": "94028695263980919862424407658493739709000655590831556337575886476241764379188", "price": "0.05", "size": "23.99", "side": "BUY", "hash": "015fadec7861cc261a840f6fe470e0a7d88f6fec", "best_bid": "0.05", "best_ask": "0.96"}, {"asset_id": "3869270757164855312650371225248655982559601630752717256310586548174182218377", "price": "0.95", "size": "23.99", "side": "SELL", "hash": "0dab3dfff12120973fc694d51be080a2c3cd2a7d", "best_bid": "0.04", "best_ask": "0.95"}], "timestamp": "1769385071424", "event_type": "price_change"}}
{"_local_timestamp": "2026-01-25T23:51:11.597382+00:00", "data": {"market": "0x618f90d78c70081e7dd7d422c3e2299e4a77d35edb8e4258ae0297ddfab14e17", "price_changes": [{"asset_id": "88493938041191305708637957243458880188207866339223186442772420759619853972732", "price": "0.05", "size": "23.99", "side": "BUY", "hash": "59aca3ea937960abbca8fbbb46e950252f388c73", "best_bid": "0.05", "best_ask": "0.96"}, {"asset_id": "630142824528014601903526077196303536591995171166379784723107847019383910560", "price": "0.95", "size": "23.99", "side": "SELL", "hash": "a676c7dfb5dd78f28c02ef29a30a05537a25a92f", "best_bid": "0.04", "best_ask": "0.95"}], "timestamp": "1769385071524", "event_type": "price_change"}}
{"_local_timestamp": "2026-01-25T23:51:11.598172+00:00", "data": {"market": "0x9e546f5bd8aaa57b741386967b6f0cb83ba70ff12cf399a3b104f5ded3e01c33", "price_changes": [{"asset_id": "98748914400722920263495947114807262573236269758480928212643590321888570153891", "price": "0.05", "size": "23.99", "side": "BUY", "hash": "5f07c1b36e9634278e4d22d5218bccfc5bf96c7a", "best_bid": "0.05", "best_ask": "0.96"}, {"asset_id": "52384449694849030011952391984862607032268821842864420008617516574964644205640", "price": "0.95", "size": "23.99", "side": "SELL", "hash": "17228337f35cea0897cd23e35d7ec9118f5cb53d", "best_bid": "0.04", "best_ask": "0.95"}], "timestamp": "1769385071525", "event_type": "price_change"}}
{"_local_timestamp": "2026-01-25T23:51:11.598893+00:00", "data": {"market": "0xc794d53782d2a57779c1bd1d7fe4e1012cd63daa340d6733478b04e43c779bb2", "price_changes": [{"asset_id": "29850745557425233278441255217116778127787897972791369065729373689355832286173", "price": "0.05", "size": "23.99", "side": "BUY", "hash": "fe67ea86efb913066b4dfedd4078e2e1b833ed59", "best_bid": "0.05", "best_ask": "0.96"}, {"asset_id": "65285709653207321996387925181629862243682185841555542627225011614554527757803", "price": "0.95", "size": "23.99", "side": "SELL", "hash": "4234233a0a87bf06c5f5d189065db14f38d8508e", "best_bid": "0.04", "best_ask": "0.95"}], "timestamp": "1769385071525", "event_type": "price_change"}}
{"_local_timestamp": "2026-01-25T23:51:14.044316+00:00", "data": {"market": "0x618f90d78c70081e7dd7d422c3e2299e4a77d35edb8e4258ae0297ddfab14e17", "price_changes": [{"asset_id": "88493938041191305708637957243458880188207866339223186442772420759619853972732", "price": "0.04", "size": "0", "side": "BUY", "hash": "f55cf51fd211824909b4ca4099f9075b20fc1057", "best_bid": "0.05", "best_ask": "0.96"}, {"asset_id": "630142824528014601903526077196303536591995171166379784723107847019383910560", "price": "0.96", "size": "0", "side": "SELL", "hash": "68b86f0563ca9b3da14f9574d76c7ce0393a715a", "best_bid": "0.04", "best_ask": "0.95"}], "timestamp": "1769385073959", "event_type": "price_change"}}
{"_local_timestamp": "2026-01-25T23:51:14.045255+00:00", "data": {"market": "0xc794d53782d2a57779c1bd1d7fe4e1012cd63daa340d6733478b04e43c779bb2", "price_changes": [{"asset_id": "29850745557425233278441255217116778127787897972791369065729373689355832286173", "price": "0.04", "size": "0", "side": "BUY", "hash": "c6632a7a1422d434862496d0cdf8b8cba2f7b437", "best_bid": "0.05", "best_ask": "0.96"}, {"asset_id": "65285709653207321996387925181629862243682185841555542627225011614554527757803", "price": "0.96", "size": "0", "side": "SELL", "hash": "200a82ee5ef428dedaeb1b527ceedcf4d636312c", "best_bid": "0.04", "best_ask": "0.95"}], "timestamp": "1769385073959", "event_type": "price_change"}}
{"_local_timestamp": "2026-01-25T23:51:14.046114+00:00", "data": {"market": "0xdae2149f65e89818c56124e772eee704f55f1a411482755dba026d4c727af0e4", "price_changes": [{"asset_id": "5731740857323119517691200242442035314690159130302063918637002279721289590857", "price": "0.04", "size": "0", "side": "BUY", "hash": "4b6535c275e7c29edd09ab111cf42de49a1c6c92", "best_bid": "0.05", "best_ask": "0.96"}, {"asset_id": "108539949567612627196500132085967459870136452742815448382213013024762772569343", "price": "0.96", "size": "0", "side": "SELL", "hash": "ef818aa1845e546f542e8bf06d112806968a331f", "best_bid": "0.04", "best_ask": "0.95"}], "timestamp": "1769385073959", "event_type": "price_change"}}
{"_local_timestamp": "2026-01-25T23:51:14.046908+00:00", "data": {"market": "0x5bb085cf19c81e4c5e288ee70965fd061fb463199a1db6aa73c289c8b5d5b576", "price_changes": [{"asset_id": "94028695263980919862424407658493739709000655590831556337575886476241764379188", "price": "0.04", "size": "0", "side": "BUY", "hash": "be44c22c1924aaa34efe28ec72e0380686316f3c", "best_bid": "0.05", "best_ask": "0.96"}, {"asset_id": "3869270757164855312650371225248655982559601630752717256310586548174182218377", "price": "0.96", "size": "0", "side": "SELL", "hash": "8ef1030bc04c179be1a0508448266b6252bfee4c", "best_bid": "0.04", "best_ask": "0.95"}], "timestamp": "1769385073959", "event_type": "price_change"}}
{"_local_timestamp": "2026-01-25T23:51:14.047675+00:00", "data": {"market": "0x644991b60a94b272357e6f68d1615680703601accb15d7302f499b737d4a0db0", "price_changes": [{"asset_id": "80482043625015601757240447150279689188946061800550924069274579383544776374468", "price": "0.04", "size": "0", "side": "BUY", "hash": "9b575278940a0883451e2b5bdc32e72ea3e9391f", "best_bid": "0.05", "best_ask": "0.96"}, {"asset_id": "107742164566063298345228923210014891131960841481018710120513126758098443996397", "price": "0.96", "size": "0", "side": "SELL", "hash": "f1bd17177a3127ef595d2b05d4119df7102e48ad", "best_bid": "0.04", "best_ask": "0.95"}], "timestamp": "1769385073959", "event_type": "price_change"}}
{"_local_timestamp": "2026-01-25T23:51:14.048467+00:00", "data": {"market": "0x9e546f5bd8aaa57b741386967b6f0cb83ba70ff12cf399a3b104f5ded3e01c33", "price_changes": [{"asset_id": "98748914400722920263495947114807262573236269758480928212643590321888570153891", "price": "0.04", "size": "0", "side": "BUY", "hash": "4d647e991c1e8a8859586c4bb8c826943b3a7e07", "best_bid": "0.05", "best_ask": "0.96"}, {"asset_id": "52384449694849030011952391984862607032268821842864420008617516574964644205640", "price": "0.96", "size": "0", "side": "SELL", "hash": "96df66b8b5a1e0a72309d3937f88dafb9d3bbaba", "best_bid": "0.04", "best_ask": "0.95"}], "timestamp": "1769385073959", "event_type": "price_change"}}
{"_local_timestamp": "2026-01-25T23:51:14.049302+00:00", "data": {"market": "0xe2522c3113503fa3310842e464c988b3ee1791790d74e3bbf01ba7abeb25c80f", "price_changes": [{"asset_id": "34396356694568550365415333424976689315210304285798066025980709860841157649078", "price": "0.04", "size": "0", "side": "BUY", "hash": "ba2ec3f16db1c7729238a9e7d7861f59c65f01f1", "best_bid": "0.05", "best_ask": "0.96"}, {"asset_id": "58029788945233188177055776782641910265995378981338051319950769448049549823705", "price": "0.96", "size": "0", "side": "SELL", "hash": "d4fdae96bc4d7428a12cfcbe5ca29394ecaa8324", "best_bid": "0.04", "best_ask": "0.95"}], "timestamp": "1769385073958", "event_type": "price_change"}}
{"_local_timestamp": "2026-01-25T23:51:14.050191+00:00", "data": {"market": "0x180cee3cb165e04b5556b5f54f156aecdfac62a7f99de19cb6e54247f046d80d", "price_changes": [{"asset_id": "45832756093987475477292835259287296516281710171095995001873781080428505369867", "price": "0.04", "size": "0", "side": "BUY", "hash": "f54ca8fa67a296f37b386889e3f41af0b45c30ed", "best_bid": "0.05", "best_ask": "0.96"}, {"asset_id": "41518792079540460126973298251922654758525254450148908246351858650533815863785", "price": "0.96", "size": "0", "side": "SELL", "hash": "5d16d93021ae3294aba5cee29e1acd203a1d4fd7", "best_bid": "0.04", "best_ask": "0.95"}], "timestamp": "1769385073959", "event_type": "price_change"}}
{"_local_timestamp": "2026-01-25T23:51:14.051015+00:00", "data": {"market": "0x66aa8a28579a59742b541d7d89f185231e24127d8d54e207d92e66213ed909ef", "price_changes": [{"asset_id": "91423736259203636828645539448680117024524087071143750679349605058506199161826", "price": "0.04", "size": "0", "side": "BUY", "hash": "9c62799208675b0c0d516a535184f669a06daf59", "best_bid": "0.05", "best_ask": "0.96"}, {"asset_id": "29482259799705002124566483090977991712914260860257479165135371688038751642644", "price": "0.96", "size": "0", "side": "SELL", "hash": "2b60c0156bfdae0a8d9700fa6bef976a06ac9a3c", "best_bid": "0.04", "best_ask": "0.95"}], "timestamp": "1769385073959", "event_type": "price_change"}}
{"_local_timestamp": "2026-01-25T23:51:14.051842+00:00", "data": {"market": "0x4d9b924e07c1868f1ae0a71542c5e2945c86c14a04bd846bfe2f0bb95848a67e", "price_changes": [{"asset_id": "75455801274299235341355169587755995541707405613253743917596982094560194111298", "price": "0.06", "size": "0", "side": "BUY", "hash": "6e34462b1b0e70636bdd5f9dd7ba95ee14cf19fb", "best_bid": "0.04", "best_ask": "0.96"}, {"asset_id": "26562265211720931675265155047873360108835400286939832140681489066284406369537", "price": "0.94", "size": "0", "side": "SELL", "hash": "4148a919422b6d20756e4bca650c6d4940e1d8a1", "best_bid": "0.04", "best_ask": "0.96"}], "timestamp": "1769385073959", "event_type": "price_change"}}
{"_local_timestamp": "2026-01-25T23:51:14.249572+00:00", "data": {"market": "0xc794d53782d2a57779c1bd1d7fe4e1012cd63daa340d6733478b04e43c779bb2", "price_changes": [{"asset_id": "29850745557425233278441255217116778127787897972791369065729373689355832286173", "price": "0.06", "size": "5.47", "side": "BUY", "hash": "8eb737c489201a14dd6df07fd1a4d19c06c13bdd", "best_bid": "0.06", "best_ask": "0.96"}, {"asset_id": "65285709653207321996387925181629862243682185841555542627225011614554527757803", "price": "0.94", "size": "5.47", "side": "SELL", "hash": "5da5e92e0decb70d33562e79060215d1d8613db7", "best_bid": "0.04", "best_ask": "0.94"}], "timestamp": "1769385074187", "event_type": "price_change"}}
{"_local_timestamp": "2026-01-25T23:51:14.250476+00:00", "data": {"market": "0xe2522c3113503fa3310842e464c988b3ee1791790d74e3bbf01ba7abeb25c80f", "price_changes": [{"asset_id": "34396356694568550365415333424976689315210304285798066025980709860841157649078", "price": "0.06", "size": "5.47", "side": "BUY", "hash": "6a5ec467a7c88b3f6ec97a24e94b03fdc5f66f0c", "best_bid": "0.06", "best_ask": "0.96"}, {"asset_id": "58029788945233188177055776782641910265995378981338051319950769448049549823705", "price": "0.94", "size": "5.47", "side": "SELL", "hash": "147eba79f5b22cd060fdcdbb3997c6e823dfa04d", "best_bid": "0.04", "best_ask": "0.94"}], "timestamp": "1769385074187", "event_type": "price_change"}}
{"_local_timestamp": "2026-01-25T23:51:14.251297+00:00", "data": {"market": "0x180cee3cb165e04b5556b5f54f156aecdfac62a7f99de19cb6e54247f046d80d", "price_changes": [{"asset_id": "45832756093987475477292835259287296516281710171095995001873781080428505369867", "price": "0.06", "size": "5.47", "side": "BUY", "hash": "f0132066c393ef7fbc263c5cc6663d19a0d806c9", "best_bid": "0.06", "best_ask": "0.96"}, {"asset_id": "41518792079540460126973298251922654758525254450148908246351858650533815863785", "price": "0.94", "size": "5.47", "side": "SELL", "hash": "81e8e8dfecdafb81ac3948feb1f790ccc7df3354", "best_bid": "0.04", "best_ask": "0.94"}], "timestamp": "1769385074187", "event_type": "price_change"}}
{"_local_timestamp": "2026-01-25T23:51:14.252107+00:00", "data": {"market": "0x644991b60a94b272357e6f68d1615680703601accb15d7302f499b737d4a0db0", "price_changes": [{"asset_id": "80482043625015601757240447150279689188946061800550924069274579383544776374468", "price": "0.06", "size": "5.47", "side": "BUY", "hash": "589dba330e5fbe1bdaeb7a8c3b1aea55508e21ce", "best_bid": "0.06", "best_ask": "0.96"}, {"asset_id": "107742164566063298345228923210014891131960841481018710120513126758098443996397", "price": "0.94", "size": "5.47", "side": "SELL", "hash": "a168dd8e2157f036e9ebc0fb02cfd6c0e4b19af2", "best_bid": "0.04", "best_ask": "0.94"}], "timestamp": "1769385074187", "event_type": "price_change"}}
{"_local_timestamp": "2026-01-25T23:51:14.258722+00:00", "data": {"market": "0x618f90d78c70081e7dd7d422c3e2299e4a77d35edb8e4258ae0297ddfab14e17", "price_changes": [{"asset_id": "88493938041191305708637957243458880188207866339223186442772420759619853972732", "price": "0.06", "size": "5.47", "side": "BUY", "hash": "6e1b07622ae24c0fb157e57b7ba9c22847b3e782", "best_bid": "0.06", "best_ask": "0.96"}, {"asset_id": "630142824528014601903526077196303536591995171166379784723107847019383910560", "price": "0.94", "size": "5.47", "side": "SELL", "hash": "82b792e998a2975a2bb5d757d6d8f79f4c38dd61", "best_bid": "0.04", "best_ask": "0.94"}], "timestamp": "1769385074187", "event_type": "price_change"}}
{"_local_timestamp": "2026-01-25T23:51:14.259808+00:00", "data": {"market": "0x9e546f5bd8aaa57b741386967b6f0cb83ba70ff12cf399a3b104f5ded3e01c33", "price_changes": [{"asset_id": "98748914400722920263495947114807262573236269758480928212643590321888570153891", "price": "0.06", "size": "5.47", "side": "BUY", "hash": "86339965121f4337529905f634772827dd7a51bc", "best_bid": "0.06", "best_ask": "0.96"}, {"asset_id": "52384449694849030011952391984862607032268821842864420008617516574964644205640", "price": "0.94", "size": "5.47", "side": "SELL", "hash": "d5453a75a8cf3b9281d27d940d624dc30480774e", "best_bid": "0.04", "best_ask": "0.94"}], "timestamp": "1769385074187", "event_type": "price_change"}}
{"_local_timestamp": "2026-01-25T23:51:14.266413+00:00", "data": {"market": "0x5bb085cf19c81e4c5e288ee70965fd061fb463199a1db6aa73c289c8b5d5b576", "price_changes": [{"asset_id": "94028695263980919862424407658493739709000655590831556337575886476241764379188", "price": "0.06", "size": "5.47", "side": "BUY", "hash": "a01e5ad45ec9c8fc50732bafacb07af9d2aecea9", "best_bid": "0.06", "best_ask": "0.96"}, {"asset_id": "3869270757164855312650371225248655982559601630752717256310586548174182218377", "price": "0.94", "size": "5.47", "side": "SELL", "hash": "120c96926b4baf3e2a8734c6c784b87a92ded90b", "best_bid": "0.04", "best_ask": "0.94"}], "timestamp": "1769385074187", "event_type": "price_change"}}
{"_local_timestamp": "2026-01-25T23:51:14.304015+00:00", "data": {"market": "0xdae2149f65e89818c56124e772eee704f55f1a411482755dba026d4c727af0e4", "price_changes": [{"asset_id": "5731740857323119517691200242442035314690159130302063918637002279721289590857", "price": "0.06", "size": "5.47", "side": "BUY", "hash": "81b1f7ae2c458978b610b3ec94b2faad04cdd509", "best_bid": "0.06", "best_ask": "0.96"}, {"asset_id": "108539949567612627196500132085967459870136452742815448382213013024762772569343", "price": "0.94", "size": "5.47", "side": "SELL", "hash": "1a108eb15db6017671c3cb6b7519ab741c6359a3", "best_bid": "0.04", "best_ask": "0.94"}], "timestamp": "1769385074239", "event_type": "price_change"}}
{"_local_timestamp": "2026-01-25T23:51:14.305685+00:00", "data": {"market": "0x66aa8a28579a59742b541d7d89f185231e24127d8d54e207d92e66213ed909ef", "price_changes": [{"asset_id": "91423736259203636828645539448680117024524087071143750679349605058506199161826", "price": "0.06", "size": "5.47", "side": "BUY", "hash": "63b7de8846d5490f967f334b1242d114ac36566d", "best_bid": "0.06", "best_ask": "0.96"}, {"asset_id": "29482259799705002124566483090977991712914260860257479165135371688038751642644", "price": "0.94", "size": "5.47", "side": "SELL", "hash": "dc0249dd6745269bb798a1abdd3bd48b7ba818f3", "best_bid": "0.04", "best_ask": "0.94"}], "timestamp": "1769385074239", "event_type": "price_change"}}
{"_local_timestamp": "2026-01-25T23:51:14.306539+00:00", "data": {"market": "0x4d9b924e07c1868f1ae0a71542c5e2945c86c14a04bd846bfe2f0bb95848a67e", "price_changes": [{"asset_id": "75455801274299235341355169587755995541707405613253743917596982094560194111298", "price": "0.05", "size": "5.47", "side": "BUY", "hash": "602c8945f8791598c936c207dca5fb3255520933", "best_bid": "0.05", "best_ask": "0.96"}, {"asset_id": "26562265211720931675265155047873360108835400286939832140681489066284406369537", "price": "0.95", "size": "5.47", "side": "SELL", "hash": "9a55f9439a3a0c6f5b84281d0c858e4f39385415", "best_bid": "0.04", "best_ask": "0.95"}], "timestamp": "1769385074240", "event_type": "price_change"}}
