{"_local_timestamp": "2026-01-25T23:33:53.249684+00:00", "data": [{"market": "0xa82369f8cd0613e9cb843d07e87c6b91b564c1265738b69e7053b75d8d194072", "asset_id": "68920659505468313520408686217763348542438468104855337990549641270016076337409", "timestamp": "1769383885943", "hash": "819b939a0f4d652e3e0f71798eb462eaa07dd3fe", "bids": [{"price": "0.01", "size": "105.78"}, {"price": "0.02", "size": "203.94"}, {"price": "0.03", "size": "10.03"}, {"price": "0.06", "size": "11.51"}], "asks": [{"price": "0.99", "size": "112.04"}, {"price": "0.98", "size": "215.48"}, {"price": "0.97", "size": "18.99"}, {"price": "0.96", "size": "29.99"}], "event_type": "book", "last_trade_price": ""}, {"market": "0x755a62c90339cdf3468fab177c6bfd9dceb5e45203e68bf069b50303a6abd25f", "asset_id": "84460776671731186445015851207745064196399530432412893483409324414283960172444", "timestamp": "1769383840241", "hash": "b56c9466a08ec5f16e395081f9c7a2dec80deea8", "bids": [{"price": "0.01", "size": "62.05"}, {"price": "0.02", "size": "190.48"}, {"price": "0.03", "size": "18.99"}, {"price": "0.04", "size": "29.99"}], "asks": [{"price": "0.99", "size": "69.11"}, {"price": "0.98", "size": "178.75"}, {"price": "0.97", "size": "20.79"}, {"price": "0.96", "size": "5.47"}], "event_type": "book", "last_trade_price": ""}, {"market": "0xa9e485d9ab8973f5683fc4992b591ab9997052b8d7acc5d800d197e95ba0f5ee", "asset_id": "52957896528748198044120161866858084167956853408096664478472083379802465908152", "timestamp": "1769383840382", "hash": "76edc13ca80164a2818ce27f3c1566a1843a32dc", "bids": [{"price": "0.01", "size": "59.79"}, {"price": "0.02", "size": "179.03"}, {"price": "0.03", "size": "23.71"}, {"price": "0.04", "size": "5.47"}], "asks": [{"price": "0.99", "size": "62.05"}, {"price": "0.98", "size": "190.48"}, {"price": "0.97", "size": "18.99"}, {"price": "0.96", "size": "38.98"}], "event_type": "book", "last_trade_price": ""}, {"market": "0x887d9af4bfb28d239e7ed0c69ff91d84ece92a11b58984d0ff0393c0c24a2d01", "asset_id": "53797474885844189083818567441605903163912505725772675434705257100199647449827", "timestamp": "1769383843652", "hash": "708950072f0df8048ad6b9e4faeb81775f848f97", "bids": [{"price": "0.01", "size": "162.05"}, {"price": "0.02", "size": "240.48"}, {"price": "0.03", "size": "18.99"}, {"price": "0.04", "size": "29.99"}], "asks": [{"price": "0.99", "size": "156.8"}, {"price": "0.98", "size": "227.67"}, {"price": "0.97", "size": "25.62"}, {"price": "0.96", "size": "5.47"}], "event_type": "book", "last_trade_price": ""}, {"market": "0xca130e51e4406596d098557a80d3fa6e95eb16d32ef09d08d20da8b7ab6d6298", "asset_id": "9877937220298673394222737478141754783632484432479493143738647510821851680044", "timestamp": "1769383843652", "hash": "0aff682a790144b0924faf1eeab82a8e174b3493", "bids": [{"price": "0.01", "size": "62.05"}, {"price": "0.02", "size": "180.48"}, {"price": "0.03", "size": "18.99"}, {"price": "0.04", "size": "29.99"}], "asks": [{"price": "0.99", "size": "57.68"}, {"price": "0.98", "size": "177.05"}, {"price": "0.97", "size": "25.74"}, {"price": "0.96", "size": "5.47"}], "event_type": "book", "last_trade_price": ""}, {"market": "0xc3e7877c4d9446b5c2ca915c4bf2b12b6165efcf74b881c5c37ae06a6f7f0b40", "asset_id": "32696279816781562603646861024864649709139349878042119834576074948718205721178", "timestamp": "1769382623700", "hash": "c179db8beaccb2b78ff33bafce090e5663c3c892", "bids": [{"price": "0.01", "size": "45"}, {"price": "0.02", "size": "155.71"}, {"price": "0.03", "size": "81"}, {"price": "0.04", "size": "22.14"}, {"price": "0.4", "size": "6"}], "asks": [{"price": "0.99", "size": "1050.25"}, {"price": "0.98", "size": "150"}, {"price": "0.97", "size": "13.24"}, {"price": "0.95", "size": "10"}, {"price": "0.94", "size": "8.33"}, {"price": "0.44", "size": "5"}, {"price": "0.43", "size": "5"}, {"price": "0.41", "size": "290"}], "event_type": "book", "last_trade_price": ""}, {"market": "0x0c35017fce45618791b247a0e015a99dfdaa11fce35665f46a21329c75539bf5", "asset_id": "91719725116883012291565512161477775996897243486374553084185529876278409496454", "timestamp": "1769383842528", "hash": "0496c36ca00cf64bcfa3ce7e24554b07a91e71f7", "bids": [{"price": "0.01", "size": "68.51"}, {"price": "0.02", "size": "179.03"}, {"price": "0.03", "size": "20.8"}, {"price": "0.04", "size": "5.47"}], "asks": [{"price": "0.99", "size": "62.05"}, {"price": "0.98", "size": "190.48"}, {"price": "0.97", "size": "18.99"}, {"price": "0.96", "size": "29.99"}], "event_type": "book", "last_trade_price": ""}, {"market": "0xa2945f80a0c041b15c57a16539369873a31aae20c028d50efc9f4fe4c46f9973", "asset_id": "36376479227210509138719694118857362983085092412966657890412021289097812996653", "timestamp": "1769383840382", "hash": "cc09d61cfbd1e2c65a58fbd5843262a330379b65", "bids": [{"price": "0.01", "size": "62.05"}, {"price": "0.02", "size": "190.48"}, {"price": "0.03", "size": "18.99"}, {"price": "0.04", "size": "29.99"}], "asks": [{"price": "0.99", "size": "59.78"}, {"price": "0.98", "size": "179.03"}, {"price": "0.97", "size": "23.72"}, {"price": "0.96", "size": "5.47"}], "event_type": "book", "last_trade_price": ""}, {"market": "0x0c35017fce45618791b247a0e015a99dfdaa11fce35665f46a21329c75539bf5", "asset_id": "113869036122116896359974222126121258669445902300788141703831662654178658580719", "timestamp": "1769383842528", "hash": "a4f78cb31150a26feb32fbf1ed9d29875ef95923", "bids": [{"price": "0.01", "size": "62.05"}, {"price": "0.02", "size": "190.48"}, {"price": "0.03", "size": "18.99"}, {"price": "0.04", "size": "29.99"}], "asks": [{"price": "0.99", "size": "68.51"}, {"price": "0.98", "size": "179.03"}, {"price": "0.97", "size": "20.8"}, {"price": "0.96", "size": "5.47"}], "event_type": "book", "last_trade_price": ""}, {"market": "0x0e43c388a48dda26db3c52eb9813ea91188aea3b296595b6e4bbe4c21d8084b0", "asset_id": "102511604076257806476238809539017003625339720903982467852262014324396343577525", "timestamp": "1769383979108", "hash": "9eb69f416ab1f4cd1b4dbbcfc20ed4d13fc1c436", "bids": [{"price": "0.01", "size": "67.05"}, {"price": "0.02", "size": "182.48"}, {"price": "0.03", "size": "18.99"}, {"price": "0.04", "size": "5.47"}], "asks": [{"price": "0.99", "size": "62.05"}, {"price": "0.98", "size": "190.48"}, {"price": "0.97", "size": "18.99"}, {"price": "0.96", "size": "29.99"}], "event_type": "book", "last_trade_price": ""}, {"market": "0x83ecbe4fce688c64f4b5d4befac5e64922cb8682e0e1365fc0468ff533c71e49", "asset_id": "105434914828600935285428845047491083161332333045327551979231234346212907811414", "timestamp": "1769383842528", "hash": "e38aa7bce719a207202503c27a66aab2f7de6a15", "bids": [{"price": "0.01", "size": "162.05"}, {"price": "0.02", "size": "240.48"}, {"price": "0.03", "size": "18.99"}, {"price": "0.04", "size": "29.99"}], "asks": [{"price": "0.99", "size": "164.89"}, {"price": "0.98", "size": "232.78"}, {"price": "0.97", "size": "19.51"}, {"price": "0.96", "size": "5.47"}], "event_type": "book", "last_trade_price": ""}, {"market": "0x755a62c90339cdf3468fab177c6bfd9dceb5e45203e68bf069b50303a6abd25f", "asset_id": "78909895416168898474213741912660947562122027739865278774230819696266961515246", "timestamp": "1769383840241", "hash": "c6eb6d5f919807b0a6ec39606d5444c4cc32f1f4", "bids": [{"price": "0.01", "size": "69.11"}, {"price": "0.02", "size": "178.75"}, {"price": "0.03", "size": "20.79"}, {"price": "0.04", "size": "5.47"}], "asks": [{"price": "0.99", "size": "62.05"}, {"price": "0.98", "size": "190.48"}, {"price": "0.97", "size": "18.99"}, {"price": "0.96", "size": "29.99"}], "event_type": "book", "last_trade_price": ""}, {"market": "0x6a4478e27573f95e3440cbc34f7b2365f7cb10cfd0b4364ca5561b4e9aab4891", "asset_id": "96043889621651020187424767256997061290487486445860257445666515755879268438162", "timestamp": "1769383946693", "hash": "a726112f307e37fe14956df0555c9960bd20a6be", "bids": [{"price": "0.01", "size": "3755.05"}, {"price": "0.02", "size": "2250"}, {"price": "0.03", "size": "9.36"}, {"price": "0.05", "size": "1700"}, {"price": "0.09", "size": "700"}, {"price": "0.1", "size": "6.18"}, {"price": "0.14", "size": "200"}, {"price": "0.21", "size": "2000"}, {"price": "0.22", "size": "250"}, {"price": "0.26", "size": "300"}, {"price": "0.29", "size": "200"}, {"price": "0.31", "size": "125"}, {"price": "0.34", "size": "75"}, {"price": "0.35", "size": "10"}, {"price": "0.5", "size": "30"}, {"price": "0.63", "size": "311.44"}, {"price": "0.64", "size": "250"}, {"price": "0.69", "size": "137.56"}], "asks": [{"price": "0.99", "size": "940"}, {"price": "0.98", "size": "156.2"}, {"price": "0.97", "size": "75"}, {"price": "0.96", "size": "21.89"}, {"price": "0.9", "size": "300"}, {"price": "0.89", "size": "300"}, {"price": "0.88", "size": "125"}, {"price": "0.87", "size": "75"}, {"price": "0.8", "size": "194.78"}, {"price": "0.78", "size": "10"}, {"price": "0.75", "size": "10"}, {"price": "0.71", "size": "500"}, {"price": "0.7", "size": "50"}], "event_type": "book", "last_trade_price": "0.690"}, {"market": "0xc3e7877c4d9446b5c2ca915c4bf2b12b6165efcf74b881c5c37ae06a6f7f0b40", "asset_id": "8986929773922569337198837371098753707143429543105092459506437941673659406551", "timestamp": "1769382623700", "hash": "47daf056ea5d52ccee04238c04b847788769274e", "bids": [{"price": "0.01", "size": "1050.25"}, {"price": "0.02", "size": "150"}, {"price": "0.03", "size": "13.24"}, {"price": "0.05", "size": "10"}, {"price": "0.06", "size": "8.33"}, {"price": "0.56", "size": "5"}, {"price": "0.57", "size": "5"}, {"price": "0.59", "size": "290"}], "asks": [{"price": "0.99", "size": "45"}, {"price": "0.98", "size": "155.71"}, {"price": "0.97", "size": "81"}, {"price": "0.96", "size": "22.14"}, {"price": "0.6", "size": "6"}], "event_type": "book", "last_trade_price": ""}, {"market": "0xa2945f80a0c041b15c57a16539369873a31aae20c028d50efc9f4fe4c46f9973", "asset_id": "45622453771453949816894791094505340162140487852041488561027748414607473630122", "timestamp": "1769383840382", "hash": "9d8196719ccac6ba3eb483367901df834d0ef2d8", "bids": [{"price": "0.01", "size": "59.78"}, {"price": "0.02", "size": "179.03"}, {"price": "0.03", "size": "23.72"}, {"price": "0.04", "size": "5.47"}], "asks": [{"price": "0.99", "size": "62.05"}, {"price": "0.98", "size": "190.48"}, {"price": "0.97", "size": "18.99"}, {"price": "0.96", "size": "29.99"}], "event_type": "book", "last_trade_price": ""}, {"market": "0xa9e485d9ab8973f5683fc4992b591ab9997052b8d7acc5d800d197e95ba0f5ee", "asset_id": "42963846885724327117066696479449241735482257984315608228983457680056285716377", "timestamp": "1769383840382", "hash": "6a1f10f7ab387d0e727a2a8fbfe5cec0777feb6d", "bids": [{"price": "0.01", "size": "62.05"}, {"price": "0.02", "size": "190.48"}, {"price": "0.03", "size": "18.99"}, {"price": "0.04", "size": "38.98"}], "asks": [{"price": "0.99", "size": "59.79"}, {"price": "0.98", "size": "179.03"}, {"price": "0.97", "size": "23.71"}, {"price": "0.96", "size": "5.47"}], "event_type": "book", "last_trade_price": ""}, {"market": "0x83ecbe4fce688c64f4b5d4befac5e64922cb8682e0e1365fc0468ff533c71e49", "asset_id": "68037078242557231080288874617522547606466154419149083356555127918659292747130", "timestamp": "1769383842528", "hash": "e43d1df920cd1da853f14a28ca72b9ff8af4500c", "bids": [{"price": "0.01", "size": "164.89"}, {"price": "0.02", "size": "232.78"}, {"price": "0.03", "size": "19.51"}, {"price": "0.04", "size": "5.47"}], "asks": [{"price": "0.99", "size": "162.05"}, {"price": "0.98", "size": "240.48"}, {"price": "0.97", "size": "18.99"}, {"price": "0.96", "size": "29.99"}], "event_type": "book", "last_trade_price": ""}, {"market": "0x754ef6f17592b0ef700ddd256368d8a853e1b2608d801cbd10bb8867943feb51", "asset_id": "100119332257398155495950907520135487242937804051607670301581332334796358396713", "timestamp": "1769383843652", "hash": "5c9d502c0eb71325d1152f9395beadf935a08002", "bids": [{"price": "0.01", "size": "111.05"}, {"price": "0.02", "size": "214.48"}, {"price": "0.03", "size": "18.99"}, {"price": "0.04", "size": "29.99"}], "asks": [{"price": "0.99", "size": "106.67"}, {"price": "0.98", "size": "202.05"}, {"price": "0.97", "size": "25.74"}, {"price": "0.96", "size": "5.47"}], "event_type": "book", "last_trade_price": ""}, {"market": "0xa82369f8cd0613e9cb843d07e87c6b91b564c1265738b69e7053b75d8d194072", "asset_id": "46422279213299921123420170221742083018235225596393864746784180664594216048059", "timestamp": "1769383885943", "hash": "f6f55b50b88db36c4d675892a7452d64fe81f79d", "bids": [{"price": "0.01", "size": "112.04"}, {"price": "0.02", "size": "215.48"}, {"price": "0.03", "size": "18.99"}, {"price": "0.04", "size": "29.99"}], "asks": [{"price": "0.99", "size": "105.78"}, {"price": "0.98", "size": "203.94"}, {"price": "0.97", "size": "10.03"}, {"price": "0.94", "size": "11.51"}], "event_type": "book", "last_trade_price": ""}, {"market": "0x887d9af4bfb28d239e7ed0c69ff91d84ece92a11b58984d0ff0393c0c24a2d01", "asset_id": "91500912612677572060291806454710032668881503701184797906037737191617363298512", "timestamp": "1769383843652", "hash": "1d393ed569a5bb59062145a9a32641ba7ee8b80c", "bids": [{"price": "0.01", "size": "156.8"}, {"price": "0.02", "size": "227.67"}, {"price": "0.03", "size": "25.62"}, {"price": "0.04", "size": "5.47"}], "asks": [{"price": "0.99", "size": "162.05"}, {"price": "0.98", "size": "240.48"}, {"price": "0.97", "size": "18.99"}, {"price": "0.96", "size": "29.99"}], "event_type": "book", "last_trade_price": ""}, {"market": "0x754ef6f17592b0ef700ddd256368d8a853e1b2608d801cbd10bb8867943feb51", "asset_id": "58817089064209115360537822581951729680659415067098716481850517826996528126939", "timestamp": "1769383843652", "hash": "651385b26a17bf2d38e0c9d0b21e0c165347d238", "bids": [{"price": "0.01", "size": "106.67"}, {"price": "0.02", "size": "202.05"}, {"price": "0.03", "size": "25.74"}, {"price": "0.04", "size": "5.47"}], "asks": [{"price": "0.99", "size": "111.05"}, {"price": "0.98", "size": "214.48"}, {"price": "0.97", "size": "18.99"}, {"price": "0.96", "size": "29.99"}], "event_type": "book", "last_trade_price": ""}, {"market": "0x0e43c388a48dda26db3c52eb9813ea91188aea3b296595b6e4bbe4c21d8084b0", "asset_id": "34585893689836828365103711114049969648303333079217680891554537778358996709791", "timestamp": "1769383979108", "hash": "cdf1df86115a01b59ec2b00d9538938182d767da", "bids": [{"price": "0.01", "size": "62.05"}, {"price": "0.02", "size": "190.48"}, {"price": "0.03", "size": "18.99"}, {"price": "0.04", "size": "29.99"}], "asks": [{"price": "0.99", "size": "67.05"}, {"price": "0.98", "size": "182.48"}, {"price": "0.97", "size": "18.99"}, {"price": "0.96", "size": "5.47"}], "event_type": "book", "last_trade_price": ""}, {"market": "0x6a4478e27573f95e3440cbc34f7b2365f7cb10cfd0b4364ca5561b4e9aab4891", "asset_id": "55381454494707880049199570510897695915429248734443086753962741530042084242732", "timestamp": "1769383946693", "hash": "fff4eab6ba670f95a8adf2fecf7547eb6fe7d91e", "bids": [{"price": "0.01", "size": "940"}, {"price": "0.02", "size": "156.2"}, {"price": "0.03", "size": "75"}, {"price": "0.04", "size": "21.89"}, {"price": "0.1", "size": "300"}, {"price": "0.11", "size": "300"}, {"price": "0.12", "size": "125"}, {"price": "0.13", "size": "75"}, {"price": "0.2", "size": "194.78"}, {"price": "0.22", "size": "10"}, {"price": "0.25", "size": "10"}, {"price": "0.29", "size": "500"}, {"price": "0.3", "size": "50"}], "asks": [{"price": "0.99", "size": "3755.05"}, {"price": "0.98", "size": "2250"}, {"price": "0.97", "size": "9.36"}, {"price": "0.95", "size": "1700"}, {"price": "0.91", "size": "700"}, {"price": "0.9", "size": "6.18"}, {"price": "0.86", "size": "200"}, {"price": "0.79", "size": "2000"}, {"price": "0.78", "size": "250"}, {"price": "0.74", "size": "300"}, {"price": "0.71", "size": "200"}, {"price": "0.69", "size": "125"}, {"price": "0.66", "size": "75"}, {"price": "0.65", "size": "10"}, {"price": "0.5", "size": "30"}, {"price": "0.37", "size": "311.44"}, {"price": "0.36", "size": "250"}, {"price": "0.31", "size": "137.56"}], "event_type": "book", "last_trade_price": "0.690"}, {"market": "0xca130e51e4406596d098557a80d3fa6e95eb16d32ef09d08d20da8b7ab6d6298", "asset_id": "35965820443596672753502165079905474159071605177387618189868308759415426382973", "timestamp": "1769383843652", "hash": "1b327eb98cb4ff165d1c34983bb89fd6ecd82d7b", "bids": [{"price": "0.01", "size": "57.68"}, {"price": "0.02", "size": "177.05"}, {"price": "0.03", "size": "25.74"}, {"price": "0.04", "size": "5.47"}], "asks": [{"price": "0.99", "size": "62.05"}, {"price": "0.98", "size": "180.48"}, {"price": "0.97", "size": "18.99"}, {"price": "0.96", "size": "29.99"}], "event_type": "book", "last_trade_price": ""}]}
{"_local_timestamp": "2026-01-25T23:34:35.504060+00:00", "data": {"market": "0x83ecbe4fce688c64f4b5d4befac5e64922cb8682e0e1365fc0468ff533c71e49", "price_changes": [{"asset_id": "68037078242557231080288874617522547606466154419149083356555127918659292747130", "price": "0.05", "size": "23.99", "side": "BUY", "hash": "3324190134fe4657f0bd3c4b9816b5e5a0e4c0d4", "best_bid": "0.05", "best_ask": "0.96"}, {"asset_id": "105434914828600935285428845047491083161332333045327551979231234346212907811414", "price": "0.95", "size": "23.99", "side": "SELL", "hash": "ce55fa3f77eaddec54d4380e79fca99d4b2d1c5a", "best_bid": "0.04", "best_ask": "0.95"}], "timestamp": "1769384075257", "event_type": "price_change"}}
{"_local_timestamp": "2026-01-25T23:34:35.507468+00:00", "data": {"market": "0xca130e51e4406596d098557a80d3fa6e95eb16d32ef09d08d20da8b7ab6d6298", "price_changes": [{"asset_id": "35965820443596672753502165079905474159071605177387618189868308759415426382973", "price": "0.05", "size": "23.99", "side": "BUY", "hash": "61d9891b3d703d7485081582aadd62ea5287edb4", "best_bid": "0.05", "best_ask": "0.96"}, {"asset_id": "9877937220298673394222737478141754783632484432479493143738647510821851680044", "price": "0.95", "size": "23.99", "side": "SELL", "hash": "18e45c33cd4a8694db6411006e6c0a5158baca95", "best_bid": "0.04", "best_ask": "0.95"}], "timestamp": "1769384075257", "event_type": "price_change"}}
{"_local_timestamp": "2026-01-25T23:34:35.509308+00:00", "data": {"market": "0x887d9af4bfb28d239e7ed0c69ff91d84ece92a11b58984d0ff0393c0c24a2d01", "price_changes": [{"asset_id": "91500912612677572060291806454710032668881503701184797906037737191617363298512", "price": "0.05", "size": "23.99", "side": "BUY", "hash": "1b2f5d7ae38937d1b70bb2c4610d396057958c08", "best_bid": "0.05", "best_ask": "0.96"}, {"asset_id": "53797474885844189083818567441605903163912505725772675434705257100199647449827", "price": "0.95", "size": "23.99", "side": "SELL", "hash": "8f878a4ad388bb30f6d9c654acea918b06fd29e6", "best_bid": "0.04", "best_ask": "0.95"}], "timestamp": "1769384075257", "event_type": "price_change"}}
{"_local_timestamp": "2026-01-25T23:34:35.617838+00:00", "data": {"market": "0x755a62c90339cdf3468fab177c6bfd9dceb5e45203e68bf069b50303a6abd25f", "price_changes": [{"asset_id": "78909895416168898474213741912660947562122027739865278774230819696266961515246", "price": "0.05", "size": "23.99", "side": "BUY", "hash": "a799725b796e200eeb1fc3ce6a7a626d679e2f07", "best_bid": "0.05", "best_ask": "0.96"}, {"asset_id": "84460776671731186445015851207745064196399530432412893483409324414283960172444", "price": "0.95", "size": "23.99", "side": "SELL", "hash": "dfd5e37c03e9daccdcb27e069944b0c3d33a6bcc", "best_bid": "0.04", "best_ask": "0.95"}], "timestamp": "1769384075380", "event_type": "price_change"}}
{"_local_timestamp": "2026-01-25T23:34:35.618319+00:00", "data": {"market": "0x754ef6f17592b0ef700ddd256368d8a853e1b2608d801cbd10bb8867943feb51", "price_changes": [{"asset_id": "58817089064209115360537822581951729680659415067098716481850517826996528126939", "price": "0.05", "size": "23.99", "side": "BUY", "hash": "82caa4230170146bca2c5471935b788b735b8b75", "best_bid": "0.05", "best_ask": "0.96"}, {"asset_id": "100119332257398155495950907520135487242937804051607670301581332334796358396713", "price": "0.95", "size": "23.99", "side": "SELL", "hash": "f05a6c612e8e741d6e43de55da087b67bc9ccfb9", "best_bid": "0.04", "best_ask": "0.95"}], "timestamp": "1769384075380", "event_type": "price_change"}}
{"_local_timestamp": "2026-01-25T23:34:35.619019+00:00", "data": {"market": "0x0c35017fce45618791b247a0e015a99dfdaa11fce35665f46a21329c75539bf5", "price_changes": [{"asset_id": "91719725116883012291565512161477775996897243486374553084185529876278409496454", "price": "0.05", "size": "23.99", "side": "BUY", "hash": "080a8564b9ad3dc93785807a6e0c57219327fe91", "best_bid": "0.05", "best_ask": "0.96"}, {"asset_id": "113869036122116896359974222126121258669445902300788141703831662654178658580719", "price": "0.95", "size": "23.99", "side": "SELL", "hash": "b803c22d9d9e9004b0b2e72c0066d8d0b656fcf4", "best_bid": "0.04", "best_ask": "0.95"}], "timestamp": "1769384075380", "event_type": "price_change"}}
{"_local_timestamp": "2026-01-25T23:34:35.625316+00:00", "data": {"market": "0xa9e485d9ab8973f5683fc4992b591ab9997052b8d7acc5d800d197e95ba0f5ee", "price_changes": [{"asset_id": "52957896528748198044120161866858084167956853408096664478472083379802465908152", "price": "0.05", "size": "23.99", "side": "BUY", "hash": "9d4c79e16bdd757322f37281b223dedc1f4251b1", "best_bid": "0.05", "best_ask": "0.96"}, {"asset_id": "42963846885724327117066696479449241735482257984315608228983457680056285716377", "price": "0.95", "size": "23.99", "side": "SELL", "hash": "287d23e82deba7b7130399dd0b3783c77843b87b", "best_bid": "0.04", "best_ask": "0.95"}], "timestamp": "1769384075380", "event_type": "price_change"}}
{"_local_timestamp": "2026-01-25T23:34:35.713231+00:00", "data": {"market": "0xa2945f80a0c041b15c57a16539369873a31aae20c028d50efc9f4fe4c46f9973", "price_changes": [{"asset_id": "45622453771453949816894791094505340162140487852041488561027748414607473630122", "price": "0.05", "size": "23.99", "side": "BUY", "hash": "dcf2b65ad72f1d58970b4452345cfa507affef6f", "best_bid": "0.05", "best_ask": "0.96"}, {"asset_id": "36376479227210509138719694118857362983085092412966657890412021289097812996653", "price": "0.95", "size": "23.99", "side": "SELL", "hash": "deede40767284bd49b9809d694359007dd77342a", "best_bid": "0.04", "best_ask": "0.95"}], "timestamp": "1769384075478", "event_type": "price_change"}}
{"_local_timestamp": "2026-01-25T23:34:38.994952+00:00", "data": {"market": "0x887d9af4bfb28d239e7ed0c69ff91d84ece92a11b58984d0ff0393c0c24a2d01", "price_changes": [{"asset_id": "91500912612677572060291806454710032668881503701184797906037737191617363298512", "price": "0.04", "size": "0", "side": "BUY", "hash": "80932222ed32d03becd09c1f82b886fda7da6e54", "best_bid": "0.05", "best_ask": "0.96"}, {"asset_id": "53797474885844189083818567441605903163912505725772675434705257100199647449827", "price": "0.96", "size": "0", "side": "SELL", "hash": "c7ac4d9fe60f763dcd94bd9e53996cf010caf628", "best_bid": "0.04", "best_ask": "0.95"}], "timestamp": "1769384078926", "event_type": "price_change"}}
{"_local_timestamp": "2026-01-25T23:34:39.005612+00:00", "data": {"market": "0x755a62c90339cdf3468fab177c6bfd9dceb5e45203e68bf069b50303a6abd25f", "price_changes": [{"asset_id": "78909895416168898474213741912660947562122027739865278774230819696266961515246", "price": "0.04", "size": "0", "side": "BUY", "hash": "6bb068d3ee8c7463e3468d93bfd16384774942a0", "best_bid": "0.05", "best_ask": "0.96"}, {"asset_id": "84460776671731186445015851207745064196399530432412893483409324414283960172444", "price": "0.96", "size": "0", "side": "SELL", "hash": "42e59f6708ce4719dfa06b7ba3054a4f5efc6c4d", "best_bid": "0.04", "best_ask": "0.95"}], "timestamp": "1769384078927", "event_type": "price_change"}}
{"_local_timestamp": "2026-01-25T23:34:39.009226+00:00", "data": {"market": "0xa2945f80a0c041b15c57a16539369873a31aae20c028d50efc9f4fe4c46f9973", "price_changes": [{"asset_id": "45622453771453949816894791094505340162140487852041488561027748414607473630122", "price": "0.04", "size": "0", "side": "BUY", "hash": "a4a571eaee30d0868e4904ed6ad8f3e57d0509cf", "best_bid": "0.05", "best_ask": "0.96"}, {"asset_id": "36376479227210509138719694118857362983085092412966657890412021289097812996653", "price": "0.96", "size": "0", "side": "SELL", "hash": "b82fb20f042dd93210bca8a2e1b4c794fec7cc5c", "best_bid": "0.04", "best_ask": "0.95"}], "timestamp": "1769384078927", "event_type": "price_change"}}
{"_local_timestamp": "2026-01-25T23:34:39.009744+00:00", "data": {"market": "0xca130e51e4406596d098557a80d3fa6e95eb16d32ef09d08d20da8b7ab6d6298", "price_changes": [{"asset_id": "35965820443596672753502165079905474159071605177387618189868308759415426382973", "price": "0.04", "size": "0", "side": "BUY", "hash": "d3049ff9060c1e75a8d5606db98f65292fe1d47a", "best_bid": "0.05", "best_ask": "0.96"}, {"asset_id": "9877937220298673394222737478141754783632484432479493143738647510821851680044", "price": "0.96", "size": "0", "side": "SELL", "hash": "715d128429de30629f735f68958406ca58b953ea", "best_bid": "0.04", "best_ask": "0.95"}], "timestamp": "1769384078926", "event_type": "price_change"}}
{"_local_timestamp": "2026-01-25T23:34:39.010222+00:00", "data": {"market": "0xa9e485d9ab8973f5683fc4992b591ab9997052b8d7acc5d800d197e95ba0f5ee", "price_changes": [{"asset_id": "52957896528748198044120161866858084167956853408096664478472083379802465908152", "price": "0.04", "size": "0", "side": "BUY", "hash": "6fa1db53e7996c28df058052d49b1bc760b006e7", "best_bid": "0.05", "best_ask": "0.96"}, {"asset_id": "42963846885724327117066696479449241735482257984315608228983457680056285716377", "price": "0.96", "size": "0", "side": "SELL", "hash": "ac1cf2801a4e5baf396a7611f0629685912678f2", "best_bid": "0.04", "best_ask": "0.95"}], "timestamp": "1769384078927", "event_type": "price_change"}}
{"_local_timestamp": "2026-01-25T23:34:39.011525+00:00", "data": {"market": "0x754ef6f17592b0ef700ddd256368d8a853e1b2608d801cbd10bb8867943feb51", "price_changes": [{"asset_id": "58817089064209115360537822581951729680659415067098716481850517826996528126939", "price": "0.04", "size": "0", "side": "BUY", "hash": "a757e30c6a93667fd5493e83227e8d9a1be71818", "best_bid": "0.05", "best_ask": "0.96"}, {"asset_id": "100119332257398155495950907520135487242937804051607670301581332334796358396713", "price": "0.96", "size": "0", "side": "SELL", "hash": "cc7b982702e51fda1c8d5d27b0b0e7378fef54f5", "best_bid": "0.04", "best_ask": "0.95"}], "timestamp": "1769384078926", "event_type": "price_change"}}
{"_local_timestamp": "2026-01-25T23:34:39.019623+00:00", "data": {"market": "0x83ecbe4fce688c64f4b5d4befac5e64922cb8682e0e1365fc0468ff533c71e49", "price_changes": [{"asset_id": "68037078242557231080288874617522547606466154419149083356555127918659292747130", "price": "0.04", "size": "0", "side": "BUY", "hash": "20634f1e94e60e827fd45fbac815163c6009d5fa", "best_bid": "0.05", "best_ask": "0.96"}, {"asset_id": "105434914828600935285428845047491083161332333045327551979231234346212907811414", "price": "0.96", "size": "0", "side": "SELL", "hash": "49881c8e3bcb4f1b87d190124ee29bea2a1a5dce", "best_bid": "0.04", "best_ask": "0.95"}], "timestamp": "1769384078927", "event_type": "price_change"}}
{"_local_timestamp": "2026-01-25T23:34:39.027088+00:00", "data": {"market": "0x0c35017fce45618791b247a0e015a99dfdaa11fce35665f46a21329c75539bf5", "price_changes": [{"asset_id": "91719725116883012291565512161477775996897243486374553084185529876278409496454", "price": "0.04", "size": "0", "side": "BUY", "hash": "425ece3c4b69445f9a92d03101913b3651882859", "best_bid": "0.05", "best_ask": "0.96"}, {"asset_id": "113869036122116896359974222126121258669445902300788141703831662654178658580719", "price": "0.96", "size": "0", "side": "SELL", "hash": "31ab5b2f65da425acda77b03966dbbe9ad8e7359", "best_bid": "0.04", "best_ask": "0.95"}], "timestamp": "1769384078926", "event_type": "price_change"}}
{"_local_timestamp": "2026-01-25T23:34:39.267452+00:00", "data": {"market": "0x754ef6f17592b0ef700ddd256368d8a853e1b2608d801cbd10bb8867943feb51", "price_changes": [{"asset_id": "58817089064209115360537822581951729680659415067098716481850517826996528126939", "price": "0.06", "size": "5.47", "side": "BUY", "hash": "898f70fbe3f5fef8a38727e61bc5dcc072996118", "best_bid": "0.06", "best_ask": "0.96"}, {"asset_id": "100119332257398155495950907520135487242937804051607670301581332334796358396713", "price": "0.94", "size": "5.47", "side": "SELL", "hash": "4eb0de24bebda706a92550745eb780c9a0f02fa3", "best_bid": "0.04", "best_ask": "0.94"}], "timestamp": "1769384079158", "event_type": "price_change"}}
{"_local_timestamp": "2026-01-25T23:34:39.271692+00:00", "data": {"market": "0x0c35017fce45618791b247a0e015a99dfdaa11fce35665f46a21329c75539bf5", "price_changes": [{"asset_id": "91719725116883012291565512161477775996897243486374553084185529876278409496454", "price": "0.06", "size": "5.47", "side": "BUY", "hash": "daa6ee4f4a9d82016e3946e36efcd4701240ddc1", "best_bid": "0.06", "best_ask": "0.96"}, {"asset_id": "113869036122116896359974222126121258669445902300788141703831662654178658580719", "price": "0.94", "size": "5.47", "side": "SELL", "hash": "27528fdb3a53a4b603a1aeb4491f6698fa2420b8", "best_bid": "0.04", "best_ask": "0.94"}], "timestamp": "1769384079158", "event_type": "price_change"}}
{"_local_timestamp": "2026-01-25T23:34:39.272106+00:00", "data": {"market": "0xca130e51e4406596d098557a80d3fa6e95eb16d32ef09d08d20da8b7ab6d6298", "price_changes": [{"asset_id": "35965820443596672753502165079905474159071605177387618189868308759415426382973", "price": "0.06", "size": "5.47", "side": "BUY", "hash": "351fd429dc0e91ef74130f3a56dc7bee37f13157", "best_bid": "0.06", "best_ask": "0.96"}, {"asset_id": "9877937220298673394222737478141754783632484432479493143738647510821851680044", "price": "0.94", "size": "5.47", "side": "SELL", "hash": "94bd427974cfff0ad9dfcab29587e7064d788115", "best_bid": "0.04", "best_ask": "0.94"}], "timestamp": "1769384079158", "event_type": "price_change"}}
{"_local_timestamp": "2026-01-25T23:34:39.272425+00:00", "data": {"market": "0xa2945f80a0c041b15c57a16539369873a31aae20c028d50efc9f4fe4c46f9973", "price_changes": [{"asset_id": "45622453771453949816894791094505340162140487852041488561027748414607473630122", "price": "0.06", "size": "5.47", "side": "BUY", "hash": "4c2cab4cbe5f27df3bab786f06679245475b5d4d", "best_bid": "0.06", "best_ask": "0.96"}, {"asset_id": "36376479227210509138719694118857362983085092412966657890412021289097812996653", "price": "0.94", "size": "5.47", "side": "SELL", "hash": "1be1cdbb1279bad5e4b1d12cf98cde337f10dd9b", "best_bid": "0.04", "best_ask": "0.94"}], "timestamp": "1769384079158", "event_type": "price_change"}}
{"_local_timestamp": "2026-01-25T23:34:39.272723+00:00", "data": {"market": "0xa9e485d9ab8973f5683fc4992b591ab9997052b8d7acc5d800d197e95ba0f5ee", "price_changes": [{"asset_id": "52957896528748198044120161866858084167956853408096664478472083379802465908152", "price": "0.06", "size": "5.47", "side": "BUY", "hash": "c85ebf8431628adeb6367b7c8efa58848d19aa1b", "best_bid": "0.06", "best_ask": "0.96"}, {"asset_id": "42963846885724327117066696479449241735482257984315608228983457680056285716377", "price": "0.94", "size": "5.47", "side": "SELL", "hash": "9e3d67b4a4f514c510e64ef26cc1d91835c9e3fa", "best_bid": "0.04", "best_ask": "0.94"}], "timestamp": "1769384079158", "event_type": "price_change"}}
{"_local_timestamp": "2026-01-25T23:34:39.273345+00:00", "data": {"market": "0x83ecbe4fce688c64f4b5d4befac5e64922cb8682e0e1365fc0468ff533c71e49", "price_changes": [{"asset_id": "68037078242557231080288874617522547606466154419149083356555127918659292747130", "price": "0.06", "size": "5.47", "side": "BUY", "hash": "145ae5db5f9846d6f020a8a3f9e3efac940f8d6a", "best_bid": "0.06", "best_ask": "0.96"}, {"asset_id": "105434914828600935285428845047491083161332333045327551979231234346212907811414", "price": "0.94", "size": "5.47", "side": "SELL", "hash": "7e141bea3d520bf4d2c47c1aedf019acf912d74d", "best_bid": "0.04", "best_ask": "0.94"}], "timestamp": "1769384079158", "event_type": "price_change"}}
{"_local_timestamp": "2026-01-25T23:34:39.273659+00:00", "data": {"market": "0x755a62c90339cdf3468fab177c6bfd9dceb5e45203e68bf069b50303a6abd25f", "price_changes": [{"asset_id": "78909895416168898474213741912660947562122027739865278774230819696266961515246", "price": "0.06", "size": "5.47", "side": "BUY", "hash": "2469a7b4ec8383866b2ee5d505d49abb0c5764d0", "best_bid": "0.06", "best_ask": "0.96"}, {"asset_id": "84460776671731186445015851207745064196399530432412893483409324414283960172444", "price": "0.94", "size": "5.47", "side": "SELL", "hash": "a1a55476d85689605b5bb994aa2c9b58314e01a5", "best_bid": "0.04", "best_ask": "0.94"}], "timestamp": "1769384079158", "event_type": "price_change"}}
{"_local_timestamp": "2026-01-25T23:34:39.273969+00:00", "data": {"market": "0x887d9af4bfb28d239e7ed0c69ff91d84ece92a11b58984d0ff0393c0c24a2d01", "price_changes": [{"asset_id": "91500912612677572060291806454710032668881503701184797906037737191617363298512", "price": "0.06", "size": "5.47", "side": "BUY", "hash": "3f937a8528a3c1f4ea9d8a7f4fd1b347813a4205", "best_bid": "0.06", "best_ask": "0.96"}, {"asset_id": "53797474885844189083818567441605903163912505725772675434705257100199647449827", "price": "0.94", "size": "5.47", "side": "SELL", "hash": "320aba4d18008685e7dcc2ea14b9aab04439c5ab", "best_bid": "0.04", "best_ask": "0.94"}], "timestamp": "1769384079158", "event_type": "price_change"}}
{"_local_timestamp": "2026-01-25T23:36:04.341629+00:00", "data": {"market": "0xa9e485d9ab8973f5683fc4992b591ab9997052b8d7acc5d800d197e95ba0f5ee", "price_changes": [{"asset_id": "52957896528748198044120161866858084167956853408096664478472083379802465908152", "price": "0.05", "size": "0", "side": "BUY", "hash": "ef9fb1d8971c46b6258380b4835433cb7acb0325", "best_bid": "0.06", "best_ask": "0.96"}, {"asset_id": "42963846885724327117066696479449241735482257984315608228983457680056285716377", "price": "0.95", "size": "0", "side": "SELL", "hash": "4c74e7b4d84b1d7053670ca4171dec77e389a1f9", "best_bid": "0.04", "best_ask": "0.94"}], "timestamp": "1769384164266", "event_type": "price_change"}}
{"_local_timestamp": "2026-01-25T23:36:04.342713+00:00", "data": {"market": "0xca130e51e4406596d098557a80d3fa6e95eb16d32ef09d08d20da8b7ab6d6298", "price_changes": [{"asset_id": "35965820443596672753502165079905474159071605177387618189868308759415426382973", "price": "0.05", "size": "0", "side": "BUY", "hash": "77ca447ea49c20452012a29aa71694308d121f23", "best_bid": "0.06", "best_ask": "0.96"}, {"asset_id": "9877937220298673394222737478141754783632484432479493143738647510821851680044", "price": "0.95", "size": "0", "side": "SELL", "hash": "59754777a05c239b28060c88b686addab145694e", "best_bid": "0.04", "best_ask": "0.94"}], "timestamp": "1769384164266", "event_type": "price_change"}}
{"_local_timestamp": "2026-01-25T23:36:04.446472+00:00", "data": {"market": "0x83ecbe4fce688c64f4b5d4befac5e64922cb8682e0e1365fc0468ff533c71e49", "price_changes": [{"asset_id": "68037078242557231080288874617522547606466154419149083356555127918659292747130", "price": "0.05", "size": "0", "side": "BUY", "hash": "b91f18df6ecfaf2de34f935291db98db3a18fbf3", "best_bid": "0.06", "best_ask": "0.96"}, {"asset_id": "105434914828600935285428845047491083161332333045327551979231234346212907811414", "price": "0.95", "size": "0", "side": "SELL", "hash": "f49063e28a91739cee4ec6b715354e965e650e8c", "best_bid": "0.04", "best_ask": "0.94"}], "timestamp": "1769384164366", "event_type": "price_change"}}
{"_local_timestamp": "2026-01-25T23:36:04.447016+00:00", "data": {"market": "0x755a62c90339cdf3468fab177c6bfd9dceb5e45203e68bf069b50303a6abd25f", "price_changes": [{"asset_id": "78909895416168898474213741912660947562122027739865278774230819696266961515246", "price": "0.05", "size": "0", "side": "BUY", "hash": "4b1da79e15211258186c526c0cbff36f92c21818", "best_bid": "0.06", "best_ask": "0.96"}, {"asset_id": "84460776671731186445015851207745064196399530432412893483409324414283960172444", "price": "0.95", "size": "0", "side": "SELL", "hash": "d69fd1efdb5dc22daea879b23a44879f3f7fe116", "best_bid": "0.04", "best_ask": "0.94"}], "timestamp": "1769384164366", "event_type": "price_change"}}
{"_local_timestamp": "2026-01-25T23:36:04.447346+00:00", "data": {"market": "0x0c35017fce45618791b247a0e015a99dfdaa11fce35665f46a21329c75539bf5", "price_changes": [{"asset_id": "91719725116883012291565512161477775996897243486374553084185529876278409496454", "price": "0.05", "size": "0", "side": "BUY", "hash": "416d7acf6f0bc6c465d41cb8684bdab39c1a2f18", "best_bid": "0.06", "best_ask": "0.96"}, {"asset_id": "113869036122116896359974222126121258669445902300788141703831662654178658580719", "price": "0.95", "size": "0", "side": "SELL", "hash": "71b013a5daa2a74795029fd13bf377815fbaf2f6", "best_bid": "0.04", "best_ask": "0.94"}], "timestamp": "1769384164366", "event_type": "price_change"}}
{"_local_timestamp": "2026-01-25T23:36:04.447659+00:00", "data": {"market": "0x754ef6f17592b0ef700ddd256368d8a853e1b2608d801cbd10bb8867943feb51", "price_changes": [{"asset_id": "58817089064209115360537822581951729680659415067098716481850517826996528126939", "price": "0.05", "size": "0", "side": "BUY", "hash": "dda2a7ca7277bf34581bb81c81e31770fd96d611", "best_bid": "0.06", "best_ask": "0.96"}, {"asset_id": "100119332257398155495950907520135487242937804051607670301581332334796358396713", "price": "0.95", "size": "0", "side": "SELL", "hash": "628219f96102a11f48357e7448952cda1eaa2bd0", "best_bid": "0.04", "best_ask": "0.94"}], "timestamp": "1769384164366", "event_type": "price_change"}}
{"_local_timestamp": "2026-01-25T23:36:04.448565+00:00", "data": {"market": "0xa2945f80a0c041b15c57a16539369873a31aae20c028d50efc9f4fe4c46f9973", "price_changes": [{"asset_id": "45622453771453949816894791094505340162140487852041488561027748414607473630122", "price": "0.05", "size": "0", "side": "BUY", "hash": "0e1181acdb9bc9e59ec13da1adec2c9a63f74b30", "best_bid": "0.06", "best_ask": "0.96"}, {"asset_id": "36376479227210509138719694118857362983085092412966657890412021289097812996653", "price": "0.95", "size": "0", "side": "SELL", "hash": "0654f2ef6b1ad6a0e24a9545908ec000a90dc35e", "best_bid": "0.04", "best_ask": "0.94"}], "timestamp": "1769384164366", "event_type": "price_change"}}
{"_local_timestamp": "2026-01-25T23:36:04.448922+00:00", "data": {"market": "0x887d9af4bfb28d239e7ed0c69ff91d84ece92a11b58984d0ff0393c0c24a2d01", "price_changes": [{"asset_id": "91500912612677572060291806454710032668881503701184797906037737191617363298512", "price": "0.05", "size": "0", "side": "BUY", "hash": "68c02b484c25c1f2a7b0622837e72423b5cce6aa", "best_bid": "0.06", "best_ask": "0.96"}, {"asset_id": "53797474885844189083818567441605903163912505725772675434705257100199647449827", "price": "0.95", "size": "0", "side": "SELL", "hash": "8ee25a1e1959f25bd111c08d015a00c4aab928b5", "best_bid": "0.04", "best_ask": "0.94"}], "timestamp": "1769384164366", "event_type": "price_change"}}
{"_local_timestamp": "2026-01-25T23:36:09.190733+00:00", "data": {"market": "0x755a62c90339cdf3468fab177c6bfd9dceb5e45203e68bf069b50303a6abd25f", "price_changes": [{"asset_id": "78909895416168898474213741912660947562122027739865278774230819696266961515246", "price": "0.06", "size": "0", "side": "BUY", "hash": "77af98edc22a76712eb76d0a0e7f767adbfe3d03", "best_bid": "0.03", "best_ask": "0.96"}, {"asset_id": "84460776671731186445015851207745064196399530432412893483409324414283960172444", "price": "0.94", "size": "0", "side": "SELL", "hash": "764d9079a02dc31cf064333e464483019ccef61d", "best_bid": "0.04", "best_ask": "0.97"}], "timestamp": "1769384169122", "event_type": "price_change"}}
{"_local_timestamp": "2026-01-25T23:36:09.198578+00:00", "data": {"market": "0xa2945f80a0c041b15c57a16539369873a31aae20c028d50efc9f4fe4c46f9973", "price_changes": [{"asset_id": "45622453771453949816894791094505340162140487852041488561027748414607473630122", "price": "0.06", "size": "0", "side": "BUY", "hash": "259bcf0bc02a02bbdae4d80cd5d57fe211a158d5", "best_bid": "0.03", "best_ask": "0.96"}, {"asset_id": "36376479227210509138719694118857362983085092412966657890412021289097812996653", "price": "0.94", "size": "0", "side": "SELL", "hash": "e20019adbe1dec61a7c7a925ff844d210df2363e", "best_bid": "0.04", "best_ask": "0.97"}], "timestamp": "1769384169122", "event_type": "price_change"}}
{"_local_timestamp": "2026-01-25T23:36:09.199310+00:00", "data": {"market": "0x887d9af4bfb28d239e7ed0c69ff91d84ece92a11b58984d0ff0393c0c24a2d01", "price_changes": [{"asset_id": "91500912612677572060291806454710032668881503701184797906037737191617363298512", "price": "0.06", "size": "0", "side": "BUY", "hash": "ffd66343958bea17804b03a8606e185cfe634152", "best_bid": "0.03", "best_ask": "0.96"}, {"asset_id": "53797474885844189083818567441605903163912505725772675434705257100199647449827", "price": "0.94", "size": "0", "side": "SELL", "hash": "5393014bc05e307c183332cc976ad8a590e6f125", "best_bid": "0.04", "best_ask": "0.97"}], "timestamp": "1769384169122", "event_type": "price_change"}}
{"_local_timestamp": "2026-01-25T23:36:09.199696+00:00", "data": {"market": "0x0c35017fce45618791b247a0e015a99dfdaa11fce35665f46a21329c75539bf5", "price_changes": [{"asset_id": "91719725116883012291565512161477775996897243486374553084185529876278409496454", "price": "0.06", "size": "0", "side": "BUY", "hash": "d983262a69c802aac2dff90c6cc20bba62b591d5", "best_bid": "0.03", "best_ask": "0.96"}, {"asset_id": "113869036122116896359974222126121258669445902300788141703831662654178658580719", "price": "0.94", "size": "0", "side": "SELL", "hash": "88850fad7adbb89e23f40fad6154d9576b2c036b", "best_bid": "0.04", "best_ask": "0.97"}], "timestamp": "1769384169123", "event_type": "price_change"}}
{"_local_timestamp": "2026-01-25T23:36:09.207161+00:00", "data": {"market": "0xa9e485d9ab8973f5683fc4992b591ab9997052b8d7acc5d800d197e95ba0f5ee", "price_changes": [{"asset_id": "52957896528748198044120161866858084167956853408096664478472083379802465908152", "price": "0.06", "size": "0", "side": "BUY", "hash": "3d40686e22543d978d926392ee1543af4542e85c", "best_bid": "0.03", "best_ask": "0.96"}, {"asset_id": "42963846885724327117066696479449241735482257984315608228983457680056285716377", "price": "0.94", "size": "0", "side": "SELL", "hash": "24cef3f0188e5e76b52e45585ca4319e6421044d", "best_bid": "0.04", "best_ask": "0.97"}], "timestamp": "1769384169123", "event_type": "price_change"}}
{"_local_timestamp": "2026-01-25T23:36:09.208145+00:00", "data": {"market": "0x754ef6f17592b0ef700ddd256368d8a853e1b2608d801cbd10bb8867943feb51", "price_changes": [{"asset_id": "58817089064209115360537822581951729680659415067098716481850517826996528126939", "price": "0.06", "size": "0", "side": "BUY", "hash": "d46f7f7db401e585b4045ec2a012da3a7807cacb", "best_bid": "0.03", "best_ask": "0.96"}, {"asset_id": "100119332257398155495950907520135487242937804051607670301581332334796358396713", "price": "0.94", "size": "0", "side": "SELL", "hash": "e1110ac66daca4b510e87c8a08c76f47c4daf070", "best_bid": "0.04", "best_ask": "0.97"}], "timestamp": "1769384169123", "event_type": "price_change"}}
{"_local_timestamp": "2026-01-25T23:36:09.208560+00:00", "data": {"market": "0xca130e51e4406596d098557a80d3fa6e95eb16d32ef09d08d20da8b7ab6d6298", "price_changes": [{"asset_id": "35965820443596672753502165079905474159071605177387618189868308759415426382973", "price": "0.06", "size": "0", "side": "BUY", "hash": "822fa14d888cd4f37bd4c388b2e72a4eee1160ac", "best_bid": "0.03", "best_ask": "0.96"}, {"asset_id": "9877937220298673394222737478141754783632484432479493143738647510821851680044", "price": "0.94", "size": "0", "side": "SELL", "hash": "f137496e13b4b6436dc948d44d2b6043dcafd858", "best_bid": "0.04", "best_ask": "0.97"}], "timestamp": "1769384169123", "event_type": "price_change"}}
{"_local_timestamp": "2026-01-25T23:36:09.208928+00:00", "data": {"market": "0x83ecbe4fce688c64f4b5d4befac5e64922cb8682e0e1365fc0468ff533c71e49", "price_changes": [{"asset_id": "68037078242557231080288874617522547606466154419149083356555127918659292747130", "price": "0.06", "size": "0", "side": "BUY", "hash": "669b7eeccd490daf6570968f99c7c9b80003696b", "best_bid": "0.03", "best_ask": "0.96"}, {"asset_id": "105434914828600935285428845047491083161332333045327551979231234346212907811414", "price": "0.94", "size": "0", "side": "SELL", "hash": "7d1459da7afb825f823a448b323d21671c185981", "best_bid": "0.04", "best_ask": "0.97"}], "timestamp": "1769384169123", "event_type": "price_change"}}
{"_local_timestamp": "2026-01-25T23:36:09.402123+00:00", "data": {"market": "0x754ef6f17592b0ef700ddd256368d8a853e1b2608d801cbd10bb8867943feb51", "price_changes": [{"asset_id": "58817089064209115360537822581951729680659415067098716481850517826996528126939", "price": "0.04", "size": "5.47", "side": "BUY", "hash": "ab6aaa4e6b900f0a989d83c1e09fcd5788112d04", "best_bid": "0.04", "best_ask": "0.96"}, {"asset_id": "100119332257398155495950907520135487242937804051607670301581332334796358396713", "price": "0.96", "size": "5.47", "side": "SELL", "hash": "aae62976b721ba9f74786b644a796497d958808b", "best_bid": "0.04", "best_ask": "0.96"}], "timestamp": "1769384169334", "event_type": "price_change"}}
{"_local_timestamp": "2026-01-25T23:36:09.402847+00:00", "data": {"market": "0x0c35017fce45618791b247a0e015a99dfdaa11fce35665f46a21329c75539bf5", "price_changes": [{"asset_id": "91719725116883012291565512161477775996897243486374553084185529876278409496454", "price": "0.04", "size": "5.47", "side": "BUY", "hash": "ae44f679ab3d8742cc3a3d21bfe49f6b6cfd09eb", "best_bid": "0.04", "best_ask": "0.96"}, {"asset_id": "113869036122116896359974222126121258669445902300788141703831662654178658580719", "price": "0.96", "size": "5.47", "side": "SELL", "hash": "fe26b9c6de79a8fe9ba25a4097485615d5a83c63", "best_bid": "0.04", "best_ask": "0.96"}], "timestamp": "1769384169334", "event_type": "price_change"}}
{"_local_timestamp": "2026-01-25T23:36:09.403600+00:00", "data": {"market": "0xca130e51e4406596d098557a80d3fa6e95eb16d32ef09d08d20da8b7ab6d6298", "price_changes": [{"asset_id": "35965820443596672753502165079905474159071605177387618189868308759415426382973", "price": "0.04", "size": "5.47", "side": "BUY", "hash": "429265c94ef4a9d96cf9738c61a3bfdc659b8742", "best_bid": "0.04", "best_ask": "0.96"}, {"asset_id": "9877937220298673394222737478141754783632484432479493143738647510821851680044", "price": "0.96", "size": "5.47", "side": "SELL", "hash": "275913bb679b63f4ea585bae65f4aefc88940e96", "best_bid": "0.04", "best_ask": "0.96"}], "timestamp": "1769384169334", "event_type": "price_change"}}
{"_local_timestamp": "2026-01-25T23:36:09.404041+00:00", "data": {"market": "0xa9e485d9ab8973f5683fc4992b591ab9997052b8d7acc5d800d197e95ba0f5ee", "price_changes": [{"asset_id": "52957896528748198044120161866858084167956853408096664478472083379802465908152", "price": "0.04", "size": "5.47", "side": "BUY", "hash": "1e092ab2c57121a14933e339c33b3bc1a7490ddf", "best_bid": "0.04", "best_ask": "0.96"}, {"asset_id": "42963846885724327117066696479449241735482257984315608228983457680056285716377", "price": "0.96", "size": "5.47", "side": "SELL", "hash": "def887d182d49ad919ee415c68543f9ef086273a", "best_bid": "0.04", "best_ask": "0.96"}], "timestamp": "1769384169334", "event_type": "price_change"}}
{"_local_timestamp": "2026-01-25T23:36:09.404473+00:00", "data": {"market": "0xa2945f80a0c041b15c57a16539369873a31aae20c028d50efc9f4fe4c46f9973", "price_changes": [{"asset_id": "45622453771453949816894791094505340162140487852041488561027748414607473630122", "price": "0.04", "size": "5.47", "side": "BUY", "hash": "f75942d5f15e8072442321a1ceb2baa25a05d35c", "best_bid": "0.04", "best_ask": "0.96"}, {"asset_id": "36376479227210509138719694118857362983085092412966657890412021289097812996653", "price": "0.96", "size": "5.47", "side": "SELL", "hash": "0199d2eb3ea8429063744d4826e48f91804b83a2", "best_bid": "0.04", "best_ask": "0.96"}], "timestamp": "1769384169334", "event_type": "price_change"}}
{"_local_timestamp": "2026-01-25T23:36:09.404860+00:00", "data": {"market": "0x83ecbe4fce688c64f4b5d4befac5e64922cb8682e0e1365fc0468ff533c71e49", "price_changes": [{"asset_id": "68037078242557231080288874617522547606466154419149083356555127918659292747130", "price": "0.04", "size": "5.47", "side": "BUY", "hash": "67029b9a092d118cf6f8668f5aaa85ba6ab8ef1c", "best_bid": "0.04", "best_ask": "0.96"}, {"asset_id": "105434914828600935285428845047491083161332333045327551979231234346212907811414", "price": "0.96", "size": "5.47", "side": "SELL", "hash": "fb078e6571835ec9cff6ddd9f0dfb28e8ec30d05", "best_bid": "0.04", "best_ask": "0.96"}], "timestamp": "1769384169334", "event_type": "price_change"}}
{"_local_timestamp": "2026-01-25T23:36:09.405238+00:00", "data": {"market": "0x755a62c90339cdf3468fab177c6bfd9dceb5e45203e68bf069b50303a6abd25f", "price_changes": [{"asset_id": "78909895416168898474213741912660947562122027739865278774230819696266961515246", "price": "0.04", "size": "5.47", "side": "BUY", "hash": "161a5e46076d2769011002a81eb6e2073fa2de06", "best_bid": "0.04", "best_ask": "0.96"}, {"asset_id": "84460776671731186445015851207745064196399530432412893483409324414283960172444", "price": "0.96", "size": "5.47", "side": "SELL", "hash": "965e86afa3deb54944fa0cf9b92b67409d14d3e4", "best_bid": "0.04", "best_ask": "0.96"}], "timestamp": "1769384169334", "event_type": "price_change"}}
{"_local_timestamp": "2026-01-25T23:36:09.405666+00:00", "data": {"market": "0x887d9af4bfb28d239e7ed0c69ff91d84ece92a11b58984d0ff0393c0c24a2d01", "price_changes": [{"asset_id": "91500912612677572060291806454710032668881503701184797906037737191617363298512", "price": "0.04", "size": "5.47", "side": "BUY", "hash": "86bebe1cd8263c00392672983893ade380215430", "best_bid": "0.04", "best_ask": "0.96"}, {"asset_id": "53797474885844189083818567441605903163912505725772675434705257100199647449827", "price": "0.96", "size": "5.47", "side": "SELL", "hash": "cd7566e56bbc8678a767c7922b7db6e76758884f", "best_bid": "0.04", "best_ask": "0.96"}], "timestamp": "1769384169334", "event_type": "price_change"}}
{"_local_timestamp": "2026-01-25T23:37:14.263631+00:00", "data": {"market": "0xa2945f80a0c041b15c57a16539369873a31aae20c028d50efc9f4fe4c46f9973", "price_changes": [{"asset_id": "45622453771453949816894791094505340162140487852041488561027748414607473630122", "price": "0.03", "size": "12.74", "side": "BUY", "hash": "2c36b700332fd63a928f71659544bfc81cf2319b", "best_bid": "0.04", "best_ask": "0.96"}, {"asset_id": "36376479227210509138719694118857362983085092412966657890412021289097812996653", "price": "0.97", "size": "12.74", "side": "SELL", "hash": "69b38f69b461b122b12b80ee1ef33eb35cfe3dd5", "best_bid": "0.04", "best_ask": "0.96"}], "timestamp": "1769384234186", "event_type": "price_change"}}
{"_local_timestamp": "2026-01-25T23:37:14.264112+00:00", "data": {"market": "0xa9e485d9ab8973f5683fc4992b591ab9997052b8d7acc5d800d197e95ba0f5ee", "price_changes": [{"asset_id": "52957896528748198044120161866858084167956853408096664478472083379802465908152", "price": "0.03", "size": "12.74", "side": "BUY", "hash": "f3357125361a5922f1f5ecd257dabf49e1bdebd6", "best_bid": "0.04", "best_ask": "0.96"}, {"asset_id": "42963846885724327117066696479449241735482257984315608228983457680056285716377", "price": "0.97", "size": "12.74", "side": "SELL", "hash": "4d17bf0883e483a1a92275eca80ddc21493d3762", "best_bid": "0.04", "best_ask": "0.96"}], "timestamp": "1769384234186", "event_type": "price_change"}}
{"_local_timestamp": "2026-01-25T23:37:14.559139+00:00", "data": {"market": "0xa9e485d9ab8973f5683fc4992b591ab9997052b8d7acc5d800d197e95ba0f5ee", "price_changes": [{"asset_id": "52957896528748198044120161866858084167956853408096664478472083379802465908152", "price": "0.01", "size": "68.97", "side": "BUY", "hash": "f9434035a41381c7de13cff6226a1d07b08b6fb6", "best_bid": "0.04", "best_ask": "0.96"}, {"asset_id": "42963846885724327117066696479449241735482257984315608228983457680056285716377", "price": "0.99", "size": "68.97", "side": "SELL", "hash": "7c62bc551e4319046868249bceb77fe12fe01b69", "best_bid": "0.04", "best_ask": "0.96"}], "timestamp": "1769384234481", "event_type": "price_change"}}
{"_local_timestamp": "2026-01-25T23:37:14.559642+00:00", "data": {"market": "0xa2945f80a0c041b15c57a16539369873a31aae20c028d50efc9f4fe4c46f9973", "price_changes": [{"asset_id": "45622453771453949816894791094505340162140487852041488561027748414607473630122", "price": "0.03", "size": "20.65", "side": "BUY", "hash": "4336cafd4bf6eb6c39df4a726820a178cbceb88c", "best_bid": "0.04", "best_ask": "0.96"}, {"asset_id": "36376479227210509138719694118857362983085092412966657890412021289097812996653", "price": "0.97", "size": "20.65", "side": "SELL", "hash": "25bf3dc4c6a86ebc4585fd781952e815f37696f0", "best_bid": "0.04", "best_ask": "0.96"}], "timestamp": "1769384234481", "event_type": "price_change"}}
{"_local_timestamp": "2026-01-25T23:37:14.567699+00:00", "data": {"market": "0xa2945f80a0c041b15c57a16539369873a31aae20c028d50efc9f4fe4c46f9973", "price_changes": [{"asset_id": "45622453771453949816894791094505340162140487852041488561027748414607473630122", "price": "0.01", "size": "68.98", "side": "BUY", "hash": "6144964bc4d6d42ad1cee4a4a8ce27f6e7349919", "best_bid": "0.04", "best_ask": "0.96"}, {"asset_id": "36376479227210509138719694118857362983085092412966657890412021289097812996653", "price": "0.99", "size": "68.98", "side": "SELL", "hash": "67983fa02eeca57b6ddfcf1dbf91a418ba9d5149", "best_bid": "0.04", "best_ask": "0.96"}], "timestamp": "1769384234485", "event_type": "price_change"}}
{"_local_timestamp": "2026-01-25T23:37:14.568177+00:00", "data": {"market": "0xa9e485d9ab8973f5683fc4992b591ab9997052b8d7acc5d800d197e95ba0f5ee", "price_changes": [{"asset_id": "52957896528748198044120161866858084167956853408096664478472083379802465908152", "price": "0.03", "size": "20.65", "side": "BUY", "hash": "d5d70074cc60604de84b49a0d087aede42fcd8e0", "best_bid": "0.04", "best_ask": "0.96"}, {"asset_id": "42963846885724327117066696479449241735482257984315608228983457680056285716377", "price": "0.97", "size": "20.65", "side": "SELL", "hash": "8d63b5ce35ae843e54a64b4b1098f5bd048b6796", "best_bid": "0.04", "best_ask": "0.96"}], "timestamp": "1769384234485", "event_type": "price_change"}}
{"_local_timestamp": "2026-01-25T23:37:15.038436+00:00", "data": {"market": "0xca130e51e4406596d098557a80d3fa6e95eb16d32ef09d08d20da8b7ab6d6298", "price_changes": [{"asset_id": "35965820443596672753502165079905474159071605177387618189868308759415426382973", "price": "0.03", "size": "8.97", "side": "BUY", "hash": "7fd378e156357762777bdd1ef553fe7e6babc220", "best_bid": "0.04", "best_ask": "0.96"}, {"asset_id": "9877937220298673394222737478141754783632484432479493143738647510821851680044", "price": "0.97", "size": "8.97", "side": "SELL", "hash": "68202b713cb6f492fc4bc647d69d16ddd0e0fb3d", "best_bid": "0.04", "best_ask": "0.96"}], "timestamp": "1769384234962", "event_type": "price_change"}}
{"_local_timestamp": "2026-01-25T23:37:15.347942+00:00", "data": {"market": "0xca130e51e4406596d098557a80d3fa6e95eb16d32ef09d08d20da8b7ab6d6298", "price_changes": [{"asset_id": "35965820443596672753502165079905474159071605177387618189868308759415426382973", "price": "0.03", "size": "18.99", "side": "BUY", "hash": "8efb9440f68ba35f4abaa921512ae5d539c79277", "best_bid": "0.04", "best_ask": "0.96"}, {"asset_id": "9877937220298673394222737478141754783632484432479493143738647510821851680044", "price": "0.97", "size": "18.99", "side": "SELL", "hash": "106015d71e0ed97953174b2f302aebdfa1db1d50", "best_bid": "0.04", "best_ask": "0.96"}], "timestamp": "1769384235280", "event_type": "price_change"}}
{"_local_timestamp": "2026-01-25T23:37:15.348403+00:00", "data": {"market": "0xca130e51e4406596d098557a80d3fa6e95eb16d32ef09d08d20da8b7ab6d6298", "price_changes": [{"asset_id": "35965820443596672753502165079905474159071605177387618189868308759415426382973", "price": "0.02", "size": "182.48", "side": "BUY", "hash": "7874e47faf7752cfdb51ce866806d4daaf252cfb", "best_bid": "0.04", "best_ask": "0.96"}, {"asset_id": "9877937220298673394222737478141754783632484432479493143738647510821851680044", "price": "0.98", "size": "182.48", "side": "SELL", "hash": "aa1b7f8cc4a966be77c67c7706d94ea5b97e34bb", "best_bid": "0.04", "best_ask": "0.96"}], "timestamp": "1769384235282", "event_type": "price_change"}}
{"_local_timestamp": "2026-01-25T23:37:15.355079+00:00", "data": {"market": "0xca130e51e4406596d098557a80d3fa6e95eb16d32ef09d08d20da8b7ab6d6298", "price_changes": [{"asset_id": "35965820443596672753502165079905474159071605177387618189868308759415426382973", "price": "0.01", "size": "67.05", "side": "BUY", "hash": "2dff1991caa75d5fb7fd0fef62cf7e6d279f9978", "best_bid": "0.04", "best_ask": "0.96"}, {"asset_id": "9877937220298673394222737478141754783632484432479493143738647510821851680044", "price": "0.99", "size": "67.05", "side": "SELL", "hash": "9db57bb22385f0fe463c40cfb8869d5cab4c9b3a", "best_bid": "0.04", "best_ask": "0.96"}], "timestamp": "1769384235285", "event_type": "price_change"}}
{"_local_timestamp": "2026-01-25T23:37:16.538928+00:00", "data": {"market": "0x754ef6f17592b0ef700ddd256368d8a853e1b2608d801cbd10bb8867943feb51", "price_changes": [{"asset_id": "58817089064209115360537822581951729680659415067098716481850517826996528126939", "price": "0.03", "size": "8.97", "side": "BUY", "hash": "27ff62166653e3e7a4636e370d7877b75126658d", "best_bid": "0.04", "best_ask": "0.96"}, {"asset_id": "100119332257398155495950907520135487242937804051607670301581332334796358396713", "price": "0.97", "size": "8.97", "side": "SELL", "hash": "89932a5a642be32efc31796487e972389e246e99", "best_bid": "0.04", "best_ask": "0.96"}], "timestamp": "1769384236464", "event_type": "price_change"}}
{"_local_timestamp": "2026-01-25T23:37:16.539467+00:00", "data": {"market": "0x887d9af4bfb28d239e7ed0c69ff91d84ece92a11b58984d0ff0393c0c24a2d01", "price_changes": [{"asset_id": "91500912612677572060291806454710032668881503701184797906037737191617363298512", "price": "0.03", "size": "9.81", "side": "BUY", "hash": "a1fed11c88795c736a943d06dbeed88d61dc86ca", "best_bid": "0.04", "best_ask": "0.96"}, {"asset_id": "53797474885844189083818567441605903163912505725772675434705257100199647449827", "price": "0.97", "size": "9.81", "side": "SELL", "hash": "f5908a4415e62719f9e094c8647075f595ec546a", "best_bid": "0.04", "best_ask": "0.96"}], "timestamp": "1769384236464", "event_type": "price_change"}}
{"_local_timestamp": "2026-01-25T23:37:16.746187+00:00", "data": {"market": "0x754ef6f17592b0ef700ddd256368d8a853e1b2608d801cbd10bb8867943feb51", "price_changes": [{"asset_id": "58817089064209115360537822581951729680659415067098716481850517826996528126939", "price": "0.02", "size": "207.48", "side": "BUY", "hash": "4fe584e0745c110114a5b6ec2ada28011adf8ef5", "best_bid": "0.04", "best_ask": "0.96"}, {"asset_id": "100119332257398155495950907520135487242937804051607670301581332334796358396713", "price": "0.98", "size": "207.48", "side": "SELL", "hash": "dff61c419c4846e61e605124844904f2c62662bb", "best_bid": "0.04", "best_ask": "0.96"}], "timestamp": "1769384236679", "event_type": "price_change"}}
{"_local_timestamp": "2026-01-25T23:37:16.746653+00:00", "data": {"market": "0x887d9af4bfb28d239e7ed0c69ff91d84ece92a11b58984d0ff0393c0c24a2d01", "price_changes": [{"asset_id": "91500912612677572060291806454710032668881503701184797906037737191617363298512", "price": "0.03", "size": "21.33", "side": "BUY", "hash": "c5a1ca10d55c48034b276655b1650351a3c392b4", "best_bid": "0.04", "best_ask": "0.96"}, {"asset_id": "53797474885844189083818567441605903163912505725772675434705257100199647449827", "price": "0.97", "size": "21.33", "side": "SELL", "hash": "43224b62d72c5b35e6158aeb3ed481a53472cf3c", "best_bid": "0.04", "best_ask": "0.96"}], "timestamp": "1769384236680", "event_type": "price_change"}}
{"_local_timestamp": "2026-01-25T23:37:16.747071+00:00", "data": {"market": "0x754ef6f17592b0ef700ddd256368d8a853e1b2608d801cbd10bb8867943feb51", "price_changes": [{"asset_id": "58817089064209115360537822581951729680659415067098716481850517826996528126939", "price": "0.01", "size": "116.05", "side": "BUY", "hash": "819093f5622ae74ec96c6e78f81e7f52dd2d0192", "best_bid": "0.04", "best_ask": "0.96"}, {"asset_id": "100119332257398155495950907520135487242937804051607670301581332334796358396713", "price": "0.99", "size": "116.05", "side": "SELL", "hash": "87fe9a7be8a7c83cf7ddf0d00d31c94392bfda21", "best_bid": "0.04", "best_ask": "0.96"}], "timestamp": "1769384236680", "event_type": "price_change"}}
{"_local_timestamp": "2026-01-25T23:37:16.747472+00:00", "data": {"market": "0x887d9af4bfb28d239e7ed0c69ff91d84ece92a11b58984d0ff0393c0c24a2d01", "price_changes": [{"asset_id": "91500912612677572060291806454710032668881503701184797906037737191617363298512", "price": "0.01", "size": "169.66", "side": "BUY", "hash": "7ea8b03142c943cff4c4fa9df0a7f55c14f3cab9", "best_bid": "0.04", "best_ask": "0.96"}, {"asset_id": "53797474885844189083818567441605903163912505725772675434705257100199647449827", "price": "0.99", "size": "169.66", "side": "SELL", "hash": "88fcda8ce9e47f5bcc59b16fabcce58be10e3eb2", "best_bid": "0.04", "best_ask": "0.96"}], "timestamp": "1769384236680", "event_type": "price_change"}}
{"_local_timestamp": "2026-01-25T23:37:16.747894+00:00", "data": {"market": "0x754ef6f17592b0ef700ddd256368d8a853e1b2608d801cbd10bb8867943feb51", "price_changes": [{"asset_id": "58817089064209115360537822581951729680659415067098716481850517826996528126939", "price": "0.03", "size": "18.99", "side": "BUY", "hash": "5ec21b8b15ee848fbbe2e36f52ecc0e498d97c50", "best_bid": "0.04", "best_ask": "0.96"}, {"asset_id": "100119332257398155495950907520135487242937804051607670301581332334796358396713", "price": "0.97", "size": "18.99", "side": "SELL", "hash": "d6b60df212502897599e17616c039e33cdeef7bf", "best_bid": "0.04", "best_ask": "0.96"}], "timestamp": "1769384236681", "event_type": "price_change"}}
{"_local_timestamp": "2026-01-25T23:37:17.811891+00:00", "data": {"market": "0xa82369f8cd0613e9cb843d07e87c6b91b564c1265738b69e7053b75d8d194072", "price_changes": [{"asset_id": "68920659505468313520408686217763348542438468104855337990549641270016076337409", "price": "0.06", "size": "5.47", "side": "BUY", "hash": "b0e915f2b8e2075d582ff5835641f88498678df5", "best_bid": "0.06", "best_ask": "0.96"}, {"asset_id": "46422279213299921123420170221742083018235225596393864746784180664594216048059", "price": "0.94", "size": "5.47", "side": "SELL", "hash": "e85dcbed789d1cd13f9f4718ec293da439872280", "best_bid": "0.04", "best_ask": "0.94"}], "timestamp": "1769384237750", "event_type": "price_change"}}
{"_local_timestamp": "2026-01-25T23:37:18.132314+00:00", "data": {"market": "0xa82369f8cd0613e9cb843d07e87c6b91b564c1265738b69e7053b75d8d194072", "price_changes": [{"asset_id": "68920659505468313520408686217763348542438468104855337990549641270016076337409", "price": "0.03", "size": "22.11", "side": "BUY", "hash": "f65b70a743c20851a8899c0a4cfe96ba8a90f989", "best_bid": "0.06", "best_ask": "0.96"}, {"asset_id": "46422279213299921123420170221742083018235225596393864746784180664594216048059", "price": "0.97", "size": "22.11", "side": "SELL", "hash": "8a67af143f9a967f61b4993e4fb4724c601eff81", "best_bid": "0.04", "best_ask": "0.94"}], "timestamp": "1769384238024", "event_type": "price_change"}}
{"_local_timestamp": "2026-01-25T23:37:20.272809+00:00", "data": {"market": "0xa82369f8cd0613e9cb843d07e87c6b91b564c1265738b69e7053b75d8d194072", "price_changes": [{"asset_id": "68920659505468313520408686217763348542438468104855337990549641270016076337409", "price": "0.06", "size": "0", "side": "BUY", "hash": "539e0b831654ed6ebb12443a17d071e0eb26212f", "best_bid": "0.03", "best_ask": "0.96"}, {"asset_id": "46422279213299921123420170221742083018235225596393864746784180664594216048059", "price": "0.94", "size": "0", "side": "SELL", "hash": "1c22bc0e8c849e1f676dc6cfc21cd68797a5698e", "best_bid": "0.04", "best_ask": "0.97"}], "timestamp": "1769384240202", "event_type": "price_change"}}
{"_local_timestamp": "2026-01-25T23:37:20.313717+00:00", "data": {"market": "0xa82369f8cd0613e9cb843d07e87c6b91b564c1265738b69e7053b75d8d194072", "price_changes": [{"asset_id": "68920659505468313520408686217763348542438468104855337990549641270016076337409", "price": "0.04", "size": "5.47", "side": "BUY", "hash": "099441d873a7c7b54bf595b5480edf9712a43cba", "best_bid": "0.04", "best_ask": "0.96"}, {"asset_id": "46422279213299921123420170221742083018235225596393864746784180664594216048059", "price": "0.96", "size": "5.47", "side": "SELL", "hash": "a7cb43480593c848cc4560c5a7ead4e2144d71c9", "best_bid": "0.04", "best_ask": "0.96"}], "timestamp": "1769384240246", "event_type": "price_change"}}
{"_local_timestamp": "2026-01-25T23:37:28.668322+00:00", "data": {"market": "0x6a4478e27573f95e3440cbc34f7b2365f7cb10cfd0b4364ca5561b4e9aab4891", "price_changes": [{"asset_id": "96043889621651020187424767256997061290487486445860257445666515755879268438162", "price": "0.69", "size": "105.3", "side": "BUY", "hash": "4aaed9845eb1b999d2c53567c43956e2e261e19e", "best_bid": "0.69", "best_ask": "0.7"}, {"asset_id": "55381454494707880049199570510897695915429248734443086753962741530042084242732", "price": "0.31", "size": "105.3", "side": "SELL", "hash": "1bfbd9ad5b051872e1fb214670b90d7a1c674955", "best_bid": "0.3", "best_ask": "0.31"}], "timestamp": "1769384248602", "event_type": "price_change"}}
{"_local_timestamp": "2026-01-25T23:37:28.668947+00:00", "data": {"market": "0x6a4478e27573f95e3440cbc34f7b2365f7cb10cfd0b4364ca5561b4e9aab4891", "asset_id": "96043889621651020187424767256997061290487486445860257445666515755879268438162", "bids": [{"price": "0.01", "size": "3755.05"}, {"price": "0.02", "size": "2250"}, {"price": "0.03", "size": "9.36"}, {"price": "0.05", "size": "1700"}, {"price": "0.09", "size": "700"}, {"price": "0.1", "size": "6.18"}, {"price": "0.14", "size": "200"}, {"price": "0.21", "size": "2000"}, {"price": "0.22", "size": "250"}, {"price": "0.26", "size": "300"}, {"price": "0.29", "size": "200"}, {"price": "0.31", "size": "125"}, {"price": "0.34", "size": "75"}, {"price": "0.35", "size": "10"}, {"price": "0.5", "size": "30"}, {"price": "0.63", "size": "311.44"}, {"price": "0.64", "size": "250"}, {"price": "0.69", "size": "105.3"}], "asks": [{"price": "0.99", "size": "940"}, {"price": "0.98", "size": "156.2"}, {"price": "0.97", "size": "75"}, {"price": "0.96", "size": "21.89"}, {"price": "0.9", "size": "300"}, {"price": "0.89", "size": "300"}, {"price": "0.88", "size": "125"}, {"price": "0.87", "size": "75"}, {"price": "0.8", "size": "194.78"}, {"price": "0.78", "size": "10"}, {"price": "0.75", "size": "10"}, {"price": "0.71", "size": "500"}, {"price": "0.7", "size": "50"}], "hash": "4aaed9845eb1b999d2c53567c43956e2e261e19e", "timestamp": "1769384248602", "event_type": "book"}}
{"_local_timestamp": "2026-01-25T23:37:28.669558+00:00", "data": {"market": "0x6a4478e27573f95e3440cbc34f7b2365f7cb10cfd0b4364ca5561b4e9aab4891", "asset_id": "55381454494707880049199570510897695915429248734443086753962741530042084242732", "bids": [{"price": "0.01", "size": "940"}, {"price": "0.02", "size": "156.2"}, {"price": "0.03", "size": "75"}, {"price": "0.04", "size": "21.89"}, {"price": "0.1", "size": "300"}, {"price": "0.11", "size": "300"}, {"price": "0.12", "size": "125"}, {"price": "0.13", "size": "75"}, {"price": "0.2", "size": "194.78"}, {"price": "0.22", "size": "10"}, {"price": "0.25", "size": "10"}, {"price": "0.29", "size": "500"}, {"price": "0.3", "size": "50"}], "asks": [{"price": "0.99", "size": "3755.05"}, {"price": "0.98", "size": "2250"}, {"price": "0.97", "size": "9.36"}, {"price": "0.95", "size": "1700"}, {"price": "0.91", "size": "700"}, {"price": "0.9", "size": "6.18"}, {"price": "0.86", "size": "200"}, {"price": "0.79", "size": "2000"}, {"price": "0.78", "size": "250"}, {"price": "0.74", "size": "300"}, {"price": "0.71", "size": "200"}, {"price": "0.69", "size": "125"}, {"price": "0.66", "size": "75"}, {"price": "0.65", "size": "10"}, {"price": "0.5", "size": "30"}, {"price": "0.37", "size": "311.44"}, {"price": "0.36", "size": "250"}, {"price": "0.31", "size": "105.3"}], "hash": "1bfbd9ad5b051872e1fb214670b90d7a1c674955", "timestamp": "1769384248602", "event_type": "book"}}
{"_local_timestamp": "2026-01-25T23:37:28.707729+00:00", "data": {"market": "0x6a4478e27573f95e3440cbc34f7b2365f7cb10cfd0b4364ca5561b4e9aab4891", "asset_id": "55381454494707880049199570510897695915429248734443086753962741530042084242732", "price": "0.31", "size": "32.258063", "fee_rate_bps": "0", "side": "BUY", "timestamp": "1769384248631", "event_type": "last_trade_price", "transaction_hash": "0x0adbd2127a271d2ee005b3aca01e6a78734fcee2d3ae0aa8fe6b3bb9cc3025ce"}}
{"_local_timestamp": "2026-01-25T23:37:44.710850+00:00", "data": {"market": "0x755a62c90339cdf3468fab177c6bfd9dceb5e45203e68bf069b50303a6abd25f", "price_changes": [{"asset_id": "78909895416168898474213741912660947562122027739865278774230819696266961515246", "price": "0.05", "size": "23.99", "side": "BUY", "hash": "17df4b643c29fe38f1eb9f8ffb1b972928923acb", "best_bid": "0.05", "best_ask": "0.96"}, {"asset_id": "84460776671731186445015851207745064196399530432412893483409324414283960172444", "price": "0.95", "size": "23.99", "side": "SELL", "hash": "cf1a938f89eb8ab4d57ea6417d6c0dea14c36c58", "best_bid": "0.04", "best_ask": "0.95"}], "timestamp": "1769384264643", "event_type": "price_change"}}
{"_local_timestamp": "2026-01-25T23:37:44.711385+00:00", "data": {"market": "0x754ef6f17592b0ef700ddd256368d8a853e1b2608d801cbd10bb8867943feb51", "price_changes": [{"asset_id": "58817089064209115360537822581951729680659415067098716481850517826996528126939", "price": "0.05", "size": "23.99", "side": "BUY", "hash": "c78517c1903bb0945d25aec56a451d87388d673a", "best_bid": "0.05", "best_ask": "0.96"}, {"asset_id": "100119332257398155495950907520135487242937804051607670301581332334796358396713", "price": "0.95", "size": "23.99", "side": "SELL", "hash": "12451a518b157d7177ea059d445bbb208c383d60", "best_bid": "0.04", "best_ask": "0.95"}], "timestamp": "1769384264643", "event_type": "price_change"}}
{"_local_timestamp": "2026-01-25T23:37:44.711852+00:00", "data": {"market": "0x0c35017fce45618791b247a0e015a99dfdaa11fce35665f46a21329c75539bf5", "price_changes": [{"asset_id": "91719725116883012291565512161477775996897243486374553084185529876278409496454", "price": "0.05", "size": "23.99", "side": "BUY", "hash": "acaa9d7f51f15f0b7c7e228585cfb2b4c8208986", "best_bid": "0.05", "best_ask": "0.96"}, {"asset_id": "113869036122116896359974222126121258669445902300788141703831662654178658580719", "price": "0.95", "size": "23.99", "side": "SELL", "hash": "3f7d20d8bc437b0069251c3b8d4db144d5e49735", "best_bid": "0.04", "best_ask": "0.95"}], "timestamp": "1769384264643", "event_type": "price_change"}}
{"_local_timestamp": "2026-01-25T23:37:44.815310+00:00", "data": {"market": "0x83ecbe4fce688c64f4b5d4befac5e64922cb8682e0e1365fc0468ff533c71e49", "price_changes": [{"asset_id": "68037078242557231080288874617522547606466154419149083356555127918659292747130", "price": "0.05", "size": "23.99", "side": "BUY", "hash": "e17c7f8a6125a274af51c9b55db095960316e7ac", "best_bid": "0.05", "best_ask": "0.96"}, {"asset_id": "105434914828600935285428845047491083161332333045327551979231234346212907811414", "price": "0.95", "size": "23.99", "side": "SELL", "hash": "7a91b85f3d7e8c915914a4b2ca3a71681798a6b1", "best_bid": "0.04", "best_ask": "0.95"}], "timestamp": "1769384264750", "event_type": "price_change"}}
{"_local_timestamp": "2026-01-25T23:37:44.815988+00:00", "data": {"market": "0x887d9af4bfb28d239e7ed0c69ff91d84ece92a11b58984d0ff0393c0c24a2d01", "price_changes": [{"asset_id": "91500912612677572060291806454710032668881503701184797906037737191617363298512", "price": "0.05", "size": "23.99", "side": "BUY", "hash": "10807121032c1c3b69a38af3c7065f1f92c67291", "best_bid": "0.05", "best_ask": "0.96"}, {"asset_id": "53797474885844189083818567441605903163912505725772675434705257100199647449827", "price": "0.95", "size": "23.99", "side": "SELL", "hash": "6ea088721eaf523ad6bb565183ce330999575b5a", "best_bid": "0.04", "best_ask": "0.95"}], "timestamp": "1769384264750", "event_type": "price_change"}}
{"_local_timestamp": "2026-01-25T23:37:44.823817+00:00", "data": {"market": "0xa9e485d9ab8973f5683fc4992b591ab9997052b8d7acc5d800d197e95ba0f5ee", "price_changes": [{"asset_id": "52957896528748198044120161866858084167956853408096664478472083379802465908152", "price": "0.05", "size": "23.99", "side": "BUY", "hash": "8973c077e4df1ad95548aad2f77f2ceb1b2fa49b", "best_bid": "0.05", "best_ask": "0.96"}, {"asset_id": "42963846885724327117066696479449241735482257984315608228983457680056285716377", "price": "0.95", "size": "23.99", "side": "SELL", "hash": "07fbf2c3f893ace7e4072be9d5f691e132277ac4", "best_bid": "0.04", "best_ask": "0.95"}], "timestamp": "1769384264750", "event_type": "price_change"}}
{"_local_timestamp": "2026-01-25T23:37:44.923674+00:00", "data": {"market": "0xca130e51e4406596d098557a80d3fa6e95eb16d32ef09d08d20da8b7ab6d6298", "price_changes": [{"asset_id": "35965820443596672753502165079905474159071605177387618189868308759415426382973", "price": "0.05", "size": "23.99", "side": "BUY", "hash": "6b0e14d116893550eb5e1adc518bcab1c7593edc", "best_bid": "0.05", "best_ask": "0.96"}, {"asset_id": "9877937220298673394222737478141754783632484432479493143738647510821851680044", "price": "0.95", "size": "23.99", "side": "SELL", "hash": "23162fb2baeb287d40a564b668f13f7eb4b098e7", "best_bid": "0.04", "best_ask": "0.95"}], "timestamp": "1769384264851", "event_type": "price_change"}}
{"_local_timestamp": "2026-01-25T23:37:44.924223+00:00", "data": {"market": "0xa2945f80a0c041b15c57a16539369873a31aae20c028d50efc9f4fe4c46f9973", "price_changes": [{"asset_id": "45622453771453949816894791094505340162140487852041488561027748414607473630122", "price": "0.05", "size": "23.99", "side": "BUY", "hash": "a9551dccd1291e4e1f47047d138e0cc3ca823023", "best_bid": "0.05", "best_ask": "0.96"}, {"asset_id": "36376479227210509138719694118857362983085092412966657890412021289097812996653", "price": "0.95", "size": "23.99", "side": "SELL", "hash": "efc4eda5b1968f1a89b0c071f0a2855a80d523ad", "best_bid": "0.04", "best_ask": "0.95"}], "timestamp": "1769384264851", "event_type": "price_change"}}
{"_local_timestamp": "2026-01-25T23:37:50.027922+00:00", "data": {"market": "0x755a62c90339cdf3468fab177c6bfd9dceb5e45203e68bf069b50303a6abd25f", "price_changes": [{"asset_id": "78909895416168898474213741912660947562122027739865278774230819696266961515246", "price": "0.04", "size": "0", "side": "BUY", "hash": "5ffa08316f5e88f03b911c9866622cce7e7249c6", "best_bid": "0.05", "best_ask": "0.96"}, {"asset_id": "84460776671731186445015851207745064196399530432412893483409324414283960172444", "price": "0.96", "size": "0", "side": "SELL", "hash": "b9db741e82d161132731e493abdae763ce9a11dd", "best_bid": "0.04", "best_ask": "0.95"}], "timestamp": "1769384269957", "event_type": "price_change"}}
{"_local_timestamp": "2026-01-25T23:37:50.028764+00:00", "data": {"market": "0x754ef6f17592b0ef700ddd256368d8a853e1b2608d801cbd10bb8867943feb51", "price_changes": [{"asset_id": "58817089064209115360537822581951729680659415067098716481850517826996528126939", "price": "0.04", "size": "0", "side": "BUY", "hash": "aff5b85762574dd0f01ec9ec14ace511c19d3f5e", "best_bid": "0.05", "best_ask": "0.96"}, {"asset_id": "100119332257398155495950907520135487242937804051607670301581332334796358396713", "price": "0.96", "size": "0", "side": "SELL", "hash": "a22bbeb0f635c714fde19fd19d67d2cfc150a952", "best_bid": "0.04", "best_ask": "0.95"}], "timestamp": "1769384269957", "event_type": "price_change"}}
{"_local_timestamp": "2026-01-25T23:37:50.032262+00:00", "data": {"market": "0xa2945f80a0c041b15c57a16539369873a31aae20c028d50efc9f4fe4c46f9973", "price_changes": [{"asset_id": "45622453771453949816894791094505340162140487852041488561027748414607473630122", "price": "0.04", "size": "0", "side": "BUY", "hash": "df0a17bc53a6335ff443e2232e9edbfbb497ded5", "best_bid": "0.05", "best_ask": "0.96"}, {"asset_id": "36376479227210509138719694118857362983085092412966657890412021289097812996653", "price": "0.96", "size": "0", "side": "SELL", "hash": "338e29f92aab5391e16d15391b186de1abbc3acc", "best_bid": "0.04", "best_ask": "0.95"}], "timestamp": "1769384269957", "event_type": "price_change"}}
{"_local_timestamp": "2026-01-25T23:37:50.033404+00:00", "data": {"market": "0x887d9af4bfb28d239e7ed0c69ff91d84ece92a11b58984d0ff0393c0c24a2d01", "price_changes": [{"asset_id": "91500912612677572060291806454710032668881503701184797906037737191617363298512", "price": "0.04", "size": "0", "side": "BUY", "hash": "4ec2984ff6eabc67b34c6cca260ebfa016fc6310", "best_bid": "0.05", "best_ask": "0.96"}, {"asset_id": "53797474885844189083818567441605903163912505725772675434705257100199647449827", "price": "0.96", "size": "0", "side": "SELL", "hash": "446828230dd159170bfe3a0364683d0bd02dcb05", "best_bid": "0.04", "best_ask": "0.95"}], "timestamp": "1769384269957", "event_type": "price_change"}}
{"_local_timestamp": "2026-01-25T23:37:50.036356+00:00", "data": {"market": "0x83ecbe4fce688c64f4b5d4befac5e64922cb8682e0e1365fc0468ff533c71e49", "price_changes": [{"asset_id": "68037078242557231080288874617522547606466154419149083356555127918659292747130", "price": "0.04", "size": "0", "side": "BUY", "hash": "b0e1e4061354706bed9c7d6e6ad5ae10496f9743", "best_bid": "0.05", "best_ask": "0.96"}, {"asset_id": "105434914828600935285428845047491083161332333045327551979231234346212907811414", "price": "0.96", "size": "0", "side": "SELL", "hash": "3450415ca28145a34402b5b9b68d8a93085d63c3", "best_bid": "0.04", "best_ask": "0.95"}], "timestamp": "1769384269957", "event_type": "price_change"}}
{"_local_timestamp": "2026-01-25T23:37:50.038351+00:00", "data": {"market": "0xca130e51e4406596d098557a80d3fa6e95eb16d32ef09d08d20da8b7ab6d6298", "price_changes": [{"asset_id": "35965820443596672753502165079905474159071605177387618189868308759415426382973", "price": "0.04", "size": "0", "side": "BUY", "hash": "25654d4613eae7ce11b4d7422e76970cb88ef2aa", "best_bid": "0.05", "best_ask": "0.96"}, {"asset_id": "9877937220298673394222737478141754783632484432479493143738647510821851680044", "price": "0.96", "size": "0", "side": "SELL", "hash": "d63a80193f16730e980df54e2701918bd88e4674", "best_bid": "0.04", "best_ask": "0.95"}], "timestamp": "1769384269957", "event_type": "price_change"}}
{"_local_timestamp": "2026-01-25T23:37:50.039184+00:00", "data": {"market": "0xa9e485d9ab8973f5683fc4992b591ab9997052b8d7acc5d800d197e95ba0f5ee", "price_changes": [{"asset_id": "52957896528748198044120161866858084167956853408096664478472083379802465908152", "price": "0.04", "size": "0", "side": "BUY", "hash": "8dd4dc9ada68711a4eed13b3d7903c9962fa0c03", "best_bid": "0.05", "best_ask": "0.96"}, {"asset_id": "42963846885724327117066696479449241735482257984315608228983457680056285716377", "price": "0.96", "size": "0", "side": "SELL", "hash": "424a3adc667298056e17d1313034f5524632f583", "best_bid": "0.04", "best_ask": "0.95"}], "timestamp": "1769384269957", "event_type": "price_change"}}
{"_local_timestamp": "2026-01-25T23:37:50.039699+00:00", "data": {"market": "0x0c35017fce45618791b247a0e015a99dfdaa11fce35665f46a21329c75539bf5", "price_changes": [{"asset_id": "91719725116883012291565512161477775996897243486374553084185529876278409496454", "price": "0.04", "size": "0", "side": "BUY", "hash": "95cd1ffaa08e1759885c71ee896193bf82a37e49", "best_bid": "0.05", "best_ask": "0.96"}, {"asset_id": "113869036122116896359974222126121258669445902300788141703831662654178658580719", "price": "0.96", "size": "0", "side": "SELL", "hash": "657478a7cf9f89a7104d2ac8656bb0d41f97c031", "best_bid": "0.04", "best_ask": "0.95"}], "timestamp": "1769384269957", "event_type": "price_change"}}
{"_local_timestamp": "2026-01-25T23:37:50.170028+00:00", "data": {"market": "0x0c35017fce45618791b247a0e015a99dfdaa11fce35665f46a21329c75539bf5", "price_changes": [{"asset_id": "91719725116883012291565512161477775996897243486374553084185529876278409496454", "price": "0.06", "size": "5.47", "side": "BUY", "hash": "d6f97558860dee8f057fcae403ff70ca32ecf8c2", "best_bid": "0.06", "best_ask": "0.96"}, {"asset_id": "113869036122116896359974222126121258669445902300788141703831662654178658580719", "price": "0.94", "size": "5.47", "side": "SELL", "hash": "44fb58f6a1bb58ea890a90cf60b6414c4c4c188e", "best_bid": "0.04", "best_ask": "0.94"}], "timestamp": "1769384270097", "event_type": "price_change"}}
{"_local_timestamp": "2026-01-25T23:37:50.170687+00:00", "data": {"market": "0x755a62c90339cdf3468fab177c6bfd9dceb5e45203e68bf069b50303a6abd25f", "price_changes": [{"asset_id": "78909895416168898474213741912660947562122027739865278774230819696266961515246", "price": "0.06", "size": "5.47", "side": "BUY", "hash": "5eb7560dd8f80c1f4fc15682e6b045b090ef0b74", "best_bid": "0.06", "best_ask": "0.96"}, {"asset_id": "84460776671731186445015851207745064196399530432412893483409324414283960172444", "price": "0.94", "size": "5.47", "side": "SELL", "hash": "c4dcc8b46b0f80be1d66f1ca2f4078055a7092f3", "best_bid": "0.04", "best_ask": "0.94"}], "timestamp": "1769384270097", "event_type": "price_change"}}
{"_local_timestamp": "2026-01-25T23:37:50.172357+00:00", "data": {"market": "0x754ef6f17592b0ef700ddd256368d8a853e1b2608d801cbd10bb8867943feb51", "price_changes": [{"asset_id": "58817089064209115360537822581951729680659415067098716481850517826996528126939", "price": "0.06", "size": "5.47", "side": "BUY", "hash": "fcb41c8c2f55860c816f8834df6d5e83716b219b", "best_bid": "0.06", "best_ask": "0.96"}, {"asset_id": "100119332257398155495950907520135487242937804051607670301581332334796358396713", "price": "0.94", "size": "5.47", "side": "SELL", "hash": "c9b14ddb2fbbe3be597429a9f7c46e1852f46130", "best_bid": "0.04", "best_ask": "0.94"}], "timestamp": "1769384270097", "event_type": "price_change"}}
{"_local_timestamp": "2026-01-25T23:37:50.176965+00:00", "data": {"market": "0xa9e485d9ab8973f5683fc4992b591ab9997052b8d7acc5d800d197e95ba0f5ee", "price_changes": [{"asset_id": "52957896528748198044120161866858084167956853408096664478472083379802465908152", "price": "0.06", "size": "5.47", "side": "BUY", "hash": "4fcbcb7694d3c38ea994e26e11e8fd0677f1adf8", "best_bid": "0.06", "best_ask": "0.96"}, {"asset_id": "42963846885724327117066696479449241735482257984315608228983457680056285716377", "price": "0.94", "size": "5.47", "side": "SELL", "hash": "29cd71962c50deb84af33003f5db77fbe5ecaedf", "best_bid": "0.04", "best_ask": "0.94"}], "timestamp": "1769384270097", "event_type": "price_change"}}
{"_local_timestamp": "2026-01-25T23:37:50.177531+00:00", "data": {"market": "0x887d9af4bfb28d239e7ed0c69ff91d84ece92a11b58984d0ff0393c0c24a2d01", "price_changes": [{"asset_id": "91500912612677572060291806454710032668881503701184797906037737191617363298512", "price": "0.06", "size": "5.47", "side": "BUY", "hash": "8e0ea1c34828d4b136e644decaf4d2670b9a9379", "best_bid": "0.06", "best_ask": "0.96"}, {"asset_id": "53797474885844189083818567441605903163912505725772675434705257100199647449827", "price": "0.94", "size": "5.47", "side": "SELL", "hash": "6082d28601c531bb4d4e8583290d9ecced197e2c", "best_bid": "0.04", "best_ask": "0.94"}], "timestamp": "1769384270097", "event_type": "price_change"}}
{"_local_timestamp": "2026-01-25T23:37:50.178027+00:00", "data": {"market": "0x83ecbe4fce688c64f4b5d4befac5e64922cb8682e0e1365fc0468ff533c71e49", "price_changes": [{"asset_id": "68037078242557231080288874617522547606466154419149083356555127918659292747130", "price": "0.06", "size": "5.47", "side": "BUY", "hash": "298f80bd6d03c3086d7b04da5d1d2bee0a384ea8", "best_bid": "0.06", "best_ask": "0.96"}, {"asset_id": "105434914828600935285428845047491083161332333045327551979231234346212907811414", "price": "0.94", "size": "5.47", "side": "SELL", "hash": "047991300c6eb5177381d15e86632409488e3348", "best_bid": "0.04", "best_ask": "0.94"}], "timestamp": "1769384270097", "event_type": "price_change"}}
{"_local_timestamp": "2026-01-25T23:37:50.178639+00:00", "data": {"market": "0xca130e51e4406596d098557a80d3fa6e95eb16d32ef09d08d20da8b7ab6d6298", "price_changes": [{"asset_id": "35965820443596672753502165079905474159071605177387618189868308759415426382973", "price": "0.06", "size": "5.47", "side": "BUY", "hash": "20dc5af36810b92c9f68e05bff9a5af493409b4a", "best_bid": "0.06", "best_ask": "0.96"}, {"asset_id": "9877937220298673394222737478141754783632484432479493143738647510821851680044", "price": "0.94", "size": "5.47", "side": "SELL", "hash": "a8f48708a4cdae8ef51b43056b88395d580147b3", "best_bid": "0.04", "best_ask": "0.94"}], "timestamp": "1769384270097", "event_type": "price_change"}}
{"_local_timestamp": "2026-01-25T23:37:50.179147+00:00", "data": {"market": "0xa2945f80a0c041b15c57a16539369873a31aae20c028d50efc9f4fe4c46f9973", "price_changes": [{"asset_id": "45622453771453949816894791094505340162140487852041488561027748414607473630122", "price": "0.06", "size": "5.47", "side": "BUY", "hash": "123b83675ff7dd252aeb5571b50f3bd6c51151f6", "best_bid": "0.06", "best_ask": "0.96"}, {"asset_id": "36376479227210509138719694118857362983085092412966657890412021289097812996653", "price": "0.94", "size": "5.47", "side": "SELL", "hash": "e9c36b2fc08baa2b0cd0db48d46b3f4b602580af", "best_bid": "0.04", "best_ask": "0.94"}], "timestamp": "1769384270097", "event_type": "price_change"}}
{"_local_timestamp": "2026-01-25T23:39:10.877666+00:00", "data": {"market": "0x754ef6f17592b0ef700ddd256368d8a853e1b2608d801cbd10bb8867943feb51", "price_changes": [{"asset_id": "58817089064209115360537822581951729680659415067098716481850517826996528126939", "price": "0.05", "size": "0", "side": "BUY", "hash": "b08a68bc89e6d5d8bd58d9821a5e20735a90c68f", "best_bid": "0.06", "best_ask": "0.96"}, {"asset_id": "100119332257398155495950907520135487242937804051607670301581332334796358396713", "price": "0.95", "size": "0", "side": "SELL", "hash": "bc78a1aae2df29c3859b5ce4909e27106ed3de2e", "best_bid": "0.04", "best_ask": "0.94"}], "timestamp": "1769384350808", "event_type": "price_change"}}
{"_local_timestamp": "2026-01-25T23:39:10.878293+00:00", "data": {"market": "0x83ecbe4fce688c64f4b5d4befac5e64922cb8682e0e1365fc0468ff533c71e49", "price_changes": [{"asset_id": "68037078242557231080288874617522547606466154419149083356555127918659292747130", "price": "0.05", "size": "0", "side": "BUY", "hash": "e9d5aa899004b498c03239e90dbdb30fcd14cd15", "best_bid": "0.06", "best_ask": "0.96"}, {"asset_id": "105434914828600935285428845047491083161332333045327551979231234346212907811414", "price": "0.95", "size": "0", "side": "SELL", "hash": "efb7bf5978631ebdfe31e1593d526460ac8ca5d8", "best_bid": "0.04", "best_ask": "0.94"}], "timestamp": "1769384350808", "event_type": "price_change"}}
{"_local_timestamp": "2026-01-25T23:39:10.974132+00:00", "data": {"market": "0x0c35017fce45618791b247a0e015a99dfdaa11fce35665f46a21329c75539bf5", "price_changes": [{"asset_id": "91719725116883012291565512161477775996897243486374553084185529876278409496454", "price": "0.05", "size": "0", "side": "BUY", "hash": "4654ab935f104db298a71ae636d2c4776b138180", "best_bid": "0.06", "best_ask": "0.96"}, {"asset_id": "113869036122116896359974222126121258669445902300788141703831662654178658580719", "price": "0.95", "size": "0", "side": "SELL", "hash": "4b6b83e23653685fe2778438964b02f33f629865", "best_bid": "0.04", "best_ask": "0.94"}], "timestamp": "1769384350905", "event_type": "price_change"}}
{"_local_timestamp": "2026-01-25T23:39:11.060668+00:00", "data": {"market": "0x755a62c90339cdf3468fab177c6bfd9dceb5e45203e68bf069b50303a6abd25f", "price_changes": [{"asset_id": "78909895416168898474213741912660947562122027739865278774230819696266961515246", "price": "0.05", "size": "0", "side": "BUY", "hash": "065334b545a148f7aeec20bc137df5e95e8d187c", "best_bid": "0.06", "best_ask": "0.96"}, {"asset_id": "84460776671731186445015851207745064196399530432412893483409324414283960172444", "price": "0.95", "size": "0", "side": "SELL", "hash": "96c265f04c3a5ee9c0c3ab655278023f49ab8bd3", "best_bid": "0.04", "best_ask": "0.94"}], "timestamp": "1769384350997", "event_type": "price_change"}}
{"_local_timestamp": "2026-01-25T23:39:11.072257+00:00", "data": {"market": "0xa2945f80a0c041b15c57a16539369873a31aae20c028d50efc9f4fe4c46f9973", "price_changes": [{"asset_id": "45622453771453949816894791094505340162140487852041488561027748414607473630122", "price": "0.05", "size": "0", "side": "BUY", "hash": "2b32dae1d4a33c3bdd6f4e866107cda59e2f32c2", "best_bid": "0.06", "best_ask": "0.96"}, {"asset_id": "36376479227210509138719694118857362983085092412966657890412021289097812996653", "price": "0.95", "size": "0", "side": "SELL", "hash": "1a0c5fe1d5bc46bccdc008868c8ac96ba07f76cf", "best_bid": "0.04", "best_ask": "0.94"}], "timestamp": "1769384350997", "event_type": "price_change"}}
{"_local_timestamp": "2026-01-25T23:39:11.073146+00:00", "data": {"market": "0xa9e485d9ab8973f5683fc4992b591ab9997052b8d7acc5d800d197e95ba0f5ee", "price_changes": [{"asset_id": "52957896528748198044120161866858084167956853408096664478472083379802465908152", "price": "0.05", "size": "0", "side": "BUY", "hash": "91a8962ec1087cbdb2daf6d7c9f134d7e62e26a5", "best_bid": "0.06", "best_ask": "0.96"}, {"asset_id": "42963846885724327117066696479449241735482257984315608228983457680056285716377", "price": "0.95", "size": "0", "side": "SELL", "hash": "4ba2b2ddf69ef58f73dc901f7a8a4b76bceecf71", "best_bid": "0.04", "best_ask": "0.94"}], "timestamp": "1769384350997", "event_type": "price_change"}}
{"_local_timestamp": "2026-01-25T23:39:11.074679+00:00", "data": {"market": "0x887d9af4bfb28d239e7ed0c69ff91d84ece92a11b58984d0ff0393c0c24a2d01", "price_changes": [{"asset_id": "91500912612677572060291806454710032668881503701184797906037737191617363298512", "price": "0.05", "size": "0", "side": "BUY", "hash": "2b8680d25c88597ea2322e77bc34aa10f3f67ab3", "best_bid": "0.06", "best_ask": "0.96"}, {"asset_id": "53797474885844189083818567441605903163912505725772675434705257100199647449827", "price": "0.95", "size": "0", "side": "SELL", "hash": "89b410425a0818404df53fe2590268808a42c9f9", "best_bid": "0.04", "best_ask": "0.94"}], "timestamp": "1769384350997", "event_type": "price_change"}}
{"_local_timestamp": "2026-01-25T23:39:11.176506+00:00", "data": {"market": "0xca130e51e4406596d098557a80d3fa6e95eb16d32ef09d08d20da8b7ab6d6298", "price_changes": [{"asset_id": "35965820443596672753502165079905474159071605177387618189868308759415426382973", "price": "0.05", "size": "0", "side": "BUY", "hash": "de4a755e52d7217cb8b0bd9fad38604a5f6b94da", "best_bid": "0.06", "best_ask": "0.96"}, {"asset_id": "9877937220298673394222737478141754783632484432479493143738647510821851680044", "price": "0.95", "size": "0", "side": "SELL", "hash": "5735a873a8456eb46a5bf1ea61e918145b6aa094", "best_bid": "0.04", "best_ask": "0.94"}], "timestamp": "1769384351102", "event_type": "price_change"}}
{"_local_timestamp": "2026-01-25T23:39:11.661211+00:00", "data": {"market": "0x0e43c388a48dda26db3c52eb9813ea91188aea3b296595b6e4bbe4c21d8084b0", "price_changes": [{"asset_id": "102511604076257806476238809539017003625339720903982467852262014324396343577525", "price": "0.05", "size": "23.99", "side": "BUY", "hash": "49dd4f7f07a3b2d488deb36ec80ae2b0b458b6fa", "best_bid": "0.05", "best_ask": "0.96"}, {"asset_id": "34585893689836828365103711114049969648303333079217680891554537778358996709791", "price": "0.95", "size": "23.99", "side": "SELL", "hash": "cf417492974f0605b2c14bce2829a8cb2bd27e43", "best_bid": "0.04", "best_ask": "0.95"}], "timestamp": "1769384351594", "event_type": "price_change"}}
{"_local_timestamp": "2026-01-25T23:39:15.153649+00:00", "data": {"market": "0xca130e51e4406596d098557a80d3fa6e95eb16d32ef09d08d20da8b7ab6d6298", "price_changes": [{"asset_id": "35965820443596672753502165079905474159071605177387618189868308759415426382973", "price": "0.06", "size": "0", "side": "BUY", "hash": "fa627f350e114fd5c17060c0973c61ae7ae98db5", "best_bid": "0.03", "best_ask": "0.96"}, {"asset_id": "9877937220298673394222737478141754783632484432479493143738647510821851680044", "price": "0.94", "size": "0", "side": "SELL", "hash": "490b4a39a4ecb97ec952c4ee3b3b28661d85b8c4", "best_bid": "0.04", "best_ask": "0.97"}], "timestamp": "1769384355032", "event_type": "price_change"}}
{"_local_timestamp": "2026-01-25T23:39:15.154336+00:00", "data": {"market": "0x755a62c90339cdf3468fab177c6bfd9dceb5e45203e68bf069b50303a6abd25f", "price_changes": [{"asset_id": "78909895416168898474213741912660947562122027739865278774230819696266961515246", "price": "0.06", "size": "0", "side": "BUY", "hash": "0960514431842ce1da7e0d8762ca757609baeac4", "best_bid": "0.03", "best_ask": "0.96"}, {"asset_id": "84460776671731186445015851207745064196399530432412893483409324414283960172444", "price": "0.94", "size": "0", "side": "SELL", "hash": "eeaab9e8cca0297c5fdece4ac14d28e9fcf23425", "best_bid": "0.04", "best_ask": "0.97"}], "timestamp": "1769384355032", "event_type": "price_change"}}
{"_local_timestamp": "2026-01-25T23:39:15.154920+00:00", "data": {"market": "0x0c35017fce45618791b247a0e015a99dfdaa11fce35665f46a21329c75539bf5", "price_changes": [{"asset_id": "91719725116883012291565512161477775996897243486374553084185529876278409496454", "price": "0.06", "size": "0", "side": "BUY", "hash": "5480de1efeae78d50078c94bf71c61e7c0858f15", "best_bid": "0.03", "best_ask": "0.96"}, {"asset_id": "113869036122116896359974222126121258669445902300788141703831662654178658580719", "price": "0.94", "size": "0", "side": "SELL", "hash": "5b58999c17b725bb138ffae4824fd8727531f0f7", "best_bid": "0.04", "best_ask": "0.97"}], "timestamp": "1769384355032", "event_type": "price_change"}}
{"_local_timestamp": "2026-01-25T23:39:15.155438+00:00", "data": {"market": "0xa9e485d9ab8973f5683fc4992b591ab9997052b8d7acc5d800d197e95ba0f5ee", "price_changes": [{"asset_id": "52957896528748198044120161866858084167956853408096664478472083379802465908152", "price": "0.06", "size": "0", "side": "BUY", "hash": "928b325a25762129b9c70c473f3a37740eb60625", "best_bid": "0.03", "best_ask": "0.96"}, {"asset_id": "42963846885724327117066696479449241735482257984315608228983457680056285716377", "price": "0.94", "size": "0", "side": "SELL", "hash": "7f8c3857485696525571a0f703c8300467225e69", "best_bid": "0.04", "best_ask": "0.97"}], "timestamp": "1769384355032", "event_type": "price_change"}}
{"_local_timestamp": "2026-01-25T23:39:15.155952+00:00", "data": {"market": "0xa2945f80a0c041b15c57a16539369873a31aae20c028d50efc9f4fe4c46f9973", "price_changes": [{"asset_id": "45622453771453949816894791094505340162140487852041488561027748414607473630122", "price": "0.06", "size": "0", "side": "BUY", "hash": "4165a96d3c6f9a0d1095bdca27f62d1732bab7b1", "best_bid": "0.03", "best_ask": "0.96"}, {"asset_id": "36376479227210509138719694118857362983085092412966657890412021289097812996653", "price": "0.94", "size": "0", "side": "SELL", "hash": "9a8140a847460a9911911463cf74d846489bd413", "best_bid": "0.04", "best_ask": "0.97"}], "timestamp": "1769384355032", "event_type": "price_change"}}
{"_local_timestamp": "2026-01-25T23:39:15.156493+00:00", "data": {"market": "0x754ef6f17592b0ef700ddd256368d8a853e1b2608d801cbd10bb8867943feb51", "price_changes": [{"asset_id": "58817089064209115360537822581951729680659415067098716481850517826996528126939", "price": "0.06", "size": "0", "side": "BUY", "hash": "4d7b6b8ef8277759d14c65f15698ce7882fdccc0", "best_bid": "0.03", "best_ask": "0.96"}, {"asset_id": "100119332257398155495950907520135487242937804051607670301581332334796358396713", "price": "0.94", "size": "0", "side": "SELL", "hash": "47ee068bb9442e1ddb12ccc4912e59c1a12726ee", "best_bid": "0.04", "best_ask": "0.97"}], "timestamp": "1769384355032", "event_type": "price_change"}}
{"_local_timestamp": "2026-01-25T23:39:15.159538+00:00", "data": {"market": "0x0e43c388a48dda26db3c52eb9813ea91188aea3b296595b6e4bbe4c21d8084b0", "price_changes": [{"asset_id": "102511604076257806476238809539017003625339720903982467852262014324396343577525", "price": "0.04", "size": "0", "side": "BUY", "hash": "8e5e48b93f9403df5a23ed23ff3197f55bfeac5c", "best_bid": "0.05", "best_ask": "0.96"}, {"asset_id": "34585893689836828365103711114049969648303333079217680891554537778358996709791", "price": "0.96", "size": "0", "side": "SELL", "hash": "bbbefb6182a550123c2da88751bcccbd74cfca94", "best_bid": "0.04", "best_ask": "0.95"}], "timestamp": "1769384355032", "event_type": "price_change"}}
{"_local_timestamp": "2026-01-25T23:39:15.175201+00:00", "data": {"market": "0x83ecbe4fce688c64f4b5d4befac5e64922cb8682e0e1365fc0468ff533c71e49", "price_changes": [{"asset_id": "68037078242557231080288874617522547606466154419149083356555127918659292747130", "price": "0.06", "size": "0", "side": "BUY", "hash": "99377cf7ccff4c261fc0dee59a3e9f3a2166451d", "best_bid": "0.03", "best_ask": "0.96"}, {"asset_id": "105434914828600935285428845047491083161332333045327551979231234346212907811414", "price": "0.94", "size": "0", "side": "SELL", "hash": "cb3a288863f781e0ddb6a1d8e45cf203edba238a", "best_bid": "0.04", "best_ask": "0.97"}], "timestamp": "1769384355032", "event_type": "price_change"}}
{"_local_timestamp": "2026-01-25T23:39:15.175809+00:00", "data": {"market": "0x887d9af4bfb28d239e7ed0c69ff91d84ece92a11b58984d0ff0393c0c24a2d01", "price_changes": [{"asset_id": "91500912612677572060291806454710032668881503701184797906037737191617363298512", "price": "0.06", "size": "0", "side": "BUY", "hash": "3f03e59264b1d417b372a7ea1561e3da4599adce", "best_bid": "0.03", "best_ask": "0.96"}, {"asset_id": "53797474885844189083818567441605903163912505725772675434705257100199647449827", "price": "0.94", "size": "0", "side": "SELL", "hash": "a3a81d2c891bc1d3eb764a6d32bd0801164201fe", "best_bid": "0.04", "best_ask": "0.97"}], "timestamp": "1769384355032", "event_type": "price_change"}}
{"_local_timestamp": "2026-01-25T23:39:15.338853+00:00", "data": {"market": "0x0c35017fce45618791b247a0e015a99dfdaa11fce35665f46a21329c75539bf5", "price_changes": [{"asset_id": "91719725116883012291565512161477775996897243486374553084185529876278409496454", "price": "0.04", "size": "5.47", "side": "BUY", "hash": "8f61088e757631068f5b001b508738cba4d17e44", "best_bid": "0.04", "best_ask": "0.96"}, {"asset_id": "113869036122116896359974222126121258669445902300788141703831662654178658580719", "price": "0.96", "size": "5.47", "side": "SELL", "hash": "9a97d8306fbaf65ea8db7e2c3e59a21b911a8578", "best_bid": "0.04", "best_ask": "0.96"}], "timestamp": "1769384355272", "event_type": "price_change"}}
{"_local_timestamp": "2026-01-25T23:39:15.339506+00:00", "data": {"market": "0xa9e485d9ab8973f5683fc4992b591ab9997052b8d7acc5d800d197e95ba0f5ee", "price_changes": [{"asset_id": "52957896528748198044120161866858084167956853408096664478472083379802465908152", "price": "0.04", "size": "5.47", "side": "BUY", "hash": "e4fb056f0dab46779843d557860cff3787df0b1c", "best_bid": "0.04", "best_ask": "0.96"}, {"asset_id": "42963846885724327117066696479449241735482257984315608228983457680056285716377", "price": "0.96", "size": "5.47", "side": "SELL", "hash": "553199232b918dd2dddbb152d1d92d3cd27529b5", "best_bid": "0.04", "best_ask": "0.96"}], "timestamp": "1769384355272", "event_type": "price_change"}}
{"_local_timestamp": "2026-01-25T23:39:15.390766+00:00", "data": {"market": "0xa2945f80a0c041b15c57a16539369873a31aae20c028d50efc9f4fe4c46f9973", "price_changes": [{"asset_id": "45622453771453949816894791094505340162140487852041488561027748414607473630122", "price": "0.04", "size": "5.47", "side": "BUY", "hash": "82b68e325300ce352846a668c9d429ca692fb8b9", "best_bid": "0.04", "best_ask": "0.96"}, {"asset_id": "36376479227210509138719694118857362983085092412966657890412021289097812996653", "price": "0.96", "size": "5.47", "side": "SELL", "hash": "36f287f36ce9c929a2aec28a8b107203040c96e4", "best_bid": "0.04", "best_ask": "0.96"}], "timestamp": "1769384355316", "event_type": "price_change"}}
{"_local_timestamp": "2026-01-25T23:39:15.391372+00:00", "data": {"market": "0x83ecbe4fce688c64f4b5d4befac5e64922cb8682e0e1365fc0468ff533c71e49", "price_changes": [{"asset_id": "68037078242557231080288874617522547606466154419149083356555127918659292747130", "price": "0.04", "size": "5.47", "side": "BUY", "hash": "35bef312469fec2811daea2521017049bc650541", "best_bid": "0.04", "best_ask": "0.96"}, {"asset_id": "105434914828600935285428845047491083161332333045327551979231234346212907811414", "price": "0.96", "size": "5.47", "side": "SELL", "hash": "392de49c9b5e996771438a5ac62f89d9c422bfb9", "best_bid": "0.04", "best_ask": "0.96"}], "timestamp": "1769384355316", "event_type": "price_change"}}
{"_local_timestamp": "2026-01-25T23:39:15.391937+00:00", "data": {"market": "0x755a62c90339cdf3468fab177c6bfd9dceb5e45203e68bf069b50303a6abd25f", "price_changes": [{"asset_id": "78909895416168898474213741912660947562122027739865278774230819696266961515246", "price": "0.04", "size": "5.47", "side": "BUY", "hash": "868123b6551e0998406b9ff0956a5801dbf77981", "best_bid": "0.04", "best_ask": "0.96"}, {"asset_id": "84460776671731186445015851207745064196399530432412893483409324414283960172444", "price": "0.96", "size": "5.47", "side": "SELL", "hash": "56076f51254ce67ec5020230bdd9ee89e75f507a", "best_bid": "0.04", "best_ask": "0.96"}], "timestamp": "1769384355316", "event_type": "price_change"}}
{"_local_timestamp": "2026-01-25T23:39:15.392455+00:00", "data": {"market": "0x887d9af4bfb28d239e7ed0c69ff91d84ece92a11b58984d0ff0393c0c24a2d01", "price_changes": [{"asset_id": "91500912612677572060291806454710032668881503701184797906037737191617363298512", "price": "0.04", "size": "5.47", "side": "BUY", "hash": "2d8d8ef0117c9fd078b619a3aab55781b6e086bf", "best_bid": "0.04", "best_ask": "0.96"}, {"asset_id": "53797474885844189083818567441605903163912505725772675434705257100199647449827", "price": "0.96", "size": "5.47", "side": "SELL", "hash": "0bfa743ded6959b70e2fab9c1dc7735e2ef0af18", "best_bid": "0.04", "best_ask": "0.96"}], "timestamp": "1769384355316", "event_type": "price_change"}}
{"_local_timestamp": "2026-01-25T23:39:15.393003+00:00", "data": {"market": "0x0e43c388a48dda26db3c52eb9813ea91188aea3b296595b6e4bbe4c21d8084b0", "price_changes": [{"asset_id": "102511604076257806476238809539017003625339720903982467852262014324396343577525", "price": "0.06", "size": "5.47", "side": "BUY", "hash": "91092d932ba45a6ea333af8490fb1a2a2064d15d", "best_bid": "0.06", "best_ask": "0.96"}, {"asset_id": "34585893689836828365103711114049969648303333079217680891554537778358996709791", "price": "0.94", "size": "5.47", "side": "SELL", "hash": "ccc76ec4d3a6436961e80cb195136332beaebaa0", "best_bid": "0.04", "best_ask": "0.94"}], "timestamp": "1769384355316", "event_type": "price_change"}}
{"_local_timestamp": "2026-01-25T23:39:15.393537+00:00", "data": {"market": "0x754ef6f17592b0ef700ddd256368d8a853e1b2608d801cbd10bb8867943feb51", "price_changes": [{"asset_id": "58817089064209115360537822581951729680659415067098716481850517826996528126939", "price": "0.04", "size": "5.47", "side": "BUY", "hash": "f9785cd33bbfbb50dbc39a36fe34112e953d27b7", "best_bid": "0.04", "best_ask": "0.96"}, {"asset_id": "100119332257398155495950907520135487242937804051607670301581332334796358396713", "price": "0.96", "size": "5.47", "side": "SELL", "hash": "5f3a95ba52c5b0a4f84857ad9b881cb581149605", "best_bid": "0.04", "best_ask": "0.96"}], "timestamp": "1769384355316", "event_type": "price_change"}}
{"_local_timestamp": "2026-01-25T23:39:15.394101+00:00", "data": {"market": "0xca130e51e4406596d098557a80d3fa6e95eb16d32ef09d08d20da8b7ab6d6298", "price_changes": [{"asset_id": "35965820443596672753502165079905474159071605177387618189868308759415426382973", "price": "0.04", "size": "5.47", "side": "BUY", "hash": "56bea76a5e3e6c6438d796c5a75d7139b6cecbb1", "best_bid": "0.04", "best_ask": "0.96"}, {"asset_id": "9877937220298673394222737478141754783632484432479493143738647510821851680044", "price": "0.96", "size": "5.47", "side": "SELL", "hash": "fb1304d3c0e29edc77de9e9799a6e8934f238e86", "best_bid": "0.04", "best_ask": "0.96"}], "timestamp": "1769384355316", "event_type": "price_change"}}
