{"_local_timestamp": "2026-01-25T23:34:23.726989+00:00", "data": [{"market": "0xcb7dc9e8c99d3894e219a6242949729a2d4736f19ee13a21ceefc20a80a0066b", "asset_id": "115788350734693757421027634879142051258958684646271080316220994609154259670413", "timestamp": "1769384040573", "hash": "b6f18d5cae44eaa3bc821857948875bf21be9b80", "bids": [{"price": "0.001", "size": "1027"}, {"price": "0.007", "size": "1000"}, {"price": "0.008", "size": "183.59"}, {"price": "0.013", "size": "16.41"}, {"price": "0.014", "size": "10.94"}, {"price": "0.99", "size": "635"}], "asks": [{"price": "0.999", "size": "1027"}], "event_type": "book", "last_trade_price": "0.010"}, {"market": "0x843d19dfca98ada8c66ebbb4d6fbb173e84553b2683a24a1e00aad0c8453cf90", "asset_id": "58062417896853254930361400136624504371975360911936924777891592824225807309392", "timestamp": "1769383583345", "hash": "e3329b1807fae9c4c1aea472128319dabf91219f", "bids": [{"price": "0.001", "size": "1084.65"}], "asks": [{"price": "0.999", "size": "2057"}, {"price": "0.997", "size": "1000"}, {"price": "0.2", "size": "407.43"}, {"price": "0.199", "size": "5.47"}, {"price": "0.005", "size": "525"}, {"price": "0.004", "size": "55.95"}], "event_type": "book", "last_trade_price": "0.002"}, {"market": "0xc2fcb0f600f10f2ae91dfab9db2698611bf969defd3e2cd5730e5b0568349bac", "asset_id": "72402309101367002301495158185582712104543606023677018896034103067959479089850", "timestamp": "1769384061662", "hash": "5ead3c191881a5ee7f3bc1d9149b5f6984a6eaf0", "bids": [], "asks": [{"price": "0.999", "size": "1065"}, {"price": "0.99", "size": "2600"}, {"price": "0.98", "size": "1000"}, {"price": "0.969", "size": "1100"}, {"price": "0.948", "size": "1700"}, {"price": "0.92", "size": "400"}, {"price": "0.86", "size": "700"}, {"price": "0.777", "size": "38"}, {"price": "0.69", "size": "100"}, {"price": "0.68", "size": "39.99"}, {"price": "0.55", "size": "5.55"}, {"price": "0.477", "size": "283"}, {"price": "0.47", "size": "24.98"}, {"price": "0.277", "size": "142"}, {"price": "0.273", "size": "106.24"}, {"price": "0.177", "size": "214"}, {"price": "0.14", "size": "194.15"}, {"price": "0.08", "size": "97.08"}, {"price": "0.079", "size": "51.66"}, {"price": "0.077", "size": "346"}, {"price": "0.076", "size": "82.23"}, {"price": "0.01", "size": "30.2"}, {"price": "0.009", "size": "45.3"}, {"price": "0.005", "size": "254"}, {"price": "0.004", "size": "634.8"}, {"price": "0.001", "size": "23.9"}], "event_type": "book", "last_trade_price": "0.999"}, {"market": "0x9806d6a5e6e617f978ef8918981422d7c383ece76bd3d53c4018d83f851df7cc", "asset_id": "96874305238055838913572671099974795248962251859827192697616088060794485331788", "timestamp": "1769384057853", "hash": "27136d3df59baae656fe0e441bf901c61b672307", "bids": [{"price": "0.001", "size": "12"}], "asks": [{"price": "0.999", "size": "978"}, {"price": "0.997", "size": "1100"}, {"price": "0.99", "size": "80"}, {"price": "0.97", "size": "100"}, {"price": "0.92", "size": "100"}, {"price": "0.86", "size": "50"}, {"price": "0.8", "size": "200"}, {"price": "0.777", "size": "31"}, {"price": "0.73", "size": "200"}, {"price": "0.66", "size": "100"}, {"price": "0.477", "size": "200"}, {"price": "0.277", "size": "143"}, {"price": "0.177", "size": "216"}, {"price": "0.077", "size": "349"}, {"price": "0.055", "size": "10.56"}, {"price": "0.054", "size": "5.47"}, {"price": "0.003", "size": "1216.9"}], "event_type": "book", "last_trade_price": "0.999"}, {"market": "0x0ca398f4564c38da69591560241e7b50b84045d73a288ee592f84dc307886c9f", "asset_id": "73758297760471023486831469668849801378829920625288067100645749063270684075558", "timestamp": "1769382471302", "hash": "900a63a4f6d68ca3fa729af4bcd95254f3b09d57", "bids": [{"price": "0.001", "size": "1057"}], "asks": [{"price": "0.999", "size": "2057"}, {"price": "0.997", "size": "1000"}, {"price": "0.996", "size": "5.47"}, {"price": "0.02", "size": "119.53"}, {"price": "0.019", "size": "100"}], "event_type": "book", "last_trade_price": "0.010"}, {"market": "0xcb7dc9e8c99d3894e219a6242949729a2d4736f19ee13a21ceefc20a80a0066b", "asset_id": "98485975070324083339941401870090885415947897822976000836314973267692056078647", "timestamp": "1769384040573", "hash": "8ee2d226418c9d552d16d3d786741efaae24571f", "bids": [{"price": "0.001", "size": "1027"}], "asks": [{"price": "0.999", "size": "1027"}, {"price": "0.993", "size": "1000"}, {"price": "0.992", "size": "183.59"}, {"price": "0.987", "size": "16.41"}, {"price": "0.986", "size": "10.94"}, {"price": "0.01", "size": "635"}], "event_type": "book", "last_trade_price": "0.010"}, {"market": "0x841529681a7a5fc77af6ee13187c65bca1400530f81be0328cfff6c19c112cee", "asset_id": "61406926682600289284199037461761473156945342642474137106642230975893372304476", "timestamp": "1769384038923", "hash": "f9cdb9f93d617b0be4f141a7a85d7f7bf2e4986c", "bids": [{"price": "0.001", "size": "1057"}, {"price": "0.007", "size": "1000"}, {"price": "0.008", "size": "200"}, {"price": "0.99", "size": "525"}], "asks": [{"price": "0.999", "size": "1057"}], "event_type": "book", "last_trade_price": "0.010"}, {"market": "0xabd15f50cde2db51b979f59df9f00561de0276a7aed657cdfc01e85c1ff39286", "asset_id": "26830899908225037126738641844177684533967567245513858554892436909273392276503", "timestamp": "1769383986573", "hash": "3dd4d5781868f3f27de97b9484b676ab44839097", "bids": [{"price": "0.001", "size": "30"}, {"price": "0.002", "size": "5.46"}, {"price": "0.99", "size": "30.2"}], "asks": [{"price": "0.999", "size": "28.99"}], "event_type": "book", "last_trade_price": "0.001"}, {"market": "0x841529681a7a5fc77af6ee13187c65bca1400530f81be0328cfff6c19c112cee", "asset_id": "50197395464408075357578095662006421013318644198206473166647680578559551606381", "timestamp": "1769384038923", "hash": "be40fbd7f5bdc46b3a61603f422be6b07e46cad3", "bids": [{"price": "0.001", "size": "1057"}], "asks": [{"price": "0.999", "size": "1057"}, {"price": "0.993", "size": "1000"}, {"price": "0.992", "size": "200"}, {"price": "0.01", "size": "525"}], "event_type": "book", "last_trade_price": "0.010"}, {"market": "0xc2fcb0f600f10f2ae91dfab9db2698611bf969defd3e2cd5730e5b0568349bac", "asset_id": "105107985691308505645208009025026303139432184401049219175851106163376118674274", "timestamp": "1769384061662", "hash": "990b8bf8144de69ba283648d1cf7ec01db5b54c5", "bids": [{"price": "0.001", "size": "1065"}, {"price": "0.01", "size": "2600"}, {"price": "0.02", "size": "1000"}, {"price": "0.031", "size": "1100"}, {"price": "0.052", "size": "1700"}, {"price": "0.08", "size": "400"}, {"price": "0.14", "size": "700"}, {"price": "0.223", "size": "38"}, {"price": "0.31", "size": "100"}, {"price": "0.32", "size": "39.99"}, {"price": "0.45", "size": "5.55"}, {"price": "0.523", "size": "283"}, {"price": "0.53", "size": "24.98"}, {"price": "0.723", "size": "142"}, {"price": "0.727", "size": "106.24"}, {"price": "0.823", "size": "214"}, {"price": "0.86", "size": "194.15"}, {"price": "0.92", "size": "97.08"}, {"price": "0.921", "size": "51.66"}, {"price": "0.923", "size": "346"}, {"price": "0.924", "size": "82.23"}, {"price": "0.99", "size": "30.2"}, {"price": "0.991", "size": "45.3"}, {"price": "0.995", "size": "254"}, {"price": "0.996", "size": "634.8"}, {"price": "0.999", "size": "23.9"}], "asks": [], "event_type": "book", "last_trade_price": "0.999"}, {"market": "0xabd15f50cde2db51b979f59df9f00561de0276a7aed657cdfc01e85c1ff39286", "asset_id": "3108203705467868906332367843117605390000549101094212995448312300029225448526", "timestamp": "1769383986573", "hash": "efb323834e4d3ec17dc334b1b70971c5084b37e0", "bids": [{"price": "0.001", "size": "28.99"}], "asks": [{"price": "0.999", "size": "30"}, {"price": "0.998", "size": "5.46"}, {"price": "0.01", "size": "30.2"}], "event_type": "book", "last_trade_price": "0.001"}, {"market": "0x9806d6a5e6e617f978ef8918981422d7c383ece76bd3d53c4018d83f851df7cc", "asset_id": "4655206770474921299388200827584555181546002874778899522765485382144463583575", "timestamp": "1769384057853", "hash": "32ad0730602ee3df3922f55bc412fc9fb9d8e32c", "bids": [{"price": "0.001", "size": "978"}, {"price": "0.003", "size": "1100"}, {"price": "0.01", "size": "80"}, {"price": "0.03", "size": "100"}, {"price": "0.08", "size": "100"}, {"price": "0.14", "size": "50"}, {"price": "0.2", "size": "200"}, {"price": "0.223", "size": "31"}, {"price": "0.27", "size": "200"}, {"price": "0.34", "size": "100"}, {"price": "0.523", "size": "200"}, {"price": "0.723", "size": "143"}, {"price": "0.823", "size": "216"}, {"price": "0.923", "size": "349"}, {"price": "0.945", "size": "10.56"}, {"price": "0.946", "size": "5.47"}, {"price": "0.997", "size": "1216.9"}], "asks": [{"price": "0.999", "size": "12"}], "event_type": "book", "last_trade_price": "0.999"}, {"market": "0x820082d9062845486d4a143f029c9f93cb9d095fb18f1aa7cda1c44c2bce1188", "asset_id": "70927268883755126554386966675213344514269002069096912114831420016073249520715", "timestamp": "1769384024687", "hash": "41927c58159f1cbae962871f1ce9fa242435115f", "bids": [], "asks": [{"price": "0.999", "size": "958"}, {"price": "0.997", "size": "1100"}, {"price": "0.99", "size": "80"}, {"price": "0.97", "size": "100"}, {"price": "0.92", "size": "100"}, {"price": "0.86", "size": "50"}, {"price": "0.8", "size": "200"}, {"price": "0.777", "size": "32"}, {"price": "0.73", "size": "200"}, {"price": "0.66", "size": "100"}, {"price": "0.477", "size": "201"}, {"price": "0.277", "size": "127"}, {"price": "0.177", "size": "205"}, {"price": "0.077", "size": "353"}, {"price": "0.076", "size": "25"}, {"price": "0.075", "size": "13.86"}, {"price": "0.024", "size": "8.21"}, {"price": "0.023", "size": "5.47"}, {"price": "0.01", "size": "2000"}, {"price": "0.005", "size": "146"}, {"price": "0.001", "size": "4749.73"}], "event_type": "book", "last_trade_price": "0.999"}, {"market": "0x0ca398f4564c38da69591560241e7b50b84045d73a288ee592f84dc307886c9f", "asset_id": "89873108860358159626430606027457644828261102103969814693169391119797511480704", "timestamp": "1769382471302", "hash": "a7ed1a80aa545ec633c5d1f6c283f99f4cb57a9f", "bids": [{"price": "0.001", "size": "2057"}, {"price": "0.003", "size": "1000"}, {"price": "0.004", "size": "5.47"}, {"price": "0.98", "size": "119.53"}, {"price": "0.981", "size": "100"}], "asks": [{"price": "0.999", "size": "1057"}], "event_type": "book", "last_trade_price": "0.010"}, {"market": "0x820082d9062845486d4a143f029c9f93cb9d095fb18f1aa7cda1c44c2bce1188", "asset_id": "23264385912109188517723056029307436593365599986842476104748104553557414072010", "timestamp": "1769384024687", "hash": "a7d2662e9e352b976c2103ad2cf48300c211c2af", "bids": [{"price": "0.001", "size": "958"}, {"price": "0.003", "size": "1100"}, {"price": "0.01", "size": "80"}, {"price": "0.03", "size": "100"}, {"price": "0.08", "size": "100"}, {"price": "0.14", "size": "50"}, {"price": "0.2", "size": "200"}, {"price": "0.223", "size": "32"}, {"price": "0.27", "size": "200"}, {"price": "0.34", "size": "100"}, {"price": "0.523", "size": "201"}, {"price": "0.723", "size": "127"}, {"price": "0.823", "size": "205"}, {"price": "0.923", "size": "353"}, {"price": "0.924", "size": "25"}, {"price": "0.925", "size": "13.86"}, {"price": "0.976", "size": "8.21"}, {"price": "0.977", "size": "5.47"}, {"price": "0.99", "size": "2000"}, {"price": "0.995", "size": "146"}, {"price": "0.999", "size": "4749.73"}], "asks": [], "event_type": "book", "last_trade_price": "0.999"}, {"market": "0x843d19dfca98ada8c66ebbb4d6fbb173e84553b2683a24a1e00aad0c8453cf90", "asset_id": "28615763915408006017271621447513804345732414042393039493947373086352681254494", "timestamp": "1769383583345", "hash": "7fcfa06a236133d6cdc17b890972ebd3e0f40a7a", "bids": [{"price": "0.001", "size": "2057"}, {"price": "0.003", "size": "1000"}, {"price": "0.8", "size": "407.43"}, {"price": "0.801", "size": "5.47"}, {"price": "0.995", "size": "525"}, {"price": "0.996", "size": "55.95"}], "asks": [{"price": "0.999", "size": "1084.65"}], "event_type": "book", "last_trade_price": "0.002"}, {"market": "0xfe2e85f6fca36e8b864be64b48521ccd513c336427bbbccfba39b5be2da560aa", "asset_id": "69403394007873424681005155433420327969196546299861361174702151771312033239993", "timestamp": "1769384023374", "hash": "d5a23a002aabc8245e7085a48021dca70c9b86b5", "bids": [{"price": "0.001", "size": "99999"}, {"price": "0.002", "size": "55000"}, {"price": "0.008", "size": "155"}, {"price": "0.01", "size": "18000"}, {"price": "0.011", "size": "55710"}, {"price": "0.02", "size": "1000"}, {"price": "0.031", "size": "10100"}, {"price": "0.04", "size": "2000"}, {"price": "0.08", "size": "155"}, {"price": "0.097", "size": "100"}, {"price": "0.099", "size": "100"}, {"price": "0.1", "size": "500"}, {"price": "0.101", "size": "10100"}, {"price": "0.102", "size": "5000"}, {"price": "0.11", "size": "3000"}, {"price": "0.14", "size": "50"}, {"price": "0.201", "size": "4600"}, {"price": "0.27", "size": "200"}, {"price": "0.34", "size": "100"}, {"price": "0.47", "size": "100"}, {"price": "0.49", "size": "100"}, {"price": "0.497", "size": "100"}, {"price": "0.499", "size": "500"}, {"price": "0.5", "size": "440"}, {"price": "0.75", "size": "60"}, {"price": "0.767", "size": "60"}, {"price": "0.768", "size": "53"}, {"price": "0.769", "size": "60"}, {"price": "0.77", "size": "60"}, {"price": "0.818", "size": "59"}, {"price": "0.819", "size": "67.4"}, {"price": "0.835", "size": "8.2"}, {"price": "0.836", "size": "5.47"}, {"price": "0.99", "size": "15.1"}, {"price": "0.991", "size": "500"}, {"price": "0.995", "size": "25"}, {"price": "0.996", "size": "1200"}, {"price": "0.999", "size": "3545"}], "asks": [], "event_type": "book", "last_trade_price": "0.999"}, {"market": "0xfe2e85f6fca36e8b864be64b48521ccd513c336427bbbccfba39b5be2da560aa", "asset_id": "48015311421026063012985711082782647083417221141101598875055317979379805670690", "timestamp": "1769384023374", "hash": "5f5269bbe187890dd2f4fb8208317fd34b1d96bd", "bids": [], "asks": [{"price": "0.999", "size": "99999"}, {"price": "0.998", "size": "55000"}, {"price": "0.992", "size": "155"}, {"price": "0.99", "size": "18000"}, {"price": "0.989", "size": "55710"}, {"price": "0.98", "size": "1000"}, {"price": "0.969", "size": "10100"}, {"price": "0.96", "size": "2000"}, {"price": "0.92", "size": "155"}, {"price": "0.903", "size": "100"}, {"price": "0.901", "size": "100"}, {"price": "0.9", "size": "500"}, {"price": "0.899", "size": "10100"}, {"price": "0.898", "size": "5000"}, {"price": "0.89", "size": "3000"}, {"price": "0.86", "size": "50"}, {"price": "0.799", "size": "4600"}, {"price": "0.73", "size": "200"}, {"price": "0.66", "size": "100"}, {"price": "0.53", "size": "100"}, {"price": "0.51", "size": "100"}, {"price": "0.503", "size": "100"}, {"price": "0.501", "size": "500"}, {"price": "0.5", "size": "440"}, {"price": "0.25", "size": "60"}, {"price": "0.233", "size": "60"}, {"price": "0.232", "size": "53"}, {"price": "0.231", "size": "60"}, {"price": "0.23", "size": "60"}, {"price": "0.182", "size": "59"}, {"price": "0.181", "size": "67.4"}, {"price": "0.165", "size": "8.2"}, {"price": "0.164", "size": "5.47"}, {"price": "0.01", "size": "15.1"}, {"price": "0.009", "size": "500"}, {"price": "0.005", "size": "25"}, {"price": "0.004", "size": "1200"}, {"price": "0.001", "size": "3545"}], "event_type": "book", "last_trade_price": "0.999"}]}
{"_local_timestamp": "2026-01-25T23:34:42.052217+00:00", "data": {"market": "0xfe2e85f6fca36e8b864be64b48521ccd513c336427bbbccfba39b5be2da560aa", "price_changes": [{"asset_id": "69403394007873424681005155433420327969196546299861361174702151771312033239993", "price": "0.111", "size": "4400", "side": "BUY", "hash": "af147b4029b96c037bf070aae58d6ca3ac728ca5", "best_bid": "0.999", "best_ask": "1"}, {"asset_id": "48015311421026063012985711082782647083417221141101598875055317979379805670690", "price": "0.889", "size": "4400", "side": "SELL", "hash": "c2561acd147e38ee7a4978c3171fbe3b0257975b", "best_bid": "0", "best_ask": "0.001"}], "timestamp": "1769384081983", "event_type": "price_change"}}
{"_local_timestamp": "2026-01-25T23:34:43.667049+00:00", "data": {"market": "0xfe2e85f6fca36e8b864be64b48521ccd513c336427bbbccfba39b5be2da560aa", "price_changes": [{"asset_id": "69403394007873424681005155433420327969196546299861361174702151771312033239993", "price": "0.82", "size": "59", "side": "BUY", "hash": "44167f34e5e7262d75b0dceeea0fd44e6bb305ee", "best_bid": "0.999", "best_ask": "1"}, {"asset_id": "48015311421026063012985711082782647083417221141101598875055317979379805670690", "price": "0.18", "size": "59", "side": "SELL", "hash": "9967108ee879aa515e2b57785bc9bb81f1d20d76", "best_bid": "0", "best_ask": "0.001"}], "timestamp": "1769384083579", "event_type": "price_change"}}
{"_local_timestamp": "2026-01-25T23:34:45.121323+00:00", "data": {"market": "0xfe2e85f6fca36e8b864be64b48521ccd513c336427bbbccfba39b5be2da560aa", "price_changes": [{"asset_id": "69403394007873424681005155433420327969196546299861361174702151771312033239993", "price": "0.818", "size": "0", "side": "BUY", "hash": "5542b2224705170dc2ff26d1986aa03b59063351", "best_bid": "0.999", "best_ask": "1"}, {"asset_id": "48015311421026063012985711082782647083417221141101598875055317979379805670690", "price": "0.182", "size": "0", "side": "SELL", "hash": "e33ca5047033068f68d5536b3b98d56289f03dd5", "best_bid": "0", "best_ask": "0.001"}], "timestamp": "1769384085009", "event_type": "price_change"}}
{"_local_timestamp": "2026-01-25T23:34:46.329366+00:00", "data": {"market": "0xfe2e85f6fca36e8b864be64b48521ccd513c336427bbbccfba39b5be2da560aa", "price_changes": [{"asset_id": "69403394007873424681005155433420327969196546299861361174702151771312033239993", "price": "0.201", "size": "200", "side": "BUY", "hash": "7e0252c76e4427a64385267c38bfdf76a4d915d8", "best_bid": "0.999", "best_ask": "1"}, {"asset_id": "48015311421026063012985711082782647083417221141101598875055317979379805670690", "price": "0.799", "size": "200", "side": "SELL", "hash": "5749ce53a2e7df4c39fd23509927142da6fab322", "best_bid": "0", "best_ask": "0.001"}], "timestamp": "1769384086261", "event_type": "price_change"}}
{"_local_timestamp": "2026-01-25T23:34:58.461049+00:00", "data": {"market": "0xfe2e85f6fca36e8b864be64b48521ccd513c336427bbbccfba39b5be2da560aa", "price_changes": [{"asset_id": "69403394007873424681005155433420327969196546299861361174702151771312033239993", "price": "0.101", "size": "10000", "side": "BUY", "hash": "6f0ec31ffbbc12228b240017f1c5b534b8b8ebc5", "best_bid": "0.999", "best_ask": "1"}, {"asset_id": "48015311421026063012985711082782647083417221141101598875055317979379805670690", "price": "0.899", "size": "10000", "side": "SELL", "hash": "20c7f034701c4bd0a3a80bdf6575a8142249cfb5", "best_bid": "0", "best_ask": "0.001"}], "timestamp": "1769384098380", "event_type": "price_change"}}
{"_local_timestamp": "2026-01-25T23:34:58.766664+00:00", "data": {"market": "0xfe2e85f6fca36e8b864be64b48521ccd513c336427bbbccfba39b5be2da560aa", "price_changes": [{"asset_id": "69403394007873424681005155433420327969196546299861361174702151771312033239993", "price": "0.111", "size": "4500", "side": "BUY", "hash": "b2b5015d9583d3db3da5ff0f018f6632c9906d00", "best_bid": "0.999", "best_ask": "1"}, {"asset_id": "48015311421026063012985711082782647083417221141101598875055317979379805670690", "price": "0.889", "size": "4500", "side": "SELL", "hash": "4cb1e6c10ac7ef3b92f1dba8352efe50cb488914", "best_bid": "0", "best_ask": "0.001"}], "timestamp": "1769384098684", "event_type": "price_change"}}
{"_local_timestamp": "2026-01-25T23:35:14.078565+00:00", "data": {"market": "0x843d19dfca98ada8c66ebbb4d6fbb173e84553b2683a24a1e00aad0c8453cf90", "price_changes": [{"asset_id": "28615763915408006017271621447513804345732414042393039493947373086352681254494", "price": "0.999", "size": "1057", "side": "SELL", "hash": "57700fea24b7675753ecb5748ad1ca67dfa3ec2b", "best_bid": "0.996", "best_ask": "0.999"}, {"asset_id": "58062417896853254930361400136624504371975360911936924777891592824225807309392", "price": "0.001", "size": "1057", "side": "BUY", "hash": "d97bc441e654d0be7c21e58d7401d88ffffb0d7c", "best_bid": "0.001", "best_ask": "0.004"}], "timestamp": "1769384114009", "event_type": "price_change"}}
{"_local_timestamp": "2026-01-25T23:35:15.449400+00:00", "data": {"market": "0xfe2e85f6fca36e8b864be64b48521ccd513c336427bbbccfba39b5be2da560aa", "price_changes": [{"asset_id": "69403394007873424681005155433420327969196546299861361174702151771312033239993", "price": "0.201", "size": "0", "side": "BUY", "hash": "0fc107e46cf68bbdca26207150d14ca893213c30", "best_bid": "0.999", "best_ask": "1"}, {"asset_id": "48015311421026063012985711082782647083417221141101598875055317979379805670690", "price": "0.799", "size": "0", "side": "SELL", "hash": "10212e29d824211666eb5c33d0955a1b58efdcda", "best_bid": "0", "best_ask": "0.001"}], "timestamp": "1769384115382", "event_type": "price_change"}}
{"_local_timestamp": "2026-01-25T23:35:15.746920+00:00", "data": {"market": "0xfe2e85f6fca36e8b864be64b48521ccd513c336427bbbccfba39b5be2da560aa", "price_changes": [{"asset_id": "69403394007873424681005155433420327969196546299861361174702151771312033239993", "price": "0.2", "size": "200", "side": "BUY", "hash": "29076c3464f0a53d8fcc5738af07df77b11492d9", "best_bid": "0.999", "best_ask": "1"}, {"asset_id": "48015311421026063012985711082782647083417221141101598875055317979379805670690", "price": "0.8", "size": "200", "side": "SELL", "hash": "b3c276ddafcc84d010ddf07eeac97986e81d6472", "best_bid": "0", "best_ask": "0.001"}], "timestamp": "1769384115676", "event_type": "price_change"}}
{"_local_timestamp": "2026-01-25T23:37:04.682679+00:00", "data": {"market": "0x843d19dfca98ada8c66ebbb4d6fbb173e84553b2683a24a1e00aad0c8453cf90", "price_changes": [{"asset_id": "28615763915408006017271621447513804345732414042393039493947373086352681254494", "price": "0.999", "size": "1084.65", "side": "SELL", "hash": "926d6706fd75dfbd5255a2d4a3f0040f9995fa70", "best_bid": "0.996", "best_ask": "0.999"}, {"asset_id": "58062417896853254930361400136624504371975360911936924777891592824225807309392", "price": "0.001", "size": "1084.65", "side": "BUY", "hash": "3260349677cf3f0579517f225792e0fc2a4f79b3", "best_bid": "0.001", "best_ask": "0.004"}], "timestamp": "1769384224508", "event_type": "price_change"}}
{"_local_timestamp": "2026-01-25T23:37:21.558854+00:00", "data": {"market": "0x841529681a7a5fc77af6ee13187c65bca1400530f81be0328cfff6c19c112cee", "price_changes": [{"asset_id": "61406926682600289284199037461761473156945342642474137106642230975893372304476", "price": "0.007", "size": "0", "side": "BUY", "hash": "fb9163c164ab32ed3a0f4e1731f54d5126ad8e32", "best_bid": "0.99", "best_ask": "0.999"}, {"asset_id": "50197395464408075357578095662006421013318644198206473166647680578559551606381", "price": "0.993", "size": "0", "side": "SELL", "hash": "00c47640ce1649382c79a59a95d8c5e716f92bf8", "best_bid": "0.001", "best_ask": "0.01"}], "timestamp": "1769384241490", "event_type": "price_change"}}
{"_local_timestamp": "2026-01-25T23:37:21.566419+00:00", "data": {"market": "0xcb7dc9e8c99d3894e219a6242949729a2d4736f19ee13a21ceefc20a80a0066b", "price_changes": [{"asset_id": "115788350734693757421027634879142051258958684646271080316220994609154259670413", "price": "0.007", "size": "0", "side": "BUY", "hash": "14478accdaae207107371d731d922da0e4754e85", "best_bid": "0.99", "best_ask": "0.999"}, {"asset_id": "98485975070324083339941401870090885415947897822976000836314973267692056078647", "price": "0.993", "size": "0", "side": "SELL", "hash": "f532228418dfd2f61becf1902654289926319e2a", "best_bid": "0.001", "best_ask": "0.01"}], "timestamp": "1769384241490", "event_type": "price_change"}}
{"_local_timestamp": "2026-01-25T23:37:21.876016+00:00", "data": {"market": "0x841529681a7a5fc77af6ee13187c65bca1400530f81be0328cfff6c19c112cee", "price_changes": [{"asset_id": "61406926682600289284199037461761473156945342642474137106642230975893372304476", "price": "0.008", "size": "1200", "side": "BUY", "hash": "67b0a9c606743846a7e0fc40ecbd0e163e7f4296", "best_bid": "0.99", "best_ask": "0.999"}, {"asset_id": "50197395464408075357578095662006421013318644198206473166647680578559551606381", "price": "0.992", "size": "1200", "side": "SELL", "hash": "5d28f2ca36f824def0957e705b0254b6274becbf", "best_bid": "0.001", "best_ask": "0.01"}], "timestamp": "1769384241784", "event_type": "price_change"}}
{"_local_timestamp": "2026-01-25T23:37:21.886921+00:00", "data": {"market": "0xcb7dc9e8c99d3894e219a6242949729a2d4736f19ee13a21ceefc20a80a0066b", "price_changes": [{"asset_id": "115788350734693757421027634879142051258958684646271080316220994609154259670413", "price": "0.008", "size": "1183.59", "side": "BUY", "hash": "9aa302fee52071233f8805c30a37eb79800234f1", "best_bid": "0.99", "best_ask": "0.999"}, {"asset_id": "98485975070324083339941401870090885415947897822976000836314973267692056078647", "price": "0.992", "size": "1183.59", "side": "SELL", "hash": "0b7be884358ee7ffdd03318f1b64010dc3b52c23", "best_bid": "0.001", "best_ask": "0.01"}], "timestamp": "1769384241793", "event_type": "price_change"}}
{"_local_timestamp": "2026-01-25T23:38:41.629340+00:00", "data": {"market": "0xfe2e85f6fca36e8b864be64b48521ccd513c336427bbbccfba39b5be2da560aa", "price_changes": [{"asset_id": "48015311421026063012985711082782647083417221141101598875055317979379805670690", "price": "0.165", "size": "0", "side": "SELL", "hash": "35a7a9bcc1e67c1c1727f6c5b7053286f6596f91", "best_bid": "0", "best_ask": "0.001"}, {"asset_id": "69403394007873424681005155433420327969196546299861361174702151771312033239993", "price": "0.835", "size": "0", "side": "BUY", "hash": "b82b4177cbbf2070cc425689b3411ef97786f089", "best_bid": "0.999", "best_ask": "1"}], "timestamp": "1769384321525", "event_type": "price_change"}}
{"_local_timestamp": "2026-01-25T23:38:41.629992+00:00", "data": {"market": "0xfe2e85f6fca36e8b864be64b48521ccd513c336427bbbccfba39b5be2da560aa", "price_changes": [{"asset_id": "48015311421026063012985711082782647083417221141101598875055317979379805670690", "price": "0.181", "size": "0", "side": "SELL", "hash": "35a7a9bcc1e67c1c1727f6c5b7053286f6596f91", "best_bid": "0", "best_ask": "0.001"}, {"asset_id": "69403394007873424681005155433420327969196546299861361174702151771312033239993", "price": "0.819", "size": "0", "side": "BUY", "hash": "b82b4177cbbf2070cc425689b3411ef97786f089", "best_bid": "0.999", "best_ask": "1"}], "timestamp": "1769384321525", "event_type": "price_change"}}
{"_local_timestamp": "2026-01-25T23:38:41.914909+00:00", "data": {"market": "0xfe2e85f6fca36e8b864be64b48521ccd513c336427bbbccfba39b5be2da560aa", "price_changes": [{"asset_id": "48015311421026063012985711082782647083417221141101598875055317979379805670690", "price": "0.163", "size": "8.2", "side": "SELL", "hash": "c07feed6ac8080242d8323064ab02304e8f1dac2", "best_bid": "0", "best_ask": "0.001"}, {"asset_id": "69403394007873424681005155433420327969196546299861361174702151771312033239993", "price": "0.837", "size": "8.2", "side": "BUY", "hash": "79f6783596d95640c291da3ac28581cf0b59ed4b", "best_bid": "0.999", "best_ask": "1"}], "timestamp": "1769384321756", "event_type": "price_change"}}
{"_local_timestamp": "2026-01-25T23:38:41.915318+00:00", "data": {"market": "0xfe2e85f6fca36e8b864be64b48521ccd513c336427bbbccfba39b5be2da560aa", "price_changes": [{"asset_id": "48015311421026063012985711082782647083417221141101598875055317979379805670690", "price": "0.179", "size": "67.4", "side": "SELL", "hash": "89f0f414d619323a50b4aa120fa07455bf5cf6f4", "best_bid": "0", "best_ask": "0.001"}, {"asset_id": "69403394007873424681005155433420327969196546299861361174702151771312033239993", "price": "0.821", "size": "67.4", "side": "BUY", "hash": "0026b4d2462917e5560224d2f0a70e5ce87ea97b", "best_bid": "0.999", "best_ask": "1"}], "timestamp": "1769384321760", "event_type": "price_change"}}
{"_local_timestamp": "2026-01-25T23:38:42.655837+00:00", "data": {"market": "0xfe2e85f6fca36e8b864be64b48521ccd513c336427bbbccfba39b5be2da560aa", "price_changes": [{"asset_id": "48015311421026063012985711082782647083417221141101598875055317979379805670690", "price": "0.164", "size": "0", "side": "SELL", "hash": "3c1a91dfdee34066437facfd9a6add28f5ce1c86", "best_bid": "0", "best_ask": "0.001"}, {"asset_id": "69403394007873424681005155433420327969196546299861361174702151771312033239993", "price": "0.836", "size": "0", "side": "BUY", "hash": "18b0d7ec75ee0ffa5b2d477c88535834f61bd017", "best_bid": "0.999", "best_ask": "1"}], "timestamp": "1769384322581", "event_type": "price_change"}}
{"_local_timestamp": "2026-01-25T23:38:42.746274+00:00", "data": {"market": "0xfe2e85f6fca36e8b864be64b48521ccd513c336427bbbccfba39b5be2da560aa", "price_changes": [{"asset_id": "48015311421026063012985711082782647083417221141101598875055317979379805670690", "price": "0.162", "size": "5.47", "side": "SELL", "hash": "f059f51d96b21f58cb00d33f7069234d098247dd", "best_bid": "0", "best_ask": "0.001"}, {"asset_id": "69403394007873424681005155433420327969196546299861361174702151771312033239993", "price": "0.838", "size": "5.47", "side": "BUY", "hash": "69b2b741f1fa8fe430cbef59268e0f1a9bf3d5d4", "best_bid": "0.999", "best_ask": "1"}], "timestamp": "1769384322678", "event_type": "price_change"}}
{"_local_timestamp": "2026-01-25T23:38:42.949249+00:00", "data": {"market": "0x820082d9062845486d4a143f029c9f93cb9d095fb18f1aa7cda1c44c2bce1188", "price_changes": [{"asset_id": "70927268883755126554386966675213344514269002069096912114831420016073249520715", "price": "0.024", "size": "0", "side": "SELL", "hash": "0cda20e25782ab63cbe7b7973cf1047e4b7984ce", "best_bid": "0", "best_ask": "0.001"}, {"asset_id": "23264385912109188517723056029307436593365599986842476104748104553557414072010", "price": "0.976", "size": "0", "side": "BUY", "hash": "881920e4dc7e9e5b11ce039a64607f87dd2b879d", "best_bid": "0.999", "best_ask": "1"}], "timestamp": "1769384322878", "event_type": "price_change"}}
{"_local_timestamp": "2026-01-25T23:38:43.208031+00:00", "data": {"market": "0x820082d9062845486d4a143f029c9f93cb9d095fb18f1aa7cda1c44c2bce1188", "price_changes": [{"asset_id": "70927268883755126554386966675213344514269002069096912114831420016073249520715", "price": "0.022", "size": "8.21", "side": "SELL", "hash": "51423d0fd58feec6a343fccd064c3f99422aee06", "best_bid": "0", "best_ask": "0.001"}, {"asset_id": "23264385912109188517723056029307436593365599986842476104748104553557414072010", "price": "0.978", "size": "8.21", "side": "BUY", "hash": "e9643a8b24c6f1b18d0c7d8f0db91084851be693", "best_bid": "0.999", "best_ask": "1"}], "timestamp": "1769384323141", "event_type": "price_change"}}
{"_local_timestamp": "2026-01-25T23:38:44.025633+00:00", "data": {"market": "0x820082d9062845486d4a143f029c9f93cb9d095fb18f1aa7cda1c44c2bce1188", "price_changes": [{"asset_id": "70927268883755126554386966675213344514269002069096912114831420016073249520715", "price": "0.023", "size": "0", "side": "SELL", "hash": "d081efd1c1b9f0f3c8e4263fb2e265f2d1cce355", "best_bid": "0", "best_ask": "0.001"}, {"asset_id": "23264385912109188517723056029307436593365599986842476104748104553557414072010", "price": "0.977", "size": "0", "side": "BUY", "hash": "d63cc8eb3f526e0b2ed0e3c5eb54e132b33a0487", "best_bid": "0.999", "best_ask": "1"}], "timestamp": "1769384323948", "event_type": "price_change"}}
{"_local_timestamp": "2026-01-25T23:38:44.109265+00:00", "data": {"market": "0x820082d9062845486d4a143f029c9f93cb9d095fb18f1aa7cda1c44c2bce1188", "price_changes": [{"asset_id": "70927268883755126554386966675213344514269002069096912114831420016073249520715", "price": "0.021", "size": "5.47", "side": "SELL", "hash": "b666f368d09db2223c29b6bbbd7608e9fec2b037", "best_bid": "0", "best_ask": "0.001"}, {"asset_id": "23264385912109188517723056029307436593365599986842476104748104553557414072010", "price": "0.979", "size": "5.47", "side": "BUY", "hash": "64204ec61f5be8f00d795a41cad96830070ef5e0", "best_bid": "0.999", "best_ask": "1"}], "timestamp": "1769384324037", "event_type": "price_change"}}
{"_local_timestamp": "2026-01-25T23:39:09.461505+00:00", "data": {"market": "0x841529681a7a5fc77af6ee13187c65bca1400530f81be0328cfff6c19c112cee", "price_changes": [{"asset_id": "50197395464408075357578095662006421013318644198206473166647680578559551606381", "price": "0.992", "size": "1000", "side": "SELL", "hash": "4e3c7a4fb0e132537daf33f2472adc543a24f2da", "best_bid": "0.001", "best_ask": "0.01"}, {"asset_id": "61406926682600289284199037461761473156945342642474137106642230975893372304476", "price": "0.008", "size": "1000", "side": "BUY", "hash": "fefd1347532a3e83d43bb4077d7336cdda2a3304", "best_bid": "0.99", "best_ask": "0.999"}], "timestamp": "1769384349387", "event_type": "price_change"}}
{"_local_timestamp": "2026-01-25T23:39:09.654496+00:00", "data": {"market": "0x841529681a7a5fc77af6ee13187c65bca1400530f81be0328cfff6c19c112cee", "price_changes": [{"asset_id": "50197395464408075357578095662006421013318644198206473166647680578559551606381", "price": "0.991", "size": "200", "side": "SELL", "hash": "6a32d1356571a7a6abc5fa1dac632aab7844070c", "best_bid": "0.001", "best_ask": "0.01"}, {"asset_id": "61406926682600289284199037461761473156945342642474137106642230975893372304476", "price": "0.009", "size": "200", "side": "BUY", "hash": "2a699c12c64021b6915dd5717e9bb0ed8a1cb0e5", "best_bid": "0.99", "best_ask": "0.999"}], "timestamp": "1769384349587", "event_type": "price_change"}}
{"_local_timestamp": "2026-01-25T23:39:09.897906+00:00", "data": {"market": "0xcb7dc9e8c99d3894e219a6242949729a2d4736f19ee13a21ceefc20a80a0066b", "price_changes": [{"asset_id": "98485975070324083339941401870090885415947897822976000836314973267692056078647", "price": "0.987", "size": "0", "side": "SELL", "hash": "03ab9de9df1dfee3bdd5ee02ed393398bd084734", "best_bid": "0.001", "best_ask": "0.01"}, {"asset_id": "115788350734693757421027634879142051258958684646271080316220994609154259670413", "price": "0.013", "size": "0", "side": "BUY", "hash": "b0d951b617c2f5587a719567769c31ac909184be", "best_bid": "0.99", "best_ask": "0.999"}], "timestamp": "1769384349818", "event_type": "price_change"}}
{"_local_timestamp": "2026-01-25T23:39:09.898346+00:00", "data": {"market": "0xcb7dc9e8c99d3894e219a6242949729a2d4736f19ee13a21ceefc20a80a0066b", "price_changes": [{"asset_id": "98485975070324083339941401870090885415947897822976000836314973267692056078647", "price": "0.992", "size": "1000", "side": "SELL", "hash": "03ab9de9df1dfee3bdd5ee02ed393398bd084734", "best_bid": "0.001", "best_ask": "0.01"}, {"asset_id": "115788350734693757421027634879142051258958684646271080316220994609154259670413", "price": "0.008", "size": "1000", "side": "BUY", "hash": "b0d951b617c2f5587a719567769c31ac909184be", "best_bid": "0.99", "best_ask": "0.999"}], "timestamp": "1769384349818", "event_type": "price_change"}}
{"_local_timestamp": "2026-01-25T23:39:10.321943+00:00", "data": {"market": "0xcb7dc9e8c99d3894e219a6242949729a2d4736f19ee13a21ceefc20a80a0066b", "price_changes": [{"asset_id": "98485975070324083339941401870090885415947897822976000836314973267692056078647", "price": "0.991", "size": "183.59", "side": "SELL", "hash": "7208c1e18a9caee69e194936b060d139a7dd062d", "best_bid": "0.001", "best_ask": "0.01"}, {"asset_id": "115788350734693757421027634879142051258958684646271080316220994609154259670413", "price": "0.009", "size": "183.59", "side": "BUY", "hash": "c4b7a1574e46aa38b8642f3caefe845621640947", "best_bid": "0.99", "best_ask": "0.999"}], "timestamp": "1769384350252", "event_type": "price_change"}}
{"_local_timestamp": "2026-01-25T23:39:10.322392+00:00", "data": {"market": "0xcb7dc9e8c99d3894e219a6242949729a2d4736f19ee13a21ceefc20a80a0066b", "price_changes": [{"asset_id": "98485975070324083339941401870090885415947897822976000836314973267692056078647", "price": "0.985", "size": "16.41", "side": "SELL", "hash": "457a3f284113ff47605333cef6775db34f2ee9c6", "best_bid": "0.001", "best_ask": "0.01"}, {"asset_id": "115788350734693757421027634879142051258958684646271080316220994609154259670413", "price": "0.015", "size": "16.41", "side": "BUY", "hash": "bdbcd3c2d82829bb0da76c02203a22adedd21bc1", "best_bid": "0.99", "best_ask": "0.999"}], "timestamp": "1769384350253", "event_type": "price_change"}}
{"_local_timestamp": "2026-01-25T23:39:11.298758+00:00", "data": {"market": "0xcb7dc9e8c99d3894e219a6242949729a2d4736f19ee13a21ceefc20a80a0066b", "price_changes": [{"asset_id": "98485975070324083339941401870090885415947897822976000836314973267692056078647", "price": "0.986", "size": "0", "side": "SELL", "hash": "4f4087633185e2d412cee9ad79f5f9086e333d94", "best_bid": "0.001", "best_ask": "0.01"}, {"asset_id": "115788350734693757421027634879142051258958684646271080316220994609154259670413", "price": "0.014", "size": "0", "side": "BUY", "hash": "e99d742bafbfda4e9fffeb7fd2039dbebd923d7d", "best_bid": "0.99", "best_ask": "0.999"}], "timestamp": "1769384351227", "event_type": "price_change"}}
{"_local_timestamp": "2026-01-25T23:39:11.346313+00:00", "data": {"market": "0xcb7dc9e8c99d3894e219a6242949729a2d4736f19ee13a21ceefc20a80a0066b", "price_changes": [{"asset_id": "98485975070324083339941401870090885415947897822976000836314973267692056078647", "price": "0.984", "size": "10.94", "side": "SELL", "hash": "481744070813e40620e12c3ef4e68b0512c47be3", "best_bid": "0.001", "best_ask": "0.01"}, {"asset_id": "115788350734693757421027634879142051258958684646271080316220994609154259670413", "price": "0.016", "size": "10.94", "side": "BUY", "hash": "83816dc426109a96b06ea2ec0a183a62cc42621c", "best_bid": "0.99", "best_ask": "0.999"}], "timestamp": "1769384351279", "event_type": "price_change"}}
{"_local_timestamp": "2026-01-25T23:39:48.981185+00:00", "data": {"market": "0x9806d6a5e6e617f978ef8918981422d7c383ece76bd3d53c4018d83f851df7cc", "price_changes": [{"asset_id": "96874305238055838913572671099974795248962251859827192697616088060794485331788", "price": "0.055", "size": "0", "side": "SELL", "hash": "bd5fbbc10f4c03fafee967cb6d0ba3f74fb6899a", "best_bid": "0.001", "best_ask": "0.003"}, {"asset_id": "4655206770474921299388200827584555181546002874778899522765485382144463583575", "price": "0.945", "size": "0", "side": "BUY", "hash": "9d96bb9cc943768b94d0aa4782dbf633bc31d5ed", "best_bid": "0.997", "best_ask": "0.999"}], "timestamp": "1769384388888", "event_type": "price_change"}}
{"_local_timestamp": "2026-01-25T23:39:49.201435+00:00", "data": {"market": "0x9806d6a5e6e617f978ef8918981422d7c383ece76bd3d53c4018d83f851df7cc", "price_changes": [{"asset_id": "96874305238055838913572671099974795248962251859827192697616088060794485331788", "price": "0.053", "size": "10.56", "side": "SELL", "hash": "5f8b79f436ef0591ca35ae36a956293f3a7b14b8", "best_bid": "0.001", "best_ask": "0.003"}, {"asset_id": "4655206770474921299388200827584555181546002874778899522765485382144463583575", "price": "0.947", "size": "10.56", "side": "BUY", "hash": "d76a8bfa2b03cd68a1bb4f93d3d71721b4a6d7ff", "best_bid": "0.997", "best_ask": "0.999"}], "timestamp": "1769384389129", "event_type": "price_change"}}
{"_local_timestamp": "2026-01-25T23:39:50.162884+00:00", "data": {"market": "0x9806d6a5e6e617f978ef8918981422d7c383ece76bd3d53c4018d83f851df7cc", "price_changes": [{"asset_id": "96874305238055838913572671099974795248962251859827192697616088060794485331788", "price": "0.054", "size": "0", "side": "SELL", "hash": "7fb9c1ca6c6fa7c7aec88dc1aa5d3bcb9c3d05fb", "best_bid": "0.001", "best_ask": "0.003"}, {"asset_id": "4655206770474921299388200827584555181546002874778899522765485382144463583575", "price": "0.946", "size": "0", "side": "BUY", "hash": "110a14ae3e1fc9bebf821e532fa30267798b1232", "best_bid": "0.997", "best_ask": "0.999"}], "timestamp": "1769384390090", "event_type": "price_change"}}
{"_local_timestamp": "2026-01-25T23:39:50.246865+00:00", "data": {"market": "0x9806d6a5e6e617f978ef8918981422d7c383ece76bd3d53c4018d83f851df7cc", "price_changes": [{"asset_id": "96874305238055838913572671099974795248962251859827192697616088060794485331788", "price": "0.052", "size": "5.47", "side": "SELL", "hash": "53923ad0f1eb8d8c8c5b8aa9a539edde035dcc92", "best_bid": "0.001", "best_ask": "0.003"}, {"asset_id": "4655206770474921299388200827584555181546002874778899522765485382144463583575", "price": "0.948", "size": "5.47", "side": "BUY", "hash": "266078a30a7d84414096ec20498808cb051921c3", "best_bid": "0.997", "best_ask": "0.999"}], "timestamp": "1769384390179", "event_type": "price_change"}}
