{"_local_timestamp": "2026-01-25T23:33:53.309239+00:00", "data": [{"market": "0xb4cb0ae16ba9281cdc5a5d20f324d0d0a7753d6116d0d905e0a8742ae8d0c244", "asset_id": "102744846850187161380521503397483870162725714816776510187447472868892066157718", "timestamp": "1769383871997", "hash": "341d06576aaee8d0ba037a845d9c8a3954c0b9de", "bids": [{"price": "0.01", "size": "112.04"}, {"price": "0.02", "size": "205.48"}, {"price": "0.03", "size": "18.99"}, {"price": "0.04", "size": "5.47"}], "asks": [{"price": "0.99", "size": "112.04"}, {"price": "0.98", "size": "215.48"}, {"price": "0.97", "size": "18.99"}, {"price": "0.96", "size": "29.99"}], "event_type": "book", "last_trade_price": ""}, {"market": "0x19a4d27add00ce27b2a3cf7ca5705ef8aade39a8ece33948e9b2f02c192152be", "asset_id": "71489691980085603195785483996972122116532490472494448024267486667321753208838", "timestamp": "1769383863285", "hash": "eace144b9c31c1e1c3d78ce81863640e278ebed2", "bids": [{"price": "0.01", "size": "62.04"}, {"price": "0.02", "size": "190.48"}, {"price": "0.03", "size": "18.99"}, {"price": "0.04", "size": "29.99"}], "asks": [{"price": "0.99", "size": "58.05"}, {"price": "0.98", "size": "177.18"}, {"price": "0.97", "size": "25.53"}, {"price": "0.96", "size": "5.47"}], "event_type": "book", "last_trade_price": ""}, {"market": "0xb4cb0ae16ba9281cdc5a5d20f324d0d0a7753d6116d0d905e0a8742ae8d0c244", "asset_id": "37092008225382265270014902992349514323037660984217265301171261275317809758859", "timestamp": "1769383871997", "hash": "ba84eb4cacb1ecacd7913f9505877bf91f09789e", "bids": [{"price": "0.01", "size": "112.04"}, {"price": "0.02", "size": "215.48"}, {"price": "0.03", "size": "18.99"}, {"price": "0.04", "size": "29.99"}], "asks": [{"price": "0.99", "size": "112.04"}, {"price": "0.98", "size": "205.48"}, {"price": "0.97", "size": "18.99"}, {"price": "0.96", "size": "5.47"}], "event_type": "book", "last_trade_price": ""}, {"market": "0x9fa8edb100e017bd5633db881bfd7f39d8feaf23e488562c7863403b75f2b72a", "asset_id": "109451912333674650094373499600078573206027333544803021029937231897917192478306", "timestamp": "1769383871996", "hash": "e7889b4e01b3d30c4a49112d73e9dc005bd6cfd0", "bids": [{"price": "0.01", "size": "119.23"}, {"price": "0.02", "size": "202.94"}, {"price": "0.03", "size": "20.96"}, {"price": "0.04", "size": "5.47"}], "asks": [{"price": "0.99", "size": "111.05"}, {"price": "0.98", "size": "214.48"}, {"price": "0.97", "size": "18.99"}, {"price": "0.96", "size": "29.99"}], "event_type": "book", "last_trade_price": ""}, {"market": "0xc62866c20352813ae054a41ad3f1b92292b5300d7bfc1143e9c6a41823fe5992", "asset_id": "52759588103937363641506362299958930445030460683736633313225430843238074731373", "timestamp": "1769383873125", "hash": "6e7224ad7ca45124b436389c212b25a4adae8d9b", "bids": [{"price": "0.01", "size": "59.8"}, {"price": "0.02", "size": "179.03"}, {"price": "0.03", "size": "23.71"}, {"price": "0.04", "size": "5.47"}], "asks": [{"price": "0.99", "size": "62.05"}, {"price": "0.98", "size": "190.48"}, {"price": "0.97", "size": "18.99"}, {"price": "0.96", "size": "29.99"}], "event_type": "book", "last_trade_price": ""}, {"market": "0x02682a05084a43701a3e859db3f03bc7035ea32f4ae3c139855869bbb49062f1", "asset_id": "35192903361091849248940718645499233167215841826837724281530158082247957989629", "timestamp": "1769383979108", "hash": "b087b2be3102fef63b88fd2cf36eff238ef74e22", "bids": [{"price": "0.01", "size": "62.05"}, {"price": "0.02", "size": "190.48"}, {"price": "0.03", "size": "18.99"}, {"price": "0.04", "size": "29.99"}], "asks": [{"price": "0.99", "size": "69.89"}, {"price": "0.98", "size": "179.03"}, {"price": "0.97", "size": "20.35"}, {"price": "0.96", "size": "5.47"}], "event_type": "book", "last_trade_price": ""}, {"market": "0xd3b44443f0b39d21079f0a72254268aee2103faf72e7b3109d8ae6764d416152", "asset_id": "66916591411271253117011649722470760555098136629103997561616701243019995826796", "timestamp": "1769383863285", "hash": "19f11e18a60d8a3050e2c7aa13597c737996a6a2", "bids": [{"price": "0.01", "size": "62.05"}, {"price": "0.02", "size": "190.48"}, {"price": "0.03", "size": "18.99"}, {"price": "0.04", "size": "29.99"}], "asks": [{"price": "0.99", "size": "59.8"}, {"price": "0.98", "size": "179.03"}, {"price": "0.97", "size": "23.71"}, {"price": "0.96", "size": "5.47"}], "event_type": "book", "last_trade_price": ""}, {"market": "0x02682a05084a43701a3e859db3f03bc7035ea32f4ae3c139855869bbb49062f1", "asset_id": "30887032572101121332187740667215094491657468658291043188830897987016129354142", "timestamp": "1769383979108", "hash": "bbd82e7f8a3599ddf6f9536d4cb54fddee13866b", "bids": [{"price": "0.01", "size": "69.89"}, {"price": "0.02", "size": "179.03"}, {"price": "0.03", "size": "20.35"}, {"price": "0.04", "size": "5.47"}], "asks": [{"price": "0.99", "size": "62.05"}, {"price": "0.98", "size": "190.48"}, {"price": "0.97", "size": "18.99"}, {"price": "0.96", "size": "29.99"}], "event_type": "book", "last_trade_price": ""}, {"market": "0xff1e6a0275ae0216a33abece78285de646cdd4ba37dc1d772578538be60329cf", "asset_id": "106561211697967626756310720720604256534170407941019828744583005941010546193812", "timestamp": "1769383982807", "hash": "c8e4f77923c37cd20fddba7689b96ed34b5a15e7", "bids": [{"price": "0.01", "size": "89.63"}, {"price": "0.02", "size": "181.14"}, {"price": "0.03", "size": "12.36"}, {"price": "0.05", "size": "23.99"}, {"price": "0.06", "size": "5.47"}], "asks": [{"price": "0.99", "size": "61.38"}, {"price": "0.98", "size": "190.17"}, {"price": "0.97", "size": "52.57"}], "event_type": "book", "last_trade_price": ""}, {"market": "0x0b3f0b56ce7a1cf75aec197fcb9f7ee8bdf65558ac2ea9971449c3096780d338", "asset_id": "95863417261965127329516942717312259763677678047436515841413814150856225930745", "timestamp": "1769383882976", "hash": "c0d5c751ee55a7da540cf9ced22b2c755d0fae17", "bids": [{"price": "0.01", "size": "48.87"}, {"price": "0.02", "size": "158.22"}, {"price": "0.03", "size": "75"}, {"price": "0.04", "size": "18.66"}, {"price": "0.07", "size": "5"}, {"price": "0.08", "size": "5"}, {"price": "0.15", "size": "25"}], "asks": [{"price": "0.99", "size": "47.32"}, {"price": "0.98", "size": "156.79"}, {"price": "0.97", "size": "84"}, {"price": "0.96", "size": "25.24"}, {"price": "0.8", "size": "3050"}, {"price": "0.79", "size": "50"}], "event_type": "book", "last_trade_price": ""}, {"market": "0xb1dfeeb0162aae13b396bcb58584b03cc46386a821c63008f0446cb68edf0944", "asset_id": "67990154379603538401421401499393251605484282027318537553294424700792145845644", "timestamp": "1769383123102", "hash": "228e6fc140413ae7155d9d6882b0b06297cd74b3", "bids": [{"price": "0.001", "size": "1067.99"}, {"price": "0.002", "size": "26.5"}, {"price": "0.005", "size": "100"}, {"price": "0.01", "size": "3740"}, {"price": "0.011", "size": "5.1"}, {"price": "0.02", "size": "2250"}, {"price": "0.021", "size": "7.68"}, {"price": "0.051", "size": "1500"}, {"price": "0.052", "size": "450"}, {"price": "0.053", "size": "13.76"}, {"price": "0.186", "size": "300"}, {"price": "0.21", "size": "2200"}, {"price": "0.22", "size": "10"}, {"price": "0.227", "size": "125"}, {"price": "0.244", "size": "75"}, {"price": "0.32", "size": "131"}, {"price": "0.33", "size": "131"}, {"price": "0.339", "size": "50"}, {"price": "0.342", "size": "142"}, {"price": "0.35", "size": "10"}, {"price": "0.361", "size": "460"}, {"price": "0.371", "size": "5"}, {"price": "0.377", "size": "470"}], "asks": [{"price": "0.999", "size": "1073.33"}, {"price": "0.998", "size": "10.55"}, {"price": "0.995", "size": "100"}, {"price": "0.994", "size": "12.56"}, {"price": "0.99", "size": "3745"}, {"price": "0.98", "size": "2250"}, {"price": "0.979", "size": "12.07"}, {"price": "0.934", "size": "1700"}, {"price": "0.919", "size": "1050"}, {"price": "0.918", "size": "7.86"}, {"price": "0.668", "size": "300"}, {"price": "0.65", "size": "10"}, {"price": "0.625", "size": "200"}, {"price": "0.595", "size": "125"}, {"price": "0.565", "size": "75"}, {"price": "0.5", "size": "20"}, {"price": "0.408", "size": "63"}, {"price": "0.4", "size": "5.7"}], "event_type": "book", "last_trade_price": "0.601"}, {"market": "0x362912f5cb655b81e79607e953e32f84dac1572753e2391f459e450478265749", "asset_id": "111407420641358258640954942754741699488195643075274492825410595934557666593274", "timestamp": "1769383979108", "hash": "feb7b250cdcd78ef300fffae8b6ae86f7afe8ef0", "bids": [{"price": "0.01", "size": "69.74"}, {"price": "0.02", "size": "179.03"}, {"price": "0.03", "size": "20.4"}, {"price": "0.04", "size": "5.47"}], "asks": [{"price": "0.99", "size": "62.04"}, {"price": "0.98", "size": "190.48"}, {"price": "0.97", "size": "18.99"}, {"price": "0.96", "size": "29.99"}], "event_type": "book", "last_trade_price": ""}, {"market": "0x0b3f0b56ce7a1cf75aec197fcb9f7ee8bdf65558ac2ea9971449c3096780d338", "asset_id": "91619075857964693393392208565070104325869093110027846136624063203645460004241", "timestamp": "1769383882976", "hash": "1e3c50cb26ffbcb1c33ff69505af0056ded1f4c1", "bids": [{"price": "0.01", "size": "47.32"}, {"price": "0.02", "size": "156.79"}, {"price": "0.03", "size": "84"}, {"price": "0.04", "size": "25.24"}, {"price": "0.2", "size": "3050"}, {"price": "0.21", "size": "50"}], "asks": [{"price": "0.99", "size": "48.87"}, {"price": "0.98", "size": "158.22"}, {"price": "0.97", "size": "75"}, {"price": "0.96", "size": "18.66"}, {"price": "0.93", "size": "5"}, {"price": "0.92", "size": "5"}, {"price": "0.85", "size": "25"}], "event_type": "book", "last_trade_price": ""}, {"market": "0x02cb406686b0e5a2c761b60dba57df5a5aa10de657d8b55c2059de1594262ef8", "asset_id": "71618273512612611641687286878012843492831706235643168298378352373515271932764", "timestamp": "1769383871627", "hash": "422252374f19cb655219b2d35143018fbeee4aa5", "bids": [{"price": "0.01", "size": "62.84"}, {"price": "0.02", "size": "177.03"}, {"price": "0.03", "size": "21.03"}, {"price": "0.06", "size": "15.47"}], "asks": [{"price": "0.99", "size": "62.05"}, {"price": "0.98", "size": "190.48"}, {"price": "0.97", "size": "18.99"}, {"price": "0.96", "size": "42.49"}], "event_type": "book", "last_trade_price": ""}, {"market": "0xff1e6a0275ae0216a33abece78285de646cdd4ba37dc1d772578538be60329cf", "asset_id": "114506854111387970982269268959966858458499074507684750968073343843315627005834", "timestamp": "1769383982807", "hash": "8cb04383c970e40804863c901e4b413136004d55", "bids": [{"price": "0.01", "size": "61.38"}, {"price": "0.02", "size": "190.17"}, {"price": "0.03", "size": "52.57"}], "asks": [{"price": "0.99", "size": "89.63"}, {"price": "0.98", "size": "181.14"}, {"price": "0.97", "size": "12.36"}, {"price": "0.95", "size": "23.99"}, {"price": "0.94", "size": "5.47"}], "event_type": "book", "last_trade_price": ""}, {"market": "0x1ad9a38d618ce04f30f9da1b23b0c7770045e9e9960a896df4e336ad32f2026c", "asset_id": "66047097802271527843368694275125051025060429048241924434656538796886352507204", "timestamp": "1769381444813", "hash": "2bb22927b0fef6e03163959cf81ffd37452bc524", "bids": [{"price": "0.01", "size": "58.82"}, {"price": "0.02", "size": "158.95"}, {"price": "0.03", "size": "21.09"}, {"price": "0.05", "size": "10000"}], "asks": [{"price": "0.99", "size": "59.8"}, {"price": "0.98", "size": "157.03"}, {"price": "0.97", "size": "12.74"}, {"price": "0.95", "size": "10000"}, {"price": "0.94", "size": "277.55"}], "event_type": "book", "last_trade_price": ""}, {"market": "0x9fa8edb100e017bd5633db881bfd7f39d8feaf23e488562c7863403b75f2b72a", "asset_id": "97737434631321407607330081336176115113173871167799349015045656897989017126587", "timestamp": "1769383871996", "hash": "de1d6fb97838d23b151e05c91b5244a93529636a", "bids": [{"price": "0.01", "size": "111.05"}, {"price": "0.02", "size": "214.48"}, {"price": "0.03", "size": "18.99"}, {"price": "0.04", "size": "29.99"}], "asks": [{"price": "0.99", "size": "119.23"}, {"price": "0.98", "size": "202.94"}, {"price": "0.97", "size": "20.96"}, {"price": "0.96", "size": "5.47"}], "event_type": "book", "last_trade_price": ""}, {"market": "0xd37f59b9c51a3548d7c9740bc25c619c6da8e03acc850023295b8b983ad20527", "asset_id": "86922549432847869502897076242034045799267352097019606723721140333601147624472", "timestamp": "1769383853623", "hash": "f0ed5ac5e028915c86900381183971face797bed", "bids": [{"price": "0.01", "size": "62.04"}, {"price": "0.02", "size": "190.48"}, {"price": "0.03", "size": "18.99"}, {"price": "0.04", "size": "29.99"}], "asks": [{"price": "0.99", "size": "59.88"}, {"price": "0.98", "size": "178.75"}, {"price": "0.97", "size": "23.87"}, {"price": "0.96", "size": "5.47"}], "event_type": "book", "last_trade_price": ""}, {"market": "0x362912f5cb655b81e79607e953e32f84dac1572753e2391f459e450478265749", "asset_id": "3087755881123905074274619731943137130363325113969580976113246712649699904601", "timestamp": "1769383979108", "hash": "8d7c021edf3cafc1c06f5ec884b8de7f78bf0b19", "bids": [{"price": "0.01", "size": "62.04"}, {"price": "0.02", "size": "190.48"}, {"price": "0.03", "size": "18.99"}, {"price": "0.04", "size": "29.99"}], "asks": [{"price": "0.99", "size": "69.74"}, {"price": "0.98", "size": "179.03"}, {"price": "0.97", "size": "20.4"}, {"price": "0.96", "size": "5.47"}], "event_type": "book", "last_trade_price": ""}, {"market": "0xc62866c20352813ae054a41ad3f1b92292b5300d7bfc1143e9c6a41823fe5992", "asset_id": "47133502308465006307801302772561127971127968369129604946852551581692421961280", "timestamp": "1769383873125", "hash": "8f3a0da93190b6900ff28d55111fa40cc22c30ba", "bids": [{"price": "0.01", "size": "62.05"}, {"price": "0.02", "size": "190.48"}, {"price": "0.03", "size": "18.99"}, {"price": "0.04", "size": "29.99"}], "asks": [{"price": "0.99", "size": "59.8"}, {"price": "0.98", "size": "179.03"}, {"price": "0.97", "size": "23.71"}, {"price": "0.96", "size": "5.47"}], "event_type": "book", "last_trade_price": ""}, {"market": "0x1ad9a38d618ce04f30f9da1b23b0c7770045e9e9960a896df4e336ad32f2026c", "asset_id": "24908639899155661575059764798804056969147578681693207123115606445236836521513", "timestamp": "1769381444813", "hash": "28b4c86e82267e63133ef984ecd29a13cff39f95", "bids": [{"price": "0.01", "size": "59.8"}, {"price": "0.02", "size": "157.03"}, {"price": "0.03", "size": "12.74"}, {"price": "0.05", "size": "10000"}, {"price": "0.06", "size": "277.55"}], "asks": [{"price": "0.99", "size": "58.82"}, {"price": "0.98", "size": "158.95"}, {"price": "0.97", "size": "21.09"}, {"price": "0.95", "size": "10000"}], "event_type": "book", "last_trade_price": ""}, {"market": "0xd37f59b9c51a3548d7c9740bc25c619c6da8e03acc850023295b8b983ad20527", "asset_id": "10617636138259507285477245956793545272020397648836479158116719634159970012149", "timestamp": "1769383853623", "hash": "1d18f5ad25e8127a43b2e5af454b376508ab8530", "bids": [{"price": "0.01", "size": "59.88"}, {"price": "0.02", "size": "178.75"}, {"price": "0.03", "size": "23.87"}, {"price": "0.04", "size": "5.47"}], "asks": [{"price": "0.99", "size": "62.04"}, {"price": "0.98", "size": "190.48"}, {"price": "0.97", "size": "18.99"}, {"price": "0.96", "size": "29.99"}], "event_type": "book", "last_trade_price": ""}, {"market": "0x02cb406686b0e5a2c761b60dba57df5a5aa10de657d8b55c2059de1594262ef8", "asset_id": "17525878431794376842013117355232170057074541567126099913305204894084193326972", "timestamp": "1769383871627", "hash": "7eb917c5f5d384ddd0410b7402ba76085418e34f", "bids": [{"price": "0.01", "size": "62.05"}, {"price": "0.02", "size": "190.48"}, {"price": "0.03", "size": "18.99"}, {"price": "0.04", "size": "42.49"}], "asks": [{"price": "0.99", "size": "62.84"}, {"price": "0.98", "size": "177.03"}, {"price": "0.97", "size": "21.03"}, {"price": "0.94", "size": "15.47"}], "event_type": "book", "last_trade_price": ""}, {"market": "0xb1dfeeb0162aae13b396bcb58584b03cc46386a821c63008f0446cb68edf0944", "asset_id": "105807781778430202450621182764387831604381299883963754488170834423433351086629", "timestamp": "1769383123102", "hash": "040be9568f77ceec416706638ec787f6ae89bbc9", "bids": [{"price": "0.001", "size": "1073.33"}, {"price": "0.002", "size": "10.55"}, {"price": "0.005", "size": "100"}, {"price": "0.006", "size": "12.56"}, {"price": "0.01", "size": "3745"}, {"price": "0.02", "size": "2250"}, {"price": "0.021", "size": "12.07"}, {"price": "0.066", "size": "1700"}, {"price": "0.081", "size": "1050"}, {"price": "0.082", "size": "7.86"}, {"price": "0.332", "size": "300"}, {"price": "0.35", "size": "10"}, {"price": "0.375", "size": "200"}, {"price": "0.405", "size": "125"}, {"price": "0.435", "size": "75"}, {"price": "0.5", "size": "20"}, {"price": "0.592", "size": "63"}, {"price": "0.6", "size": "5.7"}], "asks": [{"price": "0.999", "size": "1067.99"}, {"price": "0.998", "size": "26.5"}, {"price": "0.995", "size": "100"}, {"price": "0.99", "size": "3740"}, {"price": "0.989", "size": "5.1"}, {"price": "0.98", "size": "2250"}, {"price": "0.979", "size": "7.68"}, {"price": "0.949", "size": "1500"}, {"price": "0.948", "size": "450"}, {"price": "0.947", "size": "13.76"}, {"price": "0.814", "size": "300"}, {"price": "0.79", "size": "2200"}, {"price": "0.78", "size": "10"}, {"price": "0.773", "size": "125"}, {"price": "0.756", "size": "75"}, {"price": "0.68", "size": "131"}, {"price": "0.67", "size": "131"}, {"price": "0.661", "size": "50"}, {"price": "0.658", "size": "142"}, {"price": "0.65", "size": "10"}, {"price": "0.639", "size": "460"}, {"price": "0.629", "size": "5"}, {"price": "0.623", "size": "470"}], "event_type": "book", "last_trade_price": "0.601"}, {"market": "0x19a4d27add00ce27b2a3cf7ca5705ef8aade39a8ece33948e9b2f02c192152be", "asset_id": "95172888027281193001519088464175285929338904438226458264353810757936163188044", "timestamp": "1769383863285", "hash": "961a1f9b113947582fba81ff38e5a5edfb6e1a2b", "bids": [{"price": "0.01", "size": "58.05"}, {"price": "0.02", "size": "177.18"}, {"price": "0.03", "size": "25.53"}, {"price": "0.04", "size": "5.47"}], "asks": [{"price": "0.99", "size": "62.04"}, {"price": "0.98", "size": "190.48"}, {"price": "0.97", "size": "18.99"}, {"price": "0.96", "size": "29.99"}], "event_type": "book", "last_trade_price": ""}, {"market": "0xe34b0bb444471383c90cec5dc69f813a9b3545444de919995ff030dac71248a3", "asset_id": "112017627761537300677970694411480436137463788285461926216623118683376584067380", "timestamp": "1769383979108", "hash": "095ec7db6525f55ff29ed5fe06509db38c7d36e1", "bids": [{"price": "0.01", "size": "62.05"}, {"price": "0.02", "size": "190.48"}, {"price": "0.03", "size": "18.99"}, {"price": "0.04", "size": "29.99"}], "asks": [{"price": "0.99", "size": "69.89"}, {"price": "0.98", "size": "179.03"}, {"price": "0.97", "size": "20.35"}, {"price": "0.96", "size": "5.47"}], "event_type": "book", "last_trade_price": ""}, {"market": "0xd3b44443f0b39d21079f0a72254268aee2103faf72e7b3109d8ae6764d416152", "asset_id": "74195830337912012661209045255656626007077925536496881065075327343195504551863", "timestamp": "1769383863285", "hash": "6e2b2587ac59a6a9a53962e6a9cb7788c4dd41bb", "bids": [{"price": "0.01", "size": "59.8"}, {"price": "0.02", "size": "179.03"}, {"price": "0.03", "size": "23.71"}, {"price": "0.04", "size": "5.47"}], "asks": [{"price": "0.99", "size": "62.05"}, {"price": "0.98", "size": "190.48"}, {"price": "0.97", "size": "18.99"}, {"price": "0.96", "size": "29.99"}], "event_type": "book", "last_trade_price": ""}, {"market": "0xe34b0bb444471383c90cec5dc69f813a9b3545444de919995ff030dac71248a3", "asset_id": "97700218319543636355981601320594824056628162134390242486220190083801463286044", "timestamp": "1769383979108", "hash": "52214eaed1b043730fdcb72aecb8470badbe858a", "bids": [{"price": "0.01", "size": "69.89"}, {"price": "0.02", "size": "179.03"}, {"price": "0.03", "size": "20.35"}, {"price": "0.04", "size": "5.47"}], "asks": [{"price": "0.99", "size": "62.05"}, {"price": "0.98", "size": "190.48"}, {"price": "0.97", "size": "18.99"}, {"price": "0.96", "size": "29.99"}], "event_type": "book", "last_trade_price": ""}]}
{"_local_timestamp": "2026-01-25T23:34:33.349610+00:00", "data": {"market": "0xff1e6a0275ae0216a33abece78285de646cdd4ba37dc1d772578538be60329cf", "price_changes": [{"asset_id": "106561211697967626756310720720604256534170407941019828744583005941010546193812", "price": "0.05", "size": "0", "side": "BUY", "hash": "25626aa568eda7bddd3dc11650d2e26e6563b0ec", "best_bid": "0.06", "best_ask": "0.97"}, {"asset_id": "114506854111387970982269268959966858458499074507684750968073343843315627005834", "price": "0.95", "size": "0", "side": "SELL", "hash": "8390521cdcce3e01a092d43ead85a9153165f251", "best_bid": "0.03", "best_ask": "0.94"}], "timestamp": "1769384073281", "event_type": "price_change"}}
{"_local_timestamp": "2026-01-25T23:34:35.130205+00:00", "data": {"market": "0xff1e6a0275ae0216a33abece78285de646cdd4ba37dc1d772578538be60329cf", "price_changes": [{"asset_id": "106561211697967626756310720720604256534170407941019828744583005941010546193812", "price": "0.06", "size": "0", "side": "BUY", "hash": "9f7eb3413f6b019202a8fe47f4c43685bae67b28", "best_bid": "0.03", "best_ask": "0.97"}, {"asset_id": "114506854111387970982269268959966858458499074507684750968073343843315627005834", "price": "0.94", "size": "0", "side": "SELL", "hash": "7336dd068b267bdd4e35579ba17d1b5d4aa0b1ac", "best_bid": "0.03", "best_ask": "0.97"}], "timestamp": "1769384075057", "event_type": "price_change"}}
{"_local_timestamp": "2026-01-25T23:34:35.241212+00:00", "data": {"market": "0xff1e6a0275ae0216a33abece78285de646cdd4ba37dc1d772578538be60329cf", "price_changes": [{"asset_id": "106561211697967626756310720720604256534170407941019828744583005941010546193812", "price": "0.04", "size": "5.47", "side": "BUY", "hash": "a699c5aee74dac331fd9eb8b44440c4b441c1c10", "best_bid": "0.04", "best_ask": "0.97"}, {"asset_id": "114506854111387970982269268959966858458499074507684750968073343843315627005834", "price": "0.96", "size": "5.47", "side": "SELL", "hash": "1a12d9423b62383ba05c5bd46ae5c41aee78dd63", "best_bid": "0.03", "best_ask": "0.96"}], "timestamp": "1769384075165", "event_type": "price_change"}}
{"_local_timestamp": "2026-01-25T23:34:35.333201+00:00", "data": {"market": "0x9fa8edb100e017bd5633db881bfd7f39d8feaf23e488562c7863403b75f2b72a", "price_changes": [{"asset_id": "109451912333674650094373499600078573206027333544803021029937231897917192478306", "price": "0.05", "size": "23.99", "side": "BUY", "hash": "d262db4f2240e3d70c4a8dd1ac56ba90d6af7a86", "best_bid": "0.05", "best_ask": "0.96"}, {"asset_id": "97737434631321407607330081336176115113173871167799349015045656897989017126587", "price": "0.95", "size": "23.99", "side": "SELL", "hash": "c1158927498f274b763e919663474470be0da2b8", "best_bid": "0.04", "best_ask": "0.95"}], "timestamp": "1769384075257", "event_type": "price_change"}}
{"_local_timestamp": "2026-01-25T23:34:35.333580+00:00", "data": {"market": "0xd37f59b9c51a3548d7c9740bc25c619c6da8e03acc850023295b8b983ad20527", "price_changes": [{"asset_id": "10617636138259507285477245956793545272020397648836479158116719634159970012149", "price": "0.05", "size": "23.99", "side": "BUY", "hash": "cdc35fc8098325e14f86968dfbe3003337ce61d7", "best_bid": "0.05", "best_ask": "0.96"}, {"asset_id": "86922549432847869502897076242034045799267352097019606723721140333601147624472", "price": "0.95", "size": "23.99", "side": "SELL", "hash": "38015225b1a1e2b8217a81e542a13654b1d9aa5b", "best_bid": "0.04", "best_ask": "0.95"}], "timestamp": "1769384075257", "event_type": "price_change"}}
{"_local_timestamp": "2026-01-25T23:34:35.334035+00:00", "data": {"market": "0xd3b44443f0b39d21079f0a72254268aee2103faf72e7b3109d8ae6764d416152", "price_changes": [{"asset_id": "74195830337912012661209045255656626007077925536496881065075327343195504551863", "price": "0.05", "size": "23.99", "side": "BUY", "hash": "1ee1fa65ffa5633631d12f738982e41ef5fe2f55", "best_bid": "0.05", "best_ask": "0.96"}, {"asset_id": "66916591411271253117011649722470760555098136629103997561616701243019995826796", "price": "0.95", "size": "23.99", "side": "SELL", "hash": "1f42cdbd2607be0e85498ce3062e4dc02a2f67ed", "best_bid": "0.04", "best_ask": "0.95"}], "timestamp": "1769384075257", "event_type": "price_change"}}
{"_local_timestamp": "2026-01-25T23:34:35.553729+00:00", "data": {"market": "0x19a4d27add00ce27b2a3cf7ca5705ef8aade39a8ece33948e9b2f02c192152be", "price_changes": [{"asset_id": "95172888027281193001519088464175285929338904438226458264353810757936163188044", "price": "0.05", "size": "23.99", "side": "BUY", "hash": "c89234d324e562e2090417513f519913a79074ad", "best_bid": "0.05", "best_ask": "0.96"}, {"asset_id": "71489691980085603195785483996972122116532490472494448024267486667321753208838", "price": "0.95", "size": "23.99", "side": "SELL", "hash": "cfa8c84d8e9df4fa5f3a049be9f34a8c1735624b", "best_bid": "0.04", "best_ask": "0.95"}], "timestamp": "1769384075478", "event_type": "price_change"}}
{"_local_timestamp": "2026-01-25T23:34:35.658965+00:00", "data": {"market": "0xb4cb0ae16ba9281cdc5a5d20f324d0d0a7753d6116d0d905e0a8742ae8d0c244", "price_changes": [{"asset_id": "102744846850187161380521503397483870162725714816776510187447472868892066157718", "price": "0.05", "size": "23.99", "side": "BUY", "hash": "04c48c002f986b7648b6964e33b300a15bfeaa15", "best_bid": "0.05", "best_ask": "0.96"}, {"asset_id": "37092008225382265270014902992349514323037660984217265301171261275317809758859", "price": "0.95", "size": "23.99", "side": "SELL", "hash": "be640545ad0976afd03fea3c3ac611e624d6631f", "best_bid": "0.04", "best_ask": "0.95"}], "timestamp": "1769384075582", "event_type": "price_change"}}
{"_local_timestamp": "2026-01-25T23:34:35.661414+00:00", "data": {"market": "0xc62866c20352813ae054a41ad3f1b92292b5300d7bfc1143e9c6a41823fe5992", "price_changes": [{"asset_id": "52759588103937363641506362299958930445030460683736633313225430843238074731373", "price": "0.05", "size": "23.99", "side": "BUY", "hash": "9cf13f1b523cd5337ba6ae007d24665c046753de", "best_bid": "0.05", "best_ask": "0.96"}, {"asset_id": "47133502308465006307801302772561127971127968369129604946852551581692421961280", "price": "0.95", "size": "23.99", "side": "SELL", "hash": "01b77f4c50efaa9fe236afc65768600625da28db", "best_bid": "0.04", "best_ask": "0.95"}], "timestamp": "1769384075582", "event_type": "price_change"}}
{"_local_timestamp": "2026-01-25T23:34:38.995692+00:00", "data": {"market": "0x19a4d27add00ce27b2a3cf7ca5705ef8aade39a8ece33948e9b2f02c192152be", "price_changes": [{"asset_id": "95172888027281193001519088464175285929338904438226458264353810757936163188044", "price": "0.04", "size": "0", "side": "BUY", "hash": "88f668cdd8d1627424a1c3685734e7cec3f4f81d", "best_bid": "0.05", "best_ask": "0.96"}, {"asset_id": "71489691980085603195785483996972122116532490472494448024267486667321753208838", "price": "0.96", "size": "0", "side": "SELL", "hash": "b5ce5d159ea88d88542607a2bdf6ee5eaad9b92a", "best_bid": "0.04", "best_ask": "0.95"}], "timestamp": "1769384078926", "event_type": "price_change"}}
{"_local_timestamp": "2026-01-25T23:34:39.005506+00:00", "data": {"market": "0x9fa8edb100e017bd5633db881bfd7f39d8feaf23e488562c7863403b75f2b72a", "price_changes": [{"asset_id": "109451912333674650094373499600078573206027333544803021029937231897917192478306", "price": "0.04", "size": "0", "side": "BUY", "hash": "9e3e2f920ea5d8619207034aeefb5c929cab1fb3", "best_bid": "0.05", "best_ask": "0.96"}, {"asset_id": "97737434631321407607330081336176115113173871167799349015045656897989017126587", "price": "0.96", "size": "0", "side": "SELL", "hash": "a80d288c244cb840c7e77ba4126044da78ec7186", "best_bid": "0.04", "best_ask": "0.95"}], "timestamp": "1769384078926", "event_type": "price_change"}}
{"_local_timestamp": "2026-01-25T23:34:39.008206+00:00", "data": {"market": "0xd37f59b9c51a3548d7c9740bc25c619c6da8e03acc850023295b8b983ad20527", "price_changes": [{"asset_id": "10617636138259507285477245956793545272020397648836479158116719634159970012149", "price": "0.04", "size": "0", "side": "BUY", "hash": "0bfa1d25c54fcd667b3b0493366e6202bab8fe09", "best_bid": "0.05", "best_ask": "0.96"}, {"asset_id": "86922549432847869502897076242034045799267352097019606723721140333601147624472", "price": "0.96", "size": "0", "side": "SELL", "hash": "b6ae4158cd5480ccad02992272c6299709466c78", "best_bid": "0.04", "best_ask": "0.95"}], "timestamp": "1769384078927", "event_type": "price_change"}}
{"_local_timestamp": "2026-01-25T23:34:39.009066+00:00", "data": {"market": "0xb4cb0ae16ba9281cdc5a5d20f324d0d0a7753d6116d0d905e0a8742ae8d0c244", "price_changes": [{"asset_id": "102744846850187161380521503397483870162725714816776510187447472868892066157718", "price": "0.04", "size": "0", "side": "BUY", "hash": "f08305c8842fd05f387a3e76f7d86d7dbc8c7316", "best_bid": "0.05", "best_ask": "0.96"}, {"asset_id": "37092008225382265270014902992349514323037660984217265301171261275317809758859", "price": "0.96", "size": "0", "side": "SELL", "hash": "bd37151caaf93fc279b9f165e9d1b98c6f1249a8", "best_bid": "0.04", "best_ask": "0.95"}], "timestamp": "1769384078926", "event_type": "price_change"}}
{"_local_timestamp": "2026-01-25T23:34:39.027473+00:00", "data": {"market": "0xc62866c20352813ae054a41ad3f1b92292b5300d7bfc1143e9c6a41823fe5992", "price_changes": [{"asset_id": "52759588103937363641506362299958930445030460683736633313225430843238074731373", "price": "0.04", "size": "0", "side": "BUY", "hash": "a84c6089f07d906cdbd037cfd6590bef81becb34", "best_bid": "0.05", "best_ask": "0.96"}, {"asset_id": "47133502308465006307801302772561127971127968369129604946852551581692421961280", "price": "0.96", "size": "0", "side": "SELL", "hash": "87b8e60b5fe2fa33dcc32ed5c7571b7df615f95a", "best_bid": "0.04", "best_ask": "0.95"}], "timestamp": "1769384078926", "event_type": "price_change"}}
{"_local_timestamp": "2026-01-25T23:34:39.028653+00:00", "data": {"market": "0xd3b44443f0b39d21079f0a72254268aee2103faf72e7b3109d8ae6764d416152", "price_changes": [{"asset_id": "74195830337912012661209045255656626007077925536496881065075327343195504551863", "price": "0.04", "size": "0", "side": "BUY", "hash": "e62a903f4f3f40d6f2cf89c9ef994c09a2e41dd0", "best_bid": "0.05", "best_ask": "0.96"}, {"asset_id": "66916591411271253117011649722470760555098136629103997561616701243019995826796", "price": "0.96", "size": "0", "side": "SELL", "hash": "0f7b57cb6b1a9e867ece0751061db5dce0213d6d", "best_bid": "0.04", "best_ask": "0.95"}], "timestamp": "1769384078927", "event_type": "price_change"}}
{"_local_timestamp": "2026-01-25T23:34:39.152075+00:00", "data": {"market": "0xc62866c20352813ae054a41ad3f1b92292b5300d7bfc1143e9c6a41823fe5992", "price_changes": [{"asset_id": "52759588103937363641506362299958930445030460683736633313225430843238074731373", "price": "0.06", "size": "5.47", "side": "BUY", "hash": "f05c17bcffbe14fae91df38bdad8b1fd36589666", "best_bid": "0.06", "best_ask": "0.96"}, {"asset_id": "47133502308465006307801302772561127971127968369129604946852551581692421961280", "price": "0.94", "size": "5.47", "side": "SELL", "hash": "d36cc827a5ca0749873cbc2065a3ccab28adb0cd", "best_bid": "0.04", "best_ask": "0.94"}], "timestamp": "1769384079049", "event_type": "price_change"}}
{"_local_timestamp": "2026-01-25T23:34:39.152532+00:00", "data": {"market": "0xd37f59b9c51a3548d7c9740bc25c619c6da8e03acc850023295b8b983ad20527", "price_changes": [{"asset_id": "10617636138259507285477245956793545272020397648836479158116719634159970012149", "price": "0.06", "size": "5.47", "side": "BUY", "hash": "4dd823eb516b4ae48cf41ec53dc93c2b4d832bb9", "best_bid": "0.06", "best_ask": "0.96"}, {"asset_id": "86922549432847869502897076242034045799267352097019606723721140333601147624472", "price": "0.94", "size": "5.47", "side": "SELL", "hash": "7d132e4275df24c1e6577f21e49488f0861ee3c6", "best_bid": "0.04", "best_ask": "0.94"}], "timestamp": "1769384079048", "event_type": "price_change"}}
{"_local_timestamp": "2026-01-25T23:34:39.152858+00:00", "data": {"market": "0xb4cb0ae16ba9281cdc5a5d20f324d0d0a7753d6116d0d905e0a8742ae8d0c244", "price_changes": [{"asset_id": "102744846850187161380521503397483870162725714816776510187447472868892066157718", "price": "0.06", "size": "5.47", "side": "BUY", "hash": "f0aa902a3dff1dce8ee3b6acc1f507ec73ad5d8e", "best_bid": "0.06", "best_ask": "0.96"}, {"asset_id": "37092008225382265270014902992349514323037660984217265301171261275317809758859", "price": "0.94", "size": "5.47", "side": "SELL", "hash": "55276cec36663391c01b9a9c8004dd305828715f", "best_bid": "0.04", "best_ask": "0.94"}], "timestamp": "1769384079048", "event_type": "price_change"}}
{"_local_timestamp": "2026-01-25T23:34:39.153171+00:00", "data": {"market": "0xd3b44443f0b39d21079f0a72254268aee2103faf72e7b3109d8ae6764d416152", "price_changes": [{"asset_id": "74195830337912012661209045255656626007077925536496881065075327343195504551863", "price": "0.06", "size": "5.47", "side": "BUY", "hash": "4779f22fdc657b42b8a97665e737fa5988178cc8", "best_bid": "0.06", "best_ask": "0.96"}, {"asset_id": "66916591411271253117011649722470760555098136629103997561616701243019995826796", "price": "0.94", "size": "5.47", "side": "SELL", "hash": "869e575ddae5e891bce607e2eaddcd6086625b00", "best_bid": "0.04", "best_ask": "0.94"}], "timestamp": "1769384079049", "event_type": "price_change"}}
{"_local_timestamp": "2026-01-25T23:34:39.153477+00:00", "data": {"market": "0x19a4d27add00ce27b2a3cf7ca5705ef8aade39a8ece33948e9b2f02c192152be", "price_changes": [{"asset_id": "95172888027281193001519088464175285929338904438226458264353810757936163188044", "price": "0.06", "size": "5.47", "side": "BUY", "hash": "1685d65128b1e8a2b0934752a475c57ffba9e187", "best_bid": "0.06", "best_ask": "0.96"}, {"asset_id": "71489691980085603195785483996972122116532490472494448024267486667321753208838", "price": "0.94", "size": "5.47", "side": "SELL", "hash": "aff5b578684a2415fc38780d30fa0a805e55fdbe", "best_bid": "0.04", "best_ask": "0.94"}], "timestamp": "1769384079049", "event_type": "price_change"}}
{"_local_timestamp": "2026-01-25T23:34:39.153830+00:00", "data": {"market": "0x9fa8edb100e017bd5633db881bfd7f39d8feaf23e488562c7863403b75f2b72a", "price_changes": [{"asset_id": "109451912333674650094373499600078573206027333544803021029937231897917192478306", "price": "0.06", "size": "5.47", "side": "BUY", "hash": "c2a4ee5b775f2845daa1d7ff86e70ff4e77ec7c3", "best_bid": "0.06", "best_ask": "0.96"}, {"asset_id": "97737434631321407607330081336176115113173871167799349015045656897989017126587", "price": "0.94", "size": "5.47", "side": "SELL", "hash": "ec591b93ec9c89b9f9975290821723eee974feaf", "best_bid": "0.04", "best_ask": "0.94"}], "timestamp": "1769384079049", "event_type": "price_change"}}
{"_local_timestamp": "2026-01-25T23:36:04.243861+00:00", "data": {"market": "0xd37f59b9c51a3548d7c9740bc25c619c6da8e03acc850023295b8b983ad20527", "price_changes": [{"asset_id": "10617636138259507285477245956793545272020397648836479158116719634159970012149", "price": "0.05", "size": "0", "side": "BUY", "hash": "73e1942f2bf86f61f3a5b0dac8a4abfb1c7f2116", "best_bid": "0.06", "best_ask": "0.96"}, {"asset_id": "86922549432847869502897076242034045799267352097019606723721140333601147624472", "price": "0.95", "size": "0", "side": "SELL", "hash": "acce0327d4cc4e4ccd648d1139535cf24831dfd3", "best_bid": "0.04", "best_ask": "0.94"}], "timestamp": "1769384164173", "event_type": "price_change"}}
{"_local_timestamp": "2026-01-25T23:36:04.245140+00:00", "data": {"market": "0x9fa8edb100e017bd5633db881bfd7f39d8feaf23e488562c7863403b75f2b72a", "price_changes": [{"asset_id": "109451912333674650094373499600078573206027333544803021029937231897917192478306", "price": "0.05", "size": "0", "side": "BUY", "hash": "090ae2a4c8a75340603e219880baa4fa0213a35a", "best_bid": "0.06", "best_ask": "0.96"}, {"asset_id": "97737434631321407607330081336176115113173871167799349015045656897989017126587", "price": "0.95", "size": "0", "side": "SELL", "hash": "7ac1d41c6ad9bcfa457df76e355a13dceece4b5b", "best_bid": "0.04", "best_ask": "0.94"}], "timestamp": "1769384164174", "event_type": "price_change"}}
{"_local_timestamp": "2026-01-25T23:36:04.245697+00:00", "data": {"market": "0x19a4d27add00ce27b2a3cf7ca5705ef8aade39a8ece33948e9b2f02c192152be", "price_changes": [{"asset_id": "95172888027281193001519088464175285929338904438226458264353810757936163188044", "price": "0.05", "size": "0", "side": "BUY", "hash": "8e9555260afe77b39cb0fa9eaa02be34060c4d79", "best_bid": "0.06", "best_ask": "0.96"}, {"asset_id": "71489691980085603195785483996972122116532490472494448024267486667321753208838", "price": "0.95", "size": "0", "side": "SELL", "hash": "9dc7b5558a946f50ecec528523cd6c1c886fb808", "best_bid": "0.04", "best_ask": "0.94"}], "timestamp": "1769384164174", "event_type": "price_change"}}
{"_local_timestamp": "2026-01-25T23:36:04.334670+00:00", "data": {"market": "0xd3b44443f0b39d21079f0a72254268aee2103faf72e7b3109d8ae6764d416152", "price_changes": [{"asset_id": "74195830337912012661209045255656626007077925536496881065075327343195504551863", "price": "0.05", "size": "0", "side": "BUY", "hash": "5a345b3c78a4dc976fcb4f8071c4f1bc3834ff82", "best_bid": "0.06", "best_ask": "0.96"}, {"asset_id": "66916591411271253117011649722470760555098136629103997561616701243019995826796", "price": "0.95", "size": "0", "side": "SELL", "hash": "31e1bb15b28257810bea9aa1357d779a432f349d", "best_bid": "0.04", "best_ask": "0.94"}], "timestamp": "1769384164266", "event_type": "price_change"}}
{"_local_timestamp": "2026-01-25T23:36:04.540295+00:00", "data": {"market": "0xb4cb0ae16ba9281cdc5a5d20f324d0d0a7753d6116d0d905e0a8742ae8d0c244", "price_changes": [{"asset_id": "102744846850187161380521503397483870162725714816776510187447472868892066157718", "price": "0.05", "size": "0", "side": "BUY", "hash": "f7f3fe5f07b45b76b241a0ec010ec1a35deda2ab", "best_bid": "0.06", "best_ask": "0.96"}, {"asset_id": "37092008225382265270014902992349514323037660984217265301171261275317809758859", "price": "0.95", "size": "0", "side": "SELL", "hash": "6c250029a191aae81b8b90c90122920f659940f7", "best_bid": "0.04", "best_ask": "0.94"}], "timestamp": "1769384164468", "event_type": "price_change"}}
{"_local_timestamp": "2026-01-25T23:36:04.540906+00:00", "data": {"market": "0xc62866c20352813ae054a41ad3f1b92292b5300d7bfc1143e9c6a41823fe5992", "price_changes": [{"asset_id": "52759588103937363641506362299958930445030460683736633313225430843238074731373", "price": "0.05", "size": "0", "side": "BUY", "hash": "847f41634c096fe6cb9f9948c8383374a326efce", "best_bid": "0.06", "best_ask": "0.96"}, {"asset_id": "47133502308465006307801302772561127971127968369129604946852551581692421961280", "price": "0.95", "size": "0", "side": "SELL", "hash": "260bb26cfd3c163c131611899548b40da85de3f1", "best_bid": "0.04", "best_ask": "0.94"}], "timestamp": "1769384164468", "event_type": "price_change"}}
{"_local_timestamp": "2026-01-25T23:36:05.242238+00:00", "data": {"market": "0xff1e6a0275ae0216a33abece78285de646cdd4ba37dc1d772578538be60329cf", "price_changes": [{"asset_id": "106561211697967626756310720720604256534170407941019828744583005941010546193812", "price": "0.05", "size": "23.99", "side": "BUY", "hash": "6c2a045fa05493f7a1a8b1c33ea6c4aae7046c21", "best_bid": "0.05", "best_ask": "0.97"}, {"asset_id": "114506854111387970982269268959966858458499074507684750968073343843315627005834", "price": "0.95", "size": "23.99", "side": "SELL", "hash": "e4ad5dfa6050cdd1e83adf6e7fae8ae79738717f", "best_bid": "0.03", "best_ask": "0.95"}], "timestamp": "1769384165167", "event_type": "price_change"}}
{"_local_timestamp": "2026-01-25T23:36:09.190659+00:00", "data": {"market": "0xc62866c20352813ae054a41ad3f1b92292b5300d7bfc1143e9c6a41823fe5992", "price_changes": [{"asset_id": "52759588103937363641506362299958930445030460683736633313225430843238074731373", "price": "0.06", "size": "0", "side": "BUY", "hash": "5a49b42e2934690b8a4531221b77d7eea7d4943e", "best_bid": "0.03", "best_ask": "0.96"}, {"asset_id": "47133502308465006307801302772561127971127968369129604946852551581692421961280", "price": "0.94", "size": "0", "side": "SELL", "hash": "daf46e9d67956a735c13a4cc962b34df6908d331", "best_bid": "0.04", "best_ask": "0.97"}], "timestamp": "1769384169122", "event_type": "price_change"}}
{"_local_timestamp": "2026-01-25T23:36:09.198588+00:00", "data": {"market": "0x9fa8edb100e017bd5633db881bfd7f39d8feaf23e488562c7863403b75f2b72a", "price_changes": [{"asset_id": "109451912333674650094373499600078573206027333544803021029937231897917192478306", "price": "0.06", "size": "0", "side": "BUY", "hash": "15ab97bd01802b76ecbab65f0f3f3abcb64b643d", "best_bid": "0.03", "best_ask": "0.96"}, {"asset_id": "97737434631321407607330081336176115113173871167799349015045656897989017126587", "price": "0.94", "size": "0", "side": "SELL", "hash": "2ee83f11d5d9de1d8d9ee697798b58877ce801bc", "best_bid": "0.04", "best_ask": "0.97"}], "timestamp": "1769384169122", "event_type": "price_change"}}
{"_local_timestamp": "2026-01-25T23:36:09.199616+00:00", "data": {"market": "0xb4cb0ae16ba9281cdc5a5d20f324d0d0a7753d6116d0d905e0a8742ae8d0c244", "price_changes": [{"asset_id": "102744846850187161380521503397483870162725714816776510187447472868892066157718", "price": "0.06", "size": "0", "side": "BUY", "hash": "24bdc640f14ec0fe9883508744b3ca7d9fc8f9f9", "best_bid": "0.03", "best_ask": "0.96"}, {"asset_id": "37092008225382265270014902992349514323037660984217265301171261275317809758859", "price": "0.94", "size": "0", "side": "SELL", "hash": "16ddc4dd1854a4fa194f964522db4a783caf933b", "best_bid": "0.04", "best_ask": "0.97"}], "timestamp": "1769384169122", "event_type": "price_change"}}
{"_local_timestamp": "2026-01-25T23:36:09.200023+00:00", "data": {"market": "0x19a4d27add00ce27b2a3cf7ca5705ef8aade39a8ece33948e9b2f02c192152be", "price_changes": [{"asset_id": "95172888027281193001519088464175285929338904438226458264353810757936163188044", "price": "0.06", "size": "0", "side": "BUY", "hash": "c800dfac2102608c7a2dd83199457035d8e198c4", "best_bid": "0.03", "best_ask": "0.96"}, {"asset_id": "71489691980085603195785483996972122116532490472494448024267486667321753208838", "price": "0.94", "size": "0", "side": "SELL", "hash": "0a343832ea03851b89a5d4a26b1cd2294578c828", "best_bid": "0.04", "best_ask": "0.97"}], "timestamp": "1769384169123", "event_type": "price_change"}}
{"_local_timestamp": "2026-01-25T23:36:09.200445+00:00", "data": {"market": "0xff1e6a0275ae0216a33abece78285de646cdd4ba37dc1d772578538be60329cf", "price_changes": [{"asset_id": "106561211697967626756310720720604256534170407941019828744583005941010546193812", "price": "0.04", "size": "0", "side": "BUY", "hash": "c81f26d28be0c2bc0f687de90567d96899312824", "best_bid": "0.05", "best_ask": "0.97"}, {"asset_id": "114506854111387970982269268959966858458499074507684750968073343843315627005834", "price": "0.96", "size": "0", "side": "SELL", "hash": "21706a4693e72d8038fbc4d81dcd23ed14520def", "best_bid": "0.03", "best_ask": "0.95"}], "timestamp": "1769384169122", "event_type": "price_change"}}
{"_local_timestamp": "2026-01-25T23:36:09.200994+00:00", "data": {"market": "0xd37f59b9c51a3548d7c9740bc25c619c6da8e03acc850023295b8b983ad20527", "price_changes": [{"asset_id": "10617636138259507285477245956793545272020397648836479158116719634159970012149", "price": "0.06", "size": "0", "side": "BUY", "hash": "a3004303a495c06b3a77d1275826fa9044446492", "best_bid": "0.03", "best_ask": "0.96"}, {"asset_id": "86922549432847869502897076242034045799267352097019606723721140333601147624472", "price": "0.94", "size": "0", "side": "SELL", "hash": "d622af5bf9cba5c7f5c2f298a27ede36ba891b6e", "best_bid": "0.04", "best_ask": "0.97"}], "timestamp": "1769384169123", "event_type": "price_change"}}
{"_local_timestamp": "2026-01-25T23:36:09.207383+00:00", "data": {"market": "0xd3b44443f0b39d21079f0a72254268aee2103faf72e7b3109d8ae6764d416152", "price_changes": [{"asset_id": "74195830337912012661209045255656626007077925536496881065075327343195504551863", "price": "0.06", "size": "0", "side": "BUY", "hash": "b9b48b31b2805fff04f0b9ec013fe2472884f2db", "best_bid": "0.03", "best_ask": "0.96"}, {"asset_id": "66916591411271253117011649722470760555098136629103997561616701243019995826796", "price": "0.94", "size": "0", "side": "SELL", "hash": "c330265f02d7bc47b4e66553cbc7328c81844130", "best_bid": "0.04", "best_ask": "0.97"}], "timestamp": "1769384169123", "event_type": "price_change"}}
{"_local_timestamp": "2026-01-25T23:36:09.307671+00:00", "data": {"market": "0x9fa8edb100e017bd5633db881bfd7f39d8feaf23e488562c7863403b75f2b72a", "price_changes": [{"asset_id": "109451912333674650094373499600078573206027333544803021029937231897917192478306", "price": "0.04", "size": "5.47", "side": "BUY", "hash": "d0e68d25e279f252d7ef1d1f1cea8a3c16a44110", "best_bid": "0.04", "best_ask": "0.96"}, {"asset_id": "97737434631321407607330081336176115113173871167799349015045656897989017126587", "price": "0.96", "size": "5.47", "side": "SELL", "hash": "ab4444e998249af0cd0a41b91a53412e385c1c5d", "best_bid": "0.04", "best_ask": "0.96"}], "timestamp": "1769384169236", "event_type": "price_change"}}
{"_local_timestamp": "2026-01-25T23:36:09.308207+00:00", "data": {"market": "0xff1e6a0275ae0216a33abece78285de646cdd4ba37dc1d772578538be60329cf", "price_changes": [{"asset_id": "106561211697967626756310720720604256534170407941019828744583005941010546193812", "price": "0.06", "size": "5.47", "side": "BUY", "hash": "9cbbc1401ac55e75c77bf7730f5604ceb04f37f9", "best_bid": "0.06", "best_ask": "0.97"}, {"asset_id": "114506854111387970982269268959966858458499074507684750968073343843315627005834", "price": "0.94", "size": "5.47", "side": "SELL", "hash": "64e0d3267327944d6725c681cc1936a9db6f90c2", "best_bid": "0.03", "best_ask": "0.94"}], "timestamp": "1769384169236", "event_type": "price_change"}}
{"_local_timestamp": "2026-01-25T23:36:09.308674+00:00", "data": {"market": "0x19a4d27add00ce27b2a3cf7ca5705ef8aade39a8ece33948e9b2f02c192152be", "price_changes": [{"asset_id": "95172888027281193001519088464175285929338904438226458264353810757936163188044", "price": "0.04", "size": "5.47", "side": "BUY", "hash": "80f7f5bbf431f2c190931cd0498b6609dac0d4c9", "best_bid": "0.04", "best_ask": "0.96"}, {"asset_id": "71489691980085603195785483996972122116532490472494448024267486667321753208838", "price": "0.96", "size": "5.47", "side": "SELL", "hash": "fb2b904b21b77fd1e4b4f14eaacb6a0ad7776282", "best_bid": "0.04", "best_ask": "0.96"}], "timestamp": "1769384169236", "event_type": "price_change"}}
{"_local_timestamp": "2026-01-25T23:36:09.309093+00:00", "data": {"market": "0xd3b44443f0b39d21079f0a72254268aee2103faf72e7b3109d8ae6764d416152", "price_changes": [{"asset_id": "74195830337912012661209045255656626007077925536496881065075327343195504551863", "price": "0.04", "size": "5.47", "side": "BUY", "hash": "16386e25f29c70a8fd7ff13cc8099a435ca21490", "best_bid": "0.04", "best_ask": "0.96"}, {"asset_id": "66916591411271253117011649722470760555098136629103997561616701243019995826796", "price": "0.96", "size": "5.47", "side": "SELL", "hash": "6692f7f5ed204941ec578850121f602cb15f23d7", "best_bid": "0.04", "best_ask": "0.96"}], "timestamp": "1769384169236", "event_type": "price_change"}}
{"_local_timestamp": "2026-01-25T23:36:09.309465+00:00", "data": {"market": "0xc62866c20352813ae054a41ad3f1b92292b5300d7bfc1143e9c6a41823fe5992", "price_changes": [{"asset_id": "52759588103937363641506362299958930445030460683736633313225430843238074731373", "price": "0.04", "size": "5.47", "side": "BUY", "hash": "d2ef176527e78d1cf87b82c444dba54ed9ee221f", "best_bid": "0.04", "best_ask": "0.96"}, {"asset_id": "47133502308465006307801302772561127971127968369129604946852551581692421961280", "price": "0.96", "size": "5.47", "side": "SELL", "hash": "a0fa43f95a0329c717a116434945cb787dd110a0", "best_bid": "0.04", "best_ask": "0.96"}], "timestamp": "1769384169236", "event_type": "price_change"}}
{"_local_timestamp": "2026-01-25T23:36:09.332813+00:00", "data": {"market": "0xb4cb0ae16ba9281cdc5a5d20f324d0d0a7753d6116d0d905e0a8742ae8d0c244", "price_changes": [{"asset_id": "102744846850187161380521503397483870162725714816776510187447472868892066157718", "price": "0.04", "size": "5.47", "side": "BUY", "hash": "45ec6cd305bf71e660b9b6adb57865385eb92198", "best_bid": "0.04", "best_ask": "0.96"}, {"asset_id": "37092008225382265270014902992349514323037660984217265301171261275317809758859", "price": "0.96", "size": "5.47", "side": "SELL", "hash": "156cb6a968944f21650ef0c9fea85ae7293f0d50", "best_bid": "0.04", "best_ask": "0.96"}], "timestamp": "1769384169236", "event_type": "price_change"}}
{"_local_timestamp": "2026-01-25T23:36:09.333360+00:00", "data": {"market": "0xd37f59b9c51a3548d7c9740bc25c619c6da8e03acc850023295b8b983ad20527", "price_changes": [{"asset_id": "10617636138259507285477245956793545272020397648836479158116719634159970012149", "price": "0.04", "size": "5.47", "side": "BUY", "hash": "940dc3e616f9b9e6ec22a9ce0f3c22e1a123d162", "best_bid": "0.04", "best_ask": "0.96"}, {"asset_id": "86922549432847869502897076242034045799267352097019606723721140333601147624472", "price": "0.96", "size": "5.47", "side": "SELL", "hash": "ee7e2b3c1bf8adc9cb04ece06406fc8bca5c30ea", "best_bid": "0.04", "best_ask": "0.96"}], "timestamp": "1769384169236", "event_type": "price_change"}}
{"_local_timestamp": "2026-01-25T23:37:25.268882+00:00", "data": {"market": "0xe34b0bb444471383c90cec5dc69f813a9b3545444de919995ff030dac71248a3", "price_changes": [{"asset_id": "97700218319543636355981601320594824056628162134390242486220190083801463286044", "price": "0.01", "size": "54.18", "side": "BUY", "hash": "98733c60649fb7772868d3ae26a5b866eaa8c181", "best_bid": "0.04", "best_ask": "0.96"}, {"asset_id": "112017627761537300677970694411480436137463788285461926216623118683376584067380", "price": "0.99", "size": "54.18", "side": "SELL", "hash": "ebec9a22f58d6dc333b8df1826da568b84f5588d", "best_bid": "0.04", "best_ask": "0.96"}], "timestamp": "1769384245204", "event_type": "price_change"}}
{"_local_timestamp": "2026-01-25T23:37:25.553592+00:00", "data": {"market": "0xe34b0bb444471383c90cec5dc69f813a9b3545444de919995ff030dac71248a3", "price_changes": [{"asset_id": "97700218319543636355981601320594824056628162134390242486220190083801463286044", "price": "0.01", "size": "69.89", "side": "BUY", "hash": "aaf9fb0f9b954c70f1b96fcd4c3f2560d33389b0", "best_bid": "0.04", "best_ask": "0.96"}, {"asset_id": "112017627761537300677970694411480436137463788285461926216623118683376584067380", "price": "0.99", "size": "69.89", "side": "SELL", "hash": "7609f15b570909378efbb8f9d45cdba07e166a41", "best_bid": "0.04", "best_ask": "0.96"}], "timestamp": "1769384245490", "event_type": "price_change"}}
{"_local_timestamp": "2026-01-25T23:37:25.712629+00:00", "data": {"market": "0xd37f59b9c51a3548d7c9740bc25c619c6da8e03acc850023295b8b983ad20527", "price_changes": [{"asset_id": "10617636138259507285477245956793545272020397648836479158116719634159970012149", "price": "0.03", "size": "12.74", "side": "BUY", "hash": "d13b799a14c43a04d82bc443c34a5e7c2347cc52", "best_bid": "0.04", "best_ask": "0.96"}, {"asset_id": "86922549432847869502897076242034045799267352097019606723721140333601147624472", "price": "0.97", "size": "12.74", "side": "SELL", "hash": "e28a2a6eb569e9e2495449526fb73419223b3e4d", "best_bid": "0.04", "best_ask": "0.96"}], "timestamp": "1769384245645", "event_type": "price_change"}}
{"_local_timestamp": "2026-01-25T23:37:26.019403+00:00", "data": {"market": "0xd37f59b9c51a3548d7c9740bc25c619c6da8e03acc850023295b8b983ad20527", "price_changes": [{"asset_id": "10617636138259507285477245956793545272020397648836479158116719634159970012149", "price": "0.01", "size": "69.12", "side": "BUY", "hash": "4c3939719d849990d817b506613a758dcda1f9da", "best_bid": "0.04", "best_ask": "0.96"}, {"asset_id": "86922549432847869502897076242034045799267352097019606723721140333601147624472", "price": "0.99", "size": "69.12", "side": "SELL", "hash": "b39cd29be2ae7b370ebb660815f7f17649cb92a2", "best_bid": "0.04", "best_ask": "0.96"}], "timestamp": "1769384245950", "event_type": "price_change"}}
{"_local_timestamp": "2026-01-25T23:37:26.019980+00:00", "data": {"market": "0xd37f59b9c51a3548d7c9740bc25c619c6da8e03acc850023295b8b983ad20527", "price_changes": [{"asset_id": "10617636138259507285477245956793545272020397648836479158116719634159970012149", "price": "0.03", "size": "20.79", "side": "BUY", "hash": "386eca0036517c60ed6f75633487d8ede4916f85", "best_bid": "0.04", "best_ask": "0.96"}, {"asset_id": "86922549432847869502897076242034045799267352097019606723721140333601147624472", "price": "0.97", "size": "20.79", "side": "SELL", "hash": "352aab41f79a77610ea076df7be46e54a6e08dba", "best_bid": "0.04", "best_ask": "0.96"}], "timestamp": "1769384245951", "event_type": "price_change"}}
{"_local_timestamp": "2026-01-25T23:37:31.071694+00:00", "data": {"market": "0x362912f5cb655b81e79607e953e32f84dac1572753e2391f459e450478265749", "price_changes": [{"asset_id": "111407420641358258640954942754741699488195643075274492825410595934557666593274", "price": "0.01", "size": "51.27", "side": "BUY", "hash": "9b82f0c4135eddeb328d4350f29b46148f9d3561", "best_bid": "0.04", "best_ask": "0.96"}, {"asset_id": "3087755881123905074274619731943137130363325113969580976113246712649699904601", "price": "0.99", "size": "51.27", "side": "SELL", "hash": "3d1a33822ef755f6d1d5483a525909c784a30eab", "best_bid": "0.04", "best_ask": "0.96"}], "timestamp": "1769384250995", "event_type": "price_change"}}
{"_local_timestamp": "2026-01-25T23:37:31.072256+00:00", "data": {"market": "0x02682a05084a43701a3e859db3f03bc7035ea32f4ae3c139855869bbb49062f1", "price_changes": [{"asset_id": "30887032572101121332187740667215094491657468658291043188830897987016129354142", "price": "0.01", "size": "54.19", "side": "BUY", "hash": "f795f27013cc42c538111e48c4dbcc6b96dab1ff", "best_bid": "0.04", "best_ask": "0.96"}, {"asset_id": "35192903361091849248940718645499233167215841826837724281530158082247957989629", "price": "0.99", "size": "54.19", "side": "SELL", "hash": "46e8cafbfd5f51015fc90cfc99ee7df491ff7fae", "best_bid": "0.04", "best_ask": "0.96"}], "timestamp": "1769384250995", "event_type": "price_change"}}
{"_local_timestamp": "2026-01-25T23:37:31.224191+00:00", "data": {"market": "0x362912f5cb655b81e79607e953e32f84dac1572753e2391f459e450478265749", "price_changes": [{"asset_id": "111407420641358258640954942754741699488195643075274492825410595934557666593274", "price": "0.01", "size": "69.74", "side": "BUY", "hash": "8a2181f4dc461cc9f4165d88a52a475979356b38", "best_bid": "0.04", "best_ask": "0.96"}, {"asset_id": "3087755881123905074274619731943137130363325113969580976113246712649699904601", "price": "0.99", "size": "69.74", "side": "SELL", "hash": "b6a9128cba41a3ce04c7c697890f38921c086b21", "best_bid": "0.04", "best_ask": "0.96"}], "timestamp": "1769384251154", "event_type": "price_change"}}
{"_local_timestamp": "2026-01-25T23:37:31.553514+00:00", "data": {"market": "0x02682a05084a43701a3e859db3f03bc7035ea32f4ae3c139855869bbb49062f1", "price_changes": [{"asset_id": "30887032572101121332187740667215094491657468658291043188830897987016129354142", "price": "0.01", "size": "69.89", "side": "BUY", "hash": "b3fc6bd8dc2766717f3b10fb023dc1d303651950", "best_bid": "0.04", "best_ask": "0.96"}, {"asset_id": "35192903361091849248940718645499233167215841826837724281530158082247957989629", "price": "0.99", "size": "69.89", "side": "SELL", "hash": "009ae5a4624e64a4e4f4c8d135b68d947a75709e", "best_bid": "0.04", "best_ask": "0.96"}], "timestamp": "1769384251452", "event_type": "price_change"}}
{"_local_timestamp": "2026-01-25T23:37:34.279237+00:00", "data": {"market": "0x19a4d27add00ce27b2a3cf7ca5705ef8aade39a8ece33948e9b2f02c192152be", "price_changes": [{"asset_id": "95172888027281193001519088464175285929338904438226458264353810757936163188044", "price": "0.03", "size": "9.19", "side": "BUY", "hash": "46a7599fbdce9006cde0ded3e803abedd7e2901f", "best_bid": "0.04", "best_ask": "0.96"}, {"asset_id": "71489691980085603195785483996972122116532490472494448024267486667321753208838", "price": "0.97", "size": "9.19", "side": "SELL", "hash": "992a04a38b032d38963d5b9df0dc50e3e7e17683", "best_bid": "0.04", "best_ask": "0.96"}], "timestamp": "1769384254214", "event_type": "price_change"}}
{"_local_timestamp": "2026-01-25T23:37:34.509795+00:00", "data": {"market": "0x19a4d27add00ce27b2a3cf7ca5705ef8aade39a8ece33948e9b2f02c192152be", "price_changes": [{"asset_id": "95172888027281193001519088464175285929338904438226458264353810757936163188044", "price": "0.02", "size": "182.48", "side": "BUY", "hash": "76c54d6b0f474eb76c3bce6d6391b236c6336229", "best_bid": "0.04", "best_ask": "0.96"}, {"asset_id": "71489691980085603195785483996972122116532490472494448024267486667321753208838", "price": "0.98", "size": "182.48", "side": "SELL", "hash": "6cc35797a162aab8b60557a83306ae30c3094346", "best_bid": "0.04", "best_ask": "0.96"}], "timestamp": "1769384254432", "event_type": "price_change"}}
{"_local_timestamp": "2026-01-25T23:37:34.510271+00:00", "data": {"market": "0x19a4d27add00ce27b2a3cf7ca5705ef8aade39a8ece33948e9b2f02c192152be", "price_changes": [{"asset_id": "95172888027281193001519088464175285929338904438226458264353810757936163188044", "price": "0.01", "size": "67.05", "side": "BUY", "hash": "1746199f17fd3c2e5d78d3d2e0d3fb7063d69626", "best_bid": "0.04", "best_ask": "0.96"}, {"asset_id": "71489691980085603195785483996972122116532490472494448024267486667321753208838", "price": "0.99", "size": "67.05", "side": "SELL", "hash": "ddaa273c97db40db307e0ac900e795cb4a70f430", "best_bid": "0.04", "best_ask": "0.96"}], "timestamp": "1769384254432", "event_type": "price_change"}}
{"_local_timestamp": "2026-01-25T23:37:34.510697+00:00", "data": {"market": "0x19a4d27add00ce27b2a3cf7ca5705ef8aade39a8ece33948e9b2f02c192152be", "price_changes": [{"asset_id": "95172888027281193001519088464175285929338904438226458264353810757936163188044", "price": "0.03", "size": "18.99", "side": "BUY", "hash": "8eb05a7fc12889dc318cbccd4d03faaa0639341d", "best_bid": "0.04", "best_ask": "0.96"}, {"asset_id": "71489691980085603195785483996972122116532490472494448024267486667321753208838", "price": "0.97", "size": "18.99", "side": "SELL", "hash": "88a138cbac121a4be2997abcde265afc6363a5da", "best_bid": "0.04", "best_ask": "0.96"}], "timestamp": "1769384254434", "event_type": "price_change"}}
{"_local_timestamp": "2026-01-25T23:37:35.591067+00:00", "data": {"market": "0xd3b44443f0b39d21079f0a72254268aee2103faf72e7b3109d8ae6764d416152", "price_changes": [{"asset_id": "74195830337912012661209045255656626007077925536496881065075327343195504551863", "price": "0.03", "size": "12.74", "side": "BUY", "hash": "fd31975557120dbdf3118c920e54b74a02334c5d", "best_bid": "0.04", "best_ask": "0.96"}, {"asset_id": "66916591411271253117011649722470760555098136629103997561616701243019995826796", "price": "0.97", "size": "12.74", "side": "SELL", "hash": "21af3e1ac3586f510bdab6c30b25ad2356a5625f", "best_bid": "0.04", "best_ask": "0.96"}], "timestamp": "1769384255523", "event_type": "price_change"}}
{"_local_timestamp": "2026-01-25T23:37:35.868537+00:00", "data": {"market": "0xd3b44443f0b39d21079f0a72254268aee2103faf72e7b3109d8ae6764d416152", "price_changes": [{"asset_id": "74195830337912012661209045255656626007077925536496881065075327343195504551863", "price": "0.01", "size": "68.98", "side": "BUY", "hash": "9d4aac3826fb32832976998b3ea39e1c2b2c2404", "best_bid": "0.04", "best_ask": "0.96"}, {"asset_id": "66916591411271253117011649722470760555098136629103997561616701243019995826796", "price": "0.99", "size": "68.98", "side": "SELL", "hash": "8491eded3172cf01fd7cef14caa2c1df23634552", "best_bid": "0.04", "best_ask": "0.96"}], "timestamp": "1769384255804", "event_type": "price_change"}}
{"_local_timestamp": "2026-01-25T23:37:35.872153+00:00", "data": {"market": "0xd3b44443f0b39d21079f0a72254268aee2103faf72e7b3109d8ae6764d416152", "price_changes": [{"asset_id": "74195830337912012661209045255656626007077925536496881065075327343195504551863", "price": "0.03", "size": "20.65", "side": "BUY", "hash": "cf954fa39a9341a0cc97f38ad13a71dc86431816", "best_bid": "0.04", "best_ask": "0.96"}, {"asset_id": "66916591411271253117011649722470760555098136629103997561616701243019995826796", "price": "0.97", "size": "20.65", "side": "SELL", "hash": "8dd4a8e287fa796858b041daa3089bf365dc2544", "best_bid": "0.04", "best_ask": "0.96"}], "timestamp": "1769384255805", "event_type": "price_change"}}
{"_local_timestamp": "2026-01-25T23:37:42.872225+00:00", "data": {"market": "0xff1e6a0275ae0216a33abece78285de646cdd4ba37dc1d772578538be60329cf", "price_changes": [{"asset_id": "106561211697967626756310720720604256534170407941019828744583005941010546193812", "price": "0.05", "size": "0", "side": "BUY", "hash": "ec9c303f9c679e1d61af57c405e8ecbcf0bfb244", "best_bid": "0.06", "best_ask": "0.97"}, {"asset_id": "114506854111387970982269268959966858458499074507684750968073343843315627005834", "price": "0.95", "size": "0", "side": "SELL", "hash": "2642eedcc7c144d05aa955ddb03cd74be27c2830", "best_bid": "0.03", "best_ask": "0.94"}], "timestamp": "1769384262763", "event_type": "price_change"}}
{"_local_timestamp": "2026-01-25T23:37:44.654402+00:00", "data": {"market": "0x19a4d27add00ce27b2a3cf7ca5705ef8aade39a8ece33948e9b2f02c192152be", "price_changes": [{"asset_id": "95172888027281193001519088464175285929338904438226458264353810757936163188044", "price": "0.05", "size": "23.99", "side": "BUY", "hash": "576c4ec834d5e0840ed6c057cf2dc9bf5e56a8d1", "best_bid": "0.05", "best_ask": "0.96"}, {"asset_id": "71489691980085603195785483996972122116532490472494448024267486667321753208838", "price": "0.95", "size": "23.99", "side": "SELL", "hash": "f00b13a5fc8121b6542abd281a9a2c263692b2a3", "best_bid": "0.04", "best_ask": "0.95"}], "timestamp": "1769384264547", "event_type": "price_change"}}
{"_local_timestamp": "2026-01-25T23:37:44.659912+00:00", "data": {"market": "0x9fa8edb100e017bd5633db881bfd7f39d8feaf23e488562c7863403b75f2b72a", "price_changes": [{"asset_id": "109451912333674650094373499600078573206027333544803021029937231897917192478306", "price": "0.05", "size": "23.99", "side": "BUY", "hash": "beb8403a8724a8af6f35d864823b68c16bbb2a4f", "best_bid": "0.05", "best_ask": "0.96"}, {"asset_id": "97737434631321407607330081336176115113173871167799349015045656897989017126587", "price": "0.95", "size": "23.99", "side": "SELL", "hash": "6bc28dcd47cb272ea2898873a74e96bc8ad5c4d7", "best_bid": "0.04", "best_ask": "0.95"}], "timestamp": "1769384264547", "event_type": "price_change"}}
{"_local_timestamp": "2026-01-25T23:37:44.660396+00:00", "data": {"market": "0xc62866c20352813ae054a41ad3f1b92292b5300d7bfc1143e9c6a41823fe5992", "price_changes": [{"asset_id": "52759588103937363641506362299958930445030460683736633313225430843238074731373", "price": "0.05", "size": "23.99", "side": "BUY", "hash": "118dd4a540cb04afcde183304fdddd4dbe0a1a14", "best_bid": "0.05", "best_ask": "0.96"}, {"asset_id": "47133502308465006307801302772561127971127968369129604946852551581692421961280", "price": "0.95", "size": "23.99", "side": "SELL", "hash": "c2158f5a41fa13a71f395a4c034ed80cd6f2467c", "best_bid": "0.04", "best_ask": "0.95"}], "timestamp": "1769384264547", "event_type": "price_change"}}
{"_local_timestamp": "2026-01-25T23:37:44.946487+00:00", "data": {"market": "0xd37f59b9c51a3548d7c9740bc25c619c6da8e03acc850023295b8b983ad20527", "price_changes": [{"asset_id": "10617636138259507285477245956793545272020397648836479158116719634159970012149", "price": "0.05", "size": "23.99", "side": "BUY", "hash": "db76df86637063f7850f7d86c073e4d82967b945", "best_bid": "0.05", "best_ask": "0.96"}, {"asset_id": "86922549432847869502897076242034045799267352097019606723721140333601147624472", "price": "0.95", "size": "23.99", "side": "SELL", "hash": "45e49495b4d0ce5e7963eb200337f42d41485654", "best_bid": "0.04", "best_ask": "0.95"}], "timestamp": "1769384264851", "event_type": "price_change"}}
{"_local_timestamp": "2026-01-25T23:37:44.953791+00:00", "data": {"market": "0xb4cb0ae16ba9281cdc5a5d20f324d0d0a7753d6116d0d905e0a8742ae8d0c244", "price_changes": [{"asset_id": "102744846850187161380521503397483870162725714816776510187447472868892066157718", "price": "0.05", "size": "23.99", "side": "BUY", "hash": "f4875086aa957b1f141938618499d8dfe4193772", "best_bid": "0.05", "best_ask": "0.96"}, {"asset_id": "37092008225382265270014902992349514323037660984217265301171261275317809758859", "price": "0.95", "size": "23.99", "side": "SELL", "hash": "35cd084a8497dd7c630529fe12b9d486a50e409f", "best_bid": "0.04", "best_ask": "0.95"}], "timestamp": "1769384264851", "event_type": "price_change"}}
{"_local_timestamp": "2026-01-25T23:37:44.954348+00:00", "data": {"market": "0xd3b44443f0b39d21079f0a72254268aee2103faf72e7b3109d8ae6764d416152", "price_changes": [{"asset_id": "74195830337912012661209045255656626007077925536496881065075327343195504551863", "price": "0.05", "size": "23.99", "side": "BUY", "hash": "f4ea8be1eb95f3d2d3cfbefc00827120676a7244", "best_bid": "0.05", "best_ask": "0.96"}, {"asset_id": "66916591411271253117011649722470760555098136629103997561616701243019995826796", "price": "0.95", "size": "23.99", "side": "SELL", "hash": "7ed9af9038f359e245a6eca32a86e0020b647b70", "best_bid": "0.04", "best_ask": "0.95"}], "timestamp": "1769384264851", "event_type": "price_change"}}
{"_local_timestamp": "2026-01-25T23:37:46.004256+00:00", "data": {"market": "0xc62866c20352813ae054a41ad3f1b92292b5300d7bfc1143e9c6a41823fe5992", "price_changes": [{"asset_id": "52759588103937363641506362299958930445030460683736633313225430843238074731373", "price": "0.03", "size": "12.74", "side": "BUY", "hash": "e5f25978dea29a2582dbdece6719abf19a1a790d", "best_bid": "0.05", "best_ask": "0.96"}, {"asset_id": "47133502308465006307801302772561127971127968369129604946852551581692421961280", "price": "0.97", "size": "12.74", "side": "SELL", "hash": "779a58c90004835d49eb7d6d0b44bc80548aeb45", "best_bid": "0.04", "best_ask": "0.95"}], "timestamp": "1769384265870", "event_type": "price_change"}}
{"_local_timestamp": "2026-01-25T23:37:46.004948+00:00", "data": {"market": "0xff1e6a0275ae0216a33abece78285de646cdd4ba37dc1d772578538be60329cf", "price_changes": [{"asset_id": "106561211697967626756310720720604256534170407941019828744583005941010546193812", "price": "0.01", "size": "51.48", "side": "BUY", "hash": "a5a27eb29e3faf1c70af6a1f266a3a92ffb28760", "best_bid": "0.06", "best_ask": "0.97"}, {"asset_id": "114506854111387970982269268959966858458499074507684750968073343843315627005834", "price": "0.99", "size": "51.48", "side": "SELL", "hash": "fad44b9e2966f164021347b2536345d3e74f9628", "best_bid": "0.03", "best_ask": "0.94"}], "timestamp": "1769384265870", "event_type": "price_change"}}
{"_local_timestamp": "2026-01-25T23:37:46.262266+00:00", "data": {"market": "0xff1e6a0275ae0216a33abece78285de646cdd4ba37dc1d772578538be60329cf", "price_changes": [{"asset_id": "106561211697967626756310720720604256534170407941019828744583005941010546193812", "price": "0.03", "size": "22.58", "side": "BUY", "hash": "26a8fd2205435a31dabdc6559abca3e3d3599109", "best_bid": "0.06", "best_ask": "0.97"}, {"asset_id": "114506854111387970982269268959966858458499074507684750968073343843315627005834", "price": "0.97", "size": "22.58", "side": "SELL", "hash": "0220d3073c70c0f5c65ce24ea0ad89d1bcda9239", "best_bid": "0.03", "best_ask": "0.94"}], "timestamp": "1769384266110", "event_type": "price_change"}}
{"_local_timestamp": "2026-01-25T23:37:46.263990+00:00", "data": {"market": "0xc62866c20352813ae054a41ad3f1b92292b5300d7bfc1143e9c6a41823fe5992", "price_changes": [{"asset_id": "52759588103937363641506362299958930445030460683736633313225430843238074731373", "price": "0.01", "size": "68.98", "side": "BUY", "hash": "687bf90e3b0de6565a2e134b96eb5fb74b66e4c6", "best_bid": "0.05", "best_ask": "0.96"}, {"asset_id": "47133502308465006307801302772561127971127968369129604946852551581692421961280", "price": "0.99", "size": "68.98", "side": "SELL", "hash": "4e77b3e22ab04d59fbf67cbaa04b759429fdcc55", "best_bid": "0.04", "best_ask": "0.95"}], "timestamp": "1769384266110", "event_type": "price_change"}}
{"_local_timestamp": "2026-01-25T23:37:46.264513+00:00", "data": {"market": "0xff1e6a0275ae0216a33abece78285de646cdd4ba37dc1d772578538be60329cf", "price_changes": [{"asset_id": "106561211697967626756310720720604256534170407941019828744583005941010546193812", "price": "0.01", "size": "58.97", "side": "BUY", "hash": "e19505321024e6fc6265eefbc74039ee2ec86cf3", "best_bid": "0.06", "best_ask": "0.97"}, {"asset_id": "114506854111387970982269268959966858458499074507684750968073343843315627005834", "price": "0.99", "size": "58.97", "side": "SELL", "hash": "4107af06142f77004434027348fa92492aa0c107", "best_bid": "0.03", "best_ask": "0.94"}], "timestamp": "1769384266111", "event_type": "price_change"}}
{"_local_timestamp": "2026-01-25T23:37:46.264964+00:00", "data": {"market": "0xc62866c20352813ae054a41ad3f1b92292b5300d7bfc1143e9c6a41823fe5992", "price_changes": [{"asset_id": "52759588103937363641506362299958930445030460683736633313225430843238074731373", "price": "0.03", "size": "20.65", "side": "BUY", "hash": "427969fa429c4f2ca4b57551672adc9974153011", "best_bid": "0.05", "best_ask": "0.96"}, {"asset_id": "47133502308465006307801302772561127971127968369129604946852551581692421961280", "price": "0.97", "size": "20.65", "side": "SELL", "hash": "e1a9e327e6f06dabb753abcc1d2fdd5fef2925e9", "best_bid": "0.04", "best_ask": "0.95"}], "timestamp": "1769384266111", "event_type": "price_change"}}
{"_local_timestamp": "2026-01-25T23:37:46.307878+00:00", "data": {"market": "0xff1e6a0275ae0216a33abece78285de646cdd4ba37dc1d772578538be60329cf", "price_changes": [{"asset_id": "106561211697967626756310720720604256534170407941019828744583005941010546193812", "price": "0.06", "size": "0", "side": "BUY", "hash": "0c0212294713c8ebd84c208f4a9300468203613e", "best_bid": "0.03", "best_ask": "0.97"}, {"asset_id": "114506854111387970982269268959966858458499074507684750968073343843315627005834", "price": "0.94", "size": "0", "side": "SELL", "hash": "40315edd1892d8c04bb17004986c40551edaa7bc", "best_bid": "0.03", "best_ask": "0.97"}], "timestamp": "1769384266142", "event_type": "price_change"}}
{"_local_timestamp": "2026-01-25T23:37:46.417488+00:00", "data": {"market": "0xff1e6a0275ae0216a33abece78285de646cdd4ba37dc1d772578538be60329cf", "price_changes": [{"asset_id": "106561211697967626756310720720604256534170407941019828744583005941010546193812", "price": "0.04", "size": "5.47", "side": "BUY", "hash": "0228baad4a9e42fe7abc4f99a028af77a212b0f5", "best_bid": "0.04", "best_ask": "0.97"}, {"asset_id": "114506854111387970982269268959966858458499074507684750968073343843315627005834", "price": "0.96", "size": "5.47", "side": "SELL", "hash": "203eba180347d2f97800e74f6cb95fefe62b427d", "best_bid": "0.03", "best_ask": "0.96"}], "timestamp": "1769384266237", "event_type": "price_change"}}
{"_local_timestamp": "2026-01-25T23:37:46.746042+00:00", "data": {"market": "0xc62866c20352813ae054a41ad3f1b92292b5300d7bfc1143e9c6a41823fe5992", "price_changes": [{"asset_id": "52759588103937363641506362299958930445030460683736633313225430843238074731373", "price": "0.01", "size": "59.79", "side": "BUY", "hash": "09a19dd7fb40461fe4d366d48ca37bc0538e9768", "best_bid": "0.05", "best_ask": "0.96"}, {"asset_id": "47133502308465006307801302772561127971127968369129604946852551581692421961280", "price": "0.99", "size": "59.79", "side": "SELL", "hash": "1d16b85d2e8232a93851b29e168278d081cfd2da", "best_bid": "0.04", "best_ask": "0.95"}], "timestamp": "1769384266619", "event_type": "price_change"}}
{"_local_timestamp": "2026-01-25T23:37:46.967635+00:00", "data": {"market": "0xc62866c20352813ae054a41ad3f1b92292b5300d7bfc1143e9c6a41823fe5992", "price_changes": [{"asset_id": "52759588103937363641506362299958930445030460683736633313225430843238074731373", "price": "0.01", "size": "68.99", "side": "BUY", "hash": "f9d6a67aa3dc58748137ba64a8777be16c1cf712", "best_bid": "0.05", "best_ask": "0.96"}, {"asset_id": "47133502308465006307801302772561127971127968369129604946852551581692421961280", "price": "0.99", "size": "68.99", "side": "SELL", "hash": "5a5161642236e2c20230678558552500d2f4ceaf", "best_bid": "0.04", "best_ask": "0.95"}], "timestamp": "1769384266853", "event_type": "price_change"}}
{"_local_timestamp": "2026-01-25T23:37:47.462221+00:00", "data": {"market": "0x9fa8edb100e017bd5633db881bfd7f39d8feaf23e488562c7863403b75f2b72a", "price_changes": [{"asset_id": "109451912333674650094373499600078573206027333544803021029937231897917192478306", "price": "0.01", "size": "105.98", "side": "BUY", "hash": "04a5a1d06373758aed30ccab6fb5ce8df58643ee", "best_bid": "0.05", "best_ask": "0.96"}, {"asset_id": "97737434631321407607330081336176115113173871167799349015045656897989017126587", "price": "0.99", "size": "105.98", "side": "SELL", "hash": "fa81946b1032b7475bc343726c0cd43d894b5ddd", "best_bid": "0.04", "best_ask": "0.95"}], "timestamp": "1769384267364", "event_type": "price_change"}}
{"_local_timestamp": "2026-01-25T23:37:47.760686+00:00", "data": {"market": "0x9fa8edb100e017bd5633db881bfd7f39d8feaf23e488562c7863403b75f2b72a", "price_changes": [{"asset_id": "109451912333674650094373499600078573206027333544803021029937231897917192478306", "price": "0.01", "size": "119.23", "side": "BUY", "hash": "87738b6e1d4f3fd893a91221a47edf4885ba99b8", "best_bid": "0.05", "best_ask": "0.96"}, {"asset_id": "97737434631321407607330081336176115113173871167799349015045656897989017126587", "price": "0.99", "size": "119.23", "side": "SELL", "hash": "b8cc7b267a405852b83ddf76dc8edf5b6403f3ea", "best_bid": "0.04", "best_ask": "0.95"}], "timestamp": "1769384267648", "event_type": "price_change"}}
{"_local_timestamp": "2026-01-25T23:37:47.903200+00:00", "data": {"market": "0x02cb406686b0e5a2c761b60dba57df5a5aa10de657d8b55c2059de1594262ef8", "price_changes": [{"asset_id": "71618273512612611641687286878012843492831706235643168298378352373515271932764", "price": "0.01", "size": "48.04", "side": "BUY", "hash": "a6e75998b6d007bb7689230202efe34d3e71bb8f", "best_bid": "0.06", "best_ask": "0.96"}, {"asset_id": "17525878431794376842013117355232170057074541567126099913305204894084193326972", "price": "0.99", "size": "48.04", "side": "SELL", "hash": "a97296a7b02aea4195471de9f714de2a5abe3b90", "best_bid": "0.04", "best_ask": "0.94"}], "timestamp": "1769384267793", "event_type": "price_change"}}
{"_local_timestamp": "2026-01-25T23:37:48.191703+00:00", "data": {"market": "0x02cb406686b0e5a2c761b60dba57df5a5aa10de657d8b55c2059de1594262ef8", "price_changes": [{"asset_id": "71618273512612611641687286878012843492831706235643168298378352373515271932764", "price": "0.01", "size": "62.84", "side": "BUY", "hash": "812918cc7b0333e807dc54097f39761123440cd7", "best_bid": "0.06", "best_ask": "0.96"}, {"asset_id": "17525878431794376842013117355232170057074541567126099913305204894084193326972", "price": "0.99", "size": "62.84", "side": "SELL", "hash": "b76c9430c19f23dd762e0357b966467c54781494", "best_bid": "0.04", "best_ask": "0.94"}], "timestamp": "1769384268085", "event_type": "price_change"}}
{"_local_timestamp": "2026-01-25T23:37:50.077737+00:00", "data": {"market": "0xd37f59b9c51a3548d7c9740bc25c619c6da8e03acc850023295b8b983ad20527", "price_changes": [{"asset_id": "10617636138259507285477245956793545272020397648836479158116719634159970012149", "price": "0.04", "size": "0", "side": "BUY", "hash": "7c6b5616191475debe3228534a2225512c183a00", "best_bid": "0.05", "best_ask": "0.96"}, {"asset_id": "86922549432847869502897076242034045799267352097019606723721140333601147624472", "price": "0.96", "size": "0", "side": "SELL", "hash": "2bddcaf3d8c0ed552edead7af91c6752bb15f3cd", "best_bid": "0.04", "best_ask": "0.95"}], "timestamp": "1769384269957", "event_type": "price_change"}}
{"_local_timestamp": "2026-01-25T23:37:50.083808+00:00", "data": {"market": "0xc62866c20352813ae054a41ad3f1b92292b5300d7bfc1143e9c6a41823fe5992", "price_changes": [{"asset_id": "52759588103937363641506362299958930445030460683736633313225430843238074731373", "price": "0.04", "size": "0", "side": "BUY", "hash": "887dca3dd1ba6c384b5ae2b0d176175bdbef6598", "best_bid": "0.05", "best_ask": "0.96"}, {"asset_id": "47133502308465006307801302772561127971127968369129604946852551581692421961280", "price": "0.96", "size": "0", "side": "SELL", "hash": "d67252f3d9dde7ce1bd18ab98e5302892ffc288f", "best_bid": "0.04", "best_ask": "0.95"}], "timestamp": "1769384269957", "event_type": "price_change"}}
{"_local_timestamp": "2026-01-25T23:37:50.085534+00:00", "data": {"market": "0x9fa8edb100e017bd5633db881bfd7f39d8feaf23e488562c7863403b75f2b72a", "price_changes": [{"asset_id": "109451912333674650094373499600078573206027333544803021029937231897917192478306", "price": "0.04", "size": "0", "side": "BUY", "hash": "e289cf369c648e086803809cbec55db112f581ef", "best_bid": "0.05", "best_ask": "0.96"}, {"asset_id": "97737434631321407607330081336176115113173871167799349015045656897989017126587", "price": "0.96", "size": "0", "side": "SELL", "hash": "6d61d01d539dc199ffddf086a4fec3c5142cd5b7", "best_bid": "0.04", "best_ask": "0.95"}], "timestamp": "1769384269957", "event_type": "price_change"}}
{"_local_timestamp": "2026-01-25T23:37:50.086074+00:00", "data": {"market": "0xb4cb0ae16ba9281cdc5a5d20f324d0d0a7753d6116d0d905e0a8742ae8d0c244", "price_changes": [{"asset_id": "102744846850187161380521503397483870162725714816776510187447472868892066157718", "price": "0.04", "size": "0", "side": "BUY", "hash": "5e94ae87b219a95188bd949c5bc2e63bd4557003", "best_bid": "0.05", "best_ask": "0.96"}, {"asset_id": "37092008225382265270014902992349514323037660984217265301171261275317809758859", "price": "0.96", "size": "0", "side": "SELL", "hash": "f0bf13c4234ec53656819a19de909d34d85f4e44", "best_bid": "0.04", "best_ask": "0.95"}], "timestamp": "1769384269957", "event_type": "price_change"}}
{"_local_timestamp": "2026-01-25T23:37:50.086582+00:00", "data": {"market": "0x19a4d27add00ce27b2a3cf7ca5705ef8aade39a8ece33948e9b2f02c192152be", "price_changes": [{"asset_id": "95172888027281193001519088464175285929338904438226458264353810757936163188044", "price": "0.04", "size": "0", "side": "BUY", "hash": "ad1d0b01be72dd1d541aca92937345155ba94c13", "best_bid": "0.05", "best_ask": "0.96"}, {"asset_id": "71489691980085603195785483996972122116532490472494448024267486667321753208838", "price": "0.96", "size": "0", "side": "SELL", "hash": "43cd17acf725b7b3455f0739cb8372deb56138f1", "best_bid": "0.04", "best_ask": "0.95"}], "timestamp": "1769384269957", "event_type": "price_change"}}
{"_local_timestamp": "2026-01-25T23:37:50.094382+00:00", "data": {"market": "0xd3b44443f0b39d21079f0a72254268aee2103faf72e7b3109d8ae6764d416152", "price_changes": [{"asset_id": "74195830337912012661209045255656626007077925536496881065075327343195504551863", "price": "0.04", "size": "0", "side": "BUY", "hash": "506c0a4dcedfe31ecfe57baaf2f73453efcb0ab6", "best_bid": "0.05", "best_ask": "0.96"}, {"asset_id": "66916591411271253117011649722470760555098136629103997561616701243019995826796", "price": "0.96", "size": "0", "side": "SELL", "hash": "f82b04bc2c84c0b4842d72ee1a7f33abc349a027", "best_bid": "0.04", "best_ask": "0.95"}], "timestamp": "1769384269957", "event_type": "price_change"}}
{"_local_timestamp": "2026-01-25T23:37:50.160783+00:00", "data": {"market": "0x9fa8edb100e017bd5633db881bfd7f39d8feaf23e488562c7863403b75f2b72a", "price_changes": [{"asset_id": "109451912333674650094373499600078573206027333544803021029937231897917192478306", "price": "0.06", "size": "5.47", "side": "BUY", "hash": "802db36fc2f5aabedca1515f07a65e9040f4ec65", "best_bid": "0.06", "best_ask": "0.96"}, {"asset_id": "97737434631321407607330081336176115113173871167799349015045656897989017126587", "price": "0.94", "size": "5.47", "side": "SELL", "hash": "8b475710f2ec9854a3f66c0ae3bed2f23ebeab5e", "best_bid": "0.04", "best_ask": "0.94"}], "timestamp": "1769384270012", "event_type": "price_change"}}
{"_local_timestamp": "2026-01-25T23:37:50.161437+00:00", "data": {"market": "0xb4cb0ae16ba9281cdc5a5d20f324d0d0a7753d6116d0d905e0a8742ae8d0c244", "price_changes": [{"asset_id": "102744846850187161380521503397483870162725714816776510187447472868892066157718", "price": "0.06", "size": "5.47", "side": "BUY", "hash": "2e46bd528d7bb590e872d950ede95461233b3cc3", "best_bid": "0.06", "best_ask": "0.96"}, {"asset_id": "37092008225382265270014902992349514323037660984217265301171261275317809758859", "price": "0.94", "size": "5.47", "side": "SELL", "hash": "10e52127732b7d8bd7600df0ec90b2c4bb0cc10f", "best_bid": "0.04", "best_ask": "0.94"}], "timestamp": "1769384270012", "event_type": "price_change"}}
{"_local_timestamp": "2026-01-25T23:37:50.161949+00:00", "data": {"market": "0xc62866c20352813ae054a41ad3f1b92292b5300d7bfc1143e9c6a41823fe5992", "price_changes": [{"asset_id": "52759588103937363641506362299958930445030460683736633313225430843238074731373", "price": "0.06", "size": "5.47", "side": "BUY", "hash": "b3c8c75f9480d78089b1d291ddbbc9fdf2d3181b", "best_bid": "0.06", "best_ask": "0.96"}, {"asset_id": "47133502308465006307801302772561127971127968369129604946852551581692421961280", "price": "0.94", "size": "5.47", "side": "SELL", "hash": "0701aa280e82dfe526159961ab94abcd2b79a691", "best_bid": "0.04", "best_ask": "0.94"}], "timestamp": "1769384270012", "event_type": "price_change"}}
{"_local_timestamp": "2026-01-25T23:37:50.168380+00:00", "data": {"market": "0x19a4d27add00ce27b2a3cf7ca5705ef8aade39a8ece33948e9b2f02c192152be", "price_changes": [{"asset_id": "95172888027281193001519088464175285929338904438226458264353810757936163188044", "price": "0.06", "size": "5.47", "side": "BUY", "hash": "30e6416d9c0f0d6bfa775649da2c4dd38ea1730a", "best_bid": "0.06", "best_ask": "0.96"}, {"asset_id": "71489691980085603195785483996972122116532490472494448024267486667321753208838", "price": "0.94", "size": "5.47", "side": "SELL", "hash": "ba227c2f11d9573ecc4014397cdc715348afcf4f", "best_bid": "0.04", "best_ask": "0.94"}], "timestamp": "1769384270012", "event_type": "price_change"}}
{"_local_timestamp": "2026-01-25T23:37:50.252207+00:00", "data": {"market": "0xd3b44443f0b39d21079f0a72254268aee2103faf72e7b3109d8ae6764d416152", "price_changes": [{"asset_id": "74195830337912012661209045255656626007077925536496881065075327343195504551863", "price": "0.06", "size": "5.47", "side": "BUY", "hash": "72c11d04f5b989cfc658da7218ddc2a5ca4e6646", "best_bid": "0.06", "best_ask": "0.96"}, {"asset_id": "66916591411271253117011649722470760555098136629103997561616701243019995826796", "price": "0.94", "size": "5.47", "side": "SELL", "hash": "e098d90c0400e3d1c6dbc6d60e418235aadb29a6", "best_bid": "0.04", "best_ask": "0.94"}], "timestamp": "1769384270012", "event_type": "price_change"}}
{"_local_timestamp": "2026-01-25T23:37:50.252831+00:00", "data": {"market": "0xd37f59b9c51a3548d7c9740bc25c619c6da8e03acc850023295b8b983ad20527", "price_changes": [{"asset_id": "10617636138259507285477245956793545272020397648836479158116719634159970012149", "price": "0.06", "size": "5.47", "side": "BUY", "hash": "8da6e6187a52926e6213b3945b459ae37e699723", "best_bid": "0.06", "best_ask": "0.96"}, {"asset_id": "86922549432847869502897076242034045799267352097019606723721140333601147624472", "price": "0.94", "size": "5.47", "side": "SELL", "hash": "2018cd3cf5686eff0e252dd58696f27c7c93a744", "best_bid": "0.04", "best_ask": "0.94"}], "timestamp": "1769384270012", "event_type": "price_change"}}
{"_local_timestamp": "2026-01-25T23:39:10.877607+00:00", "data": {"market": "0x9fa8edb100e017bd5633db881bfd7f39d8feaf23e488562c7863403b75f2b72a", "price_changes": [{"asset_id": "109451912333674650094373499600078573206027333544803021029937231897917192478306", "price": "0.05", "size": "0", "side": "BUY", "hash": "56d3ea155da31468e74cbdd84252d1875c3d1adb", "best_bid": "0.06", "best_ask": "0.96"}, {"asset_id": "97737434631321407607330081336176115113173871167799349015045656897989017126587", "price": "0.95", "size": "0", "side": "SELL", "hash": "60d185c0dbbca4cf7c5f4c5e99a37cabb2ced606", "best_bid": "0.04", "best_ask": "0.94"}], "timestamp": "1769384350808", "event_type": "price_change"}}
{"_local_timestamp": "2026-01-25T23:39:10.974120+00:00", "data": {"market": "0xd37f59b9c51a3548d7c9740bc25c619c6da8e03acc850023295b8b983ad20527", "price_changes": [{"asset_id": "10617636138259507285477245956793545272020397648836479158116719634159970012149", "price": "0.05", "size": "0", "side": "BUY", "hash": "e82d907837dd1033909ffdd5d265d5259093ba14", "best_bid": "0.06", "best_ask": "0.96"}, {"asset_id": "86922549432847869502897076242034045799267352097019606723721140333601147624472", "price": "0.95", "size": "0", "side": "SELL", "hash": "546aaf6ec1890dd2c6bcacfcfd9b9b3ac4ceb8c1", "best_bid": "0.04", "best_ask": "0.94"}], "timestamp": "1769384350905", "event_type": "price_change"}}
{"_local_timestamp": "2026-01-25T23:39:10.974796+00:00", "data": {"market": "0x19a4d27add00ce27b2a3cf7ca5705ef8aade39a8ece33948e9b2f02c192152be", "price_changes": [{"asset_id": "95172888027281193001519088464175285929338904438226458264353810757936163188044", "price": "0.05", "size": "0", "side": "BUY", "hash": "54a20204891a5c3ce0105c9d5c7989583b2e925a", "best_bid": "0.06", "best_ask": "0.96"}, {"asset_id": "71489691980085603195785483996972122116532490472494448024267486667321753208838", "price": "0.95", "size": "0", "side": "SELL", "hash": "878d51af0da5b50b91b2df3849159a89a8ba18ea", "best_bid": "0.04", "best_ask": "0.94"}], "timestamp": "1769384350905", "event_type": "price_change"}}
{"_local_timestamp": "2026-01-25T23:39:11.066172+00:00", "data": {"market": "0xd3b44443f0b39d21079f0a72254268aee2103faf72e7b3109d8ae6764d416152", "price_changes": [{"asset_id": "74195830337912012661209045255656626007077925536496881065075327343195504551863", "price": "0.05", "size": "0", "side": "BUY", "hash": "8873130855fdf442c248712cdccebc9f722279f2", "best_bid": "0.06", "best_ask": "0.96"}, {"asset_id": "66916591411271253117011649722470760555098136629103997561616701243019995826796", "price": "0.95", "size": "0", "side": "SELL", "hash": "8279ed3ee6ce95cde10c13455b47a53bd18eccc0", "best_bid": "0.04", "best_ask": "0.94"}], "timestamp": "1769384350997", "event_type": "price_change"}}
{"_local_timestamp": "2026-01-25T23:39:11.170458+00:00", "data": {"market": "0xc62866c20352813ae054a41ad3f1b92292b5300d7bfc1143e9c6a41823fe5992", "price_changes": [{"asset_id": "52759588103937363641506362299958930445030460683736633313225430843238074731373", "price": "0.05", "size": "0", "side": "BUY", "hash": "1bad72797119c78f9c20dea40e5dfb283c3e5915", "best_bid": "0.06", "best_ask": "0.96"}, {"asset_id": "47133502308465006307801302772561127971127968369129604946852551581692421961280", "price": "0.95", "size": "0", "side": "SELL", "hash": "34425bb6bb4b2e112d9b840b33c45b5d1f699b9e", "best_bid": "0.04", "best_ask": "0.94"}], "timestamp": "1769384351102", "event_type": "price_change"}}
{"_local_timestamp": "2026-01-25T23:39:11.176795+00:00", "data": {"market": "0xb4cb0ae16ba9281cdc5a5d20f324d0d0a7753d6116d0d905e0a8742ae8d0c244", "price_changes": [{"asset_id": "102744846850187161380521503397483870162725714816776510187447472868892066157718", "price": "0.05", "size": "0", "side": "BUY", "hash": "22966878f06a0fe61c4d6e16bd0387ae4b6590cc", "best_bid": "0.06", "best_ask": "0.96"}, {"asset_id": "37092008225382265270014902992349514323037660984217265301171261275317809758859", "price": "0.95", "size": "0", "side": "SELL", "hash": "b4900a8b98fc7953f014c2176b8e16cd6638dd98", "best_bid": "0.04", "best_ask": "0.94"}], "timestamp": "1769384351102", "event_type": "price_change"}}
{"_local_timestamp": "2026-01-25T23:39:11.661211+00:00", "data": {"market": "0xe34b0bb444471383c90cec5dc69f813a9b3545444de919995ff030dac71248a3", "price_changes": [{"asset_id": "97700218319543636355981601320594824056628162134390242486220190083801463286044", "price": "0.05", "size": "23.99", "side": "BUY", "hash": "d24da185eb2ed70de55e584f879b1c45410044ad", "best_bid": "0.05", "best_ask": "0.96"}, {"asset_id": "112017627761537300677970694411480436137463788285461926216623118683376584067380", "price": "0.95", "size": "23.99", "side": "SELL", "hash": "2e6ad894f7f627f051595a057aaf77daf48c00d3", "best_bid": "0.04", "best_ask": "0.95"}], "timestamp": "1769384351594", "event_type": "price_change"}}
{"_local_timestamp": "2026-01-25T23:39:11.766236+00:00", "data": {"market": "0x02682a05084a43701a3e859db3f03bc7035ea32f4ae3c139855869bbb49062f1", "price_changes": [{"asset_id": "30887032572101121332187740667215094491657468658291043188830897987016129354142", "price": "0.05", "size": "23.99", "side": "BUY", "hash": "702e5efbf9b0c843cd29eb7b9b3f2cb3cbf9dc54", "best_bid": "0.05", "best_ask": "0.96"}, {"asset_id": "35192903361091849248940718645499233167215841826837724281530158082247957989629", "price": "0.95", "size": "23.99", "side": "SELL", "hash": "283db11841c0d3788f1bfae582c4a267516eaa59", "best_bid": "0.04", "best_ask": "0.95"}], "timestamp": "1769384351692", "event_type": "price_change"}}
{"_local_timestamp": "2026-01-25T23:39:11.766918+00:00", "data": {"market": "0x362912f5cb655b81e79607e953e32f84dac1572753e2391f459e450478265749", "price_changes": [{"asset_id": "111407420641358258640954942754741699488195643075274492825410595934557666593274", "price": "0.05", "size": "23.99", "side": "BUY", "hash": "61ef07ee42d2b397c8fade7400d8fd05d862098d", "best_bid": "0.05", "best_ask": "0.96"}, {"asset_id": "3087755881123905074274619731943137130363325113969580976113246712649699904601", "price": "0.95", "size": "23.99", "side": "SELL", "hash": "501ab629254fac0313618d9fd71580693f9b9e1b", "best_bid": "0.04", "best_ask": "0.95"}], "timestamp": "1769384351692", "event_type": "price_change"}}
{"_local_timestamp": "2026-01-25T23:39:15.153724+00:00", "data": {"market": "0xe34b0bb444471383c90cec5dc69f813a9b3545444de919995ff030dac71248a3", "price_changes": [{"asset_id": "97700218319543636355981601320594824056628162134390242486220190083801463286044", "price": "0.04", "size": "0", "side": "BUY", "hash": "c527eee37a459ec8c2a268c19b0f77582039ed28", "best_bid": "0.05", "best_ask": "0.96"}, {"asset_id": "112017627761537300677970694411480436137463788285461926216623118683376584067380", "price": "0.96", "size": "0", "side": "SELL", "hash": "3a38d214c18cc313cd7f23e0b7b88e0acdba213d", "best_bid": "0.04", "best_ask": "0.95"}], "timestamp": "1769384355031", "event_type": "price_change"}}
{"_local_timestamp": "2026-01-25T23:39:15.154396+00:00", "data": {"market": "0x19a4d27add00ce27b2a3cf7ca5705ef8aade39a8ece33948e9b2f02c192152be", "price_changes": [{"asset_id": "95172888027281193001519088464175285929338904438226458264353810757936163188044", "price": "0.06", "size": "0", "side": "BUY", "hash": "f332c8fd0fee098fdf950a4cf03fa7d8a9572728", "best_bid": "0.03", "best_ask": "0.96"}, {"asset_id": "71489691980085603195785483996972122116532490472494448024267486667321753208838", "price": "0.94", "size": "0", "side": "SELL", "hash": "2c51c50e00c363b2d9152bed63c318c8e6b28463", "best_bid": "0.04", "best_ask": "0.97"}], "timestamp": "1769384355031", "event_type": "price_change"}}
{"_local_timestamp": "2026-01-25T23:39:15.154973+00:00", "data": {"market": "0x362912f5cb655b81e79607e953e32f84dac1572753e2391f459e450478265749", "price_changes": [{"asset_id": "111407420641358258640954942754741699488195643075274492825410595934557666593274", "price": "0.04", "size": "0", "side": "BUY", "hash": "ee351778ab6a313a2d867ea89394be5d8c9eca0a", "best_bid": "0.05", "best_ask": "0.96"}, {"asset_id": "3087755881123905074274619731943137130363325113969580976113246712649699904601", "price": "0.96", "size": "0", "side": "SELL", "hash": "39082f7927551fb6028b31bf8dd38c63f39f6c55", "best_bid": "0.04", "best_ask": "0.95"}], "timestamp": "1769384355032", "event_type": "price_change"}}
{"_local_timestamp": "2026-01-25T23:39:15.155486+00:00", "data": {"market": "0x9fa8edb100e017bd5633db881bfd7f39d8feaf23e488562c7863403b75f2b72a", "price_changes": [{"asset_id": "109451912333674650094373499600078573206027333544803021029937231897917192478306", "price": "0.06", "size": "0", "side": "BUY", "hash": "739e67cfb71aeb88e40a5d7330b1ab241b9e2211", "best_bid": "0.03", "best_ask": "0.96"}, {"asset_id": "97737434631321407607330081336176115113173871167799349015045656897989017126587", "price": "0.94", "size": "0", "side": "SELL", "hash": "bc1fe64a138de0a7a96bf42ee295f81b7830512f", "best_bid": "0.04", "best_ask": "0.97"}], "timestamp": "1769384355032", "event_type": "price_change"}}
{"_local_timestamp": "2026-01-25T23:39:15.159511+00:00", "data": {"market": "0x02682a05084a43701a3e859db3f03bc7035ea32f4ae3c139855869bbb49062f1", "price_changes": [{"asset_id": "30887032572101121332187740667215094491657468658291043188830897987016129354142", "price": "0.04", "size": "0", "side": "BUY", "hash": "4df367b43e52e4867256716826c81de31726c5f1", "best_bid": "0.05", "best_ask": "0.96"}, {"asset_id": "35192903361091849248940718645499233167215841826837724281530158082247957989629", "price": "0.96", "size": "0", "side": "SELL", "hash": "d6dae6c05ba5899676ea7677705f2aa9a31ac03d", "best_bid": "0.04", "best_ask": "0.95"}], "timestamp": "1769384355032", "event_type": "price_change"}}
{"_local_timestamp": "2026-01-25T23:39:15.160209+00:00", "data": {"market": "0xd3b44443f0b39d21079f0a72254268aee2103faf72e7b3109d8ae6764d416152", "price_changes": [{"asset_id": "74195830337912012661209045255656626007077925536496881065075327343195504551863", "price": "0.06", "size": "0", "side": "BUY", "hash": "d6fa86a76d37486878b58aa272ab2e305dfda518", "best_bid": "0.03", "best_ask": "0.96"}, {"asset_id": "66916591411271253117011649722470760555098136629103997561616701243019995826796", "price": "0.94", "size": "0", "side": "SELL", "hash": "94713ef22866b08074908367f2ca5d6bce30aff0", "best_bid": "0.04", "best_ask": "0.97"}], "timestamp": "1769384355032", "event_type": "price_change"}}
{"_local_timestamp": "2026-01-25T23:39:15.160723+00:00", "data": {"market": "0xb4cb0ae16ba9281cdc5a5d20f324d0d0a7753d6116d0d905e0a8742ae8d0c244", "price_changes": [{"asset_id": "102744846850187161380521503397483870162725714816776510187447472868892066157718", "price": "0.06", "size": "0", "side": "BUY", "hash": "82d9869ec6eb40b1ce28b811de5d3f7d589abfdd", "best_bid": "0.03", "best_ask": "0.96"}, {"asset_id": "37092008225382265270014902992349514323037660984217265301171261275317809758859", "price": "0.94", "size": "0", "side": "SELL", "hash": "361dd6532181fd91cdd01b2dac7bfe45549cc6ab", "best_bid": "0.04", "best_ask": "0.97"}], "timestamp": "1769384355032", "event_type": "price_change"}}
{"_local_timestamp": "2026-01-25T23:39:15.161218+00:00", "data": {"market": "0xc62866c20352813ae054a41ad3f1b92292b5300d7bfc1143e9c6a41823fe5992", "price_changes": [{"asset_id": "52759588103937363641506362299958930445030460683736633313225430843238074731373", "price": "0.06", "size": "0", "side": "BUY", "hash": "10c8f5184ae487274d6031961423ac0b1f2d7439", "best_bid": "0.03", "best_ask": "0.96"}, {"asset_id": "47133502308465006307801302772561127971127968369129604946852551581692421961280", "price": "0.94", "size": "0", "side": "SELL", "hash": "250c12b05ee45befef059470ed756e8c7c8015f5", "best_bid": "0.04", "best_ask": "0.97"}], "timestamp": "1769384355032", "event_type": "price_change"}}
{"_local_timestamp": "2026-01-25T23:39:15.162248+00:00", "data": {"market": "0xd37f59b9c51a3548d7c9740bc25c619c6da8e03acc850023295b8b983ad20527", "price_changes": [{"asset_id": "10617636138259507285477245956793545272020397648836479158116719634159970012149", "price": "0.06", "size": "0", "side": "BUY", "hash": "6526d01fc0ec4ca2af781082f9781e03cace4d83", "best_bid": "0.03", "best_ask": "0.96"}, {"asset_id": "86922549432847869502897076242034045799267352097019606723721140333601147624472", "price": "0.94", "size": "0", "side": "SELL", "hash": "23883b21a26f02d0c476b5389a855ce9aed4162f", "best_bid": "0.04", "best_ask": "0.97"}], "timestamp": "1769384355032", "event_type": "price_change"}}
{"_local_timestamp": "2026-01-25T23:39:15.279875+00:00", "data": {"market": "0xd37f59b9c51a3548d7c9740bc25c619c6da8e03acc850023295b8b983ad20527", "price_changes": [{"asset_id": "10617636138259507285477245956793545272020397648836479158116719634159970012149", "price": "0.04", "size": "5.47", "side": "BUY", "hash": "28ca095677e6fb9ad4869c86ae4a60b9d72ea17f", "best_bid": "0.04", "best_ask": "0.96"}, {"asset_id": "86922549432847869502897076242034045799267352097019606723721140333601147624472", "price": "0.96", "size": "5.47", "side": "SELL", "hash": "cb317e1195b44b3b701b083bb0a915d973a328c8", "best_bid": "0.04", "best_ask": "0.96"}], "timestamp": "1769384355181", "event_type": "price_change"}}
{"_local_timestamp": "2026-01-25T23:39:15.280585+00:00", "data": {"market": "0x362912f5cb655b81e79607e953e32f84dac1572753e2391f459e450478265749", "price_changes": [{"asset_id": "111407420641358258640954942754741699488195643075274492825410595934557666593274", "price": "0.06", "size": "5.47", "side": "BUY", "hash": "4756d53b2dbb1937afa9e91e9e159a7b001d6234", "best_bid": "0.06", "best_ask": "0.96"}, {"asset_id": "3087755881123905074274619731943137130363325113969580976113246712649699904601", "price": "0.94", "size": "5.47", "side": "SELL", "hash": "c4daa5b6718a6deaf215c8420644f7a4270f4d8f", "best_bid": "0.04", "best_ask": "0.94"}], "timestamp": "1769384355181", "event_type": "price_change"}}
{"_local_timestamp": "2026-01-25T23:39:15.281181+00:00", "data": {"market": "0xe34b0bb444471383c90cec5dc69f813a9b3545444de919995ff030dac71248a3", "price_changes": [{"asset_id": "97700218319543636355981601320594824056628162134390242486220190083801463286044", "price": "0.06", "size": "5.47", "side": "BUY", "hash": "44fcd3481fa0ff5b32a92f7b35f972c0958d7df8", "best_bid": "0.06", "best_ask": "0.96"}, {"asset_id": "112017627761537300677970694411480436137463788285461926216623118683376584067380", "price": "0.94", "size": "5.47", "side": "SELL", "hash": "be9c63050b125e9a6d8ee5b99b9af9b08abcf02a", "best_bid": "0.04", "best_ask": "0.94"}], "timestamp": "1769384355181", "event_type": "price_change"}}
{"_local_timestamp": "2026-01-25T23:39:15.282050+00:00", "data": {"market": "0x9fa8edb100e017bd5633db881bfd7f39d8feaf23e488562c7863403b75f2b72a", "price_changes": [{"asset_id": "109451912333674650094373499600078573206027333544803021029937231897917192478306", "price": "0.04", "size": "5.47", "side": "BUY", "hash": "5e4c0dbd58f7f2e55badc10a3c38234ab5214f47", "best_bid": "0.04", "best_ask": "0.96"}, {"asset_id": "97737434631321407607330081336176115113173871167799349015045656897989017126587", "price": "0.96", "size": "5.47", "side": "SELL", "hash": "51209a07bfd89e9f548b8da0c5914117238c019b", "best_bid": "0.04", "best_ask": "0.96"}], "timestamp": "1769384355181", "event_type": "price_change"}}
{"_local_timestamp": "2026-01-25T23:39:15.282654+00:00", "data": {"market": "0x19a4d27add00ce27b2a3cf7ca5705ef8aade39a8ece33948e9b2f02c192152be", "price_changes": [{"asset_id": "95172888027281193001519088464175285929338904438226458264353810757936163188044", "price": "0.04", "size": "5.47", "side": "BUY", "hash": "0b80ffdb3b6afe6596f19aafe8072925fb157771", "best_bid": "0.04", "best_ask": "0.96"}, {"asset_id": "71489691980085603195785483996972122116532490472494448024267486667321753208838", "price": "0.96", "size": "5.47", "side": "SELL", "hash": "5aa3fbbfa50396b57b73c399b63229f9e5704109", "best_bid": "0.04", "best_ask": "0.96"}], "timestamp": "1769384355181", "event_type": "price_change"}}
{"_local_timestamp": "2026-01-25T23:39:15.283213+00:00", "data": {"market": "0xb4cb0ae16ba9281cdc5a5d20f324d0d0a7753d6116d0d905e0a8742ae8d0c244", "price_changes": [{"asset_id": "102744846850187161380521503397483870162725714816776510187447472868892066157718", "price": "0.04", "size": "5.47", "side": "BUY", "hash": "d8e0499cc0a088f47d921b590c51104aa1d4ccd5", "best_bid": "0.04", "best_ask": "0.96"}, {"asset_id": "37092008225382265270014902992349514323037660984217265301171261275317809758859", "price": "0.96", "size": "5.47", "side": "SELL", "hash": "a8588c7dfed776aa9fc75532800d73b5d87830d7", "best_bid": "0.04", "best_ask": "0.96"}], "timestamp": "1769384355181", "event_type": "price_change"}}
{"_local_timestamp": "2026-01-25T23:39:15.283740+00:00", "data": {"market": "0xc62866c20352813ae054a41ad3f1b92292b5300d7bfc1143e9c6a41823fe5992", "price_changes": [{"asset_id": "52759588103937363641506362299958930445030460683736633313225430843238074731373", "price": "0.04", "size": "5.47", "side": "BUY", "hash": "65f621d304d1a9b508eec54d0964626c3851e6d9", "best_bid": "0.04", "best_ask": "0.96"}, {"asset_id": "47133502308465006307801302772561127971127968369129604946852551581692421961280", "price": "0.96", "size": "5.47", "side": "SELL", "hash": "857e63aadc3fd39deb368ac85d062bc292c3e2f7", "best_bid": "0.04", "best_ask": "0.96"}], "timestamp": "1769384355181", "event_type": "price_change"}}
{"_local_timestamp": "2026-01-25T23:39:15.284279+00:00", "data": {"market": "0xd3b44443f0b39d21079f0a72254268aee2103faf72e7b3109d8ae6764d416152", "price_changes": [{"asset_id": "74195830337912012661209045255656626007077925536496881065075327343195504551863", "price": "0.04", "size": "5.47", "side": "BUY", "hash": "f5a8604c2b2788c1d643b5e8ca8637efe522aa8a", "best_bid": "0.04", "best_ask": "0.96"}, {"asset_id": "66916591411271253117011649722470760555098136629103997561616701243019995826796", "price": "0.96", "size": "5.47", "side": "SELL", "hash": "bdd8da355087fc99de888a1539ea9fc89daf23d2", "best_bid": "0.04", "best_ask": "0.96"}], "timestamp": "1769384355181", "event_type": "price_change"}}
{"_local_timestamp": "2026-01-25T23:39:15.284828+00:00", "data": {"market": "0x02682a05084a43701a3e859db3f03bc7035ea32f4ae3c139855869bbb49062f1", "price_changes": [{"asset_id": "30887032572101121332187740667215094491657468658291043188830897987016129354142", "price": "0.06", "size": "5.47", "side": "BUY", "hash": "b02c5e9fe513dd41d7ecd23e13dff5b1a37c543c", "best_bid": "0.06", "best_ask": "0.96"}, {"asset_id": "35192903361091849248940718645499233167215841826837724281530158082247957989629", "price": "0.94", "size": "5.47", "side": "SELL", "hash": "79ef4a773d3191845ade95b7a2b4c58cb792e029", "best_bid": "0.04", "best_ask": "0.94"}], "timestamp": "1769384355182", "event_type": "price_change"}}
