{"_local_timestamp": "2026-01-25T23:33:35.656592+00:00", "data": [{"market": "0xf51607fb5ef641ac5bba06ced0c497ecca038f010c6a78947a3cc2adcf0d86b7", "asset_id": "51608546776780288607506114199605032507662896760905181902893674078914900996024", "timestamp": "1769384012751", "hash": "88e39a469309cc947b7dcea0f0a1e8641d6fb059", "bids": [{"price": "0.001", "size": "100049"}, {"price": "0.002", "size": "55000"}, {"price": "0.008", "size": "155"}, {"price": "0.01", "size": "27008"}, {"price": "0.011", "size": "55710"}, {"price": "0.08", "size": "155"}, {"price": "0.097", "size": "100"}, {"price": "0.099", "size": "100"}, {"price": "0.1", "size": "3500"}, {"price": "0.101", "size": "10000"}, {"price": "0.47", "size": "100"}, {"price": "0.49", "size": "100"}, {"price": "0.497", "size": "200"}, {"price": "0.499", "size": "100"}, {"price": "0.5", "size": "176"}, {"price": "0.75", "size": "60"}, {"price": "0.767", "size": "60"}, {"price": "0.768", "size": "88"}, {"price": "0.769", "size": "60"}, {"price": "0.77", "size": "60"}, {"price": "0.771", "size": "53"}, {"price": "0.772", "size": "25"}, {"price": "0.773", "size": "5.32"}, {"price": "0.99", "size": "5"}, {"price": "0.991", "size": "500"}, {"price": "0.999", "size": "113298"}], "asks": [], "event_type": "book", "last_trade_price": ""}, {"market": "0xf51607fb5ef641ac5bba06ced0c497ecca038f010c6a78947a3cc2adcf0d86b7", "asset_id": "68683942633697084725036835213804622791934367014208146174418479991147761539557", "timestamp": "1769384012751", "hash": "e2a3acfafbf26085d52f55f29e282b865738668a", "bids": [], "asks": [{"price": "0.999", "size": "100049"}, {"price": "0.998", "size": "55000"}, {"price": "0.992", "size": "155"}, {"price": "0.99", "size": "27008"}, {"price": "0.989", "size": "55710"}, {"price": "0.92", "size": "155"}, {"price": "0.903", "size": "100"}, {"price": "0.901", "size": "100"}, {"price": "0.9", "size": "3500"}, {"price": "0.899", "size": "10000"}, {"price": "0.53", "size": "100"}, {"price": "0.51", "size": "100"}, {"price": "0.503", "size": "200"}, {"price": "0.501", "size": "100"}, {"price": "0.5", "size": "176"}, {"price": "0.25", "size": "60"}, {"price": "0.233", "size": "60"}, {"price": "0.232", "size": "88"}, {"price": "0.231", "size": "60"}, {"price": "0.23", "size": "60"}, {"price": "0.229", "size": "53"}, {"price": "0.228", "size": "25"}, {"price": "0.227", "size": "5.32"}, {"price": "0.01", "size": "5"}, {"price": "0.009", "size": "500"}, {"price": "0.001", "size": "113298"}], "event_type": "book", "last_trade_price": ""}]}
{"_local_timestamp": "2026-01-25T23:33:45.886784+00:00", "data": {"market": "0xf51607fb5ef641ac5bba06ced0c497ecca038f010c6a78947a3cc2adcf0d86b7", "price_changes": [{"asset_id": "51608546776780288607506114199605032507662896760905181902893674078914900996024", "price": "0.999", "size": "100000", "side": "BUY", "hash": "2bd539ebd0a3853bf11aa9ce25866c879eebab4e", "best_bid": "0.999", "best_ask": "1"}, {"asset_id": "68683942633697084725036835213804622791934367014208146174418479991147761539557", "price": "0.001", "size": "100000", "side": "SELL", "hash": "8bcbed467647956f55becf353a04b8df774445e1", "best_bid": "0", "best_ask": "0.001"}], "timestamp": "1769384025808", "event_type": "price_change"}}
{"_local_timestamp": "2026-01-25T23:33:47.596439+00:00", "data": {"market": "0xf51607fb5ef641ac5bba06ced0c497ecca038f010c6a78947a3cc2adcf0d86b7", "price_changes": [{"asset_id": "51608546776780288607506114199605032507662896760905181902893674078914900996024", "price": "0.999", "size": "102497", "side": "BUY", "hash": "0d38491b239e3ef732d5357d646dec2870a20eb8", "best_bid": "0.999", "best_ask": "1"}, {"asset_id": "68683942633697084725036835213804622791934367014208146174418479991147761539557", "price": "0.001", "size": "102497", "side": "SELL", "hash": "c5e6afce254e83e1555a905be38e34d5d3c994b1", "best_bid": "0", "best_ask": "0.001"}], "timestamp": "1769384027504", "event_type": "price_change"}}
{"_local_timestamp": "2026-01-25T23:33:47.996109+00:00", "data": {"market": "0xf51607fb5ef641ac5bba06ced0c497ecca038f010c6a78947a3cc2adcf0d86b7", "price_changes": [{"asset_id": "51608546776780288607506114199605032507662896760905181902893674078914900996024", "price": "0.999", "size": "104993", "side": "BUY", "hash": "6d297147bd95370a3144acf6e029b8acb1bbc4d4", "best_bid": "0.999", "best_ask": "1"}, {"asset_id": "68683942633697084725036835213804622791934367014208146174418479991147761539557", "price": "0.001", "size": "104993", "side": "SELL", "hash": "72b42d04311f6ddf8a6f3c21a6ea00c555d29275", "best_bid": "0", "best_ask": "0.001"}], "timestamp": "1769384027913", "event_type": "price_change"}}
{"_local_timestamp": "2026-01-25T23:33:48.524678+00:00", "data": {"market": "0xf51607fb5ef641ac5bba06ced0c497ecca038f010c6a78947a3cc2adcf0d86b7", "price_changes": [{"asset_id": "51608546776780288607506114199605032507662896760905181902893674078914900996024", "price": "0.999", "size": "107488", "side": "BUY", "hash": "1088493f9e77458a4bfb07065d722f75d561c6d9", "best_bid": "0.999", "best_ask": "1"}, {"asset_id": "68683942633697084725036835213804622791934367014208146174418479991147761539557", "price": "0.001", "size": "107488", "side": "SELL", "hash": "5da91122f5b026e5db8e8e8879f99016014407a2", "best_bid": "0", "best_ask": "0.001"}], "timestamp": "1769384028430", "event_type": "price_change"}}
{"_local_timestamp": "2026-01-25T23:33:49.322391+00:00", "data": {"market": "0xf51607fb5ef641ac5bba06ced0c497ecca038f010c6a78947a3cc2adcf0d86b7", "price_changes": [{"asset_id": "51608546776780288607506114199605032507662896760905181902893674078914900996024", "price": "0.999", "size": "108111", "side": "BUY", "hash": "600fd76eb226f8096e202527503c655c37323953", "best_bid": "0.999", "best_ask": "1"}, {"asset_id": "68683942633697084725036835213804622791934367014208146174418479991147761539557", "price": "0.001", "size": "108111", "side": "SELL", "hash": "066ad4abb52193ce47d612bfeee5dc7ede198ca4", "best_bid": "0", "best_ask": "0.001"}], "timestamp": "1769384029237", "event_type": "price_change"}}
{"_local_timestamp": "2026-01-25T23:33:49.815840+00:00", "data": {"market": "0xf51607fb5ef641ac5bba06ced0c497ecca038f010c6a78947a3cc2adcf0d86b7", "price_changes": [{"asset_id": "51608546776780288607506114199605032507662896760905181902893674078914900996024", "price": "0.999", "size": "108733", "side": "BUY", "hash": "f5b35fd60f5d72faeb33686f01a7eac78a928f51", "best_bid": "0.999", "best_ask": "1"}, {"asset_id": "68683942633697084725036835213804622791934367014208146174418479991147761539557", "price": "0.001", "size": "108733", "side": "SELL", "hash": "c3e260ffa580da7673a93e90301028a11f80ce22", "best_bid": "0", "best_ask": "0.001"}], "timestamp": "1769384029724", "event_type": "price_change"}}
{"_local_timestamp": "2026-01-25T23:33:51.635898+00:00", "data": {"market": "0xf51607fb5ef641ac5bba06ced0c497ecca038f010c6a78947a3cc2adcf0d86b7", "price_changes": [{"asset_id": "51608546776780288607506114199605032507662896760905181902893674078914900996024", "price": "0.999", "size": "108888", "side": "BUY", "hash": "a6e7a1f6a0ff5020bb6ef99abc5244b8bf968dcb", "best_bid": "0.999", "best_ask": "1"}, {"asset_id": "68683942633697084725036835213804622791934367014208146174418479991147761539557", "price": "0.001", "size": "108888", "side": "SELL", "hash": "9d3096bfe86ccc349dfd15a3c835cce1ad3c99a6", "best_bid": "0", "best_ask": "0.001"}], "timestamp": "1769384031551", "event_type": "price_change"}}
{"_local_timestamp": "2026-01-25T23:33:52.619692+00:00", "data": {"market": "0xf51607fb5ef641ac5bba06ced0c497ecca038f010c6a78947a3cc2adcf0d86b7", "price_changes": [{"asset_id": "51608546776780288607506114199605032507662896760905181902893674078914900996024", "price": "0.999", "size": "109042", "side": "BUY", "hash": "dc719b9800f7cae644f47b7d8caafff594af1bb3", "best_bid": "0.999", "best_ask": "1"}, {"asset_id": "68683942633697084725036835213804622791934367014208146174418479991147761539557", "price": "0.001", "size": "109042", "side": "SELL", "hash": "7c34ad89d9ac44110c9180604945b7ac36bd012b", "best_bid": "0", "best_ask": "0.001"}], "timestamp": "1769384032533", "event_type": "price_change"}}
{"_local_timestamp": "2026-01-25T23:33:52.992267+00:00", "data": {"market": "0xf51607fb5ef641ac5bba06ced0c497ecca038f010c6a78947a3cc2adcf0d86b7", "price_changes": [{"asset_id": "51608546776780288607506114199605032507662896760905181902893674078914900996024", "price": "0.999", "size": "109195", "side": "BUY", "hash": "15f9afc6765023034f6aea981ba29583eb42e24e", "best_bid": "0.999", "best_ask": "1"}, {"asset_id": "68683942633697084725036835213804622791934367014208146174418479991147761539557", "price": "0.001", "size": "109195", "side": "SELL", "hash": "6acd466eebecdc0d9b710b08fcd8c69e12541047", "best_bid": "0", "best_ask": "0.001"}], "timestamp": "1769384032904", "event_type": "price_change"}}
{"_local_timestamp": "2026-01-25T23:33:54.556024+00:00", "data": {"market": "0xf51607fb5ef641ac5bba06ced0c497ecca038f010c6a78947a3cc2adcf0d86b7", "price_changes": [{"asset_id": "51608546776780288607506114199605032507662896760905181902893674078914900996024", "price": "0.999", "size": "109232", "side": "BUY", "hash": "86538fddde94a5a44ba0dc0b07555c6e96c94aac", "best_bid": "0.999", "best_ask": "1"}, {"asset_id": "68683942633697084725036835213804622791934367014208146174418479991147761539557", "price": "0.001", "size": "109232", "side": "SELL", "hash": "80d4c06a6db9fd1e41b320470daee636601aa556", "best_bid": "0", "best_ask": "0.001"}], "timestamp": "1769384034483", "event_type": "price_change"}}
{"_local_timestamp": "2026-01-25T23:33:55.244698+00:00", "data": {"market": "0xf51607fb5ef641ac5bba06ced0c497ecca038f010c6a78947a3cc2adcf0d86b7", "price_changes": [{"asset_id": "51608546776780288607506114199605032507662896760905181902893674078914900996024", "price": "0.999", "size": "109268", "side": "BUY", "hash": "211fc77426dc9ab16a58925c1d203d2ac604b303", "best_bid": "0.999", "best_ask": "1"}, {"asset_id": "68683942633697084725036835213804622791934367014208146174418479991147761539557", "price": "0.001", "size": "109268", "side": "SELL", "hash": "753253d6aa7b10cb47878ec4f9f4cf74fd482e4b", "best_bid": "0", "best_ask": "0.001"}], "timestamp": "1769384035139", "event_type": "price_change"}}
{"_local_timestamp": "2026-01-25T23:33:55.621476+00:00", "data": {"market": "0xf51607fb5ef641ac5bba06ced0c497ecca038f010c6a78947a3cc2adcf0d86b7", "price_changes": [{"asset_id": "51608546776780288607506114199605032507662896760905181902893674078914900996024", "price": "0.999", "size": "109303", "side": "BUY", "hash": "bec70d143c294417249709c90ecf369537713d77", "best_bid": "0.999", "best_ask": "1"}, {"asset_id": "68683942633697084725036835213804622791934367014208146174418479991147761539557", "price": "0.001", "size": "109303", "side": "SELL", "hash": "c6b57aaab2ba5bf3a0f4983642b8ee8e2fcf224d", "best_bid": "0", "best_ask": "0.001"}], "timestamp": "1769384035536", "event_type": "price_change"}}
{"_local_timestamp": "2026-01-25T23:34:08.006570+00:00", "data": {"market": "0xf51607fb5ef641ac5bba06ced0c497ecca038f010c6a78947a3cc2adcf0d86b7", "price_changes": [{"asset_id": "51608546776780288607506114199605032507662896760905181902893674078914900996024", "price": "0.999", "size": "104993", "side": "BUY", "hash": "6d94db91c059068d254323489474e2c7f7359173", "best_bid": "0.999", "best_ask": "1"}, {"asset_id": "68683942633697084725036835213804622791934367014208146174418479991147761539557", "price": "0.001", "size": "104993", "side": "SELL", "hash": "4ce76e5d1fb95807aa953c117503bd4d04df8dc4", "best_bid": "0", "best_ask": "0.001"}], "timestamp": "1769384047889", "event_type": "price_change"}}
{"_local_timestamp": "2026-01-25T23:34:08.646511+00:00", "data": {"market": "0xf51607fb5ef641ac5bba06ced0c497ecca038f010c6a78947a3cc2adcf0d86b7", "price_changes": [{"asset_id": "51608546776780288607506114199605032507662896760905181902893674078914900996024", "price": "0.999", "size": "100000", "side": "BUY", "hash": "7eeedb7dba68ae3edf4a14fc819fee09e20ed636", "best_bid": "0.999", "best_ask": "1"}, {"asset_id": "68683942633697084725036835213804622791934367014208146174418479991147761539557", "price": "0.001", "size": "100000", "side": "SELL", "hash": "3e2711edaf3c131e2a84b351032ca73ab6be2bbb", "best_bid": "0", "best_ask": "0.001"}], "timestamp": "1769384048563", "event_type": "price_change"}}
{"_local_timestamp": "2026-01-25T23:34:09.287236+00:00", "data": {"market": "0xf51607fb5ef641ac5bba06ced0c497ecca038f010c6a78947a3cc2adcf0d86b7", "price_changes": [{"asset_id": "51608546776780288607506114199605032507662896760905181902893674078914900996024", "price": "0.999", "size": "90000", "side": "BUY", "hash": "b7921e5471f2f6ed40346940b2b6bb706ae7ea57", "best_bid": "0.999", "best_ask": "1"}, {"asset_id": "68683942633697084725036835213804622791934367014208146174418479991147761539557", "price": "0.001", "size": "90000", "side": "SELL", "hash": "f5fb747573a6ed023c714ed97d879a10f8ca26f1", "best_bid": "0", "best_ask": "0.001"}], "timestamp": "1769384049208", "event_type": "price_change"}}
{"_local_timestamp": "2026-01-25T23:34:11.194883+00:00", "data": {"market": "0xf51607fb5ef641ac5bba06ced0c497ecca038f010c6a78947a3cc2adcf0d86b7", "price_changes": [{"asset_id": "51608546776780288607506114199605032507662896760905181902893674078914900996024", "price": "0.999", "size": "92500", "side": "BUY", "hash": "ef0ecf8e69874aee1c6922d79f6d069335ff956f", "best_bid": "0.999", "best_ask": "1"}, {"asset_id": "68683942633697084725036835213804622791934367014208146174418479991147761539557", "price": "0.001", "size": "92500", "side": "SELL", "hash": "7e7e21ecc549165932246b8c5c3de9ab7cfbfaae", "best_bid": "0", "best_ask": "0.001"}], "timestamp": "1769384051120", "event_type": "price_change"}}
{"_local_timestamp": "2026-01-25T23:34:12.433083+00:00", "data": {"market": "0xf51607fb5ef641ac5bba06ced0c497ecca038f010c6a78947a3cc2adcf0d86b7", "price_changes": [{"asset_id": "51608546776780288607506114199605032507662896760905181902893674078914900996024", "price": "0.999", "size": "93124", "side": "BUY", "hash": "b50a22053d57c1affe09c4cffc082102403075a0", "best_bid": "0.999", "best_ask": "1"}, {"asset_id": "68683942633697084725036835213804622791934367014208146174418479991147761539557", "price": "0.001", "size": "93124", "side": "SELL", "hash": "e969ff300a2e96bfa02ce750d9ac007e66038f0a", "best_bid": "0", "best_ask": "0.001"}], "timestamp": "1769384052359", "event_type": "price_change"}}
{"_local_timestamp": "2026-01-25T23:34:13.580760+00:00", "data": {"market": "0xf51607fb5ef641ac5bba06ced0c497ecca038f010c6a78947a3cc2adcf0d86b7", "price_changes": [{"asset_id": "51608546776780288607506114199605032507662896760905181902893674078914900996024", "price": "0.999", "size": "93279", "side": "BUY", "hash": "2ca1214f644933ec422445be7b45a912a5bfc184", "best_bid": "0.999", "best_ask": "1"}, {"asset_id": "68683942633697084725036835213804622791934367014208146174418479991147761539557", "price": "0.001", "size": "93279", "side": "SELL", "hash": "01dbe984dea00da424659471f182818b373840d4", "best_bid": "0", "best_ask": "0.001"}], "timestamp": "1769384053418", "event_type": "price_change"}}
{"_local_timestamp": "2026-01-25T23:34:25.480690+00:00", "data": {"market": "0xf51607fb5ef641ac5bba06ced0c497ecca038f010c6a78947a3cc2adcf0d86b7", "price_changes": [{"asset_id": "51608546776780288607506114199605032507662896760905181902893674078914900996024", "price": "0.999", "size": "80000", "side": "BUY", "hash": "7d3fbbbb16ad04e4dee40d8113a92b7394b6a9e9", "best_bid": "0.999", "best_ask": "1"}, {"asset_id": "68683942633697084725036835213804622791934367014208146174418479991147761539557", "price": "0.001", "size": "80000", "side": "SELL", "hash": "838edbeb28721158414324c524dc6437caa46b88", "best_bid": "0", "best_ask": "0.001"}], "timestamp": "1769384065336", "event_type": "price_change"}}
{"_local_timestamp": "2026-01-25T23:34:26.323083+00:00", "data": {"market": "0xf51607fb5ef641ac5bba06ced0c497ecca038f010c6a78947a3cc2adcf0d86b7", "price_changes": [{"asset_id": "51608546776780288607506114199605032507662896760905181902893674078914900996024", "price": "0.999", "size": "80625", "side": "BUY", "hash": "4078d4ac222e56f98196dbcde540b8dae1fa6cfe", "best_bid": "0.999", "best_ask": "1"}, {"asset_id": "68683942633697084725036835213804622791934367014208146174418479991147761539557", "price": "0.001", "size": "80625", "side": "SELL", "hash": "d761f777dc4135d28f276261adff4a3857ef56d6", "best_bid": "0", "best_ask": "0.001"}], "timestamp": "1769384066211", "event_type": "price_change"}}
{"_local_timestamp": "2026-01-25T23:34:26.652258+00:00", "data": {"market": "0xf51607fb5ef641ac5bba06ced0c497ecca038f010c6a78947a3cc2adcf0d86b7", "price_changes": [{"asset_id": "51608546776780288607506114199605032507662896760905181902893674078914900996024", "price": "0.999", "size": "81249", "side": "BUY", "hash": "30f28d8674c9e0e6dce9e7ccedee62d9b67d52e6", "best_bid": "0.999", "best_ask": "1"}, {"asset_id": "68683942633697084725036835213804622791934367014208146174418479991147761539557", "price": "0.001", "size": "81249", "side": "SELL", "hash": "74168047e0541ef971a2d64370e086cdbb81e98c", "best_bid": "0", "best_ask": "0.001"}], "timestamp": "1769384066565", "event_type": "price_change"}}
{"_local_timestamp": "2026-01-25T23:34:27.935079+00:00", "data": {"market": "0xf51607fb5ef641ac5bba06ced0c497ecca038f010c6a78947a3cc2adcf0d86b7", "price_changes": [{"asset_id": "51608546776780288607506114199605032507662896760905181902893674078914900996024", "price": "0.999", "size": "81404", "side": "BUY", "hash": "bf51e4447e05319c90efda9fb8356b09c0189aca", "best_bid": "0.999", "best_ask": "1"}, {"asset_id": "68683942633697084725036835213804622791934367014208146174418479991147761539557", "price": "0.001", "size": "81404", "side": "SELL", "hash": "43f2aff922538dcaed754c7008fe27d2e292aaac", "best_bid": "0", "best_ask": "0.001"}], "timestamp": "1769384067741", "event_type": "price_change"}}
{"_local_timestamp": "2026-01-25T23:34:28.289075+00:00", "data": {"market": "0xf51607fb5ef641ac5bba06ced0c497ecca038f010c6a78947a3cc2adcf0d86b7", "price_changes": [{"asset_id": "51608546776780288607506114199605032507662896760905181902893674078914900996024", "price": "0.999", "size": "81558", "side": "BUY", "hash": "2758809e5a29b78ec04eca7d78a52c9b4b96c59d", "best_bid": "0.999", "best_ask": "1"}, {"asset_id": "68683942633697084725036835213804622791934367014208146174418479991147761539557", "price": "0.001", "size": "81558", "side": "SELL", "hash": "f77324269b4cd71806c9384bbcaa045da3d64fb6", "best_bid": "0", "best_ask": "0.001"}], "timestamp": "1769384068179", "event_type": "price_change"}}
{"_local_timestamp": "2026-01-25T23:34:29.353182+00:00", "data": {"market": "0xf51607fb5ef641ac5bba06ced0c497ecca038f010c6a78947a3cc2adcf0d86b7", "price_changes": [{"asset_id": "51608546776780288607506114199605032507662896760905181902893674078914900996024", "price": "0.999", "size": "81711", "side": "BUY", "hash": "6fe6806c348fe9008e31a9854bde8ad43ca7680b", "best_bid": "0.999", "best_ask": "1"}, {"asset_id": "68683942633697084725036835213804622791934367014208146174418479991147761539557", "price": "0.001", "size": "81711", "side": "SELL", "hash": "7f44d1fb895df1b652b1e70c9d4c1094ae456431", "best_bid": "0", "best_ask": "0.001"}], "timestamp": "1769384069278", "event_type": "price_change"}}
{"_local_timestamp": "2026-01-25T23:34:29.780837+00:00", "data": {"market": "0xf51607fb5ef641ac5bba06ced0c497ecca038f010c6a78947a3cc2adcf0d86b7", "price_changes": [{"asset_id": "51608546776780288607506114199605032507662896760905181902893674078914900996024", "price": "0.999", "size": "81863", "side": "BUY", "hash": "9d9fde262518c3cfbecf9511df7e96a4c4412a14", "best_bid": "0.999", "best_ask": "1"}, {"asset_id": "68683942633697084725036835213804622791934367014208146174418479991147761539557", "price": "0.001", "size": "81863", "side": "SELL", "hash": "e6a849a6997c57a9cbf10888ff2c5b6b3c0f53c9", "best_bid": "0", "best_ask": "0.001"}], "timestamp": "1769384069641", "event_type": "price_change"}}
{"_local_timestamp": "2026-01-25T23:34:30.386792+00:00", "data": {"market": "0xf51607fb5ef641ac5bba06ced0c497ecca038f010c6a78947a3cc2adcf0d86b7", "price_changes": [{"asset_id": "51608546776780288607506114199605032507662896760905181902893674078914900996024", "price": "0.999", "size": "82014", "side": "BUY", "hash": "c02b00d74cedf69cdce62b83193ecb3dbd8fae5e", "best_bid": "0.999", "best_ask": "1"}, {"asset_id": "68683942633697084725036835213804622791934367014208146174418479991147761539557", "price": "0.001", "size": "82014", "side": "SELL", "hash": "e04b7cbcb7a6dd8d8bd13db50976bdc0c5056fa0", "best_bid": "0", "best_ask": "0.001"}], "timestamp": "1769384070206", "event_type": "price_change"}}
{"_local_timestamp": "2026-01-25T23:34:30.694686+00:00", "data": {"market": "0xf51607fb5ef641ac5bba06ced0c497ecca038f010c6a78947a3cc2adcf0d86b7", "price_changes": [{"asset_id": "51608546776780288607506114199605032507662896760905181902893674078914900996024", "price": "0.999", "size": "82051", "side": "BUY", "hash": "52d4b5e8c6ba0a80a2639be2802c00e70a713996", "best_bid": "0.999", "best_ask": "1"}, {"asset_id": "68683942633697084725036835213804622791934367014208146174418479991147761539557", "price": "0.001", "size": "82051", "side": "SELL", "hash": "2a0db57a510f7d74796e4bf09ea88a667cb24763", "best_bid": "0", "best_ask": "0.001"}], "timestamp": "1769384070574", "event_type": "price_change"}}
{"_local_timestamp": "2026-01-25T23:34:30.995986+00:00", "data": {"market": "0xf51607fb5ef641ac5bba06ced0c497ecca038f010c6a78947a3cc2adcf0d86b7", "price_changes": [{"asset_id": "51608546776780288607506114199605032507662896760905181902893674078914900996024", "price": "0.999", "size": "82087", "side": "BUY", "hash": "7eec116ff23688c10c029efad1feda0ab5b6197e", "best_bid": "0.999", "best_ask": "1"}, {"asset_id": "68683942633697084725036835213804622791934367014208146174418479991147761539557", "price": "0.001", "size": "82087", "side": "SELL", "hash": "3a44b9f67a0f9e9de6136e3f7540bce24e5132d2", "best_bid": "0", "best_ask": "0.001"}], "timestamp": "1769384070922", "event_type": "price_change"}}
{"_local_timestamp": "2026-01-25T23:34:32.243233+00:00", "data": {"market": "0xf51607fb5ef641ac5bba06ced0c497ecca038f010c6a78947a3cc2adcf0d86b7", "price_changes": [{"asset_id": "51608546776780288607506114199605032507662896760905181902893674078914900996024", "price": "0.999", "size": "82122", "side": "BUY", "hash": "b71b90385fe812ac9ab5fca763c33b86bbccf393", "best_bid": "0.999", "best_ask": "1"}, {"asset_id": "68683942633697084725036835213804622791934367014208146174418479991147761539557", "price": "0.001", "size": "82122", "side": "SELL", "hash": "3ee0202506a0750e64b222b36212a8c0d8297277", "best_bid": "0", "best_ask": "0.001"}], "timestamp": "1769384072101", "event_type": "price_change"}}
{"_local_timestamp": "2026-01-25T23:34:32.672358+00:00", "data": {"market": "0xf51607fb5ef641ac5bba06ced0c497ecca038f010c6a78947a3cc2adcf0d86b7", "price_changes": [{"asset_id": "51608546776780288607506114199605032507662896760905181902893674078914900996024", "price": "0.999", "size": "82156", "side": "BUY", "hash": "195f0c7ccaf12a6265b8960716a480efb569c874", "best_bid": "0.999", "best_ask": "1"}, {"asset_id": "68683942633697084725036835213804622791934367014208146174418479991147761539557", "price": "0.001", "size": "82156", "side": "SELL", "hash": "51ad16c53b34143b1886d9ae636d7b2b69727363", "best_bid": "0", "best_ask": "0.001"}], "timestamp": "1769384072584", "event_type": "price_change"}}
{"_local_timestamp": "2026-01-25T23:34:33.454484+00:00", "data": {"market": "0xf51607fb5ef641ac5bba06ced0c497ecca038f010c6a78947a3cc2adcf0d86b7", "price_changes": [{"asset_id": "51608546776780288607506114199605032507662896760905181902893674078914900996024", "price": "0.999", "size": "82189", "side": "BUY", "hash": "88e1bf962e7aecf1948be1c9a7050afd5f3b13ef", "best_bid": "0.999", "best_ask": "1"}, {"asset_id": "68683942633697084725036835213804622791934367014208146174418479991147761539557", "price": "0.001", "size": "82189", "side": "SELL", "hash": "f4cd960f0e30afcf6ce6b700be7dbaff6aa85135", "best_bid": "0", "best_ask": "0.001"}], "timestamp": "1769384073355", "event_type": "price_change"}}
{"_local_timestamp": "2026-01-25T23:34:36.158801+00:00", "data": {"market": "0xf51607fb5ef641ac5bba06ced0c497ecca038f010c6a78947a3cc2adcf0d86b7", "price_changes": [{"asset_id": "51608546776780288607506114199605032507662896760905181902893674078914900996024", "price": "0.999", "size": "84689", "side": "BUY", "hash": "651691f8a8773be87422f8c3f5db572cf904bae0", "best_bid": "0.999", "best_ask": "1"}, {"asset_id": "68683942633697084725036835213804622791934367014208146174418479991147761539557", "price": "0.001", "size": "84689", "side": "SELL", "hash": "666ff54f71107a9bd63f96efec4d144afd39e132", "best_bid": "0", "best_ask": "0.001"}], "timestamp": "1769384076057", "event_type": "price_change"}}
{"_local_timestamp": "2026-01-25T23:34:38.524031+00:00", "data": {"market": "0xf51607fb5ef641ac5bba06ced0c497ecca038f010c6a78947a3cc2adcf0d86b7", "price_changes": [{"asset_id": "51608546776780288607506114199605032507662896760905181902893674078914900996024", "price": "0.999", "size": "84844", "side": "BUY", "hash": "9cc3de9fd68e9eba13a24b4e1a705fc8953c59f4", "best_bid": "0.999", "best_ask": "1"}, {"asset_id": "68683942633697084725036835213804622791934367014208146174418479991147761539557", "price": "0.001", "size": "84844", "side": "SELL", "hash": "4b752ddad2ce4efdfcba1990a275d8e61fc5f9c6", "best_bid": "0", "best_ask": "0.001"}], "timestamp": "1769384078438", "event_type": "price_change"}}
{"_local_timestamp": "2026-01-25T23:34:38.856942+00:00", "data": {"market": "0xf51607fb5ef641ac5bba06ced0c497ecca038f010c6a78947a3cc2adcf0d86b7", "price_changes": [{"asset_id": "51608546776780288607506114199605032507662896760905181902893674078914900996024", "price": "0.999", "size": "84998", "side": "BUY", "hash": "47b739dd324e96daa59822c784d3c3a32caf7bfb", "best_bid": "0.999", "best_ask": "1"}, {"asset_id": "68683942633697084725036835213804622791934367014208146174418479991147761539557", "price": "0.001", "size": "84998", "side": "SELL", "hash": "573e87dbbd679defe993a75ae217c6aa5238c955", "best_bid": "0", "best_ask": "0.001"}], "timestamp": "1769384078786", "event_type": "price_change"}}
{"_local_timestamp": "2026-01-25T23:34:40.202665+00:00", "data": {"market": "0xf51607fb5ef641ac5bba06ced0c497ecca038f010c6a78947a3cc2adcf0d86b7", "price_changes": [{"asset_id": "51608546776780288607506114199605032507662896760905181902893674078914900996024", "price": "0.999", "size": "85151", "side": "BUY", "hash": "5ea404867e37b5c46ae5414f8792a36380db2789", "best_bid": "0.999", "best_ask": "1"}, {"asset_id": "68683942633697084725036835213804622791934367014208146174418479991147761539557", "price": "0.001", "size": "85151", "side": "SELL", "hash": "67ce72da1f56f18f93e1972242955e51c19417d5", "best_bid": "0", "best_ask": "0.001"}], "timestamp": "1769384080022", "event_type": "price_change"}}
{"_local_timestamp": "2026-01-25T23:34:40.657244+00:00", "data": {"market": "0xf51607fb5ef641ac5bba06ced0c497ecca038f010c6a78947a3cc2adcf0d86b7", "price_changes": [{"asset_id": "51608546776780288607506114199605032507662896760905181902893674078914900996024", "price": "0.999", "size": "85303", "side": "BUY", "hash": "6093911cad98cb3897735a2995b93bd129079695", "best_bid": "0.999", "best_ask": "1"}, {"asset_id": "68683942633697084725036835213804622791934367014208146174418479991147761539557", "price": "0.001", "size": "85303", "side": "SELL", "hash": "498bd56d91c188877993e4b66d24a38d8a137788", "best_bid": "0", "best_ask": "0.001"}], "timestamp": "1769384080486", "event_type": "price_change"}}
{"_local_timestamp": "2026-01-25T23:35:07.621129+00:00", "data": {"market": "0xf51607fb5ef641ac5bba06ced0c497ecca038f010c6a78947a3cc2adcf0d86b7", "price_changes": [{"asset_id": "51608546776780288607506114199605032507662896760905181902893674078914900996024", "price": "0.999", "size": "80000", "side": "BUY", "hash": "66497106ecc4786482780dc5fac3628d05aa6e15", "best_bid": "0.999", "best_ask": "1"}, {"asset_id": "68683942633697084725036835213804622791934367014208146174418479991147761539557", "price": "0.001", "size": "80000", "side": "SELL", "hash": "b52781876572697a73a7a96ba1ea850d50102208", "best_bid": "0", "best_ask": "0.001"}], "timestamp": "1769384107391", "event_type": "price_change"}}
{"_local_timestamp": "2026-01-25T23:35:07.847012+00:00", "data": {"market": "0xf51607fb5ef641ac5bba06ced0c497ecca038f010c6a78947a3cc2adcf0d86b7", "price_changes": [{"asset_id": "51608546776780288607506114199605032507662896760905181902893674078914900996024", "price": "0.999", "size": "80039", "side": "BUY", "hash": "28c650fcd83c3c7756f1096d5bac6d4159e481b9", "best_bid": "0.999", "best_ask": "1"}, {"asset_id": "68683942633697084725036835213804622791934367014208146174418479991147761539557", "price": "0.001", "size": "80039", "side": "SELL", "hash": "e1c7ef1a586a99f187587d62da8555c1a9d24981", "best_bid": "0", "best_ask": "0.001"}], "timestamp": "1769384107618", "event_type": "price_change"}}
{"_local_timestamp": "2026-01-25T23:35:08.160470+00:00", "data": {"market": "0xf51607fb5ef641ac5bba06ced0c497ecca038f010c6a78947a3cc2adcf0d86b7", "price_changes": [{"asset_id": "51608546776780288607506114199605032507662896760905181902893674078914900996024", "price": "0.999", "size": "80077", "side": "BUY", "hash": "4552b374701d191fc783434427e472208c186e15", "best_bid": "0.999", "best_ask": "1"}, {"asset_id": "68683942633697084725036835213804622791934367014208146174418479991147761539557", "price": "0.001", "size": "80077", "side": "SELL", "hash": "0dbae7c20d769abb68d1eaac37f11a49f51c7929", "best_bid": "0", "best_ask": "0.001"}], "timestamp": "1769384107941", "event_type": "price_change"}}
{"_local_timestamp": "2026-01-25T23:35:08.597697+00:00", "data": {"market": "0xf51607fb5ef641ac5bba06ced0c497ecca038f010c6a78947a3cc2adcf0d86b7", "price_changes": [{"asset_id": "51608546776780288607506114199605032507662896760905181902893674078914900996024", "price": "0.999", "size": "80114", "side": "BUY", "hash": "50f012b476d228ac6719300f43545df995e95bcf", "best_bid": "0.999", "best_ask": "1"}, {"asset_id": "68683942633697084725036835213804622791934367014208146174418479991147761539557", "price": "0.001", "size": "80114", "side": "SELL", "hash": "5b622c5d44e5e8034303f44df7822d4a6aee67d1", "best_bid": "0", "best_ask": "0.001"}], "timestamp": "1769384108370", "event_type": "price_change"}}
{"_local_timestamp": "2026-01-25T23:35:09.030719+00:00", "data": {"market": "0xf51607fb5ef641ac5bba06ced0c497ecca038f010c6a78947a3cc2adcf0d86b7", "price_changes": [{"asset_id": "51608546776780288607506114199605032507662896760905181902893674078914900996024", "price": "0.999", "size": "80150", "side": "BUY", "hash": "42234c2a07ad31a3d9cc1adf98b36cc010555d83", "best_bid": "0.999", "best_ask": "1"}, {"asset_id": "68683942633697084725036835213804622791934367014208146174418479991147761539557", "price": "0.001", "size": "80150", "side": "SELL", "hash": "0d05f88b89deff15e6929698dc72bcd2e03c8c11", "best_bid": "0", "best_ask": "0.001"}], "timestamp": "1769384108822", "event_type": "price_change"}}
{"_local_timestamp": "2026-01-25T23:35:09.366256+00:00", "data": {"market": "0xf51607fb5ef641ac5bba06ced0c497ecca038f010c6a78947a3cc2adcf0d86b7", "price_changes": [{"asset_id": "51608546776780288607506114199605032507662896760905181902893674078914900996024", "price": "0.999", "size": "80185", "side": "BUY", "hash": "66c2fcf21ee3c70551d78a12bd2416992f69a0d9", "best_bid": "0.999", "best_ask": "1"}, {"asset_id": "68683942633697084725036835213804622791934367014208146174418479991147761539557", "price": "0.001", "size": "80185", "side": "SELL", "hash": "5c8183d289020ecd620358c3392b285e5a8390a1", "best_bid": "0", "best_ask": "0.001"}], "timestamp": "1769384109162", "event_type": "price_change"}}
{"_local_timestamp": "2026-01-25T23:35:12.270592+00:00", "data": {"market": "0xf51607fb5ef641ac5bba06ced0c497ecca038f010c6a78947a3cc2adcf0d86b7", "price_changes": [{"asset_id": "51608546776780288607506114199605032507662896760905181902893674078914900996024", "price": "0.999", "size": "80809", "side": "BUY", "hash": "a92106a9549cd1c64677d8898c73688849b3b188", "best_bid": "0.999", "best_ask": "1"}, {"asset_id": "68683942633697084725036835213804622791934367014208146174418479991147761539557", "price": "0.001", "size": "80809", "side": "SELL", "hash": "872547fa7f0e28efb68b8e2f2809a9e48da7ff78", "best_bid": "0", "best_ask": "0.001"}], "timestamp": "1769384112043", "event_type": "price_change"}}
{"_local_timestamp": "2026-01-25T23:35:14.253417+00:00", "data": {"market": "0xf51607fb5ef641ac5bba06ced0c497ecca038f010c6a78947a3cc2adcf0d86b7", "price_changes": [{"asset_id": "51608546776780288607506114199605032507662896760905181902893674078914900996024", "price": "0.999", "size": "80964", "side": "BUY", "hash": "dcaff016493c1fada4e0f339afe6ea50a25fdf32", "best_bid": "0.999", "best_ask": "1"}, {"asset_id": "68683942633697084725036835213804622791934367014208146174418479991147761539557", "price": "0.001", "size": "80964", "side": "SELL", "hash": "5a517538f0117ad93348cff695fa38b42ef640cc", "best_bid": "0", "best_ask": "0.001"}], "timestamp": "1769384114045", "event_type": "price_change"}}
{"_local_timestamp": "2026-01-25T23:35:14.704285+00:00", "data": {"market": "0xf51607fb5ef641ac5bba06ced0c497ecca038f010c6a78947a3cc2adcf0d86b7", "price_changes": [{"asset_id": "51608546776780288607506114199605032507662896760905181902893674078914900996024", "price": "0.999", "size": "81118", "side": "BUY", "hash": "9bb2a916d77f2c0cc55bda50dd3bab5490347ac3", "best_bid": "0.999", "best_ask": "1"}, {"asset_id": "68683942633697084725036835213804622791934367014208146174418479991147761539557", "price": "0.001", "size": "81118", "side": "SELL", "hash": "04487534817ea3a8bfd072f70a6a6f9349a933cc", "best_bid": "0", "best_ask": "0.001"}], "timestamp": "1769384114484", "event_type": "price_change"}}
{"_local_timestamp": "2026-01-25T23:35:15.343721+00:00", "data": {"market": "0xf51607fb5ef641ac5bba06ced0c497ecca038f010c6a78947a3cc2adcf0d86b7", "price_changes": [{"asset_id": "51608546776780288607506114199605032507662896760905181902893674078914900996024", "price": "0.999", "size": "81271", "side": "BUY", "hash": "5e6d8bcbc90b9929871ac6334caba1b0ef75e667", "best_bid": "0.999", "best_ask": "1"}, {"asset_id": "68683942633697084725036835213804622791934367014208146174418479991147761539557", "price": "0.001", "size": "81271", "side": "SELL", "hash": "560ba9d8a89238d45391e2fd0aefa5f3d09ef3ea", "best_bid": "0", "best_ask": "0.001"}], "timestamp": "1769384115110", "event_type": "price_change"}}
{"_local_timestamp": "2026-01-25T23:35:18.096967+00:00", "data": {"market": "0xf51607fb5ef641ac5bba06ced0c497ecca038f010c6a78947a3cc2adcf0d86b7", "price_changes": [{"asset_id": "51608546776780288607506114199605032507662896760905181902893674078914900996024", "price": "0.999", "size": "81305", "side": "BUY", "hash": "d3ab6f4d02483d63165062517041e76b6e5fb549", "best_bid": "0.999", "best_ask": "1"}, {"asset_id": "68683942633697084725036835213804622791934367014208146174418479991147761539557", "price": "0.001", "size": "81305", "side": "SELL", "hash": "d77dcec38e151ba3c3a9c386797da311f31d13ca", "best_bid": "0", "best_ask": "0.001"}], "timestamp": "1769384117850", "event_type": "price_change"}}
