{"_local_timestamp": "2026-01-25T23:33:58.688102+00:00", "data": [{"market": "0xa55cb5ef47b120e20225dfac4260a852ff2d66b1029be84140826358dd17d57f", "asset_id": "72393438098466972297597674006747034220924966382899877769423450749463824041513", "timestamp": "1769384033583", "hash": "1ac508914bde65023f3f6c0df821b7e078f39b4e", "bids": [{"price": "0.001", "size": "100009"}, {"price": "0.002", "size": "55000"}, {"price": "0.008", "size": "155"}, {"price": "0.01", "size": "19200"}, {"price": "0.011", "size": "55710"}, {"price": "0.02", "size": "1000"}, {"price": "0.031", "size": "12000"}, {"price": "0.04", "size": "2000"}, {"price": "0.05", "size": "600"}, {"price": "0.08", "size": "155"}, {"price": "0.097", "size": "100"}, {"price": "0.099", "size": "100"}, {"price": "0.1", "size": "700"}, {"price": "0.101", "size": "10700"}, {"price": "0.102", "size": "5000"}, {"price": "0.11", "size": "3000"}, {"price": "0.111", "size": "4400"}, {"price": "0.143", "size": "400"}, {"price": "0.47", "size": "100"}, {"price": "0.49", "size": "100"}, {"price": "0.497", "size": "100"}, {"price": "0.499", "size": "500"}, {"price": "0.5", "size": "440"}, {"price": "0.75", "size": "60"}, {"price": "0.767", "size": "60"}, {"price": "0.768", "size": "53"}, {"price": "0.769", "size": "60"}, {"price": "0.77", "size": "60"}, {"price": "0.771", "size": "22.27"}, {"price": "0.99", "size": "70.7"}, {"price": "0.991", "size": "622.54"}, {"price": "0.992", "size": "50.4"}, {"price": "0.993", "size": "45.31"}, {"price": "0.994", "size": "40.24"}, {"price": "0.995", "size": "35.17"}, {"price": "0.996", "size": "35.13"}, {"price": "0.997", "size": "25.07"}, {"price": "0.998", "size": "520.04"}, {"price": "0.999", "size": "114718.14"}], "asks": [], "event_type": "book", "last_trade_price": "0.999"}, {"market": "0xa55cb5ef47b120e20225dfac4260a852ff2d66b1029be84140826358dd17d57f", "asset_id": "112772951724658729290014487768777270812018717251551412726994926163223979407893", "timestamp": "1769384033583", "hash": "114a5bbf395359235dc52dfb777762e4c72a0942", "bids": [], "asks": [{"price": "0.999", "size": "100009"}, {"price": "0.998", "size": "55000"}, {"price": "0.992", "size": "155"}, {"price": "0.99", "size": "19200"}, {"price": "0.989", "size": "55710"}, {"price": "0.98", "size": "1000"}, {"price": "0.969", "size": "12000"}, {"price": "0.96", "size": "2000"}, {"price": "0.95", "size": "600"}, {"price": "0.92", "size": "155"}, {"price": "0.903", "size": "100"}, {"price": "0.901", "size": "100"}, {"price": "0.9", "size": "700"}, {"price": "0.899", "size": "10700"}, {"price": "0.898", "size": "5000"}, {"price": "0.89", "size": "3000"}, {"price": "0.889", "size": "4400"}, {"price": "0.857", "size": "400"}, {"price": "0.53", "size": "100"}, {"price": "0.51", "size": "100"}, {"price": "0.503", "size": "100"}, {"price": "0.501", "size": "500"}, {"price": "0.5", "size": "440"}, {"price": "0.25", "size": "60"}, {"price": "0.233", "size": "60"}, {"price": "0.232", "size": "53"}, {"price": "0.231", "size": "60"}, {"price": "0.23", "size": "60"}, {"price": "0.229", "size": "22.27"}, {"price": "0.01", "size": "70.7"}, {"price": "0.009", "size": "622.54"}, {"price": "0.008", "size": "50.4"}, {"price": "0.007", "size": "45.31"}, {"price": "0.006", "size": "40.24"}, {"price": "0.005", "size": "35.17"}, {"price": "0.004", "size": "35.13"}, {"price": "0.003", "size": "25.07"}, {"price": "0.002", "size": "520.04"}, {"price": "0.001", "size": "114718.14"}], "event_type": "book", "last_trade_price": "0.999"}]}
{"_local_timestamp": "2026-01-25T23:34:07.969345+00:00", "data": {"market": "0xa55cb5ef47b120e20225dfac4260a852ff2d66b1029be84140826358dd17d57f", "price_changes": [{"asset_id": "72393438098466972297597674006747034220924966382899877769423450749463824041513", "price": "0.999", "size": "110364.14", "side": "BUY", "hash": "2882e719a05db49e8622bbb004849b272c817cf4", "best_bid": "0.999", "best_ask": "1"}, {"asset_id": "112772951724658729290014487768777270812018717251551412726994926163223979407893", "price": "0.001", "size": "110364.14", "side": "SELL", "hash": "60f4dd4fd5657a64a42f6f46ffffde63a7627d8b", "best_bid": "0", "best_ask": "0.001"}], "timestamp": "1769384047888", "event_type": "price_change"}}
{"_local_timestamp": "2026-01-25T23:34:08.671419+00:00", "data": {"market": "0xa55cb5ef47b120e20225dfac4260a852ff2d66b1029be84140826358dd17d57f", "price_changes": [{"asset_id": "72393438098466972297597674006747034220924966382899877769423450749463824041513", "price": "0.999", "size": "105371.14", "side": "BUY", "hash": "019ec44e4218b47aa5a3ef78ece0f525f32bacec", "best_bid": "0.999", "best_ask": "1"}, {"asset_id": "112772951724658729290014487768777270812018717251551412726994926163223979407893", "price": "0.001", "size": "105371.14", "side": "SELL", "hash": "878e75669c6ebea918919abf65a83666d80616e5", "best_bid": "0", "best_ask": "0.001"}], "timestamp": "1769384048563", "event_type": "price_change"}}
{"_local_timestamp": "2026-01-25T23:34:09.303231+00:00", "data": {"market": "0xa55cb5ef47b120e20225dfac4260a852ff2d66b1029be84140826358dd17d57f", "price_changes": [{"asset_id": "72393438098466972297597674006747034220924966382899877769423450749463824041513", "price": "0.999", "size": "95380.14", "side": "BUY", "hash": "2a792311e77deca1a4dc2ef1a99b42629617d9dd", "best_bid": "0.999", "best_ask": "1"}, {"asset_id": "112772951724658729290014487768777270812018717251551412726994926163223979407893", "price": "0.001", "size": "95380.14", "side": "SELL", "hash": "c6b673e824a92eeabfed25e9604e69cdfacb56a6", "best_bid": "0", "best_ask": "0.001"}], "timestamp": "1769384049210", "event_type": "price_change"}}
{"_local_timestamp": "2026-01-25T23:34:11.203923+00:00", "data": {"market": "0xa55cb5ef47b120e20225dfac4260a852ff2d66b1029be84140826358dd17d57f", "price_changes": [{"asset_id": "72393438098466972297597674006747034220924966382899877769423450749463824041513", "price": "0.999", "size": "97880.14", "side": "BUY", "hash": "65f30558efea8a19288f2c6b22782bc13d86995c", "best_bid": "0.999", "best_ask": "1"}, {"asset_id": "112772951724658729290014487768777270812018717251551412726994926163223979407893", "price": "0.001", "size": "97880.14", "side": "SELL", "hash": "67d1fa18894337df3050269bd9f6f85e8a299ef5", "best_bid": "0", "best_ask": "0.001"}], "timestamp": "1769384051122", "event_type": "price_change"}}
{"_local_timestamp": "2026-01-25T23:34:12.442751+00:00", "data": {"market": "0xa55cb5ef47b120e20225dfac4260a852ff2d66b1029be84140826358dd17d57f", "price_changes": [{"asset_id": "72393438098466972297597674006747034220924966382899877769423450749463824041513", "price": "0.999", "size": "98504.14", "side": "BUY", "hash": "98923a1c6c5dd7887a242087c7873e628d0aace2", "best_bid": "0.999", "best_ask": "1"}, {"asset_id": "112772951724658729290014487768777270812018717251551412726994926163223979407893", "price": "0.001", "size": "98504.14", "side": "SELL", "hash": "c3e6fe4ec5394bba930356e20059423628262d25", "best_bid": "0", "best_ask": "0.001"}], "timestamp": "1769384052358", "event_type": "price_change"}}
{"_local_timestamp": "2026-01-25T23:34:13.573438+00:00", "data": {"market": "0xa55cb5ef47b120e20225dfac4260a852ff2d66b1029be84140826358dd17d57f", "price_changes": [{"asset_id": "72393438098466972297597674006747034220924966382899877769423450749463824041513", "price": "0.999", "size": "98659.14", "side": "BUY", "hash": "d5722aea300dc4a9db21df9ee95e39c7beefdb20", "best_bid": "0.999", "best_ask": "1"}, {"asset_id": "112772951724658729290014487768777270812018717251551412726994926163223979407893", "price": "0.001", "size": "98659.14", "side": "SELL", "hash": "64f1d5ee166f29aa4b098f9401b588ff1a838641", "best_bid": "0", "best_ask": "0.001"}], "timestamp": "1769384053417", "event_type": "price_change"}}
{"_local_timestamp": "2026-01-25T23:34:14.919551+00:00", "data": {"market": "0xa55cb5ef47b120e20225dfac4260a852ff2d66b1029be84140826358dd17d57f", "price_changes": [{"asset_id": "72393438098466972297597674006747034220924966382899877769423450749463824041513", "price": "0.999", "size": "98697.14", "side": "BUY", "hash": "3f57ab0fbd457bf13f1613f6a805fcdb92a150c7", "best_bid": "0.999", "best_ask": "1"}, {"asset_id": "112772951724658729290014487768777270812018717251551412726994926163223979407893", "price": "0.001", "size": "98697.14", "side": "SELL", "hash": "67ec3bc1ed9a2fd1d87b0197ff9ec207760a5cbb", "best_bid": "0", "best_ask": "0.001"}], "timestamp": "1769384054846", "event_type": "price_change"}}
{"_local_timestamp": "2026-01-25T23:34:25.482337+00:00", "data": {"market": "0xa55cb5ef47b120e20225dfac4260a852ff2d66b1029be84140826358dd17d57f", "price_changes": [{"asset_id": "72393438098466972297597674006747034220924966382899877769423450749463824041513", "price": "0.999", "size": "85388.14", "side": "BUY", "hash": "b984173ed47ac8eea269399e91d2e6bb560e11c0", "best_bid": "0.999", "best_ask": "1"}, {"asset_id": "112772951724658729290014487768777270812018717251551412726994926163223979407893", "price": "0.001", "size": "85388.14", "side": "SELL", "hash": "2e9f8bc27eb746bf26d5b0f41f3cf7fd94c9e93b", "best_bid": "0", "best_ask": "0.001"}], "timestamp": "1769384065336", "event_type": "price_change"}}
{"_local_timestamp": "2026-01-25T23:34:26.304764+00:00", "data": {"market": "0xa55cb5ef47b120e20225dfac4260a852ff2d66b1029be84140826358dd17d57f", "price_changes": [{"asset_id": "72393438098466972297597674006747034220924966382899877769423450749463824041513", "price": "0.999", "size": "86013.14", "side": "BUY", "hash": "673accca35f3a1b9d85802dc2b697ccde88a938b", "best_bid": "0.999", "best_ask": "1"}, {"asset_id": "112772951724658729290014487768777270812018717251551412726994926163223979407893", "price": "0.001", "size": "86013.14", "side": "SELL", "hash": "d7f59e8135b5347e7ff1d888b886d73dc1ec3dce", "best_bid": "0", "best_ask": "0.001"}], "timestamp": "1769384066210", "event_type": "price_change"}}
{"_local_timestamp": "2026-01-25T23:34:26.647824+00:00", "data": {"market": "0xa55cb5ef47b120e20225dfac4260a852ff2d66b1029be84140826358dd17d57f", "price_changes": [{"asset_id": "72393438098466972297597674006747034220924966382899877769423450749463824041513", "price": "0.999", "size": "86637.14", "side": "BUY", "hash": "8230fd852d3e084fb061f1e76e8d19f30d952f9b", "best_bid": "0.999", "best_ask": "1"}, {"asset_id": "112772951724658729290014487768777270812018717251551412726994926163223979407893", "price": "0.001", "size": "86637.14", "side": "SELL", "hash": "11db82d520035feef4cf5ea3688f372301180f78", "best_bid": "0", "best_ask": "0.001"}], "timestamp": "1769384066569", "event_type": "price_change"}}
{"_local_timestamp": "2026-01-25T23:34:27.913063+00:00", "data": {"market": "0xa55cb5ef47b120e20225dfac4260a852ff2d66b1029be84140826358dd17d57f", "price_changes": [{"asset_id": "72393438098466972297597674006747034220924966382899877769423450749463824041513", "price": "0.999", "size": "86792.14", "side": "BUY", "hash": "16065759c04b6c150332b520982f14b9263c0072", "best_bid": "0.999", "best_ask": "1"}, {"asset_id": "112772951724658729290014487768777270812018717251551412726994926163223979407893", "price": "0.001", "size": "86792.14", "side": "SELL", "hash": "9b6088b40703eb33c77d4f5ec438e328e8a67a9d", "best_bid": "0", "best_ask": "0.001"}], "timestamp": "1769384067733", "event_type": "price_change"}}
{"_local_timestamp": "2026-01-25T23:34:28.255072+00:00", "data": {"market": "0xa55cb5ef47b120e20225dfac4260a852ff2d66b1029be84140826358dd17d57f", "price_changes": [{"asset_id": "72393438098466972297597674006747034220924966382899877769423450749463824041513", "price": "0.999", "size": "86946.14", "side": "BUY", "hash": "afd2b3d90947baff4fda9574e6032a67d9dad2cc", "best_bid": "0.999", "best_ask": "1"}, {"asset_id": "112772951724658729290014487768777270812018717251551412726994926163223979407893", "price": "0.001", "size": "86946.14", "side": "SELL", "hash": "62106cf22e1aca73f57d091a1375c0a332fd6cb6", "best_bid": "0", "best_ask": "0.001"}], "timestamp": "1769384068166", "event_type": "price_change"}}
{"_local_timestamp": "2026-01-25T23:34:29.364365+00:00", "data": {"market": "0xa55cb5ef47b120e20225dfac4260a852ff2d66b1029be84140826358dd17d57f", "price_changes": [{"asset_id": "72393438098466972297597674006747034220924966382899877769423450749463824041513", "price": "0.999", "size": "87099.14", "side": "BUY", "hash": "d75fc3a39ca31bdf15669feefb85c276e258ae18", "best_bid": "0.999", "best_ask": "1"}, {"asset_id": "112772951724658729290014487768777270812018717251551412726994926163223979407893", "price": "0.001", "size": "87099.14", "side": "SELL", "hash": "d0c2bb2cc15a712f230f9c9c706c7b28fc1e6a4f", "best_bid": "0", "best_ask": "0.001"}], "timestamp": "1769384069283", "event_type": "price_change"}}
{"_local_timestamp": "2026-01-25T23:34:29.819121+00:00", "data": {"market": "0xa55cb5ef47b120e20225dfac4260a852ff2d66b1029be84140826358dd17d57f", "price_changes": [{"asset_id": "72393438098466972297597674006747034220924966382899877769423450749463824041513", "price": "0.999", "size": "87251.14", "side": "BUY", "hash": "43d329d1705a5d20b30071ddb84cf48722887715", "best_bid": "0.999", "best_ask": "1"}, {"asset_id": "112772951724658729290014487768777270812018717251551412726994926163223979407893", "price": "0.001", "size": "87251.14", "side": "SELL", "hash": "7433cd7f65610c22308be8951af1b2568cfa7d8c", "best_bid": "0", "best_ask": "0.001"}], "timestamp": "1769384069659", "event_type": "price_change"}}
{"_local_timestamp": "2026-01-25T23:34:30.365215+00:00", "data": {"market": "0xa55cb5ef47b120e20225dfac4260a852ff2d66b1029be84140826358dd17d57f", "price_changes": [{"asset_id": "72393438098466972297597674006747034220924966382899877769423450749463824041513", "price": "0.999", "size": "87402.14", "side": "BUY", "hash": "9d3713e3d87012bff11b580b3fc5b2ab51536292", "best_bid": "0.999", "best_ask": "1"}, {"asset_id": "112772951724658729290014487768777270812018717251551412726994926163223979407893", "price": "0.001", "size": "87402.14", "side": "SELL", "hash": "ec5c8fbdd89940ecb1b26468732db337ee36db84", "best_bid": "0", "best_ask": "0.001"}], "timestamp": "1769384070200", "event_type": "price_change"}}
{"_local_timestamp": "2026-01-25T23:34:30.928761+00:00", "data": {"market": "0xa55cb5ef47b120e20225dfac4260a852ff2d66b1029be84140826358dd17d57f", "price_changes": [{"asset_id": "112772951724658729290014487768777270812018717251551412726994926163223979407893", "price": "0.004", "size": "30.12", "side": "SELL", "hash": "ba863fff13fef1c0a2dc04f6a453ab3daf1e911f", "best_bid": "0", "best_ask": "0.001"}, {"asset_id": "72393438098466972297597674006747034220924966382899877769423450749463824041513", "price": "0.996", "size": "30.12", "side": "BUY", "hash": "9423fff47c5b167a56dc4178961bf4993ac4b984", "best_bid": "0.999", "best_ask": "1"}], "timestamp": "1769384070859", "event_type": "price_change"}}
{"_local_timestamp": "2026-01-25T23:34:30.930399+00:00", "data": {"market": "0xa55cb5ef47b120e20225dfac4260a852ff2d66b1029be84140826358dd17d57f", "price_changes": [{"asset_id": "112772951724658729290014487768777270812018717251551412726994926163223979407893", "price": "0.999", "size": "99999", "side": "SELL", "hash": "ba863fff13fef1c0a2dc04f6a453ab3daf1e911f", "best_bid": "0", "best_ask": "0.001"}, {"asset_id": "72393438098466972297597674006747034220924966382899877769423450749463824041513", "price": "0.001", "size": "99999", "side": "BUY", "hash": "9423fff47c5b167a56dc4178961bf4993ac4b984", "best_bid": "0.999", "best_ask": "1"}], "timestamp": "1769384070859", "event_type": "price_change"}}
{"_local_timestamp": "2026-01-25T23:34:30.938995+00:00", "data": {"market": "0xa55cb5ef47b120e20225dfac4260a852ff2d66b1029be84140826358dd17d57f", "price_changes": [{"asset_id": "112772951724658729290014487768777270812018717251551412726994926163223979407893", "price": "0.229", "size": "0", "side": "SELL", "hash": "ba863fff13fef1c0a2dc04f6a453ab3daf1e911f", "best_bid": "0", "best_ask": "0.001"}, {"asset_id": "72393438098466972297597674006747034220924966382899877769423450749463824041513", "price": "0.771", "size": "0", "side": "BUY", "hash": "9423fff47c5b167a56dc4178961bf4993ac4b984", "best_bid": "0.999", "best_ask": "1"}], "timestamp": "1769384070859", "event_type": "price_change"}}
{"_local_timestamp": "2026-01-25T23:34:30.940745+00:00", "data": {"market": "0xa55cb5ef47b120e20225dfac4260a852ff2d66b1029be84140826358dd17d57f", "price_changes": [{"asset_id": "72393438098466972297597674006747034220924966382899877769423450749463824041513", "price": "0.031", "size": "0", "side": "BUY", "hash": "6fadc1277eefd5177ac969d69b69be2a5fa5feaf", "best_bid": "0", "best_ask": "1"}, {"asset_id": "112772951724658729290014487768777270812018717251551412726994926163223979407893", "price": "0.969", "size": "0", "side": "SELL", "hash": "5b4936023dd04998eaaa476b224d24a8ca2c7743", "best_bid": "0", "best_ask": "1"}], "timestamp": "1769384070859", "event_type": "price_change"}}
{"_local_timestamp": "2026-01-25T23:34:30.943703+00:00", "data": {"market": "0xa55cb5ef47b120e20225dfac4260a852ff2d66b1029be84140826358dd17d57f", "price_changes": [{"asset_id": "72393438098466972297597674006747034220924966382899877769423450749463824041513", "price": "0.08", "size": "0", "side": "BUY", "hash": "6fadc1277eefd5177ac969d69b69be2a5fa5feaf", "best_bid": "0", "best_ask": "1"}, {"asset_id": "112772951724658729290014487768777270812018717251551412726994926163223979407893", "price": "0.92", "size": "0", "side": "SELL", "hash": "5b4936023dd04998eaaa476b224d24a8ca2c7743", "best_bid": "0", "best_ask": "1"}], "timestamp": "1769384070859", "event_type": "price_change"}}
{"_local_timestamp": "2026-01-25T23:34:30.944120+00:00", "data": {"market": "0xa55cb5ef47b120e20225dfac4260a852ff2d66b1029be84140826358dd17d57f", "price_changes": [{"asset_id": "72393438098466972297597674006747034220924966382899877769423450749463824041513", "price": "0.11", "size": "0", "side": "BUY", "hash": "6fadc1277eefd5177ac969d69b69be2a5fa5feaf", "best_bid": "0", "best_ask": "1"}, {"asset_id": "112772951724658729290014487768777270812018717251551412726994926163223979407893", "price": "0.89", "size": "0", "side": "SELL", "hash": "5b4936023dd04998eaaa476b224d24a8ca2c7743", "best_bid": "0", "best_ask": "1"}], "timestamp": "1769384070859", "event_type": "price_change"}}
{"_local_timestamp": "2026-01-25T23:34:30.944371+00:00", "data": {"market": "0xa55cb5ef47b120e20225dfac4260a852ff2d66b1029be84140826358dd17d57f", "price_changes": [{"asset_id": "72393438098466972297597674006747034220924966382899877769423450749463824041513", "price": "0.102", "size": "0", "side": "BUY", "hash": "6fadc1277eefd5177ac969d69b69be2a5fa5feaf", "best_bid": "0", "best_ask": "1"}, {"asset_id": "112772951724658729290014487768777270812018717251551412726994926163223979407893", "price": "0.898", "size": "0", "side": "SELL", "hash": "5b4936023dd04998eaaa476b224d24a8ca2c7743", "best_bid": "0", "best_ask": "1"}], "timestamp": "1769384070859", "event_type": "price_change"}}
{"_local_timestamp": "2026-01-25T23:34:30.944703+00:00", "data": {"market": "0xa55cb5ef47b120e20225dfac4260a852ff2d66b1029be84140826358dd17d57f", "price_changes": [{"asset_id": "72393438098466972297597674006747034220924966382899877769423450749463824041513", "price": "0.999", "size": "0", "side": "BUY", "hash": "6fadc1277eefd5177ac969d69b69be2a5fa5feaf", "best_bid": "0", "best_ask": "1"}, {"asset_id": "112772951724658729290014487768777270812018717251551412726994926163223979407893", "price": "0.001", "size": "0", "side": "SELL", "hash": "5b4936023dd04998eaaa476b224d24a8ca2c7743", "best_bid": "0", "best_ask": "1"}], "timestamp": "1769384070859", "event_type": "price_change"}}
{"_local_timestamp": "2026-01-25T23:34:30.946461+00:00", "data": {"market": "0xa55cb5ef47b120e20225dfac4260a852ff2d66b1029be84140826358dd17d57f", "price_changes": [{"asset_id": "72393438098466972297597674006747034220924966382899877769423450749463824041513", "price": "0.01", "size": "0", "side": "BUY", "hash": "6fadc1277eefd5177ac969d69b69be2a5fa5feaf", "best_bid": "0", "best_ask": "1"}, {"asset_id": "112772951724658729290014487768777270812018717251551412726994926163223979407893", "price": "0.99", "size": "0", "side": "SELL", "hash": "5b4936023dd04998eaaa476b224d24a8ca2c7743", "best_bid": "0", "best_ask": "1"}], "timestamp": "1769384070859", "event_type": "price_change"}}
{"_local_timestamp": "2026-01-25T23:34:30.946823+00:00", "data": {"market": "0xa55cb5ef47b120e20225dfac4260a852ff2d66b1029be84140826358dd17d57f", "price_changes": [{"asset_id": "72393438098466972297597674006747034220924966382899877769423450749463824041513", "price": "0.002", "size": "0", "side": "BUY", "hash": "6fadc1277eefd5177ac969d69b69be2a5fa5feaf", "best_bid": "0", "best_ask": "1"}, {"asset_id": "112772951724658729290014487768777270812018717251551412726994926163223979407893", "price": "0.998", "size": "0", "side": "SELL", "hash": "5b4936023dd04998eaaa476b224d24a8ca2c7743", "best_bid": "0", "best_ask": "1"}], "timestamp": "1769384070859", "event_type": "price_change"}}
{"_local_timestamp": "2026-01-25T23:34:31.058954+00:00", "data": {"market": "0xa55cb5ef47b120e20225dfac4260a852ff2d66b1029be84140826358dd17d57f", "price_changes": [{"asset_id": "72393438098466972297597674006747034220924966382899877769423450749463824041513", "price": "0.5", "size": "0", "side": "BUY", "hash": "6fadc1277eefd5177ac969d69b69be2a5fa5feaf", "best_bid": "0", "best_ask": "1"}, {"asset_id": "112772951724658729290014487768777270812018717251551412726994926163223979407893", "price": "0.5", "size": "0", "side": "SELL", "hash": "5b4936023dd04998eaaa476b224d24a8ca2c7743", "best_bid": "0", "best_ask": "1"}], "timestamp": "1769384070859", "event_type": "price_change"}}
{"_local_timestamp": "2026-01-25T23:34:31.075823+00:00", "data": {"market": "0xa55cb5ef47b120e20225dfac4260a852ff2d66b1029be84140826358dd17d57f", "price_changes": [{"asset_id": "72393438098466972297597674006747034220924966382899877769423450749463824041513", "price": "0.011", "size": "0", "side": "BUY", "hash": "6fadc1277eefd5177ac969d69b69be2a5fa5feaf", "best_bid": "0", "best_ask": "1"}, {"asset_id": "112772951724658729290014487768777270812018717251551412726994926163223979407893", "price": "0.989", "size": "0", "side": "SELL", "hash": "5b4936023dd04998eaaa476b224d24a8ca2c7743", "best_bid": "0", "best_ask": "1"}], "timestamp": "1769384070859", "event_type": "price_change"}}
{"_local_timestamp": "2026-01-25T23:34:31.076168+00:00", "data": {"market": "0xa55cb5ef47b120e20225dfac4260a852ff2d66b1029be84140826358dd17d57f", "price_changes": [{"asset_id": "72393438098466972297597674006747034220924966382899877769423450749463824041513", "price": "0.497", "size": "0", "side": "BUY", "hash": "6fadc1277eefd5177ac969d69b69be2a5fa5feaf", "best_bid": "0", "best_ask": "1"}, {"asset_id": "112772951724658729290014487768777270812018717251551412726994926163223979407893", "price": "0.503", "size": "0", "side": "SELL", "hash": "5b4936023dd04998eaaa476b224d24a8ca2c7743", "best_bid": "0", "best_ask": "1"}], "timestamp": "1769384070859", "event_type": "price_change"}}
{"_local_timestamp": "2026-01-25T23:34:31.077727+00:00", "data": {"market": "0xa55cb5ef47b120e20225dfac4260a852ff2d66b1029be84140826358dd17d57f", "price_changes": [{"asset_id": "72393438098466972297597674006747034220924966382899877769423450749463824041513", "price": "0.101", "size": "0", "side": "BUY", "hash": "6fadc1277eefd5177ac969d69b69be2a5fa5feaf", "best_bid": "0", "best_ask": "1"}, {"asset_id": "112772951724658729290014487768777270812018717251551412726994926163223979407893", "price": "0.899", "size": "0", "side": "SELL", "hash": "5b4936023dd04998eaaa476b224d24a8ca2c7743", "best_bid": "0", "best_ask": "1"}], "timestamp": "1769384070859", "event_type": "price_change"}}
{"_local_timestamp": "2026-01-25T23:34:31.078498+00:00", "data": {"market": "0xa55cb5ef47b120e20225dfac4260a852ff2d66b1029be84140826358dd17d57f", "price_changes": [{"asset_id": "72393438098466972297597674006747034220924966382899877769423450749463824041513", "price": "0.499", "size": "0", "side": "BUY", "hash": "6fadc1277eefd5177ac969d69b69be2a5fa5feaf", "best_bid": "0", "best_ask": "1"}, {"asset_id": "112772951724658729290014487768777270812018717251551412726994926163223979407893", "price": "0.501", "size": "0", "side": "SELL", "hash": "5b4936023dd04998eaaa476b224d24a8ca2c7743", "best_bid": "0", "best_ask": "1"}], "timestamp": "1769384070859", "event_type": "price_change"}}
{"_local_timestamp": "2026-01-25T23:34:31.079241+00:00", "data": {"market": "0xa55cb5ef47b120e20225dfac4260a852ff2d66b1029be84140826358dd17d57f", "price_changes": [{"asset_id": "72393438098466972297597674006747034220924966382899877769423450749463824041513", "price": "0.001", "size": "0", "side": "BUY", "hash": "6fadc1277eefd5177ac969d69b69be2a5fa5feaf", "best_bid": "0", "best_ask": "1"}, {"asset_id": "112772951724658729290014487768777270812018717251551412726994926163223979407893", "price": "0.999", "size": "0", "side": "SELL", "hash": "5b4936023dd04998eaaa476b224d24a8ca2c7743", "best_bid": "0", "best_ask": "1"}], "timestamp": "1769384070859", "event_type": "price_change"}}
{"_local_timestamp": "2026-01-25T23:34:31.080157+00:00", "data": {"market": "0xa55cb5ef47b120e20225dfac4260a852ff2d66b1029be84140826358dd17d57f", "price_changes": [{"asset_id": "72393438098466972297597674006747034220924966382899877769423450749463824041513", "price": "0.991", "size": "0", "side": "BUY", "hash": "6fadc1277eefd5177ac969d69b69be2a5fa5feaf", "best_bid": "0", "best_ask": "1"}, {"asset_id": "112772951724658729290014487768777270812018717251551412726994926163223979407893", "price": "0.009", "size": "0", "side": "SELL", "hash": "5b4936023dd04998eaaa476b224d24a8ca2c7743", "best_bid": "0", "best_ask": "1"}], "timestamp": "1769384070859", "event_type": "price_change"}}
{"_local_timestamp": "2026-01-25T23:34:31.082456+00:00", "data": {"market": "0xa55cb5ef47b120e20225dfac4260a852ff2d66b1029be84140826358dd17d57f", "price_changes": [{"asset_id": "72393438098466972297597674006747034220924966382899877769423450749463824041513", "price": "0.994", "size": "0", "side": "BUY", "hash": "6fadc1277eefd5177ac969d69b69be2a5fa5feaf", "best_bid": "0", "best_ask": "1"}, {"asset_id": "112772951724658729290014487768777270812018717251551412726994926163223979407893", "price": "0.006", "size": "0", "side": "SELL", "hash": "5b4936023dd04998eaaa476b224d24a8ca2c7743", "best_bid": "0", "best_ask": "1"}], "timestamp": "1769384070859", "event_type": "price_change"}}
{"_local_timestamp": "2026-01-25T23:34:31.101309+00:00", "data": {"market": "0xa55cb5ef47b120e20225dfac4260a852ff2d66b1029be84140826358dd17d57f", "price_changes": [{"asset_id": "72393438098466972297597674006747034220924966382899877769423450749463824041513", "price": "0.143", "size": "0", "side": "BUY", "hash": "6fadc1277eefd5177ac969d69b69be2a5fa5feaf", "best_bid": "0", "best_ask": "1"}, {"asset_id": "112772951724658729290014487768777270812018717251551412726994926163223979407893", "price": "0.857", "size": "0", "side": "SELL", "hash": "5b4936023dd04998eaaa476b224d24a8ca2c7743", "best_bid": "0", "best_ask": "1"}], "timestamp": "1769384070859", "event_type": "price_change"}}
{"_local_timestamp": "2026-01-25T23:34:31.101846+00:00", "data": {"market": "0xa55cb5ef47b120e20225dfac4260a852ff2d66b1029be84140826358dd17d57f", "price_changes": [{"asset_id": "72393438098466972297597674006747034220924966382899877769423450749463824041513", "price": "0.993", "size": "0", "side": "BUY", "hash": "6fadc1277eefd5177ac969d69b69be2a5fa5feaf", "best_bid": "0", "best_ask": "1"}, {"asset_id": "112772951724658729290014487768777270812018717251551412726994926163223979407893", "price": "0.007", "size": "0", "side": "SELL", "hash": "5b4936023dd04998eaaa476b224d24a8ca2c7743", "best_bid": "0", "best_ask": "1"}], "timestamp": "1769384070859", "event_type": "price_change"}}
{"_local_timestamp": "2026-01-25T23:34:31.102196+00:00", "data": {"market": "0xa55cb5ef47b120e20225dfac4260a852ff2d66b1029be84140826358dd17d57f", "price_changes": [{"asset_id": "72393438098466972297597674006747034220924966382899877769423450749463824041513", "price": "0.02", "size": "0", "side": "BUY", "hash": "6fadc1277eefd5177ac969d69b69be2a5fa5feaf", "best_bid": "0", "best_ask": "1"}, {"asset_id": "112772951724658729290014487768777270812018717251551412726994926163223979407893", "price": "0.98", "size": "0", "side": "SELL", "hash": "5b4936023dd04998eaaa476b224d24a8ca2c7743", "best_bid": "0", "best_ask": "1"}], "timestamp": "1769384070859", "event_type": "price_change"}}
{"_local_timestamp": "2026-01-25T23:34:31.102557+00:00", "data": {"market": "0xa55cb5ef47b120e20225dfac4260a852ff2d66b1029be84140826358dd17d57f", "price_changes": [{"asset_id": "72393438098466972297597674006747034220924966382899877769423450749463824041513", "price": "0.099", "size": "0", "side": "BUY", "hash": "6fadc1277eefd5177ac969d69b69be2a5fa5feaf", "best_bid": "0", "best_ask": "1"}, {"asset_id": "112772951724658729290014487768777270812018717251551412726994926163223979407893", "price": "0.901", "size": "0", "side": "SELL", "hash": "5b4936023dd04998eaaa476b224d24a8ca2c7743", "best_bid": "0", "best_ask": "1"}], "timestamp": "1769384070859", "event_type": "price_change"}}
{"_local_timestamp": "2026-01-25T23:34:31.102894+00:00", "data": {"market": "0xa55cb5ef47b120e20225dfac4260a852ff2d66b1029be84140826358dd17d57f", "price_changes": [{"asset_id": "72393438098466972297597674006747034220924966382899877769423450749463824041513", "price": "0.05", "size": "0", "side": "BUY", "hash": "6fadc1277eefd5177ac969d69b69be2a5fa5feaf", "best_bid": "0", "best_ask": "1"}, {"asset_id": "112772951724658729290014487768777270812018717251551412726994926163223979407893", "price": "0.95", "size": "0", "side": "SELL", "hash": "5b4936023dd04998eaaa476b224d24a8ca2c7743", "best_bid": "0", "best_ask": "1"}], "timestamp": "1769384070859", "event_type": "price_change"}}
{"_local_timestamp": "2026-01-25T23:34:31.103997+00:00", "data": {"market": "0xa55cb5ef47b120e20225dfac4260a852ff2d66b1029be84140826358dd17d57f", "price_changes": [{"asset_id": "72393438098466972297597674006747034220924966382899877769423450749463824041513", "price": "0.1", "size": "0", "side": "BUY", "hash": "6fadc1277eefd5177ac969d69b69be2a5fa5feaf", "best_bid": "0", "best_ask": "1"}, {"asset_id": "112772951724658729290014487768777270812018717251551412726994926163223979407893", "price": "0.9", "size": "0", "side": "SELL", "hash": "5b4936023dd04998eaaa476b224d24a8ca2c7743", "best_bid": "0", "best_ask": "1"}], "timestamp": "1769384070859", "event_type": "price_change"}}
{"_local_timestamp": "2026-01-25T23:34:31.105584+00:00", "data": {"market": "0xa55cb5ef47b120e20225dfac4260a852ff2d66b1029be84140826358dd17d57f", "price_changes": [{"asset_id": "72393438098466972297597674006747034220924966382899877769423450749463824041513", "price": "0.995", "size": "0", "side": "BUY", "hash": "6fadc1277eefd5177ac969d69b69be2a5fa5feaf", "best_bid": "0", "best_ask": "1"}, {"asset_id": "112772951724658729290014487768777270812018717251551412726994926163223979407893", "price": "0.005", "size": "0", "side": "SELL", "hash": "5b4936023dd04998eaaa476b224d24a8ca2c7743", "best_bid": "0", "best_ask": "1"}], "timestamp": "1769384070859", "event_type": "price_change"}}
{"_local_timestamp": "2026-01-25T23:34:31.106182+00:00", "data": {"market": "0xa55cb5ef47b120e20225dfac4260a852ff2d66b1029be84140826358dd17d57f", "price_changes": [{"asset_id": "72393438098466972297597674006747034220924966382899877769423450749463824041513", "price": "0.998", "size": "0", "side": "BUY", "hash": "6fadc1277eefd5177ac969d69b69be2a5fa5feaf", "best_bid": "0", "best_ask": "1"}, {"asset_id": "112772951724658729290014487768777270812018717251551412726994926163223979407893", "price": "0.002", "size": "0", "side": "SELL", "hash": "5b4936023dd04998eaaa476b224d24a8ca2c7743", "best_bid": "0", "best_ask": "1"}], "timestamp": "1769384070859", "event_type": "price_change"}}
{"_local_timestamp": "2026-01-25T23:34:31.107622+00:00", "data": {"market": "0xa55cb5ef47b120e20225dfac4260a852ff2d66b1029be84140826358dd17d57f", "price_changes": [{"asset_id": "72393438098466972297597674006747034220924966382899877769423450749463824041513", "price": "0.997", "size": "0", "side": "BUY", "hash": "6fadc1277eefd5177ac969d69b69be2a5fa5feaf", "best_bid": "0", "best_ask": "1"}, {"asset_id": "112772951724658729290014487768777270812018717251551412726994926163223979407893", "price": "0.003", "size": "0", "side": "SELL", "hash": "5b4936023dd04998eaaa476b224d24a8ca2c7743", "best_bid": "0", "best_ask": "1"}], "timestamp": "1769384070859", "event_type": "price_change"}}
{"_local_timestamp": "2026-01-25T23:34:31.108090+00:00", "data": {"market": "0xa55cb5ef47b120e20225dfac4260a852ff2d66b1029be84140826358dd17d57f", "price_changes": [{"asset_id": "72393438098466972297597674006747034220924966382899877769423450749463824041513", "price": "0.99", "size": "0", "side": "BUY", "hash": "6fadc1277eefd5177ac969d69b69be2a5fa5feaf", "best_bid": "0", "best_ask": "1"}, {"asset_id": "112772951724658729290014487768777270812018717251551412726994926163223979407893", "price": "0.01", "size": "0", "side": "SELL", "hash": "5b4936023dd04998eaaa476b224d24a8ca2c7743", "best_bid": "0", "best_ask": "1"}], "timestamp": "1769384070859", "event_type": "price_change"}}
{"_local_timestamp": "2026-01-25T23:34:31.108646+00:00", "data": {"market": "0xa55cb5ef47b120e20225dfac4260a852ff2d66b1029be84140826358dd17d57f", "price_changes": [{"asset_id": "72393438098466972297597674006747034220924966382899877769423450749463824041513", "price": "0.77", "size": "0", "side": "BUY", "hash": "6fadc1277eefd5177ac969d69b69be2a5fa5feaf", "best_bid": "0", "best_ask": "1"}, {"asset_id": "112772951724658729290014487768777270812018717251551412726994926163223979407893", "price": "0.23", "size": "0", "side": "SELL", "hash": "5b4936023dd04998eaaa476b224d24a8ca2c7743", "best_bid": "0", "best_ask": "1"}], "timestamp": "1769384070859", "event_type": "price_change"}}
{"_local_timestamp": "2026-01-25T23:34:31.109247+00:00", "data": {"market": "0xa55cb5ef47b120e20225dfac4260a852ff2d66b1029be84140826358dd17d57f", "price_changes": [{"asset_id": "72393438098466972297597674006747034220924966382899877769423450749463824041513", "price": "0.47", "size": "0", "side": "BUY", "hash": "6fadc1277eefd5177ac969d69b69be2a5fa5feaf", "best_bid": "0", "best_ask": "1"}, {"asset_id": "112772951724658729290014487768777270812018717251551412726994926163223979407893", "price": "0.53", "size": "0", "side": "SELL", "hash": "5b4936023dd04998eaaa476b224d24a8ca2c7743", "best_bid": "0", "best_ask": "1"}], "timestamp": "1769384070859", "event_type": "price_change"}}
{"_local_timestamp": "2026-01-25T23:34:31.109816+00:00", "data": {"market": "0xa55cb5ef47b120e20225dfac4260a852ff2d66b1029be84140826358dd17d57f", "price_changes": [{"asset_id": "72393438098466972297597674006747034220924966382899877769423450749463824041513", "price": "0.767", "size": "0", "side": "BUY", "hash": "6fadc1277eefd5177ac969d69b69be2a5fa5feaf", "best_bid": "0", "best_ask": "1"}, {"asset_id": "112772951724658729290014487768777270812018717251551412726994926163223979407893", "price": "0.233", "size": "0", "side": "SELL", "hash": "5b4936023dd04998eaaa476b224d24a8ca2c7743", "best_bid": "0", "best_ask": "1"}], "timestamp": "1769384070859", "event_type": "price_change"}}
{"_local_timestamp": "2026-01-25T23:34:31.110202+00:00", "data": {"market": "0xa55cb5ef47b120e20225dfac4260a852ff2d66b1029be84140826358dd17d57f", "price_changes": [{"asset_id": "72393438098466972297597674006747034220924966382899877769423450749463824041513", "price": "0.111", "size": "0", "side": "BUY", "hash": "6fadc1277eefd5177ac969d69b69be2a5fa5feaf", "best_bid": "0", "best_ask": "1"}, {"asset_id": "112772951724658729290014487768777270812018717251551412726994926163223979407893", "price": "0.889", "size": "0", "side": "SELL", "hash": "5b4936023dd04998eaaa476b224d24a8ca2c7743", "best_bid": "0", "best_ask": "1"}], "timestamp": "1769384070859", "event_type": "price_change"}}
{"_local_timestamp": "2026-01-25T23:34:31.110734+00:00", "data": {"market": "0xa55cb5ef47b120e20225dfac4260a852ff2d66b1029be84140826358dd17d57f", "price_changes": [{"asset_id": "72393438098466972297597674006747034220924966382899877769423450749463824041513", "price": "0.996", "size": "0", "side": "BUY", "hash": "6fadc1277eefd5177ac969d69b69be2a5fa5feaf", "best_bid": "0", "best_ask": "1"}, {"asset_id": "112772951724658729290014487768777270812018717251551412726994926163223979407893", "price": "0.004", "size": "0", "side": "SELL", "hash": "5b4936023dd04998eaaa476b224d24a8ca2c7743", "best_bid": "0", "best_ask": "1"}], "timestamp": "1769384070859", "event_type": "price_change"}}
{"_local_timestamp": "2026-01-25T23:34:31.112163+00:00", "data": {"market": "0xa55cb5ef47b120e20225dfac4260a852ff2d66b1029be84140826358dd17d57f", "price_changes": [{"asset_id": "72393438098466972297597674006747034220924966382899877769423450749463824041513", "price": "0.04", "size": "0", "side": "BUY", "hash": "6fadc1277eefd5177ac969d69b69be2a5fa5feaf", "best_bid": "0", "best_ask": "1"}, {"asset_id": "112772951724658729290014487768777270812018717251551412726994926163223979407893", "price": "0.96", "size": "0", "side": "SELL", "hash": "5b4936023dd04998eaaa476b224d24a8ca2c7743", "best_bid": "0", "best_ask": "1"}], "timestamp": "1769384070859", "event_type": "price_change"}}
{"_local_timestamp": "2026-01-25T23:34:31.112735+00:00", "data": {"market": "0xa55cb5ef47b120e20225dfac4260a852ff2d66b1029be84140826358dd17d57f", "price_changes": [{"asset_id": "72393438098466972297597674006747034220924966382899877769423450749463824041513", "price": "0.769", "size": "0", "side": "BUY", "hash": "6fadc1277eefd5177ac969d69b69be2a5fa5feaf", "best_bid": "0", "best_ask": "1"}, {"asset_id": "112772951724658729290014487768777270812018717251551412726994926163223979407893", "price": "0.231", "size": "0", "side": "SELL", "hash": "5b4936023dd04998eaaa476b224d24a8ca2c7743", "best_bid": "0", "best_ask": "1"}], "timestamp": "1769384070859", "event_type": "price_change"}}
{"_local_timestamp": "2026-01-25T23:34:31.113415+00:00", "data": {"market": "0xa55cb5ef47b120e20225dfac4260a852ff2d66b1029be84140826358dd17d57f", "price_changes": [{"asset_id": "72393438098466972297597674006747034220924966382899877769423450749463824041513", "price": "0.008", "size": "0", "side": "BUY", "hash": "6fadc1277eefd5177ac969d69b69be2a5fa5feaf", "best_bid": "0", "best_ask": "1"}, {"asset_id": "112772951724658729290014487768777270812018717251551412726994926163223979407893", "price": "0.992", "size": "0", "side": "SELL", "hash": "5b4936023dd04998eaaa476b224d24a8ca2c7743", "best_bid": "0", "best_ask": "1"}], "timestamp": "1769384070859", "event_type": "price_change"}}
{"_local_timestamp": "2026-01-25T23:34:31.115055+00:00", "data": {"market": "0xa55cb5ef47b120e20225dfac4260a852ff2d66b1029be84140826358dd17d57f", "price_changes": [{"asset_id": "72393438098466972297597674006747034220924966382899877769423450749463824041513", "price": "0.992", "size": "0", "side": "BUY", "hash": "6fadc1277eefd5177ac969d69b69be2a5fa5feaf", "best_bid": "0", "best_ask": "1"}, {"asset_id": "112772951724658729290014487768777270812018717251551412726994926163223979407893", "price": "0.008", "size": "0", "side": "SELL", "hash": "5b4936023dd04998eaaa476b224d24a8ca2c7743", "best_bid": "0", "best_ask": "1"}], "timestamp": "1769384070859", "event_type": "price_change"}}
{"_local_timestamp": "2026-01-25T23:34:31.115502+00:00", "data": {"market": "0xa55cb5ef47b120e20225dfac4260a852ff2d66b1029be84140826358dd17d57f", "price_changes": [{"asset_id": "72393438098466972297597674006747034220924966382899877769423450749463824041513", "price": "0.49", "size": "0", "side": "BUY", "hash": "6fadc1277eefd5177ac969d69b69be2a5fa5feaf", "best_bid": "0", "best_ask": "1"}, {"asset_id": "112772951724658729290014487768777270812018717251551412726994926163223979407893", "price": "0.51", "size": "0", "side": "SELL", "hash": "5b4936023dd04998eaaa476b224d24a8ca2c7743", "best_bid": "0", "best_ask": "1"}], "timestamp": "1769384070859", "event_type": "price_change"}}
{"_local_timestamp": "2026-01-25T23:34:31.116228+00:00", "data": {"market": "0xa55cb5ef47b120e20225dfac4260a852ff2d66b1029be84140826358dd17d57f", "price_changes": [{"asset_id": "72393438098466972297597674006747034220924966382899877769423450749463824041513", "price": "0.768", "size": "0", "side": "BUY", "hash": "6fadc1277eefd5177ac969d69b69be2a5fa5feaf", "best_bid": "0", "best_ask": "1"}, {"asset_id": "112772951724658729290014487768777270812018717251551412726994926163223979407893", "price": "0.232", "size": "0", "side": "SELL", "hash": "5b4936023dd04998eaaa476b224d24a8ca2c7743", "best_bid": "0", "best_ask": "1"}], "timestamp": "1769384070859", "event_type": "price_change"}}
{"_local_timestamp": "2026-01-25T23:34:31.116795+00:00", "data": {"market": "0xa55cb5ef47b120e20225dfac4260a852ff2d66b1029be84140826358dd17d57f", "price_changes": [{"asset_id": "72393438098466972297597674006747034220924966382899877769423450749463824041513", "price": "0.097", "size": "0", "side": "BUY", "hash": "6fadc1277eefd5177ac969d69b69be2a5fa5feaf", "best_bid": "0", "best_ask": "1"}, {"asset_id": "112772951724658729290014487768777270812018717251551412726994926163223979407893", "price": "0.903", "size": "0", "side": "SELL", "hash": "5b4936023dd04998eaaa476b224d24a8ca2c7743", "best_bid": "0", "best_ask": "1"}], "timestamp": "1769384070859", "event_type": "price_change"}}
{"_local_timestamp": "2026-01-25T23:34:31.117207+00:00", "data": {"market": "0xa55cb5ef47b120e20225dfac4260a852ff2d66b1029be84140826358dd17d57f", "price_changes": [{"asset_id": "72393438098466972297597674006747034220924966382899877769423450749463824041513", "price": "0.75", "size": "0", "side": "BUY", "hash": "6fadc1277eefd5177ac969d69b69be2a5fa5feaf", "best_bid": "0", "best_ask": "1"}, {"asset_id": "112772951724658729290014487768777270812018717251551412726994926163223979407893", "price": "0.25", "size": "0", "side": "SELL", "hash": "5b4936023dd04998eaaa476b224d24a8ca2c7743", "best_bid": "0", "best_ask": "1"}], "timestamp": "1769384070859", "event_type": "price_change"}}
