{"_local_timestamp": "2026-01-25T23:41:27.714933+00:00", "data": [{"market": "0x15beb6ee455f9837b69cd7dcd110770b2f489d88651e4ffb21cd54f617a23e04", "asset_id": "44868850067599122384522819337153865676781090849621105309651139851616912647528", "timestamp": "1769384425876", "hash": "dadf11661f1e33d188ac8ab6f92d8dea7642bf94", "bids": [{"price": "0.01", "size": "1138.33"}, {"price": "0.02", "size": "47.33"}, {"price": "0.48", "size": "500"}], "asks": [{"price": "0.99", "size": "1138.52"}, {"price": "0.98", "size": "47.23"}, {"price": "0.58", "size": "500"}], "event_type": "book", "last_trade_price": ""}, {"market": "0xecbb7178261e45c45a2d40f3ba28f7b90da88f208a43e3c8f0bd9f7d69900ddc", "asset_id": "75087175062739028357071911202249876424512123621414420427750062298373802728902", "timestamp": "1769384465499", "hash": "4bee8f4b4a2225fac86ae193365d3385decc20e0", "bids": [{"price": "0.01", "size": "8789.01"}, {"price": "0.02", "size": "2100"}, {"price": "0.03", "size": "8.13"}, {"price": "0.07", "size": "1700"}, {"price": "0.08", "size": "4857.32"}, {"price": "0.09", "size": "4157.32"}, {"price": "0.1", "size": "6.57"}, {"price": "0.14", "size": "300"}, {"price": "0.2", "size": "50"}, {"price": "0.27", "size": "50"}, {"price": "0.5", "size": "10"}, {"price": "0.6", "size": "1890.11"}, {"price": "0.61", "size": "890.11"}, {"price": "0.63", "size": "100"}, {"price": "0.64", "size": "50"}], "asks": [{"price": "0.99", "size": "8779.11"}, {"price": "0.98", "size": "4463.36"}, {"price": "0.96", "size": "21.97"}, {"price": "0.8", "size": "10"}, {"price": "0.73", "size": "91.94"}, {"price": "0.72", "size": "1000"}, {"price": "0.7", "size": "2140.11"}, {"price": "0.69", "size": "890.11"}], "event_type": "book", "last_trade_price": "0.270"}, {"market": "0xc2db3c0906ac69232c4998f436e34e5df7e64b6dd2d9cb9ddd6305f2aef23c0d", "asset_id": "26283804933183319314833342421447518362320608677704153347603079425527445471777", "timestamp": "1769384425877", "hash": "6ba13f5d5ad74db9152532d141545a6bc892ec81", "bids": [{"price": "0.01", "size": "7184.21"}, {"price": "0.02", "size": "4157.32"}, {"price": "0.03", "size": "921.74"}, {"price": "0.04", "size": "5047.43"}, {"price": "0.2", "size": "50"}, {"price": "0.56", "size": "1390.11"}, {"price": "0.57", "size": "890.11"}], "asks": [{"price": "0.99", "size": "7184.22"}, {"price": "0.98", "size": "4157.32"}, {"price": "0.97", "size": "31.63"}, {"price": "0.96", "size": "6889.22"}, {"price": "0.95", "size": "5047.43"}, {"price": "0.67", "size": "1390.11"}, {"price": "0.66", "size": "890.11"}], "event_type": "book", "last_trade_price": ""}, {"market": "0xecbb7178261e45c45a2d40f3ba28f7b90da88f208a43e3c8f0bd9f7d69900ddc", "asset_id": "51057777902653789433362935484116310785534127104787453577540080102342088856991", "timestamp": "1769384465499", "hash": "30c406b86aca6c7875a0dc735dad6e295d94006a", "bids": [{"price": "0.01", "size": "8779.11"}, {"price": "0.02", "size": "4463.36"}, {"price": "0.04", "size": "21.97"}, {"price": "0.2", "size": "10"}, {"price": "0.27", "size": "91.94"}, {"price": "0.28", "size": "1000"}, {"price": "0.3", "size": "2140.11"}, {"price": "0.31", "size": "890.11"}], "asks": [{"price": "0.99", "size": "8789.01"}, {"price": "0.98", "size": "2100"}, {"price": "0.97", "size": "8.13"}, {"price": "0.93", "size": "1700"}, {"price": "0.92", "size": "4857.32"}, {"price": "0.91", "size": "4157.32"}, {"price": "0.9", "size": "6.57"}, {"price": "0.86", "size": "300"}, {"price": "0.8", "size": "50"}, {"price": "0.73", "size": "50"}, {"price": "0.5", "size": "10"}, {"price": "0.4", "size": "1890.11"}, {"price": "0.39", "size": "890.11"}, {"price": "0.37", "size": "100"}, {"price": "0.36", "size": "50"}], "event_type": "book", "last_trade_price": "0.270"}, {"market": "0x15beb6ee455f9837b69cd7dcd110770b2f489d88651e4ffb21cd54f617a23e04", "asset_id": "14205737424716982918858761268248742215558565679165887656230879609115111732505", "timestamp": "1769384425876", "hash": "c64632da10d376c6b0a2b40eef095283969055d9", "bids": [{"price": "0.01", "size": "1138.52"}, {"price": "0.02", "size": "47.23"}, {"price": "0.42", "size": "500"}], "asks": [{"price": "0.99", "size": "1138.33"}, {"price": "0.98", "size": "47.33"}, {"price": "0.52", "size": "500"}], "event_type": "book", "last_trade_price": ""}, {"market": "0x171b0625db2b7f2ac2848455143776eec779ee85f6359364c1b423b23b32fc68", "asset_id": "17118621258018130257689540837975706602158094977984538267313954503349864657420", "timestamp": "1769384425884", "hash": "3dbf3b74bb3161149694abe747214205f145a80e", "bids": [{"price": "0.01", "size": "7184.28"}, {"price": "0.02", "size": "4157.32"}, {"price": "0.03", "size": "31.61"}, {"price": "0.04", "size": "890.11"}, {"price": "0.05", "size": "5047.43"}, {"price": "0.34", "size": "1390.11"}, {"price": "0.35", "size": "890.11"}], "asks": [{"price": "0.99", "size": "7189.21"}, {"price": "0.98", "size": "4157.32"}, {"price": "0.97", "size": "920.07"}, {"price": "0.96", "size": "11046.54"}, {"price": "0.8", "size": "50"}, {"price": "0.45", "size": "1390.11"}, {"price": "0.44", "size": "890.11"}], "event_type": "book", "last_trade_price": ""}, {"market": "0x8ccb39356d65ce6cd50d98b896351aaeff3a2d884158f6453fdec83a0f3f2361", "asset_id": "54115704767093899489859926330384345560631205111379974241224327571709257756515", "timestamp": "1769384438040", "hash": "5a7b5a0eb455e6aa92b4a78f13d0f54531b88bbe", "bids": [{"price": "0.01", "size": "106.9"}, {"price": "0.02", "size": "36.54"}, {"price": "0.03", "size": "5.47"}], "asks": [{"price": "0.99", "size": "100"}, {"price": "0.98", "size": "39.99"}, {"price": "0.96", "size": "29.99"}], "event_type": "book", "last_trade_price": ""}, {"market": "0xc2db3c0906ac69232c4998f436e34e5df7e64b6dd2d9cb9ddd6305f2aef23c0d", "asset_id": "68765318567686557797285708330422826706843409708557814702138983780254126785177", "timestamp": "1769384425877", "hash": "7a367983d9d0d1ac79b7a044ed6c232d76c0cbc3", "bids": [{"price": "0.01", "size": "7184.22"}, {"price": "0.02", "size": "4157.32"}, {"price": "0.03", "size": "31.63"}, {"price": "0.04", "size": "6889.22"}, {"price": "0.05", "size": "5047.43"}, {"price": "0.33", "size": "1390.11"}, {"price": "0.34", "size": "890.11"}], "asks": [{"price": "0.99", "size": "7184.21"}, {"price": "0.98", "size": "4157.32"}, {"price": "0.97", "size": "921.74"}, {"price": "0.96", "size": "5047.43"}, {"price": "0.8", "size": "50"}, {"price": "0.44", "size": "1390.11"}, {"price": "0.43", "size": "890.11"}], "event_type": "book", "last_trade_price": ""}, {"market": "0x8ccb39356d65ce6cd50d98b896351aaeff3a2d884158f6453fdec83a0f3f2361", "asset_id": "85979090154771566247057457488185735048733636408042266931260086497748605442725", "timestamp": "1769384438040", "hash": "fc81b4d461b05bdf5afff3685aa046c030e591a5", "bids": [{"price": "0.01", "size": "100"}, {"price": "0.02", "size": "39.99"}, {"price": "0.04", "size": "29.99"}], "asks": [{"price": "0.99", "size": "106.9"}, {"price": "0.98", "size": "36.54"}, {"price": "0.97", "size": "5.47"}], "event_type": "book", "last_trade_price": ""}, {"market": "0x171b0625db2b7f2ac2848455143776eec779ee85f6359364c1b423b23b32fc68", "asset_id": "110208037745521376477218629625161726044793864281199315926557875582085019919669", "timestamp": "1769384425884", "hash": "fcef8857416e526ba26f6923dc35766df4260dc3", "bids": [{"price": "0.01", "size": "7189.21"}, {"price": "0.02", "size": "4157.32"}, {"price": "0.03", "size": "920.07"}, {"price": "0.04", "size": "11046.54"}, {"price": "0.2", "size": "50"}, {"price": "0.55", "size": "1390.11"}, {"price": "0.56", "size": "890.11"}], "asks": [{"price": "0.99", "size": "7184.28"}, {"price": "0.98", "size": "4157.32"}, {"price": "0.97", "size": "31.61"}, {"price": "0.96", "size": "890.11"}, {"price": "0.95", "size": "5047.43"}, {"price": "0.66", "size": "1390.11"}, {"price": "0.65", "size": "890.11"}], "event_type": "book", "last_trade_price": ""}]}
{"_local_timestamp": "2026-01-25T23:41:27.948686+00:00", "data": {"market": "0xecbb7178261e45c45a2d40f3ba28f7b90da88f208a43e3c8f0bd9f7d69900ddc", "price_changes": [{"asset_id": "75087175062739028357071911202249876424512123621414420427750062298373802728902", "price": "0.08", "size": "4457.32", "side": "BUY", "hash": "b56cd39e5a2f81e584df0ef0079b9c4b5f2e1e07", "best_bid": "0.64", "best_ask": "0.69"}, {"asset_id": "51057777902653789433362935484116310785534127104787453577540080102342088856991", "price": "0.92", "size": "4457.32", "side": "SELL", "hash": "1a6a2739464330009ad8e9fd02a563608b2c6653", "best_bid": "0.31", "best_ask": "0.36"}], "timestamp": "1769384487844", "event_type": "price_change"}}
{"_local_timestamp": "2026-01-25T23:41:28.220949+00:00", "data": {"market": "0xecbb7178261e45c45a2d40f3ba28f7b90da88f208a43e3c8f0bd9f7d69900ddc", "price_changes": [{"asset_id": "75087175062739028357071911202249876424512123621414420427750062298373802728902", "price": "0.09", "size": "4557.32", "side": "BUY", "hash": "4568911a3b47ee0c759507159cbc0cc8cab6cff7", "best_bid": "0.64", "best_ask": "0.69"}, {"asset_id": "51057777902653789433362935484116310785534127104787453577540080102342088856991", "price": "0.91", "size": "4557.32", "side": "SELL", "hash": "1cc3bb0a15bb329d130fb87b6b7f99e147591ece", "best_bid": "0.31", "best_ask": "0.36"}], "timestamp": "1769384488124", "event_type": "price_change"}}
{"_local_timestamp": "2026-01-25T23:41:44.738935+00:00", "data": {"market": "0xc2db3c0906ac69232c4998f436e34e5df7e64b6dd2d9cb9ddd6305f2aef23c0d", "price_changes": [{"asset_id": "68765318567686557797285708330422826706843409708557814702138983780254126785177", "price": "0.03", "size": "0", "side": "BUY", "hash": "4b55408a630801dd32479dcbf48ba911aa370a67", "best_bid": "0.34", "best_ask": "0.43"}, {"asset_id": "26283804933183319314833342421447518362320608677704153347603079425527445471777", "price": "0.97", "size": "0", "side": "SELL", "hash": "11f51af6bf54337f2adccdaa0d8669d358e47bd3", "best_bid": "0.57", "best_ask": "0.66"}], "timestamp": "1769384504668", "event_type": "price_change"}}
{"_local_timestamp": "2026-01-25T23:41:44.786575+00:00", "data": {"market": "0xc2db3c0906ac69232c4998f436e34e5df7e64b6dd2d9cb9ddd6305f2aef23c0d", "price_changes": [{"asset_id": "68765318567686557797285708330422826706843409708557814702138983780254126785177", "price": "0.05", "size": "0", "side": "BUY", "hash": "bd1a9fdd76509be7e3d33cdcae74eb3fd0fd5f95", "best_bid": "0.34", "best_ask": "0.43"}, {"asset_id": "26283804933183319314833342421447518362320608677704153347603079425527445471777", "price": "0.95", "size": "0", "side": "SELL", "hash": "beecfb07562b29d1368ee9cd11e9c654194bc912", "best_bid": "0.57", "best_ask": "0.66"}], "timestamp": "1769384504709", "event_type": "price_change"}}
{"_local_timestamp": "2026-01-25T23:41:44.786963+00:00", "data": {"market": "0xc2db3c0906ac69232c4998f436e34e5df7e64b6dd2d9cb9ddd6305f2aef23c0d", "price_changes": [{"asset_id": "68765318567686557797285708330422826706843409708557814702138983780254126785177", "price": "0.04", "size": "0", "side": "BUY", "hash": "bd1a9fdd76509be7e3d33cdcae74eb3fd0fd5f95", "best_bid": "0.34", "best_ask": "0.43"}, {"asset_id": "26283804933183319314833342421447518362320608677704153347603079425527445471777", "price": "0.96", "size": "0", "side": "SELL", "hash": "beecfb07562b29d1368ee9cd11e9c654194bc912", "best_bid": "0.57", "best_ask": "0.66"}], "timestamp": "1769384504709", "event_type": "price_change"}}
{"_local_timestamp": "2026-01-25T23:41:44.792639+00:00", "data": {"market": "0xc2db3c0906ac69232c4998f436e34e5df7e64b6dd2d9cb9ddd6305f2aef23c0d", "price_changes": [{"asset_id": "26283804933183319314833342421447518362320608677704153347603079425527445471777", "price": "0.04", "size": "0", "side": "BUY", "hash": "c50656404342b1cf7d456185fff9410d6f53eedf", "best_bid": "0.57", "best_ask": "0.66"}, {"asset_id": "68765318567686557797285708330422826706843409708557814702138983780254126785177", "price": "0.96", "size": "0", "side": "SELL", "hash": "b208b79c10b769d553c465f7795a6d6c49bdaed7", "best_bid": "0.34", "best_ask": "0.43"}], "timestamp": "1769384504709", "event_type": "price_change"}}
{"_local_timestamp": "2026-01-25T23:41:44.792951+00:00", "data": {"market": "0xc2db3c0906ac69232c4998f436e34e5df7e64b6dd2d9cb9ddd6305f2aef23c0d", "price_changes": [{"asset_id": "26283804933183319314833342421447518362320608677704153347603079425527445471777", "price": "0.03", "size": "31.63", "side": "BUY", "hash": "c50656404342b1cf7d456185fff9410d6f53eedf", "best_bid": "0.57", "best_ask": "0.66"}, {"asset_id": "68765318567686557797285708330422826706843409708557814702138983780254126785177", "price": "0.97", "size": "31.63", "side": "SELL", "hash": "b208b79c10b769d553c465f7795a6d6c49bdaed7", "best_bid": "0.34", "best_ask": "0.43"}], "timestamp": "1769384504709", "event_type": "price_change"}}
{"_local_timestamp": "2026-01-25T23:41:44.814521+00:00", "data": {"market": "0xc2db3c0906ac69232c4998f436e34e5df7e64b6dd2d9cb9ddd6305f2aef23c0d", "price_changes": [{"asset_id": "26283804933183319314833342421447518362320608677704153347603079425527445471777", "price": "0.05", "size": "5999.11", "side": "BUY", "hash": "e5128c464962eb1a7a612aa43dd00a18e318b5ca", "best_bid": "0.57", "best_ask": "0.66"}, {"asset_id": "68765318567686557797285708330422826706843409708557814702138983780254126785177", "price": "0.95", "size": "5999.11", "side": "SELL", "hash": "506fa4da8045315e4e5033457e0a01827be038f8", "best_bid": "0.34", "best_ask": "0.43"}], "timestamp": "1769384504743", "event_type": "price_change"}}
{"_local_timestamp": "2026-01-25T23:41:45.043971+00:00", "data": {"market": "0xc2db3c0906ac69232c4998f436e34e5df7e64b6dd2d9cb9ddd6305f2aef23c0d", "price_changes": [{"asset_id": "26283804933183319314833342421447518362320608677704153347603079425527445471777", "price": "0.05", "size": "6889.22", "side": "BUY", "hash": "4dea521df27c702b0b871462dfc56df6b2ae6c2c", "best_bid": "0.57", "best_ask": "0.66"}, {"asset_id": "68765318567686557797285708330422826706843409708557814702138983780254126785177", "price": "0.95", "size": "6889.22", "side": "SELL", "hash": "24a3a62b54c041657737b042f18e9ac3b473b81d", "best_bid": "0.34", "best_ask": "0.43"}], "timestamp": "1769384504976", "event_type": "price_change"}}
{"_local_timestamp": "2026-01-25T23:41:45.044375+00:00", "data": {"market": "0xc2db3c0906ac69232c4998f436e34e5df7e64b6dd2d9cb9ddd6305f2aef23c0d", "price_changes": [{"asset_id": "26283804933183319314833342421447518362320608677704153347603079425527445471777", "price": "0.04", "size": "1997.11", "side": "BUY", "hash": "76fd373f5a19c552c43b65c493b8e758b70d9ad3", "best_bid": "0.57", "best_ask": "0.66"}, {"asset_id": "68765318567686557797285708330422826706843409708557814702138983780254126785177", "price": "0.96", "size": "1997.11", "side": "SELL", "hash": "6033202717b5c3b25c3a8b38e246160d53beee97", "best_bid": "0.34", "best_ask": "0.43"}], "timestamp": "1769384504977", "event_type": "price_change"}}
{"_local_timestamp": "2026-01-25T23:41:45.044703+00:00", "data": {"market": "0xc2db3c0906ac69232c4998f436e34e5df7e64b6dd2d9cb9ddd6305f2aef23c0d", "price_changes": [{"asset_id": "26283804933183319314833342421447518362320608677704153347603079425527445471777", "price": "0.05", "size": "8159.32", "side": "BUY", "hash": "1db42c9a5eb73ecd79c2b2c49770552a7ea3a998", "best_bid": "0.57", "best_ask": "0.66"}, {"asset_id": "68765318567686557797285708330422826706843409708557814702138983780254126785177", "price": "0.95", "size": "8159.32", "side": "SELL", "hash": "3cfbcec061509ecc401008854f5615cd20b10728", "best_bid": "0.34", "best_ask": "0.43"}], "timestamp": "1769384504978", "event_type": "price_change"}}
{"_local_timestamp": "2026-01-25T23:41:45.377122+00:00", "data": {"market": "0xc2db3c0906ac69232c4998f436e34e5df7e64b6dd2d9cb9ddd6305f2aef23c0d", "price_changes": [{"asset_id": "68765318567686557797285708330422826706843409708557814702138983780254126785177", "price": "0.03", "size": "31.63", "side": "BUY", "hash": "a128bae3af08ffa49a546ce83c49599f6a8d7f20", "best_bid": "0.34", "best_ask": "0.43"}, {"asset_id": "26283804933183319314833342421447518362320608677704153347603079425527445471777", "price": "0.97", "size": "31.63", "side": "SELL", "hash": "71a892d4810a22e7d0674768d6194feb55c09921", "best_bid": "0.57", "best_ask": "0.66"}], "timestamp": "1769384505311", "event_type": "price_change"}}
{"_local_timestamp": "2026-01-25T23:41:45.762641+00:00", "data": {"market": "0xc2db3c0906ac69232c4998f436e34e5df7e64b6dd2d9cb9ddd6305f2aef23c0d", "price_changes": [{"asset_id": "26283804933183319314833342421447518362320608677704153347603079425527445471777", "price": "0.03", "size": "0", "side": "BUY", "hash": "4aa0aeac4c1011003ecba19e6c1e25dc1753d894", "best_bid": "0.57", "best_ask": "0.66"}, {"asset_id": "68765318567686557797285708330422826706843409708557814702138983780254126785177", "price": "0.97", "size": "0", "side": "SELL", "hash": "3f8c66a37df0cd69dd165184f30fc253bbf972fc", "best_bid": "0.34", "best_ask": "0.43"}], "timestamp": "1769384505698", "event_type": "price_change"}}
{"_local_timestamp": "2026-01-25T23:41:45.763085+00:00", "data": {"market": "0x171b0625db2b7f2ac2848455143776eec779ee85f6359364c1b423b23b32fc68", "price_changes": [{"asset_id": "17118621258018130257689540837975706602158094977984538267313954503349864657420", "price": "0.03", "size": "0", "side": "BUY", "hash": "fed10d9f9739271a7b0da3ae051bd6696694a54b", "best_bid": "0.35", "best_ask": "0.44"}, {"asset_id": "110208037745521376477218629625161726044793864281199315926557875582085019919669", "price": "0.97", "size": "0", "side": "SELL", "hash": "8a1113c3eb6f6b3d8b4e49aff7912612b914e80a", "best_bid": "0.56", "best_ask": "0.65"}], "timestamp": "1769384505698", "event_type": "price_change"}}
{"_local_timestamp": "2026-01-25T23:41:45.825173+00:00", "data": {"market": "0x171b0625db2b7f2ac2848455143776eec779ee85f6359364c1b423b23b32fc68", "price_changes": [{"asset_id": "17118621258018130257689540837975706602158094977984538267313954503349864657420", "price": "0.05", "size": "0", "side": "BUY", "hash": "167c501fb75c1325ce21189e0e05675d0638effd", "best_bid": "0.35", "best_ask": "0.44"}, {"asset_id": "110208037745521376477218629625161726044793864281199315926557875582085019919669", "price": "0.95", "size": "0", "side": "SELL", "hash": "52e89e3e17bf4ce25708b2cdc733dbab753cdbfd", "best_bid": "0.56", "best_ask": "0.65"}], "timestamp": "1769384505743", "event_type": "price_change"}}
{"_local_timestamp": "2026-01-25T23:41:45.825637+00:00", "data": {"market": "0x171b0625db2b7f2ac2848455143776eec779ee85f6359364c1b423b23b32fc68", "price_changes": [{"asset_id": "17118621258018130257689540837975706602158094977984538267313954503349864657420", "price": "0.04", "size": "0", "side": "BUY", "hash": "167c501fb75c1325ce21189e0e05675d0638effd", "best_bid": "0.35", "best_ask": "0.44"}, {"asset_id": "110208037745521376477218629625161726044793864281199315926557875582085019919669", "price": "0.96", "size": "0", "side": "SELL", "hash": "52e89e3e17bf4ce25708b2cdc733dbab753cdbfd", "best_bid": "0.56", "best_ask": "0.65"}], "timestamp": "1769384505743", "event_type": "price_change"}}
{"_local_timestamp": "2026-01-25T23:41:45.825995+00:00", "data": {"market": "0x171b0625db2b7f2ac2848455143776eec779ee85f6359364c1b423b23b32fc68", "price_changes": [{"asset_id": "110208037745521376477218629625161726044793864281199315926557875582085019919669", "price": "0.04", "size": "0", "side": "BUY", "hash": "88687885aaca0b114de15e4e2cd4c2118db753ef", "best_bid": "0.56", "best_ask": "0.65"}, {"asset_id": "17118621258018130257689540837975706602158094977984538267313954503349864657420", "price": "0.96", "size": "0", "side": "SELL", "hash": "d62d4ee3bf7cb64b8e2981f8adbf3e8c1063f8c3", "best_bid": "0.35", "best_ask": "0.44"}], "timestamp": "1769384505744", "event_type": "price_change"}}
{"_local_timestamp": "2026-01-25T23:41:45.826354+00:00", "data": {"market": "0x171b0625db2b7f2ac2848455143776eec779ee85f6359364c1b423b23b32fc68", "price_changes": [{"asset_id": "110208037745521376477218629625161726044793864281199315926557875582085019919669", "price": "0.03", "size": "29.96", "side": "BUY", "hash": "88687885aaca0b114de15e4e2cd4c2118db753ef", "best_bid": "0.56", "best_ask": "0.65"}, {"asset_id": "17118621258018130257689540837975706602158094977984538267313954503349864657420", "price": "0.97", "size": "29.96", "side": "SELL", "hash": "d62d4ee3bf7cb64b8e2981f8adbf3e8c1063f8c3", "best_bid": "0.35", "best_ask": "0.44"}], "timestamp": "1769384505744", "event_type": "price_change"}}
{"_local_timestamp": "2026-01-25T23:41:45.930631+00:00", "data": {"market": "0x171b0625db2b7f2ac2848455143776eec779ee85f6359364c1b423b23b32fc68", "price_changes": [{"asset_id": "110208037745521376477218629625161726044793864281199315926557875582085019919669", "price": "0.05", "size": "890.11", "side": "BUY", "hash": "d1e53525bc4a3a349ab5340dd9f85fcd3642b9c5", "best_bid": "0.56", "best_ask": "0.65"}, {"asset_id": "17118621258018130257689540837975706602158094977984538267313954503349864657420", "price": "0.95", "size": "890.11", "side": "SELL", "hash": "a26a1b53eae831c416dc1673520d4c4d24e85c10", "best_bid": "0.35", "best_ask": "0.44"}], "timestamp": "1769384505866", "event_type": "price_change"}}
{"_local_timestamp": "2026-01-25T23:41:45.931406+00:00", "data": {"market": "0x171b0625db2b7f2ac2848455143776eec779ee85f6359364c1b423b23b32fc68", "price_changes": [{"asset_id": "110208037745521376477218629625161726044793864281199315926557875582085019919669", "price": "0.05", "size": "2887.22", "side": "BUY", "hash": "9ac6e29f6fe022ad4e106f72cc113f84088ab987", "best_bid": "0.56", "best_ask": "0.65"}, {"asset_id": "17118621258018130257689540837975706602158094977984538267313954503349864657420", "price": "0.95", "size": "2887.22", "side": "SELL", "hash": "51d91790e66a0c83218384c5155af8f38f6aa400", "best_bid": "0.35", "best_ask": "0.44"}], "timestamp": "1769384505867", "event_type": "price_change"}}
{"_local_timestamp": "2026-01-25T23:41:45.931791+00:00", "data": {"market": "0x171b0625db2b7f2ac2848455143776eec779ee85f6359364c1b423b23b32fc68", "price_changes": [{"asset_id": "110208037745521376477218629625161726044793864281199315926557875582085019919669", "price": "0.05", "size": "4157.32", "side": "BUY", "hash": "d2b1ed5b5d731fd6a866fef0a37ec5d9851dcfec", "best_bid": "0.56", "best_ask": "0.65"}, {"asset_id": "17118621258018130257689540837975706602158094977984538267313954503349864657420", "price": "0.95", "size": "4157.32", "side": "SELL", "hash": "d95069666d0b96de4b151cbecded497719b85d8b", "best_bid": "0.35", "best_ask": "0.44"}], "timestamp": "1769384505867", "event_type": "price_change"}}
{"_local_timestamp": "2026-01-25T23:41:46.133429+00:00", "data": {"market": "0xc2db3c0906ac69232c4998f436e34e5df7e64b6dd2d9cb9ddd6305f2aef23c0d", "price_changes": [{"asset_id": "26283804933183319314833342421447518362320608677704153347603079425527445471777", "price": "0.06", "size": "12.77", "side": "BUY", "hash": "46bdada339afb1f15cb68a5ea67bedb6ea881a18", "best_bid": "0.57", "best_ask": "0.66"}, {"asset_id": "68765318567686557797285708330422826706843409708557814702138983780254126785177", "price": "0.94", "size": "12.77", "side": "SELL", "hash": "680a33fe5d0ef42cf9997c231b77cb6297ed4c3a", "best_bid": "0.34", "best_ask": "0.43"}], "timestamp": "1769384506065", "event_type": "price_change"}}
{"_local_timestamp": "2026-01-25T23:41:46.133918+00:00", "data": {"market": "0x171b0625db2b7f2ac2848455143776eec779ee85f6359364c1b423b23b32fc68", "price_changes": [{"asset_id": "17118621258018130257689540837975706602158094977984538267313954503349864657420", "price": "0.03", "size": "31.61", "side": "BUY", "hash": "471de86b5f42894bece7b53f0a92784265ac06b3", "best_bid": "0.35", "best_ask": "0.44"}, {"asset_id": "110208037745521376477218629625161726044793864281199315926557875582085019919669", "price": "0.97", "size": "31.61", "side": "SELL", "hash": "93832727e3e4ca6b05e208df53278e25b702149a", "best_bid": "0.56", "best_ask": "0.65"}], "timestamp": "1769384506065", "event_type": "price_change"}}
{"_local_timestamp": "2026-01-25T23:41:46.134298+00:00", "data": {"market": "0xc2db3c0906ac69232c4998f436e34e5df7e64b6dd2d9cb9ddd6305f2aef23c0d", "price_changes": [{"asset_id": "26283804933183319314833342421447518362320608677704153347603079425527445471777", "price": "0.02", "size": "4166.44", "side": "BUY", "hash": "e82a3124b945b02ca0a5a63da5f2f50be64abc4e", "best_bid": "0.57", "best_ask": "0.66"}, {"asset_id": "68765318567686557797285708330422826706843409708557814702138983780254126785177", "price": "0.98", "size": "4166.44", "side": "SELL", "hash": "41c23cd8c9ea39fcb2fee5c271ea6d31b424f1a2", "best_bid": "0.34", "best_ask": "0.43"}], "timestamp": "1769384506066", "event_type": "price_change"}}
{"_local_timestamp": "2026-01-25T23:41:46.510637+00:00", "data": {"market": "0x171b0625db2b7f2ac2848455143776eec779ee85f6359364c1b423b23b32fc68", "price_changes": [{"asset_id": "110208037745521376477218629625161726044793864281199315926557875582085019919669", "price": "0.01", "size": "7184.11", "side": "BUY", "hash": "26b8904340166d558bc1a2d44c246ff700bf641c", "best_bid": "0.56", "best_ask": "0.65"}, {"asset_id": "17118621258018130257689540837975706602158094977984538267313954503349864657420", "price": "0.99", "size": "7184.11", "side": "SELL", "hash": "14f8985b6d2b620ea9e9f6febb1b1296732e18c9", "best_bid": "0.35", "best_ask": "0.44"}], "timestamp": "1769384506443", "event_type": "price_change"}}
{"_local_timestamp": "2026-01-25T23:41:46.511082+00:00", "data": {"market": "0x171b0625db2b7f2ac2848455143776eec779ee85f6359364c1b423b23b32fc68", "price_changes": [{"asset_id": "110208037745521376477218629625161726044793864281199315926557875582085019919669", "price": "0.03", "size": "0", "side": "BUY", "hash": "26b8904340166d558bc1a2d44c246ff700bf641c", "best_bid": "0.56", "best_ask": "0.65"}, {"asset_id": "17118621258018130257689540837975706602158094977984538267313954503349864657420", "price": "0.97", "size": "0", "side": "SELL", "hash": "14f8985b6d2b620ea9e9f6febb1b1296732e18c9", "best_bid": "0.35", "best_ask": "0.44"}], "timestamp": "1769384506443", "event_type": "price_change"}}
{"_local_timestamp": "2026-01-25T23:41:47.271164+00:00", "data": {"market": "0x171b0625db2b7f2ac2848455143776eec779ee85f6359364c1b423b23b32fc68", "price_changes": [{"asset_id": "110208037745521376477218629625161726044793864281199315926557875582085019919669", "price": "0.02", "size": "4166.48", "side": "BUY", "hash": "2803d0dc4cb3a006b179fd5ef911672d5c35c8d2", "best_bid": "0.56", "best_ask": "0.65"}, {"asset_id": "17118621258018130257689540837975706602158094977984538267313954503349864657420", "price": "0.98", "size": "4166.48", "side": "SELL", "hash": "d23a766483328e47e0893b98f41a9cc154cb6b52", "best_bid": "0.35", "best_ask": "0.44"}], "timestamp": "1769384507202", "event_type": "price_change"}}
{"_local_timestamp": "2026-01-25T23:41:47.271614+00:00", "data": {"market": "0x171b0625db2b7f2ac2848455143776eec779ee85f6359364c1b423b23b32fc68", "price_changes": [{"asset_id": "110208037745521376477218629625161726044793864281199315926557875582085019919669", "price": "0.06", "size": "12.77", "side": "BUY", "hash": "713d9b325081db7f50c1a42f5267b3f335ba2e57", "best_bid": "0.56", "best_ask": "0.65"}, {"asset_id": "17118621258018130257689540837975706602158094977984538267313954503349864657420", "price": "0.94", "size": "12.77", "side": "SELL", "hash": "6a0d21f142ce2e9d99a1e16b6ddc7d9b25e5dba1", "best_bid": "0.35", "best_ask": "0.44"}], "timestamp": "1769384507203", "event_type": "price_change"}}
{"_local_timestamp": "2026-01-25T23:41:59.956483+00:00", "data": {"market": "0xecbb7178261e45c45a2d40f3ba28f7b90da88f208a43e3c8f0bd9f7d69900ddc", "price_changes": [{"asset_id": "75087175062739028357071911202249876424512123621414420427750062298373802728902", "price": "0.08", "size": "4357.32", "side": "BUY", "hash": "f5f602774cdabfb5e695d634cb31ee1837bd3dbd", "best_bid": "0.64", "best_ask": "0.69"}, {"asset_id": "51057777902653789433362935484116310785534127104787453577540080102342088856991", "price": "0.92", "size": "4357.32", "side": "SELL", "hash": "db7f29c7462dea5b79c922f94807757992af42d0", "best_bid": "0.31", "best_ask": "0.36"}], "timestamp": "1769384519879", "event_type": "price_change"}}
{"_local_timestamp": "2026-01-25T23:42:00.135438+00:00", "data": {"market": "0xecbb7178261e45c45a2d40f3ba28f7b90da88f208a43e3c8f0bd9f7d69900ddc", "price_changes": [{"asset_id": "75087175062739028357071911202249876424512123621414420427750062298373802728902", "price": "0.09", "size": "400", "side": "BUY", "hash": "04e1fca3b2dc6f49f6fab2af8a0e429be508fb7f", "best_bid": "0.64", "best_ask": "0.69"}, {"asset_id": "51057777902653789433362935484116310785534127104787453577540080102342088856991", "price": "0.91", "size": "400", "side": "SELL", "hash": "1d64af126f935db8ec9491db5073ac3a59043074", "best_bid": "0.31", "best_ask": "0.36"}], "timestamp": "1769384520020", "event_type": "price_change"}}
{"_local_timestamp": "2026-01-25T23:42:00.228440+00:00", "data": {"market": "0xecbb7178261e45c45a2d40f3ba28f7b90da88f208a43e3c8f0bd9f7d69900ddc", "price_changes": [{"asset_id": "75087175062739028357071911202249876424512123621414420427750062298373802728902", "price": "0.09", "size": "500", "side": "BUY", "hash": "72f1eca9114894697ea38666b85e79d3d3ad6530", "best_bid": "0.64", "best_ask": "0.69"}, {"asset_id": "51057777902653789433362935484116310785534127104787453577540080102342088856991", "price": "0.91", "size": "500", "side": "SELL", "hash": "f48b85752635dacc46e20ceb44bb2b8ae05a0463", "best_bid": "0.31", "best_ask": "0.36"}], "timestamp": "1769384520156", "event_type": "price_change"}}
{"_local_timestamp": "2026-01-25T23:42:10.137977+00:00", "data": {"market": "0xecbb7178261e45c45a2d40f3ba28f7b90da88f208a43e3c8f0bd9f7d69900ddc", "price_changes": [{"asset_id": "75087175062739028357071911202249876424512123621414420427750062298373802728902", "price": "0.08", "size": "4257.32", "side": "BUY", "hash": "1d5fd77d943261ed1623fb0c23c1363174f35ee4", "best_bid": "0.64", "best_ask": "0.69"}, {"asset_id": "51057777902653789433362935484116310785534127104787453577540080102342088856991", "price": "0.92", "size": "4257.32", "side": "SELL", "hash": "5ca5856e1ec809631d0bd476886e0371dc0a50d0", "best_bid": "0.31", "best_ask": "0.36"}], "timestamp": "1769384530031", "event_type": "price_change"}}
{"_local_timestamp": "2026-01-25T23:42:10.408411+00:00", "data": {"market": "0xecbb7178261e45c45a2d40f3ba28f7b90da88f208a43e3c8f0bd9f7d69900ddc", "price_changes": [{"asset_id": "75087175062739028357071911202249876424512123621414420427750062298373802728902", "price": "0.09", "size": "600", "side": "BUY", "hash": "c1105f1ef25e1b13791b2a9df4760fbe2f55e081", "best_bid": "0.64", "best_ask": "0.69"}, {"asset_id": "51057777902653789433362935484116310785534127104787453577540080102342088856991", "price": "0.91", "size": "600", "side": "SELL", "hash": "0c76cbb296cf6c0f84ed02cd6616565e67bfe033", "best_bid": "0.31", "best_ask": "0.36"}], "timestamp": "1769384530334", "event_type": "price_change"}}
{"_local_timestamp": "2026-01-25T23:42:10.483841+00:00", "data": {"market": "0xecbb7178261e45c45a2d40f3ba28f7b90da88f208a43e3c8f0bd9f7d69900ddc", "price_changes": [{"asset_id": "75087175062739028357071911202249876424512123621414420427750062298373802728902", "price": "0.1", "size": "896.68", "side": "BUY", "hash": "69a4048e42b829f792a38c2e856027caa39cc3ca", "best_bid": "0.64", "best_ask": "0.69"}, {"asset_id": "51057777902653789433362935484116310785534127104787453577540080102342088856991", "price": "0.9", "size": "896.68", "side": "SELL", "hash": "df948f134738b0a7280a4e61068f7203ab79d73a", "best_bid": "0.31", "best_ask": "0.36"}], "timestamp": "1769384530416", "event_type": "price_change"}}
{"_local_timestamp": "2026-01-25T23:42:10.486328+00:00", "data": {"market": "0xecbb7178261e45c45a2d40f3ba28f7b90da88f208a43e3c8f0bd9f7d69900ddc", "price_changes": [{"asset_id": "75087175062739028357071911202249876424512123621414420427750062298373802728902", "price": "0.1", "size": "2893.79", "side": "BUY", "hash": "0bc8e67ce9f4fd78359a00a6d4b5887ab6c8f82a", "best_bid": "0.64", "best_ask": "0.69"}, {"asset_id": "51057777902653789433362935484116310785534127104787453577540080102342088856991", "price": "0.9", "size": "2893.79", "side": "SELL", "hash": "249a61016e7576f0e9c56ba22e43ed71394102af", "best_bid": "0.31", "best_ask": "0.36"}], "timestamp": "1769384530417", "event_type": "price_change"}}
{"_local_timestamp": "2026-01-25T23:42:10.653097+00:00", "data": {"market": "0xecbb7178261e45c45a2d40f3ba28f7b90da88f208a43e3c8f0bd9f7d69900ddc", "price_changes": [{"asset_id": "75087175062739028357071911202249876424512123621414420427750062298373802728902", "price": "0.1", "size": "4163.89", "side": "BUY", "hash": "c790a0ff255ca2903bd92e0f2600c13d5eb48d19", "best_bid": "0.64", "best_ask": "0.69"}, {"asset_id": "51057777902653789433362935484116310785534127104787453577540080102342088856991", "price": "0.9", "size": "4163.89", "side": "SELL", "hash": "7644a04e207466ce332466ad38d5a18d1f88252b", "best_bid": "0.31", "best_ask": "0.36"}], "timestamp": "1769384530576", "event_type": "price_change"}}
{"_local_timestamp": "2026-01-25T23:42:13.586989+00:00", "data": {"market": "0xecbb7178261e45c45a2d40f3ba28f7b90da88f208a43e3c8f0bd9f7d69900ddc", "price_changes": [{"asset_id": "75087175062739028357071911202249876424512123621414420427750062298373802728902", "price": "0.08", "size": "4157.32", "side": "BUY", "hash": "fa7252ece9a7f2529fc00b351623e404db854695", "best_bid": "0.64", "best_ask": "0.69"}, {"asset_id": "51057777902653789433362935484116310785534127104787453577540080102342088856991", "price": "0.92", "size": "4157.32", "side": "SELL", "hash": "281f39f85360cb693f456b2aa972512459b9e62c", "best_bid": "0.31", "best_ask": "0.36"}], "timestamp": "1769384533511", "event_type": "price_change"}}
{"_local_timestamp": "2026-01-25T23:42:13.644536+00:00", "data": {"market": "0xecbb7178261e45c45a2d40f3ba28f7b90da88f208a43e3c8f0bd9f7d69900ddc", "price_changes": [{"asset_id": "75087175062739028357071911202249876424512123621414420427750062298373802728902", "price": "0.08", "size": "0", "side": "BUY", "hash": "c35ed6e90ca1d867311ee360e3213b9908c46137", "best_bid": "0.64", "best_ask": "0.69"}, {"asset_id": "51057777902653789433362935484116310785534127104787453577540080102342088856991", "price": "0.92", "size": "0", "side": "SELL", "hash": "ecb77c5b513bee61e57540676c6dd9907d2a704a", "best_bid": "0.31", "best_ask": "0.36"}], "timestamp": "1769384533574", "event_type": "price_change"}}
{"_local_timestamp": "2026-01-25T23:42:13.856937+00:00", "data": {"market": "0xecbb7178261e45c45a2d40f3ba28f7b90da88f208a43e3c8f0bd9f7d69900ddc", "price_changes": [{"asset_id": "75087175062739028357071911202249876424512123621414420427750062298373802728902", "price": "0.09", "size": "700", "side": "BUY", "hash": "1d6ba3dc96018877b7f8831177c0186e183971eb", "best_bid": "0.64", "best_ask": "0.69"}, {"asset_id": "51057777902653789433362935484116310785534127104787453577540080102342088856991", "price": "0.91", "size": "700", "side": "SELL", "hash": "ca719f5eea2b36e4d180d476ff3a31ce72af2654", "best_bid": "0.31", "best_ask": "0.36"}], "timestamp": "1769384533788", "event_type": "price_change"}}
{"_local_timestamp": "2026-01-25T23:42:23.908367+00:00", "data": {"market": "0xecbb7178261e45c45a2d40f3ba28f7b90da88f208a43e3c8f0bd9f7d69900ddc", "price_changes": [{"asset_id": "75087175062739028357071911202249876424512123621414420427750062298373802728902", "price": "0.09", "size": "600", "side": "BUY", "hash": "69c767784d864f2a6490973080fbfda9a96c6b4e", "best_bid": "0.64", "best_ask": "0.69"}, {"asset_id": "51057777902653789433362935484116310785534127104787453577540080102342088856991", "price": "0.91", "size": "600", "side": "SELL", "hash": "57788ddd2269067e2a1f83b0f3f4248fc0a4867d", "best_bid": "0.31", "best_ask": "0.36"}], "timestamp": "1769384543840", "event_type": "price_change"}}
{"_local_timestamp": "2026-01-25T23:42:24.170628+00:00", "data": {"market": "0xecbb7178261e45c45a2d40f3ba28f7b90da88f208a43e3c8f0bd9f7d69900ddc", "price_changes": [{"asset_id": "75087175062739028357071911202249876424512123621414420427750062298373802728902", "price": "0.08", "size": "100", "side": "BUY", "hash": "2f4ab69c3a20cd6fdac433287efa676c19e2d2e0", "best_bid": "0.64", "best_ask": "0.69"}, {"asset_id": "51057777902653789433362935484116310785534127104787453577540080102342088856991", "price": "0.92", "size": "100", "side": "SELL", "hash": "f359fbdd5c96bf7543bf7cd71ef44d13198a5eb4", "best_bid": "0.31", "best_ask": "0.36"}], "timestamp": "1769384544105", "event_type": "price_change"}}
{"_local_timestamp": "2026-01-25T23:42:26.142513+00:00", "data": {"market": "0xecbb7178261e45c45a2d40f3ba28f7b90da88f208a43e3c8f0bd9f7d69900ddc", "price_changes": [{"asset_id": "51057777902653789433362935484116310785534127104787453577540080102342088856991", "price": "0.28", "size": "0", "side": "BUY", "hash": "ac518d245265650293b9a9d626bc2221a21aca6d", "best_bid": "0.31", "best_ask": "0.36"}, {"asset_id": "75087175062739028357071911202249876424512123621414420427750062298373802728902", "price": "0.72", "size": "0", "side": "SELL", "hash": "982b27cd71471d636796df692d269aeec4b45e6e", "best_bid": "0.64", "best_ask": "0.69"}], "timestamp": "1769384546031", "event_type": "price_change"}}
{"_local_timestamp": "2026-01-25T23:42:26.161766+00:00", "data": {"market": "0xc2db3c0906ac69232c4998f436e34e5df7e64b6dd2d9cb9ddd6305f2aef23c0d", "price_changes": [{"asset_id": "26283804933183319314833342421447518362320608677704153347603079425527445471777", "price": "0.56", "size": "890.11", "side": "BUY", "hash": "ce69d3a562d162549b88d531ace18dddea593ed4", "best_bid": "0.57", "best_ask": "0.66"}, {"asset_id": "68765318567686557797285708330422826706843409708557814702138983780254126785177", "price": "0.44", "size": "890.11", "side": "SELL", "hash": "65a34d40dcc80d55bf5172bda9d724eaf6e2cf5b", "best_bid": "0.34", "best_ask": "0.43"}], "timestamp": "1769384546038", "event_type": "price_change"}}
{"_local_timestamp": "2026-01-25T23:42:26.176618+00:00", "data": {"market": "0xecbb7178261e45c45a2d40f3ba28f7b90da88f208a43e3c8f0bd9f7d69900ddc", "price_changes": [{"asset_id": "75087175062739028357071911202249876424512123621414420427750062298373802728902", "price": "0.6", "size": "890.11", "side": "BUY", "hash": "7a81bafdc8ba75ed1d53d90a041686e67be9d2ed", "best_bid": "0.64", "best_ask": "0.69"}, {"asset_id": "51057777902653789433362935484116310785534127104787453577540080102342088856991", "price": "0.4", "size": "890.11", "side": "SELL", "hash": "c2f59a91b99ad2c12de32df046266f7ec8c868ef", "best_bid": "0.31", "best_ask": "0.36"}], "timestamp": "1769384546037", "event_type": "price_change"}}
{"_local_timestamp": "2026-01-25T23:42:26.185386+00:00", "data": {"market": "0x171b0625db2b7f2ac2848455143776eec779ee85f6359364c1b423b23b32fc68", "price_changes": [{"asset_id": "110208037745521376477218629625161726044793864281199315926557875582085019919669", "price": "0.55", "size": "890.11", "side": "BUY", "hash": "673ce1cbead9877d530a975820784eb25bc9d1f3", "best_bid": "0.56", "best_ask": "0.65"}, {"asset_id": "17118621258018130257689540837975706602158094977984538267313954503349864657420", "price": "0.45", "size": "890.11", "side": "SELL", "hash": "0dd45f3916465b2b67f5a0309bad8c8288378d07", "best_bid": "0.35", "best_ask": "0.44"}], "timestamp": "1769384546044", "event_type": "price_change"}}
{"_local_timestamp": "2026-01-25T23:42:26.192715+00:00", "data": {"market": "0x15beb6ee455f9837b69cd7dcd110770b2f489d88651e4ffb21cd54f617a23e04", "price_changes": [{"asset_id": "14205737424716982918858761268248742215558565679165887656230879609115111732505", "price": "0.42", "size": "0", "side": "BUY", "hash": "13bf94d20a490fe91def6fb7805579ff922cc512", "best_bid": "0.02", "best_ask": "0.52"}, {"asset_id": "44868850067599122384522819337153865676781090849621105309651139851616912647528", "price": "0.58", "size": "0", "side": "SELL", "hash": "fd321ecf7b990b424f20648addd1efde77960998", "best_bid": "0.48", "best_ask": "0.98"}], "timestamp": "1769384546041", "event_type": "price_change"}}
{"_local_timestamp": "2026-01-25T23:42:26.193143+00:00", "data": {"market": "0x171b0625db2b7f2ac2848455143776eec779ee85f6359364c1b423b23b32fc68", "price_changes": [{"asset_id": "17118621258018130257689540837975706602158094977984538267313954503349864657420", "price": "0.34", "size": "890.11", "side": "BUY", "hash": "2dd6d7f8697f28db969ccb938cbc5674ff066ab7", "best_bid": "0.35", "best_ask": "0.44"}, {"asset_id": "110208037745521376477218629625161726044793864281199315926557875582085019919669", "price": "0.66", "size": "890.11", "side": "SELL", "hash": "2f191f2048dc6b9b0cd16ffa4bac089bc9ab17c5", "best_bid": "0.56", "best_ask": "0.65"}], "timestamp": "1769384546045", "event_type": "price_change"}}
{"_local_timestamp": "2026-01-25T23:42:26.193509+00:00", "data": {"market": "0x15beb6ee455f9837b69cd7dcd110770b2f489d88651e4ffb21cd54f617a23e04", "price_changes": [{"asset_id": "44868850067599122384522819337153865676781090849621105309651139851616912647528", "price": "0.48", "size": "0", "side": "BUY", "hash": "a7b78612fa61d2cc520c80a1f70a97cb01ffe687", "best_bid": "0.02", "best_ask": "0.98"}, {"asset_id": "14205737424716982918858761268248742215558565679165887656230879609115111732505", "price": "0.52", "size": "0", "side": "SELL", "hash": "79c7a83e4784258ace6ecbfed12cd433e4a78c2c", "best_bid": "0.02", "best_ask": "0.98"}], "timestamp": "1769384546045", "event_type": "price_change"}}
{"_local_timestamp": "2026-01-25T23:42:26.198782+00:00", "data": {"market": "0xc2db3c0906ac69232c4998f436e34e5df7e64b6dd2d9cb9ddd6305f2aef23c0d", "price_changes": [{"asset_id": "68765318567686557797285708330422826706843409708557814702138983780254126785177", "price": "0.33", "size": "890.11", "side": "BUY", "hash": "142b02f7d59c8c5d34c8cd75df46fd0a97da24a5", "best_bid": "0.34", "best_ask": "0.43"}, {"asset_id": "26283804933183319314833342421447518362320608677704153347603079425527445471777", "price": "0.67", "size": "890.11", "side": "SELL", "hash": "e6500f03c0ba63ed38bd582b505d992612de229b", "best_bid": "0.57", "best_ask": "0.66"}], "timestamp": "1769384546050", "event_type": "price_change"}}
{"_local_timestamp": "2026-01-25T23:42:26.278189+00:00", "data": {"market": "0xc2db3c0906ac69232c4998f436e34e5df7e64b6dd2d9cb9ddd6305f2aef23c0d", "price_changes": [{"asset_id": "26283804933183319314833342421447518362320608677704153347603079425527445471777", "price": "0.01", "size": "8074.32", "side": "BUY", "hash": "bb86531ca47e2d707e6de46ea7640fe83c4031f5", "best_bid": "0.57", "best_ask": "0.66"}, {"asset_id": "68765318567686557797285708330422826706843409708557814702138983780254126785177", "price": "0.99", "size": "8074.32", "side": "SELL", "hash": "1177af482a466a1bfda14fe4010a77525f84600a", "best_bid": "0.34", "best_ask": "0.43"}], "timestamp": "1769384546203", "event_type": "price_change"}}
{"_local_timestamp": "2026-01-25T23:42:26.315323+00:00", "data": {"market": "0xc2db3c0906ac69232c4998f436e34e5df7e64b6dd2d9cb9ddd6305f2aef23c0d", "price_changes": [{"asset_id": "26283804933183319314833342421447518362320608677704153347603079425527445471777", "price": "0.05", "size": "0", "side": "BUY", "hash": "677d7cc9cf93a0f672d8867a8a59581c5c934cc2", "best_bid": "0.57", "best_ask": "0.66"}, {"asset_id": "68765318567686557797285708330422826706843409708557814702138983780254126785177", "price": "0.95", "size": "0", "side": "SELL", "hash": "bdb287857224cf26754cf86520259f063f7dc1c6", "best_bid": "0.34", "best_ask": "0.43"}], "timestamp": "1769384546246", "event_type": "price_change"}}
{"_local_timestamp": "2026-01-25T23:42:26.316341+00:00", "data": {"market": "0xc2db3c0906ac69232c4998f436e34e5df7e64b6dd2d9cb9ddd6305f2aef23c0d", "price_changes": [{"asset_id": "26283804933183319314833342421447518362320608677704153347603079425527445471777", "price": "0.04", "size": "0", "side": "BUY", "hash": "677d7cc9cf93a0f672d8867a8a59581c5c934cc2", "best_bid": "0.57", "best_ask": "0.66"}, {"asset_id": "68765318567686557797285708330422826706843409708557814702138983780254126785177", "price": "0.96", "size": "0", "side": "SELL", "hash": "bdb287857224cf26754cf86520259f063f7dc1c6", "best_bid": "0.34", "best_ask": "0.43"}], "timestamp": "1769384546246", "event_type": "price_change"}}
{"_local_timestamp": "2026-01-25T23:42:26.316766+00:00", "data": {"market": "0x171b0625db2b7f2ac2848455143776eec779ee85f6359364c1b423b23b32fc68", "price_changes": [{"asset_id": "110208037745521376477218629625161726044793864281199315926557875582085019919669", "price": "0.05", "size": "0", "side": "BUY", "hash": "db6ea15294acf8c36914edf23b393125f193cb41", "best_bid": "0.56", "best_ask": "0.65"}, {"asset_id": "17118621258018130257689540837975706602158094977984538267313954503349864657420", "price": "0.95", "size": "0", "side": "SELL", "hash": "d500642cc61277fb4e3925c09eeed2048a386659", "best_bid": "0.35", "best_ask": "0.44"}], "timestamp": "1769384546246", "event_type": "price_change"}}
{"_local_timestamp": "2026-01-25T23:42:26.375021+00:00", "data": {"market": "0xc2db3c0906ac69232c4998f436e34e5df7e64b6dd2d9cb9ddd6305f2aef23c0d", "price_changes": [{"asset_id": "26283804933183319314833342421447518362320608677704153347603079425527445471777", "price": "0.02", "size": "5056.55", "side": "BUY", "hash": "8afd1ff12e0a0f45c6ead195e73d7df18f4b86f4", "best_bid": "0.57", "best_ask": "0.66"}, {"asset_id": "68765318567686557797285708330422826706843409708557814702138983780254126785177", "price": "0.98", "size": "5056.55", "side": "SELL", "hash": "2bf748eff20fea0d20d7686eb955c58fd24268b7", "best_bid": "0.34", "best_ask": "0.43"}], "timestamp": "1769384546268", "event_type": "price_change"}}
{"_local_timestamp": "2026-01-25T23:42:26.375589+00:00", "data": {"market": "0xecbb7178261e45c45a2d40f3ba28f7b90da88f208a43e3c8f0bd9f7d69900ddc", "price_changes": [{"asset_id": "75087175062739028357071911202249876424512123621414420427750062298373802728902", "price": "0.14", "size": "1190.11", "side": "BUY", "hash": "45cbc07acc1754f79f4017e1628604ab1065b7cf", "best_bid": "0.64", "best_ask": "0.69"}, {"asset_id": "51057777902653789433362935484116310785534127104787453577540080102342088856991", "price": "0.86", "size": "1190.11", "side": "SELL", "hash": "f6f2b214eb5cbc8b73b1284d5e945fad65c47b23", "best_bid": "0.31", "best_ask": "0.36"}], "timestamp": "1769384546268", "event_type": "price_change"}}
{"_local_timestamp": "2026-01-25T23:42:26.376043+00:00", "data": {"market": "0xecbb7178261e45c45a2d40f3ba28f7b90da88f208a43e3c8f0bd9f7d69900ddc", "price_changes": [{"asset_id": "75087175062739028357071911202249876424512123621414420427750062298373802728902", "price": "0.15", "size": "890.11", "side": "BUY", "hash": "644a9614a0e08a1ba4f8777e8abd1f48928e4b34", "best_bid": "0.64", "best_ask": "0.69"}, {"asset_id": "51057777902653789433362935484116310785534127104787453577540080102342088856991", "price": "0.85", "size": "890.11", "side": "SELL", "hash": "69e505ae9d550ceee02bd8879331702099e0a485", "best_bid": "0.31", "best_ask": "0.36"}], "timestamp": "1769384546272", "event_type": "price_change"}}
{"_local_timestamp": "2026-01-25T23:42:26.443326+00:00", "data": {"market": "0x171b0625db2b7f2ac2848455143776eec779ee85f6359364c1b423b23b32fc68", "price_changes": [{"asset_id": "17118621258018130257689540837975706602158094977984538267313954503349864657420", "price": "0.02", "size": "5047.43", "side": "BUY", "hash": "c9269610be1d6a470ede2797c8ca18334c3857a2", "best_bid": "0.35", "best_ask": "0.44"}, {"asset_id": "110208037745521376477218629625161726044793864281199315926557875582085019919669", "price": "0.98", "size": "5047.43", "side": "SELL", "hash": "7d54bbd9cf935029594dc788b88753a01d6ab049", "best_bid": "0.56", "best_ask": "0.65"}], "timestamp": "1769384546377", "event_type": "price_change"}}
{"_local_timestamp": "2026-01-25T23:42:26.504809+00:00", "data": {"market": "0xecbb7178261e45c45a2d40f3ba28f7b90da88f208a43e3c8f0bd9f7d69900ddc", "price_changes": [{"asset_id": "51057777902653789433362935484116310785534127104787453577540080102342088856991", "price": "0.28", "size": "1000", "side": "BUY", "hash": "4948f4c8d327b9e1173408e687642d2bd04e4d6d", "best_bid": "0.31", "best_ask": "0.36"}, {"asset_id": "75087175062739028357071911202249876424512123621414420427750062298373802728902", "price": "0.72", "size": "1000", "side": "SELL", "hash": "9eec5953303a797cc75db562c02973523471079b", "best_bid": "0.64", "best_ask": "0.69"}], "timestamp": "1769384546422", "event_type": "price_change"}}
{"_local_timestamp": "2026-01-25T23:42:26.505259+00:00", "data": {"market": "0xecbb7178261e45c45a2d40f3ba28f7b90da88f208a43e3c8f0bd9f7d69900ddc", "price_changes": [{"asset_id": "75087175062739028357071911202249876424512123621414420427750062298373802728902", "price": "0.6", "size": "1890.11", "side": "BUY", "hash": "4df76fee49752735c90cf99d04c6e61d2a32847d", "best_bid": "0.64", "best_ask": "0.69"}, {"asset_id": "51057777902653789433362935484116310785534127104787453577540080102342088856991", "price": "0.4", "size": "1890.11", "side": "SELL", "hash": "c66bd96aa3754790211cbf68ff6b7680129dae83", "best_bid": "0.31", "best_ask": "0.36"}], "timestamp": "1769384546422", "event_type": "price_change"}}
{"_local_timestamp": "2026-01-25T23:42:26.505659+00:00", "data": {"market": "0xc2db3c0906ac69232c4998f436e34e5df7e64b6dd2d9cb9ddd6305f2aef23c0d", "price_changes": [{"asset_id": "68765318567686557797285708330422826706843409708557814702138983780254126785177", "price": "0.33", "size": "1390.11", "side": "BUY", "hash": "6a18a0e138144b829c93e45cc37dbb65e884dab0", "best_bid": "0.34", "best_ask": "0.43"}, {"asset_id": "26283804933183319314833342421447518362320608677704153347603079425527445471777", "price": "0.67", "size": "1390.11", "side": "SELL", "hash": "96015641714b647a7ff69cd59b1940c9b62a3e7f", "best_bid": "0.57", "best_ask": "0.66"}], "timestamp": "1769384546423", "event_type": "price_change"}}
{"_local_timestamp": "2026-01-25T23:42:26.506088+00:00", "data": {"market": "0x15beb6ee455f9837b69cd7dcd110770b2f489d88651e4ffb21cd54f617a23e04", "price_changes": [{"asset_id": "14205737424716982918858761268248742215558565679165887656230879609115111732505", "price": "0.42", "size": "500", "side": "BUY", "hash": "c2f049b3fb0b9998dde4399cf31543ccdb5c74d2", "best_bid": "0.42", "best_ask": "0.98"}, {"asset_id": "44868850067599122384522819337153865676781090849621105309651139851616912647528", "price": "0.58", "size": "500", "side": "SELL", "hash": "12007a0f28008f908221afcd65e50d2c6965a8dd", "best_bid": "0.02", "best_ask": "0.58"}], "timestamp": "1769384546424", "event_type": "price_change"}}
{"_local_timestamp": "2026-01-25T23:42:26.506470+00:00", "data": {"market": "0xc2db3c0906ac69232c4998f436e34e5df7e64b6dd2d9cb9ddd6305f2aef23c0d", "price_changes": [{"asset_id": "26283804933183319314833342421447518362320608677704153347603079425527445471777", "price": "0.56", "size": "1390.11", "side": "BUY", "hash": "5f5b4b4fa340342acea4d4fad72cde3e6de35c52", "best_bid": "0.57", "best_ask": "0.66"}, {"asset_id": "68765318567686557797285708330422826706843409708557814702138983780254126785177", "price": "0.44", "size": "1390.11", "side": "SELL", "hash": "0ae0b5fa03a6d57de01528335234e4027371451e", "best_bid": "0.34", "best_ask": "0.43"}], "timestamp": "1769384546424", "event_type": "price_change"}}
{"_local_timestamp": "2026-01-25T23:42:26.506887+00:00", "data": {"market": "0x171b0625db2b7f2ac2848455143776eec779ee85f6359364c1b423b23b32fc68", "price_changes": [{"asset_id": "110208037745521376477218629625161726044793864281199315926557875582085019919669", "price": "0.55", "size": "1390.11", "side": "BUY", "hash": "7eeaae3ac21c0072cf5def34ad70c2a0aba4ede5", "best_bid": "0.56", "best_ask": "0.65"}, {"asset_id": "17118621258018130257689540837975706602158094977984538267313954503349864657420", "price": "0.45", "size": "1390.11", "side": "SELL", "hash": "13729e00dd4c5211c71d27f88e55358eec07dc44", "best_bid": "0.35", "best_ask": "0.44"}], "timestamp": "1769384546425", "event_type": "price_change"}}
{"_local_timestamp": "2026-01-25T23:42:26.512876+00:00", "data": {"market": "0x171b0625db2b7f2ac2848455143776eec779ee85f6359364c1b423b23b32fc68", "price_changes": [{"asset_id": "17118621258018130257689540837975706602158094977984538267313954503349864657420", "price": "0.34", "size": "1390.11", "side": "BUY", "hash": "f64ca524ca7e83f3d6ef0115bd501d49372a9509", "best_bid": "0.35", "best_ask": "0.44"}, {"asset_id": "110208037745521376477218629625161726044793864281199315926557875582085019919669", "price": "0.66", "size": "1390.11", "side": "SELL", "hash": "47ca1e29bcaecc74832c461e63741dd7299f33b9", "best_bid": "0.56", "best_ask": "0.65"}], "timestamp": "1769384546427", "event_type": "price_change"}}
{"_local_timestamp": "2026-01-25T23:42:26.513435+00:00", "data": {"market": "0x15beb6ee455f9837b69cd7dcd110770b2f489d88651e4ffb21cd54f617a23e04", "price_changes": [{"asset_id": "44868850067599122384522819337153865676781090849621105309651139851616912647528", "price": "0.48", "size": "500", "side": "BUY", "hash": "2649cd36a7aec43bf24d9f342848872f6a1921c5", "best_bid": "0.48", "best_ask": "0.58"}, {"asset_id": "14205737424716982918858761268248742215558565679165887656230879609115111732505", "price": "0.52", "size": "500", "side": "SELL", "hash": "6f1788d18c1542c6cf4d39d3b44df1f116a44a32", "best_bid": "0.42", "best_ask": "0.52"}], "timestamp": "1769384546430", "event_type": "price_change"}}
{"_local_timestamp": "2026-01-25T23:42:26.684127+00:00", "data": {"market": "0x171b0625db2b7f2ac2848455143776eec779ee85f6359364c1b423b23b32fc68", "price_changes": [{"asset_id": "110208037745521376477218629625161726044793864281199315926557875582085019919669", "price": "0.02", "size": "5056.59", "side": "BUY", "hash": "d573a68dac2af6e1877ba2eddba07fb9a849cce8", "best_bid": "0.56", "best_ask": "0.65"}, {"asset_id": "17118621258018130257689540837975706602158094977984538267313954503349864657420", "price": "0.98", "size": "5056.59", "side": "SELL", "hash": "a3c8c8f931e3a17468bc96cec767171d39043d90", "best_bid": "0.35", "best_ask": "0.44"}], "timestamp": "1769384546613", "event_type": "price_change"}}
{"_local_timestamp": "2026-01-25T23:42:26.684631+00:00", "data": {"market": "0x171b0625db2b7f2ac2848455143776eec779ee85f6359364c1b423b23b32fc68", "price_changes": [{"asset_id": "110208037745521376477218629625161726044793864281199315926557875582085019919669", "price": "0.01", "size": "8074.22", "side": "BUY", "hash": "a40a3c0ac595ba504962392488c393147d9a5363", "best_bid": "0.56", "best_ask": "0.65"}, {"asset_id": "17118621258018130257689540837975706602158094977984538267313954503349864657420", "price": "0.99", "size": "8074.22", "side": "SELL", "hash": "4e3343f22728ff3624750eb613ca4a6d1135a58a", "best_bid": "0.35", "best_ask": "0.44"}], "timestamp": "1769384546615", "event_type": "price_change"}}
{"_local_timestamp": "2026-01-25T23:42:26.685078+00:00", "data": {"market": "0x171b0625db2b7f2ac2848455143776eec779ee85f6359364c1b423b23b32fc68", "price_changes": [{"asset_id": "17118621258018130257689540837975706602158094977984538267313954503349864657420", "price": "0.01", "size": "8074.39", "side": "BUY", "hash": "6adeba79a78c812c368a15ba9e60f461e415cdc6", "best_bid": "0.35", "best_ask": "0.44"}, {"asset_id": "110208037745521376477218629625161726044793864281199315926557875582085019919669", "price": "0.99", "size": "8074.39", "side": "SELL", "hash": "3309fa85f1f37b649cf0519f1f75629663ab0524", "best_bid": "0.56", "best_ask": "0.65"}], "timestamp": "1769384546616", "event_type": "price_change"}}
{"_local_timestamp": "2026-01-25T23:42:26.812796+00:00", "data": {"market": "0xc2db3c0906ac69232c4998f436e34e5df7e64b6dd2d9cb9ddd6305f2aef23c0d", "price_changes": [{"asset_id": "26283804933183319314833342421447518362320608677704153347603079425527445471777", "price": "0.06", "size": "902.88", "side": "BUY", "hash": "7a718bfbe7a86b9dda680c60e2bacfdf3012e08c", "best_bid": "0.57", "best_ask": "0.66"}, {"asset_id": "68765318567686557797285708330422826706843409708557814702138983780254126785177", "price": "0.94", "size": "902.88", "side": "SELL", "hash": "d98f90134316797ff2556e0f972392c7b16f4519", "best_bid": "0.34", "best_ask": "0.43"}], "timestamp": "1769384546745", "event_type": "price_change"}}
{"_local_timestamp": "2026-01-25T23:42:26.814827+00:00", "data": {"market": "0xc2db3c0906ac69232c4998f436e34e5df7e64b6dd2d9cb9ddd6305f2aef23c0d", "price_changes": [{"asset_id": "26283804933183319314833342421447518362320608677704153347603079425527445471777", "price": "0.06", "size": "6901.99", "side": "BUY", "hash": "b842dd47c7ea712a08aa65505f000dc5c91bdc34", "best_bid": "0.57", "best_ask": "0.66"}, {"asset_id": "68765318567686557797285708330422826706843409708557814702138983780254126785177", "price": "0.94", "size": "6901.99", "side": "SELL", "hash": "d324ada46df800639dcb1f5624193c0f265be22a", "best_bid": "0.34", "best_ask": "0.43"}], "timestamp": "1769384546748", "event_type": "price_change"}}
{"_local_timestamp": "2026-01-25T23:42:26.815310+00:00", "data": {"market": "0xc2db3c0906ac69232c4998f436e34e5df7e64b6dd2d9cb9ddd6305f2aef23c0d", "price_changes": [{"asset_id": "26283804933183319314833342421447518362320608677704153347603079425527445471777", "price": "0.06", "size": "8899.1", "side": "BUY", "hash": "079ef675d835a9c29df3ca2fc941bef7eaad5248", "best_bid": "0.57", "best_ask": "0.66"}, {"asset_id": "68765318567686557797285708330422826706843409708557814702138983780254126785177", "price": "0.94", "size": "8899.1", "side": "SELL", "hash": "96897ac4a00cd34656cbd21fab35c3a106159637", "best_bid": "0.34", "best_ask": "0.43"}], "timestamp": "1769384546750", "event_type": "price_change"}}
{"_local_timestamp": "2026-01-25T23:42:27.141551+00:00", "data": {"market": "0xc2db3c0906ac69232c4998f436e34e5df7e64b6dd2d9cb9ddd6305f2aef23c0d", "price_changes": [{"asset_id": "26283804933183319314833342421447518362320608677704153347603079425527445471777", "price": "0.06", "size": "10169.2", "side": "BUY", "hash": "479e5b5bd3274716b4c4a7212e0a85d2c6bea522", "best_bid": "0.57", "best_ask": "0.66"}, {"asset_id": "68765318567686557797285708330422826706843409708557814702138983780254126785177", "price": "0.94", "size": "10169.2", "side": "SELL", "hash": "95bb5f66e8db0ccabfee9d057eec5ab35d607ccf", "best_bid": "0.34", "best_ask": "0.43"}], "timestamp": "1769384547026", "event_type": "price_change"}}
{"_local_timestamp": "2026-01-25T23:42:27.166728+00:00", "data": {"market": "0x171b0625db2b7f2ac2848455143776eec779ee85f6359364c1b423b23b32fc68", "price_changes": [{"asset_id": "17118621258018130257689540837975706602158094977984538267313954503349864657420", "price": "0.01", "size": "9344.49", "side": "BUY", "hash": "07e2aaf1788e4f541c18f350697f58b1db8609a0", "best_bid": "0.35", "best_ask": "0.44"}, {"asset_id": "110208037745521376477218629625161726044793864281199315926557875582085019919669", "price": "0.99", "size": "9344.49", "side": "SELL", "hash": "25ac012f0c0e5e57464fd1b8be9a14df3df9ecb9", "best_bid": "0.56", "best_ask": "0.65"}], "timestamp": "1769384547064", "event_type": "price_change"}}
{"_local_timestamp": "2026-01-25T23:42:27.167276+00:00", "data": {"market": "0x171b0625db2b7f2ac2848455143776eec779ee85f6359364c1b423b23b32fc68", "price_changes": [{"asset_id": "110208037745521376477218629625161726044793864281199315926557875582085019919669", "price": "0.01", "size": "10071.33", "side": "BUY", "hash": "a3e4ab52cd2fb3a490dae80c84fe5b5ad9f4900f", "best_bid": "0.56", "best_ask": "0.65"}, {"asset_id": "17118621258018130257689540837975706602158094977984538267313954503349864657420", "price": "0.99", "size": "10071.33", "side": "SELL", "hash": "53b6619d2a121f24ef5ecf1f4feadfeb364d1c62", "best_bid": "0.35", "best_ask": "0.44"}], "timestamp": "1769384547067", "event_type": "price_change"}}
{"_local_timestamp": "2026-01-25T23:42:27.167751+00:00", "data": {"market": "0x171b0625db2b7f2ac2848455143776eec779ee85f6359364c1b423b23b32fc68", "price_changes": [{"asset_id": "17118621258018130257689540837975706602158094977984538267313954503349864657420", "price": "0.01", "size": "11341.6", "side": "BUY", "hash": "7eb75ad044e71f146471f9180038fca05528e6f8", "best_bid": "0.35", "best_ask": "0.44"}, {"asset_id": "110208037745521376477218629625161726044793864281199315926557875582085019919669", "price": "0.99", "size": "11341.6", "side": "SELL", "hash": "5d37a3f944e1606fd7389a140fa703c18b6c9eac", "best_bid": "0.56", "best_ask": "0.65"}], "timestamp": "1769384547070", "event_type": "price_change"}}
{"_local_timestamp": "2026-01-25T23:42:27.168242+00:00", "data": {"market": "0x171b0625db2b7f2ac2848455143776eec779ee85f6359364c1b423b23b32fc68", "price_changes": [{"asset_id": "110208037745521376477218629625161726044793864281199315926557875582085019919669", "price": "0.01", "size": "10961.44", "side": "BUY", "hash": "1dbe3fc8dde3f4ac47a7005e8a9c12232fa2ce65", "best_bid": "0.56", "best_ask": "0.65"}, {"asset_id": "17118621258018130257689540837975706602158094977984538267313954503349864657420", "price": "0.99", "size": "10961.44", "side": "SELL", "hash": "bb7145116176f7c8126b9cb64dc1315ade2e5188", "best_bid": "0.35", "best_ask": "0.44"}], "timestamp": "1769384547072", "event_type": "price_change"}}
{"_local_timestamp": "2026-01-25T23:42:27.174586+00:00", "data": {"market": "0x171b0625db2b7f2ac2848455143776eec779ee85f6359364c1b423b23b32fc68", "price_changes": [{"asset_id": "17118621258018130257689540837975706602158094977984538267313954503349864657420", "price": "0.01", "size": "12231.71", "side": "BUY", "hash": "d78d1ae59db561d49113f12255058a4153f7ec64", "best_bid": "0.35", "best_ask": "0.44"}, {"asset_id": "110208037745521376477218629625161726044793864281199315926557875582085019919669", "price": "0.99", "size": "12231.71", "side": "SELL", "hash": "99b08518b1e9464e7a8e0e15acea332733245e0a", "best_bid": "0.56", "best_ask": "0.65"}], "timestamp": "1769384547074", "event_type": "price_change"}}
{"_local_timestamp": "2026-01-25T23:42:27.175213+00:00", "data": {"market": "0x171b0625db2b7f2ac2848455143776eec779ee85f6359364c1b423b23b32fc68", "price_changes": [{"asset_id": "110208037745521376477218629625161726044793864281199315926557875582085019919669", "price": "0.01", "size": "12231.54", "side": "BUY", "hash": "d4d9a273e400ad4c65b5f46b3c693c63ef62ea3a", "best_bid": "0.56", "best_ask": "0.65"}, {"asset_id": "17118621258018130257689540837975706602158094977984538267313954503349864657420", "price": "0.99", "size": "12231.54", "side": "SELL", "hash": "332d7e3494ff2194c3ce98450fed422cf453ad1a", "best_bid": "0.35", "best_ask": "0.44"}], "timestamp": "1769384547076", "event_type": "price_change"}}
{"_local_timestamp": "2026-01-25T23:42:34.009591+00:00", "data": {"market": "0xecbb7178261e45c45a2d40f3ba28f7b90da88f208a43e3c8f0bd9f7d69900ddc", "price_changes": [{"asset_id": "75087175062739028357071911202249876424512123621414420427750062298373802728902", "price": "0.09", "size": "200", "side": "BUY", "hash": "0e15beb84564fd67e64bd4fc4323a34d050d706d", "best_bid": "0.64", "best_ask": "0.69"}, {"asset_id": "51057777902653789433362935484116310785534127104787453577540080102342088856991", "price": "0.91", "size": "200", "side": "SELL", "hash": "645e5d678e5ee3f7cf5d1c6be1a49e9177e1bc9f", "best_bid": "0.31", "best_ask": "0.36"}], "timestamp": "1769384553933", "event_type": "price_change"}}
{"_local_timestamp": "2026-01-25T23:42:34.190641+00:00", "data": {"market": "0xecbb7178261e45c45a2d40f3ba28f7b90da88f208a43e3c8f0bd9f7d69900ddc", "price_changes": [{"asset_id": "75087175062739028357071911202249876424512123621414420427750062298373802728902", "price": "0.08", "size": "990.11", "side": "BUY", "hash": "ffeea7feb084edf30c7ed81d957569213038ed8f", "best_bid": "0.64", "best_ask": "0.69"}, {"asset_id": "51057777902653789433362935484116310785534127104787453577540080102342088856991", "price": "0.92", "size": "990.11", "side": "SELL", "hash": "705ae9233b4c369cff77f6d896c372c3dde1de2c", "best_bid": "0.31", "best_ask": "0.36"}], "timestamp": "1769384554125", "event_type": "price_change"}}
{"_local_timestamp": "2026-01-25T23:42:34.198509+00:00", "data": {"market": "0xecbb7178261e45c45a2d40f3ba28f7b90da88f208a43e3c8f0bd9f7d69900ddc", "price_changes": [{"asset_id": "75087175062739028357071911202249876424512123621414420427750062298373802728902", "price": "0.15", "size": "0", "side": "BUY", "hash": "b62926d50fe8fcc9eec7b6b8035d4efb6ad18314", "best_bid": "0.64", "best_ask": "0.69"}, {"asset_id": "51057777902653789433362935484116310785534127104787453577540080102342088856991", "price": "0.85", "size": "0", "side": "SELL", "hash": "aed529f5f0c42d24350e13c6ab65e1c5cf356ff4", "best_bid": "0.31", "best_ask": "0.36"}], "timestamp": "1769384554127", "event_type": "price_change"}}
{"_local_timestamp": "2026-01-25T23:42:34.199234+00:00", "data": {"market": "0xecbb7178261e45c45a2d40f3ba28f7b90da88f208a43e3c8f0bd9f7d69900ddc", "price_changes": [{"asset_id": "75087175062739028357071911202249876424512123621414420427750062298373802728902", "price": "0.14", "size": "300", "side": "BUY", "hash": "b62926d50fe8fcc9eec7b6b8035d4efb6ad18314", "best_bid": "0.64", "best_ask": "0.69"}, {"asset_id": "51057777902653789433362935484116310785534127104787453577540080102342088856991", "price": "0.86", "size": "300", "side": "SELL", "hash": "aed529f5f0c42d24350e13c6ab65e1c5cf356ff4", "best_bid": "0.31", "best_ask": "0.36"}], "timestamp": "1769384554127", "event_type": "price_change"}}
{"_local_timestamp": "2026-01-25T23:42:34.221480+00:00", "data": {"market": "0xecbb7178261e45c45a2d40f3ba28f7b90da88f208a43e3c8f0bd9f7d69900ddc", "price_changes": [{"asset_id": "75087175062739028357071911202249876424512123621414420427750062298373802728902", "price": "0.08", "size": "2260.21", "side": "BUY", "hash": "abf7453f86c2736e0809652195ccda345773b6a1", "best_bid": "0.64", "best_ask": "0.69"}, {"asset_id": "51057777902653789433362935484116310785534127104787453577540080102342088856991", "price": "0.92", "size": "2260.21", "side": "SELL", "hash": "f4b320d74d2591043ceb536f344cf638c39f796c", "best_bid": "0.31", "best_ask": "0.36"}], "timestamp": "1769384554154", "event_type": "price_change"}}
{"_local_timestamp": "2026-01-25T23:42:34.222168+00:00", "data": {"market": "0xecbb7178261e45c45a2d40f3ba28f7b90da88f208a43e3c8f0bd9f7d69900ddc", "price_changes": [{"asset_id": "75087175062739028357071911202249876424512123621414420427750062298373802728902", "price": "0.08", "size": "4257.32", "side": "BUY", "hash": "1c8ad15e230d0508d8e4fa67955a00a4e15185de", "best_bid": "0.64", "best_ask": "0.69"}, {"asset_id": "51057777902653789433362935484116310785534127104787453577540080102342088856991", "price": "0.92", "size": "4257.32", "side": "SELL", "hash": "4c3b8e7251fe169b5eb9d83a887ab8fcd802920a", "best_bid": "0.31", "best_ask": "0.36"}], "timestamp": "1769384554155", "event_type": "price_change"}}
{"_local_timestamp": "2026-01-25T23:42:34.273376+00:00", "data": {"market": "0xecbb7178261e45c45a2d40f3ba28f7b90da88f208a43e3c8f0bd9f7d69900ddc", "price_changes": [{"asset_id": "75087175062739028357071911202249876424512123621414420427750062298373802728902", "price": "0.1", "size": "4563.89", "side": "BUY", "hash": "4fad971e7b52a7089d3a85caff3330731f4be662", "best_bid": "0.64", "best_ask": "0.69"}, {"asset_id": "51057777902653789433362935484116310785534127104787453577540080102342088856991", "price": "0.9", "size": "4563.89", "side": "SELL", "hash": "706d9a5e895025f92bd680a2656f00ceb66a2cd7", "best_bid": "0.31", "best_ask": "0.36"}], "timestamp": "1769384554196", "event_type": "price_change"}}
{"_local_timestamp": "2026-01-25T23:42:34.870310+00:00", "data": {"market": "0xecbb7178261e45c45a2d40f3ba28f7b90da88f208a43e3c8f0bd9f7d69900ddc", "price_changes": [{"asset_id": "75087175062739028357071911202249876424512123621414420427750062298373802728902", "price": "0.14", "size": "200", "side": "BUY", "hash": "b05f0ff10a376f8df2387d87e1df13e1476197b3", "best_bid": "0.64", "best_ask": "0.69"}, {"asset_id": "51057777902653789433362935484116310785534127104787453577540080102342088856991", "price": "0.86", "size": "200", "side": "SELL", "hash": "b9fe100a78edaa12574d41860405c31b4d213ef1", "best_bid": "0.31", "best_ask": "0.36"}], "timestamp": "1769384554797", "event_type": "price_change"}}
{"_local_timestamp": "2026-01-25T23:42:35.117156+00:00", "data": {"market": "0xecbb7178261e45c45a2d40f3ba28f7b90da88f208a43e3c8f0bd9f7d69900ddc", "price_changes": [{"asset_id": "75087175062739028357071911202249876424512123621414420427750062298373802728902", "price": "0.15", "size": "100", "side": "BUY", "hash": "ea05bc2f83a9536f8cb77e551d51a36023d1a798", "best_bid": "0.64", "best_ask": "0.69"}, {"asset_id": "51057777902653789433362935484116310785534127104787453577540080102342088856991", "price": "0.85", "size": "100", "side": "SELL", "hash": "336d30ad4f90842459ad5e152cdb5ab6e543da18", "best_bid": "0.31", "best_ask": "0.36"}], "timestamp": "1769384555034", "event_type": "price_change"}}
{"_local_timestamp": "2026-01-25T23:42:35.882960+00:00", "data": {"market": "0xecbb7178261e45c45a2d40f3ba28f7b90da88f208a43e3c8f0bd9f7d69900ddc", "price_changes": [{"asset_id": "51057777902653789433362935484116310785534127104787453577540080102342088856991", "price": "0.02", "size": "4457.32", "side": "BUY", "hash": "379458e9b2ca5d61cce251b5b51bd382fbdc176b", "best_bid": "0.31", "best_ask": "0.36"}, {"asset_id": "75087175062739028357071911202249876424512123621414420427750062298373802728902", "price": "0.98", "size": "4457.32", "side": "SELL", "hash": "dc4af6db8d6421db0080a9247769d43bebb4aca2", "best_bid": "0.64", "best_ask": "0.69"}], "timestamp": "1769384555818", "event_type": "price_change"}}
{"_local_timestamp": "2026-01-25T23:42:35.883667+00:00", "data": {"market": "0xecbb7178261e45c45a2d40f3ba28f7b90da88f208a43e3c8f0bd9f7d69900ddc", "price_changes": [{"asset_id": "51057777902653789433362935484116310785534127104787453577540080102342088856991", "price": "0.04", "size": "0", "side": "BUY", "hash": "379458e9b2ca5d61cce251b5b51bd382fbdc176b", "best_bid": "0.31", "best_ask": "0.36"}, {"asset_id": "75087175062739028357071911202249876424512123621414420427750062298373802728902", "price": "0.96", "size": "0", "side": "SELL", "hash": "dc4af6db8d6421db0080a9247769d43bebb4aca2", "best_bid": "0.64", "best_ask": "0.69"}], "timestamp": "1769384555818", "event_type": "price_change"}}
{"_local_timestamp": "2026-01-25T23:42:36.162997+00:00", "data": {"market": "0xecbb7178261e45c45a2d40f3ba28f7b90da88f208a43e3c8f0bd9f7d69900ddc", "price_changes": [{"asset_id": "51057777902653789433362935484116310785534127104787453577540080102342088856991", "price": "0.01", "size": "8787.99", "side": "BUY", "hash": "c2a29120ef4c3463f29bebce7d6aeffd322b93d8", "best_bid": "0.31", "best_ask": "0.36"}, {"asset_id": "75087175062739028357071911202249876424512123621414420427750062298373802728902", "price": "0.99", "size": "8787.99", "side": "SELL", "hash": "04d3927400d9ce021cd8bd7a397140330f856209", "best_bid": "0.64", "best_ask": "0.69"}], "timestamp": "1769384556066", "event_type": "price_change"}}
{"_local_timestamp": "2026-01-25T23:42:36.163677+00:00", "data": {"market": "0xecbb7178261e45c45a2d40f3ba28f7b90da88f208a43e3c8f0bd9f7d69900ddc", "price_changes": [{"asset_id": "51057777902653789433362935484116310785534127104787453577540080102342088856991", "price": "0.03", "size": "30.37", "side": "BUY", "hash": "2d46bb870315837989646b41a8b177d6f385afc7", "best_bid": "0.31", "best_ask": "0.36"}, {"asset_id": "75087175062739028357071911202249876424512123621414420427750062298373802728902", "price": "0.97", "size": "30.37", "side": "SELL", "hash": "ddf6671903b1f72d4f2b7572e9b06e5965c1a237", "best_bid": "0.64", "best_ask": "0.69"}], "timestamp": "1769384556067", "event_type": "price_change"}}
{"_local_timestamp": "2026-01-25T23:42:36.776429+00:00", "data": {"market": "0xecbb7178261e45c45a2d40f3ba28f7b90da88f208a43e3c8f0bd9f7d69900ddc", "price_changes": [{"asset_id": "75087175062739028357071911202249876424512123621414420427750062298373802728902", "price": "0.1", "size": "4557.32", "side": "BUY", "hash": "6ea00daa69ebe42f3deafec975879a0ece7af88b", "best_bid": "0.64", "best_ask": "0.69"}, {"asset_id": "51057777902653789433362935484116310785534127104787453577540080102342088856991", "price": "0.9", "size": "4557.32", "side": "SELL", "hash": "e694fedaac4310c3f6e5cb6f6990e6a58041d3b2", "best_bid": "0.31", "best_ask": "0.36"}], "timestamp": "1769384556705", "event_type": "price_change"}}
{"_local_timestamp": "2026-01-25T23:42:36.815918+00:00", "data": {"market": "0xecbb7178261e45c45a2d40f3ba28f7b90da88f208a43e3c8f0bd9f7d69900ddc", "price_changes": [{"asset_id": "75087175062739028357071911202249876424512123621414420427750062298373802728902", "price": "0.1", "size": "400", "side": "BUY", "hash": "f7d11f9556c725a95cea7834a40a44abc9b1929d", "best_bid": "0.64", "best_ask": "0.69"}, {"asset_id": "51057777902653789433362935484116310785534127104787453577540080102342088856991", "price": "0.9", "size": "400", "side": "SELL", "hash": "c4ddb17a22abd62371bfa5e704d9d69ce45ac5ed", "best_bid": "0.31", "best_ask": "0.36"}], "timestamp": "1769384556746", "event_type": "price_change"}}
{"_local_timestamp": "2026-01-25T23:42:37.157474+00:00", "data": {"market": "0xecbb7178261e45c45a2d40f3ba28f7b90da88f208a43e3c8f0bd9f7d69900ddc", "price_changes": [{"asset_id": "75087175062739028357071911202249876424512123621414420427750062298373802728902", "price": "0.11", "size": "5.97", "side": "BUY", "hash": "14e90917a47b62a96aa8769f768591b8f27f319e", "best_bid": "0.64", "best_ask": "0.69"}, {"asset_id": "51057777902653789433362935484116310785534127104787453577540080102342088856991", "price": "0.89", "size": "5.97", "side": "SELL", "hash": "fac98187a2d0c28d127771a69e04276cf8d630ec", "best_bid": "0.31", "best_ask": "0.36"}], "timestamp": "1769384557037", "event_type": "price_change"}}
{"_local_timestamp": "2026-01-25T23:42:41.360304+00:00", "data": {"market": "0xecbb7178261e45c45a2d40f3ba28f7b90da88f208a43e3c8f0bd9f7d69900ddc", "price_changes": [{"asset_id": "75087175062739028357071911202249876424512123621414420427750062298373802728902", "price": "0.09", "size": "100", "side": "BUY", "hash": "6609ae1a6d7e939abe20d7d61b0afd25f744bee9", "best_bid": "0.64", "best_ask": "0.69"}, {"asset_id": "51057777902653789433362935484116310785534127104787453577540080102342088856991", "price": "0.91", "size": "100", "side": "SELL", "hash": "7f93a8bd8b6cbdf80fad190cef161d7056c92e6b", "best_bid": "0.31", "best_ask": "0.36"}], "timestamp": "1769384561295", "event_type": "price_change"}}
{"_local_timestamp": "2026-01-25T23:42:41.697396+00:00", "data": {"market": "0xecbb7178261e45c45a2d40f3ba28f7b90da88f208a43e3c8f0bd9f7d69900ddc", "price_changes": [{"asset_id": "75087175062739028357071911202249876424512123621414420427750062298373802728902", "price": "0.1", "size": "500", "side": "BUY", "hash": "9b53d047c2533b64a1ec0327d5cfc22e298161fb", "best_bid": "0.64", "best_ask": "0.69"}, {"asset_id": "51057777902653789433362935484116310785534127104787453577540080102342088856991", "price": "0.9", "size": "500", "side": "SELL", "hash": "33209fc7d2ae552aca154106c35a0b23d0ea6c52", "best_bid": "0.31", "best_ask": "0.36"}], "timestamp": "1769384561626", "event_type": "price_change"}}
{"_local_timestamp": "2026-01-25T23:42:42.843940+00:00", "data": {"market": "0xecbb7178261e45c45a2d40f3ba28f7b90da88f208a43e3c8f0bd9f7d69900ddc", "price_changes": [{"asset_id": "75087175062739028357071911202249876424512123621414420427750062298373802728902", "price": "0.09", "size": "0", "side": "BUY", "hash": "e91ea22ce766a8535b3115901456a124c43616f1", "best_bid": "0.64", "best_ask": "0.69"}, {"asset_id": "51057777902653789433362935484116310785534127104787453577540080102342088856991", "price": "0.91", "size": "0", "side": "SELL", "hash": "5476f2c6785cfb0d4428e559178eb65a2d969ec8", "best_bid": "0.31", "best_ask": "0.36"}], "timestamp": "1769384562745", "event_type": "price_change"}}
{"_local_timestamp": "2026-01-25T23:42:43.147230+00:00", "data": {"market": "0xecbb7178261e45c45a2d40f3ba28f7b90da88f208a43e3c8f0bd9f7d69900ddc", "price_changes": [{"asset_id": "75087175062739028357071911202249876424512123621414420427750062298373802728902", "price": "0.1", "size": "600", "side": "BUY", "hash": "556641f2da34118b88f1578e2c0d4cae4868811e", "best_bid": "0.64", "best_ask": "0.69"}, {"asset_id": "51057777902653789433362935484116310785534127104787453577540080102342088856991", "price": "0.9", "size": "600", "side": "SELL", "hash": "ba3846a23b601d0d5809d692c6e9eec154eafdc6", "best_bid": "0.31", "best_ask": "0.36"}], "timestamp": "1769384563037", "event_type": "price_change"}}
{"_local_timestamp": "2026-01-25T23:42:43.203453+00:00", "data": {"market": "0xecbb7178261e45c45a2d40f3ba28f7b90da88f208a43e3c8f0bd9f7d69900ddc", "price_changes": [{"asset_id": "75087175062739028357071911202249876424512123621414420427750062298373802728902", "price": "0.11", "size": "1276.07", "side": "BUY", "hash": "b4a578813be36761e49f90bd4b8e5a272b9a1ddc", "best_bid": "0.64", "best_ask": "0.69"}, {"asset_id": "51057777902653789433362935484116310785534127104787453577540080102342088856991", "price": "0.89", "size": "1276.07", "side": "SELL", "hash": "de8717ecbd02a0cd122cdb72db094c0758ba7b6b", "best_bid": "0.31", "best_ask": "0.36"}], "timestamp": "1769384563094", "event_type": "price_change"}}
{"_local_timestamp": "2026-01-25T23:42:43.204744+00:00", "data": {"market": "0xecbb7178261e45c45a2d40f3ba28f7b90da88f208a43e3c8f0bd9f7d69900ddc", "price_changes": [{"asset_id": "75087175062739028357071911202249876424512123621414420427750062298373802728902", "price": "0.11", "size": "3273.18", "side": "BUY", "hash": "3ebc5abae640dc5e561688a7fc1ee562814f991a", "best_bid": "0.64", "best_ask": "0.69"}, {"asset_id": "51057777902653789433362935484116310785534127104787453577540080102342088856991", "price": "0.89", "size": "3273.18", "side": "SELL", "hash": "366c78394c511c39e43521ba0bc0b9b0fdb51a0c", "best_bid": "0.31", "best_ask": "0.36"}], "timestamp": "1769384563095", "event_type": "price_change"}}
{"_local_timestamp": "2026-01-25T23:42:43.205312+00:00", "data": {"market": "0xecbb7178261e45c45a2d40f3ba28f7b90da88f208a43e3c8f0bd9f7d69900ddc", "price_changes": [{"asset_id": "75087175062739028357071911202249876424512123621414420427750062298373802728902", "price": "0.11", "size": "4163.29", "side": "BUY", "hash": "3daeb18984bccfc493e64cccfe3b493ed14a75fd", "best_bid": "0.64", "best_ask": "0.69"}, {"asset_id": "51057777902653789433362935484116310785534127104787453577540080102342088856991", "price": "0.89", "size": "4163.29", "side": "SELL", "hash": "fb05addf2c036e04c642775093149b2797c05dab", "best_bid": "0.31", "best_ask": "0.36"}], "timestamp": "1769384563096", "event_type": "price_change"}}
{"_local_timestamp": "2026-01-25T23:42:47.334286+00:00", "data": {"market": "0xecbb7178261e45c45a2d40f3ba28f7b90da88f208a43e3c8f0bd9f7d69900ddc", "price_changes": [{"asset_id": "75087175062739028357071911202249876424512123621414420427750062298373802728902", "price": "0.15", "size": "0", "side": "BUY", "hash": "678b570b2f2d66261fdf5fa36a7311394cdb2137", "best_bid": "0.64", "best_ask": "0.69"}, {"asset_id": "51057777902653789433362935484116310785534127104787453577540080102342088856991", "price": "0.85", "size": "0", "side": "SELL", "hash": "f748e038ace7b055c5e109cbd0ad73ff3f4396f9", "best_bid": "0.31", "best_ask": "0.36"}], "timestamp": "1769384567012", "event_type": "price_change"}}
{"_local_timestamp": "2026-01-25T23:42:47.451297+00:00", "data": {"market": "0xecbb7178261e45c45a2d40f3ba28f7b90da88f208a43e3c8f0bd9f7d69900ddc", "price_changes": [{"asset_id": "75087175062739028357071911202249876424512123621414420427750062298373802728902", "price": "0.14", "size": "300", "side": "BUY", "hash": "ad4e87cd6e6c780f80ba0785d414622accddb39c", "best_bid": "0.64", "best_ask": "0.69"}, {"asset_id": "51057777902653789433362935484116310785534127104787453577540080102342088856991", "price": "0.86", "size": "300", "side": "SELL", "hash": "6e6b326e70c09083dd56a3a281dfa3573f48e230", "best_bid": "0.31", "best_ask": "0.36"}], "timestamp": "1769384567233", "event_type": "price_change"}}
{"_local_timestamp": "2026-01-25T23:42:47.473542+00:00", "data": {"market": "0xecbb7178261e45c45a2d40f3ba28f7b90da88f208a43e3c8f0bd9f7d69900ddc", "price_changes": [{"asset_id": "75087175062739028357071911202249876424512123621414420427750062298373802728902", "price": "0.08", "size": "100", "side": "BUY", "hash": "98a498c54bf4e1312ee1f3d085f1dbed223f1730", "best_bid": "0.64", "best_ask": "0.69"}, {"asset_id": "51057777902653789433362935484116310785534127104787453577540080102342088856991", "price": "0.92", "size": "100", "side": "SELL", "hash": "a3286eef55f530749f3a983720acb0c6fdbe38d3", "best_bid": "0.31", "best_ask": "0.36"}], "timestamp": "1769384567268", "event_type": "price_change"}}
{"_local_timestamp": "2026-01-25T23:42:49.517311+00:00", "data": {"market": "0xecbb7178261e45c45a2d40f3ba28f7b90da88f208a43e3c8f0bd9f7d69900ddc", "price_changes": [{"asset_id": "75087175062739028357071911202249876424512123621414420427750062298373802728902", "price": "0.08", "size": "0", "side": "BUY", "hash": "5d8de69217c37e4ade946036708364a6a68db8e7", "best_bid": "0.64", "best_ask": "0.69"}, {"asset_id": "51057777902653789433362935484116310785534127104787453577540080102342088856991", "price": "0.92", "size": "0", "side": "SELL", "hash": "8c0e52f7e6c15c27384c861434e1cb00504503ef", "best_bid": "0.31", "best_ask": "0.36"}], "timestamp": "1769384569331", "event_type": "price_change"}}
{"_local_timestamp": "2026-01-25T23:42:49.790945+00:00", "data": {"market": "0xecbb7178261e45c45a2d40f3ba28f7b90da88f208a43e3c8f0bd9f7d69900ddc", "price_changes": [{"asset_id": "75087175062739028357071911202249876424512123621414420427750062298373802728902", "price": "0.1", "size": "700", "side": "BUY", "hash": "a86f51ea28e451967fb5a77a1a13278ffab38708", "best_bid": "0.64", "best_ask": "0.69"}, {"asset_id": "51057777902653789433362935484116310785534127104787453577540080102342088856991", "price": "0.9", "size": "700", "side": "SELL", "hash": "deda8a52fbe4810fba74df680249fdcac6a0e179", "best_bid": "0.31", "best_ask": "0.36"}], "timestamp": "1769384569603", "event_type": "price_change"}}
{"_local_timestamp": "2026-01-25T23:42:55.218113+00:00", "data": {"market": "0xecbb7178261e45c45a2d40f3ba28f7b90da88f208a43e3c8f0bd9f7d69900ddc", "price_changes": [{"asset_id": "75087175062739028357071911202249876424512123621414420427750062298373802728902", "price": "0.14", "size": "100", "side": "BUY", "hash": "61b07fb7f37aeaee05561ef44e14a65bf73065b1", "best_bid": "0.64", "best_ask": "0.69"}, {"asset_id": "51057777902653789433362935484116310785534127104787453577540080102342088856991", "price": "0.86", "size": "100", "side": "SELL", "hash": "6dd0e72d833ee5eff1f98efce70cb27d8669f78c", "best_bid": "0.31", "best_ask": "0.36"}], "timestamp": "1769384575057", "event_type": "price_change"}}
{"_local_timestamp": "2026-01-25T23:42:55.218868+00:00", "data": {"market": "0xecbb7178261e45c45a2d40f3ba28f7b90da88f208a43e3c8f0bd9f7d69900ddc", "price_changes": [{"asset_id": "75087175062739028357071911202249876424512123621414420427750062298373802728902", "price": "0.1", "size": "300", "side": "BUY", "hash": "61b07fb7f37aeaee05561ef44e14a65bf73065b1", "best_bid": "0.64", "best_ask": "0.69"}, {"asset_id": "51057777902653789433362935484116310785534127104787453577540080102342088856991", "price": "0.9", "size": "300", "side": "SELL", "hash": "6dd0e72d833ee5eff1f98efce70cb27d8669f78c", "best_bid": "0.31", "best_ask": "0.36"}], "timestamp": "1769384575057", "event_type": "price_change"}}
{"_local_timestamp": "2026-01-25T23:42:55.281630+00:00", "data": {"market": "0xecbb7178261e45c45a2d40f3ba28f7b90da88f208a43e3c8f0bd9f7d69900ddc", "price_changes": [{"asset_id": "75087175062739028357071911202249876424512123621414420427750062298373802728902", "price": "0.08", "size": "1997.11", "side": "BUY", "hash": "fa247a55dcb23d31c7853d396bc0b3b333f24b85", "best_bid": "0.64", "best_ask": "0.69"}, {"asset_id": "51057777902653789433362935484116310785534127104787453577540080102342088856991", "price": "0.92", "size": "1997.11", "side": "SELL", "hash": "79784d766f2e7bf3cef038aeab14bd12c725fd0a", "best_bid": "0.31", "best_ask": "0.36"}], "timestamp": "1769384575125", "event_type": "price_change"}}
{"_local_timestamp": "2026-01-25T23:42:55.286482+00:00", "data": {"market": "0xecbb7178261e45c45a2d40f3ba28f7b90da88f208a43e3c8f0bd9f7d69900ddc", "price_changes": [{"asset_id": "75087175062739028357071911202249876424512123621414420427750062298373802728902", "price": "0.08", "size": "2887.22", "side": "BUY", "hash": "0de1bfd08fea39ec711a9eeeb873d65b88c7ccf2", "best_bid": "0.64", "best_ask": "0.69"}, {"asset_id": "51057777902653789433362935484116310785534127104787453577540080102342088856991", "price": "0.92", "size": "2887.22", "side": "SELL", "hash": "45067b67ec796665d55ddbbab19e3a4d4b3c73c7", "best_bid": "0.31", "best_ask": "0.36"}], "timestamp": "1769384575125", "event_type": "price_change"}}
{"_local_timestamp": "2026-01-25T23:42:55.287262+00:00", "data": {"market": "0xecbb7178261e45c45a2d40f3ba28f7b90da88f208a43e3c8f0bd9f7d69900ddc", "price_changes": [{"asset_id": "75087175062739028357071911202249876424512123621414420427750062298373802728902", "price": "0.08", "size": "4157.32", "side": "BUY", "hash": "6c15a97d344d0430dc3b01d949ce047f30bdb9b2", "best_bid": "0.64", "best_ask": "0.69"}, {"asset_id": "51057777902653789433362935484116310785534127104787453577540080102342088856991", "price": "0.92", "size": "4157.32", "side": "SELL", "hash": "248e594cbb269c2b08001f8e8fe2dc1fbaa250c8", "best_bid": "0.31", "best_ask": "0.36"}], "timestamp": "1769384575126", "event_type": "price_change"}}
{"_local_timestamp": "2026-01-25T23:42:55.507504+00:00", "data": {"market": "0xecbb7178261e45c45a2d40f3ba28f7b90da88f208a43e3c8f0bd9f7d69900ddc", "price_changes": [{"asset_id": "75087175062739028357071911202249876424512123621414420427750062298373802728902", "price": "0.08", "size": "4557.32", "side": "BUY", "hash": "77d391fe671be78fd29e303378ecdbbf85e714bb", "best_bid": "0.64", "best_ask": "0.69"}, {"asset_id": "51057777902653789433362935484116310785534127104787453577540080102342088856991", "price": "0.92", "size": "4557.32", "side": "SELL", "hash": "c9da749326468405978934b6d000b59d32b69329", "best_bid": "0.31", "best_ask": "0.36"}], "timestamp": "1769384575339", "event_type": "price_change"}}
{"_local_timestamp": "2026-01-25T23:42:55.508219+00:00", "data": {"market": "0xecbb7178261e45c45a2d40f3ba28f7b90da88f208a43e3c8f0bd9f7d69900ddc", "price_changes": [{"asset_id": "75087175062739028357071911202249876424512123621414420427750062298373802728902", "price": "0.15", "size": "200", "side": "BUY", "hash": "da79de8e643500b0e126406e1a644ad90b32787c", "best_bid": "0.64", "best_ask": "0.69"}, {"asset_id": "51057777902653789433362935484116310785534127104787453577540080102342088856991", "price": "0.85", "size": "200", "side": "SELL", "hash": "f765f29342ad8a4a8fc0b984ac218d2d3f13eac1", "best_bid": "0.31", "best_ask": "0.36"}], "timestamp": "1769384575340", "event_type": "price_change"}}
{"_local_timestamp": "2026-01-25T23:43:12.286987+00:00", "data": {"market": "0xecbb7178261e45c45a2d40f3ba28f7b90da88f208a43e3c8f0bd9f7d69900ddc", "price_changes": [{"asset_id": "75087175062739028357071911202249876424512123621414420427750062298373802728902", "price": "0.14", "size": "0", "side": "BUY", "hash": "8d1532e5cd5eddf063912dffb131cdfd54f68106", "best_bid": "0.64", "best_ask": "0.69"}, {"asset_id": "51057777902653789433362935484116310785534127104787453577540080102342088856991", "price": "0.86", "size": "0", "side": "SELL", "hash": "a49ed872da39cb13318308cdcf98f26ec6fe3353", "best_bid": "0.31", "best_ask": "0.36"}], "timestamp": "1769384592214", "event_type": "price_change"}}
{"_local_timestamp": "2026-01-25T23:43:12.367491+00:00", "data": {"market": "0xecbb7178261e45c45a2d40f3ba28f7b90da88f208a43e3c8f0bd9f7d69900ddc", "price_changes": [{"asset_id": "75087175062739028357071911202249876424512123621414420427750062298373802728902", "price": "0.11", "size": "5.97", "side": "BUY", "hash": "939569f9c9d4fd5389bb88df28ceb1a3180e8ce7", "best_bid": "0.64", "best_ask": "0.69"}, {"asset_id": "51057777902653789433362935484116310785534127104787453577540080102342088856991", "price": "0.89", "size": "5.97", "side": "SELL", "hash": "ba4404dc0117d2d5997d3398f058296cd182b4b3", "best_bid": "0.31", "best_ask": "0.36"}], "timestamp": "1769384592299", "event_type": "price_change"}}
{"_local_timestamp": "2026-01-25T23:43:12.523910+00:00", "data": {"market": "0xecbb7178261e45c45a2d40f3ba28f7b90da88f208a43e3c8f0bd9f7d69900ddc", "price_changes": [{"asset_id": "75087175062739028357071911202249876424512123621414420427750062298373802728902", "price": "0.15", "size": "300", "side": "BUY", "hash": "d51d156d93187cda1dd851b338e72d0373eef5f5", "best_bid": "0.64", "best_ask": "0.69"}, {"asset_id": "51057777902653789433362935484116310785534127104787453577540080102342088856991", "price": "0.85", "size": "300", "side": "SELL", "hash": "30a42c7124921ff71050093d1e5f32090b428e29", "best_bid": "0.31", "best_ask": "0.36"}], "timestamp": "1769384592456", "event_type": "price_change"}}
{"_local_timestamp": "2026-01-25T23:43:14.001475+00:00", "data": {"market": "0xecbb7178261e45c45a2d40f3ba28f7b90da88f208a43e3c8f0bd9f7d69900ddc", "price_changes": [{"asset_id": "75087175062739028357071911202249876424512123621414420427750062298373802728902", "price": "0.1", "size": "200", "side": "BUY", "hash": "c525e63fc35c732b0b7b9cdb9bb0c562e8fbcf43", "best_bid": "0.64", "best_ask": "0.69"}, {"asset_id": "51057777902653789433362935484116310785534127104787453577540080102342088856991", "price": "0.9", "size": "200", "side": "SELL", "hash": "370b81e8e875925d7fffcc34d59361589d7d8071", "best_bid": "0.31", "best_ask": "0.36"}], "timestamp": "1769384593932", "event_type": "price_change"}}
{"_local_timestamp": "2026-01-25T23:43:14.309653+00:00", "data": {"market": "0xecbb7178261e45c45a2d40f3ba28f7b90da88f208a43e3c8f0bd9f7d69900ddc", "price_changes": [{"asset_id": "75087175062739028357071911202249876424512123621414420427750062298373802728902", "price": "0.11", "size": "105.97", "side": "BUY", "hash": "0025d788f8ce0d85b9589bd2a79aef33d0dacfc9", "best_bid": "0.64", "best_ask": "0.69"}, {"asset_id": "51057777902653789433362935484116310785534127104787453577540080102342088856991", "price": "0.89", "size": "105.97", "side": "SELL", "hash": "ad234abc6b62aeeeae5f2bdd9fb873090f27750c", "best_bid": "0.31", "best_ask": "0.36"}], "timestamp": "1769384594238", "event_type": "price_change"}}
{"_local_timestamp": "2026-01-25T23:43:15.521494+00:00", "data": {"market": "0xecbb7178261e45c45a2d40f3ba28f7b90da88f208a43e3c8f0bd9f7d69900ddc", "price_changes": [{"asset_id": "75087175062739028357071911202249876424512123621414420427750062298373802728902", "price": "0.08", "size": "4157.32", "side": "BUY", "hash": "c167d4a6acdd3ed531072e708f15493b1ba07504", "best_bid": "0.64", "best_ask": "0.69"}, {"asset_id": "51057777902653789433362935484116310785534127104787453577540080102342088856991", "price": "0.92", "size": "4157.32", "side": "SELL", "hash": "cb63e89f9636edb200a25c92ab30f0dfdfdb910d", "best_bid": "0.31", "best_ask": "0.36"}], "timestamp": "1769384595453", "event_type": "price_change"}}
{"_local_timestamp": "2026-01-25T23:43:15.522216+00:00", "data": {"market": "0xecbb7178261e45c45a2d40f3ba28f7b90da88f208a43e3c8f0bd9f7d69900ddc", "price_changes": [{"asset_id": "75087175062739028357071911202249876424512123621414420427750062298373802728902", "price": "0.15", "size": "100", "side": "BUY", "hash": "c167d4a6acdd3ed531072e708f15493b1ba07504", "best_bid": "0.64", "best_ask": "0.69"}, {"asset_id": "51057777902653789433362935484116310785534127104787453577540080102342088856991", "price": "0.85", "size": "100", "side": "SELL", "hash": "cb63e89f9636edb200a25c92ab30f0dfdfdb910d", "best_bid": "0.31", "best_ask": "0.36"}], "timestamp": "1769384595453", "event_type": "price_change"}}
{"_local_timestamp": "2026-01-25T23:43:15.869345+00:00", "data": {"market": "0xecbb7178261e45c45a2d40f3ba28f7b90da88f208a43e3c8f0bd9f7d69900ddc", "price_changes": [{"asset_id": "75087175062739028357071911202249876424512123621414420427750062298373802728902", "price": "0.14", "size": "200", "side": "BUY", "hash": "b99af64003917778ca1a3bf72d96332c1121dd7a", "best_bid": "0.64", "best_ask": "0.69"}, {"asset_id": "51057777902653789433362935484116310785534127104787453577540080102342088856991", "price": "0.86", "size": "200", "side": "SELL", "hash": "5971ae7c0951f8248dd1af3fde336016ff7885e9", "best_bid": "0.31", "best_ask": "0.36"}], "timestamp": "1769384595781", "event_type": "price_change"}}
{"_local_timestamp": "2026-01-25T23:43:15.871900+00:00", "data": {"market": "0xecbb7178261e45c45a2d40f3ba28f7b90da88f208a43e3c8f0bd9f7d69900ddc", "price_changes": [{"asset_id": "75087175062739028357071911202249876424512123621414420427750062298373802728902", "price": "0.11", "size": "505.97", "side": "BUY", "hash": "6aff15f292c29bc6b941e5623a56486bbfcfe592", "best_bid": "0.64", "best_ask": "0.69"}, {"asset_id": "51057777902653789433362935484116310785534127104787453577540080102342088856991", "price": "0.89", "size": "505.97", "side": "SELL", "hash": "ec5f12cc9a17ced94176ecebb7db949ca3bb189e", "best_bid": "0.31", "best_ask": "0.36"}], "timestamp": "1769384595787", "event_type": "price_change"}}
{"_local_timestamp": "2026-01-25T23:43:15.980857+00:00", "data": {"market": "0xecbb7178261e45c45a2d40f3ba28f7b90da88f208a43e3c8f0bd9f7d69900ddc", "price_changes": [{"asset_id": "75087175062739028357071911202249876424512123621414420427750062298373802728902", "price": "0.1", "size": "100", "side": "BUY", "hash": "8ba64fc6b26ae3b68d1cd849927f6d0e3f52bb4a", "best_bid": "0.64", "best_ask": "0.69"}, {"asset_id": "51057777902653789433362935484116310785534127104787453577540080102342088856991", "price": "0.9", "size": "100", "side": "SELL", "hash": "dd294beacf431ff0761baa7299ca9253c78ee1d9", "best_bid": "0.31", "best_ask": "0.36"}], "timestamp": "1769384595914", "event_type": "price_change"}}
{"_local_timestamp": "2026-01-25T23:43:16.370054+00:00", "data": {"market": "0xecbb7178261e45c45a2d40f3ba28f7b90da88f208a43e3c8f0bd9f7d69900ddc", "price_changes": [{"asset_id": "75087175062739028357071911202249876424512123621414420427750062298373802728902", "price": "0.11", "size": "605.97", "side": "BUY", "hash": "84433b00948c202dc3e0f91f820004316b1d7120", "best_bid": "0.64", "best_ask": "0.69"}, {"asset_id": "51057777902653789433362935484116310785534127104787453577540080102342088856991", "price": "0.89", "size": "605.97", "side": "SELL", "hash": "a49d2921e33ef767b9f13435d0cca9941e5435ba", "best_bid": "0.31", "best_ask": "0.36"}], "timestamp": "1769384596295", "event_type": "price_change"}}
{"_local_timestamp": "2026-01-25T23:43:16.488899+00:00", "data": {"market": "0xecbb7178261e45c45a2d40f3ba28f7b90da88f208a43e3c8f0bd9f7d69900ddc", "price_changes": [{"asset_id": "75087175062739028357071911202249876424512123621414420427750062298373802728902", "price": "0.12", "size": "1997.11", "side": "BUY", "hash": "36640ae1511786b5edbbda0fe6df3ab8649d6217", "best_bid": "0.64", "best_ask": "0.69"}, {"asset_id": "51057777902653789433362935484116310785534127104787453577540080102342088856991", "price": "0.88", "size": "1997.11", "side": "SELL", "hash": "f4f7e84df7bc4758110b1511a876513a5cf127d2", "best_bid": "0.31", "best_ask": "0.36"}], "timestamp": "1769384596415", "event_type": "price_change"}}
{"_local_timestamp": "2026-01-25T23:43:16.489607+00:00", "data": {"market": "0xecbb7178261e45c45a2d40f3ba28f7b90da88f208a43e3c8f0bd9f7d69900ddc", "price_changes": [{"asset_id": "75087175062739028357071911202249876424512123621414420427750062298373802728902", "price": "0.12", "size": "3267.21", "side": "BUY", "hash": "3ab9b4359dff8dc71669d03435d8b4ac6d93d8c6", "best_bid": "0.64", "best_ask": "0.69"}, {"asset_id": "51057777902653789433362935484116310785534127104787453577540080102342088856991", "price": "0.88", "size": "3267.21", "side": "SELL", "hash": "56a2a2b58db338c4b754c88d802b1461b3619138", "best_bid": "0.31", "best_ask": "0.36"}], "timestamp": "1769384596417", "event_type": "price_change"}}
{"_local_timestamp": "2026-01-25T23:43:16.490198+00:00", "data": {"market": "0xecbb7178261e45c45a2d40f3ba28f7b90da88f208a43e3c8f0bd9f7d69900ddc", "price_changes": [{"asset_id": "75087175062739028357071911202249876424512123621414420427750062298373802728902", "price": "0.12", "size": "4157.32", "side": "BUY", "hash": "fd1fa24dd899e5bbffd1bcc9c520b80bfde2f10d", "best_bid": "0.64", "best_ask": "0.69"}, {"asset_id": "51057777902653789433362935484116310785534127104787453577540080102342088856991", "price": "0.88", "size": "4157.32", "side": "SELL", "hash": "d9b64d76083252132c91e672e779c2bcec696973", "best_bid": "0.31", "best_ask": "0.36"}], "timestamp": "1769384596420", "event_type": "price_change"}}
{"_local_timestamp": "2026-01-25T23:43:18.514488+00:00", "data": {"market": "0xecbb7178261e45c45a2d40f3ba28f7b90da88f208a43e3c8f0bd9f7d69900ddc", "price_changes": [{"asset_id": "75087175062739028357071911202249876424512123621414420427750062298373802728902", "price": "0.1", "size": "0", "side": "BUY", "hash": "4228ce70ef21af0b37d8d837c9e2e4cbb0cc3345", "best_bid": "0.64", "best_ask": "0.69"}, {"asset_id": "51057777902653789433362935484116310785534127104787453577540080102342088856991", "price": "0.9", "size": "0", "side": "SELL", "hash": "4d5c78c98d7d1cac431fdf9ffe8dec70881bfbdb", "best_bid": "0.31", "best_ask": "0.36"}], "timestamp": "1769384598435", "event_type": "price_change"}}
{"_local_timestamp": "2026-01-25T23:43:18.839874+00:00", "data": {"market": "0xecbb7178261e45c45a2d40f3ba28f7b90da88f208a43e3c8f0bd9f7d69900ddc", "price_changes": [{"asset_id": "75087175062739028357071911202249876424512123621414420427750062298373802728902", "price": "0.11", "size": "705.97", "side": "BUY", "hash": "d375d5c7aa4dbdac282aa72f505bb5b25c76bb1c", "best_bid": "0.64", "best_ask": "0.69"}, {"asset_id": "51057777902653789433362935484116310785534127104787453577540080102342088856991", "price": "0.89", "size": "705.97", "side": "SELL", "hash": "d97ff6678614bd328afbce666502a25f6e447046", "best_bid": "0.31", "best_ask": "0.36"}], "timestamp": "1769384598771", "event_type": "price_change"}}
{"_local_timestamp": "2026-01-25T23:43:23.908827+00:00", "data": {"market": "0xecbb7178261e45c45a2d40f3ba28f7b90da88f208a43e3c8f0bd9f7d69900ddc", "price_changes": [{"asset_id": "75087175062739028357071911202249876424512123621414420427750062298373802728902", "price": "0.15", "size": "0", "side": "BUY", "hash": "a4996468c14a709f92621b8249ca99b289acdf03", "best_bid": "0.64", "best_ask": "0.69"}, {"asset_id": "51057777902653789433362935484116310785534127104787453577540080102342088856991", "price": "0.85", "size": "0", "side": "SELL", "hash": "4bd62ab59129dd796bace9df3512355ab3bec8b3", "best_bid": "0.31", "best_ask": "0.36"}], "timestamp": "1769384603840", "event_type": "price_change"}}
{"_local_timestamp": "2026-01-25T23:43:24.027522+00:00", "data": {"market": "0xecbb7178261e45c45a2d40f3ba28f7b90da88f208a43e3c8f0bd9f7d69900ddc", "price_changes": [{"asset_id": "75087175062739028357071911202249876424512123621414420427750062298373802728902", "price": "0.08", "size": "0", "side": "BUY", "hash": "84d51917aab0abcaf31559029dd2014fc8257626", "best_bid": "0.64", "best_ask": "0.69"}, {"asset_id": "51057777902653789433362935484116310785534127104787453577540080102342088856991", "price": "0.92", "size": "0", "side": "SELL", "hash": "15191ef017f5a2079bbdc26c559296ccca8b0e27", "best_bid": "0.31", "best_ask": "0.36"}], "timestamp": "1769384603957", "event_type": "price_change"}}
{"_local_timestamp": "2026-01-25T23:43:24.138693+00:00", "data": {"market": "0xecbb7178261e45c45a2d40f3ba28f7b90da88f208a43e3c8f0bd9f7d69900ddc", "price_changes": [{"asset_id": "75087175062739028357071911202249876424512123621414420427750062298373802728902", "price": "0.14", "size": "300", "side": "BUY", "hash": "c960abe8b154f45f0b32366dd9fb1a83ae44c5b9", "best_bid": "0.64", "best_ask": "0.69"}, {"asset_id": "51057777902653789433362935484116310785534127104787453577540080102342088856991", "price": "0.86", "size": "300", "side": "SELL", "hash": "c7a87120ebc12928cc4a946aa6e9f577a271b4b2", "best_bid": "0.31", "best_ask": "0.36"}], "timestamp": "1769384604067", "event_type": "price_change"}}
{"_local_timestamp": "2026-01-25T23:43:38.170108+00:00", "data": {"market": "0xecbb7178261e45c45a2d40f3ba28f7b90da88f208a43e3c8f0bd9f7d69900ddc", "price_changes": [{"asset_id": "75087175062739028357071911202249876424512123621414420427750062298373802728902", "price": "0.14", "size": "100", "side": "BUY", "hash": "6ea7e72774020a5720b746de34c75e61a8c0968e", "best_bid": "0.64", "best_ask": "0.69"}, {"asset_id": "51057777902653789433362935484116310785534127104787453577540080102342088856991", "price": "0.86", "size": "100", "side": "SELL", "hash": "0be90f916a9862d142be54ea8b9965277d5d97ce", "best_bid": "0.31", "best_ask": "0.36"}], "timestamp": "1769384618105", "event_type": "price_change"}}
{"_local_timestamp": "2026-01-25T23:43:38.179202+00:00", "data": {"market": "0xecbb7178261e45c45a2d40f3ba28f7b90da88f208a43e3c8f0bd9f7d69900ddc", "price_changes": [{"asset_id": "75087175062739028357071911202249876424512123621414420427750062298373802728902", "price": "0.11", "size": "305.97", "side": "BUY", "hash": "44395338c366d6636bc5f06a9e5c9ddf497fc6d6", "best_bid": "0.64", "best_ask": "0.69"}, {"asset_id": "51057777902653789433362935484116310785534127104787453577540080102342088856991", "price": "0.89", "size": "305.97", "side": "SELL", "hash": "4d2daff9513afedd7190953f3486d8183c1f2876", "best_bid": "0.31", "best_ask": "0.36"}], "timestamp": "1769384618109", "event_type": "price_change"}}
{"_local_timestamp": "2026-01-25T23:43:38.325669+00:00", "data": {"market": "0xecbb7178261e45c45a2d40f3ba28f7b90da88f208a43e3c8f0bd9f7d69900ddc", "price_changes": [{"asset_id": "75087175062739028357071911202249876424512123621414420427750062298373802728902", "price": "0.08", "size": "1997.11", "side": "BUY", "hash": "6285df04b20e7c33ae7c15b579861e10f577154c", "best_bid": "0.64", "best_ask": "0.69"}, {"asset_id": "51057777902653789433362935484116310785534127104787453577540080102342088856991", "price": "0.92", "size": "1997.11", "side": "SELL", "hash": "1e1e85d941eac7b113837d7709b7b1ceaf04e636", "best_bid": "0.31", "best_ask": "0.36"}], "timestamp": "1769384618260", "event_type": "price_change"}}
{"_local_timestamp": "2026-01-25T23:43:38.334426+00:00", "data": {"market": "0xecbb7178261e45c45a2d40f3ba28f7b90da88f208a43e3c8f0bd9f7d69900ddc", "price_changes": [{"asset_id": "75087175062739028357071911202249876424512123621414420427750062298373802728902", "price": "0.08", "size": "2887.22", "side": "BUY", "hash": "4030c5ece1df76d9da7bfda0e2b79b9b3fa88765", "best_bid": "0.64", "best_ask": "0.69"}, {"asset_id": "51057777902653789433362935484116310785534127104787453577540080102342088856991", "price": "0.92", "size": "2887.22", "side": "SELL", "hash": "86d792863fafb46c48ed8600257fd3430e16d54c", "best_bid": "0.31", "best_ask": "0.36"}], "timestamp": "1769384618260", "event_type": "price_change"}}
{"_local_timestamp": "2026-01-25T23:43:38.335118+00:00", "data": {"market": "0xecbb7178261e45c45a2d40f3ba28f7b90da88f208a43e3c8f0bd9f7d69900ddc", "price_changes": [{"asset_id": "75087175062739028357071911202249876424512123621414420427750062298373802728902", "price": "0.08", "size": "4157.32", "side": "BUY", "hash": "1da4b12a66fe92fa1f5afd28d3d1f4dc16a93eaf", "best_bid": "0.64", "best_ask": "0.69"}, {"asset_id": "51057777902653789433362935484116310785534127104787453577540080102342088856991", "price": "0.92", "size": "4157.32", "side": "SELL", "hash": "56803ae206f5dcbb7b764e8030f563e8f9f3abb2", "best_bid": "0.31", "best_ask": "0.36"}], "timestamp": "1769384618261", "event_type": "price_change"}}
{"_local_timestamp": "2026-01-25T23:43:38.449933+00:00", "data": {"market": "0xecbb7178261e45c45a2d40f3ba28f7b90da88f208a43e3c8f0bd9f7d69900ddc", "price_changes": [{"asset_id": "75087175062739028357071911202249876424512123621414420427750062298373802728902", "price": "0.15", "size": "200", "side": "BUY", "hash": "fce118829727daa862168174a405948be701c8a4", "best_bid": "0.64", "best_ask": "0.69"}, {"asset_id": "51057777902653789433362935484116310785534127104787453577540080102342088856991", "price": "0.85", "size": "200", "side": "SELL", "hash": "9b6262144d5c5472b5d1c9c2347de9891902ec14", "best_bid": "0.31", "best_ask": "0.36"}], "timestamp": "1769384618383", "event_type": "price_change"}}
{"_local_timestamp": "2026-01-25T23:43:38.467254+00:00", "data": {"market": "0xecbb7178261e45c45a2d40f3ba28f7b90da88f208a43e3c8f0bd9f7d69900ddc", "price_changes": [{"asset_id": "75087175062739028357071911202249876424512123621414420427750062298373802728902", "price": "0.12", "size": "4557.32", "side": "BUY", "hash": "e22e22cbe3545a67e4a0d7832161ea0b13f27ec4", "best_bid": "0.64", "best_ask": "0.69"}, {"asset_id": "51057777902653789433362935484116310785534127104787453577540080102342088856991", "price": "0.88", "size": "4557.32", "side": "SELL", "hash": "4dda9a5f1b275fb4731e844d86f6d16bc73b5e83", "best_bid": "0.31", "best_ask": "0.36"}], "timestamp": "1769384618384", "event_type": "price_change"}}
{"_local_timestamp": "2026-01-25T23:43:44.747907+00:00", "data": {"market": "0xecbb7178261e45c45a2d40f3ba28f7b90da88f208a43e3c8f0bd9f7d69900ddc", "price_changes": [{"asset_id": "75087175062739028357071911202249876424512123621414420427750062298373802728902", "price": "0.11", "size": "205.97", "side": "BUY", "hash": "ae47e4fd2a8b20a58d5a3e3e0876659b1db3f777", "best_bid": "0.64", "best_ask": "0.69"}, {"asset_id": "51057777902653789433362935484116310785534127104787453577540080102342088856991", "price": "0.89", "size": "205.97", "side": "SELL", "hash": "fd9b94b46aa2fdc6e10de1e11563a7e41de5472d", "best_bid": "0.31", "best_ask": "0.36"}], "timestamp": "1769384624678", "event_type": "price_change"}}
{"_local_timestamp": "2026-01-25T23:43:44.815981+00:00", "data": {"market": "0xecbb7178261e45c45a2d40f3ba28f7b90da88f208a43e3c8f0bd9f7d69900ddc", "price_changes": [{"asset_id": "75087175062739028357071911202249876424512123621414420427750062298373802728902", "price": "0.12", "size": "400", "side": "BUY", "hash": "64480dc1764056e84e8088f3161a3569ebbc853b", "best_bid": "0.64", "best_ask": "0.69"}, {"asset_id": "51057777902653789433362935484116310785534127104787453577540080102342088856991", "price": "0.88", "size": "400", "side": "SELL", "hash": "3c32c88df0d50849376a3446724ff2f5b1e0ae1e", "best_bid": "0.31", "best_ask": "0.36"}], "timestamp": "1769384624734", "event_type": "price_change"}}
{"_local_timestamp": "2026-01-25T23:43:45.030071+00:00", "data": {"market": "0xecbb7178261e45c45a2d40f3ba28f7b90da88f208a43e3c8f0bd9f7d69900ddc", "price_changes": [{"asset_id": "75087175062739028357071911202249876424512123621414420427750062298373802728902", "price": "0.12", "size": "500", "side": "BUY", "hash": "be0a79d9dcba78fc11b6ef0728400978d97aee3d", "best_bid": "0.64", "best_ask": "0.69"}, {"asset_id": "51057777902653789433362935484116310785534127104787453577540080102342088856991", "price": "0.88", "size": "500", "side": "SELL", "hash": "5f3675cf7d615ef29ccab9ae1d4afc9ea50b0fbc", "best_bid": "0.31", "best_ask": "0.36"}], "timestamp": "1769384624960", "event_type": "price_change"}}
{"_local_timestamp": "2026-01-25T23:43:47.791855+00:00", "data": {"market": "0xecbb7178261e45c45a2d40f3ba28f7b90da88f208a43e3c8f0bd9f7d69900ddc", "price_changes": [{"asset_id": "75087175062739028357071911202249876424512123621414420427750062298373802728902", "price": "0.11", "size": "105.97", "side": "BUY", "hash": "a242d802bdbc273684a7809fd9c2016796b5dd87", "best_bid": "0.64", "best_ask": "0.69"}, {"asset_id": "51057777902653789433362935484116310785534127104787453577540080102342088856991", "price": "0.89", "size": "105.97", "side": "SELL", "hash": "2c973dc18b74743c20583a2b8ce03390036f7fda", "best_bid": "0.31", "best_ask": "0.36"}], "timestamp": "1769384627727", "event_type": "price_change"}}
{"_local_timestamp": "2026-01-25T23:43:48.109660+00:00", "data": {"market": "0xecbb7178261e45c45a2d40f3ba28f7b90da88f208a43e3c8f0bd9f7d69900ddc", "price_changes": [{"asset_id": "75087175062739028357071911202249876424512123621414420427750062298373802728902", "price": "0.12", "size": "600", "side": "BUY", "hash": "c9be8d27b96d534119b3963402278b1c4bc7de8d", "best_bid": "0.64", "best_ask": "0.69"}, {"asset_id": "51057777902653789433362935484116310785534127104787453577540080102342088856991", "price": "0.88", "size": "600", "side": "SELL", "hash": "670a69512e9fb80fac9875cfcdae4f42f38482eb", "best_bid": "0.31", "best_ask": "0.36"}], "timestamp": "1769384628034", "event_type": "price_change"}}
{"_local_timestamp": "2026-01-25T23:43:48.193789+00:00", "data": {"market": "0xecbb7178261e45c45a2d40f3ba28f7b90da88f208a43e3c8f0bd9f7d69900ddc", "price_changes": [{"asset_id": "75087175062739028357071911202249876424512123621414420427750062298373802728902", "price": "0.13", "size": "890.11", "side": "BUY", "hash": "5761daf0b4afdc16faf6c2021a1931b96b2abfdd", "best_bid": "0.64", "best_ask": "0.69"}, {"asset_id": "51057777902653789433362935484116310785534127104787453577540080102342088856991", "price": "0.87", "size": "890.11", "side": "SELL", "hash": "fb68c227491f6b262f334056faa1dd663a9f3c32", "best_bid": "0.31", "best_ask": "0.36"}], "timestamp": "1769384628122", "event_type": "price_change"}}
{"_local_timestamp": "2026-01-25T23:43:48.237559+00:00", "data": {"market": "0xecbb7178261e45c45a2d40f3ba28f7b90da88f208a43e3c8f0bd9f7d69900ddc", "price_changes": [{"asset_id": "75087175062739028357071911202249876424512123621414420427750062298373802728902", "price": "0.13", "size": "2160.21", "side": "BUY", "hash": "bca7949fc51c999888c7c53cac59cb9e3b5028b9", "best_bid": "0.64", "best_ask": "0.69"}, {"asset_id": "51057777902653789433362935484116310785534127104787453577540080102342088856991", "price": "0.87", "size": "2160.21", "side": "SELL", "hash": "c0eb33787d8d0113673b32eac46ed17945e6662b", "best_bid": "0.31", "best_ask": "0.36"}], "timestamp": "1769384628169", "event_type": "price_change"}}
{"_local_timestamp": "2026-01-25T23:43:48.269599+00:00", "data": {"market": "0xecbb7178261e45c45a2d40f3ba28f7b90da88f208a43e3c8f0bd9f7d69900ddc", "price_changes": [{"asset_id": "75087175062739028357071911202249876424512123621414420427750062298373802728902", "price": "0.13", "size": "4157.32", "side": "BUY", "hash": "4624a2fd782b6d4c09b2814eac85444e7ae3f4a9", "best_bid": "0.64", "best_ask": "0.69"}, {"asset_id": "51057777902653789433362935484116310785534127104787453577540080102342088856991", "price": "0.87", "size": "4157.32", "side": "SELL", "hash": "d3cd73deb5642ea3567c24447ba93428e272e3fe", "best_bid": "0.31", "best_ask": "0.36"}], "timestamp": "1769384628198", "event_type": "price_change"}}
{"_local_timestamp": "2026-01-25T23:43:48.749174+00:00", "data": {"market": "0xecbb7178261e45c45a2d40f3ba28f7b90da88f208a43e3c8f0bd9f7d69900ddc", "price_changes": [{"asset_id": "75087175062739028357071911202249876424512123621414420427750062298373802728902", "price": "0.14", "size": "0", "side": "BUY", "hash": "97855af5d893c2588fce85ec47370ea206ef85f9", "best_bid": "0.64", "best_ask": "0.69"}, {"asset_id": "51057777902653789433362935484116310785534127104787453577540080102342088856991", "price": "0.86", "size": "0", "side": "SELL", "hash": "ab769dc51cef29c804ccd0b006cc4d17b5dd1fa5", "best_bid": "0.31", "best_ask": "0.36"}], "timestamp": "1769384628680", "event_type": "price_change"}}
{"_local_timestamp": "2026-01-25T23:43:48.980344+00:00", "data": {"market": "0xecbb7178261e45c45a2d40f3ba28f7b90da88f208a43e3c8f0bd9f7d69900ddc", "price_changes": [{"asset_id": "75087175062739028357071911202249876424512123621414420427750062298373802728902", "price": "0.15", "size": "300", "side": "BUY", "hash": "9bb52907150101bcbd75c3ae3fa75613f112296a", "best_bid": "0.64", "best_ask": "0.69"}, {"asset_id": "51057777902653789433362935484116310785534127104787453577540080102342088856991", "price": "0.85", "size": "300", "side": "SELL", "hash": "fcd90fb69dc1df573ff4e8cc182b6c4cc0ad6217", "best_bid": "0.31", "best_ask": "0.36"}], "timestamp": "1769384628915", "event_type": "price_change"}}
{"_local_timestamp": "2026-01-25T23:43:49.799222+00:00", "data": {"market": "0xecbb7178261e45c45a2d40f3ba28f7b90da88f208a43e3c8f0bd9f7d69900ddc", "price_changes": [{"asset_id": "75087175062739028357071911202249876424512123621414420427750062298373802728902", "price": "0.11", "size": "5.97", "side": "BUY", "hash": "5868764d84906cf9b9d0f1070ab382a733cefa8f", "best_bid": "0.64", "best_ask": "0.69"}, {"asset_id": "51057777902653789433362935484116310785534127104787453577540080102342088856991", "price": "0.89", "size": "5.97", "side": "SELL", "hash": "c439e743f793988b08bfd4d468e7810d3943c398", "best_bid": "0.31", "best_ask": "0.36"}], "timestamp": "1769384629733", "event_type": "price_change"}}
{"_local_timestamp": "2026-01-25T23:43:50.113799+00:00", "data": {"market": "0xecbb7178261e45c45a2d40f3ba28f7b90da88f208a43e3c8f0bd9f7d69900ddc", "price_changes": [{"asset_id": "75087175062739028357071911202249876424512123621414420427750062298373802728902", "price": "0.12", "size": "700", "side": "BUY", "hash": "f6bf11f08642634c12da49065ba490c8f51c7093", "best_bid": "0.64", "best_ask": "0.69"}, {"asset_id": "51057777902653789433362935484116310785534127104787453577540080102342088856991", "price": "0.88", "size": "700", "side": "SELL", "hash": "bb8623365fb1b0824b16e54488645a9ce0004fa6", "best_bid": "0.31", "best_ask": "0.36"}], "timestamp": "1769384630017", "event_type": "price_change"}}
{"_local_timestamp": "2026-01-25T23:44:01.505520+00:00", "data": {"market": "0xecbb7178261e45c45a2d40f3ba28f7b90da88f208a43e3c8f0bd9f7d69900ddc", "price_changes": [{"asset_id": "75087175062739028357071911202249876424512123621414420427750062298373802728902", "price": "0.15", "size": "100", "side": "BUY", "hash": "12e72126b959b294be44835896ac455e5b3676a8", "best_bid": "0.64", "best_ask": "0.69"}, {"asset_id": "51057777902653789433362935484116310785534127104787453577540080102342088856991", "price": "0.85", "size": "100", "side": "SELL", "hash": "901d28a85b408d5509fd02478fdc7bc915421411", "best_bid": "0.31", "best_ask": "0.36"}], "timestamp": "1769384641441", "event_type": "price_change"}}
{"_local_timestamp": "2026-01-25T23:44:01.506418+00:00", "data": {"market": "0xecbb7178261e45c45a2d40f3ba28f7b90da88f208a43e3c8f0bd9f7d69900ddc", "price_changes": [{"asset_id": "75087175062739028357071911202249876424512123621414420427750062298373802728902", "price": "0.12", "size": "300", "side": "BUY", "hash": "12e72126b959b294be44835896ac455e5b3676a8", "best_bid": "0.64", "best_ask": "0.69"}, {"asset_id": "51057777902653789433362935484116310785534127104787453577540080102342088856991", "price": "0.88", "size": "300", "side": "SELL", "hash": "901d28a85b408d5509fd02478fdc7bc915421411", "best_bid": "0.31", "best_ask": "0.36"}], "timestamp": "1769384641441", "event_type": "price_change"}}
{"_local_timestamp": "2026-01-25T23:44:01.796038+00:00", "data": {"market": "0xecbb7178261e45c45a2d40f3ba28f7b90da88f208a43e3c8f0bd9f7d69900ddc", "price_changes": [{"asset_id": "75087175062739028357071911202249876424512123621414420427750062298373802728902", "price": "0.08", "size": "4557.32", "side": "BUY", "hash": "dcb8579fc3c9d4d9d102bf414dc8be018b57e69e", "best_bid": "0.64", "best_ask": "0.69"}, {"asset_id": "51057777902653789433362935484116310785534127104787453577540080102342088856991", "price": "0.92", "size": "4557.32", "side": "SELL", "hash": "8566abf2cb0767ed51ab6d227e3dfd73bc85ff31", "best_bid": "0.31", "best_ask": "0.36"}], "timestamp": "1769384641728", "event_type": "price_change"}}
{"_local_timestamp": "2026-01-25T23:44:01.817745+00:00", "data": {"market": "0xecbb7178261e45c45a2d40f3ba28f7b90da88f208a43e3c8f0bd9f7d69900ddc", "price_changes": [{"asset_id": "75087175062739028357071911202249876424512123621414420427750062298373802728902", "price": "0.14", "size": "200", "side": "BUY", "hash": "6bf863bdca995e89fc09de07608d6ba995b99753", "best_bid": "0.64", "best_ask": "0.69"}, {"asset_id": "51057777902653789433362935484116310785534127104787453577540080102342088856991", "price": "0.86", "size": "200", "side": "SELL", "hash": "880bd1476695a7407900b1b61412e292e4d9a18b", "best_bid": "0.31", "best_ask": "0.36"}], "timestamp": "1769384641729", "event_type": "price_change"}}
{"_local_timestamp": "2026-01-25T23:44:06.293702+00:00", "data": {"market": "0xecbb7178261e45c45a2d40f3ba28f7b90da88f208a43e3c8f0bd9f7d69900ddc", "price_changes": [{"asset_id": "75087175062739028357071911202249876424512123621414420427750062298373802728902", "price": "0.12", "size": "200", "side": "BUY", "hash": "6eeb64bb33f4365b0f54b466e72d168edd94e179", "best_bid": "0.64", "best_ask": "0.69"}, {"asset_id": "51057777902653789433362935484116310785534127104787453577540080102342088856991", "price": "0.88", "size": "200", "side": "SELL", "hash": "276efe3b37241358c86746e879cdd38a53a18a53", "best_bid": "0.31", "best_ask": "0.36"}], "timestamp": "1769384646223", "event_type": "price_change"}}
{"_local_timestamp": "2026-01-25T23:44:06.505389+00:00", "data": {"market": "0xecbb7178261e45c45a2d40f3ba28f7b90da88f208a43e3c8f0bd9f7d69900ddc", "price_changes": [{"asset_id": "75087175062739028357071911202249876424512123621414420427750062298373802728902", "price": "0.13", "size": "1997.11", "side": "BUY", "hash": "4a524fbbbecfb5c0bbe87e418e081fb88f9df4b2", "best_bid": "0.64", "best_ask": "0.69"}, {"asset_id": "51057777902653789433362935484116310785534127104787453577540080102342088856991", "price": "0.87", "size": "1997.11", "side": "SELL", "hash": "95c7831d294da35c381e8b05222097540c23952f", "best_bid": "0.31", "best_ask": "0.36"}], "timestamp": "1769384646442", "event_type": "price_change"}}
{"_local_timestamp": "2026-01-25T23:44:06.546325+00:00", "data": {"market": "0xecbb7178261e45c45a2d40f3ba28f7b90da88f208a43e3c8f0bd9f7d69900ddc", "price_changes": [{"asset_id": "75087175062739028357071911202249876424512123621414420427750062298373802728902", "price": "0.14", "size": "1470.1", "side": "BUY", "hash": "79e0a0d5a5bed48dc45ba23b85fd34cac4f50136", "best_bid": "0.64", "best_ask": "0.69"}, {"asset_id": "51057777902653789433362935484116310785534127104787453577540080102342088856991", "price": "0.86", "size": "1470.1", "side": "SELL", "hash": "419631ccbd419a02cf4be8c0700d33b9cc23aba9", "best_bid": "0.31", "best_ask": "0.36"}], "timestamp": "1769384646479", "event_type": "price_change"}}
{"_local_timestamp": "2026-01-25T23:44:06.547066+00:00", "data": {"market": "0xecbb7178261e45c45a2d40f3ba28f7b90da88f208a43e3c8f0bd9f7d69900ddc", "price_changes": [{"asset_id": "75087175062739028357071911202249876424512123621414420427750062298373802728902", "price": "0.14", "size": "2360.21", "side": "BUY", "hash": "ed1d5d4431bd22660d3cc28f69b14f2611969566", "best_bid": "0.64", "best_ask": "0.69"}, {"asset_id": "51057777902653789433362935484116310785534127104787453577540080102342088856991", "price": "0.86", "size": "2360.21", "side": "SELL", "hash": "985ab880628f11b9b40ceab2de3f4f45ccc705e1", "best_bid": "0.31", "best_ask": "0.36"}], "timestamp": "1769384646480", "event_type": "price_change"}}
{"_local_timestamp": "2026-01-25T23:44:06.574104+00:00", "data": {"market": "0xecbb7178261e45c45a2d40f3ba28f7b90da88f208a43e3c8f0bd9f7d69900ddc", "price_changes": [{"asset_id": "75087175062739028357071911202249876424512123621414420427750062298373802728902", "price": "0.13", "size": "2097.11", "side": "BUY", "hash": "e1113c7c25a22c88575e33392704468d526b62c2", "best_bid": "0.64", "best_ask": "0.69"}, {"asset_id": "51057777902653789433362935484116310785534127104787453577540080102342088856991", "price": "0.87", "size": "2097.11", "side": "SELL", "hash": "4dd45ec54fdd9df7bb36c1c099dc97de0696d188", "best_bid": "0.31", "best_ask": "0.36"}], "timestamp": "1769384646505", "event_type": "price_change"}}
{"_local_timestamp": "2026-01-25T23:44:06.594424+00:00", "data": {"market": "0xecbb7178261e45c45a2d40f3ba28f7b90da88f208a43e3c8f0bd9f7d69900ddc", "price_changes": [{"asset_id": "75087175062739028357071911202249876424512123621414420427750062298373802728902", "price": "0.13", "size": "100", "side": "BUY", "hash": "87c080419838ba8ad55c1c3c110db94166856350", "best_bid": "0.64", "best_ask": "0.69"}, {"asset_id": "51057777902653789433362935484116310785534127104787453577540080102342088856991", "price": "0.87", "size": "100", "side": "SELL", "hash": "edb31004556858cccc321d33447b80f878196689", "best_bid": "0.31", "best_ask": "0.36"}], "timestamp": "1769384646527", "event_type": "price_change"}}
{"_local_timestamp": "2026-01-25T23:44:06.780110+00:00", "data": {"market": "0xecbb7178261e45c45a2d40f3ba28f7b90da88f208a43e3c8f0bd9f7d69900ddc", "price_changes": [{"asset_id": "75087175062739028357071911202249876424512123621414420427750062298373802728902", "price": "0.14", "size": "4357.32", "side": "BUY", "hash": "e600106b6b60aade45e9342c8fc923bafa4bd1ce", "best_bid": "0.64", "best_ask": "0.69"}, {"asset_id": "51057777902653789433362935484116310785534127104787453577540080102342088856991", "price": "0.86", "size": "4357.32", "side": "SELL", "hash": "224d5533774c0eaedf5c1b61925158fbdb848953", "best_bid": "0.31", "best_ask": "0.36"}], "timestamp": "1769384646715", "event_type": "price_change"}}
{"_local_timestamp": "2026-01-25T23:44:12.254858+00:00", "data": {"market": "0xecbb7178261e45c45a2d40f3ba28f7b90da88f208a43e3c8f0bd9f7d69900ddc", "price_changes": [{"asset_id": "75087175062739028357071911202249876424512123621414420427750062298373802728902", "price": "0.15", "size": "0", "side": "BUY", "hash": "3a16112f4b5b0d6e66d459ceaa098c71a60760b6", "best_bid": "0.64", "best_ask": "0.69"}, {"asset_id": "51057777902653789433362935484116310785534127104787453577540080102342088856991", "price": "0.85", "size": "0", "side": "SELL", "hash": "b27d36865c0ebf7f2384c7b23fcf5d21d348cacb", "best_bid": "0.31", "best_ask": "0.36"}], "timestamp": "1769384652190", "event_type": "price_change"}}
{"_local_timestamp": "2026-01-25T23:44:12.363810+00:00", "data": {"market": "0xecbb7178261e45c45a2d40f3ba28f7b90da88f208a43e3c8f0bd9f7d69900ddc", "price_changes": [{"asset_id": "75087175062739028357071911202249876424512123621414420427750062298373802728902", "price": "0.14", "size": "200", "side": "BUY", "hash": "1aebfb51070aa41ac3afbe745635b946936789ce", "best_bid": "0.64", "best_ask": "0.69"}, {"asset_id": "51057777902653789433362935484116310785534127104787453577540080102342088856991", "price": "0.86", "size": "200", "side": "SELL", "hash": "f278725db14b99177acebd9c8b53a39610c3113d", "best_bid": "0.31", "best_ask": "0.36"}], "timestamp": "1769384652273", "event_type": "price_change"}}
{"_local_timestamp": "2026-01-25T23:44:12.524196+00:00", "data": {"market": "0xecbb7178261e45c45a2d40f3ba28f7b90da88f208a43e3c8f0bd9f7d69900ddc", "price_changes": [{"asset_id": "75087175062739028357071911202249876424512123621414420427750062298373802728902", "price": "0.14", "size": "300", "side": "BUY", "hash": "2f5b03e0a738c8bb2ffab0ee2d3bcdd105db790c", "best_bid": "0.64", "best_ask": "0.69"}, {"asset_id": "51057777902653789433362935484116310785534127104787453577540080102342088856991", "price": "0.86", "size": "300", "side": "SELL", "hash": "36e5d2a504cd2dfb313cfa6fe37c907dc02bfbb0", "best_bid": "0.31", "best_ask": "0.36"}], "timestamp": "1769384652447", "event_type": "price_change"}}
{"_local_timestamp": "2026-01-25T23:44:18.195758+00:00", "data": {"market": "0xecbb7178261e45c45a2d40f3ba28f7b90da88f208a43e3c8f0bd9f7d69900ddc", "price_changes": [{"asset_id": "75087175062739028357071911202249876424512123621414420427750062298373802728902", "price": "0.12", "size": "100", "side": "BUY", "hash": "c72243ec613685e8dde1117a8692c3b1da80cd71", "best_bid": "0.64", "best_ask": "0.69"}, {"asset_id": "51057777902653789433362935484116310785534127104787453577540080102342088856991", "price": "0.88", "size": "100", "side": "SELL", "hash": "04ce9d616aeb625a3d63f441a090e09e3a2fd5ba", "best_bid": "0.31", "best_ask": "0.36"}], "timestamp": "1769384658003", "event_type": "price_change"}}
{"_local_timestamp": "2026-01-25T23:44:18.367933+00:00", "data": {"market": "0xecbb7178261e45c45a2d40f3ba28f7b90da88f208a43e3c8f0bd9f7d69900ddc", "price_changes": [{"asset_id": "75087175062739028357071911202249876424512123621414420427750062298373802728902", "price": "0.13", "size": "200", "side": "BUY", "hash": "1b69cc30caffead63157d3e421c73dafc0cfac0d", "best_bid": "0.64", "best_ask": "0.69"}, {"asset_id": "51057777902653789433362935484116310785534127104787453577540080102342088856991", "price": "0.87", "size": "200", "side": "SELL", "hash": "f27339359e8da9edc63c994496618b647c72057b", "best_bid": "0.31", "best_ask": "0.36"}], "timestamp": "1769384658299", "event_type": "price_change"}}
{"_local_timestamp": "2026-01-25T23:44:23.462259+00:00", "data": {"market": "0xecbb7178261e45c45a2d40f3ba28f7b90da88f208a43e3c8f0bd9f7d69900ddc", "price_changes": [{"asset_id": "75087175062739028357071911202249876424512123621414420427750062298373802728902", "price": "0.12", "size": "0", "side": "BUY", "hash": "e8dc5998b9ffa11c8421b9ee680ab49fc6949fe4", "best_bid": "0.64", "best_ask": "0.69"}, {"asset_id": "51057777902653789433362935484116310785534127104787453577540080102342088856991", "price": "0.88", "size": "0", "side": "SELL", "hash": "96712a6fcaa86588f3d59e52f6cac306791d9c31", "best_bid": "0.31", "best_ask": "0.36"}], "timestamp": "1769384663390", "event_type": "price_change"}}
{"_local_timestamp": "2026-01-25T23:44:23.734614+00:00", "data": {"market": "0xecbb7178261e45c45a2d40f3ba28f7b90da88f208a43e3c8f0bd9f7d69900ddc", "price_changes": [{"asset_id": "75087175062739028357071911202249876424512123621414420427750062298373802728902", "price": "0.13", "size": "300", "side": "BUY", "hash": "e954cf67efba73cf73dc330d299174c8cca8352e", "best_bid": "0.64", "best_ask": "0.69"}, {"asset_id": "51057777902653789433362935484116310785534127104787453577540080102342088856991", "price": "0.87", "size": "300", "side": "SELL", "hash": "aeb5e8b2a68d1896d3c80e6167a47ada890cce35", "best_bid": "0.31", "best_ask": "0.36"}], "timestamp": "1769384663667", "event_type": "price_change"}}
{"_local_timestamp": "2026-01-25T23:44:26.072725+00:00", "data": {"market": "0xc2db3c0906ac69232c4998f436e34e5df7e64b6dd2d9cb9ddd6305f2aef23c0d", "price_changes": [{"asset_id": "26283804933183319314833342421447518362320608677704153347603079425527445471777", "price": "0.56", "size": "890.11", "side": "BUY", "hash": "78d3e4eb5506a25068ebde95041d38e1c62c41b3", "best_bid": "0.57", "best_ask": "0.66"}, {"asset_id": "68765318567686557797285708330422826706843409708557814702138983780254126785177", "price": "0.44", "size": "890.11", "side": "SELL", "hash": "7167fce3c332de3d4490c9245e305fa6077f4caf", "best_bid": "0.34", "best_ask": "0.43"}], "timestamp": "1769384666000", "event_type": "price_change"}}
{"_local_timestamp": "2026-01-25T23:44:26.073521+00:00", "data": {"market": "0x171b0625db2b7f2ac2848455143776eec779ee85f6359364c1b423b23b32fc68", "price_changes": [{"asset_id": "17118621258018130257689540837975706602158094977984538267313954503349864657420", "price": "0.34", "size": "890.11", "side": "BUY", "hash": "9784d30184a44b1e69fc4405421d1cc8a5cc648f", "best_bid": "0.35", "best_ask": "0.44"}, {"asset_id": "110208037745521376477218629625161726044793864281199315926557875582085019919669", "price": "0.66", "size": "890.11", "side": "SELL", "hash": "830d90544633fdd5457360a636153e549b7615f9", "best_bid": "0.56", "best_ask": "0.65"}], "timestamp": "1769384666000", "event_type": "price_change"}}
{"_local_timestamp": "2026-01-25T23:44:26.079163+00:00", "data": {"market": "0x15beb6ee455f9837b69cd7dcd110770b2f489d88651e4ffb21cd54f617a23e04", "price_changes": [{"asset_id": "44868850067599122384522819337153865676781090849621105309651139851616912647528", "price": "0.48", "size": "0", "side": "BUY", "hash": "292ccf812999f72b3c5d5901de97e34e67827460", "best_bid": "0.02", "best_ask": "0.58"}, {"asset_id": "14205737424716982918858761268248742215558565679165887656230879609115111732505", "price": "0.52", "size": "0", "side": "SELL", "hash": "4e1e91765b7a446c1b7b179f92b550a310577a42", "best_bid": "0.42", "best_ask": "0.98"}], "timestamp": "1769384666000", "event_type": "price_change"}}
{"_local_timestamp": "2026-01-25T23:44:26.081979+00:00", "data": {"market": "0xecbb7178261e45c45a2d40f3ba28f7b90da88f208a43e3c8f0bd9f7d69900ddc", "price_changes": [{"asset_id": "51057777902653789433362935484116310785534127104787453577540080102342088856991", "price": "0.28", "size": "0", "side": "BUY", "hash": "78df42efc73801f8b434a29cb944471cdac503f1", "best_bid": "0.31", "best_ask": "0.36"}, {"asset_id": "75087175062739028357071911202249876424512123621414420427750062298373802728902", "price": "0.72", "size": "0", "side": "SELL", "hash": "27493b2e4276a4c3ea56b9f659f212115cd5d13c", "best_bid": "0.64", "best_ask": "0.69"}], "timestamp": "1769384666000", "event_type": "price_change"}}
{"_local_timestamp": "2026-01-25T23:44:26.086061+00:00", "data": {"market": "0xc2db3c0906ac69232c4998f436e34e5df7e64b6dd2d9cb9ddd6305f2aef23c0d", "price_changes": [{"asset_id": "68765318567686557797285708330422826706843409708557814702138983780254126785177", "price": "0.33", "size": "890.11", "side": "BUY", "hash": "8d77336d8bbe7a0ebacb1138886c94de9dfd7305", "best_bid": "0.34", "best_ask": "0.43"}, {"asset_id": "26283804933183319314833342421447518362320608677704153347603079425527445471777", "price": "0.67", "size": "890.11", "side": "SELL", "hash": "35888ec8ae23ed61e22bc567d8134a0038254b17", "best_bid": "0.57", "best_ask": "0.66"}], "timestamp": "1769384666004", "event_type": "price_change"}}
{"_local_timestamp": "2026-01-25T23:44:26.086714+00:00", "data": {"market": "0x171b0625db2b7f2ac2848455143776eec779ee85f6359364c1b423b23b32fc68", "price_changes": [{"asset_id": "110208037745521376477218629625161726044793864281199315926557875582085019919669", "price": "0.55", "size": "890.11", "side": "BUY", "hash": "a109231b9deb37006eb92a267ce072092a83afaa", "best_bid": "0.56", "best_ask": "0.65"}, {"asset_id": "17118621258018130257689540837975706602158094977984538267313954503349864657420", "price": "0.45", "size": "890.11", "side": "SELL", "hash": "64a3efbe57f76a2c67c677cbe5afb9160ff671c8", "best_bid": "0.35", "best_ask": "0.44"}], "timestamp": "1769384666004", "event_type": "price_change"}}
{"_local_timestamp": "2026-01-25T23:44:26.096553+00:00", "data": {"market": "0xecbb7178261e45c45a2d40f3ba28f7b90da88f208a43e3c8f0bd9f7d69900ddc", "price_changes": [{"asset_id": "75087175062739028357071911202249876424512123621414420427750062298373802728902", "price": "0.6", "size": "890.11", "side": "BUY", "hash": "b18d5bf6218b49dd11e0cde1ea38bacf43000167", "best_bid": "0.64", "best_ask": "0.69"}, {"asset_id": "51057777902653789433362935484116310785534127104787453577540080102342088856991", "price": "0.4", "size": "890.11", "side": "SELL", "hash": "846891e4cc00c3ab94c44baeaca7e7540e1c2772", "best_bid": "0.31", "best_ask": "0.36"}], "timestamp": "1769384666005", "event_type": "price_change"}}
{"_local_timestamp": "2026-01-25T23:44:26.097201+00:00", "data": {"market": "0x15beb6ee455f9837b69cd7dcd110770b2f489d88651e4ffb21cd54f617a23e04", "price_changes": [{"asset_id": "14205737424716982918858761268248742215558565679165887656230879609115111732505", "price": "0.42", "size": "0", "side": "BUY", "hash": "ac7b4b4b165bcbeba857d7f22ef9c7990d0e413d", "best_bid": "0.02", "best_ask": "0.98"}, {"asset_id": "44868850067599122384522819337153865676781090849621105309651139851616912647528", "price": "0.58", "size": "0", "side": "SELL", "hash": "49fcfc3ba36088e0d5af67e950f1ad9f3f40956f", "best_bid": "0.02", "best_ask": "0.98"}], "timestamp": "1769384666005", "event_type": "price_change"}}
{"_local_timestamp": "2026-01-25T23:44:26.186450+00:00", "data": {"market": "0xc2db3c0906ac69232c4998f436e34e5df7e64b6dd2d9cb9ddd6305f2aef23c0d", "price_changes": [{"asset_id": "26283804933183319314833342421447518362320608677704153347603079425527445471777", "price": "0.06", "size": "12.77", "side": "BUY", "hash": "c486f771a297456ab5cf3c872b7ffab89ece5387", "best_bid": "0.57", "best_ask": "0.66"}, {"asset_id": "68765318567686557797285708330422826706843409708557814702138983780254126785177", "price": "0.94", "size": "12.77", "side": "SELL", "hash": "68d3e171128a373d904cce32075ad7719532822d", "best_bid": "0.34", "best_ask": "0.43"}], "timestamp": "1769384666115", "event_type": "price_change"}}
{"_local_timestamp": "2026-01-25T23:44:26.187163+00:00", "data": {"market": "0x171b0625db2b7f2ac2848455143776eec779ee85f6359364c1b423b23b32fc68", "price_changes": [{"asset_id": "110208037745521376477218629625161726044793864281199315926557875582085019919669", "price": "0.01", "size": "7184.11", "side": "BUY", "hash": "38fbca6961d9d83dacd429e839a577db69b88353", "best_bid": "0.56", "best_ask": "0.65"}, {"asset_id": "17118621258018130257689540837975706602158094977984538267313954503349864657420", "price": "0.99", "size": "7184.11", "side": "SELL", "hash": "b52746d2d594d112814812196c2af58d67a34bd5", "best_bid": "0.35", "best_ask": "0.44"}], "timestamp": "1769384666115", "event_type": "price_change"}}
{"_local_timestamp": "2026-01-25T23:44:26.207832+00:00", "data": {"market": "0x171b0625db2b7f2ac2848455143776eec779ee85f6359364c1b423b23b32fc68", "price_changes": [{"asset_id": "110208037745521376477218629625161726044793864281199315926557875582085019919669", "price": "0.02", "size": "4166.48", "side": "BUY", "hash": "38fbca6961d9d83dacd429e839a577db69b88353", "best_bid": "0.56", "best_ask": "0.65"}, {"asset_id": "17118621258018130257689540837975706602158094977984538267313954503349864657420", "price": "0.98", "size": "4166.48", "side": "SELL", "hash": "b52746d2d594d112814812196c2af58d67a34bd5", "best_bid": "0.35", "best_ask": "0.44"}], "timestamp": "1769384666115", "event_type": "price_change"}}
{"_local_timestamp": "2026-01-25T23:44:26.208526+00:00", "data": {"market": "0x171b0625db2b7f2ac2848455143776eec779ee85f6359364c1b423b23b32fc68", "price_changes": [{"asset_id": "17118621258018130257689540837975706602158094977984538267313954503349864657420", "price": "0.01", "size": "8074.39", "side": "BUY", "hash": "78806f2b299568881f451ae509430ec3a75b0278", "best_bid": "0.35", "best_ask": "0.44"}, {"asset_id": "110208037745521376477218629625161726044793864281199315926557875582085019919669", "price": "0.99", "size": "8074.39", "side": "SELL", "hash": "fe6c5444b1bca3a807661642a30c09a725858a11", "best_bid": "0.56", "best_ask": "0.65"}], "timestamp": "1769384666115", "event_type": "price_change"}}
{"_local_timestamp": "2026-01-25T23:44:26.252216+00:00", "data": {"market": "0xc2db3c0906ac69232c4998f436e34e5df7e64b6dd2d9cb9ddd6305f2aef23c0d", "price_changes": [{"asset_id": "26283804933183319314833342421447518362320608677704153347603079425527445471777", "price": "0.07", "size": "5999.11", "side": "BUY", "hash": "86f9b431e48b3f76519203063fdee2a5e0e40fb4", "best_bid": "0.57", "best_ask": "0.66"}, {"asset_id": "68765318567686557797285708330422826706843409708557814702138983780254126785177", "price": "0.93", "size": "5999.11", "side": "SELL", "hash": "8ae56813ceb79f37eb1a52874bc28790ba21f055", "best_bid": "0.34", "best_ask": "0.43"}], "timestamp": "1769384666181", "event_type": "price_change"}}
{"_local_timestamp": "2026-01-25T23:44:26.252995+00:00", "data": {"market": "0xc2db3c0906ac69232c4998f436e34e5df7e64b6dd2d9cb9ddd6305f2aef23c0d", "price_changes": [{"asset_id": "26283804933183319314833342421447518362320608677704153347603079425527445471777", "price": "0.07", "size": "6889.22", "side": "BUY", "hash": "59f8110b1d87070772bf55753736892fa13b19f3", "best_bid": "0.57", "best_ask": "0.66"}, {"asset_id": "68765318567686557797285708330422826706843409708557814702138983780254126785177", "price": "0.93", "size": "6889.22", "side": "SELL", "hash": "c8983786c0fec403864bd110b91360ddbc169fb3", "best_bid": "0.34", "best_ask": "0.43"}], "timestamp": "1769384666182", "event_type": "price_change"}}
{"_local_timestamp": "2026-01-25T23:44:26.253687+00:00", "data": {"market": "0xc2db3c0906ac69232c4998f436e34e5df7e64b6dd2d9cb9ddd6305f2aef23c0d", "price_changes": [{"asset_id": "68765318567686557797285708330422826706843409708557814702138983780254126785177", "price": "0.01", "size": "8074.33", "side": "BUY", "hash": "5df4446a4010cd717d98696b3c11686af351facb", "best_bid": "0.34", "best_ask": "0.43"}, {"asset_id": "26283804933183319314833342421447518362320608677704153347603079425527445471777", "price": "0.99", "size": "8074.33", "side": "SELL", "hash": "b79ee48c3079f736e92f644161725d100493e7ca", "best_bid": "0.57", "best_ask": "0.66"}], "timestamp": "1769384666182", "event_type": "price_change"}}
{"_local_timestamp": "2026-01-25T23:44:26.254345+00:00", "data": {"market": "0xc2db3c0906ac69232c4998f436e34e5df7e64b6dd2d9cb9ddd6305f2aef23c0d", "price_changes": [{"asset_id": "68765318567686557797285708330422826706843409708557814702138983780254126785177", "price": "0.02", "size": "5047.43", "side": "BUY", "hash": "f127b3c90619deac4d2896c8351d83d5bb7cbaf6", "best_bid": "0.34", "best_ask": "0.43"}, {"asset_id": "26283804933183319314833342421447518362320608677704153347603079425527445471777", "price": "0.98", "size": "5047.43", "side": "SELL", "hash": "2daffb57466fc6b57e664238691cfefcb1b04a46", "best_bid": "0.57", "best_ask": "0.66"}], "timestamp": "1769384666183", "event_type": "price_change"}}
{"_local_timestamp": "2026-01-25T23:44:26.255011+00:00", "data": {"market": "0xc2db3c0906ac69232c4998f436e34e5df7e64b6dd2d9cb9ddd6305f2aef23c0d", "price_changes": [{"asset_id": "26283804933183319314833342421447518362320608677704153347603079425527445471777", "price": "0.07", "size": "8159.32", "side": "BUY", "hash": "c01dbd644c0da9559203f8f3538a06c453f1e4ce", "best_bid": "0.57", "best_ask": "0.66"}, {"asset_id": "68765318567686557797285708330422826706843409708557814702138983780254126785177", "price": "0.93", "size": "8159.32", "side": "SELL", "hash": "ccbbe63f5cdf50e355db825005a7518dfb1294a8", "best_bid": "0.34", "best_ask": "0.43"}], "timestamp": "1769384666184", "event_type": "price_change"}}
{"_local_timestamp": "2026-01-25T23:44:26.255664+00:00", "data": {"market": "0xc2db3c0906ac69232c4998f436e34e5df7e64b6dd2d9cb9ddd6305f2aef23c0d", "price_changes": [{"asset_id": "26283804933183319314833342421447518362320608677704153347603079425527445471777", "price": "0.07", "size": "9049.43", "side": "BUY", "hash": "7c2dc034ae0f31bf955e6b960081243dc2bd704f", "best_bid": "0.57", "best_ask": "0.66"}, {"asset_id": "68765318567686557797285708330422826706843409708557814702138983780254126785177", "price": "0.93", "size": "9049.43", "side": "SELL", "hash": "e5eba8f6e506387886fd55ebff860c53b8176074", "best_bid": "0.34", "best_ask": "0.43"}], "timestamp": "1769384666184", "event_type": "price_change"}}
{"_local_timestamp": "2026-01-25T23:44:26.256321+00:00", "data": {"market": "0xc2db3c0906ac69232c4998f436e34e5df7e64b6dd2d9cb9ddd6305f2aef23c0d", "price_changes": [{"asset_id": "26283804933183319314833342421447518362320608677704153347603079425527445471777", "price": "0.07", "size": "11046.54", "side": "BUY", "hash": "54a05def8c335025bf7f0a077703755d3d5fd7dc", "best_bid": "0.57", "best_ask": "0.66"}, {"asset_id": "68765318567686557797285708330422826706843409708557814702138983780254126785177", "price": "0.93", "size": "11046.54", "side": "SELL", "hash": "2fcdae7d23d38ef8a2efed99d210e3007812338b", "best_bid": "0.34", "best_ask": "0.43"}], "timestamp": "1769384666185", "event_type": "price_change"}}
{"_local_timestamp": "2026-01-25T23:44:26.294478+00:00", "data": {"market": "0xc2db3c0906ac69232c4998f436e34e5df7e64b6dd2d9cb9ddd6305f2aef23c0d", "price_changes": [{"asset_id": "26283804933183319314833342421447518362320608677704153347603079425527445471777", "price": "0.06", "size": "902.88", "side": "BUY", "hash": "d0ff0910eff8965bbe65de8afc21f7cf71a519bc", "best_bid": "0.57", "best_ask": "0.66"}, {"asset_id": "68765318567686557797285708330422826706843409708557814702138983780254126785177", "price": "0.94", "size": "902.88", "side": "SELL", "hash": "ae473bc4941a0a81fb8a5399f537015b32595cd3", "best_bid": "0.34", "best_ask": "0.43"}], "timestamp": "1769384666228", "event_type": "price_change"}}
{"_local_timestamp": "2026-01-25T23:44:26.332485+00:00", "data": {"market": "0x171b0625db2b7f2ac2848455143776eec779ee85f6359364c1b423b23b32fc68", "price_changes": [{"asset_id": "110208037745521376477218629625161726044793864281199315926557875582085019919669", "price": "0.02", "size": "10165.59", "side": "BUY", "hash": "21717a996d6acbc0f9a1440207bd09d7dbb334e0", "best_bid": "0.56", "best_ask": "0.65"}, {"asset_id": "17118621258018130257689540837975706602158094977984538267313954503349864657420", "price": "0.98", "size": "10165.59", "side": "SELL", "hash": "be4c002f1a0ece0cd1b6d18a1fe51c61df02f8c8", "best_bid": "0.35", "best_ask": "0.44"}], "timestamp": "1769384666264", "event_type": "price_change"}}
{"_local_timestamp": "2026-01-25T23:44:26.335381+00:00", "data": {"market": "0x171b0625db2b7f2ac2848455143776eec779ee85f6359364c1b423b23b32fc68", "price_changes": [{"asset_id": "110208037745521376477218629625161726044793864281199315926557875582085019919669", "price": "0.03", "size": "890.11", "side": "BUY", "hash": "09060f3642fa7d2ac7dfd7fb4fc2f9f974ce5be7", "best_bid": "0.56", "best_ask": "0.65"}, {"asset_id": "17118621258018130257689540837975706602158094977984538267313954503349864657420", "price": "0.97", "size": "890.11", "side": "SELL", "hash": "a41016a854535db111281370ab1fd8a5396ffa75", "best_bid": "0.35", "best_ask": "0.44"}], "timestamp": "1769384666264", "event_type": "price_change"}}
{"_local_timestamp": "2026-01-25T23:44:26.364325+00:00", "data": {"market": "0x171b0625db2b7f2ac2848455143776eec779ee85f6359364c1b423b23b32fc68", "price_changes": [{"asset_id": "110208037745521376477218629625161726044793864281199315926557875582085019919669", "price": "0.03", "size": "1780.22", "side": "BUY", "hash": "7d1a023a7aafda5cfcb4bb87a6afb7f6d764e22c", "best_bid": "0.56", "best_ask": "0.65"}, {"asset_id": "17118621258018130257689540837975706602158094977984538267313954503349864657420", "price": "0.97", "size": "1780.22", "side": "SELL", "hash": "94883d5caf72880e0304bc01443d4c90992d55dd", "best_bid": "0.35", "best_ask": "0.44"}], "timestamp": "1769384666294", "event_type": "price_change"}}
{"_local_timestamp": "2026-01-25T23:44:26.365239+00:00", "data": {"market": "0x171b0625db2b7f2ac2848455143776eec779ee85f6359364c1b423b23b32fc68", "price_changes": [{"asset_id": "17118621258018130257689540837975706602158094977984538267313954503349864657420", "price": "0.02", "size": "11046.54", "side": "BUY", "hash": "dd08f425700a035030e43b55c2b893836f0fe8dd", "best_bid": "0.35", "best_ask": "0.44"}, {"asset_id": "110208037745521376477218629625161726044793864281199315926557875582085019919669", "price": "0.98", "size": "11046.54", "side": "SELL", "hash": "1bf6ba12c0c22b924428a2fd9dbce1641631beeb", "best_bid": "0.56", "best_ask": "0.65"}], "timestamp": "1769384666295", "event_type": "price_change"}}
{"_local_timestamp": "2026-01-25T23:44:26.366113+00:00", "data": {"market": "0x171b0625db2b7f2ac2848455143776eec779ee85f6359364c1b423b23b32fc68", "price_changes": [{"asset_id": "110208037745521376477218629625161726044793864281199315926557875582085019919669", "price": "0.03", "size": "3050.32", "side": "BUY", "hash": "d55d826da5cf35a8cbfbb97876f14a99be110ee9", "best_bid": "0.56", "best_ask": "0.65"}, {"asset_id": "17118621258018130257689540837975706602158094977984538267313954503349864657420", "price": "0.97", "size": "3050.32", "side": "SELL", "hash": "efdeb0f534dcf37ef7e001eb3f1309b556a1860d", "best_bid": "0.35", "best_ask": "0.44"}], "timestamp": "1769384666296", "event_type": "price_change"}}
{"_local_timestamp": "2026-01-25T23:44:26.366888+00:00", "data": {"market": "0x171b0625db2b7f2ac2848455143776eec779ee85f6359364c1b423b23b32fc68", "price_changes": [{"asset_id": "110208037745521376477218629625161726044793864281199315926557875582085019919669", "price": "0.02", "size": "11055.7", "side": "BUY", "hash": "90b88e3a5e04213a3b2428cae237106cb18faecb", "best_bid": "0.56", "best_ask": "0.65"}, {"asset_id": "17118621258018130257689540837975706602158094977984538267313954503349864657420", "price": "0.98", "size": "11055.7", "side": "SELL", "hash": "389e4c0291d601a965b0d13d528047dfdc41df9b", "best_bid": "0.35", "best_ask": "0.44"}], "timestamp": "1769384666296", "event_type": "price_change"}}
{"_local_timestamp": "2026-01-25T23:44:26.367646+00:00", "data": {"market": "0x171b0625db2b7f2ac2848455143776eec779ee85f6359364c1b423b23b32fc68", "price_changes": [{"asset_id": "110208037745521376477218629625161726044793864281199315926557875582085019919669", "price": "0.03", "size": "5047.43", "side": "BUY", "hash": "ed4dbb2865588f0c54f83b6a49f91a37b7733c54", "best_bid": "0.56", "best_ask": "0.65"}, {"asset_id": "17118621258018130257689540837975706602158094977984538267313954503349864657420", "price": "0.97", "size": "5047.43", "side": "SELL", "hash": "06f2d04a7a97783403bd415631025ed0531c2c79", "best_bid": "0.35", "best_ask": "0.44"}], "timestamp": "1769384666297", "event_type": "price_change"}}
{"_local_timestamp": "2026-01-25T23:44:26.390487+00:00", "data": {"market": "0xecbb7178261e45c45a2d40f3ba28f7b90da88f208a43e3c8f0bd9f7d69900ddc", "price_changes": [{"asset_id": "75087175062739028357071911202249876424512123621414420427750062298373802728902", "price": "0.15", "size": "890.11", "side": "BUY", "hash": "a85a4f13d131f0e4b2d334d9606ddb4d1709c53e", "best_bid": "0.64", "best_ask": "0.69"}, {"asset_id": "51057777902653789433362935484116310785534127104787453577540080102342088856991", "price": "0.85", "size": "890.11", "side": "SELL", "hash": "281dd445b6b8b922d02b0fef0103a6ec11b454e8", "best_bid": "0.31", "best_ask": "0.36"}], "timestamp": "1769384666325", "event_type": "price_change"}}
{"_local_timestamp": "2026-01-25T23:44:26.398447+00:00", "data": {"market": "0xecbb7178261e45c45a2d40f3ba28f7b90da88f208a43e3c8f0bd9f7d69900ddc", "price_changes": [{"asset_id": "75087175062739028357071911202249876424512123621414420427750062298373802728902", "price": "0.14", "size": "1190.11", "side": "BUY", "hash": "35ff3278c950338abee03340471bd69de4beef26", "best_bid": "0.64", "best_ask": "0.69"}, {"asset_id": "51057777902653789433362935484116310785534127104787453577540080102342088856991", "price": "0.86", "size": "1190.11", "side": "SELL", "hash": "31a910cb5b5aa439b21ce2bb2cc86322bdc70b0a", "best_bid": "0.31", "best_ask": "0.36"}], "timestamp": "1769384666326", "event_type": "price_change"}}
{"_local_timestamp": "2026-01-25T23:44:27.035628+00:00", "data": {"market": "0x15beb6ee455f9837b69cd7dcd110770b2f489d88651e4ffb21cd54f617a23e04", "price_changes": [{"asset_id": "14205737424716982918858761268248742215558565679165887656230879609115111732505", "price": "0.42", "size": "500", "side": "BUY", "hash": "708aead3c373c56808922d5ea49dcbb7ca5ef0d3", "best_bid": "0.42", "best_ask": "0.98"}, {"asset_id": "44868850067599122384522819337153865676781090849621105309651139851616912647528", "price": "0.58", "size": "500", "side": "SELL", "hash": "2e0669fc297b22ad0ff9bdf2d85f4dabb0edcd6a", "best_bid": "0.02", "best_ask": "0.58"}], "timestamp": "1769384666930", "event_type": "price_change"}}
{"_local_timestamp": "2026-01-25T23:44:27.066232+00:00", "data": {"market": "0x171b0625db2b7f2ac2848455143776eec779ee85f6359364c1b423b23b32fc68", "price_changes": [{"asset_id": "110208037745521376477218629625161726044793864281199315926557875582085019919669", "price": "0.55", "size": "1390.11", "side": "BUY", "hash": "02ae1c822ced06940bf47d8e4acfef18eb16371b", "best_bid": "0.56", "best_ask": "0.65"}, {"asset_id": "17118621258018130257689540837975706602158094977984538267313954503349864657420", "price": "0.45", "size": "1390.11", "side": "SELL", "hash": "b589202cd04e5b44a8901420cb87a4e858976c24", "best_bid": "0.35", "best_ask": "0.44"}], "timestamp": "1769384666933", "event_type": "price_change"}}
{"_local_timestamp": "2026-01-25T23:44:27.074077+00:00", "data": {"market": "0xecbb7178261e45c45a2d40f3ba28f7b90da88f208a43e3c8f0bd9f7d69900ddc", "price_changes": [{"asset_id": "51057777902653789433362935484116310785534127104787453577540080102342088856991", "price": "0.28", "size": "1000", "side": "BUY", "hash": "54e530052c57d48c9ef858d9a2c8e386f083f71d", "best_bid": "0.31", "best_ask": "0.36"}, {"asset_id": "75087175062739028357071911202249876424512123621414420427750062298373802728902", "price": "0.72", "size": "1000", "side": "SELL", "hash": "f2e3b7d14d26b18f4a1e6046339cd6d198738c2c", "best_bid": "0.64", "best_ask": "0.69"}], "timestamp": "1769384666933", "event_type": "price_change"}}
{"_local_timestamp": "2026-01-25T23:44:27.079918+00:00", "data": {"market": "0xecbb7178261e45c45a2d40f3ba28f7b90da88f208a43e3c8f0bd9f7d69900ddc", "price_changes": [{"asset_id": "75087175062739028357071911202249876424512123621414420427750062298373802728902", "price": "0.6", "size": "1890.11", "side": "BUY", "hash": "2e9d6227ca5f5421022de55cecb5bf14933bb8a9", "best_bid": "0.64", "best_ask": "0.69"}, {"asset_id": "51057777902653789433362935484116310785534127104787453577540080102342088856991", "price": "0.4", "size": "1890.11", "side": "SELL", "hash": "be71df7b737d96d50c982a0b787c60264660356e", "best_bid": "0.31", "best_ask": "0.36"}], "timestamp": "1769384666934", "event_type": "price_change"}}
{"_local_timestamp": "2026-01-25T23:44:27.080767+00:00", "data": {"market": "0x15beb6ee455f9837b69cd7dcd110770b2f489d88651e4ffb21cd54f617a23e04", "price_changes": [{"asset_id": "44868850067599122384522819337153865676781090849621105309651139851616912647528", "price": "0.48", "size": "500", "side": "BUY", "hash": "3e5740d3a13d779260d021d7548ea0d07885471f", "best_bid": "0.48", "best_ask": "0.58"}, {"asset_id": "14205737424716982918858761268248742215558565679165887656230879609115111732505", "price": "0.52", "size": "500", "side": "SELL", "hash": "9725b8461f23ce5ccda7e701bd7657f5eed992ae", "best_bid": "0.42", "best_ask": "0.52"}], "timestamp": "1769384666934", "event_type": "price_change"}}
{"_local_timestamp": "2026-01-25T23:44:27.083260+00:00", "data": {"market": "0xc2db3c0906ac69232c4998f436e34e5df7e64b6dd2d9cb9ddd6305f2aef23c0d", "price_changes": [{"asset_id": "68765318567686557797285708330422826706843409708557814702138983780254126785177", "price": "0.33", "size": "1390.11", "side": "BUY", "hash": "7af747ced7e4e167883def1b571246a105292cca", "best_bid": "0.34", "best_ask": "0.43"}, {"asset_id": "26283804933183319314833342421447518362320608677704153347603079425527445471777", "price": "0.67", "size": "1390.11", "side": "SELL", "hash": "717d96eff94c22f7abc8ec34e7cefa949544ea37", "best_bid": "0.57", "best_ask": "0.66"}], "timestamp": "1769384666935", "event_type": "price_change"}}
{"_local_timestamp": "2026-01-25T23:44:27.086264+00:00", "data": {"market": "0x171b0625db2b7f2ac2848455143776eec779ee85f6359364c1b423b23b32fc68", "price_changes": [{"asset_id": "17118621258018130257689540837975706602158094977984538267313954503349864657420", "price": "0.34", "size": "1390.11", "side": "BUY", "hash": "80f5e3518104a4eecbf068c9f0e5f07b716302ad", "best_bid": "0.35", "best_ask": "0.44"}, {"asset_id": "110208037745521376477218629625161726044793864281199315926557875582085019919669", "price": "0.66", "size": "1390.11", "side": "SELL", "hash": "4243665fc5f78ce9202fa726fee445e8bcbf7425", "best_bid": "0.56", "best_ask": "0.65"}], "timestamp": "1769384666935", "event_type": "price_change"}}
{"_local_timestamp": "2026-01-25T23:44:27.089987+00:00", "data": {"market": "0xc2db3c0906ac69232c4998f436e34e5df7e64b6dd2d9cb9ddd6305f2aef23c0d", "price_changes": [{"asset_id": "26283804933183319314833342421447518362320608677704153347603079425527445471777", "price": "0.56", "size": "1390.11", "side": "BUY", "hash": "e9ae5fa5f2a07d5dae030323253c5c24512d1b23", "best_bid": "0.57", "best_ask": "0.66"}, {"asset_id": "68765318567686557797285708330422826706843409708557814702138983780254126785177", "price": "0.44", "size": "1390.11", "side": "SELL", "hash": "783960a25bb4f9e286d43e057b05c3a77d6890f4", "best_bid": "0.34", "best_ask": "0.43"}], "timestamp": "1769384666936", "event_type": "price_change"}}
{"_local_timestamp": "2026-01-25T23:44:27.091179+00:00", "data": {"market": "0xecbb7178261e45c45a2d40f3ba28f7b90da88f208a43e3c8f0bd9f7d69900ddc", "price_changes": [{"asset_id": "75087175062739028357071911202249876424512123621414420427750062298373802728902", "price": "0.13", "size": "200", "side": "BUY", "hash": "cbcdbd9d2aa833955bb9ad22095b70da1b77ae79", "best_bid": "0.64", "best_ask": "0.69"}, {"asset_id": "51057777902653789433362935484116310785534127104787453577540080102342088856991", "price": "0.87", "size": "200", "side": "SELL", "hash": "d8abe1c8c700b3546b8d91b30cdbeeee77c669d2", "best_bid": "0.31", "best_ask": "0.36"}], "timestamp": "1769384666975", "event_type": "price_change"}}
{"_local_timestamp": "2026-01-25T23:44:27.305124+00:00", "data": {"market": "0xecbb7178261e45c45a2d40f3ba28f7b90da88f208a43e3c8f0bd9f7d69900ddc", "price_changes": [{"asset_id": "75087175062739028357071911202249876424512123621414420427750062298373802728902", "price": "0.08", "size": "4657.32", "side": "BUY", "hash": "499f90ed8cedac8ef4c187ec103dd7fe341868bb", "best_bid": "0.64", "best_ask": "0.69"}, {"asset_id": "51057777902653789433362935484116310785534127104787453577540080102342088856991", "price": "0.92", "size": "4657.32", "side": "SELL", "hash": "66594a25957edc4e712c441a151fac6a3fd74445", "best_bid": "0.31", "best_ask": "0.36"}], "timestamp": "1769384667235", "event_type": "price_change"}}
{"_local_timestamp": "2026-01-25T23:44:35.811413+00:00", "data": {"market": "0xecbb7178261e45c45a2d40f3ba28f7b90da88f208a43e3c8f0bd9f7d69900ddc", "price_changes": [{"asset_id": "75087175062739028357071911202249876424512123621414420427750062298373802728902", "price": "0.14", "size": "1090.11", "side": "BUY", "hash": "26e07e659d77e5ff6dfbfa0b8698c89e1419a2ae", "best_bid": "0.64", "best_ask": "0.69"}, {"asset_id": "51057777902653789433362935484116310785534127104787453577540080102342088856991", "price": "0.86", "size": "1090.11", "side": "SELL", "hash": "9887fe423a435e73f53cc5765e78fd6ac622c34c", "best_bid": "0.31", "best_ask": "0.36"}], "timestamp": "1769384675739", "event_type": "price_change"}}
{"_local_timestamp": "2026-01-25T23:44:35.881253+00:00", "data": {"market": "0xecbb7178261e45c45a2d40f3ba28f7b90da88f208a43e3c8f0bd9f7d69900ddc", "price_changes": [{"asset_id": "75087175062739028357071911202249876424512123621414420427750062298373802728902", "price": "0.15", "size": "0", "side": "BUY", "hash": "b4861cfdcc612d33efe434ba873e5ff8613e396e", "best_bid": "0.64", "best_ask": "0.69"}, {"asset_id": "51057777902653789433362935484116310785534127104787453577540080102342088856991", "price": "0.85", "size": "0", "side": "SELL", "hash": "e19659977121796f422e25e46f9f4bc12aca2e08", "best_bid": "0.31", "best_ask": "0.36"}], "timestamp": "1769384675806", "event_type": "price_change"}}
{"_local_timestamp": "2026-01-25T23:44:35.882074+00:00", "data": {"market": "0xecbb7178261e45c45a2d40f3ba28f7b90da88f208a43e3c8f0bd9f7d69900ddc", "price_changes": [{"asset_id": "75087175062739028357071911202249876424512123621414420427750062298373802728902", "price": "0.14", "size": "200", "side": "BUY", "hash": "b4861cfdcc612d33efe434ba873e5ff8613e396e", "best_bid": "0.64", "best_ask": "0.69"}, {"asset_id": "51057777902653789433362935484116310785534127104787453577540080102342088856991", "price": "0.86", "size": "200", "side": "SELL", "hash": "e19659977121796f422e25e46f9f4bc12aca2e08", "best_bid": "0.31", "best_ask": "0.36"}], "timestamp": "1769384675806", "event_type": "price_change"}}
{"_local_timestamp": "2026-01-25T23:44:36.040752+00:00", "data": {"market": "0xecbb7178261e45c45a2d40f3ba28f7b90da88f208a43e3c8f0bd9f7d69900ddc", "price_changes": [{"asset_id": "75087175062739028357071911202249876424512123621414420427750062298373802728902", "price": "0.15", "size": "100", "side": "BUY", "hash": "0cf51555a593a8cb02f5e539a3a8f9ee24f14316", "best_bid": "0.64", "best_ask": "0.69"}, {"asset_id": "51057777902653789433362935484116310785534127104787453577540080102342088856991", "price": "0.85", "size": "100", "side": "SELL", "hash": "c8199845effc3423b430d7903e519ccbe86cf08b", "best_bid": "0.31", "best_ask": "0.36"}], "timestamp": "1769384675969", "event_type": "price_change"}}
{"_local_timestamp": "2026-01-25T23:44:48.339767+00:00", "data": {"market": "0xecbb7178261e45c45a2d40f3ba28f7b90da88f208a43e3c8f0bd9f7d69900ddc", "price_changes": [{"asset_id": "75087175062739028357071911202249876424512123621414420427750062298373802728902", "price": "0.15", "size": "0", "side": "BUY", "hash": "e8567b371d0e1744abb7cee8dc9c6e557e230dbc", "best_bid": "0.64", "best_ask": "0.69"}, {"asset_id": "51057777902653789433362935484116310785534127104787453577540080102342088856991", "price": "0.85", "size": "0", "side": "SELL", "hash": "2dd4a9901289af71d99beaa6ebc6af7d1f01b6bc", "best_bid": "0.31", "best_ask": "0.36"}], "timestamp": "1769384688262", "event_type": "price_change"}}
{"_local_timestamp": "2026-01-25T23:44:48.612402+00:00", "data": {"market": "0xecbb7178261e45c45a2d40f3ba28f7b90da88f208a43e3c8f0bd9f7d69900ddc", "price_changes": [{"asset_id": "75087175062739028357071911202249876424512123621414420427750062298373802728902", "price": "0.14", "size": "300", "side": "BUY", "hash": "9ba4da625f207be8f3091e25c6ffd3f090d5549c", "best_bid": "0.64", "best_ask": "0.69"}, {"asset_id": "51057777902653789433362935484116310785534127104787453577540080102342088856991", "price": "0.86", "size": "300", "side": "SELL", "hash": "cda7d8c3a9b950ee2c569a0f6de4dd62c1e52905", "best_bid": "0.31", "best_ask": "0.36"}], "timestamp": "1769384688499", "event_type": "price_change"}}
{"_local_timestamp": "2026-01-25T23:44:52.439939+00:00", "data": {"market": "0xecbb7178261e45c45a2d40f3ba28f7b90da88f208a43e3c8f0bd9f7d69900ddc", "price_changes": [{"asset_id": "75087175062739028357071911202249876424512123621414420427750062298373802728902", "price": "0.13", "size": "100", "side": "BUY", "hash": "7f9bc78539996877f5ebaaa5fb2ec653ee0c083a", "best_bid": "0.64", "best_ask": "0.69"}, {"asset_id": "51057777902653789433362935484116310785534127104787453577540080102342088856991", "price": "0.87", "size": "100", "side": "SELL", "hash": "da7ee253c33c4257ffefd926787a014a83577052", "best_bid": "0.31", "best_ask": "0.36"}], "timestamp": "1769384692371", "event_type": "price_change"}}
{"_local_timestamp": "2026-01-25T23:44:52.494894+00:00", "data": {"market": "0xecbb7178261e45c45a2d40f3ba28f7b90da88f208a43e3c8f0bd9f7d69900ddc", "price_changes": [{"asset_id": "75087175062739028357071911202249876424512123621414420427750062298373802728902", "price": "0.13", "size": "0", "side": "BUY", "hash": "48aaae164f5130210f455ba8a1639ab62007ff86", "best_bid": "0.64", "best_ask": "0.69"}, {"asset_id": "51057777902653789433362935484116310785534127104787453577540080102342088856991", "price": "0.87", "size": "0", "side": "SELL", "hash": "765d32bd5ddff11382bdfb7ff8bfe061b35deee7", "best_bid": "0.31", "best_ask": "0.36"}], "timestamp": "1769384692431", "event_type": "price_change"}}
{"_local_timestamp": "2026-01-25T23:44:52.726447+00:00", "data": {"market": "0xecbb7178261e45c45a2d40f3ba28f7b90da88f208a43e3c8f0bd9f7d69900ddc", "price_changes": [{"asset_id": "75087175062739028357071911202249876424512123621414420427750062298373802728902", "price": "0.08", "size": "4757.32", "side": "BUY", "hash": "10061779527259a42962ef31a1b97457ae6b899c", "best_bid": "0.64", "best_ask": "0.69"}, {"asset_id": "51057777902653789433362935484116310785534127104787453577540080102342088856991", "price": "0.92", "size": "4757.32", "side": "SELL", "hash": "d3685ab64d9050939160e94fe2fe56363c6180b2", "best_bid": "0.31", "best_ask": "0.36"}], "timestamp": "1769384692651", "event_type": "price_change"}}
{"_local_timestamp": "2026-01-25T23:44:52.810885+00:00", "data": {"market": "0xecbb7178261e45c45a2d40f3ba28f7b90da88f208a43e3c8f0bd9f7d69900ddc", "price_changes": [{"asset_id": "75087175062739028357071911202249876424512123621414420427750062298373802728902", "price": "0.09", "size": "1997.11", "side": "BUY", "hash": "8f18cea5a8fa32a5770ba1253663fa6814e6516c", "best_bid": "0.64", "best_ask": "0.69"}, {"asset_id": "51057777902653789433362935484116310785534127104787453577540080102342088856991", "price": "0.91", "size": "1997.11", "side": "SELL", "hash": "4f7758a54dde3f145310f8540b41d7ce76834f98", "best_bid": "0.31", "best_ask": "0.36"}], "timestamp": "1769384692739", "event_type": "price_change"}}
{"_local_timestamp": "2026-01-25T23:44:52.835931+00:00", "data": {"market": "0xecbb7178261e45c45a2d40f3ba28f7b90da88f208a43e3c8f0bd9f7d69900ddc", "price_changes": [{"asset_id": "75087175062739028357071911202249876424512123621414420427750062298373802728902", "price": "0.09", "size": "3267.21", "side": "BUY", "hash": "771b913cad8922d0f587a74697571f7519c435df", "best_bid": "0.64", "best_ask": "0.69"}, {"asset_id": "51057777902653789433362935484116310785534127104787453577540080102342088856991", "price": "0.91", "size": "3267.21", "side": "SELL", "hash": "c4e5d349e571ae20a86a8c93191b1fcacaf97ec8", "best_bid": "0.31", "best_ask": "0.36"}], "timestamp": "1769384692767", "event_type": "price_change"}}
{"_local_timestamp": "2026-01-25T23:44:52.849060+00:00", "data": {"market": "0xecbb7178261e45c45a2d40f3ba28f7b90da88f208a43e3c8f0bd9f7d69900ddc", "price_changes": [{"asset_id": "75087175062739028357071911202249876424512123621414420427750062298373802728902", "price": "0.09", "size": "4157.32", "side": "BUY", "hash": "56a653db2631681e74efedd626d9bff0289f5bd1", "best_bid": "0.64", "best_ask": "0.69"}, {"asset_id": "51057777902653789433362935484116310785534127104787453577540080102342088856991", "price": "0.91", "size": "4157.32", "side": "SELL", "hash": "be84e4b10f89542935d4b113178d2ea0ba23f492", "best_bid": "0.31", "best_ask": "0.36"}], "timestamp": "1769384692768", "event_type": "price_change"}}
{"_local_timestamp": "2026-01-25T23:44:52.870600+00:00", "data": {"market": "0xecbb7178261e45c45a2d40f3ba28f7b90da88f208a43e3c8f0bd9f7d69900ddc", "price_changes": [{"asset_id": "75087175062739028357071911202249876424512123621414420427750062298373802728902", "price": "0.08", "size": "4857.32", "side": "BUY", "hash": "f5a2bbcf24736b78d5289288720a82631be232ee", "best_bid": "0.64", "best_ask": "0.69"}, {"asset_id": "51057777902653789433362935484116310785534127104787453577540080102342088856991", "price": "0.92", "size": "4857.32", "side": "SELL", "hash": "376a4828f58aa3c84ebe3b8ac967c9c79c5a722f", "best_bid": "0.31", "best_ask": "0.36"}], "timestamp": "1769384692802", "event_type": "price_change"}}
{"_local_timestamp": "2026-01-25T23:45:08.852066+00:00", "data": {"market": "0xecbb7178261e45c45a2d40f3ba28f7b90da88f208a43e3c8f0bd9f7d69900ddc", "price_changes": [{"asset_id": "75087175062739028357071911202249876424512123621414420427750062298373802728902", "price": "0.08", "size": "4457.32", "side": "BUY", "hash": "522762c74674bf22d2bc614b7a69aa73458b79ee", "best_bid": "0.64", "best_ask": "0.69"}, {"asset_id": "51057777902653789433362935484116310785534127104787453577540080102342088856991", "price": "0.92", "size": "4457.32", "side": "SELL", "hash": "7b3ac317183b34bb5067174e314a6c03b985a297", "best_bid": "0.31", "best_ask": "0.36"}], "timestamp": "1769384708770", "event_type": "price_change"}}
{"_local_timestamp": "2026-01-25T23:45:09.124506+00:00", "data": {"market": "0xecbb7178261e45c45a2d40f3ba28f7b90da88f208a43e3c8f0bd9f7d69900ddc", "price_changes": [{"asset_id": "75087175062739028357071911202249876424512123621414420427750062298373802728902", "price": "0.09", "size": "4557.32", "side": "BUY", "hash": "75cb25d16d267862d35ff756927cf702955a070d", "best_bid": "0.64", "best_ask": "0.69"}, {"asset_id": "51057777902653789433362935484116310785534127104787453577540080102342088856991", "price": "0.91", "size": "4557.32", "side": "SELL", "hash": "ed91dd09ac6d7e3aaed7f6a07e787a768d206250", "best_bid": "0.31", "best_ask": "0.36"}], "timestamp": "1769384709051", "event_type": "price_change"}}
{"_local_timestamp": "2026-01-25T23:45:10.812110+00:00", "data": {"market": "0x8ccb39356d65ce6cd50d98b896351aaeff3a2d884158f6453fdec83a0f3f2361", "price_changes": [{"asset_id": "54115704767093899489859926330384345560631205111379974241224327571709257756515", "price": "0.04", "size": "29.99", "side": "BUY", "hash": "7e45bc7e0690ccf9a9871d72b90fa3c797c522ee", "best_bid": "0.04", "best_ask": "0.96"}, {"asset_id": "85979090154771566247057457488185735048733636408042266931260086497748605442725", "price": "0.96", "size": "29.99", "side": "SELL", "hash": "f3ea6976370b3bb7bcc4bcb3f8a92ef0b2b75a2c", "best_bid": "0.04", "best_ask": "0.96"}], "timestamp": "1769384710748", "event_type": "price_change"}}
{"_local_timestamp": "2026-01-25T23:45:11.895050+00:00", "data": {"market": "0x8ccb39356d65ce6cd50d98b896351aaeff3a2d884158f6453fdec83a0f3f2361", "price_changes": [{"asset_id": "54115704767093899489859926330384345560631205111379974241224327571709257756515", "price": "0.03", "size": "0", "side": "BUY", "hash": "e797a7c5a5ac5b2be0ea494435adb946c9b1caab", "best_bid": "0.04", "best_ask": "0.96"}, {"asset_id": "85979090154771566247057457488185735048733636408042266931260086497748605442725", "price": "0.97", "size": "0", "side": "SELL", "hash": "0283a3add1d6c63109e6a863432c77b35d799503", "best_bid": "0.04", "best_ask": "0.96"}], "timestamp": "1769384711810", "event_type": "price_change"}}
{"_local_timestamp": "2026-01-25T23:45:12.248612+00:00", "data": {"market": "0x8ccb39356d65ce6cd50d98b896351aaeff3a2d884158f6453fdec83a0f3f2361", "price_changes": [{"asset_id": "54115704767093899489859926330384345560631205111379974241224327571709257756515", "price": "0.05", "size": "5.47", "side": "BUY", "hash": "1dc5974576942a10f863c6413b6d2491846c5dfb", "best_bid": "0.05", "best_ask": "0.96"}, {"asset_id": "85979090154771566247057457488185735048733636408042266931260086497748605442725", "price": "0.95", "size": "5.47", "side": "SELL", "hash": "e1ff25a3835bbb7a0824a61d63f22af8bd8c227b", "best_bid": "0.04", "best_ask": "0.95"}], "timestamp": "1769384712181", "event_type": "price_change"}}
{"_local_timestamp": "2026-01-25T23:45:17.977433+00:00", "data": {"market": "0xc2db3c0906ac69232c4998f436e34e5df7e64b6dd2d9cb9ddd6305f2aef23c0d", "price_changes": [{"asset_id": "26283804933183319314833342421447518362320608677704153347603079425527445471777", "price": "0.02", "size": "5047.43", "side": "BUY", "hash": "e068cfb0f8aa43a953666bf4327842be007daabe", "best_bid": "0.57", "best_ask": "0.66"}, {"asset_id": "68765318567686557797285708330422826706843409708557814702138983780254126785177", "price": "0.98", "size": "5047.43", "side": "SELL", "hash": "6131cc780f54d423d0e96c4ec260d79966162037", "best_bid": "0.34", "best_ask": "0.43"}], "timestamp": "1769384717910", "event_type": "price_change"}}
{"_local_timestamp": "2026-01-25T23:45:17.978488+00:00", "data": {"market": "0x8ccb39356d65ce6cd50d98b896351aaeff3a2d884158f6453fdec83a0f3f2361", "price_changes": [{"asset_id": "54115704767093899489859926330384345560631205111379974241224327571709257756515", "price": "0.01", "size": "95.76", "side": "BUY", "hash": "2b1f584d0a5c868343b07b4918440abb76142877", "best_bid": "0.05", "best_ask": "0.96"}, {"asset_id": "85979090154771566247057457488185735048733636408042266931260086497748605442725", "price": "0.99", "size": "95.76", "side": "SELL", "hash": "32645142158452e58bac41d7d2a8d1873afdc716", "best_bid": "0.04", "best_ask": "0.95"}], "timestamp": "1769384717910", "event_type": "price_change"}}
{"_local_timestamp": "2026-01-25T23:45:17.979362+00:00", "data": {"market": "0xc2db3c0906ac69232c4998f436e34e5df7e64b6dd2d9cb9ddd6305f2aef23c0d", "price_changes": [{"asset_id": "26283804933183319314833342421447518362320608677704153347603079425527445471777", "price": "0.06", "size": "890.11", "side": "BUY", "hash": "e068cfb0f8aa43a953666bf4327842be007daabe", "best_bid": "0.57", "best_ask": "0.66"}, {"asset_id": "68765318567686557797285708330422826706843409708557814702138983780254126785177", "price": "0.94", "size": "890.11", "side": "SELL", "hash": "6131cc780f54d423d0e96c4ec260d79966162037", "best_bid": "0.34", "best_ask": "0.43"}], "timestamp": "1769384717910", "event_type": "price_change"}}
{"_local_timestamp": "2026-01-25T23:45:17.980198+00:00", "data": {"market": "0x8ccb39356d65ce6cd50d98b896351aaeff3a2d884158f6453fdec83a0f3f2361", "price_changes": [{"asset_id": "54115704767093899489859926330384345560631205111379974241224327571709257756515", "price": "0.02", "size": "11.35", "side": "BUY", "hash": "2b1f584d0a5c868343b07b4918440abb76142877", "best_bid": "0.05", "best_ask": "0.96"}, {"asset_id": "85979090154771566247057457488185735048733636408042266931260086497748605442725", "price": "0.98", "size": "11.35", "side": "SELL", "hash": "32645142158452e58bac41d7d2a8d1873afdc716", "best_bid": "0.04", "best_ask": "0.95"}], "timestamp": "1769384717910", "event_type": "price_change"}}
{"_local_timestamp": "2026-01-25T23:45:18.008805+00:00", "data": {"market": "0xc2db3c0906ac69232c4998f436e34e5df7e64b6dd2d9cb9ddd6305f2aef23c0d", "price_changes": [{"asset_id": "68765318567686557797285708330422826706843409708557814702138983780254126785177", "price": "0.02", "size": "4157.32", "side": "BUY", "hash": "18d168e4df2e08727b2505228b571eb9322e4b2d", "best_bid": "0.34", "best_ask": "0.43"}, {"asset_id": "26283804933183319314833342421447518362320608677704153347603079425527445471777", "price": "0.98", "size": "4157.32", "side": "SELL", "hash": "c280275957b2322ede15916235b8a69f1218a904", "best_bid": "0.57", "best_ask": "0.66"}], "timestamp": "1769384717946", "event_type": "price_change"}}
{"_local_timestamp": "2026-01-25T23:45:18.009864+00:00", "data": {"market": "0xc2db3c0906ac69232c4998f436e34e5df7e64b6dd2d9cb9ddd6305f2aef23c0d", "price_changes": [{"asset_id": "68765318567686557797285708330422826706843409708557814702138983780254126785177", "price": "0.01", "size": "7184.22", "side": "BUY", "hash": "18d168e4df2e08727b2505228b571eb9322e4b2d", "best_bid": "0.34", "best_ask": "0.43"}, {"asset_id": "26283804933183319314833342421447518362320608677704153347603079425527445471777", "price": "0.99", "size": "7184.22", "side": "SELL", "hash": "c280275957b2322ede15916235b8a69f1218a904", "best_bid": "0.57", "best_ask": "0.66"}], "timestamp": "1769384717946", "event_type": "price_change"}}
{"_local_timestamp": "2026-01-25T23:45:18.010963+00:00", "data": {"market": "0xc2db3c0906ac69232c4998f436e34e5df7e64b6dd2d9cb9ddd6305f2aef23c0d", "price_changes": [{"asset_id": "26283804933183319314833342421447518362320608677704153347603079425527445471777", "price": "0.07", "size": "0", "side": "BUY", "hash": "5f5b51da3c5d608a342ef54e75de691baf63cf1f", "best_bid": "0.57", "best_ask": "0.66"}, {"asset_id": "68765318567686557797285708330422826706843409708557814702138983780254126785177", "price": "0.93", "size": "0", "side": "SELL", "hash": "af1651888f14e1c0254208bda56f2abe23837b33", "best_bid": "0.34", "best_ask": "0.43"}], "timestamp": "1769384717947", "event_type": "price_change"}}
{"_local_timestamp": "2026-01-25T23:45:18.012063+00:00", "data": {"market": "0xc2db3c0906ac69232c4998f436e34e5df7e64b6dd2d9cb9ddd6305f2aef23c0d", "price_changes": [{"asset_id": "26283804933183319314833342421447518362320608677704153347603079425527445471777", "price": "0.02", "size": "4157.32", "side": "BUY", "hash": "5f5b51da3c5d608a342ef54e75de691baf63cf1f", "best_bid": "0.57", "best_ask": "0.66"}, {"asset_id": "68765318567686557797285708330422826706843409708557814702138983780254126785177", "price": "0.98", "size": "4157.32", "side": "SELL", "hash": "af1651888f14e1c0254208bda56f2abe23837b33", "best_bid": "0.34", "best_ask": "0.43"}], "timestamp": "1769384717947", "event_type": "price_change"}}
{"_local_timestamp": "2026-01-25T23:45:18.013296+00:00", "data": {"market": "0xc2db3c0906ac69232c4998f436e34e5df7e64b6dd2d9cb9ddd6305f2aef23c0d", "price_changes": [{"asset_id": "26283804933183319314833342421447518362320608677704153347603079425527445471777", "price": "0.01", "size": "7184.21", "side": "BUY", "hash": "5f5b51da3c5d608a342ef54e75de691baf63cf1f", "best_bid": "0.57", "best_ask": "0.66"}, {"asset_id": "68765318567686557797285708330422826706843409708557814702138983780254126785177", "price": "0.99", "size": "7184.21", "side": "SELL", "hash": "af1651888f14e1c0254208bda56f2abe23837b33", "best_bid": "0.34", "best_ask": "0.43"}], "timestamp": "1769384717947", "event_type": "price_change"}}
{"_local_timestamp": "2026-01-25T23:45:18.014306+00:00", "data": {"market": "0xc2db3c0906ac69232c4998f436e34e5df7e64b6dd2d9cb9ddd6305f2aef23c0d", "price_changes": [{"asset_id": "26283804933183319314833342421447518362320608677704153347603079425527445471777", "price": "0.06", "size": "0", "side": "BUY", "hash": "5f5b51da3c5d608a342ef54e75de691baf63cf1f", "best_bid": "0.57", "best_ask": "0.66"}, {"asset_id": "68765318567686557797285708330422826706843409708557814702138983780254126785177", "price": "0.94", "size": "0", "side": "SELL", "hash": "af1651888f14e1c0254208bda56f2abe23837b33", "best_bid": "0.34", "best_ask": "0.43"}], "timestamp": "1769384717947", "event_type": "price_change"}}
{"_local_timestamp": "2026-01-25T23:45:18.118087+00:00", "data": {"market": "0xc2db3c0906ac69232c4998f436e34e5df7e64b6dd2d9cb9ddd6305f2aef23c0d", "price_changes": [{"asset_id": "26283804933183319314833342421447518362320608677704153347603079425527445471777", "price": "0.07", "size": "1270.1", "side": "BUY", "hash": "47653ad116152fb0e4cf1fd5270ab36a40e2873e", "best_bid": "0.57", "best_ask": "0.66"}, {"asset_id": "68765318567686557797285708330422826706843409708557814702138983780254126785177", "price": "0.93", "size": "1270.1", "side": "SELL", "hash": "9501854732205c4f11914aa05a605e5ba81023e2", "best_bid": "0.34", "best_ask": "0.43"}], "timestamp": "1769384718055", "event_type": "price_change"}}
{"_local_timestamp": "2026-01-25T23:45:18.119038+00:00", "data": {"market": "0xc2db3c0906ac69232c4998f436e34e5df7e64b6dd2d9cb9ddd6305f2aef23c0d", "price_changes": [{"asset_id": "26283804933183319314833342421447518362320608677704153347603079425527445471777", "price": "0.07", "size": "3267.21", "side": "BUY", "hash": "ae3dc0dde1c73fcb1eb68b31f9894e54e35cbdf9", "best_bid": "0.57", "best_ask": "0.66"}, {"asset_id": "68765318567686557797285708330422826706843409708557814702138983780254126785177", "price": "0.93", "size": "3267.21", "side": "SELL", "hash": "b08130049cdd782ff4c0c659d1d417beb4830458", "best_bid": "0.34", "best_ask": "0.43"}], "timestamp": "1769384718056", "event_type": "price_change"}}
{"_local_timestamp": "2026-01-25T23:45:18.120029+00:00", "data": {"market": "0xc2db3c0906ac69232c4998f436e34e5df7e64b6dd2d9cb9ddd6305f2aef23c0d", "price_changes": [{"asset_id": "26283804933183319314833342421447518362320608677704153347603079425527445471777", "price": "0.07", "size": "4157.32", "side": "BUY", "hash": "c6eb4e53cbd4c479d3841bd4dac86360515fe348", "best_bid": "0.57", "best_ask": "0.66"}, {"asset_id": "68765318567686557797285708330422826706843409708557814702138983780254126785177", "price": "0.93", "size": "4157.32", "side": "SELL", "hash": "2f1256446205b2c42687d66b12f0b438d4e4f278", "best_bid": "0.34", "best_ask": "0.43"}], "timestamp": "1769384718056", "event_type": "price_change"}}
{"_local_timestamp": "2026-01-25T23:45:19.213725+00:00", "data": {"market": "0x8ccb39356d65ce6cd50d98b896351aaeff3a2d884158f6453fdec83a0f3f2361", "price_changes": [{"asset_id": "54115704767093899489859926330384345560631205111379974241224327571709257756515", "price": "0.05", "size": "11.79", "side": "BUY", "hash": "74c146a87e39bfb860f921b6df948b5f157f43de", "best_bid": "0.05", "best_ask": "0.96"}, {"asset_id": "85979090154771566247057457488185735048733636408042266931260086497748605442725", "price": "0.95", "size": "11.79", "side": "SELL", "hash": "14a220204df3e0877fa5b9edfe98ca1a3da7703a", "best_bid": "0.04", "best_ask": "0.95"}], "timestamp": "1769384719151", "event_type": "price_change"}}
{"_local_timestamp": "2026-01-25T23:45:19.227267+00:00", "data": {"market": "0xc2db3c0906ac69232c4998f436e34e5df7e64b6dd2d9cb9ddd6305f2aef23c0d", "price_changes": [{"asset_id": "26283804933183319314833342421447518362320608677704153347603079425527445471777", "price": "0.03", "size": "31.63", "side": "BUY", "hash": "1f44e09b3de912e9a57b486e2278ac96d49ffbff", "best_bid": "0.57", "best_ask": "0.66"}, {"asset_id": "68765318567686557797285708330422826706843409708557814702138983780254126785177", "price": "0.97", "size": "31.63", "side": "SELL", "hash": "551d73a9568c3d76e4c8b8cf5c55ab8b19f6bf78", "best_bid": "0.34", "best_ask": "0.43"}], "timestamp": "1769384719151", "event_type": "price_change"}}
{"_local_timestamp": "2026-01-25T23:45:19.228258+00:00", "data": {"market": "0x8ccb39356d65ce6cd50d98b896351aaeff3a2d884158f6453fdec83a0f3f2361", "price_changes": [{"asset_id": "54115704767093899489859926330384345560631205111379974241224327571709257756515", "price": "0.02", "size": "26.3", "side": "BUY", "hash": "ddeb8fa9f750bb351cf43dd175b0e1ec381b4e58", "best_bid": "0.05", "best_ask": "0.96"}, {"asset_id": "85979090154771566247057457488185735048733636408042266931260086497748605442725", "price": "0.98", "size": "26.3", "side": "SELL", "hash": "c5030268af8fd00687ee017ad89ea53c5453f243", "best_bid": "0.04", "best_ask": "0.95"}], "timestamp": "1769384719151", "event_type": "price_change"}}
{"_local_timestamp": "2026-01-25T23:45:19.352565+00:00", "data": {"market": "0x171b0625db2b7f2ac2848455143776eec779ee85f6359364c1b423b23b32fc68", "price_changes": [{"asset_id": "110208037745521376477218629625161726044793864281199315926557875582085019919669", "price": "0.02", "size": "11046.54", "side": "BUY", "hash": "d7c59b1a86a305c67d9a89ae36217c55d009ee2b", "best_bid": "0.56", "best_ask": "0.65"}, {"asset_id": "17118621258018130257689540837975706602158094977984538267313954503349864657420", "price": "0.98", "size": "11046.54", "side": "SELL", "hash": "8afa73cad318d273a9d8575725c08ee4cac9f0ab", "best_bid": "0.35", "best_ask": "0.44"}], "timestamp": "1769384719287", "event_type": "price_change"}}
{"_local_timestamp": "2026-01-25T23:45:19.353591+00:00", "data": {"market": "0x171b0625db2b7f2ac2848455143776eec779ee85f6359364c1b423b23b32fc68", "price_changes": [{"asset_id": "110208037745521376477218629625161726044793864281199315926557875582085019919669", "price": "0.06", "size": "0", "side": "BUY", "hash": "d7c59b1a86a305c67d9a89ae36217c55d009ee2b", "best_bid": "0.56", "best_ask": "0.65"}, {"asset_id": "17118621258018130257689540837975706602158094977984538267313954503349864657420", "price": "0.94", "size": "0", "side": "SELL", "hash": "8afa73cad318d273a9d8575725c08ee4cac9f0ab", "best_bid": "0.35", "best_ask": "0.44"}], "timestamp": "1769384719287", "event_type": "price_change"}}
{"_local_timestamp": "2026-01-25T23:45:19.407146+00:00", "data": {"market": "0x171b0625db2b7f2ac2848455143776eec779ee85f6359364c1b423b23b32fc68", "price_changes": [{"asset_id": "17118621258018130257689540837975706602158094977984538267313954503349864657420", "price": "0.02", "size": "4157.32", "side": "BUY", "hash": "faa3594563533baa8d5d09f83830c85b9859abc0", "best_bid": "0.35", "best_ask": "0.44"}, {"asset_id": "110208037745521376477218629625161726044793864281199315926557875582085019919669", "price": "0.98", "size": "4157.32", "side": "SELL", "hash": "f0c011f45bbdd6238af361628c78fe9c9566a782", "best_bid": "0.56", "best_ask": "0.65"}], "timestamp": "1769384719337", "event_type": "price_change"}}
{"_local_timestamp": "2026-01-25T23:45:19.408249+00:00", "data": {"market": "0x171b0625db2b7f2ac2848455143776eec779ee85f6359364c1b423b23b32fc68", "price_changes": [{"asset_id": "17118621258018130257689540837975706602158094977984538267313954503349864657420", "price": "0.01", "size": "7184.28", "side": "BUY", "hash": "faa3594563533baa8d5d09f83830c85b9859abc0", "best_bid": "0.35", "best_ask": "0.44"}, {"asset_id": "110208037745521376477218629625161726044793864281199315926557875582085019919669", "price": "0.99", "size": "7184.28", "side": "SELL", "hash": "f0c011f45bbdd6238af361628c78fe9c9566a782", "best_bid": "0.56", "best_ask": "0.65"}], "timestamp": "1769384719337", "event_type": "price_change"}}
{"_local_timestamp": "2026-01-25T23:45:19.410091+00:00", "data": {"market": "0x171b0625db2b7f2ac2848455143776eec779ee85f6359364c1b423b23b32fc68", "price_changes": [{"asset_id": "110208037745521376477218629625161726044793864281199315926557875582085019919669", "price": "0.03", "size": "0", "side": "BUY", "hash": "4fa251c922268eb47a803fd0b90f7a954ee61edb", "best_bid": "0.56", "best_ask": "0.65"}, {"asset_id": "17118621258018130257689540837975706602158094977984538267313954503349864657420", "price": "0.97", "size": "0", "side": "SELL", "hash": "c370358697c1c220e6cd53cdd327949e4da051b5", "best_bid": "0.35", "best_ask": "0.44"}], "timestamp": "1769384719337", "event_type": "price_change"}}
{"_local_timestamp": "2026-01-25T23:45:19.411015+00:00", "data": {"market": "0x171b0625db2b7f2ac2848455143776eec779ee85f6359364c1b423b23b32fc68", "price_changes": [{"asset_id": "110208037745521376477218629625161726044793864281199315926557875582085019919669", "price": "0.02", "size": "4157.32", "side": "BUY", "hash": "4fa251c922268eb47a803fd0b90f7a954ee61edb", "best_bid": "0.56", "best_ask": "0.65"}, {"asset_id": "17118621258018130257689540837975706602158094977984538267313954503349864657420", "price": "0.98", "size": "4157.32", "side": "SELL", "hash": "c370358697c1c220e6cd53cdd327949e4da051b5", "best_bid": "0.35", "best_ask": "0.44"}], "timestamp": "1769384719337", "event_type": "price_change"}}
{"_local_timestamp": "2026-01-25T23:45:20.178182+00:00", "data": {"market": "0x171b0625db2b7f2ac2848455143776eec779ee85f6359364c1b423b23b32fc68", "price_changes": [{"asset_id": "110208037745521376477218629625161726044793864281199315926557875582085019919669", "price": "0.03", "size": "29.96", "side": "BUY", "hash": "8bd1606e98172fc3bed1db49130678b310fe7df4", "best_bid": "0.56", "best_ask": "0.65"}, {"asset_id": "17118621258018130257689540837975706602158094977984538267313954503349864657420", "price": "0.97", "size": "29.96", "side": "SELL", "hash": "a61d79a537be45abc6f38a93221ca91b054e0c14", "best_bid": "0.35", "best_ask": "0.44"}], "timestamp": "1769384720019", "event_type": "price_change"}}
{"_local_timestamp": "2026-01-25T23:45:20.179146+00:00", "data": {"market": "0x171b0625db2b7f2ac2848455143776eec779ee85f6359364c1b423b23b32fc68", "price_changes": [{"asset_id": "110208037745521376477218629625161726044793864281199315926557875582085019919669", "price": "0.01", "size": "7189.21", "side": "BUY", "hash": "5de6a6df223100574861084e4d71341f4424a1e3", "best_bid": "0.56", "best_ask": "0.65"}, {"asset_id": "17118621258018130257689540837975706602158094977984538267313954503349864657420", "price": "0.99", "size": "7189.21", "side": "SELL", "hash": "9db6a02c2adfe19a7eee2ecb34b131d1ad52ae16", "best_bid": "0.35", "best_ask": "0.44"}], "timestamp": "1769384720020", "event_type": "price_change"}}
{"_local_timestamp": "2026-01-25T23:45:28.916431+00:00", "data": {"market": "0xecbb7178261e45c45a2d40f3ba28f7b90da88f208a43e3c8f0bd9f7d69900ddc", "price_changes": [{"asset_id": "75087175062739028357071911202249876424512123621414420427750062298373802728902", "price": "0.11", "size": "0", "side": "BUY", "hash": "0bddb3b3a2cdd92b6155c6105ea984cb3e58d541", "best_bid": "0.64", "best_ask": "0.69"}, {"asset_id": "51057777902653789433362935484116310785534127104787453577540080102342088856991", "price": "0.89", "size": "0", "side": "SELL", "hash": "a89a1e15ad92090a430e7d7a4944fbed7890185e", "best_bid": "0.31", "best_ask": "0.36"}], "timestamp": "1769384728853", "event_type": "price_change"}}
{"_local_timestamp": "2026-01-25T23:45:28.974344+00:00", "data": {"market": "0xecbb7178261e45c45a2d40f3ba28f7b90da88f208a43e3c8f0bd9f7d69900ddc", "price_changes": [{"asset_id": "75087175062739028357071911202249876424512123621414420427750062298373802728902", "price": "0.09", "size": "400", "side": "BUY", "hash": "8c37870700522253a18e4648b7a621350f6ce2a3", "best_bid": "0.64", "best_ask": "0.69"}, {"asset_id": "51057777902653789433362935484116310785534127104787453577540080102342088856991", "price": "0.91", "size": "400", "side": "SELL", "hash": "12e5e92a15ae499bdb50c0b391b1ae993f146c56", "best_bid": "0.31", "best_ask": "0.36"}], "timestamp": "1769384728898", "event_type": "price_change"}}
{"_local_timestamp": "2026-01-25T23:45:30.294678+00:00", "data": {"market": "0xecbb7178261e45c45a2d40f3ba28f7b90da88f208a43e3c8f0bd9f7d69900ddc", "price_changes": [{"asset_id": "75087175062739028357071911202249876424512123621414420427750062298373802728902", "price": "0.1", "size": "6.57", "side": "BUY", "hash": "8723c441ad68a4f2a589ce8d3145cb437f48a758", "best_bid": "0.64", "best_ask": "0.69"}, {"asset_id": "51057777902653789433362935484116310785534127104787453577540080102342088856991", "price": "0.9", "size": "6.57", "side": "SELL", "hash": "ee5217202f945d2cb8ed58db583e8ac5f81e9de8", "best_bid": "0.31", "best_ask": "0.36"}], "timestamp": "1769384730228", "event_type": "price_change"}}
{"_local_timestamp": "2026-01-25T23:45:50.424958+00:00", "data": {"market": "0xecbb7178261e45c45a2d40f3ba28f7b90da88f208a43e3c8f0bd9f7d69900ddc", "price_changes": [{"asset_id": "75087175062739028357071911202249876424512123621414420427750062298373802728902", "price": "0.09", "size": "0", "side": "BUY", "hash": "e4a9f7e194255fdfefa2c4648fc18a0d4942b9fd", "best_bid": "0.64", "best_ask": "0.69"}, {"asset_id": "51057777902653789433362935484116310785534127104787453577540080102342088856991", "price": "0.91", "size": "0", "side": "SELL", "hash": "4c7344e00dd619c27a762829c426e707146afc23", "best_bid": "0.31", "best_ask": "0.36"}], "timestamp": "1769384750342", "event_type": "price_change"}}
{"_local_timestamp": "2026-01-25T23:45:50.702788+00:00", "data": {"market": "0xecbb7178261e45c45a2d40f3ba28f7b90da88f208a43e3c8f0bd9f7d69900ddc", "price_changes": [{"asset_id": "75087175062739028357071911202249876424512123621414420427750062298373802728902", "price": "0.08", "size": "4857.32", "side": "BUY", "hash": "fbbdbe886cde098e87bda5ab9a128cbf786ef235", "best_bid": "0.64", "best_ask": "0.69"}, {"asset_id": "51057777902653789433362935484116310785534127104787453577540080102342088856991", "price": "0.92", "size": "4857.32", "side": "SELL", "hash": "59bffa2455cb7dee6790dd2e9c8a3f8f5be40179", "best_bid": "0.31", "best_ask": "0.36"}], "timestamp": "1769384750621", "event_type": "price_change"}}
{"_local_timestamp": "2026-01-25T23:45:50.767194+00:00", "data": {"market": "0xecbb7178261e45c45a2d40f3ba28f7b90da88f208a43e3c8f0bd9f7d69900ddc", "price_changes": [{"asset_id": "75087175062739028357071911202249876424512123621414420427750062298373802728902", "price": "0.09", "size": "1270.1", "side": "BUY", "hash": "47697d6de5eeb9fdf4207bb2850ae9d2c30c52cd", "best_bid": "0.64", "best_ask": "0.69"}, {"asset_id": "51057777902653789433362935484116310785534127104787453577540080102342088856991", "price": "0.91", "size": "1270.1", "side": "SELL", "hash": "91b4aa446993b8ad5261c4cc3595bd1384e86680", "best_bid": "0.31", "best_ask": "0.36"}], "timestamp": "1769384750691", "event_type": "price_change"}}
{"_local_timestamp": "2026-01-25T23:45:50.768961+00:00", "data": {"market": "0xecbb7178261e45c45a2d40f3ba28f7b90da88f208a43e3c8f0bd9f7d69900ddc", "price_changes": [{"asset_id": "75087175062739028357071911202249876424512123621414420427750062298373802728902", "price": "0.09", "size": "3267.21", "side": "BUY", "hash": "17983de0494b4179cefb3416d247ea9ab0599e92", "best_bid": "0.64", "best_ask": "0.69"}, {"asset_id": "51057777902653789433362935484116310785534127104787453577540080102342088856991", "price": "0.91", "size": "3267.21", "side": "SELL", "hash": "0b6d3062606a5dcd3eb70ebc519eb2b70e249038", "best_bid": "0.31", "best_ask": "0.36"}], "timestamp": "1769384750692", "event_type": "price_change"}}
{"_local_timestamp": "2026-01-25T23:45:50.769891+00:00", "data": {"market": "0xecbb7178261e45c45a2d40f3ba28f7b90da88f208a43e3c8f0bd9f7d69900ddc", "price_changes": [{"asset_id": "75087175062739028357071911202249876424512123621414420427750062298373802728902", "price": "0.09", "size": "4157.32", "side": "BUY", "hash": "a3bb4c0df74a22f5c8c4c3caec172e851774c3eb", "best_bid": "0.64", "best_ask": "0.69"}, {"asset_id": "51057777902653789433362935484116310785534127104787453577540080102342088856991", "price": "0.91", "size": "4157.32", "side": "SELL", "hash": "1e79b043c97bc8aee04e6eb05a10ec555c92a2da", "best_bid": "0.31", "best_ask": "0.36"}], "timestamp": "1769384750693", "event_type": "price_change"}}
{"_local_timestamp": "2026-01-25T23:46:12.036006+00:00", "data": {"market": "0xecbb7178261e45c45a2d40f3ba28f7b90da88f208a43e3c8f0bd9f7d69900ddc", "price_changes": [{"asset_id": "75087175062739028357071911202249876424512123621414420427750062298373802728902", "price": "0.08", "size": "4457.32", "side": "BUY", "hash": "06bebe3cef57941fe13e38a8723a2530af3877c0", "best_bid": "0.64", "best_ask": "0.69"}, {"asset_id": "51057777902653789433362935484116310785534127104787453577540080102342088856991", "price": "0.92", "size": "4457.32", "side": "SELL", "hash": "3efb20484946513606ffee275b820230edabee10", "best_bid": "0.31", "best_ask": "0.36"}], "timestamp": "1769384771928", "event_type": "price_change"}}
{"_local_timestamp": "2026-01-25T23:46:12.096302+00:00", "data": {"market": "0xecbb7178261e45c45a2d40f3ba28f7b90da88f208a43e3c8f0bd9f7d69900ddc", "price_changes": [{"asset_id": "75087175062739028357071911202249876424512123621414420427750062298373802728902", "price": "0.09", "size": "0", "side": "BUY", "hash": "11912a7592b45d57b0fe37b2e1b15f6289893542", "best_bid": "0.64", "best_ask": "0.69"}, {"asset_id": "51057777902653789433362935484116310785534127104787453577540080102342088856991", "price": "0.91", "size": "0", "side": "SELL", "hash": "3fe136bcdd4236fa7ade350ceac355602bae287f", "best_bid": "0.31", "best_ask": "0.36"}], "timestamp": "1769384772010", "event_type": "price_change"}}
{"_local_timestamp": "2026-01-25T23:46:12.283091+00:00", "data": {"market": "0xecbb7178261e45c45a2d40f3ba28f7b90da88f208a43e3c8f0bd9f7d69900ddc", "price_changes": [{"asset_id": "75087175062739028357071911202249876424512123621414420427750062298373802728902", "price": "0.09", "size": "400", "side": "BUY", "hash": "549dfbc6abeee33d6fda876771ef24972c09b99e", "best_bid": "0.64", "best_ask": "0.69"}, {"asset_id": "51057777902653789433362935484116310785534127104787453577540080102342088856991", "price": "0.91", "size": "400", "side": "SELL", "hash": "713976139a1cc825ff6bb9b0276dfe48568c7436", "best_bid": "0.31", "best_ask": "0.36"}], "timestamp": "1769384772218", "event_type": "price_change"}}
{"_local_timestamp": "2026-01-25T23:46:27.075274+00:00", "data": {"market": "0xc2db3c0906ac69232c4998f436e34e5df7e64b6dd2d9cb9ddd6305f2aef23c0d", "price_changes": [{"asset_id": "68765318567686557797285708330422826706843409708557814702138983780254126785177", "price": "0.33", "size": "890.11", "side": "BUY", "hash": "17710bff9369850f2807c4fdb436a1eb1cead04d", "best_bid": "0.34", "best_ask": "0.43"}, {"asset_id": "26283804933183319314833342421447518362320608677704153347603079425527445471777", "price": "0.67", "size": "890.11", "side": "SELL", "hash": "586987ac0d481c6eafd382b253aea488642c9364", "best_bid": "0.57", "best_ask": "0.66"}], "timestamp": "1769384787000", "event_type": "price_change"}}
{"_local_timestamp": "2026-01-25T23:46:27.081156+00:00", "data": {"market": "0xecbb7178261e45c45a2d40f3ba28f7b90da88f208a43e3c8f0bd9f7d69900ddc", "price_changes": [{"asset_id": "75087175062739028357071911202249876424512123621414420427750062298373802728902", "price": "0.6", "size": "890.11", "side": "BUY", "hash": "8a8537392bca2134913771b410ace33925f063c1", "best_bid": "0.64", "best_ask": "0.69"}, {"asset_id": "51057777902653789433362935484116310785534127104787453577540080102342088856991", "price": "0.4", "size": "890.11", "side": "SELL", "hash": "8500306912588c1cbc5a46f2ae0e060f0ca0461f", "best_bid": "0.31", "best_ask": "0.36"}], "timestamp": "1769384787000", "event_type": "price_change"}}
{"_local_timestamp": "2026-01-25T23:46:27.082100+00:00", "data": {"market": "0x15beb6ee455f9837b69cd7dcd110770b2f489d88651e4ffb21cd54f617a23e04", "price_changes": [{"asset_id": "44868850067599122384522819337153865676781090849621105309651139851616912647528", "price": "0.48", "size": "0", "side": "BUY", "hash": "d250350fab83e9ef7ab1121d1b2576bd10a843e3", "best_bid": "0.02", "best_ask": "0.58"}, {"asset_id": "14205737424716982918858761268248742215558565679165887656230879609115111732505", "price": "0.52", "size": "0", "side": "SELL", "hash": "c990c29da08b79546a993998f6995c81024acf3d", "best_bid": "0.42", "best_ask": "0.98"}], "timestamp": "1769384787000", "event_type": "price_change"}}
{"_local_timestamp": "2026-01-25T23:46:27.082994+00:00", "data": {"market": "0xc2db3c0906ac69232c4998f436e34e5df7e64b6dd2d9cb9ddd6305f2aef23c0d", "price_changes": [{"asset_id": "26283804933183319314833342421447518362320608677704153347603079425527445471777", "price": "0.56", "size": "890.11", "side": "BUY", "hash": "3eb6415bbb23cba305853644a7b02fc6a066e8d9", "best_bid": "0.57", "best_ask": "0.66"}, {"asset_id": "68765318567686557797285708330422826706843409708557814702138983780254126785177", "price": "0.44", "size": "890.11", "side": "SELL", "hash": "2f064b190b435c039959a091b77a0fea1d5b3b01", "best_bid": "0.34", "best_ask": "0.43"}], "timestamp": "1769384787000", "event_type": "price_change"}}
{"_local_timestamp": "2026-01-25T23:46:27.083902+00:00", "data": {"market": "0x171b0625db2b7f2ac2848455143776eec779ee85f6359364c1b423b23b32fc68", "price_changes": [{"asset_id": "17118621258018130257689540837975706602158094977984538267313954503349864657420", "price": "0.34", "size": "890.11", "side": "BUY", "hash": "813836349d01d433d6a7394a62ae0dc22ba45661", "best_bid": "0.35", "best_ask": "0.44"}, {"asset_id": "110208037745521376477218629625161726044793864281199315926557875582085019919669", "price": "0.66", "size": "890.11", "side": "SELL", "hash": "7fce3bec2b74c7f13ff6847b08bb8d7e2cd01b4e", "best_bid": "0.56", "best_ask": "0.65"}], "timestamp": "1769384787000", "event_type": "price_change"}}
{"_local_timestamp": "2026-01-25T23:46:27.085499+00:00", "data": {"market": "0x15beb6ee455f9837b69cd7dcd110770b2f489d88651e4ffb21cd54f617a23e04", "price_changes": [{"asset_id": "14205737424716982918858761268248742215558565679165887656230879609115111732505", "price": "0.42", "size": "0", "side": "BUY", "hash": "6d0a3c50c67fccfb6d9572376f81c991cd7c38c8", "best_bid": "0.02", "best_ask": "0.98"}, {"asset_id": "44868850067599122384522819337153865676781090849621105309651139851616912647528", "price": "0.58", "size": "0", "side": "SELL", "hash": "6e333d5bac8459448ddd032ca834cee198e4e1cc", "best_bid": "0.02", "best_ask": "0.98"}], "timestamp": "1769384787000", "event_type": "price_change"}}
{"_local_timestamp": "2026-01-25T23:46:27.086389+00:00", "data": {"market": "0xecbb7178261e45c45a2d40f3ba28f7b90da88f208a43e3c8f0bd9f7d69900ddc", "price_changes": [{"asset_id": "51057777902653789433362935484116310785534127104787453577540080102342088856991", "price": "0.28", "size": "0", "side": "BUY", "hash": "a680b7249847d6a8e797ee32fadfc9a8a2fe5ed8", "best_bid": "0.31", "best_ask": "0.36"}, {"asset_id": "75087175062739028357071911202249876424512123621414420427750062298373802728902", "price": "0.72", "size": "0", "side": "SELL", "hash": "274d71660a4becf7249ba03a10154832948a123a", "best_bid": "0.64", "best_ask": "0.69"}], "timestamp": "1769384787000", "event_type": "price_change"}}
{"_local_timestamp": "2026-01-25T23:46:27.087299+00:00", "data": {"market": "0x171b0625db2b7f2ac2848455143776eec779ee85f6359364c1b423b23b32fc68", "price_changes": [{"asset_id": "110208037745521376477218629625161726044793864281199315926557875582085019919669", "price": "0.55", "size": "890.11", "side": "BUY", "hash": "11c20d47c2df571fc311d908476c16aca7e82135", "best_bid": "0.56", "best_ask": "0.65"}, {"asset_id": "17118621258018130257689540837975706602158094977984538267313954503349864657420", "price": "0.45", "size": "890.11", "side": "SELL", "hash": "38fd47e0b3fa4c16a583e1bbcd0261c6d22b6b7c", "best_bid": "0.35", "best_ask": "0.44"}], "timestamp": "1769384787001", "event_type": "price_change"}}
{"_local_timestamp": "2026-01-25T23:46:27.159323+00:00", "data": {"market": "0xc2db3c0906ac69232c4998f436e34e5df7e64b6dd2d9cb9ddd6305f2aef23c0d", "price_changes": [{"asset_id": "26283804933183319314833342421447518362320608677704153347603079425527445471777", "price": "0.07", "size": "0", "side": "BUY", "hash": "281d8757d64fa1b52687da10e7d07a24926a8cb9", "best_bid": "0.57", "best_ask": "0.66"}, {"asset_id": "68765318567686557797285708330422826706843409708557814702138983780254126785177", "price": "0.93", "size": "0", "side": "SELL", "hash": "d4622ea75db636ecff021fb31c148cc227633fb6", "best_bid": "0.34", "best_ask": "0.43"}], "timestamp": "1769384787075", "event_type": "price_change"}}
{"_local_timestamp": "2026-01-25T23:46:27.182878+00:00", "data": {"market": "0x171b0625db2b7f2ac2848455143776eec779ee85f6359364c1b423b23b32fc68", "price_changes": [{"asset_id": "17118621258018130257689540837975706602158094977984538267313954503349864657420", "price": "0.02", "size": "5047.43", "side": "BUY", "hash": "26aa27f55d2987daaefcab34d372419063215160", "best_bid": "0.35", "best_ask": "0.44"}, {"asset_id": "110208037745521376477218629625161726044793864281199315926557875582085019919669", "price": "0.98", "size": "5047.43", "side": "SELL", "hash": "f7a1d9c87e945ce0003c50f4cd84c44af95f77c8", "best_bid": "0.56", "best_ask": "0.65"}], "timestamp": "1769384787107", "event_type": "price_change"}}
{"_local_timestamp": "2026-01-25T23:46:27.300254+00:00", "data": {"market": "0xc2db3c0906ac69232c4998f436e34e5df7e64b6dd2d9cb9ddd6305f2aef23c0d", "price_changes": [{"asset_id": "26283804933183319314833342421447518362320608677704153347603079425527445471777", "price": "0.01", "size": "8074.32", "side": "BUY", "hash": "7819940e7019f70c6e8c78c619af47e78cd1d06c", "best_bid": "0.57", "best_ask": "0.66"}, {"asset_id": "68765318567686557797285708330422826706843409708557814702138983780254126785177", "price": "0.99", "size": "8074.32", "side": "SELL", "hash": "ba2ca752674cdfe65b089581bb93ab7a477136be", "best_bid": "0.34", "best_ask": "0.43"}], "timestamp": "1769384787107", "event_type": "price_change"}}
{"_local_timestamp": "2026-01-25T23:46:27.301294+00:00", "data": {"market": "0xecbb7178261e45c45a2d40f3ba28f7b90da88f208a43e3c8f0bd9f7d69900ddc", "price_changes": [{"asset_id": "75087175062739028357071911202249876424512123621414420427750062298373802728902", "price": "0.15", "size": "890.11", "side": "BUY", "hash": "827d074e53de7f7f9e5a20269fdccc3c6efe6f23", "best_bid": "0.64", "best_ask": "0.69"}, {"asset_id": "51057777902653789433362935484116310785534127104787453577540080102342088856991", "price": "0.85", "size": "890.11", "side": "SELL", "hash": "d50f2269ef9f7f6eea9548dc6e0797a74567c021", "best_bid": "0.31", "best_ask": "0.36"}], "timestamp": "1769384787107", "event_type": "price_change"}}
{"_local_timestamp": "2026-01-25T23:46:27.302238+00:00", "data": {"market": "0xc2db3c0906ac69232c4998f436e34e5df7e64b6dd2d9cb9ddd6305f2aef23c0d", "price_changes": [{"asset_id": "26283804933183319314833342421447518362320608677704153347603079425527445471777", "price": "0.02", "size": "5047.43", "side": "BUY", "hash": "49b8256f7d0a82b9f0889752d9057523eeeec64e", "best_bid": "0.57", "best_ask": "0.66"}, {"asset_id": "68765318567686557797285708330422826706843409708557814702138983780254126785177", "price": "0.98", "size": "5047.43", "side": "SELL", "hash": "5be64dccc1a6eb5f2c5b925270808be0677cb327", "best_bid": "0.34", "best_ask": "0.43"}], "timestamp": "1769384787108", "event_type": "price_change"}}
