{"_local_timestamp": "2026-01-25T23:34:17.178301+00:00", "data": [{"market": "0xb483376a4a11938da0ae705f901db99f563a73f84df0d3dcb2c1bf7052ca279b", "asset_id": "23776435377389573739555717891589267364161331448909103730752015156572276458827", "timestamp": "1769383984694", "hash": "a04280bca80538137bb2a70649ba1bd5c2191282", "bids": [{"price": "0.01", "size": "8079.49"}, {"price": "0.02", "size": "5047.43"}, {"price": "0.03", "size": "3080.22"}, {"price": "0.51", "size": "400"}], "asks": [{"price": "0.99", "size": "8075.27"}, {"price": "0.98", "size": "5052.52"}, {"price": "0.97", "size": "10156.43"}, {"price": "0.96", "size": "20.94"}, {"price": "0.58", "size": "400"}], "event_type": "book", "last_trade_price": ""}, {"market": "0x88608442d14bdfa98a3d2ece26857aa516f193c8161db0c8e7c779fd8f3464af", "asset_id": "42097535137505280315737745177128192451567567237475285083506851409423497113459", "timestamp": "1769384047059", "hash": "cbddf729b8385aef2fb733053ced5af00af3d863", "bids": [{"price": "0.01", "size": "8818.44"}, {"price": "0.02", "size": "1000"}, {"price": "0.03", "size": "10.29"}, {"price": "0.04", "size": "1100"}, {"price": "0.07", "size": "2590.11"}, {"price": "0.08", "size": "890.11"}, {"price": "0.1", "size": "995.98"}, {"price": "0.11", "size": "990.11"}, {"price": "0.21", "size": "37.34"}, {"price": "0.4", "size": "400"}], "asks": [{"price": "0.99", "size": "8794.47"}, {"price": "0.98", "size": "1012"}, {"price": "0.97", "size": "1100"}, {"price": "0.96", "size": "5.38"}, {"price": "0.93", "size": "2590.11"}, {"price": "0.92", "size": "5147.43"}, {"price": "0.91", "size": "100"}, {"price": "0.9", "size": "500"}, {"price": "0.89", "size": "5.73"}, {"price": "0.85", "size": "890.11"}, {"price": "0.84", "size": "1090.11"}, {"price": "0.8", "size": "50"}, {"price": "0.68", "size": "2.64"}, {"price": "0.66", "size": "60"}, {"price": "0.47", "size": "7440.27"}], "event_type": "book", "last_trade_price": "0.530"}, {"market": "0x88608442d14bdfa98a3d2ece26857aa516f193c8161db0c8e7c779fd8f3464af", "asset_id": "20794210232738155208360248995422719359166978550921485109532388301377529305580", "timestamp": "1769384047059", "hash": "443b9d6dc632e33ad88fcff2950e696679925910", "bids": [{"price": "0.01", "size": "8794.47"}, {"price": "0.02", "size": "1012"}, {"price": "0.03", "size": "1100"}, {"price": "0.04", "size": "5.38"}, {"price": "0.07", "size": "2590.11"}, {"price": "0.08", "size": "5147.43"}, {"price": "0.09", "size": "100"}, {"price": "0.1", "size": "500"}, {"price": "0.11", "size": "5.73"}, {"price": "0.15", "size": "890.11"}, {"price": "0.16", "size": "1090.11"}, {"price": "0.2", "size": "50"}, {"price": "0.32", "size": "2.64"}, {"price": "0.34", "size": "60"}, {"price": "0.53", "size": "7440.27"}], "asks": [{"price": "0.99", "size": "8818.44"}, {"price": "0.98", "size": "1000"}, {"price": "0.97", "size": "10.29"}, {"price": "0.96", "size": "1100"}, {"price": "0.93", "size": "2590.11"}, {"price": "0.92", "size": "890.11"}, {"price": "0.9", "size": "995.98"}, {"price": "0.89", "size": "990.11"}, {"price": "0.79", "size": "37.34"}, {"price": "0.6", "size": "400"}], "event_type": "book", "last_trade_price": "0.530"}, {"market": "0x72ba07862b22314dbe4f409505a9833da2dfb3ffe2f6a1c8fa1ba3add5e7a039", "asset_id": "2984940558574601482400602739691261511463191599721533374910685943278753091727", "timestamp": "1769384056412", "hash": "48420921a88d56a1e40b22cae8c1719a4aa05e69", "bids": [{"price": "0.01", "size": "11206.36"}, {"price": "0.02", "size": "24.83"}, {"price": "0.03", "size": "5.47"}], "asks": [{"price": "0.99", "size": "8019.22"}, {"price": "0.98", "size": "5107.42"}], "event_type": "book", "last_trade_price": ""}, {"market": "0x98612f171f4dc6a0e346710a7729ea695ccc2e5f49437995894dfd0809884f0c", "asset_id": "47125239482019083915651528778718935257305702079962957861743905530721500306751", "timestamp": "1769383984878", "hash": "bc6572dd7b4c853c1448f00308b704f94773679e", "bids": [{"price": "0.01", "size": "8074.95"}, {"price": "0.02", "size": "5047.43"}, {"price": "0.03", "size": "11077.96"}, {"price": "0.42", "size": "400"}], "asks": [{"price": "0.99", "size": "8074.48"}, {"price": "0.98", "size": "5054.58"}, {"price": "0.97", "size": "8886.33"}, {"price": "0.95", "size": "16.08"}, {"price": "0.49", "size": "400"}], "event_type": "book", "last_trade_price": ""}, {"market": "0x72ba07862b22314dbe4f409505a9833da2dfb3ffe2f6a1c8fa1ba3add5e7a039", "asset_id": "93425111955845150480136289753481493030447902158015790781546943758014021748210", "timestamp": "1769384056412", "hash": "11551abc30a72732ef2b4e7f1fdbea2206f741a7", "bids": [{"price": "0.01", "size": "8019.22"}, {"price": "0.02", "size": "5107.42"}], "asks": [{"price": "0.99", "size": "11206.36"}, {"price": "0.98", "size": "24.83"}, {"price": "0.97", "size": "5.47"}], "event_type": "book", "last_trade_price": ""}, {"market": "0x050d4987d8be39002515c0fa150fdc0a7bbce0866834df64e0883e3aca16cebb", "asset_id": "54622260618686572723853734237251247285564699837184079846228858628426409826720", "timestamp": "1769383886055", "hash": "f5427b2c84e7381a5774dc2b5e41f49726133711", "bids": [{"price": "0.01", "size": "98.78"}, {"price": "0.02", "size": "25.63"}, {"price": "0.05", "size": "11.46"}], "asks": [{"price": "0.99", "size": "100"}, {"price": "0.98", "size": "39.99"}, {"price": "0.96", "size": "29.99"}], "event_type": "book", "last_trade_price": ""}, {"market": "0x050d4987d8be39002515c0fa150fdc0a7bbce0866834df64e0883e3aca16cebb", "asset_id": "46879560284701891629007918945256927799382824144519183690709895963589731438674", "timestamp": "1769383886055", "hash": "fa651e2a3a3e2fb0a995422c8b3ad2be001e85d3", "bids": [{"price": "0.01", "size": "100"}, {"price": "0.02", "size": "39.99"}, {"price": "0.04", "size": "29.99"}], "asks": [{"price": "0.99", "size": "98.78"}, {"price": "0.98", "size": "25.63"}, {"price": "0.95", "size": "11.46"}], "event_type": "book", "last_trade_price": ""}, {"market": "0xb483376a4a11938da0ae705f901db99f563a73f84df0d3dcb2c1bf7052ca279b", "asset_id": "38278925131304241066712865633907202764870863859804168264871289385839720357843", "timestamp": "1769383984694", "hash": "86981b991d544d446524759832623a70725213af", "bids": [{"price": "0.01", "size": "8075.27"}, {"price": "0.02", "size": "5052.52"}, {"price": "0.03", "size": "10156.43"}, {"price": "0.04", "size": "20.94"}, {"price": "0.42", "size": "400"}], "asks": [{"price": "0.99", "size": "8079.49"}, {"price": "0.98", "size": "5047.43"}, {"price": "0.97", "size": "3080.22"}, {"price": "0.49", "size": "400"}], "event_type": "book", "last_trade_price": ""}, {"market": "0x98612f171f4dc6a0e346710a7729ea695ccc2e5f49437995894dfd0809884f0c", "asset_id": "48560990866788733674131421352321870328649148949521354561724191929176618618723", "timestamp": "1769383984878", "hash": "e2cc54f6b9764d24498f2cfb71d59d325c536cea", "bids": [{"price": "0.01", "size": "8074.48"}, {"price": "0.02", "size": "5054.58"}, {"price": "0.03", "size": "8886.33"}, {"price": "0.05", "size": "16.08"}, {"price": "0.51", "size": "400"}], "asks": [{"price": "0.99", "size": "8074.95"}, {"price": "0.98", "size": "5047.43"}, {"price": "0.97", "size": "11077.96"}, {"price": "0.58", "size": "400"}], "event_type": "book", "last_trade_price": ""}]}
{"_local_timestamp": "2026-01-25T23:34:21.617550+00:00", "data": {"market": "0x88608442d14bdfa98a3d2ece26857aa516f193c8161db0c8e7c779fd8f3464af", "price_changes": [{"asset_id": "42097535137505280315737745177128192451567567237475285083506851409423497113459", "price": "0.1", "size": "895.98", "side": "BUY", "hash": "7a8a32df8db76c559c7c08e1caccc6f0292d6902", "best_bid": "0.4", "best_ask": "0.47"}, {"asset_id": "20794210232738155208360248995422719359166978550921485109532388301377529305580", "price": "0.9", "size": "895.98", "side": "SELL", "hash": "8370de655fe70a9a615877b9732562fcb58580d6", "best_bid": "0.53", "best_ask": "0.6"}], "timestamp": "1769384061552", "event_type": "price_change"}}
{"_local_timestamp": "2026-01-25T23:34:21.624402+00:00", "data": {"market": "0x88608442d14bdfa98a3d2ece26857aa516f193c8161db0c8e7c779fd8f3464af", "price_changes": [{"asset_id": "20794210232738155208360248995422719359166978550921485109532388301377529305580", "price": "0.09", "size": "0", "side": "BUY", "hash": "0574c68a0ffc0194d5b87aa9f32c8172f7fe84e3", "best_bid": "0.53", "best_ask": "0.6"}, {"asset_id": "42097535137505280315737745177128192451567567237475285083506851409423497113459", "price": "0.91", "size": "0", "side": "SELL", "hash": "a1ecfffbb260a7a019a2e5a883e50c68cad855c1", "best_bid": "0.4", "best_ask": "0.47"}], "timestamp": "1769384061552", "event_type": "price_change"}}
{"_local_timestamp": "2026-01-25T23:34:21.671482+00:00", "data": {"market": "0x88608442d14bdfa98a3d2ece26857aa516f193c8161db0c8e7c779fd8f3464af", "price_changes": [{"asset_id": "20794210232738155208360248995422719359166978550921485109532388301377529305580", "price": "0.15", "size": "0", "side": "BUY", "hash": "86ae0de1d07c714ba76c4630abe133c2f0cae080", "best_bid": "0.53", "best_ask": "0.6"}, {"asset_id": "42097535137505280315737745177128192451567567237475285083506851409423497113459", "price": "0.85", "size": "0", "side": "SELL", "hash": "e180b24c83bcad2afc091babd7a1b9919606a69b", "best_bid": "0.4", "best_ask": "0.47"}], "timestamp": "1769384061602", "event_type": "price_change"}}
{"_local_timestamp": "2026-01-25T23:34:21.672238+00:00", "data": {"market": "0x88608442d14bdfa98a3d2ece26857aa516f193c8161db0c8e7c779fd8f3464af", "price_changes": [{"asset_id": "20794210232738155208360248995422719359166978550921485109532388301377529305580", "price": "0.08", "size": "4257.32", "side": "BUY", "hash": "86ae0de1d07c714ba76c4630abe133c2f0cae080", "best_bid": "0.53", "best_ask": "0.6"}, {"asset_id": "42097535137505280315737745177128192451567567237475285083506851409423497113459", "price": "0.92", "size": "4257.32", "side": "SELL", "hash": "e180b24c83bcad2afc091babd7a1b9919606a69b", "best_bid": "0.4", "best_ask": "0.47"}], "timestamp": "1769384061602", "event_type": "price_change"}}
{"_local_timestamp": "2026-01-25T23:34:21.674300+00:00", "data": {"market": "0x88608442d14bdfa98a3d2ece26857aa516f193c8161db0c8e7c779fd8f3464af", "price_changes": [{"asset_id": "20794210232738155208360248995422719359166978550921485109532388301377529305580", "price": "0.07", "size": "1700", "side": "BUY", "hash": "86ae0de1d07c714ba76c4630abe133c2f0cae080", "best_bid": "0.53", "best_ask": "0.6"}, {"asset_id": "42097535137505280315737745177128192451567567237475285083506851409423497113459", "price": "0.93", "size": "1700", "side": "SELL", "hash": "e180b24c83bcad2afc091babd7a1b9919606a69b", "best_bid": "0.4", "best_ask": "0.47"}], "timestamp": "1769384061602", "event_type": "price_change"}}
{"_local_timestamp": "2026-01-25T23:34:21.677939+00:00", "data": {"market": "0x88608442d14bdfa98a3d2ece26857aa516f193c8161db0c8e7c779fd8f3464af", "price_changes": [{"asset_id": "42097535137505280315737745177128192451567567237475285083506851409423497113459", "price": "0.1", "size": "5.87", "side": "BUY", "hash": "afcd2f8e2e7ab11434e9dda0c6806e2ff2e86d60", "best_bid": "0.4", "best_ask": "0.47"}, {"asset_id": "20794210232738155208360248995422719359166978550921485109532388301377529305580", "price": "0.9", "size": "5.87", "side": "SELL", "hash": "932785bdc218ee4574194c24608c0de502d83d7a", "best_bid": "0.53", "best_ask": "0.6"}], "timestamp": "1769384061602", "event_type": "price_change"}}
{"_local_timestamp": "2026-01-25T23:34:21.678528+00:00", "data": {"market": "0x88608442d14bdfa98a3d2ece26857aa516f193c8161db0c8e7c779fd8f3464af", "price_changes": [{"asset_id": "42097535137505280315737745177128192451567567237475285083506851409423497113459", "price": "0.11", "size": "100", "side": "BUY", "hash": "afcd2f8e2e7ab11434e9dda0c6806e2ff2e86d60", "best_bid": "0.4", "best_ask": "0.47"}, {"asset_id": "20794210232738155208360248995422719359166978550921485109532388301377529305580", "price": "0.89", "size": "100", "side": "SELL", "hash": "932785bdc218ee4574194c24608c0de502d83d7a", "best_bid": "0.53", "best_ask": "0.6"}], "timestamp": "1769384061602", "event_type": "price_change"}}
{"_local_timestamp": "2026-01-25T23:34:21.697604+00:00", "data": {"market": "0x88608442d14bdfa98a3d2ece26857aa516f193c8161db0c8e7c779fd8f3464af", "price_changes": [{"asset_id": "42097535137505280315737745177128192451567567237475285083506851409423497113459", "price": "0.08", "size": "2160.21", "side": "BUY", "hash": "8da4622952db2f53b3696693c54411f135006d4a", "best_bid": "0.4", "best_ask": "0.47"}, {"asset_id": "20794210232738155208360248995422719359166978550921485109532388301377529305580", "price": "0.92", "size": "2160.21", "side": "SELL", "hash": "27ea79f3e8fd1b75b65f774533a9694c5184f348", "best_bid": "0.53", "best_ask": "0.6"}], "timestamp": "1769384061625", "event_type": "price_change"}}
{"_local_timestamp": "2026-01-25T23:34:21.698810+00:00", "data": {"market": "0x88608442d14bdfa98a3d2ece26857aa516f193c8161db0c8e7c779fd8f3464af", "price_changes": [{"asset_id": "42097535137505280315737745177128192451567567237475285083506851409423497113459", "price": "0.08", "size": "3050.32", "side": "BUY", "hash": "9d005356a0fe78d4ebe14af4939faae583309f80", "best_bid": "0.4", "best_ask": "0.47"}, {"asset_id": "20794210232738155208360248995422719359166978550921485109532388301377529305580", "price": "0.92", "size": "3050.32", "side": "SELL", "hash": "cdc85072086913af5b0211abe3d681af2e198115", "best_bid": "0.53", "best_ask": "0.6"}], "timestamp": "1769384061625", "event_type": "price_change"}}
{"_local_timestamp": "2026-01-25T23:34:21.735607+00:00", "data": {"market": "0x88608442d14bdfa98a3d2ece26857aa516f193c8161db0c8e7c779fd8f3464af", "price_changes": [{"asset_id": "20794210232738155208360248995422719359166978550921485109532388301377529305580", "price": "0.17", "size": "890.11", "side": "BUY", "hash": "cce42902893acb8cf07835b0ef0ab3e626046e47", "best_bid": "0.53", "best_ask": "0.6"}, {"asset_id": "42097535137505280315737745177128192451567567237475285083506851409423497113459", "price": "0.83", "size": "890.11", "side": "SELL", "hash": "8e5860c95361f0d3441227566634e97c7179a069", "best_bid": "0.4", "best_ask": "0.47"}], "timestamp": "1769384061663", "event_type": "price_change"}}
{"_local_timestamp": "2026-01-25T23:34:21.749255+00:00", "data": {"market": "0x88608442d14bdfa98a3d2ece26857aa516f193c8161db0c8e7c779fd8f3464af", "price_changes": [{"asset_id": "42097535137505280315737745177128192451567567237475285083506851409423497113459", "price": "0.08", "size": "5047.43", "side": "BUY", "hash": "223c55492fe3e9632b4b98f2899cf90d1530edb2", "best_bid": "0.4", "best_ask": "0.47"}, {"asset_id": "20794210232738155208360248995422719359166978550921485109532388301377529305580", "price": "0.92", "size": "5047.43", "side": "SELL", "hash": "feff8d98b824c8d8071d6caf73590a5db2759929", "best_bid": "0.53", "best_ask": "0.6"}], "timestamp": "1769384061664", "event_type": "price_change"}}
{"_local_timestamp": "2026-01-25T23:34:21.912743+00:00", "data": {"market": "0x88608442d14bdfa98a3d2ece26857aa516f193c8161db0c8e7c779fd8f3464af", "price_changes": [{"asset_id": "20794210232738155208360248995422719359166978550921485109532388301377529305580", "price": "0.1", "size": "600", "side": "BUY", "hash": "37a59a8bd42afe0db113443a4f7656dfebe9bc74", "best_bid": "0.53", "best_ask": "0.6"}, {"asset_id": "42097535137505280315737745177128192451567567237475285083506851409423497113459", "price": "0.9", "size": "600", "side": "SELL", "hash": "74e50bfbbb33080021c188b536a93b0f204da70c", "best_bid": "0.4", "best_ask": "0.47"}], "timestamp": "1769384061838", "event_type": "price_change"}}
{"_local_timestamp": "2026-01-25T23:34:29.294453+00:00", "data": {"market": "0x88608442d14bdfa98a3d2ece26857aa516f193c8161db0c8e7c779fd8f3464af", "price_changes": [{"asset_id": "20794210232738155208360248995422719359166978550921485109532388301377529305580", "price": "0.1", "size": "500", "side": "BUY", "hash": "c564e10a52859e2fe16e5b88a0b4ab849953668a", "best_bid": "0.53", "best_ask": "0.6"}, {"asset_id": "42097535137505280315737745177128192451567567237475285083506851409423497113459", "price": "0.9", "size": "500", "side": "SELL", "hash": "ff7972801d9fb1c2e5b579b05826610bbbca39e1", "best_bid": "0.4", "best_ask": "0.47"}], "timestamp": "1769384069218", "event_type": "price_change"}}
{"_local_timestamp": "2026-01-25T23:34:29.554878+00:00", "data": {"market": "0x88608442d14bdfa98a3d2ece26857aa516f193c8161db0c8e7c779fd8f3464af", "price_changes": [{"asset_id": "20794210232738155208360248995422719359166978550921485109532388301377529305580", "price": "0.08", "size": "4357.32", "side": "BUY", "hash": "b34348aebc05798300949e09fadc681d5b0f2afc", "best_bid": "0.53", "best_ask": "0.6"}, {"asset_id": "42097535137505280315737745177128192451567567237475285083506851409423497113459", "price": "0.92", "size": "4357.32", "side": "SELL", "hash": "d9be3221be26beca6a536a60a3f7a025923dfd23", "best_bid": "0.4", "best_ask": "0.47"}], "timestamp": "1769384069485", "event_type": "price_change"}}
{"_local_timestamp": "2026-01-25T23:34:30.016493+00:00", "data": {"market": "0x88608442d14bdfa98a3d2ece26857aa516f193c8161db0c8e7c779fd8f3464af", "price_changes": [{"asset_id": "20794210232738155208360248995422719359166978550921485109532388301377529305580", "price": "0.1", "size": "100", "side": "BUY", "hash": "cf8a0772b6aa1db091b54c0b4b8a25ccc6e670fe", "best_bid": "0.53", "best_ask": "0.6"}, {"asset_id": "42097535137505280315737745177128192451567567237475285083506851409423497113459", "price": "0.9", "size": "100", "side": "SELL", "hash": "74bf7325a715ecf00a01764ac38cb7730f0ba4ed", "best_bid": "0.4", "best_ask": "0.47"}], "timestamp": "1769384069833", "event_type": "price_change"}}
{"_local_timestamp": "2026-01-25T23:34:30.275260+00:00", "data": {"market": "0x88608442d14bdfa98a3d2ece26857aa516f193c8161db0c8e7c779fd8f3464af", "price_changes": [{"asset_id": "20794210232738155208360248995422719359166978550921485109532388301377529305580", "price": "0.08", "size": "4757.32", "side": "BUY", "hash": "81d48e0cfb718689891ec913b7c07c222ff5df9e", "best_bid": "0.53", "best_ask": "0.6"}, {"asset_id": "42097535137505280315737745177128192451567567237475285083506851409423497113459", "price": "0.92", "size": "4757.32", "side": "SELL", "hash": "76c5bac99c50f7c26f709b972d5f635fe5302c92", "best_bid": "0.4", "best_ask": "0.47"}], "timestamp": "1769384070110", "event_type": "price_change"}}
{"_local_timestamp": "2026-01-25T23:34:30.457086+00:00", "data": {"market": "0x88608442d14bdfa98a3d2ece26857aa516f193c8161db0c8e7c779fd8f3464af", "price_changes": [{"asset_id": "20794210232738155208360248995422719359166978550921485109532388301377529305580", "price": "0.09", "size": "1270.1", "side": "BUY", "hash": "35b34875efd5baaa152a5d5fde85488defb85eaa", "best_bid": "0.53", "best_ask": "0.6"}, {"asset_id": "42097535137505280315737745177128192451567567237475285083506851409423497113459", "price": "0.91", "size": "1270.1", "side": "SELL", "hash": "c7a6f84e20d279a0247d11771c9f072a9e2c238f", "best_bid": "0.4", "best_ask": "0.47"}], "timestamp": "1769384070293", "event_type": "price_change"}}
{"_local_timestamp": "2026-01-25T23:34:30.462311+00:00", "data": {"market": "0x88608442d14bdfa98a3d2ece26857aa516f193c8161db0c8e7c779fd8f3464af", "price_changes": [{"asset_id": "20794210232738155208360248995422719359166978550921485109532388301377529305580", "price": "0.09", "size": "3267.21", "side": "BUY", "hash": "aab9465d64e4d9655a0bc4d248e5853a07020b20", "best_bid": "0.53", "best_ask": "0.6"}, {"asset_id": "42097535137505280315737745177128192451567567237475285083506851409423497113459", "price": "0.91", "size": "3267.21", "side": "SELL", "hash": "1f840935a9ee879d93fee52d1dd891df090f728d", "best_bid": "0.4", "best_ask": "0.47"}], "timestamp": "1769384070294", "event_type": "price_change"}}
{"_local_timestamp": "2026-01-25T23:34:30.464802+00:00", "data": {"market": "0x88608442d14bdfa98a3d2ece26857aa516f193c8161db0c8e7c779fd8f3464af", "price_changes": [{"asset_id": "20794210232738155208360248995422719359166978550921485109532388301377529305580", "price": "0.09", "size": "4157.32", "side": "BUY", "hash": "a0db900231afdc41bc28271f5b8e22a0ad74bfb4", "best_bid": "0.53", "best_ask": "0.6"}, {"asset_id": "42097535137505280315737745177128192451567567237475285083506851409423497113459", "price": "0.91", "size": "4157.32", "side": "SELL", "hash": "542c72b512a4504427e095956311b0d7f7b00cff", "best_bid": "0.4", "best_ask": "0.47"}], "timestamp": "1769384070295", "event_type": "price_change"}}
{"_local_timestamp": "2026-01-25T23:34:30.950992+00:00", "data": {"market": "0x88608442d14bdfa98a3d2ece26857aa516f193c8161db0c8e7c779fd8f3464af", "price_changes": [{"asset_id": "42097535137505280315737745177128192451567567237475285083506851409423497113459", "price": "0.11", "size": "0", "side": "BUY", "hash": "3f1111bbf4ff337bb8f666fcce86e7271e34cded", "best_bid": "0.4", "best_ask": "0.47"}, {"asset_id": "20794210232738155208360248995422719359166978550921485109532388301377529305580", "price": "0.89", "size": "0", "side": "SELL", "hash": "516dc8126aa3cdffd4e928c3990b5a4b1e49154f", "best_bid": "0.53", "best_ask": "0.6"}], "timestamp": "1769384070882", "event_type": "price_change"}}
{"_local_timestamp": "2026-01-25T23:34:31.180192+00:00", "data": {"market": "0x88608442d14bdfa98a3d2ece26857aa516f193c8161db0c8e7c779fd8f3464af", "price_changes": [{"asset_id": "42097535137505280315737745177128192451567567237475285083506851409423497113459", "price": "0.08", "size": "5147.43", "side": "BUY", "hash": "76989b0d3049da98f6fe0f9820f47c56ba2d30ba", "best_bid": "0.4", "best_ask": "0.47"}, {"asset_id": "20794210232738155208360248995422719359166978550921485109532388301377529305580", "price": "0.92", "size": "5147.43", "side": "SELL", "hash": "4b096887977bbb743f559b2200e0d49adbc055c0", "best_bid": "0.53", "best_ask": "0.6"}], "timestamp": "1769384071112", "event_type": "price_change"}}
{"_local_timestamp": "2026-01-25T23:34:35.758945+00:00", "data": {"market": "0x72ba07862b22314dbe4f409505a9833da2dfb3ffe2f6a1c8fa1ba3add5e7a039", "price_changes": [{"asset_id": "2984940558574601482400602739691261511463191599721533374910685943278753091727", "price": "0.04", "size": "29.99", "side": "BUY", "hash": "257339282b6da3c28261f7931d069143813e6012", "best_bid": "0.04", "best_ask": "0.98"}, {"asset_id": "93425111955845150480136289753481493030447902158015790781546943758014021748210", "price": "0.96", "size": "29.99", "side": "SELL", "hash": "dab03e1ab4de54f965942f8b08c62572fafa9480", "best_bid": "0.02", "best_ask": "0.96"}], "timestamp": "1769384075688", "event_type": "price_change"}}
{"_local_timestamp": "2026-01-25T23:34:39.019790+00:00", "data": {"market": "0x72ba07862b22314dbe4f409505a9833da2dfb3ffe2f6a1c8fa1ba3add5e7a039", "price_changes": [{"asset_id": "2984940558574601482400602739691261511463191599721533374910685943278753091727", "price": "0.03", "size": "0", "side": "BUY", "hash": "38ec7032140d5869bd6979873b473b9b2a7dd5a0", "best_bid": "0.04", "best_ask": "0.98"}, {"asset_id": "93425111955845150480136289753481493030447902158015790781546943758014021748210", "price": "0.97", "size": "0", "side": "SELL", "hash": "34fd80d137de6daa531348f9adec85d8df7cf8fa", "best_bid": "0.02", "best_ask": "0.96"}], "timestamp": "1769384078927", "event_type": "price_change"}}
{"_local_timestamp": "2026-01-25T23:34:39.380129+00:00", "data": {"market": "0x72ba07862b22314dbe4f409505a9833da2dfb3ffe2f6a1c8fa1ba3add5e7a039", "price_changes": [{"asset_id": "2984940558574601482400602739691261511463191599721533374910685943278753091727", "price": "0.05", "size": "5.47", "side": "BUY", "hash": "95d26c4cffcf1e87c75b85d023b03d3402ba4a98", "best_bid": "0.05", "best_ask": "0.98"}, {"asset_id": "93425111955845150480136289753481493030447902158015790781546943758014021748210", "price": "0.95", "size": "5.47", "side": "SELL", "hash": "5adfdc254bedaf14e0849287c8385f2a4a01a96c", "best_bid": "0.02", "best_ask": "0.95"}], "timestamp": "1769384079248", "event_type": "price_change"}}
{"_local_timestamp": "2026-01-25T23:34:50.262464+00:00", "data": {"market": "0x88608442d14bdfa98a3d2ece26857aa516f193c8161db0c8e7c779fd8f3464af", "price_changes": [{"asset_id": "20794210232738155208360248995422719359166978550921485109532388301377529305580", "price": "0.1", "size": "0", "side": "BUY", "hash": "6feeb2d7d3948863e2a82cc672062da9a6f2291a", "best_bid": "0.53", "best_ask": "0.6"}, {"asset_id": "42097535137505280315737745177128192451567567237475285083506851409423497113459", "price": "0.9", "size": "0", "side": "SELL", "hash": "50b6d67c692865d90307567eb0e1a590457ec34b", "best_bid": "0.4", "best_ask": "0.47"}], "timestamp": "1769384090193", "event_type": "price_change"}}
{"_local_timestamp": "2026-01-25T23:34:50.480475+00:00", "data": {"market": "0x88608442d14bdfa98a3d2ece26857aa516f193c8161db0c8e7c779fd8f3464af", "price_changes": [{"asset_id": "20794210232738155208360248995422719359166978550921485109532388301377529305580", "price": "0.08", "size": "600", "side": "BUY", "hash": "d5f2fd2cf305d64557e68922af2a65b875bdc078", "best_bid": "0.53", "best_ask": "0.6"}, {"asset_id": "42097535137505280315737745177128192451567567237475285083506851409423497113459", "price": "0.92", "size": "600", "side": "SELL", "hash": "b84c6591a015410dbee6ab3225408fd2c48bc0aa", "best_bid": "0.4", "best_ask": "0.47"}], "timestamp": "1769384090411", "event_type": "price_change"}}
{"_local_timestamp": "2026-01-25T23:34:50.533608+00:00", "data": {"market": "0x88608442d14bdfa98a3d2ece26857aa516f193c8161db0c8e7c779fd8f3464af", "price_changes": [{"asset_id": "20794210232738155208360248995422719359166978550921485109532388301377529305580", "price": "0.08", "size": "700", "side": "BUY", "hash": "031cc9783c4037abe792a6b39903fc5ef2dab559", "best_bid": "0.53", "best_ask": "0.6"}, {"asset_id": "42097535137505280315737745177128192451567567237475285083506851409423497113459", "price": "0.92", "size": "700", "side": "SELL", "hash": "3b0c5aad0fa0c6976a1c71abaabf75bbb7c18d64", "best_bid": "0.4", "best_ask": "0.47"}], "timestamp": "1769384090464", "event_type": "price_change"}}
{"_local_timestamp": "2026-01-25T23:34:50.537464+00:00", "data": {"market": "0x88608442d14bdfa98a3d2ece26857aa516f193c8161db0c8e7c779fd8f3464af", "price_changes": [{"asset_id": "42097535137505280315737745177128192451567567237475285083506851409423497113459", "price": "0.08", "size": "5247.43", "side": "BUY", "hash": "239ab431d922f3e347b35d987338f0ebdf124f3d", "best_bid": "0.4", "best_ask": "0.47"}, {"asset_id": "20794210232738155208360248995422719359166978550921485109532388301377529305580", "price": "0.92", "size": "5247.43", "side": "SELL", "hash": "6ee0aac4b957c21f1ff0be69bd1df02a820c95b6", "best_bid": "0.53", "best_ask": "0.6"}], "timestamp": "1769384090465", "event_type": "price_change"}}
{"_local_timestamp": "2026-01-25T23:34:50.702850+00:00", "data": {"market": "0x88608442d14bdfa98a3d2ece26857aa516f193c8161db0c8e7c779fd8f3464af", "price_changes": [{"asset_id": "42097535137505280315737745177128192451567567237475285083506851409423497113459", "price": "0.09", "size": "890.11", "side": "BUY", "hash": "30877691d2664388f3e06618ce612c0ccc5f3cda", "best_bid": "0.4", "best_ask": "0.47"}, {"asset_id": "20794210232738155208360248995422719359166978550921485109532388301377529305580", "price": "0.91", "size": "890.11", "side": "SELL", "hash": "6b7fd863e9db86495ab5c05d60f1290e25363ffc", "best_bid": "0.53", "best_ask": "0.6"}], "timestamp": "1769384090630", "event_type": "price_change"}}
{"_local_timestamp": "2026-01-25T23:34:50.731480+00:00", "data": {"market": "0x88608442d14bdfa98a3d2ece26857aa516f193c8161db0c8e7c779fd8f3464af", "price_changes": [{"asset_id": "20794210232738155208360248995422719359166978550921485109532388301377529305580", "price": "0.16", "size": "890.11", "side": "BUY", "hash": "e2391668a25fd762b66fd8a87285a356c30406c8", "best_bid": "0.53", "best_ask": "0.6"}, {"asset_id": "42097535137505280315737745177128192451567567237475285083506851409423497113459", "price": "0.84", "size": "890.11", "side": "SELL", "hash": "c5f440974af2d1ac77088f1616cf895ce23a78b5", "best_bid": "0.4", "best_ask": "0.47"}], "timestamp": "1769384090660", "event_type": "price_change"}}
{"_local_timestamp": "2026-01-25T23:34:50.731944+00:00", "data": {"market": "0x88608442d14bdfa98a3d2ece26857aa516f193c8161db0c8e7c779fd8f3464af", "price_changes": [{"asset_id": "20794210232738155208360248995422719359166978550921485109532388301377529305580", "price": "0.08", "size": "300", "side": "BUY", "hash": "e2391668a25fd762b66fd8a87285a356c30406c8", "best_bid": "0.53", "best_ask": "0.6"}, {"asset_id": "42097535137505280315737745177128192451567567237475285083506851409423497113459", "price": "0.92", "size": "300", "side": "SELL", "hash": "c5f440974af2d1ac77088f1616cf895ce23a78b5", "best_bid": "0.4", "best_ask": "0.47"}], "timestamp": "1769384090660", "event_type": "price_change"}}
{"_local_timestamp": "2026-01-25T23:34:50.834427+00:00", "data": {"market": "0x88608442d14bdfa98a3d2ece26857aa516f193c8161db0c8e7c779fd8f3464af", "price_changes": [{"asset_id": "20794210232738155208360248995422719359166978550921485109532388301377529305580", "price": "0.08", "size": "2297.11", "side": "BUY", "hash": "243b92e09b9d29792e9e070b033f8ce143e76723", "best_bid": "0.53", "best_ask": "0.6"}, {"asset_id": "42097535137505280315737745177128192451567567237475285083506851409423497113459", "price": "0.92", "size": "2297.11", "side": "SELL", "hash": "5943ca4562943e47f2f026bc977a4aa2f07809d4", "best_bid": "0.4", "best_ask": "0.47"}], "timestamp": "1769384090762", "event_type": "price_change"}}
{"_local_timestamp": "2026-01-25T23:34:51.356874+00:00", "data": {"market": "0x88608442d14bdfa98a3d2ece26857aa516f193c8161db0c8e7c779fd8f3464af", "price_changes": [{"asset_id": "20794210232738155208360248995422719359166978550921485109532388301377529305580", "price": "0.08", "size": "3187.22", "side": "BUY", "hash": "f7966636c06024edc193fb2ab15bdbbf5d551aa2", "best_bid": "0.53", "best_ask": "0.6"}, {"asset_id": "42097535137505280315737745177128192451567567237475285083506851409423497113459", "price": "0.92", "size": "3187.22", "side": "SELL", "hash": "03ed50c4e7f63c14bef7b5131546111f1d0ab5b4", "best_bid": "0.4", "best_ask": "0.47"}], "timestamp": "1769384090763", "event_type": "price_change"}}
{"_local_timestamp": "2026-01-25T23:34:51.357302+00:00", "data": {"market": "0x88608442d14bdfa98a3d2ece26857aa516f193c8161db0c8e7c779fd8f3464af", "price_changes": [{"asset_id": "20794210232738155208360248995422719359166978550921485109532388301377529305580", "price": "0.08", "size": "4457.32", "side": "BUY", "hash": "26694ad7513a37642c94bfa6c5e798aeb1f9152c", "best_bid": "0.53", "best_ask": "0.6"}, {"asset_id": "42097535137505280315737745177128192451567567237475285083506851409423497113459", "price": "0.92", "size": "4457.32", "side": "SELL", "hash": "b6df7f64b96e51aa27fb75179c6ce958b9840571", "best_bid": "0.4", "best_ask": "0.47"}], "timestamp": "1769384090792", "event_type": "price_change"}}
{"_local_timestamp": "2026-01-25T23:34:51.492746+00:00", "data": {"market": "0x88608442d14bdfa98a3d2ece26857aa516f193c8161db0c8e7c779fd8f3464af", "price_changes": [{"asset_id": "20794210232738155208360248995422719359166978550921485109532388301377529305580", "price": "0.17", "size": "1090.11", "side": "BUY", "hash": "022bed3a9768af956e315fecc078eb4092c0f291", "best_bid": "0.53", "best_ask": "0.6"}, {"asset_id": "42097535137505280315737745177128192451567567237475285083506851409423497113459", "price": "0.83", "size": "1090.11", "side": "SELL", "hash": "6360ec54abc63fae4017ef6e880702bfc7a1b662", "best_bid": "0.4", "best_ask": "0.47"}], "timestamp": "1769384090942", "event_type": "price_change"}}
{"_local_timestamp": "2026-01-25T23:34:51.493170+00:00", "data": {"market": "0x88608442d14bdfa98a3d2ece26857aa516f193c8161db0c8e7c779fd8f3464af", "price_changes": [{"asset_id": "20794210232738155208360248995422719359166978550921485109532388301377529305580", "price": "0.09", "size": "4557.32", "side": "BUY", "hash": "8e346ebc7bbc0025d3c19535a8c4e8e98853db54", "best_bid": "0.53", "best_ask": "0.6"}, {"asset_id": "42097535137505280315737745177128192451567567237475285083506851409423497113459", "price": "0.91", "size": "4557.32", "side": "SELL", "hash": "7e88da6d9ffda4241526b90a74fcb21683304404", "best_bid": "0.4", "best_ask": "0.47"}], "timestamp": "1769384090943", "event_type": "price_change"}}
{"_local_timestamp": "2026-01-25T23:34:51.493543+00:00", "data": {"market": "0x88608442d14bdfa98a3d2ece26857aa516f193c8161db0c8e7c779fd8f3464af", "price_changes": [{"asset_id": "42097535137505280315737745177128192451567567237475285083506851409423497113459", "price": "0.08", "size": "5647.43", "side": "BUY", "hash": "14bbe037fa4f3b362b13a7b73d5f5525efd10ee8", "best_bid": "0.4", "best_ask": "0.47"}, {"asset_id": "20794210232738155208360248995422719359166978550921485109532388301377529305580", "price": "0.92", "size": "5647.43", "side": "SELL", "hash": "a880c9ba85aa7a05076adb31b783c466064829e0", "best_bid": "0.53", "best_ask": "0.6"}], "timestamp": "1769384090944", "event_type": "price_change"}}
{"_local_timestamp": "2026-01-25T23:34:56.660649+00:00", "data": {"market": "0x88608442d14bdfa98a3d2ece26857aa516f193c8161db0c8e7c779fd8f3464af", "price_changes": [{"asset_id": "20794210232738155208360248995422719359166978550921485109532388301377529305580", "price": "0.08", "size": "4357.32", "side": "BUY", "hash": "0631c9358b4c37bae8813a246f66832087136d86", "best_bid": "0.53", "best_ask": "0.6"}, {"asset_id": "42097535137505280315737745177128192451567567237475285083506851409423497113459", "price": "0.92", "size": "4357.32", "side": "SELL", "hash": "858479ed161e2efb4841618c2a52831d51e69f2a", "best_bid": "0.4", "best_ask": "0.47"}], "timestamp": "1769384096590", "event_type": "price_change"}}
{"_local_timestamp": "2026-01-25T23:34:56.737653+00:00", "data": {"market": "0x88608442d14bdfa98a3d2ece26857aa516f193c8161db0c8e7c779fd8f3464af", "price_changes": [{"asset_id": "42097535137505280315737745177128192451567567237475285083506851409423497113459", "price": "0.08", "size": "1490.11", "side": "BUY", "hash": "6aa17362f537f59c00b98a418ef92a20b4bceb69", "best_bid": "0.4", "best_ask": "0.47"}, {"asset_id": "20794210232738155208360248995422719359166978550921485109532388301377529305580", "price": "0.92", "size": "1490.11", "side": "SELL", "hash": "c6b94b4bb95755d2375d50d845d0b114fd68c1df", "best_bid": "0.53", "best_ask": "0.6"}], "timestamp": "1769384096672", "event_type": "price_change"}}
{"_local_timestamp": "2026-01-25T23:34:56.738923+00:00", "data": {"market": "0x88608442d14bdfa98a3d2ece26857aa516f193c8161db0c8e7c779fd8f3464af", "price_changes": [{"asset_id": "42097535137505280315737745177128192451567567237475285083506851409423497113459", "price": "0.07", "size": "1700", "side": "BUY", "hash": "6aa17362f537f59c00b98a418ef92a20b4bceb69", "best_bid": "0.4", "best_ask": "0.47"}, {"asset_id": "20794210232738155208360248995422719359166978550921485109532388301377529305580", "price": "0.93", "size": "1700", "side": "SELL", "hash": "c6b94b4bb95755d2375d50d845d0b114fd68c1df", "best_bid": "0.53", "best_ask": "0.6"}], "timestamp": "1769384096672", "event_type": "price_change"}}
{"_local_timestamp": "2026-01-25T23:34:56.741101+00:00", "data": {"market": "0x88608442d14bdfa98a3d2ece26857aa516f193c8161db0c8e7c779fd8f3464af", "price_changes": [{"asset_id": "20794210232738155208360248995422719359166978550921485109532388301377529305580", "price": "0.09", "size": "400", "side": "BUY", "hash": "ef59c14c0e7dcab6d2fee973d37462bbe0f26f1d", "best_bid": "0.53", "best_ask": "0.6"}, {"asset_id": "42097535137505280315737745177128192451567567237475285083506851409423497113459", "price": "0.91", "size": "400", "side": "SELL", "hash": "d1105af70e480cbc6944505a39928a6de253e54f", "best_bid": "0.4", "best_ask": "0.47"}], "timestamp": "1769384096672", "event_type": "price_change"}}
{"_local_timestamp": "2026-01-25T23:34:56.792915+00:00", "data": {"market": "0x88608442d14bdfa98a3d2ece26857aa516f193c8161db0c8e7c779fd8f3464af", "price_changes": [{"asset_id": "20794210232738155208360248995422719359166978550921485109532388301377529305580", "price": "0.16", "size": "0", "side": "BUY", "hash": "ef59c14c0e7dcab6d2fee973d37462bbe0f26f1d", "best_bid": "0.53", "best_ask": "0.6"}, {"asset_id": "42097535137505280315737745177128192451567567237475285083506851409423497113459", "price": "0.84", "size": "0", "side": "SELL", "hash": "d1105af70e480cbc6944505a39928a6de253e54f", "best_bid": "0.4", "best_ask": "0.47"}], "timestamp": "1769384096672", "event_type": "price_change"}}
{"_local_timestamp": "2026-01-25T23:34:56.793360+00:00", "data": {"market": "0x88608442d14bdfa98a3d2ece26857aa516f193c8161db0c8e7c779fd8f3464af", "price_changes": [{"asset_id": "42097535137505280315737745177128192451567567237475285083506851409423497113459", "price": "0.09", "size": "1780.22", "side": "BUY", "hash": "308ee8aedcf84279028220d293c458d910fbeb4f", "best_bid": "0.4", "best_ask": "0.47"}, {"asset_id": "20794210232738155208360248995422719359166978550921485109532388301377529305580", "price": "0.91", "size": "1780.22", "side": "SELL", "hash": "fe83b206766be2525ffda527d31c4daf40e24fcb", "best_bid": "0.53", "best_ask": "0.6"}], "timestamp": "1769384096686", "event_type": "price_change"}}
{"_local_timestamp": "2026-01-25T23:34:56.793745+00:00", "data": {"market": "0x88608442d14bdfa98a3d2ece26857aa516f193c8161db0c8e7c779fd8f3464af", "price_changes": [{"asset_id": "42097535137505280315737745177128192451567567237475285083506851409423497113459", "price": "0.09", "size": "3777.33", "side": "BUY", "hash": "dba742cb4996913bd2eb7a611ecc683d0e294bee", "best_bid": "0.4", "best_ask": "0.47"}, {"asset_id": "20794210232738155208360248995422719359166978550921485109532388301377529305580", "price": "0.91", "size": "3777.33", "side": "SELL", "hash": "59376c94eb794804835154482dc48e60a2be10df", "best_bid": "0.53", "best_ask": "0.6"}], "timestamp": "1769384096689", "event_type": "price_change"}}
{"_local_timestamp": "2026-01-25T23:34:56.794134+00:00", "data": {"market": "0x88608442d14bdfa98a3d2ece26857aa516f193c8161db0c8e7c779fd8f3464af", "price_changes": [{"asset_id": "42097535137505280315737745177128192451567567237475285083506851409423497113459", "price": "0.09", "size": "5047.43", "side": "BUY", "hash": "97258085825738e7aac829b8866512992671b118", "best_bid": "0.4", "best_ask": "0.47"}, {"asset_id": "20794210232738155208360248995422719359166978550921485109532388301377529305580", "price": "0.91", "size": "5047.43", "side": "SELL", "hash": "b7a43926658feacb2fafc604b69cd92016d71f56", "best_bid": "0.53", "best_ask": "0.6"}], "timestamp": "1769384096692", "event_type": "price_change"}}
{"_local_timestamp": "2026-01-25T23:34:56.869957+00:00", "data": {"market": "0x88608442d14bdfa98a3d2ece26857aa516f193c8161db0c8e7c779fd8f3464af", "price_changes": [{"asset_id": "20794210232738155208360248995422719359166978550921485109532388301377529305580", "price": "0.18", "size": "890.11", "side": "BUY", "hash": "49b377f12719fd6b7295f7370780956ea88a8ccc", "best_bid": "0.53", "best_ask": "0.6"}, {"asset_id": "42097535137505280315737745177128192451567567237475285083506851409423497113459", "price": "0.82", "size": "890.11", "side": "SELL", "hash": "c13c34cc562da4b2b62ed1add81b4dacc39ca4b7", "best_bid": "0.4", "best_ask": "0.47"}], "timestamp": "1769384096695", "event_type": "price_change"}}
{"_local_timestamp": "2026-01-25T23:34:56.913472+00:00", "data": {"market": "0x88608442d14bdfa98a3d2ece26857aa516f193c8161db0c8e7c779fd8f3464af", "price_changes": [{"asset_id": "42097535137505280315737745177128192451567567237475285083506851409423497113459", "price": "0.08", "size": "1590.11", "side": "BUY", "hash": "89edad989fc6dbef8946640e8ca21036e9f105f7", "best_bid": "0.4", "best_ask": "0.47"}, {"asset_id": "20794210232738155208360248995422719359166978550921485109532388301377529305580", "price": "0.92", "size": "1590.11", "side": "SELL", "hash": "6af691db0a933017884e438427e3d4952d823aee", "best_bid": "0.53", "best_ask": "0.6"}], "timestamp": "1769384096845", "event_type": "price_change"}}
{"_local_timestamp": "2026-01-25T23:34:56.913996+00:00", "data": {"market": "0x88608442d14bdfa98a3d2ece26857aa516f193c8161db0c8e7c779fd8f3464af", "price_changes": [{"asset_id": "20794210232738155208360248995422719359166978550921485109532388301377529305580", "price": "0.09", "size": "500", "side": "BUY", "hash": "922627e059a6a885150a9e9d2a11b73331692c88", "best_bid": "0.53", "best_ask": "0.6"}, {"asset_id": "42097535137505280315737745177128192451567567237475285083506851409423497113459", "price": "0.91", "size": "500", "side": "SELL", "hash": "14553aeaa2cc925ffe06c5a727b7dcaa59f07028", "best_bid": "0.4", "best_ask": "0.47"}], "timestamp": "1769384096846", "event_type": "price_change"}}
{"_local_timestamp": "2026-01-25T23:34:56.949101+00:00", "data": {"market": "0x88608442d14bdfa98a3d2ece26857aa516f193c8161db0c8e7c779fd8f3464af", "price_changes": [{"asset_id": "20794210232738155208360248995422719359166978550921485109532388301377529305580", "price": "0.1", "size": "5999.11", "side": "BUY", "hash": "204358c4679aafb56b637919846619156eef4a94", "best_bid": "0.53", "best_ask": "0.6"}, {"asset_id": "42097535137505280315737745177128192451567567237475285083506851409423497113459", "price": "0.9", "size": "5999.11", "side": "SELL", "hash": "8afb86f45f7e3b09a73213b43c27a4762daa00fb", "best_bid": "0.4", "best_ask": "0.47"}], "timestamp": "1769384096884", "event_type": "price_change"}}
{"_local_timestamp": "2026-01-25T23:34:58.187658+00:00", "data": {"market": "0x72ba07862b22314dbe4f409505a9833da2dfb3ffe2f6a1c8fa1ba3add5e7a039", "price_changes": [{"asset_id": "93425111955845150480136289753481493030447902158015790781546943758014021748210", "price": "0.01", "size": "7019.22", "side": "BUY", "hash": "8f01f40844a430656459dc1e81f42e51b711fdf7", "best_bid": "0.02", "best_ask": "0.95"}, {"asset_id": "2984940558574601482400602739691261511463191599721533374910685943278753091727", "price": "0.99", "size": "7019.22", "side": "SELL", "hash": "254e14a670eb97807d5eb595bfbe52a0f5c89bf8", "best_bid": "0.05", "best_ask": "0.98"}], "timestamp": "1769384098113", "event_type": "price_change"}}
{"_local_timestamp": "2026-01-25T23:34:58.428147+00:00", "data": {"market": "0x72ba07862b22314dbe4f409505a9833da2dfb3ffe2f6a1c8fa1ba3add5e7a039", "price_changes": [{"asset_id": "93425111955845150480136289753481493030447902158015790781546943758014021748210", "price": "0.01", "size": "9016.33", "side": "BUY", "hash": "4e19c891723e215ea4a6468de84ad03d9553f5ee", "best_bid": "0.02", "best_ask": "0.95"}, {"asset_id": "2984940558574601482400602739691261511463191599721533374910685943278753091727", "price": "0.99", "size": "9016.33", "side": "SELL", "hash": "58b0c001d74907a23aa7f769f9bd0f9fc32b60ed", "best_bid": "0.05", "best_ask": "0.98"}], "timestamp": "1769384098358", "event_type": "price_change"}}
{"_local_timestamp": "2026-01-25T23:34:58.428665+00:00", "data": {"market": "0x72ba07862b22314dbe4f409505a9833da2dfb3ffe2f6a1c8fa1ba3add5e7a039", "price_changes": [{"asset_id": "93425111955845150480136289753481493030447902158015790781546943758014021748210", "price": "0.01", "size": "9906.44", "side": "BUY", "hash": "65acf78fb7090af7fa69bccc2b4b790df6001686", "best_bid": "0.02", "best_ask": "0.95"}, {"asset_id": "2984940558574601482400602739691261511463191599721533374910685943278753091727", "price": "0.99", "size": "9906.44", "side": "SELL", "hash": "5da47930751f14832fc10570ad20b88ff2548817", "best_bid": "0.05", "best_ask": "0.98"}], "timestamp": "1769384098359", "event_type": "price_change"}}
{"_local_timestamp": "2026-01-25T23:34:58.429048+00:00", "data": {"market": "0x72ba07862b22314dbe4f409505a9833da2dfb3ffe2f6a1c8fa1ba3add5e7a039", "price_changes": [{"asset_id": "93425111955845150480136289753481493030447902158015790781546943758014021748210", "price": "0.01", "size": "11176.54", "side": "BUY", "hash": "b66b7dc972e7989a2b42c2e549a00de1552367f2", "best_bid": "0.02", "best_ask": "0.95"}, {"asset_id": "2984940558574601482400602739691261511463191599721533374910685943278753091727", "price": "0.99", "size": "11176.54", "side": "SELL", "hash": "61fe99f8a4d84b94240ed80300c9f5f1e30986a9", "best_bid": "0.05", "best_ask": "0.98"}], "timestamp": "1769384098359", "event_type": "price_change"}}
{"_local_timestamp": "2026-01-25T23:35:01.811243+00:00", "data": {"market": "0x88608442d14bdfa98a3d2ece26857aa516f193c8161db0c8e7c779fd8f3464af", "price_changes": [{"asset_id": "20794210232738155208360248995422719359166978550921485109532388301377529305580", "price": "0.08", "size": "4257.32", "side": "BUY", "hash": "a63946f31ffd8dea376059c9d124a1e810645124", "best_bid": "0.53", "best_ask": "0.6"}, {"asset_id": "42097535137505280315737745177128192451567567237475285083506851409423497113459", "price": "0.92", "size": "4257.32", "side": "SELL", "hash": "6726e064c5444d40d9944169a89be57d3039dd8d", "best_bid": "0.4", "best_ask": "0.47"}], "timestamp": "1769384101738", "event_type": "price_change"}}
{"_local_timestamp": "2026-01-25T23:35:01.984512+00:00", "data": {"market": "0x88608442d14bdfa98a3d2ece26857aa516f193c8161db0c8e7c779fd8f3464af", "price_changes": [{"asset_id": "20794210232738155208360248995422719359166978550921485109532388301377529305580", "price": "0.1", "size": "0", "side": "BUY", "hash": "9f6033bb57930472c6555899facb8647bd0cf174", "best_bid": "0.53", "best_ask": "0.6"}, {"asset_id": "42097535137505280315737745177128192451567567237475285083506851409423497113459", "price": "0.9", "size": "0", "side": "SELL", "hash": "bafb12895a97df7e1badc160548245be366ff4a2", "best_bid": "0.4", "best_ask": "0.47"}], "timestamp": "1769384101917", "event_type": "price_change"}}
{"_local_timestamp": "2026-01-25T23:35:02.098081+00:00", "data": {"market": "0x88608442d14bdfa98a3d2ece26857aa516f193c8161db0c8e7c779fd8f3464af", "price_changes": [{"asset_id": "42097535137505280315737745177128192451567567237475285083506851409423497113459", "price": "0.08", "size": "1690.11", "side": "BUY", "hash": "e37e3793b63329820368390a9d36e000c2c74d08", "best_bid": "0.4", "best_ask": "0.47"}, {"asset_id": "20794210232738155208360248995422719359166978550921485109532388301377529305580", "price": "0.92", "size": "1690.11", "side": "SELL", "hash": "aebc32c2b3cc06634f690a6fcf2a659dfbec2444", "best_bid": "0.53", "best_ask": "0.6"}], "timestamp": "1769384102011", "event_type": "price_change"}}
{"_local_timestamp": "2026-01-25T23:35:02.099899+00:00", "data": {"market": "0x88608442d14bdfa98a3d2ece26857aa516f193c8161db0c8e7c779fd8f3464af", "price_changes": [{"asset_id": "20794210232738155208360248995422719359166978550921485109532388301377529305580", "price": "0.09", "size": "600", "side": "BUY", "hash": "5906554bb5f3ed970af5170e51a9b126f2adb2ec", "best_bid": "0.53", "best_ask": "0.6"}, {"asset_id": "42097535137505280315737745177128192451567567237475285083506851409423497113459", "price": "0.91", "size": "600", "side": "SELL", "hash": "1b96fea8d3d94d134a252baca3657d0744d5b816", "best_bid": "0.4", "best_ask": "0.47"}], "timestamp": "1769384102012", "event_type": "price_change"}}
{"_local_timestamp": "2026-01-25T23:35:02.213910+00:00", "data": {"market": "0x88608442d14bdfa98a3d2ece26857aa516f193c8161db0c8e7c779fd8f3464af", "price_changes": [{"asset_id": "20794210232738155208360248995422719359166978550921485109532388301377529305580", "price": "0.1", "size": "1997.11", "side": "BUY", "hash": "0f868e0659ef26999c2b6d6a48f106d7ab9a2f6f", "best_bid": "0.53", "best_ask": "0.6"}, {"asset_id": "42097535137505280315737745177128192451567567237475285083506851409423497113459", "price": "0.9", "size": "1997.11", "side": "SELL", "hash": "6b5539fb9d5115cb988581c4ea3077995a351529", "best_bid": "0.4", "best_ask": "0.47"}], "timestamp": "1769384102146", "event_type": "price_change"}}
{"_local_timestamp": "2026-01-25T23:35:02.214390+00:00", "data": {"market": "0x88608442d14bdfa98a3d2ece26857aa516f193c8161db0c8e7c779fd8f3464af", "price_changes": [{"asset_id": "20794210232738155208360248995422719359166978550921485109532388301377529305580", "price": "0.1", "size": "2887.22", "side": "BUY", "hash": "6d7a317918adba33970f04d94cb8f79c7b213667", "best_bid": "0.53", "best_ask": "0.6"}, {"asset_id": "42097535137505280315737745177128192451567567237475285083506851409423497113459", "price": "0.9", "size": "2887.22", "side": "SELL", "hash": "83223f0b33513729686c8318e3978c7ba9cc14d5", "best_bid": "0.4", "best_ask": "0.47"}], "timestamp": "1769384102147", "event_type": "price_change"}}
{"_local_timestamp": "2026-01-25T23:35:02.214803+00:00", "data": {"market": "0x88608442d14bdfa98a3d2ece26857aa516f193c8161db0c8e7c779fd8f3464af", "price_changes": [{"asset_id": "20794210232738155208360248995422719359166978550921485109532388301377529305580", "price": "0.1", "size": "4157.32", "side": "BUY", "hash": "9f5fa22c40c3dc869b8bfd1498af1e19ceea841d", "best_bid": "0.53", "best_ask": "0.6"}, {"asset_id": "42097535137505280315737745177128192451567567237475285083506851409423497113459", "price": "0.9", "size": "4157.32", "side": "SELL", "hash": "b9521e1e918a9de21e090ac50ce7933f21c90263", "best_bid": "0.4", "best_ask": "0.47"}], "timestamp": "1769384102147", "event_type": "price_change"}}
{"_local_timestamp": "2026-01-25T23:35:06.834967+00:00", "data": {"market": "0x88608442d14bdfa98a3d2ece26857aa516f193c8161db0c8e7c779fd8f3464af", "price_changes": [{"asset_id": "42097535137505280315737745177128192451567567237475285083506851409423497113459", "price": "0.08", "size": "1590.11", "side": "BUY", "hash": "e0128139a91dc24e205a4966d91f9eb7d2efb29a", "best_bid": "0.4", "best_ask": "0.47"}, {"asset_id": "20794210232738155208360248995422719359166978550921485109532388301377529305580", "price": "0.92", "size": "1590.11", "side": "SELL", "hash": "2207b6e9def4ced1dbe0237c49cf5eaf80721296", "best_bid": "0.53", "best_ask": "0.6"}], "timestamp": "1769384106760", "event_type": "price_change"}}
{"_local_timestamp": "2026-01-25T23:35:06.888812+00:00", "data": {"market": "0x88608442d14bdfa98a3d2ece26857aa516f193c8161db0c8e7c779fd8f3464af", "price_changes": [{"asset_id": "20794210232738155208360248995422719359166978550921485109532388301377529305580", "price": "0.08", "size": "2097.11", "side": "BUY", "hash": "79f5994919ee6460d52e703eb3a71322bd36c76d", "best_bid": "0.53", "best_ask": "0.6"}, {"asset_id": "42097535137505280315737745177128192451567567237475285083506851409423497113459", "price": "0.92", "size": "2097.11", "side": "SELL", "hash": "1382f2468a9945dbef8de22a4be41f64cba6aefe", "best_bid": "0.4", "best_ask": "0.47"}], "timestamp": "1769384106818", "event_type": "price_change"}}
{"_local_timestamp": "2026-01-25T23:35:06.976788+00:00", "data": {"market": "0x88608442d14bdfa98a3d2ece26857aa516f193c8161db0c8e7c779fd8f3464af", "price_changes": [{"asset_id": "20794210232738155208360248995422719359166978550921485109532388301377529305580", "price": "0.08", "size": "100", "side": "BUY", "hash": "58711ce063a6a2a3457d9d09cb11b8b6c9197701", "best_bid": "0.53", "best_ask": "0.6"}, {"asset_id": "42097535137505280315737745177128192451567567237475285083506851409423497113459", "price": "0.92", "size": "100", "side": "SELL", "hash": "41af65e3e0ffc188b0ea4a1c41a4c5397455e6ae", "best_bid": "0.4", "best_ask": "0.47"}], "timestamp": "1769384106907", "event_type": "price_change"}}
{"_local_timestamp": "2026-01-25T23:35:07.044842+00:00", "data": {"market": "0x88608442d14bdfa98a3d2ece26857aa516f193c8161db0c8e7c779fd8f3464af", "price_changes": [{"asset_id": "42097535137505280315737745177128192451567567237475285083506851409423497113459", "price": "0.09", "size": "5147.43", "side": "BUY", "hash": "c9dfcd0ce9b20699cbdc9643a811f191ea59b7dd", "best_bid": "0.4", "best_ask": "0.47"}, {"asset_id": "20794210232738155208360248995422719359166978550921485109532388301377529305580", "price": "0.91", "size": "5147.43", "side": "SELL", "hash": "301d32346d9cde26fd9efb7e175270beb04af526", "best_bid": "0.53", "best_ask": "0.6"}], "timestamp": "1769384106975", "event_type": "price_change"}}
{"_local_timestamp": "2026-01-25T23:35:07.288525+00:00", "data": {"market": "0x72ba07862b22314dbe4f409505a9833da2dfb3ffe2f6a1c8fa1ba3add5e7a039", "price_changes": [{"asset_id": "93425111955845150480136289753481493030447902158015790781546943758014021748210", "price": "0.5", "size": "222.22", "side": "BUY", "hash": "2f7e097e9ab47ccb831037b01fe5a2de4c3a2f98", "best_bid": "0.5", "best_ask": "0.95"}, {"asset_id": "2984940558574601482400602739691261511463191599721533374910685943278753091727", "price": "0.5", "size": "222.22", "side": "SELL", "hash": "bec9230f9e7e5e4c1515d1f9c96ddbeb44838912", "best_bid": "0.05", "best_ask": "0.5"}], "timestamp": "1769384107226", "event_type": "price_change"}}
{"_local_timestamp": "2026-01-25T23:35:07.388955+00:00", "data": {"market": "0x72ba07862b22314dbe4f409505a9833da2dfb3ffe2f6a1c8fa1ba3add5e7a039", "price_changes": [{"asset_id": "93425111955845150480136289753481493030447902158015790781546943758014021748210", "price": "0.02", "size": "59.99", "side": "BUY", "hash": "23bd834e373399b5a719c0036f2011a137357f81", "best_bid": "0.5", "best_ask": "0.95"}, {"asset_id": "2984940558574601482400602739691261511463191599721533374910685943278753091727", "price": "0.98", "size": "59.99", "side": "SELL", "hash": "ca9e6d77ffe54685cab740296091db8cc52fc9d5", "best_bid": "0.05", "best_ask": "0.5"}], "timestamp": "1769384107320", "event_type": "price_change"}}
{"_local_timestamp": "2026-01-25T23:35:12.486353+00:00", "data": {"market": "0x88608442d14bdfa98a3d2ece26857aa516f193c8161db0c8e7c779fd8f3464af", "price_changes": [{"asset_id": "42097535137505280315737745177128192451567567237475285083506851409423497113459", "price": "0.08", "size": "1190.11", "side": "BUY", "hash": "160fe1a61578b7bb5b02c6816049349171ef42b9", "best_bid": "0.4", "best_ask": "0.47"}, {"asset_id": "20794210232738155208360248995422719359166978550921485109532388301377529305580", "price": "0.92", "size": "1190.11", "side": "SELL", "hash": "a7fa506fcc484542e69ba16303b5c999dced79f8", "best_bid": "0.53", "best_ask": "0.6"}], "timestamp": "1769384112422", "event_type": "price_change"}}
{"_local_timestamp": "2026-01-25T23:35:12.501993+00:00", "data": {"market": "0x88608442d14bdfa98a3d2ece26857aa516f193c8161db0c8e7c779fd8f3464af", "price_changes": [{"asset_id": "20794210232738155208360248995422719359166978550921485109532388301377529305580", "price": "0.17", "size": "890.11", "side": "BUY", "hash": "0ae16e6ac0270c32c65bec749c154409f94ff2a5", "best_bid": "0.53", "best_ask": "0.6"}, {"asset_id": "42097535137505280315737745177128192451567567237475285083506851409423497113459", "price": "0.83", "size": "890.11", "side": "SELL", "hash": "b626073fcb186020362cd920b7a6d9a5822d27b9", "best_bid": "0.4", "best_ask": "0.47"}], "timestamp": "1769384112422", "event_type": "price_change"}}
{"_local_timestamp": "2026-01-25T23:35:12.502526+00:00", "data": {"market": "0x88608442d14bdfa98a3d2ece26857aa516f193c8161db0c8e7c779fd8f3464af", "price_changes": [{"asset_id": "20794210232738155208360248995422719359166978550921485109532388301377529305580", "price": "0.09", "size": "200", "side": "BUY", "hash": "0ae16e6ac0270c32c65bec749c154409f94ff2a5", "best_bid": "0.53", "best_ask": "0.6"}, {"asset_id": "42097535137505280315737745177128192451567567237475285083506851409423497113459", "price": "0.91", "size": "200", "side": "SELL", "hash": "b626073fcb186020362cd920b7a6d9a5822d27b9", "best_bid": "0.4", "best_ask": "0.47"}], "timestamp": "1769384112422", "event_type": "price_change"}}
{"_local_timestamp": "2026-01-25T23:35:12.568864+00:00", "data": {"market": "0x88608442d14bdfa98a3d2ece26857aa516f193c8161db0c8e7c779fd8f3464af", "price_changes": [{"asset_id": "42097535137505280315737745177128192451567567237475285083506851409423497113459", "price": "0.08", "size": "2080.22", "side": "BUY", "hash": "466c279d05e8b26f8682df3dcda0eb3753420b86", "best_bid": "0.4", "best_ask": "0.47"}, {"asset_id": "20794210232738155208360248995422719359166978550921485109532388301377529305580", "price": "0.92", "size": "2080.22", "side": "SELL", "hash": "af42800759dce30c178dceedd69077048b9d98f5", "best_bid": "0.53", "best_ask": "0.6"}], "timestamp": "1769384112497", "event_type": "price_change"}}
{"_local_timestamp": "2026-01-25T23:35:12.569474+00:00", "data": {"market": "0x88608442d14bdfa98a3d2ece26857aa516f193c8161db0c8e7c779fd8f3464af", "price_changes": [{"asset_id": "42097535137505280315737745177128192451567567237475285083506851409423497113459", "price": "0.08", "size": "4077.33", "side": "BUY", "hash": "733366c812be624d23f2413749ca85f4f708229a", "best_bid": "0.4", "best_ask": "0.47"}, {"asset_id": "20794210232738155208360248995422719359166978550921485109532388301377529305580", "price": "0.92", "size": "4077.33", "side": "SELL", "hash": "a58e805e54816b4e94a76022d3044bdcd51bbaee", "best_bid": "0.53", "best_ask": "0.6"}], "timestamp": "1769384112498", "event_type": "price_change"}}
{"_local_timestamp": "2026-01-25T23:35:12.569931+00:00", "data": {"market": "0x88608442d14bdfa98a3d2ece26857aa516f193c8161db0c8e7c779fd8f3464af", "price_changes": [{"asset_id": "42097535137505280315737745177128192451567567237475285083506851409423497113459", "price": "0.08", "size": "5347.43", "side": "BUY", "hash": "02425f94c6830edbb5785eef359741c62c1bdf31", "best_bid": "0.4", "best_ask": "0.47"}, {"asset_id": "20794210232738155208360248995422719359166978550921485109532388301377529305580", "price": "0.92", "size": "5347.43", "side": "SELL", "hash": "99a57f0f29137638ccc623714df1a1c06ce5abd0", "best_bid": "0.53", "best_ask": "0.6"}], "timestamp": "1769384112499", "event_type": "price_change"}}
{"_local_timestamp": "2026-01-25T23:35:12.671965+00:00", "data": {"market": "0x88608442d14bdfa98a3d2ece26857aa516f193c8161db0c8e7c779fd8f3464af", "price_changes": [{"asset_id": "20794210232738155208360248995422719359166978550921485109532388301377529305580", "price": "0.09", "size": "1090.11", "side": "BUY", "hash": "5dd58466a083f930d10b647a966ec84ed1c1c61c", "best_bid": "0.53", "best_ask": "0.6"}, {"asset_id": "42097535137505280315737745177128192451567567237475285083506851409423497113459", "price": "0.91", "size": "1090.11", "side": "SELL", "hash": "6457e2d96ba4b8a2f6f47ca546c12dcea748c15b", "best_bid": "0.4", "best_ask": "0.47"}], "timestamp": "1769384112606", "event_type": "price_change"}}
{"_local_timestamp": "2026-01-25T23:35:12.672490+00:00", "data": {"market": "0x88608442d14bdfa98a3d2ece26857aa516f193c8161db0c8e7c779fd8f3464af", "price_changes": [{"asset_id": "20794210232738155208360248995422719359166978550921485109532388301377529305580", "price": "0.1", "size": "5047.43", "side": "BUY", "hash": "810fcc0f075663f637002aca158673a96a4a1f61", "best_bid": "0.53", "best_ask": "0.6"}, {"asset_id": "42097535137505280315737745177128192451567567237475285083506851409423497113459", "price": "0.9", "size": "5047.43", "side": "SELL", "hash": "deb27c45570a6a34030aaf2d8348adc365dea444", "best_bid": "0.4", "best_ask": "0.47"}], "timestamp": "1769384112607", "event_type": "price_change"}}
{"_local_timestamp": "2026-01-25T23:35:12.787484+00:00", "data": {"market": "0x88608442d14bdfa98a3d2ece26857aa516f193c8161db0c8e7c779fd8f3464af", "price_changes": [{"asset_id": "20794210232738155208360248995422719359166978550921485109532388301377529305580", "price": "0.18", "size": "1090.11", "side": "BUY", "hash": "363120ee9a2a0c389fa0d301aba7abde9b117d21", "best_bid": "0.53", "best_ask": "0.6"}, {"asset_id": "42097535137505280315737745177128192451567567237475285083506851409423497113459", "price": "0.82", "size": "1090.11", "side": "SELL", "hash": "402c5ea26924331104688c769100a3d6caa001ba", "best_bid": "0.4", "best_ask": "0.47"}], "timestamp": "1769384112713", "event_type": "price_change"}}
{"_local_timestamp": "2026-01-25T23:35:12.795199+00:00", "data": {"market": "0x88608442d14bdfa98a3d2ece26857aa516f193c8161db0c8e7c779fd8f3464af", "price_changes": [{"asset_id": "20794210232738155208360248995422719359166978550921485109532388301377529305580", "price": "0.1", "size": "5447.43", "side": "BUY", "hash": "d2d156571aa1c24d149ce7da980c378c3d62aa63", "best_bid": "0.53", "best_ask": "0.6"}, {"asset_id": "42097535137505280315737745177128192451567567237475285083506851409423497113459", "price": "0.9", "size": "5447.43", "side": "SELL", "hash": "5907491b204738ac76804b93d44de5a893e98d6b", "best_bid": "0.4", "best_ask": "0.47"}], "timestamp": "1769384112713", "event_type": "price_change"}}
{"_local_timestamp": "2026-01-25T23:35:12.795724+00:00", "data": {"market": "0x88608442d14bdfa98a3d2ece26857aa516f193c8161db0c8e7c779fd8f3464af", "price_changes": [{"asset_id": "42097535137505280315737745177128192451567567237475285083506851409423497113459", "price": "0.09", "size": "5547.43", "side": "BUY", "hash": "c4e4fbe2e759b3af70c8ede5d8314bdf11529bea", "best_bid": "0.4", "best_ask": "0.47"}, {"asset_id": "20794210232738155208360248995422719359166978550921485109532388301377529305580", "price": "0.91", "size": "5547.43", "side": "SELL", "hash": "43c5f1acc31cba1a87dce40e4c86c20fbeda3e2a", "best_bid": "0.53", "best_ask": "0.6"}], "timestamp": "1769384112714", "event_type": "price_change"}}
{"_local_timestamp": "2026-01-25T23:35:13.131382+00:00", "data": {"market": "0x88608442d14bdfa98a3d2ece26857aa516f193c8161db0c8e7c779fd8f3464af", "price_changes": [{"asset_id": "42097535137505280315737745177128192451567567237475285083506851409423497113459", "price": "0.09", "size": "11546.54", "side": "BUY", "hash": "7e3f3fe2e550b8badbfb898c48eab69b3d0bf889", "best_bid": "0.4", "best_ask": "0.47"}, {"asset_id": "20794210232738155208360248995422719359166978550921485109532388301377529305580", "price": "0.91", "size": "11546.54", "side": "SELL", "hash": "d0437b80212ea15bed47b1be3109b585f95d89b8", "best_bid": "0.53", "best_ask": "0.6"}], "timestamp": "1769384113021", "event_type": "price_change"}}
{"_local_timestamp": "2026-01-25T23:35:16.643387+00:00", "data": {"market": "0x72ba07862b22314dbe4f409505a9833da2dfb3ffe2f6a1c8fa1ba3add5e7a039", "price_changes": [{"asset_id": "93425111955845150480136289753481493030447902158015790781546943758014021748210", "price": "0.5", "size": "0", "side": "BUY", "hash": "264c0b12a10b058e750589b81da539bceea0feff", "best_bid": "0.02", "best_ask": "0.95"}, {"asset_id": "2984940558574601482400602739691261511463191599721533374910685943278753091727", "price": "0.5", "size": "0", "side": "SELL", "hash": "bd91c3da03d05352eeced3ed4319ae48ad6e4b00", "best_bid": "0.05", "best_ask": "0.98"}], "timestamp": "1769384116577", "event_type": "price_change"}}
{"_local_timestamp": "2026-01-25T23:35:26.853122+00:00", "data": {"market": "0x88608442d14bdfa98a3d2ece26857aa516f193c8161db0c8e7c779fd8f3464af", "price_changes": [{"asset_id": "42097535137505280315737745177128192451567567237475285083506851409423497113459", "price": "0.08", "size": "5247.43", "side": "BUY", "hash": "0db3268eb9d032113916ca33650f902a4d7d9fda", "best_bid": "0.4", "best_ask": "0.47"}, {"asset_id": "20794210232738155208360248995422719359166978550921485109532388301377529305580", "price": "0.92", "size": "5247.43", "side": "SELL", "hash": "c1bbf861488f3d350e60e8aae833a79a6b4ccd9c", "best_bid": "0.53", "best_ask": "0.6"}], "timestamp": "1769384126678", "event_type": "price_change"}}
{"_local_timestamp": "2026-01-25T23:35:26.865249+00:00", "data": {"market": "0x88608442d14bdfa98a3d2ece26857aa516f193c8161db0c8e7c779fd8f3464af", "price_changes": [{"asset_id": "20794210232738155208360248995422719359166978550921485109532388301377529305580", "price": "0.08", "size": "0", "side": "BUY", "hash": "f7fc22afa4e445a8687085875a6bced699242824", "best_bid": "0.53", "best_ask": "0.6"}, {"asset_id": "42097535137505280315737745177128192451567567237475285083506851409423497113459", "price": "0.92", "size": "0", "side": "SELL", "hash": "30a5dc2fd6cfc0e03ee31646b4b8261baa5501f5", "best_bid": "0.4", "best_ask": "0.47"}], "timestamp": "1769384126679", "event_type": "price_change"}}
{"_local_timestamp": "2026-01-25T23:35:26.946886+00:00", "data": {"market": "0x88608442d14bdfa98a3d2ece26857aa516f193c8161db0c8e7c779fd8f3464af", "price_changes": [{"asset_id": "20794210232738155208360248995422719359166978550921485109532388301377529305580", "price": "0.19", "size": "890.11", "side": "BUY", "hash": "2bf98923bf24521b9fc059ba490418a7e597f940", "best_bid": "0.53", "best_ask": "0.6"}, {"asset_id": "42097535137505280315737745177128192451567567237475285083506851409423497113459", "price": "0.81", "size": "890.11", "side": "SELL", "hash": "347ab5210cbdc183f95fd75ac1fa077306f848b7", "best_bid": "0.4", "best_ask": "0.47"}], "timestamp": "1769384126856", "event_type": "price_change"}}
{"_local_timestamp": "2026-01-25T23:35:26.948760+00:00", "data": {"market": "0x88608442d14bdfa98a3d2ece26857aa516f193c8161db0c8e7c779fd8f3464af", "price_changes": [{"asset_id": "20794210232738155208360248995422719359166978550921485109532388301377529305580", "price": "0.08", "size": "890.11", "side": "BUY", "hash": "239287e4c48deeaa6918e1031713721f908e6ad5", "best_bid": "0.53", "best_ask": "0.6"}, {"asset_id": "42097535137505280315737745177128192451567567237475285083506851409423497113459", "price": "0.92", "size": "890.11", "side": "SELL", "hash": "b00d8aae369d02415fddb4742c91333ff52b39ac", "best_bid": "0.4", "best_ask": "0.47"}], "timestamp": "1769384126857", "event_type": "price_change"}}
{"_local_timestamp": "2026-01-25T23:35:26.954962+00:00", "data": {"market": "0x88608442d14bdfa98a3d2ece26857aa516f193c8161db0c8e7c779fd8f3464af", "price_changes": [{"asset_id": "20794210232738155208360248995422719359166978550921485109532388301377529305580", "price": "0.08", "size": "2887.22", "side": "BUY", "hash": "bc5d69eecf03e433a788a2b7c4769f1bb7167ef9", "best_bid": "0.53", "best_ask": "0.6"}, {"asset_id": "42097535137505280315737745177128192451567567237475285083506851409423497113459", "price": "0.92", "size": "2887.22", "side": "SELL", "hash": "644738b7151a50800bb0380ce08fcb87bd520d77", "best_bid": "0.4", "best_ask": "0.47"}], "timestamp": "1769384126858", "event_type": "price_change"}}
{"_local_timestamp": "2026-01-25T23:35:26.964301+00:00", "data": {"market": "0x88608442d14bdfa98a3d2ece26857aa516f193c8161db0c8e7c779fd8f3464af", "price_changes": [{"asset_id": "42097535137505280315737745177128192451567567237475285083506851409423497113459", "price": "0.1", "size": "895.98", "side": "BUY", "hash": "0b90e69e8e3b2a6f270441134449f5a1818aef00", "best_bid": "0.4", "best_ask": "0.47"}, {"asset_id": "20794210232738155208360248995422719359166978550921485109532388301377529305580", "price": "0.9", "size": "895.98", "side": "SELL", "hash": "1ba2268d403eeea8a5ad8a3d4a5b1790aeac993e", "best_bid": "0.53", "best_ask": "0.6"}], "timestamp": "1769384126859", "event_type": "price_change"}}
{"_local_timestamp": "2026-01-25T23:35:26.965614+00:00", "data": {"market": "0x88608442d14bdfa98a3d2ece26857aa516f193c8161db0c8e7c779fd8f3464af", "price_changes": [{"asset_id": "20794210232738155208360248995422719359166978550921485109532388301377529305580", "price": "0.08", "size": "4157.32", "side": "BUY", "hash": "58caf3e48f12f3ac56d31fbd7469d347363df752", "best_bid": "0.53", "best_ask": "0.6"}, {"asset_id": "42097535137505280315737745177128192451567567237475285083506851409423497113459", "price": "0.92", "size": "4157.32", "side": "SELL", "hash": "e02bb8cae99aeb7eadad410122d012a92ea493b7", "best_bid": "0.4", "best_ask": "0.47"}], "timestamp": "1769384126860", "event_type": "price_change"}}
{"_local_timestamp": "2026-01-25T23:35:27.186652+00:00", "data": {"market": "0x88608442d14bdfa98a3d2ece26857aa516f193c8161db0c8e7c779fd8f3464af", "price_changes": [{"asset_id": "20794210232738155208360248995422719359166978550921485109532388301377529305580", "price": "0.1", "size": "400", "side": "BUY", "hash": "b7dce8f8ba2ca513649502db1389a66cf48c45e0", "best_bid": "0.53", "best_ask": "0.6"}, {"asset_id": "42097535137505280315737745177128192451567567237475285083506851409423497113459", "price": "0.9", "size": "400", "side": "SELL", "hash": "b1f74b6f6ccf594a6a0042e638e8c31031cabbe4", "best_bid": "0.4", "best_ask": "0.47"}], "timestamp": "1769384126933", "event_type": "price_change"}}
{"_local_timestamp": "2026-01-25T23:35:27.187310+00:00", "data": {"market": "0x88608442d14bdfa98a3d2ece26857aa516f193c8161db0c8e7c779fd8f3464af", "price_changes": [{"asset_id": "20794210232738155208360248995422719359166978550921485109532388301377529305580", "price": "0.17", "size": "0", "side": "BUY", "hash": "b7dce8f8ba2ca513649502db1389a66cf48c45e0", "best_bid": "0.53", "best_ask": "0.6"}, {"asset_id": "42097535137505280315737745177128192451567567237475285083506851409423497113459", "price": "0.83", "size": "0", "side": "SELL", "hash": "b1f74b6f6ccf594a6a0042e638e8c31031cabbe4", "best_bid": "0.4", "best_ask": "0.47"}], "timestamp": "1769384126933", "event_type": "price_change"}}
{"_local_timestamp": "2026-01-25T23:35:27.188830+00:00", "data": {"market": "0x88608442d14bdfa98a3d2ece26857aa516f193c8161db0c8e7c779fd8f3464af", "price_changes": [{"asset_id": "20794210232738155208360248995422719359166978550921485109532388301377529305580", "price": "0.09", "size": "200", "side": "BUY", "hash": "b7dce8f8ba2ca513649502db1389a66cf48c45e0", "best_bid": "0.53", "best_ask": "0.6"}, {"asset_id": "42097535137505280315737745177128192451567567237475285083506851409423497113459", "price": "0.91", "size": "200", "side": "SELL", "hash": "b1f74b6f6ccf594a6a0042e638e8c31031cabbe4", "best_bid": "0.4", "best_ask": "0.47"}], "timestamp": "1769384126933", "event_type": "price_change"}}
{"_local_timestamp": "2026-01-25T23:35:27.192110+00:00", "data": {"market": "0x88608442d14bdfa98a3d2ece26857aa516f193c8161db0c8e7c779fd8f3464af", "price_changes": [{"asset_id": "42097535137505280315737745177128192451567567237475285083506851409423497113459", "price": "0.09", "size": "1390.11", "side": "BUY", "hash": "c408c15f2af682a0053b53376fbd197d2628c173", "best_bid": "0.4", "best_ask": "0.47"}, {"asset_id": "20794210232738155208360248995422719359166978550921485109532388301377529305580", "price": "0.91", "size": "1390.11", "side": "SELL", "hash": "860e8b402007043bf054d63ae685f4bfeaaec28f", "best_bid": "0.53", "best_ask": "0.6"}], "timestamp": "1769384126934", "event_type": "price_change"}}
{"_local_timestamp": "2026-01-25T23:35:27.192892+00:00", "data": {"market": "0x88608442d14bdfa98a3d2ece26857aa516f193c8161db0c8e7c779fd8f3464af", "price_changes": [{"asset_id": "42097535137505280315737745177128192451567567237475285083506851409423497113459", "price": "0.08", "size": "4357.32", "side": "BUY", "hash": "c408c15f2af682a0053b53376fbd197d2628c173", "best_bid": "0.4", "best_ask": "0.47"}, {"asset_id": "20794210232738155208360248995422719359166978550921485109532388301377529305580", "price": "0.92", "size": "4357.32", "side": "SELL", "hash": "860e8b402007043bf054d63ae685f4bfeaaec28f", "best_bid": "0.53", "best_ask": "0.6"}], "timestamp": "1769384126934", "event_type": "price_change"}}
{"_local_timestamp": "2026-01-25T23:35:27.226433+00:00", "data": {"market": "0x88608442d14bdfa98a3d2ece26857aa516f193c8161db0c8e7c779fd8f3464af", "price_changes": [{"asset_id": "20794210232738155208360248995422719359166978550921485109532388301377529305580", "price": "0.1", "size": "500", "side": "BUY", "hash": "5e819de15b0627bcbbee288507409d48b079eebf", "best_bid": "0.53", "best_ask": "0.6"}, {"asset_id": "42097535137505280315737745177128192451567567237475285083506851409423497113459", "price": "0.9", "size": "500", "side": "SELL", "hash": "9b4b89f90ef35e91a2273d42be6236bdbff3cdee", "best_bid": "0.4", "best_ask": "0.47"}], "timestamp": "1769384126955", "event_type": "price_change"}}
{"_local_timestamp": "2026-01-25T23:35:27.233135+00:00", "data": {"market": "0x88608442d14bdfa98a3d2ece26857aa516f193c8161db0c8e7c779fd8f3464af", "price_changes": [{"asset_id": "42097535137505280315737745177128192451567567237475285083506851409423497113459", "price": "0.09", "size": "1490.11", "side": "BUY", "hash": "3e2a2d312fd3ed4e58d5539989976ec7d7168f2b", "best_bid": "0.4", "best_ask": "0.47"}, {"asset_id": "20794210232738155208360248995422719359166978550921485109532388301377529305580", "price": "0.91", "size": "1490.11", "side": "SELL", "hash": "d929b9610e665b56883e04fd887bfee732c2e2fd", "best_bid": "0.53", "best_ask": "0.6"}], "timestamp": "1769384126956", "event_type": "price_change"}}
{"_local_timestamp": "2026-01-25T23:35:27.336573+00:00", "data": {"market": "0x88608442d14bdfa98a3d2ece26857aa516f193c8161db0c8e7c779fd8f3464af", "price_changes": [{"asset_id": "20794210232738155208360248995422719359166978550921485109532388301377529305580", "price": "0.11", "size": "6004.84", "side": "BUY", "hash": "1ea0dcdc4030ab0af515153b1a165c7763386638", "best_bid": "0.53", "best_ask": "0.6"}, {"asset_id": "42097535137505280315737745177128192451567567237475285083506851409423497113459", "price": "0.89", "size": "6004.84", "side": "SELL", "hash": "321bf859e7b4567d47966500907bae904577ce53", "best_bid": "0.4", "best_ask": "0.47"}], "timestamp": "1769384127175", "event_type": "price_change"}}
{"_local_timestamp": "2026-01-25T23:35:27.337184+00:00", "data": {"market": "0x88608442d14bdfa98a3d2ece26857aa516f193c8161db0c8e7c779fd8f3464af", "price_changes": [{"asset_id": "42097535137505280315737745177128192451567567237475285083506851409423497113459", "price": "0.1", "size": "6895.09", "side": "BUY", "hash": "08245be820ec0f337282dab050521139644d40ee", "best_bid": "0.4", "best_ask": "0.47"}, {"asset_id": "20794210232738155208360248995422719359166978550921485109532388301377529305580", "price": "0.9", "size": "6895.09", "side": "SELL", "hash": "3c4d8d2f8749e138edb8445f4e51d91373fd9e04", "best_bid": "0.53", "best_ask": "0.6"}], "timestamp": "1769384127176", "event_type": "price_change"}}
{"_local_timestamp": "2026-01-25T23:35:28.355973+00:00", "data": {"market": "0x88608442d14bdfa98a3d2ece26857aa516f193c8161db0c8e7c779fd8f3464af", "price_changes": [{"asset_id": "42097535137505280315737745177128192451567567237475285083506851409423497113459", "price": "0.08", "size": "4257.32", "side": "BUY", "hash": "2c0f5e225833af7a44967c5d4499ab38ab07bd1b", "best_bid": "0.4", "best_ask": "0.47"}, {"asset_id": "20794210232738155208360248995422719359166978550921485109532388301377529305580", "price": "0.92", "size": "4257.32", "side": "SELL", "hash": "1d316b93a615ac1f0711b029775b832cfb4e6912", "best_bid": "0.53", "best_ask": "0.6"}], "timestamp": "1769384128280", "event_type": "price_change"}}
{"_local_timestamp": "2026-01-25T23:35:28.364877+00:00", "data": {"market": "0x88608442d14bdfa98a3d2ece26857aa516f193c8161db0c8e7c779fd8f3464af", "price_changes": [{"asset_id": "20794210232738155208360248995422719359166978550921485109532388301377529305580", "price": "0.09", "size": "100", "side": "BUY", "hash": "ca50b1a2b9cf9af6508d62dce19603903b00f291", "best_bid": "0.53", "best_ask": "0.6"}, {"asset_id": "42097535137505280315737745177128192451567567237475285083506851409423497113459", "price": "0.91", "size": "100", "side": "SELL", "hash": "1b21d3f21cf88639afb7b8203cbdd360c59b4f88", "best_bid": "0.4", "best_ask": "0.47"}], "timestamp": "1769384128280", "event_type": "price_change"}}
{"_local_timestamp": "2026-01-25T23:35:28.615386+00:00", "data": {"market": "0x88608442d14bdfa98a3d2ece26857aa516f193c8161db0c8e7c779fd8f3464af", "price_changes": [{"asset_id": "20794210232738155208360248995422719359166978550921485109532388301377529305580", "price": "0.1", "size": "600", "side": "BUY", "hash": "fcaaf245729cc6b1ac91321dd78a0225c95fff91", "best_bid": "0.53", "best_ask": "0.6"}, {"asset_id": "42097535137505280315737745177128192451567567237475285083506851409423497113459", "price": "0.9", "size": "600", "side": "SELL", "hash": "3257c591e938c27c8579b156445c8e613ecc4306", "best_bid": "0.4", "best_ask": "0.47"}], "timestamp": "1769384128551", "event_type": "price_change"}}
{"_local_timestamp": "2026-01-25T23:35:28.628561+00:00", "data": {"market": "0x88608442d14bdfa98a3d2ece26857aa516f193c8161db0c8e7c779fd8f3464af", "price_changes": [{"asset_id": "42097535137505280315737745177128192451567567237475285083506851409423497113459", "price": "0.09", "size": "1590.11", "side": "BUY", "hash": "901240ad6802f36dd7f886c2c37a9e965d75e525", "best_bid": "0.4", "best_ask": "0.47"}, {"asset_id": "20794210232738155208360248995422719359166978550921485109532388301377529305580", "price": "0.91", "size": "1590.11", "side": "SELL", "hash": "e78dece51fefd4a8602fdb31c21727498422d031", "best_bid": "0.53", "best_ask": "0.6"}], "timestamp": "1769384128553", "event_type": "price_change"}}
{"_local_timestamp": "2026-01-25T23:35:32.908626+00:00", "data": {"market": "0x88608442d14bdfa98a3d2ece26857aa516f193c8161db0c8e7c779fd8f3464af", "price_changes": [{"asset_id": "20794210232738155208360248995422719359166978550921485109532388301377529305580", "price": "0.09", "size": "0", "side": "BUY", "hash": "4651fc8b5572d799753d6c9313780cb2a42dc382", "best_bid": "0.53", "best_ask": "0.6"}, {"asset_id": "42097535137505280315737745177128192451567567237475285083506851409423497113459", "price": "0.91", "size": "0", "side": "SELL", "hash": "d089adc9d2b880939d94c79372074f15329cf522", "best_bid": "0.4", "best_ask": "0.47"}], "timestamp": "1769384132834", "event_type": "price_change"}}
{"_local_timestamp": "2026-01-25T23:35:32.909261+00:00", "data": {"market": "0x88608442d14bdfa98a3d2ece26857aa516f193c8161db0c8e7c779fd8f3464af", "price_changes": [{"asset_id": "42097535137505280315737745177128192451567567237475285083506851409423497113459", "price": "0.08", "size": "4157.32", "side": "BUY", "hash": "b1331460d094693bd1facaf808c611f927efff4c", "best_bid": "0.4", "best_ask": "0.47"}, {"asset_id": "20794210232738155208360248995422719359166978550921485109532388301377529305580", "price": "0.92", "size": "4157.32", "side": "SELL", "hash": "b85df0bd3a53291cbfb8002ca22fca31c5400fe7", "best_bid": "0.53", "best_ask": "0.6"}], "timestamp": "1769384132835", "event_type": "price_change"}}
{"_local_timestamp": "2026-01-25T23:35:32.972386+00:00", "data": {"market": "0x88608442d14bdfa98a3d2ece26857aa516f193c8161db0c8e7c779fd8f3464af", "price_changes": [{"asset_id": "20794210232738155208360248995422719359166978550921485109532388301377529305580", "price": "0.11", "size": "8001.95", "side": "BUY", "hash": "42b590fe7cf7bda8414185a39b2c9f8da75ba568", "best_bid": "0.53", "best_ask": "0.6"}, {"asset_id": "42097535137505280315737745177128192451567567237475285083506851409423497113459", "price": "0.89", "size": "8001.95", "side": "SELL", "hash": "2761887f3576d2f781fe2f793173618f93649a92", "best_bid": "0.4", "best_ask": "0.47"}], "timestamp": "1769384132903", "event_type": "price_change"}}
{"_local_timestamp": "2026-01-25T23:35:32.973004+00:00", "data": {"market": "0x88608442d14bdfa98a3d2ece26857aa516f193c8161db0c8e7c779fd8f3464af", "price_changes": [{"asset_id": "42097535137505280315737745177128192451567567237475285083506851409423497113459", "price": "0.1", "size": "8892.2", "side": "BUY", "hash": "235e55538404fceb688b3b6d97b712cb2c1244f2", "best_bid": "0.4", "best_ask": "0.47"}, {"asset_id": "20794210232738155208360248995422719359166978550921485109532388301377529305580", "price": "0.9", "size": "8892.2", "side": "SELL", "hash": "a120a83a88e68e01cf526bce8af64095c44b8fca", "best_bid": "0.53", "best_ask": "0.6"}], "timestamp": "1769384132904", "event_type": "price_change"}}
{"_local_timestamp": "2026-01-25T23:35:32.973583+00:00", "data": {"market": "0x88608442d14bdfa98a3d2ece26857aa516f193c8161db0c8e7c779fd8f3464af", "price_changes": [{"asset_id": "42097535137505280315737745177128192451567567237475285083506851409423497113459", "price": "0.1", "size": "10162.3", "side": "BUY", "hash": "423f4f5141b46678887d89ce3119f8ce1954999d", "best_bid": "0.4", "best_ask": "0.47"}, {"asset_id": "20794210232738155208360248995422719359166978550921485109532388301377529305580", "price": "0.9", "size": "10162.3", "side": "SELL", "hash": "6db7e252f1c88a619d97da2bc0cbe41b7a9b685f", "best_bid": "0.53", "best_ask": "0.6"}], "timestamp": "1769384132905", "event_type": "price_change"}}
{"_local_timestamp": "2026-01-25T23:35:33.002815+00:00", "data": {"market": "0x88608442d14bdfa98a3d2ece26857aa516f193c8161db0c8e7c779fd8f3464af", "price_changes": [{"asset_id": "20794210232738155208360248995422719359166978550921485109532388301377529305580", "price": "0.11", "size": "9272.05", "side": "BUY", "hash": "a9c0f76bbb509c7563ff1468aacb989337e6c1d6", "best_bid": "0.53", "best_ask": "0.6"}, {"asset_id": "42097535137505280315737745177128192451567567237475285083506851409423497113459", "price": "0.89", "size": "9272.05", "side": "SELL", "hash": "a607958be52f8d1dd8565b8952c0dd0ff44d485f", "best_bid": "0.4", "best_ask": "0.47"}], "timestamp": "1769384132940", "event_type": "price_change"}}
{"_local_timestamp": "2026-01-25T23:35:33.050632+00:00", "data": {"market": "0x88608442d14bdfa98a3d2ece26857aa516f193c8161db0c8e7c779fd8f3464af", "price_changes": [{"asset_id": "20794210232738155208360248995422719359166978550921485109532388301377529305580", "price": "0.11", "size": "10162.16", "side": "BUY", "hash": "889daeef834e63dd3496cdf1d70d4aff073f5b0f", "best_bid": "0.53", "best_ask": "0.6"}, {"asset_id": "42097535137505280315737745177128192451567567237475285083506851409423497113459", "price": "0.89", "size": "10162.16", "side": "SELL", "hash": "b4a85a5fe39fd27d957899041ca696ed268cd99f", "best_bid": "0.4", "best_ask": "0.47"}], "timestamp": "1769384132974", "event_type": "price_change"}}
{"_local_timestamp": "2026-01-25T23:35:33.051265+00:00", "data": {"market": "0x88608442d14bdfa98a3d2ece26857aa516f193c8161db0c8e7c779fd8f3464af", "price_changes": [{"asset_id": "42097535137505280315737745177128192451567567237475285083506851409423497113459", "price": "0.1", "size": "11052.41", "side": "BUY", "hash": "a81096fe106e5a045576a3e219c9a162a29af1cb", "best_bid": "0.4", "best_ask": "0.47"}, {"asset_id": "20794210232738155208360248995422719359166978550921485109532388301377529305580", "price": "0.9", "size": "11052.41", "side": "SELL", "hash": "e80cb5279c8dab35ea4c18ac53b31ec77d26ff07", "best_bid": "0.53", "best_ask": "0.6"}], "timestamp": "1769384132974", "event_type": "price_change"}}
{"_local_timestamp": "2026-01-25T23:35:33.060149+00:00", "data": {"market": "0x88608442d14bdfa98a3d2ece26857aa516f193c8161db0c8e7c779fd8f3464af", "price_changes": [{"asset_id": "20794210232738155208360248995422719359166978550921485109532388301377529305580", "price": "0.08", "size": "0", "side": "BUY", "hash": "2c03bbe2af3d490c25016e30217ce2a633e91af0", "best_bid": "0.53", "best_ask": "0.6"}, {"asset_id": "42097535137505280315737745177128192451567567237475285083506851409423497113459", "price": "0.92", "size": "0", "side": "SELL", "hash": "6ad6e5bc689a28cb992d35bccd1a591691d36add", "best_bid": "0.4", "best_ask": "0.47"}], "timestamp": "1769384132980", "event_type": "price_change"}}
{"_local_timestamp": "2026-01-25T23:35:33.060821+00:00", "data": {"market": "0x88608442d14bdfa98a3d2ece26857aa516f193c8161db0c8e7c779fd8f3464af", "price_changes": [{"asset_id": "20794210232738155208360248995422719359166978550921485109532388301377529305580", "price": "0.11", "size": "4163.05", "side": "BUY", "hash": "2c03bbe2af3d490c25016e30217ce2a633e91af0", "best_bid": "0.53", "best_ask": "0.6"}, {"asset_id": "42097535137505280315737745177128192451567567237475285083506851409423497113459", "price": "0.89", "size": "4163.05", "side": "SELL", "hash": "6ad6e5bc689a28cb992d35bccd1a591691d36add", "best_bid": "0.4", "best_ask": "0.47"}], "timestamp": "1769384132980", "event_type": "price_change"}}
{"_local_timestamp": "2026-01-25T23:35:33.098590+00:00", "data": {"market": "0x88608442d14bdfa98a3d2ece26857aa516f193c8161db0c8e7c779fd8f3464af", "price_changes": [{"asset_id": "42097535137505280315737745177128192451567567237475285083506851409423497113459", "price": "0.08", "size": "0", "side": "BUY", "hash": "94b892bf65d928fd0dd3674233f798e7e987163a", "best_bid": "0.4", "best_ask": "0.47"}, {"asset_id": "20794210232738155208360248995422719359166978550921485109532388301377529305580", "price": "0.92", "size": "0", "side": "SELL", "hash": "3b3449eafd37bafdf8637eef5c0cae1bfb8f5cc0", "best_bid": "0.53", "best_ask": "0.6"}], "timestamp": "1769384132980", "event_type": "price_change"}}
{"_local_timestamp": "2026-01-25T23:35:33.099295+00:00", "data": {"market": "0x88608442d14bdfa98a3d2ece26857aa516f193c8161db0c8e7c779fd8f3464af", "price_changes": [{"asset_id": "42097535137505280315737745177128192451567567237475285083506851409423497113459", "price": "0.1", "size": "5053.3", "side": "BUY", "hash": "94b892bf65d928fd0dd3674233f798e7e987163a", "best_bid": "0.4", "best_ask": "0.47"}, {"asset_id": "20794210232738155208360248995422719359166978550921485109532388301377529305580", "price": "0.9", "size": "5053.3", "side": "SELL", "hash": "3b3449eafd37bafdf8637eef5c0cae1bfb8f5cc0", "best_bid": "0.53", "best_ask": "0.6"}], "timestamp": "1769384132980", "event_type": "price_change"}}
{"_local_timestamp": "2026-01-25T23:35:33.152080+00:00", "data": {"market": "0x88608442d14bdfa98a3d2ece26857aa516f193c8161db0c8e7c779fd8f3464af", "price_changes": [{"asset_id": "20794210232738155208360248995422719359166978550921485109532388301377529305580", "price": "0.12", "size": "5999.11", "side": "BUY", "hash": "a3d33968c809494bc6686d0598b82595eaa28e07", "best_bid": "0.53", "best_ask": "0.6"}, {"asset_id": "42097535137505280315737745177128192451567567237475285083506851409423497113459", "price": "0.88", "size": "5999.11", "side": "SELL", "hash": "d534db44d22e4e5e2ad482c1b5611d482eca4a6f", "best_bid": "0.4", "best_ask": "0.47"}], "timestamp": "1769384133057", "event_type": "price_change"}}
{"_local_timestamp": "2026-01-25T23:35:33.152806+00:00", "data": {"market": "0x88608442d14bdfa98a3d2ece26857aa516f193c8161db0c8e7c779fd8f3464af", "price_changes": [{"asset_id": "42097535137505280315737745177128192451567567237475285083506851409423497113459", "price": "0.11", "size": "5999.11", "side": "BUY", "hash": "d55dc51b7d4475d0a305c53ebc9b2533569a9f0e", "best_bid": "0.4", "best_ask": "0.47"}, {"asset_id": "20794210232738155208360248995422719359166978550921485109532388301377529305580", "price": "0.89", "size": "5999.11", "side": "SELL", "hash": "a94e5986b88adc5a50076642a4040919eba8ceca", "best_bid": "0.53", "best_ask": "0.6"}], "timestamp": "1769384133058", "event_type": "price_change"}}
{"_local_timestamp": "2026-01-25T23:35:33.154357+00:00", "data": {"market": "0x88608442d14bdfa98a3d2ece26857aa516f193c8161db0c8e7c779fd8f3464af", "price_changes": [{"asset_id": "42097535137505280315737745177128192451567567237475285083506851409423497113459", "price": "0.11", "size": "6889.22", "side": "BUY", "hash": "3e707375a25ef2454d7cadc5f2104e5988078d89", "best_bid": "0.4", "best_ask": "0.47"}, {"asset_id": "20794210232738155208360248995422719359166978550921485109532388301377529305580", "price": "0.89", "size": "6889.22", "side": "SELL", "hash": "70487e6e90796411f63a13b47ee69350802c624d", "best_bid": "0.53", "best_ask": "0.6"}], "timestamp": "1769384133058", "event_type": "price_change"}}
{"_local_timestamp": "2026-01-25T23:35:33.185399+00:00", "data": {"market": "0x88608442d14bdfa98a3d2ece26857aa516f193c8161db0c8e7c779fd8f3464af", "price_changes": [{"asset_id": "20794210232738155208360248995422719359166978550921485109532388301377529305580", "price": "0.1", "size": "700", "side": "BUY", "hash": "bb3ae9444cb0ac168e6f20545fe54369998d4647", "best_bid": "0.53", "best_ask": "0.6"}, {"asset_id": "42097535137505280315737745177128192451567567237475285083506851409423497113459", "price": "0.9", "size": "700", "side": "SELL", "hash": "fbbd4bc2928f5875189b60025940f3b235b6fcec", "best_bid": "0.4", "best_ask": "0.47"}], "timestamp": "1769384133099", "event_type": "price_change"}}
{"_local_timestamp": "2026-01-25T23:35:33.190809+00:00", "data": {"market": "0x88608442d14bdfa98a3d2ece26857aa516f193c8161db0c8e7c779fd8f3464af", "price_changes": [{"asset_id": "42097535137505280315737745177128192451567567237475285083506851409423497113459", "price": "0.09", "size": "1690.11", "side": "BUY", "hash": "62387aae15707c4c20d7b36b17df5661f8d63a7f", "best_bid": "0.4", "best_ask": "0.47"}, {"asset_id": "20794210232738155208360248995422719359166978550921485109532388301377529305580", "price": "0.91", "size": "1690.11", "side": "SELL", "hash": "6cb84b15249fef383914b0184b955cdf99415f01", "best_bid": "0.53", "best_ask": "0.6"}], "timestamp": "1769384133100", "event_type": "price_change"}}
{"_local_timestamp": "2026-01-25T23:35:41.038493+00:00", "data": {"market": "0x88608442d14bdfa98a3d2ece26857aa516f193c8161db0c8e7c779fd8f3464af", "price_changes": [{"asset_id": "42097535137505280315737745177128192451567567237475285083506851409423497113459", "price": "0.09", "size": "1590.11", "side": "BUY", "hash": "a219ba5aaeaea0dfc465218df8077276133e76a5", "best_bid": "0.4", "best_ask": "0.47"}, {"asset_id": "20794210232738155208360248995422719359166978550921485109532388301377529305580", "price": "0.91", "size": "1590.11", "side": "SELL", "hash": "7368eeb8bbcfb1e45391f058a497a25a02856fdb", "best_bid": "0.53", "best_ask": "0.6"}], "timestamp": "1769384140976", "event_type": "price_change"}}
{"_local_timestamp": "2026-01-25T23:35:41.103990+00:00", "data": {"market": "0x88608442d14bdfa98a3d2ece26857aa516f193c8161db0c8e7c779fd8f3464af", "price_changes": [{"asset_id": "42097535137505280315737745177128192451567567237475285083506851409423497113459", "price": "0.11", "size": "0", "side": "BUY", "hash": "92e798d7f1a9e053601fd202ec6dfa80e9d4ea8e", "best_bid": "0.4", "best_ask": "0.47"}, {"asset_id": "20794210232738155208360248995422719359166978550921485109532388301377529305580", "price": "0.89", "size": "0", "side": "SELL", "hash": "4ff6dbaeff41a29eac0d8aacb4d8af1ff2dfa38c", "best_bid": "0.53", "best_ask": "0.6"}], "timestamp": "1769384141029", "event_type": "price_change"}}
{"_local_timestamp": "2026-01-25T23:35:41.106343+00:00", "data": {"market": "0x88608442d14bdfa98a3d2ece26857aa516f193c8161db0c8e7c779fd8f3464af", "price_changes": [{"asset_id": "20794210232738155208360248995422719359166978550921485109532388301377529305580", "price": "0.12", "size": "0", "side": "BUY", "hash": "42ef183f3633d8f536201eb01553b56e7da63593", "best_bid": "0.53", "best_ask": "0.6"}, {"asset_id": "42097535137505280315737745177128192451567567237475285083506851409423497113459", "price": "0.88", "size": "0", "side": "SELL", "hash": "3d765cc4b8d1913491faf08a3b285a3e6f132eed", "best_bid": "0.4", "best_ask": "0.47"}], "timestamp": "1769384141030", "event_type": "price_change"}}
{"_local_timestamp": "2026-01-25T23:35:41.142346+00:00", "data": {"market": "0x88608442d14bdfa98a3d2ece26857aa516f193c8161db0c8e7c779fd8f3464af", "price_changes": [{"asset_id": "20794210232738155208360248995422719359166978550921485109532388301377529305580", "price": "0.13", "size": "890.11", "side": "BUY", "hash": "0f5ce17835e6a3d980da49ca66faffb19c3442a9", "best_bid": "0.53", "best_ask": "0.6"}, {"asset_id": "42097535137505280315737745177128192451567567237475285083506851409423497113459", "price": "0.87", "size": "890.11", "side": "SELL", "hash": "761ebd69c7492652e15c1a2014af6c80d9a2b120", "best_bid": "0.4", "best_ask": "0.47"}], "timestamp": "1769384141079", "event_type": "price_change"}}
{"_local_timestamp": "2026-01-25T23:35:41.148030+00:00", "data": {"market": "0x88608442d14bdfa98a3d2ece26857aa516f193c8161db0c8e7c779fd8f3464af", "price_changes": [{"asset_id": "20794210232738155208360248995422719359166978550921485109532388301377529305580", "price": "0.13", "size": "2887.22", "side": "BUY", "hash": "3f1c1a336d2ff44500af7e48e00c20ec580910aa", "best_bid": "0.53", "best_ask": "0.6"}, {"asset_id": "42097535137505280315737745177128192451567567237475285083506851409423497113459", "price": "0.87", "size": "2887.22", "side": "SELL", "hash": "d9e76327d2fabc8df8dc41c13fe7bcb20cef4a2e", "best_bid": "0.4", "best_ask": "0.47"}], "timestamp": "1769384141080", "event_type": "price_change"}}
{"_local_timestamp": "2026-01-25T23:35:41.149053+00:00", "data": {"market": "0x88608442d14bdfa98a3d2ece26857aa516f193c8161db0c8e7c779fd8f3464af", "price_changes": [{"asset_id": "20794210232738155208360248995422719359166978550921485109532388301377529305580", "price": "0.13", "size": "4157.32", "side": "BUY", "hash": "1511eb7f75af8dac1001884a4403dc74298c80c3", "best_bid": "0.53", "best_ask": "0.6"}, {"asset_id": "42097535137505280315737745177128192451567567237475285083506851409423497113459", "price": "0.87", "size": "4157.32", "side": "SELL", "hash": "dcfc3f38bf8abe591430895191bc665978b4a5ff", "best_bid": "0.4", "best_ask": "0.47"}], "timestamp": "1769384141081", "event_type": "price_change"}}
{"_local_timestamp": "2026-01-25T23:35:41.150460+00:00", "data": {"market": "0x88608442d14bdfa98a3d2ece26857aa516f193c8161db0c8e7c779fd8f3464af", "price_changes": [{"asset_id": "20794210232738155208360248995422719359166978550921485109532388301377529305580", "price": "0.13", "size": "10156.43", "side": "BUY", "hash": "61f18b69b6a10adcde6977cca6dafb6d6d0b7665", "best_bid": "0.53", "best_ask": "0.6"}, {"asset_id": "42097535137505280315737745177128192451567567237475285083506851409423497113459", "price": "0.87", "size": "10156.43", "side": "SELL", "hash": "f4066adf110439729742cd3b3b5564de4fdbcb83", "best_bid": "0.4", "best_ask": "0.47"}], "timestamp": "1769384141082", "event_type": "price_change"}}
{"_local_timestamp": "2026-01-25T23:35:41.270953+00:00", "data": {"market": "0x88608442d14bdfa98a3d2ece26857aa516f193c8161db0c8e7c779fd8f3464af", "price_changes": [{"asset_id": "42097535137505280315737745177128192451567567237475285083506851409423497113459", "price": "0.11", "size": "100", "side": "BUY", "hash": "86dc6d1ff7f06c2ff2c9e56054d620aeed18ee21", "best_bid": "0.4", "best_ask": "0.47"}, {"asset_id": "20794210232738155208360248995422719359166978550921485109532388301377529305580", "price": "0.89", "size": "100", "side": "SELL", "hash": "b6c3367ddf12c796d6c42fffd396687b31e4799d", "best_bid": "0.53", "best_ask": "0.6"}], "timestamp": "1769384141207", "event_type": "price_change"}}
{"_local_timestamp": "2026-01-25T23:35:53.734756+00:00", "data": {"market": "0x88608442d14bdfa98a3d2ece26857aa516f193c8161db0c8e7c779fd8f3464af", "price_changes": [{"asset_id": "42097535137505280315737745177128192451567567237475285083506851409423497113459", "price": "0.11", "size": "0", "side": "BUY", "hash": "11e5e7330c61da091dfa7c93b9f7ee815facce31", "best_bid": "0.4", "best_ask": "0.47"}, {"asset_id": "20794210232738155208360248995422719359166978550921485109532388301377529305580", "price": "0.89", "size": "0", "side": "SELL", "hash": "b6b242f37ffb337c6d7fef6681804005a220dd6d", "best_bid": "0.53", "best_ask": "0.6"}], "timestamp": "1769384153665", "event_type": "price_change"}}
{"_local_timestamp": "2026-01-25T23:35:53.799911+00:00", "data": {"market": "0x88608442d14bdfa98a3d2ece26857aa516f193c8161db0c8e7c779fd8f3464af", "price_changes": [{"asset_id": "20794210232738155208360248995422719359166978550921485109532388301377529305580", "price": "0.13", "size": "0", "side": "BUY", "hash": "c647393a3c9ad4d0b48bae3b48bf7a95f5923c6b", "best_bid": "0.53", "best_ask": "0.6"}, {"asset_id": "42097535137505280315737745177128192451567567237475285083506851409423497113459", "price": "0.87", "size": "0", "side": "SELL", "hash": "7bbf4d203d78c1573077f1fca965b42c2c237bdc", "best_bid": "0.4", "best_ask": "0.47"}], "timestamp": "1769384153735", "event_type": "price_change"}}
{"_local_timestamp": "2026-01-25T23:35:53.960622+00:00", "data": {"market": "0x88608442d14bdfa98a3d2ece26857aa516f193c8161db0c8e7c779fd8f3464af", "price_changes": [{"asset_id": "42097535137505280315737745177128192451567567237475285083506851409423497113459", "price": "0.1", "size": "5153.3", "side": "BUY", "hash": "e94c13008fcd2ff41a8539a064f45ee291831e9f", "best_bid": "0.4", "best_ask": "0.47"}, {"asset_id": "20794210232738155208360248995422719359166978550921485109532388301377529305580", "price": "0.9", "size": "5153.3", "side": "SELL", "hash": "4c713d122a5593d47078d01d31c0ea047ae7bc40", "best_bid": "0.53", "best_ask": "0.6"}], "timestamp": "1769384153889", "event_type": "price_change"}}
{"_local_timestamp": "2026-01-25T23:35:57.051248+00:00", "data": {"market": "0x88608442d14bdfa98a3d2ece26857aa516f193c8161db0c8e7c779fd8f3464af", "price_changes": [{"asset_id": "42097535137505280315737745177128192451567567237475285083506851409423497113459", "price": "0.09", "size": "1190.11", "side": "BUY", "hash": "14354027e1daca2b3be66103c111d4b77075390f", "best_bid": "0.4", "best_ask": "0.47"}, {"asset_id": "20794210232738155208360248995422719359166978550921485109532388301377529305580", "price": "0.91", "size": "1190.11", "side": "SELL", "hash": "cd1b9e78c54d94a851bdc9b0a72abd3fda62cc5d", "best_bid": "0.53", "best_ask": "0.6"}], "timestamp": "1769384156983", "event_type": "price_change"}}
{"_local_timestamp": "2026-01-25T23:35:57.055312+00:00", "data": {"market": "0x88608442d14bdfa98a3d2ece26857aa516f193c8161db0c8e7c779fd8f3464af", "price_changes": [{"asset_id": "20794210232738155208360248995422719359166978550921485109532388301377529305580", "price": "0.18", "size": "890.11", "side": "BUY", "hash": "51e0a74ae2bc49b9106e150a1ed28cd7bd4f4fe3", "best_bid": "0.53", "best_ask": "0.6"}, {"asset_id": "42097535137505280315737745177128192451567567237475285083506851409423497113459", "price": "0.82", "size": "890.11", "side": "SELL", "hash": "720ca18ff9c7aa85125ac92b551cebc4deda1814", "best_bid": "0.4", "best_ask": "0.47"}], "timestamp": "1769384156983", "event_type": "price_change"}}
{"_local_timestamp": "2026-01-25T23:35:57.058183+00:00", "data": {"market": "0x88608442d14bdfa98a3d2ece26857aa516f193c8161db0c8e7c779fd8f3464af", "price_changes": [{"asset_id": "20794210232738155208360248995422719359166978550921485109532388301377529305580", "price": "0.1", "size": "300", "side": "BUY", "hash": "51e0a74ae2bc49b9106e150a1ed28cd7bd4f4fe3", "best_bid": "0.53", "best_ask": "0.6"}, {"asset_id": "42097535137505280315737745177128192451567567237475285083506851409423497113459", "price": "0.9", "size": "300", "side": "SELL", "hash": "720ca18ff9c7aa85125ac92b551cebc4deda1814", "best_bid": "0.4", "best_ask": "0.47"}], "timestamp": "1769384156983", "event_type": "price_change"}}
{"_local_timestamp": "2026-01-25T23:35:57.153613+00:00", "data": {"market": "0x88608442d14bdfa98a3d2ece26857aa516f193c8161db0c8e7c779fd8f3464af", "price_changes": [{"asset_id": "20794210232738155208360248995422719359166978550921485109532388301377529305580", "price": "0.1", "size": "1190.11", "side": "BUY", "hash": "6de7f66f225772ebbb43aac77ff1d2ff1e93037a", "best_bid": "0.53", "best_ask": "0.6"}, {"asset_id": "42097535137505280315737745177128192451567567237475285083506851409423497113459", "price": "0.9", "size": "1190.11", "side": "SELL", "hash": "94d28ff20b76ddab00f4e2cbdad8c1e2fddfbaaf", "best_bid": "0.4", "best_ask": "0.47"}], "timestamp": "1769384157076", "event_type": "price_change"}}
{"_local_timestamp": "2026-01-25T23:35:57.154314+00:00", "data": {"market": "0x88608442d14bdfa98a3d2ece26857aa516f193c8161db0c8e7c779fd8f3464af", "price_changes": [{"asset_id": "20794210232738155208360248995422719359166978550921485109532388301377529305580", "price": "0.11", "size": "5053.16", "side": "BUY", "hash": "d677bda232a8aa9845b3de38ebb486d9b0cdf843", "best_bid": "0.53", "best_ask": "0.6"}, {"asset_id": "42097535137505280315737745177128192451567567237475285083506851409423497113459", "price": "0.89", "size": "5053.16", "side": "SELL", "hash": "075cacfd0235f3acf63b592c2d2a2d95baaddea5", "best_bid": "0.4", "best_ask": "0.47"}], "timestamp": "1769384157077", "event_type": "price_change"}}
{"_local_timestamp": "2026-01-25T23:35:57.154897+00:00", "data": {"market": "0x88608442d14bdfa98a3d2ece26857aa516f193c8161db0c8e7c779fd8f3464af", "price_changes": [{"asset_id": "42097535137505280315737745177128192451567567237475285083506851409423497113459", "price": "0.08", "size": "1270.1", "side": "BUY", "hash": "1cf2672ba2ea5706fb7db7d2299a8c85267e43a4", "best_bid": "0.4", "best_ask": "0.47"}, {"asset_id": "20794210232738155208360248995422719359166978550921485109532388301377529305580", "price": "0.92", "size": "1270.1", "side": "SELL", "hash": "6fd9276237f15a26ee05adde27784415e42e84c4", "best_bid": "0.53", "best_ask": "0.6"}], "timestamp": "1769384157078", "event_type": "price_change"}}
{"_local_timestamp": "2026-01-25T23:35:57.160355+00:00", "data": {"market": "0x88608442d14bdfa98a3d2ece26857aa516f193c8161db0c8e7c779fd8f3464af", "price_changes": [{"asset_id": "42097535137505280315737745177128192451567567237475285083506851409423497113459", "price": "0.08", "size": "2160.21", "side": "BUY", "hash": "68a07eeda007099982448cfd148944b1dc388bb8", "best_bid": "0.4", "best_ask": "0.47"}, {"asset_id": "20794210232738155208360248995422719359166978550921485109532388301377529305580", "price": "0.92", "size": "2160.21", "side": "SELL", "hash": "c1984a6939f01bc6d56782acc79e452ce345db16", "best_bid": "0.53", "best_ask": "0.6"}], "timestamp": "1769384157079", "event_type": "price_change"}}
{"_local_timestamp": "2026-01-25T23:35:57.181389+00:00", "data": {"market": "0x88608442d14bdfa98a3d2ece26857aa516f193c8161db0c8e7c779fd8f3464af", "price_changes": [{"asset_id": "42097535137505280315737745177128192451567567237475285083506851409423497113459", "price": "0.08", "size": "4157.32", "side": "BUY", "hash": "b4c22e7e505abd280ee44709dc74b3d99e74b74f", "best_bid": "0.4", "best_ask": "0.47"}, {"asset_id": "20794210232738155208360248995422719359166978550921485109532388301377529305580", "price": "0.92", "size": "4157.32", "side": "SELL", "hash": "14ecdcb99baaa2f100381738bf093b74c2fb010c", "best_bid": "0.53", "best_ask": "0.6"}], "timestamp": "1769384157080", "event_type": "price_change"}}
{"_local_timestamp": "2026-01-25T23:35:57.357508+00:00", "data": {"market": "0x88608442d14bdfa98a3d2ece26857aa516f193c8161db0c8e7c779fd8f3464af", "price_changes": [{"asset_id": "20794210232738155208360248995422719359166978550921485109532388301377529305580", "price": "0.13", "size": "400", "side": "BUY", "hash": "7d9fc8d19a82608010e467a485cda05d81d7235a", "best_bid": "0.53", "best_ask": "0.6"}, {"asset_id": "42097535137505280315737745177128192451567567237475285083506851409423497113459", "price": "0.87", "size": "400", "side": "SELL", "hash": "f2ca7e70fcaaa00c369d462b150b11a832d6d425", "best_bid": "0.4", "best_ask": "0.47"}], "timestamp": "1769384157285", "event_type": "price_change"}}
{"_local_timestamp": "2026-01-25T23:35:57.358309+00:00", "data": {"market": "0x88608442d14bdfa98a3d2ece26857aa516f193c8161db0c8e7c779fd8f3464af", "price_changes": [{"asset_id": "20794210232738155208360248995422719359166978550921485109532388301377529305580", "price": "0.19", "size": "1090.11", "side": "BUY", "hash": "098744726a7723e75e5e523fb296b88f469fa8c2", "best_bid": "0.53", "best_ask": "0.6"}, {"asset_id": "42097535137505280315737745177128192451567567237475285083506851409423497113459", "price": "0.81", "size": "1090.11", "side": "SELL", "hash": "c6d393bd085c982b40f88a95807e48eed679048a", "best_bid": "0.4", "best_ask": "0.47"}], "timestamp": "1769384157286", "event_type": "price_change"}}
{"_local_timestamp": "2026-01-25T23:35:57.358908+00:00", "data": {"market": "0x88608442d14bdfa98a3d2ece26857aa516f193c8161db0c8e7c779fd8f3464af", "price_changes": [{"asset_id": "42097535137505280315737745177128192451567567237475285083506851409423497113459", "price": "0.1", "size": "5553.3", "side": "BUY", "hash": "280283d651830c038b3ba831e2e98751b6ce08b5", "best_bid": "0.4", "best_ask": "0.47"}, {"asset_id": "20794210232738155208360248995422719359166978550921485109532388301377529305580", "price": "0.9", "size": "5553.3", "side": "SELL", "hash": "b8233d5f03ea3e130a16dd7870f08619a8612580", "best_bid": "0.53", "best_ask": "0.6"}], "timestamp": "1769384157287", "event_type": "price_change"}}
{"_local_timestamp": "2026-01-25T23:35:58.395160+00:00", "data": {"market": "0x88608442d14bdfa98a3d2ece26857aa516f193c8161db0c8e7c779fd8f3464af", "price_changes": [{"asset_id": "42097535137505280315737745177128192451567567237475285083506851409423497113459", "price": "0.09", "size": "1090.11", "side": "BUY", "hash": "6180c256ebb8d090790a53274d21cbdc85a49135", "best_bid": "0.4", "best_ask": "0.47"}, {"asset_id": "20794210232738155208360248995422719359166978550921485109532388301377529305580", "price": "0.91", "size": "1090.11", "side": "SELL", "hash": "34cae4b467dee24f2446a3ce15ae781fbf3acb20", "best_bid": "0.53", "best_ask": "0.6"}], "timestamp": "1769384158329", "event_type": "price_change"}}
{"_local_timestamp": "2026-01-25T23:35:58.396586+00:00", "data": {"market": "0x88608442d14bdfa98a3d2ece26857aa516f193c8161db0c8e7c779fd8f3464af", "price_changes": [{"asset_id": "20794210232738155208360248995422719359166978550921485109532388301377529305580", "price": "0.1", "size": "1090.11", "side": "BUY", "hash": "87fb4c6c77d77bd5390f1f2962c0b9b09b2c9cb2", "best_bid": "0.53", "best_ask": "0.6"}, {"asset_id": "42097535137505280315737745177128192451567567237475285083506851409423497113459", "price": "0.9", "size": "1090.11", "side": "SELL", "hash": "52021d676d6998439cca85d388a5ecd4d0db1081", "best_bid": "0.4", "best_ask": "0.47"}], "timestamp": "1769384158329", "event_type": "price_change"}}
{"_local_timestamp": "2026-01-25T23:35:58.670870+00:00", "data": {"market": "0x88608442d14bdfa98a3d2ece26857aa516f193c8161db0c8e7c779fd8f3464af", "price_changes": [{"asset_id": "20794210232738155208360248995422719359166978550921485109532388301377529305580", "price": "0.12", "size": "100", "side": "BUY", "hash": "22938fa78601d5ba67ead7077849d7a8ae1141ae", "best_bid": "0.53", "best_ask": "0.6"}, {"asset_id": "42097535137505280315737745177128192451567567237475285083506851409423497113459", "price": "0.88", "size": "100", "side": "SELL", "hash": "41089f2f8d74a82e7555b432dcb7c9c275ea2dfc", "best_bid": "0.4", "best_ask": "0.47"}], "timestamp": "1769384158604", "event_type": "price_change"}}
{"_local_timestamp": "2026-01-25T23:35:59.547557+00:00", "data": {"market": "0x88608442d14bdfa98a3d2ece26857aa516f193c8161db0c8e7c779fd8f3464af", "price_changes": [{"asset_id": "42097535137505280315737745177128192451567567237475285083506851409423497113459", "price": "0.09", "size": "990.11", "side": "BUY", "hash": "a3c2f2c59c55dee13b1c1ff05b0fcdec906dc482", "best_bid": "0.4", "best_ask": "0.47"}, {"asset_id": "20794210232738155208360248995422719359166978550921485109532388301377529305580", "price": "0.91", "size": "990.11", "side": "SELL", "hash": "7f5642b35a1e2e5e4c8d5b9d3f42f28814cb4703", "best_bid": "0.53", "best_ask": "0.6"}], "timestamp": "1769384159466", "event_type": "price_change"}}
{"_local_timestamp": "2026-01-25T23:35:59.548382+00:00", "data": {"market": "0x88608442d14bdfa98a3d2ece26857aa516f193c8161db0c8e7c779fd8f3464af", "price_changes": [{"asset_id": "20794210232738155208360248995422719359166978550921485109532388301377529305580", "price": "0.1", "size": "990.11", "side": "BUY", "hash": "23460c178ad6ed6d782eee203bcc4c7010f0a786", "best_bid": "0.53", "best_ask": "0.6"}, {"asset_id": "42097535137505280315737745177128192451567567237475285083506851409423497113459", "price": "0.9", "size": "990.11", "side": "SELL", "hash": "3947e2cb3f4fa6c731693b5a29646db917fce857", "best_bid": "0.4", "best_ask": "0.47"}], "timestamp": "1769384159466", "event_type": "price_change"}}
{"_local_timestamp": "2026-01-25T23:35:59.631145+00:00", "data": {"market": "0x88608442d14bdfa98a3d2ece26857aa516f193c8161db0c8e7c779fd8f3464af", "price_changes": [{"asset_id": "42097535137505280315737745177128192451567567237475285083506851409423497113459", "price": "0.1", "size": "3556.19", "side": "BUY", "hash": "a831fdbba8cdea524d5e2d756510026d635bdf86", "best_bid": "0.4", "best_ask": "0.47"}, {"asset_id": "20794210232738155208360248995422719359166978550921485109532388301377529305580", "price": "0.9", "size": "3556.19", "side": "SELL", "hash": "8f360b933d7c2d697686f364a2b9a3f429dfab11", "best_bid": "0.53", "best_ask": "0.6"}], "timestamp": "1769384159565", "event_type": "price_change"}}
{"_local_timestamp": "2026-01-25T23:35:59.715173+00:00", "data": {"market": "0x88608442d14bdfa98a3d2ece26857aa516f193c8161db0c8e7c779fd8f3464af", "price_changes": [{"asset_id": "20794210232738155208360248995422719359166978550921485109532388301377529305580", "price": "0.18", "size": "0", "side": "BUY", "hash": "b8c510b356f29381e62da747ddd9c2bdce2661e6", "best_bid": "0.53", "best_ask": "0.6"}, {"asset_id": "42097535137505280315737745177128192451567567237475285083506851409423497113459", "price": "0.82", "size": "0", "side": "SELL", "hash": "0d3c60dc31b389afe901a7db0111d9cce7bd559f", "best_bid": "0.4", "best_ask": "0.47"}], "timestamp": "1769384159644", "event_type": "price_change"}}
{"_local_timestamp": "2026-01-25T23:35:59.715967+00:00", "data": {"market": "0x88608442d14bdfa98a3d2ece26857aa516f193c8161db0c8e7c779fd8f3464af", "price_changes": [{"asset_id": "42097535137505280315737745177128192451567567237475285083506851409423497113459", "price": "0.1", "size": "1395.98", "side": "BUY", "hash": "d278735e2f3113dcbd1432da9e94ce519e3445ed", "best_bid": "0.4", "best_ask": "0.47"}, {"asset_id": "20794210232738155208360248995422719359166978550921485109532388301377529305580", "price": "0.9", "size": "1395.98", "side": "SELL", "hash": "1b190b9247c24e19e8a0667b91af47c8f3dbdab5", "best_bid": "0.53", "best_ask": "0.6"}], "timestamp": "1769384159644", "event_type": "price_change"}}
{"_local_timestamp": "2026-01-25T23:35:59.791218+00:00", "data": {"market": "0x88608442d14bdfa98a3d2ece26857aa516f193c8161db0c8e7c779fd8f3464af", "price_changes": [{"asset_id": "20794210232738155208360248995422719359166978550921485109532388301377529305580", "price": "0.11", "size": "895.84", "side": "BUY", "hash": "510ccf5a3cdb24baf137cd5905be37a2c043462c", "best_bid": "0.53", "best_ask": "0.6"}, {"asset_id": "42097535137505280315737745177128192451567567237475285083506851409423497113459", "price": "0.89", "size": "895.84", "side": "SELL", "hash": "946e54544dc156e509aac12695416fe5544970b3", "best_bid": "0.4", "best_ask": "0.47"}], "timestamp": "1769384159719", "event_type": "price_change"}}
{"_local_timestamp": "2026-01-25T23:35:59.792011+00:00", "data": {"market": "0x88608442d14bdfa98a3d2ece26857aa516f193c8161db0c8e7c779fd8f3464af", "price_changes": [{"asset_id": "20794210232738155208360248995422719359166978550921485109532388301377529305580", "price": "0.1", "size": "100", "side": "BUY", "hash": "510ccf5a3cdb24baf137cd5905be37a2c043462c", "best_bid": "0.53", "best_ask": "0.6"}, {"asset_id": "42097535137505280315737745177128192451567567237475285083506851409423497113459", "price": "0.9", "size": "100", "side": "SELL", "hash": "946e54544dc156e509aac12695416fe5544970b3", "best_bid": "0.4", "best_ask": "0.47"}], "timestamp": "1769384159719", "event_type": "price_change"}}
{"_local_timestamp": "2026-01-25T23:35:59.835004+00:00", "data": {"market": "0x88608442d14bdfa98a3d2ece26857aa516f193c8161db0c8e7c779fd8f3464af", "price_changes": [{"asset_id": "20794210232738155208360248995422719359166978550921485109532388301377529305580", "price": "0.12", "size": "200", "side": "BUY", "hash": "12d9c3f642c89d34f72cdd95fddbe350ef5660d6", "best_bid": "0.53", "best_ask": "0.6"}, {"asset_id": "42097535137505280315737745177128192451567567237475285083506851409423497113459", "price": "0.88", "size": "200", "side": "SELL", "hash": "9309b27d85864575bf0781892df55ded68b93b77", "best_bid": "0.4", "best_ask": "0.47"}], "timestamp": "1769384159759", "event_type": "price_change"}}
{"_local_timestamp": "2026-01-25T23:36:01.892846+00:00", "data": {"market": "0x88608442d14bdfa98a3d2ece26857aa516f193c8161db0c8e7c779fd8f3464af", "price_changes": [{"asset_id": "42097535137505280315737745177128192451567567237475285083506851409423497113459", "price": "0.09", "size": "890.11", "side": "BUY", "hash": "a19a824793bd5230dad9a03f0d5aaf538a7c8cfe", "best_bid": "0.4", "best_ask": "0.47"}, {"asset_id": "20794210232738155208360248995422719359166978550921485109532388301377529305580", "price": "0.91", "size": "890.11", "side": "SELL", "hash": "4b618414a1766aeeb44af4f093ebee495b7cd8df", "best_bid": "0.53", "best_ask": "0.6"}], "timestamp": "1769384161826", "event_type": "price_change"}}
{"_local_timestamp": "2026-01-25T23:36:01.903448+00:00", "data": {"market": "0x88608442d14bdfa98a3d2ece26857aa516f193c8161db0c8e7c779fd8f3464af", "price_changes": [{"asset_id": "20794210232738155208360248995422719359166978550921485109532388301377529305580", "price": "0.1", "size": "0", "side": "BUY", "hash": "0629d957c4a5bb3745f0ebef77b096f457442ebc", "best_bid": "0.53", "best_ask": "0.6"}, {"asset_id": "42097535137505280315737745177128192451567567237475285083506851409423497113459", "price": "0.9", "size": "0", "side": "SELL", "hash": "906f50af53ab1663adc29e9682957db0efe8ac87", "best_bid": "0.4", "best_ask": "0.47"}], "timestamp": "1769384161826", "event_type": "price_change"}}
{"_local_timestamp": "2026-01-25T23:36:01.986947+00:00", "data": {"market": "0x88608442d14bdfa98a3d2ece26857aa516f193c8161db0c8e7c779fd8f3464af", "price_changes": [{"asset_id": "42097535137505280315737745177128192451567567237475285083506851409423497113459", "price": "0.09", "size": "0", "side": "BUY", "hash": "9f88e56b59fc27e1152b5738b57e0ee6fd361a4c", "best_bid": "0.4", "best_ask": "0.47"}, {"asset_id": "20794210232738155208360248995422719359166978550921485109532388301377529305580", "price": "0.91", "size": "0", "side": "SELL", "hash": "e25042fda22d1dc9b640bc64a0e9bda8a6058a8b", "best_bid": "0.53", "best_ask": "0.6"}], "timestamp": "1769384161916", "event_type": "price_change"}}
{"_local_timestamp": "2026-01-25T23:36:01.987687+00:00", "data": {"market": "0x88608442d14bdfa98a3d2ece26857aa516f193c8161db0c8e7c779fd8f3464af", "price_changes": [{"asset_id": "20794210232738155208360248995422719359166978550921485109532388301377529305580", "price": "0.11", "size": "5.73", "side": "BUY", "hash": "ae6398e734539d0f4f9674185e2088550501a72e", "best_bid": "0.53", "best_ask": "0.6"}, {"asset_id": "42097535137505280315737745177128192451567567237475285083506851409423497113459", "price": "0.89", "size": "5.73", "side": "SELL", "hash": "40dd467ede5c4408acca7bed8b4dbbf24bc91a8c", "best_bid": "0.4", "best_ask": "0.47"}], "timestamp": "1769384161917", "event_type": "price_change"}}
{"_local_timestamp": "2026-01-25T23:36:02.063602+00:00", "data": {"market": "0x88608442d14bdfa98a3d2ece26857aa516f193c8161db0c8e7c779fd8f3464af", "price_changes": [{"asset_id": "20794210232738155208360248995422719359166978550921485109532388301377529305580", "price": "0.08", "size": "1997.11", "side": "BUY", "hash": "a2713331bc31e43234cb23d0fbee78d84801cb64", "best_bid": "0.53", "best_ask": "0.6"}, {"asset_id": "42097535137505280315737745177128192451567567237475285083506851409423497113459", "price": "0.92", "size": "1997.11", "side": "SELL", "hash": "a2e9e9edcec1e35f7eddbdadb497352dc722c5d8", "best_bid": "0.4", "best_ask": "0.47"}], "timestamp": "1769384161992", "event_type": "price_change"}}
{"_local_timestamp": "2026-01-25T23:36:02.064384+00:00", "data": {"market": "0x88608442d14bdfa98a3d2ece26857aa516f193c8161db0c8e7c779fd8f3464af", "price_changes": [{"asset_id": "20794210232738155208360248995422719359166978550921485109532388301377529305580", "price": "0.08", "size": "2887.22", "side": "BUY", "hash": "c465dffd9cd3430c043cca8bb2f266312deaf785", "best_bid": "0.53", "best_ask": "0.6"}, {"asset_id": "42097535137505280315737745177128192451567567237475285083506851409423497113459", "price": "0.92", "size": "2887.22", "side": "SELL", "hash": "2d9d8085e9ea39f55e6be751d0c8c3c4470aab0c", "best_bid": "0.4", "best_ask": "0.47"}], "timestamp": "1769384161993", "event_type": "price_change"}}
{"_local_timestamp": "2026-01-25T23:36:02.065021+00:00", "data": {"market": "0x88608442d14bdfa98a3d2ece26857aa516f193c8161db0c8e7c779fd8f3464af", "price_changes": [{"asset_id": "20794210232738155208360248995422719359166978550921485109532388301377529305580", "price": "0.08", "size": "4157.32", "side": "BUY", "hash": "f772d249b3021d57189cd1dfe2a23ed653d6e8fa", "best_bid": "0.53", "best_ask": "0.6"}, {"asset_id": "42097535137505280315737745177128192451567567237475285083506851409423497113459", "price": "0.92", "size": "4157.32", "side": "SELL", "hash": "3b16eb6e4440ea6a9be3d44e53d8b88badffb590", "best_bid": "0.4", "best_ask": "0.47"}], "timestamp": "1769384161993", "event_type": "price_change"}}
{"_local_timestamp": "2026-01-25T23:36:02.065636+00:00", "data": {"market": "0x88608442d14bdfa98a3d2ece26857aa516f193c8161db0c8e7c779fd8f3464af", "price_changes": [{"asset_id": "42097535137505280315737745177128192451567567237475285083506851409423497113459", "price": "0.11", "size": "890.11", "side": "BUY", "hash": "bf35b424a392a25a6f55690e6aa03365ed9396ad", "best_bid": "0.4", "best_ask": "0.47"}, {"asset_id": "20794210232738155208360248995422719359166978550921485109532388301377529305580", "price": "0.89", "size": "890.11", "side": "SELL", "hash": "c0ecc6bb67a5e7f8d0f42976cc5be910e28da5de", "best_bid": "0.53", "best_ask": "0.6"}], "timestamp": "1769384161994", "event_type": "price_change"}}
{"_local_timestamp": "2026-01-25T23:36:02.195695+00:00", "data": {"market": "0x88608442d14bdfa98a3d2ece26857aa516f193c8161db0c8e7c779fd8f3464af", "price_changes": [{"asset_id": "20794210232738155208360248995422719359166978550921485109532388301377529305580", "price": "0.12", "size": "300", "side": "BUY", "hash": "a3d1cfb1aac4ea2c7b9e9c4dc96dba0a5734bcfd", "best_bid": "0.53", "best_ask": "0.6"}, {"asset_id": "42097535137505280315737745177128192451567567237475285083506851409423497113459", "price": "0.88", "size": "300", "side": "SELL", "hash": "2c949ad79673d4dfdd91c2eb3f87fc0e94d939fd", "best_bid": "0.4", "best_ask": "0.47"}], "timestamp": "1769384162119", "event_type": "price_change"}}
{"_local_timestamp": "2026-01-25T23:36:02.253874+00:00", "data": {"market": "0x88608442d14bdfa98a3d2ece26857aa516f193c8161db0c8e7c779fd8f3464af", "price_changes": [{"asset_id": "20794210232738155208360248995422719359166978550921485109532388301377529305580", "price": "0.2", "size": "940.11", "side": "BUY", "hash": "d22267204e863f9ee350abadc70ea3511cf05a94", "best_bid": "0.53", "best_ask": "0.6"}, {"asset_id": "42097535137505280315737745177128192451567567237475285083506851409423497113459", "price": "0.8", "size": "940.11", "side": "SELL", "hash": "0162c5bd69669845a1eb2c237e499bcc140f655b", "best_bid": "0.4", "best_ask": "0.47"}], "timestamp": "1769384162187", "event_type": "price_change"}}
{"_local_timestamp": "2026-01-25T23:36:04.630528+00:00", "data": {"market": "0x72ba07862b22314dbe4f409505a9833da2dfb3ffe2f6a1c8fa1ba3add5e7a039", "price_changes": [{"asset_id": "2984940558574601482400602739691261511463191599721533374910685943278753091727", "price": "0.04", "size": "0", "side": "BUY", "hash": "9ad3bc45a11512a9d8893bd6f7a576b6d2e739d7", "best_bid": "0.05", "best_ask": "0.98"}, {"asset_id": "93425111955845150480136289753481493030447902158015790781546943758014021748210", "price": "0.96", "size": "0", "side": "SELL", "hash": "b2e7f5c6933fcc84cda0f4bd21a89f70047e763d", "best_bid": "0.02", "best_ask": "0.95"}], "timestamp": "1769384164564", "event_type": "price_change"}}
{"_local_timestamp": "2026-01-25T23:36:05.906733+00:00", "data": {"market": "0x72ba07862b22314dbe4f409505a9833da2dfb3ffe2f6a1c8fa1ba3add5e7a039", "price_changes": [{"asset_id": "2984940558574601482400602739691261511463191599721533374910685943278753091727", "price": "0.05", "size": "0", "side": "BUY", "hash": "067ad049673ae956497c55ba5454ef2504e714da", "best_bid": "0.02", "best_ask": "0.98"}, {"asset_id": "93425111955845150480136289753481493030447902158015790781546943758014021748210", "price": "0.95", "size": "0", "side": "SELL", "hash": "7e1e7047270e0e376b9541fd9e43ecbd0ad1ba2e", "best_bid": "0.02", "best_ask": "0.98"}], "timestamp": "1769384165832", "event_type": "price_change"}}
{"_local_timestamp": "2026-01-25T23:36:05.946729+00:00", "data": {"market": "0x72ba07862b22314dbe4f409505a9833da2dfb3ffe2f6a1c8fa1ba3add5e7a039", "price_changes": [{"asset_id": "2984940558574601482400602739691261511463191599721533374910685943278753091727", "price": "0.03", "size": "5.47", "side": "BUY", "hash": "25f9db0630fb0b4b5e636d261da9d2df1a2bc3a8", "best_bid": "0.03", "best_ask": "0.98"}, {"asset_id": "93425111955845150480136289753481493030447902158015790781546943758014021748210", "price": "0.97", "size": "5.47", "side": "SELL", "hash": "732080157262b703ff128bcc57229306da07c343", "best_bid": "0.02", "best_ask": "0.97"}], "timestamp": "1769384165880", "event_type": "price_change"}}
{"_local_timestamp": "2026-01-25T23:36:07.781014+00:00", "data": {"market": "0x72ba07862b22314dbe4f409505a9833da2dfb3ffe2f6a1c8fa1ba3add5e7a039", "price_changes": [{"asset_id": "93425111955845150480136289753481493030447902158015790781546943758014021748210", "price": "0.5", "size": "222.22", "side": "BUY", "hash": "8ef254b2658cccd2bf5d4ed43adc89b48c9b0d89", "best_bid": "0.5", "best_ask": "0.97"}, {"asset_id": "2984940558574601482400602739691261511463191599721533374910685943278753091727", "price": "0.5", "size": "222.22", "side": "SELL", "hash": "505a6339db61c2ee36149a18dcf5444adf427df2", "best_bid": "0.03", "best_ask": "0.5"}], "timestamp": "1769384167712", "event_type": "price_change"}}
{"_local_timestamp": "2026-01-25T23:36:17.008522+00:00", "data": {"market": "0x72ba07862b22314dbe4f409505a9833da2dfb3ffe2f6a1c8fa1ba3add5e7a039", "price_changes": [{"asset_id": "93425111955845150480136289753481493030447902158015790781546943758014021748210", "price": "0.5", "size": "0", "side": "BUY", "hash": "5211fa68c9285a538102edcaa69ac07269c73ea9", "best_bid": "0.02", "best_ask": "0.97"}, {"asset_id": "2984940558574601482400602739691261511463191599721533374910685943278753091727", "price": "0.5", "size": "0", "side": "SELL", "hash": "df2e5b696735d0cfb9eeb41154eafe64501b2d59", "best_bid": "0.03", "best_ask": "0.98"}], "timestamp": "1769384176942", "event_type": "price_change"}}
{"_local_timestamp": "2026-01-25T23:36:18.118987+00:00", "data": {"market": "0x88608442d14bdfa98a3d2ece26857aa516f193c8161db0c8e7c779fd8f3464af", "price_changes": [{"asset_id": "42097535137505280315737745177128192451567567237475285083506851409423497113459", "price": "0.1", "size": "1295.98", "side": "BUY", "hash": "3b5fb90fa96cb1db660526a7d0de06c89aedec1c", "best_bid": "0.4", "best_ask": "0.47"}, {"asset_id": "20794210232738155208360248995422719359166978550921485109532388301377529305580", "price": "0.9", "size": "1295.98", "side": "SELL", "hash": "9a4df1656f8244eac8ec3c8476772712d1d99bc1", "best_bid": "0.53", "best_ask": "0.6"}], "timestamp": "1769384178037", "event_type": "price_change"}}
{"_local_timestamp": "2026-01-25T23:36:18.349636+00:00", "data": {"market": "0x88608442d14bdfa98a3d2ece26857aa516f193c8161db0c8e7c779fd8f3464af", "price_changes": [{"asset_id": "42097535137505280315737745177128192451567567237475285083506851409423497113459", "price": "0.11", "size": "990.11", "side": "BUY", "hash": "c4b0731b77b70c0b1ee78cf545d9ecaeb67376dd", "best_bid": "0.4", "best_ask": "0.47"}, {"asset_id": "20794210232738155208360248995422719359166978550921485109532388301377529305580", "price": "0.89", "size": "990.11", "side": "SELL", "hash": "debe3523d8f4b05bcd0d33b652059138f6eae92f", "best_bid": "0.53", "best_ask": "0.6"}], "timestamp": "1769384178279", "event_type": "price_change"}}
{"_local_timestamp": "2026-01-25T23:36:18.515348+00:00", "data": {"market": "0x88608442d14bdfa98a3d2ece26857aa516f193c8161db0c8e7c779fd8f3464af", "price_changes": [{"asset_id": "20794210232738155208360248995422719359166978550921485109532388301377529305580", "price": "0.13", "size": "0", "side": "BUY", "hash": "fa16e100299fe69187a91209a6ffd015e9f7b4c3", "best_bid": "0.53", "best_ask": "0.6"}, {"asset_id": "42097535137505280315737745177128192451567567237475285083506851409423497113459", "price": "0.87", "size": "0", "side": "SELL", "hash": "9d264c50473c4a757623d008f77cdfe35298cc09", "best_bid": "0.4", "best_ask": "0.47"}], "timestamp": "1769384178451", "event_type": "price_change"}}
{"_local_timestamp": "2026-01-25T23:36:18.520060+00:00", "data": {"market": "0x88608442d14bdfa98a3d2ece26857aa516f193c8161db0c8e7c779fd8f3464af", "price_changes": [{"asset_id": "20794210232738155208360248995422719359166978550921485109532388301377529305580", "price": "0.19", "size": "890.11", "side": "BUY", "hash": "fa16e100299fe69187a91209a6ffd015e9f7b4c3", "best_bid": "0.53", "best_ask": "0.6"}, {"asset_id": "42097535137505280315737745177128192451567567237475285083506851409423497113459", "price": "0.81", "size": "890.11", "side": "SELL", "hash": "9d264c50473c4a757623d008f77cdfe35298cc09", "best_bid": "0.4", "best_ask": "0.47"}], "timestamp": "1769384178451", "event_type": "price_change"}}
{"_local_timestamp": "2026-01-25T23:36:18.520905+00:00", "data": {"market": "0x88608442d14bdfa98a3d2ece26857aa516f193c8161db0c8e7c779fd8f3464af", "price_changes": [{"asset_id": "42097535137505280315737745177128192451567567237475285083506851409423497113459", "price": "0.1", "size": "895.98", "side": "BUY", "hash": "7a41905b1f2f0984c11bc7533106167bf3d8189c", "best_bid": "0.4", "best_ask": "0.47"}, {"asset_id": "20794210232738155208360248995422719359166978550921485109532388301377529305580", "price": "0.9", "size": "895.98", "side": "SELL", "hash": "76822acf86b85ae40318858ba6d94c4ec4eaef6b", "best_bid": "0.53", "best_ask": "0.6"}], "timestamp": "1769384178452", "event_type": "price_change"}}
{"_local_timestamp": "2026-01-25T23:36:18.637893+00:00", "data": {"market": "0x88608442d14bdfa98a3d2ece26857aa516f193c8161db0c8e7c779fd8f3464af", "price_changes": [{"asset_id": "42097535137505280315737745177128192451567567237475285083506851409423497113459", "price": "0.07", "size": "2590.11", "side": "BUY", "hash": "16c56bb01049e3f587b7e386e927fb4f5b7196d1", "best_bid": "0.4", "best_ask": "0.47"}, {"asset_id": "20794210232738155208360248995422719359166978550921485109532388301377529305580", "price": "0.93", "size": "2590.11", "side": "SELL", "hash": "0e837ce2fbc0b5d327bf7e25da838f8bbed930a0", "best_bid": "0.53", "best_ask": "0.6"}], "timestamp": "1769384178573", "event_type": "price_change"}}
{"_local_timestamp": "2026-01-25T23:36:18.687587+00:00", "data": {"market": "0x88608442d14bdfa98a3d2ece26857aa516f193c8161db0c8e7c779fd8f3464af", "price_changes": [{"asset_id": "20794210232738155208360248995422719359166978550921485109532388301377529305580", "price": "0.13", "size": "890.11", "side": "BUY", "hash": "abf355cb40b3bf72fb85068289ff34386c524685", "best_bid": "0.53", "best_ask": "0.6"}, {"asset_id": "42097535137505280315737745177128192451567567237475285083506851409423497113459", "price": "0.87", "size": "890.11", "side": "SELL", "hash": "0453872aaf64a22daf0dd746a8fcef9b8971a550", "best_bid": "0.4", "best_ask": "0.47"}], "timestamp": "1769384178622", "event_type": "price_change"}}
{"_local_timestamp": "2026-01-25T23:36:18.689819+00:00", "data": {"market": "0x88608442d14bdfa98a3d2ece26857aa516f193c8161db0c8e7c779fd8f3464af", "price_changes": [{"asset_id": "20794210232738155208360248995422719359166978550921485109532388301377529305580", "price": "0.12", "size": "1190.11", "side": "BUY", "hash": "99fc99a1c850a82571f84c727f3656416cf18694", "best_bid": "0.53", "best_ask": "0.6"}, {"asset_id": "42097535137505280315737745177128192451567567237475285083506851409423497113459", "price": "0.88", "size": "1190.11", "side": "SELL", "hash": "f8ead9d997691f295e169715597719a33573ef9f", "best_bid": "0.4", "best_ask": "0.47"}], "timestamp": "1769384178623", "event_type": "price_change"}}
{"_local_timestamp": "2026-01-25T23:36:18.690664+00:00", "data": {"market": "0x88608442d14bdfa98a3d2ece26857aa516f193c8161db0c8e7c779fd8f3464af", "price_changes": [{"asset_id": "42097535137505280315737745177128192451567567237475285083506851409423497113459", "price": "0.08", "size": "5047.43", "side": "BUY", "hash": "b2f7bd0a40d93691f8229ccffd57810911051d5b", "best_bid": "0.4", "best_ask": "0.47"}, {"asset_id": "20794210232738155208360248995422719359166978550921485109532388301377529305580", "price": "0.92", "size": "5047.43", "side": "SELL", "hash": "6baa04c6fb467663413c0bf50b68b996e3a7c099", "best_bid": "0.53", "best_ask": "0.6"}], "timestamp": "1769384178624", "event_type": "price_change"}}
{"_local_timestamp": "2026-01-25T23:36:18.793991+00:00", "data": {"market": "0x88608442d14bdfa98a3d2ece26857aa516f193c8161db0c8e7c779fd8f3464af", "price_changes": [{"asset_id": "20794210232738155208360248995422719359166978550921485109532388301377529305580", "price": "0.2", "size": "1140.11", "side": "BUY", "hash": "5e056eb212d3e9c6b6cbd9dc25afbad5547b6d29", "best_bid": "0.53", "best_ask": "0.6"}, {"asset_id": "42097535137505280315737745177128192451567567237475285083506851409423497113459", "price": "0.8", "size": "1140.11", "side": "SELL", "hash": "1cc233ab80852017660d2c4edb1d6922f03acd14", "best_bid": "0.4", "best_ask": "0.47"}], "timestamp": "1769384178720", "event_type": "price_change"}}
{"_local_timestamp": "2026-01-25T23:36:18.794868+00:00", "data": {"market": "0x88608442d14bdfa98a3d2ece26857aa516f193c8161db0c8e7c779fd8f3464af", "price_changes": [{"asset_id": "42097535137505280315737745177128192451567567237475285083506851409423497113459", "price": "0.08", "size": "5447.43", "side": "BUY", "hash": "a8d2422b8e258d4d774d6a22b04bbccb0e67fca5", "best_bid": "0.4", "best_ask": "0.47"}, {"asset_id": "20794210232738155208360248995422719359166978550921485109532388301377529305580", "price": "0.92", "size": "5447.43", "side": "SELL", "hash": "964dddd1e63db289df43cdce6e77abe169c1a00c", "best_bid": "0.53", "best_ask": "0.6"}], "timestamp": "1769384178721", "event_type": "price_change"}}
{"_local_timestamp": "2026-01-25T23:36:18.796686+00:00", "data": {"market": "0x88608442d14bdfa98a3d2ece26857aa516f193c8161db0c8e7c779fd8f3464af", "price_changes": [{"asset_id": "20794210232738155208360248995422719359166978550921485109532388301377529305580", "price": "0.08", "size": "4557.32", "side": "BUY", "hash": "3cc6fcc9609d76ca1629b3e5bc294a7b26f3b3a5", "best_bid": "0.53", "best_ask": "0.6"}, {"asset_id": "42097535137505280315737745177128192451567567237475285083506851409423497113459", "price": "0.92", "size": "4557.32", "side": "SELL", "hash": "223c3dbeb5ce638012ac3d9e1b63cacd6c6cd2fc", "best_bid": "0.4", "best_ask": "0.47"}], "timestamp": "1769384178722", "event_type": "price_change"}}
{"_local_timestamp": "2026-01-25T23:36:23.543965+00:00", "data": {"market": "0x88608442d14bdfa98a3d2ece26857aa516f193c8161db0c8e7c779fd8f3464af", "price_changes": [{"asset_id": "20794210232738155208360248995422719359166978550921485109532388301377529305580", "price": "0.12", "size": "1090.11", "side": "BUY", "hash": "4454f7f6e2a3a9116776552207f2f97b6c144d7b", "best_bid": "0.53", "best_ask": "0.6"}, {"asset_id": "42097535137505280315737745177128192451567567237475285083506851409423497113459", "price": "0.88", "size": "1090.11", "side": "SELL", "hash": "6b8b138c9ca9d9532476f6a8fac5d198bd1211b6", "best_bid": "0.4", "best_ask": "0.47"}], "timestamp": "1769384183478", "event_type": "price_change"}}
{"_local_timestamp": "2026-01-25T23:36:23.611721+00:00", "data": {"market": "0x88608442d14bdfa98a3d2ece26857aa516f193c8161db0c8e7c779fd8f3464af", "price_changes": [{"asset_id": "20794210232738155208360248995422719359166978550921485109532388301377529305580", "price": "0.21", "size": "890.11", "side": "BUY", "hash": "e7a083fdee09f7ed127e19f2f899ea891a6472ce", "best_bid": "0.53", "best_ask": "0.6"}, {"asset_id": "42097535137505280315737745177128192451567567237475285083506851409423497113459", "price": "0.79", "size": "890.11", "side": "SELL", "hash": "374942b4a9f510ca041089a8894efca97d8950c1", "best_bid": "0.4", "best_ask": "0.47"}], "timestamp": "1769384183543", "event_type": "price_change"}}
{"_local_timestamp": "2026-01-25T23:36:23.612519+00:00", "data": {"market": "0x88608442d14bdfa98a3d2ece26857aa516f193c8161db0c8e7c779fd8f3464af", "price_changes": [{"asset_id": "42097535137505280315737745177128192451567567237475285083506851409423497113459", "price": "0.09", "size": "890.11", "side": "BUY", "hash": "f4636502031a29029c4c4dd301274668d88fe594", "best_bid": "0.4", "best_ask": "0.47"}, {"asset_id": "20794210232738155208360248995422719359166978550921485109532388301377529305580", "price": "0.91", "size": "890.11", "side": "SELL", "hash": "7cbb4c0cc20326f9702ca459601e0d7cd6b76147", "best_bid": "0.53", "best_ask": "0.6"}], "timestamp": "1769384183543", "event_type": "price_change"}}
{"_local_timestamp": "2026-01-25T23:36:23.622059+00:00", "data": {"market": "0x88608442d14bdfa98a3d2ece26857aa516f193c8161db0c8e7c779fd8f3464af", "price_changes": [{"asset_id": "20794210232738155208360248995422719359166978550921485109532388301377529305580", "price": "0.19", "size": "0", "side": "BUY", "hash": "23c413935417b4f16dbd98f14fcef38e91419921", "best_bid": "0.53", "best_ask": "0.6"}, {"asset_id": "42097535137505280315737745177128192451567567237475285083506851409423497113459", "price": "0.81", "size": "0", "side": "SELL", "hash": "2388e022305f7fb9a7cbb91a244ea84cd163b535", "best_bid": "0.4", "best_ask": "0.47"}], "timestamp": "1769384183558", "event_type": "price_change"}}
{"_local_timestamp": "2026-01-25T23:36:23.623880+00:00", "data": {"market": "0x88608442d14bdfa98a3d2ece26857aa516f193c8161db0c8e7c779fd8f3464af", "price_changes": [{"asset_id": "20794210232738155208360248995422719359166978550921485109532388301377529305580", "price": "0.13", "size": "0", "side": "BUY", "hash": "23c413935417b4f16dbd98f14fcef38e91419921", "best_bid": "0.53", "best_ask": "0.6"}, {"asset_id": "42097535137505280315737745177128192451567567237475285083506851409423497113459", "price": "0.87", "size": "0", "side": "SELL", "hash": "2388e022305f7fb9a7cbb91a244ea84cd163b535", "best_bid": "0.4", "best_ask": "0.47"}], "timestamp": "1769384183558", "event_type": "price_change"}}
{"_local_timestamp": "2026-01-25T23:36:23.624622+00:00", "data": {"market": "0x88608442d14bdfa98a3d2ece26857aa516f193c8161db0c8e7c779fd8f3464af", "price_changes": [{"asset_id": "20794210232738155208360248995422719359166978550921485109532388301377529305580", "price": "0.12", "size": "200", "side": "BUY", "hash": "23c413935417b4f16dbd98f14fcef38e91419921", "best_bid": "0.53", "best_ask": "0.6"}, {"asset_id": "42097535137505280315737745177128192451567567237475285083506851409423497113459", "price": "0.88", "size": "200", "side": "SELL", "hash": "2388e022305f7fb9a7cbb91a244ea84cd163b535", "best_bid": "0.4", "best_ask": "0.47"}], "timestamp": "1769384183558", "event_type": "price_change"}}
{"_local_timestamp": "2026-01-25T23:36:23.625287+00:00", "data": {"market": "0x88608442d14bdfa98a3d2ece26857aa516f193c8161db0c8e7c779fd8f3464af", "price_changes": [{"asset_id": "42097535137505280315737745177128192451567567237475285083506851409423497113459", "price": "0.1", "size": "5.87", "side": "BUY", "hash": "359b08506c3ee7ae4e7b85c2a78a388ace4dbd97", "best_bid": "0.4", "best_ask": "0.47"}, {"asset_id": "20794210232738155208360248995422719359166978550921485109532388301377529305580", "price": "0.9", "size": "5.87", "side": "SELL", "hash": "b9f90f0b103a5e67872fbbf576a84c4d6db318b3", "best_bid": "0.53", "best_ask": "0.6"}], "timestamp": "1769384183559", "event_type": "price_change"}}
{"_local_timestamp": "2026-01-25T23:36:23.627935+00:00", "data": {"market": "0x88608442d14bdfa98a3d2ece26857aa516f193c8161db0c8e7c779fd8f3464af", "price_changes": [{"asset_id": "42097535137505280315737745177128192451567567237475285083506851409423497113459", "price": "0.11", "size": "100", "side": "BUY", "hash": "359b08506c3ee7ae4e7b85c2a78a388ace4dbd97", "best_bid": "0.4", "best_ask": "0.47"}, {"asset_id": "20794210232738155208360248995422719359166978550921485109532388301377529305580", "price": "0.89", "size": "100", "side": "SELL", "hash": "b9f90f0b103a5e67872fbbf576a84c4d6db318b3", "best_bid": "0.53", "best_ask": "0.6"}], "timestamp": "1769384183559", "event_type": "price_change"}}
{"_local_timestamp": "2026-01-25T23:36:23.628770+00:00", "data": {"market": "0x88608442d14bdfa98a3d2ece26857aa516f193c8161db0c8e7c779fd8f3464af", "price_changes": [{"asset_id": "42097535137505280315737745177128192451567567237475285083506851409423497113459", "price": "0.07", "size": "1700", "side": "BUY", "hash": "359b08506c3ee7ae4e7b85c2a78a388ace4dbd97", "best_bid": "0.4", "best_ask": "0.47"}, {"asset_id": "20794210232738155208360248995422719359166978550921485109532388301377529305580", "price": "0.93", "size": "1700", "side": "SELL", "hash": "b9f90f0b103a5e67872fbbf576a84c4d6db318b3", "best_bid": "0.53", "best_ask": "0.6"}], "timestamp": "1769384183559", "event_type": "price_change"}}
{"_local_timestamp": "2026-01-25T23:36:23.675631+00:00", "data": {"market": "0x88608442d14bdfa98a3d2ece26857aa516f193c8161db0c8e7c779fd8f3464af", "price_changes": [{"asset_id": "20794210232738155208360248995422719359166978550921485109532388301377529305580", "price": "0.22", "size": "890.11", "side": "BUY", "hash": "af2bf045535e45c32a88fd288d0dc9636b349b18", "best_bid": "0.53", "best_ask": "0.6"}, {"asset_id": "42097535137505280315737745177128192451567567237475285083506851409423497113459", "price": "0.78", "size": "890.11", "side": "SELL", "hash": "abafaa51ebc726f7d91f46dd1711d7cb43ad623f", "best_bid": "0.4", "best_ask": "0.47"}], "timestamp": "1769384183604", "event_type": "price_change"}}
{"_local_timestamp": "2026-01-25T23:36:23.676430+00:00", "data": {"market": "0x88608442d14bdfa98a3d2ece26857aa516f193c8161db0c8e7c779fd8f3464af", "price_changes": [{"asset_id": "20794210232738155208360248995422719359166978550921485109532388301377529305580", "price": "0.22", "size": "2160.21", "side": "BUY", "hash": "cc6ab443da18d640a4146bb6f7fe8579ab025015", "best_bid": "0.53", "best_ask": "0.6"}, {"asset_id": "42097535137505280315737745177128192451567567237475285083506851409423497113459", "price": "0.78", "size": "2160.21", "side": "SELL", "hash": "dade0f2a8ef74c727c9cb4d4194d2c10a5c49154", "best_bid": "0.4", "best_ask": "0.47"}], "timestamp": "1769384183605", "event_type": "price_change"}}
{"_local_timestamp": "2026-01-25T23:36:23.677107+00:00", "data": {"market": "0x88608442d14bdfa98a3d2ece26857aa516f193c8161db0c8e7c779fd8f3464af", "price_changes": [{"asset_id": "42097535137505280315737745177128192451567567237475285083506851409423497113459", "price": "0.12", "size": "890.11", "side": "BUY", "hash": "4e1f8c7d7d1b6a2e9444338038ee3a43c215c9fc", "best_bid": "0.4", "best_ask": "0.47"}, {"asset_id": "20794210232738155208360248995422719359166978550921485109532388301377529305580", "price": "0.88", "size": "890.11", "side": "SELL", "hash": "4c6722ba72a08ab9b43250eceb48d8c7ee8d4c9a", "best_bid": "0.53", "best_ask": "0.6"}], "timestamp": "1769384183606", "event_type": "price_change"}}
{"_local_timestamp": "2026-01-25T23:36:23.739477+00:00", "data": {"market": "0x88608442d14bdfa98a3d2ece26857aa516f193c8161db0c8e7c779fd8f3464af", "price_changes": [{"asset_id": "42097535137505280315737745177128192451567567237475285083506851409423497113459", "price": "0.12", "size": "2160.21", "side": "BUY", "hash": "6e4f3f426775f826d640b2a8dd6f56c1b94156f6", "best_bid": "0.4", "best_ask": "0.47"}, {"asset_id": "20794210232738155208360248995422719359166978550921485109532388301377529305580", "price": "0.88", "size": "2160.21", "side": "SELL", "hash": "0bf58b1b7ae67891205f2ccfd7fb92e1ac51f823", "best_bid": "0.53", "best_ask": "0.6"}], "timestamp": "1769384183636", "event_type": "price_change"}}
{"_local_timestamp": "2026-01-25T23:36:23.740327+00:00", "data": {"market": "0x88608442d14bdfa98a3d2ece26857aa516f193c8161db0c8e7c779fd8f3464af", "price_changes": [{"asset_id": "42097535137505280315737745177128192451567567237475285083506851409423497113459", "price": "0.12", "size": "4157.32", "side": "BUY", "hash": "ca2b459f2409859e6723db554bfb9eefe7d42503", "best_bid": "0.4", "best_ask": "0.47"}, {"asset_id": "20794210232738155208360248995422719359166978550921485109532388301377529305580", "price": "0.88", "size": "4157.32", "side": "SELL", "hash": "a2dc0fcb549d9611b0d36189aef37595a96b587d", "best_bid": "0.53", "best_ask": "0.6"}], "timestamp": "1769384183637", "event_type": "price_change"}}
{"_local_timestamp": "2026-01-25T23:36:23.853929+00:00", "data": {"market": "0x88608442d14bdfa98a3d2ece26857aa516f193c8161db0c8e7c779fd8f3464af", "price_changes": [{"asset_id": "20794210232738155208360248995422719359166978550921485109532388301377529305580", "price": "0.22", "size": "4157.32", "side": "BUY", "hash": "3d2e1b88b8d009cef5a60630f170b382f8116ad6", "best_bid": "0.53", "best_ask": "0.6"}, {"asset_id": "42097535137505280315737745177128192451567567237475285083506851409423497113459", "price": "0.78", "size": "4157.32", "side": "SELL", "hash": "391127cf5883026e296c7fff6e22ca85d141f91b", "best_bid": "0.4", "best_ask": "0.47"}], "timestamp": "1769384183769", "event_type": "price_change"}}
{"_local_timestamp": "2026-01-25T23:36:23.869267+00:00", "data": {"market": "0x88608442d14bdfa98a3d2ece26857aa516f193c8161db0c8e7c779fd8f3464af", "price_changes": [{"asset_id": "20794210232738155208360248995422719359166978550921485109532388301377529305580", "price": "0.08", "size": "4657.32", "side": "BUY", "hash": "6cd2f062e9bfabe723c3da1ed1b8f4cdcba48525", "best_bid": "0.53", "best_ask": "0.6"}, {"asset_id": "42097535137505280315737745177128192451567567237475285083506851409423497113459", "price": "0.92", "size": "4657.32", "side": "SELL", "hash": "f746f4f590178d337a7ef00cbc83f1eb1825086e", "best_bid": "0.4", "best_ask": "0.47"}], "timestamp": "1769384183779", "event_type": "price_change"}}
{"_local_timestamp": "2026-01-25T23:36:23.891857+00:00", "data": {"market": "0x88608442d14bdfa98a3d2ece26857aa516f193c8161db0c8e7c779fd8f3464af", "price_changes": [{"asset_id": "42097535137505280315737745177128192451567567237475285083506851409423497113459", "price": "0.08", "size": "5547.43", "side": "BUY", "hash": "1be3907a9d99c8efdd79d66bd5287a2d6e9f4511", "best_bid": "0.4", "best_ask": "0.47"}, {"asset_id": "20794210232738155208360248995422719359166978550921485109532388301377529305580", "price": "0.92", "size": "5547.43", "side": "SELL", "hash": "345f0906cf89085bd1c781a44af666cae59fc02e", "best_bid": "0.53", "best_ask": "0.6"}], "timestamp": "1769384183785", "event_type": "price_change"}}
{"_local_timestamp": "2026-01-25T23:36:30.424213+00:00", "data": {"market": "0x88608442d14bdfa98a3d2ece26857aa516f193c8161db0c8e7c779fd8f3464af", "price_changes": [{"asset_id": "42097535137505280315737745177128192451567567237475285083506851409423497113459", "price": "0.11", "size": "0", "side": "BUY", "hash": "ca2ecd4c94ded3eda1caecc37fc3db6f8d8ce68a", "best_bid": "0.4", "best_ask": "0.47"}, {"asset_id": "20794210232738155208360248995422719359166978550921485109532388301377529305580", "price": "0.89", "size": "0", "side": "SELL", "hash": "ada20cb589424cc4b81f8d75a4febfdc43d1510e", "best_bid": "0.53", "best_ask": "0.6"}], "timestamp": "1769384190350", "event_type": "price_change"}}
{"_local_timestamp": "2026-01-25T23:36:30.475177+00:00", "data": {"market": "0x88608442d14bdfa98a3d2ece26857aa516f193c8161db0c8e7c779fd8f3464af", "price_changes": [{"asset_id": "42097535137505280315737745177128192451567567237475285083506851409423497113459", "price": "0.12", "size": "0", "side": "BUY", "hash": "fefe66b689046d2407d147227b28dfbe050e1f61", "best_bid": "0.4", "best_ask": "0.47"}, {"asset_id": "20794210232738155208360248995422719359166978550921485109532388301377529305580", "price": "0.88", "size": "0", "side": "SELL", "hash": "c4e65bbd628240d28ca0ccc7e75deb925912de23", "best_bid": "0.53", "best_ask": "0.6"}], "timestamp": "1769384190404", "event_type": "price_change"}}
{"_local_timestamp": "2026-01-25T23:36:30.486312+00:00", "data": {"market": "0x88608442d14bdfa98a3d2ece26857aa516f193c8161db0c8e7c779fd8f3464af", "price_changes": [{"asset_id": "20794210232738155208360248995422719359166978550921485109532388301377529305580", "price": "0.22", "size": "0", "side": "BUY", "hash": "7196b3a8a33d7650477079811a9104687621b0ce", "best_bid": "0.53", "best_ask": "0.6"}, {"asset_id": "42097535137505280315737745177128192451567567237475285083506851409423497113459", "price": "0.78", "size": "0", "side": "SELL", "hash": "fc3aeabcfdb46730c8f2c8e9039e65e74e32f0e5", "best_bid": "0.4", "best_ask": "0.47"}], "timestamp": "1769384190404", "event_type": "price_change"}}
{"_local_timestamp": "2026-01-25T23:36:30.530636+00:00", "data": {"market": "0x88608442d14bdfa98a3d2ece26857aa516f193c8161db0c8e7c779fd8f3464af", "price_changes": [{"asset_id": "20794210232738155208360248995422719359166978550921485109532388301377529305580", "price": "0.23", "size": "1997.11", "side": "BUY", "hash": "30d68eb42c1b57b64bca8afab165de310f3dcc36", "best_bid": "0.53", "best_ask": "0.6"}, {"asset_id": "42097535137505280315737745177128192451567567237475285083506851409423497113459", "price": "0.77", "size": "1997.11", "side": "SELL", "hash": "b901681a7e5ad5aab2273aefd2d39bfd24ec90eb", "best_bid": "0.4", "best_ask": "0.47"}], "timestamp": "1769384190461", "event_type": "price_change"}}
{"_local_timestamp": "2026-01-25T23:36:30.531512+00:00", "data": {"market": "0x88608442d14bdfa98a3d2ece26857aa516f193c8161db0c8e7c779fd8f3464af", "price_changes": [{"asset_id": "20794210232738155208360248995422719359166978550921485109532388301377529305580", "price": "0.23", "size": "2887.22", "side": "BUY", "hash": "277cc27f7bfd87e8baecb7071fb869d25d6cf972", "best_bid": "0.53", "best_ask": "0.6"}, {"asset_id": "42097535137505280315737745177128192451567567237475285083506851409423497113459", "price": "0.77", "size": "2887.22", "side": "SELL", "hash": "4536e25cc204363db8459848f93c3323ad1bb582", "best_bid": "0.4", "best_ask": "0.47"}], "timestamp": "1769384190462", "event_type": "price_change"}}
{"_local_timestamp": "2026-01-25T23:36:30.568482+00:00", "data": {"market": "0x88608442d14bdfa98a3d2ece26857aa516f193c8161db0c8e7c779fd8f3464af", "price_changes": [{"asset_id": "20794210232738155208360248995422719359166978550921485109532388301377529305580", "price": "0.23", "size": "3777.33", "side": "BUY", "hash": "f7f5e6d2274cd3e4751826e4b49c6c56f2624801", "best_bid": "0.53", "best_ask": "0.6"}, {"asset_id": "42097535137505280315737745177128192451567567237475285083506851409423497113459", "price": "0.77", "size": "3777.33", "side": "SELL", "hash": "5a1b320007052c87ffe95daed06581157ab1b378", "best_bid": "0.4", "best_ask": "0.47"}], "timestamp": "1769384190495", "event_type": "price_change"}}
{"_local_timestamp": "2026-01-25T23:36:30.569258+00:00", "data": {"market": "0x88608442d14bdfa98a3d2ece26857aa516f193c8161db0c8e7c779fd8f3464af", "price_changes": [{"asset_id": "20794210232738155208360248995422719359166978550921485109532388301377529305580", "price": "0.22", "size": "890.11", "side": "BUY", "hash": "b6023917ac1d84ceccc0789a47b2e49595443838", "best_bid": "0.53", "best_ask": "0.6"}, {"asset_id": "42097535137505280315737745177128192451567567237475285083506851409423497113459", "price": "0.78", "size": "890.11", "side": "SELL", "hash": "91e8010575590a6c83bd838856dbb7c1399f6880", "best_bid": "0.4", "best_ask": "0.47"}], "timestamp": "1769384190496", "event_type": "price_change"}}
{"_local_timestamp": "2026-01-25T23:36:30.569974+00:00", "data": {"market": "0x88608442d14bdfa98a3d2ece26857aa516f193c8161db0c8e7c779fd8f3464af", "price_changes": [{"asset_id": "20794210232738155208360248995422719359166978550921485109532388301377529305580", "price": "0.23", "size": "5047.43", "side": "BUY", "hash": "281f216dc08099b44a7179d5fbfc27faf85cdaec", "best_bid": "0.53", "best_ask": "0.6"}, {"asset_id": "42097535137505280315737745177128192451567567237475285083506851409423497113459", "price": "0.77", "size": "5047.43", "side": "SELL", "hash": "202cbba8d3ecc7af26c4e4632054836d23131ef6", "best_bid": "0.4", "best_ask": "0.47"}], "timestamp": "1769384190497", "event_type": "price_change"}}
{"_local_timestamp": "2026-01-25T23:36:30.654763+00:00", "data": {"market": "0x88608442d14bdfa98a3d2ece26857aa516f193c8161db0c8e7c779fd8f3464af", "price_changes": [{"asset_id": "42097535137505280315737745177128192451567567237475285083506851409423497113459", "price": "0.12", "size": "100", "side": "BUY", "hash": "fe400cd39ad5f90c53073cac7ac5da29b4410a7c", "best_bid": "0.4", "best_ask": "0.47"}, {"asset_id": "20794210232738155208360248995422719359166978550921485109532388301377529305580", "price": "0.88", "size": "100", "side": "SELL", "hash": "33f51a0c90ddab5fdbab0d2d0fda780e7685ad57", "best_bid": "0.53", "best_ask": "0.6"}], "timestamp": "1769384190580", "event_type": "price_change"}}
{"_local_timestamp": "2026-01-25T23:36:30.796334+00:00", "data": {"market": "0x88608442d14bdfa98a3d2ece26857aa516f193c8161db0c8e7c779fd8f3464af", "price_changes": [{"asset_id": "20794210232738155208360248995422719359166978550921485109532388301377529305580", "price": "0.24", "size": "5999.11", "side": "BUY", "hash": "0439957efad52798c55f3af5a8a4699a51f43db7", "best_bid": "0.53", "best_ask": "0.6"}, {"asset_id": "42097535137505280315737745177128192451567567237475285083506851409423497113459", "price": "0.76", "size": "5999.11", "side": "SELL", "hash": "089a5e345196fdaa741a3f5866b062547026f0c8", "best_bid": "0.4", "best_ask": "0.47"}], "timestamp": "1769384190724", "event_type": "price_change"}}
{"_local_timestamp": "2026-01-25T23:36:31.101401+00:00", "data": {"market": "0x88608442d14bdfa98a3d2ece26857aa516f193c8161db0c8e7c779fd8f3464af", "price_changes": [{"asset_id": "20794210232738155208360248995422719359166978550921485109532388301377529305580", "price": "0.12", "size": "100", "side": "BUY", "hash": "601b4bc6ce31e6f2ea0e2adea14129bc693e7347", "best_bid": "0.53", "best_ask": "0.6"}, {"asset_id": "42097535137505280315737745177128192451567567237475285083506851409423497113459", "price": "0.88", "size": "100", "side": "SELL", "hash": "13a185a21a7196a3c908d04862c9982f1365c145", "best_bid": "0.4", "best_ask": "0.47"}], "timestamp": "1769384191032", "event_type": "price_change"}}
{"_local_timestamp": "2026-01-25T23:36:31.202171+00:00", "data": {"market": "0x88608442d14bdfa98a3d2ece26857aa516f193c8161db0c8e7c779fd8f3464af", "price_changes": [{"asset_id": "20794210232738155208360248995422719359166978550921485109532388301377529305580", "price": "0.12", "size": "0", "side": "BUY", "hash": "9b819f61586368b14cd1c78cef2b1ffe3930f3d7", "best_bid": "0.53", "best_ask": "0.6"}, {"asset_id": "42097535137505280315737745177128192451567567237475285083506851409423497113459", "price": "0.88", "size": "0", "side": "SELL", "hash": "afae466dbb29ed17c794c27645c40d7c873aa948", "best_bid": "0.4", "best_ask": "0.47"}], "timestamp": "1769384191110", "event_type": "price_change"}}
{"_local_timestamp": "2026-01-25T23:36:31.393836+00:00", "data": {"market": "0x88608442d14bdfa98a3d2ece26857aa516f193c8161db0c8e7c779fd8f3464af", "price_changes": [{"asset_id": "20794210232738155208360248995422719359166978550921485109532388301377529305580", "price": "0.08", "size": "4757.32", "side": "BUY", "hash": "63c9209377b6c2267669e409286193c825a606b7", "best_bid": "0.53", "best_ask": "0.6"}, {"asset_id": "42097535137505280315737745177128192451567567237475285083506851409423497113459", "price": "0.92", "size": "4757.32", "side": "SELL", "hash": "2c17b5c2a45e36a55b041d7ba680229d52c23dfb", "best_bid": "0.4", "best_ask": "0.47"}], "timestamp": "1769384191320", "event_type": "price_change"}}
{"_local_timestamp": "2026-01-25T23:36:31.395423+00:00", "data": {"market": "0x88608442d14bdfa98a3d2ece26857aa516f193c8161db0c8e7c779fd8f3464af", "price_changes": [{"asset_id": "42097535137505280315737745177128192451567567237475285083506851409423497113459", "price": "0.08", "size": "5647.43", "side": "BUY", "hash": "4dc08d89817b23c8e1853e5443486e7ef3210529", "best_bid": "0.4", "best_ask": "0.47"}, {"asset_id": "20794210232738155208360248995422719359166978550921485109532388301377529305580", "price": "0.92", "size": "5647.43", "side": "SELL", "hash": "56345005c6c6b4c61acc00e7daa1d9ffbee79d42", "best_bid": "0.53", "best_ask": "0.6"}], "timestamp": "1769384191321", "event_type": "price_change"}}
{"_local_timestamp": "2026-01-25T23:36:31.960499+00:00", "data": {"market": "0x88608442d14bdfa98a3d2ece26857aa516f193c8161db0c8e7c779fd8f3464af", "price_changes": [{"asset_id": "20794210232738155208360248995422719359166978550921485109532388301377529305580", "price": "0.08", "size": "4857.32", "side": "BUY", "hash": "4e798693fbee2639dc46142eb5742ae4a2cb3cab", "best_bid": "0.53", "best_ask": "0.6"}, {"asset_id": "42097535137505280315737745177128192451567567237475285083506851409423497113459", "price": "0.92", "size": "4857.32", "side": "SELL", "hash": "2eb296b34222e93f58e94414344e036cc40b0cb9", "best_bid": "0.4", "best_ask": "0.47"}], "timestamp": "1769384191890", "event_type": "price_change"}}
{"_local_timestamp": "2026-01-25T23:36:31.961359+00:00", "data": {"market": "0x88608442d14bdfa98a3d2ece26857aa516f193c8161db0c8e7c779fd8f3464af", "price_changes": [{"asset_id": "42097535137505280315737745177128192451567567237475285083506851409423497113459", "price": "0.08", "size": "5747.43", "side": "BUY", "hash": "2befd818d89a04cfbb698a8da6552abcc3080d14", "best_bid": "0.4", "best_ask": "0.47"}, {"asset_id": "20794210232738155208360248995422719359166978550921485109532388301377529305580", "price": "0.92", "size": "5747.43", "side": "SELL", "hash": "827afd171314344a821ddf7ea218edc7381082c8", "best_bid": "0.53", "best_ask": "0.6"}], "timestamp": "1769384191891", "event_type": "price_change"}}
{"_local_timestamp": "2026-01-25T23:36:39.152050+00:00", "data": {"market": "0x88608442d14bdfa98a3d2ece26857aa516f193c8161db0c8e7c779fd8f3464af", "price_changes": [{"asset_id": "20794210232738155208360248995422719359166978550921485109532388301377529305580", "price": "0.11", "size": "0", "side": "BUY", "hash": "2e75ac3d78538574e6003f3df57e78083d74f218", "best_bid": "0.53", "best_ask": "0.6"}, {"asset_id": "42097535137505280315737745177128192451567567237475285083506851409423497113459", "price": "0.89", "size": "0", "side": "SELL", "hash": "49b0eadab5dc251c89f46d3832e40cbaa7818513", "best_bid": "0.4", "best_ask": "0.47"}], "timestamp": "1769384199084", "event_type": "price_change"}}
{"_local_timestamp": "2026-01-25T23:36:39.217867+00:00", "data": {"market": "0x88608442d14bdfa98a3d2ece26857aa516f193c8161db0c8e7c779fd8f3464af", "price_changes": [{"asset_id": "42097535137505280315737745177128192451567567237475285083506851409423497113459", "price": "0.08", "size": "1590.11", "side": "BUY", "hash": "8bc16f537c2ffd95aa04d8c9866ea586e1bf146e", "best_bid": "0.4", "best_ask": "0.47"}, {"asset_id": "20794210232738155208360248995422719359166978550921485109532388301377529305580", "price": "0.92", "size": "1590.11", "side": "SELL", "hash": "cd101fa0c8c7290e096397a0f0d0b4ceb2daa0cd", "best_bid": "0.53", "best_ask": "0.6"}], "timestamp": "1769384199151", "event_type": "price_change"}}
{"_local_timestamp": "2026-01-25T23:36:39.218682+00:00", "data": {"market": "0x88608442d14bdfa98a3d2ece26857aa516f193c8161db0c8e7c779fd8f3464af", "price_changes": [{"asset_id": "20794210232738155208360248995422719359166978550921485109532388301377529305580", "price": "0.23", "size": "0", "side": "BUY", "hash": "eb82944d4279056998fdbb3f0319f83da765f922", "best_bid": "0.53", "best_ask": "0.6"}, {"asset_id": "42097535137505280315737745177128192451567567237475285083506851409423497113459", "price": "0.77", "size": "0", "side": "SELL", "hash": "451fbddc7ff47300bd46827e0d006241acdf3bc8", "best_bid": "0.4", "best_ask": "0.47"}], "timestamp": "1769384199152", "event_type": "price_change"}}
{"_local_timestamp": "2026-01-25T23:36:39.219423+00:00", "data": {"market": "0x88608442d14bdfa98a3d2ece26857aa516f193c8161db0c8e7c779fd8f3464af", "price_changes": [{"asset_id": "20794210232738155208360248995422719359166978550921485109532388301377529305580", "price": "0.22", "size": "0", "side": "BUY", "hash": "eb82944d4279056998fdbb3f0319f83da765f922", "best_bid": "0.53", "best_ask": "0.6"}, {"asset_id": "42097535137505280315737745177128192451567567237475285083506851409423497113459", "price": "0.78", "size": "0", "side": "SELL", "hash": "451fbddc7ff47300bd46827e0d006241acdf3bc8", "best_bid": "0.4", "best_ask": "0.47"}], "timestamp": "1769384199152", "event_type": "price_change"}}
{"_local_timestamp": "2026-01-25T23:36:39.229005+00:00", "data": {"market": "0x88608442d14bdfa98a3d2ece26857aa516f193c8161db0c8e7c779fd8f3464af", "price_changes": [{"asset_id": "20794210232738155208360248995422719359166978550921485109532388301377529305580", "price": "0.08", "size": "700", "side": "BUY", "hash": "eb82944d4279056998fdbb3f0319f83da765f922", "best_bid": "0.53", "best_ask": "0.6"}, {"asset_id": "42097535137505280315737745177128192451567567237475285083506851409423497113459", "price": "0.92", "size": "700", "side": "SELL", "hash": "451fbddc7ff47300bd46827e0d006241acdf3bc8", "best_bid": "0.4", "best_ask": "0.47"}], "timestamp": "1769384199152", "event_type": "price_change"}}
{"_local_timestamp": "2026-01-25T23:36:39.229960+00:00", "data": {"market": "0x88608442d14bdfa98a3d2ece26857aa516f193c8161db0c8e7c779fd8f3464af", "price_changes": [{"asset_id": "20794210232738155208360248995422719359166978550921485109532388301377529305580", "price": "0.24", "size": "0", "side": "BUY", "hash": "eb82944d4279056998fdbb3f0319f83da765f922", "best_bid": "0.53", "best_ask": "0.6"}, {"asset_id": "42097535137505280315737745177128192451567567237475285083506851409423497113459", "price": "0.76", "size": "0", "side": "SELL", "hash": "451fbddc7ff47300bd46827e0d006241acdf3bc8", "best_bid": "0.4", "best_ask": "0.47"}], "timestamp": "1769384199152", "event_type": "price_change"}}
{"_local_timestamp": "2026-01-25T23:36:39.255538+00:00", "data": {"market": "0x88608442d14bdfa98a3d2ece26857aa516f193c8161db0c8e7c779fd8f3464af", "price_changes": [{"asset_id": "20794210232738155208360248995422719359166978550921485109532388301377529305580", "price": "0.25", "size": "890.11", "side": "BUY", "hash": "854cb5389571c42a45f06f3711fe6237585e7215", "best_bid": "0.53", "best_ask": "0.6"}, {"asset_id": "42097535137505280315737745177128192451567567237475285083506851409423497113459", "price": "0.75", "size": "890.11", "side": "SELL", "hash": "4db10cf5d07a24783b2e3be118965b5410f452de", "best_bid": "0.4", "best_ask": "0.47"}], "timestamp": "1769384199187", "event_type": "price_change"}}
{"_local_timestamp": "2026-01-25T23:36:39.256430+00:00", "data": {"market": "0x88608442d14bdfa98a3d2ece26857aa516f193c8161db0c8e7c779fd8f3464af", "price_changes": [{"asset_id": "20794210232738155208360248995422719359166978550921485109532388301377529305580", "price": "0.25", "size": "6889.22", "side": "BUY", "hash": "27a256173572f50f66390f19bf1284b165d6f414", "best_bid": "0.53", "best_ask": "0.6"}, {"asset_id": "42097535137505280315737745177128192451567567237475285083506851409423497113459", "price": "0.75", "size": "6889.22", "side": "SELL", "hash": "84c5ca0f71e27eeeb519ac269e1d0f7c749ab10b", "best_bid": "0.4", "best_ask": "0.47"}], "timestamp": "1769384199187", "event_type": "price_change"}}
{"_local_timestamp": "2026-01-25T23:36:39.257224+00:00", "data": {"market": "0x88608442d14bdfa98a3d2ece26857aa516f193c8161db0c8e7c779fd8f3464af", "price_changes": [{"asset_id": "20794210232738155208360248995422719359166978550921485109532388301377529305580", "price": "0.24", "size": "890.11", "side": "BUY", "hash": "d7af26a11dd05ee23115373016d5a4d86ab259a4", "best_bid": "0.53", "best_ask": "0.6"}, {"asset_id": "42097535137505280315737745177128192451567567237475285083506851409423497113459", "price": "0.76", "size": "890.11", "side": "SELL", "hash": "314ae5f2367a8476589e044890fc5ff6cafc7555", "best_bid": "0.4", "best_ask": "0.47"}], "timestamp": "1769384199188", "event_type": "price_change"}}
{"_local_timestamp": "2026-01-25T23:36:39.270047+00:00", "data": {"market": "0x88608442d14bdfa98a3d2ece26857aa516f193c8161db0c8e7c779fd8f3464af", "price_changes": [{"asset_id": "20794210232738155208360248995422719359166978550921485109532388301377529305580", "price": "0.09", "size": "1997.11", "side": "BUY", "hash": "bb3ed616a7208e132240a017fec92065a000fcba", "best_bid": "0.53", "best_ask": "0.6"}, {"asset_id": "42097535137505280315737745177128192451567567237475285083506851409423497113459", "price": "0.91", "size": "1997.11", "side": "SELL", "hash": "29d503c14f8b7577e845da3f715f6c00cbfafb47", "best_bid": "0.4", "best_ask": "0.47"}], "timestamp": "1769384199189", "event_type": "price_change"}}
{"_local_timestamp": "2026-01-25T23:36:39.286773+00:00", "data": {"market": "0x88608442d14bdfa98a3d2ece26857aa516f193c8161db0c8e7c779fd8f3464af", "price_changes": [{"asset_id": "20794210232738155208360248995422719359166978550921485109532388301377529305580", "price": "0.09", "size": "3267.21", "side": "BUY", "hash": "e2457c2936987f0b4226a6bb69d7e5b15544ca6a", "best_bid": "0.53", "best_ask": "0.6"}, {"asset_id": "42097535137505280315737745177128192451567567237475285083506851409423497113459", "price": "0.91", "size": "3267.21", "side": "SELL", "hash": "b94f3c6bf61e9b721bc61115192ed61a78a4794a", "best_bid": "0.4", "best_ask": "0.47"}], "timestamp": "1769384199190", "event_type": "price_change"}}
{"_local_timestamp": "2026-01-25T23:36:39.287663+00:00", "data": {"market": "0x88608442d14bdfa98a3d2ece26857aa516f193c8161db0c8e7c779fd8f3464af", "price_changes": [{"asset_id": "42097535137505280315737745177128192451567567237475285083506851409423497113459", "price": "0.09", "size": "2887.22", "side": "BUY", "hash": "0f879c6b58db0eddc7b8e4819db355765ad50976", "best_bid": "0.4", "best_ask": "0.47"}, {"asset_id": "20794210232738155208360248995422719359166978550921485109532388301377529305580", "price": "0.91", "size": "2887.22", "side": "SELL", "hash": "f4011aa7599eb26362659d7793c295c8cb41e97a", "best_bid": "0.53", "best_ask": "0.6"}], "timestamp": "1769384199191", "event_type": "price_change"}}
{"_local_timestamp": "2026-01-25T23:36:39.288428+00:00", "data": {"market": "0x88608442d14bdfa98a3d2ece26857aa516f193c8161db0c8e7c779fd8f3464af", "price_changes": [{"asset_id": "42097535137505280315737745177128192451567567237475285083506851409423497113459", "price": "0.09", "size": "4157.32", "side": "BUY", "hash": "034b4b896c2726534e2ece212b91d10c59ce8142", "best_bid": "0.4", "best_ask": "0.47"}, {"asset_id": "20794210232738155208360248995422719359166978550921485109532388301377529305580", "price": "0.91", "size": "4157.32", "side": "SELL", "hash": "bee9ed2e65f425aeeb7a28dbd97e45d613802a61", "best_bid": "0.53", "best_ask": "0.6"}], "timestamp": "1769384199192", "event_type": "price_change"}}
{"_local_timestamp": "2026-01-25T23:36:39.289135+00:00", "data": {"market": "0x88608442d14bdfa98a3d2ece26857aa516f193c8161db0c8e7c779fd8f3464af", "price_changes": [{"asset_id": "42097535137505280315737745177128192451567567237475285083506851409423497113459", "price": "0.09", "size": "5047.43", "side": "BUY", "hash": "09a0893ad4088d5324974e9e46a27674fd54a76a", "best_bid": "0.4", "best_ask": "0.47"}, {"asset_id": "20794210232738155208360248995422719359166978550921485109532388301377529305580", "price": "0.91", "size": "5047.43", "side": "SELL", "hash": "9a44d9de8a34309c352619023d998cfe96be9fab", "best_bid": "0.53", "best_ask": "0.6"}], "timestamp": "1769384199192", "event_type": "price_change"}}
{"_local_timestamp": "2026-01-25T23:36:39.349437+00:00", "data": {"market": "0x88608442d14bdfa98a3d2ece26857aa516f193c8161db0c8e7c779fd8f3464af", "price_changes": [{"asset_id": "20794210232738155208360248995422719359166978550921485109532388301377529305580", "price": "0.09", "size": "4157.32", "side": "BUY", "hash": "94fcff0f3ab52aea5c8d1ffc6e3b3d3b06b8d3af", "best_bid": "0.53", "best_ask": "0.6"}, {"asset_id": "42097535137505280315737745177128192451567567237475285083506851409423497113459", "price": "0.91", "size": "4157.32", "side": "SELL", "hash": "6a0edb671e6474d63c5b79193aa9c24767bd5ac0", "best_bid": "0.4", "best_ask": "0.47"}], "timestamp": "1769384199193", "event_type": "price_change"}}
{"_local_timestamp": "2026-01-25T23:36:39.439909+00:00", "data": {"market": "0x88608442d14bdfa98a3d2ece26857aa516f193c8161db0c8e7c779fd8f3464af", "price_changes": [{"asset_id": "20794210232738155208360248995422719359166978550921485109532388301377529305580", "price": "0.09", "size": "4164.33", "side": "BUY", "hash": "3fff2d174c88f654cdaa9cc3bddf80823852272d", "best_bid": "0.53", "best_ask": "0.6"}, {"asset_id": "42097535137505280315737745177128192451567567237475285083506851409423497113459", "price": "0.91", "size": "4164.33", "side": "SELL", "hash": "3c3953754dfc24d88c084964d620f6510d363016", "best_bid": "0.4", "best_ask": "0.47"}], "timestamp": "1769384199362", "event_type": "price_change"}}
{"_local_timestamp": "2026-01-25T23:36:41.749996+00:00", "data": {"market": "0x88608442d14bdfa98a3d2ece26857aa516f193c8161db0c8e7c779fd8f3464af", "price_changes": [{"asset_id": "42097535137505280315737745177128192451567567237475285083506851409423497113459", "price": "0.08", "size": "1190.11", "side": "BUY", "hash": "c1c1d958da519a13753be046f434142d7b23aea3", "best_bid": "0.4", "best_ask": "0.47"}, {"asset_id": "20794210232738155208360248995422719359166978550921485109532388301377529305580", "price": "0.92", "size": "1190.11", "side": "SELL", "hash": "c29e84bbb5d2b666d3c8a9303c18887d28a41388", "best_bid": "0.53", "best_ask": "0.6"}], "timestamp": "1769384201632", "event_type": "price_change"}}
{"_local_timestamp": "2026-01-25T23:36:43.072919+00:00", "data": {"market": "0x88608442d14bdfa98a3d2ece26857aa516f193c8161db0c8e7c779fd8f3464af", "price_changes": [{"asset_id": "42097535137505280315737745177128192451567567237475285083506851409423497113459", "price": "0.12", "size": "0", "side": "BUY", "hash": "77afcddc869663e2ada0887e1f89a127d59caf56", "best_bid": "0.4", "best_ask": "0.47"}, {"asset_id": "20794210232738155208360248995422719359166978550921485109532388301377529305580", "price": "0.88", "size": "0", "side": "SELL", "hash": "fff6bbab20d9dcacedc20f4d2d87ff8112d50dad", "best_bid": "0.53", "best_ask": "0.6"}], "timestamp": "1769384202902", "event_type": "price_change"}}
{"_local_timestamp": "2026-01-25T23:36:43.145255+00:00", "data": {"market": "0x88608442d14bdfa98a3d2ece26857aa516f193c8161db0c8e7c779fd8f3464af", "price_changes": [{"asset_id": "42097535137505280315737745177128192451567567237475285083506851409423497113459", "price": "0.08", "size": "2080.22", "side": "BUY", "hash": "9f0b4a4920ee9e81cff8cddacead434e9d9d9cfa", "best_bid": "0.4", "best_ask": "0.47"}, {"asset_id": "20794210232738155208360248995422719359166978550921485109532388301377529305580", "price": "0.92", "size": "2080.22", "side": "SELL", "hash": "f25261e608ac946c5eb6457e77963a2cab37c060", "best_bid": "0.53", "best_ask": "0.6"}], "timestamp": "1769384202978", "event_type": "price_change"}}
{"_local_timestamp": "2026-01-25T23:36:43.154530+00:00", "data": {"market": "0x88608442d14bdfa98a3d2ece26857aa516f193c8161db0c8e7c779fd8f3464af", "price_changes": [{"asset_id": "42097535137505280315737745177128192451567567237475285083506851409423497113459", "price": "0.08", "size": "3350.32", "side": "BUY", "hash": "c6980f6da17dc3111bf731258e284d32302fc0cf", "best_bid": "0.4", "best_ask": "0.47"}, {"asset_id": "20794210232738155208360248995422719359166978550921485109532388301377529305580", "price": "0.92", "size": "3350.32", "side": "SELL", "hash": "86a57d558c4e9f14c736eef0af0bdf5f9de28604", "best_bid": "0.53", "best_ask": "0.6"}], "timestamp": "1769384202979", "event_type": "price_change"}}
{"_local_timestamp": "2026-01-25T23:36:43.160950+00:00", "data": {"market": "0x88608442d14bdfa98a3d2ece26857aa516f193c8161db0c8e7c779fd8f3464af", "price_changes": [{"asset_id": "42097535137505280315737745177128192451567567237475285083506851409423497113459", "price": "0.08", "size": "5347.43", "side": "BUY", "hash": "b54da406e5c294e5769ce13fa55ee01889b91500", "best_bid": "0.4", "best_ask": "0.47"}, {"asset_id": "20794210232738155208360248995422719359166978550921485109532388301377529305580", "price": "0.92", "size": "5347.43", "side": "SELL", "hash": "18d5b052cc93f501cee3d492e9c770f0de3cb709", "best_bid": "0.53", "best_ask": "0.6"}], "timestamp": "1769384202979", "event_type": "price_change"}}
{"_local_timestamp": "2026-01-25T23:36:43.163238+00:00", "data": {"market": "0x88608442d14bdfa98a3d2ece26857aa516f193c8161db0c8e7c779fd8f3464af", "price_changes": [{"asset_id": "20794210232738155208360248995422719359166978550921485109532388301377529305580", "price": "0.25", "size": "0", "side": "BUY", "hash": "60447d11c3375aedb4d085292e41e607b9301112", "best_bid": "0.53", "best_ask": "0.6"}, {"asset_id": "42097535137505280315737745177128192451567567237475285083506851409423497113459", "price": "0.75", "size": "0", "side": "SELL", "hash": "458c0ecd68008e1d7c494ccdf26cab962c58f5b1", "best_bid": "0.4", "best_ask": "0.47"}], "timestamp": "1769384202980", "event_type": "price_change"}}
{"_local_timestamp": "2026-01-25T23:36:43.164137+00:00", "data": {"market": "0x88608442d14bdfa98a3d2ece26857aa516f193c8161db0c8e7c779fd8f3464af", "price_changes": [{"asset_id": "20794210232738155208360248995422719359166978550921485109532388301377529305580", "price": "0.24", "size": "0", "side": "BUY", "hash": "60447d11c3375aedb4d085292e41e607b9301112", "best_bid": "0.53", "best_ask": "0.6"}, {"asset_id": "42097535137505280315737745177128192451567567237475285083506851409423497113459", "price": "0.76", "size": "0", "side": "SELL", "hash": "458c0ecd68008e1d7c494ccdf26cab962c58f5b1", "best_bid": "0.4", "best_ask": "0.47"}], "timestamp": "1769384202980", "event_type": "price_change"}}
{"_local_timestamp": "2026-01-25T23:36:43.313413+00:00", "data": {"market": "0x88608442d14bdfa98a3d2ece26857aa516f193c8161db0c8e7c779fd8f3464af", "price_changes": [{"asset_id": "20794210232738155208360248995422719359166978550921485109532388301377529305580", "price": "0.08", "size": "800", "side": "BUY", "hash": "c0e774ba7ac5d0714a1aab85c542640b3bd7505d", "best_bid": "0.53", "best_ask": "0.6"}, {"asset_id": "42097535137505280315737745177128192451567567237475285083506851409423497113459", "price": "0.92", "size": "800", "side": "SELL", "hash": "e640617a080e6fff62896cbc5c24e3c7de7b4f1c", "best_bid": "0.4", "best_ask": "0.47"}], "timestamp": "1769384203140", "event_type": "price_change"}}
{"_local_timestamp": "2026-01-25T23:36:43.314359+00:00", "data": {"market": "0x88608442d14bdfa98a3d2ece26857aa516f193c8161db0c8e7c779fd8f3464af", "price_changes": [{"asset_id": "42097535137505280315737745177128192451567567237475285083506851409423497113459", "price": "0.09", "size": "5147.43", "side": "BUY", "hash": "ed6384744a1937245c77d625649d6424e70297d8", "best_bid": "0.4", "best_ask": "0.47"}, {"asset_id": "20794210232738155208360248995422719359166978550921485109532388301377529305580", "price": "0.91", "size": "5147.43", "side": "SELL", "hash": "de69ebc8dad66f6a64ea04186eac4f1784f061ca", "best_bid": "0.53", "best_ask": "0.6"}], "timestamp": "1769384203141", "event_type": "price_change"}}
{"_local_timestamp": "2026-01-25T23:36:43.318888+00:00", "data": {"market": "0x88608442d14bdfa98a3d2ece26857aa516f193c8161db0c8e7c779fd8f3464af", "price_changes": [{"asset_id": "20794210232738155208360248995422719359166978550921485109532388301377529305580", "price": "0.2", "size": "1090.11", "side": "BUY", "hash": "8e2e1185d4c054c75426e4c52c73d696b522645e", "best_bid": "0.53", "best_ask": "0.6"}, {"asset_id": "42097535137505280315737745177128192451567567237475285083506851409423497113459", "price": "0.8", "size": "1090.11", "side": "SELL", "hash": "1f4d843dd9c29d9ee4d0be66ec59ed66f3c83706", "best_bid": "0.4", "best_ask": "0.47"}], "timestamp": "1769384203148", "event_type": "price_change"}}
{"_local_timestamp": "2026-01-25T23:36:43.373852+00:00", "data": {"market": "0x88608442d14bdfa98a3d2ece26857aa516f193c8161db0c8e7c779fd8f3464af", "price_changes": [{"asset_id": "20794210232738155208360248995422719359166978550921485109532388301377529305580", "price": "0.25", "size": "890.11", "side": "BUY", "hash": "051efc80ac21d125fda668a9edb60fe100f3c80b", "best_bid": "0.53", "best_ask": "0.6"}, {"asset_id": "42097535137505280315737745177128192451567567237475285083506851409423497113459", "price": "0.75", "size": "890.11", "side": "SELL", "hash": "410c6de759ca9671339d9acd9fb16489bfa7bec4", "best_bid": "0.4", "best_ask": "0.47"}], "timestamp": "1769384203208", "event_type": "price_change"}}
{"_local_timestamp": "2026-01-25T23:36:43.374732+00:00", "data": {"market": "0x88608442d14bdfa98a3d2ece26857aa516f193c8161db0c8e7c779fd8f3464af", "price_changes": [{"asset_id": "20794210232738155208360248995422719359166978550921485109532388301377529305580", "price": "0.26", "size": "5999.11", "side": "BUY", "hash": "c008f45b0ce6f0d55485bc393f288df4b3aa9a23", "best_bid": "0.53", "best_ask": "0.6"}, {"asset_id": "42097535137505280315737745177128192451567567237475285083506851409423497113459", "price": "0.74", "size": "5999.11", "side": "SELL", "hash": "598c8122ba8d7ee9cb456e5ef7f14282c0d15ed0", "best_bid": "0.4", "best_ask": "0.47"}], "timestamp": "1769384203209", "event_type": "price_change"}}
{"_local_timestamp": "2026-01-25T23:36:43.375562+00:00", "data": {"market": "0x88608442d14bdfa98a3d2ece26857aa516f193c8161db0c8e7c779fd8f3464af", "price_changes": [{"asset_id": "20794210232738155208360248995422719359166978550921485109532388301377529305580", "price": "0.26", "size": "6889.22", "side": "BUY", "hash": "e2a5b44ab28eb93f9e05687a76dbd5a6ddd47405", "best_bid": "0.53", "best_ask": "0.6"}, {"asset_id": "42097535137505280315737745177128192451567567237475285083506851409423497113459", "price": "0.74", "size": "6889.22", "side": "SELL", "hash": "fce321193ebbbe163c87c3dbac17b77c33bad098", "best_bid": "0.4", "best_ask": "0.47"}], "timestamp": "1769384203210", "event_type": "price_change"}}
{"_local_timestamp": "2026-01-25T23:36:43.589973+00:00", "data": {"market": "0x88608442d14bdfa98a3d2ece26857aa516f193c8161db0c8e7c779fd8f3464af", "price_changes": [{"asset_id": "20794210232738155208360248995422719359166978550921485109532388301377529305580", "price": "0.22", "size": "50", "side": "BUY", "hash": "580a0dca59c01aa2452aa6e2ef96f531597d7c84", "best_bid": "0.53", "best_ask": "0.6"}, {"asset_id": "42097535137505280315737745177128192451567567237475285083506851409423497113459", "price": "0.78", "size": "50", "side": "SELL", "hash": "e4fd06279d52fba6245bd5bc0436276e45a1cc71", "best_bid": "0.4", "best_ask": "0.47"}], "timestamp": "1769384203426", "event_type": "price_change"}}
{"_local_timestamp": "2026-01-25T23:36:45.221936+00:00", "data": {"market": "0x98612f171f4dc6a0e346710a7729ea695ccc2e5f49437995894dfd0809884f0c", "price_changes": [{"asset_id": "47125239482019083915651528778718935257305702079962957861743905530721500306751", "price": "0.03", "size": "11046.54", "side": "BUY", "hash": "82ff2720ab7280d2a3c956235090ecb4e1c6fe73", "best_bid": "0.42", "best_ask": "0.49"}, {"asset_id": "48560990866788733674131421352321870328649148949521354561724191929176618618723", "price": "0.97", "size": "11046.54", "side": "SELL", "hash": "e3357d121c988493ca60a5c95573fc789bd86855", "best_bid": "0.51", "best_ask": "0.58"}], "timestamp": "1769384205056", "event_type": "price_change"}}
{"_local_timestamp": "2026-01-25T23:36:45.256855+00:00", "data": {"market": "0x98612f171f4dc6a0e346710a7729ea695ccc2e5f49437995894dfd0809884f0c", "price_changes": [{"asset_id": "48560990866788733674131421352321870328649148949521354561724191929176618618723", "price": "0.03", "size": "0", "side": "BUY", "hash": "a3e8c84248dac79bf2ea5460fb2d71a0e1a45837", "best_bid": "0.51", "best_ask": "0.58"}, {"asset_id": "47125239482019083915651528778718935257305702079962957861743905530721500306751", "price": "0.97", "size": "0", "side": "SELL", "hash": "e3a9c6225938201bd4de9d4a9a15fe1b278c0f99", "best_bid": "0.42", "best_ask": "0.49"}], "timestamp": "1769384205100", "event_type": "price_change"}}
{"_local_timestamp": "2026-01-25T23:36:45.257879+00:00", "data": {"market": "0x98612f171f4dc6a0e346710a7729ea695ccc2e5f49437995894dfd0809884f0c", "price_changes": [{"asset_id": "47125239482019083915651528778718935257305702079962957861743905530721500306751", "price": "0.03", "size": "0", "side": "BUY", "hash": "6127a9ba44718d2ab6d0f2db01a84713bc644e81", "best_bid": "0.42", "best_ask": "0.49"}, {"asset_id": "48560990866788733674131421352321870328649148949521354561724191929176618618723", "price": "0.97", "size": "0", "side": "SELL", "hash": "198de2c5b1c4b2912c004868646d024b18fa334e", "best_bid": "0.51", "best_ask": "0.58"}], "timestamp": "1769384205100", "event_type": "price_change"}}
{"_local_timestamp": "2026-01-25T23:36:45.405521+00:00", "data": {"market": "0x98612f171f4dc6a0e346710a7729ea695ccc2e5f49437995894dfd0809884f0c", "price_changes": [{"asset_id": "47125239482019083915651528778718935257305702079962957861743905530721500306751", "price": "0.04", "size": "21.01", "side": "BUY", "hash": "5fe2cfd2e2d6f325989e994643775f4a945c79f3", "best_bid": "0.42", "best_ask": "0.49"}, {"asset_id": "48560990866788733674131421352321870328649148949521354561724191929176618618723", "price": "0.96", "size": "21.01", "side": "SELL", "hash": "3ea931c71936d4bb2d11de7e2145a521b479e92f", "best_bid": "0.51", "best_ask": "0.58"}], "timestamp": "1769384205247", "event_type": "price_change"}}
{"_local_timestamp": "2026-01-25T23:36:45.406490+00:00", "data": {"market": "0x98612f171f4dc6a0e346710a7729ea695ccc2e5f49437995894dfd0809884f0c", "price_changes": [{"asset_id": "47125239482019083915651528778718935257305702079962957861743905530721500306751", "price": "0.02", "size": "5052.54", "side": "BUY", "hash": "1e1b0beb77a66f86ad66abc396822a341e76549f", "best_bid": "0.42", "best_ask": "0.49"}, {"asset_id": "48560990866788733674131421352321870328649148949521354561724191929176618618723", "price": "0.98", "size": "5052.54", "side": "SELL", "hash": "6c695d184e014c01cb71e7ec5be42b7b366cc9b1", "best_bid": "0.51", "best_ask": "0.58"}], "timestamp": "1769384205248", "event_type": "price_change"}}
{"_local_timestamp": "2026-01-25T23:36:45.653053+00:00", "data": {"market": "0xb483376a4a11938da0ae705f901db99f563a73f84df0d3dcb2c1bf7052ca279b", "price_changes": [{"asset_id": "23776435377389573739555717891589267364161331448909103730752015156572276458827", "price": "0.03", "size": "11046.54", "side": "BUY", "hash": "3d8acc80a8337b1bfc1c137ba179a672917de4e3", "best_bid": "0.51", "best_ask": "0.58"}, {"asset_id": "38278925131304241066712865633907202764870863859804168264871289385839720357843", "price": "0.97", "size": "11046.54", "side": "SELL", "hash": "062e29156aa87a73f459e637a1ccd6d90c5ad8a4", "best_bid": "0.42", "best_ask": "0.49"}], "timestamp": "1769384205509", "event_type": "price_change"}}
{"_local_timestamp": "2026-01-25T23:36:45.654032+00:00", "data": {"market": "0x98612f171f4dc6a0e346710a7729ea695ccc2e5f49437995894dfd0809884f0c", "price_changes": [{"asset_id": "48560990866788733674131421352321870328649148949521354561724191929176618618723", "price": "0.02", "size": "5047.43", "side": "BUY", "hash": "d46d186516e6833425bfaaf7f14db153c7d6311c", "best_bid": "0.51", "best_ask": "0.58"}, {"asset_id": "47125239482019083915651528778718935257305702079962957861743905530721500306751", "price": "0.98", "size": "5047.43", "side": "SELL", "hash": "3171e0bbcede7f5df193c05e66713f7cb553cee9", "best_bid": "0.42", "best_ask": "0.49"}], "timestamp": "1769384205509", "event_type": "price_change"}}
{"_local_timestamp": "2026-01-25T23:36:45.654862+00:00", "data": {"market": "0x98612f171f4dc6a0e346710a7729ea695ccc2e5f49437995894dfd0809884f0c", "price_changes": [{"asset_id": "48560990866788733674131421352321870328649148949521354561724191929176618618723", "price": "0.05", "size": "0", "side": "BUY", "hash": "d46d186516e6833425bfaaf7f14db153c7d6311c", "best_bid": "0.51", "best_ask": "0.58"}, {"asset_id": "47125239482019083915651528778718935257305702079962957861743905530721500306751", "price": "0.95", "size": "0", "side": "SELL", "hash": "3171e0bbcede7f5df193c05e66713f7cb553cee9", "best_bid": "0.42", "best_ask": "0.49"}], "timestamp": "1769384205509", "event_type": "price_change"}}
{"_local_timestamp": "2026-01-25T23:36:45.730710+00:00", "data": {"market": "0xb483376a4a11938da0ae705f901db99f563a73f84df0d3dcb2c1bf7052ca279b", "price_changes": [{"asset_id": "23776435377389573739555717891589267364161331448909103730752015156572276458827", "price": "0.03", "size": "0", "side": "BUY", "hash": "70cd6aeee9b561018286be49669c60335ba63a71", "best_bid": "0.51", "best_ask": "0.58"}, {"asset_id": "38278925131304241066712865633907202764870863859804168264871289385839720357843", "price": "0.97", "size": "0", "side": "SELL", "hash": "4e960318e59d9ee009ed4bad1c4a0cf7e0fadd96", "best_bid": "0.42", "best_ask": "0.49"}], "timestamp": "1769384205581", "event_type": "price_change"}}
{"_local_timestamp": "2026-01-25T23:36:45.731659+00:00", "data": {"market": "0xb483376a4a11938da0ae705f901db99f563a73f84df0d3dcb2c1bf7052ca279b", "price_changes": [{"asset_id": "38278925131304241066712865633907202764870863859804168264871289385839720357843", "price": "0.03", "size": "0", "side": "BUY", "hash": "af9e4a80a604edf68ba6e997abbe91b918ce3683", "best_bid": "0.42", "best_ask": "0.49"}, {"asset_id": "23776435377389573739555717891589267364161331448909103730752015156572276458827", "price": "0.97", "size": "0", "side": "SELL", "hash": "e5be10a689bf260fb995afc8ad3f8a2f5fda9f35", "best_bid": "0.51", "best_ask": "0.58"}], "timestamp": "1769384205581", "event_type": "price_change"}}
{"_local_timestamp": "2026-01-25T23:36:46.525846+00:00", "data": {"market": "0x98612f171f4dc6a0e346710a7729ea695ccc2e5f49437995894dfd0809884f0c", "price_changes": [{"asset_id": "48560990866788733674131421352321870328649148949521354561724191929176618618723", "price": "0.01", "size": "8079.49", "side": "BUY", "hash": "49a4ee4b71622cb81d8bda410676d31bb93c4f0b", "best_bid": "0.51", "best_ask": "0.58"}, {"asset_id": "47125239482019083915651528778718935257305702079962957861743905530721500306751", "price": "0.99", "size": "8079.49", "side": "SELL", "hash": "dffedcce24c4fdbeed96460f3f178c7b9df040ac", "best_bid": "0.42", "best_ask": "0.49"}], "timestamp": "1769384206323", "event_type": "price_change"}}
{"_local_timestamp": "2026-01-25T23:36:46.531430+00:00", "data": {"market": "0xb483376a4a11938da0ae705f901db99f563a73f84df0d3dcb2c1bf7052ca279b", "price_changes": [{"asset_id": "23776435377389573739555717891589267364161331448909103730752015156572276458827", "price": "0.03", "size": "29.91", "side": "BUY", "hash": "43138018aea4d842401a805fb4c7697a0c9de093", "best_bid": "0.51", "best_ask": "0.58"}, {"asset_id": "38278925131304241066712865633907202764870863859804168264871289385839720357843", "price": "0.97", "size": "29.91", "side": "SELL", "hash": "5ae9e1648d3c57af048a48284259a6f3619a4d04", "best_bid": "0.42", "best_ask": "0.49"}], "timestamp": "1769384206324", "event_type": "price_change"}}
{"_local_timestamp": "2026-01-25T23:36:46.534939+00:00", "data": {"market": "0x98612f171f4dc6a0e346710a7729ea695ccc2e5f49437995894dfd0809884f0c", "price_changes": [{"asset_id": "48560990866788733674131421352321870328649148949521354561724191929176618618723", "price": "0.03", "size": "29.9", "side": "BUY", "hash": "b79becb894a627a7c4be31250925642600afa485", "best_bid": "0.51", "best_ask": "0.58"}, {"asset_id": "47125239482019083915651528778718935257305702079962957861743905530721500306751", "price": "0.97", "size": "29.9", "side": "SELL", "hash": "fd4f7c99602d4909a10b998c2a3f9f9b4715dd68", "best_bid": "0.42", "best_ask": "0.49"}], "timestamp": "1769384206327", "event_type": "price_change"}}
{"_local_timestamp": "2026-01-25T23:36:47.133290+00:00", "data": {"market": "0x72ba07862b22314dbe4f409505a9833da2dfb3ffe2f6a1c8fa1ba3add5e7a039", "price_changes": [{"asset_id": "93425111955845150480136289753481493030447902158015790781546943758014021748210", "price": "0.03", "size": "6.22", "side": "BUY", "hash": "c863839801e466e1bb59a83f6c8230af53056d97", "best_bid": "0.03", "best_ask": "0.97"}, {"asset_id": "2984940558574601482400602739691261511463191599721533374910685943278753091727", "price": "0.97", "size": "6.22", "side": "SELL", "hash": "969670bb7215fc02ce7a60ae63bdf19952e430d6", "best_bid": "0.03", "best_ask": "0.97"}], "timestamp": "1769384206914", "event_type": "price_change"}}
{"_local_timestamp": "2026-01-25T23:36:47.134230+00:00", "data": {"market": "0x72ba07862b22314dbe4f409505a9833da2dfb3ffe2f6a1c8fa1ba3add5e7a039", "price_changes": [{"asset_id": "93425111955845150480136289753481493030447902158015790781546943758014021748210", "price": "0.02", "size": "69.81", "side": "BUY", "hash": "c679431c1a6d29b57c0728e7f0438ad03908f877", "best_bid": "0.03", "best_ask": "0.97"}, {"asset_id": "2984940558574601482400602739691261511463191599721533374910685943278753091727", "price": "0.98", "size": "69.81", "side": "SELL", "hash": "51ae57a1ec74381908a821a45a0e9c00627ab561", "best_bid": "0.03", "best_ask": "0.97"}], "timestamp": "1769384206917", "event_type": "price_change"}}
{"_local_timestamp": "2026-01-25T23:36:47.135185+00:00", "data": {"market": "0x72ba07862b22314dbe4f409505a9833da2dfb3ffe2f6a1c8fa1ba3add5e7a039", "price_changes": [{"asset_id": "93425111955845150480136289753481493030447902158015790781546943758014021748210", "price": "0.01", "size": "11197.18", "side": "BUY", "hash": "6058d2187792c550d99846f1f94142cc7ae3fef9", "best_bid": "0.03", "best_ask": "0.97"}, {"asset_id": "2984940558574601482400602739691261511463191599721533374910685943278753091727", "price": "0.99", "size": "11197.18", "side": "SELL", "hash": "b459acdfff4b6c4f7a2d34c6ecbc5eb6cf3d0156", "best_bid": "0.03", "best_ask": "0.97"}], "timestamp": "1769384206919", "event_type": "price_change"}}
{"_local_timestamp": "2026-01-25T23:36:55.673220+00:00", "data": {"market": "0x88608442d14bdfa98a3d2ece26857aa516f193c8161db0c8e7c779fd8f3464af", "price_changes": [{"asset_id": "20794210232738155208360248995422719359166978550921485109532388301377529305580", "price": "0.08", "size": "700", "side": "BUY", "hash": "eba2c9002645dae79d94bb4a92f1eacc81c0a0d8", "best_bid": "0.53", "best_ask": "0.6"}, {"asset_id": "42097535137505280315737745177128192451567567237475285083506851409423497113459", "price": "0.92", "size": "700", "side": "SELL", "hash": "872a880290cc10c3c34906f88a2dd00083b24ba4", "best_bid": "0.4", "best_ask": "0.47"}], "timestamp": "1769384215460", "event_type": "price_change"}}
{"_local_timestamp": "2026-01-25T23:36:55.774772+00:00", "data": {"market": "0x88608442d14bdfa98a3d2ece26857aa516f193c8161db0c8e7c779fd8f3464af", "price_changes": [{"asset_id": "42097535137505280315737745177128192451567567237475285083506851409423497113459", "price": "0.09", "size": "990.11", "side": "BUY", "hash": "33a5bc4becb958b1ca6869c42ac79076ba953a9b", "best_bid": "0.4", "best_ask": "0.47"}, {"asset_id": "20794210232738155208360248995422719359166978550921485109532388301377529305580", "price": "0.91", "size": "990.11", "side": "SELL", "hash": "7b8fa99a811bf81fd4ef5a1b51c6f72a63458660", "best_bid": "0.53", "best_ask": "0.6"}], "timestamp": "1769384215560", "event_type": "price_change"}}
{"_local_timestamp": "2026-01-25T23:36:55.775759+00:00", "data": {"market": "0x88608442d14bdfa98a3d2ece26857aa516f193c8161db0c8e7c779fd8f3464af", "price_changes": [{"asset_id": "20794210232738155208360248995422719359166978550921485109532388301377529305580", "price": "0.26", "size": "0", "side": "BUY", "hash": "43b10e0facedcf111584cc03ac39253ffbd0ec89", "best_bid": "0.53", "best_ask": "0.6"}, {"asset_id": "42097535137505280315737745177128192451567567237475285083506851409423497113459", "price": "0.74", "size": "0", "side": "SELL", "hash": "64e307c9a553db51a6aca1d4dab3cdbbd7997cf1", "best_bid": "0.4", "best_ask": "0.47"}], "timestamp": "1769384215560", "event_type": "price_change"}}
{"_local_timestamp": "2026-01-25T23:36:55.776603+00:00", "data": {"market": "0x88608442d14bdfa98a3d2ece26857aa516f193c8161db0c8e7c779fd8f3464af", "price_changes": [{"asset_id": "20794210232738155208360248995422719359166978550921485109532388301377529305580", "price": "0.25", "size": "0", "side": "BUY", "hash": "43b10e0facedcf111584cc03ac39253ffbd0ec89", "best_bid": "0.53", "best_ask": "0.6"}, {"asset_id": "42097535137505280315737745177128192451567567237475285083506851409423497113459", "price": "0.75", "size": "0", "side": "SELL", "hash": "64e307c9a553db51a6aca1d4dab3cdbbd7997cf1", "best_bid": "0.4", "best_ask": "0.47"}], "timestamp": "1769384215560", "event_type": "price_change"}}
{"_local_timestamp": "2026-01-25T23:36:55.966624+00:00", "data": {"market": "0x88608442d14bdfa98a3d2ece26857aa516f193c8161db0c8e7c779fd8f3464af", "price_changes": [{"asset_id": "20794210232738155208360248995422719359166978550921485109532388301377529305580", "price": "0.09", "size": "4264.33", "side": "BUY", "hash": "309917bf2a070ae4efc51afc164fe98e7c911c37", "best_bid": "0.53", "best_ask": "0.6"}, {"asset_id": "42097535137505280315737745177128192451567567237475285083506851409423497113459", "price": "0.91", "size": "4264.33", "side": "SELL", "hash": "937536b0266b2bef54096b4011f5d780076b05df", "best_bid": "0.4", "best_ask": "0.47"}], "timestamp": "1769384215677", "event_type": "price_change"}}
{"_local_timestamp": "2026-01-25T23:37:00.967088+00:00", "data": {"market": "0x88608442d14bdfa98a3d2ece26857aa516f193c8161db0c8e7c779fd8f3464af", "price_changes": [{"asset_id": "42097535137505280315737745177128192451567567237475285083506851409423497113459", "price": "0.08", "size": "5247.43", "side": "BUY", "hash": "e588a0a31f3762d74ee5ef4d308f16bfcc330fab", "best_bid": "0.4", "best_ask": "0.47"}, {"asset_id": "20794210232738155208360248995422719359166978550921485109532388301377529305580", "price": "0.92", "size": "5247.43", "side": "SELL", "hash": "adaef107502bc0d7dbff51be6dc576d268d952d8", "best_bid": "0.53", "best_ask": "0.6"}], "timestamp": "1769384220772", "event_type": "price_change"}}
{"_local_timestamp": "2026-01-25T23:37:00.968146+00:00", "data": {"market": "0x88608442d14bdfa98a3d2ece26857aa516f193c8161db0c8e7c779fd8f3464af", "price_changes": [{"asset_id": "20794210232738155208360248995422719359166978550921485109532388301377529305580", "price": "0.08", "size": "600", "side": "BUY", "hash": "b0a79be3f2048725a796d316c816e956583318d6", "best_bid": "0.53", "best_ask": "0.6"}, {"asset_id": "42097535137505280315737745177128192451567567237475285083506851409423497113459", "price": "0.92", "size": "600", "side": "SELL", "hash": "0732f5eb86cdbe6cf2ca5cabff28eb6c0bf503a8", "best_bid": "0.4", "best_ask": "0.47"}], "timestamp": "1769384220773", "event_type": "price_change"}}
{"_local_timestamp": "2026-01-25T23:37:01.240331+00:00", "data": {"market": "0x88608442d14bdfa98a3d2ece26857aa516f193c8161db0c8e7c779fd8f3464af", "price_changes": [{"asset_id": "42097535137505280315737745177128192451567567237475285083506851409423497113459", "price": "0.09", "size": "1090.11", "side": "BUY", "hash": "d906e78dedabc66fe9b9a34a88d48e1e7de6e884", "best_bid": "0.4", "best_ask": "0.47"}, {"asset_id": "20794210232738155208360248995422719359166978550921485109532388301377529305580", "price": "0.91", "size": "1090.11", "side": "SELL", "hash": "367113ba9d684e1ece5bf804662e3244b1b78a38", "best_bid": "0.53", "best_ask": "0.6"}], "timestamp": "1769384221053", "event_type": "price_change"}}
{"_local_timestamp": "2026-01-25T23:37:01.241257+00:00", "data": {"market": "0x88608442d14bdfa98a3d2ece26857aa516f193c8161db0c8e7c779fd8f3464af", "price_changes": [{"asset_id": "20794210232738155208360248995422719359166978550921485109532388301377529305580", "price": "0.09", "size": "4364.33", "side": "BUY", "hash": "1abd29bcbfb95f86fe49f171ae2de0401584d72a", "best_bid": "0.53", "best_ask": "0.6"}, {"asset_id": "42097535137505280315737745177128192451567567237475285083506851409423497113459", "price": "0.91", "size": "4364.33", "side": "SELL", "hash": "1c0661982bdaa5526ba70cd703ed27329835726c", "best_bid": "0.4", "best_ask": "0.47"}], "timestamp": "1769384221054", "event_type": "price_change"}}
{"_local_timestamp": "2026-01-25T23:37:01.521875+00:00", "data": {"market": "0x88608442d14bdfa98a3d2ece26857aa516f193c8161db0c8e7c779fd8f3464af", "price_changes": [{"asset_id": "42097535137505280315737745177128192451567567237475285083506851409423497113459", "price": "0.1", "size": "895.98", "side": "BUY", "hash": "619479e028b81a3e66dfdb03a202bcf565e8a91f", "best_bid": "0.4", "best_ask": "0.47"}, {"asset_id": "20794210232738155208360248995422719359166978550921485109532388301377529305580", "price": "0.9", "size": "895.98", "side": "SELL", "hash": "05afbe4e136f6d5b5cfb82d1b3dc7e49f35d6988", "best_bid": "0.53", "best_ask": "0.6"}], "timestamp": "1769384221336", "event_type": "price_change"}}
{"_local_timestamp": "2026-01-25T23:37:03.058877+00:00", "data": {"market": "0x88608442d14bdfa98a3d2ece26857aa516f193c8161db0c8e7c779fd8f3464af", "price_changes": [{"asset_id": "20794210232738155208360248995422719359166978550921485109532388301377529305580", "price": "0.08", "size": "200", "side": "BUY", "hash": "369345348e3f4da47cf4e8e4c711e95d9e269a58", "best_bid": "0.53", "best_ask": "0.6"}, {"asset_id": "42097535137505280315737745177128192451567567237475285083506851409423497113459", "price": "0.92", "size": "200", "side": "SELL", "hash": "b8d6944968f5178105ff236635117d28a1c71ed9", "best_bid": "0.4", "best_ask": "0.47"}], "timestamp": "1769384222858", "event_type": "price_change"}}
{"_local_timestamp": "2026-01-25T23:37:03.126957+00:00", "data": {"market": "0x88608442d14bdfa98a3d2ece26857aa516f193c8161db0c8e7c779fd8f3464af", "price_changes": [{"asset_id": "20794210232738155208360248995422719359166978550921485109532388301377529305580", "price": "0.08", "size": "2197.11", "side": "BUY", "hash": "7e189d2165d956797043a63758762472be3988a6", "best_bid": "0.53", "best_ask": "0.6"}, {"asset_id": "42097535137505280315737745177128192451567567237475285083506851409423497113459", "price": "0.92", "size": "2197.11", "side": "SELL", "hash": "d670da9af179b7ddab8704bdfaf8cf88c0f0b390", "best_bid": "0.4", "best_ask": "0.47"}], "timestamp": "1769384222934", "event_type": "price_change"}}
{"_local_timestamp": "2026-01-25T23:37:03.127968+00:00", "data": {"market": "0x88608442d14bdfa98a3d2ece26857aa516f193c8161db0c8e7c779fd8f3464af", "price_changes": [{"asset_id": "20794210232738155208360248995422719359166978550921485109532388301377529305580", "price": "0.08", "size": "3467.21", "side": "BUY", "hash": "eb01421d9bea1998102053eefe3f8f582d3fa93e", "best_bid": "0.53", "best_ask": "0.6"}, {"asset_id": "42097535137505280315737745177128192451567567237475285083506851409423497113459", "price": "0.92", "size": "3467.21", "side": "SELL", "hash": "91e3c5cf84e0e853e72bb1c57ab8f80380fac152", "best_bid": "0.4", "best_ask": "0.47"}], "timestamp": "1769384222935", "event_type": "price_change"}}
{"_local_timestamp": "2026-01-25T23:37:03.128957+00:00", "data": {"market": "0x88608442d14bdfa98a3d2ece26857aa516f193c8161db0c8e7c779fd8f3464af", "price_changes": [{"asset_id": "20794210232738155208360248995422719359166978550921485109532388301377529305580", "price": "0.08", "size": "4357.32", "side": "BUY", "hash": "b16b4a7797f67e8fb736b4a654f91e419cbf0fc6", "best_bid": "0.53", "best_ask": "0.6"}, {"asset_id": "42097535137505280315737745177128192451567567237475285083506851409423497113459", "price": "0.92", "size": "4357.32", "side": "SELL", "hash": "8510319900e25cf3ddd961f8a4a6ecb4b4692765", "best_bid": "0.4", "best_ask": "0.47"}], "timestamp": "1769384222936", "event_type": "price_change"}}
{"_local_timestamp": "2026-01-25T23:37:03.331868+00:00", "data": {"market": "0x88608442d14bdfa98a3d2ece26857aa516f193c8161db0c8e7c779fd8f3464af", "price_changes": [{"asset_id": "20794210232738155208360248995422719359166978550921485109532388301377529305580", "price": "0.09", "size": "4764.33", "side": "BUY", "hash": "2a23758c7ae556bcd152705c4b84b1d2111e5916", "best_bid": "0.53", "best_ask": "0.6"}, {"asset_id": "42097535137505280315737745177128192451567567237475285083506851409423497113459", "price": "0.91", "size": "4764.33", "side": "SELL", "hash": "8aa402ea4bb4d30bf81bda8433e088b926b82189", "best_bid": "0.4", "best_ask": "0.47"}], "timestamp": "1769384223150", "event_type": "price_change"}}
{"_local_timestamp": "2026-01-25T23:37:03.332976+00:00", "data": {"market": "0x88608442d14bdfa98a3d2ece26857aa516f193c8161db0c8e7c779fd8f3464af", "price_changes": [{"asset_id": "42097535137505280315737745177128192451567567237475285083506851409423497113459", "price": "0.09", "size": "1490.11", "side": "BUY", "hash": "98c3f9c6c0a6ad99b48706b9b324e77f134620ee", "best_bid": "0.4", "best_ask": "0.47"}, {"asset_id": "20794210232738155208360248995422719359166978550921485109532388301377529305580", "price": "0.91", "size": "1490.11", "side": "SELL", "hash": "463328ad5c2e6c4f328d82eb4b16cfdc0e357d03", "best_bid": "0.53", "best_ask": "0.6"}], "timestamp": "1769384223151", "event_type": "price_change"}}
{"_local_timestamp": "2026-01-25T23:37:05.776643+00:00", "data": {"market": "0x88608442d14bdfa98a3d2ece26857aa516f193c8161db0c8e7c779fd8f3464af", "price_changes": [{"asset_id": "20794210232738155208360248995422719359166978550921485109532388301377529305580", "price": "0.22", "size": "0", "side": "BUY", "hash": "d3e6041391753326794eb7061f6a8f2f42d726be", "best_bid": "0.53", "best_ask": "0.6"}, {"asset_id": "42097535137505280315737745177128192451567567237475285083506851409423497113459", "price": "0.78", "size": "0", "side": "SELL", "hash": "ec64a1b627befd766f647662cd09363f5f5cb425", "best_bid": "0.4", "best_ask": "0.47"}], "timestamp": "1769384225550", "event_type": "price_change"}}
{"_local_timestamp": "2026-01-25T23:37:05.836526+00:00", "data": {"market": "0x88608442d14bdfa98a3d2ece26857aa516f193c8161db0c8e7c779fd8f3464af", "price_changes": [{"asset_id": "42097535137505280315737745177128192451567567237475285083506851409423497113459", "price": "0.08", "size": "4357.32", "side": "BUY", "hash": "72334ef635ddc7297329281f44fdebe1dff93197", "best_bid": "0.4", "best_ask": "0.47"}, {"asset_id": "20794210232738155208360248995422719359166978550921485109532388301377529305580", "price": "0.92", "size": "4357.32", "side": "SELL", "hash": "244417ec134d7b976775805d77b33e373245cd09", "best_bid": "0.53", "best_ask": "0.6"}], "timestamp": "1769384225620", "event_type": "price_change"}}
{"_local_timestamp": "2026-01-25T23:37:05.849626+00:00", "data": {"market": "0x88608442d14bdfa98a3d2ece26857aa516f193c8161db0c8e7c779fd8f3464af", "price_changes": [{"asset_id": "20794210232738155208360248995422719359166978550921485109532388301377529305580", "price": "0.08", "size": "200", "side": "BUY", "hash": "109a4e2478c92f0e1915a5e85ee4417ff30e49c5", "best_bid": "0.53", "best_ask": "0.6"}, {"asset_id": "42097535137505280315737745177128192451567567237475285083506851409423497113459", "price": "0.92", "size": "200", "side": "SELL", "hash": "a6d7b1a32cbac70ed4bc8a854d3e25d550e5ceb2", "best_bid": "0.4", "best_ask": "0.47"}], "timestamp": "1769384225621", "event_type": "price_change"}}
{"_local_timestamp": "2026-01-25T23:37:06.028225+00:00", "data": {"market": "0x88608442d14bdfa98a3d2ece26857aa516f193c8161db0c8e7c779fd8f3464af", "price_changes": [{"asset_id": "20794210232738155208360248995422719359166978550921485109532388301377529305580", "price": "0.26", "size": "50", "side": "BUY", "hash": "7644ccede00ce0832ef13059f6a2b80a95b511ae", "best_bid": "0.53", "best_ask": "0.6"}, {"asset_id": "42097535137505280315737745177128192451567567237475285083506851409423497113459", "price": "0.74", "size": "50", "side": "SELL", "hash": "642a921d3f84fb84a23ac4ed61c255f5905c8e5d", "best_bid": "0.4", "best_ask": "0.47"}], "timestamp": "1769384225816", "event_type": "price_change"}}
{"_local_timestamp": "2026-01-25T23:37:06.071757+00:00", "data": {"market": "0x88608442d14bdfa98a3d2ece26857aa516f193c8161db0c8e7c779fd8f3464af", "price_changes": [{"asset_id": "42097535137505280315737745177128192451567567237475285083506851409423497113459", "price": "0.08", "size": "200", "side": "BUY", "hash": "dcbd29bbd821737481a4df9149fe33559196a5e0", "best_bid": "0.4", "best_ask": "0.47"}, {"asset_id": "20794210232738155208360248995422719359166978550921485109532388301377529305580", "price": "0.92", "size": "200", "side": "SELL", "hash": "a7bd652eb0150e760f2301399915ad57236af2d4", "best_bid": "0.53", "best_ask": "0.6"}], "timestamp": "1769384225848", "event_type": "price_change"}}
