{"_local_timestamp": "2026-01-25T23:40:30.812242+00:00", "data": [{"market": "0x60576953f8f7ecb78bf8c5a7d287d89de0dd4b9c4085a7d7eea7732e710c17ad", "asset_id": "67841192750148997275473648690260112080723046610172086481620702839701751895916", "timestamp": "1769384329145", "hash": "917e83606860139a9549ef3197dc36b1acdc749d", "bids": [{"price": "0.001", "size": "1220"}], "asks": [{"price": "0.999", "size": "4252.04"}, {"price": "0.998", "size": "250"}, {"price": "0.997", "size": "400"}, {"price": "0.996", "size": "8.67"}, {"price": "0.994", "size": "200"}, {"price": "0.99", "size": "10"}, {"price": "0.989", "size": "5.3"}, {"price": "0.968", "size": "914.28"}, {"price": "0.967", "size": "5.21"}, {"price": "0.952", "size": "8700"}, {"price": "0.95", "size": "30"}, {"price": "0.949", "size": "39"}, {"price": "0.94", "size": "700"}, {"price": "0.931", "size": "99.37"}, {"price": "0.93", "size": "6.36"}, {"price": "0.89", "size": "300"}, {"price": "0.889", "size": "61.77"}, {"price": "0.845", "size": "31"}, {"price": "0.821", "size": "38.3"}, {"price": "0.82", "size": "38.09"}, {"price": "0.819", "size": "7.04"}, {"price": "0.477", "size": "136"}, {"price": "0.475", "size": "425"}, {"price": "0.474", "size": "190"}, {"price": "0.473", "size": "13.01"}, {"price": "0.454", "size": "5"}, {"price": "0.359", "size": "10.69"}, {"price": "0.357", "size": "20"}, {"price": "0.356", "size": "25"}, {"price": "0.277", "size": "13"}, {"price": "0.273", "size": "10"}, {"price": "0.272", "size": "20"}, {"price": "0.177", "size": "5"}, {"price": "0.153", "size": "13.33"}, {"price": "0.077", "size": "539"}, {"price": "0.005", "size": "9"}, {"price": "0.003", "size": "38.17"}, {"price": "0.002", "size": "1330.11"}], "event_type": "book", "last_trade_price": ""}, {"market": "0x9ac58d2c51678463b45389b8d11d398a35f98bb9d99cd0a00e7994bf3d3bc106", "asset_id": "54236330394497042999232692608534835969733131094441295535277724798165041782814", "timestamp": "1769384370057", "hash": "2d5c2080f4a07be0bfffa382886be0bb3ba8fc2c", "bids": [{"price": "0.001", "size": "1423.73"}], "asks": [{"price": "0.999", "size": "3104309"}, {"price": "0.998", "size": "257.48"}, {"price": "0.997", "size": "400"}, {"price": "0.996", "size": "6000"}, {"price": "0.995", "size": "5.93"}, {"price": "0.994", "size": "200"}, {"price": "0.99", "size": "10"}, {"price": "0.989", "size": "5.29"}, {"price": "0.968", "size": "914.28"}, {"price": "0.967", "size": "6.82"}, {"price": "0.95", "size": "30"}, {"price": "0.949", "size": "39"}, {"price": "0.948", "size": "631.86"}, {"price": "0.92", "size": "300"}, {"price": "0.919", "size": "84.65"}, {"price": "0.918", "size": "5.13"}, {"price": "0.832", "size": "158"}, {"price": "0.831", "size": "40.57"}, {"price": "0.812", "size": "36.47"}, {"price": "0.81", "size": "10"}, {"price": "0.809", "size": "6.52"}, {"price": "0.477", "size": "413"}, {"price": "0.473", "size": "13.01"}, {"price": "0.472", "size": "10"}, {"price": "0.399", "size": "61"}, {"price": "0.391", "size": "25"}, {"price": "0.39", "size": "20"}, {"price": "0.305", "size": "9.86"}, {"price": "0.304", "size": "20"}, {"price": "0.177", "size": "146"}, {"price": "0.153", "size": "13.33"}, {"price": "0.097", "size": "500"}, {"price": "0.005", "size": "20.61"}, {"price": "0.004", "size": "334.21"}, {"price": "0.002", "size": "100"}], "event_type": "book", "last_trade_price": ""}, {"market": "0xd175d5454046b2a54c76de7ea2f91f3f179ee2460159ea70139c75c1092ab181", "asset_id": "101910817759148199956441888311840516719333433948195260861470195032539715479804", "timestamp": "1769384372333", "hash": "e4077a59cbefab2674528c68ab1f1c1e1eb1d043", "bids": [{"price": "0.01", "size": "310060.76"}, {"price": "0.02", "size": "3885.03"}, {"price": "0.03", "size": "2065"}, {"price": "0.04", "size": "11.39"}, {"price": "0.06", "size": "562"}, {"price": "0.07", "size": "355"}, {"price": "0.08", "size": "13.24"}, {"price": "0.1", "size": "762.88"}, {"price": "0.11", "size": "10.88"}, {"price": "0.12", "size": "6.86"}, {"price": "0.22", "size": "124.61"}], "asks": [{"price": "0.99", "size": "1210"}, {"price": "0.98", "size": "1250"}, {"price": "0.95", "size": "510"}, {"price": "0.94", "size": "33"}, {"price": "0.87", "size": "506.92"}, {"price": "0.84", "size": "137"}, {"price": "0.48", "size": "121"}, {"price": "0.45", "size": "300"}, {"price": "0.44", "size": "100"}, {"price": "0.43", "size": "242.48"}, {"price": "0.23", "size": "20"}], "event_type": "book", "last_trade_price": "0.780"}, {"market": "0xb8d1c3c2cbba18e247a379454e72d31129863a4dc123736926c6d991599a81b2", "asset_id": "21556602496211379227261801086635856748340201761487403620294012091632507009663", "timestamp": "1769384369995", "hash": "e6b9d68eadaec427db398bee6f3555475396b70b", "bids": [{"price": "0.001", "size": "3104315"}, {"price": "0.002", "size": "257.48"}, {"price": "0.003", "size": "400"}, {"price": "0.004", "size": "20300"}, {"price": "0.005", "size": "5.93"}, {"price": "0.006", "size": "200"}, {"price": "0.01", "size": "10"}, {"price": "0.011", "size": "5.73"}, {"price": "0.02", "size": "300"}, {"price": "0.031", "size": "921.19"}, {"price": "0.032", "size": "7.95"}, {"price": "0.05", "size": "30"}, {"price": "0.051", "size": "39"}, {"price": "0.06", "size": "700"}, {"price": "0.061", "size": "112.41"}, {"price": "0.087", "size": "78.81"}, {"price": "0.088", "size": "5.13"}, {"price": "0.11", "size": "200"}, {"price": "0.123", "size": "473"}, {"price": "0.125", "size": "8"}, {"price": "0.135", "size": "50.79"}, {"price": "0.136", "size": "14"}, {"price": "0.205", "size": "33.44"}, {"price": "0.206", "size": "5.73"}, {"price": "0.523", "size": "136"}, {"price": "0.525", "size": "13.06"}, {"price": "0.526", "size": "10"}, {"price": "0.603", "size": "11.37"}, {"price": "0.605", "size": "25"}, {"price": "0.723", "size": "148"}, {"price": "0.724", "size": "20"}, {"price": "0.823", "size": "146"}, {"price": "0.86", "size": "500"}, {"price": "0.923", "size": "1045"}, {"price": "0.924", "size": "977.4"}, {"price": "0.976", "size": "340"}, {"price": "0.996", "size": "43.27"}, {"price": "0.997", "size": "311.63"}, {"price": "0.998", "size": "200"}], "asks": [{"price": "0.999", "size": "11269.73"}], "event_type": "book", "last_trade_price": ""}, {"market": "0x653092399b4e6eb099d59869203392fa82d0ff01fbea2e9afea4aa1512867946", "asset_id": "79391923363755133111783673620134908690733495531408389463553631418324945230516", "timestamp": "1769384350707", "hash": "12d963f041d50314da1bcfd00f8df965e2e74bec", "bids": [{"price": "0.001", "size": "10228.55"}, {"price": "0.002", "size": "10.12"}, {"price": "0.003", "size": "5"}], "asks": [{"price": "0.999", "size": "3104143.02"}, {"price": "0.998", "size": "250"}, {"price": "0.997", "size": "406.66"}, {"price": "0.996", "size": "20000"}, {"price": "0.994", "size": "200"}, {"price": "0.993", "size": "9.81"}, {"price": "0.99", "size": "13"}, {"price": "0.988", "size": "800"}, {"price": "0.98", "size": "700"}, {"price": "0.979", "size": "8.43"}, {"price": "0.95", "size": "30"}, {"price": "0.949", "size": "39"}, {"price": "0.942", "size": "665.51"}, {"price": "0.941", "size": "5.78"}, {"price": "0.891", "size": "284"}, {"price": "0.859", "size": "68.08"}, {"price": "0.857", "size": "13"}, {"price": "0.856", "size": "9.6"}, {"price": "0.477", "size": "106"}, {"price": "0.476", "size": "18.32"}, {"price": "0.394", "size": "48"}, {"price": "0.373", "size": "110"}, {"price": "0.369", "size": "15.21"}, {"price": "0.363", "size": "45"}, {"price": "0.361", "size": "10"}, {"price": "0.36", "size": "20"}, {"price": "0.1", "size": "947.94"}, {"price": "0.077", "size": "760"}, {"price": "0.048", "size": "340"}, {"price": "0.005", "size": "47.49"}, {"price": "0.004", "size": "308.15"}], "event_type": "book", "last_trade_price": ""}, {"market": "0x653092399b4e6eb099d59869203392fa82d0ff01fbea2e9afea4aa1512867946", "asset_id": "68467365377349140502382558650516303800547405844469524834735876287721497052152", "timestamp": "1769384350707", "hash": "9c5df0f0c612aa82c63302af65c98ce32da3b536", "bids": [{"price": "0.001", "size": "3104143.02"}, {"price": "0.002", "size": "250"}, {"price": "0.003", "size": "406.66"}, {"price": "0.004", "size": "20000"}, {"price": "0.006", "size": "200"}, {"price": "0.007", "size": "9.81"}, {"price": "0.01", "size": "13"}, {"price": "0.012", "size": "800"}, {"price": "0.02", "size": "700"}, {"price": "0.021", "size": "8.43"}, {"price": "0.05", "size": "30"}, {"price": "0.051", "size": "39"}, {"price": "0.058", "size": "665.51"}, {"price": "0.059", "size": "5.78"}, {"price": "0.109", "size": "284"}, {"price": "0.141", "size": "68.08"}, {"price": "0.143", "size": "13"}, {"price": "0.144", "size": "9.6"}, {"price": "0.523", "size": "106"}, {"price": "0.524", "size": "18.32"}, {"price": "0.606", "size": "48"}, {"price": "0.627", "size": "110"}, {"price": "0.631", "size": "15.21"}, {"price": "0.637", "size": "45"}, {"price": "0.639", "size": "10"}, {"price": "0.64", "size": "20"}, {"price": "0.9", "size": "947.94"}, {"price": "0.923", "size": "760"}, {"price": "0.952", "size": "340"}, {"price": "0.995", "size": "47.49"}, {"price": "0.996", "size": "308.15"}], "asks": [{"price": "0.999", "size": "10228.55"}, {"price": "0.998", "size": "10.12"}, {"price": "0.997", "size": "5"}], "event_type": "book", "last_trade_price": ""}, {"market": "0xfdc15849e7bfbe9776d666108c2174047134547db0a014ec08605ca19b2c23c6", "asset_id": "99611234567111832279381235616973424305850563087425365084149737464676375626231", "timestamp": "1769384329145", "hash": "cc58dc398c193dfc156050078bd23f1eefa853aa", "bids": [{"price": "0.001", "size": "1529.78"}], "asks": [{"price": "0.999", "size": "4247.03"}, {"price": "0.998", "size": "250"}, {"price": "0.997", "size": "406.77"}, {"price": "0.994", "size": "200"}, {"price": "0.993", "size": "16.51"}, {"price": "0.99", "size": "10"}, {"price": "0.989", "size": "5.3"}, {"price": "0.974", "size": "1007.69"}, {"price": "0.95", "size": "530"}, {"price": "0.949", "size": "39"}, {"price": "0.948", "size": "8.78"}, {"price": "0.929", "size": "412.67"}, {"price": "0.92", "size": "300"}, {"price": "0.919", "size": "98.76"}, {"price": "0.848", "size": "26"}, {"price": "0.839", "size": "49.68"}, {"price": "0.838", "size": "8.26"}, {"price": "0.477", "size": "136"}, {"price": "0.473", "size": "435"}, {"price": "0.472", "size": "189"}, {"price": "0.431", "size": "14.05"}, {"price": "0.429", "size": "25"}, {"price": "0.428", "size": "20"}, {"price": "0.427", "size": "5"}, {"price": "0.31", "size": "11.59"}, {"price": "0.308", "size": "10"}, {"price": "0.307", "size": "20"}, {"price": "0.177", "size": "5"}, {"price": "0.077", "size": "156"}, {"price": "0.01", "size": "132.21"}, {"price": "0.005", "size": "5"}, {"price": "0.003", "size": "67.87"}, {"price": "0.002", "size": "108.62"}], "event_type": "book", "last_trade_price": ""}, {"market": "0x388b017fa66c293566816b3f6253af6800ca69d6ab740ef019e5a69feacacf70", "asset_id": "49541604524685067034733103567606780662654635021473570692999975492153111969210", "timestamp": "1769384417749", "hash": "e72d938c57b3ba39d178bf03bb5f811a826b7f38", "bids": [{"price": "0.001", "size": "28.78"}, {"price": "0.002", "size": "21"}, {"price": "0.003", "size": "5"}, {"price": "0.006", "size": "170.4"}, {"price": "0.007", "size": "171.6"}], "asks": [{"price": "0.999", "size": "1104247.1"}, {"price": "0.998", "size": "250"}, {"price": "0.997", "size": "406.69"}, {"price": "0.996", "size": "20300"}, {"price": "0.994", "size": "200"}, {"price": "0.993", "size": "9.85"}, {"price": "0.99", "size": "10"}, {"price": "0.98", "size": "1000"}, {"price": "0.979", "size": "9.1"}, {"price": "0.966", "size": "176.47"}, {"price": "0.95", "size": "30"}, {"price": "0.949", "size": "39"}, {"price": "0.94", "size": "700"}, {"price": "0.939", "size": "98.36"}, {"price": "0.938", "size": "7.62"}, {"price": "0.92", "size": "300"}, {"price": "0.918", "size": "42"}, {"price": "0.917", "size": "72.28"}, {"price": "0.821", "size": "33.51"}, {"price": "0.82", "size": "33.33"}, {"price": "0.819", "size": "6.83"}, {"price": "0.6", "size": "1304.4"}, {"price": "0.599", "size": "27"}, {"price": "0.59", "size": "363"}, {"price": "0.589", "size": "5"}, {"price": "0.588", "size": "14.56"}, {"price": "0.477", "size": "136"}, {"price": "0.476", "size": "10"}, {"price": "0.405", "size": "10.08"}, {"price": "0.403", "size": "25"}, {"price": "0.402", "size": "20"}, {"price": "0.301", "size": "8.58"}, {"price": "0.3", "size": "20"}, {"price": "0.177", "size": "106"}, {"price": "0.081", "size": "39.3"}, {"price": "0.077", "size": "918"}, {"price": "0.076", "size": "45"}, {"price": "0.069", "size": "340"}, {"price": "0.062", "size": "222.72"}], "event_type": "book", "last_trade_price": ""}, {"market": "0xb3f0b0a92040f41a6aca44e3f909e0236c2687ad29ca77cfd3710c83071b74c9", "asset_id": "104582508148424115897511334519834707085901645295166805533084841423912878555712", "timestamp": "1769384369970", "hash": "5237aa0db138dfce58f0fda259060ee570c6f669", "bids": [{"price": "0.001", "size": "10578"}, {"price": "0.002", "size": "3860"}], "asks": [{"price": "0.999", "size": "3104253"}, {"price": "0.998", "size": "257.48"}, {"price": "0.997", "size": "400"}, {"price": "0.996", "size": "20000"}, {"price": "0.995", "size": "5.93"}, {"price": "0.994", "size": "200"}, {"price": "0.99", "size": "10"}, {"price": "0.989", "size": "8.32"}, {"price": "0.973", "size": "18500"}, {"price": "0.971", "size": "236.45"}, {"price": "0.97", "size": "6.92"}, {"price": "0.95", "size": "30"}, {"price": "0.949", "size": "39"}, {"price": "0.94", "size": "700"}, {"price": "0.939", "size": "112.41"}, {"price": "0.925", "size": "91.42"}, {"price": "0.924", "size": "5.42"}, {"price": "0.89", "size": "200"}, {"price": "0.889", "size": "616.77"}, {"price": "0.851", "size": "32"}, {"price": "0.85", "size": "45.71"}, {"price": "0.819", "size": "37.88"}, {"price": "0.818", "size": "6.8"}, {"price": "0.777", "size": "31"}, {"price": "0.757", "size": "28.21"}, {"price": "0.755", "size": "8"}, {"price": "0.277", "size": "149"}, {"price": "0.233", "size": "20"}, {"price": "0.231", "size": "10"}, {"price": "0.23", "size": "20"}, {"price": "0.11", "size": "977.15"}, {"price": "0.09", "size": "500"}, {"price": "0.077", "size": "1045"}, {"price": "0.076", "size": "21.1"}, {"price": "0.049", "size": "10"}, {"price": "0.005", "size": "51.56"}, {"price": "0.004", "size": "94.05"}], "event_type": "book", "last_trade_price": "0.001"}, {"market": "0x586628fe04202ef38a5a82a52d66bdc6aae569e848df204f712a8decfe39ca27", "asset_id": "14113947289569660354318901014337895050808911024563232706727704224659774787942", "timestamp": "1769384329145", "hash": "7d10163c2e1a26166b7d6b18d4e4fe7a00dcdd11", "bids": [{"price": "0.001", "size": "1479.12"}], "asks": [{"price": "0.999", "size": "2272.01"}, {"price": "0.998", "size": "250"}, {"price": "0.997", "size": "166"}, {"price": "0.996", "size": "8.67"}, {"price": "0.994", "size": "83"}, {"price": "0.99", "size": "60"}, {"price": "0.989", "size": "5.3"}, {"price": "0.976", "size": "1400"}, {"price": "0.975", "size": "5.59"}, {"price": "0.95", "size": "30"}, {"price": "0.949", "size": "39"}, {"price": "0.946", "size": "677.77"}, {"price": "0.945", "size": "5.65"}, {"price": "0.907", "size": "9500"}, {"price": "0.906", "size": "102.12"}, {"price": "0.89", "size": "300"}, {"price": "0.888", "size": "36"}, {"price": "0.872", "size": "90"}, {"price": "0.871", "size": "11.17"}, {"price": "0.477", "size": "136"}, {"price": "0.472", "size": "467"}, {"price": "0.401", "size": "16.02"}, {"price": "0.4", "size": "25"}, {"price": "0.277", "size": "149"}, {"price": "0.269", "size": "20"}, {"price": "0.267", "size": "10"}, {"price": "0.266", "size": "20"}, {"price": "0.153", "size": "13.33"}, {"price": "0.077", "size": "1045"}, {"price": "0.005", "size": "5"}, {"price": "0.003", "size": "86.56"}, {"price": "0.002", "size": "870.9"}], "event_type": "book", "last_trade_price": ""}, {"market": "0xb498db5296d2aaa4d26db3c6b6dc3a80c5924a9ea83b6b4f2f18c6f12726d747", "asset_id": "104760050366702563650209438348007452609559241951955868049242892063686019535745", "timestamp": "1769384114263", "hash": "d2becfe61bb18de27c56d7d35c78fdc843304391", "bids": [{"price": "0.001", "size": "1431.11"}], "asks": [{"price": "0.999", "size": "4303"}, {"price": "0.998", "size": "250"}, {"price": "0.997", "size": "400"}, {"price": "0.996", "size": "8.59"}, {"price": "0.994", "size": "200"}, {"price": "0.99", "size": "10"}, {"price": "0.989", "size": "5.25"}, {"price": "0.978", "size": "1363.63"}, {"price": "0.977", "size": "7.95"}, {"price": "0.95", "size": "30"}, {"price": "0.949", "size": "39"}, {"price": "0.94", "size": "700"}, {"price": "0.938", "size": "129.03"}, {"price": "0.937", "size": "5.15"}, {"price": "0.89", "size": "300"}, {"price": "0.888", "size": "30"}, {"price": "0.858", "size": "70.33"}, {"price": "0.857", "size": "9.72"}, {"price": "0.777", "size": "15"}, {"price": "0.776", "size": "35.71"}, {"price": "0.477", "size": "136"}, {"price": "0.463", "size": "365"}, {"price": "0.457", "size": "14.73"}, {"price": "0.456", "size": "10"}, {"price": "0.391", "size": "25"}, {"price": "0.39", "size": "20"}, {"price": "0.331", "size": "11.95"}, {"price": "0.33", "size": "20"}, {"price": "0.177", "size": "236"}, {"price": "0.077", "size": "1045"}, {"price": "0.075", "size": "340"}, {"price": "0.005", "size": "12"}, {"price": "0.004", "size": "307.78"}, {"price": "0.002", "size": "999.97"}], "event_type": "book", "last_trade_price": "0.001"}, {"market": "0xfdc15849e7bfbe9776d666108c2174047134547db0a014ec08605ca19b2c23c6", "asset_id": "3095574627925506845218316847738268742837051689528940940903139200105416861487", "timestamp": "1769384329145", "hash": "b48908a52cfb3923521f220a049fb7607a9df61e", "bids": [{"price": "0.001", "size": "4247.03"}, {"price": "0.002", "size": "250"}, {"price": "0.003", "size": "406.77"}, {"price": "0.006", "size": "200"}, {"price": "0.007", "size": "16.51"}, {"price": "0.01", "size": "10"}, {"price": "0.011", "size": "5.3"}, {"price": "0.026", "size": "1007.69"}, {"price": "0.05", "size": "530"}, {"price": "0.051", "size": "39"}, {"price": "0.052", "size": "8.78"}, {"price": "0.071", "size": "412.67"}, {"price": "0.08", "size": "300"}, {"price": "0.081", "size": "98.76"}, {"price": "0.152", "size": "26"}, {"price": "0.161", "size": "49.68"}, {"price": "0.162", "size": "8.26"}, {"price": "0.523", "size": "136"}, {"price": "0.527", "size": "435"}, {"price": "0.528", "size": "189"}, {"price": "0.569", "size": "14.05"}, {"price": "0.571", "size": "25"}, {"price": "0.572", "size": "20"}, {"price": "0.573", "size": "5"}, {"price": "0.69", "size": "11.59"}, {"price": "0.692", "size": "10"}, {"price": "0.693", "size": "20"}, {"price": "0.823", "size": "5"}, {"price": "0.923", "size": "156"}, {"price": "0.99", "size": "132.21"}, {"price": "0.995", "size": "5"}, {"price": "0.997", "size": "67.87"}, {"price": "0.998", "size": "108.62"}], "asks": [{"price": "0.999", "size": "1529.78"}], "event_type": "book", "last_trade_price": ""}, {"market": "0x0efaf81024bc4cefd1c35a5b53ebe9f441fa1b7774c1d086374fc5dcc35be042", "asset_id": "28650397233154262434212887987498068547764853654830327874741459920347734042913", "timestamp": "1769384370062", "hash": "4b48341a2e21a348d1aa9f38f7e353f13dd3fd4f", "bids": [{"price": "0.001", "size": "2747"}, {"price": "0.002", "size": "250"}, {"price": "0.003", "size": "406.63"}, {"price": "0.006", "size": "200"}, {"price": "0.007", "size": "9.77"}, {"price": "0.01", "size": "310010"}, {"price": "0.02", "size": "8600"}, {"price": "0.021", "size": "9.03"}, {"price": "0.035", "size": "171.42"}, {"price": "0.05", "size": "30"}, {"price": "0.051", "size": "39"}, {"price": "0.06", "size": "700"}, {"price": "0.061", "size": "98.36"}, {"price": "0.062", "size": "8.46"}, {"price": "0.09", "size": "66.66"}, {"price": "0.11", "size": "300"}, {"price": "0.111", "size": "54.05"}, {"price": "0.19", "size": "2400"}, {"price": "0.192", "size": "17"}, {"price": "0.196", "size": "30.61"}, {"price": "0.198", "size": "10"}, {"price": "0.199", "size": "5.96"}, {"price": "0.222", "size": "27.02"}, {"price": "0.523", "size": "116"}, {"price": "0.532", "size": "475"}, {"price": "0.536", "size": "11.19"}, {"price": "0.537", "size": "55"}, {"price": "0.644", "size": "9.31"}, {"price": "0.645", "size": "20"}, {"price": "0.823", "size": "108"}, {"price": "0.92", "size": "48.93"}, {"price": "0.923", "size": "1034"}, {"price": "0.926", "size": "1333.16"}, {"price": "0.927", "size": "89.35"}], "asks": [{"price": "0.999", "size": "10163"}, {"price": "0.998", "size": "450"}, {"price": "0.997", "size": "293"}], "event_type": "book", "last_trade_price": ""}, {"market": "0xdf590f804dd23faba824aed591abfa3fff55392ab8c89ed0013077a07972d826", "asset_id": "41859180672365961400174931961103956629778260294033021488774095120237032437600", "timestamp": "1769384327162", "hash": "b973faeaac3197a2b118bba2dd0140246ebb1dcf", "bids": [], "asks": [{"price": "0.999", "size": "1101515"}, {"price": "0.998", "size": "7.48"}, {"price": "0.996", "size": "6300"}, {"price": "0.995", "size": "7.07"}, {"price": "0.99", "size": "10"}, {"price": "0.989", "size": "9.09"}, {"price": "0.968", "size": "887.5"}, {"price": "0.967", "size": "7.54"}, {"price": "0.949", "size": "617.64"}, {"price": "0.92", "size": "300"}, {"price": "0.912", "size": "68.18"}, {"price": "0.911", "size": "5.44"}, {"price": "0.79", "size": "2141"}, {"price": "0.789", "size": "28.43"}, {"price": "0.781", "size": "27.39"}, {"price": "0.78", "size": "5.05"}, {"price": "0.697", "size": "649"}, {"price": "0.696", "size": "11"}, {"price": "0.695", "size": "19.67"}, {"price": "0.694", "size": "6"}, {"price": "0.477", "size": "5"}, {"price": "0.408", "size": "168"}, {"price": "0.401", "size": "10.01"}, {"price": "0.358", "size": "9.34"}, {"price": "0.354", "size": "10"}, {"price": "0.353", "size": "25"}, {"price": "0.352", "size": "20"}, {"price": "0.14", "size": "535"}, {"price": "0.007", "size": "21.23"}, {"price": "0.005", "size": "301.79"}, {"price": "0.001", "size": "199.99"}], "event_type": "book", "last_trade_price": ""}, {"market": "0xa62558c07dee376f7903e95977b10c13544d3546eeae6c98130839753e093979", "asset_id": "72574656434993840186445307554025381492285372432846424590534736075839686478597", "timestamp": "1769384375129", "hash": "212f2f6a94966bd93a9ae696f90b87e2be109a77", "bids": [{"price": "0.001", "size": "413.04"}, {"price": "0.002", "size": "221"}, {"price": "0.003", "size": "1205"}], "asks": [{"price": "0.999", "size": "2751.99"}, {"price": "0.998", "size": "250"}, {"price": "0.997", "size": "400"}, {"price": "0.996", "size": "8.65"}, {"price": "0.994", "size": "200"}, {"price": "0.99", "size": "310010"}, {"price": "0.989", "size": "17.17"}, {"price": "0.97", "size": "9100"}, {"price": "0.969", "size": "221.19"}, {"price": "0.95", "size": "30"}, {"price": "0.949", "size": "39"}, {"price": "0.948", "size": "631.86"}, {"price": "0.947", "size": "5.14"}, {"price": "0.92", "size": "300"}, {"price": "0.901", "size": "8"}, {"price": "0.9", "size": "68.57"}, {"price": "0.886", "size": "17"}, {"price": "0.884", "size": "59.11"}, {"price": "0.883", "size": "12.72"}, {"price": "0.777", "size": "5"}, {"price": "0.766", "size": "29.3"}, {"price": "0.763", "size": "10"}, {"price": "0.477", "size": "136"}, {"price": "0.435", "size": "12.13"}, {"price": "0.433", "size": "25"}, {"price": "0.301", "size": "9.8"}, {"price": "0.3", "size": "444"}, {"price": "0.277", "size": "5"}, {"price": "0.276", "size": "7"}, {"price": "0.224", "size": "7"}, {"price": "0.223", "size": "20"}, {"price": "0.21", "size": "450"}, {"price": "0.177", "size": "108"}, {"price": "0.176", "size": "6.66"}, {"price": "0.175", "size": "10"}, {"price": "0.156", "size": "13"}, {"price": "0.054", "size": "500"}, {"price": "0.007", "size": "231.68"}], "event_type": "book", "last_trade_price": ""}, {"market": "0xec222c4c9935b37c2c563f34eb66715fb01f88a3a399830e83e4221153adfe6a", "asset_id": "72384687038182433689874327261984956544997236795314184718224091418094356344966", "timestamp": "1769384385727", "hash": "333d1c40cbb67b57190ece2c0bc5baeb2a625fdc", "bids": [{"price": "0.001", "size": "34"}, {"price": "0.002", "size": "255"}, {"price": "0.003", "size": "5"}], "asks": [{"price": "0.999", "size": "1104211.04"}, {"price": "0.998", "size": "257.54"}, {"price": "0.997", "size": "400"}, {"price": "0.996", "size": "20300"}, {"price": "0.995", "size": "5.98"}, {"price": "0.994", "size": "200"}, {"price": "0.99", "size": "23"}, {"price": "0.989", "size": "10.58"}, {"price": "0.963", "size": "916.21"}, {"price": "0.962", "size": "5.9"}, {"price": "0.95", "size": "30"}, {"price": "0.949", "size": "39"}, {"price": "0.948", "size": "653.84"}, {"price": "0.92", "size": "300"}, {"price": "0.914", "size": "93.02"}, {"price": "0.913", "size": "5.72"}, {"price": "0.785", "size": "2141"}, {"price": "0.784", "size": "250"}, {"price": "0.783", "size": "5.12"}, {"price": "0.766", "size": "8"}, {"price": "0.765", "size": "34.04"}, {"price": "0.477", "size": "136"}, {"price": "0.476", "size": "576"}, {"price": "0.401", "size": "13.35"}, {"price": "0.394", "size": "13.2"}, {"price": "0.386", "size": "25"}, {"price": "0.384", "size": "10"}, {"price": "0.383", "size": "20"}, {"price": "0.077", "size": "689"}, {"price": "0.075", "size": "340"}, {"price": "0.068", "size": "999.98"}, {"price": "0.063", "size": "368.86"}], "event_type": "book", "last_trade_price": ""}, {"market": "0x9ac58d2c51678463b45389b8d11d398a35f98bb9d99cd0a00e7994bf3d3bc106", "asset_id": "65530875443595461022055642853167256131284276704504495385262009209383645659674", "timestamp": "1769384370057", "hash": "2895ff8b3f68bfe5cbc090b107635e992758c2ef", "bids": [{"price": "0.001", "size": "3104309"}, {"price": "0.002", "size": "257.48"}, {"price": "0.003", "size": "400"}, {"price": "0.004", "size": "6000"}, {"price": "0.005", "size": "5.93"}, {"price": "0.006", "size": "200"}, {"price": "0.01", "size": "10"}, {"price": "0.011", "size": "5.29"}, {"price": "0.032", "size": "914.28"}, {"price": "0.033", "size": "6.82"}, {"price": "0.05", "size": "30"}, {"price": "0.051", "size": "39"}, {"price": "0.052", "size": "631.86"}, {"price": "0.08", "size": "300"}, {"price": "0.081", "size": "84.65"}, {"price": "0.082", "size": "5.13"}, {"price": "0.168", "size": "158"}, {"price": "0.169", "size": "40.57"}, {"price": "0.188", "size": "36.47"}, {"price": "0.19", "size": "10"}, {"price": "0.191", "size": "6.52"}, {"price": "0.523", "size": "413"}, {"price": "0.527", "size": "13.01"}, {"price": "0.528", "size": "10"}, {"price": "0.601", "size": "61"}, {"price": "0.609", "size": "25"}, {"price": "0.61", "size": "20"}, {"price": "0.695", "size": "9.86"}, {"price": "0.696", "size": "20"}, {"price": "0.823", "size": "146"}, {"price": "0.847", "size": "13.33"}, {"price": "0.903", "size": "500"}, {"price": "0.995", "size": "20.61"}, {"price": "0.996", "size": "334.21"}, {"price": "0.998", "size": "100"}], "asks": [{"price": "0.999", "size": "1423.73"}], "event_type": "book", "last_trade_price": ""}, {"market": "0xdfd605f298eecea4cd04c838f5347edb33c09483447bc6f2b6ffac24322f6f9b", "asset_id": "104557929326796528193056837422262406792037056098476641689006301544675050508792", "timestamp": "1769383998106", "hash": "9ad2120c2c7abc9d29d163120a66c4f7244cc867", "bids": [{"price": "0.001", "size": "20034"}, {"price": "0.002", "size": "224"}, {"price": "0.003", "size": "5"}, {"price": "0.006", "size": "28.4"}, {"price": "0.007", "size": "28.6"}], "asks": [{"price": "0.999", "size": "3047.23"}, {"price": "0.998", "size": "250"}, {"price": "0.997", "size": "406.92"}, {"price": "0.994", "size": "200"}, {"price": "0.993", "size": "5.93"}, {"price": "0.99", "size": "10"}, {"price": "0.989", "size": "5.78"}, {"price": "0.963", "size": "885.32"}, {"price": "0.962", "size": "5.81"}, {"price": "0.95", "size": "30"}, {"price": "0.949", "size": "673.45"}, {"price": "0.92", "size": "300"}, {"price": "0.916", "size": "81.63"}, {"price": "0.915", "size": "6.19"}, {"price": "0.795", "size": "2041"}, {"price": "0.794", "size": "33.28"}, {"price": "0.782", "size": "18"}, {"price": "0.781", "size": "5.1"}, {"price": "0.768", "size": "29.55"}, {"price": "0.767", "size": "8"}, {"price": "0.477", "size": "124"}, {"price": "0.419", "size": "475"}, {"price": "0.418", "size": "11.78"}, {"price": "0.398", "size": "11.39"}, {"price": "0.397", "size": "25"}, {"price": "0.277", "size": "11"}, {"price": "0.276", "size": "20"}, {"price": "0.215", "size": "10"}, {"price": "0.214", "size": "20"}, {"price": "0.13", "size": "500"}, {"price": "0.077", "size": "937"}, {"price": "0.03", "size": "50"}, {"price": "0.025", "size": "26.12"}, {"price": "0.02", "size": "49.99"}, {"price": "0.019", "size": "148.04"}], "event_type": "book", "last_trade_price": ""}, {"market": "0x20e3bf2810db76a48bb4b915bf85ec43070a54da46f7ee9f123bde8b95add82c", "asset_id": "113173738354606351153328793226311936686716030058934510835145939200861029046537", "timestamp": "1769383999186", "hash": "7f01a2b1a3d7b287c57926dcd194a9a261a41723", "bids": [{"price": "0.001", "size": "6204320.13"}, {"price": "0.002", "size": "250"}, {"price": "0.003", "size": "405.06"}, {"price": "0.004", "size": "15000"}, {"price": "0.006", "size": "200"}, {"price": "0.007", "size": "9.92"}, {"price": "0.01", "size": "10"}, {"price": "0.012", "size": "666.66"}, {"price": "0.02", "size": "700"}, {"price": "0.021", "size": "7.21"}, {"price": "0.05", "size": "30"}, {"price": "0.051", "size": "39"}, {"price": "0.052", "size": "653.84"}, {"price": "0.053", "size": "7.42"}, {"price": "0.08", "size": "300"}, {"price": "0.082", "size": "24"}, {"price": "0.083", "size": "96.38"}, {"price": "0.118", "size": "6"}, {"price": "0.119", "size": "67.22"}, {"price": "0.148", "size": "54.05"}, {"price": "0.149", "size": "9.13"}, {"price": "0.523", "size": "136"}, {"price": "0.553", "size": "521"}, {"price": "0.582", "size": "13.74"}, {"price": "0.583", "size": "25"}, {"price": "0.756", "size": "10"}, {"price": "0.757", "size": "20"}, {"price": "0.758", "size": "20"}, {"price": "0.912", "size": "479.32"}, {"price": "0.916", "size": "340"}, {"price": "0.923", "size": "361"}, {"price": "0.95", "size": "500"}, {"price": "0.952", "size": "99.99"}, {"price": "0.953", "size": "94.1"}, {"price": "0.954", "size": "8.75"}], "asks": [{"price": "0.999", "size": "48"}, {"price": "0.998", "size": "31"}, {"price": "0.997", "size": "5"}, {"price": "0.992", "size": "170.4"}, {"price": "0.991", "size": "171.6"}], "event_type": "book", "last_trade_price": ""}, {"market": "0x98fa184a1a88bad52827716102f6a24a9f0c8b1af5db07bd620eb8dfa55ee28c", "asset_id": "115525374107792247441862537671576247536802966403947578146994740913087078766607", "timestamp": "1769384370047", "hash": "2af76d6260fe00ab78efd87295e09e24f9b0f351", "bids": [{"price": "0.001", "size": "1538.99"}], "asks": [{"price": "0.999", "size": "2839.11"}, {"price": "0.998", "size": "93250"}, {"price": "0.997", "size": "400"}, {"price": "0.996", "size": "8.68"}, {"price": "0.994", "size": "200"}, {"price": "0.99", "size": "10"}, {"price": "0.989", "size": "5.3"}, {"price": "0.974", "size": "1007.69"}, {"price": "0.973", "size": "5.36"}, {"price": "0.95", "size": "30"}, {"price": "0.949", "size": "39"}, {"price": "0.943", "size": "640.35"}, {"price": "0.942", "size": "5.1"}, {"price": "0.92", "size": "300"}, {"price": "0.898", "size": "7"}, {"price": "0.897", "size": "77.66"}, {"price": "0.873", "size": "62.99"}, {"price": "0.872", "size": "11.37"}, {"price": "0.49", "size": "840"}, {"price": "0.477", "size": "282"}, {"price": "0.417", "size": "169"}, {"price": "0.415", "size": "5"}, {"price": "0.414", "size": "13.65"}, {"price": "0.357", "size": "12.44"}, {"price": "0.356", "size": "25"}, {"price": "0.351", "size": "10"}, {"price": "0.35", "size": "20"}, {"price": "0.349", "size": "20"}, {"price": "0.077", "size": "941"}, {"price": "0.049", "size": "10"}, {"price": "0.041", "size": "340"}, {"price": "0.04", "size": "7.5"}, {"price": "0.005", "size": "293.74"}, {"price": "0.004", "size": "88.61"}], "event_type": "book", "last_trade_price": ""}, {"market": "0x50fa9155b39b1f6d3041ad01296611ff7fcd7e06accc6dba1ea4458f95e6e637", "asset_id": "10645904022643906852973817125982125793552212677082290653082149741205114933184", "timestamp": "1769383999186", "hash": "9979d9038acf93fd778db5a4bd48811034956f00", "bids": [{"price": "0.001", "size": "62"}, {"price": "0.002", "size": "5"}, {"price": "0.003", "size": "5"}], "asks": [{"price": "0.999", "size": "3104315.02"}, {"price": "0.998", "size": "257.42"}, {"price": "0.997", "size": "400"}, {"price": "0.996", "size": "20000"}, {"price": "0.995", "size": "5.88"}, {"price": "0.994", "size": "200"}, {"price": "0.99", "size": "10"}, {"price": "0.989", "size": "7.56"}, {"price": "0.976", "size": "25000"}, {"price": "0.97", "size": "266.66"}, {"price": "0.969", "size": "5.32"}, {"price": "0.95", "size": "30"}, {"price": "0.949", "size": "39"}, {"price": "0.94", "size": "700"}, {"price": "0.934", "size": "121.21"}, {"price": "0.933", "size": "5.21"}, {"price": "0.89", "size": "300"}, {"price": "0.888", "size": "36"}, {"price": "0.887", "size": "70.79"}, {"price": "0.848", "size": "52.63"}, {"price": "0.847", "size": "8.84"}, {"price": "0.495", "size": "1765"}, {"price": "0.477", "size": "106"}, {"price": "0.419", "size": "382"}, {"price": "0.406", "size": "5"}, {"price": "0.405", "size": "13.44"}, {"price": "0.404", "size": "25"}, {"price": "0.346", "size": "12.23"}, {"price": "0.344", "size": "10"}, {"price": "0.342", "size": "20"}, {"price": "0.341", "size": "20"}, {"price": "0.144", "size": "1042.35"}, {"price": "0.005", "size": "412.15"}, {"price": "0.004", "size": "148.6"}], "event_type": "book", "last_trade_price": ""}, {"market": "0xdfd605f298eecea4cd04c838f5347edb33c09483447bc6f2b6ffac24322f6f9b", "asset_id": "98906042020990233475237416398190803268957533205491880020838940672709539745702", "timestamp": "1769383998106", "hash": "bea6a2bb45b7959ec1438c96ef95411d502c74de", "bids": [{"price": "0.001", "size": "3047.23"}, {"price": "0.002", "size": "250"}, {"price": "0.003", "size": "406.92"}, {"price": "0.006", "size": "200"}, {"price": "0.007", "size": "5.93"}, {"price": "0.01", "size": "10"}, {"price": "0.011", "size": "5.78"}, {"price": "0.037", "size": "885.32"}, {"price": "0.038", "size": "5.81"}, {"price": "0.05", "size": "30"}, {"price": "0.051", "size": "673.45"}, {"price": "0.08", "size": "300"}, {"price": "0.084", "size": "81.63"}, {"price": "0.085", "size": "6.19"}, {"price": "0.205", "size": "2041"}, {"price": "0.206", "size": "33.28"}, {"price": "0.218", "size": "18"}, {"price": "0.219", "size": "5.1"}, {"price": "0.232", "size": "29.55"}, {"price": "0.233", "size": "8"}, {"price": "0.523", "size": "124"}, {"price": "0.581", "size": "475"}, {"price": "0.582", "size": "11.78"}, {"price": "0.602", "size": "11.39"}, {"price": "0.603", "size": "25"}, {"price": "0.723", "size": "11"}, {"price": "0.724", "size": "20"}, {"price": "0.785", "size": "10"}, {"price": "0.786", "size": "20"}, {"price": "0.87", "size": "500"}, {"price": "0.923", "size": "937"}, {"price": "0.97", "size": "50"}, {"price": "0.975", "size": "26.12"}, {"price": "0.98", "size": "49.99"}, {"price": "0.981", "size": "148.04"}], "asks": [{"price": "0.999", "size": "20034"}, {"price": "0.998", "size": "224"}, {"price": "0.997", "size": "5"}, {"price": "0.994", "size": "28.4"}, {"price": "0.993", "size": "28.6"}], "event_type": "book", "last_trade_price": ""}, {"market": "0x180cad29950aab8a08730c47e904416559aad814321d73854151be137756ad23", "asset_id": "98909251781140045508527043137413768725223127886868660293320661027969116726188", "timestamp": "1769384329133", "hash": "845252e2ce7c632a898708d839777ead44bd1903", "bids": [{"price": "0.001", "size": "3104138.02"}, {"price": "0.002", "size": "265.6"}, {"price": "0.003", "size": "400"}, {"price": "0.004", "size": "20000"}, {"price": "0.005", "size": "12.36"}, {"price": "0.006", "size": "200"}, {"price": "0.01", "size": "10"}, {"price": "0.011", "size": "11.95"}, {"price": "0.022", "size": "1436.36"}, {"price": "0.024", "size": "16.37"}, {"price": "0.05", "size": "30"}, {"price": "0.051", "size": "39"}, {"price": "0.06", "size": "700"}, {"price": "0.064", "size": "150"}, {"price": "0.11", "size": "300"}, {"price": "0.112", "size": "36"}, {"price": "0.144", "size": "79.66"}, {"price": "0.145", "size": "9.5"}, {"price": "0.523", "size": "136"}, {"price": "0.55", "size": "395"}, {"price": "0.58", "size": "16.55"}, {"price": "0.584", "size": "10"}, {"price": "0.585", "size": "25"}, {"price": "0.586", "size": "20"}, {"price": "0.665", "size": "14.43"}, {"price": "0.666", "size": "20"}, {"price": "0.823", "size": "106"}, {"price": "0.826", "size": "16.66"}, {"price": "0.847", "size": "13"}, {"price": "0.923", "size": "1045"}, {"price": "0.997", "size": "24.37"}, {"price": "0.998", "size": "765.46"}], "asks": [{"price": "0.999", "size": "1260.21"}], "event_type": "book", "last_trade_price": ""}, {"market": "0x9f06027c84bac904fd6566b1a2155b457828d0e7676664aa454991ff8d77449e", "asset_id": "99198924097827784427532997585241286678466293148323233780401857923587127415754", "timestamp": "1769384348275", "hash": "5ac722e4e506e7c1ac1f579d7512ff04cec8d7f4", "bids": [{"price": "0.001", "size": "1168.99"}], "asks": [{"price": "0.999", "size": "3052.01"}, {"price": "0.998", "size": "250"}, {"price": "0.997", "size": "400"}, {"price": "0.996", "size": "8.67"}, {"price": "0.994", "size": "200"}, {"price": "0.99", "size": "10"}, {"price": "0.989", "size": "5.3"}, {"price": "0.98", "size": "1000"}, {"price": "0.974", "size": "230.76"}, {"price": "0.973", "size": "10.05"}, {"price": "0.95", "size": "30"}, {"price": "0.949", "size": "39"}, {"price": "0.94", "size": "700"}, {"price": "0.939", "size": "98.36"}, {"price": "0.917", "size": "72.28"}, {"price": "0.916", "size": "6.04"}, {"price": "0.89", "size": "300"}, {"price": "0.889", "size": "54.05"}, {"price": "0.79", "size": "2141"}, {"price": "0.789", "size": "28.43"}, {"price": "0.788", "size": "5.25"}, {"price": "0.735", "size": "178"}, {"price": "0.734", "size": "22.55"}, {"price": "0.477", "size": "136"}, {"price": "0.428", "size": "324"}, {"price": "0.419", "size": "172"}, {"price": "0.418", "size": "10.3"}, {"price": "0.417", "size": "5"}, {"price": "0.376", "size": "9.61"}, {"price": "0.375", "size": "20"}, {"price": "0.373", "size": "25"}, {"price": "0.277", "size": "13"}, {"price": "0.229", "size": "10"}, {"price": "0.228", "size": "20"}, {"price": "0.177", "size": "5"}, {"price": "0.153", "size": "13.33"}, {"price": "0.077", "size": "1045"}, {"price": "0.049", "size": "20"}, {"price": "0.004", "size": "293.59"}, {"price": "0.003", "size": "45"}, {"price": "0.002", "size": "145.78"}], "event_type": "book", "last_trade_price": "0.001"}, {"market": "0x4e397280306caef347fb1d7331440558273d102a4c71053f66a316a070efba45", "asset_id": "58223800218413847420838872169103872385489689201695860879487311158740884821791", "timestamp": "1769384329145", "hash": "dca8c7493f29c551d7c40a26303df9ede87034ea", "bids": [{"price": "0.001", "size": "2747.02"}, {"price": "0.002", "size": "250"}, {"price": "0.003", "size": "406.58"}, {"price": "0.006", "size": "200"}, {"price": "0.007", "size": "9.69"}, {"price": "0.01", "size": "10"}, {"price": "0.012", "size": "571.42"}, {"price": "0.02", "size": "700"}, {"price": "0.021", "size": "10.41"}, {"price": "0.05", "size": "30"}, {"price": "0.051", "size": "39"}, {"price": "0.068", "size": "600.84"}, {"price": "0.069", "size": "5.07"}, {"price": "0.08", "size": "300"}, {"price": "0.081", "size": "84.65"}, {"price": "0.14", "size": "7"}, {"price": "0.141", "size": "48.63"}, {"price": "0.155", "size": "44.23"}, {"price": "0.156", "size": "8.55"}, {"price": "0.523", "size": "136"}, {"price": "0.527", "size": "440"}, {"price": "0.528", "size": "189"}, {"price": "0.529", "size": "12.96"}, {"price": "0.633", "size": "5"}, {"price": "0.634", "size": "10.81"}, {"price": "0.64", "size": "20"}, {"price": "0.642", "size": "25"}, {"price": "0.644", "size": "10"}, {"price": "0.645", "size": "20"}, {"price": "0.846", "size": "13.33"}, {"price": "0.923", "size": "195"}, {"price": "0.925", "size": "340"}, {"price": "0.991", "size": "99.4"}, {"price": "0.992", "size": "144"}], "asks": [{"price": "0.999", "size": "11743.23"}, {"price": "0.998", "size": "200"}], "event_type": "book", "last_trade_price": ""}, {"market": "0x0b4d4807d9ada3da32f66bd906f7c79b931e836338ea9127840a22357dc80d6b", "asset_id": "28340620202432180095608171388765060781029516708678051694406697447993348774238", "timestamp": "1769384369995", "hash": "e11fa1db20f0a63db12b4db18ce64a8a2335a163", "bids": [{"price": "0.001", "size": "2751.99"}, {"price": "0.002", "size": "250"}, {"price": "0.003", "size": "400"}, {"price": "0.004", "size": "8.65"}, {"price": "0.006", "size": "200"}, {"price": "0.01", "size": "310010"}, {"price": "0.011", "size": "21.25"}, {"price": "0.03", "size": "9400"}, {"price": "0.031", "size": "258.06"}, {"price": "0.05", "size": "30"}, {"price": "0.051", "size": "39"}, {"price": "0.06", "size": "200"}, {"price": "0.061", "size": "5.07"}, {"price": "0.064", "size": "750"}, {"price": "0.065", "size": "123.07"}, {"price": "0.11", "size": "300"}, {"price": "0.127", "size": "20"}, {"price": "0.139", "size": "14"}, {"price": "0.141", "size": "56.73"}, {"price": "0.142", "size": "9.91"}, {"price": "0.227", "size": "35.24"}, {"price": "0.228", "size": "10"}, {"price": "0.523", "size": "27"}, {"price": "0.565", "size": "14.15"}, {"price": "0.567", "size": "25"}, {"price": "0.65", "size": "750"}, {"price": "0.699", "size": "11.44"}, {"price": "0.7", "size": "20"}, {"price": "0.823", "size": "108"}, {"price": "0.841", "size": "13.33"}, {"price": "0.982", "size": "7.84"}, {"price": "0.984", "size": "2696.58"}, {"price": "0.985", "size": "402"}, {"price": "0.986", "size": "44.44"}], "asks": [{"price": "0.999", "size": "516"}, {"price": "0.998", "size": "205"}, {"price": "0.997", "size": "232"}, {"price": "0.995", "size": "1349"}, {"price": "0.994", "size": "40"}], "event_type": "book", "last_trade_price": ""}, {"market": "0x586628fe04202ef38a5a82a52d66bdc6aae569e848df204f712a8decfe39ca27", "asset_id": "72560590832887097284352075245670519500409415948211560995482837879557321020248", "timestamp": "1769384329145", "hash": "eb3993adc21fa170c3dcfdf40591f3dc41f9d4ee", "bids": [{"price": "0.001", "size": "2272.01"}, {"price": "0.002", "size": "250"}, {"price": "0.003", "size": "166"}, {"price": "0.004", "size": "8.67"}, {"price": "0.006", "size": "83"}, {"price": "0.01", "size": "60"}, {"price": "0.011", "size": "5.3"}, {"price": "0.024", "size": "1400"}, {"price": "0.025", "size": "5.59"}, {"price": "0.05", "size": "30"}, {"price": "0.051", "size": "39"}, {"price": "0.054", "size": "677.77"}, {"price": "0.055", "size": "5.65"}, {"price": "0.093", "size": "9500"}, {"price": "0.094", "size": "102.12"}, {"price": "0.11", "size": "300"}, {"price": "0.112", "size": "36"}, {"price": "0.128", "size": "90"}, {"price": "0.129", "size": "11.17"}, {"price": "0.523", "size": "136"}, {"price": "0.528", "size": "467"}, {"price": "0.599", "size": "16.02"}, {"price": "0.6", "size": "25"}, {"price": "0.723", "size": "149"}, {"price": "0.731", "size": "20"}, {"price": "0.733", "size": "10"}, {"price": "0.734", "size": "20"}, {"price": "0.847", "size": "13.33"}, {"price": "0.923", "size": "1045"}, {"price": "0.995", "size": "5"}, {"price": "0.997", "size": "86.56"}, {"price": "0.998", "size": "870.9"}], "asks": [{"price": "0.999", "size": "1479.12"}], "event_type": "book", "last_trade_price": ""}, {"market": "0x388b017fa66c293566816b3f6253af6800ca69d6ab740ef019e5a69feacacf70", "asset_id": "68883925535903398159530799578268246684851592835366731124807972752959560431304", "timestamp": "1769384417749", "hash": "e885702a2a1cee4cc71eeed78f93d44aa7a25149", "bids": [{"price": "0.001", "size": "1104247.1"}, {"price": "0.002", "size": "250"}, {"price": "0.003", "size": "406.69"}, {"price": "0.004", "size": "20300"}, {"price": "0.006", "size": "200"}, {"price": "0.007", "size": "9.85"}, {"price": "0.01", "size": "10"}, {"price": "0.02", "size": "1000"}, {"price": "0.021", "size": "9.1"}, {"price": "0.034", "size": "176.47"}, {"price": "0.05", "size": "30"}, {"price": "0.051", "size": "39"}, {"price": "0.06", "size": "700"}, {"price": "0.061", "size": "98.36"}, {"price": "0.062", "size": "7.62"}, {"price": "0.08", "size": "300"}, {"price": "0.082", "size": "42"}, {"price": "0.083", "size": "72.28"}, {"price": "0.179", "size": "33.51"}, {"price": "0.18", "size": "33.33"}, {"price": "0.181", "size": "6.83"}, {"price": "0.4", "size": "1304.4"}, {"price": "0.401", "size": "27"}, {"price": "0.41", "size": "363"}, {"price": "0.411", "size": "5"}, {"price": "0.412", "size": "14.56"}, {"price": "0.523", "size": "136"}, {"price": "0.524", "size": "10"}, {"price": "0.595", "size": "10.08"}, {"price": "0.597", "size": "25"}, {"price": "0.598", "size": "20"}, {"price": "0.699", "size": "8.58"}, {"price": "0.7", "size": "20"}, {"price": "0.823", "size": "106"}, {"price": "0.919", "size": "39.3"}, {"price": "0.923", "size": "918"}, {"price": "0.924", "size": "45"}, {"price": "0.931", "size": "340"}, {"price": "0.938", "size": "222.72"}], "asks": [{"price": "0.999", "size": "28.78"}, {"price": "0.998", "size": "21"}, {"price": "0.997", "size": "5"}, {"price": "0.994", "size": "170.4"}, {"price": "0.993", "size": "171.6"}], "event_type": "book", "last_trade_price": ""}, {"market": "0x3bda95c399f34f112afeef82233601d2c7b39b732492868d4dd9fb8c06f44c4a", "asset_id": "103105445559412650197228684416234707898134960652304619455901950120717295228302", "timestamp": "1769384369995", "hash": "91052cade0151d4cbbaf8b1b5314a215605e081e", "bids": [{"price": "0.001", "size": "2762.99"}, {"price": "0.002", "size": "250"}, {"price": "0.003", "size": "400"}, {"price": "0.004", "size": "8.85"}, {"price": "0.006", "size": "200"}, {"price": "0.01", "size": "110010"}, {"price": "0.011", "size": "22.45"}, {"price": "0.034", "size": "20000"}, {"price": "0.035", "size": "274.28"}, {"price": "0.05", "size": "30"}, {"price": "0.051", "size": "39"}, {"price": "0.06", "size": "200"}, {"price": "0.062", "size": "750"}, {"price": "0.063", "size": "5.29"}, {"price": "0.065", "size": "147.69"}, {"price": "0.11", "size": "300"}, {"price": "0.142", "size": "14"}, {"price": "0.144", "size": "66.66"}, {"price": "0.145", "size": "9.44"}, {"price": "0.51", "size": "1111"}, {"price": "0.523", "size": "136"}, {"price": "0.524", "size": "18.32"}, {"price": "0.6", "size": "46"}, {"price": "0.608", "size": "15.78"}, {"price": "0.61", "size": "25"}, {"price": "0.723", "size": "149"}, {"price": "0.727", "size": "10"}, {"price": "0.728", "size": "20"}, {"price": "0.823", "size": "5"}, {"price": "0.847", "size": "13.33"}, {"price": "0.9", "size": "999.95"}, {"price": "0.923", "size": "941"}, {"price": "0.997", "size": "73.02"}, {"price": "0.998", "size": "555.68"}], "asks": [{"price": "0.999", "size": "1220"}], "event_type": "book", "last_trade_price": ""}, {"market": "0x7499cb05b10df8f07a0cd31417e9f48ece68ef3bd13a8197c12487a3630d5017", "asset_id": "112108452217672365554003857740648803941447166454729564791570976908020655526617", "timestamp": "1769383999186", "hash": "5b24574c04bddbfcf7c72abc6f96b8aa25aa7331", "bids": [{"price": "0.001", "size": "4880"}], "asks": [{"price": "0.999", "size": "4247"}, {"price": "0.998", "size": "250"}, {"price": "0.997", "size": "406.43"}, {"price": "0.994", "size": "200"}, {"price": "0.993", "size": "5.48"}, {"price": "0.99", "size": "10"}, {"price": "0.989", "size": "5.93"}, {"price": "0.981", "size": "19500"}, {"price": "0.98", "size": "20"}, {"price": "0.965", "size": "974.28"}, {"price": "0.964", "size": "8.01"}, {"price": "0.95", "size": "30"}, {"price": "0.949", "size": "39"}, {"price": "0.948", "size": "684.61"}, {"price": "0.918", "size": "42"}, {"price": "0.897", "size": "212.2"}, {"price": "0.896", "size": "15.18"}, {"price": "0.477", "size": "78"}, {"price": "0.426", "size": "501"}, {"price": "0.425", "size": "16.69"}, {"price": "0.37", "size": "15.23"}, {"price": "0.364", "size": "10"}, {"price": "0.363", "size": "20"}, {"price": "0.362", "size": "25"}, {"price": "0.361", "size": "20"}, {"price": "0.177", "size": "5"}, {"price": "0.077", "size": "579"}, {"price": "0.057", "size": "627.31"}, {"price": "0.048", "size": "340"}, {"price": "0.047", "size": "563.84"}, {"price": "0.004", "size": "30.58"}, {"price": "0.003", "size": "173.3"}, {"price": "0.002", "size": "426.66"}], "event_type": "book", "last_trade_price": ""}, {"market": "0xfc84b2b625589cc280cd7cde401696c99505639812c83bb28b0824fbb297b06f", "asset_id": "82115621880923175579102966718566549811955421198728744722120513236749387693264", "timestamp": "1769384370062", "hash": "fd9aab6ee881608926a119698c2b2f75f449c851", "bids": [{"price": "0.001", "size": "35.25"}], "asks": [{"price": "0.999", "size": "2747.03"}, {"price": "0.998", "size": "250"}, {"price": "0.997", "size": "406.66"}, {"price": "0.994", "size": "200"}, {"price": "0.993", "size": "9.12"}, {"price": "0.99", "size": "310010"}, {"price": "0.981", "size": "29000"}, {"price": "0.98", "size": "7.51"}, {"price": "0.975", "size": "1384"}, {"price": "0.95", "size": "30"}, {"price": "0.949", "size": "39"}, {"price": "0.948", "size": "5.08"}, {"price": "0.94", "size": "700"}, {"price": "0.939", "size": "157.37"}, {"price": "0.89", "size": "300"}, {"price": "0.888", "size": "36"}, {"price": "0.883", "size": "82.05"}, {"price": "0.882", "size": "12.64"}, {"price": "0.477", "size": "136"}, {"price": "0.44", "size": "1565"}, {"price": "0.439", "size": "298"}, {"price": "0.438", "size": "177"}, {"price": "0.408", "size": "5"}, {"price": "0.403", "size": "16.08"}, {"price": "0.4", "size": "10"}, {"price": "0.398", "size": "25"}, {"price": "0.397", "size": "20"}, {"price": "0.349", "size": "14.74"}, {"price": "0.277", "size": "12"}, {"price": "0.276", "size": "20"}, {"price": "0.177", "size": "5"}, {"price": "0.174", "size": "16.66"}, {"price": "0.153", "size": "13"}, {"price": "0.077", "size": "403"}, {"price": "0.049", "size": "5"}, {"price": "0.004", "size": "609.03"}, {"price": "0.003", "size": "280.04"}], "event_type": "book", "last_trade_price": ""}, {"market": "0x180cad29950aab8a08730c47e904416559aad814321d73854151be137756ad23", "asset_id": "110987038017115137467642994123824186017997884207034130837015664299010910680722", "timestamp": "1769384329133", "hash": "9835435512146965cbf68eb96f6faf2217fee668", "bids": [{"price": "0.001", "size": "1260.21"}], "asks": [{"price": "0.999", "size": "3104138.02"}, {"price": "0.998", "size": "265.6"}, {"price": "0.997", "size": "400"}, {"price": "0.996", "size": "20000"}, {"price": "0.995", "size": "12.36"}, {"price": "0.994", "size": "200"}, {"price": "0.99", "size": "10"}, {"price": "0.989", "size": "11.95"}, {"price": "0.978", "size": "1436.36"}, {"price": "0.976", "size": "16.37"}, {"price": "0.95", "size": "30"}, {"price": "0.949", "size": "39"}, {"price": "0.94", "size": "700"}, {"price": "0.936", "size": "150"}, {"price": "0.89", "size": "300"}, {"price": "0.888", "size": "36"}, {"price": "0.856", "size": "79.66"}, {"price": "0.855", "size": "9.5"}, {"price": "0.477", "size": "136"}, {"price": "0.45", "size": "395"}, {"price": "0.42", "size": "16.55"}, {"price": "0.416", "size": "10"}, {"price": "0.415", "size": "25"}, {"price": "0.414", "size": "20"}, {"price": "0.335", "size": "14.43"}, {"price": "0.334", "size": "20"}, {"price": "0.177", "size": "106"}, {"price": "0.174", "size": "16.66"}, {"price": "0.153", "size": "13"}, {"price": "0.077", "size": "1045"}, {"price": "0.003", "size": "24.37"}, {"price": "0.002", "size": "765.46"}], "event_type": "book", "last_trade_price": ""}, {"market": "0xdf590f804dd23faba824aed591abfa3fff55392ab8c89ed0013077a07972d826", "asset_id": "50817883746581129204000426127094366882808736862521647625617437604408933254141", "timestamp": "1769384327162", "hash": "f9668e8a4d665598035b1a4e5a911611f6bb5879", "bids": [{"price": "0.001", "size": "1101515"}, {"price": "0.002", "size": "7.48"}, {"price": "0.004", "size": "6300"}, {"price": "0.005", "size": "7.07"}, {"price": "0.01", "size": "10"}, {"price": "0.011", "size": "9.09"}, {"price": "0.032", "size": "887.5"}, {"price": "0.033", "size": "7.54"}, {"price": "0.051", "size": "617.64"}, {"price": "0.08", "size": "300"}, {"price": "0.088", "size": "68.18"}, {"price": "0.089", "size": "5.44"}, {"price": "0.21", "size": "2141"}, {"price": "0.211", "size": "28.43"}, {"price": "0.219", "size": "27.39"}, {"price": "0.22", "size": "5.05"}, {"price": "0.303", "size": "649"}, {"price": "0.304", "size": "11"}, {"price": "0.305", "size": "19.67"}, {"price": "0.306", "size": "6"}, {"price": "0.523", "size": "5"}, {"price": "0.592", "size": "168"}, {"price": "0.599", "size": "10.01"}, {"price": "0.642", "size": "9.34"}, {"price": "0.646", "size": "10"}, {"price": "0.647", "size": "25"}, {"price": "0.648", "size": "20"}, {"price": "0.86", "size": "535"}, {"price": "0.993", "size": "21.23"}, {"price": "0.995", "size": "301.79"}, {"price": "0.999", "size": "199.99"}], "asks": [], "event_type": "book", "last_trade_price": ""}, {"market": "0xb3f0b0a92040f41a6aca44e3f909e0236c2687ad29ca77cfd3710c83071b74c9", "asset_id": "60676933420233144798971210692068617567292894076124499641040029783755014286821", "timestamp": "1769384369970", "hash": "9e2a5851ffe567ce6839e10eb42bfe1c5dcc1f9e", "bids": [{"price": "0.001", "size": "3104253"}, {"price": "0.002", "size": "257.48"}, {"price": "0.003", "size": "400"}, {"price": "0.004", "size": "20000"}, {"price": "0.005", "size": "5.93"}, {"price": "0.006", "size": "200"}, {"price": "0.01", "size": "10"}, {"price": "0.011", "size": "8.32"}, {"price": "0.027", "size": "18500"}, {"price": "0.029", "size": "236.45"}, {"price": "0.03", "size": "6.92"}, {"price": "0.05", "size": "30"}, {"price": "0.051", "size": "39"}, {"price": "0.06", "size": "700"}, {"price": "0.061", "size": "112.41"}, {"price": "0.075", "size": "91.42"}, {"price": "0.076", "size": "5.42"}, {"price": "0.11", "size": "200"}, {"price": "0.111", "size": "616.77"}, {"price": "0.149", "size": "32"}, {"price": "0.15", "size": "45.71"}, {"price": "0.181", "size": "37.88"}, {"price": "0.182", "size": "6.8"}, {"price": "0.223", "size": "31"}, {"price": "0.243", "size": "28.21"}, {"price": "0.245", "size": "8"}, {"price": "0.723", "size": "149"}, {"price": "0.767", "size": "20"}, {"price": "0.769", "size": "10"}, {"price": "0.77", "size": "20"}, {"price": "0.89", "size": "977.15"}, {"price": "0.91", "size": "500"}, {"price": "0.923", "size": "1045"}, {"price": "0.924", "size": "21.1"}, {"price": "0.951", "size": "10"}, {"price": "0.995", "size": "51.56"}, {"price": "0.996", "size": "94.05"}], "asks": [{"price": "0.999", "size": "10578"}, {"price": "0.998", "size": "3860"}], "event_type": "book", "last_trade_price": "0.001"}, {"market": "0x0a6e6898385eade04759a401ab28ee8fa1ced611645ca1e06eb2328411c93850", "asset_id": "98373717403750989662162833750111210918944497427472212228877007287591039744041", "timestamp": "1769383998076", "hash": "1d8a891e9462d3d4c99a826891c5e8615519a022", "bids": [{"price": "0.001", "size": "1263.61"}], "asks": [{"price": "0.999", "size": "4592.49"}, {"price": "0.998", "size": "250"}, {"price": "0.997", "size": "400"}, {"price": "0.996", "size": "9.53"}, {"price": "0.994", "size": "200"}, {"price": "0.99", "size": "10"}, {"price": "0.989", "size": "5.16"}, {"price": "0.98", "size": "300"}, {"price": "0.974", "size": "963.73"}, {"price": "0.973", "size": "8.61"}, {"price": "0.95", "size": "30"}, {"price": "0.949", "size": "39"}, {"price": "0.94", "size": "700"}, {"price": "0.939", "size": "112.41"}, {"price": "0.923", "size": "89.05"}, {"price": "0.922", "size": "6.57"}, {"price": "0.89", "size": "300"}, {"price": "0.884", "size": "34"}, {"price": "0.871", "size": "53.15"}, {"price": "0.87", "size": "15"}, {"price": "0.788", "size": "32.34"}, {"price": "0.787", "size": "5.37"}, {"price": "0.477", "size": "136"}, {"price": "0.42", "size": "480"}, {"price": "0.419", "size": "11.8"}, {"price": "0.373", "size": "10.93"}, {"price": "0.37", "size": "25"}, {"price": "0.369", "size": "20"}, {"price": "0.277", "size": "13"}, {"price": "0.263", "size": "10"}, {"price": "0.262", "size": "20"}, {"price": "0.177", "size": "5"}, {"price": "0.1", "size": "340"}, {"price": "0.077", "size": "1045"}, {"price": "0.075", "size": "340"}, {"price": "0.005", "size": "102"}, {"price": "0.003", "size": "42.31"}, {"price": "0.002", "size": "1455.12"}], "event_type": "book", "last_trade_price": ""}, {"market": "0x20e3bf2810db76a48bb4b915bf85ec43070a54da46f7ee9f123bde8b95add82c", "asset_id": "111833791713605298141350391268557048852627695992567917532719982369837309341050", "timestamp": "1769383999186", "hash": "4fe378835a1f296456fb0d55d5e47073571d7bd9", "bids": [{"price": "0.001", "size": "48"}, {"price": "0.002", "size": "31"}, {"price": "0.003", "size": "5"}, {"price": "0.008", "size": "170.4"}, {"price": "0.009", "size": "171.6"}], "asks": [{"price": "0.999", "size": "6204320.13"}, {"price": "0.998", "size": "250"}, {"price": "0.997", "size": "405.06"}, {"price": "0.996", "size": "15000"}, {"price": "0.994", "size": "200"}, {"price": "0.993", "size": "9.92"}, {"price": "0.99", "size": "10"}, {"price": "0.988", "size": "666.66"}, {"price": "0.98", "size": "700"}, {"price": "0.979", "size": "7.21"}, {"price": "0.95", "size": "30"}, {"price": "0.949", "size": "39"}, {"price": "0.948", "size": "653.84"}, {"price": "0.947", "size": "7.42"}, {"price": "0.92", "size": "300"}, {"price": "0.918", "size": "24"}, {"price": "0.917", "size": "96.38"}, {"price": "0.882", "size": "6"}, {"price": "0.881", "size": "67.22"}, {"price": "0.852", "size": "54.05"}, {"price": "0.851", "size": "9.13"}, {"price": "0.477", "size": "136"}, {"price": "0.447", "size": "521"}, {"price": "0.418", "size": "13.74"}, {"price": "0.417", "size": "25"}, {"price": "0.244", "size": "10"}, {"price": "0.243", "size": "20"}, {"price": "0.242", "size": "20"}, {"price": "0.088", "size": "479.32"}, {"price": "0.084", "size": "340"}, {"price": "0.077", "size": "361"}, {"price": "0.05", "size": "500"}, {"price": "0.048", "size": "99.99"}, {"price": "0.047", "size": "94.1"}, {"price": "0.046", "size": "8.75"}], "event_type": "book", "last_trade_price": ""}, {"market": "0xfc84b2b625589cc280cd7cde401696c99505639812c83bb28b0824fbb297b06f", "asset_id": "70308869496420061197588382992609071299857414289715415451156362981997068041038", "timestamp": "1769384370062", "hash": "3e66d2a45631fcb8fbcb54b75363453d83d09016", "bids": [{"price": "0.001", "size": "2747.03"}, {"price": "0.002", "size": "250"}, {"price": "0.003", "size": "406.66"}, {"price": "0.006", "size": "200"}, {"price": "0.007", "size": "9.12"}, {"price": "0.01", "size": "310010"}, {"price": "0.019", "size": "29000"}, {"price": "0.02", "size": "7.51"}, {"price": "0.025", "size": "1384"}, {"price": "0.05", "size": "30"}, {"price": "0.051", "size": "39"}, {"price": "0.052", "size": "5.08"}, {"price": "0.06", "size": "700"}, {"price": "0.061", "size": "157.37"}, {"price": "0.11", "size": "300"}, {"price": "0.112", "size": "36"}, {"price": "0.117", "size": "82.05"}, {"price": "0.118", "size": "12.64"}, {"price": "0.523", "size": "136"}, {"price": "0.56", "size": "1565"}, {"price": "0.561", "size": "298"}, {"price": "0.562", "size": "177"}, {"price": "0.592", "size": "5"}, {"price": "0.597", "size": "16.08"}, {"price": "0.6", "size": "10"}, {"price": "0.602", "size": "25"}, {"price": "0.603", "size": "20"}, {"price": "0.651", "size": "14.74"}, {"price": "0.723", "size": "12"}, {"price": "0.724", "size": "20"}, {"price": "0.823", "size": "5"}, {"price": "0.826", "size": "16.66"}, {"price": "0.847", "size": "13"}, {"price": "0.923", "size": "403"}, {"price": "0.951", "size": "5"}, {"price": "0.996", "size": "609.03"}, {"price": "0.997", "size": "280.04"}], "asks": [{"price": "0.999", "size": "35.25"}], "event_type": "book", "last_trade_price": ""}, {"market": "0x9f06027c84bac904fd6566b1a2155b457828d0e7676664aa454991ff8d77449e", "asset_id": "106251085329490525862626543682539632336091553914280593774322950507008017594040", "timestamp": "1769384348275", "hash": "4fcee47dec65c1faf880c45fc1fe2a1a565ef69a", "bids": [{"price": "0.001", "size": "3052.01"}, {"price": "0.002", "size": "250"}, {"price": "0.003", "size": "400"}, {"price": "0.004", "size": "8.67"}, {"price": "0.006", "size": "200"}, {"price": "0.01", "size": "10"}, {"price": "0.011", "size": "5.3"}, {"price": "0.02", "size": "1000"}, {"price": "0.026", "size": "230.76"}, {"price": "0.027", "size": "10.05"}, {"price": "0.05", "size": "30"}, {"price": "0.051", "size": "39"}, {"price": "0.06", "size": "700"}, {"price": "0.061", "size": "98.36"}, {"price": "0.083", "size": "72.28"}, {"price": "0.084", "size": "6.04"}, {"price": "0.11", "size": "300"}, {"price": "0.111", "size": "54.05"}, {"price": "0.21", "size": "2141"}, {"price": "0.211", "size": "28.43"}, {"price": "0.212", "size": "5.25"}, {"price": "0.265", "size": "178"}, {"price": "0.266", "size": "22.55"}, {"price": "0.523", "size": "136"}, {"price": "0.572", "size": "324"}, {"price": "0.581", "size": "172"}, {"price": "0.582", "size": "10.3"}, {"price": "0.583", "size": "5"}, {"price": "0.624", "size": "9.61"}, {"price": "0.625", "size": "20"}, {"price": "0.627", "size": "25"}, {"price": "0.723", "size": "13"}, {"price": "0.771", "size": "10"}, {"price": "0.772", "size": "20"}, {"price": "0.823", "size": "5"}, {"price": "0.847", "size": "13.33"}, {"price": "0.923", "size": "1045"}, {"price": "0.951", "size": "20"}, {"price": "0.996", "size": "293.59"}, {"price": "0.997", "size": "45"}, {"price": "0.998", "size": "145.78"}], "asks": [{"price": "0.999", "size": "1168.99"}], "event_type": "book", "last_trade_price": "0.001"}, {"market": "0x71eb9d9a28332fd88fd5a6fbf5b2e6bb771c195a23f2c94eca1f0e89f1ef16c2", "asset_id": "56782241068199600313268662692209803590655001932781133985288119301438305647529", "timestamp": "1769384329289", "hash": "ca09da1f302b0b9b774b1f6878de2d428bc0d6a1", "bids": [{"price": "0.001", "size": "44.04"}, {"price": "0.002", "size": "5"}, {"price": "0.003", "size": "5"}, {"price": "0.005", "size": "1352"}, {"price": "0.006", "size": "240"}], "asks": [{"price": "0.999", "size": "3114315"}, {"price": "0.998", "size": "257.48"}, {"price": "0.997", "size": "400"}, {"price": "0.996", "size": "20000"}, {"price": "0.995", "size": "5.93"}, {"price": "0.994", "size": "200"}, {"price": "0.99", "size": "10"}, {"price": "0.989", "size": "5.29"}, {"price": "0.986", "size": "18300"}, {"price": "0.98", "size": "300"}, {"price": "0.974", "size": "963.73"}, {"price": "0.973", "size": "6.18"}, {"price": "0.95", "size": "30"}, {"price": "0.949", "size": "39"}, {"price": "0.94", "size": "700"}, {"price": "0.938", "size": "110.59"}, {"price": "0.937", "size": "6.6"}, {"price": "0.89", "size": "300"}, {"price": "0.867", "size": "30"}, {"price": "0.865", "size": "14"}, {"price": "0.864", "size": "50.42"}, {"price": "0.835", "size": "41.55"}, {"price": "0.834", "size": "7.88"}, {"price": "0.777", "size": "91"}, {"price": "0.776", "size": "30.61"}, {"price": "0.617", "size": "15.75"}, {"price": "0.616", "size": "17.85"}, {"price": "0.477", "size": "120"}, {"price": "0.475", "size": "89.25"}, {"price": "0.433", "size": "12.09"}, {"price": "0.432", "size": "25"}, {"price": "0.431", "size": "158"}, {"price": "0.43", "size": "350"}, {"price": "0.241", "size": "10"}, {"price": "0.24", "size": "20"}, {"price": "0.239", "size": "20"}, {"price": "0.1", "size": "934.34"}, {"price": "0.077", "size": "1044"}, {"price": "0.064", "size": "223.05"}, {"price": "0.013", "size": "15.75"}, {"price": "0.011", "size": "35"}, {"price": "0.01", "size": "89.25"}], "event_type": "book", "last_trade_price": ""}, {"market": "0x4e397280306caef347fb1d7331440558273d102a4c71053f66a316a070efba45", "asset_id": "47273346174724440037399535645384424716569244075116503754882902177445059533612", "timestamp": "1769384329145", "hash": "e6e08be2acd945c2600621d4d21738da84afc3cd", "bids": [{"price": "0.001", "size": "11743.23"}, {"price": "0.002", "size": "200"}], "asks": [{"price": "0.999", "size": "2747.02"}, {"price": "0.998", "size": "250"}, {"price": "0.997", "size": "406.58"}, {"price": "0.994", "size": "200"}, {"price": "0.993", "size": "9.69"}, {"price": "0.99", "size": "10"}, {"price": "0.988", "size": "571.42"}, {"price": "0.98", "size": "700"}, {"price": "0.979", "size": "10.41"}, {"price": "0.95", "size": "30"}, {"price": "0.949", "size": "39"}, {"price": "0.932", "size": "600.84"}, {"price": "0.931", "size": "5.07"}, {"price": "0.92", "size": "300"}, {"price": "0.919", "size": "84.65"}, {"price": "0.86", "size": "7"}, {"price": "0.859", "size": "48.63"}, {"price": "0.845", "size": "44.23"}, {"price": "0.844", "size": "8.55"}, {"price": "0.477", "size": "136"}, {"price": "0.473", "size": "440"}, {"price": "0.472", "size": "189"}, {"price": "0.471", "size": "12.96"}, {"price": "0.367", "size": "5"}, {"price": "0.366", "size": "10.81"}, {"price": "0.36", "size": "20"}, {"price": "0.358", "size": "25"}, {"price": "0.356", "size": "10"}, {"price": "0.355", "size": "20"}, {"price": "0.154", "size": "13.33"}, {"price": "0.077", "size": "195"}, {"price": "0.075", "size": "340"}, {"price": "0.009", "size": "99.4"}, {"price": "0.008", "size": "144"}], "event_type": "book", "last_trade_price": ""}, {"market": "0x0b4d4807d9ada3da32f66bd906f7c79b931e836338ea9127840a22357dc80d6b", "asset_id": "80365173313895983605325248892162569953987774602633505688541422929067192725254", "timestamp": "1769384369995", "hash": "ebfe1af640e27be21dfb48d027930f5b698f9291", "bids": [{"price": "0.001", "size": "516"}, {"price": "0.002", "size": "205"}, {"price": "0.003", "size": "232"}, {"price": "0.005", "size": "1349"}, {"price": "0.006", "size": "40"}], "asks": [{"price": "0.999", "size": "2751.99"}, {"price": "0.998", "size": "250"}, {"price": "0.997", "size": "400"}, {"price": "0.996", "size": "8.65"}, {"price": "0.994", "size": "200"}, {"price": "0.99", "size": "310010"}, {"price": "0.989", "size": "21.25"}, {"price": "0.97", "size": "9400"}, {"price": "0.969", "size": "258.06"}, {"price": "0.95", "size": "30"}, {"price": "0.949", "size": "39"}, {"price": "0.94", "size": "200"}, {"price": "0.939", "size": "5.07"}, {"price": "0.936", "size": "750"}, {"price": "0.935", "size": "123.07"}, {"price": "0.89", "size": "300"}, {"price": "0.873", "size": "20"}, {"price": "0.861", "size": "14"}, {"price": "0.859", "size": "56.73"}, {"price": "0.858", "size": "9.91"}, {"price": "0.773", "size": "35.24"}, {"price": "0.772", "size": "10"}, {"price": "0.477", "size": "27"}, {"price": "0.435", "size": "14.15"}, {"price": "0.433", "size": "25"}, {"price": "0.35", "size": "750"}, {"price": "0.301", "size": "11.44"}, {"price": "0.3", "size": "20"}, {"price": "0.177", "size": "108"}, {"price": "0.159", "size": "13.33"}, {"price": "0.018", "size": "7.84"}, {"price": "0.016", "size": "2696.58"}, {"price": "0.015", "size": "402"}, {"price": "0.014", "size": "44.44"}], "event_type": "book", "last_trade_price": ""}, {"market": "0x31967ab350da8f760c547a62ce495f63f04c7402ea2bc291f7358d6aa367fdd8", "asset_id": "74574612697917499641784436195980418240322600911590628796653263539397328153034", "timestamp": "1769384417602", "hash": "07c783594da17d58c9b62e038d893c79a330e852", "bids": [{"price": "0.001", "size": "3104211"}, {"price": "0.002", "size": "257.48"}, {"price": "0.003", "size": "400"}, {"price": "0.004", "size": "20000"}, {"price": "0.005", "size": "6.91"}, {"price": "0.006", "size": "200"}, {"price": "0.01", "size": "23"}, {"price": "0.011", "size": "17.97"}, {"price": "0.034", "size": "16700"}, {"price": "0.035", "size": "228.57"}, {"price": "0.05", "size": "30"}, {"price": "0.051", "size": "39"}, {"price": "0.058", "size": "637.93"}, {"price": "0.059", "size": "10.1"}, {"price": "0.098", "size": "581.63"}, {"price": "0.099", "size": "20"}, {"price": "0.1", "size": "10"}, {"price": "0.211", "size": "37.91"}, {"price": "0.212", "size": "5.43"}, {"price": "0.523", "size": "136"}, {"price": "0.525", "size": "291"}, {"price": "0.562", "size": "14.23"}, {"price": "0.564", "size": "25"}, {"price": "0.565", "size": "20"}, {"price": "0.698", "size": "11.46"}, {"price": "0.7", "size": "10"}, {"price": "0.701", "size": "20"}, {"price": "0.823", "size": "5"}, {"price": "0.847", "size": "13.33"}, {"price": "0.907", "size": "932.12"}, {"price": "0.931", "size": "340"}, {"price": "0.936", "size": "30"}, {"price": "0.937", "size": "45"}], "asks": [{"price": "0.999", "size": "20056.31"}, {"price": "0.998", "size": "200"}], "event_type": "book", "last_trade_price": ""}, {"market": "0xa62558c07dee376f7903e95977b10c13544d3546eeae6c98130839753e093979", "asset_id": "35970432242453970638378005355807025798529538734302331296289043262158829773976", "timestamp": "1769384375129", "hash": "c2e0b2735e6653ab99968dc2183d8c9f0adf8eb0", "bids": [{"price": "0.001", "size": "2751.99"}, {"price": "0.002", "size": "250"}, {"price": "0.003", "size": "400"}, {"price": "0.004", "size": "8.65"}, {"price": "0.006", "size": "200"}, {"price": "0.01", "size": "310010"}, {"price": "0.011", "size": "17.17"}, {"price": "0.03", "size": "9100"}, {"price": "0.031", "size": "221.19"}, {"price": "0.05", "size": "30"}, {"price": "0.051", "size": "39"}, {"price": "0.052", "size": "631.86"}, {"price": "0.053", "size": "5.14"}, {"price": "0.08", "size": "300"}, {"price": "0.099", "size": "8"}, {"price": "0.1", "size": "68.57"}, {"price": "0.114", "size": "17"}, {"price": "0.116", "size": "59.11"}, {"price": "0.117", "size": "12.72"}, {"price": "0.223", "size": "5"}, {"price": "0.234", "size": "29.3"}, {"price": "0.237", "size": "10"}, {"price": "0.523", "size": "136"}, {"price": "0.565", "size": "12.13"}, {"price": "0.567", "size": "25"}, {"price": "0.699", "size": "9.8"}, {"price": "0.7", "size": "444"}, {"price": "0.723", "size": "5"}, {"price": "0.724", "size": "7"}, {"price": "0.776", "size": "7"}, {"price": "0.777", "size": "20"}, {"price": "0.79", "size": "450"}, {"price": "0.823", "size": "108"}, {"price": "0.824", "size": "6.66"}, {"price": "0.825", "size": "10"}, {"price": "0.844", "size": "13"}, {"price": "0.946", "size": "500"}, {"price": "0.993", "size": "231.68"}], "asks": [{"price": "0.999", "size": "413.04"}, {"price": "0.998", "size": "221"}, {"price": "0.997", "size": "1205"}], "event_type": "book", "last_trade_price": ""}, {"market": "0x98fa184a1a88bad52827716102f6a24a9f0c8b1af5db07bd620eb8dfa55ee28c", "asset_id": "39074980042655340842202556305948460936159251335435619025732786947831346814953", "timestamp": "1769384370047", "hash": "2e04095216413991a5794cb6912d2b8fe8bf9cb8", "bids": [{"price": "0.001", "size": "2839.11"}, {"price": "0.002", "size": "93250"}, {"price": "0.003", "size": "400"}, {"price": "0.004", "size": "8.68"}, {"price": "0.006", "size": "200"}, {"price": "0.01", "size": "10"}, {"price": "0.011", "size": "5.3"}, {"price": "0.026", "size": "1007.69"}, {"price": "0.027", "size": "5.36"}, {"price": "0.05", "size": "30"}, {"price": "0.051", "size": "39"}, {"price": "0.057", "size": "640.35"}, {"price": "0.058", "size": "5.1"}, {"price": "0.08", "size": "300"}, {"price": "0.102", "size": "7"}, {"price": "0.103", "size": "77.66"}, {"price": "0.127", "size": "62.99"}, {"price": "0.128", "size": "11.37"}, {"price": "0.51", "size": "840"}, {"price": "0.523", "size": "282"}, {"price": "0.583", "size": "169"}, {"price": "0.585", "size": "5"}, {"price": "0.586", "size": "13.65"}, {"price": "0.643", "size": "12.44"}, {"price": "0.644", "size": "25"}, {"price": "0.649", "size": "10"}, {"price": "0.65", "size": "20"}, {"price": "0.651", "size": "20"}, {"price": "0.923", "size": "941"}, {"price": "0.951", "size": "10"}, {"price": "0.959", "size": "340"}, {"price": "0.96", "size": "7.5"}, {"price": "0.995", "size": "293.74"}, {"price": "0.996", "size": "88.61"}], "asks": [{"price": "0.999", "size": "1538.99"}], "event_type": "book", "last_trade_price": ""}, {"market": "0x06c4ac6a22e3c924d72a461148ebb4240ebb55e8ddeb962a7059927b985fc08f", "asset_id": "78300931071701042474140195804986160795843314609787519334930755714412714896602", "timestamp": "1769384372333", "hash": "be0d0ce86c1ec17276ed8a07e46fb38aaec5d1ca", "bids": [{"price": "0.001", "size": "11377.86"}], "asks": [{"price": "0.999", "size": "2752.01"}, {"price": "0.998", "size": "250"}, {"price": "0.997", "size": "400"}, {"price": "0.996", "size": "8.67"}, {"price": "0.994", "size": "200"}, {"price": "0.99", "size": "310010"}, {"price": "0.989", "size": "5.3"}, {"price": "0.976", "size": "985.71"}, {"price": "0.975", "size": "6.31"}, {"price": "0.95", "size": "30"}, {"price": "0.949", "size": "39"}, {"price": "0.942", "size": "618.22"}, {"price": "0.941", "size": "8.05"}, {"price": "0.92", "size": "8700"}, {"price": "0.918", "size": "42"}, {"price": "0.917", "size": "82.61"}, {"price": "0.823", "size": "38.74"}, {"price": "0.822", "size": "7.07"}, {"price": "0.777", "size": "143"}, {"price": "0.766", "size": "29.3"}, {"price": "0.765", "size": "10"}, {"price": "0.477", "size": "116"}, {"price": "0.476", "size": "13.08"}, {"price": "0.39", "size": "741"}, {"price": "0.389", "size": "52"}, {"price": "0.387", "size": "5"}, {"price": "0.385", "size": "85"}, {"price": "0.384", "size": "20"}, {"price": "0.333", "size": "10.28"}, {"price": "0.332", "size": "20"}, {"price": "0.177", "size": "108"}, {"price": "0.153", "size": "13.33"}, {"price": "0.077", "size": "569"}, {"price": "0.064", "size": "340"}, {"price": "0.003", "size": "179.99"}, {"price": "0.002", "size": "948.64"}], "event_type": "book", "last_trade_price": ""}, {"market": "0x0a6e6898385eade04759a401ab28ee8fa1ced611645ca1e06eb2328411c93850", "asset_id": "67803232823547511686969023843434828627262672053477282501551026534050897477694", "timestamp": "1769383998076", "hash": "f8f26720928848b2d26fc8d0b633c88145b7d54d", "bids": [{"price": "0.001", "size": "4592.49"}, {"price": "0.002", "size": "250"}, {"price": "0.003", "size": "400"}, {"price": "0.004", "size": "9.53"}, {"price": "0.006", "size": "200"}, {"price": "0.01", "size": "10"}, {"price": "0.011", "size": "5.16"}, {"price": "0.02", "size": "300"}, {"price": "0.026", "size": "963.73"}, {"price": "0.027", "size": "8.61"}, {"price": "0.05", "size": "30"}, {"price": "0.051", "size": "39"}, {"price": "0.06", "size": "700"}, {"price": "0.061", "size": "112.41"}, {"price": "0.077", "size": "89.05"}, {"price": "0.078", "size": "6.57"}, {"price": "0.11", "size": "300"}, {"price": "0.116", "size": "34"}, {"price": "0.129", "size": "53.15"}, {"price": "0.13", "size": "15"}, {"price": "0.212", "size": "32.34"}, {"price": "0.213", "size": "5.37"}, {"price": "0.523", "size": "136"}, {"price": "0.58", "size": "480"}, {"price": "0.581", "size": "11.8"}, {"price": "0.627", "size": "10.93"}, {"price": "0.63", "size": "25"}, {"price": "0.631", "size": "20"}, {"price": "0.723", "size": "13"}, {"price": "0.737", "size": "10"}, {"price": "0.738", "size": "20"}, {"price": "0.823", "size": "5"}, {"price": "0.9", "size": "340"}, {"price": "0.923", "size": "1045"}, {"price": "0.925", "size": "340"}, {"price": "0.995", "size": "102"}, {"price": "0.997", "size": "42.31"}, {"price": "0.998", "size": "1455.12"}], "asks": [{"price": "0.999", "size": "1263.61"}], "event_type": "book", "last_trade_price": ""}, {"market": "0xce465bdf15fd274b3d6bd5e4c543fb047f5bc09e306d9a70dd9cf3b207f7a547", "asset_id": "3990566517926198774760739919993523333580985526226102598439634813084268870587", "timestamp": "1769384369995", "hash": "4bbe4a7fb8b9c38ba651645272ab95531480d158", "bids": [{"price": "0.001", "size": "2784.01"}, {"price": "0.002", "size": "250"}, {"price": "0.003", "size": "400"}, {"price": "0.004", "size": "8.68"}, {"price": "0.006", "size": "200"}, {"price": "0.01", "size": "310010"}, {"price": "0.011", "size": "5.3"}, {"price": "0.019", "size": "24300"}, {"price": "0.02", "size": "300"}, {"price": "0.032", "size": "950"}, {"price": "0.033", "size": "5.61"}, {"price": "0.05", "size": "30"}, {"price": "0.051", "size": "39"}, {"price": "0.06", "size": "700"}, {"price": "0.072", "size": "111.11"}, {"price": "0.073", "size": "5.17"}, {"price": "0.11", "size": "200"}, {"price": "0.111", "size": "200"}, {"price": "0.112", "size": "71.42"}, {"price": "0.162", "size": "12"}, {"price": "0.165", "size": "48.48"}, {"price": "0.166", "size": "8"}, {"price": "0.523", "size": "136"}, {"price": "0.524", "size": "10"}, {"price": "0.571", "size": "52"}, {"price": "0.572", "size": "13.98"}, {"price": "0.61", "size": "13.11"}, {"price": "0.612", "size": "25"}, {"price": "0.735", "size": "214.4"}, {"price": "0.736", "size": "20"}, {"price": "0.823", "size": "108"}, {"price": "0.923", "size": "1045"}, {"price": "0.924", "size": "499"}, {"price": "0.995", "size": "36.25"}, {"price": "0.996", "size": "221.42"}, {"price": "0.997", "size": "147.76"}], "asks": [{"price": "0.999", "size": "1326"}, {"price": "0.998", "size": "5"}], "event_type": "book", "last_trade_price": ""}, {"market": "0xb8d1c3c2cbba18e247a379454e72d31129863a4dc123736926c6d991599a81b2", "asset_id": "65423010509110378012139184005666383471785256194188331590421933980074567091246", "timestamp": "1769384369995", "hash": "0bf64f2a94828686a669f5443629a2737d019810", "bids": [{"price": "0.001", "size": "11269.73"}], "asks": [{"price": "0.999", "size": "3104315"}, {"price": "0.998", "size": "257.48"}, {"price": "0.997", "size": "400"}, {"price": "0.996", "size": "20300"}, {"price": "0.995", "size": "5.93"}, {"price": "0.994", "size": "200"}, {"price": "0.99", "size": "10"}, {"price": "0.989", "size": "5.73"}, {"price": "0.98", "size": "300"}, {"price": "0.969", "size": "921.19"}, {"price": "0.968", "size": "7.95"}, {"price": "0.95", "size": "30"}, {"price": "0.949", "size": "39"}, {"price": "0.94", "size": "700"}, {"price": "0.939", "size": "112.41"}, {"price": "0.913", "size": "78.81"}, {"price": "0.912", "size": "5.13"}, {"price": "0.89", "size": "200"}, {"price": "0.877", "size": "473"}, {"price": "0.875", "size": "8"}, {"price": "0.865", "size": "50.79"}, {"price": "0.864", "size": "14"}, {"price": "0.795", "size": "33.44"}, {"price": "0.794", "size": "5.73"}, {"price": "0.477", "size": "136"}, {"price": "0.475", "size": "13.06"}, {"price": "0.474", "size": "10"}, {"price": "0.397", "size": "11.37"}, {"price": "0.395", "size": "25"}, {"price": "0.277", "size": "148"}, {"price": "0.276", "size": "20"}, {"price": "0.177", "size": "146"}, {"price": "0.14", "size": "500"}, {"price": "0.077", "size": "1045"}, {"price": "0.076", "size": "977.4"}, {"price": "0.024", "size": "340"}, {"price": "0.004", "size": "43.27"}, {"price": "0.003", "size": "311.63"}, {"price": "0.002", "size": "200"}], "event_type": "book", "last_trade_price": ""}, {"market": "0x06c4ac6a22e3c924d72a461148ebb4240ebb55e8ddeb962a7059927b985fc08f", "asset_id": "95452991186756085393543260434357806029751110136260308188904897281346485399255", "timestamp": "1769384372333", "hash": "74442d2d5512c25ee1015874c874238c29f3d3f8", "bids": [{"price": "0.001", "size": "2752.01"}, {"price": "0.002", "size": "250"}, {"price": "0.003", "size": "400"}, {"price": "0.004", "size": "8.67"}, {"price": "0.006", "size": "200"}, {"price": "0.01", "size": "310010"}, {"price": "0.011", "size": "5.3"}, {"price": "0.024", "size": "985.71"}, {"price": "0.025", "size": "6.31"}, {"price": "0.05", "size": "30"}, {"price": "0.051", "size": "39"}, {"price": "0.058", "size": "618.22"}, {"price": "0.059", "size": "8.05"}, {"price": "0.08", "size": "8700"}, {"price": "0.082", "size": "42"}, {"price": "0.083", "size": "82.61"}, {"price": "0.177", "size": "38.74"}, {"price": "0.178", "size": "7.07"}, {"price": "0.223", "size": "143"}, {"price": "0.234", "size": "29.3"}, {"price": "0.235", "size": "10"}, {"price": "0.523", "size": "116"}, {"price": "0.524", "size": "13.08"}, {"price": "0.61", "size": "741"}, {"price": "0.611", "size": "52"}, {"price": "0.613", "size": "5"}, {"price": "0.615", "size": "85"}, {"price": "0.616", "size": "20"}, {"price": "0.667", "size": "10.28"}, {"price": "0.668", "size": "20"}, {"price": "0.823", "size": "108"}, {"price": "0.847", "size": "13.33"}, {"price": "0.923", "size": "569"}, {"price": "0.936", "size": "340"}, {"price": "0.997", "size": "179.99"}, {"price": "0.998", "size": "948.64"}], "asks": [{"price": "0.999", "size": "11377.86"}], "event_type": "book", "last_trade_price": ""}, {"market": "0x7499cb05b10df8f07a0cd31417e9f48ece68ef3bd13a8197c12487a3630d5017", "asset_id": "59082279422583893955172337914215783274419872681224661612134457925091424048864", "timestamp": "1769383999186", "hash": "2adc1f422dd99f4d25fad6810a81998cc3b47b9f", "bids": [{"price": "0.001", "size": "4247"}, {"price": "0.002", "size": "250"}, {"price": "0.003", "size": "406.43"}, {"price": "0.006", "size": "200"}, {"price": "0.007", "size": "5.48"}, {"price": "0.01", "size": "10"}, {"price": "0.011", "size": "5.93"}, {"price": "0.019", "size": "19500"}, {"price": "0.02", "size": "20"}, {"price": "0.035", "size": "974.28"}, {"price": "0.036", "size": "8.01"}, {"price": "0.05", "size": "30"}, {"price": "0.051", "size": "39"}, {"price": "0.052", "size": "684.61"}, {"price": "0.082", "size": "42"}, {"price": "0.103", "size": "212.2"}, {"price": "0.104", "size": "15.18"}, {"price": "0.523", "size": "78"}, {"price": "0.574", "size": "501"}, {"price": "0.575", "size": "16.69"}, {"price": "0.63", "size": "15.23"}, {"price": "0.636", "size": "10"}, {"price": "0.637", "size": "20"}, {"price": "0.638", "size": "25"}, {"price": "0.639", "size": "20"}, {"price": "0.823", "size": "5"}, {"price": "0.923", "size": "579"}, {"price": "0.943", "size": "627.31"}, {"price": "0.952", "size": "340"}, {"price": "0.953", "size": "563.84"}, {"price": "0.996", "size": "30.58"}, {"price": "0.997", "size": "173.3"}, {"price": "0.998", "size": "426.66"}], "asks": [{"price": "0.999", "size": "4880"}], "event_type": "book", "last_trade_price": ""}, {"market": "0x60576953f8f7ecb78bf8c5a7d287d89de0dd4b9c4085a7d7eea7732e710c17ad", "asset_id": "105337146987487623394311401596770884763233250525561744450199908673158670881245", "timestamp": "1769384329145", "hash": "528d518d8c8604d1924fdb0ac84a4eb0527ef22d", "bids": [{"price": "0.001", "size": "4252.04"}, {"price": "0.002", "size": "250"}, {"price": "0.003", "size": "400"}, {"price": "0.004", "size": "8.67"}, {"price": "0.006", "size": "200"}, {"price": "0.01", "size": "10"}, {"price": "0.011", "size": "5.3"}, {"price": "0.032", "size": "914.28"}, {"price": "0.033", "size": "5.21"}, {"price": "0.048", "size": "8700"}, {"price": "0.05", "size": "30"}, {"price": "0.051", "size": "39"}, {"price": "0.06", "size": "700"}, {"price": "0.069", "size": "99.37"}, {"price": "0.07", "size": "6.36"}, {"price": "0.11", "size": "300"}, {"price": "0.111", "size": "61.77"}, {"price": "0.155", "size": "31"}, {"price": "0.179", "size": "38.3"}, {"price": "0.18", "size": "38.09"}, {"price": "0.181", "size": "7.04"}, {"price": "0.523", "size": "136"}, {"price": "0.525", "size": "425"}, {"price": "0.526", "size": "190"}, {"price": "0.527", "size": "13.01"}, {"price": "0.546", "size": "5"}, {"price": "0.641", "size": "10.69"}, {"price": "0.643", "size": "20"}, {"price": "0.644", "size": "25"}, {"price": "0.723", "size": "13"}, {"price": "0.727", "size": "10"}, {"price": "0.728", "size": "20"}, {"price": "0.823", "size": "5"}, {"price": "0.847", "size": "13.33"}, {"price": "0.923", "size": "539"}, {"price": "0.995", "size": "9"}, {"price": "0.997", "size": "38.17"}, {"price": "0.998", "size": "1330.11"}], "asks": [{"price": "0.999", "size": "1220"}], "event_type": "book", "last_trade_price": ""}, {"market": "0xd175d5454046b2a54c76de7ea2f91f3f179ee2460159ea70139c75c1092ab181", "asset_id": "31953493273605091846063767682320550763614773521778373247731663047594886040157", "timestamp": "1769384372333", "hash": "d45ace6ff4ac8cd6a645d424f4894de7737604df", "bids": [{"price": "0.01", "size": "1210"}, {"price": "0.02", "size": "1250"}, {"price": "0.05", "size": "510"}, {"price": "0.06", "size": "33"}, {"price": "0.13", "size": "506.92"}, {"price": "0.16", "size": "137"}, {"price": "0.52", "size": "121"}, {"price": "0.55", "size": "300"}, {"price": "0.56", "size": "100"}, {"price": "0.57", "size": "242.48"}, {"price": "0.77", "size": "20"}], "asks": [{"price": "0.99", "size": "310060.76"}, {"price": "0.98", "size": "3885.03"}, {"price": "0.97", "size": "2065"}, {"price": "0.96", "size": "11.39"}, {"price": "0.94", "size": "562"}, {"price": "0.93", "size": "355"}, {"price": "0.92", "size": "13.24"}, {"price": "0.9", "size": "762.88"}, {"price": "0.89", "size": "10.88"}, {"price": "0.88", "size": "6.86"}, {"price": "0.78", "size": "124.61"}], "event_type": "book", "last_trade_price": "0.780"}, {"market": "0x71eb9d9a28332fd88fd5a6fbf5b2e6bb771c195a23f2c94eca1f0e89f1ef16c2", "asset_id": "16600603372891129785545475539816293751986824969962802244003716447936317022721", "timestamp": "1769384329289", "hash": "988f85b8301fbeb23a4a1a78b65fae11b8ac5aac", "bids": [{"price": "0.001", "size": "3114315"}, {"price": "0.002", "size": "257.48"}, {"price": "0.003", "size": "400"}, {"price": "0.004", "size": "20000"}, {"price": "0.005", "size": "5.93"}, {"price": "0.006", "size": "200"}, {"price": "0.01", "size": "10"}, {"price": "0.011", "size": "5.29"}, {"price": "0.014", "size": "18300"}, {"price": "0.02", "size": "300"}, {"price": "0.026", "size": "963.73"}, {"price": "0.027", "size": "6.18"}, {"price": "0.05", "size": "30"}, {"price": "0.051", "size": "39"}, {"price": "0.06", "size": "700"}, {"price": "0.062", "size": "110.59"}, {"price": "0.063", "size": "6.6"}, {"price": "0.11", "size": "300"}, {"price": "0.133", "size": "30"}, {"price": "0.135", "size": "14"}, {"price": "0.136", "size": "50.42"}, {"price": "0.165", "size": "41.55"}, {"price": "0.166", "size": "7.88"}, {"price": "0.223", "size": "91"}, {"price": "0.224", "size": "30.61"}, {"price": "0.383", "size": "15.75"}, {"price": "0.384", "size": "17.85"}, {"price": "0.523", "size": "120"}, {"price": "0.525", "size": "89.25"}, {"price": "0.567", "size": "12.09"}, {"price": "0.568", "size": "25"}, {"price": "0.569", "size": "158"}, {"price": "0.57", "size": "350"}, {"price": "0.759", "size": "10"}, {"price": "0.76", "size": "20"}, {"price": "0.761", "size": "20"}, {"price": "0.9", "size": "934.34"}, {"price": "0.923", "size": "1044"}, {"price": "0.936", "size": "223.05"}, {"price": "0.987", "size": "15.75"}, {"price": "0.989", "size": "35"}, {"price": "0.99", "size": "89.25"}], "asks": [{"price": "0.999", "size": "44.04"}, {"price": "0.998", "size": "5"}, {"price": "0.997", "size": "5"}, {"price": "0.995", "size": "1352"}, {"price": "0.994", "size": "240"}], "event_type": "book", "last_trade_price": ""}, {"market": "0x94959859bde2c37abdd09ead0a77cc8befbbbde89715345620ce676a01b533a5", "asset_id": "67061927838706034299638100598272162888723579698947118337930104329771332123706", "timestamp": "1769383998076", "hash": "12635ada7243319d90bb4514c0be3d53e33164da", "bids": [{"price": "0.001", "size": "3052.01"}, {"price": "0.002", "size": "250"}, {"price": "0.003", "size": "400"}, {"price": "0.004", "size": "8.67"}, {"price": "0.006", "size": "200"}, {"price": "0.01", "size": "10"}, {"price": "0.011", "size": "5.3"}, {"price": "0.02", "size": "1000"}, {"price": "0.03", "size": "200"}, {"price": "0.031", "size": "8.09"}, {"price": "0.05", "size": "30"}, {"price": "0.051", "size": "39"}, {"price": "0.06", "size": "700"}, {"price": "0.07", "size": "57"}, {"price": "0.071", "size": "84.5"}, {"price": "0.085", "size": "70.58"}, {"price": "0.086", "size": "5.62"}, {"price": "0.11", "size": "300"}, {"price": "0.122", "size": "16"}, {"price": "0.123", "size": "48.78"}, {"price": "0.212", "size": "28.3"}, {"price": "0.213", "size": "5.43"}, {"price": "0.223", "size": "6"}, {"price": "0.224", "size": "26.78"}, {"price": "0.523", "size": "120"}, {"price": "0.581", "size": "611"}, {"price": "0.582", "size": "10.3"}, {"price": "0.623", "size": "9.63"}, {"price": "0.625", "size": "10"}, {"price": "0.627", "size": "45"}, {"price": "0.628", "size": "20"}, {"price": "0.823", "size": "5"}, {"price": "0.86", "size": "375"}, {"price": "0.923", "size": "1045"}, {"price": "0.997", "size": "88.55"}, {"price": "0.998", "size": "951.47"}], "asks": [{"price": "0.999", "size": "1301.76"}], "event_type": "book", "last_trade_price": "0.002"}, {"market": "0x50fa9155b39b1f6d3041ad01296611ff7fcd7e06accc6dba1ea4458f95e6e637", "asset_id": "13555099753310315836647270533686894971487275612829883232907522152970188644136", "timestamp": "1769383999186", "hash": "a1eb68ec0317072387cbdadbc3197ba3b689db21", "bids": [{"price": "0.001", "size": "3104315.02"}, {"price": "0.002", "size": "257.42"}, {"price": "0.003", "size": "400"}, {"price": "0.004", "size": "20000"}, {"price": "0.005", "size": "5.88"}, {"price": "0.006", "size": "200"}, {"price": "0.01", "size": "10"}, {"price": "0.011", "size": "7.56"}, {"price": "0.024", "size": "25000"}, {"price": "0.03", "size": "266.66"}, {"price": "0.031", "size": "5.32"}, {"price": "0.05", "size": "30"}, {"price": "0.051", "size": "39"}, {"price": "0.06", "size": "700"}, {"price": "0.066", "size": "121.21"}, {"price": "0.067", "size": "5.21"}, {"price": "0.11", "size": "300"}, {"price": "0.112", "size": "36"}, {"price": "0.113", "size": "70.79"}, {"price": "0.152", "size": "52.63"}, {"price": "0.153", "size": "8.84"}, {"price": "0.505", "size": "1765"}, {"price": "0.523", "size": "106"}, {"price": "0.581", "size": "382"}, {"price": "0.594", "size": "5"}, {"price": "0.595", "size": "13.44"}, {"price": "0.596", "size": "25"}, {"price": "0.654", "size": "12.23"}, {"price": "0.656", "size": "10"}, {"price": "0.658", "size": "20"}, {"price": "0.659", "size": "20"}, {"price": "0.856", "size": "1042.35"}, {"price": "0.995", "size": "412.15"}, {"price": "0.996", "size": "148.6"}], "asks": [{"price": "0.999", "size": "62"}, {"price": "0.998", "size": "5"}, {"price": "0.997", "size": "5"}], "event_type": "book", "last_trade_price": ""}, {"market": "0x0efaf81024bc4cefd1c35a5b53ebe9f441fa1b7774c1d086374fc5dcc35be042", "asset_id": "113538140807961528328992033738846637513234963111319913499967108133450953646650", "timestamp": "1769384370062", "hash": "20b053477cfe647aa189c73b7f033cd228779131", "bids": [{"price": "0.001", "size": "10163"}, {"price": "0.002", "size": "450"}, {"price": "0.003", "size": "293"}], "asks": [{"price": "0.999", "size": "2747"}, {"price": "0.998", "size": "250"}, {"price": "0.997", "size": "406.63"}, {"price": "0.994", "size": "200"}, {"price": "0.993", "size": "9.77"}, {"price": "0.99", "size": "310010"}, {"price": "0.98", "size": "8600"}, {"price": "0.979", "size": "9.03"}, {"price": "0.965", "size": "171.42"}, {"price": "0.95", "size": "30"}, {"price": "0.949", "size": "39"}, {"price": "0.94", "size": "700"}, {"price": "0.939", "size": "98.36"}, {"price": "0.938", "size": "8.46"}, {"price": "0.91", "size": "66.66"}, {"price": "0.89", "size": "300"}, {"price": "0.889", "size": "54.05"}, {"price": "0.81", "size": "2400"}, {"price": "0.808", "size": "17"}, {"price": "0.804", "size": "30.61"}, {"price": "0.802", "size": "10"}, {"price": "0.801", "size": "5.96"}, {"price": "0.778", "size": "27.02"}, {"price": "0.477", "size": "116"}, {"price": "0.468", "size": "475"}, {"price": "0.464", "size": "11.19"}, {"price": "0.463", "size": "55"}, {"price": "0.356", "size": "9.31"}, {"price": "0.355", "size": "20"}, {"price": "0.177", "size": "108"}, {"price": "0.08", "size": "48.93"}, {"price": "0.077", "size": "1034"}, {"price": "0.074", "size": "1333.16"}, {"price": "0.073", "size": "89.35"}], "event_type": "book", "last_trade_price": ""}, {"market": "0x31967ab350da8f760c547a62ce495f63f04c7402ea2bc291f7358d6aa367fdd8", "asset_id": "48096461703828524256164307708005083326532171684035677911193083899587188981253", "timestamp": "1769384417602", "hash": "9d3543dc2f469cf5461f6f2cbcf40ee990a699eb", "bids": [{"price": "0.001", "size": "20056.31"}, {"price": "0.002", "size": "200"}], "asks": [{"price": "0.999", "size": "3104211"}, {"price": "0.998", "size": "257.48"}, {"price": "0.997", "size": "400"}, {"price": "0.996", "size": "20000"}, {"price": "0.995", "size": "6.91"}, {"price": "0.994", "size": "200"}, {"price": "0.99", "size": "23"}, {"price": "0.989", "size": "17.97"}, {"price": "0.966", "size": "16700"}, {"price": "0.965", "size": "228.57"}, {"price": "0.95", "size": "30"}, {"price": "0.949", "size": "39"}, {"price": "0.942", "size": "637.93"}, {"price": "0.941", "size": "10.1"}, {"price": "0.902", "size": "581.63"}, {"price": "0.901", "size": "20"}, {"price": "0.9", "size": "10"}, {"price": "0.789", "size": "37.91"}, {"price": "0.788", "size": "5.43"}, {"price": "0.477", "size": "136"}, {"price": "0.475", "size": "291"}, {"price": "0.438", "size": "14.23"}, {"price": "0.436", "size": "25"}, {"price": "0.435", "size": "20"}, {"price": "0.302", "size": "11.46"}, {"price": "0.3", "size": "10"}, {"price": "0.299", "size": "20"}, {"price": "0.177", "size": "5"}, {"price": "0.153", "size": "13.33"}, {"price": "0.093", "size": "932.12"}, {"price": "0.069", "size": "340"}, {"price": "0.064", "size": "30"}, {"price": "0.063", "size": "45"}], "event_type": "book", "last_trade_price": ""}, {"market": "0x94959859bde2c37abdd09ead0a77cc8befbbbde89715345620ce676a01b533a5", "asset_id": "75615194763825570253105529908925735637330457129633888605679989963612334234091", "timestamp": "1769383998076", "hash": "893b4140a27adfd7441b3bf5562759d352cdd175", "bids": [{"price": "0.001", "size": "1301.76"}], "asks": [{"price": "0.999", "size": "3052.01"}, {"price": "0.998", "size": "250"}, {"price": "0.997", "size": "400"}, {"price": "0.996", "size": "8.67"}, {"price": "0.994", "size": "200"}, {"price": "0.99", "size": "10"}, {"price": "0.989", "size": "5.3"}, {"price": "0.98", "size": "1000"}, {"price": "0.97", "size": "200"}, {"price": "0.969", "size": "8.09"}, {"price": "0.95", "size": "30"}, {"price": "0.949", "size": "39"}, {"price": "0.94", "size": "700"}, {"price": "0.93", "size": "57"}, {"price": "0.929", "size": "84.5"}, {"price": "0.915", "size": "70.58"}, {"price": "0.914", "size": "5.62"}, {"price": "0.89", "size": "300"}, {"price": "0.878", "size": "16"}, {"price": "0.877", "size": "48.78"}, {"price": "0.788", "size": "28.3"}, {"price": "0.787", "size": "5.43"}, {"price": "0.777", "size": "6"}, {"price": "0.776", "size": "26.78"}, {"price": "0.477", "size": "120"}, {"price": "0.419", "size": "611"}, {"price": "0.418", "size": "10.3"}, {"price": "0.377", "size": "9.63"}, {"price": "0.375", "size": "10"}, {"price": "0.373", "size": "45"}, {"price": "0.372", "size": "20"}, {"price": "0.177", "size": "5"}, {"price": "0.14", "size": "375"}, {"price": "0.077", "size": "1045"}, {"price": "0.003", "size": "88.55"}, {"price": "0.002", "size": "951.47"}], "event_type": "book", "last_trade_price": "0.002"}, {"market": "0xec222c4c9935b37c2c563f34eb66715fb01f88a3a399830e83e4221153adfe6a", "asset_id": "45031179555990916139678136127586800287983215899550524176073382735544314971535", "timestamp": "1769384385727", "hash": "c4e641c81ee130090c5366b09860faf56b61dd77", "bids": [{"price": "0.001", "size": "1104211.04"}, {"price": "0.002", "size": "257.54"}, {"price": "0.003", "size": "400"}, {"price": "0.004", "size": "20300"}, {"price": "0.005", "size": "5.98"}, {"price": "0.006", "size": "200"}, {"price": "0.01", "size": "23"}, {"price": "0.011", "size": "10.58"}, {"price": "0.037", "size": "916.21"}, {"price": "0.038", "size": "5.9"}, {"price": "0.05", "size": "30"}, {"price": "0.051", "size": "39"}, {"price": "0.052", "size": "653.84"}, {"price": "0.08", "size": "300"}, {"price": "0.086", "size": "93.02"}, {"price": "0.087", "size": "5.72"}, {"price": "0.215", "size": "2141"}, {"price": "0.216", "size": "250"}, {"price": "0.217", "size": "5.12"}, {"price": "0.234", "size": "8"}, {"price": "0.235", "size": "34.04"}, {"price": "0.523", "size": "136"}, {"price": "0.524", "size": "576"}, {"price": "0.599", "size": "13.35"}, {"price": "0.606", "size": "13.2"}, {"price": "0.614", "size": "25"}, {"price": "0.616", "size": "10"}, {"price": "0.617", "size": "20"}, {"price": "0.923", "size": "689"}, {"price": "0.925", "size": "340"}, {"price": "0.932", "size": "999.98"}, {"price": "0.937", "size": "368.86"}], "asks": [{"price": "0.999", "size": "34"}, {"price": "0.998", "size": "255"}, {"price": "0.997", "size": "5"}], "event_type": "book", "last_trade_price": ""}, {"market": "0xce465bdf15fd274b3d6bd5e4c543fb047f5bc09e306d9a70dd9cf3b207f7a547", "asset_id": "91363015704893492073568830399375035872276923274131092245805554034196213248667", "timestamp": "1769384369995", "hash": "80abef24d77f53533636a2bd4e01e7c3abb1a9d2", "bids": [{"price": "0.001", "size": "1326"}, {"price": "0.002", "size": "5"}], "asks": [{"price": "0.999", "size": "2784.01"}, {"price": "0.998", "size": "250"}, {"price": "0.997", "size": "400"}, {"price": "0.996", "size": "8.68"}, {"price": "0.994", "size": "200"}, {"price": "0.99", "size": "310010"}, {"price": "0.989", "size": "5.3"}, {"price": "0.981", "size": "24300"}, {"price": "0.98", "size": "300"}, {"price": "0.968", "size": "950"}, {"price": "0.967", "size": "5.61"}, {"price": "0.95", "size": "30"}, {"price": "0.949", "size": "39"}, {"price": "0.94", "size": "700"}, {"price": "0.928", "size": "111.11"}, {"price": "0.927", "size": "5.17"}, {"price": "0.89", "size": "200"}, {"price": "0.889", "size": "200"}, {"price": "0.888", "size": "71.42"}, {"price": "0.838", "size": "12"}, {"price": "0.835", "size": "48.48"}, {"price": "0.834", "size": "8"}, {"price": "0.477", "size": "136"}, {"price": "0.476", "size": "10"}, {"price": "0.429", "size": "52"}, {"price": "0.428", "size": "13.98"}, {"price": "0.39", "size": "13.11"}, {"price": "0.388", "size": "25"}, {"price": "0.265", "size": "214.4"}, {"price": "0.264", "size": "20"}, {"price": "0.177", "size": "108"}, {"price": "0.077", "size": "1045"}, {"price": "0.076", "size": "499"}, {"price": "0.005", "size": "36.25"}, {"price": "0.004", "size": "221.42"}, {"price": "0.003", "size": "147.76"}], "event_type": "book", "last_trade_price": ""}, {"market": "0x3bda95c399f34f112afeef82233601d2c7b39b732492868d4dd9fb8c06f44c4a", "asset_id": "107188258966978621463100332893906494250781495859540494974336129482194560136715", "timestamp": "1769384369995", "hash": "487a69cc300cf33385c20d0d86f7332a5b088996", "bids": [{"price": "0.001", "size": "1220"}], "asks": [{"price": "0.999", "size": "2762.99"}, {"price": "0.998", "size": "250"}, {"price": "0.997", "size": "400"}, {"price": "0.996", "size": "8.85"}, {"price": "0.994", "size": "200"}, {"price": "0.99", "size": "110010"}, {"price": "0.989", "size": "22.45"}, {"price": "0.966", "size": "20000"}, {"price": "0.965", "size": "274.28"}, {"price": "0.95", "size": "30"}, {"price": "0.949", "size": "39"}, {"price": "0.94", "size": "200"}, {"price": "0.938", "size": "750"}, {"price": "0.937", "size": "5.29"}, {"price": "0.935", "size": "147.69"}, {"price": "0.89", "size": "300"}, {"price": "0.858", "size": "14"}, {"price": "0.856", "size": "66.66"}, {"price": "0.855", "size": "9.44"}, {"price": "0.49", "size": "1111"}, {"price": "0.477", "size": "136"}, {"price": "0.476", "size": "18.32"}, {"price": "0.4", "size": "46"}, {"price": "0.392", "size": "15.78"}, {"price": "0.39", "size": "25"}, {"price": "0.277", "size": "149"}, {"price": "0.273", "size": "10"}, {"price": "0.272", "size": "20"}, {"price": "0.177", "size": "5"}, {"price": "0.153", "size": "13.33"}, {"price": "0.1", "size": "999.95"}, {"price": "0.077", "size": "941"}, {"price": "0.003", "size": "73.02"}, {"price": "0.002", "size": "555.68"}], "event_type": "book", "last_trade_price": ""}, {"market": "0xb498db5296d2aaa4d26db3c6b6dc3a80c5924a9ea83b6b4f2f18c6f12726d747", "asset_id": "80044434770818464329551993094327116294077942468264664736091814178350906286521", "timestamp": "1769384114263", "hash": "d410029f0e3c01aa8b010ed3e95ad30dc147801d", "bids": [{"price": "0.001", "size": "4303"}, {"price": "0.002", "size": "250"}, {"price": "0.003", "size": "400"}, {"price": "0.004", "size": "8.59"}, {"price": "0.006", "size": "200"}, {"price": "0.01", "size": "10"}, {"price": "0.011", "size": "5.25"}, {"price": "0.022", "size": "1363.63"}, {"price": "0.023", "size": "7.95"}, {"price": "0.05", "size": "30"}, {"price": "0.051", "size": "39"}, {"price": "0.06", "size": "700"}, {"price": "0.062", "size": "129.03"}, {"price": "0.063", "size": "5.15"}, {"price": "0.11", "size": "300"}, {"price": "0.112", "size": "30"}, {"price": "0.142", "size": "70.33"}, {"price": "0.143", "size": "9.72"}, {"price": "0.223", "size": "15"}, {"price": "0.224", "size": "35.71"}, {"price": "0.523", "size": "136"}, {"price": "0.537", "size": "365"}, {"price": "0.543", "size": "14.73"}, {"price": "0.544", "size": "10"}, {"price": "0.609", "size": "25"}, {"price": "0.61", "size": "20"}, {"price": "0.669", "size": "11.95"}, {"price": "0.67", "size": "20"}, {"price": "0.823", "size": "236"}, {"price": "0.923", "size": "1045"}, {"price": "0.925", "size": "340"}, {"price": "0.995", "size": "12"}, {"price": "0.996", "size": "307.78"}, {"price": "0.998", "size": "999.97"}], "asks": [{"price": "0.999", "size": "1431.11"}], "event_type": "book", "last_trade_price": "0.001"}]}
{"_local_timestamp": "2026-01-25T23:40:44.140610+00:00", "data": {"market": "0xec222c4c9935b37c2c563f34eb66715fb01f88a3a399830e83e4221153adfe6a", "price_changes": [{"asset_id": "72384687038182433689874327261984956544997236795314184718224091418094356344966", "price": "0.063", "size": "0", "side": "SELL", "hash": "e8c5aadf0cf4d8c7931c125d750d137585c2487d", "best_bid": "0.003", "best_ask": "0.068"}, {"asset_id": "45031179555990916139678136127586800287983215899550524176073382735544314971535", "price": "0.937", "size": "0", "side": "BUY", "hash": "fc0b9a7cde955158654372967b8767ad4eb851f4", "best_bid": "0.932", "best_ask": "0.997"}], "timestamp": "1769384444044", "event_type": "price_change"}}
{"_local_timestamp": "2026-01-25T23:40:44.410045+00:00", "data": {"market": "0x31967ab350da8f760c547a62ce495f63f04c7402ea2bc291f7358d6aa367fdd8", "price_changes": [{"asset_id": "48096461703828524256164307708005083326532171684035677911193083899587188981253", "price": "0.064", "size": "0", "side": "SELL", "hash": "56ad7307562a3608215ab14a8e8e20430e4e26c6", "best_bid": "0.002", "best_ask": "0.063"}, {"asset_id": "74574612697917499641784436195980418240322600911590628796653263539397328153034", "price": "0.936", "size": "0", "side": "BUY", "hash": "34c195e360cb1b888aa12a51fffb36ebec8b60c8", "best_bid": "0.937", "best_ask": "0.998"}], "timestamp": "1769384444341", "event_type": "price_change"}}
{"_local_timestamp": "2026-01-25T23:40:45.181099+00:00", "data": {"market": "0xec222c4c9935b37c2c563f34eb66715fb01f88a3a399830e83e4221153adfe6a", "price_changes": [{"asset_id": "72384687038182433689874327261984956544997236795314184718224091418094356344966", "price": "0.067", "size": "368.86", "side": "SELL", "hash": "317687245e40727dfa507a0ddf25bdb04b4bdd79", "best_bid": "0.003", "best_ask": "0.067"}, {"asset_id": "45031179555990916139678136127586800287983215899550524176073382735544314971535", "price": "0.933", "size": "368.86", "side": "BUY", "hash": "ca22fb285dd6213248dd72e738b6b7ab334b8bbd", "best_bid": "0.933", "best_ask": "0.997"}], "timestamp": "1769384445116", "event_type": "price_change"}}
{"_local_timestamp": "2026-01-25T23:40:45.484124+00:00", "data": {"market": "0x31967ab350da8f760c547a62ce495f63f04c7402ea2bc291f7358d6aa367fdd8", "price_changes": [{"asset_id": "48096461703828524256164307708005083326532171684035677911193083899587188981253", "price": "0.062", "size": "30", "side": "SELL", "hash": "514e17666e4a3f69b4c262aadf0a37c2e0bde8c1", "best_bid": "0.002", "best_ask": "0.062"}, {"asset_id": "74574612697917499641784436195980418240322600911590628796653263539397328153034", "price": "0.938", "size": "30", "side": "BUY", "hash": "40f27d25281366a28e40e7825a60e8a15bc2ab4a", "best_bid": "0.938", "best_ask": "0.998"}], "timestamp": "1769384445413", "event_type": "price_change"}}
{"_local_timestamp": "2026-01-25T23:42:49.065693+00:00", "data": {"market": "0xce465bdf15fd274b3d6bd5e4c543fb047f5bc09e306d9a70dd9cf3b207f7a547", "price_changes": [{"asset_id": "3990566517926198774760739919993523333580985526226102598439634813084268870587", "price": "0.162", "size": "0", "side": "BUY", "hash": "3a0beb4fa11928114e14726715c78da1feb5a824", "best_bid": "0.997", "best_ask": "0.998"}, {"asset_id": "91363015704893492073568830399375035872276923274131092245805554034196213248667", "price": "0.838", "size": "0", "side": "SELL", "hash": "22dcbc32be88e9f5e7fd7d79d177df9cb04e3c31", "best_bid": "0.002", "best_ask": "0.003"}], "timestamp": "1769384568948", "event_type": "price_change"}}
{"_local_timestamp": "2026-01-25T23:42:49.117410+00:00", "data": {"market": "0xce465bdf15fd274b3d6bd5e4c543fb047f5bc09e306d9a70dd9cf3b207f7a547", "price_changes": [{"asset_id": "3990566517926198774760739919993523333580985526226102598439634813084268870587", "price": "0.167", "size": "11", "side": "BUY", "hash": "2eaf61739b853f930209798c0b0e2d5a1893e342", "best_bid": "0.997", "best_ask": "0.998"}, {"asset_id": "91363015704893492073568830399375035872276923274131092245805554034196213248667", "price": "0.833", "size": "11", "side": "SELL", "hash": "826aca6aa918b606e951bcf8d4668eb61dd3c9bf", "best_bid": "0.002", "best_ask": "0.003"}], "timestamp": "1769384568998", "event_type": "price_change"}}
{"_local_timestamp": "2026-01-25T23:42:49.163397+00:00", "data": {"market": "0xb3f0b0a92040f41a6aca44e3f909e0236c2687ad29ca77cfd3710c83071b74c9", "price_changes": [{"asset_id": "60676933420233144798971210692068617567292894076124499641040029783755014286821", "price": "0.246", "size": "25", "side": "BUY", "hash": "b2c2836bf8898cc76b16789dc11a34b1206fc2ca", "best_bid": "0.996", "best_ask": "0.998"}, {"asset_id": "104582508148424115897511334519834707085901645295166805533084841423912878555712", "price": "0.754", "size": "25", "side": "SELL", "hash": "4e5fc0c54081655ed7bc57b601797edf49173897", "best_bid": "0.002", "best_ask": "0.004"}], "timestamp": "1769384569006", "event_type": "price_change"}}
{"_local_timestamp": "2026-01-25T23:42:49.175696+00:00", "data": {"market": "0x3bda95c399f34f112afeef82233601d2c7b39b732492868d4dd9fb8c06f44c4a", "price_changes": [{"asset_id": "103105445559412650197228684416234707898134960652304619455901950120717295228302", "price": "0.611", "size": "20", "side": "BUY", "hash": "c86a6a7fcecda8fed4b70a36e60a0aadeff1556b", "best_bid": "0.998", "best_ask": "0.999"}, {"asset_id": "107188258966978621463100332893906494250781495859540494974336129482194560136715", "price": "0.389", "size": "20", "side": "SELL", "hash": "ebaaad4aa354b9b27eb394c02946cae0efa00def", "best_bid": "0.001", "best_ask": "0.002"}], "timestamp": "1769384569044", "event_type": "price_change"}}
{"_local_timestamp": "2026-01-25T23:42:49.176559+00:00", "data": {"market": "0x0b4d4807d9ada3da32f66bd906f7c79b931e836338ea9127840a22357dc80d6b", "price_changes": [{"asset_id": "28340620202432180095608171388765060781029516708678051694406697447993348774238", "price": "0.568", "size": "20", "side": "BUY", "hash": "5f6f38217374ab76ed83f9a6e4eec670c394d983", "best_bid": "0.986", "best_ask": "0.994"}, {"asset_id": "80365173313895983605325248892162569953987774602633505688541422929067192725254", "price": "0.432", "size": "20", "side": "SELL", "hash": "9e6bb51d5ee3f73dcd2d7f685c0b91990bc30fef", "best_bid": "0.006", "best_ask": "0.014"}], "timestamp": "1769384569044", "event_type": "price_change"}}
{"_local_timestamp": "2026-01-25T23:42:49.177271+00:00", "data": {"market": "0xce465bdf15fd274b3d6bd5e4c543fb047f5bc09e306d9a70dd9cf3b207f7a547", "price_changes": [{"asset_id": "3990566517926198774760739919993523333580985526226102598439634813084268870587", "price": "0.613", "size": "20", "side": "BUY", "hash": "62bf03b288594feab5321c36fc8e5ec5cc52f0e7", "best_bid": "0.997", "best_ask": "0.998"}, {"asset_id": "91363015704893492073568830399375035872276923274131092245805554034196213248667", "price": "0.387", "size": "20", "side": "SELL", "hash": "5c61ab711e5f51141271e1e245881284c90dc8be", "best_bid": "0.002", "best_ask": "0.003"}], "timestamp": "1769384569044", "event_type": "price_change"}}
{"_local_timestamp": "2026-01-25T23:42:49.177983+00:00", "data": {"market": "0xa62558c07dee376f7903e95977b10c13544d3546eeae6c98130839753e093979", "price_changes": [{"asset_id": "35970432242453970638378005355807025798529538734302331296289043262158829773976", "price": "0.568", "size": "20", "side": "BUY", "hash": "2e066effff89b0cb5d39eace65973c808e7f15b9", "best_bid": "0.993", "best_ask": "0.997"}, {"asset_id": "72574656434993840186445307554025381492285372432846424590534736075839686478597", "price": "0.432", "size": "20", "side": "SELL", "hash": "415445c59850e4c7c046c5c32463fbd050f6d195", "best_bid": "0.003", "best_ask": "0.007"}], "timestamp": "1769384569044", "event_type": "price_change"}}
{"_local_timestamp": "2026-01-25T23:42:49.180009+00:00", "data": {"market": "0xec222c4c9935b37c2c563f34eb66715fb01f88a3a399830e83e4221153adfe6a", "price_changes": [{"asset_id": "45031179555990916139678136127586800287983215899550524176073382735544314971535", "price": "0.618", "size": "20", "side": "BUY", "hash": "b74163beeb31080aed15598407bc5f02a1582b5e", "best_bid": "0.933", "best_ask": "0.997"}, {"asset_id": "72384687038182433689874327261984956544997236795314184718224091418094356344966", "price": "0.382", "size": "20", "side": "SELL", "hash": "bdb63f511c406d427f86822d84a17fb795af79fc", "best_bid": "0.003", "best_ask": "0.067"}], "timestamp": "1769384569044", "event_type": "price_change"}}
{"_local_timestamp": "2026-01-25T23:42:49.180860+00:00", "data": {"market": "0xb8d1c3c2cbba18e247a379454e72d31129863a4dc123736926c6d991599a81b2", "price_changes": [{"asset_id": "21556602496211379227261801086635856748340201761487403620294012091632507009663", "price": "0.606", "size": "20", "side": "BUY", "hash": "ff59dfdddcf8d17d1c3d0e430e9d5da615de4d28", "best_bid": "0.998", "best_ask": "0.999"}, {"asset_id": "65423010509110378012139184005666383471785256194188331590421933980074567091246", "price": "0.394", "size": "20", "side": "SELL", "hash": "e67fa7aac1011894167be5141cb6b8c3c6e8e11a", "best_bid": "0.001", "best_ask": "0.002"}], "timestamp": "1769384569044", "event_type": "price_change"}}
{"_local_timestamp": "2026-01-25T23:42:49.214170+00:00", "data": {"market": "0x0b4d4807d9ada3da32f66bd906f7c79b931e836338ea9127840a22357dc80d6b", "price_changes": [{"asset_id": "28340620202432180095608171388765060781029516708678051694406697447993348774238", "price": "0.228", "size": "0", "side": "BUY", "hash": "28543e3e2fbde3f165a57fb5560bd7ef6e5e5010", "best_bid": "0.986", "best_ask": "0.994"}, {"asset_id": "80365173313895983605325248892162569953987774602633505688541422929067192725254", "price": "0.772", "size": "0", "side": "SELL", "hash": "12c5f84ebe2455fdb10d0979b4851d8352e9920b", "best_bid": "0.006", "best_ask": "0.014"}], "timestamp": "1769384569093", "event_type": "price_change"}}
{"_local_timestamp": "2026-01-25T23:42:49.259705+00:00", "data": {"market": "0xfdc15849e7bfbe9776d666108c2174047134547db0a014ec08605ca19b2c23c6", "price_changes": [{"asset_id": "3095574627925506845218316847738268742837051689528940940903139200105416861487", "price": "0.572", "size": "0", "side": "BUY", "hash": "72c0ff69d551a23125690d322eb543469fbd58d8", "best_bid": "0.998", "best_ask": "0.999"}, {"asset_id": "99611234567111832279381235616973424305850563087425365084149737464676375626231", "price": "0.428", "size": "0", "side": "SELL", "hash": "e50ab0ffeab14e42b125ed03278932620701908f", "best_bid": "0.001", "best_ask": "0.002"}], "timestamp": "1769384569137", "event_type": "price_change"}}
{"_local_timestamp": "2026-01-25T23:42:49.260630+00:00", "data": {"market": "0x31967ab350da8f760c547a62ce495f63f04c7402ea2bc291f7358d6aa367fdd8", "price_changes": [{"asset_id": "74574612697917499641784436195980418240322600911590628796653263539397328153034", "price": "0.565", "size": "0", "side": "BUY", "hash": "dbd2f9380a332bad55fc3e95e5b90724e677f440", "best_bid": "0.938", "best_ask": "0.998"}, {"asset_id": "48096461703828524256164307708005083326532171684035677911193083899587188981253", "price": "0.435", "size": "0", "side": "SELL", "hash": "0d7af9684605f61aeeb7834ec64f3a2e0dae8a44", "best_bid": "0.002", "best_ask": "0.062"}], "timestamp": "1769384569137", "event_type": "price_change"}}
{"_local_timestamp": "2026-01-25T23:42:49.295079+00:00", "data": {"market": "0x9ac58d2c51678463b45389b8d11d398a35f98bb9d99cd0a00e7994bf3d3bc106", "price_changes": [{"asset_id": "65530875443595461022055642853167256131284276704504495385262009209383645659674", "price": "0.61", "size": "0", "side": "BUY", "hash": "88114c7e2b9bd12a68a5eded4b1c2c7efe7268f5", "best_bid": "0.998", "best_ask": "0.999"}, {"asset_id": "54236330394497042999232692608534835969733131094441295535277724798165041782814", "price": "0.39", "size": "0", "side": "SELL", "hash": "2028709fb4fc44bc63c7eff5414d900ae08eb940", "best_bid": "0.001", "best_ask": "0.002"}], "timestamp": "1769384569137", "event_type": "price_change"}}
{"_local_timestamp": "2026-01-25T23:42:49.295885+00:00", "data": {"market": "0xb498db5296d2aaa4d26db3c6b6dc3a80c5924a9ea83b6b4f2f18c6f12726d747", "price_changes": [{"asset_id": "80044434770818464329551993094327116294077942468264664736091814178350906286521", "price": "0.61", "size": "0", "side": "BUY", "hash": "2664b9584b331d1c19797291bd372a9a38afd268", "best_bid": "0.998", "best_ask": "0.999"}, {"asset_id": "104760050366702563650209438348007452609559241951955868049242892063686019535745", "price": "0.39", "size": "0", "side": "SELL", "hash": "52731563e4f90ccf8b5615b437d71568f4436aa7", "best_bid": "0.001", "best_ask": "0.002"}], "timestamp": "1769384569137", "event_type": "price_change"}}
{"_local_timestamp": "2026-01-25T23:42:49.296570+00:00", "data": {"market": "0x388b017fa66c293566816b3f6253af6800ca69d6ab740ef019e5a69feacacf70", "price_changes": [{"asset_id": "68883925535903398159530799578268246684851592835366731124807972752959560431304", "price": "0.598", "size": "0", "side": "BUY", "hash": "680de0baf9f04a996122f925b93c93af9553e6a0", "best_bid": "0.938", "best_ask": "0.993"}, {"asset_id": "49541604524685067034733103567606780662654635021473570692999975492153111969210", "price": "0.402", "size": "0", "side": "SELL", "hash": "948e7b04f3b0533fe5635366529beb65f8c7c42b", "best_bid": "0.007", "best_ask": "0.062"}], "timestamp": "1769384569137", "event_type": "price_change"}}
{"_local_timestamp": "2026-01-25T23:42:49.297274+00:00", "data": {"market": "0x180cad29950aab8a08730c47e904416559aad814321d73854151be137756ad23", "price_changes": [{"asset_id": "98909251781140045508527043137413768725223127886868660293320661027969116726188", "price": "0.586", "size": "0", "side": "BUY", "hash": "87e69911d19fc1e77598ab41c00fb1290aa7e593", "best_bid": "0.998", "best_ask": "0.999"}, {"asset_id": "110987038017115137467642994123824186017997884207034130837015664299010910680722", "price": "0.414", "size": "0", "side": "SELL", "hash": "07b1beb5a0a0aafe3e1b5177c69e3e827b3afce1", "best_bid": "0.001", "best_ask": "0.002"}], "timestamp": "1769384569137", "event_type": "price_change"}}
{"_local_timestamp": "2026-01-25T23:42:49.347110+00:00", "data": {"market": "0x0b4d4807d9ada3da32f66bd906f7c79b931e836338ea9127840a22357dc80d6b", "price_changes": [{"asset_id": "28340620202432180095608171388765060781029516708678051694406697447993348774238", "price": "0.228", "size": "10", "side": "BUY", "hash": "60100dba410cdbe65586c920e137c129dd7c9be8", "best_bid": "0.986", "best_ask": "0.994"}, {"asset_id": "80365173313895983605325248892162569953987774602633505688541422929067192725254", "price": "0.772", "size": "10", "side": "SELL", "hash": "cca88249170b5406e5987b178190877f03b62ff2", "best_bid": "0.006", "best_ask": "0.014"}], "timestamp": "1769384569171", "event_type": "price_change"}}
{"_local_timestamp": "2026-01-25T23:42:49.348062+00:00", "data": {"market": "0xfdc15849e7bfbe9776d666108c2174047134547db0a014ec08605ca19b2c23c6", "price_changes": [{"asset_id": "3095574627925506845218316847738268742837051689528940940903139200105416861487", "price": "0.574", "size": "20", "side": "BUY", "hash": "fbe0bb7e43aa2e5f568c5e399add5debd6208c7e", "best_bid": "0.998", "best_ask": "0.999"}, {"asset_id": "99611234567111832279381235616973424305850563087425365084149737464676375626231", "price": "0.426", "size": "20", "side": "SELL", "hash": "7ed7f1f1cc2ae1330926936838994ca34192f24c", "best_bid": "0.001", "best_ask": "0.002"}], "timestamp": "1769384569208", "event_type": "price_change"}}
{"_local_timestamp": "2026-01-25T23:42:49.348790+00:00", "data": {"market": "0xb498db5296d2aaa4d26db3c6b6dc3a80c5924a9ea83b6b4f2f18c6f12726d747", "price_changes": [{"asset_id": "80044434770818464329551993094327116294077942468264664736091814178350906286521", "price": "0.61", "size": "20", "side": "BUY", "hash": "c0993538b47d2c5b882edb7d13da974eaea5721e", "best_bid": "0.998", "best_ask": "0.999"}, {"asset_id": "104760050366702563650209438348007452609559241951955868049242892063686019535745", "price": "0.39", "size": "20", "side": "SELL", "hash": "098952145b279f0171818680eb36c2f296e75630", "best_bid": "0.001", "best_ask": "0.002"}], "timestamp": "1769384569208", "event_type": "price_change"}}
{"_local_timestamp": "2026-01-25T23:42:49.349486+00:00", "data": {"market": "0x9ac58d2c51678463b45389b8d11d398a35f98bb9d99cd0a00e7994bf3d3bc106", "price_changes": [{"asset_id": "65530875443595461022055642853167256131284276704504495385262009209383645659674", "price": "0.61", "size": "20", "side": "BUY", "hash": "42b5b48db3b220f74f1caec505515e2cf86bad66", "best_bid": "0.998", "best_ask": "0.999"}, {"asset_id": "54236330394497042999232692608534835969733131094441295535277724798165041782814", "price": "0.39", "size": "20", "side": "SELL", "hash": "7d0131066b6bd90385baed0f3e4ab9bbe6a3f056", "best_bid": "0.001", "best_ask": "0.002"}], "timestamp": "1769384569208", "event_type": "price_change"}}
{"_local_timestamp": "2026-01-25T23:42:49.350190+00:00", "data": {"market": "0x31967ab350da8f760c547a62ce495f63f04c7402ea2bc291f7358d6aa367fdd8", "price_changes": [{"asset_id": "74574612697917499641784436195980418240322600911590628796653263539397328153034", "price": "0.565", "size": "20", "side": "BUY", "hash": "49ae5765b59fcd617737a4f691738fe4e2769a6d", "best_bid": "0.938", "best_ask": "0.998"}, {"asset_id": "48096461703828524256164307708005083326532171684035677911193083899587188981253", "price": "0.435", "size": "20", "side": "SELL", "hash": "dd25ae4b9768622947653b559fcedf1a905f8c1c", "best_bid": "0.002", "best_ask": "0.062"}], "timestamp": "1769384569208", "event_type": "price_change"}}
{"_local_timestamp": "2026-01-25T23:42:49.361239+00:00", "data": {"market": "0x180cad29950aab8a08730c47e904416559aad814321d73854151be137756ad23", "price_changes": [{"asset_id": "98909251781140045508527043137413768725223127886868660293320661027969116726188", "price": "0.586", "size": "20", "side": "BUY", "hash": "40c58563c564b55417d8ec868c620368859b8334", "best_bid": "0.998", "best_ask": "0.999"}, {"asset_id": "110987038017115137467642994123824186017997884207034130837015664299010910680722", "price": "0.414", "size": "20", "side": "SELL", "hash": "4d20adfacf162b46a207d83d9cef18be0e259cb3", "best_bid": "0.001", "best_ask": "0.002"}], "timestamp": "1769384569208", "event_type": "price_change"}}
{"_local_timestamp": "2026-01-25T23:42:49.362054+00:00", "data": {"market": "0x388b017fa66c293566816b3f6253af6800ca69d6ab740ef019e5a69feacacf70", "price_changes": [{"asset_id": "68883925535903398159530799578268246684851592835366731124807972752959560431304", "price": "0.598", "size": "20", "side": "BUY", "hash": "c3ef337015daf350a71835c57652deb9472d3668", "best_bid": "0.938", "best_ask": "0.993"}, {"asset_id": "49541604524685067034733103567606780662654635021473570692999975492153111969210", "price": "0.402", "size": "20", "side": "SELL", "hash": "6eeea930e7d13a2e96a7ccebe1aa3a4648bbbc6a", "best_bid": "0.007", "best_ask": "0.062"}], "timestamp": "1769384569208", "event_type": "price_change"}}
{"_local_timestamp": "2026-01-25T23:42:51.437907+00:00", "data": {"market": "0xec222c4c9935b37c2c563f34eb66715fb01f88a3a399830e83e4221153adfe6a", "price_changes": [{"asset_id": "45031179555990916139678136127586800287983215899550524176073382735544314971535", "price": "0.617", "size": "0", "side": "BUY", "hash": "4270ce1bae23e86cb5b0feb633876ff1314bd257", "best_bid": "0.933", "best_ask": "0.997"}, {"asset_id": "72384687038182433689874327261984956544997236795314184718224091418094356344966", "price": "0.383", "size": "0", "side": "SELL", "hash": "d98980cf8838731cc0edb25340d18774431feb5d", "best_bid": "0.003", "best_ask": "0.067"}], "timestamp": "1769384571292", "event_type": "price_change"}}
{"_local_timestamp": "2026-01-25T23:42:51.457458+00:00", "data": {"market": "0xec222c4c9935b37c2c563f34eb66715fb01f88a3a399830e83e4221153adfe6a", "price_changes": [{"asset_id": "45031179555990916139678136127586800287983215899550524176073382735544314971535", "price": "0.619", "size": "20", "side": "BUY", "hash": "c33db0131806e6b4709e62ad904523231e9153a9", "best_bid": "0.933", "best_ask": "0.997"}, {"asset_id": "72384687038182433689874327261984956544997236795314184718224091418094356344966", "price": "0.381", "size": "20", "side": "SELL", "hash": "8db42ccb6fb4831c64b9860127a1f8c3b0eaaa10", "best_bid": "0.003", "best_ask": "0.067"}], "timestamp": "1769384571317", "event_type": "price_change"}}
{"_local_timestamp": "2026-01-25T23:42:53.386825+00:00", "data": {"market": "0x180cad29950aab8a08730c47e904416559aad814321d73854151be137756ad23", "price_changes": [{"asset_id": "98909251781140045508527043137413768725223127886868660293320661027969116726188", "price": "0.002", "size": "250", "side": "BUY", "hash": "ccdebea4c6f5cead665f60ee2eff65c9162d8708", "best_bid": "0.998", "best_ask": "0.999"}, {"asset_id": "110987038017115137467642994123824186017997884207034130837015664299010910680722", "price": "0.998", "size": "250", "side": "SELL", "hash": "da29b50359ce9582454648ec83c91a7957f75a15", "best_bid": "0.001", "best_ask": "0.002"}], "timestamp": "1769384573228", "event_type": "price_change"}}
{"_local_timestamp": "2026-01-25T23:42:53.387733+00:00", "data": {"market": "0x180cad29950aab8a08730c47e904416559aad814321d73854151be137756ad23", "price_changes": [{"asset_id": "98909251781140045508527043137413768725223127886868660293320661027969116726188", "price": "0.005", "size": "0", "side": "BUY", "hash": "ccdebea4c6f5cead665f60ee2eff65c9162d8708", "best_bid": "0.998", "best_ask": "0.999"}, {"asset_id": "110987038017115137467642994123824186017997884207034130837015664299010910680722", "price": "0.995", "size": "0", "side": "SELL", "hash": "da29b50359ce9582454648ec83c91a7957f75a15", "best_bid": "0.001", "best_ask": "0.002"}], "timestamp": "1769384573228", "event_type": "price_change"}}
{"_local_timestamp": "2026-01-25T23:42:53.388515+00:00", "data": {"market": "0x180cad29950aab8a08730c47e904416559aad814321d73854151be137756ad23", "price_changes": [{"asset_id": "98909251781140045508527043137413768725223127886868660293320661027969116726188", "price": "0.011", "size": "0", "side": "BUY", "hash": "ccdebea4c6f5cead665f60ee2eff65c9162d8708", "best_bid": "0.998", "best_ask": "0.999"}, {"asset_id": "110987038017115137467642994123824186017997884207034130837015664299010910680722", "price": "0.989", "size": "0", "side": "SELL", "hash": "da29b50359ce9582454648ec83c91a7957f75a15", "best_bid": "0.001", "best_ask": "0.002"}], "timestamp": "1769384573228", "event_type": "price_change"}}
{"_local_timestamp": "2026-01-25T23:42:53.389308+00:00", "data": {"market": "0x180cad29950aab8a08730c47e904416559aad814321d73854151be137756ad23", "price_changes": [{"asset_id": "98909251781140045508527043137413768725223127886868660293320661027969116726188", "price": "0.024", "size": "0", "side": "BUY", "hash": "ccdebea4c6f5cead665f60ee2eff65c9162d8708", "best_bid": "0.998", "best_ask": "0.999"}, {"asset_id": "110987038017115137467642994123824186017997884207034130837015664299010910680722", "price": "0.976", "size": "0", "side": "SELL", "hash": "da29b50359ce9582454648ec83c91a7957f75a15", "best_bid": "0.001", "best_ask": "0.002"}], "timestamp": "1769384573228", "event_type": "price_change"}}
{"_local_timestamp": "2026-01-25T23:42:53.787095+00:00", "data": {"market": "0x180cad29950aab8a08730c47e904416559aad814321d73854151be137756ad23", "price_changes": [{"asset_id": "98909251781140045508527043137413768725223127886868660293320661027969116726188", "price": "0.025", "size": "15.31", "side": "BUY", "hash": "1c1bc97708487363f2c3357cbedd560a9b2aef96", "best_bid": "0.998", "best_ask": "0.999"}, {"asset_id": "110987038017115137467642994123824186017997884207034130837015664299010910680722", "price": "0.975", "size": "15.31", "side": "SELL", "hash": "55af92ee02f6f3a895de00afc61c9156dfef84ca", "best_bid": "0.001", "best_ask": "0.002"}], "timestamp": "1769384573641", "event_type": "price_change"}}
{"_local_timestamp": "2026-01-25T23:42:53.788028+00:00", "data": {"market": "0x180cad29950aab8a08730c47e904416559aad814321d73854151be137756ad23", "price_changes": [{"asset_id": "98909251781140045508527043137413768725223127886868660293320661027969116726188", "price": "0.002", "size": "265.6", "side": "BUY", "hash": "095370c3bcda1f3581136716fa420fe20cd753e7", "best_bid": "0.998", "best_ask": "0.999"}, {"asset_id": "110987038017115137467642994123824186017997884207034130837015664299010910680722", "price": "0.998", "size": "265.6", "side": "SELL", "hash": "51dd995d01eec582f22efb8b5a1ed9d2ca4b5327", "best_bid": "0.001", "best_ask": "0.002"}], "timestamp": "1769384573643", "event_type": "price_change"}}
{"_local_timestamp": "2026-01-25T23:42:53.788766+00:00", "data": {"market": "0x180cad29950aab8a08730c47e904416559aad814321d73854151be137756ad23", "price_changes": [{"asset_id": "98909251781140045508527043137413768725223127886868660293320661027969116726188", "price": "0.012", "size": "10.93", "side": "BUY", "hash": "588868fb5008bd82859b2eb511961e051d1071fc", "best_bid": "0.998", "best_ask": "0.999"}, {"asset_id": "110987038017115137467642994123824186017997884207034130837015664299010910680722", "price": "0.988", "size": "10.93", "side": "SELL", "hash": "da8624a0240244069dbb392231be093b7b3722d4", "best_bid": "0.001", "best_ask": "0.002"}], "timestamp": "1769384573644", "event_type": "price_change"}}
{"_local_timestamp": "2026-01-25T23:42:53.789486+00:00", "data": {"market": "0x180cad29950aab8a08730c47e904416559aad814321d73854151be137756ad23", "price_changes": [{"asset_id": "98909251781140045508527043137413768725223127886868660293320661027969116726188", "price": "0.005", "size": "14.41", "side": "BUY", "hash": "46820c48aa2e94d1e9a96e444b4f50f6b1710bf0", "best_bid": "0.998", "best_ask": "0.999"}, {"asset_id": "110987038017115137467642994123824186017997884207034130837015664299010910680722", "price": "0.995", "size": "14.41", "side": "SELL", "hash": "0cf236992dc3be10ade1b2f711a8a124128ec0a8", "best_bid": "0.001", "best_ask": "0.002"}], "timestamp": "1769384573645", "event_type": "price_change"}}
{"_local_timestamp": "2026-01-25T23:42:53.843663+00:00", "data": {"market": "0xce465bdf15fd274b3d6bd5e4c543fb047f5bc09e306d9a70dd9cf3b207f7a547", "price_changes": [{"asset_id": "3990566517926198774760739919993523333580985526226102598439634813084268870587", "price": "0.166", "size": "0", "side": "BUY", "hash": "cb8fc55af3ee859720d6522272e5fc841ec84c10", "best_bid": "0.997", "best_ask": "0.998"}, {"asset_id": "91363015704893492073568830399375035872276923274131092245805554034196213248667", "price": "0.834", "size": "0", "side": "SELL", "hash": "8afeecd508e85a5c07ed67c9522fa220ad85a251", "best_bid": "0.002", "best_ask": "0.003"}], "timestamp": "1769384573693", "event_type": "price_change"}}
{"_local_timestamp": "2026-01-25T23:42:55.333923+00:00", "data": {"market": "0xce465bdf15fd274b3d6bd5e4c543fb047f5bc09e306d9a70dd9cf3b207f7a547", "price_changes": [{"asset_id": "3990566517926198774760739919993523333580985526226102598439634813084268870587", "price": "0.168", "size": "7.91", "side": "BUY", "hash": "d5a2f400a17eaafeb3453499fef0b15621f6acbb", "best_bid": "0.997", "best_ask": "0.998"}, {"asset_id": "91363015704893492073568830399375035872276923274131092245805554034196213248667", "price": "0.832", "size": "7.91", "side": "SELL", "hash": "361ddb68ec0802af33b47b0c4549c4ac93d14011", "best_bid": "0.002", "best_ask": "0.003"}], "timestamp": "1769384575206", "event_type": "price_change"}}
{"_local_timestamp": "2026-01-25T23:43:00.218549+00:00", "data": {"market": "0x653092399b4e6eb099d59869203392fa82d0ff01fbea2e9afea4aa1512867946", "price_changes": [{"asset_id": "68467365377349140502382558650516303800547405844469524834735876287721497052152", "price": "0.631", "size": "0", "side": "BUY", "hash": "2a6bcd8a66318ea0899b6f094347f345ed1d1ea9", "best_bid": "0.996", "best_ask": "0.997"}, {"asset_id": "79391923363755133111783673620134908690733495531408389463553631418324945230516", "price": "0.369", "size": "0", "side": "SELL", "hash": "c1a7a12a9dcd4ac9bf8a574646268b72f6b63cb1", "best_bid": "0.003", "best_ask": "0.004"}], "timestamp": "1769384580076", "event_type": "price_change"}}
{"_local_timestamp": "2026-01-25T23:43:00.398190+00:00", "data": {"market": "0x653092399b4e6eb099d59869203392fa82d0ff01fbea2e9afea4aa1512867946", "price_changes": [{"asset_id": "68467365377349140502382558650516303800547405844469524834735876287721497052152", "price": "0.141", "size": "0", "side": "BUY", "hash": "81c9de854361ad86907e6ccadda70009af9ba5ab", "best_bid": "0.996", "best_ask": "0.997"}, {"asset_id": "79391923363755133111783673620134908690733495531408389463553631418324945230516", "price": "0.859", "size": "0", "side": "SELL", "hash": "b013e04b2780eea5f60b9dd76b9481b0bc7f1e30", "best_bid": "0.003", "best_ask": "0.004"}], "timestamp": "1769384580268", "event_type": "price_change"}}
{"_local_timestamp": "2026-01-25T23:43:00.605267+00:00", "data": {"market": "0x653092399b4e6eb099d59869203392fa82d0ff01fbea2e9afea4aa1512867946", "price_changes": [{"asset_id": "68467365377349140502382558650516303800547405844469524834735876287721497052152", "price": "0.058", "size": "500", "side": "BUY", "hash": "6ea792894d2fdaaca9cdd167386b21ee67e9561b", "best_bid": "0.996", "best_ask": "0.997"}, {"asset_id": "79391923363755133111783673620134908690733495531408389463553631418324945230516", "price": "0.942", "size": "500", "side": "SELL", "hash": "e47fff6e93b5dd2160db791fb59bfc9b907d9df0", "best_bid": "0.003", "best_ask": "0.004"}], "timestamp": "1769384580475", "event_type": "price_change"}}
{"_local_timestamp": "2026-01-25T23:43:00.826516+00:00", "data": {"market": "0x653092399b4e6eb099d59869203392fa82d0ff01fbea2e9afea4aa1512867946", "price_changes": [{"asset_id": "68467365377349140502382558650516303800547405844469524834735876287721497052152", "price": "0.012", "size": "0", "side": "BUY", "hash": "63535bdab2a6e1e205aefc23ddabf2883c36baa9", "best_bid": "0.996", "best_ask": "0.997"}, {"asset_id": "79391923363755133111783673620134908690733495531408389463553631418324945230516", "price": "0.988", "size": "0", "side": "SELL", "hash": "65f9a8f0b95da8c68f6dd3a375147ed8cb739385", "best_bid": "0.003", "best_ask": "0.004"}], "timestamp": "1769384580693", "event_type": "price_change"}}
{"_local_timestamp": "2026-01-25T23:43:01.038901+00:00", "data": {"market": "0x653092399b4e6eb099d59869203392fa82d0ff01fbea2e9afea4aa1512867946", "price_changes": [{"asset_id": "68467365377349140502382558650516303800547405844469524834735876287721497052152", "price": "0.021", "size": "465.57", "side": "BUY", "hash": "111e2ee03884d43956e845219e14a9ae92484ae3", "best_bid": "0.996", "best_ask": "0.997"}, {"asset_id": "79391923363755133111783673620134908690733495531408389463553631418324945230516", "price": "0.979", "size": "465.57", "side": "SELL", "hash": "d7481dc1cb868a3c136344cc3b12b240252e81da", "best_bid": "0.003", "best_ask": "0.004"}], "timestamp": "1769384580906", "event_type": "price_change"}}
{"_local_timestamp": "2026-01-25T23:43:01.253517+00:00", "data": {"market": "0x653092399b4e6eb099d59869203392fa82d0ff01fbea2e9afea4aa1512867946", "price_changes": [{"asset_id": "68467365377349140502382558650516303800547405844469524834735876287721497052152", "price": "0.06", "size": "160", "side": "BUY", "hash": "9cdd9fbaebb23cb7ac167d75c87354bfbb99dba1", "best_bid": "0.996", "best_ask": "0.997"}, {"asset_id": "79391923363755133111783673620134908690733495531408389463553631418324945230516", "price": "0.94", "size": "160", "side": "SELL", "hash": "f0bf4ef5650a42740739d46935b86cb6d04d1c95", "best_bid": "0.003", "best_ask": "0.004"}], "timestamp": "1769384581125", "event_type": "price_change"}}
{"_local_timestamp": "2026-01-25T23:43:01.458175+00:00", "data": {"market": "0x653092399b4e6eb099d59869203392fa82d0ff01fbea2e9afea4aa1512867946", "price_changes": [{"asset_id": "68467365377349140502382558650516303800547405844469524834735876287721497052152", "price": "0.143", "size": "80.13", "side": "BUY", "hash": "0f0e1f5885c1c32c802a961d3aa735c41f3c4145", "best_bid": "0.996", "best_ask": "0.997"}, {"asset_id": "79391923363755133111783673620134908690733495531408389463553631418324945230516", "price": "0.857", "size": "80.13", "side": "SELL", "hash": "f8c90f95b595073defa745b3059c98e9c9d307b8", "best_bid": "0.003", "best_ask": "0.004"}], "timestamp": "1769384581317", "event_type": "price_change"}}
{"_local_timestamp": "2026-01-25T23:43:01.697300+00:00", "data": {"market": "0x653092399b4e6eb099d59869203392fa82d0ff01fbea2e9afea4aa1512867946", "price_changes": [{"asset_id": "68467365377349140502382558650516303800547405844469524834735876287721497052152", "price": "0.639", "size": "25.02", "side": "BUY", "hash": "d45eea415a1ae7410228bd76a75c86f3008b64c8", "best_bid": "0.996", "best_ask": "0.997"}, {"asset_id": "79391923363755133111783673620134908690733495531408389463553631418324945230516", "price": "0.361", "size": "25.02", "side": "SELL", "hash": "12112afbf6c4f1431908cf63a8a308a42b662d91", "best_bid": "0.003", "best_ask": "0.004"}], "timestamp": "1769384581534", "event_type": "price_change"}}
{"_local_timestamp": "2026-01-25T23:43:12.407738+00:00", "data": {"market": "0xce465bdf15fd274b3d6bd5e4c543fb047f5bc09e306d9a70dd9cf3b207f7a547", "price_changes": [{"asset_id": "3990566517926198774760739919993523333580985526226102598439634813084268870587", "price": "0.61", "size": "0", "side": "BUY", "hash": "f335c00b136a8153bce50beb435473d02f37ac3b", "best_bid": "0.997", "best_ask": "0.998"}, {"asset_id": "91363015704893492073568830399375035872276923274131092245805554034196213248667", "price": "0.39", "size": "0", "side": "SELL", "hash": "dd2f11057d7ba01124547b522321d473475ab2c7", "best_bid": "0.002", "best_ask": "0.003"}], "timestamp": "1769384592287", "event_type": "price_change"}}
{"_local_timestamp": "2026-01-25T23:43:12.612678+00:00", "data": {"market": "0xce465bdf15fd274b3d6bd5e4c543fb047f5bc09e306d9a70dd9cf3b207f7a547", "price_changes": [{"asset_id": "3990566517926198774760739919993523333580985526226102598439634813084268870587", "price": "0.165", "size": "0", "side": "BUY", "hash": "843c0ab83062395d2d7ee8ef8055eeee6e31aac5", "best_bid": "0.997", "best_ask": "0.998"}, {"asset_id": "91363015704893492073568830399375035872276923274131092245805554034196213248667", "price": "0.835", "size": "0", "side": "SELL", "hash": "9392e4f5e34df374ae715ef3125ff8986619e2a8", "best_bid": "0.002", "best_ask": "0.003"}], "timestamp": "1769384592500", "event_type": "price_change"}}
{"_local_timestamp": "2026-01-25T23:43:12.822980+00:00", "data": {"market": "0xce465bdf15fd274b3d6bd5e4c543fb047f5bc09e306d9a70dd9cf3b207f7a547", "price_changes": [{"asset_id": "3990566517926198774760739919993523333580985526226102598439634813084268870587", "price": "0.072", "size": "0", "side": "BUY", "hash": "b7e30ba9dd25ed9f0d3cd575657a3a8498440413", "best_bid": "0.997", "best_ask": "0.998"}, {"asset_id": "91363015704893492073568830399375035872276923274131092245805554034196213248667", "price": "0.928", "size": "0", "side": "SELL", "hash": "2b748ea51b2c8403929f8a16e53b2c0f00260e44", "best_bid": "0.002", "best_ask": "0.003"}], "timestamp": "1769384592710", "event_type": "price_change"}}
{"_local_timestamp": "2026-01-25T23:43:13.384309+00:00", "data": {"market": "0xce465bdf15fd274b3d6bd5e4c543fb047f5bc09e306d9a70dd9cf3b207f7a547", "price_changes": [{"asset_id": "3990566517926198774760739919993523333580985526226102598439634813084268870587", "price": "0.032", "size": "700", "side": "BUY", "hash": "d75de60c0f4563a9d575d34dda048894c23f00e2", "best_bid": "0.997", "best_ask": "0.998"}, {"asset_id": "91363015704893492073568830399375035872276923274131092245805554034196213248667", "price": "0.968", "size": "700", "side": "SELL", "hash": "6e9b0e516883dc96ec5ba4c7ff99545111a28535", "best_bid": "0.002", "best_ask": "0.003"}], "timestamp": "1769384592922", "event_type": "price_change"}}
{"_local_timestamp": "2026-01-25T23:43:13.386773+00:00", "data": {"market": "0xce465bdf15fd274b3d6bd5e4c543fb047f5bc09e306d9a70dd9cf3b207f7a547", "price_changes": [{"asset_id": "3990566517926198774760739919993523333580985526226102598439634813084268870587", "price": "0.034", "size": "201.68", "side": "BUY", "hash": "19f98fa8068fc6b5cd80e439f115ae5dc3138709", "best_bid": "0.997", "best_ask": "0.998"}, {"asset_id": "91363015704893492073568830399375035872276923274131092245805554034196213248667", "price": "0.966", "size": "201.68", "side": "SELL", "hash": "c22813727f56821064a87ed3e092d66ff9b809c6", "best_bid": "0.002", "best_ask": "0.003"}], "timestamp": "1769384593128", "event_type": "price_change"}}
{"_local_timestamp": "2026-01-25T23:43:13.459683+00:00", "data": {"market": "0xce465bdf15fd274b3d6bd5e4c543fb047f5bc09e306d9a70dd9cf3b207f7a547", "price_changes": [{"asset_id": "3990566517926198774760739919993523333580985526226102598439634813084268870587", "price": "0.061", "size": "112.41", "side": "BUY", "hash": "f4294997b55bd902a8b9a6b393936d33a674ca8a", "best_bid": "0.997", "best_ask": "0.998"}, {"asset_id": "91363015704893492073568830399375035872276923274131092245805554034196213248667", "price": "0.939", "size": "112.41", "side": "SELL", "hash": "6f4991f7492265440f9825790944e698b7928d76", "best_bid": "0.002", "best_ask": "0.003"}], "timestamp": "1769384593339", "event_type": "price_change"}}
{"_local_timestamp": "2026-01-25T23:43:13.709867+00:00", "data": {"market": "0xce465bdf15fd274b3d6bd5e4c543fb047f5bc09e306d9a70dd9cf3b207f7a547", "price_changes": [{"asset_id": "3990566517926198774760739919993523333580985526226102598439634813084268870587", "price": "0.074", "size": "92.66", "side": "BUY", "hash": "6840469a09429b4b8a6dc432eee2c0bec2a0afc8", "best_bid": "0.997", "best_ask": "0.998"}, {"asset_id": "91363015704893492073568830399375035872276923274131092245805554034196213248667", "price": "0.926", "size": "92.66", "side": "SELL", "hash": "24885aa12cf00875b922454afb11eba295ed97d3", "best_bid": "0.002", "best_ask": "0.003"}], "timestamp": "1769384593589", "event_type": "price_change"}}
{"_local_timestamp": "2026-01-25T23:43:13.929219+00:00", "data": {"market": "0xce465bdf15fd274b3d6bd5e4c543fb047f5bc09e306d9a70dd9cf3b207f7a547", "price_changes": [{"asset_id": "3990566517926198774760739919993523333580985526226102598439634813084268870587", "price": "0.112", "size": "0", "side": "BUY", "hash": "3c64307de04fa7090fc639e8d927bb17ffc63cbf", "best_bid": "0.997", "best_ask": "0.998"}, {"asset_id": "91363015704893492073568830399375035872276923274131092245805554034196213248667", "price": "0.888", "size": "0", "side": "SELL", "hash": "14ed35009c8526057eff49cc5c2770b7ca247460", "best_bid": "0.002", "best_ask": "0.003"}], "timestamp": "1769384593801", "event_type": "price_change"}}
{"_local_timestamp": "2026-01-25T23:43:14.173485+00:00", "data": {"market": "0xce465bdf15fd274b3d6bd5e4c543fb047f5bc09e306d9a70dd9cf3b207f7a547", "price_changes": [{"asset_id": "3990566517926198774760739919993523333580985526226102598439634813084268870587", "price": "0.112", "size": "61.22", "side": "BUY", "hash": "81f6f067a2e72b1c2dee655ceb03c154335515ad", "best_bid": "0.997", "best_ask": "0.998"}, {"asset_id": "91363015704893492073568830399375035872276923274131092245805554034196213248667", "price": "0.888", "size": "61.22", "side": "SELL", "hash": "d5b42fd86582d3e323e78f91f66884e69728ce5d", "best_bid": "0.002", "best_ask": "0.003"}], "timestamp": "1769384594018", "event_type": "price_change"}}
{"_local_timestamp": "2026-01-25T23:43:14.351729+00:00", "data": {"market": "0xce465bdf15fd274b3d6bd5e4c543fb047f5bc09e306d9a70dd9cf3b207f7a547", "price_changes": [{"asset_id": "3990566517926198774760739919993523333580985526226102598439634813084268870587", "price": "0.167", "size": "52.06", "side": "BUY", "hash": "74eb4cfa1d34195b9066260744e1214df94cdfdb", "best_bid": "0.997", "best_ask": "0.998"}, {"asset_id": "91363015704893492073568830399375035872276923274131092245805554034196213248667", "price": "0.833", "size": "52.06", "side": "SELL", "hash": "09d1bc16e33ecf3af52e324b0a15a4a06059e75d", "best_bid": "0.002", "best_ask": "0.003"}], "timestamp": "1769384594235", "event_type": "price_change"}}
{"_local_timestamp": "2026-01-25T23:43:14.562083+00:00", "data": {"market": "0xce465bdf15fd274b3d6bd5e4c543fb047f5bc09e306d9a70dd9cf3b207f7a547", "price_changes": [{"asset_id": "3990566517926198774760739919993523333580985526226102598439634813084268870587", "price": "0.572", "size": "0", "side": "BUY", "hash": "154171122cf4ea02ef91581bdd95081b25502ff0", "best_bid": "0.997", "best_ask": "0.998"}, {"asset_id": "91363015704893492073568830399375035872276923274131092245805554034196213248667", "price": "0.428", "size": "0", "side": "SELL", "hash": "7656b4356eb19ce7306e48e2ced07c71ecd37994", "best_bid": "0.002", "best_ask": "0.003"}], "timestamp": "1769384594439", "event_type": "price_change"}}
{"_local_timestamp": "2026-01-25T23:43:14.772831+00:00", "data": {"market": "0xce465bdf15fd274b3d6bd5e4c543fb047f5bc09e306d9a70dd9cf3b207f7a547", "price_changes": [{"asset_id": "3990566517926198774760739919993523333580985526226102598439634813084268870587", "price": "0.572", "size": "11.98", "side": "BUY", "hash": "f1081c7fb507ead01a080155256024f78dfb25b9", "best_bid": "0.997", "best_ask": "0.998"}, {"asset_id": "91363015704893492073568830399375035872276923274131092245805554034196213248667", "price": "0.428", "size": "11.98", "side": "SELL", "hash": "fd0e825aa388237664b899f4ecaadacfea92cc5b", "best_bid": "0.002", "best_ask": "0.003"}], "timestamp": "1769384594651", "event_type": "price_change"}}
{"_local_timestamp": "2026-01-25T23:43:14.975308+00:00", "data": {"market": "0xce465bdf15fd274b3d6bd5e4c543fb047f5bc09e306d9a70dd9cf3b207f7a547", "price_changes": [{"asset_id": "3990566517926198774760739919993523333580985526226102598439634813084268870587", "price": "0.613", "size": "31.18", "side": "BUY", "hash": "ae9ae7d949bcccb2b529a9b42d30dc0bd48e36fb", "best_bid": "0.997", "best_ask": "0.998"}, {"asset_id": "91363015704893492073568830399375035872276923274131092245805554034196213248667", "price": "0.387", "size": "31.18", "side": "SELL", "hash": "74642d1adc0742f4ed51d9b37f300acf6e8aaa9e", "best_bid": "0.002", "best_ask": "0.003"}], "timestamp": "1769384594854", "event_type": "price_change"}}
{"_local_timestamp": "2026-01-25T23:43:15.183912+00:00", "data": {"market": "0xec222c4c9935b37c2c563f34eb66715fb01f88a3a399830e83e4221153adfe6a", "price_changes": [{"asset_id": "45031179555990916139678136127586800287983215899550524176073382735544314971535", "price": "0.606", "size": "0", "side": "BUY", "hash": "2ce3e6d49fe92ed309ec4eded007727db7862059", "best_bid": "0.933", "best_ask": "0.997"}, {"asset_id": "72384687038182433689874327261984956544997236795314184718224091418094356344966", "price": "0.394", "size": "0", "side": "SELL", "hash": "6b85788db4514855b091dad1db031dfc0c23c5a7", "best_bid": "0.003", "best_ask": "0.067"}], "timestamp": "1769384595063", "event_type": "price_change"}}
{"_local_timestamp": "2026-01-25T23:43:15.379381+00:00", "data": {"market": "0xec222c4c9935b37c2c563f34eb66715fb01f88a3a399830e83e4221153adfe6a", "price_changes": [{"asset_id": "45031179555990916139678136127586800287983215899550524176073382735544314971535", "price": "0.599", "size": "0", "side": "BUY", "hash": "cfe945f84620b8cd1242380536d3106e7ecfdb44", "best_bid": "0.933", "best_ask": "0.997"}, {"asset_id": "72384687038182433689874327261984956544997236795314184718224091418094356344966", "price": "0.401", "size": "0", "side": "SELL", "hash": "4098a091adea6c18f731571d67bf7caf80a8651a", "best_bid": "0.003", "best_ask": "0.067"}], "timestamp": "1769384595264", "event_type": "price_change"}}
{"_local_timestamp": "2026-01-25T23:43:15.581268+00:00", "data": {"market": "0xec222c4c9935b37c2c563f34eb66715fb01f88a3a399830e83e4221153adfe6a", "price_changes": [{"asset_id": "45031179555990916139678136127586800287983215899550524176073382735544314971535", "price": "0.086", "size": "0", "side": "BUY", "hash": "0e396aa7915427ebd867f38feafedd23407d6c55", "best_bid": "0.933", "best_ask": "0.997"}, {"asset_id": "72384687038182433689874327261984956544997236795314184718224091418094356344966", "price": "0.914", "size": "0", "side": "SELL", "hash": "4ba9ec34e68a0de911d80ffbebdae0878ce488c3", "best_bid": "0.003", "best_ask": "0.067"}], "timestamp": "1769384595470", "event_type": "price_change"}}
{"_local_timestamp": "2026-01-25T23:43:15.775741+00:00", "data": {"market": "0xec222c4c9935b37c2c563f34eb66715fb01f88a3a399830e83e4221153adfe6a", "price_changes": [{"asset_id": "45031179555990916139678136127586800287983215899550524176073382735544314971535", "price": "0.037", "size": "700", "side": "BUY", "hash": "935ca20f85f6bc832212e1876c2bf1d33f0cad45", "best_bid": "0.933", "best_ask": "0.997"}, {"asset_id": "72384687038182433689874327261984956544997236795314184718224091418094356344966", "price": "0.963", "size": "700", "side": "SELL", "hash": "23f205e0f5eb60594a7f315baf8563d0f04ac653", "best_bid": "0.003", "best_ask": "0.067"}], "timestamp": "1769384595664", "event_type": "price_change"}}
{"_local_timestamp": "2026-01-25T23:43:15.997408+00:00", "data": {"market": "0xec222c4c9935b37c2c563f34eb66715fb01f88a3a399830e83e4221153adfe6a", "price_changes": [{"asset_id": "45031179555990916139678136127586800287983215899550524176073382735544314971535", "price": "0.012", "size": "571.42", "side": "BUY", "hash": "83c03f70fdf0e4b6f5b7e18e3e08a155cf9a2142", "best_bid": "0.933", "best_ask": "0.997"}, {"asset_id": "72384687038182433689874327261984956544997236795314184718224091418094356344966", "price": "0.988", "size": "571.42", "side": "SELL", "hash": "104c18c608a48cb285f1a30e5605052c52e747cc", "best_bid": "0.003", "best_ask": "0.067"}], "timestamp": "1769384595881", "event_type": "price_change"}}
{"_local_timestamp": "2026-01-25T23:43:16.089572+00:00", "data": {"market": "0xa62558c07dee376f7903e95977b10c13544d3546eeae6c98130839753e093979", "price_changes": [{"asset_id": "35970432242453970638378005355807025798529538734302331296289043262158829773976", "price": "0.776", "size": "0", "side": "BUY", "hash": "c6abe8cb919f9841353a8757c2ed5f3ec786e5cd", "best_bid": "0.993", "best_ask": "0.997"}, {"asset_id": "72574656434993840186445307554025381492285372432846424590534736075839686478597", "price": "0.224", "size": "0", "side": "SELL", "hash": "c50815076a069d7d154908238718cac41e7fcad3", "best_bid": "0.003", "best_ask": "0.007"}], "timestamp": "1769384595976", "event_type": "price_change"}}
{"_local_timestamp": "2026-01-25T23:43:16.194127+00:00", "data": {"market": "0xec222c4c9935b37c2c563f34eb66715fb01f88a3a399830e83e4221153adfe6a", "price_changes": [{"asset_id": "45031179555990916139678136127586800287983215899550524176073382735544314971535", "price": "0.052", "size": "500", "side": "BUY", "hash": "fcb1f952482e9fad2cfeefd379ef3a6c221cca16", "best_bid": "0.933", "best_ask": "0.997"}, {"asset_id": "72384687038182433689874327261984956544997236795314184718224091418094356344966", "price": "0.948", "size": "500", "side": "SELL", "hash": "9c16b4dd83f1aec7ea95b9d0b9a3ec683023de88", "best_bid": "0.003", "best_ask": "0.067"}], "timestamp": "1769384596077", "event_type": "price_change"}}
{"_local_timestamp": "2026-01-25T23:43:16.417042+00:00", "data": {"market": "0xec222c4c9935b37c2c563f34eb66715fb01f88a3a399830e83e4221153adfe6a", "price_changes": [{"asset_id": "45031179555990916139678136127586800287983215899550524176073382735544314971535", "price": "0.052", "size": "631.86", "side": "BUY", "hash": "6668c5a0e03cc5060eeb36782070d25230d77cb0", "best_bid": "0.933", "best_ask": "0.997"}, {"asset_id": "72384687038182433689874327261984956544997236795314184718224091418094356344966", "price": "0.948", "size": "631.86", "side": "SELL", "hash": "2a892f85420f21036d088d6c6db869ef0287f9fe", "best_bid": "0.003", "best_ask": "0.067"}], "timestamp": "1769384596288", "event_type": "price_change"}}
{"_local_timestamp": "2026-01-25T23:43:16.635415+00:00", "data": {"market": "0xec222c4c9935b37c2c563f34eb66715fb01f88a3a399830e83e4221153adfe6a", "price_changes": [{"asset_id": "45031179555990916139678136127586800287983215899550524176073382735544314971535", "price": "0.088", "size": "77.92", "side": "BUY", "hash": "6fe7b398f0845679380426c97282248bfcb31af1", "best_bid": "0.933", "best_ask": "0.997"}, {"asset_id": "72384687038182433689874327261984956544997236795314184718224091418094356344966", "price": "0.912", "size": "77.92", "side": "SELL", "hash": "e0a0b15b9cc7812bb06e9cf4a0e9c3014d3b872b", "best_bid": "0.003", "best_ask": "0.067"}], "timestamp": "1769384596511", "event_type": "price_change"}}
{"_local_timestamp": "2026-01-25T23:43:16.840554+00:00", "data": {"market": "0xec222c4c9935b37c2c563f34eb66715fb01f88a3a399830e83e4221153adfe6a", "price_changes": [{"asset_id": "45031179555990916139678136127586800287983215899550524176073382735544314971535", "price": "0.215", "size": "2172.89", "side": "BUY", "hash": "7abe56896e472d3ad17edbe738b84474156da859", "best_bid": "0.933", "best_ask": "0.997"}, {"asset_id": "72384687038182433689874327261984956544997236795314184718224091418094356344966", "price": "0.785", "size": "2172.89", "side": "SELL", "hash": "b473af7bdc7c6e32f7119de7548b14f3a21e510e", "best_bid": "0.003", "best_ask": "0.067"}], "timestamp": "1769384596716", "event_type": "price_change"}}
{"_local_timestamp": "2026-01-25T23:43:17.046415+00:00", "data": {"market": "0xec222c4c9935b37c2c563f34eb66715fb01f88a3a399830e83e4221153adfe6a", "price_changes": [{"asset_id": "45031179555990916139678136127586800287983215899550524176073382735544314971535", "price": "0.235", "size": "0", "side": "BUY", "hash": "99341048dc99b3f6fc5e424d39db8952616a7f09", "best_bid": "0.933", "best_ask": "0.997"}, {"asset_id": "72384687038182433689874327261984956544997236795314184718224091418094356344966", "price": "0.765", "size": "0", "side": "SELL", "hash": "e459a7e85c42657a36f423deb48edf072748ed1d", "best_bid": "0.003", "best_ask": "0.067"}], "timestamp": "1769384596913", "event_type": "price_change"}}
{"_local_timestamp": "2026-01-25T23:43:17.240974+00:00", "data": {"market": "0xec222c4c9935b37c2c563f34eb66715fb01f88a3a399830e83e4221153adfe6a", "price_changes": [{"asset_id": "45031179555990916139678136127586800287983215899550524176073382735544314971535", "price": "0.235", "size": "29.17", "side": "BUY", "hash": "c6d9a93a44654c59f24a2defd30e79ec7bc52843", "best_bid": "0.933", "best_ask": "0.997"}, {"asset_id": "72384687038182433689874327261984956544997236795314184718224091418094356344966", "price": "0.765", "size": "29.17", "side": "SELL", "hash": "8f345a5e8247658d6497c080dcd8e35ef37ed257", "best_bid": "0.003", "best_ask": "0.067"}], "timestamp": "1769384597123", "event_type": "price_change"}}
{"_local_timestamp": "2026-01-25T23:43:17.457778+00:00", "data": {"market": "0xec222c4c9935b37c2c563f34eb66715fb01f88a3a399830e83e4221153adfe6a", "price_changes": [{"asset_id": "45031179555990916139678136127586800287983215899550524176073382735544314971535", "price": "0.525", "size": "13.06", "side": "BUY", "hash": "6da12007e48b53a25fcce5fe547a787a36dda61e", "best_bid": "0.933", "best_ask": "0.997"}, {"asset_id": "72384687038182433689874327261984956544997236795314184718224091418094356344966", "price": "0.475", "size": "13.06", "side": "SELL", "hash": "044e993d0241c12dfd228d799993a5765280cd35", "best_bid": "0.003", "best_ask": "0.067"}], "timestamp": "1769384597347", "event_type": "price_change"}}
{"_local_timestamp": "2026-01-25T23:43:17.500854+00:00", "data": {"market": "0xa62558c07dee376f7903e95977b10c13544d3546eeae6c98130839753e093979", "price_changes": [{"asset_id": "35970432242453970638378005355807025798529538734302331296289043262158829773976", "price": "0.777", "size": "0", "side": "BUY", "hash": "1dada54742ecaeb199ba8090bd862022d970ee33", "best_bid": "0.993", "best_ask": "0.997"}, {"asset_id": "72574656434993840186445307554025381492285372432846424590534736075839686478597", "price": "0.223", "size": "0", "side": "SELL", "hash": "6752ebdc53bbceeaef178e4663ae1ba073e29b48", "best_bid": "0.003", "best_ask": "0.007"}], "timestamp": "1769384597389", "event_type": "price_change"}}
{"_local_timestamp": "2026-01-25T23:43:17.526064+00:00", "data": {"market": "0xa62558c07dee376f7903e95977b10c13544d3546eeae6c98130839753e093979", "price_changes": [{"asset_id": "35970432242453970638378005355807025798529538734302331296289043262158829773976", "price": "0.725", "size": "20", "side": "BUY", "hash": "e8b7dec91a82417d132bc6f213ec23a56caaeccc", "best_bid": "0.993", "best_ask": "0.997"}, {"asset_id": "72574656434993840186445307554025381492285372432846424590534736075839686478597", "price": "0.275", "size": "20", "side": "SELL", "hash": "67f62c4d85a5797168ec2496a6f62b43623c857f", "best_bid": "0.003", "best_ask": "0.007"}], "timestamp": "1769384597413", "event_type": "price_change"}}
{"_local_timestamp": "2026-01-25T23:43:17.677523+00:00", "data": {"market": "0xec222c4c9935b37c2c563f34eb66715fb01f88a3a399830e83e4221153adfe6a", "price_changes": [{"asset_id": "45031179555990916139678136127586800287983215899550524176073382735544314971535", "price": "0.616", "size": "21.13", "side": "BUY", "hash": "32b2acac1017565705f9331d3aceaa19e090d872", "best_bid": "0.933", "best_ask": "0.997"}, {"asset_id": "72384687038182433689874327261984956544997236795314184718224091418094356344966", "price": "0.384", "size": "21.13", "side": "SELL", "hash": "62f258411d037e4919a1d09b4f65a1eaf48a4ef1", "best_bid": "0.003", "best_ask": "0.067"}], "timestamp": "1769384597567", "event_type": "price_change"}}
{"_local_timestamp": "2026-01-25T23:43:22.355274+00:00", "data": {"market": "0x20e3bf2810db76a48bb4b915bf85ec43070a54da46f7ee9f123bde8b95add82c", "price_changes": [{"asset_id": "113173738354606351153328793226311936686716030058934510835145939200861029046537", "price": "0.082", "size": "0", "side": "BUY", "hash": "0065d614baf4e532677a0827ff3b6e50174685f2", "best_bid": "0.954", "best_ask": "0.991"}, {"asset_id": "111833791713605298141350391268557048852627695992567917532719982369837309341050", "price": "0.918", "size": "0", "side": "SELL", "hash": "f91b0192e42f78f478791d174a69f0ca4a9290cb", "best_bid": "0.009", "best_ask": "0.046"}], "timestamp": "1769384602253", "event_type": "price_change"}}
{"_local_timestamp": "2026-01-25T23:43:22.407307+00:00", "data": {"market": "0x20e3bf2810db76a48bb4b915bf85ec43070a54da46f7ee9f123bde8b95add82c", "price_changes": [{"asset_id": "113173738354606351153328793226311936686716030058934510835145939200861029046537", "price": "0.15", "size": "13", "side": "BUY", "hash": "8c5319da00d7212be8d178b3563b145b9689637b", "best_bid": "0.954", "best_ask": "0.991"}, {"asset_id": "111833791713605298141350391268557048852627695992567917532719982369837309341050", "price": "0.85", "size": "13", "side": "SELL", "hash": "dc55a60b97d09fc5aa409499f88200eae3e3e9b6", "best_bid": "0.009", "best_ask": "0.046"}], "timestamp": "1769384602307", "event_type": "price_change"}}
{"_local_timestamp": "2026-01-25T23:43:24.560505+00:00", "data": {"market": "0x20e3bf2810db76a48bb4b915bf85ec43070a54da46f7ee9f123bde8b95add82c", "price_changes": [{"asset_id": "113173738354606351153328793226311936686716030058934510835145939200861029046537", "price": "0.149", "size": "0", "side": "BUY", "hash": "ae0470f51484e892bca71b49931937db0c6f81b6", "best_bid": "0.954", "best_ask": "0.991"}, {"asset_id": "111833791713605298141350391268557048852627695992567917532719982369837309341050", "price": "0.851", "size": "0", "side": "SELL", "hash": "f3f8ef76f10ad89ca2734baad4cc026bc9cadda7", "best_bid": "0.009", "best_ask": "0.046"}], "timestamp": "1769384604451", "event_type": "price_change"}}
{"_local_timestamp": "2026-01-25T23:43:25.751355+00:00", "data": {"market": "0x20e3bf2810db76a48bb4b915bf85ec43070a54da46f7ee9f123bde8b95add82c", "price_changes": [{"asset_id": "113173738354606351153328793226311936686716030058934510835145939200861029046537", "price": "0.151", "size": "9.01", "side": "BUY", "hash": "7d9035c866ccd1dab16ea72dd61e2d37461b8587", "best_bid": "0.954", "best_ask": "0.991"}, {"asset_id": "111833791713605298141350391268557048852627695992567917532719982369837309341050", "price": "0.849", "size": "9.01", "side": "SELL", "hash": "e92f1065d18e616e152fdb06b7b23ba2445ab6cb", "best_bid": "0.009", "best_ask": "0.046"}], "timestamp": "1769384605640", "event_type": "price_change"}}
{"_local_timestamp": "2026-01-25T23:43:29.082854+00:00", "data": {"market": "0xb8d1c3c2cbba18e247a379454e72d31129863a4dc123736926c6d991599a81b2", "price_changes": [{"asset_id": "21556602496211379227261801086635856748340201761487403620294012091632507009663", "price": "0.603", "size": "0", "side": "BUY", "hash": "1c5bf37db249b93ce7eda9a10e7ca23f9592351b", "best_bid": "0.998", "best_ask": "0.999"}, {"asset_id": "65423010509110378012139184005666383471785256194188331590421933980074567091246", "price": "0.397", "size": "0", "side": "SELL", "hash": "2b52323fbcb522031ed0e84ab396ed379744f767", "best_bid": "0.001", "best_ask": "0.002"}], "timestamp": "1769384608946", "event_type": "price_change"}}
{"_local_timestamp": "2026-01-25T23:43:29.195475+00:00", "data": {"market": "0xa62558c07dee376f7903e95977b10c13544d3546eeae6c98130839753e093979", "price_changes": [{"asset_id": "35970432242453970638378005355807025798529538734302331296289043262158829773976", "price": "0.724", "size": "0", "side": "BUY", "hash": "547f73cdcc474138367b482e857fd53df7363b30", "best_bid": "0.993", "best_ask": "0.997"}, {"asset_id": "72574656434993840186445307554025381492285372432846424590534736075839686478597", "price": "0.276", "size": "0", "side": "SELL", "hash": "5895ab6a909b09b96423d833f8e0df7acbdce2ac", "best_bid": "0.003", "best_ask": "0.007"}], "timestamp": "1769384609077", "event_type": "price_change"}}
{"_local_timestamp": "2026-01-25T23:43:29.263021+00:00", "data": {"market": "0xb8d1c3c2cbba18e247a379454e72d31129863a4dc123736926c6d991599a81b2", "price_changes": [{"asset_id": "21556602496211379227261801086635856748340201761487403620294012091632507009663", "price": "0.525", "size": "0", "side": "BUY", "hash": "c448ae3b87b9e9de1989657242bc4cc112bd0d3f", "best_bid": "0.998", "best_ask": "0.999"}, {"asset_id": "65423010509110378012139184005666383471785256194188331590421933980074567091246", "price": "0.475", "size": "0", "side": "SELL", "hash": "25f2c8e7708bdc37294c9755e26504a3878ef41b", "best_bid": "0.001", "best_ask": "0.002"}], "timestamp": "1769384609165", "event_type": "price_change"}}
{"_local_timestamp": "2026-01-25T23:43:29.388578+00:00", "data": {"market": "0xa62558c07dee376f7903e95977b10c13544d3546eeae6c98130839753e093979", "price_changes": [{"asset_id": "35970432242453970638378005355807025798529538734302331296289043262158829773976", "price": "0.726", "size": "7", "side": "BUY", "hash": "a678972f241301fcc8d1176a69b0b1073ab705bd", "best_bid": "0.993", "best_ask": "0.997"}, {"asset_id": "72574656434993840186445307554025381492285372432846424590534736075839686478597", "price": "0.274", "size": "7", "side": "SELL", "hash": "7fd6953fe546d796964275b45b42242d2ce91280", "best_bid": "0.003", "best_ask": "0.007"}], "timestamp": "1769384609296", "event_type": "price_change"}}
{"_local_timestamp": "2026-01-25T23:43:29.394254+00:00", "data": {"market": "0xa62558c07dee376f7903e95977b10c13544d3546eeae6c98130839753e093979", "price_changes": [{"asset_id": "35970432242453970638378005355807025798529538734302331296289043262158829773976", "price": "0.726", "size": "14", "side": "BUY", "hash": "9b7c5b4b214a05989db9a9e3ae2af9953472e04e", "best_bid": "0.993", "best_ask": "0.997"}, {"asset_id": "72574656434993840186445307554025381492285372432846424590534736075839686478597", "price": "0.274", "size": "14", "side": "SELL", "hash": "139fc60aebc747f81c37b5d1644ccfdbca855721", "best_bid": "0.003", "best_ask": "0.007"}], "timestamp": "1769384609299", "event_type": "price_change"}}
{"_local_timestamp": "2026-01-25T23:43:29.462037+00:00", "data": {"market": "0xb8d1c3c2cbba18e247a379454e72d31129863a4dc123736926c6d991599a81b2", "price_changes": [{"asset_id": "21556602496211379227261801086635856748340201761487403620294012091632507009663", "price": "0.205", "size": "0", "side": "BUY", "hash": "188ea56cfd9aca15954b2f500581d53d41be9a64", "best_bid": "0.998", "best_ask": "0.999"}, {"asset_id": "65423010509110378012139184005666383471785256194188331590421933980074567091246", "price": "0.795", "size": "0", "side": "SELL", "hash": "8655449e07d1551bca1a429f3c2bdc0548816c9a", "best_bid": "0.001", "best_ask": "0.002"}], "timestamp": "1769384609364", "event_type": "price_change"}}
{"_local_timestamp": "2026-01-25T23:43:29.674752+00:00", "data": {"market": "0xb8d1c3c2cbba18e247a379454e72d31129863a4dc123736926c6d991599a81b2", "price_changes": [{"asset_id": "21556602496211379227261801086635856748340201761487403620294012091632507009663", "price": "0.087", "size": "0", "side": "BUY", "hash": "0f44890ee2478afaac415b26cc1e4dd1c7a5f925", "best_bid": "0.998", "best_ask": "0.999"}, {"asset_id": "65423010509110378012139184005666383471785256194188331590421933980074567091246", "price": "0.913", "size": "0", "side": "SELL", "hash": "92ec83fe83388320047714015531a06d0b4b3dbd", "best_bid": "0.001", "best_ask": "0.002"}], "timestamp": "1769384609576", "event_type": "price_change"}}
{"_local_timestamp": "2026-01-25T23:43:29.867152+00:00", "data": {"market": "0xb8d1c3c2cbba18e247a379454e72d31129863a4dc123736926c6d991599a81b2", "price_changes": [{"asset_id": "21556602496211379227261801086635856748340201761487403620294012091632507009663", "price": "0.031", "size": "700", "side": "BUY", "hash": "a672419b20403d16afd408a8bf2e3b252fa331af", "best_bid": "0.998", "best_ask": "0.999"}, {"asset_id": "65423010509110378012139184005666383471785256194188331590421933980074567091246", "price": "0.969", "size": "700", "side": "SELL", "hash": "842a504d1329b3691b84a4becd24d1104ddd7f26", "best_bid": "0.001", "best_ask": "0.002"}], "timestamp": "1769384609768", "event_type": "price_change"}}
{"_local_timestamp": "2026-01-25T23:43:30.061707+00:00", "data": {"market": "0xb8d1c3c2cbba18e247a379454e72d31129863a4dc123736926c6d991599a81b2", "price_changes": [{"asset_id": "21556602496211379227261801086635856748340201761487403620294012091632507009663", "price": "0.135", "size": "0", "side": "BUY", "hash": "7763c133dc2d34e4a87e7131336fe5816b99b166", "best_bid": "0.998", "best_ask": "0.999"}, {"asset_id": "65423010509110378012139184005666383471785256194188331590421933980074567091246", "price": "0.865", "size": "0", "side": "SELL", "hash": "afd208bbd60103b0e22ffcab43ddf0f28ab50fd4", "best_bid": "0.001", "best_ask": "0.002"}], "timestamp": "1769384609968", "event_type": "price_change"}}
{"_local_timestamp": "2026-01-25T23:43:30.078733+00:00", "data": {"market": "0xfc84b2b625589cc280cd7cde401696c99505639812c83bb28b0824fbb297b06f", "price_changes": [{"asset_id": "70308869496420061197588382992609071299857414289715415451156362981997068041038", "price": "0.592", "size": "0", "side": "BUY", "hash": "10ce890e33df3f6ed0c5cb32871cb31fda02493f", "best_bid": "0.997", "best_ask": "0.999"}, {"asset_id": "82115621880923175579102966718566549811955421198728744722120513236749387693264", "price": "0.408", "size": "0", "side": "SELL", "hash": "28b1acee38cc6709e27e4b68b8f22a886e871198", "best_bid": "0.001", "best_ask": "0.003"}], "timestamp": "1769384609979", "event_type": "price_change"}}
{"_local_timestamp": "2026-01-25T23:43:30.157778+00:00", "data": {"market": "0xfc84b2b625589cc280cd7cde401696c99505639812c83bb28b0824fbb297b06f", "price_changes": [{"asset_id": "70308869496420061197588382992609071299857414289715415451156362981997068041038", "price": "0.604", "size": "5", "side": "BUY", "hash": "3ba103ea816399b71c413b4c6e80aa568f94da34", "best_bid": "0.997", "best_ask": "0.999"}, {"asset_id": "82115621880923175579102966718566549811955421198728744722120513236749387693264", "price": "0.396", "size": "5", "side": "SELL", "hash": "e23b826401600541e6e483f0cb36a9384b7093df", "best_bid": "0.001", "best_ask": "0.003"}], "timestamp": "1769384610032", "event_type": "price_change"}}
{"_local_timestamp": "2026-01-25T23:43:30.235355+00:00", "data": {"market": "0xa62558c07dee376f7903e95977b10c13544d3546eeae6c98130839753e093979", "price_changes": [{"asset_id": "35970432242453970638378005355807025798529538734302331296289043262158829773976", "price": "0.725", "size": "0", "side": "BUY", "hash": "1ae42b2ea951a6e5f911127434304e87812ea6b7", "best_bid": "0.993", "best_ask": "0.997"}, {"asset_id": "72574656434993840186445307554025381492285372432846424590534736075839686478597", "price": "0.275", "size": "0", "side": "SELL", "hash": "785387c0fbac00edd93d3c8e5d70ec68e43702cc", "best_bid": "0.003", "best_ask": "0.007"}], "timestamp": "1769384610131", "event_type": "price_change"}}
{"_local_timestamp": "2026-01-25T23:43:30.251193+00:00", "data": {"market": "0xa62558c07dee376f7903e95977b10c13544d3546eeae6c98130839753e093979", "price_changes": [{"asset_id": "35970432242453970638378005355807025798529538734302331296289043262158829773976", "price": "0.727", "size": "20", "side": "BUY", "hash": "af09e895f061f6328b024132c2681f502b0e8b08", "best_bid": "0.993", "best_ask": "0.997"}, {"asset_id": "72574656434993840186445307554025381492285372432846424590534736075839686478597", "price": "0.273", "size": "20", "side": "SELL", "hash": "602333bba33b392a63785698e6eb6f728958847d", "best_bid": "0.003", "best_ask": "0.007"}], "timestamp": "1769384610158", "event_type": "price_change"}}
{"_local_timestamp": "2026-01-25T23:43:30.274613+00:00", "data": {"market": "0xb8d1c3c2cbba18e247a379454e72d31129863a4dc123736926c6d991599a81b2", "price_changes": [{"asset_id": "21556602496211379227261801086635856748340201761487403620294012091632507009663", "price": "0.033", "size": "207.79", "side": "BUY", "hash": "5a48e949107724370be2c33098ee6e9433167942", "best_bid": "0.998", "best_ask": "0.999"}, {"asset_id": "65423010509110378012139184005666383471785256194188331590421933980074567091246", "price": "0.967", "size": "207.79", "side": "SELL", "hash": "446944bd1483d5f571052753b5223655f57785f5", "best_bid": "0.001", "best_ask": "0.002"}], "timestamp": "1769384610183", "event_type": "price_change"}}
{"_local_timestamp": "2026-01-25T23:43:30.505150+00:00", "data": {"market": "0xb8d1c3c2cbba18e247a379454e72d31129863a4dc123736926c6d991599a81b2", "price_changes": [{"asset_id": "21556602496211379227261801086635856748340201761487403620294012091632507009663", "price": "0.089", "size": "77.04", "side": "BUY", "hash": "70dacdb2a27d2b6d9cca9a81b9957cb020d34600", "best_bid": "0.998", "best_ask": "0.999"}, {"asset_id": "65423010509110378012139184005666383471785256194188331590421933980074567091246", "price": "0.911", "size": "77.04", "side": "SELL", "hash": "8ad65f063c0466e883509aed94c2ff5f4bdaa936", "best_bid": "0.001", "best_ask": "0.002"}], "timestamp": "1769384610415", "event_type": "price_change"}}
{"_local_timestamp": "2026-01-25T23:43:30.735625+00:00", "data": {"market": "0xb8d1c3c2cbba18e247a379454e72d31129863a4dc123736926c6d991599a81b2", "price_changes": [{"asset_id": "21556602496211379227261801086635856748340201761487403620294012091632507009663", "price": "0.137", "size": "50.05", "side": "BUY", "hash": "ec7f517f82f6a7d3ac61ec69f7423276d8a216cb", "best_bid": "0.998", "best_ask": "0.999"}, {"asset_id": "65423010509110378012139184005666383471785256194188331590421933980074567091246", "price": "0.863", "size": "50.05", "side": "SELL", "hash": "e4706039bc8f68623f57062d8924ea8543454bb0", "best_bid": "0.001", "best_ask": "0.002"}], "timestamp": "1769384610639", "event_type": "price_change"}}
{"_local_timestamp": "2026-01-25T23:43:30.955611+00:00", "data": {"market": "0xb8d1c3c2cbba18e247a379454e72d31129863a4dc123736926c6d991599a81b2", "price_changes": [{"asset_id": "21556602496211379227261801086635856748340201761487403620294012091632507009663", "price": "0.207", "size": "33.12", "side": "BUY", "hash": "f2321db74214b18ee6100508c832fc52aaffbf09", "best_bid": "0.998", "best_ask": "0.999"}, {"asset_id": "65423010509110378012139184005666383471785256194188331590421933980074567091246", "price": "0.793", "size": "33.12", "side": "SELL", "hash": "f85ed60621cc2b7655eae1c023c80f03c3125a33", "best_bid": "0.001", "best_ask": "0.002"}], "timestamp": "1769384610858", "event_type": "price_change"}}
{"_local_timestamp": "2026-01-25T23:43:31.179827+00:00", "data": {"market": "0xb8d1c3c2cbba18e247a379454e72d31129863a4dc123736926c6d991599a81b2", "price_changes": [{"asset_id": "21556602496211379227261801086635856748340201761487403620294012091632507009663", "price": "0.527", "size": "13.01", "side": "BUY", "hash": "19d4cf206e9de1835d3ac3eef209d44a78e1b653", "best_bid": "0.998", "best_ask": "0.999"}, {"asset_id": "65423010509110378012139184005666383471785256194188331590421933980074567091246", "price": "0.473", "size": "13.01", "side": "SELL", "hash": "23568fd78c8d5992c78bf7344f073ccc8962adc2", "best_bid": "0.001", "best_ask": "0.002"}], "timestamp": "1769384611083", "event_type": "price_change"}}
{"_local_timestamp": "2026-01-25T23:43:31.414991+00:00", "data": {"market": "0xb8d1c3c2cbba18e247a379454e72d31129863a4dc123736926c6d991599a81b2", "price_changes": [{"asset_id": "21556602496211379227261801086635856748340201761487403620294012091632507009663", "price": "0.606", "size": "31.31", "side": "BUY", "hash": "87be123b14abfdc84dc767d83d4e6edd6c77d155", "best_bid": "0.998", "best_ask": "0.999"}, {"asset_id": "65423010509110378012139184005666383471785256194188331590421933980074567091246", "price": "0.394", "size": "31.31", "side": "SELL", "hash": "f597c843b891c5402d51115fdf0b0d5eed4f800e", "best_bid": "0.001", "best_ask": "0.002"}], "timestamp": "1769384611313", "event_type": "price_change"}}
{"_local_timestamp": "2026-01-25T23:43:33.785705+00:00", "data": {"market": "0x50fa9155b39b1f6d3041ad01296611ff7fcd7e06accc6dba1ea4458f95e6e637", "price_changes": [{"asset_id": "13555099753310315836647270533686894971487275612829883232907522152970188644136", "price": "0.654", "size": "0", "side": "BUY", "hash": "1f9766172ba8c4cd8881c316150c9ee9097e7efd", "best_bid": "0.996", "best_ask": "0.997"}, {"asset_id": "10645904022643906852973817125982125793552212677082290653082149741205114933184", "price": "0.346", "size": "0", "side": "SELL", "hash": "a144fd9f7c85ce75d8bf9962d82ad68381ab42fc", "best_bid": "0.003", "best_ask": "0.004"}], "timestamp": "1769384613700", "event_type": "price_change"}}
{"_local_timestamp": "2026-01-25T23:43:33.986326+00:00", "data": {"market": "0x50fa9155b39b1f6d3041ad01296611ff7fcd7e06accc6dba1ea4458f95e6e637", "price_changes": [{"asset_id": "13555099753310315836647270533686894971487275612829883232907522152970188644136", "price": "0.595", "size": "0", "side": "BUY", "hash": "3940bb6894a197b4fb02da02eeb8925076f817be", "best_bid": "0.996", "best_ask": "0.997"}, {"asset_id": "10645904022643906852973817125982125793552212677082290653082149741205114933184", "price": "0.405", "size": "0", "side": "SELL", "hash": "4d21545f4c4ace767c4868597e7c784237854f03", "best_bid": "0.003", "best_ask": "0.004"}], "timestamp": "1769384613896", "event_type": "price_change"}}
{"_local_timestamp": "2026-01-25T23:43:34.207008+00:00", "data": {"market": "0x50fa9155b39b1f6d3041ad01296611ff7fcd7e06accc6dba1ea4458f95e6e637", "price_changes": [{"asset_id": "13555099753310315836647270533686894971487275612829883232907522152970188644136", "price": "0.152", "size": "0", "side": "BUY", "hash": "d40197cc2e4a8d57e20ef1c95fcb629d88384267", "best_bid": "0.996", "best_ask": "0.997"}, {"asset_id": "10645904022643906852973817125982125793552212677082290653082149741205114933184", "price": "0.848", "size": "0", "side": "SELL", "hash": "17385ae9fb34f922e7511c512f36eb37162f4d32", "best_bid": "0.003", "best_ask": "0.004"}], "timestamp": "1769384614114", "event_type": "price_change"}}
{"_local_timestamp": "2026-01-25T23:43:34.381833+00:00", "data": {"market": "0x50fa9155b39b1f6d3041ad01296611ff7fcd7e06accc6dba1ea4458f95e6e637", "price_changes": [{"asset_id": "13555099753310315836647270533686894971487275612829883232907522152970188644136", "price": "0.066", "size": "0", "side": "BUY", "hash": "0d7526ca5a69e7683974eb29afcd9d3519bd9041", "best_bid": "0.996", "best_ask": "0.997"}, {"asset_id": "10645904022643906852973817125982125793552212677082290653082149741205114933184", "price": "0.934", "size": "0", "side": "SELL", "hash": "22d681ab99f28db5e7bfeb196e1d6511a2a476fd", "best_bid": "0.003", "best_ask": "0.004"}], "timestamp": "1769384614291", "event_type": "price_change"}}
{"_local_timestamp": "2026-01-25T23:43:34.581282+00:00", "data": {"market": "0x50fa9155b39b1f6d3041ad01296611ff7fcd7e06accc6dba1ea4458f95e6e637", "price_changes": [{"asset_id": "13555099753310315836647270533686894971487275612829883232907522152970188644136", "price": "0.03", "size": "0", "side": "BUY", "hash": "b68575e54ec0f4254679a0c875551a8fd39fc29b", "best_bid": "0.996", "best_ask": "0.997"}, {"asset_id": "10645904022643906852973817125982125793552212677082290653082149741205114933184", "price": "0.97", "size": "0", "side": "SELL", "hash": "93cdd3fdf1b9f5c185243c7e7d12851f2eae5873", "best_bid": "0.003", "best_ask": "0.004"}], "timestamp": "1769384614497", "event_type": "price_change"}}
{"_local_timestamp": "2026-01-25T23:43:34.806610+00:00", "data": {"market": "0x50fa9155b39b1f6d3041ad01296611ff7fcd7e06accc6dba1ea4458f95e6e637", "price_changes": [{"asset_id": "13555099753310315836647270533686894971487275612829883232907522152970188644136", "price": "0.032", "size": "250", "side": "BUY", "hash": "2c2a9f67363cae9f2db2e19235490b01adbc79b4", "best_bid": "0.996", "best_ask": "0.997"}, {"asset_id": "10645904022643906852973817125982125793552212677082290653082149741205114933184", "price": "0.968", "size": "250", "side": "SELL", "hash": "50122d008cbf97deab595bcbb8f1abf8b50c2511", "best_bid": "0.003", "best_ask": "0.004"}], "timestamp": "1769384614716", "event_type": "price_change"}}
{"_local_timestamp": "2026-01-25T23:43:35.010419+00:00", "data": {"market": "0x50fa9155b39b1f6d3041ad01296611ff7fcd7e06accc6dba1ea4458f95e6e637", "price_changes": [{"asset_id": "13555099753310315836647270533686894971487275612829883232907522152970188644136", "price": "0.068", "size": "117.64", "side": "BUY", "hash": "234cb8a480705f4bac34cf7a1f0d25b39e35ede6", "best_bid": "0.996", "best_ask": "0.997"}, {"asset_id": "10645904022643906852973817125982125793552212677082290653082149741205114933184", "price": "0.932", "size": "117.64", "side": "SELL", "hash": "f8b7713d4e05b5ab04936e957fd7268b922c7a0b", "best_bid": "0.003", "best_ask": "0.004"}], "timestamp": "1769384614921", "event_type": "price_change"}}
{"_local_timestamp": "2026-01-25T23:43:35.224955+00:00", "data": {"market": "0x50fa9155b39b1f6d3041ad01296611ff7fcd7e06accc6dba1ea4458f95e6e637", "price_changes": [{"asset_id": "13555099753310315836647270533686894971487275612829883232907522152970188644136", "price": "0.154", "size": "51.94", "side": "BUY", "hash": "ebabc13f083db6c943c2d5ee732cc6f35bebf711", "best_bid": "0.996", "best_ask": "0.997"}, {"asset_id": "10645904022643906852973817125982125793552212677082290653082149741205114933184", "price": "0.846", "size": "51.94", "side": "SELL", "hash": "c4065ce96e904eb8aabea37a77a1033ed2e108d7", "best_bid": "0.003", "best_ask": "0.004"}], "timestamp": "1769384615138", "event_type": "price_change"}}
{"_local_timestamp": "2026-01-25T23:43:35.431762+00:00", "data": {"market": "0x50fa9155b39b1f6d3041ad01296611ff7fcd7e06accc6dba1ea4458f95e6e637", "price_changes": [{"asset_id": "13555099753310315836647270533686894971487275612829883232907522152970188644136", "price": "0.597", "size": "13.4", "side": "BUY", "hash": "e5be18d3d84c14cf0a2afedafa0e4c653cee1c8e", "best_bid": "0.996", "best_ask": "0.997"}, {"asset_id": "10645904022643906852973817125982125793552212677082290653082149741205114933184", "price": "0.403", "size": "13.4", "side": "SELL", "hash": "9231095ae4ae5a8dca730cb4e883c559f690a0e2", "best_bid": "0.003", "best_ask": "0.004"}], "timestamp": "1769384615347", "event_type": "price_change"}}
{"_local_timestamp": "2026-01-25T23:43:35.636754+00:00", "data": {"market": "0x50fa9155b39b1f6d3041ad01296611ff7fcd7e06accc6dba1ea4458f95e6e637", "price_changes": [{"asset_id": "13555099753310315836647270533686894971487275612829883232907522152970188644136", "price": "0.66", "size": "12.12", "side": "BUY", "hash": "58da5ae0424baab8781e8611b5917101b38af6dc", "best_bid": "0.996", "best_ask": "0.997"}, {"asset_id": "10645904022643906852973817125982125793552212677082290653082149741205114933184", "price": "0.34", "size": "12.12", "side": "SELL", "hash": "9a71377fb30fb4090e7d1b05914ff7c2adce6d70", "best_bid": "0.003", "best_ask": "0.004"}], "timestamp": "1769384615551", "event_type": "price_change"}}
{"_local_timestamp": "2026-01-25T23:43:36.398209+00:00", "data": {"market": "0x50fa9155b39b1f6d3041ad01296611ff7fcd7e06accc6dba1ea4458f95e6e637", "price_changes": [{"asset_id": "13555099753310315836647270533686894971487275612829883232907522152970188644136", "price": "0.031", "size": "0", "side": "BUY", "hash": "199e3eab59ffb7b2c9b576437bca0f9ad716c826", "best_bid": "0.996", "best_ask": "0.997"}, {"asset_id": "10645904022643906852973817125982125793552212677082290653082149741205114933184", "price": "0.969", "size": "0", "side": "SELL", "hash": "f5090307b2fdcf798fbd1caf6af1f16cfb529a53", "best_bid": "0.003", "best_ask": "0.004"}], "timestamp": "1769384616308", "event_type": "price_change"}}
{"_local_timestamp": "2026-01-25T23:43:36.399299+00:00", "data": {"market": "0x50fa9155b39b1f6d3041ad01296611ff7fcd7e06accc6dba1ea4458f95e6e637", "price_changes": [{"asset_id": "13555099753310315836647270533686894971487275612829883232907522152970188644136", "price": "0.067", "size": "0", "side": "BUY", "hash": "199e3eab59ffb7b2c9b576437bca0f9ad716c826", "best_bid": "0.996", "best_ask": "0.997"}, {"asset_id": "10645904022643906852973817125982125793552212677082290653082149741205114933184", "price": "0.933", "size": "0", "side": "SELL", "hash": "f5090307b2fdcf798fbd1caf6af1f16cfb529a53", "best_bid": "0.003", "best_ask": "0.004"}], "timestamp": "1769384616308", "event_type": "price_change"}}
{"_local_timestamp": "2026-01-25T23:43:36.400257+00:00", "data": {"market": "0x50fa9155b39b1f6d3041ad01296611ff7fcd7e06accc6dba1ea4458f95e6e637", "price_changes": [{"asset_id": "13555099753310315836647270533686894971487275612829883232907522152970188644136", "price": "0.153", "size": "0", "side": "BUY", "hash": "199e3eab59ffb7b2c9b576437bca0f9ad716c826", "best_bid": "0.996", "best_ask": "0.997"}, {"asset_id": "10645904022643906852973817125982125793552212677082290653082149741205114933184", "price": "0.847", "size": "0", "side": "SELL", "hash": "f5090307b2fdcf798fbd1caf6af1f16cfb529a53", "best_bid": "0.003", "best_ask": "0.004"}], "timestamp": "1769384616308", "event_type": "price_change"}}
{"_local_timestamp": "2026-01-25T23:43:37.047756+00:00", "data": {"market": "0x50fa9155b39b1f6d3041ad01296611ff7fcd7e06accc6dba1ea4458f95e6e637", "price_changes": [{"asset_id": "13555099753310315836647270533686894971487275612829883232907522152970188644136", "price": "0.155", "size": "10.47", "side": "BUY", "hash": "52e38149e7cd71c4dedece994f89abe36d416c39", "best_bid": "0.996", "best_ask": "0.997"}, {"asset_id": "10645904022643906852973817125982125793552212677082290653082149741205114933184", "price": "0.845", "size": "10.47", "side": "SELL", "hash": "138da096fc6bc2940d28d0ca1890bad44e98df8b", "best_bid": "0.003", "best_ask": "0.004"}], "timestamp": "1769384616973", "event_type": "price_change"}}
{"_local_timestamp": "2026-01-25T23:43:37.059296+00:00", "data": {"market": "0x50fa9155b39b1f6d3041ad01296611ff7fcd7e06accc6dba1ea4458f95e6e637", "price_changes": [{"asset_id": "13555099753310315836647270533686894971487275612829883232907522152970188644136", "price": "0.025", "size": "9.78", "side": "BUY", "hash": "545a28e32bda6257cdbbc44308c8577494653ae1", "best_bid": "0.996", "best_ask": "0.997"}, {"asset_id": "10645904022643906852973817125982125793552212677082290653082149741205114933184", "price": "0.975", "size": "9.78", "side": "SELL", "hash": "ba71563f9a2e1ecadd129add7835151318395dd2", "best_bid": "0.003", "best_ask": "0.004"}], "timestamp": "1769384616974", "event_type": "price_change"}}
{"_local_timestamp": "2026-01-25T23:43:37.249329+00:00", "data": {"market": "0x50fa9155b39b1f6d3041ad01296611ff7fcd7e06accc6dba1ea4458f95e6e637", "price_changes": [{"asset_id": "13555099753310315836647270533686894971487275612829883232907522152970188644136", "price": "0.659", "size": "0", "side": "BUY", "hash": "039d42326a19281a36e269a64b5c73de1cd8a1e7", "best_bid": "0.996", "best_ask": "0.997"}, {"asset_id": "10645904022643906852973817125982125793552212677082290653082149741205114933184", "price": "0.341", "size": "0", "side": "SELL", "hash": "3368d8140818d1f55e925fafbedb9c4d956a3bc1", "best_bid": "0.003", "best_ask": "0.004"}], "timestamp": "1769384617171", "event_type": "price_change"}}
{"_local_timestamp": "2026-01-25T23:43:37.270733+00:00", "data": {"market": "0x50fa9155b39b1f6d3041ad01296611ff7fcd7e06accc6dba1ea4458f95e6e637", "price_changes": [{"asset_id": "13555099753310315836647270533686894971487275612829883232907522152970188644136", "price": "0.661", "size": "20", "side": "BUY", "hash": "71fd7be3c404f9691bdd2c3b04330600cc2d0443", "best_bid": "0.996", "best_ask": "0.997"}, {"asset_id": "10645904022643906852973817125982125793552212677082290653082149741205114933184", "price": "0.339", "size": "20", "side": "SELL", "hash": "7d39d78e9a5ca13ff180c0b4fdf544b450a6f6a9", "best_bid": "0.003", "best_ask": "0.004"}], "timestamp": "1769384617195", "event_type": "price_change"}}
{"_local_timestamp": "2026-01-25T23:43:44.537661+00:00", "data": {"market": "0xb3f0b0a92040f41a6aca44e3f909e0236c2687ad29ca77cfd3710c83071b74c9", "price_changes": [{"asset_id": "60676933420233144798971210692068617567292894076124499641040029783755014286821", "price": "0.243", "size": "0", "side": "BUY", "hash": "5a488ac9b2b149b208a54cfc343d4dccbead8f16", "best_bid": "0.996", "best_ask": "0.998"}, {"asset_id": "104582508148424115897511334519834707085901645295166805533084841423912878555712", "price": "0.757", "size": "0", "side": "SELL", "hash": "def34572f31d9928059480b20b5b588a98981f19", "best_bid": "0.002", "best_ask": "0.004"}], "timestamp": "1769384624465", "event_type": "price_change"}}
{"_local_timestamp": "2026-01-25T23:43:44.738219+00:00", "data": {"market": "0xb3f0b0a92040f41a6aca44e3f909e0236c2687ad29ca77cfd3710c83071b74c9", "price_changes": [{"asset_id": "60676933420233144798971210692068617567292894076124499641040029783755014286821", "price": "0.181", "size": "0", "side": "BUY", "hash": "b28103f1ae021c077bb8e56175a9176a6df62f7a", "best_bid": "0.996", "best_ask": "0.998"}, {"asset_id": "104582508148424115897511334519834707085901645295166805533084841423912878555712", "price": "0.819", "size": "0", "side": "SELL", "hash": "6061c38593c9d8544a79f9f2aa556f2df609680f", "best_bid": "0.002", "best_ask": "0.004"}], "timestamp": "1769384624667", "event_type": "price_change"}}
{"_local_timestamp": "2026-01-25T23:43:44.917001+00:00", "data": {"market": "0xb3f0b0a92040f41a6aca44e3f909e0236c2687ad29ca77cfd3710c83071b74c9", "price_changes": [{"asset_id": "60676933420233144798971210692068617567292894076124499641040029783755014286821", "price": "0.075", "size": "0", "side": "BUY", "hash": "115896139b1945f5f9f8fbb9fe92fe1113a2ae4e", "best_bid": "0.996", "best_ask": "0.998"}, {"asset_id": "104582508148424115897511334519834707085901645295166805533084841423912878555712", "price": "0.925", "size": "0", "side": "SELL", "hash": "9c07636df3491697a316128e65532dcd8962415d", "best_bid": "0.002", "best_ask": "0.004"}], "timestamp": "1769384624850", "event_type": "price_change"}}
{"_local_timestamp": "2026-01-25T23:43:45.106410+00:00", "data": {"market": "0xb3f0b0a92040f41a6aca44e3f909e0236c2687ad29ca77cfd3710c83071b74c9", "price_changes": [{"asset_id": "60676933420233144798971210692068617567292894076124499641040029783755014286821", "price": "0.029", "size": "0", "side": "BUY", "hash": "ea3a7fe7d05d84e732086210a377b39a1de5489c", "best_bid": "0.996", "best_ask": "0.998"}, {"asset_id": "104582508148424115897511334519834707085901645295166805533084841423912878555712", "price": "0.971", "size": "0", "side": "SELL", "hash": "18fe6a032e12dc7a848e3a043884a812a9e12c15", "best_bid": "0.002", "best_ask": "0.004"}], "timestamp": "1769384625038", "event_type": "price_change"}}
{"_local_timestamp": "2026-01-25T23:43:45.356680+00:00", "data": {"market": "0xb3f0b0a92040f41a6aca44e3f909e0236c2687ad29ca77cfd3710c83071b74c9", "price_changes": [{"asset_id": "60676933420233144798971210692068617567292894076124499641040029783755014286821", "price": "0.031", "size": "221.19", "side": "BUY", "hash": "62dc6ad6495cb7ab0a5e1e4727b3d4ffbe893840", "best_bid": "0.996", "best_ask": "0.998"}, {"asset_id": "104582508148424115897511334519834707085901645295166805533084841423912878555712", "price": "0.969", "size": "221.19", "side": "SELL", "hash": "2190048c56ec4c1b58d8a70f0647224eb9944a3f", "best_bid": "0.002", "best_ask": "0.004"}], "timestamp": "1769384625250", "event_type": "price_change"}}
{"_local_timestamp": "2026-01-25T23:43:45.601153+00:00", "data": {"market": "0xb3f0b0a92040f41a6aca44e3f909e0236c2687ad29ca77cfd3710c83071b74c9", "price_changes": [{"asset_id": "60676933420233144798971210692068617567292894076124499641040029783755014286821", "price": "0.077", "size": "89.05", "side": "BUY", "hash": "1886b130dd5669ee2ecd847dc0364646656cb27a", "best_bid": "0.996", "best_ask": "0.998"}, {"asset_id": "104582508148424115897511334519834707085901645295166805533084841423912878555712", "price": "0.923", "size": "89.05", "side": "SELL", "hash": "b8659f798bf0dae49fcbf69491b3ce3b243ba621", "best_bid": "0.002", "best_ask": "0.004"}], "timestamp": "1769384625437", "event_type": "price_change"}}
{"_local_timestamp": "2026-01-25T23:43:45.716134+00:00", "data": {"market": "0xb3f0b0a92040f41a6aca44e3f909e0236c2687ad29ca77cfd3710c83071b74c9", "price_changes": [{"asset_id": "60676933420233144798971210692068617567292894076124499641040029783755014286821", "price": "0.183", "size": "37.47", "side": "BUY", "hash": "cadb0deca209022c79368ff0047097dcd30e18b4", "best_bid": "0.996", "best_ask": "0.998"}, {"asset_id": "104582508148424115897511334519834707085901645295166805533084841423912878555712", "price": "0.817", "size": "37.47", "side": "SELL", "hash": "7f3118e8112eea893013b2e0d2c96928d293e78c", "best_bid": "0.002", "best_ask": "0.004"}], "timestamp": "1769384625646", "event_type": "price_change"}}
{"_local_timestamp": "2026-01-25T23:43:45.912154+00:00", "data": {"market": "0xb3f0b0a92040f41a6aca44e3f909e0236c2687ad29ca77cfd3710c83071b74c9", "price_changes": [{"asset_id": "60676933420233144798971210692068617567292894076124499641040029783755014286821", "price": "0.247", "size": "27.76", "side": "BUY", "hash": "55c95271aecb1e1b8a54e2acf58e2bccb698e42c", "best_bid": "0.996", "best_ask": "0.998"}, {"asset_id": "104582508148424115897511334519834707085901645295166805533084841423912878555712", "price": "0.753", "size": "27.76", "side": "SELL", "hash": "5760d5d1c1a38ce8cc7de78b8d322aee145199ca", "best_bid": "0.002", "best_ask": "0.004"}], "timestamp": "1769384625845", "event_type": "price_change"}}
{"_local_timestamp": "2026-01-25T23:43:46.106694+00:00", "data": {"market": "0x31967ab350da8f760c547a62ce495f63f04c7402ea2bc291f7358d6aa367fdd8", "price_changes": [{"asset_id": "74574612697917499641784436195980418240322600911590628796653263539397328153034", "price": "0.698", "size": "0", "side": "BUY", "hash": "5cd336ff3f6d82c5e8822e5030bbc3350f91c6f0", "best_bid": "0.938", "best_ask": "0.998"}, {"asset_id": "48096461703828524256164307708005083326532171684035677911193083899587188981253", "price": "0.302", "size": "0", "side": "SELL", "hash": "c516016f14a142633ca2a32a94913839006aa99f", "best_bid": "0.002", "best_ask": "0.062"}], "timestamp": "1769384626041", "event_type": "price_change"}}
{"_local_timestamp": "2026-01-25T23:43:46.308976+00:00", "data": {"market": "0x31967ab350da8f760c547a62ce495f63f04c7402ea2bc291f7358d6aa367fdd8", "price_changes": [{"asset_id": "74574612697917499641784436195980418240322600911590628796653263539397328153034", "price": "0.562", "size": "0", "side": "BUY", "hash": "7619860da69dc02cb8d95611f401222e17afbcb2", "best_bid": "0.938", "best_ask": "0.998"}, {"asset_id": "48096461703828524256164307708005083326532171684035677911193083899587188981253", "price": "0.438", "size": "0", "side": "SELL", "hash": "ef5f7ffe4915b6724922769576dd6e96ccb8337a", "best_bid": "0.002", "best_ask": "0.062"}], "timestamp": "1769384626236", "event_type": "price_change"}}
{"_local_timestamp": "2026-01-25T23:43:46.520868+00:00", "data": {"market": "0x31967ab350da8f760c547a62ce495f63f04c7402ea2bc291f7358d6aa367fdd8", "price_changes": [{"asset_id": "74574612697917499641784436195980418240322600911590628796653263539397328153034", "price": "0.211", "size": "0", "side": "BUY", "hash": "d04b9765e86c0d8f871c9d9af90d7f09df70340f", "best_bid": "0.938", "best_ask": "0.998"}, {"asset_id": "48096461703828524256164307708005083326532171684035677911193083899587188981253", "price": "0.789", "size": "0", "side": "SELL", "hash": "371263a5c7efefb12dffd831d3b53935be73b193", "best_bid": "0.002", "best_ask": "0.062"}], "timestamp": "1769384626419", "event_type": "price_change"}}
{"_local_timestamp": "2026-01-25T23:43:46.696164+00:00", "data": {"market": "0x31967ab350da8f760c547a62ce495f63f04c7402ea2bc291f7358d6aa367fdd8", "price_changes": [{"asset_id": "74574612697917499641784436195980418240322600911590628796653263539397328153034", "price": "0.098", "size": "500", "side": "BUY", "hash": "3f01bf0d313343a9c805da316ba63416ffcaa692", "best_bid": "0.938", "best_ask": "0.998"}, {"asset_id": "48096461703828524256164307708005083326532171684035677911193083899587188981253", "price": "0.902", "size": "500", "side": "SELL", "hash": "1cb080a6fac97662f902ea5c8028f9ce2acdb086", "best_bid": "0.002", "best_ask": "0.062"}], "timestamp": "1769384626628", "event_type": "price_change"}}
{"_local_timestamp": "2026-01-25T23:43:46.890944+00:00", "data": {"market": "0x31967ab350da8f760c547a62ce495f63f04c7402ea2bc291f7358d6aa367fdd8", "price_changes": [{"asset_id": "74574612697917499641784436195980418240322600911590628796653263539397328153034", "price": "0.058", "size": "500", "side": "BUY", "hash": "a5fbb74e205695d087dee3f6e3ba3f133b4b9dd4", "best_bid": "0.938", "best_ask": "0.998"}, {"asset_id": "48096461703828524256164307708005083326532171684035677911193083899587188981253", "price": "0.942", "size": "500", "side": "SELL", "hash": "af206d34c7ffd67e54b7339c4650faf00ae2bb2d", "best_bid": "0.002", "best_ask": "0.062"}], "timestamp": "1769384626819", "event_type": "price_change"}}
{"_local_timestamp": "2026-01-25T23:43:47.090085+00:00", "data": {"market": "0x31967ab350da8f760c547a62ce495f63f04c7402ea2bc291f7358d6aa367fdd8", "price_changes": [{"asset_id": "74574612697917499641784436195980418240322600911590628796653263539397328153034", "price": "0.06", "size": "133.33", "side": "BUY", "hash": "a2646ca2e50346436f8fc9f9dbef2e77c24b796e", "best_bid": "0.938", "best_ask": "0.998"}, {"asset_id": "48096461703828524256164307708005083326532171684035677911193083899587188981253", "price": "0.94", "size": "133.33", "side": "SELL", "hash": "719d17e19aba6da25bd90c0c7c25375dc76f82e9", "best_bid": "0.002", "best_ask": "0.062"}], "timestamp": "1769384627022", "event_type": "price_change"}}
{"_local_timestamp": "2026-01-25T23:43:47.305176+00:00", "data": {"market": "0x31967ab350da8f760c547a62ce495f63f04c7402ea2bc291f7358d6aa367fdd8", "price_changes": [{"asset_id": "74574612697917499641784436195980418240322600911590628796653263539397328153034", "price": "0.101", "size": "79.2", "side": "BUY", "hash": "6bbe26266b986abd24968a1e439ca40bb015398a", "best_bid": "0.938", "best_ask": "0.998"}, {"asset_id": "48096461703828524256164307708005083326532171684035677911193083899587188981253", "price": "0.899", "size": "79.2", "side": "SELL", "hash": "f4478e0b2096da0e7aa1131836cf75e0b70b5dce", "best_bid": "0.002", "best_ask": "0.062"}], "timestamp": "1769384627234", "event_type": "price_change"}}
{"_local_timestamp": "2026-01-25T23:43:47.519301+00:00", "data": {"market": "0x31967ab350da8f760c547a62ce495f63f04c7402ea2bc291f7358d6aa367fdd8", "price_changes": [{"asset_id": "74574612697917499641784436195980418240322600911590628796653263539397328153034", "price": "0.213", "size": "37.55", "side": "BUY", "hash": "45a5d62561f0ea0d2ff4017cedd589fece40601d", "best_bid": "0.938", "best_ask": "0.998"}, {"asset_id": "48096461703828524256164307708005083326532171684035677911193083899587188981253", "price": "0.787", "size": "37.55", "side": "SELL", "hash": "78d2aa482890cad76e40243081e5349dd2629b59", "best_bid": "0.002", "best_ask": "0.062"}], "timestamp": "1769384627453", "event_type": "price_change"}}
{"_local_timestamp": "2026-01-25T23:43:47.729843+00:00", "data": {"market": "0x31967ab350da8f760c547a62ce495f63f04c7402ea2bc291f7358d6aa367fdd8", "price_changes": [{"asset_id": "74574612697917499641784436195980418240322600911590628796653263539397328153034", "price": "0.565", "size": "34.15", "side": "BUY", "hash": "84aa16cd730dbc7d5b59f9a69bfed22e2f614750", "best_bid": "0.938", "best_ask": "0.998"}, {"asset_id": "48096461703828524256164307708005083326532171684035677911193083899587188981253", "price": "0.435", "size": "34.15", "side": "SELL", "hash": "a17ecee350449642d9a31daf5dbf87d6a5dd9a11", "best_bid": "0.002", "best_ask": "0.062"}], "timestamp": "1769384627661", "event_type": "price_change"}}
{"_local_timestamp": "2026-01-25T23:43:47.948318+00:00", "data": {"market": "0x31967ab350da8f760c547a62ce495f63f04c7402ea2bc291f7358d6aa367fdd8", "price_changes": [{"asset_id": "74574612697917499641784436195980418240322600911590628796653263539397328153034", "price": "0.7", "size": "21.42", "side": "BUY", "hash": "c325f746001e8d2c904521bcb709ee69a3da6d0a", "best_bid": "0.938", "best_ask": "0.998"}, {"asset_id": "48096461703828524256164307708005083326532171684035677911193083899587188981253", "price": "0.3", "size": "21.42", "side": "SELL", "hash": "f42b07e693c501a2489d7dd2fd6a86ab2cfc69f2", "best_bid": "0.002", "best_ask": "0.062"}], "timestamp": "1769384627881", "event_type": "price_change"}}
{"_local_timestamp": "2026-01-25T23:43:49.423474+00:00", "data": {"market": "0x388b017fa66c293566816b3f6253af6800ca69d6ab740ef019e5a69feacacf70", "price_changes": [{"asset_id": "68883925535903398159530799578268246684851592835366731124807972752959560431304", "price": "0.595", "size": "0", "side": "BUY", "hash": "d9c305c59cbd7516c3cc7a55a45643abfdee7659", "best_bid": "0.938", "best_ask": "0.993"}, {"asset_id": "49541604524685067034733103567606780662654635021473570692999975492153111969210", "price": "0.405", "size": "0", "side": "SELL", "hash": "2279ff5a97a2142433e32c6022bc5f2b6bfa2e09", "best_bid": "0.007", "best_ask": "0.062"}], "timestamp": "1769384629355", "event_type": "price_change"}}
{"_local_timestamp": "2026-01-25T23:43:49.627705+00:00", "data": {"market": "0x388b017fa66c293566816b3f6253af6800ca69d6ab740ef019e5a69feacacf70", "price_changes": [{"asset_id": "68883925535903398159530799578268246684851592835366731124807972752959560431304", "price": "0.18", "size": "0", "side": "BUY", "hash": "85725335f4fe51a4a365ccd5592eea5d9782640a", "best_bid": "0.938", "best_ask": "0.993"}, {"asset_id": "49541604524685067034733103567606780662654635021473570692999975492153111969210", "price": "0.82", "size": "0", "side": "SELL", "hash": "7927c53e12d47b3b49c488f5ed15eec083aadb57", "best_bid": "0.007", "best_ask": "0.062"}], "timestamp": "1769384629553", "event_type": "price_change"}}
{"_local_timestamp": "2026-01-25T23:43:49.840825+00:00", "data": {"market": "0x388b017fa66c293566816b3f6253af6800ca69d6ab740ef019e5a69feacacf70", "price_changes": [{"asset_id": "68883925535903398159530799578268246684851592835366731124807972752959560431304", "price": "0.179", "size": "0", "side": "BUY", "hash": "6c473eda75119745ada99a6e507d5da7374b81a2", "best_bid": "0.938", "best_ask": "0.993"}, {"asset_id": "49541604524685067034733103567606780662654635021473570692999975492153111969210", "price": "0.821", "size": "0", "side": "SELL", "hash": "bd7d31a30d89475d403ee9c6c2dfc9ddb0b21cb2", "best_bid": "0.007", "best_ask": "0.062"}], "timestamp": "1769384629753", "event_type": "price_change"}}
{"_local_timestamp": "2026-01-25T23:43:50.067853+00:00", "data": {"market": "0x388b017fa66c293566816b3f6253af6800ca69d6ab740ef019e5a69feacacf70", "price_changes": [{"asset_id": "68883925535903398159530799578268246684851592835366731124807972752959560431304", "price": "0.061", "size": "0", "side": "BUY", "hash": "36d49cc22928ff49ad72157ff78e9cbf7d61566f", "best_bid": "0.938", "best_ask": "0.993"}, {"asset_id": "49541604524685067034733103567606780662654635021473570692999975492153111969210", "price": "0.939", "size": "0", "side": "SELL", "hash": "f9bf10ea6e8de74c0446f66b0276a2e52841caa7", "best_bid": "0.007", "best_ask": "0.062"}], "timestamp": "1769384629971", "event_type": "price_change"}}
{"_local_timestamp": "2026-01-25T23:43:50.964139+00:00", "data": {"market": "0x388b017fa66c293566816b3f6253af6800ca69d6ab740ef019e5a69feacacf70", "price_changes": [{"asset_id": "68883925535903398159530799578268246684851592835366731124807972752959560431304", "price": "0.034", "size": "0", "side": "BUY", "hash": "939c8e39a73b5f624449cc9af848df5af6a98819", "best_bid": "0.938", "best_ask": "0.993"}, {"asset_id": "49541604524685067034733103567606780662654635021473570692999975492153111969210", "price": "0.966", "size": "0", "side": "SELL", "hash": "1bffeaa6fb7dbd25f6e056b972beab2b48d408f1", "best_bid": "0.007", "best_ask": "0.062"}], "timestamp": "1769384630172", "event_type": "price_change"}}
{"_local_timestamp": "2026-01-25T23:43:50.965277+00:00", "data": {"market": "0x388b017fa66c293566816b3f6253af6800ca69d6ab740ef019e5a69feacacf70", "price_changes": [{"asset_id": "68883925535903398159530799578268246684851592835366731124807972752959560431304", "price": "0.022", "size": "311.68", "side": "BUY", "hash": "608b7c818a16dceab54fa0ebfaf70a5874ace5ac", "best_bid": "0.938", "best_ask": "0.993"}, {"asset_id": "49541604524685067034733103567606780662654635021473570692999975492153111969210", "price": "0.978", "size": "311.68", "side": "SELL", "hash": "567357f0ae02f118bc496d4f5786b897c615ebda", "best_bid": "0.007", "best_ask": "0.062"}], "timestamp": "1769384630385", "event_type": "price_change"}}
