{"_local_timestamp": "2026-01-25T23:41:02.925766+00:00", "data": [{"market": "0x3406bde3957b114f7e5650146696c7028269c0d5dea6ac0ec8c553ac16757b84", "asset_id": "115465379638134000120897963525564934745315333930362731129252910155725648272605", "timestamp": "1769382483681", "hash": "2238c63e095df9a8f67f1e0fd44bd6c936094fbf", "bids": [{"price": "0.01", "size": "69.69"}, {"price": "0.02", "size": "850"}, {"price": "0.03", "size": "7.96"}, {"price": "0.05", "size": "500"}, {"price": "0.08", "size": "300"}, {"price": "0.09", "size": "7.37"}, {"price": "0.2", "size": "65"}, {"price": "0.22", "size": "50"}, {"price": "0.24", "size": "8"}, {"price": "0.79", "size": "350"}], "asks": [{"price": "0.99", "size": "466.79"}, {"price": "0.98", "size": "164.42"}, {"price": "0.97", "size": "75"}, {"price": "0.96", "size": "16.09"}, {"price": "0.93", "size": "355.47"}], "event_type": "book", "last_trade_price": ""}, {"market": "0x6e859824d83194fc088766d7c363adb6e32525b1890d547f2bffb3dce3b5f444", "asset_id": "1007592767152593904120906718548640287423186514852220759324946644995163459383", "timestamp": "1769384424577", "hash": "e32ee5033daad5fdd10f2a73739e36a1a9df6177", "bids": [{"price": "0.01", "size": "69.86"}, {"price": "0.02", "size": "850"}, {"price": "0.03", "size": "8.1"}, {"price": "0.05", "size": "500"}, {"price": "0.08", "size": "300"}, {"price": "0.09", "size": "7.31"}, {"price": "0.16", "size": "104"}, {"price": "0.23", "size": "56.52"}, {"price": "0.24", "size": "45.83"}, {"price": "0.66", "size": "350"}], "asks": [{"price": "0.99", "size": "65.72"}, {"price": "0.98", "size": "150"}, {"price": "0.97", "size": "12.89"}, {"price": "0.93", "size": "185.71"}, {"price": "0.92", "size": "6.95"}, {"price": "0.91", "size": "61.11"}, {"price": "0.89", "size": "300"}, {"price": "0.8", "size": "350"}], "event_type": "book", "last_trade_price": ""}, {"market": "0x594b0c20ab8dbc69e114332a492e070b443aeb224b92044cb578a12e6c2e3803", "asset_id": "53045599992634231073170577534514793656648939708140653871029455415927166771776", "timestamp": "1769384434233", "hash": "872ee8a368a535007f7ddbb15ed2f4b12eeb6998", "bids": [{"price": "0.01", "size": "170.52"}, {"price": "0.02", "size": "850"}, {"price": "0.03", "size": "6.03"}, {"price": "0.04", "size": "37"}, {"price": "0.05", "size": "500"}, {"price": "0.07", "size": "10.19"}, {"price": "0.1", "size": "525"}, {"price": "0.11", "size": "9.19"}, {"price": "0.21", "size": "61.9"}, {"price": "0.22", "size": "50"}, {"price": "0.47", "size": "350"}], "asks": [{"price": "0.99", "size": "171.06"}, {"price": "0.98", "size": "850"}, {"price": "0.97", "size": "6.34"}, {"price": "0.96", "size": "37"}, {"price": "0.95", "size": "500"}, {"price": "0.93", "size": "9.98"}, {"price": "0.88", "size": "281"}, {"price": "0.87", "size": "8.5"}, {"price": "0.8", "size": "65"}, {"price": "0.79", "size": "52.38"}, {"price": "0.61", "size": "350"}], "event_type": "book", "last_trade_price": ""}, {"market": "0x0ff3980b4522405063e04e1428c599d4f4a595046d31a2ec7645874e7428cb0d", "asset_id": "70763686139594410379687997157193094521970112097061328887093252009180194073103", "timestamp": "1769384424964", "hash": "122df909836efda9e1acac6ea94063a14f2c2842", "bids": [{"price": "0.01", "size": "70.6"}, {"price": "0.02", "size": "850"}, {"price": "0.03", "size": "6.08"}, {"price": "0.05", "size": "500"}, {"price": "0.07", "size": "10.16"}, {"price": "0.11", "size": "362"}, {"price": "0.12", "size": "8.5"}, {"price": "0.21", "size": "61.9"}, {"price": "0.22", "size": "50"}, {"price": "0.45", "size": "350"}], "asks": [{"price": "0.99", "size": "70.84"}, {"price": "0.98", "size": "850"}, {"price": "0.97", "size": "8.9"}, {"price": "0.95", "size": "500"}, {"price": "0.9", "size": "531.24"}, {"price": "0.89", "size": "9.19"}, {"price": "0.8", "size": "65"}, {"price": "0.79", "size": "52.38"}, {"price": "0.59", "size": "350"}], "event_type": "book", "last_trade_price": ""}, {"market": "0x594b0c20ab8dbc69e114332a492e070b443aeb224b92044cb578a12e6c2e3803", "asset_id": "42419209928828774975861486950092174694128319564350299621877859389614951820121", "timestamp": "1769384434233", "hash": "5944a6f9b135b1bb5acd6589f1ee0bcb92ae5bc9", "bids": [{"price": "0.01", "size": "171.06"}, {"price": "0.02", "size": "850"}, {"price": "0.03", "size": "6.34"}, {"price": "0.04", "size": "37"}, {"price": "0.05", "size": "500"}, {"price": "0.07", "size": "9.98"}, {"price": "0.12", "size": "281"}, {"price": "0.13", "size": "8.5"}, {"price": "0.2", "size": "65"}, {"price": "0.21", "size": "52.38"}, {"price": "0.39", "size": "350"}], "asks": [{"price": "0.99", "size": "170.52"}, {"price": "0.98", "size": "850"}, {"price": "0.97", "size": "6.03"}, {"price": "0.96", "size": "37"}, {"price": "0.95", "size": "500"}, {"price": "0.93", "size": "10.19"}, {"price": "0.9", "size": "525"}, {"price": "0.89", "size": "9.19"}, {"price": "0.79", "size": "61.9"}, {"price": "0.78", "size": "50"}, {"price": "0.53", "size": "350"}], "event_type": "book", "last_trade_price": ""}, {"market": "0x6e859824d83194fc088766d7c363adb6e32525b1890d547f2bffb3dce3b5f444", "asset_id": "47571364726448727838964706866240873454603775655157083187789979094117274002718", "timestamp": "1769384424577", "hash": "f37e9aebbfff53f9d48434aecafe86967be95862", "bids": [{"price": "0.01", "size": "65.72"}, {"price": "0.02", "size": "150"}, {"price": "0.03", "size": "12.89"}, {"price": "0.07", "size": "185.71"}, {"price": "0.08", "size": "6.95"}, {"price": "0.09", "size": "61.11"}, {"price": "0.11", "size": "300"}, {"price": "0.2", "size": "350"}], "asks": [{"price": "0.99", "size": "69.86"}, {"price": "0.98", "size": "850"}, {"price": "0.97", "size": "8.1"}, {"price": "0.95", "size": "500"}, {"price": "0.92", "size": "300"}, {"price": "0.91", "size": "7.31"}, {"price": "0.84", "size": "104"}, {"price": "0.77", "size": "56.52"}, {"price": "0.76", "size": "45.83"}, {"price": "0.34", "size": "350"}], "event_type": "book", "last_trade_price": ""}, {"market": "0x3406bde3957b114f7e5650146696c7028269c0d5dea6ac0ec8c553ac16757b84", "asset_id": "13785687160508004499686629689632859302705340150937798182027617547671626750582", "timestamp": "1769382483681", "hash": "2159c56da0fd691bb357badf98e2f7ff35b9e81f", "bids": [{"price": "0.01", "size": "466.79"}, {"price": "0.02", "size": "164.42"}, {"price": "0.03", "size": "75"}, {"price": "0.04", "size": "16.09"}, {"price": "0.07", "size": "355.47"}], "asks": [{"price": "0.99", "size": "69.69"}, {"price": "0.98", "size": "850"}, {"price": "0.97", "size": "7.96"}, {"price": "0.95", "size": "500"}, {"price": "0.92", "size": "300"}, {"price": "0.91", "size": "7.37"}, {"price": "0.8", "size": "65"}, {"price": "0.78", "size": "50"}, {"price": "0.76", "size": "8"}, {"price": "0.21", "size": "350"}], "event_type": "book", "last_trade_price": ""}, {"market": "0x4beaa9e724924a5aba318b9b1bc1b966da7820079a9707f4a46d39df9b89b266", "asset_id": "64918973092029733162516466002311638759789765333262546958150365325944953240690", "timestamp": "1769382595344", "hash": "f24fcc4bbc9ee5b4f1466f3babc26fccddb545e4", "bids": [{"price": "0.01", "size": "69.88"}, {"price": "0.02", "size": "850"}, {"price": "0.03", "size": "8.11"}, {"price": "0.05", "size": "500"}, {"price": "0.08", "size": "300"}, {"price": "0.09", "size": "7.3"}, {"price": "0.16", "size": "104"}, {"price": "0.22", "size": "59.09"}, {"price": "0.23", "size": "47.82"}, {"price": "0.65", "size": "350"}], "asks": [{"price": "0.99", "size": "65.23"}, {"price": "0.98", "size": "156.93"}, {"price": "0.97", "size": "75"}, {"price": "0.96", "size": "7.29"}, {"price": "0.92", "size": "162.5"}, {"price": "0.91", "size": "5.74"}, {"price": "0.9", "size": "410"}, {"price": "0.79", "size": "350"}], "event_type": "book", "last_trade_price": ""}, {"market": "0x0ff3980b4522405063e04e1428c599d4f4a595046d31a2ec7645874e7428cb0d", "asset_id": "111727512223221006993329893518872991949884788881551465044898427984500489504625", "timestamp": "1769384424964", "hash": "b5de4b319dfb94ed013e199fbcc2e09e84c3a388", "bids": [{"price": "0.01", "size": "70.84"}, {"price": "0.02", "size": "850"}, {"price": "0.03", "size": "8.9"}, {"price": "0.05", "size": "500"}, {"price": "0.1", "size": "531.24"}, {"price": "0.11", "size": "9.19"}, {"price": "0.2", "size": "65"}, {"price": "0.21", "size": "52.38"}, {"price": "0.41", "size": "350"}], "asks": [{"price": "0.99", "size": "70.6"}, {"price": "0.98", "size": "850"}, {"price": "0.97", "size": "6.08"}, {"price": "0.95", "size": "500"}, {"price": "0.93", "size": "10.16"}, {"price": "0.89", "size": "362"}, {"price": "0.88", "size": "8.5"}, {"price": "0.79", "size": "61.9"}, {"price": "0.78", "size": "50"}, {"price": "0.55", "size": "350"}], "event_type": "book", "last_trade_price": ""}, {"market": "0x4beaa9e724924a5aba318b9b1bc1b966da7820079a9707f4a46d39df9b89b266", "asset_id": "1746273149844860334325143577369673019203050555656726773624698222655821332016", "timestamp": "1769382595344", "hash": "aeb8560803d644f795bb7e55675b15fee2c39abf", "bids": [{"price": "0.01", "size": "65.23"}, {"price": "0.02", "size": "156.93"}, {"price": "0.03", "size": "75"}, {"price": "0.04", "size": "7.29"}, {"price": "0.08", "size": "162.5"}, {"price": "0.09", "size": "5.74"}, {"price": "0.1", "size": "410"}, {"price": "0.21", "size": "350"}], "asks": [{"price": "0.99", "size": "69.88"}, {"price": "0.98", "size": "850"}, {"price": "0.97", "size": "8.11"}, {"price": "0.95", "size": "500"}, {"price": "0.92", "size": "300"}, {"price": "0.91", "size": "7.3"}, {"price": "0.84", "size": "104"}, {"price": "0.78", "size": "59.09"}, {"price": "0.77", "size": "47.82"}, {"price": "0.35", "size": "350"}], "event_type": "book", "last_trade_price": ""}]}
{"_local_timestamp": "2026-01-25T23:41:52.092068+00:00", "data": {"market": "0x3406bde3957b114f7e5650146696c7028269c0d5dea6ac0ec8c553ac16757b84", "price_changes": [{"asset_id": "13785687160508004499686629689632859302705340150937798182027617547671626750582", "price": "0.02", "size": "14.42", "side": "BUY", "hash": "f7ca3bac5f9a2e40128ad3a8b129c6a32f6bf43a", "best_bid": "0.07", "best_ask": "0.21"}, {"asset_id": "115465379638134000120897963525564934745315333930362731129252910155725648272605", "price": "0.98", "size": "14.42", "side": "SELL", "hash": "77e389cb5ae74674990553063d6e813615b34524", "best_bid": "0.79", "best_ask": "0.93"}], "timestamp": "1769384512004", "event_type": "price_change"}}
{"_local_timestamp": "2026-01-25T23:41:52.097964+00:00", "data": {"market": "0x3406bde3957b114f7e5650146696c7028269c0d5dea6ac0ec8c553ac16757b84", "price_changes": [{"asset_id": "115465379638134000120897963525564934745315333930362731129252910155725648272605", "price": "0.02", "size": "700", "side": "BUY", "hash": "e683c933a040f03b7d174faedfa540c742320e03", "best_bid": "0.79", "best_ask": "0.93"}, {"asset_id": "13785687160508004499686629689632859302705340150937798182027617547671626750582", "price": "0.98", "size": "700", "side": "SELL", "hash": "e652327e9db736ad85fc37b139448c11baaa4142", "best_bid": "0.07", "best_ask": "0.21"}], "timestamp": "1769384512005", "event_type": "price_change"}}
{"_local_timestamp": "2026-01-25T23:41:58.128723+00:00", "data": {"market": "0x3406bde3957b114f7e5650146696c7028269c0d5dea6ac0ec8c553ac16757b84", "price_changes": [{"asset_id": "115465379638134000120897963525564934745315333930362731129252910155725648272605", "price": "0.02", "size": "850", "side": "BUY", "hash": "41ed04a0e22c402de8200a6b63af5152c3136548", "best_bid": "0.79", "best_ask": "0.93"}, {"asset_id": "13785687160508004499686629689632859302705340150937798182027617547671626750582", "price": "0.98", "size": "850", "side": "SELL", "hash": "785ae8b508b2abc7684ea5aea5a7b930accfdfcd", "best_bid": "0.07", "best_ask": "0.21"}], "timestamp": "1769384518052", "event_type": "price_change"}}
{"_local_timestamp": "2026-01-25T23:41:58.133021+00:00", "data": {"market": "0x3406bde3957b114f7e5650146696c7028269c0d5dea6ac0ec8c553ac16757b84", "price_changes": [{"asset_id": "13785687160508004499686629689632859302705340150937798182027617547671626750582", "price": "0.02", "size": "164.42", "side": "BUY", "hash": "a0d34c16bea95d529ca20245cb3e93a63a924d33", "best_bid": "0.07", "best_ask": "0.21"}, {"asset_id": "115465379638134000120897963525564934745315333930362731129252910155725648272605", "price": "0.98", "size": "164.42", "side": "SELL", "hash": "3592d96386a76e055fd91e0ddc1a7e56ee192fe0", "best_bid": "0.79", "best_ask": "0.93"}], "timestamp": "1769384518054", "event_type": "price_change"}}
{"_local_timestamp": "2026-01-25T23:42:45.163398+00:00", "data": {"market": "0x0ff3980b4522405063e04e1428c599d4f4a595046d31a2ec7645874e7428cb0d", "price_changes": [{"asset_id": "70763686139594410379687997157193094521970112097061328887093252009180194073103", "price": "0.02", "size": "700", "side": "BUY", "hash": "d0e15ac83f908560e3e350d9f2b7391e0b0c6234", "best_bid": "0.45", "best_ask": "0.59"}, {"asset_id": "111727512223221006993329893518872991949884788881551465044898427984500489504625", "price": "0.98", "size": "700", "side": "SELL", "hash": "abefe3da3741561d023c902064c3d23fc7af6f81", "best_bid": "0.41", "best_ask": "0.55"}], "timestamp": "1769384565003", "event_type": "price_change"}}
{"_local_timestamp": "2026-01-25T23:42:49.857287+00:00", "data": {"market": "0x0ff3980b4522405063e04e1428c599d4f4a595046d31a2ec7645874e7428cb0d", "price_changes": [{"asset_id": "70763686139594410379687997157193094521970112097061328887093252009180194073103", "price": "0.02", "size": "850", "side": "BUY", "hash": "3032785b9f1d9618fe02b08a50f2fedda3622c77", "best_bid": "0.45", "best_ask": "0.59"}, {"asset_id": "111727512223221006993329893518872991949884788881551465044898427984500489504625", "price": "0.98", "size": "850", "side": "SELL", "hash": "1fc4e8d3145501558eb8c64da56155cd2c638ef2", "best_bid": "0.41", "best_ask": "0.55"}], "timestamp": "1769384569726", "event_type": "price_change"}}
{"_local_timestamp": "2026-01-25T23:44:13.200538+00:00", "data": {"market": "0x594b0c20ab8dbc69e114332a492e070b443aeb224b92044cb578a12e6c2e3803", "price_changes": [{"asset_id": "53045599992634231073170577534514793656648939708140653871029455415927166771776", "price": "0.02", "size": "700", "side": "BUY", "hash": "4b541e3e9cfa0c3eb1e3b1f3ea18e8d3cf85671f", "best_bid": "0.47", "best_ask": "0.61"}, {"asset_id": "42419209928828774975861486950092174694128319564350299621877859389614951820121", "price": "0.98", "size": "700", "side": "SELL", "hash": "145db2791fc34427c794ddb5e79c781437668a4e", "best_bid": "0.39", "best_ask": "0.53"}], "timestamp": "1769384653002", "event_type": "price_change"}}
{"_local_timestamp": "2026-01-25T23:44:19.751146+00:00", "data": {"market": "0x594b0c20ab8dbc69e114332a492e070b443aeb224b92044cb578a12e6c2e3803", "price_changes": [{"asset_id": "53045599992634231073170577534514793656648939708140653871029455415927166771776", "price": "0.02", "size": "850", "side": "BUY", "hash": "8bc872c5e7b9a2550878f26ef316cf8103a374f9", "best_bid": "0.47", "best_ask": "0.61"}, {"asset_id": "42419209928828774975861486950092174694128319564350299621877859389614951820121", "price": "0.98", "size": "850", "side": "SELL", "hash": "135182232e911a823b03ea5f870c31fa22c02529", "best_bid": "0.39", "best_ask": "0.53"}], "timestamp": "1769384659672", "event_type": "price_change"}}
{"_local_timestamp": "2026-01-25T23:45:05.066760+00:00", "data": {"market": "0x594b0c20ab8dbc69e114332a492e070b443aeb224b92044cb578a12e6c2e3803", "price_changes": [{"asset_id": "42419209928828774975861486950092174694128319564350299621877859389614951820121", "price": "0.02", "size": "700", "side": "BUY", "hash": "67fd61bd3b11cc397088ad3a9d12aa23bde8fa22", "best_bid": "0.39", "best_ask": "0.53"}, {"asset_id": "53045599992634231073170577534514793656648939708140653871029455415927166771776", "price": "0.98", "size": "700", "side": "SELL", "hash": "08eaedd85e9c15b61aed6aa084811179f3b644fd", "best_bid": "0.47", "best_ask": "0.61"}], "timestamp": "1769384705000", "event_type": "price_change"}}
{"_local_timestamp": "2026-01-25T23:45:08.820350+00:00", "data": {"market": "0x594b0c20ab8dbc69e114332a492e070b443aeb224b92044cb578a12e6c2e3803", "price_changes": [{"asset_id": "42419209928828774975861486950092174694128319564350299621877859389614951820121", "price": "0.02", "size": "850", "side": "BUY", "hash": "8bd5c22f74341007690dd105b62e3cbfc0bdd964", "best_bid": "0.39", "best_ask": "0.53"}, {"asset_id": "53045599992634231073170577534514793656648939708140653871029455415927166771776", "price": "0.98", "size": "850", "side": "SELL", "hash": "4dd759d2bff3d955d41457ac7ed6a75ac8b3e2d1", "best_bid": "0.47", "best_ask": "0.61"}], "timestamp": "1769384708753", "event_type": "price_change"}}
{"_local_timestamp": "2026-01-25T23:45:56.393316+00:00", "data": {"market": "0x0ff3980b4522405063e04e1428c599d4f4a595046d31a2ec7645874e7428cb0d", "price_changes": [{"asset_id": "111727512223221006993329893518872991949884788881551465044898427984500489504625", "price": "0.1", "size": "306.24", "side": "BUY", "hash": "c7feb95240d65fe543e15b826c55a3dcf4ab07b2", "best_bid": "0.41", "best_ask": "0.55"}, {"asset_id": "70763686139594410379687997157193094521970112097061328887093252009180194073103", "price": "0.9", "size": "306.24", "side": "SELL", "hash": "7e0897105caa92bed1fa9560135de919d41345c0", "best_bid": "0.45", "best_ask": "0.59"}], "timestamp": "1769384756079", "event_type": "price_change"}}
{"_local_timestamp": "2026-01-25T23:45:56.396060+00:00", "data": {"market": "0x0ff3980b4522405063e04e1428c599d4f4a595046d31a2ec7645874e7428cb0d", "price_changes": [{"asset_id": "70763686139594410379687997157193094521970112097061328887093252009180194073103", "price": "0.11", "size": "100", "side": "BUY", "hash": "42e8f4d364df6aae6c90da8b4f13b2b6928aeb4a", "best_bid": "0.45", "best_ask": "0.59"}, {"asset_id": "111727512223221006993329893518872991949884788881551465044898427984500489504625", "price": "0.89", "size": "100", "side": "SELL", "hash": "4a220b781cf31e0946755acaa6f8a12fca94885e", "best_bid": "0.41", "best_ask": "0.55"}], "timestamp": "1769384756116", "event_type": "price_change"}}
{"_local_timestamp": "2026-01-25T23:45:56.667280+00:00", "data": {"market": "0x6e859824d83194fc088766d7c363adb6e32525b1890d547f2bffb3dce3b5f444", "price_changes": [{"asset_id": "47571364726448727838964706866240873454603775655157083187789979094117274002718", "price": "0.11", "size": "0", "side": "BUY", "hash": "e9a309a51c930c582a86971ae2f7519fcec680c5", "best_bid": "0.2", "best_ask": "0.34"}, {"asset_id": "1007592767152593904120906718548640287423186514852220759324946644995163459383", "price": "0.89", "size": "0", "side": "SELL", "hash": "ee7f0c547f38f1ab7c7d4f39eb266cf578a70555", "best_bid": "0.66", "best_ask": "0.8"}], "timestamp": "1769384756092", "event_type": "price_change"}}
{"_local_timestamp": "2026-01-25T23:45:56.704603+00:00", "data": {"market": "0x594b0c20ab8dbc69e114332a492e070b443aeb224b92044cb578a12e6c2e3803", "price_changes": [{"asset_id": "53045599992634231073170577534514793656648939708140653871029455415927166771776", "price": "0.1", "size": "300", "side": "BUY", "hash": "b966844844a3e212a55db66a008c2d948edcebcf", "best_bid": "0.47", "best_ask": "0.61"}, {"asset_id": "42419209928828774975861486950092174694128319564350299621877859389614951820121", "price": "0.9", "size": "300", "side": "SELL", "hash": "de68121e249f8ed7dd0583b684ba7e88249e3d03", "best_bid": "0.39", "best_ask": "0.53"}], "timestamp": "1769384756078", "event_type": "price_change"}}
{"_local_timestamp": "2026-01-25T23:45:56.705148+00:00", "data": {"market": "0x594b0c20ab8dbc69e114332a492e070b443aeb224b92044cb578a12e6c2e3803", "price_changes": [{"asset_id": "42419209928828774975861486950092174694128319564350299621877859389614951820121", "price": "0.12", "size": "100", "side": "BUY", "hash": "6afe62f2ea0acf679ebfef95c378b5404b9fa43b", "best_bid": "0.39", "best_ask": "0.53"}, {"asset_id": "53045599992634231073170577534514793656648939708140653871029455415927166771776", "price": "0.88", "size": "100", "side": "SELL", "hash": "3e660db61c6e7ec7d228457458cb40a7f55a9e9c", "best_bid": "0.47", "best_ask": "0.61"}], "timestamp": "1769384756139", "event_type": "price_change"}}
{"_local_timestamp": "2026-01-25T23:46:00.960390+00:00", "data": {"market": "0x594b0c20ab8dbc69e114332a492e070b443aeb224b92044cb578a12e6c2e3803", "price_changes": [{"asset_id": "42419209928828774975861486950092174694128319564350299621877859389614951820121", "price": "0.13", "size": "0", "side": "BUY", "hash": "1a24588913186c298b026af3262d54ac9937620c", "best_bid": "0.39", "best_ask": "0.53"}, {"asset_id": "53045599992634231073170577534514793656648939708140653871029455415927166771776", "price": "0.87", "size": "0", "side": "SELL", "hash": "ea4792bd54f7b07c1b031c18be7a231f5728aaad", "best_bid": "0.47", "best_ask": "0.61"}], "timestamp": "1769384760896", "event_type": "price_change"}}
{"_local_timestamp": "2026-01-25T23:46:00.960791+00:00", "data": {"market": "0x0ff3980b4522405063e04e1428c599d4f4a595046d31a2ec7645874e7428cb0d", "price_changes": [{"asset_id": "70763686139594410379687997157193094521970112097061328887093252009180194073103", "price": "0.12", "size": "0", "side": "BUY", "hash": "1e82649821c8cc9b3986217e8d0a8ab4a90ac780", "best_bid": "0.45", "best_ask": "0.59"}, {"asset_id": "111727512223221006993329893518872991949884788881551465044898427984500489504625", "price": "0.88", "size": "0", "side": "SELL", "hash": "344215993d879ef45c1fd8e32365bc9e0bf7e74b", "best_bid": "0.41", "best_ask": "0.55"}], "timestamp": "1769384760896", "event_type": "price_change"}}
{"_local_timestamp": "2026-01-25T23:46:00.961076+00:00", "data": {"market": "0x0ff3980b4522405063e04e1428c599d4f4a595046d31a2ec7645874e7428cb0d", "price_changes": [{"asset_id": "111727512223221006993329893518872991949884788881551465044898427984500489504625", "price": "0.11", "size": "0", "side": "BUY", "hash": "a086df633f1349cfc7816bc487ec6047dfa00b07", "best_bid": "0.41", "best_ask": "0.55"}, {"asset_id": "70763686139594410379687997157193094521970112097061328887093252009180194073103", "price": "0.89", "size": "0", "side": "SELL", "hash": "0b1c63ec6a982f12a8135f518ced8b877dafb474", "best_bid": "0.45", "best_ask": "0.59"}], "timestamp": "1769384760896", "event_type": "price_change"}}
{"_local_timestamp": "2026-01-25T23:46:00.961394+00:00", "data": {"market": "0x594b0c20ab8dbc69e114332a492e070b443aeb224b92044cb578a12e6c2e3803", "price_changes": [{"asset_id": "53045599992634231073170577534514793656648939708140653871029455415927166771776", "price": "0.11", "size": "0", "side": "BUY", "hash": "cf96d7d108953bf143b537579737bbee5764290c", "best_bid": "0.47", "best_ask": "0.61"}, {"asset_id": "42419209928828774975861486950092174694128319564350299621877859389614951820121", "price": "0.89", "size": "0", "side": "SELL", "hash": "f52b78975700a3bdab8e25e65780cb6988bdad1d", "best_bid": "0.39", "best_ask": "0.53"}], "timestamp": "1769384760896", "event_type": "price_change"}}
{"_local_timestamp": "2026-01-25T23:46:41.925255+00:00", "data": {"market": "0x0ff3980b4522405063e04e1428c599d4f4a595046d31a2ec7645874e7428cb0d", "price_changes": [{"asset_id": "70763686139594410379687997157193094521970112097061328887093252009180194073103", "price": "0.12", "size": "181", "side": "BUY", "hash": "d13a79af36a033d9de75ae26d53e8095fe703adf", "best_bid": "0.45", "best_ask": "0.59"}, {"asset_id": "111727512223221006993329893518872991949884788881551465044898427984500489504625", "price": "0.88", "size": "181", "side": "SELL", "hash": "52ff1082e61852a4397821283ebf84f36b1561c1", "best_bid": "0.41", "best_ask": "0.55"}], "timestamp": "1769384801839", "event_type": "price_change"}}
{"_local_timestamp": "2026-01-25T23:46:41.927385+00:00", "data": {"market": "0x6e859824d83194fc088766d7c363adb6e32525b1890d547f2bffb3dce3b5f444", "price_changes": [{"asset_id": "47571364726448727838964706866240873454603775655157083187789979094117274002718", "price": "0.03", "size": "87.89", "side": "BUY", "hash": "2d76cdaab46f11b516b6de09e5849c085078ff13", "best_bid": "0.2", "best_ask": "0.34"}, {"asset_id": "1007592767152593904120906718548640287423186514852220759324946644995163459383", "price": "0.97", "size": "87.89", "side": "SELL", "hash": "eb684362dcad4b3d14037ad65bb29d58bae4618e", "best_bid": "0.66", "best_ask": "0.8"}], "timestamp": "1769384801839", "event_type": "price_change"}}
{"_local_timestamp": "2026-01-25T23:46:41.927680+00:00", "data": {"market": "0x594b0c20ab8dbc69e114332a492e070b443aeb224b92044cb578a12e6c2e3803", "price_changes": [{"asset_id": "42419209928828774975861486950092174694128319564350299621877859389614951820121", "price": "0.13", "size": "140", "side": "BUY", "hash": "108defa6213d64eef6e974f0e4f2587a174f8c86", "best_bid": "0.39", "best_ask": "0.53"}, {"asset_id": "53045599992634231073170577534514793656648939708140653871029455415927166771776", "price": "0.87", "size": "140", "side": "SELL", "hash": "4a870107fcbe327ee2d19e94db45ba1c7d4b36c3", "best_bid": "0.47", "best_ask": "0.61"}], "timestamp": "1769384801839", "event_type": "price_change"}}
{"_local_timestamp": "2026-01-25T23:46:41.932773+00:00", "data": {"market": "0x0ff3980b4522405063e04e1428c599d4f4a595046d31a2ec7645874e7428cb0d", "price_changes": [{"asset_id": "111727512223221006993329893518872991949884788881551465044898427984500489504625", "price": "0.11", "size": "265", "side": "BUY", "hash": "d82e818706e621aca15272df4a9c35c784bf3e77", "best_bid": "0.41", "best_ask": "0.55"}, {"asset_id": "70763686139594410379687997157193094521970112097061328887093252009180194073103", "price": "0.89", "size": "265", "side": "SELL", "hash": "0e9a17a7335bc679e666f2b91ac965bc84f391ad", "best_bid": "0.45", "best_ask": "0.59"}], "timestamp": "1769384801841", "event_type": "price_change"}}
{"_local_timestamp": "2026-01-25T23:46:41.933084+00:00", "data": {"market": "0x594b0c20ab8dbc69e114332a492e070b443aeb224b92044cb578a12e6c2e3803", "price_changes": [{"asset_id": "53045599992634231073170577534514793656648939708140653871029455415927166771776", "price": "0.11", "size": "262", "side": "BUY", "hash": "9a36579db829aee3c6dc163e5ba34287f8e2142c", "best_bid": "0.47", "best_ask": "0.61"}, {"asset_id": "42419209928828774975861486950092174694128319564350299621877859389614951820121", "price": "0.89", "size": "262", "side": "SELL", "hash": "2c0632cb9227799ce2750b5db2d5b44b4ba29f2a", "best_bid": "0.39", "best_ask": "0.53"}], "timestamp": "1769384801842", "event_type": "price_change"}}
{"_local_timestamp": "2026-01-25T23:46:47.392690+00:00", "data": {"market": "0x0ff3980b4522405063e04e1428c599d4f4a595046d31a2ec7645874e7428cb0d", "price_changes": [{"asset_id": "70763686139594410379687997157193094521970112097061328887093252009180194073103", "price": "0.13", "size": "8.5", "side": "BUY", "hash": "a49ccadac2e61811f50bd7c7bbe073399067e9b8", "best_bid": "0.45", "best_ask": "0.59"}, {"asset_id": "111727512223221006993329893518872991949884788881551465044898427984500489504625", "price": "0.87", "size": "8.5", "side": "SELL", "hash": "ff96a7540362231d4ae61a890b9d40659597b065", "best_bid": "0.41", "best_ask": "0.55"}], "timestamp": "1769384807320", "event_type": "price_change"}}
{"_local_timestamp": "2026-01-25T23:46:47.393148+00:00", "data": {"market": "0x594b0c20ab8dbc69e114332a492e070b443aeb224b92044cb578a12e6c2e3803", "price_changes": [{"asset_id": "42419209928828774975861486950092174694128319564350299621877859389614951820121", "price": "0.22", "size": "8.5", "side": "BUY", "hash": "f9f1b8d608e35078b8026297d021f1113cbde8c0", "best_bid": "0.39", "best_ask": "0.53"}, {"asset_id": "53045599992634231073170577534514793656648939708140653871029455415927166771776", "price": "0.78", "size": "8.5", "side": "SELL", "hash": "15663d3729866bf04c740e54cd18194afee694b7", "best_bid": "0.47", "best_ask": "0.61"}], "timestamp": "1769384807320", "event_type": "price_change"}}
{"_local_timestamp": "2026-01-25T23:46:47.393528+00:00", "data": {"market": "0x594b0c20ab8dbc69e114332a492e070b443aeb224b92044cb578a12e6c2e3803", "price_changes": [{"asset_id": "53045599992634231073170577534514793656648939708140653871029455415927166771776", "price": "0.12", "size": "8.5", "side": "BUY", "hash": "b73cafdc56c337937c6d6a0ee50503edd0b3cf0a", "best_bid": "0.47", "best_ask": "0.61"}, {"asset_id": "42419209928828774975861486950092174694128319564350299621877859389614951820121", "price": "0.88", "size": "8.5", "side": "SELL", "hash": "c2d0a366fc2f5c8e584791164f316c22e2fb6d55", "best_bid": "0.39", "best_ask": "0.53"}], "timestamp": "1769384807320", "event_type": "price_change"}}
{"_local_timestamp": "2026-01-25T23:46:47.397087+00:00", "data": {"market": "0x0ff3980b4522405063e04e1428c599d4f4a595046d31a2ec7645874e7428cb0d", "price_changes": [{"asset_id": "111727512223221006993329893518872991949884788881551465044898427984500489504625", "price": "0.12", "size": "8.5", "side": "BUY", "hash": "1d2664b0d955fffd76d7154e188df3a60ec78856", "best_bid": "0.41", "best_ask": "0.55"}, {"asset_id": "70763686139594410379687997157193094521970112097061328887093252009180194073103", "price": "0.88", "size": "8.5", "side": "SELL", "hash": "e3162cf7c509008582e407a725d0130f96bc492f", "best_bid": "0.45", "best_ask": "0.59"}], "timestamp": "1769384807320", "event_type": "price_change"}}
{"_local_timestamp": "2026-01-25T23:47:18.954165+00:00", "data": {"market": "0x594b0c20ab8dbc69e114332a492e070b443aeb224b92044cb578a12e6c2e3803", "price_changes": [{"asset_id": "53045599992634231073170577534514793656648939708140653871029455415927166771776", "price": "0.1", "size": "0", "side": "BUY", "hash": "79735c714d4be452ba812d744d0b00787fabaad9", "best_bid": "0.47", "best_ask": "0.61"}, {"asset_id": "42419209928828774975861486950092174694128319564350299621877859389614951820121", "price": "0.9", "size": "0", "side": "SELL", "hash": "d160b1820395238eecef5cc04af1c76acb1e3c7c", "best_bid": "0.39", "best_ask": "0.53"}], "timestamp": "1769384838778", "event_type": "price_change"}}
{"_local_timestamp": "2026-01-25T23:47:18.960798+00:00", "data": {"market": "0x0ff3980b4522405063e04e1428c599d4f4a595046d31a2ec7645874e7428cb0d", "price_changes": [{"asset_id": "111727512223221006993329893518872991949884788881551465044898427984500489504625", "price": "0.1", "size": "6.24", "side": "BUY", "hash": "8f4f1f5aa5aa40d79239b196c12a1cfaed34be8a", "best_bid": "0.41", "best_ask": "0.55"}, {"asset_id": "70763686139594410379687997157193094521970112097061328887093252009180194073103", "price": "0.9", "size": "6.24", "side": "SELL", "hash": "3f9676b6171f3595a0d3889d1f3c49d7384d2f48", "best_bid": "0.45", "best_ask": "0.59"}], "timestamp": "1769384838778", "event_type": "price_change"}}
{"_local_timestamp": "2026-01-25T23:47:18.961293+00:00", "data": {"market": "0x0ff3980b4522405063e04e1428c599d4f4a595046d31a2ec7645874e7428cb0d", "price_changes": [{"asset_id": "70763686139594410379687997157193094521970112097061328887093252009180194073103", "price": "0.11", "size": "0", "side": "BUY", "hash": "746071320ac32b8da8673d753f61e8501b70e06b", "best_bid": "0.45", "best_ask": "0.59"}, {"asset_id": "111727512223221006993329893518872991949884788881551465044898427984500489504625", "price": "0.89", "size": "0", "side": "SELL", "hash": "65f8cd706fed587e5fb06b4037258b019471ade9", "best_bid": "0.41", "best_ask": "0.55"}], "timestamp": "1769384838779", "event_type": "price_change"}}
{"_local_timestamp": "2026-01-25T23:47:18.968101+00:00", "data": {"market": "0x594b0c20ab8dbc69e114332a492e070b443aeb224b92044cb578a12e6c2e3803", "price_changes": [{"asset_id": "42419209928828774975861486950092174694128319564350299621877859389614951820121", "price": "0.12", "size": "0", "side": "BUY", "hash": "1a9141b992674565ce398a486b4a4fa59c948a06", "best_bid": "0.39", "best_ask": "0.53"}, {"asset_id": "53045599992634231073170577534514793656648939708140653871029455415927166771776", "price": "0.88", "size": "0", "side": "SELL", "hash": "5563e4f0e98109d6e613977f2f65a57a99c89b0e", "best_bid": "0.47", "best_ask": "0.61"}], "timestamp": "1769384838779", "event_type": "price_change"}}
{"_local_timestamp": "2026-01-25T23:47:19.355950+00:00", "data": {"market": "0x594b0c20ab8dbc69e114332a492e070b443aeb224b92044cb578a12e6c2e3803", "price_changes": [{"asset_id": "42419209928828774975861486950092174694128319564350299621877859389614951820121", "price": "0.08", "size": "300", "side": "BUY", "hash": "28d8b3f6c856145ab26be81aac73bae6b999279f", "best_bid": "0.39", "best_ask": "0.53"}, {"asset_id": "53045599992634231073170577534514793656648939708140653871029455415927166771776", "price": "0.92", "size": "300", "side": "SELL", "hash": "5cb3ffd320257ebd9fb58ae8d08075e694d270df", "best_bid": "0.47", "best_ask": "0.61"}], "timestamp": "1769384839117", "event_type": "price_change"}}
{"_local_timestamp": "2026-01-25T23:47:19.367400+00:00", "data": {"market": "0x0ff3980b4522405063e04e1428c599d4f4a595046d31a2ec7645874e7428cb0d", "price_changes": [{"asset_id": "70763686139594410379687997157193094521970112097061328887093252009180194073103", "price": "0.08", "size": "300", "side": "BUY", "hash": "3a6f71e456426cc787630809e836aaa584ebac1c", "best_bid": "0.45", "best_ask": "0.59"}, {"asset_id": "111727512223221006993329893518872991949884788881551465044898427984500489504625", "price": "0.92", "size": "300", "side": "SELL", "hash": "087ecd688fc560c51eb58b45e239f66db8f599d7", "best_bid": "0.41", "best_ask": "0.55"}], "timestamp": "1769384839117", "event_type": "price_change"}}
{"_local_timestamp": "2026-01-25T23:47:19.367828+00:00", "data": {"market": "0x6e859824d83194fc088766d7c363adb6e32525b1890d547f2bffb3dce3b5f444", "price_changes": [{"asset_id": "47571364726448727838964706866240873454603775655157083187789979094117274002718", "price": "0.07", "size": "685.71", "side": "BUY", "hash": "180c7a69cde647fab68b10204a4409b8f033d269", "best_bid": "0.2", "best_ask": "0.34"}, {"asset_id": "1007592767152593904120906718548640287423186514852220759324946644995163459383", "price": "0.93", "size": "685.71", "side": "SELL", "hash": "707141a4fcc13f57304c67a79b30ec98e74adb91", "best_bid": "0.66", "best_ask": "0.8"}], "timestamp": "1769384839119", "event_type": "price_change"}}
{"_local_timestamp": "2026-01-25T23:47:19.418139+00:00", "data": {"market": "0x594b0c20ab8dbc69e114332a492e070b443aeb224b92044cb578a12e6c2e3803", "price_changes": [{"asset_id": "53045599992634231073170577534514793656648939708140653871029455415927166771776", "price": "0.08", "size": "300", "side": "BUY", "hash": "1038d55a182c9b44e3159ce6e631e0d6a18f6228", "best_bid": "0.47", "best_ask": "0.61"}, {"asset_id": "42419209928828774975861486950092174694128319564350299621877859389614951820121", "price": "0.92", "size": "300", "side": "SELL", "hash": "9dffe55faf8a34aebf6b1278a5bfec9d788a7a36", "best_bid": "0.39", "best_ask": "0.53"}], "timestamp": "1769384839149", "event_type": "price_change"}}
{"_local_timestamp": "2026-01-25T23:47:19.443967+00:00", "data": {"market": "0x0ff3980b4522405063e04e1428c599d4f4a595046d31a2ec7645874e7428cb0d", "price_changes": [{"asset_id": "111727512223221006993329893518872991949884788881551465044898427984500489504625", "price": "0.08", "size": "300", "side": "BUY", "hash": "cffb47cd957e48b11e3ec38d8a796527d755ddc4", "best_bid": "0.41", "best_ask": "0.55"}, {"asset_id": "70763686139594410379687997157193094521970112097061328887093252009180194073103", "price": "0.92", "size": "300", "side": "SELL", "hash": "7dc2c2a380c8a0a7ae0109e08727e517382b1007", "best_bid": "0.45", "best_ask": "0.59"}], "timestamp": "1769384839150", "event_type": "price_change"}}
{"_local_timestamp": "2026-01-25T23:47:24.575261+00:00", "data": {"market": "0x0ff3980b4522405063e04e1428c599d4f4a595046d31a2ec7645874e7428cb0d", "price_changes": [{"asset_id": "70763686139594410379687997157193094521970112097061328887093252009180194073103", "price": "0.13", "size": "0", "side": "BUY", "hash": "9ba4e02c2793ab3cfb5430e5cb49b70eaa0ecb5a", "best_bid": "0.45", "best_ask": "0.59"}, {"asset_id": "111727512223221006993329893518872991949884788881551465044898427984500489504625", "price": "0.87", "size": "0", "side": "SELL", "hash": "f641399d32be8f70900e53494c91456511040de4", "best_bid": "0.41", "best_ask": "0.55"}], "timestamp": "1769384844498", "event_type": "price_change"}}
{"_local_timestamp": "2026-01-25T23:47:24.575719+00:00", "data": {"market": "0x594b0c20ab8dbc69e114332a492e070b443aeb224b92044cb578a12e6c2e3803", "price_changes": [{"asset_id": "53045599992634231073170577534514793656648939708140653871029455415927166771776", "price": "0.12", "size": "0", "side": "BUY", "hash": "5f43707b6f7c43f679d28a27409f49745564f359", "best_bid": "0.47", "best_ask": "0.61"}, {"asset_id": "42419209928828774975861486950092174694128319564350299621877859389614951820121", "price": "0.88", "size": "0", "side": "SELL", "hash": "5d5944d44f3b0e16c9e5a0f4f346c8fb12d9e056", "best_bid": "0.39", "best_ask": "0.53"}], "timestamp": "1769384844498", "event_type": "price_change"}}
{"_local_timestamp": "2026-01-25T23:47:24.576055+00:00", "data": {"market": "0x0ff3980b4522405063e04e1428c599d4f4a595046d31a2ec7645874e7428cb0d", "price_changes": [{"asset_id": "111727512223221006993329893518872991949884788881551465044898427984500489504625", "price": "0.12", "size": "0", "side": "BUY", "hash": "beb865dec9d47519ce861427fa1c32007b7ce7b6", "best_bid": "0.41", "best_ask": "0.55"}, {"asset_id": "70763686139594410379687997157193094521970112097061328887093252009180194073103", "price": "0.88", "size": "0", "side": "SELL", "hash": "bbe9a233f327d335aaee05979eae572deb638250", "best_bid": "0.45", "best_ask": "0.59"}], "timestamp": "1769384844498", "event_type": "price_change"}}
{"_local_timestamp": "2026-01-25T23:47:24.576395+00:00", "data": {"market": "0x594b0c20ab8dbc69e114332a492e070b443aeb224b92044cb578a12e6c2e3803", "price_changes": [{"asset_id": "42419209928828774975861486950092174694128319564350299621877859389614951820121", "price": "0.22", "size": "0", "side": "BUY", "hash": "ecba98f899c66b8e3f3c876825c2c44d2d3c29aa", "best_bid": "0.39", "best_ask": "0.53"}, {"asset_id": "53045599992634231073170577534514793656648939708140653871029455415927166771776", "price": "0.78", "size": "0", "side": "SELL", "hash": "8eb8cc13dac8548340fc886d576c3fcd690a7251", "best_bid": "0.47", "best_ask": "0.61"}], "timestamp": "1769384844499", "event_type": "price_change"}}
{"_local_timestamp": "2026-01-25T23:47:28.867626+00:00", "data": {"market": "0x594b0c20ab8dbc69e114332a492e070b443aeb224b92044cb578a12e6c2e3803", "price_changes": [{"asset_id": "42419209928828774975861486950092174694128319564350299621877859389614951820121", "price": "0.22", "size": "8.5", "side": "BUY", "hash": "794d40baa2d0ee18ea4f864db3dcd47724efcfa9", "best_bid": "0.39", "best_ask": "0.53"}, {"asset_id": "53045599992634231073170577534514793656648939708140653871029455415927166771776", "price": "0.78", "size": "8.5", "side": "SELL", "hash": "09cb127406c53102192fd2f14a075516b89a4d06", "best_bid": "0.47", "best_ask": "0.61"}], "timestamp": "1769384848802", "event_type": "price_change"}}
{"_local_timestamp": "2026-01-25T23:47:28.868082+00:00", "data": {"market": "0x594b0c20ab8dbc69e114332a492e070b443aeb224b92044cb578a12e6c2e3803", "price_changes": [{"asset_id": "53045599992634231073170577534514793656648939708140653871029455415927166771776", "price": "0.12", "size": "8.5", "side": "BUY", "hash": "167f2e721760bfb31a5d8f65307243e6da0ff312", "best_bid": "0.47", "best_ask": "0.61"}, {"asset_id": "42419209928828774975861486950092174694128319564350299621877859389614951820121", "price": "0.88", "size": "8.5", "side": "SELL", "hash": "a0aceadc6f0bef3840dce741728669ef689444da", "best_bid": "0.39", "best_ask": "0.53"}], "timestamp": "1769384848803", "event_type": "price_change"}}
{"_local_timestamp": "2026-01-25T23:48:37.853283+00:00", "data": {"market": "0x0ff3980b4522405063e04e1428c599d4f4a595046d31a2ec7645874e7428cb0d", "price_changes": [{"asset_id": "111727512223221006993329893518872991949884788881551465044898427984500489504625", "price": "0.08", "size": "0", "side": "BUY", "hash": "ce45c00578df32be192aec393b9142ee9bc4bc1c", "best_bid": "0.41", "best_ask": "0.55"}, {"asset_id": "70763686139594410379687997157193094521970112097061328887093252009180194073103", "price": "0.92", "size": "0", "side": "SELL", "hash": "ae41886302ef7b2fd9d4ef05f5589872c0fd7b8b", "best_bid": "0.45", "best_ask": "0.59"}], "timestamp": "1769384917740", "event_type": "price_change"}}
{"_local_timestamp": "2026-01-25T23:48:37.853762+00:00", "data": {"market": "0x594b0c20ab8dbc69e114332a492e070b443aeb224b92044cb578a12e6c2e3803", "price_changes": [{"asset_id": "53045599992634231073170577534514793656648939708140653871029455415927166771776", "price": "0.08", "size": "0", "side": "BUY", "hash": "645726db5877b273c997cd90e20a032238befd02", "best_bid": "0.47", "best_ask": "0.61"}, {"asset_id": "42419209928828774975861486950092174694128319564350299621877859389614951820121", "price": "0.92", "size": "0", "side": "SELL", "hash": "4a2d5488049e0848efe12f386f207d0d06ae59a5", "best_bid": "0.39", "best_ask": "0.53"}], "timestamp": "1769384917740", "event_type": "price_change"}}
{"_local_timestamp": "2026-01-25T23:48:37.854126+00:00", "data": {"market": "0x0ff3980b4522405063e04e1428c599d4f4a595046d31a2ec7645874e7428cb0d", "price_changes": [{"asset_id": "70763686139594410379687997157193094521970112097061328887093252009180194073103", "price": "0.08", "size": "0", "side": "BUY", "hash": "6bbc4a721a4732cd308e9bcfa118ee00654c566c", "best_bid": "0.45", "best_ask": "0.59"}, {"asset_id": "111727512223221006993329893518872991949884788881551465044898427984500489504625", "price": "0.92", "size": "0", "side": "SELL", "hash": "9e6ba6bf99c5ef3fedc392568a9c81c427c47849", "best_bid": "0.41", "best_ask": "0.55"}], "timestamp": "1769384917740", "event_type": "price_change"}}
{"_local_timestamp": "2026-01-25T23:48:37.854511+00:00", "data": {"market": "0x594b0c20ab8dbc69e114332a492e070b443aeb224b92044cb578a12e6c2e3803", "price_changes": [{"asset_id": "42419209928828774975861486950092174694128319564350299621877859389614951820121", "price": "0.08", "size": "0", "side": "BUY", "hash": "f92e8728edba3dcecd1e4fb52e9d7ab33e18cb13", "best_bid": "0.39", "best_ask": "0.53"}, {"asset_id": "53045599992634231073170577534514793656648939708140653871029455415927166771776", "price": "0.92", "size": "0", "side": "SELL", "hash": "172fcaa997f8887ce3209c8a953650f726cd8b89", "best_bid": "0.47", "best_ask": "0.61"}], "timestamp": "1769384917740", "event_type": "price_change"}}
{"_local_timestamp": "2026-01-25T23:48:38.261865+00:00", "data": {"market": "0x594b0c20ab8dbc69e114332a492e070b443aeb224b92044cb578a12e6c2e3803", "price_changes": [{"asset_id": "42419209928828774975861486950092174694128319564350299621877859389614951820121", "price": "0.13", "size": "240", "side": "BUY", "hash": "87f5dad8eca57c60e873d7f6184f3bf3cfc99a66", "best_bid": "0.39", "best_ask": "0.53"}, {"asset_id": "53045599992634231073170577534514793656648939708140653871029455415927166771776", "price": "0.87", "size": "240", "side": "SELL", "hash": "b8cc7ad021e0a033905b02ad04c39b3d38b79f0f", "best_bid": "0.47", "best_ask": "0.61"}], "timestamp": "1769384918088", "event_type": "price_change"}}
{"_local_timestamp": "2026-01-25T23:48:38.318669+00:00", "data": {"market": "0x594b0c20ab8dbc69e114332a492e070b443aeb224b92044cb578a12e6c2e3803", "price_changes": [{"asset_id": "53045599992634231073170577534514793656648939708140653871029455415927166771776", "price": "0.11", "size": "362", "side": "BUY", "hash": "0f00d41493ef40d0d45a42f4a08df7b99c30bf9c", "best_bid": "0.47", "best_ask": "0.61"}, {"asset_id": "42419209928828774975861486950092174694128319564350299621877859389614951820121", "price": "0.89", "size": "362", "side": "SELL", "hash": "ff4fcd7ec3928c27e983962b343a7f4b1e59ca88", "best_bid": "0.39", "best_ask": "0.53"}], "timestamp": "1769384918126", "event_type": "price_change"}}
{"_local_timestamp": "2026-01-25T23:48:38.319100+00:00", "data": {"market": "0x0ff3980b4522405063e04e1428c599d4f4a595046d31a2ec7645874e7428cb0d", "price_changes": [{"asset_id": "111727512223221006993329893518872991949884788881551465044898427984500489504625", "price": "0.11", "size": "365", "side": "BUY", "hash": "9683d36d233bb4d7ad1ac0ce5964cdf71bf7db3b", "best_bid": "0.41", "best_ask": "0.55"}, {"asset_id": "70763686139594410379687997157193094521970112097061328887093252009180194073103", "price": "0.89", "size": "365", "side": "SELL", "hash": "f853644ea88900c7bf50f3e8596310103bad3bd4", "best_bid": "0.45", "best_ask": "0.59"}], "timestamp": "1769384918109", "event_type": "price_change"}}
{"_local_timestamp": "2026-01-25T23:48:38.331020+00:00", "data": {"market": "0x0ff3980b4522405063e04e1428c599d4f4a595046d31a2ec7645874e7428cb0d", "price_changes": [{"asset_id": "70763686139594410379687997157193094521970112097061328887093252009180194073103", "price": "0.12", "size": "281", "side": "BUY", "hash": "aaa20040c21ecbdabd9aa3719d6504abd5fc7d11", "best_bid": "0.45", "best_ask": "0.59"}, {"asset_id": "111727512223221006993329893518872991949884788881551465044898427984500489504625", "price": "0.88", "size": "281", "side": "SELL", "hash": "0217dac1f827ad6421cecdc21dcdb6a55baae9bf", "best_bid": "0.41", "best_ask": "0.55"}], "timestamp": "1769384918142", "event_type": "price_change"}}
{"_local_timestamp": "2026-01-25T23:48:44.284507+00:00", "data": {"market": "0x594b0c20ab8dbc69e114332a492e070b443aeb224b92044cb578a12e6c2e3803", "price_changes": [{"asset_id": "53045599992634231073170577534514793656648939708140653871029455415927166771776", "price": "0.12", "size": "0", "side": "BUY", "hash": "d646b79adb432716e7858fc2eb23a816bf29c133", "best_bid": "0.47", "best_ask": "0.61"}, {"asset_id": "42419209928828774975861486950092174694128319564350299621877859389614951820121", "price": "0.88", "size": "0", "side": "SELL", "hash": "652badd98ff3c7d676ff4f7880fbc72b68eb965c", "best_bid": "0.39", "best_ask": "0.53"}], "timestamp": "1769384924209", "event_type": "price_change"}}
{"_local_timestamp": "2026-01-25T23:48:44.285009+00:00", "data": {"market": "0x594b0c20ab8dbc69e114332a492e070b443aeb224b92044cb578a12e6c2e3803", "price_changes": [{"asset_id": "42419209928828774975861486950092174694128319564350299621877859389614951820121", "price": "0.22", "size": "0", "side": "BUY", "hash": "60c60c2467b2b8a8f7c987ece5a6016c240a5bcd", "best_bid": "0.39", "best_ask": "0.53"}, {"asset_id": "53045599992634231073170577534514793656648939708140653871029455415927166771776", "price": "0.78", "size": "0", "side": "SELL", "hash": "1c2a1e2c1a075d57008b5685161929fe9f31c0ec", "best_bid": "0.47", "best_ask": "0.61"}], "timestamp": "1769384924209", "event_type": "price_change"}}
{"_local_timestamp": "2026-01-25T23:48:44.339815+00:00", "data": {"market": "0x0ff3980b4522405063e04e1428c599d4f4a595046d31a2ec7645874e7428cb0d", "price_changes": [{"asset_id": "70763686139594410379687997157193094521970112097061328887093252009180194073103", "price": "0.13", "size": "8.5", "side": "BUY", "hash": "c427784b3ed532397be3a639c5200396ecfe187a", "best_bid": "0.45", "best_ask": "0.59"}, {"asset_id": "111727512223221006993329893518872991949884788881551465044898427984500489504625", "price": "0.87", "size": "8.5", "side": "SELL", "hash": "1de80d9ce0da7f375e5793fbca97dd1eb1fe2966", "best_bid": "0.41", "best_ask": "0.55"}], "timestamp": "1769384924273", "event_type": "price_change"}}
{"_local_timestamp": "2026-01-25T23:48:44.340298+00:00", "data": {"market": "0x0ff3980b4522405063e04e1428c599d4f4a595046d31a2ec7645874e7428cb0d", "price_changes": [{"asset_id": "111727512223221006993329893518872991949884788881551465044898427984500489504625", "price": "0.12", "size": "8.5", "side": "BUY", "hash": "a97718578d428fde14111155f5ee50d3faaee9df", "best_bid": "0.41", "best_ask": "0.55"}, {"asset_id": "70763686139594410379687997157193094521970112097061328887093252009180194073103", "price": "0.88", "size": "8.5", "side": "SELL", "hash": "948cbf5b3fe9d13184b85e0fdde55cefa8233619", "best_bid": "0.45", "best_ask": "0.59"}], "timestamp": "1769384924274", "event_type": "price_change"}}
{"_local_timestamp": "2026-01-25T23:49:47.923909+00:00", "data": {"market": "0x0ff3980b4522405063e04e1428c599d4f4a595046d31a2ec7645874e7428cb0d", "price_changes": [{"asset_id": "111727512223221006993329893518872991949884788881551465044898427984500489504625", "price": "0.01", "size": "65.29", "side": "BUY", "hash": "e68e9edeb27074e90293fd49f912095e8a688a5d", "best_bid": "0.41", "best_ask": "0.55"}, {"asset_id": "70763686139594410379687997157193094521970112097061328887093252009180194073103", "price": "0.99", "size": "65.29", "side": "SELL", "hash": "0b1de333267eba45de86ee4cd563f50bf18f859e", "best_bid": "0.45", "best_ask": "0.59"}], "timestamp": "1769384987833", "event_type": "price_change"}}
{"_local_timestamp": "2026-01-25T23:49:47.924674+00:00", "data": {"market": "0x0ff3980b4522405063e04e1428c599d4f4a595046d31a2ec7645874e7428cb0d", "price_changes": [{"asset_id": "111727512223221006993329893518872991949884788881551465044898427984500489504625", "price": "0.03", "size": "0", "side": "BUY", "hash": "e68e9edeb27074e90293fd49f912095e8a688a5d", "best_bid": "0.41", "best_ask": "0.55"}, {"asset_id": "70763686139594410379687997157193094521970112097061328887093252009180194073103", "price": "0.97", "size": "0", "side": "SELL", "hash": "0b1de333267eba45de86ee4cd563f50bf18f859e", "best_bid": "0.45", "best_ask": "0.59"}], "timestamp": "1769384987833", "event_type": "price_change"}}
{"_local_timestamp": "2026-01-25T23:49:47.925136+00:00", "data": {"market": "0x0ff3980b4522405063e04e1428c599d4f4a595046d31a2ec7645874e7428cb0d", "price_changes": [{"asset_id": "111727512223221006993329893518872991949884788881551465044898427984500489504625", "price": "0.1", "size": "0", "side": "BUY", "hash": "e68e9edeb27074e90293fd49f912095e8a688a5d", "best_bid": "0.41", "best_ask": "0.55"}, {"asset_id": "70763686139594410379687997157193094521970112097061328887093252009180194073103", "price": "0.9", "size": "0", "side": "SELL", "hash": "0b1de333267eba45de86ee4cd563f50bf18f859e", "best_bid": "0.45", "best_ask": "0.59"}], "timestamp": "1769384987833", "event_type": "price_change"}}
{"_local_timestamp": "2026-01-25T23:49:48.646744+00:00", "data": {"market": "0x6e859824d83194fc088766d7c363adb6e32525b1890d547f2bffb3dce3b5f444", "price_changes": [{"asset_id": "47571364726448727838964706866240873454603775655157083187789979094117274002718", "price": "0.03", "size": "75", "side": "BUY", "hash": "88e61c068b36d3d22211724f2b26639a468e056e", "best_bid": "0.2", "best_ask": "0.34"}, {"asset_id": "1007592767152593904120906718548640287423186514852220759324946644995163459383", "price": "0.97", "size": "75", "side": "SELL", "hash": "239ee606185e518fcce3d67e4bb539f72d27db0a", "best_bid": "0.66", "best_ask": "0.8"}], "timestamp": "1769384988579", "event_type": "price_change"}}
{"_local_timestamp": "2026-01-25T23:49:48.647230+00:00", "data": {"market": "0x0ff3980b4522405063e04e1428c599d4f4a595046d31a2ec7645874e7428cb0d", "price_changes": [{"asset_id": "70763686139594410379687997157193094521970112097061328887093252009180194073103", "price": "0.01", "size": "65.15", "side": "BUY", "hash": "43f16dacf3bbd2a27ac10d468280696e0ec73986", "best_bid": "0.45", "best_ask": "0.59"}, {"asset_id": "111727512223221006993329893518872991949884788881551465044898427984500489504625", "price": "0.99", "size": "65.15", "side": "SELL", "hash": "95d1404f79e9d35bcfc1f27b1943ca96da03e936", "best_bid": "0.41", "best_ask": "0.55"}], "timestamp": "1769384988579", "event_type": "price_change"}}
{"_local_timestamp": "2026-01-25T23:49:48.647637+00:00", "data": {"market": "0x0ff3980b4522405063e04e1428c599d4f4a595046d31a2ec7645874e7428cb0d", "price_changes": [{"asset_id": "70763686139594410379687997157193094521970112097061328887093252009180194073103", "price": "0.03", "size": "0", "side": "BUY", "hash": "43f16dacf3bbd2a27ac10d468280696e0ec73986", "best_bid": "0.45", "best_ask": "0.59"}, {"asset_id": "111727512223221006993329893518872991949884788881551465044898427984500489504625", "price": "0.97", "size": "0", "side": "SELL", "hash": "95d1404f79e9d35bcfc1f27b1943ca96da03e936", "best_bid": "0.41", "best_ask": "0.55"}], "timestamp": "1769384988579", "event_type": "price_change"}}
{"_local_timestamp": "2026-01-25T23:49:48.648058+00:00", "data": {"market": "0x0ff3980b4522405063e04e1428c599d4f4a595046d31a2ec7645874e7428cb0d", "price_changes": [{"asset_id": "70763686139594410379687997157193094521970112097061328887093252009180194073103", "price": "0.07", "size": "0", "side": "BUY", "hash": "43f16dacf3bbd2a27ac10d468280696e0ec73986", "best_bid": "0.45", "best_ask": "0.59"}, {"asset_id": "111727512223221006993329893518872991949884788881551465044898427984500489504625", "price": "0.93", "size": "0", "side": "SELL", "hash": "95d1404f79e9d35bcfc1f27b1943ca96da03e936", "best_bid": "0.41", "best_ask": "0.55"}], "timestamp": "1769384988579", "event_type": "price_change"}}
{"_local_timestamp": "2026-01-25T23:49:48.677772+00:00", "data": {"market": "0x0ff3980b4522405063e04e1428c599d4f4a595046d31a2ec7645874e7428cb0d", "price_changes": [{"asset_id": "111727512223221006993329893518872991949884788881551465044898427984500489504625", "price": "0.01", "size": "70.87", "side": "BUY", "hash": "4764b9aed702a3f155611b40b5e787b94bd3e143", "best_bid": "0.41", "best_ask": "0.55"}, {"asset_id": "70763686139594410379687997157193094521970112097061328887093252009180194073103", "price": "0.99", "size": "70.87", "side": "SELL", "hash": "ccaf1bf78cbd63d48537eed4817d7c38cdd69f8b", "best_bid": "0.45", "best_ask": "0.59"}], "timestamp": "1769384988611", "event_type": "price_change"}}
{"_local_timestamp": "2026-01-25T23:49:48.682173+00:00", "data": {"market": "0x0ff3980b4522405063e04e1428c599d4f4a595046d31a2ec7645874e7428cb0d", "price_changes": [{"asset_id": "111727512223221006993329893518872991949884788881551465044898427984500489504625", "price": "0.03", "size": "11.35", "side": "BUY", "hash": "d35fa2e4191eea24e83a9ac17386978f23349eb0", "best_bid": "0.41", "best_ask": "0.55"}, {"asset_id": "70763686139594410379687997157193094521970112097061328887093252009180194073103", "price": "0.97", "size": "11.35", "side": "SELL", "hash": "64d1a261061276efd8adf1774c164c1db246aa12", "best_bid": "0.45", "best_ask": "0.59"}], "timestamp": "1769384988613", "event_type": "price_change"}}
{"_local_timestamp": "2026-01-25T23:49:48.682821+00:00", "data": {"market": "0x0ff3980b4522405063e04e1428c599d4f4a595046d31a2ec7645874e7428cb0d", "price_changes": [{"asset_id": "111727512223221006993329893518872991949884788881551465044898427984500489504625", "price": "0.11", "size": "370", "side": "BUY", "hash": "7a635f8f5dab316684cb6a16354c34fd644e0515", "best_bid": "0.41", "best_ask": "0.55"}, {"asset_id": "70763686139594410379687997157193094521970112097061328887093252009180194073103", "price": "0.89", "size": "370", "side": "SELL", "hash": "54992f26307746610b498c531f1598a345e253ad", "best_bid": "0.45", "best_ask": "0.59"}], "timestamp": "1769384988615", "event_type": "price_change"}}
{"_local_timestamp": "2026-01-25T23:49:49.154397+00:00", "data": {"market": "0x594b0c20ab8dbc69e114332a492e070b443aeb224b92044cb578a12e6c2e3803", "price_changes": [{"asset_id": "53045599992634231073170577534514793656648939708140653871029455415927166771776", "price": "0.01", "size": "165.1", "side": "BUY", "hash": "0d36698fca2abbfc500d71ddf9445abe4d2fe41b", "best_bid": "0.47", "best_ask": "0.61"}, {"asset_id": "42419209928828774975861486950092174694128319564350299621877859389614951820121", "price": "0.99", "size": "165.1", "side": "SELL", "hash": "1a1acfe981acbfe841c690c4ae70a5118be676f4", "best_bid": "0.39", "best_ask": "0.53"}], "timestamp": "1769384989038", "event_type": "price_change"}}
{"_local_timestamp": "2026-01-25T23:49:49.154994+00:00", "data": {"market": "0x594b0c20ab8dbc69e114332a492e070b443aeb224b92044cb578a12e6c2e3803", "price_changes": [{"asset_id": "53045599992634231073170577534514793656648939708140653871029455415927166771776", "price": "0.03", "size": "0", "side": "BUY", "hash": "0d36698fca2abbfc500d71ddf9445abe4d2fe41b", "best_bid": "0.47", "best_ask": "0.61"}, {"asset_id": "42419209928828774975861486950092174694128319564350299621877859389614951820121", "price": "0.97", "size": "0", "side": "SELL", "hash": "1a1acfe981acbfe841c690c4ae70a5118be676f4", "best_bid": "0.39", "best_ask": "0.53"}], "timestamp": "1769384989038", "event_type": "price_change"}}
{"_local_timestamp": "2026-01-25T23:49:49.155529+00:00", "data": {"market": "0x594b0c20ab8dbc69e114332a492e070b443aeb224b92044cb578a12e6c2e3803", "price_changes": [{"asset_id": "53045599992634231073170577534514793656648939708140653871029455415927166771776", "price": "0.07", "size": "0", "side": "BUY", "hash": "0d36698fca2abbfc500d71ddf9445abe4d2fe41b", "best_bid": "0.47", "best_ask": "0.61"}, {"asset_id": "42419209928828774975861486950092174694128319564350299621877859389614951820121", "price": "0.93", "size": "0", "side": "SELL", "hash": "1a1acfe981acbfe841c690c4ae70a5118be676f4", "best_bid": "0.39", "best_ask": "0.53"}], "timestamp": "1769384989038", "event_type": "price_change"}}
{"_local_timestamp": "2026-01-25T23:49:50.191682+00:00", "data": {"market": "0x0ff3980b4522405063e04e1428c599d4f4a595046d31a2ec7645874e7428cb0d", "price_changes": [{"asset_id": "70763686139594410379687997157193094521970112097061328887093252009180194073103", "price": "0.02", "size": "859.63", "side": "BUY", "hash": "b092abacef57c10b296be3102d39e4d8511f923d", "best_bid": "0.45", "best_ask": "0.59"}, {"asset_id": "111727512223221006993329893518872991949884788881551465044898427984500489504625", "price": "0.98", "size": "859.63", "side": "SELL", "hash": "76350cb096fcd8c5c5ae2a79f823aeaad6f87a4e", "best_bid": "0.41", "best_ask": "0.55"}], "timestamp": "1769384990011", "event_type": "price_change"}}
{"_local_timestamp": "2026-01-25T23:49:50.192225+00:00", "data": {"market": "0x6e859824d83194fc088766d7c363adb6e32525b1890d547f2bffb3dce3b5f444", "price_changes": [{"asset_id": "47571364726448727838964706866240873454603775655157083187789979094117274002718", "price": "0.02", "size": "157.13", "side": "BUY", "hash": "3c0d802da555b65454894ef62ccc256b2ce580b7", "best_bid": "0.2", "best_ask": "0.34"}, {"asset_id": "1007592767152593904120906718548640287423186514852220759324946644995163459383", "price": "0.98", "size": "157.13", "side": "SELL", "hash": "943f22f05acd4a350ba7ef8f178a22b25656c929", "best_bid": "0.66", "best_ask": "0.8"}], "timestamp": "1769384990012", "event_type": "price_change"}}
{"_local_timestamp": "2026-01-25T23:49:50.192666+00:00", "data": {"market": "0x0ff3980b4522405063e04e1428c599d4f4a595046d31a2ec7645874e7428cb0d", "price_changes": [{"asset_id": "70763686139594410379687997157193094521970112097061328887093252009180194073103", "price": "0.06", "size": "12.59", "side": "BUY", "hash": "0a232b72bb2e84773a61d0f3f3516c0e8b1ac24d", "best_bid": "0.45", "best_ask": "0.59"}, {"asset_id": "111727512223221006993329893518872991949884788881551465044898427984500489504625", "price": "0.94", "size": "12.59", "side": "SELL", "hash": "46b89e5eb1e52194760769ae376e41106f769423", "best_bid": "0.41", "best_ask": "0.55"}], "timestamp": "1769384990013", "event_type": "price_change"}}
{"_local_timestamp": "2026-01-25T23:49:50.193356+00:00", "data": {"market": "0x6e859824d83194fc088766d7c363adb6e32525b1890d547f2bffb3dce3b5f444", "price_changes": [{"asset_id": "47571364726448727838964706866240873454603775655157083187789979094117274002718", "price": "0.04", "size": "6.1", "side": "BUY", "hash": "9fc15d767183f9f0e2f8acf7a177e39dddca75dc", "best_bid": "0.2", "best_ask": "0.34"}, {"asset_id": "1007592767152593904120906718548640287423186514852220759324946644995163459383", "price": "0.96", "size": "6.1", "side": "SELL", "hash": "1f8608d0011377c04c8d65af03a2d8477ae5ba77", "best_bid": "0.66", "best_ask": "0.8"}], "timestamp": "1769384990015", "event_type": "price_change"}}
{"_local_timestamp": "2026-01-25T23:49:50.235830+00:00", "data": {"market": "0x594b0c20ab8dbc69e114332a492e070b443aeb224b92044cb578a12e6c2e3803", "price_changes": [{"asset_id": "53045599992634231073170577534514793656648939708140653871029455415927166771776", "price": "0.01", "size": "170.52", "side": "BUY", "hash": "9789e81f94432155bd1f5f25ec3688af09a34de9", "best_bid": "0.47", "best_ask": "0.61"}, {"asset_id": "42419209928828774975861486950092174694128319564350299621877859389614951820121", "price": "0.99", "size": "170.52", "side": "SELL", "hash": "8e307cacaa46f57e5331eee7fd84c025f8b17dc7", "best_bid": "0.39", "best_ask": "0.53"}], "timestamp": "1769384990080", "event_type": "price_change"}}
{"_local_timestamp": "2026-01-25T23:49:50.243347+00:00", "data": {"market": "0x594b0c20ab8dbc69e114332a492e070b443aeb224b92044cb578a12e6c2e3803", "price_changes": [{"asset_id": "53045599992634231073170577534514793656648939708140653871029455415927166771776", "price": "0.08", "size": "8.42", "side": "BUY", "hash": "ee2ece2a6555ed3ceff24f9c444547885a70c80b", "best_bid": "0.47", "best_ask": "0.61"}, {"asset_id": "42419209928828774975861486950092174694128319564350299621877859389614951820121", "price": "0.92", "size": "8.42", "side": "SELL", "hash": "887eb038f7ef41b3cec590530d772a1b67af19ff", "best_bid": "0.39", "best_ask": "0.53"}], "timestamp": "1769384990083", "event_type": "price_change"}}
{"_local_timestamp": "2026-01-25T23:49:50.243867+00:00", "data": {"market": "0x594b0c20ab8dbc69e114332a492e070b443aeb224b92044cb578a12e6c2e3803", "price_changes": [{"asset_id": "53045599992634231073170577534514793656648939708140653871029455415927166771776", "price": "0.03", "size": "7.36", "side": "BUY", "hash": "16b979930f1043e16ea12cce2a9388d3290ffe38", "best_bid": "0.47", "best_ask": "0.61"}, {"asset_id": "42419209928828774975861486950092174694128319564350299621877859389614951820121", "price": "0.97", "size": "7.36", "side": "SELL", "hash": "b35f9327c8ebf2e88d89581a8477a4e120543445", "best_bid": "0.39", "best_ask": "0.53"}], "timestamp": "1769384990086", "event_type": "price_change"}}
{"_local_timestamp": "2026-01-25T23:49:50.460656+00:00", "data": {"market": "0x594b0c20ab8dbc69e114332a492e070b443aeb224b92044cb578a12e6c2e3803", "price_changes": [{"asset_id": "42419209928828774975861486950092174694128319564350299621877859389614951820121", "price": "0.01", "size": "165.42", "side": "BUY", "hash": "c68d483f4825f3cd3eca4d9b0a87b2595c1fadd1", "best_bid": "0.39", "best_ask": "0.53"}, {"asset_id": "53045599992634231073170577534514793656648939708140653871029455415927166771776", "price": "0.99", "size": "165.42", "side": "SELL", "hash": "80af427c02f914ff0f3631b05d45216d509b5d27", "best_bid": "0.47", "best_ask": "0.61"}], "timestamp": "1769384990377", "event_type": "price_change"}}
{"_local_timestamp": "2026-01-25T23:49:50.468884+00:00", "data": {"market": "0x594b0c20ab8dbc69e114332a492e070b443aeb224b92044cb578a12e6c2e3803", "price_changes": [{"asset_id": "42419209928828774975861486950092174694128319564350299621877859389614951820121", "price": "0.03", "size": "0", "side": "BUY", "hash": "c68d483f4825f3cd3eca4d9b0a87b2595c1fadd1", "best_bid": "0.39", "best_ask": "0.53"}, {"asset_id": "53045599992634231073170577534514793656648939708140653871029455415927166771776", "price": "0.97", "size": "0", "side": "SELL", "hash": "80af427c02f914ff0f3631b05d45216d509b5d27", "best_bid": "0.47", "best_ask": "0.61"}], "timestamp": "1769384990377", "event_type": "price_change"}}
{"_local_timestamp": "2026-01-25T23:49:50.480886+00:00", "data": {"market": "0x594b0c20ab8dbc69e114332a492e070b443aeb224b92044cb578a12e6c2e3803", "price_changes": [{"asset_id": "42419209928828774975861486950092174694128319564350299621877859389614951820121", "price": "0.07", "size": "0", "side": "BUY", "hash": "c68d483f4825f3cd3eca4d9b0a87b2595c1fadd1", "best_bid": "0.39", "best_ask": "0.53"}, {"asset_id": "53045599992634231073170577534514793656648939708140653871029455415927166771776", "price": "0.93", "size": "0", "side": "SELL", "hash": "80af427c02f914ff0f3631b05d45216d509b5d27", "best_bid": "0.47", "best_ask": "0.61"}], "timestamp": "1769384990377", "event_type": "price_change"}}
{"_local_timestamp": "2026-01-25T23:49:52.723052+00:00", "data": {"market": "0x594b0c20ab8dbc69e114332a492e070b443aeb224b92044cb578a12e6c2e3803", "price_changes": [{"asset_id": "42419209928828774975861486950092174694128319564350299621877859389614951820121", "price": "0.03", "size": "7.74", "side": "BUY", "hash": "3eb44c3bea832e6b59cdf18591f844c261df61e2", "best_bid": "0.39", "best_ask": "0.53"}, {"asset_id": "53045599992634231073170577534514793656648939708140653871029455415927166771776", "price": "0.97", "size": "7.74", "side": "SELL", "hash": "17a0e28b45c24887b8ab6df0caebf0bf5ed17a39", "best_bid": "0.47", "best_ask": "0.61"}], "timestamp": "1769384992656", "event_type": "price_change"}}
{"_local_timestamp": "2026-01-25T23:49:52.727332+00:00", "data": {"market": "0x594b0c20ab8dbc69e114332a492e070b443aeb224b92044cb578a12e6c2e3803", "price_changes": [{"asset_id": "42419209928828774975861486950092174694128319564350299621877859389614951820121", "price": "0.01", "size": "171.06", "side": "BUY", "hash": "4c3e05c7a4a4685e3ebb879622c13ae17f3b2932", "best_bid": "0.39", "best_ask": "0.53"}, {"asset_id": "53045599992634231073170577534514793656648939708140653871029455415927166771776", "price": "0.99", "size": "171.06", "side": "SELL", "hash": "1e3ae938b9a6ba864fce84291a8f0fe7fb29dbc4", "best_bid": "0.47", "best_ask": "0.61"}], "timestamp": "1769384992658", "event_type": "price_change"}}
{"_local_timestamp": "2026-01-25T23:49:52.727963+00:00", "data": {"market": "0x594b0c20ab8dbc69e114332a492e070b443aeb224b92044cb578a12e6c2e3803", "price_changes": [{"asset_id": "42419209928828774975861486950092174694128319564350299621877859389614951820121", "price": "0.08", "size": "8.21", "side": "BUY", "hash": "f1caaad19a3cb87da6fe73dfcfe98c681cfdb578", "best_bid": "0.39", "best_ask": "0.53"}, {"asset_id": "53045599992634231073170577534514793656648939708140653871029455415927166771776", "price": "0.92", "size": "8.21", "side": "SELL", "hash": "1eafb1babcb6846b61bcd7a748fc2cf60c057c58", "best_bid": "0.47", "best_ask": "0.61"}], "timestamp": "1769384992661", "event_type": "price_change"}}
