{"_local_timestamp": "2026-01-25T23:33:20.188440+00:00", "data": [{"market": "0xe655180a65e17b6959aa722821312de23513cba6c6d2e3a55f47f198977316bf", "asset_id": "47848555635748009983462962481545341194026880518141560747711492227563791266566", "timestamp": "1769383905194", "hash": "cfb115b69465ca9c847972db5e4f33e7c2a5da65", "bids": [{"price": "0.01", "size": "510000"}, {"price": "0.04", "size": "20000"}, {"price": "0.09", "size": "400"}, {"price": "0.14", "size": "242.85"}, {"price": "0.18", "size": "177.77"}, {"price": "0.19", "size": "3052"}, {"price": "0.23", "size": "121.73"}, {"price": "0.27", "size": "96.29"}, {"price": "0.32", "size": "75"}, {"price": "0.34", "size": "4062"}, {"price": "0.35", "size": "300"}, {"price": "0.36", "size": "55.55"}, {"price": "0.37", "size": "10"}, {"price": "0.86", "size": "111"}, {"price": "0.88", "size": "575.83"}, {"price": "0.89", "size": "2881.79"}], "asks": [{"price": "0.99", "size": "10080"}, {"price": "0.98", "size": "250"}, {"price": "0.97", "size": "20"}, {"price": "0.96", "size": "10"}, {"price": "0.93", "size": "625"}, {"price": "0.92", "size": "3065.99"}, {"price": "0.91", "size": "1624.16"}], "event_type": "book", "last_trade_price": "0.890"}, {"market": "0x0465cd005a54781e052b679e2c42c7ae5b772490fdda54316f157bf537536456", "asset_id": "37755135088405799849800190027343457715121200916302661996402931566317384140291", "timestamp": "1769383986540", "hash": "13570b888e1d87156672fa06dd8016fb7be998ea", "bids": [{"price": "0.01", "size": "510000"}, {"price": "0.03", "size": "5000"}, {"price": "0.05", "size": "15000"}, {"price": "0.06", "size": "9000"}, {"price": "0.09", "size": "400"}, {"price": "0.14", "size": "242.85"}, {"price": "0.18", "size": "177.77"}, {"price": "0.19", "size": "842"}, {"price": "0.2", "size": "2100"}, {"price": "0.23", "size": "121.73"}, {"price": "0.27", "size": "96.29"}, {"price": "0.28", "size": "7"}, {"price": "0.3", "size": "4611"}, {"price": "0.31", "size": "300"}, {"price": "0.32", "size": "75"}, {"price": "0.36", "size": "55.55"}, {"price": "0.64", "size": "10"}, {"price": "0.65", "size": "20"}, {"price": "0.87", "size": "214.9"}, {"price": "0.88", "size": "361"}, {"price": "0.89", "size": "2939.24"}], "asks": [{"price": "0.99", "size": "95"}, {"price": "0.92", "size": "3191"}, {"price": "0.91", "size": "450.61"}], "event_type": "book", "last_trade_price": ""}, {"market": "0x0465cd005a54781e052b679e2c42c7ae5b772490fdda54316f157bf537536456", "asset_id": "109815773012907461372639157658293071578555374097742562684476865021743386609433", "timestamp": "1769383986540", "hash": "ce4af4d0952ebc6b08338b81588300c54e5b3f11", "bids": [{"price": "0.01", "size": "95"}, {"price": "0.08", "size": "3191"}, {"price": "0.09", "size": "450.61"}], "asks": [{"price": "0.99", "size": "510000"}, {"price": "0.97", "size": "5000"}, {"price": "0.95", "size": "15000"}, {"price": "0.94", "size": "9000"}, {"price": "0.91", "size": "400"}, {"price": "0.86", "size": "242.85"}, {"price": "0.82", "size": "177.77"}, {"price": "0.81", "size": "842"}, {"price": "0.8", "size": "2100"}, {"price": "0.77", "size": "121.73"}, {"price": "0.73", "size": "96.29"}, {"price": "0.72", "size": "7"}, {"price": "0.7", "size": "4611"}, {"price": "0.69", "size": "300"}, {"price": "0.68", "size": "75"}, {"price": "0.64", "size": "55.55"}, {"price": "0.36", "size": "10"}, {"price": "0.35", "size": "20"}, {"price": "0.13", "size": "214.9"}, {"price": "0.12", "size": "361"}, {"price": "0.11", "size": "2939.24"}], "event_type": "book", "last_trade_price": ""}, {"market": "0xe655180a65e17b6959aa722821312de23513cba6c6d2e3a55f47f198977316bf", "asset_id": "93154595056268120397334102801062018916555787278126869430194069115332749753248", "timestamp": "1769383905194", "hash": "4bb5569a4e7f8901853a38d567d5bfb9f3cfca70", "bids": [{"price": "0.01", "size": "10080"}, {"price": "0.02", "size": "250"}, {"price": "0.03", "size": "20"}, {"price": "0.04", "size": "10"}, {"price": "0.07", "size": "625"}, {"price": "0.08", "size": "3065.99"}, {"price": "0.09", "size": "1624.16"}], "asks": [{"price": "0.99", "size": "510000"}, {"price": "0.96", "size": "20000"}, {"price": "0.91", "size": "400"}, {"price": "0.86", "size": "242.85"}, {"price": "0.82", "size": "177.77"}, {"price": "0.81", "size": "3052"}, {"price": "0.77", "size": "121.73"}, {"price": "0.73", "size": "96.29"}, {"price": "0.68", "size": "75"}, {"price": "0.66", "size": "4062"}, {"price": "0.65", "size": "300"}, {"price": "0.64", "size": "55.55"}, {"price": "0.63", "size": "10"}, {"price": "0.14", "size": "111"}, {"price": "0.12", "size": "575.83"}, {"price": "0.11", "size": "2881.79"}], "event_type": "book", "last_trade_price": "0.890"}]}
{"_local_timestamp": "2026-01-25T23:34:01.563141+00:00", "data": {"market": "0x0465cd005a54781e052b679e2c42c7ae5b772490fdda54316f157bf537536456", "price_changes": [{"asset_id": "37755135088405799849800190027343457715121200916302661996402931566317384140291", "price": "0.64", "size": "0", "side": "BUY", "hash": "e5576169089774a40a8f5c00a8e74da23e705e82", "best_bid": "0.89", "best_ask": "0.91"}, {"asset_id": "109815773012907461372639157658293071578555374097742562684476865021743386609433", "price": "0.36", "size": "0", "side": "SELL", "hash": "3647ba6424b8a8e1757f3bab1a8a10a9ca0415af", "best_bid": "0.09", "best_ask": "0.11"}], "timestamp": "1769384041485", "event_type": "price_change"}}
{"_local_timestamp": "2026-01-25T23:34:01.749026+00:00", "data": {"market": "0x0465cd005a54781e052b679e2c42c7ae5b772490fdda54316f157bf537536456", "price_changes": [{"asset_id": "37755135088405799849800190027343457715121200916302661996402931566317384140291", "price": "0.66", "size": "10", "side": "BUY", "hash": "2195b5af6f3b16beeaa638f46138fb5b0e7d78e9", "best_bid": "0.89", "best_ask": "0.91"}, {"asset_id": "109815773012907461372639157658293071578555374097742562684476865021743386609433", "price": "0.34", "size": "10", "side": "SELL", "hash": "46c266764d12bdd8abbd11c25bf5e2b3e3cb1559", "best_bid": "0.09", "best_ask": "0.11"}], "timestamp": "1769384041682", "event_type": "price_change"}}
{"_local_timestamp": "2026-01-25T23:34:03.892538+00:00", "data": {"market": "0x0465cd005a54781e052b679e2c42c7ae5b772490fdda54316f157bf537536456", "price_changes": [{"asset_id": "37755135088405799849800190027343457715121200916302661996402931566317384140291", "price": "0.65", "size": "0", "side": "BUY", "hash": "d0bc6305ab37b3384191e222389bebe3896a5f86", "best_bid": "0.89", "best_ask": "0.91"}, {"asset_id": "109815773012907461372639157658293071578555374097742562684476865021743386609433", "price": "0.35", "size": "0", "side": "SELL", "hash": "1583658469623f35ebbbede35c0daff4e0787dcc", "best_bid": "0.09", "best_ask": "0.11"}], "timestamp": "1769384043668", "event_type": "price_change"}}
{"_local_timestamp": "2026-01-25T23:34:03.913047+00:00", "data": {"market": "0x0465cd005a54781e052b679e2c42c7ae5b772490fdda54316f157bf537536456", "price_changes": [{"asset_id": "37755135088405799849800190027343457715121200916302661996402931566317384140291", "price": "0.67", "size": "20", "side": "BUY", "hash": "1d40f0f29d2f8ff9a1db165bafc966b2a07b7a40", "best_bid": "0.89", "best_ask": "0.91"}, {"asset_id": "109815773012907461372639157658293071578555374097742562684476865021743386609433", "price": "0.33", "size": "20", "side": "SELL", "hash": "25e9b2575ad356644c51907d72254558ee6de89e", "best_bid": "0.09", "best_ask": "0.11"}], "timestamp": "1769384043696", "event_type": "price_change"}}
{"_local_timestamp": "2026-01-25T23:35:01.899712+00:00", "data": {"market": "0x0465cd005a54781e052b679e2c42c7ae5b772490fdda54316f157bf537536456", "price_changes": [{"asset_id": "37755135088405799849800190027343457715121200916302661996402931566317384140291", "price": "0.66", "size": "0", "side": "BUY", "hash": "e827429e498d426c1ed088d41dec1eb9ff5a4f15", "best_bid": "0.89", "best_ask": "0.91"}, {"asset_id": "109815773012907461372639157658293071578555374097742562684476865021743386609433", "price": "0.34", "size": "0", "side": "SELL", "hash": "ed11dd569dc57e6ea08792c7ee5c8f7df0d6ea15", "best_bid": "0.09", "best_ask": "0.11"}], "timestamp": "1769384101820", "event_type": "price_change"}}
{"_local_timestamp": "2026-01-25T23:35:01.977824+00:00", "data": {"market": "0x0465cd005a54781e052b679e2c42c7ae5b772490fdda54316f157bf537536456", "price_changes": [{"asset_id": "37755135088405799849800190027343457715121200916302661996402931566317384140291", "price": "0.68", "size": "10", "side": "BUY", "hash": "92e0cced3954bfb3d5dcb26e82690cbabf8560e6", "best_bid": "0.89", "best_ask": "0.91"}, {"asset_id": "109815773012907461372639157658293071578555374097742562684476865021743386609433", "price": "0.32", "size": "10", "side": "SELL", "hash": "649efdb27a937216806e404c1c5e4326dd829cea", "best_bid": "0.09", "best_ask": "0.11"}], "timestamp": "1769384101912", "event_type": "price_change"}}
{"_local_timestamp": "2026-01-25T23:35:04.729726+00:00", "data": {"market": "0x0465cd005a54781e052b679e2c42c7ae5b772490fdda54316f157bf537536456", "price_changes": [{"asset_id": "37755135088405799849800190027343457715121200916302661996402931566317384140291", "price": "0.67", "size": "0", "side": "BUY", "hash": "25c65011cc6f052b537dacc037a75ad1b73c192c", "best_bid": "0.89", "best_ask": "0.91"}, {"asset_id": "109815773012907461372639157658293071578555374097742562684476865021743386609433", "price": "0.33", "size": "0", "side": "SELL", "hash": "0d28390c54c487d82534c45e1b28e256a23811ff", "best_bid": "0.09", "best_ask": "0.11"}], "timestamp": "1769384104652", "event_type": "price_change"}}
{"_local_timestamp": "2026-01-25T23:35:04.748930+00:00", "data": {"market": "0x0465cd005a54781e052b679e2c42c7ae5b772490fdda54316f157bf537536456", "price_changes": [{"asset_id": "37755135088405799849800190027343457715121200916302661996402931566317384140291", "price": "0.69", "size": "20", "side": "BUY", "hash": "2ebeb9373ac6a4fa3f06815b774ff5d9b50847bd", "best_bid": "0.89", "best_ask": "0.91"}, {"asset_id": "109815773012907461372639157658293071578555374097742562684476865021743386609433", "price": "0.31", "size": "20", "side": "SELL", "hash": "d427048a4c90e540ce2d53407f710256aa7fb77f", "best_bid": "0.09", "best_ask": "0.11"}], "timestamp": "1769384104680", "event_type": "price_change"}}
{"_local_timestamp": "2026-01-25T23:36:19.680324+00:00", "data": {"market": "0x0465cd005a54781e052b679e2c42c7ae5b772490fdda54316f157bf537536456", "price_changes": [{"asset_id": "37755135088405799849800190027343457715121200916302661996402931566317384140291", "price": "0.68", "size": "0", "side": "BUY", "hash": "9c8c1f64a0af984665de21bb748e821cd6c6ee76", "best_bid": "0.89", "best_ask": "0.91"}, {"asset_id": "109815773012907461372639157658293071578555374097742562684476865021743386609433", "price": "0.32", "size": "0", "side": "SELL", "hash": "195490577f35a02514339760786faba006ff4432", "best_bid": "0.09", "best_ask": "0.11"}], "timestamp": "1769384179613", "event_type": "price_change"}}
{"_local_timestamp": "2026-01-25T23:36:19.802212+00:00", "data": {"market": "0x0465cd005a54781e052b679e2c42c7ae5b772490fdda54316f157bf537536456", "price_changes": [{"asset_id": "37755135088405799849800190027343457715121200916302661996402931566317384140291", "price": "0.7", "size": "10", "side": "BUY", "hash": "38a8aea3c523f7e61a9d15c8690d7b4b3ed3b3af", "best_bid": "0.89", "best_ask": "0.91"}, {"asset_id": "109815773012907461372639157658293071578555374097742562684476865021743386609433", "price": "0.3", "size": "10", "side": "SELL", "hash": "a9d0c4b4315298a6057494139693712099cd26a7", "best_bid": "0.09", "best_ask": "0.11"}], "timestamp": "1769384179737", "event_type": "price_change"}}
{"_local_timestamp": "2026-01-25T23:36:21.574909+00:00", "data": {"market": "0x0465cd005a54781e052b679e2c42c7ae5b772490fdda54316f157bf537536456", "price_changes": [{"asset_id": "37755135088405799849800190027343457715121200916302661996402931566317384140291", "price": "0.69", "size": "0", "side": "BUY", "hash": "5ad1535c8e5acb8e65a2e4a0fa6d98fc9eb7e640", "best_bid": "0.89", "best_ask": "0.91"}, {"asset_id": "109815773012907461372639157658293071578555374097742562684476865021743386609433", "price": "0.31", "size": "0", "side": "SELL", "hash": "fd8427f164074f7a6280ab66efebac825d4306c5", "best_bid": "0.09", "best_ask": "0.11"}], "timestamp": "1769384181467", "event_type": "price_change"}}
{"_local_timestamp": "2026-01-25T23:36:21.599368+00:00", "data": {"market": "0x0465cd005a54781e052b679e2c42c7ae5b772490fdda54316f157bf537536456", "price_changes": [{"asset_id": "37755135088405799849800190027343457715121200916302661996402931566317384140291", "price": "0.71", "size": "20", "side": "BUY", "hash": "4bd7783d06131e0c8f5d17b15680f5cb9054fc74", "best_bid": "0.89", "best_ask": "0.91"}, {"asset_id": "109815773012907461372639157658293071578555374097742562684476865021743386609433", "price": "0.29", "size": "20", "side": "SELL", "hash": "9577616bbdf94afc06ffc20e98f6852643d654b6", "best_bid": "0.09", "best_ask": "0.11"}], "timestamp": "1769384181492", "event_type": "price_change"}}
{"_local_timestamp": "2026-01-25T23:36:39.489911+00:00", "data": {"market": "0x0465cd005a54781e052b679e2c42c7ae5b772490fdda54316f157bf537536456", "price_changes": [{"asset_id": "37755135088405799849800190027343457715121200916302661996402931566317384140291", "price": "0.71", "size": "70", "side": "BUY", "hash": "2ad1e66090ed4b015efa7b9967de4be2b340f8a9", "best_bid": "0.89", "best_ask": "0.91"}, {"asset_id": "109815773012907461372639157658293071578555374097742562684476865021743386609433", "price": "0.29", "size": "70", "side": "SELL", "hash": "940c8fa5ec6f0fa2e5a1800b46dc0a8a237c4414", "best_bid": "0.09", "best_ask": "0.11"}], "timestamp": "1769384199418", "event_type": "price_change"}}
{"_local_timestamp": "2026-01-25T23:36:39.490331+00:00", "data": {"market": "0x0465cd005a54781e052b679e2c42c7ae5b772490fdda54316f157bf537536456", "price_changes": [{"asset_id": "37755135088405799849800190027343457715121200916302661996402931566317384140291", "price": "0.72", "size": "100", "side": "BUY", "hash": "78bbadd871aefb61d2199f03a902a1207bbc46a8", "best_bid": "0.89", "best_ask": "0.91"}, {"asset_id": "109815773012907461372639157658293071578555374097742562684476865021743386609433", "price": "0.28", "size": "100", "side": "SELL", "hash": "3fef5d95f9121216119635edabb3d56384c4d7db", "best_bid": "0.09", "best_ask": "0.11"}], "timestamp": "1769384199419", "event_type": "price_change"}}
{"_local_timestamp": "2026-01-25T23:36:40.924842+00:00", "data": {"market": "0x0465cd005a54781e052b679e2c42c7ae5b772490fdda54316f157bf537536456", "price_changes": [{"asset_id": "37755135088405799849800190027343457715121200916302661996402931566317384140291", "price": "0.71", "size": "50", "side": "BUY", "hash": "353bb7068382aab8202501af6cdd71c9a1d5c8de", "best_bid": "0.89", "best_ask": "0.91"}, {"asset_id": "109815773012907461372639157658293071578555374097742562684476865021743386609433", "price": "0.29", "size": "50", "side": "SELL", "hash": "e770587a8940b75180dfe464eec2371bcef3bdee", "best_bid": "0.09", "best_ask": "0.11"}], "timestamp": "1769384200855", "event_type": "price_change"}}
{"_local_timestamp": "2026-01-25T23:36:40.949970+00:00", "data": {"market": "0x0465cd005a54781e052b679e2c42c7ae5b772490fdda54316f157bf537536456", "price_changes": [{"asset_id": "37755135088405799849800190027343457715121200916302661996402931566317384140291", "price": "0.73", "size": "20", "side": "BUY", "hash": "9392893b8699a7626ac89dfb3c72e98f7a377261", "best_bid": "0.89", "best_ask": "0.91"}, {"asset_id": "109815773012907461372639157658293071578555374097742562684476865021743386609433", "price": "0.27", "size": "20", "side": "SELL", "hash": "f7b8a852fbc102568036be6519e28592cf2a2bfc", "best_bid": "0.09", "best_ask": "0.11"}], "timestamp": "1769384200882", "event_type": "price_change"}}
{"_local_timestamp": "2026-01-25T23:37:12.192872+00:00", "data": {"market": "0x0465cd005a54781e052b679e2c42c7ae5b772490fdda54316f157bf537536456", "price_changes": [{"asset_id": "37755135088405799849800190027343457715121200916302661996402931566317384140291", "price": "0.72", "size": "0", "side": "BUY", "hash": "9d5af79557370cb2004c3b8d75f2f6ea20226d04", "best_bid": "0.89", "best_ask": "0.91"}, {"asset_id": "109815773012907461372639157658293071578555374097742562684476865021743386609433", "price": "0.28", "size": "0", "side": "SELL", "hash": "31220d7b8b25944f82d0100e82b5582f15b333a1", "best_bid": "0.09", "best_ask": "0.11"}], "timestamp": "1769384232122", "event_type": "price_change"}}
{"_local_timestamp": "2026-01-25T23:37:12.193358+00:00", "data": {"market": "0x0465cd005a54781e052b679e2c42c7ae5b772490fdda54316f157bf537536456", "price_changes": [{"asset_id": "37755135088405799849800190027343457715121200916302661996402931566317384140291", "price": "0.71", "size": "0", "side": "BUY", "hash": "9d5af79557370cb2004c3b8d75f2f6ea20226d04", "best_bid": "0.89", "best_ask": "0.91"}, {"asset_id": "109815773012907461372639157658293071578555374097742562684476865021743386609433", "price": "0.29", "size": "0", "side": "SELL", "hash": "31220d7b8b25944f82d0100e82b5582f15b333a1", "best_bid": "0.09", "best_ask": "0.11"}], "timestamp": "1769384232122", "event_type": "price_change"}}
{"_local_timestamp": "2026-01-25T23:37:13.313632+00:00", "data": {"market": "0x0465cd005a54781e052b679e2c42c7ae5b772490fdda54316f157bf537536456", "price_changes": [{"asset_id": "37755135088405799849800190027343457715121200916302661996402931566317384140291", "price": "0.73", "size": "0", "side": "BUY", "hash": "d76fe93155d0d7e418e929b8d862f05c03611f30", "best_bid": "0.89", "best_ask": "0.91"}, {"asset_id": "109815773012907461372639157658293071578555374097742562684476865021743386609433", "price": "0.27", "size": "0", "side": "SELL", "hash": "bb20e613ca22f574f1b4724f505e2fe102863090", "best_bid": "0.09", "best_ask": "0.11"}], "timestamp": "1769384233246", "event_type": "price_change"}}
{"_local_timestamp": "2026-01-25T23:37:13.337864+00:00", "data": {"market": "0x0465cd005a54781e052b679e2c42c7ae5b772490fdda54316f157bf537536456", "price_changes": [{"asset_id": "37755135088405799849800190027343457715121200916302661996402931566317384140291", "price": "0.71", "size": "20", "side": "BUY", "hash": "127876a1011c0b6764371dd0af7a1ad9359eb9f8", "best_bid": "0.89", "best_ask": "0.91"}, {"asset_id": "109815773012907461372639157658293071578555374097742562684476865021743386609433", "price": "0.29", "size": "20", "side": "SELL", "hash": "8813f90b4aff816128355e0742003773dd3e01fa", "best_bid": "0.09", "best_ask": "0.11"}], "timestamp": "1769384233270", "event_type": "price_change"}}
{"_local_timestamp": "2026-01-25T23:37:31.565709+00:00", "data": {"market": "0x0465cd005a54781e052b679e2c42c7ae5b772490fdda54316f157bf537536456", "price_changes": [{"asset_id": "37755135088405799849800190027343457715121200916302661996402931566317384140291", "price": "0.7", "size": "0", "side": "BUY", "hash": "3bc72a6c2f44fb6bc3ddff412ce76bfbd4755677", "best_bid": "0.89", "best_ask": "0.91"}, {"asset_id": "109815773012907461372639157658293071578555374097742562684476865021743386609433", "price": "0.3", "size": "0", "side": "SELL", "hash": "1ffbead6d22d3fdd25d32fc0987b80f67586a03d", "best_bid": "0.09", "best_ask": "0.11"}], "timestamp": "1769384251445", "event_type": "price_change"}}
{"_local_timestamp": "2026-01-25T23:37:31.606754+00:00", "data": {"market": "0x0465cd005a54781e052b679e2c42c7ae5b772490fdda54316f157bf537536456", "price_changes": [{"asset_id": "37755135088405799849800190027343457715121200916302661996402931566317384140291", "price": "0.72", "size": "10", "side": "BUY", "hash": "807a519a567d64ecfa4feef4c445746d01de97b0", "best_bid": "0.89", "best_ask": "0.91"}, {"asset_id": "109815773012907461372639157658293071578555374097742562684476865021743386609433", "price": "0.28", "size": "10", "side": "SELL", "hash": "7714ff80c2ddbf5c6c086ded44531f8784bedebe", "best_bid": "0.09", "best_ask": "0.11"}], "timestamp": "1769384251531", "event_type": "price_change"}}
{"_local_timestamp": "2026-01-25T23:37:31.961541+00:00", "data": {"market": "0x0465cd005a54781e052b679e2c42c7ae5b772490fdda54316f157bf537536456", "price_changes": [{"asset_id": "37755135088405799849800190027343457715121200916302661996402931566317384140291", "price": "0.71", "size": "0", "side": "BUY", "hash": "cee9bbeb1bb890a27eb607d23021b39fdf5ce94f", "best_bid": "0.89", "best_ask": "0.91"}, {"asset_id": "109815773012907461372639157658293071578555374097742562684476865021743386609433", "price": "0.29", "size": "0", "side": "SELL", "hash": "9a2ef7aff490e97f991c32e286006441f0e5a2b6", "best_bid": "0.09", "best_ask": "0.11"}], "timestamp": "1769384251837", "event_type": "price_change"}}
{"_local_timestamp": "2026-01-25T23:37:31.993342+00:00", "data": {"market": "0x0465cd005a54781e052b679e2c42c7ae5b772490fdda54316f157bf537536456", "price_changes": [{"asset_id": "37755135088405799849800190027343457715121200916302661996402931566317384140291", "price": "0.73", "size": "20", "side": "BUY", "hash": "44bd0534d9632268f3e1cb0a30e045cac32ffc44", "best_bid": "0.89", "best_ask": "0.91"}, {"asset_id": "109815773012907461372639157658293071578555374097742562684476865021743386609433", "price": "0.27", "size": "20", "side": "SELL", "hash": "e55a8706dcf5e55f4cc59cead4dfb9272a47f586", "best_bid": "0.09", "best_ask": "0.11"}], "timestamp": "1769384251868", "event_type": "price_change"}}
{"_local_timestamp": "2026-01-25T23:39:00.672584+00:00", "data": {"market": "0x0465cd005a54781e052b679e2c42c7ae5b772490fdda54316f157bf537536456", "price_changes": [{"asset_id": "37755135088405799849800190027343457715121200916302661996402931566317384140291", "price": "0.72", "size": "0", "side": "BUY", "hash": "849574c676e627bdf63d00a94ff2b4552ae6620f", "best_bid": "0.89", "best_ask": "0.91"}, {"asset_id": "109815773012907461372639157658293071578555374097742562684476865021743386609433", "price": "0.28", "size": "0", "side": "SELL", "hash": "09bd8b79bd75f2d6c319012ef7651d4f1838a2fe", "best_bid": "0.09", "best_ask": "0.11"}], "timestamp": "1769384340608", "event_type": "price_change"}}
{"_local_timestamp": "2026-01-25T23:39:00.880644+00:00", "data": {"market": "0x0465cd005a54781e052b679e2c42c7ae5b772490fdda54316f157bf537536456", "price_changes": [{"asset_id": "37755135088405799849800190027343457715121200916302661996402931566317384140291", "price": "0.74", "size": "10", "side": "BUY", "hash": "a51271e517e992986b335897d98c01e1922ef53f", "best_bid": "0.89", "best_ask": "0.91"}, {"asset_id": "109815773012907461372639157658293071578555374097742562684476865021743386609433", "price": "0.26", "size": "10", "side": "SELL", "hash": "243a37238872a0ee7861ff055067bd16e461509c", "best_bid": "0.09", "best_ask": "0.11"}], "timestamp": "1769384340815", "event_type": "price_change"}}
{"_local_timestamp": "2026-01-25T23:39:01.916571+00:00", "data": {"market": "0x0465cd005a54781e052b679e2c42c7ae5b772490fdda54316f157bf537536456", "price_changes": [{"asset_id": "37755135088405799849800190027343457715121200916302661996402931566317384140291", "price": "0.73", "size": "0", "side": "BUY", "hash": "a63fb94c3e3ca685bdf6370aaec794592b6b0ac9", "best_bid": "0.89", "best_ask": "0.91"}, {"asset_id": "109815773012907461372639157658293071578555374097742562684476865021743386609433", "price": "0.27", "size": "0", "side": "SELL", "hash": "5a17c3b8db9afab0de1ff6996712dfdd6990776a", "best_bid": "0.09", "best_ask": "0.11"}], "timestamp": "1769384341849", "event_type": "price_change"}}
{"_local_timestamp": "2026-01-25T23:39:01.936574+00:00", "data": {"market": "0x0465cd005a54781e052b679e2c42c7ae5b772490fdda54316f157bf537536456", "price_changes": [{"asset_id": "37755135088405799849800190027343457715121200916302661996402931566317384140291", "price": "0.75", "size": "20", "side": "BUY", "hash": "a6c8a96435e78fe9c35a0a7e59f4d41a894df3c3", "best_bid": "0.89", "best_ask": "0.91"}, {"asset_id": "109815773012907461372639157658293071578555374097742562684476865021743386609433", "price": "0.25", "size": "20", "side": "SELL", "hash": "77a330c0a88604963139420d7f36bebcc7767fbd", "best_bid": "0.09", "best_ask": "0.11"}], "timestamp": "1769384341872", "event_type": "price_change"}}
{"_local_timestamp": "2026-01-25T23:39:41.072868+00:00", "data": {"market": "0x0465cd005a54781e052b679e2c42c7ae5b772490fdda54316f157bf537536456", "price_changes": [{"asset_id": "109815773012907461372639157658293071578555374097742562684476865021743386609433", "price": "0.08", "size": "2941", "side": "BUY", "hash": "3c5afe1693607dc48f286e0cb2590a0b31176377", "best_bid": "0.09", "best_ask": "0.11"}, {"asset_id": "37755135088405799849800190027343457715121200916302661996402931566317384140291", "price": "0.92", "size": "2941", "side": "SELL", "hash": "b7523712747a976bb0b3733913bea8a2322eff51", "best_bid": "0.89", "best_ask": "0.91"}], "timestamp": "1769384381000", "event_type": "price_change"}}
{"_local_timestamp": "2026-01-25T23:39:54.054929+00:00", "data": {"market": "0x0465cd005a54781e052b679e2c42c7ae5b772490fdda54316f157bf537536456", "price_changes": [{"asset_id": "37755135088405799849800190027343457715121200916302661996402931566317384140291", "price": "0.74", "size": "0", "side": "BUY", "hash": "64e4523d0c8bb09311c102fe96a2d376c3fc3907", "best_bid": "0.89", "best_ask": "0.91"}, {"asset_id": "109815773012907461372639157658293071578555374097742562684476865021743386609433", "price": "0.26", "size": "0", "side": "SELL", "hash": "f10cb288789604dc96365bb02e8b6ff3433a92f3", "best_bid": "0.09", "best_ask": "0.11"}], "timestamp": "1769384393989", "event_type": "price_change"}}
{"_local_timestamp": "2026-01-25T23:39:54.188405+00:00", "data": {"market": "0x0465cd005a54781e052b679e2c42c7ae5b772490fdda54316f157bf537536456", "price_changes": [{"asset_id": "37755135088405799849800190027343457715121200916302661996402931566317384140291", "price": "0.76", "size": "10", "side": "BUY", "hash": "5add93add66baf14956f3222ff632cef5f43b523", "best_bid": "0.89", "best_ask": "0.91"}, {"asset_id": "109815773012907461372639157658293071578555374097742562684476865021743386609433", "price": "0.24", "size": "10", "side": "SELL", "hash": "f4b2537a813679a4aff516e357a218aa02bdacbd", "best_bid": "0.09", "best_ask": "0.11"}], "timestamp": "1769384394078", "event_type": "price_change"}}
{"_local_timestamp": "2026-01-25T23:39:55.710656+00:00", "data": {"market": "0x0465cd005a54781e052b679e2c42c7ae5b772490fdda54316f157bf537536456", "price_changes": [{"asset_id": "37755135088405799849800190027343457715121200916302661996402931566317384140291", "price": "0.75", "size": "0", "side": "BUY", "hash": "859b6aa674740afa9933fb3a6746ee5cb8a9592e", "best_bid": "0.89", "best_ask": "0.91"}, {"asset_id": "109815773012907461372639157658293071578555374097742562684476865021743386609433", "price": "0.25", "size": "0", "side": "SELL", "hash": "26c9fb0c4ac272a14025289c9c44c06e35796d93", "best_bid": "0.09", "best_ask": "0.11"}], "timestamp": "1769384395633", "event_type": "price_change"}}
{"_local_timestamp": "2026-01-25T23:39:55.745589+00:00", "data": {"market": "0x0465cd005a54781e052b679e2c42c7ae5b772490fdda54316f157bf537536456", "price_changes": [{"asset_id": "37755135088405799849800190027343457715121200916302661996402931566317384140291", "price": "0.77", "size": "20", "side": "BUY", "hash": "342fab817c204e2f16252708c793429aa29f7667", "best_bid": "0.89", "best_ask": "0.91"}, {"asset_id": "109815773012907461372639157658293071578555374097742562684476865021743386609433", "price": "0.23", "size": "20", "side": "SELL", "hash": "29a04c2d7f9e4367f2902f7c4bebdadd702d961f", "best_bid": "0.09", "best_ask": "0.11"}], "timestamp": "1769384395657", "event_type": "price_change"}}
{"_local_timestamp": "2026-01-25T23:40:08.212181+00:00", "data": {"market": "0x0465cd005a54781e052b679e2c42c7ae5b772490fdda54316f157bf537536456", "price_changes": [{"asset_id": "37755135088405799849800190027343457715121200916302661996402931566317384140291", "price": "0.88", "size": "381", "side": "BUY", "hash": "c6402d28e18ae2f595ca8cbca2b333fa4ed9d3b1", "best_bid": "0.89", "best_ask": "0.91"}, {"asset_id": "109815773012907461372639157658293071578555374097742562684476865021743386609433", "price": "0.12", "size": "381", "side": "SELL", "hash": "9b6ce85d49d667b2c5e4c2ea7dc334f68d6c3791", "best_bid": "0.09", "best_ask": "0.11"}], "timestamp": "1769384408134", "event_type": "price_change"}}
