{"_local_timestamp": "2026-01-25T23:41:19.412650+00:00", "data": [{"market": "0x3f912d2e5965430f00f074e9b8fd9cdc7fb5948074c19b271720c8e620f2cb11", "asset_id": "90179144936207028478465214931375521788167296412041627475537095855791073500041", "timestamp": "1769384371639", "hash": "efb155ed99598d2147d39b55b201e5e5b2b9ab26", "bids": [{"price": "0.01", "size": "3937.45"}, {"price": "0.02", "size": "507.73"}, {"price": "0.03", "size": "300"}, {"price": "0.04", "size": "207.12"}, {"price": "0.05", "size": "100"}, {"price": "0.06", "size": "33"}, {"price": "0.08", "size": "205.36"}, {"price": "0.09", "size": "22"}, {"price": "0.11", "size": "50"}, {"price": "0.15", "size": "7.04"}, {"price": "0.22", "size": "110"}, {"price": "0.23", "size": "20"}, {"price": "0.4", "size": "10"}], "asks": [{"price": "0.99", "size": "94.67"}, {"price": "0.98", "size": "12.99"}, {"price": "0.95", "size": "67.33"}, {"price": "0.94", "size": "200"}, {"price": "0.93", "size": "100"}, {"price": "0.92", "size": "69.83"}], "event_type": "book", "last_trade_price": "0.500"}, {"market": "0x7b9405ac2a18f553738708544a8bf8e56a2ce444f0cdced388a82219413f1e8b", "asset_id": "4705265403362581120736820785718797352184109151637378631828322862746823225674", "timestamp": "1769384461793", "hash": "e81fcf640a105597191e37d071c8989bd529a477", "bids": [{"price": "0.01", "size": "101.69"}, {"price": "0.02", "size": "60"}, {"price": "0.03", "size": "57.33"}, {"price": "0.06", "size": "71.63"}], "asks": [{"price": "0.99", "size": "5042.89"}, {"price": "0.98", "size": "2100"}, {"price": "0.97", "size": "11.55"}, {"price": "0.95", "size": "400"}, {"price": "0.94", "size": "33"}, {"price": "0.93", "size": "30"}, {"price": "0.92", "size": "19.05"}, {"price": "0.67", "size": "100"}, {"price": "0.65", "size": "5"}, {"price": "0.64", "size": "10"}, {"price": "0.63", "size": "20"}, {"price": "0.6", "size": "5"}, {"price": "0.36", "size": "15"}], "event_type": "book", "last_trade_price": ""}, {"market": "0x9b9e5813bc0b5e21a177de5cb65121297730cdcef86d32aa8b20933067546427", "asset_id": "103745946677791198802043400205446626644210595777261132684909081924706209420680", "timestamp": "1769383278644", "hash": "be23ed5167d1c36b50b687e77d2662d3239aa34b", "bids": [{"price": "0.01", "size": "6008.73"}, {"price": "0.02", "size": "2500"}, {"price": "0.03", "size": "7.41"}, {"price": "0.05", "size": "400"}, {"price": "0.06", "size": "33"}, {"price": "0.07", "size": "7.12"}, {"price": "0.09", "size": "1000"}, {"price": "0.13", "size": "586.53"}, {"price": "0.17", "size": "438.23"}, {"price": "0.18", "size": "6.43"}, {"price": "0.21", "size": "333.33"}, {"price": "0.26", "size": "100"}, {"price": "0.27", "size": "50"}, {"price": "0.3", "size": "80"}, {"price": "0.31", "size": "40"}, {"price": "0.34", "size": "58.82"}, {"price": "0.4", "size": "196.66"}, {"price": "0.41", "size": "20"}, {"price": "0.42", "size": "5"}, {"price": "0.45", "size": "10"}, {"price": "0.79", "size": "100"}, {"price": "0.8", "size": "71.66"}], "asks": [{"price": "0.99", "size": "70.36"}, {"price": "0.98", "size": "66"}, {"price": "0.97", "size": "20.18"}], "event_type": "book", "last_trade_price": ""}, {"market": "0x5f9ba531b74dd3d7be29f64741e5cad867f797da9aa73c348fd24f510ed2dfed", "asset_id": "29998772574245347891697050250557764189917474641475239534746438855989311925662", "timestamp": "1769384414360", "hash": "0c618e496041698bdd9cc15450e6ef7bd2da24ea", "bids": [{"price": "0.01", "size": "120.66"}, {"price": "0.02", "size": "73"}, {"price": "0.03", "size": "57.33"}, {"price": "0.05", "size": "65.92"}], "asks": [{"price": "0.99", "size": "6009.28"}, {"price": "0.98", "size": "2500"}, {"price": "0.97", "size": "1007.75"}, {"price": "0.95", "size": "400"}, {"price": "0.94", "size": "33"}, {"price": "0.93", "size": "7.45"}, {"price": "0.92", "size": "2600"}, {"price": "0.85", "size": "325"}, {"price": "0.84", "size": "2874"}, {"price": "0.83", "size": "951"}, {"price": "0.82", "size": "6.22"}, {"price": "0.78", "size": "200"}, {"price": "0.66", "size": "66.66"}, {"price": "0.65", "size": "20"}, {"price": "0.6", "size": "4"}, {"price": "0.49", "size": "1010"}, {"price": "0.33", "size": "10"}, {"price": "0.32", "size": "71.66"}], "event_type": "book", "last_trade_price": ""}, {"market": "0x9b9e5813bc0b5e21a177de5cb65121297730cdcef86d32aa8b20933067546427", "asset_id": "15609421898876500890369688401103884738388846122594423961190213078422097015933", "timestamp": "1769383278644", "hash": "60093edb637432cef23029560556a031d28a4239", "bids": [{"price": "0.01", "size": "70.36"}, {"price": "0.02", "size": "66"}, {"price": "0.03", "size": "20.18"}], "asks": [{"price": "0.99", "size": "6008.73"}, {"price": "0.98", "size": "2500"}, {"price": "0.97", "size": "7.41"}, {"price": "0.95", "size": "400"}, {"price": "0.94", "size": "33"}, {"price": "0.93", "size": "7.12"}, {"price": "0.91", "size": "1000"}, {"price": "0.87", "size": "586.53"}, {"price": "0.83", "size": "438.23"}, {"price": "0.82", "size": "6.43"}, {"price": "0.79", "size": "333.33"}, {"price": "0.74", "size": "100"}, {"price": "0.73", "size": "50"}, {"price": "0.7", "size": "80"}, {"price": "0.69", "size": "40"}, {"price": "0.66", "size": "58.82"}, {"price": "0.6", "size": "196.66"}, {"price": "0.59", "size": "20"}, {"price": "0.58", "size": "5"}, {"price": "0.55", "size": "10"}, {"price": "0.21", "size": "100"}, {"price": "0.2", "size": "71.66"}], "event_type": "book", "last_trade_price": ""}, {"market": "0x6d16cc6bfc59787a24d6ea41cc49ad03f3a3a44e97aad02d7300cf906c812e53", "asset_id": "21134177830802910367859690071335268803233593888575931822119572207559990909766", "timestamp": "1769384039540", "hash": "5c1e2cb115c96b40d48616fb57e2e301d137e9ff", "bids": [{"price": "0.01", "size": "3937.82"}, {"price": "0.02", "size": "507.73"}, {"price": "0.03", "size": "200"}, {"price": "0.04", "size": "305.41"}, {"price": "0.05", "size": "100"}, {"price": "0.06", "size": "433"}, {"price": "0.07", "size": "5.46"}, {"price": "0.11", "size": "50"}, {"price": "0.12", "size": "16"}, {"price": "0.13", "size": "8.98"}, {"price": "0.22", "size": "100"}, {"price": "0.28", "size": "30"}, {"price": "0.29", "size": "39"}, {"price": "0.4", "size": "5"}], "asks": [{"price": "0.99", "size": "1039.65"}, {"price": "0.98", "size": "300"}, {"price": "0.97", "size": "200"}, {"price": "0.96", "size": "60.6"}, {"price": "0.95", "size": "110"}, {"price": "0.91", "size": "200"}, {"price": "0.9", "size": "168.66"}, {"price": "0.85", "size": "20"}, {"price": "0.84", "size": "55.66"}], "event_type": "book", "last_trade_price": "0.280"}, {"market": "0x8fd23f0e974fc09874b21e86d16808f5c1da870813f580bc0bf73399fea51ca2", "asset_id": "85172525867787641402328444576848541622260332991892947577648996734803038861895", "timestamp": "1769384278911", "hash": "46ae13d1ac3d0fa94dc5f14d096f14de689510f1", "bids": [{"price": "0.01", "size": "5942.07"}, {"price": "0.02", "size": "2500"}, {"price": "0.03", "size": "7.41"}, {"price": "0.05", "size": "400"}, {"price": "0.06", "size": "33"}, {"price": "0.07", "size": "7.12"}, {"price": "0.08", "size": "1050"}, {"price": "0.13", "size": "586.53"}, {"price": "0.17", "size": "438.23"}, {"price": "0.18", "size": "6.43"}, {"price": "0.21", "size": "183.33"}, {"price": "0.23", "size": "8.5"}, {"price": "0.26", "size": "100"}, {"price": "0.3", "size": "230"}, {"price": "0.31", "size": "20"}, {"price": "0.34", "size": "58.82"}, {"price": "0.35", "size": "247.66"}, {"price": "0.36", "size": "169"}, {"price": "0.38", "size": "5"}, {"price": "0.4", "size": "6"}, {"price": "0.41", "size": "17.68"}, {"price": "0.46", "size": "6"}, {"price": "0.56", "size": "66.66"}, {"price": "0.65", "size": "6"}, {"price": "0.79", "size": "200"}, {"price": "0.81", "size": "76.66"}], "asks": [{"price": "0.99", "size": "988.84"}, {"price": "0.98", "size": "250"}, {"price": "0.97", "size": "17.11"}, {"price": "0.95", "size": "27"}, {"price": "0.93", "size": "15"}, {"price": "0.92", "size": "29.84"}, {"price": "0.88", "size": "16"}, {"price": "0.85", "size": "1.82"}], "event_type": "book", "last_trade_price": "0.150"}, {"market": "0x3f912d2e5965430f00f074e9b8fd9cdc7fb5948074c19b271720c8e620f2cb11", "asset_id": "58342639934160101133354411315222065187144122136965451700208165731325515097740", "timestamp": "1769384371639", "hash": "39417389bf4885602a94da6ffd3a489c08cd9e4e", "bids": [{"price": "0.01", "size": "94.67"}, {"price": "0.02", "size": "12.99"}, {"price": "0.05", "size": "67.33"}, {"price": "0.06", "size": "200"}, {"price": "0.07", "size": "100"}, {"price": "0.08", "size": "69.83"}], "asks": [{"price": "0.99", "size": "3937.45"}, {"price": "0.98", "size": "507.73"}, {"price": "0.97", "size": "300"}, {"price": "0.96", "size": "207.12"}, {"price": "0.95", "size": "100"}, {"price": "0.94", "size": "33"}, {"price": "0.92", "size": "205.36"}, {"price": "0.91", "size": "22"}, {"price": "0.89", "size": "50"}, {"price": "0.85", "size": "7.04"}, {"price": "0.78", "size": "110"}, {"price": "0.77", "size": "20"}, {"price": "0.6", "size": "10"}], "event_type": "book", "last_trade_price": "0.500"}, {"market": "0x5f9ba531b74dd3d7be29f64741e5cad867f797da9aa73c348fd24f510ed2dfed", "asset_id": "81414822130427608080886293296378652266575755903486095487302983244496524955033", "timestamp": "1769384414360", "hash": "34ceabad707ab5ad89b07a0281a441e01ed6625b", "bids": [{"price": "0.01", "size": "6009.28"}, {"price": "0.02", "size": "2500"}, {"price": "0.03", "size": "1007.75"}, {"price": "0.05", "size": "400"}, {"price": "0.06", "size": "33"}, {"price": "0.07", "size": "7.45"}, {"price": "0.08", "size": "2600"}, {"price": "0.15", "size": "325"}, {"price": "0.16", "size": "2874"}, {"price": "0.17", "size": "951"}, {"price": "0.18", "size": "6.22"}, {"price": "0.22", "size": "200"}, {"price": "0.34", "size": "66.66"}, {"price": "0.35", "size": "20"}, {"price": "0.4", "size": "4"}, {"price": "0.51", "size": "1010"}, {"price": "0.67", "size": "10"}, {"price": "0.68", "size": "71.66"}], "asks": [{"price": "0.99", "size": "120.66"}, {"price": "0.98", "size": "73"}, {"price": "0.97", "size": "57.33"}, {"price": "0.95", "size": "65.92"}], "event_type": "book", "last_trade_price": ""}, {"market": "0x7b9405ac2a18f553738708544a8bf8e56a2ce444f0cdced388a82219413f1e8b", "asset_id": "108462258986864408381729131013925572621223086163135850415272164030051791225397", "timestamp": "1769384461793", "hash": "52b4a74bcc905cc9d18c9dbc95347c1c2dd1445b", "bids": [{"price": "0.01", "size": "5042.89"}, {"price": "0.02", "size": "2100"}, {"price": "0.03", "size": "11.55"}, {"price": "0.05", "size": "400"}, {"price": "0.06", "size": "33"}, {"price": "0.07", "size": "30"}, {"price": "0.08", "size": "19.05"}, {"price": "0.33", "size": "100"}, {"price": "0.35", "size": "5"}, {"price": "0.36", "size": "10"}, {"price": "0.37", "size": "20"}, {"price": "0.4", "size": "5"}, {"price": "0.64", "size": "15"}], "asks": [{"price": "0.99", "size": "101.69"}, {"price": "0.98", "size": "60"}, {"price": "0.97", "size": "57.33"}, {"price": "0.94", "size": "71.63"}], "event_type": "book", "last_trade_price": ""}, {"market": "0x8fd23f0e974fc09874b21e86d16808f5c1da870813f580bc0bf73399fea51ca2", "asset_id": "56438265434513376454964845898456576437217725564238261372991430944084310725149", "timestamp": "1769384278911", "hash": "9b8ad560ab43cb8ba1574382d0f8b2d7a592dec2", "bids": [{"price": "0.01", "size": "988.84"}, {"price": "0.02", "size": "250"}, {"price": "0.03", "size": "17.11"}, {"price": "0.05", "size": "27"}, {"price": "0.07", "size": "15"}, {"price": "0.08", "size": "29.84"}, {"price": "0.12", "size": "16"}, {"price": "0.15", "size": "1.82"}], "asks": [{"price": "0.99", "size": "5942.07"}, {"price": "0.98", "size": "2500"}, {"price": "0.97", "size": "7.41"}, {"price": "0.95", "size": "400"}, {"price": "0.94", "size": "33"}, {"price": "0.93", "size": "7.12"}, {"price": "0.92", "size": "1050"}, {"price": "0.87", "size": "586.53"}, {"price": "0.83", "size": "438.23"}, {"price": "0.82", "size": "6.43"}, {"price": "0.79", "size": "183.33"}, {"price": "0.77", "size": "8.5"}, {"price": "0.74", "size": "100"}, {"price": "0.7", "size": "230"}, {"price": "0.69", "size": "20"}, {"price": "0.66", "size": "58.82"}, {"price": "0.65", "size": "247.66"}, {"price": "0.64", "size": "169"}, {"price": "0.62", "size": "5"}, {"price": "0.6", "size": "6"}, {"price": "0.59", "size": "17.68"}, {"price": "0.54", "size": "6"}, {"price": "0.44", "size": "66.66"}, {"price": "0.35", "size": "6"}, {"price": "0.21", "size": "200"}, {"price": "0.19", "size": "76.66"}], "event_type": "book", "last_trade_price": "0.150"}, {"market": "0x6d16cc6bfc59787a24d6ea41cc49ad03f3a3a44e97aad02d7300cf906c812e53", "asset_id": "60253373069171098683378509644885376353498749849701407276928730338318645499936", "timestamp": "1769384039540", "hash": "b1f1b42330b52133d021161c11c81eeaa2b27bb8", "bids": [{"price": "0.01", "size": "1039.65"}, {"price": "0.02", "size": "300"}, {"price": "0.03", "size": "200"}, {"price": "0.04", "size": "60.6"}, {"price": "0.05", "size": "110"}, {"price": "0.09", "size": "200"}, {"price": "0.1", "size": "168.66"}, {"price": "0.15", "size": "20"}, {"price": "0.16", "size": "55.66"}], "asks": [{"price": "0.99", "size": "3937.82"}, {"price": "0.98", "size": "507.73"}, {"price": "0.97", "size": "200"}, {"price": "0.96", "size": "305.41"}, {"price": "0.95", "size": "100"}, {"price": "0.94", "size": "433"}, {"price": "0.93", "size": "5.46"}, {"price": "0.89", "size": "50"}, {"price": "0.88", "size": "16"}, {"price": "0.87", "size": "8.98"}, {"price": "0.78", "size": "100"}, {"price": "0.72", "size": "30"}, {"price": "0.71", "size": "39"}, {"price": "0.6", "size": "5"}], "event_type": "book", "last_trade_price": "0.280"}]}
{"_local_timestamp": "2026-01-25T23:41:50.827794+00:00", "data": {"market": "0x8fd23f0e974fc09874b21e86d16808f5c1da870813f580bc0bf73399fea51ca2", "price_changes": [{"asset_id": "85172525867787641402328444576848541622260332991892947577648996734803038861895", "price": "0.35", "size": "172.66", "side": "BUY", "hash": "a79aebafdeb1156e205d2132c3e8a4c26997d5a8", "best_bid": "0.81", "best_ask": "0.85"}, {"asset_id": "56438265434513376454964845898456576437217725564238261372991430944084310725149", "price": "0.65", "size": "172.66", "side": "SELL", "hash": "af6714ead497488e92b73b4ffeb2e525bf10e317", "best_bid": "0.15", "best_ask": "0.19"}], "timestamp": "1769384510730", "event_type": "price_change"}}
{"_local_timestamp": "2026-01-25T23:41:50.988289+00:00", "data": {"market": "0x7b9405ac2a18f553738708544a8bf8e56a2ce444f0cdced388a82219413f1e8b", "price_changes": [{"asset_id": "108462258986864408381729131013925572621223086163135850415272164030051791225397", "price": "0.36", "size": "0", "side": "BUY", "hash": "ff55ec3a78fd478a5f4b318b1ae3173a6a7dba3b", "best_bid": "0.64", "best_ask": "0.94"}, {"asset_id": "4705265403362581120736820785718797352184109151637378631828322862746823225674", "price": "0.64", "size": "0", "side": "SELL", "hash": "5a3a2af8f817756ab0764cccfe7b4c8b0378d27b", "best_bid": "0.06", "best_ask": "0.36"}], "timestamp": "1769384510827", "event_type": "price_change"}}
{"_local_timestamp": "2026-01-25T23:41:51.011310+00:00", "data": {"market": "0x7b9405ac2a18f553738708544a8bf8e56a2ce444f0cdced388a82219413f1e8b", "price_changes": [{"asset_id": "108462258986864408381729131013925572621223086163135850415272164030051791225397", "price": "0.38", "size": "10", "side": "BUY", "hash": "988706c7ddaa48e02207a9aef848e06a62d41c7b", "best_bid": "0.64", "best_ask": "0.94"}, {"asset_id": "4705265403362581120736820785718797352184109151637378631828322862746823225674", "price": "0.62", "size": "10", "side": "SELL", "hash": "9f56a422e1d3668ad7406c6005a77b10245d4496", "best_bid": "0.06", "best_ask": "0.36"}], "timestamp": "1769384510918", "event_type": "price_change"}}
{"_local_timestamp": "2026-01-25T23:41:52.023236+00:00", "data": {"market": "0x8fd23f0e974fc09874b21e86d16808f5c1da870813f580bc0bf73399fea51ca2", "price_changes": [{"asset_id": "85172525867787641402328444576848541622260332991892947577648996734803038861895", "price": "0.36", "size": "244", "side": "BUY", "hash": "87cd2a12f988abcb55604656346d5f07d1827146", "best_bid": "0.81", "best_ask": "0.85"}, {"asset_id": "56438265434513376454964845898456576437217725564238261372991430944084310725149", "price": "0.64", "size": "244", "side": "SELL", "hash": "32d17318d49f68ada9c315273289b6b00348e2bd", "best_bid": "0.15", "best_ask": "0.19"}], "timestamp": "1769384511698", "event_type": "price_change"}}
{"_local_timestamp": "2026-01-25T23:41:55.888924+00:00", "data": {"market": "0x7b9405ac2a18f553738708544a8bf8e56a2ce444f0cdced388a82219413f1e8b", "price_changes": [{"asset_id": "108462258986864408381729131013925572621223086163135850415272164030051791225397", "price": "0.37", "size": "0", "side": "BUY", "hash": "7423101aec03cba2fa10eda7ca3e01262d5ce6f4", "best_bid": "0.64", "best_ask": "0.94"}, {"asset_id": "4705265403362581120736820785718797352184109151637378631828322862746823225674", "price": "0.63", "size": "0", "side": "SELL", "hash": "64ee9304759c8493d2e8a733e1d42a7aa408fb55", "best_bid": "0.06", "best_ask": "0.36"}], "timestamp": "1769384515817", "event_type": "price_change"}}
{"_local_timestamp": "2026-01-25T23:41:55.913923+00:00", "data": {"market": "0x7b9405ac2a18f553738708544a8bf8e56a2ce444f0cdced388a82219413f1e8b", "price_changes": [{"asset_id": "108462258986864408381729131013925572621223086163135850415272164030051791225397", "price": "0.38", "size": "30", "side": "BUY", "hash": "9d08839c593955711eefc210fc3551ee61fbfa01", "best_bid": "0.64", "best_ask": "0.94"}, {"asset_id": "4705265403362581120736820785718797352184109151637378631828322862746823225674", "price": "0.62", "size": "30", "side": "SELL", "hash": "a56c8dc49d36884d9d32ad0d59568771a68c99d7", "best_bid": "0.06", "best_ask": "0.36"}], "timestamp": "1769384515843", "event_type": "price_change"}}
{"_local_timestamp": "2026-01-25T23:42:49.647385+00:00", "data": {"market": "0x7b9405ac2a18f553738708544a8bf8e56a2ce444f0cdced388a82219413f1e8b", "price_changes": [{"asset_id": "108462258986864408381729131013925572621223086163135850415272164030051791225397", "price": "0.38", "size": "20", "side": "BUY", "hash": "231ed5e4c55f43e0179beb3a1856b2814d325e09", "best_bid": "0.64", "best_ask": "0.94"}, {"asset_id": "4705265403362581120736820785718797352184109151637378631828322862746823225674", "price": "0.62", "size": "20", "side": "SELL", "hash": "35e203e6804b64b8879cc1fd5d1ee36acd0ce965", "best_bid": "0.06", "best_ask": "0.36"}], "timestamp": "1769384569453", "event_type": "price_change"}}
{"_local_timestamp": "2026-01-25T23:42:49.739488+00:00", "data": {"market": "0x7b9405ac2a18f553738708544a8bf8e56a2ce444f0cdced388a82219413f1e8b", "price_changes": [{"asset_id": "108462258986864408381729131013925572621223086163135850415272164030051791225397", "price": "0.39", "size": "10", "side": "BUY", "hash": "00f7eb0dd39b29d9c8589cfc3982fe4a86246380", "best_bid": "0.64", "best_ask": "0.94"}, {"asset_id": "4705265403362581120736820785718797352184109151637378631828322862746823225674", "price": "0.61", "size": "10", "side": "SELL", "hash": "bb8ec29ba1dd13a17e0fd58b23a9fbf0ec16e6ab", "best_bid": "0.06", "best_ask": "0.36"}], "timestamp": "1769384569547", "event_type": "price_change"}}
{"_local_timestamp": "2026-01-25T23:42:52.306499+00:00", "data": {"market": "0x7b9405ac2a18f553738708544a8bf8e56a2ce444f0cdced388a82219413f1e8b", "price_changes": [{"asset_id": "108462258986864408381729131013925572621223086163135850415272164030051791225397", "price": "0.38", "size": "0", "side": "BUY", "hash": "8ae7281ae5e6c592c6d4a41c2eb70ba798ee8718", "best_bid": "0.64", "best_ask": "0.94"}, {"asset_id": "4705265403362581120736820785718797352184109151637378631828322862746823225674", "price": "0.62", "size": "0", "side": "SELL", "hash": "8542793372bc737055c10d5d05aca53c8d2a3c01", "best_bid": "0.06", "best_ask": "0.36"}], "timestamp": "1769384572112", "event_type": "price_change"}}
{"_local_timestamp": "2026-01-25T23:42:52.333784+00:00", "data": {"market": "0x7b9405ac2a18f553738708544a8bf8e56a2ce444f0cdced388a82219413f1e8b", "price_changes": [{"asset_id": "108462258986864408381729131013925572621223086163135850415272164030051791225397", "price": "0.34", "size": "20", "side": "BUY", "hash": "7192021f4820dc58d7cfb51b770d3c9e29f61b5a", "best_bid": "0.64", "best_ask": "0.94"}, {"asset_id": "4705265403362581120736820785718797352184109151637378631828322862746823225674", "price": "0.66", "size": "20", "side": "SELL", "hash": "2db54ae1d5b42b3428a99c0cf7a3cc009bc86479", "best_bid": "0.06", "best_ask": "0.36"}], "timestamp": "1769384572140", "event_type": "price_change"}}
{"_local_timestamp": "2026-01-25T23:43:05.080762+00:00", "data": {"market": "0x3f912d2e5965430f00f074e9b8fd9cdc7fb5948074c19b271720c8e620f2cb11", "price_changes": [{"asset_id": "90179144936207028478465214931375521788167296412041627475537095855791073500041", "price": "0.02", "size": "500", "side": "BUY", "hash": "cbaaf88165c979ffe496df5370a383d459973aa2", "best_bid": "0.4", "best_ask": "0.92"}, {"asset_id": "58342639934160101133354411315222065187144122136965451700208165731325515097740", "price": "0.98", "size": "500", "side": "SELL", "hash": "ca0da1aa25539fbb133d535d782bd4c59ae31d18", "best_bid": "0.08", "best_ask": "0.6"}], "timestamp": "1769384584864", "event_type": "price_change"}}
{"_local_timestamp": "2026-01-25T23:43:05.081343+00:00", "data": {"market": "0x3f912d2e5965430f00f074e9b8fd9cdc7fb5948074c19b271720c8e620f2cb11", "price_changes": [{"asset_id": "90179144936207028478465214931375521788167296412041627475537095855791073500041", "price": "0.04", "size": "200", "side": "BUY", "hash": "cbaaf88165c979ffe496df5370a383d459973aa2", "best_bid": "0.4", "best_ask": "0.92"}, {"asset_id": "58342639934160101133354411315222065187144122136965451700208165731325515097740", "price": "0.96", "size": "200", "side": "SELL", "hash": "ca0da1aa25539fbb133d535d782bd4c59ae31d18", "best_bid": "0.08", "best_ask": "0.6"}], "timestamp": "1769384584864", "event_type": "price_change"}}
{"_local_timestamp": "2026-01-25T23:43:05.081775+00:00", "data": {"market": "0x3f912d2e5965430f00f074e9b8fd9cdc7fb5948074c19b271720c8e620f2cb11", "price_changes": [{"asset_id": "90179144936207028478465214931375521788167296412041627475537095855791073500041", "price": "0.08", "size": "200", "side": "BUY", "hash": "cbaaf88165c979ffe496df5370a383d459973aa2", "best_bid": "0.4", "best_ask": "0.92"}, {"asset_id": "58342639934160101133354411315222065187144122136965451700208165731325515097740", "price": "0.92", "size": "200", "side": "SELL", "hash": "ca0da1aa25539fbb133d535d782bd4c59ae31d18", "best_bid": "0.08", "best_ask": "0.6"}], "timestamp": "1769384584864", "event_type": "price_change"}}
{"_local_timestamp": "2026-01-25T23:43:05.082163+00:00", "data": {"market": "0x3f912d2e5965430f00f074e9b8fd9cdc7fb5948074c19b271720c8e620f2cb11", "price_changes": [{"asset_id": "90179144936207028478465214931375521788167296412041627475537095855791073500041", "price": "0.15", "size": "0", "side": "BUY", "hash": "cbaaf88165c979ffe496df5370a383d459973aa2", "best_bid": "0.4", "best_ask": "0.92"}, {"asset_id": "58342639934160101133354411315222065187144122136965451700208165731325515097740", "price": "0.85", "size": "0", "side": "SELL", "hash": "ca0da1aa25539fbb133d535d782bd4c59ae31d18", "best_bid": "0.08", "best_ask": "0.6"}], "timestamp": "1769384584864", "event_type": "price_change"}}
{"_local_timestamp": "2026-01-25T23:43:05.412581+00:00", "data": {"market": "0x3f912d2e5965430f00f074e9b8fd9cdc7fb5948074c19b271720c8e620f2cb11", "price_changes": [{"asset_id": "90179144936207028478465214931375521788167296412041627475537095855791073500041", "price": "0.07", "size": "7.88", "side": "BUY", "hash": "c3136a442c4621808cba9d619aab50ecd39fc402", "best_bid": "0.4", "best_ask": "0.92"}, {"asset_id": "58342639934160101133354411315222065187144122136965451700208165731325515097740", "price": "0.93", "size": "7.88", "side": "SELL", "hash": "1f24f50cec9cb188e374fd9cd6553236785a97c2", "best_bid": "0.08", "best_ask": "0.6"}], "timestamp": "1769384585207", "event_type": "price_change"}}
{"_local_timestamp": "2026-01-25T23:43:05.421754+00:00", "data": {"market": "0x3f912d2e5965430f00f074e9b8fd9cdc7fb5948074c19b271720c8e620f2cb11", "price_changes": [{"asset_id": "90179144936207028478465214931375521788167296412041627475537095855791073500041", "price": "0.16", "size": "6.26", "side": "BUY", "hash": "20ff142e118887f540c3a14906a58e9655815114", "best_bid": "0.4", "best_ask": "0.92"}, {"asset_id": "58342639934160101133354411315222065187144122136965451700208165731325515097740", "price": "0.84", "size": "6.26", "side": "SELL", "hash": "ac94dc74fda752b4420e2778b852620572ad5d55", "best_bid": "0.08", "best_ask": "0.6"}], "timestamp": "1769384585208", "event_type": "price_change"}}
{"_local_timestamp": "2026-01-25T23:43:05.422268+00:00", "data": {"market": "0x3f912d2e5965430f00f074e9b8fd9cdc7fb5948074c19b271720c8e620f2cb11", "price_changes": [{"asset_id": "90179144936207028478465214931375521788167296412041627475537095855791073500041", "price": "0.02", "size": "507.73", "side": "BUY", "hash": "ff31e7119235d3016ed919aa37024c814bd20912", "best_bid": "0.4", "best_ask": "0.92"}, {"asset_id": "58342639934160101133354411315222065187144122136965451700208165731325515097740", "price": "0.98", "size": "507.73", "side": "SELL", "hash": "91725d870b9c7a1fe79628c2477d515d556694c2", "best_bid": "0.08", "best_ask": "0.6"}], "timestamp": "1769384585209", "event_type": "price_change"}}
{"_local_timestamp": "2026-01-25T23:43:05.422652+00:00", "data": {"market": "0x3f912d2e5965430f00f074e9b8fd9cdc7fb5948074c19b271720c8e620f2cb11", "price_changes": [{"asset_id": "90179144936207028478465214931375521788167296412041627475537095855791073500041", "price": "0.04", "size": "205.41", "side": "BUY", "hash": "3e409cc9acbf20c10f153e33578889174d9dd87b", "best_bid": "0.4", "best_ask": "0.92"}, {"asset_id": "58342639934160101133354411315222065187144122136965451700208165731325515097740", "price": "0.96", "size": "205.41", "side": "SELL", "hash": "bd45c55ec2bef824cfb9c7afa94417b2d952ced1", "best_bid": "0.08", "best_ask": "0.6"}], "timestamp": "1769384585209", "event_type": "price_change"}}
{"_local_timestamp": "2026-01-25T23:43:42.765681+00:00", "data": {"market": "0x7b9405ac2a18f553738708544a8bf8e56a2ce444f0cdced388a82219413f1e8b", "price_changes": [{"asset_id": "4705265403362581120736820785718797352184109151637378631828322862746823225674", "price": "0.02", "size": "69.48", "side": "BUY", "hash": "b6f2e5b3cac77fcb77bcd6e489d84f5f3a16223c", "best_bid": "0.06", "best_ask": "0.36"}, {"asset_id": "108462258986864408381729131013925572621223086163135850415272164030051791225397", "price": "0.98", "size": "69.48", "side": "SELL", "hash": "17d80abec94319e0a6050546c02aea04a88cabf3", "best_bid": "0.64", "best_ask": "0.94"}], "timestamp": "1769384622426", "event_type": "price_change"}}
{"_local_timestamp": "2026-01-25T23:43:43.496505+00:00", "data": {"market": "0x5f9ba531b74dd3d7be29f64741e5cad867f797da9aa73c348fd24f510ed2dfed", "price_changes": [{"asset_id": "29998772574245347891697050250557764189917474641475239534746438855989311925662", "price": "0.01", "size": "87.33", "side": "BUY", "hash": "4e5e19e6019f2c96a785d5edacf0a6a8e0a5d3f4", "best_bid": "0.05", "best_ask": "0.32"}, {"asset_id": "81414822130427608080886293296378652266575755903486095487302983244496524955033", "price": "0.99", "size": "87.33", "side": "SELL", "hash": "41d9d2cc3e8b07add35c7ebd63c1c61af8b7af82", "best_bid": "0.68", "best_ask": "0.95"}], "timestamp": "1769384623411", "event_type": "price_change"}}
{"_local_timestamp": "2026-01-25T23:43:43.822086+00:00", "data": {"market": "0x5f9ba531b74dd3d7be29f64741e5cad867f797da9aa73c348fd24f510ed2dfed", "price_changes": [{"asset_id": "29998772574245347891697050250557764189917474641475239534746438855989311925662", "price": "0.01", "size": "120.66", "side": "BUY", "hash": "95ff5ec0ba9b417d091e84d2b3f429fbef34c978", "best_bid": "0.05", "best_ask": "0.32"}, {"asset_id": "81414822130427608080886293296378652266575755903486095487302983244496524955033", "price": "0.99", "size": "120.66", "side": "SELL", "hash": "bcbd7f096262b50f4f410a32e2e9f9ee98330a08", "best_bid": "0.68", "best_ask": "0.95"}], "timestamp": "1769384623747", "event_type": "price_change"}}
{"_local_timestamp": "2026-01-25T23:43:45.940138+00:00", "data": {"market": "0x7b9405ac2a18f553738708544a8bf8e56a2ce444f0cdced388a82219413f1e8b", "price_changes": [{"asset_id": "108462258986864408381729131013925572621223086163135850415272164030051791225397", "price": "0.39", "size": "0", "side": "BUY", "hash": "6d0f41500e2321bb57fde26ecec85413ee95ee31", "best_bid": "0.64", "best_ask": "0.94"}, {"asset_id": "4705265403362581120736820785718797352184109151637378631828322862746823225674", "price": "0.61", "size": "0", "side": "SELL", "hash": "0a6864a22d0df5075d17be7e5bcdc966de528b27", "best_bid": "0.06", "best_ask": "0.36"}], "timestamp": "1769384625865", "event_type": "price_change"}}
{"_local_timestamp": "2026-01-25T23:43:46.024695+00:00", "data": {"market": "0x7b9405ac2a18f553738708544a8bf8e56a2ce444f0cdced388a82219413f1e8b", "price_changes": [{"asset_id": "108462258986864408381729131013925572621223086163135850415272164030051791225397", "price": "0.36", "size": "10", "side": "BUY", "hash": "7517e1677c8427eebbe4fcdd18a381ba94aac489", "best_bid": "0.64", "best_ask": "0.94"}, {"asset_id": "4705265403362581120736820785718797352184109151637378631828322862746823225674", "price": "0.64", "size": "10", "side": "SELL", "hash": "3e7ef3c23bf58bb59fdd4dd83c1d0f4263fde340", "best_bid": "0.06", "best_ask": "0.36"}], "timestamp": "1769384625956", "event_type": "price_change"}}
{"_local_timestamp": "2026-01-25T23:43:47.250864+00:00", "data": {"market": "0x7b9405ac2a18f553738708544a8bf8e56a2ce444f0cdced388a82219413f1e8b", "price_changes": [{"asset_id": "108462258986864408381729131013925572621223086163135850415272164030051791225397", "price": "0.34", "size": "0", "side": "BUY", "hash": "54ed48bc570a5fcce75bf7a0f315eb8ebde89e9c", "best_bid": "0.64", "best_ask": "0.94"}, {"asset_id": "4705265403362581120736820785718797352184109151637378631828322862746823225674", "price": "0.66", "size": "0", "side": "SELL", "hash": "3b104dd4aa8947c954ebea6c641fb7a87a2b8fe0", "best_bid": "0.06", "best_ask": "0.36"}], "timestamp": "1769384627171", "event_type": "price_change"}}
{"_local_timestamp": "2026-01-25T23:43:47.265339+00:00", "data": {"market": "0x7b9405ac2a18f553738708544a8bf8e56a2ce444f0cdced388a82219413f1e8b", "price_changes": [{"asset_id": "108462258986864408381729131013925572621223086163135850415272164030051791225397", "price": "0.37", "size": "20", "side": "BUY", "hash": "0ef41ef19d3fb95874be8da630a5bc4990828080", "best_bid": "0.64", "best_ask": "0.94"}, {"asset_id": "4705265403362581120736820785718797352184109151637378631828322862746823225674", "price": "0.63", "size": "20", "side": "SELL", "hash": "93d0a5a17c3b1a1b4642b4501d940cb1d2d68fa5", "best_bid": "0.06", "best_ask": "0.36"}], "timestamp": "1769384627198", "event_type": "price_change"}}
{"_local_timestamp": "2026-01-25T23:44:08.482528+00:00", "data": {"market": "0x8fd23f0e974fc09874b21e86d16808f5c1da870813f580bc0bf73399fea51ca2", "price_changes": [{"asset_id": "85172525867787641402328444576848541622260332991892947577648996734803038861895", "price": "0.35", "size": "122.66", "side": "BUY", "hash": "dcf21674310552b3e0bebc85b450f1f5db188dc5", "best_bid": "0.81", "best_ask": "0.85"}, {"asset_id": "56438265434513376454964845898456576437217725564238261372991430944084310725149", "price": "0.65", "size": "122.66", "side": "SELL", "hash": "c1c8bbfd9469351cbfb35b5df858c09116c69826", "best_bid": "0.15", "best_ask": "0.19"}], "timestamp": "1769384648347", "event_type": "price_change"}}
{"_local_timestamp": "2026-01-25T23:44:08.953943+00:00", "data": {"market": "0x8fd23f0e974fc09874b21e86d16808f5c1da870813f580bc0bf73399fea51ca2", "price_changes": [{"asset_id": "85172525867787641402328444576848541622260332991892947577648996734803038861895", "price": "0.3", "size": "280", "side": "BUY", "hash": "f681a1061836c9be4c89c8afb77969845875daf6", "best_bid": "0.81", "best_ask": "0.85"}, {"asset_id": "56438265434513376454964845898456576437217725564238261372991430944084310725149", "price": "0.7", "size": "280", "side": "SELL", "hash": "59c056fd1c578577497f6d4e37c1fc216cc84a4e", "best_bid": "0.15", "best_ask": "0.19"}], "timestamp": "1769384648723", "event_type": "price_change"}}
{"_local_timestamp": "2026-01-25T23:44:40.106110+00:00", "data": {"market": "0x7b9405ac2a18f553738708544a8bf8e56a2ce444f0cdced388a82219413f1e8b", "price_changes": [{"asset_id": "4705265403362581120736820785718797352184109151637378631828322862746823225674", "price": "0.02", "size": "60", "side": "BUY", "hash": "be97d81fc4659d34538c7a272bfe75967102e52f", "best_bid": "0.06", "best_ask": "0.36"}, {"asset_id": "108462258986864408381729131013925572621223086163135850415272164030051791225397", "price": "0.98", "size": "60", "side": "SELL", "hash": "7ac81735298f960a4f2c212af06929ad485ff618", "best_bid": "0.64", "best_ask": "0.94"}], "timestamp": "1769384680009", "event_type": "price_change"}}
{"_local_timestamp": "2026-01-25T23:44:45.614425+00:00", "data": {"market": "0x7b9405ac2a18f553738708544a8bf8e56a2ce444f0cdced388a82219413f1e8b", "price_changes": [{"asset_id": "108462258986864408381729131013925572621223086163135850415272164030051791225397", "price": "0.36", "size": "0", "side": "BUY", "hash": "0c7d820b4eae05afd1637cac68944ebef86c1cf6", "best_bid": "0.64", "best_ask": "0.94"}, {"asset_id": "4705265403362581120736820785718797352184109151637378631828322862746823225674", "price": "0.64", "size": "0", "side": "SELL", "hash": "037367461150873719ea4376fee7fe1d49b1835e", "best_bid": "0.06", "best_ask": "0.36"}], "timestamp": "1769384685549", "event_type": "price_change"}}
{"_local_timestamp": "2026-01-25T23:44:45.731522+00:00", "data": {"market": "0x7b9405ac2a18f553738708544a8bf8e56a2ce444f0cdced388a82219413f1e8b", "price_changes": [{"asset_id": "108462258986864408381729131013925572621223086163135850415272164030051791225397", "price": "0.38", "size": "10", "side": "BUY", "hash": "d90504015691ac7ab4b7c8abaffaec5985cb5590", "best_bid": "0.64", "best_ask": "0.94"}, {"asset_id": "4705265403362581120736820785718797352184109151637378631828322862746823225674", "price": "0.62", "size": "10", "side": "SELL", "hash": "f2df451ab7fb6082a9e102f5c8cd3965eabf40f7", "best_bid": "0.06", "best_ask": "0.36"}], "timestamp": "1769384685638", "event_type": "price_change"}}
{"_local_timestamp": "2026-01-25T23:44:49.791119+00:00", "data": {"market": "0x7b9405ac2a18f553738708544a8bf8e56a2ce444f0cdced388a82219413f1e8b", "price_changes": [{"asset_id": "108462258986864408381729131013925572621223086163135850415272164030051791225397", "price": "0.37", "size": "0", "side": "BUY", "hash": "3efa2f766f7a1f09e26172711f83ee67265c5fc5", "best_bid": "0.64", "best_ask": "0.94"}, {"asset_id": "4705265403362581120736820785718797352184109151637378631828322862746823225674", "price": "0.63", "size": "0", "side": "SELL", "hash": "51cd25792c1e2e4d3753e0c29927f55145e15991", "best_bid": "0.06", "best_ask": "0.36"}], "timestamp": "1769384689721", "event_type": "price_change"}}
{"_local_timestamp": "2026-01-25T23:44:49.816866+00:00", "data": {"market": "0x7b9405ac2a18f553738708544a8bf8e56a2ce444f0cdced388a82219413f1e8b", "price_changes": [{"asset_id": "108462258986864408381729131013925572621223086163135850415272164030051791225397", "price": "0.38", "size": "30", "side": "BUY", "hash": "95e9f58cb9b5e3a1fbc1941555d1ade150d41d3a", "best_bid": "0.64", "best_ask": "0.94"}, {"asset_id": "4705265403362581120736820785718797352184109151637378631828322862746823225674", "price": "0.62", "size": "30", "side": "SELL", "hash": "222d0c677f51a6800450a936bcf69f528e29c180", "best_bid": "0.06", "best_ask": "0.36"}], "timestamp": "1769384689745", "event_type": "price_change"}}
{"_local_timestamp": "2026-01-25T23:44:57.788313+00:00", "data": {"market": "0x8fd23f0e974fc09874b21e86d16808f5c1da870813f580bc0bf73399fea51ca2", "price_changes": [{"asset_id": "85172525867787641402328444576848541622260332991892947577648996734803038861895", "price": "0.35", "size": "72.66", "side": "BUY", "hash": "8d917c035a1944044cf3becd474240043460e2b2", "best_bid": "0.81", "best_ask": "0.85"}, {"asset_id": "56438265434513376454964845898456576437217725564238261372991430944084310725149", "price": "0.65", "size": "72.66", "side": "SELL", "hash": "f0f3c1d6ce98a8ca5221751634bf575bc413cc8f", "best_bid": "0.15", "best_ask": "0.19"}], "timestamp": "1769384697720", "event_type": "price_change"}}
{"_local_timestamp": "2026-01-25T23:44:58.315767+00:00", "data": {"market": "0x8fd23f0e974fc09874b21e86d16808f5c1da870813f580bc0bf73399fea51ca2", "price_changes": [{"asset_id": "85172525867787641402328444576848541622260332991892947577648996734803038861895", "price": "0.36", "size": "294", "side": "BUY", "hash": "076658299306a143da7a4c3f5b45379bbc235dc8", "best_bid": "0.81", "best_ask": "0.85"}, {"asset_id": "56438265434513376454964845898456576437217725564238261372991430944084310725149", "price": "0.64", "size": "294", "side": "SELL", "hash": "dc53211b403dee5e82cfe6097b0a4ba185e6dcfd", "best_bid": "0.15", "best_ask": "0.19"}], "timestamp": "1769384698215", "event_type": "price_change"}}
{"_local_timestamp": "2026-01-25T23:45:46.217488+00:00", "data": {"market": "0x7b9405ac2a18f553738708544a8bf8e56a2ce444f0cdced388a82219413f1e8b", "price_changes": [{"asset_id": "108462258986864408381729131013925572621223086163135850415272164030051791225397", "price": "0.65", "size": "7.69", "side": "BUY", "hash": "c8be853f7df4af2d98357899491f391daf4c25f8", "best_bid": "0.65", "best_ask": "0.94"}, {"asset_id": "4705265403362581120736820785718797352184109151637378631828322862746823225674", "price": "0.35", "size": "7.69", "side": "SELL", "hash": "fdf6cacb9db9ef096c1bea265b18e84f9db6df0a", "best_bid": "0.06", "best_ask": "0.35"}], "timestamp": "1769384746148", "event_type": "price_change"}}
{"_local_timestamp": "2026-01-25T23:45:51.534181+00:00", "data": {"market": "0x7b9405ac2a18f553738708544a8bf8e56a2ce444f0cdced388a82219413f1e8b", "price_changes": [{"asset_id": "4705265403362581120736820785718797352184109151637378631828322862746823225674", "price": "0.36", "size": "10", "side": "SELL", "hash": "5bc75495374a3e5dcd03c377c16adae65b6fa9af", "best_bid": "0.06", "best_ask": "0.35"}, {"asset_id": "108462258986864408381729131013925572621223086163135850415272164030051791225397", "price": "0.64", "size": "10", "side": "BUY", "hash": "9bfc437c37a645751ac3793a71d6d1e9ad2d8640", "best_bid": "0.65", "best_ask": "0.94"}], "timestamp": "1769384751460", "event_type": "price_change"}}
{"_local_timestamp": "2026-01-25T23:45:57.240393+00:00", "data": {"market": "0x8fd23f0e974fc09874b21e86d16808f5c1da870813f580bc0bf73399fea51ca2", "price_changes": [{"asset_id": "85172525867787641402328444576848541622260332991892947577648996734803038861895", "price": "0.36", "size": "125", "side": "BUY", "hash": "7e5e5ddebaad06253ebf6e5ee51228acce41eb2d", "best_bid": "0.81", "best_ask": "0.85"}, {"asset_id": "56438265434513376454964845898456576437217725564238261372991430944084310725149", "price": "0.64", "size": "125", "side": "SELL", "hash": "b788caadb3fdc21a4234b2e948e6b7f33ae45362", "best_bid": "0.15", "best_ask": "0.19"}], "timestamp": "1769384756842", "event_type": "price_change"}}
{"_local_timestamp": "2026-01-25T23:46:20.544376+00:00", "data": {"market": "0x3f912d2e5965430f00f074e9b8fd9cdc7fb5948074c19b271720c8e620f2cb11", "price_changes": [{"asset_id": "90179144936207028478465214931375521788167296412041627475537095855791073500041", "price": "0.23", "size": "178.33", "side": "BUY", "hash": "a2de5a763c99b5b029752af4769804451fee0cfe", "best_bid": "0.4", "best_ask": "0.92"}, {"asset_id": "58342639934160101133354411315222065187144122136965451700208165731325515097740", "price": "0.77", "size": "178.33", "side": "SELL", "hash": "a1b754314d73f812afb0ba6e4c104c0cc8b2cd6c", "best_bid": "0.08", "best_ask": "0.6"}], "timestamp": "1769384780473", "event_type": "price_change"}}
{"_local_timestamp": "2026-01-25T23:46:20.544947+00:00", "data": {"market": "0x3f912d2e5965430f00f074e9b8fd9cdc7fb5948074c19b271720c8e620f2cb11", "price_changes": [{"asset_id": "90179144936207028478465214931375521788167296412041627475537095855791073500041", "price": "0.24", "size": "158.33", "side": "BUY", "hash": "70ed22b4d70938a632a5f07b0091ee67d1419d6a", "best_bid": "0.4", "best_ask": "0.92"}, {"asset_id": "58342639934160101133354411315222065187144122136965451700208165731325515097740", "price": "0.76", "size": "158.33", "side": "SELL", "hash": "6762260e4947cfe8020d16be33b9fd93732f3509", "best_bid": "0.08", "best_ask": "0.6"}], "timestamp": "1769384780475", "event_type": "price_change"}}
{"_local_timestamp": "2026-01-25T23:46:23.892056+00:00", "data": {"market": "0x3f912d2e5965430f00f074e9b8fd9cdc7fb5948074c19b271720c8e620f2cb11", "price_changes": [{"asset_id": "90179144936207028478465214931375521788167296412041627475537095855791073500041", "price": "0.23", "size": "158.33", "side": "BUY", "hash": "36db0bef99a02b2261e788a16abd040f9e2583b7", "best_bid": "0.4", "best_ask": "0.92"}, {"asset_id": "58342639934160101133354411315222065187144122136965451700208165731325515097740", "price": "0.77", "size": "158.33", "side": "SELL", "hash": "d874a7c79322b14f89e56217f57596580166a2b9", "best_bid": "0.08", "best_ask": "0.6"}], "timestamp": "1769384783817", "event_type": "price_change"}}
{"_local_timestamp": "2026-01-25T23:46:23.913436+00:00", "data": {"market": "0x3f912d2e5965430f00f074e9b8fd9cdc7fb5948074c19b271720c8e620f2cb11", "price_changes": [{"asset_id": "90179144936207028478465214931375521788167296412041627475537095855791073500041", "price": "0.25", "size": "20", "side": "BUY", "hash": "c6c9628a1076bddb436529d19758e59b421190be", "best_bid": "0.4", "best_ask": "0.92"}, {"asset_id": "58342639934160101133354411315222065187144122136965451700208165731325515097740", "price": "0.75", "size": "20", "side": "SELL", "hash": "dce06fd6e03d3d2da9c08f622eb96d1a17f62d1e", "best_bid": "0.08", "best_ask": "0.6"}], "timestamp": "1769384783846", "event_type": "price_change"}}
{"_local_timestamp": "2026-01-25T23:46:32.033272+00:00", "data": {"market": "0x7b9405ac2a18f553738708544a8bf8e56a2ce444f0cdced388a82219413f1e8b", "price_changes": [{"asset_id": "4705265403362581120736820785718797352184109151637378631828322862746823225674", "price": "0.35", "size": "12.69", "side": "SELL", "hash": "c31b9e8f2b59bd6304d7fbebfd04b95d71b83297", "best_bid": "0.06", "best_ask": "0.35"}, {"asset_id": "108462258986864408381729131013925572621223086163135850415272164030051791225397", "price": "0.65", "size": "12.69", "side": "BUY", "hash": "6477cd08c6716c807a0bb85a77f4ddd685c2a6ad", "best_bid": "0.65", "best_ask": "0.94"}], "timestamp": "1769384791781", "event_type": "price_change"}}
{"_local_timestamp": "2026-01-25T23:46:33.312905+00:00", "data": {"market": "0x3f912d2e5965430f00f074e9b8fd9cdc7fb5948074c19b271720c8e620f2cb11", "price_changes": [{"asset_id": "90179144936207028478465214931375521788167296412041627475537095855791073500041", "price": "0.23", "size": "0", "side": "BUY", "hash": "fa47781687e03e38a27d06ca2c40a46aa0e4cf33", "best_bid": "0.4", "best_ask": "0.92"}, {"asset_id": "58342639934160101133354411315222065187144122136965451700208165731325515097740", "price": "0.77", "size": "0", "side": "SELL", "hash": "909ad6834bbfa3105027680aaf1aeda1cac606c5", "best_bid": "0.08", "best_ask": "0.6"}], "timestamp": "1769384793018", "event_type": "price_change"}}
{"_local_timestamp": "2026-01-25T23:46:39.112741+00:00", "data": {"market": "0x3f912d2e5965430f00f074e9b8fd9cdc7fb5948074c19b271720c8e620f2cb11", "price_changes": [{"asset_id": "90179144936207028478465214931375521788167296412041627475537095855791073500041", "price": "0.02", "size": "500", "side": "BUY", "hash": "5c8eeed2e6c7ff96f111d2072c1219d68df3f7d7", "best_bid": "0.4", "best_ask": "0.92"}, {"asset_id": "58342639934160101133354411315222065187144122136965451700208165731325515097740", "price": "0.98", "size": "500", "side": "SELL", "hash": "3c15e94eb251d375ab9bace023cf1fa6158dafea", "best_bid": "0.08", "best_ask": "0.6"}], "timestamp": "1769384798835", "event_type": "price_change"}}
{"_local_timestamp": "2026-01-25T23:46:39.113375+00:00", "data": {"market": "0x3f912d2e5965430f00f074e9b8fd9cdc7fb5948074c19b271720c8e620f2cb11", "price_changes": [{"asset_id": "90179144936207028478465214931375521788167296412041627475537095855791073500041", "price": "0.04", "size": "200", "side": "BUY", "hash": "5c8eeed2e6c7ff96f111d2072c1219d68df3f7d7", "best_bid": "0.4", "best_ask": "0.92"}, {"asset_id": "58342639934160101133354411315222065187144122136965451700208165731325515097740", "price": "0.96", "size": "200", "side": "SELL", "hash": "3c15e94eb251d375ab9bace023cf1fa6158dafea", "best_bid": "0.08", "best_ask": "0.6"}], "timestamp": "1769384798835", "event_type": "price_change"}}
{"_local_timestamp": "2026-01-25T23:46:39.113894+00:00", "data": {"market": "0x3f912d2e5965430f00f074e9b8fd9cdc7fb5948074c19b271720c8e620f2cb11", "price_changes": [{"asset_id": "90179144936207028478465214931375521788167296412041627475537095855791073500041", "price": "0.07", "size": "0", "side": "BUY", "hash": "5c8eeed2e6c7ff96f111d2072c1219d68df3f7d7", "best_bid": "0.4", "best_ask": "0.92"}, {"asset_id": "58342639934160101133354411315222065187144122136965451700208165731325515097740", "price": "0.93", "size": "0", "side": "SELL", "hash": "3c15e94eb251d375ab9bace023cf1fa6158dafea", "best_bid": "0.08", "best_ask": "0.6"}], "timestamp": "1769384798835", "event_type": "price_change"}}
{"_local_timestamp": "2026-01-25T23:46:39.114427+00:00", "data": {"market": "0x3f912d2e5965430f00f074e9b8fd9cdc7fb5948074c19b271720c8e620f2cb11", "price_changes": [{"asset_id": "90179144936207028478465214931375521788167296412041627475537095855791073500041", "price": "0.16", "size": "0", "side": "BUY", "hash": "5c8eeed2e6c7ff96f111d2072c1219d68df3f7d7", "best_bid": "0.4", "best_ask": "0.92"}, {"asset_id": "58342639934160101133354411315222065187144122136965451700208165731325515097740", "price": "0.84", "size": "0", "side": "SELL", "hash": "3c15e94eb251d375ab9bace023cf1fa6158dafea", "best_bid": "0.08", "best_ask": "0.6"}], "timestamp": "1769384798835", "event_type": "price_change"}}
{"_local_timestamp": "2026-01-25T23:46:39.523368+00:00", "data": {"market": "0x3f912d2e5965430f00f074e9b8fd9cdc7fb5948074c19b271720c8e620f2cb11", "price_changes": [{"asset_id": "90179144936207028478465214931375521788167296412041627475537095855791073500041", "price": "0.03", "size": "305", "side": "BUY", "hash": "29631c078d492f250bd7a58315524169184e0047", "best_bid": "0.4", "best_ask": "0.92"}, {"asset_id": "58342639934160101133354411315222065187144122136965451700208165731325515097740", "price": "0.97", "size": "305", "side": "SELL", "hash": "2b45231dcf7d94bfda6f0730b6c9630ed60b943e", "best_bid": "0.08", "best_ask": "0.6"}], "timestamp": "1769384799260", "event_type": "price_change"}}
{"_local_timestamp": "2026-01-25T23:46:39.528950+00:00", "data": {"market": "0x3f912d2e5965430f00f074e9b8fd9cdc7fb5948074c19b271720c8e620f2cb11", "price_changes": [{"asset_id": "90179144936207028478465214931375521788167296412041627475537095855791073500041", "price": "0.09", "size": "27.21", "side": "BUY", "hash": "a91e44d6a90d91e1ed3eab02d90a49beb8dff66c", "best_bid": "0.4", "best_ask": "0.92"}, {"asset_id": "58342639934160101133354411315222065187144122136965451700208165731325515097740", "price": "0.91", "size": "27.21", "side": "SELL", "hash": "3ff70458607405f82e7315f06ce8418a1c187b0c", "best_bid": "0.08", "best_ask": "0.6"}], "timestamp": "1769384799260", "event_type": "price_change"}}
{"_local_timestamp": "2026-01-25T23:46:39.529524+00:00", "data": {"market": "0x3f912d2e5965430f00f074e9b8fd9cdc7fb5948074c19b271720c8e620f2cb11", "price_changes": [{"asset_id": "90179144936207028478465214931375521788167296412041627475537095855791073500041", "price": "0.17", "size": "5.56", "side": "BUY", "hash": "e59c1eb40511df60088ffdd8cf024dce4647096d", "best_bid": "0.4", "best_ask": "0.92"}, {"asset_id": "58342639934160101133354411315222065187144122136965451700208165731325515097740", "price": "0.83", "size": "5.56", "side": "SELL", "hash": "38462c278c6f1abd500456a355235c191ae1efe7", "best_bid": "0.08", "best_ask": "0.6"}], "timestamp": "1769384799261", "event_type": "price_change"}}
{"_local_timestamp": "2026-01-25T23:46:39.530009+00:00", "data": {"market": "0x3f912d2e5965430f00f074e9b8fd9cdc7fb5948074c19b271720c8e620f2cb11", "price_changes": [{"asset_id": "90179144936207028478465214931375521788167296412041627475537095855791073500041", "price": "0.01", "size": "3945.86", "side": "BUY", "hash": "cdaac014113bf74aa948988cdae96801e1fab480", "best_bid": "0.4", "best_ask": "0.92"}, {"asset_id": "58342639934160101133354411315222065187144122136965451700208165731325515097740", "price": "0.99", "size": "3945.86", "side": "SELL", "hash": "d568996db40f3ec97277ef796fecd6b49d431927", "best_bid": "0.08", "best_ask": "0.6"}], "timestamp": "1769384799262", "event_type": "price_change"}}
{"_local_timestamp": "2026-01-25T23:46:39.530573+00:00", "data": {"market": "0x3f912d2e5965430f00f074e9b8fd9cdc7fb5948074c19b271720c8e620f2cb11", "price_changes": [{"asset_id": "90179144936207028478465214931375521788167296412041627475537095855791073500041", "price": "0.05", "size": "105.52", "side": "BUY", "hash": "3c3152f3892db559b95bc7bd29e64d5e98b8d6b6", "best_bid": "0.4", "best_ask": "0.92"}, {"asset_id": "58342639934160101133354411315222065187144122136965451700208165731325515097740", "price": "0.95", "size": "105.52", "side": "SELL", "hash": "291677b04317ab4dabcd5205e7a32ed0f1e6d5a4", "best_bid": "0.08", "best_ask": "0.6"}], "timestamp": "1769384799263", "event_type": "price_change"}}
{"_local_timestamp": "2026-01-25T23:46:45.869563+00:00", "data": {"market": "0x3f912d2e5965430f00f074e9b8fd9cdc7fb5948074c19b271720c8e620f2cb11", "price_changes": [{"asset_id": "90179144936207028478465214931375521788167296412041627475537095855791073500041", "price": "0.24", "size": "0", "side": "BUY", "hash": "68269a769a8b0817713c87e1961dd2a855e6541c", "best_bid": "0.4", "best_ask": "0.92"}, {"asset_id": "58342639934160101133354411315222065187144122136965451700208165731325515097740", "price": "0.76", "size": "0", "side": "SELL", "hash": "ea9d3ca536e16d23a54b53fa4060626b503fe2b2", "best_bid": "0.08", "best_ask": "0.6"}], "timestamp": "1769384805750", "event_type": "price_change"}}
{"_local_timestamp": "2026-01-25T23:46:48.166501+00:00", "data": {"market": "0x7b9405ac2a18f553738708544a8bf8e56a2ce444f0cdced388a82219413f1e8b", "price_changes": [{"asset_id": "108462258986864408381729131013925572621223086163135850415272164030051791225397", "price": "0.38", "size": "20", "side": "BUY", "hash": "5083f63f3cedc19204e59b2d9e516e9938e03b6e", "best_bid": "0.65", "best_ask": "0.94"}, {"asset_id": "4705265403362581120736820785718797352184109151637378631828322862746823225674", "price": "0.62", "size": "20", "side": "SELL", "hash": "111c6aa095676ba1447676eb15dae30a3f2f933d", "best_bid": "0.06", "best_ask": "0.35"}], "timestamp": "1769384807976", "event_type": "price_change"}}
{"_local_timestamp": "2026-01-25T23:46:48.250013+00:00", "data": {"market": "0x7b9405ac2a18f553738708544a8bf8e56a2ce444f0cdced388a82219413f1e8b", "price_changes": [{"asset_id": "108462258986864408381729131013925572621223086163135850415272164030051791225397", "price": "0.4", "size": "15", "side": "BUY", "hash": "7639749cfc3b290283c3ab7fa2085f08d38a74db", "best_bid": "0.65", "best_ask": "0.94"}, {"asset_id": "4705265403362581120736820785718797352184109151637378631828322862746823225674", "price": "0.6", "size": "15", "side": "SELL", "hash": "a27bd6268b2eeb8b7bcbfefb70a731fa228ec361", "best_bid": "0.06", "best_ask": "0.35"}], "timestamp": "1769384808060", "event_type": "price_change"}}
{"_local_timestamp": "2026-01-25T23:46:51.099618+00:00", "data": {"market": "0x3f912d2e5965430f00f074e9b8fd9cdc7fb5948074c19b271720c8e620f2cb11", "price_changes": [{"asset_id": "90179144936207028478465214931375521788167296412041627475537095855791073500041", "price": "0.25", "size": "0", "side": "BUY", "hash": "915c6df0ae700d8eb7be370d0fdb66abdabe7c4d", "best_bid": "0.4", "best_ask": "0.92"}, {"asset_id": "58342639934160101133354411315222065187144122136965451700208165731325515097740", "price": "0.75", "size": "0", "side": "SELL", "hash": "00c1dd4b93b63114a512df696bf537658e28fcc6", "best_bid": "0.08", "best_ask": "0.6"}], "timestamp": "1769384810736", "event_type": "price_change"}}
{"_local_timestamp": "2026-01-25T23:46:51.110483+00:00", "data": {"market": "0x7b9405ac2a18f553738708544a8bf8e56a2ce444f0cdced388a82219413f1e8b", "price_changes": [{"asset_id": "108462258986864408381729131013925572621223086163135850415272164030051791225397", "price": "0.38", "size": "0", "side": "BUY", "hash": "4c3d6ebcbfad4e1c20d5a401128b79cd76094c24", "best_bid": "0.65", "best_ask": "0.94"}, {"asset_id": "4705265403362581120736820785718797352184109151637378631828322862746823225674", "price": "0.62", "size": "0", "side": "SELL", "hash": "da94a660f2c8a5666e148c56133ae30d3163ce04", "best_bid": "0.06", "best_ask": "0.35"}], "timestamp": "1769384810736", "event_type": "price_change"}}
{"_local_timestamp": "2026-01-25T23:46:51.121053+00:00", "data": {"market": "0x7b9405ac2a18f553738708544a8bf8e56a2ce444f0cdced388a82219413f1e8b", "price_changes": [{"asset_id": "108462258986864408381729131013925572621223086163135850415272164030051791225397", "price": "0.34", "size": "20", "side": "BUY", "hash": "42c391bc440372cc8034ebb533322d32b076fe20", "best_bid": "0.65", "best_ask": "0.94"}, {"asset_id": "4705265403362581120736820785718797352184109151637378631828322862746823225674", "price": "0.66", "size": "20", "side": "SELL", "hash": "f06fdd4f4d306ff671e9dd90dc086a9b037e2fb4", "best_bid": "0.06", "best_ask": "0.35"}], "timestamp": "1769384810763", "event_type": "price_change"}}
{"_local_timestamp": "2026-01-25T23:46:51.125689+00:00", "data": {"market": "0x3f912d2e5965430f00f074e9b8fd9cdc7fb5948074c19b271720c8e620f2cb11", "price_changes": [{"asset_id": "90179144936207028478465214931375521788167296412041627475537095855791073500041", "price": "0.23", "size": "20", "side": "BUY", "hash": "f849e77a078d6d2927ada156ea3c3c45a7c9aa8a", "best_bid": "0.4", "best_ask": "0.92"}, {"asset_id": "58342639934160101133354411315222065187144122136965451700208165731325515097740", "price": "0.77", "size": "20", "side": "SELL", "hash": "b63b49c10c8c342d200932f946c98ea7f5edd2ed", "best_bid": "0.08", "best_ask": "0.6"}], "timestamp": "1769384810764", "event_type": "price_change"}}
{"_local_timestamp": "2026-01-25T23:46:55.452993+00:00", "data": {"market": "0x8fd23f0e974fc09874b21e86d16808f5c1da870813f580bc0bf73399fea51ca2", "price_changes": [{"asset_id": "85172525867787641402328444576848541622260332991892947577648996734803038861895", "price": "0.37", "size": "147", "side": "BUY", "hash": "da8b12f194fb212cb63867745eb94583f88d5e68", "best_bid": "0.81", "best_ask": "0.85"}, {"asset_id": "56438265434513376454964845898456576437217725564238261372991430944084310725149", "price": "0.63", "size": "147", "side": "SELL", "hash": "b0320b8626262b6dc341ba823280816c5d238027", "best_bid": "0.15", "best_ask": "0.19"}], "timestamp": "1769384815338", "event_type": "price_change"}}
{"_local_timestamp": "2026-01-25T23:47:08.501479+00:00", "data": {"market": "0x3f912d2e5965430f00f074e9b8fd9cdc7fb5948074c19b271720c8e620f2cb11", "price_changes": [{"asset_id": "90179144936207028478465214931375521788167296412041627475537095855791073500041", "price": "0.08", "size": "100", "side": "BUY", "hash": "a776d378cc041c3229d34f3a82cf76c961e86a1f", "best_bid": "0.4", "best_ask": "0.92"}, {"asset_id": "58342639934160101133354411315222065187144122136965451700208165731325515097740", "price": "0.92", "size": "100", "side": "SELL", "hash": "7903019e1e1cadbf1e5be40ca49e417473c9ff49", "best_bid": "0.08", "best_ask": "0.6"}], "timestamp": "1769384828405", "event_type": "price_change"}}
{"_local_timestamp": "2026-01-25T23:47:08.502083+00:00", "data": {"market": "0x6d16cc6bfc59787a24d6ea41cc49ad03f3a3a44e97aad02d7300cf906c812e53", "price_changes": [{"asset_id": "21134177830802910367859690071335268803233593888575931822119572207559990909766", "price": "0.03", "size": "100", "side": "BUY", "hash": "d3872232ace7be698e63554443266c5f41ee5f1b", "best_bid": "0.4", "best_ask": "0.84"}, {"asset_id": "60253373069171098683378509644885376353498749849701407276928730338318645499936", "price": "0.97", "size": "100", "side": "SELL", "hash": "5334ab4f1a72611ce9a10c50a37152660d495b06", "best_bid": "0.16", "best_ask": "0.6"}], "timestamp": "1769384828405", "event_type": "price_change"}}
{"_local_timestamp": "2026-01-25T23:47:08.790363+00:00", "data": {"market": "0x3f912d2e5965430f00f074e9b8fd9cdc7fb5948074c19b271720c8e620f2cb11", "price_changes": [{"asset_id": "90179144936207028478465214931375521788167296412041627475537095855791073500041", "price": "0.04", "size": "300", "side": "BUY", "hash": "bef099edba834595552631ef36c0b332303dc975", "best_bid": "0.4", "best_ask": "0.92"}, {"asset_id": "58342639934160101133354411315222065187144122136965451700208165731325515097740", "price": "0.96", "size": "300", "side": "SELL", "hash": "dfa68dd20279ed612d8269d02260afa1ef7ccf08", "best_bid": "0.08", "best_ask": "0.6"}], "timestamp": "1769384828681", "event_type": "price_change"}}
{"_local_timestamp": "2026-01-25T23:47:08.791080+00:00", "data": {"market": "0x6d16cc6bfc59787a24d6ea41cc49ad03f3a3a44e97aad02d7300cf906c812e53", "price_changes": [{"asset_id": "21134177830802910367859690071335268803233593888575931822119572207559990909766", "price": "0.07", "size": "105.46", "side": "BUY", "hash": "8f7a85a533f7a963d7ffdabb8722086f22795848", "best_bid": "0.4", "best_ask": "0.84"}, {"asset_id": "60253373069171098683378509644885376353498749849701407276928730338318645499936", "price": "0.93", "size": "105.46", "side": "SELL", "hash": "810d6a68366863526a8d87bd7f299e42920579c4", "best_bid": "0.16", "best_ask": "0.6"}], "timestamp": "1769384828682", "event_type": "price_change"}}
{"_local_timestamp": "2026-01-25T23:47:19.187591+00:00", "data": {"market": "0x3f912d2e5965430f00f074e9b8fd9cdc7fb5948074c19b271720c8e620f2cb11", "price_changes": [{"asset_id": "90179144936207028478465214931375521788167296412041627475537095855791073500041", "price": "0.22", "size": "100", "side": "BUY", "hash": "efc4ef08ef9ee7c90907f73c5c950252b95b610f", "best_bid": "0.4", "best_ask": "0.92"}, {"asset_id": "58342639934160101133354411315222065187144122136965451700208165731325515097740", "price": "0.78", "size": "100", "side": "SELL", "hash": "d7d1aaff9ab1170563607149d9cb4f4e511f158c", "best_bid": "0.08", "best_ask": "0.6"}], "timestamp": "1769384838862", "event_type": "price_change"}}
{"_local_timestamp": "2026-01-25T23:47:19.188248+00:00", "data": {"market": "0x3f912d2e5965430f00f074e9b8fd9cdc7fb5948074c19b271720c8e620f2cb11", "price_changes": [{"asset_id": "58342639934160101133354411315222065187144122136965451700208165731325515097740", "price": "0.05", "size": "57.33", "side": "BUY", "hash": "91cb15a534c5da82ae51b71686d37d6c3f56dce1", "best_bid": "0.08", "best_ask": "0.6"}, {"asset_id": "90179144936207028478465214931375521788167296412041627475537095855791073500041", "price": "0.95", "size": "57.33", "side": "SELL", "hash": "68ffe4aca2b9bb948d6c912f2c092b5bacc1a730", "best_bid": "0.4", "best_ask": "0.92"}], "timestamp": "1769384838862", "event_type": "price_change"}}
{"_local_timestamp": "2026-01-25T23:47:22.387089+00:00", "data": {"market": "0x7b9405ac2a18f553738708544a8bf8e56a2ce444f0cdced388a82219413f1e8b", "price_changes": [{"asset_id": "4705265403362581120736820785718797352184109151637378631828322862746823225674", "price": "0.02", "size": "69.48", "side": "BUY", "hash": "e7d5b2d6f301d4599694af9e03845251128d9510", "best_bid": "0.06", "best_ask": "0.35"}, {"asset_id": "108462258986864408381729131013925572621223086163135850415272164030051791225397", "price": "0.98", "size": "69.48", "side": "SELL", "hash": "6f414b8575f2fc3b7736bea65432d21c3e8b95e9", "best_bid": "0.65", "best_ask": "0.94"}], "timestamp": "1769384842188", "event_type": "price_change"}}
{"_local_timestamp": "2026-01-25T23:47:22.514219+00:00", "data": {"market": "0x5f9ba531b74dd3d7be29f64741e5cad867f797da9aa73c348fd24f510ed2dfed", "price_changes": [{"asset_id": "29998772574245347891697050250557764189917474641475239534746438855989311925662", "price": "0.01", "size": "87.33", "side": "BUY", "hash": "5389e6a61e37b0f7a7bb39cc8f7e8e0cdab5114d", "best_bid": "0.05", "best_ask": "0.32"}, {"asset_id": "81414822130427608080886293296378652266575755903486095487302983244496524955033", "price": "0.99", "size": "87.33", "side": "SELL", "hash": "e3640e95f0ed6c17bc9a95222646ccc8246b2f3e", "best_bid": "0.68", "best_ask": "0.95"}], "timestamp": "1769384842314", "event_type": "price_change"}}
{"_local_timestamp": "2026-01-25T23:47:22.964894+00:00", "data": {"market": "0x5f9ba531b74dd3d7be29f64741e5cad867f797da9aa73c348fd24f510ed2dfed", "price_changes": [{"asset_id": "29998772574245347891697050250557764189917474641475239534746438855989311925662", "price": "0.01", "size": "120.66", "side": "BUY", "hash": "9355eb41ab0bfd236debbee64f8ab86460c2b0b4", "best_bid": "0.05", "best_ask": "0.32"}, {"asset_id": "81414822130427608080886293296378652266575755903486095487302983244496524955033", "price": "0.99", "size": "120.66", "side": "SELL", "hash": "7f0d24257ce41f9b98316ffd3fb32defeeeef923", "best_bid": "0.68", "best_ask": "0.95"}], "timestamp": "1769384842783", "event_type": "price_change"}}
{"_local_timestamp": "2026-01-25T23:47:28.142748+00:00", "data": {"market": "0x3f912d2e5965430f00f074e9b8fd9cdc7fb5948074c19b271720c8e620f2cb11", "price_changes": [{"asset_id": "90179144936207028478465214931375521788167296412041627475537095855791073500041", "price": "0.08", "size": "0", "side": "BUY", "hash": "fe2475884638b2a442bdaf51d9ce7e3f11b1a633", "best_bid": "0.4", "best_ask": "0.92"}, {"asset_id": "58342639934160101133354411315222065187144122136965451700208165731325515097740", "price": "0.92", "size": "0", "side": "SELL", "hash": "048afcc358100017d71be873ff3c198ff2eb3a83", "best_bid": "0.08", "best_ask": "0.6"}], "timestamp": "1769384847885", "event_type": "price_change"}}
{"_local_timestamp": "2026-01-25T23:47:28.144029+00:00", "data": {"market": "0x6d16cc6bfc59787a24d6ea41cc49ad03f3a3a44e97aad02d7300cf906c812e53", "price_changes": [{"asset_id": "21134177830802910367859690071335268803233593888575931822119572207559990909766", "price": "0.06", "size": "133", "side": "BUY", "hash": "d2f9ffc21f4c7787e09a5f3701e04a96203d60e9", "best_bid": "0.4", "best_ask": "0.84"}, {"asset_id": "60253373069171098683378509644885376353498749849701407276928730338318645499936", "price": "0.94", "size": "133", "side": "SELL", "hash": "c63d908b38cc51788d31b6fd444864ac5f9bcaf2", "best_bid": "0.16", "best_ask": "0.6"}], "timestamp": "1769384847884", "event_type": "price_change"}}
{"_local_timestamp": "2026-01-25T23:47:28.403737+00:00", "data": {"market": "0x6d16cc6bfc59787a24d6ea41cc49ad03f3a3a44e97aad02d7300cf906c812e53", "price_changes": [{"asset_id": "21134177830802910367859690071335268803233593888575931822119572207559990909766", "price": "0.07", "size": "405.46", "side": "BUY", "hash": "c6dfaaf92b08ecc035d95662d8806daf5cf06e1a", "best_bid": "0.4", "best_ask": "0.84"}, {"asset_id": "60253373069171098683378509644885376353498749849701407276928730338318645499936", "price": "0.93", "size": "405.46", "side": "SELL", "hash": "c36518263401e6f8851979fb0cb0ea3a49a6dd10", "best_bid": "0.16", "best_ask": "0.6"}], "timestamp": "1769384848142", "event_type": "price_change"}}
{"_local_timestamp": "2026-01-25T23:47:28.418550+00:00", "data": {"market": "0x3f912d2e5965430f00f074e9b8fd9cdc7fb5948074c19b271720c8e620f2cb11", "price_changes": [{"asset_id": "90179144936207028478465214931375521788167296412041627475537095855791073500041", "price": "0.05", "size": "405.52", "side": "BUY", "hash": "0d1e52529ff512fa3ccfe88a6fb7173f14a9a4e4", "best_bid": "0.4", "best_ask": "0.92"}, {"asset_id": "58342639934160101133354411315222065187144122136965451700208165731325515097740", "price": "0.95", "size": "405.52", "side": "SELL", "hash": "a758c839f108e4bcf6d6f40f24b4822ddf6c0a69", "best_bid": "0.08", "best_ask": "0.6"}], "timestamp": "1769384848142", "event_type": "price_change"}}
{"_local_timestamp": "2026-01-25T23:47:51.085138+00:00", "data": {"market": "0x8fd23f0e974fc09874b21e86d16808f5c1da870813f580bc0bf73399fea51ca2", "price_changes": [{"asset_id": "56438265434513376454964845898456576437217725564238261372991430944084310725149", "price": "0.08", "size": "23.84", "side": "BUY", "hash": "b0010814dbd2d3974221e8b3ca60ec3299753be7", "best_bid": "0.15", "best_ask": "0.19"}, {"asset_id": "85172525867787641402328444576848541622260332991892947577648996734803038861895", "price": "0.92", "size": "23.84", "side": "SELL", "hash": "30678ca46ebf38019a88047fa799fed7742129e2", "best_bid": "0.81", "best_ask": "0.85"}], "timestamp": "1769384871000", "event_type": "price_change"}}
{"_local_timestamp": "2026-01-25T23:47:51.103221+00:00", "data": {"market": "0x8fd23f0e974fc09874b21e86d16808f5c1da870813f580bc0bf73399fea51ca2", "price_changes": [{"asset_id": "56438265434513376454964845898456576437217725564238261372991430944084310725149", "price": "0.12", "size": "10", "side": "BUY", "hash": "3378ec65cf0fafe012376f5f478da9b0475d61c5", "best_bid": "0.15", "best_ask": "0.19"}, {"asset_id": "85172525867787641402328444576848541622260332991892947577648996734803038861895", "price": "0.88", "size": "10", "side": "SELL", "hash": "66fecc45846b827f9d55bde9821abee744600c29", "best_bid": "0.81", "best_ask": "0.85"}], "timestamp": "1769384871001", "event_type": "price_change"}}
{"_local_timestamp": "2026-01-25T23:47:52.085613+00:00", "data": {"market": "0x8fd23f0e974fc09874b21e86d16808f5c1da870813f580bc0bf73399fea51ca2", "price_changes": [{"asset_id": "85172525867787641402328444576848541622260332991892947577648996734803038861895", "price": "0.65", "size": "0", "side": "BUY", "hash": "21b51518bf525b896ddd6e2612015dcf564ab2ae", "best_bid": "0.81", "best_ask": "0.85"}, {"asset_id": "56438265434513376454964845898456576437217725564238261372991430944084310725149", "price": "0.35", "size": "0", "side": "SELL", "hash": "e0482b87b876a634f32d256be95caba23a0052fb", "best_bid": "0.15", "best_ask": "0.19"}], "timestamp": "1769384872000", "event_type": "price_change"}}
{"_local_timestamp": "2026-01-25T23:47:52.103575+00:00", "data": {"market": "0x8fd23f0e974fc09874b21e86d16808f5c1da870813f580bc0bf73399fea51ca2", "price_changes": [{"asset_id": "85172525867787641402328444576848541622260332991892947577648996734803038861895", "price": "0.46", "size": "0", "side": "BUY", "hash": "753d299579aefc5883d6cf207f6a277965044d1d", "best_bid": "0.81", "best_ask": "0.85"}, {"asset_id": "56438265434513376454964845898456576437217725564238261372991430944084310725149", "price": "0.54", "size": "0", "side": "SELL", "hash": "80f97b1821258138718fc211c3cb7a623e5de3dc", "best_bid": "0.15", "best_ask": "0.19"}], "timestamp": "1769384872001", "event_type": "price_change"}}
{"_local_timestamp": "2026-01-25T23:47:52.104099+00:00", "data": {"market": "0x8fd23f0e974fc09874b21e86d16808f5c1da870813f580bc0bf73399fea51ca2", "price_changes": [{"asset_id": "56438265434513376454964845898456576437217725564238261372991430944084310725149", "price": "0.05", "size": "21", "side": "BUY", "hash": "4afd6391fd0a50cce0ed36517bdcb03f4d293d97", "best_bid": "0.15", "best_ask": "0.19"}, {"asset_id": "85172525867787641402328444576848541622260332991892947577648996734803038861895", "price": "0.95", "size": "21", "side": "SELL", "hash": "b77b46eca3d9a49a246a5d99441d56b4f8adb2ca", "best_bid": "0.81", "best_ask": "0.85"}], "timestamp": "1769384872002", "event_type": "price_change"}}
{"_local_timestamp": "2026-01-25T23:47:52.154049+00:00", "data": {"market": "0x8fd23f0e974fc09874b21e86d16808f5c1da870813f580bc0bf73399fea51ca2", "price_changes": [{"asset_id": "56438265434513376454964845898456576437217725564238261372991430944084310725149", "price": "0.03", "size": "11.11", "side": "BUY", "hash": "cf195eb4361c15ddf6b174d3c782625f57642fe6", "best_bid": "0.15", "best_ask": "0.19"}, {"asset_id": "85172525867787641402328444576848541622260332991892947577648996734803038861895", "price": "0.97", "size": "11.11", "side": "SELL", "hash": "739b049817494a4342c2d26b579aa0f42d0164ff", "best_bid": "0.81", "best_ask": "0.85"}], "timestamp": "1769384872080", "event_type": "price_change"}}
{"_local_timestamp": "2026-01-25T23:47:53.073472+00:00", "data": {"market": "0x8fd23f0e974fc09874b21e86d16808f5c1da870813f580bc0bf73399fea51ca2", "price_changes": [{"asset_id": "85172525867787641402328444576848541622260332991892947577648996734803038861895", "price": "0.4", "size": "0", "side": "BUY", "hash": "c6a3b61468380a7b2fe5f73e288912fbc4050c50", "best_bid": "0.81", "best_ask": "0.85"}, {"asset_id": "56438265434513376454964845898456576437217725564238261372991430944084310725149", "price": "0.6", "size": "0", "side": "SELL", "hash": "0c49b0cd46d55e5331f2007899683bdd3dc74249", "best_bid": "0.15", "best_ask": "0.19"}], "timestamp": "1769384873000", "event_type": "price_change"}}
{"_local_timestamp": "2026-01-25T23:47:53.081451+00:00", "data": {"market": "0x8fd23f0e974fc09874b21e86d16808f5c1da870813f580bc0bf73399fea51ca2", "price_changes": [{"asset_id": "85172525867787641402328444576848541622260332991892947577648996734803038861895", "price": "0.35", "size": "66.66", "side": "BUY", "hash": "c6a3b61468380a7b2fe5f73e288912fbc4050c50", "best_bid": "0.81", "best_ask": "0.85"}, {"asset_id": "56438265434513376454964845898456576437217725564238261372991430944084310725149", "price": "0.65", "size": "66.66", "side": "SELL", "hash": "0c49b0cd46d55e5331f2007899683bdd3dc74249", "best_bid": "0.15", "best_ask": "0.19"}], "timestamp": "1769384873000", "event_type": "price_change"}}
{"_local_timestamp": "2026-01-25T23:47:54.838225+00:00", "data": {"market": "0x6d16cc6bfc59787a24d6ea41cc49ad03f3a3a44e97aad02d7300cf906c812e53", "price_changes": [{"asset_id": "21134177830802910367859690071335268803233593888575931822119572207559990909766", "price": "0.28", "size": "10", "side": "BUY", "hash": "143c3828a0beb00c0485e90d58f962bb9c31cc69", "best_bid": "0.4", "best_ask": "0.84"}, {"asset_id": "60253373069171098683378509644885376353498749849701407276928730338318645499936", "price": "0.72", "size": "10", "side": "SELL", "hash": "c5658b9fe105b7ea966d38a0be752b2538b159e5", "best_bid": "0.16", "best_ask": "0.6"}], "timestamp": "1769384874769", "event_type": "price_change"}}
{"_local_timestamp": "2026-01-25T23:47:54.838823+00:00", "data": {"market": "0x9b9e5813bc0b5e21a177de5cb65121297730cdcef86d32aa8b20933067546427", "price_changes": [{"asset_id": "103745946677791198802043400205446626644210595777261132684909081924706209420680", "price": "0.41", "size": "0", "side": "BUY", "hash": "910e4eb4faa9d56c92d8c21328168c894b495b9e", "best_bid": "0.8", "best_ask": "0.97"}, {"asset_id": "15609421898876500890369688401103884738388846122594423961190213078422097015933", "price": "0.59", "size": "0", "side": "SELL", "hash": "bbfca7886481b8e53b20c57728145d9f29446b19", "best_bid": "0.03", "best_ask": "0.2"}], "timestamp": "1769384874769", "event_type": "price_change"}}
{"_local_timestamp": "2026-01-25T23:47:54.868715+00:00", "data": {"market": "0x9b9e5813bc0b5e21a177de5cb65121297730cdcef86d32aa8b20933067546427", "price_changes": [{"asset_id": "103745946677791198802043400205446626644210595777261132684909081924706209420680", "price": "0.4", "size": "216.66", "side": "BUY", "hash": "06e94219b29a7effe305679443d52906477cb39a", "best_bid": "0.8", "best_ask": "0.97"}, {"asset_id": "15609421898876500890369688401103884738388846122594423961190213078422097015933", "price": "0.6", "size": "216.66", "side": "SELL", "hash": "2124a62915a1a145086081154fa5ee70a606a9f7", "best_bid": "0.03", "best_ask": "0.2"}], "timestamp": "1769384874798", "event_type": "price_change"}}
{"_local_timestamp": "2026-01-25T23:47:54.870145+00:00", "data": {"market": "0x6d16cc6bfc59787a24d6ea41cc49ad03f3a3a44e97aad02d7300cf906c812e53", "price_changes": [{"asset_id": "21134177830802910367859690071335268803233593888575931822119572207559990909766", "price": "0.23", "size": "20", "side": "BUY", "hash": "ca373618aa7028e65e0e4793d2c7ba3c5282fcaf", "best_bid": "0.4", "best_ask": "0.84"}, {"asset_id": "60253373069171098683378509644885376353498749849701407276928730338318645499936", "price": "0.77", "size": "20", "side": "SELL", "hash": "1ce43e45398ff911000805141286eeeba3247e06", "best_bid": "0.16", "best_ask": "0.6"}], "timestamp": "1769384874798", "event_type": "price_change"}}
{"_local_timestamp": "2026-01-25T23:48:44.493032+00:00", "data": {"market": "0x7b9405ac2a18f553738708544a8bf8e56a2ce444f0cdced388a82219413f1e8b", "price_changes": [{"asset_id": "4705265403362581120736820785718797352184109151637378631828322862746823225674", "price": "0.02", "size": "60", "side": "BUY", "hash": "7264ba882171049aea0cab69dfd3735e0bc9174c", "best_bid": "0.06", "best_ask": "0.35"}, {"asset_id": "108462258986864408381729131013925572621223086163135850415272164030051791225397", "price": "0.98", "size": "60", "side": "SELL", "hash": "0ae38f2eea3c7123a41ef080e29ac287bbb71525", "best_bid": "0.65", "best_ask": "0.94"}], "timestamp": "1769384924421", "event_type": "price_change"}}
{"_local_timestamp": "2026-01-25T23:48:50.171591+00:00", "data": {"market": "0x6d16cc6bfc59787a24d6ea41cc49ad03f3a3a44e97aad02d7300cf906c812e53", "price_changes": [{"asset_id": "21134177830802910367859690071335268803233593888575931822119572207559990909766", "price": "0.28", "size": "0", "side": "BUY", "hash": "c3720b2a5e8a2fde96cf8ae070fd0f2e970aba6f", "best_bid": "0.4", "best_ask": "0.84"}, {"asset_id": "60253373069171098683378509644885376353498749849701407276928730338318645499936", "price": "0.72", "size": "0", "side": "SELL", "hash": "a1e120173446dcbc1c2234a7c1fc7d0d13e16b82", "best_bid": "0.16", "best_ask": "0.6"}], "timestamp": "1769384930101", "event_type": "price_change"}}
{"_local_timestamp": "2026-01-25T23:48:50.273113+00:00", "data": {"market": "0x6d16cc6bfc59787a24d6ea41cc49ad03f3a3a44e97aad02d7300cf906c812e53", "price_changes": [{"asset_id": "21134177830802910367859690071335268803233593888575931822119572207559990909766", "price": "0.24", "size": "10", "side": "BUY", "hash": "5324a0fd6ad6deb5e349e9b60233e54f1d74d3d4", "best_bid": "0.4", "best_ask": "0.84"}, {"asset_id": "60253373069171098683378509644885376353498749849701407276928730338318645499936", "price": "0.76", "size": "10", "side": "SELL", "hash": "a091f4c0b94e473afa67199140dcf3ca9ca5aeb5", "best_bid": "0.16", "best_ask": "0.6"}], "timestamp": "1769384930193", "event_type": "price_change"}}
{"_local_timestamp": "2026-01-25T23:48:54.915621+00:00", "data": {"market": "0x6d16cc6bfc59787a24d6ea41cc49ad03f3a3a44e97aad02d7300cf906c812e53", "price_changes": [{"asset_id": "21134177830802910367859690071335268803233593888575931822119572207559990909766", "price": "0.23", "size": "0", "side": "BUY", "hash": "d3bc3c5de1a4a5b891c32d144f5aae4155f4faf9", "best_bid": "0.4", "best_ask": "0.84"}, {"asset_id": "60253373069171098683378509644885376353498749849701407276928730338318645499936", "price": "0.77", "size": "0", "side": "SELL", "hash": "89d1424fa0a0e3c5b61ebe048e98317d3c6be9fe", "best_bid": "0.16", "best_ask": "0.6"}], "timestamp": "1769384934847", "event_type": "price_change"}}
{"_local_timestamp": "2026-01-25T23:48:54.939353+00:00", "data": {"market": "0x6d16cc6bfc59787a24d6ea41cc49ad03f3a3a44e97aad02d7300cf906c812e53", "price_changes": [{"asset_id": "21134177830802910367859690071335268803233593888575931822119572207559990909766", "price": "0.25", "size": "20", "side": "BUY", "hash": "75d0e4e0111a9746caeb0974d6091ce55b22dc65", "best_bid": "0.4", "best_ask": "0.84"}, {"asset_id": "60253373069171098683378509644885376353498749849701407276928730338318645499936", "price": "0.75", "size": "20", "side": "SELL", "hash": "7ce2febead17acaebaaa080e9aaf82ea67f16dde", "best_bid": "0.16", "best_ask": "0.6"}], "timestamp": "1769384934872", "event_type": "price_change"}}
{"_local_timestamp": "2026-01-25T23:49:27.388798+00:00", "data": {"market": "0x3f912d2e5965430f00f074e9b8fd9cdc7fb5948074c19b271720c8e620f2cb11", "price_changes": [{"asset_id": "90179144936207028478465214931375521788167296412041627475537095855791073500041", "price": "0.05", "size": "400", "side": "BUY", "hash": "6ce95cb5afc928c7fb8ffa90ff739e4f7945aa84", "best_bid": "0.4", "best_ask": "0.92"}, {"asset_id": "58342639934160101133354411315222065187144122136965451700208165731325515097740", "price": "0.95", "size": "400", "side": "SELL", "hash": "985236af1ed9109788b2a408df9c63c91c63de71", "best_bid": "0.08", "best_ask": "0.6"}], "timestamp": "1769384967318", "event_type": "price_change"}}
{"_local_timestamp": "2026-01-25T23:49:27.389729+00:00", "data": {"market": "0x3f912d2e5965430f00f074e9b8fd9cdc7fb5948074c19b271720c8e620f2cb11", "price_changes": [{"asset_id": "90179144936207028478465214931375521788167296412041627475537095855791073500041", "price": "0.09", "size": "22", "side": "BUY", "hash": "6ce95cb5afc928c7fb8ffa90ff739e4f7945aa84", "best_bid": "0.4", "best_ask": "0.92"}, {"asset_id": "58342639934160101133354411315222065187144122136965451700208165731325515097740", "price": "0.91", "size": "22", "side": "SELL", "hash": "985236af1ed9109788b2a408df9c63c91c63de71", "best_bid": "0.08", "best_ask": "0.6"}], "timestamp": "1769384967318", "event_type": "price_change"}}
{"_local_timestamp": "2026-01-25T23:49:27.390330+00:00", "data": {"market": "0x3f912d2e5965430f00f074e9b8fd9cdc7fb5948074c19b271720c8e620f2cb11", "price_changes": [{"asset_id": "90179144936207028478465214931375521788167296412041627475537095855791073500041", "price": "0.17", "size": "0", "side": "BUY", "hash": "6ce95cb5afc928c7fb8ffa90ff739e4f7945aa84", "best_bid": "0.4", "best_ask": "0.92"}, {"asset_id": "58342639934160101133354411315222065187144122136965451700208165731325515097740", "price": "0.83", "size": "0", "side": "SELL", "hash": "985236af1ed9109788b2a408df9c63c91c63de71", "best_bid": "0.08", "best_ask": "0.6"}], "timestamp": "1769384967318", "event_type": "price_change"}}
{"_local_timestamp": "2026-01-25T23:49:27.563470+00:00", "data": {"market": "0x3f912d2e5965430f00f074e9b8fd9cdc7fb5948074c19b271720c8e620f2cb11", "price_changes": [{"asset_id": "90179144936207028478465214931375521788167296412041627475537095855791073500041", "price": "0.12", "size": "10.67", "side": "BUY", "hash": "0ef9a8dcb8b940ece02546e580c5e71ab2f17ac9", "best_bid": "0.4", "best_ask": "0.92"}, {"asset_id": "58342639934160101133354411315222065187144122136965451700208165731325515097740", "price": "0.88", "size": "10.67", "side": "SELL", "hash": "d30bbc976afaa0547f9db0ce461d91cb4ae34ddf", "best_bid": "0.08", "best_ask": "0.6"}], "timestamp": "1769384967493", "event_type": "price_change"}}
{"_local_timestamp": "2026-01-25T23:49:27.567009+00:00", "data": {"market": "0x3f912d2e5965430f00f074e9b8fd9cdc7fb5948074c19b271720c8e620f2cb11", "price_changes": [{"asset_id": "90179144936207028478465214931375521788167296412041627475537095855791073500041", "price": "0.06", "size": "39.83", "side": "BUY", "hash": "a1a9845a113d97f95e53e443d8da537ee41fa86e", "best_bid": "0.4", "best_ask": "0.92"}, {"asset_id": "58342639934160101133354411315222065187144122136965451700208165731325515097740", "price": "0.94", "size": "39.83", "side": "SELL", "hash": "64e8714cae074f2a5536487b73383e0cd3267c45", "best_bid": "0.08", "best_ask": "0.6"}], "timestamp": "1769384967494", "event_type": "price_change"}}
{"_local_timestamp": "2026-01-25T23:49:30.154682+00:00", "data": {"market": "0x8fd23f0e974fc09874b21e86d16808f5c1da870813f580bc0bf73399fea51ca2", "price_changes": [{"asset_id": "85172525867787641402328444576848541622260332991892947577648996734803038861895", "price": "0.36", "size": "50", "side": "BUY", "hash": "088d0a6b18f552247fe523138609ef49235baf7c", "best_bid": "0.81", "best_ask": "0.85"}, {"asset_id": "56438265434513376454964845898456576437217725564238261372991430944084310725149", "price": "0.64", "size": "50", "side": "SELL", "hash": "e6320765f9841d53c6e6b5ea7f01a3d33a83e248", "best_bid": "0.15", "best_ask": "0.19"}], "timestamp": "1769384970025", "event_type": "price_change"}}
{"_local_timestamp": "2026-01-25T23:49:30.909491+00:00", "data": {"market": "0x8fd23f0e974fc09874b21e86d16808f5c1da870813f580bc0bf73399fea51ca2", "price_changes": [{"asset_id": "85172525867787641402328444576848541622260332991892947577648996734803038861895", "price": "0.37", "size": "222", "side": "BUY", "hash": "52d6cd1154759b1020b3d7ab40fe56033638075f", "best_bid": "0.81", "best_ask": "0.85"}, {"asset_id": "56438265434513376454964845898456576437217725564238261372991430944084310725149", "price": "0.63", "size": "222", "side": "SELL", "hash": "4c674ed12c4ca3dddbbfc296ef0b5aa14ea18602", "best_bid": "0.15", "best_ask": "0.19"}], "timestamp": "1769384970599", "event_type": "price_change"}}
{"_local_timestamp": "2026-01-25T23:49:39.437997+00:00", "data": {"market": "0x7b9405ac2a18f553738708544a8bf8e56a2ce444f0cdced388a82219413f1e8b", "price_changes": [{"asset_id": "4705265403362581120736820785718797352184109151637378631828322862746823225674", "price": "0.02", "size": "69.48", "side": "BUY", "hash": "c22da6591e1aa3418b634e635114c188b8a86247", "best_bid": "0.06", "best_ask": "0.35"}, {"asset_id": "108462258986864408381729131013925572621223086163135850415272164030051791225397", "price": "0.98", "size": "69.48", "side": "SELL", "hash": "2b10ca6c5a74ce481cfed33c72454477e6f949a7", "best_bid": "0.65", "best_ask": "0.94"}], "timestamp": "1769384979350", "event_type": "price_change"}}
{"_local_timestamp": "2026-01-25T23:49:39.439017+00:00", "data": {"market": "0x5f9ba531b74dd3d7be29f64741e5cad867f797da9aa73c348fd24f510ed2dfed", "price_changes": [{"asset_id": "29998772574245347891697050250557764189917474641475239534746438855989311925662", "price": "0.01", "size": "87.33", "side": "BUY", "hash": "a9495bb2f8337471596b4010fe0992c6e236479b", "best_bid": "0.05", "best_ask": "0.32"}, {"asset_id": "81414822130427608080886293296378652266575755903486095487302983244496524955033", "price": "0.99", "size": "87.33", "side": "SELL", "hash": "d6a9ec21bb3fd157c44ed0dd8752f60ea8eaff82", "best_bid": "0.68", "best_ask": "0.95"}], "timestamp": "1769384979354", "event_type": "price_change"}}
{"_local_timestamp": "2026-01-25T23:49:39.878797+00:00", "data": {"market": "0x5f9ba531b74dd3d7be29f64741e5cad867f797da9aa73c348fd24f510ed2dfed", "price_changes": [{"asset_id": "29998772574245347891697050250557764189917474641475239534746438855989311925662", "price": "0.01", "size": "120.66", "side": "BUY", "hash": "5b6f950caea1a84f89dc573b876d57b858a48588", "best_bid": "0.05", "best_ask": "0.32"}, {"asset_id": "81414822130427608080886293296378652266575755903486095487302983244496524955033", "price": "0.99", "size": "120.66", "side": "SELL", "hash": "78db34fb79fcfb073bad8d54186512bbf2cb9542", "best_bid": "0.68", "best_ask": "0.95"}], "timestamp": "1769384979807", "event_type": "price_change"}}
{"_local_timestamp": "2026-01-25T23:49:41.756259+00:00", "data": {"market": "0x8fd23f0e974fc09874b21e86d16808f5c1da870813f580bc0bf73399fea51ca2", "price_changes": [{"asset_id": "85172525867787641402328444576848541622260332991892947577648996734803038861895", "price": "0.36", "size": "0", "side": "BUY", "hash": "cd63842b48fb6f7580e41d4ac8b6098612dccfd6", "best_bid": "0.81", "best_ask": "0.85"}, {"asset_id": "56438265434513376454964845898456576437217725564238261372991430944084310725149", "price": "0.64", "size": "0", "side": "SELL", "hash": "74a67c3c60c0062a27dddaf7a4688320915ae500", "best_bid": "0.15", "best_ask": "0.19"}], "timestamp": "1769384981645", "event_type": "price_change"}}
{"_local_timestamp": "2026-01-25T23:49:42.408453+00:00", "data": {"market": "0x8fd23f0e974fc09874b21e86d16808f5c1da870813f580bc0bf73399fea51ca2", "price_changes": [{"asset_id": "85172525867787641402328444576848541622260332991892947577648996734803038861895", "price": "0.37", "size": "272", "side": "BUY", "hash": "bd8884b777ce71c22b23935de60b951f841512b5", "best_bid": "0.81", "best_ask": "0.85"}, {"asset_id": "56438265434513376454964845898456576437217725564238261372991430944084310725149", "price": "0.63", "size": "272", "side": "SELL", "hash": "dd86f783162bf9d62f8bb21844e9c6303be169f5", "best_bid": "0.15", "best_ask": "0.19"}], "timestamp": "1769384982226", "event_type": "price_change"}}
{"_local_timestamp": "2026-01-25T23:49:44.831764+00:00", "data": {"market": "0x7b9405ac2a18f553738708544a8bf8e56a2ce444f0cdced388a82219413f1e8b", "price_changes": [{"asset_id": "4705265403362581120736820785718797352184109151637378631828322862746823225674", "price": "0.02", "size": "60", "side": "BUY", "hash": "9034d5d834cdf0a8f9282c8e15cf2993c6ee04e0", "best_bid": "0.06", "best_ask": "0.35"}, {"asset_id": "108462258986864408381729131013925572621223086163135850415272164030051791225397", "price": "0.98", "size": "60", "side": "SELL", "hash": "b2dafc0a2d3894d9676415cb5247c0efa9a4d3ae", "best_bid": "0.65", "best_ask": "0.94"}], "timestamp": "1769384984761", "event_type": "price_change"}}
{"_local_timestamp": "2026-01-25T23:49:57.174285+00:00", "data": {"market": "0x6d16cc6bfc59787a24d6ea41cc49ad03f3a3a44e97aad02d7300cf906c812e53", "price_changes": [{"asset_id": "21134177830802910367859690071335268803233593888575931822119572207559990909766", "price": "0.24", "size": "0", "side": "BUY", "hash": "4d612a82317827ae59f625c25dc56ca6132c8a32", "best_bid": "0.4", "best_ask": "0.84"}, {"asset_id": "60253373069171098683378509644885376353498749849701407276928730338318645499936", "price": "0.76", "size": "0", "side": "SELL", "hash": "105217f3a668a412e0a2a308aefcff30be7678db", "best_bid": "0.16", "best_ask": "0.6"}], "timestamp": "1769384997085", "event_type": "price_change"}}
{"_local_timestamp": "2026-01-25T23:49:57.257251+00:00", "data": {"market": "0x6d16cc6bfc59787a24d6ea41cc49ad03f3a3a44e97aad02d7300cf906c812e53", "price_changes": [{"asset_id": "21134177830802910367859690071335268803233593888575931822119572207559990909766", "price": "0.26", "size": "10", "side": "BUY", "hash": "f157a38f10e742063852b3dd79b22c09045524f2", "best_bid": "0.4", "best_ask": "0.84"}, {"asset_id": "60253373069171098683378509644885376353498749849701407276928730338318645499936", "price": "0.74", "size": "10", "side": "SELL", "hash": "e6e91ea86c2caf6048f6408fd1a3b95999b09384", "best_bid": "0.16", "best_ask": "0.6"}], "timestamp": "1769384997176", "event_type": "price_change"}}
{"_local_timestamp": "2026-01-25T23:50:00.036780+00:00", "data": {"market": "0x6d16cc6bfc59787a24d6ea41cc49ad03f3a3a44e97aad02d7300cf906c812e53", "price_changes": [{"asset_id": "21134177830802910367859690071335268803233593888575931822119572207559990909766", "price": "0.25", "size": "0", "side": "BUY", "hash": "18e1926e371c6baf14bc82e3fff1c9fa95dc02f9", "best_bid": "0.4", "best_ask": "0.84"}, {"asset_id": "60253373069171098683378509644885376353498749849701407276928730338318645499936", "price": "0.75", "size": "0", "side": "SELL", "hash": "c11dd58de050a38c6d6252ef823bdd40ae6e25f8", "best_bid": "0.16", "best_ask": "0.6"}], "timestamp": "1769384999961", "event_type": "price_change"}}
{"_local_timestamp": "2026-01-25T23:50:00.059542+00:00", "data": {"market": "0x6d16cc6bfc59787a24d6ea41cc49ad03f3a3a44e97aad02d7300cf906c812e53", "price_changes": [{"asset_id": "21134177830802910367859690071335268803233593888575931822119572207559990909766", "price": "0.27", "size": "20", "side": "BUY", "hash": "530f6f81d7152c5a62f67db737ba5e9b755f58e4", "best_bid": "0.4", "best_ask": "0.84"}, {"asset_id": "60253373069171098683378509644885376353498749849701407276928730338318645499936", "price": "0.73", "size": "20", "side": "SELL", "hash": "771331bbf9d75bcba4d487a7e10f1a56c31ca219", "best_bid": "0.16", "best_ask": "0.6"}], "timestamp": "1769384999985", "event_type": "price_change"}}
{"_local_timestamp": "2026-01-25T23:50:00.229308+00:00", "data": {"market": "0x6d16cc6bfc59787a24d6ea41cc49ad03f3a3a44e97aad02d7300cf906c812e53", "price_changes": [{"asset_id": "21134177830802910367859690071335268803233593888575931822119572207559990909766", "price": "0.22", "size": "0", "side": "BUY", "hash": "3dffb439f8a747606ff0de22c9487045cd609ba2", "best_bid": "0.4", "best_ask": "0.84"}, {"asset_id": "60253373069171098683378509644885376353498749849701407276928730338318645499936", "price": "0.78", "size": "0", "side": "SELL", "hash": "9ff52fb32ccd609f9d80fdf53fb6d41916b067a0", "best_bid": "0.16", "best_ask": "0.6"}], "timestamp": "1769385000154", "event_type": "price_change"}}
{"_local_timestamp": "2026-01-25T23:50:00.230108+00:00", "data": {"market": "0x6d16cc6bfc59787a24d6ea41cc49ad03f3a3a44e97aad02d7300cf906c812e53", "price_changes": [{"asset_id": "21134177830802910367859690071335268803233593888575931822119572207559990909766", "price": "0.04", "size": "205.41", "side": "BUY", "hash": "3dffb439f8a747606ff0de22c9487045cd609ba2", "best_bid": "0.4", "best_ask": "0.84"}, {"asset_id": "60253373069171098683378509644885376353498749849701407276928730338318645499936", "price": "0.96", "size": "205.41", "side": "SELL", "hash": "9ff52fb32ccd609f9d80fdf53fb6d41916b067a0", "best_bid": "0.16", "best_ask": "0.6"}], "timestamp": "1769385000154", "event_type": "price_change"}}
{"_local_timestamp": "2026-01-25T23:50:00.230760+00:00", "data": {"market": "0x8fd23f0e974fc09874b21e86d16808f5c1da870813f580bc0bf73399fea51ca2", "price_changes": [{"asset_id": "85172525867787641402328444576848541622260332991892947577648996734803038861895", "price": "0.56", "size": "0", "side": "BUY", "hash": "23e2ec9cb8a5836e29b86e0427ec1d487a1f0fce", "best_bid": "0.81", "best_ask": "0.85"}, {"asset_id": "56438265434513376454964845898456576437217725564238261372991430944084310725149", "price": "0.44", "size": "0", "side": "SELL", "hash": "b0e436b1702ff58fb79141e1cd6338f43514949d", "best_bid": "0.15", "best_ask": "0.19"}], "timestamp": "1769385000154", "event_type": "price_change"}}
{"_local_timestamp": "2026-01-25T23:50:00.989821+00:00", "data": {"market": "0x6d16cc6bfc59787a24d6ea41cc49ad03f3a3a44e97aad02d7300cf906c812e53", "price_changes": [{"asset_id": "21134177830802910367859690071335268803233593888575931822119572207559990909766", "price": "0.24", "size": "100", "side": "BUY", "hash": "353878e46dedc2070fe50316c22af27a45d5a87b", "best_bid": "0.4", "best_ask": "0.84"}, {"asset_id": "60253373069171098683378509644885376353498749849701407276928730338318645499936", "price": "0.76", "size": "100", "side": "SELL", "hash": "5f13bbcd17d814872dba6f93fff082589463a31b", "best_bid": "0.16", "best_ask": "0.6"}], "timestamp": "1769385000909", "event_type": "price_change"}}
{"_local_timestamp": "2026-01-25T23:50:00.997529+00:00", "data": {"market": "0x6d16cc6bfc59787a24d6ea41cc49ad03f3a3a44e97aad02d7300cf906c812e53", "price_changes": [{"asset_id": "21134177830802910367859690071335268803233593888575931822119572207559990909766", "price": "0.08", "size": "100", "side": "BUY", "hash": "b9bcf9e367f743a5bbd9675a0e1a738ff2f0ac26", "best_bid": "0.4", "best_ask": "0.84"}, {"asset_id": "60253373069171098683378509644885376353498749849701407276928730338318645499936", "price": "0.92", "size": "100", "side": "SELL", "hash": "c833f4d1e9d7eb519ffe0bb627678476e04e0d60", "best_bid": "0.16", "best_ask": "0.6"}], "timestamp": "1769385000917", "event_type": "price_change"}}
{"_local_timestamp": "2026-01-25T23:50:01.156122+00:00", "data": {"market": "0x8fd23f0e974fc09874b21e86d16808f5c1da870813f580bc0bf73399fea51ca2", "price_changes": [{"asset_id": "85172525867787641402328444576848541622260332991892947577648996734803038861895", "price": "0.6", "size": "66.66", "side": "BUY", "hash": "c08f2484ee91d7fb4d260566964036057c425af2", "best_bid": "0.81", "best_ask": "0.85"}, {"asset_id": "56438265434513376454964845898456576437217725564238261372991430944084310725149", "price": "0.4", "size": "66.66", "side": "SELL", "hash": "62bc2d1d3687562dda9435d9bcb3c4fd56595e3a", "best_bid": "0.15", "best_ask": "0.19"}], "timestamp": "1769385001077", "event_type": "price_change"}}
{"_local_timestamp": "2026-01-25T23:50:02.594950+00:00", "data": {"market": "0x5f9ba531b74dd3d7be29f64741e5cad867f797da9aa73c348fd24f510ed2dfed", "price_changes": [{"asset_id": "81414822130427608080886293296378652266575755903486095487302983244496524955033", "price": "0.17", "size": "11", "side": "BUY", "hash": "057bcd1eaeeede46ae908a9163cf57f0a3c10a69", "best_bid": "0.68", "best_ask": "0.95"}, {"asset_id": "29998772574245347891697050250557764189917474641475239534746438855989311925662", "price": "0.83", "size": "11", "side": "SELL", "hash": "2d2d50de70371fa53c3382e636c62f3ff75119cc", "best_bid": "0.05", "best_ask": "0.32"}], "timestamp": "1769385002280", "event_type": "price_change"}}
{"_local_timestamp": "2026-01-25T23:50:03.173358+00:00", "data": {"market": "0x5f9ba531b74dd3d7be29f64741e5cad867f797da9aa73c348fd24f510ed2dfed", "price_changes": [{"asset_id": "81414822130427608080886293296378652266575755903486095487302983244496524955033", "price": "0.08", "size": "600", "side": "BUY", "hash": "13446e4b636128c8020a6693dad096e80034d9bd", "best_bid": "0.68", "best_ask": "0.95"}, {"asset_id": "29998772574245347891697050250557764189917474641475239534746438855989311925662", "price": "0.92", "size": "600", "side": "SELL", "hash": "eb8e832c4656990ed6ca35d722307711b9523311", "best_bid": "0.05", "best_ask": "0.32"}], "timestamp": "1769385002728", "event_type": "price_change"}}
{"_local_timestamp": "2026-01-25T23:50:18.750188+00:00", "data": {"market": "0x5f9ba531b74dd3d7be29f64741e5cad867f797da9aa73c348fd24f510ed2dfed", "price_changes": [{"asset_id": "81414822130427608080886293296378652266575755903486095487302983244496524955033", "price": "0.09", "size": "1776", "side": "BUY", "hash": "e2a033c613857ed0b61f1c6308918ab04c0d17ea", "best_bid": "0.68", "best_ask": "0.95"}, {"asset_id": "29998772574245347891697050250557764189917474641475239534746438855989311925662", "price": "0.91", "size": "1776", "side": "SELL", "hash": "cde5110fe0f74b66bcdec75175e5b3bb4bab3c54", "best_bid": "0.05", "best_ask": "0.32"}], "timestamp": "1769385018679", "event_type": "price_change"}}
{"_local_timestamp": "2026-01-25T23:50:29.296494+00:00", "data": {"market": "0x6d16cc6bfc59787a24d6ea41cc49ad03f3a3a44e97aad02d7300cf906c812e53", "price_changes": [{"asset_id": "21134177830802910367859690071335268803233593888575931822119572207559990909766", "price": "0.07", "size": "105.46", "side": "BUY", "hash": "b0a06df459d18390b8ab677f40757d9925608a7c", "best_bid": "0.4", "best_ask": "0.84"}, {"asset_id": "60253373069171098683378509644885376353498749849701407276928730338318645499936", "price": "0.93", "size": "105.46", "side": "SELL", "hash": "7808509558b392ea0b60939c590a9e1d6833dc1c", "best_bid": "0.16", "best_ask": "0.6"}], "timestamp": "1769385029209", "event_type": "price_change"}}
{"_local_timestamp": "2026-01-25T23:50:29.544833+00:00", "data": {"market": "0x6d16cc6bfc59787a24d6ea41cc49ad03f3a3a44e97aad02d7300cf906c812e53", "price_changes": [{"asset_id": "21134177830802910367859690071335268803233593888575931822119572207559990909766", "price": "0.08", "size": "200", "side": "BUY", "hash": "a6af8dc04f9a5e9bbbf3d85bd8f517d8ac288d56", "best_bid": "0.4", "best_ask": "0.84"}, {"asset_id": "60253373069171098683378509644885376353498749849701407276928730338318645499936", "price": "0.92", "size": "200", "side": "SELL", "hash": "31c6718fac1b23c0f763f6ff2e7e729de9cad67a", "best_bid": "0.16", "best_ask": "0.6"}], "timestamp": "1769385029469", "event_type": "price_change"}}
{"_local_timestamp": "2026-01-25T23:50:36.856449+00:00", "data": {"market": "0x3f912d2e5965430f00f074e9b8fd9cdc7fb5948074c19b271720c8e620f2cb11", "price_changes": [{"asset_id": "90179144936207028478465214931375521788167296412041627475537095855791073500041", "price": "0.24", "size": "158.33", "side": "BUY", "hash": "8b8a95068e74835e9f56762c2ef8dfee6c1fb7b1", "best_bid": "0.4", "best_ask": "0.92"}, {"asset_id": "58342639934160101133354411315222065187144122136965451700208165731325515097740", "price": "0.76", "size": "158.33", "side": "SELL", "hash": "de351d6e7ae4ba39fc251c824d03c88904759052", "best_bid": "0.08", "best_ask": "0.6"}], "timestamp": "1769385036784", "event_type": "price_change"}}
{"_local_timestamp": "2026-01-25T23:50:36.859020+00:00", "data": {"market": "0x3f912d2e5965430f00f074e9b8fd9cdc7fb5948074c19b271720c8e620f2cb11", "price_changes": [{"asset_id": "90179144936207028478465214931375521788167296412041627475537095855791073500041", "price": "0.23", "size": "99", "side": "BUY", "hash": "8f802955554b9a8577918f6c40287b97c8addad6", "best_bid": "0.4", "best_ask": "0.92"}, {"asset_id": "58342639934160101133354411315222065187144122136965451700208165731325515097740", "price": "0.77", "size": "99", "side": "SELL", "hash": "b076dc23b0142e42cf77ff4bafc516e120577297", "best_bid": "0.08", "best_ask": "0.6"}], "timestamp": "1769385036784", "event_type": "price_change"}}
{"_local_timestamp": "2026-01-25T23:50:42.202795+00:00", "data": {"market": "0x3f912d2e5965430f00f074e9b8fd9cdc7fb5948074c19b271720c8e620f2cb11", "price_changes": [{"asset_id": "90179144936207028478465214931375521788167296412041627475537095855791073500041", "price": "0.23", "size": "79", "side": "BUY", "hash": "c8568384e1f1844ae83137324679d5c808183a0f", "best_bid": "0.4", "best_ask": "0.92"}, {"asset_id": "58342639934160101133354411315222065187144122136965451700208165731325515097740", "price": "0.77", "size": "79", "side": "SELL", "hash": "6c6787505c1049b91344df83de8afee4c334738f", "best_bid": "0.08", "best_ask": "0.6"}], "timestamp": "1769385042126", "event_type": "price_change"}}
{"_local_timestamp": "2026-01-25T23:50:42.224408+00:00", "data": {"market": "0x3f912d2e5965430f00f074e9b8fd9cdc7fb5948074c19b271720c8e620f2cb11", "price_changes": [{"asset_id": "90179144936207028478465214931375521788167296412041627475537095855791073500041", "price": "0.25", "size": "20", "side": "BUY", "hash": "4516b503ed2ab178411e35d074e860b23754c120", "best_bid": "0.4", "best_ask": "0.92"}, {"asset_id": "58342639934160101133354411315222065187144122136965451700208165731325515097740", "price": "0.75", "size": "20", "side": "SELL", "hash": "01b95b1e69992f33cdae958d89a2c53c2eea0384", "best_bid": "0.08", "best_ask": "0.6"}], "timestamp": "1769385042153", "event_type": "price_change"}}
{"_local_timestamp": "2026-01-25T23:50:50.239229+00:00", "data": {"market": "0x5f9ba531b74dd3d7be29f64741e5cad867f797da9aa73c348fd24f510ed2dfed", "price_changes": [{"asset_id": "81414822130427608080886293296378652266575755903486095487302983244496524955033", "price": "0.08", "size": "500", "side": "BUY", "hash": "520a365c8f48d5658f0c504fc77a8c1eb8208d27", "best_bid": "0.68", "best_ask": "0.95"}, {"asset_id": "29998772574245347891697050250557764189917474641475239534746438855989311925662", "price": "0.92", "size": "500", "side": "SELL", "hash": "8cef9e8c7a46bc94c93b5418ecece2c57c6d5c16", "best_bid": "0.05", "best_ask": "0.32"}], "timestamp": "1769385050168", "event_type": "price_change"}}
{"_local_timestamp": "2026-01-25T23:50:50.340381+00:00", "data": {"market": "0x3f912d2e5965430f00f074e9b8fd9cdc7fb5948074c19b271720c8e620f2cb11", "price_changes": [{"asset_id": "90179144936207028478465214931375521788167296412041627475537095855791073500041", "price": "0.24", "size": "0", "side": "BUY", "hash": "84c8ac16879a9ab2b4c123d985dea4386c2650ef", "best_bid": "0.4", "best_ask": "0.92"}, {"asset_id": "58342639934160101133354411315222065187144122136965451700208165731325515097740", "price": "0.76", "size": "0", "side": "SELL", "hash": "f638d8383ff55293bb6965c774a596fa11f8aa46", "best_bid": "0.08", "best_ask": "0.6"}], "timestamp": "1769385050255", "event_type": "price_change"}}
{"_local_timestamp": "2026-01-25T23:50:50.512814+00:00", "data": {"market": "0x5f9ba531b74dd3d7be29f64741e5cad867f797da9aa73c348fd24f510ed2dfed", "price_changes": [{"asset_id": "81414822130427608080886293296378652266575755903486095487302983244496524955033", "price": "0.09", "size": "1876", "side": "BUY", "hash": "c527b75cf7d771c7842ffba4255e7d0957e44a34", "best_bid": "0.68", "best_ask": "0.95"}, {"asset_id": "29998772574245347891697050250557764189917474641475239534746438855989311925662", "price": "0.91", "size": "1876", "side": "SELL", "hash": "724c52818ca032bf5b6b2461141ac5490b430bb7", "best_bid": "0.05", "best_ask": "0.32"}], "timestamp": "1769385050436", "event_type": "price_change"}}
{"_local_timestamp": "2026-01-25T23:50:52.250662+00:00", "data": {"market": "0x3f912d2e5965430f00f074e9b8fd9cdc7fb5948074c19b271720c8e620f2cb11", "price_changes": [{"asset_id": "90179144936207028478465214931375521788167296412041627475537095855791073500041", "price": "0.25", "size": "0", "side": "BUY", "hash": "f9248e58bee317d3582891b88b48d27f525ef2ee", "best_bid": "0.4", "best_ask": "0.92"}, {"asset_id": "58342639934160101133354411315222065187144122136965451700208165731325515097740", "price": "0.75", "size": "0", "side": "SELL", "hash": "de6c44cebc96bc173228b816e84aadec324ecfe0", "best_bid": "0.08", "best_ask": "0.6"}], "timestamp": "1769385052179", "event_type": "price_change"}}
{"_local_timestamp": "2026-01-25T23:50:52.286847+00:00", "data": {"market": "0x3f912d2e5965430f00f074e9b8fd9cdc7fb5948074c19b271720c8e620f2cb11", "price_changes": [{"asset_id": "90179144936207028478465214931375521788167296412041627475537095855791073500041", "price": "0.24", "size": "20", "side": "BUY", "hash": "d28973cee99ef0da22e6991d98998bd4411c6e5a", "best_bid": "0.4", "best_ask": "0.92"}, {"asset_id": "58342639934160101133354411315222065187144122136965451700208165731325515097740", "price": "0.76", "size": "20", "side": "SELL", "hash": "f5427da44e9e236424937727d6ac6de13947b294", "best_bid": "0.08", "best_ask": "0.6"}], "timestamp": "1769385052211", "event_type": "price_change"}}
{"_local_timestamp": "2026-01-25T23:50:59.379534+00:00", "data": {"market": "0x3f912d2e5965430f00f074e9b8fd9cdc7fb5948074c19b271720c8e620f2cb11", "price_changes": [{"asset_id": "90179144936207028478465214931375521788167296412041627475537095855791073500041", "price": "0.23", "size": "0", "side": "BUY", "hash": "723cc74ca8754dd2947d62478259853cd5e449e5", "best_bid": "0.4", "best_ask": "0.92"}, {"asset_id": "58342639934160101133354411315222065187144122136965451700208165731325515097740", "price": "0.77", "size": "0", "side": "SELL", "hash": "7180d6d3a3fad5571286ab82a1e63eac88080963", "best_bid": "0.08", "best_ask": "0.6"}], "timestamp": "1769385059311", "event_type": "price_change"}}
{"_local_timestamp": "2026-01-25T23:51:00.890021+00:00", "data": {"market": "0x6d16cc6bfc59787a24d6ea41cc49ad03f3a3a44e97aad02d7300cf906c812e53", "price_changes": [{"asset_id": "21134177830802910367859690071335268803233593888575931822119572207559990909766", "price": "0.26", "size": "0", "side": "BUY", "hash": "1205a426d70bc2cee8a27af569fcb3a0c0c72c8e", "best_bid": "0.4", "best_ask": "0.84"}, {"asset_id": "60253373069171098683378509644885376353498749849701407276928730338318645499936", "price": "0.74", "size": "0", "side": "SELL", "hash": "fb60ced1d6ea8a2d51f40420828baf1372450c4d", "best_bid": "0.16", "best_ask": "0.6"}], "timestamp": "1769385060825", "event_type": "price_change"}}
{"_local_timestamp": "2026-01-25T23:51:00.986894+00:00", "data": {"market": "0x6d16cc6bfc59787a24d6ea41cc49ad03f3a3a44e97aad02d7300cf906c812e53", "price_changes": [{"asset_id": "21134177830802910367859690071335268803233593888575931822119572207559990909766", "price": "0.28", "size": "10", "side": "BUY", "hash": "e56e0fbc0d2034e8a740298d7d2d28241840d93b", "best_bid": "0.4", "best_ask": "0.84"}, {"asset_id": "60253373069171098683378509644885376353498749849701407276928730338318645499936", "price": "0.72", "size": "10", "side": "SELL", "hash": "3101c215a652a3a5108d1a176a9f298fbf0bb4fe", "best_bid": "0.16", "best_ask": "0.6"}], "timestamp": "1769385060920", "event_type": "price_change"}}
{"_local_timestamp": "2026-01-25T23:51:03.235977+00:00", "data": {"market": "0x6d16cc6bfc59787a24d6ea41cc49ad03f3a3a44e97aad02d7300cf906c812e53", "price_changes": [{"asset_id": "21134177830802910367859690071335268803233593888575931822119572207559990909766", "price": "0.27", "size": "0", "side": "BUY", "hash": "4c75fc599ab1ecee4d16789dea6aab55f1f7ffda", "best_bid": "0.4", "best_ask": "0.84"}, {"asset_id": "60253373069171098683378509644885376353498749849701407276928730338318645499936", "price": "0.73", "size": "0", "side": "SELL", "hash": "84c5bed3324386b6957c00e875c5034d40a6c3b8", "best_bid": "0.16", "best_ask": "0.6"}], "timestamp": "1769385063157", "event_type": "price_change"}}
{"_local_timestamp": "2026-01-25T23:51:03.240152+00:00", "data": {"market": "0x3f912d2e5965430f00f074e9b8fd9cdc7fb5948074c19b271720c8e620f2cb11", "price_changes": [{"asset_id": "90179144936207028478465214931375521788167296412041627475537095855791073500041", "price": "0.24", "size": "0", "side": "BUY", "hash": "d91c606b4b4aeef93dc059024eca3640d1b0359b", "best_bid": "0.4", "best_ask": "0.92"}, {"asset_id": "58342639934160101133354411315222065187144122136965451700208165731325515097740", "price": "0.76", "size": "0", "side": "SELL", "hash": "8322886103fd55f2d7cab74064b63ececb0a7969", "best_bid": "0.08", "best_ask": "0.6"}], "timestamp": "1769385063157", "event_type": "price_change"}}
{"_local_timestamp": "2026-01-25T23:51:03.262779+00:00", "data": {"market": "0x6d16cc6bfc59787a24d6ea41cc49ad03f3a3a44e97aad02d7300cf906c812e53", "price_changes": [{"asset_id": "21134177830802910367859690071335268803233593888575931822119572207559990909766", "price": "0.25", "size": "20", "side": "BUY", "hash": "986b7c50fdb4c52c88778ca779e7f63ed7e68fac", "best_bid": "0.4", "best_ask": "0.84"}, {"asset_id": "60253373069171098683378509644885376353498749849701407276928730338318645499936", "price": "0.75", "size": "20", "side": "SELL", "hash": "7abe8649fd4177154b4a7a78c672e65379b62dee", "best_bid": "0.16", "best_ask": "0.6"}], "timestamp": "1769385063184", "event_type": "price_change"}}
{"_local_timestamp": "2026-01-25T23:51:03.263502+00:00", "data": {"market": "0x3f912d2e5965430f00f074e9b8fd9cdc7fb5948074c19b271720c8e620f2cb11", "price_changes": [{"asset_id": "90179144936207028478465214931375521788167296412041627475537095855791073500041", "price": "0.23", "size": "20", "side": "BUY", "hash": "56b4b5263109d986e56d43f318d6453b795a3852", "best_bid": "0.4", "best_ask": "0.92"}, {"asset_id": "58342639934160101133354411315222065187144122136965451700208165731325515097740", "price": "0.77", "size": "20", "side": "SELL", "hash": "f1f313ebdd3f0990e3999a13d3be6b8bfce8c97a", "best_bid": "0.08", "best_ask": "0.6"}], "timestamp": "1769385063184", "event_type": "price_change"}}
