{"_local_timestamp": "2026-01-25T23:33:25.980268+00:00", "data": [{"market": "0x5fd14ce22f2d4c332bae5d9e56971eeb44570b6ec0aaede6c71bc08ee22aae84", "asset_id": "74859528307279738324579355645582848708259059823655254205378377992189727361464", "timestamp": "1769383621870", "hash": "d5e86f6e99e5ccc3bf7a87e3d3c54f2eaf23d31c", "bids": [{"price": "0.001", "size": "7340.51"}, {"price": "0.002", "size": "3750"}, {"price": "0.003", "size": "1406.96"}, {"price": "0.006", "size": "200"}, {"price": "0.007", "size": "10.24"}, {"price": "0.01", "size": "10500"}, {"price": "0.02", "size": "4700"}, {"price": "0.021", "size": "9.2"}, {"price": "0.04", "size": "1250"}, {"price": "0.05", "size": "30"}, {"price": "0.051", "size": "39"}, {"price": "0.06", "size": "500"}, {"price": "0.061", "size": "9.15"}, {"price": "0.1", "size": "2450"}, {"price": "0.15", "size": "1276.66"}, {"price": "0.2", "size": "1060"}, {"price": "0.201", "size": "5.69"}, {"price": "0.25", "size": "912"}, {"price": "0.3", "size": "186.66"}, {"price": "0.301", "size": "93"}, {"price": "0.34", "size": "50"}, {"price": "0.35", "size": "68.57"}, {"price": "0.4", "size": "50"}, {"price": "0.438", "size": "5"}, {"price": "0.442", "size": "286"}, {"price": "0.443", "size": "10"}, {"price": "0.823", "size": "17"}, {"price": "0.824", "size": "20"}, {"price": "0.94", "size": "5"}, {"price": "0.941", "size": "146.07"}, {"price": "0.942", "size": "13.71"}, {"price": "0.947", "size": "116.47"}, {"price": "0.995", "size": "10"}, {"price": "0.996", "size": "12.31"}, {"price": "0.997", "size": "28.68"}], "asks": [{"price": "0.999", "size": "42709.47"}, {"price": "0.998", "size": "4270.95"}], "event_type": "book", "last_trade_price": "0.002"}, {"market": "0xbd8114a52eed432265735ebfe174ce257047a94b378cbc36246ca0dba7a07c33", "asset_id": "113403179930780844692419404105573805354679366394847558149476632392300380613010", "timestamp": "1769383739343", "hash": "050739ea369c42e1423a192f08a1055988d5cfd7", "bids": [{"price": "0.001", "size": "28818"}, {"price": "0.002", "size": "4915"}, {"price": "0.003", "size": "5"}, {"price": "0.004", "size": "491.8"}], "asks": [{"price": "0.999", "size": "7608.3"}, {"price": "0.998", "size": "3750"}, {"price": "0.997", "size": "1406.96"}, {"price": "0.994", "size": "200"}, {"price": "0.993", "size": "10.25"}, {"price": "0.99", "size": "10500"}, {"price": "0.98", "size": "4700"}, {"price": "0.979", "size": "9.2"}, {"price": "0.96", "size": "1250"}, {"price": "0.95", "size": "30"}, {"price": "0.949", "size": "39"}, {"price": "0.94", "size": "500"}, {"price": "0.939", "size": "9.15"}, {"price": "0.9", "size": "2410"}, {"price": "0.85", "size": "1276.66"}, {"price": "0.8", "size": "810"}, {"price": "0.799", "size": "5.69"}, {"price": "0.75", "size": "762"}, {"price": "0.749", "size": "66.45"}, {"price": "0.7", "size": "186.66"}, {"price": "0.66", "size": "50"}, {"price": "0.65", "size": "68.57"}, {"price": "0.6", "size": "50"}, {"price": "0.578", "size": "5"}, {"price": "0.576", "size": "235"}, {"price": "0.574", "size": "62"}, {"price": "0.09", "size": "5"}, {"price": "0.089", "size": "10"}, {"price": "0.088", "size": "20"}, {"price": "0.01", "size": "119.98"}, {"price": "0.008", "size": "11.33"}, {"price": "0.005", "size": "7"}], "event_type": "book", "last_trade_price": "0.004"}, {"market": "0xbf2cba044810364349878bce032b495875a0ae8b575286388e79cc4bddde4a6c", "asset_id": "80303106904766949344727438756563505749348738369775655357626215899018784021389", "timestamp": "1769383921451", "hash": "eb0c53ce7c7505454fd311dbac561260c503351b", "bids": [{"price": "0.001", "size": "33415"}, {"price": "0.002", "size": "1055.73"}], "asks": [{"price": "0.999", "size": "7344.51"}, {"price": "0.998", "size": "3250"}, {"price": "0.997", "size": "1406.96"}, {"price": "0.994", "size": "200"}, {"price": "0.993", "size": "10.24"}, {"price": "0.99", "size": "10500"}, {"price": "0.98", "size": "4700"}, {"price": "0.979", "size": "9.2"}, {"price": "0.96", "size": "1250"}, {"price": "0.95", "size": "30"}, {"price": "0.949", "size": "39"}, {"price": "0.94", "size": "500"}, {"price": "0.939", "size": "9.15"}, {"price": "0.9", "size": "2110"}, {"price": "0.85", "size": "1276.66"}, {"price": "0.8", "size": "1160"}, {"price": "0.799", "size": "5.69"}, {"price": "0.777", "size": "20"}, {"price": "0.75", "size": "862"}, {"price": "0.749", "size": "179.76"}, {"price": "0.7", "size": "186.66"}, {"price": "0.699", "size": "93"}, {"price": "0.66", "size": "50"}, {"price": "0.65", "size": "68.57"}, {"price": "0.6", "size": "50"}, {"price": "0.547", "size": "5"}, {"price": "0.546", "size": "10"}, {"price": "0.545", "size": "294"}, {"price": "0.09", "size": "5"}, {"price": "0.089", "size": "42.25"}, {"price": "0.087", "size": "10"}, {"price": "0.086", "size": "20"}, {"price": "0.049", "size": "5"}, {"price": "0.048", "size": "159.09"}, {"price": "0.01", "size": "5"}, {"price": "0.005", "size": "86"}, {"price": "0.004", "size": "25"}, {"price": "0.003", "size": "13.31"}], "event_type": "book", "last_trade_price": "0.002"}, {"market": "0xdade564249db4b9daad8e06c21e06e2760c7c640b2be1c7016baa48bbfef83d9", "asset_id": "54806808255046819356872422328886643818584171246276253781026782874036677222460", "timestamp": "1769383945541", "hash": "4894d25e80912ca1fde0ba3df14d656defc605ba", "bids": [{"price": "0.01", "size": "6506.1"}, {"price": "0.02", "size": "2511.53"}, {"price": "0.03", "size": "2160.81"}, {"price": "0.04", "size": "1255.61"}, {"price": "0.05", "size": "930"}, {"price": "0.06", "size": "7.01"}, {"price": "0.07", "size": "528.74"}, {"price": "0.09", "size": "155"}, {"price": "0.1", "size": "46.63"}, {"price": "0.14", "size": "44.74"}, {"price": "0.15", "size": "20"}, {"price": "0.16", "size": "6"}, {"price": "0.18", "size": "8"}, {"price": "0.19", "size": "20"}, {"price": "0.2", "size": "13"}], "asks": [{"price": "0.99", "size": "5500"}, {"price": "0.98", "size": "2200"}, {"price": "0.97", "size": "7.4"}, {"price": "0.92", "size": "1250"}, {"price": "0.88", "size": "883.33"}, {"price": "0.83", "size": "188.23"}, {"price": "0.8", "size": "400"}, {"price": "0.79", "size": "433.33"}, {"price": "0.78", "size": "216"}, {"price": "0.75", "size": "104"}, {"price": "0.71", "size": "182.75"}, {"price": "0.7", "size": "6"}, {"price": "0.67", "size": "60.6"}, {"price": "0.66", "size": "125"}, {"price": "0.65", "size": "6"}, {"price": "0.4", "size": "5"}, {"price": "0.38", "size": "506"}, {"price": "0.37", "size": "66.66"}, {"price": "0.36", "size": "6"}, {"price": "0.31", "size": "66.66"}, {"price": "0.25", "size": "140.66"}], "event_type": "book", "last_trade_price": "0.240"}, {"market": "0x237e02f976b2e3da26581188ac589dc2fc205fe720e8fada962fc6df2cd2eba6", "asset_id": "31822061374462131695517583398967119857496606423169716082969971946507327592886", "timestamp": "1769383921241", "hash": "ee83531db45a5d5b390dd9964537cf78d932ce3b", "bids": [{"price": "0.001", "size": "7279.51"}, {"price": "0.002", "size": "3750"}, {"price": "0.003", "size": "1406.96"}, {"price": "0.006", "size": "200"}, {"price": "0.007", "size": "10.24"}, {"price": "0.01", "size": "10500"}, {"price": "0.02", "size": "4700"}, {"price": "0.021", "size": "9.2"}, {"price": "0.04", "size": "1250"}, {"price": "0.05", "size": "30"}, {"price": "0.051", "size": "39"}, {"price": "0.06", "size": "500"}, {"price": "0.061", "size": "9.15"}, {"price": "0.1", "size": "2449.99"}, {"price": "0.15", "size": "1276.66"}, {"price": "0.2", "size": "1060"}, {"price": "0.201", "size": "5.69"}, {"price": "0.25", "size": "912"}, {"price": "0.3", "size": "186.66"}, {"price": "0.34", "size": "50"}, {"price": "0.35", "size": "68.57"}, {"price": "0.4", "size": "50"}, {"price": "0.414", "size": "241"}, {"price": "0.419", "size": "125"}, {"price": "0.476", "size": "5"}, {"price": "0.481", "size": "10"}, {"price": "0.482", "size": "20"}, {"price": "0.94", "size": "5"}, {"price": "0.988", "size": "18.67"}, {"price": "0.995", "size": "88"}, {"price": "0.996", "size": "111.54"}, {"price": "0.997", "size": "17.97"}], "asks": [{"price": "0.999", "size": "43219.88"}, {"price": "0.998", "size": "1712.68"}], "event_type": "book", "last_trade_price": "0.002"}, {"market": "0xb86618f0e3e26d16e5abd848af319dd750dba3271684a2912268bb917a8f9953", "asset_id": "64643056846481598756416775559569443451634829574992414360993839787798978191969", "timestamp": "1769383906131", "hash": "c3f23bf155f403c495aa2d47c0df4437e53f56ad", "bids": [{"price": "0.01", "size": "12010.37"}, {"price": "0.02", "size": "4700"}, {"price": "0.03", "size": "9.49"}, {"price": "0.04", "size": "1250"}, {"price": "0.05", "size": "30"}, {"price": "0.08", "size": "750"}, {"price": "0.09", "size": "5.58"}, {"price": "0.1", "size": "2050"}, {"price": "0.13", "size": "261.53"}, {"price": "0.15", "size": "1050"}, {"price": "0.17", "size": "588.23"}, {"price": "0.21", "size": "668.33"}, {"price": "0.22", "size": "222.04"}, {"price": "0.26", "size": "150"}, {"price": "0.27", "size": "50"}, {"price": "0.3", "size": "80"}, {"price": "0.34", "size": "253.82"}, {"price": "0.36", "size": "5"}, {"price": "0.68", "size": "226.47"}, {"price": "0.69", "size": "309.1"}, {"price": "0.7", "size": "200"}, {"price": "0.71", "size": "200"}, {"price": "0.72", "size": "200"}, {"price": "0.73", "size": "225.53"}, {"price": "0.74", "size": "20"}, {"price": "0.75", "size": "40"}, {"price": "0.76", "size": "20"}, {"price": "0.78", "size": "25.53"}, {"price": "0.8", "size": "21.4"}, {"price": "0.81", "size": "52"}, {"price": "0.82", "size": "50.77"}, {"price": "0.83", "size": "25.53"}], "asks": [{"price": "0.95", "size": "1100"}, {"price": "0.94", "size": "350"}, {"price": "0.9", "size": "10"}, {"price": "0.89", "size": "100"}, {"price": "0.88", "size": "10"}, {"price": "0.87", "size": "67.69"}, {"price": "0.84", "size": "15"}], "event_type": "book", "last_trade_price": "0.140"}, {"market": "0xbf2cba044810364349878bce032b495875a0ae8b575286388e79cc4bddde4a6c", "asset_id": "52973946067415555340752362838729163232972184824595142980403702383146397821473", "timestamp": "1769383921451", "hash": "6c78cd9ab76e8fd38985dbe1d7bf6405b3750582", "bids": [{"price": "0.001", "size": "7344.51"}, {"price": "0.002", "size": "3250"}, {"price": "0.003", "size": "1406.96"}, {"price": "0.006", "size": "200"}, {"price": "0.007", "size": "10.24"}, {"price": "0.01", "size": "10500"}, {"price": "0.02", "size": "4700"}, {"price": "0.021", "size": "9.2"}, {"price": "0.04", "size": "1250"}, {"price": "0.05", "size": "30"}, {"price": "0.051", "size": "39"}, {"price": "0.06", "size": "500"}, {"price": "0.061", "size": "9.15"}, {"price": "0.1", "size": "2110"}, {"price": "0.15", "size": "1276.66"}, {"price": "0.2", "size": "1160"}, {"price": "0.201", "size": "5.69"}, {"price": "0.223", "size": "20"}, {"price": "0.25", "size": "862"}, {"price": "0.251", "size": "179.76"}, {"price": "0.3", "size": "186.66"}, {"price": "0.301", "size": "93"}, {"price": "0.34", "size": "50"}, {"price": "0.35", "size": "68.57"}, {"price": "0.4", "size": "50"}, {"price": "0.453", "size": "5"}, {"price": "0.454", "size": "10"}, {"price": "0.455", "size": "294"}, {"price": "0.91", "size": "5"}, {"price": "0.911", "size": "42.25"}, {"price": "0.913", "size": "10"}, {"price": "0.914", "size": "20"}, {"price": "0.951", "size": "5"}, {"price": "0.952", "size": "159.09"}, {"price": "0.99", "size": "5"}, {"price": "0.995", "size": "86"}, {"price": "0.996", "size": "25"}, {"price": "0.997", "size": "13.31"}], "asks": [{"price": "0.999", "size": "33415"}, {"price": "0.998", "size": "1055.73"}], "event_type": "book", "last_trade_price": "0.002"}, {"market": "0x237e02f976b2e3da26581188ac589dc2fc205fe720e8fada962fc6df2cd2eba6", "asset_id": "79715101438926538809511303806850682615698911910840134983914648955752864757858", "timestamp": "1769383921241", "hash": "ed01a8a01c430c1af63f4b8ab378dd60625e6745", "bids": [{"price": "0.001", "size": "43219.88"}, {"price": "0.002", "size": "1712.68"}], "asks": [{"price": "0.999", "size": "7279.51"}, {"price": "0.998", "size": "3750"}, {"price": "0.997", "size": "1406.96"}, {"price": "0.994", "size": "200"}, {"price": "0.993", "size": "10.24"}, {"price": "0.99", "size": "10500"}, {"price": "0.98", "size": "4700"}, {"price": "0.979", "size": "9.2"}, {"price": "0.96", "size": "1250"}, {"price": "0.95", "size": "30"}, {"price": "0.949", "size": "39"}, {"price": "0.94", "size": "500"}, {"price": "0.939", "size": "9.15"}, {"price": "0.9", "size": "2449.99"}, {"price": "0.85", "size": "1276.66"}, {"price": "0.8", "size": "1060"}, {"price": "0.799", "size": "5.69"}, {"price": "0.75", "size": "912"}, {"price": "0.7", "size": "186.66"}, {"price": "0.66", "size": "50"}, {"price": "0.65", "size": "68.57"}, {"price": "0.6", "size": "50"}, {"price": "0.586", "size": "241"}, {"price": "0.581", "size": "125"}, {"price": "0.524", "size": "5"}, {"price": "0.519", "size": "10"}, {"price": "0.518", "size": "20"}, {"price": "0.06", "size": "5"}, {"price": "0.012", "size": "18.67"}, {"price": "0.005", "size": "88"}, {"price": "0.004", "size": "111.54"}, {"price": "0.003", "size": "17.97"}], "event_type": "book", "last_trade_price": "0.002"}, {"market": "0xbd8114a52eed432265735ebfe174ce257047a94b378cbc36246ca0dba7a07c33", "asset_id": "34347535308090847792552379030322073016871399676099560255182105326984970187327", "timestamp": "1769383739343", "hash": "debf8098cc32ab7132a9a00ef5b8ce09f8289a2c", "bids": [{"price": "0.001", "size": "7608.3"}, {"price": "0.002", "size": "3750"}, {"price": "0.003", "size": "1406.96"}, {"price": "0.006", "size": "200"}, {"price": "0.007", "size": "10.25"}, {"price": "0.01", "size": "10500"}, {"price": "0.02", "size": "4700"}, {"price": "0.021", "size": "9.2"}, {"price": "0.04", "size": "1250"}, {"price": "0.05", "size": "30"}, {"price": "0.051", "size": "39"}, {"price": "0.06", "size": "500"}, {"price": "0.061", "size": "9.15"}, {"price": "0.1", "size": "2410"}, {"price": "0.15", "size": "1276.66"}, {"price": "0.2", "size": "810"}, {"price": "0.201", "size": "5.69"}, {"price": "0.25", "size": "762"}, {"price": "0.251", "size": "66.45"}, {"price": "0.3", "size": "186.66"}, {"price": "0.34", "size": "50"}, {"price": "0.35", "size": "68.57"}, {"price": "0.4", "size": "50"}, {"price": "0.422", "size": "5"}, {"price": "0.424", "size": "235"}, {"price": "0.426", "size": "62"}, {"price": "0.91", "size": "5"}, {"price": "0.911", "size": "10"}, {"price": "0.912", "size": "20"}, {"price": "0.99", "size": "119.98"}, {"price": "0.992", "size": "11.33"}, {"price": "0.995", "size": "7"}], "asks": [{"price": "0.999", "size": "28818"}, {"price": "0.998", "size": "4915"}, {"price": "0.997", "size": "5"}, {"price": "0.996", "size": "491.8"}], "event_type": "book", "last_trade_price": "0.004"}, {"market": "0x9ae2d920fa7f4da49b6524361fa2e7260cad95631cc8e443ddeb2d70d2f1ccfd", "asset_id": "113409560089971005551069019900801779309141794188263770657345157175671976775527", "timestamp": "1769383921244", "hash": "ab7c0193128115a8b5bff3036a187ed751174761", "bids": [{"price": "0.001", "size": "41191.28"}, {"price": "0.002", "size": "4219.82"}], "asks": [{"price": "0.999", "size": "7341.51"}, {"price": "0.998", "size": "2750"}, {"price": "0.997", "size": "1406.96"}, {"price": "0.994", "size": "200"}, {"price": "0.993", "size": "10.24"}, {"price": "0.99", "size": "10500"}, {"price": "0.98", "size": "4700"}, {"price": "0.979", "size": "9.2"}, {"price": "0.96", "size": "1250"}, {"price": "0.95", "size": "30"}, {"price": "0.949", "size": "39"}, {"price": "0.94", "size": "500"}, {"price": "0.939", "size": "9.15"}, {"price": "0.9", "size": "2449.99"}, {"price": "0.85", "size": "1276.66"}, {"price": "0.8", "size": "1060"}, {"price": "0.799", "size": "5.69"}, {"price": "0.75", "size": "912"}, {"price": "0.7", "size": "186.66"}, {"price": "0.66", "size": "50"}, {"price": "0.65", "size": "68.57"}, {"price": "0.6", "size": "50"}, {"price": "0.55", "size": "5"}, {"price": "0.546", "size": "220"}, {"price": "0.545", "size": "276"}, {"price": "0.149", "size": "5"}, {"price": "0.136", "size": "10"}, {"price": "0.135", "size": "20"}, {"price": "0.013", "size": "30"}, {"price": "0.005", "size": "121.22"}, {"price": "0.004", "size": "96.72"}, {"price": "0.003", "size": "17"}], "event_type": "book", "last_trade_price": "0.002"}, {"market": "0xbecfcab892fc16aabf72d5180094c6c51ba33ac8005c3f9497b7c6d05bbee7f1", "asset_id": "98146342803923051979042568419031220153888306546081565583042852359988504135784", "timestamp": "1769383901914", "hash": "ea9bb3b2d1b9c4b969233ec8f3ebdc40fb31f9d7", "bids": [{"price": "0.001", "size": "41191"}, {"price": "0.002", "size": "1581.48"}], "asks": [{"price": "0.999", "size": "7339.51"}, {"price": "0.998", "size": "3250"}, {"price": "0.997", "size": "1406.96"}, {"price": "0.994", "size": "200"}, {"price": "0.993", "size": "10.24"}, {"price": "0.99", "size": "10500"}, {"price": "0.98", "size": "4700"}, {"price": "0.979", "size": "9.2"}, {"price": "0.96", "size": "1250"}, {"price": "0.95", "size": "30"}, {"price": "0.949", "size": "39"}, {"price": "0.94", "size": "500"}, {"price": "0.939", "size": "9.15"}, {"price": "0.9", "size": "2449.99"}, {"price": "0.85", "size": "1276.66"}, {"price": "0.8", "size": "1060"}, {"price": "0.799", "size": "5.69"}, {"price": "0.75", "size": "862"}, {"price": "0.7", "size": "136.66"}, {"price": "0.699", "size": "68"}, {"price": "0.65", "size": "68.57"}, {"price": "0.6", "size": "50"}, {"price": "0.572", "size": "293"}, {"price": "0.547", "size": "5"}, {"price": "0.09", "size": "5"}, {"price": "0.089", "size": "61.14"}, {"price": "0.088", "size": "10"}, {"price": "0.087", "size": "20"}, {"price": "0.012", "size": "10.1"}, {"price": "0.005", "size": "97.67"}, {"price": "0.004", "size": "97"}, {"price": "0.003", "size": "10.57"}], "event_type": "book", "last_trade_price": "0.002"}, {"market": "0x26c050cf067df27a911df254445dece1b69185a84702c728a38cefc3e30bb76d", "asset_id": "7204710211839601265032236088110237384158025763199065581147651013315116777518", "timestamp": "1769383942714", "hash": "6d91369531e78d1de97ebcd7e1929b108670e4d9", "bids": [{"price": "0.001", "size": "7496.75"}, {"price": "0.002", "size": "3250"}, {"price": "0.003", "size": "1407.02"}, {"price": "0.006", "size": "200"}, {"price": "0.007", "size": "10.32"}, {"price": "0.01", "size": "10500"}, {"price": "0.02", "size": "4700"}, {"price": "0.021", "size": "7.25"}, {"price": "0.04", "size": "1250"}, {"price": "0.05", "size": "30"}, {"price": "0.051", "size": "39"}, {"price": "0.061", "size": "9.79"}, {"price": "0.09", "size": "700"}, {"price": "0.1", "size": "1750"}, {"price": "0.14", "size": "242.85"}, {"price": "0.15", "size": "1050"}, {"price": "0.19", "size": "168.42"}, {"price": "0.2", "size": "1000"}, {"price": "0.201", "size": "5.67"}, {"price": "0.24", "size": "116.66"}, {"price": "0.25", "size": "650"}, {"price": "0.251", "size": "250"}, {"price": "0.27", "size": "200"}, {"price": "0.28", "size": "92.85"}, {"price": "0.33", "size": "72.72"}, {"price": "0.38", "size": "367.63"}, {"price": "0.51", "size": "1000"}, {"price": "0.511", "size": "279.41"}, {"price": "0.517", "size": "5"}, {"price": "0.8", "size": "200"}, {"price": "0.801", "size": "115"}, {"price": "0.812", "size": "98.19"}, {"price": "0.839", "size": "100"}, {"price": "0.841", "size": "25"}, {"price": "0.842", "size": "20"}, {"price": "0.875", "size": "53.42"}, {"price": "0.876", "size": "105.55"}, {"price": "0.877", "size": "20"}], "asks": [{"price": "0.999", "size": "27430"}, {"price": "0.998", "size": "2421.28"}, {"price": "0.997", "size": "250"}, {"price": "0.996", "size": "9.03"}, {"price": "0.995", "size": "2000"}, {"price": "0.99", "size": "409.51"}, {"price": "0.989", "size": "15.95"}, {"price": "0.958", "size": "9.8"}, {"price": "0.95", "size": "10000"}, {"price": "0.948", "size": "7000"}, {"price": "0.947", "size": "300"}, {"price": "0.946", "size": "223.5"}], "event_type": "book", "last_trade_price": "0.055"}, {"market": "0xbecfcab892fc16aabf72d5180094c6c51ba33ac8005c3f9497b7c6d05bbee7f1", "asset_id": "25498200346709217272214635487844720997180443012933651618839363828578469169844", "timestamp": "1769383901914", "hash": "d16d85d21eae2be4ef94b6d3acb82371268e0a33", "bids": [{"price": "0.001", "size": "7339.51"}, {"price": "0.002", "size": "3250"}, {"price": "0.003", "size": "1406.96"}, {"price": "0.006", "size": "200"}, {"price": "0.007", "size": "10.24"}, {"price": "0.01", "size": "10500"}, {"price": "0.02", "size": "4700"}, {"price": "0.021", "size": "9.2"}, {"price": "0.04", "size": "1250"}, {"price": "0.05", "size": "30"}, {"price": "0.051", "size": "39"}, {"price": "0.06", "size": "500"}, {"price": "0.061", "size": "9.15"}, {"price": "0.1", "size": "2449.99"}, {"price": "0.15", "size": "1276.66"}, {"price": "0.2", "size": "1060"}, {"price": "0.201", "size": "5.69"}, {"price": "0.25", "size": "862"}, {"price": "0.3", "size": "136.66"}, {"price": "0.301", "size": "68"}, {"price": "0.35", "size": "68.57"}, {"price": "0.4", "size": "50"}, {"price": "0.428", "size": "293"}, {"price": "0.453", "size": "5"}, {"price": "0.91", "size": "5"}, {"price": "0.911", "size": "61.14"}, {"price": "0.912", "size": "10"}, {"price": "0.913", "size": "20"}, {"price": "0.988", "size": "10.1"}, {"price": "0.995", "size": "97.67"}, {"price": "0.996", "size": "97"}, {"price": "0.997", "size": "10.57"}], "asks": [{"price": "0.999", "size": "41191"}, {"price": "0.998", "size": "1581.48"}], "event_type": "book", "last_trade_price": "0.002"}, {"market": "0x5fd14ce22f2d4c332bae5d9e56971eeb44570b6ec0aaede6c71bc08ee22aae84", "asset_id": "11453149164952426691797891584743279450562886978014854321349969650057796367728", "timestamp": "1769383621870", "hash": "8da126fd7e5621483d56b5a85ba65ebb4e58088e", "bids": [{"price": "0.001", "size": "42709.47"}, {"price": "0.002", "size": "4270.95"}], "asks": [{"price": "0.999", "size": "7340.51"}, {"price": "0.998", "size": "3750"}, {"price": "0.997", "size": "1406.96"}, {"price": "0.994", "size": "200"}, {"price": "0.993", "size": "10.24"}, {"price": "0.99", "size": "10500"}, {"price": "0.98", "size": "4700"}, {"price": "0.979", "size": "9.2"}, {"price": "0.96", "size": "1250"}, {"price": "0.95", "size": "30"}, {"price": "0.949", "size": "39"}, {"price": "0.94", "size": "500"}, {"price": "0.939", "size": "9.15"}, {"price": "0.9", "size": "2450"}, {"price": "0.85", "size": "1276.66"}, {"price": "0.8", "size": "1060"}, {"price": "0.799", "size": "5.69"}, {"price": "0.75", "size": "912"}, {"price": "0.7", "size": "186.66"}, {"price": "0.699", "size": "93"}, {"price": "0.66", "size": "50"}, {"price": "0.65", "size": "68.57"}, {"price": "0.6", "size": "50"}, {"price": "0.562", "size": "5"}, {"price": "0.558", "size": "286"}, {"price": "0.557", "size": "10"}, {"price": "0.177", "size": "17"}, {"price": "0.176", "size": "20"}, {"price": "0.06", "size": "5"}, {"price": "0.059", "size": "146.07"}, {"price": "0.058", "size": "13.71"}, {"price": "0.053", "size": "116.47"}, {"price": "0.005", "size": "10"}, {"price": "0.004", "size": "12.31"}, {"price": "0.003", "size": "28.68"}], "event_type": "book", "last_trade_price": "0.002"}, {"market": "0xdade564249db4b9daad8e06c21e06e2760c7c640b2be1c7016baa48bbfef83d9", "asset_id": "56946384770895068627425850948061079846698583721556243142233339125040923398111", "timestamp": "1769383945541", "hash": "4992e1de20401c545bfc077a282fd77304129c18", "bids": [{"price": "0.01", "size": "5500"}, {"price": "0.02", "size": "2200"}, {"price": "0.03", "size": "7.4"}, {"price": "0.08", "size": "1250"}, {"price": "0.12", "size": "883.33"}, {"price": "0.17", "size": "188.23"}, {"price": "0.2", "size": "400"}, {"price": "0.21", "size": "433.33"}, {"price": "0.22", "size": "216"}, {"price": "0.25", "size": "104"}, {"price": "0.29", "size": "182.75"}, {"price": "0.3", "size": "6"}, {"price": "0.33", "size": "60.6"}, {"price": "0.34", "size": "125"}, {"price": "0.35", "size": "6"}, {"price": "0.6", "size": "5"}, {"price": "0.62", "size": "506"}, {"price": "0.63", "size": "66.66"}, {"price": "0.64", "size": "6"}, {"price": "0.69", "size": "66.66"}, {"price": "0.75", "size": "140.66"}], "asks": [{"price": "0.99", "size": "6506.1"}, {"price": "0.98", "size": "2511.53"}, {"price": "0.97", "size": "2160.81"}, {"price": "0.96", "size": "1255.61"}, {"price": "0.95", "size": "930"}, {"price": "0.94", "size": "7.01"}, {"price": "0.93", "size": "528.74"}, {"price": "0.91", "size": "155"}, {"price": "0.9", "size": "46.63"}, {"price": "0.86", "size": "44.74"}, {"price": "0.85", "size": "20"}, {"price": "0.84", "size": "6"}, {"price": "0.82", "size": "8"}, {"price": "0.81", "size": "20"}, {"price": "0.8", "size": "13"}], "event_type": "book", "last_trade_price": "0.240"}, {"market": "0x9ae2d920fa7f4da49b6524361fa2e7260cad95631cc8e443ddeb2d70d2f1ccfd", "asset_id": "4942360482005244918796292265006007704327799854749267861336630583944467908299", "timestamp": "1769383921244", "hash": "0deb789a1966398a67ef6f62de121ad3f35fd0ae", "bids": [{"price": "0.001", "size": "7341.51"}, {"price": "0.002", "size": "2750"}, {"price": "0.003", "size": "1406.96"}, {"price": "0.006", "size": "200"}, {"price": "0.007", "size": "10.24"}, {"price": "0.01", "size": "10500"}, {"price": "0.02", "size": "4700"}, {"price": "0.021", "size": "9.2"}, {"price": "0.04", "size": "1250"}, {"price": "0.05", "size": "30"}, {"price": "0.051", "size": "39"}, {"price": "0.06", "size": "500"}, {"price": "0.061", "size": "9.15"}, {"price": "0.1", "size": "2449.99"}, {"price": "0.15", "size": "1276.66"}, {"price": "0.2", "size": "1060"}, {"price": "0.201", "size": "5.69"}, {"price": "0.25", "size": "912"}, {"price": "0.3", "size": "186.66"}, {"price": "0.34", "size": "50"}, {"price": "0.35", "size": "68.57"}, {"price": "0.4", "size": "50"}, {"price": "0.45", "size": "5"}, {"price": "0.454", "size": "220"}, {"price": "0.455", "size": "276"}, {"price": "0.851", "size": "5"}, {"price": "0.864", "size": "10"}, {"price": "0.865", "size": "20"}, {"price": "0.987", "size": "30"}, {"price": "0.995", "size": "121.22"}, {"price": "0.996", "size": "96.72"}, {"price": "0.997", "size": "17"}], "asks": [{"price": "0.999", "size": "41191.28"}, {"price": "0.998", "size": "4219.82"}], "event_type": "book", "last_trade_price": "0.002"}, {"market": "0xb86618f0e3e26d16e5abd848af319dd750dba3271684a2912268bb917a8f9953", "asset_id": "2980904883599652826602645381294742922476754820505374946621784678629157691361", "timestamp": "1769383906131", "hash": "31a8c7b9360992acc0781d4d6f92d872bc81d73b", "bids": [{"price": "0.05", "size": "1100"}, {"price": "0.06", "size": "350"}, {"price": "0.1", "size": "10"}, {"price": "0.11", "size": "100"}, {"price": "0.12", "size": "10"}, {"price": "0.13", "size": "67.69"}, {"price": "0.16", "size": "15"}], "asks": [{"price": "0.99", "size": "12010.37"}, {"price": "0.98", "size": "4700"}, {"price": "0.97", "size": "9.49"}, {"price": "0.96", "size": "1250"}, {"price": "0.95", "size": "30"}, {"price": "0.92", "size": "750"}, {"price": "0.91", "size": "5.58"}, {"price": "0.9", "size": "2050"}, {"price": "0.87", "size": "261.53"}, {"price": "0.85", "size": "1050"}, {"price": "0.83", "size": "588.23"}, {"price": "0.79", "size": "668.33"}, {"price": "0.78", "size": "222.04"}, {"price": "0.74", "size": "150"}, {"price": "0.73", "size": "50"}, {"price": "0.7", "size": "80"}, {"price": "0.66", "size": "253.82"}, {"price": "0.64", "size": "5"}, {"price": "0.32", "size": "226.47"}, {"price": "0.31", "size": "309.1"}, {"price": "0.3", "size": "200"}, {"price": "0.29", "size": "200"}, {"price": "0.28", "size": "200"}, {"price": "0.27", "size": "225.53"}, {"price": "0.26", "size": "20"}, {"price": "0.25", "size": "40"}, {"price": "0.24", "size": "20"}, {"price": "0.22", "size": "25.53"}, {"price": "0.2", "size": "21.4"}, {"price": "0.19", "size": "52"}, {"price": "0.18", "size": "50.77"}, {"price": "0.17", "size": "25.53"}], "event_type": "book", "last_trade_price": "0.140"}, {"market": "0x26c050cf067df27a911df254445dece1b69185a84702c728a38cefc3e30bb76d", "asset_id": "35515275010400866803110168023266440497655704126461026832913883753463850460136", "timestamp": "1769383942714", "hash": "194b0ad1f558d0511ed3682f40da308927a81b46", "bids": [{"price": "0.001", "size": "27430"}, {"price": "0.002", "size": "2421.28"}, {"price": "0.003", "size": "250"}, {"price": "0.004", "size": "9.03"}, {"price": "0.005", "size": "2000"}, {"price": "0.01", "size": "409.51"}, {"price": "0.011", "size": "15.95"}, {"price": "0.042", "size": "9.8"}, {"price": "0.05", "size": "10000"}, {"price": "0.052", "size": "7000"}, {"price": "0.053", "size": "300"}, {"price": "0.054", "size": "223.5"}], "asks": [{"price": "0.999", "size": "7496.75"}, {"price": "0.998", "size": "3250"}, {"price": "0.997", "size": "1407.02"}, {"price": "0.994", "size": "200"}, {"price": "0.993", "size": "10.32"}, {"price": "0.99", "size": "10500"}, {"price": "0.98", "size": "4700"}, {"price": "0.979", "size": "7.25"}, {"price": "0.96", "size": "1250"}, {"price": "0.95", "size": "30"}, {"price": "0.949", "size": "39"}, {"price": "0.939", "size": "9.79"}, {"price": "0.91", "size": "700"}, {"price": "0.9", "size": "1750"}, {"price": "0.86", "size": "242.85"}, {"price": "0.85", "size": "1050"}, {"price": "0.81", "size": "168.42"}, {"price": "0.8", "size": "1000"}, {"price": "0.799", "size": "5.67"}, {"price": "0.76", "size": "116.66"}, {"price": "0.75", "size": "650"}, {"price": "0.749", "size": "250"}, {"price": "0.73", "size": "200"}, {"price": "0.72", "size": "92.85"}, {"price": "0.67", "size": "72.72"}, {"price": "0.62", "size": "367.63"}, {"price": "0.49", "size": "1000"}, {"price": "0.489", "size": "279.41"}, {"price": "0.483", "size": "5"}, {"price": "0.2", "size": "200"}, {"price": "0.199", "size": "115"}, {"price": "0.188", "size": "98.19"}, {"price": "0.161", "size": "100"}, {"price": "0.159", "size": "25"}, {"price": "0.158", "size": "20"}, {"price": "0.125", "size": "53.42"}, {"price": "0.124", "size": "105.55"}, {"price": "0.123", "size": "20"}], "event_type": "book", "last_trade_price": "0.055"}]}
{"_local_timestamp": "2026-01-25T23:33:52.335764+00:00", "data": {"market": "0x26c050cf067df27a911df254445dece1b69185a84702c728a38cefc3e30bb76d", "price_changes": [{"asset_id": "7204710211839601265032236088110237384158025763199065581147651013315116777518", "price": "0.001", "size": "7484.79", "side": "BUY", "hash": "3b276fca67a5e6d1e3902d4ccf704ed3ac4f31cb", "best_bid": "0.877", "best_ask": "0.946"}, {"asset_id": "35515275010400866803110168023266440497655704126461026832913883753463850460136", "price": "0.999", "size": "7484.79", "side": "SELL", "hash": "cf425f974a23048668782aedba7a2ec0a2d3b011", "best_bid": "0.054", "best_ask": "0.123"}], "timestamp": "1769384032254", "event_type": "price_change"}}
{"_local_timestamp": "2026-01-25T23:33:52.338552+00:00", "data": {"market": "0x26c050cf067df27a911df254445dece1b69185a84702c728a38cefc3e30bb76d", "price_changes": [{"asset_id": "7204710211839601265032236088110237384158025763199065581147651013315116777518", "price": "0.061", "size": "0", "side": "BUY", "hash": "3b276fca67a5e6d1e3902d4ccf704ed3ac4f31cb", "best_bid": "0.877", "best_ask": "0.946"}, {"asset_id": "35515275010400866803110168023266440497655704126461026832913883753463850460136", "price": "0.939", "size": "0", "side": "SELL", "hash": "cf425f974a23048668782aedba7a2ec0a2d3b011", "best_bid": "0.054", "best_ask": "0.123"}], "timestamp": "1769384032254", "event_type": "price_change"}}
{"_local_timestamp": "2026-01-25T23:33:52.474695+00:00", "data": {"market": "0x9ae2d920fa7f4da49b6524361fa2e7260cad95631cc8e443ddeb2d70d2f1ccfd", "price_changes": [{"asset_id": "4942360482005244918796292265006007704327799854749267861336630583944467908299", "price": "0.454", "size": "0", "side": "BUY", "hash": "d3e505c9b807b4d5e645fcee74e1d2b1d61c810b", "best_bid": "0.997", "best_ask": "0.998"}, {"asset_id": "113409560089971005551069019900801779309141794188263770657345157175671976775527", "price": "0.546", "size": "0", "side": "SELL", "hash": "e10633b3e653fdeb39c99b7d8cef3c9cd045c658", "best_bid": "0.002", "best_ask": "0.003"}], "timestamp": "1769384032410", "event_type": "price_change"}}
{"_local_timestamp": "2026-01-25T23:33:52.502836+00:00", "data": {"market": "0xbf2cba044810364349878bce032b495875a0ae8b575286388e79cc4bddde4a6c", "price_changes": [{"asset_id": "52973946067415555340752362838729163232972184824595142980403702383146397821473", "price": "0.454", "size": "0", "side": "BUY", "hash": "29f84e47e1cbac169e8875d88830fa59e5714048", "best_bid": "0.997", "best_ask": "0.998"}, {"asset_id": "80303106904766949344727438756563505749348738369775655357626215899018784021389", "price": "0.546", "size": "0", "side": "SELL", "hash": "96aa15cd8da1da42ae51936b16687501dbdfb58e", "best_bid": "0.002", "best_ask": "0.003"}], "timestamp": "1769384032440", "event_type": "price_change"}}
{"_local_timestamp": "2026-01-25T23:33:52.503337+00:00", "data": {"market": "0x5fd14ce22f2d4c332bae5d9e56971eeb44570b6ec0aaede6c71bc08ee22aae84", "price_changes": [{"asset_id": "74859528307279738324579355645582848708259059823655254205378377992189727361464", "price": "0.443", "size": "0", "side": "BUY", "hash": "50e410f70c1ae7ee49bab1236805707229a0b09f", "best_bid": "0.997", "best_ask": "0.998"}, {"asset_id": "11453149164952426691797891584743279450562886978014854321349969650057796367728", "price": "0.557", "size": "0", "side": "SELL", "hash": "093e1b8587c991599d93dc9f37d2ccff46622354", "best_bid": "0.002", "best_ask": "0.003"}], "timestamp": "1769384032440", "event_type": "price_change"}}
{"_local_timestamp": "2026-01-25T23:33:52.607730+00:00", "data": {"market": "0x5fd14ce22f2d4c332bae5d9e56971eeb44570b6ec0aaede6c71bc08ee22aae84", "price_changes": [{"asset_id": "74859528307279738324579355645582848708259059823655254205378377992189727361464", "price": "0.443", "size": "10", "side": "BUY", "hash": "e9b9fa633b8590baf2230a069aad11fa718143f3", "best_bid": "0.997", "best_ask": "0.998"}, {"asset_id": "11453149164952426691797891584743279450562886978014854321349969650057796367728", "price": "0.557", "size": "10", "side": "SELL", "hash": "b1a1670122db84e0109247b85c6375b114d60f1e", "best_bid": "0.002", "best_ask": "0.003"}], "timestamp": "1769384032529", "event_type": "price_change"}}
{"_local_timestamp": "2026-01-25T23:33:52.608124+00:00", "data": {"market": "0xbf2cba044810364349878bce032b495875a0ae8b575286388e79cc4bddde4a6c", "price_changes": [{"asset_id": "52973946067415555340752362838729163232972184824595142980403702383146397821473", "price": "0.456", "size": "10", "side": "BUY", "hash": "9d3aa42ae653d962d419475628a05aaa49c83ceb", "best_bid": "0.997", "best_ask": "0.998"}, {"asset_id": "80303106904766949344727438756563505749348738369775655357626215899018784021389", "price": "0.544", "size": "10", "side": "SELL", "hash": "bd2d976231b0d92bec6060902ef706ac1167b19f", "best_bid": "0.002", "best_ask": "0.003"}], "timestamp": "1769384032529", "event_type": "price_change"}}
{"_local_timestamp": "2026-01-25T23:33:52.628110+00:00", "data": {"market": "0x26c050cf067df27a911df254445dece1b69185a84702c728a38cefc3e30bb76d", "price_changes": [{"asset_id": "7204710211839601265032236088110237384158025763199065581147651013315116777518", "price": "0.062", "size": "9.73", "side": "BUY", "hash": "9f66ce525e6408e8ef5d419bdf4ee87fe8ffab44", "best_bid": "0.877", "best_ask": "0.946"}, {"asset_id": "35515275010400866803110168023266440497655704126461026832913883753463850460136", "price": "0.938", "size": "9.73", "side": "SELL", "hash": "1a041a8bff2b0a5f32c855c73cde6748b92bce27", "best_bid": "0.054", "best_ask": "0.123"}], "timestamp": "1769384032543", "event_type": "price_change"}}
{"_local_timestamp": "2026-01-25T23:33:52.631029+00:00", "data": {"market": "0x9ae2d920fa7f4da49b6524361fa2e7260cad95631cc8e443ddeb2d70d2f1ccfd", "price_changes": [{"asset_id": "4942360482005244918796292265006007704327799854749267861336630583944467908299", "price": "0.866", "size": "15", "side": "BUY", "hash": "faccc5ed584a5d7420862df06b1de8ae55453b11", "best_bid": "0.997", "best_ask": "0.998"}, {"asset_id": "113409560089971005551069019900801779309141794188263770657345157175671976775527", "price": "0.134", "size": "15", "side": "SELL", "hash": "f073c09ef2edda227d8f9ed46d71e5186183e3cf", "best_bid": "0.002", "best_ask": "0.003"}], "timestamp": "1769384032546", "event_type": "price_change"}}
{"_local_timestamp": "2026-01-25T23:33:52.631536+00:00", "data": {"market": "0x26c050cf067df27a911df254445dece1b69185a84702c728a38cefc3e30bb76d", "price_changes": [{"asset_id": "7204710211839601265032236088110237384158025763199065581147651013315116777518", "price": "0.001", "size": "7490.13", "side": "BUY", "hash": "3ecc7e99776c5185964b29d70dd00757912f1220", "best_bid": "0.877", "best_ask": "0.946"}, {"asset_id": "35515275010400866803110168023266440497655704126461026832913883753463850460136", "price": "0.999", "size": "7490.13", "side": "SELL", "hash": "32ee43bc20f1633f431f9b60d1c9ac97d7bce74c", "best_bid": "0.054", "best_ask": "0.123"}], "timestamp": "1769384032546", "event_type": "price_change"}}
{"_local_timestamp": "2026-01-25T23:33:52.634290+00:00", "data": {"market": "0x9ae2d920fa7f4da49b6524361fa2e7260cad95631cc8e443ddeb2d70d2f1ccfd", "price_changes": [{"asset_id": "4942360482005244918796292265006007704327799854749267861336630583944467908299", "price": "0.456", "size": "219", "side": "BUY", "hash": "d4b76f9c8f8b13c4d0e2eb8d274939ca8c06dfeb", "best_bid": "0.997", "best_ask": "0.998"}, {"asset_id": "113409560089971005551069019900801779309141794188263770657345157175671976775527", "price": "0.544", "size": "219", "side": "SELL", "hash": "05071545e0105b7766e32dbd0a1a91d91d049ea7", "best_bid": "0.002", "best_ask": "0.003"}], "timestamp": "1769384032547", "event_type": "price_change"}}
{"_local_timestamp": "2026-01-25T23:33:52.638006+00:00", "data": {"market": "0x9ae2d920fa7f4da49b6524361fa2e7260cad95631cc8e443ddeb2d70d2f1ccfd", "price_changes": [{"asset_id": "4942360482005244918796292265006007704327799854749267861336630583944467908299", "price": "0.866", "size": "25", "side": "BUY", "hash": "edc7f2b55699e248ce544fdc995d2e44fe8c9b3f", "best_bid": "0.997", "best_ask": "0.998"}, {"asset_id": "113409560089971005551069019900801779309141794188263770657345157175671976775527", "price": "0.134", "size": "25", "side": "SELL", "hash": "db873c995a4e5d3f5d9f21ee68257a653011d10e", "best_bid": "0.002", "best_ask": "0.003"}], "timestamp": "1769384032548", "event_type": "price_change"}}
{"_local_timestamp": "2026-01-25T23:33:55.805107+00:00", "data": {"market": "0x26c050cf067df27a911df254445dece1b69185a84702c728a38cefc3e30bb76d", "price_changes": [{"asset_id": "7204710211839601265032236088110237384158025763199065581147651013315116777518", "price": "0.875", "size": "10", "side": "BUY", "hash": "13280ba39fd8057ed4416a82d0f7d471034b004c", "best_bid": "0.877", "best_ask": "0.946"}, {"asset_id": "35515275010400866803110168023266440497655704126461026832913883753463850460136", "price": "0.125", "size": "10", "side": "SELL", "hash": "effe6835e79332a6a881af6685552f105463ab41", "best_bid": "0.054", "best_ask": "0.123"}], "timestamp": "1769384035737", "event_type": "price_change"}}
{"_local_timestamp": "2026-01-25T23:33:55.879914+00:00", "data": {"market": "0xbf2cba044810364349878bce032b495875a0ae8b575286388e79cc4bddde4a6c", "price_changes": [{"asset_id": "52973946067415555340752362838729163232972184824595142980403702383146397821473", "price": "0.913", "size": "0", "side": "BUY", "hash": "83bcc2aa8a66803dcf71f791b65524c2cf3ea0af", "best_bid": "0.997", "best_ask": "0.998"}, {"asset_id": "80303106904766949344727438756563505749348738369775655357626215899018784021389", "price": "0.087", "size": "0", "side": "SELL", "hash": "98a575010ab2081fbefe6a0ab71d6b7497343dc9", "best_bid": "0.002", "best_ask": "0.003"}], "timestamp": "1769384035812", "event_type": "price_change"}}
{"_local_timestamp": "2026-01-25T23:33:56.833284+00:00", "data": {"market": "0x9ae2d920fa7f4da49b6524361fa2e7260cad95631cc8e443ddeb2d70d2f1ccfd", "price_changes": [{"asset_id": "4942360482005244918796292265006007704327799854749267861336630583944467908299", "price": "0.865", "size": "0", "side": "BUY", "hash": "5c7ee39702f6730e77f329f8989d4d870982c9f6", "best_bid": "0.997", "best_ask": "0.998"}, {"asset_id": "113409560089971005551069019900801779309141794188263770657345157175671976775527", "price": "0.135", "size": "0", "side": "SELL", "hash": "dfcf8c803fa5bc0db28bb880766cda7aff0a0ab3", "best_bid": "0.002", "best_ask": "0.003"}], "timestamp": "1769384036770", "event_type": "price_change"}}
{"_local_timestamp": "2026-01-25T23:33:56.833668+00:00", "data": {"market": "0xbf2cba044810364349878bce032b495875a0ae8b575286388e79cc4bddde4a6c", "price_changes": [{"asset_id": "52973946067415555340752362838729163232972184824595142980403702383146397821473", "price": "0.914", "size": "0", "side": "BUY", "hash": "1977faefe61253c80a0e38f04d4972dd9e4d494b", "best_bid": "0.997", "best_ask": "0.998"}, {"asset_id": "80303106904766949344727438756563505749348738369775655357626215899018784021389", "price": "0.086", "size": "0", "side": "SELL", "hash": "464a49343034bb4a0f60fb04e8f49805126bbaf6", "best_bid": "0.002", "best_ask": "0.003"}], "timestamp": "1769384036770", "event_type": "price_change"}}
{"_local_timestamp": "2026-01-25T23:33:56.866861+00:00", "data": {"market": "0x9ae2d920fa7f4da49b6524361fa2e7260cad95631cc8e443ddeb2d70d2f1ccfd", "price_changes": [{"asset_id": "4942360482005244918796292265006007704327799854749267861336630583944467908299", "price": "0.867", "size": "20", "side": "BUY", "hash": "933e1a9b5c8651f5f76a5295649620b217d3ffa1", "best_bid": "0.997", "best_ask": "0.998"}, {"asset_id": "113409560089971005551069019900801779309141794188263770657345157175671976775527", "price": "0.133", "size": "20", "side": "SELL", "hash": "04b3f8f822edb41003f071d13f2a35a2f91777b8", "best_bid": "0.002", "best_ask": "0.003"}], "timestamp": "1769384036801", "event_type": "price_change"}}
{"_local_timestamp": "2026-01-25T23:33:56.867338+00:00", "data": {"market": "0xbf2cba044810364349878bce032b495875a0ae8b575286388e79cc4bddde4a6c", "price_changes": [{"asset_id": "52973946067415555340752362838729163232972184824595142980403702383146397821473", "price": "0.912", "size": "20", "side": "BUY", "hash": "73417f48988260fa1757342dbc854f4ae529f23e", "best_bid": "0.997", "best_ask": "0.998"}, {"asset_id": "80303106904766949344727438756563505749348738369775655357626215899018784021389", "price": "0.088", "size": "20", "side": "SELL", "hash": "6d2e949c97517a716a2c261efd633c49564c6291", "best_bid": "0.002", "best_ask": "0.003"}], "timestamp": "1769384036802", "event_type": "price_change"}}
{"_local_timestamp": "2026-01-25T23:33:56.901442+00:00", "data": {"market": "0xbf2cba044810364349878bce032b495875a0ae8b575286388e79cc4bddde4a6c", "price_changes": [{"asset_id": "52973946067415555340752362838729163232972184824595142980403702383146397821473", "price": "0.455", "size": "279", "side": "BUY", "hash": "61c194ec4a616dbc21aa2336a68bd19380d6b0ae", "best_bid": "0.997", "best_ask": "0.998"}, {"asset_id": "80303106904766949344727438756563505749348738369775655357626215899018784021389", "price": "0.545", "size": "279", "side": "SELL", "hash": "f59bd0a55727a5715a598580ff28bd3c74f5ef0e", "best_bid": "0.002", "best_ask": "0.003"}], "timestamp": "1769384036839", "event_type": "price_change"}}
{"_local_timestamp": "2026-01-25T23:34:27.800516+00:00", "data": {"market": "0x26c050cf067df27a911df254445dece1b69185a84702c728a38cefc3e30bb76d", "price_changes": [{"asset_id": "7204710211839601265032236088110237384158025763199065581147651013315116777518", "price": "0.27", "size": "100", "side": "BUY", "hash": "0624789b10b51f6f73d5711206afbbb30475e3d6", "best_bid": "0.877", "best_ask": "0.946"}, {"asset_id": "35515275010400866803110168023266440497655704126461026832913883753463850460136", "price": "0.73", "size": "100", "side": "SELL", "hash": "4a3545894e73b9905763f4bbd44739f875579d2c", "best_bid": "0.054", "best_ask": "0.123"}], "timestamp": "1769384067588", "event_type": "price_change"}}
{"_local_timestamp": "2026-01-25T23:34:28.608145+00:00", "data": {"market": "0x26c050cf067df27a911df254445dece1b69185a84702c728a38cefc3e30bb76d", "price_changes": [{"asset_id": "7204710211839601265032236088110237384158025763199065581147651013315116777518", "price": "0.25", "size": "750", "side": "BUY", "hash": "198b3c773b44cf736bba3b163e0e451e8db85307", "best_bid": "0.877", "best_ask": "0.946"}, {"asset_id": "35515275010400866803110168023266440497655704126461026832913883753463850460136", "price": "0.75", "size": "750", "side": "SELL", "hash": "e6c749501d28aadba5baee867e82741f9a41f309", "best_bid": "0.054", "best_ask": "0.123"}], "timestamp": "1769384068172", "event_type": "price_change"}}
{"_local_timestamp": "2026-01-25T23:34:30.982920+00:00", "data": {"market": "0x26c050cf067df27a911df254445dece1b69185a84702c728a38cefc3e30bb76d", "price_changes": [{"asset_id": "7204710211839601265032236088110237384158025763199065581147651013315116777518", "price": "0.839", "size": "0", "side": "BUY", "hash": "76870f888a4504f093202ea09c9555fb88dfd391", "best_bid": "0.877", "best_ask": "0.946"}, {"asset_id": "35515275010400866803110168023266440497655704126461026832913883753463850460136", "price": "0.161", "size": "0", "side": "SELL", "hash": "6e3bb93ca463fb03b0589a203b9b2593b8a708a8", "best_bid": "0.054", "best_ask": "0.123"}], "timestamp": "1769384070914", "event_type": "price_change"}}
{"_local_timestamp": "2026-01-25T23:34:30.983463+00:00", "data": {"market": "0x26c050cf067df27a911df254445dece1b69185a84702c728a38cefc3e30bb76d", "price_changes": [{"asset_id": "7204710211839601265032236088110237384158025763199065581147651013315116777518", "price": "0.801", "size": "15", "side": "BUY", "hash": "76870f888a4504f093202ea09c9555fb88dfd391", "best_bid": "0.877", "best_ask": "0.946"}, {"asset_id": "35515275010400866803110168023266440497655704126461026832913883753463850460136", "price": "0.199", "size": "15", "side": "SELL", "hash": "6e3bb93ca463fb03b0589a203b9b2593b8a708a8", "best_bid": "0.054", "best_ask": "0.123"}], "timestamp": "1769384070914", "event_type": "price_change"}}
{"_local_timestamp": "2026-01-25T23:34:31.672742+00:00", "data": {"market": "0x26c050cf067df27a911df254445dece1b69185a84702c728a38cefc3e30bb76d", "price_changes": [{"asset_id": "7204710211839601265032236088110237384158025763199065581147651013315116777518", "price": "0.512", "size": "100", "side": "BUY", "hash": "0c3dba36f4d08a80aa875de322247bbcd1d6c8cd", "best_bid": "0.877", "best_ask": "0.946"}, {"asset_id": "35515275010400866803110168023266440497655704126461026832913883753463850460136", "price": "0.488", "size": "100", "side": "SELL", "hash": "6b765aa89dc6c3c0d27dd9e571a58b31591e6da7", "best_bid": "0.054", "best_ask": "0.123"}], "timestamp": "1769384071606", "event_type": "price_change"}}
{"_local_timestamp": "2026-01-25T23:34:31.695437+00:00", "data": {"market": "0x26c050cf067df27a911df254445dece1b69185a84702c728a38cefc3e30bb76d", "price_changes": [{"asset_id": "7204710211839601265032236088110237384158025763199065581147651013315116777518", "price": "0.695", "size": "100", "side": "BUY", "hash": "dd2860c3b031bd3ffd5a620dd172411044f21fc1", "best_bid": "0.877", "best_ask": "0.946"}, {"asset_id": "35515275010400866803110168023266440497655704126461026832913883753463850460136", "price": "0.305", "size": "100", "side": "SELL", "hash": "74be0563961fbb8f1e9061b093e04b7c150a210d", "best_bid": "0.054", "best_ask": "0.123"}], "timestamp": "1769384071627", "event_type": "price_change"}}
{"_local_timestamp": "2026-01-25T23:35:02.781916+00:00", "data": {"market": "0x26c050cf067df27a911df254445dece1b69185a84702c728a38cefc3e30bb76d", "price_changes": [{"asset_id": "7204710211839601265032236088110237384158025763199065581147651013315116777518", "price": "0.877", "size": "63.32", "side": "BUY", "hash": "15a7b9c661f73aeaee65f47eac4c16389e28f40b", "best_bid": "0.877", "best_ask": "0.946"}, {"asset_id": "35515275010400866803110168023266440497655704126461026832913883753463850460136", "price": "0.123", "size": "63.32", "side": "SELL", "hash": "42e308b2f89e666fa3644f40a0a891d18c70759c", "best_bid": "0.054", "best_ask": "0.123"}], "timestamp": "1769384102717", "event_type": "price_change"}}
{"_local_timestamp": "2026-01-25T23:35:13.955431+00:00", "data": {"market": "0x26c050cf067df27a911df254445dece1b69185a84702c728a38cefc3e30bb76d", "price_changes": [{"asset_id": "7204710211839601265032236088110237384158025763199065581147651013315116777518", "price": "0.878", "size": "45", "side": "BUY", "hash": "b33529ba6816f7b5404a0efef35acaf15bb3e51a", "best_bid": "0.878", "best_ask": "0.946"}, {"asset_id": "35515275010400866803110168023266440497655704126461026832913883753463850460136", "price": "0.122", "size": "45", "side": "SELL", "hash": "14d67366b73c954bbb3874014e5922b88eb8b433", "best_bid": "0.054", "best_ask": "0.122"}], "timestamp": "1769384113889", "event_type": "price_change"}}
{"_local_timestamp": "2026-01-25T23:35:18.392793+00:00", "data": {"market": "0x26c050cf067df27a911df254445dece1b69185a84702c728a38cefc3e30bb76d", "price_changes": [{"asset_id": "7204710211839601265032236088110237384158025763199065581147651013315116777518", "price": "0.876", "size": "0", "side": "BUY", "hash": "035fe92b7f436ad29107e245c1dea2ece7029668", "best_bid": "0.878", "best_ask": "0.946"}, {"asset_id": "35515275010400866803110168023266440497655704126461026832913883753463850460136", "price": "0.124", "size": "0", "side": "SELL", "hash": "382bde5f0a9bdbb23f2849bbc020c554091cef55", "best_bid": "0.054", "best_ask": "0.122"}], "timestamp": "1769384118319", "event_type": "price_change"}}
{"_local_timestamp": "2026-01-25T23:35:23.802626+00:00", "data": {"market": "0x26c050cf067df27a911df254445dece1b69185a84702c728a38cefc3e30bb76d", "price_changes": [{"asset_id": "7204710211839601265032236088110237384158025763199065581147651013315116777518", "price": "0.27", "size": "50", "side": "BUY", "hash": "1fae3f73961366551f914af4fa13c22402d5c28e", "best_bid": "0.878", "best_ask": "0.946"}, {"asset_id": "35515275010400866803110168023266440497655704126461026832913883753463850460136", "price": "0.73", "size": "50", "side": "SELL", "hash": "f4bcb3f5f9c170ba6d7ba565cacf81f3b40e5883", "best_bid": "0.054", "best_ask": "0.122"}], "timestamp": "1769384123679", "event_type": "price_change"}}
{"_local_timestamp": "2026-01-25T23:35:24.003133+00:00", "data": {"market": "0x26c050cf067df27a911df254445dece1b69185a84702c728a38cefc3e30bb76d", "price_changes": [{"asset_id": "7204710211839601265032236088110237384158025763199065581147651013315116777518", "price": "0.28", "size": "142.85", "side": "BUY", "hash": "ef2cb3fed8a7a039201a30cc66d17f2b8cd84d16", "best_bid": "0.878", "best_ask": "0.946"}, {"asset_id": "35515275010400866803110168023266440497655704126461026832913883753463850460136", "price": "0.72", "size": "142.85", "side": "SELL", "hash": "16f345ebeba34dc7c6b60ccdf7441b3afe87de9c", "best_bid": "0.054", "best_ask": "0.122"}], "timestamp": "1769384123934", "event_type": "price_change"}}
{"_local_timestamp": "2026-01-25T23:35:31.397396+00:00", "data": {"market": "0xbd8114a52eed432265735ebfe174ce257047a94b378cbc36246ca0dba7a07c33", "price_changes": [{"asset_id": "113403179930780844692419404105573805354679366394847558149476632392300380613010", "price": "0.002", "size": "1255", "side": "BUY", "hash": "8f1611cb85e469077a11350bc4599c925951aa8f", "best_bid": "0.004", "best_ask": "0.005"}, {"asset_id": "34347535308090847792552379030322073016871399676099560255182105326984970187327", "price": "0.998", "size": "1255", "side": "SELL", "hash": "5678181f3fcf046406158c1bc409f4062e624e35", "best_bid": "0.995", "best_ask": "0.996"}], "timestamp": "1769384131245", "event_type": "price_change"}}
{"_local_timestamp": "2026-01-25T23:35:31.632315+00:00", "data": {"market": "0xbecfcab892fc16aabf72d5180094c6c51ba33ac8005c3f9497b7c6d05bbee7f1", "price_changes": [{"asset_id": "25498200346709217272214635487844720997180443012933651618839363828578469169844", "price": "0.912", "size": "0", "side": "BUY", "hash": "63666a926d04c5432c82f3f4a0f0bc6349f3e1c6", "best_bid": "0.997", "best_ask": "0.998"}, {"asset_id": "98146342803923051979042568419031220153888306546081565583042852359988504135784", "price": "0.088", "size": "0", "side": "SELL", "hash": "6f36cc2fdf6c16c3d0fd99cebc8464f24a7cc7ef", "best_bid": "0.002", "best_ask": "0.003"}], "timestamp": "1769384131521", "event_type": "price_change"}}
{"_local_timestamp": "2026-01-25T23:35:31.711001+00:00", "data": {"market": "0xbecfcab892fc16aabf72d5180094c6c51ba33ac8005c3f9497b7c6d05bbee7f1", "price_changes": [{"asset_id": "25498200346709217272214635487844720997180443012933651618839363828578469169844", "price": "0.914", "size": "10", "side": "BUY", "hash": "2e721867c58277f5b6f88dbd249cb41f7419e102", "best_bid": "0.997", "best_ask": "0.998"}, {"asset_id": "98146342803923051979042568419031220153888306546081565583042852359988504135784", "price": "0.086", "size": "10", "side": "SELL", "hash": "253efb110e9186902c2a181149a3f07888481550", "best_bid": "0.002", "best_ask": "0.003"}], "timestamp": "1769384131633", "event_type": "price_change"}}
{"_local_timestamp": "2026-01-25T23:35:31.715855+00:00", "data": {"market": "0xbecfcab892fc16aabf72d5180094c6c51ba33ac8005c3f9497b7c6d05bbee7f1", "price_changes": [{"asset_id": "25498200346709217272214635487844720997180443012933651618839363828578469169844", "price": "0.454", "size": "74", "side": "BUY", "hash": "f13d62d939c10f3dbcc4434f66292e70f0305da6", "best_bid": "0.997", "best_ask": "0.998"}, {"asset_id": "98146342803923051979042568419031220153888306546081565583042852359988504135784", "price": "0.546", "size": "74", "side": "SELL", "hash": "291b388140b296ab4d6aed4a9069a8d6248d757e", "best_bid": "0.002", "best_ask": "0.003"}], "timestamp": "1769384131634", "event_type": "price_change"}}
{"_local_timestamp": "2026-01-25T23:35:37.246945+00:00", "data": {"market": "0xbecfcab892fc16aabf72d5180094c6c51ba33ac8005c3f9497b7c6d05bbee7f1", "price_changes": [{"asset_id": "25498200346709217272214635487844720997180443012933651618839363828578469169844", "price": "0.913", "size": "0", "side": "BUY", "hash": "e209971e208a6b0e7ecb50e6f4996aebac25700c", "best_bid": "0.997", "best_ask": "0.998"}, {"asset_id": "98146342803923051979042568419031220153888306546081565583042852359988504135784", "price": "0.087", "size": "0", "side": "SELL", "hash": "06a4506a0435ad3534af71f6a015b34f487177a9", "best_bid": "0.002", "best_ask": "0.003"}], "timestamp": "1769384137180", "event_type": "price_change"}}
{"_local_timestamp": "2026-01-25T23:35:37.286041+00:00", "data": {"market": "0xbecfcab892fc16aabf72d5180094c6c51ba33ac8005c3f9497b7c6d05bbee7f1", "price_changes": [{"asset_id": "25498200346709217272214635487844720997180443012933651618839363828578469169844", "price": "0.915", "size": "20", "side": "BUY", "hash": "4d7ce65cb6565edcc005344e938680489cd8c4dc", "best_bid": "0.997", "best_ask": "0.998"}, {"asset_id": "98146342803923051979042568419031220153888306546081565583042852359988504135784", "price": "0.085", "size": "20", "side": "SELL", "hash": "9f4d175f85e284aa686ae5701fb3465d58ffb875", "best_bid": "0.002", "best_ask": "0.003"}], "timestamp": "1769384137211", "event_type": "price_change"}}
{"_local_timestamp": "2026-01-25T23:35:37.452148+00:00", "data": {"market": "0x26c050cf067df27a911df254445dece1b69185a84702c728a38cefc3e30bb76d", "price_changes": [{"asset_id": "7204710211839601265032236088110237384158025763199065581147651013315116777518", "price": "0.841", "size": "10", "side": "BUY", "hash": "ca3d0a13d4fd1292e0d00490fca75fddd65e5fa0", "best_bid": "0.878", "best_ask": "0.946"}, {"asset_id": "35515275010400866803110168023266440497655704126461026832913883753463850460136", "price": "0.159", "size": "10", "side": "SELL", "hash": "76ef6c3245d55c2e015408c4d426d0b0f88529f7", "best_bid": "0.054", "best_ask": "0.122"}], "timestamp": "1769384137386", "event_type": "price_change"}}
{"_local_timestamp": "2026-01-25T23:35:57.943181+00:00", "data": {"market": "0xdade564249db4b9daad8e06c21e06e2760c7c640b2be1c7016baa48bbfef83d9", "price_changes": [{"asset_id": "54806808255046819356872422328886643818584171246276253781026782874036677222460", "price": "0.1", "size": "36", "side": "BUY", "hash": "3b0afd5d8b2675e9ffc6c4285f99ba9d0f6fe419", "best_bid": "0.2", "best_ask": "0.25"}, {"asset_id": "56946384770895068627425850948061079846698583721556243142233339125040923398111", "price": "0.9", "size": "36", "side": "SELL", "hash": "c83e13046e5304b314146c8ec1c1e2b73276e423", "best_bid": "0.75", "best_ask": "0.8"}], "timestamp": "1769384157826", "event_type": "price_change"}}
{"_local_timestamp": "2026-01-25T23:35:58.301459+00:00", "data": {"market": "0xdade564249db4b9daad8e06c21e06e2760c7c640b2be1c7016baa48bbfef83d9", "price_changes": [{"asset_id": "54806808255046819356872422328886643818584171246276253781026782874036677222460", "price": "0.11", "size": "9.66", "side": "BUY", "hash": "4294854c7935ae2c5c6ac91f56676586d4cc7e2b", "best_bid": "0.2", "best_ask": "0.25"}, {"asset_id": "56946384770895068627425850948061079846698583721556243142233339125040923398111", "price": "0.89", "size": "9.66", "side": "SELL", "hash": "606255e8c736c92f503ca83a30052c5f2fb1d17f", "best_bid": "0.75", "best_ask": "0.8"}], "timestamp": "1769384158232", "event_type": "price_change"}}
{"_local_timestamp": "2026-01-25T23:36:06.264836+00:00", "data": {"market": "0xdade564249db4b9daad8e06c21e06e2760c7c640b2be1c7016baa48bbfef83d9", "price_changes": [{"asset_id": "54806808255046819356872422328886643818584171246276253781026782874036677222460", "price": "0.19", "size": "72", "side": "BUY", "hash": "0e994719b38ce248aeebac41ef203db49a382570", "best_bid": "0.2", "best_ask": "0.25"}, {"asset_id": "56946384770895068627425850948061079846698583721556243142233339125040923398111", "price": "0.81", "size": "72", "side": "SELL", "hash": "0b39484ba6f7fa1b910ea67cb830edbd1ff774fd", "best_bid": "0.75", "best_ask": "0.8"}], "timestamp": "1769384166183", "event_type": "price_change"}}
{"_local_timestamp": "2026-01-25T23:36:06.265361+00:00", "data": {"market": "0x26c050cf067df27a911df254445dece1b69185a84702c728a38cefc3e30bb76d", "price_changes": [{"asset_id": "7204710211839601265032236088110237384158025763199065581147651013315116777518", "price": "0.879", "size": "105.55", "side": "BUY", "hash": "493fc6dfeff96c7c28bfcab690fedb4bcb08b51c", "best_bid": "0.879", "best_ask": "0.946"}, {"asset_id": "35515275010400866803110168023266440497655704126461026832913883753463850460136", "price": "0.121", "size": "105.55", "side": "SELL", "hash": "ace8af3b100a7c54b3addb96ffa3ac0b604e94f5", "best_bid": "0.054", "best_ask": "0.121"}], "timestamp": "1769384166182", "event_type": "price_change"}}
{"_local_timestamp": "2026-01-25T23:36:06.265888+00:00", "data": {"market": "0x26c050cf067df27a911df254445dece1b69185a84702c728a38cefc3e30bb76d", "price_changes": [{"asset_id": "7204710211839601265032236088110237384158025763199065581147651013315116777518", "price": "0.878", "size": "97", "side": "BUY", "hash": "e268c7585bc4efa4b1b7d08a860d77aee44a21ac", "best_bid": "0.879", "best_ask": "0.946"}, {"asset_id": "35515275010400866803110168023266440497655704126461026832913883753463850460136", "price": "0.122", "size": "97", "side": "SELL", "hash": "b83e98086adb64b4bdebe0476cccd938d4a5e808", "best_bid": "0.054", "best_ask": "0.121"}], "timestamp": "1769384166183", "event_type": "price_change"}}
{"_local_timestamp": "2026-01-25T23:36:06.373089+00:00", "data": {"market": "0x26c050cf067df27a911df254445dece1b69185a84702c728a38cefc3e30bb76d", "price_changes": [{"asset_id": "7204710211839601265032236088110237384158025763199065581147651013315116777518", "price": "0.841", "size": "0", "side": "BUY", "hash": "10476621ba0382097bd74ff6669e98f2b1f2d549", "best_bid": "0.879", "best_ask": "0.946"}, {"asset_id": "35515275010400866803110168023266440497655704126461026832913883753463850460136", "price": "0.159", "size": "0", "side": "SELL", "hash": "55a9061335a74a3ce861a5ad2d17d8cfca2dd096", "best_bid": "0.054", "best_ask": "0.121"}], "timestamp": "1769384166309", "event_type": "price_change"}}
{"_local_timestamp": "2026-01-25T23:36:06.410662+00:00", "data": {"market": "0xdade564249db4b9daad8e06c21e06e2760c7c640b2be1c7016baa48bbfef83d9", "price_changes": [{"asset_id": "56946384770895068627425850948061079846698583721556243142233339125040923398111", "price": "0.9", "size": "6", "side": "SELL", "hash": "d169fd21e5a08c1e7d35607d5c48940f577e883f", "best_bid": "0.75", "best_ask": "0.8"}, {"asset_id": "54806808255046819356872422328886643818584171246276253781026782874036677222460", "price": "0.1", "size": "6", "side": "BUY", "hash": "d00cb46081cc4c36189e41eb433f4c45d2059617", "best_bid": "0.2", "best_ask": "0.25"}], "timestamp": "1769384166343", "event_type": "price_change"}}
{"_local_timestamp": "2026-01-25T23:36:06.434686+00:00", "data": {"market": "0x26c050cf067df27a911df254445dece1b69185a84702c728a38cefc3e30bb76d", "price_changes": [{"asset_id": "7204710211839601265032236088110237384158025763199065581147651013315116777518", "price": "0.875", "size": "0", "side": "BUY", "hash": "68f2367fff15f41edeba68b81ad796c006c6a7de", "best_bid": "0.879", "best_ask": "0.946"}, {"asset_id": "35515275010400866803110168023266440497655704126461026832913883753463850460136", "price": "0.125", "size": "0", "side": "SELL", "hash": "f3fc1995bade71b04a3b4ee1e25e749b7f128b6f", "best_bid": "0.054", "best_ask": "0.121"}], "timestamp": "1769384166362", "event_type": "price_change"}}
{"_local_timestamp": "2026-01-25T23:36:06.478634+00:00", "data": {"market": "0xdade564249db4b9daad8e06c21e06e2760c7c640b2be1c7016baa48bbfef83d9", "price_changes": [{"asset_id": "56946384770895068627425850948061079846698583721556243142233339125040923398111", "price": "0.8", "size": "43", "side": "SELL", "hash": "262e112f9e58bc9c23b92891b5fdde2411a81b47", "best_bid": "0.75", "best_ask": "0.8"}, {"asset_id": "54806808255046819356872422328886643818584171246276253781026782874036677222460", "price": "0.2", "size": "43", "side": "BUY", "hash": "03e0ba4d5b533245c54fa9f7e266f4ae589f5e29", "best_bid": "0.2", "best_ask": "0.25"}], "timestamp": "1769384166404", "event_type": "price_change"}}
{"_local_timestamp": "2026-01-25T23:36:06.504999+00:00", "data": {"market": "0x26c050cf067df27a911df254445dece1b69185a84702c728a38cefc3e30bb76d", "price_changes": [{"asset_id": "7204710211839601265032236088110237384158025763199065581147651013315116777518", "price": "0.843", "size": "15", "side": "BUY", "hash": "03bed87ca15cf6c59b732d223cb5e91d8c2a1b97", "best_bid": "0.879", "best_ask": "0.946"}, {"asset_id": "35515275010400866803110168023266440497655704126461026832913883753463850460136", "price": "0.157", "size": "15", "side": "SELL", "hash": "6b1bdbd58bca65cee28d33fbb42f379b5ae8cec2", "best_bid": "0.054", "best_ask": "0.121"}], "timestamp": "1769384166443", "event_type": "price_change"}}
{"_local_timestamp": "2026-01-25T23:36:06.505597+00:00", "data": {"market": "0x26c050cf067df27a911df254445dece1b69185a84702c728a38cefc3e30bb76d", "price_changes": [{"asset_id": "7204710211839601265032236088110237384158025763199065581147651013315116777518", "price": "0.843", "size": "25", "side": "BUY", "hash": "5ee01760d4d352891442d12956b4d9bd7c019d1f", "best_bid": "0.879", "best_ask": "0.946"}, {"asset_id": "35515275010400866803110168023266440497655704126461026832913883753463850460136", "price": "0.157", "size": "25", "side": "SELL", "hash": "0f6e17caaf6805fc04a86d735eb65b1a9d6c1d35", "best_bid": "0.054", "best_ask": "0.121"}], "timestamp": "1769384166444", "event_type": "price_change"}}
{"_local_timestamp": "2026-01-25T23:36:06.537227+00:00", "data": {"market": "0x26c050cf067df27a911df254445dece1b69185a84702c728a38cefc3e30bb76d", "price_changes": [{"asset_id": "7204710211839601265032236088110237384158025763199065581147651013315116777518", "price": "0.696", "size": "10", "side": "BUY", "hash": "151d2989d22e55a2e692c42f31b1c53e7c3b47e4", "best_bid": "0.879", "best_ask": "0.946"}, {"asset_id": "35515275010400866803110168023266440497655704126461026832913883753463850460136", "price": "0.304", "size": "10", "side": "SELL", "hash": "88a644f27db239efc56c4e2e453dd9d7815b94c0", "best_bid": "0.054", "best_ask": "0.121"}], "timestamp": "1769384166464", "event_type": "price_change"}}
{"_local_timestamp": "2026-01-25T23:36:07.105724+00:00", "data": {"market": "0x26c050cf067df27a911df254445dece1b69185a84702c728a38cefc3e30bb76d", "price_changes": [{"asset_id": "7204710211839601265032236088110237384158025763199065581147651013315116777518", "price": "0.696", "size": "0", "side": "BUY", "hash": "d64993dcd7150b1461d3445d21ec7c94c1d1096a", "best_bid": "0.879", "best_ask": "0.946"}, {"asset_id": "35515275010400866803110168023266440497655704126461026832913883753463850460136", "price": "0.304", "size": "0", "side": "SELL", "hash": "1dd711a1fa28a4d1aa0f33d5c298b14cdb15667e", "best_bid": "0.054", "best_ask": "0.121"}], "timestamp": "1769384167041", "event_type": "price_change"}}
{"_local_timestamp": "2026-01-25T23:36:07.273066+00:00", "data": {"market": "0x26c050cf067df27a911df254445dece1b69185a84702c728a38cefc3e30bb76d", "price_changes": [{"asset_id": "7204710211839601265032236088110237384158025763199065581147651013315116777518", "price": "0.518", "size": "10", "side": "BUY", "hash": "751a3b95bc9b10ffc68ca5e08813277967e2c07d", "best_bid": "0.879", "best_ask": "0.946"}, {"asset_id": "35515275010400866803110168023266440497655704126461026832913883753463850460136", "price": "0.482", "size": "10", "side": "SELL", "hash": "0cbf6c8f3825e7b3e473cdb4b2b33079d55c7dd3", "best_bid": "0.054", "best_ask": "0.121"}], "timestamp": "1769384167208", "event_type": "price_change"}}
{"_local_timestamp": "2026-01-25T23:36:07.599162+00:00", "data": {"market": "0xdade564249db4b9daad8e06c21e06e2760c7c640b2be1c7016baa48bbfef83d9", "price_changes": [{"asset_id": "54806808255046819356872422328886643818584171246276253781026782874036677222460", "price": "0.09", "size": "125", "side": "BUY", "hash": "9093e7ed33184b878e782dcac2c4dda0fabe14ed", "best_bid": "0.2", "best_ask": "0.25"}, {"asset_id": "56946384770895068627425850948061079846698583721556243142233339125040923398111", "price": "0.91", "size": "125", "side": "SELL", "hash": "dce90dd8829404b527a95c0cfebb3f4e6ef40e94", "best_bid": "0.75", "best_ask": "0.8"}], "timestamp": "1769384167527", "event_type": "price_change"}}
{"_local_timestamp": "2026-01-25T23:36:07.644736+00:00", "data": {"market": "0xdade564249db4b9daad8e06c21e06e2760c7c640b2be1c7016baa48bbfef83d9", "price_changes": [{"asset_id": "54806808255046819356872422328886643818584171246276253781026782874036677222460", "price": "0.19", "size": "102", "side": "BUY", "hash": "038fe3f85733c7587d067a89bcbdcfb9a0a40a80", "best_bid": "0.2", "best_ask": "0.25"}, {"asset_id": "56946384770895068627425850948061079846698583721556243142233339125040923398111", "price": "0.81", "size": "102", "side": "SELL", "hash": "2970b97a32b2bfda868cb8f6b197109468d2c768", "best_bid": "0.75", "best_ask": "0.8"}], "timestamp": "1769384167583", "event_type": "price_change"}}
{"_local_timestamp": "2026-01-25T23:36:09.782975+00:00", "data": {"market": "0x26c050cf067df27a911df254445dece1b69185a84702c728a38cefc3e30bb76d", "price_changes": [{"asset_id": "35515275010400866803110168023266440497655704126461026832913883753463850460136", "price": "0.123", "size": "43.32", "side": "SELL", "hash": "a6ce4180dace8a609661b39ab6207606b67515ac", "best_bid": "0.054", "best_ask": "0.121"}, {"asset_id": "7204710211839601265032236088110237384158025763199065581147651013315116777518", "price": "0.877", "size": "43.32", "side": "BUY", "hash": "fadd1ea563d278a187effb543c3391114e673f5f", "best_bid": "0.879", "best_ask": "0.946"}], "timestamp": "1769384169718", "event_type": "price_change"}}
{"_local_timestamp": "2026-01-25T23:36:11.226238+00:00", "data": {"market": "0x26c050cf067df27a911df254445dece1b69185a84702c728a38cefc3e30bb76d", "price_changes": [{"asset_id": "7204710211839601265032236088110237384158025763199065581147651013315116777518", "price": "0.842", "size": "0", "side": "BUY", "hash": "9a5f8c1372d493e8eae202c062bde1b71e7769b0", "best_bid": "0.879", "best_ask": "0.946"}, {"asset_id": "35515275010400866803110168023266440497655704126461026832913883753463850460136", "price": "0.158", "size": "0", "side": "SELL", "hash": "12cb040845d21862407bfb6f7013c598b84e0f86", "best_bid": "0.054", "best_ask": "0.121"}], "timestamp": "1769384171155", "event_type": "price_change"}}
{"_local_timestamp": "2026-01-25T23:36:11.264748+00:00", "data": {"market": "0x26c050cf067df27a911df254445dece1b69185a84702c728a38cefc3e30bb76d", "price_changes": [{"asset_id": "7204710211839601265032236088110237384158025763199065581147651013315116777518", "price": "0.844", "size": "20", "side": "BUY", "hash": "c7360cde60b2650dc6953f4a48a19fdea1c75503", "best_bid": "0.879", "best_ask": "0.946"}, {"asset_id": "35515275010400866803110168023266440497655704126461026832913883753463850460136", "price": "0.156", "size": "20", "side": "SELL", "hash": "2f376019d8d290b26b347ff29ae9d7509515f019", "best_bid": "0.054", "best_ask": "0.121"}], "timestamp": "1769384171189", "event_type": "price_change"}}
{"_local_timestamp": "2026-01-25T23:36:19.945854+00:00", "data": {"market": "0x26c050cf067df27a911df254445dece1b69185a84702c728a38cefc3e30bb76d", "price_changes": [{"asset_id": "35515275010400866803110168023266440497655704126461026832913883753463850460136", "price": "0.12", "size": "20", "side": "SELL", "hash": "5a045c3d1d94d7f4901f04794b6b1bd7679e1d6c", "best_bid": "0.054", "best_ask": "0.12"}, {"asset_id": "7204710211839601265032236088110237384158025763199065581147651013315116777518", "price": "0.88", "size": "20", "side": "BUY", "hash": "f70b7a4890dab977f5d8f94ddb0f0dd1c379810c", "best_bid": "0.88", "best_ask": "0.946"}], "timestamp": "1769384179869", "event_type": "price_change"}}
{"_local_timestamp": "2026-01-25T23:36:20.326681+00:00", "data": {"market": "0xdade564249db4b9daad8e06c21e06e2760c7c640b2be1c7016baa48bbfef83d9", "price_changes": [{"asset_id": "54806808255046819356872422328886643818584171246276253781026782874036677222460", "price": "0.19", "size": "50", "side": "BUY", "hash": "554172b00dfa8c9a6ebebd10295814c1ac105e31", "best_bid": "0.2", "best_ask": "0.25"}, {"asset_id": "56946384770895068627425850948061079846698583721556243142233339125040923398111", "price": "0.81", "size": "50", "side": "SELL", "hash": "93dd54d6c56155f20b2272b23016e4a2257c4539", "best_bid": "0.75", "best_ask": "0.8"}], "timestamp": "1769384180252", "event_type": "price_change"}}
{"_local_timestamp": "2026-01-25T23:36:20.328184+00:00", "data": {"market": "0x26c050cf067df27a911df254445dece1b69185a84702c728a38cefc3e30bb76d", "price_changes": [{"asset_id": "7204710211839601265032236088110237384158025763199065581147651013315116777518", "price": "0.878", "size": "45", "side": "BUY", "hash": "10dc77a930acf71ad8b793d65944a37a30f18880", "best_bid": "0.88", "best_ask": "0.946"}, {"asset_id": "35515275010400866803110168023266440497655704126461026832913883753463850460136", "price": "0.122", "size": "45", "side": "SELL", "hash": "4255cc55b77c1f33e8add843cb94312d03acab61", "best_bid": "0.054", "best_ask": "0.12"}], "timestamp": "1769384180252", "event_type": "price_change"}}
{"_local_timestamp": "2026-01-25T23:36:21.571502+00:00", "data": {"market": "0xdade564249db4b9daad8e06c21e06e2760c7c640b2be1c7016baa48bbfef83d9", "price_changes": [{"asset_id": "56946384770895068627425850948061079846698583721556243142233339125040923398111", "price": "0.8", "size": "13", "side": "SELL", "hash": "ae0f461982b48b965513bf4728b6b6dccd9e8423", "best_bid": "0.75", "best_ask": "0.8"}, {"asset_id": "54806808255046819356872422328886643818584171246276253781026782874036677222460", "price": "0.2", "size": "13", "side": "BUY", "hash": "22af1798281567f7ac0aba0f6a4a10ff220a7bec", "best_bid": "0.2", "best_ask": "0.25"}], "timestamp": "1769384181455", "event_type": "price_change"}}
{"_local_timestamp": "2026-01-25T23:36:21.631199+00:00", "data": {"market": "0xdade564249db4b9daad8e06c21e06e2760c7c640b2be1c7016baa48bbfef83d9", "price_changes": [{"asset_id": "56946384770895068627425850948061079846698583721556243142233339125040923398111", "price": "0.9", "size": "36", "side": "SELL", "hash": "05f0f0089e934c45fa99ed0e9249f2280c4ba267", "best_bid": "0.75", "best_ask": "0.8"}, {"asset_id": "54806808255046819356872422328886643818584171246276253781026782874036677222460", "price": "0.1", "size": "36", "side": "BUY", "hash": "5b4c6de182f74e0153f112675cb04b785338e58d", "best_bid": "0.2", "best_ask": "0.25"}], "timestamp": "1769384181532", "event_type": "price_change"}}
{"_local_timestamp": "2026-01-25T23:36:22.506557+00:00", "data": {"market": "0xdade564249db4b9daad8e06c21e06e2760c7c640b2be1c7016baa48bbfef83d9", "price_changes": [{"asset_id": "54806808255046819356872422328886643818584171246276253781026782874036677222460", "price": "0.19", "size": "20", "side": "BUY", "hash": "5c840d8b0e3666f7a8b296a34193d5afe6bead23", "best_bid": "0.2", "best_ask": "0.25"}, {"asset_id": "56946384770895068627425850948061079846698583721556243142233339125040923398111", "price": "0.81", "size": "20", "side": "SELL", "hash": "e4d622b8d28785e15e79d44214bc2af09a1e6288", "best_bid": "0.75", "best_ask": "0.8"}], "timestamp": "1769384182438", "event_type": "price_change"}}
{"_local_timestamp": "2026-01-25T23:36:22.563648+00:00", "data": {"market": "0xdade564249db4b9daad8e06c21e06e2760c7c640b2be1c7016baa48bbfef83d9", "price_changes": [{"asset_id": "54806808255046819356872422328886643818584171246276253781026782874036677222460", "price": "0.09", "size": "155", "side": "BUY", "hash": "7fa047051f0a6e35b849b50e5847900d21dd1b52", "best_bid": "0.2", "best_ask": "0.25"}, {"asset_id": "56946384770895068627425850948061079846698583721556243142233339125040923398111", "price": "0.91", "size": "155", "side": "SELL", "hash": "cd62faab5dfe8ce105a74229ee9310ebbb49179f", "best_bid": "0.75", "best_ask": "0.8"}], "timestamp": "1769384182500", "event_type": "price_change"}}
{"_local_timestamp": "2026-01-25T23:36:33.074637+00:00", "data": {"market": "0xbd8114a52eed432265735ebfe174ce257047a94b378cbc36246ca0dba7a07c33", "price_changes": [{"asset_id": "113403179930780844692419404105573805354679366394847558149476632392300380613010", "price": "0.002", "size": "4915", "side": "BUY", "hash": "953797a1317fc5c0dc083d81dc5f4c100cd97524", "best_bid": "0.004", "best_ask": "0.005"}, {"asset_id": "34347535308090847792552379030322073016871399676099560255182105326984970187327", "price": "0.998", "size": "4915", "side": "SELL", "hash": "14e61cfa822cf8f3fc84ba5f91adc16b1c867257", "best_bid": "0.995", "best_ask": "0.996"}], "timestamp": "1769384192989", "event_type": "price_change"}}
{"_local_timestamp": "2026-01-25T23:36:55.279658+00:00", "data": {"market": "0x9ae2d920fa7f4da49b6524361fa2e7260cad95631cc8e443ddeb2d70d2f1ccfd", "price_changes": [{"asset_id": "4942360482005244918796292265006007704327799854749267861336630583944467908299", "price": "0.455", "size": "216", "side": "BUY", "hash": "63df62b53cdbcf2a7c801174bd047a2f32555177", "best_bid": "0.997", "best_ask": "0.998"}, {"asset_id": "113409560089971005551069019900801779309141794188263770657345157175671976775527", "price": "0.545", "size": "216", "side": "SELL", "hash": "abdc10fa60416bc425c3d2036b50453309e07af3", "best_bid": "0.002", "best_ask": "0.003"}], "timestamp": "1769384215021", "event_type": "price_change"}}
{"_local_timestamp": "2026-01-25T23:36:56.242515+00:00", "data": {"market": "0x9ae2d920fa7f4da49b6524361fa2e7260cad95631cc8e443ddeb2d70d2f1ccfd", "price_changes": [{"asset_id": "4942360482005244918796292265006007704327799854749267861336630583944467908299", "price": "0.456", "size": "279", "side": "BUY", "hash": "4701e10c29e5a047a15be1f50cdad162a4280ef7", "best_bid": "0.997", "best_ask": "0.998"}, {"asset_id": "113409560089971005551069019900801779309141794188263770657345157175671976775527", "price": "0.544", "size": "279", "side": "SELL", "hash": "208f7a02585084bcc89bbf839cee29977508f01f", "best_bid": "0.002", "best_ask": "0.003"}], "timestamp": "1769384215684", "event_type": "price_change"}}
{"_local_timestamp": "2026-01-25T23:36:57.825490+00:00", "data": {"market": "0x237e02f976b2e3da26581188ac589dc2fc205fe720e8fada962fc6df2cd2eba6", "price_changes": [{"asset_id": "31822061374462131695517583398967119857496606423169716082969971946507327592886", "price": "0.419", "size": "60", "side": "BUY", "hash": "24b974d15c7fbb69ad094971331515cdb26a3685", "best_bid": "0.997", "best_ask": "0.998"}, {"asset_id": "79715101438926538809511303806850682615698911910840134983914648955752864757858", "price": "0.581", "size": "60", "side": "SELL", "hash": "937c22d0fbe6de6ad823ed0a5f1229b65a4a7367", "best_bid": "0.002", "best_ask": "0.003"}], "timestamp": "1769384217243", "event_type": "price_change"}}
{"_local_timestamp": "2026-01-25T23:36:57.910944+00:00", "data": {"market": "0x9ae2d920fa7f4da49b6524361fa2e7260cad95631cc8e443ddeb2d70d2f1ccfd", "price_changes": [{"asset_id": "4942360482005244918796292265006007704327799854749267861336630583944467908299", "price": "0.455", "size": "0", "side": "BUY", "hash": "89f2a67dbb087f764daca516d54f464fe8802cfa", "best_bid": "0.997", "best_ask": "0.998"}, {"asset_id": "113409560089971005551069019900801779309141794188263770657345157175671976775527", "price": "0.545", "size": "0", "side": "SELL", "hash": "646ea7105072d6b0e8d7437f1fdef805780e19e1", "best_bid": "0.002", "best_ask": "0.003"}], "timestamp": "1769384217238", "event_type": "price_change"}}
{"_local_timestamp": "2026-01-25T23:36:58.881905+00:00", "data": {"market": "0x237e02f976b2e3da26581188ac589dc2fc205fe720e8fada962fc6df2cd2eba6", "price_changes": [{"asset_id": "79715101438926538809511303806850682615698911910840134983914648955752864757858", "price": "0.002", "size": "1812.68", "side": "BUY", "hash": "49c396294052e6df32e6e39dcb222578db3f9579", "best_bid": "0.002", "best_ask": "0.003"}, {"asset_id": "31822061374462131695517583398967119857496606423169716082969971946507327592886", "price": "0.998", "size": "1812.68", "side": "SELL", "hash": "272582401dc22c597ab7848cfd47e35a411b6768", "best_bid": "0.997", "best_ask": "0.998"}], "timestamp": "1769384218493", "event_type": "price_change"}}
{"_local_timestamp": "2026-01-25T23:36:58.930223+00:00", "data": {"market": "0xbecfcab892fc16aabf72d5180094c6c51ba33ac8005c3f9497b7c6d05bbee7f1", "price_changes": [{"asset_id": "98146342803923051979042568419031220153888306546081565583042852359988504135784", "price": "0.002", "size": "1681.48", "side": "BUY", "hash": "2d44802145379cec7c2bb880f5bb68afe92c4c84", "best_bid": "0.002", "best_ask": "0.003"}, {"asset_id": "25498200346709217272214635487844720997180443012933651618839363828578469169844", "price": "0.998", "size": "1681.48", "side": "SELL", "hash": "13d13b08513b7f64ab19df6b9859f700b7094ac4", "best_bid": "0.997", "best_ask": "0.998"}], "timestamp": "1769384218513", "event_type": "price_change"}}
{"_local_timestamp": "2026-01-25T23:36:58.946293+00:00", "data": {"market": "0xbf2cba044810364349878bce032b495875a0ae8b575286388e79cc4bddde4a6c", "price_changes": [{"asset_id": "80303106904766949344727438756563505749348738369775655357626215899018784021389", "price": "0.002", "size": "1155.73", "side": "BUY", "hash": "cd341ea3fb15e2c822386a2c461b1198899a1a43", "best_bid": "0.002", "best_ask": "0.003"}, {"asset_id": "52973946067415555340752362838729163232972184824595142980403702383146397821473", "price": "0.998", "size": "1155.73", "side": "SELL", "hash": "ffb404c9523f33ce408e3b7112cdd99d3c513a36", "best_bid": "0.997", "best_ask": "0.998"}], "timestamp": "1769384218519", "event_type": "price_change"}}
{"_local_timestamp": "2026-01-25T23:37:02.524161+00:00", "data": {"market": "0x9ae2d920fa7f4da49b6524361fa2e7260cad95631cc8e443ddeb2d70d2f1ccfd", "price_changes": [{"asset_id": "4942360482005244918796292265006007704327799854749267861336630583944467908299", "price": "0.45", "size": "0", "side": "BUY", "hash": "4bb7273984a9f6f8e5331f7d11165e9d76281b49", "best_bid": "0.997", "best_ask": "0.998"}, {"asset_id": "113409560089971005551069019900801779309141794188263770657345157175671976775527", "price": "0.55", "size": "0", "side": "SELL", "hash": "51f7eb3853fad1b3d6a88b6208eb5bb39b80fe0d", "best_bid": "0.002", "best_ask": "0.003"}], "timestamp": "1769384222345", "event_type": "price_change"}}
{"_local_timestamp": "2026-01-25T23:37:02.570561+00:00", "data": {"market": "0x9ae2d920fa7f4da49b6524361fa2e7260cad95631cc8e443ddeb2d70d2f1ccfd", "price_changes": [{"asset_id": "4942360482005244918796292265006007704327799854749267861336630583944467908299", "price": "0.457", "size": "5", "side": "BUY", "hash": "d0d8215c1d6f39aa2b243ac78d91c60174d97e8c", "best_bid": "0.997", "best_ask": "0.998"}, {"asset_id": "113409560089971005551069019900801779309141794188263770657345157175671976775527", "price": "0.543", "size": "5", "side": "SELL", "hash": "1e7e00b312a54de3e01c794b8cd72023754aca73", "best_bid": "0.002", "best_ask": "0.003"}], "timestamp": "1769384222389", "event_type": "price_change"}}
{"_local_timestamp": "2026-01-25T23:37:08.081159+00:00", "data": {"market": "0x26c050cf067df27a911df254445dece1b69185a84702c728a38cefc3e30bb76d", "price_changes": [{"asset_id": "7204710211839601265032236088110237384158025763199065581147651013315116777518", "price": "0.877", "size": "0", "side": "BUY", "hash": "2b9a857029d8e1cb45badc03e74946b1f30f7950", "best_bid": "0.88", "best_ask": "0.946"}, {"asset_id": "35515275010400866803110168023266440497655704126461026832913883753463850460136", "price": "0.123", "size": "0", "side": "SELL", "hash": "5b5885a3e03e212ffcac0a5afe5f5eb1760fc6db", "best_bid": "0.054", "best_ask": "0.12"}], "timestamp": "1769384227903", "event_type": "price_change"}}
{"_local_timestamp": "2026-01-25T23:37:11.036997+00:00", "data": {"market": "0x9ae2d920fa7f4da49b6524361fa2e7260cad95631cc8e443ddeb2d70d2f1ccfd", "price_changes": [{"asset_id": "4942360482005244918796292265006007704327799854749267861336630583944467908299", "price": "0.457", "size": "114", "side": "BUY", "hash": "41b86c66613c89a3fe464a912d96d6a8c1cc5817", "best_bid": "0.997", "best_ask": "0.998"}, {"asset_id": "113409560089971005551069019900801779309141794188263770657345157175671976775527", "price": "0.543", "size": "114", "side": "SELL", "hash": "3cc7c744070cf16253ef8039e0b903c583b4e3e3", "best_bid": "0.002", "best_ask": "0.003"}], "timestamp": "1769384230968", "event_type": "price_change"}}
{"_local_timestamp": "2026-01-25T23:37:11.048333+00:00", "data": {"market": "0x237e02f976b2e3da26581188ac589dc2fc205fe720e8fada962fc6df2cd2eba6", "price_changes": [{"asset_id": "31822061374462131695517583398967119857496606423169716082969971946507327592886", "price": "0.42", "size": "62", "side": "BUY", "hash": "5bd7eae073c27c3115ae37e2e87630818674a4c4", "best_bid": "0.997", "best_ask": "0.998"}, {"asset_id": "79715101438926538809511303806850682615698911910840134983914648955752864757858", "price": "0.58", "size": "62", "side": "SELL", "hash": "451f40efd7af88e1e0cf7626a59746ff660f2bbb", "best_bid": "0.002", "best_ask": "0.003"}], "timestamp": "1769384230968", "event_type": "price_change"}}
{"_local_timestamp": "2026-01-25T23:37:14.313362+00:00", "data": {"market": "0x26c050cf067df27a911df254445dece1b69185a84702c728a38cefc3e30bb76d", "price_changes": [{"asset_id": "7204710211839601265032236088110237384158025763199065581147651013315116777518", "price": "0.695", "size": "0", "side": "BUY", "hash": "b7f7e25ad78950890b1d5d5007346527ddcdefea", "best_bid": "0.88", "best_ask": "0.946"}, {"asset_id": "35515275010400866803110168023266440497655704126461026832913883753463850460136", "price": "0.305", "size": "0", "side": "SELL", "hash": "509fd3c6a7d0ba1904a894bccb9171316215e98a", "best_bid": "0.054", "best_ask": "0.12"}], "timestamp": "1769384234240", "event_type": "price_change"}}
{"_local_timestamp": "2026-01-25T23:37:14.313987+00:00", "data": {"market": "0x26c050cf067df27a911df254445dece1b69185a84702c728a38cefc3e30bb76d", "price_changes": [{"asset_id": "7204710211839601265032236088110237384158025763199065581147651013315116777518", "price": "0.512", "size": "0", "side": "BUY", "hash": "b7f7e25ad78950890b1d5d5007346527ddcdefea", "best_bid": "0.88", "best_ask": "0.946"}, {"asset_id": "35515275010400866803110168023266440497655704126461026832913883753463850460136", "price": "0.488", "size": "0", "side": "SELL", "hash": "509fd3c6a7d0ba1904a894bccb9171316215e98a", "best_bid": "0.054", "best_ask": "0.12"}], "timestamp": "1769384234240", "event_type": "price_change"}}
{"_local_timestamp": "2026-01-25T23:37:14.993257+00:00", "data": {"market": "0x26c050cf067df27a911df254445dece1b69185a84702c728a38cefc3e30bb76d", "price_changes": [{"asset_id": "7204710211839601265032236088110237384158025763199065581147651013315116777518", "price": "0.841", "size": "100", "side": "BUY", "hash": "fbf92e89d8b43be60ea8516a4b1f46eb265e7d27", "best_bid": "0.88", "best_ask": "0.946"}, {"asset_id": "35515275010400866803110168023266440497655704126461026832913883753463850460136", "price": "0.159", "size": "100", "side": "SELL", "hash": "997c64ef9f2eff2e77585d59ab066f8481dac01f", "best_bid": "0.054", "best_ask": "0.12"}], "timestamp": "1769384234926", "event_type": "price_change"}}
{"_local_timestamp": "2026-01-25T23:37:15.038460+00:00", "data": {"market": "0x26c050cf067df27a911df254445dece1b69185a84702c728a38cefc3e30bb76d", "price_changes": [{"asset_id": "7204710211839601265032236088110237384158025763199065581147651013315116777518", "price": "0.801", "size": "115", "side": "BUY", "hash": "703a50502be76fa998ff585a1fdc7d28752078c2", "best_bid": "0.88", "best_ask": "0.946"}, {"asset_id": "35515275010400866803110168023266440497655704126461026832913883753463850460136", "price": "0.199", "size": "115", "side": "SELL", "hash": "25c5528949bf305984b46b5955191d0bce22f6d2", "best_bid": "0.054", "best_ask": "0.12"}], "timestamp": "1769384234968", "event_type": "price_change"}}
{"_local_timestamp": "2026-01-25T23:37:59.967492+00:00", "data": {"market": "0x26c050cf067df27a911df254445dece1b69185a84702c728a38cefc3e30bb76d", "price_changes": [{"asset_id": "7204710211839601265032236088110237384158025763199065581147651013315116777518", "price": "0.062", "size": "0", "side": "BUY", "hash": "038e54583243a46aa07f1ca724cf6ad9d28309fd", "best_bid": "0.88", "best_ask": "0.946"}, {"asset_id": "35515275010400866803110168023266440497655704126461026832913883753463850460136", "price": "0.938", "size": "0", "side": "SELL", "hash": "5f3570e80f36c7216a68742fee37338c9140b3bd", "best_bid": "0.054", "best_ask": "0.12"}], "timestamp": "1769384279875", "event_type": "price_change"}}
{"_local_timestamp": "2026-01-25T23:38:00.189594+00:00", "data": {"market": "0x237e02f976b2e3da26581188ac589dc2fc205fe720e8fada962fc6df2cd2eba6", "price_changes": [{"asset_id": "31822061374462131695517583398967119857496606423169716082969971946507327592886", "price": "0.481", "size": "0", "side": "BUY", "hash": "c2449ec1e7fac6b6a804682de9818953831ca82c", "best_bid": "0.997", "best_ask": "0.998"}, {"asset_id": "79715101438926538809511303806850682615698911910840134983914648955752864757858", "price": "0.519", "size": "0", "side": "SELL", "hash": "414e77ec4747b14bb3099e83a266b38755ec9478", "best_bid": "0.002", "best_ask": "0.003"}], "timestamp": "1769384280061", "event_type": "price_change"}}
{"_local_timestamp": "2026-01-25T23:38:00.258165+00:00", "data": {"market": "0x9ae2d920fa7f4da49b6524361fa2e7260cad95631cc8e443ddeb2d70d2f1ccfd", "price_changes": [{"asset_id": "4942360482005244918796292265006007704327799854749267861336630583944467908299", "price": "0.866", "size": "15", "side": "BUY", "hash": "97d091d2c9ff2150419a9cf267828b9ee394d409", "best_bid": "0.997", "best_ask": "0.998"}, {"asset_id": "113409560089971005551069019900801779309141794188263770657345157175671976775527", "price": "0.134", "size": "15", "side": "SELL", "hash": "d169515b7cfe576f2acdc2f7aadbafcf99cb7ac0", "best_bid": "0.002", "best_ask": "0.003"}], "timestamp": "1769384280145", "event_type": "price_change"}}
{"_local_timestamp": "2026-01-25T23:38:00.364391+00:00", "data": {"market": "0x26c050cf067df27a911df254445dece1b69185a84702c728a38cefc3e30bb76d", "price_changes": [{"asset_id": "7204710211839601265032236088110237384158025763199065581147651013315116777518", "price": "0.052", "size": "11.61", "side": "BUY", "hash": "66ac4bc87a66e0cd2ac11de3a37edaea8845ca16", "best_bid": "0.88", "best_ask": "0.946"}, {"asset_id": "35515275010400866803110168023266440497655704126461026832913883753463850460136", "price": "0.948", "size": "11.61", "side": "SELL", "hash": "70cd7cd0a3c87addc453fe9d505d2b57dc26d66d", "best_bid": "0.054", "best_ask": "0.12"}], "timestamp": "1769384280271", "event_type": "price_change"}}
{"_local_timestamp": "2026-01-25T23:38:00.365098+00:00", "data": {"market": "0x237e02f976b2e3da26581188ac589dc2fc205fe720e8fada962fc6df2cd2eba6", "price_changes": [{"asset_id": "31822061374462131695517583398967119857496606423169716082969971946507327592886", "price": "0.483", "size": "118", "side": "BUY", "hash": "167f19ca58321074c576c131dde403a38752bbe2", "best_bid": "0.997", "best_ask": "0.998"}, {"asset_id": "79715101438926538809511303806850682615698911910840134983914648955752864757858", "price": "0.517", "size": "118", "side": "SELL", "hash": "e0e7eb21ea923ac622fb7e9c62ee9418ca9b8519", "best_bid": "0.002", "best_ask": "0.003"}], "timestamp": "1769384280272", "event_type": "price_change"}}
{"_local_timestamp": "2026-01-25T23:38:00.366052+00:00", "data": {"market": "0x237e02f976b2e3da26581188ac589dc2fc205fe720e8fada962fc6df2cd2eba6", "price_changes": [{"asset_id": "31822061374462131695517583398967119857496606423169716082969971946507327592886", "price": "0.483", "size": "128", "side": "BUY", "hash": "798e8e5d63a36ddc933014747cbcdeb46cdc41d8", "best_bid": "0.997", "best_ask": "0.998"}, {"asset_id": "79715101438926538809511303806850682615698911910840134983914648955752864757858", "price": "0.517", "size": "128", "side": "SELL", "hash": "1ad08a44ed118a8f7b63b2c141b42af1cdc64c5b", "best_bid": "0.002", "best_ask": "0.003"}], "timestamp": "1769384280277", "event_type": "price_change"}}
{"_local_timestamp": "2026-01-25T23:38:01.560622+00:00", "data": {"market": "0x237e02f976b2e3da26581188ac589dc2fc205fe720e8fada962fc6df2cd2eba6", "price_changes": [{"asset_id": "31822061374462131695517583398967119857496606423169716082969971946507327592886", "price": "0.482", "size": "0", "side": "BUY", "hash": "26d1a32d0ee3be88e256b299e6ddef8e38536192", "best_bid": "0.997", "best_ask": "0.998"}, {"asset_id": "79715101438926538809511303806850682615698911910840134983914648955752864757858", "price": "0.518", "size": "0", "side": "SELL", "hash": "9e3017d9d159390fd9a038be7bbd9fc30ea87750", "best_bid": "0.002", "best_ask": "0.003"}], "timestamp": "1769384281441", "event_type": "price_change"}}
{"_local_timestamp": "2026-01-25T23:38:01.593245+00:00", "data": {"market": "0x237e02f976b2e3da26581188ac589dc2fc205fe720e8fada962fc6df2cd2eba6", "price_changes": [{"asset_id": "31822061374462131695517583398967119857496606423169716082969971946507327592886", "price": "0.484", "size": "20", "side": "BUY", "hash": "86b18f99c797fd907858d8d0d5b8d0a5ec88a090", "best_bid": "0.997", "best_ask": "0.998"}, {"asset_id": "79715101438926538809511303806850682615698911910840134983914648955752864757858", "price": "0.516", "size": "20", "side": "SELL", "hash": "fd6be468245912473b782c47e60cb0fdd5e94b02", "best_bid": "0.002", "best_ask": "0.003"}], "timestamp": "1769384281470", "event_type": "price_change"}}
{"_local_timestamp": "2026-01-25T23:38:01.717408+00:00", "data": {"market": "0x237e02f976b2e3da26581188ac589dc2fc205fe720e8fada962fc6df2cd2eba6", "price_changes": [{"asset_id": "31822061374462131695517583398967119857496606423169716082969971946507327592886", "price": "0.483", "size": "10", "side": "BUY", "hash": "c19e98f4d4e0a29a23400d4e3b6862d5c6f51f6a", "best_bid": "0.997", "best_ask": "0.998"}, {"asset_id": "79715101438926538809511303806850682615698911910840134983914648955752864757858", "price": "0.517", "size": "10", "side": "SELL", "hash": "c76f028f47c7c1e07f5f08d6f14b442443032f31", "best_bid": "0.002", "best_ask": "0.003"}], "timestamp": "1769384281590", "event_type": "price_change"}}
{"_local_timestamp": "2026-01-25T23:38:19.304310+00:00", "data": {"market": "0x26c050cf067df27a911df254445dece1b69185a84702c728a38cefc3e30bb76d", "price_changes": [{"asset_id": "7204710211839601265032236088110237384158025763199065581147651013315116777518", "price": "0.88", "size": "63.18", "side": "BUY", "hash": "9f0f6ba8c40e812d5ba32e5e74bb4352a0ed3065", "best_bid": "0.88", "best_ask": "0.946"}, {"asset_id": "35515275010400866803110168023266440497655704126461026832913883753463850460136", "price": "0.12", "size": "63.18", "side": "SELL", "hash": "aca2aaee917dabc26d5f9fd10146cdc91e9fc600", "best_bid": "0.054", "best_ask": "0.12"}], "timestamp": "1769384299234", "event_type": "price_change"}}
{"_local_timestamp": "2026-01-25T23:38:21.204661+00:00", "data": {"market": "0x26c050cf067df27a911df254445dece1b69185a84702c728a38cefc3e30bb76d", "price_changes": [{"asset_id": "7204710211839601265032236088110237384158025763199065581147651013315116777518", "price": "0.27", "size": "0", "side": "BUY", "hash": "6ee6a9259320401dfbc4f82f4d30623552e2f677", "best_bid": "0.88", "best_ask": "0.946"}, {"asset_id": "35515275010400866803110168023266440497655704126461026832913883753463850460136", "price": "0.73", "size": "0", "side": "SELL", "hash": "607987dcf27470a4e1c6725fe22a9664abc42799", "best_bid": "0.054", "best_ask": "0.12"}], "timestamp": "1769384301109", "event_type": "price_change"}}
{"_local_timestamp": "2026-01-25T23:38:21.639973+00:00", "data": {"market": "0x26c050cf067df27a911df254445dece1b69185a84702c728a38cefc3e30bb76d", "price_changes": [{"asset_id": "7204710211839601265032236088110237384158025763199065581147651013315116777518", "price": "0.28", "size": "192.85", "side": "BUY", "hash": "78fd6c7521181d97e07754d8cd9e662cb0994a0e", "best_bid": "0.88", "best_ask": "0.946"}, {"asset_id": "35515275010400866803110168023266440497655704126461026832913883753463850460136", "price": "0.72", "size": "192.85", "side": "SELL", "hash": "b7d29ef22fc50cef961a58dde8c48586dec7bb41", "best_bid": "0.054", "best_ask": "0.12"}], "timestamp": "1769384301467", "event_type": "price_change"}}
{"_local_timestamp": "2026-01-25T23:38:30.516850+00:00", "data": {"market": "0x26c050cf067df27a911df254445dece1b69185a84702c728a38cefc3e30bb76d", "price_changes": [{"asset_id": "7204710211839601265032236088110237384158025763199065581147651013315116777518", "price": "0.879", "size": "0", "side": "BUY", "hash": "ca843952f89eed6029203d7fe10d14a83306abab", "best_bid": "0.88", "best_ask": "0.946"}, {"asset_id": "35515275010400866803110168023266440497655704126461026832913883753463850460136", "price": "0.121", "size": "0", "side": "SELL", "hash": "f6f78975865896ad2b64974635641efc9d5d7ef7", "best_bid": "0.054", "best_ask": "0.12"}], "timestamp": "1769384310448", "event_type": "price_change"}}
{"_local_timestamp": "2026-01-25T23:39:22.456429+00:00", "data": {"market": "0xbecfcab892fc16aabf72d5180094c6c51ba33ac8005c3f9497b7c6d05bbee7f1", "price_changes": [{"asset_id": "25498200346709217272214635487844720997180443012933651618839363828578469169844", "price": "0.428", "size": "233", "side": "BUY", "hash": "46068fda359f369ea5610abeaddbdbf4a86b7460", "best_bid": "0.997", "best_ask": "0.998"}, {"asset_id": "98146342803923051979042568419031220153888306546081565583042852359988504135784", "price": "0.572", "size": "233", "side": "SELL", "hash": "cf28af27f7c7465deb18c6b20ae32e7814a21afd", "best_bid": "0.002", "best_ask": "0.003"}], "timestamp": "1769384362214", "event_type": "price_change"}}
{"_local_timestamp": "2026-01-25T23:39:22.492430+00:00", "data": {"market": "0x237e02f976b2e3da26581188ac589dc2fc205fe720e8fada962fc6df2cd2eba6", "price_changes": [{"asset_id": "31822061374462131695517583398967119857496606423169716082969971946507327592886", "price": "0.419", "size": "0", "side": "BUY", "hash": "28a6e5d024ec9e70856d008f854d521b5ccd497a", "best_bid": "0.997", "best_ask": "0.998"}, {"asset_id": "79715101438926538809511303806850682615698911910840134983914648955752864757858", "price": "0.581", "size": "0", "side": "SELL", "hash": "9c9588ecd123a2d04dc0e73f0daf0c506e5e4921", "best_bid": "0.002", "best_ask": "0.003"}], "timestamp": "1769384362216", "event_type": "price_change"}}
{"_local_timestamp": "2026-01-25T23:39:22.631375+00:00", "data": {"market": "0x9ae2d920fa7f4da49b6524361fa2e7260cad95631cc8e443ddeb2d70d2f1ccfd", "price_changes": [{"asset_id": "4942360482005244918796292265006007704327799854749267861336630583944467908299", "price": "0.866", "size": "0", "side": "BUY", "hash": "d62e8920cf1065868451614cb3c337377e108047", "best_bid": "0.997", "best_ask": "0.998"}, {"asset_id": "113409560089971005551069019900801779309141794188263770657345157175671976775527", "price": "0.134", "size": "0", "side": "SELL", "hash": "b0fa855252c4877049e5d60d7a9c0c00c438a70a", "best_bid": "0.002", "best_ask": "0.003"}], "timestamp": "1769384362494", "event_type": "price_change"}}
{"_local_timestamp": "2026-01-25T23:39:22.975994+00:00", "data": {"market": "0x237e02f976b2e3da26581188ac589dc2fc205fe720e8fada962fc6df2cd2eba6", "price_changes": [{"asset_id": "31822061374462131695517583398967119857496606423169716082969971946507327592886", "price": "0.414", "size": "301", "side": "BUY", "hash": "f68e19f36cdd81d85df0533ee536918b7e31922b", "best_bid": "0.997", "best_ask": "0.998"}, {"asset_id": "79715101438926538809511303806850682615698911910840134983914648955752864757858", "price": "0.586", "size": "301", "side": "SELL", "hash": "2f03fc85d3c31127c6b3b6850a0072f8cea13cbc", "best_bid": "0.002", "best_ask": "0.003"}], "timestamp": "1769384362727", "event_type": "price_change"}}
{"_local_timestamp": "2026-01-25T23:39:22.999163+00:00", "data": {"market": "0xbecfcab892fc16aabf72d5180094c6c51ba33ac8005c3f9497b7c6d05bbee7f1", "price_changes": [{"asset_id": "25498200346709217272214635487844720997180443012933651618839363828578469169844", "price": "0.454", "size": "134", "side": "BUY", "hash": "68995b8975975ca3083d3d95db2a292862b62161", "best_bid": "0.997", "best_ask": "0.998"}, {"asset_id": "98146342803923051979042568419031220153888306546081565583042852359988504135784", "price": "0.546", "size": "134", "side": "SELL", "hash": "47a0c4c94e32e5acac9f10b80dcf8051262bfd07", "best_bid": "0.002", "best_ask": "0.003"}], "timestamp": "1769384362757", "event_type": "price_change"}}
{"_local_timestamp": "2026-01-25T23:39:27.162874+00:00", "data": {"market": "0x9ae2d920fa7f4da49b6524361fa2e7260cad95631cc8e443ddeb2d70d2f1ccfd", "price_changes": [{"asset_id": "4942360482005244918796292265006007704327799854749267861336630583944467908299", "price": "0.867", "size": "0", "side": "BUY", "hash": "e59206102633e0f46b6aacf69cf8b50a81d3762a", "best_bid": "0.997", "best_ask": "0.998"}, {"asset_id": "113409560089971005551069019900801779309141794188263770657345157175671976775527", "price": "0.133", "size": "0", "side": "SELL", "hash": "9ecec1d84c4ccb9d34489b24c68b604429e52cd0", "best_bid": "0.002", "best_ask": "0.003"}], "timestamp": "1769384367092", "event_type": "price_change"}}
{"_local_timestamp": "2026-01-25T23:39:27.184923+00:00", "data": {"market": "0x9ae2d920fa7f4da49b6524361fa2e7260cad95631cc8e443ddeb2d70d2f1ccfd", "price_changes": [{"asset_id": "4942360482005244918796292265006007704327799854749267861336630583944467908299", "price": "0.865", "size": "20", "side": "BUY", "hash": "af0e15e46f2ec2dcccc766d1ec0fd91f1884f2a9", "best_bid": "0.997", "best_ask": "0.998"}, {"asset_id": "113409560089971005551069019900801779309141794188263770657345157175671976775527", "price": "0.135", "size": "20", "side": "SELL", "hash": "31765a8f596d3be26f59fef37b262b8bb2f35df1", "best_bid": "0.002", "best_ask": "0.003"}], "timestamp": "1769384367121", "event_type": "price_change"}}
{"_local_timestamp": "2026-01-25T23:39:39.502933+00:00", "data": {"market": "0xdade564249db4b9daad8e06c21e06e2760c7c640b2be1c7016baa48bbfef83d9", "price_changes": [{"asset_id": "54806808255046819356872422328886643818584171246276253781026782874036677222460", "price": "0.11", "size": "0", "side": "BUY", "hash": "a22e9c8b71fd4fc39647a0047a67af3250886d8a", "best_bid": "0.2", "best_ask": "0.25"}, {"asset_id": "56946384770895068627425850948061079846698583721556243142233339125040923398111", "price": "0.89", "size": "0", "side": "SELL", "hash": "7a147936b68d0e5ac9fba5a00443309e348de9d5", "best_bid": "0.75", "best_ask": "0.8"}], "timestamp": "1769384379434", "event_type": "price_change"}}
{"_local_timestamp": "2026-01-25T23:39:41.842777+00:00", "data": {"market": "0xdade564249db4b9daad8e06c21e06e2760c7c640b2be1c7016baa48bbfef83d9", "price_changes": [{"asset_id": "54806808255046819356872422328886643818584171246276253781026782874036677222460", "price": "0.11", "size": "9.66", "side": "BUY", "hash": "0fca84bbe6081c3a650fbd9c2bd65765a6ed3362", "best_bid": "0.2", "best_ask": "0.25"}, {"asset_id": "56946384770895068627425850948061079846698583721556243142233339125040923398111", "price": "0.89", "size": "9.66", "side": "SELL", "hash": "f0e359cef36065de094f87cd2a902ae787eb89f0", "best_bid": "0.75", "best_ask": "0.8"}], "timestamp": "1769384381756", "event_type": "price_change"}}
{"_local_timestamp": "2026-01-25T23:39:45.938276+00:00", "data": {"market": "0x26c050cf067df27a911df254445dece1b69185a84702c728a38cefc3e30bb76d", "price_changes": [{"asset_id": "7204710211839601265032236088110237384158025763199065581147651013315116777518", "price": "0.878", "size": "0", "side": "BUY", "hash": "659a2e81e41c76ac57aa6bdacc982f7972938119", "best_bid": "0.88", "best_ask": "0.946"}, {"asset_id": "35515275010400866803110168023266440497655704126461026832913883753463850460136", "price": "0.122", "size": "0", "side": "SELL", "hash": "5855ee3539e9b98ec7dd1257759d371081fd3afd", "best_bid": "0.054", "best_ask": "0.12"}], "timestamp": "1769384385730", "event_type": "price_change"}}
{"_local_timestamp": "2026-01-25T23:39:58.941388+00:00", "data": {"market": "0x26c050cf067df27a911df254445dece1b69185a84702c728a38cefc3e30bb76d", "price_changes": [{"asset_id": "7204710211839601265032236088110237384158025763199065581147651013315116777518", "price": "0.841", "size": "0", "side": "BUY", "hash": "738dcbbbb429988f2a49592433a4b81dacac7903", "best_bid": "0.88", "best_ask": "0.946"}, {"asset_id": "35515275010400866803110168023266440497655704126461026832913883753463850460136", "price": "0.159", "size": "0", "side": "SELL", "hash": "c149a5281549766711e41b1dd6efe577b2119f64", "best_bid": "0.054", "best_ask": "0.12"}], "timestamp": "1769384398868", "event_type": "price_change"}}
{"_local_timestamp": "2026-01-25T23:39:58.942158+00:00", "data": {"market": "0x26c050cf067df27a911df254445dece1b69185a84702c728a38cefc3e30bb76d", "price_changes": [{"asset_id": "7204710211839601265032236088110237384158025763199065581147651013315116777518", "price": "0.801", "size": "15", "side": "BUY", "hash": "738dcbbbb429988f2a49592433a4b81dacac7903", "best_bid": "0.88", "best_ask": "0.946"}, {"asset_id": "35515275010400866803110168023266440497655704126461026832913883753463850460136", "price": "0.199", "size": "15", "side": "SELL", "hash": "c149a5281549766711e41b1dd6efe577b2119f64", "best_bid": "0.054", "best_ask": "0.12"}], "timestamp": "1769384398868", "event_type": "price_change"}}
{"_local_timestamp": "2026-01-25T23:39:59.454142+00:00", "data": {"market": "0x26c050cf067df27a911df254445dece1b69185a84702c728a38cefc3e30bb76d", "price_changes": [{"asset_id": "7204710211839601265032236088110237384158025763199065581147651013315116777518", "price": "0.696", "size": "100", "side": "BUY", "hash": "51c84fb75efe0e3289f98eb041a390a2d48e0657", "best_bid": "0.88", "best_ask": "0.946"}, {"asset_id": "35515275010400866803110168023266440497655704126461026832913883753463850460136", "price": "0.304", "size": "100", "side": "SELL", "hash": "3d15b5439957439082ef15c38c436e597707d37e", "best_bid": "0.054", "best_ask": "0.12"}], "timestamp": "1769384399390", "event_type": "price_change"}}
{"_local_timestamp": "2026-01-25T23:39:59.548061+00:00", "data": {"market": "0x26c050cf067df27a911df254445dece1b69185a84702c728a38cefc3e30bb76d", "price_changes": [{"asset_id": "7204710211839601265032236088110237384158025763199065581147651013315116777518", "price": "0.512", "size": "100", "side": "BUY", "hash": "e75dc54b09a90f0a88ea8fc98dccd3778034b906", "best_bid": "0.88", "best_ask": "0.946"}, {"asset_id": "35515275010400866803110168023266440497655704126461026832913883753463850460136", "price": "0.488", "size": "100", "side": "SELL", "hash": "dfe6f60b87146a35962723b769fe636292698157", "best_bid": "0.054", "best_ask": "0.12"}], "timestamp": "1769384399474", "event_type": "price_change"}}
{"_local_timestamp": "2026-01-25T23:40:06.054334+00:00", "data": {"market": "0x26c050cf067df27a911df254445dece1b69185a84702c728a38cefc3e30bb76d", "price_changes": [{"asset_id": "7204710211839601265032236088110237384158025763199065581147651013315116777518", "price": "0.517", "size": "0", "side": "BUY", "hash": "4a3ee1b45aaa5499de0369f6ace6fc2ada86c2f8", "best_bid": "0.88", "best_ask": "0.946"}, {"asset_id": "35515275010400866803110168023266440497655704126461026832913883753463850460136", "price": "0.483", "size": "0", "side": "SELL", "hash": "2778b05248da7c0bafc74a01bbba384e87767ad2", "best_bid": "0.054", "best_ask": "0.12"}], "timestamp": "1769384405991", "event_type": "price_change"}}
{"_local_timestamp": "2026-01-25T23:40:06.127884+00:00", "data": {"market": "0x26c050cf067df27a911df254445dece1b69185a84702c728a38cefc3e30bb76d", "price_changes": [{"asset_id": "7204710211839601265032236088110237384158025763199065581147651013315116777518", "price": "0.519", "size": "5", "side": "BUY", "hash": "bfc853227a4ffd7fa321ac973f9b728bdcf65818", "best_bid": "0.88", "best_ask": "0.946"}, {"asset_id": "35515275010400866803110168023266440497655704126461026832913883753463850460136", "price": "0.481", "size": "5", "side": "SELL", "hash": "e2106b5b9d3feed68ba9a582d9a20d545bdd75e9", "best_bid": "0.054", "best_ask": "0.12"}], "timestamp": "1769384406043", "event_type": "price_change"}}
{"_local_timestamp": "2026-01-25T23:40:06.939640+00:00", "data": {"market": "0xbd8114a52eed432265735ebfe174ce257047a94b378cbc36246ca0dba7a07c33", "price_changes": [{"asset_id": "34347535308090847792552379030322073016871399676099560255182105326984970187327", "price": "0.912", "size": "33", "side": "BUY", "hash": "a4d992ccaba7411dd26e92b07f7b49c650f23977", "best_bid": "0.995", "best_ask": "0.996"}, {"asset_id": "113403179930780844692419404105573805354679366394847558149476632392300380613010", "price": "0.088", "size": "33", "side": "SELL", "hash": "1a0d37e22e6b44aad4eb1d7a0e79a2c6778ef808", "best_bid": "0.004", "best_ask": "0.005"}], "timestamp": "1769384406820", "event_type": "price_change"}}
{"_local_timestamp": "2026-01-25T23:40:06.979566+00:00", "data": {"market": "0xbd8114a52eed432265735ebfe174ce257047a94b378cbc36246ca0dba7a07c33", "price_changes": [{"asset_id": "34347535308090847792552379030322073016871399676099560255182105326984970187327", "price": "0.911", "size": "16.66", "side": "BUY", "hash": "88feebdd86c9d70279bc643ad80cf0a15bbf3aaa", "best_bid": "0.995", "best_ask": "0.996"}, {"asset_id": "113403179930780844692419404105573805354679366394847558149476632392300380613010", "price": "0.089", "size": "16.66", "side": "SELL", "hash": "bd8b5b0e0645fd7bd068744ac296507adc0284ee", "best_bid": "0.004", "best_ask": "0.005"}], "timestamp": "1769384406902", "event_type": "price_change"}}
{"_local_timestamp": "2026-01-25T23:40:07.571974+00:00", "data": {"market": "0xbf2cba044810364349878bce032b495875a0ae8b575286388e79cc4bddde4a6c", "price_changes": [{"asset_id": "52973946067415555340752362838729163232972184824595142980403702383146397821473", "price": "0.952", "size": "191.09", "side": "BUY", "hash": "f7946be32cc82c2b8d14baf2f802c653895584dd", "best_bid": "0.997", "best_ask": "0.998"}, {"asset_id": "80303106904766949344727438756563505749348738369775655357626215899018784021389", "price": "0.048", "size": "191.09", "side": "SELL", "hash": "f71f4b1faab0b813a2d04a9f5e7ff4261f76cdeb", "best_bid": "0.002", "best_ask": "0.003"}], "timestamp": "1769384407494", "event_type": "price_change"}}
{"_local_timestamp": "2026-01-25T23:40:07.900208+00:00", "data": {"market": "0xbecfcab892fc16aabf72d5180094c6c51ba33ac8005c3f9497b7c6d05bbee7f1", "price_changes": [{"asset_id": "25498200346709217272214635487844720997180443012933651618839363828578469169844", "price": "0.915", "size": "33.33", "side": "BUY", "hash": "ff5945ac971f3b58dfc63247915e8b84d9c16b80", "best_bid": "0.997", "best_ask": "0.998"}, {"asset_id": "98146342803923051979042568419031220153888306546081565583042852359988504135784", "price": "0.085", "size": "33.33", "side": "SELL", "hash": "32ce5e33fe040e8a047b05df0c5c2591eca3ba2f", "best_bid": "0.002", "best_ask": "0.003"}], "timestamp": "1769384407832", "event_type": "price_change"}}
{"_local_timestamp": "2026-01-25T23:40:08.268187+00:00", "data": {"market": "0xb86618f0e3e26d16e5abd848af319dd750dba3271684a2912268bb917a8f9953", "price_changes": [{"asset_id": "64643056846481598756416775559569443451634829574992414360993839787798978191969", "price": "0.8", "size": "35.4", "side": "BUY", "hash": "b3ed543e1471471a4d088e4958d91f4e233238e5", "best_bid": "0.83", "best_ask": "0.84"}, {"asset_id": "2980904883599652826602645381294742922476754820505374946621784678629157691361", "price": "0.2", "size": "35.4", "side": "SELL", "hash": "1e4a1e0f0b5cd6243d4e2a96a70ff695d5d3db2b", "best_bid": "0.16", "best_ask": "0.17"}], "timestamp": "1769384408197", "event_type": "price_change"}}
{"_local_timestamp": "2026-01-25T23:40:08.340110+00:00", "data": {"market": "0xb86618f0e3e26d16e5abd848af319dd750dba3271684a2912268bb917a8f9953", "price_changes": [{"asset_id": "64643056846481598756416775559569443451634829574992414360993839787798978191969", "price": "0.78", "size": "42.55", "side": "BUY", "hash": "4461fc65f53ce86349a203c1bbb9fed2d325d4bc", "best_bid": "0.83", "best_ask": "0.84"}, {"asset_id": "2980904883599652826602645381294742922476754820505374946621784678629157691361", "price": "0.22", "size": "42.55", "side": "SELL", "hash": "b983e73933ccf0a71271290b92618a4dd6a7d46b", "best_bid": "0.16", "best_ask": "0.17"}], "timestamp": "1769384408272", "event_type": "price_change"}}
{"_local_timestamp": "2026-01-25T23:40:09.385912+00:00", "data": {"market": "0x9ae2d920fa7f4da49b6524361fa2e7260cad95631cc8e443ddeb2d70d2f1ccfd", "price_changes": [{"asset_id": "4942360482005244918796292265006007704327799854749267861336630583944467908299", "price": "0.865", "size": "33.33", "side": "BUY", "hash": "0c7245e734e570c73ba364fd2107933a810d73c6", "best_bid": "0.997", "best_ask": "0.998"}, {"asset_id": "113409560089971005551069019900801779309141794188263770657345157175671976775527", "price": "0.135", "size": "33.33", "side": "SELL", "hash": "14cdce850dd730a4eb5a5e1fa679cbb463deb390", "best_bid": "0.002", "best_ask": "0.003"}], "timestamp": "1769384409321", "event_type": "price_change"}}
{"_local_timestamp": "2026-01-25T23:40:09.592515+00:00", "data": {"market": "0xbecfcab892fc16aabf72d5180094c6c51ba33ac8005c3f9497b7c6d05bbee7f1", "price_changes": [{"asset_id": "25498200346709217272214635487844720997180443012933651618839363828578469169844", "price": "0.915", "size": "13.33", "side": "BUY", "hash": "7bf654ff91fe28ec1392f55a151a67a1c9681bb7", "best_bid": "0.997", "best_ask": "0.998"}, {"asset_id": "98146342803923051979042568419031220153888306546081565583042852359988504135784", "price": "0.085", "size": "13.33", "side": "SELL", "hash": "ab7acca217a7814f1e87409955425f21c6ee2a9a", "best_bid": "0.002", "best_ask": "0.003"}], "timestamp": "1769384409515", "event_type": "price_change"}}
{"_local_timestamp": "2026-01-25T23:40:09.593219+00:00", "data": {"market": "0xbd8114a52eed432265735ebfe174ce257047a94b378cbc36246ca0dba7a07c33", "price_changes": [{"asset_id": "34347535308090847792552379030322073016871399676099560255182105326984970187327", "price": "0.912", "size": "13", "side": "BUY", "hash": "f748d15b8f72f56cf7c58b17f95deef26f1d4edf", "best_bid": "0.995", "best_ask": "0.996"}, {"asset_id": "113403179930780844692419404105573805354679366394847558149476632392300380613010", "price": "0.088", "size": "13", "side": "SELL", "hash": "bdc363f5f5ca0c5b756f7076aa1544f663bb8025", "best_bid": "0.004", "best_ask": "0.005"}], "timestamp": "1769384409515", "event_type": "price_change"}}
{"_local_timestamp": "2026-01-25T23:40:09.614375+00:00", "data": {"market": "0xbecfcab892fc16aabf72d5180094c6c51ba33ac8005c3f9497b7c6d05bbee7f1", "price_changes": [{"asset_id": "25498200346709217272214635487844720997180443012933651618839363828578469169844", "price": "0.916", "size": "20", "side": "BUY", "hash": "836e8c5ea45c37792d9c69ddacdb75527163d688", "best_bid": "0.997", "best_ask": "0.998"}, {"asset_id": "98146342803923051979042568419031220153888306546081565583042852359988504135784", "price": "0.084", "size": "20", "side": "SELL", "hash": "84b27ea5502b8c9b1c7a600676d0d5d2673d713e", "best_bid": "0.002", "best_ask": "0.003"}], "timestamp": "1769384409545", "event_type": "price_change"}}
{"_local_timestamp": "2026-01-25T23:40:09.615372+00:00", "data": {"market": "0xbd8114a52eed432265735ebfe174ce257047a94b378cbc36246ca0dba7a07c33", "price_changes": [{"asset_id": "34347535308090847792552379030322073016871399676099560255182105326984970187327", "price": "0.913", "size": "20", "side": "BUY", "hash": "79b33e8b6233d2c197609b5c9eee8e73d64011c7", "best_bid": "0.995", "best_ask": "0.996"}, {"asset_id": "113403179930780844692419404105573805354679366394847558149476632392300380613010", "price": "0.087", "size": "20", "side": "SELL", "hash": "ef0586e9f435799b6e239863cdb01372df01b12d", "best_bid": "0.004", "best_ask": "0.005"}], "timestamp": "1769384409545", "event_type": "price_change"}}
{"_local_timestamp": "2026-01-25T23:40:10.905138+00:00", "data": {"market": "0x9ae2d920fa7f4da49b6524361fa2e7260cad95631cc8e443ddeb2d70d2f1ccfd", "price_changes": [{"asset_id": "4942360482005244918796292265006007704327799854749267861336630583944467908299", "price": "0.865", "size": "13.33", "side": "BUY", "hash": "96acb1364f8b7ba887f6b52aa4ca8b6c2023c6e6", "best_bid": "0.997", "best_ask": "0.998"}, {"asset_id": "113409560089971005551069019900801779309141794188263770657345157175671976775527", "price": "0.135", "size": "13.33", "side": "SELL", "hash": "d2084f9af0b19764b98c7308757967700fb0e629", "best_bid": "0.002", "best_ask": "0.003"}], "timestamp": "1769384410837", "event_type": "price_change"}}
{"_local_timestamp": "2026-01-25T23:40:10.932983+00:00", "data": {"market": "0x9ae2d920fa7f4da49b6524361fa2e7260cad95631cc8e443ddeb2d70d2f1ccfd", "price_changes": [{"asset_id": "4942360482005244918796292265006007704327799854749267861336630583944467908299", "price": "0.866", "size": "20", "side": "BUY", "hash": "2fcbc78b3165134365e538acfb242730398e53ef", "best_bid": "0.997", "best_ask": "0.998"}, {"asset_id": "113409560089971005551069019900801779309141794188263770657345157175671976775527", "price": "0.134", "size": "20", "side": "SELL", "hash": "07e253dbc072471030b90c21c38df77a30b458b7", "best_bid": "0.002", "best_ask": "0.003"}], "timestamp": "1769384410868", "event_type": "price_change"}}
