{"_local_timestamp": "2026-01-25T23:33:35.346628+00:00", "data": [{"market": "0xbbf9e226512452452438571385c111fafd7a581f227d997183b3c0ed0aaa6e94", "asset_id": "32365631237478011719581335465835096900088880772439977051943287219696169513404", "timestamp": "1769384014827", "hash": "3ebd95d2f397b4c4382f27524caa6ad6ec8a34e8", "bids": [{"price": "0.01", "size": "35806.36"}, {"price": "0.02", "size": "2013.53"}, {"price": "0.03", "size": "2390"}, {"price": "0.04", "size": "16.99"}, {"price": "0.06", "size": "1200"}, {"price": "0.07", "size": "250"}, {"price": "0.08", "size": "50"}, {"price": "0.09", "size": "144.44"}, {"price": "0.1", "size": "6.63"}, {"price": "0.13", "size": "269.79"}, {"price": "0.14", "size": "78.57"}, {"price": "0.16", "size": "900"}, {"price": "0.17", "size": "456"}, {"price": "0.18", "size": "150"}, {"price": "0.19", "size": "518"}, {"price": "0.2", "size": "216.08"}], "asks": [{"price": "0.99", "size": "16013.8"}, {"price": "0.98", "size": "5012.9"}, {"price": "0.97", "size": "6000"}, {"price": "0.96", "size": "5.39"}, {"price": "0.95", "size": "10"}, {"price": "0.94", "size": "3000"}, {"price": "0.93", "size": "15.19"}, {"price": "0.85", "size": "900"}, {"price": "0.82", "size": "888"}, {"price": "0.78", "size": "300"}, {"price": "0.77", "size": "1826"}, {"price": "0.76", "size": "50"}, {"price": "0.75", "size": "986"}, {"price": "0.73", "size": "50"}, {"price": "0.6", "size": "850"}, {"price": "0.59", "size": "5"}, {"price": "0.48", "size": "69"}, {"price": "0.47", "size": "10"}, {"price": "0.34", "size": "19.69"}, {"price": "0.33", "size": "20"}, {"price": "0.32", "size": "136.17"}, {"price": "0.31", "size": "51"}, {"price": "0.27", "size": "249"}, {"price": "0.26", "size": "40"}, {"price": "0.25", "size": "130"}], "event_type": "book", "last_trade_price": "0.200"}, {"market": "0xa19142e40da92f4110d29f63475ed9689f1471f8963c87e3220a989cdb356d45", "asset_id": "81750849409365469972793631297951692550835139647103107287253620651299358774290", "timestamp": "1769384013545", "hash": "49d0cb6bb5789040c6f871c52a917f3c3a7dd6a7", "bids": [{"price": "0.001", "size": "3305.17"}, {"price": "0.002", "size": "1264.14"}, {"price": "0.003", "size": "62000"}, {"price": "0.004", "size": "34.31"}, {"price": "0.013", "size": "4000"}, {"price": "0.014", "size": "6.6"}, {"price": "0.02", "size": "1000"}, {"price": "0.021", "size": "11.83"}, {"price": "0.03", "size": "17250"}, {"price": "0.04", "size": "12"}, {"price": "0.041", "size": "5.53"}, {"price": "0.05", "size": "30"}, {"price": "0.051", "size": "39"}, {"price": "0.06", "size": "2033"}, {"price": "0.063", "size": "7440"}, {"price": "0.064", "size": "14.5"}, {"price": "0.15", "size": "900"}, {"price": "0.151", "size": "1058"}, {"price": "0.152", "size": "4062"}, {"price": "0.2", "size": "50"}, {"price": "0.28", "size": "5"}, {"price": "0.326", "size": "300"}, {"price": "0.327", "size": "1514"}, {"price": "0.328", "size": "379"}, {"price": "0.34", "size": "50"}, {"price": "0.341", "size": "5"}, {"price": "0.42", "size": "7.01"}, {"price": "0.421", "size": "10"}, {"price": "0.77", "size": "400"}, {"price": "0.775", "size": "25.67"}, {"price": "0.776", "size": "20"}, {"price": "0.78", "size": "340.15"}, {"price": "0.782", "size": "30"}, {"price": "0.79", "size": "12.62"}, {"price": "0.794", "size": "16.37"}, {"price": "0.795", "size": "40"}, {"price": "0.81", "size": "50"}, {"price": "0.822", "size": "13.38"}, {"price": "0.85", "size": "61.73"}, {"price": "0.86", "size": "150"}, {"price": "0.878", "size": "30"}, {"price": "0.888", "size": "30"}, {"price": "0.891", "size": "250"}, {"price": "0.892", "size": "136"}, {"price": "0.899", "size": "134.29"}], "asks": [{"price": "0.999", "size": "73506.99"}, {"price": "0.998", "size": "30176.39"}, {"price": "0.997", "size": "341.89"}, {"price": "0.996", "size": "31.62"}, {"price": "0.995", "size": "49"}, {"price": "0.994", "size": "42.11"}, {"price": "0.98", "size": "25"}, {"price": "0.979", "size": "619.04"}, {"price": "0.978", "size": "5.83"}, {"price": "0.972", "size": "196.42"}, {"price": "0.971", "size": "7.27"}, {"price": "0.96", "size": "200"}, {"price": "0.959", "size": "11.93"}, {"price": "0.935", "size": "1.52"}, {"price": "0.934", "size": "34.18"}, {"price": "0.932", "size": "1133.6"}, {"price": "0.931", "size": "6.18"}, {"price": "0.927", "size": "16"}, {"price": "0.909", "size": "100"}, {"price": "0.907", "size": "150"}, {"price": "0.905", "size": "962.42"}, {"price": "0.904", "size": "5.23"}], "event_type": "book", "last_trade_price": "0.099"}, {"market": "0x7130b2c99bee81af658adafb4a6235f21575f568e3ae2a850af742afa50c2d85", "asset_id": "79480641743596328156888881841837787012633513624072222555595000167813156519758", "timestamp": "1769384013384", "hash": "2c135ee44814963b43af9a2bcccf747c2ed7b414", "bids": [{"price": "0.001", "size": "53526.56"}, {"price": "0.002", "size": "79011.45"}, {"price": "0.003", "size": "22.56"}, {"price": "0.004", "size": "46"}, {"price": "0.005", "size": "400"}, {"price": "0.006", "size": "48.07"}, {"price": "0.014", "size": "300"}, {"price": "0.015", "size": "22.08"}, {"price": "0.024", "size": "50"}, {"price": "0.025", "size": "8.8"}, {"price": "0.03", "size": "28.26"}, {"price": "0.032", "size": "171.87"}, {"price": "0.033", "size": "11.11"}, {"price": "0.046", "size": "56"}, {"price": "0.05", "size": "419.99"}, {"price": "0.051", "size": "16"}, {"price": "0.052", "size": "6.4"}, {"price": "0.067", "size": "899.98"}, {"price": "0.071", "size": "661"}, {"price": "0.073", "size": "8.87"}, {"price": "0.075", "size": "150"}, {"price": "0.079", "size": "594"}, {"price": "0.08", "size": "116"}, {"price": "0.086", "size": "100"}, {"price": "0.087", "size": "1540"}, {"price": "0.091", "size": "119.54"}, {"price": "0.092", "size": "71.2"}], "asks": [{"price": "0.999", "size": "3908.17"}, {"price": "0.998", "size": "1263.93"}, {"price": "0.997", "size": "12000"}, {"price": "0.996", "size": "57.43"}, {"price": "0.98", "size": "5000"}, {"price": "0.979", "size": "6.05"}, {"price": "0.97", "size": "4000"}, {"price": "0.969", "size": "11.25"}, {"price": "0.95", "size": "30"}, {"price": "0.949", "size": "39"}, {"price": "0.94", "size": "2000"}, {"price": "0.939", "size": "5.3"}, {"price": "0.903", "size": "3092"}, {"price": "0.901", "size": "5642"}, {"price": "0.9", "size": "6.04"}, {"price": "0.781", "size": "730"}, {"price": "0.78", "size": "50"}, {"price": "0.779", "size": "25"}, {"price": "0.73", "size": "50"}, {"price": "0.66", "size": "50"}, {"price": "0.649", "size": "15"}, {"price": "0.5", "size": "422.82"}, {"price": "0.499", "size": "596"}, {"price": "0.498", "size": "5"}, {"price": "0.497", "size": "10"}, {"price": "0.25", "size": "81.96"}, {"price": "0.245", "size": "10"}, {"price": "0.243", "size": "40"}, {"price": "0.24", "size": "30"}, {"price": "0.239", "size": "50"}, {"price": "0.238", "size": "20"}, {"price": "0.198", "size": "150"}, {"price": "0.189", "size": "16.02"}, {"price": "0.188", "size": "13.54"}, {"price": "0.114", "size": "117.41"}], "event_type": "book", "last_trade_price": "0.886"}, {"market": "0x5b87791e06388b1a91fd402c29e483842da0f9fec156bb3cefe9d58275a0373b", "asset_id": "88022913747451311038559242580697856881859219751804674115271835179181575694176", "timestamp": "1769384006674", "hash": "691c661ffc0b417b73b328180561f8f19a47150d", "bids": [{"price": "0.001", "size": "18203.18"}, {"price": "0.002", "size": "1264.1"}, {"price": "0.003", "size": "2000"}, {"price": "0.004", "size": "57.47"}, {"price": "0.02", "size": "5000"}, {"price": "0.021", "size": "11.83"}, {"price": "0.03", "size": "6000"}, {"price": "0.04", "size": "12"}, {"price": "0.041", "size": "5.53"}, {"price": "0.05", "size": "20"}, {"price": "0.06", "size": "3033"}, {"price": "0.061", "size": "15.21"}, {"price": "0.143", "size": "2018"}, {"price": "0.24", "size": "3216"}, {"price": "0.242", "size": "300"}, {"price": "0.243", "size": "1728"}, {"price": "0.27", "size": "57"}, {"price": "0.271", "size": "7"}, {"price": "0.34", "size": "50"}, {"price": "0.44", "size": "34.05"}, {"price": "0.45", "size": "7"}, {"price": "0.54", "size": "12.19"}, {"price": "0.62", "size": "12.19"}, {"price": "0.65", "size": "200"}, {"price": "0.652", "size": "344"}, {"price": "0.681", "size": "10"}, {"price": "0.683", "size": "30"}, {"price": "0.685", "size": "40"}, {"price": "0.686", "size": "20"}, {"price": "0.87", "size": "100"}, {"price": "0.88", "size": "99.99"}, {"price": "0.91", "size": "302.46"}, {"price": "0.92", "size": "400"}, {"price": "0.932", "size": "179.97"}, {"price": "0.938", "size": "67.06"}, {"price": "0.947", "size": "300"}, {"price": "0.95", "size": "254.84"}, {"price": "0.956", "size": "129.99"}, {"price": "0.957", "size": "345.27"}, {"price": "0.959", "size": "25"}, {"price": "0.96", "size": "21"}], "asks": [{"price": "0.999", "size": "132072.99"}, {"price": "0.998", "size": "77189.95"}, {"price": "0.997", "size": "64.39"}, {"price": "0.994", "size": "701.87"}, {"price": "0.993", "size": "4108.92"}, {"price": "0.992", "size": "22.85"}, {"price": "0.99", "size": "700"}, {"price": "0.989", "size": "970"}, {"price": "0.988", "size": "11.33"}, {"price": "0.987", "size": "330"}, {"price": "0.986", "size": "165"}, {"price": "0.985", "size": "20.8"}, {"price": "0.98", "size": "25"}, {"price": "0.979", "size": "50"}, {"price": "0.978", "size": "11.38"}, {"price": "0.976", "size": "10.4"}, {"price": "0.975", "size": "10"}, {"price": "0.969", "size": "234"}, {"price": "0.968", "size": "130"}, {"price": "0.967", "size": "26.03"}], "event_type": "book", "last_trade_price": "0.039"}, {"market": "0x74cda80b2734086fa7e6bfce27d6321bb617d28dde6b486e7d3567c6afa5f46f", "asset_id": "54097693815260016929707363796097268965809730515171531228590357799043969397342", "timestamp": "1769384013366", "hash": "b351523c5f192bd7772e6d4fb031d75a1e8e0bb1", "bids": [{"price": "0.01", "size": "61013.8"}, {"price": "0.02", "size": "5012.9"}, {"price": "0.03", "size": "17250"}, {"price": "0.04", "size": "11.27"}, {"price": "0.05", "size": "30"}, {"price": "0.06", "size": "2033"}, {"price": "0.07", "size": "7440"}, {"price": "0.08", "size": "10.35"}, {"price": "0.12", "size": "1332"}, {"price": "0.13", "size": "4530"}, {"price": "0.2", "size": "50"}, {"price": "0.32", "size": "1601"}, {"price": "0.33", "size": "250"}, {"price": "0.34", "size": "50"}, {"price": "0.51", "size": "21.56"}, {"price": "0.57", "size": "5"}, {"price": "0.67", "size": "149"}, {"price": "0.68", "size": "10"}, {"price": "0.69", "size": "20"}, {"price": "0.78", "size": "46.66"}, {"price": "0.79", "size": "40"}, {"price": "0.8", "size": "135"}, {"price": "0.85", "size": "63"}, {"price": "0.86", "size": "329.71"}, {"price": "0.87", "size": "130"}], "asks": [{"price": "0.99", "size": "25805.69"}, {"price": "0.98", "size": "17.45"}, {"price": "0.97", "size": "3116"}, {"price": "0.96", "size": "706.47"}, {"price": "0.95", "size": "157.5"}, {"price": "0.94", "size": "16.84"}, {"price": "0.93", "size": "10"}, {"price": "0.92", "size": "930.66"}, {"price": "0.91", "size": "184"}, {"price": "0.9", "size": "52.2"}], "event_type": "book", "last_trade_price": "0.870"}, {"market": "0x5e75c47528185caa0b8140d5199a505b111d535d004f10c14c77099e160f8c43", "asset_id": "40497352693029741963885292742967835565636400191703716161158810847504561227789", "timestamp": "1769384014714", "hash": "0dbbf2d3b718347a1e0ff6ed9f029a16194c4ecf", "bids": [{"price": "0.01", "size": "25800"}, {"price": "0.02", "size": "33.54"}, {"price": "0.03", "size": "3305.07"}, {"price": "0.04", "size": "260.76"}, {"price": "0.05", "size": "330"}, {"price": "0.06", "size": "56.56"}, {"price": "0.07", "size": "264.28"}, {"price": "0.08", "size": "116.59"}, {"price": "0.09", "size": "130"}, {"price": "0.1", "size": "50"}, {"price": "0.11", "size": "9.09"}], "asks": [{"price": "0.99", "size": "61013.78"}, {"price": "0.98", "size": "5012.89"}, {"price": "0.97", "size": "17266"}, {"price": "0.96", "size": "5.38"}, {"price": "0.95", "size": "70"}, {"price": "0.94", "size": "9480"}, {"price": "0.91", "size": "6600"}, {"price": "0.9", "size": "6.44"}, {"price": "0.89", "size": "2250"}, {"price": "0.8", "size": "800"}, {"price": "0.79", "size": "300"}, {"price": "0.78", "size": "3558"}, {"price": "0.73", "size": "50"}, {"price": "0.71", "size": "6"}, {"price": "0.66", "size": "50"}, {"price": "0.33", "size": "28.72"}, {"price": "0.32", "size": "16"}, {"price": "0.29", "size": "853.31"}, {"price": "0.28", "size": "731"}, {"price": "0.27", "size": "858.81"}, {"price": "0.26", "size": "345"}, {"price": "0.25", "size": "17.33"}, {"price": "0.24", "size": "20"}, {"price": "0.23", "size": "44.28"}, {"price": "0.21", "size": "40"}, {"price": "0.16", "size": "260.59"}, {"price": "0.15", "size": "1004"}, {"price": "0.13", "size": "75"}, {"price": "0.12", "size": "49.71"}], "event_type": "book", "last_trade_price": "0.880"}, {"market": "0x3f973c672acd8233f5b953a9eaece0c41d82b932354f14cca316c8c8adbc5430", "asset_id": "93900842269737238576470860642705247823244098999914913757632782327103374288912", "timestamp": "1769384009585", "hash": "f2d687870fbd92923128bca1947130995b6cd89a", "bids": [{"price": "0.001", "size": "1163281.18"}, {"price": "0.002", "size": "201257.06"}, {"price": "0.003", "size": "1009.35"}, {"price": "0.004", "size": "4000"}, {"price": "0.005", "size": "45.74"}, {"price": "0.01", "size": "5"}, {"price": "0.02", "size": "5000"}, {"price": "0.021", "size": "43250"}, {"price": "0.022", "size": "5.75"}, {"price": "0.03", "size": "4000"}, {"price": "0.031", "size": "9000"}, {"price": "0.032", "size": "7.04"}, {"price": "0.05", "size": "30"}, {"price": "0.051", "size": "6.44"}, {"price": "0.06", "size": "9473"}, {"price": "0.081", "size": "14200"}, {"price": "0.082", "size": "8.67"}, {"price": "0.14", "size": "6400"}, {"price": "0.199", "size": "3550"}, {"price": "0.2", "size": "50"}, {"price": "0.201", "size": "25"}, {"price": "0.202", "size": "9"}, {"price": "0.27", "size": "50"}, {"price": "0.34", "size": "50"}, {"price": "0.341", "size": "10"}, {"price": "0.342", "size": "40"}, {"price": "0.343", "size": "15"}, {"price": "0.84", "size": "5"}, {"price": "0.841", "size": "30"}, {"price": "0.85", "size": "1000"}, {"price": "0.851", "size": "20"}, {"price": "0.86", "size": "2000"}, {"price": "0.87", "size": "200"}, {"price": "0.89", "size": "421"}, {"price": "0.9", "size": "100"}, {"price": "0.91", "size": "10"}, {"price": "0.94", "size": "25"}, {"price": "0.957", "size": "39.28"}, {"price": "0.958", "size": "40.37"}, {"price": "0.962", "size": "23"}, {"price": "0.969", "size": "20"}, {"price": "0.97", "size": "243.65"}, {"price": "0.971", "size": "18.64"}, {"price": "0.972", "size": "417.03"}, {"price": "0.973", "size": "209.56"}, {"price": "0.975", "size": "21.19"}], "asks": [{"price": "0.999", "size": "72371.99"}, {"price": "0.998", "size": "693.59"}, {"price": "0.997", "size": "35906.31"}, {"price": "0.996", "size": "11763.67"}, {"price": "0.995", "size": "21.84"}, {"price": "0.993", "size": "726.05"}, {"price": "0.992", "size": "14383.95"}, {"price": "0.991", "size": "255.63"}, {"price": "0.99", "size": "7.11"}, {"price": "0.989", "size": "454.54"}, {"price": "0.988", "size": "9029.4"}, {"price": "0.987", "size": "77"}, {"price": "0.986", "size": "7.45"}, {"price": "0.985", "size": "68"}, {"price": "0.984", "size": "106.46"}, {"price": "0.983", "size": "1324.2"}, {"price": "0.982", "size": "5.78"}, {"price": "0.98", "size": "2400"}, {"price": "0.979", "size": "42.3"}], "event_type": "book", "last_trade_price": "0.021"}, {"market": "0xbbf9e226512452452438571385c111fafd7a581f227d997183b3c0ed0aaa6e94", "asset_id": "70641103843303633433849051708048017041225992079285926883062800006960120844878", "timestamp": "1769384014827", "hash": "4090db70f4fe30daa4544db33acc4248f23104fc", "bids": [{"price": "0.01", "size": "16013.8"}, {"price": "0.02", "size": "5012.9"}, {"price": "0.03", "size": "6000"}, {"price": "0.04", "size": "5.39"}, {"price": "0.05", "size": "10"}, {"price": "0.06", "size": "3000"}, {"price": "0.07", "size": "15.19"}, {"price": "0.15", "size": "900"}, {"price": "0.18", "size": "888"}, {"price": "0.22", "size": "300"}, {"price": "0.23", "size": "1826"}, {"price": "0.24", "size": "50"}, {"price": "0.25", "size": "986"}, {"price": "0.27", "size": "50"}, {"price": "0.4", "size": "850"}, {"price": "0.41", "size": "5"}, {"price": "0.52", "size": "69"}, {"price": "0.53", "size": "10"}, {"price": "0.66", "size": "19.69"}, {"price": "0.67", "size": "20"}, {"price": "0.68", "size": "136.17"}, {"price": "0.69", "size": "51"}, {"price": "0.73", "size": "249"}, {"price": "0.74", "size": "40"}, {"price": "0.75", "size": "130"}], "asks": [{"price": "0.99", "size": "35806.36"}, {"price": "0.98", "size": "2013.53"}, {"price": "0.97", "size": "2390"}, {"price": "0.96", "size": "16.99"}, {"price": "0.94", "size": "1200"}, {"price": "0.93", "size": "250"}, {"price": "0.92", "size": "50"}, {"price": "0.91", "size": "144.44"}, {"price": "0.9", "size": "6.63"}, {"price": "0.87", "size": "269.79"}, {"price": "0.86", "size": "78.57"}, {"price": "0.84", "size": "900"}, {"price": "0.83", "size": "456"}, {"price": "0.82", "size": "150"}, {"price": "0.81", "size": "518"}, {"price": "0.8", "size": "216.08"}], "event_type": "book", "last_trade_price": "0.200"}, {"market": "0x3f973c672acd8233f5b953a9eaece0c41d82b932354f14cca316c8c8adbc5430", "asset_id": "98245576915057665054883165975987196038445195653094902203445898901996168030329", "timestamp": "1769384009585", "hash": "9c657a8f564d1788b0b4fb5fffcb69fb51e8e1b4", "bids": [{"price": "0.001", "size": "72371.99"}, {"price": "0.002", "size": "693.59"}, {"price": "0.003", "size": "35906.31"}, {"price": "0.004", "size": "11763.67"}, {"price": "0.005", "size": "21.84"}, {"price": "0.007", "size": "726.05"}, {"price": "0.008", "size": "14383.95"}, {"price": "0.009", "size": "255.63"}, {"price": "0.01", "size": "7.11"}, {"price": "0.011", "size": "454.54"}, {"price": "0.012", "size": "9029.4"}, {"price": "0.013", "size": "77"}, {"price": "0.014", "size": "7.45"}, {"price": "0.015", "size": "68"}, {"price": "0.016", "size": "106.46"}, {"price": "0.017", "size": "1324.2"}, {"price": "0.018", "size": "5.78"}, {"price": "0.02", "size": "2400"}, {"price": "0.021", "size": "42.3"}], "asks": [{"price": "0.999", "size": "1163281.18"}, {"price": "0.998", "size": "201257.06"}, {"price": "0.997", "size": "1009.35"}, {"price": "0.996", "size": "4000"}, {"price": "0.995", "size": "45.74"}, {"price": "0.99", "size": "5"}, {"price": "0.98", "size": "5000"}, {"price": "0.979", "size": "43250"}, {"price": "0.978", "size": "5.75"}, {"price": "0.97", "size": "4000"}, {"price": "0.969", "size": "9000"}, {"price": "0.968", "size": "7.04"}, {"price": "0.95", "size": "30"}, {"price": "0.949", "size": "6.44"}, {"price": "0.94", "size": "9473"}, {"price": "0.919", "size": "14200"}, {"price": "0.918", "size": "8.67"}, {"price": "0.86", "size": "6400"}, {"price": "0.801", "size": "3550"}, {"price": "0.8", "size": "50"}, {"price": "0.799", "size": "25"}, {"price": "0.798", "size": "9"}, {"price": "0.73", "size": "50"}, {"price": "0.66", "size": "50"}, {"price": "0.659", "size": "10"}, {"price": "0.658", "size": "40"}, {"price": "0.657", "size": "15"}, {"price": "0.16", "size": "5"}, {"price": "0.159", "size": "30"}, {"price": "0.15", "size": "1000"}, {"price": "0.149", "size": "20"}, {"price": "0.14", "size": "2000"}, {"price": "0.13", "size": "200"}, {"price": "0.11", "size": "421"}, {"price": "0.1", "size": "100"}, {"price": "0.09", "size": "10"}, {"price": "0.06", "size": "25"}, {"price": "0.043", "size": "39.28"}, {"price": "0.042", "size": "40.37"}, {"price": "0.038", "size": "23"}, {"price": "0.031", "size": "20"}, {"price": "0.03", "size": "243.65"}, {"price": "0.029", "size": "18.64"}, {"price": "0.028", "size": "417.03"}, {"price": "0.027", "size": "209.56"}, {"price": "0.025", "size": "21.19"}], "event_type": "book", "last_trade_price": "0.021"}, {"market": "0xa19142e40da92f4110d29f63475ed9689f1471f8963c87e3220a989cdb356d45", "asset_id": "49980127219724914096527114792845752329307347014547067418981570311158802130688", "timestamp": "1769384013545", "hash": "eebb27e26f1c67752c904c7a208631b70439e68d", "bids": [{"price": "0.001", "size": "73506.99"}, {"price": "0.002", "size": "30176.39"}, {"price": "0.003", "size": "341.89"}, {"price": "0.004", "size": "31.62"}, {"price": "0.005", "size": "49"}, {"price": "0.006", "size": "42.11"}, {"price": "0.02", "size": "25"}, {"price": "0.021", "size": "619.04"}, {"price": "0.022", "size": "5.83"}, {"price": "0.028", "size": "196.42"}, {"price": "0.029", "size": "7.27"}, {"price": "0.04", "size": "200"}, {"price": "0.041", "size": "11.93"}, {"price": "0.065", "size": "1.52"}, {"price": "0.066", "size": "34.18"}, {"price": "0.068", "size": "1133.6"}, {"price": "0.069", "size": "6.18"}, {"price": "0.073", "size": "16"}, {"price": "0.091", "size": "100"}, {"price": "0.093", "size": "150"}, {"price": "0.095", "size": "962.42"}, {"price": "0.096", "size": "5.23"}], "asks": [{"price": "0.999", "size": "3305.17"}, {"price": "0.998", "size": "1264.14"}, {"price": "0.997", "size": "62000"}, {"price": "0.996", "size": "34.31"}, {"price": "0.987", "size": "4000"}, {"price": "0.986", "size": "6.6"}, {"price": "0.98", "size": "1000"}, {"price": "0.979", "size": "11.83"}, {"price": "0.97", "size": "17250"}, {"price": "0.96", "size": "12"}, {"price": "0.959", "size": "5.53"}, {"price": "0.95", "size": "30"}, {"price": "0.949", "size": "39"}, {"price": "0.94", "size": "2033"}, {"price": "0.937", "size": "7440"}, {"price": "0.936", "size": "14.5"}, {"price": "0.85", "size": "900"}, {"price": "0.849", "size": "1058"}, {"price": "0.848", "size": "4062"}, {"price": "0.8", "size": "50"}, {"price": "0.72", "size": "5"}, {"price": "0.674", "size": "300"}, {"price": "0.673", "size": "1514"}, {"price": "0.672", "size": "379"}, {"price": "0.66", "size": "50"}, {"price": "0.659", "size": "5"}, {"price": "0.58", "size": "7.01"}, {"price": "0.579", "size": "10"}, {"price": "0.23", "size": "400"}, {"price": "0.225", "size": "25.67"}, {"price": "0.224", "size": "20"}, {"price": "0.22", "size": "340.15"}, {"price": "0.218", "size": "30"}, {"price": "0.21", "size": "12.62"}, {"price": "0.206", "size": "16.37"}, {"price": "0.205", "size": "40"}, {"price": "0.19", "size": "50"}, {"price": "0.178", "size": "13.38"}, {"price": "0.15", "size": "61.73"}, {"price": "0.14", "size": "150"}, {"price": "0.122", "size": "30"}, {"price": "0.112", "size": "30"}, {"price": "0.109", "size": "250"}, {"price": "0.108", "size": "136"}, {"price": "0.101", "size": "134.29"}], "event_type": "book", "last_trade_price": "0.099"}, {"market": "0x5b87791e06388b1a91fd402c29e483842da0f9fec156bb3cefe9d58275a0373b", "asset_id": "90132986654259086678529082268082617450254793801662820786849470352289449813683", "timestamp": "1769384006674", "hash": "cd06d99609ccaa09a14adf30ada3bd1d33d81ee4", "bids": [{"price": "0.001", "size": "132072.99"}, {"price": "0.002", "size": "77189.95"}, {"price": "0.003", "size": "64.39"}, {"price": "0.006", "size": "701.87"}, {"price": "0.007", "size": "4108.92"}, {"price": "0.008", "size": "22.85"}, {"price": "0.01", "size": "700"}, {"price": "0.011", "size": "970"}, {"price": "0.012", "size": "11.33"}, {"price": "0.013", "size": "330"}, {"price": "0.014", "size": "165"}, {"price": "0.015", "size": "20.8"}, {"price": "0.02", "size": "25"}, {"price": "0.021", "size": "50"}, {"price": "0.022", "size": "11.38"}, {"price": "0.024", "size": "10.4"}, {"price": "0.025", "size": "10"}, {"price": "0.031", "size": "234"}, {"price": "0.032", "size": "130"}, {"price": "0.033", "size": "26.03"}], "asks": [{"price": "0.999", "size": "18203.18"}, {"price": "0.998", "size": "1264.1"}, {"price": "0.997", "size": "2000"}, {"price": "0.996", "size": "57.47"}, {"price": "0.98", "size": "5000"}, {"price": "0.979", "size": "11.83"}, {"price": "0.97", "size": "6000"}, {"price": "0.96", "size": "12"}, {"price": "0.959", "size": "5.53"}, {"price": "0.95", "size": "20"}, {"price": "0.94", "size": "3033"}, {"price": "0.939", "size": "15.21"}, {"price": "0.857", "size": "2018"}, {"price": "0.76", "size": "3216"}, {"price": "0.758", "size": "300"}, {"price": "0.757", "size": "1728"}, {"price": "0.73", "size": "57"}, {"price": "0.729", "size": "7"}, {"price": "0.66", "size": "50"}, {"price": "0.56", "size": "34.05"}, {"price": "0.55", "size": "7"}, {"price": "0.46", "size": "12.19"}, {"price": "0.38", "size": "12.19"}, {"price": "0.35", "size": "200"}, {"price": "0.348", "size": "344"}, {"price": "0.319", "size": "10"}, {"price": "0.317", "size": "30"}, {"price": "0.315", "size": "40"}, {"price": "0.314", "size": "20"}, {"price": "0.13", "size": "100"}, {"price": "0.12", "size": "99.99"}, {"price": "0.09", "size": "302.46"}, {"price": "0.08", "size": "400"}, {"price": "0.068", "size": "179.97"}, {"price": "0.062", "size": "67.06"}, {"price": "0.053", "size": "300"}, {"price": "0.05", "size": "254.84"}, {"price": "0.044", "size": "129.99"}, {"price": "0.043", "size": "345.27"}, {"price": "0.041", "size": "25"}, {"price": "0.04", "size": "21"}], "event_type": "book", "last_trade_price": "0.039"}, {"market": "0x5e75c47528185caa0b8140d5199a505b111d535d004f10c14c77099e160f8c43", "asset_id": "37216599669721820787426834964764344032227136269811356205946493119045847831924", "timestamp": "1769384014714", "hash": "d5df7f1ed1ea79007475e149f5c72ced17eb7970", "bids": [{"price": "0.01", "size": "61013.78"}, {"price": "0.02", "size": "5012.89"}, {"price": "0.03", "size": "17266"}, {"price": "0.04", "size": "5.38"}, {"price": "0.05", "size": "70"}, {"price": "0.06", "size": "9480"}, {"price": "0.09", "size": "6600"}, {"price": "0.1", "size": "6.44"}, {"price": "0.11", "size": "2250"}, {"price": "0.2", "size": "800"}, {"price": "0.21", "size": "300"}, {"price": "0.22", "size": "3558"}, {"price": "0.27", "size": "50"}, {"price": "0.29", "size": "6"}, {"price": "0.34", "size": "50"}, {"price": "0.67", "size": "28.72"}, {"price": "0.68", "size": "16"}, {"price": "0.71", "size": "853.31"}, {"price": "0.72", "size": "731"}, {"price": "0.73", "size": "858.81"}, {"price": "0.74", "size": "345"}, {"price": "0.75", "size": "17.33"}, {"price": "0.76", "size": "20"}, {"price": "0.77", "size": "44.28"}, {"price": "0.79", "size": "40"}, {"price": "0.84", "size": "260.59"}, {"price": "0.85", "size": "1004"}, {"price": "0.87", "size": "75"}, {"price": "0.88", "size": "49.71"}], "asks": [{"price": "0.99", "size": "25800"}, {"price": "0.98", "size": "33.54"}, {"price": "0.97", "size": "3305.07"}, {"price": "0.96", "size": "260.76"}, {"price": "0.95", "size": "330"}, {"price": "0.94", "size": "56.56"}, {"price": "0.93", "size": "264.28"}, {"price": "0.92", "size": "116.59"}, {"price": "0.91", "size": "130"}, {"price": "0.9", "size": "50"}, {"price": "0.89", "size": "9.09"}], "event_type": "book", "last_trade_price": "0.880"}, {"market": "0x7d4227c3c4f79de22bbf5b10301d3e99733151de11a2af04ee5d4fe9147fdb94", "asset_id": "106160144365361466407303030429537634959446638743399742742547862828370756994868", "timestamp": "1769384014818", "hash": "926cc1b67c35599353197e63ece7bd6dfcf3e35c", "bids": [{"price": "0.001", "size": "96708.36"}, {"price": "0.002", "size": "77480.15"}, {"price": "0.003", "size": "4814"}, {"price": "0.004", "size": "37.81"}, {"price": "0.01", "size": "3000"}, {"price": "0.011", "size": "3100"}, {"price": "0.014", "size": "7100"}, {"price": "0.015", "size": "5.29"}, {"price": "0.02", "size": "1000"}, {"price": "0.021", "size": "11.86"}, {"price": "0.03", "size": "4000"}, {"price": "0.04", "size": "300"}, {"price": "0.041", "size": "7.91"}, {"price": "0.05", "size": "1650.23"}, {"price": "0.06", "size": "2000"}, {"price": "0.062", "size": "179.86"}, {"price": "0.065", "size": "500"}, {"price": "0.067", "size": "800"}, {"price": "0.069", "size": "73"}, {"price": "0.07", "size": "11.95"}, {"price": "0.13", "size": "400"}, {"price": "0.143", "size": "36.01"}, {"price": "0.146", "size": "100"}, {"price": "0.149", "size": "100"}, {"price": "0.153", "size": "100"}, {"price": "0.156", "size": "100"}, {"price": "0.166", "size": "100.31"}, {"price": "0.167", "size": "65.86"}, {"price": "0.178", "size": "35.97"}, {"price": "0.188", "size": "16"}, {"price": "0.191", "size": "57.41"}, {"price": "0.203", "size": "84"}, {"price": "0.206", "size": "150"}, {"price": "0.213", "size": "16"}, {"price": "0.215", "size": "100"}, {"price": "0.217", "size": "141.74"}, {"price": "0.25", "size": "400"}, {"price": "0.277", "size": "898.85"}, {"price": "0.28", "size": "5"}], "asks": [{"price": "0.999", "size": "1118909.18"}, {"price": "0.998", "size": "1257.06"}, {"price": "0.997", "size": "1175.35"}, {"price": "0.996", "size": "201000"}, {"price": "0.995", "size": "5.56"}, {"price": "0.994", "size": "83"}, {"price": "0.993", "size": "26.84"}, {"price": "0.98", "size": "5000"}, {"price": "0.979", "size": "6.64"}, {"price": "0.97", "size": "4000"}, {"price": "0.969", "size": "32000"}, {"price": "0.968", "size": "10.85"}, {"price": "0.95", "size": "30"}, {"price": "0.949", "size": "39"}, {"price": "0.94", "size": "2000"}, {"price": "0.939", "size": "6000"}, {"price": "0.938", "size": "5.04"}, {"price": "0.908", "size": "4400"}, {"price": "0.907", "size": "6.49"}, {"price": "0.854", "size": "1094"}, {"price": "0.848", "size": "300"}, {"price": "0.847", "size": "3644"}, {"price": "0.8", "size": "50"}, {"price": "0.69", "size": "350"}, {"price": "0.66", "size": "444"}, {"price": "0.659", "size": "952"}, {"price": "0.656", "size": "5"}, {"price": "0.51", "size": "9.26"}, {"price": "0.5", "size": "151"}, {"price": "0.49", "size": "5"}, {"price": "0.48", "size": "5"}, {"price": "0.47", "size": "5"}, {"price": "0.469", "size": "10"}, {"price": "0.46", "size": "5"}, {"price": "0.45", "size": "5"}, {"price": "0.44", "size": "5"}, {"price": "0.43", "size": "5"}, {"price": "0.42", "size": "5"}, {"price": "0.41", "size": "5"}, {"price": "0.409", "size": "40"}, {"price": "0.408", "size": "30"}, {"price": "0.407", "size": "20"}, {"price": "0.4", "size": "158.47"}, {"price": "0.39", "size": "205"}, {"price": "0.389", "size": "50"}, {"price": "0.38", "size": "5"}, {"price": "0.375", "size": "9.1"}, {"price": "0.37", "size": "5"}, {"price": "0.36", "size": "5"}, {"price": "0.35", "size": "5"}, {"price": "0.349", "size": "46.24"}, {"price": "0.344", "size": "7"}, {"price": "0.34", "size": "15"}, {"price": "0.339", "size": "10"}, {"price": "0.319", "size": "9.34"}], "event_type": "book", "last_trade_price": "0.300"}, {"market": "0x7130b2c99bee81af658adafb4a6235f21575f568e3ae2a850af742afa50c2d85", "asset_id": "17878506599231681723092997062254912120536148530389060800857875232098186845304", "timestamp": "1769384013384", "hash": "38156e1a917c1ed27da395cc4313d8678fa79374", "bids": [{"price": "0.001", "size": "3908.17"}, {"price": "0.002", "size": "1263.93"}, {"price": "0.003", "size": "12000"}, {"price": "0.004", "size": "57.43"}, {"price": "0.02", "size": "5000"}, {"price": "0.021", "size": "6.05"}, {"price": "0.03", "size": "4000"}, {"price": "0.031", "size": "11.25"}, {"price": "0.05", "size": "30"}, {"price": "0.051", "size": "39"}, {"price": "0.06", "size": "2000"}, {"price": "0.061", "size": "5.3"}, {"price": "0.097", "size": "3092"}, {"price": "0.099", "size": "5642"}, {"price": "0.1", "size": "6.04"}, {"price": "0.219", "size": "730"}, {"price": "0.22", "size": "50"}, {"price": "0.221", "size": "25"}, {"price": "0.27", "size": "50"}, {"price": "0.34", "size": "50"}, {"price": "0.351", "size": "15"}, {"price": "0.5", "size": "422.82"}, {"price": "0.501", "size": "596"}, {"price": "0.502", "size": "5"}, {"price": "0.503", "size": "10"}, {"price": "0.75", "size": "81.96"}, {"price": "0.755", "size": "10"}, {"price": "0.757", "size": "40"}, {"price": "0.76", "size": "30"}, {"price": "0.761", "size": "50"}, {"price": "0.762", "size": "20"}, {"price": "0.802", "size": "150"}, {"price": "0.811", "size": "16.02"}, {"price": "0.812", "size": "13.54"}, {"price": "0.886", "size": "117.41"}], "asks": [{"price": "0.999", "size": "53526.56"}, {"price": "0.998", "size": "79011.45"}, {"price": "0.997", "size": "22.56"}, {"price": "0.996", "size": "46"}, {"price": "0.995", "size": "400"}, {"price": "0.994", "size": "48.07"}, {"price": "0.986", "size": "300"}, {"price": "0.985", "size": "22.08"}, {"price": "0.976", "size": "50"}, {"price": "0.975", "size": "8.8"}, {"price": "0.97", "size": "28.26"}, {"price": "0.968", "size": "171.87"}, {"price": "0.967", "size": "11.11"}, {"price": "0.954", "size": "56"}, {"price": "0.95", "size": "419.99"}, {"price": "0.949", "size": "16"}, {"price": "0.948", "size": "6.4"}, {"price": "0.933", "size": "899.98"}, {"price": "0.929", "size": "661"}, {"price": "0.927", "size": "8.87"}, {"price": "0.925", "size": "150"}, {"price": "0.921", "size": "594"}, {"price": "0.92", "size": "116"}, {"price": "0.914", "size": "100"}, {"price": "0.913", "size": "1540"}, {"price": "0.909", "size": "119.54"}, {"price": "0.908", "size": "71.2"}], "event_type": "book", "last_trade_price": "0.886"}, {"market": "0x74cda80b2734086fa7e6bfce27d6321bb617d28dde6b486e7d3567c6afa5f46f", "asset_id": "108808298639528397169807740481685882973822875737039638334154867204245949286757", "timestamp": "1769384013366", "hash": "569c76eda64fe56d7585f7f1ce899b96765bd8c6", "bids": [{"price": "0.01", "size": "25805.69"}, {"price": "0.02", "size": "17.45"}, {"price": "0.03", "size": "3116"}, {"price": "0.04", "size": "706.47"}, {"price": "0.05", "size": "157.5"}, {"price": "0.06", "size": "16.84"}, {"price": "0.07", "size": "10"}, {"price": "0.08", "size": "930.66"}, {"price": "0.09", "size": "184"}, {"price": "0.1", "size": "52.2"}], "asks": [{"price": "0.99", "size": "61013.8"}, {"price": "0.98", "size": "5012.9"}, {"price": "0.97", "size": "17250"}, {"price": "0.96", "size": "11.27"}, {"price": "0.95", "size": "30"}, {"price": "0.94", "size": "2033"}, {"price": "0.93", "size": "7440"}, {"price": "0.92", "size": "10.35"}, {"price": "0.88", "size": "1332"}, {"price": "0.87", "size": "4530"}, {"price": "0.8", "size": "50"}, {"price": "0.68", "size": "1601"}, {"price": "0.67", "size": "250"}, {"price": "0.66", "size": "50"}, {"price": "0.49", "size": "21.56"}, {"price": "0.43", "size": "5"}, {"price": "0.33", "size": "149"}, {"price": "0.32", "size": "10"}, {"price": "0.31", "size": "20"}, {"price": "0.22", "size": "46.66"}, {"price": "0.21", "size": "40"}, {"price": "0.2", "size": "135"}, {"price": "0.15", "size": "63"}, {"price": "0.14", "size": "329.71"}, {"price": "0.13", "size": "130"}], "event_type": "book", "last_trade_price": "0.870"}, {"market": "0x7d4227c3c4f79de22bbf5b10301d3e99733151de11a2af04ee5d4fe9147fdb94", "asset_id": "114175921346199629913576111903487851727201567831569002664280492572302128017807", "timestamp": "1769384014818", "hash": "d500c3238997748411d132e44d5fe17ed5275cac", "bids": [{"price": "0.001", "size": "1118909.18"}, {"price": "0.002", "size": "1257.06"}, {"price": "0.003", "size": "1175.35"}, {"price": "0.004", "size": "201000"}, {"price": "0.005", "size": "5.56"}, {"price": "0.006", "size": "83"}, {"price": "0.007", "size": "26.84"}, {"price": "0.02", "size": "5000"}, {"price": "0.021", "size": "6.64"}, {"price": "0.03", "size": "4000"}, {"price": "0.031", "size": "32000"}, {"price": "0.032", "size": "10.85"}, {"price": "0.05", "size": "30"}, {"price": "0.051", "size": "39"}, {"price": "0.06", "size": "2000"}, {"price": "0.061", "size": "6000"}, {"price": "0.062", "size": "5.04"}, {"price": "0.092", "size": "4400"}, {"price": "0.093", "size": "6.49"}, {"price": "0.146", "size": "1094"}, {"price": "0.152", "size": "300"}, {"price": "0.153", "size": "3644"}, {"price": "0.2", "size": "50"}, {"price": "0.31", "size": "350"}, {"price": "0.34", "size": "444"}, {"price": "0.341", "size": "952"}, {"price": "0.344", "size": "5"}, {"price": "0.49", "size": "9.26"}, {"price": "0.5", "size": "151"}, {"price": "0.51", "size": "5"}, {"price": "0.52", "size": "5"}, {"price": "0.53", "size": "5"}, {"price": "0.531", "size": "10"}, {"price": "0.54", "size": "5"}, {"price": "0.55", "size": "5"}, {"price": "0.56", "size": "5"}, {"price": "0.57", "size": "5"}, {"price": "0.58", "size": "5"}, {"price": "0.59", "size": "5"}, {"price": "0.591", "size": "40"}, {"price": "0.592", "size": "30"}, {"price": "0.593", "size": "20"}, {"price": "0.6", "size": "158.47"}, {"price": "0.61", "size": "205"}, {"price": "0.611", "size": "50"}, {"price": "0.62", "size": "5"}, {"price": "0.625", "size": "9.1"}, {"price": "0.63", "size": "5"}, {"price": "0.64", "size": "5"}, {"price": "0.65", "size": "5"}, {"price": "0.651", "size": "46.24"}, {"price": "0.656", "size": "7"}, {"price": "0.66", "size": "15"}, {"price": "0.661", "size": "10"}, {"price": "0.681", "size": "9.34"}], "asks": [{"price": "0.999", "size": "96708.36"}, {"price": "0.998", "size": "77480.15"}, {"price": "0.997", "size": "4814"}, {"price": "0.996", "size": "37.81"}, {"price": "0.99", "size": "3000"}, {"price": "0.989", "size": "3100"}, {"price": "0.986", "size": "7100"}, {"price": "0.985", "size": "5.29"}, {"price": "0.98", "size": "1000"}, {"price": "0.979", "size": "11.86"}, {"price": "0.97", "size": "4000"}, {"price": "0.96", "size": "300"}, {"price": "0.959", "size": "7.91"}, {"price": "0.95", "size": "1650.23"}, {"price": "0.94", "size": "2000"}, {"price": "0.938", "size": "179.86"}, {"price": "0.935", "size": "500"}, {"price": "0.933", "size": "800"}, {"price": "0.931", "size": "73"}, {"price": "0.93", "size": "11.95"}, {"price": "0.87", "size": "400"}, {"price": "0.857", "size": "36.01"}, {"price": "0.854", "size": "100"}, {"price": "0.851", "size": "100"}, {"price": "0.847", "size": "100"}, {"price": "0.844", "size": "100"}, {"price": "0.834", "size": "100.31"}, {"price": "0.833", "size": "65.86"}, {"price": "0.822", "size": "35.97"}, {"price": "0.812", "size": "16"}, {"price": "0.809", "size": "57.41"}, {"price": "0.797", "size": "84"}, {"price": "0.794", "size": "150"}, {"price": "0.787", "size": "16"}, {"price": "0.785", "size": "100"}, {"price": "0.783", "size": "141.74"}, {"price": "0.75", "size": "400"}, {"price": "0.723", "size": "898.85"}, {"price": "0.72", "size": "5"}], "event_type": "book", "last_trade_price": "0.300"}]}
{"_local_timestamp": "2026-01-25T23:33:36.619459+00:00", "data": {"market": "0x7d4227c3c4f79de22bbf5b10301d3e99733151de11a2af04ee5d4fe9147fdb94", "price_changes": [{"asset_id": "114175921346199629913576111903487851727201567831569002664280492572302128017807", "price": "0.73", "size": "5", "side": "SELL", "hash": "f6d479323b817d805ed68e17587306526dbdefe5", "best_bid": "0.681", "best_ask": "0.72"}, {"asset_id": "106160144365361466407303030429537634959446638743399742742547862828370756994868", "price": "0.27", "size": "5", "side": "BUY", "hash": "f5eb4c1abba21873491b7d131b5e2521c8b27216", "best_bid": "0.28", "best_ask": "0.319"}], "timestamp": "1769384016547", "event_type": "price_change"}}
{"_local_timestamp": "2026-01-25T23:33:36.747071+00:00", "data": {"market": "0xbbf9e226512452452438571385c111fafd7a581f227d997183b3c0ed0aaa6e94", "price_changes": [{"asset_id": "70641103843303633433849051708048017041225992079285926883062800006960120844878", "price": "0.69", "size": "102", "side": "BUY", "hash": "8fb94f178bfbed41e7fcf7cca5e7008e57c09916", "best_bid": "0.75", "best_ask": "0.8"}, {"asset_id": "32365631237478011719581335465835096900088880772439977051943287219696169513404", "price": "0.31", "size": "102", "side": "SELL", "hash": "dd0331d7a72f2241ddaff36c0e4e0301c7205966", "best_bid": "0.2", "best_ask": "0.25"}], "timestamp": "1769384016673", "event_type": "price_change"}}
{"_local_timestamp": "2026-01-25T23:33:36.761871+00:00", "data": {"market": "0xa19142e40da92f4110d29f63475ed9689f1471f8963c87e3220a989cdb356d45", "price_changes": [{"asset_id": "49980127219724914096527114792845752329307347014547067418981570311158802130688", "price": "0.101", "size": "182.85", "side": "SELL", "hash": "e4c0ebceecca5abafb43cd3027d1c3af0a0245c2", "best_bid": "0.096", "best_ask": "0.101"}, {"asset_id": "81750849409365469972793631297951692550835139647103107287253620651299358774290", "price": "0.899", "size": "182.85", "side": "BUY", "hash": "0e8ae5cd43bf12aa9c830ead7f2017f50e5d71c6", "best_bid": "0.899", "best_ask": "0.904"}], "timestamp": "1769384016682", "event_type": "price_change"}}
{"_local_timestamp": "2026-01-25T23:33:36.762551+00:00", "data": {"market": "0x7d4227c3c4f79de22bbf5b10301d3e99733151de11a2af04ee5d4fe9147fdb94", "price_changes": [{"asset_id": "114175921346199629913576111903487851727201567831569002664280492572302128017807", "price": "0.656", "size": "0", "side": "BUY", "hash": "48efd269a7bef8554b25bd01e142bb18d01ab0ea", "best_bid": "0.681", "best_ask": "0.72"}, {"asset_id": "106160144365361466407303030429537634959446638743399742742547862828370756994868", "price": "0.344", "size": "0", "side": "SELL", "hash": "4a2441cf9590bc45bd97f507262555c26c6cb0b4", "best_bid": "0.28", "best_ask": "0.319"}], "timestamp": "1769384016683", "event_type": "price_change"}}
{"_local_timestamp": "2026-01-25T23:33:36.762988+00:00", "data": {"market": "0xbbf9e226512452452438571385c111fafd7a581f227d997183b3c0ed0aaa6e94", "price_changes": [{"asset_id": "70641103843303633433849051708048017041225992079285926883062800006960120844878", "price": "0.68", "size": "86.17", "side": "BUY", "hash": "76aa2211158fbf7357cf96faafcf94724d08bd22", "best_bid": "0.75", "best_ask": "0.8"}, {"asset_id": "32365631237478011719581335465835096900088880772439977051943287219696169513404", "price": "0.32", "size": "86.17", "side": "SELL", "hash": "f53db82caaf5fb52157ad9f0ea29566e18f75ee4", "best_bid": "0.2", "best_ask": "0.25"}], "timestamp": "1769384016684", "event_type": "price_change"}}
{"_local_timestamp": "2026-01-25T23:33:36.868224+00:00", "data": {"market": "0x7d4227c3c4f79de22bbf5b10301d3e99733151de11a2af04ee5d4fe9147fdb94", "price_changes": [{"asset_id": "114175921346199629913576111903487851727201567831569002664280492572302128017807", "price": "0.656", "size": "7", "side": "BUY", "hash": "a074bec188b6b1af3217fe865c3911c0d473e0d0", "best_bid": "0.681", "best_ask": "0.72"}, {"asset_id": "106160144365361466407303030429537634959446638743399742742547862828370756994868", "price": "0.344", "size": "7", "side": "SELL", "hash": "32e255245452d565774fb6d55c3601e6d73eeb7a", "best_bid": "0.28", "best_ask": "0.319"}], "timestamp": "1769384016798", "event_type": "price_change"}}
{"_local_timestamp": "2026-01-25T23:33:36.979110+00:00", "data": {"market": "0x5e75c47528185caa0b8140d5199a505b111d535d004f10c14c77099e160f8c43", "price_changes": [{"asset_id": "37216599669721820787426834964764344032227136269811356205946493119045847831924", "price": "0.79", "size": "90", "side": "BUY", "hash": "8ab8f0fc892d47812243d0f681f419354467df4a", "best_bid": "0.88", "best_ask": "0.89"}, {"asset_id": "40497352693029741963885292742967835565636400191703716161158810847504561227789", "price": "0.21", "size": "90", "side": "SELL", "hash": "680889f23af0e8ae704001108619bfc787d95b53", "best_bid": "0.11", "best_ask": "0.12"}], "timestamp": "1769384016906", "event_type": "price_change"}}
{"_local_timestamp": "2026-01-25T23:33:37.081083+00:00", "data": {"market": "0x5e75c47528185caa0b8140d5199a505b111d535d004f10c14c77099e160f8c43", "price_changes": [{"asset_id": "37216599669721820787426834964764344032227136269811356205946493119045847831924", "price": "0.79", "size": "40", "side": "BUY", "hash": "d1392bcd87c5a96c8aa85864aa9df611bf8ca7bd", "best_bid": "0.88", "best_ask": "0.89"}, {"asset_id": "40497352693029741963885292742967835565636400191703716161158810847504561227789", "price": "0.21", "size": "40", "side": "SELL", "hash": "b0ff21703f8014e579bcc9855253a89dd8b26b3a", "best_bid": "0.11", "best_ask": "0.12"}], "timestamp": "1769384017008", "event_type": "price_change"}}
{"_local_timestamp": "2026-01-25T23:33:37.099172+00:00", "data": {"market": "0x7d4227c3c4f79de22bbf5b10301d3e99733151de11a2af04ee5d4fe9147fdb94", "price_changes": [{"asset_id": "114175921346199629913576111903487851727201567831569002664280492572302128017807", "price": "0.656", "size": "0", "side": "BUY", "hash": "ffda0ea97609fedbabbb0d3ffd972f78383eab7c", "best_bid": "0.681", "best_ask": "0.72"}, {"asset_id": "106160144365361466407303030429537634959446638743399742742547862828370756994868", "price": "0.344", "size": "0", "side": "SELL", "hash": "77e43cf7c44d87f1467ad3d048b2e038c29bbbc0", "best_bid": "0.28", "best_ask": "0.319"}], "timestamp": "1769384017030", "event_type": "price_change"}}
{"_local_timestamp": "2026-01-25T23:33:37.167104+00:00", "data": {"market": "0x7d4227c3c4f79de22bbf5b10301d3e99733151de11a2af04ee5d4fe9147fdb94", "price_changes": [{"asset_id": "106160144365361466407303030429537634959446638743399742742547862828370756994868", "price": "0.28", "size": "30", "side": "BUY", "hash": "0c2ca77bef8af3dd15b16a48fafb95b47a359db0", "best_bid": "0.28", "best_ask": "0.319"}, {"asset_id": "114175921346199629913576111903487851727201567831569002664280492572302128017807", "price": "0.72", "size": "30", "side": "SELL", "hash": "80a79ccfd739b2c1b029feed9ea96c6160e9fc2e", "best_bid": "0.681", "best_ask": "0.72"}], "timestamp": "1769384017099", "event_type": "price_change"}}
{"_local_timestamp": "2026-01-25T23:33:37.541138+00:00", "data": {"market": "0x7d4227c3c4f79de22bbf5b10301d3e99733151de11a2af04ee5d4fe9147fdb94", "price_changes": [{"asset_id": "106160144365361466407303030429537634959446638743399742742547862828370756994868", "price": "0.277", "size": "888.85", "side": "BUY", "hash": "182e7d8e5bad92f70129d508157464afa853f051", "best_bid": "0.28", "best_ask": "0.319"}, {"asset_id": "114175921346199629913576111903487851727201567831569002664280492572302128017807", "price": "0.723", "size": "888.85", "side": "SELL", "hash": "a68811d25cec849c49c439e06c3447bc5b2de03a", "best_bid": "0.681", "best_ask": "0.72"}], "timestamp": "1769384017438", "event_type": "price_change"}}
{"_local_timestamp": "2026-01-25T23:33:37.604699+00:00", "data": {"market": "0x7d4227c3c4f79de22bbf5b10301d3e99733151de11a2af04ee5d4fe9147fdb94", "price_changes": [{"asset_id": "106160144365361466407303030429537634959446638743399742742547862828370756994868", "price": "0.271", "size": "10", "side": "BUY", "hash": "52fbf043b3293dddb9639ccde44e32b57980485b", "best_bid": "0.28", "best_ask": "0.319"}, {"asset_id": "114175921346199629913576111903487851727201567831569002664280492572302128017807", "price": "0.729", "size": "10", "side": "SELL", "hash": "de29fd6c2d82288a5046baba31af8566028a74e1", "best_bid": "0.681", "best_ask": "0.72"}], "timestamp": "1769384017525", "event_type": "price_change"}}
{"_local_timestamp": "2026-01-25T23:33:38.502818+00:00", "data": {"market": "0x5b87791e06388b1a91fd402c29e483842da0f9fec156bb3cefe9d58275a0373b", "price_changes": [{"asset_id": "90132986654259086678529082268082617450254793801662820786849470352289449813683", "price": "0.033", "size": "63.88", "side": "BUY", "hash": "bc849f5005ed1b334948921b32d573df4f2de63c", "best_bid": "0.033", "best_ask": "0.04"}, {"asset_id": "88022913747451311038559242580697856881859219751804674115271835179181575694176", "price": "0.967", "size": "63.88", "side": "SELL", "hash": "2e6ba55cf3df0d662f4ead73b1d5e94addd7b2cb", "best_bid": "0.96", "best_ask": "0.967"}], "timestamp": "1769384018429", "event_type": "price_change"}}
{"_local_timestamp": "2026-01-25T23:33:38.622780+00:00", "data": {"market": "0x5b87791e06388b1a91fd402c29e483842da0f9fec156bb3cefe9d58275a0373b", "price_changes": [{"asset_id": "90132986654259086678529082268082617450254793801662820786849470352289449813683", "price": "0.031", "size": "184", "side": "BUY", "hash": "e764d3409c3ef21d596f53b06f7105233d1b0c59", "best_bid": "0.033", "best_ask": "0.04"}, {"asset_id": "88022913747451311038559242580697856881859219751804674115271835179181575694176", "price": "0.969", "size": "184", "side": "SELL", "hash": "0ddc663db42924311d454cbad984a30c41e9597e", "best_bid": "0.96", "best_ask": "0.967"}], "timestamp": "1769384018554", "event_type": "price_change"}}
{"_local_timestamp": "2026-01-25T23:33:38.624231+00:00", "data": {"market": "0x5b87791e06388b1a91fd402c29e483842da0f9fec156bb3cefe9d58275a0373b", "price_changes": [{"asset_id": "88022913747451311038559242580697856881859219751804674115271835179181575694176", "price": "0.956", "size": "79.99", "side": "BUY", "hash": "d21fa0ea64850e70cd3b3befcd358b0d81df8232", "best_bid": "0.96", "best_ask": "0.967"}, {"asset_id": "90132986654259086678529082268082617450254793801662820786849470352289449813683", "price": "0.044", "size": "79.99", "side": "SELL", "hash": "827a128b63c4875f9bba3a63b3666d449049e561", "best_bid": "0.033", "best_ask": "0.04"}], "timestamp": "1769384018554", "event_type": "price_change"}}
{"_local_timestamp": "2026-01-25T23:33:38.689744+00:00", "data": {"market": "0x7d4227c3c4f79de22bbf5b10301d3e99733151de11a2af04ee5d4fe9147fdb94", "price_changes": [{"asset_id": "114175921346199629913576111903487851727201567831569002664280492572302128017807", "price": "0.74", "size": "5", "side": "SELL", "hash": "05062d05343c179b165a80f423aedf27c3a9907e", "best_bid": "0.681", "best_ask": "0.72"}, {"asset_id": "106160144365361466407303030429537634959446638743399742742547862828370756994868", "price": "0.26", "size": "5", "side": "BUY", "hash": "ca0bb017f8b2c8accd52fb4b5cc92fd03b24684f", "best_bid": "0.28", "best_ask": "0.319"}], "timestamp": "1769384018605", "event_type": "price_change"}}
{"_local_timestamp": "2026-01-25T23:33:38.778958+00:00", "data": {"market": "0x5b87791e06388b1a91fd402c29e483842da0f9fec156bb3cefe9d58275a0373b", "price_changes": [{"asset_id": "88022913747451311038559242580697856881859219751804674115271835179181575694176", "price": "0.956", "size": "129.99", "side": "BUY", "hash": "c71bc59720a63be57382b36360f11a8bc1ee87e7", "best_bid": "0.96", "best_ask": "0.967"}, {"asset_id": "90132986654259086678529082268082617450254793801662820786849470352289449813683", "price": "0.044", "size": "129.99", "side": "SELL", "hash": "c8296510a8984c0d1acff9c5eb8c64a040a34636", "best_bid": "0.033", "best_ask": "0.04"}], "timestamp": "1769384018703", "event_type": "price_change"}}
{"_local_timestamp": "2026-01-25T23:33:38.790424+00:00", "data": {"market": "0x5b87791e06388b1a91fd402c29e483842da0f9fec156bb3cefe9d58275a0373b", "price_changes": [{"asset_id": "90132986654259086678529082268082617450254793801662820786849470352289449813683", "price": "0.032", "size": "180", "side": "BUY", "hash": "3d1ad0672cb66bf4f081bafcf86f7fb903cfd65b", "best_bid": "0.033", "best_ask": "0.04"}, {"asset_id": "88022913747451311038559242580697856881859219751804674115271835179181575694176", "price": "0.968", "size": "180", "side": "SELL", "hash": "1446c98aaec5b1149c646e920d44259776cfdf85", "best_bid": "0.96", "best_ask": "0.967"}], "timestamp": "1769384018704", "event_type": "price_change"}}
{"_local_timestamp": "2026-01-25T23:33:38.849611+00:00", "data": {"market": "0x7d4227c3c4f79de22bbf5b10301d3e99733151de11a2af04ee5d4fe9147fdb94", "price_changes": [{"asset_id": "114175921346199629913576111903487851727201567831569002664280492572302128017807", "price": "0.656", "size": "7", "side": "BUY", "hash": "c28a20812486e9339d6b96a1c82d9d1e624e77d6", "best_bid": "0.681", "best_ask": "0.72"}, {"asset_id": "106160144365361466407303030429537634959446638743399742742547862828370756994868", "price": "0.344", "size": "7", "side": "SELL", "hash": "916c640350d5cef4002f0de86755f94d5e8c7d50", "best_bid": "0.28", "best_ask": "0.319"}], "timestamp": "1769384018772", "event_type": "price_change"}}
{"_local_timestamp": "2026-01-25T23:33:38.850500+00:00", "data": {"market": "0x5e75c47528185caa0b8140d5199a505b111d535d004f10c14c77099e160f8c43", "price_changes": [{"asset_id": "37216599669721820787426834964764344032227136269811356205946493119045847831924", "price": "0.76", "size": "0", "side": "BUY", "hash": "25ee477feaff969f43b752c992331c8c64d7665d", "best_bid": "0.88", "best_ask": "0.89"}, {"asset_id": "40497352693029741963885292742967835565636400191703716161158810847504561227789", "price": "0.24", "size": "0", "side": "SELL", "hash": "637f955655ac2421bba4057ee1a92997ae9eee3b", "best_bid": "0.11", "best_ask": "0.12"}], "timestamp": "1769384018777", "event_type": "price_change"}}
{"_local_timestamp": "2026-01-25T23:33:38.851210+00:00", "data": {"market": "0xa19142e40da92f4110d29f63475ed9689f1471f8963c87e3220a989cdb356d45", "price_changes": [{"asset_id": "81750849409365469972793631297951692550835139647103107287253620651299358774290", "price": "0.776", "size": "0", "side": "BUY", "hash": "adf9516f3c9fa4064fff208b6b3a6441acd72164", "best_bid": "0.899", "best_ask": "0.904"}, {"asset_id": "49980127219724914096527114792845752329307347014547067418981570311158802130688", "price": "0.224", "size": "0", "side": "SELL", "hash": "b0cbaf74ce692669bb3ec9411c2e0217b458b423", "best_bid": "0.096", "best_ask": "0.101"}], "timestamp": "1769384018777", "event_type": "price_change"}}
{"_local_timestamp": "2026-01-25T23:33:38.873485+00:00", "data": {"market": "0x5e75c47528185caa0b8140d5199a505b111d535d004f10c14c77099e160f8c43", "price_changes": [{"asset_id": "37216599669721820787426834964764344032227136269811356205946493119045847831924", "price": "0.77", "size": "64.28", "side": "BUY", "hash": "99cefebd7d1e1fd2b612d07068fb703ff6241a1a", "best_bid": "0.88", "best_ask": "0.89"}, {"asset_id": "40497352693029741963885292742967835565636400191703716161158810847504561227789", "price": "0.23", "size": "64.28", "side": "SELL", "hash": "3ca1da5654a9817c62dd907e3097173c2131dafc", "best_bid": "0.11", "best_ask": "0.12"}], "timestamp": "1769384018803", "event_type": "price_change"}}
{"_local_timestamp": "2026-01-25T23:33:38.874820+00:00", "data": {"market": "0xa19142e40da92f4110d29f63475ed9689f1471f8963c87e3220a989cdb356d45", "price_changes": [{"asset_id": "81750849409365469972793631297951692550835139647103107287253620651299358774290", "price": "0.78", "size": "360.15", "side": "BUY", "hash": "1ed51ecbe1df5de585c4ecc75a77b60f0a75469b", "best_bid": "0.899", "best_ask": "0.904"}, {"asset_id": "49980127219724914096527114792845752329307347014547067418981570311158802130688", "price": "0.22", "size": "360.15", "side": "SELL", "hash": "5c8768dee0e596d84400aecc5d45e7969a3d364a", "best_bid": "0.096", "best_ask": "0.101"}], "timestamp": "1769384018803", "event_type": "price_change"}}
{"_local_timestamp": "2026-01-25T23:33:39.109129+00:00", "data": {"market": "0x5b87791e06388b1a91fd402c29e483842da0f9fec156bb3cefe9d58275a0373b", "price_changes": [{"asset_id": "88022913747451311038559242580697856881859219751804674115271835179181575694176", "price": "0.968", "size": "150", "side": "SELL", "hash": "fd1254e55bb020dc052fdcb22183297e5958d671", "best_bid": "0.96", "best_ask": "0.967"}, {"asset_id": "90132986654259086678529082268082617450254793801662820786849470352289449813683", "price": "0.032", "size": "150", "side": "BUY", "hash": "e77c940f0e0937c7adfa8c1fc2c1bb3829ff32f5", "best_bid": "0.033", "best_ask": "0.04"}], "timestamp": "1769384019022", "event_type": "price_change"}}
{"_local_timestamp": "2026-01-25T23:33:39.151741+00:00", "data": {"market": "0x7d4227c3c4f79de22bbf5b10301d3e99733151de11a2af04ee5d4fe9147fdb94", "price_changes": [{"asset_id": "106160144365361466407303030429537634959446638743399742742547862828370756994868", "price": "0.349", "size": "11.56", "side": "SELL", "hash": "a77af7ceadf918eb0aeed45f1accb6cba6323cca", "best_bid": "0.28", "best_ask": "0.319"}, {"asset_id": "114175921346199629913576111903487851727201567831569002664280492572302128017807", "price": "0.651", "size": "11.56", "side": "BUY", "hash": "98ff0c67fa35cfd559657f5ffc2bd4e0611906a4", "best_bid": "0.681", "best_ask": "0.72"}], "timestamp": "1769384019081", "event_type": "price_change"}}
{"_local_timestamp": "2026-01-25T23:33:39.168493+00:00", "data": {"market": "0x7d4227c3c4f79de22bbf5b10301d3e99733151de11a2af04ee5d4fe9147fdb94", "price_changes": [{"asset_id": "106160144365361466407303030429537634959446638743399742742547862828370756994868", "price": "0.349", "size": "0", "side": "SELL", "hash": "b72f132b4fc51ff1065b18cdca2d4a20d0629c5a", "best_bid": "0.28", "best_ask": "0.319"}, {"asset_id": "114175921346199629913576111903487851727201567831569002664280492572302128017807", "price": "0.651", "size": "0", "side": "BUY", "hash": "666097ba4431537aad69cd322b1d7be1d47d302c", "best_bid": "0.681", "best_ask": "0.72"}], "timestamp": "1769384019098", "event_type": "price_change"}}
{"_local_timestamp": "2026-01-25T23:33:39.235649+00:00", "data": {"market": "0x7d4227c3c4f79de22bbf5b10301d3e99733151de11a2af04ee5d4fe9147fdb94", "price_changes": [{"asset_id": "114175921346199629913576111903487851727201567831569002664280492572302128017807", "price": "0.656", "size": "0", "side": "BUY", "hash": "f612af9f7938065301c5377b5f2c440afe983819", "best_bid": "0.681", "best_ask": "0.72"}, {"asset_id": "106160144365361466407303030429537634959446638743399742742547862828370756994868", "price": "0.344", "size": "0", "side": "SELL", "hash": "b1ee81e5c69724a98f0babbeea4e1e81acd8f6f8", "best_bid": "0.28", "best_ask": "0.319"}], "timestamp": "1769384019167", "event_type": "price_change"}}
{"_local_timestamp": "2026-01-25T23:33:39.290381+00:00", "data": {"market": "0x7d4227c3c4f79de22bbf5b10301d3e99733151de11a2af04ee5d4fe9147fdb94", "price_changes": [{"asset_id": "114175921346199629913576111903487851727201567831569002664280492572302128017807", "price": "0.629", "size": "7", "side": "BUY", "hash": "b0bd8e1b27410a05fe337b38fa61fdc538d1a0bc", "best_bid": "0.681", "best_ask": "0.72"}, {"asset_id": "106160144365361466407303030429537634959446638743399742742547862828370756994868", "price": "0.371", "size": "7", "side": "SELL", "hash": "3412b4f0e1222c9672b5e7c7aec8b9d2ed54812e", "best_bid": "0.28", "best_ask": "0.319"}], "timestamp": "1769384019223", "event_type": "price_change"}}
{"_local_timestamp": "2026-01-25T23:33:39.337291+00:00", "data": {"market": "0x5b87791e06388b1a91fd402c29e483842da0f9fec156bb3cefe9d58275a0373b", "price_changes": [{"asset_id": "88022913747451311038559242580697856881859219751804674115271835179181575694176", "price": "0.966", "size": "30", "side": "SELL", "hash": "58272f3584b87f5604d2af0b4f1ff86964adc4bb", "best_bid": "0.96", "best_ask": "0.966"}, {"asset_id": "90132986654259086678529082268082617450254793801662820786849470352289449813683", "price": "0.034", "size": "30", "side": "BUY", "hash": "826f6d09ee7bea02fae1b1366f7cb694f17fbfce", "best_bid": "0.034", "best_ask": "0.04"}], "timestamp": "1769384019267", "event_type": "price_change"}}
{"_local_timestamp": "2026-01-25T23:33:39.341842+00:00", "data": {"market": "0x5e75c47528185caa0b8140d5199a505b111d535d004f10c14c77099e160f8c43", "price_changes": [{"asset_id": "37216599669721820787426834964764344032227136269811356205946493119045847831924", "price": "0.79", "size": "90", "side": "BUY", "hash": "ef3dcc2c8656b01da28785a0ccf3486509e5492e", "best_bid": "0.88", "best_ask": "0.89"}, {"asset_id": "40497352693029741963885292742967835565636400191703716161158810847504561227789", "price": "0.21", "size": "90", "side": "SELL", "hash": "72eefb0e474a098fe5ae9df1ae1d57c20f18ebfa", "best_bid": "0.11", "best_ask": "0.12"}], "timestamp": "1769384019268", "event_type": "price_change"}}
{"_local_timestamp": "2026-01-25T23:33:39.545423+00:00", "data": {"market": "0x74cda80b2734086fa7e6bfce27d6321bb617d28dde6b486e7d3567c6afa5f46f", "price_changes": [{"asset_id": "108808298639528397169807740481685882973822875737039638334154867204245949286757", "price": "0.1", "size": "181.21", "side": "BUY", "hash": "4f714bc25da498812b42bce544a474252fc30f1e", "best_bid": "0.1", "best_ask": "0.13"}, {"asset_id": "54097693815260016929707363796097268965809730515171531228590357799043969397342", "price": "0.9", "size": "181.21", "side": "SELL", "hash": "9f9cf0b664edbfaf772f3f9eb68486c03985e97c", "best_bid": "0.87", "best_ask": "0.9"}], "timestamp": "1769384019468", "event_type": "price_change"}}
{"_local_timestamp": "2026-01-25T23:33:39.669354+00:00", "data": {"market": "0xbbf9e226512452452438571385c111fafd7a581f227d997183b3c0ed0aaa6e94", "price_changes": [{"asset_id": "70641103843303633433849051708048017041225992079285926883062800006960120844878", "price": "0.7", "size": "50", "side": "BUY", "hash": "fc9ebb1684d8a20bf89677f85968288c0dd4d629", "best_bid": "0.75", "best_ask": "0.8"}, {"asset_id": "32365631237478011719581335465835096900088880772439977051943287219696169513404", "price": "0.3", "size": "50", "side": "SELL", "hash": "0882f22ff3c72efb1d6b5e8d27a9c7d632ba8c23", "best_bid": "0.2", "best_ask": "0.25"}], "timestamp": "1769384019583", "event_type": "price_change"}}
{"_local_timestamp": "2026-01-25T23:33:39.670252+00:00", "data": {"market": "0x7130b2c99bee81af658adafb4a6235f21575f568e3ae2a850af742afa50c2d85", "price_changes": [{"asset_id": "17878506599231681723092997062254912120536148530389060800857875232098186845304", "price": "0.802", "size": "100", "side": "BUY", "hash": "7bdf5e2baef9184c544b3d1ec805346fd25d0abb", "best_bid": "0.886", "best_ask": "0.908"}, {"asset_id": "79480641743596328156888881841837787012633513624072222555595000167813156519758", "price": "0.198", "size": "100", "side": "SELL", "hash": "dff93bdfd521dbf1ab97cbb6e23754df137b8324", "best_bid": "0.092", "best_ask": "0.114"}], "timestamp": "1769384019584", "event_type": "price_change"}}
{"_local_timestamp": "2026-01-25T23:33:39.672055+00:00", "data": {"market": "0xbbf9e226512452452438571385c111fafd7a581f227d997183b3c0ed0aaa6e94", "price_changes": [{"asset_id": "70641103843303633433849051708048017041225992079285926883062800006960120844878", "price": "0.69", "size": "51", "side": "BUY", "hash": "56953fc77f55255ab343bed93e17defe5aee7f05", "best_bid": "0.75", "best_ask": "0.8"}, {"asset_id": "32365631237478011719581335465835096900088880772439977051943287219696169513404", "price": "0.31", "size": "51", "side": "SELL", "hash": "4c82b80b1ca81f110385388b604d215840287eac", "best_bid": "0.2", "best_ask": "0.25"}], "timestamp": "1769384019586", "event_type": "price_change"}}
{"_local_timestamp": "2026-01-25T23:33:39.673873+00:00", "data": {"market": "0x7130b2c99bee81af658adafb4a6235f21575f568e3ae2a850af742afa50c2d85", "price_changes": [{"asset_id": "17878506599231681723092997062254912120536148530389060800857875232098186845304", "price": "0.802", "size": "50", "side": "BUY", "hash": "8a98177abb01e2542728159ced9c4872eb935852", "best_bid": "0.886", "best_ask": "0.908"}, {"asset_id": "79480641743596328156888881841837787012633513624072222555595000167813156519758", "price": "0.198", "size": "50", "side": "SELL", "hash": "94972f3183849fdabc8ad8fd40e934616d8cc940", "best_bid": "0.092", "best_ask": "0.114"}], "timestamp": "1769384019588", "event_type": "price_change"}}
{"_local_timestamp": "2026-01-25T23:33:39.675149+00:00", "data": {"market": "0x7130b2c99bee81af658adafb4a6235f21575f568e3ae2a850af742afa50c2d85", "price_changes": [{"asset_id": "17878506599231681723092997062254912120536148530389060800857875232098186845304", "price": "0.812", "size": "63.54", "side": "BUY", "hash": "40e3daa25fb1ce25af54a4e3a38fa7cdb15947ca", "best_bid": "0.886", "best_ask": "0.908"}, {"asset_id": "79480641743596328156888881841837787012633513624072222555595000167813156519758", "price": "0.188", "size": "63.54", "side": "SELL", "hash": "6a3a5dcc764a06c7178b56def50ae4f35c4826d3", "best_bid": "0.092", "best_ask": "0.114"}], "timestamp": "1769384019595", "event_type": "price_change"}}
{"_local_timestamp": "2026-01-25T23:33:39.680450+00:00", "data": {"market": "0x7130b2c99bee81af658adafb4a6235f21575f568e3ae2a850af742afa50c2d85", "price_changes": [{"asset_id": "17878506599231681723092997062254912120536148530389060800857875232098186845304", "price": "0.802", "size": "0", "side": "BUY", "hash": "db2153005e1ba86787db7d2a53519083d88d2876", "best_bid": "0.886", "best_ask": "0.908"}, {"asset_id": "79480641743596328156888881841837787012633513624072222555595000167813156519758", "price": "0.198", "size": "0", "side": "SELL", "hash": "3eb6e18ed4138a78093c6e3f33d91acb566a1cd7", "best_bid": "0.092", "best_ask": "0.114"}], "timestamp": "1769384019610", "event_type": "price_change"}}
{"_local_timestamp": "2026-01-25T23:33:39.689925+00:00", "data": {"market": "0xbbf9e226512452452438571385c111fafd7a581f227d997183b3c0ed0aaa6e94", "price_changes": [{"asset_id": "70641103843303633433849051708048017041225992079285926883062800006960120844878", "price": "0.7", "size": "100", "side": "BUY", "hash": "e10dfd1a9542ab31012f8af9fc1b8331b6db6371", "best_bid": "0.75", "best_ask": "0.8"}, {"asset_id": "32365631237478011719581335465835096900088880772439977051943287219696169513404", "price": "0.3", "size": "100", "side": "SELL", "hash": "0d34faa8a3de35e6ca71c2eef288e4fd13326a4b", "best_bid": "0.2", "best_ask": "0.25"}], "timestamp": "1769384019613", "event_type": "price_change"}}
{"_local_timestamp": "2026-01-25T23:33:39.711164+00:00", "data": {"market": "0x7130b2c99bee81af658adafb4a6235f21575f568e3ae2a850af742afa50c2d85", "price_changes": [{"asset_id": "17878506599231681723092997062254912120536148530389060800857875232098186845304", "price": "0.812", "size": "113.54", "side": "BUY", "hash": "4376fbf1f85537b2d152c2e92319c777b8adcb61", "best_bid": "0.886", "best_ask": "0.908"}, {"asset_id": "79480641743596328156888881841837787012633513624072222555595000167813156519758", "price": "0.188", "size": "113.54", "side": "SELL", "hash": "a9fdbb58264bc12c2a45dc728392d26f3eecd4f8", "best_bid": "0.092", "best_ask": "0.114"}], "timestamp": "1769384019642", "event_type": "price_change"}}
{"_local_timestamp": "2026-01-25T23:33:39.718364+00:00", "data": {"market": "0xbbf9e226512452452438571385c111fafd7a581f227d997183b3c0ed0aaa6e94", "price_changes": [{"asset_id": "70641103843303633433849051708048017041225992079285926883062800006960120844878", "price": "0.69", "size": "0", "side": "BUY", "hash": "e9751e2f1bc42d03e87fce08f9965fa47bb4f59a", "best_bid": "0.75", "best_ask": "0.8"}, {"asset_id": "32365631237478011719581335465835096900088880772439977051943287219696169513404", "price": "0.31", "size": "0", "side": "SELL", "hash": "f4c652704f27933e0aedef24760d7c39e1e9ebf2", "best_bid": "0.2", "best_ask": "0.25"}], "timestamp": "1769384019643", "event_type": "price_change"}}
{"_local_timestamp": "2026-01-25T23:33:39.808360+00:00", "data": {"market": "0xbbf9e226512452452438571385c111fafd7a581f227d997183b3c0ed0aaa6e94", "price_changes": [{"asset_id": "70641103843303633433849051708048017041225992079285926883062800006960120844878", "price": "0.69", "size": "26", "side": "BUY", "hash": "3c24a6730e4d9f7f9c8ba53e72f26082254ad56d", "best_bid": "0.75", "best_ask": "0.8"}, {"asset_id": "32365631237478011719581335465835096900088880772439977051943287219696169513404", "price": "0.31", "size": "26", "side": "SELL", "hash": "f9a4833baefcd161c7acb58f016d3b24262f79e9", "best_bid": "0.2", "best_ask": "0.25"}], "timestamp": "1769384019696", "event_type": "price_change"}}
{"_local_timestamp": "2026-01-25T23:33:39.809122+00:00", "data": {"market": "0x7130b2c99bee81af658adafb4a6235f21575f568e3ae2a850af742afa50c2d85", "price_changes": [{"asset_id": "17878506599231681723092997062254912120536148530389060800857875232098186845304", "price": "0.802", "size": "50", "side": "BUY", "hash": "c7a806fd3d8b86bf6ba3fa5881e067b3b0ac218c", "best_bid": "0.886", "best_ask": "0.908"}, {"asset_id": "79480641743596328156888881841837787012633513624072222555595000167813156519758", "price": "0.198", "size": "50", "side": "SELL", "hash": "d0ea682832f18111cc004fb7efbe68fe99bf4ef7", "best_bid": "0.092", "best_ask": "0.114"}], "timestamp": "1769384019712", "event_type": "price_change"}}
{"_local_timestamp": "2026-01-25T23:33:39.851601+00:00", "data": {"market": "0x7d4227c3c4f79de22bbf5b10301d3e99733151de11a2af04ee5d4fe9147fdb94", "price_changes": [{"asset_id": "114175921346199629913576111903487851727201567831569002664280492572302128017807", "price": "0.656", "size": "7", "side": "BUY", "hash": "a735ba84a9f67783aa7ef7753f72aa15f75117c3", "best_bid": "0.681", "best_ask": "0.72"}, {"asset_id": "106160144365361466407303030429537634959446638743399742742547862828370756994868", "price": "0.344", "size": "7", "side": "SELL", "hash": "83fa9be1023416f61322be6c2d0d05a8c07a6ee5", "best_bid": "0.28", "best_ask": "0.319"}], "timestamp": "1769384019781", "event_type": "price_change"}}
{"_local_timestamp": "2026-01-25T23:33:41.235052+00:00", "data": {"market": "0x7130b2c99bee81af658adafb4a6235f21575f568e3ae2a850af742afa50c2d85", "price_changes": [{"asset_id": "79480641743596328156888881841837787012633513624072222555595000167813156519758", "price": "0.114", "size": "166.32", "side": "SELL", "hash": "fe1a3f896927cf28076ff485677b5ed6e89c06d6", "best_bid": "0.092", "best_ask": "0.114"}, {"asset_id": "17878506599231681723092997062254912120536148530389060800857875232098186845304", "price": "0.886", "size": "166.32", "side": "BUY", "hash": "54b189873116601ba6511d9f96b482441af837a5", "best_bid": "0.886", "best_ask": "0.908"}], "timestamp": "1769384021156", "event_type": "price_change"}}
{"_local_timestamp": "2026-01-25T23:33:41.361161+00:00", "data": {"market": "0x5e75c47528185caa0b8140d5199a505b111d535d004f10c14c77099e160f8c43", "price_changes": [{"asset_id": "37216599669721820787426834964764344032227136269811356205946493119045847831924", "price": "0.79", "size": "40", "side": "BUY", "hash": "7098f15d1a363844e91667c8381aa420f4758f7f", "best_bid": "0.88", "best_ask": "0.89"}, {"asset_id": "40497352693029741963885292742967835565636400191703716161158810847504561227789", "price": "0.21", "size": "40", "side": "SELL", "hash": "84bfb80a1028d221759f72e62c2994ba71245c11", "best_bid": "0.11", "best_ask": "0.12"}], "timestamp": "1769384021271", "event_type": "price_change"}}
{"_local_timestamp": "2026-01-25T23:33:41.371580+00:00", "data": {"market": "0x7d4227c3c4f79de22bbf5b10301d3e99733151de11a2af04ee5d4fe9147fdb94", "price_changes": [{"asset_id": "114175921346199629913576111903487851727201567831569002664280492572302128017807", "price": "0.656", "size": "0", "side": "BUY", "hash": "8b8508c5a1d1584a50305d95ebeb7bb3618def12", "best_bid": "0.681", "best_ask": "0.72"}, {"asset_id": "106160144365361466407303030429537634959446638743399742742547862828370756994868", "price": "0.344", "size": "0", "side": "SELL", "hash": "8a334cfcb4dc147597c177da041ca8346bb99a12", "best_bid": "0.28", "best_ask": "0.319"}], "timestamp": "1769384021277", "event_type": "price_change"}}
{"_local_timestamp": "2026-01-25T23:33:41.372824+00:00", "data": {"market": "0x7130b2c99bee81af658adafb4a6235f21575f568e3ae2a850af742afa50c2d85", "price_changes": [{"asset_id": "17878506599231681723092997062254912120536148530389060800857875232098186845304", "price": "0.802", "size": "0", "side": "BUY", "hash": "7825680c9ef2f6c37fa2b358c5087dae15f0cd23", "best_bid": "0.886", "best_ask": "0.908"}, {"asset_id": "79480641743596328156888881841837787012633513624072222555595000167813156519758", "price": "0.198", "size": "0", "side": "SELL", "hash": "3a61804e8bdc6d28ce0d3507c3f0c8a669db790c", "best_bid": "0.092", "best_ask": "0.114"}], "timestamp": "1769384021279", "event_type": "price_change"}}
{"_local_timestamp": "2026-01-25T23:33:41.374624+00:00", "data": {"market": "0xbbf9e226512452452438571385c111fafd7a581f227d997183b3c0ed0aaa6e94", "price_changes": [{"asset_id": "70641103843303633433849051708048017041225992079285926883062800006960120844878", "price": "0.69", "size": "0", "side": "BUY", "hash": "bc68b31f858b110e224765e53d1b11cf921975bf", "best_bid": "0.75", "best_ask": "0.8"}, {"asset_id": "32365631237478011719581335465835096900088880772439977051943287219696169513404", "price": "0.31", "size": "0", "side": "SELL", "hash": "cb44fe3563804eeefb182991f14883c25c469b8d", "best_bid": "0.2", "best_ask": "0.25"}], "timestamp": "1769384021281", "event_type": "price_change"}}
{"_local_timestamp": "2026-01-25T23:33:41.386554+00:00", "data": {"market": "0xa19142e40da92f4110d29f63475ed9689f1471f8963c87e3220a989cdb356d45", "price_changes": [{"asset_id": "81750849409365469972793631297951692550835139647103107287253620651299358774290", "price": "0.78", "size": "340.15", "side": "BUY", "hash": "ed5ea785b9393adc38e1c20485d558eee3c033ae", "best_bid": "0.899", "best_ask": "0.904"}, {"asset_id": "49980127219724914096527114792845752329307347014547067418981570311158802130688", "price": "0.22", "size": "340.15", "side": "SELL", "hash": "78f87d5886fdc56f981d37b9ac3413c65b5a3d79", "best_bid": "0.096", "best_ask": "0.101"}], "timestamp": "1769384021311", "event_type": "price_change"}}
{"_local_timestamp": "2026-01-25T23:33:41.389233+00:00", "data": {"market": "0x5e75c47528185caa0b8140d5199a505b111d535d004f10c14c77099e160f8c43", "price_changes": [{"asset_id": "37216599669721820787426834964764344032227136269811356205946493119045847831924", "price": "0.8", "size": "50", "side": "BUY", "hash": "e60eff8e51ca94c9d44506e4975fb0bffcfe1c30", "best_bid": "0.88", "best_ask": "0.89"}, {"asset_id": "40497352693029741963885292742967835565636400191703716161158810847504561227789", "price": "0.2", "size": "50", "side": "SELL", "hash": "764e9b6d8f0461301897b451b934b8891b515831", "best_bid": "0.11", "best_ask": "0.12"}], "timestamp": "1769384021313", "event_type": "price_change"}}
{"_local_timestamp": "2026-01-25T23:33:41.390602+00:00", "data": {"market": "0x7d4227c3c4f79de22bbf5b10301d3e99733151de11a2af04ee5d4fe9147fdb94", "price_changes": [{"asset_id": "114175921346199629913576111903487851727201567831569002664280492572302128017807", "price": "0.629", "size": "0", "side": "BUY", "hash": "a07cb7786108632a811f88709e3c00fd8de6423e", "best_bid": "0.681", "best_ask": "0.72"}, {"asset_id": "106160144365361466407303030429537634959446638743399742742547862828370756994868", "price": "0.371", "size": "0", "side": "SELL", "hash": "9529580317b10e5cbe32029cb412304bcad989bb", "best_bid": "0.28", "best_ask": "0.319"}], "timestamp": "1769384021317", "event_type": "price_change"}}
{"_local_timestamp": "2026-01-25T23:33:41.406033+00:00", "data": {"market": "0xa19142e40da92f4110d29f63475ed9689f1471f8963c87e3220a989cdb356d45", "price_changes": [{"asset_id": "81750849409365469972793631297951692550835139647103107287253620651299358774290", "price": "0.781", "size": "20", "side": "BUY", "hash": "57e5a7c3600aee2a3c1d5a46327b74eb197a5e50", "best_bid": "0.899", "best_ask": "0.904"}, {"asset_id": "49980127219724914096527114792845752329307347014547067418981570311158802130688", "price": "0.219", "size": "20", "side": "SELL", "hash": "80b2759ffad86ed9a1342347d269a4cd341dcdd7", "best_bid": "0.096", "best_ask": "0.101"}], "timestamp": "1769384021338", "event_type": "price_change"}}
{"_local_timestamp": "2026-01-25T23:33:41.463639+00:00", "data": {"market": "0x7d4227c3c4f79de22bbf5b10301d3e99733151de11a2af04ee5d4fe9147fdb94", "price_changes": [{"asset_id": "114175921346199629913576111903487851727201567831569002664280492572302128017807", "price": "0.656", "size": "7", "side": "BUY", "hash": "80227fa948cee8c1bff595cb2a1cc5d6f17594d9", "best_bid": "0.681", "best_ask": "0.72"}, {"asset_id": "106160144365361466407303030429537634959446638743399742742547862828370756994868", "price": "0.344", "size": "7", "side": "SELL", "hash": "9f7501e4b09e85b0ef009b04780217312c8fc360", "best_bid": "0.28", "best_ask": "0.319"}], "timestamp": "1769384021385", "event_type": "price_change"}}
{"_local_timestamp": "2026-01-25T23:33:41.497908+00:00", "data": {"market": "0x7d4227c3c4f79de22bbf5b10301d3e99733151de11a2af04ee5d4fe9147fdb94", "price_changes": [{"asset_id": "114175921346199629913576111903487851727201567831569002664280492572302128017807", "price": "0.629", "size": "7", "side": "BUY", "hash": "d671b539fd752215dcd25439cd34fa09ffffdf8a", "best_bid": "0.681", "best_ask": "0.72"}, {"asset_id": "106160144365361466407303030429537634959446638743399742742547862828370756994868", "price": "0.371", "size": "7", "side": "SELL", "hash": "d138c376771cf8aae8cf395684ecc94776ccfabd", "best_bid": "0.28", "best_ask": "0.319"}], "timestamp": "1769384021422", "event_type": "price_change"}}
{"_local_timestamp": "2026-01-25T23:33:41.821442+00:00", "data": {"market": "0x7130b2c99bee81af658adafb4a6235f21575f568e3ae2a850af742afa50c2d85", "price_changes": [{"asset_id": "17878506599231681723092997062254912120536148530389060800857875232098186845304", "price": "0.813", "size": "50", "side": "BUY", "hash": "80aa599c73a9533c28872b117aed51d55167e55a", "best_bid": "0.886", "best_ask": "0.908"}, {"asset_id": "79480641743596328156888881841837787012633513624072222555595000167813156519758", "price": "0.187", "size": "50", "side": "SELL", "hash": "5924295eb1a1853eae7ff1ad88ce21db9f055ef7", "best_bid": "0.092", "best_ask": "0.114"}], "timestamp": "1769384021749", "event_type": "price_change"}}
{"_local_timestamp": "2026-01-25T23:33:41.842216+00:00", "data": {"market": "0x5b87791e06388b1a91fd402c29e483842da0f9fec156bb3cefe9d58275a0373b", "price_changes": [{"asset_id": "90132986654259086678529082268082617450254793801662820786849470352289449813683", "price": "0.031", "size": "134", "side": "BUY", "hash": "726b67d19189dab786177132beae4e380f0b4575", "best_bid": "0.034", "best_ask": "0.04"}, {"asset_id": "88022913747451311038559242580697856881859219751804674115271835179181575694176", "price": "0.969", "size": "134", "side": "SELL", "hash": "9d912fae889b061350384b7c20d2705bae706f5b", "best_bid": "0.96", "best_ask": "0.966"}], "timestamp": "1769384021762", "event_type": "price_change"}}
{"_local_timestamp": "2026-01-25T23:33:41.940521+00:00", "data": {"market": "0x7130b2c99bee81af658adafb4a6235f21575f568e3ae2a850af742afa50c2d85", "price_changes": [{"asset_id": "17878506599231681723092997062254912120536148530389060800857875232098186845304", "price": "0.813", "size": "75", "side": "BUY", "hash": "e8681d68d9753453b05831a377796d6d2abcc454", "best_bid": "0.886", "best_ask": "0.908"}, {"asset_id": "79480641743596328156888881841837787012633513624072222555595000167813156519758", "price": "0.187", "size": "75", "side": "SELL", "hash": "d2f9f05b402bd53af786d64bb7edf52c4733a79c", "best_bid": "0.092", "best_ask": "0.114"}], "timestamp": "1769384021865", "event_type": "price_change"}}
{"_local_timestamp": "2026-01-25T23:33:41.944625+00:00", "data": {"market": "0x7130b2c99bee81af658adafb4a6235f21575f568e3ae2a850af742afa50c2d85", "price_changes": [{"asset_id": "17878506599231681723092997062254912120536148530389060800857875232098186845304", "price": "0.813", "size": "100", "side": "BUY", "hash": "c015fab154cf25d56fe93467747c657dbe488775", "best_bid": "0.886", "best_ask": "0.908"}, {"asset_id": "79480641743596328156888881841837787012633513624072222555595000167813156519758", "price": "0.187", "size": "100", "side": "SELL", "hash": "1321133dae089cbcd970bcc8fc35141c62f0fd75", "best_bid": "0.092", "best_ask": "0.114"}], "timestamp": "1769384021866", "event_type": "price_change"}}
{"_local_timestamp": "2026-01-25T23:33:42.033782+00:00", "data": {"market": "0x7130b2c99bee81af658adafb4a6235f21575f568e3ae2a850af742afa50c2d85", "price_changes": [{"asset_id": "17878506599231681723092997062254912120536148530389060800857875232098186845304", "price": "0.813", "size": "125", "side": "BUY", "hash": "4424cf82bccad3524c1d933c7c67e24d8f212e26", "best_bid": "0.886", "best_ask": "0.908"}, {"asset_id": "79480641743596328156888881841837787012633513624072222555595000167813156519758", "price": "0.187", "size": "125", "side": "SELL", "hash": "ef5ccc73ffae8f17341f73924fa9d1b95bc503ac", "best_bid": "0.092", "best_ask": "0.114"}], "timestamp": "1769384021903", "event_type": "price_change"}}
{"_local_timestamp": "2026-01-25T23:33:42.056414+00:00", "data": {"market": "0x5e75c47528185caa0b8140d5199a505b111d535d004f10c14c77099e160f8c43", "price_changes": [{"asset_id": "37216599669721820787426834964764344032227136269811356205946493119045847831924", "price": "0.8", "size": "0", "side": "BUY", "hash": "a15de139acbf2e1b364b88515724cf3cd6b1c9ee", "best_bid": "0.88", "best_ask": "0.89"}, {"asset_id": "40497352693029741963885292742967835565636400191703716161158810847504561227789", "price": "0.2", "size": "0", "side": "SELL", "hash": "143c873ed250851dd2a7e4108b55743c5f4b3ddf", "best_bid": "0.11", "best_ask": "0.12"}], "timestamp": "1769384021976", "event_type": "price_change"}}
{"_local_timestamp": "2026-01-25T23:33:42.061660+00:00", "data": {"market": "0x7d4227c3c4f79de22bbf5b10301d3e99733151de11a2af04ee5d4fe9147fdb94", "price_changes": [{"asset_id": "114175921346199629913576111903487851727201567831569002664280492572302128017807", "price": "0.656", "size": "0", "side": "BUY", "hash": "f11c3c38fdfb1bd88bc2143a935e66bc4c34d919", "best_bid": "0.681", "best_ask": "0.72"}, {"asset_id": "106160144365361466407303030429537634959446638743399742742547862828370756994868", "price": "0.344", "size": "0", "side": "SELL", "hash": "b3345be3af2b809b4b7676d644a22d3f4980de36", "best_bid": "0.28", "best_ask": "0.319"}], "timestamp": "1769384021983", "event_type": "price_change"}}
{"_local_timestamp": "2026-01-25T23:33:42.089310+00:00", "data": {"market": "0x7d4227c3c4f79de22bbf5b10301d3e99733151de11a2af04ee5d4fe9147fdb94", "price_changes": [{"asset_id": "114175921346199629913576111903487851727201567831569002664280492572302128017807", "price": "0.629", "size": "0", "side": "BUY", "hash": "098cb63a28616f599df5512d68f51dc1eee10597", "best_bid": "0.681", "best_ask": "0.72"}, {"asset_id": "106160144365361466407303030429537634959446638743399742742547862828370756994868", "price": "0.371", "size": "0", "side": "SELL", "hash": "8abf723abc59f65889d38f823920993d6b83fc03", "best_bid": "0.28", "best_ask": "0.319"}], "timestamp": "1769384022006", "event_type": "price_change"}}
{"_local_timestamp": "2026-01-25T23:33:42.089968+00:00", "data": {"market": "0x7130b2c99bee81af658adafb4a6235f21575f568e3ae2a850af742afa50c2d85", "price_changes": [{"asset_id": "17878506599231681723092997062254912120536148530389060800857875232098186845304", "price": "0.813", "size": "100", "side": "BUY", "hash": "f4bcf23946d3c0554b6ada025e6e83cf229172ca", "best_bid": "0.886", "best_ask": "0.908"}, {"asset_id": "79480641743596328156888881841837787012633513624072222555595000167813156519758", "price": "0.187", "size": "100", "side": "SELL", "hash": "408f9a532dce46c0a0ae558211143211800c4a85", "best_bid": "0.092", "best_ask": "0.114"}], "timestamp": "1769384022013", "event_type": "price_change"}}
{"_local_timestamp": "2026-01-25T23:33:42.094707+00:00", "data": {"market": "0x7130b2c99bee81af658adafb4a6235f21575f568e3ae2a850af742afa50c2d85", "price_changes": [{"asset_id": "17878506599231681723092997062254912120536148530389060800857875232098186845304", "price": "0.813", "size": "75", "side": "BUY", "hash": "111236577488c9c822d52a4436c2cff2f3f5038a", "best_bid": "0.886", "best_ask": "0.908"}, {"asset_id": "79480641743596328156888881841837787012633513624072222555595000167813156519758", "price": "0.187", "size": "75", "side": "SELL", "hash": "53e12296922ad7a6f4df93947f04c3ebcd13a4aa", "best_bid": "0.092", "best_ask": "0.114"}], "timestamp": "1769384022014", "event_type": "price_change"}}
{"_local_timestamp": "2026-01-25T23:33:42.208998+00:00", "data": {"market": "0x7130b2c99bee81af658adafb4a6235f21575f568e3ae2a850af742afa50c2d85", "price_changes": [{"asset_id": "17878506599231681723092997062254912120536148530389060800857875232098186845304", "price": "0.761", "size": "0", "side": "BUY", "hash": "47ce4203245db6c007afb8d24aaedae7c0643c4a", "best_bid": "0.886", "best_ask": "0.908"}, {"asset_id": "79480641743596328156888881841837787012633513624072222555595000167813156519758", "price": "0.239", "size": "0", "side": "SELL", "hash": "ff4a26c0d84502de3a36b1084599c3d0ed30f645", "best_bid": "0.092", "best_ask": "0.114"}], "timestamp": "1769384022141", "event_type": "price_change"}}
{"_local_timestamp": "2026-01-25T23:33:44.588972+00:00", "data": {"market": "0x7d4227c3c4f79de22bbf5b10301d3e99733151de11a2af04ee5d4fe9147fdb94", "price_changes": [{"asset_id": "114175921346199629913576111903487851727201567831569002664280492572302128017807", "price": "0.76", "size": "5", "side": "SELL", "hash": "e10b0f3c2bce88d8dbd44c6f181cc47252c671a0", "best_bid": "0.681", "best_ask": "0.72"}, {"asset_id": "106160144365361466407303030429537634959446638743399742742547862828370756994868", "price": "0.24", "size": "5", "side": "BUY", "hash": "9b214a856d7faacef4fba397f04288c90839715c", "best_bid": "0.28", "best_ask": "0.319"}], "timestamp": "1769384024522", "event_type": "price_change"}}
{"_local_timestamp": "2026-01-25T23:33:44.711655+00:00", "data": {"market": "0x7130b2c99bee81af658adafb4a6235f21575f568e3ae2a850af742afa50c2d85", "price_changes": [{"asset_id": "17878506599231681723092997062254912120536148530389060800857875232098186845304", "price": "0.813", "size": "100", "side": "BUY", "hash": "e8f7106837f95c0869a4f2dbc3cc711e76a1ef50", "best_bid": "0.886", "best_ask": "0.908"}, {"asset_id": "79480641743596328156888881841837787012633513624072222555595000167813156519758", "price": "0.187", "size": "100", "side": "SELL", "hash": "83fa2a651364b28ee21b0ad52571d868b4cb5aa7", "best_bid": "0.092", "best_ask": "0.114"}], "timestamp": "1769384024641", "event_type": "price_change"}}
{"_local_timestamp": "2026-01-25T23:33:44.717999+00:00", "data": {"market": "0x7d4227c3c4f79de22bbf5b10301d3e99733151de11a2af04ee5d4fe9147fdb94", "price_changes": [{"asset_id": "114175921346199629913576111903487851727201567831569002664280492572302128017807", "price": "0.656", "size": "7", "side": "BUY", "hash": "f48c72050382875bcd841e93081c2c9582ebd41c", "best_bid": "0.681", "best_ask": "0.72"}, {"asset_id": "106160144365361466407303030429537634959446638743399742742547862828370756994868", "price": "0.344", "size": "7", "side": "SELL", "hash": "4ae0db17f7ca16db994e49dd16ca6b87fd1fc6fa", "best_bid": "0.28", "best_ask": "0.319"}], "timestamp": "1769384024650", "event_type": "price_change"}}
{"_local_timestamp": "2026-01-25T23:33:44.725269+00:00", "data": {"market": "0x3f973c672acd8233f5b953a9eaece0c41d82b932354f14cca316c8c8adbc5430", "price_changes": [{"asset_id": "98245576915057665054883165975987196038445195653094902203445898901996168030329", "price": "0.021", "size": "157.08", "side": "BUY", "hash": "0a9baba1b2a9834f0683381f040f00d212cc924f", "best_bid": "0.021", "best_ask": "0.025"}, {"asset_id": "93900842269737238576470860642705247823244098999914913757632782327103374288912", "price": "0.979", "size": "157.08", "side": "SELL", "hash": "09d8d853fadd321a97939b51ab4ca4c1a73aca21", "best_bid": "0.975", "best_ask": "0.979"}], "timestamp": "1769384024658", "event_type": "price_change"}}
{"_local_timestamp": "2026-01-25T23:33:44.809304+00:00", "data": {"market": "0x7d4227c3c4f79de22bbf5b10301d3e99733151de11a2af04ee5d4fe9147fdb94", "price_changes": [{"asset_id": "114175921346199629913576111903487851727201567831569002664280492572302128017807", "price": "0.629", "size": "7", "side": "BUY", "hash": "e7e7fb2ebf11fb9e9f137284d7abcec8150c3c81", "best_bid": "0.681", "best_ask": "0.72"}, {"asset_id": "106160144365361466407303030429537634959446638743399742742547862828370756994868", "price": "0.371", "size": "7", "side": "SELL", "hash": "79cc7cae1faa312a1e8441da4e1f383360a142e4", "best_bid": "0.28", "best_ask": "0.319"}], "timestamp": "1769384024744", "event_type": "price_change"}}
{"_local_timestamp": "2026-01-25T23:33:44.846581+00:00", "data": {"market": "0x7130b2c99bee81af658adafb4a6235f21575f568e3ae2a850af742afa50c2d85", "price_changes": [{"asset_id": "17878506599231681723092997062254912120536148530389060800857875232098186845304", "price": "0.812", "size": "63.54", "side": "BUY", "hash": "973f1d8f8aa189a09044a5a0ef76213ead59c558", "best_bid": "0.886", "best_ask": "0.908"}, {"asset_id": "79480641743596328156888881841837787012633513624072222555595000167813156519758", "price": "0.188", "size": "63.54", "side": "SELL", "hash": "a807463a2778cf7cde3d4bceb3710c5c18fff693", "best_bid": "0.092", "best_ask": "0.114"}], "timestamp": "1769384024778", "event_type": "price_change"}}
{"_local_timestamp": "2026-01-25T23:33:44.890988+00:00", "data": {"market": "0x7130b2c99bee81af658adafb4a6235f21575f568e3ae2a850af742afa50c2d85", "price_changes": [{"asset_id": "17878506599231681723092997062254912120536148530389060800857875232098186845304", "price": "0.812", "size": "13.54", "side": "BUY", "hash": "8ecca009c8b2784024a3783fdbf36daee3178616", "best_bid": "0.886", "best_ask": "0.908"}, {"asset_id": "79480641743596328156888881841837787012633513624072222555595000167813156519758", "price": "0.188", "size": "13.54", "side": "SELL", "hash": "98c8ed0615be969671af7d9d8b2d4cb2fb14bf50", "best_bid": "0.092", "best_ask": "0.114"}], "timestamp": "1769384024825", "event_type": "price_change"}}
{"_local_timestamp": "2026-01-25T23:33:45.136551+00:00", "data": {"market": "0x7130b2c99bee81af658adafb4a6235f21575f568e3ae2a850af742afa50c2d85", "price_changes": [{"asset_id": "17878506599231681723092997062254912120536148530389060800857875232098186845304", "price": "0.762", "size": "0", "side": "BUY", "hash": "371eb5b580ca8d06c0c864fd5f9af47f69a175b7", "best_bid": "0.886", "best_ask": "0.908"}, {"asset_id": "79480641743596328156888881841837787012633513624072222555595000167813156519758", "price": "0.238", "size": "0", "side": "SELL", "hash": "f8d679d993d047bf6e8aa48cc19dd348f004f495", "best_bid": "0.092", "best_ask": "0.114"}], "timestamp": "1769384025064", "event_type": "price_change"}}
{"_local_timestamp": "2026-01-25T23:33:45.162664+00:00", "data": {"market": "0x7130b2c99bee81af658adafb4a6235f21575f568e3ae2a850af742afa50c2d85", "price_changes": [{"asset_id": "17878506599231681723092997062254912120536148530389060800857875232098186845304", "price": "0.761", "size": "20", "side": "BUY", "hash": "3c0b0686e9f90fda3547d839c0dab73b6137ed40", "best_bid": "0.886", "best_ask": "0.908"}, {"asset_id": "79480641743596328156888881841837787012633513624072222555595000167813156519758", "price": "0.239", "size": "20", "side": "SELL", "hash": "981c6e0ea9d4eeeca7be9eef9ffd1720a8d0e964", "best_bid": "0.092", "best_ask": "0.114"}], "timestamp": "1769384025094", "event_type": "price_change"}}
{"_local_timestamp": "2026-01-25T23:33:45.256943+00:00", "data": {"market": "0x7d4227c3c4f79de22bbf5b10301d3e99733151de11a2af04ee5d4fe9147fdb94", "price_changes": [{"asset_id": "114175921346199629913576111903487851727201567831569002664280492572302128017807", "price": "0.656", "size": "0", "side": "BUY", "hash": "69fac6b0a2fae4af16a5627bbd29dc21c827fb2a", "best_bid": "0.681", "best_ask": "0.72"}, {"asset_id": "106160144365361466407303030429537634959446638743399742742547862828370756994868", "price": "0.344", "size": "0", "side": "SELL", "hash": "42c28cdab75efa2a6813b3adbdc1fffb542213e4", "best_bid": "0.28", "best_ask": "0.319"}], "timestamp": "1769384025180", "event_type": "price_change"}}
{"_local_timestamp": "2026-01-25T23:33:45.257935+00:00", "data": {"market": "0x7130b2c99bee81af658adafb4a6235f21575f568e3ae2a850af742afa50c2d85", "price_changes": [{"asset_id": "17878506599231681723092997062254912120536148530389060800857875232098186845304", "price": "0.813", "size": "75", "side": "BUY", "hash": "08cd4d0f82acaaeff6a93f8551cc4492fdec7517", "best_bid": "0.886", "best_ask": "0.908"}, {"asset_id": "79480641743596328156888881841837787012633513624072222555595000167813156519758", "price": "0.187", "size": "75", "side": "SELL", "hash": "4a88bd035b89b8f233a45436300d134b8f6aacd2", "best_bid": "0.092", "best_ask": "0.114"}], "timestamp": "1769384025183", "event_type": "price_change"}}
{"_local_timestamp": "2026-01-25T23:33:45.258428+00:00", "data": {"market": "0x7d4227c3c4f79de22bbf5b10301d3e99733151de11a2af04ee5d4fe9147fdb94", "price_changes": [{"asset_id": "114175921346199629913576111903487851727201567831569002664280492572302128017807", "price": "0.629", "size": "0", "side": "BUY", "hash": "f58ee8252df77a9156099c941f62a97d049655e5", "best_bid": "0.681", "best_ask": "0.72"}, {"asset_id": "106160144365361466407303030429537634959446638743399742742547862828370756994868", "price": "0.371", "size": "0", "side": "SELL", "hash": "56b88323dd0a308752961cca861695832191d6b9", "best_bid": "0.28", "best_ask": "0.319"}], "timestamp": "1769384025184", "event_type": "price_change"}}
{"_local_timestamp": "2026-01-25T23:33:45.293413+00:00", "data": {"market": "0x5e75c47528185caa0b8140d5199a505b111d535d004f10c14c77099e160f8c43", "price_changes": [{"asset_id": "40497352693029741963885292742967835565636400191703716161158810847504561227789", "price": "0.11", "size": "126.2", "side": "BUY", "hash": "d84278c856dd15a3b9c3bf316d70d1a235296beb", "best_bid": "0.11", "best_ask": "0.12"}, {"asset_id": "37216599669721820787426834964764344032227136269811356205946493119045847831924", "price": "0.89", "size": "126.2", "side": "SELL", "hash": "97b8678e219ee9a6770103113d01b9e69d340e69", "best_bid": "0.88", "best_ask": "0.89"}], "timestamp": "1769384025224", "event_type": "price_change"}}
{"_local_timestamp": "2026-01-25T23:33:45.317335+00:00", "data": {"market": "0xa19142e40da92f4110d29f63475ed9689f1471f8963c87e3220a989cdb356d45", "price_changes": [{"asset_id": "81750849409365469972793631297951692550835139647103107287253620651299358774290", "price": "0.835", "size": "20", "side": "BUY", "hash": "b007e94f1803b7d000e131b48ba74fd20105bb91", "best_bid": "0.899", "best_ask": "0.904"}, {"asset_id": "49980127219724914096527114792845752329307347014547067418981570311158802130688", "price": "0.165", "size": "20", "side": "SELL", "hash": "4795ed76d11ad8b7993b8abdff64d7c33194f4af", "best_bid": "0.096", "best_ask": "0.101"}], "timestamp": "1769384025248", "event_type": "price_change"}}
{"_local_timestamp": "2026-01-25T23:33:45.378358+00:00", "data": {"market": "0x7130b2c99bee81af658adafb4a6235f21575f568e3ae2a850af742afa50c2d85", "price_changes": [{"asset_id": "17878506599231681723092997062254912120536148530389060800857875232098186845304", "price": "0.813", "size": "125", "side": "BUY", "hash": "06b8d36641b00227c62b205f553f3f24e25ef14f", "best_bid": "0.886", "best_ask": "0.908"}, {"asset_id": "79480641743596328156888881841837787012633513624072222555595000167813156519758", "price": "0.187", "size": "125", "side": "SELL", "hash": "0e320ba2599a39ba50d5dc74c43e48f826889699", "best_bid": "0.092", "best_ask": "0.114"}], "timestamp": "1769384025293", "event_type": "price_change"}}
{"_local_timestamp": "2026-01-25T23:33:45.402951+00:00", "data": {"market": "0xbbf9e226512452452438571385c111fafd7a581f227d997183b3c0ed0aaa6e94", "price_changes": [{"asset_id": "70641103843303633433849051708048017041225992079285926883062800006960120844878", "price": "0.71", "size": "50", "side": "BUY", "hash": "b3278367fd1aa8b1e75f4007ba8d104dc726a710", "best_bid": "0.75", "best_ask": "0.8"}, {"asset_id": "32365631237478011719581335465835096900088880772439977051943287219696169513404", "price": "0.29", "size": "50", "side": "SELL", "hash": "99f9a94b677a642e89ddb45ad245e3209b7da9bc", "best_bid": "0.2", "best_ask": "0.25"}], "timestamp": "1769384025331", "event_type": "price_change"}}
{"_local_timestamp": "2026-01-25T23:33:45.409376+00:00", "data": {"market": "0xbbf9e226512452452438571385c111fafd7a581f227d997183b3c0ed0aaa6e94", "price_changes": [{"asset_id": "70641103843303633433849051708048017041225992079285926883062800006960120844878", "price": "0.7", "size": "50", "side": "BUY", "hash": "979e7e83ca5df0b5f3a18a65dbaba41f219ffa63", "best_bid": "0.75", "best_ask": "0.8"}, {"asset_id": "32365631237478011719581335465835096900088880772439977051943287219696169513404", "price": "0.3", "size": "50", "side": "SELL", "hash": "3adf892625c9dc96a74843a1e989f38c3bdb9376", "best_bid": "0.2", "best_ask": "0.25"}], "timestamp": "1769384025334", "event_type": "price_change"}}
{"_local_timestamp": "2026-01-25T23:33:45.417674+00:00", "data": {"market": "0x7130b2c99bee81af658adafb4a6235f21575f568e3ae2a850af742afa50c2d85", "price_changes": [{"asset_id": "17878506599231681723092997062254912120536148530389060800857875232098186845304", "price": "0.823", "size": "50", "side": "BUY", "hash": "04c723a382e1fcec772a42bd224254f2c3c9e64c", "best_bid": "0.886", "best_ask": "0.908"}, {"asset_id": "79480641743596328156888881841837787012633513624072222555595000167813156519758", "price": "0.177", "size": "50", "side": "SELL", "hash": "deb4b81ccf2b0d49c10a2205d47c0429f84eb895", "best_bid": "0.092", "best_ask": "0.114"}], "timestamp": "1769384025336", "event_type": "price_change"}}
{"_local_timestamp": "2026-01-25T23:33:45.418446+00:00", "data": {"market": "0x74cda80b2734086fa7e6bfce27d6321bb617d28dde6b486e7d3567c6afa5f46f", "price_changes": [{"asset_id": "54097693815260016929707363796097268965809730515171531228590357799043969397342", "price": "0.8", "size": "85", "side": "BUY", "hash": "3ab810db1d66906dd21b11a24362391271dde4a9", "best_bid": "0.87", "best_ask": "0.9"}, {"asset_id": "108808298639528397169807740481685882973822875737039638334154867204245949286757", "price": "0.2", "size": "85", "side": "SELL", "hash": "6acf5f5e3d2e75775e56067518ce667c34a2ea95", "best_bid": "0.1", "best_ask": "0.13"}], "timestamp": "1769384025338", "event_type": "price_change"}}
{"_local_timestamp": "2026-01-25T23:33:45.421471+00:00", "data": {"market": "0x7130b2c99bee81af658adafb4a6235f21575f568e3ae2a850af742afa50c2d85", "price_changes": [{"asset_id": "17878506599231681723092997062254912120536148530389060800857875232098186845304", "price": "0.813", "size": "100", "side": "BUY", "hash": "347d5746ecdda1ff8050bf0d888e87e1a78f2ddc", "best_bid": "0.886", "best_ask": "0.908"}, {"asset_id": "79480641743596328156888881841837787012633513624072222555595000167813156519758", "price": "0.187", "size": "100", "side": "SELL", "hash": "5a71ee18005be72181f2f307997a73b2f82f8aea", "best_bid": "0.092", "best_ask": "0.114"}], "timestamp": "1769384025344", "event_type": "price_change"}}
{"_local_timestamp": "2026-01-25T23:33:45.423698+00:00", "data": {"market": "0x5e75c47528185caa0b8140d5199a505b111d535d004f10c14c77099e160f8c43", "price_changes": [{"asset_id": "37216599669721820787426834964764344032227136269811356205946493119045847831924", "price": "0.85", "size": "954", "side": "BUY", "hash": "ba09a4a169d780bc46a95c47587531c42d838f78", "best_bid": "0.88", "best_ask": "0.89"}, {"asset_id": "40497352693029741963885292742967835565636400191703716161158810847504561227789", "price": "0.15", "size": "954", "side": "SELL", "hash": "2a3050896db73133d637412f1ceb4c6d37d4fd9c", "best_bid": "0.11", "best_ask": "0.12"}], "timestamp": "1769384025344", "event_type": "price_change"}}
{"_local_timestamp": "2026-01-25T23:33:45.424673+00:00", "data": {"market": "0x5e75c47528185caa0b8140d5199a505b111d535d004f10c14c77099e160f8c43", "price_changes": [{"asset_id": "40497352693029741963885292742967835565636400191703716161158810847504561227789", "price": "0.09", "size": "80", "side": "BUY", "hash": "dcfec5c21249c802092f42db562377fcf3780dcf", "best_bid": "0.11", "best_ask": "0.12"}, {"asset_id": "37216599669721820787426834964764344032227136269811356205946493119045847831924", "price": "0.91", "size": "80", "side": "SELL", "hash": "2d7aca89733ae02069ac09abaa7ce1f248b41dd3", "best_bid": "0.88", "best_ask": "0.89"}], "timestamp": "1769384025345", "event_type": "price_change"}}
{"_local_timestamp": "2026-01-25T23:33:45.442551+00:00", "data": {"market": "0xbbf9e226512452452438571385c111fafd7a581f227d997183b3c0ed0aaa6e94", "price_changes": [{"asset_id": "70641103843303633433849051708048017041225992079285926883062800006960120844878", "price": "0.71", "size": "100", "side": "BUY", "hash": "bc45d49d0f0a8451e1b7f6cf03dfa04bfbdd97b3", "best_bid": "0.75", "best_ask": "0.8"}, {"asset_id": "32365631237478011719581335465835096900088880772439977051943287219696169513404", "price": "0.29", "size": "100", "side": "SELL", "hash": "c6ef9f268ad61ca5005b54cc9604c9e0f46fa1f1", "best_bid": "0.2", "best_ask": "0.25"}], "timestamp": "1769384025363", "event_type": "price_change"}}
{"_local_timestamp": "2026-01-25T23:33:45.444882+00:00", "data": {"market": "0xbbf9e226512452452438571385c111fafd7a581f227d997183b3c0ed0aaa6e94", "price_changes": [{"asset_id": "70641103843303633433849051708048017041225992079285926883062800006960120844878", "price": "0.7", "size": "0", "side": "BUY", "hash": "be31b0a8b683d03fd70831f071ff76951bd1539c", "best_bid": "0.75", "best_ask": "0.8"}, {"asset_id": "32365631237478011719581335465835096900088880772439977051943287219696169513404", "price": "0.3", "size": "0", "side": "SELL", "hash": "64991bc9af499f116e23f4a21b36255221916717", "best_bid": "0.2", "best_ask": "0.25"}], "timestamp": "1769384025365", "event_type": "price_change"}}
{"_local_timestamp": "2026-01-25T23:33:45.449929+00:00", "data": {"market": "0x74cda80b2734086fa7e6bfce27d6321bb617d28dde6b486e7d3567c6afa5f46f", "price_changes": [{"asset_id": "54097693815260016929707363796097268965809730515171531228590357799043969397342", "price": "0.81", "size": "50", "side": "BUY", "hash": "330fe68179868a5730d5bb37bba7e5a4b1075899", "best_bid": "0.87", "best_ask": "0.9"}, {"asset_id": "108808298639528397169807740481685882973822875737039638334154867204245949286757", "price": "0.19", "size": "50", "side": "SELL", "hash": "efd79c735c6f35578b7a2b825188722f3b654311", "best_bid": "0.1", "best_ask": "0.13"}], "timestamp": "1769384025365", "event_type": "price_change"}}
{"_local_timestamp": "2026-01-25T23:33:45.452093+00:00", "data": {"market": "0x74cda80b2734086fa7e6bfce27d6321bb617d28dde6b486e7d3567c6afa5f46f", "price_changes": [{"asset_id": "54097693815260016929707363796097268965809730515171531228590357799043969397342", "price": "0.8", "size": "35", "side": "BUY", "hash": "d893d8d43eb69858e2691fc25567a3a88810e04c", "best_bid": "0.87", "best_ask": "0.9"}, {"asset_id": "108808298639528397169807740481685882973822875737039638334154867204245949286757", "price": "0.2", "size": "35", "side": "SELL", "hash": "86f765d0bd6380a938f32c63e3449cd67979a44d", "best_bid": "0.1", "best_ask": "0.13"}], "timestamp": "1769384025370", "event_type": "price_change"}}
{"_local_timestamp": "2026-01-25T23:33:45.454928+00:00", "data": {"market": "0x74cda80b2734086fa7e6bfce27d6321bb617d28dde6b486e7d3567c6afa5f46f", "price_changes": [{"asset_id": "54097693815260016929707363796097268965809730515171531228590357799043969397342", "price": "0.8", "size": "10", "side": "BUY", "hash": "3267d7ea82f935819a1845beada75f731d4f85a1", "best_bid": "0.87", "best_ask": "0.9"}, {"asset_id": "108808298639528397169807740481685882973822875737039638334154867204245949286757", "price": "0.2", "size": "10", "side": "SELL", "hash": "b977f1bb3f32a9a6721841c691a188a4be10ff07", "best_bid": "0.1", "best_ask": "0.13"}], "timestamp": "1769384025370", "event_type": "price_change"}}
{"_local_timestamp": "2026-01-25T23:33:45.456618+00:00", "data": {"market": "0x74cda80b2734086fa7e6bfce27d6321bb617d28dde6b486e7d3567c6afa5f46f", "price_changes": [{"asset_id": "54097693815260016929707363796097268965809730515171531228590357799043969397342", "price": "0.81", "size": "100", "side": "BUY", "hash": "2d92baf0fe46504ffa5a119afcbd6e2eda890cb1", "best_bid": "0.87", "best_ask": "0.9"}, {"asset_id": "108808298639528397169807740481685882973822875737039638334154867204245949286757", "price": "0.19", "size": "100", "side": "SELL", "hash": "b72b42b592f96f2f5e41007caee75eecad738bfc", "best_bid": "0.1", "best_ask": "0.13"}], "timestamp": "1769384025373", "event_type": "price_change"}}
{"_local_timestamp": "2026-01-25T23:33:45.528208+00:00", "data": {"market": "0xbbf9e226512452452438571385c111fafd7a581f227d997183b3c0ed0aaa6e94", "price_changes": [{"asset_id": "70641103843303633433849051708048017041225992079285926883062800006960120844878", "price": "0.72", "size": "25", "side": "BUY", "hash": "4953822fcbe32aacbe61c5c6c44965b8b724bc21", "best_bid": "0.75", "best_ask": "0.8"}, {"asset_id": "32365631237478011719581335465835096900088880772439977051943287219696169513404", "price": "0.28", "size": "25", "side": "SELL", "hash": "622e6cb0ed2c8b0eb7a5087b638fabbee81bb7cc", "best_bid": "0.2", "best_ask": "0.25"}], "timestamp": "1769384025454", "event_type": "price_change"}}
{"_local_timestamp": "2026-01-25T23:33:45.571711+00:00", "data": {"market": "0x5e75c47528185caa0b8140d5199a505b111d535d004f10c14c77099e160f8c43", "price_changes": [{"asset_id": "37216599669721820787426834964764344032227136269811356205946493119045847831924", "price": "0.85", "size": "1004", "side": "BUY", "hash": "eb5c103005443cbb8fda307b5c398a487ee3f536", "best_bid": "0.88", "best_ask": "0.89"}, {"asset_id": "40497352693029741963885292742967835565636400191703716161158810847504561227789", "price": "0.15", "size": "1004", "side": "SELL", "hash": "d58b91bf1de8b0474982355a07138aef67bcae75", "best_bid": "0.11", "best_ask": "0.12"}], "timestamp": "1769384025494", "event_type": "price_change"}}
{"_local_timestamp": "2026-01-25T23:33:45.572443+00:00", "data": {"market": "0x5e75c47528185caa0b8140d5199a505b111d535d004f10c14c77099e160f8c43", "price_changes": [{"asset_id": "40497352693029741963885292742967835565636400191703716161158810847504561227789", "price": "0.1", "size": "100", "side": "BUY", "hash": "fd8fabbd85867cd13f62b05e12ba99fceddc78af", "best_bid": "0.11", "best_ask": "0.12"}, {"asset_id": "37216599669721820787426834964764344032227136269811356205946493119045847831924", "price": "0.9", "size": "100", "side": "SELL", "hash": "5006e1a2c5d73a7f44552ba45141b9b613b5c907", "best_bid": "0.88", "best_ask": "0.89"}], "timestamp": "1769384025495", "event_type": "price_change"}}
{"_local_timestamp": "2026-01-25T23:33:45.579016+00:00", "data": {"market": "0x74cda80b2734086fa7e6bfce27d6321bb617d28dde6b486e7d3567c6afa5f46f", "price_changes": [{"asset_id": "54097693815260016929707363796097268965809730515171531228590357799043969397342", "price": "0.81", "size": "50", "side": "BUY", "hash": "9655343cb7ea26758ad244317e0e41dba1cffd6f", "best_bid": "0.87", "best_ask": "0.9"}, {"asset_id": "108808298639528397169807740481685882973822875737039638334154867204245949286757", "price": "0.19", "size": "50", "side": "SELL", "hash": "3698e684fdf24a5c22fa6b57b1ee56b9a92e0fa6", "best_bid": "0.1", "best_ask": "0.13"}], "timestamp": "1769384025497", "event_type": "price_change"}}
{"_local_timestamp": "2026-01-25T23:33:45.580629+00:00", "data": {"market": "0x74cda80b2734086fa7e6bfce27d6321bb617d28dde6b486e7d3567c6afa5f46f", "price_changes": [{"asset_id": "54097693815260016929707363796097268965809730515171531228590357799043969397342", "price": "0.8", "size": "60", "side": "BUY", "hash": "85314ac89aa64f4e236c5177edbe1dbe05c2d50f", "best_bid": "0.87", "best_ask": "0.9"}, {"asset_id": "108808298639528397169807740481685882973822875737039638334154867204245949286757", "price": "0.2", "size": "60", "side": "SELL", "hash": "d1deefe3e048e6969ca21d7ddcd385a255199e2f", "best_bid": "0.1", "best_ask": "0.13"}], "timestamp": "1769384025506", "event_type": "price_change"}}
{"_local_timestamp": "2026-01-25T23:33:45.747858+00:00", "data": {"market": "0x5b87791e06388b1a91fd402c29e483842da0f9fec156bb3cefe9d58275a0373b", "price_changes": [{"asset_id": "90132986654259086678529082268082617450254793801662820786849470352289449813683", "price": "0.032", "size": "200", "side": "BUY", "hash": "04ac968a03202ab5e1477fa032ec469d1bb9f87e", "best_bid": "0.034", "best_ask": "0.04"}, {"asset_id": "88022913747451311038559242580697856881859219751804674115271835179181575694176", "price": "0.968", "size": "200", "side": "SELL", "hash": "af8662d38d35a5d2e8f2b511603c48ee297f50cd", "best_bid": "0.96", "best_ask": "0.966"}], "timestamp": "1769384025677", "event_type": "price_change"}}
{"_local_timestamp": "2026-01-25T23:33:45.850457+00:00", "data": {"market": "0x7d4227c3c4f79de22bbf5b10301d3e99733151de11a2af04ee5d4fe9147fdb94", "price_changes": [{"asset_id": "114175921346199629913576111903487851727201567831569002664280492572302128017807", "price": "0.656", "size": "7", "side": "BUY", "hash": "c9f5cab2fae7212353a79566262ba18fe991d085", "best_bid": "0.681", "best_ask": "0.72"}, {"asset_id": "106160144365361466407303030429537634959446638743399742742547862828370756994868", "price": "0.344", "size": "7", "side": "SELL", "hash": "3e807dc749208430f88a875a3328e3c268c8afc0", "best_bid": "0.28", "best_ask": "0.319"}], "timestamp": "1769384025782", "event_type": "price_change"}}
{"_local_timestamp": "2026-01-25T23:33:45.857472+00:00", "data": {"market": "0x7d4227c3c4f79de22bbf5b10301d3e99733151de11a2af04ee5d4fe9147fdb94", "price_changes": [{"asset_id": "114175921346199629913576111903487851727201567831569002664280492572302128017807", "price": "0.629", "size": "7", "side": "BUY", "hash": "0745c3f449e673c9447f6fa405ce09632b180828", "best_bid": "0.681", "best_ask": "0.72"}, {"asset_id": "106160144365361466407303030429537634959446638743399742742547862828370756994868", "price": "0.371", "size": "7", "side": "SELL", "hash": "144abeddf5e9f6294fdc91764a5beb21c97187b1", "best_bid": "0.28", "best_ask": "0.319"}], "timestamp": "1769384025790", "event_type": "price_change"}}
{"_local_timestamp": "2026-01-25T23:33:45.868205+00:00", "data": {"market": "0x7130b2c99bee81af658adafb4a6235f21575f568e3ae2a850af742afa50c2d85", "price_changes": [{"asset_id": "17878506599231681723092997062254912120536148530389060800857875232098186845304", "price": "0.834", "size": "25", "side": "BUY", "hash": "4f2e0038598108aa736c6d81240eaf73c4648fdb", "best_bid": "0.886", "best_ask": "0.908"}, {"asset_id": "79480641743596328156888881841837787012633513624072222555595000167813156519758", "price": "0.166", "size": "25", "side": "SELL", "hash": "7d848dcf4414d003aca9b0b89d83e816520cee41", "best_bid": "0.092", "best_ask": "0.114"}], "timestamp": "1769384025798", "event_type": "price_change"}}
{"_local_timestamp": "2026-01-25T23:33:45.967898+00:00", "data": {"market": "0xbbf9e226512452452438571385c111fafd7a581f227d997183b3c0ed0aaa6e94", "price_changes": [{"asset_id": "70641103843303633433849051708048017041225992079285926883062800006960120844878", "price": "0.72", "size": "50", "side": "BUY", "hash": "250202c62ecf15f76274d1df099ad4f8cedb76e0", "best_bid": "0.75", "best_ask": "0.8"}, {"asset_id": "32365631237478011719581335465835096900088880772439977051943287219696169513404", "price": "0.28", "size": "50", "side": "SELL", "hash": "709d579e5f3d99d9c9add65722830c2c7a6fe1c2", "best_bid": "0.2", "best_ask": "0.25"}], "timestamp": "1769384025888", "event_type": "price_change"}}
{"_local_timestamp": "2026-01-25T23:33:45.973206+00:00", "data": {"market": "0xbbf9e226512452452438571385c111fafd7a581f227d997183b3c0ed0aaa6e94", "price_changes": [{"asset_id": "70641103843303633433849051708048017041225992079285926883062800006960120844878", "price": "0.71", "size": "50", "side": "BUY", "hash": "60f9626268b522ca7dbd6dd7e54d403be5b25e18", "best_bid": "0.75", "best_ask": "0.8"}, {"asset_id": "32365631237478011719581335465835096900088880772439977051943287219696169513404", "price": "0.29", "size": "50", "side": "SELL", "hash": "b8a3d4a5285fdcd424c2af57a4d8716705ecf468", "best_bid": "0.2", "best_ask": "0.25"}], "timestamp": "1769384025899", "event_type": "price_change"}}
{"_local_timestamp": "2026-01-25T23:33:45.985189+00:00", "data": {"market": "0xbbf9e226512452452438571385c111fafd7a581f227d997183b3c0ed0aaa6e94", "price_changes": [{"asset_id": "70641103843303633433849051708048017041225992079285926883062800006960120844878", "price": "0.75", "size": "160", "side": "BUY", "hash": "80f1083fd811394e252162757e6ccfca1242f7e0", "best_bid": "0.75", "best_ask": "0.8"}, {"asset_id": "32365631237478011719581335465835096900088880772439977051943287219696169513404", "price": "0.25", "size": "160", "side": "SELL", "hash": "e808e42447f7c7f6d549d8c472673e94c203e716", "best_bid": "0.2", "best_ask": "0.25"}], "timestamp": "1769384025918", "event_type": "price_change"}}
{"_local_timestamp": "2026-01-25T23:33:45.989059+00:00", "data": {"market": "0x7130b2c99bee81af658adafb4a6235f21575f568e3ae2a850af742afa50c2d85", "price_changes": [{"asset_id": "17878506599231681723092997062254912120536148530389060800857875232098186845304", "price": "0.834", "size": "50", "side": "BUY", "hash": "023375d9cd5b3ae1de85dfcf1d958ecd953f6cab", "best_bid": "0.886", "best_ask": "0.908"}, {"asset_id": "79480641743596328156888881841837787012633513624072222555595000167813156519758", "price": "0.166", "size": "50", "side": "SELL", "hash": "6685cfb7d153488f441b7f85447ac8b6cca0a3fd", "best_bid": "0.092", "best_ask": "0.114"}], "timestamp": "1769384025924", "event_type": "price_change"}}
{"_local_timestamp": "2026-01-25T23:33:46.003644+00:00", "data": {"market": "0x74cda80b2734086fa7e6bfce27d6321bb617d28dde6b486e7d3567c6afa5f46f", "price_changes": [{"asset_id": "54097693815260016929707363796097268965809730515171531228590357799043969397342", "price": "0.81", "size": "100", "side": "BUY", "hash": "bc3e3b61539ae9ef167be358770025640fc8f463", "best_bid": "0.87", "best_ask": "0.9"}, {"asset_id": "108808298639528397169807740481685882973822875737039638334154867204245949286757", "price": "0.19", "size": "100", "side": "SELL", "hash": "4f1c0a998f98d94e23782ee5a4a15934cbbd7dfa", "best_bid": "0.1", "best_ask": "0.13"}], "timestamp": "1769384025931", "event_type": "price_change"}}
{"_local_timestamp": "2026-01-25T23:33:46.059062+00:00", "data": {"market": "0xbbf9e226512452452438571385c111fafd7a581f227d997183b3c0ed0aaa6e94", "price_changes": [{"asset_id": "70641103843303633433849051708048017041225992079285926883062800006960120844878", "price": "0.72", "size": "25", "side": "BUY", "hash": "af65aa37b1d86d6db6341311e61977dca34484b0", "best_bid": "0.75", "best_ask": "0.8"}, {"asset_id": "32365631237478011719581335465835096900088880772439977051943287219696169513404", "price": "0.28", "size": "25", "side": "SELL", "hash": "46c1f696dfdba87718481794382074a8b34afaad", "best_bid": "0.2", "best_ask": "0.25"}], "timestamp": "1769384025990", "event_type": "price_change"}}
{"_local_timestamp": "2026-01-25T23:33:46.083743+00:00", "data": {"market": "0xbbf9e226512452452438571385c111fafd7a581f227d997183b3c0ed0aaa6e94", "price_changes": [{"asset_id": "70641103843303633433849051708048017041225992079285926883062800006960120844878", "price": "0.71", "size": "0", "side": "BUY", "hash": "e0667fd0cc0a0af176c2b0b3a9f2f017beac83fe", "best_bid": "0.75", "best_ask": "0.8"}, {"asset_id": "32365631237478011719581335465835096900088880772439977051943287219696169513404", "price": "0.29", "size": "0", "side": "SELL", "hash": "d78b0667f1c7ba294a42b792323cfcdad4d6fc2b", "best_bid": "0.2", "best_ask": "0.25"}], "timestamp": "1769384026004", "event_type": "price_change"}}
{"_local_timestamp": "2026-01-25T23:33:46.114982+00:00", "data": {"market": "0x7d4227c3c4f79de22bbf5b10301d3e99733151de11a2af04ee5d4fe9147fdb94", "price_changes": [{"asset_id": "114175921346199629913576111903487851727201567831569002664280492572302128017807", "price": "0.656", "size": "0", "side": "BUY", "hash": "b07334fa60af23cc2d9dc536858a73685ee7bff8", "best_bid": "0.681", "best_ask": "0.72"}, {"asset_id": "106160144365361466407303030429537634959446638743399742742547862828370756994868", "price": "0.344", "size": "0", "side": "SELL", "hash": "0b6063ba86afdda6ec8c8ee8a62c09351b2cfa79", "best_bid": "0.28", "best_ask": "0.319"}], "timestamp": "1769384026022", "event_type": "price_change"}}
{"_local_timestamp": "2026-01-25T23:33:46.116062+00:00", "data": {"market": "0x7d4227c3c4f79de22bbf5b10301d3e99733151de11a2af04ee5d4fe9147fdb94", "price_changes": [{"asset_id": "114175921346199629913576111903487851727201567831569002664280492572302128017807", "price": "0.629", "size": "0", "side": "BUY", "hash": "e5d3f0c101ada089fe518b86722df2d7cbd2a928", "best_bid": "0.681", "best_ask": "0.72"}, {"asset_id": "106160144365361466407303030429537634959446638743399742742547862828370756994868", "price": "0.371", "size": "0", "side": "SELL", "hash": "52775bb494d30d8bcbaeeb966be100e518fa8aef", "best_bid": "0.28", "best_ask": "0.319"}], "timestamp": "1769384026027", "event_type": "price_change"}}
{"_local_timestamp": "2026-01-25T23:33:46.116888+00:00", "data": {"market": "0x74cda80b2734086fa7e6bfce27d6321bb617d28dde6b486e7d3567c6afa5f46f", "price_changes": [{"asset_id": "54097693815260016929707363796097268965809730515171531228590357799043969397342", "price": "0.8", "size": "10", "side": "BUY", "hash": "3f00946218b9a1e1f4492c8fdaeb62a28d17d527", "best_bid": "0.87", "best_ask": "0.9"}, {"asset_id": "108808298639528397169807740481685882973822875737039638334154867204245949286757", "price": "0.2", "size": "10", "side": "SELL", "hash": "b181af2ecd388a7866d5e9cb16e90c145d8a1bd2", "best_bid": "0.1", "best_ask": "0.13"}], "timestamp": "1769384026009", "event_type": "price_change"}}
{"_local_timestamp": "2026-01-25T23:33:46.118067+00:00", "data": {"market": "0x74cda80b2734086fa7e6bfce27d6321bb617d28dde6b486e7d3567c6afa5f46f", "price_changes": [{"asset_id": "54097693815260016929707363796097268965809730515171531228590357799043969397342", "price": "0.81", "size": "50", "side": "BUY", "hash": "bab0da5015e2de5fb121374aa283895cc756f48f", "best_bid": "0.87", "best_ask": "0.9"}, {"asset_id": "108808298639528397169807740481685882973822875737039638334154867204245949286757", "price": "0.19", "size": "50", "side": "SELL", "hash": "6076e30018e80aeaa9df5eff09b7e6bd6c01f542", "best_bid": "0.1", "best_ask": "0.13"}], "timestamp": "1769384026020", "event_type": "price_change"}}
{"_local_timestamp": "2026-01-25T23:33:46.119782+00:00", "data": {"market": "0x7130b2c99bee81af658adafb4a6235f21575f568e3ae2a850af742afa50c2d85", "price_changes": [{"asset_id": "17878506599231681723092997062254912120536148530389060800857875232098186845304", "price": "0.834", "size": "25", "side": "BUY", "hash": "25137338bf56eafb4aa4d33280109c57d0e8f872", "best_bid": "0.886", "best_ask": "0.908"}, {"asset_id": "79480641743596328156888881841837787012633513624072222555595000167813156519758", "price": "0.166", "size": "25", "side": "SELL", "hash": "61051e48e9b2f8c21c13c4420ad579b885eb607f", "best_bid": "0.092", "best_ask": "0.114"}], "timestamp": "1769384026018", "event_type": "price_change"}}
{"_local_timestamp": "2026-01-25T23:33:46.121423+00:00", "data": {"market": "0x7130b2c99bee81af658adafb4a6235f21575f568e3ae2a850af742afa50c2d85", "price_changes": [{"asset_id": "17878506599231681723092997062254912120536148530389060800857875232098186845304", "price": "0.813", "size": "50", "side": "BUY", "hash": "ef7d9fdd434338c171ab8d8053737606762cbb3c", "best_bid": "0.886", "best_ask": "0.908"}, {"asset_id": "79480641743596328156888881841837787012633513624072222555595000167813156519758", "price": "0.187", "size": "50", "side": "SELL", "hash": "aa47b9d0a7e98a17803add5165f1fec165fff010", "best_bid": "0.092", "best_ask": "0.114"}], "timestamp": "1769384026026", "event_type": "price_change"}}
{"_local_timestamp": "2026-01-25T23:33:46.122149+00:00", "data": {"market": "0x7130b2c99bee81af658adafb4a6235f21575f568e3ae2a850af742afa50c2d85", "price_changes": [{"asset_id": "17878506599231681723092997062254912120536148530389060800857875232098186845304", "price": "0.834", "size": "0", "side": "BUY", "hash": "943c6011f3e5ee8b04237f5cf8c1b75e09378d5d", "best_bid": "0.886", "best_ask": "0.908"}, {"asset_id": "79480641743596328156888881841837787012633513624072222555595000167813156519758", "price": "0.166", "size": "0", "side": "SELL", "hash": "58ffaec52e40cb35ab7ee6a40c9aabed74ec4720", "best_bid": "0.092", "best_ask": "0.114"}], "timestamp": "1769384026047", "event_type": "price_change"}}
{"_local_timestamp": "2026-01-25T23:33:46.134367+00:00", "data": {"market": "0x5e75c47528185caa0b8140d5199a505b111d535d004f10c14c77099e160f8c43", "price_changes": [{"asset_id": "37216599669721820787426834964764344032227136269811356205946493119045847831924", "price": "0.91", "size": "50", "side": "SELL", "hash": "9957f9963ecc9a42e5e978d650989cd3613cad30", "best_bid": "0.88", "best_ask": "0.89"}, {"asset_id": "40497352693029741963885292742967835565636400191703716161158810847504561227789", "price": "0.09", "size": "50", "side": "BUY", "hash": "01b60427071cfaaafb1222b9218cbae4b2a4a36b", "best_bid": "0.11", "best_ask": "0.12"}], "timestamp": "1769384026059", "event_type": "price_change"}}
{"_local_timestamp": "2026-01-25T23:33:46.165027+00:00", "data": {"market": "0xbbf9e226512452452438571385c111fafd7a581f227d997183b3c0ed0aaa6e94", "price_changes": [{"asset_id": "70641103843303633433849051708048017041225992079285926883062800006960120844878", "price": "0.72", "size": "0", "side": "BUY", "hash": "a5734cf444a3fec5a94684b08d44b14dbcb93597", "best_bid": "0.75", "best_ask": "0.8"}, {"asset_id": "32365631237478011719581335465835096900088880772439977051943287219696169513404", "price": "0.28", "size": "0", "side": "SELL", "hash": "3ac325bf86cff2677f12084f841c8b442a6f915c", "best_bid": "0.2", "best_ask": "0.25"}], "timestamp": "1769384026098", "event_type": "price_change"}}
{"_local_timestamp": "2026-01-25T23:33:46.194578+00:00", "data": {"market": "0x5e75c47528185caa0b8140d5199a505b111d535d004f10c14c77099e160f8c43", "price_changes": [{"asset_id": "37216599669721820787426834964764344032227136269811356205946493119045847831924", "price": "0.88", "size": "19.71", "side": "BUY", "hash": "1395b5543cad23c6903ec05eb14a83a0b3a22a80", "best_bid": "0.88", "best_ask": "0.89"}, {"asset_id": "40497352693029741963885292742967835565636400191703716161158810847504561227789", "price": "0.12", "size": "19.71", "side": "SELL", "hash": "ed881caf30bc7f782a3bce55d2fde0afab43a7e9", "best_bid": "0.11", "best_ask": "0.12"}], "timestamp": "1769384026126", "event_type": "price_change"}}
{"_local_timestamp": "2026-01-25T23:33:46.196538+00:00", "data": {"market": "0x5e75c47528185caa0b8140d5199a505b111d535d004f10c14c77099e160f8c43", "asset_id": "40497352693029741963885292742967835565636400191703716161158810847504561227789", "bids": [{"price": "0.01", "size": "25800"}, {"price": "0.02", "size": "33.54"}, {"price": "0.03", "size": "3305.07"}, {"price": "0.04", "size": "260.76"}, {"price": "0.05", "size": "330"}, {"price": "0.06", "size": "56.56"}, {"price": "0.07", "size": "264.28"}, {"price": "0.08", "size": "116.59"}, {"price": "0.09", "size": "50"}, {"price": "0.1", "size": "100"}, {"price": "0.11", "size": "126.2"}], "asks": [{"price": "0.99", "size": "61013.78"}, {"price": "0.98", "size": "5012.89"}, {"price": "0.97", "size": "17266"}, {"price": "0.96", "size": "5.38"}, {"price": "0.95", "size": "70"}, {"price": "0.94", "size": "9480"}, {"price": "0.91", "size": "6600"}, {"price": "0.9", "size": "6.44"}, {"price": "0.89", "size": "2250"}, {"price": "0.8", "size": "800"}, {"price": "0.79", "size": "300"}, {"price": "0.78", "size": "3558"}, {"price": "0.73", "size": "50"}, {"price": "0.71", "size": "6"}, {"price": "0.66", "size": "50"}, {"price": "0.33", "size": "28.72"}, {"price": "0.32", "size": "16"}, {"price": "0.29", "size": "853.31"}, {"price": "0.28", "size": "731"}, {"price": "0.27", "size": "858.81"}, {"price": "0.26", "size": "345"}, {"price": "0.25", "size": "17.33"}, {"price": "0.23", "size": "64.28"}, {"price": "0.21", "size": "40"}, {"price": "0.16", "size": "260.59"}, {"price": "0.15", "size": "1004"}, {"price": "0.13", "size": "75"}, {"price": "0.12", "size": "19.71"}], "hash": "ed881caf30bc7f782a3bce55d2fde0afab43a7e9", "timestamp": "1769384026126", "event_type": "book"}}
{"_local_timestamp": "2026-01-25T23:33:46.204359+00:00", "data": {"market": "0x5e75c47528185caa0b8140d5199a505b111d535d004f10c14c77099e160f8c43", "asset_id": "37216599669721820787426834964764344032227136269811356205946493119045847831924", "bids": [{"price": "0.01", "size": "61013.78"}, {"price": "0.02", "size": "5012.89"}, {"price": "0.03", "size": "17266"}, {"price": "0.04", "size": "5.38"}, {"price": "0.05", "size": "70"}, {"price": "0.06", "size": "9480"}, {"price": "0.09", "size": "6600"}, {"price": "0.1", "size": "6.44"}, {"price": "0.11", "size": "2250"}, {"price": "0.2", "size": "800"}, {"price": "0.21", "size": "300"}, {"price": "0.22", "size": "3558"}, {"price": "0.27", "size": "50"}, {"price": "0.29", "size": "6"}, {"price": "0.34", "size": "50"}, {"price": "0.67", "size": "28.72"}, {"price": "0.68", "size": "16"}, {"price": "0.71", "size": "853.31"}, {"price": "0.72", "size": "731"}, {"price": "0.73", "size": "858.81"}, {"price": "0.74", "size": "345"}, {"price": "0.75", "size": "17.33"}, {"price": "0.77", "size": "64.28"}, {"price": "0.79", "size": "40"}, {"price": "0.84", "size": "260.59"}, {"price": "0.85", "size": "1004"}, {"price": "0.87", "size": "75"}, {"price": "0.88", "size": "19.71"}], "asks": [{"price": "0.99", "size": "25800"}, {"price": "0.98", "size": "33.54"}, {"price": "0.97", "size": "3305.07"}, {"price": "0.96", "size": "260.76"}, {"price": "0.95", "size": "330"}, {"price": "0.94", "size": "56.56"}, {"price": "0.93", "size": "264.28"}, {"price": "0.92", "size": "116.59"}, {"price": "0.91", "size": "50"}, {"price": "0.9", "size": "100"}, {"price": "0.89", "size": "126.2"}], "hash": "1395b5543cad23c6903ec05eb14a83a0b3a22a80", "timestamp": "1769384026126", "event_type": "book"}}
{"_local_timestamp": "2026-01-25T23:33:46.236858+00:00", "data": {"market": "0x5e75c47528185caa0b8140d5199a505b111d535d004f10c14c77099e160f8c43", "asset_id": "37216599669721820787426834964764344032227136269811356205946493119045847831924", "price": "0.88", "size": "30", "fee_rate_bps": "0", "side": "SELL", "timestamp": "1769384026157", "event_type": "last_trade_price", "transaction_hash": "0xb97e4c9e66e41b9cf46757012b461ae19ad7b83d366b43065e04719fda8953d1"}}
{"_local_timestamp": "2026-01-25T23:33:46.307715+00:00", "data": {"market": "0x5e75c47528185caa0b8140d5199a505b111d535d004f10c14c77099e160f8c43", "price_changes": [{"asset_id": "37216599669721820787426834964764344032227136269811356205946493119045847831924", "price": "0.8", "size": "50", "side": "BUY", "hash": "93c5e6b93b7022a2cd841b7bdb09e6b8ba210790", "best_bid": "0.88", "best_ask": "0.89"}, {"asset_id": "40497352693029741963885292742967835565636400191703716161158810847504561227789", "price": "0.2", "size": "50", "side": "SELL", "hash": "f327d8034fe275b3ce1de5432d56fd26405a3514", "best_bid": "0.11", "best_ask": "0.12"}], "timestamp": "1769384026234", "event_type": "price_change"}}
{"_local_timestamp": "2026-01-25T23:33:46.407861+00:00", "data": {"market": "0x7130b2c99bee81af658adafb4a6235f21575f568e3ae2a850af742afa50c2d85", "price_changes": [{"asset_id": "17878506599231681723092997062254912120536148530389060800857875232098186845304", "price": "0.823", "size": "100", "side": "BUY", "hash": "fed1720496906d647fc2bb231e5ec1e5c0b6390e", "best_bid": "0.886", "best_ask": "0.908"}, {"asset_id": "79480641743596328156888881841837787012633513624072222555595000167813156519758", "price": "0.177", "size": "100", "side": "SELL", "hash": "73983cc4a033cd5198e9c1377d44cfdd14e15eb1", "best_bid": "0.092", "best_ask": "0.114"}], "timestamp": "1769384026339", "event_type": "price_change"}}
{"_local_timestamp": "2026-01-25T23:33:46.527881+00:00", "data": {"market": "0x74cda80b2734086fa7e6bfce27d6321bb617d28dde6b486e7d3567c6afa5f46f", "price_changes": [{"asset_id": "54097693815260016929707363796097268965809730515171531228590357799043969397342", "price": "0.81", "size": "0", "side": "BUY", "hash": "aaa67f24a020929a1488b6d071569d90c57412a5", "best_bid": "0.87", "best_ask": "0.9"}, {"asset_id": "108808298639528397169807740481685882973822875737039638334154867204245949286757", "price": "0.19", "size": "0", "side": "SELL", "hash": "5376ac59c435ab134298adcf840a1620ec4482c3", "best_bid": "0.1", "best_ask": "0.13"}], "timestamp": "1769384026457", "event_type": "price_change"}}
{"_local_timestamp": "2026-01-25T23:33:46.546213+00:00", "data": {"market": "0xbbf9e226512452452438571385c111fafd7a581f227d997183b3c0ed0aaa6e94", "price_changes": [{"asset_id": "70641103843303633433849051708048017041225992079285926883062800006960120844878", "price": "0.76", "size": "30", "side": "BUY", "hash": "e31b6d63d86dc3d11840ddb221cc9f6140eec23d", "best_bid": "0.76", "best_ask": "0.8"}, {"asset_id": "32365631237478011719581335465835096900088880772439977051943287219696169513404", "price": "0.24", "size": "30", "side": "SELL", "hash": "e34e1713af8a97acd36b0a8809638d24648ca50f", "best_bid": "0.2", "best_ask": "0.24"}], "timestamp": "1769384026476", "event_type": "price_change"}}
{"_local_timestamp": "2026-01-25T23:33:46.657961+00:00", "data": {"market": "0x7d4227c3c4f79de22bbf5b10301d3e99733151de11a2af04ee5d4fe9147fdb94", "price_changes": [{"asset_id": "106160144365361466407303030429537634959446638743399742742547862828370756994868", "price": "0.271", "size": "108", "side": "BUY", "hash": "f4dbfb9edc40c3c23e57fbdcc9c9a343b453154c", "best_bid": "0.28", "best_ask": "0.319"}, {"asset_id": "114175921346199629913576111903487851727201567831569002664280492572302128017807", "price": "0.729", "size": "108", "side": "SELL", "hash": "bb18dfbfda259c68e65568920f30caed958ae8a7", "best_bid": "0.681", "best_ask": "0.72"}], "timestamp": "1769384026581", "event_type": "price_change"}}
{"_local_timestamp": "2026-01-25T23:33:46.933965+00:00", "data": {"market": "0x5e75c47528185caa0b8140d5199a505b111d535d004f10c14c77099e160f8c43", "price_changes": [{"asset_id": "37216599669721820787426834964764344032227136269811356205946493119045847831924", "price": "0.09", "size": "5900", "side": "BUY", "hash": "1c5d965685e2d5bb14f96d0fd0b07225f10e6acd", "best_bid": "0.88", "best_ask": "0.89"}, {"asset_id": "40497352693029741963885292742967835565636400191703716161158810847504561227789", "price": "0.91", "size": "5900", "side": "SELL", "hash": "9268c5bf717d02bcdf993094c14ede281db56254", "best_bid": "0.11", "best_ask": "0.12"}], "timestamp": "1769384026865", "event_type": "price_change"}}
{"_local_timestamp": "2026-01-25T23:33:47.046419+00:00", "data": {"market": "0x7d4227c3c4f79de22bbf5b10301d3e99733151de11a2af04ee5d4fe9147fdb94", "price_changes": [{"asset_id": "114175921346199629913576111903487851727201567831569002664280492572302128017807", "price": "0.629", "size": "7", "side": "BUY", "hash": "abbf9f3c3f6dab4b95791846da0e8947a2e572a0", "best_bid": "0.681", "best_ask": "0.72"}, {"asset_id": "106160144365361466407303030429537634959446638743399742742547862828370756994868", "price": "0.371", "size": "7", "side": "SELL", "hash": "04b02b142bdcc5bb4d65bf5fa6dc0077c839b135", "best_bid": "0.28", "best_ask": "0.319"}], "timestamp": "1769384026976", "event_type": "price_change"}}
{"_local_timestamp": "2026-01-25T23:33:47.053897+00:00", "data": {"market": "0x5e75c47528185caa0b8140d5199a505b111d535d004f10c14c77099e160f8c43", "price_changes": [{"asset_id": "37216599669721820787426834964764344032227136269811356205946493119045847831924", "price": "0.8", "size": "0", "side": "BUY", "hash": "6cacac9635164eb61e3680bd1f3382262df78bf1", "best_bid": "0.88", "best_ask": "0.89"}, {"asset_id": "40497352693029741963885292742967835565636400191703716161158810847504561227789", "price": "0.2", "size": "0", "side": "SELL", "hash": "2120b16542ec8b6f3f8c97edf63be9f3c5883838", "best_bid": "0.11", "best_ask": "0.12"}], "timestamp": "1769384026986", "event_type": "price_change"}}
{"_local_timestamp": "2026-01-25T23:33:47.089476+00:00", "data": {"market": "0x7130b2c99bee81af658adafb4a6235f21575f568e3ae2a850af742afa50c2d85", "price_changes": [{"asset_id": "17878506599231681723092997062254912120536148530389060800857875232098186845304", "price": "0.823", "size": "50", "side": "BUY", "hash": "bd664d61785d243e90a531124fb0c2389b0c64b5", "best_bid": "0.886", "best_ask": "0.908"}, {"asset_id": "79480641743596328156888881841837787012633513624072222555595000167813156519758", "price": "0.177", "size": "50", "side": "SELL", "hash": "f80ede4d51a5a779d8d91ff895525e2b82c59210", "best_bid": "0.092", "best_ask": "0.114"}], "timestamp": "1769384027010", "event_type": "price_change"}}
{"_local_timestamp": "2026-01-25T23:33:47.096801+00:00", "data": {"market": "0x7130b2c99bee81af658adafb4a6235f21575f568e3ae2a850af742afa50c2d85", "price_changes": [{"asset_id": "17878506599231681723092997062254912120536148530389060800857875232098186845304", "price": "0.834", "size": "25", "side": "BUY", "hash": "7ee30d90202a5332d665d7581f4a60c838fa0868", "best_bid": "0.886", "best_ask": "0.908"}, {"asset_id": "79480641743596328156888881841837787012633513624072222555595000167813156519758", "price": "0.166", "size": "25", "side": "SELL", "hash": "2355659e0e508524f9c106a51ed000893d2ef498", "best_bid": "0.092", "best_ask": "0.114"}], "timestamp": "1769384027012", "event_type": "price_change"}}
{"_local_timestamp": "2026-01-25T23:33:47.101130+00:00", "data": {"market": "0x7d4227c3c4f79de22bbf5b10301d3e99733151de11a2af04ee5d4fe9147fdb94", "price_changes": [{"asset_id": "114175921346199629913576111903487851727201567831569002664280492572302128017807", "price": "0.656", "size": "7", "side": "BUY", "hash": "aebb7c5306d477c1b82647769ea818ef675452ae", "best_bid": "0.681", "best_ask": "0.72"}, {"asset_id": "106160144365361466407303030429537634959446638743399742742547862828370756994868", "price": "0.344", "size": "7", "side": "SELL", "hash": "364faa98d3dff723ffad007586715d1f215d07de", "best_bid": "0.28", "best_ask": "0.319"}], "timestamp": "1769384027013", "event_type": "price_change"}}
{"_local_timestamp": "2026-01-25T23:33:47.155669+00:00", "data": {"market": "0x7d4227c3c4f79de22bbf5b10301d3e99733151de11a2af04ee5d4fe9147fdb94", "price_changes": [{"asset_id": "114175921346199629913576111903487851727201567831569002664280492572302128017807", "price": "0.629", "size": "0", "side": "BUY", "hash": "2490126357cda37bf3f6d58a6f50dc78eef0afbf", "best_bid": "0.681", "best_ask": "0.72"}, {"asset_id": "106160144365361466407303030429537634959446638743399742742547862828370756994868", "price": "0.371", "size": "0", "side": "SELL", "hash": "78f48e2e744876161a107ae5b780457b3364ca27", "best_bid": "0.28", "best_ask": "0.319"}], "timestamp": "1769384027079", "event_type": "price_change"}}
{"_local_timestamp": "2026-01-25T23:33:47.156981+00:00", "data": {"market": "0xbbf9e226512452452438571385c111fafd7a581f227d997183b3c0ed0aaa6e94", "price_changes": [{"asset_id": "70641103843303633433849051708048017041225992079285926883062800006960120844878", "price": "0.75", "size": "130", "side": "BUY", "hash": "4290e059ac31bd71e539494e36365a234511cf4c", "best_bid": "0.76", "best_ask": "0.8"}, {"asset_id": "32365631237478011719581335465835096900088880772439977051943287219696169513404", "price": "0.25", "size": "130", "side": "SELL", "hash": "8408c3baa06a5509a753a626f5499e0caa278d08", "best_bid": "0.2", "best_ask": "0.24"}], "timestamp": "1769384027091", "event_type": "price_change"}}
{"_local_timestamp": "2026-01-25T23:33:47.214284+00:00", "data": {"market": "0x5e75c47528185caa0b8140d5199a505b111d535d004f10c14c77099e160f8c43", "price_changes": [{"asset_id": "37216599669721820787426834964764344032227136269811356205946493119045847831924", "price": "0.11", "size": "2650", "side": "BUY", "hash": "4e232e6db1bd754ec0f189c5dcf9c54a22fccd9c", "best_bid": "0.88", "best_ask": "0.89"}, {"asset_id": "40497352693029741963885292742967835565636400191703716161158810847504561227789", "price": "0.89", "size": "2650", "side": "SELL", "hash": "4a82fec9a17bc61444a469b1a2e3c6d507109112", "best_bid": "0.11", "best_ask": "0.12"}], "timestamp": "1769384027144", "event_type": "price_change"}}
{"_local_timestamp": "2026-01-25T23:33:47.353003+00:00", "data": {"market": "0x5e75c47528185caa0b8140d5199a505b111d535d004f10c14c77099e160f8c43", "price_changes": [{"asset_id": "37216599669721820787426834964764344032227136269811356205946493119045847831924", "price": "0.8", "size": "50", "side": "BUY", "hash": "268322890dfe43d9ab5354f2e9179eaaf1f0194b", "best_bid": "0.88", "best_ask": "0.89"}, {"asset_id": "40497352693029741963885292742967835565636400191703716161158810847504561227789", "price": "0.2", "size": "50", "side": "SELL", "hash": "53b28a76f68fd77338045b40c03bb66af52564d1", "best_bid": "0.11", "best_ask": "0.12"}], "timestamp": "1769384027267", "event_type": "price_change"}}
{"_local_timestamp": "2026-01-25T23:33:47.452910+00:00", "data": {"market": "0x7130b2c99bee81af658adafb4a6235f21575f568e3ae2a850af742afa50c2d85", "price_changes": [{"asset_id": "17878506599231681723092997062254912120536148530389060800857875232098186845304", "price": "0.823", "size": "100", "side": "BUY", "hash": "2ba5240490ea1f7cff781913168aa667271df42f", "best_bid": "0.886", "best_ask": "0.908"}, {"asset_id": "79480641743596328156888881841837787012633513624072222555595000167813156519758", "price": "0.177", "size": "100", "side": "SELL", "hash": "e1c2f93179bd2986c5e6813f21f9f350b72716f6", "best_bid": "0.092", "best_ask": "0.114"}], "timestamp": "1769384027386", "event_type": "price_change"}}
{"_local_timestamp": "2026-01-25T23:33:47.573884+00:00", "data": {"market": "0x74cda80b2734086fa7e6bfce27d6321bb617d28dde6b486e7d3567c6afa5f46f", "price_changes": [{"asset_id": "54097693815260016929707363796097268965809730515171531228590357799043969397342", "price": "0.81", "size": "50", "side": "BUY", "hash": "870718ff0cb4ed7e2dcbd414537634d813670830", "best_bid": "0.87", "best_ask": "0.9"}, {"asset_id": "108808298639528397169807740481685882973822875737039638334154867204245949286757", "price": "0.19", "size": "50", "side": "SELL", "hash": "c9afbb1c2b8e39dc768642ec3f0e5afe2de46b33", "best_bid": "0.1", "best_ask": "0.13"}], "timestamp": "1769384027500", "event_type": "price_change"}}
{"_local_timestamp": "2026-01-25T23:33:47.904893+00:00", "data": {"market": "0x7130b2c99bee81af658adafb4a6235f21575f568e3ae2a850af742afa50c2d85", "price_changes": [{"asset_id": "17878506599231681723092997062254912120536148530389060800857875232098186845304", "price": "0.761", "size": "70", "side": "BUY", "hash": "ee4f5b9481d48b67e40c0b9a87107950f79005eb", "best_bid": "0.886", "best_ask": "0.908"}, {"asset_id": "79480641743596328156888881841837787012633513624072222555595000167813156519758", "price": "0.239", "size": "70", "side": "SELL", "hash": "b7c5aeb2e9093790ffb3231330777c3841029eba", "best_bid": "0.092", "best_ask": "0.114"}], "timestamp": "1769384027834", "event_type": "price_change"}}
{"_local_timestamp": "2026-01-25T23:33:48.233297+00:00", "data": {"market": "0x7130b2c99bee81af658adafb4a6235f21575f568e3ae2a850af742afa50c2d85", "price_changes": [{"asset_id": "17878506599231681723092997062254912120536148530389060800857875232098186845304", "price": "0.813", "size": "0", "side": "BUY", "hash": "0ffe51e2d3f2ddcbd7b9ea5f8e09b2f5dc0d7c91", "best_bid": "0.886", "best_ask": "0.908"}, {"asset_id": "79480641743596328156888881841837787012633513624072222555595000167813156519758", "price": "0.187", "size": "0", "side": "SELL", "hash": "423ac9443ae9b89cd27c317db183ae1ff4f7b9ca", "best_bid": "0.092", "best_ask": "0.114"}], "timestamp": "1769384028160", "event_type": "price_change"}}
{"_local_timestamp": "2026-01-25T23:33:48.272147+00:00", "data": {"market": "0xbbf9e226512452452438571385c111fafd7a581f227d997183b3c0ed0aaa6e94", "price_changes": [{"asset_id": "70641103843303633433849051708048017041225992079285926883062800006960120844878", "price": "0.73", "size": "199", "side": "BUY", "hash": "05086106efe0e90f8c7c828bcaa48c50d087ea9b", "best_bid": "0.76", "best_ask": "0.8"}, {"asset_id": "32365631237478011719581335465835096900088880772439977051943287219696169513404", "price": "0.27", "size": "199", "side": "SELL", "hash": "6629a214a65b9377a8b6b726dbbaec3f75627145", "best_bid": "0.2", "best_ask": "0.24"}], "timestamp": "1769384028202", "event_type": "price_change"}}
{"_local_timestamp": "2026-01-25T23:33:48.343929+00:00", "data": {"market": "0x7130b2c99bee81af658adafb4a6235f21575f568e3ae2a850af742afa50c2d85", "price_changes": [{"asset_id": "17878506599231681723092997062254912120536148530389060800857875232098186845304", "price": "0.834", "size": "0", "side": "BUY", "hash": "82408d45d2620b5461a59eb80c60baf60ddc326f", "best_bid": "0.886", "best_ask": "0.908"}, {"asset_id": "79480641743596328156888881841837787012633513624072222555595000167813156519758", "price": "0.166", "size": "0", "side": "SELL", "hash": "d51b87cf0f0369057de51318f317ce0714cbbcd4", "best_bid": "0.092", "best_ask": "0.114"}], "timestamp": "1769384028274", "event_type": "price_change"}}
{"_local_timestamp": "2026-01-25T23:33:48.357528+00:00", "data": {"market": "0x74cda80b2734086fa7e6bfce27d6321bb617d28dde6b486e7d3567c6afa5f46f", "price_changes": [{"asset_id": "54097693815260016929707363796097268965809730515171531228590357799043969397342", "price": "0.82", "size": "25", "side": "BUY", "hash": "26cc468119a4de6a121b326437b2deae65578307", "best_bid": "0.87", "best_ask": "0.9"}, {"asset_id": "108808298639528397169807740481685882973822875737039638334154867204245949286757", "price": "0.18", "size": "25", "side": "SELL", "hash": "1cdb3646bb12916a0539f2acf3dd111a8b55591f", "best_bid": "0.1", "best_ask": "0.13"}], "timestamp": "1769384028283", "event_type": "price_change"}}
{"_local_timestamp": "2026-01-25T23:33:48.358404+00:00", "data": {"market": "0x7130b2c99bee81af658adafb4a6235f21575f568e3ae2a850af742afa50c2d85", "price_changes": [{"asset_id": "17878506599231681723092997062254912120536148530389060800857875232098186845304", "price": "0.834", "size": "25", "side": "BUY", "hash": "8fdcaeddcaa87234770cb31e8404e7f339fae8a3", "best_bid": "0.886", "best_ask": "0.908"}, {"asset_id": "79480641743596328156888881841837787012633513624072222555595000167813156519758", "price": "0.166", "size": "25", "side": "SELL", "hash": "928095369b86a06846b17bbbac3753e6f67e6014", "best_bid": "0.092", "best_ask": "0.114"}], "timestamp": "1769384028283", "event_type": "price_change"}}
{"_local_timestamp": "2026-01-25T23:33:48.361371+00:00", "data": {"market": "0x7130b2c99bee81af658adafb4a6235f21575f568e3ae2a850af742afa50c2d85", "price_changes": [{"asset_id": "17878506599231681723092997062254912120536148530389060800857875232098186845304", "price": "0.823", "size": "50", "side": "BUY", "hash": "30e8a208df15006f868d3596094822bab2a24dd4", "best_bid": "0.886", "best_ask": "0.908"}, {"asset_id": "79480641743596328156888881841837787012633513624072222555595000167813156519758", "price": "0.177", "size": "50", "side": "SELL", "hash": "789844ffd374c9f4fae211149137ba5e7605f8af", "best_bid": "0.092", "best_ask": "0.114"}], "timestamp": "1769384028284", "event_type": "price_change"}}
{"_local_timestamp": "2026-01-25T23:33:48.365466+00:00", "data": {"market": "0x5e75c47528185caa0b8140d5199a505b111d535d004f10c14c77099e160f8c43", "price_changes": [{"asset_id": "37216599669721820787426834964764344032227136269811356205946493119045847831924", "price": "0.8", "size": "0", "side": "BUY", "hash": "e7596b5e229a7563d026341174583a1aadcfa8d6", "best_bid": "0.88", "best_ask": "0.89"}, {"asset_id": "40497352693029741963885292742967835565636400191703716161158810847504561227789", "price": "0.2", "size": "0", "side": "SELL", "hash": "fe41e53fdbf8f1bc7074a4c932c8391f3a2c1a46", "best_bid": "0.11", "best_ask": "0.12"}], "timestamp": "1769384028289", "event_type": "price_change"}}
{"_local_timestamp": "2026-01-25T23:33:48.367048+00:00", "data": {"market": "0x7130b2c99bee81af658adafb4a6235f21575f568e3ae2a850af742afa50c2d85", "price_changes": [{"asset_id": "17878506599231681723092997062254912120536148530389060800857875232098186845304", "price": "0.822", "size": "50", "side": "BUY", "hash": "52e5aad962e558beaa2b49f71656136f71e5e8cc", "best_bid": "0.886", "best_ask": "0.908"}, {"asset_id": "79480641743596328156888881841837787012633513624072222555595000167813156519758", "price": "0.178", "size": "50", "side": "SELL", "hash": "5a55b04e7fe7554b4f3a4bd1f23360fb22f23140", "best_bid": "0.092", "best_ask": "0.114"}], "timestamp": "1769384028290", "event_type": "price_change"}}
{"_local_timestamp": "2026-01-25T23:33:48.368146+00:00", "data": {"market": "0x74cda80b2734086fa7e6bfce27d6321bb617d28dde6b486e7d3567c6afa5f46f", "price_changes": [{"asset_id": "54097693815260016929707363796097268965809730515171531228590357799043969397342", "price": "0.81", "size": "100", "side": "BUY", "hash": "9bcdbb9a41c230568dba980c8640e8695f2ffe83", "best_bid": "0.87", "best_ask": "0.9"}, {"asset_id": "108808298639528397169807740481685882973822875737039638334154867204245949286757", "price": "0.19", "size": "100", "side": "SELL", "hash": "99e6338b104d53bb6dbfae2e94ee41d82ac8a61c", "best_bid": "0.1", "best_ask": "0.13"}], "timestamp": "1769384028290", "event_type": "price_change"}}
{"_local_timestamp": "2026-01-25T23:33:48.375227+00:00", "data": {"market": "0x7130b2c99bee81af658adafb4a6235f21575f568e3ae2a850af742afa50c2d85", "price_changes": [{"asset_id": "17878506599231681723092997062254912120536148530389060800857875232098186845304", "price": "0.761", "size": "50", "side": "BUY", "hash": "9db8c119609b4ebda3160b042c7f8fbda04e7c2b", "best_bid": "0.886", "best_ask": "0.908"}, {"asset_id": "79480641743596328156888881841837787012633513624072222555595000167813156519758", "price": "0.239", "size": "50", "side": "SELL", "hash": "b034abd3c0dc5dc1258f3e164d6a7076ebe70dba", "best_bid": "0.092", "best_ask": "0.114"}], "timestamp": "1769384028301", "event_type": "price_change"}}
{"_local_timestamp": "2026-01-25T23:33:48.376751+00:00", "data": {"market": "0x74cda80b2734086fa7e6bfce27d6321bb617d28dde6b486e7d3567c6afa5f46f", "price_changes": [{"asset_id": "54097693815260016929707363796097268965809730515171531228590357799043969397342", "price": "0.69", "size": "0", "side": "BUY", "hash": "cbed146e8c251412173958f4e2bc040312d97789", "best_bid": "0.87", "best_ask": "0.9"}, {"asset_id": "108808298639528397169807740481685882973822875737039638334154867204245949286757", "price": "0.31", "size": "0", "side": "SELL", "hash": "50e49c597cfdf5b4d7fa073ddd5728aa603e2d8a", "best_bid": "0.1", "best_ask": "0.13"}], "timestamp": "1769384028301", "event_type": "price_change"}}
{"_local_timestamp": "2026-01-25T23:33:48.378190+00:00", "data": {"market": "0x3f973c672acd8233f5b953a9eaece0c41d82b932354f14cca316c8c8adbc5430", "price_changes": [{"asset_id": "93900842269737238576470860642705247823244098999914913757632782327103374288912", "price": "0.851", "size": "0", "side": "BUY", "hash": "47e95eda5dda6cdcb9605f20d4ad32e0b4346603", "best_bid": "0.975", "best_ask": "0.979"}, {"asset_id": "98245576915057665054883165975987196038445195653094902203445898901996168030329", "price": "0.149", "size": "0", "side": "SELL", "hash": "1948220701054b10e78387f6e65d2577ab870963", "best_bid": "0.021", "best_ask": "0.025"}], "timestamp": "1769384028301", "event_type": "price_change"}}
{"_local_timestamp": "2026-01-25T23:33:48.378965+00:00", "data": {"market": "0xa19142e40da92f4110d29f63475ed9689f1471f8963c87e3220a989cdb356d45", "price_changes": [{"asset_id": "81750849409365469972793631297951692550835139647103107287253620651299358774290", "price": "0.781", "size": "0", "side": "BUY", "hash": "68b2cb7298a29c7c5f3eed5278f4775ceefa252e", "best_bid": "0.899", "best_ask": "0.904"}, {"asset_id": "49980127219724914096527114792845752329307347014547067418981570311158802130688", "price": "0.219", "size": "0", "side": "SELL", "hash": "351fda8bc74d282330a911d53d7467241c7fa0b4", "best_bid": "0.096", "best_ask": "0.101"}], "timestamp": "1769384028301", "event_type": "price_change"}}
{"_local_timestamp": "2026-01-25T23:33:48.379682+00:00", "data": {"market": "0x7d4227c3c4f79de22bbf5b10301d3e99733151de11a2af04ee5d4fe9147fdb94", "price_changes": [{"asset_id": "114175921346199629913576111903487851727201567831569002664280492572302128017807", "price": "0.593", "size": "0", "side": "BUY", "hash": "585efa84e3e5725fbb378484defe9a4c030fcb38", "best_bid": "0.681", "best_ask": "0.72"}, {"asset_id": "106160144365361466407303030429537634959446638743399742742547862828370756994868", "price": "0.407", "size": "0", "side": "SELL", "hash": "d1b8023980cdb5e01dea7677d890d690d00228ae", "best_bid": "0.28", "best_ask": "0.319"}], "timestamp": "1769384028301", "event_type": "price_change"}}
{"_local_timestamp": "2026-01-25T23:33:48.380671+00:00", "data": {"market": "0xbbf9e226512452452438571385c111fafd7a581f227d997183b3c0ed0aaa6e94", "price_changes": [{"asset_id": "70641103843303633433849051708048017041225992079285926883062800006960120844878", "price": "0.67", "size": "0", "side": "BUY", "hash": "6a75ac670e5e4c5de69c21678a338e99471e3953", "best_bid": "0.76", "best_ask": "0.8"}, {"asset_id": "32365631237478011719581335465835096900088880772439977051943287219696169513404", "price": "0.33", "size": "0", "side": "SELL", "hash": "34da13b359be63dbfe049f4f0850f6558316dbcc", "best_bid": "0.2", "best_ask": "0.24"}], "timestamp": "1769384028301", "event_type": "price_change"}}
{"_local_timestamp": "2026-01-25T23:33:48.381743+00:00", "data": {"market": "0x7d4227c3c4f79de22bbf5b10301d3e99733151de11a2af04ee5d4fe9147fdb94", "price_changes": [{"asset_id": "114175921346199629913576111903487851727201567831569002664280492572302128017807", "price": "0.629", "size": "7", "side": "BUY", "hash": "2f20f74cd820131cabeafd4d0dfbfd95107634bb", "best_bid": "0.681", "best_ask": "0.72"}, {"asset_id": "106160144365361466407303030429537634959446638743399742742547862828370756994868", "price": "0.371", "size": "7", "side": "SELL", "hash": "1e83a0e5a2d1282eadf91d2a945ea800efa5f3ce", "best_bid": "0.28", "best_ask": "0.319"}], "timestamp": "1769384028304", "event_type": "price_change"}}
{"_local_timestamp": "2026-01-25T23:33:48.398085+00:00", "data": {"market": "0x7130b2c99bee81af658adafb4a6235f21575f568e3ae2a850af742afa50c2d85", "price_changes": [{"asset_id": "17878506599231681723092997062254912120536148530389060800857875232098186845304", "price": "0.762", "size": "20", "side": "BUY", "hash": "e6b36b534ee3ca0c6b83c14565c83bef5e6d6f87", "best_bid": "0.886", "best_ask": "0.908"}, {"asset_id": "79480641743596328156888881841837787012633513624072222555595000167813156519758", "price": "0.238", "size": "20", "side": "SELL", "hash": "fc941a08b921d07504e83a5231eafa19a159f537", "best_bid": "0.092", "best_ask": "0.114"}], "timestamp": "1769384028332", "event_type": "price_change"}}
{"_local_timestamp": "2026-01-25T23:33:48.398932+00:00", "data": {"market": "0x74cda80b2734086fa7e6bfce27d6321bb617d28dde6b486e7d3567c6afa5f46f", "price_changes": [{"asset_id": "54097693815260016929707363796097268965809730515171531228590357799043969397342", "price": "0.78", "size": "66.66", "side": "BUY", "hash": "f0b3fb3a42751022652325fac56893234597b52a", "best_bid": "0.87", "best_ask": "0.9"}, {"asset_id": "108808298639528397169807740481685882973822875737039638334154867204245949286757", "price": "0.22", "size": "66.66", "side": "SELL", "hash": "681bee1fb75555a0b22d29d1d085edcd89f916ec", "best_bid": "0.1", "best_ask": "0.13"}], "timestamp": "1769384028332", "event_type": "price_change"}}
{"_local_timestamp": "2026-01-25T23:33:48.399987+00:00", "data": {"market": "0xbbf9e226512452452438571385c111fafd7a581f227d997183b3c0ed0aaa6e94", "price_changes": [{"asset_id": "70641103843303633433849051708048017041225992079285926883062800006960120844878", "price": "0.68", "size": "106.17", "side": "BUY", "hash": "22bccf06096448abcf05906fcedb04b63fe1327e", "best_bid": "0.76", "best_ask": "0.8"}, {"asset_id": "32365631237478011719581335465835096900088880772439977051943287219696169513404", "price": "0.32", "size": "106.17", "side": "SELL", "hash": "c7413b7c606a1f88210a3d1caa55ccd8239b7b7f", "best_bid": "0.2", "best_ask": "0.24"}], "timestamp": "1769384028332", "event_type": "price_change"}}
{"_local_timestamp": "2026-01-25T23:33:48.400930+00:00", "data": {"market": "0x3f973c672acd8233f5b953a9eaece0c41d82b932354f14cca316c8c8adbc5430", "price_changes": [{"asset_id": "93900842269737238576470860642705247823244098999914913757632782327103374288912", "price": "0.861", "size": "20", "side": "BUY", "hash": "fe593bcb2aae4b4e0f6abae9f10292a4612a34f2", "best_bid": "0.975", "best_ask": "0.979"}, {"asset_id": "98245576915057665054883165975987196038445195653094902203445898901996168030329", "price": "0.139", "size": "20", "side": "SELL", "hash": "8755ee4fde5fcb756a1fbda9800affcfb4330df6", "best_bid": "0.021", "best_ask": "0.025"}], "timestamp": "1769384028332", "event_type": "price_change"}}
{"_local_timestamp": "2026-01-25T23:33:48.401680+00:00", "data": {"market": "0xa19142e40da92f4110d29f63475ed9689f1471f8963c87e3220a989cdb356d45", "price_changes": [{"asset_id": "81750849409365469972793631297951692550835139647103107287253620651299358774290", "price": "0.783", "size": "20", "side": "BUY", "hash": "b389d983097c273aec049087c3d5ab328dbdb8e1", "best_bid": "0.899", "best_ask": "0.904"}, {"asset_id": "49980127219724914096527114792845752329307347014547067418981570311158802130688", "price": "0.217", "size": "20", "side": "SELL", "hash": "ace701e3474d2101dd31a97397965fc3c26103b1", "best_bid": "0.096", "best_ask": "0.101"}], "timestamp": "1769384028332", "event_type": "price_change"}}
{"_local_timestamp": "2026-01-25T23:33:48.402873+00:00", "data": {"market": "0x7d4227c3c4f79de22bbf5b10301d3e99733151de11a2af04ee5d4fe9147fdb94", "price_changes": [{"asset_id": "114175921346199629913576111903487851727201567831569002664280492572302128017807", "price": "0.601", "size": "20", "side": "BUY", "hash": "080d6b02bbee1e8eeb38a335cc1f3d542db6363a", "best_bid": "0.681", "best_ask": "0.72"}, {"asset_id": "106160144365361466407303030429537634959446638743399742742547862828370756994868", "price": "0.399", "size": "20", "side": "SELL", "hash": "7c5a4044852da7bd32e596b30b0f69a82b14c4b1", "best_bid": "0.28", "best_ask": "0.319"}], "timestamp": "1769384028332", "event_type": "price_change"}}
{"_local_timestamp": "2026-01-25T23:33:48.404835+00:00", "data": {"market": "0x7d4227c3c4f79de22bbf5b10301d3e99733151de11a2af04ee5d4fe9147fdb94", "price_changes": [{"asset_id": "114175921346199629913576111903487851727201567831569002664280492572302128017807", "price": "0.656", "size": "0", "side": "BUY", "hash": "5b7900d5cf907a0191690dfa29c1ac562aacc5cf", "best_bid": "0.681", "best_ask": "0.72"}, {"asset_id": "106160144365361466407303030429537634959446638743399742742547862828370756994868", "price": "0.344", "size": "0", "side": "SELL", "hash": "73b5578a911ab30324af3db91232938d75dc471c", "best_bid": "0.28", "best_ask": "0.319"}], "timestamp": "1769384028332", "event_type": "price_change"}}
{"_local_timestamp": "2026-01-25T23:33:48.465746+00:00", "data": {"market": "0x74cda80b2734086fa7e6bfce27d6321bb617d28dde6b486e7d3567c6afa5f46f", "price_changes": [{"asset_id": "54097693815260016929707363796097268965809730515171531228590357799043969397342", "price": "0.82", "size": "50", "side": "BUY", "hash": "2fac8ed66ac079b25d7b057997301f781181b2be", "best_bid": "0.87", "best_ask": "0.9"}, {"asset_id": "108808298639528397169807740481685882973822875737039638334154867204245949286757", "price": "0.18", "size": "50", "side": "SELL", "hash": "6267ffe347ae7bd2892e0fc811a61d1137903b93", "best_bid": "0.1", "best_ask": "0.13"}], "timestamp": "1769384028397", "event_type": "price_change"}}
{"_local_timestamp": "2026-01-25T23:33:48.466944+00:00", "data": {"market": "0x74cda80b2734086fa7e6bfce27d6321bb617d28dde6b486e7d3567c6afa5f46f", "price_changes": [{"asset_id": "54097693815260016929707363796097268965809730515171531228590357799043969397342", "price": "0.81", "size": "50", "side": "BUY", "hash": "35a40e1322581678aed2c3540d00518048632e75", "best_bid": "0.87", "best_ask": "0.9"}, {"asset_id": "108808298639528397169807740481685882973822875737039638334154867204245949286757", "price": "0.19", "size": "50", "side": "SELL", "hash": "3a27980a18a53724c2a5cd03a29dd2177945b4ce", "best_bid": "0.1", "best_ask": "0.13"}], "timestamp": "1769384028401", "event_type": "price_change"}}
{"_local_timestamp": "2026-01-25T23:33:48.473004+00:00", "data": {"market": "0x7130b2c99bee81af658adafb4a6235f21575f568e3ae2a850af742afa50c2d85", "price_changes": [{"asset_id": "17878506599231681723092997062254912120536148530389060800857875232098186845304", "price": "0.823", "size": "100", "side": "BUY", "hash": "0a913445fc5ebabad8072d1e18d2ae56034c896d", "best_bid": "0.886", "best_ask": "0.908"}, {"asset_id": "79480641743596328156888881841837787012633513624072222555595000167813156519758", "price": "0.177", "size": "100", "side": "SELL", "hash": "740eb25194d05e5401f6d3684a089cfcbefc2c5f", "best_bid": "0.092", "best_ask": "0.114"}], "timestamp": "1769384028405", "event_type": "price_change"}}
{"_local_timestamp": "2026-01-25T23:33:48.559626+00:00", "data": {"market": "0x7d4227c3c4f79de22bbf5b10301d3e99733151de11a2af04ee5d4fe9147fdb94", "price_changes": [{"asset_id": "114175921346199629913576111903487851727201567831569002664280492572302128017807", "price": "0.656", "size": "7", "side": "BUY", "hash": "3ce893d12505c1ead04ba9908dcb81e9c11ba56f", "best_bid": "0.681", "best_ask": "0.72"}, {"asset_id": "106160144365361466407303030429537634959446638743399742742547862828370756994868", "price": "0.344", "size": "7", "side": "SELL", "hash": "b654e41da5ae9e6e24587f008530b34a0c52720a", "best_bid": "0.28", "best_ask": "0.319"}], "timestamp": "1769384028452", "event_type": "price_change"}}
{"_local_timestamp": "2026-01-25T23:33:48.560981+00:00", "data": {"market": "0x7130b2c99bee81af658adafb4a6235f21575f568e3ae2a850af742afa50c2d85", "price_changes": [{"asset_id": "17878506599231681723092997062254912120536148530389060800857875232098186845304", "price": "0.834", "size": "0", "side": "BUY", "hash": "c02bfe0737013021778ac2ce04ab7eb4063204e4", "best_bid": "0.886", "best_ask": "0.908"}, {"asset_id": "79480641743596328156888881841837787012633513624072222555595000167813156519758", "price": "0.166", "size": "0", "side": "SELL", "hash": "921490961fcdd56b19b8edb5bc8910d049bf3f8c", "best_bid": "0.092", "best_ask": "0.114"}], "timestamp": "1769384028475", "event_type": "price_change"}}
{"_local_timestamp": "2026-01-25T23:33:48.573612+00:00", "data": {"market": "0x74cda80b2734086fa7e6bfce27d6321bb617d28dde6b486e7d3567c6afa5f46f", "price_changes": [{"asset_id": "54097693815260016929707363796097268965809730515171531228590357799043969397342", "price": "0.82", "size": "25", "side": "BUY", "hash": "9d266defabda441da2cc3f8ac9c8c3576ff6f990", "best_bid": "0.87", "best_ask": "0.9"}, {"asset_id": "108808298639528397169807740481685882973822875737039638334154867204245949286757", "price": "0.18", "size": "25", "side": "SELL", "hash": "cbc9bd518adf81e90dae1f35d8ad914d80ea2290", "best_bid": "0.1", "best_ask": "0.13"}], "timestamp": "1769384028506", "event_type": "price_change"}}
{"_local_timestamp": "2026-01-25T23:33:48.696914+00:00", "data": {"market": "0x7d4227c3c4f79de22bbf5b10301d3e99733151de11a2af04ee5d4fe9147fdb94", "price_changes": [{"asset_id": "114175921346199629913576111903487851727201567831569002664280492572302128017807", "price": "0.77", "size": "5", "side": "SELL", "hash": "eff66f93fc1e85adc0dba1272e157ca047916242", "best_bid": "0.681", "best_ask": "0.72"}, {"asset_id": "106160144365361466407303030429537634959446638743399742742547862828370756994868", "price": "0.23", "size": "5", "side": "BUY", "hash": "8019524d8f32309eff1ae8f86cdbc25e6311c4e1", "best_bid": "0.28", "best_ask": "0.319"}], "timestamp": "1769384028631", "event_type": "price_change"}}
{"_local_timestamp": "2026-01-25T23:33:50.278065+00:00", "data": {"market": "0xbbf9e226512452452438571385c111fafd7a581f227d997183b3c0ed0aaa6e94", "price_changes": [{"asset_id": "70641103843303633433849051708048017041225992079285926883062800006960120844878", "price": "0.75", "size": "186.29", "side": "BUY", "hash": "72722fd4fd504e54b4f48f3e7035b232fbf0c7bc", "best_bid": "0.76", "best_ask": "0.8"}, {"asset_id": "32365631237478011719581335465835096900088880772439977051943287219696169513404", "price": "0.25", "size": "186.29", "side": "SELL", "hash": "ebcef143639c2f88e988ea70e1a2ea498513392e", "best_bid": "0.2", "best_ask": "0.24"}], "timestamp": "1769384030207", "event_type": "price_change"}}
{"_local_timestamp": "2026-01-25T23:33:50.384576+00:00", "data": {"market": "0x74cda80b2734086fa7e6bfce27d6321bb617d28dde6b486e7d3567c6afa5f46f", "price_changes": [{"asset_id": "54097693815260016929707363796097268965809730515171531228590357799043969397342", "price": "0.82", "size": "0", "side": "BUY", "hash": "30d381f518b1883217621bb58b6faf3db392f965", "best_bid": "0.87", "best_ask": "0.9"}, {"asset_id": "108808298639528397169807740481685882973822875737039638334154867204245949286757", "price": "0.18", "size": "0", "side": "SELL", "hash": "736e0b8dc54027b548f28fcaf69adccc371ac58f", "best_bid": "0.1", "best_ask": "0.13"}], "timestamp": "1769384030310", "event_type": "price_change"}}
{"_local_timestamp": "2026-01-25T23:33:50.405635+00:00", "data": {"market": "0x74cda80b2734086fa7e6bfce27d6321bb617d28dde6b486e7d3567c6afa5f46f", "price_changes": [{"asset_id": "54097693815260016929707363796097268965809730515171531228590357799043969397342", "price": "0.81", "size": "0", "side": "BUY", "hash": "e8f984551c404b9b746c5344d4342656902afb7e", "best_bid": "0.87", "best_ask": "0.9"}, {"asset_id": "108808298639528397169807740481685882973822875737039638334154867204245949286757", "price": "0.19", "size": "0", "side": "SELL", "hash": "cf8fd8df9609f35171bdfaafc420f8f526f4862a", "best_bid": "0.1", "best_ask": "0.13"}], "timestamp": "1769384030310", "event_type": "price_change"}}
{"_local_timestamp": "2026-01-25T23:33:50.408995+00:00", "data": {"market": "0x7130b2c99bee81af658adafb4a6235f21575f568e3ae2a850af742afa50c2d85", "price_changes": [{"asset_id": "17878506599231681723092997062254912120536148530389060800857875232098186845304", "price": "0.823", "size": "50", "side": "BUY", "hash": "427578a670e72b2576ed2234f4ca697bd293b50b", "best_bid": "0.886", "best_ask": "0.908"}, {"asset_id": "79480641743596328156888881841837787012633513624072222555595000167813156519758", "price": "0.177", "size": "50", "side": "SELL", "hash": "d6b9c984df4e782ae26c0ad0b704e02d15d7549c", "best_bid": "0.092", "best_ask": "0.114"}], "timestamp": "1769384030314", "event_type": "price_change"}}
{"_local_timestamp": "2026-01-25T23:33:50.413484+00:00", "data": {"market": "0x7d4227c3c4f79de22bbf5b10301d3e99733151de11a2af04ee5d4fe9147fdb94", "price_changes": [{"asset_id": "114175921346199629913576111903487851727201567831569002664280492572302128017807", "price": "0.629", "size": "0", "side": "BUY", "hash": "c9515d1a35a7d119393d2a1ed9282e472617c3c1", "best_bid": "0.681", "best_ask": "0.72"}, {"asset_id": "106160144365361466407303030429537634959446638743399742742547862828370756994868", "price": "0.371", "size": "0", "side": "SELL", "hash": "808288e136485a594526b12b77f3970f2b7c122d", "best_bid": "0.28", "best_ask": "0.319"}], "timestamp": "1769384030322", "event_type": "price_change"}}
{"_local_timestamp": "2026-01-25T23:33:50.414753+00:00", "data": {"market": "0x7d4227c3c4f79de22bbf5b10301d3e99733151de11a2af04ee5d4fe9147fdb94", "price_changes": [{"asset_id": "114175921346199629913576111903487851727201567831569002664280492572302128017807", "price": "0.656", "size": "0", "side": "BUY", "hash": "f85467bab33cc1734241609f59288cb950bb0c63", "best_bid": "0.681", "best_ask": "0.72"}, {"asset_id": "106160144365361466407303030429537634959446638743399742742547862828370756994868", "price": "0.344", "size": "0", "side": "SELL", "hash": "9dd10223216d227a35d4b3a52a7fea0a45d952f8", "best_bid": "0.28", "best_ask": "0.319"}], "timestamp": "1769384030326", "event_type": "price_change"}}
{"_local_timestamp": "2026-01-25T23:33:50.417847+00:00", "data": {"market": "0x7130b2c99bee81af658adafb4a6235f21575f568e3ae2a850af742afa50c2d85", "price_changes": [{"asset_id": "17878506599231681723092997062254912120536148530389060800857875232098186845304", "price": "0.822", "size": "0", "side": "BUY", "hash": "cd739e0021bc3c03f95d3eb77d23c7a1f7f21eaa", "best_bid": "0.886", "best_ask": "0.908"}, {"asset_id": "79480641743596328156888881841837787012633513624072222555595000167813156519758", "price": "0.178", "size": "0", "side": "SELL", "hash": "3aed23f68689ebc8c7bf005c91c1fc0762d8c034", "best_bid": "0.092", "best_ask": "0.114"}], "timestamp": "1769384030334", "event_type": "price_change"}}
{"_local_timestamp": "2026-01-25T23:33:50.493096+00:00", "data": {"market": "0x7130b2c99bee81af658adafb4a6235f21575f568e3ae2a850af742afa50c2d85", "price_changes": [{"asset_id": "17878506599231681723092997062254912120536148530389060800857875232098186845304", "price": "0.823", "size": "100", "side": "BUY", "hash": "f7c762241b0d771123ed56f20e5d5b9edc72104a", "best_bid": "0.886", "best_ask": "0.908"}, {"asset_id": "79480641743596328156888881841837787012633513624072222555595000167813156519758", "price": "0.177", "size": "100", "side": "SELL", "hash": "6167bbc87bfe437b62c3356f00e96ad4d52f4fb7", "best_bid": "0.092", "best_ask": "0.114"}], "timestamp": "1769384030428", "event_type": "price_change"}}
{"_local_timestamp": "2026-01-25T23:33:50.497539+00:00", "data": {"market": "0x7130b2c99bee81af658adafb4a6235f21575f568e3ae2a850af742afa50c2d85", "price_changes": [{"asset_id": "17878506599231681723092997062254912120536148530389060800857875232098186845304", "price": "0.834", "size": "25", "side": "BUY", "hash": "00f38e390287d4435a7f33ae4158ee7850b2c617", "best_bid": "0.886", "best_ask": "0.908"}, {"asset_id": "79480641743596328156888881841837787012633513624072222555595000167813156519758", "price": "0.166", "size": "25", "side": "SELL", "hash": "86092643525b339a4bf3d6fad9c0839e8b7420b1", "best_bid": "0.092", "best_ask": "0.114"}], "timestamp": "1769384030429", "event_type": "price_change"}}
{"_local_timestamp": "2026-01-25T23:33:50.505222+00:00", "data": {"market": "0xbbf9e226512452452438571385c111fafd7a581f227d997183b3c0ed0aaa6e94", "price_changes": [{"asset_id": "70641103843303633433849051708048017041225992079285926883062800006960120844878", "price": "0.74", "size": "30", "side": "BUY", "hash": "ae6a1ae7b477c230fdaccb07aad6e1c9a413965f", "best_bid": "0.76", "best_ask": "0.8"}, {"asset_id": "32365631237478011719581335465835096900088880772439977051943287219696169513404", "price": "0.26", "size": "30", "side": "SELL", "hash": "27125731f199ed98b8642bb8f6fe92349077c78c", "best_bid": "0.2", "best_ask": "0.24"}], "timestamp": "1769384030438", "event_type": "price_change"}}
{"_local_timestamp": "2026-01-25T23:33:50.507818+00:00", "data": {"market": "0x7d4227c3c4f79de22bbf5b10301d3e99733151de11a2af04ee5d4fe9147fdb94", "price_changes": [{"asset_id": "114175921346199629913576111903487851727201567831569002664280492572302128017807", "price": "0.656", "size": "7", "side": "BUY", "hash": "3b9a6afe2ef64ff013e0cb1544ee17769a580db4", "best_bid": "0.681", "best_ask": "0.72"}, {"asset_id": "106160144365361466407303030429537634959446638743399742742547862828370756994868", "price": "0.344", "size": "7", "side": "SELL", "hash": "0b0341d842c17376385f2168aacb851e3f6c9343", "best_bid": "0.28", "best_ask": "0.319"}], "timestamp": "1769384030439", "event_type": "price_change"}}
{"_local_timestamp": "2026-01-25T23:33:50.509860+00:00", "data": {"market": "0x7d4227c3c4f79de22bbf5b10301d3e99733151de11a2af04ee5d4fe9147fdb94", "price_changes": [{"asset_id": "114175921346199629913576111903487851727201567831569002664280492572302128017807", "price": "0.629", "size": "7", "side": "BUY", "hash": "c5385b283a81dc693af8b2a7273339bea33104e7", "best_bid": "0.681", "best_ask": "0.72"}, {"asset_id": "106160144365361466407303030429537634959446638743399742742547862828370756994868", "price": "0.371", "size": "7", "side": "SELL", "hash": "d03db6edd8974708d4881709605d2e79595500ef", "best_bid": "0.28", "best_ask": "0.319"}], "timestamp": "1769384030440", "event_type": "price_change"}}
{"_local_timestamp": "2026-01-25T23:33:50.525412+00:00", "data": {"market": "0x7d4227c3c4f79de22bbf5b10301d3e99733151de11a2af04ee5d4fe9147fdb94", "price_changes": [{"asset_id": "114175921346199629913576111903487851727201567831569002664280492572302128017807", "price": "0.637", "size": "27", "side": "BUY", "hash": "9459878cc9287ec3dbd6988ee712eda82233b9e5", "best_bid": "0.681", "best_ask": "0.72"}, {"asset_id": "106160144365361466407303030429537634959446638743399742742547862828370756994868", "price": "0.363", "size": "27", "side": "SELL", "hash": "9ee0c840ebe31135ac5eb39a3d4b77adfbf7151c", "best_bid": "0.28", "best_ask": "0.319"}], "timestamp": "1769384030457", "event_type": "price_change"}}
{"_local_timestamp": "2026-01-25T23:33:50.546581+00:00", "data": {"market": "0x7d4227c3c4f79de22bbf5b10301d3e99733151de11a2af04ee5d4fe9147fdb94", "price_changes": [{"asset_id": "114175921346199629913576111903487851727201567831569002664280492572302128017807", "price": "0.78", "size": "5", "side": "SELL", "hash": "616b952b699580fee20e7f1ecc17b6d29352d9e9", "best_bid": "0.681", "best_ask": "0.72"}, {"asset_id": "106160144365361466407303030429537634959446638743399742742547862828370756994868", "price": "0.22", "size": "5", "side": "BUY", "hash": "da3f6014ee5f09db1eb3fc64ffbdd74c93a4b0a5", "best_bid": "0.28", "best_ask": "0.319"}], "timestamp": "1769384030478", "event_type": "price_change"}}
{"_local_timestamp": "2026-01-25T23:33:50.648808+00:00", "data": {"market": "0xbbf9e226512452452438571385c111fafd7a581f227d997183b3c0ed0aaa6e94", "price_changes": [{"asset_id": "70641103843303633433849051708048017041225992079285926883062800006960120844878", "price": "0.73", "size": "209", "side": "BUY", "hash": "345a8226e9faf23101b4971255a7e539b4ddf1ac", "best_bid": "0.76", "best_ask": "0.8"}, {"asset_id": "32365631237478011719581335465835096900088880772439977051943287219696169513404", "price": "0.27", "size": "209", "side": "SELL", "hash": "4a19dd53c383431e2f5b42604dfc06660116cd8d", "best_bid": "0.2", "best_ask": "0.24"}], "timestamp": "1769384030542", "event_type": "price_change"}}
{"_local_timestamp": "2026-01-25T23:33:50.677585+00:00", "data": {"market": "0x7d4227c3c4f79de22bbf5b10301d3e99733151de11a2af04ee5d4fe9147fdb94", "price_changes": [{"asset_id": "114175921346199629913576111903487851727201567831569002664280492572302128017807", "price": "0.637", "size": "0", "side": "BUY", "hash": "aec7a0f648375086cd0820a07156aff6d2b8b7fe", "best_bid": "0.681", "best_ask": "0.72"}, {"asset_id": "106160144365361466407303030429537634959446638743399742742547862828370756994868", "price": "0.363", "size": "0", "side": "SELL", "hash": "991116709349c27325eea500f930a9d09732df2b", "best_bid": "0.28", "best_ask": "0.319"}], "timestamp": "1769384030564", "event_type": "price_change"}}
{"_local_timestamp": "2026-01-25T23:33:51.575311+00:00", "data": {"market": "0xbbf9e226512452452438571385c111fafd7a581f227d997183b3c0ed0aaa6e94", "price_changes": [{"asset_id": "70641103843303633433849051708048017041225992079285926883062800006960120844878", "price": "0.77", "size": "30", "side": "BUY", "hash": "4f0d5d7a624d9a47f31cbda009f851e27db85a78", "best_bid": "0.77", "best_ask": "0.8"}, {"asset_id": "32365631237478011719581335465835096900088880772439977051943287219696169513404", "price": "0.23", "size": "30", "side": "SELL", "hash": "9a7079fcaae0490621fbace1b475cfe15bee21a9", "best_bid": "0.2", "best_ask": "0.23"}], "timestamp": "1769384031508", "event_type": "price_change"}}
{"_local_timestamp": "2026-01-25T23:33:51.673952+00:00", "data": {"market": "0xbbf9e226512452452438571385c111fafd7a581f227d997183b3c0ed0aaa6e94", "price_changes": [{"asset_id": "70641103843303633433849051708048017041225992079285926883062800006960120844878", "price": "0.74", "size": "80", "side": "BUY", "hash": "a4c996effd0361ec699e188a068b2ed1a2ed705c", "best_bid": "0.77", "best_ask": "0.8"}, {"asset_id": "32365631237478011719581335465835096900088880772439977051943287219696169513404", "price": "0.26", "size": "80", "side": "SELL", "hash": "0c61b64f47ed7a13756f9a84dab2ababdb1c43a5", "best_bid": "0.2", "best_ask": "0.23"}], "timestamp": "1769384031587", "event_type": "price_change"}}
{"_local_timestamp": "2026-01-25T23:33:51.682590+00:00", "data": {"market": "0x7130b2c99bee81af658adafb4a6235f21575f568e3ae2a850af742afa50c2d85", "price_changes": [{"asset_id": "17878506599231681723092997062254912120536148530389060800857875232098186845304", "price": "0.834", "size": "50", "side": "BUY", "hash": "daad6a55ef0e18408ef783d8ae15449a8b972399", "best_bid": "0.886", "best_ask": "0.908"}, {"asset_id": "79480641743596328156888881841837787012633513624072222555595000167813156519758", "price": "0.166", "size": "50", "side": "SELL", "hash": "e169e5be6359b9b7827cb822a065bb9c4aefb6da", "best_bid": "0.092", "best_ask": "0.114"}], "timestamp": "1769384031614", "event_type": "price_change"}}
{"_local_timestamp": "2026-01-25T23:33:51.686034+00:00", "data": {"market": "0x7d4227c3c4f79de22bbf5b10301d3e99733151de11a2af04ee5d4fe9147fdb94", "price_changes": [{"asset_id": "114175921346199629913576111903487851727201567831569002664280492572302128017807", "price": "0.629", "size": "0", "side": "BUY", "hash": "081cca1172d3571b2667eee5f26488cf409776d8", "best_bid": "0.681", "best_ask": "0.72"}, {"asset_id": "106160144365361466407303030429537634959446638743399742742547862828370756994868", "price": "0.371", "size": "0", "side": "SELL", "hash": "fcaa2d6c59ccf2d1000b3d0702359d88bd5b9828", "best_bid": "0.28", "best_ask": "0.319"}], "timestamp": "1769384031619", "event_type": "price_change"}}
{"_local_timestamp": "2026-01-25T23:33:51.690149+00:00", "data": {"market": "0x7130b2c99bee81af658adafb4a6235f21575f568e3ae2a850af742afa50c2d85", "price_changes": [{"asset_id": "17878506599231681723092997062254912120536148530389060800857875232098186845304", "price": "0.834", "size": "25", "side": "BUY", "hash": "831e43790af6ee0657e89e03fc5801091ed12174", "best_bid": "0.886", "best_ask": "0.908"}, {"asset_id": "79480641743596328156888881841837787012633513624072222555595000167813156519758", "price": "0.166", "size": "25", "side": "SELL", "hash": "4e42a2476cd5c4f7678a41f2b09ad4302dbd567c", "best_bid": "0.092", "best_ask": "0.114"}], "timestamp": "1769384031623", "event_type": "price_change"}}
{"_local_timestamp": "2026-01-25T23:33:51.693597+00:00", "data": {"market": "0x7130b2c99bee81af658adafb4a6235f21575f568e3ae2a850af742afa50c2d85", "price_changes": [{"asset_id": "17878506599231681723092997062254912120536148530389060800857875232098186845304", "price": "0.822", "size": "50", "side": "BUY", "hash": "c52ade1661a3f32e6cdbcf34d3e3671044da0d0d", "best_bid": "0.886", "best_ask": "0.908"}, {"asset_id": "79480641743596328156888881841837787012633513624072222555595000167813156519758", "price": "0.178", "size": "50", "side": "SELL", "hash": "f8c227651ab8b2fdcefa0d5413c424a503487f81", "best_bid": "0.092", "best_ask": "0.114"}], "timestamp": "1769384031626", "event_type": "price_change"}}
{"_local_timestamp": "2026-01-25T23:33:51.698388+00:00", "data": {"market": "0x7d4227c3c4f79de22bbf5b10301d3e99733151de11a2af04ee5d4fe9147fdb94", "price_changes": [{"asset_id": "114175921346199629913576111903487851727201567831569002664280492572302128017807", "price": "0.656", "size": "0", "side": "BUY", "hash": "8e45e13f28095f6c11eebb8a2537c9733ce734ed", "best_bid": "0.681", "best_ask": "0.72"}, {"asset_id": "106160144365361466407303030429537634959446638743399742742547862828370756994868", "price": "0.344", "size": "0", "side": "SELL", "hash": "8d10ed4aa18518014f7cf338f6318a63eaf267fb", "best_bid": "0.28", "best_ask": "0.319"}], "timestamp": "1769384031630", "event_type": "price_change"}}
{"_local_timestamp": "2026-01-25T23:33:51.714799+00:00", "data": {"market": "0x7130b2c99bee81af658adafb4a6235f21575f568e3ae2a850af742afa50c2d85", "price_changes": [{"asset_id": "17878506599231681723092997062254912120536148530389060800857875232098186845304", "price": "0.823", "size": "50", "side": "BUY", "hash": "ac89b7fda21df8a8974c391c7efe7848cbe55989", "best_bid": "0.886", "best_ask": "0.908"}, {"asset_id": "79480641743596328156888881841837787012633513624072222555595000167813156519758", "price": "0.177", "size": "50", "side": "SELL", "hash": "620fe929092441c4317c4384b461437c1afff2d2", "best_bid": "0.092", "best_ask": "0.114"}], "timestamp": "1769384031645", "event_type": "price_change"}}
{"_local_timestamp": "2026-01-25T23:33:51.745666+00:00", "data": {"market": "0xbbf9e226512452452438571385c111fafd7a581f227d997183b3c0ed0aaa6e94", "price_changes": [{"asset_id": "70641103843303633433849051708048017041225992079285926883062800006960120844878", "price": "0.75", "size": "156.29", "side": "BUY", "hash": "e4369c3dc6b13cfad4edc93f7b20ea406c798bba", "best_bid": "0.77", "best_ask": "0.8"}, {"asset_id": "32365631237478011719581335465835096900088880772439977051943287219696169513404", "price": "0.25", "size": "156.29", "side": "SELL", "hash": "4e3e848c47fe85aa1f8109f2e3d3e3189fe2e15d", "best_bid": "0.2", "best_ask": "0.23"}], "timestamp": "1769384031675", "event_type": "price_change"}}
{"_local_timestamp": "2026-01-25T23:33:51.789817+00:00", "data": {"market": "0x7130b2c99bee81af658adafb4a6235f21575f568e3ae2a850af742afa50c2d85", "price_changes": [{"asset_id": "17878506599231681723092997062254912120536148530389060800857875232098186845304", "price": "0.834", "size": "0", "side": "BUY", "hash": "ba0f97afe83282da4bfec9a6c69bc6c3a1bf8ae8", "best_bid": "0.886", "best_ask": "0.908"}, {"asset_id": "79480641743596328156888881841837787012633513624072222555595000167813156519758", "price": "0.166", "size": "0", "side": "SELL", "hash": "c1844c59f39d84330dd45fd9ef8e1918171969e7", "best_bid": "0.092", "best_ask": "0.114"}], "timestamp": "1769384031723", "event_type": "price_change"}}
{"_local_timestamp": "2026-01-25T23:33:51.793726+00:00", "data": {"market": "0x7d4227c3c4f79de22bbf5b10301d3e99733151de11a2af04ee5d4fe9147fdb94", "price_changes": [{"asset_id": "114175921346199629913576111903487851727201567831569002664280492572302128017807", "price": "0.629", "size": "7", "side": "BUY", "hash": "353161d659ac898caec14d9ae2caa6972bd6f485", "best_bid": "0.681", "best_ask": "0.72"}, {"asset_id": "106160144365361466407303030429537634959446638743399742742547862828370756994868", "price": "0.371", "size": "7", "side": "SELL", "hash": "5155babc403265e88dd0c2096eaac93da59a256d", "best_bid": "0.28", "best_ask": "0.319"}], "timestamp": "1769384031728", "event_type": "price_change"}}
{"_local_timestamp": "2026-01-25T23:33:51.797463+00:00", "data": {"market": "0x7130b2c99bee81af658adafb4a6235f21575f568e3ae2a850af742afa50c2d85", "price_changes": [{"asset_id": "17878506599231681723092997062254912120536148530389060800857875232098186845304", "price": "0.834", "size": "25", "side": "BUY", "hash": "770a02698ca2e8aba3ce39d2cbb770e837bc7a36", "best_bid": "0.886", "best_ask": "0.908"}, {"asset_id": "79480641743596328156888881841837787012633513624072222555595000167813156519758", "price": "0.166", "size": "25", "side": "SELL", "hash": "8757c4bf081a071cb518066894d47d6004660535", "best_bid": "0.092", "best_ask": "0.114"}], "timestamp": "1769384031728", "event_type": "price_change"}}
{"_local_timestamp": "2026-01-25T23:33:51.826064+00:00", "data": {"market": "0x7d4227c3c4f79de22bbf5b10301d3e99733151de11a2af04ee5d4fe9147fdb94", "price_changes": [{"asset_id": "114175921346199629913576111903487851727201567831569002664280492572302128017807", "price": "0.656", "size": "7", "side": "BUY", "hash": "74c020f66d94a3ac5b8e640ef6c33adc2916c48e", "best_bid": "0.681", "best_ask": "0.72"}, {"asset_id": "106160144365361466407303030429537634959446638743399742742547862828370756994868", "price": "0.344", "size": "7", "side": "SELL", "hash": "6d8ffbe0cdde53ec7481f0f636d22ee3b8b732b0", "best_bid": "0.28", "best_ask": "0.319"}], "timestamp": "1769384031737", "event_type": "price_change"}}
{"_local_timestamp": "2026-01-25T23:33:51.827476+00:00", "data": {"market": "0x7d4227c3c4f79de22bbf5b10301d3e99733151de11a2af04ee5d4fe9147fdb94", "price_changes": [{"asset_id": "114175921346199629913576111903487851727201567831569002664280492572302128017807", "price": "0.637", "size": "27", "side": "BUY", "hash": "b10dc092b6f4932e0b757c15da4a8a45444ad9dc", "best_bid": "0.681", "best_ask": "0.72"}, {"asset_id": "106160144365361466407303030429537634959446638743399742742547862828370756994868", "price": "0.363", "size": "27", "side": "SELL", "hash": "ae5e97ea6c06b119a363c9d0e599ca83aa6c22f9", "best_bid": "0.28", "best_ask": "0.319"}], "timestamp": "1769384031751", "event_type": "price_change"}}
{"_local_timestamp": "2026-01-25T23:33:51.937403+00:00", "data": {"market": "0x7d4227c3c4f79de22bbf5b10301d3e99733151de11a2af04ee5d4fe9147fdb94", "price_changes": [{"asset_id": "114175921346199629913576111903487851727201567831569002664280492572302128017807", "price": "0.637", "size": "0", "side": "BUY", "hash": "32b947d8c008276658cdf7ca92f8b6ee0e989e34", "best_bid": "0.681", "best_ask": "0.72"}, {"asset_id": "106160144365361466407303030429537634959446638743399742742547862828370756994868", "price": "0.363", "size": "0", "side": "SELL", "hash": "13bb94d5b52da477b1cdd8ef3a04f31107bb941c", "best_bid": "0.28", "best_ask": "0.319"}], "timestamp": "1769384031857", "event_type": "price_change"}}
{"_local_timestamp": "2026-01-25T23:33:52.038303+00:00", "data": {"market": "0x7130b2c99bee81af658adafb4a6235f21575f568e3ae2a850af742afa50c2d85", "price_changes": [{"asset_id": "17878506599231681723092997062254912120536148530389060800857875232098186845304", "price": "0.822", "size": "0", "side": "BUY", "hash": "9b97a6c77b71000935317a4ed27f4320e662a3e9", "best_bid": "0.886", "best_ask": "0.908"}, {"asset_id": "79480641743596328156888881841837787012633513624072222555595000167813156519758", "price": "0.178", "size": "0", "side": "SELL", "hash": "44ab5148f6e42ca5b1acb80f230801a9aec5d2e2", "best_bid": "0.092", "best_ask": "0.114"}], "timestamp": "1769384031962", "event_type": "price_change"}}
{"_local_timestamp": "2026-01-25T23:33:52.042359+00:00", "data": {"market": "0x7d4227c3c4f79de22bbf5b10301d3e99733151de11a2af04ee5d4fe9147fdb94", "price_changes": [{"asset_id": "114175921346199629913576111903487851727201567831569002664280492572302128017807", "price": "0.656", "size": "0", "side": "BUY", "hash": "3d858fb145dd920e18446468348ee87c462a102b", "best_bid": "0.681", "best_ask": "0.72"}, {"asset_id": "106160144365361466407303030429537634959446638743399742742547862828370756994868", "price": "0.344", "size": "0", "side": "SELL", "hash": "d7663b76cfdcca8d49ef635fcc1876bb5525ca04", "best_bid": "0.28", "best_ask": "0.319"}], "timestamp": "1769384031963", "event_type": "price_change"}}
{"_local_timestamp": "2026-01-25T23:33:52.043174+00:00", "data": {"market": "0x7130b2c99bee81af658adafb4a6235f21575f568e3ae2a850af742afa50c2d85", "price_changes": [{"asset_id": "17878506599231681723092997062254912120536148530389060800857875232098186845304", "price": "0.834", "size": "0", "side": "BUY", "hash": "c5e0795475aedb6a116424252344a89bf016a851", "best_bid": "0.886", "best_ask": "0.908"}, {"asset_id": "79480641743596328156888881841837787012633513624072222555595000167813156519758", "price": "0.166", "size": "0", "side": "SELL", "hash": "ef2244723c046d01c5b6daff04495e51a7f13a6e", "best_bid": "0.092", "best_ask": "0.114"}], "timestamp": "1769384031964", "event_type": "price_change"}}
{"_local_timestamp": "2026-01-25T23:33:52.046799+00:00", "data": {"market": "0x7d4227c3c4f79de22bbf5b10301d3e99733151de11a2af04ee5d4fe9147fdb94", "price_changes": [{"asset_id": "114175921346199629913576111903487851727201567831569002664280492572302128017807", "price": "0.629", "size": "0", "side": "BUY", "hash": "2f976d8568f55c345b4ed7620b5e421064fafcb4", "best_bid": "0.681", "best_ask": "0.72"}, {"asset_id": "106160144365361466407303030429537634959446638743399742742547862828370756994868", "price": "0.371", "size": "0", "side": "SELL", "hash": "20bb2b1164d06cdd17893bf48220660e2a896444", "best_bid": "0.28", "best_ask": "0.319"}], "timestamp": "1769384031976", "event_type": "price_change"}}
{"_local_timestamp": "2026-01-25T23:33:52.172946+00:00", "data": {"market": "0x7d4227c3c4f79de22bbf5b10301d3e99733151de11a2af04ee5d4fe9147fdb94", "price_changes": [{"asset_id": "106160144365361466407303030429537634959446638743399742742547862828370756994868", "price": "0.359", "size": "11.56", "side": "SELL", "hash": "c0fbe372bb456eb0642cc6d35e45194207b7361e", "best_bid": "0.28", "best_ask": "0.319"}, {"asset_id": "114175921346199629913576111903487851727201567831569002664280492572302128017807", "price": "0.641", "size": "11.56", "side": "BUY", "hash": "a34d9fd16c6552fa8a370884332c78e4d12f3f06", "best_bid": "0.681", "best_ask": "0.72"}], "timestamp": "1769384032093", "event_type": "price_change"}}
{"_local_timestamp": "2026-01-25T23:33:52.173787+00:00", "data": {"market": "0x7d4227c3c4f79de22bbf5b10301d3e99733151de11a2af04ee5d4fe9147fdb94", "price_changes": [{"asset_id": "106160144365361466407303030429537634959446638743399742742547862828370756994868", "price": "0.359", "size": "23.12", "side": "SELL", "hash": "bb9f15df984b5bdc0ba5db16a160953443953d4f", "best_bid": "0.28", "best_ask": "0.319"}, {"asset_id": "114175921346199629913576111903487851727201567831569002664280492572302128017807", "price": "0.641", "size": "23.12", "side": "BUY", "hash": "01269db4aa39e5148c032c6930778b8267d6ac2f", "best_bid": "0.681", "best_ask": "0.72"}], "timestamp": "1769384032094", "event_type": "price_change"}}
{"_local_timestamp": "2026-01-25T23:33:52.174526+00:00", "data": {"market": "0x7d4227c3c4f79de22bbf5b10301d3e99733151de11a2af04ee5d4fe9147fdb94", "price_changes": [{"asset_id": "106160144365361466407303030429537634959446638743399742742547862828370756994868", "price": "0.359", "size": "34.68", "side": "SELL", "hash": "0501087a919caa6ccd079d54be3be0a963aad840", "best_bid": "0.28", "best_ask": "0.319"}, {"asset_id": "114175921346199629913576111903487851727201567831569002664280492572302128017807", "price": "0.641", "size": "34.68", "side": "BUY", "hash": "588263c99df2ecc315ae79a0ddddbfd49c766661", "best_bid": "0.681", "best_ask": "0.72"}], "timestamp": "1769384032095", "event_type": "price_change"}}
{"_local_timestamp": "2026-01-25T23:33:52.175683+00:00", "data": {"market": "0x7d4227c3c4f79de22bbf5b10301d3e99733151de11a2af04ee5d4fe9147fdb94", "price_changes": [{"asset_id": "106160144365361466407303030429537634959446638743399742742547862828370756994868", "price": "0.359", "size": "46.24", "side": "SELL", "hash": "e0be2fd41528abccb9b1fd126529d36ed9cd3ec1", "best_bid": "0.28", "best_ask": "0.319"}, {"asset_id": "114175921346199629913576111903487851727201567831569002664280492572302128017807", "price": "0.641", "size": "46.24", "side": "BUY", "hash": "cd1e5a870d42591ef3db23a933db50f10b5c9937", "best_bid": "0.681", "best_ask": "0.72"}], "timestamp": "1769384032095", "event_type": "price_change"}}
{"_local_timestamp": "2026-01-25T23:33:52.323817+00:00", "data": {"market": "0x7d4227c3c4f79de22bbf5b10301d3e99733151de11a2af04ee5d4fe9147fdb94", "price_changes": [{"asset_id": "114175921346199629913576111903487851727201567831569002664280492572302128017807", "price": "0.79", "size": "5", "side": "SELL", "hash": "1684cc9d6dfebb3bdebafc58b59f1ae2581e7e92", "best_bid": "0.681", "best_ask": "0.72"}, {"asset_id": "106160144365361466407303030429537634959446638743399742742547862828370756994868", "price": "0.21", "size": "5", "side": "BUY", "hash": "56f4272bf5b089676920e3ae1bf894ebedc2cff5", "best_bid": "0.28", "best_ask": "0.319"}], "timestamp": "1769384032241", "event_type": "price_change"}}
{"_local_timestamp": "2026-01-25T23:33:52.453538+00:00", "data": {"market": "0x7d4227c3c4f79de22bbf5b10301d3e99733151de11a2af04ee5d4fe9147fdb94", "price_changes": [{"asset_id": "114175921346199629913576111903487851727201567831569002664280492572302128017807", "price": "0.648", "size": "52", "side": "BUY", "hash": "f6473cd41ec57aafc6a2645ade5ac6546548c373", "best_bid": "0.681", "best_ask": "0.72"}, {"asset_id": "106160144365361466407303030429537634959446638743399742742547862828370756994868", "price": "0.352", "size": "52", "side": "SELL", "hash": "5226f45db079792c67f9654f3cd0f42313c4c79d", "best_bid": "0.28", "best_ask": "0.319"}], "timestamp": "1769384032366", "event_type": "price_change"}}
{"_local_timestamp": "2026-01-25T23:33:53.464652+00:00", "data": {"market": "0xbbf9e226512452452438571385c111fafd7a581f227d997183b3c0ed0aaa6e94", "price_changes": [{"asset_id": "70641103843303633433849051708048017041225992079285926883062800006960120844878", "price": "0.75", "size": "56.29", "side": "BUY", "hash": "e718735dfa86e3f9c860f3ff651c88240f418bc9", "best_bid": "0.77", "best_ask": "0.8"}, {"asset_id": "32365631237478011719581335465835096900088880772439977051943287219696169513404", "price": "0.25", "size": "56.29", "side": "SELL", "hash": "d7aaa12636912390239980c99791241555c0ea17", "best_bid": "0.2", "best_ask": "0.23"}], "timestamp": "1769384033393", "event_type": "price_change"}}
{"_local_timestamp": "2026-01-25T23:33:53.568957+00:00", "data": {"market": "0x7d4227c3c4f79de22bbf5b10301d3e99733151de11a2af04ee5d4fe9147fdb94", "price_changes": [{"asset_id": "114175921346199629913576111903487851727201567831569002664280492572302128017807", "price": "0.648", "size": "84", "side": "BUY", "hash": "78cc2fccabdcda9a36f364452e830c1ffcceffb1", "best_bid": "0.681", "best_ask": "0.72"}, {"asset_id": "106160144365361466407303030429537634959446638743399742742547862828370756994868", "price": "0.352", "size": "84", "side": "SELL", "hash": "c248daa11d4c105370c697e9e6f88fcf695030dd", "best_bid": "0.28", "best_ask": "0.319"}], "timestamp": "1769384033502", "event_type": "price_change"}}
{"_local_timestamp": "2026-01-25T23:33:53.571433+00:00", "data": {"market": "0x7d4227c3c4f79de22bbf5b10301d3e99733151de11a2af04ee5d4fe9147fdb94", "price_changes": [{"asset_id": "114175921346199629913576111903487851727201567831569002664280492572302128017807", "price": "0.656", "size": "7", "side": "BUY", "hash": "233b9ce7d5d128f83b55d3ca022a33fe06efcdea", "best_bid": "0.681", "best_ask": "0.72"}, {"asset_id": "106160144365361466407303030429537634959446638743399742742547862828370756994868", "price": "0.344", "size": "7", "side": "SELL", "hash": "0d3141883857ff03a9dd8833fb8c4efa3152071f", "best_bid": "0.28", "best_ask": "0.319"}], "timestamp": "1769384033503", "event_type": "price_change"}}
{"_local_timestamp": "2026-01-25T23:33:53.573019+00:00", "data": {"market": "0x7130b2c99bee81af658adafb4a6235f21575f568e3ae2a850af742afa50c2d85", "price_changes": [{"asset_id": "17878506599231681723092997062254912120536148530389060800857875232098186845304", "price": "0.822", "size": "50", "side": "BUY", "hash": "e2b2e8f0b6133d4be70b91daf24fc9ce7b290b35", "best_bid": "0.886", "best_ask": "0.908"}, {"asset_id": "79480641743596328156888881841837787012633513624072222555595000167813156519758", "price": "0.178", "size": "50", "side": "SELL", "hash": "47d75cd35164f3d7faa710bc34a8906357c4e901", "best_bid": "0.092", "best_ask": "0.114"}], "timestamp": "1769384033503", "event_type": "price_change"}}
{"_local_timestamp": "2026-01-25T23:33:53.574328+00:00", "data": {"market": "0x7130b2c99bee81af658adafb4a6235f21575f568e3ae2a850af742afa50c2d85", "price_changes": [{"asset_id": "17878506599231681723092997062254912120536148530389060800857875232098186845304", "price": "0.823", "size": "100", "side": "BUY", "hash": "7426132b4a24fd07f9e949aea142a96f798e25e3", "best_bid": "0.886", "best_ask": "0.908"}, {"asset_id": "79480641743596328156888881841837787012633513624072222555595000167813156519758", "price": "0.177", "size": "100", "side": "SELL", "hash": "c21b4ee2370451719faece46873a6001440595a4", "best_bid": "0.092", "best_ask": "0.114"}], "timestamp": "1769384033505", "event_type": "price_change"}}
{"_local_timestamp": "2026-01-25T23:33:53.617075+00:00", "data": {"market": "0xbbf9e226512452452438571385c111fafd7a581f227d997183b3c0ed0aaa6e94", "price_changes": [{"asset_id": "70641103843303633433849051708048017041225992079285926883062800006960120844878", "price": "0.76", "size": "0", "side": "BUY", "hash": "596f8aeb3f647ea55796494f4a8a3316e8087724", "best_bid": "0.77", "best_ask": "0.8"}, {"asset_id": "32365631237478011719581335465835096900088880772439977051943287219696169513404", "price": "0.24", "size": "0", "side": "SELL", "hash": "57116c9c0785b70936ffd67ce65553dd7003a6d5", "best_bid": "0.2", "best_ask": "0.23"}], "timestamp": "1769384033551", "event_type": "price_change"}}
{"_local_timestamp": "2026-01-25T23:33:53.689604+00:00", "data": {"market": "0x7d4227c3c4f79de22bbf5b10301d3e99733151de11a2af04ee5d4fe9147fdb94", "price_changes": [{"asset_id": "114175921346199629913576111903487851727201567831569002664280492572302128017807", "price": "0.648", "size": "32", "side": "BUY", "hash": "f2557443c4691391a73165961b767837126b13ec", "best_bid": "0.681", "best_ask": "0.72"}, {"asset_id": "106160144365361466407303030429537634959446638743399742742547862828370756994868", "price": "0.352", "size": "32", "side": "SELL", "hash": "5b5b4e7ba00ec0c4b80ceef21eac32f5789954b5", "best_bid": "0.28", "best_ask": "0.319"}], "timestamp": "1769384033623", "event_type": "price_change"}}
{"_local_timestamp": "2026-01-25T23:33:54.033650+00:00", "data": {"market": "0x7d4227c3c4f79de22bbf5b10301d3e99733151de11a2af04ee5d4fe9147fdb94", "price_changes": [{"asset_id": "114175921346199629913576111903487851727201567831569002664280492572302128017807", "price": "0.649", "size": "50", "side": "BUY", "hash": "7f28ac83c46150d00b9f271041186eb795e32f1d", "best_bid": "0.681", "best_ask": "0.72"}, {"asset_id": "106160144365361466407303030429537634959446638743399742742547862828370756994868", "price": "0.351", "size": "50", "side": "SELL", "hash": "319a1bc724a8513350620fc1d2c16d7b73bf0007", "best_bid": "0.28", "best_ask": "0.319"}], "timestamp": "1769384033966", "event_type": "price_change"}}
{"_local_timestamp": "2026-01-25T23:33:54.142942+00:00", "data": {"market": "0x7130b2c99bee81af658adafb4a6235f21575f568e3ae2a850af742afa50c2d85", "price_changes": [{"asset_id": "17878506599231681723092997062254912120536148530389060800857875232098186845304", "price": "0.823", "size": "50", "side": "BUY", "hash": "3b93cd331e90d6e8b1a1ffe2a68f72ce99f19a97", "best_bid": "0.886", "best_ask": "0.908"}, {"asset_id": "79480641743596328156888881841837787012633513624072222555595000167813156519758", "price": "0.177", "size": "50", "side": "SELL", "hash": "3cc8cbd8e4cc19504d76441a8fdae7316585bb44", "best_bid": "0.092", "best_ask": "0.114"}], "timestamp": "1769384034073", "event_type": "price_change"}}
{"_local_timestamp": "2026-01-25T23:33:54.144635+00:00", "data": {"market": "0x7d4227c3c4f79de22bbf5b10301d3e99733151de11a2af04ee5d4fe9147fdb94", "price_changes": [{"asset_id": "114175921346199629913576111903487851727201567831569002664280492572302128017807", "price": "0.648", "size": "0", "side": "BUY", "hash": "c87208b231945b92b5113b4047a1c26894c487be", "best_bid": "0.681", "best_ask": "0.72"}, {"asset_id": "106160144365361466407303030429537634959446638743399742742547862828370756994868", "price": "0.352", "size": "0", "side": "SELL", "hash": "a41b84a938505c9cc5af4b09b1746a2888826d96", "best_bid": "0.28", "best_ask": "0.319"}], "timestamp": "1769384034073", "event_type": "price_change"}}
{"_local_timestamp": "2026-01-25T23:33:54.158957+00:00", "data": {"market": "0xbbf9e226512452452438571385c111fafd7a581f227d997183b3c0ed0aaa6e94", "price_changes": [{"asset_id": "70641103843303633433849051708048017041225992079285926883062800006960120844878", "price": "0.76", "size": "100", "side": "BUY", "hash": "2695ddf95c717f0fe3c0f79b27f64769e41fc090", "best_bid": "0.77", "best_ask": "0.8"}, {"asset_id": "32365631237478011719581335465835096900088880772439977051943287219696169513404", "price": "0.24", "size": "100", "side": "SELL", "hash": "d5d6f5e4724e243be4a92a85528af067b162df1f", "best_bid": "0.2", "best_ask": "0.23"}], "timestamp": "1769384034082", "event_type": "price_change"}}
{"_local_timestamp": "2026-01-25T23:33:54.162844+00:00", "data": {"market": "0x7d4227c3c4f79de22bbf5b10301d3e99733151de11a2af04ee5d4fe9147fdb94", "price_changes": [{"asset_id": "114175921346199629913576111903487851727201567831569002664280492572302128017807", "price": "0.656", "size": "0", "side": "BUY", "hash": "ed41a385f150ef5a2728e96f97785d334b93eac8", "best_bid": "0.681", "best_ask": "0.72"}, {"asset_id": "106160144365361466407303030429537634959446638743399742742547862828370756994868", "price": "0.344", "size": "0", "side": "SELL", "hash": "a3d03fe8acc26416ca33352f5f4ff91b948002a0", "best_bid": "0.28", "best_ask": "0.319"}], "timestamp": "1769384034085", "event_type": "price_change"}}
{"_local_timestamp": "2026-01-25T23:33:54.165625+00:00", "data": {"market": "0x7130b2c99bee81af658adafb4a6235f21575f568e3ae2a850af742afa50c2d85", "price_changes": [{"asset_id": "17878506599231681723092997062254912120536148530389060800857875232098186845304", "price": "0.822", "size": "0", "side": "BUY", "hash": "6ff32f0c7baa917ce5cf7830160f604c212c9027", "best_bid": "0.886", "best_ask": "0.908"}, {"asset_id": "79480641743596328156888881841837787012633513624072222555595000167813156519758", "price": "0.178", "size": "0", "side": "SELL", "hash": "f583c9a32238071b9b28d112d36d5e0a71b9a13d", "best_bid": "0.092", "best_ask": "0.114"}], "timestamp": "1769384034089", "event_type": "price_change"}}
{"_local_timestamp": "2026-01-25T23:33:54.381857+00:00", "data": {"market": "0x7d4227c3c4f79de22bbf5b10301d3e99733151de11a2af04ee5d4fe9147fdb94", "price_changes": [{"asset_id": "114175921346199629913576111903487851727201567831569002664280492572302128017807", "price": "0.611", "size": "0", "side": "BUY", "hash": "d4992f94dfc838c43997dbea70abd3e347e6da20", "best_bid": "0.681", "best_ask": "0.72"}, {"asset_id": "106160144365361466407303030429537634959446638743399742742547862828370756994868", "price": "0.389", "size": "0", "side": "SELL", "hash": "9417d36d36b62a0a1391a89076211a8f0715744f", "best_bid": "0.28", "best_ask": "0.319"}], "timestamp": "1769384034303", "event_type": "price_change"}}
{"_local_timestamp": "2026-01-25T23:33:54.530319+00:00", "data": {"market": "0x7d4227c3c4f79de22bbf5b10301d3e99733151de11a2af04ee5d4fe9147fdb94", "price_changes": [{"asset_id": "114175921346199629913576111903487851727201567831569002664280492572302128017807", "price": "0.8", "size": "5", "side": "SELL", "hash": "3bebb2a9e4987451dd930bcf0d4739cefdc8b190", "best_bid": "0.681", "best_ask": "0.72"}, {"asset_id": "106160144365361466407303030429537634959446638743399742742547862828370756994868", "price": "0.2", "size": "5", "side": "BUY", "hash": "064b18739b858c42b9063444a6da0c67569e4c0d", "best_bid": "0.28", "best_ask": "0.319"}], "timestamp": "1769384034464", "event_type": "price_change"}}
{"_local_timestamp": "2026-01-25T23:33:54.637832+00:00", "data": {"market": "0x7130b2c99bee81af658adafb4a6235f21575f568e3ae2a850af742afa50c2d85", "price_changes": [{"asset_id": "17878506599231681723092997062254912120536148530389060800857875232098186845304", "price": "0.822", "size": "50", "side": "BUY", "hash": "116b364220ec8b766ddc5ebacc6edb04cce8b066", "best_bid": "0.886", "best_ask": "0.908"}, {"asset_id": "79480641743596328156888881841837787012633513624072222555595000167813156519758", "price": "0.178", "size": "50", "side": "SELL", "hash": "e0a7729f4ab21a10df92dcce550849d09cb75e2b", "best_bid": "0.092", "best_ask": "0.114"}], "timestamp": "1769384034569", "event_type": "price_change"}}
{"_local_timestamp": "2026-01-25T23:33:54.639594+00:00", "data": {"market": "0x7130b2c99bee81af658adafb4a6235f21575f568e3ae2a850af742afa50c2d85", "price_changes": [{"asset_id": "17878506599231681723092997062254912120536148530389060800857875232098186845304", "price": "0.823", "size": "100", "side": "BUY", "hash": "34a26afe8d283534ca5e89702c330cec9351d1d9", "best_bid": "0.886", "best_ask": "0.908"}, {"asset_id": "79480641743596328156888881841837787012633513624072222555595000167813156519758", "price": "0.177", "size": "100", "side": "SELL", "hash": "bf7f2264f00dfb10c6d1597f2436a800585e00f1", "best_bid": "0.092", "best_ask": "0.114"}], "timestamp": "1769384034572", "event_type": "price_change"}}
{"_local_timestamp": "2026-01-25T23:33:54.646866+00:00", "data": {"market": "0x7d4227c3c4f79de22bbf5b10301d3e99733151de11a2af04ee5d4fe9147fdb94", "price_changes": [{"asset_id": "114175921346199629913576111903487851727201567831569002664280492572302128017807", "price": "0.656", "size": "7", "side": "BUY", "hash": "199658d7b50f8b375a6a022b0d6b4ae2309a3d33", "best_bid": "0.681", "best_ask": "0.72"}, {"asset_id": "106160144365361466407303030429537634959446638743399742742547862828370756994868", "price": "0.344", "size": "7", "side": "SELL", "hash": "980fa5afd32487c9aaabdb8d83d5417bef4643cf", "best_bid": "0.28", "best_ask": "0.319"}], "timestamp": "1769384034578", "event_type": "price_change"}}
