{"_local_timestamp": "2026-01-25T23:40:54.984923+00:00", "data": [{"market": "0xb6509995a13af1391202841312769768df5cfdfd81e941a85be235d8fb148248", "asset_id": "59506743557928779608571177404246985081593919356120638521936130122237779605413", "timestamp": "1769384440252", "hash": "a02c42b413237a3580379836609b20f6717e6eb6", "bids": [{"price": "0.01", "size": "180"}, {"price": "0.02", "size": "140"}], "asks": [{"price": "0.99", "size": "3513.26"}, {"price": "0.98", "size": "1400"}, {"price": "0.97", "size": "208.05"}, {"price": "0.96", "size": "250"}, {"price": "0.95", "size": "30"}, {"price": "0.94", "size": "233"}, {"price": "0.93", "size": "8.63"}, {"price": "0.85", "size": "325"}, {"price": "0.84", "size": "450"}, {"price": "0.81", "size": "10"}, {"price": "0.8", "size": "5.1"}, {"price": "0.76", "size": "225"}, {"price": "0.54", "size": "100"}, {"price": "0.38", "size": "100"}, {"price": "0.37", "size": "10"}, {"price": "0.36", "size": "10"}, {"price": "0.35", "size": "20"}, {"price": "0.33", "size": "25"}, {"price": "0.31", "size": "25"}, {"price": "0.1", "size": "50"}, {"price": "0.09", "size": "24.67"}], "event_type": "book", "last_trade_price": "0.060"}, {"market": "0xb2454e9cc596945400864ac06f667af5c13822100e52e90d56f8958bf9975e90", "asset_id": "86490147998839916409987788995385468072126583555463813903067323555322199860102", "timestamp": "1769384362692", "hash": "ba34e547bfb2eb64b5e7f845ab4f329494640b46", "bids": [{"price": "0.01", "size": "1100"}, {"price": "0.02", "size": "400"}, {"price": "0.03", "size": "13.33"}, {"price": "0.06", "size": "1133"}, {"price": "0.09", "size": "377.77"}, {"price": "0.12", "size": "591.66"}, {"price": "0.15", "size": "186.66"}, {"price": "0.18", "size": "144.44"}, {"price": "0.19", "size": "66.66"}, {"price": "0.21", "size": "114.28"}, {"price": "0.22", "size": "57"}, {"price": "0.23", "size": "8.5"}, {"price": "0.24", "size": "83.33"}, {"price": "0.31", "size": "66.66"}, {"price": "0.42", "size": "100"}, {"price": "0.43", "size": "66.66"}], "asks": [{"price": "0.99", "size": "3119.77"}, {"price": "0.98", "size": "1000"}, {"price": "0.97", "size": "11.82"}, {"price": "0.96", "size": "1850"}, {"price": "0.95", "size": "30"}, {"price": "0.94", "size": "566.66"}, {"price": "0.93", "size": "7.48"}, {"price": "0.92", "size": "400"}, {"price": "0.91", "size": "300"}, {"price": "0.9", "size": "380"}, {"price": "0.89", "size": "18"}, {"price": "0.88", "size": "216.66"}, {"price": "0.87", "size": "251.27"}, {"price": "0.86", "size": "6.59"}, {"price": "0.85", "size": "133.33"}, {"price": "0.84", "size": "79"}, {"price": "0.83", "size": "10"}, {"price": "0.78", "size": "66.66"}, {"price": "0.76", "size": "10"}, {"price": "0.75", "size": "20"}, {"price": "0.73", "size": "20"}, {"price": "0.72", "size": "20"}, {"price": "0.71", "size": "8.5"}, {"price": "0.67", "size": "66.66"}], "event_type": "book", "last_trade_price": ""}, {"market": "0xc6d40f33829d2ea23cac35ca87c1f1a0ec084ae675b793bacaf47588abd68af7", "asset_id": "111604871160804053792665137520804934115113332935784329174488506531258467665310", "timestamp": "1769384440252", "hash": "4cf404f439b5147b0048f81d0b28cfebd65164ae", "bids": [{"price": "0.01", "size": "166.66"}, {"price": "0.02", "size": "20"}, {"price": "0.1", "size": "66.66"}, {"price": "0.18", "size": "150"}, {"price": "0.19", "size": "66.66"}], "asks": [{"price": "0.99", "size": "3480.25"}, {"price": "0.98", "size": "1400"}, {"price": "0.97", "size": "6.29"}, {"price": "0.96", "size": "250"}, {"price": "0.95", "size": "30"}, {"price": "0.94", "size": "241.02"}, {"price": "0.89", "size": "620"}, {"price": "0.88", "size": "9.95"}, {"price": "0.81", "size": "250"}, {"price": "0.79", "size": "100"}, {"price": "0.69", "size": "141.66"}, {"price": "0.68", "size": "6"}, {"price": "0.52", "size": "10"}, {"price": "0.51", "size": "20"}, {"price": "0.5", "size": "10"}, {"price": "0.49", "size": "20"}, {"price": "0.48", "size": "20"}, {"price": "0.4", "size": "100"}, {"price": "0.39", "size": "66.66"}, {"price": "0.33", "size": "50"}], "event_type": "book", "last_trade_price": ""}, {"market": "0x486489d4708ad5a43f8de8e0c114a1e136f70384dccfe64370c1d8bc10b93cdb", "asset_id": "56838236357874430791537188558616388556208946622144106414539714148475287541623", "timestamp": "1769384413461", "hash": "b07527341b8aa3a4e86d6c02782cd862e3249ff3", "bids": [{"price": "0.01", "size": "226.96"}], "asks": [{"price": "0.99", "size": "3513.02"}, {"price": "0.98", "size": "1400"}, {"price": "0.97", "size": "207.92"}, {"price": "0.96", "size": "250"}, {"price": "0.95", "size": "30"}, {"price": "0.94", "size": "233"}, {"price": "0.93", "size": "8.55"}, {"price": "0.85", "size": "325"}, {"price": "0.81", "size": "250"}, {"price": "0.8", "size": "5.16"}, {"price": "0.79", "size": "150"}, {"price": "0.78", "size": "9"}, {"price": "0.77", "size": "10"}, {"price": "0.55", "size": "100"}, {"price": "0.4", "size": "100"}, {"price": "0.37", "size": "15"}, {"price": "0.36", "size": "10"}, {"price": "0.35", "size": "20"}, {"price": "0.31", "size": "25"}, {"price": "0.3", "size": "25"}, {"price": "0.12", "size": "6"}, {"price": "0.11", "size": "50"}], "event_type": "book", "last_trade_price": ""}, {"market": "0xc6d40f33829d2ea23cac35ca87c1f1a0ec084ae675b793bacaf47588abd68af7", "asset_id": "49872171312816848131376503230796566946171252643195539532075216530371086282173", "timestamp": "1769384440252", "hash": "2c906c9fb9c195438620850c5ec540c8ae599903", "bids": [{"price": "0.01", "size": "3480.25"}, {"price": "0.02", "size": "1400"}, {"price": "0.03", "size": "6.29"}, {"price": "0.04", "size": "250"}, {"price": "0.05", "size": "30"}, {"price": "0.06", "size": "241.02"}, {"price": "0.11", "size": "620"}, {"price": "0.12", "size": "9.95"}, {"price": "0.19", "size": "250"}, {"price": "0.21", "size": "100"}, {"price": "0.31", "size": "141.66"}, {"price": "0.32", "size": "6"}, {"price": "0.48", "size": "10"}, {"price": "0.49", "size": "20"}, {"price": "0.5", "size": "10"}, {"price": "0.51", "size": "20"}, {"price": "0.52", "size": "20"}, {"price": "0.6", "size": "100"}, {"price": "0.61", "size": "66.66"}, {"price": "0.67", "size": "50"}], "asks": [{"price": "0.99", "size": "166.66"}, {"price": "0.98", "size": "20"}, {"price": "0.9", "size": "66.66"}, {"price": "0.82", "size": "150"}, {"price": "0.81", "size": "66.66"}], "event_type": "book", "last_trade_price": ""}, {"market": "0xb2454e9cc596945400864ac06f667af5c13822100e52e90d56f8958bf9975e90", "asset_id": "114052061120418968776706506466935854651907852664788849843223384815399545148233", "timestamp": "1769384362692", "hash": "d049d0ef81ad22e6d26bdb1d591f13dd014765d2", "bids": [{"price": "0.01", "size": "3119.77"}, {"price": "0.02", "size": "1000"}, {"price": "0.03", "size": "11.82"}, {"price": "0.04", "size": "1850"}, {"price": "0.05", "size": "30"}, {"price": "0.06", "size": "566.66"}, {"price": "0.07", "size": "7.48"}, {"price": "0.08", "size": "400"}, {"price": "0.09", "size": "300"}, {"price": "0.1", "size": "380"}, {"price": "0.11", "size": "18"}, {"price": "0.12", "size": "216.66"}, {"price": "0.13", "size": "251.27"}, {"price": "0.14", "size": "6.59"}, {"price": "0.15", "size": "133.33"}, {"price": "0.16", "size": "79"}, {"price": "0.17", "size": "10"}, {"price": "0.22", "size": "66.66"}, {"price": "0.24", "size": "10"}, {"price": "0.25", "size": "20"}, {"price": "0.27", "size": "20"}, {"price": "0.28", "size": "20"}, {"price": "0.29", "size": "8.5"}, {"price": "0.33", "size": "66.66"}], "asks": [{"price": "0.99", "size": "1100"}, {"price": "0.98", "size": "400"}, {"price": "0.97", "size": "13.33"}, {"price": "0.94", "size": "1133"}, {"price": "0.91", "size": "377.77"}, {"price": "0.88", "size": "591.66"}, {"price": "0.85", "size": "186.66"}, {"price": "0.82", "size": "144.44"}, {"price": "0.81", "size": "66.66"}, {"price": "0.79", "size": "114.28"}, {"price": "0.78", "size": "57"}, {"price": "0.77", "size": "8.5"}, {"price": "0.76", "size": "83.33"}, {"price": "0.69", "size": "66.66"}, {"price": "0.58", "size": "100"}, {"price": "0.57", "size": "66.66"}], "event_type": "book", "last_trade_price": ""}, {"market": "0x486489d4708ad5a43f8de8e0c114a1e136f70384dccfe64370c1d8bc10b93cdb", "asset_id": "4276217737744301565675595183887401382782581341383125250557157305669874015276", "timestamp": "1769384413461", "hash": "80aad1cfc5d7b5b6dc19cf8a801cd89a8b930a0e", "bids": [{"price": "0.01", "size": "3513.02"}, {"price": "0.02", "size": "1400"}, {"price": "0.03", "size": "207.92"}, {"price": "0.04", "size": "250"}, {"price": "0.05", "size": "30"}, {"price": "0.06", "size": "233"}, {"price": "0.07", "size": "8.55"}, {"price": "0.15", "size": "325"}, {"price": "0.19", "size": "250"}, {"price": "0.2", "size": "5.16"}, {"price": "0.21", "size": "150"}, {"price": "0.22", "size": "9"}, {"price": "0.23", "size": "10"}, {"price": "0.45", "size": "100"}, {"price": "0.6", "size": "100"}, {"price": "0.63", "size": "15"}, {"price": "0.64", "size": "10"}, {"price": "0.65", "size": "20"}, {"price": "0.69", "size": "25"}, {"price": "0.7", "size": "25"}, {"price": "0.88", "size": "6"}, {"price": "0.89", "size": "50"}], "asks": [{"price": "0.99", "size": "226.96"}], "event_type": "book", "last_trade_price": ""}, {"market": "0x37be51a4497a9ae96dcb5610cb7f26e24a1e633fdd7860b910a3d675d1e14ab0", "asset_id": "79076673506907717638765187843939471964492280241073125714298327262170536871810", "timestamp": "1769384440450", "hash": "0ded1ff33968ec53b349b5dadf14bebfa58e377d", "bids": [{"price": "0.01", "size": "179.13"}, {"price": "0.02", "size": "100"}, {"price": "0.03", "size": "9.17"}, {"price": "0.04", "size": "78.66"}, {"price": "0.05", "size": "20"}, {"price": "0.09", "size": "77.76"}], "asks": [{"price": "0.99", "size": "3480.61"}, {"price": "0.98", "size": "1400"}, {"price": "0.97", "size": "306.46"}, {"price": "0.96", "size": "250"}, {"price": "0.95", "size": "30"}, {"price": "0.94", "size": "233"}, {"price": "0.93", "size": "7.61"}, {"price": "0.89", "size": "325"}, {"price": "0.84", "size": "250"}, {"price": "0.83", "size": "6.66"}, {"price": "0.7", "size": "300"}, {"price": "0.69", "size": "141.66"}, {"price": "0.68", "size": "6"}, {"price": "0.67", "size": "95"}, {"price": "0.65", "size": "20"}, {"price": "0.64", "size": "20"}, {"price": "0.4", "size": "100"}, {"price": "0.39", "size": "25"}, {"price": "0.38", "size": "72"}, {"price": "0.37", "size": "66.66"}], "event_type": "book", "last_trade_price": ""}, {"market": "0xb6509995a13af1391202841312769768df5cfdfd81e941a85be235d8fb148248", "asset_id": "61293388742692902172483944971273981064818704065183312737680051681028772972191", "timestamp": "1769384440252", "hash": "6f6f37e5a2584008d6f4feaae20b9236418c62b5", "bids": [{"price": "0.01", "size": "3513.26"}, {"price": "0.02", "size": "1400"}, {"price": "0.03", "size": "208.05"}, {"price": "0.04", "size": "250"}, {"price": "0.05", "size": "30"}, {"price": "0.06", "size": "233"}, {"price": "0.07", "size": "8.63"}, {"price": "0.15", "size": "325"}, {"price": "0.16", "size": "450"}, {"price": "0.19", "size": "10"}, {"price": "0.2", "size": "5.1"}, {"price": "0.24", "size": "225"}, {"price": "0.46", "size": "100"}, {"price": "0.62", "size": "100"}, {"price": "0.63", "size": "10"}, {"price": "0.64", "size": "10"}, {"price": "0.65", "size": "20"}, {"price": "0.67", "size": "25"}, {"price": "0.69", "size": "25"}, {"price": "0.9", "size": "50"}, {"price": "0.91", "size": "24.67"}], "asks": [{"price": "0.99", "size": "180"}, {"price": "0.98", "size": "140"}], "event_type": "book", "last_trade_price": "0.060"}, {"market": "0x37be51a4497a9ae96dcb5610cb7f26e24a1e633fdd7860b910a3d675d1e14ab0", "asset_id": "22009953520357011584148547274963289285204304765324187781336259113331278150470", "timestamp": "1769384440450", "hash": "c1100a3ac98925ac51c308cdc8bb9c97cd4691d8", "bids": [{"price": "0.01", "size": "3480.61"}, {"price": "0.02", "size": "1400"}, {"price": "0.03", "size": "306.46"}, {"price": "0.04", "size": "250"}, {"price": "0.05", "size": "30"}, {"price": "0.06", "size": "233"}, {"price": "0.07", "size": "7.61"}, {"price": "0.11", "size": "325"}, {"price": "0.16", "size": "250"}, {"price": "0.17", "size": "6.66"}, {"price": "0.3", "size": "300"}, {"price": "0.31", "size": "141.66"}, {"price": "0.32", "size": "6"}, {"price": "0.33", "size": "95"}, {"price": "0.35", "size": "20"}, {"price": "0.36", "size": "20"}, {"price": "0.6", "size": "100"}, {"price": "0.61", "size": "25"}, {"price": "0.62", "size": "72"}, {"price": "0.63", "size": "66.66"}], "asks": [{"price": "0.99", "size": "179.13"}, {"price": "0.98", "size": "100"}, {"price": "0.97", "size": "9.17"}, {"price": "0.96", "size": "78.66"}, {"price": "0.95", "size": "20"}, {"price": "0.91", "size": "77.76"}], "event_type": "book", "last_trade_price": ""}]}
{"_local_timestamp": "2026-01-25T23:40:59.179370+00:00", "data": {"market": "0xb2454e9cc596945400864ac06f667af5c13822100e52e90d56f8958bf9975e90", "price_changes": [{"asset_id": "114052061120418968776706506466935854651907852664788849843223384815399545148233", "price": "0.01", "size": "2119.77", "side": "BUY", "hash": "bef7f08e5816476c64fd7038a477335659047d4f", "best_bid": "0.33", "best_ask": "0.57"}, {"asset_id": "86490147998839916409987788995385468072126583555463813903067323555322199860102", "price": "0.99", "size": "2119.77", "side": "SELL", "hash": "39a97a50836d42ff5956ccbc8d5e13623b1e3fd9", "best_bid": "0.43", "best_ask": "0.67"}], "timestamp": "1769384459094", "event_type": "price_change"}}
{"_local_timestamp": "2026-01-25T23:40:59.180840+00:00", "data": {"market": "0xb2454e9cc596945400864ac06f667af5c13822100e52e90d56f8958bf9975e90", "price_changes": [{"asset_id": "114052061120418968776706506466935854651907852664788849843223384815399545148233", "price": "0.04", "size": "1450", "side": "BUY", "hash": "bef7f08e5816476c64fd7038a477335659047d4f", "best_bid": "0.33", "best_ask": "0.57"}, {"asset_id": "86490147998839916409987788995385468072126583555463813903067323555322199860102", "price": "0.96", "size": "1450", "side": "SELL", "hash": "39a97a50836d42ff5956ccbc8d5e13623b1e3fd9", "best_bid": "0.43", "best_ask": "0.67"}], "timestamp": "1769384459094", "event_type": "price_change"}}
{"_local_timestamp": "2026-01-25T23:41:19.366774+00:00", "data": {"market": "0xc6d40f33829d2ea23cac35ca87c1f1a0ec084ae675b793bacaf47588abd68af7", "price_changes": [{"asset_id": "49872171312816848131376503230796566946171252643195539532075216530371086282173", "price": "0.61", "size": "0", "side": "BUY", "hash": "570b95a73f610b6fea17331593c3a1f8b813dd7f", "best_bid": "0.67", "best_ask": "0.81"}, {"asset_id": "111604871160804053792665137520804934115113332935784329174488506531258467665310", "price": "0.39", "size": "0", "side": "SELL", "hash": "7c23fa4065bc3a112f8889b13bfae9be8153dd42", "best_bid": "0.19", "best_ask": "0.33"}], "timestamp": "1769384479225", "event_type": "price_change"}}
{"_local_timestamp": "2026-01-25T23:41:19.372243+00:00", "data": {"market": "0xb2454e9cc596945400864ac06f667af5c13822100e52e90d56f8958bf9975e90", "price_changes": [{"asset_id": "114052061120418968776706506466935854651907852664788849843223384815399545148233", "price": "0.33", "size": "0", "side": "BUY", "hash": "4b40d96eb4d43ab5f9d5fb0b3c3de8b4db054cea", "best_bid": "0.29", "best_ask": "0.57"}, {"asset_id": "86490147998839916409987788995385468072126583555463813903067323555322199860102", "price": "0.67", "size": "0", "side": "SELL", "hash": "1b1e5fc3535900a0d25c3899dfdb7df1868e8b83", "best_bid": "0.43", "best_ask": "0.71"}], "timestamp": "1769384479226", "event_type": "price_change"}}
{"_local_timestamp": "2026-01-25T23:41:19.465461+00:00", "data": {"market": "0x37be51a4497a9ae96dcb5610cb7f26e24a1e633fdd7860b910a3d675d1e14ab0", "price_changes": [{"asset_id": "22009953520357011584148547274963289285204304765324187781336259113331278150470", "price": "0.35", "size": "0", "side": "BUY", "hash": "bc6550e89ab565a1a0f1ccd2ab7182992d8da0c6", "best_bid": "0.63", "best_ask": "0.91"}, {"asset_id": "79076673506907717638765187843939471964492280241073125714298327262170536871810", "price": "0.65", "size": "0", "side": "SELL", "hash": "90038952a58c39cf9a471e1f03776a12bc7402f8", "best_bid": "0.09", "best_ask": "0.37"}], "timestamp": "1769384479392", "event_type": "price_change"}}
{"_local_timestamp": "2026-01-25T23:41:19.852928+00:00", "data": {"market": "0xc6d40f33829d2ea23cac35ca87c1f1a0ec084ae675b793bacaf47588abd68af7", "price_changes": [{"asset_id": "49872171312816848131376503230796566946171252643195539532075216530371086282173", "price": "0.68", "size": "66.66", "side": "BUY", "hash": "0e667499a658b6d126cb5036a668928219e3271f", "best_bid": "0.68", "best_ask": "0.81"}, {"asset_id": "111604871160804053792665137520804934115113332935784329174488506531258467665310", "price": "0.32", "size": "66.66", "side": "SELL", "hash": "a79c66d11f8d8e6012ce9d43138d271993bfb10f", "best_bid": "0.19", "best_ask": "0.32"}], "timestamp": "1769384479770", "event_type": "price_change"}}
{"_local_timestamp": "2026-01-25T23:41:19.969076+00:00", "data": {"market": "0x486489d4708ad5a43f8de8e0c114a1e136f70384dccfe64370c1d8bc10b93cdb", "price_changes": [{"asset_id": "4276217737744301565675595183887401382782581341383125250557157305669874015276", "price": "0.64", "size": "0", "side": "BUY", "hash": "3ff32412d7d5a266eb97f25567bc9309ee77c8dc", "best_bid": "0.89", "best_ask": "0.99"}, {"asset_id": "56838236357874430791537188558616388556208946622144106414539714148475287541623", "price": "0.36", "size": "0", "side": "SELL", "hash": "1b53f0ace6c7eec7fb89e4dd63a0d2fcf84e3775", "best_bid": "0.01", "best_ask": "0.11"}], "timestamp": "1769384479901", "event_type": "price_change"}}
{"_local_timestamp": "2026-01-25T23:41:19.989010+00:00", "data": {"market": "0x37be51a4497a9ae96dcb5610cb7f26e24a1e633fdd7860b910a3d675d1e14ab0", "price_changes": [{"asset_id": "22009953520357011584148547274963289285204304765324187781336259113331278150470", "price": "0.36", "size": "0", "side": "BUY", "hash": "69c7e30d1579f16520534021f34ef1e1bfe98f42", "best_bid": "0.63", "best_ask": "0.91"}, {"asset_id": "79076673506907717638765187843939471964492280241073125714298327262170536871810", "price": "0.64", "size": "0", "side": "SELL", "hash": "6384bd90292b4aa6a82109860ba61cb233636a06", "best_bid": "0.09", "best_ask": "0.37"}], "timestamp": "1769384479913", "event_type": "price_change"}}
{"_local_timestamp": "2026-01-25T23:41:20.008582+00:00", "data": {"market": "0x37be51a4497a9ae96dcb5610cb7f26e24a1e633fdd7860b910a3d675d1e14ab0", "price_changes": [{"asset_id": "22009953520357011584148547274963289285204304765324187781336259113331278150470", "price": "0.37", "size": "5", "side": "BUY", "hash": "c12a140e0c7773d99f86ce6bb508403834fdd460", "best_bid": "0.63", "best_ask": "0.91"}, {"asset_id": "79076673506907717638765187843939471964492280241073125714298327262170536871810", "price": "0.63", "size": "5", "side": "SELL", "hash": "fd2671ae293d86a597e628970e90f6c07bba20f9", "best_bid": "0.09", "best_ask": "0.37"}], "timestamp": "1769384479939", "event_type": "price_change"}}
{"_local_timestamp": "2026-01-25T23:41:20.010018+00:00", "data": {"market": "0x37be51a4497a9ae96dcb5610cb7f26e24a1e633fdd7860b910a3d675d1e14ab0", "price_changes": [{"asset_id": "22009953520357011584148547274963289285204304765324187781336259113331278150470", "price": "0.61", "size": "45", "side": "BUY", "hash": "97819d4d729d212ce36f12ebd0a2fb28ec7a6888", "best_bid": "0.63", "best_ask": "0.91"}, {"asset_id": "79076673506907717638765187843939471964492280241073125714298327262170536871810", "price": "0.39", "size": "45", "side": "SELL", "hash": "cf55ba002f2551b83f3537654c555e2ee33b51b4", "best_bid": "0.09", "best_ask": "0.37"}], "timestamp": "1769384479940", "event_type": "price_change"}}
{"_local_timestamp": "2026-01-25T23:41:20.010365+00:00", "data": {"market": "0x37be51a4497a9ae96dcb5610cb7f26e24a1e633fdd7860b910a3d675d1e14ab0", "price_changes": [{"asset_id": "22009953520357011584148547274963289285204304765324187781336259113331278150470", "price": "0.34", "size": "20", "side": "BUY", "hash": "558733327ee68dd175fba0e7b0a26823db54a0aa", "best_bid": "0.63", "best_ask": "0.91"}, {"asset_id": "79076673506907717638765187843939471964492280241073125714298327262170536871810", "price": "0.66", "size": "20", "side": "SELL", "hash": "361763efd24c555340ba8ede583c269e9b5b03c5", "best_bid": "0.09", "best_ask": "0.37"}], "timestamp": "1769384479941", "event_type": "price_change"}}
{"_local_timestamp": "2026-01-25T23:41:20.157331+00:00", "data": {"market": "0xb2454e9cc596945400864ac06f667af5c13822100e52e90d56f8958bf9975e90", "price_changes": [{"asset_id": "114052061120418968776706506466935854651907852664788849843223384815399545148233", "price": "0.3", "size": "66.66", "side": "BUY", "hash": "58e24911a029c7cb4c576266d565932d0c5f01a5", "best_bid": "0.3", "best_ask": "0.57"}, {"asset_id": "86490147998839916409987788995385468072126583555463813903067323555322199860102", "price": "0.7", "size": "66.66", "side": "SELL", "hash": "b0e96c452b177328d2d0403b3e879a1318c012e6", "best_bid": "0.43", "best_ask": "0.7"}], "timestamp": "1769384480075", "event_type": "price_change"}}
{"_local_timestamp": "2026-01-25T23:41:20.485821+00:00", "data": {"market": "0x37be51a4497a9ae96dcb5610cb7f26e24a1e633fdd7860b910a3d675d1e14ab0", "price_changes": [{"asset_id": "22009953520357011584148547274963289285204304765324187781336259113331278150470", "price": "0.61", "size": "25", "side": "BUY", "hash": "307c05b514d1031d064720f1a99c8994c1cd9e8e", "best_bid": "0.63", "best_ask": "0.91"}, {"asset_id": "79076673506907717638765187843939471964492280241073125714298327262170536871810", "price": "0.39", "size": "25", "side": "SELL", "hash": "6185273aedf134181ffc65b721d263cca88d6cef", "best_bid": "0.09", "best_ask": "0.37"}], "timestamp": "1769384480411", "event_type": "price_change"}}
{"_local_timestamp": "2026-01-25T23:41:20.814365+00:00", "data": {"market": "0x486489d4708ad5a43f8de8e0c114a1e136f70384dccfe64370c1d8bc10b93cdb", "price_changes": [{"asset_id": "4276217737744301565675595183887401382782581341383125250557157305669874015276", "price": "0.65", "size": "0", "side": "BUY", "hash": "076f5732e891b0db05d73513bce2d14a4d211d59", "best_bid": "0.89", "best_ask": "0.99"}, {"asset_id": "56838236357874430791537188558616388556208946622144106414539714148475287541623", "price": "0.35", "size": "0", "side": "SELL", "hash": "bcb0fc3b479a5bff857eb2b825f98a90f6ded81a", "best_bid": "0.01", "best_ask": "0.11"}], "timestamp": "1769384480748", "event_type": "price_change"}}
{"_local_timestamp": "2026-01-25T23:41:20.846433+00:00", "data": {"market": "0x486489d4708ad5a43f8de8e0c114a1e136f70384dccfe64370c1d8bc10b93cdb", "price_changes": [{"asset_id": "4276217737744301565675595183887401382782581341383125250557157305669874015276", "price": "0.64", "size": "20", "side": "BUY", "hash": "c416a8a0354158e8e8a94aba485917ed450efd01", "best_bid": "0.89", "best_ask": "0.99"}, {"asset_id": "56838236357874430791537188558616388556208946622144106414539714148475287541623", "price": "0.36", "size": "20", "side": "SELL", "hash": "8d1d47a5c362de0fd076eef1da496cde8042465a", "best_bid": "0.01", "best_ask": "0.11"}], "timestamp": "1769384480776", "event_type": "price_change"}}
{"_local_timestamp": "2026-01-25T23:41:20.990083+00:00", "data": {"market": "0x486489d4708ad5a43f8de8e0c114a1e136f70384dccfe64370c1d8bc10b93cdb", "price_changes": [{"asset_id": "4276217737744301565675595183887401382782581341383125250557157305669874015276", "price": "0.63", "size": "0", "side": "BUY", "hash": "2dd7e809d13b777008711e296f92a536ae46cabf", "best_bid": "0.89", "best_ask": "0.99"}, {"asset_id": "56838236357874430791537188558616388556208946622144106414539714148475287541623", "price": "0.37", "size": "0", "side": "SELL", "hash": "2f3189755c2365048d04ecfbc5fc32a4e0e85772", "best_bid": "0.01", "best_ask": "0.11"}], "timestamp": "1769384480921", "event_type": "price_change"}}
{"_local_timestamp": "2026-01-25T23:41:22.307971+00:00", "data": {"market": "0xb2454e9cc596945400864ac06f667af5c13822100e52e90d56f8958bf9975e90", "price_changes": [{"asset_id": "114052061120418968776706506466935854651907852664788849843223384815399545148233", "price": "0.3", "size": "116.66", "side": "BUY", "hash": "2661ee67e016f573bbe8d190d189c7b57ac12d47", "best_bid": "0.3", "best_ask": "0.57"}, {"asset_id": "86490147998839916409987788995385468072126583555463813903067323555322199860102", "price": "0.7", "size": "116.66", "side": "SELL", "hash": "7e66017dfc3299840a351be4dd1da05190b04615", "best_bid": "0.43", "best_ask": "0.7"}], "timestamp": "1769384482241", "event_type": "price_change"}}
{"_local_timestamp": "2026-01-25T23:41:22.323163+00:00", "data": {"market": "0x486489d4708ad5a43f8de8e0c114a1e136f70384dccfe64370c1d8bc10b93cdb", "price_changes": [{"asset_id": "4276217737744301565675595183887401382782581341383125250557157305669874015276", "price": "0.64", "size": "0", "side": "BUY", "hash": "dc9b29dc416d3d930dd2475069a68bbb727a7dcc", "best_bid": "0.89", "best_ask": "0.99"}, {"asset_id": "56838236357874430791537188558616388556208946622144106414539714148475287541623", "price": "0.36", "size": "0", "side": "SELL", "hash": "020d39b7d9d1152bf3646e7c7c5680d4a597a51d", "best_bid": "0.01", "best_ask": "0.11"}], "timestamp": "1769384482257", "event_type": "price_change"}}
{"_local_timestamp": "2026-01-25T23:41:22.359585+00:00", "data": {"market": "0x486489d4708ad5a43f8de8e0c114a1e136f70384dccfe64370c1d8bc10b93cdb", "price_changes": [{"asset_id": "4276217737744301565675595183887401382782581341383125250557157305669874015276", "price": "0.61", "size": "20", "side": "BUY", "hash": "d788abb302b921ea131fbbce5e292dbebea56d6a", "best_bid": "0.89", "best_ask": "0.99"}, {"asset_id": "56838236357874430791537188558616388556208946622144106414539714148475287541623", "price": "0.39", "size": "20", "side": "SELL", "hash": "87b8646751f476b8842fe52c9ef2d7c9c7dc6215", "best_bid": "0.01", "best_ask": "0.11"}], "timestamp": "1769384482285", "event_type": "price_change"}}
{"_local_timestamp": "2026-01-25T23:41:22.407316+00:00", "data": {"market": "0x486489d4708ad5a43f8de8e0c114a1e136f70384dccfe64370c1d8bc10b93cdb", "price_changes": [{"asset_id": "4276217737744301565675595183887401382782581341383125250557157305669874015276", "price": "0.61", "size": "30", "side": "BUY", "hash": "e1bafa29111a6140a674e90d8f957d53fc8e8b37", "best_bid": "0.89", "best_ask": "0.99"}, {"asset_id": "56838236357874430791537188558616388556208946622144106414539714148475287541623", "price": "0.39", "size": "30", "side": "SELL", "hash": "e0f9cb249aa83de14f18bd9fb95448a2686f8132", "best_bid": "0.01", "best_ask": "0.11"}], "timestamp": "1769384482342", "event_type": "price_change"}}
{"_local_timestamp": "2026-01-25T23:41:22.408905+00:00", "data": {"market": "0x486489d4708ad5a43f8de8e0c114a1e136f70384dccfe64370c1d8bc10b93cdb", "price_changes": [{"asset_id": "4276217737744301565675595183887401382782581341383125250557157305669874015276", "price": "0.61", "size": "45", "side": "BUY", "hash": "e5d11ece9e07e37c927f3765e9cd9a29d9af85d1", "best_bid": "0.89", "best_ask": "0.99"}, {"asset_id": "56838236357874430791537188558616388556208946622144106414539714148475287541623", "price": "0.39", "size": "45", "side": "SELL", "hash": "4678d8ab01619ad79415b7b16c742d715780bc46", "best_bid": "0.01", "best_ask": "0.11"}], "timestamp": "1769384482343", "event_type": "price_change"}}
{"_local_timestamp": "2026-01-25T23:41:22.469353+00:00", "data": {"market": "0xb2454e9cc596945400864ac06f667af5c13822100e52e90d56f8958bf9975e90", "price_changes": [{"asset_id": "114052061120418968776706506466935854651907852664788849843223384815399545148233", "price": "0.28", "size": "0", "side": "BUY", "hash": "702cfc1a2aa7adea41f65db9025bde7f4aa0e70f", "best_bid": "0.3", "best_ask": "0.57"}, {"asset_id": "86490147998839916409987788995385468072126583555463813903067323555322199860102", "price": "0.72", "size": "0", "side": "SELL", "hash": "3d5be5a0db3d8e17920d98637cf437c8ce16e1e8", "best_bid": "0.43", "best_ask": "0.7"}], "timestamp": "1769384482404", "event_type": "price_change"}}
{"_local_timestamp": "2026-01-25T23:41:22.644404+00:00", "data": {"market": "0xb2454e9cc596945400864ac06f667af5c13822100e52e90d56f8958bf9975e90", "price_changes": [{"asset_id": "114052061120418968776706506466935854651907852664788849843223384815399545148233", "price": "0.26", "size": "20", "side": "BUY", "hash": "5da0c84add5a7feefc46da5e7c13172beccb0a11", "best_bid": "0.3", "best_ask": "0.57"}, {"asset_id": "86490147998839916409987788995385468072126583555463813903067323555322199860102", "price": "0.74", "size": "20", "side": "SELL", "hash": "dc7679e0ee6944a2efabaef8c3c6d8b5414b0f6b", "best_bid": "0.43", "best_ask": "0.7"}], "timestamp": "1769384482566", "event_type": "price_change"}}
{"_local_timestamp": "2026-01-25T23:41:22.947764+00:00", "data": {"market": "0x486489d4708ad5a43f8de8e0c114a1e136f70384dccfe64370c1d8bc10b93cdb", "price_changes": [{"asset_id": "4276217737744301565675595183887401382782581341383125250557157305669874015276", "price": "0.61", "size": "25", "side": "BUY", "hash": "301d391bdb0f7113073a13c44a6b84d1010f41d8", "best_bid": "0.89", "best_ask": "0.99"}, {"asset_id": "56838236357874430791537188558616388556208946622144106414539714148475287541623", "price": "0.39", "size": "25", "side": "SELL", "hash": "f775dcba1227304a395de022d3430afb05edf659", "best_bid": "0.01", "best_ask": "0.11"}], "timestamp": "1769384482880", "event_type": "price_change"}}
{"_local_timestamp": "2026-01-25T23:41:22.965917+00:00", "data": {"market": "0x37be51a4497a9ae96dcb5610cb7f26e24a1e633fdd7860b910a3d675d1e14ab0", "price_changes": [{"asset_id": "22009953520357011584148547274963289285204304765324187781336259113331278150470", "price": "0.64", "size": "20", "side": "BUY", "hash": "b57584acb1a53612bd10ad7c361ffd7f29bd55aa", "best_bid": "0.64", "best_ask": "0.91"}, {"asset_id": "79076673506907717638765187843939471964492280241073125714298327262170536871810", "price": "0.36", "size": "20", "side": "SELL", "hash": "240b7a6c0f76344c3197d27f95002dc87e4bb726", "best_bid": "0.09", "best_ask": "0.36"}], "timestamp": "1769384482901", "event_type": "price_change"}}
{"_local_timestamp": "2026-01-25T23:41:22.972752+00:00", "data": {"market": "0x486489d4708ad5a43f8de8e0c114a1e136f70384dccfe64370c1d8bc10b93cdb", "price_changes": [{"asset_id": "4276217737744301565675595183887401382782581341383125250557157305669874015276", "price": "0.62", "size": "20", "side": "BUY", "hash": "0200860b43e54d8ddfb1f010698c83adcf4ce394", "best_bid": "0.89", "best_ask": "0.99"}, {"asset_id": "56838236357874430791537188558616388556208946622144106414539714148475287541623", "price": "0.38", "size": "20", "side": "SELL", "hash": "306d32e81d19f3fcc147c3a98add5cb7b23f38f7", "best_bid": "0.01", "best_ask": "0.11"}], "timestamp": "1769384482910", "event_type": "price_change"}}
{"_local_timestamp": "2026-01-25T23:41:23.180022+00:00", "data": {"market": "0x37be51a4497a9ae96dcb5610cb7f26e24a1e633fdd7860b910a3d675d1e14ab0", "price_changes": [{"asset_id": "22009953520357011584148547274963289285204304765324187781336259113331278150470", "price": "0.61", "size": "0", "side": "BUY", "hash": "71f4db61a4343f45152420e87c7d7fc1185b109f", "best_bid": "0.64", "best_ask": "0.91"}, {"asset_id": "79076673506907717638765187843939471964492280241073125714298327262170536871810", "price": "0.39", "size": "0", "side": "SELL", "hash": "5f5dd569351e60e7c21aad715fef52a3e8f9db57", "best_bid": "0.09", "best_ask": "0.36"}], "timestamp": "1769384483092", "event_type": "price_change"}}
{"_local_timestamp": "2026-01-25T23:41:23.344927+00:00", "data": {"market": "0x37be51a4497a9ae96dcb5610cb7f26e24a1e633fdd7860b910a3d675d1e14ab0", "price_changes": [{"asset_id": "22009953520357011584148547274963289285204304765324187781336259113331278150470", "price": "0.38", "size": "25", "side": "BUY", "hash": "76291b3cc5ee9a95890a67a3302f7efb4b9bb4db", "best_bid": "0.64", "best_ask": "0.91"}, {"asset_id": "79076673506907717638765187843939471964492280241073125714298327262170536871810", "price": "0.62", "size": "25", "side": "SELL", "hash": "6c4d3a62e448968fa0f5cbdb4fa6dbfe50196ed2", "best_bid": "0.09", "best_ask": "0.36"}], "timestamp": "1769384483279", "event_type": "price_change"}}
{"_local_timestamp": "2026-01-25T23:41:23.813459+00:00", "data": {"market": "0x37be51a4497a9ae96dcb5610cb7f26e24a1e633fdd7860b910a3d675d1e14ab0", "price_changes": [{"asset_id": "22009953520357011584148547274963289285204304765324187781336259113331278150470", "price": "0.34", "size": "0", "side": "BUY", "hash": "09774f002ddc0672482f41b9f47023aa46ddab0c", "best_bid": "0.64", "best_ask": "0.91"}, {"asset_id": "79076673506907717638765187843939471964492280241073125714298327262170536871810", "price": "0.66", "size": "0", "side": "SELL", "hash": "a7b1a0d8a250ee265d177607a587bce78a90fdd7", "best_bid": "0.09", "best_ask": "0.36"}], "timestamp": "1769384483735", "event_type": "price_change"}}
{"_local_timestamp": "2026-01-25T23:41:23.836219+00:00", "data": {"market": "0x37be51a4497a9ae96dcb5610cb7f26e24a1e633fdd7860b910a3d675d1e14ab0", "price_changes": [{"asset_id": "22009953520357011584148547274963289285204304765324187781336259113331278150470", "price": "0.39", "size": "20", "side": "BUY", "hash": "5715067479010fe530f001e2d8d4e01adadde672", "best_bid": "0.64", "best_ask": "0.91"}, {"asset_id": "79076673506907717638765187843939471964492280241073125714298327262170536871810", "price": "0.61", "size": "20", "side": "SELL", "hash": "cddd2e2de16e0ef58f7740b5b3145ca196ec8301", "best_bid": "0.09", "best_ask": "0.36"}], "timestamp": "1769384483767", "event_type": "price_change"}}
{"_local_timestamp": "2026-01-25T23:41:23.853229+00:00", "data": {"market": "0xb2454e9cc596945400864ac06f667af5c13822100e52e90d56f8958bf9975e90", "price_changes": [{"asset_id": "114052061120418968776706506466935854651907852664788849843223384815399545148233", "price": "0.3", "size": "136.66", "side": "BUY", "hash": "6c260c31e89e07c8e7ed9e5ea72656f6c9bbb084", "best_bid": "0.3", "best_ask": "0.57"}, {"asset_id": "86490147998839916409987788995385468072126583555463813903067323555322199860102", "price": "0.7", "size": "136.66", "side": "SELL", "hash": "ab60a70d014a79420d364792fef56ebb1415ca47", "best_bid": "0.43", "best_ask": "0.7"}], "timestamp": "1769384483787", "event_type": "price_change"}}
{"_local_timestamp": "2026-01-25T23:41:36.877393+00:00", "data": {"market": "0x37be51a4497a9ae96dcb5610cb7f26e24a1e633fdd7860b910a3d675d1e14ab0", "price_changes": [{"asset_id": "22009953520357011584148547274963289285204304765324187781336259113331278150470", "price": "0.62", "size": "25", "side": "BUY", "hash": "bd37c4fb26cb6c345ffe4c71a6e876630a5314d3", "best_bid": "0.64", "best_ask": "0.91"}, {"asset_id": "79076673506907717638765187843939471964492280241073125714298327262170536871810", "price": "0.38", "size": "25", "side": "SELL", "hash": "08ab6431ca52520589acd0d3166e2356140ec4e6", "best_bid": "0.09", "best_ask": "0.36"}], "timestamp": "1769384496810", "event_type": "price_change"}}
{"_local_timestamp": "2026-01-25T23:41:37.019537+00:00", "data": {"market": "0x37be51a4497a9ae96dcb5610cb7f26e24a1e633fdd7860b910a3d675d1e14ab0", "price_changes": [{"asset_id": "22009953520357011584148547274963289285204304765324187781336259113331278150470", "price": "0.33", "size": "75", "side": "BUY", "hash": "f8347ae7b43276ec8af629711a7a142b77a7871f", "best_bid": "0.64", "best_ask": "0.91"}, {"asset_id": "79076673506907717638765187843939471964492280241073125714298327262170536871810", "price": "0.67", "size": "75", "side": "SELL", "hash": "9dbf82e1d0f7015a4d57e5f483093e3bd2ce5645", "best_bid": "0.09", "best_ask": "0.36"}], "timestamp": "1769384496929", "event_type": "price_change"}}
{"_local_timestamp": "2026-01-25T23:41:40.398234+00:00", "data": {"market": "0xb2454e9cc596945400864ac06f667af5c13822100e52e90d56f8958bf9975e90", "price_changes": [{"asset_id": "114052061120418968776706506466935854651907852664788849843223384815399545148233", "price": "0.29", "size": "0", "side": "BUY", "hash": "aebf244c7e29261a4d504cc7bc398ba184afbb90", "best_bid": "0.3", "best_ask": "0.57"}, {"asset_id": "86490147998839916409987788995385468072126583555463813903067323555322199860102", "price": "0.71", "size": "0", "side": "SELL", "hash": "477586d4c2cf62a3606754e3bf67294241de4645", "best_bid": "0.43", "best_ask": "0.7"}], "timestamp": "1769384500269", "event_type": "price_change"}}
{"_local_timestamp": "2026-01-25T23:41:40.426440+00:00", "data": {"market": "0xb2454e9cc596945400864ac06f667af5c13822100e52e90d56f8958bf9975e90", "price_changes": [{"asset_id": "114052061120418968776706506466935854651907852664788849843223384815399545148233", "price": "0.28", "size": "8.5", "side": "BUY", "hash": "5fc3b3db9a6535dd1562f7f46a1e4edd8bb149ab", "best_bid": "0.3", "best_ask": "0.57"}, {"asset_id": "86490147998839916409987788995385468072126583555463813903067323555322199860102", "price": "0.72", "size": "8.5", "side": "SELL", "hash": "af08ac373e070d15c2563f3bca110787917f43ad", "best_bid": "0.43", "best_ask": "0.7"}], "timestamp": "1769384500318", "event_type": "price_change"}}
{"_local_timestamp": "2026-01-25T23:41:40.496794+00:00", "data": {"market": "0x37be51a4497a9ae96dcb5610cb7f26e24a1e633fdd7860b910a3d675d1e14ab0", "price_changes": [{"asset_id": "22009953520357011584148547274963289285204304765324187781336259113331278150470", "price": "0.4", "size": "20", "side": "BUY", "hash": "09e8733c5893bb5f9f0a25ff038fd8d4a4e39860", "best_bid": "0.64", "best_ask": "0.91"}, {"asset_id": "79076673506907717638765187843939471964492280241073125714298327262170536871810", "price": "0.6", "size": "20", "side": "SELL", "hash": "080e92eedc26c550e8e48afe5860aeda6ca91962", "best_bid": "0.09", "best_ask": "0.36"}], "timestamp": "1769384500417", "event_type": "price_change"}}
{"_local_timestamp": "2026-01-25T23:41:42.088451+00:00", "data": {"market": "0x37be51a4497a9ae96dcb5610cb7f26e24a1e633fdd7860b910a3d675d1e14ab0", "price_changes": [{"asset_id": "22009953520357011584148547274963289285204304765324187781336259113331278150470", "price": "0.39", "size": "0", "side": "BUY", "hash": "06dc6d36da6ead259132f506ec9508f4479cb1eb", "best_bid": "0.64", "best_ask": "0.91"}, {"asset_id": "79076673506907717638765187843939471964492280241073125714298327262170536871810", "price": "0.61", "size": "0", "side": "SELL", "hash": "a9aaa7be452f5e0f6928813fe68ee36b733161b8", "best_bid": "0.09", "best_ask": "0.36"}], "timestamp": "1769384502004", "event_type": "price_change"}}
{"_local_timestamp": "2026-01-25T23:41:42.112372+00:00", "data": {"market": "0x37be51a4497a9ae96dcb5610cb7f26e24a1e633fdd7860b910a3d675d1e14ab0", "price_changes": [{"asset_id": "22009953520357011584148547274963289285204304765324187781336259113331278150470", "price": "0.41", "size": "20", "side": "BUY", "hash": "780d5d1871e0e0916f6c034d272d53a61b2ad3f9", "best_bid": "0.64", "best_ask": "0.91"}, {"asset_id": "79076673506907717638765187843939471964492280241073125714298327262170536871810", "price": "0.59", "size": "20", "side": "SELL", "hash": "00b664011b8930440d9f896dbda9332c06d1b2e2", "best_bid": "0.09", "best_ask": "0.36"}], "timestamp": "1769384502030", "event_type": "price_change"}}
{"_local_timestamp": "2026-01-25T23:41:50.845327+00:00", "data": {"market": "0xb6509995a13af1391202841312769768df5cfdfd81e941a85be235d8fb148248", "price_changes": [{"asset_id": "61293388742692902172483944971273981064818704065183312737680051681028772972191", "price": "0.24", "size": "125", "side": "BUY", "hash": "5a2c92f05c950b076d5b162d190f5965747a1735", "best_bid": "0.91", "best_ask": "0.98"}, {"asset_id": "59506743557928779608571177404246985081593919356120638521936130122237779605413", "price": "0.76", "size": "125", "side": "SELL", "hash": "83158680087a0abfbc762f6e698045cd4933acac", "best_bid": "0.02", "best_ask": "0.09"}], "timestamp": "1769384510732", "event_type": "price_change"}}
{"_local_timestamp": "2026-01-25T23:41:50.847125+00:00", "data": {"market": "0x37be51a4497a9ae96dcb5610cb7f26e24a1e633fdd7860b910a3d675d1e14ab0", "price_changes": [{"asset_id": "22009953520357011584148547274963289285204304765324187781336259113331278150470", "price": "0.31", "size": "66.66", "side": "BUY", "hash": "a2f8d6fb2e6b54258203cfca57528255cf3b53cd", "best_bid": "0.64", "best_ask": "0.91"}, {"asset_id": "79076673506907717638765187843939471964492280241073125714298327262170536871810", "price": "0.69", "size": "66.66", "side": "SELL", "hash": "16c40d78168b47adca1e62f485bf755647d4ace2", "best_bid": "0.09", "best_ask": "0.36"}], "timestamp": "1769384510732", "event_type": "price_change"}}
{"_local_timestamp": "2026-01-25T23:41:50.855162+00:00", "data": {"market": "0xb2454e9cc596945400864ac06f667af5c13822100e52e90d56f8958bf9975e90", "price_changes": [{"asset_id": "114052061120418968776706506466935854651907852664788849843223384815399545148233", "price": "0.04", "size": "1150", "side": "BUY", "hash": "5d2d91b31d351b32122c84b78bfc2cd2cd1ce462", "best_bid": "0.3", "best_ask": "0.57"}, {"asset_id": "86490147998839916409987788995385468072126583555463813903067323555322199860102", "price": "0.96", "size": "1150", "side": "SELL", "hash": "ebc277df0c4450312e35b988667ec2c5a2d57db9", "best_bid": "0.43", "best_ask": "0.7"}], "timestamp": "1769384510735", "event_type": "price_change"}}
{"_local_timestamp": "2026-01-25T23:41:51.977927+00:00", "data": {"market": "0x37be51a4497a9ae96dcb5610cb7f26e24a1e633fdd7860b910a3d675d1e14ab0", "price_changes": [{"asset_id": "22009953520357011584148547274963289285204304765324187781336259113331278150470", "price": "0.33", "size": "150", "side": "BUY", "hash": "0068b5979512fdaba1689cd2033b15add5ce7b18", "best_bid": "0.64", "best_ask": "0.91"}, {"asset_id": "79076673506907717638765187843939471964492280241073125714298327262170536871810", "price": "0.67", "size": "150", "side": "SELL", "hash": "9e6e852aaf3f8f0eef27d835535bfe79bf4fc2eb", "best_bid": "0.09", "best_ask": "0.36"}], "timestamp": "1769384511688", "event_type": "price_change"}}
{"_local_timestamp": "2026-01-25T23:42:25.124672+00:00", "data": {"market": "0xc6d40f33829d2ea23cac35ca87c1f1a0ec084ae675b793bacaf47588abd68af7", "price_changes": [{"asset_id": "49872171312816848131376503230796566946171252643195539532075216530371086282173", "price": "0.31", "size": "191.66", "side": "BUY", "hash": "f6e9145b5b98fd87c84e88818ea2c7bedf538786", "best_bid": "0.68", "best_ask": "0.81"}, {"asset_id": "111604871160804053792665137520804934115113332935784329174488506531258467665310", "price": "0.69", "size": "191.66", "side": "SELL", "hash": "28266384e176a84c3d7a0b3049da705095d74345", "best_bid": "0.19", "best_ask": "0.32"}], "timestamp": "1769384544926", "event_type": "price_change"}}
{"_local_timestamp": "2026-01-25T23:42:25.156066+00:00", "data": {"market": "0xb6509995a13af1391202841312769768df5cfdfd81e941a85be235d8fb148248", "price_changes": [{"asset_id": "61293388742692902172483944971273981064818704065183312737680051681028772972191", "price": "0.24", "size": "175", "side": "BUY", "hash": "1dd773d9244de0ab9fbe3229597f14d761979c0d", "best_bid": "0.91", "best_ask": "0.98"}, {"asset_id": "59506743557928779608571177404246985081593919356120638521936130122237779605413", "price": "0.76", "size": "175", "side": "SELL", "hash": "5530200058e3cbd2d4e1326d7cfd1a2bb40b5e2e", "best_bid": "0.02", "best_ask": "0.09"}], "timestamp": "1769384544937", "event_type": "price_change"}}
{"_local_timestamp": "2026-01-25T23:43:11.230440+00:00", "data": {"market": "0x37be51a4497a9ae96dcb5610cb7f26e24a1e633fdd7860b910a3d675d1e14ab0", "price_changes": [{"asset_id": "22009953520357011584148547274963289285204304765324187781336259113331278150470", "price": "0.64", "size": "67", "side": "BUY", "hash": "f07536011772eec3835048c639f1fba1902324d7", "best_bid": "0.64", "best_ask": "0.91"}, {"asset_id": "79076673506907717638765187843939471964492280241073125714298327262170536871810", "price": "0.36", "size": "67", "side": "SELL", "hash": "413e7d4934f7446083337772c40c6c6e6dc36a17", "best_bid": "0.09", "best_ask": "0.36"}], "timestamp": "1769384591094", "event_type": "price_change"}}
{"_local_timestamp": "2026-01-25T23:43:11.449780+00:00", "data": {"market": "0xb2454e9cc596945400864ac06f667af5c13822100e52e90d56f8958bf9975e90", "price_changes": [{"asset_id": "114052061120418968776706506466935854651907852664788849843223384815399545148233", "price": "0.27", "size": "0", "side": "BUY", "hash": "f885c834a5ddcfc3b313e7679d5edd1e1335e102", "best_bid": "0.3", "best_ask": "0.57"}, {"asset_id": "86490147998839916409987788995385468072126583555463813903067323555322199860102", "price": "0.73", "size": "0", "side": "SELL", "hash": "8e486d95ca29bc3bcc03cff0e4c89166f75b4983", "best_bid": "0.43", "best_ask": "0.7"}], "timestamp": "1769384591307", "event_type": "price_change"}}
{"_local_timestamp": "2026-01-25T23:43:11.499664+00:00", "data": {"market": "0xb2454e9cc596945400864ac06f667af5c13822100e52e90d56f8958bf9975e90", "price_changes": [{"asset_id": "114052061120418968776706506466935854651907852664788849843223384815399545148233", "price": "0.26", "size": "40", "side": "BUY", "hash": "8b643a1e25a855b2d6ee0f573b11014e94b27049", "best_bid": "0.3", "best_ask": "0.57"}, {"asset_id": "86490147998839916409987788995385468072126583555463813903067323555322199860102", "price": "0.74", "size": "40", "side": "SELL", "hash": "38731e5e8614bdc3f82d7ec7198af7bf212886a9", "best_bid": "0.43", "best_ask": "0.7"}], "timestamp": "1769384591365", "event_type": "price_change"}}
{"_local_timestamp": "2026-01-25T23:43:18.100536+00:00", "data": {"market": "0xb2454e9cc596945400864ac06f667af5c13822100e52e90d56f8958bf9975e90", "price_changes": [{"asset_id": "114052061120418968776706506466935854651907852664788849843223384815399545148233", "price": "0.28", "size": "0", "side": "BUY", "hash": "1d950e5f0d7634df0a7e6bdbbcf1daa39ea85be6", "best_bid": "0.3", "best_ask": "0.57"}, {"asset_id": "86490147998839916409987788995385468072126583555463813903067323555322199860102", "price": "0.72", "size": "0", "side": "SELL", "hash": "2172b321a86dcb3212313168c79c197609b6a8bd", "best_bid": "0.43", "best_ask": "0.7"}], "timestamp": "1769384597986", "event_type": "price_change"}}
{"_local_timestamp": "2026-01-25T23:43:18.161096+00:00", "data": {"market": "0xb2454e9cc596945400864ac06f667af5c13822100e52e90d56f8958bf9975e90", "price_changes": [{"asset_id": "114052061120418968776706506466935854651907852664788849843223384815399545148233", "price": "0.27", "size": "8.5", "side": "BUY", "hash": "9d7463662e235b32267a7644837813f5a7e66317", "best_bid": "0.3", "best_ask": "0.57"}, {"asset_id": "86490147998839916409987788995385468072126583555463813903067323555322199860102", "price": "0.73", "size": "8.5", "side": "SELL", "hash": "281d7c587acd88dd160be2ce99c844d015131bd8", "best_bid": "0.43", "best_ask": "0.7"}], "timestamp": "1769384598035", "event_type": "price_change"}}
{"_local_timestamp": "2026-01-25T23:43:54.149940+00:00", "data": {"market": "0xb6509995a13af1391202841312769768df5cfdfd81e941a85be235d8fb148248", "price_changes": [{"asset_id": "61293388742692902172483944971273981064818704065183312737680051681028772972191", "price": "0.9", "size": "0", "side": "BUY", "hash": "0b8419dc876ee6b8ecf235defe2a8e883b15b4cf", "best_bid": "0.91", "best_ask": "0.98"}, {"asset_id": "59506743557928779608571177404246985081593919356120638521936130122237779605413", "price": "0.1", "size": "0", "side": "SELL", "hash": "786523e58e36140ce61fe7dbc927ce1ce6924f20", "best_bid": "0.02", "best_ask": "0.09"}], "timestamp": "1769384634000", "event_type": "price_change"}}
{"_local_timestamp": "2026-01-25T23:43:54.180080+00:00", "data": {"market": "0x486489d4708ad5a43f8de8e0c114a1e136f70384dccfe64370c1d8bc10b93cdb", "price_changes": [{"asset_id": "4276217737744301565675595183887401382782581341383125250557157305669874015276", "price": "0.89", "size": "0", "side": "BUY", "hash": "ae4c14412243df3e490b86a4889c158cd4fe1683", "best_bid": "0.88", "best_ask": "0.99"}, {"asset_id": "56838236357874430791537188558616388556208946622144106414539714148475287541623", "price": "0.11", "size": "0", "side": "SELL", "hash": "d4eb55971d9a1b1750599f94160be290870e48ed", "best_bid": "0.01", "best_ask": "0.12"}], "timestamp": "1769384634000", "event_type": "price_change"}}
{"_local_timestamp": "2026-01-25T23:43:54.181053+00:00", "data": {"market": "0xc6d40f33829d2ea23cac35ca87c1f1a0ec084ae675b793bacaf47588abd68af7", "price_changes": [{"asset_id": "49872171312816848131376503230796566946171252643195539532075216530371086282173", "price": "0.67", "size": "0", "side": "BUY", "hash": "60f182ed123473b563dd8dcfe58062b2cfb36531", "best_bid": "0.68", "best_ask": "0.81"}, {"asset_id": "111604871160804053792665137520804934115113332935784329174488506531258467665310", "price": "0.33", "size": "0", "side": "SELL", "hash": "4842a5f68e582ac6bc5d7057354c706afa35402c", "best_bid": "0.19", "best_ask": "0.32"}], "timestamp": "1769384634003", "event_type": "price_change"}}
{"_local_timestamp": "2026-01-25T23:43:54.236190+00:00", "data": {"market": "0xb6509995a13af1391202841312769768df5cfdfd81e941a85be235d8fb148248", "price_changes": [{"asset_id": "61293388742692902172483944971273981064818704065183312737680051681028772972191", "price": "0.63", "size": "0", "side": "BUY", "hash": "a2bcfbf30c7b95c0dd471c3ef5d096f8169b6248", "best_bid": "0.91", "best_ask": "0.98"}, {"asset_id": "59506743557928779608571177404246985081593919356120638521936130122237779605413", "price": "0.37", "size": "0", "side": "SELL", "hash": "bc96082861ef1808e1ca5dc42cb2cfe595ca0279", "best_bid": "0.02", "best_ask": "0.09"}], "timestamp": "1769384634085", "event_type": "price_change"}}
{"_local_timestamp": "2026-01-25T23:43:54.476888+00:00", "data": {"market": "0xb6509995a13af1391202841312769768df5cfdfd81e941a85be235d8fb148248", "price_changes": [{"asset_id": "61293388742692902172483944971273981064818704065183312737680051681028772972191", "price": "0.66", "size": "10", "side": "BUY", "hash": "ba4d4f98a3b828adbe3f336de81304342fee03c5", "best_bid": "0.91", "best_ask": "0.98"}, {"asset_id": "59506743557928779608571177404246985081593919356120638521936130122237779605413", "price": "0.34", "size": "10", "side": "SELL", "hash": "d6be90bfa0bca6af7eec70ccfee64f530f896845", "best_bid": "0.02", "best_ask": "0.09"}], "timestamp": "1769384634345", "event_type": "price_change"}}
{"_local_timestamp": "2026-01-25T23:43:55.523513+00:00", "data": {"market": "0xb6509995a13af1391202841312769768df5cfdfd81e941a85be235d8fb148248", "price_changes": [{"asset_id": "61293388742692902172483944971273981064818704065183312737680051681028772972191", "price": "0.65", "size": "0", "side": "BUY", "hash": "a3bbcd79a2cc3dae7eed4c27da930fbdefac7f56", "best_bid": "0.91", "best_ask": "0.98"}, {"asset_id": "59506743557928779608571177404246985081593919356120638521936130122237779605413", "price": "0.35", "size": "0", "side": "SELL", "hash": "018b8ed9fe735eb2e11d4337791421506a0506ad", "best_bid": "0.02", "best_ask": "0.09"}], "timestamp": "1769384635397", "event_type": "price_change"}}
{"_local_timestamp": "2026-01-25T23:43:55.551712+00:00", "data": {"market": "0xb6509995a13af1391202841312769768df5cfdfd81e941a85be235d8fb148248", "price_changes": [{"asset_id": "61293388742692902172483944971273981064818704065183312737680051681028772972191", "price": "0.67", "size": "45", "side": "BUY", "hash": "8fbbc7d2cff8ce86a01c3c36f4c3137e6bae7a6b", "best_bid": "0.91", "best_ask": "0.98"}, {"asset_id": "59506743557928779608571177404246985081593919356120638521936130122237779605413", "price": "0.33", "size": "45", "side": "SELL", "hash": "34c3da678e27fb1645abdcc37ed2ab6f97bf8abc", "best_bid": "0.02", "best_ask": "0.09"}], "timestamp": "1769384635427", "event_type": "price_change"}}
{"_local_timestamp": "2026-01-25T23:43:55.752511+00:00", "data": {"market": "0xb6509995a13af1391202841312769768df5cfdfd81e941a85be235d8fb148248", "price_changes": [{"asset_id": "61293388742692902172483944971273981064818704065183312737680051681028772972191", "price": "0.64", "size": "0", "side": "BUY", "hash": "916c934ac1a861eb49da28da843e669777399596", "best_bid": "0.91", "best_ask": "0.98"}, {"asset_id": "59506743557928779608571177404246985081593919356120638521936130122237779605413", "price": "0.36", "size": "0", "side": "SELL", "hash": "972f9b6590b66a4040d7450571b6e8ba74e87afb", "best_bid": "0.02", "best_ask": "0.09"}], "timestamp": "1769384635622", "event_type": "price_change"}}
{"_local_timestamp": "2026-01-25T23:43:55.971542+00:00", "data": {"market": "0xb6509995a13af1391202841312769768df5cfdfd81e941a85be235d8fb148248", "price_changes": [{"asset_id": "61293388742692902172483944971273981064818704065183312737680051681028772972191", "price": "0.63", "size": "15", "side": "BUY", "hash": "57ddb31d0f800454e50b3665b516ba4f88964ea7", "best_bid": "0.91", "best_ask": "0.98"}, {"asset_id": "59506743557928779608571177404246985081593919356120638521936130122237779605413", "price": "0.37", "size": "15", "side": "SELL", "hash": "0037a8e58bb55031f97bfa687d936db34a7a2e57", "best_bid": "0.02", "best_ask": "0.09"}], "timestamp": "1769384635839", "event_type": "price_change"}}
{"_local_timestamp": "2026-01-25T23:43:55.974059+00:00", "data": {"market": "0xb6509995a13af1391202841312769768df5cfdfd81e941a85be235d8fb148248", "price_changes": [{"asset_id": "61293388742692902172483944971273981064818704065183312737680051681028772972191", "price": "0.67", "size": "55", "side": "BUY", "hash": "240c9ef074859854add9ce853d576d92c882115f", "best_bid": "0.91", "best_ask": "0.98"}, {"asset_id": "59506743557928779608571177404246985081593919356120638521936130122237779605413", "price": "0.33", "size": "55", "side": "SELL", "hash": "a457f2b9307866f3de8e0cc22ea4ac5ed686b167", "best_bid": "0.02", "best_ask": "0.09"}], "timestamp": "1769384635842", "event_type": "price_change"}}
{"_local_timestamp": "2026-01-25T23:43:59.587574+00:00", "data": {"market": "0xc6d40f33829d2ea23cac35ca87c1f1a0ec084ae675b793bacaf47588abd68af7", "price_changes": [{"asset_id": "49872171312816848131376503230796566946171252643195539532075216530371086282173", "price": "0.68", "size": "0", "side": "BUY", "hash": "1e9abaeb15c85e259046b8c15567e6ddba092b3d", "best_bid": "0.6", "best_ask": "0.81"}, {"asset_id": "111604871160804053792665137520804934115113332935784329174488506531258467665310", "price": "0.32", "size": "0", "side": "SELL", "hash": "92d550217a5d00351dc00f2e5632ec9931efe75a", "best_bid": "0.19", "best_ask": "0.4"}], "timestamp": "1769384639476", "event_type": "price_change"}}
{"_local_timestamp": "2026-01-25T23:43:59.595398+00:00", "data": {"market": "0x37be51a4497a9ae96dcb5610cb7f26e24a1e633fdd7860b910a3d675d1e14ab0", "price_changes": [{"asset_id": "22009953520357011584148547274963289285204304765324187781336259113331278150470", "price": "0.63", "size": "0", "side": "BUY", "hash": "ffb2dbac6f86986140261436573b4a53c85d6e7b", "best_bid": "0.64", "best_ask": "0.91"}, {"asset_id": "79076673506907717638765187843939471964492280241073125714298327262170536871810", "price": "0.37", "size": "0", "side": "SELL", "hash": "7de3a982d372855e23169d7b158bdce34c5b9378", "best_bid": "0.09", "best_ask": "0.36"}], "timestamp": "1769384639476", "event_type": "price_change"}}
{"_local_timestamp": "2026-01-25T23:43:59.964418+00:00", "data": {"market": "0xc6d40f33829d2ea23cac35ca87c1f1a0ec084ae675b793bacaf47588abd68af7", "price_changes": [{"asset_id": "49872171312816848131376503230796566946171252643195539532075216530371086282173", "price": "0.61", "size": "66.66", "side": "BUY", "hash": "c7c897d5cf60b25fe5145e666acee3d3c8254a93", "best_bid": "0.61", "best_ask": "0.81"}, {"asset_id": "111604871160804053792665137520804934115113332935784329174488506531258467665310", "price": "0.39", "size": "66.66", "side": "SELL", "hash": "4e83ac3af314adc7393ae05371aadb09a03198e8", "best_bid": "0.19", "best_ask": "0.39"}], "timestamp": "1769384639853", "event_type": "price_change"}}
{"_local_timestamp": "2026-01-25T23:44:00.382456+00:00", "data": {"market": "0x37be51a4497a9ae96dcb5610cb7f26e24a1e633fdd7860b910a3d675d1e14ab0", "price_changes": [{"asset_id": "22009953520357011584148547274963289285204304765324187781336259113331278150470", "price": "0.65", "size": "66.66", "side": "BUY", "hash": "a6cfa49d370ab3f86dda1aaca64452b29822006e", "best_bid": "0.65", "best_ask": "0.91"}, {"asset_id": "79076673506907717638765187843939471964492280241073125714298327262170536871810", "price": "0.35", "size": "66.66", "side": "SELL", "hash": "8d330a347ea99c5443c3548d7ad874299a0ac16e", "best_bid": "0.09", "best_ask": "0.35"}], "timestamp": "1769384640273", "event_type": "price_change"}}
{"_local_timestamp": "2026-01-25T23:44:09.591217+00:00", "data": {"market": "0x37be51a4497a9ae96dcb5610cb7f26e24a1e633fdd7860b910a3d675d1e14ab0", "price_changes": [{"asset_id": "22009953520357011584148547274963289285204304765324187781336259113331278150470", "price": "0.32", "size": "0", "side": "BUY", "hash": "2f0a1fafcc1927b183cfd6ec0dec9123cfc7a067", "best_bid": "0.65", "best_ask": "0.91"}, {"asset_id": "79076673506907717638765187843939471964492280241073125714298327262170536871810", "price": "0.68", "size": "0", "side": "SELL", "hash": "d5f0c6a4beaadb50335d6901f7213be5d687a8f1", "best_bid": "0.09", "best_ask": "0.35"}], "timestamp": "1769384649448", "event_type": "price_change"}}
{"_local_timestamp": "2026-01-25T23:44:09.632274+00:00", "data": {"market": "0x37be51a4497a9ae96dcb5610cb7f26e24a1e633fdd7860b910a3d675d1e14ab0", "price_changes": [{"asset_id": "22009953520357011584148547274963289285204304765324187781336259113331278150470", "price": "0.34", "size": "5", "side": "BUY", "hash": "28328f44e75bc2b4da7f6e8eebf1a8dd7551cc08", "best_bid": "0.65", "best_ask": "0.91"}, {"asset_id": "79076673506907717638765187843939471964492280241073125714298327262170536871810", "price": "0.66", "size": "5", "side": "SELL", "hash": "d11d5da7ba2f95a087191194a416c1e8ffaa8319", "best_bid": "0.09", "best_ask": "0.35"}], "timestamp": "1769384649500", "event_type": "price_change"}}
{"_local_timestamp": "2026-01-25T23:44:19.216056+00:00", "data": {"market": "0x37be51a4497a9ae96dcb5610cb7f26e24a1e633fdd7860b910a3d675d1e14ab0", "price_changes": [{"asset_id": "22009953520357011584148547274963289285204304765324187781336259113331278150470", "price": "0.64", "size": "20", "side": "BUY", "hash": "0284baf07c328f9792d1e07d3fa9f4e33a56a0f2", "best_bid": "0.65", "best_ask": "0.91"}, {"asset_id": "79076673506907717638765187843939471964492280241073125714298327262170536871810", "price": "0.36", "size": "20", "side": "SELL", "hash": "48741d44b99ee2c3c0b49064867b3c854f64f8b3", "best_bid": "0.09", "best_ask": "0.35"}], "timestamp": "1769384659105", "event_type": "price_change"}}
{"_local_timestamp": "2026-01-25T23:44:21.301656+00:00", "data": {"market": "0xb6509995a13af1391202841312769768df5cfdfd81e941a85be235d8fb148248", "price_changes": [{"asset_id": "61293388742692902172483944971273981064818704065183312737680051681028772972191", "price": "0.24", "size": "275", "side": "BUY", "hash": "d048c586e815679b008ed7de5b0763a983bd3039", "best_bid": "0.91", "best_ask": "0.98"}, {"asset_id": "59506743557928779608571177404246985081593919356120638521936130122237779605413", "price": "0.76", "size": "275", "side": "SELL", "hash": "9991416353cf18d9580f1738cd9f490b682df2ea", "best_bid": "0.02", "best_ask": "0.09"}], "timestamp": "1769384660873", "event_type": "price_change"}}
{"_local_timestamp": "2026-01-25T23:45:22.097537+00:00", "data": {"market": "0xb2454e9cc596945400864ac06f667af5c13822100e52e90d56f8958bf9975e90", "price_changes": [{"asset_id": "114052061120418968776706506466935854651907852664788849843223384815399545148233", "price": "0.3", "size": "86.66", "side": "BUY", "hash": "3d18974346c3f8298a1ad461d7eb142956ba6fe2", "best_bid": "0.3", "best_ask": "0.57"}, {"asset_id": "86490147998839916409987788995385468072126583555463813903067323555322199860102", "price": "0.7", "size": "86.66", "side": "SELL", "hash": "61b8ab7502e21fc38cb809b169ecd0f49ad0634b", "best_bid": "0.43", "best_ask": "0.7"}], "timestamp": "1769384722001", "event_type": "price_change"}}
{"_local_timestamp": "2026-01-25T23:45:23.629345+00:00", "data": {"market": "0x486489d4708ad5a43f8de8e0c114a1e136f70384dccfe64370c1d8bc10b93cdb", "price_changes": [{"asset_id": "4276217737744301565675595183887401382782581341383125250557157305669874015276", "price": "0.89", "size": "50", "side": "BUY", "hash": "1ba16877e28c0a3943c447943d5cd6dd40593449", "best_bid": "0.89", "best_ask": "0.99"}, {"asset_id": "56838236357874430791537188558616388556208946622144106414539714148475287541623", "price": "0.11", "size": "50", "side": "SELL", "hash": "971d53f0859888ac4a1a036b31156740e2f6f5e4", "best_bid": "0.01", "best_ask": "0.11"}], "timestamp": "1769384723566", "event_type": "price_change"}}
{"_local_timestamp": "2026-01-25T23:45:23.637266+00:00", "data": {"market": "0xb6509995a13af1391202841312769768df5cfdfd81e941a85be235d8fb148248", "price_changes": [{"asset_id": "61293388742692902172483944971273981064818704065183312737680051681028772972191", "price": "0.9", "size": "50", "side": "BUY", "hash": "ff20068fec4bdce114a849e3cde0747f5a12ea25", "best_bid": "0.91", "best_ask": "0.98"}, {"asset_id": "59506743557928779608571177404246985081593919356120638521936130122237779605413", "price": "0.1", "size": "50", "side": "SELL", "hash": "ae58992618a750e4b510a96bcab4f05a102ba808", "best_bid": "0.02", "best_ask": "0.09"}], "timestamp": "1769384723566", "event_type": "price_change"}}
{"_local_timestamp": "2026-01-25T23:45:23.637617+00:00", "data": {"market": "0xc6d40f33829d2ea23cac35ca87c1f1a0ec084ae675b793bacaf47588abd68af7", "price_changes": [{"asset_id": "49872171312816848131376503230796566946171252643195539532075216530371086282173", "price": "0.67", "size": "50", "side": "BUY", "hash": "30cde8a14e06354f3e1c700072f3de38673eb2f3", "best_bid": "0.67", "best_ask": "0.81"}, {"asset_id": "111604871160804053792665137520804934115113332935784329174488506531258467665310", "price": "0.33", "size": "50", "side": "SELL", "hash": "999238d77081b4fecebc8c3372f6c2e6d0c534c2", "best_bid": "0.19", "best_ask": "0.33"}], "timestamp": "1769384723566", "event_type": "price_change"}}
{"_local_timestamp": "2026-01-25T23:45:23.686578+00:00", "data": {"market": "0x486489d4708ad5a43f8de8e0c114a1e136f70384dccfe64370c1d8bc10b93cdb", "price_changes": [{"asset_id": "4276217737744301565675595183887401382782581341383125250557157305669874015276", "price": "0.23", "size": "0", "side": "BUY", "hash": "345fac87ad352d3ae9eac44447d4a4e411d5b3c6", "best_bid": "0.89", "best_ask": "0.99"}, {"asset_id": "56838236357874430791537188558616388556208946622144106414539714148475287541623", "price": "0.77", "size": "0", "side": "SELL", "hash": "3f626c175453dddf8986f103d0b332dc6c06e95b", "best_bid": "0.01", "best_ask": "0.11"}], "timestamp": "1769384723608", "event_type": "price_change"}}
{"_local_timestamp": "2026-01-25T23:45:23.754552+00:00", "data": {"market": "0x486489d4708ad5a43f8de8e0c114a1e136f70384dccfe64370c1d8bc10b93cdb", "price_changes": [{"asset_id": "4276217737744301565675595183887401382782581341383125250557157305669874015276", "price": "0.63", "size": "10", "side": "BUY", "hash": "fdbd2bd3a5fde6d3d2357673f6baef17eff4635d", "best_bid": "0.89", "best_ask": "0.99"}, {"asset_id": "56838236357874430791537188558616388556208946622144106414539714148475287541623", "price": "0.37", "size": "10", "side": "SELL", "hash": "3c0f8900fee48ba03d93b19000d0ac35f671e74e", "best_bid": "0.01", "best_ask": "0.11"}], "timestamp": "1769384723685", "event_type": "price_change"}}
{"_local_timestamp": "2026-01-25T23:45:23.857178+00:00", "data": {"market": "0x37be51a4497a9ae96dcb5610cb7f26e24a1e633fdd7860b910a3d675d1e14ab0", "price_changes": [{"asset_id": "22009953520357011584148547274963289285204304765324187781336259113331278150470", "price": "0.37", "size": "0", "side": "BUY", "hash": "050261717fb41424e22f231cfeeaae205992067b", "best_bid": "0.65", "best_ask": "0.91"}, {"asset_id": "79076673506907717638765187843939471964492280241073125714298327262170536871810", "price": "0.63", "size": "0", "side": "SELL", "hash": "8aa5c59cb5cf72d96e11888325c837c97eae5d9d", "best_bid": "0.09", "best_ask": "0.35"}], "timestamp": "1769384723782", "event_type": "price_change"}}
{"_local_timestamp": "2026-01-25T23:45:23.889235+00:00", "data": {"market": "0x37be51a4497a9ae96dcb5610cb7f26e24a1e633fdd7860b910a3d675d1e14ab0", "price_changes": [{"asset_id": "22009953520357011584148547274963289285204304765324187781336259113331278150470", "price": "0.42", "size": "5", "side": "BUY", "hash": "adae31f783294d0b8b639f905e381fc04a6c92f2", "best_bid": "0.65", "best_ask": "0.91"}, {"asset_id": "79076673506907717638765187843939471964492280241073125714298327262170536871810", "price": "0.58", "size": "5", "side": "SELL", "hash": "8de1b157f4e30a87403f54e329b680bd904c064e", "best_bid": "0.09", "best_ask": "0.35"}], "timestamp": "1769384723824", "event_type": "price_change"}}
{"_local_timestamp": "2026-01-25T23:45:23.898240+00:00", "data": {"market": "0x37be51a4497a9ae96dcb5610cb7f26e24a1e633fdd7860b910a3d675d1e14ab0", "price_changes": [{"asset_id": "22009953520357011584148547274963289285204304765324187781336259113331278150470", "price": "0.42", "size": "25", "side": "BUY", "hash": "d3b00f26f7f7a51d614ad83db96d7a9680a20dec", "best_bid": "0.65", "best_ask": "0.91"}, {"asset_id": "79076673506907717638765187843939471964492280241073125714298327262170536871810", "price": "0.58", "size": "25", "side": "SELL", "hash": "6f3757d7eece4ce2d14b2b5bf273a66b303b5f36", "best_bid": "0.09", "best_ask": "0.35"}], "timestamp": "1769384723828", "event_type": "price_change"}}
{"_local_timestamp": "2026-01-25T23:45:25.259796+00:00", "data": {"market": "0x37be51a4497a9ae96dcb5610cb7f26e24a1e633fdd7860b910a3d675d1e14ab0", "price_changes": [{"asset_id": "22009953520357011584148547274963289285204304765324187781336259113331278150470", "price": "0.41", "size": "0", "side": "BUY", "hash": "b091f4f570a05926613d79138b9c881556e884c5", "best_bid": "0.65", "best_ask": "0.91"}, {"asset_id": "79076673506907717638765187843939471964492280241073125714298327262170536871810", "price": "0.59", "size": "0", "side": "SELL", "hash": "d8470aba1e8cf64166573ce291c86f667bae2a26", "best_bid": "0.09", "best_ask": "0.35"}], "timestamp": "1769384725193", "event_type": "price_change"}}
{"_local_timestamp": "2026-01-25T23:45:25.260181+00:00", "data": {"market": "0x486489d4708ad5a43f8de8e0c114a1e136f70384dccfe64370c1d8bc10b93cdb", "price_changes": [{"asset_id": "4276217737744301565675595183887401382782581341383125250557157305669874015276", "price": "0.62", "size": "0", "side": "BUY", "hash": "0d231dce36cca0debba7e4ccbfc1251d02787dee", "best_bid": "0.89", "best_ask": "0.99"}, {"asset_id": "56838236357874430791537188558616388556208946622144106414539714148475287541623", "price": "0.38", "size": "0", "side": "SELL", "hash": "f9c2b08a3ed5e43dc85bbdaed0d147e3edead57e", "best_bid": "0.01", "best_ask": "0.11"}], "timestamp": "1769384725193", "event_type": "price_change"}}
{"_local_timestamp": "2026-01-25T23:45:25.302929+00:00", "data": {"market": "0x486489d4708ad5a43f8de8e0c114a1e136f70384dccfe64370c1d8bc10b93cdb", "price_changes": [{"asset_id": "4276217737744301565675595183887401382782581341383125250557157305669874015276", "price": "0.64", "size": "20", "side": "BUY", "hash": "963ab303f0c2ab9834ce1f6fdc38cf56f8478c25", "best_bid": "0.89", "best_ask": "0.99"}, {"asset_id": "56838236357874430791537188558616388556208946622144106414539714148475287541623", "price": "0.36", "size": "20", "side": "SELL", "hash": "8cf8fb87f7c50ce08fd89bd34192f937e1676910", "best_bid": "0.01", "best_ask": "0.11"}], "timestamp": "1769384725225", "event_type": "price_change"}}
{"_local_timestamp": "2026-01-25T23:45:25.303243+00:00", "data": {"market": "0x37be51a4497a9ae96dcb5610cb7f26e24a1e633fdd7860b910a3d675d1e14ab0", "price_changes": [{"asset_id": "22009953520357011584148547274963289285204304765324187781336259113331278150470", "price": "0.43", "size": "20", "side": "BUY", "hash": "6fcb202a91c7083e540f10f9acb6a936d786b881", "best_bid": "0.65", "best_ask": "0.91"}, {"asset_id": "79076673506907717638765187843939471964492280241073125714298327262170536871810", "price": "0.57", "size": "20", "side": "SELL", "hash": "77b8e8ff41bd1616de03c05762c03327e61ba855", "best_bid": "0.09", "best_ask": "0.35"}], "timestamp": "1769384725225", "event_type": "price_change"}}
{"_local_timestamp": "2026-01-25T23:45:25.379891+00:00", "data": {"market": "0x486489d4708ad5a43f8de8e0c114a1e136f70384dccfe64370c1d8bc10b93cdb", "price_changes": [{"asset_id": "4276217737744301565675595183887401382782581341383125250557157305669874015276", "price": "0.61", "size": "10", "side": "BUY", "hash": "26cf75eb7535ab186e8c408e8cfa913dd74b577f", "best_bid": "0.89", "best_ask": "0.99"}, {"asset_id": "56838236357874430791537188558616388556208946622144106414539714148475287541623", "price": "0.39", "size": "10", "side": "SELL", "hash": "3a14159f93ec746b61f6927e4d186fc1f95db6f4", "best_bid": "0.01", "best_ask": "0.11"}], "timestamp": "1769384725314", "event_type": "price_change"}}
{"_local_timestamp": "2026-01-25T23:45:32.006648+00:00", "data": {"market": "0xc6d40f33829d2ea23cac35ca87c1f1a0ec084ae675b793bacaf47588abd68af7", "price_changes": [{"asset_id": "49872171312816848131376503230796566946171252643195539532075216530371086282173", "price": "0.06", "size": "233", "side": "BUY", "hash": "53212adeb85073a7418235a45f8a8b2c1e2dee77", "best_bid": "0.67", "best_ask": "0.81"}, {"asset_id": "111604871160804053792665137520804934115113332935784329174488506531258467665310", "price": "0.94", "size": "233", "side": "SELL", "hash": "2890dafdc26f95685cabd2532827e7cdcc1d35f2", "best_bid": "0.19", "best_ask": "0.33"}], "timestamp": "1769384731933", "event_type": "price_change"}}
{"_local_timestamp": "2026-01-25T23:45:34.266569+00:00", "data": {"market": "0xc6d40f33829d2ea23cac35ca87c1f1a0ec084ae675b793bacaf47588abd68af7", "price_changes": [{"asset_id": "49872171312816848131376503230796566946171252643195539532075216530371086282173", "price": "0.06", "size": "241.02", "side": "BUY", "hash": "147078dcdd58a70d0a8762f3f239e563fadc5776", "best_bid": "0.67", "best_ask": "0.81"}, {"asset_id": "111604871160804053792665137520804934115113332935784329174488506531258467665310", "price": "0.94", "size": "241.02", "side": "SELL", "hash": "3f65409abeecc214bc62cd0858810023d86010d0", "best_bid": "0.19", "best_ask": "0.33"}], "timestamp": "1769384734194", "event_type": "price_change"}}
{"_local_timestamp": "2026-01-25T23:45:34.432819+00:00", "data": {"market": "0x486489d4708ad5a43f8de8e0c114a1e136f70384dccfe64370c1d8bc10b93cdb", "price_changes": [{"asset_id": "4276217737744301565675595183887401382782581341383125250557157305669874015276", "price": "0.61", "size": "0", "side": "BUY", "hash": "956ff48bb1bc527e8c3e46b120fbdf42f8b3d5c5", "best_bid": "0.89", "best_ask": "0.99"}, {"asset_id": "56838236357874430791537188558616388556208946622144106414539714148475287541623", "price": "0.39", "size": "0", "side": "SELL", "hash": "e204e252052bdcc05c43699d5730b9cf6526a3f9", "best_bid": "0.01", "best_ask": "0.11"}], "timestamp": "1769384734369", "event_type": "price_change"}}
{"_local_timestamp": "2026-01-25T23:45:53.182729+00:00", "data": {"market": "0x486489d4708ad5a43f8de8e0c114a1e136f70384dccfe64370c1d8bc10b93cdb", "price_changes": [{"asset_id": "4276217737744301565675595183887401382782581341383125250557157305669874015276", "price": "0.21", "size": "100", "side": "BUY", "hash": "221c3b48bf8ba9041178b95c1d49b5a14ecc75c2", "best_bid": "0.89", "best_ask": "0.99"}, {"asset_id": "56838236357874430791537188558616388556208946622144106414539714148475287541623", "price": "0.79", "size": "100", "side": "SELL", "hash": "328a5cb2183dc98503242672144ff2b53addffa2", "best_bid": "0.01", "best_ask": "0.11"}], "timestamp": "1769384753011", "event_type": "price_change"}}
{"_local_timestamp": "2026-01-25T23:45:53.189972+00:00", "data": {"market": "0xc6d40f33829d2ea23cac35ca87c1f1a0ec084ae675b793bacaf47588abd68af7", "price_changes": [{"asset_id": "49872171312816848131376503230796566946171252643195539532075216530371086282173", "price": "0.31", "size": "141.66", "side": "BUY", "hash": "d26c10cbdfe9eef3aecf0bd8825229559e39fef9", "best_bid": "0.67", "best_ask": "0.81"}, {"asset_id": "111604871160804053792665137520804934115113332935784329174488506531258467665310", "price": "0.69", "size": "141.66", "side": "SELL", "hash": "9c9c6b20428383ced2c17170448d4babce881784", "best_bid": "0.19", "best_ask": "0.33"}], "timestamp": "1769384753011", "event_type": "price_change"}}
{"_local_timestamp": "2026-01-25T23:45:53.392879+00:00", "data": {"market": "0x486489d4708ad5a43f8de8e0c114a1e136f70384dccfe64370c1d8bc10b93cdb", "price_changes": [{"asset_id": "4276217737744301565675595183887401382782581341383125250557157305669874015276", "price": "0.64", "size": "35", "side": "BUY", "hash": "592a2023cf01fb64d236062d2974c2e6dec786cd", "best_bid": "0.89", "best_ask": "0.99"}, {"asset_id": "56838236357874430791537188558616388556208946622144106414539714148475287541623", "price": "0.36", "size": "35", "side": "SELL", "hash": "47bef391da0bb032625ca6434a98ee497880fb5c", "best_bid": "0.01", "best_ask": "0.11"}], "timestamp": "1769384753251", "event_type": "price_change"}}
{"_local_timestamp": "2026-01-25T23:45:53.393199+00:00", "data": {"market": "0x486489d4708ad5a43f8de8e0c114a1e136f70384dccfe64370c1d8bc10b93cdb", "price_changes": [{"asset_id": "4276217737744301565675595183887401382782581341383125250557157305669874015276", "price": "0.65", "size": "10", "side": "BUY", "hash": "6a362b16dddb63df23ad70475d14d737f22c8f7c", "best_bid": "0.89", "best_ask": "0.99"}, {"asset_id": "56838236357874430791537188558616388556208946622144106414539714148475287541623", "price": "0.35", "size": "10", "side": "SELL", "hash": "1ca73b8dbb4e673999d08ab80a602cdac64e5836", "best_bid": "0.01", "best_ask": "0.11"}], "timestamp": "1769384753251", "event_type": "price_change"}}
{"_local_timestamp": "2026-01-25T23:45:54.768730+00:00", "data": {"market": "0x486489d4708ad5a43f8de8e0c114a1e136f70384dccfe64370c1d8bc10b93cdb", "price_changes": [{"asset_id": "4276217737744301565675595183887401382782581341383125250557157305669874015276", "price": "0.64", "size": "15", "side": "BUY", "hash": "c63f6770b5e1be3ffeb59c62bf8eeffdadc9448f", "best_bid": "0.89", "best_ask": "0.99"}, {"asset_id": "56838236357874430791537188558616388556208946622144106414539714148475287541623", "price": "0.36", "size": "15", "side": "SELL", "hash": "4de9e7e2182b9d2bab2f17af52b1fad95bf3a42b", "best_bid": "0.01", "best_ask": "0.11"}], "timestamp": "1769384754706", "event_type": "price_change"}}
{"_local_timestamp": "2026-01-25T23:45:54.797668+00:00", "data": {"market": "0x486489d4708ad5a43f8de8e0c114a1e136f70384dccfe64370c1d8bc10b93cdb", "price_changes": [{"asset_id": "4276217737744301565675595183887401382782581341383125250557157305669874015276", "price": "0.66", "size": "20", "side": "BUY", "hash": "f6c3b7b481b2f0d96add7d4b8945f430378eb5d3", "best_bid": "0.89", "best_ask": "0.99"}, {"asset_id": "56838236357874430791537188558616388556208946622144106414539714148475287541623", "price": "0.34", "size": "20", "side": "SELL", "hash": "482c72d48c693dca31ca6df68356273f84552161", "best_bid": "0.01", "best_ask": "0.11"}], "timestamp": "1769384754733", "event_type": "price_change"}}
{"_local_timestamp": "2026-01-25T23:45:54.989209+00:00", "data": {"market": "0x486489d4708ad5a43f8de8e0c114a1e136f70384dccfe64370c1d8bc10b93cdb", "price_changes": [{"asset_id": "4276217737744301565675595183887401382782581341383125250557157305669874015276", "price": "0.64", "size": "0", "side": "BUY", "hash": "48a7d4111c0c823a2f31e606ce4adb97bab80fc0", "best_bid": "0.89", "best_ask": "0.99"}, {"asset_id": "56838236357874430791537188558616388556208946622144106414539714148475287541623", "price": "0.36", "size": "0", "side": "SELL", "hash": "cd5f93151ff89b2963dccd5174307b7a1dc35d00", "best_bid": "0.01", "best_ask": "0.11"}], "timestamp": "1769384754918", "event_type": "price_change"}}
{"_local_timestamp": "2026-01-25T23:45:56.223078+00:00", "data": {"market": "0xb6509995a13af1391202841312769768df5cfdfd81e941a85be235d8fb148248", "price_changes": [{"asset_id": "61293388742692902172483944971273981064818704065183312737680051681028772972191", "price": "0.24", "size": "150", "side": "BUY", "hash": "4ab01d3c8e0fcef4ebe82c2dd9d01f0f125018b7", "best_bid": "0.91", "best_ask": "0.98"}, {"asset_id": "59506743557928779608571177404246985081593919356120638521936130122237779605413", "price": "0.76", "size": "150", "side": "SELL", "hash": "8ad183a8db3bd5227c922c890423b06112b4081b", "best_bid": "0.02", "best_ask": "0.09"}], "timestamp": "1769384756077", "event_type": "price_change"}}
{"_local_timestamp": "2026-01-25T23:46:30.176918+00:00", "data": {"market": "0xb6509995a13af1391202841312769768df5cfdfd81e941a85be235d8fb148248", "price_changes": [{"asset_id": "61293388742692902172483944971273981064818704065183312737680051681028772972191", "price": "0.25", "size": "137", "side": "BUY", "hash": "93d9c346b835effb060529c1ee97924e2eb7300b", "best_bid": "0.91", "best_ask": "0.98"}, {"asset_id": "59506743557928779608571177404246985081593919356120638521936130122237779605413", "price": "0.75", "size": "137", "side": "SELL", "hash": "e298f4525b95730507cc32da8627c68dfffa901c", "best_bid": "0.02", "best_ask": "0.09"}], "timestamp": "1769384790074", "event_type": "price_change"}}
{"_local_timestamp": "2026-01-25T23:46:43.127312+00:00", "data": {"market": "0xb2454e9cc596945400864ac06f667af5c13822100e52e90d56f8958bf9975e90", "price_changes": [{"asset_id": "114052061120418968776706506466935854651907852664788849843223384815399545148233", "price": "0.3", "size": "136.66", "side": "BUY", "hash": "3bbf6e10825914fd6c0e8559091629e629fff6e6", "best_bid": "0.3", "best_ask": "0.57"}, {"asset_id": "86490147998839916409987788995385468072126583555463813903067323555322199860102", "price": "0.7", "size": "136.66", "side": "SELL", "hash": "cc938b0590e1299c3c925e20e91638ec944deed3", "best_bid": "0.43", "best_ask": "0.7"}], "timestamp": "1769384803013", "event_type": "price_change"}}
{"_local_timestamp": "2026-01-25T23:46:43.274804+00:00", "data": {"market": "0xc6d40f33829d2ea23cac35ca87c1f1a0ec084ae675b793bacaf47588abd68af7", "price_changes": [{"asset_id": "49872171312816848131376503230796566946171252643195539532075216530371086282173", "price": "0.61", "size": "0", "side": "BUY", "hash": "4c610cbb63d5ba0832ee74a0d05819d62d1d1e7d", "best_bid": "0.67", "best_ask": "0.81"}, {"asset_id": "111604871160804053792665137520804934115113332935784329174488506531258467665310", "price": "0.39", "size": "0", "side": "SELL", "hash": "73a71737b2d6ff3328bd43c75ccbf14b0d746f16", "best_bid": "0.19", "best_ask": "0.33"}], "timestamp": "1769384803097", "event_type": "price_change"}}
{"_local_timestamp": "2026-01-25T23:46:44.159211+00:00", "data": {"market": "0xc6d40f33829d2ea23cac35ca87c1f1a0ec084ae675b793bacaf47588abd68af7", "price_changes": [{"asset_id": "49872171312816848131376503230796566946171252643195539532075216530371086282173", "price": "0.68", "size": "66.66", "side": "BUY", "hash": "a40f8b841ec6e9ecf2cb1f1f534b939c7910fd0b", "best_bid": "0.68", "best_ask": "0.81"}, {"asset_id": "111604871160804053792665137520804934115113332935784329174488506531258467665310", "price": "0.32", "size": "66.66", "side": "SELL", "hash": "4a9b918ee09ef4566d1b8b881ffb1438682aa50c", "best_bid": "0.19", "best_ask": "0.32"}], "timestamp": "1769384804094", "event_type": "price_change"}}
{"_local_timestamp": "2026-01-25T23:46:50.767372+00:00", "data": {"market": "0x486489d4708ad5a43f8de8e0c114a1e136f70384dccfe64370c1d8bc10b93cdb", "price_changes": [{"asset_id": "4276217737744301565675595183887401382782581341383125250557157305669874015276", "price": "0.21", "size": "0", "side": "BUY", "hash": "60444c68d4f793f7d71fc36a468f6d36229bfcd8", "best_bid": "0.89", "best_ask": "0.99"}, {"asset_id": "56838236357874430791537188558616388556208946622144106414539714148475287541623", "price": "0.79", "size": "0", "side": "SELL", "hash": "78911ce06d1c665ef22e7b5dabbf779fa8217260", "best_bid": "0.01", "best_ask": "0.11"}], "timestamp": "1769384810644", "event_type": "price_change"}}
{"_local_timestamp": "2026-01-25T23:47:38.436832+00:00", "data": {"market": "0x486489d4708ad5a43f8de8e0c114a1e136f70384dccfe64370c1d8bc10b93cdb", "price_changes": [{"asset_id": "4276217737744301565675595183887401382782581341383125250557157305669874015276", "price": "0.21", "size": "50", "side": "BUY", "hash": "7b4a3c8775470ba42165d6609eb0a5f4597f2617", "best_bid": "0.89", "best_ask": "0.99"}, {"asset_id": "56838236357874430791537188558616388556208946622144106414539714148475287541623", "price": "0.79", "size": "50", "side": "SELL", "hash": "65367712e4c0dbd03fb756ba11898442fa8cf23d", "best_bid": "0.01", "best_ask": "0.11"}], "timestamp": "1769384858093", "event_type": "price_change"}}
{"_local_timestamp": "2026-01-25T23:47:38.449897+00:00", "data": {"market": "0xc6d40f33829d2ea23cac35ca87c1f1a0ec084ae675b793bacaf47588abd68af7", "price_changes": [{"asset_id": "49872171312816848131376503230796566946171252643195539532075216530371086282173", "price": "0.31", "size": "191.66", "side": "BUY", "hash": "1c6696f2eeea9fa333c51974ccbd3ff10a65ce78", "best_bid": "0.68", "best_ask": "0.81"}, {"asset_id": "111604871160804053792665137520804934115113332935784329174488506531258467665310", "price": "0.69", "size": "191.66", "side": "SELL", "hash": "1b0513869e131a9755faec929ad0f2f2637c1066", "best_bid": "0.19", "best_ask": "0.32"}], "timestamp": "1769384858101", "event_type": "price_change"}}
{"_local_timestamp": "2026-01-25T23:47:38.526658+00:00", "data": {"market": "0x37be51a4497a9ae96dcb5610cb7f26e24a1e633fdd7860b910a3d675d1e14ab0", "price_changes": [{"asset_id": "22009953520357011584148547274963289285204304765324187781336259113331278150470", "price": "0.38", "size": "0", "side": "BUY", "hash": "a4256dfc07b98daf1323edfbef687edcb07d5395", "best_bid": "0.65", "best_ask": "0.91"}, {"asset_id": "79076673506907717638765187843939471964492280241073125714298327262170536871810", "price": "0.62", "size": "0", "side": "SELL", "hash": "7ab00050dcb20ed396bd3add7d31c16e67992288", "best_bid": "0.09", "best_ask": "0.35"}], "timestamp": "1769384858462", "event_type": "price_change"}}
{"_local_timestamp": "2026-01-25T23:47:38.697717+00:00", "data": {"market": "0x37be51a4497a9ae96dcb5610cb7f26e24a1e633fdd7860b910a3d675d1e14ab0", "price_changes": [{"asset_id": "22009953520357011584148547274963289285204304765324187781336259113331278150470", "price": "0.61", "size": "25", "side": "BUY", "hash": "1238faff22222180355965102bb75a98db071a43", "best_bid": "0.65", "best_ask": "0.91"}, {"asset_id": "79076673506907717638765187843939471964492280241073125714298327262170536871810", "price": "0.39", "size": "25", "side": "SELL", "hash": "589fb8621bb6baebd2bb308877f5eaa8b54292b0", "best_bid": "0.09", "best_ask": "0.35"}], "timestamp": "1769384858628", "event_type": "price_change"}}
{"_local_timestamp": "2026-01-25T23:48:26.074277+00:00", "data": {"market": "0x37be51a4497a9ae96dcb5610cb7f26e24a1e633fdd7860b910a3d675d1e14ab0", "price_changes": [{"asset_id": "22009953520357011584148547274963289285204304765324187781336259113331278150470", "price": "0.64", "size": "0", "side": "BUY", "hash": "839ca9c318f197c072c195ee0779ac39c3aebc48", "best_bid": "0.65", "best_ask": "0.91"}, {"asset_id": "79076673506907717638765187843939471964492280241073125714298327262170536871810", "price": "0.36", "size": "0", "side": "SELL", "hash": "6f62e6b3fc342b4504a5ca4d856b0565d2493bfd", "best_bid": "0.09", "best_ask": "0.35"}], "timestamp": "1769384906000", "event_type": "price_change"}}
{"_local_timestamp": "2026-01-25T23:48:26.137138+00:00", "data": {"market": "0x37be51a4497a9ae96dcb5610cb7f26e24a1e633fdd7860b910a3d675d1e14ab0", "price_changes": [{"asset_id": "22009953520357011584148547274963289285204304765324187781336259113331278150470", "price": "0.4", "size": "0", "side": "BUY", "hash": "9fe231e489ac9fbe150959078d1eaf04bcee2201", "best_bid": "0.65", "best_ask": "0.91"}, {"asset_id": "79076673506907717638765187843939471964492280241073125714298327262170536871810", "price": "0.6", "size": "0", "side": "SELL", "hash": "0dc180c0ee906df879abea60699cb27e99b2ba23", "best_bid": "0.09", "best_ask": "0.35"}], "timestamp": "1769384906049", "event_type": "price_change"}}
{"_local_timestamp": "2026-01-25T23:48:26.229066+00:00", "data": {"market": "0x37be51a4497a9ae96dcb5610cb7f26e24a1e633fdd7860b910a3d675d1e14ab0", "price_changes": [{"asset_id": "22009953520357011584148547274963289285204304765324187781336259113331278150470", "price": "0.61", "size": "45", "side": "BUY", "hash": "75d113c4f10dddd9b8855338c77c4570bb6c1052", "best_bid": "0.65", "best_ask": "0.91"}, {"asset_id": "79076673506907717638765187843939471964492280241073125714298327262170536871810", "price": "0.39", "size": "45", "side": "SELL", "hash": "24180c1431224c445b42abe255b7b53b6f014f44", "best_bid": "0.09", "best_ask": "0.35"}], "timestamp": "1769384906157", "event_type": "price_change"}}
{"_local_timestamp": "2026-01-25T23:49:19.170082+00:00", "data": {"market": "0x37be51a4497a9ae96dcb5610cb7f26e24a1e633fdd7860b910a3d675d1e14ab0", "price_changes": [{"asset_id": "22009953520357011584148547274963289285204304765324187781336259113331278150470", "price": "0.65", "size": "0", "side": "BUY", "hash": "2ec8a292196099b53f66d5c0da1e67264d7121c8", "best_bid": "0.62", "best_ask": "0.91"}, {"asset_id": "79076673506907717638765187843939471964492280241073125714298327262170536871810", "price": "0.35", "size": "0", "side": "SELL", "hash": "7157d0840b7b37db21456321e5728e01c5553301", "best_bid": "0.09", "best_ask": "0.38"}], "timestamp": "1769384959098", "event_type": "price_change"}}
{"_local_timestamp": "2026-01-25T23:49:19.200438+00:00", "data": {"market": "0x37be51a4497a9ae96dcb5610cb7f26e24a1e633fdd7860b910a3d675d1e14ab0", "price_changes": [{"asset_id": "22009953520357011584148547274963289285204304765324187781336259113331278150470", "price": "0.63", "size": "20", "side": "BUY", "hash": "166486eabd0c99af8850b5f33af71b53f1dd1dc0", "best_bid": "0.63", "best_ask": "0.91"}, {"asset_id": "79076673506907717638765187843939471964492280241073125714298327262170536871810", "price": "0.37", "size": "20", "side": "SELL", "hash": "d2b5efaa21f476508aec34eb5ae6435af35311ea", "best_bid": "0.09", "best_ask": "0.37"}], "timestamp": "1769384959128", "event_type": "price_change"}}
{"_local_timestamp": "2026-01-25T23:49:19.339271+00:00", "data": {"market": "0x37be51a4497a9ae96dcb5610cb7f26e24a1e633fdd7860b910a3d675d1e14ab0", "price_changes": [{"asset_id": "22009953520357011584148547274963289285204304765324187781336259113331278150470", "price": "0.42", "size": "20", "side": "BUY", "hash": "e705b806576fada6b5213b9bfa32ba96929e4248", "best_bid": "0.63", "best_ask": "0.91"}, {"asset_id": "79076673506907717638765187843939471964492280241073125714298327262170536871810", "price": "0.58", "size": "20", "side": "SELL", "hash": "c574a95522d29c9f4762c7986b9cc74b9f4cd6ab", "best_bid": "0.09", "best_ask": "0.37"}], "timestamp": "1769384959267", "event_type": "price_change"}}
{"_local_timestamp": "2026-01-25T23:49:20.127819+00:00", "data": {"market": "0x37be51a4497a9ae96dcb5610cb7f26e24a1e633fdd7860b910a3d675d1e14ab0", "price_changes": [{"asset_id": "22009953520357011584148547274963289285204304765324187781336259113331278150470", "price": "0.63", "size": "86.66", "side": "BUY", "hash": "177e178200e64bb29115f8e40c221d61792cc26f", "best_bid": "0.63", "best_ask": "0.91"}, {"asset_id": "79076673506907717638765187843939471964492280241073125714298327262170536871810", "price": "0.37", "size": "86.66", "side": "SELL", "hash": "0fbe6535de076e10740b10f9f3f35ce0fc3ce8ba", "best_bid": "0.09", "best_ask": "0.37"}], "timestamp": "1769384960061", "event_type": "price_change"}}
{"_local_timestamp": "2026-01-25T23:49:20.247946+00:00", "data": {"market": "0x37be51a4497a9ae96dcb5610cb7f26e24a1e633fdd7860b910a3d675d1e14ab0", "price_changes": [{"asset_id": "22009953520357011584148547274963289285204304765324187781336259113331278150470", "price": "0.61", "size": "25", "side": "BUY", "hash": "17f1ffc614519267654acf5d837ba33bd9b140fe", "best_bid": "0.63", "best_ask": "0.91"}, {"asset_id": "79076673506907717638765187843939471964492280241073125714298327262170536871810", "price": "0.39", "size": "25", "side": "SELL", "hash": "ab98d666284e22266a6dbfbfa1d07c258900571b", "best_bid": "0.09", "best_ask": "0.37"}], "timestamp": "1769384960164", "event_type": "price_change"}}
{"_local_timestamp": "2026-01-25T23:49:20.370177+00:00", "data": {"market": "0x37be51a4497a9ae96dcb5610cb7f26e24a1e633fdd7860b910a3d675d1e14ab0", "price_changes": [{"asset_id": "22009953520357011584148547274963289285204304765324187781336259113331278150470", "price": "0.42", "size": "0", "side": "BUY", "hash": "f6fe3663ebbf2f8a1f5249faa9cccb28218d2bd7", "best_bid": "0.63", "best_ask": "0.91"}, {"asset_id": "79076673506907717638765187843939471964492280241073125714298327262170536871810", "price": "0.58", "size": "0", "side": "SELL", "hash": "390a5ae4970df46e5d8cce8d88a21fd8870aaea6", "best_bid": "0.09", "best_ask": "0.37"}], "timestamp": "1769384960294", "event_type": "price_change"}}
{"_local_timestamp": "2026-01-25T23:49:20.472473+00:00", "data": {"market": "0x37be51a4497a9ae96dcb5610cb7f26e24a1e633fdd7860b910a3d675d1e14ab0", "price_changes": [{"asset_id": "22009953520357011584148547274963289285204304765324187781336259113331278150470", "price": "0.44", "size": "20", "side": "BUY", "hash": "64ded6c89d866e3a6d6a616f411393321fb82cb6", "best_bid": "0.63", "best_ask": "0.91"}, {"asset_id": "79076673506907717638765187843939471964492280241073125714298327262170536871810", "price": "0.56", "size": "20", "side": "SELL", "hash": "528e2df8fa00d317b8174740b6a5cdbe0577131b", "best_bid": "0.09", "best_ask": "0.37"}], "timestamp": "1769384960401", "event_type": "price_change"}}
{"_local_timestamp": "2026-01-25T23:49:20.640955+00:00", "data": {"market": "0x37be51a4497a9ae96dcb5610cb7f26e24a1e633fdd7860b910a3d675d1e14ab0", "price_changes": [{"asset_id": "22009953520357011584148547274963289285204304765324187781336259113331278150470", "price": "0.61", "size": "45", "side": "BUY", "hash": "440546be076e80c59f8cd6aca619a56c44782d50", "best_bid": "0.63", "best_ask": "0.91"}, {"asset_id": "79076673506907717638765187843939471964492280241073125714298327262170536871810", "price": "0.39", "size": "45", "side": "SELL", "hash": "cbc0c1926af027076b0b2b46edb337ad36303366", "best_bid": "0.09", "best_ask": "0.37"}], "timestamp": "1769384960575", "event_type": "price_change"}}
{"_local_timestamp": "2026-01-25T23:49:20.645149+00:00", "data": {"market": "0x37be51a4497a9ae96dcb5610cb7f26e24a1e633fdd7860b910a3d675d1e14ab0", "price_changes": [{"asset_id": "22009953520357011584148547274963289285204304765324187781336259113331278150470", "price": "0.45", "size": "5", "side": "BUY", "hash": "b9ddb669acf0c6f1ab86e68714d753f65010c6aa", "best_bid": "0.63", "best_ask": "0.91"}, {"asset_id": "79076673506907717638765187843939471964492280241073125714298327262170536871810", "price": "0.55", "size": "5", "side": "SELL", "hash": "e21b5dc8402dc4d14abbb2444e5c03d267200791", "best_bid": "0.09", "best_ask": "0.37"}], "timestamp": "1769384960576", "event_type": "price_change"}}
{"_local_timestamp": "2026-01-25T23:49:21.249731+00:00", "data": {"market": "0x37be51a4497a9ae96dcb5610cb7f26e24a1e633fdd7860b910a3d675d1e14ab0", "price_changes": [{"asset_id": "22009953520357011584148547274963289285204304765324187781336259113331278150470", "price": "0.43", "size": "0", "side": "BUY", "hash": "6b4a889ec35aa69f02e37ede71900ce822e0a4ea", "best_bid": "0.63", "best_ask": "0.91"}, {"asset_id": "79076673506907717638765187843939471964492280241073125714298327262170536871810", "price": "0.57", "size": "0", "side": "SELL", "hash": "9c5bf0c5163ada8cb868b79b0c5eb15680daa289", "best_bid": "0.09", "best_ask": "0.37"}], "timestamp": "1769384961184", "event_type": "price_change"}}
{"_local_timestamp": "2026-01-25T23:49:21.274622+00:00", "data": {"market": "0x37be51a4497a9ae96dcb5610cb7f26e24a1e633fdd7860b910a3d675d1e14ab0", "price_changes": [{"asset_id": "22009953520357011584148547274963289285204304765324187781336259113331278150470", "price": "0.45", "size": "25", "side": "BUY", "hash": "d4b8a7eb35afd1370884355d9cb65137cf94ab2d", "best_bid": "0.63", "best_ask": "0.91"}, {"asset_id": "79076673506907717638765187843939471964492280241073125714298327262170536871810", "price": "0.55", "size": "25", "side": "SELL", "hash": "a970a7a23df2bc2dbc99ebe8da16c4542607ca7b", "best_bid": "0.09", "best_ask": "0.37"}], "timestamp": "1769384961211", "event_type": "price_change"}}
{"_local_timestamp": "2026-01-25T23:49:23.078462+00:00", "data": {"market": "0xb6509995a13af1391202841312769768df5cfdfd81e941a85be235d8fb148248", "price_changes": [{"asset_id": "61293388742692902172483944971273981064818704065183312737680051681028772972191", "price": "0.9", "size": "0", "side": "BUY", "hash": "6b6af4c26a0e94827fad8ff9d4ff6fac08454bd3", "best_bid": "0.91", "best_ask": "0.98"}, {"asset_id": "59506743557928779608571177404246985081593919356120638521936130122237779605413", "price": "0.1", "size": "0", "side": "SELL", "hash": "7de51a9488f3b8510b9a6d8dfa7d24da430f0a2e", "best_bid": "0.02", "best_ask": "0.09"}], "timestamp": "1769384963000", "event_type": "price_change"}}
{"_local_timestamp": "2026-01-25T23:49:23.078763+00:00", "data": {"market": "0xc6d40f33829d2ea23cac35ca87c1f1a0ec084ae675b793bacaf47588abd68af7", "price_changes": [{"asset_id": "49872171312816848131376503230796566946171252643195539532075216530371086282173", "price": "0.67", "size": "0", "side": "BUY", "hash": "eceb80ea652f2844a5ef53b1c219b17ee57246b7", "best_bid": "0.68", "best_ask": "0.81"}, {"asset_id": "111604871160804053792665137520804934115113332935784329174488506531258467665310", "price": "0.33", "size": "0", "side": "SELL", "hash": "d106c797941c830465892e844784a0fd39d20b52", "best_bid": "0.19", "best_ask": "0.32"}], "timestamp": "1769384963000", "event_type": "price_change"}}
{"_local_timestamp": "2026-01-25T23:49:23.100320+00:00", "data": {"market": "0x486489d4708ad5a43f8de8e0c114a1e136f70384dccfe64370c1d8bc10b93cdb", "price_changes": [{"asset_id": "4276217737744301565675595183887401382782581341383125250557157305669874015276", "price": "0.89", "size": "0", "side": "BUY", "hash": "5efb5533cab7c960c37e0a914a9af9dcbd23d138", "best_bid": "0.88", "best_ask": "0.99"}, {"asset_id": "56838236357874430791537188558616388556208946622144106414539714148475287541623", "price": "0.11", "size": "0", "side": "SELL", "hash": "a06741d92b58b846852ea47e401a3d1db3a125b5", "best_bid": "0.01", "best_ask": "0.12"}], "timestamp": "1769384963002", "event_type": "price_change"}}
{"_local_timestamp": "2026-01-25T23:49:25.457534+00:00", "data": {"market": "0xb6509995a13af1391202841312769768df5cfdfd81e941a85be235d8fb148248", "price_changes": [{"asset_id": "61293388742692902172483944971273981064818704065183312737680051681028772972191", "price": "0.24", "size": "100", "side": "BUY", "hash": "538caa422017d23838a6e932dcf408c572100b20", "best_bid": "0.91", "best_ask": "0.98"}, {"asset_id": "59506743557928779608571177404246985081593919356120638521936130122237779605413", "price": "0.76", "size": "100", "side": "SELL", "hash": "a2fdf94a031d2a4f79714292c7f651fb2341fc55", "best_bid": "0.02", "best_ask": "0.09"}], "timestamp": "1769384965285", "event_type": "price_change"}}
{"_local_timestamp": "2026-01-25T23:49:25.830792+00:00", "data": {"market": "0xb6509995a13af1391202841312769768df5cfdfd81e941a85be235d8fb148248", "price_changes": [{"asset_id": "61293388742692902172483944971273981064818704065183312737680051681028772972191", "price": "0.25", "size": "187", "side": "BUY", "hash": "7545721a5417ed7d32dcf82a18d9a0ca56ba6cc4", "best_bid": "0.91", "best_ask": "0.98"}, {"asset_id": "59506743557928779608571177404246985081593919356120638521936130122237779605413", "price": "0.75", "size": "187", "side": "SELL", "hash": "310ceece94a6fa229fde7faae7ee38895c394a47", "best_bid": "0.02", "best_ask": "0.09"}], "timestamp": "1769384965758", "event_type": "price_change"}}
{"_local_timestamp": "2026-01-25T23:49:30.213885+00:00", "data": {"market": "0xb6509995a13af1391202841312769768df5cfdfd81e941a85be235d8fb148248", "price_changes": [{"asset_id": "61293388742692902172483944971273981064818704065183312737680051681028772972191", "price": "0.24", "size": "0", "side": "BUY", "hash": "9abb07f567093ec200871c5b3c32caf5c19acabd", "best_bid": "0.91", "best_ask": "0.98"}, {"asset_id": "59506743557928779608571177404246985081593919356120638521936130122237779605413", "price": "0.76", "size": "0", "side": "SELL", "hash": "cb551bed9f7ebcb0710226a2c1c04e7e886b4ab4", "best_bid": "0.02", "best_ask": "0.09"}], "timestamp": "1769384970040", "event_type": "price_change"}}
{"_local_timestamp": "2026-01-25T23:49:30.932559+00:00", "data": {"market": "0xb6509995a13af1391202841312769768df5cfdfd81e941a85be235d8fb148248", "price_changes": [{"asset_id": "61293388742692902172483944971273981064818704065183312737680051681028772972191", "price": "0.25", "size": "287", "side": "BUY", "hash": "74810805e3973d8bec9f1bc1ca68e4cdb9dab2a5", "best_bid": "0.91", "best_ask": "0.98"}, {"asset_id": "59506743557928779608571177404246985081593919356120638521936130122237779605413", "price": "0.75", "size": "287", "side": "SELL", "hash": "705d5b1bc5b27d7767cadec408a67cb7e4147cae", "best_bid": "0.02", "best_ask": "0.09"}], "timestamp": "1769384970610", "event_type": "price_change"}}
{"_local_timestamp": "2026-01-25T23:49:31.034203+00:00", "data": {"market": "0x486489d4708ad5a43f8de8e0c114a1e136f70384dccfe64370c1d8bc10b93cdb", "price_changes": [{"asset_id": "4276217737744301565675595183887401382782581341383125250557157305669874015276", "price": "0.21", "size": "150", "side": "BUY", "hash": "f8ab59f6c2091e05b1699f17883fbd0dd01ef5a7", "best_bid": "0.88", "best_ask": "0.99"}, {"asset_id": "56838236357874430791537188558616388556208946622144106414539714148475287541623", "price": "0.79", "size": "150", "side": "SELL", "hash": "df06b03dc42970aab14f334bdc59c0330e6e2156", "best_bid": "0.01", "best_ask": "0.12"}], "timestamp": "1769384970649", "event_type": "price_change"}}
{"_local_timestamp": "2026-01-25T23:50:03.104805+00:00", "data": {"market": "0xb6509995a13af1391202841312769768df5cfdfd81e941a85be235d8fb148248", "price_changes": [{"asset_id": "61293388742692902172483944971273981064818704065183312737680051681028772972191", "price": "0.19", "size": "0", "side": "BUY", "hash": "b668c0282ebc6708400746c9619d52f130a2168e", "best_bid": "0.91", "best_ask": "0.98"}, {"asset_id": "59506743557928779608571177404246985081593919356120638521936130122237779605413", "price": "0.81", "size": "0", "side": "SELL", "hash": "f7ee1596ca9ae3e858805e843e176dbd77a291ac", "best_bid": "0.02", "best_ask": "0.09"}], "timestamp": "1769385002582", "event_type": "price_change"}}
{"_local_timestamp": "2026-01-25T23:50:03.121443+00:00", "data": {"market": "0xb6509995a13af1391202841312769768df5cfdfd81e941a85be235d8fb148248", "price_changes": [{"asset_id": "61293388742692902172483944971273981064818704065183312737680051681028772972191", "price": "0.26", "size": "7", "side": "BUY", "hash": "1192b597879ee14f29c87832cc71a969ad93fe3e", "best_bid": "0.91", "best_ask": "0.98"}, {"asset_id": "59506743557928779608571177404246985081593919356120638521936130122237779605413", "price": "0.74", "size": "7", "side": "SELL", "hash": "bd011e20044415729ce5825147f3db47f6f54583", "best_bid": "0.02", "best_ask": "0.09"}], "timestamp": "1769385002629", "event_type": "price_change"}}
{"_local_timestamp": "2026-01-25T23:50:05.083596+00:00", "data": {"market": "0xb2454e9cc596945400864ac06f667af5c13822100e52e90d56f8958bf9975e90", "price_changes": [{"asset_id": "114052061120418968776706506466935854651907852664788849843223384815399545148233", "price": "0.3", "size": "116.66", "side": "BUY", "hash": "5cc022bc276ae6b40303d2f2afee1d19fc5d1e57", "best_bid": "0.3", "best_ask": "0.57"}, {"asset_id": "86490147998839916409987788995385468072126583555463813903067323555322199860102", "price": "0.7", "size": "116.66", "side": "SELL", "hash": "195306d169476dc36f511318b6d463a98f512072", "best_bid": "0.43", "best_ask": "0.7"}], "timestamp": "1769385005002", "event_type": "price_change"}}
{"_local_timestamp": "2026-01-25T23:50:05.153838+00:00", "data": {"market": "0xb2454e9cc596945400864ac06f667af5c13822100e52e90d56f8958bf9975e90", "price_changes": [{"asset_id": "114052061120418968776706506466935854651907852664788849843223384815399545148233", "price": "0.3", "size": "136.66", "side": "BUY", "hash": "fb2f81e50d4d7238c47364994f7667428d8fb0a9", "best_bid": "0.3", "best_ask": "0.57"}, {"asset_id": "86490147998839916409987788995385468072126583555463813903067323555322199860102", "price": "0.7", "size": "136.66", "side": "SELL", "hash": "9edf44386a8abaab41b5590ce90f7d5e078a0294", "best_bid": "0.43", "best_ask": "0.7"}], "timestamp": "1769385005028", "event_type": "price_change"}}
{"_local_timestamp": "2026-01-25T23:50:42.234138+00:00", "data": {"market": "0xb2454e9cc596945400864ac06f667af5c13822100e52e90d56f8958bf9975e90", "price_changes": [{"asset_id": "114052061120418968776706506466935854651907852664788849843223384815399545148233", "price": "0.3", "size": "86.66", "side": "BUY", "hash": "9e2b5ad9665ff0ba0fecb6255641d49e2e21aa88", "best_bid": "0.3", "best_ask": "0.57"}, {"asset_id": "86490147998839916409987788995385468072126583555463813903067323555322199860102", "price": "0.7", "size": "86.66", "side": "SELL", "hash": "adfcb4e02aa69e0c9e3c1d5cd285334b5ab2bef6", "best_bid": "0.43", "best_ask": "0.7"}], "timestamp": "1769385042002", "event_type": "price_change"}}
{"_local_timestamp": "2026-01-25T23:50:42.382351+00:00", "data": {"market": "0xb2454e9cc596945400864ac06f667af5c13822100e52e90d56f8958bf9975e90", "price_changes": [{"asset_id": "114052061120418968776706506466935854651907852664788849843223384815399545148233", "price": "0.17", "size": "0", "side": "BUY", "hash": "ad3888227ab0146822e8f8e73f7b2a0fe64832b7", "best_bid": "0.3", "best_ask": "0.57"}, {"asset_id": "86490147998839916409987788995385468072126583555463813903067323555322199860102", "price": "0.83", "size": "0", "side": "SELL", "hash": "11a8530bfbecad268bdef4e2f52c3163e843753b", "best_bid": "0.43", "best_ask": "0.7"}], "timestamp": "1769385042210", "event_type": "price_change"}}
{"_local_timestamp": "2026-01-25T23:50:42.442231+00:00", "data": {"market": "0xb2454e9cc596945400864ac06f667af5c13822100e52e90d56f8958bf9975e90", "price_changes": [{"asset_id": "114052061120418968776706506466935854651907852664788849843223384815399545148233", "price": "0.17", "size": "10", "side": "BUY", "hash": "463c8b109c52e92c99ec939baf3e12d054d79bd7", "best_bid": "0.3", "best_ask": "0.57"}, {"asset_id": "86490147998839916409987788995385468072126583555463813903067323555322199860102", "price": "0.83", "size": "10", "side": "SELL", "hash": "2192e80d24130c6dc74f6b543a093a23edd1fe62", "best_bid": "0.43", "best_ask": "0.7"}], "timestamp": "1769385042269", "event_type": "price_change"}}
{"_local_timestamp": "2026-01-25T23:50:57.759118+00:00", "data": {"market": "0xc6d40f33829d2ea23cac35ca87c1f1a0ec084ae675b793bacaf47588abd68af7", "price_changes": [{"asset_id": "49872171312816848131376503230796566946171252643195539532075216530371086282173", "price": "0.67", "size": "50", "side": "BUY", "hash": "d2f927f8a60b9311af23373609de0a63d7f462e7", "best_bid": "0.68", "best_ask": "0.81"}, {"asset_id": "111604871160804053792665137520804934115113332935784329174488506531258467665310", "price": "0.33", "size": "50", "side": "SELL", "hash": "962fa0a53df70a1488b65ff10a9e19ccc90499f7", "best_bid": "0.19", "best_ask": "0.32"}], "timestamp": "1769385057694", "event_type": "price_change"}}
{"_local_timestamp": "2026-01-25T23:50:57.759715+00:00", "data": {"market": "0xb6509995a13af1391202841312769768df5cfdfd81e941a85be235d8fb148248", "price_changes": [{"asset_id": "61293388742692902172483944971273981064818704065183312737680051681028772972191", "price": "0.9", "size": "50", "side": "BUY", "hash": "05fb51be8914f510a3f38271926289f15f0df9a2", "best_bid": "0.91", "best_ask": "0.98"}, {"asset_id": "59506743557928779608571177404246985081593919356120638521936130122237779605413", "price": "0.1", "size": "50", "side": "SELL", "hash": "233383a5f9168c21ddc882021408cddadcb1f36e", "best_bid": "0.02", "best_ask": "0.09"}], "timestamp": "1769385057695", "event_type": "price_change"}}
{"_local_timestamp": "2026-01-25T23:50:57.761559+00:00", "data": {"market": "0x486489d4708ad5a43f8de8e0c114a1e136f70384dccfe64370c1d8bc10b93cdb", "price_changes": [{"asset_id": "4276217737744301565675595183887401382782581341383125250557157305669874015276", "price": "0.89", "size": "50", "side": "BUY", "hash": "37de5c5332d5a69d0575e8b42a576438dc60d3f4", "best_bid": "0.89", "best_ask": "0.99"}, {"asset_id": "56838236357874430791537188558616388556208946622144106414539714148475287541623", "price": "0.11", "size": "50", "side": "SELL", "hash": "ed8251781417068f8e9c0de318de01793f4b1f4c", "best_bid": "0.01", "best_ask": "0.11"}], "timestamp": "1769385057695", "event_type": "price_change"}}
{"_local_timestamp": "2026-01-25T23:51:05.512374+00:00", "data": {"market": "0xc6d40f33829d2ea23cac35ca87c1f1a0ec084ae675b793bacaf47588abd68af7", "price_changes": [{"asset_id": "49872171312816848131376503230796566946171252643195539532075216530371086282173", "price": "0.31", "size": "141.66", "side": "BUY", "hash": "a7872bf7a2704a1f52ded500b0b6343d679ee9a3", "best_bid": "0.68", "best_ask": "0.81"}, {"asset_id": "111604871160804053792665137520804934115113332935784329174488506531258467665310", "price": "0.69", "size": "141.66", "side": "SELL", "hash": "e967c473d694a476845b2d32013cdead963f9bb8", "best_bid": "0.19", "best_ask": "0.32"}], "timestamp": "1769385065411", "event_type": "price_change"}}
{"_local_timestamp": "2026-01-25T23:51:05.512890+00:00", "data": {"market": "0x486489d4708ad5a43f8de8e0c114a1e136f70384dccfe64370c1d8bc10b93cdb", "price_changes": [{"asset_id": "4276217737744301565675595183887401382782581341383125250557157305669874015276", "price": "0.21", "size": "100", "side": "BUY", "hash": "10b3524fc0e7ff99ce20bf4ff48c605a54f09402", "best_bid": "0.89", "best_ask": "0.99"}, {"asset_id": "56838236357874430791537188558616388556208946622144106414539714148475287541623", "price": "0.79", "size": "100", "side": "SELL", "hash": "11d45bf51a066c410c96471a5755291bac48daac", "best_bid": "0.01", "best_ask": "0.11"}], "timestamp": "1769385065411", "event_type": "price_change"}}
{"_local_timestamp": "2026-01-25T23:51:05.780193+00:00", "data": {"market": "0x486489d4708ad5a43f8de8e0c114a1e136f70384dccfe64370c1d8bc10b93cdb", "price_changes": [{"asset_id": "4276217737744301565675595183887401382782581341383125250557157305669874015276", "price": "0.65", "size": "0", "side": "BUY", "hash": "8869264ca5818b579c448ba22e4d5865a43a794b", "best_bid": "0.89", "best_ask": "0.99"}, {"asset_id": "56838236357874430791537188558616388556208946622144106414539714148475287541623", "price": "0.35", "size": "0", "side": "SELL", "hash": "85877cb74d107dfe97627c9a5004b764b46970a0", "best_bid": "0.01", "best_ask": "0.11"}], "timestamp": "1769385065627", "event_type": "price_change"}}
{"_local_timestamp": "2026-01-25T23:51:06.092140+00:00", "data": {"market": "0x486489d4708ad5a43f8de8e0c114a1e136f70384dccfe64370c1d8bc10b93cdb", "price_changes": [{"asset_id": "4276217737744301565675595183887401382782581341383125250557157305669874015276", "price": "0.64", "size": "10", "side": "BUY", "hash": "ec155c3dc28a306ef14e7d7ec5b1cfd0dbf7af26", "best_bid": "0.89", "best_ask": "0.99"}, {"asset_id": "56838236357874430791537188558616388556208946622144106414539714148475287541623", "price": "0.36", "size": "10", "side": "SELL", "hash": "8670f421c9ea2a5ba17752f34184c370f6647349", "best_bid": "0.01", "best_ask": "0.11"}], "timestamp": "1769385065862", "event_type": "price_change"}}
{"_local_timestamp": "2026-01-25T23:51:06.092458+00:00", "data": {"market": "0x486489d4708ad5a43f8de8e0c114a1e136f70384dccfe64370c1d8bc10b93cdb", "price_changes": [{"asset_id": "4276217737744301565675595183887401382782581341383125250557157305669874015276", "price": "0.61", "size": "15", "side": "BUY", "hash": "d90a6e4d05f63cbd4362d8a5395cb6d35d53cc2b", "best_bid": "0.89", "best_ask": "0.99"}, {"asset_id": "56838236357874430791537188558616388556208946622144106414539714148475287541623", "price": "0.39", "size": "15", "side": "SELL", "hash": "ea37b322adf5fa1d23655a6ae1557e6a0e9a961f", "best_bid": "0.01", "best_ask": "0.11"}], "timestamp": "1769385065863", "event_type": "price_change"}}
{"_local_timestamp": "2026-01-25T23:51:06.976695+00:00", "data": {"market": "0x486489d4708ad5a43f8de8e0c114a1e136f70384dccfe64370c1d8bc10b93cdb", "price_changes": [{"asset_id": "4276217737744301565675595183887401382782581341383125250557157305669874015276", "price": "0.66", "size": "0", "side": "BUY", "hash": "c54aeceb8b99dba311b4e6e9fe85377ec0f12757", "best_bid": "0.89", "best_ask": "0.99"}, {"asset_id": "56838236357874430791537188558616388556208946622144106414539714148475287541623", "price": "0.34", "size": "0", "side": "SELL", "hash": "55995b2cfcff3e06f7d53f0865528281d4623916", "best_bid": "0.01", "best_ask": "0.11"}], "timestamp": "1769385066907", "event_type": "price_change"}}
{"_local_timestamp": "2026-01-25T23:51:06.999758+00:00", "data": {"market": "0x486489d4708ad5a43f8de8e0c114a1e136f70384dccfe64370c1d8bc10b93cdb", "price_changes": [{"asset_id": "4276217737744301565675595183887401382782581341383125250557157305669874015276", "price": "0.65", "size": "20", "side": "BUY", "hash": "e0ae922113ac80c14803cfab1695a84fd174f0db", "best_bid": "0.89", "best_ask": "0.99"}, {"asset_id": "56838236357874430791537188558616388556208946622144106414539714148475287541623", "price": "0.35", "size": "20", "side": "SELL", "hash": "d98039e31813948d2a68b1dfc58eee600b299b73", "best_bid": "0.01", "best_ask": "0.11"}], "timestamp": "1769385066935", "event_type": "price_change"}}
