{"_local_timestamp": "2026-01-25T23:33:19.528916+00:00", "data": [{"market": "0x32821c03c1a785af6bea72291b578e722f02f7da80e204c42be3dee38694756f", "asset_id": "11222612568007649347690827040340431718068607305340023819591655077557696898272", "timestamp": "1769383994441", "hash": "b2654eb96690e683e1818da6e6152d90aa06fbce", "bids": [{"price": "0.001", "size": "3262.78"}, {"price": "0.002", "size": "1250"}, {"price": "0.003", "size": "1173.36"}, {"price": "0.006", "size": "83"}, {"price": "0.007", "size": "10.81"}, {"price": "0.01", "size": "6750"}, {"price": "0.02", "size": "3000"}, {"price": "0.021", "size": "9.66"}, {"price": "0.04", "size": "1500"}, {"price": "0.046", "size": "5700"}, {"price": "0.05", "size": "30"}, {"price": "0.051", "size": "39"}, {"price": "0.06", "size": "375"}, {"price": "0.061", "size": "8.82"}, {"price": "0.1", "size": "560"}, {"price": "0.15", "size": "551.66"}, {"price": "0.2", "size": "410"}, {"price": "0.201", "size": "5.72"}, {"price": "0.242", "size": "1042"}, {"price": "0.25", "size": "112"}, {"price": "0.29", "size": "89.65"}, {"price": "0.298", "size": "6536"}, {"price": "0.299", "size": "300"}, {"price": "0.34", "size": "70.58"}, {"price": "0.39", "size": "51.28"}, {"price": "0.391", "size": "986"}, {"price": "0.452", "size": "573"}, {"price": "0.456", "size": "5"}, {"price": "0.457", "size": "20"}, {"price": "0.483", "size": "175"}, {"price": "0.484", "size": "20"}, {"price": "0.485", "size": "20"}, {"price": "0.89", "size": "850"}, {"price": "0.958", "size": "300"}, {"price": "0.959", "size": "394.7"}, {"price": "0.96", "size": "123.12"}, {"price": "0.962", "size": "12.5"}, {"price": "0.963", "size": "59.8"}, {"price": "0.964", "size": "24.6"}, {"price": "0.966", "size": "17"}, {"price": "0.967", "size": "245.94"}, {"price": "0.969", "size": "30"}], "asks": [{"price": "0.999", "size": "5527"}, {"price": "0.998", "size": "49.98"}, {"price": "0.994", "size": "436.81"}, {"price": "0.993", "size": "11.3"}, {"price": "0.991", "size": "10"}, {"price": "0.99", "size": "3200"}, {"price": "0.989", "size": "250"}, {"price": "0.988", "size": "222.91"}, {"price": "0.98", "size": "15"}, {"price": "0.979", "size": "10"}, {"price": "0.978", "size": "102.59"}], "event_type": "book", "last_trade_price": "0.977"}, {"market": "0xd55b7e07b66b1d6702aa8f8c0c761a4f2838b55fa31395676bd0150b9fabb3a4", "asset_id": "71934813421791148309055586854264573769390957341135501297936685395378523616284", "timestamp": "1769383998791", "hash": "184ce3508c1f11107f03cc5885bc97efc6c02129", "bids": [{"price": "0.001", "size": "3925.91"}, {"price": "0.002", "size": "1255.55"}, {"price": "0.003", "size": "1000"}, {"price": "0.004", "size": "23.07"}, {"price": "0.01", "size": "6750"}, {"price": "0.02", "size": "3700"}, {"price": "0.021", "size": "12.17"}, {"price": "0.04", "size": "1500"}, {"price": "0.05", "size": "30"}, {"price": "0.051", "size": "39"}, {"price": "0.06", "size": "375"}, {"price": "0.07", "size": "868.06"}, {"price": "0.071", "size": "7.13"}, {"price": "0.09", "size": "400"}, {"price": "0.14", "size": "242.85"}, {"price": "0.141", "size": "1459"}, {"price": "0.19", "size": "168.42"}, {"price": "0.196", "size": "1066"}, {"price": "0.198", "size": "300"}, {"price": "0.199", "size": "2115.67"}, {"price": "0.24", "size": "116.66"}, {"price": "0.241", "size": "150"}, {"price": "0.29", "size": "89.65"}, {"price": "0.33", "size": "72.72"}, {"price": "0.38", "size": "52.63"}, {"price": "0.402", "size": "500"}, {"price": "0.44", "size": "930"}, {"price": "0.442", "size": "3700"}, {"price": "0.443", "size": "1414"}, {"price": "0.444", "size": "5"}, {"price": "0.69", "size": "332.24"}, {"price": "0.691", "size": "257"}, {"price": "0.692", "size": "400"}, {"price": "0.715", "size": "139"}, {"price": "0.719", "size": "10"}, {"price": "0.721", "size": "20"}, {"price": "0.723", "size": "20"}, {"price": "0.724", "size": "20"}, {"price": "0.87", "size": "150"}, {"price": "0.909", "size": "110"}, {"price": "0.91", "size": "50"}, {"price": "0.918", "size": "300"}, {"price": "0.92", "size": "99.93"}, {"price": "0.926", "size": "8.01"}, {"price": "0.934", "size": "103.01"}], "asks": [{"price": "0.999", "size": "2583.99"}, {"price": "0.998", "size": "21.26"}, {"price": "0.99", "size": "10"}, {"price": "0.989", "size": "5.68"}, {"price": "0.977", "size": "55"}, {"price": "0.975", "size": "9681.12"}, {"price": "0.974", "size": "300"}, {"price": "0.973", "size": "100"}, {"price": "0.972", "size": "55"}, {"price": "0.97", "size": "50"}, {"price": "0.961", "size": "282"}, {"price": "0.96", "size": "300"}, {"price": "0.955", "size": "100"}, {"price": "0.95", "size": "100"}, {"price": "0.946", "size": "600"}, {"price": "0.945", "size": "300"}, {"price": "0.944", "size": "333.62"}, {"price": "0.943", "size": "140"}, {"price": "0.939", "size": "39.2"}, {"price": "0.937", "size": "15"}, {"price": "0.936", "size": "213"}], "event_type": "book", "last_trade_price": "0.066"}, {"market": "0x378f76341e555b6d54b89cc527afde5f8c293025cf6f48980145b94dc5726ce7", "asset_id": "7664065636701295840769263287437558246574946591549211748470097864098826204283", "timestamp": "1769383994182", "hash": "29bd5b909f883b19121cf52cf387da6cca29248e", "bids": [{"price": "0.01", "size": "6830"}, {"price": "0.02", "size": "3400"}, {"price": "0.04", "size": "1500"}, {"price": "0.05", "size": "30"}, {"price": "0.06", "size": "408"}, {"price": "0.09", "size": "400"}, {"price": "0.1", "size": "3500"}, {"price": "0.11", "size": "300"}, {"price": "0.14", "size": "567.85"}, {"price": "0.18", "size": "427.77"}, {"price": "0.22", "size": "726"}, {"price": "0.23", "size": "121.73"}, {"price": "0.26", "size": "150"}, {"price": "0.27", "size": "1650.29"}, {"price": "0.32", "size": "75"}, {"price": "0.36", "size": "1055.55"}, {"price": "0.38", "size": "930"}, {"price": "0.39", "size": "3638"}, {"price": "0.4", "size": "5"}, {"price": "0.64", "size": "760"}, {"price": "0.65", "size": "10"}, {"price": "0.77", "size": "20"}, {"price": "0.78", "size": "20"}, {"price": "0.81", "size": "870"}, {"price": "0.85", "size": "125"}, {"price": "0.86", "size": "98"}, {"price": "0.87", "size": "750"}, {"price": "0.88", "size": "278"}, {"price": "0.89", "size": "1031.42"}], "asks": [{"price": "0.99", "size": "3092"}, {"price": "0.98", "size": "1000"}, {"price": "0.97", "size": "3000"}, {"price": "0.96", "size": "1100"}, {"price": "0.95", "size": "100"}, {"price": "0.93", "size": "2620.05"}, {"price": "0.92", "size": "256"}, {"price": "0.91", "size": "669.86"}, {"price": "0.9", "size": "24"}], "event_type": "book", "last_trade_price": "0.100"}, {"market": "0xffe62176c4eb6eb83ccff978b60f26f2c106398fa3c12f8f10c390069f1c0327", "asset_id": "98032013532486965224887573635135423443725925647904190791194069311921831803628", "timestamp": "1769383978912", "hash": "4d054d49026a1422130f822e524b27efb05eace0", "bids": [{"price": "0.001", "size": "59404"}, {"price": "0.002", "size": "250"}, {"price": "0.003", "size": "11.67"}, {"price": "0.004", "size": "6"}, {"price": "0.006", "size": "550"}, {"price": "0.007", "size": "12.01"}, {"price": "0.01", "size": "2600"}, {"price": "0.013", "size": "1536"}, {"price": "0.015", "size": "1700"}, {"price": "0.016", "size": "7.4"}, {"price": "0.02", "size": "4500"}, {"price": "0.022", "size": "1000"}, {"price": "0.025", "size": "2020"}, {"price": "0.027", "size": "1050"}, {"price": "0.028", "size": "230.16"}, {"price": "0.029", "size": "700"}, {"price": "0.03", "size": "310"}, {"price": "0.031", "size": "300"}, {"price": "0.032", "size": "24.01"}, {"price": "0.033", "size": "700"}], "asks": [{"price": "0.999", "size": "3697.08"}, {"price": "0.998", "size": "1250"}, {"price": "0.997", "size": "1407.33"}, {"price": "0.994", "size": "200"}, {"price": "0.993", "size": "10.77"}, {"price": "0.99", "size": "6750"}, {"price": "0.98", "size": "3700"}, {"price": "0.979", "size": "9.63"}, {"price": "0.96", "size": "1500"}, {"price": "0.95", "size": "730"}, {"price": "0.949", "size": "39"}, {"price": "0.94", "size": "375"}, {"price": "0.939", "size": "10.04"}, {"price": "0.9", "size": "560"}, {"price": "0.85", "size": "551.66"}, {"price": "0.849", "size": "1058"}, {"price": "0.81", "size": "418.42"}, {"price": "0.79", "size": "1600"}, {"price": "0.789", "size": "758"}, {"price": "0.788", "size": "5.07"}, {"price": "0.76", "size": "116.66"}, {"price": "0.748", "size": "150"}, {"price": "0.71", "size": "89.65"}, {"price": "0.66", "size": "70.58"}, {"price": "0.649", "size": "1000"}, {"price": "0.647", "size": "4613"}, {"price": "0.646", "size": "300"}, {"price": "0.61", "size": "126.28"}, {"price": "0.32", "size": "300"}, {"price": "0.316", "size": "431"}, {"price": "0.302", "size": "5"}, {"price": "0.299", "size": "175"}, {"price": "0.298", "size": "142"}, {"price": "0.16", "size": "20"}, {"price": "0.159", "size": "20"}, {"price": "0.158", "size": "20"}, {"price": "0.12", "size": "150"}, {"price": "0.119", "size": "100"}, {"price": "0.081", "size": "150"}, {"price": "0.061", "size": "153.66"}, {"price": "0.052", "size": "50"}, {"price": "0.046", "size": "55"}, {"price": "0.045", "size": "35.59"}, {"price": "0.044", "size": "25"}, {"price": "0.043", "size": "10"}], "event_type": "book", "last_trade_price": "0.036"}, {"market": "0x378f76341e555b6d54b89cc527afde5f8c293025cf6f48980145b94dc5726ce7", "asset_id": "100508935738063536113321312580877764668655616361107299342990907747250271040586", "timestamp": "1769383994182", "hash": "7e55f5bcda7e0bce17c64a249135e92907e71270", "bids": [{"price": "0.01", "size": "3092"}, {"price": "0.02", "size": "1000"}, {"price": "0.03", "size": "3000"}, {"price": "0.04", "size": "1100"}, {"price": "0.05", "size": "100"}, {"price": "0.07", "size": "2620.05"}, {"price": "0.08", "size": "256"}, {"price": "0.09", "size": "669.86"}, {"price": "0.1", "size": "24"}], "asks": [{"price": "0.99", "size": "6830"}, {"price": "0.98", "size": "3400"}, {"price": "0.96", "size": "1500"}, {"price": "0.95", "size": "30"}, {"price": "0.94", "size": "408"}, {"price": "0.91", "size": "400"}, {"price": "0.9", "size": "3500"}, {"price": "0.89", "size": "300"}, {"price": "0.86", "size": "567.85"}, {"price": "0.82", "size": "427.77"}, {"price": "0.78", "size": "726"}, {"price": "0.77", "size": "121.73"}, {"price": "0.74", "size": "150"}, {"price": "0.73", "size": "1650.29"}, {"price": "0.68", "size": "75"}, {"price": "0.64", "size": "1055.55"}, {"price": "0.62", "size": "930"}, {"price": "0.61", "size": "3638"}, {"price": "0.6", "size": "5"}, {"price": "0.36", "size": "760"}, {"price": "0.35", "size": "10"}, {"price": "0.23", "size": "20"}, {"price": "0.22", "size": "20"}, {"price": "0.19", "size": "870"}, {"price": "0.15", "size": "125"}, {"price": "0.14", "size": "98"}, {"price": "0.13", "size": "750"}, {"price": "0.12", "size": "278"}, {"price": "0.11", "size": "1031.42"}], "event_type": "book", "last_trade_price": "0.100"}, {"market": "0x8d8b98fb4c290c4e152ce8b653c5598b74a630dd1dbb800a5f328ea9c8b00727", "asset_id": "78474559114932529051705203752686517828085200880957778785050112163927946260911", "timestamp": "1769383999201", "hash": "794fc94347ef913c7359940aade3eb623d6a9292", "bids": [{"price": "0.001", "size": "3840.15"}, {"price": "0.002", "size": "1250"}, {"price": "0.003", "size": "1407.37"}, {"price": "0.006", "size": "200"}, {"price": "0.007", "size": "10.83"}, {"price": "0.01", "size": "6750"}, {"price": "0.02", "size": "3700"}, {"price": "0.021", "size": "9.67"}, {"price": "0.04", "size": "1500"}, {"price": "0.05", "size": "30"}, {"price": "0.051", "size": "39"}, {"price": "0.06", "size": "375"}, {"price": "0.061", "size": "9.45"}, {"price": "0.1", "size": "560"}, {"price": "0.105", "size": "2856"}, {"price": "0.106", "size": "300"}, {"price": "0.14", "size": "567.85"}, {"price": "0.19", "size": "168.42"}, {"price": "0.2", "size": "1050"}, {"price": "0.201", "size": "5.52"}, {"price": "0.24", "size": "116.66"}, {"price": "0.241", "size": "1892"}, {"price": "0.29", "size": "89.65"}, {"price": "0.34", "size": "70.58"}, {"price": "0.39", "size": "51.28"}, {"price": "0.399", "size": "1000"}, {"price": "0.4", "size": "1500"}, {"price": "0.46", "size": "840"}, {"price": "0.467", "size": "3510"}, {"price": "0.468", "size": "5"}, {"price": "0.469", "size": "454"}, {"price": "0.47", "size": "400"}, {"price": "0.505", "size": "10"}, {"price": "0.506", "size": "20"}, {"price": "0.87", "size": "850"}, {"price": "0.871", "size": "20"}, {"price": "0.872", "size": "20"}, {"price": "0.901", "size": "55"}, {"price": "0.921", "size": "62.39"}, {"price": "0.93", "size": "1000"}, {"price": "0.933", "size": "300"}, {"price": "0.934", "size": "55"}, {"price": "0.935", "size": "35.38"}, {"price": "0.936", "size": "10"}, {"price": "0.94", "size": "30"}, {"price": "0.942", "size": "50"}, {"price": "0.943", "size": "7.14"}], "asks": [{"price": "0.999", "size": "1581"}, {"price": "0.998", "size": "42.4"}, {"price": "0.992", "size": "7560.12"}, {"price": "0.989", "size": "100"}, {"price": "0.988", "size": "100"}, {"price": "0.987", "size": "12.7"}, {"price": "0.98", "size": "1055"}, {"price": "0.979", "size": "428"}, {"price": "0.978", "size": "314"}, {"price": "0.977", "size": "100"}, {"price": "0.97", "size": "55"}, {"price": "0.966", "size": "200"}, {"price": "0.964", "size": "96.56"}, {"price": "0.963", "size": "100"}, {"price": "0.962", "size": "26"}, {"price": "0.959", "size": "15"}, {"price": "0.958", "size": "35.04"}], "event_type": "book", "last_trade_price": "0.044"}, {"market": "0xc4b1f725c9398876af6cca482c700c5e385c6f00d042c4d890e27751fe438159", "asset_id": "36682362629639494488015513206921105629079574146230131761660121413854480955196", "timestamp": "1769383967044", "hash": "d11b71b022f4c49f835a985e939f60f4b6900cf5", "bids": [{"price": "0.001", "size": "3806.1"}, {"price": "0.002", "size": "1250"}, {"price": "0.003", "size": "1407.34"}, {"price": "0.006", "size": "200"}, {"price": "0.007", "size": "10.79"}, {"price": "0.01", "size": "6750"}, {"price": "0.02", "size": "3700"}, {"price": "0.021", "size": "9.64"}, {"price": "0.04", "size": "1500"}, {"price": "0.05", "size": "30"}, {"price": "0.051", "size": "39"}, {"price": "0.06", "size": "375"}, {"price": "0.061", "size": "9.43"}, {"price": "0.1", "size": "560"}, {"price": "0.15", "size": "551.66"}, {"price": "0.2", "size": "410"}, {"price": "0.201", "size": "5.53"}, {"price": "0.24", "size": "266.66"}, {"price": "0.29", "size": "89.65"}, {"price": "0.34", "size": "70.58"}, {"price": "0.39", "size": "51.28"}, {"price": "0.398", "size": "500"}, {"price": "0.404", "size": "840"}, {"price": "0.405", "size": "4690"}, {"price": "0.406", "size": "975"}, {"price": "0.425", "size": "5"}, {"price": "0.436", "size": "10"}, {"price": "0.437", "size": "20"}, {"price": "0.438", "size": "10"}, {"price": "0.863", "size": "560.74"}, {"price": "0.864", "size": "20"}, {"price": "0.89", "size": "850"}, {"price": "0.891", "size": "20"}, {"price": "0.948", "size": "165.19"}, {"price": "0.964", "size": "19.5"}, {"price": "0.967", "size": "6.45"}, {"price": "0.968", "size": "62.77"}, {"price": "0.969", "size": "300"}, {"price": "0.97", "size": "206.25"}, {"price": "0.971", "size": "169.94"}, {"price": "0.972", "size": "60"}, {"price": "0.973", "size": "10"}], "asks": [{"price": "0.999", "size": "4585"}, {"price": "0.998", "size": "4009.22"}, {"price": "0.997", "size": "2178.2"}, {"price": "0.996", "size": "1062.55"}, {"price": "0.995", "size": "1136.31"}, {"price": "0.994", "size": "250"}, {"price": "0.993", "size": "10.2"}, {"price": "0.99", "size": "1000"}, {"price": "0.989", "size": "7.94"}, {"price": "0.983", "size": "910"}, {"price": "0.982", "size": "499"}, {"price": "0.981", "size": "215.8"}, {"price": "0.98", "size": "60"}, {"price": "0.979", "size": "49.4"}], "event_type": "book", "last_trade_price": "0.021"}, {"market": "0x6a3bc08c62413e6594164bc15aa07b282b22a6d7efc61cd69df92b63f4132289", "asset_id": "5598960237790161917534060866496363286228389060029699153094526893891604621525", "timestamp": "1769383998787", "hash": "9b4ef3aab09d4e1484bd9f4deb07c75530dd7147", "bids": [{"price": "0.001", "size": "3980.43"}, {"price": "0.002", "size": "1250"}, {"price": "0.003", "size": "1407.33"}, {"price": "0.006", "size": "200"}, {"price": "0.007", "size": "10.77"}, {"price": "0.01", "size": "6750"}, {"price": "0.02", "size": "3400"}, {"price": "0.021", "size": "13.24"}, {"price": "0.04", "size": "1500"}, {"price": "0.05", "size": "30"}, {"price": "0.051", "size": "39"}, {"price": "0.06", "size": "375"}, {"price": "0.076", "size": "4500"}, {"price": "0.077", "size": "6.93"}, {"price": "0.1", "size": "360"}, {"price": "0.15", "size": "551.66"}, {"price": "0.2", "size": "410"}, {"price": "0.21", "size": "1900"}, {"price": "0.211", "size": "5.11"}, {"price": "0.231", "size": "8368"}, {"price": "0.232", "size": "300"}, {"price": "0.25", "size": "112"}, {"price": "0.253", "size": "7"}, {"price": "0.3", "size": "86.66"}, {"price": "0.35", "size": "68.57"}, {"price": "0.351", "size": "10"}, {"price": "0.4", "size": "125"}, {"price": "0.411", "size": "40"}, {"price": "0.415", "size": "20"}, {"price": "0.416", "size": "20"}, {"price": "0.91", "size": "3850"}, {"price": "0.911", "size": "84"}, {"price": "0.915", "size": "688"}, {"price": "0.987", "size": "1425.23"}, {"price": "0.99", "size": "49.3"}], "asks": [{"price": "0.999", "size": "4580"}, {"price": "0.998", "size": "800"}, {"price": "0.997", "size": "1100"}, {"price": "0.996", "size": "1342"}, {"price": "0.991", "size": "21176.2"}], "event_type": "book", "last_trade_price": "0.009"}, {"market": "0xd55b7e07b66b1d6702aa8f8c0c761a4f2838b55fa31395676bd0150b9fabb3a4", "asset_id": "100252164279000180790972381908103319470423853298906411193188634318600215482432", "timestamp": "1769383998791", "hash": "c704b4ac7ed14ff1dfe844c93a4970f02ad9f3db", "bids": [{"price": "0.001", "size": "2583.99"}, {"price": "0.002", "size": "21.26"}, {"price": "0.01", "size": "10"}, {"price": "0.011", "size": "5.68"}, {"price": "0.023", "size": "55"}, {"price": "0.025", "size": "9681.12"}, {"price": "0.026", "size": "300"}, {"price": "0.027", "size": "100"}, {"price": "0.028", "size": "55"}, {"price": "0.03", "size": "50"}, {"price": "0.039", "size": "282"}, {"price": "0.04", "size": "300"}, {"price": "0.045", "size": "100"}, {"price": "0.05", "size": "100"}, {"price": "0.054", "size": "600"}, {"price": "0.055", "size": "300"}, {"price": "0.056", "size": "333.62"}, {"price": "0.057", "size": "140"}, {"price": "0.061", "size": "39.2"}, {"price": "0.063", "size": "15"}, {"price": "0.064", "size": "213"}], "asks": [{"price": "0.999", "size": "3925.91"}, {"price": "0.998", "size": "1255.55"}, {"price": "0.997", "size": "1000"}, {"price": "0.996", "size": "23.07"}, {"price": "0.99", "size": "6750"}, {"price": "0.98", "size": "3700"}, {"price": "0.979", "size": "12.17"}, {"price": "0.96", "size": "1500"}, {"price": "0.95", "size": "30"}, {"price": "0.949", "size": "39"}, {"price": "0.94", "size": "375"}, {"price": "0.93", "size": "868.06"}, {"price": "0.929", "size": "7.13"}, {"price": "0.91", "size": "400"}, {"price": "0.86", "size": "242.85"}, {"price": "0.859", "size": "1459"}, {"price": "0.81", "size": "168.42"}, {"price": "0.804", "size": "1066"}, {"price": "0.802", "size": "300"}, {"price": "0.801", "size": "2115.67"}, {"price": "0.76", "size": "116.66"}, {"price": "0.759", "size": "150"}, {"price": "0.71", "size": "89.65"}, {"price": "0.67", "size": "72.72"}, {"price": "0.62", "size": "52.63"}, {"price": "0.598", "size": "500"}, {"price": "0.56", "size": "930"}, {"price": "0.558", "size": "3700"}, {"price": "0.557", "size": "1414"}, {"price": "0.556", "size": "5"}, {"price": "0.31", "size": "332.24"}, {"price": "0.309", "size": "257"}, {"price": "0.308", "size": "400"}, {"price": "0.285", "size": "139"}, {"price": "0.281", "size": "10"}, {"price": "0.279", "size": "20"}, {"price": "0.277", "size": "20"}, {"price": "0.276", "size": "20"}, {"price": "0.13", "size": "150"}, {"price": "0.091", "size": "110"}, {"price": "0.09", "size": "50"}, {"price": "0.082", "size": "300"}, {"price": "0.08", "size": "99.93"}, {"price": "0.074", "size": "8.01"}, {"price": "0.066", "size": "103.01"}], "event_type": "book", "last_trade_price": "0.066"}, {"market": "0xc512e0c0fa2d19ad6fe8bd885b3089a80fa2bf8382c104321c7359e7014cf567", "asset_id": "83334600217205368371784439992248024883439507053390974906923524834233064415427", "timestamp": "1769383999094", "hash": "5f60ebb2017b9859877834eb24543bbba836ef84", "bids": [{"price": "0.001", "size": "4749.52"}, {"price": "0.002", "size": "2250"}, {"price": "0.003", "size": "2832"}, {"price": "0.004", "size": "6.46"}, {"price": "0.02", "size": "400"}, {"price": "0.021", "size": "10.67"}, {"price": "0.07", "size": "1014.28"}, {"price": "0.1", "size": "101"}, {"price": "0.11", "size": "509.09"}, {"price": "0.14", "size": "228.57"}, {"price": "0.15", "size": "125"}, {"price": "0.151", "size": "1058"}, {"price": "0.17", "size": "164.7"}, {"price": "0.172", "size": "11.4"}, {"price": "0.18", "size": "3000"}, {"price": "0.195", "size": "4130"}, {"price": "0.196", "size": "2142"}, {"price": "0.21", "size": "123.8"}, {"price": "0.211", "size": "61"}, {"price": "0.24", "size": "100"}, {"price": "0.28", "size": "71.42"}, {"price": "0.286", "size": "150"}, {"price": "0.39", "size": "175"}, {"price": "0.5", "size": "29"}, {"price": "0.509", "size": "10"}, {"price": "0.511", "size": "10"}, {"price": "0.53", "size": "41.74"}, {"price": "0.57", "size": "850"}, {"price": "0.571", "size": "6"}, {"price": "0.6", "size": "20"}, {"price": "0.602", "size": "6"}, {"price": "0.62", "size": "2000"}, {"price": "0.633", "size": "156.66"}, {"price": "0.64", "size": "116.66"}, {"price": "0.641", "size": "6"}, {"price": "0.643", "size": "6"}, {"price": "0.646", "size": "310"}, {"price": "0.65", "size": "96.66"}, {"price": "0.651", "size": "33.24"}], "asks": [{"price": "0.999", "size": "3693.06"}, {"price": "0.998", "size": "1250"}, {"price": "0.997", "size": "12.82"}, {"price": "0.994", "size": "200"}, {"price": "0.993", "size": "5.44"}, {"price": "0.99", "size": "6750"}, {"price": "0.989", "size": "8.51"}, {"price": "0.98", "size": "3013.7"}, {"price": "0.979", "size": "11.53"}, {"price": "0.96", "size": "1500"}, {"price": "0.954", "size": "5400"}, {"price": "0.948", "size": "2500"}, {"price": "0.947", "size": "5.57"}, {"price": "0.94", "size": "375"}, {"price": "0.938", "size": "300"}, {"price": "0.92", "size": "1000"}, {"price": "0.918", "size": "200"}, {"price": "0.909", "size": "5.12"}, {"price": "0.85", "size": "1000"}, {"price": "0.842", "size": "1528.55"}, {"price": "0.841", "size": "5.11"}, {"price": "0.79", "size": "3000"}, {"price": "0.78", "size": "850"}, {"price": "0.779", "size": "958"}, {"price": "0.777", "size": "20"}, {"price": "0.77", "size": "20"}, {"price": "0.769", "size": "22.22"}, {"price": "0.767", "size": "20"}, {"price": "0.765", "size": "20"}, {"price": "0.764", "size": "20"}, {"price": "0.729", "size": "22.22"}, {"price": "0.714", "size": "6"}, {"price": "0.71", "size": "40.27"}, {"price": "0.704", "size": "389.88"}, {"price": "0.703", "size": "30"}, {"price": "0.702", "size": "50"}, {"price": "0.7", "size": "6"}, {"price": "0.698", "size": "6"}, {"price": "0.695", "size": "6"}, {"price": "0.688", "size": "32.22"}, {"price": "0.686", "size": "10"}, {"price": "0.685", "size": "11.1"}], "event_type": "book", "last_trade_price": "0.321"}, {"market": "0xc512e0c0fa2d19ad6fe8bd885b3089a80fa2bf8382c104321c7359e7014cf567", "asset_id": "107858355690036086153439322350404767983557761088489336428558005982078386490488", "timestamp": "1769383999094", "hash": "0434c4972b6877c2a57191ab7a27879f0cca3294", "bids": [{"price": "0.001", "size": "3693.06"}, {"price": "0.002", "size": "1250"}, {"price": "0.003", "size": "12.82"}, {"price": "0.006", "size": "200"}, {"price": "0.007", "size": "5.44"}, {"price": "0.01", "size": "6750"}, {"price": "0.011", "size": "8.51"}, {"price": "0.02", "size": "3013.7"}, {"price": "0.021", "size": "11.53"}, {"price": "0.04", "size": "1500"}, {"price": "0.046", "size": "5400"}, {"price": "0.052", "size": "2500"}, {"price": "0.053", "size": "5.57"}, {"price": "0.06", "size": "375"}, {"price": "0.062", "size": "300"}, {"price": "0.08", "size": "1000"}, {"price": "0.082", "size": "200"}, {"price": "0.091", "size": "5.12"}, {"price": "0.15", "size": "1000"}, {"price": "0.158", "size": "1528.55"}, {"price": "0.159", "size": "5.11"}, {"price": "0.21", "size": "3000"}, {"price": "0.22", "size": "850"}, {"price": "0.221", "size": "958"}, {"price": "0.223", "size": "20"}, {"price": "0.23", "size": "20"}, {"price": "0.231", "size": "22.22"}, {"price": "0.233", "size": "20"}, {"price": "0.235", "size": "20"}, {"price": "0.236", "size": "20"}, {"price": "0.271", "size": "22.22"}, {"price": "0.286", "size": "6"}, {"price": "0.29", "size": "40.27"}, {"price": "0.296", "size": "389.88"}, {"price": "0.297", "size": "30"}, {"price": "0.298", "size": "50"}, {"price": "0.3", "size": "6"}, {"price": "0.302", "size": "6"}, {"price": "0.305", "size": "6"}, {"price": "0.312", "size": "32.22"}, {"price": "0.314", "size": "10"}, {"price": "0.315", "size": "11.1"}], "asks": [{"price": "0.999", "size": "4749.52"}, {"price": "0.998", "size": "2250"}, {"price": "0.997", "size": "2832"}, {"price": "0.996", "size": "6.46"}, {"price": "0.98", "size": "400"}, {"price": "0.979", "size": "10.67"}, {"price": "0.93", "size": "1014.28"}, {"price": "0.9", "size": "101"}, {"price": "0.89", "size": "509.09"}, {"price": "0.86", "size": "228.57"}, {"price": "0.85", "size": "125"}, {"price": "0.849", "size": "1058"}, {"price": "0.83", "size": "164.7"}, {"price": "0.828", "size": "11.4"}, {"price": "0.82", "size": "3000"}, {"price": "0.805", "size": "4130"}, {"price": "0.804", "size": "2142"}, {"price": "0.79", "size": "123.8"}, {"price": "0.789", "size": "61"}, {"price": "0.76", "size": "100"}, {"price": "0.72", "size": "71.42"}, {"price": "0.714", "size": "150"}, {"price": "0.61", "size": "175"}, {"price": "0.5", "size": "29"}, {"price": "0.491", "size": "10"}, {"price": "0.489", "size": "10"}, {"price": "0.47", "size": "41.74"}, {"price": "0.43", "size": "850"}, {"price": "0.429", "size": "6"}, {"price": "0.4", "size": "20"}, {"price": "0.398", "size": "6"}, {"price": "0.38", "size": "2000"}, {"price": "0.367", "size": "156.66"}, {"price": "0.36", "size": "116.66"}, {"price": "0.359", "size": "6"}, {"price": "0.357", "size": "6"}, {"price": "0.354", "size": "310"}, {"price": "0.35", "size": "96.66"}, {"price": "0.349", "size": "33.24"}], "event_type": "book", "last_trade_price": "0.321"}, {"market": "0xffe62176c4eb6eb83ccff978b60f26f2c106398fa3c12f8f10c390069f1c0327", "asset_id": "96053159599260004603905372121344488945548265884928713587631467689929621790840", "timestamp": "1769383978912", "hash": "fcc23c8ff074cfb722fd668648f501b7ed7b7aac", "bids": [{"price": "0.001", "size": "3697.08"}, {"price": "0.002", "size": "1250"}, {"price": "0.003", "size": "1407.33"}, {"price": "0.006", "size": "200"}, {"price": "0.007", "size": "10.77"}, {"price": "0.01", "size": "6750"}, {"price": "0.02", "size": "3700"}, {"price": "0.021", "size": "9.63"}, {"price": "0.04", "size": "1500"}, {"price": "0.05", "size": "730"}, {"price": "0.051", "size": "39"}, {"price": "0.06", "size": "375"}, {"price": "0.061", "size": "10.04"}, {"price": "0.1", "size": "560"}, {"price": "0.15", "size": "551.66"}, {"price": "0.151", "size": "1058"}, {"price": "0.19", "size": "418.42"}, {"price": "0.21", "size": "1600"}, {"price": "0.211", "size": "758"}, {"price": "0.212", "size": "5.07"}, {"price": "0.24", "size": "116.66"}, {"price": "0.252", "size": "150"}, {"price": "0.29", "size": "89.65"}, {"price": "0.34", "size": "70.58"}, {"price": "0.351", "size": "1000"}, {"price": "0.353", "size": "4613"}, {"price": "0.354", "size": "300"}, {"price": "0.39", "size": "126.28"}, {"price": "0.68", "size": "300"}, {"price": "0.684", "size": "431"}, {"price": "0.698", "size": "5"}, {"price": "0.701", "size": "175"}, {"price": "0.702", "size": "142"}, {"price": "0.84", "size": "20"}, {"price": "0.841", "size": "20"}, {"price": "0.842", "size": "20"}, {"price": "0.88", "size": "150"}, {"price": "0.881", "size": "100"}, {"price": "0.919", "size": "150"}, {"price": "0.939", "size": "153.66"}, {"price": "0.948", "size": "50"}, {"price": "0.954", "size": "55"}, {"price": "0.955", "size": "35.59"}, {"price": "0.956", "size": "25"}, {"price": "0.957", "size": "10"}], "asks": [{"price": "0.999", "size": "59404"}, {"price": "0.998", "size": "250"}, {"price": "0.997", "size": "11.67"}, {"price": "0.996", "size": "6"}, {"price": "0.994", "size": "550"}, {"price": "0.993", "size": "12.01"}, {"price": "0.99", "size": "2600"}, {"price": "0.987", "size": "1536"}, {"price": "0.985", "size": "1700"}, {"price": "0.984", "size": "7.4"}, {"price": "0.98", "size": "4500"}, {"price": "0.978", "size": "1000"}, {"price": "0.975", "size": "2020"}, {"price": "0.973", "size": "1050"}, {"price": "0.972", "size": "230.16"}, {"price": "0.971", "size": "700"}, {"price": "0.97", "size": "310"}, {"price": "0.969", "size": "300"}, {"price": "0.968", "size": "24.01"}, {"price": "0.967", "size": "700"}], "event_type": "book", "last_trade_price": "0.036"}, {"market": "0x8d8b98fb4c290c4e152ce8b653c5598b74a630dd1dbb800a5f328ea9c8b00727", "asset_id": "80938914484826983068438930343848557974856639667615266122989436725895029352478", "timestamp": "1769383999201", "hash": "9f3d3e1396b33ed338ad3417f44b4b43fad7051f", "bids": [{"price": "0.001", "size": "1581"}, {"price": "0.002", "size": "42.4"}, {"price": "0.008", "size": "7560.12"}, {"price": "0.011", "size": "100"}, {"price": "0.012", "size": "100"}, {"price": "0.013", "size": "12.7"}, {"price": "0.02", "size": "1055"}, {"price": "0.021", "size": "428"}, {"price": "0.022", "size": "314"}, {"price": "0.023", "size": "100"}, {"price": "0.03", "size": "55"}, {"price": "0.034", "size": "200"}, {"price": "0.036", "size": "96.56"}, {"price": "0.037", "size": "100"}, {"price": "0.038", "size": "26"}, {"price": "0.041", "size": "15"}, {"price": "0.042", "size": "35.04"}], "asks": [{"price": "0.999", "size": "3840.15"}, {"price": "0.998", "size": "1250"}, {"price": "0.997", "size": "1407.37"}, {"price": "0.994", "size": "200"}, {"price": "0.993", "size": "10.83"}, {"price": "0.99", "size": "6750"}, {"price": "0.98", "size": "3700"}, {"price": "0.979", "size": "9.67"}, {"price": "0.96", "size": "1500"}, {"price": "0.95", "size": "30"}, {"price": "0.949", "size": "39"}, {"price": "0.94", "size": "375"}, {"price": "0.939", "size": "9.45"}, {"price": "0.9", "size": "560"}, {"price": "0.895", "size": "2856"}, {"price": "0.894", "size": "300"}, {"price": "0.86", "size": "567.85"}, {"price": "0.81", "size": "168.42"}, {"price": "0.8", "size": "1050"}, {"price": "0.799", "size": "5.52"}, {"price": "0.76", "size": "116.66"}, {"price": "0.759", "size": "1892"}, {"price": "0.71", "size": "89.65"}, {"price": "0.66", "size": "70.58"}, {"price": "0.61", "size": "51.28"}, {"price": "0.601", "size": "1000"}, {"price": "0.6", "size": "1500"}, {"price": "0.54", "size": "840"}, {"price": "0.533", "size": "3510"}, {"price": "0.532", "size": "5"}, {"price": "0.531", "size": "454"}, {"price": "0.53", "size": "400"}, {"price": "0.495", "size": "10"}, {"price": "0.494", "size": "20"}, {"price": "0.13", "size": "850"}, {"price": "0.129", "size": "20"}, {"price": "0.128", "size": "20"}, {"price": "0.099", "size": "55"}, {"price": "0.079", "size": "62.39"}, {"price": "0.07", "size": "1000"}, {"price": "0.067", "size": "300"}, {"price": "0.066", "size": "55"}, {"price": "0.065", "size": "35.38"}, {"price": "0.064", "size": "10"}, {"price": "0.06", "size": "30"}, {"price": "0.058", "size": "50"}, {"price": "0.057", "size": "7.14"}], "event_type": "book", "last_trade_price": "0.044"}, {"market": "0x32821c03c1a785af6bea72291b578e722f02f7da80e204c42be3dee38694756f", "asset_id": "46526486688025872076957171866031437643304744954855308137561748620272587627152", "timestamp": "1769383994441", "hash": "583091b4960702b5602161643fafd089a69659fc", "bids": [{"price": "0.001", "size": "5527"}, {"price": "0.002", "size": "49.98"}, {"price": "0.006", "size": "436.81"}, {"price": "0.007", "size": "11.3"}, {"price": "0.009", "size": "10"}, {"price": "0.01", "size": "3200"}, {"price": "0.011", "size": "250"}, {"price": "0.012", "size": "222.91"}, {"price": "0.02", "size": "15"}, {"price": "0.021", "size": "10"}, {"price": "0.022", "size": "102.59"}], "asks": [{"price": "0.999", "size": "3262.78"}, {"price": "0.998", "size": "1250"}, {"price": "0.997", "size": "1173.36"}, {"price": "0.994", "size": "83"}, {"price": "0.993", "size": "10.81"}, {"price": "0.99", "size": "6750"}, {"price": "0.98", "size": "3000"}, {"price": "0.979", "size": "9.66"}, {"price": "0.96", "size": "1500"}, {"price": "0.954", "size": "5700"}, {"price": "0.95", "size": "30"}, {"price": "0.949", "size": "39"}, {"price": "0.94", "size": "375"}, {"price": "0.939", "size": "8.82"}, {"price": "0.9", "size": "560"}, {"price": "0.85", "size": "551.66"}, {"price": "0.8", "size": "410"}, {"price": "0.799", "size": "5.72"}, {"price": "0.758", "size": "1042"}, {"price": "0.75", "size": "112"}, {"price": "0.71", "size": "89.65"}, {"price": "0.702", "size": "6536"}, {"price": "0.701", "size": "300"}, {"price": "0.66", "size": "70.58"}, {"price": "0.61", "size": "51.28"}, {"price": "0.609", "size": "986"}, {"price": "0.548", "size": "573"}, {"price": "0.544", "size": "5"}, {"price": "0.543", "size": "20"}, {"price": "0.517", "size": "175"}, {"price": "0.516", "size": "20"}, {"price": "0.515", "size": "20"}, {"price": "0.11", "size": "850"}, {"price": "0.042", "size": "300"}, {"price": "0.041", "size": "394.7"}, {"price": "0.04", "size": "123.12"}, {"price": "0.038", "size": "12.5"}, {"price": "0.037", "size": "59.8"}, {"price": "0.036", "size": "24.6"}, {"price": "0.034", "size": "17"}, {"price": "0.033", "size": "245.94"}, {"price": "0.031", "size": "30"}], "event_type": "book", "last_trade_price": "0.977"}, {"market": "0x6a3bc08c62413e6594164bc15aa07b282b22a6d7efc61cd69df92b63f4132289", "asset_id": "99482729937705145912235477495415874028392807588978105657655512338616047660547", "timestamp": "1769383998787", "hash": "fe02001bbe59c2a1a8d8cffff2a423b73c71ff1c", "bids": [{"price": "0.001", "size": "4580"}, {"price": "0.002", "size": "800"}, {"price": "0.003", "size": "1100"}, {"price": "0.004", "size": "1342"}, {"price": "0.009", "size": "21176.2"}], "asks": [{"price": "0.999", "size": "3980.43"}, {"price": "0.998", "size": "1250"}, {"price": "0.997", "size": "1407.33"}, {"price": "0.994", "size": "200"}, {"price": "0.993", "size": "10.77"}, {"price": "0.99", "size": "6750"}, {"price": "0.98", "size": "3400"}, {"price": "0.979", "size": "13.24"}, {"price": "0.96", "size": "1500"}, {"price": "0.95", "size": "30"}, {"price": "0.949", "size": "39"}, {"price": "0.94", "size": "375"}, {"price": "0.924", "size": "4500"}, {"price": "0.923", "size": "6.93"}, {"price": "0.9", "size": "360"}, {"price": "0.85", "size": "551.66"}, {"price": "0.8", "size": "410"}, {"price": "0.79", "size": "1900"}, {"price": "0.789", "size": "5.11"}, {"price": "0.769", "size": "8368"}, {"price": "0.768", "size": "300"}, {"price": "0.75", "size": "112"}, {"price": "0.747", "size": "7"}, {"price": "0.7", "size": "86.66"}, {"price": "0.65", "size": "68.57"}, {"price": "0.649", "size": "10"}, {"price": "0.6", "size": "125"}, {"price": "0.589", "size": "40"}, {"price": "0.585", "size": "20"}, {"price": "0.584", "size": "20"}, {"price": "0.09", "size": "3850"}, {"price": "0.089", "size": "84"}, {"price": "0.085", "size": "688"}, {"price": "0.013", "size": "1425.23"}, {"price": "0.01", "size": "49.3"}], "event_type": "book", "last_trade_price": "0.009"}, {"market": "0xc4b1f725c9398876af6cca482c700c5e385c6f00d042c4d890e27751fe438159", "asset_id": "73358948829688554251799945001823247657631792677595071371964098966398235853723", "timestamp": "1769383967044", "hash": "863c2de391f5dce8706b111d5bbb19f0b16def5b", "bids": [{"price": "0.001", "size": "4585"}, {"price": "0.002", "size": "4009.22"}, {"price": "0.003", "size": "2178.2"}, {"price": "0.004", "size": "1062.55"}, {"price": "0.005", "size": "1136.31"}, {"price": "0.006", "size": "250"}, {"price": "0.007", "size": "10.2"}, {"price": "0.01", "size": "1000"}, {"price": "0.011", "size": "7.94"}, {"price": "0.017", "size": "910"}, {"price": "0.018", "size": "499"}, {"price": "0.019", "size": "215.8"}, {"price": "0.02", "size": "60"}, {"price": "0.021", "size": "49.4"}], "asks": [{"price": "0.999", "size": "3806.1"}, {"price": "0.998", "size": "1250"}, {"price": "0.997", "size": "1407.34"}, {"price": "0.994", "size": "200"}, {"price": "0.993", "size": "10.79"}, {"price": "0.99", "size": "6750"}, {"price": "0.98", "size": "3700"}, {"price": "0.979", "size": "9.64"}, {"price": "0.96", "size": "1500"}, {"price": "0.95", "size": "30"}, {"price": "0.949", "size": "39"}, {"price": "0.94", "size": "375"}, {"price": "0.939", "size": "9.43"}, {"price": "0.9", "size": "560"}, {"price": "0.85", "size": "551.66"}, {"price": "0.8", "size": "410"}, {"price": "0.799", "size": "5.53"}, {"price": "0.76", "size": "266.66"}, {"price": "0.71", "size": "89.65"}, {"price": "0.66", "size": "70.58"}, {"price": "0.61", "size": "51.28"}, {"price": "0.602", "size": "500"}, {"price": "0.596", "size": "840"}, {"price": "0.595", "size": "4690"}, {"price": "0.594", "size": "975"}, {"price": "0.575", "size": "5"}, {"price": "0.564", "size": "10"}, {"price": "0.563", "size": "20"}, {"price": "0.562", "size": "10"}, {"price": "0.137", "size": "560.74"}, {"price": "0.136", "size": "20"}, {"price": "0.11", "size": "850"}, {"price": "0.109", "size": "20"}, {"price": "0.052", "size": "165.19"}, {"price": "0.036", "size": "19.5"}, {"price": "0.033", "size": "6.45"}, {"price": "0.032", "size": "62.77"}, {"price": "0.031", "size": "300"}, {"price": "0.03", "size": "206.25"}, {"price": "0.029", "size": "169.94"}, {"price": "0.028", "size": "60"}, {"price": "0.027", "size": "10"}], "event_type": "book", "last_trade_price": "0.021"}]}
{"_local_timestamp": "2026-01-25T23:33:19.715912+00:00", "data": {"market": "0xc512e0c0fa2d19ad6fe8bd885b3089a80fa2bf8382c104321c7359e7014cf567", "price_changes": [{"asset_id": "107858355690036086153439322350404767983557761088489336428558005982078386490488", "price": "0.297", "size": "0", "side": "BUY", "hash": "a2709e0b3c35f3f01f3a58ab2c9eb1496a69cc68", "best_bid": "0.315", "best_ask": "0.349"}, {"asset_id": "83334600217205368371784439992248024883439507053390974906923524834233064415427", "price": "0.703", "size": "0", "side": "SELL", "hash": "c5e0571a8886239273d0abade2d062432d491302", "best_bid": "0.651", "best_ask": "0.685"}], "timestamp": "1769383999641", "event_type": "price_change"}}
{"_local_timestamp": "2026-01-25T23:33:19.716606+00:00", "data": {"market": "0x8d8b98fb4c290c4e152ce8b653c5598b74a630dd1dbb800a5f328ea9c8b00727", "price_changes": [{"asset_id": "78474559114932529051705203752686517828085200880957778785050112163927946260911", "price": "0.94", "size": "0", "side": "BUY", "hash": "c79496e01914de2827c7bfc56779411c573869d2", "best_bid": "0.943", "best_ask": "0.958"}, {"asset_id": "80938914484826983068438930343848557974856639667615266122989436725895029352478", "price": "0.06", "size": "0", "side": "SELL", "hash": "3d7eac554a8eb87b1c2712d2f84d135c62670bca", "best_bid": "0.042", "best_ask": "0.057"}], "timestamp": "1769383999641", "event_type": "price_change"}}
{"_local_timestamp": "2026-01-25T23:33:19.773222+00:00", "data": {"market": "0x8d8b98fb4c290c4e152ce8b653c5598b74a630dd1dbb800a5f328ea9c8b00727", "price_changes": [{"asset_id": "78474559114932529051705203752686517828085200880957778785050112163927946260911", "price": "0.934", "size": "85", "side": "BUY", "hash": "c6cf847bbae235df49c922c633ca4be9a28f68b5", "best_bid": "0.943", "best_ask": "0.958"}, {"asset_id": "80938914484826983068438930343848557974856639667615266122989436725895029352478", "price": "0.066", "size": "85", "side": "SELL", "hash": "457633c3088a2670315a03892856aa8b4c033b4b", "best_bid": "0.042", "best_ask": "0.057"}], "timestamp": "1769383999707", "event_type": "price_change"}}
{"_local_timestamp": "2026-01-25T23:33:19.817074+00:00", "data": {"market": "0x6a3bc08c62413e6594164bc15aa07b282b22a6d7efc61cd69df92b63f4132289", "price_changes": [{"asset_id": "5598960237790161917534060866496363286228389060029699153094526893891604621525", "price": "0.915", "size": "713", "side": "BUY", "hash": "e8fbcf908dce336a531f912d6131ec3e840bc71c", "best_bid": "0.99", "best_ask": "0.991"}, {"asset_id": "99482729937705145912235477495415874028392807588978105657655512338616047660547", "price": "0.085", "size": "713", "side": "SELL", "hash": "6723093eca351cc8d7a9a61a315b7f36efaa7b42", "best_bid": "0.009", "best_ask": "0.01"}], "timestamp": "1769383999754", "event_type": "price_change"}}
{"_local_timestamp": "2026-01-25T23:33:19.947550+00:00", "data": {"market": "0x6a3bc08c62413e6594164bc15aa07b282b22a6d7efc61cd69df92b63f4132289", "price_changes": [{"asset_id": "5598960237790161917534060866496363286228389060029699153094526893891604621525", "price": "0.915", "size": "688", "side": "BUY", "hash": "422d9a460b7b3d85cea19fba0367fe69d42d3102", "best_bid": "0.99", "best_ask": "0.991"}, {"asset_id": "99482729937705145912235477495415874028392807588978105657655512338616047660547", "price": "0.085", "size": "688", "side": "SELL", "hash": "4e8c3948de4af56aa6ce38c95f419c25a7e9831b", "best_bid": "0.009", "best_ask": "0.01"}], "timestamp": "1769383999878", "event_type": "price_change"}}
{"_local_timestamp": "2026-01-25T23:33:20.953501+00:00", "data": {"market": "0x8d8b98fb4c290c4e152ce8b653c5598b74a630dd1dbb800a5f328ea9c8b00727", "price_changes": [{"asset_id": "78474559114932529051705203752686517828085200880957778785050112163927946260911", "price": "0.934", "size": "55", "side": "BUY", "hash": "e8889a0b6aa05fa988c53ff70278d5db3ff445be", "best_bid": "0.943", "best_ask": "0.958"}, {"asset_id": "80938914484826983068438930343848557974856639667615266122989436725895029352478", "price": "0.066", "size": "55", "side": "SELL", "hash": "25f618c86c82478493d762ca961b17423bf4c406", "best_bid": "0.042", "best_ask": "0.057"}], "timestamp": "1769384000885", "event_type": "price_change"}}
{"_local_timestamp": "2026-01-25T23:33:21.173109+00:00", "data": {"market": "0x6a3bc08c62413e6594164bc15aa07b282b22a6d7efc61cd69df92b63f4132289", "price_changes": [{"asset_id": "5598960237790161917534060866496363286228389060029699153094526893891604621525", "price": "0.915", "size": "713", "side": "BUY", "hash": "02a2b31474fecadd77b488250d244e4cb0b07eaf", "best_bid": "0.99", "best_ask": "0.991"}, {"asset_id": "99482729937705145912235477495415874028392807588978105657655512338616047660547", "price": "0.085", "size": "713", "side": "SELL", "hash": "ad014901fe685c59fe4dde001516cf90ef2ee65c", "best_bid": "0.009", "best_ask": "0.01"}], "timestamp": "1769384001103", "event_type": "price_change"}}
{"_local_timestamp": "2026-01-25T23:33:21.272618+00:00", "data": {"market": "0x6a3bc08c62413e6594164bc15aa07b282b22a6d7efc61cd69df92b63f4132289", "price_changes": [{"asset_id": "5598960237790161917534060866496363286228389060029699153094526893891604621525", "price": "0.915", "size": "688", "side": "BUY", "hash": "9655c92e49866da3bdda038f0d605819468ba0d3", "best_bid": "0.99", "best_ask": "0.991"}, {"asset_id": "99482729937705145912235477495415874028392807588978105657655512338616047660547", "price": "0.085", "size": "688", "side": "SELL", "hash": "5101b6ac50d56eeaa020534fba11a9476c11613e", "best_bid": "0.009", "best_ask": "0.01"}], "timestamp": "1769384001207", "event_type": "price_change"}}
{"_local_timestamp": "2026-01-25T23:33:21.289757+00:00", "data": {"market": "0xd55b7e07b66b1d6702aa8f8c0c761a4f2838b55fa31395676bd0150b9fabb3a4", "price_changes": [{"asset_id": "100252164279000180790972381908103319470423853298906411193188634318600215482432", "price": "0.063", "size": "65", "side": "BUY", "hash": "20695e2a4a8859e2d2853d0ea5cf60475b821a75", "best_bid": "0.064", "best_ask": "0.066"}, {"asset_id": "71934813421791148309055586854264573769390957341135501297936685395378523616284", "price": "0.937", "size": "65", "side": "SELL", "hash": "7edcdb6fc9937564d3ef74c2e7313d97b49c2646", "best_bid": "0.934", "best_ask": "0.936"}], "timestamp": "1769384001221", "event_type": "price_change"}}
{"_local_timestamp": "2026-01-25T23:33:21.540993+00:00", "data": {"market": "0xd55b7e07b66b1d6702aa8f8c0c761a4f2838b55fa31395676bd0150b9fabb3a4", "price_changes": [{"asset_id": "71934813421791148309055586854264573769390957341135501297936685395378523616284", "price": "0.933", "size": "50", "side": "BUY", "hash": "4f92ec0cc86342aa98e794e7747e098caf6b6005", "best_bid": "0.934", "best_ask": "0.936"}, {"asset_id": "100252164279000180790972381908103319470423853298906411193188634318600215482432", "price": "0.067", "size": "50", "side": "SELL", "hash": "623b8843f7745854ba64b7b7b83ae79aa5fd2e04", "best_bid": "0.064", "best_ask": "0.066"}], "timestamp": "1769384001469", "event_type": "price_change"}}
{"_local_timestamp": "2026-01-25T23:33:21.557404+00:00", "data": {"market": "0xd55b7e07b66b1d6702aa8f8c0c761a4f2838b55fa31395676bd0150b9fabb3a4", "price_changes": [{"asset_id": "100252164279000180790972381908103319470423853298906411193188634318600215482432", "price": "0.064", "size": "10", "side": "BUY", "hash": "3144a7a212e00ef84b40839fdf579b2fff8c692f", "best_bid": "0.064", "best_ask": "0.066"}, {"asset_id": "71934813421791148309055586854264573769390957341135501297936685395378523616284", "price": "0.936", "size": "10", "side": "SELL", "hash": "dcd41a9977dd6618a45ff1d43e8bd98d1cafc8cd", "best_bid": "0.934", "best_ask": "0.936"}], "timestamp": "1769384001493", "event_type": "price_change"}}
{"_local_timestamp": "2026-01-25T23:33:21.584852+00:00", "data": {"market": "0xd55b7e07b66b1d6702aa8f8c0c761a4f2838b55fa31395676bd0150b9fabb3a4", "price_changes": [{"asset_id": "71934813421791148309055586854264573769390957341135501297936685395378523616284", "price": "0.939", "size": "200.2", "side": "SELL", "hash": "46a3345e91953aeb2608fb5e199c3f7156f47031", "best_bid": "0.934", "best_ask": "0.936"}, {"asset_id": "100252164279000180790972381908103319470423853298906411193188634318600215482432", "price": "0.061", "size": "200.2", "side": "BUY", "hash": "5b736e57c12d0ef52edb1d436b2cf519b4d8984a", "best_bid": "0.064", "best_ask": "0.066"}], "timestamp": "1769384001522", "event_type": "price_change"}}
{"_local_timestamp": "2026-01-25T23:33:21.710105+00:00", "data": {"market": "0xc512e0c0fa2d19ad6fe8bd885b3089a80fa2bf8382c104321c7359e7014cf567", "price_changes": [{"asset_id": "107858355690036086153439322350404767983557761088489336428558005982078386490488", "price": "0.223", "size": "0", "side": "BUY", "hash": "48aeb8f38ded5ac3b631179be047e54572a30df5", "best_bid": "0.315", "best_ask": "0.349"}, {"asset_id": "83334600217205368371784439992248024883439507053390974906923524834233064415427", "price": "0.777", "size": "0", "side": "SELL", "hash": "855739f2635234d7b7b77df79050ac504b4709b5", "best_bid": "0.651", "best_ask": "0.685"}], "timestamp": "1769384001643", "event_type": "price_change"}}
{"_local_timestamp": "2026-01-25T23:33:21.816900+00:00", "data": {"market": "0xc512e0c0fa2d19ad6fe8bd885b3089a80fa2bf8382c104321c7359e7014cf567", "price_changes": [{"asset_id": "107858355690036086153439322350404767983557761088489336428558005982078386490488", "price": "0.222", "size": "20", "side": "BUY", "hash": "3dea3c42c185a1b0ae8832aaeacdb156a3f218e1", "best_bid": "0.315", "best_ask": "0.349"}, {"asset_id": "83334600217205368371784439992248024883439507053390974906923524834233064415427", "price": "0.778", "size": "20", "side": "SELL", "hash": "c2655c81bc29941311b6a9bbc8e425076f687fe8", "best_bid": "0.651", "best_ask": "0.685"}], "timestamp": "1769384001751", "event_type": "price_change"}}
{"_local_timestamp": "2026-01-25T23:33:22.253467+00:00", "data": {"market": "0x8d8b98fb4c290c4e152ce8b653c5598b74a630dd1dbb800a5f328ea9c8b00727", "price_changes": [{"asset_id": "80938914484826983068438930343848557974856639667615266122989436725895029352478", "price": "0.02", "size": "55", "side": "BUY", "hash": "8f15950c6f2c47c46f093d24a5337974a8a80736", "best_bid": "0.042", "best_ask": "0.057"}, {"asset_id": "78474559114932529051705203752686517828085200880957778785050112163927946260911", "price": "0.98", "size": "55", "side": "SELL", "hash": "3d2fa5ff78b042205ac16f56d53fbdaf06ffa6ac", "best_bid": "0.943", "best_ask": "0.958"}], "timestamp": "1769384002187", "event_type": "price_change"}}
{"_local_timestamp": "2026-01-25T23:33:22.269162+00:00", "data": {"market": "0x8d8b98fb4c290c4e152ce8b653c5598b74a630dd1dbb800a5f328ea9c8b00727", "price_changes": [{"asset_id": "80938914484826983068438930343848557974856639667615266122989436725895029352478", "price": "0.01", "size": "2000", "side": "BUY", "hash": "37b700fb8f9f9bb35f5819178b60285ba8c816b1", "best_bid": "0.042", "best_ask": "0.057"}, {"asset_id": "78474559114932529051705203752686517828085200880957778785050112163927946260911", "price": "0.99", "size": "2000", "side": "SELL", "hash": "224d1e3b1b159ee013e9e58ad7aee9facb4828bf", "best_bid": "0.943", "best_ask": "0.958"}], "timestamp": "1769384002200", "event_type": "price_change"}}
{"_local_timestamp": "2026-01-25T23:33:22.361064+00:00", "data": {"market": "0x6a3bc08c62413e6594164bc15aa07b282b22a6d7efc61cd69df92b63f4132289", "price_changes": [{"asset_id": "5598960237790161917534060866496363286228389060029699153094526893891604621525", "price": "0.914", "size": "25", "side": "BUY", "hash": "45233d526f6e3c968916c54c67c6613559aba4af", "best_bid": "0.99", "best_ask": "0.991"}, {"asset_id": "99482729937705145912235477495415874028392807588978105657655512338616047660547", "price": "0.086", "size": "25", "side": "SELL", "hash": "e5f28291d7bb8ce2c43bb7bbae005e0a75296893", "best_bid": "0.009", "best_ask": "0.01"}], "timestamp": "1769384002295", "event_type": "price_change"}}
{"_local_timestamp": "2026-01-25T23:33:22.469191+00:00", "data": {"market": "0x6a3bc08c62413e6594164bc15aa07b282b22a6d7efc61cd69df92b63f4132289", "price_changes": [{"asset_id": "5598960237790161917534060866496363286228389060029699153094526893891604621525", "price": "0.914", "size": "0", "side": "BUY", "hash": "863bdc4086886ae6c831fe7f4a5c1c8538bdcbb6", "best_bid": "0.99", "best_ask": "0.991"}, {"asset_id": "99482729937705145912235477495415874028392807588978105657655512338616047660547", "price": "0.086", "size": "0", "side": "SELL", "hash": "ab07d317028661c836029d5eff31420ad3f4f562", "best_bid": "0.009", "best_ask": "0.01"}], "timestamp": "1769384002402", "event_type": "price_change"}}
{"_local_timestamp": "2026-01-25T23:33:23.621316+00:00", "data": {"market": "0x8d8b98fb4c290c4e152ce8b653c5598b74a630dd1dbb800a5f328ea9c8b00727", "price_changes": [{"asset_id": "78474559114932529051705203752686517828085200880957778785050112163927946260911", "price": "0.936", "size": "60", "side": "BUY", "hash": "82c3451591eecb2bf8fe882a6f712fab87daa617", "best_bid": "0.943", "best_ask": "0.958"}, {"asset_id": "80938914484826983068438930343848557974856639667615266122989436725895029352478", "price": "0.064", "size": "60", "side": "SELL", "hash": "50c8cf76b72ce9a0fe45ab29a267e2ff6e6efc61", "best_bid": "0.042", "best_ask": "0.057"}], "timestamp": "1769384003540", "event_type": "price_change"}}
{"_local_timestamp": "2026-01-25T23:33:23.621783+00:00", "data": {"market": "0xc512e0c0fa2d19ad6fe8bd885b3089a80fa2bf8382c104321c7359e7014cf567", "price_changes": [{"asset_id": "107858355690036086153439322350404767983557761088489336428558005982078386490488", "price": "0.313", "size": "50", "side": "BUY", "hash": "a9bb2e51b03b4bd1001a169b2da8ffbe0545aff5", "best_bid": "0.315", "best_ask": "0.349"}, {"asset_id": "83334600217205368371784439992248024883439507053390974906923524834233064415427", "price": "0.687", "size": "50", "side": "SELL", "hash": "2a759cb99b6ee74da3580f567dec4fb14e70a205", "best_bid": "0.651", "best_ask": "0.685"}], "timestamp": "1769384003542", "event_type": "price_change"}}
{"_local_timestamp": "2026-01-25T23:33:23.733840+00:00", "data": {"market": "0x6a3bc08c62413e6594164bc15aa07b282b22a6d7efc61cd69df92b63f4132289", "price_changes": [{"asset_id": "5598960237790161917534060866496363286228389060029699153094526893891604621525", "price": "0.914", "size": "25", "side": "BUY", "hash": "520ab09f547bfe0cb43e0b63a3ef6953cb6e7194", "best_bid": "0.99", "best_ask": "0.991"}, {"asset_id": "99482729937705145912235477495415874028392807588978105657655512338616047660547", "price": "0.086", "size": "25", "side": "SELL", "hash": "587f1cb1070124fed8d93048a1e473f8e63a0e14", "best_bid": "0.009", "best_ask": "0.01"}], "timestamp": "1769384003666", "event_type": "price_change"}}
{"_local_timestamp": "2026-01-25T23:33:23.759598+00:00", "data": {"market": "0x6a3bc08c62413e6594164bc15aa07b282b22a6d7efc61cd69df92b63f4132289", "price_changes": [{"asset_id": "99482729937705145912235477495415874028392807588978105657655512338616047660547", "price": "0.085", "size": "0", "side": "SELL", "hash": "cc99b9eaff94629bf44fd95b8a89f41e0851af73", "best_bid": "0.009", "best_ask": "0.01"}, {"asset_id": "5598960237790161917534060866496363286228389060029699153094526893891604621525", "price": "0.915", "size": "0", "side": "BUY", "hash": "2d3a9d2301e43de799ec1245ad7fcd989e9a266c", "best_bid": "0.99", "best_ask": "0.991"}], "timestamp": "1769384003691", "event_type": "price_change"}}
{"_local_timestamp": "2026-01-25T23:33:23.793377+00:00", "data": {"market": "0x6a3bc08c62413e6594164bc15aa07b282b22a6d7efc61cd69df92b63f4132289", "price_changes": [{"asset_id": "99482729937705145912235477495415874028392807588978105657655512338616047660547", "price": "0.086", "size": "738", "side": "SELL", "hash": "49e43ca1506654f8b41d4ee2ac0b2cdb81abbe4d", "best_bid": "0.009", "best_ask": "0.01"}, {"asset_id": "5598960237790161917534060866496363286228389060029699153094526893891604621525", "price": "0.914", "size": "738", "side": "BUY", "hash": "ba194e4613e6429c8cc24e5220d2116f5f69e84c", "best_bid": "0.99", "best_ask": "0.991"}], "timestamp": "1769384003720", "event_type": "price_change"}}
{"_local_timestamp": "2026-01-25T23:33:23.901796+00:00", "data": {"market": "0x6a3bc08c62413e6594164bc15aa07b282b22a6d7efc61cd69df92b63f4132289", "price_changes": [{"asset_id": "5598960237790161917534060866496363286228389060029699153094526893891604621525", "price": "0.914", "size": "713", "side": "BUY", "hash": "4c49c8aaf9651f1a5542119ed98bc3cdcee8af03", "best_bid": "0.99", "best_ask": "0.991"}, {"asset_id": "99482729937705145912235477495415874028392807588978105657655512338616047660547", "price": "0.086", "size": "713", "side": "SELL", "hash": "2c2b31c7c6f17d576dfadd55813c73ab33de6400", "best_bid": "0.009", "best_ask": "0.01"}], "timestamp": "1769384003805", "event_type": "price_change"}}
{"_local_timestamp": "2026-01-25T23:33:23.981850+00:00", "data": {"market": "0xc512e0c0fa2d19ad6fe8bd885b3089a80fa2bf8382c104321c7359e7014cf567", "price_changes": [{"asset_id": "107858355690036086153439322350404767983557761088489336428558005982078386490488", "price": "0.298", "size": "0", "side": "BUY", "hash": "365a0ca7dcc50b7de575b74004fec2344d2c8c42", "best_bid": "0.315", "best_ask": "0.349"}, {"asset_id": "83334600217205368371784439992248024883439507053390974906923524834233064415427", "price": "0.702", "size": "0", "side": "SELL", "hash": "010f2825bf7f0babb5f8c4a7582ff8eeb41f689a", "best_bid": "0.651", "best_ask": "0.685"}], "timestamp": "1769384003914", "event_type": "price_change"}}
{"_local_timestamp": "2026-01-25T23:33:23.982646+00:00", "data": {"market": "0x8d8b98fb4c290c4e152ce8b653c5598b74a630dd1dbb800a5f328ea9c8b00727", "price_changes": [{"asset_id": "78474559114932529051705203752686517828085200880957778785050112163927946260911", "price": "0.942", "size": "0", "side": "BUY", "hash": "ee0c02d34940849689fcd57d4673c1c31539e98d", "best_bid": "0.943", "best_ask": "0.958"}, {"asset_id": "80938914484826983068438930343848557974856639667615266122989436725895029352478", "price": "0.058", "size": "0", "side": "SELL", "hash": "6bd7beb5c2608980dc3e3a9cc5f874420ebe9ebe", "best_bid": "0.042", "best_ask": "0.057"}], "timestamp": "1769384003915", "event_type": "price_change"}}
{"_local_timestamp": "2026-01-25T23:33:24.356765+00:00", "data": {"market": "0xd55b7e07b66b1d6702aa8f8c0c761a4f2838b55fa31395676bd0150b9fabb3a4", "price_changes": [{"asset_id": "100252164279000180790972381908103319470423853298906411193188634318600215482432", "price": "0.063", "size": "15", "side": "BUY", "hash": "b877abde1d5613fcca6f2f5d02843ab8cf5311e0", "best_bid": "0.064", "best_ask": "0.066"}, {"asset_id": "71934813421791148309055586854264573769390957341135501297936685395378523616284", "price": "0.937", "size": "15", "side": "SELL", "hash": "653413bbaff18b2be4a20f10b1bb7f3acca27e59", "best_bid": "0.934", "best_ask": "0.936"}], "timestamp": "1769384004282", "event_type": "price_change"}}
{"_local_timestamp": "2026-01-25T23:33:24.557245+00:00", "data": {"market": "0xd55b7e07b66b1d6702aa8f8c0c761a4f2838b55fa31395676bd0150b9fabb3a4", "price_changes": [{"asset_id": "71934813421791148309055586854264573769390957341135501297936685395378523616284", "price": "0.933", "size": "0", "side": "BUY", "hash": "9c5c0021d72802453374ddaabe2bc3801d98baf7", "best_bid": "0.934", "best_ask": "0.936"}, {"asset_id": "100252164279000180790972381908103319470423853298906411193188634318600215482432", "price": "0.067", "size": "0", "side": "SELL", "hash": "17164588385934fd382ecb5c61171f7c86e87a2a", "best_bid": "0.064", "best_ask": "0.066"}], "timestamp": "1769384004492", "event_type": "price_change"}}
{"_local_timestamp": "2026-01-25T23:33:24.579100+00:00", "data": {"market": "0x8d8b98fb4c290c4e152ce8b653c5598b74a630dd1dbb800a5f328ea9c8b00727", "price_changes": [{"asset_id": "80938914484826983068438930343848557974856639667615266122989436725895029352478", "price": "0.065", "size": "5.38", "side": "SELL", "hash": "11e0d2dc47bee80a3bda3b03cff4e9611df2b077", "best_bid": "0.042", "best_ask": "0.057"}, {"asset_id": "78474559114932529051705203752686517828085200880957778785050112163927946260911", "price": "0.935", "size": "5.38", "side": "BUY", "hash": "987fd0ce41df726f0e2f071063f1ae722be7996d", "best_bid": "0.943", "best_ask": "0.958"}], "timestamp": "1769384004505", "event_type": "price_change"}}
{"_local_timestamp": "2026-01-25T23:33:24.642152+00:00", "data": {"market": "0xffe62176c4eb6eb83ccff978b60f26f2c106398fa3c12f8f10c390069f1c0327", "price_changes": [{"asset_id": "96053159599260004603905372121344488945548265884928713587631467689929621790840", "price": "0.253", "size": "1660", "side": "BUY", "hash": "e10097000a448bb5835d2b9dbc6f39b719491647", "best_bid": "0.957", "best_ask": "0.967"}, {"asset_id": "98032013532486965224887573635135423443725925647904190791194069311921831803628", "price": "0.747", "size": "1660", "side": "SELL", "hash": "97d038707ccc829c3a027b3471144d8d68d39eb5", "best_bid": "0.033", "best_ask": "0.043"}], "timestamp": "1769384004571", "event_type": "price_change"}}
{"_local_timestamp": "2026-01-25T23:33:24.651176+00:00", "data": {"market": "0x8d8b98fb4c290c4e152ce8b653c5598b74a630dd1dbb800a5f328ea9c8b00727", "price_changes": [{"asset_id": "80938914484826983068438930343848557974856639667615266122989436725895029352478", "price": "0.063", "size": "30", "side": "SELL", "hash": "46c19a002f3cdf5ab70d77dd43041cabd4a768fd", "best_bid": "0.042", "best_ask": "0.057"}, {"asset_id": "78474559114932529051705203752686517828085200880957778785050112163927946260911", "price": "0.937", "size": "30", "side": "BUY", "hash": "51b5bd1664de976496be1766c88acc6656b47572", "best_bid": "0.943", "best_ask": "0.958"}], "timestamp": "1769384004577", "event_type": "price_change"}}
{"_local_timestamp": "2026-01-25T23:33:24.765659+00:00", "data": {"market": "0x6a3bc08c62413e6594164bc15aa07b282b22a6d7efc61cd69df92b63f4132289", "price_changes": [{"asset_id": "5598960237790161917534060866496363286228389060029699153094526893891604621525", "price": "0.912", "size": "25", "side": "BUY", "hash": "d6413e9ddf8e7ae28c6e073cdfd8445bedfd59cf", "best_bid": "0.99", "best_ask": "0.991"}, {"asset_id": "99482729937705145912235477495415874028392807588978105657655512338616047660547", "price": "0.088", "size": "25", "side": "SELL", "hash": "ffa9a3065cab71864e050b66ec536d1d4bf49592", "best_bid": "0.009", "best_ask": "0.01"}], "timestamp": "1769384004691", "event_type": "price_change"}}
{"_local_timestamp": "2026-01-25T23:33:24.884860+00:00", "data": {"market": "0x6a3bc08c62413e6594164bc15aa07b282b22a6d7efc61cd69df92b63f4132289", "price_changes": [{"asset_id": "5598960237790161917534060866496363286228389060029699153094526893891604621525", "price": "0.912", "size": "0", "side": "BUY", "hash": "3d1ba0c6965a027c0e85274101c199489ef0cee4", "best_bid": "0.99", "best_ask": "0.991"}, {"asset_id": "99482729937705145912235477495415874028392807588978105657655512338616047660547", "price": "0.088", "size": "0", "side": "SELL", "hash": "9f9207560fb56f5d3e5592d031924cdcbaf19773", "best_bid": "0.009", "best_ask": "0.01"}], "timestamp": "1769384004805", "event_type": "price_change"}}
{"_local_timestamp": "2026-01-25T23:33:25.293313+00:00", "data": {"market": "0xc512e0c0fa2d19ad6fe8bd885b3089a80fa2bf8382c104321c7359e7014cf567", "price_changes": [{"asset_id": "107858355690036086153439322350404767983557761088489336428558005982078386490488", "price": "0.22", "size": "700", "side": "BUY", "hash": "ef257d7ca3d959a216b0a9e9a604574c0707661f", "best_bid": "0.315", "best_ask": "0.349"}, {"asset_id": "83334600217205368371784439992248024883439507053390974906923524834233064415427", "price": "0.78", "size": "700", "side": "SELL", "hash": "d4b585a3fd17dbf95112b3fffe669e9173ef8f93", "best_bid": "0.651", "best_ask": "0.685"}], "timestamp": "1769384005174", "event_type": "price_change"}}
{"_local_timestamp": "2026-01-25T23:33:25.977491+00:00", "data": {"market": "0x8d8b98fb4c290c4e152ce8b653c5598b74a630dd1dbb800a5f328ea9c8b00727", "price_changes": [{"asset_id": "80938914484826983068438930343848557974856639667615266122989436725895029352478", "price": "0.057", "size": "0", "side": "SELL", "hash": "3aed76f06a0554026da1b06d12170ca3fb1c45b4", "best_bid": "0.042", "best_ask": "0.063"}, {"asset_id": "78474559114932529051705203752686517828085200880957778785050112163927946260911", "price": "0.943", "size": "0", "side": "BUY", "hash": "2431ae071f89b22e1909a87bba88493c5439873d", "best_bid": "0.937", "best_ask": "0.958"}], "timestamp": "1769384005912", "event_type": "price_change"}}
{"_local_timestamp": "2026-01-25T23:33:26.008253+00:00", "data": {"market": "0x8d8b98fb4c290c4e152ce8b653c5598b74a630dd1dbb800a5f328ea9c8b00727", "price_changes": [{"asset_id": "80938914484826983068438930343848557974856639667615266122989436725895029352478", "price": "0.063", "size": "256", "side": "SELL", "hash": "93efb81108c8ace7a4056eb3f3a3df2414a2aa6b", "best_bid": "0.042", "best_ask": "0.063"}, {"asset_id": "78474559114932529051705203752686517828085200880957778785050112163927946260911", "price": "0.937", "size": "256", "side": "BUY", "hash": "67fb0762d62d4a21074f0721e7dc85c14fb2429c", "best_bid": "0.937", "best_ask": "0.958"}], "timestamp": "1769384005937", "event_type": "price_change"}}
{"_local_timestamp": "2026-01-25T23:33:26.008809+00:00", "data": {"market": "0x8d8b98fb4c290c4e152ce8b653c5598b74a630dd1dbb800a5f328ea9c8b00727", "price_changes": [{"asset_id": "80938914484826983068438930343848557974856639667615266122989436725895029352478", "price": "0.037", "size": "121", "side": "BUY", "hash": "fa784f02f97bc00a851f927eeec3801115d66cc1", "best_bid": "0.042", "best_ask": "0.063"}, {"asset_id": "78474559114932529051705203752686517828085200880957778785050112163927946260911", "price": "0.963", "size": "121", "side": "SELL", "hash": "4679fe8a39b5343b237a4a4f9321fe5ff74c2e9e", "best_bid": "0.937", "best_ask": "0.958"}], "timestamp": "1769384005943", "event_type": "price_change"}}
{"_local_timestamp": "2026-01-25T23:33:26.098394+00:00", "data": {"market": "0x6a3bc08c62413e6594164bc15aa07b282b22a6d7efc61cd69df92b63f4132289", "price_changes": [{"asset_id": "5598960237790161917534060866496363286228389060029699153094526893891604621525", "price": "0.912", "size": "25", "side": "BUY", "hash": "b60315c65825b2f6682202b1f5748a03fdc54405", "best_bid": "0.99", "best_ask": "0.991"}, {"asset_id": "99482729937705145912235477495415874028392807588978105657655512338616047660547", "price": "0.088", "size": "25", "side": "SELL", "hash": "7fbde4cc3410da335d2f3ddb92809471b17fa514", "best_bid": "0.009", "best_ask": "0.01"}], "timestamp": "1769384006021", "event_type": "price_change"}}
{"_local_timestamp": "2026-01-25T23:33:26.198815+00:00", "data": {"market": "0x8d8b98fb4c290c4e152ce8b653c5598b74a630dd1dbb800a5f328ea9c8b00727", "price_changes": [{"asset_id": "80938914484826983068438930343848557974856639667615266122989436725895029352478", "price": "0.062", "size": "7.14", "side": "SELL", "hash": "d632ad29a8ab150dae386ab48bd537c0c61e0c5f", "best_bid": "0.042", "best_ask": "0.062"}, {"asset_id": "78474559114932529051705203752686517828085200880957778785050112163927946260911", "price": "0.938", "size": "7.14", "side": "BUY", "hash": "feda6609da78f9cbecce4504e49ac0581acca5d2", "best_bid": "0.938", "best_ask": "0.958"}], "timestamp": "1769384006124", "event_type": "price_change"}}
{"_local_timestamp": "2026-01-25T23:33:26.218211+00:00", "data": {"market": "0x6a3bc08c62413e6594164bc15aa07b282b22a6d7efc61cd69df92b63f4132289", "price_changes": [{"asset_id": "5598960237790161917534060866496363286228389060029699153094526893891604621525", "price": "0.912", "size": "0", "side": "BUY", "hash": "bcbe6002abfe21a7288b0d8483daea3c12bee6c5", "best_bid": "0.99", "best_ask": "0.991"}, {"asset_id": "99482729937705145912235477495415874028392807588978105657655512338616047660547", "price": "0.088", "size": "0", "side": "SELL", "hash": "24ba394202a0695b8b1b8db0bad98742af756a57", "best_bid": "0.009", "best_ask": "0.01"}], "timestamp": "1769384006150", "event_type": "price_change"}}
{"_local_timestamp": "2026-01-25T23:33:26.830893+00:00", "data": {"market": "0x8d8b98fb4c290c4e152ce8b653c5598b74a630dd1dbb800a5f328ea9c8b00727", "price_changes": [{"asset_id": "78474559114932529051705203752686517828085200880957778785050112163927946260911", "price": "0.938", "size": "37.14", "side": "BUY", "hash": "8ff8a6525ce05cc4855eba0e9b9e03acd649b448", "best_bid": "0.938", "best_ask": "0.958"}, {"asset_id": "80938914484826983068438930343848557974856639667615266122989436725895029352478", "price": "0.062", "size": "37.14", "side": "SELL", "hash": "1974caf3c66275c7ed7a56fd9e2e7544d9bdc4f9", "best_bid": "0.042", "best_ask": "0.062"}], "timestamp": "1769384006754", "event_type": "price_change"}}
{"_local_timestamp": "2026-01-25T23:33:27.095680+00:00", "data": {"market": "0x8d8b98fb4c290c4e152ce8b653c5598b74a630dd1dbb800a5f328ea9c8b00727", "price_changes": [{"asset_id": "80938914484826983068438930343848557974856639667615266122989436725895029352478", "price": "0.037", "size": "100", "side": "BUY", "hash": "c485b7b1560a3ed7fe1d6cc053b3980c0693ba07", "best_bid": "0.042", "best_ask": "0.062"}, {"asset_id": "78474559114932529051705203752686517828085200880957778785050112163927946260911", "price": "0.963", "size": "100", "side": "SELL", "hash": "8f6ef403fb1fcfab79f099e6ceb08a5380ee488f", "best_bid": "0.938", "best_ask": "0.958"}], "timestamp": "1769384007021", "event_type": "price_change"}}
{"_local_timestamp": "2026-01-25T23:33:27.096921+00:00", "data": {"market": "0x8d8b98fb4c290c4e152ce8b653c5598b74a630dd1dbb800a5f328ea9c8b00727", "price_changes": [{"asset_id": "80938914484826983068438930343848557974856639667615266122989436725895029352478", "price": "0.063", "size": "30", "side": "SELL", "hash": "c485b7b1560a3ed7fe1d6cc053b3980c0693ba07", "best_bid": "0.042", "best_ask": "0.062"}, {"asset_id": "78474559114932529051705203752686517828085200880957778785050112163927946260911", "price": "0.937", "size": "30", "side": "BUY", "hash": "8f6ef403fb1fcfab79f099e6ceb08a5380ee488f", "best_bid": "0.938", "best_ask": "0.958"}], "timestamp": "1769384007021", "event_type": "price_change"}}
{"_local_timestamp": "2026-01-25T23:33:27.113666+00:00", "data": {"market": "0x8d8b98fb4c290c4e152ce8b653c5598b74a630dd1dbb800a5f328ea9c8b00727", "price_changes": [{"asset_id": "80938914484826983068438930343848557974856639667615266122989436725895029352478", "price": "0.062", "size": "263.14", "side": "SELL", "hash": "b6cac8b10b3d9c50de4c33400556570f4bf5088d", "best_bid": "0.042", "best_ask": "0.062"}, {"asset_id": "78474559114932529051705203752686517828085200880957778785050112163927946260911", "price": "0.938", "size": "263.14", "side": "BUY", "hash": "ff2309c051304d8ebe62b9d0e79187cc05d41e1a", "best_bid": "0.938", "best_ask": "0.958"}], "timestamp": "1769384007047", "event_type": "price_change"}}
{"_local_timestamp": "2026-01-25T23:33:27.118581+00:00", "data": {"market": "0x8d8b98fb4c290c4e152ce8b653c5598b74a630dd1dbb800a5f328ea9c8b00727", "price_changes": [{"asset_id": "80938914484826983068438930343848557974856639667615266122989436725895029352478", "price": "0.037", "size": "151", "side": "BUY", "hash": "87c160483a255544e62e86347b07c5f84080e6bf", "best_bid": "0.042", "best_ask": "0.062"}, {"asset_id": "78474559114932529051705203752686517828085200880957778785050112163927946260911", "price": "0.963", "size": "151", "side": "SELL", "hash": "0c8195a392e0928acd9cea239a399f176136d677", "best_bid": "0.938", "best_ask": "0.958"}], "timestamp": "1769384007050", "event_type": "price_change"}}
{"_local_timestamp": "2026-01-25T23:33:27.209747+00:00", "data": {"market": "0x6a3bc08c62413e6594164bc15aa07b282b22a6d7efc61cd69df92b63f4132289", "price_changes": [{"asset_id": "5598960237790161917534060866496363286228389060029699153094526893891604621525", "price": "0.912", "size": "25", "side": "BUY", "hash": "bf3f567ab248bcfa83440872af710680db67ec01", "best_bid": "0.99", "best_ask": "0.991"}, {"asset_id": "99482729937705145912235477495415874028392807588978105657655512338616047660547", "price": "0.088", "size": "25", "side": "SELL", "hash": "a84815bd0cdd72bcdb4f172732ff4c5cc18b93b2", "best_bid": "0.009", "best_ask": "0.01"}], "timestamp": "1769384007141", "event_type": "price_change"}}
{"_local_timestamp": "2026-01-25T23:33:27.358432+00:00", "data": {"market": "0x6a3bc08c62413e6594164bc15aa07b282b22a6d7efc61cd69df92b63f4132289", "price_changes": [{"asset_id": "5598960237790161917534060866496363286228389060029699153094526893891604621525", "price": "0.912", "size": "0", "side": "BUY", "hash": "904efcec91d98401d7f12c0ab27e9625521d6ef9", "best_bid": "0.99", "best_ask": "0.991"}, {"asset_id": "99482729937705145912235477495415874028392807588978105657655512338616047660547", "price": "0.088", "size": "0", "side": "SELL", "hash": "ec8528e955f9e16799a2936ab18a3986ef3ca16e", "best_bid": "0.009", "best_ask": "0.01"}], "timestamp": "1769384007286", "event_type": "price_change"}}
{"_local_timestamp": "2026-01-25T23:33:27.625848+00:00", "data": {"market": "0x8d8b98fb4c290c4e152ce8b653c5598b74a630dd1dbb800a5f328ea9c8b00727", "price_changes": [{"asset_id": "80938914484826983068438930343848557974856639667615266122989436725895029352478", "price": "0.063", "size": "0", "side": "SELL", "hash": "467ab48ddc5412c768f983c57d92d1121cce6325", "best_bid": "0.042", "best_ask": "0.062"}, {"asset_id": "78474559114932529051705203752686517828085200880957778785050112163927946260911", "price": "0.937", "size": "0", "side": "BUY", "hash": "ab3144a0db3b15dbea7474c417e4fd9f6e863fd7", "best_bid": "0.938", "best_ask": "0.958"}], "timestamp": "1769384007556", "event_type": "price_change"}}
{"_local_timestamp": "2026-01-25T23:33:27.679473+00:00", "data": {"market": "0x8d8b98fb4c290c4e152ce8b653c5598b74a630dd1dbb800a5f328ea9c8b00727", "price_changes": [{"asset_id": "80938914484826983068438930343848557974856639667615266122989436725895029352478", "price": "0.061", "size": "30", "side": "SELL", "hash": "28764a7afb6d3e7945cf470d5c4ccc118d374f93", "best_bid": "0.042", "best_ask": "0.061"}, {"asset_id": "78474559114932529051705203752686517828085200880957778785050112163927946260911", "price": "0.939", "size": "30", "side": "BUY", "hash": "be520741286d6feae22819408c22876f035bf5dd", "best_bid": "0.939", "best_ask": "0.958"}], "timestamp": "1769384007609", "event_type": "price_change"}}
{"_local_timestamp": "2026-01-25T23:33:27.854328+00:00", "data": {"market": "0xffe62176c4eb6eb83ccff978b60f26f2c106398fa3c12f8f10c390069f1c0327", "price_changes": [{"asset_id": "96053159599260004603905372121344488945548265884928713587631467689929621790840", "price": "0.05", "size": "30", "side": "BUY", "hash": "cd6bf3cd17e964c210aef4a932264cb8769872b8", "best_bid": "0.957", "best_ask": "0.967"}, {"asset_id": "98032013532486965224887573635135423443725925647904190791194069311921831803628", "price": "0.95", "size": "30", "side": "SELL", "hash": "55fc1ce6cac1634b3e6cf3f33199324d55eddd7d", "best_bid": "0.033", "best_ask": "0.043"}], "timestamp": "1769384007785", "event_type": "price_change"}}
{"_local_timestamp": "2026-01-25T23:33:28.223634+00:00", "data": {"market": "0x8d8b98fb4c290c4e152ce8b653c5598b74a630dd1dbb800a5f328ea9c8b00727", "price_changes": [{"asset_id": "78474559114932529051705203752686517828085200880957778785050112163927946260911", "price": "0.938", "size": "233.14", "side": "BUY", "hash": "72df5b8b84322dd7c4a619462d5fe922255c93a6", "best_bid": "0.939", "best_ask": "0.958"}, {"asset_id": "80938914484826983068438930343848557974856639667615266122989436725895029352478", "price": "0.062", "size": "233.14", "side": "SELL", "hash": "5b850220bc4a1fbde250a6ac7a48560de15469fe", "best_bid": "0.042", "best_ask": "0.061"}], "timestamp": "1769384008154", "event_type": "price_change"}}
{"_local_timestamp": "2026-01-25T23:33:28.249273+00:00", "data": {"market": "0x8d8b98fb4c290c4e152ce8b653c5598b74a630dd1dbb800a5f328ea9c8b00727", "price_changes": [{"asset_id": "80938914484826983068438930343848557974856639667615266122989436725895029352478", "price": "0.062", "size": "7.14", "side": "SELL", "hash": "383dfb65c8b55195167a7b214ff026f47ee7829b", "best_bid": "0.042", "best_ask": "0.061"}, {"asset_id": "78474559114932529051705203752686517828085200880957778785050112163927946260911", "price": "0.938", "size": "7.14", "side": "BUY", "hash": "8fea9263bd89ab77a91e914b6986dcd65abb388a", "best_bid": "0.939", "best_ask": "0.958"}], "timestamp": "1769384008178", "event_type": "price_change"}}
{"_local_timestamp": "2026-01-25T23:33:28.275571+00:00", "data": {"market": "0x8d8b98fb4c290c4e152ce8b653c5598b74a630dd1dbb800a5f328ea9c8b00727", "price_changes": [{"asset_id": "80938914484826983068438930343848557974856639667615266122989436725895029352478", "price": "0.061", "size": "256", "side": "SELL", "hash": "3be63bf1161af3a3e437f21498a24908ed7b1bf7", "best_bid": "0.042", "best_ask": "0.061"}, {"asset_id": "78474559114932529051705203752686517828085200880957778785050112163927946260911", "price": "0.939", "size": "256", "side": "BUY", "hash": "d8966b5abdc0384b61bc5b68efd43b795f94f298", "best_bid": "0.939", "best_ask": "0.958"}], "timestamp": "1769384008206", "event_type": "price_change"}}
{"_local_timestamp": "2026-01-25T23:33:28.280929+00:00", "data": {"market": "0x8d8b98fb4c290c4e152ce8b653c5598b74a630dd1dbb800a5f328ea9c8b00727", "price_changes": [{"asset_id": "78474559114932529051705203752686517828085200880957778785050112163927946260911", "price": "0.939", "size": "286", "side": "BUY", "hash": "d2d00d5c8819a0768ee1a89829fbb4a01a029631", "best_bid": "0.939", "best_ask": "0.958"}, {"asset_id": "80938914484826983068438930343848557974856639667615266122989436725895029352478", "price": "0.061", "size": "286", "side": "SELL", "hash": "156d3b1ed320642fb94b64681f0a1639e20ebf9a", "best_bid": "0.042", "best_ask": "0.061"}], "timestamp": "1769384008210", "event_type": "price_change"}}
{"_local_timestamp": "2026-01-25T23:33:28.297279+00:00", "data": {"market": "0x8d8b98fb4c290c4e152ce8b653c5598b74a630dd1dbb800a5f328ea9c8b00727", "price_changes": [{"asset_id": "80938914484826983068438930343848557974856639667615266122989436725895029352478", "price": "0.037", "size": "100", "side": "BUY", "hash": "04eb19145b702a549bf9f9c17473b7427bff72f0", "best_bid": "0.042", "best_ask": "0.061"}, {"asset_id": "78474559114932529051705203752686517828085200880957778785050112163927946260911", "price": "0.963", "size": "100", "side": "SELL", "hash": "0ecf53a1f9ab58fc21d9cd563fb6bae25c23afc5", "best_bid": "0.939", "best_ask": "0.958"}], "timestamp": "1769384008233", "event_type": "price_change"}}
{"_local_timestamp": "2026-01-25T23:33:28.329090+00:00", "data": {"market": "0x6a3bc08c62413e6594164bc15aa07b282b22a6d7efc61cd69df92b63f4132289", "price_changes": [{"asset_id": "5598960237790161917534060866496363286228389060029699153094526893891604621525", "price": "0.912", "size": "25", "side": "BUY", "hash": "2b81ce185e9616da14cd4114f2c186e91642af5b", "best_bid": "0.99", "best_ask": "0.991"}, {"asset_id": "99482729937705145912235477495415874028392807588978105657655512338616047660547", "price": "0.088", "size": "25", "side": "SELL", "hash": "afe50cca80027d11aed844b0a786c39b753d9cdb", "best_bid": "0.009", "best_ask": "0.01"}], "timestamp": "1769384008263", "event_type": "price_change"}}
{"_local_timestamp": "2026-01-25T23:33:28.436905+00:00", "data": {"market": "0x6a3bc08c62413e6594164bc15aa07b282b22a6d7efc61cd69df92b63f4132289", "price_changes": [{"asset_id": "5598960237790161917534060866496363286228389060029699153094526893891604621525", "price": "0.912", "size": "0", "side": "BUY", "hash": "67e312995035ea4dae68e5b8602bd517151c93d8", "best_bid": "0.99", "best_ask": "0.991"}, {"asset_id": "99482729937705145912235477495415874028392807588978105657655512338616047660547", "price": "0.088", "size": "0", "side": "SELL", "hash": "3a14e936a63c548e2c42d0e286d9aadbaf301cc2", "best_bid": "0.009", "best_ask": "0.01"}], "timestamp": "1769384008367", "event_type": "price_change"}}
{"_local_timestamp": "2026-01-25T23:33:28.820427+00:00", "data": {"market": "0x8d8b98fb4c290c4e152ce8b653c5598b74a630dd1dbb800a5f328ea9c8b00727", "price_changes": [{"asset_id": "78474559114932529051705203752686517828085200880957778785050112163927946260911", "price": "0.939", "size": "256", "side": "BUY", "hash": "324d6dd59f547c1e6159ba83089a9abfbbb53c13", "best_bid": "0.939", "best_ask": "0.958"}, {"asset_id": "80938914484826983068438930343848557974856639667615266122989436725895029352478", "price": "0.061", "size": "256", "side": "SELL", "hash": "2c85177076c379f175cb9843fd334591a10e0956", "best_bid": "0.042", "best_ask": "0.061"}], "timestamp": "1769384008748", "event_type": "price_change"}}
{"_local_timestamp": "2026-01-25T23:33:28.857620+00:00", "data": {"market": "0x8d8b98fb4c290c4e152ce8b653c5598b74a630dd1dbb800a5f328ea9c8b00727", "price_changes": [{"asset_id": "78474559114932529051705203752686517828085200880957778785050112163927946260911", "price": "0.94", "size": "30", "side": "BUY", "hash": "75f28c4d5fb3fc8c976cf686061449dc2fe7f11f", "best_bid": "0.94", "best_ask": "0.958"}, {"asset_id": "80938914484826983068438930343848557974856639667615266122989436725895029352478", "price": "0.06", "size": "30", "side": "SELL", "hash": "aa6fe460c38cfb104310775648001c0c8cb02c9f", "best_bid": "0.042", "best_ask": "0.06"}], "timestamp": "1769384008789", "event_type": "price_change"}}
{"_local_timestamp": "2026-01-25T23:33:29.459679+00:00", "data": {"market": "0x8d8b98fb4c290c4e152ce8b653c5598b74a630dd1dbb800a5f328ea9c8b00727", "price_changes": [{"asset_id": "80938914484826983068438930343848557974856639667615266122989436725895029352478", "price": "0.062", "size": "0", "side": "SELL", "hash": "b3cebf11120678efc058ff855a198ecffde688b0", "best_bid": "0.042", "best_ask": "0.06"}, {"asset_id": "78474559114932529051705203752686517828085200880957778785050112163927946260911", "price": "0.938", "size": "0", "side": "BUY", "hash": "5a4e3bfddc9a8c39f48916b44824bb7b51a23d94", "best_bid": "0.94", "best_ask": "0.958"}], "timestamp": "1769384009393", "event_type": "price_change"}}
{"_local_timestamp": "2026-01-25T23:33:29.571565+00:00", "data": {"market": "0x6a3bc08c62413e6594164bc15aa07b282b22a6d7efc61cd69df92b63f4132289", "price_changes": [{"asset_id": "5598960237790161917534060866496363286228389060029699153094526893891604621525", "price": "0.912", "size": "25", "side": "BUY", "hash": "394be89777e67580bbeda23afc8e8cfdb48cef5a", "best_bid": "0.99", "best_ask": "0.991"}, {"asset_id": "99482729937705145912235477495415874028392807588978105657655512338616047660547", "price": "0.088", "size": "25", "side": "SELL", "hash": "cd2264b643a6952b91613ed4c0b0b2429e2b28c5", "best_bid": "0.009", "best_ask": "0.01"}], "timestamp": "1769384009497", "event_type": "price_change"}}
{"_local_timestamp": "2026-01-25T23:33:29.673242+00:00", "data": {"market": "0x6a3bc08c62413e6594164bc15aa07b282b22a6d7efc61cd69df92b63f4132289", "price_changes": [{"asset_id": "5598960237790161917534060866496363286228389060029699153094526893891604621525", "price": "0.912", "size": "0", "side": "BUY", "hash": "230ba54f32489d7df3195bc90bf5dba4c80a9e21", "best_bid": "0.99", "best_ask": "0.991"}, {"asset_id": "99482729937705145912235477495415874028392807588978105657655512338616047660547", "price": "0.088", "size": "0", "side": "SELL", "hash": "b850fb5ce30a22b552cab35e6b027a4dce8f65a5", "best_bid": "0.009", "best_ask": "0.01"}], "timestamp": "1769384009605", "event_type": "price_change"}}
{"_local_timestamp": "2026-01-25T23:33:29.690820+00:00", "data": {"market": "0x6a3bc08c62413e6594164bc15aa07b282b22a6d7efc61cd69df92b63f4132289", "price_changes": [{"asset_id": "5598960237790161917534060866496363286228389060029699153094526893891604621525", "price": "0.411", "size": "20", "side": "BUY", "hash": "f468a074df27fc81c6ed1307dec7eea97d227585", "best_bid": "0.99", "best_ask": "0.991"}, {"asset_id": "99482729937705145912235477495415874028392807588978105657655512338616047660547", "price": "0.589", "size": "20", "side": "SELL", "hash": "323bee1618e9864dfe123f7ec693c8586926a040", "best_bid": "0.009", "best_ask": "0.01"}], "timestamp": "1769384009622", "event_type": "price_change"}}
{"_local_timestamp": "2026-01-25T23:33:29.731498+00:00", "data": {"market": "0x6a3bc08c62413e6594164bc15aa07b282b22a6d7efc61cd69df92b63f4132289", "price_changes": [{"asset_id": "5598960237790161917534060866496363286228389060029699153094526893891604621525", "price": "0.417", "size": "20", "side": "BUY", "hash": "c82346c63d8bdf7963a31f1c16555ae55e16476c", "best_bid": "0.99", "best_ask": "0.991"}, {"asset_id": "99482729937705145912235477495415874028392807588978105657655512338616047660547", "price": "0.583", "size": "20", "side": "SELL", "hash": "bb720881c1672709ff299bfb67e9c46d0a85fc32", "best_bid": "0.009", "best_ask": "0.01"}], "timestamp": "1769384009668", "event_type": "price_change"}}
{"_local_timestamp": "2026-01-25T23:33:29.799869+00:00", "data": {"market": "0x8d8b98fb4c290c4e152ce8b653c5598b74a630dd1dbb800a5f328ea9c8b00727", "price_changes": [{"asset_id": "78474559114932529051705203752686517828085200880957778785050112163927946260911", "price": "0.941", "size": "50", "side": "BUY", "hash": "093c72e9975776f9cee50b17adcdeeceec1f453c", "best_bid": "0.941", "best_ask": "0.958"}, {"asset_id": "80938914484826983068438930343848557974856639667615266122989436725895029352478", "price": "0.059", "size": "50", "side": "SELL", "hash": "0c53c884d89adb88ab36d81652bcda8f3d8a5c9e", "best_bid": "0.042", "best_ask": "0.059"}], "timestamp": "1769384009720", "event_type": "price_change"}}
{"_local_timestamp": "2026-01-25T23:33:30.101343+00:00", "data": {"market": "0x8d8b98fb4c290c4e152ce8b653c5598b74a630dd1dbb800a5f328ea9c8b00727", "price_changes": [{"asset_id": "78474559114932529051705203752686517828085200880957778785050112163927946260911", "price": "0.936", "size": "10", "side": "BUY", "hash": "ec49dee7c680af07d1636b7227be584b4db64ba0", "best_bid": "0.941", "best_ask": "0.958"}, {"asset_id": "80938914484826983068438930343848557974856639667615266122989436725895029352478", "price": "0.064", "size": "10", "side": "SELL", "hash": "aff88965b14a4ffa9d322aef6bad1cebd2a2e8db", "best_bid": "0.042", "best_ask": "0.059"}], "timestamp": "1769384010011", "event_type": "price_change"}}
{"_local_timestamp": "2026-01-25T23:33:30.309979+00:00", "data": {"market": "0x8d8b98fb4c290c4e152ce8b653c5598b74a630dd1dbb800a5f328ea9c8b00727", "price_changes": [{"asset_id": "80938914484826983068438930343848557974856639667615266122989436725895029352478", "price": "0.06", "size": "37.14", "side": "SELL", "hash": "7a515346a2dcaca0f49521207735f682d9fff858", "best_bid": "0.042", "best_ask": "0.059"}, {"asset_id": "78474559114932529051705203752686517828085200880957778785050112163927946260911", "price": "0.94", "size": "37.14", "side": "BUY", "hash": "f6e780c6921c7dfff2f0dd68470421d1b8154590", "best_bid": "0.941", "best_ask": "0.958"}], "timestamp": "1769384010230", "event_type": "price_change"}}
{"_local_timestamp": "2026-01-25T23:33:30.369382+00:00", "data": {"market": "0xc512e0c0fa2d19ad6fe8bd885b3089a80fa2bf8382c104321c7359e7014cf567", "price_changes": [{"asset_id": "107858355690036086153439322350404767983557761088489336428558005982078386490488", "price": "0.29", "size": "127.27", "side": "BUY", "hash": "39019946536d617ac765120023f1da1bf2549a59", "best_bid": "0.315", "best_ask": "0.349"}, {"asset_id": "83334600217205368371784439992248024883439507053390974906923524834233064415427", "price": "0.71", "size": "127.27", "side": "SELL", "hash": "f1cdc2384026d229ad96708ba047b3cd7912bb9e", "best_bid": "0.651", "best_ask": "0.685"}], "timestamp": "1769384010297", "event_type": "price_change"}}
{"_local_timestamp": "2026-01-25T23:33:30.500139+00:00", "data": {"market": "0x6a3bc08c62413e6594164bc15aa07b282b22a6d7efc61cd69df92b63f4132289", "price_changes": [{"asset_id": "5598960237790161917534060866496363286228389060029699153094526893891604621525", "price": "0.411", "size": "0", "side": "BUY", "hash": "725ac642bb357383b087b65dd4e06e8473628f4e", "best_bid": "0.99", "best_ask": "0.991"}, {"asset_id": "99482729937705145912235477495415874028392807588978105657655512338616047660547", "price": "0.589", "size": "0", "side": "SELL", "hash": "be0053bc26b81bf772a95a44deaedba8220d7d27", "best_bid": "0.009", "best_ask": "0.01"}], "timestamp": "1769384010433", "event_type": "price_change"}}
{"_local_timestamp": "2026-01-25T23:33:30.613081+00:00", "data": {"market": "0x6a3bc08c62413e6594164bc15aa07b282b22a6d7efc61cd69df92b63f4132289", "price_changes": [{"asset_id": "5598960237790161917534060866496363286228389060029699153094526893891604621525", "price": "0.912", "size": "25", "side": "BUY", "hash": "7083b2f77cae3e5ce9201a958ce5cc91c33d7daf", "best_bid": "0.99", "best_ask": "0.991"}, {"asset_id": "99482729937705145912235477495415874028392807588978105657655512338616047660547", "price": "0.088", "size": "25", "side": "SELL", "hash": "fe2982ba302563604975898705a4fe10f9e1293d", "best_bid": "0.009", "best_ask": "0.01"}], "timestamp": "1769384010540", "event_type": "price_change"}}
{"_local_timestamp": "2026-01-25T23:33:30.628842+00:00", "data": {"market": "0x6a3bc08c62413e6594164bc15aa07b282b22a6d7efc61cd69df92b63f4132289", "price_changes": [{"asset_id": "5598960237790161917534060866496363286228389060029699153094526893891604621525", "price": "0.418", "size": "20", "side": "BUY", "hash": "0604241631730e6327f0d981cdec1073a84bb8aa", "best_bid": "0.99", "best_ask": "0.991"}, {"asset_id": "99482729937705145912235477495415874028392807588978105657655512338616047660547", "price": "0.582", "size": "20", "side": "SELL", "hash": "785bf2778f7131d56b525229294046f1fe5cb45f", "best_bid": "0.009", "best_ask": "0.01"}], "timestamp": "1769384010560", "event_type": "price_change"}}
{"_local_timestamp": "2026-01-25T23:33:30.672627+00:00", "data": {"market": "0x32821c03c1a785af6bea72291b578e722f02f7da80e204c42be3dee38694756f", "price_changes": [{"asset_id": "11222612568007649347690827040340431718068607305340023819591655077557696898272", "price": "0.452", "size": "553", "side": "BUY", "hash": "edee2cd312aef184b321ec1cbf3bdf883230bf0b", "best_bid": "0.969", "best_ask": "0.978"}, {"asset_id": "46526486688025872076957171866031437643304744954855308137561748620272587627152", "price": "0.548", "size": "553", "side": "SELL", "hash": "2eeff7f088eb1769d4084494fe51ebcb0cafab5c", "best_bid": "0.022", "best_ask": "0.031"}], "timestamp": "1769384010602", "event_type": "price_change"}}
{"_local_timestamp": "2026-01-25T23:33:30.727697+00:00", "data": {"market": "0x6a3bc08c62413e6594164bc15aa07b282b22a6d7efc61cd69df92b63f4132289", "price_changes": [{"asset_id": "5598960237790161917534060866496363286228389060029699153094526893891604621525", "price": "0.416", "size": "0", "side": "BUY", "hash": "b2092c386ff342e15c9a0251e49492e27cbe5147", "best_bid": "0.99", "best_ask": "0.991"}, {"asset_id": "99482729937705145912235477495415874028392807588978105657655512338616047660547", "price": "0.584", "size": "0", "side": "SELL", "hash": "e68f7290b9daec9fa552a3c702ad5be4b42e016c", "best_bid": "0.009", "best_ask": "0.01"}], "timestamp": "1769384010645", "event_type": "price_change"}}
{"_local_timestamp": "2026-01-25T23:33:30.731477+00:00", "data": {"market": "0x6a3bc08c62413e6594164bc15aa07b282b22a6d7efc61cd69df92b63f4132289", "price_changes": [{"asset_id": "5598960237790161917534060866496363286228389060029699153094526893891604621525", "price": "0.912", "size": "0", "side": "BUY", "hash": "7939ce5e862cc7ddac81b46ba78ec52a8e6630da", "best_bid": "0.99", "best_ask": "0.991"}, {"asset_id": "99482729937705145912235477495415874028392807588978105657655512338616047660547", "price": "0.088", "size": "0", "side": "SELL", "hash": "09c80b86bf88ceee3e4c7df18f9c53c011fb3f88", "best_bid": "0.009", "best_ask": "0.01"}], "timestamp": "1769384010660", "event_type": "price_change"}}
{"_local_timestamp": "2026-01-25T23:33:30.735292+00:00", "data": {"market": "0x6a3bc08c62413e6594164bc15aa07b282b22a6d7efc61cd69df92b63f4132289", "price_changes": [{"asset_id": "5598960237790161917534060866496363286228389060029699153094526893891604621525", "price": "0.418", "size": "40", "side": "BUY", "hash": "7d3c690fb00848bfdeee5545c9e795e328d7543f", "best_bid": "0.99", "best_ask": "0.991"}, {"asset_id": "99482729937705145912235477495415874028392807588978105657655512338616047660547", "price": "0.582", "size": "40", "side": "SELL", "hash": "eb9509f60f8873f655190f652bdd77d0e5d5453b", "best_bid": "0.009", "best_ask": "0.01"}], "timestamp": "1769384010669", "event_type": "price_change"}}
{"_local_timestamp": "2026-01-25T23:33:30.778607+00:00", "data": {"market": "0x32821c03c1a785af6bea72291b578e722f02f7da80e204c42be3dee38694756f", "price_changes": [{"asset_id": "11222612568007649347690827040340431718068607305340023819591655077557696898272", "price": "0.891", "size": "20", "side": "BUY", "hash": "f98e79b4fea560863561594098c272b4473feeeb", "best_bid": "0.969", "best_ask": "0.978"}, {"asset_id": "46526486688025872076957171866031437643304744954855308137561748620272587627152", "price": "0.109", "size": "20", "side": "SELL", "hash": "4fd7e0ad2cd3bf067a97154434fe1f5ce33220a6", "best_bid": "0.022", "best_ask": "0.031"}], "timestamp": "1769384010709", "event_type": "price_change"}}
{"_local_timestamp": "2026-01-25T23:33:31.990835+00:00", "data": {"market": "0x6a3bc08c62413e6594164bc15aa07b282b22a6d7efc61cd69df92b63f4132289", "price_changes": [{"asset_id": "5598960237790161917534060866496363286228389060029699153094526893891604621525", "price": "0.418", "size": "20", "side": "BUY", "hash": "70fb92959fc7bb18881409da095fb3d7bddde143", "best_bid": "0.99", "best_ask": "0.991"}, {"asset_id": "99482729937705145912235477495415874028392807588978105657655512338616047660547", "price": "0.582", "size": "20", "side": "SELL", "hash": "1aa96a6d37b1205eb45e8f0f1f1f18ac86fa6227", "best_bid": "0.009", "best_ask": "0.01"}], "timestamp": "1769384011904", "event_type": "price_change"}}
{"_local_timestamp": "2026-01-25T23:33:32.001296+00:00", "data": {"market": "0x6a3bc08c62413e6594164bc15aa07b282b22a6d7efc61cd69df92b63f4132289", "price_changes": [{"asset_id": "5598960237790161917534060866496363286228389060029699153094526893891604621525", "price": "0.419", "size": "20", "side": "BUY", "hash": "8d49cb2b4308efd141a2bf2cc6842a6f5967a119", "best_bid": "0.99", "best_ask": "0.991"}, {"asset_id": "99482729937705145912235477495415874028392807588978105657655512338616047660547", "price": "0.581", "size": "20", "side": "SELL", "hash": "ce4d866a256d8ab0179b08b3fe5cf62579d77e8a", "best_bid": "0.009", "best_ask": "0.01"}], "timestamp": "1769384011931", "event_type": "price_change"}}
{"_local_timestamp": "2026-01-25T23:33:32.112260+00:00", "data": {"market": "0x6a3bc08c62413e6594164bc15aa07b282b22a6d7efc61cd69df92b63f4132289", "price_changes": [{"asset_id": "5598960237790161917534060866496363286228389060029699153094526893891604621525", "price": "0.912", "size": "25", "side": "BUY", "hash": "31a901fdcd1f0a9b2c7638688cc9e0b2c5f67e26", "best_bid": "0.99", "best_ask": "0.991"}, {"asset_id": "99482729937705145912235477495415874028392807588978105657655512338616047660547", "price": "0.088", "size": "25", "side": "SELL", "hash": "81db78e96897700beb74618e13a533fc4879dd47", "best_bid": "0.009", "best_ask": "0.01"}], "timestamp": "1769384012019", "event_type": "price_change"}}
{"_local_timestamp": "2026-01-25T23:33:32.206831+00:00", "data": {"market": "0x6a3bc08c62413e6594164bc15aa07b282b22a6d7efc61cd69df92b63f4132289", "price_changes": [{"asset_id": "5598960237790161917534060866496363286228389060029699153094526893891604621525", "price": "0.912", "size": "0", "side": "BUY", "hash": "06b157cbbccb2a1efe258e7600fb8f19a95edc9c", "best_bid": "0.99", "best_ask": "0.991"}, {"asset_id": "99482729937705145912235477495415874028392807588978105657655512338616047660547", "price": "0.088", "size": "0", "side": "SELL", "hash": "ce13192f2f3c274753dc300bc01bbc79fc760fc5", "best_bid": "0.009", "best_ask": "0.01"}], "timestamp": "1769384012129", "event_type": "price_change"}}
{"_local_timestamp": "2026-01-25T23:33:32.639300+00:00", "data": {"market": "0x8d8b98fb4c290c4e152ce8b653c5598b74a630dd1dbb800a5f328ea9c8b00727", "price_changes": [{"asset_id": "80938914484826983068438930343848557974856639667615266122989436725895029352478", "price": "0.06", "size": "30", "side": "SELL", "hash": "96e0789e646968217913096e69978c5692fa6201", "best_bid": "0.042", "best_ask": "0.059"}, {"asset_id": "78474559114932529051705203752686517828085200880957778785050112163927946260911", "price": "0.94", "size": "30", "side": "BUY", "hash": "a79107c2388dad29511a323f994e36739529f772", "best_bid": "0.941", "best_ask": "0.958"}], "timestamp": "1769384012568", "event_type": "price_change"}}
{"_local_timestamp": "2026-01-25T23:33:33.569097+00:00", "data": {"market": "0x8d8b98fb4c290c4e152ce8b653c5598b74a630dd1dbb800a5f328ea9c8b00727", "price_changes": [{"asset_id": "80938914484826983068438930343848557974856639667615266122989436725895029352478", "price": "0.058", "size": "7.14", "side": "SELL", "hash": "502b6a628221fef106778459087827a9066bf473", "best_bid": "0.042", "best_ask": "0.058"}, {"asset_id": "78474559114932529051705203752686517828085200880957778785050112163927946260911", "price": "0.942", "size": "7.14", "side": "BUY", "hash": "afffb4313ce10dc0e5bd83b8555b8d2ecdc9e435", "best_bid": "0.942", "best_ask": "0.958"}], "timestamp": "1769384013449", "event_type": "price_change"}}
{"_local_timestamp": "2026-01-25T23:33:33.626511+00:00", "data": {"market": "0x8d8b98fb4c290c4e152ce8b653c5598b74a630dd1dbb800a5f328ea9c8b00727", "price_changes": [{"asset_id": "80938914484826983068438930343848557974856639667615266122989436725895029352478", "price": "0.061", "size": "30", "side": "SELL", "hash": "a037be77af4c6b69bfa15089b69564b1303c3030", "best_bid": "0.042", "best_ask": "0.058"}, {"asset_id": "78474559114932529051705203752686517828085200880957778785050112163927946260911", "price": "0.939", "size": "30", "side": "BUY", "hash": "78e48e7c32621ffe581ab555adbd693e8573fab1", "best_bid": "0.942", "best_ask": "0.958"}], "timestamp": "1769384013526", "event_type": "price_change"}}
{"_local_timestamp": "2026-01-25T23:33:33.735123+00:00", "data": {"market": "0x6a3bc08c62413e6594164bc15aa07b282b22a6d7efc61cd69df92b63f4132289", "price_changes": [{"asset_id": "5598960237790161917534060866496363286228389060029699153094526893891604621525", "price": "0.912", "size": "25", "side": "BUY", "hash": "b00e547e873b1643d1906419e0105933d777733a", "best_bid": "0.99", "best_ask": "0.991"}, {"asset_id": "99482729937705145912235477495415874028392807588978105657655512338616047660547", "price": "0.088", "size": "25", "side": "SELL", "hash": "c28039b4c40632c6bc6264ee98a9f01b1852e814", "best_bid": "0.009", "best_ask": "0.01"}], "timestamp": "1769384013618", "event_type": "price_change"}}
{"_local_timestamp": "2026-01-25T23:33:33.742048+00:00", "data": {"market": "0x8d8b98fb4c290c4e152ce8b653c5598b74a630dd1dbb800a5f328ea9c8b00727", "price_changes": [{"asset_id": "80938914484826983068438930343848557974856639667615266122989436725895029352478", "price": "0.061", "size": "0", "side": "SELL", "hash": "6124c53d8085288b1cf4e7da73bd2e2dd429a1b4", "best_bid": "0.042", "best_ask": "0.058"}, {"asset_id": "78474559114932529051705203752686517828085200880957778785050112163927946260911", "price": "0.939", "size": "0", "side": "BUY", "hash": "74fcb6b5ead9752ac1cf9a25b850ed1417e2e18c", "best_bid": "0.942", "best_ask": "0.958"}], "timestamp": "1769384013668", "event_type": "price_change"}}
{"_local_timestamp": "2026-01-25T23:33:33.830810+00:00", "data": {"market": "0x8d8b98fb4c290c4e152ce8b653c5598b74a630dd1dbb800a5f328ea9c8b00727", "price_changes": [{"asset_id": "80938914484826983068438930343848557974856639667615266122989436725895029352478", "price": "0.065", "size": "35.38", "side": "SELL", "hash": "86b6d62e1ad657634430093d1f6522c60305fd65", "best_bid": "0.042", "best_ask": "0.058"}, {"asset_id": "78474559114932529051705203752686517828085200880957778785050112163927946260911", "price": "0.935", "size": "35.38", "side": "BUY", "hash": "34e327a73c23f445f1a49b20a042364493e66908", "best_bid": "0.942", "best_ask": "0.958"}], "timestamp": "1769384013761", "event_type": "price_change"}}
{"_local_timestamp": "2026-01-25T23:33:33.831522+00:00", "data": {"market": "0x6a3bc08c62413e6594164bc15aa07b282b22a6d7efc61cd69df92b63f4132289", "price_changes": [{"asset_id": "5598960237790161917534060866496363286228389060029699153094526893891604621525", "price": "0.912", "size": "0", "side": "BUY", "hash": "8fbd5bd690c319e9cafa855b06128ad46ec9af44", "best_bid": "0.99", "best_ask": "0.991"}, {"asset_id": "99482729937705145912235477495415874028392807588978105657655512338616047660547", "price": "0.088", "size": "0", "side": "SELL", "hash": "2b9a796401856a66c9b19bc97ad322be14ad2b05", "best_bid": "0.009", "best_ask": "0.01"}], "timestamp": "1769384013762", "event_type": "price_change"}}
{"_local_timestamp": "2026-01-25T23:33:34.319529+00:00", "data": {"market": "0x8d8b98fb4c290c4e152ce8b653c5598b74a630dd1dbb800a5f328ea9c8b00727", "price_changes": [{"asset_id": "78474559114932529051705203752686517828085200880957778785050112163927946260911", "price": "0.94", "size": "0", "side": "BUY", "hash": "cc3f60cee9c9e824b2d2ed1353b9f5641724f692", "best_bid": "0.942", "best_ask": "0.958"}, {"asset_id": "80938914484826983068438930343848557974856639667615266122989436725895029352478", "price": "0.06", "size": "0", "side": "SELL", "hash": "91d64a729dc527a352cff1afb80df9bffef23768", "best_bid": "0.042", "best_ask": "0.058"}], "timestamp": "1769384014246", "event_type": "price_change"}}
{"_local_timestamp": "2026-01-25T23:33:34.378134+00:00", "data": {"market": "0x8d8b98fb4c290c4e152ce8b653c5598b74a630dd1dbb800a5f328ea9c8b00727", "price_changes": [{"asset_id": "78474559114932529051705203752686517828085200880957778785050112163927946260911", "price": "0.934", "size": "85", "side": "BUY", "hash": "5096b3d96b114aed3353d99aac7224f615b6e53b", "best_bid": "0.942", "best_ask": "0.958"}, {"asset_id": "80938914484826983068438930343848557974856639667615266122989436725895029352478", "price": "0.066", "size": "85", "side": "SELL", "hash": "9322400547322d1b90665d5043b0008e09aff706", "best_bid": "0.042", "best_ask": "0.058"}], "timestamp": "1769384014307", "event_type": "price_change"}}
{"_local_timestamp": "2026-01-25T23:33:34.414173+00:00", "data": {"market": "0x6a3bc08c62413e6594164bc15aa07b282b22a6d7efc61cd69df92b63f4132289", "price_changes": [{"asset_id": "5598960237790161917534060866496363286228389060029699153094526893891604621525", "price": "0.912", "size": "25", "side": "BUY", "hash": "f63563f1b3fcf90420d42952d772a72b2b1b9b2c", "best_bid": "0.99", "best_ask": "0.991"}, {"asset_id": "99482729937705145912235477495415874028392807588978105657655512338616047660547", "price": "0.088", "size": "25", "side": "SELL", "hash": "968dab89ec9f634e6f3b0eca5d3a2dcb503eadca", "best_bid": "0.009", "best_ask": "0.01"}], "timestamp": "1769384014351", "event_type": "price_change"}}
{"_local_timestamp": "2026-01-25T23:33:35.803092+00:00", "data": {"market": "0x8d8b98fb4c290c4e152ce8b653c5598b74a630dd1dbb800a5f328ea9c8b00727", "price_changes": [{"asset_id": "78474559114932529051705203752686517828085200880957778785050112163927946260911", "price": "0.936", "size": "60", "side": "BUY", "hash": "de41d5124177ddd14b3571a8cfe4fd10f3d20284", "best_bid": "0.942", "best_ask": "0.958"}, {"asset_id": "80938914484826983068438930343848557974856639667615266122989436725895029352478", "price": "0.064", "size": "60", "side": "SELL", "hash": "1a5828828161c8397a4913728207c6821290213c", "best_bid": "0.042", "best_ask": "0.058"}], "timestamp": "1769384015733", "event_type": "price_change"}}
{"_local_timestamp": "2026-01-25T23:33:35.907386+00:00", "data": {"market": "0x8d8b98fb4c290c4e152ce8b653c5598b74a630dd1dbb800a5f328ea9c8b00727", "price_changes": [{"asset_id": "80938914484826983068438930343848557974856639667615266122989436725895029352478", "price": "0.065", "size": "5.38", "side": "SELL", "hash": "d2f47d8706c66d82879b1ce2784c9b002e2e1c0f", "best_bid": "0.042", "best_ask": "0.058"}, {"asset_id": "78474559114932529051705203752686517828085200880957778785050112163927946260911", "price": "0.935", "size": "5.38", "side": "BUY", "hash": "27f8b9946e2f97085ef1b2d524408e8e658581dd", "best_bid": "0.942", "best_ask": "0.958"}], "timestamp": "1769384015839", "event_type": "price_change"}}
{"_local_timestamp": "2026-01-25T23:33:35.912989+00:00", "data": {"market": "0x6a3bc08c62413e6594164bc15aa07b282b22a6d7efc61cd69df92b63f4132289", "price_changes": [{"asset_id": "5598960237790161917534060866496363286228389060029699153094526893891604621525", "price": "0.912", "size": "50", "side": "BUY", "hash": "5811435a8c79dc3633126b1e2e2a698684d38c5e", "best_bid": "0.99", "best_ask": "0.991"}, {"asset_id": "99482729937705145912235477495415874028392807588978105657655512338616047660547", "price": "0.088", "size": "50", "side": "SELL", "hash": "e2c499d97d7e68ef5713276ca5bea29cd208b677", "best_bid": "0.009", "best_ask": "0.01"}], "timestamp": "1769384015846", "event_type": "price_change"}}
{"_local_timestamp": "2026-01-25T23:33:35.968253+00:00", "data": {"market": "0x8d8b98fb4c290c4e152ce8b653c5598b74a630dd1dbb800a5f328ea9c8b00727", "price_changes": [{"asset_id": "80938914484826983068438930343848557974856639667615266122989436725895029352478", "price": "0.063", "size": "30", "side": "SELL", "hash": "f5cfc66ff42edf952369ebe9bc547d7df7ac817b", "best_bid": "0.042", "best_ask": "0.058"}, {"asset_id": "78474559114932529051705203752686517828085200880957778785050112163927946260911", "price": "0.937", "size": "30", "side": "BUY", "hash": "80e07e76f19f1c67a03f508cee7cc7cd0d594dd1", "best_bid": "0.942", "best_ask": "0.958"}], "timestamp": "1769384015896", "event_type": "price_change"}}
{"_local_timestamp": "2026-01-25T23:33:36.019375+00:00", "data": {"market": "0x6a3bc08c62413e6594164bc15aa07b282b22a6d7efc61cd69df92b63f4132289", "price_changes": [{"asset_id": "5598960237790161917534060866496363286228389060029699153094526893891604621525", "price": "0.912", "size": "25", "side": "BUY", "hash": "3a5e0d05bcda08410cb7d752fc7de3a9a416226b", "best_bid": "0.99", "best_ask": "0.991"}, {"asset_id": "99482729937705145912235477495415874028392807588978105657655512338616047660547", "price": "0.088", "size": "25", "side": "SELL", "hash": "00c45e905865d82ea7463e49c5eba034e81cc769", "best_bid": "0.009", "best_ask": "0.01"}], "timestamp": "1769384015947", "event_type": "price_change"}}
{"_local_timestamp": "2026-01-25T23:33:36.153836+00:00", "data": {"market": "0x8d8b98fb4c290c4e152ce8b653c5598b74a630dd1dbb800a5f328ea9c8b00727", "price_changes": [{"asset_id": "78474559114932529051705203752686517828085200880957778785050112163927946260911", "price": "0.941", "size": "0", "side": "BUY", "hash": "df25421ccf731b36b81369d77000074e51203841", "best_bid": "0.942", "best_ask": "0.958"}, {"asset_id": "80938914484826983068438930343848557974856639667615266122989436725895029352478", "price": "0.059", "size": "0", "side": "SELL", "hash": "aafbdeeb29bdc3122d275aedd8c900d6ee16b750", "best_bid": "0.042", "best_ask": "0.058"}], "timestamp": "1769384016070", "event_type": "price_change"}}
{"_local_timestamp": "2026-01-25T23:33:37.011762+00:00", "data": {"market": "0x8d8b98fb4c290c4e152ce8b653c5598b74a630dd1dbb800a5f328ea9c8b00727", "price_changes": [{"asset_id": "78474559114932529051705203752686517828085200880957778785050112163927946260911", "price": "0.934", "size": "55", "side": "BUY", "hash": "7377ac4d6b57c46e80e0139f28ef36178f5b8d5c", "best_bid": "0.942", "best_ask": "0.958"}, {"asset_id": "80938914484826983068438930343848557974856639667615266122989436725895029352478", "price": "0.066", "size": "55", "side": "SELL", "hash": "abb98490e63d38aeca898de67ede70f2b5584452", "best_bid": "0.042", "best_ask": "0.058"}], "timestamp": "1769384016948", "event_type": "price_change"}}
{"_local_timestamp": "2026-01-25T23:33:37.075519+00:00", "data": {"market": "0x8d8b98fb4c290c4e152ce8b653c5598b74a630dd1dbb800a5f328ea9c8b00727", "price_changes": [{"asset_id": "78474559114932529051705203752686517828085200880957778785050112163927946260911", "price": "0.936", "size": "90", "side": "BUY", "hash": "ca0af40090b6783a83c9ea35501de902cc39cabe", "best_bid": "0.942", "best_ask": "0.958"}, {"asset_id": "80938914484826983068438930343848557974856639667615266122989436725895029352478", "price": "0.064", "size": "90", "side": "SELL", "hash": "84474890d2ca6bd8f9706f64a92216a9fb9d0d1c", "best_bid": "0.042", "best_ask": "0.058"}], "timestamp": "1769384017008", "event_type": "price_change"}}
{"_local_timestamp": "2026-01-25T23:33:37.118486+00:00", "data": {"market": "0x6a3bc08c62413e6594164bc15aa07b282b22a6d7efc61cd69df92b63f4132289", "price_changes": [{"asset_id": "5598960237790161917534060866496363286228389060029699153094526893891604621525", "price": "0.912", "size": "50", "side": "BUY", "hash": "adbbc89dc383c6e04d9976fa68b4c4fd64356f41", "best_bid": "0.99", "best_ask": "0.991"}, {"asset_id": "99482729937705145912235477495415874028392807588978105657655512338616047660547", "price": "0.088", "size": "50", "side": "SELL", "hash": "26e910ee5dd917ead9f4ae7e020c410c74b6096a", "best_bid": "0.009", "best_ask": "0.01"}], "timestamp": "1769384017055", "event_type": "price_change"}}
{"_local_timestamp": "2026-01-25T23:33:37.198381+00:00", "data": {"market": "0x8d8b98fb4c290c4e152ce8b653c5598b74a630dd1dbb800a5f328ea9c8b00727", "price_changes": [{"asset_id": "80938914484826983068438930343848557974856639667615266122989436725895029352478", "price": "0.058", "size": "0", "side": "SELL", "hash": "aaa4ddc40e833ef91e942d69341e50b424734724", "best_bid": "0.042", "best_ask": "0.063"}, {"asset_id": "78474559114932529051705203752686517828085200880957778785050112163927946260911", "price": "0.942", "size": "0", "side": "BUY", "hash": "e6e6f7e32c9047b6c1e3fc2fe626e23172bee5de", "best_bid": "0.937", "best_ask": "0.958"}], "timestamp": "1769384017123", "event_type": "price_change"}}
{"_local_timestamp": "2026-01-25T23:33:37.219727+00:00", "data": {"market": "0x8d8b98fb4c290c4e152ce8b653c5598b74a630dd1dbb800a5f328ea9c8b00727", "price_changes": [{"asset_id": "80938914484826983068438930343848557974856639667615266122989436725895029352478", "price": "0.038", "size": "40", "side": "BUY", "hash": "7f520ebf4d01fed85dbfdc68d5e3fe60fd01fd3d", "best_bid": "0.042", "best_ask": "0.063"}, {"asset_id": "78474559114932529051705203752686517828085200880957778785050112163927946260911", "price": "0.962", "size": "40", "side": "SELL", "hash": "1496a4370ceeb3a1177b9db61740a734d6ef83f5", "best_bid": "0.937", "best_ask": "0.958"}], "timestamp": "1769384017149", "event_type": "price_change"}}
{"_local_timestamp": "2026-01-25T23:33:37.223722+00:00", "data": {"market": "0x8d8b98fb4c290c4e152ce8b653c5598b74a630dd1dbb800a5f328ea9c8b00727", "price_changes": [{"asset_id": "80938914484826983068438930343848557974856639667615266122989436725895029352478", "price": "0.063", "size": "256", "side": "SELL", "hash": "643ad18ecc34c63e42cd94944f07274030c66692", "best_bid": "0.042", "best_ask": "0.063"}, {"asset_id": "78474559114932529051705203752686517828085200880957778785050112163927946260911", "price": "0.937", "size": "256", "side": "BUY", "hash": "b0ee3747926bc1b4ec7ba35bdb2df65d2c519653", "best_bid": "0.937", "best_ask": "0.958"}], "timestamp": "1769384017150", "event_type": "price_change"}}
{"_local_timestamp": "2026-01-25T23:33:37.235984+00:00", "data": {"market": "0x6a3bc08c62413e6594164bc15aa07b282b22a6d7efc61cd69df92b63f4132289", "price_changes": [{"asset_id": "5598960237790161917534060866496363286228389060029699153094526893891604621525", "price": "0.912", "size": "25", "side": "BUY", "hash": "5968f66594495129e3de7484257bbf063cce529e", "best_bid": "0.99", "best_ask": "0.991"}, {"asset_id": "99482729937705145912235477495415874028392807588978105657655512338616047660547", "price": "0.088", "size": "25", "side": "SELL", "hash": "ef41e86048a60359cbe45e4f3db36ce79477b9e1", "best_bid": "0.009", "best_ask": "0.01"}], "timestamp": "1769384017171", "event_type": "price_change"}}
{"_local_timestamp": "2026-01-25T23:33:37.301990+00:00", "data": {"market": "0x8d8b98fb4c290c4e152ce8b653c5598b74a630dd1dbb800a5f328ea9c8b00727", "price_changes": [{"asset_id": "80938914484826983068438930343848557974856639667615266122989436725895029352478", "price": "0.062", "size": "7.14", "side": "SELL", "hash": "623f734845016f71dbbedbaeb13fddf10c6fbaf7", "best_bid": "0.042", "best_ask": "0.062"}, {"asset_id": "78474559114932529051705203752686517828085200880957778785050112163927946260911", "price": "0.938", "size": "7.14", "side": "BUY", "hash": "149f641ef43e26451c8d60c04bd371752f179a2a", "best_bid": "0.938", "best_ask": "0.958"}], "timestamp": "1769384017228", "event_type": "price_change"}}
{"_local_timestamp": "2026-01-25T23:33:38.129229+00:00", "data": {"market": "0x8d8b98fb4c290c4e152ce8b653c5598b74a630dd1dbb800a5f328ea9c8b00727", "price_changes": [{"asset_id": "78474559114932529051705203752686517828085200880957778785050112163927946260911", "price": "0.936", "size": "60", "side": "BUY", "hash": "f43ea2b03946130bfad15aa868f11c85feb1fcb7", "best_bid": "0.938", "best_ask": "0.958"}, {"asset_id": "80938914484826983068438930343848557974856639667615266122989436725895029352478", "price": "0.064", "size": "60", "side": "SELL", "hash": "dd9a4cbf7c6b27c7f54fe5c16ba34c62bb7b70eb", "best_bid": "0.042", "best_ask": "0.062"}], "timestamp": "1769384018056", "event_type": "price_change"}}
{"_local_timestamp": "2026-01-25T23:33:38.170298+00:00", "data": {"market": "0x8d8b98fb4c290c4e152ce8b653c5598b74a630dd1dbb800a5f328ea9c8b00727", "price_changes": [{"asset_id": "78474559114932529051705203752686517828085200880957778785050112163927946260911", "price": "0.938", "size": "37.14", "side": "BUY", "hash": "6d2bae725ab0836e7ab935e2b75ed85a54ca7be1", "best_bid": "0.938", "best_ask": "0.958"}, {"asset_id": "80938914484826983068438930343848557974856639667615266122989436725895029352478", "price": "0.062", "size": "37.14", "side": "SELL", "hash": "9bfa520bec3e2beb26fae0771fe7e35e9a45a1b3", "best_bid": "0.042", "best_ask": "0.062"}], "timestamp": "1769384018102", "event_type": "price_change"}}
{"_local_timestamp": "2026-01-25T23:33:38.217597+00:00", "data": {"market": "0x6a3bc08c62413e6594164bc15aa07b282b22a6d7efc61cd69df92b63f4132289", "price_changes": [{"asset_id": "5598960237790161917534060866496363286228389060029699153094526893891604621525", "price": "0.351", "size": "0", "side": "BUY", "hash": "7f21d5c36a1974abdb00b860e37ebf5aec10b8d0", "best_bid": "0.99", "best_ask": "0.991"}, {"asset_id": "99482729937705145912235477495415874028392807588978105657655512338616047660547", "price": "0.649", "size": "0", "side": "SELL", "hash": "e8d216c41beabe15025aee7f17cd81ec395dcf14", "best_bid": "0.009", "best_ask": "0.01"}], "timestamp": "1769384018151", "event_type": "price_change"}}
{"_local_timestamp": "2026-01-25T23:33:38.251723+00:00", "data": {"market": "0x6a3bc08c62413e6594164bc15aa07b282b22a6d7efc61cd69df92b63f4132289", "price_changes": [{"asset_id": "5598960237790161917534060866496363286228389060029699153094526893891604621525", "price": "0.912", "size": "50", "side": "BUY", "hash": "da4cc4bebecca2c0e282aea720e4223a2eb0c5b8", "best_bid": "0.99", "best_ask": "0.991"}, {"asset_id": "99482729937705145912235477495415874028392807588978105657655512338616047660547", "price": "0.088", "size": "50", "side": "SELL", "hash": "588df748bf4fbc2268c2f5f6114fbc502654ebfd", "best_bid": "0.009", "best_ask": "0.01"}], "timestamp": "1769384018174", "event_type": "price_change"}}
{"_local_timestamp": "2026-01-25T23:33:38.341571+00:00", "data": {"market": "0x6a3bc08c62413e6594164bc15aa07b282b22a6d7efc61cd69df92b63f4132289", "price_changes": [{"asset_id": "5598960237790161917534060866496363286228389060029699153094526893891604621525", "price": "0.42", "size": "10", "side": "BUY", "hash": "dda4f51fda2e3293f7994f4b5d43993d83de90ff", "best_bid": "0.99", "best_ask": "0.991"}, {"asset_id": "99482729937705145912235477495415874028392807588978105657655512338616047660547", "price": "0.58", "size": "10", "side": "SELL", "hash": "2c5a2afe5f252e44a5c50ab66a473599ba8121c9", "best_bid": "0.009", "best_ask": "0.01"}], "timestamp": "1769384018270", "event_type": "price_change"}}
{"_local_timestamp": "2026-01-25T23:33:38.367830+00:00", "data": {"market": "0x6a3bc08c62413e6594164bc15aa07b282b22a6d7efc61cd69df92b63f4132289", "price_changes": [{"asset_id": "5598960237790161917534060866496363286228389060029699153094526893891604621525", "price": "0.912", "size": "25", "side": "BUY", "hash": "428b5007b4a10858eea5e57c4cf058e2b339a57f", "best_bid": "0.99", "best_ask": "0.991"}, {"asset_id": "99482729937705145912235477495415874028392807588978105657655512338616047660547", "price": "0.088", "size": "25", "side": "SELL", "hash": "31c85b5ae557b44b58dcea7a884c39c895c7d0ac", "best_bid": "0.009", "best_ask": "0.01"}], "timestamp": "1769384018296", "event_type": "price_change"}}
{"_local_timestamp": "2026-01-25T23:33:38.590382+00:00", "data": {"market": "0x8d8b98fb4c290c4e152ce8b653c5598b74a630dd1dbb800a5f328ea9c8b00727", "price_changes": [{"asset_id": "80938914484826983068438930343848557974856639667615266122989436725895029352478", "price": "0.038", "size": "26", "side": "BUY", "hash": "2512195aae55fe3a76104f25f640b76c7e9d1152", "best_bid": "0.042", "best_ask": "0.062"}, {"asset_id": "78474559114932529051705203752686517828085200880957778785050112163927946260911", "price": "0.962", "size": "26", "side": "SELL", "hash": "ca14ca024397d8a107a29bc1fc558a190dcffdbb", "best_bid": "0.938", "best_ask": "0.958"}], "timestamp": "1769384018522", "event_type": "price_change"}}
{"_local_timestamp": "2026-01-25T23:33:38.591727+00:00", "data": {"market": "0x8d8b98fb4c290c4e152ce8b653c5598b74a630dd1dbb800a5f328ea9c8b00727", "price_changes": [{"asset_id": "80938914484826983068438930343848557974856639667615266122989436725895029352478", "price": "0.063", "size": "30", "side": "SELL", "hash": "2512195aae55fe3a76104f25f640b76c7e9d1152", "best_bid": "0.042", "best_ask": "0.062"}, {"asset_id": "78474559114932529051705203752686517828085200880957778785050112163927946260911", "price": "0.937", "size": "30", "side": "BUY", "hash": "ca14ca024397d8a107a29bc1fc558a190dcffdbb", "best_bid": "0.938", "best_ask": "0.958"}], "timestamp": "1769384018522", "event_type": "price_change"}}
{"_local_timestamp": "2026-01-25T23:33:38.620231+00:00", "data": {"market": "0x8d8b98fb4c290c4e152ce8b653c5598b74a630dd1dbb800a5f328ea9c8b00727", "price_changes": [{"asset_id": "80938914484826983068438930343848557974856639667615266122989436725895029352478", "price": "0.061", "size": "226", "side": "SELL", "hash": "1d1e1656022de1e4f2118a6030a882345b4fcf4b", "best_bid": "0.042", "best_ask": "0.061"}, {"asset_id": "78474559114932529051705203752686517828085200880957778785050112163927946260911", "price": "0.939", "size": "226", "side": "BUY", "hash": "810bf6b860bf3fafd7af5f68081a0afb53892863", "best_bid": "0.939", "best_ask": "0.958"}], "timestamp": "1769384018547", "event_type": "price_change"}}
{"_local_timestamp": "2026-01-25T23:33:38.621085+00:00", "data": {"market": "0x8d8b98fb4c290c4e152ce8b653c5598b74a630dd1dbb800a5f328ea9c8b00727", "price_changes": [{"asset_id": "80938914484826983068438930343848557974856639667615266122989436725895029352478", "price": "0.039", "size": "23", "side": "BUY", "hash": "1e545b179627b216241d56672401633404d3b45e", "best_bid": "0.042", "best_ask": "0.061"}, {"asset_id": "78474559114932529051705203752686517828085200880957778785050112163927946260911", "price": "0.961", "size": "23", "side": "SELL", "hash": "d1e86702417ae3025e14a3bcfd89dfaf5b03b0da", "best_bid": "0.939", "best_ask": "0.958"}], "timestamp": "1769384018548", "event_type": "price_change"}}
{"_local_timestamp": "2026-01-25T23:33:39.098828+00:00", "data": {"market": "0x8d8b98fb4c290c4e152ce8b653c5598b74a630dd1dbb800a5f328ea9c8b00727", "price_changes": [{"asset_id": "78474559114932529051705203752686517828085200880957778785050112163927946260911", "price": "0.938", "size": "47.14", "side": "BUY", "hash": "15e401bbdd8206e0f77dce9a25118bd1d22434be", "best_bid": "0.939", "best_ask": "0.958"}, {"asset_id": "80938914484826983068438930343848557974856639667615266122989436725895029352478", "price": "0.062", "size": "47.14", "side": "SELL", "hash": "553e35d1ada9902df1ec8bdbdb96fc90feb35535", "best_bid": "0.042", "best_ask": "0.061"}], "timestamp": "1769384019004", "event_type": "price_change"}}
{"_local_timestamp": "2026-01-25T23:33:39.327379+00:00", "data": {"market": "0x6a3bc08c62413e6594164bc15aa07b282b22a6d7efc61cd69df92b63f4132289", "price_changes": [{"asset_id": "5598960237790161917534060866496363286228389060029699153094526893891604621525", "price": "0.419", "size": "0", "side": "BUY", "hash": "3b64e46886cfcb676905f6faf5c55a802d99c829", "best_bid": "0.99", "best_ask": "0.991"}, {"asset_id": "99482729937705145912235477495415874028392807588978105657655512338616047660547", "price": "0.581", "size": "0", "side": "SELL", "hash": "1ae291fd74a07506c4c6eeb0488bda9e73d77f3f", "best_bid": "0.009", "best_ask": "0.01"}], "timestamp": "1769384019256", "event_type": "price_change"}}
{"_local_timestamp": "2026-01-25T23:33:39.348270+00:00", "data": {"market": "0x6a3bc08c62413e6594164bc15aa07b282b22a6d7efc61cd69df92b63f4132289", "price_changes": [{"asset_id": "5598960237790161917534060866496363286228389060029699153094526893891604621525", "price": "0.421", "size": "20", "side": "BUY", "hash": "7f3a2800e2a97840e04ed55dab6be82825d16778", "best_bid": "0.99", "best_ask": "0.991"}, {"asset_id": "99482729937705145912235477495415874028392807588978105657655512338616047660547", "price": "0.579", "size": "20", "side": "SELL", "hash": "685a0ddba76c3875c6613faf53938badbba6825a", "best_bid": "0.009", "best_ask": "0.01"}], "timestamp": "1769384019280", "event_type": "price_change"}}
{"_local_timestamp": "2026-01-25T23:33:39.450249+00:00", "data": {"market": "0x6a3bc08c62413e6594164bc15aa07b282b22a6d7efc61cd69df92b63f4132289", "price_changes": [{"asset_id": "5598960237790161917534060866496363286228389060029699153094526893891604621525", "price": "0.912", "size": "50", "side": "BUY", "hash": "e9ecfc6c19528f657534e426966054869572c09e", "best_bid": "0.99", "best_ask": "0.991"}, {"asset_id": "99482729937705145912235477495415874028392807588978105657655512338616047660547", "price": "0.088", "size": "50", "side": "SELL", "hash": "9e5eeb9010fb87cd3c5a7df66f868a49f592fa91", "best_bid": "0.009", "best_ask": "0.01"}], "timestamp": "1769384019384", "event_type": "price_change"}}
{"_local_timestamp": "2026-01-25T23:33:39.565849+00:00", "data": {"market": "0x6a3bc08c62413e6594164bc15aa07b282b22a6d7efc61cd69df92b63f4132289", "price_changes": [{"asset_id": "5598960237790161917534060866496363286228389060029699153094526893891604621525", "price": "0.912", "size": "25", "side": "BUY", "hash": "ce7878520f43110e117f5e1447542c4303eef55e", "best_bid": "0.99", "best_ask": "0.991"}, {"asset_id": "99482729937705145912235477495415874028392807588978105657655512338616047660547", "price": "0.088", "size": "25", "side": "SELL", "hash": "1a96e8d64025ff84a3903390dd84f48a3f56d345", "best_bid": "0.009", "best_ask": "0.01"}], "timestamp": "1769384019492", "event_type": "price_change"}}
{"_local_timestamp": "2026-01-25T23:33:39.769394+00:00", "data": {"market": "0x8d8b98fb4c290c4e152ce8b653c5598b74a630dd1dbb800a5f328ea9c8b00727", "price_changes": [{"asset_id": "80938914484826983068438930343848557974856639667615266122989436725895029352478", "price": "0.063", "size": "0", "side": "SELL", "hash": "9ae6c7cdee11e3c17b118ddaf00f6cab3cd53978", "best_bid": "0.042", "best_ask": "0.061"}, {"asset_id": "78474559114932529051705203752686517828085200880957778785050112163927946260911", "price": "0.937", "size": "0", "side": "BUY", "hash": "c71ab51b010c9dbabbad9e9caf7a510d2af0914d", "best_bid": "0.939", "best_ask": "0.958"}], "timestamp": "1769384019698", "event_type": "price_change"}}
{"_local_timestamp": "2026-01-25T23:33:39.842149+00:00", "data": {"market": "0x8d8b98fb4c290c4e152ce8b653c5598b74a630dd1dbb800a5f328ea9c8b00727", "price_changes": [{"asset_id": "80938914484826983068438930343848557974856639667615266122989436725895029352478", "price": "0.062", "size": "40", "side": "SELL", "hash": "f931dfb3f45910b1ccc0b1067966cb3d5bbb7d67", "best_bid": "0.042", "best_ask": "0.061"}, {"asset_id": "78474559114932529051705203752686517828085200880957778785050112163927946260911", "price": "0.938", "size": "40", "side": "BUY", "hash": "12278a657647b983020050fa1c9e5ecd6a836e29", "best_bid": "0.939", "best_ask": "0.958"}], "timestamp": "1769384019766", "event_type": "price_change"}}
{"_local_timestamp": "2026-01-25T23:33:39.873908+00:00", "data": {"market": "0x8d8b98fb4c290c4e152ce8b653c5598b74a630dd1dbb800a5f328ea9c8b00727", "price_changes": [{"asset_id": "80938914484826983068438930343848557974856639667615266122989436725895029352478", "price": "0.06", "size": "30", "side": "SELL", "hash": "5fa0c512d1fbb6c2ffcb7112ed3f3f3b4797be37", "best_bid": "0.042", "best_ask": "0.06"}, {"asset_id": "78474559114932529051705203752686517828085200880957778785050112163927946260911", "price": "0.94", "size": "30", "side": "BUY", "hash": "265b97a2121c97ea3c5494a4b4c5c402a0c1888f", "best_bid": "0.94", "best_ask": "0.958"}], "timestamp": "1769384019801", "event_type": "price_change"}}
{"_local_timestamp": "2026-01-25T23:33:39.898745+00:00", "data": {"market": "0x8d8b98fb4c290c4e152ce8b653c5598b74a630dd1dbb800a5f328ea9c8b00727", "price_changes": [{"asset_id": "80938914484826983068438930343848557974856639667615266122989436725895029352478", "price": "0.039", "size": "0", "side": "BUY", "hash": "d94129db3e20f420b3fadd17628eeb1a3c3cdfd2", "best_bid": "0.042", "best_ask": "0.06"}, {"asset_id": "78474559114932529051705203752686517828085200880957778785050112163927946260911", "price": "0.961", "size": "0", "side": "SELL", "hash": "78456997a7d69ba792d9ccaf49867263d01f7f03", "best_bid": "0.94", "best_ask": "0.958"}], "timestamp": "1769384019829", "event_type": "price_change"}}
{"_local_timestamp": "2026-01-25T23:33:40.330975+00:00", "data": {"market": "0x378f76341e555b6d54b89cc527afde5f8c293025cf6f48980145b94dc5726ce7", "price_changes": [{"asset_id": "7664065636701295840769263287437558246574946591549211748470097864098826204283", "price": "0.26", "size": "100", "side": "BUY", "hash": "685ae137cfc1659bf9ed0e90eab7f37c921b8909", "best_bid": "0.89", "best_ask": "0.9"}, {"asset_id": "100508935738063536113321312580877764668655616361107299342990907747250271040586", "price": "0.74", "size": "100", "side": "SELL", "hash": "167f690bc6c6c2161930164c36d27268dfd5b8b8", "best_bid": "0.1", "best_ask": "0.11"}], "timestamp": "1769384020105", "event_type": "price_change"}}
{"_local_timestamp": "2026-01-25T23:33:40.346598+00:00", "data": {"market": "0xffe62176c4eb6eb83ccff978b60f26f2c106398fa3c12f8f10c390069f1c0327", "price_changes": [{"asset_id": "96053159599260004603905372121344488945548265884928713587631467689929621790840", "price": "0.252", "size": "100", "side": "BUY", "hash": "9c76217ceea378fcb458cb49b434a7dc951ce669", "best_bid": "0.957", "best_ask": "0.967"}, {"asset_id": "98032013532486965224887573635135423443725925647904190791194069311921831803628", "price": "0.748", "size": "100", "side": "SELL", "hash": "9b167dcdc442dddce4e0ae1da6a9d4342e9873fb", "best_bid": "0.033", "best_ask": "0.043"}], "timestamp": "1769384020105", "event_type": "price_change"}}
{"_local_timestamp": "2026-01-25T23:33:40.359005+00:00", "data": {"market": "0xd55b7e07b66b1d6702aa8f8c0c761a4f2838b55fa31395676bd0150b9fabb3a4", "price_changes": [{"asset_id": "71934813421791148309055586854264573769390957341135501297936685395378523616284", "price": "0.241", "size": "100", "side": "BUY", "hash": "f1df4982c50c509817578e561ee8b6bf7c808d13", "best_bid": "0.934", "best_ask": "0.936"}, {"asset_id": "100252164279000180790972381908103319470423853298906411193188634318600215482432", "price": "0.759", "size": "100", "side": "SELL", "hash": "edce1d49d03a8c232618bf20abf8f1286451e668", "best_bid": "0.064", "best_ask": "0.066"}], "timestamp": "1769384020105", "event_type": "price_change"}}
{"_local_timestamp": "2026-01-25T23:33:40.360427+00:00", "data": {"market": "0xc512e0c0fa2d19ad6fe8bd885b3089a80fa2bf8382c104321c7359e7014cf567", "price_changes": [{"asset_id": "83334600217205368371784439992248024883439507053390974906923524834233064415427", "price": "0.15", "size": "0", "side": "BUY", "hash": "79a5ef5ffb0c378e57a8c29c3169aae49f1fcb97", "best_bid": "0.651", "best_ask": "0.685"}, {"asset_id": "107858355690036086153439322350404767983557761088489336428558005982078386490488", "price": "0.85", "size": "0", "side": "SELL", "hash": "78ce84d84b186cff1f5e278d719329fa07ada0c2", "best_bid": "0.315", "best_ask": "0.349"}], "timestamp": "1769384020105", "event_type": "price_change"}}
{"_local_timestamp": "2026-01-25T23:33:40.481962+00:00", "data": {"market": "0x6a3bc08c62413e6594164bc15aa07b282b22a6d7efc61cd69df92b63f4132289", "price_changes": [{"asset_id": "5598960237790161917534060866496363286228389060029699153094526893891604621525", "price": "0.912", "size": "50", "side": "BUY", "hash": "1a4042e6dbafd8df4fe7eb6e8e08eafd34f1b4d7", "best_bid": "0.99", "best_ask": "0.991"}, {"asset_id": "99482729937705145912235477495415874028392807588978105657655512338616047660547", "price": "0.088", "size": "50", "side": "SELL", "hash": "c838b5d0227c66d78832ae5ea83b6b7f33728683", "best_bid": "0.009", "best_ask": "0.01"}], "timestamp": "1769384020383", "event_type": "price_change"}}
{"_local_timestamp": "2026-01-25T23:33:40.552982+00:00", "data": {"market": "0x6a3bc08c62413e6594164bc15aa07b282b22a6d7efc61cd69df92b63f4132289", "price_changes": [{"asset_id": "5598960237790161917534060866496363286228389060029699153094526893891604621525", "price": "0.912", "size": "25", "side": "BUY", "hash": "e62a3b4292e44c226c2f803b4e1238d6265bc9db", "best_bid": "0.99", "best_ask": "0.991"}, {"asset_id": "99482729937705145912235477495415874028392807588978105657655512338616047660547", "price": "0.088", "size": "25", "side": "SELL", "hash": "8ca016d6970fe987fd6d4aeda4d7a842352782e6", "best_bid": "0.009", "best_ask": "0.01"}], "timestamp": "1769384020487", "event_type": "price_change"}}
{"_local_timestamp": "2026-01-25T23:33:40.591561+00:00", "data": {"market": "0x8d8b98fb4c290c4e152ce8b653c5598b74a630dd1dbb800a5f328ea9c8b00727", "price_changes": [{"asset_id": "80938914484826983068438930343848557974856639667615266122989436725895029352478", "price": "0.06", "size": "37.14", "side": "SELL", "hash": "1ff7f3f31a143ac9f7ba3eb3623acf1a4707715d", "best_bid": "0.042", "best_ask": "0.06"}, {"asset_id": "78474559114932529051705203752686517828085200880957778785050112163927946260911", "price": "0.94", "size": "37.14", "side": "BUY", "hash": "f936220ec7cc7498567adb60a191d7d55dc9b24d", "best_bid": "0.94", "best_ask": "0.958"}], "timestamp": "1769384020518", "event_type": "price_change"}}
{"_local_timestamp": "2026-01-25T23:33:40.638240+00:00", "data": {"market": "0x378f76341e555b6d54b89cc527afde5f8c293025cf6f48980145b94dc5726ce7", "price_changes": [{"asset_id": "7664065636701295840769263287437558246574946591549211748470097864098826204283", "price": "0.23", "size": "171.73", "side": "BUY", "hash": "9ae906264fb96a17144b8e0aa5af792a2d115957", "best_bid": "0.89", "best_ask": "0.9"}, {"asset_id": "100508935738063536113321312580877764668655616361107299342990907747250271040586", "price": "0.77", "size": "171.73", "side": "SELL", "hash": "d3bcc74045a3ca7a10f281ab86a5407adce2e607", "best_bid": "0.1", "best_ask": "0.11"}], "timestamp": "1769384020523", "event_type": "price_change"}}
{"_local_timestamp": "2026-01-25T23:33:40.649359+00:00", "data": {"market": "0xd55b7e07b66b1d6702aa8f8c0c761a4f2838b55fa31395676bd0150b9fabb3a4", "price_changes": [{"asset_id": "71934813421791148309055586854264573769390957341135501297936685395378523616284", "price": "0.243", "size": "50", "side": "BUY", "hash": "beb5805871d01411a485857ebd336e5525de785b", "best_bid": "0.934", "best_ask": "0.936"}, {"asset_id": "100252164279000180790972381908103319470423853298906411193188634318600215482432", "price": "0.757", "size": "50", "side": "SELL", "hash": "72faa40946255a8abe3a0bac945be7dd81548ec5", "best_bid": "0.064", "best_ask": "0.066"}], "timestamp": "1769384020523", "event_type": "price_change"}}
{"_local_timestamp": "2026-01-25T23:33:40.652528+00:00", "data": {"market": "0xffe62176c4eb6eb83ccff978b60f26f2c106398fa3c12f8f10c390069f1c0327", "price_changes": [{"asset_id": "96053159599260004603905372121344488945548265884928713587631467689929621790840", "price": "0.212", "size": "55.07", "side": "BUY", "hash": "26eb9b797665e56e5371b4f826640b509b2631a6", "best_bid": "0.957", "best_ask": "0.967"}, {"asset_id": "98032013532486965224887573635135423443725925647904190791194069311921831803628", "price": "0.788", "size": "55.07", "side": "SELL", "hash": "4d3a9cfc98ce0d93bd657e33e09c75341fddbca0", "best_bid": "0.033", "best_ask": "0.043"}], "timestamp": "1769384020523", "event_type": "price_change"}}
{"_local_timestamp": "2026-01-25T23:33:40.659950+00:00", "data": {"market": "0xc512e0c0fa2d19ad6fe8bd885b3089a80fa2bf8382c104321c7359e7014cf567", "price_changes": [{"asset_id": "83334600217205368371784439992248024883439507053390974906923524834233064415427", "price": "0.11", "size": "634.09", "side": "BUY", "hash": "5220910619ed5d9eb20c1728bea124641663dfa0", "best_bid": "0.651", "best_ask": "0.685"}, {"asset_id": "107858355690036086153439322350404767983557761088489336428558005982078386490488", "price": "0.89", "size": "634.09", "side": "SELL", "hash": "08aa11e45b5bb9e419a6d41a813f53d6f153a977", "best_bid": "0.315", "best_ask": "0.349"}], "timestamp": "1769384020523", "event_type": "price_change"}}
{"_local_timestamp": "2026-01-25T23:33:40.891569+00:00", "data": {"market": "0x8d8b98fb4c290c4e152ce8b653c5598b74a630dd1dbb800a5f328ea9c8b00727", "price_changes": [{"asset_id": "78474559114932529051705203752686517828085200880957778785050112163927946260911", "price": "0.938", "size": "10", "side": "BUY", "hash": "a43dca0724115f8daa15172f30329d56780ab58c", "best_bid": "0.94", "best_ask": "0.958"}, {"asset_id": "80938914484826983068438930343848557974856639667615266122989436725895029352478", "price": "0.062", "size": "10", "side": "SELL", "hash": "52f95d5ab59b16d0d08688da00aae02595307a2b", "best_bid": "0.042", "best_ask": "0.06"}], "timestamp": "1769384020670", "event_type": "price_change"}}
{"_local_timestamp": "2026-01-25T23:33:40.905263+00:00", "data": {"market": "0x8d8b98fb4c290c4e152ce8b653c5598b74a630dd1dbb800a5f328ea9c8b00727", "price_changes": [{"asset_id": "78474559114932529051705203752686517828085200880957778785050112163927946260911", "price": "0.94", "size": "67.14", "side": "BUY", "hash": "e3f3494e07b6d673150c19fa5dba8049d24730e9", "best_bid": "0.94", "best_ask": "0.958"}, {"asset_id": "80938914484826983068438930343848557974856639667615266122989436725895029352478", "price": "0.06", "size": "67.14", "side": "SELL", "hash": "ca6f9d1f8c962634f3361271ed2740f4e0fa5573", "best_bid": "0.042", "best_ask": "0.06"}], "timestamp": "1769384020708", "event_type": "price_change"}}
{"_local_timestamp": "2026-01-25T23:33:41.610800+00:00", "data": {"market": "0x378f76341e555b6d54b89cc527afde5f8c293025cf6f48980145b94dc5726ce7", "price_changes": [{"asset_id": "100508935738063536113321312580877764668655616361107299342990907747250271040586", "price": "0.07", "size": "620.05", "side": "BUY", "hash": "be4d6251fe763a60b96417c21ea56f3139e5add0", "best_bid": "0.1", "best_ask": "0.11"}, {"asset_id": "7664065636701295840769263287437558246574946591549211748470097864098826204283", "price": "0.93", "size": "620.05", "side": "SELL", "hash": "cf066fb620038555ee48bdd147a38009f9584d36", "best_bid": "0.89", "best_ask": "0.9"}], "timestamp": "1769384021521", "event_type": "price_change"}}
{"_local_timestamp": "2026-01-25T23:33:41.612007+00:00", "data": {"market": "0x378f76341e555b6d54b89cc527afde5f8c293025cf6f48980145b94dc5726ce7", "price_changes": [{"asset_id": "100508935738063536113321312580877764668655616361107299342990907747250271040586", "price": "0.07", "size": "1620.05", "side": "BUY", "hash": "15625dae3eb52e09bff1d6562b0ec025253cf9cb", "best_bid": "0.1", "best_ask": "0.11"}, {"asset_id": "7664065636701295840769263287437558246574946591549211748470097864098826204283", "price": "0.93", "size": "1620.05", "side": "SELL", "hash": "fae1388fb51ff4503847cdd60c0b8e91f94ac196", "best_bid": "0.89", "best_ask": "0.9"}], "timestamp": "1769384021531", "event_type": "price_change"}}
{"_local_timestamp": "2026-01-25T23:33:41.632527+00:00", "data": {"market": "0x378f76341e555b6d54b89cc527afde5f8c293025cf6f48980145b94dc5726ce7", "price_changes": [{"asset_id": "100508935738063536113321312580877764668655616361107299342990907747250271040586", "price": "0.08", "size": "100", "side": "BUY", "hash": "092ff5aa01777ecb84da4994abf979a8a967e168", "best_bid": "0.1", "best_ask": "0.11"}, {"asset_id": "7664065636701295840769263287437558246574946591549211748470097864098826204283", "price": "0.92", "size": "100", "side": "SELL", "hash": "04c0804e5d53e632a44499264a7ebab9debabdc8", "best_bid": "0.89", "best_ask": "0.9"}], "timestamp": "1769384021555", "event_type": "price_change"}}
{"_local_timestamp": "2026-01-25T23:33:41.727413+00:00", "data": {"market": "0x378f76341e555b6d54b89cc527afde5f8c293025cf6f48980145b94dc5726ce7", "price_changes": [{"asset_id": "100508935738063536113321312580877764668655616361107299342990907747250271040586", "price": "0.08", "size": "161", "side": "BUY", "hash": "98cf4c948bd08faaf489bdcf3aebc7ad74ea45b2", "best_bid": "0.1", "best_ask": "0.11"}, {"asset_id": "7664065636701295840769263287437558246574946591549211748470097864098826204283", "price": "0.92", "size": "161", "side": "SELL", "hash": "13c00b20d47bd3bd1fc997c01901c576e8aa7dcb", "best_bid": "0.89", "best_ask": "0.9"}], "timestamp": "1769384021649", "event_type": "price_change"}}
{"_local_timestamp": "2026-01-25T23:33:41.738470+00:00", "data": {"market": "0x6a3bc08c62413e6594164bc15aa07b282b22a6d7efc61cd69df92b63f4132289", "price_changes": [{"asset_id": "5598960237790161917534060866496363286228389060029699153094526893891604621525", "price": "0.912", "size": "50", "side": "BUY", "hash": "2c24f31df5dd1ec9519b820381955dcd5d05149f", "best_bid": "0.99", "best_ask": "0.991"}, {"asset_id": "99482729937705145912235477495415874028392807588978105657655512338616047660547", "price": "0.088", "size": "50", "side": "SELL", "hash": "1bcc3c9043e288ddbc07ff3aac7a5ae43a74f4e9", "best_bid": "0.009", "best_ask": "0.01"}], "timestamp": "1769384021665", "event_type": "price_change"}}
{"_local_timestamp": "2026-01-25T23:33:41.829498+00:00", "data": {"market": "0x32821c03c1a785af6bea72291b578e722f02f7da80e204c42be3dee38694756f", "price_changes": [{"asset_id": "11222612568007649347690827040340431718068607305340023819591655077557696898272", "price": "0.483", "size": "10", "side": "BUY", "hash": "0a4ad8d0b31690e9b13fc7283106d7f3f8f38d17", "best_bid": "0.969", "best_ask": "0.978"}, {"asset_id": "46526486688025872076957171866031437643304744954855308137561748620272587627152", "price": "0.517", "size": "10", "side": "SELL", "hash": "1c2d48442af0101427f58372a1b847fd20eaa343", "best_bid": "0.022", "best_ask": "0.031"}], "timestamp": "1769384021748", "event_type": "price_change"}}
{"_local_timestamp": "2026-01-25T23:33:41.830338+00:00", "data": {"market": "0x8d8b98fb4c290c4e152ce8b653c5598b74a630dd1dbb800a5f328ea9c8b00727", "price_changes": [{"asset_id": "78474559114932529051705203752686517828085200880957778785050112163927946260911", "price": "0.941", "size": "50", "side": "BUY", "hash": "ab3be77a2c799af3aa004df41aacd0e6ed982419", "best_bid": "0.941", "best_ask": "0.958"}, {"asset_id": "80938914484826983068438930343848557974856639667615266122989436725895029352478", "price": "0.059", "size": "50", "side": "SELL", "hash": "36a113f7596578052a6b19fa065b9b6b21027e61", "best_bid": "0.042", "best_ask": "0.059"}], "timestamp": "1769384021754", "event_type": "price_change"}}
{"_local_timestamp": "2026-01-25T23:33:41.853137+00:00", "data": {"market": "0x8d8b98fb4c290c4e152ce8b653c5598b74a630dd1dbb800a5f328ea9c8b00727", "price_changes": [{"asset_id": "80938914484826983068438930343848557974856639667615266122989436725895029352478", "price": "0.061", "size": "0", "side": "SELL", "hash": "597c46fc089e69d36c3cd02a9e93b4c9a3dd3868", "best_bid": "0.042", "best_ask": "0.059"}, {"asset_id": "78474559114932529051705203752686517828085200880957778785050112163927946260911", "price": "0.939", "size": "0", "side": "BUY", "hash": "359dd86a1f29fa6ec2944eac4e403be7c57f8d9f", "best_bid": "0.941", "best_ask": "0.958"}], "timestamp": "1769384021778", "event_type": "price_change"}}
{"_local_timestamp": "2026-01-25T23:33:41.874518+00:00", "data": {"market": "0x8d8b98fb4c290c4e152ce8b653c5598b74a630dd1dbb800a5f328ea9c8b00727", "price_changes": [{"asset_id": "80938914484826983068438930343848557974856639667615266122989436725895029352478", "price": "0.059", "size": "252", "side": "SELL", "hash": "e871dc5fb4937c69bff31cb7410c96c4ab88b258", "best_bid": "0.042", "best_ask": "0.059"}, {"asset_id": "78474559114932529051705203752686517828085200880957778785050112163927946260911", "price": "0.941", "size": "252", "side": "BUY", "hash": "c244cfa33fb07e03c63085cdf142d502c8b9809d", "best_bid": "0.941", "best_ask": "0.958"}], "timestamp": "1769384021805", "event_type": "price_change"}}
{"_local_timestamp": "2026-01-25T23:33:42.142911+00:00", "data": {"market": "0x8d8b98fb4c290c4e152ce8b653c5598b74a630dd1dbb800a5f328ea9c8b00727", "price_changes": [{"asset_id": "78474559114932529051705203752686517828085200880957778785050112163927946260911", "price": "0.936", "size": "10", "side": "BUY", "hash": "3cc22866a8a79224e1fb37af321777ec86d7339a", "best_bid": "0.941", "best_ask": "0.958"}, {"asset_id": "80938914484826983068438930343848557974856639667615266122989436725895029352478", "price": "0.064", "size": "10", "side": "SELL", "hash": "5577e1680d9fa5403805a6c1770b6c1760656522", "best_bid": "0.042", "best_ask": "0.059"}], "timestamp": "1769384022077", "event_type": "price_change"}}
{"_local_timestamp": "2026-01-25T23:33:42.390317+00:00", "data": {"market": "0x378f76341e555b6d54b89cc527afde5f8c293025cf6f48980145b94dc5726ce7", "price_changes": [{"asset_id": "7664065636701295840769263287437558246574946591549211748470097864098826204283", "price": "0.63", "size": "3000", "side": "BUY", "hash": "631f0eb650bea40c3d117a757d792662afac1a5d", "best_bid": "0.89", "best_ask": "0.9"}, {"asset_id": "100508935738063536113321312580877764668655616361107299342990907747250271040586", "price": "0.37", "size": "3000", "side": "SELL", "hash": "fa8f5a2e31790e71803691777261541d43eb0873", "best_bid": "0.1", "best_ask": "0.11"}], "timestamp": "1769384022323", "event_type": "price_change"}}
{"_local_timestamp": "2026-01-25T23:33:42.468774+00:00", "data": {"market": "0x8d8b98fb4c290c4e152ce8b653c5598b74a630dd1dbb800a5f328ea9c8b00727", "price_changes": [{"asset_id": "80938914484826983068438930343848557974856639667615266122989436725895029352478", "price": "0.06", "size": "37.14", "side": "SELL", "hash": "45cd40d810a01fcb7aff06ff45bb3bf9aec7dc1a", "best_bid": "0.042", "best_ask": "0.059"}, {"asset_id": "78474559114932529051705203752686517828085200880957778785050112163927946260911", "price": "0.94", "size": "37.14", "side": "BUY", "hash": "deb4358c5939c2fcf218f1c799a816ac749b3246", "best_bid": "0.941", "best_ask": "0.958"}], "timestamp": "1769384022403", "event_type": "price_change"}}
{"_local_timestamp": "2026-01-25T23:33:42.543514+00:00", "data": {"market": "0x8d8b98fb4c290c4e152ce8b653c5598b74a630dd1dbb800a5f328ea9c8b00727", "price_changes": [{"asset_id": "80938914484826983068438930343848557974856639667615266122989436725895029352478", "price": "0.058", "size": "30", "side": "SELL", "hash": "c133e880637dda85b38083b42bb9fab6853e31d7", "best_bid": "0.042", "best_ask": "0.058"}, {"asset_id": "78474559114932529051705203752686517828085200880957778785050112163927946260911", "price": "0.942", "size": "30", "side": "BUY", "hash": "56326b94fa5cff29c31c2139ebd4bc227812deec", "best_bid": "0.942", "best_ask": "0.958"}], "timestamp": "1769384022475", "event_type": "price_change"}}
{"_local_timestamp": "2026-01-25T23:33:42.789870+00:00", "data": {"market": "0x378f76341e555b6d54b89cc527afde5f8c293025cf6f48980145b94dc5726ce7", "price_changes": [{"asset_id": "100508935738063536113321312580877764668655616361107299342990907747250271040586", "price": "0.08", "size": "100", "side": "BUY", "hash": "2e5d32546c3ab12a382240c6a3e3dd4568f99b55", "best_bid": "0.1", "best_ask": "0.11"}, {"asset_id": "7664065636701295840769263287437558246574946591549211748470097864098826204283", "price": "0.92", "size": "100", "side": "SELL", "hash": "eab7090ee3efa37fb821a9941fc28a561a347b4b", "best_bid": "0.89", "best_ask": "0.9"}], "timestamp": "1769384022727", "event_type": "price_change"}}
{"_local_timestamp": "2026-01-25T23:33:42.817403+00:00", "data": {"market": "0x378f76341e555b6d54b89cc527afde5f8c293025cf6f48980145b94dc5726ce7", "price_changes": [{"asset_id": "100508935738063536113321312580877764668655616361107299342990907747250271040586", "price": "0.08", "size": "199", "side": "BUY", "hash": "e281a9a60f5999aaa5cae1f6d58d1846b635bde2", "best_bid": "0.1", "best_ask": "0.11"}, {"asset_id": "7664065636701295840769263287437558246574946591549211748470097864098826204283", "price": "0.92", "size": "199", "side": "SELL", "hash": "fb039080e892b5d609658db674ff7e873e2192b8", "best_bid": "0.89", "best_ask": "0.9"}], "timestamp": "1769384022754", "event_type": "price_change"}}
{"_local_timestamp": "2026-01-25T23:33:42.900218+00:00", "data": {"market": "0x6a3bc08c62413e6594164bc15aa07b282b22a6d7efc61cd69df92b63f4132289", "price_changes": [{"asset_id": "5598960237790161917534060866496363286228389060029699153094526893891604621525", "price": "0.912", "size": "25", "side": "BUY", "hash": "ed8205df1d6523f99cde9a6d8bd8ad1e014ab1f6", "best_bid": "0.99", "best_ask": "0.991"}, {"asset_id": "99482729937705145912235477495415874028392807588978105657655512338616047660547", "price": "0.088", "size": "25", "side": "SELL", "hash": "a3011e6e8066e2fc560d0c6c72be5f33bba1fae4", "best_bid": "0.009", "best_ask": "0.01"}], "timestamp": "1769384022827", "event_type": "price_change"}}
{"_local_timestamp": "2026-01-25T23:33:42.998893+00:00", "data": {"market": "0x6a3bc08c62413e6594164bc15aa07b282b22a6d7efc61cd69df92b63f4132289", "price_changes": [{"asset_id": "5598960237790161917534060866496363286228389060029699153094526893891604621525", "price": "0.912", "size": "50", "side": "BUY", "hash": "d07c84b569f828a3fdea7e5f658f09039fc42192", "best_bid": "0.99", "best_ask": "0.991"}, {"asset_id": "99482729937705145912235477495415874028392807588978105657655512338616047660547", "price": "0.088", "size": "50", "side": "SELL", "hash": "560ffb089392be8eb4b2ebb0d0af457244f06a56", "best_bid": "0.009", "best_ask": "0.01"}], "timestamp": "1769384022933", "event_type": "price_change"}}
{"_local_timestamp": "2026-01-25T23:33:43.052164+00:00", "data": {"market": "0x8d8b98fb4c290c4e152ce8b653c5598b74a630dd1dbb800a5f328ea9c8b00727", "price_changes": [{"asset_id": "80938914484826983068438930343848557974856639667615266122989436725895029352478", "price": "0.06", "size": "30", "side": "SELL", "hash": "46f7d4c6d19fa8e4419ef3c30b3c7ff4f9bdb433", "best_bid": "0.042", "best_ask": "0.058"}, {"asset_id": "78474559114932529051705203752686517828085200880957778785050112163927946260911", "price": "0.94", "size": "30", "side": "BUY", "hash": "c078a83d243ed93da162feda2bb1a07dbddd79f6", "best_bid": "0.942", "best_ask": "0.958"}], "timestamp": "1769384022985", "event_type": "price_change"}}
{"_local_timestamp": "2026-01-25T23:33:43.130146+00:00", "data": {"market": "0x8d8b98fb4c290c4e152ce8b653c5598b74a630dd1dbb800a5f328ea9c8b00727", "price_changes": [{"asset_id": "80938914484826983068438930343848557974856639667615266122989436725895029352478", "price": "0.059", "size": "50", "side": "SELL", "hash": "82b856c5d8a87fe46d1290abfc5eb0f3be93b6e7", "best_bid": "0.042", "best_ask": "0.058"}, {"asset_id": "78474559114932529051705203752686517828085200880957778785050112163927946260911", "price": "0.941", "size": "50", "side": "BUY", "hash": "4a5eec8f2655a009f7794393f4175326d9e552e5", "best_bid": "0.942", "best_ask": "0.958"}], "timestamp": "1769384023011", "event_type": "price_change"}}
{"_local_timestamp": "2026-01-25T23:33:43.131194+00:00", "data": {"market": "0x6a3bc08c62413e6594164bc15aa07b282b22a6d7efc61cd69df92b63f4132289", "price_changes": [{"asset_id": "5598960237790161917534060866496363286228389060029699153094526893891604621525", "price": "0.912", "size": "25", "side": "BUY", "hash": "84f5948f69c97aca31386a1e958fc19fc8cb4ae9", "best_bid": "0.99", "best_ask": "0.991"}, {"asset_id": "99482729937705145912235477495415874028392807588978105657655512338616047660547", "price": "0.088", "size": "25", "side": "SELL", "hash": "c6d06888f9aff65b9897ef75ecc091fb1db9b125", "best_bid": "0.009", "best_ask": "0.01"}], "timestamp": "1769384023034", "event_type": "price_change"}}
{"_local_timestamp": "2026-01-25T23:33:43.169905+00:00", "data": {"market": "0x8d8b98fb4c290c4e152ce8b653c5598b74a630dd1dbb800a5f328ea9c8b00727", "price_changes": [{"asset_id": "78474559114932529051705203752686517828085200880957778785050112163927946260911", "price": "0.94", "size": "0", "side": "BUY", "hash": "1dc6309121a836dbb3bccc4a4e968d5b22ddc329", "best_bid": "0.942", "best_ask": "0.958"}, {"asset_id": "80938914484826983068438930343848557974856639667615266122989436725895029352478", "price": "0.06", "size": "0", "side": "SELL", "hash": "96f2edaa38a9eefc331a4311166a15c482a229a2", "best_bid": "0.042", "best_ask": "0.058"}], "timestamp": "1769384023106", "event_type": "price_change"}}
{"_local_timestamp": "2026-01-25T23:33:43.241549+00:00", "data": {"market": "0x8d8b98fb4c290c4e152ce8b653c5598b74a630dd1dbb800a5f328ea9c8b00727", "price_changes": [{"asset_id": "78474559114932529051705203752686517828085200880957778785050112163927946260911", "price": "0.942", "size": "60", "side": "BUY", "hash": "cff6d42b8614bf2ffcc53d8bd05874e6b408929b", "best_bid": "0.942", "best_ask": "0.958"}, {"asset_id": "80938914484826983068438930343848557974856639667615266122989436725895029352478", "price": "0.058", "size": "60", "side": "SELL", "hash": "fee1627292a9beb7dd2d1f110fcf0b6bf3526734", "best_bid": "0.042", "best_ask": "0.058"}], "timestamp": "1769384023173", "event_type": "price_change"}}
{"_local_timestamp": "2026-01-25T23:33:43.854247+00:00", "data": {"market": "0x8d8b98fb4c290c4e152ce8b653c5598b74a630dd1dbb800a5f328ea9c8b00727", "price_changes": [{"asset_id": "80938914484826983068438930343848557974856639667615266122989436725895029352478", "price": "0.058", "size": "67.14", "side": "SELL", "hash": "20098e06600fbef6259ea602dcbf1b3ee97ac1e7", "best_bid": "0.042", "best_ask": "0.058"}, {"asset_id": "78474559114932529051705203752686517828085200880957778785050112163927946260911", "price": "0.942", "size": "67.14", "side": "BUY", "hash": "fef4373122388faadfa28286ac9d2f035c3e560b", "best_bid": "0.942", "best_ask": "0.958"}], "timestamp": "1769384023745", "event_type": "price_change"}}
{"_local_timestamp": "2026-01-25T23:33:43.987556+00:00", "data": {"market": "0x8d8b98fb4c290c4e152ce8b653c5598b74a630dd1dbb800a5f328ea9c8b00727", "price_changes": [{"asset_id": "78474559114932529051705203752686517828085200880957778785050112163927946260911", "price": "0.24", "size": "3116.66", "side": "BUY", "hash": "c026cc163e0c87e22d47295b865f67fa06275f79", "best_bid": "0.942", "best_ask": "0.958"}, {"asset_id": "80938914484826983068438930343848557974856639667615266122989436725895029352478", "price": "0.76", "size": "3116.66", "side": "SELL", "hash": "b52ae4039c90d412a2d38947b71934e6d16a10bb", "best_bid": "0.042", "best_ask": "0.058"}], "timestamp": "1769384023918", "event_type": "price_change"}}
{"_local_timestamp": "2026-01-25T23:33:44.134720+00:00", "data": {"market": "0x6a3bc08c62413e6594164bc15aa07b282b22a6d7efc61cd69df92b63f4132289", "price_changes": [{"asset_id": "5598960237790161917534060866496363286228389060029699153094526893891604621525", "price": "0.912", "size": "50", "side": "BUY", "hash": "210e1e6b95c7967a8168c0484cf9490768b1488a", "best_bid": "0.99", "best_ask": "0.991"}, {"asset_id": "99482729937705145912235477495415874028392807588978105657655512338616047660547", "price": "0.088", "size": "50", "side": "SELL", "hash": "afd6938b984d53bfb8db66536e23ad2bc6c60a90", "best_bid": "0.009", "best_ask": "0.01"}], "timestamp": "1769384024061", "event_type": "price_change"}}
{"_local_timestamp": "2026-01-25T23:33:44.244942+00:00", "data": {"market": "0x6a3bc08c62413e6594164bc15aa07b282b22a6d7efc61cd69df92b63f4132289", "price_changes": [{"asset_id": "5598960237790161917534060866496363286228389060029699153094526893891604621525", "price": "0.912", "size": "25", "side": "BUY", "hash": "6adc7eec2759643738e4d2544d251fa80c37a818", "best_bid": "0.99", "best_ask": "0.991"}, {"asset_id": "99482729937705145912235477495415874028392807588978105657655512338616047660547", "price": "0.088", "size": "25", "side": "SELL", "hash": "12c7450e7eb2099fb605ff83fadf3f6d76c6a706", "best_bid": "0.009", "best_ask": "0.01"}], "timestamp": "1769384024180", "event_type": "price_change"}}
{"_local_timestamp": "2026-01-25T23:33:44.461293+00:00", "data": {"market": "0x8d8b98fb4c290c4e152ce8b653c5598b74a630dd1dbb800a5f328ea9c8b00727", "price_changes": [{"asset_id": "80938914484826983068438930343848557974856639667615266122989436725895029352478", "price": "0.058", "size": "37.14", "side": "SELL", "hash": "12fd6735dcfa027094c5637ea95c9e95215d0f12", "best_bid": "0.042", "best_ask": "0.058"}, {"asset_id": "78474559114932529051705203752686517828085200880957778785050112163927946260911", "price": "0.942", "size": "37.14", "side": "BUY", "hash": "6aff04bf780235db0cea46db2f2814bf61718c1c", "best_bid": "0.942", "best_ask": "0.958"}], "timestamp": "1769384024394", "event_type": "price_change"}}
{"_local_timestamp": "2026-01-25T23:33:44.529960+00:00", "data": {"market": "0x8d8b98fb4c290c4e152ce8b653c5598b74a630dd1dbb800a5f328ea9c8b00727", "price_changes": [{"asset_id": "80938914484826983068438930343848557974856639667615266122989436725895029352478", "price": "0.065", "size": "35.38", "side": "SELL", "hash": "69a16396233812b5ac0e2e708b30aec8c24d9e93", "best_bid": "0.042", "best_ask": "0.058"}, {"asset_id": "78474559114932529051705203752686517828085200880957778785050112163927946260911", "price": "0.935", "size": "35.38", "side": "BUY", "hash": "bd306e89997dcfefec7bcb443c619072a819f1fa", "best_bid": "0.942", "best_ask": "0.958"}], "timestamp": "1769384024447", "event_type": "price_change"}}
{"_local_timestamp": "2026-01-25T23:33:45.353426+00:00", "data": {"market": "0x8d8b98fb4c290c4e152ce8b653c5598b74a630dd1dbb800a5f328ea9c8b00727", "price_changes": [{"asset_id": "78474559114932529051705203752686517828085200880957778785050112163927946260911", "price": "0.942", "size": "7.14", "side": "BUY", "hash": "195f0c0f83028c1bdecc3e5254deb1d5d292cb8d", "best_bid": "0.942", "best_ask": "0.958"}, {"asset_id": "80938914484826983068438930343848557974856639667615266122989436725895029352478", "price": "0.058", "size": "7.14", "side": "SELL", "hash": "8a392d871217e57a64bd6ba7abbb3a57ecdc3a7f", "best_bid": "0.042", "best_ask": "0.058"}], "timestamp": "1769384025277", "event_type": "price_change"}}
{"_local_timestamp": "2026-01-25T23:33:45.402830+00:00", "data": {"market": "0x8d8b98fb4c290c4e152ce8b653c5598b74a630dd1dbb800a5f328ea9c8b00727", "price_changes": [{"asset_id": "78474559114932529051705203752686517828085200880957778785050112163927946260911", "price": "0.934", "size": "85", "side": "BUY", "hash": "3b324bddb7ed47ffaeabf8960fe8d252d055ae16", "best_bid": "0.942", "best_ask": "0.958"}, {"asset_id": "80938914484826983068438930343848557974856639667615266122989436725895029352478", "price": "0.066", "size": "85", "side": "SELL", "hash": "688ad159f5e9fe107e091fc015d2ba946d0fb1a5", "best_bid": "0.042", "best_ask": "0.058"}], "timestamp": "1769384025332", "event_type": "price_change"}}
{"_local_timestamp": "2026-01-25T23:33:45.477024+00:00", "data": {"market": "0x6a3bc08c62413e6594164bc15aa07b282b22a6d7efc61cd69df92b63f4132289", "price_changes": [{"asset_id": "5598960237790161917534060866496363286228389060029699153094526893891604621525", "price": "0.912", "size": "50", "side": "BUY", "hash": "6c3e65f381f7f7ec60deb2322e972409c1407a75", "best_bid": "0.99", "best_ask": "0.991"}, {"asset_id": "99482729937705145912235477495415874028392807588978105657655512338616047660547", "price": "0.088", "size": "50", "side": "SELL", "hash": "a2f270d3c0ca14508f2241db902cfc00afa0982e", "best_bid": "0.009", "best_ask": "0.01"}], "timestamp": "1769384025413", "event_type": "price_change"}}
{"_local_timestamp": "2026-01-25T23:33:45.587137+00:00", "data": {"market": "0x6a3bc08c62413e6594164bc15aa07b282b22a6d7efc61cd69df92b63f4132289", "price_changes": [{"asset_id": "5598960237790161917534060866496363286228389060029699153094526893891604621525", "price": "0.912", "size": "25", "side": "BUY", "hash": "39816d9b9d6904ee687af2dd9324941cebc69491", "best_bid": "0.99", "best_ask": "0.991"}, {"asset_id": "99482729937705145912235477495415874028392807588978105657655512338616047660547", "price": "0.088", "size": "25", "side": "SELL", "hash": "13baaf3a51745b76bfc2ac8b4d3157e13b331a12", "best_bid": "0.009", "best_ask": "0.01"}], "timestamp": "1769384025519", "event_type": "price_change"}}
{"_local_timestamp": "2026-01-25T23:33:45.981130+00:00", "data": {"market": "0x32821c03c1a785af6bea72291b578e722f02f7da80e204c42be3dee38694756f", "price_changes": [{"asset_id": "11222612568007649347690827040340431718068607305340023819591655077557696898272", "price": "0.11", "size": "3000", "side": "BUY", "hash": "584b05b43a15f2785384ebea8ed3e615189e73cb", "best_bid": "0.969", "best_ask": "0.978"}, {"asset_id": "46526486688025872076957171866031437643304744954855308137561748620272587627152", "price": "0.89", "size": "3000", "side": "SELL", "hash": "515a5bcbfd15579c2325b68ac8bc6ecff95fe583", "best_bid": "0.022", "best_ask": "0.031"}], "timestamp": "1769384025915", "event_type": "price_change"}}
{"_local_timestamp": "2026-01-25T23:33:47.899325+00:00", "data": {"market": "0x8d8b98fb4c290c4e152ce8b653c5598b74a630dd1dbb800a5f328ea9c8b00727", "price_changes": [{"asset_id": "78474559114932529051705203752686517828085200880957778785050112163927946260911", "price": "0.936", "size": "60", "side": "BUY", "hash": "936a94dac4a3350fbf1db40a1ae573bb1254cde1", "best_bid": "0.942", "best_ask": "0.958"}, {"asset_id": "80938914484826983068438930343848557974856639667615266122989436725895029352478", "price": "0.064", "size": "60", "side": "SELL", "hash": "7f646a7a081d238d037bfbf3655e1c3c824b2ef2", "best_bid": "0.042", "best_ask": "0.058"}], "timestamp": "1769384027834", "event_type": "price_change"}}
{"_local_timestamp": "2026-01-25T23:33:47.945595+00:00", "data": {"market": "0xc512e0c0fa2d19ad6fe8bd885b3089a80fa2bf8382c104321c7359e7014cf567", "price_changes": [{"asset_id": "107858355690036086153439322350404767983557761088489336428558005982078386490488", "price": "0.23", "size": "170", "side": "BUY", "hash": "77aa00f29c587b25a94482124a58f6ddf4404225", "best_bid": "0.315", "best_ask": "0.349"}, {"asset_id": "83334600217205368371784439992248024883439507053390974906923524834233064415427", "price": "0.77", "size": "170", "side": "SELL", "hash": "1dc712f51daf11634b1cf7aec6eebc71f3bd7c1e", "best_bid": "0.651", "best_ask": "0.685"}], "timestamp": "1769384027880", "event_type": "price_change"}}
{"_local_timestamp": "2026-01-25T23:33:48.043032+00:00", "data": {"market": "0x6a3bc08c62413e6594164bc15aa07b282b22a6d7efc61cd69df92b63f4132289", "price_changes": [{"asset_id": "5598960237790161917534060866496363286228389060029699153094526893891604621525", "price": "0.912", "size": "50", "side": "BUY", "hash": "2320b2cbe70e3b970e28f4400579027e4a4fc13a", "best_bid": "0.99", "best_ask": "0.991"}, {"asset_id": "99482729937705145912235477495415874028392807588978105657655512338616047660547", "price": "0.088", "size": "50", "side": "SELL", "hash": "29870de08773612a73209ec6d1d1e6bc14c5d7a0", "best_bid": "0.009", "best_ask": "0.01"}], "timestamp": "1769384027942", "event_type": "price_change"}}
{"_local_timestamp": "2026-01-25T23:33:48.110056+00:00", "data": {"market": "0xc512e0c0fa2d19ad6fe8bd885b3089a80fa2bf8382c104321c7359e7014cf567", "price_changes": [{"asset_id": "107858355690036086153439322350404767983557761088489336428558005982078386490488", "price": "0.221", "size": "400", "side": "BUY", "hash": "166f503c929ee70eac33548e644f61e3e95d1820", "best_bid": "0.315", "best_ask": "0.349"}, {"asset_id": "83334600217205368371784439992248024883439507053390974906923524834233064415427", "price": "0.779", "size": "400", "side": "SELL", "hash": "23e9953e4f7485b0c8771f97d98d8e7d4ca03e06", "best_bid": "0.651", "best_ask": "0.685"}], "timestamp": "1769384028026", "event_type": "price_change"}}
{"_local_timestamp": "2026-01-25T23:33:48.130883+00:00", "data": {"market": "0x6a3bc08c62413e6594164bc15aa07b282b22a6d7efc61cd69df92b63f4132289", "price_changes": [{"asset_id": "5598960237790161917534060866496363286228389060029699153094526893891604621525", "price": "0.912", "size": "25", "side": "BUY", "hash": "d3f9a2c75036ebd4a0632f32f4e07d18c5405162", "best_bid": "0.99", "best_ask": "0.991"}, {"asset_id": "99482729937705145912235477495415874028392807588978105657655512338616047660547", "price": "0.088", "size": "25", "side": "SELL", "hash": "400b8198394b314f464e09efec4a593cf87d80d8", "best_bid": "0.009", "best_ask": "0.01"}], "timestamp": "1769384028057", "event_type": "price_change"}}
{"_local_timestamp": "2026-01-25T23:33:48.225631+00:00", "data": {"market": "0x8d8b98fb4c290c4e152ce8b653c5598b74a630dd1dbb800a5f328ea9c8b00727", "price_changes": [{"asset_id": "78474559114932529051705203752686517828085200880957778785050112163927946260911", "price": "0.941", "size": "0", "side": "BUY", "hash": "776ca977837722ca7146a74e6fbcdf8200970965", "best_bid": "0.942", "best_ask": "0.958"}, {"asset_id": "80938914484826983068438930343848557974856639667615266122989436725895029352478", "price": "0.059", "size": "0", "side": "SELL", "hash": "bf5ac07cd9f3ab296014d2051387eba7cd27bee7", "best_bid": "0.042", "best_ask": "0.058"}], "timestamp": "1769384028157", "event_type": "price_change"}}
{"_local_timestamp": "2026-01-25T23:33:48.415664+00:00", "data": {"market": "0x8d8b98fb4c290c4e152ce8b653c5598b74a630dd1dbb800a5f328ea9c8b00727", "price_changes": [{"asset_id": "80938914484826983068438930343848557974856639667615266122989436725895029352478", "price": "0.01", "size": "0", "side": "BUY", "hash": "e96d17506ea46f1c726d4ba16c4ead1903c8ccc2", "best_bid": "0.042", "best_ask": "0.058"}, {"asset_id": "78474559114932529051705203752686517828085200880957778785050112163927946260911", "price": "0.99", "size": "0", "side": "SELL", "hash": "48959fe60916afe2b97aecf14db061e5fa39d962", "best_bid": "0.942", "best_ask": "0.958"}], "timestamp": "1769384028352", "event_type": "price_change"}}
{"_local_timestamp": "2026-01-25T23:33:48.421510+00:00", "data": {"market": "0x8d8b98fb4c290c4e152ce8b653c5598b74a630dd1dbb800a5f328ea9c8b00727", "price_changes": [{"asset_id": "80938914484826983068438930343848557974856639667615266122989436725895029352478", "price": "0.065", "size": "5.38", "side": "SELL", "hash": "6c1ef8965ae07dda72ac80c663b5ed9dbf17c1b5", "best_bid": "0.042", "best_ask": "0.058"}, {"asset_id": "78474559114932529051705203752686517828085200880957778785050112163927946260911", "price": "0.935", "size": "5.38", "side": "BUY", "hash": "599704e91589575917cf45b409e38f49df6395d6", "best_bid": "0.942", "best_ask": "0.958"}], "timestamp": "1769384028355", "event_type": "price_change"}}
{"_local_timestamp": "2026-01-25T23:33:48.436421+00:00", "data": {"market": "0x8d8b98fb4c290c4e152ce8b653c5598b74a630dd1dbb800a5f328ea9c8b00727", "price_changes": [{"asset_id": "80938914484826983068438930343848557974856639667615266122989436725895029352478", "price": "0.01", "size": "500", "side": "BUY", "hash": "f74b93caf18156d6282207b8527a86b64ab360c2", "best_bid": "0.042", "best_ask": "0.058"}, {"asset_id": "78474559114932529051705203752686517828085200880957778785050112163927946260911", "price": "0.99", "size": "500", "side": "SELL", "hash": "09843d4f972b9d722f9052de835d89f0c37c1927", "best_bid": "0.942", "best_ask": "0.958"}], "timestamp": "1769384028365", "event_type": "price_change"}}
{"_local_timestamp": "2026-01-25T23:33:48.438111+00:00", "data": {"market": "0x8d8b98fb4c290c4e152ce8b653c5598b74a630dd1dbb800a5f328ea9c8b00727", "price_changes": [{"asset_id": "80938914484826983068438930343848557974856639667615266122989436725895029352478", "price": "0.02", "size": "555", "side": "BUY", "hash": "bd90296fe28788d5a83dc83de363e64402b780dd", "best_bid": "0.042", "best_ask": "0.058"}, {"asset_id": "78474559114932529051705203752686517828085200880957778785050112163927946260911", "price": "0.98", "size": "555", "side": "SELL", "hash": "023091d855c211ebdf2fa7e071bdbe55e594fea1", "best_bid": "0.942", "best_ask": "0.958"}], "timestamp": "1769384028365", "event_type": "price_change"}}
{"_local_timestamp": "2026-01-25T23:33:48.522483+00:00", "data": {"market": "0x8d8b98fb4c290c4e152ce8b653c5598b74a630dd1dbb800a5f328ea9c8b00727", "price_changes": [{"asset_id": "80938914484826983068438930343848557974856639667615266122989436725895029352478", "price": "0.063", "size": "30", "side": "SELL", "hash": "5f0f4244cc178917b4eeeddabc9ce36dbd4a513e", "best_bid": "0.042", "best_ask": "0.058"}, {"asset_id": "78474559114932529051705203752686517828085200880957778785050112163927946260911", "price": "0.937", "size": "30", "side": "BUY", "hash": "4f918f9d287e8b9f5311f3605b163e0ef161d895", "best_bid": "0.942", "best_ask": "0.958"}], "timestamp": "1769384028440", "event_type": "price_change"}}
{"_local_timestamp": "2026-01-25T23:33:48.788927+00:00", "data": {"market": "0x8d8b98fb4c290c4e152ce8b653c5598b74a630dd1dbb800a5f328ea9c8b00727", "price_changes": [{"asset_id": "78474559114932529051705203752686517828085200880957778785050112163927946260911", "price": "0.24", "size": "116.66", "side": "BUY", "hash": "39c60ff1ef4b25a8d8519040b05f55f513bce794", "best_bid": "0.942", "best_ask": "0.958"}, {"asset_id": "80938914484826983068438930343848557974856639667615266122989436725895029352478", "price": "0.76", "size": "116.66", "side": "SELL", "hash": "923c455705d227c594fefb65005c0834ba6fad40", "best_bid": "0.042", "best_ask": "0.058"}], "timestamp": "1769384028725", "event_type": "price_change"}}
{"_local_timestamp": "2026-01-25T23:33:49.162361+00:00", "data": {"market": "0x8d8b98fb4c290c4e152ce8b653c5598b74a630dd1dbb800a5f328ea9c8b00727", "price_changes": [{"asset_id": "78474559114932529051705203752686517828085200880957778785050112163927946260911", "price": "0.934", "size": "55", "side": "BUY", "hash": "2d2cb1ba31c3cdde5605a0174344f15e5d324eea", "best_bid": "0.942", "best_ask": "0.958"}, {"asset_id": "80938914484826983068438930343848557974856639667615266122989436725895029352478", "price": "0.066", "size": "55", "side": "SELL", "hash": "29226dc29fb45b303bc4f07220ac37407174bf4e", "best_bid": "0.042", "best_ask": "0.058"}], "timestamp": "1769384029088", "event_type": "price_change"}}
{"_local_timestamp": "2026-01-25T23:33:49.241330+00:00", "data": {"market": "0x8d8b98fb4c290c4e152ce8b653c5598b74a630dd1dbb800a5f328ea9c8b00727", "price_changes": [{"asset_id": "78474559114932529051705203752686517828085200880957778785050112163927946260911", "price": "0.936", "size": "90", "side": "BUY", "hash": "528390d4797c91b7e332914ba56a44de995816be", "best_bid": "0.942", "best_ask": "0.958"}, {"asset_id": "80938914484826983068438930343848557974856639667615266122989436725895029352478", "price": "0.064", "size": "90", "side": "SELL", "hash": "e151435d855dadce069ee394a9b8f79114e57686", "best_bid": "0.042", "best_ask": "0.058"}], "timestamp": "1769384029173", "event_type": "price_change"}}
{"_local_timestamp": "2026-01-25T23:33:49.277930+00:00", "data": {"market": "0x6a3bc08c62413e6594164bc15aa07b282b22a6d7efc61cd69df92b63f4132289", "price_changes": [{"asset_id": "5598960237790161917534060866496363286228389060029699153094526893891604621525", "price": "0.912", "size": "50", "side": "BUY", "hash": "9813c0e264986f62a317b70cbd747f5a0d15390d", "best_bid": "0.99", "best_ask": "0.991"}, {"asset_id": "99482729937705145912235477495415874028392807588978105657655512338616047660547", "price": "0.088", "size": "50", "side": "SELL", "hash": "1c6d4f18cc6a2381456a11b6b0a7e93c2c62227e", "best_bid": "0.009", "best_ask": "0.01"}], "timestamp": "1769384029209", "event_type": "price_change"}}
{"_local_timestamp": "2026-01-25T23:33:49.401565+00:00", "data": {"market": "0x6a3bc08c62413e6594164bc15aa07b282b22a6d7efc61cd69df92b63f4132289", "price_changes": [{"asset_id": "5598960237790161917534060866496363286228389060029699153094526893891604621525", "price": "0.912", "size": "25", "side": "BUY", "hash": "d9211454ca10e0e2c527448b4744d0822ccc7a6f", "best_bid": "0.99", "best_ask": "0.991"}, {"asset_id": "99482729937705145912235477495415874028392807588978105657655512338616047660547", "price": "0.088", "size": "25", "side": "SELL", "hash": "6d0902fde60940a12bd8d31d2d519eb602be8474", "best_bid": "0.009", "best_ask": "0.01"}], "timestamp": "1769384029338", "event_type": "price_change"}}
{"_local_timestamp": "2026-01-25T23:33:49.825894+00:00", "data": {"market": "0x8d8b98fb4c290c4e152ce8b653c5598b74a630dd1dbb800a5f328ea9c8b00727", "price_changes": [{"asset_id": "80938914484826983068438930343848557974856639667615266122989436725895029352478", "price": "0.058", "size": "0", "side": "SELL", "hash": "d10e5d0263ce95797916330d6c21d46aea401a20", "best_bid": "0.042", "best_ask": "0.062"}, {"asset_id": "78474559114932529051705203752686517828085200880957778785050112163927946260911", "price": "0.942", "size": "0", "side": "BUY", "hash": "2b9389f69d2c022ad068c2c2f7de79602091847a", "best_bid": "0.938", "best_ask": "0.958"}], "timestamp": "1769384029740", "event_type": "price_change"}}
{"_local_timestamp": "2026-01-25T23:33:49.856133+00:00", "data": {"market": "0x8d8b98fb4c290c4e152ce8b653c5598b74a630dd1dbb800a5f328ea9c8b00727", "price_changes": [{"asset_id": "80938914484826983068438930343848557974856639667615266122989436725895029352478", "price": "0.062", "size": "195", "side": "SELL", "hash": "9b1d8b5ebab6518bb6ea279c6741e9c01471c9d0", "best_bid": "0.042", "best_ask": "0.062"}, {"asset_id": "78474559114932529051705203752686517828085200880957778785050112163927946260911", "price": "0.938", "size": "195", "side": "BUY", "hash": "fea5c6720b295a9d4a3b714549417e472003cced", "best_bid": "0.938", "best_ask": "0.958"}], "timestamp": "1769384029778", "event_type": "price_change"}}
{"_local_timestamp": "2026-01-25T23:33:49.856984+00:00", "data": {"market": "0x8d8b98fb4c290c4e152ce8b653c5598b74a630dd1dbb800a5f328ea9c8b00727", "price_changes": [{"asset_id": "80938914484826983068438930343848557974856639667615266122989436725895029352478", "price": "0.038", "size": "56", "side": "BUY", "hash": "df29b0e3ee24e24d28b8c7b6f8b20a843f0c902d", "best_bid": "0.042", "best_ask": "0.062"}, {"asset_id": "78474559114932529051705203752686517828085200880957778785050112163927946260911", "price": "0.962", "size": "56", "side": "SELL", "hash": "c35de56a7a1d868bf5df80b90762a70535d30c7c", "best_bid": "0.938", "best_ask": "0.958"}], "timestamp": "1769384029780", "event_type": "price_change"}}
{"_local_timestamp": "2026-01-25T23:33:50.262242+00:00", "data": {"market": "0x8d8b98fb4c290c4e152ce8b653c5598b74a630dd1dbb800a5f328ea9c8b00727", "price_changes": [{"asset_id": "80938914484826983068438930343848557974856639667615266122989436725895029352478", "price": "0.063", "size": "0", "side": "SELL", "hash": "55945f028e110ea1b596c3a235eac27c363b95e4", "best_bid": "0.042", "best_ask": "0.062"}, {"asset_id": "78474559114932529051705203752686517828085200880957778785050112163927946260911", "price": "0.937", "size": "0", "side": "BUY", "hash": "cc9eda37d801e33b3fa0f73a3082521347b7f2d0", "best_bid": "0.938", "best_ask": "0.958"}], "timestamp": "1769384030197", "event_type": "price_change"}}
{"_local_timestamp": "2026-01-25T23:33:50.324716+00:00", "data": {"market": "0x8d8b98fb4c290c4e152ce8b653c5598b74a630dd1dbb800a5f328ea9c8b00727", "price_changes": [{"asset_id": "80938914484826983068438930343848557974856639667615266122989436725895029352478", "price": "0.061", "size": "30", "side": "SELL", "hash": "eb8255301e31c11ebcf8cb4bc1cde6039d5216d3", "best_bid": "0.042", "best_ask": "0.061"}, {"asset_id": "78474559114932529051705203752686517828085200880957778785050112163927946260911", "price": "0.939", "size": "30", "side": "BUY", "hash": "a60d2740337289d283260b3ba7c63b7ba227acda", "best_bid": "0.939", "best_ask": "0.958"}], "timestamp": "1769384030249", "event_type": "price_change"}}
{"_local_timestamp": "2026-01-25T23:33:50.375722+00:00", "data": {"market": "0x6a3bc08c62413e6594164bc15aa07b282b22a6d7efc61cd69df92b63f4132289", "price_changes": [{"asset_id": "5598960237790161917534060866496363286228389060029699153094526893891604621525", "price": "0.912", "size": "50", "side": "BUY", "hash": "b1655645dae845c59997969280d4a6b347597082", "best_bid": "0.99", "best_ask": "0.991"}, {"asset_id": "99482729937705145912235477495415874028392807588978105657655512338616047660547", "price": "0.088", "size": "50", "side": "SELL", "hash": "c9c6a28b6578a699bc8ffb8281e1d312320d0674", "best_bid": "0.009", "best_ask": "0.01"}], "timestamp": "1769384030309", "event_type": "price_change"}}
{"_local_timestamp": "2026-01-25T23:33:50.479238+00:00", "data": {"market": "0x6a3bc08c62413e6594164bc15aa07b282b22a6d7efc61cd69df92b63f4132289", "price_changes": [{"asset_id": "5598960237790161917534060866496363286228389060029699153094526893891604621525", "price": "0.912", "size": "25", "side": "BUY", "hash": "fd344fedf566362e6b47399b30bfbb8d6f8aeb38", "best_bid": "0.99", "best_ask": "0.991"}, {"asset_id": "99482729937705145912235477495415874028392807588978105657655512338616047660547", "price": "0.088", "size": "25", "side": "SELL", "hash": "787709de5a3e0950a1f9bf3f6df26830e77d2d67", "best_bid": "0.009", "best_ask": "0.01"}], "timestamp": "1769384030416", "event_type": "price_change"}}
{"_local_timestamp": "2026-01-25T23:33:50.529143+00:00", "data": {"market": "0x8d8b98fb4c290c4e152ce8b653c5598b74a630dd1dbb800a5f328ea9c8b00727", "price_changes": [{"asset_id": "80938914484826983068438930343848557974856639667615266122989436725895029352478", "price": "0.061", "size": "37.14", "side": "SELL", "hash": "91f3583c2561ce9f1cd3707c08c1be26e226546e", "best_bid": "0.042", "best_ask": "0.061"}, {"asset_id": "78474559114932529051705203752686517828085200880957778785050112163927946260911", "price": "0.939", "size": "37.14", "side": "BUY", "hash": "72d977f494c2218ee1470b87ce1597d5eb0562d3", "best_bid": "0.939", "best_ask": "0.958"}], "timestamp": "1769384030464", "event_type": "price_change"}}
{"_local_timestamp": "2026-01-25T23:33:51.098428+00:00", "data": {"market": "0x8d8b98fb4c290c4e152ce8b653c5598b74a630dd1dbb800a5f328ea9c8b00727", "price_changes": [{"asset_id": "80938914484826983068438930343848557974856639667615266122989436725895029352478", "price": "0.062", "size": "10", "side": "SELL", "hash": "19a90cdcdfd6ee4e0039c2f1f41bf955b866374f", "best_bid": "0.042", "best_ask": "0.061"}, {"asset_id": "78474559114932529051705203752686517828085200880957778785050112163927946260911", "price": "0.938", "size": "10", "side": "BUY", "hash": "6edb56b93a463f06ed51261ca173c881f09c10fd", "best_bid": "0.939", "best_ask": "0.958"}], "timestamp": "1769384031023", "event_type": "price_change"}}
{"_local_timestamp": "2026-01-25T23:33:51.118534+00:00", "data": {"market": "0x8d8b98fb4c290c4e152ce8b653c5598b74a630dd1dbb800a5f328ea9c8b00727", "price_changes": [{"asset_id": "80938914484826983068438930343848557974856639667615266122989436725895029352478", "price": "0.06", "size": "210", "side": "SELL", "hash": "165858b42366bc76802693095dbef5b502a70fe4", "best_bid": "0.042", "best_ask": "0.06"}, {"asset_id": "78474559114932529051705203752686517828085200880957778785050112163927946260911", "price": "0.94", "size": "210", "side": "BUY", "hash": "214de2eec96ce8faed80dbcaff503906d502bc32", "best_bid": "0.94", "best_ask": "0.958"}], "timestamp": "1769384031052", "event_type": "price_change"}}
{"_local_timestamp": "2026-01-25T23:33:51.125197+00:00", "data": {"market": "0x8d8b98fb4c290c4e152ce8b653c5598b74a630dd1dbb800a5f328ea9c8b00727", "price_changes": [{"asset_id": "80938914484826983068438930343848557974856639667615266122989436725895029352478", "price": "0.038", "size": "26", "side": "BUY", "hash": "d78426f7b95d6d120b857d44d3a9c5af97e189e8", "best_bid": "0.042", "best_ask": "0.06"}, {"asset_id": "78474559114932529051705203752686517828085200880957778785050112163927946260911", "price": "0.962", "size": "26", "side": "SELL", "hash": "82565c85e28e67ab26822f59591101724069aacd", "best_bid": "0.94", "best_ask": "0.958"}], "timestamp": "1769384031057", "event_type": "price_change"}}
{"_local_timestamp": "2026-01-25T23:33:51.162988+00:00", "data": {"market": "0x8d8b98fb4c290c4e152ce8b653c5598b74a630dd1dbb800a5f328ea9c8b00727", "price_changes": [{"asset_id": "80938914484826983068438930343848557974856639667615266122989436725895029352478", "price": "0.038", "size": "64", "side": "BUY", "hash": "11496851b92d662957c3afd2bbc3752b6ec1c820", "best_bid": "0.042", "best_ask": "0.06"}, {"asset_id": "78474559114932529051705203752686517828085200880957778785050112163927946260911", "price": "0.962", "size": "64", "side": "SELL", "hash": "e23260f72c4fd19b5825d9124f3856bcb486e963", "best_bid": "0.94", "best_ask": "0.958"}], "timestamp": "1769384031090", "event_type": "price_change"}}
{"_local_timestamp": "2026-01-25T23:33:51.505941+00:00", "data": {"market": "0x8d8b98fb4c290c4e152ce8b653c5598b74a630dd1dbb800a5f328ea9c8b00727", "price_changes": [{"asset_id": "80938914484826983068438930343848557974856639667615266122989436725895029352478", "price": "0.02", "size": "55", "side": "BUY", "hash": "ec222682315678eb87c09ef8837847753ce6d7f8", "best_bid": "0.042", "best_ask": "0.06"}, {"asset_id": "78474559114932529051705203752686517828085200880957778785050112163927946260911", "price": "0.98", "size": "55", "side": "SELL", "hash": "e1ddef5958a257c186cc019a74f9e53e1e16968b", "best_bid": "0.94", "best_ask": "0.958"}], "timestamp": "1769384031437", "event_type": "price_change"}}
{"_local_timestamp": "2026-01-25T23:33:51.508887+00:00", "data": {"market": "0x8d8b98fb4c290c4e152ce8b653c5598b74a630dd1dbb800a5f328ea9c8b00727", "price_changes": [{"asset_id": "80938914484826983068438930343848557974856639667615266122989436725895029352478", "price": "0.01", "size": "2000", "side": "BUY", "hash": "0c0af1046f4ae533267fe14683839f4b713c9799", "best_bid": "0.042", "best_ask": "0.06"}, {"asset_id": "78474559114932529051705203752686517828085200880957778785050112163927946260911", "price": "0.99", "size": "2000", "side": "SELL", "hash": "006e995aefadf3467a283c8b00889961417755b6", "best_bid": "0.94", "best_ask": "0.958"}], "timestamp": "1769384031441", "event_type": "price_change"}}
{"_local_timestamp": "2026-01-25T23:33:51.513270+00:00", "data": {"market": "0x8d8b98fb4c290c4e152ce8b653c5598b74a630dd1dbb800a5f328ea9c8b00727", "price_changes": [{"asset_id": "78474559114932529051705203752686517828085200880957778785050112163927946260911", "price": "0.936", "size": "60", "side": "BUY", "hash": "16ca5eddf8b94b250e4e8c1fdbedad97313c9f07", "best_bid": "0.94", "best_ask": "0.958"}, {"asset_id": "80938914484826983068438930343848557974856639667615266122989436725895029352478", "price": "0.064", "size": "60", "side": "SELL", "hash": "638f9295a3e69c5e36a655bd37ed6b4b79ae699d", "best_bid": "0.042", "best_ask": "0.06"}], "timestamp": "1769384031447", "event_type": "price_change"}}
{"_local_timestamp": "2026-01-25T23:33:51.577799+00:00", "data": {"market": "0x8d8b98fb4c290c4e152ce8b653c5598b74a630dd1dbb800a5f328ea9c8b00727", "price_changes": [{"asset_id": "78474559114932529051705203752686517828085200880957778785050112163927946260911", "price": "0.938", "size": "40", "side": "BUY", "hash": "d8067421c29e52904cecc4ee234e6b2887138c81", "best_bid": "0.94", "best_ask": "0.958"}, {"asset_id": "80938914484826983068438930343848557974856639667615266122989436725895029352478", "price": "0.062", "size": "40", "side": "SELL", "hash": "44a36c169398a0f09683b728e2c95b7e3bf38117", "best_bid": "0.042", "best_ask": "0.06"}], "timestamp": "1769384031511", "event_type": "price_change"}}
{"_local_timestamp": "2026-01-25T23:33:51.665167+00:00", "data": {"market": "0x6a3bc08c62413e6594164bc15aa07b282b22a6d7efc61cd69df92b63f4132289", "price_changes": [{"asset_id": "5598960237790161917534060866496363286228389060029699153094526893891604621525", "price": "0.912", "size": "50", "side": "BUY", "hash": "97e72d786c5d18a220d4decb62f5c8387aa8c4ed", "best_bid": "0.99", "best_ask": "0.991"}, {"asset_id": "99482729937705145912235477495415874028392807588978105657655512338616047660547", "price": "0.088", "size": "50", "side": "SELL", "hash": "1a58440824514a99d5337670eeaf97fa736db037", "best_bid": "0.009", "best_ask": "0.01"}], "timestamp": "1769384031569", "event_type": "price_change"}}
{"_local_timestamp": "2026-01-25T23:33:51.743041+00:00", "data": {"market": "0x6a3bc08c62413e6594164bc15aa07b282b22a6d7efc61cd69df92b63f4132289", "price_changes": [{"asset_id": "5598960237790161917534060866496363286228389060029699153094526893891604621525", "price": "0.912", "size": "25", "side": "BUY", "hash": "7c110034cfb5905cd57cdc73bfe599bd6513d99f", "best_bid": "0.99", "best_ask": "0.991"}, {"asset_id": "99482729937705145912235477495415874028392807588978105657655512338616047660547", "price": "0.088", "size": "25", "side": "SELL", "hash": "2bf7ec49362f6d6195abd3c6b61cdb228d74422c", "best_bid": "0.009", "best_ask": "0.01"}], "timestamp": "1769384031678", "event_type": "price_change"}}
{"_local_timestamp": "2026-01-25T23:33:52.584971+00:00", "data": {"market": "0x8d8b98fb4c290c4e152ce8b653c5598b74a630dd1dbb800a5f328ea9c8b00727", "price_changes": [{"asset_id": "80938914484826983068438930343848557974856639667615266122989436725895029352478", "price": "0.038", "size": "26", "side": "BUY", "hash": "c02b2a3a0e325f8d74d2e5cb7ee25e3488a1c1f2", "best_bid": "0.042", "best_ask": "0.06"}, {"asset_id": "78474559114932529051705203752686517828085200880957778785050112163927946260911", "price": "0.962", "size": "26", "side": "SELL", "hash": "0d586c9d7dc4233c406e975b4fc0560dde943084", "best_bid": "0.94", "best_ask": "0.958"}], "timestamp": "1769384032521", "event_type": "price_change"}}
{"_local_timestamp": "2026-01-25T23:33:52.632512+00:00", "data": {"market": "0x8d8b98fb4c290c4e152ce8b653c5598b74a630dd1dbb800a5f328ea9c8b00727", "price_changes": [{"asset_id": "80938914484826983068438930343848557974856639667615266122989436725895029352478", "price": "0.037", "size": "113", "side": "BUY", "hash": "c3473312572e5b926802c2838faee096c5dfb4cb", "best_bid": "0.042", "best_ask": "0.06"}, {"asset_id": "78474559114932529051705203752686517828085200880957778785050112163927946260911", "price": "0.963", "size": "113", "side": "SELL", "hash": "b063029c07d0529857ec42b884983bdb8374739c", "best_bid": "0.94", "best_ask": "0.958"}], "timestamp": "1769384032548", "event_type": "price_change"}}
{"_local_timestamp": "2026-01-25T23:33:52.717129+00:00", "data": {"market": "0x6a3bc08c62413e6594164bc15aa07b282b22a6d7efc61cd69df92b63f4132289", "price_changes": [{"asset_id": "5598960237790161917534060866496363286228389060029699153094526893891604621525", "price": "0.912", "size": "50", "side": "BUY", "hash": "1160f1f2f21c71dbce62bd53c0665ee2303980ed", "best_bid": "0.99", "best_ask": "0.991"}, {"asset_id": "99482729937705145912235477495415874028392807588978105657655512338616047660547", "price": "0.088", "size": "50", "side": "SELL", "hash": "2a7f3c8b1c66a13d1f74c4eac386a7dff531b635", "best_bid": "0.009", "best_ask": "0.01"}], "timestamp": "1769384032649", "event_type": "price_change"}}
{"_local_timestamp": "2026-01-25T23:33:52.826650+00:00", "data": {"market": "0x6a3bc08c62413e6594164bc15aa07b282b22a6d7efc61cd69df92b63f4132289", "price_changes": [{"asset_id": "5598960237790161917534060866496363286228389060029699153094526893891604621525", "price": "0.912", "size": "25", "side": "BUY", "hash": "d88d0489b5f56939178d67471cf6ee119cf3ca88", "best_bid": "0.99", "best_ask": "0.991"}, {"asset_id": "99482729937705145912235477495415874028392807588978105657655512338616047660547", "price": "0.088", "size": "25", "side": "SELL", "hash": "f68653a01e6df63c8a9d48672f79dcb7472009e3", "best_bid": "0.009", "best_ask": "0.01"}], "timestamp": "1769384032760", "event_type": "price_change"}}
{"_local_timestamp": "2026-01-25T23:33:52.989278+00:00", "data": {"market": "0x8d8b98fb4c290c4e152ce8b653c5598b74a630dd1dbb800a5f328ea9c8b00727", "price_changes": [{"asset_id": "80938914484826983068438930343848557974856639667615266122989436725895029352478", "price": "0.061", "size": "30", "side": "SELL", "hash": "25b3fec8b0ae878b84a198771ab3b74fbd62988d", "best_bid": "0.042", "best_ask": "0.06"}, {"asset_id": "78474559114932529051705203752686517828085200880957778785050112163927946260911", "price": "0.939", "size": "30", "side": "BUY", "hash": "6f7a4c5c8f99e3b0d317ab249965e804ffb1acde", "best_bid": "0.94", "best_ask": "0.958"}], "timestamp": "1769384032907", "event_type": "price_change"}}
{"_local_timestamp": "2026-01-25T23:33:53.401352+00:00", "data": {"market": "0x8d8b98fb4c290c4e152ce8b653c5598b74a630dd1dbb800a5f328ea9c8b00727", "price_changes": [{"asset_id": "80938914484826983068438930343848557974856639667615266122989436725895029352478", "price": "0.061", "size": "0", "side": "SELL", "hash": "c0ff6efeb257fd2f8a8b6ab259909e2c1059be14", "best_bid": "0.042", "best_ask": "0.06"}, {"asset_id": "78474559114932529051705203752686517828085200880957778785050112163927946260911", "price": "0.939", "size": "0", "side": "BUY", "hash": "58bf9903cd422f8b6b70e60b6ab205cb271a3fc4", "best_bid": "0.94", "best_ask": "0.958"}], "timestamp": "1769384033336", "event_type": "price_change"}}
{"_local_timestamp": "2026-01-25T23:33:53.478977+00:00", "data": {"market": "0x8d8b98fb4c290c4e152ce8b653c5598b74a630dd1dbb800a5f328ea9c8b00727", "price_changes": [{"asset_id": "80938914484826983068438930343848557974856639667615266122989436725895029352478", "price": "0.059", "size": "30", "side": "SELL", "hash": "37efd31158f195536b3124a0158bf03e8e544fa9", "best_bid": "0.042", "best_ask": "0.059"}, {"asset_id": "78474559114932529051705203752686517828085200880957778785050112163927946260911", "price": "0.941", "size": "30", "side": "BUY", "hash": "30d3896b1c70cbbac89aa6e45fbcebb755a9bfb9", "best_bid": "0.941", "best_ask": "0.958"}], "timestamp": "1769384033407", "event_type": "price_change"}}
{"_local_timestamp": "2026-01-25T23:33:53.657153+00:00", "data": {"market": "0x8d8b98fb4c290c4e152ce8b653c5598b74a630dd1dbb800a5f328ea9c8b00727", "price_changes": [{"asset_id": "80938914484826983068438930343848557974856639667615266122989436725895029352478", "price": "0.059", "size": "37.14", "side": "SELL", "hash": "a9942c90646a2101ae457607d489c365d05dd7de", "best_bid": "0.042", "best_ask": "0.059"}, {"asset_id": "78474559114932529051705203752686517828085200880957778785050112163927946260911", "price": "0.941", "size": "37.14", "side": "BUY", "hash": "4e934f0f7370a0df9f54cf6479829def0b32e71d", "best_bid": "0.941", "best_ask": "0.958"}], "timestamp": "1769384033596", "event_type": "price_change"}}
{"_local_timestamp": "2026-01-25T23:33:53.685423+00:00", "data": {"market": "0x8d8b98fb4c290c4e152ce8b653c5598b74a630dd1dbb800a5f328ea9c8b00727", "price_changes": [{"asset_id": "80938914484826983068438930343848557974856639667615266122989436725895029352478", "price": "0.037", "size": "100", "side": "BUY", "hash": "2649cb3e5bfd6a24c38e363ba19a257a0684e031", "best_bid": "0.042", "best_ask": "0.059"}, {"asset_id": "78474559114932529051705203752686517828085200880957778785050112163927946260911", "price": "0.963", "size": "100", "side": "SELL", "hash": "6ac0dcba8003be2e0ce08de9ef56e8f97405b41a", "best_bid": "0.941", "best_ask": "0.958"}], "timestamp": "1769384033620", "event_type": "price_change"}}
{"_local_timestamp": "2026-01-25T23:33:53.770265+00:00", "data": {"market": "0x6a3bc08c62413e6594164bc15aa07b282b22a6d7efc61cd69df92b63f4132289", "price_changes": [{"asset_id": "5598960237790161917534060866496363286228389060029699153094526893891604621525", "price": "0.912", "size": "50", "side": "BUY", "hash": "f35204f5bfcb223614c86deb0b1cf0e1a237697f", "best_bid": "0.99", "best_ask": "0.991"}, {"asset_id": "99482729937705145912235477495415874028392807588978105657655512338616047660547", "price": "0.088", "size": "50", "side": "SELL", "hash": "139ad177f2481664f370ef9da3064d0f9f075e4c", "best_bid": "0.009", "best_ask": "0.01"}], "timestamp": "1769384033706", "event_type": "price_change"}}
{"_local_timestamp": "2026-01-25T23:33:53.886134+00:00", "data": {"market": "0x6a3bc08c62413e6594164bc15aa07b282b22a6d7efc61cd69df92b63f4132289", "price_changes": [{"asset_id": "5598960237790161917534060866496363286228389060029699153094526893891604621525", "price": "0.912", "size": "25", "side": "BUY", "hash": "5f8244d662058a56f0d99a144862fb8eb2ec038f", "best_bid": "0.99", "best_ask": "0.991"}, {"asset_id": "99482729937705145912235477495415874028392807588978105657655512338616047660547", "price": "0.088", "size": "25", "side": "SELL", "hash": "eb8b9a8bf2efa4704ef449fc1598f913dc81290f", "best_bid": "0.009", "best_ask": "0.01"}], "timestamp": "1769384033814", "event_type": "price_change"}}
{"_local_timestamp": "2026-01-25T23:33:54.037668+00:00", "data": {"market": "0x8d8b98fb4c290c4e152ce8b653c5598b74a630dd1dbb800a5f328ea9c8b00727", "price_changes": [{"asset_id": "78474559114932529051705203752686517828085200880957778785050112163927946260911", "price": "0.942", "size": "50", "side": "BUY", "hash": "643e00eccc1a681966773656fe9370974ee05a58", "best_bid": "0.942", "best_ask": "0.958"}, {"asset_id": "80938914484826983068438930343848557974856639667615266122989436725895029352478", "price": "0.058", "size": "50", "side": "SELL", "hash": "28ac5cd51d398adc15f9e223790f0d08c7f758a9", "best_bid": "0.042", "best_ask": "0.058"}], "timestamp": "1769384033974", "event_type": "price_change"}}
{"_local_timestamp": "2026-01-25T23:33:54.096368+00:00", "data": {"market": "0x8d8b98fb4c290c4e152ce8b653c5598b74a630dd1dbb800a5f328ea9c8b00727", "price_changes": [{"asset_id": "80938914484826983068438930343848557974856639667615266122989436725895029352478", "price": "0.06", "size": "0", "side": "SELL", "hash": "a6abc40fb2c19dcb715f92b84c3b9eee660e1524", "best_bid": "0.042", "best_ask": "0.058"}, {"asset_id": "78474559114932529051705203752686517828085200880957778785050112163927946260911", "price": "0.94", "size": "0", "side": "BUY", "hash": "dbd3b0ba5041fdad9e017b42f9acb31835905b24", "best_bid": "0.942", "best_ask": "0.958"}], "timestamp": "1769384034002", "event_type": "price_change"}}
{"_local_timestamp": "2026-01-25T23:33:54.111780+00:00", "data": {"market": "0x8d8b98fb4c290c4e152ce8b653c5598b74a630dd1dbb800a5f328ea9c8b00727", "price_changes": [{"asset_id": "78474559114932529051705203752686517828085200880957778785050112163927946260911", "price": "0.936", "size": "50", "side": "BUY", "hash": "e6a8e02512351729f5f816a16e35bc1f88975e18", "best_bid": "0.942", "best_ask": "0.958"}, {"asset_id": "80938914484826983068438930343848557974856639667615266122989436725895029352478", "price": "0.064", "size": "50", "side": "SELL", "hash": "825a4957419e9ce986f3a61c30c8f08e5a1c8670", "best_bid": "0.042", "best_ask": "0.058"}], "timestamp": "1769384034022", "event_type": "price_change"}}
{"_local_timestamp": "2026-01-25T23:33:54.112837+00:00", "data": {"market": "0x8d8b98fb4c290c4e152ce8b653c5598b74a630dd1dbb800a5f328ea9c8b00727", "price_changes": [{"asset_id": "78474559114932529051705203752686517828085200880957778785050112163927946260911", "price": "0.938", "size": "10", "side": "BUY", "hash": "ddd901d9f89c3882711f8871b69458f70402e179", "best_bid": "0.942", "best_ask": "0.958"}, {"asset_id": "80938914484826983068438930343848557974856639667615266122989436725895029352478", "price": "0.062", "size": "10", "side": "SELL", "hash": "6e0071055e8045092b8a7cdd69b0d90ef873503d", "best_bid": "0.042", "best_ask": "0.058"}], "timestamp": "1769384034035", "event_type": "price_change"}}
{"_local_timestamp": "2026-01-25T23:33:54.254506+00:00", "data": {"market": "0x8d8b98fb4c290c4e152ce8b653c5598b74a630dd1dbb800a5f328ea9c8b00727", "price_changes": [{"asset_id": "78474559114932529051705203752686517828085200880957778785050112163927946260911", "price": "0.941", "size": "67.14", "side": "BUY", "hash": "c9137890c285746411108a46395a13f3318eccf6", "best_bid": "0.942", "best_ask": "0.958"}, {"asset_id": "80938914484826983068438930343848557974856639667615266122989436725895029352478", "price": "0.059", "size": "67.14", "side": "SELL", "hash": "3f349644d66ee87fd0d3e042b147a64552e3d769", "best_bid": "0.042", "best_ask": "0.058"}], "timestamp": "1769384034182", "event_type": "price_change"}}
{"_local_timestamp": "2026-01-25T23:33:54.376920+00:00", "data": {"market": "0x8d8b98fb4c290c4e152ce8b653c5598b74a630dd1dbb800a5f328ea9c8b00727", "price_changes": [{"asset_id": "78474559114932529051705203752686517828085200880957778785050112163927946260911", "price": "0.936", "size": "0", "side": "BUY", "hash": "017ca51c2a20f7ad7b46d925c4ccdf7042b93e87", "best_bid": "0.942", "best_ask": "0.958"}, {"asset_id": "80938914484826983068438930343848557974856639667615266122989436725895029352478", "price": "0.064", "size": "0", "side": "SELL", "hash": "7b50895e86124cc53f11764df1b2b67f5554e7c2", "best_bid": "0.042", "best_ask": "0.058"}], "timestamp": "1769384034306", "event_type": "price_change"}}
{"_local_timestamp": "2026-01-25T23:33:54.969906+00:00", "data": {"market": "0x8d8b98fb4c290c4e152ce8b653c5598b74a630dd1dbb800a5f328ea9c8b00727", "price_changes": [{"asset_id": "80938914484826983068438930343848557974856639667615266122989436725895029352478", "price": "0.059", "size": "37.14", "side": "SELL", "hash": "471b0eb5a4cadca7639650b63d19c22a0c79d588", "best_bid": "0.042", "best_ask": "0.058"}, {"asset_id": "78474559114932529051705203752686517828085200880957778785050112163927946260911", "price": "0.941", "size": "37.14", "side": "BUY", "hash": "9e10745d5de6997abe2c83e5825ac8abea8a2280", "best_bid": "0.942", "best_ask": "0.958"}], "timestamp": "1769384034903", "event_type": "price_change"}}
{"_local_timestamp": "2026-01-25T23:33:55.033777+00:00", "data": {"market": "0x8d8b98fb4c290c4e152ce8b653c5598b74a630dd1dbb800a5f328ea9c8b00727", "price_changes": [{"asset_id": "80938914484826983068438930343848557974856639667615266122989436725895029352478", "price": "0.065", "size": "35.38", "side": "SELL", "hash": "0ebd4cc40823c07e3dcfcc0721ba202fa7d51e5f", "best_bid": "0.042", "best_ask": "0.058"}, {"asset_id": "78474559114932529051705203752686517828085200880957778785050112163927946260911", "price": "0.935", "size": "35.38", "side": "BUY", "hash": "ee38e668e5821b872b8a41950c811d19f022f4d4", "best_bid": "0.942", "best_ask": "0.958"}], "timestamp": "1769384034969", "event_type": "price_change"}}
{"_local_timestamp": "2026-01-25T23:33:55.121425+00:00", "data": {"market": "0x6a3bc08c62413e6594164bc15aa07b282b22a6d7efc61cd69df92b63f4132289", "price_changes": [{"asset_id": "5598960237790161917534060866496363286228389060029699153094526893891604621525", "price": "0.912", "size": "50", "side": "BUY", "hash": "6387fe655d1fa22acc84ee380345b046f1f74c3d", "best_bid": "0.99", "best_ask": "0.991"}, {"asset_id": "99482729937705145912235477495415874028392807588978105657655512338616047660547", "price": "0.088", "size": "50", "side": "SELL", "hash": "505f9fb1a8297e097ca7410e3636be7b03db9600", "best_bid": "0.009", "best_ask": "0.01"}], "timestamp": "1769384035018", "event_type": "price_change"}}
{"_local_timestamp": "2026-01-25T23:33:55.206192+00:00", "data": {"market": "0x6a3bc08c62413e6594164bc15aa07b282b22a6d7efc61cd69df92b63f4132289", "price_changes": [{"asset_id": "5598960237790161917534060866496363286228389060029699153094526893891604621525", "price": "0.912", "size": "25", "side": "BUY", "hash": "499603e48633fa70337ccd09d7a63c452e9b7798", "best_bid": "0.99", "best_ask": "0.991"}, {"asset_id": "99482729937705145912235477495415874028392807588978105657655512338616047660547", "price": "0.088", "size": "25", "side": "SELL", "hash": "e1f3ef810d15a75856fda3753dd2e9849dd7f533", "best_bid": "0.009", "best_ask": "0.01"}], "timestamp": "1769384035132", "event_type": "price_change"}}
{"_local_timestamp": "2026-01-25T23:33:55.537495+00:00", "data": {"market": "0x8d8b98fb4c290c4e152ce8b653c5598b74a630dd1dbb800a5f328ea9c8b00727", "price_changes": [{"asset_id": "78474559114932529051705203752686517828085200880957778785050112163927946260911", "price": "0.941", "size": "7.14", "side": "BUY", "hash": "505909772c0764e42667388ba90a9f82dafd1c95", "best_bid": "0.942", "best_ask": "0.958"}, {"asset_id": "80938914484826983068438930343848557974856639667615266122989436725895029352478", "price": "0.059", "size": "7.14", "side": "SELL", "hash": "526dc5de52c38c3f36f8caee396fb2efbec8a07a", "best_bid": "0.042", "best_ask": "0.058"}], "timestamp": "1769384035467", "event_type": "price_change"}}
{"_local_timestamp": "2026-01-25T23:33:55.577326+00:00", "data": {"market": "0x8d8b98fb4c290c4e152ce8b653c5598b74a630dd1dbb800a5f328ea9c8b00727", "price_changes": [{"asset_id": "78474559114932529051705203752686517828085200880957778785050112163927946260911", "price": "0.934", "size": "85", "side": "BUY", "hash": "13cd7381220c56d6bff15068d6e4d024160a2b2c", "best_bid": "0.942", "best_ask": "0.958"}, {"asset_id": "80938914484826983068438930343848557974856639667615266122989436725895029352478", "price": "0.066", "size": "85", "side": "SELL", "hash": "045e7116a1802a93a8e59cc130a60ba0b1417d47", "best_bid": "0.042", "best_ask": "0.058"}], "timestamp": "1769384035512", "event_type": "price_change"}}
{"_local_timestamp": "2026-01-25T23:33:56.106216+00:00", "data": {"market": "0x8d8b98fb4c290c4e152ce8b653c5598b74a630dd1dbb800a5f328ea9c8b00727", "price_changes": [{"asset_id": "80938914484826983068438930343848557974856639667615266122989436725895029352478", "price": "0.059", "size": "0", "side": "SELL", "hash": "3f8315ee710338f738566e732adb3947de5d946d", "best_bid": "0.042", "best_ask": "0.058"}, {"asset_id": "78474559114932529051705203752686517828085200880957778785050112163927946260911", "price": "0.941", "size": "0", "side": "BUY", "hash": "cee04bf3cd2c70466ca2c1924974e1185c78f680", "best_bid": "0.942", "best_ask": "0.958"}], "timestamp": "1769384036022", "event_type": "price_change"}}
{"_local_timestamp": "2026-01-25T23:33:56.227556+00:00", "data": {"market": "0x6a3bc08c62413e6594164bc15aa07b282b22a6d7efc61cd69df92b63f4132289", "price_changes": [{"asset_id": "5598960237790161917534060866496363286228389060029699153094526893891604621525", "price": "0.912", "size": "50", "side": "BUY", "hash": "3d619c2ffa09b981ce9df273473f10cf892e8307", "best_bid": "0.99", "best_ask": "0.991"}, {"asset_id": "99482729937705145912235477495415874028392807588978105657655512338616047660547", "price": "0.088", "size": "50", "side": "SELL", "hash": "1c8b1699c2d937ad3628fc9785d33edb70b51b12", "best_bid": "0.009", "best_ask": "0.01"}], "timestamp": "1769384036148", "event_type": "price_change"}}
{"_local_timestamp": "2026-01-25T23:33:56.342309+00:00", "data": {"market": "0x6a3bc08c62413e6594164bc15aa07b282b22a6d7efc61cd69df92b63f4132289", "price_changes": [{"asset_id": "5598960237790161917534060866496363286228389060029699153094526893891604621525", "price": "0.912", "size": "25", "side": "BUY", "hash": "94470d68f4065ebe87eee83dc14c37379afc8639", "best_bid": "0.99", "best_ask": "0.991"}, {"asset_id": "99482729937705145912235477495415874028392807588978105657655512338616047660547", "price": "0.088", "size": "25", "side": "SELL", "hash": "7494a40900355c66ac304815ac45226dd59f3bb3", "best_bid": "0.009", "best_ask": "0.01"}], "timestamp": "1769384036278", "event_type": "price_change"}}
{"_local_timestamp": "2026-01-25T23:33:56.828464+00:00", "data": {"market": "0x8d8b98fb4c290c4e152ce8b653c5598b74a630dd1dbb800a5f328ea9c8b00727", "price_changes": [{"asset_id": "80938914484826983068438930343848557974856639667615266122989436725895029352478", "price": "0.057", "size": "7.14", "side": "SELL", "hash": "00e1e84e58e37cb534632bacdf8a6bc55f21a7c5", "best_bid": "0.042", "best_ask": "0.057"}, {"asset_id": "78474559114932529051705203752686517828085200880957778785050112163927946260911", "price": "0.943", "size": "7.14", "side": "BUY", "hash": "ce19d83d79c62f2e47ba4023e4c4816deeabeb3b", "best_bid": "0.943", "best_ask": "0.958"}], "timestamp": "1769384036760", "event_type": "price_change"}}
{"_local_timestamp": "2026-01-25T23:33:57.449670+00:00", "data": {"market": "0x378f76341e555b6d54b89cc527afde5f8c293025cf6f48980145b94dc5726ce7", "price_changes": [{"asset_id": "7664065636701295840769263287437558246574946591549211748470097864098826204283", "price": "0.63", "size": "0", "side": "BUY", "hash": "4c2de8f9fcdc84a0cb81f176d579bfb4240c9eae", "best_bid": "0.89", "best_ask": "0.9"}, {"asset_id": "100508935738063536113321312580877764668655616361107299342990907747250271040586", "price": "0.37", "size": "0", "side": "SELL", "hash": "285943ad050a362006e8a91971e28dc83a95a2ab", "best_bid": "0.1", "best_ask": "0.11"}], "timestamp": "1769384037385", "event_type": "price_change"}}
