{"_local_timestamp": "2026-01-25T23:33:19.544204+00:00", "data": [{"market": "0x7af772ffd32b7726faabc964493d3e3b187186dcaea0d8e60110da9aa0771a42", "asset_id": "33977621156566454256243426751711042651548860329437292067732819030497867836755", "timestamp": "1769383993145", "hash": "e637633095d934951d50bebd85218b2a1079c37a", "bids": [{"price": "0.001", "size": "3907.28"}, {"price": "0.002", "size": "1250"}, {"price": "0.003", "size": "1407.35"}, {"price": "0.006", "size": "200"}, {"price": "0.007", "size": "10.8"}, {"price": "0.01", "size": "8300"}, {"price": "0.02", "size": "3900"}, {"price": "0.021", "size": "9.66"}, {"price": "0.04", "size": "1500"}, {"price": "0.05", "size": "30"}, {"price": "0.051", "size": "39"}, {"price": "0.06", "size": "375"}, {"price": "0.061", "size": "9.45"}, {"price": "0.1", "size": "560"}, {"price": "0.15", "size": "551.66"}, {"price": "0.2", "size": "410"}, {"price": "0.201", "size": "5.53"}, {"price": "0.221", "size": "1322"}, {"price": "0.25", "size": "112"}, {"price": "0.3", "size": "86.66"}, {"price": "0.31", "size": "6"}, {"price": "0.312", "size": "6147"}, {"price": "0.313", "size": "300"}, {"price": "0.35", "size": "68.57"}, {"price": "0.4", "size": "125"}, {"price": "0.403", "size": "10"}, {"price": "0.404", "size": "10"}, {"price": "0.91", "size": "3850"}, {"price": "0.911", "size": "6"}, {"price": "0.914", "size": "6"}, {"price": "0.915", "size": "10"}, {"price": "0.917", "size": "25"}, {"price": "0.918", "size": "20"}, {"price": "0.919", "size": "20"}, {"price": "0.93", "size": "6"}, {"price": "0.945", "size": "300"}, {"price": "0.95", "size": "20"}, {"price": "0.953", "size": "37"}, {"price": "0.954", "size": "148.75"}, {"price": "0.955", "size": "50"}], "asks": [{"price": "0.999", "size": "20250.99"}, {"price": "0.998", "size": "5765.89"}, {"price": "0.997", "size": "1917.84"}, {"price": "0.996", "size": "119.15"}, {"price": "0.995", "size": "16"}, {"price": "0.994", "size": "14.68"}, {"price": "0.992", "size": "380"}, {"price": "0.991", "size": "257.66"}, {"price": "0.99", "size": "6"}, {"price": "0.989", "size": "6.02"}, {"price": "0.978", "size": "0.38"}], "event_type": "book", "last_trade_price": "0.023"}, {"market": "0x1198b4cfb84b6078c6f432a9b034ae7d6047ca462fcee0f1895d1d94f5392bd6", "asset_id": "48633487062848646741583673336029083373164703684898528527193929763953273671096", "timestamp": "1769383978156", "hash": "3f282d10d86949990c115dfa0b278d4b2502ba13", "bids": [{"price": "0.001", "size": "21431.91"}, {"price": "0.003", "size": "6088"}, {"price": "0.004", "size": "2636.1"}, {"price": "0.006", "size": "647"}, {"price": "0.007", "size": "58.88"}, {"price": "0.008", "size": "149.99"}], "asks": [{"price": "0.999", "size": "3745.02"}, {"price": "0.998", "size": "1250"}, {"price": "0.997", "size": "1407.36"}, {"price": "0.994", "size": "200"}, {"price": "0.993", "size": "10.81"}, {"price": "0.99", "size": "8300"}, {"price": "0.98", "size": "3900"}, {"price": "0.979", "size": "9.66"}, {"price": "0.96", "size": "1500"}, {"price": "0.95", "size": "30"}, {"price": "0.949", "size": "39"}, {"price": "0.94", "size": "375"}, {"price": "0.939", "size": "9.45"}, {"price": "0.9", "size": "560"}, {"price": "0.85", "size": "551.66"}, {"price": "0.839", "size": "2250"}, {"price": "0.8", "size": "160"}, {"price": "0.799", "size": "5.53"}, {"price": "0.75", "size": "112"}, {"price": "0.727", "size": "7115"}, {"price": "0.726", "size": "300"}, {"price": "0.7", "size": "86.66"}, {"price": "0.699", "size": "10"}, {"price": "0.65", "size": "68.57"}, {"price": "0.6", "size": "125"}, {"price": "0.122", "size": "854.04"}, {"price": "0.09", "size": "3850"}, {"price": "0.089", "size": "128.22"}, {"price": "0.088", "size": "100"}, {"price": "0.084", "size": "10"}, {"price": "0.083", "size": "20"}, {"price": "0.055", "size": "100"}, {"price": "0.054", "size": "45"}, {"price": "0.049", "size": "6"}, {"price": "0.039", "size": "98.99"}, {"price": "0.038", "size": "6"}, {"price": "0.029", "size": "6"}, {"price": "0.028", "size": "77"}, {"price": "0.022", "size": "33"}], "event_type": "book", "last_trade_price": "0.008"}, {"market": "0xb7427b891a0134371023603986edc842ce369e83dcc42f300e7a03049295d4b1", "asset_id": "79849296060580317277275866407031080149422127632028665473147696931641259289529", "timestamp": "1769383968887", "hash": "71af704c6a06e63e003e4b511b2e4654e669a218", "bids": [{"price": "0.001", "size": "2633.62"}, {"price": "0.002", "size": "1250"}, {"price": "0.003", "size": "26.54"}, {"price": "0.01", "size": "8000"}, {"price": "0.011", "size": "8.55"}, {"price": "0.02", "size": "3500"}, {"price": "0.021", "size": "8.65"}, {"price": "0.04", "size": "1500"}, {"price": "0.041", "size": "6.18"}, {"price": "0.046", "size": "3000"}, {"price": "0.047", "size": "3225"}, {"price": "0.05", "size": "7.11"}, {"price": "0.06", "size": "375"}, {"price": "0.062", "size": "100"}, {"price": "0.07", "size": "19.7"}, {"price": "0.071", "size": "20"}, {"price": "0.22", "size": "3850"}, {"price": "0.228", "size": "50"}, {"price": "0.237", "size": "20"}, {"price": "0.238", "size": "20"}, {"price": "0.26", "size": "2000"}, {"price": "0.261", "size": "1"}, {"price": "0.27", "size": "2000"}, {"price": "0.28", "size": "3133.47"}, {"price": "0.286", "size": "16.2"}, {"price": "0.287", "size": "59"}], "asks": [{"price": "0.999", "size": "3651.4"}, {"price": "0.998", "size": "1250"}, {"price": "0.997", "size": "2400"}, {"price": "0.996", "size": "5.27"}, {"price": "0.994", "size": "200"}, {"price": "0.98", "size": "400"}, {"price": "0.979", "size": "10.89"}, {"price": "0.93", "size": "514.28"}, {"price": "0.928", "size": "4666"}, {"price": "0.9", "size": "51"}, {"price": "0.89", "size": "634.09"}, {"price": "0.85", "size": "213.33"}, {"price": "0.849", "size": "1058"}, {"price": "0.82", "size": "155.55"}, {"price": "0.819", "size": "2570"}, {"price": "0.78", "size": "218.18"}, {"price": "0.779", "size": "134"}, {"price": "0.74", "size": "92.3"}, {"price": "0.71", "size": "218.96"}, {"price": "0.39", "size": "150"}, {"price": "0.38", "size": "25"}, {"price": "0.379", "size": "100"}, {"price": "0.349", "size": "55"}, {"price": "0.343", "size": "100"}, {"price": "0.317", "size": "95.82"}, {"price": "0.316", "size": "10"}, {"price": "0.308", "size": "21.2"}, {"price": "0.307", "size": "10.5"}, {"price": "0.306", "size": "106.3"}], "event_type": "book", "last_trade_price": "0.300"}, {"market": "0x1278f161b546f237cf9a029d9383ff5da371ff047a5adad48ee3243a6f93b6fb", "asset_id": "83477010551081586181287014200977553131804751829676583771272159234562620010416", "timestamp": "1769383981385", "hash": "9ec99c72234efe7430e41c5bdffb36cbe1c4b1ed", "bids": [{"price": "0.001", "size": "3679.08"}, {"price": "0.002", "size": "1250"}, {"price": "0.003", "size": "1407.33"}, {"price": "0.006", "size": "200"}, {"price": "0.007", "size": "10.77"}, {"price": "0.01", "size": "8300"}, {"price": "0.02", "size": "3900"}, {"price": "0.021", "size": "9.63"}, {"price": "0.04", "size": "1500"}, {"price": "0.041", "size": "250"}, {"price": "0.05", "size": "30"}, {"price": "0.051", "size": "39"}, {"price": "0.052", "size": "10"}, {"price": "0.06", "size": "375"}, {"price": "0.061", "size": "9.43"}, {"price": "0.1", "size": "560"}, {"price": "0.15", "size": "551.66"}, {"price": "0.2", "size": "410"}, {"price": "0.201", "size": "5.54"}, {"price": "0.25", "size": "262"}, {"price": "0.29", "size": "89.65"}, {"price": "0.34", "size": "70.58"}, {"price": "0.39", "size": "51.28"}, {"price": "0.455", "size": "1000"}, {"price": "0.456", "size": "4208"}, {"price": "0.463", "size": "5"}, {"price": "0.465", "size": "20"}, {"price": "0.466", "size": "25"}, {"price": "0.8", "size": "49.01"}, {"price": "0.83", "size": "155"}, {"price": "0.861", "size": "536.39"}, {"price": "0.862", "size": "10"}, {"price": "0.9", "size": "850"}, {"price": "0.901", "size": "259.84"}, {"price": "0.91", "size": "136.04"}, {"price": "0.911", "size": "210"}, {"price": "0.912", "size": "360"}, {"price": "0.913", "size": "738.25"}, {"price": "0.921", "size": "281.03"}, {"price": "0.925", "size": "242.81"}, {"price": "0.931", "size": "549.37"}, {"price": "0.935", "size": "326.46"}, {"price": "0.938", "size": "536.39"}, {"price": "0.939", "size": "123.02"}, {"price": "0.945", "size": "374.71"}, {"price": "0.948", "size": "54.15"}, {"price": "0.951", "size": "740.09"}, {"price": "0.955", "size": "404.37"}, {"price": "0.963", "size": "54.98"}, {"price": "0.965", "size": "50"}, {"price": "0.968", "size": "300"}, {"price": "0.969", "size": "298.41"}, {"price": "0.97", "size": "108.41"}, {"price": "0.971", "size": "13"}], "asks": [{"price": "0.999", "size": "7581"}, {"price": "0.998", "size": "1008.62"}, {"price": "0.997", "size": "289.8"}, {"price": "0.996", "size": "12.74"}, {"price": "0.993", "size": "1129.07"}, {"price": "0.992", "size": "10.42"}, {"price": "0.99", "size": "2050"}, {"price": "0.989", "size": "3662.1"}, {"price": "0.988", "size": "6.77"}, {"price": "0.987", "size": "50"}, {"price": "0.985", "size": "1777"}, {"price": "0.982", "size": "1555"}, {"price": "0.979", "size": "2233"}, {"price": "0.978", "size": "409"}, {"price": "0.977", "size": "362"}], "event_type": "book", "last_trade_price": "0.022"}, {"market": "0xb7427b891a0134371023603986edc842ce369e83dcc42f300e7a03049295d4b1", "asset_id": "109919329920505980115727737237456054640803613381042045664921404844196255236880", "timestamp": "1769383968887", "hash": "4370a990ed03b08db57872339e6191326cff273b", "bids": [{"price": "0.001", "size": "3651.4"}, {"price": "0.002", "size": "1250"}, {"price": "0.003", "size": "2400"}, {"price": "0.004", "size": "5.27"}, {"price": "0.006", "size": "200"}, {"price": "0.02", "size": "400"}, {"price": "0.021", "size": "10.89"}, {"price": "0.07", "size": "514.28"}, {"price": "0.072", "size": "4666"}, {"price": "0.1", "size": "51"}, {"price": "0.11", "size": "634.09"}, {"price": "0.15", "size": "213.33"}, {"price": "0.151", "size": "1058"}, {"price": "0.18", "size": "155.55"}, {"price": "0.181", "size": "2570"}, {"price": "0.22", "size": "218.18"}, {"price": "0.221", "size": "134"}, {"price": "0.26", "size": "92.3"}, {"price": "0.29", "size": "218.96"}, {"price": "0.61", "size": "150"}, {"price": "0.62", "size": "25"}, {"price": "0.621", "size": "100"}, {"price": "0.651", "size": "55"}, {"price": "0.657", "size": "100"}, {"price": "0.683", "size": "95.82"}, {"price": "0.684", "size": "10"}, {"price": "0.692", "size": "21.2"}, {"price": "0.693", "size": "10.5"}, {"price": "0.694", "size": "106.3"}], "asks": [{"price": "0.999", "size": "2633.62"}, {"price": "0.998", "size": "1250"}, {"price": "0.997", "size": "26.54"}, {"price": "0.99", "size": "8000"}, {"price": "0.989", "size": "8.55"}, {"price": "0.98", "size": "3500"}, {"price": "0.979", "size": "8.65"}, {"price": "0.96", "size": "1500"}, {"price": "0.959", "size": "6.18"}, {"price": "0.954", "size": "3000"}, {"price": "0.953", "size": "3225"}, {"price": "0.95", "size": "7.11"}, {"price": "0.94", "size": "375"}, {"price": "0.938", "size": "100"}, {"price": "0.93", "size": "19.7"}, {"price": "0.929", "size": "20"}, {"price": "0.78", "size": "3850"}, {"price": "0.772", "size": "50"}, {"price": "0.763", "size": "20"}, {"price": "0.762", "size": "20"}, {"price": "0.74", "size": "2000"}, {"price": "0.739", "size": "1"}, {"price": "0.73", "size": "2000"}, {"price": "0.72", "size": "3133.47"}, {"price": "0.714", "size": "16.2"}, {"price": "0.713", "size": "59"}], "event_type": "book", "last_trade_price": "0.300"}, {"market": "0x7e897a7826222708d178062c82e9166b37a98df0ce92ace40f3b9357f2526157", "asset_id": "8417326734150529989790022001226615602996938938967740280020227231905495513816", "timestamp": "1769383990831", "hash": "a20798934a18fd6a305ffac7da1eeb6a8b77d226", "bids": [{"price": "0.001", "size": "3834.07"}, {"price": "0.002", "size": "1250"}, {"price": "0.003", "size": "1407.33"}, {"price": "0.006", "size": "200"}, {"price": "0.007", "size": "10.77"}, {"price": "0.01", "size": "8000"}, {"price": "0.02", "size": "3900"}, {"price": "0.021", "size": "9.63"}, {"price": "0.04", "size": "1500"}, {"price": "0.05", "size": "330"}, {"price": "0.051", "size": "39"}, {"price": "0.06", "size": "375"}, {"price": "0.061", "size": "9.42"}, {"price": "0.1", "size": "560"}, {"price": "0.15", "size": "551.66"}, {"price": "0.161", "size": "2250"}, {"price": "0.162", "size": "250"}, {"price": "0.2", "size": "160"}, {"price": "0.201", "size": "5.54"}, {"price": "0.25", "size": "262"}, {"price": "0.3", "size": "86.66"}, {"price": "0.35", "size": "68.57"}, {"price": "0.4", "size": "50"}, {"price": "0.412", "size": "4648"}, {"price": "0.413", "size": "10"}, {"price": "0.414", "size": "20"}, {"price": "0.415", "size": "5"}, {"price": "0.416", "size": "25"}, {"price": "0.9", "size": "150"}, {"price": "0.904", "size": "10"}, {"price": "0.921", "size": "323.05"}, {"price": "0.922", "size": "10"}, {"price": "0.923", "size": "20"}, {"price": "0.929", "size": "281.5"}, {"price": "0.962", "size": "674.94"}, {"price": "0.965", "size": "502.79"}, {"price": "0.971", "size": "189.71"}, {"price": "0.976", "size": "226.65"}, {"price": "0.978", "size": "70.25"}, {"price": "0.979", "size": "360"}, {"price": "0.981", "size": "30.7"}, {"price": "0.986", "size": "487.33"}, {"price": "0.987", "size": "31"}], "asks": [{"price": "0.999", "size": "21525.8"}, {"price": "0.998", "size": "2362.65"}, {"price": "0.997", "size": "6596.56"}, {"price": "0.996", "size": "1250"}, {"price": "0.994", "size": "2110.99"}, {"price": "0.992", "size": "4598"}, {"price": "0.991", "size": "30.55"}, {"price": "0.99", "size": "2958.15"}], "event_type": "book", "last_trade_price": "0.010"}, {"market": "0x3b7fa5e73b58e3e8db12f33b0888ce58c24d6249cc237581ebe11ac4867dd7b7", "asset_id": "2058086706657815889669487757317075047972583222463683616694793460955010144892", "timestamp": "1769383990573", "hash": "9328963bfae2c1903a4a7a85f3b29643d63eb98a", "bids": [{"price": "0.01", "size": "8390.95"}, {"price": "0.02", "size": "3900"}, {"price": "0.03", "size": "6.8"}, {"price": "0.04", "size": "1500"}, {"price": "0.05", "size": "20"}, {"price": "0.06", "size": "441"}, {"price": "0.08", "size": "650"}, {"price": "0.09", "size": "5.36"}, {"price": "0.11", "size": "125"}, {"price": "0.12", "size": "2700"}, {"price": "0.13", "size": "261.53"}, {"price": "0.14", "size": "1142"}, {"price": "0.17", "size": "188.23"}, {"price": "0.2", "size": "1050"}, {"price": "0.21", "size": "139.06"}, {"price": "0.24", "size": "1000"}, {"price": "0.26", "size": "100"}, {"price": "0.27", "size": "7"}, {"price": "0.3", "size": "3264"}, {"price": "0.31", "size": "300"}, {"price": "0.34", "size": "133.82"}, {"price": "0.66", "size": "7"}, {"price": "0.67", "size": "6"}, {"price": "0.68", "size": "700"}, {"price": "0.69", "size": "157"}, {"price": "0.7", "size": "26"}, {"price": "0.71", "size": "20"}, {"price": "0.72", "size": "7"}, {"price": "0.73", "size": "26"}, {"price": "0.74", "size": "40"}, {"price": "0.75", "size": "104.02"}, {"price": "0.76", "size": "56"}, {"price": "0.77", "size": "95.82"}, {"price": "0.78", "size": "179.52"}], "asks": [{"price": "0.99", "size": "6107.32"}, {"price": "0.98", "size": "12.5"}, {"price": "0.97", "size": "250"}, {"price": "0.96", "size": "6"}, {"price": "0.88", "size": "700"}, {"price": "0.87", "size": "156"}, {"price": "0.85", "size": "200"}, {"price": "0.84", "size": "6"}, {"price": "0.83", "size": "2971.62"}, {"price": "0.82", "size": "116.66"}, {"price": "0.81", "size": "77.66"}, {"price": "0.8", "size": "66.66"}], "event_type": "book", "last_trade_price": "0.180"}, {"market": "0xd94cb5bf446cb8142d22091a40ba14d8c7355bd06fda75e61e25207135348550", "asset_id": "73232075333787574101356206392441747050603477997678734507064104196778724283091", "timestamp": "1769383980427", "hash": "b6417aebe5b912453a43f413fcc427487dfaa042", "bids": [{"price": "0.001", "size": "3869.19"}, {"price": "0.002", "size": "1250"}, {"price": "0.003", "size": "1407.34"}, {"price": "0.006", "size": "200"}, {"price": "0.007", "size": "10.78"}, {"price": "0.01", "size": "8000"}, {"price": "0.02", "size": "3900"}, {"price": "0.021", "size": "9.63"}, {"price": "0.04", "size": "1500"}, {"price": "0.05", "size": "330"}, {"price": "0.051", "size": "39"}, {"price": "0.06", "size": "375"}, {"price": "0.061", "size": "9.43"}, {"price": "0.1", "size": "560"}, {"price": "0.15", "size": "551.66"}, {"price": "0.2", "size": "410"}, {"price": "0.201", "size": "5.54"}, {"price": "0.215", "size": "1372"}, {"price": "0.25", "size": "112"}, {"price": "0.3", "size": "86.66"}, {"price": "0.35", "size": "68.57"}, {"price": "0.4", "size": "50"}, {"price": "0.418", "size": "5"}, {"price": "0.421", "size": "3887"}, {"price": "0.422", "size": "360"}, {"price": "0.423", "size": "10"}, {"price": "0.9", "size": "850"}, {"price": "0.901", "size": "1054.71"}, {"price": "0.904", "size": "10"}, {"price": "0.927", "size": "10"}, {"price": "0.928", "size": "20"}, {"price": "0.936", "size": "20"}, {"price": "0.937", "size": "25"}, {"price": "0.961", "size": "43.09"}, {"price": "0.962", "size": "118.75"}, {"price": "0.98", "size": "59.38"}, {"price": "0.995", "size": "8.2"}], "asks": [{"price": "0.999", "size": "15600.05"}, {"price": "0.998", "size": "266"}, {"price": "0.997", "size": "3598.7"}, {"price": "0.996", "size": "214.8"}], "event_type": "book", "last_trade_price": "0.004"}, {"market": "0x7e897a7826222708d178062c82e9166b37a98df0ce92ace40f3b9357f2526157", "asset_id": "85126848831263873777721669142266306730253139367446060083090258474801299057771", "timestamp": "1769383990831", "hash": "5621a27dfba88c121ab45aeabbf764d74b9c822a", "bids": [{"price": "0.001", "size": "21525.8"}, {"price": "0.002", "size": "2362.65"}, {"price": "0.003", "size": "6596.56"}, {"price": "0.004", "size": "1250"}, {"price": "0.006", "size": "2110.99"}, {"price": "0.008", "size": "4598"}, {"price": "0.009", "size": "30.55"}, {"price": "0.01", "size": "2958.15"}], "asks": [{"price": "0.999", "size": "3834.07"}, {"price": "0.998", "size": "1250"}, {"price": "0.997", "size": "1407.33"}, {"price": "0.994", "size": "200"}, {"price": "0.993", "size": "10.77"}, {"price": "0.99", "size": "8000"}, {"price": "0.98", "size": "3900"}, {"price": "0.979", "size": "9.63"}, {"price": "0.96", "size": "1500"}, {"price": "0.95", "size": "330"}, {"price": "0.949", "size": "39"}, {"price": "0.94", "size": "375"}, {"price": "0.939", "size": "9.42"}, {"price": "0.9", "size": "560"}, {"price": "0.85", "size": "551.66"}, {"price": "0.839", "size": "2250"}, {"price": "0.838", "size": "250"}, {"price": "0.8", "size": "160"}, {"price": "0.799", "size": "5.54"}, {"price": "0.75", "size": "262"}, {"price": "0.7", "size": "86.66"}, {"price": "0.65", "size": "68.57"}, {"price": "0.6", "size": "50"}, {"price": "0.588", "size": "4648"}, {"price": "0.587", "size": "10"}, {"price": "0.586", "size": "20"}, {"price": "0.585", "size": "5"}, {"price": "0.584", "size": "25"}, {"price": "0.1", "size": "150"}, {"price": "0.096", "size": "10"}, {"price": "0.079", "size": "323.05"}, {"price": "0.078", "size": "10"}, {"price": "0.077", "size": "20"}, {"price": "0.071", "size": "281.5"}, {"price": "0.038", "size": "674.94"}, {"price": "0.035", "size": "502.79"}, {"price": "0.029", "size": "189.71"}, {"price": "0.024", "size": "226.65"}, {"price": "0.022", "size": "70.25"}, {"price": "0.021", "size": "360"}, {"price": "0.019", "size": "30.7"}, {"price": "0.014", "size": "487.33"}, {"price": "0.013", "size": "31"}], "event_type": "book", "last_trade_price": "0.010"}, {"market": "0xd94cb5bf446cb8142d22091a40ba14d8c7355bd06fda75e61e25207135348550", "asset_id": "58192906727610480118792319554990896451617120222517723334233116219918933677749", "timestamp": "1769383980427", "hash": "acf083a0b542995d6961c5e622c48929501aaaf1", "bids": [{"price": "0.001", "size": "15600.05"}, {"price": "0.002", "size": "266"}, {"price": "0.003", "size": "3598.7"}, {"price": "0.004", "size": "214.8"}], "asks": [{"price": "0.999", "size": "3869.19"}, {"price": "0.998", "size": "1250"}, {"price": "0.997", "size": "1407.34"}, {"price": "0.994", "size": "200"}, {"price": "0.993", "size": "10.78"}, {"price": "0.99", "size": "8000"}, {"price": "0.98", "size": "3900"}, {"price": "0.979", "size": "9.63"}, {"price": "0.96", "size": "1500"}, {"price": "0.95", "size": "330"}, {"price": "0.949", "size": "39"}, {"price": "0.94", "size": "375"}, {"price": "0.939", "size": "9.43"}, {"price": "0.9", "size": "560"}, {"price": "0.85", "size": "551.66"}, {"price": "0.8", "size": "410"}, {"price": "0.799", "size": "5.54"}, {"price": "0.785", "size": "1372"}, {"price": "0.75", "size": "112"}, {"price": "0.7", "size": "86.66"}, {"price": "0.65", "size": "68.57"}, {"price": "0.6", "size": "50"}, {"price": "0.582", "size": "5"}, {"price": "0.579", "size": "3887"}, {"price": "0.578", "size": "360"}, {"price": "0.577", "size": "10"}, {"price": "0.1", "size": "850"}, {"price": "0.099", "size": "1054.71"}, {"price": "0.096", "size": "10"}, {"price": "0.073", "size": "10"}, {"price": "0.072", "size": "20"}, {"price": "0.064", "size": "20"}, {"price": "0.063", "size": "25"}, {"price": "0.039", "size": "43.09"}, {"price": "0.038", "size": "118.75"}, {"price": "0.02", "size": "59.38"}, {"price": "0.005", "size": "8.2"}], "event_type": "book", "last_trade_price": "0.004"}, {"market": "0x1278f161b546f237cf9a029d9383ff5da371ff047a5adad48ee3243a6f93b6fb", "asset_id": "91844810080062648436529776287166848099843976612137997296770938567257266660379", "timestamp": "1769383981385", "hash": "ad5ad745925e28f03df596efbb546c109a9657fc", "bids": [{"price": "0.001", "size": "7581"}, {"price": "0.002", "size": "1008.62"}, {"price": "0.003", "size": "289.8"}, {"price": "0.004", "size": "12.74"}, {"price": "0.007", "size": "1129.07"}, {"price": "0.008", "size": "10.42"}, {"price": "0.01", "size": "2050"}, {"price": "0.011", "size": "3662.1"}, {"price": "0.012", "size": "6.77"}, {"price": "0.013", "size": "50"}, {"price": "0.015", "size": "1777"}, {"price": "0.018", "size": "1555"}, {"price": "0.021", "size": "2233"}, {"price": "0.022", "size": "409"}, {"price": "0.023", "size": "362"}], "asks": [{"price": "0.999", "size": "3679.08"}, {"price": "0.998", "size": "1250"}, {"price": "0.997", "size": "1407.33"}, {"price": "0.994", "size": "200"}, {"price": "0.993", "size": "10.77"}, {"price": "0.99", "size": "8300"}, {"price": "0.98", "size": "3900"}, {"price": "0.979", "size": "9.63"}, {"price": "0.96", "size": "1500"}, {"price": "0.959", "size": "250"}, {"price": "0.95", "size": "30"}, {"price": "0.949", "size": "39"}, {"price": "0.948", "size": "10"}, {"price": "0.94", "size": "375"}, {"price": "0.939", "size": "9.43"}, {"price": "0.9", "size": "560"}, {"price": "0.85", "size": "551.66"}, {"price": "0.8", "size": "410"}, {"price": "0.799", "size": "5.54"}, {"price": "0.75", "size": "262"}, {"price": "0.71", "size": "89.65"}, {"price": "0.66", "size": "70.58"}, {"price": "0.61", "size": "51.28"}, {"price": "0.545", "size": "1000"}, {"price": "0.544", "size": "4208"}, {"price": "0.537", "size": "5"}, {"price": "0.535", "size": "20"}, {"price": "0.534", "size": "25"}, {"price": "0.2", "size": "49.01"}, {"price": "0.17", "size": "155"}, {"price": "0.139", "size": "536.39"}, {"price": "0.138", "size": "10"}, {"price": "0.1", "size": "850"}, {"price": "0.099", "size": "259.84"}, {"price": "0.09", "size": "136.04"}, {"price": "0.089", "size": "210"}, {"price": "0.088", "size": "360"}, {"price": "0.087", "size": "738.25"}, {"price": "0.079", "size": "281.03"}, {"price": "0.075", "size": "242.81"}, {"price": "0.069", "size": "549.37"}, {"price": "0.065", "size": "326.46"}, {"price": "0.062", "size": "536.39"}, {"price": "0.061", "size": "123.02"}, {"price": "0.055", "size": "374.71"}, {"price": "0.052", "size": "54.15"}, {"price": "0.049", "size": "740.09"}, {"price": "0.045", "size": "404.37"}, {"price": "0.037", "size": "54.98"}, {"price": "0.035", "size": "50"}, {"price": "0.032", "size": "300"}, {"price": "0.031", "size": "298.41"}, {"price": "0.03", "size": "108.41"}, {"price": "0.029", "size": "13"}], "event_type": "book", "last_trade_price": "0.022"}, {"market": "0x3b7fa5e73b58e3e8db12f33b0888ce58c24d6249cc237581ebe11ac4867dd7b7", "asset_id": "84798712361559471793400029586324344677411006191640081141558912454287016164875", "timestamp": "1769383990573", "hash": "39ad676eee0d21b2e614a08c2f728c3779079ab6", "bids": [{"price": "0.01", "size": "6107.32"}, {"price": "0.02", "size": "12.5"}, {"price": "0.03", "size": "250"}, {"price": "0.04", "size": "6"}, {"price": "0.12", "size": "700"}, {"price": "0.13", "size": "156"}, {"price": "0.15", "size": "200"}, {"price": "0.16", "size": "6"}, {"price": "0.17", "size": "2971.62"}, {"price": "0.18", "size": "116.66"}, {"price": "0.19", "size": "77.66"}, {"price": "0.2", "size": "66.66"}], "asks": [{"price": "0.99", "size": "8390.95"}, {"price": "0.98", "size": "3900"}, {"price": "0.97", "size": "6.8"}, {"price": "0.96", "size": "1500"}, {"price": "0.95", "size": "20"}, {"price": "0.94", "size": "441"}, {"price": "0.92", "size": "650"}, {"price": "0.91", "size": "5.36"}, {"price": "0.89", "size": "125"}, {"price": "0.88", "size": "2700"}, {"price": "0.87", "size": "261.53"}, {"price": "0.86", "size": "1142"}, {"price": "0.83", "size": "188.23"}, {"price": "0.8", "size": "1050"}, {"price": "0.79", "size": "139.06"}, {"price": "0.76", "size": "1000"}, {"price": "0.74", "size": "100"}, {"price": "0.73", "size": "7"}, {"price": "0.7", "size": "3264"}, {"price": "0.69", "size": "300"}, {"price": "0.66", "size": "133.82"}, {"price": "0.34", "size": "7"}, {"price": "0.33", "size": "6"}, {"price": "0.32", "size": "700"}, {"price": "0.31", "size": "157"}, {"price": "0.3", "size": "26"}, {"price": "0.29", "size": "20"}, {"price": "0.28", "size": "7"}, {"price": "0.27", "size": "26"}, {"price": "0.26", "size": "40"}, {"price": "0.25", "size": "104.02"}, {"price": "0.24", "size": "56"}, {"price": "0.23", "size": "95.82"}, {"price": "0.22", "size": "179.52"}], "event_type": "book", "last_trade_price": "0.180"}, {"market": "0x1198b4cfb84b6078c6f432a9b034ae7d6047ca462fcee0f1895d1d94f5392bd6", "asset_id": "90632278970929861972446673124743838350086669096023265555286080414820908223619", "timestamp": "1769383978156", "hash": "a86a99dcebbf5259ca1e3b48c96e0177dd6dec73", "bids": [{"price": "0.001", "size": "3745.02"}, {"price": "0.002", "size": "1250"}, {"price": "0.003", "size": "1407.36"}, {"price": "0.006", "size": "200"}, {"price": "0.007", "size": "10.81"}, {"price": "0.01", "size": "8300"}, {"price": "0.02", "size": "3900"}, {"price": "0.021", "size": "9.66"}, {"price": "0.04", "size": "1500"}, {"price": "0.05", "size": "30"}, {"price": "0.051", "size": "39"}, {"price": "0.06", "size": "375"}, {"price": "0.061", "size": "9.45"}, {"price": "0.1", "size": "560"}, {"price": "0.15", "size": "551.66"}, {"price": "0.161", "size": "2250"}, {"price": "0.2", "size": "160"}, {"price": "0.201", "size": "5.53"}, {"price": "0.25", "size": "112"}, {"price": "0.273", "size": "7115"}, {"price": "0.274", "size": "300"}, {"price": "0.3", "size": "86.66"}, {"price": "0.301", "size": "10"}, {"price": "0.35", "size": "68.57"}, {"price": "0.4", "size": "125"}, {"price": "0.878", "size": "854.04"}, {"price": "0.91", "size": "3850"}, {"price": "0.911", "size": "128.22"}, {"price": "0.912", "size": "100"}, {"price": "0.916", "size": "10"}, {"price": "0.917", "size": "20"}, {"price": "0.945", "size": "100"}, {"price": "0.946", "size": "45"}, {"price": "0.951", "size": "6"}, {"price": "0.961", "size": "98.99"}, {"price": "0.962", "size": "6"}, {"price": "0.971", "size": "6"}, {"price": "0.972", "size": "77"}, {"price": "0.978", "size": "33"}], "asks": [{"price": "0.999", "size": "21431.91"}, {"price": "0.997", "size": "6088"}, {"price": "0.996", "size": "2636.1"}, {"price": "0.994", "size": "647"}, {"price": "0.993", "size": "58.88"}, {"price": "0.992", "size": "149.99"}], "event_type": "book", "last_trade_price": "0.008"}, {"market": "0x7af772ffd32b7726faabc964493d3e3b187186dcaea0d8e60110da9aa0771a42", "asset_id": "21959934108087357306634929435608062329442380143600039127574312668523401447958", "timestamp": "1769383993145", "hash": "b7c4c5c2a7ac18a6f00e091446ede52fb12427b8", "bids": [{"price": "0.001", "size": "20250.99"}, {"price": "0.002", "size": "5765.89"}, {"price": "0.003", "size": "1917.84"}, {"price": "0.004", "size": "119.15"}, {"price": "0.005", "size": "16"}, {"price": "0.006", "size": "14.68"}, {"price": "0.008", "size": "380"}, {"price": "0.009", "size": "257.66"}, {"price": "0.01", "size": "6"}, {"price": "0.011", "size": "6.02"}, {"price": "0.022", "size": "0.38"}], "asks": [{"price": "0.999", "size": "3907.28"}, {"price": "0.998", "size": "1250"}, {"price": "0.997", "size": "1407.35"}, {"price": "0.994", "size": "200"}, {"price": "0.993", "size": "10.8"}, {"price": "0.99", "size": "8300"}, {"price": "0.98", "size": "3900"}, {"price": "0.979", "size": "9.66"}, {"price": "0.96", "size": "1500"}, {"price": "0.95", "size": "30"}, {"price": "0.949", "size": "39"}, {"price": "0.94", "size": "375"}, {"price": "0.939", "size": "9.45"}, {"price": "0.9", "size": "560"}, {"price": "0.85", "size": "551.66"}, {"price": "0.8", "size": "410"}, {"price": "0.799", "size": "5.53"}, {"price": "0.779", "size": "1322"}, {"price": "0.75", "size": "112"}, {"price": "0.7", "size": "86.66"}, {"price": "0.69", "size": "6"}, {"price": "0.688", "size": "6147"}, {"price": "0.687", "size": "300"}, {"price": "0.65", "size": "68.57"}, {"price": "0.6", "size": "125"}, {"price": "0.597", "size": "10"}, {"price": "0.596", "size": "10"}, {"price": "0.09", "size": "3850"}, {"price": "0.089", "size": "6"}, {"price": "0.086", "size": "6"}, {"price": "0.085", "size": "10"}, {"price": "0.083", "size": "25"}, {"price": "0.082", "size": "20"}, {"price": "0.081", "size": "20"}, {"price": "0.07", "size": "6"}, {"price": "0.055", "size": "300"}, {"price": "0.05", "size": "20"}, {"price": "0.047", "size": "37"}, {"price": "0.046", "size": "148.75"}, {"price": "0.045", "size": "50"}], "event_type": "book", "last_trade_price": "0.023"}, {"market": "0xa1f25c89068b04aee1d436a1007070ca2037fd25d93d1040351c140a8a91d076", "asset_id": "13121373823796973338446309203577015676646957310329888618967056669196081566471", "timestamp": "1769383992948", "hash": "b68ed7179a12fb232a346e6f229af737bd475cff", "bids": [{"price": "0.001", "size": "5580"}, {"price": "0.002", "size": "250"}, {"price": "0.003", "size": "37.38"}, {"price": "0.01", "size": "2640.3"}, {"price": "0.012", "size": "1167.39"}, {"price": "0.015", "size": "2110"}, {"price": "0.016", "size": "8.61"}, {"price": "0.023", "size": "758.19"}, {"price": "0.029", "size": "1688.25"}, {"price": "0.035", "size": "1142.49"}, {"price": "0.036", "size": "273.5"}], "asks": [{"price": "0.999", "size": "3690.09"}, {"price": "0.998", "size": "1250"}, {"price": "0.997", "size": "1407.34"}, {"price": "0.994", "size": "200"}, {"price": "0.993", "size": "10.78"}, {"price": "0.99", "size": "8000"}, {"price": "0.98", "size": "3900"}, {"price": "0.979", "size": "11.68"}, {"price": "0.96", "size": "1500"}, {"price": "0.95", "size": "30"}, {"price": "0.949", "size": "39"}, {"price": "0.94", "size": "375"}, {"price": "0.932", "size": "4500"}, {"price": "0.931", "size": "250"}, {"price": "0.93", "size": "7.1"}, {"price": "0.9", "size": "360"}, {"price": "0.86", "size": "567.85"}, {"price": "0.81", "size": "418.42"}, {"price": "0.809", "size": "6.01"}, {"price": "0.808", "size": "10"}, {"price": "0.76", "size": "266.66"}, {"price": "0.757", "size": "8"}, {"price": "0.71", "size": "89.65"}, {"price": "0.66", "size": "70.58"}, {"price": "0.659", "size": "20"}, {"price": "0.62", "size": "127.63"}, {"price": "0.619", "size": "25"}, {"price": "0.12", "size": "3860"}, {"price": "0.116", "size": "10"}, {"price": "0.115", "size": "20"}, {"price": "0.098", "size": "82.45"}, {"price": "0.074", "size": "451.19"}, {"price": "0.062", "size": "184.83"}, {"price": "0.06", "size": "2000"}, {"price": "0.058", "size": "80"}, {"price": "0.057", "size": "159.82"}, {"price": "0.056", "size": "50"}, {"price": "0.048", "size": "18.3"}, {"price": "0.047", "size": "16.7"}], "event_type": "book", "last_trade_price": "0.961"}, {"market": "0xa1f25c89068b04aee1d436a1007070ca2037fd25d93d1040351c140a8a91d076", "asset_id": "93336408690807793579464128885533576538481371309320986000405780693674239617931", "timestamp": "1769383992948", "hash": "138d362c3cb7a71aed621bd18598c267da946326", "bids": [{"price": "0.001", "size": "3690.09"}, {"price": "0.002", "size": "1250"}, {"price": "0.003", "size": "1407.34"}, {"price": "0.006", "size": "200"}, {"price": "0.007", "size": "10.78"}, {"price": "0.01", "size": "8000"}, {"price": "0.02", "size": "3900"}, {"price": "0.021", "size": "11.68"}, {"price": "0.04", "size": "1500"}, {"price": "0.05", "size": "30"}, {"price": "0.051", "size": "39"}, {"price": "0.06", "size": "375"}, {"price": "0.068", "size": "4500"}, {"price": "0.069", "size": "250"}, {"price": "0.07", "size": "7.1"}, {"price": "0.1", "size": "360"}, {"price": "0.14", "size": "567.85"}, {"price": "0.19", "size": "418.42"}, {"price": "0.191", "size": "6.01"}, {"price": "0.192", "size": "10"}, {"price": "0.24", "size": "266.66"}, {"price": "0.243", "size": "8"}, {"price": "0.29", "size": "89.65"}, {"price": "0.34", "size": "70.58"}, {"price": "0.341", "size": "20"}, {"price": "0.38", "size": "127.63"}, {"price": "0.381", "size": "25"}, {"price": "0.88", "size": "3860"}, {"price": "0.884", "size": "10"}, {"price": "0.885", "size": "20"}, {"price": "0.902", "size": "82.45"}, {"price": "0.926", "size": "451.19"}, {"price": "0.938", "size": "184.83"}, {"price": "0.94", "size": "2000"}, {"price": "0.942", "size": "80"}, {"price": "0.943", "size": "159.82"}, {"price": "0.944", "size": "50"}, {"price": "0.952", "size": "18.3"}, {"price": "0.953", "size": "16.7"}], "asks": [{"price": "0.999", "size": "5580"}, {"price": "0.998", "size": "250"}, {"price": "0.997", "size": "37.38"}, {"price": "0.99", "size": "2640.3"}, {"price": "0.988", "size": "1167.39"}, {"price": "0.985", "size": "2110"}, {"price": "0.984", "size": "8.61"}, {"price": "0.977", "size": "758.19"}, {"price": "0.971", "size": "1688.25"}, {"price": "0.965", "size": "1142.49"}, {"price": "0.964", "size": "273.5"}], "event_type": "book", "last_trade_price": "0.961"}]}
{"_local_timestamp": "2026-01-25T23:33:20.915615+00:00", "data": {"market": "0xa1f25c89068b04aee1d436a1007070ca2037fd25d93d1040351c140a8a91d076", "price_changes": [{"asset_id": "13121373823796973338446309203577015676646957310329888618967056669196081566471", "price": "0.01", "size": "2240.3", "side": "BUY", "hash": "502b5e7fc2144aef5f0460bf217c78052369aadd", "best_bid": "0.036", "best_ask": "0.047"}, {"asset_id": "93336408690807793579464128885533576538481371309320986000405780693674239617931", "price": "0.99", "size": "2240.3", "side": "SELL", "hash": "a43407a6042eb0dbe22888a130dd5ceb312ffb78", "best_bid": "0.953", "best_ask": "0.964"}], "timestamp": "1769384000837", "event_type": "price_change"}}
{"_local_timestamp": "2026-01-25T23:33:20.957524+00:00", "data": {"market": "0xa1f25c89068b04aee1d436a1007070ca2037fd25d93d1040351c140a8a91d076", "price_changes": [{"asset_id": "13121373823796973338446309203577015676646957310329888618967056669196081566471", "price": "0.02", "size": "100", "side": "BUY", "hash": "741ac547395d44fd0381336c3d072ae29cfd5468", "best_bid": "0.036", "best_ask": "0.047"}, {"asset_id": "93336408690807793579464128885533576538481371309320986000405780693674239617931", "price": "0.98", "size": "100", "side": "SELL", "hash": "2029b7089d1185cc03c81eabb9876aeeacb06875", "best_bid": "0.953", "best_ask": "0.964"}], "timestamp": "1769384000890", "event_type": "price_change"}}
{"_local_timestamp": "2026-01-25T23:33:22.177773+00:00", "data": {"market": "0x1198b4cfb84b6078c6f432a9b034ae7d6047ca462fcee0f1895d1d94f5392bd6", "price_changes": [{"asset_id": "48633487062848646741583673336029083373164703684898528527193929763953273671096", "price": "0.006", "size": "148", "side": "BUY", "hash": "44d3da2b325b1e5380eec91806e8de0f593d6aa9", "best_bid": "0.008", "best_ask": "0.022"}, {"asset_id": "90632278970929861972446673124743838350086669096023265555286080414820908223619", "price": "0.994", "size": "148", "side": "SELL", "hash": "485a1ca5fd5bcc0344278260f37af4ce421261d8", "best_bid": "0.978", "best_ask": "0.992"}], "timestamp": "1769384002110", "event_type": "price_change"}}
{"_local_timestamp": "2026-01-25T23:33:22.293282+00:00", "data": {"market": "0x1198b4cfb84b6078c6f432a9b034ae7d6047ca462fcee0f1895d1d94f5392bd6", "price_changes": [{"asset_id": "48633487062848646741583673336029083373164703684898528527193929763953273671096", "price": "0.008", "size": "523.99", "side": "BUY", "hash": "ef99139f1dd6c720300183ecf48fee02f87713b4", "best_bid": "0.008", "best_ask": "0.022"}, {"asset_id": "90632278970929861972446673124743838350086669096023265555286080414820908223619", "price": "0.992", "size": "523.99", "side": "SELL", "hash": "80fd56fe0636534d1aea1eae8f1d2d925d7498bc", "best_bid": "0.978", "best_ask": "0.992"}], "timestamp": "1769384002225", "event_type": "price_change"}}
{"_local_timestamp": "2026-01-25T23:33:33.463019+00:00", "data": {"market": "0xa1f25c89068b04aee1d436a1007070ca2037fd25d93d1040351c140a8a91d076", "price_changes": [{"asset_id": "13121373823796973338446309203577015676646957310329888618967056669196081566471", "price": "0.02", "size": "0", "side": "BUY", "hash": "b9681eefecf29488eb4eb21b49e9ebdb3be2fd77", "best_bid": "0.036", "best_ask": "0.047"}, {"asset_id": "93336408690807793579464128885533576538481371309320986000405780693674239617931", "price": "0.98", "size": "0", "side": "SELL", "hash": "7075656ec58edea1c9c2c20dd94c10640e0fbf2f", "best_bid": "0.953", "best_ask": "0.964"}], "timestamp": "1769384013288", "event_type": "price_change"}}
{"_local_timestamp": "2026-01-25T23:33:33.472130+00:00", "data": {"market": "0xa1f25c89068b04aee1d436a1007070ca2037fd25d93d1040351c140a8a91d076", "price_changes": [{"asset_id": "93336408690807793579464128885533576538481371309320986000405780693674239617931", "price": "0.94", "size": "0", "side": "BUY", "hash": "f72eb3b31da07cee22c5fd2db87441a309483ef0", "best_bid": "0.953", "best_ask": "0.964"}, {"asset_id": "13121373823796973338446309203577015676646957310329888618967056669196081566471", "price": "0.06", "size": "0", "side": "SELL", "hash": "197a273eee6d4c7d7c2509f21511e818deae4b0e", "best_bid": "0.036", "best_ask": "0.047"}], "timestamp": "1769384013288", "event_type": "price_change"}}
{"_local_timestamp": "2026-01-25T23:33:33.473785+00:00", "data": {"market": "0xa1f25c89068b04aee1d436a1007070ca2037fd25d93d1040351c140a8a91d076", "price_changes": [{"asset_id": "13121373823796973338446309203577015676646957310329888618967056669196081566471", "price": "0.01", "size": "2640.3", "side": "BUY", "hash": "976cdd377cc3da71e8e90296e65f92d0e87fa3b0", "best_bid": "0.036", "best_ask": "0.047"}, {"asset_id": "93336408690807793579464128885533576538481371309320986000405780693674239617931", "price": "0.99", "size": "2640.3", "side": "SELL", "hash": "8e9d8fba6b4398dbf2b00fd9ccc6db0d687d7f5c", "best_bid": "0.953", "best_ask": "0.964"}], "timestamp": "1769384013298", "event_type": "price_change"}}
{"_local_timestamp": "2026-01-25T23:33:33.474158+00:00", "data": {"market": "0xa1f25c89068b04aee1d436a1007070ca2037fd25d93d1040351c140a8a91d076", "price_changes": [{"asset_id": "93336408690807793579464128885533576538481371309320986000405780693674239617931", "price": "0.94", "size": "1000", "side": "BUY", "hash": "2c782b3c2ced81d2b9597f9705386a502c0bef19", "best_bid": "0.953", "best_ask": "0.964"}, {"asset_id": "13121373823796973338446309203577015676646957310329888618967056669196081566471", "price": "0.06", "size": "1000", "side": "SELL", "hash": "a3d739e631809ff4364c0c103aabbbc8f4682210", "best_bid": "0.036", "best_ask": "0.047"}], "timestamp": "1769384013299", "event_type": "price_change"}}
{"_local_timestamp": "2026-01-25T23:33:40.113773+00:00", "data": {"market": "0x3b7fa5e73b58e3e8db12f33b0888ce58c24d6249cc237581ebe11ac4867dd7b7", "price_changes": [{"asset_id": "2058086706657815889669487757317075047972583222463683616694793460955010144892", "price": "0.22", "size": "1908", "side": "BUY", "hash": "3de8a836235f261b53592a89bde151ab43f79951", "best_bid": "0.78", "best_ask": "0.8"}, {"asset_id": "84798712361559471793400029586324344677411006191640081141558912454287016164875", "price": "0.78", "size": "1908", "side": "SELL", "hash": "05dcb26af0d77567be8e532994f687a7610b6e15", "best_bid": "0.2", "best_ask": "0.22"}], "timestamp": "1769384020007", "event_type": "price_change"}}
{"_local_timestamp": "2026-01-25T23:33:40.355541+00:00", "data": {"market": "0x3b7fa5e73b58e3e8db12f33b0888ce58c24d6249cc237581ebe11ac4867dd7b7", "price_changes": [{"asset_id": "2058086706657815889669487757317075047972583222463683616694793460955010144892", "price": "0.11", "size": "0", "side": "BUY", "hash": "059d620f3a6c06774f952b9b65194d2b17364a7b", "best_bid": "0.78", "best_ask": "0.8"}, {"asset_id": "84798712361559471793400029586324344677411006191640081141558912454287016164875", "price": "0.89", "size": "0", "side": "SELL", "hash": "908b50737978fefcb1e0c1ade026a7eac5dd6f99", "best_bid": "0.2", "best_ask": "0.22"}], "timestamp": "1769384020105", "event_type": "price_change"}}
{"_local_timestamp": "2026-01-25T23:33:40.461306+00:00", "data": {"market": "0xb7427b891a0134371023603986edc842ce369e83dcc42f300e7a03049295d4b1", "price_changes": [{"asset_id": "79849296060580317277275866407031080149422127632028665473147696931641259289529", "price": "0.228", "size": "25", "side": "BUY", "hash": "3ba96d03358f2cc29dcdd4d958e1e54286c12607", "best_bid": "0.287", "best_ask": "0.306"}, {"asset_id": "109919329920505980115727737237456054640803613381042045664921404844196255236880", "price": "0.772", "size": "25", "side": "SELL", "hash": "c51c517040b20dfc7ed002dec74cc34c6e4b0ff9", "best_bid": "0.694", "best_ask": "0.713"}], "timestamp": "1769384020337", "event_type": "price_change"}}
{"_local_timestamp": "2026-01-25T23:33:40.538826+00:00", "data": {"market": "0xb7427b891a0134371023603986edc842ce369e83dcc42f300e7a03049295d4b1", "price_changes": [{"asset_id": "79849296060580317277275866407031080149422127632028665473147696931641259289529", "price": "0.072", "size": "25", "side": "BUY", "hash": "f064f68093cf837506060a7169ed1d65cf09ff38", "best_bid": "0.287", "best_ask": "0.306"}, {"asset_id": "109919329920505980115727737237456054640803613381042045664921404844196255236880", "price": "0.928", "size": "25", "side": "SELL", "hash": "097a8ef77514958db50df9568649d63cef2df5dc", "best_bid": "0.694", "best_ask": "0.713"}], "timestamp": "1769384020467", "event_type": "price_change"}}
{"_local_timestamp": "2026-01-25T23:33:40.609068+00:00", "data": {"market": "0x3b7fa5e73b58e3e8db12f33b0888ce58c24d6249cc237581ebe11ac4867dd7b7", "price_changes": [{"asset_id": "2058086706657815889669487757317075047972583222463683616694793460955010144892", "price": "0.12", "size": "2825", "side": "BUY", "hash": "f650bafed706f0f1e1d94868f9aca4c8a16adaba", "best_bid": "0.78", "best_ask": "0.8"}, {"asset_id": "84798712361559471793400029586324344677411006191640081141558912454287016164875", "price": "0.88", "size": "2825", "side": "SELL", "hash": "865cf8eb48e97777576996fd34f1ec1e792f05d3", "best_bid": "0.2", "best_ask": "0.22"}], "timestamp": "1769384020523", "event_type": "price_change"}}
{"_local_timestamp": "2026-01-25T23:33:43.186238+00:00", "data": {"market": "0xd94cb5bf446cb8142d22091a40ba14d8c7355bd06fda75e61e25207135348550", "price_changes": [{"asset_id": "73232075333787574101356206392441747050603477997678734507064104196778724283091", "price": "0.05", "size": "3330", "side": "BUY", "hash": "00bf7dc4349e67011eaf85a44d7b6d61a77695bb", "best_bid": "0.995", "best_ask": "0.996"}, {"asset_id": "58192906727610480118792319554990896451617120222517723334233116219918933677749", "price": "0.95", "size": "3330", "side": "SELL", "hash": "23a559443d38123df293898a3f219ccfdffbe469", "best_bid": "0.004", "best_ask": "0.005"}], "timestamp": "1769384023117", "event_type": "price_change"}}
{"_local_timestamp": "2026-01-25T23:33:43.568126+00:00", "data": {"market": "0x7e897a7826222708d178062c82e9166b37a98df0ce92ace40f3b9357f2526157", "price_changes": [{"asset_id": "8417326734150529989790022001226615602996938938967740280020227231905495513816", "price": "0.35", "size": "768.57", "side": "BUY", "hash": "22eb0d36ab343321d61cdbf01d68bd23e507a386", "best_bid": "0.987", "best_ask": "0.99"}, {"asset_id": "85126848831263873777721669142266306730253139367446060083090258474801299057771", "price": "0.65", "size": "768.57", "side": "SELL", "hash": "28f01c057b3ca708dd268275aac46bd0125ce96f", "best_bid": "0.01", "best_ask": "0.013"}], "timestamp": "1769384023493", "event_type": "price_change"}}
{"_local_timestamp": "2026-01-25T23:33:43.568754+00:00", "data": {"market": "0x7e897a7826222708d178062c82e9166b37a98df0ce92ace40f3b9357f2526157", "price_changes": [{"asset_id": "8417326734150529989790022001226615602996938938967740280020227231905495513816", "price": "0.05", "size": "3330", "side": "BUY", "hash": "cfafb65f7fd9ef2f8fe5a79f3b345c3ec01f4854", "best_bid": "0.987", "best_ask": "0.99"}, {"asset_id": "85126848831263873777721669142266306730253139367446060083090258474801299057771", "price": "0.95", "size": "3330", "side": "SELL", "hash": "4ae7256420b2f43f7ca0ff4e0553714570555670", "best_bid": "0.01", "best_ask": "0.013"}], "timestamp": "1769384023494", "event_type": "price_change"}}
{"_local_timestamp": "2026-01-25T23:33:43.633326+00:00", "data": {"market": "0xa1f25c89068b04aee1d436a1007070ca2037fd25d93d1040351c140a8a91d076", "price_changes": [{"asset_id": "93336408690807793579464128885533576538481371309320986000405780693674239617931", "price": "0.884", "size": "0", "side": "BUY", "hash": "640b84ff371c14a5fdbd6de9456f4180098b7d91", "best_bid": "0.953", "best_ask": "0.964"}, {"asset_id": "13121373823796973338446309203577015676646957310329888618967056669196081566471", "price": "0.116", "size": "0", "side": "SELL", "hash": "192f9447b439fa8f26a299d66f4ad08664cc126b", "best_bid": "0.036", "best_ask": "0.047"}], "timestamp": "1769384023565", "event_type": "price_change"}}
{"_local_timestamp": "2026-01-25T23:33:46.118374+00:00", "data": {"market": "0xa1f25c89068b04aee1d436a1007070ca2037fd25d93d1040351c140a8a91d076", "price_changes": [{"asset_id": "93336408690807793579464128885533576538481371309320986000405780693674239617931", "price": "0.885", "size": "0", "side": "BUY", "hash": "b64d10e684146994d531b52af071ad3c6eba6204", "best_bid": "0.953", "best_ask": "0.964"}, {"asset_id": "13121373823796973338446309203577015676646957310329888618967056669196081566471", "price": "0.115", "size": "0", "side": "SELL", "hash": "fefdb61aeb2680b7c220f6c5772a02f59fa50ca0", "best_bid": "0.036", "best_ask": "0.047"}], "timestamp": "1769384026020", "event_type": "price_change"}}
{"_local_timestamp": "2026-01-25T23:33:46.135533+00:00", "data": {"market": "0xa1f25c89068b04aee1d436a1007070ca2037fd25d93d1040351c140a8a91d076", "price_changes": [{"asset_id": "93336408690807793579464128885533576538481371309320986000405780693674239617931", "price": "0.881", "size": "20", "side": "BUY", "hash": "6638c922181a8ad39e996b7ef49d82052c8df1bf", "best_bid": "0.953", "best_ask": "0.964"}, {"asset_id": "13121373823796973338446309203577015676646957310329888618967056669196081566471", "price": "0.119", "size": "20", "side": "SELL", "hash": "c8670d15161da315f67db6d6d4b4c839ca298f63", "best_bid": "0.036", "best_ask": "0.047"}], "timestamp": "1769384026062", "event_type": "price_change"}}
{"_local_timestamp": "2026-01-25T23:33:47.527209+00:00", "data": {"market": "0x3b7fa5e73b58e3e8db12f33b0888ce58c24d6249cc237581ebe11ac4867dd7b7", "price_changes": [{"asset_id": "2058086706657815889669487757317075047972583222463683616694793460955010144892", "price": "0.11", "size": "3000", "side": "BUY", "hash": "d01a2090922100b82c7ca4661df4a725ac42c2fb", "best_bid": "0.78", "best_ask": "0.8"}, {"asset_id": "84798712361559471793400029586324344677411006191640081141558912454287016164875", "price": "0.89", "size": "3000", "side": "SELL", "hash": "8bbbcc2044615e59ac40acac3117dae59b175067", "best_bid": "0.2", "best_ask": "0.22"}], "timestamp": "1769384027452", "event_type": "price_change"}}
{"_local_timestamp": "2026-01-25T23:33:47.721681+00:00", "data": {"market": "0xd94cb5bf446cb8142d22091a40ba14d8c7355bd06fda75e61e25207135348550", "price_changes": [{"asset_id": "73232075333787574101356206392441747050603477997678734507064104196778724283091", "price": "0.904", "size": "0", "side": "BUY", "hash": "b2fbf89bc8e2802a67264a1065850ee072b4de23", "best_bid": "0.995", "best_ask": "0.996"}, {"asset_id": "58192906727610480118792319554990896451617120222517723334233116219918933677749", "price": "0.096", "size": "0", "side": "SELL", "hash": "534e069187f68219e1876b010bc1f16589122db7", "best_bid": "0.004", "best_ask": "0.005"}], "timestamp": "1769384027647", "event_type": "price_change"}}
{"_local_timestamp": "2026-01-25T23:33:48.502963+00:00", "data": {"market": "0x7e897a7826222708d178062c82e9166b37a98df0ce92ace40f3b9357f2526157", "price_changes": [{"asset_id": "8417326734150529989790022001226615602996938938967740280020227231905495513816", "price": "0.05", "size": "330", "side": "BUY", "hash": "822c052dd3f68fcb068176bd47f96dd3d21d93bb", "best_bid": "0.987", "best_ask": "0.99"}, {"asset_id": "85126848831263873777721669142266306730253139367446060083090258474801299057771", "price": "0.95", "size": "330", "side": "SELL", "hash": "634c877eaf140534db7c6c550c2846d89ef81383", "best_bid": "0.01", "best_ask": "0.013"}], "timestamp": "1769384028428", "event_type": "price_change"}}
{"_local_timestamp": "2026-01-25T23:33:48.516546+00:00", "data": {"market": "0x7e897a7826222708d178062c82e9166b37a98df0ce92ace40f3b9357f2526157", "price_changes": [{"asset_id": "8417326734150529989790022001226615602996938938967740280020227231905495513816", "price": "0.35", "size": "68.57", "side": "BUY", "hash": "822c052dd3f68fcb068176bd47f96dd3d21d93bb", "best_bid": "0.987", "best_ask": "0.99"}, {"asset_id": "85126848831263873777721669142266306730253139367446060083090258474801299057771", "price": "0.65", "size": "68.57", "side": "SELL", "hash": "634c877eaf140534db7c6c550c2846d89ef81383", "best_bid": "0.01", "best_ask": "0.013"}], "timestamp": "1769384028428", "event_type": "price_change"}}
{"_local_timestamp": "2026-01-25T23:33:48.602365+00:00", "data": {"market": "0x1278f161b546f237cf9a029d9383ff5da371ff047a5adad48ee3243a6f93b6fb", "price_changes": [{"asset_id": "83477010551081586181287014200977553131804751829676583771272159234562620010416", "price": "0.052", "size": "0", "side": "BUY", "hash": "58a7c2fb897ebc6ac3777f99711f548c0ef167fe", "best_bid": "0.971", "best_ask": "0.977"}, {"asset_id": "91844810080062648436529776287166848099843976612137997296770938567257266660379", "price": "0.948", "size": "0", "side": "SELL", "hash": "cbc359f09fb6835a26612a1d213c9532fb51af83", "best_bid": "0.023", "best_ask": "0.029"}], "timestamp": "1769384028525", "event_type": "price_change"}}
{"_local_timestamp": "2026-01-25T23:33:48.715139+00:00", "data": {"market": "0x1278f161b546f237cf9a029d9383ff5da371ff047a5adad48ee3243a6f93b6fb", "price_changes": [{"asset_id": "83477010551081586181287014200977553131804751829676583771272159234562620010416", "price": "0.101", "size": "10", "side": "BUY", "hash": "c6c653479aaa77cb22d52f4cf8df51151283a37a", "best_bid": "0.971", "best_ask": "0.977"}, {"asset_id": "91844810080062648436529776287166848099843976612137997296770938567257266660379", "price": "0.899", "size": "10", "side": "SELL", "hash": "1309d6846138bcf9e09b5eaac99b95337ee3ea43", "best_bid": "0.023", "best_ask": "0.029"}], "timestamp": "1769384028642", "event_type": "price_change"}}
{"_local_timestamp": "2026-01-25T23:33:48.739074+00:00", "data": {"market": "0xd94cb5bf446cb8142d22091a40ba14d8c7355bd06fda75e61e25207135348550", "price_changes": [{"asset_id": "73232075333787574101356206392441747050603477997678734507064104196778724283091", "price": "0.927", "size": "0", "side": "BUY", "hash": "72fc5e4f6c45914021ef93fb017ed1b9f6242288", "best_bid": "0.995", "best_ask": "0.996"}, {"asset_id": "58192906727610480118792319554990896451617120222517723334233116219918933677749", "price": "0.073", "size": "0", "side": "SELL", "hash": "418b9a5c8561139b1cfba2be237222b24d7ab4be", "best_bid": "0.004", "best_ask": "0.005"}], "timestamp": "1769384028668", "event_type": "price_change"}}
{"_local_timestamp": "2026-01-25T23:33:48.855224+00:00", "data": {"market": "0xd94cb5bf446cb8142d22091a40ba14d8c7355bd06fda75e61e25207135348550", "price_changes": [{"asset_id": "73232075333787574101356206392441747050603477997678734507064104196778724283091", "price": "0.929", "size": "10", "side": "BUY", "hash": "74493c04cde22cdea6dfeb000613f9e83ed3d4ca", "best_bid": "0.995", "best_ask": "0.996"}, {"asset_id": "58192906727610480118792319554990896451617120222517723334233116219918933677749", "price": "0.071", "size": "10", "side": "SELL", "hash": "1bbb332da8a62c75c3458ecac7db7ef7fa737cac", "best_bid": "0.004", "best_ask": "0.005"}], "timestamp": "1769384028786", "event_type": "price_change"}}
{"_local_timestamp": "2026-01-25T23:33:48.859825+00:00", "data": {"market": "0xd94cb5bf446cb8142d22091a40ba14d8c7355bd06fda75e61e25207135348550", "price_changes": [{"asset_id": "73232075333787574101356206392441747050603477997678734507064104196778724283091", "price": "0.902", "size": "10", "side": "BUY", "hash": "88384355ee215b4e780cef86858efb2e21734d9c", "best_bid": "0.995", "best_ask": "0.996"}, {"asset_id": "58192906727610480118792319554990896451617120222517723334233116219918933677749", "price": "0.098", "size": "10", "side": "SELL", "hash": "b417becabc4bf3ca299bbfaee25633b2ffe44308", "best_bid": "0.004", "best_ask": "0.005"}], "timestamp": "1769384028787", "event_type": "price_change"}}
{"_local_timestamp": "2026-01-25T23:33:49.189340+00:00", "data": {"market": "0xd94cb5bf446cb8142d22091a40ba14d8c7355bd06fda75e61e25207135348550", "price_changes": [{"asset_id": "73232075333787574101356206392441747050603477997678734507064104196778724283091", "price": "0.928", "size": "0", "side": "BUY", "hash": "9c97ee94eeeea799c0ad7d9b5544fde6a3300f31", "best_bid": "0.995", "best_ask": "0.996"}, {"asset_id": "58192906727610480118792319554990896451617120222517723334233116219918933677749", "price": "0.072", "size": "0", "side": "SELL", "hash": "53b6265c79cce81eeec251b2c5fe6749d80cb74e", "best_bid": "0.004", "best_ask": "0.005"}], "timestamp": "1769384029124", "event_type": "price_change"}}
{"_local_timestamp": "2026-01-25T23:33:49.219081+00:00", "data": {"market": "0x7e897a7826222708d178062c82e9166b37a98df0ce92ace40f3b9357f2526157", "price_changes": [{"asset_id": "85126848831263873777721669142266306730253139367446060083090258474801299057771", "price": "0.003", "size": "6555", "side": "BUY", "hash": "1ac310157764c014785fbc457b296ab0f9644635", "best_bid": "0.01", "best_ask": "0.013"}, {"asset_id": "8417326734150529989790022001226615602996938938967740280020227231905495513816", "price": "0.997", "size": "6555", "side": "SELL", "hash": "ad34ee03ac78c0a4fb6e71d6ecaf2bad937185e5", "best_bid": "0.987", "best_ask": "0.99"}], "timestamp": "1769384029147", "event_type": "price_change"}}
{"_local_timestamp": "2026-01-25T23:33:49.219449+00:00", "data": {"market": "0xd94cb5bf446cb8142d22091a40ba14d8c7355bd06fda75e61e25207135348550", "price_changes": [{"asset_id": "73232075333787574101356206392441747050603477997678734507064104196778724283091", "price": "0.93", "size": "20", "side": "BUY", "hash": "d7541cd39d03b516b80d121e3b6d4a6545461ba0", "best_bid": "0.995", "best_ask": "0.996"}, {"asset_id": "58192906727610480118792319554990896451617120222517723334233116219918933677749", "price": "0.07", "size": "20", "side": "SELL", "hash": "7f178ef997fca54b4f3910ef0bc9766ec6b6bbee", "best_bid": "0.004", "best_ask": "0.005"}], "timestamp": "1769384029149", "event_type": "price_change"}}
{"_local_timestamp": "2026-01-25T23:33:54.081256+00:00", "data": {"market": "0xb7427b891a0134371023603986edc842ce369e83dcc42f300e7a03049295d4b1", "price_changes": [{"asset_id": "79849296060580317277275866407031080149422127632028665473147696931641259289529", "price": "0.317", "size": "15.9", "side": "SELL", "hash": "8315bdeb81e235eb644a0576f8baebb76f590375", "best_bid": "0.287", "best_ask": "0.306"}, {"asset_id": "109919329920505980115727737237456054640803613381042045664921404844196255236880", "price": "0.683", "size": "15.9", "side": "BUY", "hash": "a73d5cac65b27b382c710cfa1987d1c41345250a", "best_bid": "0.694", "best_ask": "0.713"}], "timestamp": "1769384034000", "event_type": "price_change"}}
{"_local_timestamp": "2026-01-25T23:33:54.232655+00:00", "data": {"market": "0x1278f161b546f237cf9a029d9383ff5da371ff047a5adad48ee3243a6f93b6fb", "price_changes": [{"asset_id": "83477010551081586181287014200977553131804751829676583771272159234562620010416", "price": "0.101", "size": "0", "side": "BUY", "hash": "5bb3ca8d40f474908b13b019c5c467bb5a5cabc4", "best_bid": "0.971", "best_ask": "0.977"}, {"asset_id": "91844810080062648436529776287166848099843976612137997296770938567257266660379", "price": "0.899", "size": "0", "side": "SELL", "hash": "41e0b067b268f0de01d248ab3ccc225d4bda534a", "best_bid": "0.023", "best_ask": "0.029"}], "timestamp": "1769384034141", "event_type": "price_change"}}
{"_local_timestamp": "2026-01-25T23:33:54.415269+00:00", "data": {"market": "0x1278f161b546f237cf9a029d9383ff5da371ff047a5adad48ee3243a6f93b6fb", "price_changes": [{"asset_id": "83477010551081586181287014200977553131804751829676583771272159234562620010416", "price": "0.062", "size": "10", "side": "BUY", "hash": "46613c3afb21da773c093cf0467bc1ebfb6d808f", "best_bid": "0.971", "best_ask": "0.977"}, {"asset_id": "91844810080062648436529776287166848099843976612137997296770938567257266660379", "price": "0.938", "size": "10", "side": "SELL", "hash": "320c9315d4e334c897947886bb41f7d11f32e67e", "best_bid": "0.023", "best_ask": "0.029"}], "timestamp": "1769384034346", "event_type": "price_change"}}
{"_local_timestamp": "2026-01-25T23:33:54.523544+00:00", "data": {"market": "0x1198b4cfb84b6078c6f432a9b034ae7d6047ca462fcee0f1895d1d94f5392bd6", "price_changes": [{"asset_id": "90632278970929861972446673124743838350086669096023265555286080414820908223619", "price": "0.916", "size": "0", "side": "BUY", "hash": "0f34753cea74ca8e438990dd0119267e3a09a25c", "best_bid": "0.978", "best_ask": "0.992"}, {"asset_id": "48633487062848646741583673336029083373164703684898528527193929763953273671096", "price": "0.084", "size": "0", "side": "SELL", "hash": "c0c59a8d6b10137f0923b545bb3376a9ac672962", "best_bid": "0.008", "best_ask": "0.022"}], "timestamp": "1769384034454", "event_type": "price_change"}}
{"_local_timestamp": "2026-01-25T23:33:54.587930+00:00", "data": {"market": "0x1198b4cfb84b6078c6f432a9b034ae7d6047ca462fcee0f1895d1d94f5392bd6", "price_changes": [{"asset_id": "90632278970929861972446673124743838350086669096023265555286080414820908223619", "price": "0.918", "size": "10", "side": "BUY", "hash": "35de594b8884f87ab6260667174e6bd07f62e279", "best_bid": "0.978", "best_ask": "0.992"}, {"asset_id": "48633487062848646741583673336029083373164703684898528527193929763953273671096", "price": "0.082", "size": "10", "side": "SELL", "hash": "6542eb872e91465099d9ba303901f2397847617d", "best_bid": "0.008", "best_ask": "0.022"}], "timestamp": "1769384034496", "event_type": "price_change"}}
{"_local_timestamp": "2026-01-25T23:33:54.589313+00:00", "data": {"market": "0x1198b4cfb84b6078c6f432a9b034ae7d6047ca462fcee0f1895d1d94f5392bd6", "price_changes": [{"asset_id": "90632278970929861972446673124743838350086669096023265555286080414820908223619", "price": "0.911", "size": "138.22", "side": "BUY", "hash": "528f081bc07f957de588f9d62e211b86d995a316", "best_bid": "0.978", "best_ask": "0.992"}, {"asset_id": "48633487062848646741583673336029083373164703684898528527193929763953273671096", "price": "0.089", "size": "138.22", "side": "SELL", "hash": "2e8828146c6c7e81b99c9e838242a2f8d0054f1e", "best_bid": "0.008", "best_ask": "0.022"}], "timestamp": "1769384034497", "event_type": "price_change"}}
{"_local_timestamp": "2026-01-25T23:33:55.297066+00:00", "data": {"market": "0x1198b4cfb84b6078c6f432a9b034ae7d6047ca462fcee0f1895d1d94f5392bd6", "price_changes": [{"asset_id": "90632278970929861972446673124743838350086669096023265555286080414820908223619", "price": "0.917", "size": "0", "side": "BUY", "hash": "49ac67e54500f9ddd3f9a6e28bd03f40348d7eee", "best_bid": "0.978", "best_ask": "0.992"}, {"asset_id": "48633487062848646741583673336029083373164703684898528527193929763953273671096", "price": "0.083", "size": "0", "side": "SELL", "hash": "9b710d0f33cee834269ee54e6b601ae74570d718", "best_bid": "0.008", "best_ask": "0.022"}], "timestamp": "1769384035224", "event_type": "price_change"}}
{"_local_timestamp": "2026-01-25T23:33:55.332968+00:00", "data": {"market": "0x1198b4cfb84b6078c6f432a9b034ae7d6047ca462fcee0f1895d1d94f5392bd6", "price_changes": [{"asset_id": "90632278970929861972446673124743838350086669096023265555286080414820908223619", "price": "0.919", "size": "20", "side": "BUY", "hash": "c3e20d42768463a6d59583abc7841f4214e5082b", "best_bid": "0.978", "best_ask": "0.992"}, {"asset_id": "48633487062848646741583673336029083373164703684898528527193929763953273671096", "price": "0.081", "size": "20", "side": "SELL", "hash": "7d776ccbaf56b30c543496ee650902b7c7b39e52", "best_bid": "0.008", "best_ask": "0.022"}], "timestamp": "1769384035261", "event_type": "price_change"}}
{"_local_timestamp": "2026-01-25T23:33:57.125153+00:00", "data": {"market": "0xa1f25c89068b04aee1d436a1007070ca2037fd25d93d1040351c140a8a91d076", "price_changes": [{"asset_id": "93336408690807793579464128885533576538481371309320986000405780693674239617931", "price": "0.942", "size": "0", "side": "BUY", "hash": "85d116c36e01994cd5e2177974a6fb6e2d71382a", "best_bid": "0.953", "best_ask": "0.964"}, {"asset_id": "13121373823796973338446309203577015676646957310329888618967056669196081566471", "price": "0.058", "size": "0", "side": "SELL", "hash": "06942ec8ed2bb44e3f7c24f94b8948b72efa647e", "best_bid": "0.036", "best_ask": "0.047"}], "timestamp": "1769384037033", "event_type": "price_change"}}
{"_local_timestamp": "2026-01-25T23:33:57.129976+00:00", "data": {"market": "0xa1f25c89068b04aee1d436a1007070ca2037fd25d93d1040351c140a8a91d076", "price_changes": [{"asset_id": "13121373823796973338446309203577015676646957310329888618967056669196081566471", "price": "0.012", "size": "0", "side": "BUY", "hash": "817c5d979f15ff63f93e0087db6559662afc697b", "best_bid": "0.036", "best_ask": "0.047"}, {"asset_id": "93336408690807793579464128885533576538481371309320986000405780693674239617931", "price": "0.988", "size": "0", "side": "SELL", "hash": "0ea0df9c7b285ba2303ef4499426557ff6a76b7c", "best_bid": "0.953", "best_ask": "0.964"}], "timestamp": "1769384037033", "event_type": "price_change"}}
{"_local_timestamp": "2026-01-25T23:33:57.241656+00:00", "data": {"market": "0x7e897a7826222708d178062c82e9166b37a98df0ce92ace40f3b9357f2526157", "price_changes": [{"asset_id": "8417326734150529989790022001226615602996938938967740280020227231905495513816", "price": "0.922", "size": "0", "side": "BUY", "hash": "ad3fc7ab87a1cce9b7b19ca4f2c235db52b9cdb1", "best_bid": "0.987", "best_ask": "0.99"}, {"asset_id": "85126848831263873777721669142266306730253139367446060083090258474801299057771", "price": "0.078", "size": "0", "side": "SELL", "hash": "9d0b83491115e6569202c4c7487274c7f01f0d01", "best_bid": "0.01", "best_ask": "0.013"}], "timestamp": "1769384037172", "event_type": "price_change"}}
{"_local_timestamp": "2026-01-25T23:33:59.258352+00:00", "data": {"market": "0x7e897a7826222708d178062c82e9166b37a98df0ce92ace40f3b9357f2526157", "price_changes": [{"asset_id": "8417326734150529989790022001226615602996938938967740280020227231905495513816", "price": "0.923", "size": "0", "side": "BUY", "hash": "de831299287ef79defad65f4d16960d80bb81723", "best_bid": "0.987", "best_ask": "0.99"}, {"asset_id": "85126848831263873777721669142266306730253139367446060083090258474801299057771", "price": "0.077", "size": "0", "side": "SELL", "hash": "7eb0c5b1ecda96b482e92a3b2fab1b33581c18c8", "best_bid": "0.01", "best_ask": "0.013"}], "timestamp": "1769384039185", "event_type": "price_change"}}
{"_local_timestamp": "2026-01-25T23:33:59.284901+00:00", "data": {"market": "0x7e897a7826222708d178062c82e9166b37a98df0ce92ace40f3b9357f2526157", "price_changes": [{"asset_id": "8417326734150529989790022001226615602996938938967740280020227231905495513816", "price": "0.922", "size": "20", "side": "BUY", "hash": "5856aab9195441dcb696803c6e35f0f031cdfeb2", "best_bid": "0.987", "best_ask": "0.99"}, {"asset_id": "85126848831263873777721669142266306730253139367446060083090258474801299057771", "price": "0.078", "size": "20", "side": "SELL", "hash": "609048536fb7f318bf4a8e8b18eb9ab40c1808b5", "best_bid": "0.01", "best_ask": "0.013"}], "timestamp": "1769384039209", "event_type": "price_change"}}
{"_local_timestamp": "2026-01-25T23:34:10.961470+00:00", "data": {"market": "0xb7427b891a0134371023603986edc842ce369e83dcc42f300e7a03049295d4b1", "price_changes": [{"asset_id": "109919329920505980115727737237456054640803613381042045664921404844196255236880", "price": "0.657", "size": "0", "side": "BUY", "hash": "bf798428ad816bb970dbe77e4a8d3fd57ed11909", "best_bid": "0.694", "best_ask": "0.713"}, {"asset_id": "79849296060580317277275866407031080149422127632028665473147696931641259289529", "price": "0.343", "size": "0", "side": "SELL", "hash": "ded6a370823bfbef08044d6a9972076424cf7489", "best_bid": "0.287", "best_ask": "0.306"}], "timestamp": "1769384050879", "event_type": "price_change"}}
{"_local_timestamp": "2026-01-25T23:34:10.962334+00:00", "data": {"market": "0xb7427b891a0134371023603986edc842ce369e83dcc42f300e7a03049295d4b1", "price_changes": [{"asset_id": "109919329920505980115727737237456054640803613381042045664921404844196255236880", "price": "0.621", "size": "0", "side": "BUY", "hash": "bf798428ad816bb970dbe77e4a8d3fd57ed11909", "best_bid": "0.694", "best_ask": "0.713"}, {"asset_id": "79849296060580317277275866407031080149422127632028665473147696931641259289529", "price": "0.379", "size": "0", "side": "SELL", "hash": "ded6a370823bfbef08044d6a9972076424cf7489", "best_bid": "0.287", "best_ask": "0.306"}], "timestamp": "1769384050879", "event_type": "price_change"}}
{"_local_timestamp": "2026-01-25T23:34:10.962648+00:00", "data": {"market": "0x3b7fa5e73b58e3e8db12f33b0888ce58c24d6249cc237581ebe11ac4867dd7b7", "price_changes": [{"asset_id": "2058086706657815889669487757317075047972583222463683616694793460955010144892", "price": "0.75", "size": "7", "side": "BUY", "hash": "622ade94d06d44bc96637861a57f03c75acf7b9b", "best_bid": "0.78", "best_ask": "0.8"}, {"asset_id": "84798712361559471793400029586324344677411006191640081141558912454287016164875", "price": "0.25", "size": "7", "side": "SELL", "hash": "625ab07263cd9e8f8045d5a9210e6af1d611d5fe", "best_bid": "0.2", "best_ask": "0.22"}], "timestamp": "1769384050879", "event_type": "price_change"}}
{"_local_timestamp": "2026-01-25T23:34:11.026082+00:00", "data": {"market": "0x7e897a7826222708d178062c82e9166b37a98df0ce92ace40f3b9357f2526157", "price_changes": [{"asset_id": "8417326734150529989790022001226615602996938938967740280020227231905495513816", "price": "0.904", "size": "0", "side": "BUY", "hash": "9cb19812a91f8106c21929cdfd73990c35bae97d", "best_bid": "0.987", "best_ask": "0.99"}, {"asset_id": "85126848831263873777721669142266306730253139367446060083090258474801299057771", "price": "0.096", "size": "0", "side": "SELL", "hash": "fe539dc03e8cf5df2a1b1bb08dfb401bb1774b72", "best_bid": "0.01", "best_ask": "0.013"}], "timestamp": "1769384050956", "event_type": "price_change"}}
{"_local_timestamp": "2026-01-25T23:34:11.060516+00:00", "data": {"market": "0x7af772ffd32b7726faabc964493d3e3b187186dcaea0d8e60110da9aa0771a42", "price_changes": [{"asset_id": "33977621156566454256243426751711042651548860329437292067732819030497867836755", "price": "0.404", "size": "0", "side": "BUY", "hash": "6c9e1e49e271e887faa706e7082a741642670f46", "best_bid": "0.955", "best_ask": "0.978"}, {"asset_id": "21959934108087357306634929435608062329442380143600039127574312668523401447958", "price": "0.596", "size": "0", "side": "SELL", "hash": "476d0af516405637c929bb6bbab1dabf3fc112f2", "best_bid": "0.022", "best_ask": "0.045"}], "timestamp": "1769384050985", "event_type": "price_change"}}
{"_local_timestamp": "2026-01-25T23:34:11.060991+00:00", "data": {"market": "0x3b7fa5e73b58e3e8db12f33b0888ce58c24d6249cc237581ebe11ac4867dd7b7", "price_changes": [{"asset_id": "2058086706657815889669487757317075047972583222463683616694793460955010144892", "price": "0.7", "size": "6", "side": "BUY", "hash": "270bf6cc211df63c5e8830847eaf99c8319265fd", "best_bid": "0.78", "best_ask": "0.8"}, {"asset_id": "84798712361559471793400029586324344677411006191640081141558912454287016164875", "price": "0.3", "size": "6", "side": "SELL", "hash": "b94c1f2e0dc7cb3285a9fee82da5319ea5b9fac3", "best_bid": "0.2", "best_ask": "0.22"}], "timestamp": "1769384050985", "event_type": "price_change"}}
{"_local_timestamp": "2026-01-25T23:34:11.215336+00:00", "data": {"market": "0x7af772ffd32b7726faabc964493d3e3b187186dcaea0d8e60110da9aa0771a42", "price_changes": [{"asset_id": "33977621156566454256243426751711042651548860329437292067732819030497867836755", "price": "0.403", "size": "0", "side": "BUY", "hash": "ef74a59691735bcc867dacaeff84d100abeeefe5", "best_bid": "0.955", "best_ask": "0.978"}, {"asset_id": "21959934108087357306634929435608062329442380143600039127574312668523401447958", "price": "0.597", "size": "0", "side": "SELL", "hash": "b4108c96ed5423956fc297b60fd99e57cd93b456", "best_bid": "0.022", "best_ask": "0.045"}], "timestamp": "1769384051128", "event_type": "price_change"}}
{"_local_timestamp": "2026-01-25T23:34:11.215698+00:00", "data": {"market": "0x1278f161b546f237cf9a029d9383ff5da371ff047a5adad48ee3243a6f93b6fb", "price_changes": [{"asset_id": "83477010551081586181287014200977553131804751829676583771272159234562620010416", "price": "0.911", "size": "200", "side": "BUY", "hash": "6bb7ccab48489725377ce6ca77ea3af3fb344bd4", "best_bid": "0.971", "best_ask": "0.977"}, {"asset_id": "91844810080062648436529776287166848099843976612137997296770938567257266660379", "price": "0.089", "size": "200", "side": "SELL", "hash": "f7d228d03925bc17abf3bd24981720381c2bfcca", "best_bid": "0.023", "best_ask": "0.029"}], "timestamp": "1769384051128", "event_type": "price_change"}}
{"_local_timestamp": "2026-01-25T23:34:11.235694+00:00", "data": {"market": "0x3b7fa5e73b58e3e8db12f33b0888ce58c24d6249cc237581ebe11ac4867dd7b7", "price_changes": [{"asset_id": "2058086706657815889669487757317075047972583222463683616694793460955010144892", "price": "0.23", "size": "20", "side": "BUY", "hash": "32545b9d9375fad21335aedf87b6f402e258ce3f", "best_bid": "0.78", "best_ask": "0.8"}, {"asset_id": "84798712361559471793400029586324344677411006191640081141558912454287016164875", "price": "0.77", "size": "20", "side": "SELL", "hash": "f6de938aea45b9fec705357f32a1600c94a1990c", "best_bid": "0.2", "best_ask": "0.22"}], "timestamp": "1769384051144", "event_type": "price_change"}}
{"_local_timestamp": "2026-01-25T23:34:11.236044+00:00", "data": {"market": "0x7af772ffd32b7726faabc964493d3e3b187186dcaea0d8e60110da9aa0771a42", "price_changes": [{"asset_id": "33977621156566454256243426751711042651548860329437292067732819030497867836755", "price": "0.351", "size": "10", "side": "BUY", "hash": "fb66878c23546144eed54716b7fd5d24cf467c7d", "best_bid": "0.955", "best_ask": "0.978"}, {"asset_id": "21959934108087357306634929435608062329442380143600039127574312668523401447958", "price": "0.649", "size": "10", "side": "SELL", "hash": "8df269a4c38060e717d30a1e8cf0ccefbd02d787", "best_bid": "0.022", "best_ask": "0.045"}], "timestamp": "1769384051144", "event_type": "price_change"}}
{"_local_timestamp": "2026-01-25T23:34:11.239660+00:00", "data": {"market": "0x7e897a7826222708d178062c82e9166b37a98df0ce92ace40f3b9357f2526157", "price_changes": [{"asset_id": "8417326734150529989790022001226615602996938938967740280020227231905495513816", "price": "0.901", "size": "10", "side": "BUY", "hash": "d23e7ac8bf8f4c279efd2941f46f4e881721a971", "best_bid": "0.987", "best_ask": "0.99"}, {"asset_id": "85126848831263873777721669142266306730253139367446060083090258474801299057771", "price": "0.099", "size": "10", "side": "SELL", "hash": "a22ccba287a38123dfaf40f17347fc4a77fb71d3", "best_bid": "0.01", "best_ask": "0.013"}], "timestamp": "1769384051154", "event_type": "price_change"}}
{"_local_timestamp": "2026-01-25T23:34:11.239960+00:00", "data": {"market": "0x7e897a7826222708d178062c82e9166b37a98df0ce92ace40f3b9357f2526157", "price_changes": [{"asset_id": "8417326734150529989790022001226615602996938938967740280020227231905495513816", "price": "0.923", "size": "10", "side": "BUY", "hash": "1b1247b56e6f82236855c009e2ca2b1fed4f80c8", "best_bid": "0.987", "best_ask": "0.99"}, {"asset_id": "85126848831263873777721669142266306730253139367446060083090258474801299057771", "price": "0.077", "size": "10", "side": "SELL", "hash": "b001b080ea08ef250467a5d249e2f930ef0a9dae", "best_bid": "0.01", "best_ask": "0.013"}], "timestamp": "1769384051155", "event_type": "price_change"}}
{"_local_timestamp": "2026-01-25T23:34:11.374223+00:00", "data": {"market": "0x7af772ffd32b7726faabc964493d3e3b187186dcaea0d8e60110da9aa0771a42", "price_changes": [{"asset_id": "33977621156566454256243426751711042651548860329437292067732819030497867836755", "price": "0.915", "size": "0", "side": "BUY", "hash": "05ee225eddec5a868563e72e4e05a3c8585f0c50", "best_bid": "0.955", "best_ask": "0.978"}, {"asset_id": "21959934108087357306634929435608062329442380143600039127574312668523401447958", "price": "0.085", "size": "0", "side": "SELL", "hash": "419ed9ecdb8cc7c047a72cfb689f2915d12271b2", "best_bid": "0.022", "best_ask": "0.045"}], "timestamp": "1769384051297", "event_type": "price_change"}}
{"_local_timestamp": "2026-01-25T23:34:11.525148+00:00", "data": {"market": "0x7af772ffd32b7726faabc964493d3e3b187186dcaea0d8e60110da9aa0771a42", "price_changes": [{"asset_id": "33977621156566454256243426751711042651548860329437292067732819030497867836755", "price": "0.401", "size": "10", "side": "BUY", "hash": "9e1b3422a92b8d5c5a11d2daa03d26a6cf14f936", "best_bid": "0.955", "best_ask": "0.978"}, {"asset_id": "21959934108087357306634929435608062329442380143600039127574312668523401447958", "price": "0.599", "size": "10", "side": "SELL", "hash": "38f543da3f1ac8ec3723784dd8b625c09507f0bc", "best_bid": "0.022", "best_ask": "0.045"}], "timestamp": "1769384051456", "event_type": "price_change"}}
{"_local_timestamp": "2026-01-25T23:34:11.525502+00:00", "data": {"market": "0x7af772ffd32b7726faabc964493d3e3b187186dcaea0d8e60110da9aa0771a42", "price_changes": [{"asset_id": "33977621156566454256243426751711042651548860329437292067732819030497867836755", "price": "0.915", "size": "10", "side": "BUY", "hash": "a30a731ae14ed19b9dfea377bb4e6298cb0e31b8", "best_bid": "0.955", "best_ask": "0.978"}, {"asset_id": "21959934108087357306634929435608062329442380143600039127574312668523401447958", "price": "0.085", "size": "10", "side": "SELL", "hash": "79787da277b6546f0456dac8fb60148f12bf64ec", "best_bid": "0.022", "best_ask": "0.045"}], "timestamp": "1769384051457", "event_type": "price_change"}}
{"_local_timestamp": "2026-01-25T23:34:11.545028+00:00", "data": {"market": "0x3b7fa5e73b58e3e8db12f33b0888ce58c24d6249cc237581ebe11ac4867dd7b7", "price_changes": [{"asset_id": "2058086706657815889669487757317075047972583222463683616694793460955010144892", "price": "0.7", "size": "54.51", "side": "BUY", "hash": "d709f4269d62c9ac3f04979d667acc42d65b6cef", "best_bid": "0.78", "best_ask": "0.8"}, {"asset_id": "84798712361559471793400029586324344677411006191640081141558912454287016164875", "price": "0.3", "size": "54.51", "side": "SELL", "hash": "91f429b60cefb7d6a03fde748fae9cd4e69e0c4c", "best_bid": "0.2", "best_ask": "0.22"}], "timestamp": "1769384051478", "event_type": "price_change"}}
{"_local_timestamp": "2026-01-25T23:34:11.552985+00:00", "data": {"market": "0x1278f161b546f237cf9a029d9383ff5da371ff047a5adad48ee3243a6f93b6fb", "price_changes": [{"asset_id": "83477010551081586181287014200977553131804751829676583771272159234562620010416", "price": "0.862", "size": "0", "side": "BUY", "hash": "cf5083fef079832cd2468bb48a8fd635c874073c", "best_bid": "0.971", "best_ask": "0.977"}, {"asset_id": "91844810080062648436529776287166848099843976612137997296770938567257266660379", "price": "0.138", "size": "0", "side": "SELL", "hash": "4cc7f2f8589ea0a146d83e35eeef91670ba7d92c", "best_bid": "0.023", "best_ask": "0.029"}], "timestamp": "1769384051485", "event_type": "price_change"}}
{"_local_timestamp": "2026-01-25T23:34:11.553394+00:00", "data": {"market": "0xa1f25c89068b04aee1d436a1007070ca2037fd25d93d1040351c140a8a91d076", "price_changes": [{"asset_id": "93336408690807793579464128885533576538481371309320986000405780693674239617931", "price": "0.88", "size": "3850", "side": "BUY", "hash": "0a642f85eb6d6acbaa341e7f5dcae9d973725c53", "best_bid": "0.953", "best_ask": "0.964"}, {"asset_id": "13121373823796973338446309203577015676646957310329888618967056669196081566471", "price": "0.12", "size": "3850", "side": "SELL", "hash": "020befe4f2b120e14c60395b2ce9313da082b59f", "best_bid": "0.036", "best_ask": "0.047"}], "timestamp": "1769384051485", "event_type": "price_change"}}
{"_local_timestamp": "2026-01-25T23:34:11.680446+00:00", "data": {"market": "0xa1f25c89068b04aee1d436a1007070ca2037fd25d93d1040351c140a8a91d076", "price_changes": [{"asset_id": "93336408690807793579464128885533576538481371309320986000405780693674239617931", "price": "0.882", "size": "10", "side": "BUY", "hash": "ab4079551d391e7f6acc482060919553699660a8", "best_bid": "0.953", "best_ask": "0.964"}, {"asset_id": "13121373823796973338446309203577015676646957310329888618967056669196081566471", "price": "0.118", "size": "10", "side": "SELL", "hash": "c7e7b11aa95129733fd45fe61aeabcb085894260", "best_bid": "0.036", "best_ask": "0.047"}], "timestamp": "1769384051604", "event_type": "price_change"}}
{"_local_timestamp": "2026-01-25T23:34:11.680999+00:00", "data": {"market": "0x1278f161b546f237cf9a029d9383ff5da371ff047a5adad48ee3243a6f93b6fb", "price_changes": [{"asset_id": "83477010551081586181287014200977553131804751829676583771272159234562620010416", "price": "0.913", "size": "748.25", "side": "BUY", "hash": "7eb1aeb903db801e05f37d683f4a08a5834267a3", "best_bid": "0.971", "best_ask": "0.977"}, {"asset_id": "91844810080062648436529776287166848099843976612137997296770938567257266660379", "price": "0.087", "size": "748.25", "side": "SELL", "hash": "fb95034921bed870685add7bea1c9a70fcce14fc", "best_bid": "0.023", "best_ask": "0.029"}], "timestamp": "1769384051604", "event_type": "price_change"}}
{"_local_timestamp": "2026-01-25T23:34:11.681312+00:00", "data": {"market": "0xa1f25c89068b04aee1d436a1007070ca2037fd25d93d1040351c140a8a91d076", "price_changes": [{"asset_id": "93336408690807793579464128885533576538481371309320986000405780693674239617931", "price": "0.882", "size": "20", "side": "BUY", "hash": "312acacd101ea183b342cc736e80af688e02c10f", "best_bid": "0.953", "best_ask": "0.964"}, {"asset_id": "13121373823796973338446309203577015676646957310329888618967056669196081566471", "price": "0.118", "size": "20", "side": "SELL", "hash": "f8bf5319c1a32528ba73d953b2b5de88b774a748", "best_bid": "0.036", "best_ask": "0.047"}], "timestamp": "1769384051605", "event_type": "price_change"}}
{"_local_timestamp": "2026-01-25T23:34:11.681599+00:00", "data": {"market": "0x1278f161b546f237cf9a029d9383ff5da371ff047a5adad48ee3243a6f93b6fb", "price_changes": [{"asset_id": "83477010551081586181287014200977553131804751829676583771272159234562620010416", "price": "0.862", "size": "10", "side": "BUY", "hash": "0085d7cd691d160322d630a88a36c2baf2852196", "best_bid": "0.971", "best_ask": "0.977"}, {"asset_id": "91844810080062648436529776287166848099843976612137997296770938567257266660379", "price": "0.138", "size": "10", "side": "SELL", "hash": "662f3f4868a795b7108fa3a9d57c6e328a2ace56", "best_bid": "0.023", "best_ask": "0.029"}], "timestamp": "1769384051605", "event_type": "price_change"}}
{"_local_timestamp": "2026-01-25T23:34:11.749157+00:00", "data": {"market": "0x3b7fa5e73b58e3e8db12f33b0888ce58c24d6249cc237581ebe11ac4867dd7b7", "price_changes": [{"asset_id": "2058086706657815889669487757317075047972583222463683616694793460955010144892", "price": "0.74", "size": "88.51", "side": "BUY", "hash": "9d8b2918476a60940d86041c250bc2ee1943b6c0", "best_bid": "0.78", "best_ask": "0.8"}, {"asset_id": "84798712361559471793400029586324344677411006191640081141558912454287016164875", "price": "0.26", "size": "88.51", "side": "SELL", "hash": "3698005fd60240dbba0d33d37638f27da72ac725", "best_bid": "0.2", "best_ask": "0.22"}], "timestamp": "1769384051680", "event_type": "price_change"}}
{"_local_timestamp": "2026-01-25T23:34:11.801307+00:00", "data": {"market": "0xb7427b891a0134371023603986edc842ce369e83dcc42f300e7a03049295d4b1", "price_changes": [{"asset_id": "109919329920505980115727737237456054640803613381042045664921404844196255236880", "price": "0.291", "size": "100", "side": "BUY", "hash": "503b195fc652a781427ad1d76acad23ad089a6bb", "best_bid": "0.694", "best_ask": "0.713"}, {"asset_id": "79849296060580317277275866407031080149422127632028665473147696931641259289529", "price": "0.709", "size": "100", "side": "SELL", "hash": "f296c90fefe68c012150393a7a82bd62e5190d9a", "best_bid": "0.287", "best_ask": "0.306"}], "timestamp": "1769384051733", "event_type": "price_change"}}
{"_local_timestamp": "2026-01-25T23:34:11.838730+00:00", "data": {"market": "0xb7427b891a0134371023603986edc842ce369e83dcc42f300e7a03049295d4b1", "price_changes": [{"asset_id": "109919329920505980115727737237456054640803613381042045664921404844196255236880", "price": "0.492", "size": "100", "side": "BUY", "hash": "65f2d9072aa3c9019032becc3fb6869f19e663fd", "best_bid": "0.694", "best_ask": "0.713"}, {"asset_id": "79849296060580317277275866407031080149422127632028665473147696931641259289529", "price": "0.508", "size": "100", "side": "SELL", "hash": "cafeec373995a0e13950a78fb70eb1bf04bde19f", "best_bid": "0.287", "best_ask": "0.306"}], "timestamp": "1769384051768", "event_type": "price_change"}}
{"_local_timestamp": "2026-01-25T23:34:11.869125+00:00", "data": {"market": "0xb7427b891a0134371023603986edc842ce369e83dcc42f300e7a03049295d4b1", "price_changes": [{"asset_id": "79849296060580317277275866407031080149422127632028665473147696931641259289529", "price": "0.281", "size": "41.95", "side": "BUY", "hash": "5a0ee32751c41c42353193407f7679be17de86a9", "best_bid": "0.287", "best_ask": "0.306"}, {"asset_id": "109919329920505980115727737237456054640803613381042045664921404844196255236880", "price": "0.719", "size": "41.95", "side": "SELL", "hash": "b1e3678be79cf75b1810c460c659876c007619df", "best_bid": "0.694", "best_ask": "0.713"}], "timestamp": "1769384051801", "event_type": "price_change"}}
{"_local_timestamp": "2026-01-25T23:34:11.881406+00:00", "data": {"market": "0xb7427b891a0134371023603986edc842ce369e83dcc42f300e7a03049295d4b1", "price_changes": [{"asset_id": "79849296060580317277275866407031080149422127632028665473147696931641259289529", "price": "0.288", "size": "41.95", "side": "BUY", "hash": "7eabbb3b0bfedcfc7c422de1010bb1612d0fb10f", "best_bid": "0.288", "best_ask": "0.306"}, {"asset_id": "109919329920505980115727737237456054640803613381042045664921404844196255236880", "price": "0.712", "size": "41.95", "side": "SELL", "hash": "bd53393fe527b58d37e799b8f902afd2f80bba75", "best_bid": "0.694", "best_ask": "0.712"}], "timestamp": "1769384051804", "event_type": "price_change"}}
{"_local_timestamp": "2026-01-25T23:34:11.881869+00:00", "data": {"market": "0xb7427b891a0134371023603986edc842ce369e83dcc42f300e7a03049295d4b1", "price_changes": [{"asset_id": "79849296060580317277275866407031080149422127632028665473147696931641259289529", "price": "0.284", "size": "41.95", "side": "BUY", "hash": "afa56f3aef7063fc55165516020e071a8db2b435", "best_bid": "0.288", "best_ask": "0.306"}, {"asset_id": "109919329920505980115727737237456054640803613381042045664921404844196255236880", "price": "0.716", "size": "41.95", "side": "SELL", "hash": "8217735b03c4f747a6fb7c172f3433a4b2ce54b7", "best_bid": "0.694", "best_ask": "0.712"}], "timestamp": "1769384051807", "event_type": "price_change"}}
{"_local_timestamp": "2026-01-25T23:34:11.903401+00:00", "data": {"market": "0x7e897a7826222708d178062c82e9166b37a98df0ce92ace40f3b9357f2526157", "price_changes": [{"asset_id": "8417326734150529989790022001226615602996938938967740280020227231905495513816", "price": "0.922", "size": "0", "side": "BUY", "hash": "9da79070fa4b6e565e95d97b32e2996bf536d7c8", "best_bid": "0.987", "best_ask": "0.99"}, {"asset_id": "85126848831263873777721669142266306730253139367446060083090258474801299057771", "price": "0.078", "size": "0", "side": "SELL", "hash": "09dba87b443cd296737f812813ae21e1922554bb", "best_bid": "0.01", "best_ask": "0.013"}], "timestamp": "1769384051827", "event_type": "price_change"}}
{"_local_timestamp": "2026-01-25T23:34:11.931194+00:00", "data": {"market": "0x7e897a7826222708d178062c82e9166b37a98df0ce92ace40f3b9357f2526157", "price_changes": [{"asset_id": "8417326734150529989790022001226615602996938938967740280020227231905495513816", "price": "0.924", "size": "20", "side": "BUY", "hash": "931a8e67df2afe4e157f51d08e1bcf49e713d77d", "best_bid": "0.987", "best_ask": "0.99"}, {"asset_id": "85126848831263873777721669142266306730253139367446060083090258474801299057771", "price": "0.076", "size": "20", "side": "SELL", "hash": "50ed461cc1206a9d25f653d5eb75f5f1c2d1896f", "best_bid": "0.01", "best_ask": "0.013"}], "timestamp": "1769384051854", "event_type": "price_change"}}
{"_local_timestamp": "2026-01-25T23:34:12.137277+00:00", "data": {"market": "0x1198b4cfb84b6078c6f432a9b034ae7d6047ca462fcee0f1895d1d94f5392bd6", "price_changes": [{"asset_id": "48633487062848646741583673336029083373164703684898528527193929763953273671096", "price": "0.007", "size": "0", "side": "BUY", "hash": "04a4137ebedf976eeb52f8f3b5e96e5ecb48d52b", "best_bid": "0.008", "best_ask": "0.022"}, {"asset_id": "90632278970929861972446673124743838350086669096023265555286080414820908223619", "price": "0.993", "size": "0", "side": "SELL", "hash": "eb34d0ded267c62ddfcffde3e83055bc2cb24494", "best_bid": "0.978", "best_ask": "0.992"}], "timestamp": "1769384051929", "event_type": "price_change"}}
{"_local_timestamp": "2026-01-25T23:34:12.137612+00:00", "data": {"market": "0xb7427b891a0134371023603986edc842ce369e83dcc42f300e7a03049295d4b1", "price_changes": [{"asset_id": "79849296060580317277275866407031080149422127632028665473147696931641259289529", "price": "0.287", "size": "89", "side": "BUY", "hash": "b798ce429e3fef3748837f53fa758de09252bbe4", "best_bid": "0.288", "best_ask": "0.306"}, {"asset_id": "109919329920505980115727737237456054640803613381042045664921404844196255236880", "price": "0.713", "size": "89", "side": "SELL", "hash": "99e1373c189fef54e1ee618ac72d96d06f324f5a", "best_bid": "0.694", "best_ask": "0.712"}], "timestamp": "1769384052034", "event_type": "price_change"}}
{"_local_timestamp": "2026-01-25T23:34:12.196250+00:00", "data": {"market": "0xa1f25c89068b04aee1d436a1007070ca2037fd25d93d1040351c140a8a91d076", "price_changes": [{"asset_id": "93336408690807793579464128885533576538481371309320986000405780693674239617931", "price": "0.881", "size": "0", "side": "BUY", "hash": "f829236e2c4cb40107000771766b0cce1f1e8508", "best_bid": "0.953", "best_ask": "0.964"}, {"asset_id": "13121373823796973338446309203577015676646957310329888618967056669196081566471", "price": "0.119", "size": "0", "side": "SELL", "hash": "f0950393e85eca65515a09e84661928f679e7525", "best_bid": "0.036", "best_ask": "0.047"}], "timestamp": "1769384052127", "event_type": "price_change"}}
{"_local_timestamp": "2026-01-25T23:34:12.223996+00:00", "data": {"market": "0xa1f25c89068b04aee1d436a1007070ca2037fd25d93d1040351c140a8a91d076", "price_changes": [{"asset_id": "93336408690807793579464128885533576538481371309320986000405780693674239617931", "price": "0.883", "size": "20", "side": "BUY", "hash": "ca6cc779faf57691bb386b3c192224d6b1d49b5d", "best_bid": "0.953", "best_ask": "0.964"}, {"asset_id": "13121373823796973338446309203577015676646957310329888618967056669196081566471", "price": "0.117", "size": "20", "side": "SELL", "hash": "17cce0691c2ae685cb6016b837f0f0ed2178567c", "best_bid": "0.036", "best_ask": "0.047"}], "timestamp": "1769384052154", "event_type": "price_change"}}
{"_local_timestamp": "2026-01-25T23:34:12.399950+00:00", "data": {"market": "0x3b7fa5e73b58e3e8db12f33b0888ce58c24d6249cc237581ebe11ac4867dd7b7", "price_changes": [{"asset_id": "2058086706657815889669487757317075047972583222463683616694793460955010144892", "price": "0.11", "size": "0", "side": "BUY", "hash": "094724547bcc1f6e425bab07caabf030c511bc04", "best_bid": "0.78", "best_ask": "0.8"}, {"asset_id": "84798712361559471793400029586324344677411006191640081141558912454287016164875", "price": "0.89", "size": "0", "side": "SELL", "hash": "82beff7d6205aa41ce370b0204541cf70dff57fb", "best_bid": "0.2", "best_ask": "0.22"}], "timestamp": "1769384052330", "event_type": "price_change"}}
{"_local_timestamp": "2026-01-25T23:34:12.756379+00:00", "data": {"market": "0x1198b4cfb84b6078c6f432a9b034ae7d6047ca462fcee0f1895d1d94f5392bd6", "price_changes": [{"asset_id": "48633487062848646741583673336029083373164703684898528527193929763953273671096", "price": "0.009", "size": "58.88", "side": "BUY", "hash": "631bc12dd8795f1ce553947080a061c7f130b7d2", "best_bid": "0.009", "best_ask": "0.022"}, {"asset_id": "90632278970929861972446673124743838350086669096023265555286080414820908223619", "price": "0.991", "size": "58.88", "side": "SELL", "hash": "689ba330cad66a2d66e541f5c633101da5285c74", "best_bid": "0.978", "best_ask": "0.991"}], "timestamp": "1769384052687", "event_type": "price_change"}}
{"_local_timestamp": "2026-01-25T23:34:12.885328+00:00", "data": {"market": "0x1278f161b546f237cf9a029d9383ff5da371ff047a5adad48ee3243a6f93b6fb", "price_changes": [{"asset_id": "83477010551081586181287014200977553131804751829676583771272159234562620010416", "price": "0.912", "size": "340", "side": "BUY", "hash": "6c508bfb01b1def71e6932cf71390f186c936aad", "best_bid": "0.971", "best_ask": "0.977"}, {"asset_id": "91844810080062648436529776287166848099843976612137997296770938567257266660379", "price": "0.088", "size": "340", "side": "SELL", "hash": "30ea3215b1e25b16bb0b626c61335cced270e041", "best_bid": "0.023", "best_ask": "0.029"}], "timestamp": "1769384052802", "event_type": "price_change"}}
{"_local_timestamp": "2026-01-25T23:34:13.017005+00:00", "data": {"market": "0x1278f161b546f237cf9a029d9383ff5da371ff047a5adad48ee3243a6f93b6fb", "price_changes": [{"asset_id": "83477010551081586181287014200977553131804751829676583771272159234562620010416", "price": "0.913", "size": "768.25", "side": "BUY", "hash": "16538ff9460f4d02ad755fe353c213c087e678f4", "best_bid": "0.971", "best_ask": "0.977"}, {"asset_id": "91844810080062648436529776287166848099843976612137997296770938567257266660379", "price": "0.087", "size": "768.25", "side": "SELL", "hash": "8e5412f20bf8f1ec4c50bd971201e136c2acd59e", "best_bid": "0.023", "best_ask": "0.029"}], "timestamp": "1769384052828", "event_type": "price_change"}}
{"_local_timestamp": "2026-01-25T23:34:19.903240+00:00", "data": {"market": "0x3b7fa5e73b58e3e8db12f33b0888ce58c24d6249cc237581ebe11ac4867dd7b7", "price_changes": [{"asset_id": "2058086706657815889669487757317075047972583222463683616694793460955010144892", "price": "0.22", "size": "0", "side": "BUY", "hash": "84655163416cf192668cac58bb88b06b7781dbda", "best_bid": "0.78", "best_ask": "0.8"}, {"asset_id": "84798712361559471793400029586324344677411006191640081141558912454287016164875", "price": "0.78", "size": "0", "side": "SELL", "hash": "65ec5e1de6175ad5520731d8c9a559931edb262d", "best_bid": "0.2", "best_ask": "0.22"}], "timestamp": "1769384059753", "event_type": "price_change"}}
{"_local_timestamp": "2026-01-25T23:34:21.574696+00:00", "data": {"market": "0xd94cb5bf446cb8142d22091a40ba14d8c7355bd06fda75e61e25207135348550", "price_changes": [{"asset_id": "73232075333787574101356206392441747050603477997678734507064104196778724283091", "price": "0.05", "size": "330", "side": "BUY", "hash": "c004d74c28e357c2662a4262eab6352d6553ff86", "best_bid": "0.995", "best_ask": "0.996"}, {"asset_id": "58192906727610480118792319554990896451617120222517723334233116219918933677749", "price": "0.95", "size": "330", "side": "SELL", "hash": "4299df14caadda9339485b6e8f8d14561dc12bbb", "best_bid": "0.004", "best_ask": "0.005"}], "timestamp": "1769384061504", "event_type": "price_change"}}
{"_local_timestamp": "2026-01-25T23:34:22.175767+00:00", "data": {"market": "0x3b7fa5e73b58e3e8db12f33b0888ce58c24d6249cc237581ebe11ac4867dd7b7", "price_changes": [{"asset_id": "2058086706657815889669487757317075047972583222463683616694793460955010144892", "price": "0.25", "size": "1680", "side": "BUY", "hash": "748059e361cb03df582ced98313864f0eb8b056c", "best_bid": "0.78", "best_ask": "0.8"}, {"asset_id": "84798712361559471793400029586324344677411006191640081141558912454287016164875", "price": "0.75", "size": "1680", "side": "SELL", "hash": "57295e178585211b17567f838a03b05dbdcd3562", "best_bid": "0.2", "best_ask": "0.22"}], "timestamp": "1769384062107", "event_type": "price_change"}}
{"_local_timestamp": "2026-01-25T23:34:25.490177+00:00", "data": {"market": "0xb7427b891a0134371023603986edc842ce369e83dcc42f300e7a03049295d4b1", "price_changes": [{"asset_id": "79849296060580317277275866407031080149422127632028665473147696931641259289529", "price": "0.287", "size": "30", "side": "BUY", "hash": "d3f11fda5e885ffdf3ba9ffc06603d0724dd5cce", "best_bid": "0.288", "best_ask": "0.306"}, {"asset_id": "109919329920505980115727737237456054640803613381042045664921404844196255236880", "price": "0.713", "size": "30", "side": "SELL", "hash": "2f729956123c9452377f1c3ae2d34e83e455a71c", "best_bid": "0.694", "best_ask": "0.712"}], "timestamp": "1769384065368", "event_type": "price_change"}}
{"_local_timestamp": "2026-01-25T23:34:25.902866+00:00", "data": {"market": "0xb7427b891a0134371023603986edc842ce369e83dcc42f300e7a03049295d4b1", "price_changes": [{"asset_id": "79849296060580317277275866407031080149422127632028665473147696931641259289529", "price": "0.287", "size": "0", "side": "BUY", "hash": "f19fa049f2c38620341d93ec4306a657193ebbaf", "best_bid": "0.288", "best_ask": "0.306"}, {"asset_id": "109919329920505980115727737237456054640803613381042045664921404844196255236880", "price": "0.713", "size": "0", "side": "SELL", "hash": "fb104c606365821834f013758e8aa0ae65b9232c", "best_bid": "0.694", "best_ask": "0.712"}], "timestamp": "1769384065811", "event_type": "price_change"}}
{"_local_timestamp": "2026-01-25T23:34:25.957548+00:00", "data": {"market": "0xb7427b891a0134371023603986edc842ce369e83dcc42f300e7a03049295d4b1", "price_changes": [{"asset_id": "79849296060580317277275866407031080149422127632028665473147696931641259289529", "price": "0.281", "size": "71.95", "side": "BUY", "hash": "f119206c8a322001f71275665c229a02fd6bb42f", "best_bid": "0.288", "best_ask": "0.306"}, {"asset_id": "109919329920505980115727737237456054640803613381042045664921404844196255236880", "price": "0.719", "size": "71.95", "side": "SELL", "hash": "10cb45de1883526fbeb5f8118c133bd735fa326a", "best_bid": "0.694", "best_ask": "0.712"}], "timestamp": "1769384065883", "event_type": "price_change"}}
{"_local_timestamp": "2026-01-25T23:34:27.826881+00:00", "data": {"market": "0x7e897a7826222708d178062c82e9166b37a98df0ce92ace40f3b9357f2526157", "price_changes": [{"asset_id": "8417326734150529989790022001226615602996938938967740280020227231905495513816", "price": "0.05", "size": "30", "side": "BUY", "hash": "fbed2324a60fa70adb642f08502702ee6e8abe4d", "best_bid": "0.987", "best_ask": "0.99"}, {"asset_id": "85126848831263873777721669142266306730253139367446060083090258474801299057771", "price": "0.95", "size": "30", "side": "SELL", "hash": "05b874a3e45614b981e8be54871e156070485411", "best_bid": "0.01", "best_ask": "0.013"}], "timestamp": "1769384067596", "event_type": "price_change"}}
{"_local_timestamp": "2026-01-25T23:34:27.827252+00:00", "data": {"market": "0xb7427b891a0134371023603986edc842ce369e83dcc42f300e7a03049295d4b1", "price_changes": [{"asset_id": "109919329920505980115727737237456054640803613381042045664921404844196255236880", "price": "0.11", "size": "434.09", "side": "BUY", "hash": "d423bc86bee252023c0712c44917c1809a7cb103", "best_bid": "0.694", "best_ask": "0.712"}, {"asset_id": "79849296060580317277275866407031080149422127632028665473147696931641259289529", "price": "0.89", "size": "434.09", "side": "SELL", "hash": "3916feb4fbc5c185e72bac810d2b9d1c2562d90d", "best_bid": "0.288", "best_ask": "0.306"}], "timestamp": "1769384067598", "event_type": "price_change"}}
{"_local_timestamp": "2026-01-25T23:34:27.833590+00:00", "data": {"market": "0xd94cb5bf446cb8142d22091a40ba14d8c7355bd06fda75e61e25207135348550", "price_changes": [{"asset_id": "73232075333787574101356206392441747050603477997678734507064104196778724283091", "price": "0.05", "size": "30", "side": "BUY", "hash": "7457b7fa98104f3d85056bdd6c6f0ceb43d47268", "best_bid": "0.995", "best_ask": "0.996"}, {"asset_id": "58192906727610480118792319554990896451617120222517723334233116219918933677749", "price": "0.95", "size": "30", "side": "SELL", "hash": "f70d2e599d752dd33d258017df79c63220b48222", "best_bid": "0.004", "best_ask": "0.005"}], "timestamp": "1769384067598", "event_type": "price_change"}}
{"_local_timestamp": "2026-01-25T23:34:27.846679+00:00", "data": {"market": "0x3b7fa5e73b58e3e8db12f33b0888ce58c24d6249cc237581ebe11ac4867dd7b7", "price_changes": [{"asset_id": "2058086706657815889669487757317075047972583222463683616694793460955010144892", "price": "0.12", "size": "2625", "side": "BUY", "hash": "ba00060f8a9ef6541fc14da1a9a8ed74811561c7", "best_bid": "0.78", "best_ask": "0.8"}, {"asset_id": "84798712361559471793400029586324344677411006191640081141558912454287016164875", "price": "0.88", "size": "2625", "side": "SELL", "hash": "f9bb4687eade06c54315b94b88de077fb6a6382a", "best_bid": "0.2", "best_ask": "0.22"}], "timestamp": "1769384067597", "event_type": "price_change"}}
{"_local_timestamp": "2026-01-25T23:34:28.583037+00:00", "data": {"market": "0xd94cb5bf446cb8142d22091a40ba14d8c7355bd06fda75e61e25207135348550", "price_changes": [{"asset_id": "73232075333787574101356206392441747050603477997678734507064104196778724283091", "price": "0.01", "size": "8300", "side": "BUY", "hash": "90422c1d4c2627c3c978aabc23afaa4cf306d80f", "best_bid": "0.995", "best_ask": "0.996"}, {"asset_id": "58192906727610480118792319554990896451617120222517723334233116219918933677749", "price": "0.99", "size": "8300", "side": "SELL", "hash": "02c5d8492ec5094c57e12c66ec5cbaa8bf1b0780", "best_bid": "0.004", "best_ask": "0.005"}], "timestamp": "1769384068166", "event_type": "price_change"}}
{"_local_timestamp": "2026-01-25T23:34:28.590130+00:00", "data": {"market": "0x7e897a7826222708d178062c82e9166b37a98df0ce92ace40f3b9357f2526157", "price_changes": [{"asset_id": "8417326734150529989790022001226615602996938938967740280020227231905495513816", "price": "0.01", "size": "8300", "side": "BUY", "hash": "549e3865e50135879e9a07a3485c6e42405b48d7", "best_bid": "0.987", "best_ask": "0.99"}, {"asset_id": "85126848831263873777721669142266306730253139367446060083090258474801299057771", "price": "0.99", "size": "8300", "side": "SELL", "hash": "f8ce921d5d2979b3602ca1b1eed3db13f4e0442c", "best_bid": "0.01", "best_ask": "0.013"}], "timestamp": "1769384068166", "event_type": "price_change"}}
{"_local_timestamp": "2026-01-25T23:34:28.610478+00:00", "data": {"market": "0xb7427b891a0134371023603986edc842ce369e83dcc42f300e7a03049295d4b1", "price_changes": [{"asset_id": "109919329920505980115727737237456054640803613381042045664921404844196255236880", "price": "0.14", "size": "200", "side": "BUY", "hash": "66e6edb99688de4a96ad043a7d7a112941b00750", "best_bid": "0.694", "best_ask": "0.712"}, {"asset_id": "79849296060580317277275866407031080149422127632028665473147696931641259289529", "price": "0.86", "size": "200", "side": "SELL", "hash": "c8b3bc45f83f91ce30679306c6e58128fe2dda7d", "best_bid": "0.288", "best_ask": "0.306"}], "timestamp": "1769384068171", "event_type": "price_change"}}
{"_local_timestamp": "2026-01-25T23:34:28.622398+00:00", "data": {"market": "0x3b7fa5e73b58e3e8db12f33b0888ce58c24d6249cc237581ebe11ac4867dd7b7", "price_changes": [{"asset_id": "2058086706657815889669487757317075047972583222463683616694793460955010144892", "price": "0.11", "size": "200", "side": "BUY", "hash": "00cdfde517c26e383eedc8ea6adf5d8002116a32", "best_bid": "0.78", "best_ask": "0.8"}, {"asset_id": "84798712361559471793400029586324344677411006191640081141558912454287016164875", "price": "0.89", "size": "200", "side": "SELL", "hash": "1df51765802babe7e00d2cb1917977fe301b9dee", "best_bid": "0.2", "best_ask": "0.22"}], "timestamp": "1769384068177", "event_type": "price_change"}}
{"_local_timestamp": "2026-01-25T23:34:29.993430+00:00", "data": {"market": "0xd94cb5bf446cb8142d22091a40ba14d8c7355bd06fda75e61e25207135348550", "price_changes": [{"asset_id": "73232075333787574101356206392441747050603477997678734507064104196778724283091", "price": "0.05", "size": "3030", "side": "BUY", "hash": "687c63c492537e404411eec092abc0de527ae268", "best_bid": "0.995", "best_ask": "0.996"}, {"asset_id": "58192906727610480118792319554990896451617120222517723334233116219918933677749", "price": "0.95", "size": "3030", "side": "SELL", "hash": "2eb7abb2a2ef5d2a7c54570e67e32d53716b9021", "best_bid": "0.004", "best_ask": "0.005"}], "timestamp": "1769384069802", "event_type": "price_change"}}
{"_local_timestamp": "2026-01-25T23:34:33.053257+00:00", "data": {"market": "0x7af772ffd32b7726faabc964493d3e3b187186dcaea0d8e60110da9aa0771a42", "price_changes": [{"asset_id": "21959934108087357306634929435608062329442380143600039127574312668523401447958", "price": "0.001", "size": "19950.99", "side": "BUY", "hash": "8fa7a93039e84e612917e6c1f48587c5ef4663c2", "best_bid": "0.022", "best_ask": "0.045"}, {"asset_id": "33977621156566454256243426751711042651548860329437292067732819030497867836755", "price": "0.999", "size": "19950.99", "side": "SELL", "hash": "23022ab033179f53c4a8cd1226ea86d0697bb423", "best_bid": "0.955", "best_ask": "0.978"}], "timestamp": "1769384072985", "event_type": "price_change"}}
{"_local_timestamp": "2026-01-25T23:34:33.160808+00:00", "data": {"market": "0x1198b4cfb84b6078c6f432a9b034ae7d6047ca462fcee0f1895d1d94f5392bd6", "price_changes": [{"asset_id": "48633487062848646741583673336029083373164703684898528527193929763953273671096", "price": "0.008", "size": "374", "side": "BUY", "hash": "717c09e42423060c34752ce8ef8fa7b544f6a018", "best_bid": "0.009", "best_ask": "0.022"}, {"asset_id": "90632278970929861972446673124743838350086669096023265555286080414820908223619", "price": "0.992", "size": "374", "side": "SELL", "hash": "b6525a7244605f1dc1d7b6b10a8966177894dbd4", "best_bid": "0.978", "best_ask": "0.991"}], "timestamp": "1769384073093", "event_type": "price_change"}}
{"_local_timestamp": "2026-01-25T23:34:33.266779+00:00", "data": {"market": "0x7af772ffd32b7726faabc964493d3e3b187186dcaea0d8e60110da9aa0771a42", "price_changes": [{"asset_id": "33977621156566454256243426751711042651548860329437292067732819030497867836755", "price": "0.945", "size": "0", "side": "BUY", "hash": "0b7b1c204e680065c045138dcec87c8ee2815b6d", "best_bid": "0.955", "best_ask": "0.978"}, {"asset_id": "21959934108087357306634929435608062329442380143600039127574312668523401447958", "price": "0.055", "size": "0", "side": "SELL", "hash": "cfd9f9f86be8eca28f827298bf25d5f4baf73f7f", "best_bid": "0.022", "best_ask": "0.045"}], "timestamp": "1769384073192", "event_type": "price_change"}}
{"_local_timestamp": "2026-01-25T23:34:33.475234+00:00", "data": {"market": "0x7af772ffd32b7726faabc964493d3e3b187186dcaea0d8e60110da9aa0771a42", "price_changes": [{"asset_id": "33977621156566454256243426751711042651548860329437292067732819030497867836755", "price": "0.954", "size": "118.75", "side": "BUY", "hash": "db65e99ff3f412ce8e27e79862faf57b86bb0f4d", "best_bid": "0.955", "best_ask": "0.978"}, {"asset_id": "21959934108087357306634929435608062329442380143600039127574312668523401447958", "price": "0.046", "size": "118.75", "side": "SELL", "hash": "1008f838449c7f20804fa3d527fc2af4dcb9f5a3", "best_bid": "0.022", "best_ask": "0.045"}], "timestamp": "1769384073399", "event_type": "price_change"}}
{"_local_timestamp": "2026-01-25T23:34:35.478528+00:00", "data": {"market": "0x7af772ffd32b7726faabc964493d3e3b187186dcaea0d8e60110da9aa0771a42", "price_changes": [{"asset_id": "21959934108087357306634929435608062329442380143600039127574312668523401447958", "price": "0.002", "size": "6280.71", "side": "BUY", "hash": "50fb99ab77872a2ca9ef1da106568db7694d10bc", "best_bid": "0.022", "best_ask": "0.045"}, {"asset_id": "33977621156566454256243426751711042651548860329437292067732819030497867836755", "price": "0.998", "size": "6280.71", "side": "SELL", "hash": "02e3121076505f225bf01209dba6080909ecfdfe", "best_bid": "0.955", "best_ask": "0.978"}], "timestamp": "1769384075397", "event_type": "price_change"}}
{"_local_timestamp": "2026-01-25T23:34:35.479672+00:00", "data": {"market": "0x7af772ffd32b7726faabc964493d3e3b187186dcaea0d8e60110da9aa0771a42", "price_changes": [{"asset_id": "33977621156566454256243426751711042651548860329437292067732819030497867836755", "price": "0.951", "size": "300", "side": "BUY", "hash": "6135dc9f0c9ccd57cbe0737c6e33a9cc19772786", "best_bid": "0.955", "best_ask": "0.978"}, {"asset_id": "21959934108087357306634929435608062329442380143600039127574312668523401447958", "price": "0.049", "size": "300", "side": "SELL", "hash": "6f5619b911c74ea9cef53a528656e264a52bd328", "best_bid": "0.022", "best_ask": "0.045"}], "timestamp": "1769384075398", "event_type": "price_change"}}
{"_local_timestamp": "2026-01-25T23:34:36.283117+00:00", "data": {"market": "0x7af772ffd32b7726faabc964493d3e3b187186dcaea0d8e60110da9aa0771a42", "price_changes": [{"asset_id": "33977621156566454256243426751711042651548860329437292067732819030497867836755", "price": "0.954", "size": "148.75", "side": "BUY", "hash": "9d52cc2878152f6e3cc858d2ad0265c720bfa3d8", "best_bid": "0.955", "best_ask": "0.978"}, {"asset_id": "21959934108087357306634929435608062329442380143600039127574312668523401447958", "price": "0.046", "size": "148.75", "side": "SELL", "hash": "6d852a489d33b42ead4200b1e10d3e25b7d249fd", "best_bid": "0.022", "best_ask": "0.045"}], "timestamp": "1769384076214", "event_type": "price_change"}}
{"_local_timestamp": "2026-01-25T23:35:11.501902+00:00", "data": {"market": "0x7e897a7826222708d178062c82e9166b37a98df0ce92ace40f3b9357f2526157", "price_changes": [{"asset_id": "8417326734150529989790022001226615602996938938967740280020227231905495513816", "price": "0.05", "size": "3030", "side": "BUY", "hash": "7de05b50e8828ff3c5ddf3f0b992b611c7d31dfb", "best_bid": "0.987", "best_ask": "0.99"}, {"asset_id": "85126848831263873777721669142266306730253139367446060083090258474801299057771", "price": "0.95", "size": "3030", "side": "SELL", "hash": "91661dc5cf1bd3b5f5ab881c0b07d9db71d4b06f", "best_bid": "0.01", "best_ask": "0.013"}], "timestamp": "1769384111297", "event_type": "price_change"}}
{"_local_timestamp": "2026-01-25T23:35:11.654432+00:00", "data": {"market": "0x7e897a7826222708d178062c82e9166b37a98df0ce92ace40f3b9357f2526157", "price_changes": [{"asset_id": "8417326734150529989790022001226615602996938938967740280020227231905495513816", "price": "0.38", "size": "700", "side": "BUY", "hash": "f956f882141b9081b6a5f63b2b9949310553a552", "best_bid": "0.987", "best_ask": "0.99"}, {"asset_id": "85126848831263873777721669142266306730253139367446060083090258474801299057771", "price": "0.62", "size": "700", "side": "SELL", "hash": "9fb23685c7c08df33cf1006386e98d747592177f", "best_bid": "0.01", "best_ask": "0.013"}], "timestamp": "1769384111437", "event_type": "price_change"}}
{"_local_timestamp": "2026-01-25T23:35:11.726576+00:00", "data": {"market": "0xd94cb5bf446cb8142d22091a40ba14d8c7355bd06fda75e61e25207135348550", "price_changes": [{"asset_id": "73232075333787574101356206392441747050603477997678734507064104196778724283091", "price": "0.936", "size": "0", "side": "BUY", "hash": "ce8898688b2cc147497bf4d16ace4e7c27297aa7", "best_bid": "0.995", "best_ask": "0.996"}, {"asset_id": "58192906727610480118792319554990896451617120222517723334233116219918933677749", "price": "0.064", "size": "0", "side": "SELL", "hash": "9519db7b10eabd6c49986bc0ed918be85881e3f1", "best_bid": "0.004", "best_ask": "0.005"}], "timestamp": "1769384111523", "event_type": "price_change"}}
{"_local_timestamp": "2026-01-25T23:35:11.838285+00:00", "data": {"market": "0xd94cb5bf446cb8142d22091a40ba14d8c7355bd06fda75e61e25207135348550", "price_changes": [{"asset_id": "73232075333787574101356206392441747050603477997678734507064104196778724283091", "price": "0.938", "size": "20", "side": "BUY", "hash": "ef0a904a2f8b6f41ba2c518909dd1196bde3b422", "best_bid": "0.995", "best_ask": "0.996"}, {"asset_id": "58192906727610480118792319554990896451617120222517723334233116219918933677749", "price": "0.062", "size": "20", "side": "SELL", "hash": "3ee12bb1c1f59a2e4bc69772d5aace3dee940040", "best_bid": "0.004", "best_ask": "0.005"}], "timestamp": "1769384111632", "event_type": "price_change"}}
{"_local_timestamp": "2026-01-25T23:35:11.889931+00:00", "data": {"market": "0x1278f161b546f237cf9a029d9383ff5da371ff047a5adad48ee3243a6f93b6fb", "price_changes": [{"asset_id": "83477010551081586181287014200977553131804751829676583771272159234562620010416", "price": "0.465", "size": "0", "side": "BUY", "hash": "3b7617c8e7eadb46766851dd553367c021b7b003", "best_bid": "0.971", "best_ask": "0.977"}, {"asset_id": "91844810080062648436529776287166848099843976612137997296770938567257266660379", "price": "0.535", "size": "0", "side": "SELL", "hash": "c3adf89d226cc94809de1f7dd634559258fc4cab", "best_bid": "0.023", "best_ask": "0.029"}], "timestamp": "1769384111688", "event_type": "price_change"}}
{"_local_timestamp": "2026-01-25T23:35:12.035955+00:00", "data": {"market": "0x7e897a7826222708d178062c82e9166b37a98df0ce92ace40f3b9357f2526157", "price_changes": [{"asset_id": "8417326734150529989790022001226615602996938938967740280020227231905495513816", "price": "0.05", "size": "30", "side": "BUY", "hash": "8a399617813780690246de957642d5e8d0e33201", "best_bid": "0.987", "best_ask": "0.99"}, {"asset_id": "85126848831263873777721669142266306730253139367446060083090258474801299057771", "price": "0.95", "size": "30", "side": "SELL", "hash": "ccdfae76d0da9b7df7da596c5eaa7c2cbe432208", "best_bid": "0.01", "best_ask": "0.013"}], "timestamp": "1769384111818", "event_type": "price_change"}}
{"_local_timestamp": "2026-01-25T23:35:12.036616+00:00", "data": {"market": "0x7e897a7826222708d178062c82e9166b37a98df0ce92ace40f3b9357f2526157", "price_changes": [{"asset_id": "8417326734150529989790022001226615602996938938967740280020227231905495513816", "price": "0.38", "size": "0", "side": "BUY", "hash": "8a399617813780690246de957642d5e8d0e33201", "best_bid": "0.987", "best_ask": "0.99"}, {"asset_id": "85126848831263873777721669142266306730253139367446060083090258474801299057771", "price": "0.62", "size": "0", "side": "SELL", "hash": "ccdfae76d0da9b7df7da596c5eaa7c2cbe432208", "best_bid": "0.01", "best_ask": "0.013"}], "timestamp": "1769384111818", "event_type": "price_change"}}
{"_local_timestamp": "2026-01-25T23:35:12.159324+00:00", "data": {"market": "0x1278f161b546f237cf9a029d9383ff5da371ff047a5adad48ee3243a6f93b6fb", "price_changes": [{"asset_id": "83477010551081586181287014200977553131804751829676583771272159234562620010416", "price": "0.467", "size": "20", "side": "BUY", "hash": "e10a7a516b65a350d9ec4cb2f70fad7e40e364ae", "best_bid": "0.971", "best_ask": "0.977"}, {"asset_id": "91844810080062648436529776287166848099843976612137997296770938567257266660379", "price": "0.533", "size": "20", "side": "SELL", "hash": "088ba189df70f3bc2063f8c0257b0528dfa0f656", "best_bid": "0.023", "best_ask": "0.029"}], "timestamp": "1769384111959", "event_type": "price_change"}}
{"_local_timestamp": "2026-01-25T23:35:13.105816+00:00", "data": {"market": "0x3b7fa5e73b58e3e8db12f33b0888ce58c24d6249cc237581ebe11ac4867dd7b7", "price_changes": [{"asset_id": "2058086706657815889669487757317075047972583222463683616694793460955010144892", "price": "0.11", "size": "3200", "side": "BUY", "hash": "1349e3377bee21343f960117825aafad40377874", "best_bid": "0.78", "best_ask": "0.8"}, {"asset_id": "84798712361559471793400029586324344677411006191640081141558912454287016164875", "price": "0.89", "size": "3200", "side": "SELL", "hash": "62fd2dfed380f9a4350780da9c223b6ec5a097c8", "best_bid": "0.2", "best_ask": "0.22"}], "timestamp": "1769384112892", "event_type": "price_change"}}
{"_local_timestamp": "2026-01-25T23:35:15.839384+00:00", "data": {"market": "0xa1f25c89068b04aee1d436a1007070ca2037fd25d93d1040351c140a8a91d076", "price_changes": [{"asset_id": "13121373823796973338446309203577015676646957310329888618967056669196081566471", "price": "0.056", "size": "20", "side": "SELL", "hash": "316de2ddf26aac8f23c14b0c41f5dcdb0c7bf2d1", "best_bid": "0.036", "best_ask": "0.047"}, {"asset_id": "93336408690807793579464128885533576538481371309320986000405780693674239617931", "price": "0.944", "size": "20", "side": "BUY", "hash": "ea6d4c2df2f2208058a1f27a7196e9a1e73b1fda", "best_bid": "0.953", "best_ask": "0.964"}], "timestamp": "1769384115621", "event_type": "price_change"}}
{"_local_timestamp": "2026-01-25T23:35:15.994621+00:00", "data": {"market": "0xa1f25c89068b04aee1d436a1007070ca2037fd25d93d1040351c140a8a91d076", "price_changes": [{"asset_id": "13121373823796973338446309203577015676646957310329888618967056669196081566471", "price": "0.056", "size": "50", "side": "SELL", "hash": "638e38dbcdf895ac21e1ed7c0d3c97d74259ee87", "best_bid": "0.036", "best_ask": "0.047"}, {"asset_id": "93336408690807793579464128885533576538481371309320986000405780693674239617931", "price": "0.944", "size": "50", "side": "BUY", "hash": "2c493bf322f67c0164504df5372cc950577dbfde", "best_bid": "0.953", "best_ask": "0.964"}], "timestamp": "1769384115773", "event_type": "price_change"}}
{"_local_timestamp": "2026-01-25T23:35:22.224338+00:00", "data": {"market": "0x7e897a7826222708d178062c82e9166b37a98df0ce92ace40f3b9357f2526157", "price_changes": [{"asset_id": "8417326734150529989790022001226615602996938938967740280020227231905495513816", "price": "0.979", "size": "60", "side": "BUY", "hash": "bd8c2c6d52b2f454004d0816ba41fbf348e316a9", "best_bid": "0.987", "best_ask": "0.99"}, {"asset_id": "85126848831263873777721669142266306730253139367446060083090258474801299057771", "price": "0.021", "size": "60", "side": "SELL", "hash": "afa86424053c72335e10614f04ca052228ce549d", "best_bid": "0.01", "best_ask": "0.013"}], "timestamp": "1769384122001", "event_type": "price_change"}}
{"_local_timestamp": "2026-01-25T23:35:22.228482+00:00", "data": {"market": "0x7e897a7826222708d178062c82e9166b37a98df0ce92ace40f3b9357f2526157", "price_changes": [{"asset_id": "85126848831263873777721669142266306730253139367446060083090258474801299057771", "price": "0.002", "size": "2062.65", "side": "BUY", "hash": "e9a32d882c1f27e405e582de57b8b10433de3c86", "best_bid": "0.01", "best_ask": "0.013"}, {"asset_id": "8417326734150529989790022001226615602996938938967740280020227231905495513816", "price": "0.998", "size": "2062.65", "side": "SELL", "hash": "f07660d6375526b4cfbd49d685929cbcc4dd0a2d", "best_bid": "0.987", "best_ask": "0.99"}], "timestamp": "1769384122003", "event_type": "price_change"}}
{"_local_timestamp": "2026-01-25T23:35:25.458914+00:00", "data": {"market": "0x1198b4cfb84b6078c6f432a9b034ae7d6047ca462fcee0f1895d1d94f5392bd6", "price_changes": [{"asset_id": "48633487062848646741583673336029083373164703684898528527193929763953273671096", "price": "0.008", "size": "0", "side": "BUY", "hash": "6c8d4c378f6f482416b58d8dec5828106c077a38", "best_bid": "0.009", "best_ask": "0.022"}, {"asset_id": "90632278970929861972446673124743838350086669096023265555286080414820908223619", "price": "0.992", "size": "0", "side": "SELL", "hash": "8acdebf0e5ebb5407c2a2986222ffc6efb983938", "best_bid": "0.978", "best_ask": "0.991"}], "timestamp": "1769384125242", "event_type": "price_change"}}
{"_local_timestamp": "2026-01-25T23:35:25.558971+00:00", "data": {"market": "0x1198b4cfb84b6078c6f432a9b034ae7d6047ca462fcee0f1895d1d94f5392bd6", "price_changes": [{"asset_id": "48633487062848646741583673336029083373164703684898528527193929763953273671096", "price": "0.004", "size": "3385.1", "side": "BUY", "hash": "61bc076cea27a644abef273499daeaccd644766d", "best_bid": "0.009", "best_ask": "0.022"}, {"asset_id": "90632278970929861972446673124743838350086669096023265555286080414820908223619", "price": "0.996", "size": "3385.1", "side": "SELL", "hash": "cdbb21ecd5d9b38f1d42db0f420970b2d634df7e", "best_bid": "0.978", "best_ask": "0.991"}], "timestamp": "1769384125342", "event_type": "price_change"}}
{"_local_timestamp": "2026-01-25T23:35:26.805515+00:00", "data": {"market": "0x3b7fa5e73b58e3e8db12f33b0888ce58c24d6249cc237581ebe11ac4867dd7b7", "price_changes": [{"asset_id": "2058086706657815889669487757317075047972583222463683616694793460955010144892", "price": "0.12", "size": "2500", "side": "BUY", "hash": "4d7483ef2f0319d00eff69606d9d5ab9dc803736", "best_bid": "0.78", "best_ask": "0.8"}, {"asset_id": "84798712361559471793400029586324344677411006191640081141558912454287016164875", "price": "0.88", "size": "2500", "side": "SELL", "hash": "63db3b7cbb59d6899d37810a93436bdb34a0cb81", "best_bid": "0.2", "best_ask": "0.22"}], "timestamp": "1769384126556", "event_type": "price_change"}}
{"_local_timestamp": "2026-01-25T23:35:27.167273+00:00", "data": {"market": "0x3b7fa5e73b58e3e8db12f33b0888ce58c24d6249cc237581ebe11ac4867dd7b7", "price_changes": [{"asset_id": "2058086706657815889669487757317075047972583222463683616694793460955010144892", "price": "0.11", "size": "3325", "side": "BUY", "hash": "ff2611f7f779ed73a0c790e167ae5ef565e31b25", "best_bid": "0.78", "best_ask": "0.8"}, {"asset_id": "84798712361559471793400029586324344677411006191640081141558912454287016164875", "price": "0.89", "size": "3325", "side": "SELL", "hash": "fc77cda0bca6088227ee5c64981c0b41483f5fb7", "best_bid": "0.2", "best_ask": "0.22"}], "timestamp": "1769384126870", "event_type": "price_change"}}
{"_local_timestamp": "2026-01-25T23:35:31.812186+00:00", "data": {"market": "0xa1f25c89068b04aee1d436a1007070ca2037fd25d93d1040351c140a8a91d076", "price_changes": [{"asset_id": "13121373823796973338446309203577015676646957310329888618967056669196081566471", "price": "0.036", "size": "24.5", "side": "BUY", "hash": "75d0847ac9321a47691d451e5c80b6ce7e89d271", "best_bid": "0.036", "best_ask": "0.047"}, {"asset_id": "93336408690807793579464128885533576538481371309320986000405780693674239617931", "price": "0.964", "size": "24.5", "side": "SELL", "hash": "696b49990adab82df803b84d32b1a50d8197da89", "best_bid": "0.953", "best_ask": "0.964"}], "timestamp": "1769384131241", "event_type": "price_change"}}
{"_local_timestamp": "2026-01-25T23:35:31.812595+00:00", "data": {"market": "0x1278f161b546f237cf9a029d9383ff5da371ff047a5adad48ee3243a6f93b6fb", "price_changes": [{"asset_id": "91844810080062648436529776287166848099843976612137997296770938567257266660379", "price": "0.022", "size": "0", "side": "BUY", "hash": "64d825ef02728f6f04755de089bfc53ac2fb6b14", "best_bid": "0.023", "best_ask": "0.029"}, {"asset_id": "83477010551081586181287014200977553131804751829676583771272159234562620010416", "price": "0.978", "size": "0", "side": "SELL", "hash": "67463542b2a490424fad4e7d43e32132ab768460", "best_bid": "0.971", "best_ask": "0.977"}], "timestamp": "1769384131244", "event_type": "price_change"}}
{"_local_timestamp": "2026-01-25T23:35:31.812874+00:00", "data": {"market": "0x1278f161b546f237cf9a029d9383ff5da371ff047a5adad48ee3243a6f93b6fb", "price_changes": [{"asset_id": "91844810080062648436529776287166848099843976612137997296770938567257266660379", "price": "0.023", "size": "0", "side": "BUY", "hash": "3e98f8ad0f47de8328cea4f24085e15e2ae6ec16", "best_bid": "0.021", "best_ask": "0.029"}, {"asset_id": "83477010551081586181287014200977553131804751829676583771272159234562620010416", "price": "0.977", "size": "0", "side": "SELL", "hash": "d4c820a2d298dfda4b3a7457b6d345bf5906aea0", "best_bid": "0.971", "best_ask": "0.979"}], "timestamp": "1769384131337", "event_type": "price_change"}}
{"_local_timestamp": "2026-01-25T23:35:31.813121+00:00", "data": {"market": "0x1278f161b546f237cf9a029d9383ff5da371ff047a5adad48ee3243a6f93b6fb", "price_changes": [{"asset_id": "91844810080062648436529776287166848099843976612137997296770938567257266660379", "price": "0.022", "size": "358", "side": "BUY", "hash": "41eca01ff256c0ab29a258301bfc155affc5939f", "best_bid": "0.022", "best_ask": "0.029"}, {"asset_id": "83477010551081586181287014200977553131804751829676583771272159234562620010416", "price": "0.978", "size": "358", "side": "SELL", "hash": "786d35ec26e7098fbbb1c9cceb68d78e4487cf55", "best_bid": "0.971", "best_ask": "0.978"}], "timestamp": "1769384131364", "event_type": "price_change"}}
{"_local_timestamp": "2026-01-25T23:35:31.894643+00:00", "data": {"market": "0x1198b4cfb84b6078c6f432a9b034ae7d6047ca462fcee0f1895d1d94f5392bd6", "price_changes": [{"asset_id": "90632278970929861972446673124743838350086669096023265555286080414820908223619", "price": "0.911", "size": "128.22", "side": "BUY", "hash": "2ecd61ee6e198e577cfc863ec47eee132973b19a", "best_bid": "0.978", "best_ask": "0.991"}, {"asset_id": "48633487062848646741583673336029083373164703684898528527193929763953273671096", "price": "0.089", "size": "128.22", "side": "SELL", "hash": "189c200c466ab602208332c89f1781cf3064788c", "best_bid": "0.009", "best_ask": "0.022"}], "timestamp": "1769384131605", "event_type": "price_change"}}
{"_local_timestamp": "2026-01-25T23:35:39.027976+00:00", "data": {"market": "0xd94cb5bf446cb8142d22091a40ba14d8c7355bd06fda75e61e25207135348550", "price_changes": [{"asset_id": "73232075333787574101356206392441747050603477997678734507064104196778724283091", "price": "0.02", "size": "3500", "side": "BUY", "hash": "a973c074508fdcf441c4d16edb9a7e5552e02e34", "best_bid": "0.995", "best_ask": "0.996"}, {"asset_id": "58192906727610480118792319554990896451617120222517723334233116219918933677749", "price": "0.98", "size": "3500", "side": "SELL", "hash": "ff170a2c1736a910495eab7ddac39d0419406755", "best_bid": "0.004", "best_ask": "0.005"}], "timestamp": "1769384138947", "event_type": "price_change"}}
{"_local_timestamp": "2026-01-25T23:35:39.387853+00:00", "data": {"market": "0xd94cb5bf446cb8142d22091a40ba14d8c7355bd06fda75e61e25207135348550", "price_changes": [{"asset_id": "73232075333787574101356206392441747050603477997678734507064104196778724283091", "price": "0.05", "size": "3430", "side": "BUY", "hash": "6c57cb2e6112e04448c28f11e4d4de1850ddda26", "best_bid": "0.995", "best_ask": "0.996"}, {"asset_id": "58192906727610480118792319554990896451617120222517723334233116219918933677749", "price": "0.95", "size": "3430", "side": "SELL", "hash": "4687836562ea9b2f6a90e687a4d51dcdb9c2b499", "best_bid": "0.004", "best_ask": "0.005"}], "timestamp": "1769384139279", "event_type": "price_change"}}
{"_local_timestamp": "2026-01-25T23:35:43.639322+00:00", "data": {"market": "0x1198b4cfb84b6078c6f432a9b034ae7d6047ca462fcee0f1895d1d94f5392bd6", "price_changes": [{"asset_id": "90632278970929861972446673124743838350086669096023265555286080414820908223619", "price": "0.972", "size": "18", "side": "BUY", "hash": "9630b326ec5e2d4aad403fad12e779383b17d6fd", "best_bid": "0.978", "best_ask": "0.991"}, {"asset_id": "48633487062848646741583673336029083373164703684898528527193929763953273671096", "price": "0.028", "size": "18", "side": "SELL", "hash": "2cbab2c1e23c9608cf6b7cf8ecf4f11c11860a2a", "best_bid": "0.009", "best_ask": "0.022"}], "timestamp": "1769384143567", "event_type": "price_change"}}
{"_local_timestamp": "2026-01-25T23:35:43.640212+00:00", "data": {"market": "0xd94cb5bf446cb8142d22091a40ba14d8c7355bd06fda75e61e25207135348550", "price_changes": [{"asset_id": "73232075333787574101356206392441747050603477997678734507064104196778724283091", "price": "0.962", "size": "0", "side": "BUY", "hash": "c987f7529167c3497164f49e5a81ed45cc96bbf7", "best_bid": "0.995", "best_ask": "0.996"}, {"asset_id": "58192906727610480118792319554990896451617120222517723334233116219918933677749", "price": "0.038", "size": "0", "side": "SELL", "hash": "7b06c7a4fd9ba0af3a20f89edab419af42ca482e", "best_bid": "0.004", "best_ask": "0.005"}], "timestamp": "1769384143568", "event_type": "price_change"}}
{"_local_timestamp": "2026-01-25T23:35:43.808570+00:00", "data": {"market": "0xd94cb5bf446cb8142d22091a40ba14d8c7355bd06fda75e61e25207135348550", "price_changes": [{"asset_id": "73232075333787574101356206392441747050603477997678734507064104196778724283091", "price": "0.423", "size": "0", "side": "BUY", "hash": "29b18ef3ea08b95678e14e16540c5e2173280399", "best_bid": "0.995", "best_ask": "0.996"}, {"asset_id": "58192906727610480118792319554990896451617120222517723334233116219918933677749", "price": "0.577", "size": "0", "side": "SELL", "hash": "5e63e460b26d7b10b041e596873d7b1e6276d9e5", "best_bid": "0.004", "best_ask": "0.005"}], "timestamp": "1769384143734", "event_type": "price_change"}}
{"_local_timestamp": "2026-01-25T23:35:44.007462+00:00", "data": {"market": "0xd94cb5bf446cb8142d22091a40ba14d8c7355bd06fda75e61e25207135348550", "price_changes": [{"asset_id": "73232075333787574101356206392441747050603477997678734507064104196778724283091", "price": "0.903", "size": "10", "side": "BUY", "hash": "28a81defd7a84d869ff8027baa073380d0fe2b51", "best_bid": "0.995", "best_ask": "0.996"}, {"asset_id": "58192906727610480118792319554990896451617120222517723334233116219918933677749", "price": "0.097", "size": "10", "side": "SELL", "hash": "2e9aa207a3494ab4374ffd61759bb71dacfb54c4", "best_bid": "0.004", "best_ask": "0.005"}], "timestamp": "1769384143940", "event_type": "price_change"}}
{"_local_timestamp": "2026-01-25T23:35:44.694717+00:00", "data": {"market": "0xd94cb5bf446cb8142d22091a40ba14d8c7355bd06fda75e61e25207135348550", "price_changes": [{"asset_id": "73232075333787574101356206392441747050603477997678734507064104196778724283091", "price": "0.05", "size": "430", "side": "BUY", "hash": "a5ae26e7c751264cfa9d3b16e63a114df70eb5bc", "best_bid": "0.995", "best_ask": "0.996"}, {"asset_id": "58192906727610480118792319554990896451617120222517723334233116219918933677749", "price": "0.95", "size": "430", "side": "SELL", "hash": "a5d925a3c674c90fb6b2f4477651fae62d8c55cb", "best_bid": "0.004", "best_ask": "0.005"}], "timestamp": "1769384144623", "event_type": "price_change"}}
{"_local_timestamp": "2026-01-25T23:35:44.773282+00:00", "data": {"market": "0xb7427b891a0134371023603986edc842ce369e83dcc42f300e7a03049295d4b1", "price_changes": [{"asset_id": "79849296060580317277275866407031080149422127632028665473147696931641259289529", "price": "0.237", "size": "0", "side": "BUY", "hash": "7eccee9ace3e32c281a31bb40cd85f511b487f26", "best_bid": "0.288", "best_ask": "0.306"}, {"asset_id": "109919329920505980115727737237456054640803613381042045664921404844196255236880", "price": "0.763", "size": "0", "side": "SELL", "hash": "e8658c57b2b50eadd2ded552caedda2d3d8649a9", "best_bid": "0.694", "best_ask": "0.712"}], "timestamp": "1769384144703", "event_type": "price_change"}}
{"_local_timestamp": "2026-01-25T23:35:44.911400+00:00", "data": {"market": "0xb7427b891a0134371023603986edc842ce369e83dcc42f300e7a03049295d4b1", "price_changes": [{"asset_id": "79849296060580317277275866407031080149422127632028665473147696931641259289529", "price": "0.239", "size": "20", "side": "BUY", "hash": "7e2656b91875c3115a719bb33fbd55eefca1356a", "best_bid": "0.288", "best_ask": "0.306"}, {"asset_id": "109919329920505980115727737237456054640803613381042045664921404844196255236880", "price": "0.761", "size": "20", "side": "SELL", "hash": "8770ee939609538ee1d7fffec5eb0982168a2569", "best_bid": "0.694", "best_ask": "0.712"}], "timestamp": "1769384144842", "event_type": "price_change"}}
{"_local_timestamp": "2026-01-25T23:35:46.116369+00:00", "data": {"market": "0xb7427b891a0134371023603986edc842ce369e83dcc42f300e7a03049295d4b1", "price_changes": [{"asset_id": "79849296060580317277275866407031080149422127632028665473147696931641259289529", "price": "0.238", "size": "0", "side": "BUY", "hash": "93c93044b14533f1ce14d14be692c81cc758cc08", "best_bid": "0.288", "best_ask": "0.306"}, {"asset_id": "109919329920505980115727737237456054640803613381042045664921404844196255236880", "price": "0.762", "size": "0", "side": "SELL", "hash": "047fd688ec52bd4ba6a39f6fc0dc0c7339b39b6d", "best_bid": "0.694", "best_ask": "0.712"}], "timestamp": "1769384146028", "event_type": "price_change"}}
{"_local_timestamp": "2026-01-25T23:35:46.126793+00:00", "data": {"market": "0xb7427b891a0134371023603986edc842ce369e83dcc42f300e7a03049295d4b1", "price_changes": [{"asset_id": "79849296060580317277275866407031080149422127632028665473147696931641259289529", "price": "0.24", "size": "20", "side": "BUY", "hash": "9b70f64405cfbc9ad5835d8bcb884d755a1c6da3", "best_bid": "0.288", "best_ask": "0.306"}, {"asset_id": "109919329920505980115727737237456054640803613381042045664921404844196255236880", "price": "0.76", "size": "20", "side": "SELL", "hash": "def60964d457388971bc2059790ef39507007e46", "best_bid": "0.694", "best_ask": "0.712"}], "timestamp": "1769384146055", "event_type": "price_change"}}
{"_local_timestamp": "2026-01-25T23:35:46.302950+00:00", "data": {"market": "0x3b7fa5e73b58e3e8db12f33b0888ce58c24d6249cc237581ebe11ac4867dd7b7", "price_changes": [{"asset_id": "2058086706657815889669487757317075047972583222463683616694793460955010144892", "price": "0.71", "size": "0", "side": "BUY", "hash": "781c1f74f92a549a04eadf1c23f913e0a557de9a", "best_bid": "0.78", "best_ask": "0.8"}, {"asset_id": "84798712361559471793400029586324344677411006191640081141558912454287016164875", "price": "0.29", "size": "0", "side": "SELL", "hash": "872f5712c631ac866be94215afe43442cdfd9346", "best_bid": "0.2", "best_ask": "0.22"}], "timestamp": "1769384146231", "event_type": "price_change"}}
{"_local_timestamp": "2026-01-25T23:35:46.546975+00:00", "data": {"market": "0x3b7fa5e73b58e3e8db12f33b0888ce58c24d6249cc237581ebe11ac4867dd7b7", "price_changes": [{"asset_id": "2058086706657815889669487757317075047972583222463683616694793460955010144892", "price": "0.71", "size": "20", "side": "BUY", "hash": "f808623aaf3c0a115f6ebf4013760f8086fb64c7", "best_bid": "0.78", "best_ask": "0.8"}, {"asset_id": "84798712361559471793400029586324344677411006191640081141558912454287016164875", "price": "0.29", "size": "20", "side": "SELL", "hash": "cabbf6ae661d58361abb548913c45c3c30694525", "best_bid": "0.2", "best_ask": "0.22"}], "timestamp": "1769384146473", "event_type": "price_change"}}
{"_local_timestamp": "2026-01-25T23:35:50.035620+00:00", "data": {"market": "0xa1f25c89068b04aee1d436a1007070ca2037fd25d93d1040351c140a8a91d076", "price_changes": [{"asset_id": "93336408690807793579464128885533576538481371309320986000405780693674239617931", "price": "0.243", "size": "0", "side": "BUY", "hash": "e577e31a03b23108a52b4771f4f0f095af085113", "best_bid": "0.953", "best_ask": "0.964"}, {"asset_id": "13121373823796973338446309203577015676646957310329888618967056669196081566471", "price": "0.757", "size": "0", "side": "SELL", "hash": "87abc16b22eeb0d45b38681015ac419e008b1595", "best_bid": "0.036", "best_ask": "0.047"}], "timestamp": "1769384149969", "event_type": "price_change"}}
{"_local_timestamp": "2026-01-25T23:35:50.128980+00:00", "data": {"market": "0xa1f25c89068b04aee1d436a1007070ca2037fd25d93d1040351c140a8a91d076", "price_changes": [{"asset_id": "93336408690807793579464128885533576538481371309320986000405780693674239617931", "price": "0.241", "size": "8", "side": "BUY", "hash": "765b254ff815cd5962a7fb4a4031c92b46fed5d6", "best_bid": "0.953", "best_ask": "0.964"}, {"asset_id": "13121373823796973338446309203577015676646957310329888618967056669196081566471", "price": "0.759", "size": "8", "side": "SELL", "hash": "87313f3e03fb28d42c16892c2f6ed6819fee72a2", "best_bid": "0.036", "best_ask": "0.047"}], "timestamp": "1769384150015", "event_type": "price_change"}}
{"_local_timestamp": "2026-01-25T23:35:55.935020+00:00", "data": {"market": "0xd94cb5bf446cb8142d22091a40ba14d8c7355bd06fda75e61e25207135348550", "price_changes": [{"asset_id": "73232075333787574101356206392441747050603477997678734507064104196778724283091", "price": "0.05", "size": "3430", "side": "BUY", "hash": "75b9adc14d724355a31d5f39e4a841eb13c8ac39", "best_bid": "0.995", "best_ask": "0.996"}, {"asset_id": "58192906727610480118792319554990896451617120222517723334233116219918933677749", "price": "0.95", "size": "3430", "side": "SELL", "hash": "d138db53d6bd8e1f2597ee37d467d7ee873c6e77", "best_bid": "0.004", "best_ask": "0.005"}], "timestamp": "1769384155860", "event_type": "price_change"}}
{"_local_timestamp": "2026-01-25T23:36:05.139972+00:00", "data": {"market": "0x1198b4cfb84b6078c6f432a9b034ae7d6047ca462fcee0f1895d1d94f5392bd6", "price_changes": [{"asset_id": "48633487062848646741583673336029083373164703684898528527193929763953273671096", "price": "0.01", "size": "119.99", "side": "BUY", "hash": "d8586f2abe3693219a74a018d24e409e24dd5dad", "best_bid": "0.01", "best_ask": "0.022"}, {"asset_id": "90632278970929861972446673124743838350086669096023265555286080414820908223619", "price": "0.99", "size": "119.99", "side": "SELL", "hash": "ef3235a4dd42e39a757aa13e45ac1d7e472a23f4", "best_bid": "0.978", "best_ask": "0.99"}], "timestamp": "1769384165069", "event_type": "price_change"}}
{"_local_timestamp": "2026-01-25T23:36:06.217483+00:00", "data": {"market": "0x1278f161b546f237cf9a029d9383ff5da371ff047a5adad48ee3243a6f93b6fb", "price_changes": [{"asset_id": "83477010551081586181287014200977553131804751829676583771272159234562620010416", "price": "0.913", "size": "748.25", "side": "BUY", "hash": "0075416d8c9a72e4b17f4a05705e3a198ac87ec4", "best_bid": "0.971", "best_ask": "0.978"}, {"asset_id": "91844810080062648436529776287166848099843976612137997296770938567257266660379", "price": "0.087", "size": "748.25", "side": "SELL", "hash": "a88125c5184be63a22ae54bb9935a11db3d10866", "best_bid": "0.022", "best_ask": "0.029"}], "timestamp": "1769384166119", "event_type": "price_change"}}
{"_local_timestamp": "2026-01-25T23:36:06.233941+00:00", "data": {"market": "0x1278f161b546f237cf9a029d9383ff5da371ff047a5adad48ee3243a6f93b6fb", "price_changes": [{"asset_id": "83477010551081586181287014200977553131804751829676583771272159234562620010416", "price": "0.914", "size": "20", "side": "BUY", "hash": "5dae211ed2aafe6df98693c63ce65d2803474850", "best_bid": "0.971", "best_ask": "0.978"}, {"asset_id": "91844810080062648436529776287166848099843976612137997296770938567257266660379", "price": "0.086", "size": "20", "side": "SELL", "hash": "1262d5a9cced20032371e5b0054d6e2bf09a2e2f", "best_bid": "0.022", "best_ask": "0.029"}], "timestamp": "1769384166143", "event_type": "price_change"}}
{"_local_timestamp": "2026-01-25T23:36:06.378401+00:00", "data": {"market": "0xd94cb5bf446cb8142d22091a40ba14d8c7355bd06fda75e61e25207135348550", "price_changes": [{"asset_id": "73232075333787574101356206392441747050603477997678734507064104196778724283091", "price": "0.937", "size": "0", "side": "BUY", "hash": "ffbee2a1c4a6962f8631c9c504b96682bda14719", "best_bid": "0.995", "best_ask": "0.996"}, {"asset_id": "58192906727610480118792319554990896451617120222517723334233116219918933677749", "price": "0.063", "size": "0", "side": "SELL", "hash": "1a8b364dd2764fde9f0ff0bb92da9e24fa4c467d", "best_bid": "0.004", "best_ask": "0.005"}], "timestamp": "1769384166298", "event_type": "price_change"}}
{"_local_timestamp": "2026-01-25T23:36:06.577049+00:00", "data": {"market": "0xd94cb5bf446cb8142d22091a40ba14d8c7355bd06fda75e61e25207135348550", "price_changes": [{"asset_id": "73232075333787574101356206392441747050603477997678734507064104196778724283091", "price": "0.939", "size": "25", "side": "BUY", "hash": "e0dfe79d7d5c1efa1f69876da87332046ccb4b34", "best_bid": "0.995", "best_ask": "0.996"}, {"asset_id": "58192906727610480118792319554990896451617120222517723334233116219918933677749", "price": "0.061", "size": "25", "side": "SELL", "hash": "2618ef45c5b3c171ce7eca04df695fb9e4c31db3", "best_bid": "0.004", "best_ask": "0.005"}], "timestamp": "1769384166503", "event_type": "price_change"}}
{"_local_timestamp": "2026-01-25T23:36:18.950122+00:00", "data": {"market": "0xd94cb5bf446cb8142d22091a40ba14d8c7355bd06fda75e61e25207135348550", "price_changes": [{"asset_id": "73232075333787574101356206392441747050603477997678734507064104196778724283091", "price": "0.05", "size": "430", "side": "BUY", "hash": "cf12f4b3902c914840eb3b1a6c2aa72ff4d33d0b", "best_bid": "0.995", "best_ask": "0.996"}, {"asset_id": "58192906727610480118792319554990896451617120222517723334233116219918933677749", "price": "0.95", "size": "430", "side": "SELL", "hash": "ef28ff3e227c537da590b1bf14b9402ba541f656", "best_bid": "0.004", "best_ask": "0.005"}], "timestamp": "1769384178883", "event_type": "price_change"}}
{"_local_timestamp": "2026-01-25T23:36:28.282865+00:00", "data": {"market": "0x1198b4cfb84b6078c6f432a9b034ae7d6047ca462fcee0f1895d1d94f5392bd6", "price_changes": [{"asset_id": "48633487062848646741583673336029083373164703684898528527193929763953273671096", "price": "0.004", "size": "2636.1", "side": "BUY", "hash": "ad1aafe35bc20c4b1c5171ae67a3798bbbb5a523", "best_bid": "0.01", "best_ask": "0.022"}, {"asset_id": "90632278970929861972446673124743838350086669096023265555286080414820908223619", "price": "0.996", "size": "2636.1", "side": "SELL", "hash": "7c193c7385693b32b852b497a29f672969710694", "best_bid": "0.978", "best_ask": "0.99"}], "timestamp": "1769384188206", "event_type": "price_change"}}
{"_local_timestamp": "2026-01-25T23:36:28.487640+00:00", "data": {"market": "0x1198b4cfb84b6078c6f432a9b034ae7d6047ca462fcee0f1895d1d94f5392bd6", "price_changes": [{"asset_id": "48633487062848646741583673336029083373164703684898528527193929763953273671096", "price": "0.01", "size": "418.99", "side": "BUY", "hash": "b5c27a27b270e96d28f045eca0d39996ebb42904", "best_bid": "0.01", "best_ask": "0.022"}, {"asset_id": "90632278970929861972446673124743838350086669096023265555286080414820908223619", "price": "0.99", "size": "418.99", "side": "SELL", "hash": "6dd98b3d1d8daf629841192bfbac327279615e74", "best_bid": "0.978", "best_ask": "0.99"}], "timestamp": "1769384188412", "event_type": "price_change"}}
{"_local_timestamp": "2026-01-25T23:36:32.086840+00:00", "data": {"market": "0xa1f25c89068b04aee1d436a1007070ca2037fd25d93d1040351c140a8a91d076", "price_changes": [{"asset_id": "13121373823796973338446309203577015676646957310329888618967056669196081566471", "price": "0.036", "size": "273.5", "side": "BUY", "hash": "e148bf0c979f7d55412dcd77823f6767f60c8371", "best_bid": "0.036", "best_ask": "0.047"}, {"asset_id": "93336408690807793579464128885533576538481371309320986000405780693674239617931", "price": "0.964", "size": "273.5", "side": "SELL", "hash": "da6dd6aa95a028448d93be20bf729142ca38ba41", "best_bid": "0.953", "best_ask": "0.964"}], "timestamp": "1769384192017", "event_type": "price_change"}}
{"_local_timestamp": "2026-01-25T23:36:32.934221+00:00", "data": {"market": "0x1278f161b546f237cf9a029d9383ff5da371ff047a5adad48ee3243a6f93b6fb", "price_changes": [{"asset_id": "91844810080062648436529776287166848099843976612137997296770938567257266660379", "price": "0.022", "size": "767", "side": "BUY", "hash": "316468a13566dcd98b7c7ec8294498d391490210", "best_bid": "0.022", "best_ask": "0.029"}, {"asset_id": "83477010551081586181287014200977553131804751829676583771272159234562620010416", "price": "0.978", "size": "767", "side": "SELL", "hash": "bdc2a0a55347c57fa2903c875b4673638c77aefd", "best_bid": "0.971", "best_ask": "0.978"}], "timestamp": "1769384192854", "event_type": "price_change"}}
{"_local_timestamp": "2026-01-25T23:36:33.553581+00:00", "data": {"market": "0x7e897a7826222708d178062c82e9166b37a98df0ce92ace40f3b9357f2526157", "price_changes": [{"asset_id": "8417326734150529989790022001226615602996938938967740280020227231905495513816", "price": "0.05", "size": "3030", "side": "BUY", "hash": "86e15b851ef1cf4967bc525b217912a93769e0e0", "best_bid": "0.987", "best_ask": "0.99"}, {"asset_id": "85126848831263873777721669142266306730253139367446060083090258474801299057771", "price": "0.95", "size": "3030", "side": "SELL", "hash": "774815db4d110ddbad76a985491921d9d5521b70", "best_bid": "0.01", "best_ask": "0.013"}], "timestamp": "1769384193480", "event_type": "price_change"}}
{"_local_timestamp": "2026-01-25T23:36:41.099543+00:00", "data": {"market": "0x1278f161b546f237cf9a029d9383ff5da371ff047a5adad48ee3243a6f93b6fb", "price_changes": [{"asset_id": "83477010551081586181287014200977553131804751829676583771272159234562620010416", "price": "0.968", "size": "0", "side": "BUY", "hash": "0cabeaca788345b21f3ad191ddc0be66b27cef9c", "best_bid": "0.971", "best_ask": "0.978"}, {"asset_id": "91844810080062648436529776287166848099843976612137997296770938567257266660379", "price": "0.032", "size": "0", "side": "SELL", "hash": "cc7d8068144df9b435f2f9c22d2de073af8c8705", "best_bid": "0.022", "best_ask": "0.029"}], "timestamp": "1769384201001", "event_type": "price_change"}}
{"_local_timestamp": "2026-01-25T23:36:50.006121+00:00", "data": {"market": "0xd94cb5bf446cb8142d22091a40ba14d8c7355bd06fda75e61e25207135348550", "price_changes": [{"asset_id": "73232075333787574101356206392441747050603477997678734507064104196778724283091", "price": "0.962", "size": "118.75", "side": "BUY", "hash": "109ae2bac42b2672c1181c2a9919940a0f4ea465", "best_bid": "0.995", "best_ask": "0.996"}, {"asset_id": "58192906727610480118792319554990896451617120222517723334233116219918933677749", "price": "0.038", "size": "118.75", "side": "SELL", "hash": "2f77aeabb893f98d882838c76919bcfac5d96350", "best_bid": "0.004", "best_ask": "0.005"}], "timestamp": "1769384209937", "event_type": "price_change"}}
{"_local_timestamp": "2026-01-25T23:36:50.006545+00:00", "data": {"market": "0xb7427b891a0134371023603986edc842ce369e83dcc42f300e7a03049295d4b1", "price_changes": [{"asset_id": "79849296060580317277275866407031080149422127632028665473147696931641259289529", "price": "0.289", "size": "59", "side": "BUY", "hash": "c7cc9708d74a17cd9326bedbd44a6a7232dd0f28", "best_bid": "0.289", "best_ask": "0.306"}, {"asset_id": "109919329920505980115727737237456054640803613381042045664921404844196255236880", "price": "0.711", "size": "59", "side": "SELL", "hash": "9acc3ec3e779b89dba1afa99c27bd5d7e2b09397", "best_bid": "0.694", "best_ask": "0.711"}], "timestamp": "1769384209936", "event_type": "price_change"}}
{"_local_timestamp": "2026-01-25T23:36:50.006798+00:00", "data": {"market": "0x7af772ffd32b7726faabc964493d3e3b187186dcaea0d8e60110da9aa0771a42", "price_changes": [{"asset_id": "33977621156566454256243426751711042651548860329437292067732819030497867836755", "price": "0.955", "size": "168.75", "side": "BUY", "hash": "62d5d5a1e66d7f8d8a2ec9feb85086380d91e573", "best_bid": "0.955", "best_ask": "0.978"}, {"asset_id": "21959934108087357306634929435608062329442380143600039127574312668523401447958", "price": "0.045", "size": "168.75", "side": "SELL", "hash": "d5ed340fcb22edda03caee14b5da17e48dbc143a", "best_bid": "0.022", "best_ask": "0.045"}], "timestamp": "1769384209937", "event_type": "price_change"}}
{"_local_timestamp": "2026-01-25T23:36:50.007078+00:00", "data": {"market": "0x1198b4cfb84b6078c6f432a9b034ae7d6047ca462fcee0f1895d1d94f5392bd6", "price_changes": [{"asset_id": "90632278970929861972446673124743838350086669096023265555286080414820908223619", "price": "0.963", "size": "118.75", "side": "BUY", "hash": "738efdaf77867932c9f12ea6631957c958c9efc6", "best_bid": "0.978", "best_ask": "0.99"}, {"asset_id": "48633487062848646741583673336029083373164703684898528527193929763953273671096", "price": "0.037", "size": "118.75", "side": "SELL", "hash": "2403de3010bae9dddc5e581b8286a4042ce22eb4", "best_bid": "0.01", "best_ask": "0.022"}], "timestamp": "1769384209937", "event_type": "price_change"}}
{"_local_timestamp": "2026-01-25T23:36:50.008593+00:00", "data": {"market": "0x7af772ffd32b7726faabc964493d3e3b187186dcaea0d8e60110da9aa0771a42", "price_changes": [{"asset_id": "33977621156566454256243426751711042651548860329437292067732819030497867836755", "price": "0.956", "size": "118.75", "side": "BUY", "hash": "2dfa189e4dbcafab6aea76532a8542fba5dc3de5", "best_bid": "0.956", "best_ask": "0.978"}, {"asset_id": "21959934108087357306634929435608062329442380143600039127574312668523401447958", "price": "0.044", "size": "118.75", "side": "SELL", "hash": "757486888412973e5101afebcb6c1bfa5d03141d", "best_bid": "0.022", "best_ask": "0.044"}], "timestamp": "1769384209937", "event_type": "price_change"}}
{"_local_timestamp": "2026-01-25T23:36:50.192035+00:00", "data": {"market": "0xd94cb5bf446cb8142d22091a40ba14d8c7355bd06fda75e61e25207135348550", "price_changes": [{"asset_id": "73232075333787574101356206392441747050603477997678734507064104196778724283091", "price": "0.903", "size": "0", "side": "BUY", "hash": "e9914ca1bfc5ae89a50e56b03996992aa3a2bcce", "best_bid": "0.995", "best_ask": "0.996"}, {"asset_id": "58192906727610480118792319554990896451617120222517723334233116219918933677749", "price": "0.097", "size": "0", "side": "SELL", "hash": "0c03ab0157693be68d198d111142c834c9fb1eba", "best_bid": "0.004", "best_ask": "0.005"}], "timestamp": "1769384210111", "event_type": "price_change"}}
{"_local_timestamp": "2026-01-25T23:36:50.228890+00:00", "data": {"market": "0xd94cb5bf446cb8142d22091a40ba14d8c7355bd06fda75e61e25207135348550", "price_changes": [{"asset_id": "73232075333787574101356206392441747050603477997678734507064104196778724283091", "price": "0.423", "size": "10", "side": "BUY", "hash": "d5414ff5f56f57f1add1d0566b9c35441d23f0c3", "best_bid": "0.995", "best_ask": "0.996"}, {"asset_id": "58192906727610480118792319554990896451617120222517723334233116219918933677749", "price": "0.577", "size": "10", "side": "SELL", "hash": "d1d55e499761e8e62c5d98d61de90f7ca731800f", "best_bid": "0.004", "best_ask": "0.005"}], "timestamp": "1769384210159", "event_type": "price_change"}}
{"_local_timestamp": "2026-01-25T23:36:50.508874+00:00", "data": {"market": "0xb7427b891a0134371023603986edc842ce369e83dcc42f300e7a03049295d4b1", "price_changes": [{"asset_id": "79849296060580317277275866407031080149422127632028665473147696931641259289529", "price": "0.26", "size": "0", "side": "BUY", "hash": "ead9193e523d720b3d18d31539145b4b66e21d28", "best_bid": "0.289", "best_ask": "0.306"}, {"asset_id": "109919329920505980115727737237456054640803613381042045664921404844196255236880", "price": "0.74", "size": "0", "side": "SELL", "hash": "619bc49436132abb7d01ba388470c6bb82315ee4", "best_bid": "0.694", "best_ask": "0.711"}], "timestamp": "1769384210443", "event_type": "price_change"}}
{"_local_timestamp": "2026-01-25T23:36:50.613966+00:00", "data": {"market": "0xb7427b891a0134371023603986edc842ce369e83dcc42f300e7a03049295d4b1", "price_changes": [{"asset_id": "79849296060580317277275866407031080149422127632028665473147696931641259289529", "price": "0.281", "size": "41.95", "side": "BUY", "hash": "884b3d78977b09fd98b05ea9a0a2b2f3b607a791", "best_bid": "0.289", "best_ask": "0.306"}, {"asset_id": "109919329920505980115727737237456054640803613381042045664921404844196255236880", "price": "0.719", "size": "41.95", "side": "SELL", "hash": "03413079757a25222cd649e0a696723a22a8ad45", "best_bid": "0.694", "best_ask": "0.711"}], "timestamp": "1769384210533", "event_type": "price_change"}}
{"_local_timestamp": "2026-01-25T23:36:50.658843+00:00", "data": {"market": "0xb7427b891a0134371023603986edc842ce369e83dcc42f300e7a03049295d4b1", "price_changes": [{"asset_id": "79849296060580317277275866407031080149422127632028665473147696931641259289529", "price": "0.289", "size": "89", "side": "BUY", "hash": "4cfaf2318d658c633d87c99aa3981170d7cdf0bd", "best_bid": "0.289", "best_ask": "0.306"}, {"asset_id": "109919329920505980115727737237456054640803613381042045664921404844196255236880", "price": "0.711", "size": "89", "side": "SELL", "hash": "3ab125e27e660de74b4abb45a7782953423adae7", "best_bid": "0.694", "best_ask": "0.711"}], "timestamp": "1769384210588", "event_type": "price_change"}}
{"_local_timestamp": "2026-01-25T23:36:51.002288+00:00", "data": {"market": "0x7af772ffd32b7726faabc964493d3e3b187186dcaea0d8e60110da9aa0771a42", "price_changes": [{"asset_id": "33977621156566454256243426751711042651548860329437292067732819030497867836755", "price": "0.957", "size": "50", "side": "BUY", "hash": "d7a9ea061155609f11441cf1506fe5a6edfd0412", "best_bid": "0.957", "best_ask": "0.978"}, {"asset_id": "21959934108087357306634929435608062329442380143600039127574312668523401447958", "price": "0.043", "size": "50", "side": "SELL", "hash": "2fc37e411331a24b77b23036b1b5d63d52a0473b", "best_bid": "0.022", "best_ask": "0.043"}], "timestamp": "1769384210932", "event_type": "price_change"}}
{"_local_timestamp": "2026-01-25T23:36:51.202375+00:00", "data": {"market": "0x7af772ffd32b7726faabc964493d3e3b187186dcaea0d8e60110da9aa0771a42", "price_changes": [{"asset_id": "33977621156566454256243426751711042651548860329437292067732819030497867836755", "price": "0.954", "size": "118.75", "side": "BUY", "hash": "4b7d1b9d1db565266cbda5f5fe6fcf40fe092950", "best_bid": "0.957", "best_ask": "0.978"}, {"asset_id": "21959934108087357306634929435608062329442380143600039127574312668523401447958", "price": "0.046", "size": "118.75", "side": "SELL", "hash": "2bc2f9fa3d3d109003d356167506532b3defee59", "best_bid": "0.022", "best_ask": "0.043"}], "timestamp": "1769384211109", "event_type": "price_change"}}
{"_local_timestamp": "2026-01-25T23:36:51.322257+00:00", "data": {"market": "0x7af772ffd32b7726faabc964493d3e3b187186dcaea0d8e60110da9aa0771a42", "price_changes": [{"asset_id": "33977621156566454256243426751711042651548860329437292067732819030497867836755", "price": "0.955", "size": "118.75", "side": "BUY", "hash": "77680aec7f364adffc348286c183f612f58e8405", "best_bid": "0.957", "best_ask": "0.978"}, {"asset_id": "21959934108087357306634929435608062329442380143600039127574312668523401447958", "price": "0.045", "size": "118.75", "side": "SELL", "hash": "c580227d16e57cf1fa904e20d3006c4fde8d81bb", "best_bid": "0.022", "best_ask": "0.043"}], "timestamp": "1769384211245", "event_type": "price_change"}}
{"_local_timestamp": "2026-01-25T23:36:51.750328+00:00", "data": {"market": "0x7af772ffd32b7726faabc964493d3e3b187186dcaea0d8e60110da9aa0771a42", "price_changes": [{"asset_id": "33977621156566454256243426751711042651548860329437292067732819030497867836755", "price": "0.956", "size": "148.75", "side": "BUY", "hash": "fb6eff99febfc9eacd6874f474610b98c5c6e830", "best_bid": "0.957", "best_ask": "0.978"}, {"asset_id": "21959934108087357306634929435608062329442380143600039127574312668523401447958", "price": "0.044", "size": "148.75", "side": "SELL", "hash": "8b1d6a44fc16a966ed6756bd53fa4387a2edc7e3", "best_bid": "0.022", "best_ask": "0.043"}], "timestamp": "1769384211677", "event_type": "price_change"}}
{"_local_timestamp": "2026-01-25T23:36:53.589617+00:00", "data": {"market": "0x7e897a7826222708d178062c82e9166b37a98df0ce92ace40f3b9357f2526157", "price_changes": [{"asset_id": "8417326734150529989790022001226615602996938938967740280020227231905495513816", "price": "0.05", "size": "30", "side": "BUY", "hash": "283d10832a771d5246e8913fd2a319d276862c4f", "best_bid": "0.987", "best_ask": "0.99"}, {"asset_id": "85126848831263873777721669142266306730253139367446060083090258474801299057771", "price": "0.95", "size": "30", "side": "SELL", "hash": "9987cdb8144c0cbcd56d08bc36c41de794c297d7", "best_bid": "0.01", "best_ask": "0.013"}], "timestamp": "1769384213521", "event_type": "price_change"}}
{"_local_timestamp": "2026-01-25T23:36:54.438368+00:00", "data": {"market": "0xb7427b891a0134371023603986edc842ce369e83dcc42f300e7a03049295d4b1", "price_changes": [{"asset_id": "109919329920505980115727737237456054640803613381042045664921404844196255236880", "price": "0.492", "size": "0", "side": "BUY", "hash": "8b7a495e56fc935f78545200ea9c5c9d66d1a4ae", "best_bid": "0.694", "best_ask": "0.711"}, {"asset_id": "79849296060580317277275866407031080149422127632028665473147696931641259289529", "price": "0.508", "size": "0", "side": "SELL", "hash": "56c7f26017f75227568e884952b36e3690ae06d1", "best_bid": "0.289", "best_ask": "0.306"}], "timestamp": "1769384214360", "event_type": "price_change"}}
{"_local_timestamp": "2026-01-25T23:36:54.438863+00:00", "data": {"market": "0xb7427b891a0134371023603986edc842ce369e83dcc42f300e7a03049295d4b1", "price_changes": [{"asset_id": "109919329920505980115727737237456054640803613381042045664921404844196255236880", "price": "0.291", "size": "0", "side": "BUY", "hash": "8b7a495e56fc935f78545200ea9c5c9d66d1a4ae", "best_bid": "0.694", "best_ask": "0.711"}, {"asset_id": "79849296060580317277275866407031080149422127632028665473147696931641259289529", "price": "0.709", "size": "0", "side": "SELL", "hash": "56c7f26017f75227568e884952b36e3690ae06d1", "best_bid": "0.289", "best_ask": "0.306"}], "timestamp": "1769384214360", "event_type": "price_change"}}
{"_local_timestamp": "2026-01-25T23:36:54.439102+00:00", "data": {"market": "0xb7427b891a0134371023603986edc842ce369e83dcc42f300e7a03049295d4b1", "price_changes": [{"asset_id": "79849296060580317277275866407031080149422127632028665473147696931641259289529", "price": "0.288", "size": "0", "side": "BUY", "hash": "e2b6006933935aed4ffba9fcfe2ae7a5531dd43d", "best_bid": "0.289", "best_ask": "0.306"}, {"asset_id": "109919329920505980115727737237456054640803613381042045664921404844196255236880", "price": "0.712", "size": "0", "side": "SELL", "hash": "c7e3caf76844b059d4e3799c0cb2ea44dde9f6b4", "best_bid": "0.694", "best_ask": "0.711"}], "timestamp": "1769384214361", "event_type": "price_change"}}
{"_local_timestamp": "2026-01-25T23:36:54.621148+00:00", "data": {"market": "0x3b7fa5e73b58e3e8db12f33b0888ce58c24d6249cc237581ebe11ac4867dd7b7", "price_changes": [{"asset_id": "2058086706657815889669487757317075047972583222463683616694793460955010144892", "price": "0.23", "size": "0", "side": "BUY", "hash": "bd428cb53cda803367b30103bc3e0c2bf5f2596e", "best_bid": "0.78", "best_ask": "0.8"}, {"asset_id": "84798712361559471793400029586324344677411006191640081141558912454287016164875", "price": "0.77", "size": "0", "side": "SELL", "hash": "71c35b6c116acbd8503e924e9ce74ad6bb3cbedc", "best_bid": "0.2", "best_ask": "0.22"}], "timestamp": "1769384214547", "event_type": "price_change"}}
{"_local_timestamp": "2026-01-25T23:36:54.988972+00:00", "data": {"market": "0xb7427b891a0134371023603986edc842ce369e83dcc42f300e7a03049295d4b1", "price_changes": [{"asset_id": "109919329920505980115727737237456054640803613381042045664921404844196255236880", "price": "0.693", "size": "77.16", "side": "BUY", "hash": "48a0e85b9589c7de4a164be308b819d3dea6c703", "best_bid": "0.694", "best_ask": "0.711"}, {"asset_id": "79849296060580317277275866407031080149422127632028665473147696931641259289529", "price": "0.307", "size": "77.16", "side": "SELL", "hash": "4388f77e73cffb7877e9ba993f22021020269f0b", "best_bid": "0.289", "best_ask": "0.306"}], "timestamp": "1769384214916", "event_type": "price_change"}}
{"_local_timestamp": "2026-01-25T23:36:55.046578+00:00", "data": {"market": "0x3b7fa5e73b58e3e8db12f33b0888ce58c24d6249cc237581ebe11ac4867dd7b7", "price_changes": [{"asset_id": "2058086706657815889669487757317075047972583222463683616694793460955010144892", "price": "0.71", "size": "40", "side": "BUY", "hash": "020d34f15b5e0f0f01eae554ba19649c83339456", "best_bid": "0.78", "best_ask": "0.8"}, {"asset_id": "84798712361559471793400029586324344677411006191640081141558912454287016164875", "price": "0.29", "size": "40", "side": "SELL", "hash": "9d6a9ee0c5d403da301d3b9b08582e70dd3385bf", "best_bid": "0.2", "best_ask": "0.22"}], "timestamp": "1769384214961", "event_type": "price_change"}}
{"_local_timestamp": "2026-01-25T23:36:55.170468+00:00", "data": {"market": "0xb7427b891a0134371023603986edc842ce369e83dcc42f300e7a03049295d4b1", "price_changes": [{"asset_id": "109919329920505980115727737237456054640803613381042045664921404844196255236880", "price": "0.492", "size": "66.66", "side": "BUY", "hash": "51cc7cec46f41532a003c6439eb8ddca2f1a1bd8", "best_bid": "0.694", "best_ask": "0.711"}, {"asset_id": "79849296060580317277275866407031080149422127632028665473147696931641259289529", "price": "0.508", "size": "66.66", "side": "SELL", "hash": "266ccab43672d0d38392f19d24f463fbf4721daa", "best_bid": "0.289", "best_ask": "0.306"}], "timestamp": "1769384215014", "event_type": "price_change"}}
{"_local_timestamp": "2026-01-25T23:36:55.171207+00:00", "data": {"market": "0x3b7fa5e73b58e3e8db12f33b0888ce58c24d6249cc237581ebe11ac4867dd7b7", "price_changes": [{"asset_id": "2058086706657815889669487757317075047972583222463683616694793460955010144892", "price": "0.11", "size": "3125", "side": "BUY", "hash": "deeea6e0aa7a03f62540a40c488851cd8a35a40d", "best_bid": "0.78", "best_ask": "0.8"}, {"asset_id": "84798712361559471793400029586324344677411006191640081141558912454287016164875", "price": "0.89", "size": "3125", "side": "SELL", "hash": "595aefeb08ff428730c41e7b055ffd3d9b982a2e", "best_bid": "0.2", "best_ask": "0.22"}], "timestamp": "1769384215024", "event_type": "price_change"}}
{"_local_timestamp": "2026-01-25T23:36:55.171905+00:00", "data": {"market": "0xb7427b891a0134371023603986edc842ce369e83dcc42f300e7a03049295d4b1", "price_changes": [{"asset_id": "109919329920505980115727737237456054640803613381042045664921404844196255236880", "price": "0.29", "size": "118.96", "side": "BUY", "hash": "8d1e0af14faf22570f891ed9813082ec43be6cd0", "best_bid": "0.694", "best_ask": "0.711"}, {"asset_id": "79849296060580317277275866407031080149422127632028665473147696931641259289529", "price": "0.71", "size": "118.96", "side": "SELL", "hash": "f8d4b98c8d59f311218441c191313752ae8dba44", "best_bid": "0.289", "best_ask": "0.306"}], "timestamp": "1769384215026", "event_type": "price_change"}}
{"_local_timestamp": "2026-01-25T23:36:55.172302+00:00", "data": {"market": "0xb7427b891a0134371023603986edc842ce369e83dcc42f300e7a03049295d4b1", "price_changes": [{"asset_id": "109919329920505980115727737237456054640803613381042045664921404844196255236880", "price": "0.14", "size": "0", "side": "BUY", "hash": "8d1e0af14faf22570f891ed9813082ec43be6cd0", "best_bid": "0.694", "best_ask": "0.711"}, {"asset_id": "79849296060580317277275866407031080149422127632028665473147696931641259289529", "price": "0.86", "size": "0", "side": "SELL", "hash": "f8d4b98c8d59f311218441c191313752ae8dba44", "best_bid": "0.289", "best_ask": "0.306"}], "timestamp": "1769384215026", "event_type": "price_change"}}
{"_local_timestamp": "2026-01-25T23:36:55.177897+00:00", "data": {"market": "0xd94cb5bf446cb8142d22091a40ba14d8c7355bd06fda75e61e25207135348550", "price_changes": [{"asset_id": "73232075333787574101356206392441747050603477997678734507064104196778724283091", "price": "0.01", "size": "8000", "side": "BUY", "hash": "53a5ad89f265599ae06f6255de2920d647850996", "best_bid": "0.995", "best_ask": "0.996"}, {"asset_id": "58192906727610480118792319554990896451617120222517723334233116219918933677749", "price": "0.99", "size": "8000", "side": "SELL", "hash": "7a2b792850fc5ae01e93dbb94b3674f4088ddf42", "best_bid": "0.004", "best_ask": "0.005"}], "timestamp": "1769384215024", "event_type": "price_change"}}
{"_local_timestamp": "2026-01-25T23:36:55.194880+00:00", "data": {"market": "0xb7427b891a0134371023603986edc842ce369e83dcc42f300e7a03049295d4b1", "price_changes": [{"asset_id": "79849296060580317277275866407031080149422127632028665473147696931641259289529", "price": "0.29", "size": "41.95", "side": "BUY", "hash": "9430717316701ca87638dd01b53867fe0b6286dc", "best_bid": "0.29", "best_ask": "0.306"}, {"asset_id": "109919329920505980115727737237456054640803613381042045664921404844196255236880", "price": "0.71", "size": "41.95", "side": "SELL", "hash": "db70f8ae3913cd2498e9b5901fcb31a38ffbaebd", "best_bid": "0.694", "best_ask": "0.71"}], "timestamp": "1769384215052", "event_type": "price_change"}}
{"_local_timestamp": "2026-01-25T23:36:55.195328+00:00", "data": {"market": "0xb7427b891a0134371023603986edc842ce369e83dcc42f300e7a03049295d4b1", "price_changes": [{"asset_id": "109919329920505980115727737237456054640803613381042045664921404844196255236880", "price": "0.291", "size": "66.66", "side": "BUY", "hash": "b270bfc241d4df1bd914c9ab457fcac0a54937eb", "best_bid": "0.694", "best_ask": "0.71"}, {"asset_id": "79849296060580317277275866407031080149422127632028665473147696931641259289529", "price": "0.709", "size": "66.66", "side": "SELL", "hash": "cca3ec1b24c9b796fb4c2265e36108bf8b1b393d", "best_bid": "0.29", "best_ask": "0.306"}], "timestamp": "1769384215065", "event_type": "price_change"}}
{"_local_timestamp": "2026-01-25T23:36:55.294556+00:00", "data": {"market": "0x1198b4cfb84b6078c6f432a9b034ae7d6047ca462fcee0f1895d1d94f5392bd6", "price_changes": [{"asset_id": "48633487062848646741583673336029083373164703684898528527193929763953273671096", "price": "0.009", "size": "0", "side": "BUY", "hash": "875c07b4a3e1b8ca3f88a7ffc4a208d980bf0990", "best_bid": "0.01", "best_ask": "0.022"}, {"asset_id": "90632278970929861972446673124743838350086669096023265555286080414820908223619", "price": "0.991", "size": "0", "side": "SELL", "hash": "7fce6f559a52bb9a06e7d1b1e9c69be1d9a453e9", "best_bid": "0.978", "best_ask": "0.99"}], "timestamp": "1769384215222", "event_type": "price_change"}}
{"_local_timestamp": "2026-01-25T23:36:55.935254+00:00", "data": {"market": "0x1198b4cfb84b6078c6f432a9b034ae7d6047ca462fcee0f1895d1d94f5392bd6", "price_changes": [{"asset_id": "48633487062848646741583673336029083373164703684898528527193929763953273671096", "price": "0.007", "size": "19.62", "side": "BUY", "hash": "01d1d226d4464a4c69a9943deb8447923f224ec7", "best_bid": "0.01", "best_ask": "0.022"}, {"asset_id": "90632278970929861972446673124743838350086669096023265555286080414820908223619", "price": "0.993", "size": "19.62", "side": "SELL", "hash": "27b2f603e160a8021fd26940ac11515275f47a7e", "best_bid": "0.978", "best_ask": "0.99"}], "timestamp": "1769384215715", "event_type": "price_change"}}
{"_local_timestamp": "2026-01-25T23:36:56.117836+00:00", "data": {"market": "0x3b7fa5e73b58e3e8db12f33b0888ce58c24d6249cc237581ebe11ac4867dd7b7", "price_changes": [{"asset_id": "2058086706657815889669487757317075047972583222463683616694793460955010144892", "price": "0.12", "size": "2700", "side": "BUY", "hash": "a9df08bfbf34792af1de3217314be67a962bf76f", "best_bid": "0.78", "best_ask": "0.8"}, {"asset_id": "84798712361559471793400029586324344677411006191640081141558912454287016164875", "price": "0.88", "size": "2700", "side": "SELL", "hash": "ec28a42db275aa1d292d5387add2755fa0671c29", "best_bid": "0.2", "best_ask": "0.22"}], "timestamp": "1769384215707", "event_type": "price_change"}}
{"_local_timestamp": "2026-01-25T23:36:56.122508+00:00", "data": {"market": "0xd94cb5bf446cb8142d22091a40ba14d8c7355bd06fda75e61e25207135348550", "price_changes": [{"asset_id": "73232075333787574101356206392441747050603477997678734507064104196778724283091", "price": "0.05", "size": "730", "side": "BUY", "hash": "f40f835580f2c70aa997a666ad772305b4d5a1f4", "best_bid": "0.995", "best_ask": "0.996"}, {"asset_id": "58192906727610480118792319554990896451617120222517723334233116219918933677749", "price": "0.95", "size": "730", "side": "SELL", "hash": "639b7183c7d7fe84f9b83ab14dc046068e3e386f", "best_bid": "0.004", "best_ask": "0.005"}], "timestamp": "1769384215709", "event_type": "price_change"}}
{"_local_timestamp": "2026-01-25T23:36:56.134737+00:00", "data": {"market": "0xb7427b891a0134371023603986edc842ce369e83dcc42f300e7a03049295d4b1", "price_changes": [{"asset_id": "109919329920505980115727737237456054640803613381042045664921404844196255236880", "price": "0.291", "size": "166.66", "side": "BUY", "hash": "669b10f2e2cba851dc5856e50d776774b82d80cb", "best_bid": "0.694", "best_ask": "0.71"}, {"asset_id": "79849296060580317277275866407031080149422127632028665473147696931641259289529", "price": "0.709", "size": "166.66", "side": "SELL", "hash": "7fc98825dffdec1d415b2a7cc5748731e3596888", "best_bid": "0.29", "best_ask": "0.306"}], "timestamp": "1769384215710", "event_type": "price_change"}}
{"_local_timestamp": "2026-01-25T23:36:56.201842+00:00", "data": {"market": "0xb7427b891a0134371023603986edc842ce369e83dcc42f300e7a03049295d4b1", "price_changes": [{"asset_id": "109919329920505980115727737237456054640803613381042045664921404844196255236880", "price": "0.11", "size": "634.09", "side": "BUY", "hash": "a4278bb984178f775632e1495c8824c41af8a1de", "best_bid": "0.694", "best_ask": "0.71"}, {"asset_id": "79849296060580317277275866407031080149422127632028665473147696931641259289529", "price": "0.89", "size": "634.09", "side": "SELL", "hash": "2d141e97b35a92f197dd951bd733c0cc83f9195b", "best_bid": "0.29", "best_ask": "0.306"}], "timestamp": "1769384215769", "event_type": "price_change"}}
{"_local_timestamp": "2026-01-25T23:36:56.282326+00:00", "data": {"market": "0x1198b4cfb84b6078c6f432a9b034ae7d6047ca462fcee0f1895d1d94f5392bd6", "price_changes": [{"asset_id": "48633487062848646741583673336029083373164703684898528527193929763953273671096", "price": "0.009", "size": "19.62", "side": "BUY", "hash": "42cc09073c72acf073a96be319e6c05d265de0ed", "best_bid": "0.01", "best_ask": "0.022"}, {"asset_id": "90632278970929861972446673124743838350086669096023265555286080414820908223619", "price": "0.991", "size": "19.62", "side": "SELL", "hash": "d0d854292a37f65de6dfad6f8be82ae13fc11118", "best_bid": "0.978", "best_ask": "0.99"}], "timestamp": "1769384215826", "event_type": "price_change"}}
{"_local_timestamp": "2026-01-25T23:36:56.282753+00:00", "data": {"market": "0x1198b4cfb84b6078c6f432a9b034ae7d6047ca462fcee0f1895d1d94f5392bd6", "price_changes": [{"asset_id": "48633487062848646741583673336029083373164703684898528527193929763953273671096", "price": "0.011", "size": "19.62", "side": "BUY", "hash": "9754fcbbddd630b07c7972be7f98a7b4b554169f", "best_bid": "0.011", "best_ask": "0.022"}, {"asset_id": "90632278970929861972446673124743838350086669096023265555286080414820908223619", "price": "0.989", "size": "19.62", "side": "SELL", "hash": "d4f4787749136893b18260e6e99d3792e58c5951", "best_bid": "0.978", "best_ask": "0.989"}], "timestamp": "1769384215832", "event_type": "price_change"}}
{"_local_timestamp": "2026-01-25T23:36:57.590490+00:00", "data": {"market": "0x1198b4cfb84b6078c6f432a9b034ae7d6047ca462fcee0f1895d1d94f5392bd6", "price_changes": [{"asset_id": "48633487062848646741583673336029083373164703684898528527193929763953273671096", "price": "0.004", "size": "2336.1", "side": "BUY", "hash": "65a714f49797ccef76b7a31ecf787cd04ddfa88f", "best_bid": "0.011", "best_ask": "0.022"}, {"asset_id": "90632278970929861972446673124743838350086669096023265555286080414820908223619", "price": "0.996", "size": "2336.1", "side": "SELL", "hash": "5a89aa20f6367b51323231bf5276395653dc2c89", "best_bid": "0.978", "best_ask": "0.989"}], "timestamp": "1769384217227", "event_type": "price_change"}}
{"_local_timestamp": "2026-01-25T23:37:03.697955+00:00", "data": {"market": "0x1198b4cfb84b6078c6f432a9b034ae7d6047ca462fcee0f1895d1d94f5392bd6", "price_changes": [{"asset_id": "48633487062848646741583673336029083373164703684898528527193929763953273671096", "price": "0.005", "size": "300", "side": "BUY", "hash": "6ec7be7b6bd826a6351eaed49218c58b75b5be50", "best_bid": "0.011", "best_ask": "0.022"}, {"asset_id": "90632278970929861972446673124743838350086669096023265555286080414820908223619", "price": "0.995", "size": "300", "side": "SELL", "hash": "c126efb17f761b8346fc34cbd62e9303bf780b6b", "best_bid": "0.978", "best_ask": "0.989"}], "timestamp": "1769384223624", "event_type": "price_change"}}
{"_local_timestamp": "2026-01-25T23:37:04.033837+00:00", "data": {"market": "0x3b7fa5e73b58e3e8db12f33b0888ce58c24d6249cc237581ebe11ac4867dd7b7", "price_changes": [{"asset_id": "84798712361559471793400029586324344677411006191640081141558912454287016164875", "price": "0.31", "size": "150", "side": "SELL", "hash": "736775e1beebd7723f541d6920f045e0b32bc93a", "best_bid": "0.2", "best_ask": "0.22"}, {"asset_id": "2058086706657815889669487757317075047972583222463683616694793460955010144892", "price": "0.69", "size": "150", "side": "BUY", "hash": "8a2e0f4f80e5407d696ecbf3e7bc4483df475c69", "best_bid": "0.78", "best_ask": "0.8"}], "timestamp": "1769384223951", "event_type": "price_change"}}
{"_local_timestamp": "2026-01-25T23:37:04.038828+00:00", "data": {"market": "0x3b7fa5e73b58e3e8db12f33b0888ce58c24d6249cc237581ebe11ac4867dd7b7", "price_changes": [{"asset_id": "84798712361559471793400029586324344677411006191640081141558912454287016164875", "price": "0.34", "size": "0", "side": "SELL", "hash": "736775e1beebd7723f541d6920f045e0b32bc93a", "best_bid": "0.2", "best_ask": "0.22"}, {"asset_id": "2058086706657815889669487757317075047972583222463683616694793460955010144892", "price": "0.66", "size": "0", "side": "BUY", "hash": "8a2e0f4f80e5407d696ecbf3e7bc4483df475c69", "best_bid": "0.78", "best_ask": "0.8"}], "timestamp": "1769384223951", "event_type": "price_change"}}
{"_local_timestamp": "2026-01-25T23:37:04.040551+00:00", "data": {"market": "0x3b7fa5e73b58e3e8db12f33b0888ce58c24d6249cc237581ebe11ac4867dd7b7", "price_changes": [{"asset_id": "84798712361559471793400029586324344677411006191640081141558912454287016164875", "price": "0.25", "size": "0", "side": "SELL", "hash": "736775e1beebd7723f541d6920f045e0b32bc93a", "best_bid": "0.2", "best_ask": "0.22"}, {"asset_id": "2058086706657815889669487757317075047972583222463683616694793460955010144892", "price": "0.75", "size": "0", "side": "BUY", "hash": "8a2e0f4f80e5407d696ecbf3e7bc4483df475c69", "best_bid": "0.78", "best_ask": "0.8"}], "timestamp": "1769384223951", "event_type": "price_change"}}
{"_local_timestamp": "2026-01-25T23:37:04.041365+00:00", "data": {"market": "0x3b7fa5e73b58e3e8db12f33b0888ce58c24d6249cc237581ebe11ac4867dd7b7", "price_changes": [{"asset_id": "84798712361559471793400029586324344677411006191640081141558912454287016164875", "price": "0.22", "size": "172.52", "side": "SELL", "hash": "736775e1beebd7723f541d6920f045e0b32bc93a", "best_bid": "0.2", "best_ask": "0.22"}, {"asset_id": "2058086706657815889669487757317075047972583222463683616694793460955010144892", "price": "0.78", "size": "172.52", "side": "BUY", "hash": "8a2e0f4f80e5407d696ecbf3e7bc4483df475c69", "best_bid": "0.78", "best_ask": "0.8"}], "timestamp": "1769384223951", "event_type": "price_change"}}
{"_local_timestamp": "2026-01-25T23:37:04.041748+00:00", "data": {"market": "0x3b7fa5e73b58e3e8db12f33b0888ce58c24d6249cc237581ebe11ac4867dd7b7", "price_changes": [{"asset_id": "84798712361559471793400029586324344677411006191640081141558912454287016164875", "price": "0.28", "size": "0", "side": "SELL", "hash": "736775e1beebd7723f541d6920f045e0b32bc93a", "best_bid": "0.2", "best_ask": "0.22"}, {"asset_id": "2058086706657815889669487757317075047972583222463683616694793460955010144892", "price": "0.72", "size": "0", "side": "BUY", "hash": "8a2e0f4f80e5407d696ecbf3e7bc4483df475c69", "best_bid": "0.78", "best_ask": "0.8"}], "timestamp": "1769384223951", "event_type": "price_change"}}
{"_local_timestamp": "2026-01-25T23:37:04.578262+00:00", "data": {"market": "0x3b7fa5e73b58e3e8db12f33b0888ce58c24d6249cc237581ebe11ac4867dd7b7", "price_changes": [{"asset_id": "2058086706657815889669487757317075047972583222463683616694793460955010144892", "price": "0.11", "size": "125", "side": "BUY", "hash": "49ff1d21d33c7749a337ca9ce63657811bf9852f", "best_bid": "0.78", "best_ask": "0.8"}, {"asset_id": "84798712361559471793400029586324344677411006191640081141558912454287016164875", "price": "0.89", "size": "125", "side": "SELL", "hash": "9eb1d17512a53b61c41b40a276876a3715c64111", "best_bid": "0.2", "best_ask": "0.22"}], "timestamp": "1769384224511", "event_type": "price_change"}}
{"_local_timestamp": "2026-01-25T23:37:04.690920+00:00", "data": {"market": "0x3b7fa5e73b58e3e8db12f33b0888ce58c24d6249cc237581ebe11ac4867dd7b7", "price_changes": [{"asset_id": "2058086706657815889669487757317075047972583222463683616694793460955010144892", "price": "0.73", "size": "6", "side": "BUY", "hash": "adaa956771827290e61cc9532f50342691860049", "best_bid": "0.78", "best_ask": "0.8"}, {"asset_id": "84798712361559471793400029586324344677411006191640081141558912454287016164875", "price": "0.27", "size": "6", "side": "SELL", "hash": "6f2e3b27c644ed01f2c58969432b1d762b0a26a0", "best_bid": "0.2", "best_ask": "0.22"}], "timestamp": "1769384224618", "event_type": "price_change"}}
{"_local_timestamp": "2026-01-25T23:37:04.715012+00:00", "data": {"market": "0x3b7fa5e73b58e3e8db12f33b0888ce58c24d6249cc237581ebe11ac4867dd7b7", "price_changes": [{"asset_id": "2058086706657815889669487757317075047972583222463683616694793460955010144892", "price": "0.72", "size": "20", "side": "BUY", "hash": "c806579bc3a005a376c81684633030512de052eb", "best_bid": "0.78", "best_ask": "0.8"}, {"asset_id": "84798712361559471793400029586324344677411006191640081141558912454287016164875", "price": "0.28", "size": "20", "side": "SELL", "hash": "01c9eeaad12f908ada7d138eb56eee45bf8503e5", "best_bid": "0.2", "best_ask": "0.22"}], "timestamp": "1769384224643", "event_type": "price_change"}}
{"_local_timestamp": "2026-01-25T23:37:08.586639+00:00", "data": {"market": "0xb7427b891a0134371023603986edc842ce369e83dcc42f300e7a03049295d4b1", "price_changes": [{"asset_id": "79849296060580317277275866407031080149422127632028665473147696931641259289529", "price": "0.289", "size": "30", "side": "BUY", "hash": "4be7a8d4c83b460352b4e97dbd217d5dfa8921f0", "best_bid": "0.29", "best_ask": "0.306"}, {"asset_id": "109919329920505980115727737237456054640803613381042045664921404844196255236880", "price": "0.711", "size": "30", "side": "SELL", "hash": "bd4de98ec6510c19f758b89b954819bda79b2150", "best_bid": "0.694", "best_ask": "0.71"}], "timestamp": "1769384228515", "event_type": "price_change"}}
{"_local_timestamp": "2026-01-25T23:37:08.587005+00:00", "data": {"market": "0x7af772ffd32b7726faabc964493d3e3b187186dcaea0d8e60110da9aa0771a42", "price_changes": [{"asset_id": "33977621156566454256243426751711042651548860329437292067732819030497867836755", "price": "0.954", "size": "0", "side": "BUY", "hash": "783fa7b490e20573a4feda8785a6797c225af1d7", "best_bid": "0.957", "best_ask": "0.978"}, {"asset_id": "21959934108087357306634929435608062329442380143600039127574312668523401447958", "price": "0.046", "size": "0", "side": "SELL", "hash": "caf79dad23b669f83c1cf0f428c88dc70cd4511c", "best_bid": "0.022", "best_ask": "0.043"}], "timestamp": "1769384228515", "event_type": "price_change"}}
{"_local_timestamp": "2026-01-25T23:37:08.587262+00:00", "data": {"market": "0x7af772ffd32b7726faabc964493d3e3b187186dcaea0d8e60110da9aa0771a42", "price_changes": [{"asset_id": "33977621156566454256243426751711042651548860329437292067732819030497867836755", "price": "0.955", "size": "0", "side": "BUY", "hash": "783fa7b490e20573a4feda8785a6797c225af1d7", "best_bid": "0.957", "best_ask": "0.978"}, {"asset_id": "21959934108087357306634929435608062329442380143600039127574312668523401447958", "price": "0.045", "size": "0", "side": "SELL", "hash": "caf79dad23b669f83c1cf0f428c88dc70cd4511c", "best_bid": "0.022", "best_ask": "0.043"}], "timestamp": "1769384228515", "event_type": "price_change"}}
{"_local_timestamp": "2026-01-25T23:37:09.022986+00:00", "data": {"market": "0xb7427b891a0134371023603986edc842ce369e83dcc42f300e7a03049295d4b1", "price_changes": [{"asset_id": "79849296060580317277275866407031080149422127632028665473147696931641259289529", "price": "0.289", "size": "0", "side": "BUY", "hash": "5c80d0ccf11f5be655e33cde75b29c61819d74b4", "best_bid": "0.29", "best_ask": "0.306"}, {"asset_id": "109919329920505980115727737237456054640803613381042045664921404844196255236880", "price": "0.711", "size": "0", "side": "SELL", "hash": "c09228688aa64c07c020e3cbed3df4a777cd914c", "best_bid": "0.694", "best_ask": "0.71"}], "timestamp": "1769384228953", "event_type": "price_change"}}
{"_local_timestamp": "2026-01-25T23:37:09.098173+00:00", "data": {"market": "0xb7427b891a0134371023603986edc842ce369e83dcc42f300e7a03049295d4b1", "price_changes": [{"asset_id": "79849296060580317277275866407031080149422127632028665473147696931641259289529", "price": "0.281", "size": "71.95", "side": "BUY", "hash": "67dce79e165bc0ae25efc62e837d54872f76d815", "best_bid": "0.29", "best_ask": "0.306"}, {"asset_id": "109919329920505980115727737237456054640803613381042045664921404844196255236880", "price": "0.719", "size": "71.95", "side": "SELL", "hash": "b903a4cdda2eabba10e120f1b95eb26e9647e5eb", "best_bid": "0.694", "best_ask": "0.71"}], "timestamp": "1769384229009", "event_type": "price_change"}}
{"_local_timestamp": "2026-01-25T23:37:10.218058+00:00", "data": {"market": "0xd94cb5bf446cb8142d22091a40ba14d8c7355bd06fda75e61e25207135348550", "price_changes": [{"asset_id": "73232075333787574101356206392441747050603477997678734507064104196778724283091", "price": "0.05", "size": "3730", "side": "BUY", "hash": "9d7fe73260a32c0eaa138dc3ae4b765f16869ee6", "best_bid": "0.995", "best_ask": "0.996"}, {"asset_id": "58192906727610480118792319554990896451617120222517723334233116219918933677749", "price": "0.95", "size": "3730", "side": "SELL", "hash": "d66f0e66122d8a1d85e813d3757e44b9558d8c98", "best_bid": "0.004", "best_ask": "0.005"}], "timestamp": "1769384230147", "event_type": "price_change"}}
{"_local_timestamp": "2026-01-25T23:37:10.754689+00:00", "data": {"market": "0xb7427b891a0134371023603986edc842ce369e83dcc42f300e7a03049295d4b1", "price_changes": [{"asset_id": "109919329920505980115727737237456054640803613381042045664921404844196255236880", "price": "0.684", "size": "0", "side": "BUY", "hash": "d349cddfc3977c0e36c44e329604d48b4ed78b36", "best_bid": "0.694", "best_ask": "0.71"}, {"asset_id": "79849296060580317277275866407031080149422127632028665473147696931641259289529", "price": "0.316", "size": "0", "side": "SELL", "hash": "6a989c77e86a602e08002c76e27b243375a31096", "best_bid": "0.29", "best_ask": "0.306"}], "timestamp": "1769384230673", "event_type": "price_change"}}
{"_local_timestamp": "2026-01-25T23:37:11.544891+00:00", "data": {"market": "0x7e897a7826222708d178062c82e9166b37a98df0ce92ace40f3b9357f2526157", "price_changes": [{"asset_id": "8417326734150529989790022001226615602996938938967740280020227231905495513816", "price": "0.35", "size": "768.57", "side": "BUY", "hash": "818362e116226d857cc5413c659b57a118e1889b", "best_bid": "0.987", "best_ask": "0.99"}, {"asset_id": "85126848831263873777721669142266306730253139367446060083090258474801299057771", "price": "0.65", "size": "768.57", "side": "SELL", "hash": "9fddcdd23c10dd0669d1ee9f42e919f0c90a76f8", "best_bid": "0.01", "best_ask": "0.013"}], "timestamp": "1769384231476", "event_type": "price_change"}}
{"_local_timestamp": "2026-01-25T23:37:14.883643+00:00", "data": {"market": "0x7e897a7826222708d178062c82e9166b37a98df0ce92ace40f3b9357f2526157", "price_changes": [{"asset_id": "8417326734150529989790022001226615602996938938967740280020227231905495513816", "price": "0.35", "size": "68.57", "side": "BUY", "hash": "9af8a35c6d1e6b5a303328b000381354b0025679", "best_bid": "0.987", "best_ask": "0.99"}, {"asset_id": "85126848831263873777721669142266306730253139367446060083090258474801299057771", "price": "0.65", "size": "68.57", "side": "SELL", "hash": "73298e909fd5075bfd23af03810e3e6f5a549f07", "best_bid": "0.01", "best_ask": "0.013"}], "timestamp": "1769384234811", "event_type": "price_change"}}
{"_local_timestamp": "2026-01-25T23:37:17.829562+00:00", "data": {"market": "0xd94cb5bf446cb8142d22091a40ba14d8c7355bd06fda75e61e25207135348550", "price_changes": [{"asset_id": "73232075333787574101356206392441747050603477997678734507064104196778724283091", "price": "0.05", "size": "730", "side": "BUY", "hash": "73341a5307468cde84f17f3c2f4aa12f8c5a0947", "best_bid": "0.995", "best_ask": "0.996"}, {"asset_id": "58192906727610480118792319554990896451617120222517723334233116219918933677749", "price": "0.95", "size": "730", "side": "SELL", "hash": "15d27dd299e59de0483b47e3badefbda1425f88d", "best_bid": "0.004", "best_ask": "0.005"}], "timestamp": "1769384237756", "event_type": "price_change"}}
{"_local_timestamp": "2026-01-25T23:37:18.207668+00:00", "data": {"market": "0x7e897a7826222708d178062c82e9166b37a98df0ce92ace40f3b9357f2526157", "price_changes": [{"asset_id": "8417326734150529989790022001226615602996938938967740280020227231905495513816", "price": "0.979", "size": "360", "side": "BUY", "hash": "3bfeb5b374141b90fee03b7c723c2d9bf588fbf7", "best_bid": "0.987", "best_ask": "0.99"}, {"asset_id": "85126848831263873777721669142266306730253139367446060083090258474801299057771", "price": "0.021", "size": "360", "side": "SELL", "hash": "4351831674c58bc9c670c0483b23537bc7bd33fc", "best_bid": "0.01", "best_ask": "0.013"}], "timestamp": "1769384238132", "event_type": "price_change"}}
{"_local_timestamp": "2026-01-25T23:37:18.216779+00:00", "data": {"market": "0x7e897a7826222708d178062c82e9166b37a98df0ce92ace40f3b9357f2526157", "price_changes": [{"asset_id": "85126848831263873777721669142266306730253139367446060083090258474801299057771", "price": "0.002", "size": "2362.65", "side": "BUY", "hash": "a1db990128a76bcc4055c1eb443ecc0d933ba67b", "best_bid": "0.01", "best_ask": "0.013"}, {"asset_id": "8417326734150529989790022001226615602996938938967740280020227231905495513816", "price": "0.998", "size": "2362.65", "side": "SELL", "hash": "c3bc69208a61db61ce92f33f6c5ecb2e42b5e700", "best_bid": "0.987", "best_ask": "0.99"}], "timestamp": "1769384238133", "event_type": "price_change"}}
{"_local_timestamp": "2026-01-25T23:37:32.661237+00:00", "data": {"market": "0xd94cb5bf446cb8142d22091a40ba14d8c7355bd06fda75e61e25207135348550", "price_changes": [{"asset_id": "73232075333787574101356206392441747050603477997678734507064104196778724283091", "price": "0.05", "size": "330", "side": "BUY", "hash": "b2f9a207e7159901d4220b1c804e2de9e5d25aa4", "best_bid": "0.995", "best_ask": "0.996"}, {"asset_id": "58192906727610480118792319554990896451617120222517723334233116219918933677749", "price": "0.95", "size": "330", "side": "SELL", "hash": "d9861c97481eed7a708d854093383ee61377d439", "best_bid": "0.004", "best_ask": "0.005"}], "timestamp": "1769384252552", "event_type": "price_change"}}
{"_local_timestamp": "2026-01-25T23:37:32.965633+00:00", "data": {"market": "0xd94cb5bf446cb8142d22091a40ba14d8c7355bd06fda75e61e25207135348550", "price_changes": [{"asset_id": "73232075333787574101356206392441747050603477997678734507064104196778724283091", "price": "0.02", "size": "3900", "side": "BUY", "hash": "63bb6dd2f11d8760f58ea7355f687de9f002b8b1", "best_bid": "0.995", "best_ask": "0.996"}, {"asset_id": "58192906727610480118792319554990896451617120222517723334233116219918933677749", "price": "0.98", "size": "3900", "side": "SELL", "hash": "3b35703a29ccaa9cc69f14089fe9887543f032a8", "best_bid": "0.004", "best_ask": "0.005"}], "timestamp": "1769384252872", "event_type": "price_change"}}
{"_local_timestamp": "2026-01-25T23:37:42.730189+00:00", "data": {"market": "0x1198b4cfb84b6078c6f432a9b034ae7d6047ca462fcee0f1895d1d94f5392bd6", "price_changes": [{"asset_id": "48633487062848646741583673336029083373164703684898528527193929763953273671096", "price": "0.01", "size": "299", "side": "BUY", "hash": "c366d6ed4620913d33711e7f93350822842836ff", "best_bid": "0.011", "best_ask": "0.022"}, {"asset_id": "90632278970929861972446673124743838350086669096023265555286080414820908223619", "price": "0.99", "size": "299", "side": "SELL", "hash": "abdd1e0819a9380b2641681cb0d3089af4e6090e", "best_bid": "0.978", "best_ask": "0.989"}], "timestamp": "1769384262657", "event_type": "price_change"}}
{"_local_timestamp": "2026-01-25T23:37:42.946624+00:00", "data": {"market": "0x3b7fa5e73b58e3e8db12f33b0888ce58c24d6249cc237581ebe11ac4867dd7b7", "price_changes": [{"asset_id": "2058086706657815889669487757317075047972583222463683616694793460955010144892", "price": "0.71", "size": "20", "side": "BUY", "hash": "35eac79794c7daffaf736b9ac40d6f8faecc840b", "best_bid": "0.78", "best_ask": "0.8"}, {"asset_id": "84798712361559471793400029586324344677411006191640081141558912454287016164875", "price": "0.29", "size": "20", "side": "SELL", "hash": "464f70cc7009becd5e38a10cbe9f32590145c8f9", "best_bid": "0.2", "best_ask": "0.22"}], "timestamp": "1769384262870", "event_type": "price_change"}}
{"_local_timestamp": "2026-01-25T23:37:43.099702+00:00", "data": {"market": "0x3b7fa5e73b58e3e8db12f33b0888ce58c24d6249cc237581ebe11ac4867dd7b7", "price_changes": [{"asset_id": "2058086706657815889669487757317075047972583222463683616694793460955010144892", "price": "0.7", "size": "74.51", "side": "BUY", "hash": "34236ff13f76f11ba47f95fa09e339341ec4e24b", "best_bid": "0.78", "best_ask": "0.8"}, {"asset_id": "84798712361559471793400029586324344677411006191640081141558912454287016164875", "price": "0.3", "size": "74.51", "side": "SELL", "hash": "6b443c0267969c671d2cd98a2036d5484c201056", "best_bid": "0.2", "best_ask": "0.22"}], "timestamp": "1769384263005", "event_type": "price_change"}}
{"_local_timestamp": "2026-01-25T23:37:57.068106+00:00", "data": {"market": "0x3b7fa5e73b58e3e8db12f33b0888ce58c24d6249cc237581ebe11ac4867dd7b7", "price_changes": [{"asset_id": "84798712361559471793400029586324344677411006191640081141558912454287016164875", "price": "0.25", "size": "7", "side": "SELL", "hash": "bd55889edb4e0efa90ee4e2c489e21028b76f56a", "best_bid": "0.2", "best_ask": "0.22"}, {"asset_id": "2058086706657815889669487757317075047972583222463683616694793460955010144892", "price": "0.75", "size": "7", "side": "BUY", "hash": "8c8daf86372883ed3170c4f946bed20f2c222518", "best_bid": "0.78", "best_ask": "0.8"}], "timestamp": "1769384276998", "event_type": "price_change"}}
{"_local_timestamp": "2026-01-25T23:37:57.068539+00:00", "data": {"market": "0x3b7fa5e73b58e3e8db12f33b0888ce58c24d6249cc237581ebe11ac4867dd7b7", "price_changes": [{"asset_id": "84798712361559471793400029586324344677411006191640081141558912454287016164875", "price": "0.22", "size": "179.52", "side": "SELL", "hash": "a4bc95cffae52d5fde48f715a7d91c21062cd4c7", "best_bid": "0.2", "best_ask": "0.22"}, {"asset_id": "2058086706657815889669487757317075047972583222463683616694793460955010144892", "price": "0.78", "size": "179.52", "side": "BUY", "hash": "2eb297be9e46c431ce4a209d591eb9388db19b2b", "best_bid": "0.78", "best_ask": "0.8"}], "timestamp": "1769384276999", "event_type": "price_change"}}
{"_local_timestamp": "2026-01-25T23:37:57.079697+00:00", "data": {"market": "0x3b7fa5e73b58e3e8db12f33b0888ce58c24d6249cc237581ebe11ac4867dd7b7", "price_changes": [{"asset_id": "84798712361559471793400029586324344677411006191640081141558912454287016164875", "price": "0.34", "size": "7", "side": "SELL", "hash": "3e163768f6994ac2f691deb9e14261e9af93a84a", "best_bid": "0.2", "best_ask": "0.22"}, {"asset_id": "2058086706657815889669487757317075047972583222463683616694793460955010144892", "price": "0.66", "size": "7", "side": "BUY", "hash": "b80ebff91ef9078cf80db6a3f486b7c421e7785d", "best_bid": "0.78", "best_ask": "0.8"}], "timestamp": "1769384277000", "event_type": "price_change"}}
{"_local_timestamp": "2026-01-25T23:37:57.087260+00:00", "data": {"market": "0x3b7fa5e73b58e3e8db12f33b0888ce58c24d6249cc237581ebe11ac4867dd7b7", "price_changes": [{"asset_id": "84798712361559471793400029586324344677411006191640081141558912454287016164875", "price": "0.31", "size": "157", "side": "SELL", "hash": "be6563a93fbf0b2bfcb1c7e8a4b52899e537a5b4", "best_bid": "0.2", "best_ask": "0.22"}, {"asset_id": "2058086706657815889669487757317075047972583222463683616694793460955010144892", "price": "0.69", "size": "157", "side": "BUY", "hash": "cde14f10a641bec102238734444e7ee4c90bba64", "best_bid": "0.78", "best_ask": "0.8"}], "timestamp": "1769384277003", "event_type": "price_change"}}
{"_local_timestamp": "2026-01-25T23:37:57.087550+00:00", "data": {"market": "0x3b7fa5e73b58e3e8db12f33b0888ce58c24d6249cc237581ebe11ac4867dd7b7", "price_changes": [{"asset_id": "84798712361559471793400029586324344677411006191640081141558912454287016164875", "price": "0.28", "size": "27", "side": "SELL", "hash": "8e6223d66fe5d3a84b3226a9f449e08d0ed4850d", "best_bid": "0.2", "best_ask": "0.22"}, {"asset_id": "2058086706657815889669487757317075047972583222463683616694793460955010144892", "price": "0.72", "size": "27", "side": "BUY", "hash": "847b28a17bf3f22e69fdde5e5950d538ccf1af3c", "best_bid": "0.78", "best_ask": "0.8"}], "timestamp": "1769384277004", "event_type": "price_change"}}
{"_local_timestamp": "2026-01-25T23:37:57.161287+00:00", "data": {"market": "0x1198b4cfb84b6078c6f432a9b034ae7d6047ca462fcee0f1895d1d94f5392bd6", "price_changes": [{"asset_id": "90632278970929861972446673124743838350086669096023265555286080414820908223619", "price": "0.918", "size": "0", "side": "BUY", "hash": "31e866ed7f2724e87f35c8106d9d766fc87ebbe7", "best_bid": "0.978", "best_ask": "0.989"}, {"asset_id": "48633487062848646741583673336029083373164703684898528527193929763953273671096", "price": "0.082", "size": "0", "side": "SELL", "hash": "eb7e6af490df9f2828fc241aaa8b488f8db49e43", "best_bid": "0.011", "best_ask": "0.022"}], "timestamp": "1769384277086", "event_type": "price_change"}}
{"_local_timestamp": "2026-01-25T23:37:57.161682+00:00", "data": {"market": "0x1278f161b546f237cf9a029d9383ff5da371ff047a5adad48ee3243a6f93b6fb", "price_changes": [{"asset_id": "83477010551081586181287014200977553131804751829676583771272159234562620010416", "price": "0.862", "size": "0", "side": "BUY", "hash": "1cda935d5cb42dc86dcac2a2032b0c96056a20ae", "best_bid": "0.971", "best_ask": "0.978"}, {"asset_id": "91844810080062648436529776287166848099843976612137997296770938567257266660379", "price": "0.138", "size": "0", "side": "SELL", "hash": "90a3a91e9608b4410b86f82dc20425786cc56258", "best_bid": "0.022", "best_ask": "0.029"}], "timestamp": "1769384277086", "event_type": "price_change"}}
{"_local_timestamp": "2026-01-25T23:37:57.330624+00:00", "data": {"market": "0x1198b4cfb84b6078c6f432a9b034ae7d6047ca462fcee0f1895d1d94f5392bd6", "price_changes": [{"asset_id": "90632278970929861972446673124743838350086669096023265555286080414820908223619", "price": "0.92", "size": "20", "side": "BUY", "hash": "55c77a183f4be52a6f2da9c94b7b36e3c8a30543", "best_bid": "0.978", "best_ask": "0.989"}, {"asset_id": "48633487062848646741583673336029083373164703684898528527193929763953273671096", "price": "0.08", "size": "20", "side": "SELL", "hash": "b9ee74abdfc569ba726f588d1997b26e7d00479b", "best_bid": "0.011", "best_ask": "0.022"}], "timestamp": "1769384277260", "event_type": "price_change"}}
{"_local_timestamp": "2026-01-25T23:37:57.558035+00:00", "data": {"market": "0x1278f161b546f237cf9a029d9383ff5da371ff047a5adad48ee3243a6f93b6fb", "price_changes": [{"asset_id": "91844810080062648436529776287166848099843976612137997296770938567257266660379", "price": "0.01", "size": "1050", "side": "BUY", "hash": "b6bb5c3a6a77b3589970c8f19cbffbf55bba922a", "best_bid": "0.022", "best_ask": "0.029"}, {"asset_id": "83477010551081586181287014200977553131804751829676583771272159234562620010416", "price": "0.99", "size": "1050", "side": "SELL", "hash": "87ec380418a26605ab7128cd5b17b1ef38fce211", "best_bid": "0.971", "best_ask": "0.978"}], "timestamp": "1769384277488", "event_type": "price_change"}}
{"_local_timestamp": "2026-01-25T23:37:58.470717+00:00", "data": {"market": "0x1198b4cfb84b6078c6f432a9b034ae7d6047ca462fcee0f1895d1d94f5392bd6", "price_changes": [{"asset_id": "90632278970929861972446673124743838350086669096023265555286080414820908223619", "price": "0.919", "size": "0", "side": "BUY", "hash": "693c291b70d74dd460305a46751971d2101acc09", "best_bid": "0.978", "best_ask": "0.989"}, {"asset_id": "48633487062848646741583673336029083373164703684898528527193929763953273671096", "price": "0.081", "size": "0", "side": "SELL", "hash": "41ec8888004b49429ae012231791a78767fefe15", "best_bid": "0.011", "best_ask": "0.022"}], "timestamp": "1769384278396", "event_type": "price_change"}}
{"_local_timestamp": "2026-01-25T23:37:58.471089+00:00", "data": {"market": "0x3b7fa5e73b58e3e8db12f33b0888ce58c24d6249cc237581ebe11ac4867dd7b7", "price_changes": [{"asset_id": "2058086706657815889669487757317075047972583222463683616694793460955010144892", "price": "0.72", "size": "7", "side": "BUY", "hash": "b61341d9613e8a756db5bda830545d1464272028", "best_bid": "0.78", "best_ask": "0.8"}, {"asset_id": "84798712361559471793400029586324344677411006191640081141558912454287016164875", "price": "0.28", "size": "7", "side": "SELL", "hash": "c5bf58fcceab3e67bddc9824ab9bd403bd53b1c5", "best_bid": "0.2", "best_ask": "0.22"}], "timestamp": "1769384278396", "event_type": "price_change"}}
{"_local_timestamp": "2026-01-25T23:37:58.513198+00:00", "data": {"market": "0x3b7fa5e73b58e3e8db12f33b0888ce58c24d6249cc237581ebe11ac4867dd7b7", "price_changes": [{"asset_id": "2058086706657815889669487757317075047972583222463683616694793460955010144892", "price": "0.73", "size": "26", "side": "BUY", "hash": "adceed601b2f122755f15afe71a4ce448a428b11", "best_bid": "0.78", "best_ask": "0.8"}, {"asset_id": "84798712361559471793400029586324344677411006191640081141558912454287016164875", "price": "0.27", "size": "26", "side": "SELL", "hash": "8b46d4e5fb5d2bd3fb19c08cd1fd7b2db7f8e7ab", "best_bid": "0.2", "best_ask": "0.22"}], "timestamp": "1769384278430", "event_type": "price_change"}}
{"_local_timestamp": "2026-01-25T23:37:58.513503+00:00", "data": {"market": "0x1198b4cfb84b6078c6f432a9b034ae7d6047ca462fcee0f1895d1d94f5392bd6", "price_changes": [{"asset_id": "90632278970929861972446673124743838350086669096023265555286080414820908223619", "price": "0.921", "size": "20", "side": "BUY", "hash": "cf1ddd5ddc604047727e5bf14e5f4dd60476cd66", "best_bid": "0.978", "best_ask": "0.989"}, {"asset_id": "48633487062848646741583673336029083373164703684898528527193929763953273671096", "price": "0.079", "size": "20", "side": "SELL", "hash": "6e125af1d036d71ec7a8af72c3061fcde01056cc", "best_bid": "0.011", "best_ask": "0.022"}], "timestamp": "1769384278430", "event_type": "price_change"}}
{"_local_timestamp": "2026-01-25T23:37:58.523497+00:00", "data": {"market": "0x7e897a7826222708d178062c82e9166b37a98df0ce92ace40f3b9357f2526157", "price_changes": [{"asset_id": "8417326734150529989790022001226615602996938938967740280020227231905495513816", "price": "0.923", "size": "0", "side": "BUY", "hash": "3e8c6afb8c56ecd64941250a928d0e2ea2322b81", "best_bid": "0.987", "best_ask": "0.99"}, {"asset_id": "85126848831263873777721669142266306730253139367446060083090258474801299057771", "price": "0.077", "size": "0", "side": "SELL", "hash": "88f43c1f340a6558a74cce0508f70ab1c98092b1", "best_bid": "0.01", "best_ask": "0.013"}], "timestamp": "1769384278443", "event_type": "price_change"}}
{"_local_timestamp": "2026-01-25T23:37:58.684858+00:00", "data": {"market": "0xd94cb5bf446cb8142d22091a40ba14d8c7355bd06fda75e61e25207135348550", "price_changes": [{"asset_id": "73232075333787574101356206392441747050603477997678734507064104196778724283091", "price": "0.929", "size": "0", "side": "BUY", "hash": "a7436521b671dfa73b0936239cbdeff1ba3ab36c", "best_bid": "0.995", "best_ask": "0.996"}, {"asset_id": "58192906727610480118792319554990896451617120222517723334233116219918933677749", "price": "0.071", "size": "0", "side": "SELL", "hash": "a9e4bed06ff83cb09ad87344c4d2b09026b55e55", "best_bid": "0.004", "best_ask": "0.005"}], "timestamp": "1769384278616", "event_type": "price_change"}}
{"_local_timestamp": "2026-01-25T23:37:58.685287+00:00", "data": {"market": "0x7e897a7826222708d178062c82e9166b37a98df0ce92ace40f3b9357f2526157", "price_changes": [{"asset_id": "8417326734150529989790022001226615602996938938967740280020227231905495513816", "price": "0.901", "size": "0", "side": "BUY", "hash": "05aa7ccbe1aad8e3fdbeede89c2bcf09980b9fbe", "best_bid": "0.987", "best_ask": "0.99"}, {"asset_id": "85126848831263873777721669142266306730253139367446060083090258474801299057771", "price": "0.099", "size": "0", "side": "SELL", "hash": "cbe61b1bffe3d17fcc7ae4fdd1cc68d060cc7535", "best_bid": "0.01", "best_ask": "0.013"}], "timestamp": "1769384278616", "event_type": "price_change"}}
{"_local_timestamp": "2026-01-25T23:37:58.850832+00:00", "data": {"market": "0x7e897a7826222708d178062c82e9166b37a98df0ce92ace40f3b9357f2526157", "price_changes": [{"asset_id": "8417326734150529989790022001226615602996938938967740280020227231905495513816", "price": "0.93", "size": "20", "side": "BUY", "hash": "397ea6016a9888522244c0d1339457c80fad2e24", "best_bid": "0.987", "best_ask": "0.99"}, {"asset_id": "85126848831263873777721669142266306730253139367446060083090258474801299057771", "price": "0.07", "size": "20", "side": "SELL", "hash": "3942e5c4780cd4086eac67028578a27c4cf2b0c9", "best_bid": "0.01", "best_ask": "0.013"}], "timestamp": "1769384278765", "event_type": "price_change"}}
{"_local_timestamp": "2026-01-25T23:37:58.866703+00:00", "data": {"market": "0x7af772ffd32b7726faabc964493d3e3b187186dcaea0d8e60110da9aa0771a42", "price_changes": [{"asset_id": "33977621156566454256243426751711042651548860329437292067732819030497867836755", "price": "0.401", "size": "0", "side": "BUY", "hash": "5c9a0aa870e7b9838eaa7e0df0a43bae6abfc9c1", "best_bid": "0.957", "best_ask": "0.978"}, {"asset_id": "21959934108087357306634929435608062329442380143600039127574312668523401447958", "price": "0.599", "size": "0", "side": "SELL", "hash": "7de4a960bffc52ba1bb46e70a4073d3c990262d7", "best_bid": "0.022", "best_ask": "0.043"}], "timestamp": "1769384278791", "event_type": "price_change"}}
{"_local_timestamp": "2026-01-25T23:37:58.875491+00:00", "data": {"market": "0x7e897a7826222708d178062c82e9166b37a98df0ce92ace40f3b9357f2526157", "price_changes": [{"asset_id": "8417326734150529989790022001226615602996938938967740280020227231905495513816", "price": "0.05", "size": "3030", "side": "BUY", "hash": "1663ef8d730d82e6ee6796c79111122dbbbd13b6", "best_bid": "0.987", "best_ask": "0.99"}, {"asset_id": "85126848831263873777721669142266306730253139367446060083090258474801299057771", "price": "0.95", "size": "3030", "side": "SELL", "hash": "e7a6002ab8f9ed89c752ccb3fe0da354a43a2f26", "best_bid": "0.01", "best_ask": "0.013"}], "timestamp": "1769384278804", "event_type": "price_change"}}
{"_local_timestamp": "2026-01-25T23:38:00.269233+00:00", "data": {"market": "0xd94cb5bf446cb8142d22091a40ba14d8c7355bd06fda75e61e25207135348550", "price_changes": [{"asset_id": "73232075333787574101356206392441747050603477997678734507064104196778724283091", "price": "0.93", "size": "0", "side": "BUY", "hash": "4724fbe0cf409becd149b14be946b27276e82467", "best_bid": "0.995", "best_ask": "0.996"}, {"asset_id": "58192906727610480118792319554990896451617120222517723334233116219918933677749", "price": "0.07", "size": "0", "side": "SELL", "hash": "80916826ec2051e285a2072c3ca579d12250cd30", "best_bid": "0.004", "best_ask": "0.005"}], "timestamp": "1769384280184", "event_type": "price_change"}}
