{"_local_timestamp": "2026-01-25T23:40:54.895775+00:00", "data": [{"market": "0xc7e04626fbed6834456b0b9ed45e7da039ad826933e3abba81e26e71a79b2388", "asset_id": "108633032965983853701783501560325265009339710531442379830307955199797783135140", "timestamp": "1769384440258", "hash": "074bcdf39c24bdde414d78cc10b3b9ceb489fbff", "bids": [{"price": "0.01", "size": "3212.82"}, {"price": "0.02", "size": "1400"}, {"price": "0.03", "size": "6.52"}, {"price": "0.04", "size": "250"}, {"price": "0.05", "size": "30"}, {"price": "0.06", "size": "33"}, {"price": "0.07", "size": "7.94"}, {"price": "0.08", "size": "950"}, {"price": "0.13", "size": "586.53"}, {"price": "0.17", "size": "438.23"}, {"price": "0.18", "size": "6.22"}, {"price": "0.21", "size": "233.33"}, {"price": "0.22", "size": "91"}, {"price": "0.25", "size": "104"}, {"price": "0.26", "size": "15"}, {"price": "0.29", "size": "82.75"}, {"price": "0.3", "size": "10"}, {"price": "0.33", "size": "60.6"}, {"price": "0.41", "size": "160"}, {"price": "0.44", "size": "5"}, {"price": "0.45", "size": "50"}, {"price": "0.64", "size": "8.84"}, {"price": "0.68", "size": "150"}, {"price": "0.69", "size": "20"}, {"price": "0.81", "size": "10"}, {"price": "0.82", "size": "50"}], "asks": [{"price": "0.99", "size": "163.94"}, {"price": "0.98", "size": "149.29"}, {"price": "0.97", "size": "63.03"}, {"price": "0.95", "size": "82.53"}], "event_type": "book", "last_trade_price": ""}, {"market": "0x33315bd63d0cc17257c5d7524e5283639a5e17c6ce030d937f135aab02170c40", "asset_id": "92512666728361163935047824440150917945153592049030110328840756457871300635229", "timestamp": "1769384440257", "hash": "23c1c29abcd5f2ebff6ecf396c919da9e6b25fca", "bids": [{"price": "0.01", "size": "3112.93"}, {"price": "0.02", "size": "1400"}, {"price": "0.03", "size": "7.87"}, {"price": "0.04", "size": "250"}, {"price": "0.05", "size": "30"}, {"price": "0.06", "size": "33"}, {"price": "0.07", "size": "6.82"}, {"price": "0.09", "size": "900"}, {"price": "0.13", "size": "461.53"}, {"price": "0.18", "size": "327.77"}, {"price": "0.19", "size": "6.09"}, {"price": "0.2", "size": "15"}, {"price": "0.22", "size": "227.27"}, {"price": "0.23", "size": "10"}, {"price": "0.27", "size": "96.29"}, {"price": "0.31", "size": "927.41"}, {"price": "0.32", "size": "100"}, {"price": "0.33", "size": "71"}, {"price": "0.36", "size": "55.55"}, {"price": "0.37", "size": "50"}, {"price": "0.56", "size": "100"}, {"price": "0.57", "size": "25"}, {"price": "0.79", "size": "6.4"}, {"price": "0.8", "size": "50"}], "asks": [{"price": "0.99", "size": "98.75"}, {"price": "0.98", "size": "78"}, {"price": "0.97", "size": "10.12"}, {"price": "0.94", "size": "850"}, {"price": "0.93", "size": "300"}, {"price": "0.92", "size": "300"}, {"price": "0.91", "size": "52.13"}, {"price": "0.9", "size": "52.13"}, {"price": "0.89", "size": "82.13"}], "event_type": "book", "last_trade_price": ""}, {"market": "0xb3c09b93dc7b394fbea2b169b54da525c5d6de9ad5caf56da920058e7b74f161", "asset_id": "100335878774855355346358755214398113208570878540440188453565903904895328912285", "timestamp": "1769384440257", "hash": "37b336b7cc0483ef5e7d9e460504ae70f3829680", "bids": [{"price": "0.01", "size": "166.66"}, {"price": "0.02", "size": "6.44"}, {"price": "0.03", "size": "100"}, {"price": "0.04", "size": "6.77"}, {"price": "0.06", "size": "66.66"}, {"price": "0.1", "size": "150"}, {"price": "0.11", "size": "116.66"}], "asks": [{"price": "0.99", "size": "3113.09"}, {"price": "0.98", "size": "1400"}, {"price": "0.97", "size": "11.59"}, {"price": "0.96", "size": "250"}, {"price": "0.95", "size": "30"}, {"price": "0.94", "size": "33"}, {"price": "0.92", "size": "950"}, {"price": "0.91", "size": "205.48"}, {"price": "0.89", "size": "509.09"}, {"price": "0.85", "size": "213.33"}, {"price": "0.81", "size": "297.36"}, {"price": "0.8", "size": "5.14"}, {"price": "0.77", "size": "228.04"}, {"price": "0.76", "size": "71.6"}, {"price": "0.73", "size": "88.88"}, {"price": "0.69", "size": "64.51"}, {"price": "0.68", "size": "32"}, {"price": "0.67", "size": "50"}, {"price": "0.5", "size": "61.6"}, {"price": "0.49", "size": "20"}, {"price": "0.47", "size": "5"}, {"price": "0.27", "size": "50"}, {"price": "0.25", "size": "36"}], "event_type": "book", "last_trade_price": ""}, {"market": "0x7f04c6bd72b53986c4e05d52ffdb3a0e8717ae809be62a1d4ec481313e86a0d0", "asset_id": "102967796728400955038420194199510769009042070489201650126144119775936757647743", "timestamp": "1769384440257", "hash": "756e1b866d6d1014cb2bb0c5b0faf028dadb74ba", "bids": [{"price": "0.01", "size": "3412.93"}, {"price": "0.02", "size": "1400"}, {"price": "0.03", "size": "207.87"}, {"price": "0.04", "size": "350"}, {"price": "0.05", "size": "30"}, {"price": "0.06", "size": "233"}, {"price": "0.07", "size": "5"}, {"price": "0.13", "size": "325"}, {"price": "0.17", "size": "250"}, {"price": "0.19", "size": "6.76"}, {"price": "0.21", "size": "100"}, {"price": "0.22", "size": "15"}, {"price": "0.33", "size": "885"}, {"price": "0.36", "size": "118"}, {"price": "0.37", "size": "50"}, {"price": "0.38", "size": "5"}, {"price": "0.6", "size": "100"}, {"price": "0.61", "size": "20"}, {"price": "0.73", "size": "150"}, {"price": "0.85", "size": "6.4"}, {"price": "0.86", "size": "50"}], "asks": [{"price": "0.99", "size": "172.33"}, {"price": "0.98", "size": "20"}, {"price": "0.97", "size": "129.33"}, {"price": "0.95", "size": "18.75"}, {"price": "0.94", "size": "162.39"}], "event_type": "book", "last_trade_price": ""}, {"market": "0xc7e04626fbed6834456b0b9ed45e7da039ad826933e3abba81e26e71a79b2388", "asset_id": "20915970858057867358422412033597169312902618738489336824716408730559800805214", "timestamp": "1769384440258", "hash": "b33c20dc883efa78cc32d07b24426feff8af3118", "bids": [{"price": "0.01", "size": "163.94"}, {"price": "0.02", "size": "149.29"}, {"price": "0.03", "size": "63.03"}, {"price": "0.05", "size": "82.53"}], "asks": [{"price": "0.99", "size": "3212.82"}, {"price": "0.98", "size": "1400"}, {"price": "0.97", "size": "6.52"}, {"price": "0.96", "size": "250"}, {"price": "0.95", "size": "30"}, {"price": "0.94", "size": "33"}, {"price": "0.93", "size": "7.94"}, {"price": "0.92", "size": "950"}, {"price": "0.87", "size": "586.53"}, {"price": "0.83", "size": "438.23"}, {"price": "0.82", "size": "6.22"}, {"price": "0.79", "size": "233.33"}, {"price": "0.78", "size": "91"}, {"price": "0.75", "size": "104"}, {"price": "0.74", "size": "15"}, {"price": "0.71", "size": "82.75"}, {"price": "0.7", "size": "10"}, {"price": "0.67", "size": "60.6"}, {"price": "0.59", "size": "160"}, {"price": "0.56", "size": "5"}, {"price": "0.55", "size": "50"}, {"price": "0.36", "size": "8.84"}, {"price": "0.32", "size": "150"}, {"price": "0.31", "size": "20"}, {"price": "0.19", "size": "10"}, {"price": "0.18", "size": "50"}], "event_type": "book", "last_trade_price": ""}, {"market": "0xb3c09b93dc7b394fbea2b169b54da525c5d6de9ad5caf56da920058e7b74f161", "asset_id": "39663779628084842897937886547518878184317206079104235500705380518100175496233", "timestamp": "1769384440257", "hash": "a7455e03f6a1731519c1a2b70ff498a04b910f6d", "bids": [{"price": "0.01", "size": "3113.09"}, {"price": "0.02", "size": "1400"}, {"price": "0.03", "size": "11.59"}, {"price": "0.04", "size": "250"}, {"price": "0.05", "size": "30"}, {"price": "0.06", "size": "33"}, {"price": "0.08", "size": "950"}, {"price": "0.09", "size": "205.48"}, {"price": "0.11", "size": "509.09"}, {"price": "0.15", "size": "213.33"}, {"price": "0.19", "size": "297.36"}, {"price": "0.2", "size": "5.14"}, {"price": "0.23", "size": "228.04"}, {"price": "0.24", "size": "71.6"}, {"price": "0.27", "size": "88.88"}, {"price": "0.31", "size": "64.51"}, {"price": "0.32", "size": "32"}, {"price": "0.33", "size": "50"}, {"price": "0.5", "size": "61.6"}, {"price": "0.51", "size": "20"}, {"price": "0.53", "size": "5"}, {"price": "0.73", "size": "50"}, {"price": "0.75", "size": "36"}], "asks": [{"price": "0.99", "size": "166.66"}, {"price": "0.98", "size": "6.44"}, {"price": "0.97", "size": "100"}, {"price": "0.96", "size": "6.77"}, {"price": "0.94", "size": "66.66"}, {"price": "0.9", "size": "150"}, {"price": "0.89", "size": "116.66"}], "event_type": "book", "last_trade_price": ""}, {"market": "0x2df8bb66d0a96661ec2a4f57b0510ca7c8e154d78d6d8f3b557478ddc34fcfae", "asset_id": "34218064140411222044683093812278888477247876051063075885631415084973387284228", "timestamp": "1769384440258", "hash": "40a0e8bbe632de506429eb6adfbd6a63cb6560bf", "bids": [{"price": "0.01", "size": "1100"}, {"price": "0.03", "size": "13.33"}, {"price": "0.05", "size": "1420"}, {"price": "0.08", "size": "425"}, {"price": "0.09", "size": "100"}, {"price": "0.11", "size": "290.9"}, {"price": "0.14", "size": "200"}, {"price": "0.16", "size": "162.5"}, {"price": "0.18", "size": "50"}, {"price": "0.19", "size": "176.31"}, {"price": "0.2", "size": "88"}, {"price": "0.22", "size": "90.9"}, {"price": "0.23", "size": "50"}, {"price": "0.24", "size": "8.5"}, {"price": "0.47", "size": "50"}], "asks": [{"price": "0.99", "size": "3108.63"}, {"price": "0.98", "size": "1008.68"}, {"price": "0.97", "size": "1850"}, {"price": "0.96", "size": "256.03"}, {"price": "0.95", "size": "330"}, {"price": "0.94", "size": "533"}, {"price": "0.93", "size": "33.07"}, {"price": "0.89", "size": "300"}, {"price": "0.88", "size": "9.52"}, {"price": "0.79", "size": "36.2"}, {"price": "0.78", "size": "15"}, {"price": "0.77", "size": "100"}, {"price": "0.75", "size": "10"}, {"price": "0.73", "size": "10"}, {"price": "0.72", "size": "20"}, {"price": "0.71", "size": "20"}, {"price": "0.7", "size": "20"}, {"price": "0.69", "size": "8.5"}, {"price": "0.63", "size": "50"}], "event_type": "book", "last_trade_price": ""}, {"market": "0x2df8bb66d0a96661ec2a4f57b0510ca7c8e154d78d6d8f3b557478ddc34fcfae", "asset_id": "104293714017628859730042534598620180600303966146090765434616358106204241123622", "timestamp": "1769384440258", "hash": "f57c329e436fff5c27fc72aa719956859d7b5ee0", "bids": [{"price": "0.01", "size": "3108.63"}, {"price": "0.02", "size": "1008.68"}, {"price": "0.03", "size": "1850"}, {"price": "0.04", "size": "256.03"}, {"price": "0.05", "size": "330"}, {"price": "0.06", "size": "533"}, {"price": "0.07", "size": "33.07"}, {"price": "0.11", "size": "300"}, {"price": "0.12", "size": "9.52"}, {"price": "0.21", "size": "36.2"}, {"price": "0.22", "size": "15"}, {"price": "0.23", "size": "100"}, {"price": "0.25", "size": "10"}, {"price": "0.27", "size": "10"}, {"price": "0.28", "size": "20"}, {"price": "0.29", "size": "20"}, {"price": "0.3", "size": "20"}, {"price": "0.31", "size": "8.5"}, {"price": "0.37", "size": "50"}], "asks": [{"price": "0.99", "size": "1100"}, {"price": "0.97", "size": "13.33"}, {"price": "0.95", "size": "1420"}, {"price": "0.92", "size": "425"}, {"price": "0.91", "size": "100"}, {"price": "0.89", "size": "290.9"}, {"price": "0.86", "size": "200"}, {"price": "0.84", "size": "162.5"}, {"price": "0.82", "size": "50"}, {"price": "0.81", "size": "176.31"}, {"price": "0.8", "size": "88"}, {"price": "0.78", "size": "90.9"}, {"price": "0.77", "size": "50"}, {"price": "0.76", "size": "8.5"}, {"price": "0.53", "size": "50"}], "event_type": "book", "last_trade_price": ""}, {"market": "0x33315bd63d0cc17257c5d7524e5283639a5e17c6ce030d937f135aab02170c40", "asset_id": "109227307115212040009558734329420624109955456904374090651494287022030420438197", "timestamp": "1769384440257", "hash": "6749ba7d8aa4baecf45287f5b69737760fffd791", "bids": [{"price": "0.01", "size": "98.75"}, {"price": "0.02", "size": "78"}, {"price": "0.03", "size": "10.12"}, {"price": "0.06", "size": "850"}, {"price": "0.07", "size": "300"}, {"price": "0.08", "size": "300"}, {"price": "0.09", "size": "52.13"}, {"price": "0.1", "size": "52.13"}, {"price": "0.11", "size": "82.13"}], "asks": [{"price": "0.99", "size": "3112.93"}, {"price": "0.98", "size": "1400"}, {"price": "0.97", "size": "7.87"}, {"price": "0.96", "size": "250"}, {"price": "0.95", "size": "30"}, {"price": "0.94", "size": "33"}, {"price": "0.93", "size": "6.82"}, {"price": "0.91", "size": "900"}, {"price": "0.87", "size": "461.53"}, {"price": "0.82", "size": "327.77"}, {"price": "0.81", "size": "6.09"}, {"price": "0.8", "size": "15"}, {"price": "0.78", "size": "227.27"}, {"price": "0.77", "size": "10"}, {"price": "0.73", "size": "96.29"}, {"price": "0.69", "size": "927.41"}, {"price": "0.68", "size": "100"}, {"price": "0.67", "size": "71"}, {"price": "0.64", "size": "55.55"}, {"price": "0.63", "size": "50"}, {"price": "0.44", "size": "100"}, {"price": "0.43", "size": "25"}, {"price": "0.21", "size": "6.4"}, {"price": "0.2", "size": "50"}], "event_type": "book", "last_trade_price": ""}, {"market": "0x7f04c6bd72b53986c4e05d52ffdb3a0e8717ae809be62a1d4ec481313e86a0d0", "asset_id": "53325847113338736338902840435383727831746710692724054663504837250405920447353", "timestamp": "1769384440257", "hash": "c1d999dbb27a1f4c00cdd07ba5edf7bc77abd1b5", "bids": [{"price": "0.01", "size": "172.33"}, {"price": "0.02", "size": "20"}, {"price": "0.03", "size": "129.33"}, {"price": "0.05", "size": "18.75"}, {"price": "0.06", "size": "162.39"}], "asks": [{"price": "0.99", "size": "3412.93"}, {"price": "0.98", "size": "1400"}, {"price": "0.97", "size": "207.87"}, {"price": "0.96", "size": "350"}, {"price": "0.95", "size": "30"}, {"price": "0.94", "size": "233"}, {"price": "0.93", "size": "5"}, {"price": "0.87", "size": "325"}, {"price": "0.83", "size": "250"}, {"price": "0.81", "size": "6.76"}, {"price": "0.79", "size": "100"}, {"price": "0.78", "size": "15"}, {"price": "0.67", "size": "885"}, {"price": "0.64", "size": "118"}, {"price": "0.63", "size": "50"}, {"price": "0.62", "size": "5"}, {"price": "0.4", "size": "100"}, {"price": "0.39", "size": "20"}, {"price": "0.27", "size": "150"}, {"price": "0.15", "size": "6.4"}, {"price": "0.14", "size": "50"}], "event_type": "book", "last_trade_price": ""}]}
{"_local_timestamp": "2026-01-25T23:40:59.207116+00:00", "data": {"market": "0x2df8bb66d0a96661ec2a4f57b0510ca7c8e154d78d6d8f3b557478ddc34fcfae", "price_changes": [{"asset_id": "34218064140411222044683093812278888477247876051063075885631415084973387284228", "price": "0.01", "size": "100", "side": "BUY", "hash": "24083446595c7b2faabdf45e8f986d78e39b4223", "best_bid": "0.47", "best_ask": "0.63"}, {"asset_id": "104293714017628859730042534598620180600303966146090765434616358106204241123622", "price": "0.99", "size": "100", "side": "SELL", "hash": "7a4110fed3a1f8a98fed4a4b413408387ecd6f40", "best_bid": "0.37", "best_ask": "0.53"}], "timestamp": "1769384459107", "event_type": "price_change"}}
{"_local_timestamp": "2026-01-25T23:40:59.209634+00:00", "data": {"market": "0x2df8bb66d0a96661ec2a4f57b0510ca7c8e154d78d6d8f3b557478ddc34fcfae", "price_changes": [{"asset_id": "34218064140411222044683093812278888477247876051063075885631415084973387284228", "price": "0.05", "size": "1020", "side": "BUY", "hash": "24083446595c7b2faabdf45e8f986d78e39b4223", "best_bid": "0.47", "best_ask": "0.63"}, {"asset_id": "104293714017628859730042534598620180600303966146090765434616358106204241123622", "price": "0.95", "size": "1020", "side": "SELL", "hash": "7a4110fed3a1f8a98fed4a4b413408387ecd6f40", "best_bid": "0.37", "best_ask": "0.53"}], "timestamp": "1769384459107", "event_type": "price_change"}}
{"_local_timestamp": "2026-01-25T23:40:59.213062+00:00", "data": {"market": "0x33315bd63d0cc17257c5d7524e5283639a5e17c6ce030d937f135aab02170c40", "price_changes": [{"asset_id": "92512666728361163935047824440150917945153592049030110328840756457871300635229", "price": "0.09", "size": "700", "side": "BUY", "hash": "49880a5c53abe696d840f1e4c6bd51b3766f9c3e", "best_bid": "0.8", "best_ask": "0.89"}, {"asset_id": "109227307115212040009558734329420624109955456904374090651494287022030420438197", "price": "0.91", "size": "700", "side": "SELL", "hash": "f7a1a480fbc779d18d3bba1aef724486fa7ee2fb", "best_bid": "0.11", "best_ask": "0.2"}], "timestamp": "1769384459107", "event_type": "price_change"}}
{"_local_timestamp": "2026-01-25T23:40:59.214509+00:00", "data": {"market": "0xb3c09b93dc7b394fbea2b169b54da525c5d6de9ad5caf56da920058e7b74f161", "price_changes": [{"asset_id": "39663779628084842897937886547518878184317206079104235500705380518100175496233", "price": "0.08", "size": "750", "side": "BUY", "hash": "8c188713106876d4861efbfb4184d09c33a3380e", "best_bid": "0.75", "best_ask": "0.89"}, {"asset_id": "100335878774855355346358755214398113208570878540440188453565903904895328912285", "price": "0.92", "size": "750", "side": "SELL", "hash": "e77510a11463e7e629a092ea2253673638a6e7fe", "best_bid": "0.11", "best_ask": "0.25"}], "timestamp": "1769384459107", "event_type": "price_change"}}
{"_local_timestamp": "2026-01-25T23:40:59.215270+00:00", "data": {"market": "0x2df8bb66d0a96661ec2a4f57b0510ca7c8e154d78d6d8f3b557478ddc34fcfae", "price_changes": [{"asset_id": "104293714017628859730042534598620180600303966146090765434616358106204241123622", "price": "0.03", "size": "1450", "side": "BUY", "hash": "097fc0862d1c46e80e9f2ea82644fce4a8e5d423", "best_bid": "0.37", "best_ask": "0.53"}, {"asset_id": "34218064140411222044683093812278888477247876051063075885631415084973387284228", "price": "0.97", "size": "1450", "side": "SELL", "hash": "2aca3688cdfcc66a34e945991b4f2559094877cb", "best_bid": "0.47", "best_ask": "0.63"}], "timestamp": "1769384459107", "event_type": "price_change"}}
{"_local_timestamp": "2026-01-25T23:40:59.217073+00:00", "data": {"market": "0x2df8bb66d0a96661ec2a4f57b0510ca7c8e154d78d6d8f3b557478ddc34fcfae", "price_changes": [{"asset_id": "104293714017628859730042534598620180600303966146090765434616358106204241123622", "price": "0.06", "size": "333", "side": "BUY", "hash": "097fc0862d1c46e80e9f2ea82644fce4a8e5d423", "best_bid": "0.37", "best_ask": "0.53"}, {"asset_id": "34218064140411222044683093812278888477247876051063075885631415084973387284228", "price": "0.94", "size": "333", "side": "SELL", "hash": "2aca3688cdfcc66a34e945991b4f2559094877cb", "best_bid": "0.47", "best_ask": "0.63"}], "timestamp": "1769384459107", "event_type": "price_change"}}
{"_local_timestamp": "2026-01-25T23:40:59.217371+00:00", "data": {"market": "0x2df8bb66d0a96661ec2a4f57b0510ca7c8e154d78d6d8f3b557478ddc34fcfae", "price_changes": [{"asset_id": "104293714017628859730042534598620180600303966146090765434616358106204241123622", "price": "0.01", "size": "2108.63", "side": "BUY", "hash": "097fc0862d1c46e80e9f2ea82644fce4a8e5d423", "best_bid": "0.37", "best_ask": "0.53"}, {"asset_id": "34218064140411222044683093812278888477247876051063075885631415084973387284228", "price": "0.99", "size": "2108.63", "side": "SELL", "hash": "2aca3688cdfcc66a34e945991b4f2559094877cb", "best_bid": "0.47", "best_ask": "0.63"}], "timestamp": "1769384459107", "event_type": "price_change"}}
{"_local_timestamp": "2026-01-25T23:41:03.533754+00:00", "data": {"market": "0x2df8bb66d0a96661ec2a4f57b0510ca7c8e154d78d6d8f3b557478ddc34fcfae", "price_changes": [{"asset_id": "104293714017628859730042534598620180600303966146090765434616358106204241123622", "price": "0.32", "size": "20", "side": "BUY", "hash": "1ac8a8874ea84a3474ce5efe14877020b699f8b7", "best_bid": "0.37", "best_ask": "0.53"}, {"asset_id": "34218064140411222044683093812278888477247876051063075885631415084973387284228", "price": "0.68", "size": "20", "side": "SELL", "hash": "356c697c345b80c7249ae7cda2c94f96499d6a1c", "best_bid": "0.47", "best_ask": "0.63"}], "timestamp": "1769384463435", "event_type": "price_change"}}
{"_local_timestamp": "2026-01-25T23:41:16.515754+00:00", "data": {"market": "0x2df8bb66d0a96661ec2a4f57b0510ca7c8e154d78d6d8f3b557478ddc34fcfae", "price_changes": [{"asset_id": "34218064140411222044683093812278888477247876051063075885631415084973387284228", "price": "0.23", "size": "0", "side": "BUY", "hash": "d83cb18a7ea01f6ca535404c7b87e4448747ccce", "best_bid": "0.47", "best_ask": "0.63"}, {"asset_id": "104293714017628859730042534598620180600303966146090765434616358106204241123622", "price": "0.77", "size": "0", "side": "SELL", "hash": "b3b098d58bdd61c15a270c90b3e1878770250914", "best_bid": "0.37", "best_ask": "0.53"}], "timestamp": "1769384476442", "event_type": "price_change"}}
{"_local_timestamp": "2026-01-25T23:41:16.523153+00:00", "data": {"market": "0x2df8bb66d0a96661ec2a4f57b0510ca7c8e154d78d6d8f3b557478ddc34fcfae", "price_changes": [{"asset_id": "34218064140411222044683093812278888477247876051063075885631415084973387284228", "price": "0.19", "size": "126.31", "side": "BUY", "hash": "d83cb18a7ea01f6ca535404c7b87e4448747ccce", "best_bid": "0.47", "best_ask": "0.63"}, {"asset_id": "104293714017628859730042534598620180600303966146090765434616358106204241123622", "price": "0.81", "size": "126.31", "side": "SELL", "hash": "b3b098d58bdd61c15a270c90b3e1878770250914", "best_bid": "0.37", "best_ask": "0.53"}], "timestamp": "1769384476442", "event_type": "price_change"}}
{"_local_timestamp": "2026-01-25T23:41:16.523682+00:00", "data": {"market": "0x2df8bb66d0a96661ec2a4f57b0510ca7c8e154d78d6d8f3b557478ddc34fcfae", "price_changes": [{"asset_id": "104293714017628859730042534598620180600303966146090765434616358106204241123622", "price": "0.06", "size": "233", "side": "BUY", "hash": "f87fcfbaccd05a1d574cec414de44b5657b94c4a", "best_bid": "0.37", "best_ask": "0.53"}, {"asset_id": "34218064140411222044683093812278888477247876051063075885631415084973387284228", "price": "0.94", "size": "233", "side": "SELL", "hash": "b74cb1be6d32f4b40d45f9d022a8042e4cced8b2", "best_bid": "0.47", "best_ask": "0.63"}], "timestamp": "1769384476442", "event_type": "price_change"}}
{"_local_timestamp": "2026-01-25T23:41:16.523969+00:00", "data": {"market": "0x2df8bb66d0a96661ec2a4f57b0510ca7c8e154d78d6d8f3b557478ddc34fcfae", "price_changes": [{"asset_id": "104293714017628859730042534598620180600303966146090765434616358106204241123622", "price": "0.23", "size": "0", "side": "BUY", "hash": "f87fcfbaccd05a1d574cec414de44b5657b94c4a", "best_bid": "0.37", "best_ask": "0.53"}, {"asset_id": "34218064140411222044683093812278888477247876051063075885631415084973387284228", "price": "0.77", "size": "0", "side": "SELL", "hash": "b74cb1be6d32f4b40d45f9d022a8042e4cced8b2", "best_bid": "0.47", "best_ask": "0.63"}], "timestamp": "1769384476442", "event_type": "price_change"}}
{"_local_timestamp": "2026-01-25T23:41:17.568911+00:00", "data": {"market": "0x2df8bb66d0a96661ec2a4f57b0510ca7c8e154d78d6d8f3b557478ddc34fcfae", "price_changes": [{"asset_id": "104293714017628859730042534598620180600303966146090765434616358106204241123622", "price": "0.12", "size": "76.18", "side": "BUY", "hash": "2c85c378d5b9f3521a0c5043360f2ca26ec34178", "best_bid": "0.37", "best_ask": "0.53"}, {"asset_id": "34218064140411222044683093812278888477247876051063075885631415084973387284228", "price": "0.88", "size": "76.18", "side": "SELL", "hash": "37544ff5ea5a5c388491f0e3774bfe8201c08939", "best_bid": "0.47", "best_ask": "0.63"}], "timestamp": "1769384477494", "event_type": "price_change"}}
{"_local_timestamp": "2026-01-25T23:41:17.571252+00:00", "data": {"market": "0x2df8bb66d0a96661ec2a4f57b0510ca7c8e154d78d6d8f3b557478ddc34fcfae", "price_changes": [{"asset_id": "34218064140411222044683093812278888477247876051063075885631415084973387284228", "price": "0.48", "size": "50", "side": "BUY", "hash": "34171cf9865922d7e1cca2d94093d392a59552fe", "best_bid": "0.48", "best_ask": "0.63"}, {"asset_id": "104293714017628859730042534598620180600303966146090765434616358106204241123622", "price": "0.52", "size": "50", "side": "SELL", "hash": "890b7ca30d384711c2a59139e41ad32fe3abd426", "best_bid": "0.37", "best_ask": "0.52"}], "timestamp": "1769384477496", "event_type": "price_change"}}
{"_local_timestamp": "2026-01-25T23:41:17.574024+00:00", "data": {"market": "0x2df8bb66d0a96661ec2a4f57b0510ca7c8e154d78d6d8f3b557478ddc34fcfae", "price_changes": [{"asset_id": "104293714017628859730042534598620180600303966146090765434616358106204241123622", "price": "0.38", "size": "66.66", "side": "BUY", "hash": "bf5d21b8b0d93e24ab068ba47cd502e7c916eda8", "best_bid": "0.38", "best_ask": "0.52"}, {"asset_id": "34218064140411222044683093812278888477247876051063075885631415084973387284228", "price": "0.62", "size": "66.66", "side": "SELL", "hash": "152ac63021c52fefb9cc04b26fc6094ed0ea0886", "best_bid": "0.48", "best_ask": "0.62"}], "timestamp": "1769384477506", "event_type": "price_change"}}
{"_local_timestamp": "2026-01-25T23:41:17.591066+00:00", "data": {"market": "0x2df8bb66d0a96661ec2a4f57b0510ca7c8e154d78d6d8f3b557478ddc34fcfae", "price_changes": [{"asset_id": "104293714017628859730042534598620180600303966146090765434616358106204241123622", "price": "0.25", "size": "76.66", "side": "BUY", "hash": "777153b6077a20a3ad9237f2bf067d469c56e681", "best_bid": "0.38", "best_ask": "0.52"}, {"asset_id": "34218064140411222044683093812278888477247876051063075885631415084973387284228", "price": "0.75", "size": "76.66", "side": "SELL", "hash": "ba6b981c99c2d35174816680518e5d1983ac1f82", "best_bid": "0.48", "best_ask": "0.62"}], "timestamp": "1769384477529", "event_type": "price_change"}}
{"_local_timestamp": "2026-01-25T23:41:17.612294+00:00", "data": {"market": "0x2df8bb66d0a96661ec2a4f57b0510ca7c8e154d78d6d8f3b557478ddc34fcfae", "price_changes": [{"asset_id": "34218064140411222044683093812278888477247876051063075885631415084973387284228", "price": "0.32", "size": "50", "side": "BUY", "hash": "512991096286c38943b00399923d7190d18f3f6f", "best_bid": "0.48", "best_ask": "0.62"}, {"asset_id": "104293714017628859730042534598620180600303966146090765434616358106204241123622", "price": "0.68", "size": "50", "side": "SELL", "hash": "6eda95375acd4a051b065e0b62a02ca531702b4a", "best_bid": "0.38", "best_ask": "0.52"}], "timestamp": "1769384477530", "event_type": "price_change"}}
{"_local_timestamp": "2026-01-25T23:41:17.665594+00:00", "data": {"market": "0xb3c09b93dc7b394fbea2b169b54da525c5d6de9ad5caf56da920058e7b74f161", "price_changes": [{"asset_id": "39663779628084842897937886547518878184317206079104235500705380518100175496233", "price": "0.34", "size": "10", "side": "BUY", "hash": "ccd51f9a7797df7b5010e671c8c4c0304283ecd1", "best_bid": "0.75", "best_ask": "0.89"}, {"asset_id": "100335878774855355346358755214398113208570878540440188453565903904895328912285", "price": "0.66", "size": "10", "side": "SELL", "hash": "bc2033c020b309f59f66627f3fd8af5fcc8862a5", "best_bid": "0.11", "best_ask": "0.25"}], "timestamp": "1769384477599", "event_type": "price_change"}}
{"_local_timestamp": "2026-01-25T23:41:18.334072+00:00", "data": {"market": "0x2df8bb66d0a96661ec2a4f57b0510ca7c8e154d78d6d8f3b557478ddc34fcfae", "price_changes": [{"asset_id": "104293714017628859730042534598620180600303966146090765434616358106204241123622", "price": "0.18", "size": "111.11", "side": "BUY", "hash": "314473e9261ea273b04125779dde45f5f58cad73", "best_bid": "0.38", "best_ask": "0.52"}, {"asset_id": "34218064140411222044683093812278888477247876051063075885631415084973387284228", "price": "0.82", "size": "111.11", "side": "SELL", "hash": "3c307da48d2c619d945e6edca6a099e343985528", "best_bid": "0.48", "best_ask": "0.62"}], "timestamp": "1769384478208", "event_type": "price_change"}}
{"_local_timestamp": "2026-01-25T23:41:18.390968+00:00", "data": {"market": "0x2df8bb66d0a96661ec2a4f57b0510ca7c8e154d78d6d8f3b557478ddc34fcfae", "price_changes": [{"asset_id": "104293714017628859730042534598620180600303966146090765434616358106204241123622", "price": "0.16", "size": "150", "side": "BUY", "hash": "c4e6db2c1ae672a12cd00aa93df3ae86cdcff60f", "best_bid": "0.38", "best_ask": "0.52"}, {"asset_id": "34218064140411222044683093812278888477247876051063075885631415084973387284228", "price": "0.84", "size": "150", "side": "SELL", "hash": "157fdc6963af829593782435646127fb79813a33", "best_bid": "0.48", "best_ask": "0.62"}], "timestamp": "1769384478259", "event_type": "price_change"}}
{"_local_timestamp": "2026-01-25T23:41:18.437786+00:00", "data": {"market": "0x2df8bb66d0a96661ec2a4f57b0510ca7c8e154d78d6d8f3b557478ddc34fcfae", "price_changes": [{"asset_id": "104293714017628859730042534598620180600303966146090765434616358106204241123622", "price": "0.14", "size": "185.71", "side": "BUY", "hash": "8bc9f405bbad4e0ad55fba5bd21f9f158542c079", "best_bid": "0.38", "best_ask": "0.52"}, {"asset_id": "34218064140411222044683093812278888477247876051063075885631415084973387284228", "price": "0.86", "size": "185.71", "side": "SELL", "hash": "78c6287ba511b3fe25ec242868b2d000f9c3eca5", "best_bid": "0.48", "best_ask": "0.62"}], "timestamp": "1769384478310", "event_type": "price_change"}}
{"_local_timestamp": "2026-01-25T23:41:18.497787+00:00", "data": {"market": "0x2df8bb66d0a96661ec2a4f57b0510ca7c8e154d78d6d8f3b557478ddc34fcfae", "price_changes": [{"asset_id": "104293714017628859730042534598620180600303966146090765434616358106204241123622", "price": "0.11", "size": "554.54", "side": "BUY", "hash": "ce5126980df4e7f8f8c3a4f4bfb6ebd067a5f5d1", "best_bid": "0.38", "best_ask": "0.52"}, {"asset_id": "34218064140411222044683093812278888477247876051063075885631415084973387284228", "price": "0.89", "size": "554.54", "side": "SELL", "hash": "2244e1437266ba122274d619cbfa2ed6845c3a30", "best_bid": "0.48", "best_ask": "0.62"}], "timestamp": "1769384478365", "event_type": "price_change"}}
{"_local_timestamp": "2026-01-25T23:41:18.530813+00:00", "data": {"market": "0x2df8bb66d0a96661ec2a4f57b0510ca7c8e154d78d6d8f3b557478ddc34fcfae", "price_changes": [{"asset_id": "104293714017628859730042534598620180600303966146090765434616358106204241123622", "price": "0.09", "size": "355.55", "side": "BUY", "hash": "29ea6a06cc74a7707ca9a3846043e1def9ef2b89", "best_bid": "0.38", "best_ask": "0.52"}, {"asset_id": "34218064140411222044683093812278888477247876051063075885631415084973387284228", "price": "0.91", "size": "355.55", "side": "SELL", "hash": "1f2c3fd52ac7ccecce735608895a6d6dd5bce742", "best_bid": "0.48", "best_ask": "0.62"}], "timestamp": "1769384478421", "event_type": "price_change"}}
{"_local_timestamp": "2026-01-25T23:41:18.564968+00:00", "data": {"market": "0x2df8bb66d0a96661ec2a4f57b0510ca7c8e154d78d6d8f3b557478ddc34fcfae", "price_changes": [{"asset_id": "104293714017628859730042534598620180600303966146090765434616358106204241123622", "price": "0.07", "size": "518.78", "side": "BUY", "hash": "ea4a5c0a21f0413ba173dd131023acefbd11491f", "best_bid": "0.38", "best_ask": "0.52"}, {"asset_id": "34218064140411222044683093812278888477247876051063075885631415084973387284228", "price": "0.93", "size": "518.78", "side": "SELL", "hash": "f7250df39ddded8038bb0abef01083445f1fc9fa", "best_bid": "0.48", "best_ask": "0.62"}], "timestamp": "1769384478485", "event_type": "price_change"}}
{"_local_timestamp": "2026-01-25T23:41:18.602753+00:00", "data": {"market": "0x2df8bb66d0a96661ec2a4f57b0510ca7c8e154d78d6d8f3b557478ddc34fcfae", "price_changes": [{"asset_id": "104293714017628859730042534598620180600303966146090765434616358106204241123622", "price": "0.05", "size": "1050", "side": "BUY", "hash": "0c2982d4a925ff6d8f05ab235892d302f606f575", "best_bid": "0.38", "best_ask": "0.52"}, {"asset_id": "34218064140411222044683093812278888477247876051063075885631415084973387284228", "price": "0.95", "size": "1050", "side": "SELL", "hash": "dbdc54b61ee333acccd70a101544c13d433b73ef", "best_bid": "0.48", "best_ask": "0.62"}], "timestamp": "1769384478539", "event_type": "price_change"}}
{"_local_timestamp": "2026-01-25T23:41:22.122868+00:00", "data": {"market": "0x2df8bb66d0a96661ec2a4f57b0510ca7c8e154d78d6d8f3b557478ddc34fcfae", "price_changes": [{"asset_id": "34218064140411222044683093812278888477247876051063075885631415084973387284228", "price": "0.24", "size": "0", "side": "BUY", "hash": "133277d056bf85b716bb5afa475558c63b5c0491", "best_bid": "0.48", "best_ask": "0.62"}, {"asset_id": "104293714017628859730042534598620180600303966146090765434616358106204241123622", "price": "0.76", "size": "0", "side": "SELL", "hash": "5db4cbe82ed54bdfed15679e48eff44a794a13a9", "best_bid": "0.38", "best_ask": "0.52"}], "timestamp": "1769384482013", "event_type": "price_change"}}
{"_local_timestamp": "2026-01-25T23:41:22.149305+00:00", "data": {"market": "0x2df8bb66d0a96661ec2a4f57b0510ca7c8e154d78d6d8f3b557478ddc34fcfae", "price_changes": [{"asset_id": "34218064140411222044683093812278888477247876051063075885631415084973387284228", "price": "0.21", "size": "8.5", "side": "BUY", "hash": "f450a9cc39931930756c01c1fe891b944c986b29", "best_bid": "0.48", "best_ask": "0.62"}, {"asset_id": "104293714017628859730042534598620180600303966146090765434616358106204241123622", "price": "0.79", "size": "8.5", "side": "SELL", "hash": "1ad61a5fc2b32f41cb47b906070b6543243ed096", "best_bid": "0.38", "best_ask": "0.52"}], "timestamp": "1769384482059", "event_type": "price_change"}}
{"_local_timestamp": "2026-01-25T23:41:28.378407+00:00", "data": {"market": "0x2df8bb66d0a96661ec2a4f57b0510ca7c8e154d78d6d8f3b557478ddc34fcfae", "price_changes": [{"asset_id": "104293714017628859730042534598620180600303966146090765434616358106204241123622", "price": "0.31", "size": "0", "side": "BUY", "hash": "3894f7a7e8eb3df442906c5007b06c1d7635b34f", "best_bid": "0.38", "best_ask": "0.52"}, {"asset_id": "34218064140411222044683093812278888477247876051063075885631415084973387284228", "price": "0.69", "size": "0", "side": "SELL", "hash": "f522a7d7dc6446428e7f05001d76242f2a4df56a", "best_bid": "0.48", "best_ask": "0.62"}], "timestamp": "1769384488305", "event_type": "price_change"}}
{"_local_timestamp": "2026-01-25T23:41:28.440629+00:00", "data": {"market": "0x2df8bb66d0a96661ec2a4f57b0510ca7c8e154d78d6d8f3b557478ddc34fcfae", "price_changes": [{"asset_id": "104293714017628859730042534598620180600303966146090765434616358106204241123622", "price": "0.39", "size": "8.5", "side": "BUY", "hash": "519a867db8d912d1fe33e631c99b55218dbee051", "best_bid": "0.39", "best_ask": "0.52"}, {"asset_id": "34218064140411222044683093812278888477247876051063075885631415084973387284228", "price": "0.61", "size": "8.5", "side": "SELL", "hash": "c1629ce037c5f5c248a001225f24111474509a16", "best_bid": "0.48", "best_ask": "0.61"}], "timestamp": "1769384488342", "event_type": "price_change"}}
{"_local_timestamp": "2026-01-25T23:41:50.868306+00:00", "data": {"market": "0x2df8bb66d0a96661ec2a4f57b0510ca7c8e154d78d6d8f3b557478ddc34fcfae", "price_changes": [{"asset_id": "104293714017628859730042534598620180600303966146090765434616358106204241123622", "price": "0.03", "size": "1150", "side": "BUY", "hash": "59952fb419de2ef0bee0a8a9f00ada80b902c5dc", "best_bid": "0.39", "best_ask": "0.52"}, {"asset_id": "34218064140411222044683093812278888477247876051063075885631415084973387284228", "price": "0.97", "size": "1150", "side": "SELL", "hash": "4269c27b11f7ff43def7ca447667876525537b0a", "best_bid": "0.48", "best_ask": "0.61"}], "timestamp": "1769384510741", "event_type": "price_change"}}
{"_local_timestamp": "2026-01-25T23:41:50.869033+00:00", "data": {"market": "0x2df8bb66d0a96661ec2a4f57b0510ca7c8e154d78d6d8f3b557478ddc34fcfae", "price_changes": [{"asset_id": "104293714017628859730042534598620180600303966146090765434616358106204241123622", "price": "0.11", "size": "354.54", "side": "BUY", "hash": "59952fb419de2ef0bee0a8a9f00ada80b902c5dc", "best_bid": "0.39", "best_ask": "0.52"}, {"asset_id": "34218064140411222044683093812278888477247876051063075885631415084973387284228", "price": "0.89", "size": "354.54", "side": "SELL", "hash": "4269c27b11f7ff43def7ca447667876525537b0a", "best_bid": "0.48", "best_ask": "0.61"}], "timestamp": "1769384510741", "event_type": "price_change"}}
{"_local_timestamp": "2026-01-25T23:41:50.869463+00:00", "data": {"market": "0xc7e04626fbed6834456b0b9ed45e7da039ad826933e3abba81e26e71a79b2388", "price_changes": [{"asset_id": "108633032965983853701783501560325265009339710531442379830307955199797783135140", "price": "0.41", "size": "100", "side": "BUY", "hash": "357d1525d49adfb5a41ebb19eee98fb14d042403", "best_bid": "0.82", "best_ask": "0.95"}, {"asset_id": "20915970858057867358422412033597169312902618738489336824716408730559800805214", "price": "0.59", "size": "100", "side": "SELL", "hash": "d3ae0bc777ed2e9c76c7dd5f6bd09df0642039f2", "best_bid": "0.05", "best_ask": "0.18"}], "timestamp": "1769384510741", "event_type": "price_change"}}
{"_local_timestamp": "2026-01-25T23:41:50.877507+00:00", "data": {"market": "0x2df8bb66d0a96661ec2a4f57b0510ca7c8e154d78d6d8f3b557478ddc34fcfae", "price_changes": [{"asset_id": "34218064140411222044683093812278888477247876051063075885631415084973387284228", "price": "0.05", "size": "720", "side": "BUY", "hash": "8eee8c436b43fcbecd37baa88dba1428f80ca74d", "best_bid": "0.48", "best_ask": "0.61"}, {"asset_id": "104293714017628859730042534598620180600303966146090765434616358106204241123622", "price": "0.95", "size": "720", "side": "SELL", "hash": "81123ba7d92da2b03e42ee96cb1f3267602d8e35", "best_bid": "0.39", "best_ask": "0.52"}], "timestamp": "1769384510742", "event_type": "price_change"}}
{"_local_timestamp": "2026-01-25T23:41:50.884941+00:00", "data": {"market": "0x7f04c6bd72b53986c4e05d52ffdb3a0e8717ae809be62a1d4ec481313e86a0d0", "price_changes": [{"asset_id": "102967796728400955038420194199510769009042070489201650126144119775936757647743", "price": "0.33", "size": "810", "side": "BUY", "hash": "a9aa615af4ebdf00747778d0651009b7f5ff3b53", "best_bid": "0.86", "best_ask": "0.94"}, {"asset_id": "53325847113338736338902840435383727831746710692724054663504837250405920447353", "price": "0.67", "size": "810", "side": "SELL", "hash": "31782e3bbd7a286ee86e64bd0238d7a977d69192", "best_bid": "0.06", "best_ask": "0.14"}], "timestamp": "1769384510746", "event_type": "price_change"}}
{"_local_timestamp": "2026-01-25T23:41:50.886254+00:00", "data": {"market": "0x33315bd63d0cc17257c5d7524e5283639a5e17c6ce030d937f135aab02170c40", "price_changes": [{"asset_id": "92512666728361163935047824440150917945153592049030110328840756457871300635229", "price": "0.18", "size": "177.77", "side": "BUY", "hash": "57d2cd681626686e3e505ca3dc838a3f2ea47193", "best_bid": "0.8", "best_ask": "0.89"}, {"asset_id": "109227307115212040009558734329420624109955456904374090651494287022030420438197", "price": "0.82", "size": "177.77", "side": "SELL", "hash": "455662e0e08ee0021405bc7eccd5734c8d234c5c", "best_bid": "0.11", "best_ask": "0.2"}], "timestamp": "1769384510746", "event_type": "price_change"}}
{"_local_timestamp": "2026-01-25T23:41:50.887182+00:00", "data": {"market": "0x33315bd63d0cc17257c5d7524e5283639a5e17c6ce030d937f135aab02170c40", "price_changes": [{"asset_id": "92512666728361163935047824440150917945153592049030110328840756457871300635229", "price": "0.13", "size": "261.53", "side": "BUY", "hash": "57d2cd681626686e3e505ca3dc838a3f2ea47193", "best_bid": "0.8", "best_ask": "0.89"}, {"asset_id": "109227307115212040009558734329420624109955456904374090651494287022030420438197", "price": "0.87", "size": "261.53", "side": "SELL", "hash": "455662e0e08ee0021405bc7eccd5734c8d234c5c", "best_bid": "0.11", "best_ask": "0.2"}], "timestamp": "1769384510746", "event_type": "price_change"}}
{"_local_timestamp": "2026-01-25T23:41:50.888752+00:00", "data": {"market": "0x33315bd63d0cc17257c5d7524e5283639a5e17c6ce030d937f135aab02170c40", "price_changes": [{"asset_id": "92512666728361163935047824440150917945153592049030110328840756457871300635229", "price": "0.22", "size": "127.27", "side": "BUY", "hash": "57d2cd681626686e3e505ca3dc838a3f2ea47193", "best_bid": "0.8", "best_ask": "0.89"}, {"asset_id": "109227307115212040009558734329420624109955456904374090651494287022030420438197", "price": "0.78", "size": "127.27", "side": "SELL", "hash": "455662e0e08ee0021405bc7eccd5734c8d234c5c", "best_bid": "0.11", "best_ask": "0.2"}], "timestamp": "1769384510746", "event_type": "price_change"}}
{"_local_timestamp": "2026-01-25T23:41:50.889406+00:00", "data": {"market": "0xc7e04626fbed6834456b0b9ed45e7da039ad826933e3abba81e26e71a79b2388", "price_changes": [{"asset_id": "108633032965983853701783501560325265009339710531442379830307955199797783135140", "price": "0.21", "size": "133.33", "side": "BUY", "hash": "9f04c2f97df3de7700d476b77e789b58892bc2e9", "best_bid": "0.82", "best_ask": "0.95"}, {"asset_id": "20915970858057867358422412033597169312902618738489336824716408730559800805214", "price": "0.79", "size": "133.33", "side": "SELL", "hash": "9c77680f3061712cf473378457e27db830c45b89", "best_bid": "0.05", "best_ask": "0.18"}], "timestamp": "1769384510745", "event_type": "price_change"}}
{"_local_timestamp": "2026-01-25T23:41:50.899727+00:00", "data": {"market": "0xb3c09b93dc7b394fbea2b169b54da525c5d6de9ad5caf56da920058e7b74f161", "price_changes": [{"asset_id": "39663779628084842897937886547518878184317206079104235500705380518100175496233", "price": "0.19", "size": "147.36", "side": "BUY", "hash": "1f26566dd168e03507a481019fc83582f85f278d", "best_bid": "0.75", "best_ask": "0.89"}, {"asset_id": "100335878774855355346358755214398113208570878540440188453565903904895328912285", "price": "0.81", "size": "147.36", "side": "SELL", "hash": "f02fdaf34d0cda5a3f19faf3843a3c5822a9d1f2", "best_bid": "0.11", "best_ask": "0.25"}], "timestamp": "1769384510745", "event_type": "price_change"}}
{"_local_timestamp": "2026-01-25T23:41:50.900269+00:00", "data": {"market": "0xb3c09b93dc7b394fbea2b169b54da525c5d6de9ad5caf56da920058e7b74f161", "price_changes": [{"asset_id": "39663779628084842897937886547518878184317206079104235500705380518100175496233", "price": "0.23", "size": "128.04", "side": "BUY", "hash": "1f26566dd168e03507a481019fc83582f85f278d", "best_bid": "0.75", "best_ask": "0.89"}, {"asset_id": "100335878774855355346358755214398113208570878540440188453565903904895328912285", "price": "0.77", "size": "128.04", "side": "SELL", "hash": "f02fdaf34d0cda5a3f19faf3843a3c5822a9d1f2", "best_bid": "0.11", "best_ask": "0.25"}], "timestamp": "1769384510745", "event_type": "price_change"}}
{"_local_timestamp": "2026-01-25T23:41:50.901449+00:00", "data": {"market": "0xb3c09b93dc7b394fbea2b169b54da525c5d6de9ad5caf56da920058e7b74f161", "price_changes": [{"asset_id": "39663779628084842897937886547518878184317206079104235500705380518100175496233", "price": "0.11", "size": "309.09", "side": "BUY", "hash": "1f26566dd168e03507a481019fc83582f85f278d", "best_bid": "0.75", "best_ask": "0.89"}, {"asset_id": "100335878774855355346358755214398113208570878540440188453565903904895328912285", "price": "0.89", "size": "309.09", "side": "SELL", "hash": "f02fdaf34d0cda5a3f19faf3843a3c5822a9d1f2", "best_bid": "0.11", "best_ask": "0.25"}], "timestamp": "1769384510745", "event_type": "price_change"}}
{"_local_timestamp": "2026-01-25T23:42:13.444027+00:00", "data": {"market": "0xb3c09b93dc7b394fbea2b169b54da525c5d6de9ad5caf56da920058e7b74f161", "price_changes": [{"asset_id": "39663779628084842897937886547518878184317206079104235500705380518100175496233", "price": "0.69", "size": "20", "side": "BUY", "hash": "7b039317833bd40a7e46141c147b36740c00bf17", "best_bid": "0.75", "best_ask": "0.89"}, {"asset_id": "100335878774855355346358755214398113208570878540440188453565903904895328912285", "price": "0.31", "size": "20", "side": "SELL", "hash": "274faf55cd9e66504ae8a5df1b75d69c5ac1b500", "best_bid": "0.11", "best_ask": "0.25"}], "timestamp": "1769384533381", "event_type": "price_change"}}
{"_local_timestamp": "2026-01-25T23:42:25.092889+00:00", "data": {"market": "0x7f04c6bd72b53986c4e05d52ffdb3a0e8717ae809be62a1d4ec481313e86a0d0", "price_changes": [{"asset_id": "102967796728400955038420194199510769009042070489201650126144119775936757647743", "price": "0.33", "size": "860", "side": "BUY", "hash": "2ad69d4340817218fbd98a43463abb0bde0d5914", "best_bid": "0.86", "best_ask": "0.94"}, {"asset_id": "53325847113338736338902840435383727831746710692724054663504837250405920447353", "price": "0.67", "size": "860", "side": "SELL", "hash": "186755e4ea68c452807eac3dd508bb7a47bcaf4b", "best_bid": "0.06", "best_ask": "0.14"}], "timestamp": "1769384544905", "event_type": "price_change"}}
{"_local_timestamp": "2026-01-25T23:42:25.100523+00:00", "data": {"market": "0xc7e04626fbed6834456b0b9ed45e7da039ad826933e3abba81e26e71a79b2388", "price_changes": [{"asset_id": "108633032965983853701783501560325265009339710531442379830307955199797783135140", "price": "0.21", "size": "183.33", "side": "BUY", "hash": "de9d164de90808a06d91b2375f771b977bfe8758", "best_bid": "0.82", "best_ask": "0.95"}, {"asset_id": "20915970858057867358422412033597169312902618738489336824716408730559800805214", "price": "0.79", "size": "183.33", "side": "SELL", "hash": "4606523f09a23f22c9a4a22be0c1afdfe6b6101e", "best_bid": "0.05", "best_ask": "0.18"}], "timestamp": "1769384544908", "event_type": "price_change"}}
{"_local_timestamp": "2026-01-25T23:42:25.100987+00:00", "data": {"market": "0x33315bd63d0cc17257c5d7524e5283639a5e17c6ce030d937f135aab02170c40", "price_changes": [{"asset_id": "92512666728361163935047824440150917945153592049030110328840756457871300635229", "price": "0.13", "size": "386.53", "side": "BUY", "hash": "aed4f9ca610f40134a5f6baafe586b0b069b5f1f", "best_bid": "0.8", "best_ask": "0.89"}, {"asset_id": "109227307115212040009558734329420624109955456904374090651494287022030420438197", "price": "0.87", "size": "386.53", "side": "SELL", "hash": "8f73bde3dfad37f692dcd237a8f56773b1f3a239", "best_bid": "0.11", "best_ask": "0.2"}], "timestamp": "1769384544903", "event_type": "price_change"}}
{"_local_timestamp": "2026-01-25T23:42:25.147677+00:00", "data": {"market": "0xb3c09b93dc7b394fbea2b169b54da525c5d6de9ad5caf56da920058e7b74f161", "price_changes": [{"asset_id": "39663779628084842897937886547518878184317206079104235500705380518100175496233", "price": "0.11", "size": "434.09", "side": "BUY", "hash": "29559444c9ad0b8ae807e757d3712d80e2ea4b6a", "best_bid": "0.75", "best_ask": "0.89"}, {"asset_id": "100335878774855355346358755214398113208570878540440188453565903904895328912285", "price": "0.89", "size": "434.09", "side": "SELL", "hash": "51f2c21e2f81725ae54dcbf2261daf19fd0f888f", "best_bid": "0.11", "best_ask": "0.25"}], "timestamp": "1769384544929", "event_type": "price_change"}}
{"_local_timestamp": "2026-01-25T23:42:25.181503+00:00", "data": {"market": "0x33315bd63d0cc17257c5d7524e5283639a5e17c6ce030d937f135aab02170c40", "price_changes": [{"asset_id": "92512666728361163935047824440150917945153592049030110328840756457871300635229", "price": "0.18", "size": "277.77", "side": "BUY", "hash": "5bbc7d53dafe2d53fe06b9afe61a1a962d9f51f6", "best_bid": "0.8", "best_ask": "0.89"}, {"asset_id": "109227307115212040009558734329420624109955456904374090651494287022030420438197", "price": "0.82", "size": "277.77", "side": "SELL", "hash": "00848fbbfb665b335c79ea7cf4bd8e6f060b14c8", "best_bid": "0.11", "best_ask": "0.2"}], "timestamp": "1769384544944", "event_type": "price_change"}}
{"_local_timestamp": "2026-01-25T23:42:25.182572+00:00", "data": {"market": "0xb3c09b93dc7b394fbea2b169b54da525c5d6de9ad5caf56da920058e7b74f161", "price_changes": [{"asset_id": "39663779628084842897937886547518878184317206079104235500705380518100175496233", "price": "0.19", "size": "247.36", "side": "BUY", "hash": "7b388872c9972c847705792db3ff3749933b0dcb", "best_bid": "0.75", "best_ask": "0.89"}, {"asset_id": "100335878774855355346358755214398113208570878540440188453565903904895328912285", "price": "0.81", "size": "247.36", "side": "SELL", "hash": "eebdb7d1b6455a7cd60da3b07dffe63f1d18490c", "best_bid": "0.11", "best_ask": "0.25"}], "timestamp": "1769384544953", "event_type": "price_change"}}
{"_local_timestamp": "2026-01-25T23:42:25.188314+00:00", "data": {"market": "0x33315bd63d0cc17257c5d7524e5283639a5e17c6ce030d937f135aab02170c40", "price_changes": [{"asset_id": "92512666728361163935047824440150917945153592049030110328840756457871300635229", "price": "0.69", "size": "20", "side": "BUY", "hash": "8461d62e6e75d107de562252876201b9752b0199", "best_bid": "0.8", "best_ask": "0.89"}, {"asset_id": "109227307115212040009558734329420624109955456904374090651494287022030420438197", "price": "0.31", "size": "20", "side": "SELL", "hash": "5048714f1a84e449af237f52086d7a9a54608dd8", "best_bid": "0.11", "best_ask": "0.2"}], "timestamp": "1769384544985", "event_type": "price_change"}}
{"_local_timestamp": "2026-01-25T23:42:25.237407+00:00", "data": {"market": "0xc7e04626fbed6834456b0b9ed45e7da039ad826933e3abba81e26e71a79b2388", "price_changes": [{"asset_id": "108633032965983853701783501560325265009339710531442379830307955199797783135140", "price": "0.26", "size": "0", "side": "BUY", "hash": "a318797c404a94b279de321c58055aa49b97ddec", "best_bid": "0.82", "best_ask": "0.95"}, {"asset_id": "20915970858057867358422412033597169312902618738489336824716408730559800805214", "price": "0.74", "size": "0", "side": "SELL", "hash": "d17d8168fccb4fc4ac6d1e5655a29db8fdab4a1b", "best_bid": "0.05", "best_ask": "0.18"}], "timestamp": "1769384545098", "event_type": "price_change"}}
{"_local_timestamp": "2026-01-25T23:42:28.521355+00:00", "data": {"market": "0x7f04c6bd72b53986c4e05d52ffdb3a0e8717ae809be62a1d4ec481313e86a0d0", "price_changes": [{"asset_id": "102967796728400955038420194199510769009042070489201650126144119775936757647743", "price": "0.74", "size": "20", "side": "BUY", "hash": "645fa1f09982f474312eef93274513ce488c7dcf", "best_bid": "0.86", "best_ask": "0.94"}, {"asset_id": "53325847113338736338902840435383727831746710692724054663504837250405920447353", "price": "0.26", "size": "20", "side": "SELL", "hash": "79342f44ff9d32c42cbb0c63176b69bb6a551fc7", "best_bid": "0.06", "best_ask": "0.14"}], "timestamp": "1769384548382", "event_type": "price_change"}}
{"_local_timestamp": "2026-01-25T23:42:33.127826+00:00", "data": {"market": "0x2df8bb66d0a96661ec2a4f57b0510ca7c8e154d78d6d8f3b557478ddc34fcfae", "price_changes": [{"asset_id": "34218064140411222044683093812278888477247876051063075885631415084973387284228", "price": "0.47", "size": "0", "side": "BUY", "hash": "2c665463aa0cf7071646f55f4d98d954acde285a", "best_bid": "0.48", "best_ask": "0.61"}, {"asset_id": "104293714017628859730042534598620180600303966146090765434616358106204241123622", "price": "0.53", "size": "0", "side": "SELL", "hash": "de131086af4aae44347c232b3666e557b72bce1f", "best_bid": "0.39", "best_ask": "0.52"}], "timestamp": "1769384553000", "event_type": "price_change"}}
{"_local_timestamp": "2026-01-25T23:42:33.139910+00:00", "data": {"market": "0xb3c09b93dc7b394fbea2b169b54da525c5d6de9ad5caf56da920058e7b74f161", "price_changes": [{"asset_id": "100335878774855355346358755214398113208570878540440188453565903904895328912285", "price": "0.11", "size": "66.66", "side": "BUY", "hash": "7bb361e4a361a0a4ab1a347c12ecae72d586625f", "best_bid": "0.11", "best_ask": "0.25"}, {"asset_id": "39663779628084842897937886547518878184317206079104235500705380518100175496233", "price": "0.89", "size": "66.66", "side": "SELL", "hash": "d90981eb64a61497923775a86cc91b7143c7f80a", "best_bid": "0.75", "best_ask": "0.89"}], "timestamp": "1769384553001", "event_type": "price_change"}}
{"_local_timestamp": "2026-01-25T23:42:33.212715+00:00", "data": {"market": "0xb3c09b93dc7b394fbea2b169b54da525c5d6de9ad5caf56da920058e7b74f161", "price_changes": [{"asset_id": "39663779628084842897937886547518878184317206079104235500705380518100175496233", "price": "0.34", "size": "0", "side": "BUY", "hash": "f9e0c5ff2f00c6f4fee1a2293079ced81e73418f", "best_bid": "0.75", "best_ask": "0.89"}, {"asset_id": "100335878774855355346358755214398113208570878540440188453565903904895328912285", "price": "0.66", "size": "0", "side": "SELL", "hash": "283e96316c9dbd2a7af2d8585d4bbeb3cb66a639", "best_bid": "0.11", "best_ask": "0.25"}], "timestamp": "1769384553080", "event_type": "price_change"}}
{"_local_timestamp": "2026-01-25T23:42:40.107364+00:00", "data": {"market": "0xb3c09b93dc7b394fbea2b169b54da525c5d6de9ad5caf56da920058e7b74f161", "price_changes": [{"asset_id": "39663779628084842897937886547518878184317206079104235500705380518100175496233", "price": "0.08", "size": "950", "side": "BUY", "hash": "6618da4e0bfea61fdf73882e4fb710f8d608adb5", "best_bid": "0.75", "best_ask": "0.89"}, {"asset_id": "100335878774855355346358755214398113208570878540440188453565903904895328912285", "price": "0.92", "size": "950", "side": "SELL", "hash": "bcc871299178b3c10fe5b9db901f7bc27363f762", "best_bid": "0.11", "best_ask": "0.25"}], "timestamp": "1769384559917", "event_type": "price_change"}}
{"_local_timestamp": "2026-01-25T23:42:40.194964+00:00", "data": {"market": "0x33315bd63d0cc17257c5d7524e5283639a5e17c6ce030d937f135aab02170c40", "price_changes": [{"asset_id": "92512666728361163935047824440150917945153592049030110328840756457871300635229", "price": "0.09", "size": "900", "side": "BUY", "hash": "d44001cb672751ac0c823d8901349d62b9a328b5", "best_bid": "0.8", "best_ask": "0.89"}, {"asset_id": "109227307115212040009558734329420624109955456904374090651494287022030420438197", "price": "0.91", "size": "900", "side": "SELL", "hash": "cee6c7db9718974520b604dcfe451b29b79ddcaa", "best_bid": "0.11", "best_ask": "0.2"}], "timestamp": "1769384559928", "event_type": "price_change"}}
{"_local_timestamp": "2026-01-25T23:42:40.293091+00:00", "data": {"market": "0x7f04c6bd72b53986c4e05d52ffdb3a0e8717ae809be62a1d4ec481313e86a0d0", "price_changes": [{"asset_id": "102967796728400955038420194199510769009042070489201650126144119775936757647743", "price": "0.22", "size": "0", "side": "BUY", "hash": "0ebedd7e7088fa4e0c6e8154c3ffdca14a609470", "best_bid": "0.86", "best_ask": "0.94"}, {"asset_id": "53325847113338736338902840435383727831746710692724054663504837250405920447353", "price": "0.78", "size": "0", "side": "SELL", "hash": "7f2d8836a2cead943bc4bb157a8575a2997ec689", "best_bid": "0.06", "best_ask": "0.14"}], "timestamp": "1769384560073", "event_type": "price_change"}}
{"_local_timestamp": "2026-01-25T23:42:40.373146+00:00", "data": {"market": "0x33315bd63d0cc17257c5d7524e5283639a5e17c6ce030d937f135aab02170c40", "price_changes": [{"asset_id": "92512666728361163935047824440150917945153592049030110328840756457871300635229", "price": "0.2", "size": "0", "side": "BUY", "hash": "28c32bc398a04cdccc48f37286f55bfdf85b9a45", "best_bid": "0.8", "best_ask": "0.89"}, {"asset_id": "109227307115212040009558734329420624109955456904374090651494287022030420438197", "price": "0.8", "size": "0", "side": "SELL", "hash": "ca31cafcc44dbceeb6ca374d6588dd7c66e80ba4", "best_bid": "0.11", "best_ask": "0.2"}], "timestamp": "1769384560242", "event_type": "price_change"}}
{"_local_timestamp": "2026-01-25T23:42:40.373679+00:00", "data": {"market": "0x7f04c6bd72b53986c4e05d52ffdb3a0e8717ae809be62a1d4ec481313e86a0d0", "price_changes": [{"asset_id": "102967796728400955038420194199510769009042070489201650126144119775936757647743", "price": "0.33", "size": "850", "side": "BUY", "hash": "2b845aeed4e80ed9c327f183ccb1a23e4c1f666a", "best_bid": "0.86", "best_ask": "0.94"}, {"asset_id": "53325847113338736338902840435383727831746710692724054663504837250405920447353", "price": "0.67", "size": "850", "side": "SELL", "hash": "6ed94f46416b4aac48bd934d326f510a383dfca6", "best_bid": "0.06", "best_ask": "0.14"}], "timestamp": "1769384560242", "event_type": "price_change"}}
{"_local_timestamp": "2026-01-25T23:42:40.427718+00:00", "data": {"market": "0x7f04c6bd72b53986c4e05d52ffdb3a0e8717ae809be62a1d4ec481313e86a0d0", "price_changes": [{"asset_id": "102967796728400955038420194199510769009042070489201650126144119775936757647743", "price": "0.39", "size": "15", "side": "BUY", "hash": "15fb23bbdb6121620e78deff263f21938a38ff4e", "best_bid": "0.86", "best_ask": "0.94"}, {"asset_id": "53325847113338736338902840435383727831746710692724054663504837250405920447353", "price": "0.61", "size": "15", "side": "SELL", "hash": "df0b8f9ab33b4c8b639e058bed0003b4c419c3be", "best_bid": "0.06", "best_ask": "0.14"}], "timestamp": "1769384560290", "event_type": "price_change"}}
{"_local_timestamp": "2026-01-25T23:42:40.428290+00:00", "data": {"market": "0x7f04c6bd72b53986c4e05d52ffdb3a0e8717ae809be62a1d4ec481313e86a0d0", "price_changes": [{"asset_id": "102967796728400955038420194199510769009042070489201650126144119775936757647743", "price": "0.39", "size": "25", "side": "BUY", "hash": "fa0d1022077d923e778b0b15432b0040ee5f14fe", "best_bid": "0.86", "best_ask": "0.94"}, {"asset_id": "53325847113338736338902840435383727831746710692724054663504837250405920447353", "price": "0.61", "size": "25", "side": "SELL", "hash": "ab0ad72df0fdfdae2b3e0b786efbac6484cecebe", "best_bid": "0.06", "best_ask": "0.14"}], "timestamp": "1769384560294", "event_type": "price_change"}}
{"_local_timestamp": "2026-01-25T23:42:40.545525+00:00", "data": {"market": "0x33315bd63d0cc17257c5d7524e5283639a5e17c6ce030d937f135aab02170c40", "price_changes": [{"asset_id": "92512666728361163935047824440150917945153592049030110328840756457871300635229", "price": "0.23", "size": "0", "side": "BUY", "hash": "1226bdb68ba029268d4c53554afe66e386882a56", "best_bid": "0.8", "best_ask": "0.89"}, {"asset_id": "109227307115212040009558734329420624109955456904374090651494287022030420438197", "price": "0.77", "size": "0", "side": "SELL", "hash": "fb5c6b5a74764651fd8164c7ecd9a312bd0c65aa", "best_bid": "0.11", "best_ask": "0.2"}], "timestamp": "1769384560411", "event_type": "price_change"}}
{"_local_timestamp": "2026-01-25T23:42:40.725583+00:00", "data": {"market": "0x33315bd63d0cc17257c5d7524e5283639a5e17c6ce030d937f135aab02170c40", "price_changes": [{"asset_id": "92512666728361163935047824440150917945153592049030110328840756457871300635229", "price": "0.38", "size": "15", "side": "BUY", "hash": "73da6d80d27b8ee482cc5cd88ca90c2394e965bd", "best_bid": "0.8", "best_ask": "0.89"}, {"asset_id": "109227307115212040009558734329420624109955456904374090651494287022030420438197", "price": "0.62", "size": "15", "side": "SELL", "hash": "50f9fe07b66882740f72f7e85e4da7c6d62ee3ec", "best_bid": "0.11", "best_ask": "0.2"}], "timestamp": "1769384560590", "event_type": "price_change"}}
{"_local_timestamp": "2026-01-25T23:42:40.726128+00:00", "data": {"market": "0x33315bd63d0cc17257c5d7524e5283639a5e17c6ce030d937f135aab02170c40", "price_changes": [{"asset_id": "92512666728361163935047824440150917945153592049030110328840756457871300635229", "price": "0.38", "size": "25", "side": "BUY", "hash": "ff70c27742708952bb7f96c5a6d4a9d2cd5250d4", "best_bid": "0.8", "best_ask": "0.89"}, {"asset_id": "109227307115212040009558734329420624109955456904374090651494287022030420438197", "price": "0.62", "size": "25", "side": "SELL", "hash": "5060e03acd2f8ddd9bd23730235ea41913f9d70b", "best_bid": "0.11", "best_ask": "0.2"}], "timestamp": "1769384560592", "event_type": "price_change"}}
{"_local_timestamp": "2026-01-25T23:43:13.002439+00:00", "data": {"market": "0x2df8bb66d0a96661ec2a4f57b0510ca7c8e154d78d6d8f3b557478ddc34fcfae", "price_changes": [{"asset_id": "104293714017628859730042534598620180600303966146090765434616358106204241123622", "price": "0.06", "size": "133", "side": "BUY", "hash": "9efe202609ca2089d673b24520c582de6c6a62d6", "best_bid": "0.39", "best_ask": "0.52"}, {"asset_id": "34218064140411222044683093812278888477247876051063075885631415084973387284228", "price": "0.94", "size": "133", "side": "SELL", "hash": "109f4ef57a7a11e140a53f924925bcf7f7dc14cf", "best_bid": "0.48", "best_ask": "0.61"}], "timestamp": "1769384592869", "event_type": "price_change"}}
{"_local_timestamp": "2026-01-25T23:43:13.328602+00:00", "data": {"market": "0xb3c09b93dc7b394fbea2b169b54da525c5d6de9ad5caf56da920058e7b74f161", "price_changes": [{"asset_id": "39663779628084842897937886547518878184317206079104235500705380518100175496233", "price": "0.24", "size": "61.6", "side": "BUY", "hash": "a24cb710c7daf4e5c304d4e62e22f8dffafd14a0", "best_bid": "0.75", "best_ask": "0.89"}, {"asset_id": "100335878774855355346358755214398113208570878540440188453565903904895328912285", "price": "0.76", "size": "61.6", "side": "SELL", "hash": "11674a323eb85261827f7bfd9315187ce2843f35", "best_bid": "0.11", "best_ask": "0.25"}], "timestamp": "1769384592908", "event_type": "price_change"}}
{"_local_timestamp": "2026-01-25T23:43:13.353931+00:00", "data": {"market": "0x2df8bb66d0a96661ec2a4f57b0510ca7c8e154d78d6d8f3b557478ddc34fcfae", "price_changes": [{"asset_id": "34218064140411222044683093812278888477247876051063075885631415084973387284228", "price": "0.06", "size": "100", "side": "BUY", "hash": "3ba2a8e14db9704e42c845aa994f04abb4d5fac4", "best_bid": "0.48", "best_ask": "0.61"}, {"asset_id": "104293714017628859730042534598620180600303966146090765434616358106204241123622", "price": "0.94", "size": "100", "side": "SELL", "hash": "036bd288fcbfb63660439fa9f8e06a761022e9cf", "best_bid": "0.39", "best_ask": "0.52"}], "timestamp": "1769384593148", "event_type": "price_change"}}
{"_local_timestamp": "2026-01-25T23:43:54.147820+00:00", "data": {"market": "0x33315bd63d0cc17257c5d7524e5283639a5e17c6ce030d937f135aab02170c40", "price_changes": [{"asset_id": "92512666728361163935047824440150917945153592049030110328840756457871300635229", "price": "0.8", "size": "0", "side": "BUY", "hash": "31d468854e421fddbcbb69ca35c95b0b1051e9c9", "best_bid": "0.79", "best_ask": "0.89"}, {"asset_id": "109227307115212040009558734329420624109955456904374090651494287022030420438197", "price": "0.2", "size": "0", "side": "SELL", "hash": "d0978e671f7c358a0a9cbe7255b01b02fa40d1c5", "best_bid": "0.11", "best_ask": "0.21"}], "timestamp": "1769384634000", "event_type": "price_change"}}
{"_local_timestamp": "2026-01-25T23:43:54.160007+00:00", "data": {"market": "0xb3c09b93dc7b394fbea2b169b54da525c5d6de9ad5caf56da920058e7b74f161", "price_changes": [{"asset_id": "39663779628084842897937886547518878184317206079104235500705380518100175496233", "price": "0.73", "size": "0", "side": "BUY", "hash": "0afaa35e592c79e7e48298887f052ceef45054b7", "best_bid": "0.75", "best_ask": "0.89"}, {"asset_id": "100335878774855355346358755214398113208570878540440188453565903904895328912285", "price": "0.27", "size": "0", "side": "SELL", "hash": "d874a61cba240e8dfe1e55d73ae5f97ef8530d47", "best_bid": "0.11", "best_ask": "0.25"}], "timestamp": "1769384634001", "event_type": "price_change"}}
{"_local_timestamp": "2026-01-25T23:43:54.160675+00:00", "data": {"market": "0x7f04c6bd72b53986c4e05d52ffdb3a0e8717ae809be62a1d4ec481313e86a0d0", "price_changes": [{"asset_id": "102967796728400955038420194199510769009042070489201650126144119775936757647743", "price": "0.86", "size": "0", "side": "BUY", "hash": "26a81a7f7ee58d7ed1c260803cff055c517ffe04", "best_bid": "0.85", "best_ask": "0.94"}, {"asset_id": "53325847113338736338902840435383727831746710692724054663504837250405920447353", "price": "0.14", "size": "0", "side": "SELL", "hash": "bb3d9574159f6cf534c98424e20599a2128294be", "best_bid": "0.06", "best_ask": "0.15"}], "timestamp": "1769384634000", "event_type": "price_change"}}
{"_local_timestamp": "2026-01-25T23:43:54.161244+00:00", "data": {"market": "0x2df8bb66d0a96661ec2a4f57b0510ca7c8e154d78d6d8f3b557478ddc34fcfae", "price_changes": [{"asset_id": "104293714017628859730042534598620180600303966146090765434616358106204241123622", "price": "0.37", "size": "0", "side": "BUY", "hash": "260f2e34f87ee8f64ec1001f34cbe90dff5148e9", "best_bid": "0.39", "best_ask": "0.52"}, {"asset_id": "34218064140411222044683093812278888477247876051063075885631415084973387284228", "price": "0.63", "size": "0", "side": "SELL", "hash": "89c8692ae8c583baf6a6c26a4d598eb516433198", "best_bid": "0.48", "best_ask": "0.61"}], "timestamp": "1769384634000", "event_type": "price_change"}}
{"_local_timestamp": "2026-01-25T23:43:54.166032+00:00", "data": {"market": "0xc7e04626fbed6834456b0b9ed45e7da039ad826933e3abba81e26e71a79b2388", "price_changes": [{"asset_id": "108633032965983853701783501560325265009339710531442379830307955199797783135140", "price": "0.82", "size": "0", "side": "BUY", "hash": "f99210363d5b464e66df6222bc3962b2a756c444", "best_bid": "0.81", "best_ask": "0.95"}, {"asset_id": "20915970858057867358422412033597169312902618738489336824716408730559800805214", "price": "0.18", "size": "0", "side": "SELL", "hash": "d045c6c836a6d5b7114aab738668edb586b49e3d", "best_bid": "0.05", "best_ask": "0.19"}], "timestamp": "1769384634002", "event_type": "price_change"}}
{"_local_timestamp": "2026-01-25T23:43:56.706149+00:00", "data": {"market": "0x2df8bb66d0a96661ec2a4f57b0510ca7c8e154d78d6d8f3b557478ddc34fcfae", "price_changes": [{"asset_id": "34218064140411222044683093812278888477247876051063075885631415084973387284228", "price": "0.48", "size": "0", "side": "BUY", "hash": "36cfcc2a27ed69475d2ebb7ac0612326d384d763", "best_bid": "0.22", "best_ask": "0.61"}, {"asset_id": "104293714017628859730042534598620180600303966146090765434616358106204241123622", "price": "0.52", "size": "0", "side": "SELL", "hash": "92efa79081df77284bf660391327df1f6ccd47de", "best_bid": "0.39", "best_ask": "0.78"}], "timestamp": "1769384636547", "event_type": "price_change"}}
{"_local_timestamp": "2026-01-25T23:43:56.706777+00:00", "data": {"market": "0x2df8bb66d0a96661ec2a4f57b0510ca7c8e154d78d6d8f3b557478ddc34fcfae", "price_changes": [{"asset_id": "34218064140411222044683093812278888477247876051063075885631415084973387284228", "price": "0.32", "size": "0", "side": "BUY", "hash": "36cfcc2a27ed69475d2ebb7ac0612326d384d763", "best_bid": "0.22", "best_ask": "0.61"}, {"asset_id": "104293714017628859730042534598620180600303966146090765434616358106204241123622", "price": "0.68", "size": "0", "side": "SELL", "hash": "92efa79081df77284bf660391327df1f6ccd47de", "best_bid": "0.39", "best_ask": "0.78"}], "timestamp": "1769384636547", "event_type": "price_change"}}
{"_local_timestamp": "2026-01-25T23:43:56.707275+00:00", "data": {"market": "0x33315bd63d0cc17257c5d7524e5283639a5e17c6ce030d937f135aab02170c40", "price_changes": [{"asset_id": "92512666728361163935047824440150917945153592049030110328840756457871300635229", "price": "0.56", "size": "0", "side": "BUY", "hash": "f0e370cafc6a637ba4bf228dccf560505ac8bad3", "best_bid": "0.79", "best_ask": "0.89"}, {"asset_id": "109227307115212040009558734329420624109955456904374090651494287022030420438197", "price": "0.44", "size": "0", "side": "SELL", "hash": "b83cbacee0fba772a2c4571ef5f9dbd95ead52f1", "best_bid": "0.11", "best_ask": "0.21"}], "timestamp": "1769384636547", "event_type": "price_change"}}
{"_local_timestamp": "2026-01-25T23:43:56.707791+00:00", "data": {"market": "0xb3c09b93dc7b394fbea2b169b54da525c5d6de9ad5caf56da920058e7b74f161", "price_changes": [{"asset_id": "39663779628084842897937886547518878184317206079104235500705380518100175496233", "price": "0.5", "size": "0", "side": "BUY", "hash": "4317c99060de83e67db2ea4422dacfe0879a1cbf", "best_bid": "0.75", "best_ask": "0.89"}, {"asset_id": "100335878774855355346358755214398113208570878540440188453565903904895328912285", "price": "0.5", "size": "0", "side": "SELL", "hash": "3fe41a7997714c3e9a56732f83f12634fb05661c", "best_bid": "0.11", "best_ask": "0.25"}], "timestamp": "1769384636547", "event_type": "price_change"}}
{"_local_timestamp": "2026-01-25T23:43:56.708567+00:00", "data": {"market": "0x33315bd63d0cc17257c5d7524e5283639a5e17c6ce030d937f135aab02170c40", "price_changes": [{"asset_id": "92512666728361163935047824440150917945153592049030110328840756457871300635229", "price": "0.32", "size": "0", "side": "BUY", "hash": "f0e370cafc6a637ba4bf228dccf560505ac8bad3", "best_bid": "0.79", "best_ask": "0.89"}, {"asset_id": "109227307115212040009558734329420624109955456904374090651494287022030420438197", "price": "0.68", "size": "0", "side": "SELL", "hash": "b83cbacee0fba772a2c4571ef5f9dbd95ead52f1", "best_bid": "0.11", "best_ask": "0.21"}], "timestamp": "1769384636547", "event_type": "price_change"}}
{"_local_timestamp": "2026-01-25T23:43:56.709140+00:00", "data": {"market": "0xb3c09b93dc7b394fbea2b169b54da525c5d6de9ad5caf56da920058e7b74f161", "price_changes": [{"asset_id": "39663779628084842897937886547518878184317206079104235500705380518100175496233", "price": "0.24", "size": "0", "side": "BUY", "hash": "4317c99060de83e67db2ea4422dacfe0879a1cbf", "best_bid": "0.75", "best_ask": "0.89"}, {"asset_id": "100335878774855355346358755214398113208570878540440188453565903904895328912285", "price": "0.76", "size": "0", "side": "SELL", "hash": "3fe41a7997714c3e9a56732f83f12634fb05661c", "best_bid": "0.11", "best_ask": "0.25"}], "timestamp": "1769384636547", "event_type": "price_change"}}
{"_local_timestamp": "2026-01-25T23:43:56.709591+00:00", "data": {"market": "0x2df8bb66d0a96661ec2a4f57b0510ca7c8e154d78d6d8f3b557478ddc34fcfae", "price_changes": [{"asset_id": "104293714017628859730042534598620180600303966146090765434616358106204241123622", "price": "0.38", "size": "0", "side": "BUY", "hash": "4acc8bc5a874fac864fdb3d1c33e29dab54bf3cf", "best_bid": "0.39", "best_ask": "0.78"}, {"asset_id": "34218064140411222044683093812278888477247876051063075885631415084973387284228", "price": "0.62", "size": "0", "side": "SELL", "hash": "0f5e99a33ac6fc920f763bdefa28c42f3211c5cb", "best_bid": "0.22", "best_ask": "0.61"}], "timestamp": "1769384636547", "event_type": "price_change"}}
{"_local_timestamp": "2026-01-25T23:43:56.710064+00:00", "data": {"market": "0x2df8bb66d0a96661ec2a4f57b0510ca7c8e154d78d6d8f3b557478ddc34fcfae", "price_changes": [{"asset_id": "104293714017628859730042534598620180600303966146090765434616358106204241123622", "price": "0.25", "size": "10", "side": "BUY", "hash": "4acc8bc5a874fac864fdb3d1c33e29dab54bf3cf", "best_bid": "0.39", "best_ask": "0.78"}, {"asset_id": "34218064140411222044683093812278888477247876051063075885631415084973387284228", "price": "0.75", "size": "10", "side": "SELL", "hash": "0f5e99a33ac6fc920f763bdefa28c42f3211c5cb", "best_bid": "0.22", "best_ask": "0.61"}], "timestamp": "1769384636547", "event_type": "price_change"}}
{"_local_timestamp": "2026-01-25T23:43:56.710503+00:00", "data": {"market": "0x2df8bb66d0a96661ec2a4f57b0510ca7c8e154d78d6d8f3b557478ddc34fcfae", "price_changes": [{"asset_id": "104293714017628859730042534598620180600303966146090765434616358106204241123622", "price": "0.12", "size": "9.52", "side": "BUY", "hash": "4acc8bc5a874fac864fdb3d1c33e29dab54bf3cf", "best_bid": "0.39", "best_ask": "0.78"}, {"asset_id": "34218064140411222044683093812278888477247876051063075885631415084973387284228", "price": "0.88", "size": "9.52", "side": "SELL", "hash": "0f5e99a33ac6fc920f763bdefa28c42f3211c5cb", "best_bid": "0.22", "best_ask": "0.61"}], "timestamp": "1769384636547", "event_type": "price_change"}}
{"_local_timestamp": "2026-01-25T23:43:56.760445+00:00", "data": {"market": "0x2df8bb66d0a96661ec2a4f57b0510ca7c8e154d78d6d8f3b557478ddc34fcfae", "price_changes": [{"asset_id": "34218064140411222044683093812278888477247876051063075885631415084973387284228", "price": "0.05", "size": "0", "side": "BUY", "hash": "31cc58c7bd110ff383a86aec3c584d008345e192", "best_bid": "0.21", "best_ask": "0.61"}, {"asset_id": "104293714017628859730042534598620180600303966146090765434616358106204241123622", "price": "0.95", "size": "0", "side": "SELL", "hash": "300796098b8b2f309071be4ed7bc4aa60537719e", "best_bid": "0.39", "best_ask": "0.79"}], "timestamp": "1769384636621", "event_type": "price_change"}}
{"_local_timestamp": "2026-01-25T23:43:56.761007+00:00", "data": {"market": "0x2df8bb66d0a96661ec2a4f57b0510ca7c8e154d78d6d8f3b557478ddc34fcfae", "price_changes": [{"asset_id": "34218064140411222044683093812278888477247876051063075885631415084973387284228", "price": "0.14", "size": "0", "side": "BUY", "hash": "31cc58c7bd110ff383a86aec3c584d008345e192", "best_bid": "0.21", "best_ask": "0.61"}, {"asset_id": "104293714017628859730042534598620180600303966146090765434616358106204241123622", "price": "0.86", "size": "0", "side": "SELL", "hash": "300796098b8b2f309071be4ed7bc4aa60537719e", "best_bid": "0.39", "best_ask": "0.79"}], "timestamp": "1769384636621", "event_type": "price_change"}}
{"_local_timestamp": "2026-01-25T23:43:56.901891+00:00", "data": {"market": "0x2df8bb66d0a96661ec2a4f57b0510ca7c8e154d78d6d8f3b557478ddc34fcfae", "price_changes": [{"asset_id": "34218064140411222044683093812278888477247876051063075885631415084973387284228", "price": "0.11", "size": "0", "side": "BUY", "hash": "31cc58c7bd110ff383a86aec3c584d008345e192", "best_bid": "0.21", "best_ask": "0.61"}, {"asset_id": "104293714017628859730042534598620180600303966146090765434616358106204241123622", "price": "0.89", "size": "0", "side": "SELL", "hash": "300796098b8b2f309071be4ed7bc4aa60537719e", "best_bid": "0.39", "best_ask": "0.79"}], "timestamp": "1769384636621", "event_type": "price_change"}}
{"_local_timestamp": "2026-01-25T23:43:56.902414+00:00", "data": {"market": "0x2df8bb66d0a96661ec2a4f57b0510ca7c8e154d78d6d8f3b557478ddc34fcfae", "price_changes": [{"asset_id": "34218064140411222044683093812278888477247876051063075885631415084973387284228", "price": "0.08", "size": "0", "side": "BUY", "hash": "31cc58c7bd110ff383a86aec3c584d008345e192", "best_bid": "0.21", "best_ask": "0.61"}, {"asset_id": "104293714017628859730042534598620180600303966146090765434616358106204241123622", "price": "0.92", "size": "0", "side": "SELL", "hash": "300796098b8b2f309071be4ed7bc4aa60537719e", "best_bid": "0.39", "best_ask": "0.79"}], "timestamp": "1769384636621", "event_type": "price_change"}}
{"_local_timestamp": "2026-01-25T23:43:56.902872+00:00", "data": {"market": "0x2df8bb66d0a96661ec2a4f57b0510ca7c8e154d78d6d8f3b557478ddc34fcfae", "price_changes": [{"asset_id": "34218064140411222044683093812278888477247876051063075885631415084973387284228", "price": "0.19", "size": "0", "side": "BUY", "hash": "31cc58c7bd110ff383a86aec3c584d008345e192", "best_bid": "0.21", "best_ask": "0.61"}, {"asset_id": "104293714017628859730042534598620180600303966146090765434616358106204241123622", "price": "0.81", "size": "0", "side": "SELL", "hash": "300796098b8b2f309071be4ed7bc4aa60537719e", "best_bid": "0.39", "best_ask": "0.79"}], "timestamp": "1769384636621", "event_type": "price_change"}}
{"_local_timestamp": "2026-01-25T23:43:56.903317+00:00", "data": {"market": "0x2df8bb66d0a96661ec2a4f57b0510ca7c8e154d78d6d8f3b557478ddc34fcfae", "price_changes": [{"asset_id": "34218064140411222044683093812278888477247876051063075885631415084973387284228", "price": "0.16", "size": "0", "side": "BUY", "hash": "31cc58c7bd110ff383a86aec3c584d008345e192", "best_bid": "0.21", "best_ask": "0.61"}, {"asset_id": "104293714017628859730042534598620180600303966146090765434616358106204241123622", "price": "0.84", "size": "0", "side": "SELL", "hash": "300796098b8b2f309071be4ed7bc4aa60537719e", "best_bid": "0.39", "best_ask": "0.79"}], "timestamp": "1769384636621", "event_type": "price_change"}}
{"_local_timestamp": "2026-01-25T23:43:56.903766+00:00", "data": {"market": "0x2df8bb66d0a96661ec2a4f57b0510ca7c8e154d78d6d8f3b557478ddc34fcfae", "price_changes": [{"asset_id": "34218064140411222044683093812278888477247876051063075885631415084973387284228", "price": "0.22", "size": "0", "side": "BUY", "hash": "31cc58c7bd110ff383a86aec3c584d008345e192", "best_bid": "0.21", "best_ask": "0.61"}, {"asset_id": "104293714017628859730042534598620180600303966146090765434616358106204241123622", "price": "0.78", "size": "0", "side": "SELL", "hash": "300796098b8b2f309071be4ed7bc4aa60537719e", "best_bid": "0.39", "best_ask": "0.79"}], "timestamp": "1769384636621", "event_type": "price_change"}}
{"_local_timestamp": "2026-01-25T23:43:56.904227+00:00", "data": {"market": "0x7f04c6bd72b53986c4e05d52ffdb3a0e8717ae809be62a1d4ec481313e86a0d0", "price_changes": [{"asset_id": "102967796728400955038420194199510769009042070489201650126144119775936757647743", "price": "0.74", "size": "0", "side": "BUY", "hash": "d1744e544843be0157b69a96134332fad9b3b870", "best_bid": "0.85", "best_ask": "0.94"}, {"asset_id": "53325847113338736338902840435383727831746710692724054663504837250405920447353", "price": "0.26", "size": "0", "side": "SELL", "hash": "e5703ef68e2ddd1a9bd123c44fa52826923bc36d", "best_bid": "0.06", "best_ask": "0.15"}], "timestamp": "1769384636631", "event_type": "price_change"}}
{"_local_timestamp": "2026-01-25T23:43:56.904683+00:00", "data": {"market": "0x33315bd63d0cc17257c5d7524e5283639a5e17c6ce030d937f135aab02170c40", "price_changes": [{"asset_id": "92512666728361163935047824440150917945153592049030110328840756457871300635229", "price": "0.69", "size": "0", "side": "BUY", "hash": "04587941c28518d7f5cf4f312bf925454ba86c38", "best_bid": "0.79", "best_ask": "0.89"}, {"asset_id": "109227307115212040009558734329420624109955456904374090651494287022030420438197", "price": "0.31", "size": "0", "side": "SELL", "hash": "01c9a963d97d74d1f1b7633da9a52a84bbca1e39", "best_bid": "0.11", "best_ask": "0.21"}], "timestamp": "1769384636631", "event_type": "price_change"}}
{"_local_timestamp": "2026-01-25T23:43:56.905136+00:00", "data": {"market": "0xb3c09b93dc7b394fbea2b169b54da525c5d6de9ad5caf56da920058e7b74f161", "price_changes": [{"asset_id": "39663779628084842897937886547518878184317206079104235500705380518100175496233", "price": "0.69", "size": "0", "side": "BUY", "hash": "b8d66cd3f8cc7c31ded2cbc0157e04d63b4ffba2", "best_bid": "0.75", "best_ask": "0.89"}, {"asset_id": "100335878774855355346358755214398113208570878540440188453565903904895328912285", "price": "0.31", "size": "0", "side": "SELL", "hash": "fb59ba849372060f7ee35ffad6fbe81bc54619d4", "best_bid": "0.11", "best_ask": "0.25"}], "timestamp": "1769384636631", "event_type": "price_change"}}
{"_local_timestamp": "2026-01-25T23:43:56.905594+00:00", "data": {"market": "0x33315bd63d0cc17257c5d7524e5283639a5e17c6ce030d937f135aab02170c40", "price_changes": [{"asset_id": "92512666728361163935047824440150917945153592049030110328840756457871300635229", "price": "0.38", "size": "0", "side": "BUY", "hash": "37c9588d078a9928ac2b76a64bfe5d37671186f6", "best_bid": "0.79", "best_ask": "0.89"}, {"asset_id": "109227307115212040009558734329420624109955456904374090651494287022030420438197", "price": "0.62", "size": "0", "side": "SELL", "hash": "96943cdb1ada95be1edbeaabe55ae72d60e3866a", "best_bid": "0.11", "best_ask": "0.21"}], "timestamp": "1769384636641", "event_type": "price_change"}}
{"_local_timestamp": "2026-01-25T23:43:56.906073+00:00", "data": {"market": "0x7f04c6bd72b53986c4e05d52ffdb3a0e8717ae809be62a1d4ec481313e86a0d0", "price_changes": [{"asset_id": "102967796728400955038420194199510769009042070489201650126144119775936757647743", "price": "0.39", "size": "0", "side": "BUY", "hash": "a623dd83966d4fb5bd877b2ee081cc015cc14fe2", "best_bid": "0.85", "best_ask": "0.94"}, {"asset_id": "53325847113338736338902840435383727831746710692724054663504837250405920447353", "price": "0.61", "size": "0", "side": "SELL", "hash": "3092bb9dcc4d59570ec4972d231b9d4907e85258", "best_bid": "0.06", "best_ask": "0.15"}], "timestamp": "1769384636641", "event_type": "price_change"}}
{"_local_timestamp": "2026-01-25T23:43:56.906544+00:00", "data": {"market": "0xc7e04626fbed6834456b0b9ed45e7da039ad826933e3abba81e26e71a79b2388", "price_changes": [{"asset_id": "108633032965983853701783501560325265009339710531442379830307955199797783135140", "price": "0.3", "size": "0", "side": "BUY", "hash": "295deb3d9af5193636cc4a530ceab4da9a83e7d1", "best_bid": "0.81", "best_ask": "0.95"}, {"asset_id": "20915970858057867358422412033597169312902618738489336824716408730559800805214", "price": "0.7", "size": "0", "side": "SELL", "hash": "fe225d1c43449964f51cb32d14078da095067c63", "best_bid": "0.05", "best_ask": "0.19"}], "timestamp": "1769384636641", "event_type": "price_change"}}
{"_local_timestamp": "2026-01-25T23:43:56.907004+00:00", "data": {"market": "0x2df8bb66d0a96661ec2a4f57b0510ca7c8e154d78d6d8f3b557478ddc34fcfae", "price_changes": [{"asset_id": "104293714017628859730042534598620180600303966146090765434616358106204241123622", "price": "0.16", "size": "0", "side": "BUY", "hash": "c6569bb216207d88079c2662818dae6f4aac74f8", "best_bid": "0.39", "best_ask": "0.79"}, {"asset_id": "34218064140411222044683093812278888477247876051063075885631415084973387284228", "price": "0.84", "size": "0", "side": "SELL", "hash": "f37c79c898ef80890622fc6403c04e99abc325b8", "best_bid": "0.21", "best_ask": "0.61"}], "timestamp": "1769384636667", "event_type": "price_change"}}
{"_local_timestamp": "2026-01-25T23:43:56.907461+00:00", "data": {"market": "0x2df8bb66d0a96661ec2a4f57b0510ca7c8e154d78d6d8f3b557478ddc34fcfae", "price_changes": [{"asset_id": "104293714017628859730042534598620180600303966146090765434616358106204241123622", "price": "0.09", "size": "0", "side": "BUY", "hash": "c6569bb216207d88079c2662818dae6f4aac74f8", "best_bid": "0.39", "best_ask": "0.79"}, {"asset_id": "34218064140411222044683093812278888477247876051063075885631415084973387284228", "price": "0.91", "size": "0", "side": "SELL", "hash": "f37c79c898ef80890622fc6403c04e99abc325b8", "best_bid": "0.21", "best_ask": "0.61"}], "timestamp": "1769384636667", "event_type": "price_change"}}
{"_local_timestamp": "2026-01-25T23:43:56.907918+00:00", "data": {"market": "0x2df8bb66d0a96661ec2a4f57b0510ca7c8e154d78d6d8f3b557478ddc34fcfae", "price_changes": [{"asset_id": "104293714017628859730042534598620180600303966146090765434616358106204241123622", "price": "0.11", "size": "100", "side": "BUY", "hash": "c6569bb216207d88079c2662818dae6f4aac74f8", "best_bid": "0.39", "best_ask": "0.79"}, {"asset_id": "34218064140411222044683093812278888477247876051063075885631415084973387284228", "price": "0.89", "size": "100", "side": "SELL", "hash": "f37c79c898ef80890622fc6403c04e99abc325b8", "best_bid": "0.21", "best_ask": "0.61"}], "timestamp": "1769384636667", "event_type": "price_change"}}
{"_local_timestamp": "2026-01-25T23:43:56.908538+00:00", "data": {"market": "0x2df8bb66d0a96661ec2a4f57b0510ca7c8e154d78d6d8f3b557478ddc34fcfae", "price_changes": [{"asset_id": "104293714017628859730042534598620180600303966146090765434616358106204241123622", "price": "0.05", "size": "330", "side": "BUY", "hash": "c6569bb216207d88079c2662818dae6f4aac74f8", "best_bid": "0.39", "best_ask": "0.79"}, {"asset_id": "34218064140411222044683093812278888477247876051063075885631415084973387284228", "price": "0.95", "size": "330", "side": "SELL", "hash": "f37c79c898ef80890622fc6403c04e99abc325b8", "best_bid": "0.21", "best_ask": "0.61"}], "timestamp": "1769384636667", "event_type": "price_change"}}
{"_local_timestamp": "2026-01-25T23:43:56.909005+00:00", "data": {"market": "0x2df8bb66d0a96661ec2a4f57b0510ca7c8e154d78d6d8f3b557478ddc34fcfae", "price_changes": [{"asset_id": "104293714017628859730042534598620180600303966146090765434616358106204241123622", "price": "0.18", "size": "0", "side": "BUY", "hash": "c6569bb216207d88079c2662818dae6f4aac74f8", "best_bid": "0.39", "best_ask": "0.79"}, {"asset_id": "34218064140411222044683093812278888477247876051063075885631415084973387284228", "price": "0.82", "size": "0", "side": "SELL", "hash": "f37c79c898ef80890622fc6403c04e99abc325b8", "best_bid": "0.21", "best_ask": "0.61"}], "timestamp": "1769384636667", "event_type": "price_change"}}
{"_local_timestamp": "2026-01-25T23:43:56.909466+00:00", "data": {"market": "0x2df8bb66d0a96661ec2a4f57b0510ca7c8e154d78d6d8f3b557478ddc34fcfae", "price_changes": [{"asset_id": "104293714017628859730042534598620180600303966146090765434616358106204241123622", "price": "0.14", "size": "0", "side": "BUY", "hash": "c6569bb216207d88079c2662818dae6f4aac74f8", "best_bid": "0.39", "best_ask": "0.79"}, {"asset_id": "34218064140411222044683093812278888477247876051063075885631415084973387284228", "price": "0.86", "size": "0", "side": "SELL", "hash": "f37c79c898ef80890622fc6403c04e99abc325b8", "best_bid": "0.21", "best_ask": "0.61"}], "timestamp": "1769384636667", "event_type": "price_change"}}
{"_local_timestamp": "2026-01-25T23:43:56.909931+00:00", "data": {"market": "0x2df8bb66d0a96661ec2a4f57b0510ca7c8e154d78d6d8f3b557478ddc34fcfae", "price_changes": [{"asset_id": "104293714017628859730042534598620180600303966146090765434616358106204241123622", "price": "0.07", "size": "33.07", "side": "BUY", "hash": "c6569bb216207d88079c2662818dae6f4aac74f8", "best_bid": "0.39", "best_ask": "0.79"}, {"asset_id": "34218064140411222044683093812278888477247876051063075885631415084973387284228", "price": "0.93", "size": "33.07", "side": "SELL", "hash": "f37c79c898ef80890622fc6403c04e99abc325b8", "best_bid": "0.21", "best_ask": "0.61"}], "timestamp": "1769384636667", "event_type": "price_change"}}
{"_local_timestamp": "2026-01-25T23:43:56.910419+00:00", "data": {"market": "0x33315bd63d0cc17257c5d7524e5283639a5e17c6ce030d937f135aab02170c40", "price_changes": [{"asset_id": "92512666728361163935047824440150917945153592049030110328840756457871300635229", "price": "0.23", "size": "10", "side": "BUY", "hash": "ca3d6e2a4129173115d94e6b8ce8018ecaa8a1b2", "best_bid": "0.79", "best_ask": "0.89"}, {"asset_id": "109227307115212040009558734329420624109955456904374090651494287022030420438197", "price": "0.77", "size": "10", "side": "SELL", "hash": "f097826575befa3356bc17a5229797f755fc49b9", "best_bid": "0.11", "best_ask": "0.21"}], "timestamp": "1769384636736", "event_type": "price_change"}}
{"_local_timestamp": "2026-01-25T23:43:56.910940+00:00", "data": {"market": "0xc7e04626fbed6834456b0b9ed45e7da039ad826933e3abba81e26e71a79b2388", "price_changes": [{"asset_id": "108633032965983853701783501560325265009339710531442379830307955199797783135140", "price": "0.3", "size": "10", "side": "BUY", "hash": "0dafae52ae5215508695796d569a4c25043a8015", "best_bid": "0.81", "best_ask": "0.95"}, {"asset_id": "20915970858057867358422412033597169312902618738489336824716408730559800805214", "price": "0.7", "size": "10", "side": "SELL", "hash": "230086f912d3124bb29a10bcedf0f69b8b3b898d", "best_bid": "0.05", "best_ask": "0.19"}], "timestamp": "1769384636737", "event_type": "price_change"}}
{"_local_timestamp": "2026-01-25T23:43:56.911415+00:00", "data": {"market": "0x7f04c6bd72b53986c4e05d52ffdb3a0e8717ae809be62a1d4ec481313e86a0d0", "price_changes": [{"asset_id": "102967796728400955038420194199510769009042070489201650126144119775936757647743", "price": "0.22", "size": "10", "side": "BUY", "hash": "58837907bc31a6883242afbcdba1948fb018fea3", "best_bid": "0.85", "best_ask": "0.94"}, {"asset_id": "53325847113338736338902840435383727831746710692724054663504837250405920447353", "price": "0.78", "size": "10", "side": "SELL", "hash": "baf2a7b9087b377f901998baf4bf4bce09283acf", "best_bid": "0.06", "best_ask": "0.15"}], "timestamp": "1769384636737", "event_type": "price_change"}}
{"_local_timestamp": "2026-01-25T23:43:56.911902+00:00", "data": {"market": "0xc7e04626fbed6834456b0b9ed45e7da039ad826933e3abba81e26e71a79b2388", "price_changes": [{"asset_id": "108633032965983853701783501560325265009339710531442379830307955199797783135140", "price": "0.23", "size": "15", "side": "BUY", "hash": "1711175b9488e238e6addbe33bfb3074b4825f4b", "best_bid": "0.81", "best_ask": "0.95"}, {"asset_id": "20915970858057867358422412033597169312902618738489336824716408730559800805214", "price": "0.77", "size": "15", "side": "SELL", "hash": "8771f2c62225a0c9e3c0fdee1dd3e3edc84a87c7", "best_bid": "0.05", "best_ask": "0.19"}], "timestamp": "1769384636741", "event_type": "price_change"}}
{"_local_timestamp": "2026-01-25T23:43:56.912379+00:00", "data": {"market": "0x33315bd63d0cc17257c5d7524e5283639a5e17c6ce030d937f135aab02170c40", "price_changes": [{"asset_id": "92512666728361163935047824440150917945153592049030110328840756457871300635229", "price": "0.19", "size": "21.09", "side": "BUY", "hash": "09e17be930bd2ac6789e3d65880415d24981b984", "best_bid": "0.79", "best_ask": "0.89"}, {"asset_id": "109227307115212040009558734329420624109955456904374090651494287022030420438197", "price": "0.81", "size": "21.09", "side": "SELL", "hash": "8b4085a1cb3f072aec510375974e4fc62f2af160", "best_bid": "0.11", "best_ask": "0.21"}], "timestamp": "1769384636740", "event_type": "price_change"}}
{"_local_timestamp": "2026-01-25T23:43:56.912862+00:00", "data": {"market": "0x7f04c6bd72b53986c4e05d52ffdb3a0e8717ae809be62a1d4ec481313e86a0d0", "price_changes": [{"asset_id": "102967796728400955038420194199510769009042070489201650126144119775936757647743", "price": "0.22", "size": "25", "side": "BUY", "hash": "f9f9ce070c9d683326313017748f2b3fb70c2970", "best_bid": "0.85", "best_ask": "0.94"}, {"asset_id": "53325847113338736338902840435383727831746710692724054663504837250405920447353", "price": "0.78", "size": "25", "side": "SELL", "hash": "7d75a444dc3eadac4fa3359003fbb8b671d071a3", "best_bid": "0.06", "best_ask": "0.15"}], "timestamp": "1769384636741", "event_type": "price_change"}}
{"_local_timestamp": "2026-01-25T23:43:56.941736+00:00", "data": {"market": "0xb3c09b93dc7b394fbea2b169b54da525c5d6de9ad5caf56da920058e7b74f161", "price_changes": [{"asset_id": "39663779628084842897937886547518878184317206079104235500705380518100175496233", "price": "0.23", "size": "113.04", "side": "BUY", "hash": "76c06f9ec6a81cf6a8b4e620645843b7ddb18b7d", "best_bid": "0.75", "best_ask": "0.89"}, {"asset_id": "100335878774855355346358755214398113208570878540440188453565903904895328912285", "price": "0.77", "size": "113.04", "side": "SELL", "hash": "bb3f1a2e371de6a74e3120056e10535fcc750109", "best_bid": "0.11", "best_ask": "0.25"}], "timestamp": "1769384636809", "event_type": "price_change"}}
{"_local_timestamp": "2026-01-25T23:43:57.026643+00:00", "data": {"market": "0xb3c09b93dc7b394fbea2b169b54da525c5d6de9ad5caf56da920058e7b74f161", "price_changes": [{"asset_id": "39663779628084842897937886547518878184317206079104235500705380518100175496233", "price": "0.24", "size": "10", "side": "BUY", "hash": "8fff6981b3475648278d7b0eba2306df19e00774", "best_bid": "0.75", "best_ask": "0.89"}, {"asset_id": "100335878774855355346358755214398113208570878540440188453565903904895328912285", "price": "0.76", "size": "10", "side": "SELL", "hash": "4c45f76546169ab8937b27e63d20f3c7e0e3dcbd", "best_bid": "0.11", "best_ask": "0.25"}], "timestamp": "1769384636890", "event_type": "price_change"}}
{"_local_timestamp": "2026-01-25T23:43:57.032278+00:00", "data": {"market": "0xb3c09b93dc7b394fbea2b169b54da525c5d6de9ad5caf56da920058e7b74f161", "price_changes": [{"asset_id": "39663779628084842897937886547518878184317206079104235500705380518100175496233", "price": "0.19", "size": "262.36", "side": "BUY", "hash": "58cfacd8f0950e3ee4a0082d256d5cc5f8b61e04", "best_bid": "0.75", "best_ask": "0.89"}, {"asset_id": "100335878774855355346358755214398113208570878540440188453565903904895328912285", "price": "0.81", "size": "262.36", "side": "SELL", "hash": "748ab2468cce1cb5f57c556967f3910aa1a66288", "best_bid": "0.11", "best_ask": "0.25"}], "timestamp": "1769384636895", "event_type": "price_change"}}
{"_local_timestamp": "2026-01-25T23:43:57.409272+00:00", "data": {"market": "0xb3c09b93dc7b394fbea2b169b54da525c5d6de9ad5caf56da920058e7b74f161", "price_changes": [{"asset_id": "39663779628084842897937886547518878184317206079104235500705380518100175496233", "price": "0.51", "size": "0", "side": "BUY", "hash": "618e9b8b78f73ea1be7a58aef6f08765b3e74f99", "best_bid": "0.75", "best_ask": "0.89"}, {"asset_id": "100335878774855355346358755214398113208570878540440188453565903904895328912285", "price": "0.49", "size": "0", "side": "SELL", "hash": "93dbe461326fda42a9fb76aabb464ce9a423f0be", "best_bid": "0.11", "best_ask": "0.25"}], "timestamp": "1769384637273", "event_type": "price_change"}}
{"_local_timestamp": "2026-01-25T23:43:57.409896+00:00", "data": {"market": "0x7f04c6bd72b53986c4e05d52ffdb3a0e8717ae809be62a1d4ec481313e86a0d0", "price_changes": [{"asset_id": "102967796728400955038420194199510769009042070489201650126144119775936757647743", "price": "0.61", "size": "0", "side": "BUY", "hash": "9e0ba2fafed932b60cce65abaca888ac0d09a558", "best_bid": "0.85", "best_ask": "0.94"}, {"asset_id": "53325847113338736338902840435383727831746710692724054663504837250405920447353", "price": "0.39", "size": "0", "side": "SELL", "hash": "4379937d50e24e4b163dd0e9ec667580c9406e35", "best_bid": "0.06", "best_ask": "0.15"}], "timestamp": "1769384637273", "event_type": "price_change"}}
{"_local_timestamp": "2026-01-25T23:43:57.410520+00:00", "data": {"market": "0xc7e04626fbed6834456b0b9ed45e7da039ad826933e3abba81e26e71a79b2388", "price_changes": [{"asset_id": "108633032965983853701783501560325265009339710531442379830307955199797783135140", "price": "0.69", "size": "0", "side": "BUY", "hash": "c79ae625f766ba8f9c9d2cafecc207554189e8c3", "best_bid": "0.81", "best_ask": "0.95"}, {"asset_id": "20915970858057867358422412033597169312902618738489336824716408730559800805214", "price": "0.31", "size": "0", "side": "SELL", "hash": "495a1d6290261b49f4977cac806057776ffa5430", "best_bid": "0.05", "best_ask": "0.19"}], "timestamp": "1769384637273", "event_type": "price_change"}}
{"_local_timestamp": "2026-01-25T23:43:57.411051+00:00", "data": {"market": "0x33315bd63d0cc17257c5d7524e5283639a5e17c6ce030d937f135aab02170c40", "price_changes": [{"asset_id": "92512666728361163935047824440150917945153592049030110328840756457871300635229", "price": "0.57", "size": "5", "side": "BUY", "hash": "a10143fb687557c74f27fe2d011bc9cc0609203d", "best_bid": "0.79", "best_ask": "0.89"}, {"asset_id": "109227307115212040009558734329420624109955456904374090651494287022030420438197", "price": "0.43", "size": "5", "side": "SELL", "hash": "4e98d07783c2006b1ac8b7ad21647c83fd716030", "best_bid": "0.11", "best_ask": "0.21"}], "timestamp": "1769384637273", "event_type": "price_change"}}
{"_local_timestamp": "2026-01-25T23:43:57.442094+00:00", "data": {"market": "0xb3c09b93dc7b394fbea2b169b54da525c5d6de9ad5caf56da920058e7b74f161", "price_changes": [{"asset_id": "39663779628084842897937886547518878184317206079104235500705380518100175496233", "price": "0.34", "size": "20", "side": "BUY", "hash": "22af56d6705b8e3f579942155a9bbf57bd964dd2", "best_bid": "0.75", "best_ask": "0.89"}, {"asset_id": "100335878774855355346358755214398113208570878540440188453565903904895328912285", "price": "0.66", "size": "20", "side": "SELL", "hash": "43f0e222e33cf61152c697a46d4193b5f37fb934", "best_bid": "0.11", "best_ask": "0.25"}], "timestamp": "1769384637306", "event_type": "price_change"}}
{"_local_timestamp": "2026-01-25T23:43:57.442744+00:00", "data": {"market": "0x7f04c6bd72b53986c4e05d52ffdb3a0e8717ae809be62a1d4ec481313e86a0d0", "price_changes": [{"asset_id": "102967796728400955038420194199510769009042070489201650126144119775936757647743", "price": "0.38", "size": "25", "side": "BUY", "hash": "b5fa8c7acf23346328782c33174865098d794c04", "best_bid": "0.85", "best_ask": "0.94"}, {"asset_id": "53325847113338736338902840435383727831746710692724054663504837250405920447353", "price": "0.62", "size": "25", "side": "SELL", "hash": "ffefd6c788187d0d98b30a94e4116a5eedefc665", "best_bid": "0.06", "best_ask": "0.15"}], "timestamp": "1769384637307", "event_type": "price_change"}}
{"_local_timestamp": "2026-01-25T23:43:57.443278+00:00", "data": {"market": "0xc7e04626fbed6834456b0b9ed45e7da039ad826933e3abba81e26e71a79b2388", "price_changes": [{"asset_id": "108633032965983853701783501560325265009339710531442379830307955199797783135140", "price": "0.42", "size": "20", "side": "BUY", "hash": "94d05c11a796973b7eb9ac284ab9a9a4d7b55dc7", "best_bid": "0.81", "best_ask": "0.95"}, {"asset_id": "20915970858057867358422412033597169312902618738489336824716408730559800805214", "price": "0.58", "size": "20", "side": "SELL", "hash": "f0cc1a98da22bae1e3bfbcb99b9e348929a100b6", "best_bid": "0.05", "best_ask": "0.19"}], "timestamp": "1769384637306", "event_type": "price_change"}}
{"_local_timestamp": "2026-01-25T23:43:57.443796+00:00", "data": {"market": "0x33315bd63d0cc17257c5d7524e5283639a5e17c6ce030d937f135aab02170c40", "price_changes": [{"asset_id": "92512666728361163935047824440150917945153592049030110328840756457871300635229", "price": "0.37", "size": "70", "side": "BUY", "hash": "8f0e939998f40f7c393ba0fe3133b9cf3ab391a1", "best_bid": "0.79", "best_ask": "0.89"}, {"asset_id": "109227307115212040009558734329420624109955456904374090651494287022030420438197", "price": "0.63", "size": "70", "side": "SELL", "hash": "2250e1ec7de11f1a19fd8a82653962e8b1c0fd20", "best_bid": "0.11", "best_ask": "0.21"}], "timestamp": "1769384637308", "event_type": "price_change"}}
{"_local_timestamp": "2026-01-25T23:43:57.799705+00:00", "data": {"market": "0x2df8bb66d0a96661ec2a4f57b0510ca7c8e154d78d6d8f3b557478ddc34fcfae", "price_changes": [{"asset_id": "104293714017628859730042534598620180600303966146090765434616358106204241123622", "price": "0.27", "size": "110", "side": "BUY", "hash": "36104dfea42412a779822394f09ac2f5dd4ac226", "best_bid": "0.39", "best_ask": "0.79"}, {"asset_id": "34218064140411222044683093812278888477247876051063075885631415084973387284228", "price": "0.73", "size": "110", "side": "SELL", "hash": "8fdbd31e9cf7e3090c9db32a7db93684993f88f2", "best_bid": "0.21", "best_ask": "0.61"}], "timestamp": "1769384637680", "event_type": "price_change"}}
{"_local_timestamp": "2026-01-25T23:43:57.882443+00:00", "data": {"market": "0xb3c09b93dc7b394fbea2b169b54da525c5d6de9ad5caf56da920058e7b74f161", "price_changes": [{"asset_id": "39663779628084842897937886547518878184317206079104235500705380518100175496233", "price": "0.19", "size": "323.96", "side": "BUY", "hash": "830109c8c6346b2de4d0eae4231568f67b5372aa", "best_bid": "0.75", "best_ask": "0.89"}, {"asset_id": "100335878774855355346358755214398113208570878540440188453565903904895328912285", "price": "0.81", "size": "323.96", "side": "SELL", "hash": "e8059a2dc0eab770e5e69cb7c5140b50886efb7f", "best_bid": "0.11", "best_ask": "0.25"}], "timestamp": "1769384637764", "event_type": "price_change"}}
{"_local_timestamp": "2026-01-25T23:43:57.883047+00:00", "data": {"market": "0x2df8bb66d0a96661ec2a4f57b0510ca7c8e154d78d6d8f3b557478ddc34fcfae", "price_changes": [{"asset_id": "104293714017628859730042534598620180600303966146090765434616358106204241123622", "price": "0.15", "size": "100", "side": "BUY", "hash": "e728db6c2febb24c37ed09fdb6c9bf3e3ca07ad0", "best_bid": "0.39", "best_ask": "0.79"}, {"asset_id": "34218064140411222044683093812278888477247876051063075885631415084973387284228", "price": "0.85", "size": "100", "side": "SELL", "hash": "633d7f11140d9d98deb86aed08d6739153462601", "best_bid": "0.21", "best_ask": "0.61"}], "timestamp": "1769384637769", "event_type": "price_change"}}
{"_local_timestamp": "2026-01-25T23:43:57.893537+00:00", "data": {"market": "0x2df8bb66d0a96661ec2a4f57b0510ca7c8e154d78d6d8f3b557478ddc34fcfae", "price_changes": [{"asset_id": "34218064140411222044683093812278888477247876051063075885631415084973387284228", "price": "0.15", "size": "50", "side": "BUY", "hash": "1818b606f3636cbe7a3ae95d637f9a2b37b75d93", "best_bid": "0.21", "best_ask": "0.61"}, {"asset_id": "104293714017628859730042534598620180600303966146090765434616358106204241123622", "price": "0.85", "size": "50", "side": "SELL", "hash": "12189db066efd33f579621740726afd54ccc5db5", "best_bid": "0.39", "best_ask": "0.79"}], "timestamp": "1769384637771", "event_type": "price_change"}}
{"_local_timestamp": "2026-01-25T23:43:57.894132+00:00", "data": {"market": "0x2df8bb66d0a96661ec2a4f57b0510ca7c8e154d78d6d8f3b557478ddc34fcfae", "price_changes": [{"asset_id": "34218064140411222044683093812278888477247876051063075885631415084973387284228", "price": "0.23", "size": "50", "side": "BUY", "hash": "b10e4745d20e2417c5f2a733c3e5b3424449e39a", "best_bid": "0.23", "best_ask": "0.61"}, {"asset_id": "104293714017628859730042534598620180600303966146090765434616358106204241123622", "price": "0.77", "size": "50", "side": "SELL", "hash": "02602083f5710a134c7998951aa6938506c4b78c", "best_bid": "0.39", "best_ask": "0.77"}], "timestamp": "1769384637772", "event_type": "price_change"}}
{"_local_timestamp": "2026-01-25T23:43:57.894674+00:00", "data": {"market": "0x33315bd63d0cc17257c5d7524e5283639a5e17c6ce030d937f135aab02170c40", "price_changes": [{"asset_id": "92512666728361163935047824440150917945153592049030110328840756457871300635229", "price": "0.32", "size": "200", "side": "BUY", "hash": "294400fd4deb8ecb43757a9682750ccf81411060", "best_bid": "0.79", "best_ask": "0.89"}, {"asset_id": "109227307115212040009558734329420624109955456904374090651494287022030420438197", "price": "0.68", "size": "200", "side": "SELL", "hash": "ec7e07de75d8b094a86cc487c8ec25b332e1e26a", "best_bid": "0.11", "best_ask": "0.21"}], "timestamp": "1769384637773", "event_type": "price_change"}}
{"_local_timestamp": "2026-01-25T23:43:57.895237+00:00", "data": {"market": "0xb3c09b93dc7b394fbea2b169b54da525c5d6de9ad5caf56da920058e7b74f161", "price_changes": [{"asset_id": "39663779628084842897937886547518878184317206079104235500705380518100175496233", "price": "0.48", "size": "61.6", "side": "BUY", "hash": "cd0673a1a0303ae20d7e3590f7036e29972097cc", "best_bid": "0.75", "best_ask": "0.89"}, {"asset_id": "100335878774855355346358755214398113208570878540440188453565903904895328912285", "price": "0.52", "size": "61.6", "side": "SELL", "hash": "18c977a1121ea477b385e15eba7c3a8d5c11a30c", "best_bid": "0.11", "best_ask": "0.25"}], "timestamp": "1769384637775", "event_type": "price_change"}}
{"_local_timestamp": "2026-01-25T23:43:57.951439+00:00", "data": {"market": "0x2df8bb66d0a96661ec2a4f57b0510ca7c8e154d78d6d8f3b557478ddc34fcfae", "price_changes": [{"asset_id": "104293714017628859730042534598620180600303966146090765434616358106204241123622", "price": "0.25", "size": "0", "side": "BUY", "hash": "b9f33a17fd98a6f7d95f836071d1f69b19cfcbbe", "best_bid": "0.39", "best_ask": "0.77"}, {"asset_id": "34218064140411222044683093812278888477247876051063075885631415084973387284228", "price": "0.75", "size": "0", "side": "SELL", "hash": "4d297ab808986e8153861d25c2925127a3b0ff8e", "best_bid": "0.23", "best_ask": "0.61"}], "timestamp": "1769384637830", "event_type": "price_change"}}
{"_local_timestamp": "2026-01-25T23:43:57.952038+00:00", "data": {"market": "0x2df8bb66d0a96661ec2a4f57b0510ca7c8e154d78d6d8f3b557478ddc34fcfae", "price_changes": [{"asset_id": "104293714017628859730042534598620180600303966146090765434616358106204241123622", "price": "0.22", "size": "0", "side": "BUY", "hash": "b9f33a17fd98a6f7d95f836071d1f69b19cfcbbe", "best_bid": "0.39", "best_ask": "0.77"}, {"asset_id": "34218064140411222044683093812278888477247876051063075885631415084973387284228", "price": "0.78", "size": "0", "side": "SELL", "hash": "4d297ab808986e8153861d25c2925127a3b0ff8e", "best_bid": "0.23", "best_ask": "0.61"}], "timestamp": "1769384637830", "event_type": "price_change"}}
{"_local_timestamp": "2026-01-25T23:43:58.049817+00:00", "data": {"market": "0x2df8bb66d0a96661ec2a4f57b0510ca7c8e154d78d6d8f3b557478ddc34fcfae", "price_changes": [{"asset_id": "104293714017628859730042534598620180600303966146090765434616358106204241123622", "price": "0.22", "size": "10", "side": "BUY", "hash": "20913bc1fd05dabf1425b791a97a9edeb4e21baa", "best_bid": "0.39", "best_ask": "0.77"}, {"asset_id": "34218064140411222044683093812278888477247876051063075885631415084973387284228", "price": "0.78", "size": "10", "side": "SELL", "hash": "d72c32f66b60face1cc364d00fb7f1b92e378d64", "best_bid": "0.23", "best_ask": "0.61"}], "timestamp": "1769384637932", "event_type": "price_change"}}
{"_local_timestamp": "2026-01-25T23:43:58.050450+00:00", "data": {"market": "0x2df8bb66d0a96661ec2a4f57b0510ca7c8e154d78d6d8f3b557478ddc34fcfae", "price_changes": [{"asset_id": "104293714017628859730042534598620180600303966146090765434616358106204241123622", "price": "0.22", "size": "25", "side": "BUY", "hash": "2075075884e03673a574da1159842238dea401ed", "best_bid": "0.39", "best_ask": "0.77"}, {"asset_id": "34218064140411222044683093812278888477247876051063075885631415084973387284228", "price": "0.78", "size": "25", "side": "SELL", "hash": "d284bf70342c4e9ff89ed1776f8ffb9252ada750", "best_bid": "0.23", "best_ask": "0.61"}], "timestamp": "1769384637933", "event_type": "price_change"}}
{"_local_timestamp": "2026-01-25T23:43:58.193143+00:00", "data": {"market": "0x2df8bb66d0a96661ec2a4f57b0510ca7c8e154d78d6d8f3b557478ddc34fcfae", "price_changes": [{"asset_id": "104293714017628859730042534598620180600303966146090765434616358106204241123622", "price": "0.39", "size": "0", "side": "BUY", "hash": "ce6a561e6a60a35da056de4bf3386509947599bb", "best_bid": "0.32", "best_ask": "0.77"}, {"asset_id": "34218064140411222044683093812278888477247876051063075885631415084973387284228", "price": "0.61", "size": "0", "side": "SELL", "hash": "b90f41f388226528e06484a2e9eeaaec27cfcb0b", "best_bid": "0.23", "best_ask": "0.68"}], "timestamp": "1769384638074", "event_type": "price_change"}}
{"_local_timestamp": "2026-01-25T23:43:58.229861+00:00", "data": {"market": "0x2df8bb66d0a96661ec2a4f57b0510ca7c8e154d78d6d8f3b557478ddc34fcfae", "price_changes": [{"asset_id": "104293714017628859730042534598620180600303966146090765434616358106204241123622", "price": "0.31", "size": "8.5", "side": "BUY", "hash": "05a4d8f7e965fd72d38906f3172d1f1db72114db", "best_bid": "0.32", "best_ask": "0.77"}, {"asset_id": "34218064140411222044683093812278888477247876051063075885631415084973387284228", "price": "0.69", "size": "8.5", "side": "SELL", "hash": "5340adb68908f5ce5e5cb2d28c278480e479bbf2", "best_bid": "0.23", "best_ask": "0.68"}], "timestamp": "1769384638113", "event_type": "price_change"}}
{"_local_timestamp": "2026-01-25T23:43:58.536046+00:00", "data": {"market": "0x2df8bb66d0a96661ec2a4f57b0510ca7c8e154d78d6d8f3b557478ddc34fcfae", "price_changes": [{"asset_id": "104293714017628859730042534598620180600303966146090765434616358106204241123622", "price": "0.27", "size": "140", "side": "BUY", "hash": "5ebf852778e0c39ed3a4a916dcc1ad2f24c47cf6", "best_bid": "0.32", "best_ask": "0.77"}, {"asset_id": "34218064140411222044683093812278888477247876051063075885631415084973387284228", "price": "0.73", "size": "140", "side": "SELL", "hash": "55d6821683e91c80395a63c49b055cac18c39f55", "best_bid": "0.23", "best_ask": "0.68"}], "timestamp": "1769384638415", "event_type": "price_change"}}
{"_local_timestamp": "2026-01-25T23:43:59.082475+00:00", "data": {"market": "0x33315bd63d0cc17257c5d7524e5283639a5e17c6ce030d937f135aab02170c40", "price_changes": [{"asset_id": "92512666728361163935047824440150917945153592049030110328840756457871300635229", "price": "0.37", "size": "50", "side": "BUY", "hash": "cacc3c9ee897bff5ebd9dce44f7bb35e2413e844", "best_bid": "0.79", "best_ask": "0.89"}, {"asset_id": "109227307115212040009558734329420624109955456904374090651494287022030420438197", "price": "0.63", "size": "50", "side": "SELL", "hash": "2642c676885792e1a815cb2616525af4d8cf0e36", "best_bid": "0.11", "best_ask": "0.21"}], "timestamp": "1769384638966", "event_type": "price_change"}}
{"_local_timestamp": "2026-01-25T23:43:59.083194+00:00", "data": {"market": "0xc7e04626fbed6834456b0b9ed45e7da039ad826933e3abba81e26e71a79b2388", "price_changes": [{"asset_id": "108633032965983853701783501560325265009339710531442379830307955199797783135140", "price": "0.42", "size": "0", "side": "BUY", "hash": "19e5ad51358386a3b37313f48aab3d43dae1c88c", "best_bid": "0.81", "best_ask": "0.95"}, {"asset_id": "20915970858057867358422412033597169312902618738489336824716408730559800805214", "price": "0.58", "size": "0", "side": "SELL", "hash": "6c939dc1c8c8a9a4c4c7b72d18a7254925ca7e73", "best_bid": "0.05", "best_ask": "0.19"}], "timestamp": "1769384638966", "event_type": "price_change"}}
{"_local_timestamp": "2026-01-25T23:43:59.114437+00:00", "data": {"market": "0x33315bd63d0cc17257c5d7524e5283639a5e17c6ce030d937f135aab02170c40", "price_changes": [{"asset_id": "92512666728361163935047824440150917945153592049030110328840756457871300635229", "price": "0.38", "size": "20", "side": "BUY", "hash": "ec379399a088e5653f7ab91f77c36f0b15e2ab02", "best_bid": "0.79", "best_ask": "0.89"}, {"asset_id": "109227307115212040009558734329420624109955456904374090651494287022030420438197", "price": "0.62", "size": "20", "side": "SELL", "hash": "40d93ae0762f5a17539bb54a32d384f14df11fcd", "best_bid": "0.11", "best_ask": "0.21"}], "timestamp": "1769384638993", "event_type": "price_change"}}
{"_local_timestamp": "2026-01-25T23:43:59.115159+00:00", "data": {"market": "0xc7e04626fbed6834456b0b9ed45e7da039ad826933e3abba81e26e71a79b2388", "price_changes": [{"asset_id": "108633032965983853701783501560325265009339710531442379830307955199797783135140", "price": "0.46", "size": "20", "side": "BUY", "hash": "92d99677bf10af1200a104b81de81266adb23497", "best_bid": "0.81", "best_ask": "0.95"}, {"asset_id": "20915970858057867358422412033597169312902618738489336824716408730559800805214", "price": "0.54", "size": "20", "side": "SELL", "hash": "dc20cfe0c43b6e809e9340cee2134242f4c068eb", "best_bid": "0.05", "best_ask": "0.19"}], "timestamp": "1769384638993", "event_type": "price_change"}}
{"_local_timestamp": "2026-01-25T23:44:03.564726+00:00", "data": {"market": "0x2df8bb66d0a96661ec2a4f57b0510ca7c8e154d78d6d8f3b557478ddc34fcfae", "price_changes": [{"asset_id": "34218064140411222044683093812278888477247876051063075885631415084973387284228", "price": "0.06", "size": "200", "side": "BUY", "hash": "ab67fa79ce71a8d2fcac748a70f3f001d7c7cfcb", "best_bid": "0.23", "best_ask": "0.68"}, {"asset_id": "104293714017628859730042534598620180600303966146090765434616358106204241123622", "price": "0.94", "size": "200", "side": "SELL", "hash": "85387c56941bbd59eefdb93d1cbc420ea7083100", "best_bid": "0.32", "best_ask": "0.77"}], "timestamp": "1769384643413", "event_type": "price_change"}}
{"_local_timestamp": "2026-01-25T23:44:06.362104+00:00", "data": {"market": "0x2df8bb66d0a96661ec2a4f57b0510ca7c8e154d78d6d8f3b557478ddc34fcfae", "price_changes": [{"asset_id": "34218064140411222044683093812278888477247876051063075885631415084973387284228", "price": "0.21", "size": "0", "side": "BUY", "hash": "9d0c8a80e09597d0856254fea621877203015ebb", "best_bid": "0.23", "best_ask": "0.68"}, {"asset_id": "104293714017628859730042534598620180600303966146090765434616358106204241123622", "price": "0.79", "size": "0", "side": "SELL", "hash": "e0e87c38cab53c040be448c3b7d128416fed703e", "best_bid": "0.32", "best_ask": "0.77"}], "timestamp": "1769384646234", "event_type": "price_change"}}
{"_local_timestamp": "2026-01-25T23:44:06.362784+00:00", "data": {"market": "0x2df8bb66d0a96661ec2a4f57b0510ca7c8e154d78d6d8f3b557478ddc34fcfae", "price_changes": [{"asset_id": "104293714017628859730042534598620180600303966146090765434616358106204241123622", "price": "0.31", "size": "0", "side": "BUY", "hash": "65ed6c76bc0518cd5d6ef5fe436be52ec57b7d93", "best_bid": "0.32", "best_ask": "0.77"}, {"asset_id": "34218064140411222044683093812278888477247876051063075885631415084973387284228", "price": "0.69", "size": "0", "side": "SELL", "hash": "063827302a197080b08f20c34b73d4bfd8e19b93", "best_bid": "0.23", "best_ask": "0.68"}], "timestamp": "1769384646234", "event_type": "price_change"}}
{"_local_timestamp": "2026-01-25T23:44:08.393827+00:00", "data": {"market": "0xb3c09b93dc7b394fbea2b169b54da525c5d6de9ad5caf56da920058e7b74f161", "price_changes": [{"asset_id": "100335878774855355346358755214398113208570878540440188453565903904895328912285", "price": "0.11", "size": "116.66", "side": "BUY", "hash": "6725f8926fbe875f217a0dc10dc64865b39ee4ec", "best_bid": "0.11", "best_ask": "0.25"}, {"asset_id": "39663779628084842897937886547518878184317206079104235500705380518100175496233", "price": "0.89", "size": "116.66", "side": "SELL", "hash": "f787272d9935db8a8d362781b50803011d03407b", "best_bid": "0.75", "best_ask": "0.89"}], "timestamp": "1769384648162", "event_type": "price_change"}}
{"_local_timestamp": "2026-01-25T23:44:08.396967+00:00", "data": {"market": "0x2df8bb66d0a96661ec2a4f57b0510ca7c8e154d78d6d8f3b557478ddc34fcfae", "price_changes": [{"asset_id": "34218064140411222044683093812278888477247876051063075885631415084973387284228", "price": "0.47", "size": "50", "side": "BUY", "hash": "739b1818942a16480919e040941f8ed5b84d24ca", "best_bid": "0.47", "best_ask": "0.68"}, {"asset_id": "104293714017628859730042534598620180600303966146090765434616358106204241123622", "price": "0.53", "size": "50", "side": "SELL", "hash": "c0c04ae30d0c3a4c44f1e1dd5430dd90c0993c13", "best_bid": "0.32", "best_ask": "0.53"}], "timestamp": "1769384648162", "event_type": "price_change"}}
{"_local_timestamp": "2026-01-25T23:44:08.482549+00:00", "data": {"market": "0xb3c09b93dc7b394fbea2b169b54da525c5d6de9ad5caf56da920058e7b74f161", "price_changes": [{"asset_id": "39663779628084842897937886547518878184317206079104235500705380518100175496233", "price": "0.68", "size": "20", "side": "BUY", "hash": "32752de54e6f53194a21c098d27c881f4d587bed", "best_bid": "0.75", "best_ask": "0.89"}, {"asset_id": "100335878774855355346358755214398113208570878540440188453565903904895328912285", "price": "0.32", "size": "20", "side": "SELL", "hash": "b16021545f150f65d497ff9b908b6f80e64a193f", "best_bid": "0.11", "best_ask": "0.25"}], "timestamp": "1769384648276", "event_type": "price_change"}}
{"_local_timestamp": "2026-01-25T23:44:08.496592+00:00", "data": {"market": "0x33315bd63d0cc17257c5d7524e5283639a5e17c6ce030d937f135aab02170c40", "price_changes": [{"asset_id": "92512666728361163935047824440150917945153592049030110328840756457871300635229", "price": "0.39", "size": "10", "side": "BUY", "hash": "3c4ef3167d577e09d9b58083d90fe2891ee7e804", "best_bid": "0.79", "best_ask": "0.89"}, {"asset_id": "109227307115212040009558734329420624109955456904374090651494287022030420438197", "price": "0.61", "size": "10", "side": "SELL", "hash": "432623475d5c87b1224bd13edbf5858eee91dfe4", "best_bid": "0.11", "best_ask": "0.21"}], "timestamp": "1769384648310", "event_type": "price_change"}}
{"_local_timestamp": "2026-01-25T23:44:09.034059+00:00", "data": {"market": "0x2df8bb66d0a96661ec2a4f57b0510ca7c8e154d78d6d8f3b557478ddc34fcfae", "price_changes": [{"asset_id": "104293714017628859730042534598620180600303966146090765434616358106204241123622", "price": "0.11", "size": "225", "side": "BUY", "hash": "c2da0c9657dca738dabc27e2ed76e0b8952b61b8", "best_bid": "0.32", "best_ask": "0.53"}, {"asset_id": "34218064140411222044683093812278888477247876051063075885631415084973387284228", "price": "0.89", "size": "225", "side": "SELL", "hash": "0d37d05cee3d2cc1f2e10ecec665484009ac0ce6", "best_bid": "0.47", "best_ask": "0.68"}], "timestamp": "1769384648742", "event_type": "price_change"}}
{"_local_timestamp": "2026-01-25T23:44:09.505751+00:00", "data": {"market": "0x33315bd63d0cc17257c5d7524e5283639a5e17c6ce030d937f135aab02170c40", "price_changes": [{"asset_id": "92512666728361163935047824440150917945153592049030110328840756457871300635229", "price": "0.38", "size": "0", "side": "BUY", "hash": "a9563e772ba8d5ce5da02e1c86cb93878cd19a7a", "best_bid": "0.79", "best_ask": "0.89"}, {"asset_id": "109227307115212040009558734329420624109955456904374090651494287022030420438197", "price": "0.62", "size": "0", "side": "SELL", "hash": "70eb27d6571908cd9938555f1d73f294cd1d568e", "best_bid": "0.11", "best_ask": "0.21"}], "timestamp": "1769384649356", "event_type": "price_change"}}
{"_local_timestamp": "2026-01-25T23:44:09.506447+00:00", "data": {"market": "0x7f04c6bd72b53986c4e05d52ffdb3a0e8717ae809be62a1d4ec481313e86a0d0", "price_changes": [{"asset_id": "102967796728400955038420194199510769009042070489201650126144119775936757647743", "price": "0.38", "size": "5", "side": "BUY", "hash": "805d765e033bb62aee45eddf8a4d33cc6b84e780", "best_bid": "0.85", "best_ask": "0.94"}, {"asset_id": "53325847113338736338902840435383727831746710692724054663504837250405920447353", "price": "0.62", "size": "5", "side": "SELL", "hash": "25d895b67d6f97e18813ec3deaaea69a14e84654", "best_bid": "0.06", "best_ask": "0.15"}], "timestamp": "1769384649356", "event_type": "price_change"}}
{"_local_timestamp": "2026-01-25T23:44:09.507033+00:00", "data": {"market": "0xb3c09b93dc7b394fbea2b169b54da525c5d6de9ad5caf56da920058e7b74f161", "price_changes": [{"asset_id": "39663779628084842897937886547518878184317206079104235500705380518100175496233", "price": "0.34", "size": "0", "side": "BUY", "hash": "8e479dcc4c129185ac50e6a9e4e9f209de540957", "best_bid": "0.75", "best_ask": "0.89"}, {"asset_id": "100335878774855355346358755214398113208570878540440188453565903904895328912285", "price": "0.66", "size": "0", "side": "SELL", "hash": "985d55ead6329a9601f6943db656c2db4c5d0f16", "best_bid": "0.11", "best_ask": "0.25"}], "timestamp": "1769384649356", "event_type": "price_change"}}
{"_local_timestamp": "2026-01-25T23:44:09.507607+00:00", "data": {"market": "0xc7e04626fbed6834456b0b9ed45e7da039ad826933e3abba81e26e71a79b2388", "price_changes": [{"asset_id": "108633032965983853701783501560325265009339710531442379830307955199797783135140", "price": "0.46", "size": "0", "side": "BUY", "hash": "9e038b532591ef565cf3df11e70579b85c45d87a", "best_bid": "0.81", "best_ask": "0.95"}, {"asset_id": "20915970858057867358422412033597169312902618738489336824716408730559800805214", "price": "0.54", "size": "0", "side": "SELL", "hash": "f15eb204e3d91b2282769dc96ec05f7de7c4d957", "best_bid": "0.05", "best_ask": "0.19"}], "timestamp": "1769384649356", "event_type": "price_change"}}
{"_local_timestamp": "2026-01-25T23:44:09.532048+00:00", "data": {"market": "0x33315bd63d0cc17257c5d7524e5283639a5e17c6ce030d937f135aab02170c40", "price_changes": [{"asset_id": "92512666728361163935047824440150917945153592049030110328840756457871300635229", "price": "0.4", "size": "20", "side": "BUY", "hash": "452f06ee36b4801e15764ffde74fcc1f752e81f0", "best_bid": "0.79", "best_ask": "0.89"}, {"asset_id": "109227307115212040009558734329420624109955456904374090651494287022030420438197", "price": "0.6", "size": "20", "side": "SELL", "hash": "387336cdaecf907a023f75fd445c564d790a7117", "best_bid": "0.11", "best_ask": "0.21"}], "timestamp": "1769384649397", "event_type": "price_change"}}
{"_local_timestamp": "2026-01-25T23:44:09.532658+00:00", "data": {"market": "0xb3c09b93dc7b394fbea2b169b54da525c5d6de9ad5caf56da920058e7b74f161", "price_changes": [{"asset_id": "39663779628084842897937886547518878184317206079104235500705380518100175496233", "price": "0.49", "size": "20", "side": "BUY", "hash": "2839a1620436fb71825eaf2feb5a463c9109a1e2", "best_bid": "0.75", "best_ask": "0.89"}, {"asset_id": "100335878774855355346358755214398113208570878540440188453565903904895328912285", "price": "0.51", "size": "20", "side": "SELL", "hash": "ea406980bf253e7e05fc1657db177e7f0772fef7", "best_bid": "0.11", "best_ask": "0.25"}], "timestamp": "1769384649397", "event_type": "price_change"}}
{"_local_timestamp": "2026-01-25T23:44:09.533230+00:00", "data": {"market": "0xc7e04626fbed6834456b0b9ed45e7da039ad826933e3abba81e26e71a79b2388", "price_changes": [{"asset_id": "108633032965983853701783501560325265009339710531442379830307955199797783135140", "price": "0.69", "size": "20", "side": "BUY", "hash": "ed8c27af6279575c126a13d240373507ac8a1aa7", "best_bid": "0.81", "best_ask": "0.95"}, {"asset_id": "20915970858057867358422412033597169312902618738489336824716408730559800805214", "price": "0.31", "size": "20", "side": "SELL", "hash": "3053363ee9471044e2079a9f935651a3395fba36", "best_bid": "0.05", "best_ask": "0.19"}], "timestamp": "1769384649397", "event_type": "price_change"}}
{"_local_timestamp": "2026-01-25T23:44:09.533818+00:00", "data": {"market": "0x7f04c6bd72b53986c4e05d52ffdb3a0e8717ae809be62a1d4ec481313e86a0d0", "price_changes": [{"asset_id": "102967796728400955038420194199510769009042070489201650126144119775936757647743", "price": "0.61", "size": "20", "side": "BUY", "hash": "9e261f44dd44eb14fd064cf04b58db19ce293ae2", "best_bid": "0.85", "best_ask": "0.94"}, {"asset_id": "53325847113338736338902840435383727831746710692724054663504837250405920447353", "price": "0.39", "size": "20", "side": "SELL", "hash": "18b833ab7b1e5dd26937e22dd35869aadd3bf14b", "best_bid": "0.06", "best_ask": "0.15"}], "timestamp": "1769384649397", "event_type": "price_change"}}
{"_local_timestamp": "2026-01-25T23:44:13.519790+00:00", "data": {"market": "0x33315bd63d0cc17257c5d7524e5283639a5e17c6ce030d937f135aab02170c40", "price_changes": [{"asset_id": "92512666728361163935047824440150917945153592049030110328840756457871300635229", "price": "0.68", "size": "20", "side": "BUY", "hash": "5038ab5b2e11a6fec5dae72b9d56130ba30af2e2", "best_bid": "0.79", "best_ask": "0.89"}, {"asset_id": "109227307115212040009558734329420624109955456904374090651494287022030420438197", "price": "0.32", "size": "20", "side": "SELL", "hash": "915a86a4df34d889e24e00ad462f654f4efc8ba3", "best_bid": "0.11", "best_ask": "0.21"}], "timestamp": "1769384653380", "event_type": "price_change"}}
{"_local_timestamp": "2026-01-25T23:44:18.451017+00:00", "data": {"market": "0x7f04c6bd72b53986c4e05d52ffdb3a0e8717ae809be62a1d4ec481313e86a0d0", "price_changes": [{"asset_id": "102967796728400955038420194199510769009042070489201650126144119775936757647743", "price": "0.73", "size": "170", "side": "BUY", "hash": "f754e6f0652a0c20e85e4c34f0013d9d07ea7c1f", "best_bid": "0.85", "best_ask": "0.94"}, {"asset_id": "53325847113338736338902840435383727831746710692724054663504837250405920447353", "price": "0.27", "size": "170", "side": "SELL", "hash": "3ec26d010b0728af6661bded9ae8c2c986947272", "best_bid": "0.06", "best_ask": "0.15"}], "timestamp": "1769384658383", "event_type": "price_change"}}
{"_local_timestamp": "2026-01-25T23:44:21.256999+00:00", "data": {"market": "0x2df8bb66d0a96661ec2a4f57b0510ca7c8e154d78d6d8f3b557478ddc34fcfae", "price_changes": [{"asset_id": "34218064140411222044683093812278888477247876051063075885631415084973387284228", "price": "0.22", "size": "100", "side": "BUY", "hash": "712999fc784f6c02190aa2dee747d1bf65518b12", "best_bid": "0.47", "best_ask": "0.68"}, {"asset_id": "104293714017628859730042534598620180600303966146090765434616358106204241123622", "price": "0.78", "size": "100", "side": "SELL", "hash": "a06717b05a944ba3aff74ceaa5aab21ea1278ef9", "best_bid": "0.32", "best_ask": "0.53"}], "timestamp": "1769384660833", "event_type": "price_change"}}
{"_local_timestamp": "2026-01-25T23:44:21.277280+00:00", "data": {"market": "0x7f04c6bd72b53986c4e05d52ffdb3a0e8717ae809be62a1d4ec481313e86a0d0", "price_changes": [{"asset_id": "102967796728400955038420194199510769009042070489201650126144119775936757647743", "price": "0.37", "size": "125", "side": "BUY", "hash": "31ba2d7dfe0be02e3d5d64a6c4309205fffc3531", "best_bid": "0.85", "best_ask": "0.94"}, {"asset_id": "53325847113338736338902840435383727831746710692724054663504837250405920447353", "price": "0.63", "size": "125", "side": "SELL", "hash": "cdc08149a903c884eda14b3cb59a730741fcf32f", "best_bid": "0.06", "best_ask": "0.15"}], "timestamp": "1769384660832", "event_type": "price_change"}}
{"_local_timestamp": "2026-01-25T23:44:21.316007+00:00", "data": {"market": "0xc7e04626fbed6834456b0b9ed45e7da039ad826933e3abba81e26e71a79b2388", "price_changes": [{"asset_id": "108633032965983853701783501560325265009339710531442379830307955199797783135140", "price": "0.21", "size": "283.33", "side": "BUY", "hash": "b960a9533466ece27f9e4c5bd3b4f9999b33defd", "best_bid": "0.81", "best_ask": "0.95"}, {"asset_id": "20915970858057867358422412033597169312902618738489336824716408730559800805214", "price": "0.79", "size": "283.33", "side": "SELL", "hash": "3a105243338602701146165f4b2cd0ac760dd757", "best_bid": "0.05", "best_ask": "0.19"}], "timestamp": "1769384660843", "event_type": "price_change"}}
{"_local_timestamp": "2026-01-25T23:44:21.503327+00:00", "data": {"market": "0xb3c09b93dc7b394fbea2b169b54da525c5d6de9ad5caf56da920058e7b74f161", "price_changes": [{"asset_id": "39663779628084842897937886547518878184317206079104235500705380518100175496233", "price": "0.23", "size": "213.04", "side": "BUY", "hash": "e35f3b1995d43b9df35059cd8df93e020edc2b52", "best_bid": "0.75", "best_ask": "0.89"}, {"asset_id": "100335878774855355346358755214398113208570878540440188453565903904895328912285", "price": "0.77", "size": "213.04", "side": "SELL", "hash": "01d561d67e0d588729cc20593ace9864b26301f6", "best_bid": "0.11", "best_ask": "0.25"}], "timestamp": "1769384660923", "event_type": "price_change"}}
{"_local_timestamp": "2026-01-25T23:44:21.515449+00:00", "data": {"market": "0x33315bd63d0cc17257c5d7524e5283639a5e17c6ce030d937f135aab02170c40", "price_changes": [{"asset_id": "92512666728361163935047824440150917945153592049030110328840756457871300635229", "price": "0.13", "size": "586.53", "side": "BUY", "hash": "59bda4670ce020209f31b8c65f56474b6cf8f270", "best_bid": "0.79", "best_ask": "0.89"}, {"asset_id": "109227307115212040009558734329420624109955456904374090651494287022030420438197", "price": "0.87", "size": "586.53", "side": "SELL", "hash": "859ab2dec301bf5ae4ba99c8b7c8b8cce9c30f0d", "best_bid": "0.11", "best_ask": "0.21"}], "timestamp": "1769384660914", "event_type": "price_change"}}
{"_local_timestamp": "2026-01-25T23:44:21.537796+00:00", "data": {"market": "0x33315bd63d0cc17257c5d7524e5283639a5e17c6ce030d937f135aab02170c40", "price_changes": [{"asset_id": "92512666728361163935047824440150917945153592049030110328840756457871300635229", "price": "0.22", "size": "227.27", "side": "BUY", "hash": "22ea3e99b8ceaf5dfe9b940271de6e4ca1fa0921", "best_bid": "0.79", "best_ask": "0.89"}, {"asset_id": "109227307115212040009558734329420624109955456904374090651494287022030420438197", "price": "0.78", "size": "227.27", "side": "SELL", "hash": "42af7abe5b96604fe2fa9c5f21b7f4473fac369a", "best_bid": "0.11", "best_ask": "0.21"}], "timestamp": "1769384660968", "event_type": "price_change"}}
{"_local_timestamp": "2026-01-25T23:44:21.557924+00:00", "data": {"market": "0xb3c09b93dc7b394fbea2b169b54da525c5d6de9ad5caf56da920058e7b74f161", "price_changes": [{"asset_id": "39663779628084842897937886547518878184317206079104235500705380518100175496233", "price": "0.19", "size": "473.96", "side": "BUY", "hash": "33f894df9102d861e603f6e117d0ac993999bf8c", "best_bid": "0.75", "best_ask": "0.89"}, {"asset_id": "100335878774855355346358755214398113208570878540440188453565903904895328912285", "price": "0.81", "size": "473.96", "side": "SELL", "hash": "3b8f9ca113322bdf4d4055a7f3f781434ecaf62b", "best_bid": "0.11", "best_ask": "0.25"}], "timestamp": "1769384660968", "event_type": "price_change"}}
{"_local_timestamp": "2026-01-25T23:44:21.558651+00:00", "data": {"market": "0xb3c09b93dc7b394fbea2b169b54da525c5d6de9ad5caf56da920058e7b74f161", "price_changes": [{"asset_id": "39663779628084842897937886547518878184317206079104235500705380518100175496233", "price": "0.11", "size": "634.09", "side": "BUY", "hash": "d00f32bcbc9e3ee59e46c4d3fb5f5b224ad69520", "best_bid": "0.75", "best_ask": "0.89"}, {"asset_id": "100335878774855355346358755214398113208570878540440188453565903904895328912285", "price": "0.89", "size": "634.09", "side": "SELL", "hash": "46693934e27f16b7af51fcbf8fa407f5a79543ca", "best_bid": "0.11", "best_ask": "0.25"}], "timestamp": "1769384660976", "event_type": "price_change"}}
{"_local_timestamp": "2026-01-25T23:44:21.565495+00:00", "data": {"market": "0x33315bd63d0cc17257c5d7524e5283639a5e17c6ce030d937f135aab02170c40", "price_changes": [{"asset_id": "92512666728361163935047824440150917945153592049030110328840756457871300635229", "price": "0.18", "size": "427.77", "side": "BUY", "hash": "602854898e15f344bad9660fba867ab516879b81", "best_bid": "0.79", "best_ask": "0.89"}, {"asset_id": "109227307115212040009558734329420624109955456904374090651494287022030420438197", "price": "0.82", "size": "427.77", "side": "SELL", "hash": "4bf0d602158d9a106c6841467156410da006508b", "best_bid": "0.11", "best_ask": "0.21"}], "timestamp": "1769384660976", "event_type": "price_change"}}
{"_local_timestamp": "2026-01-25T23:44:21.569228+00:00", "data": {"market": "0x2df8bb66d0a96661ec2a4f57b0510ca7c8e154d78d6d8f3b557478ddc34fcfae", "price_changes": [{"asset_id": "104293714017628859730042534598620180600303966146090765434616358106204241123622", "price": "0.05", "size": "630", "side": "BUY", "hash": "173ecffeae60e19a211b9ffa27ca8702e7a29a9b", "best_bid": "0.32", "best_ask": "0.53"}, {"asset_id": "34218064140411222044683093812278888477247876051063075885631415084973387284228", "price": "0.95", "size": "630", "side": "SELL", "hash": "a28d4dc9052ab255c2b4b5a24a836f4135b55419", "best_bid": "0.47", "best_ask": "0.68"}], "timestamp": "1769384660928", "event_type": "price_change"}}
{"_local_timestamp": "2026-01-25T23:44:21.595069+00:00", "data": {"market": "0x2df8bb66d0a96661ec2a4f57b0510ca7c8e154d78d6d8f3b557478ddc34fcfae", "price_changes": [{"asset_id": "104293714017628859730042534598620180600303966146090765434616358106204241123622", "price": "0.11", "size": "425", "side": "BUY", "hash": "8a38c8d579c3344a55767cf530042917c5fb1e43", "best_bid": "0.32", "best_ask": "0.53"}, {"asset_id": "34218064140411222044683093812278888477247876051063075885631415084973387284228", "price": "0.89", "size": "425", "side": "SELL", "hash": "e9a4139860983e1993346c0bc40d8402518198a2", "best_bid": "0.47", "best_ask": "0.68"}], "timestamp": "1769384660972", "event_type": "price_change"}}
{"_local_timestamp": "2026-01-25T23:44:21.641034+00:00", "data": {"market": "0x2df8bb66d0a96661ec2a4f57b0510ca7c8e154d78d6d8f3b557478ddc34fcfae", "price_changes": [{"asset_id": "34218064140411222044683093812278888477247876051063075885631415084973387284228", "price": "0.05", "size": "300", "side": "BUY", "hash": "164d42fe0d14baf8f717f0b12ed89070e5d37045", "best_bid": "0.47", "best_ask": "0.68"}, {"asset_id": "104293714017628859730042534598620180600303966146090765434616358106204241123622", "price": "0.95", "size": "300", "side": "SELL", "hash": "b5f32aca9b25a9442a326d3d2995e153f6a8e573", "best_bid": "0.32", "best_ask": "0.53"}], "timestamp": "1769384660979", "event_type": "price_change"}}
{"_local_timestamp": "2026-01-25T23:44:21.645443+00:00", "data": {"market": "0x2df8bb66d0a96661ec2a4f57b0510ca7c8e154d78d6d8f3b557478ddc34fcfae", "price_changes": [{"asset_id": "34218064140411222044683093812278888477247876051063075885631415084973387284228", "price": "0.16", "size": "150", "side": "BUY", "hash": "2947411bf7c69dcf8dbaa25f74a8f8caf45f8c91", "best_bid": "0.47", "best_ask": "0.68"}, {"asset_id": "104293714017628859730042534598620180600303966146090765434616358106204241123622", "price": "0.84", "size": "150", "side": "SELL", "hash": "e2757b69385cb468a88d0cd37e3bf5afc5be3bdf", "best_bid": "0.32", "best_ask": "0.53"}], "timestamp": "1769384660982", "event_type": "price_change"}}
{"_local_timestamp": "2026-01-25T23:44:21.648165+00:00", "data": {"market": "0x2df8bb66d0a96661ec2a4f57b0510ca7c8e154d78d6d8f3b557478ddc34fcfae", "price_changes": [{"asset_id": "34218064140411222044683093812278888477247876051063075885631415084973387284228", "price": "0.11", "size": "200", "side": "BUY", "hash": "de8d8b214cf90a540025016a0249019205242118", "best_bid": "0.47", "best_ask": "0.68"}, {"asset_id": "104293714017628859730042534598620180600303966146090765434616358106204241123622", "price": "0.89", "size": "200", "side": "SELL", "hash": "f4fb71cc4dff220f6308e05dcf2ab7cfc340dfdf", "best_bid": "0.32", "best_ask": "0.53"}], "timestamp": "1769384660984", "event_type": "price_change"}}
{"_local_timestamp": "2026-01-25T23:44:35.906872+00:00", "data": {"market": "0x2df8bb66d0a96661ec2a4f57b0510ca7c8e154d78d6d8f3b557478ddc34fcfae", "price_changes": [{"asset_id": "34218064140411222044683093812278888477247876051063075885631415084973387284228", "price": "0.05", "size": "700", "side": "BUY", "hash": "a86e63c8eea8a1bbb76fd11aaeee86060e668916", "best_bid": "0.47", "best_ask": "0.68"}, {"asset_id": "104293714017628859730042534598620180600303966146090765434616358106204241123622", "price": "0.95", "size": "700", "side": "SELL", "hash": "ef8301f96a81c9d7c8ce3ad72ba6f9729a0bef3c", "best_bid": "0.32", "best_ask": "0.53"}], "timestamp": "1769384675812", "event_type": "price_change"}}
{"_local_timestamp": "2026-01-25T23:44:35.921222+00:00", "data": {"market": "0x2df8bb66d0a96661ec2a4f57b0510ca7c8e154d78d6d8f3b557478ddc34fcfae", "price_changes": [{"asset_id": "34218064140411222044683093812278888477247876051063075885631415084973387284228", "price": "0.01", "size": "1100", "side": "BUY", "hash": "f9f0035e2b87418778d0e40d855e7558291d11a1", "best_bid": "0.47", "best_ask": "0.68"}, {"asset_id": "104293714017628859730042534598620180600303966146090765434616358106204241123622", "price": "0.99", "size": "1100", "side": "SELL", "hash": "1cc56221144c9d2c4753f6742b29ef3a28b7ba8d", "best_bid": "0.32", "best_ask": "0.53"}], "timestamp": "1769384675814", "event_type": "price_change"}}
{"_local_timestamp": "2026-01-25T23:44:35.930333+00:00", "data": {"market": "0x2df8bb66d0a96661ec2a4f57b0510ca7c8e154d78d6d8f3b557478ddc34fcfae", "price_changes": [{"asset_id": "104293714017628859730042534598620180600303966146090765434616358106204241123622", "price": "0.05", "size": "1030", "side": "BUY", "hash": "dcafe4cc0bfbdb08a10d9840bcb947f01f04cb9e", "best_bid": "0.32", "best_ask": "0.53"}, {"asset_id": "34218064140411222044683093812278888477247876051063075885631415084973387284228", "price": "0.95", "size": "1030", "side": "SELL", "hash": "bc77c9ddcd5fcc90e3d132128f8a7cd749025077", "best_bid": "0.47", "best_ask": "0.68"}], "timestamp": "1769384675819", "event_type": "price_change"}}
{"_local_timestamp": "2026-01-25T23:44:35.931050+00:00", "data": {"market": "0x2df8bb66d0a96661ec2a4f57b0510ca7c8e154d78d6d8f3b557478ddc34fcfae", "price_changes": [{"asset_id": "104293714017628859730042534598620180600303966146090765434616358106204241123622", "price": "0.07", "size": "233.07", "side": "BUY", "hash": "67565518f1e6f911e9ece19b7a01009015aeffa5", "best_bid": "0.32", "best_ask": "0.53"}, {"asset_id": "34218064140411222044683093812278888477247876051063075885631415084973387284228", "price": "0.93", "size": "233.07", "side": "SELL", "hash": "b97047534a1595fa1602537aff3b746538d97f00", "best_bid": "0.47", "best_ask": "0.68"}], "timestamp": "1769384675823", "event_type": "price_change"}}
{"_local_timestamp": "2026-01-25T23:44:35.931719+00:00", "data": {"market": "0x2df8bb66d0a96661ec2a4f57b0510ca7c8e154d78d6d8f3b557478ddc34fcfae", "price_changes": [{"asset_id": "104293714017628859730042534598620180600303966146090765434616358106204241123622", "price": "0.01", "size": "3108.63", "side": "BUY", "hash": "b7073888118b70175f219a2b2ad83a619d3d3409", "best_bid": "0.32", "best_ask": "0.53"}, {"asset_id": "34218064140411222044683093812278888477247876051063075885631415084973387284228", "price": "0.99", "size": "3108.63", "side": "SELL", "hash": "9becf72d23a6a732e5d1c8049f7ebe3ac844d644", "best_bid": "0.47", "best_ask": "0.68"}], "timestamp": "1769384675826", "event_type": "price_change"}}
{"_local_timestamp": "2026-01-25T23:44:35.950297+00:00", "data": {"market": "0x7f04c6bd72b53986c4e05d52ffdb3a0e8717ae809be62a1d4ec481313e86a0d0", "price_changes": [{"asset_id": "102967796728400955038420194199510769009042070489201650126144119775936757647743", "price": "0.37", "size": "100", "side": "BUY", "hash": "c2c6a46cf20c75871019a907e34c47a6916d07ac", "best_bid": "0.85", "best_ask": "0.94"}, {"asset_id": "53325847113338736338902840435383727831746710692724054663504837250405920447353", "price": "0.63", "size": "100", "side": "SELL", "hash": "b0f4bf38ed21e94e73505f49504a0ef5aca765c6", "best_bid": "0.06", "best_ask": "0.15"}], "timestamp": "1769384675872", "event_type": "price_change"}}
{"_local_timestamp": "2026-01-25T23:44:35.951044+00:00", "data": {"market": "0x33315bd63d0cc17257c5d7524e5283639a5e17c6ce030d937f135aab02170c40", "price_changes": [{"asset_id": "92512666728361163935047824440150917945153592049030110328840756457871300635229", "price": "0.37", "size": "25", "side": "BUY", "hash": "db1cfe32c3aa8bd2db6e8436e37ddd5dd3a8183f", "best_bid": "0.79", "best_ask": "0.89"}, {"asset_id": "109227307115212040009558734329420624109955456904374090651494287022030420438197", "price": "0.63", "size": "25", "side": "SELL", "hash": "3499701f4c8f1a171c66ac9bf109b2e1d47637f4", "best_bid": "0.11", "best_ask": "0.21"}], "timestamp": "1769384675872", "event_type": "price_change"}}
{"_local_timestamp": "2026-01-25T23:44:35.951704+00:00", "data": {"market": "0xc7e04626fbed6834456b0b9ed45e7da039ad826933e3abba81e26e71a79b2388", "price_changes": [{"asset_id": "108633032965983853701783501560325265009339710531442379830307955199797783135140", "price": "0.45", "size": "25", "side": "BUY", "hash": "cb7b8263e1fa7e8ea561b7fdefc1840a001fef48", "best_bid": "0.81", "best_ask": "0.95"}, {"asset_id": "20915970858057867358422412033597169312902618738489336824716408730559800805214", "price": "0.55", "size": "25", "side": "SELL", "hash": "b2034f8524c79da780b0095223c28049c4081275", "best_bid": "0.05", "best_ask": "0.19"}], "timestamp": "1769384675872", "event_type": "price_change"}}
{"_local_timestamp": "2026-01-25T23:44:35.952544+00:00", "data": {"market": "0xb3c09b93dc7b394fbea2b169b54da525c5d6de9ad5caf56da920058e7b74f161", "price_changes": [{"asset_id": "39663779628084842897937886547518878184317206079104235500705380518100175496233", "price": "0.33", "size": "25", "side": "BUY", "hash": "ad571c418727daf8c3a500553d33b7f3df361c36", "best_bid": "0.75", "best_ask": "0.89"}, {"asset_id": "100335878774855355346358755214398113208570878540440188453565903904895328912285", "price": "0.67", "size": "25", "side": "SELL", "hash": "4580ee73d940f166ebdedb3be734c4dd0e8940ed", "best_bid": "0.11", "best_ask": "0.25"}], "timestamp": "1769384675872", "event_type": "price_change"}}
{"_local_timestamp": "2026-01-25T23:44:35.958606+00:00", "data": {"market": "0xb3c09b93dc7b394fbea2b169b54da525c5d6de9ad5caf56da920058e7b74f161", "price_changes": [{"asset_id": "39663779628084842897937886547518878184317206079104235500705380518100175496233", "price": "0.33", "size": "0", "side": "BUY", "hash": "13acf2d4b9be1ea6c56a0fa13f5c3533a4e4e8e0", "best_bid": "0.75", "best_ask": "0.89"}, {"asset_id": "100335878774855355346358755214398113208570878540440188453565903904895328912285", "price": "0.67", "size": "0", "side": "SELL", "hash": "b48df79f21538489ed9fe2753c5e2044330de609", "best_bid": "0.11", "best_ask": "0.25"}], "timestamp": "1769384675885", "event_type": "price_change"}}
{"_local_timestamp": "2026-01-25T23:44:36.038783+00:00", "data": {"market": "0x7f04c6bd72b53986c4e05d52ffdb3a0e8717ae809be62a1d4ec481313e86a0d0", "price_changes": [{"asset_id": "102967796728400955038420194199510769009042070489201650126144119775936757647743", "price": "0.37", "size": "75", "side": "BUY", "hash": "8fff27a23267f335ce0863d39262a5e67268da43", "best_bid": "0.85", "best_ask": "0.94"}, {"asset_id": "53325847113338736338902840435383727831746710692724054663504837250405920447353", "price": "0.63", "size": "75", "side": "SELL", "hash": "8802eabc0ddb41b1571f0b1a170d82225934a9ae", "best_bid": "0.06", "best_ask": "0.15"}], "timestamp": "1769384675886", "event_type": "price_change"}}
{"_local_timestamp": "2026-01-25T23:44:36.039647+00:00", "data": {"market": "0x33315bd63d0cc17257c5d7524e5283639a5e17c6ce030d937f135aab02170c40", "price_changes": [{"asset_id": "92512666728361163935047824440150917945153592049030110328840756457871300635229", "price": "0.37", "size": "0", "side": "BUY", "hash": "aa980ced557c075635272d7cd89d5379c4510fdc", "best_bid": "0.79", "best_ask": "0.89"}, {"asset_id": "109227307115212040009558734329420624109955456904374090651494287022030420438197", "price": "0.63", "size": "0", "side": "SELL", "hash": "28f493b6fedec2958ffb8f0efd503be60046168d", "best_bid": "0.11", "best_ask": "0.21"}], "timestamp": "1769384675885", "event_type": "price_change"}}
{"_local_timestamp": "2026-01-25T23:44:36.040360+00:00", "data": {"market": "0xc7e04626fbed6834456b0b9ed45e7da039ad826933e3abba81e26e71a79b2388", "price_changes": [{"asset_id": "108633032965983853701783501560325265009339710531442379830307955199797783135140", "price": "0.45", "size": "0", "side": "BUY", "hash": "077bff0b7edf75c4c92be96bb3a1ebdd1c300983", "best_bid": "0.81", "best_ask": "0.95"}, {"asset_id": "20915970858057867358422412033597169312902618738489336824716408730559800805214", "price": "0.55", "size": "0", "side": "SELL", "hash": "ff0321565f2ae30843fd5f8c58bf51e71a094c3a", "best_bid": "0.05", "best_ask": "0.19"}], "timestamp": "1769384675886", "event_type": "price_change"}}
{"_local_timestamp": "2026-01-25T23:44:36.041097+00:00", "data": {"market": "0x7f04c6bd72b53986c4e05d52ffdb3a0e8717ae809be62a1d4ec481313e86a0d0", "price_changes": [{"asset_id": "102967796728400955038420194199510769009042070489201650126144119775936757647743", "price": "0.39", "size": "25", "side": "BUY", "hash": "9bf42c795f06d2840f9c53d876785a320ffdb0b0", "best_bid": "0.85", "best_ask": "0.94"}, {"asset_id": "53325847113338736338902840435383727831746710692724054663504837250405920447353", "price": "0.61", "size": "25", "side": "SELL", "hash": "d7a312ed4a45426210c8fa28a24ce678e8a603ca", "best_bid": "0.06", "best_ask": "0.15"}], "timestamp": "1769384675915", "event_type": "price_change"}}
{"_local_timestamp": "2026-01-25T23:44:36.065144+00:00", "data": {"market": "0xb3c09b93dc7b394fbea2b169b54da525c5d6de9ad5caf56da920058e7b74f161", "price_changes": [{"asset_id": "39663779628084842897937886547518878184317206079104235500705380518100175496233", "price": "0.54", "size": "25", "side": "BUY", "hash": "bc1100e237edfccf375d52880474429969982259", "best_bid": "0.75", "best_ask": "0.89"}, {"asset_id": "100335878774855355346358755214398113208570878540440188453565903904895328912285", "price": "0.46", "size": "25", "side": "SELL", "hash": "dd30d4d6eeabf936aa8a2c5a00181543fea0f2dd", "best_bid": "0.11", "best_ask": "0.25"}], "timestamp": "1769384675915", "event_type": "price_change"}}
{"_local_timestamp": "2026-01-25T23:44:36.065852+00:00", "data": {"market": "0x33315bd63d0cc17257c5d7524e5283639a5e17c6ce030d937f135aab02170c40", "price_changes": [{"asset_id": "92512666728361163935047824440150917945153592049030110328840756457871300635229", "price": "0.58", "size": "25", "side": "BUY", "hash": "18b741e35930c5ec30415a0db5417a113048467a", "best_bid": "0.79", "best_ask": "0.89"}, {"asset_id": "109227307115212040009558734329420624109955456904374090651494287022030420438197", "price": "0.42", "size": "25", "side": "SELL", "hash": "222e95d22b48aa27b65e26c68699ea1fb38e3ed4", "best_bid": "0.11", "best_ask": "0.21"}], "timestamp": "1769384675915", "event_type": "price_change"}}
{"_local_timestamp": "2026-01-25T23:44:36.066526+00:00", "data": {"market": "0xc7e04626fbed6834456b0b9ed45e7da039ad826933e3abba81e26e71a79b2388", "price_changes": [{"asset_id": "108633032965983853701783501560325265009339710531442379830307955199797783135140", "price": "0.7", "size": "25", "side": "BUY", "hash": "0b0471e2db149376f729c1db6e195a93928286cf", "best_bid": "0.81", "best_ask": "0.95"}, {"asset_id": "20915970858057867358422412033597169312902618738489336824716408730559800805214", "price": "0.3", "size": "25", "side": "SELL", "hash": "ddc7900dc9a1b840d634d39c76f95064b8d3cb2f", "best_bid": "0.05", "best_ask": "0.19"}], "timestamp": "1769384675915", "event_type": "price_change"}}
{"_local_timestamp": "2026-01-25T23:44:36.143386+00:00", "data": {"market": "0x33315bd63d0cc17257c5d7524e5283639a5e17c6ce030d937f135aab02170c40", "price_changes": [{"asset_id": "92512666728361163935047824440150917945153592049030110328840756457871300635229", "price": "0.58", "size": "50", "side": "BUY", "hash": "d1843de8e181d93935bb2a19eb7aff919d0ee6e4", "best_bid": "0.79", "best_ask": "0.89"}, {"asset_id": "109227307115212040009558734329420624109955456904374090651494287022030420438197", "price": "0.42", "size": "50", "side": "SELL", "hash": "6ea33399008ae30175706ea1d0c8d678eb3abaa1", "best_bid": "0.11", "best_ask": "0.21"}], "timestamp": "1769384676071", "event_type": "price_change"}}
{"_local_timestamp": "2026-01-25T23:44:36.144273+00:00", "data": {"market": "0xb3c09b93dc7b394fbea2b169b54da525c5d6de9ad5caf56da920058e7b74f161", "price_changes": [{"asset_id": "39663779628084842897937886547518878184317206079104235500705380518100175496233", "price": "0.54", "size": "50", "side": "BUY", "hash": "c1c91db3b7534711d48f9ffb99783f6ebea6741a", "best_bid": "0.75", "best_ask": "0.89"}, {"asset_id": "100335878774855355346358755214398113208570878540440188453565903904895328912285", "price": "0.46", "size": "50", "side": "SELL", "hash": "b72e795109192473d4ae44b2ed62a95215c61922", "best_bid": "0.11", "best_ask": "0.25"}], "timestamp": "1769384676071", "event_type": "price_change"}}
{"_local_timestamp": "2026-01-25T23:44:36.145036+00:00", "data": {"market": "0xc7e04626fbed6834456b0b9ed45e7da039ad826933e3abba81e26e71a79b2388", "price_changes": [{"asset_id": "108633032965983853701783501560325265009339710531442379830307955199797783135140", "price": "0.7", "size": "50", "side": "BUY", "hash": "34ae8258504f5bd82d59a2f744a3df5e16e5f0ec", "best_bid": "0.81", "best_ask": "0.95"}, {"asset_id": "20915970858057867358422412033597169312902618738489336824716408730559800805214", "price": "0.3", "size": "50", "side": "SELL", "hash": "dd6bc36a389598b56ef7a47662f7a9872a4fa8a7", "best_bid": "0.05", "best_ask": "0.19"}], "timestamp": "1769384676071", "event_type": "price_change"}}
{"_local_timestamp": "2026-01-25T23:44:36.145747+00:00", "data": {"market": "0x7f04c6bd72b53986c4e05d52ffdb3a0e8717ae809be62a1d4ec481313e86a0d0", "price_changes": [{"asset_id": "102967796728400955038420194199510769009042070489201650126144119775936757647743", "price": "0.39", "size": "50", "side": "BUY", "hash": "65a16cdf07b761d749115d2d8a5c4d093e733bea", "best_bid": "0.85", "best_ask": "0.94"}, {"asset_id": "53325847113338736338902840435383727831746710692724054663504837250405920447353", "price": "0.61", "size": "50", "side": "SELL", "hash": "b60b7c4fbec89a91726ea32060fa71d086701db9", "best_bid": "0.06", "best_ask": "0.15"}], "timestamp": "1769384676071", "event_type": "price_change"}}
{"_local_timestamp": "2026-01-25T23:44:36.186022+00:00", "data": {"market": "0x33315bd63d0cc17257c5d7524e5283639a5e17c6ce030d937f135aab02170c40", "price_changes": [{"asset_id": "92512666728361163935047824440150917945153592049030110328840756457871300635229", "price": "0.39", "size": "0", "side": "BUY", "hash": "0e4c1150a727a1e42e46742bff830be2c7b6c975", "best_bid": "0.79", "best_ask": "0.89"}, {"asset_id": "109227307115212040009558734329420624109955456904374090651494287022030420438197", "price": "0.61", "size": "0", "side": "SELL", "hash": "572d9cab0c961bdadc618e86fb7cf6174a1037ee", "best_bid": "0.11", "best_ask": "0.21"}], "timestamp": "1769384676117", "event_type": "price_change"}}
{"_local_timestamp": "2026-01-25T23:44:37.238096+00:00", "data": {"market": "0xb3c09b93dc7b394fbea2b169b54da525c5d6de9ad5caf56da920058e7b74f161", "price_changes": [{"asset_id": "39663779628084842897937886547518878184317206079104235500705380518100175496233", "price": "0.49", "size": "0", "side": "BUY", "hash": "0daa8379e65c7d01559a0daeca6a0df64a345712", "best_bid": "0.75", "best_ask": "0.89"}, {"asset_id": "100335878774855355346358755214398113208570878540440188453565903904895328912285", "price": "0.51", "size": "0", "side": "SELL", "hash": "f3ed6fe5741ad7405b5dae04366493b205b46cbb", "best_bid": "0.11", "best_ask": "0.25"}], "timestamp": "1769384677164", "event_type": "price_change"}}
{"_local_timestamp": "2026-01-25T23:44:37.238935+00:00", "data": {"market": "0x33315bd63d0cc17257c5d7524e5283639a5e17c6ce030d937f135aab02170c40", "price_changes": [{"asset_id": "92512666728361163935047824440150917945153592049030110328840756457871300635229", "price": "0.4", "size": "0", "side": "BUY", "hash": "16a7b0fb7bbc735d76f0e6171e0ae904bf176955", "best_bid": "0.79", "best_ask": "0.89"}, {"asset_id": "109227307115212040009558734329420624109955456904374090651494287022030420438197", "price": "0.6", "size": "0", "side": "SELL", "hash": "efb3e4deee2cc11d34ff528cb297f8cf7872075a", "best_bid": "0.11", "best_ask": "0.21"}], "timestamp": "1769384677164", "event_type": "price_change"}}
{"_local_timestamp": "2026-01-25T23:44:37.257322+00:00", "data": {"market": "0xb3c09b93dc7b394fbea2b169b54da525c5d6de9ad5caf56da920058e7b74f161", "price_changes": [{"asset_id": "39663779628084842897937886547518878184317206079104235500705380518100175496233", "price": "0.55", "size": "20", "side": "BUY", "hash": "dd94585d43553e8c7c1837f062f3a22fa5a1234b", "best_bid": "0.75", "best_ask": "0.89"}, {"asset_id": "100335878774855355346358755214398113208570878540440188453565903904895328912285", "price": "0.45", "size": "20", "side": "SELL", "hash": "8d1e93fff31174188d8e0e62db3ec0e0b6992c53", "best_bid": "0.11", "best_ask": "0.25"}], "timestamp": "1769384677194", "event_type": "price_change"}}
{"_local_timestamp": "2026-01-25T23:44:37.258144+00:00", "data": {"market": "0x33315bd63d0cc17257c5d7524e5283639a5e17c6ce030d937f135aab02170c40", "price_changes": [{"asset_id": "92512666728361163935047824440150917945153592049030110328840756457871300635229", "price": "0.59", "size": "20", "side": "BUY", "hash": "976330a8cac57f5b472a99e7ab1cb92d10e399e3", "best_bid": "0.79", "best_ask": "0.89"}, {"asset_id": "109227307115212040009558734329420624109955456904374090651494287022030420438197", "price": "0.41", "size": "20", "side": "SELL", "hash": "f197b21f7d2e4e74fe4be81812551ff41dd4581d", "best_bid": "0.11", "best_ask": "0.21"}], "timestamp": "1769384677194", "event_type": "price_change"}}
{"_local_timestamp": "2026-01-25T23:44:37.798899+00:00", "data": {"market": "0x2df8bb66d0a96661ec2a4f57b0510ca7c8e154d78d6d8f3b557478ddc34fcfae", "price_changes": [{"asset_id": "104293714017628859730042534598620180600303966146090765434616358106204241123622", "price": "0.05", "size": "930", "side": "BUY", "hash": "bff5daaf18cee013a82c0b36d2dd0a93954d952a", "best_bid": "0.32", "best_ask": "0.53"}, {"asset_id": "34218064140411222044683093812278888477247876051063075885631415084973387284228", "price": "0.95", "size": "930", "side": "SELL", "hash": "5ca1aeee0cf83fc91572a173e1a4187a4ad412ae", "best_bid": "0.47", "best_ask": "0.68"}], "timestamp": "1769384677730", "event_type": "price_change"}}
{"_local_timestamp": "2026-01-25T23:44:38.057592+00:00", "data": {"market": "0x2df8bb66d0a96661ec2a4f57b0510ca7c8e154d78d6d8f3b557478ddc34fcfae", "price_changes": [{"asset_id": "34218064140411222044683093812278888477247876051063075885631415084973387284228", "price": "0.06", "size": "300", "side": "BUY", "hash": "439fd02ba736d21f790a7fd19a67e05df9198a96", "best_bid": "0.47", "best_ask": "0.68"}, {"asset_id": "104293714017628859730042534598620180600303966146090765434616358106204241123622", "price": "0.94", "size": "300", "side": "SELL", "hash": "4e7143d8dba27e28caffa62144d436f2e67be84d", "best_bid": "0.32", "best_ask": "0.53"}], "timestamp": "1769384677978", "event_type": "price_change"}}
{"_local_timestamp": "2026-01-25T23:45:09.367405+00:00", "data": {"market": "0x2df8bb66d0a96661ec2a4f57b0510ca7c8e154d78d6d8f3b557478ddc34fcfae", "price_changes": [{"asset_id": "34218064140411222044683093812278888477247876051063075885631415084973387284228", "price": "0.24", "size": "8.5", "side": "BUY", "hash": "da900dc0e1ee0d4aad7cefcb13844cdc60882f86", "best_bid": "0.47", "best_ask": "0.68"}, {"asset_id": "104293714017628859730042534598620180600303966146090765434616358106204241123622", "price": "0.76", "size": "8.5", "side": "SELL", "hash": "7f0ee1cb84e0440012fcc4a2c95ff755082b0aca", "best_bid": "0.32", "best_ask": "0.53"}], "timestamp": "1769384709302", "event_type": "price_change"}}
{"_local_timestamp": "2026-01-25T23:45:09.369709+00:00", "data": {"market": "0x2df8bb66d0a96661ec2a4f57b0510ca7c8e154d78d6d8f3b557478ddc34fcfae", "price_changes": [{"asset_id": "104293714017628859730042534598620180600303966146090765434616358106204241123622", "price": "0.31", "size": "8.5", "side": "BUY", "hash": "dd86391595d679a2fadaeec142155285f7510eaa", "best_bid": "0.32", "best_ask": "0.53"}, {"asset_id": "34218064140411222044683093812278888477247876051063075885631415084973387284228", "price": "0.69", "size": "8.5", "side": "SELL", "hash": "65ddb9a8b162a5255dbc3068470445d8369798f9", "best_bid": "0.47", "best_ask": "0.68"}], "timestamp": "1769384709302", "event_type": "price_change"}}
{"_local_timestamp": "2026-01-25T23:45:27.677470+00:00", "data": {"market": "0xb3c09b93dc7b394fbea2b169b54da525c5d6de9ad5caf56da920058e7b74f161", "price_changes": [{"asset_id": "39663779628084842897937886547518878184317206079104235500705380518100175496233", "price": "0.73", "size": "50", "side": "BUY", "hash": "4f519e8e04492a1815802a864a18fd580b9c27d3", "best_bid": "0.75", "best_ask": "0.89"}, {"asset_id": "100335878774855355346358755214398113208570878540440188453565903904895328912285", "price": "0.27", "size": "50", "side": "SELL", "hash": "96acdf03ccf6ec1fce3f128d8de997ae939d8f20", "best_bid": "0.11", "best_ask": "0.25"}], "timestamp": "1769384727615", "event_type": "price_change"}}
{"_local_timestamp": "2026-01-25T23:45:27.678280+00:00", "data": {"market": "0x2df8bb66d0a96661ec2a4f57b0510ca7c8e154d78d6d8f3b557478ddc34fcfae", "price_changes": [{"asset_id": "104293714017628859730042534598620180600303966146090765434616358106204241123622", "price": "0.37", "size": "50", "side": "BUY", "hash": "90e9e50ea2501b8bd2fa65df7e18798e5373d19e", "best_bid": "0.37", "best_ask": "0.53"}, {"asset_id": "34218064140411222044683093812278888477247876051063075885631415084973387284228", "price": "0.63", "size": "50", "side": "SELL", "hash": "8bc1c3213754b8eb37cf5f0d8970b1976c9e9bef", "best_bid": "0.47", "best_ask": "0.63"}], "timestamp": "1769384727615", "event_type": "price_change"}}
{"_local_timestamp": "2026-01-25T23:45:27.682409+00:00", "data": {"market": "0x7f04c6bd72b53986c4e05d52ffdb3a0e8717ae809be62a1d4ec481313e86a0d0", "price_changes": [{"asset_id": "102967796728400955038420194199510769009042070489201650126144119775936757647743", "price": "0.86", "size": "50", "side": "BUY", "hash": "2041470138270f34e46503399d42208b2afb31dd", "best_bid": "0.86", "best_ask": "0.94"}, {"asset_id": "53325847113338736338902840435383727831746710692724054663504837250405920447353", "price": "0.14", "size": "50", "side": "SELL", "hash": "7d8832b126b86365fae44e01d2c06a3e610cf220", "best_bid": "0.06", "best_ask": "0.14"}], "timestamp": "1769384727615", "event_type": "price_change"}}
{"_local_timestamp": "2026-01-25T23:45:27.683101+00:00", "data": {"market": "0x33315bd63d0cc17257c5d7524e5283639a5e17c6ce030d937f135aab02170c40", "price_changes": [{"asset_id": "92512666728361163935047824440150917945153592049030110328840756457871300635229", "price": "0.8", "size": "50", "side": "BUY", "hash": "e103cdae2fc2687be629d55fa0a593da86770fcf", "best_bid": "0.8", "best_ask": "0.89"}, {"asset_id": "109227307115212040009558734329420624109955456904374090651494287022030420438197", "price": "0.2", "size": "50", "side": "SELL", "hash": "17dbaf64dc57787ece409f40e91b26db40f027a7", "best_bid": "0.11", "best_ask": "0.2"}], "timestamp": "1769384727615", "event_type": "price_change"}}
{"_local_timestamp": "2026-01-25T23:45:27.683782+00:00", "data": {"market": "0xc7e04626fbed6834456b0b9ed45e7da039ad826933e3abba81e26e71a79b2388", "price_changes": [{"asset_id": "108633032965983853701783501560325265009339710531442379830307955199797783135140", "price": "0.82", "size": "50", "side": "BUY", "hash": "8ebbddcedb91546da8460b8229677c0f7ee8fc68", "best_bid": "0.82", "best_ask": "0.95"}, {"asset_id": "20915970858057867358422412033597169312902618738489336824716408730559800805214", "price": "0.18", "size": "50", "side": "SELL", "hash": "39fa3621110a4bcdba2877e5903cdb31e432fd88", "best_bid": "0.05", "best_ask": "0.18"}], "timestamp": "1769384727615", "event_type": "price_change"}}
{"_local_timestamp": "2026-01-25T23:45:27.764115+00:00", "data": {"market": "0x2df8bb66d0a96661ec2a4f57b0510ca7c8e154d78d6d8f3b557478ddc34fcfae", "price_changes": [{"asset_id": "34218064140411222044683093812278888477247876051063075885631415084973387284228", "price": "0.22", "size": "190.9", "side": "BUY", "hash": "606af118ff0dfee4bc1a2958414ddb13b606780a", "best_bid": "0.47", "best_ask": "0.63"}, {"asset_id": "104293714017628859730042534598620180600303966146090765434616358106204241123622", "price": "0.78", "size": "190.9", "side": "SELL", "hash": "ea441c834fe4c19bf604780d81c272fbab39af3c", "best_bid": "0.37", "best_ask": "0.53"}], "timestamp": "1769384727694", "event_type": "price_change"}}
{"_local_timestamp": "2026-01-25T23:45:27.803224+00:00", "data": {"market": "0x2df8bb66d0a96661ec2a4f57b0510ca7c8e154d78d6d8f3b557478ddc34fcfae", "price_changes": [{"asset_id": "34218064140411222044683093812278888477247876051063075885631415084973387284228", "price": "0.19", "size": "126.31", "side": "BUY", "hash": "95c5986525a722342b17b8406317929eebb31070", "best_bid": "0.47", "best_ask": "0.63"}, {"asset_id": "104293714017628859730042534598620180600303966146090765434616358106204241123622", "price": "0.81", "size": "126.31", "side": "SELL", "hash": "7ff81c8e4e87507251322c256b5151e180ae565e", "best_bid": "0.37", "best_ask": "0.53"}], "timestamp": "1769384727738", "event_type": "price_change"}}
{"_local_timestamp": "2026-01-25T23:45:27.851727+00:00", "data": {"market": "0x2df8bb66d0a96661ec2a4f57b0510ca7c8e154d78d6d8f3b557478ddc34fcfae", "price_changes": [{"asset_id": "34218064140411222044683093812278888477247876051063075885631415084973387284228", "price": "0.16", "size": "312.5", "side": "BUY", "hash": "f0e8891072c1865cfe910a1e14a081b2b0a591d3", "best_bid": "0.47", "best_ask": "0.63"}, {"asset_id": "104293714017628859730042534598620180600303966146090765434616358106204241123622", "price": "0.84", "size": "312.5", "side": "SELL", "hash": "0bfa882717e4c47964286dab81082a437fc02715", "best_bid": "0.37", "best_ask": "0.53"}], "timestamp": "1769384727778", "event_type": "price_change"}}
{"_local_timestamp": "2026-01-25T23:45:27.889219+00:00", "data": {"market": "0x2df8bb66d0a96661ec2a4f57b0510ca7c8e154d78d6d8f3b557478ddc34fcfae", "price_changes": [{"asset_id": "34218064140411222044683093812278888477247876051063075885631415084973387284228", "price": "0.14", "size": "200", "side": "BUY", "hash": "ebc43e963ecb742b0c9775d2af731d875d291391", "best_bid": "0.47", "best_ask": "0.63"}, {"asset_id": "104293714017628859730042534598620180600303966146090765434616358106204241123622", "price": "0.86", "size": "200", "side": "SELL", "hash": "f0498e85d3f62627efca1db65a9e2702ad2860c3", "best_bid": "0.37", "best_ask": "0.53"}], "timestamp": "1769384727826", "event_type": "price_change"}}
{"_local_timestamp": "2026-01-25T23:45:27.975495+00:00", "data": {"market": "0x2df8bb66d0a96661ec2a4f57b0510ca7c8e154d78d6d8f3b557478ddc34fcfae", "price_changes": [{"asset_id": "34218064140411222044683093812278888477247876051063075885631415084973387284228", "price": "0.11", "size": "490.9", "side": "BUY", "hash": "fcc3dc5d4c7089ef8085a3651d11b8ba1346c958", "best_bid": "0.47", "best_ask": "0.63"}, {"asset_id": "104293714017628859730042534598620180600303966146090765434616358106204241123622", "price": "0.89", "size": "490.9", "side": "SELL", "hash": "e88a01b0fe05b7d9ff257a634f44e08c6f3b654c", "best_bid": "0.37", "best_ask": "0.53"}], "timestamp": "1769384727890", "event_type": "price_change"}}
{"_local_timestamp": "2026-01-25T23:45:28.036792+00:00", "data": {"market": "0x2df8bb66d0a96661ec2a4f57b0510ca7c8e154d78d6d8f3b557478ddc34fcfae", "price_changes": [{"asset_id": "34218064140411222044683093812278888477247876051063075885631415084973387284228", "price": "0.08", "size": "425", "side": "BUY", "hash": "9981bb4d648d565d32b2ec0bd481b5b4172720ed", "best_bid": "0.47", "best_ask": "0.63"}, {"asset_id": "104293714017628859730042534598620180600303966146090765434616358106204241123622", "price": "0.92", "size": "425", "side": "SELL", "hash": "f082f4d1ffe210253eab6cedd624274eeda6dec6", "best_bid": "0.37", "best_ask": "0.53"}], "timestamp": "1769384727954", "event_type": "price_change"}}
{"_local_timestamp": "2026-01-25T23:45:28.085706+00:00", "data": {"market": "0x2df8bb66d0a96661ec2a4f57b0510ca7c8e154d78d6d8f3b557478ddc34fcfae", "price_changes": [{"asset_id": "34218064140411222044683093812278888477247876051063075885631415084973387284228", "price": "0.05", "size": "1420", "side": "BUY", "hash": "946a8dead3241616d4e3076875402682c1512475", "best_bid": "0.47", "best_ask": "0.63"}, {"asset_id": "104293714017628859730042534598620180600303966146090765434616358106204241123622", "price": "0.95", "size": "1420", "side": "SELL", "hash": "5f61ee9165326bca0afec303e8dd2aad535b490d", "best_bid": "0.37", "best_ask": "0.53"}], "timestamp": "1769384728002", "event_type": "price_change"}}
{"_local_timestamp": "2026-01-25T23:45:28.594544+00:00", "data": {"market": "0x2df8bb66d0a96661ec2a4f57b0510ca7c8e154d78d6d8f3b557478ddc34fcfae", "price_changes": [{"asset_id": "104293714017628859730042534598620180600303966146090765434616358106204241123622", "price": "0.27", "size": "110", "side": "BUY", "hash": "a8b1271b6788c3b0e6988f2b6a922681ec8d292a", "best_bid": "0.37", "best_ask": "0.53"}, {"asset_id": "34218064140411222044683093812278888477247876051063075885631415084973387284228", "price": "0.73", "size": "110", "side": "SELL", "hash": "2b967556dd156b20a7ce13f7bb813dbe52c86129", "best_bid": "0.47", "best_ask": "0.63"}], "timestamp": "1769384728527", "event_type": "price_change"}}
{"_local_timestamp": "2026-01-25T23:45:53.168914+00:00", "data": {"market": "0x7f04c6bd72b53986c4e05d52ffdb3a0e8717ae809be62a1d4ec481313e86a0d0", "price_changes": [{"asset_id": "102967796728400955038420194199510769009042070489201650126144119775936757647743", "price": "0.33", "size": "800", "side": "BUY", "hash": "431ad0e60a64137f6504cde7d1180cae74a4cf26", "best_bid": "0.86", "best_ask": "0.94"}, {"asset_id": "53325847113338736338902840435383727831746710692724054663504837250405920447353", "price": "0.67", "size": "800", "side": "SELL", "hash": "b8968a0cc273bc4559973318e9fb68783bcb2427", "best_bid": "0.06", "best_ask": "0.14"}], "timestamp": "1769384753009", "event_type": "price_change"}}
{"_local_timestamp": "2026-01-25T23:45:53.169807+00:00", "data": {"market": "0xc7e04626fbed6834456b0b9ed45e7da039ad826933e3abba81e26e71a79b2388", "price_changes": [{"asset_id": "108633032965983853701783501560325265009339710531442379830307955199797783135140", "price": "0.21", "size": "233.33", "side": "BUY", "hash": "e7cfa850e6a5cdf72732a22964ab84d16257732e", "best_bid": "0.82", "best_ask": "0.95"}, {"asset_id": "20915970858057867358422412033597169312902618738489336824716408730559800805214", "price": "0.79", "size": "233.33", "side": "SELL", "hash": "7b584869005b3c9f911634d39ffbcaa12772b4b4", "best_bid": "0.05", "best_ask": "0.18"}], "timestamp": "1769384753009", "event_type": "price_change"}}
{"_local_timestamp": "2026-01-25T23:45:53.170764+00:00", "data": {"market": "0x2df8bb66d0a96661ec2a4f57b0510ca7c8e154d78d6d8f3b557478ddc34fcfae", "price_changes": [{"asset_id": "104293714017628859730042534598620180600303966146090765434616358106204241123622", "price": "0.11", "size": "300", "side": "BUY", "hash": "b0281ab8ca8a50572ac08d21bb6fb0c65decea9a", "best_bid": "0.37", "best_ask": "0.53"}, {"asset_id": "34218064140411222044683093812278888477247876051063075885631415084973387284228", "price": "0.89", "size": "300", "side": "SELL", "hash": "57bad93bd63e5959db28370353e318ca70640660", "best_bid": "0.47", "best_ask": "0.63"}], "timestamp": "1769384753009", "event_type": "price_change"}}
{"_local_timestamp": "2026-01-25T23:45:53.171542+00:00", "data": {"market": "0xb3c09b93dc7b394fbea2b169b54da525c5d6de9ad5caf56da920058e7b74f161", "price_changes": [{"asset_id": "39663779628084842897937886547518878184317206079104235500705380518100175496233", "price": "0.11", "size": "509.09", "side": "BUY", "hash": "d732bcf164359bf3a4c3268da23524f15e3fb746", "best_bid": "0.75", "best_ask": "0.89"}, {"asset_id": "100335878774855355346358755214398113208570878540440188453565903904895328912285", "price": "0.89", "size": "509.09", "side": "SELL", "hash": "9431d4d837683015904a4faf552ffae699cfd425", "best_bid": "0.11", "best_ask": "0.25"}], "timestamp": "1769384753008", "event_type": "price_change"}}
{"_local_timestamp": "2026-01-25T23:45:53.175630+00:00", "data": {"market": "0xb3c09b93dc7b394fbea2b169b54da525c5d6de9ad5caf56da920058e7b74f161", "price_changes": [{"asset_id": "39663779628084842897937886547518878184317206079104235500705380518100175496233", "price": "0.19", "size": "373.96", "side": "BUY", "hash": "d732bcf164359bf3a4c3268da23524f15e3fb746", "best_bid": "0.75", "best_ask": "0.89"}, {"asset_id": "100335878774855355346358755214398113208570878540440188453565903904895328912285", "price": "0.81", "size": "373.96", "side": "SELL", "hash": "9431d4d837683015904a4faf552ffae699cfd425", "best_bid": "0.11", "best_ask": "0.25"}], "timestamp": "1769384753008", "event_type": "price_change"}}
{"_local_timestamp": "2026-01-25T23:45:53.176446+00:00", "data": {"market": "0x33315bd63d0cc17257c5d7524e5283639a5e17c6ce030d937f135aab02170c40", "price_changes": [{"asset_id": "92512666728361163935047824440150917945153592049030110328840756457871300635229", "price": "0.13", "size": "461.53", "side": "BUY", "hash": "2a7d53e83ab352dae473a57d126c076f6c2a540d", "best_bid": "0.8", "best_ask": "0.89"}, {"asset_id": "109227307115212040009558734329420624109955456904374090651494287022030420438197", "price": "0.87", "size": "461.53", "side": "SELL", "hash": "5f6c3ed6fdfac9eb98f72b636f4c0a4a29e395d1", "best_bid": "0.11", "best_ask": "0.2"}], "timestamp": "1769384753009", "event_type": "price_change"}}
{"_local_timestamp": "2026-01-25T23:45:53.177205+00:00", "data": {"market": "0x33315bd63d0cc17257c5d7524e5283639a5e17c6ce030d937f135aab02170c40", "price_changes": [{"asset_id": "92512666728361163935047824440150917945153592049030110328840756457871300635229", "price": "0.18", "size": "327.77", "side": "BUY", "hash": "2a7d53e83ab352dae473a57d126c076f6c2a540d", "best_bid": "0.8", "best_ask": "0.89"}, {"asset_id": "109227307115212040009558734329420624109955456904374090651494287022030420438197", "price": "0.82", "size": "327.77", "side": "SELL", "hash": "5f6c3ed6fdfac9eb98f72b636f4c0a4a29e395d1", "best_bid": "0.11", "best_ask": "0.2"}], "timestamp": "1769384753009", "event_type": "price_change"}}
{"_local_timestamp": "2026-01-25T23:45:56.337035+00:00", "data": {"market": "0xc7e04626fbed6834456b0b9ed45e7da039ad826933e3abba81e26e71a79b2388", "price_changes": [{"asset_id": "108633032965983853701783501560325265009339710531442379830307955199797783135140", "price": "0.22", "size": "0", "side": "BUY", "hash": "e204a768fb069eee1b9ec172cace93b06857fb09", "best_bid": "0.82", "best_ask": "0.95"}, {"asset_id": "20915970858057867358422412033597169312902618738489336824716408730559800805214", "price": "0.78", "size": "0", "side": "SELL", "hash": "e08b320646334cf454ee1eff94f6be57d0356142", "best_bid": "0.05", "best_ask": "0.18"}], "timestamp": "1769384756075", "event_type": "price_change"}}
{"_local_timestamp": "2026-01-25T23:45:56.346028+00:00", "data": {"market": "0x7f04c6bd72b53986c4e05d52ffdb3a0e8717ae809be62a1d4ec481313e86a0d0", "price_changes": [{"asset_id": "102967796728400955038420194199510769009042070489201650126144119775936757647743", "price": "0.36", "size": "0", "side": "BUY", "hash": "3baf07fd102eaad0ce0b4cdf661043fe05af08c0", "best_bid": "0.86", "best_ask": "0.94"}, {"asset_id": "53325847113338736338902840435383727831746710692724054663504837250405920447353", "price": "0.64", "size": "0", "side": "SELL", "hash": "efd6c52e1c66acc7a24a65b32d9cfa050825ff4a", "best_bid": "0.06", "best_ask": "0.14"}], "timestamp": "1769384756073", "event_type": "price_change"}}
{"_local_timestamp": "2026-01-25T23:45:56.466222+00:00", "data": {"market": "0x2df8bb66d0a96661ec2a4f57b0510ca7c8e154d78d6d8f3b557478ddc34fcfae", "price_changes": [{"asset_id": "104293714017628859730042534598620180600303966146090765434616358106204241123622", "price": "0.11", "size": "200", "side": "BUY", "hash": "e5f9ebc13451f352a428161ee47bf29698400038", "best_bid": "0.37", "best_ask": "0.53"}, {"asset_id": "34218064140411222044683093812278888477247876051063075885631415084973387284228", "price": "0.89", "size": "200", "side": "SELL", "hash": "6fa34941da30e2697e2cbebe55ad65060b0663b9", "best_bid": "0.47", "best_ask": "0.63"}], "timestamp": "1769384756085", "event_type": "price_change"}}
{"_local_timestamp": "2026-01-25T23:46:17.122417+00:00", "data": {"market": "0x2df8bb66d0a96661ec2a4f57b0510ca7c8e154d78d6d8f3b557478ddc34fcfae", "price_changes": [{"asset_id": "104293714017628859730042534598620180600303966146090765434616358106204241123622", "price": "0.05", "size": "530", "side": "BUY", "hash": "fbf26849366c94872cfa6b115100aae501e0a05f", "best_bid": "0.37", "best_ask": "0.53"}, {"asset_id": "34218064140411222044683093812278888477247876051063075885631415084973387284228", "price": "0.95", "size": "530", "side": "SELL", "hash": "decb7227a993937adb7dc377ff1d940132f0a325", "best_bid": "0.47", "best_ask": "0.63"}], "timestamp": "1769384777005", "event_type": "price_change"}}
{"_local_timestamp": "2026-01-25T23:46:17.123378+00:00", "data": {"market": "0x2df8bb66d0a96661ec2a4f57b0510ca7c8e154d78d6d8f3b557478ddc34fcfae", "price_changes": [{"asset_id": "104293714017628859730042534598620180600303966146090765434616358106204241123622", "price": "0.07", "size": "33.07", "side": "BUY", "hash": "fbf26849366c94872cfa6b115100aae501e0a05f", "best_bid": "0.37", "best_ask": "0.53"}, {"asset_id": "34218064140411222044683093812278888477247876051063075885631415084973387284228", "price": "0.93", "size": "33.07", "side": "SELL", "hash": "decb7227a993937adb7dc377ff1d940132f0a325", "best_bid": "0.47", "best_ask": "0.63"}], "timestamp": "1769384777005", "event_type": "price_change"}}
{"_local_timestamp": "2026-01-25T23:46:17.124157+00:00", "data": {"market": "0x2df8bb66d0a96661ec2a4f57b0510ca7c8e154d78d6d8f3b557478ddc34fcfae", "price_changes": [{"asset_id": "104293714017628859730042534598620180600303966146090765434616358106204241123622", "price": "0.01", "size": "2108.63", "side": "BUY", "hash": "fbf26849366c94872cfa6b115100aae501e0a05f", "best_bid": "0.37", "best_ask": "0.53"}, {"asset_id": "34218064140411222044683093812278888477247876051063075885631415084973387284228", "price": "0.99", "size": "2108.63", "side": "SELL", "hash": "decb7227a993937adb7dc377ff1d940132f0a325", "best_bid": "0.47", "best_ask": "0.63"}], "timestamp": "1769384777005", "event_type": "price_change"}}
{"_local_timestamp": "2026-01-25T23:46:17.124915+00:00", "data": {"market": "0x2df8bb66d0a96661ec2a4f57b0510ca7c8e154d78d6d8f3b557478ddc34fcfae", "price_changes": [{"asset_id": "34218064140411222044683093812278888477247876051063075885631415084973387284228", "price": "0.05", "size": "1020", "side": "BUY", "hash": "7549f0e2ecb3300245be5c022f373907d7aad29a", "best_bid": "0.47", "best_ask": "0.63"}, {"asset_id": "104293714017628859730042534598620180600303966146090765434616358106204241123622", "price": "0.95", "size": "1020", "side": "SELL", "hash": "77da468c7f7a4502b514df95dde0a905299eee37", "best_bid": "0.37", "best_ask": "0.53"}], "timestamp": "1769384777005", "event_type": "price_change"}}
{"_local_timestamp": "2026-01-25T23:46:17.125667+00:00", "data": {"market": "0x2df8bb66d0a96661ec2a4f57b0510ca7c8e154d78d6d8f3b557478ddc34fcfae", "price_changes": [{"asset_id": "34218064140411222044683093812278888477247876051063075885631415084973387284228", "price": "0.01", "size": "100", "side": "BUY", "hash": "7549f0e2ecb3300245be5c022f373907d7aad29a", "best_bid": "0.47", "best_ask": "0.63"}, {"asset_id": "104293714017628859730042534598620180600303966146090765434616358106204241123622", "price": "0.99", "size": "100", "side": "SELL", "hash": "77da468c7f7a4502b514df95dde0a905299eee37", "best_bid": "0.37", "best_ask": "0.53"}], "timestamp": "1769384777005", "event_type": "price_change"}}
{"_local_timestamp": "2026-01-25T23:46:17.132539+00:00", "data": {"market": "0x33315bd63d0cc17257c5d7524e5283639a5e17c6ce030d937f135aab02170c40", "price_changes": [{"asset_id": "92512666728361163935047824440150917945153592049030110328840756457871300635229", "price": "0.09", "size": "700", "side": "BUY", "hash": "840a13ec9696da5ccbae49ed02fa9a4be763957e", "best_bid": "0.8", "best_ask": "0.89"}, {"asset_id": "109227307115212040009558734329420624109955456904374090651494287022030420438197", "price": "0.91", "size": "700", "side": "SELL", "hash": "f2000ab823819af1cf651977e28e34385b38de0c", "best_bid": "0.11", "best_ask": "0.2"}], "timestamp": "1769384777005", "event_type": "price_change"}}
{"_local_timestamp": "2026-01-25T23:46:29.851765+00:00", "data": {"market": "0x7f04c6bd72b53986c4e05d52ffdb3a0e8717ae809be62a1d4ec481313e86a0d0", "price_changes": [{"asset_id": "102967796728400955038420194199510769009042070489201650126144119775936757647743", "price": "0.38", "size": "42", "side": "BUY", "hash": "42ce390e7d8490d626a362c5e6ab4d9450d61282", "best_bid": "0.86", "best_ask": "0.94"}, {"asset_id": "53325847113338736338902840435383727831746710692724054663504837250405920447353", "price": "0.62", "size": "42", "side": "SELL", "hash": "810ab79b826ab7dd1e4f6d0ad77e55fc3b14cc0b", "best_bid": "0.06", "best_ask": "0.14"}], "timestamp": "1769384789754", "event_type": "price_change"}}
{"_local_timestamp": "2026-01-25T23:46:29.855569+00:00", "data": {"market": "0xc7e04626fbed6834456b0b9ed45e7da039ad826933e3abba81e26e71a79b2388", "price_changes": [{"asset_id": "108633032965983853701783501560325265009339710531442379830307955199797783135140", "price": "0.3", "size": "51", "side": "BUY", "hash": "90f80b9df8cf68e2e7a52dfeda7b41369bd6d2f8", "best_bid": "0.82", "best_ask": "0.95"}, {"asset_id": "20915970858057867358422412033597169312902618738489336824716408730559800805214", "price": "0.7", "size": "51", "side": "SELL", "hash": "8a2b163211b174dee7bad86753fae8c063833c86", "best_bid": "0.05", "best_ask": "0.18"}], "timestamp": "1769384789755", "event_type": "price_change"}}
{"_local_timestamp": "2026-01-25T23:46:29.856450+00:00", "data": {"market": "0x2df8bb66d0a96661ec2a4f57b0510ca7c8e154d78d6d8f3b557478ddc34fcfae", "price_changes": [{"asset_id": "104293714017628859730042534598620180600303966146090765434616358106204241123622", "price": "0.12", "size": "221.52", "side": "BUY", "hash": "d3f1482b359aacfc40c75d4b3e1392e5a0870abe", "best_bid": "0.37", "best_ask": "0.53"}, {"asset_id": "34218064140411222044683093812278888477247876051063075885631415084973387284228", "price": "0.88", "size": "221.52", "side": "SELL", "hash": "f5347c3daf1f88c63a243e8beda1fcae6eb3663f", "best_bid": "0.47", "best_ask": "0.63"}], "timestamp": "1769384789755", "event_type": "price_change"}}
{"_local_timestamp": "2026-01-25T23:46:31.908809+00:00", "data": {"market": "0x33315bd63d0cc17257c5d7524e5283639a5e17c6ce030d937f135aab02170c40", "price_changes": [{"asset_id": "92512666728361163935047824440150917945153592049030110328840756457871300635229", "price": "0.19", "size": "15", "side": "BUY", "hash": "31120cd74d673760eaf7f261ec668da2010d6048", "best_bid": "0.8", "best_ask": "0.89"}, {"asset_id": "109227307115212040009558734329420624109955456904374090651494287022030420438197", "price": "0.81", "size": "15", "side": "SELL", "hash": "57e45895c9bdd38be79ce44ded1933cbda126788", "best_bid": "0.11", "best_ask": "0.2"}], "timestamp": "1769384791831", "event_type": "price_change"}}
{"_local_timestamp": "2026-01-25T23:46:33.217066+00:00", "data": {"market": "0x33315bd63d0cc17257c5d7524e5283639a5e17c6ce030d937f135aab02170c40", "price_changes": [{"asset_id": "92512666728361163935047824440150917945153592049030110328840756457871300635229", "price": "0.2", "size": "5.78", "side": "BUY", "hash": "c034a3c2c9fb9bd18d9a1486a6df344bc37156ff", "best_bid": "0.8", "best_ask": "0.89"}, {"asset_id": "109227307115212040009558734329420624109955456904374090651494287022030420438197", "price": "0.8", "size": "5.78", "side": "SELL", "hash": "23afaa9e83cf714e33b7a4f6b3614909c4405b0a", "best_bid": "0.11", "best_ask": "0.2"}], "timestamp": "1769384793092", "event_type": "price_change"}}
{"_local_timestamp": "2026-01-25T23:46:33.657926+00:00", "data": {"market": "0x7f04c6bd72b53986c4e05d52ffdb3a0e8717ae809be62a1d4ec481313e86a0d0", "price_changes": [{"asset_id": "102967796728400955038420194199510769009042070489201650126144119775936757647743", "price": "0.19", "size": "0", "side": "BUY", "hash": "f1cc40b022a5968de09bf5af23ec70a7db07dacd", "best_bid": "0.86", "best_ask": "0.94"}, {"asset_id": "53325847113338736338902840435383727831746710692724054663504837250405920447353", "price": "0.81", "size": "0", "side": "SELL", "hash": "839c9d473e35815df0dc70f6cd298cc15edccf17", "best_bid": "0.06", "best_ask": "0.14"}], "timestamp": "1769384793576", "event_type": "price_change"}}
{"_local_timestamp": "2026-01-25T23:46:34.559159+00:00", "data": {"market": "0x7f04c6bd72b53986c4e05d52ffdb3a0e8717ae809be62a1d4ec481313e86a0d0", "price_changes": [{"asset_id": "102967796728400955038420194199510769009042070489201650126144119775936757647743", "price": "0.2", "size": "6.42", "side": "BUY", "hash": "bdd1ceadb6701facc19f95d2ff3fa1862f39bb63", "best_bid": "0.86", "best_ask": "0.94"}, {"asset_id": "53325847113338736338902840435383727831746710692724054663504837250405920447353", "price": "0.8", "size": "6.42", "side": "SELL", "hash": "56bd6671c682a75ecac8ae61f0e0815bf03b038d", "best_bid": "0.06", "best_ask": "0.14"}], "timestamp": "1769384794487", "event_type": "price_change"}}
{"_local_timestamp": "2026-01-25T23:46:40.068519+00:00", "data": {"market": "0xb3c09b93dc7b394fbea2b169b54da525c5d6de9ad5caf56da920058e7b74f161", "price_changes": [{"asset_id": "39663779628084842897937886547518878184317206079104235500705380518100175496233", "price": "0.48", "size": "0", "side": "BUY", "hash": "8300eb297f97a57527ad0d25fd1f0221a1b98080", "best_bid": "0.75", "best_ask": "0.89"}, {"asset_id": "100335878774855355346358755214398113208570878540440188453565903904895328912285", "price": "0.52", "size": "0", "side": "SELL", "hash": "053feedde0205b9a0e19f76759083f32a0286fa0", "best_bid": "0.11", "best_ask": "0.25"}], "timestamp": "1769384799991", "event_type": "price_change"}}
{"_local_timestamp": "2026-01-25T23:46:40.069666+00:00", "data": {"market": "0x2df8bb66d0a96661ec2a4f57b0510ca7c8e154d78d6d8f3b557478ddc34fcfae", "price_changes": [{"asset_id": "104293714017628859730042534598620180600303966146090765434616358106204241123622", "price": "0.27", "size": "10", "side": "BUY", "hash": "4e1e551384c7f43cacf999cb1babc7e60133cfa7", "best_bid": "0.37", "best_ask": "0.53"}, {"asset_id": "34218064140411222044683093812278888477247876051063075885631415084973387284228", "price": "0.73", "size": "10", "side": "SELL", "hash": "e72d1981c12728a01b8800ef1e9dc2edbaca7ed9", "best_bid": "0.47", "best_ask": "0.63"}], "timestamp": "1769384799991", "event_type": "price_change"}}
{"_local_timestamp": "2026-01-25T23:46:40.071902+00:00", "data": {"market": "0x33315bd63d0cc17257c5d7524e5283639a5e17c6ce030d937f135aab02170c40", "price_changes": [{"asset_id": "92512666728361163935047824440150917945153592049030110328840756457871300635229", "price": "0.32", "size": "0", "side": "BUY", "hash": "4cbd66cd45021ee65436dbb14fcd98a83e0f695d", "best_bid": "0.8", "best_ask": "0.89"}, {"asset_id": "109227307115212040009558734329420624109955456904374090651494287022030420438197", "price": "0.68", "size": "0", "side": "SELL", "hash": "aa6f2262d03729f5d143c3a3986ff03126fe4c70", "best_bid": "0.11", "best_ask": "0.2"}], "timestamp": "1769384799991", "event_type": "price_change"}}
{"_local_timestamp": "2026-01-25T23:46:40.073438+00:00", "data": {"market": "0xb3c09b93dc7b394fbea2b169b54da525c5d6de9ad5caf56da920058e7b74f161", "price_changes": [{"asset_id": "39663779628084842897937886547518878184317206079104235500705380518100175496233", "price": "0.19", "size": "312.36", "side": "BUY", "hash": "8300eb297f97a57527ad0d25fd1f0221a1b98080", "best_bid": "0.75", "best_ask": "0.89"}, {"asset_id": "100335878774855355346358755214398113208570878540440188453565903904895328912285", "price": "0.81", "size": "312.36", "side": "SELL", "hash": "053feedde0205b9a0e19f76759083f32a0286fa0", "best_bid": "0.11", "best_ask": "0.25"}], "timestamp": "1769384799991", "event_type": "price_change"}}
{"_local_timestamp": "2026-01-25T23:46:40.075129+00:00", "data": {"market": "0x2df8bb66d0a96661ec2a4f57b0510ca7c8e154d78d6d8f3b557478ddc34fcfae", "price_changes": [{"asset_id": "104293714017628859730042534598620180600303966146090765434616358106204241123622", "price": "0.15", "size": "0", "side": "BUY", "hash": "4e1e551384c7f43cacf999cb1babc7e60133cfa7", "best_bid": "0.37", "best_ask": "0.53"}, {"asset_id": "34218064140411222044683093812278888477247876051063075885631415084973387284228", "price": "0.85", "size": "0", "side": "SELL", "hash": "e72d1981c12728a01b8800ef1e9dc2edbaca7ed9", "best_bid": "0.47", "best_ask": "0.63"}], "timestamp": "1769384799991", "event_type": "price_change"}}
{"_local_timestamp": "2026-01-25T23:46:40.075996+00:00", "data": {"market": "0x2df8bb66d0a96661ec2a4f57b0510ca7c8e154d78d6d8f3b557478ddc34fcfae", "price_changes": [{"asset_id": "34218064140411222044683093812278888477247876051063075885631415084973387284228", "price": "0.23", "size": "0", "side": "BUY", "hash": "749ccfd6416c3ed9193d802611a1ceb4e18da832", "best_bid": "0.47", "best_ask": "0.63"}, {"asset_id": "104293714017628859730042534598620180600303966146090765434616358106204241123622", "price": "0.77", "size": "0", "side": "SELL", "hash": "8e5a6a7a2ff78674174c5eebd9e7df82a3011d68", "best_bid": "0.37", "best_ask": "0.53"}], "timestamp": "1769384799991", "event_type": "price_change"}}
{"_local_timestamp": "2026-01-25T23:46:40.076854+00:00", "data": {"market": "0x2df8bb66d0a96661ec2a4f57b0510ca7c8e154d78d6d8f3b557478ddc34fcfae", "price_changes": [{"asset_id": "34218064140411222044683093812278888477247876051063075885631415084973387284228", "price": "0.15", "size": "0", "side": "BUY", "hash": "749ccfd6416c3ed9193d802611a1ceb4e18da832", "best_bid": "0.47", "best_ask": "0.63"}, {"asset_id": "104293714017628859730042534598620180600303966146090765434616358106204241123622", "price": "0.85", "size": "0", "side": "SELL", "hash": "8e5a6a7a2ff78674174c5eebd9e7df82a3011d68", "best_bid": "0.37", "best_ask": "0.53"}], "timestamp": "1769384799991", "event_type": "price_change"}}
{"_local_timestamp": "2026-01-25T23:46:41.060583+00:00", "data": {"market": "0x2df8bb66d0a96661ec2a4f57b0510ca7c8e154d78d6d8f3b557478ddc34fcfae", "price_changes": [{"asset_id": "34218064140411222044683093812278888477247876051063075885631415084973387284228", "price": "0.32", "size": "50", "side": "BUY", "hash": "bae8388d49d59b412598be7ea1d9f6f3c4a36685", "best_bid": "0.47", "best_ask": "0.63"}, {"asset_id": "104293714017628859730042534598620180600303966146090765434616358106204241123622", "price": "0.68", "size": "50", "side": "SELL", "hash": "35558fb648c2adc9657ed2df2bcbcbccaaf4e27f", "best_bid": "0.37", "best_ask": "0.53"}], "timestamp": "1769384800986", "event_type": "price_change"}}
{"_local_timestamp": "2026-01-25T23:46:41.095005+00:00", "data": {"market": "0xb3c09b93dc7b394fbea2b169b54da525c5d6de9ad5caf56da920058e7b74f161", "price_changes": [{"asset_id": "39663779628084842897937886547518878184317206079104235500705380518100175496233", "price": "0.33", "size": "10", "side": "BUY", "hash": "92284542945c6e94ea638a9a53bb144db8e2a728", "best_bid": "0.75", "best_ask": "0.89"}, {"asset_id": "100335878774855355346358755214398113208570878540440188453565903904895328912285", "price": "0.67", "size": "10", "side": "SELL", "hash": "3b589935be248ef9a9004f2ac1a341c4294fa8d5", "best_bid": "0.11", "best_ask": "0.25"}], "timestamp": "1769384801021", "event_type": "price_change"}}
{"_local_timestamp": "2026-01-25T23:46:41.140604+00:00", "data": {"market": "0x2df8bb66d0a96661ec2a4f57b0510ca7c8e154d78d6d8f3b557478ddc34fcfae", "price_changes": [{"asset_id": "104293714017628859730042534598620180600303966146090765434616358106204241123622", "price": "0.12", "size": "288.18", "side": "BUY", "hash": "7e1622c8693cc21e6bfd39d1d95952d716be1d0d", "best_bid": "0.37", "best_ask": "0.53"}, {"asset_id": "34218064140411222044683093812278888477247876051063075885631415084973387284228", "price": "0.88", "size": "288.18", "side": "SELL", "hash": "efa399e128479a2248e13fc75bce4c94c6177eed", "best_bid": "0.47", "best_ask": "0.63"}], "timestamp": "1769384801059", "event_type": "price_change"}}
{"_local_timestamp": "2026-01-25T23:46:41.178912+00:00", "data": {"market": "0x33315bd63d0cc17257c5d7524e5283639a5e17c6ce030d937f135aab02170c40", "price_changes": [{"asset_id": "92512666728361163935047824440150917945153592049030110328840756457871300635229", "price": "0.32", "size": "100", "side": "BUY", "hash": "ee70c5650f58146ca72b38edd295992712255949", "best_bid": "0.8", "best_ask": "0.89"}, {"asset_id": "109227307115212040009558734329420624109955456904374090651494287022030420438197", "price": "0.68", "size": "100", "side": "SELL", "hash": "3c9101bb39e8da1609621b13dd973416c68f076a", "best_bid": "0.11", "best_ask": "0.2"}], "timestamp": "1769384801098", "event_type": "price_change"}}
{"_local_timestamp": "2026-01-25T23:46:41.224253+00:00", "data": {"market": "0x33315bd63d0cc17257c5d7524e5283639a5e17c6ce030d937f135aab02170c40", "price_changes": [{"asset_id": "92512666728361163935047824440150917945153592049030110328840756457871300635229", "price": "0.56", "size": "100", "side": "BUY", "hash": "de804e39c60109fed3d1c8e684e072267f6156d1", "best_bid": "0.8", "best_ask": "0.89"}, {"asset_id": "109227307115212040009558734329420624109955456904374090651494287022030420438197", "price": "0.44", "size": "100", "side": "SELL", "hash": "a8cb4b24ed0ec60658954873f94055c9c3b4c69d", "best_bid": "0.11", "best_ask": "0.2"}], "timestamp": "1769384801152", "event_type": "price_change"}}
{"_local_timestamp": "2026-01-25T23:46:41.271406+00:00", "data": {"market": "0x2df8bb66d0a96661ec2a4f57b0510ca7c8e154d78d6d8f3b557478ddc34fcfae", "price_changes": [{"asset_id": "34218064140411222044683093812278888477247876051063075885631415084973387284228", "price": "0.48", "size": "50", "side": "BUY", "hash": "165cf9979ae510da5b1c0e0394c3070f589155f3", "best_bid": "0.48", "best_ask": "0.63"}, {"asset_id": "104293714017628859730042534598620180600303966146090765434616358106204241123622", "price": "0.52", "size": "50", "side": "SELL", "hash": "e3b243c9103cd526f5455bb0f097676e7d450da4", "best_bid": "0.37", "best_ask": "0.52"}], "timestamp": "1769384801199", "event_type": "price_change"}}
{"_local_timestamp": "2026-01-25T23:46:41.274591+00:00", "data": {"market": "0x2df8bb66d0a96661ec2a4f57b0510ca7c8e154d78d6d8f3b557478ddc34fcfae", "price_changes": [{"asset_id": "104293714017628859730042534598620180600303966146090765434616358106204241123622", "price": "0.25", "size": "66.66", "side": "BUY", "hash": "446ec81833e4ec559e8aabc99a2428203986080b", "best_bid": "0.37", "best_ask": "0.52"}, {"asset_id": "34218064140411222044683093812278888477247876051063075885631415084973387284228", "price": "0.75", "size": "66.66", "side": "SELL", "hash": "c2168cf161a62e76a2151b33772e2d6f4a31f906", "best_bid": "0.48", "best_ask": "0.63"}], "timestamp": "1769384801203", "event_type": "price_change"}}
{"_local_timestamp": "2026-01-25T23:46:41.280013+00:00", "data": {"market": "0xb3c09b93dc7b394fbea2b169b54da525c5d6de9ad5caf56da920058e7b74f161", "price_changes": [{"asset_id": "39663779628084842897937886547518878184317206079104235500705380518100175496233", "price": "0.5", "size": "61.6", "side": "BUY", "hash": "d9096332171fd52ae22f5bbebf177db5e83d07df", "best_bid": "0.75", "best_ask": "0.89"}, {"asset_id": "100335878774855355346358755214398113208570878540440188453565903904895328912285", "price": "0.5", "size": "61.6", "side": "SELL", "hash": "ca43fde99b89117d9cfc51af8b247871d481168b", "best_bid": "0.11", "best_ask": "0.25"}], "timestamp": "1769384801207", "event_type": "price_change"}}
{"_local_timestamp": "2026-01-25T23:46:41.298724+00:00", "data": {"market": "0xb3c09b93dc7b394fbea2b169b54da525c5d6de9ad5caf56da920058e7b74f161", "price_changes": [{"asset_id": "39663779628084842897937886547518878184317206079104235500705380518100175496233", "price": "0.24", "size": "71.6", "side": "BUY", "hash": "884cfa13764642848f5003e4ead14bcaaea1fb8c", "best_bid": "0.75", "best_ask": "0.89"}, {"asset_id": "100335878774855355346358755214398113208570878540440188453565903904895328912285", "price": "0.76", "size": "71.6", "side": "SELL", "hash": "3ae00c8e4d7f2ea9dbd3f0741217202daf00fb90", "best_bid": "0.11", "best_ask": "0.25"}], "timestamp": "1769384801225", "event_type": "price_change"}}
{"_local_timestamp": "2026-01-25T23:46:41.304385+00:00", "data": {"market": "0x2df8bb66d0a96661ec2a4f57b0510ca7c8e154d78d6d8f3b557478ddc34fcfae", "price_changes": [{"asset_id": "104293714017628859730042534598620180600303966146090765434616358106204241123622", "price": "0.38", "size": "66.66", "side": "BUY", "hash": "142a3f27746634c33c8ae79dfcf932cdeb74cfff", "best_bid": "0.38", "best_ask": "0.52"}, {"asset_id": "34218064140411222044683093812278888477247876051063075885631415084973387284228", "price": "0.62", "size": "66.66", "side": "SELL", "hash": "b4ed8cadda6bb2dab0105e4b4a1ea7d6475f69dd", "best_bid": "0.48", "best_ask": "0.62"}], "timestamp": "1769384801229", "event_type": "price_change"}}
{"_local_timestamp": "2026-01-25T23:46:41.891885+00:00", "data": {"market": "0x2df8bb66d0a96661ec2a4f57b0510ca7c8e154d78d6d8f3b557478ddc34fcfae", "price_changes": [{"asset_id": "104293714017628859730042534598620180600303966146090765434616358106204241123622", "price": "0.12", "size": "278.66", "side": "BUY", "hash": "c44e06f91f7430bf6c9bcce82053a12884de7576", "best_bid": "0.38", "best_ask": "0.52"}, {"asset_id": "34218064140411222044683093812278888477247876051063075885631415084973387284228", "price": "0.88", "size": "278.66", "side": "SELL", "hash": "7db45cec8a27689f5fb61bbd8dc18e4d75b66808", "best_bid": "0.48", "best_ask": "0.62"}], "timestamp": "1769384801779", "event_type": "price_change"}}
{"_local_timestamp": "2026-01-25T23:46:41.901154+00:00", "data": {"market": "0x2df8bb66d0a96661ec2a4f57b0510ca7c8e154d78d6d8f3b557478ddc34fcfae", "price_changes": [{"asset_id": "104293714017628859730042534598620180600303966146090765434616358106204241123622", "price": "0.18", "size": "111.11", "side": "BUY", "hash": "918a9f9488b0e87388e8a1068c1961da79a1d85e", "best_bid": "0.38", "best_ask": "0.52"}, {"asset_id": "34218064140411222044683093812278888477247876051063075885631415084973387284228", "price": "0.82", "size": "111.11", "side": "SELL", "hash": "a076ce8b52f1e9f0d696b15f23ee0e3d346c529f", "best_bid": "0.48", "best_ask": "0.62"}], "timestamp": "1769384801792", "event_type": "price_change"}}
{"_local_timestamp": "2026-01-25T23:46:41.923989+00:00", "data": {"market": "0x2df8bb66d0a96661ec2a4f57b0510ca7c8e154d78d6d8f3b557478ddc34fcfae", "price_changes": [{"asset_id": "104293714017628859730042534598620180600303966146090765434616358106204241123622", "price": "0.16", "size": "150", "side": "BUY", "hash": "44541e07464fbe73276496009626c96e799cc5ca", "best_bid": "0.38", "best_ask": "0.52"}, {"asset_id": "34218064140411222044683093812278888477247876051063075885631415084973387284228", "price": "0.84", "size": "150", "side": "SELL", "hash": "da2f08a853db0eaa823c0a4bad6defeaa01261c1", "best_bid": "0.48", "best_ask": "0.62"}], "timestamp": "1769384801836", "event_type": "price_change"}}
{"_local_timestamp": "2026-01-25T23:46:41.956199+00:00", "data": {"market": "0xc7e04626fbed6834456b0b9ed45e7da039ad826933e3abba81e26e71a79b2388", "price_changes": [{"asset_id": "108633032965983853701783501560325265009339710531442379830307955199797783135140", "price": "0.69", "size": "0", "side": "BUY", "hash": "b649628c75cd40ec6c835873d2c5e084e3ece1c0", "best_bid": "0.82", "best_ask": "0.95"}, {"asset_id": "20915970858057867358422412033597169312902618738489336824716408730559800805214", "price": "0.31", "size": "0", "side": "SELL", "hash": "204bd532f5840fc6d123d1258a9fc6614370f5e7", "best_bid": "0.05", "best_ask": "0.18"}], "timestamp": "1769384801881", "event_type": "price_change"}}
{"_local_timestamp": "2026-01-25T23:46:42.287538+00:00", "data": {"market": "0x2df8bb66d0a96661ec2a4f57b0510ca7c8e154d78d6d8f3b557478ddc34fcfae", "price_changes": [{"asset_id": "104293714017628859730042534598620180600303966146090765434616358106204241123622", "price": "0.14", "size": "185.71", "side": "BUY", "hash": "0a596e2970de716a81ce9b22c7679a8b35bd930e", "best_bid": "0.38", "best_ask": "0.52"}, {"asset_id": "34218064140411222044683093812278888477247876051063075885631415084973387284228", "price": "0.86", "size": "185.71", "side": "SELL", "hash": "0c9eba80f7547c1a3d4997fd3b2ce4c14d4b6f02", "best_bid": "0.48", "best_ask": "0.62"}], "timestamp": "1769384801898", "event_type": "price_change"}}
{"_local_timestamp": "2026-01-25T23:46:42.288506+00:00", "data": {"market": "0xc7e04626fbed6834456b0b9ed45e7da039ad826933e3abba81e26e71a79b2388", "price_changes": [{"asset_id": "108633032965983853701783501560325265009339710531442379830307955199797783135140", "price": "0.71", "size": "20", "side": "BUY", "hash": "11624b65649c6bb9ee163c9b3b568d3c34f69a44", "best_bid": "0.82", "best_ask": "0.95"}, {"asset_id": "20915970858057867358422412033597169312902618738489336824716408730559800805214", "price": "0.29", "size": "20", "side": "SELL", "hash": "7185a1d4a57061d38cfe6dd7bd5c2ba0433897e5", "best_bid": "0.05", "best_ask": "0.18"}], "timestamp": "1769384801915", "event_type": "price_change"}}
{"_local_timestamp": "2026-01-25T23:46:42.289397+00:00", "data": {"market": "0x2df8bb66d0a96661ec2a4f57b0510ca7c8e154d78d6d8f3b557478ddc34fcfae", "price_changes": [{"asset_id": "104293714017628859730042534598620180600303966146090765434616358106204241123622", "price": "0.11", "size": "454.54", "side": "BUY", "hash": "358c3ad78baed772cff6aad357811f0429628e28", "best_bid": "0.38", "best_ask": "0.52"}, {"asset_id": "34218064140411222044683093812278888477247876051063075885631415084973387284228", "price": "0.89", "size": "454.54", "side": "SELL", "hash": "18c87c2b5df9d86525743c14987bc5b2a95e4c94", "best_bid": "0.48", "best_ask": "0.62"}], "timestamp": "1769384801950", "event_type": "price_change"}}
{"_local_timestamp": "2026-01-25T23:46:42.290277+00:00", "data": {"market": "0x2df8bb66d0a96661ec2a4f57b0510ca7c8e154d78d6d8f3b557478ddc34fcfae", "price_changes": [{"asset_id": "104293714017628859730042534598620180600303966146090765434616358106204241123622", "price": "0.09", "size": "355.55", "side": "BUY", "hash": "0cd906e07f1f43119157e15e589c17c1a1eb80a7", "best_bid": "0.38", "best_ask": "0.52"}, {"asset_id": "34218064140411222044683093812278888477247876051063075885631415084973387284228", "price": "0.91", "size": "355.55", "side": "SELL", "hash": "463c0464edf88fa4dd4ea1501ccf7062aff2b2cc", "best_bid": "0.48", "best_ask": "0.62"}], "timestamp": "1769384801991", "event_type": "price_change"}}
{"_local_timestamp": "2026-01-25T23:46:42.291160+00:00", "data": {"market": "0x2df8bb66d0a96661ec2a4f57b0510ca7c8e154d78d6d8f3b557478ddc34fcfae", "price_changes": [{"asset_id": "104293714017628859730042534598620180600303966146090765434616358106204241123622", "price": "0.07", "size": "518.78", "side": "BUY", "hash": "4a03cc5f35492f4833975e133224182ed7f570a2", "best_bid": "0.38", "best_ask": "0.52"}, {"asset_id": "34218064140411222044683093812278888477247876051063075885631415084973387284228", "price": "0.93", "size": "518.78", "side": "SELL", "hash": "6f87eccd615821874f961753943e7bf72dfa7136", "best_bid": "0.48", "best_ask": "0.62"}], "timestamp": "1769384802039", "event_type": "price_change"}}
{"_local_timestamp": "2026-01-25T23:46:42.506528+00:00", "data": {"market": "0x2df8bb66d0a96661ec2a4f57b0510ca7c8e154d78d6d8f3b557478ddc34fcfae", "price_changes": [{"asset_id": "104293714017628859730042534598620180600303966146090765434616358106204241123622", "price": "0.05", "size": "1250", "side": "BUY", "hash": "68892d5a03993fcdb7aaea519def790a0a23a3d4", "best_bid": "0.38", "best_ask": "0.52"}, {"asset_id": "34218064140411222044683093812278888477247876051063075885631415084973387284228", "price": "0.95", "size": "1250", "side": "SELL", "hash": "9cecafff532c4354c412edafe05f88fc13f4aa08", "best_bid": "0.48", "best_ask": "0.62"}], "timestamp": "1769384802080", "event_type": "price_change"}}
{"_local_timestamp": "2026-01-25T23:46:44.505703+00:00", "data": {"market": "0x2df8bb66d0a96661ec2a4f57b0510ca7c8e154d78d6d8f3b557478ddc34fcfae", "price_changes": [{"asset_id": "104293714017628859730042534598620180600303966146090765434616358106204241123622", "price": "0.13", "size": "8.79", "side": "BUY", "hash": "34be6f9acfce08abeec800cdd2b25fe6a91cf5cd", "best_bid": "0.38", "best_ask": "0.52"}, {"asset_id": "34218064140411222044683093812278888477247876051063075885631415084973387284228", "price": "0.87", "size": "8.79", "side": "SELL", "hash": "9835c7f0d681cea30654fd04945684582d30fe01", "best_bid": "0.48", "best_ask": "0.62"}], "timestamp": "1769384804441", "event_type": "price_change"}}
{"_local_timestamp": "2026-01-25T23:46:50.820936+00:00", "data": {"market": "0x33315bd63d0cc17257c5d7524e5283639a5e17c6ce030d937f135aab02170c40", "price_changes": [{"asset_id": "92512666728361163935047824440150917945153592049030110328840756457871300635229", "price": "0.13", "size": "261.53", "side": "BUY", "hash": "33dc2b610def4b5706cfa5274da2c53c2b12e403", "best_bid": "0.8", "best_ask": "0.89"}, {"asset_id": "109227307115212040009558734329420624109955456904374090651494287022030420438197", "price": "0.87", "size": "261.53", "side": "SELL", "hash": "35780e55f173f5a7afccc0bc0681ac48cd9ca3e4", "best_bid": "0.11", "best_ask": "0.2"}], "timestamp": "1769384810652", "event_type": "price_change"}}
{"_local_timestamp": "2026-01-25T23:46:50.822067+00:00", "data": {"market": "0xb3c09b93dc7b394fbea2b169b54da525c5d6de9ad5caf56da920058e7b74f161", "price_changes": [{"asset_id": "39663779628084842897937886547518878184317206079104235500705380518100175496233", "price": "0.23", "size": "113.04", "side": "BUY", "hash": "51e9cbdd4ab4588e0f1256c1b7195e6592aff349", "best_bid": "0.75", "best_ask": "0.89"}, {"asset_id": "100335878774855355346358755214398113208570878540440188453565903904895328912285", "price": "0.77", "size": "113.04", "side": "SELL", "hash": "0e869fbb6dac4c38acfa86fcc81ae7b41f728f20", "best_bid": "0.11", "best_ask": "0.25"}], "timestamp": "1769384810652", "event_type": "price_change"}}
{"_local_timestamp": "2026-01-25T23:46:50.822990+00:00", "data": {"market": "0x33315bd63d0cc17257c5d7524e5283639a5e17c6ce030d937f135aab02170c40", "price_changes": [{"asset_id": "92512666728361163935047824440150917945153592049030110328840756457871300635229", "price": "0.22", "size": "127.27", "side": "BUY", "hash": "33dc2b610def4b5706cfa5274da2c53c2b12e403", "best_bid": "0.8", "best_ask": "0.89"}, {"asset_id": "109227307115212040009558734329420624109955456904374090651494287022030420438197", "price": "0.78", "size": "127.27", "side": "SELL", "hash": "35780e55f173f5a7afccc0bc0681ac48cd9ca3e4", "best_bid": "0.11", "best_ask": "0.2"}], "timestamp": "1769384810652", "event_type": "price_change"}}
{"_local_timestamp": "2026-01-25T23:46:50.823894+00:00", "data": {"market": "0xb3c09b93dc7b394fbea2b169b54da525c5d6de9ad5caf56da920058e7b74f161", "price_changes": [{"asset_id": "39663779628084842897937886547518878184317206079104235500705380518100175496233", "price": "0.19", "size": "162.36", "side": "BUY", "hash": "51e9cbdd4ab4588e0f1256c1b7195e6592aff349", "best_bid": "0.75", "best_ask": "0.89"}, {"asset_id": "100335878774855355346358755214398113208570878540440188453565903904895328912285", "price": "0.81", "size": "162.36", "side": "SELL", "hash": "0e869fbb6dac4c38acfa86fcc81ae7b41f728f20", "best_bid": "0.11", "best_ask": "0.25"}], "timestamp": "1769384810652", "event_type": "price_change"}}
{"_local_timestamp": "2026-01-25T23:46:50.824778+00:00", "data": {"market": "0x33315bd63d0cc17257c5d7524e5283639a5e17c6ce030d937f135aab02170c40", "price_changes": [{"asset_id": "92512666728361163935047824440150917945153592049030110328840756457871300635229", "price": "0.18", "size": "177.77", "side": "BUY", "hash": "33dc2b610def4b5706cfa5274da2c53c2b12e403", "best_bid": "0.8", "best_ask": "0.89"}, {"asset_id": "109227307115212040009558734329420624109955456904374090651494287022030420438197", "price": "0.82", "size": "177.77", "side": "SELL", "hash": "35780e55f173f5a7afccc0bc0681ac48cd9ca3e4", "best_bid": "0.11", "best_ask": "0.2"}], "timestamp": "1769384810652", "event_type": "price_change"}}
