{"_local_timestamp": "2026-01-25T23:33:47.212559+00:00", "data": [{"market": "0xc114f4fc118df768372c3604e92d404c7c95ab6b25ada140c77dee976a890777", "asset_id": "114016092226346692646025674182722281295722777137086779627843163223516672173339", "timestamp": "1769383992494", "hash": "9a40b54472fdddc3238c214e8fcc59702610d557", "bids": [{"price": "0.01", "size": "2105.81"}, {"price": "0.02", "size": "1007.09"}, {"price": "0.03", "size": "300"}, {"price": "0.04", "size": "356.46"}, {"price": "0.05", "size": "330"}, {"price": "0.06", "size": "199.66"}, {"price": "0.07", "size": "6.11"}, {"price": "0.08", "size": "25"}, {"price": "0.12", "size": "62"}, {"price": "0.13", "size": "8.56"}, {"price": "0.2", "size": "66.66"}, {"price": "0.21", "size": "25"}, {"price": "0.23", "size": "10"}, {"price": "0.25", "size": "25"}, {"price": "0.26", "size": "25"}, {"price": "0.27", "size": "20"}, {"price": "0.35", "size": "66.66"}], "asks": [{"price": "0.99", "size": "178.09"}, {"price": "0.98", "size": "100"}, {"price": "0.95", "size": "87"}, {"price": "0.88", "size": "66.66"}, {"price": "0.77", "size": "50"}, {"price": "0.76", "size": "66.66"}], "event_type": "book", "last_trade_price": ""}, {"market": "0x11912cb7cc6561870be58a6a52be2943f3e86d2395032f064ef3091d6901882d", "asset_id": "25107464912227300161765664477112846497546753335497087400297930691126705811916", "timestamp": "1769384020532", "hash": "c51f1ec81950139618a321cdd9e10ec720d6786e", "bids": [{"price": "0.01", "size": "185.94"}, {"price": "0.02", "size": "100"}, {"price": "0.03", "size": "50"}, {"price": "0.04", "size": "6.43"}, {"price": "0.07", "size": "66.66"}, {"price": "0.13", "size": "73.32"}], "asks": [{"price": "0.99", "size": "2172.14"}, {"price": "0.98", "size": "1008.46"}, {"price": "0.97", "size": "300"}, {"price": "0.96", "size": "355.87"}, {"price": "0.95", "size": "130"}, {"price": "0.94", "size": "33"}, {"price": "0.93", "size": "7.5"}, {"price": "0.88", "size": "15"}, {"price": "0.85", "size": "66.66"}, {"price": "0.84", "size": "10"}, {"price": "0.82", "size": "5.64"}, {"price": "0.78", "size": "25"}, {"price": "0.74", "size": "32"}, {"price": "0.72", "size": "25"}, {"price": "0.7", "size": "66.66"}, {"price": "0.69", "size": "20"}], "event_type": "book", "last_trade_price": ""}, {"market": "0x11912cb7cc6561870be58a6a52be2943f3e86d2395032f064ef3091d6901882d", "asset_id": "50369611503686433705495168228906407585201475093386767089387389512232179527221", "timestamp": "1769384020532", "hash": "575d2e4e8d6f2e4749966bbfbe0903673299ca8c", "bids": [{"price": "0.01", "size": "2172.14"}, {"price": "0.02", "size": "1008.46"}, {"price": "0.03", "size": "300"}, {"price": "0.04", "size": "355.87"}, {"price": "0.05", "size": "130"}, {"price": "0.06", "size": "33"}, {"price": "0.07", "size": "7.5"}, {"price": "0.12", "size": "15"}, {"price": "0.15", "size": "66.66"}, {"price": "0.16", "size": "10"}, {"price": "0.18", "size": "5.64"}, {"price": "0.22", "size": "25"}, {"price": "0.26", "size": "32"}, {"price": "0.28", "size": "25"}, {"price": "0.3", "size": "66.66"}, {"price": "0.31", "size": "20"}], "asks": [{"price": "0.99", "size": "185.94"}, {"price": "0.98", "size": "100"}, {"price": "0.97", "size": "50"}, {"price": "0.96", "size": "6.43"}, {"price": "0.93", "size": "66.66"}, {"price": "0.87", "size": "73.32"}], "event_type": "book", "last_trade_price": ""}, {"market": "0xf6d98f9984cbd7994c5ad4b44b57e6e65771833e1f682cb6c08e1881cba0be23", "asset_id": "14133747134142323771619199606203638420186745480544687065966512009432569296940", "timestamp": "1769383991745", "hash": "8ac034a1a3d6ddf9f595e25e562bc3fd05dd504c", "bids": [{"price": "0.01", "size": "171.66"}, {"price": "0.02", "size": "5.82"}, {"price": "0.03", "size": "66"}, {"price": "0.04", "size": "40.09"}, {"price": "0.06", "size": "66.66"}, {"price": "0.12", "size": "73.32"}], "asks": [{"price": "0.99", "size": "3205.92"}, {"price": "0.98", "size": "1006.59"}, {"price": "0.97", "size": "300"}, {"price": "0.96", "size": "356"}, {"price": "0.95", "size": "230"}, {"price": "0.94", "size": "133"}, {"price": "0.93", "size": "100"}, {"price": "0.92", "size": "6.56"}, {"price": "0.91", "size": "15"}, {"price": "0.83", "size": "50"}, {"price": "0.82", "size": "5.8"}, {"price": "0.76", "size": "100"}, {"price": "0.74", "size": "50"}, {"price": "0.73", "size": "10"}, {"price": "0.72", "size": "20"}, {"price": "0.54", "size": "5"}], "event_type": "book", "last_trade_price": ""}, {"market": "0x86fec61dd9c27294756303c47b77cf6b7ed13ff4097e2967bc333dde4c1ea4da", "asset_id": "37660683447879901945455922570375098409697520769704430824022672297921367915347", "timestamp": "1769384020091", "hash": "92922b53ba2009fd112b3dbd27c6fc13a1ad6405", "bids": [{"price": "0.01", "size": "3405.28"}, {"price": "0.02", "size": "1406.56"}, {"price": "0.03", "size": "200"}, {"price": "0.04", "size": "350"}, {"price": "0.05", "size": "235.5"}, {"price": "0.06", "size": "33"}, {"price": "0.07", "size": "100"}, {"price": "0.08", "size": "200"}, {"price": "0.09", "size": "105.78"}, {"price": "0.18", "size": "10.66"}, {"price": "0.19", "size": "25"}, {"price": "0.25", "size": "8"}, {"price": "0.32", "size": "150"}, {"price": "0.33", "size": "10"}, {"price": "0.34", "size": "20"}, {"price": "0.55", "size": "9.09"}], "asks": [{"price": "0.99", "size": "185.71"}, {"price": "0.98", "size": "112.97"}, {"price": "0.97", "size": "122.66"}, {"price": "0.94", "size": "83.26"}], "event_type": "book", "last_trade_price": ""}, {"market": "0xf6d98f9984cbd7994c5ad4b44b57e6e65771833e1f682cb6c08e1881cba0be23", "asset_id": "111619066987530654938781515834745418625505306643795368186113638707368057832687", "timestamp": "1769383991745", "hash": "468c1ed4253c897c4726d474a358ce1bddeffcc1", "bids": [{"price": "0.01", "size": "3205.92"}, {"price": "0.02", "size": "1006.59"}, {"price": "0.03", "size": "300"}, {"price": "0.04", "size": "356"}, {"price": "0.05", "size": "230"}, {"price": "0.06", "size": "133"}, {"price": "0.07", "size": "100"}, {"price": "0.08", "size": "6.56"}, {"price": "0.09", "size": "15"}, {"price": "0.17", "size": "50"}, {"price": "0.18", "size": "5.8"}, {"price": "0.24", "size": "100"}, {"price": "0.26", "size": "50"}, {"price": "0.27", "size": "10"}, {"price": "0.28", "size": "20"}, {"price": "0.46", "size": "5"}], "asks": [{"price": "0.99", "size": "171.66"}, {"price": "0.98", "size": "5.82"}, {"price": "0.97", "size": "66"}, {"price": "0.96", "size": "40.09"}, {"price": "0.94", "size": "66.66"}, {"price": "0.88", "size": "73.32"}], "event_type": "book", "last_trade_price": ""}, {"market": "0xb5f61d0c9ce431d64ba702815984246fa9cd6c2d6399849f0051d8695f2d98ab", "asset_id": "81582701062623199779039420976989567002417039977161919375131982089037196418005", "timestamp": "1769384020091", "hash": "568b82fe6c20297445bb812c84d5001ff5fbee26", "bids": [{"price": "0.01", "size": "185.72"}, {"price": "0.02", "size": "112.97"}, {"price": "0.03", "size": "122.66"}, {"price": "0.06", "size": "126.66"}], "asks": [{"price": "0.99", "size": "3406.33"}, {"price": "0.98", "size": "1406.63"}, {"price": "0.97", "size": "200"}, {"price": "0.96", "size": "350"}, {"price": "0.95", "size": "235.51"}, {"price": "0.94", "size": "133"}, {"price": "0.93", "size": "100"}, {"price": "0.92", "size": "100"}, {"price": "0.91", "size": "105.61"}, {"price": "0.83", "size": "11"}, {"price": "0.82", "size": "5.68"}, {"price": "0.81", "size": "15"}, {"price": "0.78", "size": "50"}, {"price": "0.77", "size": "10"}, {"price": "0.76", "size": "45"}, {"price": "0.71", "size": "10"}, {"price": "0.68", "size": "100"}, {"price": "0.67", "size": "20"}, {"price": "0.45", "size": "9.09"}], "event_type": "book", "last_trade_price": ""}, {"market": "0xb5f61d0c9ce431d64ba702815984246fa9cd6c2d6399849f0051d8695f2d98ab", "asset_id": "98590289222817581558553345992202318138659660940538324229915000516905381167250", "timestamp": "1769384020091", "hash": "425fc8363e37c63e408a243e07633ab5270398e6", "bids": [{"price": "0.01", "size": "3406.33"}, {"price": "0.02", "size": "1406.63"}, {"price": "0.03", "size": "200"}, {"price": "0.04", "size": "350"}, {"price": "0.05", "size": "235.51"}, {"price": "0.06", "size": "133"}, {"price": "0.07", "size": "100"}, {"price": "0.08", "size": "100"}, {"price": "0.09", "size": "105.61"}, {"price": "0.17", "size": "11"}, {"price": "0.18", "size": "5.68"}, {"price": "0.19", "size": "15"}, {"price": "0.22", "size": "50"}, {"price": "0.23", "size": "10"}, {"price": "0.24", "size": "45"}, {"price": "0.29", "size": "10"}, {"price": "0.32", "size": "100"}, {"price": "0.33", "size": "20"}, {"price": "0.55", "size": "9.09"}], "asks": [{"price": "0.99", "size": "185.72"}, {"price": "0.98", "size": "112.97"}, {"price": "0.97", "size": "122.66"}, {"price": "0.94", "size": "126.66"}], "event_type": "book", "last_trade_price": ""}, {"market": "0xc114f4fc118df768372c3604e92d404c7c95ab6b25ada140c77dee976a890777", "asset_id": "95497640963223955548410937239974920841410215692686671066528121763996154872565", "timestamp": "1769383992494", "hash": "a88c1de87ae72f2c503ef64951fca351d86c779a", "bids": [{"price": "0.01", "size": "178.09"}, {"price": "0.02", "size": "100"}, {"price": "0.05", "size": "87"}, {"price": "0.12", "size": "66.66"}, {"price": "0.23", "size": "50"}, {"price": "0.24", "size": "66.66"}], "asks": [{"price": "0.99", "size": "2105.81"}, {"price": "0.98", "size": "1007.09"}, {"price": "0.97", "size": "300"}, {"price": "0.96", "size": "356.46"}, {"price": "0.95", "size": "330"}, {"price": "0.94", "size": "199.66"}, {"price": "0.93", "size": "6.11"}, {"price": "0.92", "size": "25"}, {"price": "0.88", "size": "62"}, {"price": "0.87", "size": "8.56"}, {"price": "0.8", "size": "66.66"}, {"price": "0.79", "size": "25"}, {"price": "0.77", "size": "10"}, {"price": "0.75", "size": "25"}, {"price": "0.74", "size": "25"}, {"price": "0.73", "size": "20"}, {"price": "0.65", "size": "66.66"}], "event_type": "book", "last_trade_price": ""}, {"market": "0x86fec61dd9c27294756303c47b77cf6b7ed13ff4097e2967bc333dde4c1ea4da", "asset_id": "63898934961262618957913174161832335092659130397470681441362226870577487706450", "timestamp": "1769384020091", "hash": "ebc2bdd99f037bfa174815dd643cb94ffe3ac160", "bids": [{"price": "0.01", "size": "185.71"}, {"price": "0.02", "size": "112.97"}, {"price": "0.03", "size": "122.66"}, {"price": "0.06", "size": "83.26"}], "asks": [{"price": "0.99", "size": "3405.28"}, {"price": "0.98", "size": "1406.56"}, {"price": "0.97", "size": "200"}, {"price": "0.96", "size": "350"}, {"price": "0.95", "size": "235.5"}, {"price": "0.94", "size": "33"}, {"price": "0.93", "size": "100"}, {"price": "0.92", "size": "200"}, {"price": "0.91", "size": "105.78"}, {"price": "0.82", "size": "10.66"}, {"price": "0.81", "size": "25"}, {"price": "0.75", "size": "8"}, {"price": "0.68", "size": "150"}, {"price": "0.67", "size": "10"}, {"price": "0.66", "size": "20"}, {"price": "0.45", "size": "9.09"}], "event_type": "book", "last_trade_price": ""}]}
{"_local_timestamp": "2026-01-25T23:33:49.654756+00:00", "data": {"market": "0xb5f61d0c9ce431d64ba702815984246fa9cd6c2d6399849f0051d8695f2d98ab", "price_changes": [{"asset_id": "98590289222817581558553345992202318138659660940538324229915000516905381167250", "price": "0.55", "size": "0", "side": "BUY", "hash": "957a8c2fb5d0fcbf02174977e57923bc26fce01c", "best_bid": "0.33", "best_ask": "0.94"}, {"asset_id": "81582701062623199779039420976989567002417039977161919375131982089037196418005", "price": "0.45", "size": "0", "side": "SELL", "hash": "e6efa99316ef7a6814890e70fc42e8c6706b9760", "best_bid": "0.06", "best_ask": "0.67"}], "timestamp": "1769384029589", "event_type": "price_change"}}
{"_local_timestamp": "2026-01-25T23:33:49.701853+00:00", "data": {"market": "0x86fec61dd9c27294756303c47b77cf6b7ed13ff4097e2967bc333dde4c1ea4da", "price_changes": [{"asset_id": "37660683447879901945455922570375098409697520769704430824022672297921367915347", "price": "0.55", "size": "0", "side": "BUY", "hash": "e95a495696f9a5410b4d702e52127a90acdd4a06", "best_bid": "0.34", "best_ask": "0.94"}, {"asset_id": "63898934961262618957913174161832335092659130397470681441362226870577487706450", "price": "0.45", "size": "0", "side": "SELL", "hash": "5c87096b77e95d8f88b805cb50b8c2f25c38c89c", "best_bid": "0.06", "best_ask": "0.66"}], "timestamp": "1769384029627", "event_type": "price_change"}}
{"_local_timestamp": "2026-01-25T23:34:04.651526+00:00", "data": {"market": "0x86fec61dd9c27294756303c47b77cf6b7ed13ff4097e2967bc333dde4c1ea4da", "price_changes": [{"asset_id": "37660683447879901945455922570375098409697520769704430824022672297921367915347", "price": "0.8", "size": "50", "side": "BUY", "hash": "41136237b358646ae1a2c71c16ef72d708b1619f", "best_bid": "0.8", "best_ask": "0.94"}, {"asset_id": "63898934961262618957913174161832335092659130397470681441362226870577487706450", "price": "0.2", "size": "50", "side": "SELL", "hash": "976ae77d5965609ec9c6139290ac1c64fb35421e", "best_bid": "0.06", "best_ask": "0.2"}], "timestamp": "1769384044570", "event_type": "price_change"}}
{"_local_timestamp": "2026-01-25T23:34:04.652388+00:00", "data": {"market": "0xf6d98f9984cbd7994c5ad4b44b57e6e65771833e1f682cb6c08e1881cba0be23", "price_changes": [{"asset_id": "111619066987530654938781515834745418625505306643795368186113638707368057832687", "price": "0.72", "size": "50", "side": "BUY", "hash": "2117e780a7d933b1d1061dbe6667769ace8f169d", "best_bid": "0.72", "best_ask": "0.88"}, {"asset_id": "14133747134142323771619199606203638420186745480544687065966512009432569296940", "price": "0.28", "size": "50", "side": "SELL", "hash": "7189ed64021a397100e481e5b9ac3901f344e72c", "best_bid": "0.12", "best_ask": "0.28"}], "timestamp": "1769384044570", "event_type": "price_change"}}
{"_local_timestamp": "2026-01-25T23:34:04.654311+00:00", "data": {"market": "0x11912cb7cc6561870be58a6a52be2943f3e86d2395032f064ef3091d6901882d", "price_changes": [{"asset_id": "50369611503686433705495168228906407585201475093386767089387389512232179527221", "price": "0.75", "size": "50", "side": "BUY", "hash": "85ac9e16e87728e1b09e809619b3e31847589679", "best_bid": "0.75", "best_ask": "0.87"}, {"asset_id": "25107464912227300161765664477112846497546753335497087400297930691126705811916", "price": "0.25", "size": "50", "side": "SELL", "hash": "44596074b1138be3a01a8eb784e882e60c3424c4", "best_bid": "0.13", "best_ask": "0.25"}], "timestamp": "1769384044570", "event_type": "price_change"}}
{"_local_timestamp": "2026-01-25T23:34:04.654634+00:00", "data": {"market": "0xc114f4fc118df768372c3604e92d404c7c95ab6b25ada140c77dee976a890777", "price_changes": [{"asset_id": "114016092226346692646025674182722281295722777137086779627843163223516672173339", "price": "0.58", "size": "50", "side": "BUY", "hash": "59c063e41cc863b8b73b5633f9c2bfa5c2bc59fc", "best_bid": "0.58", "best_ask": "0.76"}, {"asset_id": "95497640963223955548410937239974920841410215692686671066528121763996154872565", "price": "0.42", "size": "50", "side": "SELL", "hash": "24a02833adc9888fa64956139e6f05c64d91d8ea", "best_bid": "0.24", "best_ask": "0.42"}], "timestamp": "1769384044570", "event_type": "price_change"}}
{"_local_timestamp": "2026-01-25T23:34:04.654929+00:00", "data": {"market": "0xb5f61d0c9ce431d64ba702815984246fa9cd6c2d6399849f0051d8695f2d98ab", "price_changes": [{"asset_id": "98590289222817581558553345992202318138659660940538324229915000516905381167250", "price": "0.76", "size": "50", "side": "BUY", "hash": "8214d9f4fc1a8f14b6af59db2adab96b5b2e4e6f", "best_bid": "0.76", "best_ask": "0.94"}, {"asset_id": "81582701062623199779039420976989567002417039977161919375131982089037196418005", "price": "0.24", "size": "50", "side": "SELL", "hash": "0195009d2a5c3bd2f675967d43e40f2966e13caa", "best_bid": "0.06", "best_ask": "0.24"}], "timestamp": "1769384044571", "event_type": "price_change"}}
{"_local_timestamp": "2026-01-25T23:34:12.929526+00:00", "data": {"market": "0xf6d98f9984cbd7994c5ad4b44b57e6e65771833e1f682cb6c08e1881cba0be23", "price_changes": [{"asset_id": "111619066987530654938781515834745418625505306643795368186113638707368057832687", "price": "0.06", "size": "33", "side": "BUY", "hash": "4bca1eef9f194872aadbce04096138f624b28b47", "best_bid": "0.72", "best_ask": "0.88"}, {"asset_id": "14133747134142323771619199606203638420186745480544687065966512009432569296940", "price": "0.94", "size": "33", "side": "SELL", "hash": "6320d0035e4fd4ccd97d9a7e46a82ad439cf4d0e", "best_bid": "0.12", "best_ask": "0.28"}], "timestamp": "1769384052803", "event_type": "price_change"}}
{"_local_timestamp": "2026-01-25T23:34:12.949054+00:00", "data": {"market": "0x86fec61dd9c27294756303c47b77cf6b7ed13ff4097e2967bc333dde4c1ea4da", "price_changes": [{"asset_id": "37660683447879901945455922570375098409697520769704430824022672297921367915347", "price": "0.04", "size": "250", "side": "BUY", "hash": "60cee0de9ea130219c4534790124aa03d500419f", "best_bid": "0.8", "best_ask": "0.94"}, {"asset_id": "63898934961262618957913174161832335092659130397470681441362226870577487706450", "price": "0.96", "size": "250", "side": "SELL", "hash": "fc7fe0181e50faecbb1272c8d30679612a4e418a", "best_bid": "0.06", "best_ask": "0.2"}], "timestamp": "1769384052803", "event_type": "price_change"}}
{"_local_timestamp": "2026-01-25T23:34:13.118169+00:00", "data": {"market": "0x86fec61dd9c27294756303c47b77cf6b7ed13ff4097e2967bc333dde4c1ea4da", "price_changes": [{"asset_id": "37660683447879901945455922570375098409697520769704430824022672297921367915347", "price": "0.19", "size": "15", "side": "BUY", "hash": "5bb1a3097d98ad1ea76bcc0c55d9c3051888bac6", "best_bid": "0.8", "best_ask": "0.94"}, {"asset_id": "63898934961262618957913174161832335092659130397470681441362226870577487706450", "price": "0.81", "size": "15", "side": "SELL", "hash": "523e96b011185c868328a2814a4a2e5cb843ba5c", "best_bid": "0.06", "best_ask": "0.2"}], "timestamp": "1769384052999", "event_type": "price_change"}}
{"_local_timestamp": "2026-01-25T23:34:13.382549+00:00", "data": {"market": "0xf6d98f9984cbd7994c5ad4b44b57e6e65771833e1f682cb6c08e1881cba0be23", "price_changes": [{"asset_id": "111619066987530654938781515834745418625505306643795368186113638707368057832687", "price": "0.05", "size": "330", "side": "BUY", "hash": "7f02ccfd35668ee42346bc0d98d5e5b2ca05f5b6", "best_bid": "0.72", "best_ask": "0.88"}, {"asset_id": "14133747134142323771619199606203638420186745480544687065966512009432569296940", "price": "0.95", "size": "330", "side": "SELL", "hash": "acfc3d9e5eb5b98b16df963cce7b3aeaa395a5ec", "best_bid": "0.12", "best_ask": "0.28"}], "timestamp": "1769384053264", "event_type": "price_change"}}
{"_local_timestamp": "2026-01-25T23:34:13.383139+00:00", "data": {"market": "0x11912cb7cc6561870be58a6a52be2943f3e86d2395032f064ef3091d6901882d", "price_changes": [{"asset_id": "50369611503686433705495168228906407585201475093386767089387389512232179527221", "price": "0.05", "size": "230", "side": "BUY", "hash": "f125864736a0bb81c0d15f4fca646e8721a499e5", "best_bid": "0.75", "best_ask": "0.87"}, {"asset_id": "25107464912227300161765664477112846497546753335497087400297930691126705811916", "price": "0.95", "size": "230", "side": "SELL", "hash": "e5e02c707cbe687d18521b7257a93107d1f9509b", "best_bid": "0.13", "best_ask": "0.25"}], "timestamp": "1769384053266", "event_type": "price_change"}}
{"_local_timestamp": "2026-01-25T23:34:13.411063+00:00", "data": {"market": "0x86fec61dd9c27294756303c47b77cf6b7ed13ff4097e2967bc333dde4c1ea4da", "price_changes": [{"asset_id": "37660683447879901945455922570375098409697520769704430824022672297921367915347", "price": "0.03", "size": "300", "side": "BUY", "hash": "5b8b2efe6460bac23da34469e3246135e688dd8a", "best_bid": "0.8", "best_ask": "0.94"}, {"asset_id": "63898934961262618957913174161832335092659130397470681441362226870577487706450", "price": "0.97", "size": "300", "side": "SELL", "hash": "7891c6c88bcfc4df6b2aaa8c5424cfe2a58f3649", "best_bid": "0.06", "best_ask": "0.2"}], "timestamp": "1769384053270", "event_type": "price_change"}}
{"_local_timestamp": "2026-01-25T23:34:28.375358+00:00", "data": {"market": "0xf6d98f9984cbd7994c5ad4b44b57e6e65771833e1f682cb6c08e1881cba0be23", "price_changes": [{"asset_id": "111619066987530654938781515834745418625505306643795368186113638707368057832687", "price": "0.01", "size": "3505.92", "side": "BUY", "hash": "43c41ec54c327283ae51140b862264313240873d", "best_bid": "0.72", "best_ask": "0.88"}, {"asset_id": "14133747134142323771619199606203638420186745480544687065966512009432569296940", "price": "0.99", "size": "3505.92", "side": "SELL", "hash": "d83e2d2f67d9b0b45a0a53a2c0ce2b2540e1b629", "best_bid": "0.12", "best_ask": "0.28"}], "timestamp": "1769384068094", "event_type": "price_change"}}
{"_local_timestamp": "2026-01-25T23:34:28.901405+00:00", "data": {"market": "0x86fec61dd9c27294756303c47b77cf6b7ed13ff4097e2967bc333dde4c1ea4da", "price_changes": [{"asset_id": "37660683447879901945455922570375098409697520769704430824022672297921367915347", "price": "0.19", "size": "0", "side": "BUY", "hash": "cf0782126abd3d1dbdc584da0c23e390ccb84f2c", "best_bid": "0.8", "best_ask": "0.94"}, {"asset_id": "63898934961262618957913174161832335092659130397470681441362226870577487706450", "price": "0.81", "size": "0", "side": "SELL", "hash": "558c0c4fd4254f3e24d8c6dabf17829a074e8e79", "best_bid": "0.06", "best_ask": "0.2"}], "timestamp": "1769384068482", "event_type": "price_change"}}
{"_local_timestamp": "2026-01-25T23:34:29.119374+00:00", "data": {"market": "0x86fec61dd9c27294756303c47b77cf6b7ed13ff4097e2967bc333dde4c1ea4da", "price_changes": [{"asset_id": "37660683447879901945455922570375098409697520769704430824022672297921367915347", "price": "0.35", "size": "15", "side": "BUY", "hash": "1b15ac9717cb543f4d75f422711fd453e33572dc", "best_bid": "0.8", "best_ask": "0.94"}, {"asset_id": "63898934961262618957913174161832335092659130397470681441362226870577487706450", "price": "0.65", "size": "15", "side": "SELL", "hash": "05ab6b083553682d1768c3a2a697220ff76e1aca", "best_bid": "0.06", "best_ask": "0.2"}], "timestamp": "1769384068870", "event_type": "price_change"}}
{"_local_timestamp": "2026-01-25T23:34:29.120105+00:00", "data": {"market": "0x86fec61dd9c27294756303c47b77cf6b7ed13ff4097e2967bc333dde4c1ea4da", "price_changes": [{"asset_id": "37660683447879901945455922570375098409697520769704430824022672297921367915347", "price": "0.35", "size": "25", "side": "BUY", "hash": "4ea2ca91b831a035d86854ae525ceb7ec36bddcf", "best_bid": "0.8", "best_ask": "0.94"}, {"asset_id": "63898934961262618957913174161832335092659130397470681441362226870577487706450", "price": "0.65", "size": "25", "side": "SELL", "hash": "f8f1ba0c19626cb091b38a0c0f6f7f310f7c0157", "best_bid": "0.06", "best_ask": "0.2"}], "timestamp": "1769384068871", "event_type": "price_change"}}
{"_local_timestamp": "2026-01-25T23:34:29.525048+00:00", "data": {"market": "0x86fec61dd9c27294756303c47b77cf6b7ed13ff4097e2967bc333dde4c1ea4da", "price_changes": [{"asset_id": "37660683447879901945455922570375098409697520769704430824022672297921367915347", "price": "0.34", "size": "0", "side": "BUY", "hash": "9b95d76579b27232101a2eb28047fdd37de3b2e7", "best_bid": "0.8", "best_ask": "0.94"}, {"asset_id": "63898934961262618957913174161832335092659130397470681441362226870577487706450", "price": "0.66", "size": "0", "side": "SELL", "hash": "00643f9b118826f3c11c9b50837348f4904f0b1b", "best_bid": "0.06", "best_ask": "0.2"}], "timestamp": "1769384069456", "event_type": "price_change"}}
{"_local_timestamp": "2026-01-25T23:34:29.564032+00:00", "data": {"market": "0x86fec61dd9c27294756303c47b77cf6b7ed13ff4097e2967bc333dde4c1ea4da", "price_changes": [{"asset_id": "37660683447879901945455922570375098409697520769704430824022672297921367915347", "price": "0.36", "size": "20", "side": "BUY", "hash": "283c66f9af9a3f06245d5aa796d98d8154f49f68", "best_bid": "0.8", "best_ask": "0.94"}, {"asset_id": "63898934961262618957913174161832335092659130397470681441362226870577487706450", "price": "0.64", "size": "20", "side": "SELL", "hash": "9b73e0be91d01eb27d3a5c9807980c616d892d18", "best_bid": "0.06", "best_ask": "0.2"}], "timestamp": "1769384069482", "event_type": "price_change"}}
{"_local_timestamp": "2026-01-25T23:34:54.648278+00:00", "data": {"market": "0xb5f61d0c9ce431d64ba702815984246fa9cd6c2d6399849f0051d8695f2d98ab", "price_changes": [{"asset_id": "98590289222817581558553345992202318138659660940538324229915000516905381167250", "price": "0.06", "size": "33", "side": "BUY", "hash": "03710e57428948f108fe59e20eb052a3ba9af607", "best_bid": "0.76", "best_ask": "0.94"}, {"asset_id": "81582701062623199779039420976989567002417039977161919375131982089037196418005", "price": "0.94", "size": "33", "side": "SELL", "hash": "a1c84517dc4f8d182b5a7f7bade950f8fc29e081", "best_bid": "0.06", "best_ask": "0.24"}], "timestamp": "1769384094555", "event_type": "price_change"}}
{"_local_timestamp": "2026-01-25T23:34:54.993081+00:00", "data": {"market": "0xb5f61d0c9ce431d64ba702815984246fa9cd6c2d6399849f0051d8695f2d98ab", "price_changes": [{"asset_id": "98590289222817581558553345992202318138659660940538324229915000516905381167250", "price": "0.05", "size": "335.51", "side": "BUY", "hash": "2071c1f4450a086afba1efd14f43f8ad00ec6b09", "best_bid": "0.76", "best_ask": "0.94"}, {"asset_id": "81582701062623199779039420976989567002417039977161919375131982089037196418005", "price": "0.95", "size": "335.51", "side": "SELL", "hash": "d802fa1069f5e2c940a4adc255af8acf3599a4a9", "best_bid": "0.06", "best_ask": "0.24"}], "timestamp": "1769384094893", "event_type": "price_change"}}
{"_local_timestamp": "2026-01-25T23:35:39.409273+00:00", "data": {"market": "0xc114f4fc118df768372c3604e92d404c7c95ab6b25ada140c77dee976a890777", "price_changes": [{"asset_id": "114016092226346692646025674182722281295722777137086779627843163223516672173339", "price": "0.01", "size": "3105.81", "side": "BUY", "hash": "90dc52079ec2bc398754b32d65d499cd62dcd307", "best_bid": "0.58", "best_ask": "0.76"}, {"asset_id": "95497640963223955548410937239974920841410215692686671066528121763996154872565", "price": "0.99", "size": "3105.81", "side": "SELL", "hash": "ad2eda049fc9a41ea728c19ddff1873e6b1ef921", "best_bid": "0.24", "best_ask": "0.42"}], "timestamp": "1769384139299", "event_type": "price_change"}}
{"_local_timestamp": "2026-01-25T23:35:39.412928+00:00", "data": {"market": "0x11912cb7cc6561870be58a6a52be2943f3e86d2395032f064ef3091d6901882d", "price_changes": [{"asset_id": "50369611503686433705495168228906407585201475093386767089387389512232179527221", "price": "0.01", "size": "3172.14", "side": "BUY", "hash": "0d3413107fa8bbe2569ed9d8c96f76a30606bd55", "best_bid": "0.75", "best_ask": "0.87"}, {"asset_id": "25107464912227300161765664477112846497546753335497087400297930691126705811916", "price": "0.99", "size": "3172.14", "side": "SELL", "hash": "fe63d43b822498e947b64d43e5d569f27c7829bb", "best_bid": "0.13", "best_ask": "0.25"}], "timestamp": "1769384139299", "event_type": "price_change"}}
{"_local_timestamp": "2026-01-25T23:35:39.416858+00:00", "data": {"market": "0xc114f4fc118df768372c3604e92d404c7c95ab6b25ada140c77dee976a890777", "price_changes": [{"asset_id": "114016092226346692646025674182722281295722777137086779627843163223516672173339", "price": "0.02", "size": "1407.09", "side": "BUY", "hash": "c0fb15552b85f6dd3abac720bc55a93fb54d9806", "best_bid": "0.58", "best_ask": "0.76"}, {"asset_id": "95497640963223955548410937239974920841410215692686671066528121763996154872565", "price": "0.98", "size": "1407.09", "side": "SELL", "hash": "835b239fd9a106d55f8a3dbee1c2eed34739264b", "best_bid": "0.24", "best_ask": "0.42"}], "timestamp": "1769384139313", "event_type": "price_change"}}
{"_local_timestamp": "2026-01-25T23:35:39.417305+00:00", "data": {"market": "0x11912cb7cc6561870be58a6a52be2943f3e86d2395032f064ef3091d6901882d", "price_changes": [{"asset_id": "50369611503686433705495168228906407585201475093386767089387389512232179527221", "price": "0.02", "size": "1408.46", "side": "BUY", "hash": "a0dfaa1b6458c989ff1d6757c696b162b6c7ff41", "best_bid": "0.75", "best_ask": "0.87"}, {"asset_id": "25107464912227300161765664477112846497546753335497087400297930691126705811916", "price": "0.98", "size": "1408.46", "side": "SELL", "hash": "ce55151e869d66f88d54b5a99f9e03e8e6566ec7", "best_bid": "0.13", "best_ask": "0.25"}], "timestamp": "1769384139314", "event_type": "price_change"}}
{"_local_timestamp": "2026-01-25T23:35:39.494429+00:00", "data": {"market": "0xc114f4fc118df768372c3604e92d404c7c95ab6b25ada140c77dee976a890777", "price_changes": [{"asset_id": "114016092226346692646025674182722281295722777137086779627843163223516672173339", "price": "0.21", "size": "15", "side": "BUY", "hash": "4d288b34f28d8d961e9669bc6984957de6dc4cc0", "best_bid": "0.58", "best_ask": "0.76"}, {"asset_id": "95497640963223955548410937239974920841410215692686671066528121763996154872565", "price": "0.79", "size": "15", "side": "SELL", "hash": "f72620f426eadf502327ccb30af7e01e22e57690", "best_bid": "0.24", "best_ask": "0.42"}], "timestamp": "1769384139428", "event_type": "price_change"}}
{"_local_timestamp": "2026-01-25T23:35:39.494776+00:00", "data": {"market": "0x11912cb7cc6561870be58a6a52be2943f3e86d2395032f064ef3091d6901882d", "price_changes": [{"asset_id": "50369611503686433705495168228906407585201475093386767089387389512232179527221", "price": "0.12", "size": "0", "side": "BUY", "hash": "6a01956acd4750e6f1c58541d1110cf8ea2b78d9", "best_bid": "0.75", "best_ask": "0.87"}, {"asset_id": "25107464912227300161765664477112846497546753335497087400297930691126705811916", "price": "0.88", "size": "0", "side": "SELL", "hash": "dd4be6252ae6465fce558dba63c4b84e2fc760f4", "best_bid": "0.13", "best_ask": "0.25"}], "timestamp": "1769384139428", "event_type": "price_change"}}
{"_local_timestamp": "2026-01-25T23:35:39.504011+00:00", "data": {"market": "0xf6d98f9984cbd7994c5ad4b44b57e6e65771833e1f682cb6c08e1881cba0be23", "price_changes": [{"asset_id": "111619066987530654938781515834745418625505306643795368186113638707368057832687", "price": "0.26", "size": "25", "side": "BUY", "hash": "3ebffda512b0ed44b060361358ab0aa402c1810b", "best_bid": "0.72", "best_ask": "0.88"}, {"asset_id": "14133747134142323771619199606203638420186745480544687065966512009432569296940", "price": "0.74", "size": "25", "side": "SELL", "hash": "d0c7e7aaab5b1eafcbb81192389de3f92ae47d1c", "best_bid": "0.12", "best_ask": "0.28"}], "timestamp": "1769384139437", "event_type": "price_change"}}
{"_local_timestamp": "2026-01-25T23:35:39.627870+00:00", "data": {"market": "0xf6d98f9984cbd7994c5ad4b44b57e6e65771833e1f682cb6c08e1881cba0be23", "price_changes": [{"asset_id": "111619066987530654938781515834745418625505306643795368186113638707368057832687", "price": "0.29", "size": "25", "side": "BUY", "hash": "c96bb4b7dddbb10ff57f37b507d24b8509421ca8", "best_bid": "0.72", "best_ask": "0.88"}, {"asset_id": "14133747134142323771619199606203638420186745480544687065966512009432569296940", "price": "0.71", "size": "25", "side": "SELL", "hash": "973540bd5c10afd8a30078744d1441ded5e0de72", "best_bid": "0.12", "best_ask": "0.28"}], "timestamp": "1769384139560", "event_type": "price_change"}}
{"_local_timestamp": "2026-01-25T23:35:39.640606+00:00", "data": {"market": "0x11912cb7cc6561870be58a6a52be2943f3e86d2395032f064ef3091d6901882d", "price_changes": [{"asset_id": "50369611503686433705495168228906407585201475093386767089387389512232179527221", "price": "0.32", "size": "10", "side": "BUY", "hash": "2e14cc8f10d2590d7834626b1ce3f7b3a5d7b20f", "best_bid": "0.75", "best_ask": "0.87"}, {"asset_id": "25107464912227300161765664477112846497546753335497087400297930691126705811916", "price": "0.68", "size": "10", "side": "SELL", "hash": "fd3005d466ae15ed67ca7f69226afc5767504a1a", "best_bid": "0.13", "best_ask": "0.25"}], "timestamp": "1769384139573", "event_type": "price_change"}}
{"_local_timestamp": "2026-01-25T23:35:39.644618+00:00", "data": {"market": "0x11912cb7cc6561870be58a6a52be2943f3e86d2395032f064ef3091d6901882d", "price_changes": [{"asset_id": "50369611503686433705495168228906407585201475093386767089387389512232179527221", "price": "0.31", "size": "35", "side": "BUY", "hash": "6395e7e1d17ea6a881a3e64c9322cff110967ed0", "best_bid": "0.75", "best_ask": "0.87"}, {"asset_id": "25107464912227300161765664477112846497546753335497087400297930691126705811916", "price": "0.69", "size": "35", "side": "SELL", "hash": "3122548ec09749fda707e2b1c41b47494affc7b5", "best_bid": "0.13", "best_ask": "0.25"}], "timestamp": "1769384139574", "event_type": "price_change"}}
{"_local_timestamp": "2026-01-25T23:35:39.680345+00:00", "data": {"market": "0x86fec61dd9c27294756303c47b77cf6b7ed13ff4097e2967bc333dde4c1ea4da", "price_changes": [{"asset_id": "37660683447879901945455922570375098409697520769704430824022672297921367915347", "price": "0.32", "size": "125", "side": "BUY", "hash": "1125a7533129e09567e3f3252800b7106620df67", "best_bid": "0.8", "best_ask": "0.94"}, {"asset_id": "63898934961262618957913174161832335092659130397470681441362226870577487706450", "price": "0.68", "size": "125", "side": "SELL", "hash": "e01c8d78adacece6001fd111e816523a62ad2589", "best_bid": "0.06", "best_ask": "0.2"}], "timestamp": "1769384139594", "event_type": "price_change"}}
{"_local_timestamp": "2026-01-25T23:35:39.681111+00:00", "data": {"market": "0xb5f61d0c9ce431d64ba702815984246fa9cd6c2d6399849f0051d8695f2d98ab", "price_changes": [{"asset_id": "98590289222817581558553345992202318138659660940538324229915000516905381167250", "price": "0.24", "size": "20", "side": "BUY", "hash": "67c1f44ac6eee0a1ba2a8c0944cf8ab2c629908f", "best_bid": "0.76", "best_ask": "0.94"}, {"asset_id": "81582701062623199779039420976989567002417039977161919375131982089037196418005", "price": "0.76", "size": "20", "side": "SELL", "hash": "77d859d67cd862fe9668277c9dbb4a388fc315b1", "best_bid": "0.06", "best_ask": "0.24"}], "timestamp": "1769384139594", "event_type": "price_change"}}
{"_local_timestamp": "2026-01-25T23:35:39.681396+00:00", "data": {"market": "0xf6d98f9984cbd7994c5ad4b44b57e6e65771833e1f682cb6c08e1881cba0be23", "price_changes": [{"asset_id": "111619066987530654938781515834745418625505306643795368186113638707368057832687", "price": "0.26", "size": "0", "side": "BUY", "hash": "3ff1a294f7c80db10ebe87944933ce501148ba86", "best_bid": "0.72", "best_ask": "0.88"}, {"asset_id": "14133747134142323771619199606203638420186745480544687065966512009432569296940", "price": "0.74", "size": "0", "side": "SELL", "hash": "631463ee9953c3cc2591a53d807af16be81112f7", "best_bid": "0.12", "best_ask": "0.28"}], "timestamp": "1769384139602", "event_type": "price_change"}}
{"_local_timestamp": "2026-01-25T23:35:39.715354+00:00", "data": {"market": "0x11912cb7cc6561870be58a6a52be2943f3e86d2395032f064ef3091d6901882d", "price_changes": [{"asset_id": "50369611503686433705495168228906407585201475093386767089387389512232179527221", "price": "0.16", "size": "0", "side": "BUY", "hash": "1ac994c0c2edfcfe74d73f636fe7dbab30510bc8", "best_bid": "0.75", "best_ask": "0.87"}, {"asset_id": "25107464912227300161765664477112846497546753335497087400297930691126705811916", "price": "0.84", "size": "0", "side": "SELL", "hash": "af5b4d584ee1cdc1c9e12c8029cd20abae8d2d9e", "best_bid": "0.13", "best_ask": "0.25"}], "timestamp": "1769384139652", "event_type": "price_change"}}
{"_local_timestamp": "2026-01-25T23:35:39.744406+00:00", "data": {"market": "0xf6d98f9984cbd7994c5ad4b44b57e6e65771833e1f682cb6c08e1881cba0be23", "price_changes": [{"asset_id": "111619066987530654938781515834745418625505306643795368186113638707368057832687", "price": "0.46", "size": "30", "side": "BUY", "hash": "ca8f8a6188517ead288d39db9fd0f654d969c100", "best_bid": "0.72", "best_ask": "0.88"}, {"asset_id": "14133747134142323771619199606203638420186745480544687065966512009432569296940", "price": "0.54", "size": "30", "side": "SELL", "hash": "5635b242ee9a93d68e158e6d4714a6c7a623df19", "best_bid": "0.12", "best_ask": "0.28"}], "timestamp": "1769384139678", "event_type": "price_change"}}
{"_local_timestamp": "2026-01-25T23:35:39.775021+00:00", "data": {"market": "0xb5f61d0c9ce431d64ba702815984246fa9cd6c2d6399849f0051d8695f2d98ab", "price_changes": [{"asset_id": "98590289222817581558553345992202318138659660940538324229915000516905381167250", "price": "0.34", "size": "25", "side": "BUY", "hash": "ec1ba37318b8d9bcb2856ed7069bfe4b8a5a49d3", "best_bid": "0.76", "best_ask": "0.94"}, {"asset_id": "81582701062623199779039420976989567002417039977161919375131982089037196418005", "price": "0.66", "size": "25", "side": "SELL", "hash": "1d3f3f0287dbe7e86570844cb7c0bd27d1b8d8f7", "best_bid": "0.06", "best_ask": "0.24"}], "timestamp": "1769384139711", "event_type": "price_change"}}
{"_local_timestamp": "2026-01-25T23:35:39.775474+00:00", "data": {"market": "0x86fec61dd9c27294756303c47b77cf6b7ed13ff4097e2967bc333dde4c1ea4da", "price_changes": [{"asset_id": "37660683447879901945455922570375098409697520769704430824022672297921367915347", "price": "0.37", "size": "25", "side": "BUY", "hash": "1a1aa4631780a59370c2b0ca0683af7a3e9da562", "best_bid": "0.8", "best_ask": "0.94"}, {"asset_id": "63898934961262618957913174161832335092659130397470681441362226870577487706450", "price": "0.63", "size": "25", "side": "SELL", "hash": "6fc13e07e78b4cd5e86c780692481233412476a7", "best_bid": "0.06", "best_ask": "0.2"}], "timestamp": "1769384139711", "event_type": "price_change"}}
{"_local_timestamp": "2026-01-25T23:35:39.794847+00:00", "data": {"market": "0x11912cb7cc6561870be58a6a52be2943f3e86d2395032f064ef3091d6901882d", "price_changes": [{"asset_id": "50369611503686433705495168228906407585201475093386767089387389512232179527221", "price": "0.08", "size": "10", "side": "BUY", "hash": "319e1f2bf70ce55f9d9f724fa8644f78f15160dc", "best_bid": "0.75", "best_ask": "0.87"}, {"asset_id": "25107464912227300161765664477112846497546753335497087400297930691126705811916", "price": "0.92", "size": "10", "side": "SELL", "hash": "d728a62836ecfd575275f5faa7181adbe9672128", "best_bid": "0.13", "best_ask": "0.25"}], "timestamp": "1769384139731", "event_type": "price_change"}}
{"_local_timestamp": "2026-01-25T23:35:39.846711+00:00", "data": {"market": "0x86fec61dd9c27294756303c47b77cf6b7ed13ff4097e2967bc333dde4c1ea4da", "price_changes": [{"asset_id": "37660683447879901945455922570375098409697520769704430824022672297921367915347", "price": "0.32", "size": "100", "side": "BUY", "hash": "bfe9c5595b541fb3be8ac3400e66b62dc026f4bb", "best_bid": "0.8", "best_ask": "0.94"}, {"asset_id": "63898934961262618957913174161832335092659130397470681441362226870577487706450", "price": "0.68", "size": "100", "side": "SELL", "hash": "3772faeb1c3ad9ca68ce143342e5f2ff6e291b7a", "best_bid": "0.06", "best_ask": "0.2"}], "timestamp": "1769384139783", "event_type": "price_change"}}
{"_local_timestamp": "2026-01-25T23:35:39.896244+00:00", "data": {"market": "0x86fec61dd9c27294756303c47b77cf6b7ed13ff4097e2967bc333dde4c1ea4da", "price_changes": [{"asset_id": "37660683447879901945455922570375098409697520769704430824022672297921367915347", "price": "0.38", "size": "25", "side": "BUY", "hash": "5d68ea16602cfdc8b9728a8f9c4ad999f529ab4d", "best_bid": "0.8", "best_ask": "0.94"}, {"asset_id": "63898934961262618957913174161832335092659130397470681441362226870577487706450", "price": "0.62", "size": "25", "side": "SELL", "hash": "92863f3469a050ddd7aff5ca8dc3f6888e4afa82", "best_bid": "0.06", "best_ask": "0.2"}], "timestamp": "1769384139831", "event_type": "price_change"}}
{"_local_timestamp": "2026-01-25T23:35:40.002827+00:00", "data": {"market": "0xc114f4fc118df768372c3604e92d404c7c95ab6b25ada140c77dee976a890777", "price_changes": [{"asset_id": "114016092226346692646025674182722281295722777137086779627843163223516672173339", "price": "0.21", "size": "0", "side": "BUY", "hash": "c525ed195ab18a91bda5a6a2f247a88eb987378c", "best_bid": "0.58", "best_ask": "0.76"}, {"asset_id": "95497640963223955548410937239974920841410215692686671066528121763996154872565", "price": "0.79", "size": "0", "side": "SELL", "hash": "6946b062a97067f78c6885361fc07b3b09c039c4", "best_bid": "0.24", "best_ask": "0.42"}], "timestamp": "1769384139941", "event_type": "price_change"}}
{"_local_timestamp": "2026-01-25T23:35:40.086967+00:00", "data": {"market": "0xc114f4fc118df768372c3604e92d404c7c95ab6b25ada140c77dee976a890777", "price_changes": [{"asset_id": "114016092226346692646025674182722281295722777137086779627843163223516672173339", "price": "0.27", "size": "35", "side": "BUY", "hash": "307337eccfef4c37df76e6bb61f8c5f851fae3a5", "best_bid": "0.58", "best_ask": "0.76"}, {"asset_id": "95497640963223955548410937239974920841410215692686671066528121763996154872565", "price": "0.73", "size": "35", "side": "SELL", "hash": "379ac2a43cd096d53e8887cc9ee7355f6df22c45", "best_bid": "0.24", "best_ask": "0.42"}], "timestamp": "1769384140017", "event_type": "price_change"}}
{"_local_timestamp": "2026-01-25T23:35:40.087290+00:00", "data": {"market": "0xc114f4fc118df768372c3604e92d404c7c95ab6b25ada140c77dee976a890777", "price_changes": [{"asset_id": "114016092226346692646025674182722281295722777137086779627843163223516672173339", "price": "0.28", "size": "10", "side": "BUY", "hash": "ba9b9e84b089097f987bd42b17e7c00f3793e19a", "best_bid": "0.58", "best_ask": "0.76"}, {"asset_id": "95497640963223955548410937239974920841410215692686671066528121763996154872565", "price": "0.72", "size": "10", "side": "SELL", "hash": "88cf1091801e594cd9863035deea5ac03716e88e", "best_bid": "0.24", "best_ask": "0.42"}], "timestamp": "1769384140018", "event_type": "price_change"}}
{"_local_timestamp": "2026-01-25T23:35:40.087553+00:00", "data": {"market": "0x86fec61dd9c27294756303c47b77cf6b7ed13ff4097e2967bc333dde4c1ea4da", "price_changes": [{"asset_id": "37660683447879901945455922570375098409697520769704430824022672297921367915347", "price": "0.33", "size": "0", "side": "BUY", "hash": "85f0150ea5e390f9b116b91ef9d82f8df474ccab", "best_bid": "0.8", "best_ask": "0.94"}, {"asset_id": "63898934961262618957913174161832335092659130397470681441362226870577487706450", "price": "0.67", "size": "0", "side": "SELL", "hash": "fcab086b55780ff6f1d27bd1ab66d8b410d692bb", "best_bid": "0.06", "best_ask": "0.2"}], "timestamp": "1769384140020", "event_type": "price_change"}}
{"_local_timestamp": "2026-01-25T23:35:40.182217+00:00", "data": {"market": "0x11912cb7cc6561870be58a6a52be2943f3e86d2395032f064ef3091d6901882d", "price_changes": [{"asset_id": "50369611503686433705495168228906407585201475093386767089387389512232179527221", "price": "0.31", "size": "20", "side": "BUY", "hash": "e52b3213c2efde4aa9bace31940e2b372e1ee701", "best_bid": "0.75", "best_ask": "0.87"}, {"asset_id": "25107464912227300161765664477112846497546753335497087400297930691126705811916", "price": "0.69", "size": "20", "side": "SELL", "hash": "4be9780e713c8060d79b802883dd17bcaffad366", "best_bid": "0.13", "best_ask": "0.25"}], "timestamp": "1769384140110", "event_type": "price_change"}}
{"_local_timestamp": "2026-01-25T23:35:40.408608+00:00", "data": {"market": "0x86fec61dd9c27294756303c47b77cf6b7ed13ff4097e2967bc333dde4c1ea4da", "price_changes": [{"asset_id": "37660683447879901945455922570375098409697520769704430824022672297921367915347", "price": "0.1", "size": "10", "side": "BUY", "hash": "3ebf2ee3f70fb25cd05c31ed920db058123b1e01", "best_bid": "0.8", "best_ask": "0.94"}, {"asset_id": "63898934961262618957913174161832335092659130397470681441362226870577487706450", "price": "0.9", "size": "10", "side": "SELL", "hash": "122b597de235fcaeea8d917151e62a20699b101d", "best_bid": "0.06", "best_ask": "0.2"}], "timestamp": "1769384140336", "event_type": "price_change"}}
{"_local_timestamp": "2026-01-25T23:35:42.292689+00:00", "data": {"market": "0x11912cb7cc6561870be58a6a52be2943f3e86d2395032f064ef3091d6901882d", "price_changes": [{"asset_id": "50369611503686433705495168228906407585201475093386767089387389512232179527221", "price": "0.31", "size": "0", "side": "BUY", "hash": "7f586b34471850eb98a0043cc084e4d279837a6a", "best_bid": "0.75", "best_ask": "0.87"}, {"asset_id": "25107464912227300161765664477112846497546753335497087400297930691126705811916", "price": "0.69", "size": "0", "side": "SELL", "hash": "42d94decddf4524545f0794114dff1d991b2cfb9", "best_bid": "0.13", "best_ask": "0.25"}], "timestamp": "1769384142223", "event_type": "price_change"}}
{"_local_timestamp": "2026-01-25T23:35:42.296584+00:00", "data": {"market": "0xc114f4fc118df768372c3604e92d404c7c95ab6b25ada140c77dee976a890777", "price_changes": [{"asset_id": "114016092226346692646025674182722281295722777137086779627843163223516672173339", "price": "0.27", "size": "15", "side": "BUY", "hash": "7b473ad89e35dfc490ee4c69fe422f0519896f3e", "best_bid": "0.58", "best_ask": "0.76"}, {"asset_id": "95497640963223955548410937239974920841410215692686671066528121763996154872565", "price": "0.73", "size": "15", "side": "SELL", "hash": "031877af53673218f13a8d78e69db720aa29992a", "best_bid": "0.24", "best_ask": "0.42"}], "timestamp": "1769384142222", "event_type": "price_change"}}
{"_local_timestamp": "2026-01-25T23:35:42.296934+00:00", "data": {"market": "0xb5f61d0c9ce431d64ba702815984246fa9cd6c2d6399849f0051d8695f2d98ab", "price_changes": [{"asset_id": "98590289222817581558553345992202318138659660940538324229915000516905381167250", "price": "0.33", "size": "0", "side": "BUY", "hash": "35ea0788224a4c169c22ad7087212f19844c321a", "best_bid": "0.76", "best_ask": "0.94"}, {"asset_id": "81582701062623199779039420976989567002417039977161919375131982089037196418005", "price": "0.67", "size": "0", "side": "SELL", "hash": "3f16e474a315d029bbc7f25f07d4f5d29d82148b", "best_bid": "0.06", "best_ask": "0.24"}], "timestamp": "1769384142223", "event_type": "price_change"}}
{"_local_timestamp": "2026-01-25T23:35:42.297457+00:00", "data": {"market": "0xf6d98f9984cbd7994c5ad4b44b57e6e65771833e1f682cb6c08e1881cba0be23", "price_changes": [{"asset_id": "111619066987530654938781515834745418625505306643795368186113638707368057832687", "price": "0.28", "size": "0", "side": "BUY", "hash": "6b5692ed2e99e8111bcb9191ae2aac13143607e9", "best_bid": "0.72", "best_ask": "0.88"}, {"asset_id": "14133747134142323771619199606203638420186745480544687065966512009432569296940", "price": "0.72", "size": "0", "side": "SELL", "hash": "ba614dc364bac6ff1ae04223e8bdd793834b42c8", "best_bid": "0.12", "best_ask": "0.28"}], "timestamp": "1769384142223", "event_type": "price_change"}}
{"_local_timestamp": "2026-01-25T23:35:42.297862+00:00", "data": {"market": "0x86fec61dd9c27294756303c47b77cf6b7ed13ff4097e2967bc333dde4c1ea4da", "price_changes": [{"asset_id": "37660683447879901945455922570375098409697520769704430824022672297921367915347", "price": "0.36", "size": "0", "side": "BUY", "hash": "19a654de4cd12bef54c9d1d5cd6d627359a95c49", "best_bid": "0.8", "best_ask": "0.94"}, {"asset_id": "63898934961262618957913174161832335092659130397470681441362226870577487706450", "price": "0.64", "size": "0", "side": "SELL", "hash": "37a74ee3bbaff79a14d68bebe38395d29050528a", "best_bid": "0.06", "best_ask": "0.2"}], "timestamp": "1769384142223", "event_type": "price_change"}}
{"_local_timestamp": "2026-01-25T23:35:42.316659+00:00", "data": {"market": "0xf6d98f9984cbd7994c5ad4b44b57e6e65771833e1f682cb6c08e1881cba0be23", "price_changes": [{"asset_id": "111619066987530654938781515834745418625505306643795368186113638707368057832687", "price": "0.3", "size": "20", "side": "BUY", "hash": "f0ba91633cfb58372900deddba71fd4a2089e39f", "best_bid": "0.72", "best_ask": "0.88"}, {"asset_id": "14133747134142323771619199606203638420186745480544687065966512009432569296940", "price": "0.7", "size": "20", "side": "SELL", "hash": "364eccd51c859ecd58edde03d9568b0a89832112", "best_bid": "0.12", "best_ask": "0.28"}], "timestamp": "1769384142250", "event_type": "price_change"}}
{"_local_timestamp": "2026-01-25T23:35:42.317044+00:00", "data": {"market": "0x86fec61dd9c27294756303c47b77cf6b7ed13ff4097e2967bc333dde4c1ea4da", "price_changes": [{"asset_id": "37660683447879901945455922570375098409697520769704430824022672297921367915347", "price": "0.39", "size": "20", "side": "BUY", "hash": "7aff10d0242a3ecec933adfd592f72abe23308f9", "best_bid": "0.8", "best_ask": "0.94"}, {"asset_id": "63898934961262618957913174161832335092659130397470681441362226870577487706450", "price": "0.61", "size": "20", "side": "SELL", "hash": "9f94edc56ec046624f44c01d2fbceb406c51c01a", "best_bid": "0.06", "best_ask": "0.2"}], "timestamp": "1769384142250", "event_type": "price_change"}}
{"_local_timestamp": "2026-01-25T23:35:42.317309+00:00", "data": {"market": "0xb5f61d0c9ce431d64ba702815984246fa9cd6c2d6399849f0051d8695f2d98ab", "price_changes": [{"asset_id": "98590289222817581558553345992202318138659660940538324229915000516905381167250", "price": "0.35", "size": "20", "side": "BUY", "hash": "aa06c7c41026a1e66163cc03fdd080dbbfd35713", "best_bid": "0.76", "best_ask": "0.94"}, {"asset_id": "81582701062623199779039420976989567002417039977161919375131982089037196418005", "price": "0.65", "size": "20", "side": "SELL", "hash": "5e5a3814ade14f05b62d7872218f8aa2ef5e70e0", "best_bid": "0.06", "best_ask": "0.24"}], "timestamp": "1769384142250", "event_type": "price_change"}}
{"_local_timestamp": "2026-01-25T23:35:42.317539+00:00", "data": {"market": "0x11912cb7cc6561870be58a6a52be2943f3e86d2395032f064ef3091d6901882d", "price_changes": [{"asset_id": "50369611503686433705495168228906407585201475093386767089387389512232179527221", "price": "0.33", "size": "20", "side": "BUY", "hash": "66eb93061a6cc35b2c6e1ca753d845fc7e380fd1", "best_bid": "0.75", "best_ask": "0.87"}, {"asset_id": "25107464912227300161765664477112846497546753335497087400297930691126705811916", "price": "0.67", "size": "20", "side": "SELL", "hash": "da18b8b56f5eb877feadfb77e0b9ce3e5464a055", "best_bid": "0.13", "best_ask": "0.25"}], "timestamp": "1769384142250", "event_type": "price_change"}}
{"_local_timestamp": "2026-01-25T23:35:42.317846+00:00", "data": {"market": "0xc114f4fc118df768372c3604e92d404c7c95ab6b25ada140c77dee976a890777", "price_changes": [{"asset_id": "114016092226346692646025674182722281295722777137086779627843163223516672173339", "price": "0.29", "size": "20", "side": "BUY", "hash": "b04efbfe4fca8d064ce52fbfef4de6b22e3418e9", "best_bid": "0.58", "best_ask": "0.76"}, {"asset_id": "95497640963223955548410937239974920841410215692686671066528121763996154872565", "price": "0.71", "size": "20", "side": "SELL", "hash": "d8ab7383db23f9ce375c4e28b5371608e0b9006f", "best_bid": "0.24", "best_ask": "0.42"}], "timestamp": "1769384142250", "event_type": "price_change"}}
{"_local_timestamp": "2026-01-25T23:35:42.382862+00:00", "data": {"market": "0xc114f4fc118df768372c3604e92d404c7c95ab6b25ada140c77dee976a890777", "price_changes": [{"asset_id": "114016092226346692646025674182722281295722777137086779627843163223516672173339", "price": "0.27", "size": "0", "side": "BUY", "hash": "38537d95dc9cab6725b28dd7d598ae071c285e1c", "best_bid": "0.58", "best_ask": "0.76"}, {"asset_id": "95497640963223955548410937239974920841410215692686671066528121763996154872565", "price": "0.73", "size": "0", "side": "SELL", "hash": "d9e4ad343e5e83fa06a205116d8baf865698b444", "best_bid": "0.24", "best_ask": "0.42"}], "timestamp": "1769384142319", "event_type": "price_change"}}
{"_local_timestamp": "2026-01-25T23:35:42.443381+00:00", "data": {"market": "0xf6d98f9984cbd7994c5ad4b44b57e6e65771833e1f682cb6c08e1881cba0be23", "price_changes": [{"asset_id": "111619066987530654938781515834745418625505306643795368186113638707368057832687", "price": "0.27", "size": "0", "side": "BUY", "hash": "e1271ab10ce3f2750ddd43ef70d3ae2f9e826986", "best_bid": "0.72", "best_ask": "0.88"}, {"asset_id": "14133747134142323771619199606203638420186745480544687065966512009432569296940", "price": "0.73", "size": "0", "side": "SELL", "hash": "c1232576e93e7651e8a5a9ffe7f90b3307e48602", "best_bid": "0.12", "best_ask": "0.28"}], "timestamp": "1769384142375", "event_type": "price_change"}}
{"_local_timestamp": "2026-01-25T23:35:42.658693+00:00", "data": {"market": "0xf6d98f9984cbd7994c5ad4b44b57e6e65771833e1f682cb6c08e1881cba0be23", "price_changes": [{"asset_id": "111619066987530654938781515834745418625505306643795368186113638707368057832687", "price": "0.25", "size": "10", "side": "BUY", "hash": "91ec862f98e5c43fdcdb1f449d7b643f040d1b73", "best_bid": "0.72", "best_ask": "0.88"}, {"asset_id": "14133747134142323771619199606203638420186745480544687065966512009432569296940", "price": "0.75", "size": "10", "side": "SELL", "hash": "214727e5187dd083825c10aa0fc7272aaf929ea6", "best_bid": "0.12", "best_ask": "0.28"}], "timestamp": "1769384142591", "event_type": "price_change"}}
{"_local_timestamp": "2026-01-25T23:35:54.592851+00:00", "data": {"market": "0xb5f61d0c9ce431d64ba702815984246fa9cd6c2d6399849f0051d8695f2d98ab", "price_changes": [{"asset_id": "98590289222817581558553345992202318138659660940538324229915000516905381167250", "price": "0.32", "size": "0", "side": "BUY", "hash": "21411280f6a2dfc0b881fb40c32e7ce976a17159", "best_bid": "0.76", "best_ask": "0.94"}, {"asset_id": "81582701062623199779039420976989567002417039977161919375131982089037196418005", "price": "0.68", "size": "0", "side": "SELL", "hash": "10e86da0c361238848f41cebd03bbae41fcc1a9b", "best_bid": "0.06", "best_ask": "0.24"}], "timestamp": "1769384154519", "event_type": "price_change"}}
{"_local_timestamp": "2026-01-25T23:35:54.593437+00:00", "data": {"market": "0x86fec61dd9c27294756303c47b77cf6b7ed13ff4097e2967bc333dde4c1ea4da", "price_changes": [{"asset_id": "37660683447879901945455922570375098409697520769704430824022672297921367915347", "price": "0.32", "size": "0", "side": "BUY", "hash": "47cd70f0feee6c1322645ea2e16610e03c349b75", "best_bid": "0.8", "best_ask": "0.94"}, {"asset_id": "63898934961262618957913174161832335092659130397470681441362226870577487706450", "price": "0.68", "size": "0", "side": "SELL", "hash": "5b459638c484bc46e5ed80fb50d3c69ab55cb8b9", "best_bid": "0.06", "best_ask": "0.2"}], "timestamp": "1769384154519", "event_type": "price_change"}}
{"_local_timestamp": "2026-01-25T23:35:54.593761+00:00", "data": {"market": "0xc114f4fc118df768372c3604e92d404c7c95ab6b25ada140c77dee976a890777", "price_changes": [{"asset_id": "114016092226346692646025674182722281295722777137086779627843163223516672173339", "price": "0.35", "size": "0", "side": "BUY", "hash": "281d2e7a1d7f87ffb2a0b0dfb779c43fc6a03b5e", "best_bid": "0.58", "best_ask": "0.76"}, {"asset_id": "95497640963223955548410937239974920841410215692686671066528121763996154872565", "price": "0.65", "size": "0", "side": "SELL", "hash": "9b9aa4a79809037be37e49791c5017b2d14e7ecb", "best_bid": "0.24", "best_ask": "0.42"}], "timestamp": "1769384154518", "event_type": "price_change"}}
{"_local_timestamp": "2026-01-25T23:35:54.594023+00:00", "data": {"market": "0xc114f4fc118df768372c3604e92d404c7c95ab6b25ada140c77dee976a890777", "price_changes": [{"asset_id": "114016092226346692646025674182722281295722777137086779627843163223516672173339", "price": "0.2", "size": "0", "side": "BUY", "hash": "281d2e7a1d7f87ffb2a0b0dfb779c43fc6a03b5e", "best_bid": "0.58", "best_ask": "0.76"}, {"asset_id": "95497640963223955548410937239974920841410215692686671066528121763996154872565", "price": "0.8", "size": "0", "side": "SELL", "hash": "9b9aa4a79809037be37e49791c5017b2d14e7ecb", "best_bid": "0.24", "best_ask": "0.42"}], "timestamp": "1769384154518", "event_type": "price_change"}}
{"_local_timestamp": "2026-01-25T23:35:54.594302+00:00", "data": {"market": "0xc114f4fc118df768372c3604e92d404c7c95ab6b25ada140c77dee976a890777", "price_changes": [{"asset_id": "114016092226346692646025674182722281295722777137086779627843163223516672173339", "price": "0.06", "size": "133", "side": "BUY", "hash": "281d2e7a1d7f87ffb2a0b0dfb779c43fc6a03b5e", "best_bid": "0.58", "best_ask": "0.76"}, {"asset_id": "95497640963223955548410937239974920841410215692686671066528121763996154872565", "price": "0.94", "size": "133", "side": "SELL", "hash": "9b9aa4a79809037be37e49791c5017b2d14e7ecb", "best_bid": "0.24", "best_ask": "0.42"}], "timestamp": "1769384154518", "event_type": "price_change"}}
{"_local_timestamp": "2026-01-25T23:35:54.594576+00:00", "data": {"market": "0x11912cb7cc6561870be58a6a52be2943f3e86d2395032f064ef3091d6901882d", "price_changes": [{"asset_id": "50369611503686433705495168228906407585201475093386767089387389512232179527221", "price": "0.3", "size": "0", "side": "BUY", "hash": "b73b7cca4f253b8ad36c44efadc59f26a1b6e56d", "best_bid": "0.75", "best_ask": "0.87"}, {"asset_id": "25107464912227300161765664477112846497546753335497087400297930691126705811916", "price": "0.7", "size": "0", "side": "SELL", "hash": "48c89f9668b28a64c85b4cbdbaf234bd6172f688", "best_bid": "0.13", "best_ask": "0.25"}], "timestamp": "1769384154519", "event_type": "price_change"}}
{"_local_timestamp": "2026-01-25T23:35:54.594866+00:00", "data": {"market": "0x11912cb7cc6561870be58a6a52be2943f3e86d2395032f064ef3091d6901882d", "price_changes": [{"asset_id": "50369611503686433705495168228906407585201475093386767089387389512232179527221", "price": "0.15", "size": "0", "side": "BUY", "hash": "b73b7cca4f253b8ad36c44efadc59f26a1b6e56d", "best_bid": "0.75", "best_ask": "0.87"}, {"asset_id": "25107464912227300161765664477112846497546753335497087400297930691126705811916", "price": "0.85", "size": "0", "side": "SELL", "hash": "48c89f9668b28a64c85b4cbdbaf234bd6172f688", "best_bid": "0.13", "best_ask": "0.25"}], "timestamp": "1769384154519", "event_type": "price_change"}}
{"_local_timestamp": "2026-01-25T23:35:54.595173+00:00", "data": {"market": "0x11912cb7cc6561870be58a6a52be2943f3e86d2395032f064ef3091d6901882d", "price_changes": [{"asset_id": "50369611503686433705495168228906407585201475093386767089387389512232179527221", "price": "0.01", "size": "3105.48", "side": "BUY", "hash": "b73b7cca4f253b8ad36c44efadc59f26a1b6e56d", "best_bid": "0.75", "best_ask": "0.87"}, {"asset_id": "25107464912227300161765664477112846497546753335497087400297930691126705811916", "price": "0.99", "size": "3105.48", "side": "SELL", "hash": "48c89f9668b28a64c85b4cbdbaf234bd6172f688", "best_bid": "0.13", "best_ask": "0.25"}], "timestamp": "1769384154519", "event_type": "price_change"}}
{"_local_timestamp": "2026-01-25T23:35:54.600422+00:00", "data": {"market": "0xf6d98f9984cbd7994c5ad4b44b57e6e65771833e1f682cb6c08e1881cba0be23", "price_changes": [{"asset_id": "111619066987530654938781515834745418625505306643795368186113638707368057832687", "price": "0.24", "size": "0", "side": "BUY", "hash": "6aff923d02233c1ca02b7a095539a2f83d9be8dc", "best_bid": "0.72", "best_ask": "0.88"}, {"asset_id": "14133747134142323771619199606203638420186745480544687065966512009432569296940", "price": "0.76", "size": "0", "side": "SELL", "hash": "d71b9757a7dc2efef5bcbfa25d1e7ef801f82b90", "best_bid": "0.12", "best_ask": "0.28"}], "timestamp": "1769384154519", "event_type": "price_change"}}
{"_local_timestamp": "2026-01-25T23:35:54.836931+00:00", "data": {"market": "0xf6d98f9984cbd7994c5ad4b44b57e6e65771833e1f682cb6c08e1881cba0be23", "price_changes": [{"asset_id": "111619066987530654938781515834745418625505306643795368186113638707368057832687", "price": "0.09", "size": "0", "side": "BUY", "hash": "0ff9c161a8d10a53affa1d847698d907ba24e480", "best_bid": "0.72", "best_ask": "0.88"}, {"asset_id": "14133747134142323771619199606203638420186745480544687065966512009432569296940", "price": "0.91", "size": "0", "side": "SELL", "hash": "fa04dcb226157c85ffaf9f72a688cdee9476126f", "best_bid": "0.12", "best_ask": "0.28"}], "timestamp": "1769384154765", "event_type": "price_change"}}
{"_local_timestamp": "2026-01-25T23:35:54.954683+00:00", "data": {"market": "0xf6d98f9984cbd7994c5ad4b44b57e6e65771833e1f682cb6c08e1881cba0be23", "price_changes": [{"asset_id": "111619066987530654938781515834745418625505306643795368186113638707368057832687", "price": "0.3", "size": "35", "side": "BUY", "hash": "8ef1597fa0fc129ee4cc281b765e4af1b94990d5", "best_bid": "0.72", "best_ask": "0.88"}, {"asset_id": "14133747134142323771619199606203638420186745480544687065966512009432569296940", "price": "0.7", "size": "35", "side": "SELL", "hash": "ba91a3cc4c11005302f73efacdcf7834cf0c880f", "best_bid": "0.12", "best_ask": "0.28"}], "timestamp": "1769384154886", "event_type": "price_change"}}
{"_local_timestamp": "2026-01-25T23:35:54.955139+00:00", "data": {"market": "0xf6d98f9984cbd7994c5ad4b44b57e6e65771833e1f682cb6c08e1881cba0be23", "price_changes": [{"asset_id": "111619066987530654938781515834745418625505306643795368186113638707368057832687", "price": "0.31", "size": "10", "side": "BUY", "hash": "4c59deb3937236a019491d1a630c8534d59a4214", "best_bid": "0.72", "best_ask": "0.88"}, {"asset_id": "14133747134142323771619199606203638420186745480544687065966512009432569296940", "price": "0.69", "size": "10", "side": "SELL", "hash": "825cd5e7568ffd490a071707eeff3975a2d444ef", "best_bid": "0.12", "best_ask": "0.28"}], "timestamp": "1769384154889", "event_type": "price_change"}}
{"_local_timestamp": "2026-01-25T23:35:55.047533+00:00", "data": {"market": "0xf6d98f9984cbd7994c5ad4b44b57e6e65771833e1f682cb6c08e1881cba0be23", "price_changes": [{"asset_id": "111619066987530654938781515834745418625505306643795368186113638707368057832687", "price": "0.25", "size": "0", "side": "BUY", "hash": "d8e994757677a81e773641c01e82a2de1e32151c", "best_bid": "0.72", "best_ask": "0.88"}, {"asset_id": "14133747134142323771619199606203638420186745480544687065966512009432569296940", "price": "0.75", "size": "0", "side": "SELL", "hash": "b3f9378af56a8e53b50dea01948c89cdb5748042", "best_bid": "0.12", "best_ask": "0.28"}], "timestamp": "1769384154962", "event_type": "price_change"}}
{"_local_timestamp": "2026-01-25T23:35:55.151067+00:00", "data": {"market": "0xf6d98f9984cbd7994c5ad4b44b57e6e65771833e1f682cb6c08e1881cba0be23", "price_changes": [{"asset_id": "111619066987530654938781515834745418625505306643795368186113638707368057832687", "price": "0.19", "size": "10", "side": "BUY", "hash": "d95fb30901fa38db8201fb4ddd3b315e1f2dfcc1", "best_bid": "0.72", "best_ask": "0.88"}, {"asset_id": "14133747134142323771619199606203638420186745480544687065966512009432569296940", "price": "0.81", "size": "10", "side": "SELL", "hash": "d8b4be5d39ee8bf5a0db2a122c5d54fa820e59ad", "best_bid": "0.12", "best_ask": "0.28"}], "timestamp": "1769384155058", "event_type": "price_change"}}
{"_local_timestamp": "2026-01-25T23:35:55.329542+00:00", "data": {"market": "0xb5f61d0c9ce431d64ba702815984246fa9cd6c2d6399849f0051d8695f2d98ab", "price_changes": [{"asset_id": "98590289222817581558553345992202318138659660940538324229915000516905381167250", "price": "0.19", "size": "0", "side": "BUY", "hash": "0fd6354194fe8cb014372c30e539b8718d605557", "best_bid": "0.76", "best_ask": "0.94"}, {"asset_id": "81582701062623199779039420976989567002417039977161919375131982089037196418005", "price": "0.81", "size": "0", "side": "SELL", "hash": "3e10e66e336a3cd605fa0a69a7747fb7d7f36576", "best_bid": "0.06", "best_ask": "0.24"}], "timestamp": "1769384155247", "event_type": "price_change"}}
{"_local_timestamp": "2026-01-25T23:35:56.267317+00:00", "data": {"market": "0xf6d98f9984cbd7994c5ad4b44b57e6e65771833e1f682cb6c08e1881cba0be23", "price_changes": [{"asset_id": "111619066987530654938781515834745418625505306643795368186113638707368057832687", "price": "0.3", "size": "15", "side": "BUY", "hash": "fdac357ae7ed55d71367949e87f16091851097d3", "best_bid": "0.72", "best_ask": "0.88"}, {"asset_id": "14133747134142323771619199606203638420186745480544687065966512009432569296940", "price": "0.7", "size": "15", "side": "SELL", "hash": "891bb69d2d8fe4d56e0b43378e94d7a30053f96b", "best_bid": "0.12", "best_ask": "0.28"}], "timestamp": "1769384156195", "event_type": "price_change"}}
{"_local_timestamp": "2026-01-25T23:35:56.285006+00:00", "data": {"market": "0x11912cb7cc6561870be58a6a52be2943f3e86d2395032f064ef3091d6901882d", "price_changes": [{"asset_id": "50369611503686433705495168228906407585201475093386767089387389512232179527221", "price": "0.01", "size": "3205.48", "side": "BUY", "hash": "58c4f0219b2f427a0026dade4809f156a5179470", "best_bid": "0.75", "best_ask": "0.87"}, {"asset_id": "25107464912227300161765664477112846497546753335497087400297930691126705811916", "price": "0.99", "size": "3205.48", "side": "SELL", "hash": "cae51ff61f4bae864b74deaac2de577dfe00f242", "best_bid": "0.13", "best_ask": "0.25"}], "timestamp": "1769384156214", "event_type": "price_change"}}
{"_local_timestamp": "2026-01-25T23:35:56.286405+00:00", "data": {"market": "0xf6d98f9984cbd7994c5ad4b44b57e6e65771833e1f682cb6c08e1881cba0be23", "price_changes": [{"asset_id": "111619066987530654938781515834745418625505306643795368186113638707368057832687", "price": "0.32", "size": "20", "side": "BUY", "hash": "291b3ae475a7d2805d67d6c005be6a0d0e83b06f", "best_bid": "0.72", "best_ask": "0.88"}, {"asset_id": "14133747134142323771619199606203638420186745480544687065966512009432569296940", "price": "0.68", "size": "20", "side": "SELL", "hash": "ee5c8e366b2514be6d15690890eff817857f6521", "best_bid": "0.12", "best_ask": "0.28"}], "timestamp": "1769384156223", "event_type": "price_change"}}
{"_local_timestamp": "2026-01-25T23:35:56.342966+00:00", "data": {"market": "0xb5f61d0c9ce431d64ba702815984246fa9cd6c2d6399849f0051d8695f2d98ab", "price_changes": [{"asset_id": "98590289222817581558553345992202318138659660940538324229915000516905381167250", "price": "0.24", "size": "0", "side": "BUY", "hash": "93bf24cfd370cd700dac02ad90cb01c0eb63fad0", "best_bid": "0.76", "best_ask": "0.94"}, {"asset_id": "81582701062623199779039420976989567002417039977161919375131982089037196418005", "price": "0.76", "size": "0", "side": "SELL", "hash": "1bb09206875768b2fa93a341eeef66088876d805", "best_bid": "0.06", "best_ask": "0.24"}], "timestamp": "1769384156262", "event_type": "price_change"}}
{"_local_timestamp": "2026-01-25T23:35:56.362987+00:00", "data": {"market": "0xf6d98f9984cbd7994c5ad4b44b57e6e65771833e1f682cb6c08e1881cba0be23", "price_changes": [{"asset_id": "111619066987530654938781515834745418625505306643795368186113638707368057832687", "price": "0.37", "size": "100", "side": "BUY", "hash": "19b1d8c9a68e64fa03d5516ce3665064aa7c3196", "best_bid": "0.72", "best_ask": "0.88"}, {"asset_id": "14133747134142323771619199606203638420186745480544687065966512009432569296940", "price": "0.63", "size": "100", "side": "SELL", "hash": "c529e3194ceac3e48e7d1542c9308547ed0f5bde", "best_bid": "0.12", "best_ask": "0.28"}], "timestamp": "1769384156265", "event_type": "price_change"}}
{"_local_timestamp": "2026-01-25T23:35:56.408992+00:00", "data": {"market": "0xc114f4fc118df768372c3604e92d404c7c95ab6b25ada140c77dee976a890777", "price_changes": [{"asset_id": "114016092226346692646025674182722281295722777137086779627843163223516672173339", "price": "0.05", "size": "430", "side": "BUY", "hash": "a5d7180e97db6f8ab5ed7c310c34eff06ef25631", "best_bid": "0.58", "best_ask": "0.76"}, {"asset_id": "95497640963223955548410937239974920841410215692686671066528121763996154872565", "price": "0.95", "size": "430", "side": "SELL", "hash": "8de64d532f6f4e83d39319e7befd54dfe59ec712", "best_bid": "0.24", "best_ask": "0.42"}], "timestamp": "1769384156286", "event_type": "price_change"}}
{"_local_timestamp": "2026-01-25T23:35:56.445927+00:00", "data": {"market": "0xb5f61d0c9ce431d64ba702815984246fa9cd6c2d6399849f0051d8695f2d98ab", "price_changes": [{"asset_id": "98590289222817581558553345992202318138659660940538324229915000516905381167250", "price": "0.41", "size": "100", "side": "BUY", "hash": "a758bdab8e14f4dbbb84daccdede09cbe2213462", "best_bid": "0.76", "best_ask": "0.94"}, {"asset_id": "81582701062623199779039420976989567002417039977161919375131982089037196418005", "price": "0.59", "size": "100", "side": "SELL", "hash": "0af512acff351478bea66c20ef07439f4e763415", "best_bid": "0.06", "best_ask": "0.24"}], "timestamp": "1769384156293", "event_type": "price_change"}}
{"_local_timestamp": "2026-01-25T23:35:56.485509+00:00", "data": {"market": "0x11912cb7cc6561870be58a6a52be2943f3e86d2395032f064ef3091d6901882d", "price_changes": [{"asset_id": "50369611503686433705495168228906407585201475093386767089387389512232179527221", "price": "0.38", "size": "100", "side": "BUY", "hash": "b82c6968bb436b8a71eee6124fd659ddbf569376", "best_bid": "0.75", "best_ask": "0.87"}, {"asset_id": "25107464912227300161765664477112846497546753335497087400297930691126705811916", "price": "0.62", "size": "100", "side": "SELL", "hash": "aba571d0075127ba31b9312bbad53ea27c4ab5ed", "best_bid": "0.13", "best_ask": "0.25"}], "timestamp": "1769384156314", "event_type": "price_change"}}
{"_local_timestamp": "2026-01-25T23:35:56.489881+00:00", "data": {"market": "0x86fec61dd9c27294756303c47b77cf6b7ed13ff4097e2967bc333dde4c1ea4da", "price_changes": [{"asset_id": "37660683447879901945455922570375098409697520769704430824022672297921367915347", "price": "0.43", "size": "100", "side": "BUY", "hash": "bcb9bc791721a958441b9518005fb2d85e0ce322", "best_bid": "0.8", "best_ask": "0.94"}, {"asset_id": "63898934961262618957913174161832335092659130397470681441362226870577487706450", "price": "0.57", "size": "100", "side": "SELL", "hash": "fd3bf6c4ad40158608a02263041ba3a8dc2d89f3", "best_bid": "0.06", "best_ask": "0.2"}], "timestamp": "1769384156319", "event_type": "price_change"}}
{"_local_timestamp": "2026-01-25T23:35:56.496226+00:00", "data": {"market": "0xc114f4fc118df768372c3604e92d404c7c95ab6b25ada140c77dee976a890777", "price_changes": [{"asset_id": "114016092226346692646025674182722281295722777137086779627843163223516672173339", "price": "0.31", "size": "100", "side": "BUY", "hash": "d471ea0b909026d56a07d9c495da174f0a8a2ee7", "best_bid": "0.58", "best_ask": "0.76"}, {"asset_id": "95497640963223955548410937239974920841410215692686671066528121763996154872565", "price": "0.69", "size": "100", "side": "SELL", "hash": "c2df6f351388610659b5c592193d99a6fa8a2167", "best_bid": "0.24", "best_ask": "0.42"}], "timestamp": "1769384156331", "event_type": "price_change"}}
{"_local_timestamp": "2026-01-25T23:35:56.521431+00:00", "data": {"market": "0xb5f61d0c9ce431d64ba702815984246fa9cd6c2d6399849f0051d8695f2d98ab", "price_changes": [{"asset_id": "98590289222817581558553345992202318138659660940538324229915000516905381167250", "price": "0.36", "size": "20", "side": "BUY", "hash": "aa7a23509c61d525029612132a76f44fd46e37fc", "best_bid": "0.76", "best_ask": "0.94"}, {"asset_id": "81582701062623199779039420976989567002417039977161919375131982089037196418005", "price": "0.64", "size": "20", "side": "SELL", "hash": "5b6ef0affed0158b7cf7a09add7ca7f636588d11", "best_bid": "0.06", "best_ask": "0.24"}], "timestamp": "1769384156352", "event_type": "price_change"}}
{"_local_timestamp": "2026-01-25T23:35:56.597262+00:00", "data": {"market": "0xf6d98f9984cbd7994c5ad4b44b57e6e65771833e1f682cb6c08e1881cba0be23", "price_changes": [{"asset_id": "111619066987530654938781515834745418625505306643795368186113638707368057832687", "price": "0.19", "size": "0", "side": "BUY", "hash": "6e8c17024d35707ced0c5ab99000ad5f987d0bd7", "best_bid": "0.72", "best_ask": "0.88"}, {"asset_id": "14133747134142323771619199606203638420186745480544687065966512009432569296940", "price": "0.81", "size": "0", "side": "SELL", "hash": "a465b55c0d8aa69e87640fa99670b51c2601dd7d", "best_bid": "0.12", "best_ask": "0.28"}], "timestamp": "1769384156492", "event_type": "price_change"}}
{"_local_timestamp": "2026-01-25T23:35:56.598070+00:00", "data": {"market": "0xb5f61d0c9ce431d64ba702815984246fa9cd6c2d6399849f0051d8695f2d98ab", "price_changes": [{"asset_id": "98590289222817581558553345992202318138659660940538324229915000516905381167250", "price": "0.29", "size": "0", "side": "BUY", "hash": "b0250641e84a0603f7078cf69bd88f008c860902", "best_bid": "0.76", "best_ask": "0.94"}, {"asset_id": "81582701062623199779039420976989567002417039977161919375131982089037196418005", "price": "0.71", "size": "0", "side": "SELL", "hash": "3ae7a14bd8a06f1e3d75c1fbaabc070ec7510aca", "best_bid": "0.06", "best_ask": "0.24"}], "timestamp": "1769384156492", "event_type": "price_change"}}
{"_local_timestamp": "2026-01-25T23:35:56.640883+00:00", "data": {"market": "0xf6d98f9984cbd7994c5ad4b44b57e6e65771833e1f682cb6c08e1881cba0be23", "price_changes": [{"asset_id": "111619066987530654938781515834745418625505306643795368186113638707368057832687", "price": "0.08", "size": "16.56", "side": "BUY", "hash": "367c116d4560ddc617b2c5b9ec4422b335724d4e", "best_bid": "0.72", "best_ask": "0.88"}, {"asset_id": "14133747134142323771619199606203638420186745480544687065966512009432569296940", "price": "0.92", "size": "16.56", "side": "SELL", "hash": "79d6de5e4a9a810f8bfad6e9090a7a636d78b44f", "best_bid": "0.12", "best_ask": "0.28"}], "timestamp": "1769384156549", "event_type": "price_change"}}
{"_local_timestamp": "2026-01-25T23:35:56.641579+00:00", "data": {"market": "0xb5f61d0c9ce431d64ba702815984246fa9cd6c2d6399849f0051d8695f2d98ab", "price_changes": [{"asset_id": "98590289222817581558553345992202318138659660940538324229915000516905381167250", "price": "0.1", "size": "10", "side": "BUY", "hash": "9dd9785d6c385a644b89ee1aa2a26574bc3423c0", "best_bid": "0.76", "best_ask": "0.94"}, {"asset_id": "81582701062623199779039420976989567002417039977161919375131982089037196418005", "price": "0.9", "size": "10", "side": "SELL", "hash": "05f019c49c1e9311f67baf7a579ca9087c65f1ba", "best_bid": "0.06", "best_ask": "0.24"}], "timestamp": "1769384156550", "event_type": "price_change"}}
{"_local_timestamp": "2026-01-25T23:35:59.202751+00:00", "data": {"market": "0x86fec61dd9c27294756303c47b77cf6b7ed13ff4097e2967bc333dde4c1ea4da", "price_changes": [{"asset_id": "37660683447879901945455922570375098409697520769704430824022672297921367915347", "price": "0.39", "size": "0", "side": "BUY", "hash": "60e44e49175588766e6b09851d1d5bae075c347d", "best_bid": "0.8", "best_ask": "0.94"}, {"asset_id": "63898934961262618957913174161832335092659130397470681441362226870577487706450", "price": "0.61", "size": "0", "side": "SELL", "hash": "ece643c800bac060e6efec8612706f3111efaa15", "best_bid": "0.06", "best_ask": "0.2"}], "timestamp": "1769384159112", "event_type": "price_change"}}
{"_local_timestamp": "2026-01-25T23:35:59.204439+00:00", "data": {"market": "0xc114f4fc118df768372c3604e92d404c7c95ab6b25ada140c77dee976a890777", "price_changes": [{"asset_id": "114016092226346692646025674182722281295722777137086779627843163223516672173339", "price": "0.29", "size": "0", "side": "BUY", "hash": "bb8ce8a4a34b9dc07c9c902c8766e1fa87982868", "best_bid": "0.58", "best_ask": "0.76"}, {"asset_id": "95497640963223955548410937239974920841410215692686671066528121763996154872565", "price": "0.71", "size": "0", "side": "SELL", "hash": "6e07146b22d3893cac4d42ea1115f100475283c2", "best_bid": "0.24", "best_ask": "0.42"}], "timestamp": "1769384159112", "event_type": "price_change"}}
{"_local_timestamp": "2026-01-25T23:35:59.204764+00:00", "data": {"market": "0x11912cb7cc6561870be58a6a52be2943f3e86d2395032f064ef3091d6901882d", "price_changes": [{"asset_id": "50369611503686433705495168228906407585201475093386767089387389512232179527221", "price": "0.33", "size": "0", "side": "BUY", "hash": "052d00aef49ec286e5cffd2f624f13f87b26ce90", "best_bid": "0.75", "best_ask": "0.87"}, {"asset_id": "25107464912227300161765664477112846497546753335497087400297930691126705811916", "price": "0.67", "size": "0", "side": "SELL", "hash": "a51fe439bb1bb9ac2802e49e0e3d8fe4caa6ec90", "best_bid": "0.13", "best_ask": "0.25"}], "timestamp": "1769384159112", "event_type": "price_change"}}
{"_local_timestamp": "2026-01-25T23:35:59.205026+00:00", "data": {"market": "0xf6d98f9984cbd7994c5ad4b44b57e6e65771833e1f682cb6c08e1881cba0be23", "price_changes": [{"asset_id": "111619066987530654938781515834745418625505306643795368186113638707368057832687", "price": "0.32", "size": "0", "side": "BUY", "hash": "cb0c3f04530936a999cf6b269c4a139ad5d6e67a", "best_bid": "0.72", "best_ask": "0.88"}, {"asset_id": "14133747134142323771619199606203638420186745480544687065966512009432569296940", "price": "0.68", "size": "0", "side": "SELL", "hash": "e96564ac2154b3c98a2fa98e24efa46c85e40f9e", "best_bid": "0.12", "best_ask": "0.28"}], "timestamp": "1769384159112", "event_type": "price_change"}}
{"_local_timestamp": "2026-01-25T23:35:59.205309+00:00", "data": {"market": "0xb5f61d0c9ce431d64ba702815984246fa9cd6c2d6399849f0051d8695f2d98ab", "price_changes": [{"asset_id": "98590289222817581558553345992202318138659660940538324229915000516905381167250", "price": "0.35", "size": "0", "side": "BUY", "hash": "6bfb2ee89f642b6d8d4debe012965f1da01049b9", "best_bid": "0.76", "best_ask": "0.94"}, {"asset_id": "81582701062623199779039420976989567002417039977161919375131982089037196418005", "price": "0.65", "size": "0", "side": "SELL", "hash": "2a022f06a944cef387764d89fcf6b827a62cc236", "best_bid": "0.06", "best_ask": "0.24"}], "timestamp": "1769384159112", "event_type": "price_change"}}
{"_local_timestamp": "2026-01-25T23:35:59.217167+00:00", "data": {"market": "0x11912cb7cc6561870be58a6a52be2943f3e86d2395032f064ef3091d6901882d", "price_changes": [{"asset_id": "50369611503686433705495168228906407585201475093386767089387389512232179527221", "price": "0.39", "size": "20", "side": "BUY", "hash": "9013a38db74903a6f3883b12037dd5fa7e9d8815", "best_bid": "0.75", "best_ask": "0.87"}, {"asset_id": "25107464912227300161765664477112846497546753335497087400297930691126705811916", "price": "0.61", "size": "20", "side": "SELL", "hash": "a129712d951383719062f6fd69a6abc272fe8069", "best_bid": "0.13", "best_ask": "0.25"}], "timestamp": "1769384159138", "event_type": "price_change"}}
{"_local_timestamp": "2026-01-25T23:35:59.217747+00:00", "data": {"market": "0x86fec61dd9c27294756303c47b77cf6b7ed13ff4097e2967bc333dde4c1ea4da", "price_changes": [{"asset_id": "37660683447879901945455922570375098409697520769704430824022672297921367915347", "price": "0.44", "size": "20", "side": "BUY", "hash": "2095037d9039c029cd20ecdec1673f180426e462", "best_bid": "0.8", "best_ask": "0.94"}, {"asset_id": "63898934961262618957913174161832335092659130397470681441362226870577487706450", "price": "0.56", "size": "20", "side": "SELL", "hash": "e8d9d6db0b4139f0a3967a9ae0b9c37aebb0f7e5", "best_bid": "0.06", "best_ask": "0.2"}], "timestamp": "1769384159138", "event_type": "price_change"}}
{"_local_timestamp": "2026-01-25T23:35:59.218065+00:00", "data": {"market": "0xb5f61d0c9ce431d64ba702815984246fa9cd6c2d6399849f0051d8695f2d98ab", "price_changes": [{"asset_id": "98590289222817581558553345992202318138659660940538324229915000516905381167250", "price": "0.42", "size": "20", "side": "BUY", "hash": "60f381218bca7257f0dd5973da1c33f41e94c087", "best_bid": "0.76", "best_ask": "0.94"}, {"asset_id": "81582701062623199779039420976989567002417039977161919375131982089037196418005", "price": "0.58", "size": "20", "side": "SELL", "hash": "f809577dd754379e22f38ac56909630c22febaa2", "best_bid": "0.06", "best_ask": "0.24"}], "timestamp": "1769384159138", "event_type": "price_change"}}
{"_local_timestamp": "2026-01-25T23:35:59.218349+00:00", "data": {"market": "0xc114f4fc118df768372c3604e92d404c7c95ab6b25ada140c77dee976a890777", "price_changes": [{"asset_id": "114016092226346692646025674182722281295722777137086779627843163223516672173339", "price": "0.32", "size": "20", "side": "BUY", "hash": "1f48fc3c4fa591cf6a0a7493c053f270458bb5b8", "best_bid": "0.58", "best_ask": "0.76"}, {"asset_id": "95497640963223955548410937239974920841410215692686671066528121763996154872565", "price": "0.68", "size": "20", "side": "SELL", "hash": "9d029a8cff2722f8643d40a22a82f986da48579f", "best_bid": "0.24", "best_ask": "0.42"}], "timestamp": "1769384159138", "event_type": "price_change"}}
{"_local_timestamp": "2026-01-25T23:35:59.225072+00:00", "data": {"market": "0xf6d98f9984cbd7994c5ad4b44b57e6e65771833e1f682cb6c08e1881cba0be23", "price_changes": [{"asset_id": "111619066987530654938781515834745418625505306643795368186113638707368057832687", "price": "0.38", "size": "20", "side": "BUY", "hash": "deb2566d2155e282cf7c0404f6b1f02ca1ba2406", "best_bid": "0.72", "best_ask": "0.88"}, {"asset_id": "14133747134142323771619199606203638420186745480544687065966512009432569296940", "price": "0.62", "size": "20", "side": "SELL", "hash": "4e2016288050a37208ab774600462e7dbcfceb2a", "best_bid": "0.12", "best_ask": "0.28"}], "timestamp": "1769384159138", "event_type": "price_change"}}
{"_local_timestamp": "2026-01-25T23:36:50.077506+00:00", "data": {"market": "0xb5f61d0c9ce431d64ba702815984246fa9cd6c2d6399849f0051d8695f2d98ab", "price_changes": [{"asset_id": "81582701062623199779039420976989567002417039977161919375131982089037196418005", "price": "0.06", "size": "76.66", "side": "BUY", "hash": "a6aafa9fda4943ce10ab729f2253ad9f75fcfe81", "best_bid": "0.06", "best_ask": "0.24"}, {"asset_id": "98590289222817581558553345992202318138659660940538324229915000516905381167250", "price": "0.94", "size": "76.66", "side": "SELL", "hash": "f549f9bad452a5bec5925251e92f95d6449b89e1", "best_bid": "0.76", "best_ask": "0.94"}], "timestamp": "1769384210001", "event_type": "price_change"}}
{"_local_timestamp": "2026-01-25T23:36:50.087881+00:00", "data": {"market": "0xc114f4fc118df768372c3604e92d404c7c95ab6b25ada140c77dee976a890777", "price_changes": [{"asset_id": "95497640963223955548410937239974920841410215692686671066528121763996154872565", "price": "0.23", "size": "0", "side": "BUY", "hash": "b726149f08f86a8ea209415998d715fccf8b42d2", "best_bid": "0.24", "best_ask": "0.42"}, {"asset_id": "114016092226346692646025674182722281295722777137086779627843163223516672173339", "price": "0.77", "size": "0", "side": "SELL", "hash": "847afd4c2c55bff3bb123e5445e393ef418ad4ac", "best_bid": "0.58", "best_ask": "0.76"}], "timestamp": "1769384210002", "event_type": "price_change"}}
{"_local_timestamp": "2026-01-25T23:36:50.177004+00:00", "data": {"market": "0xb5f61d0c9ce431d64ba702815984246fa9cd6c2d6399849f0051d8695f2d98ab", "price_changes": [{"asset_id": "98590289222817581558553345992202318138659660940538324229915000516905381167250", "price": "0.1", "size": "0", "side": "BUY", "hash": "7cef00cce3b94f338f35bd43df4123076069a345", "best_bid": "0.76", "best_ask": "0.94"}, {"asset_id": "81582701062623199779039420976989567002417039977161919375131982089037196418005", "price": "0.9", "size": "0", "side": "SELL", "hash": "2dd2dfb49103f0336958aea9e32e6b8efa69dc3a", "best_bid": "0.06", "best_ask": "0.24"}], "timestamp": "1769384210110", "event_type": "price_change"}}
{"_local_timestamp": "2026-01-25T23:36:50.177531+00:00", "data": {"market": "0xf6d98f9984cbd7994c5ad4b44b57e6e65771833e1f682cb6c08e1881cba0be23", "price_changes": [{"asset_id": "111619066987530654938781515834745418625505306643795368186113638707368057832687", "price": "0.08", "size": "6.56", "side": "BUY", "hash": "4fb01a84137160a926157193c26b4766191809da", "best_bid": "0.72", "best_ask": "0.88"}, {"asset_id": "14133747134142323771619199606203638420186745480544687065966512009432569296940", "price": "0.92", "size": "6.56", "side": "SELL", "hash": "2898840c61e0c706e6ec5893ce66ebdbb6ba0cc8", "best_bid": "0.12", "best_ask": "0.28"}], "timestamp": "1769384210110", "event_type": "price_change"}}
{"_local_timestamp": "2026-01-25T23:36:50.192035+00:00", "data": {"market": "0x11912cb7cc6561870be58a6a52be2943f3e86d2395032f064ef3091d6901882d", "price_changes": [{"asset_id": "50369611503686433705495168228906407585201475093386767089387389512232179527221", "price": "0.08", "size": "0", "side": "BUY", "hash": "aa982d4476313778330a438313612f9f1ed43fa3", "best_bid": "0.75", "best_ask": "0.87"}, {"asset_id": "25107464912227300161765664477112846497546753335497087400297930691126705811916", "price": "0.92", "size": "0", "side": "SELL", "hash": "5615d4dd25a73255d4ab1d84202feda9d22af113", "best_bid": "0.13", "best_ask": "0.25"}], "timestamp": "1769384210111", "event_type": "price_change"}}
{"_local_timestamp": "2026-01-25T23:36:50.228867+00:00", "data": {"market": "0x11912cb7cc6561870be58a6a52be2943f3e86d2395032f064ef3091d6901882d", "price_changes": [{"asset_id": "50369611503686433705495168228906407585201475093386767089387389512232179527221", "price": "0.06", "size": "43", "side": "BUY", "hash": "9017a73553e4ec4e17dc42a10dbf6f24a4f3ec22", "best_bid": "0.75", "best_ask": "0.87"}, {"asset_id": "25107464912227300161765664477112846497546753335497087400297930691126705811916", "price": "0.94", "size": "43", "side": "SELL", "hash": "b04cd416b73acafb3413334c3110fc1c17605782", "best_bid": "0.13", "best_ask": "0.25"}], "timestamp": "1769384210159", "event_type": "price_change"}}
{"_local_timestamp": "2026-01-25T23:36:50.288693+00:00", "data": {"market": "0xb5f61d0c9ce431d64ba702815984246fa9cd6c2d6399849f0051d8695f2d98ab", "price_changes": [{"asset_id": "98590289222817581558553345992202318138659660940538324229915000516905381167250", "price": "0.23", "size": "0", "side": "BUY", "hash": "63dfa9a97fbaca1eb3e940e36eae78f121bc333d", "best_bid": "0.76", "best_ask": "0.94"}, {"asset_id": "81582701062623199779039420976989567002417039977161919375131982089037196418005", "price": "0.77", "size": "0", "side": "SELL", "hash": "1dd9daf61f43b69792f56e8d9b6472aa63dd93a3", "best_bid": "0.06", "best_ask": "0.24"}], "timestamp": "1769384210216", "event_type": "price_change"}}
{"_local_timestamp": "2026-01-25T23:36:50.356821+00:00", "data": {"market": "0xb5f61d0c9ce431d64ba702815984246fa9cd6c2d6399849f0051d8695f2d98ab", "price_changes": [{"asset_id": "98590289222817581558553345992202318138659660940538324229915000516905381167250", "price": "0.42", "size": "30", "side": "BUY", "hash": "f9b5fea37a7c21f7b80868cba4b77d07e62006e2", "best_bid": "0.76", "best_ask": "0.94"}, {"asset_id": "81582701062623199779039420976989567002417039977161919375131982089037196418005", "price": "0.58", "size": "30", "side": "SELL", "hash": "5fd193f8a29b79566ba49c3bd5b49182c7e1214b", "best_bid": "0.06", "best_ask": "0.24"}], "timestamp": "1769384210282", "event_type": "price_change"}}
{"_local_timestamp": "2026-01-25T23:36:50.357334+00:00", "data": {"market": "0xb5f61d0c9ce431d64ba702815984246fa9cd6c2d6399849f0051d8695f2d98ab", "price_changes": [{"asset_id": "98590289222817581558553345992202318138659660940538324229915000516905381167250", "price": "0.37", "size": "15", "side": "BUY", "hash": "9026dce46cf2bf79cede97d21b2cd6f11b8739ab", "best_bid": "0.76", "best_ask": "0.94"}, {"asset_id": "81582701062623199779039420976989567002417039977161919375131982089037196418005", "price": "0.63", "size": "15", "side": "SELL", "hash": "307a58990be90574d5ec21a4742037ca3270bbad", "best_bid": "0.06", "best_ask": "0.24"}], "timestamp": "1769384210283", "event_type": "price_change"}}
{"_local_timestamp": "2026-01-25T23:36:50.373108+00:00", "data": {"market": "0xb5f61d0c9ce431d64ba702815984246fa9cd6c2d6399849f0051d8695f2d98ab", "price_changes": [{"asset_id": "98590289222817581558553345992202318138659660940538324229915000516905381167250", "price": "0.1", "size": "10", "side": "BUY", "hash": "6d21019d01fe136d7136e976608c4d1f6828816b", "best_bid": "0.76", "best_ask": "0.94"}, {"asset_id": "81582701062623199779039420976989567002417039977161919375131982089037196418005", "price": "0.9", "size": "10", "side": "SELL", "hash": "79860b6cce26c7c04cedcdb0e8dc70e1f86f9e7e", "best_bid": "0.06", "best_ask": "0.24"}], "timestamp": "1769384210309", "event_type": "price_change"}}
{"_local_timestamp": "2026-01-25T23:36:50.876761+00:00", "data": {"market": "0xb5f61d0c9ce431d64ba702815984246fa9cd6c2d6399849f0051d8695f2d98ab", "price_changes": [{"asset_id": "98590289222817581558553345992202318138659660940538324229915000516905381167250", "price": "0.1", "size": "0", "side": "BUY", "hash": "4e6e1ce42c9cb4b3d0833b35f22ccb50034f482d", "best_bid": "0.76", "best_ask": "0.94"}, {"asset_id": "81582701062623199779039420976989567002417039977161919375131982089037196418005", "price": "0.9", "size": "0", "side": "SELL", "hash": "79cc2c402d567dc409920145e87f75b24a6458e6", "best_bid": "0.06", "best_ask": "0.24"}], "timestamp": "1769384210780", "event_type": "price_change"}}
{"_local_timestamp": "2026-01-25T23:36:53.779410+00:00", "data": {"market": "0xb5f61d0c9ce431d64ba702815984246fa9cd6c2d6399849f0051d8695f2d98ab", "price_changes": [{"asset_id": "98590289222817581558553345992202318138659660940538324229915000516905381167250", "price": "0.42", "size": "10", "side": "BUY", "hash": "5478621ac3796ff891ea2d14ce438694701a3431", "best_bid": "0.76", "best_ask": "0.94"}, {"asset_id": "81582701062623199779039420976989567002417039977161919375131982089037196418005", "price": "0.58", "size": "10", "side": "SELL", "hash": "131b94c6b3aa9476eb60cf1c957fa03796944df2", "best_bid": "0.06", "best_ask": "0.24"}], "timestamp": "1769384213709", "event_type": "price_change"}}
{"_local_timestamp": "2026-01-25T23:36:53.798442+00:00", "data": {"market": "0xb5f61d0c9ce431d64ba702815984246fa9cd6c2d6399849f0051d8695f2d98ab", "price_changes": [{"asset_id": "98590289222817581558553345992202318138659660940538324229915000516905381167250", "price": "0.43", "size": "20", "side": "BUY", "hash": "48a86f3c968badf02595a5c747a8882896c836bf", "best_bid": "0.76", "best_ask": "0.94"}, {"asset_id": "81582701062623199779039420976989567002417039977161919375131982089037196418005", "price": "0.57", "size": "20", "side": "SELL", "hash": "410bd9ea03ca4b59f6bd8154e7829a0c2f92f26d", "best_bid": "0.06", "best_ask": "0.24"}], "timestamp": "1769384213730", "event_type": "price_change"}}
{"_local_timestamp": "2026-01-25T23:36:53.856026+00:00", "data": {"market": "0xb5f61d0c9ce431d64ba702815984246fa9cd6c2d6399849f0051d8695f2d98ab", "price_changes": [{"asset_id": "98590289222817581558553345992202318138659660940538324229915000516905381167250", "price": "0.42", "size": "0", "side": "BUY", "hash": "57c9f5d798b78230ad2ae1e6797682c868c6b9a5", "best_bid": "0.76", "best_ask": "0.94"}, {"asset_id": "81582701062623199779039420976989567002417039977161919375131982089037196418005", "price": "0.58", "size": "0", "side": "SELL", "hash": "0ac04195e96c6f5a760a0daea0ed4c404a069c13", "best_bid": "0.06", "best_ask": "0.24"}], "timestamp": "1769384213788", "event_type": "price_change"}}
{"_local_timestamp": "2026-01-25T23:36:55.897945+00:00", "data": {"market": "0xc114f4fc118df768372c3604e92d404c7c95ab6b25ada140c77dee976a890777", "price_changes": [{"asset_id": "114016092226346692646025674182722281295722777137086779627843163223516672173339", "price": "0.01", "size": "3405.81", "side": "BUY", "hash": "32cd707edb7471ae0a529f1d827b13c9e76caf05", "best_bid": "0.58", "best_ask": "0.76"}, {"asset_id": "95497640963223955548410937239974920841410215692686671066528121763996154872565", "price": "0.99", "size": "3405.81", "side": "SELL", "hash": "e34b9bbb77bdd7b1a8b93f4fdca7215698bf86c4", "best_bid": "0.24", "best_ask": "0.42"}], "timestamp": "1769384215642", "event_type": "price_change"}}
{"_local_timestamp": "2026-01-25T23:36:55.977490+00:00", "data": {"market": "0x11912cb7cc6561870be58a6a52be2943f3e86d2395032f064ef3091d6901882d", "price_changes": [{"asset_id": "50369611503686433705495168228906407585201475093386767089387389512232179527221", "price": "0.05", "size": "530", "side": "BUY", "hash": "3229ac52b71c916d5c39d0b6c3e32f82d1e544ec", "best_bid": "0.75", "best_ask": "0.87"}, {"asset_id": "25107464912227300161765664477112846497546753335497087400297930691126705811916", "price": "0.95", "size": "530", "side": "SELL", "hash": "23e29aac421a15f28e3ceabe307017016505fbb2", "best_bid": "0.13", "best_ask": "0.25"}], "timestamp": "1769384215652", "event_type": "price_change"}}
{"_local_timestamp": "2026-01-25T23:36:56.391920+00:00", "data": {"market": "0xb5f61d0c9ce431d64ba702815984246fa9cd6c2d6399849f0051d8695f2d98ab", "price_changes": [{"asset_id": "98590289222817581558553345992202318138659660940538324229915000516905381167250", "price": "0.37", "size": "0", "side": "BUY", "hash": "8f81b50082ae0d47ecd3bd28120e952b7cf303d0", "best_bid": "0.76", "best_ask": "0.94"}, {"asset_id": "81582701062623199779039420976989567002417039977161919375131982089037196418005", "price": "0.63", "size": "0", "side": "SELL", "hash": "255b459eea87528e8ca2c1a455f098dc5e7fdb23", "best_bid": "0.06", "best_ask": "0.24"}], "timestamp": "1769384216015", "event_type": "price_change"}}
{"_local_timestamp": "2026-01-25T23:36:56.511180+00:00", "data": {"market": "0xb5f61d0c9ce431d64ba702815984246fa9cd6c2d6399849f0051d8695f2d98ab", "price_changes": [{"asset_id": "98590289222817581558553345992202318138659660940538324229915000516905381167250", "price": "0.37", "size": "10", "side": "BUY", "hash": "84be897156fb1ed825c6bb4062f844f6c7e03545", "best_bid": "0.76", "best_ask": "0.94"}, {"asset_id": "81582701062623199779039420976989567002417039977161919375131982089037196418005", "price": "0.63", "size": "10", "side": "SELL", "hash": "d906c05a25f35f535c234dae51d8b1c81ac1afe6", "best_bid": "0.06", "best_ask": "0.24"}], "timestamp": "1769384216445", "event_type": "price_change"}}
{"_local_timestamp": "2026-01-25T23:36:56.511518+00:00", "data": {"market": "0xb5f61d0c9ce431d64ba702815984246fa9cd6c2d6399849f0051d8695f2d98ab", "price_changes": [{"asset_id": "98590289222817581558553345992202318138659660940538324229915000516905381167250", "price": "0.35", "size": "15", "side": "BUY", "hash": "a2cee80d8ea544621838e30822ef5d23798ec277", "best_bid": "0.76", "best_ask": "0.94"}, {"asset_id": "81582701062623199779039420976989567002417039977161919375131982089037196418005", "price": "0.65", "size": "15", "side": "SELL", "hash": "620fd6b3af3583449df7cd285428452ec6ea090a", "best_bid": "0.06", "best_ask": "0.24"}], "timestamp": "1769384216446", "event_type": "price_change"}}
{"_local_timestamp": "2026-01-25T23:36:56.527184+00:00", "data": {"market": "0xb5f61d0c9ce431d64ba702815984246fa9cd6c2d6399849f0051d8695f2d98ab", "price_changes": [{"asset_id": "98590289222817581558553345992202318138659660940538324229915000516905381167250", "price": "0.1", "size": "10", "side": "BUY", "hash": "b25e7c9392981f456ad5bbebb05a2223efc369b8", "best_bid": "0.76", "best_ask": "0.94"}, {"asset_id": "81582701062623199779039420976989567002417039977161919375131982089037196418005", "price": "0.9", "size": "10", "side": "SELL", "hash": "fae9dd5cbb56fd3435acd1d23b9f4c7cb7b26318", "best_bid": "0.06", "best_ask": "0.24"}], "timestamp": "1769384216462", "event_type": "price_change"}}
{"_local_timestamp": "2026-01-25T23:36:57.037142+00:00", "data": {"market": "0xb5f61d0c9ce431d64ba702815984246fa9cd6c2d6399849f0051d8695f2d98ab", "price_changes": [{"asset_id": "98590289222817581558553345992202318138659660940538324229915000516905381167250", "price": "0.1", "size": "0", "side": "BUY", "hash": "9e0cd91bb2832f15e8ac5d6e6486599b06e43fe9", "best_bid": "0.76", "best_ask": "0.94"}, {"asset_id": "81582701062623199779039420976989567002417039977161919375131982089037196418005", "price": "0.9", "size": "0", "side": "SELL", "hash": "638d1a1abbd43e3dcdeb763bed20fa7017ccbd0d", "best_bid": "0.06", "best_ask": "0.24"}], "timestamp": "1769384216938", "event_type": "price_change"}}
{"_local_timestamp": "2026-01-25T23:36:57.509848+00:00", "data": {"market": "0x86fec61dd9c27294756303c47b77cf6b7ed13ff4097e2967bc333dde4c1ea4da", "price_changes": [{"asset_id": "37660683447879901945455922570375098409697520769704430824022672297921367915347", "price": "0.18", "size": "5.66", "side": "BUY", "hash": "85b4c6d5569bb852b2eeee24a1f88a737673e39d", "best_bid": "0.8", "best_ask": "0.94"}, {"asset_id": "63898934961262618957913174161832335092659130397470681441362226870577487706450", "price": "0.82", "size": "5.66", "side": "SELL", "hash": "6d79bb623cf51e167960542a1745bf5b9d7d6f4d", "best_bid": "0.06", "best_ask": "0.2"}], "timestamp": "1769384217223", "event_type": "price_change"}}
{"_local_timestamp": "2026-01-25T23:36:57.633945+00:00", "data": {"market": "0xb5f61d0c9ce431d64ba702815984246fa9cd6c2d6399849f0051d8695f2d98ab", "price_changes": [{"asset_id": "98590289222817581558553345992202318138659660940538324229915000516905381167250", "price": "0.22", "size": "0", "side": "BUY", "hash": "afd99841306c0814654882c09be0a2adf100773c", "best_bid": "0.76", "best_ask": "0.94"}, {"asset_id": "81582701062623199779039420976989567002417039977161919375131982089037196418005", "price": "0.78", "size": "0", "side": "SELL", "hash": "8cf0c704c77f4a3e57de247f9cad5a00dffa4012", "best_bid": "0.06", "best_ask": "0.24"}], "timestamp": "1769384217223", "event_type": "price_change"}}
{"_local_timestamp": "2026-01-25T23:36:57.637081+00:00", "data": {"market": "0xb5f61d0c9ce431d64ba702815984246fa9cd6c2d6399849f0051d8695f2d98ab", "price_changes": [{"asset_id": "98590289222817581558553345992202318138659660940538324229915000516905381167250", "price": "0.43", "size": "0", "side": "BUY", "hash": "1abacd2c52c02230bdf8107c9c09b59ccbb9f816", "best_bid": "0.76", "best_ask": "0.94"}, {"asset_id": "81582701062623199779039420976989567002417039977161919375131982089037196418005", "price": "0.57", "size": "0", "side": "SELL", "hash": "af786a83e256774f5195036633d028760cb48e92", "best_bid": "0.06", "best_ask": "0.24"}], "timestamp": "1769384217274", "event_type": "price_change"}}
{"_local_timestamp": "2026-01-25T23:36:57.813935+00:00", "data": {"market": "0xb5f61d0c9ce431d64ba702815984246fa9cd6c2d6399849f0051d8695f2d98ab", "price_changes": [{"asset_id": "98590289222817581558553345992202318138659660940538324229915000516905381167250", "price": "0.42", "size": "20", "side": "BUY", "hash": "8be9e25203a8a924199c6770496b53cdfbcf3b61", "best_bid": "0.76", "best_ask": "0.94"}, {"asset_id": "81582701062623199779039420976989567002417039977161919375131982089037196418005", "price": "0.58", "size": "20", "side": "SELL", "hash": "cae4332f0b50cc7603e78c07f0dd9c93993b63ea", "best_bid": "0.06", "best_ask": "0.24"}], "timestamp": "1769384217306", "event_type": "price_change"}}
{"_local_timestamp": "2026-01-25T23:36:57.893449+00:00", "data": {"market": "0xb5f61d0c9ce431d64ba702815984246fa9cd6c2d6399849f0051d8695f2d98ab", "price_changes": [{"asset_id": "98590289222817581558553345992202318138659660940538324229915000516905381167250", "price": "0.1", "size": "10", "side": "BUY", "hash": "61b89d8395dedd70ce1860d568c5d547e74137d3", "best_bid": "0.76", "best_ask": "0.94"}, {"asset_id": "81582701062623199779039420976989567002417039977161919375131982089037196418005", "price": "0.9", "size": "10", "side": "SELL", "hash": "16bd3a441a1331623498677928e180f8a9db4e3d", "best_bid": "0.06", "best_ask": "0.24"}], "timestamp": "1769384217685", "event_type": "price_change"}}
{"_local_timestamp": "2026-01-25T23:36:58.332930+00:00", "data": {"market": "0xb5f61d0c9ce431d64ba702815984246fa9cd6c2d6399849f0051d8695f2d98ab", "price_changes": [{"asset_id": "98590289222817581558553345992202318138659660940538324229915000516905381167250", "price": "0.42", "size": "0", "side": "BUY", "hash": "7f492db4b029cbca1eb89c049bc67afe08bd5160", "best_bid": "0.76", "best_ask": "0.94"}, {"asset_id": "81582701062623199779039420976989567002417039977161919375131982089037196418005", "price": "0.58", "size": "0", "side": "SELL", "hash": "7df10fcc47510e2d8a8ea4c55cfa8715500c0aaa", "best_bid": "0.06", "best_ask": "0.24"}], "timestamp": "1769384218150", "event_type": "price_change"}}
{"_local_timestamp": "2026-01-25T23:36:58.346008+00:00", "data": {"market": "0xb5f61d0c9ce431d64ba702815984246fa9cd6c2d6399849f0051d8695f2d98ab", "price_changes": [{"asset_id": "98590289222817581558553345992202318138659660940538324229915000516905381167250", "price": "0.44", "size": "20", "side": "BUY", "hash": "c64b698f7082d702fabf68791671d9b13df87787", "best_bid": "0.76", "best_ask": "0.94"}, {"asset_id": "81582701062623199779039420976989567002417039977161919375131982089037196418005", "price": "0.56", "size": "20", "side": "SELL", "hash": "4c9463ade572fd763337deafdcdc8bb612a89b22", "best_bid": "0.06", "best_ask": "0.24"}], "timestamp": "1769384218180", "event_type": "price_change"}}
{"_local_timestamp": "2026-01-25T23:37:02.774840+00:00", "data": {"market": "0xb5f61d0c9ce431d64ba702815984246fa9cd6c2d6399849f0051d8695f2d98ab", "price_changes": [{"asset_id": "98590289222817581558553345992202318138659660940538324229915000516905381167250", "price": "0.44", "size": "0", "side": "BUY", "hash": "4cb311699fbc4475062f21bc59dfaf6f795e37ae", "best_bid": "0.76", "best_ask": "0.94"}, {"asset_id": "81582701062623199779039420976989567002417039977161919375131982089037196418005", "price": "0.56", "size": "0", "side": "SELL", "hash": "48adc8bc611df32632b6c2b5d5f8f3c0ffde8961", "best_bid": "0.06", "best_ask": "0.24"}], "timestamp": "1769384222705", "event_type": "price_change"}}
{"_local_timestamp": "2026-01-25T23:37:02.804369+00:00", "data": {"market": "0xb5f61d0c9ce431d64ba702815984246fa9cd6c2d6399849f0051d8695f2d98ab", "price_changes": [{"asset_id": "98590289222817581558553345992202318138659660940538324229915000516905381167250", "price": "0.42", "size": "20", "side": "BUY", "hash": "3a5e83eb0512a7ba9dfedc808f61b527b4cfbca6", "best_bid": "0.76", "best_ask": "0.94"}, {"asset_id": "81582701062623199779039420976989567002417039977161919375131982089037196418005", "price": "0.58", "size": "20", "side": "SELL", "hash": "d211d7342e18c31a779769195c06610808d7566a", "best_bid": "0.06", "best_ask": "0.24"}], "timestamp": "1769384222733", "event_type": "price_change"}}
{"_local_timestamp": "2026-01-25T23:37:02.883527+00:00", "data": {"market": "0xf6d98f9984cbd7994c5ad4b44b57e6e65771833e1f682cb6c08e1881cba0be23", "price_changes": [{"asset_id": "111619066987530654938781515834745418625505306643795368186113638707368057832687", "price": "0.3", "size": "0", "side": "BUY", "hash": "ba5c03cd9118b8498c657788365e43dd95829438", "best_bid": "0.72", "best_ask": "0.88"}, {"asset_id": "14133747134142323771619199606203638420186745480544687065966512009432569296940", "price": "0.7", "size": "0", "side": "SELL", "hash": "45d0de128fc73ce4df75a0dc2f5e6dba394531b8", "best_bid": "0.12", "best_ask": "0.28"}], "timestamp": "1769384222811", "event_type": "price_change"}}
{"_local_timestamp": "2026-01-25T23:37:32.638037+00:00", "data": {"market": "0xf6d98f9984cbd7994c5ad4b44b57e6e65771833e1f682cb6c08e1881cba0be23", "price_changes": [{"asset_id": "111619066987530654938781515834745418625505306643795368186113638707368057832687", "price": "0.01", "size": "2505.92", "side": "BUY", "hash": "1e7ffcdd65a0e0f813a7b50ea21ef1950971601b", "best_bid": "0.72", "best_ask": "0.88"}, {"asset_id": "14133747134142323771619199606203638420186745480544687065966512009432569296940", "price": "0.99", "size": "2505.92", "side": "SELL", "hash": "c73f36ee9c21a9a85f05797b9253619e28f3a007", "best_bid": "0.12", "best_ask": "0.28"}], "timestamp": "1769384252544", "event_type": "price_change"}}
{"_local_timestamp": "2026-01-25T23:37:34.356831+00:00", "data": {"market": "0x86fec61dd9c27294756303c47b77cf6b7ed13ff4097e2967bc333dde4c1ea4da", "price_changes": [{"asset_id": "37660683447879901945455922570375098409697520769704430824022672297921367915347", "price": "0.11", "size": "5", "side": "BUY", "hash": "a8798988d37759716af06bb284ab6e453f244fa3", "best_bid": "0.8", "best_ask": "0.94"}, {"asset_id": "63898934961262618957913174161832335092659130397470681441362226870577487706450", "price": "0.89", "size": "5", "side": "SELL", "hash": "a33710c07dfcef2f5784d9e16c9251ceac2e6609", "best_bid": "0.06", "best_ask": "0.2"}], "timestamp": "1769384254288", "event_type": "price_change"}}
{"_local_timestamp": "2026-01-25T23:37:34.357338+00:00", "data": {"market": "0xb5f61d0c9ce431d64ba702815984246fa9cd6c2d6399849f0051d8695f2d98ab", "price_changes": [{"asset_id": "98590289222817581558553345992202318138659660940538324229915000516905381167250", "price": "0.1", "size": "62", "side": "BUY", "hash": "91a62e2c52d184a2b6fdd4241871bfbb2d88575c", "best_bid": "0.76", "best_ask": "0.94"}, {"asset_id": "81582701062623199779039420976989567002417039977161919375131982089037196418005", "price": "0.9", "size": "62", "side": "SELL", "hash": "e4899d9d3e02edf8266267ec7d2846ec3619d04f", "best_bid": "0.06", "best_ask": "0.24"}], "timestamp": "1769384254288", "event_type": "price_change"}}
{"_local_timestamp": "2026-01-25T23:37:40.114332+00:00", "data": {"market": "0xb5f61d0c9ce431d64ba702815984246fa9cd6c2d6399849f0051d8695f2d98ab", "price_changes": [{"asset_id": "98590289222817581558553345992202318138659660940538324229915000516905381167250", "price": "0.76", "size": "0", "side": "BUY", "hash": "6de84479016408b0e6b47839bb2063a58872e8bd", "best_bid": "0.42", "best_ask": "0.94"}, {"asset_id": "81582701062623199779039420976989567002417039977161919375131982089037196418005", "price": "0.24", "size": "0", "side": "SELL", "hash": "65121db6d45cbb2eb76bbb24f87aff944a0cec25", "best_bid": "0.06", "best_ask": "0.58"}], "timestamp": "1769384260003", "event_type": "price_change"}}
{"_local_timestamp": "2026-01-25T23:37:40.114678+00:00", "data": {"market": "0xc114f4fc118df768372c3604e92d404c7c95ab6b25ada140c77dee976a890777", "price_changes": [{"asset_id": "114016092226346692646025674182722281295722777137086779627843163223516672173339", "price": "0.58", "size": "0", "side": "BUY", "hash": "2c5419b55bc0bb8acc5541a053dd24ac1e77aa7d", "best_bid": "0.32", "best_ask": "0.76"}, {"asset_id": "95497640963223955548410937239974920841410215692686671066528121763996154872565", "price": "0.42", "size": "0", "side": "SELL", "hash": "88d25ca0794d18b43c6457862d0fb11b78ebd7e6", "best_bid": "0.24", "best_ask": "0.68"}], "timestamp": "1769384260004", "event_type": "price_change"}}
{"_local_timestamp": "2026-01-25T23:37:40.117334+00:00", "data": {"market": "0xf6d98f9984cbd7994c5ad4b44b57e6e65771833e1f682cb6c08e1881cba0be23", "price_changes": [{"asset_id": "111619066987530654938781515834745418625505306643795368186113638707368057832687", "price": "0.72", "size": "0", "side": "BUY", "hash": "10edb3025d3e814b2f67c440a122d6389933c12c", "best_bid": "0.46", "best_ask": "0.88"}, {"asset_id": "14133747134142323771619199606203638420186745480544687065966512009432569296940", "price": "0.28", "size": "0", "side": "SELL", "hash": "f5c5e205a2b5e0551741d2b4e38f08f91e0d89a3", "best_bid": "0.12", "best_ask": "0.54"}], "timestamp": "1769384260004", "event_type": "price_change"}}
{"_local_timestamp": "2026-01-25T23:37:40.125382+00:00", "data": {"market": "0x11912cb7cc6561870be58a6a52be2943f3e86d2395032f064ef3091d6901882d", "price_changes": [{"asset_id": "50369611503686433705495168228906407585201475093386767089387389512232179527221", "price": "0.75", "size": "0", "side": "BUY", "hash": "998dbedd7497a674a8981a114361534fe9044212", "best_bid": "0.39", "best_ask": "0.87"}, {"asset_id": "25107464912227300161765664477112846497546753335497087400297930691126705811916", "price": "0.25", "size": "0", "side": "SELL", "hash": "26d4e4df0cb7cc5226d73e47365d7f7683305d5a", "best_bid": "0.13", "best_ask": "0.61"}], "timestamp": "1769384260005", "event_type": "price_change"}}
{"_local_timestamp": "2026-01-25T23:37:40.178639+00:00", "data": {"market": "0x86fec61dd9c27294756303c47b77cf6b7ed13ff4097e2967bc333dde4c1ea4da", "price_changes": [{"asset_id": "37660683447879901945455922570375098409697520769704430824022672297921367915347", "price": "0.8", "size": "0", "side": "BUY", "hash": "03f11388533d6104bd01b988c66aa22f81c8de6c", "best_bid": "0.44", "best_ask": "0.94"}, {"asset_id": "63898934961262618957913174161832335092659130397470681441362226870577487706450", "price": "0.2", "size": "0", "side": "SELL", "hash": "e227caaf89b316c3d7b91cd56f698c668992251e", "best_bid": "0.06", "best_ask": "0.56"}], "timestamp": "1769384260002", "event_type": "price_change"}}
{"_local_timestamp": "2026-01-25T23:38:35.650701+00:00", "data": {"market": "0xb5f61d0c9ce431d64ba702815984246fa9cd6c2d6399849f0051d8695f2d98ab", "price_changes": [{"asset_id": "81582701062623199779039420976989567002417039977161919375131982089037196418005", "price": "0.06", "size": "126.66", "side": "BUY", "hash": "adaaefbf752a4dfd41e541d0dc99dd17e9c2039f", "best_bid": "0.06", "best_ask": "0.58"}, {"asset_id": "98590289222817581558553345992202318138659660940538324229915000516905381167250", "price": "0.94", "size": "126.66", "side": "SELL", "hash": "726407939d52b5e3285c57b9cb166f6135a68e4a", "best_bid": "0.42", "best_ask": "0.94"}], "timestamp": "1769384315578", "event_type": "price_change"}}
{"_local_timestamp": "2026-01-25T23:38:35.651372+00:00", "data": {"market": "0xc114f4fc118df768372c3604e92d404c7c95ab6b25ada140c77dee976a890777", "price_changes": [{"asset_id": "95497640963223955548410937239974920841410215692686671066528121763996154872565", "price": "0.23", "size": "50", "side": "BUY", "hash": "aab581050d6f7fea722d645219cc2d78ed88cbca", "best_bid": "0.24", "best_ask": "0.68"}, {"asset_id": "114016092226346692646025674182722281295722777137086779627843163223516672173339", "price": "0.77", "size": "50", "side": "SELL", "hash": "995f72b8031c43409e57d8e022a10a67e94eb687", "best_bid": "0.32", "best_ask": "0.76"}], "timestamp": "1769384315578", "event_type": "price_change"}}
{"_local_timestamp": "2026-01-25T23:38:35.770757+00:00", "data": {"market": "0xf6d98f9984cbd7994c5ad4b44b57e6e65771833e1f682cb6c08e1881cba0be23", "price_changes": [{"asset_id": "111619066987530654938781515834745418625505306643795368186113638707368057832687", "price": "0.08", "size": "16.56", "side": "BUY", "hash": "5f68869bc2dc317b829e00f5e7ac6bfde399e810", "best_bid": "0.46", "best_ask": "0.88"}, {"asset_id": "14133747134142323771619199606203638420186745480544687065966512009432569296940", "price": "0.92", "size": "16.56", "side": "SELL", "hash": "876b1cc2c97983edf29c9facaabdff5db2ab830a", "best_bid": "0.12", "best_ask": "0.54"}], "timestamp": "1769384315701", "event_type": "price_change"}}
{"_local_timestamp": "2026-01-25T23:38:40.019310+00:00", "data": {"market": "0xb5f61d0c9ce431d64ba702815984246fa9cd6c2d6399849f0051d8695f2d98ab", "price_changes": [{"asset_id": "98590289222817581558553345992202318138659660940538324229915000516905381167250", "price": "0.41", "size": "0", "side": "BUY", "hash": "7dfd337978b68d6afebebbb2d6b860cf0f132a03", "best_bid": "0.42", "best_ask": "0.94"}, {"asset_id": "81582701062623199779039420976989567002417039977161919375131982089037196418005", "price": "0.59", "size": "0", "side": "SELL", "hash": "a8ca93ecfa0809a87f021a27526e2d85b4c6d4e8", "best_bid": "0.06", "best_ask": "0.58"}], "timestamp": "1769384319952", "event_type": "price_change"}}
{"_local_timestamp": "2026-01-25T23:38:40.021401+00:00", "data": {"market": "0xb5f61d0c9ce431d64ba702815984246fa9cd6c2d6399849f0051d8695f2d98ab", "price_changes": [{"asset_id": "98590289222817581558553345992202318138659660940538324229915000516905381167250", "price": "0.08", "size": "0", "side": "BUY", "hash": "7dfd337978b68d6afebebbb2d6b860cf0f132a03", "best_bid": "0.42", "best_ask": "0.94"}, {"asset_id": "81582701062623199779039420976989567002417039977161919375131982089037196418005", "price": "0.92", "size": "0", "side": "SELL", "hash": "a8ca93ecfa0809a87f021a27526e2d85b4c6d4e8", "best_bid": "0.06", "best_ask": "0.58"}], "timestamp": "1769384319952", "event_type": "price_change"}}
{"_local_timestamp": "2026-01-25T23:38:40.021701+00:00", "data": {"market": "0x86fec61dd9c27294756303c47b77cf6b7ed13ff4097e2967bc333dde4c1ea4da", "price_changes": [{"asset_id": "37660683447879901945455922570375098409697520769704430824022672297921367915347", "price": "0.43", "size": "0", "side": "BUY", "hash": "114d04452ddab49dcadd3d38902db3c226028a6e", "best_bid": "0.44", "best_ask": "0.94"}, {"asset_id": "63898934961262618957913174161832335092659130397470681441362226870577487706450", "price": "0.57", "size": "0", "side": "SELL", "hash": "e5b3869c64410d88518b86ef4b33e6cd6f93362a", "best_bid": "0.06", "best_ask": "0.56"}], "timestamp": "1769384319952", "event_type": "price_change"}}
{"_local_timestamp": "2026-01-25T23:38:40.021980+00:00", "data": {"market": "0x86fec61dd9c27294756303c47b77cf6b7ed13ff4097e2967bc333dde4c1ea4da", "price_changes": [{"asset_id": "37660683447879901945455922570375098409697520769704430824022672297921367915347", "price": "0.08", "size": "100", "side": "BUY", "hash": "114d04452ddab49dcadd3d38902db3c226028a6e", "best_bid": "0.44", "best_ask": "0.94"}, {"asset_id": "63898934961262618957913174161832335092659130397470681441362226870577487706450", "price": "0.92", "size": "100", "side": "SELL", "hash": "e5b3869c64410d88518b86ef4b33e6cd6f93362a", "best_bid": "0.06", "best_ask": "0.56"}], "timestamp": "1769384319952", "event_type": "price_change"}}
{"_local_timestamp": "2026-01-25T23:38:40.022255+00:00", "data": {"market": "0xf6d98f9984cbd7994c5ad4b44b57e6e65771833e1f682cb6c08e1881cba0be23", "price_changes": [{"asset_id": "111619066987530654938781515834745418625505306643795368186113638707368057832687", "price": "0.37", "size": "0", "side": "BUY", "hash": "9787f9a0b6f2e4871b3dc593bb94c68044cb00b1", "best_bid": "0.46", "best_ask": "0.88"}, {"asset_id": "14133747134142323771619199606203638420186745480544687065966512009432569296940", "price": "0.63", "size": "0", "side": "SELL", "hash": "e93784cb2052bbf0e72902120d2a4141514a3c46", "best_bid": "0.12", "best_ask": "0.54"}], "timestamp": "1769384319952", "event_type": "price_change"}}
{"_local_timestamp": "2026-01-25T23:38:40.026897+00:00", "data": {"market": "0xf6d98f9984cbd7994c5ad4b44b57e6e65771833e1f682cb6c08e1881cba0be23", "price_changes": [{"asset_id": "111619066987530654938781515834745418625505306643795368186113638707368057832687", "price": "0.01", "size": "2405.92", "side": "BUY", "hash": "9787f9a0b6f2e4871b3dc593bb94c68044cb00b1", "best_bid": "0.46", "best_ask": "0.88"}, {"asset_id": "14133747134142323771619199606203638420186745480544687065966512009432569296940", "price": "0.99", "size": "2405.92", "side": "SELL", "hash": "e93784cb2052bbf0e72902120d2a4141514a3c46", "best_bid": "0.12", "best_ask": "0.54"}], "timestamp": "1769384319952", "event_type": "price_change"}}
{"_local_timestamp": "2026-01-25T23:38:40.027266+00:00", "data": {"market": "0x11912cb7cc6561870be58a6a52be2943f3e86d2395032f064ef3091d6901882d", "price_changes": [{"asset_id": "50369611503686433705495168228906407585201475093386767089387389512232179527221", "price": "0.38", "size": "0", "side": "BUY", "hash": "53e31e3c0a55833b26fdd07c9bbd7764c9eb0f70", "best_bid": "0.39", "best_ask": "0.87"}, {"asset_id": "25107464912227300161765664477112846497546753335497087400297930691126705811916", "price": "0.62", "size": "0", "side": "SELL", "hash": "aaf8cdf0a273762136ff1ae8c650c633662b9a32", "best_bid": "0.13", "best_ask": "0.61"}], "timestamp": "1769384319952", "event_type": "price_change"}}
{"_local_timestamp": "2026-01-25T23:38:40.027586+00:00", "data": {"market": "0x11912cb7cc6561870be58a6a52be2943f3e86d2395032f064ef3091d6901882d", "price_changes": [{"asset_id": "50369611503686433705495168228906407585201475093386767089387389512232179527221", "price": "0.01", "size": "3105.48", "side": "BUY", "hash": "53e31e3c0a55833b26fdd07c9bbd7764c9eb0f70", "best_bid": "0.39", "best_ask": "0.87"}, {"asset_id": "25107464912227300161765664477112846497546753335497087400297930691126705811916", "price": "0.99", "size": "3105.48", "side": "SELL", "hash": "aaf8cdf0a273762136ff1ae8c650c633662b9a32", "best_bid": "0.13", "best_ask": "0.61"}], "timestamp": "1769384319952", "event_type": "price_change"}}
{"_local_timestamp": "2026-01-25T23:38:40.027844+00:00", "data": {"market": "0xc114f4fc118df768372c3604e92d404c7c95ab6b25ada140c77dee976a890777", "price_changes": [{"asset_id": "114016092226346692646025674182722281295722777137086779627843163223516672173339", "price": "0.31", "size": "0", "side": "BUY", "hash": "0d65d7194a36dfa9bd67ad1a20e1090cf36011a1", "best_bid": "0.32", "best_ask": "0.76"}, {"asset_id": "95497640963223955548410937239974920841410215692686671066528121763996154872565", "price": "0.69", "size": "0", "side": "SELL", "hash": "e39178425962f260f06c457fb56dd68558c03ff9", "best_bid": "0.24", "best_ask": "0.68"}], "timestamp": "1769384319952", "event_type": "price_change"}}
{"_local_timestamp": "2026-01-25T23:38:40.028107+00:00", "data": {"market": "0xc114f4fc118df768372c3604e92d404c7c95ab6b25ada140c77dee976a890777", "price_changes": [{"asset_id": "114016092226346692646025674182722281295722777137086779627843163223516672173339", "price": "0.05", "size": "330", "side": "BUY", "hash": "0d65d7194a36dfa9bd67ad1a20e1090cf36011a1", "best_bid": "0.32", "best_ask": "0.76"}, {"asset_id": "95497640963223955548410937239974920841410215692686671066528121763996154872565", "price": "0.95", "size": "330", "side": "SELL", "hash": "e39178425962f260f06c457fb56dd68558c03ff9", "best_bid": "0.24", "best_ask": "0.68"}], "timestamp": "1769384319952", "event_type": "price_change"}}
{"_local_timestamp": "2026-01-25T23:38:42.333251+00:00", "data": {"market": "0x11912cb7cc6561870be58a6a52be2943f3e86d2395032f064ef3091d6901882d", "price_changes": [{"asset_id": "50369611503686433705495168228906407585201475093386767089387389512232179527221", "price": "0.4", "size": "66.66", "side": "BUY", "hash": "8c06aedd92844622e97cfc003eae75190d8ab2cc", "best_bid": "0.4", "best_ask": "0.87"}, {"asset_id": "25107464912227300161765664477112846497546753335497087400297930691126705811916", "price": "0.6", "size": "66.66", "side": "SELL", "hash": "9feab941f45129e38db055ed45473847bd5998b8", "best_bid": "0.13", "best_ask": "0.6"}], "timestamp": "1769384322249", "event_type": "price_change"}}
{"_local_timestamp": "2026-01-25T23:38:42.378656+00:00", "data": {"market": "0xf6d98f9984cbd7994c5ad4b44b57e6e65771833e1f682cb6c08e1881cba0be23", "price_changes": [{"asset_id": "111619066987530654938781515834745418625505306643795368186113638707368057832687", "price": "0.46", "size": "96.66", "side": "BUY", "hash": "d843790516233da62ef0abd1f69bc867c18451cb", "best_bid": "0.46", "best_ask": "0.88"}, {"asset_id": "14133747134142323771619199606203638420186745480544687065966512009432569296940", "price": "0.54", "size": "96.66", "side": "SELL", "hash": "bdddf71ef883d5c673903f2344171d45ac3c2566", "best_bid": "0.12", "best_ask": "0.54"}], "timestamp": "1769384322297", "event_type": "price_change"}}
{"_local_timestamp": "2026-01-25T23:38:42.473049+00:00", "data": {"market": "0xb5f61d0c9ce431d64ba702815984246fa9cd6c2d6399849f0051d8695f2d98ab", "price_changes": [{"asset_id": "98590289222817581558553345992202318138659660940538324229915000516905381167250", "price": "0.43", "size": "66.66", "side": "BUY", "hash": "9be7dc5f5e3790f24f06f626b42e1e8c1edd4c66", "best_bid": "0.43", "best_ask": "0.94"}, {"asset_id": "81582701062623199779039420976989567002417039977161919375131982089037196418005", "price": "0.57", "size": "66.66", "side": "SELL", "hash": "727d32faedd486beb04b6a12734b5a9806f908d4", "best_bid": "0.06", "best_ask": "0.57"}], "timestamp": "1769384322397", "event_type": "price_change"}}
{"_local_timestamp": "2026-01-25T23:38:42.536123+00:00", "data": {"market": "0x11912cb7cc6561870be58a6a52be2943f3e86d2395032f064ef3091d6901882d", "price_changes": [{"asset_id": "50369611503686433705495168228906407585201475093386767089387389512232179527221", "price": "0.2", "size": "66.66", "side": "BUY", "hash": "26fc622e25c576a7ee15c369bf272c1af9373a94", "best_bid": "0.4", "best_ask": "0.87"}, {"asset_id": "25107464912227300161765664477112846497546753335497087400297930691126705811916", "price": "0.8", "size": "66.66", "side": "SELL", "hash": "db4e856b0cbd0601e71c6570e1b68723b802e3d4", "best_bid": "0.13", "best_ask": "0.6"}], "timestamp": "1769384322454", "event_type": "price_change"}}
{"_local_timestamp": "2026-01-25T23:38:42.584517+00:00", "data": {"market": "0xf6d98f9984cbd7994c5ad4b44b57e6e65771833e1f682cb6c08e1881cba0be23", "price_changes": [{"asset_id": "111619066987530654938781515834745418625505306643795368186113638707368057832687", "price": "0.24", "size": "66.66", "side": "BUY", "hash": "b0b994f33bd93954fc1568bc3b1ff5904b97c59e", "best_bid": "0.46", "best_ask": "0.88"}, {"asset_id": "14133747134142323771619199606203638420186745480544687065966512009432569296940", "price": "0.76", "size": "66.66", "side": "SELL", "hash": "046fbdca60f1ef2fbfe7368f856f5b8aa1c507f2", "best_bid": "0.12", "best_ask": "0.54"}], "timestamp": "1769384322511", "event_type": "price_change"}}
{"_local_timestamp": "2026-01-25T23:38:42.643070+00:00", "data": {"market": "0x11912cb7cc6561870be58a6a52be2943f3e86d2395032f064ef3091d6901882d", "price_changes": [{"asset_id": "50369611503686433705495168228906407585201475093386767089387389512232179527221", "price": "0.01", "size": "3172.14", "side": "BUY", "hash": "c36ee1863df11ad21074ccb9b9ee9f45f3fa9719", "best_bid": "0.4", "best_ask": "0.87"}, {"asset_id": "25107464912227300161765664477112846497546753335497087400297930691126705811916", "price": "0.99", "size": "3172.14", "side": "SELL", "hash": "8e44b8dcc255119efe407e32af346feff7082a44", "best_bid": "0.13", "best_ask": "0.6"}], "timestamp": "1769384322562", "event_type": "price_change"}}
{"_local_timestamp": "2026-01-25T23:38:42.643432+00:00", "data": {"market": "0xc114f4fc118df768372c3604e92d404c7c95ab6b25ada140c77dee976a890777", "price_changes": [{"asset_id": "114016092226346692646025674182722281295722777137086779627843163223516672173339", "price": "0.33", "size": "66.66", "side": "BUY", "hash": "081a07f897712be22836574647f1be5bda7049e5", "best_bid": "0.33", "best_ask": "0.76"}, {"asset_id": "95497640963223955548410937239974920841410215692686671066528121763996154872565", "price": "0.67", "size": "66.66", "side": "SELL", "hash": "ade4731f2766ff5af615022562ad32d62dd81454", "best_bid": "0.24", "best_ask": "0.67"}], "timestamp": "1769384322570", "event_type": "price_change"}}
{"_local_timestamp": "2026-01-25T23:38:42.676977+00:00", "data": {"market": "0x86fec61dd9c27294756303c47b77cf6b7ed13ff4097e2967bc333dde4c1ea4da", "price_changes": [{"asset_id": "37660683447879901945455922570375098409697520769704430824022672297921367915347", "price": "0.45", "size": "66.66", "side": "BUY", "hash": "0395e81607b1360eb9d4c0095a6f00ae385bcd96", "best_bid": "0.45", "best_ask": "0.94"}, {"asset_id": "63898934961262618957913174161832335092659130397470681441362226870577487706450", "price": "0.55", "size": "66.66", "side": "SELL", "hash": "37ad122bf431a968fd40846720ec46309862074a", "best_bid": "0.06", "best_ask": "0.55"}], "timestamp": "1769384322577", "event_type": "price_change"}}
{"_local_timestamp": "2026-01-25T23:38:42.677357+00:00", "data": {"market": "0xc114f4fc118df768372c3604e92d404c7c95ab6b25ada140c77dee976a890777", "price_changes": [{"asset_id": "114016092226346692646025674182722281295722777137086779627843163223516672173339", "price": "0.06", "size": "199.66", "side": "BUY", "hash": "651f3048ff11ff6870a2c95e37f122c7f1f7de9a", "best_bid": "0.33", "best_ask": "0.76"}, {"asset_id": "95497640963223955548410937239974920841410215692686671066528121763996154872565", "price": "0.94", "size": "199.66", "side": "SELL", "hash": "c78abea1b9579887725fa46f1e8d711eb1a788d7", "best_bid": "0.24", "best_ask": "0.67"}], "timestamp": "1769384322582", "event_type": "price_change"}}
{"_local_timestamp": "2026-01-25T23:38:42.677646+00:00", "data": {"market": "0xb5f61d0c9ce431d64ba702815984246fa9cd6c2d6399849f0051d8695f2d98ab", "price_changes": [{"asset_id": "98590289222817581558553345992202318138659660940538324229915000516905381167250", "price": "0.24", "size": "66.66", "side": "BUY", "hash": "a744f0300c8ee441198f48c27290009c178b4f69", "best_bid": "0.43", "best_ask": "0.94"}, {"asset_id": "81582701062623199779039420976989567002417039977161919375131982089037196418005", "price": "0.76", "size": "66.66", "side": "SELL", "hash": "efbcff846714c203a92c62af8feb83514f2e485b", "best_bid": "0.06", "best_ask": "0.57"}], "timestamp": "1769384322589", "event_type": "price_change"}}
{"_local_timestamp": "2026-01-25T23:38:42.677974+00:00", "data": {"market": "0xc114f4fc118df768372c3604e92d404c7c95ab6b25ada140c77dee976a890777", "price_changes": [{"asset_id": "114016092226346692646025674182722281295722777137086779627843163223516672173339", "price": "0.19", "size": "66.66", "side": "BUY", "hash": "a3389c59d8eb57324decda51fb49180c57a801c6", "best_bid": "0.33", "best_ask": "0.76"}, {"asset_id": "95497640963223955548410937239974920841410215692686671066528121763996154872565", "price": "0.81", "size": "66.66", "side": "SELL", "hash": "6109fa946210e335fdead5308e0846c9865f7b59", "best_bid": "0.24", "best_ask": "0.67"}], "timestamp": "1769384322595", "event_type": "price_change"}}
{"_local_timestamp": "2026-01-25T23:38:42.685645+00:00", "data": {"market": "0xb5f61d0c9ce431d64ba702815984246fa9cd6c2d6399849f0051d8695f2d98ab", "price_changes": [{"asset_id": "98590289222817581558553345992202318138659660940538324229915000516905381167250", "price": "0.06", "size": "99.66", "side": "BUY", "hash": "d177c9a75b3f48acc40b77e5403d2e7169c0ce8e", "best_bid": "0.43", "best_ask": "0.94"}, {"asset_id": "81582701062623199779039420976989567002417039977161919375131982089037196418005", "price": "0.94", "size": "99.66", "side": "SELL", "hash": "f45e43b6762a5ac149f8bf0fa73a38ea0ec120d9", "best_bid": "0.06", "best_ask": "0.57"}], "timestamp": "1769384322603", "event_type": "price_change"}}
{"_local_timestamp": "2026-01-25T23:38:42.696505+00:00", "data": {"market": "0xf6d98f9984cbd7994c5ad4b44b57e6e65771833e1f682cb6c08e1881cba0be23", "price_changes": [{"asset_id": "111619066987530654938781515834745418625505306643795368186113638707368057832687", "price": "0.01", "size": "2472.58", "side": "BUY", "hash": "ba226ac4a78bdb160506723bbbe925c3bae80303", "best_bid": "0.46", "best_ask": "0.88"}, {"asset_id": "14133747134142323771619199606203638420186745480544687065966512009432569296940", "price": "0.99", "size": "2472.58", "side": "SELL", "hash": "6bca50c8a49c97843f6af933bf188afb117d0fb0", "best_bid": "0.12", "best_ask": "0.54"}], "timestamp": "1769384322612", "event_type": "price_change"}}
{"_local_timestamp": "2026-01-25T23:38:42.696855+00:00", "data": {"market": "0x86fec61dd9c27294756303c47b77cf6b7ed13ff4097e2967bc333dde4c1ea4da", "price_changes": [{"asset_id": "37660683447879901945455922570375098409697520769704430824022672297921367915347", "price": "0.06", "size": "99.66", "side": "BUY", "hash": "0f8f7e8a8cfe3af22dbacffa20d1f29ac74da2f6", "best_bid": "0.45", "best_ask": "0.94"}, {"asset_id": "63898934961262618957913174161832335092659130397470681441362226870577487706450", "price": "0.94", "size": "99.66", "side": "SELL", "hash": "6cbe2f6b8d2da5b220aaf81e2caac9508f3b93e7", "best_bid": "0.06", "best_ask": "0.55"}], "timestamp": "1769384322615", "event_type": "price_change"}}
{"_local_timestamp": "2026-01-25T23:38:42.733044+00:00", "data": {"market": "0x86fec61dd9c27294756303c47b77cf6b7ed13ff4097e2967bc333dde4c1ea4da", "price_changes": [{"asset_id": "37660683447879901945455922570375098409697520769704430824022672297921367915347", "price": "0.25", "size": "74.66", "side": "BUY", "hash": "a11a72f60c8aa98192310cdf319ed7d4f0decc67", "best_bid": "0.45", "best_ask": "0.94"}, {"asset_id": "63898934961262618957913174161832335092659130397470681441362226870577487706450", "price": "0.75", "size": "74.66", "side": "SELL", "hash": "ed7fc0aa6e80f25c767960064c9c495e9cd02f2b", "best_bid": "0.06", "best_ask": "0.55"}], "timestamp": "1769384322629", "event_type": "price_change"}}
{"_local_timestamp": "2026-01-25T23:38:42.733386+00:00", "data": {"market": "0xf6d98f9984cbd7994c5ad4b44b57e6e65771833e1f682cb6c08e1881cba0be23", "price_changes": [{"asset_id": "111619066987530654938781515834745418625505306643795368186113638707368057832687", "price": "0.08", "size": "6.56", "side": "BUY", "hash": "1f5121aa7c90e8393a25da20a61e750c21b8a352", "best_bid": "0.46", "best_ask": "0.88"}, {"asset_id": "14133747134142323771619199606203638420186745480544687065966512009432569296940", "price": "0.92", "size": "6.56", "side": "SELL", "hash": "181bd9c6389b831ad3b4b34ddd174dd103dbc3d4", "best_bid": "0.12", "best_ask": "0.54"}], "timestamp": "1769384322630", "event_type": "price_change"}}
{"_local_timestamp": "2026-01-25T23:38:42.756878+00:00", "data": {"market": "0x86fec61dd9c27294756303c47b77cf6b7ed13ff4097e2967bc333dde4c1ea4da", "price_changes": [{"asset_id": "37660683447879901945455922570375098409697520769704430824022672297921367915347", "price": "0.35", "size": "0", "side": "BUY", "hash": "7d0c50b2334c2aa5cf7aa71c3b328f84e071a9cf", "best_bid": "0.45", "best_ask": "0.94"}, {"asset_id": "63898934961262618957913174161832335092659130397470681441362226870577487706450", "price": "0.65", "size": "0", "side": "SELL", "hash": "8aa5770953cb0b5d32361735b37f20150bbc9fe5", "best_bid": "0.06", "best_ask": "0.55"}], "timestamp": "1769384322677", "event_type": "price_change"}}
{"_local_timestamp": "2026-01-25T23:38:42.963410+00:00", "data": {"market": "0x86fec61dd9c27294756303c47b77cf6b7ed13ff4097e2967bc333dde4c1ea4da", "price_changes": [{"asset_id": "37660683447879901945455922570375098409697520769704430824022672297921367915347", "price": "0.39", "size": "10", "side": "BUY", "hash": "80a2c169bc4e8a7b3768898c3e51ca2dfdef2625", "best_bid": "0.45", "best_ask": "0.94"}, {"asset_id": "63898934961262618957913174161832335092659130397470681441362226870577487706450", "price": "0.61", "size": "10", "side": "SELL", "hash": "9eace7d2c4d143461f5caaeee3c853af4c198750", "best_bid": "0.06", "best_ask": "0.55"}], "timestamp": "1769384322894", "event_type": "price_change"}}
{"_local_timestamp": "2026-01-25T23:38:42.963919+00:00", "data": {"market": "0x86fec61dd9c27294756303c47b77cf6b7ed13ff4097e2967bc333dde4c1ea4da", "price_changes": [{"asset_id": "37660683447879901945455922570375098409697520769704430824022672297921367915347", "price": "0.26", "size": "15", "side": "BUY", "hash": "84836128eeb0c977ecb7c0baa99ee78ab8ceaec7", "best_bid": "0.45", "best_ask": "0.94"}, {"asset_id": "63898934961262618957913174161832335092659130397470681441362226870577487706450", "price": "0.74", "size": "15", "side": "SELL", "hash": "c333284551a1f23e81887cd0478870a1aaa2cb78", "best_bid": "0.06", "best_ask": "0.55"}], "timestamp": "1769384322895", "event_type": "price_change"}}
{"_local_timestamp": "2026-01-25T23:38:42.979326+00:00", "data": {"market": "0xf6d98f9984cbd7994c5ad4b44b57e6e65771833e1f682cb6c08e1881cba0be23", "price_changes": [{"asset_id": "111619066987530654938781515834745418625505306643795368186113638707368057832687", "price": "0.07", "size": "110", "side": "BUY", "hash": "894b1a2acaac52c91014c819df6973f25c6bf474", "best_bid": "0.46", "best_ask": "0.88"}, {"asset_id": "14133747134142323771619199606203638420186745480544687065966512009432569296940", "price": "0.93", "size": "110", "side": "SELL", "hash": "4646caf2e2b17e70be5115ab237631a9c829a24e", "best_bid": "0.12", "best_ask": "0.54"}], "timestamp": "1769384322912", "event_type": "price_change"}}
{"_local_timestamp": "2026-01-25T23:38:43.327208+00:00", "data": {"market": "0x86fec61dd9c27294756303c47b77cf6b7ed13ff4097e2967bc333dde4c1ea4da", "price_changes": [{"asset_id": "37660683447879901945455922570375098409697520769704430824022672297921367915347", "price": "0.44", "size": "0", "side": "BUY", "hash": "7b9ebc6a477013d5e196ac72b23c251454673ee5", "best_bid": "0.45", "best_ask": "0.94"}, {"asset_id": "63898934961262618957913174161832335092659130397470681441362226870577487706450", "price": "0.56", "size": "0", "side": "SELL", "hash": "b7abe1e8c72742abfa30f7c14fcda187835b5df7", "best_bid": "0.06", "best_ask": "0.55"}], "timestamp": "1769384323254", "event_type": "price_change"}}
{"_local_timestamp": "2026-01-25T23:38:43.327597+00:00", "data": {"market": "0xf6d98f9984cbd7994c5ad4b44b57e6e65771833e1f682cb6c08e1881cba0be23", "price_changes": [{"asset_id": "111619066987530654938781515834745418625505306643795368186113638707368057832687", "price": "0.38", "size": "0", "side": "BUY", "hash": "67ddf9924d13a75b3be7912e36023ebe4aa444d7", "best_bid": "0.46", "best_ask": "0.88"}, {"asset_id": "14133747134142323771619199606203638420186745480544687065966512009432569296940", "price": "0.62", "size": "0", "side": "SELL", "hash": "0bbd14494bb7571b3afee520e44d47d8de52beeb", "best_bid": "0.12", "best_ask": "0.54"}], "timestamp": "1769384323254", "event_type": "price_change"}}
{"_local_timestamp": "2026-01-25T23:38:43.327891+00:00", "data": {"market": "0x11912cb7cc6561870be58a6a52be2943f3e86d2395032f064ef3091d6901882d", "price_changes": [{"asset_id": "50369611503686433705495168228906407585201475093386767089387389512232179527221", "price": "0.39", "size": "0", "side": "BUY", "hash": "86280510b2ed790890dbae7fe3b6a455fe4e44ea", "best_bid": "0.4", "best_ask": "0.87"}, {"asset_id": "25107464912227300161765664477112846497546753335497087400297930691126705811916", "price": "0.61", "size": "0", "side": "SELL", "hash": "115fee73fcf0e8dd2efcdf9b00f7ceec277b82b7", "best_bid": "0.13", "best_ask": "0.6"}], "timestamp": "1769384323254", "event_type": "price_change"}}
{"_local_timestamp": "2026-01-25T23:38:43.328138+00:00", "data": {"market": "0xc114f4fc118df768372c3604e92d404c7c95ab6b25ada140c77dee976a890777", "price_changes": [{"asset_id": "114016092226346692646025674182722281295722777137086779627843163223516672173339", "price": "0.32", "size": "0", "side": "BUY", "hash": "ce76463c154a16defdbf6e5dac7b5d511f61264d", "best_bid": "0.33", "best_ask": "0.76"}, {"asset_id": "95497640963223955548410937239974920841410215692686671066528121763996154872565", "price": "0.68", "size": "0", "side": "SELL", "hash": "ee22fbc1ec423bca58b24d131286876d6c8413c1", "best_bid": "0.24", "best_ask": "0.67"}], "timestamp": "1769384323254", "event_type": "price_change"}}
{"_local_timestamp": "2026-01-25T23:38:43.328402+00:00", "data": {"market": "0xb5f61d0c9ce431d64ba702815984246fa9cd6c2d6399849f0051d8695f2d98ab", "price_changes": [{"asset_id": "98590289222817581558553345992202318138659660940538324229915000516905381167250", "price": "0.42", "size": "0", "side": "BUY", "hash": "58879da46dadeb517427d1e94b9bab732d5bdfe7", "best_bid": "0.43", "best_ask": "0.94"}, {"asset_id": "81582701062623199779039420976989567002417039977161919375131982089037196418005", "price": "0.58", "size": "0", "side": "SELL", "hash": "a73b029793ff1e694c2209088154dbd90b3e96d3", "best_bid": "0.06", "best_ask": "0.57"}], "timestamp": "1769384323254", "event_type": "price_change"}}
{"_local_timestamp": "2026-01-25T23:38:43.352789+00:00", "data": {"market": "0xf6d98f9984cbd7994c5ad4b44b57e6e65771833e1f682cb6c08e1881cba0be23", "price_changes": [{"asset_id": "111619066987530654938781515834745418625505306643795368186113638707368057832687", "price": "0.32", "size": "20", "side": "BUY", "hash": "d5bc5e977ebfa45c45210f52a233cbf1aa67bc08", "best_bid": "0.46", "best_ask": "0.88"}, {"asset_id": "14133747134142323771619199606203638420186745480544687065966512009432569296940", "price": "0.68", "size": "20", "side": "SELL", "hash": "465da1b8186d89b8e305bd415c848824f95f7082", "best_bid": "0.12", "best_ask": "0.54"}], "timestamp": "1769384323285", "event_type": "price_change"}}
{"_local_timestamp": "2026-01-25T23:38:43.353064+00:00", "data": {"market": "0xc114f4fc118df768372c3604e92d404c7c95ab6b25ada140c77dee976a890777", "price_changes": [{"asset_id": "114016092226346692646025674182722281295722777137086779627843163223516672173339", "price": "0.29", "size": "20", "side": "BUY", "hash": "21b425ec1bbe0dd523c1a915d5da9e8adc22eb4a", "best_bid": "0.33", "best_ask": "0.76"}, {"asset_id": "95497640963223955548410937239974920841410215692686671066528121763996154872565", "price": "0.71", "size": "20", "side": "SELL", "hash": "b5d99053541af65403833c50af75c8adcce4e68f", "best_bid": "0.24", "best_ask": "0.67"}], "timestamp": "1769384323286", "event_type": "price_change"}}
{"_local_timestamp": "2026-01-25T23:38:43.353292+00:00", "data": {"market": "0xb5f61d0c9ce431d64ba702815984246fa9cd6c2d6399849f0051d8695f2d98ab", "price_changes": [{"asset_id": "98590289222817581558553345992202318138659660940538324229915000516905381167250", "price": "0.44", "size": "20", "side": "BUY", "hash": "726c55c99a3f0bbaf2f996695b42e6498b3e7fd8", "best_bid": "0.44", "best_ask": "0.94"}, {"asset_id": "81582701062623199779039420976989567002417039977161919375131982089037196418005", "price": "0.56", "size": "20", "side": "SELL", "hash": "8012fa04c5add5ae08e832831c3fce9488bcc4ad", "best_bid": "0.06", "best_ask": "0.56"}], "timestamp": "1769384323285", "event_type": "price_change"}}
{"_local_timestamp": "2026-01-25T23:38:43.353543+00:00", "data": {"market": "0x11912cb7cc6561870be58a6a52be2943f3e86d2395032f064ef3091d6901882d", "price_changes": [{"asset_id": "50369611503686433705495168228906407585201475093386767089387389512232179527221", "price": "0.41", "size": "20", "side": "BUY", "hash": "98182c330eb7bd5e4a44c48b039eb9b808452b90", "best_bid": "0.41", "best_ask": "0.87"}, {"asset_id": "25107464912227300161765664477112846497546753335497087400297930691126705811916", "price": "0.59", "size": "20", "side": "SELL", "hash": "e8b445d9bde01eeb9aa0703730f61cbca8a4ea63", "best_bid": "0.13", "best_ask": "0.59"}], "timestamp": "1769384323285", "event_type": "price_change"}}
{"_local_timestamp": "2026-01-25T23:38:43.353763+00:00", "data": {"market": "0x86fec61dd9c27294756303c47b77cf6b7ed13ff4097e2967bc333dde4c1ea4da", "price_changes": [{"asset_id": "37660683447879901945455922570375098409697520769704430824022672297921367915347", "price": "0.46", "size": "20", "side": "BUY", "hash": "e50af746f9ae715b0c57837b608dcd757b915eb6", "best_bid": "0.46", "best_ask": "0.94"}, {"asset_id": "63898934961262618957913174161832335092659130397470681441362226870577487706450", "price": "0.54", "size": "20", "side": "SELL", "hash": "b42bccf21508a3f8041e7d60338f91b35f235156", "best_bid": "0.06", "best_ask": "0.54"}], "timestamp": "1769384323285", "event_type": "price_change"}}
{"_local_timestamp": "2026-01-25T23:38:58.786798+00:00", "data": {"market": "0x86fec61dd9c27294756303c47b77cf6b7ed13ff4097e2967bc333dde4c1ea4da", "price_changes": [{"asset_id": "37660683447879901945455922570375098409697520769704430824022672297921367915347", "price": "0.11", "size": "130", "side": "BUY", "hash": "ffd3f67f6bd74ff17f909b0d02f77c0350135215", "best_bid": "0.46", "best_ask": "0.94"}, {"asset_id": "63898934961262618957913174161832335092659130397470681441362226870577487706450", "price": "0.89", "size": "130", "side": "SELL", "hash": "1a8689308ef76a56ff5308e8eff3a0fafa38aca7", "best_bid": "0.06", "best_ask": "0.54"}], "timestamp": "1769384338637", "event_type": "price_change"}}
{"_local_timestamp": "2026-01-25T23:38:58.894142+00:00", "data": {"market": "0xb5f61d0c9ce431d64ba702815984246fa9cd6c2d6399849f0051d8695f2d98ab", "price_changes": [{"asset_id": "98590289222817581558553345992202318138659660940538324229915000516905381167250", "price": "0.16", "size": "100", "side": "BUY", "hash": "cd04bb0f5095f84880beb3441c307c879612452d", "best_bid": "0.44", "best_ask": "0.94"}, {"asset_id": "81582701062623199779039420976989567002417039977161919375131982089037196418005", "price": "0.84", "size": "100", "side": "SELL", "hash": "c11eb10a49d5236ac48b99407ec87cd6c2871722", "best_bid": "0.06", "best_ask": "0.56"}], "timestamp": "1769384338661", "event_type": "price_change"}}
{"_local_timestamp": "2026-01-25T23:38:58.894556+00:00", "data": {"market": "0xf6d98f9984cbd7994c5ad4b44b57e6e65771833e1f682cb6c08e1881cba0be23", "price_changes": [{"asset_id": "111619066987530654938781515834745418625505306643795368186113638707368057832687", "price": "0.11", "size": "125", "side": "BUY", "hash": "cde71877258499930246cdce4994826f37962ad6", "best_bid": "0.46", "best_ask": "0.88"}, {"asset_id": "14133747134142323771619199606203638420186745480544687065966512009432569296940", "price": "0.89", "size": "125", "side": "SELL", "hash": "e59e9e625592b68a60ce75b6b04463c7eb79d213", "best_bid": "0.12", "best_ask": "0.54"}], "timestamp": "1769384338666", "event_type": "price_change"}}
{"_local_timestamp": "2026-01-25T23:38:58.950022+00:00", "data": {"market": "0x11912cb7cc6561870be58a6a52be2943f3e86d2395032f064ef3091d6901882d", "price_changes": [{"asset_id": "50369611503686433705495168228906407585201475093386767089387389512232179527221", "price": "0.11", "size": "125", "side": "BUY", "hash": "70a6d3c95db4739d51acd4a3c180451fcab38aac", "best_bid": "0.41", "best_ask": "0.87"}, {"asset_id": "25107464912227300161765664477112846497546753335497087400297930691126705811916", "price": "0.89", "size": "125", "side": "SELL", "hash": "1bd66c3efef8ae279906aeb523f508c6cbdcd9dd", "best_bid": "0.13", "best_ask": "0.59"}], "timestamp": "1769384338668", "event_type": "price_change"}}
{"_local_timestamp": "2026-01-25T23:38:58.950380+00:00", "data": {"market": "0xb5f61d0c9ce431d64ba702815984246fa9cd6c2d6399849f0051d8695f2d98ab", "price_changes": [{"asset_id": "98590289222817581558553345992202318138659660940538324229915000516905381167250", "price": "0.11", "size": "125", "side": "BUY", "hash": "a0cca6bc54fe5d18cb816a876bc4fa6131fcd401", "best_bid": "0.44", "best_ask": "0.94"}, {"asset_id": "81582701062623199779039420976989567002417039977161919375131982089037196418005", "price": "0.89", "size": "125", "side": "SELL", "hash": "1291f8e5107154bd5fe5ac2491adf8bf6ca3596c", "best_bid": "0.06", "best_ask": "0.56"}], "timestamp": "1769384338831", "event_type": "price_change"}}
{"_local_timestamp": "2026-01-25T23:38:59.165996+00:00", "data": {"market": "0x86fec61dd9c27294756303c47b77cf6b7ed13ff4097e2967bc333dde4c1ea4da", "price_changes": [{"asset_id": "37660683447879901945455922570375098409697520769704430824022672297921367915347", "price": "0.16", "size": "100", "side": "BUY", "hash": "b3cb7ee9d2fb0c55f801781f9caead3ff0d5b8fe", "best_bid": "0.46", "best_ask": "0.94"}, {"asset_id": "63898934961262618957913174161832335092659130397470681441362226870577487706450", "price": "0.84", "size": "100", "side": "SELL", "hash": "bb1bb0e45b2274a1db393a3329e33b895a0ac266", "best_bid": "0.06", "best_ask": "0.54"}], "timestamp": "1769384338726", "event_type": "price_change"}}
{"_local_timestamp": "2026-01-25T23:38:59.186325+00:00", "data": {"market": "0xf6d98f9984cbd7994c5ad4b44b57e6e65771833e1f682cb6c08e1881cba0be23", "price_changes": [{"asset_id": "111619066987530654938781515834745418625505306643795368186113638707368057832687", "price": "0.07", "size": "100", "side": "BUY", "hash": "271057687cf3378d23ce9007784a0975e302d3a9", "best_bid": "0.46", "best_ask": "0.88"}, {"asset_id": "14133747134142323771619199606203638420186745480544687065966512009432569296940", "price": "0.93", "size": "100", "side": "SELL", "hash": "b99745d50eb4b8556fce1b2d490bf85802d72095", "best_bid": "0.12", "best_ask": "0.54"}], "timestamp": "1769384339014", "event_type": "price_change"}}
{"_local_timestamp": "2026-01-25T23:38:59.186701+00:00", "data": {"market": "0xb5f61d0c9ce431d64ba702815984246fa9cd6c2d6399849f0051d8695f2d98ab", "price_changes": [{"asset_id": "98590289222817581558553345992202318138659660940538324229915000516905381167250", "price": "0.1", "size": "52", "side": "BUY", "hash": "496a5ccd53d695fd7d0436765e9647360ef5d326", "best_bid": "0.44", "best_ask": "0.94"}, {"asset_id": "81582701062623199779039420976989567002417039977161919375131982089037196418005", "price": "0.9", "size": "52", "side": "SELL", "hash": "41577123700f8fc22056870de1a91606b9f363ec", "best_bid": "0.06", "best_ask": "0.56"}], "timestamp": "1769384339015", "event_type": "price_change"}}
{"_local_timestamp": "2026-01-25T23:38:59.188760+00:00", "data": {"market": "0x11912cb7cc6561870be58a6a52be2943f3e86d2395032f064ef3091d6901882d", "price_changes": [{"asset_id": "50369611503686433705495168228906407585201475093386767089387389512232179527221", "price": "0.06", "size": "33", "side": "BUY", "hash": "1d47ca52f0c6011bf1ea915fe74dcf7aeee50de0", "best_bid": "0.41", "best_ask": "0.87"}, {"asset_id": "25107464912227300161765664477112846497546753335497087400297930691126705811916", "price": "0.94", "size": "33", "side": "SELL", "hash": "ecf35cde38fb13e11a97466b09cc17e1de5eae4c", "best_bid": "0.13", "best_ask": "0.59"}], "timestamp": "1769384339015", "event_type": "price_change"}}
{"_local_timestamp": "2026-01-25T23:38:59.237041+00:00", "data": {"market": "0x86fec61dd9c27294756303c47b77cf6b7ed13ff4097e2967bc333dde4c1ea4da", "price_changes": [{"asset_id": "37660683447879901945455922570375098409697520769704430824022672297921367915347", "price": "0.1", "size": "0", "side": "BUY", "hash": "d737f4632e0d009bbb26705867448a6060a105ce", "best_bid": "0.46", "best_ask": "0.94"}, {"asset_id": "63898934961262618957913174161832335092659130397470681441362226870577487706450", "price": "0.9", "size": "0", "side": "SELL", "hash": "8d2ace5198dda944fdbcf83c307aebfff3b8cbca", "best_bid": "0.06", "best_ask": "0.54"}], "timestamp": "1769384339160", "event_type": "price_change"}}
{"_local_timestamp": "2026-01-25T23:39:04.395933+00:00", "data": {"market": "0x86fec61dd9c27294756303c47b77cf6b7ed13ff4097e2967bc333dde4c1ea4da", "price_changes": [{"asset_id": "37660683447879901945455922570375098409697520769704430824022672297921367915347", "price": "0.05", "size": "135.5", "side": "BUY", "hash": "825a8e25395bfeef445c4a73d32ba5cc000f23dd", "best_bid": "0.46", "best_ask": "0.94"}, {"asset_id": "63898934961262618957913174161832335092659130397470681441362226870577487706450", "price": "0.95", "size": "135.5", "side": "SELL", "hash": "1566b247e0de6c20410a6d62a552c104f646c2ca", "best_bid": "0.06", "best_ask": "0.54"}], "timestamp": "1769384344316", "event_type": "price_change"}}
{"_local_timestamp": "2026-01-25T23:39:04.767423+00:00", "data": {"market": "0x86fec61dd9c27294756303c47b77cf6b7ed13ff4097e2967bc333dde4c1ea4da", "price_changes": [{"asset_id": "37660683447879901945455922570375098409697520769704430824022672297921367915347", "price": "0.04", "size": "350", "side": "BUY", "hash": "01d506a7237109b3a86135078e2f746c12a2b6ff", "best_bid": "0.46", "best_ask": "0.94"}, {"asset_id": "63898934961262618957913174161832335092659130397470681441362226870577487706450", "price": "0.96", "size": "350", "side": "SELL", "hash": "db16e7492cef575fd8d64ea179c00490dc66a723", "best_bid": "0.06", "best_ask": "0.54"}], "timestamp": "1769384344637", "event_type": "price_change"}}
{"_local_timestamp": "2026-01-25T23:39:08.079686+00:00", "data": {"market": "0xf6d98f9984cbd7994c5ad4b44b57e6e65771833e1f682cb6c08e1881cba0be23", "price_changes": [{"asset_id": "111619066987530654938781515834745418625505306643795368186113638707368057832687", "price": "0.47", "size": "47", "side": "BUY", "hash": "727e49da44c0d979cd7dc361e57b3e42b8c7b31b", "best_bid": "0.47", "best_ask": "0.88"}, {"asset_id": "14133747134142323771619199606203638420186745480544687065966512009432569296940", "price": "0.53", "size": "47", "side": "SELL", "hash": "9f8f39eacf7ddc989b48690583f142e7d8c8d88d", "best_bid": "0.12", "best_ask": "0.53"}], "timestamp": "1769384348007", "event_type": "price_change"}}
{"_local_timestamp": "2026-01-25T23:39:16.803267+00:00", "data": {"market": "0x86fec61dd9c27294756303c47b77cf6b7ed13ff4097e2967bc333dde4c1ea4da", "price_changes": [{"asset_id": "37660683447879901945455922570375098409697520769704430824022672297921367915347", "price": "0.01", "size": "2405.28", "side": "BUY", "hash": "ba9d325976da3426cd7f46bac101f5c56c5ea9cb", "best_bid": "0.46", "best_ask": "0.94"}, {"asset_id": "63898934961262618957913174161832335092659130397470681441362226870577487706450", "price": "0.99", "size": "2405.28", "side": "SELL", "hash": "3502873c7d4a608b5ea4ea7676731d8827ee83fd", "best_bid": "0.06", "best_ask": "0.54"}], "timestamp": "1769384356684", "event_type": "price_change"}}
{"_local_timestamp": "2026-01-25T23:39:16.804642+00:00", "data": {"market": "0x86fec61dd9c27294756303c47b77cf6b7ed13ff4097e2967bc333dde4c1ea4da", "price_changes": [{"asset_id": "37660683447879901945455922570375098409697520769704430824022672297921367915347", "price": "0.02", "size": "1006.56", "side": "BUY", "hash": "ba9d325976da3426cd7f46bac101f5c56c5ea9cb", "best_bid": "0.46", "best_ask": "0.94"}, {"asset_id": "63898934961262618957913174161832335092659130397470681441362226870577487706450", "price": "0.98", "size": "1006.56", "side": "SELL", "hash": "3502873c7d4a608b5ea4ea7676731d8827ee83fd", "best_bid": "0.06", "best_ask": "0.54"}], "timestamp": "1769384356684", "event_type": "price_change"}}
{"_local_timestamp": "2026-01-25T23:39:16.804957+00:00", "data": {"market": "0xb5f61d0c9ce431d64ba702815984246fa9cd6c2d6399849f0051d8695f2d98ab", "price_changes": [{"asset_id": "98590289222817581558553345992202318138659660940538324229915000516905381167250", "price": "0.02", "size": "1006.63", "side": "BUY", "hash": "42d95c555f8fcd9fd7e9946bac5d3a2403804cda", "best_bid": "0.44", "best_ask": "0.94"}, {"asset_id": "81582701062623199779039420976989567002417039977161919375131982089037196418005", "price": "0.98", "size": "1006.63", "side": "SELL", "hash": "c8796b15ddb09633a6a43e3d2d4cd2d8cda32fd3", "best_bid": "0.06", "best_ask": "0.56"}], "timestamp": "1769384356684", "event_type": "price_change"}}
{"_local_timestamp": "2026-01-25T23:39:16.805217+00:00", "data": {"market": "0xb5f61d0c9ce431d64ba702815984246fa9cd6c2d6399849f0051d8695f2d98ab", "price_changes": [{"asset_id": "98590289222817581558553345992202318138659660940538324229915000516905381167250", "price": "0.01", "size": "2406.33", "side": "BUY", "hash": "42d95c555f8fcd9fd7e9946bac5d3a2403804cda", "best_bid": "0.44", "best_ask": "0.94"}, {"asset_id": "81582701062623199779039420976989567002417039977161919375131982089037196418005", "price": "0.99", "size": "2406.33", "side": "SELL", "hash": "c8796b15ddb09633a6a43e3d2d4cd2d8cda32fd3", "best_bid": "0.06", "best_ask": "0.56"}], "timestamp": "1769384356684", "event_type": "price_change"}}
{"_local_timestamp": "2026-01-25T23:39:16.805478+00:00", "data": {"market": "0x11912cb7cc6561870be58a6a52be2943f3e86d2395032f064ef3091d6901882d", "price_changes": [{"asset_id": "50369611503686433705495168228906407585201475093386767089387389512232179527221", "price": "0.01", "size": "2172.14", "side": "BUY", "hash": "388ebc07bb95580783a2096762dc02954e839d59", "best_bid": "0.41", "best_ask": "0.87"}, {"asset_id": "25107464912227300161765664477112846497546753335497087400297930691126705811916", "price": "0.99", "size": "2172.14", "side": "SELL", "hash": "f6be37d4aad7b272acbe96c061c7ff8b725ba76a", "best_bid": "0.13", "best_ask": "0.59"}], "timestamp": "1769384356684", "event_type": "price_change"}}
{"_local_timestamp": "2026-01-25T23:39:16.805712+00:00", "data": {"market": "0xc114f4fc118df768372c3604e92d404c7c95ab6b25ada140c77dee976a890777", "price_changes": [{"asset_id": "114016092226346692646025674182722281295722777137086779627843163223516672173339", "price": "0.01", "size": "2405.81", "side": "BUY", "hash": "2829dc9108e18efdb78a16662d23ccfc5bfc8a96", "best_bid": "0.33", "best_ask": "0.76"}, {"asset_id": "95497640963223955548410937239974920841410215692686671066528121763996154872565", "price": "0.99", "size": "2405.81", "side": "SELL", "hash": "77d77cc3173de99d010de9964356edb9b142e024", "best_bid": "0.24", "best_ask": "0.67"}], "timestamp": "1769384356684", "event_type": "price_change"}}
{"_local_timestamp": "2026-01-25T23:39:16.806041+00:00", "data": {"market": "0x11912cb7cc6561870be58a6a52be2943f3e86d2395032f064ef3091d6901882d", "price_changes": [{"asset_id": "50369611503686433705495168228906407585201475093386767089387389512232179527221", "price": "0.02", "size": "1008.46", "side": "BUY", "hash": "388ebc07bb95580783a2096762dc02954e839d59", "best_bid": "0.41", "best_ask": "0.87"}, {"asset_id": "25107464912227300161765664477112846497546753335497087400297930691126705811916", "price": "0.98", "size": "1008.46", "side": "SELL", "hash": "f6be37d4aad7b272acbe96c061c7ff8b725ba76a", "best_bid": "0.13", "best_ask": "0.59"}], "timestamp": "1769384356684", "event_type": "price_change"}}
{"_local_timestamp": "2026-01-25T23:39:16.806287+00:00", "data": {"market": "0xc114f4fc118df768372c3604e92d404c7c95ab6b25ada140c77dee976a890777", "price_changes": [{"asset_id": "114016092226346692646025674182722281295722777137086779627843163223516672173339", "price": "0.02", "size": "1007.09", "side": "BUY", "hash": "2829dc9108e18efdb78a16662d23ccfc5bfc8a96", "best_bid": "0.33", "best_ask": "0.76"}, {"asset_id": "95497640963223955548410937239974920841410215692686671066528121763996154872565", "price": "0.98", "size": "1007.09", "side": "SELL", "hash": "77d77cc3173de99d010de9964356edb9b142e024", "best_bid": "0.24", "best_ask": "0.67"}], "timestamp": "1769384356684", "event_type": "price_change"}}
{"_local_timestamp": "2026-01-25T23:39:22.369822+00:00", "data": {"market": "0xf6d98f9984cbd7994c5ad4b44b57e6e65771833e1f682cb6c08e1881cba0be23", "price_changes": [{"asset_id": "111619066987530654938781515834745418625505306643795368186113638707368057832687", "price": "0.01", "size": "2172.58", "side": "BUY", "hash": "c47894f1dd5cd77ff00b4519900080d49691f809", "best_bid": "0.47", "best_ask": "0.88"}, {"asset_id": "14133747134142323771619199606203638420186745480544687065966512009432569296940", "price": "0.99", "size": "2172.58", "side": "SELL", "hash": "c6c347b034d553c3ff0316bb4bf3ddf3f050ea1f", "best_bid": "0.12", "best_ask": "0.53"}], "timestamp": "1769384362199", "event_type": "price_change"}}
{"_local_timestamp": "2026-01-25T23:39:22.370174+00:00", "data": {"market": "0x86fec61dd9c27294756303c47b77cf6b7ed13ff4097e2967bc333dde4c1ea4da", "price_changes": [{"asset_id": "37660683447879901945455922570375098409697520769704430824022672297921367915347", "price": "0.01", "size": "2105.28", "side": "BUY", "hash": "a4fafcbd249c602de2aeb43c9a292a8ce133306b", "best_bid": "0.46", "best_ask": "0.94"}, {"asset_id": "63898934961262618957913174161832335092659130397470681441362226870577487706450", "price": "0.99", "size": "2105.28", "side": "SELL", "hash": "e86ccd9b3beb1936b61b87d3915dc3e8620ae229", "best_bid": "0.06", "best_ask": "0.54"}], "timestamp": "1769384362199", "event_type": "price_change"}}
{"_local_timestamp": "2026-01-25T23:39:22.370412+00:00", "data": {"market": "0xb5f61d0c9ce431d64ba702815984246fa9cd6c2d6399849f0051d8695f2d98ab", "price_changes": [{"asset_id": "98590289222817581558553345992202318138659660940538324229915000516905381167250", "price": "0.01", "size": "2106.33", "side": "BUY", "hash": "f207b41e51332e15867e0bac0bb5cc9cb0667133", "best_bid": "0.44", "best_ask": "0.94"}, {"asset_id": "81582701062623199779039420976989567002417039977161919375131982089037196418005", "price": "0.99", "size": "2106.33", "side": "SELL", "hash": "fc2c920273f30fd2e6fba238340b4960f22bcc69", "best_bid": "0.06", "best_ask": "0.56"}], "timestamp": "1769384362199", "event_type": "price_change"}}
{"_local_timestamp": "2026-01-25T23:39:22.953183+00:00", "data": {"market": "0xf6d98f9984cbd7994c5ad4b44b57e6e65771833e1f682cb6c08e1881cba0be23", "price_changes": [{"asset_id": "111619066987530654938781515834745418625505306643795368186113638707368057832687", "price": "0.11", "size": "325", "side": "BUY", "hash": "54bb850d7b8fa20649c583d0ad91e3915a3bc202", "best_bid": "0.47", "best_ask": "0.88"}, {"asset_id": "14133747134142323771619199606203638420186745480544687065966512009432569296940", "price": "0.89", "size": "325", "side": "SELL", "hash": "72fc7b372e8e33afd4aca7a1ab37a1b54d3fe9d2", "best_bid": "0.12", "best_ask": "0.53"}], "timestamp": "1769384362730", "event_type": "price_change"}}
{"_local_timestamp": "2026-01-25T23:39:22.980925+00:00", "data": {"market": "0x11912cb7cc6561870be58a6a52be2943f3e86d2395032f064ef3091d6901882d", "price_changes": [{"asset_id": "50369611503686433705495168228906407585201475093386767089387389512232179527221", "price": "0.11", "size": "325", "side": "BUY", "hash": "43a13b216499a10d5ffb3de09a02188e23194988", "best_bid": "0.41", "best_ask": "0.87"}, {"asset_id": "25107464912227300161765664477112846497546753335497087400297930691126705811916", "price": "0.89", "size": "325", "side": "SELL", "hash": "25144a4c801e1dc93f95c55a8709090ea691bf31", "best_bid": "0.13", "best_ask": "0.59"}], "timestamp": "1769384362734", "event_type": "price_change"}}
{"_local_timestamp": "2026-01-25T23:39:22.981977+00:00", "data": {"market": "0xb5f61d0c9ce431d64ba702815984246fa9cd6c2d6399849f0051d8695f2d98ab", "price_changes": [{"asset_id": "98590289222817581558553345992202318138659660940538324229915000516905381167250", "price": "0.09", "size": "405.61", "side": "BUY", "hash": "7444203087f83e6296500f0aa66896f7f7f0ae1e", "best_bid": "0.44", "best_ask": "0.94"}, {"asset_id": "81582701062623199779039420976989567002417039977161919375131982089037196418005", "price": "0.91", "size": "405.61", "side": "SELL", "hash": "5d68a7f74d2bee804decd2d2a603e21b9560951c", "best_bid": "0.06", "best_ask": "0.56"}], "timestamp": "1769384362734", "event_type": "price_change"}}
{"_local_timestamp": "2026-01-25T23:39:23.021593+00:00", "data": {"market": "0x86fec61dd9c27294756303c47b77cf6b7ed13ff4097e2967bc333dde4c1ea4da", "price_changes": [{"asset_id": "37660683447879901945455922570375098409697520769704430824022672297921367915347", "price": "0.16", "size": "250", "side": "BUY", "hash": "0f6c5916fc847af2319874ae8ff4267c28a071f3", "best_bid": "0.46", "best_ask": "0.94"}, {"asset_id": "63898934961262618957913174161832335092659130397470681441362226870577487706450", "price": "0.84", "size": "250", "side": "SELL", "hash": "282cf12157feb44fbbaa12a655dfb86a38af50a9", "best_bid": "0.06", "best_ask": "0.54"}], "timestamp": "1769384362758", "event_type": "price_change"}}
{"_local_timestamp": "2026-01-25T23:39:23.023361+00:00", "data": {"market": "0xf6d98f9984cbd7994c5ad4b44b57e6e65771833e1f682cb6c08e1881cba0be23", "price_changes": [{"asset_id": "111619066987530654938781515834745418625505306643795368186113638707368057832687", "price": "0.07", "size": "400", "side": "BUY", "hash": "f840ee1850f52151e4268723f5cd110a50060f15", "best_bid": "0.47", "best_ask": "0.88"}, {"asset_id": "14133747134142323771619199606203638420186745480544687065966512009432569296940", "price": "0.93", "size": "400", "side": "SELL", "hash": "7a383ba7f2da5cd91dbc7a23d0a3f3ae14516068", "best_bid": "0.12", "best_ask": "0.53"}], "timestamp": "1769384362814", "event_type": "price_change"}}
{"_local_timestamp": "2026-01-25T23:39:23.030776+00:00", "data": {"market": "0xb5f61d0c9ce431d64ba702815984246fa9cd6c2d6399849f0051d8695f2d98ab", "price_changes": [{"asset_id": "98590289222817581558553345992202318138659660940538324229915000516905381167250", "price": "0.11", "size": "325", "side": "BUY", "hash": "298ce0f9ede33f935ea6cb2d2b5b44dd0c95c1ec", "best_bid": "0.44", "best_ask": "0.94"}, {"asset_id": "81582701062623199779039420976989567002417039977161919375131982089037196418005", "price": "0.89", "size": "325", "side": "SELL", "hash": "9b31be8203c0d97ed60c3660d7731ed7ad837003", "best_bid": "0.06", "best_ask": "0.56"}], "timestamp": "1769384362813", "event_type": "price_change"}}
{"_local_timestamp": "2026-01-25T23:39:23.033022+00:00", "data": {"market": "0x86fec61dd9c27294756303c47b77cf6b7ed13ff4097e2967bc333dde4c1ea4da", "price_changes": [{"asset_id": "37660683447879901945455922570375098409697520769704430824022672297921367915347", "price": "0.11", "size": "330", "side": "BUY", "hash": "08c47d5867b2f4063187166265d1829938efc164", "best_bid": "0.46", "best_ask": "0.94"}, {"asset_id": "63898934961262618957913174161832335092659130397470681441362226870577487706450", "price": "0.89", "size": "330", "side": "SELL", "hash": "7b60ef97206835ad19d58e8c2c1d61a67fa2aa54", "best_bid": "0.06", "best_ask": "0.54"}], "timestamp": "1769384362828", "event_type": "price_change"}}
{"_local_timestamp": "2026-01-25T23:39:23.036429+00:00", "data": {"market": "0xb5f61d0c9ce431d64ba702815984246fa9cd6c2d6399849f0051d8695f2d98ab", "price_changes": [{"asset_id": "98590289222817581558553345992202318138659660940538324229915000516905381167250", "price": "0.16", "size": "250", "side": "BUY", "hash": "346720591a9e08fdde0428643bd5ebbb06be8291", "best_bid": "0.44", "best_ask": "0.94"}, {"asset_id": "81582701062623199779039420976989567002417039977161919375131982089037196418005", "price": "0.84", "size": "250", "side": "SELL", "hash": "b1eb25748bff1b682d64f6dc960d588fb2d6c42e", "best_bid": "0.06", "best_ask": "0.56"}], "timestamp": "1769384362834", "event_type": "price_change"}}
{"_local_timestamp": "2026-01-25T23:39:23.036729+00:00", "data": {"market": "0x86fec61dd9c27294756303c47b77cf6b7ed13ff4097e2967bc333dde4c1ea4da", "price_changes": [{"asset_id": "37660683447879901945455922570375098409697520769704430824022672297921367915347", "price": "0.09", "size": "405.78", "side": "BUY", "hash": "76e13aa9a00a7ee4065b5158cc310568dfaa881e", "best_bid": "0.46", "best_ask": "0.94"}, {"asset_id": "63898934961262618957913174161832335092659130397470681441362226870577487706450", "price": "0.91", "size": "405.78", "side": "SELL", "hash": "3a800fc230665e76897b7137a94579757106e243", "best_bid": "0.06", "best_ask": "0.54"}], "timestamp": "1769384362837", "event_type": "price_change"}}
{"_local_timestamp": "2026-01-25T23:39:23.127860+00:00", "data": {"market": "0x11912cb7cc6561870be58a6a52be2943f3e86d2395032f064ef3091d6901882d", "price_changes": [{"asset_id": "50369611503686433705495168228906407585201475093386767089387389512232179527221", "price": "0.32", "size": "0", "side": "BUY", "hash": "086170743e88283c0426d39fa95c355b5db736d8", "best_bid": "0.41", "best_ask": "0.87"}, {"asset_id": "25107464912227300161765664477112846497546753335497087400297930691126705811916", "price": "0.68", "size": "0", "side": "SELL", "hash": "3347cfe88220a34b7a5deae99f8f59d0707c8181", "best_bid": "0.13", "best_ask": "0.59"}], "timestamp": "1769384363011", "event_type": "price_change"}}
{"_local_timestamp": "2026-01-25T23:39:23.206340+00:00", "data": {"market": "0x11912cb7cc6561870be58a6a52be2943f3e86d2395032f064ef3091d6901882d", "price_changes": [{"asset_id": "50369611503686433705495168228906407585201475093386767089387389512232179527221", "price": "0.27", "size": "15", "side": "BUY", "hash": "9e5df242bf5d467f2385ecb45fedfb34f66e2563", "best_bid": "0.41", "best_ask": "0.87"}, {"asset_id": "25107464912227300161765664477112846497546753335497087400297930691126705811916", "price": "0.73", "size": "15", "side": "SELL", "hash": "2a77cfdfa286514ad7c1f8c08876b9203421f512", "best_bid": "0.13", "best_ask": "0.59"}], "timestamp": "1769384363138", "event_type": "price_change"}}
{"_local_timestamp": "2026-01-25T23:39:23.242536+00:00", "data": {"market": "0x11912cb7cc6561870be58a6a52be2943f3e86d2395032f064ef3091d6901882d", "price_changes": [{"asset_id": "50369611503686433705495168228906407585201475093386767089387389512232179527221", "price": "0.29", "size": "10", "side": "BUY", "hash": "bc708e3f633e5b589e3aba6b9f45cce82d13cc65", "best_bid": "0.41", "best_ask": "0.87"}, {"asset_id": "25107464912227300161765664477112846497546753335497087400297930691126705811916", "price": "0.71", "size": "10", "side": "SELL", "hash": "7207f7761fd3390f2284bc27bfa6da6698fd272d", "best_bid": "0.13", "best_ask": "0.59"}], "timestamp": "1769384363139", "event_type": "price_change"}}
{"_local_timestamp": "2026-01-25T23:39:43.498923+00:00", "data": {"market": "0x86fec61dd9c27294756303c47b77cf6b7ed13ff4097e2967bc333dde4c1ea4da", "price_changes": [{"asset_id": "37660683447879901945455922570375098409697520769704430824022672297921367915347", "price": "0.8", "size": "50", "side": "BUY", "hash": "b2d89c92e92fc523435ad9bb31adb2554ecec572", "best_bid": "0.8", "best_ask": "0.94"}, {"asset_id": "63898934961262618957913174161832335092659130397470681441362226870577487706450", "price": "0.2", "size": "50", "side": "SELL", "hash": "2813406944a78257cb595d535a58f2b8d08805ff", "best_bid": "0.06", "best_ask": "0.2"}], "timestamp": "1769384383434", "event_type": "price_change"}}
{"_local_timestamp": "2026-01-25T23:39:43.499323+00:00", "data": {"market": "0xc114f4fc118df768372c3604e92d404c7c95ab6b25ada140c77dee976a890777", "price_changes": [{"asset_id": "114016092226346692646025674182722281295722777137086779627843163223516672173339", "price": "0.58", "size": "50", "side": "BUY", "hash": "fefb42b8436ad2c97dbe54f8b65d1722b66fec0f", "best_bid": "0.58", "best_ask": "0.76"}, {"asset_id": "95497640963223955548410937239974920841410215692686671066528121763996154872565", "price": "0.42", "size": "50", "side": "SELL", "hash": "96b79a54c0453d2b441643d0d6a1e31503bab045", "best_bid": "0.24", "best_ask": "0.42"}], "timestamp": "1769384383434", "event_type": "price_change"}}
{"_local_timestamp": "2026-01-25T23:39:43.499683+00:00", "data": {"market": "0x11912cb7cc6561870be58a6a52be2943f3e86d2395032f064ef3091d6901882d", "price_changes": [{"asset_id": "50369611503686433705495168228906407585201475093386767089387389512232179527221", "price": "0.75", "size": "50", "side": "BUY", "hash": "c91a602bd82631a1317c3cc717a11c5a5649c437", "best_bid": "0.75", "best_ask": "0.87"}, {"asset_id": "25107464912227300161765664477112846497546753335497087400297930691126705811916", "price": "0.25", "size": "50", "side": "SELL", "hash": "cbb8aef1affc3ab01e0472e175c08e0292a999fd", "best_bid": "0.13", "best_ask": "0.25"}], "timestamp": "1769384383434", "event_type": "price_change"}}
{"_local_timestamp": "2026-01-25T23:39:43.664682+00:00", "data": {"market": "0xc114f4fc118df768372c3604e92d404c7c95ab6b25ada140c77dee976a890777", "price_changes": [{"asset_id": "114016092226346692646025674182722281295722777137086779627843163223516672173339", "price": "0.28", "size": "0", "side": "BUY", "hash": "87b5ed670ae0f2256faf33f7292f07cb2867fc44", "best_bid": "0.58", "best_ask": "0.76"}, {"asset_id": "95497640963223955548410937239974920841410215692686671066528121763996154872565", "price": "0.72", "size": "0", "side": "SELL", "hash": "5362dec615172b34d460483e0bed308592740401", "best_bid": "0.24", "best_ask": "0.42"}], "timestamp": "1769384383594", "event_type": "price_change"}}
{"_local_timestamp": "2026-01-25T23:39:43.762597+00:00", "data": {"market": "0xc114f4fc118df768372c3604e92d404c7c95ab6b25ada140c77dee976a890777", "price_changes": [{"asset_id": "114016092226346692646025674182722281295722777137086779627843163223516672173339", "price": "0.27", "size": "10", "side": "BUY", "hash": "d1083787e145e71cd9e71a77cac658ad244e4a51", "best_bid": "0.58", "best_ask": "0.76"}, {"asset_id": "95497640963223955548410937239974920841410215692686671066528121763996154872565", "price": "0.73", "size": "10", "side": "SELL", "hash": "bbf6a564fa432bc805cf57e8d118db3226bba848", "best_bid": "0.24", "best_ask": "0.42"}], "timestamp": "1769384383695", "event_type": "price_change"}}
{"_local_timestamp": "2026-01-25T23:39:43.762984+00:00", "data": {"market": "0xc114f4fc118df768372c3604e92d404c7c95ab6b25ada140c77dee976a890777", "price_changes": [{"asset_id": "114016092226346692646025674182722281295722777137086779627843163223516672173339", "price": "0.26", "size": "40", "side": "BUY", "hash": "3a6abfe819c0b3cd2f78f5e0a702e449fa3c1bc0", "best_bid": "0.58", "best_ask": "0.76"}, {"asset_id": "95497640963223955548410937239974920841410215692686671066528121763996154872565", "price": "0.74", "size": "40", "side": "SELL", "hash": "59046f9116d5564c794a7f02b1ec9f311ec5ec1e", "best_bid": "0.24", "best_ask": "0.42"}], "timestamp": "1769384383696", "event_type": "price_change"}}
{"_local_timestamp": "2026-01-25T23:39:45.481431+00:00", "data": {"market": "0xf6d98f9984cbd7994c5ad4b44b57e6e65771833e1f682cb6c08e1881cba0be23", "price_changes": [{"asset_id": "111619066987530654938781515834745418625505306643795368186113638707368057832687", "price": "0.72", "size": "50", "side": "BUY", "hash": "4afa4f92c1584dc7750534caf52437b50eb5ede6", "best_bid": "0.72", "best_ask": "0.88"}, {"asset_id": "14133747134142323771619199606203638420186745480544687065966512009432569296940", "price": "0.28", "size": "50", "side": "SELL", "hash": "3db59e75ef3edbd48fc23a429a4b5a191424ff26", "best_bid": "0.12", "best_ask": "0.28"}], "timestamp": "1769384385411", "event_type": "price_change"}}
{"_local_timestamp": "2026-01-25T23:39:45.483081+00:00", "data": {"market": "0xb5f61d0c9ce431d64ba702815984246fa9cd6c2d6399849f0051d8695f2d98ab", "price_changes": [{"asset_id": "98590289222817581558553345992202318138659660940538324229915000516905381167250", "price": "0.76", "size": "50", "side": "BUY", "hash": "f18451bc3051543bde93e5307d12bbe66d4e8b19", "best_bid": "0.76", "best_ask": "0.94"}, {"asset_id": "81582701062623199779039420976989567002417039977161919375131982089037196418005", "price": "0.24", "size": "50", "side": "SELL", "hash": "c206e398539296e271401aca2a7abc774bfbabc2", "best_bid": "0.06", "best_ask": "0.24"}], "timestamp": "1769384385411", "event_type": "price_change"}}
{"_local_timestamp": "2026-01-25T23:39:46.103575+00:00", "data": {"market": "0xc114f4fc118df768372c3604e92d404c7c95ab6b25ada140c77dee976a890777", "price_changes": [{"asset_id": "114016092226346692646025674182722281295722777137086779627843163223516672173339", "price": "0.29", "size": "0", "side": "BUY", "hash": "ed7e1709f2561e135f81b152251534b656a2406f", "best_bid": "0.58", "best_ask": "0.76"}, {"asset_id": "95497640963223955548410937239974920841410215692686671066528121763996154872565", "price": "0.71", "size": "0", "side": "SELL", "hash": "5c49ea1f15c129784205069570b55e28aafc9ea9", "best_bid": "0.24", "best_ask": "0.42"}], "timestamp": "1769384386035", "event_type": "price_change"}}
{"_local_timestamp": "2026-01-25T23:39:46.126818+00:00", "data": {"market": "0xc114f4fc118df768372c3604e92d404c7c95ab6b25ada140c77dee976a890777", "price_changes": [{"asset_id": "114016092226346692646025674182722281295722777137086779627843163223516672173339", "price": "0.28", "size": "20", "side": "BUY", "hash": "b7e9ac9b80b8e1106a234b2954951ab7f1298284", "best_bid": "0.58", "best_ask": "0.76"}, {"asset_id": "95497640963223955548410937239974920841410215692686671066528121763996154872565", "price": "0.72", "size": "20", "side": "SELL", "hash": "17fe1df6e800dd2ecd0fad5e56a5782a855c5c30", "best_bid": "0.24", "best_ask": "0.42"}], "timestamp": "1769384386063", "event_type": "price_change"}}
{"_local_timestamp": "2026-01-25T23:39:46.238565+00:00", "data": {"market": "0xf6d98f9984cbd7994c5ad4b44b57e6e65771833e1f682cb6c08e1881cba0be23", "price_changes": [{"asset_id": "111619066987530654938781515834745418625505306643795368186113638707368057832687", "price": "0.31", "size": "0", "side": "BUY", "hash": "34f5bcc8d2b168bfef9d519458e11f66a2c06744", "best_bid": "0.72", "best_ask": "0.88"}, {"asset_id": "14133747134142323771619199606203638420186745480544687065966512009432569296940", "price": "0.69", "size": "0", "side": "SELL", "hash": "4a769431e811b567377995903080e7ee57203f4c", "best_bid": "0.12", "best_ask": "0.28"}], "timestamp": "1769384386165", "event_type": "price_change"}}
{"_local_timestamp": "2026-01-25T23:39:46.331830+00:00", "data": {"market": "0xf6d98f9984cbd7994c5ad4b44b57e6e65771833e1f682cb6c08e1881cba0be23", "price_changes": [{"asset_id": "111619066987530654938781515834745418625505306643795368186113638707368057832687", "price": "0.33", "size": "10", "side": "BUY", "hash": "490f9df5ed9df473aa94d98ee5a9cb17eb00f095", "best_bid": "0.72", "best_ask": "0.88"}, {"asset_id": "14133747134142323771619199606203638420186745480544687065966512009432569296940", "price": "0.67", "size": "10", "side": "SELL", "hash": "51bb569a37be27993e2966da7cb5d4442b54878b", "best_bid": "0.12", "best_ask": "0.28"}], "timestamp": "1769384386255", "event_type": "price_change"}}
{"_local_timestamp": "2026-01-25T23:39:46.333855+00:00", "data": {"market": "0xf6d98f9984cbd7994c5ad4b44b57e6e65771833e1f682cb6c08e1881cba0be23", "price_changes": [{"asset_id": "111619066987530654938781515834745418625505306643795368186113638707368057832687", "price": "0.25", "size": "15", "side": "BUY", "hash": "70d5502ca9e785f8495031b48ed2d35d48ed6aeb", "best_bid": "0.72", "best_ask": "0.88"}, {"asset_id": "14133747134142323771619199606203638420186745480544687065966512009432569296940", "price": "0.75", "size": "15", "side": "SELL", "hash": "1da9da289054c91e2675e5b2e2b47e2d1f361a6d", "best_bid": "0.12", "best_ask": "0.28"}], "timestamp": "1769384386261", "event_type": "price_change"}}
{"_local_timestamp": "2026-01-25T23:39:50.246860+00:00", "data": {"market": "0xf6d98f9984cbd7994c5ad4b44b57e6e65771833e1f682cb6c08e1881cba0be23", "price_changes": [{"asset_id": "111619066987530654938781515834745418625505306643795368186113638707368057832687", "price": "0.32", "size": "0", "side": "BUY", "hash": "f584a9bad154a57526e1e0b301fcb211b288edfa", "best_bid": "0.72", "best_ask": "0.88"}, {"asset_id": "14133747134142323771619199606203638420186745480544687065966512009432569296940", "price": "0.68", "size": "0", "side": "SELL", "hash": "3e2f0c5079560f381cc50ebd784eb2b0a36c6f01", "best_bid": "0.12", "best_ask": "0.28"}], "timestamp": "1769384390178", "event_type": "price_change"}}
{"_local_timestamp": "2026-01-25T23:39:50.271532+00:00", "data": {"market": "0xf6d98f9984cbd7994c5ad4b44b57e6e65771833e1f682cb6c08e1881cba0be23", "price_changes": [{"asset_id": "111619066987530654938781515834745418625505306643795368186113638707368057832687", "price": "0.34", "size": "20", "side": "BUY", "hash": "2c89857ca59d2541c1ee6bc745ba4e732776157f", "best_bid": "0.72", "best_ask": "0.88"}, {"asset_id": "14133747134142323771619199606203638420186745480544687065966512009432569296940", "price": "0.66", "size": "20", "side": "SELL", "hash": "f469f9bf9bf3f92ddf363031d12b04d36279061e", "best_bid": "0.12", "best_ask": "0.28"}], "timestamp": "1769384390204", "event_type": "price_change"}}
{"_local_timestamp": "2026-01-25T23:40:13.523598+00:00", "data": {"market": "0xf6d98f9984cbd7994c5ad4b44b57e6e65771833e1f682cb6c08e1881cba0be23", "price_changes": [{"asset_id": "111619066987530654938781515834745418625505306643795368186113638707368057832687", "price": "0.47", "size": "0", "side": "BUY", "hash": "f243f342a02a3186fb7cdf03fafa83caa8c9b1de", "best_bid": "0.72", "best_ask": "0.88"}, {"asset_id": "14133747134142323771619199606203638420186745480544687065966512009432569296940", "price": "0.53", "size": "0", "side": "SELL", "hash": "021209cbfe0ed3586da7178562025f950b6bd622", "best_bid": "0.12", "best_ask": "0.28"}], "timestamp": "1769384413461", "event_type": "price_change"}}
