{"_local_timestamp": "2026-01-25T23:40:36.706721+00:00", "data": [{"market": "0x29d688e8ee4dc83cff27ce5d583553be477b4202aba945dff96730aa88397071", "asset_id": "46123672832602976783793170370598938766981479048132054420648285300054482204701", "timestamp": "1769384401342", "hash": "a0be574fd14c7c03fc741cda4ca89000cf816daa", "bids": [{"price": "0.01", "size": "80"}, {"price": "0.02", "size": "261.33"}, {"price": "0.03", "size": "42.39"}, {"price": "0.04", "size": "17.28"}, {"price": "0.05", "size": "35.33"}], "asks": [{"price": "0.99", "size": "7162.91"}, {"price": "0.98", "size": "3400"}, {"price": "0.97", "size": "6.64"}, {"price": "0.96", "size": "1500"}, {"price": "0.95", "size": "30"}, {"price": "0.94", "size": "608"}, {"price": "0.93", "size": "7.41"}, {"price": "0.86", "size": "325"}, {"price": "0.83", "size": "950"}, {"price": "0.82", "size": "156.4"}, {"price": "0.75", "size": "50"}, {"price": "0.58", "size": "100"}, {"price": "0.57", "size": "20"}, {"price": "0.54", "size": "10"}, {"price": "0.5", "size": "5"}, {"price": "0.49", "size": "50"}, {"price": "0.47", "size": "25"}, {"price": "0.46", "size": "20"}, {"price": "0.2", "size": "5"}], "event_type": "book", "last_trade_price": ""}, {"market": "0x29d688e8ee4dc83cff27ce5d583553be477b4202aba945dff96730aa88397071", "asset_id": "22395241560984864794587761975509529149656370897276070318169938852205137917866", "timestamp": "1769384401342", "hash": "0792af280595439d4d23009cf6c72a36f46db570", "bids": [{"price": "0.01", "size": "7162.91"}, {"price": "0.02", "size": "3400"}, {"price": "0.03", "size": "6.64"}, {"price": "0.04", "size": "1500"}, {"price": "0.05", "size": "30"}, {"price": "0.06", "size": "608"}, {"price": "0.07", "size": "7.41"}, {"price": "0.14", "size": "325"}, {"price": "0.17", "size": "950"}, {"price": "0.18", "size": "156.4"}, {"price": "0.25", "size": "50"}, {"price": "0.42", "size": "100"}, {"price": "0.43", "size": "20"}, {"price": "0.46", "size": "10"}, {"price": "0.5", "size": "5"}, {"price": "0.51", "size": "50"}, {"price": "0.53", "size": "25"}, {"price": "0.54", "size": "20"}, {"price": "0.8", "size": "5"}], "asks": [{"price": "0.99", "size": "80"}, {"price": "0.98", "size": "261.33"}, {"price": "0.97", "size": "42.39"}, {"price": "0.96", "size": "17.28"}, {"price": "0.95", "size": "35.33"}], "event_type": "book", "last_trade_price": ""}, {"market": "0xebd6b4d15beed0a4a3a274d6d1bc13e0b15d13a330586190932a3c4c7887b72f", "asset_id": "113435897598335750012134454342623244279140769314836288769122310705258616530095", "timestamp": "1769384406208", "hash": "a6fd17443042fcc7bc9a7d999132fe78c6cceceb", "bids": [{"price": "0.01", "size": "6763.09"}, {"price": "0.02", "size": "3000"}, {"price": "0.03", "size": "9.79"}, {"price": "0.04", "size": "2200"}, {"price": "0.05", "size": "30"}, {"price": "0.06", "size": "408"}, {"price": "0.07", "size": "7.73"}, {"price": "0.09", "size": "600"}, {"price": "0.13", "size": "825"}, {"price": "0.14", "size": "442.85"}, {"price": "0.19", "size": "418.42"}, {"price": "0.2", "size": "105.17"}, {"price": "0.21", "size": "52"}, {"price": "0.24", "size": "266.66"}, {"price": "0.29", "size": "89.65"}, {"price": "0.33", "size": "72.72"}, {"price": "0.38", "size": "127.63"}, {"price": "0.4", "size": "5"}, {"price": "0.41", "size": "10"}, {"price": "0.42", "size": "15"}, {"price": "0.58", "size": "25"}, {"price": "0.6", "size": "25"}, {"price": "0.61", "size": "110"}, {"price": "0.62", "size": "20"}, {"price": "0.71", "size": "150"}, {"price": "0.75", "size": "108.86"}, {"price": "0.84", "size": "154.94"}, {"price": "0.85", "size": "100"}, {"price": "0.86", "size": "10.1"}, {"price": "0.87", "size": "6.38"}], "asks": [{"price": "0.99", "size": "80"}, {"price": "0.98", "size": "20.53"}, {"price": "0.96", "size": "255.09"}, {"price": "0.95", "size": "180"}, {"price": "0.94", "size": "35.08"}], "event_type": "book", "last_trade_price": "0.090"}, {"market": "0x715dc274a5c7adf3771646e36d5e3a8844163dc31e7f02331eb30d2b8108bf9e", "asset_id": "19458454719947582257633203202425613630572016962838703318400930704175824104136", "timestamp": "1769384395958", "hash": "a3ffc1a5d9d7cd716f76c38b2b2718caa29b31ed", "bids": [{"price": "0.01", "size": "1000"}, {"price": "0.02", "size": "400"}, {"price": "0.03", "size": "13.33"}, {"price": "0.06", "size": "600"}, {"price": "0.09", "size": "377.77"}, {"price": "0.12", "size": "306.66"}, {"price": "0.13", "size": "20"}, {"price": "0.15", "size": "186.66"}, {"price": "0.19", "size": "136.84"}, {"price": "0.21", "size": "6"}, {"price": "0.22", "size": "109.09"}, {"price": "0.25", "size": "80"}, {"price": "0.28", "size": "15"}, {"price": "0.29", "size": "229"}, {"price": "0.56", "size": "9.59"}, {"price": "0.57", "size": "16"}, {"price": "0.58", "size": "500"}], "asks": [{"price": "0.99", "size": "5774.98"}, {"price": "0.98", "size": "3000"}, {"price": "0.97", "size": "5.36"}, {"price": "0.96", "size": "2400"}, {"price": "0.95", "size": "35.93"}, {"price": "0.94", "size": "375"}, {"price": "0.93", "size": "485.71"}, {"price": "0.92", "size": "10"}, {"price": "0.91", "size": "361.03"}, {"price": "0.89", "size": "254.54"}, {"price": "0.88", "size": "157"}, {"price": "0.87", "size": "40"}, {"price": "0.86", "size": "205.71"}, {"price": "0.85", "size": "13"}, {"price": "0.84", "size": "150"}, {"price": "0.83", "size": "11.29"}, {"price": "0.82", "size": "111.11"}, {"price": "0.81", "size": "56"}, {"price": "0.75", "size": "252"}, {"price": "0.62", "size": "590"}], "event_type": "book", "last_trade_price": "0.610"}, {"market": "0xebd6b4d15beed0a4a3a274d6d1bc13e0b15d13a330586190932a3c4c7887b72f", "asset_id": "43860483933578174366905172776039394809444972860267197366014959631913892252602", "timestamp": "1769384406208", "hash": "ee1da782d26c96c5c1282c597ae73f5114dabb70", "bids": [{"price": "0.01", "size": "80"}, {"price": "0.02", "size": "20.53"}, {"price": "0.04", "size": "255.09"}, {"price": "0.05", "size": "180"}, {"price": "0.06", "size": "35.08"}], "asks": [{"price": "0.99", "size": "6763.09"}, {"price": "0.98", "size": "3000"}, {"price": "0.97", "size": "9.79"}, {"price": "0.96", "size": "2200"}, {"price": "0.95", "size": "30"}, {"price": "0.94", "size": "408"}, {"price": "0.93", "size": "7.73"}, {"price": "0.91", "size": "600"}, {"price": "0.87", "size": "825"}, {"price": "0.86", "size": "442.85"}, {"price": "0.81", "size": "418.42"}, {"price": "0.8", "size": "105.17"}, {"price": "0.79", "size": "52"}, {"price": "0.76", "size": "266.66"}, {"price": "0.71", "size": "89.65"}, {"price": "0.67", "size": "72.72"}, {"price": "0.62", "size": "127.63"}, {"price": "0.6", "size": "5"}, {"price": "0.59", "size": "10"}, {"price": "0.58", "size": "15"}, {"price": "0.42", "size": "25"}, {"price": "0.4", "size": "25"}, {"price": "0.39", "size": "110"}, {"price": "0.38", "size": "20"}, {"price": "0.29", "size": "150"}, {"price": "0.25", "size": "108.86"}, {"price": "0.16", "size": "154.94"}, {"price": "0.15", "size": "100"}, {"price": "0.14", "size": "10.1"}, {"price": "0.13", "size": "6.38"}], "event_type": "book", "last_trade_price": "0.090"}, {"market": "0xd62d0fd81efeba80c7d331577b8cfdaf89eb287a64f65f6418677f5669da4374", "asset_id": "50806857340536377589471864244012059415352637140902118853666778383891415395995", "timestamp": "1769384406240", "hash": "0e4d0e9b097fcb8077626bffa8fdbea5173e20c4", "bids": [{"price": "0.01", "size": "7129.6"}, {"price": "0.02", "size": "3400"}, {"price": "0.03", "size": "7.88"}, {"price": "0.04", "size": "1500"}, {"price": "0.05", "size": "30"}, {"price": "0.06", "size": "408"}, {"price": "0.07", "size": "7.41"}, {"price": "0.09", "size": "600"}, {"price": "0.14", "size": "567.85"}, {"price": "0.16", "size": "1100"}, {"price": "0.18", "size": "177.77"}, {"price": "0.19", "size": "5.87"}, {"price": "0.23", "size": "271.73"}, {"price": "0.24", "size": "135"}, {"price": "0.28", "size": "92.85"}, {"price": "0.32", "size": "75"}, {"price": "0.37", "size": "54.05"}, {"price": "0.4", "size": "20"}, {"price": "0.42", "size": "47.72"}, {"price": "0.45", "size": "126.66"}, {"price": "0.46", "size": "5"}, {"price": "0.47", "size": "10"}, {"price": "0.5", "size": "50"}, {"price": "0.52", "size": "25"}, {"price": "0.53", "size": "20"}, {"price": "0.71", "size": "20"}, {"price": "0.77", "size": "5"}, {"price": "0.87", "size": "300"}, {"price": "0.88", "size": "100"}, {"price": "0.89", "size": "66.66"}], "asks": [{"price": "0.99", "size": "97.22"}, {"price": "0.98", "size": "55"}, {"price": "0.97", "size": "8.66"}, {"price": "0.96", "size": "17.22"}, {"price": "0.93", "size": "13.1"}], "event_type": "book", "last_trade_price": "0.100"}, {"market": "0x715dc274a5c7adf3771646e36d5e3a8844163dc31e7f02331eb30d2b8108bf9e", "asset_id": "817582445527276447057755966542888616081641371741603398122454732956499627950", "timestamp": "1769384395958", "hash": "39afa848c8e6590b57e2e11932319281bbdd375c", "bids": [{"price": "0.01", "size": "5774.98"}, {"price": "0.02", "size": "3000"}, {"price": "0.03", "size": "5.36"}, {"price": "0.04", "size": "2400"}, {"price": "0.05", "size": "35.93"}, {"price": "0.06", "size": "375"}, {"price": "0.07", "size": "485.71"}, {"price": "0.08", "size": "10"}, {"price": "0.09", "size": "361.03"}, {"price": "0.11", "size": "254.54"}, {"price": "0.12", "size": "157"}, {"price": "0.13", "size": "40"}, {"price": "0.14", "size": "205.71"}, {"price": "0.15", "size": "13"}, {"price": "0.16", "size": "150"}, {"price": "0.17", "size": "11.29"}, {"price": "0.18", "size": "111.11"}, {"price": "0.19", "size": "56"}, {"price": "0.25", "size": "252"}, {"price": "0.38", "size": "590"}], "asks": [{"price": "0.99", "size": "1000"}, {"price": "0.98", "size": "400"}, {"price": "0.97", "size": "13.33"}, {"price": "0.94", "size": "600"}, {"price": "0.91", "size": "377.77"}, {"price": "0.88", "size": "306.66"}, {"price": "0.87", "size": "20"}, {"price": "0.85", "size": "186.66"}, {"price": "0.81", "size": "136.84"}, {"price": "0.79", "size": "6"}, {"price": "0.78", "size": "109.09"}, {"price": "0.75", "size": "80"}, {"price": "0.72", "size": "15"}, {"price": "0.71", "size": "229"}, {"price": "0.44", "size": "9.59"}, {"price": "0.43", "size": "16"}, {"price": "0.42", "size": "500"}], "event_type": "book", "last_trade_price": "0.610"}, {"market": "0xd62d0fd81efeba80c7d331577b8cfdaf89eb287a64f65f6418677f5669da4374", "asset_id": "44436347575766030163252235546454470356610478743001712085002709882075518933616", "timestamp": "1769384406240", "hash": "43b15e968cdaf2aaee450d51a309d2846ba00790", "bids": [{"price": "0.01", "size": "97.22"}, {"price": "0.02", "size": "55"}, {"price": "0.03", "size": "8.66"}, {"price": "0.04", "size": "17.22"}, {"price": "0.07", "size": "13.1"}], "asks": [{"price": "0.99", "size": "7129.6"}, {"price": "0.98", "size": "3400"}, {"price": "0.97", "size": "7.88"}, {"price": "0.96", "size": "1500"}, {"price": "0.95", "size": "30"}, {"price": "0.94", "size": "408"}, {"price": "0.93", "size": "7.41"}, {"price": "0.91", "size": "600"}, {"price": "0.86", "size": "567.85"}, {"price": "0.84", "size": "1100"}, {"price": "0.82", "size": "177.77"}, {"price": "0.81", "size": "5.87"}, {"price": "0.77", "size": "271.73"}, {"price": "0.76", "size": "135"}, {"price": "0.72", "size": "92.85"}, {"price": "0.68", "size": "75"}, {"price": "0.63", "size": "54.05"}, {"price": "0.6", "size": "20"}, {"price": "0.58", "size": "47.72"}, {"price": "0.55", "size": "126.66"}, {"price": "0.54", "size": "5"}, {"price": "0.53", "size": "10"}, {"price": "0.5", "size": "50"}, {"price": "0.48", "size": "25"}, {"price": "0.47", "size": "20"}, {"price": "0.29", "size": "20"}, {"price": "0.23", "size": "5"}, {"price": "0.13", "size": "300"}, {"price": "0.12", "size": "100"}, {"price": "0.11", "size": "66.66"}], "event_type": "book", "last_trade_price": "0.100"}, {"market": "0xfb08a969a2c05beda8b5743959182db28be71832f9a84872a786e809b77b5350", "asset_id": "13908252531396871469657521961663517650827376216919668668811621820614371209132", "timestamp": "1769384397880", "hash": "0101232ac5cdabe6b7404ccd01d1ecafe4b43afd", "bids": [{"price": "0.001", "size": "3707.59"}, {"price": "0.002", "size": "1256.56"}, {"price": "0.003", "size": "1400"}, {"price": "0.004", "size": "11.34"}, {"price": "0.006", "size": "200"}, {"price": "0.01", "size": "6750"}, {"price": "0.011", "size": "5.74"}, {"price": "0.02", "size": "3700"}, {"price": "0.021", "size": "11.43"}, {"price": "0.04", "size": "1500"}, {"price": "0.05", "size": "30"}, {"price": "0.051", "size": "39"}, {"price": "0.06", "size": "375"}, {"price": "0.061", "size": "9.38"}, {"price": "0.09", "size": "600"}, {"price": "0.13", "size": "586.53"}, {"price": "0.17", "size": "950"}, {"price": "0.18", "size": "327.77"}, {"price": "0.181", "size": "5.85"}, {"price": "0.22", "size": "127.27"}, {"price": "0.231", "size": "500"}, {"price": "0.27", "size": "96.29"}, {"price": "0.31", "size": "77.41"}, {"price": "0.35", "size": "57.14"}, {"price": "0.351", "size": "5"}, {"price": "0.537", "size": "100"}, {"price": "0.538", "size": "15"}, {"price": "0.632", "size": "10"}, {"price": "0.634", "size": "25"}, {"price": "0.636", "size": "25"}, {"price": "0.64", "size": "10"}, {"price": "0.641", "size": "20"}, {"price": "0.84", "size": "50"}, {"price": "0.842", "size": "40"}], "asks": [{"price": "0.999", "size": "5596.36"}, {"price": "0.998", "size": "560.34"}, {"price": "0.997", "size": "206.3"}, {"price": "0.996", "size": "5.14"}, {"price": "0.995", "size": "40.04"}, {"price": "0.989", "size": "133.03"}, {"price": "0.985", "size": "8.95"}, {"price": "0.979", "size": "133.03"}, {"price": "0.978", "size": "45.4"}, {"price": "0.976", "size": "110.4"}, {"price": "0.975", "size": "180"}, {"price": "0.974", "size": "33.03"}], "event_type": "book", "last_trade_price": ""}, {"market": "0xfb08a969a2c05beda8b5743959182db28be71832f9a84872a786e809b77b5350", "asset_id": "28670530274590253141384619337562139640467932392972183997943459931027267172276", "timestamp": "1769384397880", "hash": "d14c28d995f480e6454aa5c1d2939ec30ed28fda", "bids": [{"price": "0.001", "size": "5596.36"}, {"price": "0.002", "size": "560.34"}, {"price": "0.003", "size": "206.3"}, {"price": "0.004", "size": "5.14"}, {"price": "0.005", "size": "40.04"}, {"price": "0.011", "size": "133.03"}, {"price": "0.015", "size": "8.95"}, {"price": "0.021", "size": "133.03"}, {"price": "0.022", "size": "45.4"}, {"price": "0.024", "size": "110.4"}, {"price": "0.025", "size": "180"}, {"price": "0.026", "size": "33.03"}], "asks": [{"price": "0.999", "size": "3707.59"}, {"price": "0.998", "size": "1256.56"}, {"price": "0.997", "size": "1400"}, {"price": "0.996", "size": "11.34"}, {"price": "0.994", "size": "200"}, {"price": "0.99", "size": "6750"}, {"price": "0.989", "size": "5.74"}, {"price": "0.98", "size": "3700"}, {"price": "0.979", "size": "11.43"}, {"price": "0.96", "size": "1500"}, {"price": "0.95", "size": "30"}, {"price": "0.949", "size": "39"}, {"price": "0.94", "size": "375"}, {"price": "0.939", "size": "9.38"}, {"price": "0.91", "size": "600"}, {"price": "0.87", "size": "586.53"}, {"price": "0.83", "size": "950"}, {"price": "0.82", "size": "327.77"}, {"price": "0.819", "size": "5.85"}, {"price": "0.78", "size": "127.27"}, {"price": "0.769", "size": "500"}, {"price": "0.73", "size": "96.29"}, {"price": "0.69", "size": "77.41"}, {"price": "0.65", "size": "57.14"}, {"price": "0.649", "size": "5"}, {"price": "0.463", "size": "100"}, {"price": "0.462", "size": "15"}, {"price": "0.368", "size": "10"}, {"price": "0.366", "size": "25"}, {"price": "0.364", "size": "25"}, {"price": "0.36", "size": "10"}, {"price": "0.359", "size": "20"}, {"price": "0.16", "size": "50"}, {"price": "0.158", "size": "40"}], "event_type": "book", "last_trade_price": ""}]}
{"_local_timestamp": "2026-01-25T23:40:45.767243+00:00", "data": {"market": "0x29d688e8ee4dc83cff27ce5d583553be477b4202aba945dff96730aa88397071", "price_changes": [{"asset_id": "22395241560984864794587761975509529149656370897276070318169938852205137917866", "price": "0.54", "size": "210", "side": "BUY", "hash": "9b7060553972c343bb1540b8ef07dd60117e00d4", "best_bid": "0.8", "best_ask": "0.95"}, {"asset_id": "46123672832602976783793170370598938766981479048132054420648285300054482204701", "price": "0.46", "size": "210", "side": "SELL", "hash": "c257341595affea85fb9db975f457710b25dcd7f", "best_bid": "0.05", "best_ask": "0.2"}], "timestamp": "1769384445701", "event_type": "price_change"}}
{"_local_timestamp": "2026-01-25T23:40:45.772670+00:00", "data": {"market": "0x29d688e8ee4dc83cff27ce5d583553be477b4202aba945dff96730aa88397071", "price_changes": [{"asset_id": "22395241560984864794587761975509529149656370897276070318169938852205137917866", "price": "0.55", "size": "190", "side": "BUY", "hash": "f6a95bf923a1c5ee3d46018942f60c8ab03a0ef7", "best_bid": "0.8", "best_ask": "0.95"}, {"asset_id": "46123672832602976783793170370598938766981479048132054420648285300054482204701", "price": "0.45", "size": "190", "side": "SELL", "hash": "d95e4d0950338ee45c6ce9778c21ca84712a40e0", "best_bid": "0.05", "best_ask": "0.2"}], "timestamp": "1769384445702", "event_type": "price_change"}}
{"_local_timestamp": "2026-01-25T23:40:47.681697+00:00", "data": {"market": "0x29d688e8ee4dc83cff27ce5d583553be477b4202aba945dff96730aa88397071", "price_changes": [{"asset_id": "46123672832602976783793170370598938766981479048132054420648285300054482204701", "price": "0.57", "size": "0", "side": "SELL", "hash": "800f8a60a1ee0e92eae44fe22fcd2967a4feb1f9", "best_bid": "0.05", "best_ask": "0.2"}, {"asset_id": "22395241560984864794587761975509529149656370897276070318169938852205137917866", "price": "0.43", "size": "0", "side": "BUY", "hash": "6d6f52c3797d7f0c464f807bfe0a190d2f4db8ef", "best_bid": "0.8", "best_ask": "0.95"}], "timestamp": "1769384447611", "event_type": "price_change"}}
{"_local_timestamp": "2026-01-25T23:40:47.745889+00:00", "data": {"market": "0x29d688e8ee4dc83cff27ce5d583553be477b4202aba945dff96730aa88397071", "price_changes": [{"asset_id": "46123672832602976783793170370598938766981479048132054420648285300054482204701", "price": "0.44", "size": "20", "side": "SELL", "hash": "7da96e54a3ff2e1de121d64dd3516a9184bc2759", "best_bid": "0.05", "best_ask": "0.2"}, {"asset_id": "22395241560984864794587761975509529149656370897276070318169938852205137917866", "price": "0.56", "size": "20", "side": "BUY", "hash": "940979a143e3d4035a0604c1f72975ce119ebf44", "best_bid": "0.8", "best_ask": "0.95"}], "timestamp": "1769384447670", "event_type": "price_change"}}
{"_local_timestamp": "2026-01-25T23:40:48.333811+00:00", "data": {"market": "0x29d688e8ee4dc83cff27ce5d583553be477b4202aba945dff96730aa88397071", "price_changes": [{"asset_id": "22395241560984864794587761975509529149656370897276070318169938852205137917866", "price": "0.54", "size": "190", "side": "BUY", "hash": "a84ab0e7a92d7fa791566074203eb2da946877ae", "best_bid": "0.8", "best_ask": "0.95"}, {"asset_id": "46123672832602976783793170370598938766981479048132054420648285300054482204701", "price": "0.46", "size": "190", "side": "SELL", "hash": "e8c8b59580a15a165e548b5d7efd4d100f25f612", "best_bid": "0.05", "best_ask": "0.2"}], "timestamp": "1769384448270", "event_type": "price_change"}}
{"_local_timestamp": "2026-01-25T23:40:48.367482+00:00", "data": {"market": "0x29d688e8ee4dc83cff27ce5d583553be477b4202aba945dff96730aa88397071", "price_changes": [{"asset_id": "22395241560984864794587761975509529149656370897276070318169938852205137917866", "price": "0.57", "size": "20", "side": "BUY", "hash": "90b1b96b066f56afa96f568517fca0e7db9d70ad", "best_bid": "0.8", "best_ask": "0.95"}, {"asset_id": "46123672832602976783793170370598938766981479048132054420648285300054482204701", "price": "0.43", "size": "20", "side": "SELL", "hash": "62debd619368162d8da7c1d7cb1a95c1115fd778", "best_bid": "0.05", "best_ask": "0.2"}], "timestamp": "1769384448295", "event_type": "price_change"}}
{"_local_timestamp": "2026-01-25T23:41:06.791298+00:00", "data": {"market": "0xfb08a969a2c05beda8b5743959182db28be71832f9a84872a786e809b77b5350", "price_changes": [{"asset_id": "28670530274590253141384619337562139640467932392972183997943459931027267172276", "price": "0.002", "size": "460.34", "side": "BUY", "hash": "d469b78679a42807217a145cbcfc6ae315d9868f", "best_bid": "0.026", "best_ask": "0.158"}, {"asset_id": "13908252531396871469657521961663517650827376216919668668811621820614371209132", "price": "0.998", "size": "460.34", "side": "SELL", "hash": "e938c23aff486aa8244e607d91f8388be9fffb99", "best_bid": "0.842", "best_ask": "0.974"}], "timestamp": "1769384466638", "event_type": "price_change"}}
{"_local_timestamp": "2026-01-25T23:41:12.040330+00:00", "data": {"market": "0x29d688e8ee4dc83cff27ce5d583553be477b4202aba945dff96730aa88397071", "price_changes": [{"asset_id": "22395241560984864794587761975509529149656370897276070318169938852205137917866", "price": "0.55", "size": "0", "side": "BUY", "hash": "c73474f20a82f7804eba497f8dfe5669e48b9dff", "best_bid": "0.8", "best_ask": "0.95"}, {"asset_id": "46123672832602976783793170370598938766981479048132054420648285300054482204701", "price": "0.45", "size": "0", "side": "SELL", "hash": "5e7145b94e82ba7f87ab84b6efd0daefd31c72c4", "best_bid": "0.05", "best_ask": "0.2"}], "timestamp": "1769384471927", "event_type": "price_change"}}
{"_local_timestamp": "2026-01-25T23:41:12.046348+00:00", "data": {"market": "0x29d688e8ee4dc83cff27ce5d583553be477b4202aba945dff96730aa88397071", "price_changes": [{"asset_id": "22395241560984864794587761975509529149656370897276070318169938852205137917866", "price": "0.54", "size": "0", "side": "BUY", "hash": "c73474f20a82f7804eba497f8dfe5669e48b9dff", "best_bid": "0.8", "best_ask": "0.95"}, {"asset_id": "46123672832602976783793170370598938766981479048132054420648285300054482204701", "price": "0.46", "size": "0", "side": "SELL", "hash": "5e7145b94e82ba7f87ab84b6efd0daefd31c72c4", "best_bid": "0.05", "best_ask": "0.2"}], "timestamp": "1769384471927", "event_type": "price_change"}}
{"_local_timestamp": "2026-01-25T23:41:12.676616+00:00", "data": {"market": "0x29d688e8ee4dc83cff27ce5d583553be477b4202aba945dff96730aa88397071", "price_changes": [{"asset_id": "46123672832602976783793170370598938766981479048132054420648285300054482204701", "price": "0.44", "size": "0", "side": "SELL", "hash": "7ff37ac871c6bda22fd6d211b7e846cf30b01d95", "best_bid": "0.05", "best_ask": "0.2"}, {"asset_id": "22395241560984864794587761975509529149656370897276070318169938852205137917866", "price": "0.56", "size": "0", "side": "BUY", "hash": "514f0f51d54bbf343761bc38929a1a4e7ce924a6", "best_bid": "0.8", "best_ask": "0.95"}], "timestamp": "1769384472610", "event_type": "price_change"}}
{"_local_timestamp": "2026-01-25T23:41:12.766540+00:00", "data": {"market": "0x29d688e8ee4dc83cff27ce5d583553be477b4202aba945dff96730aa88397071", "price_changes": [{"asset_id": "46123672832602976783793170370598938766981479048132054420648285300054482204701", "price": "0.57", "size": "20", "side": "SELL", "hash": "827496b7c4723a9a31ad03cc5b62fe3567d341b1", "best_bid": "0.05", "best_ask": "0.2"}, {"asset_id": "22395241560984864794587761975509529149656370897276070318169938852205137917866", "price": "0.43", "size": "20", "side": "BUY", "hash": "2753858d58085d891ee3a27280b3f4ff31062000", "best_bid": "0.8", "best_ask": "0.95"}], "timestamp": "1769384472689", "event_type": "price_change"}}
{"_local_timestamp": "2026-01-25T23:41:12.831235+00:00", "data": {"market": "0xebd6b4d15beed0a4a3a274d6d1bc13e0b15d13a330586190932a3c4c7887b72f", "price_changes": [{"asset_id": "113435897598335750012134454342623244279140769314836288769122310705258616530095", "price": "0.42", "size": "0", "side": "BUY", "hash": "386bc21345bee00a70b36dbbdeee6071a23037a4", "best_bid": "0.87", "best_ask": "0.94"}, {"asset_id": "43860483933578174366905172776039394809444972860267197366014959631913892252602", "price": "0.58", "size": "0", "side": "SELL", "hash": "d2c8e14da1ea22d219c9430eabcfafe3e88a6d88", "best_bid": "0.06", "best_ask": "0.13"}], "timestamp": "1769384472761", "event_type": "price_change"}}
{"_local_timestamp": "2026-01-25T23:41:15.927450+00:00", "data": {"market": "0x29d688e8ee4dc83cff27ce5d583553be477b4202aba945dff96730aa88397071", "price_changes": [{"asset_id": "22395241560984864794587761975509529149656370897276070318169938852205137917866", "price": "0.57", "size": "0", "side": "BUY", "hash": "9baa96a2f7b7a7c9866393d2569ea6d4186251bf", "best_bid": "0.8", "best_ask": "0.95"}, {"asset_id": "46123672832602976783793170370598938766981479048132054420648285300054482204701", "price": "0.43", "size": "0", "side": "SELL", "hash": "d39286863e5306eaf54bc6f3b67b20fa33c5d823", "best_bid": "0.05", "best_ask": "0.2"}], "timestamp": "1769384475860", "event_type": "price_change"}}
{"_local_timestamp": "2026-01-25T23:41:15.960794+00:00", "data": {"market": "0x29d688e8ee4dc83cff27ce5d583553be477b4202aba945dff96730aa88397071", "price_changes": [{"asset_id": "22395241560984864794587761975509529149656370897276070318169938852205137917866", "price": "0.54", "size": "20", "side": "BUY", "hash": "ecadcb3dd5c6399de95d9588829d26ede4f58095", "best_bid": "0.8", "best_ask": "0.95"}, {"asset_id": "46123672832602976783793170370598938766981479048132054420648285300054482204701", "price": "0.46", "size": "20", "side": "SELL", "hash": "336c952f89a9f61016701a68b78ab67a1241aabb", "best_bid": "0.05", "best_ask": "0.2"}], "timestamp": "1769384475885", "event_type": "price_change"}}
{"_local_timestamp": "2026-01-25T23:41:30.084545+00:00", "data": {"market": "0xfb08a969a2c05beda8b5743959182db28be71832f9a84872a786e809b77b5350", "price_changes": [{"asset_id": "13908252531396871469657521961663517650827376216919668668811621820614371209132", "price": "0.84", "size": "0", "side": "BUY", "hash": "480058b06b7c54088cac5e4fbf93843c7d05badb", "best_bid": "0.842", "best_ask": "0.974"}, {"asset_id": "28670530274590253141384619337562139640467932392972183997943459931027267172276", "price": "0.16", "size": "0", "side": "SELL", "hash": "244a5f685afb2a00c6b21db39231e97bb90672b0", "best_bid": "0.026", "best_ask": "0.158"}], "timestamp": "1769384490000", "event_type": "price_change"}}
{"_local_timestamp": "2026-01-25T23:41:42.547396+00:00", "data": {"market": "0xebd6b4d15beed0a4a3a274d6d1bc13e0b15d13a330586190932a3c4c7887b72f", "price_changes": [{"asset_id": "113435897598335750012134454342623244279140769314836288769122310705258616530095", "price": "0.87", "size": "50.05", "side": "BUY", "hash": "b9db671ebbc54714283935db8412e578934ac67e", "best_bid": "0.87", "best_ask": "0.94"}, {"asset_id": "43860483933578174366905172776039394809444972860267197366014959631913892252602", "price": "0.13", "size": "50.05", "side": "SELL", "hash": "1cb42240d88f1bea0b9a9b4c417d3ebdc9421839", "best_bid": "0.06", "best_ask": "0.13"}], "timestamp": "1769384502467", "event_type": "price_change"}}
{"_local_timestamp": "2026-01-25T23:41:42.566807+00:00", "data": {"market": "0xebd6b4d15beed0a4a3a274d6d1bc13e0b15d13a330586190932a3c4c7887b72f", "price_changes": [{"asset_id": "113435897598335750012134454342623244279140769314836288769122310705258616530095", "price": "0.71", "size": "170", "side": "BUY", "hash": "9a5c91ac80553e86dc503ccead8cc037e0f8c081", "best_bid": "0.87", "best_ask": "0.94"}, {"asset_id": "43860483933578174366905172776039394809444972860267197366014959631913892252602", "price": "0.29", "size": "170", "side": "SELL", "hash": "1accf968a45b009ecf719c1cffdcb31498c4aee0", "best_bid": "0.06", "best_ask": "0.13"}], "timestamp": "1769384502499", "event_type": "price_change"}}
{"_local_timestamp": "2026-01-25T23:41:50.953302+00:00", "data": {"market": "0xebd6b4d15beed0a4a3a274d6d1bc13e0b15d13a330586190932a3c4c7887b72f", "price_changes": [{"asset_id": "113435897598335750012134454342623244279140769314836288769122310705258616530095", "price": "0.14", "size": "242.85", "side": "BUY", "hash": "48e95450492f1bae9b757518080d9fca505aa04b", "best_bid": "0.87", "best_ask": "0.94"}, {"asset_id": "43860483933578174366905172776039394809444972860267197366014959631913892252602", "price": "0.86", "size": "242.85", "side": "SELL", "hash": "01dc3876581b32fad9f2a41a6c6172f6d7065acf", "best_bid": "0.06", "best_ask": "0.13"}], "timestamp": "1769384510760", "event_type": "price_change"}}
{"_local_timestamp": "2026-01-25T23:41:50.967930+00:00", "data": {"market": "0xd62d0fd81efeba80c7d331577b8cfdaf89eb287a64f65f6418677f5669da4374", "price_changes": [{"asset_id": "50806857340536377589471864244012059415352637140902118853666778383891415395995", "price": "0.45", "size": "66.66", "side": "BUY", "hash": "aa9b17651587ce32d463840379c0c5104c28043f", "best_bid": "0.89", "best_ask": "0.93"}, {"asset_id": "44436347575766030163252235546454470356610478743001712085002709882075518933616", "price": "0.55", "size": "66.66", "side": "SELL", "hash": "e435e8757faa8a1f6481d36fa74aef1af5cceda1", "best_bid": "0.07", "best_ask": "0.11"}], "timestamp": "1769384510772", "event_type": "price_change"}}
{"_local_timestamp": "2026-01-25T23:41:52.811038+00:00", "data": {"market": "0xebd6b4d15beed0a4a3a274d6d1bc13e0b15d13a330586190932a3c4c7887b72f", "price_changes": [{"asset_id": "113435897598335750012134454342623244279140769314836288769122310705258616530095", "price": "0.13", "size": "1025", "side": "BUY", "hash": "f8b44b95a02d24dfd34ed96a360c7632746478d0", "best_bid": "0.87", "best_ask": "0.94"}, {"asset_id": "43860483933578174366905172776039394809444972860267197366014959631913892252602", "price": "0.87", "size": "1025", "side": "SELL", "hash": "c944aefb86958331d3db7316b0fe865d7589a0c2", "best_bid": "0.06", "best_ask": "0.13"}], "timestamp": "1769384511800", "event_type": "price_change"}}
{"_local_timestamp": "2026-01-25T23:41:52.894716+00:00", "data": {"market": "0xd62d0fd81efeba80c7d331577b8cfdaf89eb287a64f65f6418677f5669da4374", "price_changes": [{"asset_id": "50806857340536377589471864244012059415352637140902118853666778383891415395995", "price": "0.5", "size": "110", "side": "BUY", "hash": "aaac9ddda51ce1f24b60a3033816816b408c1041", "best_bid": "0.89", "best_ask": "0.93"}, {"asset_id": "44436347575766030163252235546454470356610478743001712085002709882075518933616", "price": "0.5", "size": "110", "side": "SELL", "hash": "3384ee37dfe0471a189fdd50d826344d3d0e648e", "best_bid": "0.07", "best_ask": "0.11"}], "timestamp": "1769384511840", "event_type": "price_change"}}
{"_local_timestamp": "2026-01-25T23:42:30.894812+00:00", "data": {"market": "0xebd6b4d15beed0a4a3a274d6d1bc13e0b15d13a330586190932a3c4c7887b72f", "price_changes": [{"asset_id": "113435897598335750012134454342623244279140769314836288769122310705258616530095", "price": "0.75", "size": "8.86", "side": "BUY", "hash": "9765ba56cb77f3926795abdfb17cdbe12f89d772", "best_bid": "0.87", "best_ask": "0.94"}, {"asset_id": "43860483933578174366905172776039394809444972860267197366014959631913892252602", "price": "0.25", "size": "8.86", "side": "SELL", "hash": "1163af33552c293dac1bf4674d5e348e914c47af", "best_bid": "0.06", "best_ask": "0.13"}], "timestamp": "1769384550799", "event_type": "price_change"}}
{"_local_timestamp": "2026-01-25T23:42:30.895742+00:00", "data": {"market": "0xebd6b4d15beed0a4a3a274d6d1bc13e0b15d13a330586190932a3c4c7887b72f", "price_changes": [{"asset_id": "113435897598335750012134454342623244279140769314836288769122310705258616530095", "price": "0.61", "size": "10", "side": "BUY", "hash": "9765ba56cb77f3926795abdfb17cdbe12f89d772", "best_bid": "0.87", "best_ask": "0.94"}, {"asset_id": "43860483933578174366905172776039394809444972860267197366014959631913892252602", "price": "0.39", "size": "10", "side": "SELL", "hash": "1163af33552c293dac1bf4674d5e348e914c47af", "best_bid": "0.06", "best_ask": "0.13"}], "timestamp": "1769384550799", "event_type": "price_change"}}
{"_local_timestamp": "2026-01-25T23:42:31.321037+00:00", "data": {"market": "0xebd6b4d15beed0a4a3a274d6d1bc13e0b15d13a330586190932a3c4c7887b72f", "price_changes": [{"asset_id": "113435897598335750012134454342623244279140769314836288769122310705258616530095", "price": "0.88", "size": "66.66", "side": "BUY", "hash": "c6c91d2db93651bb84ffc2e9d0d7f8cb9bd08609", "best_bid": "0.88", "best_ask": "0.94"}, {"asset_id": "43860483933578174366905172776039394809444972860267197366014959631913892252602", "price": "0.12", "size": "66.66", "side": "SELL", "hash": "02af69c25c023d06c7fb2336dbba5afce6695610", "best_bid": "0.06", "best_ask": "0.12"}], "timestamp": "1769384551217", "event_type": "price_change"}}
{"_local_timestamp": "2026-01-25T23:42:31.321606+00:00", "data": {"market": "0xebd6b4d15beed0a4a3a274d6d1bc13e0b15d13a330586190932a3c4c7887b72f", "price_changes": [{"asset_id": "113435897598335750012134454342623244279140769314836288769122310705258616530095", "price": "0.75", "size": "75.52", "side": "BUY", "hash": "b972c2155a640465061fa8b2dc1e5501dc5de299", "best_bid": "0.88", "best_ask": "0.94"}, {"asset_id": "43860483933578174366905172776039394809444972860267197366014959631913892252602", "price": "0.25", "size": "75.52", "side": "SELL", "hash": "7f129524d09a017272acc39baa5fb890e8d0c20f", "best_bid": "0.06", "best_ask": "0.12"}], "timestamp": "1769384551221", "event_type": "price_change"}}
{"_local_timestamp": "2026-01-25T23:42:31.333705+00:00", "data": {"market": "0xebd6b4d15beed0a4a3a274d6d1bc13e0b15d13a330586190932a3c4c7887b72f", "price_changes": [{"asset_id": "113435897598335750012134454342623244279140769314836288769122310705258616530095", "price": "0.63", "size": "66.66", "side": "BUY", "hash": "e4bbbb1ed543358d819bc9eac4e1a1faee9bcd9e", "best_bid": "0.88", "best_ask": "0.94"}, {"asset_id": "43860483933578174366905172776039394809444972860267197366014959631913892252602", "price": "0.37", "size": "66.66", "side": "SELL", "hash": "46e811aa93c5846755a1537309135471b2490745", "best_bid": "0.06", "best_ask": "0.12"}], "timestamp": "1769384551237", "event_type": "price_change"}}
{"_local_timestamp": "2026-01-25T23:42:31.337113+00:00", "data": {"market": "0xebd6b4d15beed0a4a3a274d6d1bc13e0b15d13a330586190932a3c4c7887b72f", "price_changes": [{"asset_id": "113435897598335750012134454342623244279140769314836288769122310705258616530095", "price": "0.71", "size": "150", "side": "BUY", "hash": "d3d8bdefc3d762288871c90dbc02cd889943155f", "best_bid": "0.88", "best_ask": "0.94"}, {"asset_id": "43860483933578174366905172776039394809444972860267197366014959631913892252602", "price": "0.29", "size": "150", "side": "SELL", "hash": "0d453ff609b28c87eeb0653e918d7f3123ef5d97", "best_bid": "0.06", "best_ask": "0.12"}], "timestamp": "1769384551241", "event_type": "price_change"}}
{"_local_timestamp": "2026-01-25T23:42:31.805223+00:00", "data": {"market": "0xebd6b4d15beed0a4a3a274d6d1bc13e0b15d13a330586190932a3c4c7887b72f", "price_changes": [{"asset_id": "113435897598335750012134454342623244279140769314836288769122310705258616530095", "price": "0.88", "size": "96.66", "side": "BUY", "hash": "1d637280cfa9e8043f95080ca23be90c52886f97", "best_bid": "0.88", "best_ask": "0.94"}, {"asset_id": "43860483933578174366905172776039394809444972860267197366014959631913892252602", "price": "0.12", "size": "96.66", "side": "SELL", "hash": "814fe3a2e160f3c8de06d7e9b41255256ee08068", "best_bid": "0.06", "best_ask": "0.12"}], "timestamp": "1769384551703", "event_type": "price_change"}}
{"_local_timestamp": "2026-01-25T23:42:32.892837+00:00", "data": {"market": "0xebd6b4d15beed0a4a3a274d6d1bc13e0b15d13a330586190932a3c4c7887b72f", "price_changes": [{"asset_id": "113435897598335750012134454342623244279140769314836288769122310705258616530095", "price": "0.62", "size": "0", "side": "BUY", "hash": "aab68f703237cbbfce2368aaf258bf475a27512c", "best_bid": "0.88", "best_ask": "0.94"}, {"asset_id": "43860483933578174366905172776039394809444972860267197366014959631913892252602", "price": "0.38", "size": "0", "side": "SELL", "hash": "ca8cc34894e3c558f720dd1f86ad69adf70e6ce6", "best_bid": "0.06", "best_ask": "0.12"}], "timestamp": "1769384552786", "event_type": "price_change"}}
{"_local_timestamp": "2026-01-25T23:42:32.918878+00:00", "data": {"market": "0xebd6b4d15beed0a4a3a274d6d1bc13e0b15d13a330586190932a3c4c7887b72f", "price_changes": [{"asset_id": "113435897598335750012134454342623244279140769314836288769122310705258616530095", "price": "0.64", "size": "20", "side": "BUY", "hash": "7453428b30b183a0ab925d7ed9ff446f74318b3e", "best_bid": "0.88", "best_ask": "0.94"}, {"asset_id": "43860483933578174366905172776039394809444972860267197366014959631913892252602", "price": "0.36", "size": "20", "side": "SELL", "hash": "929a4450ec72dba04050f501205b1eb66be8617e", "best_bid": "0.06", "best_ask": "0.12"}], "timestamp": "1769384552810", "event_type": "price_change"}}
{"_local_timestamp": "2026-01-25T23:42:37.733577+00:00", "data": {"market": "0xebd6b4d15beed0a4a3a274d6d1bc13e0b15d13a330586190932a3c4c7887b72f", "price_changes": [{"asset_id": "43860483933578174366905172776039394809444972860267197366014959631913892252602", "price": "0.13", "size": "43.67", "side": "SELL", "hash": "5f7a7588bf1b0c2fb10f9aa356bcc10530e1992c", "best_bid": "0.06", "best_ask": "0.12"}, {"asset_id": "113435897598335750012134454342623244279140769314836288769122310705258616530095", "price": "0.87", "size": "43.67", "side": "BUY", "hash": "cb9f19bad1995f44578fd4bdcd5c607e5c92171b", "best_bid": "0.88", "best_ask": "0.94"}], "timestamp": "1769384557618", "event_type": "price_change"}}
{"_local_timestamp": "2026-01-25T23:42:47.810240+00:00", "data": {"market": "0xebd6b4d15beed0a4a3a274d6d1bc13e0b15d13a330586190932a3c4c7887b72f", "price_changes": [{"asset_id": "43860483933578174366905172776039394809444972860267197366014959631913892252602", "price": "0.11", "size": "6.38", "side": "SELL", "hash": "29d34797eb2298bdbc2bc1372e9eedbf505d6d7f", "best_bid": "0.06", "best_ask": "0.11"}, {"asset_id": "113435897598335750012134454342623244279140769314836288769122310705258616530095", "price": "0.89", "size": "6.38", "side": "BUY", "hash": "d39d8810aee99f88ff6f9881a00368cc46c0cf0c", "best_bid": "0.89", "best_ask": "0.94"}], "timestamp": "1769384567700", "event_type": "price_change"}}
{"_local_timestamp": "2026-01-25T23:42:50.513850+00:00", "data": {"market": "0x715dc274a5c7adf3771646e36d5e3a8844163dc31e7f02331eb30d2b8108bf9e", "price_changes": [{"asset_id": "817582445527276447057755966542888616081641371741603398122454732956499627950", "price": "0.07", "size": "1185.71", "side": "BUY", "hash": "4d2e35e2f74bc19553d209ef0eed0dca54fbcd0a", "best_bid": "0.38", "best_ask": "0.42"}, {"asset_id": "19458454719947582257633203202425613630572016962838703318400930704175824104136", "price": "0.93", "size": "1185.71", "side": "SELL", "hash": "9d1f7e6462e97ee26e18e8bd14477410062c6135", "best_bid": "0.58", "best_ask": "0.62"}], "timestamp": "1769384570411", "event_type": "price_change"}}
{"_local_timestamp": "2026-01-25T23:42:50.538176+00:00", "data": {"market": "0x715dc274a5c7adf3771646e36d5e3a8844163dc31e7f02331eb30d2b8108bf9e", "price_changes": [{"asset_id": "817582445527276447057755966542888616081641371741603398122454732956499627950", "price": "0.19", "size": "206", "side": "BUY", "hash": "f1fb59af6dd582989b4ed99485027bbce194e111", "best_bid": "0.38", "best_ask": "0.42"}, {"asset_id": "19458454719947582257633203202425613630572016962838703318400930704175824104136", "price": "0.81", "size": "206", "side": "SELL", "hash": "9da883050cdd02cc62dedcbaeaaa36e2a4322b5b", "best_bid": "0.58", "best_ask": "0.62"}], "timestamp": "1769384570412", "event_type": "price_change"}}
{"_local_timestamp": "2026-01-25T23:42:51.174670+00:00", "data": {"market": "0x715dc274a5c7adf3771646e36d5e3a8844163dc31e7f02331eb30d2b8108bf9e", "price_changes": [{"asset_id": "19458454719947582257633203202425613630572016962838703318400930704175824104136", "price": "0.58", "size": "0", "side": "BUY", "hash": "380da44c661dcf6faa19aa1626ae476d2a78dad9", "best_bid": "0.57", "best_ask": "0.62"}, {"asset_id": "817582445527276447057755966542888616081641371741603398122454732956499627950", "price": "0.42", "size": "0", "side": "SELL", "hash": "b7b85b009966e8a9c01ca293358b68c1364113de", "best_bid": "0.38", "best_ask": "0.43"}], "timestamp": "1769384571069", "event_type": "price_change"}}
{"_local_timestamp": "2026-01-25T23:42:51.194514+00:00", "data": {"market": "0xd62d0fd81efeba80c7d331577b8cfdaf89eb287a64f65f6418677f5669da4374", "price_changes": [{"asset_id": "50806857340536377589471864244012059415352637140902118853666778383891415395995", "price": "0.71", "size": "0", "side": "BUY", "hash": "3663ac17e059eccf7e88e96ad3667f8741833cf8", "best_bid": "0.89", "best_ask": "0.93"}, {"asset_id": "44436347575766030163252235546454470356610478743001712085002709882075518933616", "price": "0.29", "size": "0", "side": "SELL", "hash": "13e97b61f4d4230bbba8f5d7eab5920973e3f91b", "best_bid": "0.07", "best_ask": "0.11"}], "timestamp": "1769384571100", "event_type": "price_change"}}
{"_local_timestamp": "2026-01-25T23:42:51.207689+00:00", "data": {"market": "0x715dc274a5c7adf3771646e36d5e3a8844163dc31e7f02331eb30d2b8108bf9e", "price_changes": [{"asset_id": "817582445527276447057755966542888616081641371741603398122454732956499627950", "price": "0.25", "size": "5", "side": "BUY", "hash": "1fef09451b60755234c8881cc7f24aff439b7912", "best_bid": "0.38", "best_ask": "0.43"}, {"asset_id": "19458454719947582257633203202425613630572016962838703318400930704175824104136", "price": "0.75", "size": "5", "side": "SELL", "hash": "df75be4fa209072ffe65ea97ac65d43dc82bfb24", "best_bid": "0.57", "best_ask": "0.62"}], "timestamp": "1769384571108", "event_type": "price_change"}}
{"_local_timestamp": "2026-01-25T23:42:51.219250+00:00", "data": {"market": "0x715dc274a5c7adf3771646e36d5e3a8844163dc31e7f02331eb30d2b8108bf9e", "price_changes": [{"asset_id": "19458454719947582257633203202425613630572016962838703318400930704175824104136", "price": "0.56", "size": "109.59", "side": "BUY", "hash": "77edb8dee9ed5fc29d7b3f2974ee6ee572948145", "best_bid": "0.57", "best_ask": "0.62"}, {"asset_id": "817582445527276447057755966542888616081641371741603398122454732956499627950", "price": "0.44", "size": "109.59", "side": "SELL", "hash": "44b7f4706ee12b780b2176df11bfb44051cc5782", "best_bid": "0.38", "best_ask": "0.43"}], "timestamp": "1769384571127", "event_type": "price_change"}}
{"_local_timestamp": "2026-01-25T23:42:51.223231+00:00", "data": {"market": "0x715dc274a5c7adf3771646e36d5e3a8844163dc31e7f02331eb30d2b8108bf9e", "price_changes": [{"asset_id": "19458454719947582257633203202425613630572016962838703318400930704175824104136", "price": "0.58", "size": "100", "side": "BUY", "hash": "3c95eaeba13527421d787527013b95f52f9bf541", "best_bid": "0.58", "best_ask": "0.62"}, {"asset_id": "817582445527276447057755966542888616081641371741603398122454732956499627950", "price": "0.42", "size": "100", "side": "SELL", "hash": "6e0d3cf86986544ba37535da361e7fa61ac20897", "best_bid": "0.38", "best_ask": "0.42"}], "timestamp": "1769384571128", "event_type": "price_change"}}
{"_local_timestamp": "2026-01-25T23:42:51.223665+00:00", "data": {"market": "0x715dc274a5c7adf3771646e36d5e3a8844163dc31e7f02331eb30d2b8108bf9e", "price_changes": [{"asset_id": "19458454719947582257633203202425613630572016962838703318400930704175824104136", "price": "0.57", "size": "116", "side": "BUY", "hash": "d35b748133e67ab4be10644b915c292314126828", "best_bid": "0.58", "best_ask": "0.62"}, {"asset_id": "817582445527276447057755966542888616081641371741603398122454732956499627950", "price": "0.43", "size": "116", "side": "SELL", "hash": "dd08a04b3191d46acd192dbeb281f5dab8b62c93", "best_bid": "0.38", "best_ask": "0.42"}], "timestamp": "1769384571128", "event_type": "price_change"}}
{"_local_timestamp": "2026-01-25T23:42:51.229476+00:00", "data": {"market": "0x29d688e8ee4dc83cff27ce5d583553be477b4202aba945dff96730aa88397071", "price_changes": [{"asset_id": "22395241560984864794587761975509529149656370897276070318169938852205137917866", "price": "0.53", "size": "0", "side": "BUY", "hash": "cbd15d073665b61b3aaf76ce8f43388462f9201c", "best_bid": "0.8", "best_ask": "0.95"}, {"asset_id": "46123672832602976783793170370598938766981479048132054420648285300054482204701", "price": "0.47", "size": "0", "side": "SELL", "hash": "186cc8bb24b55c358ae74b777707f9927ea6b4d6", "best_bid": "0.05", "best_ask": "0.2"}], "timestamp": "1769384571129", "event_type": "price_change"}}
{"_local_timestamp": "2026-01-25T23:42:51.230457+00:00", "data": {"market": "0xebd6b4d15beed0a4a3a274d6d1bc13e0b15d13a330586190932a3c4c7887b72f", "price_changes": [{"asset_id": "113435897598335750012134454342623244279140769314836288769122310705258616530095", "price": "0.61", "size": "0", "side": "BUY", "hash": "293da60952d78ee46920d70b5b2678b763a00740", "best_bid": "0.89", "best_ask": "0.94"}, {"asset_id": "43860483933578174366905172776039394809444972860267197366014959631913892252602", "price": "0.39", "size": "0", "side": "SELL", "hash": "3343ff64188536c9b95764a24caacabb15843be0", "best_bid": "0.06", "best_ask": "0.11"}], "timestamp": "1769384571129", "event_type": "price_change"}}
{"_local_timestamp": "2026-01-25T23:42:51.254066+00:00", "data": {"market": "0xfb08a969a2c05beda8b5743959182db28be71832f9a84872a786e809b77b5350", "price_changes": [{"asset_id": "13908252531396871469657521961663517650827376216919668668811621820614371209132", "price": "0.64", "size": "0", "side": "BUY", "hash": "672a3432cc674d5217d07eeb01aaf0358369a255", "best_bid": "0.842", "best_ask": "0.974"}, {"asset_id": "28670530274590253141384619337562139640467932392972183997943459931027267172276", "price": "0.36", "size": "0", "side": "SELL", "hash": "5931a2f2c005d0b2569e8263733d63a50bf830b7", "best_bid": "0.026", "best_ask": "0.158"}], "timestamp": "1769384571129", "event_type": "price_change"}}
{"_local_timestamp": "2026-01-25T23:42:51.270945+00:00", "data": {"market": "0xd62d0fd81efeba80c7d331577b8cfdaf89eb287a64f65f6418677f5669da4374", "price_changes": [{"asset_id": "50806857340536377589471864244012059415352637140902118853666778383891415395995", "price": "0.52", "size": "0", "side": "BUY", "hash": "a77c0808878ae4f4e0d015855eecb5bccd417dc8", "best_bid": "0.89", "best_ask": "0.93"}, {"asset_id": "44436347575766030163252235546454470356610478743001712085002709882075518933616", "price": "0.48", "size": "0", "side": "SELL", "hash": "ccc5e1957959cd73fd1b8c581bd765c352dac6e1", "best_bid": "0.07", "best_ask": "0.11"}], "timestamp": "1769384571129", "event_type": "price_change"}}
{"_local_timestamp": "2026-01-25T23:42:51.340037+00:00", "data": {"market": "0xfb08a969a2c05beda8b5743959182db28be71832f9a84872a786e809b77b5350", "price_changes": [{"asset_id": "13908252531396871469657521961663517650827376216919668668811621820614371209132", "price": "0.538", "size": "0", "side": "BUY", "hash": "672a3432cc674d5217d07eeb01aaf0358369a255", "best_bid": "0.842", "best_ask": "0.974"}, {"asset_id": "28670530274590253141384619337562139640467932392972183997943459931027267172276", "price": "0.462", "size": "0", "side": "SELL", "hash": "5931a2f2c005d0b2569e8263733d63a50bf830b7", "best_bid": "0.026", "best_ask": "0.158"}], "timestamp": "1769384571129", "event_type": "price_change"}}
{"_local_timestamp": "2026-01-25T23:42:51.340453+00:00", "data": {"market": "0x715dc274a5c7adf3771646e36d5e3a8844163dc31e7f02331eb30d2b8108bf9e", "price_changes": [{"asset_id": "817582445527276447057755966542888616081641371741603398122454732956499627950", "price": "0.39", "size": "205", "side": "BUY", "hash": "f557b3d78c853d022bea1c50b996a1016cc75e73", "best_bid": "0.39", "best_ask": "0.42"}, {"asset_id": "19458454719947582257633203202425613630572016962838703318400930704175824104136", "price": "0.61", "size": "205", "side": "SELL", "hash": "0cf975fdeb44549f53ea480428bcff1aa46976c5", "best_bid": "0.58", "best_ask": "0.61"}], "timestamp": "1769384571138", "event_type": "price_change"}}
{"_local_timestamp": "2026-01-25T23:42:51.340801+00:00", "data": {"market": "0xd62d0fd81efeba80c7d331577b8cfdaf89eb287a64f65f6418677f5669da4374", "price_changes": [{"asset_id": "50806857340536377589471864244012059415352637140902118853666778383891415395995", "price": "0.71", "size": "20", "side": "BUY", "hash": "a99ba869668ae8d5b25ecc23547522e18884b01a", "best_bid": "0.89", "best_ask": "0.93"}, {"asset_id": "44436347575766030163252235546454470356610478743001712085002709882075518933616", "price": "0.29", "size": "20", "side": "SELL", "hash": "2a6ecdfe686bde76717471af3527bb0ba10942ff", "best_bid": "0.07", "best_ask": "0.11"}], "timestamp": "1769384571155", "event_type": "price_change"}}
{"_local_timestamp": "2026-01-25T23:42:51.341174+00:00", "data": {"market": "0xfb08a969a2c05beda8b5743959182db28be71832f9a84872a786e809b77b5350", "price_changes": [{"asset_id": "13908252531396871469657521961663517650827376216919668668811621820614371209132", "price": "0.632", "size": "0", "side": "BUY", "hash": "411481bef5a742ad22e11ea287adcf5df2a8ad3c", "best_bid": "0.842", "best_ask": "0.974"}, {"asset_id": "28670530274590253141384619337562139640467932392972183997943459931027267172276", "price": "0.368", "size": "0", "side": "SELL", "hash": "5d8ad9b90fc222e60092e59c52d7c45236ec4319", "best_bid": "0.026", "best_ask": "0.158"}], "timestamp": "1769384571156", "event_type": "price_change"}}
{"_local_timestamp": "2026-01-25T23:42:51.375985+00:00", "data": {"market": "0xebd6b4d15beed0a4a3a274d6d1bc13e0b15d13a330586190932a3c4c7887b72f", "price_changes": [{"asset_id": "113435897598335750012134454342623244279140769314836288769122310705258616530095", "price": "0.41", "size": "0", "side": "BUY", "hash": "114e806992430873b84dca86541c9fee08608c15", "best_bid": "0.89", "best_ask": "0.94"}, {"asset_id": "43860483933578174366905172776039394809444972860267197366014959631913892252602", "price": "0.59", "size": "0", "side": "SELL", "hash": "a4e79f88dfd8afc0503d3ed2e7caf3ca1bce4f22", "best_bid": "0.06", "best_ask": "0.11"}], "timestamp": "1769384571157", "event_type": "price_change"}}
{"_local_timestamp": "2026-01-25T23:42:51.377324+00:00", "data": {"market": "0xebd6b4d15beed0a4a3a274d6d1bc13e0b15d13a330586190932a3c4c7887b72f", "price_changes": [{"asset_id": "113435897598335750012134454342623244279140769314836288769122310705258616530095", "price": "0.58", "size": "0", "side": "BUY", "hash": "c5081719e5dd40598473d6c5417d9a937807b7f2", "best_bid": "0.89", "best_ask": "0.94"}, {"asset_id": "43860483933578174366905172776039394809444972860267197366014959631913892252602", "price": "0.42", "size": "0", "side": "SELL", "hash": "f3e7acf8284a938c7c176237c0f624bec3c3117c", "best_bid": "0.06", "best_ask": "0.11"}], "timestamp": "1769384571164", "event_type": "price_change"}}
{"_local_timestamp": "2026-01-25T23:42:51.377601+00:00", "data": {"market": "0xebd6b4d15beed0a4a3a274d6d1bc13e0b15d13a330586190932a3c4c7887b72f", "price_changes": [{"asset_id": "113435897598335750012134454342623244279140769314836288769122310705258616530095", "price": "0.13", "size": "325", "side": "BUY", "hash": "349d73b83cb4ceba6b781af685b2e64b7b016da8", "best_bid": "0.89", "best_ask": "0.94"}, {"asset_id": "43860483933578174366905172776039394809444972860267197366014959631913892252602", "price": "0.87", "size": "325", "side": "SELL", "hash": "a2bf663395569eeb393c8599418e32a34b74e539", "best_bid": "0.06", "best_ask": "0.11"}], "timestamp": "1769384571168", "event_type": "price_change"}}
{"_local_timestamp": "2026-01-25T23:42:51.377841+00:00", "data": {"market": "0x29d688e8ee4dc83cff27ce5d583553be477b4202aba945dff96730aa88397071", "price_changes": [{"asset_id": "22395241560984864794587761975509529149656370897276070318169938852205137917866", "price": "0.55", "size": "10", "side": "BUY", "hash": "d06a960af292d094fe10e1eb0e7cd948bd7c0239", "best_bid": "0.8", "best_ask": "0.95"}, {"asset_id": "46123672832602976783793170370598938766981479048132054420648285300054482204701", "price": "0.45", "size": "10", "side": "SELL", "hash": "3f3888a7403af2bd72c418d8be2f7fb16464ecfa", "best_bid": "0.05", "best_ask": "0.2"}], "timestamp": "1769384571268", "event_type": "price_change"}}
{"_local_timestamp": "2026-01-25T23:42:51.378078+00:00", "data": {"market": "0xebd6b4d15beed0a4a3a274d6d1bc13e0b15d13a330586190932a3c4c7887b72f", "price_changes": [{"asset_id": "113435897598335750012134454342623244279140769314836288769122310705258616530095", "price": "0.42", "size": "15", "side": "BUY", "hash": "9852c725aae1634ab88d213c8dfc06a820d1f05c", "best_bid": "0.89", "best_ask": "0.94"}, {"asset_id": "43860483933578174366905172776039394809444972860267197366014959631913892252602", "price": "0.58", "size": "15", "side": "SELL", "hash": "83612306823029ae0e97a8541bd66091cc36f517", "best_bid": "0.06", "best_ask": "0.11"}], "timestamp": "1769384571268", "event_type": "price_change"}}
{"_local_timestamp": "2026-01-25T23:42:51.378309+00:00", "data": {"market": "0xfb08a969a2c05beda8b5743959182db28be71832f9a84872a786e809b77b5350", "price_changes": [{"asset_id": "13908252531396871469657521961663517650827376216919668668811621820614371209132", "price": "0.538", "size": "15", "side": "BUY", "hash": "9043afff1eebc126e2244fb43df2318b40c9f35c", "best_bid": "0.842", "best_ask": "0.974"}, {"asset_id": "28670530274590253141384619337562139640467932392972183997943459931027267172276", "price": "0.462", "size": "15", "side": "SELL", "hash": "280728da1cf53020fba6b1f0c6b95e362742e7df", "best_bid": "0.026", "best_ask": "0.158"}], "timestamp": "1769384571268", "event_type": "price_change"}}
{"_local_timestamp": "2026-01-25T23:42:51.407584+00:00", "data": {"market": "0xd62d0fd81efeba80c7d331577b8cfdaf89eb287a64f65f6418677f5669da4374", "price_changes": [{"asset_id": "50806857340536377589471864244012059415352637140902118853666778383891415395995", "price": "0.54", "size": "15", "side": "BUY", "hash": "a90dd6e740f1111fc48c41f8fe159522f6051c1b", "best_bid": "0.89", "best_ask": "0.93"}, {"asset_id": "44436347575766030163252235546454470356610478743001712085002709882075518933616", "price": "0.46", "size": "15", "side": "SELL", "hash": "7167408a73d40a5cd601a87e790a7eff0d32a764", "best_bid": "0.07", "best_ask": "0.11"}], "timestamp": "1769384571268", "event_type": "price_change"}}
{"_local_timestamp": "2026-01-25T23:42:51.407954+00:00", "data": {"market": "0xebd6b4d15beed0a4a3a274d6d1bc13e0b15d13a330586190932a3c4c7887b72f", "price_changes": [{"asset_id": "113435897598335750012134454342623244279140769314836288769122310705258616530095", "price": "0.61", "size": "10", "side": "BUY", "hash": "24913f4ab6917e8f4ce0b3f1d96e0aa4a93a1a22", "best_bid": "0.89", "best_ask": "0.94"}, {"asset_id": "43860483933578174366905172776039394809444972860267197366014959631913892252602", "price": "0.39", "size": "10", "side": "SELL", "hash": "256dbd6041d5c7dfcf4f56b92c780c2dbea12557", "best_bid": "0.06", "best_ask": "0.11"}], "timestamp": "1769384571269", "event_type": "price_change"}}
{"_local_timestamp": "2026-01-25T23:42:51.416405+00:00", "data": {"market": "0x29d688e8ee4dc83cff27ce5d583553be477b4202aba945dff96730aa88397071", "price_changes": [{"asset_id": "22395241560984864794587761975509529149656370897276070318169938852205137917866", "price": "0.55", "size": "25", "side": "BUY", "hash": "3a9acc8d0cfedc7577a6055ab578ded0eed56c0c", "best_bid": "0.8", "best_ask": "0.95"}, {"asset_id": "46123672832602976783793170370598938766981479048132054420648285300054482204701", "price": "0.45", "size": "25", "side": "SELL", "hash": "0fd0a093d739fad049d73d04f188ca42fc1f4a71", "best_bid": "0.05", "best_ask": "0.2"}], "timestamp": "1769384571268", "event_type": "price_change"}}
{"_local_timestamp": "2026-01-25T23:42:51.416658+00:00", "data": {"market": "0xfb08a969a2c05beda8b5743959182db28be71832f9a84872a786e809b77b5350", "price_changes": [{"asset_id": "13908252531396871469657521961663517650827376216919668668811621820614371209132", "price": "0.642", "size": "10", "side": "BUY", "hash": "bd6f1e7c049bfd325d3e278f3f35a49a2e3c0e31", "best_bid": "0.842", "best_ask": "0.974"}, {"asset_id": "28670530274590253141384619337562139640467932392972183997943459931027267172276", "price": "0.358", "size": "10", "side": "SELL", "hash": "b2bc5826b306d53a792438d742aea0d8740e0e4b", "best_bid": "0.026", "best_ask": "0.158"}], "timestamp": "1769384571269", "event_type": "price_change"}}
{"_local_timestamp": "2026-01-25T23:42:51.417083+00:00", "data": {"market": "0xd62d0fd81efeba80c7d331577b8cfdaf89eb287a64f65f6418677f5669da4374", "price_changes": [{"asset_id": "50806857340536377589471864244012059415352637140902118853666778383891415395995", "price": "0.54", "size": "25", "side": "BUY", "hash": "90cecb10e15728a46a014438dca10dc26ce0754b", "best_bid": "0.89", "best_ask": "0.93"}, {"asset_id": "44436347575766030163252235546454470356610478743001712085002709882075518933616", "price": "0.46", "size": "25", "side": "SELL", "hash": "66231d16df647005bc512164043368228827673c", "best_bid": "0.07", "best_ask": "0.11"}], "timestamp": "1769384571269", "event_type": "price_change"}}
{"_local_timestamp": "2026-01-25T23:42:51.417353+00:00", "data": {"market": "0xebd6b4d15beed0a4a3a274d6d1bc13e0b15d13a330586190932a3c4c7887b72f", "price_changes": [{"asset_id": "113435897598335750012134454342623244279140769314836288769122310705258616530095", "price": "0.41", "size": "10", "side": "BUY", "hash": "7bb768d5e9e558d9645d58ef3b001dad93b41dd5", "best_bid": "0.89", "best_ask": "0.94"}, {"asset_id": "43860483933578174366905172776039394809444972860267197366014959631913892252602", "price": "0.59", "size": "10", "side": "SELL", "hash": "672e4e39221963bbe2d4fddcadc7ef8c36ad95c8", "best_bid": "0.06", "best_ask": "0.11"}], "timestamp": "1769384571275", "event_type": "price_change"}}
{"_local_timestamp": "2026-01-25T23:42:51.417622+00:00", "data": {"market": "0xfb08a969a2c05beda8b5743959182db28be71832f9a84872a786e809b77b5350", "price_changes": [{"asset_id": "13908252531396871469657521961663517650827376216919668668811621820614371209132", "price": "0.642", "size": "20", "side": "BUY", "hash": "5d3afa1f30930bfa0d2eab2ee32ca993eefa3217", "best_bid": "0.842", "best_ask": "0.974"}, {"asset_id": "28670530274590253141384619337562139640467932392972183997943459931027267172276", "price": "0.358", "size": "20", "side": "SELL", "hash": "b78441888c2ed7b660114ebb60103c62a8b9ecb3", "best_bid": "0.026", "best_ask": "0.158"}], "timestamp": "1769384571275", "event_type": "price_change"}}
{"_local_timestamp": "2026-01-25T23:42:51.437966+00:00", "data": {"market": "0xebd6b4d15beed0a4a3a274d6d1bc13e0b15d13a330586190932a3c4c7887b72f", "price_changes": [{"asset_id": "113435897598335750012134454342623244279140769314836288769122310705258616530095", "price": "0.64", "size": "45", "side": "BUY", "hash": "5a375fcd1b186dce546c94e89dd513e76939d8de", "best_bid": "0.89", "best_ask": "0.94"}, {"asset_id": "43860483933578174366905172776039394809444972860267197366014959631913892252602", "price": "0.36", "size": "45", "side": "SELL", "hash": "4401e5562bab9e6d5d2ab72735e13d27b7f59491", "best_bid": "0.06", "best_ask": "0.11"}], "timestamp": "1769384571341", "event_type": "price_change"}}
{"_local_timestamp": "2026-01-25T23:42:51.745864+00:00", "data": {"market": "0x715dc274a5c7adf3771646e36d5e3a8844163dc31e7f02331eb30d2b8108bf9e", "price_changes": [{"asset_id": "817582445527276447057755966542888616081641371741603398122454732956499627950", "price": "0.07", "size": "485.71", "side": "BUY", "hash": "c2bc4c15611131bc756ace3afb20ec4642064b34", "best_bid": "0.39", "best_ask": "0.42"}, {"asset_id": "19458454719947582257633203202425613630572016962838703318400930704175824104136", "price": "0.93", "size": "485.71", "side": "SELL", "hash": "275ffd30f0f3b320e7add27da056a415ae8797a8", "best_bid": "0.58", "best_ask": "0.61"}], "timestamp": "1769384571648", "event_type": "price_change"}}
{"_local_timestamp": "2026-01-25T23:42:51.746607+00:00", "data": {"market": "0x715dc274a5c7adf3771646e36d5e3a8844163dc31e7f02331eb30d2b8108bf9e", "price_changes": [{"asset_id": "817582445527276447057755966542888616081641371741603398122454732956499627950", "price": "0.19", "size": "56", "side": "BUY", "hash": "c2bc4c15611131bc756ace3afb20ec4642064b34", "best_bid": "0.39", "best_ask": "0.42"}, {"asset_id": "19458454719947582257633203202425613630572016962838703318400930704175824104136", "price": "0.81", "size": "56", "side": "SELL", "hash": "275ffd30f0f3b320e7add27da056a415ae8797a8", "best_bid": "0.58", "best_ask": "0.61"}], "timestamp": "1769384571648", "event_type": "price_change"}}
{"_local_timestamp": "2026-01-25T23:42:52.441562+00:00", "data": {"market": "0x715dc274a5c7adf3771646e36d5e3a8844163dc31e7f02331eb30d2b8108bf9e", "price_changes": [{"asset_id": "817582445527276447057755966542888616081641371741603398122454732956499627950", "price": "0.39", "size": "0", "side": "BUY", "hash": "88fb7f11e875370db97e9541041a84f18ae3eab1", "best_bid": "0.38", "best_ask": "0.42"}, {"asset_id": "19458454719947582257633203202425613630572016962838703318400930704175824104136", "price": "0.61", "size": "0", "side": "SELL", "hash": "fd91c1813497c9f617fd46da5dede1cfec1e87fb", "best_bid": "0.58", "best_ask": "0.62"}], "timestamp": "1769384572340", "event_type": "price_change"}}
{"_local_timestamp": "2026-01-25T23:42:52.478906+00:00", "data": {"market": "0x715dc274a5c7adf3771646e36d5e3a8844163dc31e7f02331eb30d2b8108bf9e", "price_changes": [{"asset_id": "817582445527276447057755966542888616081641371741603398122454732956499627950", "price": "0.25", "size": "193", "side": "BUY", "hash": "5119a374567d58341012f275647f040b738b4416", "best_bid": "0.38", "best_ask": "0.42"}, {"asset_id": "19458454719947582257633203202425613630572016962838703318400930704175824104136", "price": "0.75", "size": "193", "side": "SELL", "hash": "cf61180f784c0144dec01fb8ed5c2f4a89d9b475", "best_bid": "0.58", "best_ask": "0.62"}], "timestamp": "1769384572373", "event_type": "price_change"}}
{"_local_timestamp": "2026-01-25T23:42:54.182319+00:00", "data": {"market": "0x29d688e8ee4dc83cff27ce5d583553be477b4202aba945dff96730aa88397071", "price_changes": [{"asset_id": "22395241560984864794587761975509529149656370897276070318169938852205137917866", "price": "0.54", "size": "0", "side": "BUY", "hash": "8e0be37753a4fe63d35a1bb2a9c04c5174aebf95", "best_bid": "0.8", "best_ask": "0.95"}, {"asset_id": "46123672832602976783793170370598938766981479048132054420648285300054482204701", "price": "0.46", "size": "0", "side": "SELL", "hash": "39715c96a16ccc2cb3e8aae5ebf62daecea060d1", "best_bid": "0.05", "best_ask": "0.2"}], "timestamp": "1769384574091", "event_type": "price_change"}}
{"_local_timestamp": "2026-01-25T23:42:54.182689+00:00", "data": {"market": "0xd62d0fd81efeba80c7d331577b8cfdaf89eb287a64f65f6418677f5669da4374", "price_changes": [{"asset_id": "50806857340536377589471864244012059415352637140902118853666778383891415395995", "price": "0.53", "size": "0", "side": "BUY", "hash": "9dd2bdff36ba93d025561edf5a0e0753e7e9ebec", "best_bid": "0.89", "best_ask": "0.93"}, {"asset_id": "44436347575766030163252235546454470356610478743001712085002709882075518933616", "price": "0.47", "size": "0", "side": "SELL", "hash": "c036818c687ddfbdcb716d838a94556a4fc10ffd", "best_bid": "0.07", "best_ask": "0.11"}], "timestamp": "1769384574091", "event_type": "price_change"}}
{"_local_timestamp": "2026-01-25T23:42:54.186257+00:00", "data": {"market": "0xebd6b4d15beed0a4a3a274d6d1bc13e0b15d13a330586190932a3c4c7887b72f", "price_changes": [{"asset_id": "113435897598335750012134454342623244279140769314836288769122310705258616530095", "price": "0.64", "size": "25", "side": "BUY", "hash": "d62ab8a1216abf848845980fc18b9343f350f71d", "best_bid": "0.89", "best_ask": "0.94"}, {"asset_id": "43860483933578174366905172776039394809444972860267197366014959631913892252602", "price": "0.36", "size": "25", "side": "SELL", "hash": "959c14ded703d2ed400a0b8ae89c454f054dde08", "best_bid": "0.06", "best_ask": "0.11"}], "timestamp": "1769384574091", "event_type": "price_change"}}
{"_local_timestamp": "2026-01-25T23:42:54.186590+00:00", "data": {"market": "0xfb08a969a2c05beda8b5743959182db28be71832f9a84872a786e809b77b5350", "price_changes": [{"asset_id": "13908252531396871469657521961663517650827376216919668668811621820614371209132", "price": "0.641", "size": "0", "side": "BUY", "hash": "b0fefe30f680d0d5e581998baa537463140a9e07", "best_bid": "0.842", "best_ask": "0.974"}, {"asset_id": "28670530274590253141384619337562139640467932392972183997943459931027267172276", "price": "0.359", "size": "0", "side": "SELL", "hash": "6d8236a3f49afd9586cc8741eb2db8e04c2a56a8", "best_bid": "0.026", "best_ask": "0.158"}], "timestamp": "1769384574091", "event_type": "price_change"}}
{"_local_timestamp": "2026-01-25T23:42:54.223878+00:00", "data": {"market": "0xd62d0fd81efeba80c7d331577b8cfdaf89eb287a64f65f6418677f5669da4374", "price_changes": [{"asset_id": "50806857340536377589471864244012059415352637140902118853666778383891415395995", "price": "0.55", "size": "20", "side": "BUY", "hash": "fdaac8c1296e7fbe19174f21c18edc733ea7ce21", "best_bid": "0.89", "best_ask": "0.93"}, {"asset_id": "44436347575766030163252235546454470356610478743001712085002709882075518933616", "price": "0.45", "size": "20", "side": "SELL", "hash": "6f9cf27983dce80a6028c0702b5db809dc8df86c", "best_bid": "0.07", "best_ask": "0.11"}], "timestamp": "1769384574120", "event_type": "price_change"}}
{"_local_timestamp": "2026-01-25T23:42:54.224190+00:00", "data": {"market": "0xfb08a969a2c05beda8b5743959182db28be71832f9a84872a786e809b77b5350", "price_changes": [{"asset_id": "13908252531396871469657521961663517650827376216919668668811621820614371209132", "price": "0.643", "size": "20", "side": "BUY", "hash": "50974ddea0106a4155c05f1b6d2c74c71bb714bb", "best_bid": "0.842", "best_ask": "0.974"}, {"asset_id": "28670530274590253141384619337562139640467932392972183997943459931027267172276", "price": "0.357", "size": "20", "side": "SELL", "hash": "928d054a1ba45d66b40e60c408286d4e1db7ed33", "best_bid": "0.026", "best_ask": "0.158"}], "timestamp": "1769384574119", "event_type": "price_change"}}
{"_local_timestamp": "2026-01-25T23:42:54.224485+00:00", "data": {"market": "0x29d688e8ee4dc83cff27ce5d583553be477b4202aba945dff96730aa88397071", "price_changes": [{"asset_id": "22395241560984864794587761975509529149656370897276070318169938852205137917866", "price": "0.56", "size": "20", "side": "BUY", "hash": "17274d14f87b3e17e3ddffad590185ec30ae9351", "best_bid": "0.8", "best_ask": "0.95"}, {"asset_id": "46123672832602976783793170370598938766981479048132054420648285300054482204701", "price": "0.44", "size": "20", "side": "SELL", "hash": "569c591703753bb4416d88fd6f2f32bc729cf58b", "best_bid": "0.05", "best_ask": "0.2"}], "timestamp": "1769384574120", "event_type": "price_change"}}
{"_local_timestamp": "2026-01-25T23:42:54.224775+00:00", "data": {"market": "0xebd6b4d15beed0a4a3a274d6d1bc13e0b15d13a330586190932a3c4c7887b72f", "price_changes": [{"asset_id": "113435897598335750012134454342623244279140769314836288769122310705258616530095", "price": "0.65", "size": "20", "side": "BUY", "hash": "51ab86e96f4bacf772c1968e3d75df57feb71f7b", "best_bid": "0.89", "best_ask": "0.94"}, {"asset_id": "43860483933578174366905172776039394809444972860267197366014959631913892252602", "price": "0.35", "size": "20", "side": "SELL", "hash": "55961fe1c986ab3e2f51d8bb9c55f94101a25365", "best_bid": "0.06", "best_ask": "0.11"}], "timestamp": "1769384574120", "event_type": "price_change"}}
{"_local_timestamp": "2026-01-25T23:43:04.900553+00:00", "data": {"market": "0xfb08a969a2c05beda8b5743959182db28be71832f9a84872a786e809b77b5350", "price_changes": [{"asset_id": "13908252531396871469657521961663517650827376216919668668811621820614371209132", "price": "0.84", "size": "50", "side": "BUY", "hash": "3ba983a347a025df7978df9130b3573c0532fd00", "best_bid": "0.842", "best_ask": "0.974"}, {"asset_id": "28670530274590253141384619337562139640467932392972183997943459931027267172276", "price": "0.16", "size": "50", "side": "SELL", "hash": "ad1190de3cc71226432fdf0b155f628deb275b36", "best_bid": "0.026", "best_ask": "0.158"}], "timestamp": "1769384584802", "event_type": "price_change"}}
{"_local_timestamp": "2026-01-25T23:43:25.042234+00:00", "data": {"market": "0x715dc274a5c7adf3771646e36d5e3a8844163dc31e7f02331eb30d2b8108bf9e", "price_changes": [{"asset_id": "19458454719947582257633203202425613630572016962838703318400930704175824104136", "price": "0.56", "size": "9.59", "side": "BUY", "hash": "c4f353948395ad50552c3e3b22ee82d1485eb452", "best_bid": "0.58", "best_ask": "0.62"}, {"asset_id": "817582445527276447057755966542888616081641371741603398122454732956499627950", "price": "0.44", "size": "9.59", "side": "SELL", "hash": "44eae0e3149e23c78317fe13062b176e3f5087d5", "best_bid": "0.38", "best_ask": "0.42"}], "timestamp": "1769384604906", "event_type": "price_change"}}
{"_local_timestamp": "2026-01-25T23:43:25.474907+00:00", "data": {"market": "0xebd6b4d15beed0a4a3a274d6d1bc13e0b15d13a330586190932a3c4c7887b72f", "price_changes": [{"asset_id": "113435897598335750012134454342623244279140769314836288769122310705258616530095", "price": "0.41", "size": "0", "side": "BUY", "hash": "46fa1ebdd35cd74903f7352eb0b78ee08b322861", "best_bid": "0.89", "best_ask": "0.94"}, {"asset_id": "43860483933578174366905172776039394809444972860267197366014959631913892252602", "price": "0.59", "size": "0", "side": "SELL", "hash": "29756c0aae7eaca21e6ca907ac1de47b68c818db", "best_bid": "0.06", "best_ask": "0.11"}], "timestamp": "1769384605340", "event_type": "price_change"}}
{"_local_timestamp": "2026-01-25T23:43:25.500402+00:00", "data": {"market": "0xebd6b4d15beed0a4a3a274d6d1bc13e0b15d13a330586190932a3c4c7887b72f", "price_changes": [{"asset_id": "113435897598335750012134454342623244279140769314836288769122310705258616530095", "price": "0.34", "size": "10", "side": "BUY", "hash": "81c89e6c777bbf7df5f9db4648b2c82b9007ab67", "best_bid": "0.89", "best_ask": "0.94"}, {"asset_id": "43860483933578174366905172776039394809444972860267197366014959631913892252602", "price": "0.66", "size": "10", "side": "SELL", "hash": "c9babfb3d89e3f57d548b6ea577b1ff09b79ebd2", "best_bid": "0.06", "best_ask": "0.11"}], "timestamp": "1769384605370", "event_type": "price_change"}}
{"_local_timestamp": "2026-01-25T23:43:28.670252+00:00", "data": {"market": "0x715dc274a5c7adf3771646e36d5e3a8844163dc31e7f02331eb30d2b8108bf9e", "price_changes": [{"asset_id": "817582445527276447057755966542888616081641371741603398122454732956499627950", "price": "0.27", "size": "150", "side": "BUY", "hash": "25caeab4b4373a7ecfdffc4b66bc5c0a5b6d332d", "best_bid": "0.38", "best_ask": "0.42"}, {"asset_id": "19458454719947582257633203202425613630572016962838703318400930704175824104136", "price": "0.73", "size": "150", "side": "SELL", "hash": "48bf7503260398bbe87ec0ec2d9eff1d15101bfc", "best_bid": "0.58", "best_ask": "0.62"}], "timestamp": "1769384608535", "event_type": "price_change"}}
{"_local_timestamp": "2026-01-25T23:43:28.670686+00:00", "data": {"market": "0x715dc274a5c7adf3771646e36d5e3a8844163dc31e7f02331eb30d2b8108bf9e", "price_changes": [{"asset_id": "817582445527276447057755966542888616081641371741603398122454732956499627950", "price": "0.07", "size": "1185.71", "side": "BUY", "hash": "d4c9a668d7febe8dfcadb0a873adf672f06c0afd", "best_bid": "0.38", "best_ask": "0.42"}, {"asset_id": "19458454719947582257633203202425613630572016962838703318400930704175824104136", "price": "0.93", "size": "1185.71", "side": "SELL", "hash": "01821284a5a9f3b789453ba80279cbc842b3a275", "best_bid": "0.58", "best_ask": "0.62"}], "timestamp": "1769384608536", "event_type": "price_change"}}
{"_local_timestamp": "2026-01-25T23:43:28.693887+00:00", "data": {"market": "0x715dc274a5c7adf3771646e36d5e3a8844163dc31e7f02331eb30d2b8108bf9e", "price_changes": [{"asset_id": "817582445527276447057755966542888616081641371741603398122454732956499627950", "price": "0.25", "size": "5", "side": "BUY", "hash": "2ac14e2f06c602fdc9a63475373ca592f06ad500", "best_bid": "0.38", "best_ask": "0.42"}, {"asset_id": "19458454719947582257633203202425613630572016962838703318400930704175824104136", "price": "0.75", "size": "5", "side": "SELL", "hash": "6012f34c9af4ea764f644e02855f8195bf27bca0", "best_bid": "0.58", "best_ask": "0.62"}], "timestamp": "1769384608560", "event_type": "price_change"}}
{"_local_timestamp": "2026-01-25T23:43:28.715566+00:00", "data": {"market": "0x715dc274a5c7adf3771646e36d5e3a8844163dc31e7f02331eb30d2b8108bf9e", "price_changes": [{"asset_id": "817582445527276447057755966542888616081641371741603398122454732956499627950", "price": "0.28", "size": "146", "side": "BUY", "hash": "7a577ebaea33701c40ab1ea74b449f1a8a4cde3c", "best_bid": "0.38", "best_ask": "0.42"}, {"asset_id": "19458454719947582257633203202425613630572016962838703318400930704175824104136", "price": "0.72", "size": "146", "side": "SELL", "hash": "ed5150475bb5dd23d127f51a7ebc126e75297abe", "best_bid": "0.58", "best_ask": "0.62"}], "timestamp": "1769384608587", "event_type": "price_change"}}
{"_local_timestamp": "2026-01-25T23:43:29.965770+00:00", "data": {"market": "0x715dc274a5c7adf3771646e36d5e3a8844163dc31e7f02331eb30d2b8108bf9e", "price_changes": [{"asset_id": "817582445527276447057755966542888616081641371741603398122454732956499627950", "price": "0.29", "size": "30", "side": "BUY", "hash": "44d978aae0a0fb548f4648d9b76b95e4a833b5e7", "best_bid": "0.38", "best_ask": "0.42"}, {"asset_id": "19458454719947582257633203202425613630572016962838703318400930704175824104136", "price": "0.71", "size": "30", "side": "SELL", "hash": "1457f6b860e615dc9f7a7691c4906035423ca5ed", "best_bid": "0.58", "best_ask": "0.62"}], "timestamp": "1769384609830", "event_type": "price_change"}}
{"_local_timestamp": "2026-01-25T23:43:30.235358+00:00", "data": {"market": "0x715dc274a5c7adf3771646e36d5e3a8844163dc31e7f02331eb30d2b8108bf9e", "price_changes": [{"asset_id": "817582445527276447057755966542888616081641371741603398122454732956499627950", "price": "0.19", "size": "26", "side": "BUY", "hash": "37074177b0ccca907cc045a6cc33c78d1a8fa1b1", "best_bid": "0.38", "best_ask": "0.42"}, {"asset_id": "19458454719947582257633203202425613630572016962838703318400930704175824104136", "price": "0.81", "size": "26", "side": "SELL", "hash": "cd141775d4ba62605eb8f8ad539b17204c4084db", "best_bid": "0.58", "best_ask": "0.62"}], "timestamp": "1769384610085", "event_type": "price_change"}}
{"_local_timestamp": "2026-01-25T23:43:45.604321+00:00", "data": {"market": "0xebd6b4d15beed0a4a3a274d6d1bc13e0b15d13a330586190932a3c4c7887b72f", "price_changes": [{"asset_id": "113435897598335750012134454342623244279140769314836288769122310705258616530095", "price": "0.87", "size": "0", "side": "BUY", "hash": "f7eb75b8f161a031cc283fa7fbab4ff0080efa0d", "best_bid": "0.89", "best_ask": "0.94"}, {"asset_id": "43860483933578174366905172776039394809444972860267197366014959631913892252602", "price": "0.13", "size": "0", "side": "SELL", "hash": "4eb3f61e8c472b3fb521c2e7b6db48977a2cfb17", "best_bid": "0.06", "best_ask": "0.11"}], "timestamp": "1769384625474", "event_type": "price_change"}}
{"_local_timestamp": "2026-01-25T23:43:53.210510+00:00", "data": {"market": "0x715dc274a5c7adf3771646e36d5e3a8844163dc31e7f02331eb30d2b8108bf9e", "price_changes": [{"asset_id": "19458454719947582257633203202425613630572016962838703318400930704175824104136", "price": "0.57", "size": "110", "side": "BUY", "hash": "ecc0b982f920c5bf2d380492a99269bd591bf3f0", "best_bid": "0.58", "best_ask": "0.62"}, {"asset_id": "817582445527276447057755966542888616081641371741603398122454732956499627950", "price": "0.43", "size": "110", "side": "SELL", "hash": "7aa373b73bec6f15fd624e2d1a61e566d441aa3b", "best_bid": "0.38", "best_ask": "0.42"}], "timestamp": "1769384633000", "event_type": "price_change"}}
{"_local_timestamp": "2026-01-25T23:43:53.210875+00:00", "data": {"market": "0x715dc274a5c7adf3771646e36d5e3a8844163dc31e7f02331eb30d2b8108bf9e", "price_changes": [{"asset_id": "19458454719947582257633203202425613630572016962838703318400930704175824104136", "price": "0.21", "size": "0", "side": "BUY", "hash": "2ea2921048514f30ef0294403179a4e211e5a0e3", "best_bid": "0.58", "best_ask": "0.62"}, {"asset_id": "817582445527276447057755966542888616081641371741603398122454732956499627950", "price": "0.79", "size": "0", "side": "SELL", "hash": "e2a067591487471b03ad317605a1bfb92d30f62b", "best_bid": "0.38", "best_ask": "0.42"}], "timestamp": "1769384633001", "event_type": "price_change"}}
{"_local_timestamp": "2026-01-25T23:43:53.211154+00:00", "data": {"market": "0x715dc274a5c7adf3771646e36d5e3a8844163dc31e7f02331eb30d2b8108bf9e", "price_changes": [{"asset_id": "817582445527276447057755966542888616081641371741603398122454732956499627950", "price": "0.19", "size": "20", "side": "BUY", "hash": "aaffa4a0545621df1e66a310c1225ee9fd68f0f4", "best_bid": "0.38", "best_ask": "0.42"}, {"asset_id": "19458454719947582257633203202425613630572016962838703318400930704175824104136", "price": "0.81", "size": "20", "side": "SELL", "hash": "91a44b025a8ef6acb15c04c7e016c9ba54045475", "best_bid": "0.58", "best_ask": "0.62"}], "timestamp": "1769384633002", "event_type": "price_change"}}
{"_local_timestamp": "2026-01-25T23:43:53.211394+00:00", "data": {"market": "0x715dc274a5c7adf3771646e36d5e3a8844163dc31e7f02331eb30d2b8108bf9e", "price_changes": [{"asset_id": "19458454719947582257633203202425613630572016962838703318400930704175824104136", "price": "0.29", "size": "223", "side": "BUY", "hash": "0f97839f642afb8d3d6302bbd541b3751430e307", "best_bid": "0.58", "best_ask": "0.62"}, {"asset_id": "817582445527276447057755966542888616081641371741603398122454732956499627950", "price": "0.71", "size": "223", "side": "SELL", "hash": "a6322de27b23cab14959739e0b29d6e770a785bd", "best_bid": "0.38", "best_ask": "0.42"}], "timestamp": "1769384633003", "event_type": "price_change"}}
{"_local_timestamp": "2026-01-25T23:43:53.239859+00:00", "data": {"market": "0x715dc274a5c7adf3771646e36d5e3a8844163dc31e7f02331eb30d2b8108bf9e", "price_changes": [{"asset_id": "817582445527276447057755966542888616081641371741603398122454732956499627950", "price": "0.28", "size": "0", "side": "BUY", "hash": "0fcf8a209e2450888d2bdb82049f388714433984", "best_bid": "0.38", "best_ask": "0.42"}, {"asset_id": "19458454719947582257633203202425613630572016962838703318400930704175824104136", "price": "0.72", "size": "0", "side": "SELL", "hash": "670eec639d2e1857c08dd880d8e3a8a1b65c14ab", "best_bid": "0.58", "best_ask": "0.62"}], "timestamp": "1769384633051", "event_type": "price_change"}}
{"_local_timestamp": "2026-01-25T23:43:53.269101+00:00", "data": {"market": "0x715dc274a5c7adf3771646e36d5e3a8844163dc31e7f02331eb30d2b8108bf9e", "price_changes": [{"asset_id": "817582445527276447057755966542888616081641371741603398122454732956499627950", "price": "0.29", "size": "150", "side": "BUY", "hash": "460e8ccdd800159a41e752f07f0df801a3e60419", "best_bid": "0.38", "best_ask": "0.42"}, {"asset_id": "19458454719947582257633203202425613630572016962838703318400930704175824104136", "price": "0.71", "size": "150", "side": "SELL", "hash": "8b64e94b74b36d91a8557eb2c92c3ad88bc72575", "best_bid": "0.58", "best_ask": "0.62"}], "timestamp": "1769384633078", "event_type": "price_change"}}
{"_local_timestamp": "2026-01-25T23:43:53.963340+00:00", "data": {"market": "0x715dc274a5c7adf3771646e36d5e3a8844163dc31e7f02331eb30d2b8108bf9e", "price_changes": [{"asset_id": "817582445527276447057755966542888616081641371741603398122454732956499627950", "price": "0.19", "size": "50", "side": "BUY", "hash": "9ed4461633078e900c0e1c3b27574aaa9af9e168", "best_bid": "0.38", "best_ask": "0.42"}, {"asset_id": "19458454719947582257633203202425613630572016962838703318400930704175824104136", "price": "0.81", "size": "50", "side": "SELL", "hash": "10d248efc4097b944b0829806a7e20b04aaf7b43", "best_bid": "0.58", "best_ask": "0.62"}], "timestamp": "1769384633818", "event_type": "price_change"}}
{"_local_timestamp": "2026-01-25T23:43:54.177885+00:00", "data": {"market": "0x715dc274a5c7adf3771646e36d5e3a8844163dc31e7f02331eb30d2b8108bf9e", "price_changes": [{"asset_id": "817582445527276447057755966542888616081641371741603398122454732956499627950", "price": "0.17", "size": "5.29", "side": "BUY", "hash": "2eb313ebb044b7c322b8c2e9c273e1a98ad650e6", "best_bid": "0.38", "best_ask": "0.42"}, {"asset_id": "19458454719947582257633203202425613630572016962838703318400930704175824104136", "price": "0.83", "size": "5.29", "side": "SELL", "hash": "96a0a8adff0805e004440949bc8bc85f688c698c", "best_bid": "0.58", "best_ask": "0.62"}], "timestamp": "1769384634002", "event_type": "price_change"}}
{"_local_timestamp": "2026-01-25T23:43:54.225013+00:00", "data": {"market": "0x715dc274a5c7adf3771646e36d5e3a8844163dc31e7f02331eb30d2b8108bf9e", "price_changes": [{"asset_id": "817582445527276447057755966542888616081641371741603398122454732956499627950", "price": "0.29", "size": "120", "side": "BUY", "hash": "2db3f76e11fbde0ebf0a40da36c57896b77df8ef", "best_bid": "0.38", "best_ask": "0.42"}, {"asset_id": "19458454719947582257633203202425613630572016962838703318400930704175824104136", "price": "0.71", "size": "120", "side": "SELL", "hash": "e7a7a04b3c5aaca90c037b0aa9f543581c50285c", "best_bid": "0.58", "best_ask": "0.62"}], "timestamp": "1769384634058", "event_type": "price_change"}}
{"_local_timestamp": "2026-01-25T23:43:58.826380+00:00", "data": {"market": "0x715dc274a5c7adf3771646e36d5e3a8844163dc31e7f02331eb30d2b8108bf9e", "price_changes": [{"asset_id": "817582445527276447057755966542888616081641371741603398122454732956499627950", "price": "0.07", "size": "485.71", "side": "BUY", "hash": "02d475eceec64a1022a34e58b369317526d86636", "best_bid": "0.38", "best_ask": "0.42"}, {"asset_id": "19458454719947582257633203202425613630572016962838703318400930704175824104136", "price": "0.93", "size": "485.71", "side": "SELL", "hash": "7db33ca202bee96ccfdaebaa68f3171d75ff79f4", "best_bid": "0.58", "best_ask": "0.62"}], "timestamp": "1769384638685", "event_type": "price_change"}}
{"_local_timestamp": "2026-01-25T23:43:59.927290+00:00", "data": {"market": "0x715dc274a5c7adf3771646e36d5e3a8844163dc31e7f02331eb30d2b8108bf9e", "price_changes": [{"asset_id": "817582445527276447057755966542888616081641371741603398122454732956499627950", "price": "0.3", "size": "30", "side": "BUY", "hash": "f0ba549262f784c4db328a7c98facb4bbdbd0dbb", "best_bid": "0.38", "best_ask": "0.42"}, {"asset_id": "19458454719947582257633203202425613630572016962838703318400930704175824104136", "price": "0.7", "size": "30", "side": "SELL", "hash": "ca5995b6f737d4ff0801720a45dc8c9d6992138c", "best_bid": "0.58", "best_ask": "0.62"}], "timestamp": "1769384639797", "event_type": "price_change"}}
{"_local_timestamp": "2026-01-25T23:43:59.960473+00:00", "data": {"market": "0x715dc274a5c7adf3771646e36d5e3a8844163dc31e7f02331eb30d2b8108bf9e", "price_changes": [{"asset_id": "817582445527276447057755966542888616081641371741603398122454732956499627950", "price": "0.29", "size": "0", "side": "BUY", "hash": "64796d20750972de9a056f4dd96ea01ec77fc6bb", "best_bid": "0.38", "best_ask": "0.42"}, {"asset_id": "19458454719947582257633203202425613630572016962838703318400930704175824104136", "price": "0.71", "size": "0", "side": "SELL", "hash": "e02880765c3436d283f6d382b52b5f0dafda80e9", "best_bid": "0.58", "best_ask": "0.62"}], "timestamp": "1769384639820", "event_type": "price_change"}}
{"_local_timestamp": "2026-01-25T23:43:59.977407+00:00", "data": {"market": "0x715dc274a5c7adf3771646e36d5e3a8844163dc31e7f02331eb30d2b8108bf9e", "price_changes": [{"asset_id": "817582445527276447057755966542888616081641371741603398122454732956499627950", "price": "0.31", "size": "113", "side": "BUY", "hash": "cbb95b787cbcfd9e37956b5ea8ed1c76c0082824", "best_bid": "0.38", "best_ask": "0.42"}, {"asset_id": "19458454719947582257633203202425613630572016962838703318400930704175824104136", "price": "0.69", "size": "113", "side": "SELL", "hash": "42c54eaf911139cba249ff2414ff70dcd3826e85", "best_bid": "0.58", "best_ask": "0.62"}], "timestamp": "1769384639847", "event_type": "price_change"}}
{"_local_timestamp": "2026-01-25T23:44:00.203175+00:00", "data": {"market": "0x715dc274a5c7adf3771646e36d5e3a8844163dc31e7f02331eb30d2b8108bf9e", "price_changes": [{"asset_id": "817582445527276447057755966542888616081641371741603398122454732956499627950", "price": "0.19", "size": "20", "side": "BUY", "hash": "1dbe1362268e7bfa2fe19768ee4ac8342700746b", "best_bid": "0.38", "best_ask": "0.42"}, {"asset_id": "19458454719947582257633203202425613630572016962838703318400930704175824104136", "price": "0.81", "size": "20", "side": "SELL", "hash": "30d8972edab23876894231116b2900d61fcdf25a", "best_bid": "0.58", "best_ask": "0.62"}], "timestamp": "1769384640060", "event_type": "price_change"}}
{"_local_timestamp": "2026-01-25T23:44:05.964994+00:00", "data": {"market": "0x715dc274a5c7adf3771646e36d5e3a8844163dc31e7f02331eb30d2b8108bf9e", "price_changes": [{"asset_id": "817582445527276447057755966542888616081641371741603398122454732956499627950", "price": "0.19", "size": "50", "side": "BUY", "hash": "c2ae65ba3e6426db63a34e819a52ebade40fb5c2", "best_bid": "0.38", "best_ask": "0.42"}, {"asset_id": "19458454719947582257633203202425613630572016962838703318400930704175824104136", "price": "0.81", "size": "50", "side": "SELL", "hash": "7c7f77ced9fec41d64a0e481de6e340c3f39c153", "best_bid": "0.58", "best_ask": "0.62"}], "timestamp": "1769384645822", "event_type": "price_change"}}
{"_local_timestamp": "2026-01-25T23:44:06.234105+00:00", "data": {"market": "0x715dc274a5c7adf3771646e36d5e3a8844163dc31e7f02331eb30d2b8108bf9e", "price_changes": [{"asset_id": "817582445527276447057755966542888616081641371741603398122454732956499627950", "price": "0.3", "size": "0", "side": "BUY", "hash": "4bb61cf0625c287c92fcd9080a44a553db4ccafe", "best_bid": "0.38", "best_ask": "0.42"}, {"asset_id": "19458454719947582257633203202425613630572016962838703318400930704175824104136", "price": "0.7", "size": "0", "side": "SELL", "hash": "5ea785eb22c9c3007a2463530cb3ee59b8f0c177", "best_bid": "0.58", "best_ask": "0.62"}], "timestamp": "1769384646089", "event_type": "price_change"}}
{"_local_timestamp": "2026-01-25T23:44:06.257680+00:00", "data": {"market": "0x715dc274a5c7adf3771646e36d5e3a8844163dc31e7f02331eb30d2b8108bf9e", "price_changes": [{"asset_id": "817582445527276447057755966542888616081641371741603398122454732956499627950", "price": "0.31", "size": "0", "side": "BUY", "hash": "17a528d7615015ebcd932e6e5845667b82366264", "best_bid": "0.38", "best_ask": "0.42"}, {"asset_id": "19458454719947582257633203202425613630572016962838703318400930704175824104136", "price": "0.69", "size": "0", "side": "SELL", "hash": "c093532f76cdc8959116a0ad8c9c444f7ada174f", "best_bid": "0.58", "best_ask": "0.62"}], "timestamp": "1769384646115", "event_type": "price_change"}}
{"_local_timestamp": "2026-01-25T23:44:06.275964+00:00", "data": {"market": "0x715dc274a5c7adf3771646e36d5e3a8844163dc31e7f02331eb30d2b8108bf9e", "price_changes": [{"asset_id": "817582445527276447057755966542888616081641371741603398122454732956499627950", "price": "0.28", "size": "113", "side": "BUY", "hash": "9e631eaeded0d2cba502ee0784a5ed95fab5e7fd", "best_bid": "0.38", "best_ask": "0.42"}, {"asset_id": "19458454719947582257633203202425613630572016962838703318400930704175824104136", "price": "0.72", "size": "113", "side": "SELL", "hash": "6cddbefe7878444eb71f1df07cef7b3ac92a16ee", "best_bid": "0.58", "best_ask": "0.62"}], "timestamp": "1769384646140", "event_type": "price_change"}}
{"_local_timestamp": "2026-01-25T23:44:08.753189+00:00", "data": {"market": "0xfb08a969a2c05beda8b5743959182db28be71832f9a84872a786e809b77b5350", "price_changes": [{"asset_id": "13908252531396871469657521961663517650827376216919668668811621820614371209132", "price": "0.13", "size": "461.53", "side": "BUY", "hash": "0ac0911a679a02c6dfc8214be4e0bb091b33baf1", "best_bid": "0.842", "best_ask": "0.974"}, {"asset_id": "28670530274590253141384619337562139640467932392972183997943459931027267172276", "price": "0.87", "size": "461.53", "side": "SELL", "hash": "c70c882246eb28e5a1cbf9e264463701443ac1bd", "best_bid": "0.026", "best_ask": "0.158"}], "timestamp": "1769384648442", "event_type": "price_change"}}
{"_local_timestamp": "2026-01-25T23:44:08.753492+00:00", "data": {"market": "0xfb08a969a2c05beda8b5743959182db28be71832f9a84872a786e809b77b5350", "price_changes": [{"asset_id": "13908252531396871469657521961663517650827376216919668668811621820614371209132", "price": "0.231", "size": "450", "side": "BUY", "hash": "0ac0911a679a02c6dfc8214be4e0bb091b33baf1", "best_bid": "0.842", "best_ask": "0.974"}, {"asset_id": "28670530274590253141384619337562139640467932392972183997943459931027267172276", "price": "0.769", "size": "450", "side": "SELL", "hash": "c70c882246eb28e5a1cbf9e264463701443ac1bd", "best_bid": "0.026", "best_ask": "0.158"}], "timestamp": "1769384648442", "event_type": "price_change"}}
{"_local_timestamp": "2026-01-25T23:44:08.753720+00:00", "data": {"market": "0xfb08a969a2c05beda8b5743959182db28be71832f9a84872a786e809b77b5350", "price_changes": [{"asset_id": "13908252531396871469657521961663517650827376216919668668811621820614371209132", "price": "0.17", "size": "850", "side": "BUY", "hash": "0ac0911a679a02c6dfc8214be4e0bb091b33baf1", "best_bid": "0.842", "best_ask": "0.974"}, {"asset_id": "28670530274590253141384619337562139640467932392972183997943459931027267172276", "price": "0.83", "size": "850", "side": "SELL", "hash": "c70c882246eb28e5a1cbf9e264463701443ac1bd", "best_bid": "0.026", "best_ask": "0.158"}], "timestamp": "1769384648442", "event_type": "price_change"}}
{"_local_timestamp": "2026-01-25T23:44:11.928950+00:00", "data": {"market": "0x715dc274a5c7adf3771646e36d5e3a8844163dc31e7f02331eb30d2b8108bf9e", "price_changes": [{"asset_id": "817582445527276447057755966542888616081641371741603398122454732956499627950", "price": "0.29", "size": "30", "side": "BUY", "hash": "5969f9e14a20bceaf175e59f9d36fe390bc9387e", "best_bid": "0.38", "best_ask": "0.42"}, {"asset_id": "19458454719947582257633203202425613630572016962838703318400930704175824104136", "price": "0.71", "size": "30", "side": "SELL", "hash": "5bf53ec4e079a461ddd5095ce9b79218c724aff1", "best_bid": "0.58", "best_ask": "0.62"}], "timestamp": "1769384651781", "event_type": "price_change"}}
{"_local_timestamp": "2026-01-25T23:44:11.954805+00:00", "data": {"market": "0x715dc274a5c7adf3771646e36d5e3a8844163dc31e7f02331eb30d2b8108bf9e", "price_changes": [{"asset_id": "817582445527276447057755966542888616081641371741603398122454732956499627950", "price": "0.28", "size": "0", "side": "BUY", "hash": "ca1a3e35eab11702fe23a48503bebacec7e32547", "best_bid": "0.38", "best_ask": "0.42"}, {"asset_id": "19458454719947582257633203202425613630572016962838703318400930704175824104136", "price": "0.72", "size": "0", "side": "SELL", "hash": "e61745dc2086374fcc3e044726a0156f7d0377c2", "best_bid": "0.58", "best_ask": "0.62"}], "timestamp": "1769384651812", "event_type": "price_change"}}
{"_local_timestamp": "2026-01-25T23:44:12.023615+00:00", "data": {"market": "0x715dc274a5c7adf3771646e36d5e3a8844163dc31e7f02331eb30d2b8108bf9e", "price_changes": [{"asset_id": "817582445527276447057755966542888616081641371741603398122454732956499627950", "price": "0.3", "size": "113", "side": "BUY", "hash": "505b46d126f75e99e9910bf5755aef632d6ded8f", "best_bid": "0.38", "best_ask": "0.42"}, {"asset_id": "19458454719947582257633203202425613630572016962838703318400930704175824104136", "price": "0.7", "size": "113", "side": "SELL", "hash": "2a03df14cc387d033088b054b71605d9bc5eb110", "best_bid": "0.58", "best_ask": "0.62"}], "timestamp": "1769384651843", "event_type": "price_change"}}
{"_local_timestamp": "2026-01-25T23:44:12.206667+00:00", "data": {"market": "0x715dc274a5c7adf3771646e36d5e3a8844163dc31e7f02331eb30d2b8108bf9e", "price_changes": [{"asset_id": "817582445527276447057755966542888616081641371741603398122454732956499627950", "price": "0.19", "size": "20", "side": "BUY", "hash": "47a8d15851f4fcf2c00e0ad98a185149dfb20020", "best_bid": "0.38", "best_ask": "0.42"}, {"asset_id": "19458454719947582257633203202425613630572016962838703318400930704175824104136", "price": "0.81", "size": "20", "side": "SELL", "hash": "f7b61e5707ebd9f71717fe5d4dadaecacc072cf8", "best_bid": "0.58", "best_ask": "0.62"}], "timestamp": "1769384652051", "event_type": "price_change"}}
{"_local_timestamp": "2026-01-25T23:44:18.025374+00:00", "data": {"market": "0x715dc274a5c7adf3771646e36d5e3a8844163dc31e7f02331eb30d2b8108bf9e", "price_changes": [{"asset_id": "817582445527276447057755966542888616081641371741603398122454732956499627950", "price": "0.31", "size": "30", "side": "BUY", "hash": "c249e34358eb5f129de43ae0d1dcb900cd728a5c", "best_bid": "0.38", "best_ask": "0.42"}, {"asset_id": "19458454719947582257633203202425613630572016962838703318400930704175824104136", "price": "0.69", "size": "30", "side": "SELL", "hash": "9de4359b74a49fedb254a9e4cdd73ad1139effdf", "best_bid": "0.58", "best_ask": "0.62"}], "timestamp": "1769384657780", "event_type": "price_change"}}
{"_local_timestamp": "2026-01-25T23:44:18.048134+00:00", "data": {"market": "0x715dc274a5c7adf3771646e36d5e3a8844163dc31e7f02331eb30d2b8108bf9e", "price_changes": [{"asset_id": "817582445527276447057755966542888616081641371741603398122454732956499627950", "price": "0.19", "size": "0", "side": "BUY", "hash": "1fde01bdd0f137c71ba2cf3d97279c01e72058cc", "best_bid": "0.38", "best_ask": "0.42"}, {"asset_id": "19458454719947582257633203202425613630572016962838703318400930704175824104136", "price": "0.81", "size": "0", "side": "SELL", "hash": "bed04d9f5a8383bc57992518b2c499ed277ce92c", "best_bid": "0.58", "best_ask": "0.62"}], "timestamp": "1769384657804", "event_type": "price_change"}}
{"_local_timestamp": "2026-01-25T23:44:18.080102+00:00", "data": {"market": "0x715dc274a5c7adf3771646e36d5e3a8844163dc31e7f02331eb30d2b8108bf9e", "price_changes": [{"asset_id": "817582445527276447057755966542888616081641371741603398122454732956499627950", "price": "0.3", "size": "0", "side": "BUY", "hash": "ad6406164938fc88afbbbd1e733efd51de667938", "best_bid": "0.38", "best_ask": "0.42"}, {"asset_id": "19458454719947582257633203202425613630572016962838703318400930704175824104136", "price": "0.7", "size": "0", "side": "SELL", "hash": "eef234376150555bf7cdd62add134bc796f505a2", "best_bid": "0.58", "best_ask": "0.62"}], "timestamp": "1769384657834", "event_type": "price_change"}}
{"_local_timestamp": "2026-01-25T23:44:18.110707+00:00", "data": {"market": "0x715dc274a5c7adf3771646e36d5e3a8844163dc31e7f02331eb30d2b8108bf9e", "price_changes": [{"asset_id": "817582445527276447057755966542888616081641371741603398122454732956499627950", "price": "0.31", "size": "139", "side": "BUY", "hash": "838f9ee7c16c2f8928325528397b79fdc5bc5dc0", "best_bid": "0.38", "best_ask": "0.42"}, {"asset_id": "19458454719947582257633203202425613630572016962838703318400930704175824104136", "price": "0.69", "size": "139", "side": "SELL", "hash": "cb1a4eacc63cd914df7c308f071b3e148a665b91", "best_bid": "0.58", "best_ask": "0.62"}], "timestamp": "1769384657858", "event_type": "price_change"}}
{"_local_timestamp": "2026-01-25T23:44:18.195945+00:00", "data": {"market": "0x715dc274a5c7adf3771646e36d5e3a8844163dc31e7f02331eb30d2b8108bf9e", "price_changes": [{"asset_id": "817582445527276447057755966542888616081641371741603398122454732956499627950", "price": "0.19", "size": "20", "side": "BUY", "hash": "88a3a6894eecfd883b7348b6ed99fdeee27a1035", "best_bid": "0.38", "best_ask": "0.42"}, {"asset_id": "19458454719947582257633203202425613630572016962838703318400930704175824104136", "price": "0.81", "size": "20", "side": "SELL", "hash": "33b78ceb13039aa58fa4dc48bab5afea6e3749f8", "best_bid": "0.58", "best_ask": "0.62"}], "timestamp": "1769384657929", "event_type": "price_change"}}
{"_local_timestamp": "2026-01-25T23:44:18.336827+00:00", "data": {"market": "0x715dc274a5c7adf3771646e36d5e3a8844163dc31e7f02331eb30d2b8108bf9e", "price_changes": [{"asset_id": "817582445527276447057755966542888616081641371741603398122454732956499627950", "price": "0.29", "size": "0", "side": "BUY", "hash": "065f7806969b3303c58ea12c22653fa0ae9d0953", "best_bid": "0.38", "best_ask": "0.42"}, {"asset_id": "19458454719947582257633203202425613630572016962838703318400930704175824104136", "price": "0.71", "size": "0", "side": "SELL", "hash": "2a04789136fd82a007c549da79ea37619e92122d", "best_bid": "0.58", "best_ask": "0.62"}], "timestamp": "1769384658096", "event_type": "price_change"}}
{"_local_timestamp": "2026-01-25T23:44:20.966442+00:00", "data": {"market": "0xfb08a969a2c05beda8b5743959182db28be71832f9a84872a786e809b77b5350", "price_changes": [{"asset_id": "13908252531396871469657521961663517650827376216919668668811621820614371209132", "price": "0.13", "size": "261.53", "side": "BUY", "hash": "21cda232481a65d3880065a635e659b604dba9e2", "best_bid": "0.842", "best_ask": "0.974"}, {"asset_id": "28670530274590253141384619337562139640467932392972183997943459931027267172276", "price": "0.87", "size": "261.53", "side": "SELL", "hash": "2f2056540c9a64fc31fb09b34a828aa289427f13", "best_bid": "0.026", "best_ask": "0.158"}], "timestamp": "1769384660493", "event_type": "price_change"}}
{"_local_timestamp": "2026-01-25T23:44:21.364659+00:00", "data": {"market": "0xfb08a969a2c05beda8b5743959182db28be71832f9a84872a786e809b77b5350", "price_changes": [{"asset_id": "13908252531396871469657521961663517650827376216919668668811621820614371209132", "price": "0.17", "size": "700", "side": "BUY", "hash": "21cda232481a65d3880065a635e659b604dba9e2", "best_bid": "0.842", "best_ask": "0.974"}, {"asset_id": "28670530274590253141384619337562139640467932392972183997943459931027267172276", "price": "0.83", "size": "700", "side": "SELL", "hash": "2f2056540c9a64fc31fb09b34a828aa289427f13", "best_bid": "0.026", "best_ask": "0.158"}], "timestamp": "1769384660493", "event_type": "price_change"}}
{"_local_timestamp": "2026-01-25T23:44:21.381320+00:00", "data": {"market": "0xfb08a969a2c05beda8b5743959182db28be71832f9a84872a786e809b77b5350", "price_changes": [{"asset_id": "13908252531396871469657521961663517650827376216919668668811621820614371209132", "price": "0.231", "size": "350", "side": "BUY", "hash": "21cda232481a65d3880065a635e659b604dba9e2", "best_bid": "0.842", "best_ask": "0.974"}, {"asset_id": "28670530274590253141384619337562139640467932392972183997943459931027267172276", "price": "0.769", "size": "350", "side": "SELL", "hash": "2f2056540c9a64fc31fb09b34a828aa289427f13", "best_bid": "0.026", "best_ask": "0.158"}], "timestamp": "1769384660493", "event_type": "price_change"}}
{"_local_timestamp": "2026-01-25T23:44:24.058566+00:00", "data": {"market": "0x715dc274a5c7adf3771646e36d5e3a8844163dc31e7f02331eb30d2b8108bf9e", "price_changes": [{"asset_id": "817582445527276447057755966542888616081641371741603398122454732956499627950", "price": "0.19", "size": "50", "side": "BUY", "hash": "dce912e41dfdff030fdb66b6598a88827fbaa198", "best_bid": "0.38", "best_ask": "0.42"}, {"asset_id": "19458454719947582257633203202425613630572016962838703318400930704175824104136", "price": "0.81", "size": "50", "side": "SELL", "hash": "34a389aae15dc3612361d3fc78353d2855c783b7", "best_bid": "0.58", "best_ask": "0.62"}], "timestamp": "1769384663793", "event_type": "price_change"}}
{"_local_timestamp": "2026-01-25T23:44:24.320608+00:00", "data": {"market": "0x715dc274a5c7adf3771646e36d5e3a8844163dc31e7f02331eb30d2b8108bf9e", "price_changes": [{"asset_id": "817582445527276447057755966542888616081641371741603398122454732956499627950", "price": "0.31", "size": "109", "side": "BUY", "hash": "bcab3abcf23a1c4d806b918dddd46f6efa17f944", "best_bid": "0.38", "best_ask": "0.42"}, {"asset_id": "19458454719947582257633203202425613630572016962838703318400930704175824104136", "price": "0.69", "size": "109", "side": "SELL", "hash": "ebfec118225ba6926490e59d530a2e2c2e39e6c0", "best_bid": "0.58", "best_ask": "0.62"}], "timestamp": "1769384664050", "event_type": "price_change"}}
{"_local_timestamp": "2026-01-25T23:44:24.349367+00:00", "data": {"market": "0x715dc274a5c7adf3771646e36d5e3a8844163dc31e7f02331eb30d2b8108bf9e", "price_changes": [{"asset_id": "817582445527276447057755966542888616081641371741603398122454732956499627950", "price": "0.31", "size": "0", "side": "BUY", "hash": "603f17e3e77de0d6b509b946a5c2bedf2f1cf9a4", "best_bid": "0.38", "best_ask": "0.42"}, {"asset_id": "19458454719947582257633203202425613630572016962838703318400930704175824104136", "price": "0.69", "size": "0", "side": "SELL", "hash": "a58f76ca051437c73f53958c02ca8655e8b2c86d", "best_bid": "0.58", "best_ask": "0.62"}], "timestamp": "1769384664082", "event_type": "price_change"}}
{"_local_timestamp": "2026-01-25T23:44:24.382372+00:00", "data": {"market": "0x715dc274a5c7adf3771646e36d5e3a8844163dc31e7f02331eb30d2b8108bf9e", "price_changes": [{"asset_id": "817582445527276447057755966542888616081641371741603398122454732956499627950", "price": "0.28", "size": "144", "side": "BUY", "hash": "282484af38af174ee5fcc9a722d6900eaa69217b", "best_bid": "0.38", "best_ask": "0.42"}, {"asset_id": "19458454719947582257633203202425613630572016962838703318400930704175824104136", "price": "0.72", "size": "144", "side": "SELL", "hash": "d8f34c633b69b810a18c9cbbc3e185f00a840908", "best_bid": "0.58", "best_ask": "0.62"}], "timestamp": "1769384664125", "event_type": "price_change"}}
{"_local_timestamp": "2026-01-25T23:44:29.881374+00:00", "data": {"market": "0x715dc274a5c7adf3771646e36d5e3a8844163dc31e7f02331eb30d2b8108bf9e", "price_changes": [{"asset_id": "817582445527276447057755966542888616081641371741603398122454732956499627950", "price": "0.29", "size": "30", "side": "BUY", "hash": "afbbfd0349f15b8e098ed757ecb95928e2335c8f", "best_bid": "0.38", "best_ask": "0.42"}, {"asset_id": "19458454719947582257633203202425613630572016962838703318400930704175824104136", "price": "0.71", "size": "30", "side": "SELL", "hash": "2e5718b09a0a94f12ebbd2aa19bdcef2058af4c8", "best_bid": "0.58", "best_ask": "0.62"}], "timestamp": "1769384669612", "event_type": "price_change"}}
{"_local_timestamp": "2026-01-25T23:44:30.078463+00:00", "data": {"market": "0x29d688e8ee4dc83cff27ce5d583553be477b4202aba945dff96730aa88397071", "price_changes": [{"asset_id": "22395241560984864794587761975509529149656370897276070318169938852205137917866", "price": "0.46", "size": "0", "side": "BUY", "hash": "09c10b6106367f9ae9e2107429a3a2f6c2ae533f", "best_bid": "0.8", "best_ask": "0.95"}, {"asset_id": "46123672832602976783793170370598938766981479048132054420648285300054482204701", "price": "0.54", "size": "0", "side": "SELL", "hash": "081bb9b14b98acfc9af993a35220146551851f99", "best_bid": "0.05", "best_ask": "0.2"}], "timestamp": "1769384669815", "event_type": "price_change"}}
{"_local_timestamp": "2026-01-25T23:44:30.161771+00:00", "data": {"market": "0x715dc274a5c7adf3771646e36d5e3a8844163dc31e7f02331eb30d2b8108bf9e", "price_changes": [{"asset_id": "817582445527276447057755966542888616081641371741603398122454732956499627950", "price": "0.19", "size": "20", "side": "BUY", "hash": "560289889a575aed2e97bf0fdbe3b3e864283e2a", "best_bid": "0.38", "best_ask": "0.42"}, {"asset_id": "19458454719947582257633203202425613630572016962838703318400930704175824104136", "price": "0.81", "size": "20", "side": "SELL", "hash": "1d113cca66d61be1ad0a24f0f3a8e78313ef29d6", "best_bid": "0.58", "best_ask": "0.62"}], "timestamp": "1769384669886", "event_type": "price_change"}}
{"_local_timestamp": "2026-01-25T23:44:30.244557+00:00", "data": {"market": "0x715dc274a5c7adf3771646e36d5e3a8844163dc31e7f02331eb30d2b8108bf9e", "price_changes": [{"asset_id": "817582445527276447057755966542888616081641371741603398122454732956499627950", "price": "0.08", "size": "0", "side": "BUY", "hash": "a90833c3ade0c0a960d0a02935de38505ccb3290", "best_bid": "0.38", "best_ask": "0.42"}, {"asset_id": "19458454719947582257633203202425613630572016962838703318400930704175824104136", "price": "0.92", "size": "0", "side": "SELL", "hash": "254f402e78686020e5a39abb3ee6c2373db26837", "best_bid": "0.58", "best_ask": "0.62"}], "timestamp": "1769384669987", "event_type": "price_change"}}
{"_local_timestamp": "2026-01-25T23:44:30.373452+00:00", "data": {"market": "0x29d688e8ee4dc83cff27ce5d583553be477b4202aba945dff96730aa88397071", "price_changes": [{"asset_id": "22395241560984864794587761975509529149656370897276070318169938852205137917866", "price": "0.57", "size": "10", "side": "BUY", "hash": "f48807bd0803539a7575bea59ffaa5c8a8718e53", "best_bid": "0.8", "best_ask": "0.95"}, {"asset_id": "46123672832602976783793170370598938766981479048132054420648285300054482204701", "price": "0.43", "size": "10", "side": "SELL", "hash": "00ad4127357a1b961725606ff4f2d0fe7e5cfb4e", "best_bid": "0.05", "best_ask": "0.2"}], "timestamp": "1769384670111", "event_type": "price_change"}}
{"_local_timestamp": "2026-01-25T23:44:32.124735+00:00", "data": {"market": "0x29d688e8ee4dc83cff27ce5d583553be477b4202aba945dff96730aa88397071", "price_changes": [{"asset_id": "22395241560984864794587761975509529149656370897276070318169938852205137917866", "price": "0.56", "size": "0", "side": "BUY", "hash": "70dd94ba3a8acb6ba892b3d2d0cae2b098db2a7e", "best_bid": "0.8", "best_ask": "0.95"}, {"asset_id": "46123672832602976783793170370598938766981479048132054420648285300054482204701", "price": "0.44", "size": "0", "side": "SELL", "hash": "cf661f11490712a05218dd0e74e7a362489b1d15", "best_bid": "0.05", "best_ask": "0.2"}], "timestamp": "1769384671833", "event_type": "price_change"}}
{"_local_timestamp": "2026-01-25T23:44:34.693485+00:00", "data": {"market": "0x29d688e8ee4dc83cff27ce5d583553be477b4202aba945dff96730aa88397071", "price_changes": [{"asset_id": "22395241560984864794587761975509529149656370897276070318169938852205137917866", "price": "0.58", "size": "20", "side": "BUY", "hash": "21a7631bd045f34ec4b7b454c6f0ed156d20eb2c", "best_bid": "0.8", "best_ask": "0.95"}, {"asset_id": "46123672832602976783793170370598938766981479048132054420648285300054482204701", "price": "0.42", "size": "20", "side": "SELL", "hash": "49441650e4a2863e88fbc938c05b3c504f18219c", "best_bid": "0.05", "best_ask": "0.2"}], "timestamp": "1769384671857", "event_type": "price_change"}}
{"_local_timestamp": "2026-01-25T23:44:35.800485+00:00", "data": {"market": "0xfb08a969a2c05beda8b5743959182db28be71832f9a84872a786e809b77b5350", "price_changes": [{"asset_id": "13908252531396871469657521961663517650827376216919668668811621820614371209132", "price": "0.09", "size": "400", "side": "BUY", "hash": "026edabf4638db11fe939c1072b675a00802eebf", "best_bid": "0.842", "best_ask": "0.974"}, {"asset_id": "28670530274590253141384619337562139640467932392972183997943459931027267172276", "price": "0.91", "size": "400", "side": "SELL", "hash": "cdd6f34fd2b045c89b6e578463d7a4888dd59c41", "best_bid": "0.026", "best_ask": "0.158"}], "timestamp": "1769384675490", "event_type": "price_change"}}
{"_local_timestamp": "2026-01-25T23:44:36.119316+00:00", "data": {"market": "0x715dc274a5c7adf3771646e36d5e3a8844163dc31e7f02331eb30d2b8108bf9e", "price_changes": [{"asset_id": "817582445527276447057755966542888616081641371741603398122454732956499627950", "price": "0.07", "size": "685.71", "side": "BUY", "hash": "f2ac988381e90f51747b2dfeb8838fc0fad02f67", "best_bid": "0.38", "best_ask": "0.42"}, {"asset_id": "19458454719947582257633203202425613630572016962838703318400930704175824104136", "price": "0.93", "size": "685.71", "side": "SELL", "hash": "27b6d2b8887c288cd6aa764604addeec60615df2", "best_bid": "0.58", "best_ask": "0.62"}], "timestamp": "1769384675803", "event_type": "price_change"}}
{"_local_timestamp": "2026-01-25T23:44:36.124061+00:00", "data": {"market": "0x715dc274a5c7adf3771646e36d5e3a8844163dc31e7f02331eb30d2b8108bf9e", "price_changes": [{"asset_id": "19458454719947582257633203202425613630572016962838703318400930704175824104136", "price": "0.06", "size": "800", "side": "BUY", "hash": "fdfaf88120d9624e3016fb8eebfcb33d08ce9e37", "best_bid": "0.58", "best_ask": "0.62"}, {"asset_id": "817582445527276447057755966542888616081641371741603398122454732956499627950", "price": "0.94", "size": "800", "side": "SELL", "hash": "c150b8e8597701d55d7232f5d8e9243c6352399f", "best_bid": "0.38", "best_ask": "0.42"}], "timestamp": "1769384675815", "event_type": "price_change"}}
{"_local_timestamp": "2026-01-25T23:44:36.129731+00:00", "data": {"market": "0x715dc274a5c7adf3771646e36d5e3a8844163dc31e7f02331eb30d2b8108bf9e", "price_changes": [{"asset_id": "817582445527276447057755966542888616081641371741603398122454732956499627950", "price": "0.01", "size": "6774.98", "side": "BUY", "hash": "ea4b67cacb8ddd0ced7ab4dd232d276b6b4cddec", "best_bid": "0.38", "best_ask": "0.42"}, {"asset_id": "19458454719947582257633203202425613630572016962838703318400930704175824104136", "price": "0.99", "size": "6774.98", "side": "SELL", "hash": "2dd1519ddb8c5339faec2e200a322b3844229885", "best_bid": "0.58", "best_ask": "0.62"}], "timestamp": "1769384675820", "event_type": "price_change"}}
{"_local_timestamp": "2026-01-25T23:44:36.454109+00:00", "data": {"market": "0x715dc274a5c7adf3771646e36d5e3a8844163dc31e7f02331eb30d2b8108bf9e", "price_changes": [{"asset_id": "817582445527276447057755966542888616081641371741603398122454732956499627950", "price": "0.04", "size": "2800", "side": "BUY", "hash": "6fb70b8da219ca418749b81e8576065c64dae45e", "best_bid": "0.38", "best_ask": "0.42"}, {"asset_id": "19458454719947582257633203202425613630572016962838703318400930704175824104136", "price": "0.96", "size": "2800", "side": "SELL", "hash": "e3a0ad90695c4203b214c2c44feed679bc9154f8", "best_bid": "0.58", "best_ask": "0.62"}], "timestamp": "1769384675824", "event_type": "price_change"}}
{"_local_timestamp": "2026-01-25T23:44:39.256354+00:00", "data": {"market": "0x29d688e8ee4dc83cff27ce5d583553be477b4202aba945dff96730aa88397071", "price_changes": [{"asset_id": "22395241560984864794587761975509529149656370897276070318169938852205137917866", "price": "0.57", "size": "200", "side": "BUY", "hash": "4180abe67b9236451cdc2a84eac4674c3ec0531e", "best_bid": "0.8", "best_ask": "0.95"}, {"asset_id": "46123672832602976783793170370598938766981479048132054420648285300054482204701", "price": "0.43", "size": "200", "side": "SELL", "hash": "40b96a868190240c2f6aa6fe45c55d431268bd50", "best_bid": "0.05", "best_ask": "0.2"}], "timestamp": "1769384678967", "event_type": "price_change"}}
{"_local_timestamp": "2026-01-25T23:44:39.256667+00:00", "data": {"market": "0x29d688e8ee4dc83cff27ce5d583553be477b4202aba945dff96730aa88397071", "price_changes": [{"asset_id": "22395241560984864794587761975509529149656370897276070318169938852205137917866", "price": "0.56", "size": "190", "side": "BUY", "hash": "8a7606895bd92505252de9bfda8461bbdf2d5f6b", "best_bid": "0.8", "best_ask": "0.95"}, {"asset_id": "46123672832602976783793170370598938766981479048132054420648285300054482204701", "price": "0.44", "size": "190", "side": "SELL", "hash": "b6542297fd8329ae1a749ca4f638e6071ff4e17a", "best_bid": "0.05", "best_ask": "0.2"}], "timestamp": "1769384678968", "event_type": "price_change"}}
{"_local_timestamp": "2026-01-25T23:44:40.321226+00:00", "data": {"market": "0x29d688e8ee4dc83cff27ce5d583553be477b4202aba945dff96730aa88397071", "price_changes": [{"asset_id": "46123672832602976783793170370598938766981479048132054420648285300054482204701", "price": "0.57", "size": "0", "side": "SELL", "hash": "77fbf770c9c890b3bf656073e4d00d0a22f476f9", "best_bid": "0.05", "best_ask": "0.2"}, {"asset_id": "22395241560984864794587761975509529149656370897276070318169938852205137917866", "price": "0.43", "size": "0", "side": "BUY", "hash": "9e84f90290173e3dbb21bf1b610ea623e770eec5", "best_bid": "0.8", "best_ask": "0.95"}], "timestamp": "1769384680041", "event_type": "price_change"}}
{"_local_timestamp": "2026-01-25T23:44:40.406901+00:00", "data": {"market": "0x29d688e8ee4dc83cff27ce5d583553be477b4202aba945dff96730aa88397071", "price_changes": [{"asset_id": "46123672832602976783793170370598938766981479048132054420648285300054482204701", "price": "0.42", "size": "40", "side": "SELL", "hash": "d15096a6637b05efe1c9443e268e5dd309b91166", "best_bid": "0.05", "best_ask": "0.2"}, {"asset_id": "22395241560984864794587761975509529149656370897276070318169938852205137917866", "price": "0.58", "size": "40", "side": "BUY", "hash": "bbd06c7ca2cd29ee37998c435eb3e91af00b255b", "best_bid": "0.8", "best_ask": "0.95"}], "timestamp": "1769384680122", "event_type": "price_change"}}
{"_local_timestamp": "2026-01-25T23:44:44.548542+00:00", "data": {"market": "0x29d688e8ee4dc83cff27ce5d583553be477b4202aba945dff96730aa88397071", "price_changes": [{"asset_id": "22395241560984864794587761975509529149656370897276070318169938852205137917866", "price": "0.58", "size": "20", "side": "BUY", "hash": "7faea71de8c89e0eb54a75a29ae299c0028afbd5", "best_bid": "0.8", "best_ask": "0.95"}, {"asset_id": "46123672832602976783793170370598938766981479048132054420648285300054482204701", "price": "0.42", "size": "20", "side": "SELL", "hash": "d7a6feddbe5a2e2833b95f59a89c53c80203b157", "best_bid": "0.05", "best_ask": "0.2"}], "timestamp": "1769384684392", "event_type": "price_change"}}
{"_local_timestamp": "2026-01-25T23:44:44.580210+00:00", "data": {"market": "0x29d688e8ee4dc83cff27ce5d583553be477b4202aba945dff96730aa88397071", "price_changes": [{"asset_id": "22395241560984864794587761975509529149656370897276070318169938852205137917866", "price": "0.59", "size": "20", "side": "BUY", "hash": "52a613736ae1b80a74d8fdd0d37bb4cd62dc5fa0", "best_bid": "0.8", "best_ask": "0.95"}, {"asset_id": "46123672832602976783793170370598938766981479048132054420648285300054482204701", "price": "0.41", "size": "20", "side": "SELL", "hash": "cc86a806aa1790fba24ad02eef6ab616d6769e6b", "best_bid": "0.05", "best_ask": "0.2"}], "timestamp": "1769384684421", "event_type": "price_change"}}
{"_local_timestamp": "2026-01-25T23:45:11.404515+00:00", "data": {"market": "0xfb08a969a2c05beda8b5743959182db28be71832f9a84872a786e809b77b5350", "price_changes": [{"asset_id": "28670530274590253141384619337562139640467932392972183997943459931027267172276", "price": "0.002", "size": "560.34", "side": "BUY", "hash": "a2bc3cff8dc1c82b5b246dd26a467599274016fb", "best_bid": "0.026", "best_ask": "0.158"}, {"asset_id": "13908252531396871469657521961663517650827376216919668668811621820614371209132", "price": "0.998", "size": "560.34", "side": "SELL", "hash": "f214c8e2cbfee976c440e95a7f11e808d3a66e15", "best_bid": "0.842", "best_ask": "0.974"}], "timestamp": "1769384711281", "event_type": "price_change"}}
{"_local_timestamp": "2026-01-25T23:45:11.480323+00:00", "data": {"market": "0x29d688e8ee4dc83cff27ce5d583553be477b4202aba945dff96730aa88397071", "price_changes": [{"asset_id": "22395241560984864794587761975509529149656370897276070318169938852205137917866", "price": "0.56", "size": "0", "side": "BUY", "hash": "4ccb45701f3af5a0231c07b9c65850bbcbdc45bf", "best_bid": "0.8", "best_ask": "0.95"}, {"asset_id": "46123672832602976783793170370598938766981479048132054420648285300054482204701", "price": "0.44", "size": "0", "side": "SELL", "hash": "a66675dcd9b5af47e2fdd5f78a3810db0c133409", "best_bid": "0.05", "best_ask": "0.2"}], "timestamp": "1769384711387", "event_type": "price_change"}}
{"_local_timestamp": "2026-01-25T23:45:11.643179+00:00", "data": {"market": "0xd62d0fd81efeba80c7d331577b8cfdaf89eb287a64f65f6418677f5669da4374", "price_changes": [{"asset_id": "50806857340536377589471864244012059415352637140902118853666778383891415395995", "price": "0.47", "size": "0", "side": "BUY", "hash": "e7445311ac47992b0c27faa807b89c0de191fe25", "best_bid": "0.89", "best_ask": "0.93"}, {"asset_id": "44436347575766030163252235546454470356610478743001712085002709882075518933616", "price": "0.53", "size": "0", "side": "SELL", "hash": "ad3060f478dee131f811d8df3b6de98a495e39fb", "best_bid": "0.07", "best_ask": "0.11"}], "timestamp": "1769384711569", "event_type": "price_change"}}
{"_local_timestamp": "2026-01-25T23:45:11.777345+00:00", "data": {"market": "0xd62d0fd81efeba80c7d331577b8cfdaf89eb287a64f65f6418677f5669da4374", "price_changes": [{"asset_id": "50806857340536377589471864244012059415352637140902118853666778383891415395995", "price": "0.56", "size": "10", "side": "BUY", "hash": "2bc735a89d1e5438f4d5b6b7eb478619bd729d2e", "best_bid": "0.89", "best_ask": "0.93"}, {"asset_id": "44436347575766030163252235546454470356610478743001712085002709882075518933616", "price": "0.44", "size": "10", "side": "SELL", "hash": "4a493e0adc95a6fbeb2c5e4c82ff6eebc38c9208", "best_bid": "0.07", "best_ask": "0.11"}], "timestamp": "1769384711675", "event_type": "price_change"}}
{"_local_timestamp": "2026-01-25T23:45:16.159231+00:00", "data": {"market": "0xd62d0fd81efeba80c7d331577b8cfdaf89eb287a64f65f6418677f5669da4374", "price_changes": [{"asset_id": "50806857340536377589471864244012059415352637140902118853666778383891415395995", "price": "0.55", "size": "0", "side": "BUY", "hash": "373048a567e8bf3f970f24304f274ef81af6e79c", "best_bid": "0.89", "best_ask": "0.93"}, {"asset_id": "44436347575766030163252235546454470356610478743001712085002709882075518933616", "price": "0.45", "size": "0", "side": "SELL", "hash": "da4d6fd03989ba25865379970224c798324b9430", "best_bid": "0.07", "best_ask": "0.11"}], "timestamp": "1769384716078", "event_type": "price_change"}}
{"_local_timestamp": "2026-01-25T23:45:16.184166+00:00", "data": {"market": "0xd62d0fd81efeba80c7d331577b8cfdaf89eb287a64f65f6418677f5669da4374", "price_changes": [{"asset_id": "50806857340536377589471864244012059415352637140902118853666778383891415395995", "price": "0.57", "size": "20", "side": "BUY", "hash": "fdf20dbd609d3fde9a4f5fcb768ebbcb77af5d3e", "best_bid": "0.89", "best_ask": "0.93"}, {"asset_id": "44436347575766030163252235546454470356610478743001712085002709882075518933616", "price": "0.43", "size": "20", "side": "SELL", "hash": "c516bf52c65f01460b07c2c1b201809aecdea1c6", "best_bid": "0.07", "best_ask": "0.11"}], "timestamp": "1769384716107", "event_type": "price_change"}}
{"_local_timestamp": "2026-01-25T23:45:17.616550+00:00", "data": {"market": "0xebd6b4d15beed0a4a3a274d6d1bc13e0b15d13a330586190932a3c4c7887b72f", "price_changes": [{"asset_id": "113435897598335750012134454342623244279140769314836288769122310705258616530095", "price": "0.88", "size": "30", "side": "BUY", "hash": "605c68255389adefb15cb22610669d47b5e9f144", "best_bid": "0.89", "best_ask": "0.94"}, {"asset_id": "43860483933578174366905172776039394809444972860267197366014959631913892252602", "price": "0.12", "size": "30", "side": "SELL", "hash": "63a5a955520a56f69d840b472b889c560970e16a", "best_bid": "0.06", "best_ask": "0.11"}], "timestamp": "1769384717550", "event_type": "price_change"}}
{"_local_timestamp": "2026-01-25T23:45:17.617220+00:00", "data": {"market": "0xebd6b4d15beed0a4a3a274d6d1bc13e0b15d13a330586190932a3c4c7887b72f", "price_changes": [{"asset_id": "113435897598335750012134454342623244279140769314836288769122310705258616530095", "price": "0.75", "size": "8.86", "side": "BUY", "hash": "605c68255389adefb15cb22610669d47b5e9f144", "best_bid": "0.89", "best_ask": "0.94"}, {"asset_id": "43860483933578174366905172776039394809444972860267197366014959631913892252602", "price": "0.25", "size": "8.86", "side": "SELL", "hash": "63a5a955520a56f69d840b472b889c560970e16a", "best_bid": "0.06", "best_ask": "0.11"}], "timestamp": "1769384717550", "event_type": "price_change"}}
{"_local_timestamp": "2026-01-25T23:45:17.617553+00:00", "data": {"market": "0xebd6b4d15beed0a4a3a274d6d1bc13e0b15d13a330586190932a3c4c7887b72f", "price_changes": [{"asset_id": "113435897598335750012134454342623244279140769314836288769122310705258616530095", "price": "0.63", "size": "0", "side": "BUY", "hash": "605c68255389adefb15cb22610669d47b5e9f144", "best_bid": "0.89", "best_ask": "0.94"}, {"asset_id": "43860483933578174366905172776039394809444972860267197366014959631913892252602", "price": "0.37", "size": "0", "side": "SELL", "hash": "63a5a955520a56f69d840b472b889c560970e16a", "best_bid": "0.06", "best_ask": "0.11"}], "timestamp": "1769384717550", "event_type": "price_change"}}
{"_local_timestamp": "2026-01-25T23:45:17.724615+00:00", "data": {"market": "0x715dc274a5c7adf3771646e36d5e3a8844163dc31e7f02331eb30d2b8108bf9e", "price_changes": [{"asset_id": "817582445527276447057755966542888616081641371741603398122454732956499627950", "price": "0.12", "size": "147", "side": "BUY", "hash": "fe04ffef948e986577cc5f3e53e60f2e664f4074", "best_bid": "0.38", "best_ask": "0.42"}, {"asset_id": "19458454719947582257633203202425613630572016962838703318400930704175824104136", "price": "0.88", "size": "147", "side": "SELL", "hash": "10fc04b384b1b61750ccea4d92fb919863576cf9", "best_bid": "0.58", "best_ask": "0.62"}], "timestamp": "1769384717657", "event_type": "price_change"}}
{"_local_timestamp": "2026-01-25T23:45:18.054223+00:00", "data": {"market": "0xebd6b4d15beed0a4a3a274d6d1bc13e0b15d13a330586190932a3c4c7887b72f", "price_changes": [{"asset_id": "113435897598335750012134454342623244279140769314836288769122310705258616530095", "price": "0.65", "size": "120", "side": "BUY", "hash": "d049b4676316e30ab2c8c73bd84ce7fb07ef8eca", "best_bid": "0.89", "best_ask": "0.94"}, {"asset_id": "43860483933578174366905172776039394809444972860267197366014959631913892252602", "price": "0.35", "size": "120", "side": "SELL", "hash": "dae00d0901699e55ef946789c76991ec04be8ff5", "best_bid": "0.06", "best_ask": "0.11"}], "timestamp": "1769384717991", "event_type": "price_change"}}
{"_local_timestamp": "2026-01-25T23:45:18.087091+00:00", "data": {"market": "0xebd6b4d15beed0a4a3a274d6d1bc13e0b15d13a330586190932a3c4c7887b72f", "price_changes": [{"asset_id": "113435897598335750012134454342623244279140769314836288769122310705258616530095", "price": "0.77", "size": "100", "side": "BUY", "hash": "deff09ba30f7e19b6b1af62b5290687aba057b9d", "best_bid": "0.89", "best_ask": "0.94"}, {"asset_id": "43860483933578174366905172776039394809444972860267197366014959631913892252602", "price": "0.23", "size": "100", "side": "SELL", "hash": "d52eed412e6756f2de98a6ebab9ef487c676f969", "best_bid": "0.06", "best_ask": "0.11"}], "timestamp": "1769384718021", "event_type": "price_change"}}
{"_local_timestamp": "2026-01-25T23:45:18.118107+00:00", "data": {"market": "0x715dc274a5c7adf3771646e36d5e3a8844163dc31e7f02331eb30d2b8108bf9e", "price_changes": [{"asset_id": "19458454719947582257633203202425613630572016962838703318400930704175824104136", "price": "0.26", "size": "100", "side": "BUY", "hash": "1e446953efcfcb965b6b52d7c71d7d44ddfb1b64", "best_bid": "0.58", "best_ask": "0.62"}, {"asset_id": "817582445527276447057755966542888616081641371741603398122454732956499627950", "price": "0.74", "size": "100", "side": "SELL", "hash": "1bc6f0f18968787e01d4415639f5f5745d6da415", "best_bid": "0.38", "best_ask": "0.42"}], "timestamp": "1769384718056", "event_type": "price_change"}}
{"_local_timestamp": "2026-01-25T23:45:18.120034+00:00", "data": {"market": "0x715dc274a5c7adf3771646e36d5e3a8844163dc31e7f02331eb30d2b8108bf9e", "price_changes": [{"asset_id": "19458454719947582257633203202425613630572016962838703318400930704175824104136", "price": "0.42", "size": "100", "side": "BUY", "hash": "e711c9985e959ae6d02d4d0f392fb76328c3f348", "best_bid": "0.58", "best_ask": "0.62"}, {"asset_id": "817582445527276447057755966542888616081641371741603398122454732956499627950", "price": "0.58", "size": "100", "side": "SELL", "hash": "3f605a5a57f78408e00e5110467e78310ea4c4b3", "best_bid": "0.38", "best_ask": "0.42"}], "timestamp": "1769384718058", "event_type": "price_change"}}
{"_local_timestamp": "2026-01-25T23:45:18.202842+00:00", "data": {"market": "0x715dc274a5c7adf3771646e36d5e3a8844163dc31e7f02331eb30d2b8108bf9e", "price_changes": [{"asset_id": "817582445527276447057755966542888616081641371741603398122454732956499627950", "price": "0.39", "size": "111.65", "side": "BUY", "hash": "2977217218415842e167fc879ec317f9c4ee390e", "best_bid": "0.39", "best_ask": "0.42"}, {"asset_id": "19458454719947582257633203202425613630572016962838703318400930704175824104136", "price": "0.61", "size": "111.65", "side": "SELL", "hash": "d37c79be80f0594185bb5b29b1ffc3eb23a6512c", "best_bid": "0.58", "best_ask": "0.61"}], "timestamp": "1769384718063", "event_type": "price_change"}}
{"_local_timestamp": "2026-01-25T23:45:18.203238+00:00", "data": {"market": "0x715dc274a5c7adf3771646e36d5e3a8844163dc31e7f02331eb30d2b8108bf9e", "price_changes": [{"asset_id": "19458454719947582257633203202425613630572016962838703318400930704175824104136", "price": "0.29", "size": "0", "side": "BUY", "hash": "e37f8bea0b464befd64ce1502fa4f9ef7d220aa2", "best_bid": "0.58", "best_ask": "0.61"}, {"asset_id": "817582445527276447057755966542888616081641371741603398122454732956499627950", "price": "0.71", "size": "0", "side": "SELL", "hash": "2098b39d2eafe805edd62e92df7aad6f8097a552", "best_bid": "0.39", "best_ask": "0.42"}], "timestamp": "1769384718084", "event_type": "price_change"}}
{"_local_timestamp": "2026-01-25T23:45:18.203524+00:00", "data": {"market": "0x715dc274a5c7adf3771646e36d5e3a8844163dc31e7f02331eb30d2b8108bf9e", "price_changes": [{"asset_id": "817582445527276447057755966542888616081641371741603398122454732956499627950", "price": "0.19", "size": "0", "side": "BUY", "hash": "1cc871ab56e7a4d4a25321f6f268b738c2fb5caf", "best_bid": "0.39", "best_ask": "0.42"}, {"asset_id": "19458454719947582257633203202425613630572016962838703318400930704175824104136", "price": "0.81", "size": "0", "side": "SELL", "hash": "9adfa83fcc80102966d1bff567cf62a994e2c9f6", "best_bid": "0.58", "best_ask": "0.61"}], "timestamp": "1769384718085", "event_type": "price_change"}}
{"_local_timestamp": "2026-01-25T23:45:18.203787+00:00", "data": {"market": "0x715dc274a5c7adf3771646e36d5e3a8844163dc31e7f02331eb30d2b8108bf9e", "price_changes": [{"asset_id": "817582445527276447057755966542888616081641371741603398122454732956499627950", "price": "0.28", "size": "0", "side": "BUY", "hash": "11f4141931d9bd3a5cec3d12d397d2e34ab66699", "best_bid": "0.39", "best_ask": "0.42"}, {"asset_id": "19458454719947582257633203202425613630572016962838703318400930704175824104136", "price": "0.72", "size": "0", "side": "SELL", "hash": "d922e22f931af2beaddc92b81ab0dc9c6902bbbc", "best_bid": "0.58", "best_ask": "0.61"}], "timestamp": "1769384718092", "event_type": "price_change"}}
{"_local_timestamp": "2026-01-25T23:45:18.219153+00:00", "data": {"market": "0x715dc274a5c7adf3771646e36d5e3a8844163dc31e7f02331eb30d2b8108bf9e", "price_changes": [{"asset_id": "19458454719947582257633203202425613630572016962838703318400930704175824104136", "price": "0.43", "size": "72", "side": "BUY", "hash": "7b497f7dfa628ed0e27c84c05252b6b9008190c3", "best_bid": "0.58", "best_ask": "0.61"}, {"asset_id": "817582445527276447057755966542888616081641371741603398122454732956499627950", "price": "0.57", "size": "72", "side": "SELL", "hash": "2137b1128bb230d49f33c9959fe27a3d386f431d", "best_bid": "0.39", "best_ask": "0.42"}], "timestamp": "1769384718110", "event_type": "price_change"}}
{"_local_timestamp": "2026-01-25T23:45:18.219450+00:00", "data": {"market": "0x715dc274a5c7adf3771646e36d5e3a8844163dc31e7f02331eb30d2b8108bf9e", "price_changes": [{"asset_id": "817582445527276447057755966542888616081641371741603398122454732956499627950", "price": "0.3", "size": "147", "side": "BUY", "hash": "7ed4010325dbb6227cd1a0217d27c6adc74bd859", "best_bid": "0.39", "best_ask": "0.42"}, {"asset_id": "19458454719947582257633203202425613630572016962838703318400930704175824104136", "price": "0.7", "size": "147", "side": "SELL", "hash": "91ad5724233e6316e5fa77f0c46ea99082e417db", "best_bid": "0.58", "best_ask": "0.61"}], "timestamp": "1769384718120", "event_type": "price_change"}}
{"_local_timestamp": "2026-01-25T23:45:18.219701+00:00", "data": {"market": "0x715dc274a5c7adf3771646e36d5e3a8844163dc31e7f02331eb30d2b8108bf9e", "price_changes": [{"asset_id": "817582445527276447057755966542888616081641371741603398122454732956499627950", "price": "0.13", "size": "50", "side": "BUY", "hash": "5f34d7ac574123537faf8b7da85e083a215d6138", "best_bid": "0.39", "best_ask": "0.42"}, {"asset_id": "19458454719947582257633203202425613630572016962838703318400930704175824104136", "price": "0.87", "size": "50", "side": "SELL", "hash": "c59db2fe678134414852f874ad0efc153d1e49de", "best_bid": "0.58", "best_ask": "0.61"}], "timestamp": "1769384718125", "event_type": "price_change"}}
{"_local_timestamp": "2026-01-25T23:45:18.254949+00:00", "data": {"market": "0x715dc274a5c7adf3771646e36d5e3a8844163dc31e7f02331eb30d2b8108bf9e", "price_changes": [{"asset_id": "817582445527276447057755966542888616081641371741603398122454732956499627950", "price": "0.09", "size": "371.03", "side": "BUY", "hash": "a9d91ccf8ffd4ec11d9dc2f5ca72ad3d5c020741", "best_bid": "0.39", "best_ask": "0.42"}, {"asset_id": "19458454719947582257633203202425613630572016962838703318400930704175824104136", "price": "0.91", "size": "371.03", "side": "SELL", "hash": "2769f2f49a179f17ca279a05d8fddb733988725a", "best_bid": "0.58", "best_ask": "0.61"}], "timestamp": "1769384718126", "event_type": "price_change"}}
{"_local_timestamp": "2026-01-25T23:45:18.304552+00:00", "data": {"market": "0xebd6b4d15beed0a4a3a274d6d1bc13e0b15d13a330586190932a3c4c7887b72f", "price_changes": [{"asset_id": "113435897598335750012134454342623244279140769314836288769122310705258616530095", "price": "0.88", "size": "0", "side": "BUY", "hash": "4abb086b595f4f7770219e70d58a8266323bd7e5", "best_bid": "0.89", "best_ask": "0.94"}, {"asset_id": "43860483933578174366905172776039394809444972860267197366014959631913892252602", "price": "0.12", "size": "0", "side": "SELL", "hash": "ab3740735b14d485f18bba61d027fbdeb6cf7ca7", "best_bid": "0.06", "best_ask": "0.11"}], "timestamp": "1769384718228", "event_type": "price_change"}}
{"_local_timestamp": "2026-01-25T23:45:18.354973+00:00", "data": {"market": "0xebd6b4d15beed0a4a3a274d6d1bc13e0b15d13a330586190932a3c4c7887b72f", "price_changes": [{"asset_id": "113435897598335750012134454342623244279140769314836288769122310705258616530095", "price": "0.85", "size": "130", "side": "BUY", "hash": "262c78176b15f95a18f918947e626bc3beb10c18", "best_bid": "0.89", "best_ask": "0.94"}, {"asset_id": "43860483933578174366905172776039394809444972860267197366014959631913892252602", "price": "0.15", "size": "130", "side": "SELL", "hash": "074ee58ad2813227b30604fac3d069776e0cd07a", "best_bid": "0.06", "best_ask": "0.11"}], "timestamp": "1769384718282", "event_type": "price_change"}}
{"_local_timestamp": "2026-01-25T23:45:19.162402+00:00", "data": {"market": "0xebd6b4d15beed0a4a3a274d6d1bc13e0b15d13a330586190932a3c4c7887b72f", "price_changes": [{"asset_id": "113435897598335750012134454342623244279140769314836288769122310705258616530095", "price": "0.65", "size": "100", "side": "BUY", "hash": "4157f3cb53cafc79e23a1f777748f19444405c16", "best_bid": "0.89", "best_ask": "0.94"}, {"asset_id": "43860483933578174366905172776039394809444972860267197366014959631913892252602", "price": "0.35", "size": "100", "side": "SELL", "hash": "f058b1994b36b0c0d04185e25797917ed04b7850", "best_bid": "0.06", "best_ask": "0.11"}], "timestamp": "1769384719058", "event_type": "price_change"}}
{"_local_timestamp": "2026-01-25T23:45:19.172584+00:00", "data": {"market": "0xebd6b4d15beed0a4a3a274d6d1bc13e0b15d13a330586190932a3c4c7887b72f", "price_changes": [{"asset_id": "113435897598335750012134454342623244279140769314836288769122310705258616530095", "price": "0.66", "size": "20", "side": "BUY", "hash": "410b677ac298a3d53e1b233a1cfc1e7fca2c7be1", "best_bid": "0.89", "best_ask": "0.94"}, {"asset_id": "43860483933578174366905172776039394809444972860267197366014959631913892252602", "price": "0.34", "size": "20", "side": "SELL", "hash": "856783a325bc1ce527f9071f9ea23cef69515c35", "best_bid": "0.06", "best_ask": "0.11"}], "timestamp": "1769384719084", "event_type": "price_change"}}
{"_local_timestamp": "2026-01-25T23:45:19.630532+00:00", "data": {"market": "0xebd6b4d15beed0a4a3a274d6d1bc13e0b15d13a330586190932a3c4c7887b72f", "price_changes": [{"asset_id": "113435897598335750012134454342623244279140769314836288769122310705258616530095", "price": "0.85", "size": "100", "side": "BUY", "hash": "ef53105c28ab48b9cdf86ff92fbfbc3358c3c7b8", "best_bid": "0.89", "best_ask": "0.94"}, {"asset_id": "43860483933578174366905172776039394809444972860267197366014959631913892252602", "price": "0.15", "size": "100", "side": "SELL", "hash": "e55ec6a4799870013957359c158a8877456d6d78", "best_bid": "0.06", "best_ask": "0.11"}], "timestamp": "1769384719552", "event_type": "price_change"}}
{"_local_timestamp": "2026-01-25T23:45:24.536514+00:00", "data": {"market": "0x715dc274a5c7adf3771646e36d5e3a8844163dc31e7f02331eb30d2b8108bf9e", "price_changes": [{"asset_id": "817582445527276447057755966542888616081641371741603398122454732956499627950", "price": "0.29", "size": "0", "side": "BUY", "hash": "14c47d0dac984d9dc6282e95683756194008255e", "best_bid": "0.39", "best_ask": "0.42"}, {"asset_id": "19458454719947582257633203202425613630572016962838703318400930704175824104136", "price": "0.71", "size": "0", "side": "SELL", "hash": "0a18a44f40e60ef391105e4401797566fb417c0b", "best_bid": "0.58", "best_ask": "0.61"}], "timestamp": "1769384724458", "event_type": "price_change"}}
{"_local_timestamp": "2026-01-25T23:45:24.580701+00:00", "data": {"market": "0x715dc274a5c7adf3771646e36d5e3a8844163dc31e7f02331eb30d2b8108bf9e", "price_changes": [{"asset_id": "817582445527276447057755966542888616081641371741603398122454732956499627950", "price": "0.19", "size": "20", "side": "BUY", "hash": "15c2dd3412e21d6c2871c4f014bd53e427b36036", "best_bid": "0.39", "best_ask": "0.42"}, {"asset_id": "19458454719947582257633203202425613630572016962838703318400930704175824104136", "price": "0.81", "size": "20", "side": "SELL", "hash": "cc4a447182e7cd3bceab96d46f4ad88979826c34", "best_bid": "0.58", "best_ask": "0.61"}], "timestamp": "1769384724496", "event_type": "price_change"}}
{"_local_timestamp": "2026-01-25T23:45:24.581213+00:00", "data": {"market": "0x715dc274a5c7adf3771646e36d5e3a8844163dc31e7f02331eb30d2b8108bf9e", "price_changes": [{"asset_id": "817582445527276447057755966542888616081641371741603398122454732956499627950", "price": "0.3", "size": "0", "side": "BUY", "hash": "1839e44d8726603efe9dc438a7fa1de7751bb97c", "best_bid": "0.39", "best_ask": "0.42"}, {"asset_id": "19458454719947582257633203202425613630572016962838703318400930704175824104136", "price": "0.7", "size": "0", "side": "SELL", "hash": "71d8ecc4bb236dad7d7a8325c2fcb54b4581cae8", "best_bid": "0.58", "best_ask": "0.61"}], "timestamp": "1769384724496", "event_type": "price_change"}}
{"_local_timestamp": "2026-01-25T23:45:24.601684+00:00", "data": {"market": "0x715dc274a5c7adf3771646e36d5e3a8844163dc31e7f02331eb30d2b8108bf9e", "price_changes": [{"asset_id": "817582445527276447057755966542888616081641371741603398122454732956499627950", "price": "0.28", "size": "152", "side": "BUY", "hash": "6537d0ac98dbefabb97ec1427a21ef7adffe9a55", "best_bid": "0.39", "best_ask": "0.42"}, {"asset_id": "19458454719947582257633203202425613630572016962838703318400930704175824104136", "price": "0.72", "size": "152", "side": "SELL", "hash": "305236d4e3fabdf6a9c947fd2faa8021505dac40", "best_bid": "0.58", "best_ask": "0.61"}], "timestamp": "1769384724524", "event_type": "price_change"}}
{"_local_timestamp": "2026-01-25T23:45:34.814794+00:00", "data": {"market": "0x715dc274a5c7adf3771646e36d5e3a8844163dc31e7f02331eb30d2b8108bf9e", "price_changes": [{"asset_id": "817582445527276447057755966542888616081641371741603398122454732956499627950", "price": "0.07", "size": "1385.71", "side": "BUY", "hash": "cec58c9e32e5f4870d7dbde80374835278747a94", "best_bid": "0.39", "best_ask": "0.42"}, {"asset_id": "19458454719947582257633203202425613630572016962838703318400930704175824104136", "price": "0.93", "size": "1385.71", "side": "SELL", "hash": "413a7c06cea99be6ba044b0042b726f1a8957420", "best_bid": "0.58", "best_ask": "0.61"}], "timestamp": "1769384734745", "event_type": "price_change"}}
{"_local_timestamp": "2026-01-25T23:45:34.834506+00:00", "data": {"market": "0x715dc274a5c7adf3771646e36d5e3a8844163dc31e7f02331eb30d2b8108bf9e", "price_changes": [{"asset_id": "817582445527276447057755966542888616081641371741603398122454732956499627950", "price": "0.19", "size": "0", "side": "BUY", "hash": "2d63d1929b06a4d274bfb23efbd29ebe5c3c8071", "best_bid": "0.39", "best_ask": "0.42"}, {"asset_id": "19458454719947582257633203202425613630572016962838703318400930704175824104136", "price": "0.81", "size": "0", "side": "SELL", "hash": "1c7c7654b80405cc149c73667a8c16b4b7286dd7", "best_bid": "0.58", "best_ask": "0.61"}], "timestamp": "1769384734768", "event_type": "price_change"}}
{"_local_timestamp": "2026-01-25T23:45:36.043698+00:00", "data": {"market": "0x29d688e8ee4dc83cff27ce5d583553be477b4202aba945dff96730aa88397071", "price_changes": [{"asset_id": "22395241560984864794587761975509529149656370897276070318169938852205137917866", "price": "0.57", "size": "10", "side": "BUY", "hash": "7c97c109d910ce3f2f3bb134f8d295fe07dd1c95", "best_bid": "0.8", "best_ask": "0.95"}, {"asset_id": "46123672832602976783793170370598938766981479048132054420648285300054482204701", "price": "0.43", "size": "10", "side": "SELL", "hash": "64f8c720a44c7235a2ba81fd79d404764a88f19e", "best_bid": "0.05", "best_ask": "0.2"}], "timestamp": "1769384735975", "event_type": "price_change"}}
{"_local_timestamp": "2026-01-25T23:45:36.881054+00:00", "data": {"market": "0x29d688e8ee4dc83cff27ce5d583553be477b4202aba945dff96730aa88397071", "price_changes": [{"asset_id": "46123672832602976783793170370598938766981479048132054420648285300054482204701", "price": "0.42", "size": "0", "side": "SELL", "hash": "78ed5de26f624db2f016914bc9101a08c84a776e", "best_bid": "0.05", "best_ask": "0.2"}, {"asset_id": "22395241560984864794587761975509529149656370897276070318169938852205137917866", "price": "0.58", "size": "0", "side": "BUY", "hash": "3bddbf184fbc0cb99b98aa7463fb3187eec9e691", "best_bid": "0.8", "best_ask": "0.95"}], "timestamp": "1769384736813", "event_type": "price_change"}}
{"_local_timestamp": "2026-01-25T23:45:36.950873+00:00", "data": {"market": "0x29d688e8ee4dc83cff27ce5d583553be477b4202aba945dff96730aa88397071", "price_changes": [{"asset_id": "46123672832602976783793170370598938766981479048132054420648285300054482204701", "price": "0.57", "size": "20", "side": "SELL", "hash": "771d160990b46a19cd78f9e21d97e08a6d10a05c", "best_bid": "0.05", "best_ask": "0.2"}, {"asset_id": "22395241560984864794587761975509529149656370897276070318169938852205137917866", "price": "0.43", "size": "20", "side": "BUY", "hash": "3ac1deebd83f00e3a33d22fdae72ce6aab556fbe", "best_bid": "0.8", "best_ask": "0.95"}], "timestamp": "1769384736884", "event_type": "price_change"}}
{"_local_timestamp": "2026-01-25T23:45:37.565356+00:00", "data": {"market": "0x29d688e8ee4dc83cff27ce5d583553be477b4202aba945dff96730aa88397071", "price_changes": [{"asset_id": "22395241560984864794587761975509529149656370897276070318169938852205137917866", "price": "0.59", "size": "0", "side": "BUY", "hash": "1a5c213359fb38bc3b0de63be7a58bd5e6183217", "best_bid": "0.8", "best_ask": "0.95"}, {"asset_id": "46123672832602976783793170370598938766981479048132054420648285300054482204701", "price": "0.41", "size": "0", "side": "SELL", "hash": "e3b1c53cc71a46b668b5fb2d2fb621bd0cdf4740", "best_bid": "0.05", "best_ask": "0.2"}], "timestamp": "1769384737501", "event_type": "price_change"}}
{"_local_timestamp": "2026-01-25T23:45:37.594967+00:00", "data": {"market": "0x29d688e8ee4dc83cff27ce5d583553be477b4202aba945dff96730aa88397071", "price_changes": [{"asset_id": "22395241560984864794587761975509529149656370897276070318169938852205137917866", "price": "0.58", "size": "20", "side": "BUY", "hash": "3ce617b5da1b37892db180ea0fab3a2decc7b200", "best_bid": "0.8", "best_ask": "0.95"}, {"asset_id": "46123672832602976783793170370598938766981479048132054420648285300054482204701", "price": "0.42", "size": "20", "side": "SELL", "hash": "ddd157af96ad1570d57e60b75837f9ab646d53c8", "best_bid": "0.05", "best_ask": "0.2"}], "timestamp": "1769384737528", "event_type": "price_change"}}
{"_local_timestamp": "2026-01-25T23:45:53.278415+00:00", "data": {"market": "0xebd6b4d15beed0a4a3a274d6d1bc13e0b15d13a330586190932a3c4c7887b72f", "price_changes": [{"asset_id": "113435897598335750012134454342623244279140769314836288769122310705258616530095", "price": "0.13", "size": "200", "side": "BUY", "hash": "aa6f17d8628dd72a66755105f491417c4f8c530c", "best_bid": "0.89", "best_ask": "0.94"}, {"asset_id": "43860483933578174366905172776039394809444972860267197366014959631913892252602", "price": "0.87", "size": "200", "side": "SELL", "hash": "07df764810fecfc2b049a307f43fe5e4cd628a20", "best_bid": "0.06", "best_ask": "0.11"}], "timestamp": "1769384753030", "event_type": "price_change"}}
{"_local_timestamp": "2026-01-25T23:45:53.642444+00:00", "data": {"market": "0x715dc274a5c7adf3771646e36d5e3a8844163dc31e7f02331eb30d2b8108bf9e", "price_changes": [{"asset_id": "19458454719947582257633203202425613630572016962838703318400930704175824104136", "price": "0.12", "size": "431.66", "side": "BUY", "hash": "f24acdbcae8769af00304da21ee33e989cc51565", "best_bid": "0.58", "best_ask": "0.61"}, {"asset_id": "817582445527276447057755966542888616081641371741603398122454732956499627950", "price": "0.88", "size": "431.66", "side": "SELL", "hash": "fd745c81382c385f1560d8da0595441a5b1c71e6", "best_bid": "0.39", "best_ask": "0.42"}], "timestamp": "1769384753516", "event_type": "price_change"}}
{"_local_timestamp": "2026-01-25T23:45:53.643159+00:00", "data": {"market": "0xfb08a969a2c05beda8b5743959182db28be71832f9a84872a786e809b77b5350", "price_changes": [{"asset_id": "13908252531396871469657521961663517650827376216919668668811621820614371209132", "price": "0.231", "size": "400", "side": "BUY", "hash": "9a89682b78c48da8b905cf21f65eee2e5a9a6829", "best_bid": "0.842", "best_ask": "0.974"}, {"asset_id": "28670530274590253141384619337562139640467932392972183997943459931027267172276", "price": "0.769", "size": "400", "side": "SELL", "hash": "8fae1f6c2e0f9f10b76427d37ecd06eff45260d1", "best_bid": "0.026", "best_ask": "0.158"}], "timestamp": "1769384753516", "event_type": "price_change"}}
{"_local_timestamp": "2026-01-25T23:45:53.731052+00:00", "data": {"market": "0xebd6b4d15beed0a4a3a274d6d1bc13e0b15d13a330586190932a3c4c7887b72f", "price_changes": [{"asset_id": "113435897598335750012134454342623244279140769314836288769122310705258616530095", "price": "0.14", "size": "367.85", "side": "BUY", "hash": "e4b0c7f6551cb9e9e3d2e95483cba55f0023624f", "best_bid": "0.89", "best_ask": "0.94"}, {"asset_id": "43860483933578174366905172776039394809444972860267197366014959631913892252602", "price": "0.86", "size": "367.85", "side": "SELL", "hash": "ab4e946d7755b4715f0664ff904baae7a4d5f920", "best_bid": "0.06", "best_ask": "0.11"}], "timestamp": "1769384753534", "event_type": "price_change"}}
{"_local_timestamp": "2026-01-25T23:45:53.750188+00:00", "data": {"market": "0xfb08a969a2c05beda8b5743959182db28be71832f9a84872a786e809b77b5350", "price_changes": [{"asset_id": "13908252531396871469657521961663517650827376216919668668811621820614371209132", "price": "0.17", "size": "800", "side": "BUY", "hash": "d7752102f7a9c33a50e0111069620b7b39833797", "best_bid": "0.842", "best_ask": "0.974"}, {"asset_id": "28670530274590253141384619337562139640467932392972183997943459931027267172276", "price": "0.83", "size": "800", "side": "SELL", "hash": "bdc87f567cc5f67b0d2d8ff17215e925d9fd6c59", "best_bid": "0.026", "best_ask": "0.158"}], "timestamp": "1769384753547", "event_type": "price_change"}}
{"_local_timestamp": "2026-01-25T23:45:53.752941+00:00", "data": {"market": "0x715dc274a5c7adf3771646e36d5e3a8844163dc31e7f02331eb30d2b8108bf9e", "price_changes": [{"asset_id": "19458454719947582257633203202425613630572016962838703318400930704175824104136", "price": "0.19", "size": "236.84", "side": "BUY", "hash": "98bcafe74bc9c00bb2b123f599813d383e7412fb", "best_bid": "0.58", "best_ask": "0.61"}, {"asset_id": "817582445527276447057755966542888616081641371741603398122454732956499627950", "price": "0.81", "size": "236.84", "side": "SELL", "hash": "11fe2656bd085e7b8ceb5da8e4b8a11f30a75330", "best_bid": "0.39", "best_ask": "0.42"}], "timestamp": "1769384753547", "event_type": "price_change"}}
{"_local_timestamp": "2026-01-25T23:45:53.755207+00:00", "data": {"market": "0xfb08a969a2c05beda8b5743959182db28be71832f9a84872a786e809b77b5350", "price_changes": [{"asset_id": "13908252531396871469657521961663517650827376216919668668811621820614371209132", "price": "0.13", "size": "386.53", "side": "BUY", "hash": "11c8902d69cda09ba461da61fdac10fa698cbd53", "best_bid": "0.842", "best_ask": "0.974"}, {"asset_id": "28670530274590253141384619337562139640467932392972183997943459931027267172276", "price": "0.87", "size": "386.53", "side": "SELL", "hash": "c091248c11a74ed0dbe1ae7c0cbfd330f3a6d361", "best_bid": "0.026", "best_ask": "0.158"}], "timestamp": "1769384753562", "event_type": "price_change"}}
{"_local_timestamp": "2026-01-25T23:45:53.786621+00:00", "data": {"market": "0x715dc274a5c7adf3771646e36d5e3a8844163dc31e7f02331eb30d2b8108bf9e", "price_changes": [{"asset_id": "19458454719947582257633203202425613630572016962838703318400930704175824104136", "price": "0.43", "size": "0", "side": "BUY", "hash": "c82e83155e2b5f8c4e8b6eabda9c59d7d8f81866", "best_bid": "0.58", "best_ask": "0.61"}, {"asset_id": "817582445527276447057755966542888616081641371741603398122454732956499627950", "price": "0.57", "size": "0", "side": "SELL", "hash": "2a400eac991d4c4705e53ec1be4db69acc47ae62", "best_bid": "0.39", "best_ask": "0.42"}], "timestamp": "1769384753709", "event_type": "price_change"}}
{"_local_timestamp": "2026-01-25T23:45:53.804810+00:00", "data": {"market": "0x715dc274a5c7adf3771646e36d5e3a8844163dc31e7f02331eb30d2b8108bf9e", "price_changes": [{"asset_id": "19458454719947582257633203202425613630572016962838703318400930704175824104136", "price": "0.43", "size": "120", "side": "BUY", "hash": "1ed1a7571b86b750219b036174e4d5edaf1c8f33", "best_bid": "0.58", "best_ask": "0.61"}, {"asset_id": "817582445527276447057755966542888616081641371741603398122454732956499627950", "price": "0.57", "size": "120", "side": "SELL", "hash": "8e2f52e405b27c015287261032af0710d29f68f2", "best_bid": "0.39", "best_ask": "0.42"}], "timestamp": "1769384753737", "event_type": "price_change"}}
{"_local_timestamp": "2026-01-25T23:45:53.994247+00:00", "data": {"market": "0x715dc274a5c7adf3771646e36d5e3a8844163dc31e7f02331eb30d2b8108bf9e", "price_changes": [{"asset_id": "817582445527276447057755966542888616081641371741603398122454732956499627950", "price": "0.07", "size": "685.71", "side": "BUY", "hash": "c16986601bc4287d2c39d3174864e75e67c88562", "best_bid": "0.39", "best_ask": "0.42"}, {"asset_id": "19458454719947582257633203202425613630572016962838703318400930704175824104136", "price": "0.93", "size": "685.71", "side": "SELL", "hash": "6f6d1b66b69d2c9eba61b4649f03170b1e9505ad", "best_bid": "0.58", "best_ask": "0.61"}], "timestamp": "1769384753930", "event_type": "price_change"}}
{"_local_timestamp": "2026-01-25T23:45:56.651139+00:00", "data": {"market": "0x29d688e8ee4dc83cff27ce5d583553be477b4202aba945dff96730aa88397071", "price_changes": [{"asset_id": "22395241560984864794587761975509529149656370897276070318169938852205137917866", "price": "0.25", "size": "0", "side": "BUY", "hash": "9b6cb1936ded0d4273f0f2d115d1321988c2a970", "best_bid": "0.8", "best_ask": "0.95"}, {"asset_id": "46123672832602976783793170370598938766981479048132054420648285300054482204701", "price": "0.75", "size": "0", "side": "SELL", "hash": "241e47e33cc446818e3e7b8d69dde649a297f6c5", "best_bid": "0.05", "best_ask": "0.2"}], "timestamp": "1769384756092", "event_type": "price_change"}}
{"_local_timestamp": "2026-01-25T23:45:56.785397+00:00", "data": {"market": "0xfb08a969a2c05beda8b5743959182db28be71832f9a84872a786e809b77b5350", "price_changes": [{"asset_id": "13908252531396871469657521961663517650827376216919668668811621820614371209132", "price": "0.231", "size": "150", "side": "BUY", "hash": "02e12e24faac37fb03212c1409a254a48930fd18", "best_bid": "0.842", "best_ask": "0.974"}, {"asset_id": "28670530274590253141384619337562139640467932392972183997943459931027267172276", "price": "0.769", "size": "150", "side": "SELL", "hash": "32247c21df313c9248e63633740d2863d3c5db62", "best_bid": "0.026", "best_ask": "0.158"}], "timestamp": "1769384756090", "event_type": "price_change"}}
{"_local_timestamp": "2026-01-25T23:46:02.984941+00:00", "data": {"market": "0x715dc274a5c7adf3771646e36d5e3a8844163dc31e7f02331eb30d2b8108bf9e", "price_changes": [{"asset_id": "817582445527276447057755966542888616081641371741603398122454732956499627950", "price": "0.09", "size": "401.35", "side": "BUY", "hash": "8e7187025bb2ca6a7baada0b6fff24e7090181fe", "best_bid": "0.39", "best_ask": "0.42"}, {"asset_id": "19458454719947582257633203202425613630572016962838703318400930704175824104136", "price": "0.91", "size": "401.35", "side": "SELL", "hash": "fd3adaa8ef648f616575fe258d63407758215ea1", "best_bid": "0.58", "best_ask": "0.61"}], "timestamp": "1769384762906", "event_type": "price_change"}}
{"_local_timestamp": "2026-01-25T23:46:11.417608+00:00", "data": {"market": "0x29d688e8ee4dc83cff27ce5d583553be477b4202aba945dff96730aa88397071", "price_changes": [{"asset_id": "22395241560984864794587761975509529149656370897276070318169938852205137917866", "price": "0.19", "size": "78", "side": "BUY", "hash": "5c6d5d284f73c994076e2cac0404d175c789b879", "best_bid": "0.8", "best_ask": "0.95"}, {"asset_id": "46123672832602976783793170370598938766981479048132054420648285300054482204701", "price": "0.81", "size": "78", "side": "SELL", "hash": "56f17a1ca21563da6acae89cd81384eac95b3978", "best_bid": "0.05", "best_ask": "0.2"}], "timestamp": "1769384771349", "event_type": "price_change"}}
{"_local_timestamp": "2026-01-25T23:46:11.417970+00:00", "data": {"market": "0xfb08a969a2c05beda8b5743959182db28be71832f9a84872a786e809b77b5350", "price_changes": [{"asset_id": "13908252531396871469657521961663517650827376216919668668811621820614371209132", "price": "0.311", "size": "38", "side": "BUY", "hash": "9f5b29d557f30c1809da99a02aae0beda1447482", "best_bid": "0.842", "best_ask": "0.974"}, {"asset_id": "28670530274590253141384619337562139640467932392972183997943459931027267172276", "price": "0.689", "size": "38", "side": "SELL", "hash": "cd41b7c8a2a6b2ee88344ff11a9e51002ab6eae6", "best_bid": "0.026", "best_ask": "0.158"}], "timestamp": "1769384771349", "event_type": "price_change"}}
{"_local_timestamp": "2026-01-25T23:46:17.063941+00:00", "data": {"market": "0x715dc274a5c7adf3771646e36d5e3a8844163dc31e7f02331eb30d2b8108bf9e", "price_changes": [{"asset_id": "817582445527276447057755966542888616081641371741603398122454732956499627950", "price": "0.07", "size": "485.71", "side": "BUY", "hash": "d6cc95d24047958b117718220ef0b2b95b3e42c5", "best_bid": "0.39", "best_ask": "0.42"}, {"asset_id": "19458454719947582257633203202425613630572016962838703318400930704175824104136", "price": "0.93", "size": "485.71", "side": "SELL", "hash": "54eb725c5caa50558ec545c8da7e793c6416dbb5", "best_bid": "0.58", "best_ask": "0.61"}], "timestamp": "1769384776984", "event_type": "price_change"}}
{"_local_timestamp": "2026-01-25T23:46:17.065257+00:00", "data": {"market": "0x715dc274a5c7adf3771646e36d5e3a8844163dc31e7f02331eb30d2b8108bf9e", "price_changes": [{"asset_id": "817582445527276447057755966542888616081641371741603398122454732956499627950", "price": "0.04", "size": "2400", "side": "BUY", "hash": "d6cc95d24047958b117718220ef0b2b95b3e42c5", "best_bid": "0.39", "best_ask": "0.42"}, {"asset_id": "19458454719947582257633203202425613630572016962838703318400930704175824104136", "price": "0.96", "size": "2400", "side": "SELL", "hash": "54eb725c5caa50558ec545c8da7e793c6416dbb5", "best_bid": "0.58", "best_ask": "0.61"}], "timestamp": "1769384776984", "event_type": "price_change"}}
{"_local_timestamp": "2026-01-25T23:46:17.412197+00:00", "data": {"market": "0xfb08a969a2c05beda8b5743959182db28be71832f9a84872a786e809b77b5350", "price_changes": [{"asset_id": "13908252531396871469657521961663517650827376216919668668811621820614371209132", "price": "0.09", "size": "600", "side": "BUY", "hash": "906331709fabe60f7dcb60382869c569b066b4f8", "best_bid": "0.842", "best_ask": "0.974"}, {"asset_id": "28670530274590253141384619337562139640467932392972183997943459931027267172276", "price": "0.91", "size": "600", "side": "SELL", "hash": "365c7a71357fc9aa28e7d53c52f1d07d390aa98a", "best_bid": "0.026", "best_ask": "0.158"}], "timestamp": "1769384777324", "event_type": "price_change"}}
{"_local_timestamp": "2026-01-25T23:46:33.656180+00:00", "data": {"market": "0x715dc274a5c7adf3771646e36d5e3a8844163dc31e7f02331eb30d2b8108bf9e", "price_changes": [{"asset_id": "817582445527276447057755966542888616081641371741603398122454732956499627950", "price": "0.05", "size": "30", "side": "BUY", "hash": "e5d1be927eb70d09d548685a620d4e63e3f56340", "best_bid": "0.39", "best_ask": "0.42"}, {"asset_id": "19458454719947582257633203202425613630572016962838703318400930704175824104136", "price": "0.95", "size": "30", "side": "SELL", "hash": "b55a7a42e31d95f5db9a08eddd90ccf0aa39e3e5", "best_bid": "0.58", "best_ask": "0.61"}], "timestamp": "1769384793576", "event_type": "price_change"}}
{"_local_timestamp": "2026-01-25T23:46:33.656528+00:00", "data": {"market": "0x715dc274a5c7adf3771646e36d5e3a8844163dc31e7f02331eb30d2b8108bf9e", "price_changes": [{"asset_id": "817582445527276447057755966542888616081641371741603398122454732956499627950", "price": "0.09", "size": "395.87", "side": "BUY", "hash": "e5d1be927eb70d09d548685a620d4e63e3f56340", "best_bid": "0.39", "best_ask": "0.42"}, {"asset_id": "19458454719947582257633203202425613630572016962838703318400930704175824104136", "price": "0.91", "size": "395.87", "side": "SELL", "hash": "b55a7a42e31d95f5db9a08eddd90ccf0aa39e3e5", "best_bid": "0.58", "best_ask": "0.61"}], "timestamp": "1769384793576", "event_type": "price_change"}}
{"_local_timestamp": "2026-01-25T23:46:34.559178+00:00", "data": {"market": "0x715dc274a5c7adf3771646e36d5e3a8844163dc31e7f02331eb30d2b8108bf9e", "price_changes": [{"asset_id": "817582445527276447057755966542888616081641371741603398122454732956499627950", "price": "0.08", "size": "7.05", "side": "BUY", "hash": "86d1885d2b3092dc252da0975337c068bbd346a3", "best_bid": "0.39", "best_ask": "0.42"}, {"asset_id": "19458454719947582257633203202425613630572016962838703318400930704175824104136", "price": "0.92", "size": "7.05", "side": "SELL", "hash": "199da9af6b27a83dfb95af63b34536bb861b2226", "best_bid": "0.58", "best_ask": "0.61"}], "timestamp": "1769384794487", "event_type": "price_change"}}
{"_local_timestamp": "2026-01-25T23:46:34.559544+00:00", "data": {"market": "0x715dc274a5c7adf3771646e36d5e3a8844163dc31e7f02331eb30d2b8108bf9e", "price_changes": [{"asset_id": "817582445527276447057755966542888616081641371741603398122454732956499627950", "price": "0.03", "size": "12.89", "side": "BUY", "hash": "031ae8c1a5ddb8e6817659d2f06cb112243bbbb1", "best_bid": "0.39", "best_ask": "0.42"}, {"asset_id": "19458454719947582257633203202425613630572016962838703318400930704175824104136", "price": "0.97", "size": "12.89", "side": "SELL", "hash": "f1b028a20963785bedc612f7ac17355894c8a82c", "best_bid": "0.58", "best_ask": "0.61"}], "timestamp": "1769384794488", "event_type": "price_change"}}
{"_local_timestamp": "2026-01-25T23:46:39.171375+00:00", "data": {"market": "0x29d688e8ee4dc83cff27ce5d583553be477b4202aba945dff96730aa88397071", "price_changes": [{"asset_id": "22395241560984864794587761975509529149656370897276070318169938852205137917866", "price": "0.18", "size": "150", "side": "BUY", "hash": "05ddd0baf08952c9681d407e2b2b04ba3c2b133d", "best_bid": "0.8", "best_ask": "0.95"}, {"asset_id": "46123672832602976783793170370598938766981479048132054420648285300054482204701", "price": "0.82", "size": "150", "side": "SELL", "hash": "46b49349e06128a973b303731727d78c0f2c5b83", "best_bid": "0.05", "best_ask": "0.2"}], "timestamp": "1769384799091", "event_type": "price_change"}}
{"_local_timestamp": "2026-01-25T23:46:41.535531+00:00", "data": {"market": "0x29d688e8ee4dc83cff27ce5d583553be477b4202aba945dff96730aa88397071", "price_changes": [{"asset_id": "22395241560984864794587761975509529149656370897276070318169938852205137917866", "price": "0.2", "size": "5.76", "side": "BUY", "hash": "8e680e357d4537767755817e9092b6d67a62855a", "best_bid": "0.8", "best_ask": "0.95"}, {"asset_id": "46123672832602976783793170370598938766981479048132054420648285300054482204701", "price": "0.8", "size": "5.76", "side": "SELL", "hash": "ee83b4559b48db3a1fd10c76580b6fc773d57d77", "best_bid": "0.05", "best_ask": "0.2"}], "timestamp": "1769384801465", "event_type": "price_change"}}
{"_local_timestamp": "2026-01-25T23:46:41.615669+00:00", "data": {"market": "0xfb08a969a2c05beda8b5743959182db28be71832f9a84872a786e809b77b5350", "price_changes": [{"asset_id": "13908252531396871469657521961663517650827376216919668668811621820614371209132", "price": "0.538", "size": "0", "side": "BUY", "hash": "a4e1c2e66c4f5abc3e7800c607bba22a237e4d58", "best_bid": "0.842", "best_ask": "0.974"}, {"asset_id": "28670530274590253141384619337562139640467932392972183997943459931027267172276", "price": "0.462", "size": "0", "side": "SELL", "hash": "c32834fca20b197d67c3b225fae2bc228c296612", "best_bid": "0.026", "best_ask": "0.158"}], "timestamp": "1769384801543", "event_type": "price_change"}}
{"_local_timestamp": "2026-01-25T23:46:41.810912+00:00", "data": {"market": "0xd62d0fd81efeba80c7d331577b8cfdaf89eb287a64f65f6418677f5669da4374", "price_changes": [{"asset_id": "50806857340536377589471864244012059415352637140902118853666778383891415395995", "price": "0.54", "size": "15", "side": "BUY", "hash": "e9c3069e26fd399590232fa3e838148236aa38c9", "best_bid": "0.89", "best_ask": "0.93"}, {"asset_id": "44436347575766030163252235546454470356610478743001712085002709882075518933616", "price": "0.46", "size": "15", "side": "SELL", "hash": "0bb905d26d7d3e5eb7db867427245defbcf07d60", "best_bid": "0.07", "best_ask": "0.11"}], "timestamp": "1769384801714", "event_type": "price_change"}}
{"_local_timestamp": "2026-01-25T23:46:48.358574+00:00", "data": {"market": "0x29d688e8ee4dc83cff27ce5d583553be477b4202aba945dff96730aa88397071", "price_changes": [{"asset_id": "46123672832602976783793170370598938766981479048132054420648285300054482204701", "price": "0.02", "size": "161.33", "side": "BUY", "hash": "b53c99eb9088e3e7311f95ef4d0ebbd468b48dcb", "best_bid": "0.05", "best_ask": "0.2"}, {"asset_id": "22395241560984864794587761975509529149656370897276070318169938852205137917866", "price": "0.98", "size": "161.33", "side": "SELL", "hash": "6a81050803dd67625c6c6dba1396bc02fe29f4be", "best_bid": "0.8", "best_ask": "0.95"}], "timestamp": "1769384808284", "event_type": "price_change"}}
{"_local_timestamp": "2026-01-25T23:46:48.358923+00:00", "data": {"market": "0xfb08a969a2c05beda8b5743959182db28be71832f9a84872a786e809b77b5350", "price_changes": [{"asset_id": "28670530274590253141384619337562139640467932392972183997943459931027267172276", "price": "0.025", "size": "80", "side": "BUY", "hash": "4099f8f2877b3230babec5cf6e7bc48a1c3e48cd", "best_bid": "0.026", "best_ask": "0.158"}, {"asset_id": "13908252531396871469657521961663517650827376216919668668811621820614371209132", "price": "0.975", "size": "80", "side": "SELL", "hash": "edf0e9ea4d8ea83dac53994b9b4021a6703194ab", "best_bid": "0.842", "best_ask": "0.974"}], "timestamp": "1769384808284", "event_type": "price_change"}}
{"_local_timestamp": "2026-01-25T23:46:48.439302+00:00", "data": {"market": "0x29d688e8ee4dc83cff27ce5d583553be477b4202aba945dff96730aa88397071", "price_changes": [{"asset_id": "22395241560984864794587761975509529149656370897276070318169938852205137917866", "price": "0.55", "size": "10", "side": "BUY", "hash": "bbd6bd373afacbd04aa52cf19e64a8217dfd2c8c", "best_bid": "0.8", "best_ask": "0.95"}, {"asset_id": "46123672832602976783793170370598938766981479048132054420648285300054482204701", "price": "0.45", "size": "10", "side": "SELL", "hash": "4027db98fc74b9414b468b0cd2a9df68e846e053", "best_bid": "0.05", "best_ask": "0.2"}], "timestamp": "1769384808364", "event_type": "price_change"}}
{"_local_timestamp": "2026-01-25T23:46:48.597511+00:00", "data": {"market": "0xebd6b4d15beed0a4a3a274d6d1bc13e0b15d13a330586190932a3c4c7887b72f", "price_changes": [{"asset_id": "113435897598335750012134454342623244279140769314836288769122310705258616530095", "price": "0.42", "size": "0", "side": "BUY", "hash": "6d5a132ba91116738ff4e9835fa3393b136c265d", "best_bid": "0.89", "best_ask": "0.94"}, {"asset_id": "43860483933578174366905172776039394809444972860267197366014959631913892252602", "price": "0.58", "size": "0", "side": "SELL", "hash": "a9eeee77dcf897b652178a4ab3f61e1cdbc270d4", "best_bid": "0.06", "best_ask": "0.11"}], "timestamp": "1769384808519", "event_type": "price_change"}}
{"_local_timestamp": "2026-01-25T23:46:48.660936+00:00", "data": {"market": "0xfb08a969a2c05beda8b5743959182db28be71832f9a84872a786e809b77b5350", "price_changes": [{"asset_id": "28670530274590253141384619337562139640467932392972183997943459931027267172276", "price": "0.003", "size": "306.3", "side": "BUY", "hash": "ab3d2f2b883be9e6b69ada9a5d86dfb8f2a2db1b", "best_bid": "0.026", "best_ask": "0.158"}, {"asset_id": "13908252531396871469657521961663517650827376216919668668811621820614371209132", "price": "0.997", "size": "306.3", "side": "SELL", "hash": "4caba6208b76287bdc455f0346d31a0684b126b7", "best_bid": "0.842", "best_ask": "0.974"}], "timestamp": "1769384808579", "event_type": "price_change"}}
{"_local_timestamp": "2026-01-25T23:46:50.982302+00:00", "data": {"market": "0xebd6b4d15beed0a4a3a274d6d1bc13e0b15d13a330586190932a3c4c7887b72f", "price_changes": [{"asset_id": "113435897598335750012134454342623244279140769314836288769122310705258616530095", "price": "0.13", "size": "0", "side": "BUY", "hash": "eca0cf23c823acffc2f2e3d6f5217d7327e3484b", "best_bid": "0.89", "best_ask": "0.94"}, {"asset_id": "43860483933578174366905172776039394809444972860267197366014959631913892252602", "price": "0.87", "size": "0", "side": "SELL", "hash": "accdcf26d2bc1bd2a556838fd2866809c7f0870a", "best_bid": "0.06", "best_ask": "0.11"}], "timestamp": "1769384810675", "event_type": "price_change"}}
{"_local_timestamp": "2026-01-25T23:46:51.488828+00:00", "data": {"market": "0xfb08a969a2c05beda8b5743959182db28be71832f9a84872a786e809b77b5350", "price_changes": [{"asset_id": "13908252531396871469657521961663517650827376216919668668811621820614371209132", "price": "0.17", "size": "950", "side": "BUY", "hash": "3a7efd5bc466c7a60fc415b9e6749dec18cde5cc", "best_bid": "0.842", "best_ask": "0.974"}, {"asset_id": "28670530274590253141384619337562139640467932392972183997943459931027267172276", "price": "0.83", "size": "950", "side": "SELL", "hash": "775bb1a9442a4628be1797f025f983856eaa83d1", "best_bid": "0.026", "best_ask": "0.158"}], "timestamp": "1769384811192", "event_type": "price_change"}}
{"_local_timestamp": "2026-01-25T23:46:51.490237+00:00", "data": {"market": "0x715dc274a5c7adf3771646e36d5e3a8844163dc31e7f02331eb30d2b8108bf9e", "price_changes": [{"asset_id": "19458454719947582257633203202425613630572016962838703318400930704175824104136", "price": "0.06", "size": "1100", "side": "BUY", "hash": "e6af16da1779952e91f46a7e64bd5ff00761f4ff", "best_bid": "0.58", "best_ask": "0.61"}, {"asset_id": "817582445527276447057755966542888616081641371741603398122454732956499627950", "price": "0.94", "size": "1100", "side": "SELL", "hash": "28ba188dd51754dc0bf95d3ee38bea5f5145221a", "best_bid": "0.39", "best_ask": "0.42"}], "timestamp": "1769384811195", "event_type": "price_change"}}
{"_local_timestamp": "2026-01-25T23:46:51.527723+00:00", "data": {"market": "0xebd6b4d15beed0a4a3a274d6d1bc13e0b15d13a330586190932a3c4c7887b72f", "price_changes": [{"asset_id": "113435897598335750012134454342623244279140769314836288769122310705258616530095", "price": "0.14", "size": "567.85", "side": "BUY", "hash": "6e75d774f659ae20d9feba3a05b535502fc64f40", "best_bid": "0.89", "best_ask": "0.94"}, {"asset_id": "43860483933578174366905172776039394809444972860267197366014959631913892252602", "price": "0.86", "size": "567.85", "side": "SELL", "hash": "cd30cf6ba675b86074e7eba366c1c6ece08d3911", "best_bid": "0.06", "best_ask": "0.11"}], "timestamp": "1769384811195", "event_type": "price_change"}}
{"_local_timestamp": "2026-01-25T23:46:51.658306+00:00", "data": {"market": "0x715dc274a5c7adf3771646e36d5e3a8844163dc31e7f02331eb30d2b8108bf9e", "price_changes": [{"asset_id": "19458454719947582257633203202425613630572016962838703318400930704175824104136", "price": "0.29", "size": "100", "side": "BUY", "hash": "ee0dccf13915dcc95d91ce82f04a8dff3a9d7c88", "best_bid": "0.58", "best_ask": "0.61"}, {"asset_id": "817582445527276447057755966542888616081641371741603398122454732956499627950", "price": "0.71", "size": "100", "side": "SELL", "hash": "9f4326426d64d242a62c133e32ed51baa048beb2", "best_bid": "0.39", "best_ask": "0.42"}], "timestamp": "1769384811258", "event_type": "price_change"}}
{"_local_timestamp": "2026-01-25T23:46:51.658601+00:00", "data": {"market": "0xfb08a969a2c05beda8b5743959182db28be71832f9a84872a786e809b77b5350", "price_changes": [{"asset_id": "13908252531396871469657521961663517650827376216919668668811621820614371209132", "price": "0.13", "size": "586.53", "side": "BUY", "hash": "bb49ec3876bf875cf5fe215661c522fbc079f662", "best_bid": "0.842", "best_ask": "0.974"}, {"asset_id": "28670530274590253141384619337562139640467932392972183997943459931027267172276", "price": "0.87", "size": "586.53", "side": "SELL", "hash": "97266436c5c7f45ec69ab83d70da96694fa32e53", "best_bid": "0.026", "best_ask": "0.158"}], "timestamp": "1769384811257", "event_type": "price_change"}}
{"_local_timestamp": "2026-01-25T23:46:51.672686+00:00", "data": {"market": "0xfb08a969a2c05beda8b5743959182db28be71832f9a84872a786e809b77b5350", "price_changes": [{"asset_id": "13908252531396871469657521961663517650827376216919668668811621820614371209132", "price": "0.231", "size": "250", "side": "BUY", "hash": "8a36a0323da59628157d15761b4f183ad8aa7121", "best_bid": "0.842", "best_ask": "0.974"}, {"asset_id": "28670530274590253141384619337562139640467932392972183997943459931027267172276", "price": "0.769", "size": "250", "side": "SELL", "hash": "db362ef335dc22c1bb23ee8da0c2fb5e09dbca6a", "best_bid": "0.026", "best_ask": "0.158"}], "timestamp": "1769384811291", "event_type": "price_change"}}
{"_local_timestamp": "2026-01-25T23:46:51.673226+00:00", "data": {"market": "0x715dc274a5c7adf3771646e36d5e3a8844163dc31e7f02331eb30d2b8108bf9e", "price_changes": [{"asset_id": "19458454719947582257633203202425613630572016962838703318400930704175824104136", "price": "0.12", "size": "631.66", "side": "BUY", "hash": "56788b227f90af711e8068b2e370af32c91a7038", "best_bid": "0.58", "best_ask": "0.61"}, {"asset_id": "817582445527276447057755966542888616081641371741603398122454732956499627950", "price": "0.88", "size": "631.66", "side": "SELL", "hash": "b30dc451ce58771525e131b8b2f43ea0a812c1c4", "best_bid": "0.39", "best_ask": "0.42"}], "timestamp": "1769384811289", "event_type": "price_change"}}
{"_local_timestamp": "2026-01-25T23:46:51.676060+00:00", "data": {"market": "0x715dc274a5c7adf3771646e36d5e3a8844163dc31e7f02331eb30d2b8108bf9e", "price_changes": [{"asset_id": "19458454719947582257633203202425613630572016962838703318400930704175824104136", "price": "0.19", "size": "386.84", "side": "BUY", "hash": "6ec2a7f9c3eb53c4dde4117c113de246d4dee8ae", "best_bid": "0.58", "best_ask": "0.61"}, {"asset_id": "817582445527276447057755966542888616081641371741603398122454732956499627950", "price": "0.81", "size": "386.84", "side": "SELL", "hash": "d572b33abdffe3cbfebec7f808bc4b1c706b692c", "best_bid": "0.39", "best_ask": "0.42"}], "timestamp": "1769384811299", "event_type": "price_change"}}
{"_local_timestamp": "2026-01-25T23:46:57.085424+00:00", "data": {"market": "0xfb08a969a2c05beda8b5743959182db28be71832f9a84872a786e809b77b5350", "price_changes": [{"asset_id": "13908252531396871469657521961663517650827376216919668668811621820614371209132", "price": "0.84", "size": "0", "side": "BUY", "hash": "02e11b0d13ff52950d07d2b72dbe93b34f31ea6a", "best_bid": "0.842", "best_ask": "0.974"}, {"asset_id": "28670530274590253141384619337562139640467932392972183997943459931027267172276", "price": "0.16", "size": "0", "side": "SELL", "hash": "07e1c792eaec6d9e6d46deb1980bec94aacc2d82", "best_bid": "0.026", "best_ask": "0.158"}], "timestamp": "1769384817003", "event_type": "price_change"}}
{"_local_timestamp": "2026-01-25T23:47:27.138842+00:00", "data": {"market": "0x715dc274a5c7adf3771646e36d5e3a8844163dc31e7f02331eb30d2b8108bf9e", "price_changes": [{"asset_id": "19458454719947582257633203202425613630572016962838703318400930704175824104136", "price": "0.57", "size": "10", "side": "BUY", "hash": "d908276bc926028f60863922a0ee07ad5a75a743", "best_bid": "0.58", "best_ask": "0.61"}, {"asset_id": "817582445527276447057755966542888616081641371741603398122454732956499627950", "price": "0.43", "size": "10", "side": "SELL", "hash": "7c4f09699c8f96720d289591377dd385338549b0", "best_bid": "0.39", "best_ask": "0.42"}], "timestamp": "1769384847056", "event_type": "price_change"}}
{"_local_timestamp": "2026-01-25T23:47:27.226895+00:00", "data": {"market": "0xd62d0fd81efeba80c7d331577b8cfdaf89eb287a64f65f6418677f5669da4374", "price_changes": [{"asset_id": "50806857340536377589471864244012059415352637140902118853666778383891415395995", "price": "0.54", "size": "0", "side": "BUY", "hash": "6bd8e85515f64611ee6805d4faae0cc5b52014a0", "best_bid": "0.89", "best_ask": "0.93"}, {"asset_id": "44436347575766030163252235546454470356610478743001712085002709882075518933616", "price": "0.46", "size": "0", "side": "SELL", "hash": "9d5b7ad40106e91437c84854b65577e1b5f2be12", "best_bid": "0.07", "best_ask": "0.11"}], "timestamp": "1769384847148", "event_type": "price_change"}}
{"_local_timestamp": "2026-01-25T23:47:27.302223+00:00", "data": {"market": "0xebd6b4d15beed0a4a3a274d6d1bc13e0b15d13a330586190932a3c4c7887b72f", "price_changes": [{"asset_id": "113435897598335750012134454342623244279140769314836288769122310705258616530095", "price": "0.6", "size": "0", "side": "BUY", "hash": "4c69ce1c01d50ecee976fb1b4c93e9abfc3b29f2", "best_bid": "0.89", "best_ask": "0.94"}, {"asset_id": "43860483933578174366905172776039394809444972860267197366014959631913892252602", "price": "0.4", "size": "0", "side": "SELL", "hash": "b6f79949a84bfc67fb4a764382e4346fff3afe5e", "best_bid": "0.06", "best_ask": "0.11"}], "timestamp": "1769384847237", "event_type": "price_change"}}
{"_local_timestamp": "2026-01-25T23:47:27.329586+00:00", "data": {"market": "0xd62d0fd81efeba80c7d331577b8cfdaf89eb287a64f65f6418677f5669da4374", "price_changes": [{"asset_id": "50806857340536377589471864244012059415352637140902118853666778383891415395995", "price": "0.58", "size": "15", "side": "BUY", "hash": "c98a5a4e2d80ac013047a518fc4f97c8cec06532", "best_bid": "0.89", "best_ask": "0.93"}, {"asset_id": "44436347575766030163252235546454470356610478743001712085002709882075518933616", "price": "0.42", "size": "15", "side": "SELL", "hash": "734813a44e111f5f717a2934d55578f777f1fa3b", "best_bid": "0.07", "best_ask": "0.11"}], "timestamp": "1769384847263", "event_type": "price_change"}}
{"_local_timestamp": "2026-01-25T23:47:27.329954+00:00", "data": {"market": "0xd62d0fd81efeba80c7d331577b8cfdaf89eb287a64f65f6418677f5669da4374", "price_changes": [{"asset_id": "50806857340536377589471864244012059415352637140902118853666778383891415395995", "price": "0.58", "size": "25", "side": "BUY", "hash": "e935c752d010aaf8ef43a80faaa53509d399ec79", "best_bid": "0.89", "best_ask": "0.93"}, {"asset_id": "44436347575766030163252235546454470356610478743001712085002709882075518933616", "price": "0.42", "size": "25", "side": "SELL", "hash": "fb01a306e3202dc4d40ddde77dd37b114fa5a0e4", "best_bid": "0.07", "best_ask": "0.11"}], "timestamp": "1769384847264", "event_type": "price_change"}}
{"_local_timestamp": "2026-01-25T23:47:27.386512+00:00", "data": {"market": "0x29d688e8ee4dc83cff27ce5d583553be477b4202aba945dff96730aa88397071", "price_changes": [{"asset_id": "22395241560984864794587761975509529149656370897276070318169938852205137917866", "price": "0.55", "size": "0", "side": "BUY", "hash": "bf934d8f2e1fdb29ae9d305d304b9b42b68214df", "best_bid": "0.8", "best_ask": "0.95"}, {"asset_id": "46123672832602976783793170370598938766981479048132054420648285300054482204701", "price": "0.45", "size": "0", "side": "SELL", "hash": "b5bf03be9662a308fc6d89ff868955d1410bc1bb", "best_bid": "0.05", "best_ask": "0.2"}], "timestamp": "1769384847322", "event_type": "price_change"}}
{"_local_timestamp": "2026-01-25T23:47:27.386874+00:00", "data": {"market": "0xebd6b4d15beed0a4a3a274d6d1bc13e0b15d13a330586190932a3c4c7887b72f", "price_changes": [{"asset_id": "113435897598335750012134454342623244279140769314836288769122310705258616530095", "price": "0.61", "size": "0", "side": "BUY", "hash": "eaae509e6e3faa8efc7a090da68eb99960411141", "best_bid": "0.89", "best_ask": "0.94"}, {"asset_id": "43860483933578174366905172776039394809444972860267197366014959631913892252602", "price": "0.39", "size": "0", "side": "SELL", "hash": "fb489c7a3e3472e4f6ac452873dbb663acbcc40e", "best_bid": "0.06", "best_ask": "0.11"}], "timestamp": "1769384847322", "event_type": "price_change"}}
{"_local_timestamp": "2026-01-25T23:47:27.425492+00:00", "data": {"market": "0xebd6b4d15beed0a4a3a274d6d1bc13e0b15d13a330586190932a3c4c7887b72f", "price_changes": [{"asset_id": "113435897598335750012134454342623244279140769314836288769122310705258616530095", "price": "0.41", "size": "25", "side": "BUY", "hash": "a2a44261df1a87a45b57c7303d66c3a624c31a1b", "best_bid": "0.89", "best_ask": "0.94"}, {"asset_id": "43860483933578174366905172776039394809444972860267197366014959631913892252602", "price": "0.59", "size": "25", "side": "SELL", "hash": "0bf477207b375335ab317baf5cfaa8a40923bb78", "best_bid": "0.06", "best_ask": "0.11"}], "timestamp": "1769384847363", "event_type": "price_change"}}
{"_local_timestamp": "2026-01-25T23:47:27.613224+00:00", "data": {"market": "0xebd6b4d15beed0a4a3a274d6d1bc13e0b15d13a330586190932a3c4c7887b72f", "price_changes": [{"asset_id": "113435897598335750012134454342623244279140769314836288769122310705258616530095", "price": "0.42", "size": "15", "side": "BUY", "hash": "1cb4228fa893b54aa5e3e3cb835c31ae2aeefa8f", "best_bid": "0.89", "best_ask": "0.94"}, {"asset_id": "43860483933578174366905172776039394809444972860267197366014959631913892252602", "price": "0.58", "size": "15", "side": "SELL", "hash": "19ef10fc49d93e5eaeb5b10d16867f84f91ace5a", "best_bid": "0.06", "best_ask": "0.11"}], "timestamp": "1769384847535", "event_type": "price_change"}}
{"_local_timestamp": "2026-01-25T23:47:27.613530+00:00", "data": {"market": "0x29d688e8ee4dc83cff27ce5d583553be477b4202aba945dff96730aa88397071", "price_changes": [{"asset_id": "22395241560984864794587761975509529149656370897276070318169938852205137917866", "price": "0.59", "size": "15", "side": "BUY", "hash": "29da03847e5275f4dd688f818ad9131883c8120d", "best_bid": "0.8", "best_ask": "0.95"}, {"asset_id": "46123672832602976783793170370598938766981479048132054420648285300054482204701", "price": "0.41", "size": "15", "side": "SELL", "hash": "31d6e48287f76e861e4e477bcc8b4f32f66685c0", "best_bid": "0.05", "best_ask": "0.2"}], "timestamp": "1769384847535", "event_type": "price_change"}}
{"_local_timestamp": "2026-01-25T23:47:27.613776+00:00", "data": {"market": "0x29d688e8ee4dc83cff27ce5d583553be477b4202aba945dff96730aa88397071", "price_changes": [{"asset_id": "22395241560984864794587761975509529149656370897276070318169938852205137917866", "price": "0.59", "size": "25", "side": "BUY", "hash": "158c652adc33a8650b176b62a97020f4e7d816c3", "best_bid": "0.8", "best_ask": "0.95"}, {"asset_id": "46123672832602976783793170370598938766981479048132054420648285300054482204701", "price": "0.41", "size": "25", "side": "SELL", "hash": "6e69de256821e49379bbc46e4d0a608d21f54775", "best_bid": "0.05", "best_ask": "0.2"}], "timestamp": "1769384847536", "event_type": "price_change"}}
{"_local_timestamp": "2026-01-25T23:47:27.614003+00:00", "data": {"market": "0xebd6b4d15beed0a4a3a274d6d1bc13e0b15d13a330586190932a3c4c7887b72f", "price_changes": [{"asset_id": "113435897598335750012134454342623244279140769314836288769122310705258616530095", "price": "0.66", "size": "30", "side": "BUY", "hash": "54f7c274b81d778b478b468a684bf6238a9807f6", "best_bid": "0.89", "best_ask": "0.94"}, {"asset_id": "43860483933578174366905172776039394809444972860267197366014959631913892252602", "price": "0.34", "size": "30", "side": "SELL", "hash": "c1db73c032499a91a4658ab74e87016a8fe8ee7e", "best_bid": "0.06", "best_ask": "0.11"}], "timestamp": "1769384847536", "event_type": "price_change"}}
{"_local_timestamp": "2026-01-25T23:47:32.396960+00:00", "data": {"market": "0x29d688e8ee4dc83cff27ce5d583553be477b4202aba945dff96730aa88397071", "price_changes": [{"asset_id": "22395241560984864794587761975509529149656370897276070318169938852205137917866", "price": "0.58", "size": "0", "side": "BUY", "hash": "657c1c6b9f3c9e7d5f92f171b95c1c7976a76746", "best_bid": "0.8", "best_ask": "0.95"}, {"asset_id": "46123672832602976783793170370598938766981479048132054420648285300054482204701", "price": "0.42", "size": "0", "side": "SELL", "hash": "9b4b6c4250b0f840807882cf6eb781ceab1364f5", "best_bid": "0.05", "best_ask": "0.2"}], "timestamp": "1769384852326", "event_type": "price_change"}}
{"_local_timestamp": "2026-01-25T23:47:32.397537+00:00", "data": {"market": "0xd62d0fd81efeba80c7d331577b8cfdaf89eb287a64f65f6418677f5669da4374", "price_changes": [{"asset_id": "50806857340536377589471864244012059415352637140902118853666778383891415395995", "price": "0.57", "size": "0", "side": "BUY", "hash": "f4dd913c3874e9c45cc2ad71b0ad21a2b3d2d6a2", "best_bid": "0.89", "best_ask": "0.93"}, {"asset_id": "44436347575766030163252235546454470356610478743001712085002709882075518933616", "price": "0.43", "size": "0", "side": "SELL", "hash": "ec60a3273d4112782ae8c9f4b7bf9079783063e8", "best_bid": "0.07", "best_ask": "0.11"}], "timestamp": "1769384852326", "event_type": "price_change"}}
{"_local_timestamp": "2026-01-25T23:47:32.417681+00:00", "data": {"market": "0x29d688e8ee4dc83cff27ce5d583553be477b4202aba945dff96730aa88397071", "price_changes": [{"asset_id": "22395241560984864794587761975509529149656370897276070318169938852205137917866", "price": "0.6", "size": "20", "side": "BUY", "hash": "3c9604727151908160c91ba543259cd1f6a9548f", "best_bid": "0.8", "best_ask": "0.95"}, {"asset_id": "46123672832602976783793170370598938766981479048132054420648285300054482204701", "price": "0.4", "size": "20", "side": "SELL", "hash": "fffa5eb2850b90703796aee85ad251310143c04b", "best_bid": "0.05", "best_ask": "0.2"}], "timestamp": "1769384852352", "event_type": "price_change"}}
{"_local_timestamp": "2026-01-25T23:47:32.418084+00:00", "data": {"market": "0xd62d0fd81efeba80c7d331577b8cfdaf89eb287a64f65f6418677f5669da4374", "price_changes": [{"asset_id": "50806857340536377589471864244012059415352637140902118853666778383891415395995", "price": "0.59", "size": "20", "side": "BUY", "hash": "f015e9498bbbfbc94504f69ce70019cd6ebe7965", "best_bid": "0.89", "best_ask": "0.93"}, {"asset_id": "44436347575766030163252235546454470356610478743001712085002709882075518933616", "price": "0.41", "size": "20", "side": "SELL", "hash": "e3bb206ec9270c53b412a7b129f2a8972604de6f", "best_bid": "0.07", "best_ask": "0.11"}], "timestamp": "1769384852352", "event_type": "price_change"}}
{"_local_timestamp": "2026-01-25T23:47:32.484904+00:00", "data": {"market": "0xfb08a969a2c05beda8b5743959182db28be71832f9a84872a786e809b77b5350", "price_changes": [{"asset_id": "13908252531396871469657521961663517650827376216919668668811621820614371209132", "price": "0.642", "size": "10", "side": "BUY", "hash": "2e7c534d863816af0a822aba0b0bacd1a25dfc67", "best_bid": "0.842", "best_ask": "0.974"}, {"asset_id": "28670530274590253141384619337562139640467932392972183997943459931027267172276", "price": "0.358", "size": "10", "side": "SELL", "hash": "6962cb4ec0862623acd5d7e04aed2c4ad62d8eff", "best_bid": "0.026", "best_ask": "0.158"}], "timestamp": "1769384852421", "event_type": "price_change"}}
{"_local_timestamp": "2026-01-25T23:47:32.559117+00:00", "data": {"market": "0xfb08a969a2c05beda8b5743959182db28be71832f9a84872a786e809b77b5350", "price_changes": [{"asset_id": "13908252531396871469657521961663517650827376216919668668811621820614371209132", "price": "0.644", "size": "15", "side": "BUY", "hash": "9f747dfff6c1d540045d15798cfd5c175718f1d4", "best_bid": "0.842", "best_ask": "0.974"}, {"asset_id": "28670530274590253141384619337562139640467932392972183997943459931027267172276", "price": "0.356", "size": "15", "side": "SELL", "hash": "85cd826e377554ece63f33148bbd7a3a56bbe461", "best_bid": "0.026", "best_ask": "0.158"}], "timestamp": "1769384852489", "event_type": "price_change"}}
{"_local_timestamp": "2026-01-25T23:47:32.559922+00:00", "data": {"market": "0xfb08a969a2c05beda8b5743959182db28be71832f9a84872a786e809b77b5350", "price_changes": [{"asset_id": "13908252531396871469657521961663517650827376216919668668811621820614371209132", "price": "0.644", "size": "25", "side": "BUY", "hash": "6fdc3917b2c9d1adb3b7855dae4a1d44fac0978c", "best_bid": "0.842", "best_ask": "0.974"}, {"asset_id": "28670530274590253141384619337562139640467932392972183997943459931027267172276", "price": "0.356", "size": "25", "side": "SELL", "hash": "5609462c4519be1cdf695cd1121911ca8e2a4c3d", "best_bid": "0.026", "best_ask": "0.158"}], "timestamp": "1769384852490", "event_type": "price_change"}}
{"_local_timestamp": "2026-01-25T23:47:37.777326+00:00", "data": {"market": "0xfb08a969a2c05beda8b5743959182db28be71832f9a84872a786e809b77b5350", "price_changes": [{"asset_id": "13908252531396871469657521961663517650827376216919668668811621820614371209132", "price": "0.231", "size": "200", "side": "BUY", "hash": "99c12c50092d27c2f334cfe7a9e6eb0b5b2a5e21", "best_bid": "0.842", "best_ask": "0.974"}, {"asset_id": "28670530274590253141384619337562139640467932392972183997943459931027267172276", "price": "0.769", "size": "200", "side": "SELL", "hash": "29572377e2d297e4bae4047b6bcd7281fcebe9e0", "best_bid": "0.026", "best_ask": "0.158"}], "timestamp": "1769384857548", "event_type": "price_change"}}
{"_local_timestamp": "2026-01-25T23:47:38.401677+00:00", "data": {"market": "0x715dc274a5c7adf3771646e36d5e3a8844163dc31e7f02331eb30d2b8108bf9e", "price_changes": [{"asset_id": "19458454719947582257633203202425613630572016962838703318400930704175824104136", "price": "0.26", "size": "150", "side": "BUY", "hash": "e67ecf240b77e5a3c91b77da0cbcce3abe3ba97f", "best_bid": "0.58", "best_ask": "0.61"}, {"asset_id": "817582445527276447057755966542888616081641371741603398122454732956499627950", "price": "0.74", "size": "150", "side": "SELL", "hash": "e4fda863cb63f20cf93510f686d339416a635116", "best_bid": "0.39", "best_ask": "0.42"}], "timestamp": "1769384858079", "event_type": "price_change"}}
{"_local_timestamp": "2026-01-25T23:47:38.421048+00:00", "data": {"market": "0xfb08a969a2c05beda8b5743959182db28be71832f9a84872a786e809b77b5350", "price_changes": [{"asset_id": "13908252531396871469657521961663517650827376216919668668811621820614371209132", "price": "0.22", "size": "177.27", "side": "BUY", "hash": "343e1ab94ce06677aaf7aaf3c02f51da8cde8b75", "best_bid": "0.842", "best_ask": "0.974"}, {"asset_id": "28670530274590253141384619337562139640467932392972183997943459931027267172276", "price": "0.78", "size": "177.27", "side": "SELL", "hash": "b31da89334f3808acf66c932e3e1430f82f76e8f", "best_bid": "0.026", "best_ask": "0.158"}], "timestamp": "1769384858076", "event_type": "price_change"}}
{"_local_timestamp": "2026-01-25T23:47:39.133044+00:00", "data": {"market": "0xfb08a969a2c05beda8b5743959182db28be71832f9a84872a786e809b77b5350", "price_changes": [{"asset_id": "13908252531396871469657521961663517650827376216919668668811621820614371209132", "price": "0.643", "size": "0", "side": "BUY", "hash": "579b61d49b445c9c211c43aa9dec5005c5dedbf3", "best_bid": "0.842", "best_ask": "0.974"}, {"asset_id": "28670530274590253141384619337562139640467932392972183997943459931027267172276", "price": "0.357", "size": "0", "side": "SELL", "hash": "9c45162bc767801fe7905de95bc805bf0041b7b1", "best_bid": "0.026", "best_ask": "0.158"}], "timestamp": "1769384859028", "event_type": "price_change"}}
{"_local_timestamp": "2026-01-25T23:47:39.146645+00:00", "data": {"market": "0xfb08a969a2c05beda8b5743959182db28be71832f9a84872a786e809b77b5350", "price_changes": [{"asset_id": "13908252531396871469657521961663517650827376216919668668811621820614371209132", "price": "0.645", "size": "20", "side": "BUY", "hash": "a2d66e5dec264e70ef583bd364d2a744e263fee3", "best_bid": "0.842", "best_ask": "0.974"}, {"asset_id": "28670530274590253141384619337562139640467932392972183997943459931027267172276", "price": "0.355", "size": "20", "side": "SELL", "hash": "219a499dc62a8420a5dd71be8ae1fc096496b8be", "best_bid": "0.026", "best_ask": "0.158"}], "timestamp": "1769384859055", "event_type": "price_change"}}
{"_local_timestamp": "2026-01-25T23:47:54.130097+00:00", "data": {"market": "0x29d688e8ee4dc83cff27ce5d583553be477b4202aba945dff96730aa88397071", "price_changes": [{"asset_id": "46123672832602976783793170370598938766981479048132054420648285300054482204701", "price": "0.02", "size": "175.4", "side": "BUY", "hash": "3d6469b7189822af1a3d805bd5a3accec641bd95", "best_bid": "0.05", "best_ask": "0.2"}, {"asset_id": "22395241560984864794587761975509529149656370897276070318169938852205137917866", "price": "0.98", "size": "175.4", "side": "SELL", "hash": "c4e47d686ea4c2ba377aedc15291b16fc966c958", "best_bid": "0.8", "best_ask": "0.95"}], "timestamp": "1769384874050", "event_type": "price_change"}}
{"_local_timestamp": "2026-01-25T23:47:54.137970+00:00", "data": {"market": "0x29d688e8ee4dc83cff27ce5d583553be477b4202aba945dff96730aa88397071", "price_changes": [{"asset_id": "46123672832602976783793170370598938766981479048132054420648285300054482204701", "price": "0.01", "size": "91.84", "side": "BUY", "hash": "39350e0e79a43d01822842cc0949cbde68d3bded", "best_bid": "0.05", "best_ask": "0.2"}, {"asset_id": "22395241560984864794587761975509529149656370897276070318169938852205137917866", "price": "0.99", "size": "91.84", "side": "SELL", "hash": "d2b2d05947464f876d4dcb8ac3341f52d68f0b05", "best_bid": "0.8", "best_ask": "0.95"}], "timestamp": "1769384874051", "event_type": "price_change"}}
{"_local_timestamp": "2026-01-25T23:47:55.181572+00:00", "data": {"market": "0xebd6b4d15beed0a4a3a274d6d1bc13e0b15d13a330586190932a3c4c7887b72f", "price_changes": [{"asset_id": "113435897598335750012134454342623244279140769314836288769122310705258616530095", "price": "0.77", "size": "0", "side": "BUY", "hash": "f23173175a5005d0aef8cc0593a8af88a562cd81", "best_bid": "0.89", "best_ask": "0.94"}, {"asset_id": "43860483933578174366905172776039394809444972860267197366014959631913892252602", "price": "0.23", "size": "0", "side": "SELL", "hash": "eccb160f2099c0cb3812ed0c2c229652e95a6163", "best_bid": "0.06", "best_ask": "0.11"}], "timestamp": "1769384875110", "event_type": "price_change"}}
{"_local_timestamp": "2026-01-25T23:47:55.181945+00:00", "data": {"market": "0x715dc274a5c7adf3771646e36d5e3a8844163dc31e7f02331eb30d2b8108bf9e", "price_changes": [{"asset_id": "19458454719947582257633203202425613630572016962838703318400930704175824104136", "price": "0.42", "size": "0", "side": "BUY", "hash": "e21fcb2fab1fe2a4844a8f268b41174edb5f64ca", "best_bid": "0.58", "best_ask": "0.61"}, {"asset_id": "817582445527276447057755966542888616081641371741603398122454732956499627950", "price": "0.58", "size": "0", "side": "SELL", "hash": "3a3297d002c89ece4b0b41783a60813de6314476", "best_bid": "0.39", "best_ask": "0.42"}], "timestamp": "1769384875110", "event_type": "price_change"}}
{"_local_timestamp": "2026-01-25T23:47:55.182270+00:00", "data": {"market": "0xfb08a969a2c05beda8b5743959182db28be71832f9a84872a786e809b77b5350", "price_changes": [{"asset_id": "28670530274590253141384619337562139640467932392972183997943459931027267172276", "price": "0.021", "size": "100", "side": "BUY", "hash": "02a2eeea15deabdb89b8aa61a9105c8c3a3c52a2", "best_bid": "0.026", "best_ask": "0.158"}, {"asset_id": "13908252531396871469657521961663517650827376216919668668811621820614371209132", "price": "0.979", "size": "100", "side": "SELL", "hash": "d535599f1cde5407fafaccb3a917a0d8ceed9c37", "best_bid": "0.842", "best_ask": "0.974"}], "timestamp": "1769384875110", "event_type": "price_change"}}
{"_local_timestamp": "2026-01-25T23:47:55.182558+00:00", "data": {"market": "0xfb08a969a2c05beda8b5743959182db28be71832f9a84872a786e809b77b5350", "price_changes": [{"asset_id": "28670530274590253141384619337562139640467932392972183997943459931027267172276", "price": "0.011", "size": "100", "side": "BUY", "hash": "02a2eeea15deabdb89b8aa61a9105c8c3a3c52a2", "best_bid": "0.026", "best_ask": "0.158"}, {"asset_id": "13908252531396871469657521961663517650827376216919668668811621820614371209132", "price": "0.989", "size": "100", "side": "SELL", "hash": "d535599f1cde5407fafaccb3a917a0d8ceed9c37", "best_bid": "0.842", "best_ask": "0.974"}], "timestamp": "1769384875110", "event_type": "price_change"}}
{"_local_timestamp": "2026-01-25T23:47:55.182846+00:00", "data": {"market": "0x715dc274a5c7adf3771646e36d5e3a8844163dc31e7f02331eb30d2b8108bf9e", "price_changes": [{"asset_id": "19458454719947582257633203202425613630572016962838703318400930704175824104136", "price": "0.26", "size": "50", "side": "BUY", "hash": "e21fcb2fab1fe2a4844a8f268b41174edb5f64ca", "best_bid": "0.58", "best_ask": "0.61"}, {"asset_id": "817582445527276447057755966542888616081641371741603398122454732956499627950", "price": "0.74", "size": "50", "side": "SELL", "hash": "3a3297d002c89ece4b0b41783a60813de6314476", "best_bid": "0.39", "best_ask": "0.42"}], "timestamp": "1769384875110", "event_type": "price_change"}}
{"_local_timestamp": "2026-01-25T23:47:55.203307+00:00", "data": {"market": "0x715dc274a5c7adf3771646e36d5e3a8844163dc31e7f02331eb30d2b8108bf9e", "price_changes": [{"asset_id": "19458454719947582257633203202425613630572016962838703318400930704175824104136", "price": "0.43", "size": "0", "side": "BUY", "hash": "dc2e5fdc578d2d2514a7a8de1a001c90a025765e", "best_bid": "0.58", "best_ask": "0.61"}, {"asset_id": "817582445527276447057755966542888616081641371741603398122454732956499627950", "price": "0.57", "size": "0", "side": "SELL", "hash": "8a82eebcff2adc1dbe1af8252ee9a914cdff73d4", "best_bid": "0.39", "best_ask": "0.42"}], "timestamp": "1769384875137", "event_type": "price_change"}}
{"_local_timestamp": "2026-01-25T23:47:55.237535+00:00", "data": {"market": "0x715dc274a5c7adf3771646e36d5e3a8844163dc31e7f02331eb30d2b8108bf9e", "price_changes": [{"asset_id": "19458454719947582257633203202425613630572016962838703318400930704175824104136", "price": "0.3", "size": "124", "side": "BUY", "hash": "60bcd91f19991d7d40316c331cca7d57cf170b22", "best_bid": "0.58", "best_ask": "0.61"}, {"asset_id": "817582445527276447057755966542888616081641371741603398122454732956499627950", "price": "0.7", "size": "124", "side": "SELL", "hash": "ef49df0ac93300fb38647e83f19e8379c47fed90", "best_bid": "0.39", "best_ask": "0.42"}], "timestamp": "1769384875167", "event_type": "price_change"}}
{"_local_timestamp": "2026-01-25T23:47:55.708283+00:00", "data": {"market": "0x715dc274a5c7adf3771646e36d5e3a8844163dc31e7f02331eb30d2b8108bf9e", "price_changes": [{"asset_id": "19458454719947582257633203202425613630572016962838703318400930704175824104136", "price": "0.22", "size": "209.09", "side": "BUY", "hash": "18d7b1e779c33b6726dc31223a574d3619382889", "best_bid": "0.58", "best_ask": "0.61"}, {"asset_id": "817582445527276447057755966542888616081641371741603398122454732956499627950", "price": "0.78", "size": "209.09", "side": "SELL", "hash": "5285a37ade54587c1fe8a2ac140ae85635fa1fa4", "best_bid": "0.39", "best_ask": "0.42"}], "timestamp": "1769384875500", "event_type": "price_change"}}
{"_local_timestamp": "2026-01-25T23:47:55.708582+00:00", "data": {"market": "0x715dc274a5c7adf3771646e36d5e3a8844163dc31e7f02331eb30d2b8108bf9e", "price_changes": [{"asset_id": "19458454719947582257633203202425613630572016962838703318400930704175824104136", "price": "0.4", "size": "100", "side": "BUY", "hash": "137e9e177d3e5042f68546235426108e96405cba", "best_bid": "0.58", "best_ask": "0.61"}, {"asset_id": "817582445527276447057755966542888616081641371741603398122454732956499627950", "price": "0.6", "size": "100", "side": "SELL", "hash": "815866d16b8d416a86a0e206a3bbff7be11fd086", "best_bid": "0.39", "best_ask": "0.42"}], "timestamp": "1769384875509", "event_type": "price_change"}}
{"_local_timestamp": "2026-01-25T23:47:55.775915+00:00", "data": {"market": "0xebd6b4d15beed0a4a3a274d6d1bc13e0b15d13a330586190932a3c4c7887b72f", "price_changes": [{"asset_id": "113435897598335750012134454342623244279140769314836288769122310705258616530095", "price": "0.43", "size": "100", "side": "BUY", "hash": "888b9f81080304a60234e8b6e5f410d86e6456d9", "best_bid": "0.89", "best_ask": "0.94"}, {"asset_id": "43860483933578174366905172776039394809444972860267197366014959631913892252602", "price": "0.57", "size": "100", "side": "SELL", "hash": "d3cc99fdcdeaa1852c783bfe6bf85ff91b934384", "best_bid": "0.06", "best_ask": "0.11"}], "timestamp": "1769384875640", "event_type": "price_change"}}
{"_local_timestamp": "2026-01-25T23:47:55.796487+00:00", "data": {"market": "0xfb08a969a2c05beda8b5743959182db28be71832f9a84872a786e809b77b5350", "price_changes": [{"asset_id": "28670530274590253141384619337562139640467932392972183997943459931027267172276", "price": "0.015", "size": "41.98", "side": "BUY", "hash": "d152a1e9487ef3f4bf8d72f48a78f2348ff1132d", "best_bid": "0.026", "best_ask": "0.158"}, {"asset_id": "13908252531396871469657521961663517650827376216919668668811621820614371209132", "price": "0.985", "size": "41.98", "side": "SELL", "hash": "e62ea4a87b9ba63f31f6c2afd507120f1ae389c9", "best_bid": "0.842", "best_ask": "0.974"}], "timestamp": "1769384875678", "event_type": "price_change"}}
{"_local_timestamp": "2026-01-25T23:47:55.796816+00:00", "data": {"market": "0xfb08a969a2c05beda8b5743959182db28be71832f9a84872a786e809b77b5350", "price_changes": [{"asset_id": "28670530274590253141384619337562139640467932392972183997943459931027267172276", "price": "0.004", "size": "38.17", "side": "BUY", "hash": "0d3092369ca636a26c5727368c6ef9fed3843f21", "best_bid": "0.026", "best_ask": "0.158"}, {"asset_id": "13908252531396871469657521961663517650827376216919668668811621820614371209132", "price": "0.996", "size": "38.17", "side": "SELL", "hash": "0c283cce5e54a93c5b965353ea5ee4ee24b3e520", "best_bid": "0.842", "best_ask": "0.974"}], "timestamp": "1769384875679", "event_type": "price_change"}}
{"_local_timestamp": "2026-01-25T23:47:55.969538+00:00", "data": {"market": "0xebd6b4d15beed0a4a3a274d6d1bc13e0b15d13a330586190932a3c4c7887b72f", "price_changes": [{"asset_id": "113435897598335750012134454342623244279140769314836288769122310705258616530095", "price": "0.34", "size": "0", "side": "BUY", "hash": "df038c1a3b2d41083ac6f80f55f1d852622ffcfd", "best_bid": "0.89", "best_ask": "0.94"}, {"asset_id": "43860483933578174366905172776039394809444972860267197366014959631913892252602", "price": "0.66", "size": "0", "side": "SELL", "hash": "0d1a0840b0f94d3f087586af7c9e4c5acaf7151f", "best_bid": "0.06", "best_ask": "0.11"}], "timestamp": "1769384875901", "event_type": "price_change"}}
{"_local_timestamp": "2026-01-25T23:47:56.037161+00:00", "data": {"market": "0xebd6b4d15beed0a4a3a274d6d1bc13e0b15d13a330586190932a3c4c7887b72f", "price_changes": [{"asset_id": "113435897598335750012134454342623244279140769314836288769122310705258616530095", "price": "0.3", "size": "10", "side": "BUY", "hash": "e07794d3a1209e247d46e360b06f29a0087e78bc", "best_bid": "0.89", "best_ask": "0.94"}, {"asset_id": "43860483933578174366905172776039394809444972860267197366014959631913892252602", "price": "0.7", "size": "10", "side": "SELL", "hash": "3fa001d9360bc9ac6396693aaad26bb27fb3a2c3", "best_bid": "0.06", "best_ask": "0.11"}], "timestamp": "1769384875963", "event_type": "price_change"}}
{"_local_timestamp": "2026-01-25T23:47:56.425470+00:00", "data": {"market": "0x715dc274a5c7adf3771646e36d5e3a8844163dc31e7f02331eb30d2b8108bf9e", "price_changes": [{"asset_id": "19458454719947582257633203202425613630572016962838703318400930704175824104136", "price": "0.3", "size": "0", "side": "BUY", "hash": "d6352613330e7ab14b0c729befd9b798715637ef", "best_bid": "0.58", "best_ask": "0.61"}, {"asset_id": "817582445527276447057755966542888616081641371741603398122454732956499627950", "price": "0.7", "size": "0", "side": "SELL", "hash": "ca900a269e6ef350ba27f914f541ce5fe867b787", "best_bid": "0.39", "best_ask": "0.42"}], "timestamp": "1769384876337", "event_type": "price_change"}}
{"_local_timestamp": "2026-01-25T23:47:56.445451+00:00", "data": {"market": "0x715dc274a5c7adf3771646e36d5e3a8844163dc31e7f02331eb30d2b8108bf9e", "price_changes": [{"asset_id": "19458454719947582257633203202425613630572016962838703318400930704175824104136", "price": "0.41", "size": "124", "side": "BUY", "hash": "fd3fe70bc021cdee1f43d8149e22029252ca973c", "best_bid": "0.58", "best_ask": "0.61"}, {"asset_id": "817582445527276447057755966542888616081641371741603398122454732956499627950", "price": "0.59", "size": "124", "side": "SELL", "hash": "d99879e43ff81a1e57aacc7bcfd8521dc5c99a50", "best_bid": "0.39", "best_ask": "0.42"}], "timestamp": "1769384876364", "event_type": "price_change"}}
{"_local_timestamp": "2026-01-25T23:47:56.901691+00:00", "data": {"market": "0xfb08a969a2c05beda8b5743959182db28be71832f9a84872a786e809b77b5350", "price_changes": [{"asset_id": "28670530274590253141384619337562139640467932392972183997943459931027267172276", "price": "0.004", "size": "33.03", "side": "BUY", "hash": "9105ad7ff4752695f00d63f37d6a3a0068e5f80f", "best_bid": "0.026", "best_ask": "0.158"}, {"asset_id": "13908252531396871469657521961663517650827376216919668668811621820614371209132", "price": "0.996", "size": "33.03", "side": "SELL", "hash": "72308574c9811553ccf8d3e26c13cd5bd7119e21", "best_bid": "0.842", "best_ask": "0.974"}], "timestamp": "1769384876825", "event_type": "price_change"}}
{"_local_timestamp": "2026-01-25T23:47:56.901987+00:00", "data": {"market": "0xfb08a969a2c05beda8b5743959182db28be71832f9a84872a786e809b77b5350", "price_changes": [{"asset_id": "28670530274590253141384619337562139640467932392972183997943459931027267172276", "price": "0.005", "size": "0", "side": "BUY", "hash": "9105ad7ff4752695f00d63f37d6a3a0068e5f80f", "best_bid": "0.026", "best_ask": "0.158"}, {"asset_id": "13908252531396871469657521961663517650827376216919668668811621820614371209132", "price": "0.995", "size": "0", "side": "SELL", "hash": "72308574c9811553ccf8d3e26c13cd5bd7119e21", "best_bid": "0.842", "best_ask": "0.974"}], "timestamp": "1769384876825", "event_type": "price_change"}}
{"_local_timestamp": "2026-01-25T23:47:56.902214+00:00", "data": {"market": "0xfb08a969a2c05beda8b5743959182db28be71832f9a84872a786e809b77b5350", "price_changes": [{"asset_id": "28670530274590253141384619337562139640467932392972183997943459931027267172276", "price": "0.015", "size": "33.03", "side": "BUY", "hash": "9105ad7ff4752695f00d63f37d6a3a0068e5f80f", "best_bid": "0.026", "best_ask": "0.158"}, {"asset_id": "13908252531396871469657521961663517650827376216919668668811621820614371209132", "price": "0.985", "size": "33.03", "side": "SELL", "hash": "72308574c9811553ccf8d3e26c13cd5bd7119e21", "best_bid": "0.842", "best_ask": "0.974"}], "timestamp": "1769384876825", "event_type": "price_change"}}
