{"_local_timestamp": "2026-01-25T23:33:31.613953+00:00", "data": [{"market": "0x6a9cec83f126fe719234360176ec90d6e9ddf7738dd18fc24591acfa4ffeb438", "asset_id": "78298172603094196759720747983969683263067089881616851711638692098317616210827", "timestamp": "1769383821027", "hash": "eb6a068057429a0801efc195f5fa82e65c3f51b2", "bids": [{"price": "0.01", "size": "124.81"}], "asks": [{"price": "0.99", "size": "79.41"}, {"price": "0.98", "size": "31.13"}, {"price": "0.95", "size": "30"}, {"price": "0.94", "size": "33"}, {"price": "0.93", "size": "6.25"}, {"price": "0.9", "size": "111.66"}, {"price": "0.89", "size": "7.38"}, {"price": "0.88", "size": "20"}, {"price": "0.82", "size": "86.66"}], "event_type": "book", "last_trade_price": ""}, {"market": "0xfe1bf101fc2fccefb3fc1aa63bad31a8af9c9cd089cee49a18ac5cef2ad3df9d", "asset_id": "106868601358842247470253892236107805424912362944570632749183596082130781890442", "timestamp": "1769383981028", "hash": "d298a962f8de0a4701b3963bc5533e986d765176", "bids": [{"price": "0.01", "size": "81.86"}, {"price": "0.02", "size": "31.03"}, {"price": "0.05", "size": "30"}, {"price": "0.06", "size": "33"}, {"price": "0.07", "size": "6.13"}, {"price": "0.08", "size": "66.66"}, {"price": "0.1", "size": "48"}, {"price": "0.11", "size": "7.25"}, {"price": "0.12", "size": "20"}, {"price": "0.18", "size": "86.66"}], "asks": [{"price": "0.99", "size": "133.52"}], "event_type": "book", "last_trade_price": ""}, {"market": "0xe7ab60d49b4d5747305aaaf0dbe619feb8a22e78d091d6b5daa275f42d16d84a", "asset_id": "45511410739384206088534279412676879327589236940175619921931351874029445093083", "timestamp": "1769384004373", "hash": "77c387182dd07cc6b2c3ef1f6f343a157986b963", "bids": [{"price": "0.01", "size": "51.74"}, {"price": "0.02", "size": "57.76"}, {"price": "0.03", "size": "43.26"}, {"price": "0.05", "size": "210"}, {"price": "0.06", "size": "89.86"}], "asks": [{"price": "0.99", "size": "5612.97"}, {"price": "0.98", "size": "2200"}, {"price": "0.97", "size": "7.9"}, {"price": "0.95", "size": "30"}, {"price": "0.94", "size": "33"}, {"price": "0.93", "size": "6.91"}, {"price": "0.92", "size": "750"}, {"price": "0.91", "size": "20"}, {"price": "0.88", "size": "508.33"}, {"price": "0.84", "size": "350"}, {"price": "0.83", "size": "6.76"}, {"price": "0.8", "size": "140"}, {"price": "0.76", "size": "108.33"}, {"price": "0.72", "size": "85.71"}, {"price": "0.71", "size": "42"}, {"price": "0.68", "size": "62.5"}, {"price": "0.62", "size": "100"}, {"price": "0.61", "size": "5"}, {"price": "0.25", "size": "5"}], "event_type": "book", "last_trade_price": ""}, {"market": "0xfe1bf101fc2fccefb3fc1aa63bad31a8af9c9cd089cee49a18ac5cef2ad3df9d", "asset_id": "14858755749296911737498127480919214289892392705578682755430166976872701509135", "timestamp": "1769383981028", "hash": "ac95f4bc322871fdffb80624add88acdc3c26450", "bids": [{"price": "0.01", "size": "133.52"}], "asks": [{"price": "0.99", "size": "81.86"}, {"price": "0.98", "size": "31.03"}, {"price": "0.95", "size": "30"}, {"price": "0.94", "size": "33"}, {"price": "0.93", "size": "6.13"}, {"price": "0.92", "size": "66.66"}, {"price": "0.9", "size": "48"}, {"price": "0.89", "size": "7.25"}, {"price": "0.88", "size": "20"}, {"price": "0.82", "size": "86.66"}], "event_type": "book", "last_trade_price": ""}, {"market": "0x73ff7789989688f99810a16020072cadd8cc7770a1912045f5db08c13fc32382", "asset_id": "37562085027903904152518421234859398339374813402295085283238242112770810111282", "timestamp": "1769383901938", "hash": "d6d4570573368c8c655e37e92a6a0ec3dffe51d3", "bids": [{"price": "0.01", "size": "48.75"}, {"price": "0.02", "size": "56.23"}, {"price": "0.03", "size": "39.23"}, {"price": "0.05", "size": "10"}, {"price": "0.06", "size": "47.07"}], "asks": [{"price": "0.99", "size": "4606.68"}, {"price": "0.98", "size": "1806.38"}, {"price": "0.97", "size": "300"}, {"price": "0.96", "size": "305.84"}, {"price": "0.95", "size": "130"}, {"price": "0.94", "size": "33"}, {"price": "0.93", "size": "100"}, {"price": "0.92", "size": "25.93"}, {"price": "0.89", "size": "225"}, {"price": "0.83", "size": "150"}, {"price": "0.82", "size": "6.09"}, {"price": "0.64", "size": "100"}, {"price": "0.63", "size": "5"}, {"price": "0.29", "size": "5"}], "event_type": "book", "last_trade_price": ""}, {"market": "0xe7ab60d49b4d5747305aaaf0dbe619feb8a22e78d091d6b5daa275f42d16d84a", "asset_id": "35936290539436654611572364686180136134178663550736813139576585272060876949210", "timestamp": "1769384004373", "hash": "d067500d1fe93aa4f1a98131e8398f2a5394c995", "bids": [{"price": "0.01", "size": "5612.97"}, {"price": "0.02", "size": "2200"}, {"price": "0.03", "size": "7.9"}, {"price": "0.05", "size": "30"}, {"price": "0.06", "size": "33"}, {"price": "0.07", "size": "6.91"}, {"price": "0.08", "size": "750"}, {"price": "0.09", "size": "20"}, {"price": "0.12", "size": "508.33"}, {"price": "0.16", "size": "350"}, {"price": "0.17", "size": "6.76"}, {"price": "0.2", "size": "140"}, {"price": "0.24", "size": "108.33"}, {"price": "0.28", "size": "85.71"}, {"price": "0.29", "size": "42"}, {"price": "0.32", "size": "62.5"}, {"price": "0.38", "size": "100"}, {"price": "0.39", "size": "5"}, {"price": "0.75", "size": "5"}], "asks": [{"price": "0.99", "size": "51.74"}, {"price": "0.98", "size": "57.76"}, {"price": "0.97", "size": "43.26"}, {"price": "0.95", "size": "210"}, {"price": "0.94", "size": "89.86"}], "event_type": "book", "last_trade_price": ""}, {"market": "0x1b8f1648103f01c600898751790f12daf1fa8bba42d19e3794fdf6977d5779c1", "asset_id": "62442318956257168924205035411035853934498981543770714133491707937613119083548", "timestamp": "1769383901913", "hash": "b521e2b5247539481a0112a6e2004d9891ed696e", "bids": [{"price": "0.01", "size": "51.93"}, {"price": "0.02", "size": "57.49"}, {"price": "0.03", "size": "42.92"}, {"price": "0.05", "size": "10"}, {"price": "0.06", "size": "89.52"}], "asks": [{"price": "0.99", "size": "4613.07"}, {"price": "0.98", "size": "1800"}, {"price": "0.97", "size": "307.97"}, {"price": "0.96", "size": "300"}, {"price": "0.95", "size": "230"}, {"price": "0.94", "size": "533"}, {"price": "0.93", "size": "6.94"}, {"price": "0.92", "size": "20"}, {"price": "0.89", "size": "225"}, {"price": "0.84", "size": "200"}, {"price": "0.83", "size": "6.73"}, {"price": "0.77", "size": "75"}, {"price": "0.63", "size": "100"}, {"price": "0.62", "size": "5"}, {"price": "0.35", "size": "13.97"}, {"price": "0.27", "size": "13.97"}], "event_type": "book", "last_trade_price": ""}, {"market": "0x6a9cec83f126fe719234360176ec90d6e9ddf7738dd18fc24591acfa4ffeb438", "asset_id": "108322799557128551277706551902450376060911637056120058762288194247437063581805", "timestamp": "1769383821027", "hash": "09f6f8f18122b173dfd9b92397ad90744fe4477f", "bids": [{"price": "0.01", "size": "79.41"}, {"price": "0.02", "size": "31.13"}, {"price": "0.05", "size": "30"}, {"price": "0.06", "size": "33"}, {"price": "0.07", "size": "6.25"}, {"price": "0.1", "size": "111.66"}, {"price": "0.11", "size": "7.38"}, {"price": "0.12", "size": "20"}, {"price": "0.18", "size": "86.66"}], "asks": [{"price": "0.99", "size": "124.81"}], "event_type": "book", "last_trade_price": ""}, {"market": "0x73ff7789989688f99810a16020072cadd8cc7770a1912045f5db08c13fc32382", "asset_id": "104982584497253080340094031934675952186454655786883785448698311378148350932294", "timestamp": "1769383901938", "hash": "147f9ad250750757e4d3387995971c1d81e43b96", "bids": [{"price": "0.01", "size": "4606.68"}, {"price": "0.02", "size": "1806.38"}, {"price": "0.03", "size": "300"}, {"price": "0.04", "size": "305.84"}, {"price": "0.05", "size": "130"}, {"price": "0.06", "size": "33"}, {"price": "0.07", "size": "100"}, {"price": "0.08", "size": "25.93"}, {"price": "0.11", "size": "225"}, {"price": "0.17", "size": "150"}, {"price": "0.18", "size": "6.09"}, {"price": "0.36", "size": "100"}, {"price": "0.37", "size": "5"}, {"price": "0.71", "size": "5"}], "asks": [{"price": "0.99", "size": "48.75"}, {"price": "0.98", "size": "56.23"}, {"price": "0.97", "size": "39.23"}, {"price": "0.95", "size": "10"}, {"price": "0.94", "size": "47.07"}], "event_type": "book", "last_trade_price": ""}, {"market": "0x1b8f1648103f01c600898751790f12daf1fa8bba42d19e3794fdf6977d5779c1", "asset_id": "69777017473999802256622422036106901974723398553663432971711296907567160107711", "timestamp": "1769383901913", "hash": "b23a2451696b17a3a195381f7c544aaecc7879c3", "bids": [{"price": "0.01", "size": "4613.07"}, {"price": "0.02", "size": "1800"}, {"price": "0.03", "size": "307.97"}, {"price": "0.04", "size": "300"}, {"price": "0.05", "size": "230"}, {"price": "0.06", "size": "533"}, {"price": "0.07", "size": "6.94"}, {"price": "0.08", "size": "20"}, {"price": "0.11", "size": "225"}, {"price": "0.16", "size": "200"}, {"price": "0.17", "size": "6.73"}, {"price": "0.23", "size": "75"}, {"price": "0.37", "size": "100"}, {"price": "0.38", "size": "5"}, {"price": "0.65", "size": "13.97"}, {"price": "0.73", "size": "13.97"}], "asks": [{"price": "0.99", "size": "51.93"}, {"price": "0.98", "size": "57.49"}, {"price": "0.97", "size": "42.92"}, {"price": "0.95", "size": "10"}, {"price": "0.94", "size": "89.52"}], "event_type": "book", "last_trade_price": ""}]}
{"_local_timestamp": "2026-01-25T23:34:12.944241+00:00", "data": {"market": "0x1b8f1648103f01c600898751790f12daf1fa8bba42d19e3794fdf6977d5779c1", "price_changes": [{"asset_id": "69777017473999802256622422036106901974723398553663432971711296907567160107711", "price": "0.04", "size": "200", "side": "BUY", "hash": "cd956c55fd9e8376b974e4c8dd5e52cd2ee11541", "best_bid": "0.73", "best_ask": "0.94"}, {"asset_id": "62442318956257168924205035411035853934498981543770714133491707937613119083548", "price": "0.96", "size": "200", "side": "SELL", "hash": "1bfa24910df4f8d89397163c2bd2bdba8e7d9d06", "best_bid": "0.06", "best_ask": "0.27"}], "timestamp": "1769384052808", "event_type": "price_change"}}
{"_local_timestamp": "2026-01-25T23:34:12.995079+00:00", "data": {"market": "0x73ff7789989688f99810a16020072cadd8cc7770a1912045f5db08c13fc32382", "price_changes": [{"asset_id": "104982584497253080340094031934675952186454655786883785448698311378148350932294", "price": "0.07", "size": "0", "side": "BUY", "hash": "b0be7b798237bd6e73f821a5a5cb089403432a9c", "best_bid": "0.71", "best_ask": "0.94"}, {"asset_id": "37562085027903904152518421234859398339374813402295085283238242112770810111282", "price": "0.93", "size": "0", "side": "SELL", "hash": "b85f3d7691aae6c17e9ad0a4e3b43a524e7a3473", "best_bid": "0.06", "best_ask": "0.29"}], "timestamp": "1769384052808", "event_type": "price_change"}}
{"_local_timestamp": "2026-01-25T23:34:13.444943+00:00", "data": {"market": "0x1b8f1648103f01c600898751790f12daf1fa8bba42d19e3794fdf6977d5779c1", "price_changes": [{"asset_id": "69777017473999802256622422036106901974723398553663432971711296907567160107711", "price": "0.07", "size": "106.94", "side": "BUY", "hash": "f34f13147df14da525c9833e0f7b3c48daf32111", "best_bid": "0.73", "best_ask": "0.94"}, {"asset_id": "62442318956257168924205035411035853934498981543770714133491707937613119083548", "price": "0.93", "size": "106.94", "side": "SELL", "hash": "820e5f8aa6ffa827743e786847836af47015f6e5", "best_bid": "0.06", "best_ask": "0.27"}], "timestamp": "1769384053293", "event_type": "price_change"}}
{"_local_timestamp": "2026-01-25T23:34:13.488679+00:00", "data": {"market": "0x73ff7789989688f99810a16020072cadd8cc7770a1912045f5db08c13fc32382", "price_changes": [{"asset_id": "104982584497253080340094031934675952186454655786883785448698311378148350932294", "price": "0.05", "size": "230", "side": "BUY", "hash": "7845a99e7a1f6a0d2f963208b509da1f290527df", "best_bid": "0.71", "best_ask": "0.94"}, {"asset_id": "37562085027903904152518421234859398339374813402295085283238242112770810111282", "price": "0.95", "size": "230", "side": "SELL", "hash": "bc971be27a957b60ea6e67ca088f554bfff53691", "best_bid": "0.06", "best_ask": "0.29"}], "timestamp": "1769384053293", "event_type": "price_change"}}
{"_local_timestamp": "2026-01-25T23:34:13.783881+00:00", "data": {"market": "0x73ff7789989688f99810a16020072cadd8cc7770a1912045f5db08c13fc32382", "price_changes": [{"asset_id": "104982584497253080340094031934675952186454655786883785448698311378148350932294", "price": "0.08", "size": "5.93", "side": "BUY", "hash": "945026f2d255f09788593f71bfb52242b76ef689", "best_bid": "0.71", "best_ask": "0.94"}, {"asset_id": "37562085027903904152518421234859398339374813402295085283238242112770810111282", "price": "0.92", "size": "5.93", "side": "SELL", "hash": "82f397f23e15eaf906a6faef544d491749d22b54", "best_bid": "0.06", "best_ask": "0.29"}], "timestamp": "1769384053712", "event_type": "price_change"}}
{"_local_timestamp": "2026-01-25T23:34:13.811437+00:00", "data": {"market": "0x73ff7789989688f99810a16020072cadd8cc7770a1912045f5db08c13fc32382", "price_changes": [{"asset_id": "104982584497253080340094031934675952186454655786883785448698311378148350932294", "price": "0.07", "size": "20", "side": "BUY", "hash": "3855e737957527dbcfa051911588245546e322ee", "best_bid": "0.71", "best_ask": "0.94"}, {"asset_id": "37562085027903904152518421234859398339374813402295085283238242112770810111282", "price": "0.93", "size": "20", "side": "SELL", "hash": "9e1d1e5a080a3dc8d690a9f9f64137ae05b52368", "best_bid": "0.06", "best_ask": "0.29"}], "timestamp": "1769384053740", "event_type": "price_change"}}
{"_local_timestamp": "2026-01-25T23:35:17.801671+00:00", "data": {"market": "0x1b8f1648103f01c600898751790f12daf1fa8bba42d19e3794fdf6977d5779c1", "price_changes": [{"asset_id": "69777017473999802256622422036106901974723398553663432971711296907567160107711", "price": "0.01", "size": "4606.44", "side": "BUY", "hash": "c2c153ccc56543abba7f6cfc5c989cf8c330d0f7", "best_bid": "0.73", "best_ask": "0.94"}, {"asset_id": "62442318956257168924205035411035853934498981543770714133491707937613119083548", "price": "0.99", "size": "4606.44", "side": "SELL", "hash": "8258a72ec431bdcbb54991c10278c13f1e819383", "best_bid": "0.06", "best_ask": "0.27"}], "timestamp": "1769384117738", "event_type": "price_change"}}
{"_local_timestamp": "2026-01-25T23:35:17.802561+00:00", "data": {"market": "0x1b8f1648103f01c600898751790f12daf1fa8bba42d19e3794fdf6977d5779c1", "price_changes": [{"asset_id": "69777017473999802256622422036106901974723398553663432971711296907567160107711", "price": "0.03", "size": "300", "side": "BUY", "hash": "c2c153ccc56543abba7f6cfc5c989cf8c330d0f7", "best_bid": "0.73", "best_ask": "0.94"}, {"asset_id": "62442318956257168924205035411035853934498981543770714133491707937613119083548", "price": "0.97", "size": "300", "side": "SELL", "hash": "8258a72ec431bdcbb54991c10278c13f1e819383", "best_bid": "0.06", "best_ask": "0.27"}], "timestamp": "1769384117738", "event_type": "price_change"}}
{"_local_timestamp": "2026-01-25T23:35:17.805710+00:00", "data": {"market": "0x1b8f1648103f01c600898751790f12daf1fa8bba42d19e3794fdf6977d5779c1", "price_changes": [{"asset_id": "69777017473999802256622422036106901974723398553663432971711296907567160107711", "price": "0.07", "size": "100", "side": "BUY", "hash": "c2c153ccc56543abba7f6cfc5c989cf8c330d0f7", "best_bid": "0.73", "best_ask": "0.94"}, {"asset_id": "62442318956257168924205035411035853934498981543770714133491707937613119083548", "price": "0.93", "size": "100", "side": "SELL", "hash": "8258a72ec431bdcbb54991c10278c13f1e819383", "best_bid": "0.06", "best_ask": "0.27"}], "timestamp": "1769384117738", "event_type": "price_change"}}
{"_local_timestamp": "2026-01-25T23:35:18.604641+00:00", "data": {"market": "0x1b8f1648103f01c600898751790f12daf1fa8bba42d19e3794fdf6977d5779c1", "price_changes": [{"asset_id": "69777017473999802256622422036106901974723398553663432971711296907567160107711", "price": "0.08", "size": "25.39", "side": "BUY", "hash": "3b4415672a49ac7663fc9a18c1fbd6c3d02a9e91", "best_bid": "0.73", "best_ask": "0.94"}, {"asset_id": "62442318956257168924205035411035853934498981543770714133491707937613119083548", "price": "0.92", "size": "25.39", "side": "SELL", "hash": "83ffd659e77ce3bb4cf04c8c6ca94a4843739c38", "best_bid": "0.06", "best_ask": "0.27"}], "timestamp": "1769384118534", "event_type": "price_change"}}
{"_local_timestamp": "2026-01-25T23:35:18.605036+00:00", "data": {"market": "0x1b8f1648103f01c600898751790f12daf1fa8bba42d19e3794fdf6977d5779c1", "price_changes": [{"asset_id": "69777017473999802256622422036106901974723398553663432971711296907567160107711", "price": "0.04", "size": "205.81", "side": "BUY", "hash": "dad8d55dff69377c375738c131439ebc9099f049", "best_bid": "0.73", "best_ask": "0.94"}, {"asset_id": "62442318956257168924205035411035853934498981543770714133491707937613119083548", "price": "0.96", "size": "205.81", "side": "SELL", "hash": "6b7c56dfc08a75b1f6d290c09f0cfe389b94cd8d", "best_bid": "0.06", "best_ask": "0.27"}], "timestamp": "1769384118536", "event_type": "price_change"}}
{"_local_timestamp": "2026-01-25T23:35:18.605339+00:00", "data": {"market": "0x1b8f1648103f01c600898751790f12daf1fa8bba42d19e3794fdf6977d5779c1", "price_changes": [{"asset_id": "69777017473999802256622422036106901974723398553663432971711296907567160107711", "price": "0.02", "size": "1806.35", "side": "BUY", "hash": "7f5bd6023c3de048c00fa6041cdef1a846e3fb3b", "best_bid": "0.73", "best_ask": "0.94"}, {"asset_id": "62442318956257168924205035411035853934498981543770714133491707937613119083548", "price": "0.98", "size": "1806.35", "side": "SELL", "hash": "5ecf257faec9aaf58b896ff7dfb4415549bf1a5c", "best_bid": "0.06", "best_ask": "0.27"}], "timestamp": "1769384118537", "event_type": "price_change"}}
{"_local_timestamp": "2026-01-25T23:35:30.837247+00:00", "data": {"market": "0x1b8f1648103f01c600898751790f12daf1fa8bba42d19e3794fdf6977d5779c1", "price_changes": [{"asset_id": "69777017473999802256622422036106901974723398553663432971711296907567160107711", "price": "0.06", "size": "33", "side": "BUY", "hash": "8a784e39646531b522e86f9024fc2685adab1ae4", "best_bid": "0.73", "best_ask": "0.94"}, {"asset_id": "62442318956257168924205035411035853934498981543770714133491707937613119083548", "price": "0.94", "size": "33", "side": "SELL", "hash": "dca9f236116c79fbc470af3c4f845a85cb4f3e46", "best_bid": "0.06", "best_ask": "0.27"}], "timestamp": "1769384130729", "event_type": "price_change"}}
{"_local_timestamp": "2026-01-25T23:35:31.112860+00:00", "data": {"market": "0x73ff7789989688f99810a16020072cadd8cc7770a1912045f5db08c13fc32382", "price_changes": [{"asset_id": "104982584497253080340094031934675952186454655786883785448698311378148350932294", "price": "0.06", "size": "533", "side": "BUY", "hash": "511c05b06afada309fae7b167839879c613ce2ba", "best_bid": "0.71", "best_ask": "0.94"}, {"asset_id": "37562085027903904152518421234859398339374813402295085283238242112770810111282", "price": "0.94", "size": "533", "side": "SELL", "hash": "34d3b554d371f588d036b668635137b9d49a8b9f", "best_bid": "0.06", "best_ask": "0.29"}], "timestamp": "1769384131022", "event_type": "price_change"}}
{"_local_timestamp": "2026-01-25T23:35:31.113359+00:00", "data": {"market": "0x1b8f1648103f01c600898751790f12daf1fa8bba42d19e3794fdf6977d5779c1", "price_changes": [{"asset_id": "69777017473999802256622422036106901974723398553663432971711296907567160107711", "price": "0.07", "size": "600", "side": "BUY", "hash": "62962c8d97d8f8f77cfd09b386b2de3a7a98f49d", "best_bid": "0.73", "best_ask": "0.94"}, {"asset_id": "62442318956257168924205035411035853934498981543770714133491707937613119083548", "price": "0.93", "size": "600", "side": "SELL", "hash": "11a15bec043d94f37c91461a836a4c129cff15e7", "best_bid": "0.06", "best_ask": "0.27"}], "timestamp": "1769384131019", "event_type": "price_change"}}
{"_local_timestamp": "2026-01-25T23:36:48.594429+00:00", "data": {"market": "0xe7ab60d49b4d5747305aaaf0dbe619feb8a22e78d091d6b5daa275f42d16d84a", "price_changes": [{"asset_id": "45511410739384206088534279412676879327589236940175619921931351874029445093083", "price": "0.02", "size": "42", "side": "BUY", "hash": "27f7a2fb1f7d8e4afd10195fa796e80790a3f302", "best_bid": "0.06", "best_ask": "0.25"}, {"asset_id": "35936290539436654611572364686180136134178663550736813139576585272060876949210", "price": "0.98", "size": "42", "side": "SELL", "hash": "038bd305bb0d27e2e73cdf92ad2766f6f89c248c", "best_bid": "0.75", "best_ask": "0.94"}], "timestamp": "1769384208448", "event_type": "price_change"}}
{"_local_timestamp": "2026-01-25T23:36:48.957036+00:00", "data": {"market": "0xe7ab60d49b4d5747305aaaf0dbe619feb8a22e78d091d6b5daa275f42d16d84a", "price_changes": [{"asset_id": "45511410739384206088534279412676879327589236940175619921931351874029445093083", "price": "0.02", "size": "57.76", "side": "BUY", "hash": "c899d7dd71af136d9261ff152930823ffc14a1a1", "best_bid": "0.06", "best_ask": "0.25"}, {"asset_id": "35936290539436654611572364686180136134178663550736813139576585272060876949210", "price": "0.98", "size": "57.76", "side": "SELL", "hash": "bdf082fa23ed069f2b67c1e6fee34d79e3861e08", "best_bid": "0.75", "best_ask": "0.94"}], "timestamp": "1769384208815", "event_type": "price_change"}}
{"_local_timestamp": "2026-01-25T23:37:32.029770+00:00", "data": {"market": "0xfe1bf101fc2fccefb3fc1aa63bad31a8af9c9cd089cee49a18ac5cef2ad3df9d", "price_changes": [{"asset_id": "106868601358842247470253892236107805424912362944570632749183596082130781890442", "price": "0.18", "size": "66.66", "side": "BUY", "hash": "30e1e88cad9ba8805cbf7b08aa9ac8fb8b251420", "best_bid": "0.18", "best_ask": "0.99"}, {"asset_id": "14858755749296911737498127480919214289892392705578682755430166976872701509135", "price": "0.82", "size": "66.66", "side": "SELL", "hash": "c72d0ade2a79640fb72376061e159c4330448bcb", "best_bid": "0.01", "best_ask": "0.82"}], "timestamp": "1769384251912", "event_type": "price_change"}}
{"_local_timestamp": "2026-01-25T23:37:32.037430+00:00", "data": {"market": "0x6a9cec83f126fe719234360176ec90d6e9ddf7738dd18fc24591acfa4ffeb438", "price_changes": [{"asset_id": "108322799557128551277706551902450376060911637056120058762288194247437063581805", "price": "0.18", "size": "66.66", "side": "BUY", "hash": "68ee7dbfae6d59ca5bae25fa8d119484f825bbb1", "best_bid": "0.18", "best_ask": "0.99"}, {"asset_id": "78298172603094196759720747983969683263067089881616851711638692098317616210827", "price": "0.82", "size": "66.66", "side": "SELL", "hash": "0088fc08e076647a50b45c2ab5b4b4f865b91da4", "best_bid": "0.01", "best_ask": "0.82"}], "timestamp": "1769384251912", "event_type": "price_change"}}
{"_local_timestamp": "2026-01-25T23:37:45.346449+00:00", "data": {"market": "0x6a9cec83f126fe719234360176ec90d6e9ddf7738dd18fc24591acfa4ffeb438", "price_changes": [{"asset_id": "108322799557128551277706551902450376060911637056120058762288194247437063581805", "price": "0.18", "size": "0", "side": "BUY", "hash": "f57ef8ada4e101e7d7647bc60bdc0d2bd9bb8bce", "best_bid": "0.12", "best_ask": "0.99"}, {"asset_id": "78298172603094196759720747983969683263067089881616851711638692098317616210827", "price": "0.82", "size": "0", "side": "SELL", "hash": "7b3c952d3821c915301caac0c468e0bee9202d6c", "best_bid": "0.01", "best_ask": "0.88"}], "timestamp": "1769384265224", "event_type": "price_change"}}
{"_local_timestamp": "2026-01-25T23:37:45.346918+00:00", "data": {"market": "0xfe1bf101fc2fccefb3fc1aa63bad31a8af9c9cd089cee49a18ac5cef2ad3df9d", "price_changes": [{"asset_id": "106868601358842247470253892236107805424912362944570632749183596082130781890442", "price": "0.18", "size": "0", "side": "BUY", "hash": "8e2cf17b4909e7a6f8030328d92587596d62f9d1", "best_bid": "0.12", "best_ask": "0.99"}, {"asset_id": "14858755749296911737498127480919214289892392705578682755430166976872701509135", "price": "0.82", "size": "0", "side": "SELL", "hash": "550bc54e94dea50fb31d7ebc199cd3973b472834", "best_bid": "0.01", "best_ask": "0.88"}], "timestamp": "1769384265224", "event_type": "price_change"}}
{"_local_timestamp": "2026-01-25T23:37:46.010248+00:00", "data": {"market": "0x6a9cec83f126fe719234360176ec90d6e9ddf7738dd18fc24591acfa4ffeb438", "price_changes": [{"asset_id": "108322799557128551277706551902450376060911637056120058762288194247437063581805", "price": "0.13", "size": "66.66", "side": "BUY", "hash": "2fb0129a5957574dff680903634afb79d616c1bb", "best_bid": "0.13", "best_ask": "0.99"}, {"asset_id": "78298172603094196759720747983969683263067089881616851711638692098317616210827", "price": "0.87", "size": "66.66", "side": "SELL", "hash": "0648fee4423ee06898b5d88f414a0a8f62c46623", "best_bid": "0.01", "best_ask": "0.87"}], "timestamp": "1769384265885", "event_type": "price_change"}}
{"_local_timestamp": "2026-01-25T23:37:46.054016+00:00", "data": {"market": "0xfe1bf101fc2fccefb3fc1aa63bad31a8af9c9cd089cee49a18ac5cef2ad3df9d", "price_changes": [{"asset_id": "106868601358842247470253892236107805424912362944570632749183596082130781890442", "price": "0.13", "size": "66.66", "side": "BUY", "hash": "73ddc7e25732a48c707f3db8a24ad92433fd81a8", "best_bid": "0.13", "best_ask": "0.99"}, {"asset_id": "14858755749296911737498127480919214289892392705578682755430166976872701509135", "price": "0.87", "size": "66.66", "side": "SELL", "hash": "a9bb1cbc0e90a0ddd0e63c6926ea7b91f823a93d", "best_bid": "0.01", "best_ask": "0.87"}], "timestamp": "1769384265931", "event_type": "price_change"}}
{"_local_timestamp": "2026-01-25T23:37:46.515911+00:00", "data": {"market": "0xfe1bf101fc2fccefb3fc1aa63bad31a8af9c9cd089cee49a18ac5cef2ad3df9d", "price_changes": [{"asset_id": "106868601358842247470253892236107805424912362944570632749183596082130781890442", "price": "0.12", "size": "0", "side": "BUY", "hash": "8ad7baf0af152aa0dd921bc0b5999bcb05de686d", "best_bid": "0.13", "best_ask": "0.99"}, {"asset_id": "14858755749296911737498127480919214289892392705578682755430166976872701509135", "price": "0.88", "size": "0", "side": "SELL", "hash": "9db374d558a47fa129be32576285e284855a8fe2", "best_bid": "0.01", "best_ask": "0.87"}], "timestamp": "1769384266352", "event_type": "price_change"}}
{"_local_timestamp": "2026-01-25T23:37:46.516292+00:00", "data": {"market": "0x6a9cec83f126fe719234360176ec90d6e9ddf7738dd18fc24591acfa4ffeb438", "price_changes": [{"asset_id": "108322799557128551277706551902450376060911637056120058762288194247437063581805", "price": "0.12", "size": "0", "side": "BUY", "hash": "16ef9c599f1c5b191077594fa8a8f63173406d9c", "best_bid": "0.13", "best_ask": "0.99"}, {"asset_id": "78298172603094196759720747983969683263067089881616851711638692098317616210827", "price": "0.88", "size": "0", "side": "SELL", "hash": "9fe9fab068502c42d6ff16fbd44a5f3ff7c34958", "best_bid": "0.01", "best_ask": "0.87"}], "timestamp": "1769384266352", "event_type": "price_change"}}
{"_local_timestamp": "2026-01-25T23:37:46.536151+00:00", "data": {"market": "0xfe1bf101fc2fccefb3fc1aa63bad31a8af9c9cd089cee49a18ac5cef2ad3df9d", "price_changes": [{"asset_id": "106868601358842247470253892236107805424912362944570632749183596082130781890442", "price": "0.14", "size": "20", "side": "BUY", "hash": "beb7f1ef7ea837201f25e0b2d8e84a3353147842", "best_bid": "0.14", "best_ask": "0.99"}, {"asset_id": "14858755749296911737498127480919214289892392705578682755430166976872701509135", "price": "0.86", "size": "20", "side": "SELL", "hash": "4b1fec95403d0e3cd13b51ee5055da7f5a8f3067", "best_bid": "0.01", "best_ask": "0.86"}], "timestamp": "1769384266382", "event_type": "price_change"}}
{"_local_timestamp": "2026-01-25T23:37:46.536543+00:00", "data": {"market": "0x6a9cec83f126fe719234360176ec90d6e9ddf7738dd18fc24591acfa4ffeb438", "price_changes": [{"asset_id": "108322799557128551277706551902450376060911637056120058762288194247437063581805", "price": "0.14", "size": "20", "side": "BUY", "hash": "1662e4e2c44488217a278cde65957342fd21ee3e", "best_bid": "0.14", "best_ask": "0.99"}, {"asset_id": "78298172603094196759720747983969683263067089881616851711638692098317616210827", "price": "0.86", "size": "20", "side": "SELL", "hash": "6fbd52168d150c5ce667dca0cc91736de9ee9f38", "best_bid": "0.01", "best_ask": "0.86"}], "timestamp": "1769384266382", "event_type": "price_change"}}
