{"_local_timestamp": "2026-01-25T23:41:32.642213+00:00", "data": [{"market": "0xd4e866883ef71c1a0686768b2089df0ee27f4bc6fb09fd6c5322826d788446b1", "asset_id": "42562896281558908480353570722568310587471823543536714415123687719180859691787", "timestamp": "1769384440245", "hash": "85d4d083f5a22c0642dd39fcd0c8443834ddd5ad", "bids": [{"price": "0.01", "size": "240.54"}, {"price": "0.02", "size": "100"}, {"price": "0.03", "size": "100"}, {"price": "0.04", "size": "84.25"}, {"price": "0.11", "size": "20"}, {"price": "0.12", "size": "20"}, {"price": "0.14", "size": "20"}, {"price": "0.18", "size": "100"}, {"price": "0.19", "size": "102"}], "asks": [{"price": "0.99", "size": "896.8"}, {"price": "0.98", "size": "350"}, {"price": "0.97", "size": "6.47"}, {"price": "0.96", "size": "100"}, {"price": "0.95", "size": "160"}, {"price": "0.94", "size": "80"}, {"price": "0.93", "size": "23.82"}, {"price": "0.81", "size": "10"}, {"price": "0.52", "size": "38.61"}, {"price": "0.51", "size": "25.5"}, {"price": "0.5", "size": "67"}], "event_type": "book", "last_trade_price": "0.360"}, {"market": "0xeb13f5b879c912aaaa6ea4de58570f48f107db4c74f7e816becf030e6272fd9c", "asset_id": "29829995287367853408312885951206913575599941748874598029431212839187459174632", "timestamp": "1769384434786", "hash": "9a8f3c9bf84f85ab1b39e0d708c96c0b376df29b", "bids": [{"price": "0.01", "size": "794.48"}, {"price": "0.02", "size": "50"}, {"price": "0.03", "size": "6.22"}, {"price": "0.05", "size": "100"}, {"price": "0.06", "size": "38.43"}, {"price": "0.07", "size": "44"}, {"price": "0.12", "size": "107.06"}, {"price": "0.13", "size": "10.56"}, {"price": "0.21", "size": "9"}, {"price": "0.22", "size": "20"}, {"price": "0.81", "size": "3.54"}, {"price": "0.82", "size": "60.5"}], "asks": [{"price": "0.99", "size": "233"}, {"price": "0.98", "size": "116"}, {"price": "0.94", "size": "23.93"}], "event_type": "book", "last_trade_price": "0.120"}, {"market": "0xd4e866883ef71c1a0686768b2089df0ee27f4bc6fb09fd6c5322826d788446b1", "asset_id": "82597844215693023613587868745168688782245401597513036676400621185216539262737", "timestamp": "1769384440245", "hash": "bf8313f7870ea7486b21dbbacda8f52b9f0d2e1a", "bids": [{"price": "0.01", "size": "896.8"}, {"price": "0.02", "size": "350"}, {"price": "0.03", "size": "6.47"}, {"price": "0.04", "size": "100"}, {"price": "0.05", "size": "160"}, {"price": "0.06", "size": "80"}, {"price": "0.07", "size": "23.82"}, {"price": "0.19", "size": "10"}, {"price": "0.48", "size": "38.61"}, {"price": "0.49", "size": "25.5"}, {"price": "0.5", "size": "67"}], "asks": [{"price": "0.99", "size": "240.54"}, {"price": "0.98", "size": "100"}, {"price": "0.97", "size": "100"}, {"price": "0.96", "size": "84.25"}, {"price": "0.89", "size": "20"}, {"price": "0.88", "size": "20"}, {"price": "0.86", "size": "20"}, {"price": "0.82", "size": "100"}, {"price": "0.81", "size": "102"}], "event_type": "book", "last_trade_price": "0.360"}, {"market": "0x360d307c81347c875de7462eacfe5911502a243fd217649c1ca4a3aa508b74b5", "asset_id": "105444447917873248544404578405344916559093921935031004928660089912306272641018", "timestamp": "1769384313285", "hash": "63c2429ac79cb19263da3f7f3afce99e949024a9", "bids": [{"price": "0.01", "size": "233"}, {"price": "0.02", "size": "196"}, {"price": "0.03", "size": "93.06"}], "asks": [{"price": "0.99", "size": "895.06"}, {"price": "0.98", "size": "300"}, {"price": "0.97", "size": "207.77"}, {"price": "0.95", "size": "100"}, {"price": "0.94", "size": "88.26"}, {"price": "0.88", "size": "71"}, {"price": "0.87", "size": "10.23"}, {"price": "0.79", "size": "9"}, {"price": "0.78", "size": "20"}, {"price": "0.2", "size": "5"}, {"price": "0.18", "size": "38.61"}, {"price": "0.17", "size": "23.21"}], "event_type": "book", "last_trade_price": "0.030"}, {"market": "0x4c2eb1c2553628d59b2dbb4640b6d650637bd6a1462cff94334355ae206ae7b4", "asset_id": "42433781921146230236897276928227396822059794002552428345815748354041495759547", "timestamp": "1769384314290", "hash": "79b0f618f11dd740992bebd2af566fa71d2fb948", "bids": [{"price": "0.01", "size": "239.73"}, {"price": "0.02", "size": "100"}, {"price": "0.03", "size": "100"}, {"price": "0.04", "size": "5.45"}, {"price": "0.05", "size": "62"}, {"price": "0.16", "size": "20"}, {"price": "0.18", "size": "120"}, {"price": "0.19", "size": "77"}], "asks": [{"price": "0.99", "size": "895.88"}, {"price": "0.98", "size": "250"}, {"price": "0.97", "size": "306.04"}, {"price": "0.95", "size": "20"}, {"price": "0.94", "size": "8.16"}, {"price": "0.93", "size": "30"}, {"price": "0.92", "size": "15"}, {"price": "0.91", "size": "13.33"}, {"price": "0.78", "size": "9"}, {"price": "0.55", "size": "38.61"}, {"price": "0.54", "size": "20"}, {"price": "0.5", "size": "72.5"}, {"price": "0.43", "size": "12.86"}], "event_type": "book", "last_trade_price": "0.230"}, {"market": "0x528fe62a407a299d927d5b612386a4b4f558d4fb0776460373d7e97e8aea79db", "asset_id": "36208978152381894236053536257317511772939147258243384911045733411987516778587", "timestamp": "1769384286019", "hash": "1587ec6c4ff2c23eae4fc1a415dc884b3c926c2a", "bids": [{"price": "0.01", "size": "239.52"}, {"price": "0.02", "size": "100"}, {"price": "0.03", "size": "100"}, {"price": "0.04", "size": "5.51"}, {"price": "0.05", "size": "62"}, {"price": "0.12", "size": "20"}, {"price": "0.15", "size": "40"}, {"price": "0.17", "size": "100"}, {"price": "0.18", "size": "10"}, {"price": "0.19", "size": "10.11"}, {"price": "0.2", "size": "97"}], "asks": [{"price": "0.99", "size": "895.28"}, {"price": "0.98", "size": "350"}, {"price": "0.97", "size": "205.76"}, {"price": "0.96", "size": "100"}, {"price": "0.95", "size": "20"}, {"price": "0.94", "size": "6.69"}, {"price": "0.93", "size": "30"}, {"price": "0.88", "size": "16"}, {"price": "0.84", "size": "8.14"}, {"price": "0.83", "size": "20"}, {"price": "0.37", "size": "7.5"}, {"price": "0.36", "size": "33.99"}], "event_type": "book", "last_trade_price": "0.640"}, {"market": "0x4c65d9aa2bac477a2a9be69d9f707d9105d805d3d19b76854e23cb18bc08c465", "asset_id": "98682086811885890631327975014650377593666125070789241199777154553006778841258", "timestamp": "1769384434786", "hash": "986bd371e21b9ec38647c1639f08e9b00ad50879", "bids": [{"price": "0.01", "size": "313"}, {"price": "0.02", "size": "300"}, {"price": "0.03", "size": "100"}, {"price": "0.04", "size": "162.91"}, {"price": "0.05", "size": "6.47"}, {"price": "0.06", "size": "93.06"}], "asks": [{"price": "0.99", "size": "894.43"}, {"price": "0.98", "size": "350"}, {"price": "0.97", "size": "205.36"}, {"price": "0.95", "size": "100"}, {"price": "0.94", "size": "83"}, {"price": "0.93", "size": "45.95"}, {"price": "0.88", "size": "16"}, {"price": "0.84", "size": "8.17"}, {"price": "0.83", "size": "20"}, {"price": "0.24", "size": "7.89"}, {"price": "0.22", "size": "5"}, {"price": "0.21", "size": "5"}, {"price": "0.2", "size": "5"}, {"price": "0.19", "size": "5"}, {"price": "0.18", "size": "38.61"}, {"price": "0.13", "size": "10.5"}], "event_type": "book", "last_trade_price": "0.060"}, {"market": "0x4c65d9aa2bac477a2a9be69d9f707d9105d805d3d19b76854e23cb18bc08c465", "asset_id": "56000570238632019339090117389091714658106578523885428868978722779674215227202", "timestamp": "1769384434786", "hash": "464f1b0c6008126247388c17d0ea3111f7c6c077", "bids": [{"price": "0.01", "size": "894.43"}, {"price": "0.02", "size": "350"}, {"price": "0.03", "size": "205.36"}, {"price": "0.05", "size": "100"}, {"price": "0.06", "size": "83"}, {"price": "0.07", "size": "45.95"}, {"price": "0.12", "size": "16"}, {"price": "0.16", "size": "8.17"}, {"price": "0.17", "size": "20"}, {"price": "0.76", "size": "7.89"}, {"price": "0.78", "size": "5"}, {"price": "0.79", "size": "5"}, {"price": "0.8", "size": "5"}, {"price": "0.81", "size": "5"}, {"price": "0.82", "size": "38.61"}, {"price": "0.87", "size": "10.5"}], "asks": [{"price": "0.99", "size": "313"}, {"price": "0.98", "size": "300"}, {"price": "0.97", "size": "100"}, {"price": "0.96", "size": "162.91"}, {"price": "0.95", "size": "6.47"}, {"price": "0.94", "size": "93.06"}], "event_type": "book", "last_trade_price": "0.060"}, {"market": "0xeb13f5b879c912aaaa6ea4de58570f48f107db4c74f7e816becf030e6272fd9c", "asset_id": "113827665827621863662330176029339371613062711060109786539031002756320088862803", "timestamp": "1769384434786", "hash": "a7be57eeb40f348ebed00e71783c4d39896d4996", "bids": [{"price": "0.01", "size": "233"}, {"price": "0.02", "size": "116"}, {"price": "0.06", "size": "23.93"}], "asks": [{"price": "0.99", "size": "794.48"}, {"price": "0.98", "size": "50"}, {"price": "0.97", "size": "6.22"}, {"price": "0.95", "size": "100"}, {"price": "0.94", "size": "38.43"}, {"price": "0.93", "size": "44"}, {"price": "0.88", "size": "107.06"}, {"price": "0.87", "size": "10.56"}, {"price": "0.79", "size": "9"}, {"price": "0.78", "size": "20"}, {"price": "0.19", "size": "3.54"}, {"price": "0.18", "size": "60.5"}], "event_type": "book", "last_trade_price": "0.120"}, {"market": "0x930bda5ea16724849ebd2a879634f3ab04522c45a018a1957bbb0319d118c94e", "asset_id": "1829171049271516235440282127137400632547540012227351935219418265043248885571", "timestamp": "1769384421746", "hash": "16e2acc84774dfaeea1eeecb44b3e7e1f053172a", "bids": [{"price": "0.001", "size": "7437.85"}, {"price": "0.002", "size": "1255.83"}, {"price": "0.003", "size": "1166"}, {"price": "0.004", "size": "10.09"}, {"price": "0.006", "size": "83"}, {"price": "0.01", "size": "2783"}, {"price": "0.011", "size": "5.13"}, {"price": "0.02", "size": "3700"}, {"price": "0.021", "size": "10.21"}, {"price": "0.041", "size": "48"}, {"price": "0.05", "size": "60"}, {"price": "0.06", "size": "233"}, {"price": "0.061", "size": "7.02"}, {"price": "0.113", "size": "425"}, {"price": "0.114", "size": "99.99"}, {"price": "0.16", "size": "250"}, {"price": "0.161", "size": "7.72"}, {"price": "0.213", "size": "150"}, {"price": "0.247", "size": "8"}, {"price": "0.251", "size": "10"}, {"price": "0.253", "size": "45"}, {"price": "0.254", "size": "20"}, {"price": "0.889", "size": "5.84"}, {"price": "0.89", "size": "5"}, {"price": "0.9", "size": "100"}, {"price": "0.915", "size": "8.86"}, {"price": "0.924", "size": "109.09"}, {"price": "0.925", "size": "5"}], "asks": [{"price": "0.999", "size": "1749.72"}, {"price": "0.998", "size": "67.29"}, {"price": "0.997", "size": "400"}, {"price": "0.995", "size": "102"}, {"price": "0.993", "size": "295"}], "event_type": "book", "last_trade_price": "0.009"}, {"market": "0x930bda5ea16724849ebd2a879634f3ab04522c45a018a1957bbb0319d118c94e", "asset_id": "85973355253604996307258416942389548140991752390701227925867193238957025004704", "timestamp": "1769384421746", "hash": "873e62cf02caea13ea9f83adc6546d4e5a738a83", "bids": [{"price": "0.001", "size": "1749.72"}, {"price": "0.002", "size": "67.29"}, {"price": "0.003", "size": "400"}, {"price": "0.005", "size": "102"}, {"price": "0.007", "size": "295"}], "asks": [{"price": "0.999", "size": "7437.85"}, {"price": "0.998", "size": "1255.83"}, {"price": "0.997", "size": "1166"}, {"price": "0.996", "size": "10.09"}, {"price": "0.994", "size": "83"}, {"price": "0.99", "size": "2783"}, {"price": "0.989", "size": "5.13"}, {"price": "0.98", "size": "3700"}, {"price": "0.979", "size": "10.21"}, {"price": "0.959", "size": "48"}, {"price": "0.95", "size": "60"}, {"price": "0.94", "size": "233"}, {"price": "0.939", "size": "7.02"}, {"price": "0.887", "size": "425"}, {"price": "0.886", "size": "99.99"}, {"price": "0.84", "size": "250"}, {"price": "0.839", "size": "7.72"}, {"price": "0.787", "size": "150"}, {"price": "0.753", "size": "8"}, {"price": "0.749", "size": "10"}, {"price": "0.747", "size": "45"}, {"price": "0.746", "size": "20"}, {"price": "0.111", "size": "5.84"}, {"price": "0.11", "size": "5"}, {"price": "0.1", "size": "100"}, {"price": "0.085", "size": "8.86"}, {"price": "0.076", "size": "109.09"}, {"price": "0.075", "size": "5"}], "event_type": "book", "last_trade_price": "0.009"}, {"market": "0x528fe62a407a299d927d5b612386a4b4f558d4fb0776460373d7e97e8aea79db", "asset_id": "102485972951606238793769017987999788096270850857875715717770053964568134356702", "timestamp": "1769384286019", "hash": "01bc9e837a977daff87cfbbcc70105d25dc7d800", "bids": [{"price": "0.01", "size": "895.28"}, {"price": "0.02", "size": "350"}, {"price": "0.03", "size": "205.76"}, {"price": "0.04", "size": "100"}, {"price": "0.05", "size": "20"}, {"price": "0.06", "size": "6.69"}, {"price": "0.07", "size": "30"}, {"price": "0.12", "size": "16"}, {"price": "0.16", "size": "8.14"}, {"price": "0.17", "size": "20"}, {"price": "0.63", "size": "7.5"}, {"price": "0.64", "size": "33.99"}], "asks": [{"price": "0.99", "size": "239.52"}, {"price": "0.98", "size": "100"}, {"price": "0.97", "size": "100"}, {"price": "0.96", "size": "5.51"}, {"price": "0.95", "size": "62"}, {"price": "0.88", "size": "20"}, {"price": "0.85", "size": "40"}, {"price": "0.83", "size": "100"}, {"price": "0.82", "size": "10"}, {"price": "0.81", "size": "10.11"}, {"price": "0.8", "size": "97"}], "event_type": "book", "last_trade_price": "0.640"}, {"market": "0x4c2eb1c2553628d59b2dbb4640b6d650637bd6a1462cff94334355ae206ae7b4", "asset_id": "48370595165483556992313158202325404898706481073615732950100193255535553444828", "timestamp": "1769384314290", "hash": "e2e81752ab9b1bd2d1ecfeebc54c1e1cc8e1b355", "bids": [{"price": "0.01", "size": "895.88"}, {"price": "0.02", "size": "250"}, {"price": "0.03", "size": "306.04"}, {"price": "0.05", "size": "20"}, {"price": "0.06", "size": "8.16"}, {"price": "0.07", "size": "30"}, {"price": "0.08", "size": "15"}, {"price": "0.09", "size": "13.33"}, {"price": "0.22", "size": "9"}, {"price": "0.45", "size": "38.61"}, {"price": "0.46", "size": "20"}, {"price": "0.5", "size": "72.5"}, {"price": "0.57", "size": "12.86"}], "asks": [{"price": "0.99", "size": "239.73"}, {"price": "0.98", "size": "100"}, {"price": "0.97", "size": "100"}, {"price": "0.96", "size": "5.45"}, {"price": "0.95", "size": "62"}, {"price": "0.84", "size": "20"}, {"price": "0.82", "size": "120"}, {"price": "0.81", "size": "77"}], "event_type": "book", "last_trade_price": "0.230"}, {"market": "0x360d307c81347c875de7462eacfe5911502a243fd217649c1ca4a3aa508b74b5", "asset_id": "58819872064062181007250722108850107363593409188335583369532125677052623689183", "timestamp": "1769384313285", "hash": "d5a5e6e5f8081503378f955263a3b0257d64e00f", "bids": [{"price": "0.01", "size": "895.06"}, {"price": "0.02", "size": "300"}, {"price": "0.03", "size": "207.77"}, {"price": "0.05", "size": "100"}, {"price": "0.06", "size": "88.26"}, {"price": "0.12", "size": "71"}, {"price": "0.13", "size": "10.23"}, {"price": "0.21", "size": "9"}, {"price": "0.22", "size": "20"}, {"price": "0.8", "size": "5"}, {"price": "0.82", "size": "38.61"}, {"price": "0.83", "size": "23.21"}], "asks": [{"price": "0.99", "size": "233"}, {"price": "0.98", "size": "196"}, {"price": "0.97", "size": "93.06"}], "event_type": "book", "last_trade_price": "0.030"}]}
{"_local_timestamp": "2026-01-25T23:41:37.636030+00:00", "data": {"market": "0x930bda5ea16724849ebd2a879634f3ab04522c45a018a1957bbb0319d118c94e", "price_changes": [{"asset_id": "85973355253604996307258416942389548140991752390701227925867193238957025004704", "price": "0.887", "size": "325", "side": "SELL", "hash": "2d41a43e5134e1ea6eedf721be9adc141f77e5b0", "best_bid": "0.007", "best_ask": "0.075"}, {"asset_id": "1829171049271516235440282127137400632547540012227351935219418265043248885571", "price": "0.113", "size": "325", "side": "BUY", "hash": "b8f6504a9957ab4198e291a989eeb2e9afe8601d", "best_bid": "0.925", "best_ask": "0.993"}], "timestamp": "1769384497500", "event_type": "price_change"}}
{"_local_timestamp": "2026-01-25T23:41:37.903059+00:00", "data": {"market": "0x930bda5ea16724849ebd2a879634f3ab04522c45a018a1957bbb0319d118c94e", "price_changes": [{"asset_id": "85973355253604996307258416942389548140991752390701227925867193238957025004704", "price": "0.886", "size": "199.99", "side": "SELL", "hash": "dfbcf6976e703d72091e4e2760bcf3fd24f71e0b", "best_bid": "0.007", "best_ask": "0.075"}, {"asset_id": "1829171049271516235440282127137400632547540012227351935219418265043248885571", "price": "0.114", "size": "199.99", "side": "BUY", "hash": "878d23af8eaeac16737af610d54feea81353e32c", "best_bid": "0.925", "best_ask": "0.993"}], "timestamp": "1769384497763", "event_type": "price_change"}}
{"_local_timestamp": "2026-01-25T23:41:42.815128+00:00", "data": {"market": "0x4c65d9aa2bac477a2a9be69d9f707d9105d805d3d19b76854e23cb18bc08c465", "price_changes": [{"asset_id": "56000570238632019339090117389091714658106578523885428868978722779674215227202", "price": "0.01", "size": "888.12", "side": "BUY", "hash": "33d9420b4bb4a96298f68d65d63e6bf93149c0e0", "best_bid": "0.87", "best_ask": "0.94"}, {"asset_id": "98682086811885890631327975014650377593666125070789241199777154553006778841258", "price": "0.99", "size": "888.12", "side": "SELL", "hash": "905d7e71be7f2befbee117efb821d9a3bbd09694", "best_bid": "0.06", "best_ask": "0.13"}], "timestamp": "1769384502745", "event_type": "price_change"}}
{"_local_timestamp": "2026-01-25T23:41:42.816212+00:00", "data": {"market": "0x4c65d9aa2bac477a2a9be69d9f707d9105d805d3d19b76854e23cb18bc08c465", "price_changes": [{"asset_id": "56000570238632019339090117389091714658106578523885428868978722779674215227202", "price": "0.03", "size": "200", "side": "BUY", "hash": "33d9420b4bb4a96298f68d65d63e6bf93149c0e0", "best_bid": "0.87", "best_ask": "0.94"}, {"asset_id": "98682086811885890631327975014650377593666125070789241199777154553006778841258", "price": "0.97", "size": "200", "side": "SELL", "hash": "905d7e71be7f2befbee117efb821d9a3bbd09694", "best_bid": "0.06", "best_ask": "0.13"}], "timestamp": "1769384502745", "event_type": "price_change"}}
{"_local_timestamp": "2026-01-25T23:41:42.816752+00:00", "data": {"market": "0x4c65d9aa2bac477a2a9be69d9f707d9105d805d3d19b76854e23cb18bc08c465", "price_changes": [{"asset_id": "56000570238632019339090117389091714658106578523885428868978722779674215227202", "price": "0.07", "size": "40", "side": "BUY", "hash": "33d9420b4bb4a96298f68d65d63e6bf93149c0e0", "best_bid": "0.87", "best_ask": "0.94"}, {"asset_id": "98682086811885890631327975014650377593666125070789241199777154553006778841258", "price": "0.93", "size": "40", "side": "SELL", "hash": "905d7e71be7f2befbee117efb821d9a3bbd09694", "best_bid": "0.06", "best_ask": "0.13"}], "timestamp": "1769384502745", "event_type": "price_change"}}
{"_local_timestamp": "2026-01-25T23:41:42.817271+00:00", "data": {"market": "0x4c65d9aa2bac477a2a9be69d9f707d9105d805d3d19b76854e23cb18bc08c465", "price_changes": [{"asset_id": "56000570238632019339090117389091714658106578523885428868978722779674215227202", "price": "0.16", "size": "0", "side": "BUY", "hash": "33d9420b4bb4a96298f68d65d63e6bf93149c0e0", "best_bid": "0.87", "best_ask": "0.94"}, {"asset_id": "98682086811885890631327975014650377593666125070789241199777154553006778841258", "price": "0.84", "size": "0", "side": "SELL", "hash": "905d7e71be7f2befbee117efb821d9a3bbd09694", "best_bid": "0.06", "best_ask": "0.13"}], "timestamp": "1769384502745", "event_type": "price_change"}}
{"_local_timestamp": "2026-01-25T23:41:43.141015+00:00", "data": {"market": "0x4c65d9aa2bac477a2a9be69d9f707d9105d805d3d19b76854e23cb18bc08c465", "price_changes": [{"asset_id": "56000570238632019339090117389091714658106578523885428868978722779674215227202", "price": "0.18", "size": "6.64", "side": "BUY", "hash": "4eadfc28289722b2a608517b41b090781c963e93", "best_bid": "0.87", "best_ask": "0.94"}, {"asset_id": "98682086811885890631327975014650377593666125070789241199777154553006778841258", "price": "0.82", "size": "6.64", "side": "SELL", "hash": "63d8c4426613c7364870839585afeebaf49ae651", "best_bid": "0.06", "best_ask": "0.13"}], "timestamp": "1769384503078", "event_type": "price_change"}}
{"_local_timestamp": "2026-01-25T23:41:43.198934+00:00", "data": {"market": "0x4c65d9aa2bac477a2a9be69d9f707d9105d805d3d19b76854e23cb18bc08c465", "price_changes": [{"asset_id": "56000570238632019339090117389091714658106578523885428868978722779674215227202", "price": "0.04", "size": "5.18", "side": "BUY", "hash": "c996aa1d5a1b7ab071a12a3bba1718dd038d7148", "best_bid": "0.87", "best_ask": "0.94"}, {"asset_id": "98682086811885890631327975014650377593666125070789241199777154553006778841258", "price": "0.96", "size": "5.18", "side": "SELL", "hash": "b4a1857c07cfaab0ef7a606603d8edfb6d98f760", "best_bid": "0.06", "best_ask": "0.13"}], "timestamp": "1769384503131", "event_type": "price_change"}}
{"_local_timestamp": "2026-01-25T23:41:43.199818+00:00", "data": {"market": "0x4c65d9aa2bac477a2a9be69d9f707d9105d805d3d19b76854e23cb18bc08c465", "price_changes": [{"asset_id": "56000570238632019339090117389091714658106578523885428868978722779674215227202", "price": "0.02", "size": "355.59", "side": "BUY", "hash": "879c258248874f5df83763e4ff063fe326495e9f", "best_bid": "0.87", "best_ask": "0.94"}, {"asset_id": "98682086811885890631327975014650377593666125070789241199777154553006778841258", "price": "0.98", "size": "355.59", "side": "SELL", "hash": "45b5885d788402da2a6d255f42d4c9cd594436ca", "best_bid": "0.06", "best_ask": "0.13"}], "timestamp": "1769384503132", "event_type": "price_change"}}
{"_local_timestamp": "2026-01-25T23:41:43.200420+00:00", "data": {"market": "0x4c65d9aa2bac477a2a9be69d9f707d9105d805d3d19b76854e23cb18bc08c465", "price_changes": [{"asset_id": "56000570238632019339090117389091714658106578523885428868978722779674215227202", "price": "0.08", "size": "5.42", "side": "BUY", "hash": "58c6407459941cc79917916371c561abfc068a59", "best_bid": "0.87", "best_ask": "0.94"}, {"asset_id": "98682086811885890631327975014650377593666125070789241199777154553006778841258", "price": "0.92", "size": "5.42", "side": "SELL", "hash": "6c5d9296c3a43f1b0bf3244f7b76b3d4e5cc247f", "best_bid": "0.06", "best_ask": "0.13"}], "timestamp": "1769384503133", "event_type": "price_change"}}
{"_local_timestamp": "2026-01-25T23:41:45.570063+00:00", "data": {"market": "0x4c65d9aa2bac477a2a9be69d9f707d9105d805d3d19b76854e23cb18bc08c465", "price_changes": [{"asset_id": "56000570238632019339090117389091714658106578523885428868978722779674215227202", "price": "0.17", "size": "0", "side": "BUY", "hash": "cd8d3d9d558adbeba7ef5fbb3282862a3596864c", "best_bid": "0.87", "best_ask": "0.94"}, {"asset_id": "98682086811885890631327975014650377593666125070789241199777154553006778841258", "price": "0.83", "size": "0", "side": "SELL", "hash": "4ad30d72887ba022fe77493e654c86dd474fb140", "best_bid": "0.06", "best_ask": "0.13"}], "timestamp": "1769384505507", "event_type": "price_change"}}
{"_local_timestamp": "2026-01-25T23:41:45.593872+00:00", "data": {"market": "0x4c65d9aa2bac477a2a9be69d9f707d9105d805d3d19b76854e23cb18bc08c465", "price_changes": [{"asset_id": "56000570238632019339090117389091714658106578523885428868978722779674215227202", "price": "0.19", "size": "20", "side": "BUY", "hash": "6f5b1390e206a3cdee7a25b19aea27e13817df1d", "best_bid": "0.87", "best_ask": "0.94"}, {"asset_id": "98682086811885890631327975014650377593666125070789241199777154553006778841258", "price": "0.81", "size": "20", "side": "SELL", "hash": "85b92fb848f6b98151504a030361e97d5ec2ee0e", "best_bid": "0.06", "best_ask": "0.13"}], "timestamp": "1769384505531", "event_type": "price_change"}}
{"_local_timestamp": "2026-01-25T23:41:47.222983+00:00", "data": {"market": "0x528fe62a407a299d927d5b612386a4b4f558d4fb0776460373d7e97e8aea79db", "price_changes": [{"asset_id": "102485972951606238793769017987999788096270850857875715717770053964568134356702", "price": "0.01", "size": "888.67", "side": "BUY", "hash": "e2cdd397de3de7116a0e062ae2ec4467df638f9e", "best_bid": "0.64", "best_ask": "0.8"}, {"asset_id": "36208978152381894236053536257317511772939147258243384911045733411987516778587", "price": "0.99", "size": "888.67", "side": "SELL", "hash": "a1de3cbe9e89e48ebd7682253f0483be7c8aaefb", "best_bid": "0.2", "best_ask": "0.36"}], "timestamp": "1769384507156", "event_type": "price_change"}}
{"_local_timestamp": "2026-01-25T23:41:47.223628+00:00", "data": {"market": "0x528fe62a407a299d927d5b612386a4b4f558d4fb0776460373d7e97e8aea79db", "price_changes": [{"asset_id": "102485972951606238793769017987999788096270850857875715717770053964568134356702", "price": "0.03", "size": "200", "side": "BUY", "hash": "e2cdd397de3de7116a0e062ae2ec4467df638f9e", "best_bid": "0.64", "best_ask": "0.8"}, {"asset_id": "36208978152381894236053536257317511772939147258243384911045733411987516778587", "price": "0.97", "size": "200", "side": "SELL", "hash": "a1de3cbe9e89e48ebd7682253f0483be7c8aaefb", "best_bid": "0.2", "best_ask": "0.36"}], "timestamp": "1769384507156", "event_type": "price_change"}}
{"_local_timestamp": "2026-01-25T23:41:47.224221+00:00", "data": {"market": "0x528fe62a407a299d927d5b612386a4b4f558d4fb0776460373d7e97e8aea79db", "price_changes": [{"asset_id": "102485972951606238793769017987999788096270850857875715717770053964568134356702", "price": "0.06", "size": "0", "side": "BUY", "hash": "e2cdd397de3de7116a0e062ae2ec4467df638f9e", "best_bid": "0.64", "best_ask": "0.8"}, {"asset_id": "36208978152381894236053536257317511772939147258243384911045733411987516778587", "price": "0.94", "size": "0", "side": "SELL", "hash": "a1de3cbe9e89e48ebd7682253f0483be7c8aaefb", "best_bid": "0.2", "best_ask": "0.36"}], "timestamp": "1769384507156", "event_type": "price_change"}}
{"_local_timestamp": "2026-01-25T23:41:47.224745+00:00", "data": {"market": "0x528fe62a407a299d927d5b612386a4b4f558d4fb0776460373d7e97e8aea79db", "price_changes": [{"asset_id": "102485972951606238793769017987999788096270850857875715717770053964568134356702", "price": "0.16", "size": "0", "side": "BUY", "hash": "e2cdd397de3de7116a0e062ae2ec4467df638f9e", "best_bid": "0.64", "best_ask": "0.8"}, {"asset_id": "36208978152381894236053536257317511772939147258243384911045733411987516778587", "price": "0.84", "size": "0", "side": "SELL", "hash": "a1de3cbe9e89e48ebd7682253f0483be7c8aaefb", "best_bid": "0.2", "best_ask": "0.36"}], "timestamp": "1769384507156", "event_type": "price_change"}}
{"_local_timestamp": "2026-01-25T23:41:47.534918+00:00", "data": {"market": "0x528fe62a407a299d927d5b612386a4b4f558d4fb0776460373d7e97e8aea79db", "price_changes": [{"asset_id": "102485972951606238793769017987999788096270850857875715717770053964568134356702", "price": "0.18", "size": "6.29", "side": "BUY", "hash": "f30ddd14f5887b2aa7da73c0415d2e6c6ca1aa95", "best_bid": "0.64", "best_ask": "0.8"}, {"asset_id": "36208978152381894236053536257317511772939147258243384911045733411987516778587", "price": "0.82", "size": "6.29", "side": "SELL", "hash": "a8c37f688dc045bc5b2ebd1d8cab2cc590d8812d", "best_bid": "0.2", "best_ask": "0.36"}], "timestamp": "1769384507468", "event_type": "price_change"}}
{"_local_timestamp": "2026-01-25T23:41:47.535670+00:00", "data": {"market": "0x528fe62a407a299d927d5b612386a4b4f558d4fb0776460373d7e97e8aea79db", "price_changes": [{"asset_id": "102485972951606238793769017987999788096270850857875715717770053964568134356702", "price": "0.02", "size": "356", "side": "BUY", "hash": "2055c35d036fc00a46805981180c922c785f51f3", "best_bid": "0.64", "best_ask": "0.8"}, {"asset_id": "36208978152381894236053536257317511772939147258243384911045733411987516778587", "price": "0.98", "size": "356", "side": "SELL", "hash": "064ac80336452aafd8bdaecdbbdbcdadd13e863b", "best_bid": "0.2", "best_ask": "0.36"}], "timestamp": "1769384507469", "event_type": "price_change"}}
{"_local_timestamp": "2026-01-25T23:41:47.536307+00:00", "data": {"market": "0x528fe62a407a299d927d5b612386a4b4f558d4fb0776460373d7e97e8aea79db", "price_changes": [{"asset_id": "102485972951606238793769017987999788096270850857875715717770053964568134356702", "price": "0.08", "size": "5.83", "side": "BUY", "hash": "71844dfc18192a484521fdb6dc9c6a0581e8ac27", "best_bid": "0.64", "best_ask": "0.8"}, {"asset_id": "36208978152381894236053536257317511772939147258243384911045733411987516778587", "price": "0.92", "size": "5.83", "side": "SELL", "hash": "2d60abbe2faa0e9daeeff562c2b2223c64094311", "best_bid": "0.2", "best_ask": "0.36"}], "timestamp": "1769384507469", "event_type": "price_change"}}
{"_local_timestamp": "2026-01-25T23:41:47.540522+00:00", "data": {"market": "0x528fe62a407a299d927d5b612386a4b4f558d4fb0776460373d7e97e8aea79db", "price_changes": [{"asset_id": "102485972951606238793769017987999788096270850857875715717770053964568134356702", "price": "0.04", "size": "105.56", "side": "BUY", "hash": "ec50e7bf9402881ccf38b06189c90d2d60d8a80c", "best_bid": "0.64", "best_ask": "0.8"}, {"asset_id": "36208978152381894236053536257317511772939147258243384911045733411987516778587", "price": "0.96", "size": "105.56", "side": "SELL", "hash": "9cfb38c97224023cfca01debdb64b04f84c209e7", "best_bid": "0.2", "best_ask": "0.36"}], "timestamp": "1769384507470", "event_type": "price_change"}}
{"_local_timestamp": "2026-01-25T23:41:48.563443+00:00", "data": {"market": "0x528fe62a407a299d927d5b612386a4b4f558d4fb0776460373d7e97e8aea79db", "price_changes": [{"asset_id": "102485972951606238793769017987999788096270850857875715717770053964568134356702", "price": "0.17", "size": "0", "side": "BUY", "hash": "3007bee21024842f7f7bfef6fb2e1daec99cb0dd", "best_bid": "0.64", "best_ask": "0.8"}, {"asset_id": "36208978152381894236053536257317511772939147258243384911045733411987516778587", "price": "0.83", "size": "0", "side": "SELL", "hash": "5dc5068b81aa8c9c021edfbcd5a3f0bc9b8f4b22", "best_bid": "0.2", "best_ask": "0.36"}], "timestamp": "1769384508498", "event_type": "price_change"}}
{"_local_timestamp": "2026-01-25T23:41:48.593991+00:00", "data": {"market": "0x528fe62a407a299d927d5b612386a4b4f558d4fb0776460373d7e97e8aea79db", "price_changes": [{"asset_id": "102485972951606238793769017987999788096270850857875715717770053964568134356702", "price": "0.19", "size": "20", "side": "BUY", "hash": "1e820fd077090c737a771649e3e23d45343fda8c", "best_bid": "0.64", "best_ask": "0.8"}, {"asset_id": "36208978152381894236053536257317511772939147258243384911045733411987516778587", "price": "0.81", "size": "20", "side": "SELL", "hash": "99895125fa0616bf2710ee4bb368465cd74096b7", "best_bid": "0.2", "best_ask": "0.36"}], "timestamp": "1769384508527", "event_type": "price_change"}}
{"_local_timestamp": "2026-01-25T23:42:38.817627+00:00", "data": {"market": "0x360d307c81347c875de7462eacfe5911502a243fd217649c1ca4a3aa508b74b5", "price_changes": [{"asset_id": "105444447917873248544404578405344916559093921935031004928660089912306272641018", "price": "0.04", "size": "20", "side": "BUY", "hash": "646110f2c97657b3c9ec165bd2fbae43399c2d9b", "best_bid": "0.04", "best_ask": "0.17"}, {"asset_id": "58819872064062181007250722108850107363593409188335583369532125677052623689183", "price": "0.96", "size": "20", "side": "SELL", "hash": "fd4ba255c84d6dd6d053160ba50ce88fbd53aa7b", "best_bid": "0.83", "best_ask": "0.96"}], "timestamp": "1769384558753", "event_type": "price_change"}}
{"_local_timestamp": "2026-01-25T23:42:41.330364+00:00", "data": {"market": "0xd4e866883ef71c1a0686768b2089df0ee27f4bc6fb09fd6c5322826d788446b1", "price_changes": [{"asset_id": "82597844215693023613587868745168688782245401597513036676400621185216539262737", "price": "0.49", "size": "5.5", "side": "BUY", "hash": "12be023078d4ff2d16afc2e2d3608ef556433498", "best_bid": "0.5", "best_ask": "0.81"}, {"asset_id": "42562896281558908480353570722568310587471823543536714415123687719180859691787", "price": "0.51", "size": "5.5", "side": "SELL", "hash": "eb03b4e37998e497077bf7472544a3ac30c06986", "best_bid": "0.19", "best_ask": "0.5"}], "timestamp": "1769384561263", "event_type": "price_change"}}
{"_local_timestamp": "2026-01-25T23:42:41.331522+00:00", "data": {"market": "0x4c2eb1c2553628d59b2dbb4640b6d650637bd6a1462cff94334355ae206ae7b4", "price_changes": [{"asset_id": "48370595165483556992313158202325404898706481073615732950100193255535553444828", "price": "0.46", "size": "0", "side": "BUY", "hash": "164fe11e5c9e2c8bab66537ff83f0d869532138e", "best_bid": "0.57", "best_ask": "0.81"}, {"asset_id": "42433781921146230236897276928227396822059794002552428345815748354041495759547", "price": "0.54", "size": "0", "side": "SELL", "hash": "f7645a9d0a826b86e5c245888a30ca5a94c68feb", "best_bid": "0.19", "best_ask": "0.43"}], "timestamp": "1769384561263", "event_type": "price_change"}}
{"_local_timestamp": "2026-01-25T23:42:41.386569+00:00", "data": {"market": "0xd4e866883ef71c1a0686768b2089df0ee27f4bc6fb09fd6c5322826d788446b1", "price_changes": [{"asset_id": "82597844215693023613587868745168688782245401597513036676400621185216539262737", "price": "0.5", "size": "87", "side": "BUY", "hash": "c75dfcebe7a034cab0a7c3580c14a5af42a589d8", "best_bid": "0.5", "best_ask": "0.81"}, {"asset_id": "42562896281558908480353570722568310587471823543536714415123687719180859691787", "price": "0.5", "size": "87", "side": "SELL", "hash": "e50e78ef500926d955a12f8eb9fd288ca60b94e9", "best_bid": "0.19", "best_ask": "0.5"}], "timestamp": "1769384561307", "event_type": "price_change"}}
{"_local_timestamp": "2026-01-25T23:42:41.387273+00:00", "data": {"market": "0x4c2eb1c2553628d59b2dbb4640b6d650637bd6a1462cff94334355ae206ae7b4", "price_changes": [{"asset_id": "48370595165483556992313158202325404898706481073615732950100193255535553444828", "price": "0.5", "size": "92.5", "side": "BUY", "hash": "e7892a728d22dfc491805c4c585224f07c081857", "best_bid": "0.57", "best_ask": "0.81"}, {"asset_id": "42433781921146230236897276928227396822059794002552428345815748354041495759547", "price": "0.5", "size": "92.5", "side": "SELL", "hash": "a68d343523b9e6569464d5eaa74ae2a43cd80ad7", "best_bid": "0.19", "best_ask": "0.43"}], "timestamp": "1769384561307", "event_type": "price_change"}}
{"_local_timestamp": "2026-01-25T23:42:42.773092+00:00", "data": {"market": "0x930bda5ea16724849ebd2a879634f3ab04522c45a018a1957bbb0319d118c94e", "price_changes": [{"asset_id": "85973355253604996307258416942389548140991752390701227925867193238957025004704", "price": "0.008", "size": "20", "side": "BUY", "hash": "e82d3c1adcdc0186bcd8c8fee4cb5a79e5a351b9", "best_bid": "0.008", "best_ask": "0.075"}, {"asset_id": "1829171049271516235440282127137400632547540012227351935219418265043248885571", "price": "0.992", "size": "20", "side": "SELL", "hash": "79e9706cb19dcea8fce25a863b28b637e57eb4be", "best_bid": "0.925", "best_ask": "0.992"}], "timestamp": "1769384562680", "event_type": "price_change"}}
{"_local_timestamp": "2026-01-25T23:43:10.643365+00:00", "data": {"market": "0x930bda5ea16724849ebd2a879634f3ab04522c45a018a1957bbb0319d118c94e", "price_changes": [{"asset_id": "85973355253604996307258416942389548140991752390701227925867193238957025004704", "price": "0.001", "size": "1732", "side": "BUY", "hash": "d44225c78310caddb386559a184515007c860a4d", "best_bid": "0.008", "best_ask": "0.075"}, {"asset_id": "1829171049271516235440282127137400632547540012227351935219418265043248885571", "price": "0.999", "size": "1732", "side": "SELL", "hash": "03799cd345bb923e8b4864d5107caca18d24a661", "best_bid": "0.925", "best_ask": "0.992"}], "timestamp": "1769384590568", "event_type": "price_change"}}
{"_local_timestamp": "2026-01-25T23:43:10.644687+00:00", "data": {"market": "0x930bda5ea16724849ebd2a879634f3ab04522c45a018a1957bbb0319d118c94e", "price_changes": [{"asset_id": "85973355253604996307258416942389548140991752390701227925867193238957025004704", "price": "0.002", "size": "43.83", "side": "BUY", "hash": "d44225c78310caddb386559a184515007c860a4d", "best_bid": "0.008", "best_ask": "0.075"}, {"asset_id": "1829171049271516235440282127137400632547540012227351935219418265043248885571", "price": "0.998", "size": "43.83", "side": "SELL", "hash": "03799cd345bb923e8b4864d5107caca18d24a661", "best_bid": "0.925", "best_ask": "0.992"}], "timestamp": "1769384590568", "event_type": "price_change"}}
{"_local_timestamp": "2026-01-25T23:43:10.919211+00:00", "data": {"market": "0x930bda5ea16724849ebd2a879634f3ab04522c45a018a1957bbb0319d118c94e", "price_changes": [{"asset_id": "85973355253604996307258416942389548140991752390701227925867193238957025004704", "price": "0.003", "size": "423.5", "side": "BUY", "hash": "cba78e18212d9b79b39752c843469defa9dff9ab", "best_bid": "0.008", "best_ask": "0.075"}, {"asset_id": "1829171049271516235440282127137400632547540012227351935219418265043248885571", "price": "0.997", "size": "423.5", "side": "SELL", "hash": "b2a599d1dfa316034e758ff2d07182345c327032", "best_bid": "0.925", "best_ask": "0.992"}], "timestamp": "1769384590855", "event_type": "price_change"}}
{"_local_timestamp": "2026-01-25T23:43:11.906390+00:00", "data": {"market": "0x4c65d9aa2bac477a2a9be69d9f707d9105d805d3d19b76854e23cb18bc08c465", "price_changes": [{"asset_id": "98682086811885890631327975014650377593666125070789241199777154553006778841258", "price": "0.01", "size": "341.57", "side": "BUY", "hash": "81702ae55dc3102fbf36f07a0d8710eb41e59ce0", "best_bid": "0.06", "best_ask": "0.13"}, {"asset_id": "56000570238632019339090117389091714658106578523885428868978722779674215227202", "price": "0.99", "size": "341.57", "side": "SELL", "hash": "eebb12a9d07e9af0656d17e6fd7e416f5f25063f", "best_bid": "0.87", "best_ask": "0.94"}], "timestamp": "1769384591843", "event_type": "price_change"}}
{"_local_timestamp": "2026-01-25T23:43:12.119595+00:00", "data": {"market": "0xeb13f5b879c912aaaa6ea4de58570f48f107db4c74f7e816becf030e6272fd9c", "price_changes": [{"asset_id": "113827665827621863662330176029339371613062711060109786539031002756320088862803", "price": "0.01", "size": "261.57", "side": "BUY", "hash": "ff50db14a47c9c49ffe3707ea1e5262457adaeca", "best_bid": "0.06", "best_ask": "0.18"}, {"asset_id": "29829995287367853408312885951206913575599941748874598029431212839187459174632", "price": "0.99", "size": "261.57", "side": "SELL", "hash": "947cd7c363492ec8ef0179a84d42942b3bc17606", "best_bid": "0.82", "best_ask": "0.94"}], "timestamp": "1769384592051", "event_type": "price_change"}}
{"_local_timestamp": "2026-01-25T23:44:08.366038+00:00", "data": {"market": "0x930bda5ea16724849ebd2a879634f3ab04522c45a018a1957bbb0319d118c94e", "price_changes": [{"asset_id": "1829171049271516235440282127137400632547540012227351935219418265043248885571", "price": "0.113", "size": "200", "side": "BUY", "hash": "8a72fa2103c367ed2e50e8aa6a87c7baa200c1c1", "best_bid": "0.925", "best_ask": "0.992"}, {"asset_id": "85973355253604996307258416942389548140991752390701227925867193238957025004704", "price": "0.887", "size": "200", "side": "SELL", "hash": "d0da927fbfca37020da2866f63e5bbcfac30210e", "best_bid": "0.008", "best_ask": "0.075"}], "timestamp": "1769384648226", "event_type": "price_change"}}
{"_local_timestamp": "2026-01-25T23:44:08.928286+00:00", "data": {"market": "0x930bda5ea16724849ebd2a879634f3ab04522c45a018a1957bbb0319d118c94e", "price_changes": [{"asset_id": "1829171049271516235440282127137400632547540012227351935219418265043248885571", "price": "0.114", "size": "324.99", "side": "BUY", "hash": "26dbfbc734d0cde57ae32a43f994643e4256931e", "best_bid": "0.925", "best_ask": "0.992"}, {"asset_id": "85973355253604996307258416942389548140991752390701227925867193238957025004704", "price": "0.886", "size": "324.99", "side": "SELL", "hash": "0fdbb3ff7cba3421f5ac3aee7ab8d81fd612fc8e", "best_bid": "0.008", "best_ask": "0.075"}], "timestamp": "1769384648766", "event_type": "price_change"}}
{"_local_timestamp": "2026-01-25T23:44:20.489641+00:00", "data": {"market": "0x930bda5ea16724849ebd2a879634f3ab04522c45a018a1957bbb0319d118c94e", "price_changes": [{"asset_id": "1829171049271516235440282127137400632547540012227351935219418265043248885571", "price": "0.113", "size": "0", "side": "BUY", "hash": "bcdd1b28d91e0a28e270c142a583b929e88b5661", "best_bid": "0.925", "best_ask": "0.992"}, {"asset_id": "85973355253604996307258416942389548140991752390701227925867193238957025004704", "price": "0.887", "size": "0", "side": "SELL", "hash": "8cafec6cdb84ee7f4c22575eccaa34cb6f1535bd", "best_bid": "0.008", "best_ask": "0.075"}], "timestamp": "1769384660421", "event_type": "price_change"}}
{"_local_timestamp": "2026-01-25T23:44:21.276562+00:00", "data": {"market": "0x930bda5ea16724849ebd2a879634f3ab04522c45a018a1957bbb0319d118c94e", "price_changes": [{"asset_id": "1829171049271516235440282127137400632547540012227351935219418265043248885571", "price": "0.114", "size": "524.99", "side": "BUY", "hash": "12699ec24ce25fef9f493ab38476abef754b10d0", "best_bid": "0.925", "best_ask": "0.992"}, {"asset_id": "85973355253604996307258416942389548140991752390701227925867193238957025004704", "price": "0.886", "size": "524.99", "side": "SELL", "hash": "4160f5d598b66ea824c27fc15c8427b99f79e48c", "best_bid": "0.008", "best_ask": "0.075"}], "timestamp": "1769384660851", "event_type": "price_change"}}
{"_local_timestamp": "2026-01-25T23:44:40.105792+00:00", "data": {"market": "0x4c65d9aa2bac477a2a9be69d9f707d9105d805d3d19b76854e23cb18bc08c465", "price_changes": [{"asset_id": "98682086811885890631327975014650377593666125070789241199777154553006778841258", "price": "0.01", "size": "313", "side": "BUY", "hash": "39e8f485f8d587311f6e37afb75014fe2ddaef4c", "best_bid": "0.06", "best_ask": "0.13"}, {"asset_id": "56000570238632019339090117389091714658106578523885428868978722779674215227202", "price": "0.99", "size": "313", "side": "SELL", "hash": "349e85d5db2973246bf27984ad0f7091acb6bbeb", "best_bid": "0.87", "best_ask": "0.94"}], "timestamp": "1769384680009", "event_type": "price_change"}}
{"_local_timestamp": "2026-01-25T23:44:40.106571+00:00", "data": {"market": "0xeb13f5b879c912aaaa6ea4de58570f48f107db4c74f7e816becf030e6272fd9c", "price_changes": [{"asset_id": "113827665827621863662330176029339371613062711060109786539031002756320088862803", "price": "0.01", "size": "233", "side": "BUY", "hash": "57fdacebe3e02e02ac1e5803a3a276c36309dc20", "best_bid": "0.06", "best_ask": "0.18"}, {"asset_id": "29829995287367853408312885951206913575599941748874598029431212839187459174632", "price": "0.99", "size": "233", "side": "SELL", "hash": "cfc02fa114081fea692d75df6f6cd45e58ec4eec", "best_bid": "0.82", "best_ask": "0.94"}], "timestamp": "1769384680009", "event_type": "price_change"}}
{"_local_timestamp": "2026-01-25T23:44:47.560746+00:00", "data": {"market": "0x930bda5ea16724849ebd2a879634f3ab04522c45a018a1957bbb0319d118c94e", "price_changes": [{"asset_id": "1829171049271516235440282127137400632547540012227351935219418265043248885571", "price": "0.253", "size": "0", "side": "BUY", "hash": "9aa214b9aad2a4f31c6b6e130b47909e435031e9", "best_bid": "0.925", "best_ask": "0.992"}, {"asset_id": "85973355253604996307258416942389548140991752390701227925867193238957025004704", "price": "0.747", "size": "0", "side": "SELL", "hash": "1227d2067f8ada356acb48768d87ca481f7b26f0", "best_bid": "0.008", "best_ask": "0.075"}], "timestamp": "1769384687465", "event_type": "price_change"}}
{"_local_timestamp": "2026-01-25T23:44:51.256300+00:00", "data": {"market": "0x930bda5ea16724849ebd2a879634f3ab04522c45a018a1957bbb0319d118c94e", "price_changes": [{"asset_id": "1829171049271516235440282127137400632547540012227351935219418265043248885571", "price": "0.254", "size": "0", "side": "BUY", "hash": "85e044f192d5cc9243741caa34a2a8fc88b9a5d3", "best_bid": "0.925", "best_ask": "0.992"}, {"asset_id": "85973355253604996307258416942389548140991752390701227925867193238957025004704", "price": "0.746", "size": "0", "side": "SELL", "hash": "5120630aae817c578bd4e8dc49644b94f9f27352", "best_bid": "0.008", "best_ask": "0.075"}], "timestamp": "1769384691187", "event_type": "price_change"}}
{"_local_timestamp": "2026-01-25T23:44:51.287151+00:00", "data": {"market": "0x930bda5ea16724849ebd2a879634f3ab04522c45a018a1957bbb0319d118c94e", "price_changes": [{"asset_id": "1829171049271516235440282127137400632547540012227351935219418265043248885571", "price": "0.252", "size": "20", "side": "BUY", "hash": "a1101a7dafbda1acdc0534fa6f8e273d5edaada6", "best_bid": "0.925", "best_ask": "0.992"}, {"asset_id": "85973355253604996307258416942389548140991752390701227925867193238957025004704", "price": "0.748", "size": "20", "side": "SELL", "hash": "34d1f5d730daf705c9c4840e0a53e162ae90e592", "best_bid": "0.008", "best_ask": "0.075"}], "timestamp": "1769384691216", "event_type": "price_change"}}
{"_local_timestamp": "2026-01-25T23:45:04.499805+00:00", "data": {"market": "0x4c65d9aa2bac477a2a9be69d9f707d9105d805d3d19b76854e23cb18bc08c465", "price_changes": [{"asset_id": "56000570238632019339090117389091714658106578523885428868978722779674215227202", "price": "0.18", "size": "0", "side": "BUY", "hash": "2c7b118e2e5f34e53fa8af68521e9f6a929bca72", "best_bid": "0.87", "best_ask": "0.94"}, {"asset_id": "98682086811885890631327975014650377593666125070789241199777154553006778841258", "price": "0.82", "size": "0", "side": "SELL", "hash": "7160917b798a137a65ea83a371a9ee351006bb3d", "best_bid": "0.06", "best_ask": "0.13"}], "timestamp": "1769384704428", "event_type": "price_change"}}
{"_local_timestamp": "2026-01-25T23:45:04.862162+00:00", "data": {"market": "0x4c65d9aa2bac477a2a9be69d9f707d9105d805d3d19b76854e23cb18bc08c465", "price_changes": [{"asset_id": "56000570238632019339090117389091714658106578523885428868978722779674215227202", "price": "0.2", "size": "5.98", "side": "BUY", "hash": "5b1595020b9e0a69d9472d857d14cd394c121afd", "best_bid": "0.87", "best_ask": "0.94"}, {"asset_id": "98682086811885890631327975014650377593666125070789241199777154553006778841258", "price": "0.8", "size": "5.98", "side": "SELL", "hash": "8ba3edbabf1b9e3bbad76ea6c3d4e272c8fb86d4", "best_bid": "0.06", "best_ask": "0.13"}], "timestamp": "1769384704801", "event_type": "price_change"}}
{"_local_timestamp": "2026-01-25T23:45:05.494783+00:00", "data": {"market": "0x4c65d9aa2bac477a2a9be69d9f707d9105d805d3d19b76854e23cb18bc08c465", "price_changes": [{"asset_id": "56000570238632019339090117389091714658106578523885428868978722779674215227202", "price": "0.19", "size": "0", "side": "BUY", "hash": "6caa67820ab7b58eede63cd7d18b700bcb1e0b22", "best_bid": "0.87", "best_ask": "0.94"}, {"asset_id": "98682086811885890631327975014650377593666125070789241199777154553006778841258", "price": "0.81", "size": "0", "side": "SELL", "hash": "c5f57a75e78aad95212ee21f97af20638129bb70", "best_bid": "0.06", "best_ask": "0.13"}], "timestamp": "1769384705425", "event_type": "price_change"}}
{"_local_timestamp": "2026-01-25T23:45:05.524086+00:00", "data": {"market": "0x4c65d9aa2bac477a2a9be69d9f707d9105d805d3d19b76854e23cb18bc08c465", "price_changes": [{"asset_id": "56000570238632019339090117389091714658106578523885428868978722779674215227202", "price": "0.13", "size": "20", "side": "BUY", "hash": "8860169d23ddf1ecee8ccd1d13fba265708c8cf7", "best_bid": "0.87", "best_ask": "0.94"}, {"asset_id": "98682086811885890631327975014650377593666125070789241199777154553006778841258", "price": "0.87", "size": "20", "side": "SELL", "hash": "161432a7d0daa9a5a152581e3ddc39ff09c07dcd", "best_bid": "0.06", "best_ask": "0.13"}], "timestamp": "1769384705457", "event_type": "price_change"}}
{"_local_timestamp": "2026-01-25T23:45:07.940572+00:00", "data": {"market": "0x528fe62a407a299d927d5b612386a4b4f558d4fb0776460373d7e97e8aea79db", "price_changes": [{"asset_id": "102485972951606238793769017987999788096270850857875715717770053964568134356702", "price": "0.18", "size": "0", "side": "BUY", "hash": "7cb5652e01109b6755710214a82af94565b2a3e8", "best_bid": "0.64", "best_ask": "0.8"}, {"asset_id": "36208978152381894236053536257317511772939147258243384911045733411987516778587", "price": "0.82", "size": "0", "side": "SELL", "hash": "4fbafaad15402d64fc25b0f7f5c241eefb3d477d", "best_bid": "0.2", "best_ask": "0.36"}], "timestamp": "1769384707875", "event_type": "price_change"}}
{"_local_timestamp": "2026-01-25T23:45:08.362221+00:00", "data": {"market": "0x528fe62a407a299d927d5b612386a4b4f558d4fb0776460373d7e97e8aea79db", "price_changes": [{"asset_id": "102485972951606238793769017987999788096270850857875715717770053964568134356702", "price": "0.2", "size": "5.67", "side": "BUY", "hash": "09f6157603d3a52702e625cfce56d1631590d5c7", "best_bid": "0.64", "best_ask": "0.8"}, {"asset_id": "36208978152381894236053536257317511772939147258243384911045733411987516778587", "price": "0.8", "size": "5.67", "side": "SELL", "hash": "da0b91df4e99399f44a2d31e30372bd4ced47916", "best_bid": "0.2", "best_ask": "0.36"}], "timestamp": "1769384708292", "event_type": "price_change"}}
{"_local_timestamp": "2026-01-25T23:45:09.132532+00:00", "data": {"market": "0x528fe62a407a299d927d5b612386a4b4f558d4fb0776460373d7e97e8aea79db", "price_changes": [{"asset_id": "102485972951606238793769017987999788096270850857875715717770053964568134356702", "price": "0.19", "size": "0", "side": "BUY", "hash": "3ac7d9bc2d96008e32e58288160e32aa1aa5372d", "best_bid": "0.64", "best_ask": "0.8"}, {"asset_id": "36208978152381894236053536257317511772939147258243384911045733411987516778587", "price": "0.81", "size": "0", "side": "SELL", "hash": "0ebae7968c4f122bf86960fc1da5e58695d822be", "best_bid": "0.2", "best_ask": "0.36"}], "timestamp": "1769384709054", "event_type": "price_change"}}
{"_local_timestamp": "2026-01-25T23:45:09.158321+00:00", "data": {"market": "0x528fe62a407a299d927d5b612386a4b4f558d4fb0776460373d7e97e8aea79db", "price_changes": [{"asset_id": "102485972951606238793769017987999788096270850857875715717770053964568134356702", "price": "0.13", "size": "20", "side": "BUY", "hash": "de66d577167a8816da67fd9bdcf98da5a86cb9d9", "best_bid": "0.64", "best_ask": "0.8"}, {"asset_id": "36208978152381894236053536257317511772939147258243384911045733411987516778587", "price": "0.87", "size": "20", "side": "SELL", "hash": "770f46e6afebe0d19d6cd5da51a43c8f92b545c5", "best_bid": "0.2", "best_ask": "0.36"}], "timestamp": "1769384709075", "event_type": "price_change"}}
{"_local_timestamp": "2026-01-25T23:45:19.229335+00:00", "data": {"market": "0x930bda5ea16724849ebd2a879634f3ab04522c45a018a1957bbb0319d118c94e", "price_changes": [{"asset_id": "1829171049271516235440282127137400632547540012227351935219418265043248885571", "price": "0.253", "size": "45", "side": "BUY", "hash": "1473b216c6bfbd5cdf87ccd1682d9ea6cca03803", "best_bid": "0.925", "best_ask": "0.992"}, {"asset_id": "85973355253604996307258416942389548140991752390701227925867193238957025004704", "price": "0.747", "size": "45", "side": "SELL", "hash": "c6621b36320d1d449b0c21f6b93b05228210f261", "best_bid": "0.008", "best_ask": "0.075"}], "timestamp": "1769384719156", "event_type": "price_change"}}
{"_local_timestamp": "2026-01-25T23:45:22.766346+00:00", "data": {"market": "0x930bda5ea16724849ebd2a879634f3ab04522c45a018a1957bbb0319d118c94e", "price_changes": [{"asset_id": "1829171049271516235440282127137400632547540012227351935219418265043248885571", "price": "0.252", "size": "0", "side": "BUY", "hash": "a77ee91f5d32f287faadeb04c71bf9db96137cfd", "best_bid": "0.925", "best_ask": "0.992"}, {"asset_id": "85973355253604996307258416942389548140991752390701227925867193238957025004704", "price": "0.748", "size": "0", "side": "SELL", "hash": "4e785e5a47d2129f3a219bc225a7150e30208a51", "best_bid": "0.008", "best_ask": "0.075"}], "timestamp": "1769384722698", "event_type": "price_change"}}
{"_local_timestamp": "2026-01-25T23:45:22.792415+00:00", "data": {"market": "0x930bda5ea16724849ebd2a879634f3ab04522c45a018a1957bbb0319d118c94e", "price_changes": [{"asset_id": "1829171049271516235440282127137400632547540012227351935219418265043248885571", "price": "0.254", "size": "20", "side": "BUY", "hash": "8c83902f45f3ff38d2a51e736f0e9d1d3d3d90b8", "best_bid": "0.925", "best_ask": "0.992"}, {"asset_id": "85973355253604996307258416942389548140991752390701227925867193238957025004704", "price": "0.746", "size": "20", "side": "SELL", "hash": "c1a69d18fcf6db1bdb5e2ea482c28574ead1c40d", "best_bid": "0.008", "best_ask": "0.075"}], "timestamp": "1769384722730", "event_type": "price_change"}}
{"_local_timestamp": "2026-01-25T23:45:57.231586+00:00", "data": {"market": "0x930bda5ea16724849ebd2a879634f3ab04522c45a018a1957bbb0319d118c94e", "price_changes": [{"asset_id": "1829171049271516235440282127137400632547540012227351935219418265043248885571", "price": "0.251", "size": "0", "side": "BUY", "hash": "80527e31445774ce2fafe1075fbd9cdef2584ab2", "best_bid": "0.925", "best_ask": "0.992"}, {"asset_id": "85973355253604996307258416942389548140991752390701227925867193238957025004704", "price": "0.749", "size": "0", "side": "SELL", "hash": "0da5d86e236201b291e3cb280161797cb24e6f09", "best_bid": "0.008", "best_ask": "0.075"}], "timestamp": "1769384756840", "event_type": "price_change"}}
{"_local_timestamp": "2026-01-25T23:46:45.697141+00:00", "data": {"market": "0xeb13f5b879c912aaaa6ea4de58570f48f107db4c74f7e816becf030e6272fd9c", "price_changes": [{"asset_id": "113827665827621863662330176029339371613062711060109786539031002756320088862803", "price": "0.01", "size": "261.57", "side": "BUY", "hash": "4028e4996c3fd33608d1ac3b2897c3538289bac7", "best_bid": "0.06", "best_ask": "0.18"}, {"asset_id": "29829995287367853408312885951206913575599941748874598029431212839187459174632", "price": "0.99", "size": "261.57", "side": "SELL", "hash": "f2048ed6abe3ea8f8d018d6b10756b63a4db967b", "best_bid": "0.82", "best_ask": "0.94"}], "timestamp": "1769384805594", "event_type": "price_change"}}
{"_local_timestamp": "2026-01-25T23:46:45.705381+00:00", "data": {"market": "0x4c65d9aa2bac477a2a9be69d9f707d9105d805d3d19b76854e23cb18bc08c465", "price_changes": [{"asset_id": "98682086811885890631327975014650377593666125070789241199777154553006778841258", "price": "0.01", "size": "341.57", "side": "BUY", "hash": "4bf1382e4e3e7b39f4a4f762257661f0ad8c3ebb", "best_bid": "0.06", "best_ask": "0.13"}, {"asset_id": "56000570238632019339090117389091714658106578523885428868978722779674215227202", "price": "0.99", "size": "341.57", "side": "SELL", "hash": "29c5398d13900eabe26b09fd42c3560f962fd0f7", "best_bid": "0.87", "best_ask": "0.94"}], "timestamp": "1769384805594", "event_type": "price_change"}}
{"_local_timestamp": "2026-01-25T23:46:47.139205+00:00", "data": {"market": "0x930bda5ea16724849ebd2a879634f3ab04522c45a018a1957bbb0319d118c94e", "price_changes": [{"asset_id": "85973355253604996307258416942389548140991752390701227925867193238957025004704", "price": "0.003", "size": "400", "side": "BUY", "hash": "4464a40324a551cbcdb87a2cf562878cc2a00310", "best_bid": "0.008", "best_ask": "0.075"}, {"asset_id": "1829171049271516235440282127137400632547540012227351935219418265043248885571", "price": "0.997", "size": "400", "side": "SELL", "hash": "11eea577e5afbd5b5f76aeb73eae257d3385d98a", "best_bid": "0.925", "best_ask": "0.992"}], "timestamp": "1769384806987", "event_type": "price_change"}}
{"_local_timestamp": "2026-01-25T23:46:47.328949+00:00", "data": {"market": "0x930bda5ea16724849ebd2a879634f3ab04522c45a018a1957bbb0319d118c94e", "price_changes": [{"asset_id": "85973355253604996307258416942389548140991752390701227925867193238957025004704", "price": "0.003", "size": "423.5", "side": "BUY", "hash": "23803a1b98a57a16a735f427d54f89a982b2a12b", "best_bid": "0.008", "best_ask": "0.075"}, {"asset_id": "1829171049271516235440282127137400632547540012227351935219418265043248885571", "price": "0.997", "size": "423.5", "side": "SELL", "hash": "19ce7d778a68d7606260007fee99c461c00a2aca", "best_bid": "0.925", "best_ask": "0.992"}], "timestamp": "1769384807188", "event_type": "price_change"}}
{"_local_timestamp": "2026-01-25T23:46:57.917834+00:00", "data": {"market": "0x930bda5ea16724849ebd2a879634f3ab04522c45a018a1957bbb0319d118c94e", "price_changes": [{"asset_id": "1829171049271516235440282127137400632547540012227351935219418265043248885571", "price": "0.254", "size": "42", "side": "BUY", "hash": "6a3a8053d00b398406e8acc0de43bbf07b2bcb4f", "best_bid": "0.925", "best_ask": "0.992"}, {"asset_id": "85973355253604996307258416942389548140991752390701227925867193238957025004704", "price": "0.746", "size": "42", "side": "SELL", "hash": "d21f7f2a775d9551bdbc9805db941f78244fd8b8", "best_bid": "0.008", "best_ask": "0.075"}], "timestamp": "1769384817800", "event_type": "price_change"}}
{"_local_timestamp": "2026-01-25T23:47:04.311120+00:00", "data": {"market": "0x930bda5ea16724849ebd2a879634f3ab04522c45a018a1957bbb0319d118c94e", "price_changes": [{"asset_id": "1829171049271516235440282127137400632547540012227351935219418265043248885571", "price": "0.254", "size": "22", "side": "BUY", "hash": "1561a9e3dc47648a9dbe5dc0eade8dfd94363fe2", "best_bid": "0.925", "best_ask": "0.992"}, {"asset_id": "85973355253604996307258416942389548140991752390701227925867193238957025004704", "price": "0.746", "size": "22", "side": "SELL", "hash": "7ecc2fa7a3f4a3ecee77391604d6b838b36fbea1", "best_bid": "0.008", "best_ask": "0.075"}], "timestamp": "1769384824182", "event_type": "price_change"}}
{"_local_timestamp": "2026-01-25T23:47:04.338947+00:00", "data": {"market": "0x930bda5ea16724849ebd2a879634f3ab04522c45a018a1957bbb0319d118c94e", "price_changes": [{"asset_id": "1829171049271516235440282127137400632547540012227351935219418265043248885571", "price": "0.255", "size": "20", "side": "BUY", "hash": "45ea14e7c6805495251b06567c158da32d888c92", "best_bid": "0.925", "best_ask": "0.992"}, {"asset_id": "85973355253604996307258416942389548140991752390701227925867193238957025004704", "price": "0.745", "size": "20", "side": "SELL", "hash": "eb2bd8538cf2dc847383321531ad1f096dfc04fd", "best_bid": "0.008", "best_ask": "0.075"}], "timestamp": "1769384824211", "event_type": "price_change"}}
{"_local_timestamp": "2026-01-25T23:47:09.119459+00:00", "data": {"market": "0x528fe62a407a299d927d5b612386a4b4f558d4fb0776460373d7e97e8aea79db", "price_changes": [{"asset_id": "36208978152381894236053536257317511772939147258243384911045733411987516778587", "price": "0.2", "size": "0", "side": "BUY", "hash": "7ff8359ff3741c28ae795488154db445b5ae82b3", "best_bid": "0.19", "best_ask": "0.36"}, {"asset_id": "102485972951606238793769017987999788096270850857875715717770053964568134356702", "price": "0.8", "size": "0", "side": "SELL", "hash": "5bdf994a320795370d876885a4349fb80ba62e3a", "best_bid": "0.64", "best_ask": "0.81"}], "timestamp": "1769384829004", "event_type": "price_change"}}
{"_local_timestamp": "2026-01-25T23:47:09.120317+00:00", "data": {"market": "0x4c2eb1c2553628d59b2dbb4640b6d650637bd6a1462cff94334355ae206ae7b4", "price_changes": [{"asset_id": "42433781921146230236897276928227396822059794002552428345815748354041495759547", "price": "0.19", "size": "0", "side": "BUY", "hash": "de479b0945ae5ae2397a58aae2a2b04b2676a0b1", "best_bid": "0.18", "best_ask": "0.43"}, {"asset_id": "48370595165483556992313158202325404898706481073615732950100193255535553444828", "price": "0.81", "size": "0", "side": "SELL", "hash": "71436fc47d03b450e83b70343a781a0a97a24696", "best_bid": "0.57", "best_ask": "0.82"}], "timestamp": "1769384829005", "event_type": "price_change"}}
{"_local_timestamp": "2026-01-25T23:47:09.122738+00:00", "data": {"market": "0xd4e866883ef71c1a0686768b2089df0ee27f4bc6fb09fd6c5322826d788446b1", "price_changes": [{"asset_id": "42562896281558908480353570722568310587471823543536714415123687719180859691787", "price": "0.19", "size": "0", "side": "BUY", "hash": "e2b37f4b35d93499e4adb9eae106c809e43042de", "best_bid": "0.18", "best_ask": "0.5"}, {"asset_id": "82597844215693023613587868745168688782245401597513036676400621185216539262737", "price": "0.81", "size": "0", "side": "SELL", "hash": "f87af0ffd5f5fcf088a8a9f9cc0de1cfffb1038f", "best_bid": "0.5", "best_ask": "0.82"}], "timestamp": "1769384829006", "event_type": "price_change"}}
{"_local_timestamp": "2026-01-25T23:47:11.262059+00:00", "data": {"market": "0x4c2eb1c2553628d59b2dbb4640b6d650637bd6a1462cff94334355ae206ae7b4", "price_changes": [{"asset_id": "48370595165483556992313158202325404898706481073615732950100193255535553444828", "price": "0.5", "size": "72.5", "side": "BUY", "hash": "a6df0b6da58f37c88e17ff8ee85868f780acce5d", "best_bid": "0.57", "best_ask": "0.82"}, {"asset_id": "42433781921146230236897276928227396822059794002552428345815748354041495759547", "price": "0.5", "size": "72.5", "side": "SELL", "hash": "7ebc359a99a52aa8f126b2df073a5a0c0b23d903", "best_bid": "0.18", "best_ask": "0.43"}], "timestamp": "1769384831129", "event_type": "price_change"}}
{"_local_timestamp": "2026-01-25T23:47:11.262839+00:00", "data": {"market": "0xd4e866883ef71c1a0686768b2089df0ee27f4bc6fb09fd6c5322826d788446b1", "price_changes": [{"asset_id": "82597844215693023613587868745168688782245401597513036676400621185216539262737", "price": "0.5", "size": "67", "side": "BUY", "hash": "4de63870c3c9e95aede9dcf1639c1ec515c24a07", "best_bid": "0.5", "best_ask": "0.82"}, {"asset_id": "42562896281558908480353570722568310587471823543536714415123687719180859691787", "price": "0.5", "size": "67", "side": "SELL", "hash": "7c9be9e6f0e464faad6f5b36c85745d5367e720f", "best_bid": "0.18", "best_ask": "0.5"}], "timestamp": "1769384831129", "event_type": "price_change"}}
{"_local_timestamp": "2026-01-25T23:47:11.295200+00:00", "data": {"market": "0xd4e866883ef71c1a0686768b2089df0ee27f4bc6fb09fd6c5322826d788446b1", "price_changes": [{"asset_id": "82597844215693023613587868745168688782245401597513036676400621185216539262737", "price": "0.48", "size": "58.61", "side": "BUY", "hash": "e41d24739839e15d7382310a4d6994fdb26098e7", "best_bid": "0.5", "best_ask": "0.82"}, {"asset_id": "42562896281558908480353570722568310587471823543536714415123687719180859691787", "price": "0.52", "size": "58.61", "side": "SELL", "hash": "040be3366042646408adf11a89c8b365471c1ff5", "best_bid": "0.18", "best_ask": "0.5"}], "timestamp": "1769384831164", "event_type": "price_change"}}
{"_local_timestamp": "2026-01-25T23:47:11.296064+00:00", "data": {"market": "0x4c2eb1c2553628d59b2dbb4640b6d650637bd6a1462cff94334355ae206ae7b4", "price_changes": [{"asset_id": "48370595165483556992313158202325404898706481073615732950100193255535553444828", "price": "0.46", "size": "20", "side": "BUY", "hash": "08ce62e0d7f6b146ae8f34d64684f3195e31e35a", "best_bid": "0.57", "best_ask": "0.82"}, {"asset_id": "42433781921146230236897276928227396822059794002552428345815748354041495759547", "price": "0.54", "size": "20", "side": "SELL", "hash": "ab87e7a95373ac4d152cdae46bce5e209bd741c3", "best_bid": "0.18", "best_ask": "0.43"}], "timestamp": "1769384831164", "event_type": "price_change"}}
{"_local_timestamp": "2026-01-25T23:47:35.286067+00:00", "data": {"market": "0x4c2eb1c2553628d59b2dbb4640b6d650637bd6a1462cff94334355ae206ae7b4", "price_changes": [{"asset_id": "48370595165483556992313158202325404898706481073615732950100193255535553444828", "price": "0.5", "size": "5.5", "side": "BUY", "hash": "d52a337adbaa71aeaf67034a558a16fba6c0a634", "best_bid": "0.57", "best_ask": "0.82"}, {"asset_id": "42433781921146230236897276928227396822059794002552428345815748354041495759547", "price": "0.5", "size": "5.5", "side": "SELL", "hash": "3958e6fe67b4aae1415415f6b566b7a1c1f743f1", "best_bid": "0.18", "best_ask": "0.43"}], "timestamp": "1769384855056", "event_type": "price_change"}}
{"_local_timestamp": "2026-01-25T23:47:35.286851+00:00", "data": {"market": "0xd4e866883ef71c1a0686768b2089df0ee27f4bc6fb09fd6c5322826d788446b1", "price_changes": [{"asset_id": "82597844215693023613587868745168688782245401597513036676400621185216539262737", "price": "0.5", "size": "0", "side": "BUY", "hash": "afc8e6217718ac4b629021109d561b94217f9565", "best_bid": "0.49", "best_ask": "0.82"}, {"asset_id": "42562896281558908480353570722568310587471823543536714415123687719180859691787", "price": "0.5", "size": "0", "side": "SELL", "hash": "7567e3101f411b2bcf059d6f66e02877e982f01b", "best_bid": "0.18", "best_ask": "0.51"}], "timestamp": "1769384855056", "event_type": "price_change"}}
{"_local_timestamp": "2026-01-25T23:48:12.698430+00:00", "data": {"market": "0xd4e866883ef71c1a0686768b2089df0ee27f4bc6fb09fd6c5322826d788446b1", "price_changes": [{"asset_id": "42562896281558908480353570722568310587471823543536714415123687719180859691787", "price": "0.19", "size": "102", "side": "BUY", "hash": "7fcb135d669a1a3a2289852f6e719f8529897d1f", "best_bid": "0.19", "best_ask": "0.51"}, {"asset_id": "82597844215693023613587868745168688782245401597513036676400621185216539262737", "price": "0.81", "size": "102", "side": "SELL", "hash": "00e5fb2aa8f004962b0ab190941888e3bf5af9b8", "best_bid": "0.49", "best_ask": "0.81"}], "timestamp": "1769384892631", "event_type": "price_change"}}
{"_local_timestamp": "2026-01-25T23:48:12.929626+00:00", "data": {"market": "0x4c2eb1c2553628d59b2dbb4640b6d650637bd6a1462cff94334355ae206ae7b4", "price_changes": [{"asset_id": "42433781921146230236897276928227396822059794002552428345815748354041495759547", "price": "0.19", "size": "77", "side": "BUY", "hash": "561163539c935a6dbb2958bbafeaf6925668f837", "best_bid": "0.19", "best_ask": "0.43"}, {"asset_id": "48370595165483556992313158202325404898706481073615732950100193255535553444828", "price": "0.81", "size": "77", "side": "SELL", "hash": "999869d6b2c908cb9bc31f3fdd51f85de8acd080", "best_bid": "0.57", "best_ask": "0.81"}], "timestamp": "1769384892866", "event_type": "price_change"}}
{"_local_timestamp": "2026-01-25T23:48:13.165593+00:00", "data": {"market": "0x528fe62a407a299d927d5b612386a4b4f558d4fb0776460373d7e97e8aea79db", "price_changes": [{"asset_id": "36208978152381894236053536257317511772939147258243384911045733411987516778587", "price": "0.2", "size": "97", "side": "BUY", "hash": "5faf17f9605bf2307aec3f1c2b0ad7e6f86e0370", "best_bid": "0.2", "best_ask": "0.36"}, {"asset_id": "102485972951606238793769017987999788096270850857875715717770053964568134356702", "price": "0.8", "size": "97", "side": "SELL", "hash": "842f3a9810a1814f4baee6522b02c49c346b16fe", "best_bid": "0.64", "best_ask": "0.8"}], "timestamp": "1769384893101", "event_type": "price_change"}}
{"_local_timestamp": "2026-01-25T23:48:14.214332+00:00", "data": {"market": "0xd4e866883ef71c1a0686768b2089df0ee27f4bc6fb09fd6c5322826d788446b1", "price_changes": [{"asset_id": "82597844215693023613587868745168688782245401597513036676400621185216539262737", "price": "0.48", "size": "38.61", "side": "BUY", "hash": "d0e6037e9314c9a54b4076309b97912e009bfc09", "best_bid": "0.49", "best_ask": "0.81"}, {"asset_id": "42562896281558908480353570722568310587471823543536714415123687719180859691787", "price": "0.52", "size": "38.61", "side": "SELL", "hash": "914fc22b1e231412a7d451c9ef43e6e09c2c6629", "best_bid": "0.19", "best_ask": "0.51"}], "timestamp": "1769384894150", "event_type": "price_change"}}
{"_local_timestamp": "2026-01-25T23:48:14.240200+00:00", "data": {"market": "0xd4e866883ef71c1a0686768b2089df0ee27f4bc6fb09fd6c5322826d788446b1", "price_changes": [{"asset_id": "82597844215693023613587868745168688782245401597513036676400621185216539262737", "price": "0.49", "size": "25.5", "side": "BUY", "hash": "1dc01cbbcd0dfb3f657a06e910f08e397384e3f9", "best_bid": "0.49", "best_ask": "0.81"}, {"asset_id": "42562896281558908480353570722568310587471823543536714415123687719180859691787", "price": "0.51", "size": "25.5", "side": "SELL", "hash": "cfa06635399ddf9a02bf21c9643f269eacc4e068", "best_bid": "0.19", "best_ask": "0.51"}], "timestamp": "1769384894176", "event_type": "price_change"}}
{"_local_timestamp": "2026-01-25T23:48:35.813264+00:00", "data": {"market": "0x4c65d9aa2bac477a2a9be69d9f707d9105d805d3d19b76854e23cb18bc08c465", "price_changes": [{"asset_id": "56000570238632019339090117389091714658106578523885428868978722779674215227202", "price": "0.02", "size": "350", "side": "BUY", "hash": "eb133b5234af4dee8fbca2d3451fe6a90a12a510", "best_bid": "0.87", "best_ask": "0.94"}, {"asset_id": "98682086811885890631327975014650377593666125070789241199777154553006778841258", "price": "0.98", "size": "350", "side": "SELL", "hash": "fa65e085a819c32494f7b6a5b8ea2dde6c0154ad", "best_bid": "0.06", "best_ask": "0.13"}], "timestamp": "1769384915727", "event_type": "price_change"}}
{"_local_timestamp": "2026-01-25T23:48:35.814087+00:00", "data": {"market": "0x4c65d9aa2bac477a2a9be69d9f707d9105d805d3d19b76854e23cb18bc08c465", "price_changes": [{"asset_id": "56000570238632019339090117389091714658106578523885428868978722779674215227202", "price": "0.04", "size": "0", "side": "BUY", "hash": "eb133b5234af4dee8fbca2d3451fe6a90a12a510", "best_bid": "0.87", "best_ask": "0.94"}, {"asset_id": "98682086811885890631327975014650377593666125070789241199777154553006778841258", "price": "0.96", "size": "0", "side": "SELL", "hash": "fa65e085a819c32494f7b6a5b8ea2dde6c0154ad", "best_bid": "0.06", "best_ask": "0.13"}], "timestamp": "1769384915727", "event_type": "price_change"}}
{"_local_timestamp": "2026-01-25T23:48:35.814752+00:00", "data": {"market": "0x4c65d9aa2bac477a2a9be69d9f707d9105d805d3d19b76854e23cb18bc08c465", "price_changes": [{"asset_id": "56000570238632019339090117389091714658106578523885428868978722779674215227202", "price": "0.08", "size": "0", "side": "BUY", "hash": "eb133b5234af4dee8fbca2d3451fe6a90a12a510", "best_bid": "0.87", "best_ask": "0.94"}, {"asset_id": "98682086811885890631327975014650377593666125070789241199777154553006778841258", "price": "0.92", "size": "0", "side": "SELL", "hash": "fa65e085a819c32494f7b6a5b8ea2dde6c0154ad", "best_bid": "0.06", "best_ask": "0.13"}], "timestamp": "1769384915727", "event_type": "price_change"}}
{"_local_timestamp": "2026-01-25T23:48:35.815413+00:00", "data": {"market": "0x4c65d9aa2bac477a2a9be69d9f707d9105d805d3d19b76854e23cb18bc08c465", "price_changes": [{"asset_id": "56000570238632019339090117389091714658106578523885428868978722779674215227202", "price": "0.2", "size": "0", "side": "BUY", "hash": "eb133b5234af4dee8fbca2d3451fe6a90a12a510", "best_bid": "0.87", "best_ask": "0.94"}, {"asset_id": "98682086811885890631327975014650377593666125070789241199777154553006778841258", "price": "0.8", "size": "0", "side": "SELL", "hash": "fa65e085a819c32494f7b6a5b8ea2dde6c0154ad", "best_bid": "0.06", "best_ask": "0.13"}], "timestamp": "1769384915727", "event_type": "price_change"}}
{"_local_timestamp": "2026-01-25T23:48:36.209244+00:00", "data": {"market": "0x4c65d9aa2bac477a2a9be69d9f707d9105d805d3d19b76854e23cb18bc08c465", "price_changes": [{"asset_id": "56000570238632019339090117389091714658106578523885428868978722779674215227202", "price": "0.03", "size": "205.36", "side": "BUY", "hash": "d415f3a6898ac2ca99ec76607ec81eb1cc9a2bac", "best_bid": "0.87", "best_ask": "0.94"}, {"asset_id": "98682086811885890631327975014650377593666125070789241199777154553006778841258", "price": "0.97", "size": "205.36", "side": "SELL", "hash": "d2e5e993bd742e6cb4d9f2b57ff4408c89120582", "best_bid": "0.06", "best_ask": "0.13"}], "timestamp": "1769384916129", "event_type": "price_change"}}
{"_local_timestamp": "2026-01-25T23:48:36.214169+00:00", "data": {"market": "0x4c65d9aa2bac477a2a9be69d9f707d9105d805d3d19b76854e23cb18bc08c465", "price_changes": [{"asset_id": "56000570238632019339090117389091714658106578523885428868978722779674215227202", "price": "0.01", "size": "894.43", "side": "BUY", "hash": "fbf91e0607e288901e6be26989366ea28ece6a68", "best_bid": "0.87", "best_ask": "0.94"}, {"asset_id": "98682086811885890631327975014650377593666125070789241199777154553006778841258", "price": "0.99", "size": "894.43", "side": "SELL", "hash": "43f023acb15e4f0d32a45af53dfc5fc6f9364408", "best_bid": "0.06", "best_ask": "0.13"}], "timestamp": "1769384916131", "event_type": "price_change"}}
{"_local_timestamp": "2026-01-25T23:48:36.216315+00:00", "data": {"market": "0x4c65d9aa2bac477a2a9be69d9f707d9105d805d3d19b76854e23cb18bc08c465", "price_changes": [{"asset_id": "56000570238632019339090117389091714658106578523885428868978722779674215227202", "price": "0.14", "size": "9.65", "side": "BUY", "hash": "1ee2a4ac73ad7a301beada6be37b1355e134f524", "best_bid": "0.87", "best_ask": "0.94"}, {"asset_id": "98682086811885890631327975014650377593666125070789241199777154553006778841258", "price": "0.86", "size": "9.65", "side": "SELL", "hash": "791fae50a79a6d7ba258d80900c786adfcf6ca16", "best_bid": "0.06", "best_ask": "0.13"}], "timestamp": "1769384916134", "event_type": "price_change"}}
{"_local_timestamp": "2026-01-25T23:48:36.225961+00:00", "data": {"market": "0x4c65d9aa2bac477a2a9be69d9f707d9105d805d3d19b76854e23cb18bc08c465", "price_changes": [{"asset_id": "56000570238632019339090117389091714658106578523885428868978722779674215227202", "price": "0.06", "size": "89.22", "side": "BUY", "hash": "8d1d64f8d2e3477243326dfc65868a65dad31d02", "best_bid": "0.87", "best_ask": "0.94"}, {"asset_id": "98682086811885890631327975014650377593666125070789241199777154553006778841258", "price": "0.94", "size": "89.22", "side": "SELL", "hash": "83416fe5a1c0b6aa2c23ec0aba35d6275ea9bfdf", "best_bid": "0.06", "best_ask": "0.13"}], "timestamp": "1769384916138", "event_type": "price_change"}}
{"_local_timestamp": "2026-01-25T23:48:36.508751+00:00", "data": {"market": "0x4c65d9aa2bac477a2a9be69d9f707d9105d805d3d19b76854e23cb18bc08c465", "price_changes": [{"asset_id": "56000570238632019339090117389091714658106578523885428868978722779674215227202", "price": "0.13", "size": "0", "side": "BUY", "hash": "6627f5d2bbf50fa6576823fa59f5e60c110cf131", "best_bid": "0.87", "best_ask": "0.94"}, {"asset_id": "98682086811885890631327975014650377593666125070789241199777154553006778841258", "price": "0.87", "size": "0", "side": "SELL", "hash": "3f3dda575de01d7059531afa503796805d455d67", "best_bid": "0.06", "best_ask": "0.13"}], "timestamp": "1769384916429", "event_type": "price_change"}}
{"_local_timestamp": "2026-01-25T23:48:36.547301+00:00", "data": {"market": "0x4c65d9aa2bac477a2a9be69d9f707d9105d805d3d19b76854e23cb18bc08c465", "price_changes": [{"asset_id": "56000570238632019339090117389091714658106578523885428868978722779674215227202", "price": "0.15", "size": "20", "side": "BUY", "hash": "9e515b5d5fd460ef31743c3c189bd6cbb680092b", "best_bid": "0.87", "best_ask": "0.94"}, {"asset_id": "98682086811885890631327975014650377593666125070789241199777154553006778841258", "price": "0.85", "size": "20", "side": "SELL", "hash": "7304553564cfdac971fc844b32332a4e2ca8c5bf", "best_bid": "0.06", "best_ask": "0.13"}], "timestamp": "1769384916460", "event_type": "price_change"}}
{"_local_timestamp": "2026-01-25T23:48:41.671615+00:00", "data": {"market": "0x528fe62a407a299d927d5b612386a4b4f558d4fb0776460373d7e97e8aea79db", "price_changes": [{"asset_id": "102485972951606238793769017987999788096270850857875715717770053964568134356702", "price": "0.02", "size": "350", "side": "BUY", "hash": "798e39bb32d5313e88dc7b255c79861c4c03a70e", "best_bid": "0.64", "best_ask": "0.8"}, {"asset_id": "36208978152381894236053536257317511772939147258243384911045733411987516778587", "price": "0.98", "size": "350", "side": "SELL", "hash": "1d3c8d7b09ab5246744aeeb9ca9d178d2887af5c", "best_bid": "0.2", "best_ask": "0.36"}], "timestamp": "1769384921596", "event_type": "price_change"}}
{"_local_timestamp": "2026-01-25T23:48:41.673863+00:00", "data": {"market": "0x528fe62a407a299d927d5b612386a4b4f558d4fb0776460373d7e97e8aea79db", "price_changes": [{"asset_id": "102485972951606238793769017987999788096270850857875715717770053964568134356702", "price": "0.04", "size": "100", "side": "BUY", "hash": "798e39bb32d5313e88dc7b255c79861c4c03a70e", "best_bid": "0.64", "best_ask": "0.8"}, {"asset_id": "36208978152381894236053536257317511772939147258243384911045733411987516778587", "price": "0.96", "size": "100", "side": "SELL", "hash": "1d3c8d7b09ab5246744aeeb9ca9d178d2887af5c", "best_bid": "0.2", "best_ask": "0.36"}], "timestamp": "1769384921596", "event_type": "price_change"}}
{"_local_timestamp": "2026-01-25T23:48:41.674762+00:00", "data": {"market": "0x528fe62a407a299d927d5b612386a4b4f558d4fb0776460373d7e97e8aea79db", "price_changes": [{"asset_id": "102485972951606238793769017987999788096270850857875715717770053964568134356702", "price": "0.08", "size": "0", "side": "BUY", "hash": "798e39bb32d5313e88dc7b255c79861c4c03a70e", "best_bid": "0.64", "best_ask": "0.8"}, {"asset_id": "36208978152381894236053536257317511772939147258243384911045733411987516778587", "price": "0.92", "size": "0", "side": "SELL", "hash": "1d3c8d7b09ab5246744aeeb9ca9d178d2887af5c", "best_bid": "0.2", "best_ask": "0.36"}], "timestamp": "1769384921596", "event_type": "price_change"}}
{"_local_timestamp": "2026-01-25T23:48:41.675475+00:00", "data": {"market": "0x528fe62a407a299d927d5b612386a4b4f558d4fb0776460373d7e97e8aea79db", "price_changes": [{"asset_id": "102485972951606238793769017987999788096270850857875715717770053964568134356702", "price": "0.2", "size": "0", "side": "BUY", "hash": "798e39bb32d5313e88dc7b255c79861c4c03a70e", "best_bid": "0.64", "best_ask": "0.8"}, {"asset_id": "36208978152381894236053536257317511772939147258243384911045733411987516778587", "price": "0.8", "size": "0", "side": "SELL", "hash": "1d3c8d7b09ab5246744aeeb9ca9d178d2887af5c", "best_bid": "0.2", "best_ask": "0.36"}], "timestamp": "1769384921596", "event_type": "price_change"}}
{"_local_timestamp": "2026-01-25T23:48:42.104381+00:00", "data": {"market": "0x528fe62a407a299d927d5b612386a4b4f558d4fb0776460373d7e97e8aea79db", "price_changes": [{"asset_id": "102485972951606238793769017987999788096270850857875715717770053964568134356702", "price": "0.01", "size": "895.28", "side": "BUY", "hash": "11392d7de448d652e88f0ebf4bf0187282a27371", "best_bid": "0.64", "best_ask": "0.8"}, {"asset_id": "36208978152381894236053536257317511772939147258243384911045733411987516778587", "price": "0.99", "size": "895.28", "side": "SELL", "hash": "fff62ac6be1e4c7dd876d2f48774c28b0f1a1cdf", "best_bid": "0.2", "best_ask": "0.36"}], "timestamp": "1769384922038", "event_type": "price_change"}}
{"_local_timestamp": "2026-01-25T23:48:42.108044+00:00", "data": {"market": "0x528fe62a407a299d927d5b612386a4b4f558d4fb0776460373d7e97e8aea79db", "price_changes": [{"asset_id": "102485972951606238793769017987999788096270850857875715717770053964568134356702", "price": "0.14", "size": "9.3", "side": "BUY", "hash": "e431adb5cea499806728b6183ddb1949ff5c5352", "best_bid": "0.64", "best_ask": "0.8"}, {"asset_id": "36208978152381894236053536257317511772939147258243384911045733411987516778587", "price": "0.86", "size": "9.3", "side": "SELL", "hash": "1d46b606274719d88de49e8a03a7e982314f2e0d", "best_bid": "0.2", "best_ask": "0.36"}], "timestamp": "1769384922039", "event_type": "price_change"}}
{"_local_timestamp": "2026-01-25T23:48:42.108722+00:00", "data": {"market": "0x528fe62a407a299d927d5b612386a4b4f558d4fb0776460373d7e97e8aea79db", "price_changes": [{"asset_id": "102485972951606238793769017987999788096270850857875715717770053964568134356702", "price": "0.06", "size": "6.69", "side": "BUY", "hash": "d98ba7b99df01dbfe9e102dbaff3f6a8bf577a6a", "best_bid": "0.64", "best_ask": "0.8"}, {"asset_id": "36208978152381894236053536257317511772939147258243384911045733411987516778587", "price": "0.94", "size": "6.69", "side": "SELL", "hash": "c1e77a0db4905e85f09ac94aefa88a21e8b11330", "best_bid": "0.2", "best_ask": "0.36"}], "timestamp": "1769384922040", "event_type": "price_change"}}
{"_local_timestamp": "2026-01-25T23:48:42.109392+00:00", "data": {"market": "0x528fe62a407a299d927d5b612386a4b4f558d4fb0776460373d7e97e8aea79db", "price_changes": [{"asset_id": "102485972951606238793769017987999788096270850857875715717770053964568134356702", "price": "0.03", "size": "205.76", "side": "BUY", "hash": "d3105485317458953cf41baf3e96cf7dc46b3ca3", "best_bid": "0.64", "best_ask": "0.8"}, {"asset_id": "36208978152381894236053536257317511772939147258243384911045733411987516778587", "price": "0.97", "size": "205.76", "side": "SELL", "hash": "69ef9a3d853dceb1f169863b3490ad0d6c8a0867", "best_bid": "0.2", "best_ask": "0.36"}], "timestamp": "1769384922041", "event_type": "price_change"}}
{"_local_timestamp": "2026-01-25T23:48:42.313367+00:00", "data": {"market": "0x528fe62a407a299d927d5b612386a4b4f558d4fb0776460373d7e97e8aea79db", "price_changes": [{"asset_id": "102485972951606238793769017987999788096270850857875715717770053964568134356702", "price": "0.13", "size": "0", "side": "BUY", "hash": "55bf5a8e57e972c890813ba9421ac9367257b16e", "best_bid": "0.64", "best_ask": "0.8"}, {"asset_id": "36208978152381894236053536257317511772939147258243384911045733411987516778587", "price": "0.87", "size": "0", "side": "SELL", "hash": "385c7f4241feee6eaee77a81b67db68e25e41684", "best_bid": "0.2", "best_ask": "0.36"}], "timestamp": "1769384922246", "event_type": "price_change"}}
{"_local_timestamp": "2026-01-25T23:48:42.337259+00:00", "data": {"market": "0x528fe62a407a299d927d5b612386a4b4f558d4fb0776460373d7e97e8aea79db", "price_changes": [{"asset_id": "102485972951606238793769017987999788096270850857875715717770053964568134356702", "price": "0.15", "size": "20", "side": "BUY", "hash": "51e806e8a8ddc865c857e36a757bdc8a867c84ae", "best_bid": "0.64", "best_ask": "0.8"}, {"asset_id": "36208978152381894236053536257317511772939147258243384911045733411987516778587", "price": "0.85", "size": "20", "side": "SELL", "hash": "9ca57d096dba47a9b4256badbd326cf142208202", "best_bid": "0.2", "best_ask": "0.36"}], "timestamp": "1769384922269", "event_type": "price_change"}}
{"_local_timestamp": "2026-01-25T23:48:44.485077+00:00", "data": {"market": "0xeb13f5b879c912aaaa6ea4de58570f48f107db4c74f7e816becf030e6272fd9c", "price_changes": [{"asset_id": "113827665827621863662330176029339371613062711060109786539031002756320088862803", "price": "0.01", "size": "233", "side": "BUY", "hash": "a9e3df92baea4451ea9c9efba93c4395d6ec71cd", "best_bid": "0.06", "best_ask": "0.18"}, {"asset_id": "29829995287367853408312885951206913575599941748874598029431212839187459174632", "price": "0.99", "size": "233", "side": "SELL", "hash": "af10e88c9479efd0887cad4e29f0970e215d6e09", "best_bid": "0.82", "best_ask": "0.94"}], "timestamp": "1769384924420", "event_type": "price_change"}}
{"_local_timestamp": "2026-01-25T23:48:44.492833+00:00", "data": {"market": "0x4c65d9aa2bac477a2a9be69d9f707d9105d805d3d19b76854e23cb18bc08c465", "price_changes": [{"asset_id": "98682086811885890631327975014650377593666125070789241199777154553006778841258", "price": "0.01", "size": "313", "side": "BUY", "hash": "6155720a7f289e0fcb748c9849d74a5f3174cd64", "best_bid": "0.06", "best_ask": "0.13"}, {"asset_id": "56000570238632019339090117389091714658106578523885428868978722779674215227202", "price": "0.99", "size": "313", "side": "SELL", "hash": "98ec5b8e8cfecb8d63315ea72d58f91a3541ecdc", "best_bid": "0.87", "best_ask": "0.94"}], "timestamp": "1769384924420", "event_type": "price_change"}}
{"_local_timestamp": "2026-01-25T23:49:22.091110+00:00", "data": {"market": "0xeb13f5b879c912aaaa6ea4de58570f48f107db4c74f7e816becf030e6272fd9c", "price_changes": [{"asset_id": "29829995287367853408312885951206913575599941748874598029431212839187459174632", "price": "0.21", "size": "0", "side": "BUY", "hash": "ea7893ee748a2331b459b7a5bc44a439d15295c8", "best_bid": "0.82", "best_ask": "0.94"}, {"asset_id": "113827665827621863662330176029339371613062711060109786539031002756320088862803", "price": "0.79", "size": "0", "side": "SELL", "hash": "f42940b4131079e7b2e90b2387e641222bbfa969", "best_bid": "0.06", "best_ask": "0.18"}], "timestamp": "1769384962024", "event_type": "price_change"}}
{"_local_timestamp": "2026-01-25T23:49:22.143816+00:00", "data": {"market": "0xeb13f5b879c912aaaa6ea4de58570f48f107db4c74f7e816becf030e6272fd9c", "price_changes": [{"asset_id": "29829995287367853408312885951206913575599941748874598029431212839187459174632", "price": "0.23", "size": "8", "side": "BUY", "hash": "b95d718af4dc5e2bb30383eca64ca5f421c1060c", "best_bid": "0.82", "best_ask": "0.94"}, {"asset_id": "113827665827621863662330176029339371613062711060109786539031002756320088862803", "price": "0.77", "size": "8", "side": "SELL", "hash": "cf6d97de19122593e46185debd0d6bc721cf91de", "best_bid": "0.06", "best_ask": "0.18"}], "timestamp": "1769384962081", "event_type": "price_change"}}
{"_local_timestamp": "2026-01-25T23:49:22.999232+00:00", "data": {"market": "0xeb13f5b879c912aaaa6ea4de58570f48f107db4c74f7e816becf030e6272fd9c", "price_changes": [{"asset_id": "29829995287367853408312885951206913575599941748874598029431212839187459174632", "price": "0.22", "size": "0", "side": "BUY", "hash": "7ad2e5fdc56011be1cb3553c98e820c50fb0fc35", "best_bid": "0.82", "best_ask": "0.94"}, {"asset_id": "113827665827621863662330176029339371613062711060109786539031002756320088862803", "price": "0.78", "size": "0", "side": "SELL", "hash": "96a2178b4c661ea23d92702d643264027cfedb6b", "best_bid": "0.06", "best_ask": "0.18"}], "timestamp": "1769384962930", "event_type": "price_change"}}
{"_local_timestamp": "2026-01-25T23:49:23.025577+00:00", "data": {"market": "0xeb13f5b879c912aaaa6ea4de58570f48f107db4c74f7e816becf030e6272fd9c", "price_changes": [{"asset_id": "29829995287367853408312885951206913575599941748874598029431212839187459174632", "price": "0.24", "size": "20", "side": "BUY", "hash": "4ec8a540e43c267cbe092bf62a9de2b64480d706", "best_bid": "0.82", "best_ask": "0.94"}, {"asset_id": "113827665827621863662330176029339371613062711060109786539031002756320088862803", "price": "0.76", "size": "20", "side": "SELL", "hash": "e4ec0f90252440ce5fe83a5c3976dc3867df8796", "best_bid": "0.06", "best_ask": "0.18"}], "timestamp": "1769384962958", "event_type": "price_change"}}
{"_local_timestamp": "2026-01-25T23:49:28.926600+00:00", "data": {"market": "0xeb13f5b879c912aaaa6ea4de58570f48f107db4c74f7e816becf030e6272fd9c", "price_changes": [{"asset_id": "113827665827621863662330176029339371613062711060109786539031002756320088862803", "price": "0.01", "size": "261.57", "side": "BUY", "hash": "e4a15cf3230fae72b0a008b0a455167e8cf88c9f", "best_bid": "0.06", "best_ask": "0.18"}, {"asset_id": "29829995287367853408312885951206913575599941748874598029431212839187459174632", "price": "0.99", "size": "261.57", "side": "SELL", "hash": "d02dcab451a7821c01997559c7591a6cc116fcbc", "best_bid": "0.82", "best_ask": "0.94"}], "timestamp": "1769384968857", "event_type": "price_change"}}
{"_local_timestamp": "2026-01-25T23:49:28.930408+00:00", "data": {"market": "0x4c65d9aa2bac477a2a9be69d9f707d9105d805d3d19b76854e23cb18bc08c465", "price_changes": [{"asset_id": "98682086811885890631327975014650377593666125070789241199777154553006778841258", "price": "0.01", "size": "341.57", "side": "BUY", "hash": "e28429824d90dfcddecc6c6eb17674fcc0b7ccd9", "best_bid": "0.06", "best_ask": "0.13"}, {"asset_id": "56000570238632019339090117389091714658106578523885428868978722779674215227202", "price": "0.99", "size": "341.57", "side": "SELL", "hash": "540bed01009929267e1e8fa7e6f418d8a2d7f368", "best_bid": "0.87", "best_ask": "0.94"}], "timestamp": "1769384968857", "event_type": "price_change"}}
{"_local_timestamp": "2026-01-25T23:49:31.237224+00:00", "data": {"market": "0x930bda5ea16724849ebd2a879634f3ab04522c45a018a1957bbb0319d118c94e", "price_changes": [{"asset_id": "85973355253604996307258416942389548140991752390701227925867193238957025004704", "price": "0.003", "size": "400", "side": "BUY", "hash": "51c5ad12560effcadb55108916b7517a5a270fe9", "best_bid": "0.008", "best_ask": "0.075"}, {"asset_id": "1829171049271516235440282127137400632547540012227351935219418265043248885571", "price": "0.997", "size": "400", "side": "SELL", "hash": "086b527f51198541d5b38c38c865905a9f460d07", "best_bid": "0.925", "best_ask": "0.992"}], "timestamp": "1769384970915", "event_type": "price_change"}}
{"_local_timestamp": "2026-01-25T23:49:31.331755+00:00", "data": {"market": "0x930bda5ea16724849ebd2a879634f3ab04522c45a018a1957bbb0319d118c94e", "price_changes": [{"asset_id": "85973355253604996307258416942389548140991752390701227925867193238957025004704", "price": "0.003", "size": "423.5", "side": "BUY", "hash": "6fc1b631958b456216183142b984d1e848718a02", "best_bid": "0.008", "best_ask": "0.075"}, {"asset_id": "1829171049271516235440282127137400632547540012227351935219418265043248885571", "price": "0.997", "size": "423.5", "side": "SELL", "hash": "48b9913182524eab362cc935121e994576eead4c", "best_bid": "0.925", "best_ask": "0.992"}], "timestamp": "1769384971225", "event_type": "price_change"}}
{"_local_timestamp": "2026-01-25T23:49:44.831680+00:00", "data": {"market": "0xeb13f5b879c912aaaa6ea4de58570f48f107db4c74f7e816becf030e6272fd9c", "price_changes": [{"asset_id": "113827665827621863662330176029339371613062711060109786539031002756320088862803", "price": "0.01", "size": "233", "side": "BUY", "hash": "e4541bb28fc892de99c74c49a6c2b279741164e2", "best_bid": "0.06", "best_ask": "0.18"}, {"asset_id": "29829995287367853408312885951206913575599941748874598029431212839187459174632", "price": "0.99", "size": "233", "side": "SELL", "hash": "84fb2135f037e5d7c17138b39acb2514a41bd755", "best_bid": "0.82", "best_ask": "0.94"}], "timestamp": "1769384984761", "event_type": "price_change"}}
{"_local_timestamp": "2026-01-25T23:49:44.838052+00:00", "data": {"market": "0x4c65d9aa2bac477a2a9be69d9f707d9105d805d3d19b76854e23cb18bc08c465", "price_changes": [{"asset_id": "98682086811885890631327975014650377593666125070789241199777154553006778841258", "price": "0.01", "size": "313", "side": "BUY", "hash": "069305b46a989a98033578143ef0768ea7c107dd", "best_bid": "0.06", "best_ask": "0.13"}, {"asset_id": "56000570238632019339090117389091714658106578523885428868978722779674215227202", "price": "0.99", "size": "313", "side": "SELL", "hash": "4561460cd50d274c781cfe6292312d6cf5d1fc2e", "best_bid": "0.87", "best_ask": "0.94"}], "timestamp": "1769384984761", "event_type": "price_change"}}
{"_local_timestamp": "2026-01-25T23:49:50.083722+00:00", "data": {"market": "0x930bda5ea16724849ebd2a879634f3ab04522c45a018a1957bbb0319d118c94e", "price_changes": [{"asset_id": "1829171049271516235440282127137400632547540012227351935219418265043248885571", "price": "0.253", "size": "0", "side": "BUY", "hash": "99fa0519dbe8f46a910856cf07b6e413f74161e2", "best_bid": "0.925", "best_ask": "0.992"}, {"asset_id": "85973355253604996307258416942389548140991752390701227925867193238957025004704", "price": "0.747", "size": "0", "side": "SELL", "hash": "00cfc08726f38dc573cef81e04d3c244a1543602", "best_bid": "0.008", "best_ask": "0.075"}], "timestamp": "1769384989969", "event_type": "price_change"}}
{"_local_timestamp": "2026-01-25T23:50:16.806823+00:00", "data": {"market": "0xd4e866883ef71c1a0686768b2089df0ee27f4bc6fb09fd6c5322826d788446b1", "price_changes": [{"asset_id": "82597844215693023613587868745168688782245401597513036676400621185216539262737", "price": "0.49", "size": "92.5", "side": "BUY", "hash": "556fdcd08e2ef40cbb784b5819038f3615d86770", "best_bid": "0.49", "best_ask": "0.81"}, {"asset_id": "42562896281558908480353570722568310587471823543536714415123687719180859691787", "price": "0.51", "size": "92.5", "side": "SELL", "hash": "279b7cddd79a0d1f5325ea05555d5a9b3e7c8e05", "best_bid": "0.19", "best_ask": "0.51"}], "timestamp": "1769385016736", "event_type": "price_change"}}
{"_local_timestamp": "2026-01-25T23:50:16.807959+00:00", "data": {"market": "0x4c2eb1c2553628d59b2dbb4640b6d650637bd6a1462cff94334355ae206ae7b4", "price_changes": [{"asset_id": "48370595165483556992313158202325404898706481073615732950100193255535553444828", "price": "0.5", "size": "72.5", "side": "BUY", "hash": "e485ab86d9aba6f9d1888d1c2663bb6cdf17eb1a", "best_bid": "0.57", "best_ask": "0.81"}, {"asset_id": "42433781921146230236897276928227396822059794002552428345815748354041495759547", "price": "0.5", "size": "72.5", "side": "SELL", "hash": "9e85cc7d545d01c572137b6ebaf68a082f16ba62", "best_bid": "0.19", "best_ask": "0.43"}], "timestamp": "1769385016736", "event_type": "price_change"}}
{"_local_timestamp": "2026-01-25T23:50:16.808696+00:00", "data": {"market": "0xd4e866883ef71c1a0686768b2089df0ee27f4bc6fb09fd6c5322826d788446b1", "price_changes": [{"asset_id": "82597844215693023613587868745168688782245401597513036676400621185216539262737", "price": "0.5", "size": "67", "side": "BUY", "hash": "410db9ba49ff70d1daf80c6c0c400be2811d664c", "best_bid": "0.5", "best_ask": "0.81"}, {"asset_id": "42562896281558908480353570722568310587471823543536714415123687719180859691787", "price": "0.5", "size": "67", "side": "SELL", "hash": "00f72c922c54083e7875a30353b33d8187038ead", "best_bid": "0.19", "best_ask": "0.5"}], "timestamp": "1769385016737", "event_type": "price_change"}}
{"_local_timestamp": "2026-01-25T23:50:18.418783+00:00", "data": {"market": "0x4c2eb1c2553628d59b2dbb4640b6d650637bd6a1462cff94334355ae206ae7b4", "price_changes": [{"asset_id": "48370595165483556992313158202325404898706481073615732950100193255535553444828", "price": "0.46", "size": "0", "side": "BUY", "hash": "e7028ae293fd99a5f6aabca2157049f36289673f", "best_bid": "0.57", "best_ask": "0.81"}, {"asset_id": "42433781921146230236897276928227396822059794002552428345815748354041495759547", "price": "0.54", "size": "0", "side": "SELL", "hash": "d3d31bd13b9822ca3db9228e101e9eb5580e384f", "best_bid": "0.19", "best_ask": "0.43"}], "timestamp": "1769385018355", "event_type": "price_change"}}
{"_local_timestamp": "2026-01-25T23:50:18.419627+00:00", "data": {"market": "0xd4e866883ef71c1a0686768b2089df0ee27f4bc6fb09fd6c5322826d788446b1", "price_changes": [{"asset_id": "82597844215693023613587868745168688782245401597513036676400621185216539262737", "price": "0.49", "size": "72.5", "side": "BUY", "hash": "0b3436ebef10e49da44fe3feb1555f06dd06c2fb", "best_bid": "0.5", "best_ask": "0.81"}, {"asset_id": "42562896281558908480353570722568310587471823543536714415123687719180859691787", "price": "0.51", "size": "72.5", "side": "SELL", "hash": "9dbacb432453bb1607586f821d710c7d8c05d751", "best_bid": "0.19", "best_ask": "0.5"}], "timestamp": "1769385018355", "event_type": "price_change"}}
{"_local_timestamp": "2026-01-25T23:50:18.450579+00:00", "data": {"market": "0xd4e866883ef71c1a0686768b2089df0ee27f4bc6fb09fd6c5322826d788446b1", "price_changes": [{"asset_id": "82597844215693023613587868745168688782245401597513036676400621185216539262737", "price": "0.5", "size": "87", "side": "BUY", "hash": "322484f60f13ae43ca499ac99139913ac9c2bee2", "best_bid": "0.5", "best_ask": "0.81"}, {"asset_id": "42562896281558908480353570722568310587471823543536714415123687719180859691787", "price": "0.5", "size": "87", "side": "SELL", "hash": "11f4d29eb0701cc32123485cc66f4e60cf77629d", "best_bid": "0.19", "best_ask": "0.5"}], "timestamp": "1769385018384", "event_type": "price_change"}}
{"_local_timestamp": "2026-01-25T23:50:18.451366+00:00", "data": {"market": "0x4c2eb1c2553628d59b2dbb4640b6d650637bd6a1462cff94334355ae206ae7b4", "price_changes": [{"asset_id": "48370595165483556992313158202325404898706481073615732950100193255535553444828", "price": "0.5", "size": "92.5", "side": "BUY", "hash": "d7f88480a5cff33819e86cc3cdbf1929a3b8f281", "best_bid": "0.57", "best_ask": "0.81"}, {"asset_id": "42433781921146230236897276928227396822059794002552428345815748354041495759547", "price": "0.5", "size": "92.5", "side": "SELL", "hash": "6d61da0504a55ee1c63f9c5ac6eb566aae588db9", "best_bid": "0.19", "best_ask": "0.43"}], "timestamp": "1769385018384", "event_type": "price_change"}}
{"_local_timestamp": "2026-01-25T23:50:22.691275+00:00", "data": {"market": "0x930bda5ea16724849ebd2a879634f3ab04522c45a018a1957bbb0319d118c94e", "price_changes": [{"asset_id": "1829171049271516235440282127137400632547540012227351935219418265043248885571", "price": "0.256", "size": "45", "side": "BUY", "hash": "bcd1a5c42b3358f6892625f43bf3b7813957bd19", "best_bid": "0.925", "best_ask": "0.992"}, {"asset_id": "85973355253604996307258416942389548140991752390701227925867193238957025004704", "price": "0.744", "size": "45", "side": "SELL", "hash": "a64a0cbd0db0abe392407963eed98be89399f08e", "best_bid": "0.008", "best_ask": "0.075"}], "timestamp": "1769385022626", "event_type": "price_change"}}
{"_local_timestamp": "2026-01-25T23:50:24.696590+00:00", "data": {"market": "0xeb13f5b879c912aaaa6ea4de58570f48f107db4c74f7e816becf030e6272fd9c", "price_changes": [{"asset_id": "29829995287367853408312885951206913575599941748874598029431212839187459174632", "price": "0.01", "size": "788.65", "side": "BUY", "hash": "31ab22342784c48d9375141a621d7100dc4b52f7", "best_bid": "0.82", "best_ask": "0.94"}, {"asset_id": "113827665827621863662330176029339371613062711060109786539031002756320088862803", "price": "0.99", "size": "788.65", "side": "SELL", "hash": "e38e8e4f641a60a7207ab8c14b81a95d69b0b5fc", "best_bid": "0.06", "best_ask": "0.18"}], "timestamp": "1769385024629", "event_type": "price_change"}}
{"_local_timestamp": "2026-01-25T23:50:26.629559+00:00", "data": {"market": "0x930bda5ea16724849ebd2a879634f3ab04522c45a018a1957bbb0319d118c94e", "price_changes": [{"asset_id": "1829171049271516235440282127137400632547540012227351935219418265043248885571", "price": "0.255", "size": "0", "side": "BUY", "hash": "cd4326c0bae94f7b7abe217a79e81019413f07f9", "best_bid": "0.925", "best_ask": "0.992"}, {"asset_id": "85973355253604996307258416942389548140991752390701227925867193238957025004704", "price": "0.745", "size": "0", "side": "SELL", "hash": "c3ff1e5dd085503222c2f1f16dbb56b175dd3bdd", "best_bid": "0.008", "best_ask": "0.075"}], "timestamp": "1769385026554", "event_type": "price_change"}}
{"_local_timestamp": "2026-01-25T23:50:26.647557+00:00", "data": {"market": "0x930bda5ea16724849ebd2a879634f3ab04522c45a018a1957bbb0319d118c94e", "price_changes": [{"asset_id": "1829171049271516235440282127137400632547540012227351935219418265043248885571", "price": "0.257", "size": "20", "side": "BUY", "hash": "ecf2d8581d1680a9f2ab1a34197350a2b1f3508f", "best_bid": "0.925", "best_ask": "0.992"}, {"asset_id": "85973355253604996307258416942389548140991752390701227925867193238957025004704", "price": "0.743", "size": "20", "side": "SELL", "hash": "d9c11f0ff2d093e936b63180d484d86e6c1910ca", "best_bid": "0.008", "best_ask": "0.075"}], "timestamp": "1769385026584", "event_type": "price_change"}}
{"_local_timestamp": "2026-01-25T23:50:29.392089+00:00", "data": {"market": "0xd4e866883ef71c1a0686768b2089df0ee27f4bc6fb09fd6c5322826d788446b1", "price_changes": [{"asset_id": "82597844215693023613587868745168688782245401597513036676400621185216539262737", "price": "0.49", "size": "5.5", "side": "BUY", "hash": "f3681c75edc473d70c44a2cfac12680c74bea4d5", "best_bid": "0.5", "best_ask": "0.81"}, {"asset_id": "42562896281558908480353570722568310587471823543536714415123687719180859691787", "price": "0.51", "size": "5.5", "side": "SELL", "hash": "59e4f5f60ff70f509afbfed756e5d0d75006c020", "best_bid": "0.19", "best_ask": "0.5"}], "timestamp": "1769385029313", "event_type": "price_change"}}
{"_local_timestamp": "2026-01-25T23:50:31.135901+00:00", "data": {"market": "0x4c65d9aa2bac477a2a9be69d9f707d9105d805d3d19b76854e23cb18bc08c465", "price_changes": [{"asset_id": "56000570238632019339090117389091714658106578523885428868978722779674215227202", "price": "0.06", "size": "83", "side": "BUY", "hash": "d5aa2bcfb24faa30dd66ca051a24be9c72710e87", "best_bid": "0.87", "best_ask": "0.94"}, {"asset_id": "98682086811885890631327975014650377593666125070789241199777154553006778841258", "price": "0.94", "size": "83", "side": "SELL", "hash": "ab78e96ba5239692b23eb1847f96773a517e719a", "best_bid": "0.06", "best_ask": "0.13"}], "timestamp": "1769385031058", "event_type": "price_change"}}
{"_local_timestamp": "2026-01-25T23:50:31.136789+00:00", "data": {"market": "0x4c65d9aa2bac477a2a9be69d9f707d9105d805d3d19b76854e23cb18bc08c465", "price_changes": [{"asset_id": "56000570238632019339090117389091714658106578523885428868978722779674215227202", "price": "0.14", "size": "0", "side": "BUY", "hash": "d5aa2bcfb24faa30dd66ca051a24be9c72710e87", "best_bid": "0.87", "best_ask": "0.94"}, {"asset_id": "98682086811885890631327975014650377593666125070789241199777154553006778841258", "price": "0.86", "size": "0", "side": "SELL", "hash": "ab78e96ba5239692b23eb1847f96773a517e719a", "best_bid": "0.06", "best_ask": "0.13"}], "timestamp": "1769385031058", "event_type": "price_change"}}
{"_local_timestamp": "2026-01-25T23:50:31.518322+00:00", "data": {"market": "0x4c65d9aa2bac477a2a9be69d9f707d9105d805d3d19b76854e23cb18bc08c465", "price_changes": [{"asset_id": "56000570238632019339090117389091714658106578523885428868978722779674215227202", "price": "0.07", "size": "45.95", "side": "BUY", "hash": "0929a65c615c2e7be093c13dcc0328bf3dbb06d7", "best_bid": "0.87", "best_ask": "0.94"}, {"asset_id": "98682086811885890631327975014650377593666125070789241199777154553006778841258", "price": "0.93", "size": "45.95", "side": "SELL", "hash": "2709339fb1619c9f9c9147cccd22ee6bbd87d208", "best_bid": "0.06", "best_ask": "0.13"}], "timestamp": "1769385031442", "event_type": "price_change"}}
{"_local_timestamp": "2026-01-25T23:50:31.519618+00:00", "data": {"market": "0x4c65d9aa2bac477a2a9be69d9f707d9105d805d3d19b76854e23cb18bc08c465", "price_changes": [{"asset_id": "56000570238632019339090117389091714658106578523885428868978722779674215227202", "price": "0.16", "size": "8.17", "side": "BUY", "hash": "708f4efd295f04dc4c72083cbc9ee09b3abeb165", "best_bid": "0.87", "best_ask": "0.94"}, {"asset_id": "98682086811885890631327975014650377593666125070789241199777154553006778841258", "price": "0.84", "size": "8.17", "side": "SELL", "hash": "854ee1a8e38a2139a8844b53e12afe4611808e1a", "best_bid": "0.06", "best_ask": "0.13"}], "timestamp": "1769385031443", "event_type": "price_change"}}
{"_local_timestamp": "2026-01-25T23:50:31.873175+00:00", "data": {"market": "0x4c65d9aa2bac477a2a9be69d9f707d9105d805d3d19b76854e23cb18bc08c465", "price_changes": [{"asset_id": "56000570238632019339090117389091714658106578523885428868978722779674215227202", "price": "0.15", "size": "0", "side": "BUY", "hash": "a45d94c2e516c4d273668acb04fec59645c30a82", "best_bid": "0.87", "best_ask": "0.94"}, {"asset_id": "98682086811885890631327975014650377593666125070789241199777154553006778841258", "price": "0.85", "size": "0", "side": "SELL", "hash": "b5385d71e2e3c69e64cf9e93ffe32883ced63410", "best_bid": "0.06", "best_ask": "0.13"}], "timestamp": "1769385031804", "event_type": "price_change"}}
{"_local_timestamp": "2026-01-25T23:50:31.906580+00:00", "data": {"market": "0x4c65d9aa2bac477a2a9be69d9f707d9105d805d3d19b76854e23cb18bc08c465", "price_changes": [{"asset_id": "56000570238632019339090117389091714658106578523885428868978722779674215227202", "price": "0.17", "size": "20", "side": "BUY", "hash": "d9768298471967fe02604e37822e05a9a2b8ce65", "best_bid": "0.87", "best_ask": "0.94"}, {"asset_id": "98682086811885890631327975014650377593666125070789241199777154553006778841258", "price": "0.83", "size": "20", "side": "SELL", "hash": "460a6d4f7fea9c978f9036b0822688b465da973e", "best_bid": "0.06", "best_ask": "0.13"}], "timestamp": "1769385031832", "event_type": "price_change"}}
{"_local_timestamp": "2026-01-25T23:50:32.928848+00:00", "data": {"market": "0x528fe62a407a299d927d5b612386a4b4f558d4fb0776460373d7e97e8aea79db", "price_changes": [{"asset_id": "102485972951606238793769017987999788096270850857875715717770053964568134356702", "price": "0.14", "size": "0", "side": "BUY", "hash": "963a31148a7509ad4402e80de8651269f2ecb904", "best_bid": "0.64", "best_ask": "0.8"}, {"asset_id": "36208978152381894236053536257317511772939147258243384911045733411987516778587", "price": "0.86", "size": "0", "side": "SELL", "hash": "1ff5cbaeff550cc08e244838c15c3426ff244cb3", "best_bid": "0.2", "best_ask": "0.36"}], "timestamp": "1769385032851", "event_type": "price_change"}}
{"_local_timestamp": "2026-01-25T23:50:33.296304+00:00", "data": {"market": "0x528fe62a407a299d927d5b612386a4b4f558d4fb0776460373d7e97e8aea79db", "price_changes": [{"asset_id": "102485972951606238793769017987999788096270850857875715717770053964568134356702", "price": "0.16", "size": "8.14", "side": "BUY", "hash": "f2aab444021815fdaa073bdcd0aef1d4a9c2ea74", "best_bid": "0.64", "best_ask": "0.8"}, {"asset_id": "36208978152381894236053536257317511772939147258243384911045733411987516778587", "price": "0.84", "size": "8.14", "side": "SELL", "hash": "6f462ac3a233491fa08f59a2acc7fc79a0dcefa0", "best_bid": "0.2", "best_ask": "0.36"}], "timestamp": "1769385033223", "event_type": "price_change"}}
{"_local_timestamp": "2026-01-25T23:50:34.125065+00:00", "data": {"market": "0x528fe62a407a299d927d5b612386a4b4f558d4fb0776460373d7e97e8aea79db", "price_changes": [{"asset_id": "102485972951606238793769017987999788096270850857875715717770053964568134356702", "price": "0.15", "size": "0", "side": "BUY", "hash": "76058c4cf348663541e8e838fc32565079a880ec", "best_bid": "0.64", "best_ask": "0.8"}, {"asset_id": "36208978152381894236053536257317511772939147258243384911045733411987516778587", "price": "0.85", "size": "0", "side": "SELL", "hash": "6788661109dab3e7206d1dfa9427d125cab16f69", "best_bid": "0.2", "best_ask": "0.36"}], "timestamp": "1769385034054", "event_type": "price_change"}}
{"_local_timestamp": "2026-01-25T23:50:34.145878+00:00", "data": {"market": "0x528fe62a407a299d927d5b612386a4b4f558d4fb0776460373d7e97e8aea79db", "price_changes": [{"asset_id": "102485972951606238793769017987999788096270850857875715717770053964568134356702", "price": "0.17", "size": "20", "side": "BUY", "hash": "232199608e7857f729dcf11028312bb42d70a869", "best_bid": "0.64", "best_ask": "0.8"}, {"asset_id": "36208978152381894236053536257317511772939147258243384911045733411987516778587", "price": "0.83", "size": "20", "side": "SELL", "hash": "c1df3da68a8720c1cdf0f4fe723e5d8d93f911a7", "best_bid": "0.2", "best_ask": "0.36"}], "timestamp": "1769385034077", "event_type": "price_change"}}
