{"_local_timestamp": "2026-01-25T23:41:24.888673+00:00", "data": [{"market": "0xf81a1470a1df60b339e19ef08f4f50f6b1e16b72abc5ada0abeba3176f6ebf39", "asset_id": "31066355360623088659431128901874672236359160986840206439049282354337176000405", "timestamp": "1769384460924", "hash": "d30df8e782e154fb0b1d5ad8c94dcc3c35c52ba8", "bids": [{"price": "0.001", "size": "10862.13"}], "asks": [{"price": "0.999", "size": "7776.84"}, {"price": "0.998", "size": "1755.83"}, {"price": "0.997", "size": "1166"}, {"price": "0.996", "size": "10.09"}, {"price": "0.994", "size": "83"}, {"price": "0.99", "size": "2781.5"}, {"price": "0.989", "size": "5.14"}, {"price": "0.98", "size": "3400"}, {"price": "0.979", "size": "7.98"}, {"price": "0.95", "size": "100"}, {"price": "0.949", "size": "39"}, {"price": "0.94", "size": "200"}, {"price": "0.939", "size": "7.47"}, {"price": "0.89", "size": "125"}, {"price": "0.84", "size": "100"}, {"price": "0.839", "size": "7.84"}, {"price": "0.8", "size": "5"}, {"price": "0.79", "size": "50"}, {"price": "0.789", "size": "9"}, {"price": "0.5", "size": "13.08"}, {"price": "0.31", "size": "10"}, {"price": "0.277", "size": "8"}, {"price": "0.11", "size": "10"}, {"price": "0.109", "size": "20"}, {"price": "0.1", "size": "5"}, {"price": "0.077", "size": "93"}, {"price": "0.07", "size": "10"}, {"price": "0.06", "size": "60"}, {"price": "0.05", "size": "500"}, {"price": "0.049", "size": "50"}, {"price": "0.009", "size": "10"}, {"price": "0.008", "size": "28.17"}, {"price": "0.005", "size": "7"}, {"price": "0.004", "size": "10.5"}], "event_type": "book", "last_trade_price": "0.001"}, {"market": "0xc98360464eaf681200432e9d5f4e6af1717b26415587fc0729001529e9244bf0", "asset_id": "106154843522663118346636909846921460990194186879780202123781120445178139681772", "timestamp": "1769384404515", "hash": "25b091b693094a422e1b438b5d79e47b55762bfd", "bids": [{"price": "0.001", "size": "671.22"}], "asks": [{"price": "0.999", "size": "7788.84"}, {"price": "0.998", "size": "1255.83"}, {"price": "0.997", "size": "1166"}, {"price": "0.996", "size": "10.09"}, {"price": "0.994", "size": "83"}, {"price": "0.99", "size": "2781.5"}, {"price": "0.989", "size": "5.63"}, {"price": "0.98", "size": "3400"}, {"price": "0.979", "size": "2137.4"}, {"price": "0.978", "size": "9.37"}, {"price": "0.959", "size": "48"}, {"price": "0.95", "size": "60"}, {"price": "0.949", "size": "39"}, {"price": "0.94", "size": "200"}, {"price": "0.939", "size": "9.71"}, {"price": "0.89", "size": "125"}, {"price": "0.84", "size": "100"}, {"price": "0.8", "size": "20"}, {"price": "0.799", "size": "5.38"}, {"price": "0.777", "size": "108"}, {"price": "0.776", "size": "8"}, {"price": "0.5", "size": "10"}, {"price": "0.477", "size": "117"}, {"price": "0.34", "size": "10"}, {"price": "0.277", "size": "35"}, {"price": "0.177", "size": "282"}, {"price": "0.11", "size": "5"}, {"price": "0.1", "size": "10"}, {"price": "0.099", "size": "20"}, {"price": "0.077", "size": "346"}, {"price": "0.076", "size": "50"}, {"price": "0.065", "size": "47"}, {"price": "0.007", "size": "20.01"}, {"price": "0.005", "size": "275"}], "event_type": "book", "last_trade_price": "0.001"}, {"market": "0x03c6817aa84a2b980d54fdd383dd530797ba4b6c27e48591e682cfdbf7449754", "asset_id": "81177944114764661253164662145140713030265691622775789519288758937685378375453", "timestamp": "1769384463859", "hash": "6b48566e0b3580e90c532364be267e31e49f780a", "bids": [{"price": "0.001", "size": "7784.84"}, {"price": "0.002", "size": "1255.83"}, {"price": "0.003", "size": "1166"}, {"price": "0.004", "size": "10.09"}, {"price": "0.006", "size": "83"}, {"price": "0.01", "size": "2781.5"}, {"price": "0.011", "size": "5.14"}, {"price": "0.02", "size": "3400"}, {"price": "0.021", "size": "7.9"}, {"price": "0.041", "size": "48"}, {"price": "0.05", "size": "60"}, {"price": "0.051", "size": "39"}, {"price": "0.06", "size": "200"}, {"price": "0.061", "size": "7.47"}, {"price": "0.11", "size": "125"}, {"price": "0.16", "size": "100"}, {"price": "0.161", "size": "7.84"}, {"price": "0.21", "size": "50"}, {"price": "0.3", "size": "20"}, {"price": "0.301", "size": "6"}, {"price": "0.886", "size": "5"}, {"price": "0.891", "size": "9.94"}, {"price": "0.892", "size": "20"}, {"price": "0.943", "size": "122.45"}, {"price": "0.944", "size": "20"}, {"price": "0.949", "size": "15"}, {"price": "0.951", "size": "7"}, {"price": "0.952", "size": "6"}, {"price": "0.954", "size": "49.1"}, {"price": "0.955", "size": "50"}, {"price": "0.956", "size": "9"}], "asks": [{"price": "0.999", "size": "12549.46"}, {"price": "0.998", "size": "5134.97"}, {"price": "0.995", "size": "174"}, {"price": "0.993", "size": "1970"}, {"price": "0.992", "size": "265"}], "event_type": "book", "last_trade_price": "0.990"}, {"market": "0x3cb3b76b6a4c3fdc6f933464859626df576eaf3e3e404ead3e75056fd48c04f5", "asset_id": "106006396008449636653509336329453630557359114983730727555924443870035053210127", "timestamp": "1769384484659", "hash": "944e9ebdbfcc6f3eacb716bf7b1c94080177d846", "bids": [{"price": "0.01", "size": "2744.36"}, {"price": "0.02", "size": "3407.5"}, {"price": "0.03", "size": "66"}, {"price": "0.04", "size": "5.28"}, {"price": "0.05", "size": "20"}, {"price": "0.07", "size": "9.29"}, {"price": "0.1", "size": "10"}, {"price": "0.17", "size": "200"}, {"price": "0.18", "size": "15.09"}, {"price": "0.2", "size": "25"}, {"price": "0.32", "size": "61.54"}, {"price": "0.33", "size": "100"}, {"price": "0.34", "size": "20"}, {"price": "0.35", "size": "5"}, {"price": "0.37", "size": "16"}, {"price": "0.38", "size": "163.55"}, {"price": "0.39", "size": "30"}], "asks": [{"price": "0.99", "size": "2389.5"}, {"price": "0.98", "size": "1405"}, {"price": "0.97", "size": "14.52"}, {"price": "0.94", "size": "330"}, {"price": "0.93", "size": "15"}, {"price": "0.89", "size": "125"}, {"price": "0.86", "size": "15"}, {"price": "0.84", "size": "100"}, {"price": "0.83", "size": "10"}, {"price": "0.82", "size": "6"}, {"price": "0.8", "size": "5"}, {"price": "0.79", "size": "50"}, {"price": "0.76", "size": "32"}, {"price": "0.75", "size": "8"}, {"price": "0.58", "size": "10"}, {"price": "0.53", "size": "30"}, {"price": "0.5", "size": "90"}, {"price": "0.49", "size": "100"}, {"price": "0.47", "size": "53.92"}, {"price": "0.45", "size": "124.25"}, {"price": "0.44", "size": "29.62"}], "event_type": "book", "last_trade_price": "0.560"}, {"market": "0xc98360464eaf681200432e9d5f4e6af1717b26415587fc0729001529e9244bf0", "asset_id": "42965909532341023203156107784861847526426548942642864755763404570972223043030", "timestamp": "1769384404515", "hash": "51489b2efb195bbb646275bdef1387f6795b8a46", "bids": [{"price": "0.001", "size": "7788.84"}, {"price": "0.002", "size": "1255.83"}, {"price": "0.003", "size": "1166"}, {"price": "0.004", "size": "10.09"}, {"price": "0.006", "size": "83"}, {"price": "0.01", "size": "2781.5"}, {"price": "0.011", "size": "5.63"}, {"price": "0.02", "size": "3400"}, {"price": "0.021", "size": "2137.4"}, {"price": "0.022", "size": "9.37"}, {"price": "0.041", "size": "48"}, {"price": "0.05", "size": "60"}, {"price": "0.051", "size": "39"}, {"price": "0.06", "size": "200"}, {"price": "0.061", "size": "9.71"}, {"price": "0.11", "size": "125"}, {"price": "0.16", "size": "100"}, {"price": "0.2", "size": "20"}, {"price": "0.201", "size": "5.38"}, {"price": "0.223", "size": "108"}, {"price": "0.224", "size": "8"}, {"price": "0.5", "size": "10"}, {"price": "0.523", "size": "117"}, {"price": "0.66", "size": "10"}, {"price": "0.723", "size": "35"}, {"price": "0.823", "size": "282"}, {"price": "0.89", "size": "5"}, {"price": "0.9", "size": "10"}, {"price": "0.901", "size": "20"}, {"price": "0.923", "size": "346"}, {"price": "0.924", "size": "50"}, {"price": "0.935", "size": "47"}, {"price": "0.993", "size": "20.01"}, {"price": "0.995", "size": "275"}], "asks": [{"price": "0.999", "size": "671.22"}], "event_type": "book", "last_trade_price": "0.001"}, {"market": "0x8b9ba80fb00ffd3ea3d259e0e3d64c2bc057e2d258dbb416138082721491de1f", "asset_id": "95471394592044775311259204363647835057798671562193368798960379123943071173821", "timestamp": "1769384482092", "hash": "3539f95101ccdb40b3709c0b9e9f8cf2b3153b02", "bids": [{"price": "0.001", "size": "1702"}, {"price": "0.002", "size": "500"}, {"price": "0.003", "size": "1006.14"}, {"price": "0.006", "size": "1000"}, {"price": "0.007", "size": "6.98"}, {"price": "0.01", "size": "504.5"}, {"price": "0.011", "size": "1799.73"}, {"price": "0.012", "size": "400"}, {"price": "0.013", "size": "200"}, {"price": "0.016", "size": "13.15"}, {"price": "0.02", "size": "151"}, {"price": "0.022", "size": "53"}], "asks": [{"price": "0.999", "size": "5913.69"}, {"price": "0.998", "size": "1505.18"}, {"price": "0.997", "size": "1000"}, {"price": "0.996", "size": "8.96"}, {"price": "0.99", "size": "1781.5"}, {"price": "0.989", "size": "5.16"}, {"price": "0.98", "size": "3000"}, {"price": "0.979", "size": "17.11"}, {"price": "0.978", "size": "9.63"}, {"price": "0.95", "size": "100"}, {"price": "0.94", "size": "33"}, {"price": "0.939", "size": "10.6"}, {"price": "0.9", "size": "273.4"}, {"price": "0.898", "size": "19"}, {"price": "0.897", "size": "14.39"}, {"price": "0.5", "size": "11.14"}, {"price": "0.15", "size": "9.09"}, {"price": "0.12", "size": "5"}, {"price": "0.11", "size": "119.03"}, {"price": "0.109", "size": "20"}, {"price": "0.09", "size": "20.18"}, {"price": "0.083", "size": "5.79"}, {"price": "0.079", "size": "5.79"}, {"price": "0.074", "size": "25"}, {"price": "0.073", "size": "5"}, {"price": "0.072", "size": "14.48"}], "event_type": "book", "last_trade_price": "0.022"}, {"market": "0x07a77d4ac864ae8782c36437e175ea35a810775cac542978ed318b3421330bcd", "asset_id": "5831166839639059436338242242541375169895658234727937972141068292901230575322", "timestamp": "1769384470508", "hash": "b92241494e0860d35c931df033c0ff3e91e91ca0", "bids": [{"price": "0.001", "size": "2168.85"}, {"price": "0.002", "size": "26.01"}, {"price": "0.01", "size": "881.5"}, {"price": "0.011", "size": "5.13"}, {"price": "0.02", "size": "2000"}, {"price": "0.021", "size": "19.19"}, {"price": "0.05", "size": "100"}, {"price": "0.06", "size": "33"}, {"price": "0.08", "size": "30"}, {"price": "0.1", "size": "20"}, {"price": "0.101", "size": "14.67"}, {"price": "0.2", "size": "5"}, {"price": "0.84", "size": "9.9"}, {"price": "0.841", "size": "20"}, {"price": "0.92", "size": "58.75"}, {"price": "0.93", "size": "30"}, {"price": "0.94", "size": "40"}, {"price": "0.941", "size": "15"}, {"price": "0.95", "size": "130"}], "asks": [{"price": "0.999", "size": "1163"}, {"price": "0.998", "size": "84.24"}, {"price": "0.99", "size": "1211.5"}, {"price": "0.98", "size": "116.18"}], "event_type": "book", "last_trade_price": "0.020"}, {"market": "0x8b9ba80fb00ffd3ea3d259e0e3d64c2bc057e2d258dbb416138082721491de1f", "asset_id": "58714825001137751155185117146321345902961648511702872797387135565669201406384", "timestamp": "1769384482092", "hash": "e0806d6c661a82a24f9964e489f598cd3f4d700e", "bids": [{"price": "0.001", "size": "5913.69"}, {"price": "0.002", "size": "1505.18"}, {"price": "0.003", "size": "1000"}, {"price": "0.004", "size": "8.96"}, {"price": "0.01", "size": "1781.5"}, {"price": "0.011", "size": "5.16"}, {"price": "0.02", "size": "3000"}, {"price": "0.021", "size": "17.11"}, {"price": "0.022", "size": "9.63"}, {"price": "0.05", "size": "100"}, {"price": "0.06", "size": "33"}, {"price": "0.061", "size": "10.6"}, {"price": "0.1", "size": "273.4"}, {"price": "0.102", "size": "19"}, {"price": "0.103", "size": "14.39"}, {"price": "0.5", "size": "11.14"}, {"price": "0.85", "size": "9.09"}, {"price": "0.88", "size": "5"}, {"price": "0.89", "size": "119.03"}, {"price": "0.891", "size": "20"}, {"price": "0.91", "size": "20.18"}, {"price": "0.917", "size": "5.79"}, {"price": "0.921", "size": "5.79"}, {"price": "0.926", "size": "25"}, {"price": "0.927", "size": "5"}, {"price": "0.928", "size": "14.48"}], "asks": [{"price": "0.999", "size": "1702"}, {"price": "0.998", "size": "500"}, {"price": "0.997", "size": "1006.14"}, {"price": "0.994", "size": "1000"}, {"price": "0.993", "size": "6.98"}, {"price": "0.99", "size": "504.5"}, {"price": "0.989", "size": "1799.73"}, {"price": "0.988", "size": "400"}, {"price": "0.987", "size": "200"}, {"price": "0.984", "size": "13.15"}, {"price": "0.98", "size": "151"}, {"price": "0.978", "size": "53"}], "event_type": "book", "last_trade_price": "0.022"}, {"market": "0x03c6817aa84a2b980d54fdd383dd530797ba4b6c27e48591e682cfdbf7449754", "asset_id": "80150595742123714617427381010000002467992506994314405336410604686924790622727", "timestamp": "1769384463859", "hash": "dd7b8c2961c761349e9ca65dbd331acb8f90b983", "bids": [{"price": "0.001", "size": "12549.46"}, {"price": "0.002", "size": "5134.97"}, {"price": "0.005", "size": "174"}, {"price": "0.007", "size": "1970"}, {"price": "0.008", "size": "265"}], "asks": [{"price": "0.999", "size": "7784.84"}, {"price": "0.998", "size": "1255.83"}, {"price": "0.997", "size": "1166"}, {"price": "0.996", "size": "10.09"}, {"price": "0.994", "size": "83"}, {"price": "0.99", "size": "2781.5"}, {"price": "0.989", "size": "5.14"}, {"price": "0.98", "size": "3400"}, {"price": "0.979", "size": "7.9"}, {"price": "0.959", "size": "48"}, {"price": "0.95", "size": "60"}, {"price": "0.949", "size": "39"}, {"price": "0.94", "size": "200"}, {"price": "0.939", "size": "7.47"}, {"price": "0.89", "size": "125"}, {"price": "0.84", "size": "100"}, {"price": "0.839", "size": "7.84"}, {"price": "0.79", "size": "50"}, {"price": "0.7", "size": "20"}, {"price": "0.699", "size": "6"}, {"price": "0.114", "size": "5"}, {"price": "0.109", "size": "9.94"}, {"price": "0.108", "size": "20"}, {"price": "0.057", "size": "122.45"}, {"price": "0.056", "size": "20"}, {"price": "0.051", "size": "15"}, {"price": "0.049", "size": "7"}, {"price": "0.048", "size": "6"}, {"price": "0.046", "size": "49.1"}, {"price": "0.045", "size": "50"}, {"price": "0.044", "size": "9"}], "event_type": "book", "last_trade_price": "0.990"}, {"market": "0x75700f135fc1aa9106eecad102e82a5e304afa684948c453d9020973a6dacda6", "asset_id": "106943703042015764099709708127099569908287532239730770276583638212344318814024", "timestamp": "1769384484179", "hash": "4431263a61c51402f39b6b26410d862db4d5259b", "bids": [{"price": "0.01", "size": "2894.22"}, {"price": "0.02", "size": "1400"}, {"price": "0.03", "size": "7.71"}, {"price": "0.05", "size": "20"}, {"price": "0.06", "size": "200"}, {"price": "0.07", "size": "6.93"}, {"price": "0.1", "size": "10"}, {"price": "0.12", "size": "325"}, {"price": "0.16", "size": "100"}, {"price": "0.17", "size": "17.8"}, {"price": "0.25", "size": "100"}, {"price": "0.35", "size": "100"}, {"price": "0.45", "size": "50"}, {"price": "0.48", "size": "21.45"}, {"price": "0.55", "size": "56"}, {"price": "0.56", "size": "42"}, {"price": "0.57", "size": "20"}, {"price": "0.59", "size": "136.03"}, {"price": "0.6", "size": "35"}, {"price": "0.61", "size": "30"}], "asks": [{"price": "0.99", "size": "1131.5"}, {"price": "0.97", "size": "9.52"}, {"price": "0.94", "size": "100"}, {"price": "0.93", "size": "70"}, {"price": "0.92", "size": "8"}, {"price": "0.87", "size": "15"}, {"price": "0.85", "size": "7"}, {"price": "0.84", "size": "150"}, {"price": "0.74", "size": "12"}, {"price": "0.7", "size": "8.57"}, {"price": "0.69", "size": "100"}, {"price": "0.68", "size": "49.99"}, {"price": "0.66", "size": "6"}, {"price": "0.65", "size": "23.46"}, {"price": "0.64", "size": "11.73"}], "event_type": "book", "last_trade_price": "0.400"}, {"market": "0x07a77d4ac864ae8782c36437e175ea35a810775cac542978ed318b3421330bcd", "asset_id": "64719283305526429064975004309909261932559589141844838695019397557360982016594", "timestamp": "1769384470508", "hash": "179849d44a2234037a1de058fcdbf1cf2d5d6eb3", "bids": [{"price": "0.001", "size": "1163"}, {"price": "0.002", "size": "84.24"}, {"price": "0.01", "size": "1211.5"}, {"price": "0.02", "size": "116.18"}], "asks": [{"price": "0.999", "size": "2168.85"}, {"price": "0.998", "size": "26.01"}, {"price": "0.99", "size": "881.5"}, {"price": "0.989", "size": "5.13"}, {"price": "0.98", "size": "2000"}, {"price": "0.979", "size": "19.19"}, {"price": "0.95", "size": "100"}, {"price": "0.94", "size": "33"}, {"price": "0.92", "size": "30"}, {"price": "0.9", "size": "20"}, {"price": "0.899", "size": "14.67"}, {"price": "0.8", "size": "5"}, {"price": "0.16", "size": "9.9"}, {"price": "0.159", "size": "20"}, {"price": "0.08", "size": "58.75"}, {"price": "0.07", "size": "30"}, {"price": "0.06", "size": "40"}, {"price": "0.059", "size": "15"}, {"price": "0.05", "size": "130"}], "event_type": "book", "last_trade_price": "0.020"}, {"market": "0xf81a1470a1df60b339e19ef08f4f50f6b1e16b72abc5ada0abeba3176f6ebf39", "asset_id": "107613004969601337516553589346677804481909532422183375899340300747909195154490", "timestamp": "1769384460924", "hash": "f7db21e9962e153a5e123ea903227cf68ccfd0a4", "bids": [{"price": "0.001", "size": "7776.84"}, {"price": "0.002", "size": "1755.83"}, {"price": "0.003", "size": "1166"}, {"price": "0.004", "size": "10.09"}, {"price": "0.006", "size": "83"}, {"price": "0.01", "size": "2781.5"}, {"price": "0.011", "size": "5.14"}, {"price": "0.02", "size": "3400"}, {"price": "0.021", "size": "7.98"}, {"price": "0.05", "size": "100"}, {"price": "0.051", "size": "39"}, {"price": "0.06", "size": "200"}, {"price": "0.061", "size": "7.47"}, {"price": "0.11", "size": "125"}, {"price": "0.16", "size": "100"}, {"price": "0.161", "size": "7.84"}, {"price": "0.2", "size": "5"}, {"price": "0.21", "size": "50"}, {"price": "0.211", "size": "9"}, {"price": "0.5", "size": "13.08"}, {"price": "0.69", "size": "10"}, {"price": "0.723", "size": "8"}, {"price": "0.89", "size": "10"}, {"price": "0.891", "size": "20"}, {"price": "0.9", "size": "5"}, {"price": "0.923", "size": "93"}, {"price": "0.93", "size": "10"}, {"price": "0.94", "size": "60"}, {"price": "0.95", "size": "500"}, {"price": "0.951", "size": "50"}, {"price": "0.991", "size": "10"}, {"price": "0.992", "size": "28.17"}, {"price": "0.995", "size": "7"}, {"price": "0.996", "size": "10.5"}], "asks": [{"price": "0.999", "size": "10862.13"}], "event_type": "book", "last_trade_price": "0.001"}, {"market": "0x3cb3b76b6a4c3fdc6f933464859626df576eaf3e3e404ead3e75056fd48c04f5", "asset_id": "50224211346577003424157970845956631119711245094103571068877904015222053747922", "timestamp": "1769384484659", "hash": "bdee9c627884d29e435046039e8bd82e2960b900", "bids": [{"price": "0.01", "size": "2389.5"}, {"price": "0.02", "size": "1405"}, {"price": "0.03", "size": "14.52"}, {"price": "0.06", "size": "330"}, {"price": "0.07", "size": "15"}, {"price": "0.11", "size": "125"}, {"price": "0.14", "size": "15"}, {"price": "0.16", "size": "100"}, {"price": "0.17", "size": "10"}, {"price": "0.18", "size": "6"}, {"price": "0.2", "size": "5"}, {"price": "0.21", "size": "50"}, {"price": "0.24", "size": "32"}, {"price": "0.25", "size": "8"}, {"price": "0.42", "size": "10"}, {"price": "0.47", "size": "30"}, {"price": "0.5", "size": "90"}, {"price": "0.51", "size": "100"}, {"price": "0.53", "size": "53.92"}, {"price": "0.55", "size": "124.25"}, {"price": "0.56", "size": "29.62"}], "asks": [{"price": "0.99", "size": "2744.36"}, {"price": "0.98", "size": "3407.5"}, {"price": "0.97", "size": "66"}, {"price": "0.96", "size": "5.28"}, {"price": "0.95", "size": "20"}, {"price": "0.93", "size": "9.29"}, {"price": "0.9", "size": "10"}, {"price": "0.83", "size": "200"}, {"price": "0.82", "size": "15.09"}, {"price": "0.8", "size": "25"}, {"price": "0.68", "size": "61.54"}, {"price": "0.67", "size": "100"}, {"price": "0.66", "size": "20"}, {"price": "0.65", "size": "5"}, {"price": "0.63", "size": "16"}, {"price": "0.62", "size": "163.55"}, {"price": "0.61", "size": "30"}], "event_type": "book", "last_trade_price": "0.560"}, {"market": "0x75700f135fc1aa9106eecad102e82a5e304afa684948c453d9020973a6dacda6", "asset_id": "28461223070646267397095106287041417408320289813700921421278280340813748146076", "timestamp": "1769384484179", "hash": "60f5984c25b5b28326eb31136e470fe65626d82a", "bids": [{"price": "0.01", "size": "1131.5"}, {"price": "0.03", "size": "9.52"}, {"price": "0.06", "size": "100"}, {"price": "0.07", "size": "70"}, {"price": "0.08", "size": "8"}, {"price": "0.13", "size": "15"}, {"price": "0.15", "size": "7"}, {"price": "0.16", "size": "150"}, {"price": "0.26", "size": "12"}, {"price": "0.3", "size": "8.57"}, {"price": "0.31", "size": "100"}, {"price": "0.32", "size": "49.99"}, {"price": "0.34", "size": "6"}, {"price": "0.35", "size": "23.46"}, {"price": "0.36", "size": "11.73"}], "asks": [{"price": "0.99", "size": "2894.22"}, {"price": "0.98", "size": "1400"}, {"price": "0.97", "size": "7.71"}, {"price": "0.95", "size": "20"}, {"price": "0.94", "size": "200"}, {"price": "0.93", "size": "6.93"}, {"price": "0.9", "size": "10"}, {"price": "0.88", "size": "325"}, {"price": "0.84", "size": "100"}, {"price": "0.83", "size": "17.8"}, {"price": "0.75", "size": "100"}, {"price": "0.65", "size": "100"}, {"price": "0.55", "size": "50"}, {"price": "0.52", "size": "21.45"}, {"price": "0.45", "size": "56"}, {"price": "0.44", "size": "42"}, {"price": "0.43", "size": "20"}, {"price": "0.41", "size": "136.03"}, {"price": "0.4", "size": "35"}, {"price": "0.39", "size": "30"}], "event_type": "book", "last_trade_price": "0.400"}]}
{"_local_timestamp": "2026-01-25T23:41:25.726345+00:00", "data": {"market": "0x3cb3b76b6a4c3fdc6f933464859626df576eaf3e3e404ead3e75056fd48c04f5", "price_changes": [{"asset_id": "106006396008449636653509336329453630557359114983730727555924443870035053210127", "price": "0.38", "size": "63.55", "side": "BUY", "hash": "d7200b6bed9cd29f6e8d654021c1f4dd63f5817b", "best_bid": "0.39", "best_ask": "0.44"}, {"asset_id": "50224211346577003424157970845956631119711245094103571068877904015222053747922", "price": "0.62", "size": "63.55", "side": "SELL", "hash": "fea376fa1dbb7159bb67339de21f2a6f3ef9d8e0", "best_bid": "0.56", "best_ask": "0.61"}], "timestamp": "1769384485652", "event_type": "price_change"}}
{"_local_timestamp": "2026-01-25T23:41:25.731165+00:00", "data": {"market": "0x75700f135fc1aa9106eecad102e82a5e304afa684948c453d9020973a6dacda6", "price_changes": [{"asset_id": "106943703042015764099709708127099569908287532239730770276583638212344318814024", "price": "0.59", "size": "36.03", "side": "BUY", "hash": "004e8614f3209ac1e202b9ab8495ee686117b3e5", "best_bid": "0.61", "best_ask": "0.64"}, {"asset_id": "28461223070646267397095106287041417408320289813700921421278280340813748146076", "price": "0.41", "size": "36.03", "side": "SELL", "hash": "40aecdbee3d37acfbb714a54ec2eaf9dd752a3a1", "best_bid": "0.36", "best_ask": "0.39"}], "timestamp": "1769384485658", "event_type": "price_change"}}
{"_local_timestamp": "2026-01-25T23:41:26.063714+00:00", "data": {"market": "0x3cb3b76b6a4c3fdc6f933464859626df576eaf3e3e404ead3e75056fd48c04f5", "price_changes": [{"asset_id": "106006396008449636653509336329453630557359114983730727555924443870035053210127", "price": "0.38", "size": "33.55", "side": "BUY", "hash": "e66e5dda7f00cc036d4a63d1394eb1846c61e0be", "best_bid": "0.39", "best_ask": "0.44"}, {"asset_id": "50224211346577003424157970845956631119711245094103571068877904015222053747922", "price": "0.62", "size": "33.55", "side": "SELL", "hash": "c4bff2131173e1a67e26d5d71f482c594bc52461", "best_bid": "0.56", "best_ask": "0.61"}], "timestamp": "1769384485986", "event_type": "price_change"}}
{"_local_timestamp": "2026-01-25T23:41:26.142284+00:00", "data": {"market": "0x3cb3b76b6a4c3fdc6f933464859626df576eaf3e3e404ead3e75056fd48c04f5", "price_changes": [{"asset_id": "106006396008449636653509336329453630557359114983730727555924443870035053210127", "price": "0.33", "size": "130", "side": "BUY", "hash": "9b997e8791796e797726d2106036ecbed2e519b3", "best_bid": "0.39", "best_ask": "0.44"}, {"asset_id": "50224211346577003424157970845956631119711245094103571068877904015222053747922", "price": "0.67", "size": "130", "side": "SELL", "hash": "8f045253811e28295d6957fa559e052aabd53edf", "best_bid": "0.56", "best_ask": "0.61"}], "timestamp": "1769384486076", "event_type": "price_change"}}
{"_local_timestamp": "2026-01-25T23:41:26.422341+00:00", "data": {"market": "0x3cb3b76b6a4c3fdc6f933464859626df576eaf3e3e404ead3e75056fd48c04f5", "price_changes": [{"asset_id": "106006396008449636653509336329453630557359114983730727555924443870035053210127", "price": "0.34", "size": "120", "side": "BUY", "hash": "885d9eb6473b0d9ec747963421bb70c3b2c403e7", "best_bid": "0.39", "best_ask": "0.44"}, {"asset_id": "50224211346577003424157970845956631119711245094103571068877904015222053747922", "price": "0.66", "size": "120", "side": "SELL", "hash": "13ca65790fa6a721e632eb31e92cbd3f4889fdd2", "best_bid": "0.56", "best_ask": "0.61"}], "timestamp": "1769384486355", "event_type": "price_change"}}
{"_local_timestamp": "2026-01-25T23:41:26.439046+00:00", "data": {"market": "0x75700f135fc1aa9106eecad102e82a5e304afa684948c453d9020973a6dacda6", "price_changes": [{"asset_id": "106943703042015764099709708127099569908287532239730770276583638212344318814024", "price": "0.6", "size": "135", "side": "BUY", "hash": "c55023431443c748949304eb0231a5221d4cb799", "best_bid": "0.61", "best_ask": "0.64"}, {"asset_id": "28461223070646267397095106287041417408320289813700921421278280340813748146076", "price": "0.4", "size": "135", "side": "SELL", "hash": "3d10aeeab32b81ff018ff3ba6eb24ba87ee26024", "best_bid": "0.36", "best_ask": "0.39"}], "timestamp": "1769384486360", "event_type": "price_change"}}
{"_local_timestamp": "2026-01-25T23:41:26.589080+00:00", "data": {"market": "0x3cb3b76b6a4c3fdc6f933464859626df576eaf3e3e404ead3e75056fd48c04f5", "price_changes": [{"asset_id": "106006396008449636653509336329453630557359114983730727555924443870035053210127", "price": "0.34", "size": "100", "side": "BUY", "hash": "a1c7404419251970c895c6b768771503e6ff294f", "best_bid": "0.39", "best_ask": "0.44"}, {"asset_id": "50224211346577003424157970845956631119711245094103571068877904015222053747922", "price": "0.66", "size": "100", "side": "SELL", "hash": "9be7c10a1cbbfd41daaa3ae3b726420631dc38ca", "best_bid": "0.56", "best_ask": "0.61"}], "timestamp": "1769384486509", "event_type": "price_change"}}
{"_local_timestamp": "2026-01-25T23:41:26.612097+00:00", "data": {"market": "0x3cb3b76b6a4c3fdc6f933464859626df576eaf3e3e404ead3e75056fd48c04f5", "price_changes": [{"asset_id": "106006396008449636653509336329453630557359114983730727555924443870035053210127", "price": "0.35", "size": "25", "side": "BUY", "hash": "ae6c85bd0c179cb14604b75e6bf7225e2d21934f", "best_bid": "0.39", "best_ask": "0.44"}, {"asset_id": "50224211346577003424157970845956631119711245094103571068877904015222053747922", "price": "0.65", "size": "25", "side": "SELL", "hash": "0577ceb3904341b6c29d5817ffbcdfd65865e22a", "best_bid": "0.56", "best_ask": "0.61"}], "timestamp": "1769384486537", "event_type": "price_change"}}
{"_local_timestamp": "2026-01-25T23:41:28.962141+00:00", "data": {"market": "0x75700f135fc1aa9106eecad102e82a5e304afa684948c453d9020973a6dacda6", "price_changes": [{"asset_id": "106943703042015764099709708127099569908287532239730770276583638212344318814024", "price": "0.59", "size": "0", "side": "BUY", "hash": "761f95efabb29523e97ac35a161929fcc1ba570a", "best_bid": "0.61", "best_ask": "0.64"}, {"asset_id": "28461223070646267397095106287041417408320289813700921421278280340813748146076", "price": "0.41", "size": "0", "side": "SELL", "hash": "630c39177f23bcd592576225b3ae2695ca75618f", "best_bid": "0.36", "best_ask": "0.39"}], "timestamp": "1769384488896", "event_type": "price_change"}}
{"_local_timestamp": "2026-01-25T23:41:29.100546+00:00", "data": {"market": "0x3cb3b76b6a4c3fdc6f933464859626df576eaf3e3e404ead3e75056fd48c04f5", "price_changes": [{"asset_id": "106006396008449636653509336329453630557359114983730727555924443870035053210127", "price": "0.38", "size": "5.98", "side": "BUY", "hash": "2570b9b5f68dfe92a087f8cfa8fb741a7da06b47", "best_bid": "0.39", "best_ask": "0.44"}, {"asset_id": "50224211346577003424157970845956631119711245094103571068877904015222053747922", "price": "0.62", "size": "5.98", "side": "SELL", "hash": "5e33dc202a9ae8f742dc06426ccfc3ef644f856b", "best_bid": "0.56", "best_ask": "0.61"}], "timestamp": "1769384489009", "event_type": "price_change"}}
{"_local_timestamp": "2026-01-25T23:41:29.164426+00:00", "data": {"market": "0x3cb3b76b6a4c3fdc6f933464859626df576eaf3e3e404ead3e75056fd48c04f5", "price_changes": [{"asset_id": "106006396008449636653509336329453630557359114983730727555924443870035053210127", "price": "0.33", "size": "100", "side": "BUY", "hash": "a75a280b2ea502e93a43f8a6becfb5ba8b82ce9a", "best_bid": "0.39", "best_ask": "0.44"}, {"asset_id": "50224211346577003424157970845956631119711245094103571068877904015222053747922", "price": "0.67", "size": "100", "side": "SELL", "hash": "50c9b6f5b680427c36b49b9b8d2ee0501d6f02d6", "best_bid": "0.56", "best_ask": "0.61"}], "timestamp": "1769384489094", "event_type": "price_change"}}
{"_local_timestamp": "2026-01-25T23:41:29.238091+00:00", "data": {"market": "0x3cb3b76b6a4c3fdc6f933464859626df576eaf3e3e404ead3e75056fd48c04f5", "price_changes": [{"asset_id": "106006396008449636653509336329453630557359114983730727555924443870035053210127", "price": "0.34", "size": "130", "side": "BUY", "hash": "db3d677a782bb4babcd486da17ab59a46d427f3a", "best_bid": "0.39", "best_ask": "0.44"}, {"asset_id": "50224211346577003424157970845956631119711245094103571068877904015222053747922", "price": "0.66", "size": "130", "side": "SELL", "hash": "f52424ce1692d221f0de58ecc226547ce2d22b8b", "best_bid": "0.56", "best_ask": "0.61"}], "timestamp": "1769384489156", "event_type": "price_change"}}
{"_local_timestamp": "2026-01-25T23:41:29.874609+00:00", "data": {"market": "0x3cb3b76b6a4c3fdc6f933464859626df576eaf3e3e404ead3e75056fd48c04f5", "price_changes": [{"asset_id": "106006396008449636653509336329453630557359114983730727555924443870035053210127", "price": "0.35", "size": "55", "side": "BUY", "hash": "3971567becf582021cb85cdfc5d9a35560f0e16a", "best_bid": "0.39", "best_ask": "0.44"}, {"asset_id": "50224211346577003424157970845956631119711245094103571068877904015222053747922", "price": "0.65", "size": "55", "side": "SELL", "hash": "68d76b3e98f7f2c69fbca6ce2c52495125c413ea", "best_bid": "0.56", "best_ask": "0.61"}], "timestamp": "1769384489808", "event_type": "price_change"}}
{"_local_timestamp": "2026-01-25T23:41:29.948713+00:00", "data": {"market": "0x75700f135fc1aa9106eecad102e82a5e304afa684948c453d9020973a6dacda6", "price_changes": [{"asset_id": "106943703042015764099709708127099569908287532239730770276583638212344318814024", "price": "0.6", "size": "105", "side": "BUY", "hash": "9cf80e7acad4a181fdf18a5c53ad72be88fa0817", "best_bid": "0.61", "best_ask": "0.64"}, {"asset_id": "28461223070646267397095106287041417408320289813700921421278280340813748146076", "price": "0.4", "size": "105", "side": "SELL", "hash": "cddcadbf5db036050e3e463c196484e4b05cc40c", "best_bid": "0.36", "best_ask": "0.39"}], "timestamp": "1769384489876", "event_type": "price_change"}}
{"_local_timestamp": "2026-01-25T23:41:30.083691+00:00", "data": {"market": "0x75700f135fc1aa9106eecad102e82a5e304afa684948c453d9020973a6dacda6", "price_changes": [{"asset_id": "106943703042015764099709708127099569908287532239730770276583638212344318814024", "price": "0.57", "size": "50", "side": "BUY", "hash": "223a48f40eb6c9cfbd5c2b8e832ba70e146da5da", "best_bid": "0.61", "best_ask": "0.64"}, {"asset_id": "28461223070646267397095106287041417408320289813700921421278280340813748146076", "price": "0.43", "size": "50", "side": "SELL", "hash": "0a72cee85a09eed4c370932d4423ddbac9b3532d", "best_bid": "0.36", "best_ask": "0.39"}], "timestamp": "1769384490005", "event_type": "price_change"}}
{"_local_timestamp": "2026-01-25T23:41:30.179840+00:00", "data": {"market": "0x75700f135fc1aa9106eecad102e82a5e304afa684948c453d9020973a6dacda6", "price_changes": [{"asset_id": "106943703042015764099709708127099569908287532239730770276583638212344318814024", "price": "0.6", "size": "5", "side": "BUY", "hash": "fac85547324eac9c693a821376d814bc91335a43", "best_bid": "0.61", "best_ask": "0.64"}, {"asset_id": "28461223070646267397095106287041417408320289813700921421278280340813748146076", "price": "0.4", "size": "5", "side": "SELL", "hash": "e4d47a1492845fd1b474f2a32b5152f450063ffc", "best_bid": "0.36", "best_ask": "0.39"}], "timestamp": "1769384490107", "event_type": "price_change"}}
{"_local_timestamp": "2026-01-25T23:41:30.331157+00:00", "data": {"market": "0x3cb3b76b6a4c3fdc6f933464859626df576eaf3e3e404ead3e75056fd48c04f5", "price_changes": [{"asset_id": "106006396008449636653509336329453630557359114983730727555924443870035053210127", "price": "0.39", "size": "0", "side": "BUY", "hash": "c1ef988221351cd77f6a7bbc1328e60649f53881", "best_bid": "0.38", "best_ask": "0.44"}, {"asset_id": "50224211346577003424157970845956631119711245094103571068877904015222053747922", "price": "0.61", "size": "0", "side": "SELL", "hash": "5ae7284adac4540d08d1cc564cc804dc669f6ba2", "best_bid": "0.56", "best_ask": "0.62"}], "timestamp": "1769384490262", "event_type": "price_change"}}
{"_local_timestamp": "2026-01-25T23:41:30.338545+00:00", "data": {"market": "0x75700f135fc1aa9106eecad102e82a5e304afa684948c453d9020973a6dacda6", "price_changes": [{"asset_id": "106943703042015764099709708127099569908287532239730770276583638212344318814024", "price": "0.61", "size": "0", "side": "BUY", "hash": "fcb389b63387086d047a169eade151de96a49321", "best_bid": "0.6", "best_ask": "0.64"}, {"asset_id": "28461223070646267397095106287041417408320289813700921421278280340813748146076", "price": "0.39", "size": "0", "side": "SELL", "hash": "035bd79a49bdc00b3c48ef6b1d86926a6f8caa2e", "best_bid": "0.36", "best_ask": "0.4"}], "timestamp": "1769384490275", "event_type": "price_change"}}
{"_local_timestamp": "2026-01-25T23:41:30.368123+00:00", "data": {"market": "0x75700f135fc1aa9106eecad102e82a5e304afa684948c453d9020973a6dacda6", "price_changes": [{"asset_id": "28461223070646267397095106287041417408320289813700921421278280340813748146076", "price": "0.34", "size": "27", "side": "BUY", "hash": "d274db36906040d6c9408086d4d2cf79f97b8dcc", "best_bid": "0.36", "best_ask": "0.4"}, {"asset_id": "106943703042015764099709708127099569908287532239730770276583638212344318814024", "price": "0.66", "size": "27", "side": "SELL", "hash": "5b6a91ba4d9b486c69a17eca58926cfa04534411", "best_bid": "0.6", "best_ask": "0.64"}], "timestamp": "1769384490303", "event_type": "price_change"}}
{"_local_timestamp": "2026-01-25T23:41:30.375856+00:00", "data": {"market": "0x75700f135fc1aa9106eecad102e82a5e304afa684948c453d9020973a6dacda6", "price_changes": [{"asset_id": "106943703042015764099709708127099569908287532239730770276583638212344318814024", "price": "0.58", "size": "75", "side": "BUY", "hash": "5b92a6ffb9dbaed4fc440015fed8925c8c56e5de", "best_bid": "0.6", "best_ask": "0.64"}, {"asset_id": "28461223070646267397095106287041417408320289813700921421278280340813748146076", "price": "0.42", "size": "75", "side": "SELL", "hash": "3878d8f4e1a43411e0020b8745a6b0090afcfe70", "best_bid": "0.36", "best_ask": "0.4"}], "timestamp": "1769384490304", "event_type": "price_change"}}
{"_local_timestamp": "2026-01-25T23:41:30.575737+00:00", "data": {"market": "0x75700f135fc1aa9106eecad102e82a5e304afa684948c453d9020973a6dacda6", "price_changes": [{"asset_id": "106943703042015764099709708127099569908287532239730770276583638212344318814024", "price": "0.58", "size": "105", "side": "BUY", "hash": "77b363a0d4f418dfbd77dfe90aa64c5fd53c6abd", "best_bid": "0.6", "best_ask": "0.64"}, {"asset_id": "28461223070646267397095106287041417408320289813700921421278280340813748146076", "price": "0.42", "size": "105", "side": "SELL", "hash": "3e32e0b371afb069c8ee63124eb2d11ab2b74826", "best_bid": "0.36", "best_ask": "0.4"}], "timestamp": "1769384490509", "event_type": "price_change"}}
{"_local_timestamp": "2026-01-25T23:41:30.643774+00:00", "data": {"market": "0x3cb3b76b6a4c3fdc6f933464859626df576eaf3e3e404ead3e75056fd48c04f5", "price_changes": [{"asset_id": "106006396008449636653509336329453630557359114983730727555924443870035053210127", "price": "0.34", "size": "100", "side": "BUY", "hash": "df079450785cf8bcd1f14a467800c1e9185c023d", "best_bid": "0.38", "best_ask": "0.44"}, {"asset_id": "50224211346577003424157970845956631119711245094103571068877904015222053747922", "price": "0.66", "size": "100", "side": "SELL", "hash": "2ab87758131bbfc7f0d790750836479d68bad138", "best_bid": "0.56", "best_ask": "0.62"}], "timestamp": "1769384490574", "event_type": "price_change"}}
{"_local_timestamp": "2026-01-25T23:41:30.691517+00:00", "data": {"market": "0x3cb3b76b6a4c3fdc6f933464859626df576eaf3e3e404ead3e75056fd48c04f5", "price_changes": [{"asset_id": "106006396008449636653509336329453630557359114983730727555924443870035053210127", "price": "0.35", "size": "85", "side": "BUY", "hash": "a36884b91f188e158a2ab21c6d480fed4ef274cf", "best_bid": "0.38", "best_ask": "0.44"}, {"asset_id": "50224211346577003424157970845956631119711245094103571068877904015222053747922", "price": "0.65", "size": "85", "side": "SELL", "hash": "6f0499942fefdb65dc4711f7d347758632983183", "best_bid": "0.56", "best_ask": "0.62"}], "timestamp": "1769384490625", "event_type": "price_change"}}
{"_local_timestamp": "2026-01-25T23:41:30.768540+00:00", "data": {"market": "0x75700f135fc1aa9106eecad102e82a5e304afa684948c453d9020973a6dacda6", "price_changes": [{"asset_id": "106943703042015764099709708127099569908287532239730770276583638212344318814024", "price": "0.57", "size": "150", "side": "BUY", "hash": "5904567790b6b0798ce6c7858173ac34acf3603e", "best_bid": "0.6", "best_ask": "0.64"}, {"asset_id": "28461223070646267397095106287041417408320289813700921421278280340813748146076", "price": "0.43", "size": "150", "side": "SELL", "hash": "cf4e12f19e14c493a3f5a16f1f5c4d6e6a3facc5", "best_bid": "0.36", "best_ask": "0.4"}], "timestamp": "1769384490698", "event_type": "price_change"}}
{"_local_timestamp": "2026-01-25T23:41:31.364145+00:00", "data": {"market": "0x75700f135fc1aa9106eecad102e82a5e304afa684948c453d9020973a6dacda6", "price_changes": [{"asset_id": "106943703042015764099709708127099569908287532239730770276583638212344318814024", "price": "0.61", "size": "36.03", "side": "BUY", "hash": "94caf482bd35a7793f8aa82d18c191bd09172c63", "best_bid": "0.61", "best_ask": "0.64"}, {"asset_id": "28461223070646267397095106287041417408320289813700921421278280340813748146076", "price": "0.39", "size": "36.03", "side": "SELL", "hash": "9fe1041a923534391999ed1cdb00614285492928", "best_bid": "0.36", "best_ask": "0.39"}], "timestamp": "1769384491285", "event_type": "price_change"}}
{"_local_timestamp": "2026-01-25T23:41:31.427908+00:00", "data": {"market": "0x75700f135fc1aa9106eecad102e82a5e304afa684948c453d9020973a6dacda6", "price_changes": [{"asset_id": "106943703042015764099709708127099569908287532239730770276583638212344318814024", "price": "0.58", "size": "30", "side": "BUY", "hash": "51353e6470067bea4cf20aba007481465d71925f", "best_bid": "0.61", "best_ask": "0.64"}, {"asset_id": "28461223070646267397095106287041417408320289813700921421278280340813748146076", "price": "0.42", "size": "30", "side": "SELL", "hash": "f0729c892ac19fbc6e13a4a7feaffc981b027146", "best_bid": "0.36", "best_ask": "0.39"}], "timestamp": "1769384491360", "event_type": "price_change"}}
{"_local_timestamp": "2026-01-25T23:41:31.428425+00:00", "data": {"market": "0x75700f135fc1aa9106eecad102e82a5e304afa684948c453d9020973a6dacda6", "price_changes": [{"asset_id": "28461223070646267397095106287041417408320289813700921421278280340813748146076", "price": "0.34", "size": "6", "side": "BUY", "hash": "57b402cee16ec0d18c2972603a989604578d8a5d", "best_bid": "0.36", "best_ask": "0.39"}, {"asset_id": "106943703042015764099709708127099569908287532239730770276583638212344318814024", "price": "0.66", "size": "6", "side": "SELL", "hash": "4e07ebcc2d8ef04688b7031f0a4eb496d3974011", "best_bid": "0.61", "best_ask": "0.64"}], "timestamp": "1769384491360", "event_type": "price_change"}}
{"_local_timestamp": "2026-01-25T23:41:32.208181+00:00", "data": {"market": "0x3cb3b76b6a4c3fdc6f933464859626df576eaf3e3e404ead3e75056fd48c04f5", "price_changes": [{"asset_id": "106006396008449636653509336329453630557359114983730727555924443870035053210127", "price": "0.36", "size": "27.5", "side": "BUY", "hash": "6070736bc80873bacdcf9c60474c14c52a1a2362", "best_bid": "0.38", "best_ask": "0.44"}, {"asset_id": "50224211346577003424157970845956631119711245094103571068877904015222053747922", "price": "0.64", "size": "27.5", "side": "SELL", "hash": "7195cf2ee18ae7422be425848382a7129d8a0a70", "best_bid": "0.56", "best_ask": "0.62"}], "timestamp": "1769384492134", "event_type": "price_change"}}
{"_local_timestamp": "2026-01-25T23:41:34.508345+00:00", "data": {"market": "0x75700f135fc1aa9106eecad102e82a5e304afa684948c453d9020973a6dacda6", "price_changes": [{"asset_id": "106943703042015764099709708127099569908287532239730770276583638212344318814024", "price": "0.57", "size": "50", "side": "BUY", "hash": "45dc519b8cd9096a3a928f464991e411e7322d6d", "best_bid": "0.61", "best_ask": "0.64"}, {"asset_id": "28461223070646267397095106287041417408320289813700921421278280340813748146076", "price": "0.43", "size": "50", "side": "SELL", "hash": "5de8a0ff5aa83af94f507b8c9028e16f4026fe7a", "best_bid": "0.36", "best_ask": "0.39"}], "timestamp": "1769384494441", "event_type": "price_change"}}
{"_local_timestamp": "2026-01-25T23:41:34.515947+00:00", "data": {"market": "0x3cb3b76b6a4c3fdc6f933464859626df576eaf3e3e404ead3e75056fd48c04f5", "price_changes": [{"asset_id": "106006396008449636653509336329453630557359114983730727555924443870035053210127", "price": "0.34", "size": "0", "side": "BUY", "hash": "e39b68b5d00cb57f823ce40b013715b83395c81c", "best_bid": "0.38", "best_ask": "0.44"}, {"asset_id": "50224211346577003424157970845956631119711245094103571068877904015222053747922", "price": "0.66", "size": "0", "side": "SELL", "hash": "548c60b91ba45ac5d866a59cbd3c1879a5cf178a", "best_bid": "0.56", "best_ask": "0.62"}], "timestamp": "1769384494441", "event_type": "price_change"}}
{"_local_timestamp": "2026-01-25T23:41:35.069138+00:00", "data": {"market": "0x3cb3b76b6a4c3fdc6f933464859626df576eaf3e3e404ead3e75056fd48c04f5", "price_changes": [{"asset_id": "106006396008449636653509336329453630557359114983730727555924443870035053210127", "price": "0.36", "size": "127.5", "side": "BUY", "hash": "ac98181c61220bcf0202170ed37c69f080f6c5e8", "best_bid": "0.38", "best_ask": "0.44"}, {"asset_id": "50224211346577003424157970845956631119711245094103571068877904015222053747922", "price": "0.64", "size": "127.5", "side": "SELL", "hash": "224df5ace473fd37bdd8a192377f0be58089fda6", "best_bid": "0.56", "best_ask": "0.62"}], "timestamp": "1769384494994", "event_type": "price_change"}}
{"_local_timestamp": "2026-01-25T23:41:35.091765+00:00", "data": {"market": "0x75700f135fc1aa9106eecad102e82a5e304afa684948c453d9020973a6dacda6", "price_changes": [{"asset_id": "106943703042015764099709708127099569908287532239730770276583638212344318814024", "price": "0.58", "size": "130", "side": "BUY", "hash": "aa8c41f75e57252b3e9ea10a37c7d7513ca29250", "best_bid": "0.61", "best_ask": "0.64"}, {"asset_id": "28461223070646267397095106287041417408320289813700921421278280340813748146076", "price": "0.42", "size": "130", "side": "SELL", "hash": "b0fcd44d094502346df65af7e3c073c70e34179d", "best_bid": "0.36", "best_ask": "0.39"}], "timestamp": "1769384495000", "event_type": "price_change"}}
{"_local_timestamp": "2026-01-25T23:41:35.721834+00:00", "data": {"market": "0x3cb3b76b6a4c3fdc6f933464859626df576eaf3e3e404ead3e75056fd48c04f5", "price_changes": [{"asset_id": "106006396008449636653509336329453630557359114983730727555924443870035053210127", "price": "0.35", "size": "55", "side": "BUY", "hash": "20e4937b9ad533a5d94cf0224b86eea7136b6fb7", "best_bid": "0.38", "best_ask": "0.44"}, {"asset_id": "50224211346577003424157970845956631119711245094103571068877904015222053747922", "price": "0.65", "size": "55", "side": "SELL", "hash": "da71d38a06c09882d2e83df949622983a072c5bb", "best_bid": "0.56", "best_ask": "0.62"}], "timestamp": "1769384495649", "event_type": "price_change"}}
{"_local_timestamp": "2026-01-25T23:41:35.787474+00:00", "data": {"market": "0x3cb3b76b6a4c3fdc6f933464859626df576eaf3e3e404ead3e75056fd48c04f5", "price_changes": [{"asset_id": "106006396008449636653509336329453630557359114983730727555924443870035053210127", "price": "0.36", "size": "157.5", "side": "BUY", "hash": "22c4cb4f4a18a72845e7847a7c1f4f472062c9a8", "best_bid": "0.38", "best_ask": "0.44"}, {"asset_id": "50224211346577003424157970845956631119711245094103571068877904015222053747922", "price": "0.64", "size": "157.5", "side": "SELL", "hash": "5b33f636548f5cc50d9b8f677c89e217116f9240", "best_bid": "0.56", "best_ask": "0.62"}], "timestamp": "1769384495714", "event_type": "price_change"}}
{"_local_timestamp": "2026-01-25T23:41:36.021509+00:00", "data": {"market": "0x3cb3b76b6a4c3fdc6f933464859626df576eaf3e3e404ead3e75056fd48c04f5", "price_changes": [{"asset_id": "106006396008449636653509336329453630557359114983730727555924443870035053210127", "price": "0.37", "size": "46", "side": "BUY", "hash": "f406378db92616913ffd5d5c74244b957b386200", "best_bid": "0.38", "best_ask": "0.44"}, {"asset_id": "50224211346577003424157970845956631119711245094103571068877904015222053747922", "price": "0.63", "size": "46", "side": "SELL", "hash": "ade1018cbadc0a25f2f5cac0118e61fd8d2fc15e", "best_bid": "0.56", "best_ask": "0.62"}], "timestamp": "1769384495944", "event_type": "price_change"}}
{"_local_timestamp": "2026-01-25T23:41:36.334974+00:00", "data": {"market": "0x75700f135fc1aa9106eecad102e82a5e304afa684948c453d9020973a6dacda6", "price_changes": [{"asset_id": "106943703042015764099709708127099569908287532239730770276583638212344318814024", "price": "0.57", "size": "20", "side": "BUY", "hash": "45c70e8a5fb5ab236efacc8c21428036a108156f", "best_bid": "0.61", "best_ask": "0.64"}, {"asset_id": "28461223070646267397095106287041417408320289813700921421278280340813748146076", "price": "0.43", "size": "20", "side": "SELL", "hash": "8b110d6446aab51f879bb494e871a13e2c1f660b", "best_bid": "0.36", "best_ask": "0.39"}], "timestamp": "1769384496260", "event_type": "price_change"}}
{"_local_timestamp": "2026-01-25T23:41:36.335785+00:00", "data": {"market": "0x3cb3b76b6a4c3fdc6f933464859626df576eaf3e3e404ead3e75056fd48c04f5", "price_changes": [{"asset_id": "106006396008449636653509336329453630557359114983730727555924443870035053210127", "price": "0.35", "size": "25", "side": "BUY", "hash": "f82a0512a6163f80b889116f6cb7736cb79c1b23", "best_bid": "0.38", "best_ask": "0.44"}, {"asset_id": "50224211346577003424157970845956631119711245094103571068877904015222053747922", "price": "0.65", "size": "25", "side": "SELL", "hash": "d2335dcc0f20e3b4b282194eb21c65c5ea4adc3c", "best_bid": "0.56", "best_ask": "0.62"}], "timestamp": "1769384496265", "event_type": "price_change"}}
{"_local_timestamp": "2026-01-25T23:41:36.548705+00:00", "data": {"market": "0x3cb3b76b6a4c3fdc6f933464859626df576eaf3e3e404ead3e75056fd48c04f5", "price_changes": [{"asset_id": "106006396008449636653509336329453630557359114983730727555924443870035053210127", "price": "0.35", "size": "5", "side": "BUY", "hash": "4d65db9c22fc33650527d349f5b049bce33bc571", "best_bid": "0.38", "best_ask": "0.44"}, {"asset_id": "50224211346577003424157970845956631119711245094103571068877904015222053747922", "price": "0.65", "size": "5", "side": "SELL", "hash": "d42de6c1e160a6972a6c5765a1cbd0add2d79809", "best_bid": "0.56", "best_ask": "0.62"}], "timestamp": "1769384496484", "event_type": "price_change"}}
{"_local_timestamp": "2026-01-25T23:41:36.589525+00:00", "data": {"market": "0x3cb3b76b6a4c3fdc6f933464859626df576eaf3e3e404ead3e75056fd48c04f5", "price_changes": [{"asset_id": "106006396008449636653509336329453630557359114983730727555924443870035053210127", "price": "0.34", "size": "20", "side": "BUY", "hash": "7b8496e71a975fa3200ba40f6d1f7ac19bade912", "best_bid": "0.38", "best_ask": "0.44"}, {"asset_id": "50224211346577003424157970845956631119711245094103571068877904015222053747922", "price": "0.66", "size": "20", "side": "SELL", "hash": "853a6439762258b44eeb1b92a8c914a644da20a1", "best_bid": "0.56", "best_ask": "0.62"}], "timestamp": "1769384496517", "event_type": "price_change"}}
{"_local_timestamp": "2026-01-25T23:41:37.849838+00:00", "data": {"market": "0x75700f135fc1aa9106eecad102e82a5e304afa684948c453d9020973a6dacda6", "price_changes": [{"asset_id": "106943703042015764099709708127099569908287532239730770276583638212344318814024", "price": "0.61", "size": "0", "side": "BUY", "hash": "4cf03ea7d2ec0b1c6a17b859507e6bbcc47d2979", "best_bid": "0.6", "best_ask": "0.64"}, {"asset_id": "28461223070646267397095106287041417408320289813700921421278280340813748146076", "price": "0.39", "size": "0", "side": "SELL", "hash": "2cd1819267ffd50bee379e2cf1c6e54e4210d281", "best_bid": "0.36", "best_ask": "0.4"}], "timestamp": "1769384497775", "event_type": "price_change"}}
{"_local_timestamp": "2026-01-25T23:41:37.869986+00:00", "data": {"market": "0x75700f135fc1aa9106eecad102e82a5e304afa684948c453d9020973a6dacda6", "price_changes": [{"asset_id": "106943703042015764099709708127099569908287532239730770276583638212344318814024", "price": "0.6", "size": "78", "side": "BUY", "hash": "7e5e82b612f810c80f1edfec7298ff77934e6cef", "best_bid": "0.6", "best_ask": "0.64"}, {"asset_id": "28461223070646267397095106287041417408320289813700921421278280340813748146076", "price": "0.4", "size": "78", "side": "SELL", "hash": "53277f5e1398c0920e904d7498365f887c872d92", "best_bid": "0.36", "best_ask": "0.4"}], "timestamp": "1769384497805", "event_type": "price_change"}}
{"_local_timestamp": "2026-01-25T23:41:38.452033+00:00", "data": {"market": "0x75700f135fc1aa9106eecad102e82a5e304afa684948c453d9020973a6dacda6", "price_changes": [{"asset_id": "106943703042015764099709708127099569908287532239730770276583638212344318814024", "price": "0.58", "size": "100", "side": "BUY", "hash": "05a63d26197b32bd6833ca0b5915fcd5b460dc2c", "best_bid": "0.6", "best_ask": "0.64"}, {"asset_id": "28461223070646267397095106287041417408320289813700921421278280340813748146076", "price": "0.42", "size": "100", "side": "SELL", "hash": "6fd75cff67c6aa598780a18b2a6e1cd3c102548f", "best_bid": "0.36", "best_ask": "0.4"}], "timestamp": "1769384498364", "event_type": "price_change"}}
{"_local_timestamp": "2026-01-25T23:41:38.498698+00:00", "data": {"market": "0x75700f135fc1aa9106eecad102e82a5e304afa684948c453d9020973a6dacda6", "price_changes": [{"asset_id": "106943703042015764099709708127099569908287532239730770276583638212344318814024", "price": "0.6", "size": "108", "side": "BUY", "hash": "c5329d1e0096bfd28e09486b4dfac10d21e9cafb", "best_bid": "0.6", "best_ask": "0.64"}, {"asset_id": "28461223070646267397095106287041417408320289813700921421278280340813748146076", "price": "0.4", "size": "108", "side": "SELL", "hash": "f9491b5307c78244b3209db2bb4f5293e011ca85", "best_bid": "0.36", "best_ask": "0.4"}], "timestamp": "1769384498428", "event_type": "price_change"}}
{"_local_timestamp": "2026-01-25T23:41:38.599024+00:00", "data": {"market": "0x75700f135fc1aa9106eecad102e82a5e304afa684948c453d9020973a6dacda6", "price_changes": [{"asset_id": "106943703042015764099709708127099569908287532239730770276583638212344318814024", "price": "0.59", "size": "14.43", "side": "BUY", "hash": "a81662afb6c67204884c4e3059542fb2ef5aeecd", "best_bid": "0.6", "best_ask": "0.64"}, {"asset_id": "28461223070646267397095106287041417408320289813700921421278280340813748146076", "price": "0.41", "size": "14.43", "side": "SELL", "hash": "fd947f68cb19063d4cb665f8ccc0da3b1d79c301", "best_bid": "0.36", "best_ask": "0.4"}], "timestamp": "1769384498526", "event_type": "price_change"}}
{"_local_timestamp": "2026-01-25T23:41:38.870565+00:00", "data": {"market": "0x75700f135fc1aa9106eecad102e82a5e304afa684948c453d9020973a6dacda6", "price_changes": [{"asset_id": "106943703042015764099709708127099569908287532239730770276583638212344318814024", "price": "0.58", "size": "0", "side": "BUY", "hash": "379a6a3d9c544c784728cdaebbf484b90b12bd32", "best_bid": "0.6", "best_ask": "0.64"}, {"asset_id": "28461223070646267397095106287041417408320289813700921421278280340813748146076", "price": "0.42", "size": "0", "side": "SELL", "hash": "526d46af3f078dc49b1e62b6dd6ff0869262c4f4", "best_bid": "0.36", "best_ask": "0.4"}], "timestamp": "1769384498791", "event_type": "price_change"}}
{"_local_timestamp": "2026-01-25T23:41:38.870973+00:00", "data": {"market": "0x3cb3b76b6a4c3fdc6f933464859626df576eaf3e3e404ead3e75056fd48c04f5", "price_changes": [{"asset_id": "106006396008449636653509336329453630557359114983730727555924443870035053210127", "price": "0.36", "size": "57.5", "side": "BUY", "hash": "de8781188e02773ff3005a160b93805659305e3a", "best_bid": "0.38", "best_ask": "0.44"}, {"asset_id": "50224211346577003424157970845956631119711245094103571068877904015222053747922", "price": "0.64", "size": "57.5", "side": "SELL", "hash": "276545e72775dbe8506a6a5302ebed1596576ff2", "best_bid": "0.56", "best_ask": "0.62"}], "timestamp": "1769384498791", "event_type": "price_change"}}
{"_local_timestamp": "2026-01-25T23:41:39.138209+00:00", "data": {"market": "0x3cb3b76b6a4c3fdc6f933464859626df576eaf3e3e404ead3e75056fd48c04f5", "price_changes": [{"asset_id": "106006396008449636653509336329453630557359114983730727555924443870035053210127", "price": "0.36", "size": "27.5", "side": "BUY", "hash": "cc492d8dbf6772cf175a3db1898a1fc5cb4cee97", "best_bid": "0.38", "best_ask": "0.44"}, {"asset_id": "50224211346577003424157970845956631119711245094103571068877904015222053747922", "price": "0.64", "size": "27.5", "side": "SELL", "hash": "7ff78217f50efcd72e47ca754fdfae306d57ca6f", "best_bid": "0.56", "best_ask": "0.62"}], "timestamp": "1769384499064", "event_type": "price_change"}}
{"_local_timestamp": "2026-01-25T23:41:39.198814+00:00", "data": {"market": "0x3cb3b76b6a4c3fdc6f933464859626df576eaf3e3e404ead3e75056fd48c04f5", "price_changes": [{"asset_id": "106006396008449636653509336329453630557359114983730727555924443870035053210127", "price": "0.33", "size": "130", "side": "BUY", "hash": "e8e41ab1739d494b01b86e6ba97c41d36c0497dc", "best_bid": "0.38", "best_ask": "0.44"}, {"asset_id": "50224211346577003424157970845956631119711245094103571068877904015222053747922", "price": "0.67", "size": "130", "side": "SELL", "hash": "e4f6ec3699c686e5dc3d8c120f5db8361ba096ce", "best_bid": "0.56", "best_ask": "0.62"}], "timestamp": "1769384499128", "event_type": "price_change"}}
{"_local_timestamp": "2026-01-25T23:41:39.587985+00:00", "data": {"market": "0x3cb3b76b6a4c3fdc6f933464859626df576eaf3e3e404ead3e75056fd48c04f5", "price_changes": [{"asset_id": "106006396008449636653509336329453630557359114983730727555924443870035053210127", "price": "0.38", "size": "105.98", "side": "BUY", "hash": "5d62b388dd37845b19306e438f921cad8cb4f17a", "best_bid": "0.38", "best_ask": "0.44"}, {"asset_id": "50224211346577003424157970845956631119711245094103571068877904015222053747922", "price": "0.62", "size": "105.98", "side": "SELL", "hash": "adcb1e6003ec1265af944b7ebd8e24ca55a06b24", "best_bid": "0.56", "best_ask": "0.62"}], "timestamp": "1769384499500", "event_type": "price_change"}}
{"_local_timestamp": "2026-01-25T23:41:39.594659+00:00", "data": {"market": "0x75700f135fc1aa9106eecad102e82a5e304afa684948c453d9020973a6dacda6", "price_changes": [{"asset_id": "106943703042015764099709708127099569908287532239730770276583638212344318814024", "price": "0.57", "size": "120", "side": "BUY", "hash": "199f13c4acdc62f1c11a76545aeb04b564d8336f", "best_bid": "0.6", "best_ask": "0.64"}, {"asset_id": "28461223070646267397095106287041417408320289813700921421278280340813748146076", "price": "0.43", "size": "120", "side": "SELL", "hash": "4f0a39b769f3197b7b6236ea30ca62a9035413a8", "best_bid": "0.36", "best_ask": "0.4"}], "timestamp": "1769384499500", "event_type": "price_change"}}
{"_local_timestamp": "2026-01-25T23:41:40.553929+00:00", "data": {"market": "0x3cb3b76b6a4c3fdc6f933464859626df576eaf3e3e404ead3e75056fd48c04f5", "price_changes": [{"asset_id": "106006396008449636653509336329453630557359114983730727555924443870035053210127", "price": "0.33", "size": "100", "side": "BUY", "hash": "c3e61c27ef95b3671a7c684daa7e202bd77fd5e4", "best_bid": "0.38", "best_ask": "0.44"}, {"asset_id": "50224211346577003424157970845956631119711245094103571068877904015222053747922", "price": "0.67", "size": "100", "side": "SELL", "hash": "eca30193f0cc97baa8786186a21683d80676f80c", "best_bid": "0.56", "best_ask": "0.62"}], "timestamp": "1769384500487", "event_type": "price_change"}}
{"_local_timestamp": "2026-01-25T23:41:40.616447+00:00", "data": {"market": "0x3cb3b76b6a4c3fdc6f933464859626df576eaf3e3e404ead3e75056fd48c04f5", "price_changes": [{"asset_id": "106006396008449636653509336329453630557359114983730727555924443870035053210127", "price": "0.38", "size": "135.98", "side": "BUY", "hash": "739cc065a449d4a0fc0642da7badb31604ce8dce", "best_bid": "0.38", "best_ask": "0.44"}, {"asset_id": "50224211346577003424157970845956631119711245094103571068877904015222053747922", "price": "0.62", "size": "135.98", "side": "SELL", "hash": "b11df57db4ebd4addeae37d5ab37aa3da2705f1f", "best_bid": "0.56", "best_ask": "0.62"}], "timestamp": "1769384500554", "event_type": "price_change"}}
{"_local_timestamp": "2026-01-25T23:41:42.118173+00:00", "data": {"market": "0x75700f135fc1aa9106eecad102e82a5e304afa684948c453d9020973a6dacda6", "price_changes": [{"asset_id": "106943703042015764099709708127099569908287532239730770276583638212344318814024", "price": "0.61", "size": "30", "side": "BUY", "hash": "2edc6e97e19c49a977c9e7b9d325aaf11890c393", "best_bid": "0.61", "best_ask": "0.64"}, {"asset_id": "28461223070646267397095106287041417408320289813700921421278280340813748146076", "price": "0.39", "size": "30", "side": "SELL", "hash": "730f00a7d544b58461405d32a3b0d27a6d28822c", "best_bid": "0.36", "best_ask": "0.39"}], "timestamp": "1769384502048", "event_type": "price_change"}}
{"_local_timestamp": "2026-01-25T23:41:42.121888+00:00", "data": {"market": "0x3cb3b76b6a4c3fdc6f933464859626df576eaf3e3e404ead3e75056fd48c04f5", "price_changes": [{"asset_id": "106006396008449636653509336329453630557359114983730727555924443870035053210127", "price": "0.39", "size": "30", "side": "BUY", "hash": "cadcfc6b245ab0a4bce178444ef48fba8ddf5faa", "best_bid": "0.39", "best_ask": "0.44"}, {"asset_id": "50224211346577003424157970845956631119711245094103571068877904015222053747922", "price": "0.61", "size": "30", "side": "SELL", "hash": "b3f83ef64e711a6b8440b8f248b795e916d0acfb", "best_bid": "0.56", "best_ask": "0.61"}], "timestamp": "1769384502048", "event_type": "price_change"}}
{"_local_timestamp": "2026-01-25T23:41:42.145478+00:00", "data": {"market": "0x75700f135fc1aa9106eecad102e82a5e304afa684948c453d9020973a6dacda6", "price_changes": [{"asset_id": "106943703042015764099709708127099569908287532239730770276583638212344318814024", "price": "0.6", "size": "35", "side": "BUY", "hash": "8f0a2b11e973a5f2cf5be05e356e3599b7162bcc", "best_bid": "0.61", "best_ask": "0.64"}, {"asset_id": "28461223070646267397095106287041417408320289813700921421278280340813748146076", "price": "0.4", "size": "35", "side": "SELL", "hash": "84547f07af140e62edba059da5a7afc15551f73c", "best_bid": "0.36", "best_ask": "0.39"}], "timestamp": "1769384502080", "event_type": "price_change"}}
{"_local_timestamp": "2026-01-25T23:41:42.160799+00:00", "data": {"market": "0x3cb3b76b6a4c3fdc6f933464859626df576eaf3e3e404ead3e75056fd48c04f5", "price_changes": [{"asset_id": "106006396008449636653509336329453630557359114983730727555924443870035053210127", "price": "0.36", "size": "0", "side": "BUY", "hash": "2255dc2646f850915027e650a14a402e4cd2c3f0", "best_bid": "0.39", "best_ask": "0.44"}, {"asset_id": "50224211346577003424157970845956631119711245094103571068877904015222053747922", "price": "0.64", "size": "0", "side": "SELL", "hash": "c62a3e76eb25ce0255b5dca8c016501e99e373cd", "best_bid": "0.56", "best_ask": "0.61"}], "timestamp": "1769384502094", "event_type": "price_change"}}
{"_local_timestamp": "2026-01-25T23:41:42.447254+00:00", "data": {"market": "0x3cb3b76b6a4c3fdc6f933464859626df576eaf3e3e404ead3e75056fd48c04f5", "price_changes": [{"asset_id": "106006396008449636653509336329453630557359114983730727555924443870035053210127", "price": "0.37", "size": "16", "side": "BUY", "hash": "01d3383710f0944c19318ba4f1b7b311461c1bff", "best_bid": "0.39", "best_ask": "0.44"}, {"asset_id": "50224211346577003424157970845956631119711245094103571068877904015222053747922", "price": "0.63", "size": "16", "side": "SELL", "hash": "b6e6331d3616dc7230d5b0eae42d38322c66e7b5", "best_bid": "0.56", "best_ask": "0.61"}], "timestamp": "1769384502374", "event_type": "price_change"}}
{"_local_timestamp": "2026-01-25T23:41:42.749076+00:00", "data": {"market": "0x75700f135fc1aa9106eecad102e82a5e304afa684948c453d9020973a6dacda6", "price_changes": [{"asset_id": "106943703042015764099709708127099569908287532239730770276583638212344318814024", "price": "0.6", "size": "5", "side": "BUY", "hash": "75cc0ac4f9f9d2746adaee58b52a7748bd49ffbe", "best_bid": "0.61", "best_ask": "0.64"}, {"asset_id": "28461223070646267397095106287041417408320289813700921421278280340813748146076", "price": "0.4", "size": "5", "side": "SELL", "hash": "0aede4c09d32dd2f2969fc35d54b63fb55887e52", "best_bid": "0.36", "best_ask": "0.39"}], "timestamp": "1769384502674", "event_type": "price_change"}}
{"_local_timestamp": "2026-01-25T23:41:42.798553+00:00", "data": {"market": "0x75700f135fc1aa9106eecad102e82a5e304afa684948c453d9020973a6dacda6", "price_changes": [{"asset_id": "106943703042015764099709708127099569908287532239730770276583638212344318814024", "price": "0.57", "size": "150", "side": "BUY", "hash": "cc1628188f2443b0c0b5907455f67f8f7e2aef52", "best_bid": "0.61", "best_ask": "0.64"}, {"asset_id": "28461223070646267397095106287041417408320289813700921421278280340813748146076", "price": "0.43", "size": "150", "side": "SELL", "hash": "dd0c64ff93599dc8189b362d8f8dd15e146bf0c6", "best_bid": "0.36", "best_ask": "0.39"}], "timestamp": "1769384502732", "event_type": "price_change"}}
{"_local_timestamp": "2026-01-25T23:41:42.902082+00:00", "data": {"market": "0x3cb3b76b6a4c3fdc6f933464859626df576eaf3e3e404ead3e75056fd48c04f5", "price_changes": [{"asset_id": "106006396008449636653509336329453630557359114983730727555924443870035053210127", "price": "0.38", "size": "148.55", "side": "BUY", "hash": "5a183289e4a9c2d725d0ca443687163fbeb481fb", "best_bid": "0.39", "best_ask": "0.44"}, {"asset_id": "50224211346577003424157970845956631119711245094103571068877904015222053747922", "price": "0.62", "size": "148.55", "side": "SELL", "hash": "4b47ae9f04faff8d9f554ea6ea5384f30a3cc711", "best_bid": "0.56", "best_ask": "0.61"}], "timestamp": "1769384502838", "event_type": "price_change"}}
{"_local_timestamp": "2026-01-25T23:41:43.326187+00:00", "data": {"market": "0x75700f135fc1aa9106eecad102e82a5e304afa684948c453d9020973a6dacda6", "price_changes": [{"asset_id": "106943703042015764099709708127099569908287532239730770276583638212344318814024", "price": "0.57", "size": "50", "side": "BUY", "hash": "ac999e863ef4b515ef730008b5f0ebcc0f7c41ac", "best_bid": "0.61", "best_ask": "0.64"}, {"asset_id": "28461223070646267397095106287041417408320289813700921421278280340813748146076", "price": "0.43", "size": "50", "side": "SELL", "hash": "047647215fe8462d589a3c4336aaf4efc5d491a7", "best_bid": "0.36", "best_ask": "0.39"}], "timestamp": "1769384503241", "event_type": "price_change"}}
{"_local_timestamp": "2026-01-25T23:41:43.326677+00:00", "data": {"market": "0x3cb3b76b6a4c3fdc6f933464859626df576eaf3e3e404ead3e75056fd48c04f5", "price_changes": [{"asset_id": "106006396008449636653509336329453630557359114983730727555924443870035053210127", "price": "0.38", "size": "48.55", "side": "BUY", "hash": "157ec4808c04ee0870fdc294a55fe9a967e14da7", "best_bid": "0.39", "best_ask": "0.44"}, {"asset_id": "50224211346577003424157970845956631119711245094103571068877904015222053747922", "price": "0.62", "size": "48.55", "side": "SELL", "hash": "0db6a19c66e8c448b3678b8c8a4f26dae346fe74", "best_bid": "0.56", "best_ask": "0.61"}], "timestamp": "1769384503245", "event_type": "price_change"}}
{"_local_timestamp": "2026-01-25T23:41:43.722731+00:00", "data": {"market": "0x75700f135fc1aa9106eecad102e82a5e304afa684948c453d9020973a6dacda6", "price_changes": [{"asset_id": "106943703042015764099709708127099569908287532239730770276583638212344318814024", "price": "0.57", "size": "20", "side": "BUY", "hash": "5803cbb014e2c24ffb0ae56fae425445e43fa092", "best_bid": "0.61", "best_ask": "0.64"}, {"asset_id": "28461223070646267397095106287041417408320289813700921421278280340813748146076", "price": "0.43", "size": "20", "side": "SELL", "hash": "cc09dcecbbeb277d7c4011305388c316d5b974d9", "best_bid": "0.36", "best_ask": "0.39"}], "timestamp": "1769384503657", "event_type": "price_change"}}
{"_local_timestamp": "2026-01-25T23:41:43.782546+00:00", "data": {"market": "0x75700f135fc1aa9106eecad102e82a5e304afa684948c453d9020973a6dacda6", "price_changes": [{"asset_id": "106943703042015764099709708127099569908287532239730770276583638212344318814024", "price": "0.55", "size": "86", "side": "BUY", "hash": "8005246ba7e4dcc8abb074f7c87924ff0328c6e1", "best_bid": "0.61", "best_ask": "0.64"}, {"asset_id": "28461223070646267397095106287041417408320289813700921421278280340813748146076", "price": "0.45", "size": "86", "side": "SELL", "hash": "2a1d5af61f922bf0e0b81e8a43c7486089b9eae8", "best_bid": "0.36", "best_ask": "0.39"}], "timestamp": "1769384503712", "event_type": "price_change"}}
{"_local_timestamp": "2026-01-25T23:41:44.038552+00:00", "data": {"market": "0x75700f135fc1aa9106eecad102e82a5e304afa684948c453d9020973a6dacda6", "price_changes": [{"asset_id": "106943703042015764099709708127099569908287532239730770276583638212344318814024", "price": "0.58", "size": "100", "side": "BUY", "hash": "138c60e5267fc9a31075d69a2b1983b0f770bcd3", "best_bid": "0.61", "best_ask": "0.64"}, {"asset_id": "28461223070646267397095106287041417408320289813700921421278280340813748146076", "price": "0.42", "size": "100", "side": "SELL", "hash": "17a84cc45988e8eb8c56296ed92ab6288a74f365", "best_bid": "0.36", "best_ask": "0.39"}], "timestamp": "1769384503971", "event_type": "price_change"}}
{"_local_timestamp": "2026-01-25T23:41:44.046615+00:00", "data": {"market": "0x3cb3b76b6a4c3fdc6f933464859626df576eaf3e3e404ead3e75056fd48c04f5", "price_changes": [{"asset_id": "106006396008449636653509336329453630557359114983730727555924443870035053210127", "price": "0.34", "size": "120", "side": "BUY", "hash": "bdcd5733413c7df42326a7cb01fda6cb909f7d19", "best_bid": "0.39", "best_ask": "0.44"}, {"asset_id": "50224211346577003424157970845956631119711245094103571068877904015222053747922", "price": "0.66", "size": "120", "side": "SELL", "hash": "f1ba8c732e338ac724b6a7e4a977f5f95db88d65", "best_bid": "0.56", "best_ask": "0.61"}], "timestamp": "1769384503973", "event_type": "price_change"}}
{"_local_timestamp": "2026-01-25T23:41:44.394908+00:00", "data": {"market": "0x3cb3b76b6a4c3fdc6f933464859626df576eaf3e3e404ead3e75056fd48c04f5", "price_changes": [{"asset_id": "106006396008449636653509336329453630557359114983730727555924443870035053210127", "price": "0.38", "size": "18.55", "side": "BUY", "hash": "a48de2f2a4c3435cab957b12a01012826677efd9", "best_bid": "0.39", "best_ask": "0.44"}, {"asset_id": "50224211346577003424157970845956631119711245094103571068877904015222053747922", "price": "0.62", "size": "18.55", "side": "SELL", "hash": "01fbbeaaa78a3f4f0b7357090e5a9e15b994b45a", "best_bid": "0.56", "best_ask": "0.61"}], "timestamp": "1769384504329", "event_type": "price_change"}}
{"_local_timestamp": "2026-01-25T23:41:44.643479+00:00", "data": {"market": "0x3cb3b76b6a4c3fdc6f933464859626df576eaf3e3e404ead3e75056fd48c04f5", "price_changes": [{"asset_id": "106006396008449636653509336329453630557359114983730727555924443870035053210127", "price": "0.34", "size": "100", "side": "BUY", "hash": "b07fac0eefd0f05f7425d3c22716a2af6f08397b", "best_bid": "0.39", "best_ask": "0.44"}, {"asset_id": "50224211346577003424157970845956631119711245094103571068877904015222053747922", "price": "0.66", "size": "100", "side": "SELL", "hash": "e6e54e01d3192ae5a60a29e0b91d0819fee51ecc", "best_bid": "0.56", "best_ask": "0.61"}], "timestamp": "1769384504573", "event_type": "price_change"}}
{"_local_timestamp": "2026-01-25T23:41:44.681469+00:00", "data": {"market": "0x3cb3b76b6a4c3fdc6f933464859626df576eaf3e3e404ead3e75056fd48c04f5", "price_changes": [{"asset_id": "106006396008449636653509336329453630557359114983730727555924443870035053210127", "price": "0.35", "size": "25", "side": "BUY", "hash": "853c235bc614d8427032bcab546eeeaeb8d939d8", "best_bid": "0.39", "best_ask": "0.44"}, {"asset_id": "50224211346577003424157970845956631119711245094103571068877904015222053747922", "price": "0.65", "size": "25", "side": "SELL", "hash": "61c3e8545d20f00eda93ae7b318d2e4a06170fce", "best_bid": "0.56", "best_ask": "0.61"}], "timestamp": "1769384504602", "event_type": "price_change"}}
{"_local_timestamp": "2026-01-25T23:41:44.759780+00:00", "data": {"market": "0x3cb3b76b6a4c3fdc6f933464859626df576eaf3e3e404ead3e75056fd48c04f5", "price_changes": [{"asset_id": "106006396008449636653509336329453630557359114983730727555924443870035053210127", "price": "0.34", "size": "130", "side": "BUY", "hash": "29e7a657fa2ad4b45688e7288ed244f79b7604e5", "best_bid": "0.39", "best_ask": "0.44"}, {"asset_id": "50224211346577003424157970845956631119711245094103571068877904015222053747922", "price": "0.66", "size": "130", "side": "SELL", "hash": "84e40134906c323eb4b50cb71b85ba8e2967b032", "best_bid": "0.56", "best_ask": "0.61"}], "timestamp": "1769384504690", "event_type": "price_change"}}
{"_local_timestamp": "2026-01-25T23:41:45.246695+00:00", "data": {"market": "0x75700f135fc1aa9106eecad102e82a5e304afa684948c453d9020973a6dacda6", "price_changes": [{"asset_id": "106943703042015764099709708127099569908287532239730770276583638212344318814024", "price": "0.55", "size": "56", "side": "BUY", "hash": "432844596161655092cb0437087022c36ce30592", "best_bid": "0.61", "best_ask": "0.64"}, {"asset_id": "28461223070646267397095106287041417408320289813700921421278280340813748146076", "price": "0.45", "size": "56", "side": "SELL", "hash": "446cf8e08071a2316646a8f03920238acb771e07", "best_bid": "0.36", "best_ask": "0.39"}], "timestamp": "1769384505179", "event_type": "price_change"}}
{"_local_timestamp": "2026-01-25T23:41:45.256157+00:00", "data": {"market": "0x8b9ba80fb00ffd3ea3d259e0e3d64c2bc057e2d258dbb416138082721491de1f", "price_changes": [{"asset_id": "95471394592044775311259204363647835057798671562193368798960379123943071173821", "price": "0.072", "size": "5.79", "side": "SELL", "hash": "efa8d9aa7b27e456661aaed038adb508771ce2b2", "best_bid": "0.022", "best_ask": "0.072"}, {"asset_id": "58714825001137751155185117146321345902961648511702872797387135565669201406384", "price": "0.928", "size": "5.79", "side": "BUY", "hash": "97f9237212ff42a6af6c53392759d8f278e591d8", "best_bid": "0.928", "best_ask": "0.978"}], "timestamp": "1769384505188", "event_type": "price_change"}}
{"_local_timestamp": "2026-01-25T23:41:45.326968+00:00", "data": {"market": "0x75700f135fc1aa9106eecad102e82a5e304afa684948c453d9020973a6dacda6", "price_changes": [{"asset_id": "106943703042015764099709708127099569908287532239730770276583638212344318814024", "price": "0.58", "size": "130", "side": "BUY", "hash": "e4e9a0f11eacbedd81888b034d03372f25d34679", "best_bid": "0.61", "best_ask": "0.64"}, {"asset_id": "28461223070646267397095106287041417408320289813700921421278280340813748146076", "price": "0.42", "size": "130", "side": "SELL", "hash": "ec5a7b8c364cd4c08702d72ecc534d10dadeff9e", "best_bid": "0.36", "best_ask": "0.39"}], "timestamp": "1769384505252", "event_type": "price_change"}}
{"_local_timestamp": "2026-01-25T23:41:46.015341+00:00", "data": {"market": "0x3cb3b76b6a4c3fdc6f933464859626df576eaf3e3e404ead3e75056fd48c04f5", "price_changes": [{"asset_id": "106006396008449636653509336329453630557359114983730727555924443870035053210127", "price": "0.47", "size": "0", "side": "SELL", "hash": "e2a15aca4adacc03039bb0a3a4c763467cf17556", "best_bid": "0.39", "best_ask": "0.44"}, {"asset_id": "50224211346577003424157970845956631119711245094103571068877904015222053747922", "price": "0.53", "size": "0", "side": "BUY", "hash": "041877340c01b3b7a555163d99fb35687a6e6e79", "best_bid": "0.56", "best_ask": "0.61"}], "timestamp": "1769384505942", "event_type": "price_change"}}
{"_local_timestamp": "2026-01-25T23:41:46.032502+00:00", "data": {"market": "0x3cb3b76b6a4c3fdc6f933464859626df576eaf3e3e404ead3e75056fd48c04f5", "price_changes": [{"asset_id": "106006396008449636653509336329453630557359114983730727555924443870035053210127", "price": "0.37", "size": "69", "side": "BUY", "hash": "c9f8cf8cf15c623fcb0cd76dbd31d3a3929e5dac", "best_bid": "0.39", "best_ask": "0.44"}, {"asset_id": "50224211346577003424157970845956631119711245094103571068877904015222053747922", "price": "0.63", "size": "69", "side": "SELL", "hash": "eae11a845d5bbd235da1d56951a72e140dc5c281", "best_bid": "0.56", "best_ask": "0.61"}], "timestamp": "1769384505971", "event_type": "price_change"}}
{"_local_timestamp": "2026-01-25T23:41:46.067204+00:00", "data": {"market": "0x8b9ba80fb00ffd3ea3d259e0e3d64c2bc057e2d258dbb416138082721491de1f", "price_changes": [{"asset_id": "95471394592044775311259204363647835057798671562193368798960379123943071173821", "price": "0.071", "size": "8.69", "side": "SELL", "hash": "6f582e373ac6ae2d0b0d52c6e3f7f3b7b1f102f5", "best_bid": "0.022", "best_ask": "0.071"}, {"asset_id": "58714825001137751155185117146321345902961648511702872797387135565669201406384", "price": "0.929", "size": "8.69", "side": "BUY", "hash": "43aa2ddcb34eaf4d23cd49350b22312bac6b700f", "best_bid": "0.929", "best_ask": "0.978"}], "timestamp": "1769384505996", "event_type": "price_change"}}
{"_local_timestamp": "2026-01-25T23:41:46.906484+00:00", "data": {"market": "0x3cb3b76b6a4c3fdc6f933464859626df576eaf3e3e404ead3e75056fd48c04f5", "price_changes": [{"asset_id": "50224211346577003424157970845956631119711245094103571068877904015222053747922", "price": "0.55", "size": "94.25", "side": "BUY", "hash": "5ad5062208fa961397ebcdb9a6dbb650c6f4c1d2", "best_bid": "0.56", "best_ask": "0.61"}, {"asset_id": "106006396008449636653509336329453630557359114983730727555924443870035053210127", "price": "0.45", "size": "94.25", "side": "SELL", "hash": "764761123cdb2c748a64f0936e9bd1d83c966695", "best_bid": "0.39", "best_ask": "0.44"}], "timestamp": "1769384506832", "event_type": "price_change"}}
{"_local_timestamp": "2026-01-25T23:41:47.767113+00:00", "data": {"market": "0x75700f135fc1aa9106eecad102e82a5e304afa684948c453d9020973a6dacda6", "price_changes": [{"asset_id": "106943703042015764099709708127099569908287532239730770276583638212344318814024", "price": "0.58", "size": "30", "side": "BUY", "hash": "556b58f426b0a934afe510793f4d818a3ee1c774", "best_bid": "0.61", "best_ask": "0.64"}, {"asset_id": "28461223070646267397095106287041417408320289813700921421278280340813748146076", "price": "0.42", "size": "30", "side": "SELL", "hash": "31f370f05d1af15dc9cf2839788be4f2f25809dc", "best_bid": "0.36", "best_ask": "0.39"}], "timestamp": "1769384507693", "event_type": "price_change"}}
{"_local_timestamp": "2026-01-25T23:41:47.818627+00:00", "data": {"market": "0x3cb3b76b6a4c3fdc6f933464859626df576eaf3e3e404ead3e75056fd48c04f5", "price_changes": [{"asset_id": "106006396008449636653509336329453630557359114983730727555924443870035053210127", "price": "0.34", "size": "100", "side": "BUY", "hash": "d607cf89cda96f02ca4019186113b83190baa585", "best_bid": "0.39", "best_ask": "0.44"}, {"asset_id": "50224211346577003424157970845956631119711245094103571068877904015222053747922", "price": "0.66", "size": "100", "side": "SELL", "hash": "36406a79c537926717af7f9ad7a2cc0ca10455d6", "best_bid": "0.56", "best_ask": "0.61"}], "timestamp": "1769384507749", "event_type": "price_change"}}
{"_local_timestamp": "2026-01-25T23:41:47.875560+00:00", "data": {"market": "0x3cb3b76b6a4c3fdc6f933464859626df576eaf3e3e404ead3e75056fd48c04f5", "price_changes": [{"asset_id": "106006396008449636653509336329453630557359114983730727555924443870035053210127", "price": "0.37", "size": "99", "side": "BUY", "hash": "e095f01c052022c654abe82355aa407bdbc6d9ed", "best_bid": "0.39", "best_ask": "0.44"}, {"asset_id": "50224211346577003424157970845956631119711245094103571068877904015222053747922", "price": "0.63", "size": "99", "side": "SELL", "hash": "253e1632470d8ec6179ee2cb489c939460788147", "best_bid": "0.56", "best_ask": "0.61"}], "timestamp": "1769384507803", "event_type": "price_change"}}
{"_local_timestamp": "2026-01-25T23:41:48.181731+00:00", "data": {"market": "0x3cb3b76b6a4c3fdc6f933464859626df576eaf3e3e404ead3e75056fd48c04f5", "price_changes": [{"asset_id": "106006396008449636653509336329453630557359114983730727555924443870035053210127", "price": "0.38", "size": "48.55", "side": "BUY", "hash": "236cf1fa194f9abc29e5fe1945047c4792ff6428", "best_bid": "0.39", "best_ask": "0.44"}, {"asset_id": "50224211346577003424157970845956631119711245094103571068877904015222053747922", "price": "0.62", "size": "48.55", "side": "SELL", "hash": "8dc16c7c49f005efa7baa35a020c7395a1993052", "best_bid": "0.56", "best_ask": "0.61"}], "timestamp": "1769384508101", "event_type": "price_change"}}
{"_local_timestamp": "2026-01-25T23:41:48.182303+00:00", "data": {"market": "0x75700f135fc1aa9106eecad102e82a5e304afa684948c453d9020973a6dacda6", "price_changes": [{"asset_id": "106943703042015764099709708127099569908287532239730770276583638212344318814024", "price": "0.59", "size": "44.43", "side": "BUY", "hash": "cfb14957b402b0f23e8123dba6b4a72fe5fab60c", "best_bid": "0.61", "best_ask": "0.64"}, {"asset_id": "28461223070646267397095106287041417408320289813700921421278280340813748146076", "price": "0.41", "size": "44.43", "side": "SELL", "hash": "01ac293a95d84814df6eed8eb99e423b469f1073", "best_bid": "0.36", "best_ask": "0.39"}], "timestamp": "1769384508109", "event_type": "price_change"}}
{"_local_timestamp": "2026-01-25T23:41:48.195937+00:00", "data": {"market": "0x3cb3b76b6a4c3fdc6f933464859626df576eaf3e3e404ead3e75056fd48c04f5", "price_changes": [{"asset_id": "106006396008449636653509336329453630557359114983730727555924443870035053210127", "price": "0.45", "size": "17.25", "side": "SELL", "hash": "674bdc5a09c3e85b421c5eb508dbe3eea8d87f6e", "best_bid": "0.39", "best_ask": "0.44"}, {"asset_id": "50224211346577003424157970845956631119711245094103571068877904015222053747922", "price": "0.55", "size": "17.25", "side": "BUY", "hash": "faf1d2a98412fc4c147b4dc9cfa42de9cfcd391a", "best_bid": "0.56", "best_ask": "0.61"}], "timestamp": "1769384508125", "event_type": "price_change"}}
{"_local_timestamp": "2026-01-25T23:41:48.196607+00:00", "data": {"market": "0x3cb3b76b6a4c3fdc6f933464859626df576eaf3e3e404ead3e75056fd48c04f5", "price_changes": [{"asset_id": "106006396008449636653509336329453630557359114983730727555924443870035053210127", "price": "0.37", "size": "46", "side": "BUY", "hash": "674bdc5a09c3e85b421c5eb508dbe3eea8d87f6e", "best_bid": "0.39", "best_ask": "0.44"}, {"asset_id": "50224211346577003424157970845956631119711245094103571068877904015222053747922", "price": "0.63", "size": "46", "side": "SELL", "hash": "faf1d2a98412fc4c147b4dc9cfa42de9cfcd391a", "best_bid": "0.56", "best_ask": "0.61"}], "timestamp": "1769384508125", "event_type": "price_change"}}
{"_local_timestamp": "2026-01-25T23:41:48.216881+00:00", "data": {"market": "0x3cb3b76b6a4c3fdc6f933464859626df576eaf3e3e404ead3e75056fd48c04f5", "price_changes": [{"asset_id": "106006396008449636653509336329453630557359114983730727555924443870035053210127", "price": "0.38", "size": "132.55", "side": "BUY", "hash": "abf3bb4f33d7361497fdd3820beeaba699cbd200", "best_bid": "0.39", "best_ask": "0.44"}, {"asset_id": "50224211346577003424157970845956631119711245094103571068877904015222053747922", "price": "0.62", "size": "132.55", "side": "SELL", "hash": "f5dcf88eb1d517e505e8d499af205404876b02b6", "best_bid": "0.56", "best_ask": "0.61"}], "timestamp": "1769384508152", "event_type": "price_change"}}
{"_local_timestamp": "2026-01-25T23:41:48.390445+00:00", "data": {"market": "0x75700f135fc1aa9106eecad102e82a5e304afa684948c453d9020973a6dacda6", "price_changes": [{"asset_id": "106943703042015764099709708127099569908287532239730770276583638212344318814024", "price": "0.57", "size": "120", "side": "BUY", "hash": "a9c84f7f731bf0a4154ac76ed7107b35d028a69c", "best_bid": "0.61", "best_ask": "0.64"}, {"asset_id": "28461223070646267397095106287041417408320289813700921421278280340813748146076", "price": "0.43", "size": "120", "side": "SELL", "hash": "9ea8b9bab6d64383476f9523a4011c9938487c05", "best_bid": "0.36", "best_ask": "0.39"}], "timestamp": "1769384508322", "event_type": "price_change"}}
{"_local_timestamp": "2026-01-25T23:41:48.467292+00:00", "data": {"market": "0x75700f135fc1aa9106eecad102e82a5e304afa684948c453d9020973a6dacda6", "price_changes": [{"asset_id": "106943703042015764099709708127099569908287532239730770276583638212344318814024", "price": "0.61", "size": "0", "side": "BUY", "hash": "abeead55ac5c9eaf3ab73f72d97af1f67c113b90", "best_bid": "0.6", "best_ask": "0.64"}, {"asset_id": "28461223070646267397095106287041417408320289813700921421278280340813748146076", "price": "0.39", "size": "0", "side": "SELL", "hash": "b6fa924ebc2ba4194ee65246c6e98733badbf80f", "best_bid": "0.36", "best_ask": "0.4"}], "timestamp": "1769384508396", "event_type": "price_change"}}
{"_local_timestamp": "2026-01-25T23:41:48.468113+00:00", "data": {"market": "0x3cb3b76b6a4c3fdc6f933464859626df576eaf3e3e404ead3e75056fd48c04f5", "price_changes": [{"asset_id": "106006396008449636653509336329453630557359114983730727555924443870035053210127", "price": "0.39", "size": "0", "side": "BUY", "hash": "fe5e0726785d16ba4b53c8d142b31fae43b590fc", "best_bid": "0.38", "best_ask": "0.44"}, {"asset_id": "50224211346577003424157970845956631119711245094103571068877904015222053747922", "price": "0.61", "size": "0", "side": "SELL", "hash": "e935d8f67d1006342eab6ddce7112de10bb41591", "best_bid": "0.56", "best_ask": "0.62"}], "timestamp": "1769384508400", "event_type": "price_change"}}
{"_local_timestamp": "2026-01-25T23:41:48.490239+00:00", "data": {"market": "0x75700f135fc1aa9106eecad102e82a5e304afa684948c453d9020973a6dacda6", "price_changes": [{"asset_id": "28461223070646267397095106287041417408320289813700921421278280340813748146076", "price": "0.4", "size": "51", "side": "SELL", "hash": "86a86d1c291d0117ad1b066b230932c99133dff2", "best_bid": "0.36", "best_ask": "0.4"}, {"asset_id": "106943703042015764099709708127099569908287532239730770276583638212344318814024", "price": "0.6", "size": "51", "side": "BUY", "hash": "71edb918088fd9fdfde167d0610e1165fb108dfb", "best_bid": "0.6", "best_ask": "0.64"}], "timestamp": "1769384508423", "event_type": "price_change"}}
{"_local_timestamp": "2026-01-25T23:41:48.689517+00:00", "data": {"market": "0x3cb3b76b6a4c3fdc6f933464859626df576eaf3e3e404ead3e75056fd48c04f5", "price_changes": [{"asset_id": "106006396008449636653509336329453630557359114983730727555924443870035053210127", "price": "0.37", "size": "16", "side": "BUY", "hash": "e21f2f72622e5416e91bcaddf14f234caa08816a", "best_bid": "0.38", "best_ask": "0.44"}, {"asset_id": "50224211346577003424157970845956631119711245094103571068877904015222053747922", "price": "0.63", "size": "16", "side": "SELL", "hash": "33bb33689d3032e46eb7d4e18c5943698f6395f3", "best_bid": "0.56", "best_ask": "0.62"}], "timestamp": "1769384508617", "event_type": "price_change"}}
{"_local_timestamp": "2026-01-25T23:41:48.761189+00:00", "data": {"market": "0x3cb3b76b6a4c3fdc6f933464859626df576eaf3e3e404ead3e75056fd48c04f5", "price_changes": [{"asset_id": "106006396008449636653509336329453630557359114983730727555924443870035053210127", "price": "0.38", "size": "162.55", "side": "BUY", "hash": "e59379fac6c4e95fe4fff30dc36ce350b6aea31b", "best_bid": "0.38", "best_ask": "0.44"}, {"asset_id": "50224211346577003424157970845956631119711245094103571068877904015222053747922", "price": "0.62", "size": "162.55", "side": "SELL", "hash": "996d095689beff18f73de876f0d7fbcb01c03409", "best_bid": "0.56", "best_ask": "0.62"}], "timestamp": "1769384508692", "event_type": "price_change"}}
{"_local_timestamp": "2026-01-25T23:41:49.527393+00:00", "data": {"market": "0x75700f135fc1aa9106eecad102e82a5e304afa684948c453d9020973a6dacda6", "price_changes": [{"asset_id": "106943703042015764099709708127099569908287532239730770276583638212344318814024", "price": "0.58", "size": "0", "side": "BUY", "hash": "a44abe6b3d910acec03991c7ff26f0d7a8a87400", "best_bid": "0.6", "best_ask": "0.64"}, {"asset_id": "28461223070646267397095106287041417408320289813700921421278280340813748146076", "price": "0.42", "size": "0", "side": "SELL", "hash": "30c974c60161e8794c74b26a308c5017ef4932da", "best_bid": "0.36", "best_ask": "0.4"}], "timestamp": "1769384509455", "event_type": "price_change"}}
{"_local_timestamp": "2026-01-25T23:41:49.545266+00:00", "data": {"market": "0x75700f135fc1aa9106eecad102e82a5e304afa684948c453d9020973a6dacda6", "price_changes": [{"asset_id": "28461223070646267397095106287041417408320289813700921421278280340813748146076", "price": "0.4", "size": "5", "side": "SELL", "hash": "7bbe6e25341df666304861bee95fe5421ade096e", "best_bid": "0.36", "best_ask": "0.4"}, {"asset_id": "106943703042015764099709708127099569908287532239730770276583638212344318814024", "price": "0.6", "size": "5", "side": "BUY", "hash": "ff28dd6dfcdec5f4823244c56a78507f12d1037f", "best_bid": "0.6", "best_ask": "0.64"}], "timestamp": "1769384509481", "event_type": "price_change"}}
{"_local_timestamp": "2026-01-25T23:41:49.574652+00:00", "data": {"market": "0x75700f135fc1aa9106eecad102e82a5e304afa684948c453d9020973a6dacda6", "price_changes": [{"asset_id": "106943703042015764099709708127099569908287532239730770276583638212344318814024", "price": "0.6", "size": "82", "side": "BUY", "hash": "1ac75ebbc6b0b7e69854f6db4d5581d5ddb8b441", "best_bid": "0.6", "best_ask": "0.64"}, {"asset_id": "28461223070646267397095106287041417408320289813700921421278280340813748146076", "price": "0.4", "size": "82", "side": "SELL", "hash": "17530740bed13e245c87f80967eea9fcff35de53", "best_bid": "0.36", "best_ask": "0.4"}], "timestamp": "1769384509509", "event_type": "price_change"}}
{"_local_timestamp": "2026-01-25T23:41:49.583685+00:00", "data": {"market": "0x75700f135fc1aa9106eecad102e82a5e304afa684948c453d9020973a6dacda6", "price_changes": [{"asset_id": "106943703042015764099709708127099569908287532239730770276583638212344318814024", "price": "0.6", "size": "112", "side": "BUY", "hash": "e69ad5af267d76d5914a9b6ec887198af6322e17", "best_bid": "0.6", "best_ask": "0.64"}, {"asset_id": "28461223070646267397095106287041417408320289813700921421278280340813748146076", "price": "0.4", "size": "112", "side": "SELL", "hash": "9a12e6e51e3b31e1464f29d6588d7d8a22ade5ba", "best_bid": "0.36", "best_ask": "0.4"}], "timestamp": "1769384509516", "event_type": "price_change"}}
{"_local_timestamp": "2026-01-25T23:41:49.854483+00:00", "data": {"market": "0x3cb3b76b6a4c3fdc6f933464859626df576eaf3e3e404ead3e75056fd48c04f5", "price_changes": [{"asset_id": "106006396008449636653509336329453630557359114983730727555924443870035053210127", "price": "0.39", "size": "48.28", "side": "BUY", "hash": "b642774bff3876f15d12b6068857d0984da8889a", "best_bid": "0.39", "best_ask": "0.44"}, {"asset_id": "50224211346577003424157970845956631119711245094103571068877904015222053747922", "price": "0.61", "size": "48.28", "side": "SELL", "hash": "f37fabb25ec1587e7089bc2500d7817d6eba20bb", "best_bid": "0.56", "best_ask": "0.61"}], "timestamp": "1769384509749", "event_type": "price_change"}}
{"_local_timestamp": "2026-01-25T23:41:51.951405+00:00", "data": {"market": "0x3cb3b76b6a4c3fdc6f933464859626df576eaf3e3e404ead3e75056fd48c04f5", "price_changes": [{"asset_id": "106006396008449636653509336329453630557359114983730727555924443870035053210127", "price": "0.34", "size": "0", "side": "BUY", "hash": "c9be584ff8619b3282e257224ea68589797bb5c2", "best_bid": "0.39", "best_ask": "0.44"}, {"asset_id": "50224211346577003424157970845956631119711245094103571068877904015222053747922", "price": "0.66", "size": "0", "side": "SELL", "hash": "bdd98c08bf071440997e587655e528885c7e9c9b", "best_bid": "0.56", "best_ask": "0.61"}], "timestamp": "1769384511843", "event_type": "price_change"}}
{"_local_timestamp": "2026-01-25T23:41:51.954212+00:00", "data": {"market": "0x75700f135fc1aa9106eecad102e82a5e304afa684948c453d9020973a6dacda6", "price_changes": [{"asset_id": "106943703042015764099709708127099569908287532239730770276583638212344318814024", "price": "0.57", "size": "20", "side": "BUY", "hash": "52821a2b2b6553741207fd8da438e6c5a1bc701f", "best_bid": "0.6", "best_ask": "0.64"}, {"asset_id": "28461223070646267397095106287041417408320289813700921421278280340813748146076", "price": "0.43", "size": "20", "side": "SELL", "hash": "c4eef54d8e2751e2b624ba5f268ba48e523c7548", "best_bid": "0.36", "best_ask": "0.4"}], "timestamp": "1769384511843", "event_type": "price_change"}}
{"_local_timestamp": "2026-01-25T23:41:53.490051+00:00", "data": {"market": "0x75700f135fc1aa9106eecad102e82a5e304afa684948c453d9020973a6dacda6", "price_changes": [{"asset_id": "106943703042015764099709708127099569908287532239730770276583638212344318814024", "price": "0.61", "size": "100", "side": "BUY", "hash": "131e33caf7ad55b3344d72db514bee043c8ab3fe", "best_bid": "0.61", "best_ask": "0.64"}, {"asset_id": "28461223070646267397095106287041417408320289813700921421278280340813748146076", "price": "0.39", "size": "100", "side": "SELL", "hash": "492c4152278e9f209370fd92832fb7413528b120", "best_bid": "0.36", "best_ask": "0.39"}], "timestamp": "1769384513424", "event_type": "price_change"}}
{"_local_timestamp": "2026-01-25T23:41:53.505615+00:00", "data": {"market": "0x3cb3b76b6a4c3fdc6f933464859626df576eaf3e3e404ead3e75056fd48c04f5", "price_changes": [{"asset_id": "106006396008449636653509336329453630557359114983730727555924443870035053210127", "price": "0.4", "size": "100", "side": "BUY", "hash": "16b6266494941e9905bf08b805a17dcf740b69b2", "best_bid": "0.4", "best_ask": "0.44"}, {"asset_id": "50224211346577003424157970845956631119711245094103571068877904015222053747922", "price": "0.6", "size": "100", "side": "SELL", "hash": "61886ea349bfbc48370ca71ce6fc99dd680c9a8f", "best_bid": "0.56", "best_ask": "0.6"}], "timestamp": "1769384513429", "event_type": "price_change"}}
{"_local_timestamp": "2026-01-25T23:41:53.517168+00:00", "data": {"market": "0x75700f135fc1aa9106eecad102e82a5e304afa684948c453d9020973a6dacda6", "price_changes": [{"asset_id": "106943703042015764099709708127099569908287532239730770276583638212344318814024", "price": "0.6", "size": "35", "side": "BUY", "hash": "1e21287941c38bdc3dad49f089df966e65a3317c", "best_bid": "0.61", "best_ask": "0.64"}, {"asset_id": "28461223070646267397095106287041417408320289813700921421278280340813748146076", "price": "0.4", "size": "35", "side": "SELL", "hash": "e3596bca74c4365029bd7bff1b1d8c51b1bf1a5a", "best_bid": "0.36", "best_ask": "0.39"}], "timestamp": "1769384513448", "event_type": "price_change"}}
{"_local_timestamp": "2026-01-25T23:41:53.955012+00:00", "data": {"market": "0x3cb3b76b6a4c3fdc6f933464859626df576eaf3e3e404ead3e75056fd48c04f5", "price_changes": [{"asset_id": "106006396008449636653509336329453630557359114983730727555924443870035053210127", "price": "0.38", "size": "132.55", "side": "BUY", "hash": "5f92ac13c4bed784def5532be15b357f27f98b99", "best_bid": "0.4", "best_ask": "0.44"}, {"asset_id": "50224211346577003424157970845956631119711245094103571068877904015222053747922", "price": "0.62", "size": "132.55", "side": "SELL", "hash": "6ec5b144e62f18d10ac897b3c404da213a700aea", "best_bid": "0.56", "best_ask": "0.6"}], "timestamp": "1769384513890", "event_type": "price_change"}}
{"_local_timestamp": "2026-01-25T23:41:53.962054+00:00", "data": {"market": "0x75700f135fc1aa9106eecad102e82a5e304afa684948c453d9020973a6dacda6", "price_changes": [{"asset_id": "106943703042015764099709708127099569908287532239730770276583638212344318814024", "price": "0.6", "size": "5", "side": "BUY", "hash": "d2337e50b65adec0fb958cf2f3651d7a3a2ec19e", "best_bid": "0.61", "best_ask": "0.64"}, {"asset_id": "28461223070646267397095106287041417408320289813700921421278280340813748146076", "price": "0.4", "size": "5", "side": "SELL", "hash": "5b898d75658b29ed7695a1de231ac2b095931f80", "best_bid": "0.36", "best_ask": "0.39"}], "timestamp": "1769384513890", "event_type": "price_change"}}
{"_local_timestamp": "2026-01-25T23:41:53.979936+00:00", "data": {"market": "0x3cb3b76b6a4c3fdc6f933464859626df576eaf3e3e404ead3e75056fd48c04f5", "price_changes": [{"asset_id": "106006396008449636653509336329453630557359114983730727555924443870035053210127", "price": "0.38", "size": "48.55", "side": "BUY", "hash": "2a6943d252cc8b81078ed76ed251bd08803d82da", "best_bid": "0.4", "best_ask": "0.44"}, {"asset_id": "50224211346577003424157970845956631119711245094103571068877904015222053747922", "price": "0.62", "size": "48.55", "side": "SELL", "hash": "d0ff76c066198bec0904a8bf42c049e767cd4ac8", "best_bid": "0.56", "best_ask": "0.6"}], "timestamp": "1769384513913", "event_type": "price_change"}}
{"_local_timestamp": "2026-01-25T23:41:54.011191+00:00", "data": {"market": "0x3cb3b76b6a4c3fdc6f933464859626df576eaf3e3e404ead3e75056fd48c04f5", "price_changes": [{"asset_id": "106006396008449636653509336329453630557359114983730727555924443870035053210127", "price": "0.41", "size": "36", "side": "BUY", "hash": "7b6b6c5ba0e7e97bf977969d52332cfd0b4cf13f", "best_bid": "0.41", "best_ask": "0.44"}, {"asset_id": "50224211346577003424157970845956631119711245094103571068877904015222053747922", "price": "0.59", "size": "36", "side": "SELL", "hash": "a44251a2f41af816ea7414502e2e5801f446c5bc", "best_bid": "0.56", "best_ask": "0.59"}], "timestamp": "1769384513940", "event_type": "price_change"}}
{"_local_timestamp": "2026-01-25T23:41:54.041940+00:00", "data": {"market": "0x75700f135fc1aa9106eecad102e82a5e304afa684948c453d9020973a6dacda6", "price_changes": [{"asset_id": "106943703042015764099709708127099569908287532239730770276583638212344318814024", "price": "0.61", "size": "130", "side": "BUY", "hash": "46e7781cae13dc39f16a0293f66e312cc684c1fd", "best_bid": "0.61", "best_ask": "0.64"}, {"asset_id": "28461223070646267397095106287041417408320289813700921421278280340813748146076", "price": "0.39", "size": "130", "side": "SELL", "hash": "4c111750bf9effa4152bfd7059c51d533e4ce092", "best_bid": "0.36", "best_ask": "0.39"}], "timestamp": "1769384513972", "event_type": "price_change"}}
{"_local_timestamp": "2026-01-25T23:41:54.042665+00:00", "data": {"market": "0x3cb3b76b6a4c3fdc6f933464859626df576eaf3e3e404ead3e75056fd48c04f5", "price_changes": [{"asset_id": "106006396008449636653509336329453630557359114983730727555924443870035053210127", "price": "0.4", "size": "130", "side": "BUY", "hash": "ca3d6a7c26d692412e4b82121fd0bf657424c7ea", "best_bid": "0.41", "best_ask": "0.44"}, {"asset_id": "50224211346577003424157970845956631119711245094103571068877904015222053747922", "price": "0.6", "size": "130", "side": "SELL", "hash": "536ebaffd89394058b72862d3875cf055378f048", "best_bid": "0.56", "best_ask": "0.59"}], "timestamp": "1769384513973", "event_type": "price_change"}}
{"_local_timestamp": "2026-01-25T23:41:54.207080+00:00", "data": {"market": "0x3cb3b76b6a4c3fdc6f933464859626df576eaf3e3e404ead3e75056fd48c04f5", "price_changes": [{"asset_id": "106006396008449636653509336329453630557359114983730727555924443870035053210127", "price": "0.41", "size": "66", "side": "BUY", "hash": "00eacfcbe654673ac8fa8cb0e814db38d9589987", "best_bid": "0.41", "best_ask": "0.44"}, {"asset_id": "50224211346577003424157970845956631119711245094103571068877904015222053747922", "price": "0.59", "size": "66", "side": "SELL", "hash": "b84bfa6ba61f0e63ce99533f64fa36e595581779", "best_bid": "0.56", "best_ask": "0.59"}], "timestamp": "1769384514135", "event_type": "price_change"}}
{"_local_timestamp": "2026-01-25T23:41:54.529418+00:00", "data": {"market": "0x3cb3b76b6a4c3fdc6f933464859626df576eaf3e3e404ead3e75056fd48c04f5", "price_changes": [{"asset_id": "106006396008449636653509336329453630557359114983730727555924443870035053210127", "price": "0.38", "size": "18.55", "side": "BUY", "hash": "eff0eb833e85422d08b7662a5485ef881e93afaa", "best_bid": "0.41", "best_ask": "0.44"}, {"asset_id": "50224211346577003424157970845956631119711245094103571068877904015222053747922", "price": "0.62", "size": "18.55", "side": "SELL", "hash": "547094b798a6a0570f6b4e29de9a14330c6648f0", "best_bid": "0.56", "best_ask": "0.59"}], "timestamp": "1769384514452", "event_type": "price_change"}}
{"_local_timestamp": "2026-01-25T23:41:54.530460+00:00", "data": {"market": "0x75700f135fc1aa9106eecad102e82a5e304afa684948c453d9020973a6dacda6", "price_changes": [{"asset_id": "106943703042015764099709708127099569908287532239730770276583638212344318814024", "price": "0.59", "size": "14.43", "side": "BUY", "hash": "9a67774f15e7565108e8e25a10f8440456a45db2", "best_bid": "0.61", "best_ask": "0.64"}, {"asset_id": "28461223070646267397095106287041417408320289813700921421278280340813748146076", "price": "0.41", "size": "14.43", "side": "SELL", "hash": "9f735bb87a80f924197e3bf1ab2d3699b63bb9c8", "best_bid": "0.36", "best_ask": "0.39"}], "timestamp": "1769384514452", "event_type": "price_change"}}
{"_local_timestamp": "2026-01-25T23:41:55.827124+00:00", "data": {"market": "0x3cb3b76b6a4c3fdc6f933464859626df576eaf3e3e404ead3e75056fd48c04f5", "price_changes": [{"asset_id": "106006396008449636653509336329453630557359114983730727555924443870035053210127", "price": "0.35", "size": "5", "side": "BUY", "hash": "bf86823aef86335ab8df82a35c2ae263960b84ba", "best_bid": "0.41", "best_ask": "0.44"}, {"asset_id": "50224211346577003424157970845956631119711245094103571068877904015222053747922", "price": "0.65", "size": "5", "side": "SELL", "hash": "a3e5a353b024ceae9f011131ad518f46f7926a6f", "best_bid": "0.56", "best_ask": "0.59"}], "timestamp": "1769384515759", "event_type": "price_change"}}
{"_local_timestamp": "2026-01-25T23:41:55.867255+00:00", "data": {"market": "0x3cb3b76b6a4c3fdc6f933464859626df576eaf3e3e404ead3e75056fd48c04f5", "price_changes": [{"asset_id": "106006396008449636653509336329453630557359114983730727555924443870035053210127", "price": "0.34", "size": "20", "side": "BUY", "hash": "3266499fda7f3793765419d47266395a5b0221e5", "best_bid": "0.41", "best_ask": "0.44"}, {"asset_id": "50224211346577003424157970845956631119711245094103571068877904015222053747922", "price": "0.66", "size": "20", "side": "SELL", "hash": "4b696ee6dbefea1b0376f4314622bdd7b65950e8", "best_bid": "0.56", "best_ask": "0.59"}], "timestamp": "1769384515786", "event_type": "price_change"}}
{"_local_timestamp": "2026-01-25T23:41:56.182475+00:00", "data": {"market": "0x3cb3b76b6a4c3fdc6f933464859626df576eaf3e3e404ead3e75056fd48c04f5", "price_changes": [{"asset_id": "106006396008449636653509336329453630557359114983730727555924443870035053210127", "price": "0.4", "size": "100", "side": "BUY", "hash": "1638eca124bca3ce41bbefe370e00f975391ee90", "best_bid": "0.41", "best_ask": "0.44"}, {"asset_id": "50224211346577003424157970845956631119711245094103571068877904015222053747922", "price": "0.6", "size": "100", "side": "SELL", "hash": "675823cdbf2462001a5ba284036ce2e12b27d4f9", "best_bid": "0.56", "best_ask": "0.59"}], "timestamp": "1769384516110", "event_type": "price_change"}}
{"_local_timestamp": "2026-01-25T23:41:56.250385+00:00", "data": {"market": "0x3cb3b76b6a4c3fdc6f933464859626df576eaf3e3e404ead3e75056fd48c04f5", "price_changes": [{"asset_id": "106006396008449636653509336329453630557359114983730727555924443870035053210127", "price": "0.41", "size": "96", "side": "BUY", "hash": "04d37f84885cdfd125524caa1a8dfe5dc6df1676", "best_bid": "0.41", "best_ask": "0.44"}, {"asset_id": "50224211346577003424157970845956631119711245094103571068877904015222053747922", "price": "0.59", "size": "96", "side": "SELL", "hash": "5eb28719e16836935c52cdc0bc48ba1f66ac093c", "best_bid": "0.56", "best_ask": "0.59"}], "timestamp": "1769384516159", "event_type": "price_change"}}
{"_local_timestamp": "2026-01-25T23:41:57.300407+00:00", "data": {"market": "0x75700f135fc1aa9106eecad102e82a5e304afa684948c453d9020973a6dacda6", "price_changes": [{"asset_id": "106943703042015764099709708127099569908287532239730770276583638212344318814024", "price": "0.61", "size": "30", "side": "BUY", "hash": "63302970c56b59870d3c6e97d8cc7141a283e571", "best_bid": "0.61", "best_ask": "0.64"}, {"asset_id": "28461223070646267397095106287041417408320289813700921421278280340813748146076", "price": "0.39", "size": "30", "side": "SELL", "hash": "119b4fdc6b9b81b4abf3c763fa412e0571c3f2ce", "best_bid": "0.36", "best_ask": "0.39"}], "timestamp": "1769384517230", "event_type": "price_change"}}
{"_local_timestamp": "2026-01-25T23:41:57.301101+00:00", "data": {"market": "0x3cb3b76b6a4c3fdc6f933464859626df576eaf3e3e404ead3e75056fd48c04f5", "price_changes": [{"asset_id": "106006396008449636653509336329453630557359114983730727555924443870035053210127", "price": "0.4", "size": "0", "side": "BUY", "hash": "63e18194b79b40aef5dd205fbf7583ad4cb6be49", "best_bid": "0.41", "best_ask": "0.44"}, {"asset_id": "50224211346577003424157970845956631119711245094103571068877904015222053747922", "price": "0.6", "size": "0", "side": "SELL", "hash": "034fd8a9f1307094bc576273246cf4904dff718a", "best_bid": "0.56", "best_ask": "0.59"}], "timestamp": "1769384517230", "event_type": "price_change"}}
{"_local_timestamp": "2026-01-25T23:41:58.036780+00:00", "data": {"market": "0x75700f135fc1aa9106eecad102e82a5e304afa684948c453d9020973a6dacda6", "price_changes": [{"asset_id": "106943703042015764099709708127099569908287532239730770276583638212344318814024", "price": "0.59", "size": "0", "side": "BUY", "hash": "0b46714ec19081560c0198d88912815cbfc5b70e", "best_bid": "0.61", "best_ask": "0.64"}, {"asset_id": "28461223070646267397095106287041417408320289813700921421278280340813748146076", "price": "0.41", "size": "0", "side": "SELL", "hash": "9c48f737163e3c26b78cd069755b99d98eee9b0d", "best_bid": "0.36", "best_ask": "0.39"}], "timestamp": "1769384517969", "event_type": "price_change"}}
{"_local_timestamp": "2026-01-25T23:41:58.104547+00:00", "data": {"market": "0x75700f135fc1aa9106eecad102e82a5e304afa684948c453d9020973a6dacda6", "price_changes": [{"asset_id": "106943703042015764099709708127099569908287532239730770276583638212344318814024", "price": "0.57", "size": "120", "side": "BUY", "hash": "43e1182922d03fdde1374fed43d51660e19461c3", "best_bid": "0.61", "best_ask": "0.64"}, {"asset_id": "28461223070646267397095106287041417408320289813700921421278280340813748146076", "price": "0.43", "size": "120", "side": "SELL", "hash": "6b51af7c04d481f4c69d537edafd55c181d34e9f", "best_bid": "0.36", "best_ask": "0.39"}], "timestamp": "1769384518009", "event_type": "price_change"}}
{"_local_timestamp": "2026-01-25T23:41:58.186641+00:00", "data": {"market": "0x75700f135fc1aa9106eecad102e82a5e304afa684948c453d9020973a6dacda6", "price_changes": [{"asset_id": "106943703042015764099709708127099569908287532239730770276583638212344318814024", "price": "0.61", "size": "0", "side": "BUY", "hash": "39e965591347f3a18ffd012991ce9912903a2f3a", "best_bid": "0.6", "best_ask": "0.64"}, {"asset_id": "28461223070646267397095106287041417408320289813700921421278280340813748146076", "price": "0.39", "size": "0", "side": "SELL", "hash": "e65c4cf5cb8611314bd2f2008946597e0f1d5a4b", "best_bid": "0.36", "best_ask": "0.4"}], "timestamp": "1769384518113", "event_type": "price_change"}}
{"_local_timestamp": "2026-01-25T23:41:58.215142+00:00", "data": {"market": "0x75700f135fc1aa9106eecad102e82a5e304afa684948c453d9020973a6dacda6", "price_changes": [{"asset_id": "106943703042015764099709708127099569908287532239730770276583638212344318814024", "price": "0.58", "size": "77", "side": "BUY", "hash": "4c0ce5dbad166c92b3f52e6e3a20586f2a3f1a34", "best_bid": "0.6", "best_ask": "0.64"}, {"asset_id": "28461223070646267397095106287041417408320289813700921421278280340813748146076", "price": "0.42", "size": "77", "side": "SELL", "hash": "9578f43c0848f3a22c5a6384a0ffc37a4c899d25", "best_bid": "0.36", "best_ask": "0.4"}], "timestamp": "1769384518139", "event_type": "price_change"}}
{"_local_timestamp": "2026-01-25T23:41:58.215872+00:00", "data": {"market": "0x75700f135fc1aa9106eecad102e82a5e304afa684948c453d9020973a6dacda6", "price_changes": [{"asset_id": "28461223070646267397095106287041417408320289813700921421278280340813748146076", "price": "0.33", "size": "24", "side": "BUY", "hash": "41f3f96630f10ae10586369ec57ec85338f9ba8a", "best_bid": "0.36", "best_ask": "0.4"}, {"asset_id": "106943703042015764099709708127099569908287532239730770276583638212344318814024", "price": "0.67", "size": "24", "side": "SELL", "hash": "f7da28badd5f776aa9d9ab6b1f1a1d09e4c1a713", "best_bid": "0.6", "best_ask": "0.64"}], "timestamp": "1769384518142", "event_type": "price_change"}}
{"_local_timestamp": "2026-01-25T23:41:58.247347+00:00", "data": {"market": "0x75700f135fc1aa9106eecad102e82a5e304afa684948c453d9020973a6dacda6", "price_changes": [{"asset_id": "106943703042015764099709708127099569908287532239730770276583638212344318814024", "price": "0.55", "size": "86", "side": "BUY", "hash": "85867ea6c8f9c90bd63928bf35c1e3def8e70d1b", "best_bid": "0.6", "best_ask": "0.64"}, {"asset_id": "28461223070646267397095106287041417408320289813700921421278280340813748146076", "price": "0.45", "size": "86", "side": "SELL", "hash": "9e407da8d766ae03bcdc6ddce8626db8e041fe74", "best_bid": "0.36", "best_ask": "0.4"}], "timestamp": "1769384518173", "event_type": "price_change"}}
{"_local_timestamp": "2026-01-25T23:41:58.476320+00:00", "data": {"market": "0x75700f135fc1aa9106eecad102e82a5e304afa684948c453d9020973a6dacda6", "price_changes": [{"asset_id": "106943703042015764099709708127099569908287532239730770276583638212344318814024", "price": "0.61", "size": "36.03", "side": "BUY", "hash": "feebc2bb2300fb0b5eba3fcc0c54e88b41203492", "best_bid": "0.61", "best_ask": "0.64"}, {"asset_id": "28461223070646267397095106287041417408320289813700921421278280340813748146076", "price": "0.39", "size": "36.03", "side": "SELL", "hash": "9bed93ce5c980ffdf8baa51c8bfe960eaec9b7ee", "best_bid": "0.36", "best_ask": "0.39"}], "timestamp": "1769384518410", "event_type": "price_change"}}
{"_local_timestamp": "2026-01-25T23:41:59.411972+00:00", "data": {"market": "0x75700f135fc1aa9106eecad102e82a5e304afa684948c453d9020973a6dacda6", "price_changes": [{"asset_id": "106943703042015764099709708127099569908287532239730770276583638212344318814024", "price": "0.58", "size": "0", "side": "BUY", "hash": "48af0574cb53d4d3aa317bf61749120b47cdcb32", "best_bid": "0.61", "best_ask": "0.64"}, {"asset_id": "28461223070646267397095106287041417408320289813700921421278280340813748146076", "price": "0.42", "size": "0", "side": "SELL", "hash": "d637349fe2a8a377171a0ba897eff6d2a06e98bf", "best_bid": "0.36", "best_ask": "0.39"}], "timestamp": "1769384519345", "event_type": "price_change"}}
{"_local_timestamp": "2026-01-25T23:41:59.412709+00:00", "data": {"market": "0x75700f135fc1aa9106eecad102e82a5e304afa684948c453d9020973a6dacda6", "price_changes": [{"asset_id": "28461223070646267397095106287041417408320289813700921421278280340813748146076", "price": "0.33", "size": "0", "side": "BUY", "hash": "0a6d3e9d90cdabbc86ecc597f3267d3dd535422b", "best_bid": "0.36", "best_ask": "0.39"}, {"asset_id": "106943703042015764099709708127099569908287532239730770276583638212344318814024", "price": "0.67", "size": "0", "side": "SELL", "hash": "b58b84b7454df60292d5dc59874fc8cc91c1e9a9", "best_bid": "0.61", "best_ask": "0.64"}], "timestamp": "1769384519346", "event_type": "price_change"}}
{"_local_timestamp": "2026-01-25T23:41:59.781162+00:00", "data": {"market": "0x75700f135fc1aa9106eecad102e82a5e304afa684948c453d9020973a6dacda6", "price_changes": [{"asset_id": "106943703042015764099709708127099569908287532239730770276583638212344318814024", "price": "0.55", "size": "56", "side": "BUY", "hash": "a26386dd947a74042753e4f434ab53c20ae1f1ee", "best_bid": "0.61", "best_ask": "0.64"}, {"asset_id": "28461223070646267397095106287041417408320289813700921421278280340813748146076", "price": "0.45", "size": "56", "side": "SELL", "hash": "2d13e1d6205bc676d8bb56364bd89b0bc6b2fd17", "best_bid": "0.36", "best_ask": "0.39"}], "timestamp": "1769384519706", "event_type": "price_change"}}
{"_local_timestamp": "2026-01-25T23:41:59.835594+00:00", "data": {"market": "0x75700f135fc1aa9106eecad102e82a5e304afa684948c453d9020973a6dacda6", "price_changes": [{"asset_id": "106943703042015764099709708127099569908287532239730770276583638212344318814024", "price": "0.58", "size": "30", "side": "BUY", "hash": "1b1e7ee269d0d7f16adfa31677c43c78e456afa0", "best_bid": "0.61", "best_ask": "0.64"}, {"asset_id": "28461223070646267397095106287041417408320289813700921421278280340813748146076", "price": "0.42", "size": "30", "side": "SELL", "hash": "f7b2bd9e710dbb3244d83dbebf055bc84881eda7", "best_bid": "0.36", "best_ask": "0.39"}], "timestamp": "1769384519770", "event_type": "price_change"}}
{"_local_timestamp": "2026-01-25T23:42:00.275048+00:00", "data": {"market": "0x3cb3b76b6a4c3fdc6f933464859626df576eaf3e3e404ead3e75056fd48c04f5", "price_changes": [{"asset_id": "106006396008449636653509336329453630557359114983730727555924443870035053210127", "price": "0.34", "size": "50", "side": "BUY", "hash": "b60fe046be5f5b364dca0e0ecb5914eef107572b", "best_bid": "0.41", "best_ask": "0.44"}, {"asset_id": "50224211346577003424157970845956631119711245094103571068877904015222053747922", "price": "0.66", "size": "50", "side": "SELL", "hash": "e2e0b6bb09bc198dbf0b1bca3b0178cfb51bde9c", "best_bid": "0.56", "best_ask": "0.59"}], "timestamp": "1769384520206", "event_type": "price_change"}}
{"_local_timestamp": "2026-01-25T23:42:00.516181+00:00", "data": {"market": "0x3cb3b76b6a4c3fdc6f933464859626df576eaf3e3e404ead3e75056fd48c04f5", "price_changes": [{"asset_id": "106006396008449636653509336329453630557359114983730727555924443870035053210127", "price": "0.41", "size": "66", "side": "BUY", "hash": "7a9830a264b1849b5d3e63f69af8becbc78314dd", "best_bid": "0.41", "best_ask": "0.44"}, {"asset_id": "50224211346577003424157970845956631119711245094103571068877904015222053747922", "price": "0.59", "size": "66", "side": "SELL", "hash": "16440ef4d244f45268873f6c3755a14f34fd29a3", "best_bid": "0.56", "best_ask": "0.59"}], "timestamp": "1769384520450", "event_type": "price_change"}}
{"_local_timestamp": "2026-01-25T23:42:00.524950+00:00", "data": {"market": "0x3cb3b76b6a4c3fdc6f933464859626df576eaf3e3e404ead3e75056fd48c04f5", "price_changes": [{"asset_id": "106006396008449636653509336329453630557359114983730727555924443870035053210127", "price": "0.34", "size": "30", "side": "BUY", "hash": "004fdcb6364f85e3e1d33c56191ade6536d43fb6", "best_bid": "0.41", "best_ask": "0.44"}, {"asset_id": "50224211346577003424157970845956631119711245094103571068877904015222053747922", "price": "0.66", "size": "30", "side": "SELL", "hash": "dca3d2b937ace607550f651921e0bb27fea4e77e", "best_bid": "0.56", "best_ask": "0.59"}], "timestamp": "1769384520460", "event_type": "price_change"}}
{"_local_timestamp": "2026-01-25T23:42:00.557270+00:00", "data": {"market": "0x3cb3b76b6a4c3fdc6f933464859626df576eaf3e3e404ead3e75056fd48c04f5", "price_changes": [{"asset_id": "106006396008449636653509336329453630557359114983730727555924443870035053210127", "price": "0.35", "size": "25", "side": "BUY", "hash": "723ea3ec8ee03022990202043aa6387f5f7a4945", "best_bid": "0.41", "best_ask": "0.44"}, {"asset_id": "50224211346577003424157970845956631119711245094103571068877904015222053747922", "price": "0.65", "size": "25", "side": "SELL", "hash": "e082e31f9232971754f93e79b36967ebd776089b", "best_bid": "0.56", "best_ask": "0.59"}], "timestamp": "1769384520491", "event_type": "price_change"}}
{"_local_timestamp": "2026-01-25T23:42:00.684430+00:00", "data": {"market": "0x3cb3b76b6a4c3fdc6f933464859626df576eaf3e3e404ead3e75056fd48c04f5", "price_changes": [{"asset_id": "106006396008449636653509336329453630557359114983730727555924443870035053210127", "price": "0.41", "size": "36", "side": "BUY", "hash": "e31005516558fe1f05e7946c3dcc71cf233c5fbf", "best_bid": "0.41", "best_ask": "0.44"}, {"asset_id": "50224211346577003424157970845956631119711245094103571068877904015222053747922", "price": "0.59", "size": "36", "side": "SELL", "hash": "415a76cef782dfe1bfbb8c160e3a03d6d3ffec98", "best_bid": "0.56", "best_ask": "0.59"}], "timestamp": "1769384520613", "event_type": "price_change"}}
{"_local_timestamp": "2026-01-25T23:42:00.790410+00:00", "data": {"market": "0x3cb3b76b6a4c3fdc6f933464859626df576eaf3e3e404ead3e75056fd48c04f5", "price_changes": [{"asset_id": "106006396008449636653509336329453630557359114983730727555924443870035053210127", "price": "0.33", "size": "130", "side": "BUY", "hash": "cc0ac6e438b153aff675bc312f4c9da36afa25bb", "best_bid": "0.41", "best_ask": "0.44"}, {"asset_id": "50224211346577003424157970845956631119711245094103571068877904015222053747922", "price": "0.67", "size": "130", "side": "SELL", "hash": "fe8882ba722b7da935be3ed6a3abbd8faeb3fee8", "best_bid": "0.56", "best_ask": "0.59"}], "timestamp": "1769384520728", "event_type": "price_change"}}
{"_local_timestamp": "2026-01-25T23:42:02.472459+00:00", "data": {"market": "0x3cb3b76b6a4c3fdc6f933464859626df576eaf3e3e404ead3e75056fd48c04f5", "price_changes": [{"asset_id": "106006396008449636653509336329453630557359114983730727555924443870035053210127", "price": "0.34", "size": "130", "side": "BUY", "hash": "365a3e87c025a14c8be3f659fa3ce7a8e4af8575", "best_bid": "0.41", "best_ask": "0.44"}, {"asset_id": "50224211346577003424157970845956631119711245094103571068877904015222053747922", "price": "0.66", "size": "130", "side": "SELL", "hash": "62685910c5d7015857c47a1ed08a61b16cba4401", "best_bid": "0.56", "best_ask": "0.59"}], "timestamp": "1769384522397", "event_type": "price_change"}}
{"_local_timestamp": "2026-01-25T23:42:02.899615+00:00", "data": {"market": "0x3cb3b76b6a4c3fdc6f933464859626df576eaf3e3e404ead3e75056fd48c04f5", "price_changes": [{"asset_id": "106006396008449636653509336329453630557359114983730727555924443870035053210127", "price": "0.33", "size": "100", "side": "BUY", "hash": "e1955355c97a04cfe38237338695a8272897bb60", "best_bid": "0.41", "best_ask": "0.44"}, {"asset_id": "50224211346577003424157970845956631119711245094103571068877904015222053747922", "price": "0.67", "size": "100", "side": "SELL", "hash": "d829cd3297efba0c6ca041e46d20befa1dbf0726", "best_bid": "0.56", "best_ask": "0.59"}], "timestamp": "1769384522835", "event_type": "price_change"}}
{"_local_timestamp": "2026-01-25T23:42:02.988956+00:00", "data": {"market": "0x3cb3b76b6a4c3fdc6f933464859626df576eaf3e3e404ead3e75056fd48c04f5", "price_changes": [{"asset_id": "106006396008449636653509336329453630557359114983730727555924443870035053210127", "price": "0.34", "size": "160", "side": "BUY", "hash": "5453fe579e58e28c323de1f2d4ede46bee13c084", "best_bid": "0.41", "best_ask": "0.44"}, {"asset_id": "50224211346577003424157970845956631119711245094103571068877904015222053747922", "price": "0.66", "size": "160", "side": "SELL", "hash": "2e410d7a184bae18e32fdda7139f3b9e0415ccb2", "best_bid": "0.56", "best_ask": "0.59"}], "timestamp": "1769384522921", "event_type": "price_change"}}
{"_local_timestamp": "2026-01-25T23:42:03.676514+00:00", "data": {"market": "0x75700f135fc1aa9106eecad102e82a5e304afa684948c453d9020973a6dacda6", "price_changes": [{"asset_id": "106943703042015764099709708127099569908287532239730770276583638212344318814024", "price": "0.61", "size": "0", "side": "BUY", "hash": "3c2e386cbbd14cda4698edeee4818797171a45be", "best_bid": "0.6", "best_ask": "0.64"}, {"asset_id": "28461223070646267397095106287041417408320289813700921421278280340813748146076", "price": "0.39", "size": "0", "side": "SELL", "hash": "23f16c8cddef5b04a088d68b9dc92857874f94c9", "best_bid": "0.36", "best_ask": "0.4"}], "timestamp": "1769384523612", "event_type": "price_change"}}
{"_local_timestamp": "2026-01-25T23:42:03.705484+00:00", "data": {"market": "0x75700f135fc1aa9106eecad102e82a5e304afa684948c453d9020973a6dacda6", "price_changes": [{"asset_id": "106943703042015764099709708127099569908287532239730770276583638212344318814024", "price": "0.58", "size": "104", "side": "BUY", "hash": "46fc0a3534d393368e354005262fa8a957e00690", "best_bid": "0.6", "best_ask": "0.64"}, {"asset_id": "28461223070646267397095106287041417408320289813700921421278280340813748146076", "price": "0.42", "size": "104", "side": "SELL", "hash": "2dbf864e9db0e057de1231b089e67faccbb816b7", "best_bid": "0.36", "best_ask": "0.4"}], "timestamp": "1769384523637", "event_type": "price_change"}}
{"_local_timestamp": "2026-01-25T23:42:04.524412+00:00", "data": {"market": "0x75700f135fc1aa9106eecad102e82a5e304afa684948c453d9020973a6dacda6", "price_changes": [{"asset_id": "106943703042015764099709708127099569908287532239730770276583638212344318814024", "price": "0.58", "size": "128.67", "side": "BUY", "hash": "b8b7cdcbc96d9737af04d55bf21b0fd8ed7da9e5", "best_bid": "0.6", "best_ask": "0.64"}, {"asset_id": "28461223070646267397095106287041417408320289813700921421278280340813748146076", "price": "0.42", "size": "128.67", "side": "SELL", "hash": "4dcd0902a7d107051df121b900e070eabde2d3d5", "best_bid": "0.36", "best_ask": "0.4"}], "timestamp": "1769384524455", "event_type": "price_change"}}
{"_local_timestamp": "2026-01-25T23:42:06.127194+00:00", "data": {"market": "0x75700f135fc1aa9106eecad102e82a5e304afa684948c453d9020973a6dacda6", "price_changes": [{"asset_id": "106943703042015764099709708127099569908287532239730770276583638212344318814024", "price": "0.57", "size": "20", "side": "BUY", "hash": "c239cc9ea744bfb596a55a1480b29450a26e6ab1", "best_bid": "0.6", "best_ask": "0.64"}, {"asset_id": "28461223070646267397095106287041417408320289813700921421278280340813748146076", "price": "0.43", "size": "20", "side": "SELL", "hash": "b33256a9d44626ade22b029440791f7b3a58ad91", "best_bid": "0.36", "best_ask": "0.4"}], "timestamp": "1769384526057", "event_type": "price_change"}}
{"_local_timestamp": "2026-01-25T23:42:06.139203+00:00", "data": {"market": "0x3cb3b76b6a4c3fdc6f933464859626df576eaf3e3e404ead3e75056fd48c04f5", "price_changes": [{"asset_id": "106006396008449636653509336329453630557359114983730727555924443870035053210127", "price": "0.34", "size": "60", "side": "BUY", "hash": "b14287b0ac0d0ffe30459fdd640f31cda7c1169e", "best_bid": "0.41", "best_ask": "0.44"}, {"asset_id": "50224211346577003424157970845956631119711245094103571068877904015222053747922", "price": "0.66", "size": "60", "side": "SELL", "hash": "a11712631de3f857c5228cd913cae621b0c3dd7e", "best_bid": "0.56", "best_ask": "0.59"}], "timestamp": "1769384526066", "event_type": "price_change"}}
{"_local_timestamp": "2026-01-25T23:42:06.155197+00:00", "data": {"market": "0x75700f135fc1aa9106eecad102e82a5e304afa684948c453d9020973a6dacda6", "price_changes": [{"asset_id": "28461223070646267397095106287041417408320289813700921421278280340813748146076", "price": "0.33", "size": "19", "side": "BUY", "hash": "8649b0f605ff0539af6f3081bba04fc242a86299", "best_bid": "0.36", "best_ask": "0.4"}, {"asset_id": "106943703042015764099709708127099569908287532239730770276583638212344318814024", "price": "0.67", "size": "19", "side": "SELL", "hash": "f9d88dcdb2345b42b60098c939a9d86c903fe548", "best_bid": "0.6", "best_ask": "0.64"}], "timestamp": "1769384526089", "event_type": "price_change"}}
{"_local_timestamp": "2026-01-25T23:42:06.163899+00:00", "data": {"market": "0x3cb3b76b6a4c3fdc6f933464859626df576eaf3e3e404ead3e75056fd48c04f5", "price_changes": [{"asset_id": "106006396008449636653509336329453630557359114983730727555924443870035053210127", "price": "0.41", "size": "0", "side": "BUY", "hash": "9989f63fb52e20e392736ce54563f3a9df1a61ce", "best_bid": "0.39", "best_ask": "0.44"}, {"asset_id": "50224211346577003424157970845956631119711245094103571068877904015222053747922", "price": "0.59", "size": "0", "side": "SELL", "hash": "5099738d752d9aa0fd0de69e509e96f7346bd558", "best_bid": "0.56", "best_ask": "0.61"}], "timestamp": "1769384526099", "event_type": "price_change"}}
{"_local_timestamp": "2026-01-25T23:42:06.187665+00:00", "data": {"market": "0x3cb3b76b6a4c3fdc6f933464859626df576eaf3e3e404ead3e75056fd48c04f5", "price_changes": [{"asset_id": "106006396008449636653509336329453630557359114983730727555924443870035053210127", "price": "0.37", "size": "67", "side": "BUY", "hash": "93b23bc92537d8fdf71e4bea3e1dcfd5bbbe6cd8", "best_bid": "0.39", "best_ask": "0.44"}, {"asset_id": "50224211346577003424157970845956631119711245094103571068877904015222053747922", "price": "0.63", "size": "67", "side": "SELL", "hash": "37f0ffabe0c24a5bb791c29dd058b060a5cb28f9", "best_bid": "0.56", "best_ask": "0.61"}], "timestamp": "1769384526125", "event_type": "price_change"}}
{"_local_timestamp": "2026-01-25T23:42:06.200780+00:00", "data": {"market": "0x75700f135fc1aa9106eecad102e82a5e304afa684948c453d9020973a6dacda6", "price_changes": [{"asset_id": "106943703042015764099709708127099569908287532239730770276583638212344318814024", "price": "0.59", "size": "30", "side": "BUY", "hash": "a8e879b4cb5479fd1f7aab6193b920bcaf820d37", "best_bid": "0.6", "best_ask": "0.64"}, {"asset_id": "28461223070646267397095106287041417408320289813700921421278280340813748146076", "price": "0.41", "size": "30", "side": "SELL", "hash": "6df1d9f75ee86dd88cb8a98808839a93d4d8021d", "best_bid": "0.36", "best_ask": "0.4"}], "timestamp": "1769384526126", "event_type": "price_change"}}
{"_local_timestamp": "2026-01-25T23:42:06.492924+00:00", "data": {"market": "0x3cb3b76b6a4c3fdc6f933464859626df576eaf3e3e404ead3e75056fd48c04f5", "price_changes": [{"asset_id": "106006396008449636653509336329453630557359114983730727555924443870035053210127", "price": "0.34", "size": "30", "side": "BUY", "hash": "f9ee34309db1fd390054e2b440476dc27b07552c", "best_bid": "0.39", "best_ask": "0.44"}, {"asset_id": "50224211346577003424157970845956631119711245094103571068877904015222053747922", "price": "0.66", "size": "30", "side": "SELL", "hash": "a02750f2c4ecc4727facb709b332bc1840c401a4", "best_bid": "0.56", "best_ask": "0.61"}], "timestamp": "1769384526422", "event_type": "price_change"}}
{"_local_timestamp": "2026-01-25T23:42:06.556191+00:00", "data": {"market": "0x3cb3b76b6a4c3fdc6f933464859626df576eaf3e3e404ead3e75056fd48c04f5", "price_changes": [{"asset_id": "106006396008449636653509336329453630557359114983730727555924443870035053210127", "price": "0.35", "size": "125", "side": "BUY", "hash": "56411eb220a011e07683441d9ff19372d44729f9", "best_bid": "0.39", "best_ask": "0.44"}, {"asset_id": "50224211346577003424157970845956631119711245094103571068877904015222053747922", "price": "0.65", "size": "125", "side": "SELL", "hash": "ebd4a7edf360d87f19c98d1d4852f8122bf85d7d", "best_bid": "0.56", "best_ask": "0.61"}], "timestamp": "1769384526491", "event_type": "price_change"}}
{"_local_timestamp": "2026-01-25T23:42:06.564824+00:00", "data": {"market": "0x75700f135fc1aa9106eecad102e82a5e304afa684948c453d9020973a6dacda6", "price_changes": [{"asset_id": "106943703042015764099709708127099569908287532239730770276583638212344318814024", "price": "0.59", "size": "130", "side": "BUY", "hash": "240b8c48289371f2abac544f408a40a893016ec8", "best_bid": "0.6", "best_ask": "0.64"}, {"asset_id": "28461223070646267397095106287041417408320289813700921421278280340813748146076", "price": "0.41", "size": "130", "side": "SELL", "hash": "8626131f769536ad3c6167439f8fa62a93d20238", "best_bid": "0.36", "best_ask": "0.4"}], "timestamp": "1769384526494", "event_type": "price_change"}}
{"_local_timestamp": "2026-01-25T23:42:06.582323+00:00", "data": {"market": "0x75700f135fc1aa9106eecad102e82a5e304afa684948c453d9020973a6dacda6", "price_changes": [{"asset_id": "106943703042015764099709708127099569908287532239730770276583638212344318814024", "price": "0.58", "size": "54.67", "side": "BUY", "hash": "a4e4fa749d4ba665d8819062774e443a6a2b80ee", "best_bid": "0.6", "best_ask": "0.64"}, {"asset_id": "28461223070646267397095106287041417408320289813700921421278280340813748146076", "price": "0.42", "size": "54.67", "side": "SELL", "hash": "62df3ea41e9e487d700fbbc238ef11e3a8ec5f77", "best_bid": "0.36", "best_ask": "0.4"}], "timestamp": "1769384526519", "event_type": "price_change"}}
{"_local_timestamp": "2026-01-25T23:42:06.610502+00:00", "data": {"market": "0x75700f135fc1aa9106eecad102e82a5e304afa684948c453d9020973a6dacda6", "price_changes": [{"asset_id": "106943703042015764099709708127099569908287532239730770276583638212344318814024", "price": "0.6", "size": "79", "side": "BUY", "hash": "eb8e570e5052df49b10ed980bf9bcc684eaebe90", "best_bid": "0.6", "best_ask": "0.64"}, {"asset_id": "28461223070646267397095106287041417408320289813700921421278280340813748146076", "price": "0.4", "size": "79", "side": "SELL", "hash": "55816b7b729ff8fd26b08aad56827ff908e65558", "best_bid": "0.36", "best_ask": "0.4"}], "timestamp": "1769384526547", "event_type": "price_change"}}
{"_local_timestamp": "2026-01-25T23:42:07.182268+00:00", "data": {"market": "0x3cb3b76b6a4c3fdc6f933464859626df576eaf3e3e404ead3e75056fd48c04f5", "price_changes": [{"asset_id": "106006396008449636653509336329453630557359114983730727555924443870035053210127", "price": "0.34", "size": "0", "side": "BUY", "hash": "e934efb7c8c9dbf64962f578594ea832f136dd5b", "best_bid": "0.39", "best_ask": "0.44"}, {"asset_id": "50224211346577003424157970845956631119711245094103571068877904015222053747922", "price": "0.66", "size": "0", "side": "SELL", "hash": "cfef8c7db024d7f4d5de356bf05d176717264269", "best_bid": "0.56", "best_ask": "0.61"}], "timestamp": "1769384527114", "event_type": "price_change"}}
{"_local_timestamp": "2026-01-25T23:42:07.242756+00:00", "data": {"market": "0x3cb3b76b6a4c3fdc6f933464859626df576eaf3e3e404ead3e75056fd48c04f5", "price_changes": [{"asset_id": "106006396008449636653509336329453630557359114983730727555924443870035053210127", "price": "0.37", "size": "97", "side": "BUY", "hash": "26449b66f02a41cd4df2e1050283af06f42f93f9", "best_bid": "0.39", "best_ask": "0.44"}, {"asset_id": "50224211346577003424157970845956631119711245094103571068877904015222053747922", "price": "0.63", "size": "97", "side": "SELL", "hash": "f47a33c3c6b2ac2508de6eba002c49f181876bbc", "best_bid": "0.56", "best_ask": "0.61"}], "timestamp": "1769384527174", "event_type": "price_change"}}
{"_local_timestamp": "2026-01-25T23:42:07.268573+00:00", "data": {"market": "0x3cb3b76b6a4c3fdc6f933464859626df576eaf3e3e404ead3e75056fd48c04f5", "price_changes": [{"asset_id": "106006396008449636653509336329453630557359114983730727555924443870035053210127", "price": "0.37", "size": "46", "side": "BUY", "hash": "10a849a60235802dd17cffdb97365d83f205c373", "best_bid": "0.39", "best_ask": "0.44"}, {"asset_id": "50224211346577003424157970845956631119711245094103571068877904015222053747922", "price": "0.63", "size": "46", "side": "SELL", "hash": "1bdacbb777a54675cb62a5e8946cb93250a6d7b8", "best_bid": "0.56", "best_ask": "0.61"}], "timestamp": "1769384527198", "event_type": "price_change"}}
{"_local_timestamp": "2026-01-25T23:42:07.298738+00:00", "data": {"market": "0x3cb3b76b6a4c3fdc6f933464859626df576eaf3e3e404ead3e75056fd48c04f5", "price_changes": [{"asset_id": "106006396008449636653509336329453630557359114983730727555924443870035053210127", "price": "0.38", "size": "75.55", "side": "BUY", "hash": "1ae3229d60a5da419c4c2fb9b58d57e25864275b", "best_bid": "0.39", "best_ask": "0.44"}, {"asset_id": "50224211346577003424157970845956631119711245094103571068877904015222053747922", "price": "0.62", "size": "75.55", "side": "SELL", "hash": "6caa2351d7279a317d6b0e86509cfeec101d43a3", "best_bid": "0.56", "best_ask": "0.61"}], "timestamp": "1769384527227", "event_type": "price_change"}}
{"_local_timestamp": "2026-01-25T23:42:07.412046+00:00", "data": {"market": "0x75700f135fc1aa9106eecad102e82a5e304afa684948c453d9020973a6dacda6", "price_changes": [{"asset_id": "28461223070646267397095106287041417408320289813700921421278280340813748146076", "price": "0.33", "size": "0", "side": "BUY", "hash": "f8642baeb7ef07585d28b974de7c4f7cd26ebdca", "best_bid": "0.36", "best_ask": "0.4"}, {"asset_id": "106943703042015764099709708127099569908287532239730770276583638212344318814024", "price": "0.67", "size": "0", "side": "SELL", "hash": "9cc5bbc100c3dc53a8fdca810d317cd0fe13cf1a", "best_bid": "0.6", "best_ask": "0.64"}], "timestamp": "1769384527349", "event_type": "price_change"}}
{"_local_timestamp": "2026-01-25T23:42:07.884985+00:00", "data": {"market": "0x3cb3b76b6a4c3fdc6f933464859626df576eaf3e3e404ead3e75056fd48c04f5", "price_changes": [{"asset_id": "106006396008449636653509336329453630557359114983730727555924443870035053210127", "price": "0.37", "size": "16", "side": "BUY", "hash": "4f8dfc1c07d3916ea9522dab6e76e4368975301b", "best_bid": "0.39", "best_ask": "0.44"}, {"asset_id": "50224211346577003424157970845956631119711245094103571068877904015222053747922", "price": "0.63", "size": "16", "side": "SELL", "hash": "20dc5a5765ddff6e276513ec5acb358e5528d3e0", "best_bid": "0.56", "best_ask": "0.61"}], "timestamp": "1769384527814", "event_type": "price_change"}}
{"_local_timestamp": "2026-01-25T23:42:07.885781+00:00", "data": {"market": "0x75700f135fc1aa9106eecad102e82a5e304afa684948c453d9020973a6dacda6", "price_changes": [{"asset_id": "106943703042015764099709708127099569908287532239730770276583638212344318814024", "price": "0.58", "size": "24.67", "side": "BUY", "hash": "fca9626ae86535c4a4b64e6c33a2268206d1236d", "best_bid": "0.6", "best_ask": "0.64"}, {"asset_id": "28461223070646267397095106287041417408320289813700921421278280340813748146076", "price": "0.42", "size": "24.67", "side": "SELL", "hash": "c7b3b084ce012b9d173223e0ce1870789c3e12f1", "best_bid": "0.36", "best_ask": "0.4"}], "timestamp": "1769384527814", "event_type": "price_change"}}
{"_local_timestamp": "2026-01-25T23:42:08.532572+00:00", "data": {"market": "0x3cb3b76b6a4c3fdc6f933464859626df576eaf3e3e404ead3e75056fd48c04f5", "price_changes": [{"asset_id": "106006396008449636653509336329453630557359114983730727555924443870035053210127", "price": "0.38", "size": "105.55", "side": "BUY", "hash": "f4082ed48cbc6f19c8ba798d6f0e1184d753c38c", "best_bid": "0.39", "best_ask": "0.44"}, {"asset_id": "50224211346577003424157970845956631119711245094103571068877904015222053747922", "price": "0.62", "size": "105.55", "side": "SELL", "hash": "8fad1a97de38e724126a5d35711cc15a6c2bef48", "best_bid": "0.56", "best_ask": "0.61"}], "timestamp": "1769384528463", "event_type": "price_change"}}
{"_local_timestamp": "2026-01-25T23:42:08.719194+00:00", "data": {"market": "0x75700f135fc1aa9106eecad102e82a5e304afa684948c453d9020973a6dacda6", "price_changes": [{"asset_id": "106943703042015764099709708127099569908287532239730770276583638212344318814024", "price": "0.6", "size": "109", "side": "BUY", "hash": "50c5ce677b27f3255801903ac4d2fda41d8e8afd", "best_bid": "0.6", "best_ask": "0.64"}, {"asset_id": "28461223070646267397095106287041417408320289813700921421278280340813748146076", "price": "0.4", "size": "109", "side": "SELL", "hash": "94df2cf520ac218dc8c8732254457f2a69fe9464", "best_bid": "0.36", "best_ask": "0.4"}], "timestamp": "1769384528655", "event_type": "price_change"}}
{"_local_timestamp": "2026-01-25T23:42:10.252262+00:00", "data": {"market": "0x75700f135fc1aa9106eecad102e82a5e304afa684948c453d9020973a6dacda6", "price_changes": [{"asset_id": "106943703042015764099709708127099569908287532239730770276583638212344318814024", "price": "0.59", "size": "30", "side": "BUY", "hash": "ee6c7284ef9585b41b8c56a2dae84aa3944c4c96", "best_bid": "0.6", "best_ask": "0.64"}, {"asset_id": "28461223070646267397095106287041417408320289813700921421278280340813748146076", "price": "0.41", "size": "30", "side": "SELL", "hash": "c9042ecec5c7a5299fa58f43798f7b895e147eaa", "best_bid": "0.36", "best_ask": "0.4"}], "timestamp": "1769384530173", "event_type": "price_change"}}
{"_local_timestamp": "2026-01-25T23:42:10.261353+00:00", "data": {"market": "0x3cb3b76b6a4c3fdc6f933464859626df576eaf3e3e404ead3e75056fd48c04f5", "price_changes": [{"asset_id": "106006396008449636653509336329453630557359114983730727555924443870035053210127", "price": "0.35", "size": "25", "side": "BUY", "hash": "70de19d886d005857464fcec94905684cebb7c8c", "best_bid": "0.39", "best_ask": "0.44"}, {"asset_id": "50224211346577003424157970845956631119711245094103571068877904015222053747922", "price": "0.65", "size": "25", "side": "SELL", "hash": "aaef213765f9a3e28b7b6243df7552e8835e070f", "best_bid": "0.56", "best_ask": "0.61"}], "timestamp": "1769384530180", "event_type": "price_change"}}
{"_local_timestamp": "2026-01-25T23:42:10.432542+00:00", "data": {"market": "0x3cb3b76b6a4c3fdc6f933464859626df576eaf3e3e404ead3e75056fd48c04f5", "price_changes": [{"asset_id": "106006396008449636653509336329453630557359114983730727555924443870035053210127", "price": "0.35", "size": "5", "side": "BUY", "hash": "3f7ca61fe79cf96e4873a62c3a7d234b0797af67", "best_bid": "0.39", "best_ask": "0.44"}, {"asset_id": "50224211346577003424157970845956631119711245094103571068877904015222053747922", "price": "0.65", "size": "5", "side": "SELL", "hash": "343bc3822fcdfd3ed0d3ae910a2fd18ed0d5f892", "best_bid": "0.56", "best_ask": "0.61"}], "timestamp": "1769384530364", "event_type": "price_change"}}
{"_local_timestamp": "2026-01-25T23:42:10.464242+00:00", "data": {"market": "0x3cb3b76b6a4c3fdc6f933464859626df576eaf3e3e404ead3e75056fd48c04f5", "price_changes": [{"asset_id": "106006396008449636653509336329453630557359114983730727555924443870035053210127", "price": "0.34", "size": "20", "side": "BUY", "hash": "0b6337e7566d82b72f2240405cde6f2f52466939", "best_bid": "0.39", "best_ask": "0.44"}, {"asset_id": "50224211346577003424157970845956631119711245094103571068877904015222053747922", "price": "0.66", "size": "20", "side": "SELL", "hash": "a4b1a16a1a06e1cd1e44d1f499fcfe3d386c2ba7", "best_bid": "0.56", "best_ask": "0.61"}], "timestamp": "1769384530397", "event_type": "price_change"}}
{"_local_timestamp": "2026-01-25T23:42:10.876751+00:00", "data": {"market": "0x3cb3b76b6a4c3fdc6f933464859626df576eaf3e3e404ead3e75056fd48c04f5", "price_changes": [{"asset_id": "106006396008449636653509336329453630557359114983730727555924443870035053210127", "price": "0.4", "size": "100", "side": "BUY", "hash": "011f5b3536e15ab479768507493f152f7872a1c1", "best_bid": "0.4", "best_ask": "0.44"}, {"asset_id": "50224211346577003424157970845956631119711245094103571068877904015222053747922", "price": "0.6", "size": "100", "side": "SELL", "hash": "6d6bf9372eeb8019a674e8332042cc39b31e5dc3", "best_bid": "0.56", "best_ask": "0.6"}], "timestamp": "1769384530801", "event_type": "price_change"}}
{"_local_timestamp": "2026-01-25T23:42:10.878255+00:00", "data": {"market": "0x75700f135fc1aa9106eecad102e82a5e304afa684948c453d9020973a6dacda6", "price_changes": [{"asset_id": "106943703042015764099709708127099569908287532239730770276583638212344318814024", "price": "0.57", "size": "120", "side": "BUY", "hash": "f5ac62031bdad737ab40f9091452e3262448ee30", "best_bid": "0.6", "best_ask": "0.64"}, {"asset_id": "28461223070646267397095106287041417408320289813700921421278280340813748146076", "price": "0.43", "size": "120", "side": "SELL", "hash": "2f5dcc13061d312d2bc538239640f35ae30f1e44", "best_bid": "0.36", "best_ask": "0.4"}], "timestamp": "1769384530801", "event_type": "price_change"}}
{"_local_timestamp": "2026-01-25T23:42:10.908298+00:00", "data": {"market": "0x75700f135fc1aa9106eecad102e82a5e304afa684948c453d9020973a6dacda6", "price_changes": [{"asset_id": "106943703042015764099709708127099569908287532239730770276583638212344318814024", "price": "0.58", "size": "0", "side": "BUY", "hash": "49ae3499166ddc938b97561009086d915f2455da", "best_bid": "0.6", "best_ask": "0.64"}, {"asset_id": "28461223070646267397095106287041417408320289813700921421278280340813748146076", "price": "0.42", "size": "0", "side": "SELL", "hash": "9f776039f063d1dd50ee46d2213698970b1c690a", "best_bid": "0.36", "best_ask": "0.4"}], "timestamp": "1769384530828", "event_type": "price_change"}}
{"_local_timestamp": "2026-01-25T23:42:11.572941+00:00", "data": {"market": "0x3cb3b76b6a4c3fdc6f933464859626df576eaf3e3e404ead3e75056fd48c04f5", "price_changes": [{"asset_id": "106006396008449636653509336329453630557359114983730727555924443870035053210127", "price": "0.38", "size": "75.55", "side": "BUY", "hash": "45b7dd0f8f42270aaff2f309a8fa45191a679002", "best_bid": "0.4", "best_ask": "0.44"}, {"asset_id": "50224211346577003424157970845956631119711245094103571068877904015222053747922", "price": "0.62", "size": "75.55", "side": "SELL", "hash": "2a1e47f97ab70e7404669c38301a2a313e08518c", "best_bid": "0.56", "best_ask": "0.6"}], "timestamp": "1769384531500", "event_type": "price_change"}}
{"_local_timestamp": "2026-01-25T23:42:11.591042+00:00", "data": {"market": "0x3cb3b76b6a4c3fdc6f933464859626df576eaf3e3e404ead3e75056fd48c04f5", "price_changes": [{"asset_id": "106006396008449636653509336329453630557359114983730727555924443870035053210127", "price": "0.38", "size": "18.55", "side": "BUY", "hash": "618e6db6756a0c229915bf920ddf13878c35a0e6", "best_bid": "0.4", "best_ask": "0.44"}, {"asset_id": "50224211346577003424157970845956631119711245094103571068877904015222053747922", "price": "0.62", "size": "18.55", "side": "SELL", "hash": "9adca9a94f263428d26ff3578a247ef616238ffe", "best_bid": "0.56", "best_ask": "0.6"}], "timestamp": "1769384531528", "event_type": "price_change"}}
{"_local_timestamp": "2026-01-25T23:42:11.629074+00:00", "data": {"market": "0x3cb3b76b6a4c3fdc6f933464859626df576eaf3e3e404ead3e75056fd48c04f5", "price_changes": [{"asset_id": "106006396008449636653509336329453630557359114983730727555924443870035053210127", "price": "0.41", "size": "24", "side": "BUY", "hash": "c69ba8590049945e3498405aaa001164ea936a15", "best_bid": "0.41", "best_ask": "0.44"}, {"asset_id": "50224211346577003424157970845956631119711245094103571068877904015222053747922", "price": "0.59", "size": "24", "side": "SELL", "hash": "d314955b836854449820e41c9e9b4b79d4672547", "best_bid": "0.56", "best_ask": "0.59"}], "timestamp": "1769384531554", "event_type": "price_change"}}
{"_local_timestamp": "2026-01-25T23:42:11.629906+00:00", "data": {"market": "0x3cb3b76b6a4c3fdc6f933464859626df576eaf3e3e404ead3e75056fd48c04f5", "price_changes": [{"asset_id": "106006396008449636653509336329453630557359114983730727555924443870035053210127", "price": "0.4", "size": "130", "side": "BUY", "hash": "c8d2451998465113fa2b9cf599ef5565a47b184a", "best_bid": "0.41", "best_ask": "0.44"}, {"asset_id": "50224211346577003424157970845956631119711245094103571068877904015222053747922", "price": "0.6", "size": "130", "side": "SELL", "hash": "f5482db343dc31d1605e019e23e173ca7f7cbf26", "best_bid": "0.56", "best_ask": "0.59"}], "timestamp": "1769384531556", "event_type": "price_change"}}
{"_local_timestamp": "2026-01-25T23:42:12.174884+00:00", "data": {"market": "0x3cb3b76b6a4c3fdc6f933464859626df576eaf3e3e404ead3e75056fd48c04f5", "price_changes": [{"asset_id": "106006396008449636653509336329453630557359114983730727555924443870035053210127", "price": "0.41", "size": "54", "side": "BUY", "hash": "3418b7fafc3d7bd0b719459a5e0a037f506e8d7f", "best_bid": "0.41", "best_ask": "0.44"}, {"asset_id": "50224211346577003424157970845956631119711245094103571068877904015222053747922", "price": "0.59", "size": "54", "side": "SELL", "hash": "638c3753cd692f765cd35ad182579898a3180172", "best_bid": "0.56", "best_ask": "0.59"}], "timestamp": "1769384532078", "event_type": "price_change"}}
{"_local_timestamp": "2026-01-25T23:42:12.179607+00:00", "data": {"market": "0x75700f135fc1aa9106eecad102e82a5e304afa684948c453d9020973a6dacda6", "price_changes": [{"asset_id": "106943703042015764099709708127099569908287532239730770276583638212344318814024", "price": "0.61", "size": "30", "side": "BUY", "hash": "f8530df18b42a9d5a98a05a39260770030145624", "best_bid": "0.61", "best_ask": "0.64"}, {"asset_id": "28461223070646267397095106287041417408320289813700921421278280340813748146076", "price": "0.39", "size": "30", "side": "SELL", "hash": "1e62befa74bc880b096475d5549faa9fcdcf2377", "best_bid": "0.36", "best_ask": "0.39"}], "timestamp": "1769384532079", "event_type": "price_change"}}
{"_local_timestamp": "2026-01-25T23:42:12.217653+00:00", "data": {"market": "0x75700f135fc1aa9106eecad102e82a5e304afa684948c453d9020973a6dacda6", "price_changes": [{"asset_id": "106943703042015764099709708127099569908287532239730770276583638212344318814024", "price": "0.6", "size": "35", "side": "BUY", "hash": "6ea9d28e28c2e12a9425d850841f059661ab81e7", "best_bid": "0.61", "best_ask": "0.64"}, {"asset_id": "28461223070646267397095106287041417408320289813700921421278280340813748146076", "price": "0.4", "size": "35", "side": "SELL", "hash": "72f0311a617c9741771000b4037d57d4d28f2378", "best_bid": "0.36", "best_ask": "0.39"}], "timestamp": "1769384532140", "event_type": "price_change"}}
{"_local_timestamp": "2026-01-25T23:42:12.444389+00:00", "data": {"market": "0x75700f135fc1aa9106eecad102e82a5e304afa684948c453d9020973a6dacda6", "price_changes": [{"asset_id": "106943703042015764099709708127099569908287532239730770276583638212344318814024", "price": "0.59", "size": "0", "side": "BUY", "hash": "9b98b600699dd7077c8104ef26d2768ae4bd952c", "best_bid": "0.61", "best_ask": "0.64"}, {"asset_id": "28461223070646267397095106287041417408320289813700921421278280340813748146076", "price": "0.41", "size": "0", "side": "SELL", "hash": "ac951c76d788b02f7db59878b23d695204ec518b", "best_bid": "0.36", "best_ask": "0.39"}], "timestamp": "1769384532379", "event_type": "price_change"}}
{"_local_timestamp": "2026-01-25T23:42:12.520112+00:00", "data": {"market": "0x3cb3b76b6a4c3fdc6f933464859626df576eaf3e3e404ead3e75056fd48c04f5", "price_changes": [{"asset_id": "106006396008449636653509336329453630557359114983730727555924443870035053210127", "price": "0.4", "size": "100", "side": "BUY", "hash": "3d4d625cd5f65f273467d47f7731b52e74662376", "best_bid": "0.41", "best_ask": "0.44"}, {"asset_id": "50224211346577003424157970845956631119711245094103571068877904015222053747922", "price": "0.6", "size": "100", "side": "SELL", "hash": "0fc766f980dc003f27f4acc226ea62225f5d8265", "best_bid": "0.56", "best_ask": "0.59"}], "timestamp": "1769384532454", "event_type": "price_change"}}
{"_local_timestamp": "2026-01-25T23:42:12.521006+00:00", "data": {"market": "0x75700f135fc1aa9106eecad102e82a5e304afa684948c453d9020973a6dacda6", "price_changes": [{"asset_id": "106943703042015764099709708127099569908287532239730770276583638212344318814024", "price": "0.6", "size": "5", "side": "BUY", "hash": "3025ea3b9c4fc6e7d0ecceaf5896fb2e01f3dec7", "best_bid": "0.61", "best_ask": "0.64"}, {"asset_id": "28461223070646267397095106287041417408320289813700921421278280340813748146076", "price": "0.4", "size": "5", "side": "SELL", "hash": "b3c16a4bb36af6ef87e96cfc8d355289d4847792", "best_bid": "0.36", "best_ask": "0.39"}], "timestamp": "1769384532454", "event_type": "price_change"}}
{"_local_timestamp": "2026-01-25T23:42:12.571861+00:00", "data": {"market": "0x3cb3b76b6a4c3fdc6f933464859626df576eaf3e3e404ead3e75056fd48c04f5", "price_changes": [{"asset_id": "106006396008449636653509336329453630557359114983730727555924443870035053210127", "price": "0.41", "size": "84", "side": "BUY", "hash": "84ab6a960202f79899cf02a802dc94bde8d2929a", "best_bid": "0.41", "best_ask": "0.44"}, {"asset_id": "50224211346577003424157970845956631119711245094103571068877904015222053747922", "price": "0.59", "size": "84", "side": "SELL", "hash": "1cd896b83acd5f03715c71f33b495a3b2194f401", "best_bid": "0.56", "best_ask": "0.59"}], "timestamp": "1769384532502", "event_type": "price_change"}}
{"_local_timestamp": "2026-01-25T23:42:12.572873+00:00", "data": {"market": "0x75700f135fc1aa9106eecad102e82a5e304afa684948c453d9020973a6dacda6", "price_changes": [{"asset_id": "106943703042015764099709708127099569908287532239730770276583638212344318814024", "price": "0.57", "size": "150", "side": "BUY", "hash": "1738b6502532b3ccf84350f0601c783d4d586277", "best_bid": "0.61", "best_ask": "0.64"}, {"asset_id": "28461223070646267397095106287041417408320289813700921421278280340813748146076", "price": "0.43", "size": "150", "side": "SELL", "hash": "a4615ec004c06f1c523178d0c15fbf8316b01472", "best_bid": "0.36", "best_ask": "0.39"}], "timestamp": "1769384532504", "event_type": "price_change"}}
{"_local_timestamp": "2026-01-25T23:42:13.958499+00:00", "data": {"market": "0x3cb3b76b6a4c3fdc6f933464859626df576eaf3e3e404ead3e75056fd48c04f5", "price_changes": [{"asset_id": "106006396008449636653509336329453630557359114983730727555924443870035053210127", "price": "0.39", "size": "0", "side": "BUY", "hash": "a3e32f17a512e058ad69959d0296ec79206ac9bf", "best_bid": "0.41", "best_ask": "0.44"}, {"asset_id": "50224211346577003424157970845956631119711245094103571068877904015222053747922", "price": "0.61", "size": "0", "side": "SELL", "hash": "a7517066ff1c17d6b328342f8dab9b38088ca559", "best_bid": "0.56", "best_ask": "0.59"}], "timestamp": "1769384533888", "event_type": "price_change"}}
{"_local_timestamp": "2026-01-25T23:42:13.959393+00:00", "data": {"market": "0x3cb3b76b6a4c3fdc6f933464859626df576eaf3e3e404ead3e75056fd48c04f5", "price_changes": [{"asset_id": "106006396008449636653509336329453630557359114983730727555924443870035053210127", "price": "0.38", "size": "5.98", "side": "BUY", "hash": "a3e32f17a512e058ad69959d0296ec79206ac9bf", "best_bid": "0.41", "best_ask": "0.44"}, {"asset_id": "50224211346577003424157970845956631119711245094103571068877904015222053747922", "price": "0.62", "size": "5.98", "side": "SELL", "hash": "a7517066ff1c17d6b328342f8dab9b38088ca559", "best_bid": "0.56", "best_ask": "0.59"}], "timestamp": "1769384533888", "event_type": "price_change"}}
{"_local_timestamp": "2026-01-25T23:42:14.375066+00:00", "data": {"market": "0x75700f135fc1aa9106eecad102e82a5e304afa684948c453d9020973a6dacda6", "price_changes": [{"asset_id": "106943703042015764099709708127099569908287532239730770276583638212344318814024", "price": "0.57", "size": "120", "side": "BUY", "hash": "f48deec3e12d8d0c22d1de95e68a7f577a8c377d", "best_bid": "0.61", "best_ask": "0.64"}, {"asset_id": "28461223070646267397095106287041417408320289813700921421278280340813748146076", "price": "0.43", "size": "120", "side": "SELL", "hash": "d774fabb6d7e019059a5257d779574be1254847c", "best_bid": "0.36", "best_ask": "0.39"}], "timestamp": "1769384534298", "event_type": "price_change"}}
{"_local_timestamp": "2026-01-25T23:42:14.612769+00:00", "data": {"market": "0x3cb3b76b6a4c3fdc6f933464859626df576eaf3e3e404ead3e75056fd48c04f5", "price_changes": [{"asset_id": "106006396008449636653509336329453630557359114983730727555924443870035053210127", "price": "0.4", "size": "0", "side": "BUY", "hash": "f5a0866352b049ffb13177d46670f389e442c1b8", "best_bid": "0.41", "best_ask": "0.44"}, {"asset_id": "50224211346577003424157970845956631119711245094103571068877904015222053747922", "price": "0.6", "size": "0", "side": "SELL", "hash": "cab34ff8519e9c8b4264f287ebf4247480eabedd", "best_bid": "0.56", "best_ask": "0.59"}], "timestamp": "1769384534540", "event_type": "price_change"}}
{"_local_timestamp": "2026-01-25T23:42:14.628905+00:00", "data": {"market": "0x75700f135fc1aa9106eecad102e82a5e304afa684948c453d9020973a6dacda6", "price_changes": [{"asset_id": "106943703042015764099709708127099569908287532239730770276583638212344318814024", "price": "0.57", "size": "20", "side": "BUY", "hash": "691f9b71f0c70965094d486ab75593dbbf9373ef", "best_bid": "0.61", "best_ask": "0.64"}, {"asset_id": "28461223070646267397095106287041417408320289813700921421278280340813748146076", "price": "0.43", "size": "20", "side": "SELL", "hash": "5d9704b375901d6720bbcae7a863aee8aeecc32b", "best_bid": "0.36", "best_ask": "0.39"}], "timestamp": "1769384534544", "event_type": "price_change"}}
{"_local_timestamp": "2026-01-25T23:42:14.638414+00:00", "data": {"market": "0x3cb3b76b6a4c3fdc6f933464859626df576eaf3e3e404ead3e75056fd48c04f5", "price_changes": [{"asset_id": "106006396008449636653509336329453630557359114983730727555924443870035053210127", "price": "0.35", "size": "70", "side": "BUY", "hash": "36723dce217065773e7db45d7ada120ccc09830d", "best_bid": "0.41", "best_ask": "0.44"}, {"asset_id": "50224211346577003424157970845956631119711245094103571068877904015222053747922", "price": "0.65", "size": "70", "side": "SELL", "hash": "fe9245f690219d1dacdcb2a4fa7aa7ce427dde3d", "best_bid": "0.56", "best_ask": "0.59"}], "timestamp": "1769384534566", "event_type": "price_change"}}
{"_local_timestamp": "2026-01-25T23:42:14.639218+00:00", "data": {"market": "0x3cb3b76b6a4c3fdc6f933464859626df576eaf3e3e404ead3e75056fd48c04f5", "price_changes": [{"asset_id": "106006396008449636653509336329453630557359114983730727555924443870035053210127", "price": "0.41", "size": "60", "side": "BUY", "hash": "01614b71e9ee9b5dae618bb45f11a51793204d4b", "best_bid": "0.41", "best_ask": "0.44"}, {"asset_id": "50224211346577003424157970845956631119711245094103571068877904015222053747922", "price": "0.59", "size": "60", "side": "SELL", "hash": "09ab8e6e9e26ef4be8a8f001333bcc24db623680", "best_bid": "0.56", "best_ask": "0.59"}], "timestamp": "1769384534570", "event_type": "price_change"}}
{"_local_timestamp": "2026-01-25T23:42:14.668103+00:00", "data": {"market": "0x3cb3b76b6a4c3fdc6f933464859626df576eaf3e3e404ead3e75056fd48c04f5", "price_changes": [{"asset_id": "106006396008449636653509336329453630557359114983730727555924443870035053210127", "price": "0.37", "size": "63", "side": "BUY", "hash": "eb53d40c28e630b8143e068e58c9690e262df3ba", "best_bid": "0.41", "best_ask": "0.44"}, {"asset_id": "50224211346577003424157970845956631119711245094103571068877904015222053747922", "price": "0.63", "size": "63", "side": "SELL", "hash": "be0c19a63a23889946edc9a475769b92ec2deeb7", "best_bid": "0.56", "best_ask": "0.59"}], "timestamp": "1769384534597", "event_type": "price_change"}}
{"_local_timestamp": "2026-01-25T23:42:14.921554+00:00", "data": {"market": "0x3cb3b76b6a4c3fdc6f933464859626df576eaf3e3e404ead3e75056fd48c04f5", "price_changes": [{"asset_id": "106006396008449636653509336329453630557359114983730727555924443870035053210127", "price": "0.41", "size": "30", "side": "BUY", "hash": "110dc6a7227f8cff8b18680f4c02b6573b8283a3", "best_bid": "0.41", "best_ask": "0.44"}, {"asset_id": "50224211346577003424157970845956631119711245094103571068877904015222053747922", "price": "0.59", "size": "30", "side": "SELL", "hash": "b38daa4dd3c72bb8c00f36ec39a5f33a3fb38d35", "best_bid": "0.56", "best_ask": "0.59"}], "timestamp": "1769384534848", "event_type": "price_change"}}
{"_local_timestamp": "2026-01-25T23:42:15.163969+00:00", "data": {"market": "0x3cb3b76b6a4c3fdc6f933464859626df576eaf3e3e404ead3e75056fd48c04f5", "price_changes": [{"asset_id": "106006396008449636653509336329453630557359114983730727555924443870035053210127", "price": "0.34", "size": "120", "side": "BUY", "hash": "d954c91e7bbcd950b4c365357ec9b021be521440", "best_bid": "0.41", "best_ask": "0.44"}, {"asset_id": "50224211346577003424157970845956631119711245094103571068877904015222053747922", "price": "0.66", "size": "120", "side": "SELL", "hash": "cd10d16fc8961a2b6098f3853de3719e21b82bfb", "best_bid": "0.56", "best_ask": "0.59"}], "timestamp": "1769384535084", "event_type": "price_change"}}
{"_local_timestamp": "2026-01-25T23:42:15.190738+00:00", "data": {"market": "0x75700f135fc1aa9106eecad102e82a5e304afa684948c453d9020973a6dacda6", "price_changes": [{"asset_id": "106943703042015764099709708127099569908287532239730770276583638212344318814024", "price": "0.58", "size": "100", "side": "BUY", "hash": "bc683516ff4be3b7d512902e2759d7bbbdcd9c50", "best_bid": "0.61", "best_ask": "0.64"}, {"asset_id": "28461223070646267397095106287041417408320289813700921421278280340813748146076", "price": "0.42", "size": "100", "side": "SELL", "hash": "c485890a9d5677c553c71abf4ffe2a34c3b5eafa", "best_bid": "0.36", "best_ask": "0.39"}], "timestamp": "1769384535111", "event_type": "price_change"}}
{"_local_timestamp": "2026-01-25T23:42:15.359410+00:00", "data": {"market": "0x75700f135fc1aa9106eecad102e82a5e304afa684948c453d9020973a6dacda6", "price_changes": [{"asset_id": "106943703042015764099709708127099569908287532239730770276583638212344318814024", "price": "0.58", "size": "130", "side": "BUY", "hash": "e70f0e67dd87c20443fd0589c9713f66c7022a59", "best_bid": "0.61", "best_ask": "0.64"}, {"asset_id": "28461223070646267397095106287041417408320289813700921421278280340813748146076", "price": "0.42", "size": "130", "side": "SELL", "hash": "6b4b1d35d43a0d2cb97f8ab77d5ced4826ea13b1", "best_bid": "0.36", "best_ask": "0.39"}], "timestamp": "1769384535257", "event_type": "price_change"}}
{"_local_timestamp": "2026-01-25T23:42:15.603552+00:00", "data": {"market": "0x3cb3b76b6a4c3fdc6f933464859626df576eaf3e3e404ead3e75056fd48c04f5", "price_changes": [{"asset_id": "106006396008449636653509336329453630557359114983730727555924443870035053210127", "price": "0.34", "size": "100", "side": "BUY", "hash": "453244a5ab6cdfd4193e405481f90e385537b0f4", "best_bid": "0.41", "best_ask": "0.44"}, {"asset_id": "50224211346577003424157970845956631119711245094103571068877904015222053747922", "price": "0.66", "size": "100", "side": "SELL", "hash": "f3bdfe527a16aa4d5c1c3c3d1b7e394ea055b5d5", "best_bid": "0.56", "best_ask": "0.59"}], "timestamp": "1769384535518", "event_type": "price_change"}}
{"_local_timestamp": "2026-01-25T23:42:15.634426+00:00", "data": {"market": "0x3cb3b76b6a4c3fdc6f933464859626df576eaf3e3e404ead3e75056fd48c04f5", "price_changes": [{"asset_id": "106006396008449636653509336329453630557359114983730727555924443870035053210127", "price": "0.35", "size": "90", "side": "BUY", "hash": "075f37d0ba77205d155b102f852617ec482c76f8", "best_bid": "0.41", "best_ask": "0.44"}, {"asset_id": "50224211346577003424157970845956631119711245094103571068877904015222053747922", "price": "0.65", "size": "90", "side": "SELL", "hash": "9599da7448e6b6c542d749eaa5f5529e9fc5cd50", "best_bid": "0.56", "best_ask": "0.59"}], "timestamp": "1769384535550", "event_type": "price_change"}}
{"_local_timestamp": "2026-01-25T23:42:17.755900+00:00", "data": {"market": "0x75700f135fc1aa9106eecad102e82a5e304afa684948c453d9020973a6dacda6", "price_changes": [{"asset_id": "106943703042015764099709708127099569908287532239730770276583638212344318814024", "price": "0.61", "size": "66.03", "side": "BUY", "hash": "4bb225289260f8c7592bc0db27bb34bf4611b6f4", "best_bid": "0.61", "best_ask": "0.64"}, {"asset_id": "28461223070646267397095106287041417408320289813700921421278280340813748146076", "price": "0.39", "size": "66.03", "side": "SELL", "hash": "3c1d7393ee44059669c1fd58acf73ee6987af082", "best_bid": "0.36", "best_ask": "0.39"}], "timestamp": "1769384537648", "event_type": "price_change"}}
{"_local_timestamp": "2026-01-25T23:42:18.219706+00:00", "data": {"market": "0x3cb3b76b6a4c3fdc6f933464859626df576eaf3e3e404ead3e75056fd48c04f5", "price_changes": [{"asset_id": "106006396008449636653509336329453630557359114983730727555924443870035053210127", "price": "0.38", "size": "35.98", "side": "BUY", "hash": "3a3ab6fb9e7e30dcbd3e0c715c7332e6fa46def6", "best_bid": "0.41", "best_ask": "0.44"}, {"asset_id": "50224211346577003424157970845956631119711245094103571068877904015222053747922", "price": "0.62", "size": "35.98", "side": "SELL", "hash": "f96cb5b9f76647c58164d13bf55b24f2de36891e", "best_bid": "0.56", "best_ask": "0.59"}], "timestamp": "1769384538110", "event_type": "price_change"}}
{"_local_timestamp": "2026-01-25T23:42:18.220531+00:00", "data": {"market": "0x75700f135fc1aa9106eecad102e82a5e304afa684948c453d9020973a6dacda6", "price_changes": [{"asset_id": "106943703042015764099709708127099569908287532239730770276583638212344318814024", "price": "0.59", "size": "30", "side": "BUY", "hash": "55b79dff5d449876485080cddd668cc08dcf4f73", "best_bid": "0.61", "best_ask": "0.64"}, {"asset_id": "28461223070646267397095106287041417408320289813700921421278280340813748146076", "price": "0.41", "size": "30", "side": "SELL", "hash": "47b31e77a5df9eeb2f6d43656d8aff35a7b2a7cd", "best_bid": "0.36", "best_ask": "0.39"}], "timestamp": "1769384538115", "event_type": "price_change"}}
{"_local_timestamp": "2026-01-25T23:42:18.233466+00:00", "data": {"market": "0x75700f135fc1aa9106eecad102e82a5e304afa684948c453d9020973a6dacda6", "price_changes": [{"asset_id": "106943703042015764099709708127099569908287532239730770276583638212344318814024", "price": "0.58", "size": "100", "side": "BUY", "hash": "17ddbbb7e2a2486865d42423e8090ca59f77d96c", "best_bid": "0.61", "best_ask": "0.64"}, {"asset_id": "28461223070646267397095106287041417408320289813700921421278280340813748146076", "price": "0.42", "size": "100", "side": "SELL", "hash": "9f8cceb6f128b79ac82f6cbf96107d5ed475e54d", "best_bid": "0.36", "best_ask": "0.39"}], "timestamp": "1769384538127", "event_type": "price_change"}}
{"_local_timestamp": "2026-01-25T23:42:18.238089+00:00", "data": {"market": "0x3cb3b76b6a4c3fdc6f933464859626df576eaf3e3e404ead3e75056fd48c04f5", "price_changes": [{"asset_id": "106006396008449636653509336329453630557359114983730727555924443870035053210127", "price": "0.37", "size": "16", "side": "BUY", "hash": "f1fa0b450986cc39dc6b5a8295bf5418e4abf9b6", "best_bid": "0.41", "best_ask": "0.44"}, {"asset_id": "50224211346577003424157970845956631119711245094103571068877904015222053747922", "price": "0.63", "size": "16", "side": "SELL", "hash": "81c4ba17f250168d91a8524f7ab12e95fdbb1832", "best_bid": "0.56", "best_ask": "0.59"}], "timestamp": "1769384538136", "event_type": "price_change"}}
{"_local_timestamp": "2026-01-25T23:42:18.269889+00:00", "data": {"market": "0x3cb3b76b6a4c3fdc6f933464859626df576eaf3e3e404ead3e75056fd48c04f5", "price_changes": [{"asset_id": "106006396008449636653509336329453630557359114983730727555924443870035053210127", "price": "0.37", "size": "81", "side": "BUY", "hash": "be645755dd59056dbbde338f8ff20c25da10b1f2", "best_bid": "0.41", "best_ask": "0.44"}, {"asset_id": "50224211346577003424157970845956631119711245094103571068877904015222053747922", "price": "0.63", "size": "81", "side": "SELL", "hash": "a35aa24d2dcce1c929227440fec4b1c27178a831", "best_bid": "0.56", "best_ask": "0.59"}], "timestamp": "1769384538161", "event_type": "price_change"}}
{"_local_timestamp": "2026-01-25T23:42:18.292746+00:00", "data": {"market": "0x75700f135fc1aa9106eecad102e82a5e304afa684948c453d9020973a6dacda6", "price_changes": [{"asset_id": "106943703042015764099709708127099569908287532239730770276583638212344318814024", "price": "0.61", "size": "96.03", "side": "BUY", "hash": "6e29bd0df3104c7421a111b681be24c67fd86fb4", "best_bid": "0.61", "best_ask": "0.64"}, {"asset_id": "28461223070646267397095106287041417408320289813700921421278280340813748146076", "price": "0.39", "size": "96.03", "side": "SELL", "hash": "dc8df619253fcc3c9a63511d49a86181f3b330e4", "best_bid": "0.36", "best_ask": "0.39"}], "timestamp": "1769384538182", "event_type": "price_change"}}
{"_local_timestamp": "2026-01-25T23:42:18.544898+00:00", "data": {"market": "0x3cb3b76b6a4c3fdc6f933464859626df576eaf3e3e404ead3e75056fd48c04f5", "price_changes": [{"asset_id": "106006396008449636653509336329453630557359114983730727555924443870035053210127", "price": "0.41", "size": "0", "side": "BUY", "hash": "329b6dba571224395e453d4b58a5f0bdf18d54c1", "best_bid": "0.38", "best_ask": "0.44"}, {"asset_id": "50224211346577003424157970845956631119711245094103571068877904015222053747922", "price": "0.59", "size": "0", "side": "SELL", "hash": "bea1608b64e321c991446b511e7e86fb2e720742", "best_bid": "0.56", "best_ask": "0.62"}], "timestamp": "1769384538436", "event_type": "price_change"}}
{"_local_timestamp": "2026-01-25T23:42:18.547813+00:00", "data": {"market": "0x75700f135fc1aa9106eecad102e82a5e304afa684948c453d9020973a6dacda6", "price_changes": [{"asset_id": "106943703042015764099709708127099569908287532239730770276583638212344318814024", "price": "0.61", "size": "66.03", "side": "BUY", "hash": "8d35491afc192e676862ec50e7665450b15d304e", "best_bid": "0.61", "best_ask": "0.64"}, {"asset_id": "28461223070646267397095106287041417408320289813700921421278280340813748146076", "price": "0.39", "size": "66.03", "side": "SELL", "hash": "6cbb75d47fe534adf028317abe2e05c8755077ad", "best_bid": "0.36", "best_ask": "0.39"}], "timestamp": "1769384538439", "event_type": "price_change"}}
{"_local_timestamp": "2026-01-25T23:42:18.901055+00:00", "data": {"market": "0x3cb3b76b6a4c3fdc6f933464859626df576eaf3e3e404ead3e75056fd48c04f5", "price_changes": [{"asset_id": "106006396008449636653509336329453630557359114983730727555924443870035053210127", "price": "0.37", "size": "111", "side": "BUY", "hash": "d9481c060522a97359cfd5bd36e52da5b7ff2439", "best_bid": "0.38", "best_ask": "0.44"}, {"asset_id": "50224211346577003424157970845956631119711245094103571068877904015222053747922", "price": "0.63", "size": "111", "side": "SELL", "hash": "5cc54aae8b81fd8e94689ebd8a1bb138ecd461d9", "best_bid": "0.56", "best_ask": "0.62"}], "timestamp": "1769384538787", "event_type": "price_change"}}
{"_local_timestamp": "2026-01-25T23:42:18.980310+00:00", "data": {"market": "0x3cb3b76b6a4c3fdc6f933464859626df576eaf3e3e404ead3e75056fd48c04f5", "price_changes": [{"asset_id": "106006396008449636653509336329453630557359114983730727555924443870035053210127", "price": "0.34", "size": "0", "side": "BUY", "hash": "93fd9c58ed42102ccbecd3243ace214f8724e6c8", "best_bid": "0.38", "best_ask": "0.44"}, {"asset_id": "50224211346577003424157970845956631119711245094103571068877904015222053747922", "price": "0.66", "size": "0", "side": "SELL", "hash": "e5eadda4d143ece2374589534e7b2d3bfe67d20e", "best_bid": "0.56", "best_ask": "0.62"}], "timestamp": "1769384538865", "event_type": "price_change"}}
{"_local_timestamp": "2026-01-25T23:42:18.981109+00:00", "data": {"market": "0x75700f135fc1aa9106eecad102e82a5e304afa684948c453d9020973a6dacda6", "price_changes": [{"asset_id": "106943703042015764099709708127099569908287532239730770276583638212344318814024", "price": "0.58", "size": "0", "side": "BUY", "hash": "ca0219e465a4688385afc9e1b689c401139d9f36", "best_bid": "0.61", "best_ask": "0.64"}, {"asset_id": "28461223070646267397095106287041417408320289813700921421278280340813748146076", "price": "0.42", "size": "0", "side": "SELL", "hash": "e2ad9b3463a471245fc67f5fcf3c4ab4ffdf739c", "best_bid": "0.36", "best_ask": "0.39"}], "timestamp": "1769384538865", "event_type": "price_change"}}
{"_local_timestamp": "2026-01-25T23:42:19.303614+00:00", "data": {"market": "0x3cb3b76b6a4c3fdc6f933464859626df576eaf3e3e404ead3e75056fd48c04f5", "price_changes": [{"asset_id": "106006396008449636653509336329453630557359114983730727555924443870035053210127", "price": "0.35", "size": "25", "side": "BUY", "hash": "18df37a5fee0d33ca4721eeb1a9222c57f8a37ae", "best_bid": "0.38", "best_ask": "0.44"}, {"asset_id": "50224211346577003424157970845956631119711245094103571068877904015222053747922", "price": "0.65", "size": "25", "side": "SELL", "hash": "98b624d5d1f169c528c21dd20078a706179e3c88", "best_bid": "0.56", "best_ask": "0.62"}], "timestamp": "1769384539199", "event_type": "price_change"}}
{"_local_timestamp": "2026-01-25T23:42:19.304483+00:00", "data": {"market": "0x3cb3b76b6a4c3fdc6f933464859626df576eaf3e3e404ead3e75056fd48c04f5", "price_changes": [{"asset_id": "50224211346577003424157970845956631119711245094103571068877904015222053747922", "price": "0.56", "size": "0", "side": "BUY", "hash": "dc0d6ae51523881402cfc83f412f13b7936ba0d9", "best_bid": "0.55", "best_ask": "0.62"}, {"asset_id": "106006396008449636653509336329453630557359114983730727555924443870035053210127", "price": "0.44", "size": "0", "side": "SELL", "hash": "e5d570c107941ad76a0a7c0d7eb4332652720485", "best_bid": "0.38", "best_ask": "0.45"}], "timestamp": "1769384539199", "event_type": "price_change"}}
{"_local_timestamp": "2026-01-25T23:42:19.305244+00:00", "data": {"market": "0x3cb3b76b6a4c3fdc6f933464859626df576eaf3e3e404ead3e75056fd48c04f5", "price_changes": [{"asset_id": "50224211346577003424157970845956631119711245094103571068877904015222053747922", "price": "0.55", "size": "2.25", "side": "BUY", "hash": "dc0d6ae51523881402cfc83f412f13b7936ba0d9", "best_bid": "0.55", "best_ask": "0.62"}, {"asset_id": "106006396008449636653509336329453630557359114983730727555924443870035053210127", "price": "0.45", "size": "2.25", "side": "SELL", "hash": "e5d570c107941ad76a0a7c0d7eb4332652720485", "best_bid": "0.38", "best_ask": "0.45"}], "timestamp": "1769384539199", "event_type": "price_change"}}
{"_local_timestamp": "2026-01-25T23:42:19.332783+00:00", "data": {"market": "0x3cb3b76b6a4c3fdc6f933464859626df576eaf3e3e404ead3e75056fd48c04f5", "price_changes": [{"asset_id": "106006396008449636653509336329453630557359114983730727555924443870035053210127", "price": "0.37", "size": "46", "side": "BUY", "hash": "161207ec7fd43d657b0bf57561f550e5782ac8e6", "best_bid": "0.38", "best_ask": "0.45"}, {"asset_id": "50224211346577003424157970845956631119711245094103571068877904015222053747922", "price": "0.63", "size": "46", "side": "SELL", "hash": "018cee3ffed6e8e354aa3456126aba464dc69a6e", "best_bid": "0.55", "best_ask": "0.62"}], "timestamp": "1769384539225", "event_type": "price_change"}}
{"_local_timestamp": "2026-01-25T23:42:19.367390+00:00", "data": {"market": "0x3cb3b76b6a4c3fdc6f933464859626df576eaf3e3e404ead3e75056fd48c04f5", "price_changes": [{"asset_id": "106006396008449636653509336329453630557359114983730727555924443870035053210127", "price": "0.35", "size": "125", "side": "BUY", "hash": "bd5721439a5e5abd20b2feeaa0c41f50a483fccd", "best_bid": "0.38", "best_ask": "0.45"}, {"asset_id": "50224211346577003424157970845956631119711245094103571068877904015222053747922", "price": "0.65", "size": "125", "side": "SELL", "hash": "4002c50fec6ee0645b8f72e7c85be0b8af6bb351", "best_bid": "0.55", "best_ask": "0.62"}], "timestamp": "1769384539252", "event_type": "price_change"}}
{"_local_timestamp": "2026-01-25T23:42:19.456068+00:00", "data": {"market": "0x75700f135fc1aa9106eecad102e82a5e304afa684948c453d9020973a6dacda6", "price_changes": [{"asset_id": "106943703042015764099709708127099569908287532239730770276583638212344318814024", "price": "0.56", "size": "22", "side": "BUY", "hash": "0a8db8c867d6bbb8e8ae28aa916060c479e28128", "best_bid": "0.61", "best_ask": "0.64"}, {"asset_id": "28461223070646267397095106287041417408320289813700921421278280340813748146076", "price": "0.44", "size": "22", "side": "SELL", "hash": "e51e227ff5aa22cfc4377b47ad00c3fd91674ba3", "best_bid": "0.36", "best_ask": "0.39"}], "timestamp": "1769384539355", "event_type": "price_change"}}
{"_local_timestamp": "2026-01-25T23:42:19.456943+00:00", "data": {"market": "0xc98360464eaf681200432e9d5f4e6af1717b26415587fc0729001529e9244bf0", "price_changes": [{"asset_id": "42965909532341023203156107784861847526426548942642864755763404570972223043030", "price": "0.901", "size": "0", "side": "BUY", "hash": "a5f028a5d74dec3f4669ac6e483e3cafad911b3b", "best_bid": "0.995", "best_ask": "0.999"}, {"asset_id": "106154843522663118346636909846921460990194186879780202123781120445178139681772", "price": "0.099", "size": "0", "side": "SELL", "hash": "46ea84637bc6f9391917914799a752a9783ad58a", "best_bid": "0.001", "best_ask": "0.005"}], "timestamp": "1769384539355", "event_type": "price_change"}}
{"_local_timestamp": "2026-01-25T23:42:19.459226+00:00", "data": {"market": "0xf81a1470a1df60b339e19ef08f4f50f6b1e16b72abc5ada0abeba3176f6ebf39", "price_changes": [{"asset_id": "107613004969601337516553589346677804481909532422183375899340300747909195154490", "price": "0.891", "size": "0", "side": "BUY", "hash": "4557e12f455f577df7ac85ae8b5c6726526ff208", "best_bid": "0.996", "best_ask": "0.999"}, {"asset_id": "31066355360623088659431128901874672236359160986840206439049282354337176000405", "price": "0.109", "size": "0", "side": "SELL", "hash": "ec797ca5fb487b2d9023aefcd13b877bea912fb8", "best_bid": "0.001", "best_ask": "0.004"}], "timestamp": "1769384539355", "event_type": "price_change"}}
{"_local_timestamp": "2026-01-25T23:42:19.460172+00:00", "data": {"market": "0x03c6817aa84a2b980d54fdd383dd530797ba4b6c27e48591e682cfdbf7449754", "price_changes": [{"asset_id": "81177944114764661253164662145140713030265691622775789519288758937685378375453", "price": "0.892", "size": "0", "side": "BUY", "hash": "baffd74b04f6928bc74c852c0230e55785afbcba", "best_bid": "0.956", "best_ask": "0.992"}, {"asset_id": "80150595742123714617427381010000002467992506994314405336410604686924790622727", "price": "0.108", "size": "0", "side": "SELL", "hash": "5af158d54e6dfe6bcc90d40e6a714c4348762884", "best_bid": "0.008", "best_ask": "0.044"}], "timestamp": "1769384539355", "event_type": "price_change"}}
{"_local_timestamp": "2026-01-25T23:42:19.468255+00:00", "data": {"market": "0x8b9ba80fb00ffd3ea3d259e0e3d64c2bc057e2d258dbb416138082721491de1f", "price_changes": [{"asset_id": "58714825001137751155185117146321345902961648511702872797387135565669201406384", "price": "0.891", "size": "0", "side": "BUY", "hash": "c3596d95db2f1f96d34dc645e331b91274a0017b", "best_bid": "0.929", "best_ask": "0.978"}, {"asset_id": "95471394592044775311259204363647835057798671562193368798960379123943071173821", "price": "0.109", "size": "0", "side": "SELL", "hash": "41a645d6120e7e9e347521f544da80bc77d211be", "best_bid": "0.022", "best_ask": "0.071"}], "timestamp": "1769384539355", "event_type": "price_change"}}
{"_local_timestamp": "2026-01-25T23:42:19.492435+00:00", "data": {"market": "0x75700f135fc1aa9106eecad102e82a5e304afa684948c453d9020973a6dacda6", "price_changes": [{"asset_id": "106943703042015764099709708127099569908287532239730770276583638212344318814024", "price": "0.49", "size": "20", "side": "BUY", "hash": "71c1a8dc282d1f49c750cb73a1719e3cee5d42d8", "best_bid": "0.61", "best_ask": "0.64"}, {"asset_id": "28461223070646267397095106287041417408320289813700921421278280340813748146076", "price": "0.51", "size": "20", "side": "SELL", "hash": "97480960426a1adbe137d70b4240ca537ec72013", "best_bid": "0.36", "best_ask": "0.39"}], "timestamp": "1769384539386", "event_type": "price_change"}}
{"_local_timestamp": "2026-01-25T23:42:19.493441+00:00", "data": {"market": "0xf81a1470a1df60b339e19ef08f4f50f6b1e16b72abc5ada0abeba3176f6ebf39", "price_changes": [{"asset_id": "107613004969601337516553589346677804481909532422183375899340300747909195154490", "price": "0.724", "size": "20", "side": "BUY", "hash": "f05636e851cbf076a0a45d9877dcabcf9aed11fa", "best_bid": "0.996", "best_ask": "0.999"}, {"asset_id": "31066355360623088659431128901874672236359160986840206439049282354337176000405", "price": "0.276", "size": "20", "side": "SELL", "hash": "a9c31fd6121bdb1433e920d4a886202809e6155a", "best_bid": "0.001", "best_ask": "0.004"}], "timestamp": "1769384539386", "event_type": "price_change"}}
{"_local_timestamp": "2026-01-25T23:42:19.494259+00:00", "data": {"market": "0x03c6817aa84a2b980d54fdd383dd530797ba4b6c27e48591e682cfdbf7449754", "price_changes": [{"asset_id": "81177944114764661253164662145140713030265691622775789519288758937685378375453", "price": "0.301", "size": "26", "side": "BUY", "hash": "0d3d7c4e032aeebb8f86e555468a929746447392", "best_bid": "0.956", "best_ask": "0.992"}, {"asset_id": "80150595742123714617427381010000002467992506994314405336410604686924790622727", "price": "0.699", "size": "26", "side": "SELL", "hash": "20160b3a0b5f626a1f4291d9d87f54518997c76c", "best_bid": "0.008", "best_ask": "0.044"}], "timestamp": "1769384539386", "event_type": "price_change"}}
{"_local_timestamp": "2026-01-25T23:42:19.499177+00:00", "data": {"market": "0xc98360464eaf681200432e9d5f4e6af1717b26415587fc0729001529e9244bf0", "price_changes": [{"asset_id": "42965909532341023203156107784861847526426548942642864755763404570972223043030", "price": "0.824", "size": "20", "side": "BUY", "hash": "0255dee975bb4ac5aaf34823f04d4d27998ce8eb", "best_bid": "0.995", "best_ask": "0.999"}, {"asset_id": "106154843522663118346636909846921460990194186879780202123781120445178139681772", "price": "0.176", "size": "20", "side": "SELL", "hash": "0de72162497029f1f2fc319bb68316fe34e685ec", "best_bid": "0.001", "best_ask": "0.005"}], "timestamp": "1769384539386", "event_type": "price_change"}}
{"_local_timestamp": "2026-01-25T23:42:19.500049+00:00", "data": {"market": "0x8b9ba80fb00ffd3ea3d259e0e3d64c2bc057e2d258dbb416138082721491de1f", "price_changes": [{"asset_id": "58714825001137751155185117146321345902961648511702872797387135565669201406384", "price": "0.85", "size": "29.09", "side": "BUY", "hash": "49cfd82d4525a35a787d590a5a5a368b37a6e2cb", "best_bid": "0.929", "best_ask": "0.978"}, {"asset_id": "95471394592044775311259204363647835057798671562193368798960379123943071173821", "price": "0.15", "size": "29.09", "side": "SELL", "hash": "c54cd899ae87ad59af02dbf4fb62f18d44293ddb", "best_bid": "0.022", "best_ask": "0.071"}], "timestamp": "1769384539386", "event_type": "price_change"}}
{"_local_timestamp": "2026-01-25T23:42:19.572583+00:00", "data": {"market": "0x3cb3b76b6a4c3fdc6f933464859626df576eaf3e3e404ead3e75056fd48c04f5", "price_changes": [{"asset_id": "106006396008449636653509336329453630557359114983730727555924443870035053210127", "price": "0.38", "size": "135.98", "side": "BUY", "hash": "820782525480f0d9baa608d937a862532cd2bdea", "best_bid": "0.38", "best_ask": "0.45"}, {"asset_id": "50224211346577003424157970845956631119711245094103571068877904015222053747922", "price": "0.62", "size": "135.98", "side": "SELL", "hash": "ee835255637e9aa28b412945a95bd1d16245a5fc", "best_bid": "0.55", "best_ask": "0.62"}], "timestamp": "1769384539463", "event_type": "price_change"}}
{"_local_timestamp": "2026-01-25T23:42:19.573580+00:00", "data": {"market": "0x75700f135fc1aa9106eecad102e82a5e304afa684948c453d9020973a6dacda6", "price_changes": [{"asset_id": "106943703042015764099709708127099569908287532239730770276583638212344318814024", "price": "0.57", "size": "120", "side": "BUY", "hash": "1183a63ee0893f5e0bc8f7232eec540989a5bee0", "best_bid": "0.61", "best_ask": "0.64"}, {"asset_id": "28461223070646267397095106287041417408320289813700921421278280340813748146076", "price": "0.43", "size": "120", "side": "SELL", "hash": "0bdd94284a484cc8c33bb3179a3159a93c8f9d4f", "best_bid": "0.36", "best_ask": "0.39"}], "timestamp": "1769384539468", "event_type": "price_change"}}
{"_local_timestamp": "2026-01-25T23:42:19.934428+00:00", "data": {"market": "0x3cb3b76b6a4c3fdc6f933464859626df576eaf3e3e404ead3e75056fd48c04f5", "price_changes": [{"asset_id": "106006396008449636653509336329453630557359114983730727555924443870035053210127", "price": "0.37", "size": "16", "side": "BUY", "hash": "26e3e1146b83ce7ba7ef835e3cfadd7e61ab3389", "best_bid": "0.38", "best_ask": "0.45"}, {"asset_id": "50224211346577003424157970845956631119711245094103571068877904015222053747922", "price": "0.63", "size": "16", "side": "SELL", "hash": "8cc4f1db2ce7a08b48fabfbdc81441515ee25a2f", "best_bid": "0.55", "best_ask": "0.62"}], "timestamp": "1769384539813", "event_type": "price_change"}}
{"_local_timestamp": "2026-01-25T23:42:19.936248+00:00", "data": {"market": "0x75700f135fc1aa9106eecad102e82a5e304afa684948c453d9020973a6dacda6", "price_changes": [{"asset_id": "106943703042015764099709708127099569908287532239730770276583638212344318814024", "price": "0.61", "size": "36.03", "side": "BUY", "hash": "6fa2b703b43a34923b8a44a1564e447dc03709a0", "best_bid": "0.61", "best_ask": "0.64"}, {"asset_id": "28461223070646267397095106287041417408320289813700921421278280340813748146076", "price": "0.39", "size": "36.03", "side": "SELL", "hash": "de327bccf4160a87c0972e44c4ce173098fb892f", "best_bid": "0.36", "best_ask": "0.39"}], "timestamp": "1769384539813", "event_type": "price_change"}}
{"_local_timestamp": "2026-01-25T23:42:19.987315+00:00", "data": {"market": "0x75700f135fc1aa9106eecad102e82a5e304afa684948c453d9020973a6dacda6", "price_changes": [{"asset_id": "106943703042015764099709708127099569908287532239730770276583638212344318814024", "price": "0.55", "size": "86", "side": "BUY", "hash": "e868169bd649d3dc8110ba752be4f767cc812b53", "best_bid": "0.61", "best_ask": "0.64"}, {"asset_id": "28461223070646267397095106287041417408320289813700921421278280340813748146076", "price": "0.45", "size": "86", "side": "SELL", "hash": "cb363e76551d7d33566d042db5de5c9828a28762", "best_bid": "0.36", "best_ask": "0.39"}], "timestamp": "1769384539868", "event_type": "price_change"}}
{"_local_timestamp": "2026-01-25T23:42:20.021018+00:00", "data": {"market": "0x3cb3b76b6a4c3fdc6f933464859626df576eaf3e3e404ead3e75056fd48c04f5", "price_changes": [{"asset_id": "106006396008449636653509336329453630557359114983730727555924443870035053210127", "price": "0.35", "size": "155", "side": "BUY", "hash": "a672e7794598b6b810d69c83db1dc1628deac72d", "best_bid": "0.38", "best_ask": "0.45"}, {"asset_id": "50224211346577003424157970845956631119711245094103571068877904015222053747922", "price": "0.65", "size": "155", "side": "SELL", "hash": "c35af8edf618c018abe0855385af69fad40b0768", "best_bid": "0.55", "best_ask": "0.62"}], "timestamp": "1769384539897", "event_type": "price_change"}}
{"_local_timestamp": "2026-01-25T23:42:20.346477+00:00", "data": {"market": "0x3cb3b76b6a4c3fdc6f933464859626df576eaf3e3e404ead3e75056fd48c04f5", "price_changes": [{"asset_id": "50224211346577003424157970845956631119711245094103571068877904015222053747922", "price": "0.52", "size": "50", "side": "BUY", "hash": "5ea74dfb5ebbd86ff0952cba0aba05d533c42fa2", "best_bid": "0.55", "best_ask": "0.62"}, {"asset_id": "106006396008449636653509336329453630557359114983730727555924443870035053210127", "price": "0.48", "size": "50", "side": "SELL", "hash": "ae59e8f2c4354dded5454529f6cf8c9a976c7774", "best_bid": "0.38", "best_ask": "0.45"}], "timestamp": "1769384540222", "event_type": "price_change"}}
{"_local_timestamp": "2026-01-25T23:42:20.347353+00:00", "data": {"market": "0x3cb3b76b6a4c3fdc6f933464859626df576eaf3e3e404ead3e75056fd48c04f5", "price_changes": [{"asset_id": "106006396008449636653509336329453630557359114983730727555924443870035053210127", "price": "0.39", "size": "75.86", "side": "BUY", "hash": "7b223ff54c87ea4714f3cec1c525eedb2535f48d", "best_bid": "0.39", "best_ask": "0.45"}, {"asset_id": "50224211346577003424157970845956631119711245094103571068877904015222053747922", "price": "0.61", "size": "75.86", "side": "SELL", "hash": "b4b510857eccd9a03e996ff6a464fa53f5c091c3", "best_bid": "0.55", "best_ask": "0.61"}], "timestamp": "1769384540222", "event_type": "price_change"}}
{"_local_timestamp": "2026-01-25T23:42:20.348137+00:00", "data": {"market": "0x3cb3b76b6a4c3fdc6f933464859626df576eaf3e3e404ead3e75056fd48c04f5", "price_changes": [{"asset_id": "106006396008449636653509336329453630557359114983730727555924443870035053210127", "price": "0.4", "size": "10.72", "side": "BUY", "hash": "65f24fff84cd4512e571ab02d3e8fde4d3173900", "best_bid": "0.4", "best_ask": "0.45"}, {"asset_id": "50224211346577003424157970845956631119711245094103571068877904015222053747922", "price": "0.6", "size": "10.72", "side": "SELL", "hash": "eb966fea2e517c0d9980645ae8f331174e36bf4c", "best_bid": "0.55", "best_ask": "0.6"}], "timestamp": "1769384540223", "event_type": "price_change"}}
{"_local_timestamp": "2026-01-25T23:42:20.442982+00:00", "data": {"market": "0x3cb3b76b6a4c3fdc6f933464859626df576eaf3e3e404ead3e75056fd48c04f5", "price_changes": [{"asset_id": "106006396008449636653509336329453630557359114983730727555924443870035053210127", "price": "0.35", "size": "55", "side": "BUY", "hash": "7e6c7faa0fcef49a5178b5f3ff9981de08715089", "best_bid": "0.4", "best_ask": "0.45"}, {"asset_id": "50224211346577003424157970845956631119711245094103571068877904015222053747922", "price": "0.65", "size": "55", "side": "SELL", "hash": "8f98d5f4a975edc13274a22ecf0478c56869a119", "best_bid": "0.55", "best_ask": "0.6"}], "timestamp": "1769384540326", "event_type": "price_change"}}
{"_local_timestamp": "2026-01-25T23:42:20.475612+00:00", "data": {"market": "0x3cb3b76b6a4c3fdc6f933464859626df576eaf3e3e404ead3e75056fd48c04f5", "price_changes": [{"asset_id": "106006396008449636653509336329453630557359114983730727555924443870035053210127", "price": "0.4", "size": "60.72", "side": "BUY", "hash": "8ac4e124a491b0abd99da8e4f064cc2c03cc8d12", "best_bid": "0.4", "best_ask": "0.45"}, {"asset_id": "50224211346577003424157970845956631119711245094103571068877904015222053747922", "price": "0.6", "size": "60.72", "side": "SELL", "hash": "30f661bece9a6e1a885729105eb032744e529b9f", "best_bid": "0.55", "best_ask": "0.6"}], "timestamp": "1769384540353", "event_type": "price_change"}}
{"_local_timestamp": "2026-01-25T23:42:20.540601+00:00", "data": {"market": "0x8b9ba80fb00ffd3ea3d259e0e3d64c2bc057e2d258dbb416138082721491de1f", "price_changes": [{"asset_id": "58714825001137751155185117146321345902961648511702872797387135565669201406384", "price": "0.85", "size": "9.09", "side": "BUY", "hash": "5999f8a6eafc2afd6cdb44f15172ef1008682317", "best_bid": "0.929", "best_ask": "0.978"}, {"asset_id": "95471394592044775311259204363647835057798671562193368798960379123943071173821", "price": "0.15", "size": "9.09", "side": "SELL", "hash": "7e11da5a16b295b23ef513a18d86775e43cd686e", "best_bid": "0.022", "best_ask": "0.071"}], "timestamp": "1769384540419", "event_type": "price_change"}}
{"_local_timestamp": "2026-01-25T23:42:20.571741+00:00", "data": {"market": "0x8b9ba80fb00ffd3ea3d259e0e3d64c2bc057e2d258dbb416138082721491de1f", "price_changes": [{"asset_id": "58714825001137751155185117146321345902961648511702872797387135565669201406384", "price": "0.851", "size": "20", "side": "BUY", "hash": "08396e4f99573b3a94421a11810b2fd9dec2fe04", "best_bid": "0.929", "best_ask": "0.978"}, {"asset_id": "95471394592044775311259204363647835057798671562193368798960379123943071173821", "price": "0.149", "size": "20", "side": "SELL", "hash": "b9509f7335df25b39559c616e43d4fa3946e864c", "best_bid": "0.022", "best_ask": "0.071"}], "timestamp": "1769384540448", "event_type": "price_change"}}
{"_local_timestamp": "2026-01-25T23:42:21.539954+00:00", "data": {"market": "0x75700f135fc1aa9106eecad102e82a5e304afa684948c453d9020973a6dacda6", "price_changes": [{"asset_id": "106943703042015764099709708127099569908287532239730770276583638212344318814024", "price": "0.61", "size": "0", "side": "BUY", "hash": "0cf1d72ffefebc8addb4556a5e386f19bd3b166a", "best_bid": "0.6", "best_ask": "0.64"}, {"asset_id": "28461223070646267397095106287041417408320289813700921421278280340813748146076", "price": "0.39", "size": "0", "side": "SELL", "hash": "691d7513dfbd8f760dd044b9a77acc912cf7c322", "best_bid": "0.36", "best_ask": "0.4"}], "timestamp": "1769384541414", "event_type": "price_change"}}
{"_local_timestamp": "2026-01-25T23:42:21.562799+00:00", "data": {"market": "0x75700f135fc1aa9106eecad102e82a5e304afa684948c453d9020973a6dacda6", "price_changes": [{"asset_id": "28461223070646267397095106287041417408320289813700921421278280340813748146076", "price": "0.4", "size": "50", "side": "SELL", "hash": "6daa8429c231cf65e8d7b11dbf92377da48488fd", "best_bid": "0.36", "best_ask": "0.4"}, {"asset_id": "106943703042015764099709708127099569908287532239730770276583638212344318814024", "price": "0.6", "size": "50", "side": "BUY", "hash": "fa3678747f893398f7d14281d385ea71367622cb", "best_bid": "0.6", "best_ask": "0.64"}], "timestamp": "1769384541440", "event_type": "price_change"}}
{"_local_timestamp": "2026-01-25T23:42:21.990292+00:00", "data": {"market": "0x75700f135fc1aa9106eecad102e82a5e304afa684948c453d9020973a6dacda6", "price_changes": [{"asset_id": "106943703042015764099709708127099569908287532239730770276583638212344318814024", "price": "0.55", "size": "56", "side": "BUY", "hash": "1d71b64c3ce37ce9bcfd9cede633430eb8779192", "best_bid": "0.6", "best_ask": "0.64"}, {"asset_id": "28461223070646267397095106287041417408320289813700921421278280340813748146076", "price": "0.45", "size": "56", "side": "SELL", "hash": "7244ae6b396bfea5c4adc92daa0b15ac8473dfb9", "best_bid": "0.36", "best_ask": "0.4"}], "timestamp": "1769384541859", "event_type": "price_change"}}
{"_local_timestamp": "2026-01-25T23:42:21.991251+00:00", "data": {"market": "0x3cb3b76b6a4c3fdc6f933464859626df576eaf3e3e404ead3e75056fd48c04f5", "price_changes": [{"asset_id": "106006396008449636653509336329453630557359114983730727555924443870035053210127", "price": "0.35", "size": "25", "side": "BUY", "hash": "ce9c1192a9c44a906f22880c1a19131984f41241", "best_bid": "0.4", "best_ask": "0.45"}, {"asset_id": "50224211346577003424157970845956631119711245094103571068877904015222053747922", "price": "0.65", "size": "25", "side": "SELL", "hash": "c8db73da71272636aa18c8e0f5a77368d108c964", "best_bid": "0.55", "best_ask": "0.6"}], "timestamp": "1769384541859", "event_type": "price_change"}}
{"_local_timestamp": "2026-01-25T23:42:22.038716+00:00", "data": {"market": "0x3cb3b76b6a4c3fdc6f933464859626df576eaf3e3e404ead3e75056fd48c04f5", "price_changes": [{"asset_id": "106006396008449636653509336329453630557359114983730727555924443870035053210127", "price": "0.35", "size": "5", "side": "BUY", "hash": "30a75c59e4bcd2977832d2d272391776094a65b4", "best_bid": "0.4", "best_ask": "0.45"}, {"asset_id": "50224211346577003424157970845956631119711245094103571068877904015222053747922", "price": "0.65", "size": "5", "side": "SELL", "hash": "8cff581c9c402801a4a8eed66d052dceba2caa52", "best_bid": "0.55", "best_ask": "0.6"}], "timestamp": "1769384541920", "event_type": "price_change"}}
{"_local_timestamp": "2026-01-25T23:42:22.055582+00:00", "data": {"market": "0x3cb3b76b6a4c3fdc6f933464859626df576eaf3e3e404ead3e75056fd48c04f5", "price_changes": [{"asset_id": "106006396008449636653509336329453630557359114983730727555924443870035053210127", "price": "0.4", "size": "90.72", "side": "BUY", "hash": "ad0cc5df0b6ff1423c1581244d62b53ca3d9a0eb", "best_bid": "0.4", "best_ask": "0.45"}, {"asset_id": "50224211346577003424157970845956631119711245094103571068877904015222053747922", "price": "0.6", "size": "90.72", "side": "SELL", "hash": "9fcd015d54c61a564c5bd32cd02db7f9b8131279", "best_bid": "0.55", "best_ask": "0.6"}], "timestamp": "1769384541934", "event_type": "price_change"}}
{"_local_timestamp": "2026-01-25T23:42:22.074379+00:00", "data": {"market": "0x75700f135fc1aa9106eecad102e82a5e304afa684948c453d9020973a6dacda6", "price_changes": [{"asset_id": "106943703042015764099709708127099569908287532239730770276583638212344318814024", "price": "0.57", "size": "150", "side": "BUY", "hash": "01f90538da0aa36639537b12f8f981d0404d3165", "best_bid": "0.6", "best_ask": "0.64"}, {"asset_id": "28461223070646267397095106287041417408320289813700921421278280340813748146076", "price": "0.43", "size": "150", "side": "SELL", "hash": "285c93f91a6adc0144a8bc13dd000b019b8025b1", "best_bid": "0.36", "best_ask": "0.4"}], "timestamp": "1769384541942", "event_type": "price_change"}}
{"_local_timestamp": "2026-01-25T23:42:22.075431+00:00", "data": {"market": "0x3cb3b76b6a4c3fdc6f933464859626df576eaf3e3e404ead3e75056fd48c04f5", "price_changes": [{"asset_id": "106006396008449636653509336329453630557359114983730727555924443870035053210127", "price": "0.34", "size": "20", "side": "BUY", "hash": "9832189c44340fbd4a7997dcfe8e10555b4cc00f", "best_bid": "0.4", "best_ask": "0.45"}, {"asset_id": "50224211346577003424157970845956631119711245094103571068877904015222053747922", "price": "0.66", "size": "20", "side": "SELL", "hash": "1c8f012a05db1076aca8f2d79baab496df0be29a", "best_bid": "0.55", "best_ask": "0.6"}], "timestamp": "1769384541947", "event_type": "price_change"}}
{"_local_timestamp": "2026-01-25T23:42:22.324136+00:00", "data": {"market": "0x75700f135fc1aa9106eecad102e82a5e304afa684948c453d9020973a6dacda6", "price_changes": [{"asset_id": "106943703042015764099709708127099569908287532239730770276583638212344318814024", "price": "0.58", "size": "36.03", "side": "BUY", "hash": "20ec5b7174d8b1c946532dd27f7215ae630148dd", "best_bid": "0.6", "best_ask": "0.64"}, {"asset_id": "28461223070646267397095106287041417408320289813700921421278280340813748146076", "price": "0.42", "size": "36.03", "side": "SELL", "hash": "838fbcac62baa837b29ec3ca4cc9dc94da2f7f06", "best_bid": "0.36", "best_ask": "0.4"}], "timestamp": "1769384542193", "event_type": "price_change"}}
{"_local_timestamp": "2026-01-25T23:42:23.395931+00:00", "data": {"market": "0x75700f135fc1aa9106eecad102e82a5e304afa684948c453d9020973a6dacda6", "price_changes": [{"asset_id": "106943703042015764099709708127099569908287532239730770276583638212344318814024", "price": "0.57", "size": "50", "side": "BUY", "hash": "959cf43dc33086f0d513712d40efb1ebec68f23a", "best_bid": "0.6", "best_ask": "0.64"}, {"asset_id": "28461223070646267397095106287041417408320289813700921421278280340813748146076", "price": "0.43", "size": "50", "side": "SELL", "hash": "9c6cc6a9ac2bcf70c43ed04c49f918437d1be648", "best_bid": "0.36", "best_ask": "0.4"}], "timestamp": "1769384543255", "event_type": "price_change"}}
{"_local_timestamp": "2026-01-25T23:42:23.397019+00:00", "data": {"market": "0x3cb3b76b6a4c3fdc6f933464859626df576eaf3e3e404ead3e75056fd48c04f5", "price_changes": [{"asset_id": "106006396008449636653509336329453630557359114983730727555924443870035053210127", "price": "0.38", "size": "35.98", "side": "BUY", "hash": "abcded4bf85065edb572a51cc3dc36a1903ea6a9", "best_bid": "0.4", "best_ask": "0.45"}, {"asset_id": "50224211346577003424157970845956631119711245094103571068877904015222053747922", "price": "0.62", "size": "35.98", "side": "SELL", "hash": "8534929ee131cc9f65a579dc84e67850b813fcab", "best_bid": "0.55", "best_ask": "0.6"}], "timestamp": "1769384543257", "event_type": "price_change"}}
{"_local_timestamp": "2026-01-25T23:42:23.828223+00:00", "data": {"market": "0x3cb3b76b6a4c3fdc6f933464859626df576eaf3e3e404ead3e75056fd48c04f5", "price_changes": [{"asset_id": "106006396008449636653509336329453630557359114983730727555924443870035053210127", "price": "0.41", "size": "100", "side": "BUY", "hash": "a3dd7bbda83b910fe0cda549f8ad32679e169f1a", "best_bid": "0.41", "best_ask": "0.45"}, {"asset_id": "50224211346577003424157970845956631119711245094103571068877904015222053747922", "price": "0.59", "size": "100", "side": "SELL", "hash": "a3b89a4f35ee41959ec55b0df3f09d21d60c6924", "best_bid": "0.55", "best_ask": "0.59"}], "timestamp": "1769384543678", "event_type": "price_change"}}
{"_local_timestamp": "2026-01-25T23:42:23.834799+00:00", "data": {"market": "0x75700f135fc1aa9106eecad102e82a5e304afa684948c453d9020973a6dacda6", "price_changes": [{"asset_id": "106943703042015764099709708127099569908287532239730770276583638212344318814024", "price": "0.61", "size": "100", "side": "BUY", "hash": "52456a0a2f9f82a64e0ad9e9f5ee9f17077abdd0", "best_bid": "0.61", "best_ask": "0.64"}, {"asset_id": "28461223070646267397095106287041417408320289813700921421278280340813748146076", "price": "0.39", "size": "100", "side": "SELL", "hash": "14215299ebb343a74dca03fa57a91c81e709c40e", "best_bid": "0.36", "best_ask": "0.39"}], "timestamp": "1769384543680", "event_type": "price_change"}}
{"_local_timestamp": "2026-01-25T23:42:23.854482+00:00", "data": {"market": "0x75700f135fc1aa9106eecad102e82a5e304afa684948c453d9020973a6dacda6", "price_changes": [{"asset_id": "28461223070646267397095106287041417408320289813700921421278280340813748146076", "price": "0.4", "size": "5", "side": "SELL", "hash": "44614aa2af2b9279612ee5c0c41b9bed167f3954", "best_bid": "0.36", "best_ask": "0.39"}, {"asset_id": "106943703042015764099709708127099569908287532239730770276583638212344318814024", "price": "0.6", "size": "5", "side": "BUY", "hash": "437ab41f8d59697166077d113434852513b5a5ee", "best_bid": "0.61", "best_ask": "0.64"}], "timestamp": "1769384543710", "event_type": "price_change"}}
{"_local_timestamp": "2026-01-25T23:42:24.194661+00:00", "data": {"market": "0x3cb3b76b6a4c3fdc6f933464859626df576eaf3e3e404ead3e75056fd48c04f5", "price_changes": [{"asset_id": "106006396008449636653509336329453630557359114983730727555924443870035053210127", "price": "0.42", "size": "30", "side": "BUY", "hash": "3be29051bec6d317c594549c02abf52080cb5542", "best_bid": "0.42", "best_ask": "0.45"}, {"asset_id": "50224211346577003424157970845956631119711245094103571068877904015222053747922", "price": "0.58", "size": "30", "side": "SELL", "hash": "b013308eda978aed49990cae94dbf52b3175147a", "best_bid": "0.55", "best_ask": "0.58"}], "timestamp": "1769384544025", "event_type": "price_change"}}
{"_local_timestamp": "2026-01-25T23:42:24.206437+00:00", "data": {"market": "0x75700f135fc1aa9106eecad102e82a5e304afa684948c453d9020973a6dacda6", "price_changes": [{"asset_id": "106943703042015764099709708127099569908287532239730770276583638212344318814024", "price": "0.57", "size": "20", "side": "BUY", "hash": "22a7beec107101b665cc6579161eca77ce3c1290", "best_bid": "0.61", "best_ask": "0.64"}, {"asset_id": "28461223070646267397095106287041417408320289813700921421278280340813748146076", "price": "0.43", "size": "20", "side": "SELL", "hash": "508d010dd8f1d335b320681b5e2197b67edfef64", "best_bid": "0.36", "best_ask": "0.39"}], "timestamp": "1769384544033", "event_type": "price_change"}}
{"_local_timestamp": "2026-01-25T23:42:24.207463+00:00", "data": {"market": "0x75700f135fc1aa9106eecad102e82a5e304afa684948c453d9020973a6dacda6", "price_changes": [{"asset_id": "106943703042015764099709708127099569908287532239730770276583638212344318814024", "price": "0.61", "size": "130", "side": "BUY", "hash": "f22769664eca3273aa13e31a3d99de943c0bc559", "best_bid": "0.61", "best_ask": "0.64"}, {"asset_id": "28461223070646267397095106287041417408320289813700921421278280340813748146076", "price": "0.39", "size": "130", "side": "SELL", "hash": "ed7d3cdf5c012943578915694dbb143612fa1f6b", "best_bid": "0.36", "best_ask": "0.39"}], "timestamp": "1769384544036", "event_type": "price_change"}}
{"_local_timestamp": "2026-01-25T23:42:24.276831+00:00", "data": {"market": "0x75700f135fc1aa9106eecad102e82a5e304afa684948c453d9020973a6dacda6", "price_changes": [{"asset_id": "106943703042015764099709708127099569908287532239730770276583638212344318814024", "price": "0.61", "size": "160", "side": "BUY", "hash": "b0fe37e250c5488920bb77968f26215e05061dd0", "best_bid": "0.61", "best_ask": "0.64"}, {"asset_id": "28461223070646267397095106287041417408320289813700921421278280340813748146076", "price": "0.39", "size": "160", "side": "SELL", "hash": "8dd90c110f6f333bd9c39b16f2bd1621fc5c512a", "best_bid": "0.36", "best_ask": "0.39"}], "timestamp": "1769384544141", "event_type": "price_change"}}
{"_local_timestamp": "2026-01-25T23:42:24.451445+00:00", "data": {"market": "0x75700f135fc1aa9106eecad102e82a5e304afa684948c453d9020973a6dacda6", "price_changes": [{"asset_id": "106943703042015764099709708127099569908287532239730770276583638212344318814024", "price": "0.59", "size": "0", "side": "BUY", "hash": "1f1445c29f2a44f4599391072c8c3fc98acb7dba", "best_bid": "0.61", "best_ask": "0.64"}, {"asset_id": "28461223070646267397095106287041417408320289813700921421278280340813748146076", "price": "0.41", "size": "0", "side": "SELL", "hash": "cd904bcaa7571bce00fc04e4049030dc52f4265c", "best_bid": "0.36", "best_ask": "0.39"}], "timestamp": "1769384544319", "event_type": "price_change"}}
{"_local_timestamp": "2026-01-25T23:42:24.458834+00:00", "data": {"market": "0x3cb3b76b6a4c3fdc6f933464859626df576eaf3e3e404ead3e75056fd48c04f5", "price_changes": [{"asset_id": "106006396008449636653509336329453630557359114983730727555924443870035053210127", "price": "0.38", "size": "5.98", "side": "BUY", "hash": "27a8b2241b589d965c972f2e208b19829dfe841d", "best_bid": "0.42", "best_ask": "0.45"}, {"asset_id": "50224211346577003424157970845956631119711245094103571068877904015222053747922", "price": "0.62", "size": "5.98", "side": "SELL", "hash": "b87896f3ee8c4d7d5eed38b56d6dda6f72e6f776", "best_bid": "0.55", "best_ask": "0.58"}], "timestamp": "1769384544321", "event_type": "price_change"}}
{"_local_timestamp": "2026-01-25T23:42:25.174537+00:00", "data": {"market": "0x3cb3b76b6a4c3fdc6f933464859626df576eaf3e3e404ead3e75056fd48c04f5", "price_changes": [{"asset_id": "106006396008449636653509336329453630557359114983730727555924443870035053210127", "price": "0.4", "size": "60.72", "side": "BUY", "hash": "08badaa669d4328edc2c51505d3506d955c04f8a", "best_bid": "0.42", "best_ask": "0.45"}, {"asset_id": "50224211346577003424157970845956631119711245094103571068877904015222053747922", "price": "0.6", "size": "60.72", "side": "SELL", "hash": "ead2903f7bbdbd5ee62ae6d24988f8780e072bea", "best_bid": "0.55", "best_ask": "0.58"}], "timestamp": "1769384544958", "event_type": "price_change"}}
{"_local_timestamp": "2026-01-25T23:42:25.214444+00:00", "data": {"market": "0x3cb3b76b6a4c3fdc6f933464859626df576eaf3e3e404ead3e75056fd48c04f5", "price_changes": [{"asset_id": "106006396008449636653509336329453630557359114983730727555924443870035053210127", "price": "0.41", "size": "130", "side": "BUY", "hash": "43069f689699d8dcf8b78d74a105f365dae07688", "best_bid": "0.42", "best_ask": "0.45"}, {"asset_id": "50224211346577003424157970845956631119711245094103571068877904015222053747922", "price": "0.59", "size": "130", "side": "SELL", "hash": "3b6190cceb1235192a637f3d86b64d918f0bfad0", "best_bid": "0.55", "best_ask": "0.58"}], "timestamp": "1769384545016", "event_type": "price_change"}}
{"_local_timestamp": "2026-01-25T23:42:25.220409+00:00", "data": {"market": "0x3cb3b76b6a4c3fdc6f933464859626df576eaf3e3e404ead3e75056fd48c04f5", "price_changes": [{"asset_id": "106006396008449636653509336329453630557359114983730727555924443870035053210127", "price": "0.4", "size": "10.72", "side": "BUY", "hash": "bbf68401ccd8b03f7c41ee9554b9d9a0b81cd964", "best_bid": "0.42", "best_ask": "0.45"}, {"asset_id": "50224211346577003424157970845956631119711245094103571068877904015222053747922", "price": "0.6", "size": "10.72", "side": "SELL", "hash": "544c2f5f36581e34e480d3950c2515a931329814", "best_bid": "0.55", "best_ask": "0.58"}], "timestamp": "1769384545056", "event_type": "price_change"}}
{"_local_timestamp": "2026-01-25T23:42:25.230497+00:00", "data": {"market": "0x3cb3b76b6a4c3fdc6f933464859626df576eaf3e3e404ead3e75056fd48c04f5", "price_changes": [{"asset_id": "106006396008449636653509336329453630557359114983730727555924443870035053210127", "price": "0.4", "size": "23.72", "side": "BUY", "hash": "0abf98a61a4a85a3b4c19f3737afdb2c653a079c", "best_bid": "0.42", "best_ask": "0.45"}, {"asset_id": "50224211346577003424157970845956631119711245094103571068877904015222053747922", "price": "0.6", "size": "23.72", "side": "SELL", "hash": "2ebb701ce681d1f7a827b6d66cddaaa384b4d96e", "best_bid": "0.55", "best_ask": "0.58"}], "timestamp": "1769384545084", "event_type": "price_change"}}
{"_local_timestamp": "2026-01-25T23:42:25.524388+00:00", "data": {"market": "0x75700f135fc1aa9106eecad102e82a5e304afa684948c453d9020973a6dacda6", "price_changes": [{"asset_id": "106943703042015764099709708127099569908287532239730770276583638212344318814024", "price": "0.58", "size": "0", "side": "BUY", "hash": "fe6b2c8d29b4a6e0f10bbf470bb883c27627536d", "best_bid": "0.61", "best_ask": "0.64"}, {"asset_id": "28461223070646267397095106287041417408320289813700921421278280340813748146076", "price": "0.42", "size": "0", "side": "SELL", "hash": "acc8f7986f9d30ff37b38dbc759db33d713c7500", "best_bid": "0.36", "best_ask": "0.39"}], "timestamp": "1769384545381", "event_type": "price_change"}}
