{"_local_timestamp": "2026-01-25T23:41:32.472570+00:00", "data": [{"market": "0x991358f2fe27cd377bbfa5675f11abe0260f57d96b2213df2f524b65e1318ba2", "asset_id": "30781978636182677294175184280628024916751245666283796904338430160661072344567", "timestamp": "1769384267223", "hash": "0f223cfc1b7f6af53a1839e0293a94435a6ea535", "bids": [{"price": "0.001", "size": "7444.85"}, {"price": "0.002", "size": "1755.83"}, {"price": "0.003", "size": "1166"}, {"price": "0.004", "size": "10.09"}, {"price": "0.006", "size": "83"}, {"price": "0.01", "size": "2783"}, {"price": "0.011", "size": "5.13"}, {"price": "0.02", "size": "3700"}, {"price": "0.021", "size": "10.08"}, {"price": "0.041", "size": "48"}, {"price": "0.05", "size": "60"}, {"price": "0.051", "size": "39"}, {"price": "0.06", "size": "200"}, {"price": "0.061", "size": "7.34"}, {"price": "0.114", "size": "325"}, {"price": "0.161", "size": "250"}, {"price": "0.162", "size": "7.56"}, {"price": "0.213", "size": "5"}, {"price": "0.233", "size": "299"}, {"price": "0.234", "size": "8"}, {"price": "0.9", "size": "50"}, {"price": "0.901", "size": "20"}, {"price": "0.95", "size": "1000"}, {"price": "0.957", "size": "59.37"}, {"price": "0.96", "size": "500"}, {"price": "0.961", "size": "300"}, {"price": "0.962", "size": "200"}, {"price": "0.964", "size": "25"}, {"price": "0.966", "size": "16"}, {"price": "0.97", "size": "125"}, {"price": "0.971", "size": "170.31"}, {"price": "0.995", "size": "43"}], "asks": [{"price": "0.999", "size": "19307.93"}, {"price": "0.998", "size": "4405"}, {"price": "0.996", "size": "250"}], "event_type": "book", "last_trade_price": "0.002"}, {"market": "0xfbc27b527d29e83b5add21aec7e8ae12bcfe1802cc9d697fd2fc3ef971e73b1a", "asset_id": "20742295429047093344183624784356215475991906727753544432953361940370520424440", "timestamp": "1769384383626", "hash": "50fa4e20d2fb449fa3da5a806092d7472b8e6f8a", "bids": [{"price": "0.001", "size": "7404.85"}, {"price": "0.002", "size": "1755.83"}, {"price": "0.003", "size": "1166"}, {"price": "0.004", "size": "10.09"}, {"price": "0.006", "size": "83"}, {"price": "0.01", "size": "2783"}, {"price": "0.011", "size": "5.13"}, {"price": "0.02", "size": "3700"}, {"price": "0.021", "size": "10.08"}, {"price": "0.041", "size": "48"}, {"price": "0.05", "size": "60"}, {"price": "0.051", "size": "39"}, {"price": "0.06", "size": "200"}, {"price": "0.061", "size": "7.28"}, {"price": "0.113", "size": "325"}, {"price": "0.115", "size": "100"}, {"price": "0.16", "size": "250"}, {"price": "0.161", "size": "7.63"}, {"price": "0.21", "size": "100"}, {"price": "0.301", "size": "262.81"}, {"price": "0.302", "size": "6"}, {"price": "0.823", "size": "92"}, {"price": "0.92", "size": "40"}, {"price": "0.921", "size": "20"}, {"price": "0.923", "size": "5"}, {"price": "0.979", "size": "46.82"}, {"price": "0.99", "size": "2000"}, {"price": "0.991", "size": "300"}, {"price": "0.992", "size": "200"}, {"price": "0.993", "size": "53.7"}, {"price": "0.994", "size": "25.54"}, {"price": "0.995", "size": "10"}, {"price": "0.996", "size": "25"}, {"price": "0.997", "size": "15"}], "asks": [{"price": "0.999", "size": "18841.37"}, {"price": "0.998", "size": "3660"}], "event_type": "book", "last_trade_price": "0.002"}, {"market": "0x85a5b08650fc9da8d93e9eee346c5b54edbdbf83cb9f55465fdfcdb9f17151a8", "asset_id": "61857642644203197654538794139397189976239069779458940587434285917874264673085", "timestamp": "1769383983539", "hash": "7ebdf69be197c303c875cbda04e34c49bda500e8", "bids": [{"price": "0.001", "size": "1190"}], "asks": [{"price": "0.999", "size": "7408.85"}, {"price": "0.998", "size": "1255.83"}, {"price": "0.997", "size": "1166"}, {"price": "0.996", "size": "10.09"}, {"price": "0.994", "size": "83"}, {"price": "0.99", "size": "2783"}, {"price": "0.989", "size": "5.13"}, {"price": "0.98", "size": "3700"}, {"price": "0.979", "size": "10.08"}, {"price": "0.959", "size": "48"}, {"price": "0.95", "size": "60"}, {"price": "0.949", "size": "39"}, {"price": "0.94", "size": "200"}, {"price": "0.939", "size": "7.27"}, {"price": "0.886", "size": "325"}, {"price": "0.84", "size": "250"}, {"price": "0.839", "size": "7.63"}, {"price": "0.786", "size": "119.98"}, {"price": "0.777", "size": "16"}, {"price": "0.767", "size": "299"}, {"price": "0.766", "size": "8"}, {"price": "0.477", "size": "20"}, {"price": "0.177", "size": "6"}, {"price": "0.08", "size": "30"}, {"price": "0.077", "size": "252"}, {"price": "0.076", "size": "8"}, {"price": "0.075", "size": "13"}, {"price": "0.074", "size": "20"}, {"price": "0.005", "size": "2506"}], "event_type": "book", "last_trade_price": "0.001"}, {"market": "0x991358f2fe27cd377bbfa5675f11abe0260f57d96b2213df2f524b65e1318ba2", "asset_id": "30899708905792632770828483686577399318459107910488619954838451416937410382210", "timestamp": "1769384267223", "hash": "e57c84e3e3c4471cf9a545b3f52d5b33d3fd62f0", "bids": [{"price": "0.001", "size": "19307.93"}, {"price": "0.002", "size": "4405"}, {"price": "0.004", "size": "250"}], "asks": [{"price": "0.999", "size": "7444.85"}, {"price": "0.998", "size": "1755.83"}, {"price": "0.997", "size": "1166"}, {"price": "0.996", "size": "10.09"}, {"price": "0.994", "size": "83"}, {"price": "0.99", "size": "2783"}, {"price": "0.989", "size": "5.13"}, {"price": "0.98", "size": "3700"}, {"price": "0.979", "size": "10.08"}, {"price": "0.959", "size": "48"}, {"price": "0.95", "size": "60"}, {"price": "0.949", "size": "39"}, {"price": "0.94", "size": "200"}, {"price": "0.939", "size": "7.34"}, {"price": "0.886", "size": "325"}, {"price": "0.839", "size": "250"}, {"price": "0.838", "size": "7.56"}, {"price": "0.787", "size": "5"}, {"price": "0.767", "size": "299"}, {"price": "0.766", "size": "8"}, {"price": "0.1", "size": "50"}, {"price": "0.099", "size": "20"}, {"price": "0.05", "size": "1000"}, {"price": "0.043", "size": "59.37"}, {"price": "0.04", "size": "500"}, {"price": "0.039", "size": "300"}, {"price": "0.038", "size": "200"}, {"price": "0.036", "size": "25"}, {"price": "0.034", "size": "16"}, {"price": "0.03", "size": "125"}, {"price": "0.029", "size": "170.31"}, {"price": "0.005", "size": "43"}], "event_type": "book", "last_trade_price": "0.002"}, {"market": "0x0e4536b6aaf51d080f7414bb68009ba5b1d826d24530fbadbca2e3f7e4227e34", "asset_id": "13539255989319659082805101136090441229143955236158172607278915698110589985388", "timestamp": "1769383849677", "hash": "bd72ed74c944560f6326ade760cd2763594e7787", "bids": [{"price": "0.001", "size": "1551.06"}], "asks": [{"price": "0.999", "size": "7406.85"}, {"price": "0.998", "size": "1755.83"}, {"price": "0.997", "size": "1166"}, {"price": "0.996", "size": "10.09"}, {"price": "0.994", "size": "83"}, {"price": "0.99", "size": "2783"}, {"price": "0.989", "size": "5.13"}, {"price": "0.98", "size": "3700"}, {"price": "0.979", "size": "10.08"}, {"price": "0.959", "size": "48"}, {"price": "0.95", "size": "60"}, {"price": "0.949", "size": "39"}, {"price": "0.94", "size": "200"}, {"price": "0.939", "size": "7.27"}, {"price": "0.89", "size": "325"}, {"price": "0.888", "size": "52"}, {"price": "0.84", "size": "250"}, {"price": "0.839", "size": "7.63"}, {"price": "0.777", "size": "9"}, {"price": "0.76", "size": "150"}, {"price": "0.759", "size": "8"}, {"price": "0.177", "size": "75"}, {"price": "0.176", "size": "20"}, {"price": "0.05", "size": "172"}, {"price": "0.012", "size": "10.82"}, {"price": "0.005", "size": "1921.2"}], "event_type": "book", "last_trade_price": "0.001"}, {"market": "0x70e2c432a9f1c46194b4ed01276fce4b42ba14fa4121bb6a204bd27043fa6ec0", "asset_id": "96293988997073127556538359019802355814918008050500416514241789357023389177644", "timestamp": "1769384483689", "hash": "b16587ffe0d0f08e32c9c97fd14fe1b717025866", "bids": [{"price": "0.001", "size": "7406.85"}, {"price": "0.002", "size": "1755.83"}, {"price": "0.003", "size": "1166"}, {"price": "0.004", "size": "10.09"}, {"price": "0.006", "size": "83"}, {"price": "0.01", "size": "1783"}, {"price": "0.011", "size": "23.93"}, {"price": "0.041", "size": "48"}, {"price": "0.05", "size": "60"}, {"price": "0.051", "size": "39"}, {"price": "0.052", "size": "19"}, {"price": "0.058", "size": "34"}, {"price": "0.06", "size": "27.98"}, {"price": "0.061", "size": "50"}, {"price": "0.86", "size": "17.17"}, {"price": "0.875", "size": "45"}, {"price": "0.876", "size": "20"}], "asks": [{"price": "0.999", "size": "19367.05"}, {"price": "0.998", "size": "380.76"}, {"price": "0.997", "size": "9.42"}, {"price": "0.996", "size": "300"}, {"price": "0.995", "size": "20.35"}, {"price": "0.99", "size": "148"}, {"price": "0.987", "size": "274.98"}, {"price": "0.986", "size": "137"}, {"price": "0.985", "size": "70"}, {"price": "0.983", "size": "20"}, {"price": "0.982", "size": "66.66"}], "event_type": "book", "last_trade_price": "0.877"}, {"market": "0xfbc27b527d29e83b5add21aec7e8ae12bcfe1802cc9d697fd2fc3ef971e73b1a", "asset_id": "20976114661621715860645243051991645946734532418059434954111576177898236905114", "timestamp": "1769384383626", "hash": "58b38b828d78bb5240062028c738cefaa6200e32", "bids": [{"price": "0.001", "size": "18841.37"}, {"price": "0.002", "size": "3660"}], "asks": [{"price": "0.999", "size": "7404.85"}, {"price": "0.998", "size": "1755.83"}, {"price": "0.997", "size": "1166"}, {"price": "0.996", "size": "10.09"}, {"price": "0.994", "size": "83"}, {"price": "0.99", "size": "2783"}, {"price": "0.989", "size": "5.13"}, {"price": "0.98", "size": "3700"}, {"price": "0.979", "size": "10.08"}, {"price": "0.959", "size": "48"}, {"price": "0.95", "size": "60"}, {"price": "0.949", "size": "39"}, {"price": "0.94", "size": "200"}, {"price": "0.939", "size": "7.28"}, {"price": "0.887", "size": "325"}, {"price": "0.885", "size": "100"}, {"price": "0.84", "size": "250"}, {"price": "0.839", "size": "7.63"}, {"price": "0.79", "size": "100"}, {"price": "0.699", "size": "262.81"}, {"price": "0.698", "size": "6"}, {"price": "0.177", "size": "92"}, {"price": "0.08", "size": "40"}, {"price": "0.079", "size": "20"}, {"price": "0.077", "size": "5"}, {"price": "0.021", "size": "46.82"}, {"price": "0.01", "size": "2000"}, {"price": "0.009", "size": "300"}, {"price": "0.008", "size": "200"}, {"price": "0.007", "size": "53.7"}, {"price": "0.006", "size": "25.54"}, {"price": "0.005", "size": "10"}, {"price": "0.004", "size": "25"}, {"price": "0.003", "size": "15"}], "event_type": "book", "last_trade_price": "0.002"}, {"market": "0x0e4536b6aaf51d080f7414bb68009ba5b1d826d24530fbadbca2e3f7e4227e34", "asset_id": "66796898799007262533573083628291477479823184385652148020496261238624922732970", "timestamp": "1769383849677", "hash": "4a2895f141d35e134530917d92d7b476d61ad7d1", "bids": [{"price": "0.001", "size": "7406.85"}, {"price": "0.002", "size": "1755.83"}, {"price": "0.003", "size": "1166"}, {"price": "0.004", "size": "10.09"}, {"price": "0.006", "size": "83"}, {"price": "0.01", "size": "2783"}, {"price": "0.011", "size": "5.13"}, {"price": "0.02", "size": "3700"}, {"price": "0.021", "size": "10.08"}, {"price": "0.041", "size": "48"}, {"price": "0.05", "size": "60"}, {"price": "0.051", "size": "39"}, {"price": "0.06", "size": "200"}, {"price": "0.061", "size": "7.27"}, {"price": "0.11", "size": "325"}, {"price": "0.112", "size": "52"}, {"price": "0.16", "size": "250"}, {"price": "0.161", "size": "7.63"}, {"price": "0.223", "size": "9"}, {"price": "0.24", "size": "150"}, {"price": "0.241", "size": "8"}, {"price": "0.823", "size": "75"}, {"price": "0.824", "size": "20"}, {"price": "0.95", "size": "172"}, {"price": "0.988", "size": "10.82"}, {"price": "0.995", "size": "1921.2"}], "asks": [{"price": "0.999", "size": "1551.06"}], "event_type": "book", "last_trade_price": "0.001"}, {"market": "0x026f75cda28b435d52c8615dc2eaa8895b4632e9f53c98255f2bced50fbb5018", "asset_id": "103477786055085350112953174136231624107339341173836019810109648103195092330225", "timestamp": "1769384444831", "hash": "f3c1a4e4358ceec9d143ee83ed58f1ad0a3d68ba", "bids": [{"price": "0.01", "size": "1999.6"}, {"price": "0.02", "size": "299.28"}, {"price": "0.05", "size": "1000"}, {"price": "0.06", "size": "1180"}, {"price": "0.08", "size": "10"}, {"price": "0.09", "size": "5"}, {"price": "0.1", "size": "119"}, {"price": "0.11", "size": "574.21"}, {"price": "0.12", "size": "134.57"}], "asks": [{"price": "0.99", "size": "3194.45"}, {"price": "0.98", "size": "1400"}, {"price": "0.97", "size": "7.08"}, {"price": "0.95", "size": "80"}, {"price": "0.94", "size": "200"}, {"price": "0.93", "size": "6.34"}, {"price": "0.89", "size": "325"}, {"price": "0.84", "size": "250"}, {"price": "0.83", "size": "7.23"}, {"price": "0.79", "size": "100"}, {"price": "0.71", "size": "6"}, {"price": "0.68", "size": "75"}, {"price": "0.67", "size": "181"}, {"price": "0.35", "size": "70"}, {"price": "0.3", "size": "60"}, {"price": "0.29", "size": "20"}, {"price": "0.18", "size": "10"}, {"price": "0.15", "size": "35"}, {"price": "0.14", "size": "3.52"}, {"price": "0.13", "size": "10"}], "event_type": "book", "last_trade_price": "0.120"}, {"market": "0x85a5b08650fc9da8d93e9eee346c5b54edbdbf83cb9f55465fdfcdb9f17151a8", "asset_id": "7748084461925509330048730794685020928130479141303753203741718956919910252040", "timestamp": "1769383983539", "hash": "3e557cce4668aaa5b3630ea03a47c12513b6b181", "bids": [{"price": "0.001", "size": "7408.85"}, {"price": "0.002", "size": "1255.83"}, {"price": "0.003", "size": "1166"}, {"price": "0.004", "size": "10.09"}, {"price": "0.006", "size": "83"}, {"price": "0.01", "size": "2783"}, {"price": "0.011", "size": "5.13"}, {"price": "0.02", "size": "3700"}, {"price": "0.021", "size": "10.08"}, {"price": "0.041", "size": "48"}, {"price": "0.05", "size": "60"}, {"price": "0.051", "size": "39"}, {"price": "0.06", "size": "200"}, {"price": "0.061", "size": "7.27"}, {"price": "0.114", "size": "325"}, {"price": "0.16", "size": "250"}, {"price": "0.161", "size": "7.63"}, {"price": "0.214", "size": "119.98"}, {"price": "0.223", "size": "16"}, {"price": "0.233", "size": "299"}, {"price": "0.234", "size": "8"}, {"price": "0.523", "size": "20"}, {"price": "0.823", "size": "6"}, {"price": "0.92", "size": "30"}, {"price": "0.923", "size": "252"}, {"price": "0.924", "size": "8"}, {"price": "0.925", "size": "13"}, {"price": "0.926", "size": "20"}, {"price": "0.995", "size": "2506"}], "asks": [{"price": "0.999", "size": "1190"}], "event_type": "book", "last_trade_price": "0.001"}, {"market": "0x10aa044e00621209c1e6516ed820607867e1939c51e6416e78389133c07a28ca", "asset_id": "106590375374356420328249754119755979864494562435507082169975336179942135107522", "timestamp": "1769384353801", "hash": "a95f671a93c8bdbb6196c171434937285a718011", "bids": [{"price": "0.01", "size": "2639.14"}, {"price": "0.02", "size": "26.2"}, {"price": "0.03", "size": "40"}, {"price": "0.04", "size": "84"}, {"price": "0.05", "size": "18.04"}, {"price": "0.06", "size": "20"}, {"price": "0.08", "size": "5.95"}, {"price": "0.09", "size": "5.69"}, {"price": "0.1", "size": "2.44"}, {"price": "0.13", "size": "114.66"}, {"price": "0.14", "size": "18"}, {"price": "0.15", "size": "19"}], "asks": [{"price": "0.99", "size": "4252.6"}, {"price": "0.98", "size": "3550"}, {"price": "0.97", "size": "100"}, {"price": "0.96", "size": "132.14"}, {"price": "0.95", "size": "120"}, {"price": "0.94", "size": "100"}, {"price": "0.93", "size": "100"}, {"price": "0.92", "size": "100"}, {"price": "0.91", "size": "100"}, {"price": "0.9", "size": "1100"}, {"price": "0.87", "size": "325"}, {"price": "0.8", "size": "350"}, {"price": "0.79", "size": "125"}, {"price": "0.75", "size": "105"}, {"price": "0.71", "size": "150"}, {"price": "0.55", "size": "160"}, {"price": "0.5", "size": "25"}, {"price": "0.45", "size": "180"}, {"price": "0.44", "size": "40"}, {"price": "0.26", "size": "100"}, {"price": "0.25", "size": "15"}, {"price": "0.24", "size": "100"}, {"price": "0.23", "size": "20"}, {"price": "0.22", "size": "10"}, {"price": "0.2", "size": "80"}, {"price": "0.18", "size": "11.48"}, {"price": "0.17", "size": "60"}, {"price": "0.16", "size": "46.07"}], "event_type": "book", "last_trade_price": "0.160"}, {"market": "0x026f75cda28b435d52c8615dc2eaa8895b4632e9f53c98255f2bced50fbb5018", "asset_id": "18282828012097738947825685359604327312283762551135248913642539025764020349015", "timestamp": "1769384444831", "hash": "0b672ea63c088c4ea26b313398e3db98ddf6b248", "bids": [{"price": "0.01", "size": "3194.45"}, {"price": "0.02", "size": "1400"}, {"price": "0.03", "size": "7.08"}, {"price": "0.05", "size": "80"}, {"price": "0.06", "size": "200"}, {"price": "0.07", "size": "6.34"}, {"price": "0.11", "size": "325"}, {"price": "0.16", "size": "250"}, {"price": "0.17", "size": "7.23"}, {"price": "0.21", "size": "100"}, {"price": "0.29", "size": "6"}, {"price": "0.32", "size": "75"}, {"price": "0.33", "size": "181"}, {"price": "0.65", "size": "70"}, {"price": "0.7", "size": "60"}, {"price": "0.71", "size": "20"}, {"price": "0.82", "size": "10"}, {"price": "0.85", "size": "35"}, {"price": "0.86", "size": "3.52"}, {"price": "0.87", "size": "10"}], "asks": [{"price": "0.99", "size": "1999.6"}, {"price": "0.98", "size": "299.28"}, {"price": "0.95", "size": "1000"}, {"price": "0.94", "size": "1180"}, {"price": "0.92", "size": "10"}, {"price": "0.91", "size": "5"}, {"price": "0.9", "size": "119"}, {"price": "0.89", "size": "574.21"}, {"price": "0.88", "size": "134.57"}], "event_type": "book", "last_trade_price": "0.120"}, {"market": "0x70e2c432a9f1c46194b4ed01276fce4b42ba14fa4121bb6a204bd27043fa6ec0", "asset_id": "76151979298166149168681611766855150167264661944933736838438696924609959086385", "timestamp": "1769384483689", "hash": "289314be1a12395a853df024143c86c872c49c55", "bids": [{"price": "0.001", "size": "19367.05"}, {"price": "0.002", "size": "380.76"}, {"price": "0.003", "size": "9.42"}, {"price": "0.004", "size": "300"}, {"price": "0.005", "size": "20.35"}, {"price": "0.01", "size": "148"}, {"price": "0.013", "size": "274.98"}, {"price": "0.014", "size": "137"}, {"price": "0.015", "size": "70"}, {"price": "0.017", "size": "20"}, {"price": "0.018", "size": "66.66"}], "asks": [{"price": "0.999", "size": "7406.85"}, {"price": "0.998", "size": "1755.83"}, {"price": "0.997", "size": "1166"}, {"price": "0.996", "size": "10.09"}, {"price": "0.994", "size": "83"}, {"price": "0.99", "size": "1783"}, {"price": "0.989", "size": "23.93"}, {"price": "0.959", "size": "48"}, {"price": "0.95", "size": "60"}, {"price": "0.949", "size": "39"}, {"price": "0.948", "size": "19"}, {"price": "0.942", "size": "34"}, {"price": "0.94", "size": "27.98"}, {"price": "0.939", "size": "50"}, {"price": "0.14", "size": "17.17"}, {"price": "0.125", "size": "45"}, {"price": "0.124", "size": "20"}], "event_type": "book", "last_trade_price": "0.877"}, {"market": "0x10aa044e00621209c1e6516ed820607867e1939c51e6416e78389133c07a28ca", "asset_id": "114217190078574681732390148219500280529940631077811733810801001867278151517965", "timestamp": "1769384353801", "hash": "320166ec3ae1d48d59009b793f070509187724da", "bids": [{"price": "0.01", "size": "4252.6"}, {"price": "0.02", "size": "3550"}, {"price": "0.03", "size": "100"}, {"price": "0.04", "size": "132.14"}, {"price": "0.05", "size": "120"}, {"price": "0.06", "size": "100"}, {"price": "0.07", "size": "100"}, {"price": "0.08", "size": "100"}, {"price": "0.09", "size": "100"}, {"price": "0.1", "size": "1100"}, {"price": "0.13", "size": "325"}, {"price": "0.2", "size": "350"}, {"price": "0.21", "size": "125"}, {"price": "0.25", "size": "105"}, {"price": "0.29", "size": "150"}, {"price": "0.45", "size": "160"}, {"price": "0.5", "size": "25"}, {"price": "0.55", "size": "180"}, {"price": "0.56", "size": "40"}, {"price": "0.74", "size": "100"}, {"price": "0.75", "size": "15"}, {"price": "0.76", "size": "100"}, {"price": "0.77", "size": "20"}, {"price": "0.78", "size": "10"}, {"price": "0.8", "size": "80"}, {"price": "0.82", "size": "11.48"}, {"price": "0.83", "size": "60"}, {"price": "0.84", "size": "46.07"}], "asks": [{"price": "0.99", "size": "2639.14"}, {"price": "0.98", "size": "26.2"}, {"price": "0.97", "size": "40"}, {"price": "0.96", "size": "84"}, {"price": "0.95", "size": "18.04"}, {"price": "0.94", "size": "20"}, {"price": "0.92", "size": "5.95"}, {"price": "0.91", "size": "5.69"}, {"price": "0.9", "size": "2.44"}, {"price": "0.87", "size": "114.66"}, {"price": "0.86", "size": "18"}, {"price": "0.85", "size": "19"}], "event_type": "book", "last_trade_price": "0.160"}]}
{"_local_timestamp": "2026-01-25T23:41:32.779524+00:00", "data": {"market": "0x026f75cda28b435d52c8615dc2eaa8895b4632e9f53c98255f2bced50fbb5018", "price_changes": [{"asset_id": "103477786055085350112953174136231624107339341173836019810109648103195092330225", "price": "0.12", "size": "44.21", "side": "BUY", "hash": "be91ddae822bce47e6fc77e7eab017b160c091db", "best_bid": "0.12", "best_ask": "0.13"}, {"asset_id": "18282828012097738947825685359604327312283762551135248913642539025764020349015", "price": "0.88", "size": "44.21", "side": "SELL", "hash": "8e7e0c9e9af91c18070d7d2b422180cc8a230ae5", "best_bid": "0.87", "best_ask": "0.88"}], "timestamp": "1769384492702", "event_type": "price_change"}}
{"_local_timestamp": "2026-01-25T23:41:32.796079+00:00", "data": {"market": "0x026f75cda28b435d52c8615dc2eaa8895b4632e9f53c98255f2bced50fbb5018", "price_changes": [{"asset_id": "103477786055085350112953174136231624107339341173836019810109648103195092330225", "price": "0.12", "size": "14.09", "side": "BUY", "hash": "10c4aecf711a63707348fc68b2090ad355fba258", "best_bid": "0.12", "best_ask": "0.13"}, {"asset_id": "18282828012097738947825685359604327312283762551135248913642539025764020349015", "price": "0.88", "size": "14.09", "side": "SELL", "hash": "0040e8d76ced4ce2243bab883b2332c81e8e5582", "best_bid": "0.87", "best_ask": "0.88"}], "timestamp": "1769384492717", "event_type": "price_change"}}
{"_local_timestamp": "2026-01-25T23:41:47.375506+00:00", "data": {"market": "0x026f75cda28b435d52c8615dc2eaa8895b4632e9f53c98255f2bced50fbb5018", "price_changes": [{"asset_id": "103477786055085350112953174136231624107339341173836019810109648103195092330225", "price": "0.12", "size": "44.21", "side": "BUY", "hash": "dc5ad52e91a0fd4c6f0f1ead2839a07f207a93b2", "best_bid": "0.12", "best_ask": "0.13"}, {"asset_id": "18282828012097738947825685359604327312283762551135248913642539025764020349015", "price": "0.88", "size": "44.21", "side": "SELL", "hash": "4bbe917291127d106116aa8e71b1ebe9d90d6d9e", "best_bid": "0.87", "best_ask": "0.88"}], "timestamp": "1769384507307", "event_type": "price_change"}}
{"_local_timestamp": "2026-01-25T23:41:47.376336+00:00", "data": {"market": "0x026f75cda28b435d52c8615dc2eaa8895b4632e9f53c98255f2bced50fbb5018", "price_changes": [{"asset_id": "103477786055085350112953174136231624107339341173836019810109648103195092330225", "price": "0.12", "size": "74.33", "side": "BUY", "hash": "8873902a07b5e6c1079e5fd32c92efb198f9351b", "best_bid": "0.12", "best_ask": "0.13"}, {"asset_id": "18282828012097738947825685359604327312283762551135248913642539025764020349015", "price": "0.88", "size": "74.33", "side": "SELL", "hash": "c74a24ac3c5e1296b715ad838e15a1a9255a6682", "best_bid": "0.87", "best_ask": "0.88"}], "timestamp": "1769384507307", "event_type": "price_change"}}
{"_local_timestamp": "2026-01-25T23:41:47.376670+00:00", "data": {"market": "0x026f75cda28b435d52c8615dc2eaa8895b4632e9f53c98255f2bced50fbb5018", "price_changes": [{"asset_id": "103477786055085350112953174136231624107339341173836019810109648103195092330225", "price": "0.12", "size": "104.45", "side": "BUY", "hash": "bd96b757c717bf71c4ca661b5b9baa1a45a7f179", "best_bid": "0.12", "best_ask": "0.13"}, {"asset_id": "18282828012097738947825685359604327312283762551135248913642539025764020349015", "price": "0.88", "size": "104.45", "side": "SELL", "hash": "f694fb8dd3c8b57740504911e723f039a5680f5b", "best_bid": "0.87", "best_ask": "0.88"}], "timestamp": "1769384507308", "event_type": "price_change"}}
{"_local_timestamp": "2026-01-25T23:41:47.376969+00:00", "data": {"market": "0x026f75cda28b435d52c8615dc2eaa8895b4632e9f53c98255f2bced50fbb5018", "price_changes": [{"asset_id": "103477786055085350112953174136231624107339341173836019810109648103195092330225", "price": "0.12", "size": "134.57", "side": "BUY", "hash": "b2b55b0dcbdd28796e17d7c2b8d271fb73c0fb27", "best_bid": "0.12", "best_ask": "0.13"}, {"asset_id": "18282828012097738947825685359604327312283762551135248913642539025764020349015", "price": "0.88", "size": "134.57", "side": "SELL", "hash": "f2f1a636535fd11e27caf322c808ac6108c30ec1", "best_bid": "0.87", "best_ask": "0.88"}], "timestamp": "1769384507308", "event_type": "price_change"}}
{"_local_timestamp": "2026-01-25T23:41:50.642949+00:00", "data": {"market": "0x026f75cda28b435d52c8615dc2eaa8895b4632e9f53c98255f2bced50fbb5018", "price_changes": [{"asset_id": "18282828012097738947825685359604327312283762551135248913642539025764020349015", "price": "0.32", "size": "0", "side": "BUY", "hash": "ad0312695e256630a23a353b34e3bb4aa910601e", "best_bid": "0.87", "best_ask": "0.88"}, {"asset_id": "103477786055085350112953174136231624107339341173836019810109648103195092330225", "price": "0.68", "size": "0", "side": "SELL", "hash": "79cf23ee140662bce18824c7d528437c07a949df", "best_bid": "0.12", "best_ask": "0.13"}], "timestamp": "1769384510566", "event_type": "price_change"}}
{"_local_timestamp": "2026-01-25T23:41:51.254840+00:00", "data": {"market": "0x70e2c432a9f1c46194b4ed01276fce4b42ba14fa4121bb6a204bd27043fa6ec0", "price_changes": [{"asset_id": "96293988997073127556538359019802355814918008050500416514241789357023389177644", "price": "0.876", "size": "155.71", "side": "BUY", "hash": "176f4cc2f4b2b8e0238e704ef3b2b815dca467d6", "best_bid": "0.876", "best_ask": "0.982"}, {"asset_id": "76151979298166149168681611766855150167264661944933736838438696924609959086385", "price": "0.124", "size": "155.71", "side": "SELL", "hash": "fa2f6db45cb55ee69aaa28db4a7ea268dfb4cc9d", "best_bid": "0.018", "best_ask": "0.124"}], "timestamp": "1769384511162", "event_type": "price_change"}}
{"_local_timestamp": "2026-01-25T23:41:51.256623+00:00", "data": {"market": "0x70e2c432a9f1c46194b4ed01276fce4b42ba14fa4121bb6a204bd27043fa6ec0", "price_changes": [{"asset_id": "96293988997073127556538359019802355814918008050500416514241789357023389177644", "price": "0.877", "size": "135.71", "side": "BUY", "hash": "9d2b9f62eae3d53dd6cec5b0a0c787dca38b9e02", "best_bid": "0.877", "best_ask": "0.982"}, {"asset_id": "76151979298166149168681611766855150167264661944933736838438696924609959086385", "price": "0.123", "size": "135.71", "side": "SELL", "hash": "2256527bf746a526b5a5ee9e7b78457a9ea599b7", "best_bid": "0.018", "best_ask": "0.123"}], "timestamp": "1769384511165", "event_type": "price_change"}}
{"_local_timestamp": "2026-01-25T23:41:52.045192+00:00", "data": {"market": "0x026f75cda28b435d52c8615dc2eaa8895b4632e9f53c98255f2bced50fbb5018", "price_changes": [{"asset_id": "18282828012097738947825685359604327312283762551135248913642539025764020349015", "price": "0.33", "size": "256", "side": "BUY", "hash": "dbd2ad515b3a943730d46cf09378f5af30e02dfd", "best_bid": "0.87", "best_ask": "0.88"}, {"asset_id": "103477786055085350112953174136231624107339341173836019810109648103195092330225", "price": "0.67", "size": "256", "side": "SELL", "hash": "ffd5806d4243328c76d7def53dba901c1881e8df", "best_bid": "0.12", "best_ask": "0.13"}], "timestamp": "1769384511702", "event_type": "price_change"}}
{"_local_timestamp": "2026-01-25T23:41:53.279129+00:00", "data": {"market": "0x70e2c432a9f1c46194b4ed01276fce4b42ba14fa4121bb6a204bd27043fa6ec0", "price_changes": [{"asset_id": "96293988997073127556538359019802355814918008050500416514241789357023389177644", "price": "0.876", "size": "135.71", "side": "BUY", "hash": "6643e1e00124e1cc235d28e968d3d42ecb733880", "best_bid": "0.877", "best_ask": "0.982"}, {"asset_id": "76151979298166149168681611766855150167264661944933736838438696924609959086385", "price": "0.124", "size": "135.71", "side": "SELL", "hash": "d644c4897b86a123da5281156fca29f883ebba35", "best_bid": "0.018", "best_ask": "0.123"}], "timestamp": "1769384513090", "event_type": "price_change"}}
{"_local_timestamp": "2026-01-25T23:41:53.287266+00:00", "data": {"market": "0x70e2c432a9f1c46194b4ed01276fce4b42ba14fa4121bb6a204bd27043fa6ec0", "price_changes": [{"asset_id": "96293988997073127556538359019802355814918008050500416514241789357023389177644", "price": "0.878", "size": "20", "side": "BUY", "hash": "339f4e6db4c767156bbbbc920a7485c6834c94f8", "best_bid": "0.878", "best_ask": "0.982"}, {"asset_id": "76151979298166149168681611766855150167264661944933736838438696924609959086385", "price": "0.122", "size": "20", "side": "SELL", "hash": "7b95201f0cc60cc4f94ea71ee84e6b343a7cc8b9", "best_bid": "0.018", "best_ask": "0.122"}], "timestamp": "1769384513118", "event_type": "price_change"}}
{"_local_timestamp": "2026-01-25T23:41:53.378271+00:00", "data": {"market": "0x70e2c432a9f1c46194b4ed01276fce4b42ba14fa4121bb6a204bd27043fa6ec0", "price_changes": [{"asset_id": "96293988997073127556538359019802355814918008050500416514241789357023389177644", "price": "0.878", "size": "70", "side": "BUY", "hash": "d38accf24752c705b6090df370504a67a01b1ca7", "best_bid": "0.878", "best_ask": "0.982"}, {"asset_id": "76151979298166149168681611766855150167264661944933736838438696924609959086385", "price": "0.122", "size": "70", "side": "SELL", "hash": "29dc63795046c2ac02a36c30c14571fa49fde5bd", "best_bid": "0.018", "best_ask": "0.122"}], "timestamp": "1769384513311", "event_type": "price_change"}}
{"_local_timestamp": "2026-01-25T23:41:53.751218+00:00", "data": {"market": "0x70e2c432a9f1c46194b4ed01276fce4b42ba14fa4121bb6a204bd27043fa6ec0", "price_changes": [{"asset_id": "96293988997073127556538359019802355814918008050500416514241789357023389177644", "price": "0.061", "size": "0", "side": "BUY", "hash": "252a81b739e017481a7d3e64fa3ba8ea1d5e5f83", "best_bid": "0.878", "best_ask": "0.982"}, {"asset_id": "76151979298166149168681611766855150167264661944933736838438696924609959086385", "price": "0.939", "size": "0", "side": "SELL", "hash": "73d043c7f69d26ae01fed7ee0e8f1609e3a10ee4", "best_bid": "0.018", "best_ask": "0.122"}], "timestamp": "1769384513682", "event_type": "price_change"}}
{"_local_timestamp": "2026-01-25T23:41:55.534568+00:00", "data": {"market": "0x70e2c432a9f1c46194b4ed01276fce4b42ba14fa4121bb6a204bd27043fa6ec0", "price_changes": [{"asset_id": "96293988997073127556538359019802355814918008050500416514241789357023389177644", "price": "0.878", "size": "50", "side": "BUY", "hash": "d7d447d5cbed36b1c35df6045bba2973e4059691", "best_bid": "0.878", "best_ask": "0.982"}, {"asset_id": "76151979298166149168681611766855150167264661944933736838438696924609959086385", "price": "0.122", "size": "50", "side": "SELL", "hash": "fc6394f37d1487a03899b8f34a5c1c5571ed9b1a", "best_bid": "0.018", "best_ask": "0.122"}], "timestamp": "1769384515468", "event_type": "price_change"}}
{"_local_timestamp": "2026-01-25T23:41:55.566271+00:00", "data": {"market": "0x70e2c432a9f1c46194b4ed01276fce4b42ba14fa4121bb6a204bd27043fa6ec0", "price_changes": [{"asset_id": "96293988997073127556538359019802355814918008050500416514241789357023389177644", "price": "0.879", "size": "20", "side": "BUY", "hash": "558db085d818ced556185afc5922966eb3349db6", "best_bid": "0.879", "best_ask": "0.982"}, {"asset_id": "76151979298166149168681611766855150167264661944933736838438696924609959086385", "price": "0.121", "size": "20", "side": "SELL", "hash": "7aec0752ae9f46549cf9c1144e448b4aef921ef8", "best_bid": "0.018", "best_ask": "0.121"}], "timestamp": "1769384515495", "event_type": "price_change"}}
{"_local_timestamp": "2026-01-25T23:41:56.189006+00:00", "data": {"market": "0x70e2c432a9f1c46194b4ed01276fce4b42ba14fa4121bb6a204bd27043fa6ec0", "price_changes": [{"asset_id": "96293988997073127556538359019802355814918008050500416514241789357023389177644", "price": "0.877", "size": "165.71", "side": "BUY", "hash": "60e03cdd34325e37030ce656eaa86f884fc2b424", "best_bid": "0.879", "best_ask": "0.982"}, {"asset_id": "76151979298166149168681611766855150167264661944933736838438696924609959086385", "price": "0.123", "size": "165.71", "side": "SELL", "hash": "0746ae85b8a35629881d2e3de40231e60fdc8b96", "best_bid": "0.018", "best_ask": "0.121"}], "timestamp": "1769384516116", "event_type": "price_change"}}
{"_local_timestamp": "2026-01-25T23:41:57.103466+00:00", "data": {"market": "0x10aa044e00621209c1e6516ed820607867e1939c51e6416e78389133c07a28ca", "asset_id": "106590375374356420328249754119755979864494562435507082169975336179942135107522", "price": "0.16", "size": "13", "fee_rate_bps": "0", "side": "BUY", "timestamp": "1769384517037", "event_type": "last_trade_price", "transaction_hash": "0x0d5d48dfcf3720db04d58d91ec52fe3f90ced5386384bb0a6ec4b1770ae3bd10"}}
{"_local_timestamp": "2026-01-25T23:41:57.121122+00:00", "data": {"market": "0x10aa044e00621209c1e6516ed820607867e1939c51e6416e78389133c07a28ca", "price_changes": [{"asset_id": "106590375374356420328249754119755979864494562435507082169975336179942135107522", "price": "0.16", "size": "33.07", "side": "SELL", "hash": "08b3afd883fe0851f690e7b33524adc820e9a48e", "best_bid": "0.15", "best_ask": "0.16"}, {"asset_id": "114217190078574681732390148219500280529940631077811733810801001867278151517965", "price": "0.84", "size": "33.07", "side": "BUY", "hash": "fe4b25e8c98ee170bf9d31d3ad41009da0f18582", "best_bid": "0.84", "best_ask": "0.85"}], "timestamp": "1769384517006", "event_type": "price_change"}}
{"_local_timestamp": "2026-01-25T23:41:57.121689+00:00", "data": {"market": "0x10aa044e00621209c1e6516ed820607867e1939c51e6416e78389133c07a28ca", "asset_id": "114217190078574681732390148219500280529940631077811733810801001867278151517965", "bids": [{"price": "0.01", "size": "4252.6"}, {"price": "0.02", "size": "3550"}, {"price": "0.03", "size": "100"}, {"price": "0.04", "size": "132.14"}, {"price": "0.05", "size": "120"}, {"price": "0.06", "size": "100"}, {"price": "0.07", "size": "100"}, {"price": "0.08", "size": "100"}, {"price": "0.09", "size": "100"}, {"price": "0.1", "size": "1100"}, {"price": "0.13", "size": "325"}, {"price": "0.2", "size": "350"}, {"price": "0.21", "size": "125"}, {"price": "0.25", "size": "105"}, {"price": "0.29", "size": "150"}, {"price": "0.45", "size": "160"}, {"price": "0.5", "size": "25"}, {"price": "0.55", "size": "180"}, {"price": "0.56", "size": "40"}, {"price": "0.74", "size": "100"}, {"price": "0.75", "size": "15"}, {"price": "0.76", "size": "100"}, {"price": "0.77", "size": "20"}, {"price": "0.78", "size": "10"}, {"price": "0.8", "size": "80"}, {"price": "0.82", "size": "11.48"}, {"price": "0.83", "size": "60"}, {"price": "0.84", "size": "33.07"}], "asks": [{"price": "0.99", "size": "2639.14"}, {"price": "0.98", "size": "26.2"}, {"price": "0.97", "size": "40"}, {"price": "0.96", "size": "84"}, {"price": "0.95", "size": "18.04"}, {"price": "0.94", "size": "20"}, {"price": "0.92", "size": "5.95"}, {"price": "0.91", "size": "5.69"}, {"price": "0.9", "size": "2.44"}, {"price": "0.87", "size": "114.66"}, {"price": "0.86", "size": "18"}, {"price": "0.85", "size": "19"}], "hash": "fe4b25e8c98ee170bf9d31d3ad41009da0f18582", "timestamp": "1769384517006", "event_type": "book"}}
{"_local_timestamp": "2026-01-25T23:41:57.122176+00:00", "data": {"market": "0x10aa044e00621209c1e6516ed820607867e1939c51e6416e78389133c07a28ca", "asset_id": "106590375374356420328249754119755979864494562435507082169975336179942135107522", "bids": [{"price": "0.01", "size": "2639.14"}, {"price": "0.02", "size": "26.2"}, {"price": "0.03", "size": "40"}, {"price": "0.04", "size": "84"}, {"price": "0.05", "size": "18.04"}, {"price": "0.06", "size": "20"}, {"price": "0.08", "size": "5.95"}, {"price": "0.09", "size": "5.69"}, {"price": "0.1", "size": "2.44"}, {"price": "0.13", "size": "114.66"}, {"price": "0.14", "size": "18"}, {"price": "0.15", "size": "19"}], "asks": [{"price": "0.99", "size": "4252.6"}, {"price": "0.98", "size": "3550"}, {"price": "0.97", "size": "100"}, {"price": "0.96", "size": "132.14"}, {"price": "0.95", "size": "120"}, {"price": "0.94", "size": "100"}, {"price": "0.93", "size": "100"}, {"price": "0.92", "size": "100"}, {"price": "0.91", "size": "100"}, {"price": "0.9", "size": "1100"}, {"price": "0.87", "size": "325"}, {"price": "0.8", "size": "350"}, {"price": "0.79", "size": "125"}, {"price": "0.75", "size": "105"}, {"price": "0.71", "size": "150"}, {"price": "0.55", "size": "160"}, {"price": "0.5", "size": "25"}, {"price": "0.45", "size": "180"}, {"price": "0.44", "size": "40"}, {"price": "0.26", "size": "100"}, {"price": "0.25", "size": "15"}, {"price": "0.24", "size": "100"}, {"price": "0.23", "size": "20"}, {"price": "0.22", "size": "10"}, {"price": "0.2", "size": "80"}, {"price": "0.18", "size": "11.48"}, {"price": "0.17", "size": "60"}, {"price": "0.16", "size": "33.07"}], "hash": "08b3afd883fe0851f690e7b33524adc820e9a48e", "timestamp": "1769384517006", "event_type": "book"}}
{"_local_timestamp": "2026-01-25T23:41:57.529678+00:00", "data": {"market": "0x70e2c432a9f1c46194b4ed01276fce4b42ba14fa4121bb6a204bd27043fa6ec0", "price_changes": [{"asset_id": "96293988997073127556538359019802355814918008050500416514241789357023389177644", "price": "0.01", "size": "3783", "side": "BUY", "hash": "c1ab1bed87b76f73ef6dbfced0f6179967bd2203", "best_bid": "0.879", "best_ask": "0.982"}, {"asset_id": "76151979298166149168681611766855150167264661944933736838438696924609959086385", "price": "0.99", "size": "3783", "side": "SELL", "hash": "c361a7653c16bbbd42f03ac796a19e706dda075c", "best_bid": "0.018", "best_ask": "0.121"}], "timestamp": "1769384517460", "event_type": "price_change"}}
{"_local_timestamp": "2026-01-25T23:41:57.530070+00:00", "data": {"market": "0x70e2c432a9f1c46194b4ed01276fce4b42ba14fa4121bb6a204bd27043fa6ec0", "price_changes": [{"asset_id": "96293988997073127556538359019802355814918008050500416514241789357023389177644", "price": "0.02", "size": "2000", "side": "BUY", "hash": "6a9656eb9796410ace592e42cbe376c2a997b7f0", "best_bid": "0.879", "best_ask": "0.982"}, {"asset_id": "76151979298166149168681611766855150167264661944933736838438696924609959086385", "price": "0.98", "size": "2000", "side": "SELL", "hash": "bb0576cca292271ffbe8258e83f4d4a5da3c9eed", "best_bid": "0.018", "best_ask": "0.121"}], "timestamp": "1769384517460", "event_type": "price_change"}}
{"_local_timestamp": "2026-01-25T23:42:11.229943+00:00", "data": {"market": "0x10aa044e00621209c1e6516ed820607867e1939c51e6416e78389133c07a28ca", "price_changes": [{"asset_id": "106590375374356420328249754119755979864494562435507082169975336179942135107522", "price": "0.15", "size": "0", "side": "BUY", "hash": "1e17ac4a09df7e3df4a31d258db4b254311d6de1", "best_bid": "0.14", "best_ask": "0.16"}, {"asset_id": "114217190078574681732390148219500280529940631077811733810801001867278151517965", "price": "0.85", "size": "0", "side": "SELL", "hash": "cf2de0fb3ef8547789a03bb16b5c7dabf5933a1c", "best_bid": "0.84", "best_ask": "0.86"}], "timestamp": "1769384531158", "event_type": "price_change"}}
{"_local_timestamp": "2026-01-25T23:42:11.550509+00:00", "data": {"market": "0x70e2c432a9f1c46194b4ed01276fce4b42ba14fa4121bb6a204bd27043fa6ec0", "price_changes": [{"asset_id": "96293988997073127556538359019802355814918008050500416514241789357023389177644", "price": "0.876", "size": "0", "side": "BUY", "hash": "28746c08b84c30fb1aef67f9c7fd035c51433881", "best_bid": "0.879", "best_ask": "0.982"}, {"asset_id": "76151979298166149168681611766855150167264661944933736838438696924609959086385", "price": "0.124", "size": "0", "side": "SELL", "hash": "b590bd46cfbb85f01f2807e8f4f3ac47525a1313", "best_bid": "0.018", "best_ask": "0.121"}], "timestamp": "1769384531476", "event_type": "price_change"}}
{"_local_timestamp": "2026-01-25T23:42:12.526395+00:00", "data": {"market": "0x70e2c432a9f1c46194b4ed01276fce4b42ba14fa4121bb6a204bd27043fa6ec0", "price_changes": [{"asset_id": "96293988997073127556538359019802355814918008050500416514241789357023389177644", "price": "0.877", "size": "135.71", "side": "BUY", "hash": "6b05cbb19dee2a719eecb550370073876f9fe55b", "best_bid": "0.879", "best_ask": "0.982"}, {"asset_id": "76151979298166149168681611766855150167264661944933736838438696924609959086385", "price": "0.123", "size": "135.71", "side": "SELL", "hash": "a8db6bb8cc8213debbff2327bd861fd583961ba5", "best_bid": "0.018", "best_ask": "0.121"}], "timestamp": "1769384532454", "event_type": "price_change"}}
{"_local_timestamp": "2026-01-25T23:42:12.532331+00:00", "data": {"market": "0x10aa044e00621209c1e6516ed820607867e1939c51e6416e78389133c07a28ca", "price_changes": [{"asset_id": "106590375374356420328249754119755979864494562435507082169975336179942135107522", "price": "0.15", "size": "34", "side": "BUY", "hash": "5dc9fd9719b2cf6b0bc594ded535370e2ea33366", "best_bid": "0.15", "best_ask": "0.16"}, {"asset_id": "114217190078574681732390148219500280529940631077811733810801001867278151517965", "price": "0.85", "size": "34", "side": "SELL", "hash": "696e57f9a2e953963efb7eaab6406a55ae119800", "best_bid": "0.84", "best_ask": "0.85"}], "timestamp": "1769384532463", "event_type": "price_change"}}
{"_local_timestamp": "2026-01-25T23:42:25.072044+00:00", "data": {"market": "0x70e2c432a9f1c46194b4ed01276fce4b42ba14fa4121bb6a204bd27043fa6ec0", "price_changes": [{"asset_id": "96293988997073127556538359019802355814918008050500416514241789357023389177644", "price": "0.21", "size": "50", "side": "BUY", "hash": "661f3aceec6a87a6d2b6986ab547a0fe2262eaf3", "best_bid": "0.879", "best_ask": "0.982"}, {"asset_id": "76151979298166149168681611766855150167264661944933736838438696924609959086385", "price": "0.79", "size": "50", "side": "SELL", "hash": "68b1e731a65b8f260308a41032b5f3c66a45d040", "best_bid": "0.018", "best_ask": "0.121"}], "timestamp": "1769384544907", "event_type": "price_change"}}
{"_local_timestamp": "2026-01-25T23:42:25.147432+00:00", "data": {"market": "0x70e2c432a9f1c46194b4ed01276fce4b42ba14fa4121bb6a204bd27043fa6ec0", "price_changes": [{"asset_id": "96293988997073127556538359019802355814918008050500416514241789357023389177644", "price": "0.16", "size": "100", "side": "BUY", "hash": "70c42526eb03e463edc4427e8ecad930b5fb1058", "best_bid": "0.879", "best_ask": "0.982"}, {"asset_id": "76151979298166149168681611766855150167264661944933736838438696924609959086385", "price": "0.84", "size": "100", "side": "SELL", "hash": "f2c9637b92c3a65adbbbefa5d4460a58187dc41a", "best_bid": "0.018", "best_ask": "0.121"}], "timestamp": "1769384544944", "event_type": "price_change"}}
{"_local_timestamp": "2026-01-25T23:42:25.147891+00:00", "data": {"market": "0x70e2c432a9f1c46194b4ed01276fce4b42ba14fa4121bb6a204bd27043fa6ec0", "price_changes": [{"asset_id": "96293988997073127556538359019802355814918008050500416514241789357023389177644", "price": "0.11", "size": "125", "side": "BUY", "hash": "06b6131b2a792bbf15b94ad4e9423b99bcdee74b", "best_bid": "0.879", "best_ask": "0.982"}, {"asset_id": "76151979298166149168681611766855150167264661944933736838438696924609959086385", "price": "0.89", "size": "125", "side": "SELL", "hash": "ce1aa66e74109a3c4ccdb70371a79e7a0e6425d3", "best_bid": "0.018", "best_ask": "0.121"}], "timestamp": "1769384544960", "event_type": "price_change"}}
{"_local_timestamp": "2026-01-25T23:42:36.360952+00:00", "data": {"market": "0x026f75cda28b435d52c8615dc2eaa8895b4632e9f53c98255f2bced50fbb5018", "price_changes": [{"asset_id": "103477786055085350112953174136231624107339341173836019810109648103195092330225", "price": "0.12", "size": "14.09", "side": "BUY", "hash": "378f7e8e1a876bbe1b0061358a2eb537e8fb91f7", "best_bid": "0.12", "best_ask": "0.13"}, {"asset_id": "18282828012097738947825685359604327312283762551135248913642539025764020349015", "price": "0.88", "size": "14.09", "side": "SELL", "hash": "f012b126cc0aab174830072cc58eefc89712b727", "best_bid": "0.87", "best_ask": "0.88"}], "timestamp": "1769384556258", "event_type": "price_change"}}
{"_local_timestamp": "2026-01-25T23:42:40.107327+00:00", "data": {"market": "0x70e2c432a9f1c46194b4ed01276fce4b42ba14fa4121bb6a204bd27043fa6ec0", "price_changes": [{"asset_id": "96293988997073127556538359019802355814918008050500416514241789357023389177644", "price": "0.01", "size": "4783", "side": "BUY", "hash": "33f4eea0bddb6fa2450067fcab3bfffe280b08a4", "best_bid": "0.879", "best_ask": "0.982"}, {"asset_id": "76151979298166149168681611766855150167264661944933736838438696924609959086385", "price": "0.99", "size": "4783", "side": "SELL", "hash": "bc4ba57d2ddf13df93e320a27567cbd1cf124163", "best_bid": "0.018", "best_ask": "0.121"}], "timestamp": "1769384559918", "event_type": "price_change"}}
{"_local_timestamp": "2026-01-25T23:42:40.171854+00:00", "data": {"market": "0x70e2c432a9f1c46194b4ed01276fce4b42ba14fa4121bb6a204bd27043fa6ec0", "price_changes": [{"asset_id": "96293988997073127556538359019802355814918008050500416514241789357023389177644", "price": "0.02", "size": "2400", "side": "BUY", "hash": "4a4fa5b2531b376735cadbea33009a45f115134b", "best_bid": "0.879", "best_ask": "0.982"}, {"asset_id": "76151979298166149168681611766855150167264661944933736838438696924609959086385", "price": "0.98", "size": "2400", "side": "SELL", "hash": "d2a8de763e117bdfdb239b2e06ec7ee65e840285", "best_bid": "0.018", "best_ask": "0.121"}], "timestamp": "1769384559964", "event_type": "price_change"}}
{"_local_timestamp": "2026-01-25T23:42:40.194825+00:00", "data": {"market": "0x70e2c432a9f1c46194b4ed01276fce4b42ba14fa4121bb6a204bd27043fa6ec0", "price_changes": [{"asset_id": "96293988997073127556538359019802355814918008050500416514241789357023389177644", "price": "0.06", "size": "227.98", "side": "BUY", "hash": "eb9c046b95fe95562eb2af0d25d04108adde553a", "best_bid": "0.879", "best_ask": "0.982"}, {"asset_id": "76151979298166149168681611766855150167264661944933736838438696924609959086385", "price": "0.94", "size": "227.98", "side": "SELL", "hash": "8d7a654a6a0a09ceba3c5ea7d86b722f0adf3035", "best_bid": "0.018", "best_ask": "0.121"}], "timestamp": "1769384559989", "event_type": "price_change"}}
{"_local_timestamp": "2026-01-25T23:42:47.326947+00:00", "data": {"market": "0x70e2c432a9f1c46194b4ed01276fce4b42ba14fa4121bb6a204bd27043fa6ec0", "price_changes": [{"asset_id": "96293988997073127556538359019802355814918008050500416514241789357023389177644", "price": "0.01", "size": "2783", "side": "BUY", "hash": "0895d1be175eb43e63e597f66948397a0e0c4ef4", "best_bid": "0.879", "best_ask": "0.982"}, {"asset_id": "76151979298166149168681611766855150167264661944933736838438696924609959086385", "price": "0.99", "size": "2783", "side": "SELL", "hash": "00ce893c92b4e498bc6331c1c114d269254a724f", "best_bid": "0.018", "best_ask": "0.121"}], "timestamp": "1769384567097", "event_type": "price_change"}}
{"_local_timestamp": "2026-01-25T23:42:48.287172+00:00", "data": {"market": "0x10aa044e00621209c1e6516ed820607867e1939c51e6416e78389133c07a28ca", "price_changes": [{"asset_id": "106590375374356420328249754119755979864494562435507082169975336179942135107522", "price": "0.05", "size": "6.85", "side": "BUY", "hash": "fd2a999ef49ed2ca25621f3222a1954b0dffde78", "best_bid": "0.15", "best_ask": "0.16"}, {"asset_id": "114217190078574681732390148219500280529940631077811733810801001867278151517965", "price": "0.95", "size": "6.85", "side": "SELL", "hash": "5f78f8c534022f5adfd231af4e8d45c85c22e977", "best_bid": "0.84", "best_ask": "0.85"}], "timestamp": "1769384568167", "event_type": "price_change"}}
{"_local_timestamp": "2026-01-25T23:42:48.530895+00:00", "data": {"market": "0x026f75cda28b435d52c8615dc2eaa8895b4632e9f53c98255f2bced50fbb5018", "price_changes": [{"asset_id": "103477786055085350112953174136231624107339341173836019810109648103195092330225", "price": "0.12", "size": "44.21", "side": "BUY", "hash": "e18c0c434f38bfb158c0b8a3ce33f87eac2e9e1c", "best_bid": "0.12", "best_ask": "0.13"}, {"asset_id": "18282828012097738947825685359604327312283762551135248913642539025764020349015", "price": "0.88", "size": "44.21", "side": "SELL", "hash": "4e035ce74e1728dddfc36bec6b644edfa1116d4d", "best_bid": "0.87", "best_ask": "0.88"}], "timestamp": "1769384568412", "event_type": "price_change"}}
{"_local_timestamp": "2026-01-25T23:42:48.578960+00:00", "data": {"market": "0x026f75cda28b435d52c8615dc2eaa8895b4632e9f53c98255f2bced50fbb5018", "price_changes": [{"asset_id": "103477786055085350112953174136231624107339341173836019810109648103195092330225", "price": "0.12", "size": "74.33", "side": "BUY", "hash": "bb0b0d317dc10ce1f22ff3da5a4b5288aae7be0f", "best_bid": "0.12", "best_ask": "0.13"}, {"asset_id": "18282828012097738947825685359604327312283762551135248913642539025764020349015", "price": "0.88", "size": "74.33", "side": "SELL", "hash": "cb6276399037b64812ffcaf3431c7fc5a8b65d87", "best_bid": "0.87", "best_ask": "0.88"}], "timestamp": "1769384568454", "event_type": "price_change"}}
{"_local_timestamp": "2026-01-25T23:42:48.579472+00:00", "data": {"market": "0x026f75cda28b435d52c8615dc2eaa8895b4632e9f53c98255f2bced50fbb5018", "price_changes": [{"asset_id": "103477786055085350112953174136231624107339341173836019810109648103195092330225", "price": "0.12", "size": "104.45", "side": "BUY", "hash": "67570ee5d571d6c2fc071a6b48190a8fd7ff36a5", "best_bid": "0.12", "best_ask": "0.13"}, {"asset_id": "18282828012097738947825685359604327312283762551135248913642539025764020349015", "price": "0.88", "size": "104.45", "side": "SELL", "hash": "21a4e4be47ba668ca158a3ab2274f557f78de59c", "best_bid": "0.87", "best_ask": "0.88"}], "timestamp": "1769384568455", "event_type": "price_change"}}
{"_local_timestamp": "2026-01-25T23:42:48.579850+00:00", "data": {"market": "0x026f75cda28b435d52c8615dc2eaa8895b4632e9f53c98255f2bced50fbb5018", "price_changes": [{"asset_id": "103477786055085350112953174136231624107339341173836019810109648103195092330225", "price": "0.12", "size": "134.57", "side": "BUY", "hash": "cbac2c18b31d2bcd606f2c65d74620426691dc4e", "best_bid": "0.12", "best_ask": "0.13"}, {"asset_id": "18282828012097738947825685359604327312283762551135248913642539025764020349015", "price": "0.88", "size": "134.57", "side": "SELL", "hash": "503165189ba69314bbf27646f936a0f348efa65b", "best_bid": "0.87", "best_ask": "0.88"}], "timestamp": "1769384568455", "event_type": "price_change"}}
{"_local_timestamp": "2026-01-25T23:42:48.835436+00:00", "data": {"market": "0x10aa044e00621209c1e6516ed820607867e1939c51e6416e78389133c07a28ca", "price_changes": [{"asset_id": "106590375374356420328249754119755979864494562435507082169975336179942135107522", "price": "0.07", "size": "7.99", "side": "BUY", "hash": "5e6b4e094c8eb3d68d563059de7af9ab53813f55", "best_bid": "0.15", "best_ask": "0.16"}, {"asset_id": "114217190078574681732390148219500280529940631077811733810801001867278151517965", "price": "0.93", "size": "7.99", "side": "SELL", "hash": "865683a48f5d7864ea9cc5d6370958ce5b7a7002", "best_bid": "0.84", "best_ask": "0.85"}], "timestamp": "1769384568715", "event_type": "price_change"}}
{"_local_timestamp": "2026-01-25T23:42:50.480010+00:00", "data": {"market": "0x10aa044e00621209c1e6516ed820607867e1939c51e6416e78389133c07a28ca", "price_changes": [{"asset_id": "106590375374356420328249754119755979864494562435507082169975336179942135107522", "price": "0.06", "size": "0", "side": "BUY", "hash": "d10ce0dd066c76a8f0a6fc2c89f0981822c5ff76", "best_bid": "0.15", "best_ask": "0.16"}, {"asset_id": "114217190078574681732390148219500280529940631077811733810801001867278151517965", "price": "0.94", "size": "0", "side": "SELL", "hash": "70888d4a314ff59da4600b89001632b49e043876", "best_bid": "0.84", "best_ask": "0.85"}], "timestamp": "1769384570379", "event_type": "price_change"}}
{"_local_timestamp": "2026-01-25T23:42:50.513662+00:00", "data": {"market": "0x10aa044e00621209c1e6516ed820607867e1939c51e6416e78389133c07a28ca", "price_changes": [{"asset_id": "106590375374356420328249754119755979864494562435507082169975336179942135107522", "price": "0.08", "size": "25.95", "side": "BUY", "hash": "b7ec596afb9a45da44e950c7e190073e81bb39fd", "best_bid": "0.15", "best_ask": "0.16"}, {"asset_id": "114217190078574681732390148219500280529940631077811733810801001867278151517965", "price": "0.92", "size": "25.95", "side": "SELL", "hash": "7c6c0030b58b3154cf1aa46c8107b74e739b4198", "best_bid": "0.84", "best_ask": "0.85"}], "timestamp": "1769384570412", "event_type": "price_change"}}
{"_local_timestamp": "2026-01-25T23:43:32.633186+00:00", "data": {"market": "0x026f75cda28b435d52c8615dc2eaa8895b4632e9f53c98255f2bced50fbb5018", "price_changes": [{"asset_id": "103477786055085350112953174136231624107339341173836019810109648103195092330225", "price": "0.12", "size": "14.09", "side": "BUY", "hash": "96e5dec075e1baabb8e3c5fb90a48c9702223abe", "best_bid": "0.12", "best_ask": "0.13"}, {"asset_id": "18282828012097738947825685359604327312283762551135248913642539025764020349015", "price": "0.88", "size": "14.09", "side": "SELL", "hash": "450c3b8336d79c9a08e854a8582b3bc3330acfcc", "best_bid": "0.87", "best_ask": "0.88"}], "timestamp": "1769384612513", "event_type": "price_change"}}
{"_local_timestamp": "2026-01-25T23:43:45.051518+00:00", "data": {"market": "0x026f75cda28b435d52c8615dc2eaa8895b4632e9f53c98255f2bced50fbb5018", "price_changes": [{"asset_id": "103477786055085350112953174136231624107339341173836019810109648103195092330225", "price": "0.12", "size": "44.21", "side": "BUY", "hash": "e6c661ba3a6f51eeaa8bf87dfb90560dc43b036a", "best_bid": "0.12", "best_ask": "0.13"}, {"asset_id": "18282828012097738947825685359604327312283762551135248913642539025764020349015", "price": "0.88", "size": "44.21", "side": "SELL", "hash": "7434b34c888c30e9c97580c19034b489c28bbed3", "best_bid": "0.87", "best_ask": "0.88"}], "timestamp": "1769384624942", "event_type": "price_change"}}
{"_local_timestamp": "2026-01-25T23:43:45.052040+00:00", "data": {"market": "0x026f75cda28b435d52c8615dc2eaa8895b4632e9f53c98255f2bced50fbb5018", "price_changes": [{"asset_id": "103477786055085350112953174136231624107339341173836019810109648103195092330225", "price": "0.12", "size": "74.33", "side": "BUY", "hash": "a6bed2dd5203c1d3809925e2d1c80b15dbb19adb", "best_bid": "0.12", "best_ask": "0.13"}, {"asset_id": "18282828012097738947825685359604327312283762551135248913642539025764020349015", "price": "0.88", "size": "74.33", "side": "SELL", "hash": "621b784c3ebce298aaf0f2bfc65c29ef1be78f36", "best_bid": "0.87", "best_ask": "0.88"}], "timestamp": "1769384624942", "event_type": "price_change"}}
{"_local_timestamp": "2026-01-25T23:43:45.055683+00:00", "data": {"market": "0x026f75cda28b435d52c8615dc2eaa8895b4632e9f53c98255f2bced50fbb5018", "price_changes": [{"asset_id": "103477786055085350112953174136231624107339341173836019810109648103195092330225", "price": "0.12", "size": "104.45", "side": "BUY", "hash": "759019e69f6dbed7079d4c6333a0f4c83c178760", "best_bid": "0.12", "best_ask": "0.13"}, {"asset_id": "18282828012097738947825685359604327312283762551135248913642539025764020349015", "price": "0.88", "size": "104.45", "side": "SELL", "hash": "4209512ada3537cc7af0580958177cac936e9838", "best_bid": "0.87", "best_ask": "0.88"}], "timestamp": "1769384624943", "event_type": "price_change"}}
{"_local_timestamp": "2026-01-25T23:43:45.056063+00:00", "data": {"market": "0x026f75cda28b435d52c8615dc2eaa8895b4632e9f53c98255f2bced50fbb5018", "price_changes": [{"asset_id": "103477786055085350112953174136231624107339341173836019810109648103195092330225", "price": "0.12", "size": "134.57", "side": "BUY", "hash": "3db350042ffdc587ee48c806477ce6d9b242e6de", "best_bid": "0.12", "best_ask": "0.13"}, {"asset_id": "18282828012097738947825685359604327312283762551135248913642539025764020349015", "price": "0.88", "size": "134.57", "side": "SELL", "hash": "44e36001219c788989fcdc11bc2ee9c9dcb6a611", "best_bid": "0.87", "best_ask": "0.88"}], "timestamp": "1769384624943", "event_type": "price_change"}}
{"_local_timestamp": "2026-01-25T23:43:48.641418+00:00", "data": {"market": "0x70e2c432a9f1c46194b4ed01276fce4b42ba14fa4121bb6a204bd27043fa6ec0", "price_changes": [{"asset_id": "96293988997073127556538359019802355814918008050500416514241789357023389177644", "price": "0.02", "size": "3400", "side": "BUY", "hash": "eb1171fb748ef64887fccde70674fb688421b8f4", "best_bid": "0.879", "best_ask": "0.982"}, {"asset_id": "76151979298166149168681611766855150167264661944933736838438696924609959086385", "price": "0.98", "size": "3400", "side": "SELL", "hash": "fe84f65d6ef10d598ab922fdad216002956e9244", "best_bid": "0.018", "best_ask": "0.121"}], "timestamp": "1769384628548", "event_type": "price_change"}}
{"_local_timestamp": "2026-01-25T23:43:48.735016+00:00", "data": {"market": "0x026f75cda28b435d52c8615dc2eaa8895b4632e9f53c98255f2bced50fbb5018", "price_changes": [{"asset_id": "18282828012097738947825685359604327312283762551135248913642539025764020349015", "price": "0.29", "size": "0", "side": "BUY", "hash": "090674aadcb93cb085deeb88f8063253e46b1cad", "best_bid": "0.87", "best_ask": "0.88"}, {"asset_id": "103477786055085350112953174136231624107339341173836019810109648103195092330225", "price": "0.71", "size": "0", "side": "SELL", "hash": "c2a0ca475280c70b7991bfd4cf5dfa6ae7565a6f", "best_bid": "0.12", "best_ask": "0.13"}], "timestamp": "1769384628647", "event_type": "price_change"}}
{"_local_timestamp": "2026-01-25T23:43:48.775574+00:00", "data": {"market": "0x026f75cda28b435d52c8615dc2eaa8895b4632e9f53c98255f2bced50fbb5018", "price_changes": [{"asset_id": "18282828012097738947825685359604327312283762551135248913642539025764020349015", "price": "0.34", "size": "5", "side": "BUY", "hash": "1649c792181ce22a0b655c06da1c0a4a16cc5769", "best_bid": "0.87", "best_ask": "0.88"}, {"asset_id": "103477786055085350112953174136231624107339341173836019810109648103195092330225", "price": "0.66", "size": "5", "side": "SELL", "hash": "bd414004ab9d303c40920b828090a32108e13142", "best_bid": "0.12", "best_ask": "0.13"}], "timestamp": "1769384628693", "event_type": "price_change"}}
{"_local_timestamp": "2026-01-25T23:43:53.136711+00:00", "data": {"market": "0x026f75cda28b435d52c8615dc2eaa8895b4632e9f53c98255f2bced50fbb5018", "price_changes": [{"asset_id": "103477786055085350112953174136231624107339341173836019810109648103195092330225", "price": "0.02", "size": "285", "side": "BUY", "hash": "dd578fc3d9c219fbe22bf4c221d546fce9b917a7", "best_bid": "0.12", "best_ask": "0.13"}, {"asset_id": "18282828012097738947825685359604327312283762551135248913642539025764020349015", "price": "0.98", "size": "285", "side": "SELL", "hash": "9b9b35a6ad1fde77b3cdfddfdf6ba5a4576c1251", "best_bid": "0.87", "best_ask": "0.88"}], "timestamp": "1769384632954", "event_type": "price_change"}}
{"_local_timestamp": "2026-01-25T23:43:53.431822+00:00", "data": {"market": "0x026f75cda28b435d52c8615dc2eaa8895b4632e9f53c98255f2bced50fbb5018", "price_changes": [{"asset_id": "103477786055085350112953174136231624107339341173836019810109648103195092330225", "price": "0.02", "size": "299.28", "side": "BUY", "hash": "4027c874757b4b0f51fd42df13647c4348f75063", "best_bid": "0.12", "best_ask": "0.13"}, {"asset_id": "18282828012097738947825685359604327312283762551135248913642539025764020349015", "price": "0.98", "size": "299.28", "side": "SELL", "hash": "a58dea39ff71de8623e5219cd9559ab781be5da1", "best_bid": "0.87", "best_ask": "0.88"}], "timestamp": "1769384633264", "event_type": "price_change"}}
{"_local_timestamp": "2026-01-25T23:44:21.499606+00:00", "data": {"market": "0x70e2c432a9f1c46194b4ed01276fce4b42ba14fa4121bb6a204bd27043fa6ec0", "price_changes": [{"asset_id": "96293988997073127556538359019802355814918008050500416514241789357023389177644", "price": "0.05", "size": "360", "side": "BUY", "hash": "a135c89cba07382b004059e7b14af85e34fdd235", "best_bid": "0.879", "best_ask": "0.982"}, {"asset_id": "76151979298166149168681611766855150167264661944933736838438696924609959086385", "price": "0.95", "size": "360", "side": "SELL", "hash": "fb693bf9b1866b2baf81e13053c654adbd4f9f21", "best_bid": "0.018", "best_ask": "0.121"}], "timestamp": "1769384660847", "event_type": "price_change"}}
{"_local_timestamp": "2026-01-25T23:44:21.677760+00:00", "data": {"market": "0x70e2c432a9f1c46194b4ed01276fce4b42ba14fa4121bb6a204bd27043fa6ec0", "price_changes": [{"asset_id": "96293988997073127556538359019802355814918008050500416514241789357023389177644", "price": "0.11", "size": "325", "side": "BUY", "hash": "b169dc1b725a371a58d4230cf58b8ad327576361", "best_bid": "0.879", "best_ask": "0.982"}, {"asset_id": "76151979298166149168681611766855150167264661944933736838438696924609959086385", "price": "0.89", "size": "325", "side": "SELL", "hash": "cfa0eaa1d13bb8e5b5496809fd6df308100518c5", "best_bid": "0.018", "best_ask": "0.121"}], "timestamp": "1769384660940", "event_type": "price_change"}}
{"_local_timestamp": "2026-01-25T23:44:21.681409+00:00", "data": {"market": "0x70e2c432a9f1c46194b4ed01276fce4b42ba14fa4121bb6a204bd27043fa6ec0", "price_changes": [{"asset_id": "96293988997073127556538359019802355814918008050500416514241789357023389177644", "price": "0.21", "size": "150", "side": "BUY", "hash": "8531c44e5d080296659f7e3edec82d8e1a022ced", "best_bid": "0.879", "best_ask": "0.982"}, {"asset_id": "76151979298166149168681611766855150167264661944933736838438696924609959086385", "price": "0.79", "size": "150", "side": "SELL", "hash": "138be97cda82fb681252f415e3606e905156f574", "best_bid": "0.018", "best_ask": "0.121"}], "timestamp": "1769384660971", "event_type": "price_change"}}
{"_local_timestamp": "2026-01-25T23:44:21.695195+00:00", "data": {"market": "0x70e2c432a9f1c46194b4ed01276fce4b42ba14fa4121bb6a204bd27043fa6ec0", "price_changes": [{"asset_id": "96293988997073127556538359019802355814918008050500416514241789357023389177644", "price": "0.16", "size": "250", "side": "BUY", "hash": "f105f6374eeb31374b4046b26dacd05c0c6dd51b", "best_bid": "0.879", "best_ask": "0.982"}, {"asset_id": "76151979298166149168681611766855150167264661944933736838438696924609959086385", "price": "0.84", "size": "250", "side": "SELL", "hash": "be02358dca22817b5874ff0b0f2e6a780e21c1ff", "best_bid": "0.018", "best_ask": "0.121"}], "timestamp": "1769384660978", "event_type": "price_change"}}
{"_local_timestamp": "2026-01-25T23:44:23.140669+00:00", "data": {"market": "0x70e2c432a9f1c46194b4ed01276fce4b42ba14fa4121bb6a204bd27043fa6ec0", "price_changes": [{"asset_id": "76151979298166149168681611766855150167264661944933736838438696924609959086385", "price": "0.017", "size": "0", "side": "BUY", "hash": "701f18ba25768eafb0a8b91780389e035053a2a6", "best_bid": "0.018", "best_ask": "0.121"}, {"asset_id": "96293988997073127556538359019802355814918008050500416514241789357023389177644", "price": "0.983", "size": "0", "side": "SELL", "hash": "c953daf472d38c9506907f263d4ee92ec5254a3e", "best_bid": "0.879", "best_ask": "0.982"}], "timestamp": "1769384662890", "event_type": "price_change"}}
{"_local_timestamp": "2026-01-25T23:44:31.949630+00:00", "data": {"market": "0x026f75cda28b435d52c8615dc2eaa8895b4632e9f53c98255f2bced50fbb5018", "price_changes": [{"asset_id": "103477786055085350112953174136231624107339341173836019810109648103195092330225", "price": "0.12", "size": "14.09", "side": "BUY", "hash": "390433ff548731da9a14259452524f0bac4275d4", "best_bid": "0.12", "best_ask": "0.13"}, {"asset_id": "18282828012097738947825685359604327312283762551135248913642539025764020349015", "price": "0.88", "size": "14.09", "side": "SELL", "hash": "767cd5f14fcfc0b60f789b55dbe42587941426d3", "best_bid": "0.87", "best_ask": "0.88"}], "timestamp": "1769384671660", "event_type": "price_change"}}
{"_local_timestamp": "2026-01-25T23:44:44.584203+00:00", "data": {"market": "0x026f75cda28b435d52c8615dc2eaa8895b4632e9f53c98255f2bced50fbb5018", "price_changes": [{"asset_id": "103477786055085350112953174136231624107339341173836019810109648103195092330225", "price": "0.12", "size": "44.21", "side": "BUY", "hash": "e69c756ea8d8ce3308ff693b83181f4488f07b4d", "best_bid": "0.12", "best_ask": "0.13"}, {"asset_id": "18282828012097738947825685359604327312283762551135248913642539025764020349015", "price": "0.88", "size": "44.21", "side": "SELL", "hash": "a3e0d9aafc1ea086d83aa9dfe63513b904695124", "best_bid": "0.87", "best_ask": "0.88"}], "timestamp": "1769384684432", "event_type": "price_change"}}
{"_local_timestamp": "2026-01-25T23:44:44.587844+00:00", "data": {"market": "0x026f75cda28b435d52c8615dc2eaa8895b4632e9f53c98255f2bced50fbb5018", "price_changes": [{"asset_id": "103477786055085350112953174136231624107339341173836019810109648103195092330225", "price": "0.12", "size": "74.33", "side": "BUY", "hash": "5cc23cf55e2a8ec71a174f6e0351a97ca928775d", "best_bid": "0.12", "best_ask": "0.13"}, {"asset_id": "18282828012097738947825685359604327312283762551135248913642539025764020349015", "price": "0.88", "size": "74.33", "side": "SELL", "hash": "58f1c7dba2653ac95320c3c638e6131b722797e2", "best_bid": "0.87", "best_ask": "0.88"}], "timestamp": "1769384684433", "event_type": "price_change"}}
{"_local_timestamp": "2026-01-25T23:44:44.588328+00:00", "data": {"market": "0x026f75cda28b435d52c8615dc2eaa8895b4632e9f53c98255f2bced50fbb5018", "price_changes": [{"asset_id": "103477786055085350112953174136231624107339341173836019810109648103195092330225", "price": "0.12", "size": "104.45", "side": "BUY", "hash": "03cbd9f3b811b30d95c3fdda7262fb287f5c69ff", "best_bid": "0.12", "best_ask": "0.13"}, {"asset_id": "18282828012097738947825685359604327312283762551135248913642539025764020349015", "price": "0.88", "size": "104.45", "side": "SELL", "hash": "470161cc7253ef187707c98f9998d002c9b7cc1d", "best_bid": "0.87", "best_ask": "0.88"}], "timestamp": "1769384684433", "event_type": "price_change"}}
{"_local_timestamp": "2026-01-25T23:44:44.588778+00:00", "data": {"market": "0x026f75cda28b435d52c8615dc2eaa8895b4632e9f53c98255f2bced50fbb5018", "price_changes": [{"asset_id": "103477786055085350112953174136231624107339341173836019810109648103195092330225", "price": "0.12", "size": "134.57", "side": "BUY", "hash": "2de3a0b2333dd26e1bf8c81c9083d94aca130ca0", "best_bid": "0.12", "best_ask": "0.13"}, {"asset_id": "18282828012097738947825685359604327312283762551135248913642539025764020349015", "price": "0.88", "size": "134.57", "side": "SELL", "hash": "7d2e8e54de7e0c9ba72b93703dea40ce94c17ef3", "best_bid": "0.87", "best_ask": "0.88"}], "timestamp": "1769384684434", "event_type": "price_change"}}
{"_local_timestamp": "2026-01-25T23:44:47.716628+00:00", "data": {"market": "0x70e2c432a9f1c46194b4ed01276fce4b42ba14fa4121bb6a204bd27043fa6ec0", "price_changes": [{"asset_id": "96293988997073127556538359019802355814918008050500416514241789357023389177644", "price": "0.875", "size": "0", "side": "BUY", "hash": "ae14f728a0d35192ff3ef91095fd17c700f29e71", "best_bid": "0.879", "best_ask": "0.982"}, {"asset_id": "76151979298166149168681611766855150167264661944933736838438696924609959086385", "price": "0.125", "size": "0", "side": "SELL", "hash": "87e90da3493d4c4fbb3284483d876b31e05a49db", "best_bid": "0.018", "best_ask": "0.121"}], "timestamp": "1769384687471", "event_type": "price_change"}}
{"_local_timestamp": "2026-01-25T23:44:47.822662+00:00", "data": {"market": "0x70e2c432a9f1c46194b4ed01276fce4b42ba14fa4121bb6a204bd27043fa6ec0", "price_changes": [{"asset_id": "96293988997073127556538359019802355814918008050500416514241789357023389177644", "price": "0.011", "size": "5.72", "side": "BUY", "hash": "5e5a8fb9422941a0e6543c0117ec7367160011f2", "best_bid": "0.879", "best_ask": "0.982"}, {"asset_id": "76151979298166149168681611766855150167264661944933736838438696924609959086385", "price": "0.989", "size": "5.72", "side": "SELL", "hash": "0a4f32493d8008bc829333d482fc62ecf2bfb6cc", "best_bid": "0.018", "best_ask": "0.121"}], "timestamp": "1769384687533", "event_type": "price_change"}}
{"_local_timestamp": "2026-01-25T23:44:47.823164+00:00", "data": {"market": "0x70e2c432a9f1c46194b4ed01276fce4b42ba14fa4121bb6a204bd27043fa6ec0", "price_changes": [{"asset_id": "96293988997073127556538359019802355814918008050500416514241789357023389177644", "price": "0.06", "size": "200", "side": "BUY", "hash": "5e5a8fb9422941a0e6543c0117ec7367160011f2", "best_bid": "0.879", "best_ask": "0.982"}, {"asset_id": "76151979298166149168681611766855150167264661944933736838438696924609959086385", "price": "0.94", "size": "200", "side": "SELL", "hash": "0a4f32493d8008bc829333d482fc62ecf2bfb6cc", "best_bid": "0.018", "best_ask": "0.121"}], "timestamp": "1769384687533", "event_type": "price_change"}}
{"_local_timestamp": "2026-01-25T23:44:48.144225+00:00", "data": {"market": "0x70e2c432a9f1c46194b4ed01276fce4b42ba14fa4121bb6a204bd27043fa6ec0", "price_changes": [{"asset_id": "96293988997073127556538359019802355814918008050500416514241789357023389177644", "price": "0.021", "size": "10.05", "side": "BUY", "hash": "846a67ed42460987844d7257f81069cd92b99348", "best_bid": "0.879", "best_ask": "0.982"}, {"asset_id": "76151979298166149168681611766855150167264661944933736838438696924609959086385", "price": "0.979", "size": "10.05", "side": "SELL", "hash": "694395e80353e3a6a683310f7258685e3eee025b", "best_bid": "0.018", "best_ask": "0.121"}], "timestamp": "1769384687943", "event_type": "price_change"}}
{"_local_timestamp": "2026-01-25T23:44:48.144734+00:00", "data": {"market": "0x70e2c432a9f1c46194b4ed01276fce4b42ba14fa4121bb6a204bd27043fa6ec0", "price_changes": [{"asset_id": "96293988997073127556538359019802355814918008050500416514241789357023389177644", "price": "0.161", "size": "7.61", "side": "BUY", "hash": "d08ef0c3ae134cdd2776e3984a6060ab8731ee21", "best_bid": "0.879", "best_ask": "0.982"}, {"asset_id": "76151979298166149168681611766855150167264661944933736838438696924609959086385", "price": "0.839", "size": "7.61", "side": "SELL", "hash": "023aba02defa4e922676d4b208674b873e1484ed", "best_bid": "0.018", "best_ask": "0.121"}], "timestamp": "1769384687943", "event_type": "price_change"}}
{"_local_timestamp": "2026-01-25T23:44:48.145263+00:00", "data": {"market": "0x70e2c432a9f1c46194b4ed01276fce4b42ba14fa4121bb6a204bd27043fa6ec0", "price_changes": [{"asset_id": "96293988997073127556538359019802355814918008050500416514241789357023389177644", "price": "0.061", "size": "7.25", "side": "BUY", "hash": "84d23f3b027dec37eca762022b8b368a2403996f", "best_bid": "0.879", "best_ask": "0.982"}, {"asset_id": "76151979298166149168681611766855150167264661944933736838438696924609959086385", "price": "0.939", "size": "7.25", "side": "SELL", "hash": "28afb39ba165378bd3b321a5921e7117611fb90f", "best_bid": "0.018", "best_ask": "0.121"}], "timestamp": "1769384687944", "event_type": "price_change"}}
{"_local_timestamp": "2026-01-25T23:44:54.650349+00:00", "data": {"market": "0x70e2c432a9f1c46194b4ed01276fce4b42ba14fa4121bb6a204bd27043fa6ec0", "price_changes": [{"asset_id": "96293988997073127556538359019802355814918008050500416514241789357023389177644", "price": "0.061", "size": "57.25", "side": "BUY", "hash": "247fcffc455d7a0e7505234d51d31d6926c3032b", "best_bid": "0.879", "best_ask": "0.982"}, {"asset_id": "76151979298166149168681611766855150167264661944933736838438696924609959086385", "price": "0.939", "size": "57.25", "side": "SELL", "hash": "894a98d0d4a4daeee3aea2690081311545ecd0c0", "best_bid": "0.018", "best_ask": "0.121"}], "timestamp": "1769384694550", "event_type": "price_change"}}
{"_local_timestamp": "2026-01-25T23:44:55.174506+00:00", "data": {"market": "0x70e2c432a9f1c46194b4ed01276fce4b42ba14fa4121bb6a204bd27043fa6ec0", "price_changes": [{"asset_id": "96293988997073127556538359019802355814918008050500416514241789357023389177644", "price": "0.878", "size": "0", "side": "BUY", "hash": "2d4eceb672253e3ecfb1862982f45e26964c30d8", "best_bid": "0.879", "best_ask": "0.982"}, {"asset_id": "76151979298166149168681611766855150167264661944933736838438696924609959086385", "price": "0.122", "size": "0", "side": "SELL", "hash": "9716cd74493b36d0b545e0f19365a157e017ff6c", "best_bid": "0.018", "best_ask": "0.121"}], "timestamp": "1769384695061", "event_type": "price_change"}}
{"_local_timestamp": "2026-01-25T23:44:57.596283+00:00", "data": {"market": "0x70e2c432a9f1c46194b4ed01276fce4b42ba14fa4121bb6a204bd27043fa6ec0", "price_changes": [{"asset_id": "96293988997073127556538359019802355814918008050500416514241789357023389177644", "price": "0.879", "size": "0", "side": "BUY", "hash": "f84352850448b14104b45207907937e4215b5ba8", "best_bid": "0.877", "best_ask": "0.982"}, {"asset_id": "76151979298166149168681611766855150167264661944933736838438696924609959086385", "price": "0.121", "size": "0", "side": "SELL", "hash": "4140966bb7a3e8952fbd95783b22ce9cf03207f9", "best_bid": "0.018", "best_ask": "0.123"}], "timestamp": "1769384697512", "event_type": "price_change"}}
{"_local_timestamp": "2026-01-25T23:44:57.620192+00:00", "data": {"market": "0x70e2c432a9f1c46194b4ed01276fce4b42ba14fa4121bb6a204bd27043fa6ec0", "price_changes": [{"asset_id": "96293988997073127556538359019802355814918008050500416514241789357023389177644", "price": "0.878", "size": "20", "side": "BUY", "hash": "62c5205d1e68d52cefd008f741d27257ca8becc9", "best_bid": "0.878", "best_ask": "0.982"}, {"asset_id": "76151979298166149168681611766855150167264661944933736838438696924609959086385", "price": "0.122", "size": "20", "side": "SELL", "hash": "e22f8232ca0641f56af0abbdd763a34a50cf43fb", "best_bid": "0.018", "best_ask": "0.122"}], "timestamp": "1769384697543", "event_type": "price_change"}}
{"_local_timestamp": "2026-01-25T23:45:10.115680+00:00", "data": {"market": "0x70e2c432a9f1c46194b4ed01276fce4b42ba14fa4121bb6a204bd27043fa6ec0", "price_changes": [{"asset_id": "76151979298166149168681611766855150167264661944933736838438696924609959086385", "price": "0.018", "size": "0", "side": "BUY", "hash": "45c5b361cebe6919525608f5257a84e828acc6a1", "best_bid": "0.015", "best_ask": "0.122"}, {"asset_id": "96293988997073127556538359019802355814918008050500416514241789357023389177644", "price": "0.982", "size": "0", "side": "SELL", "hash": "f1bb4b636859af7d724d7036407b5e7cb4c45969", "best_bid": "0.878", "best_ask": "0.985"}], "timestamp": "1769384710044", "event_type": "price_change"}}
{"_local_timestamp": "2026-01-25T23:45:11.643168+00:00", "data": {"market": "0x70e2c432a9f1c46194b4ed01276fce4b42ba14fa4121bb6a204bd27043fa6ec0", "price_changes": [{"asset_id": "76151979298166149168681611766855150167264661944933736838438696924609959086385", "price": "0.016", "size": "74.99", "side": "BUY", "hash": "083d728b407fe9cc091888d16f721dd5f4a75572", "best_bid": "0.016", "best_ask": "0.122"}, {"asset_id": "96293988997073127556538359019802355814918008050500416514241789357023389177644", "price": "0.984", "size": "74.99", "side": "SELL", "hash": "9d1a0d41818e15c050e993fc3a7873c7f64400a1", "best_bid": "0.878", "best_ask": "0.984"}], "timestamp": "1769384711575", "event_type": "price_change"}}
{"_local_timestamp": "2026-01-25T23:45:19.213732+00:00", "data": {"market": "0x70e2c432a9f1c46194b4ed01276fce4b42ba14fa4121bb6a204bd27043fa6ec0", "price_changes": [{"asset_id": "96293988997073127556538359019802355814918008050500416514241789357023389177644", "price": "0.879", "size": "45", "side": "BUY", "hash": "a3ffbd103a3c4112c2ea3fd5a0fd3697cd2d05f3", "best_bid": "0.879", "best_ask": "0.984"}, {"asset_id": "76151979298166149168681611766855150167264661944933736838438696924609959086385", "price": "0.121", "size": "45", "side": "SELL", "hash": "b9a1872c5339ac71eaac526c43babad29483d1ba", "best_bid": "0.016", "best_ask": "0.121"}], "timestamp": "1769384719150", "event_type": "price_change"}}
{"_local_timestamp": "2026-01-25T23:45:26.247091+00:00", "data": {"market": "0x70e2c432a9f1c46194b4ed01276fce4b42ba14fa4121bb6a204bd27043fa6ec0", "price_changes": [{"asset_id": "96293988997073127556538359019802355814918008050500416514241789357023389177644", "price": "0.878", "size": "0", "side": "BUY", "hash": "f22da6258373e3145cb21e56044ad9f4d7ea5401", "best_bid": "0.879", "best_ask": "0.984"}, {"asset_id": "76151979298166149168681611766855150167264661944933736838438696924609959086385", "price": "0.122", "size": "0", "side": "SELL", "hash": "beaf9963f47d40e488c4eaa5d9d6f6e7d127ff7a", "best_bid": "0.016", "best_ask": "0.121"}], "timestamp": "1769384726177", "event_type": "price_change"}}
{"_local_timestamp": "2026-01-25T23:45:26.276537+00:00", "data": {"market": "0x70e2c432a9f1c46194b4ed01276fce4b42ba14fa4121bb6a204bd27043fa6ec0", "price_changes": [{"asset_id": "96293988997073127556538359019802355814918008050500416514241789357023389177644", "price": "0.88", "size": "20", "side": "BUY", "hash": "c07648612bc8f5410a07544b47bcc227bfe33aea", "best_bid": "0.88", "best_ask": "0.984"}, {"asset_id": "76151979298166149168681611766855150167264661944933736838438696924609959086385", "price": "0.12", "size": "20", "side": "SELL", "hash": "8f65e5acd92d8803f054115e3ee4c4ef3fe2768c", "best_bid": "0.016", "best_ask": "0.12"}], "timestamp": "1769384726208", "event_type": "price_change"}}
{"_local_timestamp": "2026-01-25T23:45:26.390252+00:00", "data": {"market": "0x70e2c432a9f1c46194b4ed01276fce4b42ba14fa4121bb6a204bd27043fa6ec0", "price_changes": [{"asset_id": "96293988997073127556538359019802355814918008050500416514241789357023389177644", "price": "0.88", "size": "70", "side": "BUY", "hash": "5dc24f90f03a9f864c4df7e7330122410ca15df2", "best_bid": "0.88", "best_ask": "0.984"}, {"asset_id": "76151979298166149168681611766855150167264661944933736838438696924609959086385", "price": "0.12", "size": "70", "side": "SELL", "hash": "1fd8aa06fa2f19d17da810ae35511178651f1166", "best_bid": "0.016", "best_ask": "0.12"}], "timestamp": "1769384726313", "event_type": "price_change"}}
{"_local_timestamp": "2026-01-25T23:45:26.908576+00:00", "data": {"market": "0x70e2c432a9f1c46194b4ed01276fce4b42ba14fa4121bb6a204bd27043fa6ec0", "price_changes": [{"asset_id": "96293988997073127556538359019802355814918008050500416514241789357023389177644", "price": "0.061", "size": "7.25", "side": "BUY", "hash": "babd045177820e62c936d46aca6c459fb7515236", "best_bid": "0.88", "best_ask": "0.984"}, {"asset_id": "76151979298166149168681611766855150167264661944933736838438696924609959086385", "price": "0.939", "size": "7.25", "side": "SELL", "hash": "59c251d5cc501c6b698ddf9d8c1ca1366bb7c7cf", "best_bid": "0.016", "best_ask": "0.12"}], "timestamp": "1769384726833", "event_type": "price_change"}}
{"_local_timestamp": "2026-01-25T23:45:28.499432+00:00", "data": {"market": "0x70e2c432a9f1c46194b4ed01276fce4b42ba14fa4121bb6a204bd27043fa6ec0", "price_changes": [{"asset_id": "96293988997073127556538359019802355814918008050500416514241789357023389177644", "price": "0.88", "size": "50", "side": "BUY", "hash": "594ba117c12517910f9a1a362edc241d86a44ff9", "best_bid": "0.88", "best_ask": "0.984"}, {"asset_id": "76151979298166149168681611766855150167264661944933736838438696924609959086385", "price": "0.12", "size": "50", "side": "SELL", "hash": "455ffb97fd4638b860be837024933700627f85b6", "best_bid": "0.016", "best_ask": "0.12"}], "timestamp": "1769384728429", "event_type": "price_change"}}
{"_local_timestamp": "2026-01-25T23:45:28.522306+00:00", "data": {"market": "0x70e2c432a9f1c46194b4ed01276fce4b42ba14fa4121bb6a204bd27043fa6ec0", "price_changes": [{"asset_id": "96293988997073127556538359019802355814918008050500416514241789357023389177644", "price": "0.881", "size": "20", "side": "BUY", "hash": "bbd4a39ec9f7fb0b41f0ae8942637f4acde5dfce", "best_bid": "0.881", "best_ask": "0.984"}, {"asset_id": "76151979298166149168681611766855150167264661944933736838438696924609959086385", "price": "0.119", "size": "20", "side": "SELL", "hash": "3ddebf6d62be78e297b0786e541fbf0c4afe67c4", "best_bid": "0.016", "best_ask": "0.119"}], "timestamp": "1769384728457", "event_type": "price_change"}}
{"_local_timestamp": "2026-01-25T23:45:35.611803+00:00", "data": {"market": "0x026f75cda28b435d52c8615dc2eaa8895b4632e9f53c98255f2bced50fbb5018", "price_changes": [{"asset_id": "103477786055085350112953174136231624107339341173836019810109648103195092330225", "price": "0.12", "size": "14.09", "side": "BUY", "hash": "58793dce1cbc2c9d3ecb2c7df9a7ad8bf6688cc9", "best_bid": "0.12", "best_ask": "0.13"}, {"asset_id": "18282828012097738947825685359604327312283762551135248913642539025764020349015", "price": "0.88", "size": "14.09", "side": "SELL", "hash": "38b8f28a0b1993d2d124c0998cbceb2abec77dfd", "best_bid": "0.87", "best_ask": "0.88"}], "timestamp": "1769384735537", "event_type": "price_change"}}
{"_local_timestamp": "2026-01-25T23:45:36.084718+00:00", "data": {"market": "0x70e2c432a9f1c46194b4ed01276fce4b42ba14fa4121bb6a204bd27043fa6ec0", "price_changes": [{"asset_id": "96293988997073127556538359019802355814918008050500416514241789357023389177644", "price": "0.877", "size": "0", "side": "BUY", "hash": "f96fd61c46c64ca85f25c8d87adbceea1db9377e", "best_bid": "0.881", "best_ask": "0.984"}, {"asset_id": "76151979298166149168681611766855150167264661944933736838438696924609959086385", "price": "0.123", "size": "0", "side": "SELL", "hash": "3a4222eb9c127f7c5a56b63755f9479816fe31f2", "best_bid": "0.016", "best_ask": "0.119"}], "timestamp": "1769384735976", "event_type": "price_change"}}
{"_local_timestamp": "2026-01-25T23:45:36.107747+00:00", "data": {"market": "0x85a5b08650fc9da8d93e9eee346c5b54edbdbf83cb9f55465fdfcdb9f17151a8", "asset_id": "7748084461925509330048730794685020928130479141303753203741718956919910252040", "price": "0.999", "size": "17.017", "fee_rate_bps": "0", "side": "BUY", "timestamp": "1769384736038", "event_type": "last_trade_price", "transaction_hash": "0x70e16b51d7f54317e4e4f5dffe314c81f8a9037a32e7298ab9a16cffe70333c3"}}
{"_local_timestamp": "2026-01-25T23:45:36.136514+00:00", "data": {"market": "0x85a5b08650fc9da8d93e9eee346c5b54edbdbf83cb9f55465fdfcdb9f17151a8", "price_changes": [{"asset_id": "61857642644203197654538794139397189976239069779458940587434285917874264673085", "price": "0.001", "size": "1172.98", "side": "BUY", "hash": "4b90db5c36c23f45c49a95955b5579ab5ac47c2f", "best_bid": "0.001", "best_ask": "0.005"}, {"asset_id": "7748084461925509330048730794685020928130479141303753203741718956919910252040", "price": "0.999", "size": "1172.98", "side": "SELL", "hash": "df8f3067ed1d9be32de80a101ed78578e5d9c9f3", "best_bid": "0.995", "best_ask": "0.999"}], "timestamp": "1769384736008", "event_type": "price_change"}}
{"_local_timestamp": "2026-01-25T23:45:36.137449+00:00", "data": {"market": "0x85a5b08650fc9da8d93e9eee346c5b54edbdbf83cb9f55465fdfcdb9f17151a8", "asset_id": "61857642644203197654538794139397189976239069779458940587434285917874264673085", "bids": [{"price": "0.001", "size": "1172.98"}], "asks": [{"price": "0.999", "size": "7408.85"}, {"price": "0.998", "size": "1255.83"}, {"price": "0.997", "size": "1166"}, {"price": "0.996", "size": "10.09"}, {"price": "0.994", "size": "83"}, {"price": "0.99", "size": "2783"}, {"price": "0.989", "size": "5.13"}, {"price": "0.98", "size": "3700"}, {"price": "0.979", "size": "10.08"}, {"price": "0.959", "size": "48"}, {"price": "0.95", "size": "60"}, {"price": "0.949", "size": "39"}, {"price": "0.94", "size": "200"}, {"price": "0.939", "size": "7.27"}, {"price": "0.886", "size": "325"}, {"price": "0.84", "size": "250"}, {"price": "0.839", "size": "7.63"}, {"price": "0.786", "size": "119.98"}, {"price": "0.777", "size": "16"}, {"price": "0.767", "size": "299"}, {"price": "0.766", "size": "8"}, {"price": "0.477", "size": "20"}, {"price": "0.177", "size": "6"}, {"price": "0.08", "size": "30"}, {"price": "0.077", "size": "252"}, {"price": "0.076", "size": "8"}, {"price": "0.075", "size": "13"}, {"price": "0.074", "size": "20"}, {"price": "0.005", "size": "2506"}], "hash": "4b90db5c36c23f45c49a95955b5579ab5ac47c2f", "timestamp": "1769384736008", "event_type": "book"}}
{"_local_timestamp": "2026-01-25T23:45:36.138808+00:00", "data": {"market": "0x85a5b08650fc9da8d93e9eee346c5b54edbdbf83cb9f55465fdfcdb9f17151a8", "asset_id": "7748084461925509330048730794685020928130479141303753203741718956919910252040", "bids": [{"price": "0.001", "size": "7408.85"}, {"price": "0.002", "size": "1255.83"}, {"price": "0.003", "size": "1166"}, {"price": "0.004", "size": "10.09"}, {"price": "0.006", "size": "83"}, {"price": "0.01", "size": "2783"}, {"price": "0.011", "size": "5.13"}, {"price": "0.02", "size": "3700"}, {"price": "0.021", "size": "10.08"}, {"price": "0.041", "size": "48"}, {"price": "0.05", "size": "60"}, {"price": "0.051", "size": "39"}, {"price": "0.06", "size": "200"}, {"price": "0.061", "size": "7.27"}, {"price": "0.114", "size": "325"}, {"price": "0.16", "size": "250"}, {"price": "0.161", "size": "7.63"}, {"price": "0.214", "size": "119.98"}, {"price": "0.223", "size": "16"}, {"price": "0.233", "size": "299"}, {"price": "0.234", "size": "8"}, {"price": "0.523", "size": "20"}, {"price": "0.823", "size": "6"}, {"price": "0.92", "size": "30"}, {"price": "0.923", "size": "252"}, {"price": "0.924", "size": "8"}, {"price": "0.925", "size": "13"}, {"price": "0.926", "size": "20"}, {"price": "0.995", "size": "2506"}], "asks": [{"price": "0.999", "size": "1172.98"}], "hash": "df8f3067ed1d9be32de80a101ed78578e5d9c9f3", "timestamp": "1769384736008", "event_type": "book"}}
{"_local_timestamp": "2026-01-25T23:45:38.751268+00:00", "data": {"market": "0x70e2c432a9f1c46194b4ed01276fce4b42ba14fa4121bb6a204bd27043fa6ec0", "price_changes": [{"asset_id": "96293988997073127556538359019802355814918008050500416514241789357023389177644", "price": "0.061", "size": "57.25", "side": "BUY", "hash": "c65eab32a0e2702c63860c7ebb454fcdf0192b17", "best_bid": "0.881", "best_ask": "0.984"}, {"asset_id": "76151979298166149168681611766855150167264661944933736838438696924609959086385", "price": "0.939", "size": "57.25", "side": "SELL", "hash": "00ed9492d5373b3f720b4c3e0d110334bcd55d8c", "best_bid": "0.016", "best_ask": "0.119"}], "timestamp": "1769384738688", "event_type": "price_change"}}
{"_local_timestamp": "2026-01-25T23:45:39.123514+00:00", "data": {"market": "0x70e2c432a9f1c46194b4ed01276fce4b42ba14fa4121bb6a204bd27043fa6ec0", "price_changes": [{"asset_id": "96293988997073127556538359019802355814918008050500416514241789357023389177644", "price": "0.88", "size": "0", "side": "BUY", "hash": "83ea73493fb678f0c9b33d074c1fea2f00f95644", "best_bid": "0.881", "best_ask": "0.984"}, {"asset_id": "76151979298166149168681611766855150167264661944933736838438696924609959086385", "price": "0.12", "size": "0", "side": "SELL", "hash": "39ac8b5d6a25ec7ee29a206d68551ffd4ded29e2", "best_bid": "0.016", "best_ask": "0.119"}], "timestamp": "1769384739012", "event_type": "price_change"}}
{"_local_timestamp": "2026-01-25T23:45:42.192995+00:00", "data": {"market": "0x70e2c432a9f1c46194b4ed01276fce4b42ba14fa4121bb6a204bd27043fa6ec0", "price_changes": [{"asset_id": "96293988997073127556538359019802355814918008050500416514241789357023389177644", "price": "0.881", "size": "0", "side": "BUY", "hash": "c9fb4c297fd6c1ce605b865751c16d3e0bc8dba2", "best_bid": "0.879", "best_ask": "0.984"}, {"asset_id": "76151979298166149168681611766855150167264661944933736838438696924609959086385", "price": "0.119", "size": "0", "side": "SELL", "hash": "8b313bf546c0ff2ece73eed1aed6ebf66656eee6", "best_bid": "0.016", "best_ask": "0.121"}], "timestamp": "1769384742128", "event_type": "price_change"}}
{"_local_timestamp": "2026-01-25T23:45:42.230580+00:00", "data": {"market": "0x70e2c432a9f1c46194b4ed01276fce4b42ba14fa4121bb6a204bd27043fa6ec0", "price_changes": [{"asset_id": "96293988997073127556538359019802355814918008050500416514241789357023389177644", "price": "0.88", "size": "20", "side": "BUY", "hash": "019cd20fb5796d1ccf41af7fd02879eaa28e798c", "best_bid": "0.88", "best_ask": "0.984"}, {"asset_id": "76151979298166149168681611766855150167264661944933736838438696924609959086385", "price": "0.12", "size": "20", "side": "SELL", "hash": "11d2b01df6440604b114877d77fa07be41963fed", "best_bid": "0.016", "best_ask": "0.12"}], "timestamp": "1769384742162", "event_type": "price_change"}}
{"_local_timestamp": "2026-01-25T23:45:44.108072+00:00", "data": {"market": "0x70e2c432a9f1c46194b4ed01276fce4b42ba14fa4121bb6a204bd27043fa6ec0", "price_changes": [{"asset_id": "96293988997073127556538359019802355814918008050500416514241789357023389177644", "price": "0.02", "size": "1400", "side": "BUY", "hash": "a9bab9ba5e3eb15c97bae00603110ac58b689712", "best_bid": "0.88", "best_ask": "0.984"}, {"asset_id": "76151979298166149168681611766855150167264661944933736838438696924609959086385", "price": "0.98", "size": "1400", "side": "SELL", "hash": "52e39bdfa867bcedba8b2db5e0c1307e12ad2181", "best_bid": "0.016", "best_ask": "0.12"}], "timestamp": "1769384744021", "event_type": "price_change"}}
{"_local_timestamp": "2026-01-25T23:45:48.938710+00:00", "data": {"market": "0x026f75cda28b435d52c8615dc2eaa8895b4632e9f53c98255f2bced50fbb5018", "price_changes": [{"asset_id": "103477786055085350112953174136231624107339341173836019810109648103195092330225", "price": "0.12", "size": "44.21", "side": "BUY", "hash": "e2cb76fa9a65e18294e566f7bb4633e2bec184a8", "best_bid": "0.12", "best_ask": "0.13"}, {"asset_id": "18282828012097738947825685359604327312283762551135248913642539025764020349015", "price": "0.88", "size": "44.21", "side": "SELL", "hash": "decc749e34742d182ff8ba67135a242eae1eee0b", "best_bid": "0.87", "best_ask": "0.88"}], "timestamp": "1769384748872", "event_type": "price_change"}}
{"_local_timestamp": "2026-01-25T23:45:48.939293+00:00", "data": {"market": "0x026f75cda28b435d52c8615dc2eaa8895b4632e9f53c98255f2bced50fbb5018", "price_changes": [{"asset_id": "103477786055085350112953174136231624107339341173836019810109648103195092330225", "price": "0.12", "size": "74.33", "side": "BUY", "hash": "886f1e4905b5abc070eb817ba8fac0194cc83c1a", "best_bid": "0.12", "best_ask": "0.13"}, {"asset_id": "18282828012097738947825685359604327312283762551135248913642539025764020349015", "price": "0.88", "size": "74.33", "side": "SELL", "hash": "df3f106708c57ed4541984259e6baef4bea19d8b", "best_bid": "0.87", "best_ask": "0.88"}], "timestamp": "1769384748873", "event_type": "price_change"}}
{"_local_timestamp": "2026-01-25T23:45:48.939814+00:00", "data": {"market": "0x026f75cda28b435d52c8615dc2eaa8895b4632e9f53c98255f2bced50fbb5018", "price_changes": [{"asset_id": "103477786055085350112953174136231624107339341173836019810109648103195092330225", "price": "0.12", "size": "104.45", "side": "BUY", "hash": "edde8949184ad5bd93c4d308bc5785b0a0a0852c", "best_bid": "0.12", "best_ask": "0.13"}, {"asset_id": "18282828012097738947825685359604327312283762551135248913642539025764020349015", "price": "0.88", "size": "104.45", "side": "SELL", "hash": "e00c9d1f0231425549880b3d0971146533e39149", "best_bid": "0.87", "best_ask": "0.88"}], "timestamp": "1769384748873", "event_type": "price_change"}}
{"_local_timestamp": "2026-01-25T23:45:48.940476+00:00", "data": {"market": "0x026f75cda28b435d52c8615dc2eaa8895b4632e9f53c98255f2bced50fbb5018", "price_changes": [{"asset_id": "103477786055085350112953174136231624107339341173836019810109648103195092330225", "price": "0.12", "size": "134.57", "side": "BUY", "hash": "26e2d1ed304295112ccd33fa45449ce7fdeffb19", "best_bid": "0.12", "best_ask": "0.13"}, {"asset_id": "18282828012097738947825685359604327312283762551135248913642539025764020349015", "price": "0.88", "size": "134.57", "side": "SELL", "hash": "ccbe3c6a6c32309e53a13b0508d899de7ea1543e", "best_bid": "0.87", "best_ask": "0.88"}], "timestamp": "1769384748874", "event_type": "price_change"}}
{"_local_timestamp": "2026-01-25T23:45:51.102256+00:00", "data": {"market": "0x10aa044e00621209c1e6516ed820607867e1939c51e6416e78389133c07a28ca", "asset_id": "106590375374356420328249754119755979864494562435507082169975336179942135107522", "price": "0.16", "size": "13", "fee_rate_bps": "0", "side": "BUY", "timestamp": "1769384751034", "event_type": "last_trade_price", "transaction_hash": "0xabc425236a54a51e525c7aa7f1dc15a0abb383a3c322c42441b9c3dc00608054"}}
{"_local_timestamp": "2026-01-25T23:45:51.105501+00:00", "data": {"market": "0x10aa044e00621209c1e6516ed820607867e1939c51e6416e78389133c07a28ca", "price_changes": [{"asset_id": "106590375374356420328249754119755979864494562435507082169975336179942135107522", "price": "0.16", "size": "20.07", "side": "SELL", "hash": "0daebff59027d14bb15fcfa8ab5f0b568e0fa97c", "best_bid": "0.15", "best_ask": "0.16"}, {"asset_id": "114217190078574681732390148219500280529940631077811733810801001867278151517965", "price": "0.84", "size": "20.07", "side": "BUY", "hash": "eabdcd6a961bee3751796f1b0c6d5c08fc5491d0", "best_bid": "0.84", "best_ask": "0.85"}], "timestamp": "1769384751005", "event_type": "price_change"}}
{"_local_timestamp": "2026-01-25T23:45:51.107834+00:00", "data": {"market": "0x10aa044e00621209c1e6516ed820607867e1939c51e6416e78389133c07a28ca", "asset_id": "114217190078574681732390148219500280529940631077811733810801001867278151517965", "bids": [{"price": "0.01", "size": "4252.6"}, {"price": "0.02", "size": "3550"}, {"price": "0.03", "size": "100"}, {"price": "0.04", "size": "132.14"}, {"price": "0.05", "size": "120"}, {"price": "0.06", "size": "100"}, {"price": "0.07", "size": "100"}, {"price": "0.08", "size": "100"}, {"price": "0.09", "size": "100"}, {"price": "0.1", "size": "1100"}, {"price": "0.13", "size": "325"}, {"price": "0.2", "size": "350"}, {"price": "0.21", "size": "125"}, {"price": "0.25", "size": "105"}, {"price": "0.29", "size": "150"}, {"price": "0.45", "size": "160"}, {"price": "0.5", "size": "25"}, {"price": "0.55", "size": "180"}, {"price": "0.56", "size": "40"}, {"price": "0.74", "size": "100"}, {"price": "0.75", "size": "15"}, {"price": "0.76", "size": "100"}, {"price": "0.77", "size": "20"}, {"price": "0.78", "size": "10"}, {"price": "0.8", "size": "80"}, {"price": "0.82", "size": "11.48"}, {"price": "0.83", "size": "60"}, {"price": "0.84", "size": "20.07"}], "asks": [{"price": "0.99", "size": "2639.14"}, {"price": "0.98", "size": "26.2"}, {"price": "0.97", "size": "40"}, {"price": "0.96", "size": "84"}, {"price": "0.95", "size": "6.85"}, {"price": "0.93", "size": "7.99"}, {"price": "0.92", "size": "25.95"}, {"price": "0.91", "size": "5.69"}, {"price": "0.9", "size": "2.44"}, {"price": "0.87", "size": "114.66"}, {"price": "0.86", "size": "18"}, {"price": "0.85", "size": "34"}], "hash": "eabdcd6a961bee3751796f1b0c6d5c08fc5491d0", "timestamp": "1769384751005", "event_type": "book"}}
{"_local_timestamp": "2026-01-25T23:45:51.108511+00:00", "data": {"market": "0x10aa044e00621209c1e6516ed820607867e1939c51e6416e78389133c07a28ca", "asset_id": "106590375374356420328249754119755979864494562435507082169975336179942135107522", "bids": [{"price": "0.01", "size": "2639.14"}, {"price": "0.02", "size": "26.2"}, {"price": "0.03", "size": "40"}, {"price": "0.04", "size": "84"}, {"price": "0.05", "size": "6.85"}, {"price": "0.07", "size": "7.99"}, {"price": "0.08", "size": "25.95"}, {"price": "0.09", "size": "5.69"}, {"price": "0.1", "size": "2.44"}, {"price": "0.13", "size": "114.66"}, {"price": "0.14", "size": "18"}, {"price": "0.15", "size": "34"}], "asks": [{"price": "0.99", "size": "4252.6"}, {"price": "0.98", "size": "3550"}, {"price": "0.97", "size": "100"}, {"price": "0.96", "size": "132.14"}, {"price": "0.95", "size": "120"}, {"price": "0.94", "size": "100"}, {"price": "0.93", "size": "100"}, {"price": "0.92", "size": "100"}, {"price": "0.91", "size": "100"}, {"price": "0.9", "size": "1100"}, {"price": "0.87", "size": "325"}, {"price": "0.8", "size": "350"}, {"price": "0.79", "size": "125"}, {"price": "0.75", "size": "105"}, {"price": "0.71", "size": "150"}, {"price": "0.55", "size": "160"}, {"price": "0.5", "size": "25"}, {"price": "0.45", "size": "180"}, {"price": "0.44", "size": "40"}, {"price": "0.26", "size": "100"}, {"price": "0.25", "size": "15"}, {"price": "0.24", "size": "100"}, {"price": "0.23", "size": "20"}, {"price": "0.22", "size": "10"}, {"price": "0.2", "size": "80"}, {"price": "0.18", "size": "11.48"}, {"price": "0.17", "size": "60"}, {"price": "0.16", "size": "20.07"}], "hash": "0daebff59027d14bb15fcfa8ab5f0b568e0fa97c", "timestamp": "1769384751005", "event_type": "book"}}
{"_local_timestamp": "2026-01-25T23:45:57.232038+00:00", "data": {"market": "0x70e2c432a9f1c46194b4ed01276fce4b42ba14fa4121bb6a204bd27043fa6ec0", "price_changes": [{"asset_id": "96293988997073127556538359019802355814918008050500416514241789357023389177644", "price": "0.052", "size": "0", "side": "BUY", "hash": "9d22cba71e838fe55bcd0451e25559be7c52cb98", "best_bid": "0.88", "best_ask": "0.984"}, {"asset_id": "76151979298166149168681611766855150167264661944933736838438696924609959086385", "price": "0.948", "size": "0", "side": "SELL", "hash": "644505f66da0818259542696da52450736566277", "best_bid": "0.016", "best_ask": "0.12"}], "timestamp": "1769384756839", "event_type": "price_change"}}
{"_local_timestamp": "2026-01-25T23:45:57.252944+00:00", "data": {"market": "0x026f75cda28b435d52c8615dc2eaa8895b4632e9f53c98255f2bced50fbb5018", "price_changes": [{"asset_id": "18282828012097738947825685359604327312283762551135248913642539025764020349015", "price": "0.33", "size": "125", "side": "BUY", "hash": "1881dc44af5a70d7923f1fe24046b703a10960e9", "best_bid": "0.87", "best_ask": "0.88"}, {"asset_id": "103477786055085350112953174136231624107339341173836019810109648103195092330225", "price": "0.67", "size": "125", "side": "SELL", "hash": "b19e01a33636ae02999dc4d6a774e669b20708af", "best_bid": "0.12", "best_ask": "0.13"}], "timestamp": "1769384756840", "event_type": "price_change"}}
{"_local_timestamp": "2026-01-25T23:45:57.491411+00:00", "data": {"market": "0x70e2c432a9f1c46194b4ed01276fce4b42ba14fa4121bb6a204bd27043fa6ec0", "price_changes": [{"asset_id": "96293988997073127556538359019802355814918008050500416514241789357023389177644", "price": "0.88", "size": "155.71", "side": "BUY", "hash": "e5691e036404d09ab0952c1cd4fd67f04717c0a1", "best_bid": "0.88", "best_ask": "0.984"}, {"asset_id": "76151979298166149168681611766855150167264661944933736838438696924609959086385", "price": "0.12", "size": "155.71", "side": "SELL", "hash": "c14fc156f046e0165ad1dbcc83d34b2a82c88cc1", "best_bid": "0.016", "best_ask": "0.12"}], "timestamp": "1769384757343", "event_type": "price_change"}}
{"_local_timestamp": "2026-01-25T23:45:57.492019+00:00", "data": {"market": "0x70e2c432a9f1c46194b4ed01276fce4b42ba14fa4121bb6a204bd27043fa6ec0", "price_changes": [{"asset_id": "96293988997073127556538359019802355814918008050500416514241789357023389177644", "price": "0.881", "size": "135.71", "side": "BUY", "hash": "de37bc887fc4faac516c3184cea0e8a0428c964f", "best_bid": "0.881", "best_ask": "0.984"}, {"asset_id": "76151979298166149168681611766855150167264661944933736838438696924609959086385", "price": "0.119", "size": "135.71", "side": "SELL", "hash": "bafede7de138319e7aad9b8f197d250e11943a51", "best_bid": "0.016", "best_ask": "0.119"}], "timestamp": "1769384757344", "event_type": "price_change"}}
{"_local_timestamp": "2026-01-25T23:46:02.827265+00:00", "data": {"market": "0x70e2c432a9f1c46194b4ed01276fce4b42ba14fa4121bb6a204bd27043fa6ec0", "price_changes": [{"asset_id": "96293988997073127556538359019802355814918008050500416514241789357023389177644", "price": "0.882", "size": "50", "side": "BUY", "hash": "b9e3a8b8a4d69616c4c9b08733e45bc7a11c8aa6", "best_bid": "0.882", "best_ask": "0.984"}, {"asset_id": "76151979298166149168681611766855150167264661944933736838438696924609959086385", "price": "0.118", "size": "50", "side": "SELL", "hash": "abf1624500e0059ddbfbf1887fe7998292938cb8", "best_bid": "0.016", "best_ask": "0.118"}], "timestamp": "1769384762762", "event_type": "price_change"}}
{"_local_timestamp": "2026-01-25T23:46:02.855751+00:00", "data": {"market": "0x70e2c432a9f1c46194b4ed01276fce4b42ba14fa4121bb6a204bd27043fa6ec0", "price_changes": [{"asset_id": "96293988997073127556538359019802355814918008050500416514241789357023389177644", "price": "0.88", "size": "135.71", "side": "BUY", "hash": "5ab1ca81543cda427cf25c198793cac176e53cc5", "best_bid": "0.882", "best_ask": "0.984"}, {"asset_id": "76151979298166149168681611766855150167264661944933736838438696924609959086385", "price": "0.12", "size": "135.71", "side": "SELL", "hash": "924844331f8c8b94b0ee138553ac8d4e0c14f253", "best_bid": "0.016", "best_ask": "0.118"}], "timestamp": "1769384762786", "event_type": "price_change"}}
{"_local_timestamp": "2026-01-25T23:46:02.881693+00:00", "data": {"market": "0x70e2c432a9f1c46194b4ed01276fce4b42ba14fa4121bb6a204bd27043fa6ec0", "price_changes": [{"asset_id": "96293988997073127556538359019802355814918008050500416514241789357023389177644", "price": "0.882", "size": "70", "side": "BUY", "hash": "74029f3a46dc9d119c104698847d498309cc6fd8", "best_bid": "0.882", "best_ask": "0.984"}, {"asset_id": "76151979298166149168681611766855150167264661944933736838438696924609959086385", "price": "0.118", "size": "70", "side": "SELL", "hash": "c68613da771893b887cede4b597aa780ec387f20", "best_bid": "0.016", "best_ask": "0.118"}], "timestamp": "1769384762819", "event_type": "price_change"}}
{"_local_timestamp": "2026-01-25T23:46:03.156159+00:00", "data": {"market": "0x70e2c432a9f1c46194b4ed01276fce4b42ba14fa4121bb6a204bd27043fa6ec0", "price_changes": [{"asset_id": "96293988997073127556538359019802355814918008050500416514241789357023389177644", "price": "0.061", "size": "7.25", "side": "BUY", "hash": "22c269543e4190ce14162a334295c06247f0da44", "best_bid": "0.882", "best_ask": "0.984"}, {"asset_id": "76151979298166149168681611766855150167264661944933736838438696924609959086385", "price": "0.939", "size": "7.25", "side": "SELL", "hash": "05cbcfb195806b61213b35ca23fb056e969b0e06", "best_bid": "0.016", "best_ask": "0.118"}], "timestamp": "1769384763091", "event_type": "price_change"}}
{"_local_timestamp": "2026-01-25T23:46:04.417167+00:00", "data": {"market": "0x70e2c432a9f1c46194b4ed01276fce4b42ba14fa4121bb6a204bd27043fa6ec0", "price_changes": [{"asset_id": "96293988997073127556538359019802355814918008050500416514241789357023389177644", "price": "0.02", "size": "3400", "side": "BUY", "hash": "582c738a7fc7a1d2bea16f879a4ad31572eecc98", "best_bid": "0.882", "best_ask": "0.984"}, {"asset_id": "76151979298166149168681611766855150167264661944933736838438696924609959086385", "price": "0.98", "size": "3400", "side": "SELL", "hash": "ef3fa51caba9e9977746116436dea51a1656d424", "best_bid": "0.016", "best_ask": "0.118"}], "timestamp": "1769384764347", "event_type": "price_change"}}
{"_local_timestamp": "2026-01-25T23:46:05.367687+00:00", "data": {"market": "0x70e2c432a9f1c46194b4ed01276fce4b42ba14fa4121bb6a204bd27043fa6ec0", "price_changes": [{"asset_id": "96293988997073127556538359019802355814918008050500416514241789357023389177644", "price": "0.882", "size": "50", "side": "BUY", "hash": "7d13519a02fdf3b2a425d7839fe2b5590145aef1", "best_bid": "0.882", "best_ask": "0.984"}, {"asset_id": "76151979298166149168681611766855150167264661944933736838438696924609959086385", "price": "0.118", "size": "50", "side": "SELL", "hash": "f82b9c282461d8415c149d1c8f76965e22e5de2b", "best_bid": "0.016", "best_ask": "0.118"}], "timestamp": "1769384765294", "event_type": "price_change"}}
{"_local_timestamp": "2026-01-25T23:46:05.400785+00:00", "data": {"market": "0x70e2c432a9f1c46194b4ed01276fce4b42ba14fa4121bb6a204bd27043fa6ec0", "price_changes": [{"asset_id": "96293988997073127556538359019802355814918008050500416514241789357023389177644", "price": "0.883", "size": "20", "side": "BUY", "hash": "198197995d7c380ccb12231368ef9c6152666001", "best_bid": "0.883", "best_ask": "0.984"}, {"asset_id": "76151979298166149168681611766855150167264661944933736838438696924609959086385", "price": "0.117", "size": "20", "side": "SELL", "hash": "09502eee589ee763fbc48626446dae1bd2b20fbd", "best_bid": "0.016", "best_ask": "0.117"}], "timestamp": "1769384765329", "event_type": "price_change"}}
{"_local_timestamp": "2026-01-25T23:46:05.937033+00:00", "data": {"market": "0x70e2c432a9f1c46194b4ed01276fce4b42ba14fa4121bb6a204bd27043fa6ec0", "price_changes": [{"asset_id": "96293988997073127556538359019802355814918008050500416514241789357023389177644", "price": "0.881", "size": "165.71", "side": "BUY", "hash": "cecb7fb852d240727ea0034dc7a953a5b5bbd760", "best_bid": "0.883", "best_ask": "0.984"}, {"asset_id": "76151979298166149168681611766855150167264661944933736838438696924609959086385", "price": "0.119", "size": "165.71", "side": "SELL", "hash": "7503de717389e7d388525abb238988df101e8a53", "best_bid": "0.016", "best_ask": "0.117"}], "timestamp": "1769384765863", "event_type": "price_change"}}
{"_local_timestamp": "2026-01-25T23:46:19.445369+00:00", "data": {"market": "0x70e2c432a9f1c46194b4ed01276fce4b42ba14fa4121bb6a204bd27043fa6ec0", "price_changes": [{"asset_id": "96293988997073127556538359019802355814918008050500416514241789357023389177644", "price": "0.88", "size": "0", "side": "BUY", "hash": "17d59e7dee61b869f19d140eb4774c826a6b943c", "best_bid": "0.883", "best_ask": "0.984"}, {"asset_id": "76151979298166149168681611766855150167264661944933736838438696924609959086385", "price": "0.12", "size": "0", "side": "SELL", "hash": "148ae14cd2bcb1b2287ff1624b3e19ca9e4394e9", "best_bid": "0.016", "best_ask": "0.117"}], "timestamp": "1769384779370", "event_type": "price_change"}}
{"_local_timestamp": "2026-01-25T23:46:21.142971+00:00", "data": {"market": "0x70e2c432a9f1c46194b4ed01276fce4b42ba14fa4121bb6a204bd27043fa6ec0", "price_changes": [{"asset_id": "96293988997073127556538359019802355814918008050500416514241789357023389177644", "price": "0.881", "size": "135.71", "side": "BUY", "hash": "3857a619cdeaab4c50962aa31ea980bfac9d0824", "best_bid": "0.883", "best_ask": "0.984"}, {"asset_id": "76151979298166149168681611766855150167264661944933736838438696924609959086385", "price": "0.119", "size": "135.71", "side": "SELL", "hash": "55c8856a148a86b61a5b16002d2ba76f7662b924", "best_bid": "0.016", "best_ask": "0.117"}], "timestamp": "1769384781019", "event_type": "price_change"}}
{"_local_timestamp": "2026-01-25T23:46:22.843488+00:00", "data": {"market": "0x10aa044e00621209c1e6516ed820607867e1939c51e6416e78389133c07a28ca", "price_changes": [{"asset_id": "106590375374356420328249754119755979864494562435507082169975336179942135107522", "price": "0.07", "size": "0", "side": "BUY", "hash": "f4bcf431e960b864f7c4d75e9c069bdb35d211f1", "best_bid": "0.15", "best_ask": "0.16"}, {"asset_id": "114217190078574681732390148219500280529940631077811733810801001867278151517965", "price": "0.93", "size": "0", "side": "SELL", "hash": "ba03cdcb1698407eb45d8a2238cc9a022ad2dd4a", "best_bid": "0.84", "best_ask": "0.85"}], "timestamp": "1769384782776", "event_type": "price_change"}}
{"_local_timestamp": "2026-01-25T23:46:23.240764+00:00", "data": {"market": "0x10aa044e00621209c1e6516ed820607867e1939c51e6416e78389133c07a28ca", "price_changes": [{"asset_id": "106590375374356420328249754119755979864494562435507082169975336179942135107522", "price": "0.05", "size": "18.04", "side": "BUY", "hash": "d73604ef5fed93150e313d24539e1d27c60ebd03", "best_bid": "0.15", "best_ask": "0.16"}, {"asset_id": "114217190078574681732390148219500280529940631077811733810801001867278151517965", "price": "0.95", "size": "18.04", "side": "SELL", "hash": "2f3b2bfe80cb19daf6658b4acb1dbd0a82b55a21", "best_bid": "0.84", "best_ask": "0.85"}], "timestamp": "1769384783173", "event_type": "price_change"}}
{"_local_timestamp": "2026-01-25T23:46:24.989098+00:00", "data": {"market": "0x10aa044e00621209c1e6516ed820607867e1939c51e6416e78389133c07a28ca", "price_changes": [{"asset_id": "106590375374356420328249754119755979864494562435507082169975336179942135107522", "price": "0.08", "size": "5.95", "side": "BUY", "hash": "224a660f8b1d48d197844f8d262533a6d3b627c2", "best_bid": "0.15", "best_ask": "0.16"}, {"asset_id": "114217190078574681732390148219500280529940631077811733810801001867278151517965", "price": "0.92", "size": "5.95", "side": "SELL", "hash": "ed8a6d83c9db69d7e820f2b52d6d565282ec775d", "best_bid": "0.84", "best_ask": "0.85"}], "timestamp": "1769384784921", "event_type": "price_change"}}
{"_local_timestamp": "2026-01-25T23:46:25.018441+00:00", "data": {"market": "0x10aa044e00621209c1e6516ed820607867e1939c51e6416e78389133c07a28ca", "price_changes": [{"asset_id": "106590375374356420328249754119755979864494562435507082169975336179942135107522", "price": "0.06", "size": "20", "side": "BUY", "hash": "14e17c392e38ab371c0e5bc23d09d34b9843cb60", "best_bid": "0.15", "best_ask": "0.16"}, {"asset_id": "114217190078574681732390148219500280529940631077811733810801001867278151517965", "price": "0.94", "size": "20", "side": "SELL", "hash": "23c3840d50327c07a8067f378880878383bba649", "best_bid": "0.84", "best_ask": "0.85"}], "timestamp": "1769384784949", "event_type": "price_change"}}
{"_local_timestamp": "2026-01-25T23:46:41.343037+00:00", "data": {"market": "0x026f75cda28b435d52c8615dc2eaa8895b4632e9f53c98255f2bced50fbb5018", "price_changes": [{"asset_id": "103477786055085350112953174136231624107339341173836019810109648103195092330225", "price": "0.12", "size": "14.09", "side": "BUY", "hash": "cb97c680d46c6fb4acf539fb891e323e0862acdf", "best_bid": "0.12", "best_ask": "0.13"}, {"asset_id": "18282828012097738947825685359604327312283762551135248913642539025764020349015", "price": "0.88", "size": "14.09", "side": "SELL", "hash": "c503bb09e22e9738e43c06751015f077d753c7f0", "best_bid": "0.87", "best_ask": "0.88"}], "timestamp": "1769384801259", "event_type": "price_change"}}
{"_local_timestamp": "2026-01-25T23:46:50.780527+00:00", "data": {"market": "0x70e2c432a9f1c46194b4ed01276fce4b42ba14fa4121bb6a204bd27043fa6ec0", "price_changes": [{"asset_id": "96293988997073127556538359019802355814918008050500416514241789357023389177644", "price": "0.05", "size": "60", "side": "BUY", "hash": "47397a98c653bb9204f9f6381569a1b6156bcfc4", "best_bid": "0.883", "best_ask": "0.984"}, {"asset_id": "76151979298166149168681611766855150167264661944933736838438696924609959086385", "price": "0.95", "size": "60", "side": "SELL", "hash": "658f1318db18dca31660decdc468b40ba6edaad4", "best_bid": "0.016", "best_ask": "0.117"}], "timestamp": "1769384810646", "event_type": "price_change"}}
{"_local_timestamp": "2026-01-25T23:46:51.448894+00:00", "data": {"market": "0x70e2c432a9f1c46194b4ed01276fce4b42ba14fa4121bb6a204bd27043fa6ec0", "price_changes": [{"asset_id": "96293988997073127556538359019802355814918008050500416514241789357023389177644", "price": "0.02", "size": "3700", "side": "BUY", "hash": "a37a6a54ec14c709fdbcf3e4e627bb878a2938c8", "best_bid": "0.883", "best_ask": "0.984"}, {"asset_id": "76151979298166149168681611766855150167264661944933736838438696924609959086385", "price": "0.98", "size": "3700", "side": "SELL", "hash": "fa9614ccfff087006c1bdde04d94ea6e90e2b2e9", "best_bid": "0.016", "best_ask": "0.117"}], "timestamp": "1769384811178", "event_type": "price_change"}}
{"_local_timestamp": "2026-01-25T23:46:54.747328+00:00", "data": {"market": "0x026f75cda28b435d52c8615dc2eaa8895b4632e9f53c98255f2bced50fbb5018", "price_changes": [{"asset_id": "103477786055085350112953174136231624107339341173836019810109648103195092330225", "price": "0.12", "size": "44.21", "side": "BUY", "hash": "5258256fcb39be78294bf439fd2fda023226f4f6", "best_bid": "0.12", "best_ask": "0.13"}, {"asset_id": "18282828012097738947825685359604327312283762551135248913642539025764020349015", "price": "0.88", "size": "44.21", "side": "SELL", "hash": "c4192547e2fbaf0399287def8938e88275b99738", "best_bid": "0.87", "best_ask": "0.88"}], "timestamp": "1769384814662", "event_type": "price_change"}}
{"_local_timestamp": "2026-01-25T23:46:54.748581+00:00", "data": {"market": "0x026f75cda28b435d52c8615dc2eaa8895b4632e9f53c98255f2bced50fbb5018", "price_changes": [{"asset_id": "103477786055085350112953174136231624107339341173836019810109648103195092330225", "price": "0.12", "size": "74.33", "side": "BUY", "hash": "4b09234ce470353ea835e06017d66c48bf577170", "best_bid": "0.12", "best_ask": "0.13"}, {"asset_id": "18282828012097738947825685359604327312283762551135248913642539025764020349015", "price": "0.88", "size": "74.33", "side": "SELL", "hash": "e8a433609e52c187adf83842f22c60444a9e7149", "best_bid": "0.87", "best_ask": "0.88"}], "timestamp": "1769384814662", "event_type": "price_change"}}
{"_local_timestamp": "2026-01-25T23:46:54.769182+00:00", "data": {"market": "0x026f75cda28b435d52c8615dc2eaa8895b4632e9f53c98255f2bced50fbb5018", "price_changes": [{"asset_id": "103477786055085350112953174136231624107339341173836019810109648103195092330225", "price": "0.12", "size": "104.45", "side": "BUY", "hash": "117b5af945bc83854018dbf0c92d54c314db2433", "best_bid": "0.12", "best_ask": "0.13"}, {"asset_id": "18282828012097738947825685359604327312283762551135248913642539025764020349015", "price": "0.88", "size": "104.45", "side": "SELL", "hash": "88141d1780e64fa1b0ec04796107163cde12cf91", "best_bid": "0.87", "best_ask": "0.88"}], "timestamp": "1769384814695", "event_type": "price_change"}}
{"_local_timestamp": "2026-01-25T23:46:54.769878+00:00", "data": {"market": "0x026f75cda28b435d52c8615dc2eaa8895b4632e9f53c98255f2bced50fbb5018", "price_changes": [{"asset_id": "103477786055085350112953174136231624107339341173836019810109648103195092330225", "price": "0.12", "size": "134.57", "side": "BUY", "hash": "5222d698a959976218d5441fc23e7996309c5aed", "best_bid": "0.12", "best_ask": "0.13"}, {"asset_id": "18282828012097738947825685359604327312283762551135248913642539025764020349015", "price": "0.88", "size": "134.57", "side": "SELL", "hash": "02b8e6d2066f0b75c8ed4c1a414000edf8b371bc", "best_bid": "0.87", "best_ask": "0.88"}], "timestamp": "1769384814695", "event_type": "price_change"}}
{"_local_timestamp": "2026-01-25T23:46:57.870617+00:00", "data": {"market": "0x026f75cda28b435d52c8615dc2eaa8895b4632e9f53c98255f2bced50fbb5018", "price_changes": [{"asset_id": "18282828012097738947825685359604327312283762551135248913642539025764020349015", "price": "0.34", "size": "133", "side": "BUY", "hash": "201c3edb99532337d6049c64973317862e629387", "best_bid": "0.87", "best_ask": "0.88"}, {"asset_id": "103477786055085350112953174136231624107339341173836019810109648103195092330225", "price": "0.66", "size": "133", "side": "SELL", "hash": "88deccff2e7ee21817a7f2cde18372d902f7fa59", "best_bid": "0.12", "best_ask": "0.13"}], "timestamp": "1769384817800", "event_type": "price_change"}}
{"_local_timestamp": "2026-01-25T23:46:57.871287+00:00", "data": {"market": "0x70e2c432a9f1c46194b4ed01276fce4b42ba14fa4121bb6a204bd27043fa6ec0", "price_changes": [{"asset_id": "96293988997073127556538359019802355814918008050500416514241789357023389177644", "price": "0.211", "size": "75", "side": "BUY", "hash": "83bd6daf63666be8279f8ad2167c6de13b91df2f", "best_bid": "0.883", "best_ask": "0.984"}, {"asset_id": "76151979298166149168681611766855150167264661944933736838438696924609959086385", "price": "0.789", "size": "75", "side": "SELL", "hash": "cfd58ee74f0bc0051d16836e0e13a7cf019a43a3", "best_bid": "0.016", "best_ask": "0.117"}], "timestamp": "1769384817801", "event_type": "price_change"}}
{"_local_timestamp": "2026-01-25T23:47:34.055510+00:00", "data": {"market": "0x026f75cda28b435d52c8615dc2eaa8895b4632e9f53c98255f2bced50fbb5018", "price_changes": [{"asset_id": "103477786055085350112953174136231624107339341173836019810109648103195092330225", "price": "0.02", "size": "285", "side": "BUY", "hash": "466a13f97bb587dd8dfa8b39b0d50082c41b0777", "best_bid": "0.12", "best_ask": "0.13"}, {"asset_id": "18282828012097738947825685359604327312283762551135248913642539025764020349015", "price": "0.98", "size": "285", "side": "SELL", "hash": "26a222402e7ba226b8b7c997c79357773ea2c2ca", "best_bid": "0.87", "best_ask": "0.88"}], "timestamp": "1769384853989", "event_type": "price_change"}}
{"_local_timestamp": "2026-01-25T23:47:34.497506+00:00", "data": {"market": "0x026f75cda28b435d52c8615dc2eaa8895b4632e9f53c98255f2bced50fbb5018", "price_changes": [{"asset_id": "103477786055085350112953174136231624107339341173836019810109648103195092330225", "price": "0.02", "size": "299.28", "side": "BUY", "hash": "0c7899b8c09cb8bfe5b0ab7ca3c385449b3cdaa0", "best_bid": "0.12", "best_ask": "0.13"}, {"asset_id": "18282828012097738947825685359604327312283762551135248913642539025764020349015", "price": "0.98", "size": "299.28", "side": "SELL", "hash": "d4a96bc35539533f6fb7139d039023c4b0240895", "best_bid": "0.87", "best_ask": "0.88"}], "timestamp": "1769384854426", "event_type": "price_change"}}
{"_local_timestamp": "2026-01-25T23:47:46.665423+00:00", "data": {"market": "0x026f75cda28b435d52c8615dc2eaa8895b4632e9f53c98255f2bced50fbb5018", "price_changes": [{"asset_id": "103477786055085350112953174136231624107339341173836019810109648103195092330225", "price": "0.12", "size": "74.33", "side": "BUY", "hash": "4d3aa53f009b29d677d94deca11190d05ca60f6b", "best_bid": "0.12", "best_ask": "0.13"}, {"asset_id": "18282828012097738947825685359604327312283762551135248913642539025764020349015", "price": "0.88", "size": "74.33", "side": "SELL", "hash": "cc897eae34c714697e1dfd6a41af185d35fc3c1f", "best_bid": "0.87", "best_ask": "0.88"}], "timestamp": "1769384866596", "event_type": "price_change"}}
{"_local_timestamp": "2026-01-25T23:47:46.672564+00:00", "data": {"market": "0x026f75cda28b435d52c8615dc2eaa8895b4632e9f53c98255f2bced50fbb5018", "price_changes": [{"asset_id": "103477786055085350112953174136231624107339341173836019810109648103195092330225", "price": "0.12", "size": "14.09", "side": "BUY", "hash": "cafcd4fb128556b66538e2fccf2fffee1345281a", "best_bid": "0.12", "best_ask": "0.13"}, {"asset_id": "18282828012097738947825685359604327312283762551135248913642539025764020349015", "price": "0.88", "size": "14.09", "side": "SELL", "hash": "8eace31c6bb9a67cd82f100aa9b77385c5a76469", "best_bid": "0.87", "best_ask": "0.88"}], "timestamp": "1769384866605", "event_type": "price_change"}}
{"_local_timestamp": "2026-01-25T23:48:00.682686+00:00", "data": {"market": "0x026f75cda28b435d52c8615dc2eaa8895b4632e9f53c98255f2bced50fbb5018", "price_changes": [{"asset_id": "103477786055085350112953174136231624107339341173836019810109648103195092330225", "price": "0.12", "size": "44.21", "side": "BUY", "hash": "fb4b80627f42a2243fe45a359c0ac2cd2081c825", "best_bid": "0.12", "best_ask": "0.13"}, {"asset_id": "18282828012097738947825685359604327312283762551135248913642539025764020349015", "price": "0.88", "size": "44.21", "side": "SELL", "hash": "2f4ddf91aa216f0b9aade5f5d963338b4ac913d4", "best_bid": "0.87", "best_ask": "0.88"}], "timestamp": "1769384880603", "event_type": "price_change"}}
{"_local_timestamp": "2026-01-25T23:48:00.683611+00:00", "data": {"market": "0x026f75cda28b435d52c8615dc2eaa8895b4632e9f53c98255f2bced50fbb5018", "price_changes": [{"asset_id": "103477786055085350112953174136231624107339341173836019810109648103195092330225", "price": "0.12", "size": "74.33", "side": "BUY", "hash": "120cccacde20bd103611d6ed7fc0a884e0eb0b19", "best_bid": "0.12", "best_ask": "0.13"}, {"asset_id": "18282828012097738947825685359604327312283762551135248913642539025764020349015", "price": "0.88", "size": "74.33", "side": "SELL", "hash": "c0bf1507b6e3b2b74c51cb37853c91c810ebd324", "best_bid": "0.87", "best_ask": "0.88"}], "timestamp": "1769384880603", "event_type": "price_change"}}
{"_local_timestamp": "2026-01-25T23:48:00.684209+00:00", "data": {"market": "0x026f75cda28b435d52c8615dc2eaa8895b4632e9f53c98255f2bced50fbb5018", "price_changes": [{"asset_id": "103477786055085350112953174136231624107339341173836019810109648103195092330225", "price": "0.12", "size": "104.45", "side": "BUY", "hash": "316ea195edb313c0b198472e22639abde47fb416", "best_bid": "0.12", "best_ask": "0.13"}, {"asset_id": "18282828012097738947825685359604327312283762551135248913642539025764020349015", "price": "0.88", "size": "104.45", "side": "SELL", "hash": "ce89b5d3eba4240617f4b3d10afe8e80e32ff3d1", "best_bid": "0.87", "best_ask": "0.88"}], "timestamp": "1769384880604", "event_type": "price_change"}}
{"_local_timestamp": "2026-01-25T23:48:00.684825+00:00", "data": {"market": "0x026f75cda28b435d52c8615dc2eaa8895b4632e9f53c98255f2bced50fbb5018", "price_changes": [{"asset_id": "103477786055085350112953174136231624107339341173836019810109648103195092330225", "price": "0.12", "size": "134.57", "side": "BUY", "hash": "b52b7650a2548495287e01bc38b09d2faab0bbe4", "best_bid": "0.12", "best_ask": "0.13"}, {"asset_id": "18282828012097738947825685359604327312283762551135248913642539025764020349015", "price": "0.88", "size": "134.57", "side": "SELL", "hash": "7bebc472c54847fb1b3f94a71b72a0614357a237", "best_bid": "0.87", "best_ask": "0.88"}], "timestamp": "1769384880605", "event_type": "price_change"}}
{"_local_timestamp": "2026-01-25T23:48:21.520196+00:00", "data": {"market": "0x70e2c432a9f1c46194b4ed01276fce4b42ba14fa4121bb6a204bd27043fa6ec0", "price_changes": [{"asset_id": "76151979298166149168681611766855150167264661944933736838438696924609959086385", "price": "0.017", "size": "20", "side": "BUY", "hash": "0005f17faed824cb8c694320cc0845443baf18f3", "best_bid": "0.017", "best_ask": "0.117"}, {"asset_id": "96293988997073127556538359019802355814918008050500416514241789357023389177644", "price": "0.983", "size": "20", "side": "SELL", "hash": "d91e755b71009f23dbc419cde728a65f88e01051", "best_bid": "0.883", "best_ask": "0.983"}], "timestamp": "1769384901454", "event_type": "price_change"}}
{"_local_timestamp": "2026-01-25T23:48:47.390004+00:00", "data": {"market": "0x026f75cda28b435d52c8615dc2eaa8895b4632e9f53c98255f2bced50fbb5018", "price_changes": [{"asset_id": "103477786055085350112953174136231624107339341173836019810109648103195092330225", "price": "0.12", "size": "14.09", "side": "BUY", "hash": "776405a0bbe104c7d9ad8303d9119e82283164f8", "best_bid": "0.12", "best_ask": "0.13"}, {"asset_id": "18282828012097738947825685359604327312283762551135248913642539025764020349015", "price": "0.88", "size": "14.09", "side": "SELL", "hash": "fcef921e8159514a32f36c145aaa966470b7b107", "best_bid": "0.87", "best_ask": "0.88"}], "timestamp": "1769384927317", "event_type": "price_change"}}
{"_local_timestamp": "2026-01-25T23:49:00.494915+00:00", "data": {"market": "0x026f75cda28b435d52c8615dc2eaa8895b4632e9f53c98255f2bced50fbb5018", "price_changes": [{"asset_id": "103477786055085350112953174136231624107339341173836019810109648103195092330225", "price": "0.12", "size": "44.21", "side": "BUY", "hash": "2f1470d2a30976a5a4a331590e0b9963caf52d0b", "best_bid": "0.12", "best_ask": "0.13"}, {"asset_id": "18282828012097738947825685359604327312283762551135248913642539025764020349015", "price": "0.88", "size": "44.21", "side": "SELL", "hash": "deed759f86dfa89b56e1d291d6aaf38d9a0fb439", "best_bid": "0.87", "best_ask": "0.88"}], "timestamp": "1769384940421", "event_type": "price_change"}}
{"_local_timestamp": "2026-01-25T23:49:00.495588+00:00", "data": {"market": "0x026f75cda28b435d52c8615dc2eaa8895b4632e9f53c98255f2bced50fbb5018", "price_changes": [{"asset_id": "103477786055085350112953174136231624107339341173836019810109648103195092330225", "price": "0.12", "size": "74.33", "side": "BUY", "hash": "b84e3be949d8b3cfd6b0f58ec91d336b095d4417", "best_bid": "0.12", "best_ask": "0.13"}, {"asset_id": "18282828012097738947825685359604327312283762551135248913642539025764020349015", "price": "0.88", "size": "74.33", "side": "SELL", "hash": "33485bfeb779f88bc6f11b45f8ff23a57c1fa915", "best_bid": "0.87", "best_ask": "0.88"}], "timestamp": "1769384940422", "event_type": "price_change"}}
{"_local_timestamp": "2026-01-25T23:49:00.496168+00:00", "data": {"market": "0x026f75cda28b435d52c8615dc2eaa8895b4632e9f53c98255f2bced50fbb5018", "price_changes": [{"asset_id": "103477786055085350112953174136231624107339341173836019810109648103195092330225", "price": "0.12", "size": "104.45", "side": "BUY", "hash": "2ee862131726949e5aee67758cbc0d84213c8dad", "best_bid": "0.12", "best_ask": "0.13"}, {"asset_id": "18282828012097738947825685359604327312283762551135248913642539025764020349015", "price": "0.88", "size": "104.45", "side": "SELL", "hash": "181138f6bf670581f30ad89cf628e599fa91b1b9", "best_bid": "0.87", "best_ask": "0.88"}], "timestamp": "1769384940423", "event_type": "price_change"}}
{"_local_timestamp": "2026-01-25T23:49:00.496745+00:00", "data": {"market": "0x026f75cda28b435d52c8615dc2eaa8895b4632e9f53c98255f2bced50fbb5018", "price_changes": [{"asset_id": "103477786055085350112953174136231624107339341173836019810109648103195092330225", "price": "0.12", "size": "134.57", "side": "BUY", "hash": "93c6bf691714cb91c96a2f63a32b028a9d77bdc4", "best_bid": "0.12", "best_ask": "0.13"}, {"asset_id": "18282828012097738947825685359604327312283762551135248913642539025764020349015", "price": "0.88", "size": "134.57", "side": "SELL", "hash": "8e25cc383a7d72c2c39c9555b8d334f3eb340766", "best_bid": "0.87", "best_ask": "0.88"}], "timestamp": "1769384940423", "event_type": "price_change"}}
{"_local_timestamp": "2026-01-25T23:49:20.438082+00:00", "data": {"market": "0x10aa044e00621209c1e6516ed820607867e1939c51e6416e78389133c07a28ca", "price_changes": [{"asset_id": "106590375374356420328249754119755979864494562435507082169975336179942135107522", "price": "0.05", "size": "6.85", "side": "BUY", "hash": "19f07ff9fbe081cbe8b92f4142928b244412c6a2", "best_bid": "0.15", "best_ask": "0.16"}, {"asset_id": "114217190078574681732390148219500280529940631077811733810801001867278151517965", "price": "0.95", "size": "6.85", "side": "SELL", "hash": "de94c39588a918b4b0884a8597d60d093dc7a7f5", "best_bid": "0.84", "best_ask": "0.85"}], "timestamp": "1769384960368", "event_type": "price_change"}}
{"_local_timestamp": "2026-01-25T23:49:20.858921+00:00", "data": {"market": "0x10aa044e00621209c1e6516ed820607867e1939c51e6416e78389133c07a28ca", "price_changes": [{"asset_id": "106590375374356420328249754119755979864494562435507082169975336179942135107522", "price": "0.07", "size": "7.99", "side": "BUY", "hash": "4d286ee7f2119f71d66820a4b0d8fb12ea87deec", "best_bid": "0.15", "best_ask": "0.16"}, {"asset_id": "114217190078574681732390148219500280529940631077811733810801001867278151517965", "price": "0.93", "size": "7.99", "side": "SELL", "hash": "ebca10a022d334df9b31af4d80ed58b769c91212", "best_bid": "0.84", "best_ask": "0.85"}], "timestamp": "1769384960793", "event_type": "price_change"}}
{"_local_timestamp": "2026-01-25T23:49:25.358723+00:00", "data": {"market": "0x026f75cda28b435d52c8615dc2eaa8895b4632e9f53c98255f2bced50fbb5018", "price_changes": [{"asset_id": "18282828012097738947825685359604327312283762551135248913642539025764020349015", "price": "0.33", "size": "75", "side": "BUY", "hash": "a8c16fd84bd8b2469efb8e7c07951f3027ff2b9a", "best_bid": "0.87", "best_ask": "0.88"}, {"asset_id": "103477786055085350112953174136231624107339341173836019810109648103195092330225", "price": "0.67", "size": "75", "side": "SELL", "hash": "62ba0a80035d5e193acaf45f87089b9238125bd6", "best_bid": "0.12", "best_ask": "0.13"}], "timestamp": "1769384965269", "event_type": "price_change"}}
{"_local_timestamp": "2026-01-25T23:49:25.911081+00:00", "data": {"market": "0x026f75cda28b435d52c8615dc2eaa8895b4632e9f53c98255f2bced50fbb5018", "price_changes": [{"asset_id": "18282828012097738947825685359604327312283762551135248913642539025764020349015", "price": "0.34", "size": "183", "side": "BUY", "hash": "9a7a6f397f6cddd7cec3602a30f695a22c918708", "best_bid": "0.87", "best_ask": "0.88"}, {"asset_id": "103477786055085350112953174136231624107339341173836019810109648103195092330225", "price": "0.66", "size": "183", "side": "SELL", "hash": "5d1328e31325b5db7f27fe6d69cefcbfa6c76ae3", "best_bid": "0.12", "best_ask": "0.13"}], "timestamp": "1769384965771", "event_type": "price_change"}}
{"_local_timestamp": "2026-01-25T23:49:27.687444+00:00", "data": {"market": "0x10aa044e00621209c1e6516ed820607867e1939c51e6416e78389133c07a28ca", "price_changes": [{"asset_id": "106590375374356420328249754119755979864494562435507082169975336179942135107522", "price": "0.06", "size": "0", "side": "BUY", "hash": "74139809e3e04277a071816f61c279949f7e7d23", "best_bid": "0.15", "best_ask": "0.16"}, {"asset_id": "114217190078574681732390148219500280529940631077811733810801001867278151517965", "price": "0.94", "size": "0", "side": "SELL", "hash": "1a05358ef28944d5809de1c0a7abce9dcac1cffe", "best_bid": "0.84", "best_ask": "0.85"}], "timestamp": "1769384967621", "event_type": "price_change"}}
{"_local_timestamp": "2026-01-25T23:49:27.715705+00:00", "data": {"market": "0x10aa044e00621209c1e6516ed820607867e1939c51e6416e78389133c07a28ca", "price_changes": [{"asset_id": "106590375374356420328249754119755979864494562435507082169975336179942135107522", "price": "0.08", "size": "25.95", "side": "BUY", "hash": "ce6b3c000bac8a6fd7aac99bfe2df4fb927a5b23", "best_bid": "0.15", "best_ask": "0.16"}, {"asset_id": "114217190078574681732390148219500280529940631077811733810801001867278151517965", "price": "0.92", "size": "25.95", "side": "SELL", "hash": "ebe483465964c0d17b3706c3535a41a76318b63e", "best_bid": "0.84", "best_ask": "0.85"}], "timestamp": "1769384967651", "event_type": "price_change"}}
{"_local_timestamp": "2026-01-25T23:49:30.026261+00:00", "data": {"market": "0x026f75cda28b435d52c8615dc2eaa8895b4632e9f53c98255f2bced50fbb5018", "price_changes": [{"asset_id": "18282828012097738947825685359604327312283762551135248913642539025764020349015", "price": "0.33", "size": "0", "side": "BUY", "hash": "69b9d009d38e39990b75eca036fbb20bf3e114dc", "best_bid": "0.87", "best_ask": "0.88"}, {"asset_id": "103477786055085350112953174136231624107339341173836019810109648103195092330225", "price": "0.67", "size": "0", "side": "SELL", "hash": "1fdbc41c833323b5113329d0a0843f15667400c0", "best_bid": "0.12", "best_ask": "0.13"}], "timestamp": "1769384969960", "event_type": "price_change"}}
{"_local_timestamp": "2026-01-25T23:49:30.028021+00:00", "data": {"market": "0x70e2c432a9f1c46194b4ed01276fce4b42ba14fa4121bb6a204bd27043fa6ec0", "price_changes": [{"asset_id": "96293988997073127556538359019802355814918008050500416514241789357023389177644", "price": "0.21", "size": "50", "side": "BUY", "hash": "e7a235adf425fc42532c4bc2695d0a1e6f3a5d57", "best_bid": "0.883", "best_ask": "0.983"}, {"asset_id": "76151979298166149168681611766855150167264661944933736838438696924609959086385", "price": "0.79", "size": "50", "side": "SELL", "hash": "a6652b20b2a132a100077186f685dc015ae410e7", "best_bid": "0.017", "best_ask": "0.117"}], "timestamp": "1769384969960", "event_type": "price_change"}}
{"_local_timestamp": "2026-01-25T23:49:30.836726+00:00", "data": {"market": "0x70e2c432a9f1c46194b4ed01276fce4b42ba14fa4121bb6a204bd27043fa6ec0", "price_changes": [{"asset_id": "96293988997073127556538359019802355814918008050500416514241789357023389177644", "price": "0.211", "size": "175", "side": "BUY", "hash": "3f4a670785820fbf732e2843369a1fa370bee4cd", "best_bid": "0.883", "best_ask": "0.983"}, {"asset_id": "76151979298166149168681611766855150167264661944933736838438696924609959086385", "price": "0.789", "size": "175", "side": "SELL", "hash": "4e57a4ddbab3352496d329f3444d8fae73603ff6", "best_bid": "0.017", "best_ask": "0.117"}], "timestamp": "1769384970596", "event_type": "price_change"}}
{"_local_timestamp": "2026-01-25T23:49:30.837826+00:00", "data": {"market": "0x026f75cda28b435d52c8615dc2eaa8895b4632e9f53c98255f2bced50fbb5018", "price_changes": [{"asset_id": "18282828012097738947825685359604327312283762551135248913642539025764020349015", "price": "0.34", "size": "258", "side": "BUY", "hash": "636c24c136dce2d568de7c5d1afb1553a956ac44", "best_bid": "0.87", "best_ask": "0.88"}, {"asset_id": "103477786055085350112953174136231624107339341173836019810109648103195092330225", "price": "0.66", "size": "258", "side": "SELL", "hash": "17284c949c8c0842050246ef1d60c42bfa30508f", "best_bid": "0.12", "best_ask": "0.13"}], "timestamp": "1769384970595", "event_type": "price_change"}}
{"_local_timestamp": "2026-01-25T23:49:34.967761+00:00", "data": {"market": "0x85a5b08650fc9da8d93e9eee346c5b54edbdbf83cb9f55465fdfcdb9f17151a8", "price_changes": [{"asset_id": "7748084461925509330048730794685020928130479141303753203741718956919910252040", "price": "0.923", "size": "241", "side": "BUY", "hash": "02e0aac04a7543cb578493476991f0a31d90f10b", "best_bid": "0.995", "best_ask": "0.999"}, {"asset_id": "61857642644203197654538794139397189976239069779458940587434285917874264673085", "price": "0.077", "size": "241", "side": "SELL", "hash": "5814bec7a28bf8097e9aa3b3fce909b8a9573263", "best_bid": "0.001", "best_ask": "0.005"}], "timestamp": "1769384974901", "event_type": "price_change"}}
{"_local_timestamp": "2026-01-25T23:49:35.012116+00:00", "data": {"market": "0x85a5b08650fc9da8d93e9eee346c5b54edbdbf83cb9f55465fdfcdb9f17151a8", "price_changes": [{"asset_id": "7748084461925509330048730794685020928130479141303753203741718956919910252040", "price": "0.924", "size": "0", "side": "BUY", "hash": "6d719ee0f1fb5ec07db5e38557a129b7d9ce5830", "best_bid": "0.995", "best_ask": "0.999"}, {"asset_id": "61857642644203197654538794139397189976239069779458940587434285917874264673085", "price": "0.076", "size": "0", "side": "SELL", "hash": "80200425d0c12bc76e3a3dc9b58cc9afcb3ffb19", "best_bid": "0.001", "best_ask": "0.005"}], "timestamp": "1769384974938", "event_type": "price_change"}}
{"_local_timestamp": "2026-01-25T23:49:35.048342+00:00", "data": {"market": "0x85a5b08650fc9da8d93e9eee346c5b54edbdbf83cb9f55465fdfcdb9f17151a8", "price_changes": [{"asset_id": "7748084461925509330048730794685020928130479141303753203741718956919910252040", "price": "0.925", "size": "0", "side": "BUY", "hash": "d3c075b0799b3ddca0d0052e152549c4f5eb4ae6", "best_bid": "0.995", "best_ask": "0.999"}, {"asset_id": "61857642644203197654538794139397189976239069779458940587434285917874264673085", "price": "0.075", "size": "0", "side": "SELL", "hash": "eb15d990f0ebd4503aebc612618c0ec64740aadf", "best_bid": "0.001", "best_ask": "0.005"}], "timestamp": "1769384974976", "event_type": "price_change"}}
{"_local_timestamp": "2026-01-25T23:49:35.099704+00:00", "data": {"market": "0x85a5b08650fc9da8d93e9eee346c5b54edbdbf83cb9f55465fdfcdb9f17151a8", "price_changes": [{"asset_id": "7748084461925509330048730794685020928130479141303753203741718956919910252040", "price": "0.926", "size": "33", "side": "BUY", "hash": "b2a3f4cbd99dc3d3e05e3e9b9b3ce46c78b286a2", "best_bid": "0.995", "best_ask": "0.999"}, {"asset_id": "61857642644203197654538794139397189976239069779458940587434285917874264673085", "price": "0.074", "size": "33", "side": "SELL", "hash": "c1ea88ddd88d9e05a34a088be30065cc987cfbac", "best_bid": "0.001", "best_ask": "0.005"}], "timestamp": "1769384975031", "event_type": "price_change"}}
{"_local_timestamp": "2026-01-25T23:49:35.160028+00:00", "data": {"market": "0x85a5b08650fc9da8d93e9eee346c5b54edbdbf83cb9f55465fdfcdb9f17151a8", "price_changes": [{"asset_id": "7748084461925509330048730794685020928130479141303753203741718956919910252040", "price": "0.925", "size": "8", "side": "BUY", "hash": "71ee4a8fcdc70bf7756261e97f72259f4c655f7a", "best_bid": "0.995", "best_ask": "0.999"}, {"asset_id": "61857642644203197654538794139397189976239069779458940587434285917874264673085", "price": "0.075", "size": "8", "side": "SELL", "hash": "827e02610f126ba77ee77a70ebd3e43a34f2d84d", "best_bid": "0.001", "best_ask": "0.005"}], "timestamp": "1769384975094", "event_type": "price_change"}}
{"_local_timestamp": "2026-01-25T23:49:35.225127+00:00", "data": {"market": "0x85a5b08650fc9da8d93e9eee346c5b54edbdbf83cb9f55465fdfcdb9f17151a8", "price_changes": [{"asset_id": "7748084461925509330048730794685020928130479141303753203741718956919910252040", "price": "0.924", "size": "5", "side": "BUY", "hash": "d7f6f8a8f902d9837f92836edf8397920d0adaf0", "best_bid": "0.995", "best_ask": "0.999"}, {"asset_id": "61857642644203197654538794139397189976239069779458940587434285917874264673085", "price": "0.076", "size": "5", "side": "SELL", "hash": "d9babd77e40b959533cbb687ddcccb1de44bd963", "best_bid": "0.001", "best_ask": "0.005"}], "timestamp": "1769384975155", "event_type": "price_change"}}
{"_local_timestamp": "2026-01-25T23:49:35.270063+00:00", "data": {"market": "0x85a5b08650fc9da8d93e9eee346c5b54edbdbf83cb9f55465fdfcdb9f17151a8", "price_changes": [{"asset_id": "7748084461925509330048730794685020928130479141303753203741718956919910252040", "price": "0.923", "size": "247", "side": "BUY", "hash": "c6f478d4bdf860fd8754af3d63d9a40d59475f29", "best_bid": "0.995", "best_ask": "0.999"}, {"asset_id": "61857642644203197654538794139397189976239069779458940587434285917874264673085", "price": "0.077", "size": "247", "side": "SELL", "hash": "a18ef455ab0567328f8a22c4a1b3b8bc6931557b", "best_bid": "0.001", "best_ask": "0.005"}], "timestamp": "1769384975201", "event_type": "price_change"}}
{"_local_timestamp": "2026-01-25T23:49:35.999824+00:00", "data": {"market": "0x85a5b08650fc9da8d93e9eee346c5b54edbdbf83cb9f55465fdfcdb9f17151a8", "price_changes": [{"asset_id": "7748084461925509330048730794685020928130479141303753203741718956919910252040", "price": "0.926", "size": "13", "side": "BUY", "hash": "9c373b09f423f2e1a11059d62186d65186830555", "best_bid": "0.995", "best_ask": "0.999"}, {"asset_id": "61857642644203197654538794139397189976239069779458940587434285917874264673085", "price": "0.074", "size": "13", "side": "SELL", "hash": "6c347ebe45a69efa083028d108c8e5d2ba7937ef", "best_bid": "0.001", "best_ask": "0.005"}], "timestamp": "1769384975934", "event_type": "price_change"}}
{"_local_timestamp": "2026-01-25T23:49:36.028817+00:00", "data": {"market": "0x85a5b08650fc9da8d93e9eee346c5b54edbdbf83cb9f55465fdfcdb9f17151a8", "price_changes": [{"asset_id": "7748084461925509330048730794685020928130479141303753203741718956919910252040", "price": "0.927", "size": "20", "side": "BUY", "hash": "6e8755b1fed5435449ef7fe8a9dff97240e2d5c3", "best_bid": "0.995", "best_ask": "0.999"}, {"asset_id": "61857642644203197654538794139397189976239069779458940587434285917874264673085", "price": "0.073", "size": "20", "side": "SELL", "hash": "df49ef9064bdb7b64240986f388315a308f8a19e", "best_bid": "0.001", "best_ask": "0.005"}], "timestamp": "1769384975962", "event_type": "price_change"}}
{"_local_timestamp": "2026-01-25T23:49:42.060601+00:00", "data": {"market": "0x10aa044e00621209c1e6516ed820607867e1939c51e6416e78389133c07a28ca", "price_changes": [{"asset_id": "106590375374356420328249754119755979864494562435507082169975336179942135107522", "price": "0.15", "size": "0", "side": "BUY", "hash": "b4e3314a7fbe0bb659c0f6a96165fad134b4bb32", "best_bid": "0.14", "best_ask": "0.16"}, {"asset_id": "114217190078574681732390148219500280529940631077811733810801001867278151517965", "price": "0.85", "size": "0", "side": "SELL", "hash": "20d4939bc0b5bf0e313c9ffb1cb823cc069b55ca", "best_bid": "0.84", "best_ask": "0.86"}], "timestamp": "1769384981908", "event_type": "price_change"}}
{"_local_timestamp": "2026-01-25T23:49:43.286194+00:00", "data": {"market": "0x10aa044e00621209c1e6516ed820607867e1939c51e6416e78389133c07a28ca", "price_changes": [{"asset_id": "106590375374356420328249754119755979864494562435507082169975336179942135107522", "price": "0.15", "size": "34", "side": "BUY", "hash": "0cd11e1b94f6be149635f25c488654da8ca6810e", "best_bid": "0.15", "best_ask": "0.16"}, {"asset_id": "114217190078574681732390148219500280529940631077811733810801001867278151517965", "price": "0.85", "size": "34", "side": "SELL", "hash": "98c71237fdd5bff10fb259f69ef2853d827326a1", "best_bid": "0.84", "best_ask": "0.85"}], "timestamp": "1769384983220", "event_type": "price_change"}}
{"_local_timestamp": "2026-01-25T23:49:43.419064+00:00", "data": {"market": "0x026f75cda28b435d52c8615dc2eaa8895b4632e9f53c98255f2bced50fbb5018", "price_changes": [{"asset_id": "103477786055085350112953174136231624107339341173836019810109648103195092330225", "price": "0.02", "size": "285", "side": "BUY", "hash": "651d2e5dc4b9dac9e5da9ee7df559365b0d273d7", "best_bid": "0.12", "best_ask": "0.13"}, {"asset_id": "18282828012097738947825685359604327312283762551135248913642539025764020349015", "price": "0.98", "size": "285", "side": "SELL", "hash": "ba8900f3efd4f85beeb2823c2e25f324cc8e6e22", "best_bid": "0.87", "best_ask": "0.88"}], "timestamp": "1769384983338", "event_type": "price_change"}}
{"_local_timestamp": "2026-01-25T23:49:43.478005+00:00", "data": {"market": "0x70e2c432a9f1c46194b4ed01276fce4b42ba14fa4121bb6a204bd27043fa6ec0", "price_changes": [{"asset_id": "76151979298166149168681611766855150167264661944933736838438696924609959086385", "price": "0.016", "size": "0", "side": "BUY", "hash": "e4984d07806e1e5e80753fb3b61a851a8391c1d0", "best_bid": "0.017", "best_ask": "0.117"}, {"asset_id": "96293988997073127556538359019802355814918008050500416514241789357023389177644", "price": "0.984", "size": "0", "side": "SELL", "hash": "c4f918f76e3e08a06fab52a3f007ffcbcdc02ec5", "best_bid": "0.883", "best_ask": "0.983"}], "timestamp": "1769384983405", "event_type": "price_change"}}
{"_local_timestamp": "2026-01-25T23:49:43.594256+00:00", "data": {"market": "0x026f75cda28b435d52c8615dc2eaa8895b4632e9f53c98255f2bced50fbb5018", "price_changes": [{"asset_id": "103477786055085350112953174136231624107339341173836019810109648103195092330225", "price": "0.02", "size": "299.28", "side": "BUY", "hash": "1ea5c744e40ba1dbe156d220fc18d18844fcd13b", "best_bid": "0.12", "best_ask": "0.13"}, {"asset_id": "18282828012097738947825685359604327312283762551135248913642539025764020349015", "price": "0.98", "size": "299.28", "side": "SELL", "hash": "9595ea9051260f43e183cbc0ed36834f930f1627", "best_bid": "0.87", "best_ask": "0.88"}], "timestamp": "1769384983527", "event_type": "price_change"}}
{"_local_timestamp": "2026-01-25T23:49:44.502017+00:00", "data": {"market": "0x70e2c432a9f1c46194b4ed01276fce4b42ba14fa4121bb6a204bd27043fa6ec0", "price_changes": [{"asset_id": "76151979298166149168681611766855150167264661944933736838438696924609959086385", "price": "0.018", "size": "66.66", "side": "BUY", "hash": "1ae37ab989b6f1c538ed0bd094ba5db446a24e95", "best_bid": "0.018", "best_ask": "0.117"}, {"asset_id": "96293988997073127556538359019802355814918008050500416514241789357023389177644", "price": "0.982", "size": "66.66", "side": "SELL", "hash": "2ccb279db3d1777fa191c46c9d3b4c1b0900516b", "best_bid": "0.883", "best_ask": "0.982"}], "timestamp": "1769384984427", "event_type": "price_change"}}
{"_local_timestamp": "2026-01-25T23:49:49.159969+00:00", "data": {"market": "0x026f75cda28b435d52c8615dc2eaa8895b4632e9f53c98255f2bced50fbb5018", "price_changes": [{"asset_id": "103477786055085350112953174136231624107339341173836019810109648103195092330225", "price": "0.12", "size": "104.45", "side": "BUY", "hash": "90045765297b6e05bcd79dcaf5a64c4e4059b951", "best_bid": "0.12", "best_ask": "0.13"}, {"asset_id": "18282828012097738947825685359604327312283762551135248913642539025764020349015", "price": "0.88", "size": "104.45", "side": "SELL", "hash": "84f4fd4116b16174a626e28ecfd4b1f56533bd90", "best_bid": "0.87", "best_ask": "0.88"}], "timestamp": "1769384989085", "event_type": "price_change"}}
{"_local_timestamp": "2026-01-25T23:49:49.167594+00:00", "data": {"market": "0x026f75cda28b435d52c8615dc2eaa8895b4632e9f53c98255f2bced50fbb5018", "price_changes": [{"asset_id": "103477786055085350112953174136231624107339341173836019810109648103195092330225", "price": "0.12", "size": "14.09", "side": "BUY", "hash": "859ca306d7457c81e5f327940c0862fc3e470742", "best_bid": "0.12", "best_ask": "0.13"}, {"asset_id": "18282828012097738947825685359604327312283762551135248913642539025764020349015", "price": "0.88", "size": "14.09", "side": "SELL", "hash": "17b3b2e2ae6ee1c0a70a6a641b687f56e5faac84", "best_bid": "0.87", "best_ask": "0.88"}], "timestamp": "1769384989089", "event_type": "price_change"}}
{"_local_timestamp": "2026-01-25T23:49:50.083562+00:00", "data": {"market": "0x70e2c432a9f1c46194b4ed01276fce4b42ba14fa4121bb6a204bd27043fa6ec0", "price_changes": [{"asset_id": "96293988997073127556538359019802355814918008050500416514241789357023389177644", "price": "0.879", "size": "0", "side": "BUY", "hash": "e5ad0b295c480c4e85c11b587599c190734cee28", "best_bid": "0.883", "best_ask": "0.982"}, {"asset_id": "76151979298166149168681611766855150167264661944933736838438696924609959086385", "price": "0.121", "size": "0", "side": "SELL", "hash": "d4158270a49fe7dcca4302334601ef217a7905dc", "best_bid": "0.018", "best_ask": "0.117"}], "timestamp": "1769384989970", "event_type": "price_change"}}
{"_local_timestamp": "2026-01-25T23:49:56.679777+00:00", "data": {"market": "0x70e2c432a9f1c46194b4ed01276fce4b42ba14fa4121bb6a204bd27043fa6ec0", "price_changes": [{"asset_id": "96293988997073127556538359019802355814918008050500416514241789357023389177644", "price": "0.212", "size": "50", "side": "BUY", "hash": "34cc0a316120a65831bacdac26f651ab10a6e2b0", "best_bid": "0.883", "best_ask": "0.982"}, {"asset_id": "76151979298166149168681611766855150167264661944933736838438696924609959086385", "price": "0.788", "size": "50", "side": "SELL", "hash": "2d39120ddaecdb7be613295961dc3081cd856c72", "best_bid": "0.018", "best_ask": "0.117"}], "timestamp": "1769384996611", "event_type": "price_change"}}
{"_local_timestamp": "2026-01-25T23:49:57.136865+00:00", "data": {"market": "0x70e2c432a9f1c46194b4ed01276fce4b42ba14fa4121bb6a204bd27043fa6ec0", "price_changes": [{"asset_id": "96293988997073127556538359019802355814918008050500416514241789357023389177644", "price": "0.882", "size": "0", "side": "BUY", "hash": "f62f4e7fd527ce0f0ec39ed4c826eb6dadc33e09", "best_bid": "0.883", "best_ask": "0.982"}, {"asset_id": "76151979298166149168681611766855150167264661944933736838438696924609959086385", "price": "0.118", "size": "0", "side": "SELL", "hash": "7467dbf7bf738210022c801bb04b8d0eb609216c", "best_bid": "0.018", "best_ask": "0.117"}], "timestamp": "1769384997026", "event_type": "price_change"}}
{"_local_timestamp": "2026-01-25T23:49:58.115686+00:00", "data": {"market": "0x10aa044e00621209c1e6516ed820607867e1939c51e6416e78389133c07a28ca", "price_changes": [{"asset_id": "106590375374356420328249754119755979864494562435507082169975336179942135107522", "price": "0.16", "size": "7.07", "side": "SELL", "hash": "c0fc0e442e4d4310502ec88913e5cdf540d67ecc", "best_bid": "0.15", "best_ask": "0.16"}, {"asset_id": "114217190078574681732390148219500280529940631077811733810801001867278151517965", "price": "0.84", "size": "7.07", "side": "BUY", "hash": "10d77da9a464bc4e434d4aeb3860f256cb0dfe03", "best_bid": "0.84", "best_ask": "0.85"}], "timestamp": "1769384998005", "event_type": "price_change"}}
{"_local_timestamp": "2026-01-25T23:49:58.116569+00:00", "data": {"market": "0x10aa044e00621209c1e6516ed820607867e1939c51e6416e78389133c07a28ca", "asset_id": "114217190078574681732390148219500280529940631077811733810801001867278151517965", "bids": [{"price": "0.01", "size": "4252.6"}, {"price": "0.02", "size": "3550"}, {"price": "0.03", "size": "100"}, {"price": "0.04", "size": "132.14"}, {"price": "0.05", "size": "120"}, {"price": "0.06", "size": "100"}, {"price": "0.07", "size": "100"}, {"price": "0.08", "size": "100"}, {"price": "0.09", "size": "100"}, {"price": "0.1", "size": "1100"}, {"price": "0.13", "size": "325"}, {"price": "0.2", "size": "350"}, {"price": "0.21", "size": "125"}, {"price": "0.25", "size": "105"}, {"price": "0.29", "size": "150"}, {"price": "0.45", "size": "160"}, {"price": "0.5", "size": "25"}, {"price": "0.55", "size": "180"}, {"price": "0.56", "size": "40"}, {"price": "0.74", "size": "100"}, {"price": "0.75", "size": "15"}, {"price": "0.76", "size": "100"}, {"price": "0.77", "size": "20"}, {"price": "0.78", "size": "10"}, {"price": "0.8", "size": "80"}, {"price": "0.82", "size": "11.48"}, {"price": "0.83", "size": "60"}, {"price": "0.84", "size": "7.07"}], "asks": [{"price": "0.99", "size": "2639.14"}, {"price": "0.98", "size": "26.2"}, {"price": "0.97", "size": "40"}, {"price": "0.96", "size": "84"}, {"price": "0.95", "size": "6.85"}, {"price": "0.93", "size": "7.99"}, {"price": "0.92", "size": "25.95"}, {"price": "0.91", "size": "5.69"}, {"price": "0.9", "size": "2.44"}, {"price": "0.87", "size": "114.66"}, {"price": "0.86", "size": "18"}, {"price": "0.85", "size": "34"}], "hash": "10d77da9a464bc4e434d4aeb3860f256cb0dfe03", "timestamp": "1769384998005", "event_type": "book"}}
{"_local_timestamp": "2026-01-25T23:49:58.117397+00:00", "data": {"market": "0x10aa044e00621209c1e6516ed820607867e1939c51e6416e78389133c07a28ca", "asset_id": "106590375374356420328249754119755979864494562435507082169975336179942135107522", "bids": [{"price": "0.01", "size": "2639.14"}, {"price": "0.02", "size": "26.2"}, {"price": "0.03", "size": "40"}, {"price": "0.04", "size": "84"}, {"price": "0.05", "size": "6.85"}, {"price": "0.07", "size": "7.99"}, {"price": "0.08", "size": "25.95"}, {"price": "0.09", "size": "5.69"}, {"price": "0.1", "size": "2.44"}, {"price": "0.13", "size": "114.66"}, {"price": "0.14", "size": "18"}, {"price": "0.15", "size": "34"}], "asks": [{"price": "0.99", "size": "4252.6"}, {"price": "0.98", "size": "3550"}, {"price": "0.97", "size": "100"}, {"price": "0.96", "size": "132.14"}, {"price": "0.95", "size": "120"}, {"price": "0.94", "size": "100"}, {"price": "0.93", "size": "100"}, {"price": "0.92", "size": "100"}, {"price": "0.91", "size": "100"}, {"price": "0.9", "size": "1100"}, {"price": "0.87", "size": "325"}, {"price": "0.8", "size": "350"}, {"price": "0.79", "size": "125"}, {"price": "0.75", "size": "105"}, {"price": "0.71", "size": "150"}, {"price": "0.55", "size": "160"}, {"price": "0.5", "size": "25"}, {"price": "0.45", "size": "180"}, {"price": "0.44", "size": "40"}, {"price": "0.26", "size": "100"}, {"price": "0.25", "size": "15"}, {"price": "0.24", "size": "100"}, {"price": "0.23", "size": "20"}, {"price": "0.22", "size": "10"}, {"price": "0.2", "size": "80"}, {"price": "0.18", "size": "11.48"}, {"price": "0.17", "size": "60"}, {"price": "0.16", "size": "7.07"}], "hash": "c0fc0e442e4d4310502ec88913e5cdf540d67ecc", "timestamp": "1769384998005", "event_type": "book"}}
{"_local_timestamp": "2026-01-25T23:49:58.118027+00:00", "data": {"market": "0x10aa044e00621209c1e6516ed820607867e1939c51e6416e78389133c07a28ca", "asset_id": "106590375374356420328249754119755979864494562435507082169975336179942135107522", "price": "0.16", "size": "13", "fee_rate_bps": "0", "side": "BUY", "timestamp": "1769384998040", "event_type": "last_trade_price", "transaction_hash": "0x7f9061cffbd90c83a5479a71bcd58241b1d5b300d0c0b26d891b4f172de0ed2b"}}
{"_local_timestamp": "2026-01-25T23:50:01.840731+00:00", "data": {"market": "0x85a5b08650fc9da8d93e9eee346c5b54edbdbf83cb9f55465fdfcdb9f17151a8", "price_changes": [{"asset_id": "7748084461925509330048730794685020928130479141303753203741718956919910252040", "price": "0.927", "size": "0", "side": "BUY", "hash": "653cd4bc2b9a064a2b3a4ad5080366d0adfdd2b8", "best_bid": "0.995", "best_ask": "0.999"}, {"asset_id": "61857642644203197654538794139397189976239069779458940587434285917874264673085", "price": "0.073", "size": "0", "side": "SELL", "hash": "0d16341d556061bc4723aaff1e6f60bc1342ef88", "best_bid": "0.001", "best_ask": "0.005"}], "timestamp": "1769385001763", "event_type": "price_change"}}
{"_local_timestamp": "2026-01-25T23:50:01.842553+00:00", "data": {"market": "0x70e2c432a9f1c46194b4ed01276fce4b42ba14fa4121bb6a204bd27043fa6ec0", "price_changes": [{"asset_id": "96293988997073127556538359019802355814918008050500416514241789357023389177644", "price": "0.883", "size": "0", "side": "BUY", "hash": "35dcdad70f0b45570665e178c2bc501ef483c130", "best_bid": "0.881", "best_ask": "0.982"}, {"asset_id": "76151979298166149168681611766855150167264661944933736838438696924609959086385", "price": "0.117", "size": "0", "side": "SELL", "hash": "e880fbaea15763cd00bb8a7b6fe70a76857f9a3e", "best_bid": "0.018", "best_ask": "0.119"}], "timestamp": "1769385001763", "event_type": "price_change"}}
{"_local_timestamp": "2026-01-25T23:50:01.870841+00:00", "data": {"market": "0x85a5b08650fc9da8d93e9eee346c5b54edbdbf83cb9f55465fdfcdb9f17151a8", "price_changes": [{"asset_id": "7748084461925509330048730794685020928130479141303753203741718956919910252040", "price": "0.925", "size": "28", "side": "BUY", "hash": "517bb70e51a1fc83a8d2619cbbbbca332635fa8a", "best_bid": "0.995", "best_ask": "0.999"}, {"asset_id": "61857642644203197654538794139397189976239069779458940587434285917874264673085", "price": "0.075", "size": "28", "side": "SELL", "hash": "41385b428c61b56449ca89f09504cbf2a361cbda", "best_bid": "0.001", "best_ask": "0.005"}], "timestamp": "1769385001794", "event_type": "price_change"}}
{"_local_timestamp": "2026-01-25T23:50:01.877370+00:00", "data": {"market": "0x70e2c432a9f1c46194b4ed01276fce4b42ba14fa4121bb6a204bd27043fa6ec0", "price_changes": [{"asset_id": "96293988997073127556538359019802355814918008050500416514241789357023389177644", "price": "0.882", "size": "20", "side": "BUY", "hash": "02449ca095412f9dc7f02353fab229f56b4a5845", "best_bid": "0.882", "best_ask": "0.982"}, {"asset_id": "76151979298166149168681611766855150167264661944933736838438696924609959086385", "price": "0.118", "size": "20", "side": "SELL", "hash": "9ee64199b49952f09dd0fa333451f544176727b0", "best_bid": "0.018", "best_ask": "0.118"}], "timestamp": "1769385001794", "event_type": "price_change"}}
{"_local_timestamp": "2026-01-25T23:50:02.860151+00:00", "data": {"market": "0x026f75cda28b435d52c8615dc2eaa8895b4632e9f53c98255f2bced50fbb5018", "price_changes": [{"asset_id": "103477786055085350112953174136231624107339341173836019810109648103195092330225", "price": "0.12", "size": "44.21", "side": "BUY", "hash": "5c665211ad70f98c739221bd0f263b27ae0c523d", "best_bid": "0.12", "best_ask": "0.13"}, {"asset_id": "18282828012097738947825685359604327312283762551135248913642539025764020349015", "price": "0.88", "size": "44.21", "side": "SELL", "hash": "07927ed35cbc31d607a4a3814ea226b73868965f", "best_bid": "0.87", "best_ask": "0.88"}], "timestamp": "1769385002328", "event_type": "price_change"}}
{"_local_timestamp": "2026-01-25T23:50:02.865391+00:00", "data": {"market": "0x026f75cda28b435d52c8615dc2eaa8895b4632e9f53c98255f2bced50fbb5018", "price_changes": [{"asset_id": "103477786055085350112953174136231624107339341173836019810109648103195092330225", "price": "0.12", "size": "74.33", "side": "BUY", "hash": "baad16dd6188f3988cc2c78b74f9635c5b8bb4b2", "best_bid": "0.12", "best_ask": "0.13"}, {"asset_id": "18282828012097738947825685359604327312283762551135248913642539025764020349015", "price": "0.88", "size": "74.33", "side": "SELL", "hash": "d0dea24694119e4e58f1c5a574363b44233026d1", "best_bid": "0.87", "best_ask": "0.88"}], "timestamp": "1769385002329", "event_type": "price_change"}}
{"_local_timestamp": "2026-01-25T23:50:02.866261+00:00", "data": {"market": "0x026f75cda28b435d52c8615dc2eaa8895b4632e9f53c98255f2bced50fbb5018", "price_changes": [{"asset_id": "103477786055085350112953174136231624107339341173836019810109648103195092330225", "price": "0.12", "size": "104.45", "side": "BUY", "hash": "2f9e47501c964e3fe8266ab7128da12723963c63", "best_bid": "0.12", "best_ask": "0.13"}, {"asset_id": "18282828012097738947825685359604327312283762551135248913642539025764020349015", "price": "0.88", "size": "104.45", "side": "SELL", "hash": "e9be8848892b0bf2b37cb12763a105aad0f0a47e", "best_bid": "0.87", "best_ask": "0.88"}], "timestamp": "1769385002330", "event_type": "price_change"}}
{"_local_timestamp": "2026-01-25T23:50:02.867004+00:00", "data": {"market": "0x026f75cda28b435d52c8615dc2eaa8895b4632e9f53c98255f2bced50fbb5018", "price_changes": [{"asset_id": "103477786055085350112953174136231624107339341173836019810109648103195092330225", "price": "0.12", "size": "134.57", "side": "BUY", "hash": "c3008d2b6d63585309dd429de76e93a8fb37c3c0", "best_bid": "0.12", "best_ask": "0.13"}, {"asset_id": "18282828012097738947825685359604327312283762551135248913642539025764020349015", "price": "0.88", "size": "134.57", "side": "SELL", "hash": "acf16040e1c7ccb62e5ce58816a52247db9fdbe1", "best_bid": "0.87", "best_ask": "0.88"}], "timestamp": "1769385002330", "event_type": "price_change"}}
{"_local_timestamp": "2026-01-25T23:50:03.352384+00:00", "data": {"market": "0x85a5b08650fc9da8d93e9eee346c5b54edbdbf83cb9f55465fdfcdb9f17151a8", "price_changes": [{"asset_id": "7748084461925509330048730794685020928130479141303753203741718956919910252040", "price": "0.925", "size": "8", "side": "BUY", "hash": "d0cd996b239c7f5624fa7518a51a8eed6ee77ed1", "best_bid": "0.995", "best_ask": "0.999"}, {"asset_id": "61857642644203197654538794139397189976239069779458940587434285917874264673085", "price": "0.075", "size": "8", "side": "SELL", "hash": "f29878edb55e6c6c9ab44ebbbbe9c95015e74747", "best_bid": "0.001", "best_ask": "0.005"}], "timestamp": "1769385003224", "event_type": "price_change"}}
{"_local_timestamp": "2026-01-25T23:50:03.371349+00:00", "data": {"market": "0x85a5b08650fc9da8d93e9eee346c5b54edbdbf83cb9f55465fdfcdb9f17151a8", "price_changes": [{"asset_id": "7748084461925509330048730794685020928130479141303753203741718956919910252040", "price": "0.927", "size": "20", "side": "BUY", "hash": "8cb1f8a603b960bade235ede96d9e91cd5496b6e", "best_bid": "0.995", "best_ask": "0.999"}, {"asset_id": "61857642644203197654538794139397189976239069779458940587434285917874264673085", "price": "0.073", "size": "20", "side": "SELL", "hash": "bd87477714a62d2cbbd5278d8423c1fd9d5d86ce", "best_bid": "0.001", "best_ask": "0.005"}], "timestamp": "1769385003259", "event_type": "price_change"}}
{"_local_timestamp": "2026-01-25T23:50:16.163434+00:00", "data": {"market": "0x70e2c432a9f1c46194b4ed01276fce4b42ba14fa4121bb6a204bd27043fa6ec0", "price_changes": [{"asset_id": "96293988997073127556538359019802355814918008050500416514241789357023389177644", "price": "0.882", "size": "155.71", "side": "BUY", "hash": "808871e656b70ebe962ea9a9a28636444ac63f58", "best_bid": "0.882", "best_ask": "0.982"}, {"asset_id": "76151979298166149168681611766855150167264661944933736838438696924609959086385", "price": "0.118", "size": "155.71", "side": "SELL", "hash": "a4c45df07fe0ebc26b1af6caaad9fee8500fece7", "best_bid": "0.018", "best_ask": "0.118"}], "timestamp": "1769385016028", "event_type": "price_change"}}
{"_local_timestamp": "2026-01-25T23:50:16.164390+00:00", "data": {"market": "0x70e2c432a9f1c46194b4ed01276fce4b42ba14fa4121bb6a204bd27043fa6ec0", "price_changes": [{"asset_id": "96293988997073127556538359019802355814918008050500416514241789357023389177644", "price": "0.883", "size": "135.71", "side": "BUY", "hash": "b528abccb01d2ad1ba98a812fcb533600835136e", "best_bid": "0.883", "best_ask": "0.982"}, {"asset_id": "76151979298166149168681611766855150167264661944933736838438696924609959086385", "price": "0.117", "size": "135.71", "side": "SELL", "hash": "f090c432f43cd990ae80d8a6f640a014b34bbc8f", "best_bid": "0.018", "best_ask": "0.117"}], "timestamp": "1769385016029", "event_type": "price_change"}}
{"_local_timestamp": "2026-01-25T23:50:17.284070+00:00", "data": {"market": "0x10aa044e00621209c1e6516ed820607867e1939c51e6416e78389133c07a28ca", "price_changes": [{"asset_id": "114217190078574681732390148219500280529940631077811733810801001867278151517965", "price": "0.74", "size": "0", "side": "BUY", "hash": "256d9daf5734af55f22db0186954d92b6157e26a", "best_bid": "0.84", "best_ask": "0.85"}, {"asset_id": "106590375374356420328249754119755979864494562435507082169975336179942135107522", "price": "0.26", "size": "0", "side": "SELL", "hash": "2b21556785824f3101b97add80540442b9392de6", "best_bid": "0.15", "best_ask": "0.16"}], "timestamp": "1769385017184", "event_type": "price_change"}}
{"_local_timestamp": "2026-01-25T23:50:17.950338+00:00", "data": {"market": "0x70e2c432a9f1c46194b4ed01276fce4b42ba14fa4121bb6a204bd27043fa6ec0", "price_changes": [{"asset_id": "96293988997073127556538359019802355814918008050500416514241789357023389177644", "price": "0.882", "size": "135.71", "side": "BUY", "hash": "9729c72740243e20a75ddedf69b442401fd3cd4c", "best_bid": "0.883", "best_ask": "0.982"}, {"asset_id": "76151979298166149168681611766855150167264661944933736838438696924609959086385", "price": "0.118", "size": "135.71", "side": "SELL", "hash": "410dfdf29e074c8fd6734e48dd0fabebbad198a3", "best_bid": "0.018", "best_ask": "0.117"}], "timestamp": "1769385017855", "event_type": "price_change"}}
{"_local_timestamp": "2026-01-25T23:50:17.981910+00:00", "data": {"market": "0x70e2c432a9f1c46194b4ed01276fce4b42ba14fa4121bb6a204bd27043fa6ec0", "price_changes": [{"asset_id": "96293988997073127556538359019802355814918008050500416514241789357023389177644", "price": "0.884", "size": "20", "side": "BUY", "hash": "ecdf0660720a3ffa8542ea879ee465af40f58d93", "best_bid": "0.884", "best_ask": "0.982"}, {"asset_id": "76151979298166149168681611766855150167264661944933736838438696924609959086385", "price": "0.116", "size": "20", "side": "SELL", "hash": "5a96b701d4a21f089ad6be489e209d3ee8e09579", "best_bid": "0.018", "best_ask": "0.116"}], "timestamp": "1769385017883", "event_type": "price_change"}}
{"_local_timestamp": "2026-01-25T23:50:21.630910+00:00", "data": {"market": "0x70e2c432a9f1c46194b4ed01276fce4b42ba14fa4121bb6a204bd27043fa6ec0", "price_changes": [{"asset_id": "96293988997073127556538359019802355814918008050500416514241789357023389177644", "price": "0.884", "size": "70", "side": "BUY", "hash": "a64f34485fecaa1d5493910ac9b08c15877f3ef0", "best_bid": "0.884", "best_ask": "0.982"}, {"asset_id": "76151979298166149168681611766855150167264661944933736838438696924609959086385", "price": "0.116", "size": "70", "side": "SELL", "hash": "b92588564906664949d65d6db35510d3d33fa7a6", "best_bid": "0.018", "best_ask": "0.116"}], "timestamp": "1769385021531", "event_type": "price_change"}}
{"_local_timestamp": "2026-01-25T23:50:22.067037+00:00", "data": {"market": "0x70e2c432a9f1c46194b4ed01276fce4b42ba14fa4121bb6a204bd27043fa6ec0", "price_changes": [{"asset_id": "96293988997073127556538359019802355814918008050500416514241789357023389177644", "price": "0.212", "size": "0", "side": "BUY", "hash": "c3ab4e962ac265bbdc865746380f25aeca7be62e", "best_bid": "0.884", "best_ask": "0.982"}, {"asset_id": "76151979298166149168681611766855150167264661944933736838438696924609959086385", "price": "0.788", "size": "0", "side": "SELL", "hash": "c9b06536eb8446ddaf4a609ea1740d0f1c78b743", "best_bid": "0.018", "best_ask": "0.116"}], "timestamp": "1769385021979", "event_type": "price_change"}}
{"_local_timestamp": "2026-01-25T23:50:22.465568+00:00", "data": {"market": "0x70e2c432a9f1c46194b4ed01276fce4b42ba14fa4121bb6a204bd27043fa6ec0", "price_changes": [{"asset_id": "96293988997073127556538359019802355814918008050500416514241789357023389177644", "price": "0.884", "size": "115", "side": "BUY", "hash": "68a7d7a396eacac238bb5f8e5d6b4deb073af9b2", "best_bid": "0.884", "best_ask": "0.982"}, {"asset_id": "76151979298166149168681611766855150167264661944933736838438696924609959086385", "price": "0.116", "size": "115", "side": "SELL", "hash": "d272aa64c4d8079b853acdde8e31f54928786f0d", "best_bid": "0.018", "best_ask": "0.116"}], "timestamp": "1769385022370", "event_type": "price_change"}}
{"_local_timestamp": "2026-01-25T23:50:24.214869+00:00", "data": {"market": "0x10aa044e00621209c1e6516ed820607867e1939c51e6416e78389133c07a28ca", "price_changes": [{"asset_id": "114217190078574681732390148219500280529940631077811733810801001867278151517965", "price": "0.84", "size": "127.07", "side": "BUY", "hash": "7fdae3e12568e7a84a9d4522c693090fe15d073a", "best_bid": "0.84", "best_ask": "0.85"}, {"asset_id": "106590375374356420328249754119755979864494562435507082169975336179942135107522", "price": "0.16", "size": "127.07", "side": "SELL", "hash": "d5c1fe77c4d13300de3f0556bc165e7ebe541882", "best_bid": "0.15", "best_ask": "0.16"}], "timestamp": "1769385024109", "event_type": "price_change"}}
{"_local_timestamp": "2026-01-25T23:50:26.152318+00:00", "data": {"market": "0x70e2c432a9f1c46194b4ed01276fce4b42ba14fa4121bb6a204bd27043fa6ec0", "price_changes": [{"asset_id": "96293988997073127556538359019802355814918008050500416514241789357023389177644", "price": "0.884", "size": "95", "side": "BUY", "hash": "eeb7c5f440f43199cf84a2cdad080f9bc9b60f61", "best_bid": "0.884", "best_ask": "0.982"}, {"asset_id": "76151979298166149168681611766855150167264661944933736838438696924609959086385", "price": "0.116", "size": "95", "side": "SELL", "hash": "e1c00ec5666ec5d112cf88eb0958ecc49496ce73", "best_bid": "0.018", "best_ask": "0.116"}], "timestamp": "1769385026003", "event_type": "price_change"}}
{"_local_timestamp": "2026-01-25T23:50:26.198931+00:00", "data": {"market": "0x70e2c432a9f1c46194b4ed01276fce4b42ba14fa4121bb6a204bd27043fa6ec0", "price_changes": [{"asset_id": "96293988997073127556538359019802355814918008050500416514241789357023389177644", "price": "0.885", "size": "20", "side": "BUY", "hash": "e2937752b93947caeac2145e968b6e6cc250f948", "best_bid": "0.885", "best_ask": "0.982"}, {"asset_id": "76151979298166149168681611766855150167264661944933736838438696924609959086385", "price": "0.115", "size": "20", "side": "SELL", "hash": "7ddce2a9d0304dd45d5e83a19d5e3af8e43b9d2c", "best_bid": "0.018", "best_ask": "0.115"}], "timestamp": "1769385026037", "event_type": "price_change"}}
{"_local_timestamp": "2026-01-25T23:50:26.647525+00:00", "data": {"market": "0x70e2c432a9f1c46194b4ed01276fce4b42ba14fa4121bb6a204bd27043fa6ec0", "price_changes": [{"asset_id": "96293988997073127556538359019802355814918008050500416514241789357023389177644", "price": "0.884", "size": "125", "side": "BUY", "hash": "85883964251f8438ca0f7fdf3c936683e8d60216", "best_bid": "0.885", "best_ask": "0.982"}, {"asset_id": "76151979298166149168681611766855150167264661944933736838438696924609959086385", "price": "0.116", "size": "125", "side": "SELL", "hash": "5c7073a0c597d86f29bd8ff5b36ceab0b4aa34ab", "best_bid": "0.018", "best_ask": "0.115"}], "timestamp": "1769385026565", "event_type": "price_change"}}
{"_local_timestamp": "2026-01-25T23:50:29.485234+00:00", "data": {"market": "0x70e2c432a9f1c46194b4ed01276fce4b42ba14fa4121bb6a204bd27043fa6ec0", "price_changes": [{"asset_id": "96293988997073127556538359019802355814918008050500416514241789357023389177644", "price": "0.881", "size": "0", "side": "BUY", "hash": "f58d40104cc330c9bad669b5e77159dc90cb5f14", "best_bid": "0.885", "best_ask": "0.982"}, {"asset_id": "76151979298166149168681611766855150167264661944933736838438696924609959086385", "price": "0.119", "size": "0", "side": "SELL", "hash": "7e62eebc4b3c0404f930a4b1f94c846648efda40", "best_bid": "0.018", "best_ask": "0.115"}], "timestamp": "1769385029313", "event_type": "price_change"}}
{"_local_timestamp": "2026-01-25T23:50:29.486217+00:00", "data": {"market": "0x70e2c432a9f1c46194b4ed01276fce4b42ba14fa4121bb6a204bd27043fa6ec0", "price_changes": [{"asset_id": "96293988997073127556538359019802355814918008050500416514241789357023389177644", "price": "0.882", "size": "0", "side": "BUY", "hash": "f58d40104cc330c9bad669b5e77159dc90cb5f14", "best_bid": "0.885", "best_ask": "0.982"}, {"asset_id": "76151979298166149168681611766855150167264661944933736838438696924609959086385", "price": "0.118", "size": "0", "side": "SELL", "hash": "7e62eebc4b3c0404f930a4b1f94c846648efda40", "best_bid": "0.018", "best_ask": "0.115"}], "timestamp": "1769385029313", "event_type": "price_change"}}
{"_local_timestamp": "2026-01-25T23:50:30.194489+00:00", "data": {"market": "0x70e2c432a9f1c46194b4ed01276fce4b42ba14fa4121bb6a204bd27043fa6ec0", "price_changes": [{"asset_id": "96293988997073127556538359019802355814918008050500416514241789357023389177644", "price": "0.884", "size": "95", "side": "BUY", "hash": "567ce2ef472fc794613dd9e270b2bcbbe3238873", "best_bid": "0.885", "best_ask": "0.982"}, {"asset_id": "76151979298166149168681611766855150167264661944933736838438696924609959086385", "price": "0.116", "size": "95", "side": "SELL", "hash": "d9ed36daaf509ed1ba11b310a6821e9edf2dc10e", "best_bid": "0.018", "best_ask": "0.115"}], "timestamp": "1769385030024", "event_type": "price_change"}}
{"_local_timestamp": "2026-01-25T23:50:34.167289+00:00", "data": {"market": "0x70e2c432a9f1c46194b4ed01276fce4b42ba14fa4121bb6a204bd27043fa6ec0", "price_changes": [{"asset_id": "96293988997073127556538359019802355814918008050500416514241789357023389177644", "price": "0.212", "size": "50", "side": "BUY", "hash": "e3b3acf6f2d250780b958b014f6988423f22193f", "best_bid": "0.885", "best_ask": "0.982"}, {"asset_id": "76151979298166149168681611766855150167264661944933736838438696924609959086385", "price": "0.788", "size": "50", "side": "SELL", "hash": "9664c4cdb1858e5b1b42b201d63e356884e8eea7", "best_bid": "0.018", "best_ask": "0.115"}], "timestamp": "1769385033973", "event_type": "price_change"}}
{"_local_timestamp": "2026-01-25T23:50:34.603465+00:00", "data": {"market": "0x70e2c432a9f1c46194b4ed01276fce4b42ba14fa4121bb6a204bd27043fa6ec0", "price_changes": [{"asset_id": "96293988997073127556538359019802355814918008050500416514241789357023389177644", "price": "0.884", "size": "45", "side": "BUY", "hash": "80577fec20a50c2700c630dd14cf7746f8d9aac6", "best_bid": "0.885", "best_ask": "0.982"}, {"asset_id": "76151979298166149168681611766855150167264661944933736838438696924609959086385", "price": "0.116", "size": "45", "side": "SELL", "hash": "c1564e2517e169527f345452f84a1350601454a4", "best_bid": "0.018", "best_ask": "0.115"}], "timestamp": "1769385034401", "event_type": "price_change"}}
{"_local_timestamp": "2026-01-25T23:50:40.413533+00:00", "data": {"market": "0x70e2c432a9f1c46194b4ed01276fce4b42ba14fa4121bb6a204bd27043fa6ec0", "price_changes": [{"asset_id": "96293988997073127556538359019802355814918008050500416514241789357023389177644", "price": "0.885", "size": "70", "side": "BUY", "hash": "a901dd2fc5704bb33864ebb57dca73fda05f484a", "best_bid": "0.885", "best_ask": "0.982"}, {"asset_id": "76151979298166149168681611766855150167264661944933736838438696924609959086385", "price": "0.115", "size": "70", "side": "SELL", "hash": "2440d10c3c38c13a6ec4c15b4868b3e94448b89f", "best_bid": "0.018", "best_ask": "0.115"}], "timestamp": "1769385040200", "event_type": "price_change"}}
{"_local_timestamp": "2026-01-25T23:50:40.729631+00:00", "data": {"market": "0x70e2c432a9f1c46194b4ed01276fce4b42ba14fa4121bb6a204bd27043fa6ec0", "price_changes": [{"asset_id": "96293988997073127556538359019802355814918008050500416514241789357023389177644", "price": "0.212", "size": "0", "side": "BUY", "hash": "8ca08db4bd33037d291b12a7afcd35e320bc579b", "best_bid": "0.885", "best_ask": "0.982"}, {"asset_id": "76151979298166149168681611766855150167264661944933736838438696924609959086385", "price": "0.788", "size": "0", "side": "SELL", "hash": "d45e95dd572fc6a3009c7846b19f97fb118fad38", "best_bid": "0.018", "best_ask": "0.115"}], "timestamp": "1769385040540", "event_type": "price_change"}}
{"_local_timestamp": "2026-01-25T23:50:45.270113+00:00", "data": {"market": "0x70e2c432a9f1c46194b4ed01276fce4b42ba14fa4121bb6a204bd27043fa6ec0", "price_changes": [{"asset_id": "96293988997073127556538359019802355814918008050500416514241789357023389177644", "price": "0.885", "size": "50", "side": "BUY", "hash": "62d53467dd3f72095dc6089d31568444938113ce", "best_bid": "0.885", "best_ask": "0.982"}, {"asset_id": "76151979298166149168681611766855150167264661944933736838438696924609959086385", "price": "0.115", "size": "50", "side": "SELL", "hash": "1aafde0fc6f63d10918705ba3d46b00ffc3dbb20", "best_bid": "0.018", "best_ask": "0.115"}], "timestamp": "1769385045196", "event_type": "price_change"}}
{"_local_timestamp": "2026-01-25T23:50:45.295934+00:00", "data": {"market": "0x70e2c432a9f1c46194b4ed01276fce4b42ba14fa4121bb6a204bd27043fa6ec0", "price_changes": [{"asset_id": "96293988997073127556538359019802355814918008050500416514241789357023389177644", "price": "0.886", "size": "20", "side": "BUY", "hash": "f3b13fc2940a8d215f454a26a04b87c1a194acc8", "best_bid": "0.886", "best_ask": "0.982"}, {"asset_id": "76151979298166149168681611766855150167264661944933736838438696924609959086385", "price": "0.114", "size": "20", "side": "SELL", "hash": "ccbcee4883c83cc647d6531c639f5b3ad35d6921", "best_bid": "0.018", "best_ask": "0.114"}], "timestamp": "1769385045225", "event_type": "price_change"}}
{"_local_timestamp": "2026-01-25T23:50:52.266582+00:00", "data": {"market": "0x026f75cda28b435d52c8615dc2eaa8895b4632e9f53c98255f2bced50fbb5018", "price_changes": [{"asset_id": "103477786055085350112953174136231624107339341173836019810109648103195092330225", "price": "0.12", "size": "14.09", "side": "BUY", "hash": "6f65330acfff89015cb85950897dff1d4e62e657", "best_bid": "0.12", "best_ask": "0.13"}, {"asset_id": "18282828012097738947825685359604327312283762551135248913642539025764020349015", "price": "0.88", "size": "14.09", "side": "SELL", "hash": "3e3e7ab1b9da368b5ccd4482301f3a8d8e6edb4a", "best_bid": "0.87", "best_ask": "0.88"}], "timestamp": "1769385052191", "event_type": "price_change"}}
{"_local_timestamp": "2026-01-25T23:50:56.106992+00:00", "data": {"market": "0x0e4536b6aaf51d080f7414bb68009ba5b1d826d24530fbadbca2e3f7e4227e34", "asset_id": "66796898799007262533573083628291477479823184385652148020496261238624922732970", "price": "0.999", "size": "17.017", "fee_rate_bps": "0", "side": "BUY", "timestamp": "1769385056032", "event_type": "last_trade_price", "transaction_hash": "0x04e23d39cc1bbec30907b96d48864bd9041a155598b096321e303c3c80a19549"}}
{"_local_timestamp": "2026-01-25T23:50:56.130906+00:00", "data": {"market": "0x0e4536b6aaf51d080f7414bb68009ba5b1d826d24530fbadbca2e3f7e4227e34", "price_changes": [{"asset_id": "13539255989319659082805101136090441229143955236158172607278915698110589985388", "price": "0.001", "size": "1534.04", "side": "BUY", "hash": "03ecbef77d5ff399b278f4080eab1e3e49247a54", "best_bid": "0.001", "best_ask": "0.005"}, {"asset_id": "66796898799007262533573083628291477479823184385652148020496261238624922732970", "price": "0.999", "size": "1534.04", "side": "SELL", "hash": "c07d29720a4c2a8e9a696a8da50f81ed974c3d57", "best_bid": "0.995", "best_ask": "0.999"}], "timestamp": "1769385056007", "event_type": "price_change"}}
{"_local_timestamp": "2026-01-25T23:50:56.131820+00:00", "data": {"market": "0x0e4536b6aaf51d080f7414bb68009ba5b1d826d24530fbadbca2e3f7e4227e34", "asset_id": "13539255989319659082805101136090441229143955236158172607278915698110589985388", "bids": [{"price": "0.001", "size": "1534.04"}], "asks": [{"price": "0.999", "size": "7406.85"}, {"price": "0.998", "size": "1755.83"}, {"price": "0.997", "size": "1166"}, {"price": "0.996", "size": "10.09"}, {"price": "0.994", "size": "83"}, {"price": "0.99", "size": "2783"}, {"price": "0.989", "size": "5.13"}, {"price": "0.98", "size": "3700"}, {"price": "0.979", "size": "10.08"}, {"price": "0.959", "size": "48"}, {"price": "0.95", "size": "60"}, {"price": "0.949", "size": "39"}, {"price": "0.94", "size": "200"}, {"price": "0.939", "size": "7.27"}, {"price": "0.89", "size": "325"}, {"price": "0.888", "size": "52"}, {"price": "0.84", "size": "250"}, {"price": "0.839", "size": "7.63"}, {"price": "0.777", "size": "9"}, {"price": "0.76", "size": "150"}, {"price": "0.759", "size": "8"}, {"price": "0.177", "size": "75"}, {"price": "0.176", "size": "20"}, {"price": "0.05", "size": "172"}, {"price": "0.012", "size": "10.82"}, {"price": "0.005", "size": "1921.2"}], "hash": "03ecbef77d5ff399b278f4080eab1e3e49247a54", "timestamp": "1769385056007", "event_type": "book"}}
{"_local_timestamp": "2026-01-25T23:50:56.132660+00:00", "data": {"market": "0x0e4536b6aaf51d080f7414bb68009ba5b1d826d24530fbadbca2e3f7e4227e34", "asset_id": "66796898799007262533573083628291477479823184385652148020496261238624922732970", "bids": [{"price": "0.001", "size": "7406.85"}, {"price": "0.002", "size": "1755.83"}, {"price": "0.003", "size": "1166"}, {"price": "0.004", "size": "10.09"}, {"price": "0.006", "size": "83"}, {"price": "0.01", "size": "2783"}, {"price": "0.011", "size": "5.13"}, {"price": "0.02", "size": "3700"}, {"price": "0.021", "size": "10.08"}, {"price": "0.041", "size": "48"}, {"price": "0.05", "size": "60"}, {"price": "0.051", "size": "39"}, {"price": "0.06", "size": "200"}, {"price": "0.061", "size": "7.27"}, {"price": "0.11", "size": "325"}, {"price": "0.112", "size": "52"}, {"price": "0.16", "size": "250"}, {"price": "0.161", "size": "7.63"}, {"price": "0.223", "size": "9"}, {"price": "0.24", "size": "150"}, {"price": "0.241", "size": "8"}, {"price": "0.823", "size": "75"}, {"price": "0.824", "size": "20"}, {"price": "0.95", "size": "172"}, {"price": "0.988", "size": "10.82"}, {"price": "0.995", "size": "1921.2"}], "asks": [{"price": "0.999", "size": "1534.04"}], "hash": "c07d29720a4c2a8e9a696a8da50f81ed974c3d57", "timestamp": "1769385056007", "event_type": "book"}}
{"_local_timestamp": "2026-01-25T23:51:05.423974+00:00", "data": {"market": "0x70e2c432a9f1c46194b4ed01276fce4b42ba14fa4121bb6a204bd27043fa6ec0", "price_changes": [{"asset_id": "96293988997073127556538359019802355814918008050500416514241789357023389177644", "price": "0.21", "size": "0", "side": "BUY", "hash": "49c0a4788dc9bf4cd05a5eb223ce2b15e463c0c8", "best_bid": "0.886", "best_ask": "0.982"}, {"asset_id": "76151979298166149168681611766855150167264661944933736838438696924609959086385", "price": "0.79", "size": "0", "side": "SELL", "hash": "9166e3f25bc0fff3d36291c089a251a8de61bc10", "best_bid": "0.018", "best_ask": "0.114"}], "timestamp": "1769385065356", "event_type": "price_change"}}
{"_local_timestamp": "2026-01-25T23:51:05.882787+00:00", "data": {"market": "0x70e2c432a9f1c46194b4ed01276fce4b42ba14fa4121bb6a204bd27043fa6ec0", "price_changes": [{"asset_id": "96293988997073127556538359019802355814918008050500416514241789357023389177644", "price": "0.211", "size": "225", "side": "BUY", "hash": "11761a807f33765d4454e3a6875a4d1b7bbc4d7d", "best_bid": "0.886", "best_ask": "0.982"}, {"asset_id": "76151979298166149168681611766855150167264661944933736838438696924609959086385", "price": "0.789", "size": "225", "side": "SELL", "hash": "e416af378141d1a815842e1c538455c27e00a0ac", "best_bid": "0.018", "best_ask": "0.114"}], "timestamp": "1769385065766", "event_type": "price_change"}}
{"_local_timestamp": "2026-01-25T23:51:08.059937+00:00", "data": {"market": "0x026f75cda28b435d52c8615dc2eaa8895b4632e9f53c98255f2bced50fbb5018", "price_changes": [{"asset_id": "103477786055085350112953174136231624107339341173836019810109648103195092330225", "price": "0.12", "size": "44.21", "side": "BUY", "hash": "d828bb647f328dbcb43274b306c603ab85c9e5b4", "best_bid": "0.12", "best_ask": "0.13"}, {"asset_id": "18282828012097738947825685359604327312283762551135248913642539025764020349015", "price": "0.88", "size": "44.21", "side": "SELL", "hash": "31603609e51d407009a304b2eb0431541f2e84bd", "best_bid": "0.87", "best_ask": "0.88"}], "timestamp": "1769385067990", "event_type": "price_change"}}
{"_local_timestamp": "2026-01-25T23:51:08.060799+00:00", "data": {"market": "0x026f75cda28b435d52c8615dc2eaa8895b4632e9f53c98255f2bced50fbb5018", "price_changes": [{"asset_id": "103477786055085350112953174136231624107339341173836019810109648103195092330225", "price": "0.12", "size": "74.33", "side": "BUY", "hash": "ae23a9aa3decad505d354a643495a0c97a5df9ba", "best_bid": "0.12", "best_ask": "0.13"}, {"asset_id": "18282828012097738947825685359604327312283762551135248913642539025764020349015", "price": "0.88", "size": "74.33", "side": "SELL", "hash": "ff3f0d153f9ef79a0c79415c919b6ee9ce183beb", "best_bid": "0.87", "best_ask": "0.88"}], "timestamp": "1769385067990", "event_type": "price_change"}}
{"_local_timestamp": "2026-01-25T23:51:08.067793+00:00", "data": {"market": "0x026f75cda28b435d52c8615dc2eaa8895b4632e9f53c98255f2bced50fbb5018", "price_changes": [{"asset_id": "103477786055085350112953174136231624107339341173836019810109648103195092330225", "price": "0.12", "size": "104.45", "side": "BUY", "hash": "e03a167c6dc85921f55d1d6274ca9165f41d016e", "best_bid": "0.12", "best_ask": "0.13"}, {"asset_id": "18282828012097738947825685359604327312283762551135248913642539025764020349015", "price": "0.88", "size": "104.45", "side": "SELL", "hash": "daa411b7519dcdd72d9b7fe190ccb86d0eed5e3a", "best_bid": "0.87", "best_ask": "0.88"}], "timestamp": "1769385067991", "event_type": "price_change"}}
{"_local_timestamp": "2026-01-25T23:51:08.068580+00:00", "data": {"market": "0x026f75cda28b435d52c8615dc2eaa8895b4632e9f53c98255f2bced50fbb5018", "price_changes": [{"asset_id": "103477786055085350112953174136231624107339341173836019810109648103195092330225", "price": "0.12", "size": "134.57", "side": "BUY", "hash": "2dc59f79f2d4c6b83861d590e081e745093bd0bd", "best_bid": "0.12", "best_ask": "0.13"}, {"asset_id": "18282828012097738947825685359604327312283762551135248913642539025764020349015", "price": "0.88", "size": "134.57", "side": "SELL", "hash": "ef886aa4b34f9b48b30c79f4321e93dd14fbcc63", "best_bid": "0.87", "best_ask": "0.88"}], "timestamp": "1769385067991", "event_type": "price_change"}}
{"_local_timestamp": "2026-01-25T23:51:19.927164+00:00", "data": {"market": "0xfbc27b527d29e83b5add21aec7e8ae12bcfe1802cc9d697fd2fc3ef971e73b1a", "price_changes": [{"asset_id": "20742295429047093344183624784356215475991906727753544432953361940370520424440", "price": "0.302", "size": "0", "side": "BUY", "hash": "1464ae5ea75974fe356389a5cfea5bfadd6c53c0", "best_bid": "0.997", "best_ask": "0.998"}, {"asset_id": "20976114661621715860645243051991645946734532418059434954111576177898236905114", "price": "0.698", "size": "0", "side": "SELL", "hash": "e64cc9d328def6c1e706115abd21cf78dd0481a6", "best_bid": "0.002", "best_ask": "0.003"}], "timestamp": "1769385079852", "event_type": "price_change"}}
{"_local_timestamp": "2026-01-25T23:51:19.982338+00:00", "data": {"market": "0xfbc27b527d29e83b5add21aec7e8ae12bcfe1802cc9d697fd2fc3ef971e73b1a", "price_changes": [{"asset_id": "20742295429047093344183624784356215475991906727753544432953361940370520424440", "price": "0.302", "size": "6", "side": "BUY", "hash": "e78672e35805f8be77249b5627403cf8f2593b43", "best_bid": "0.997", "best_ask": "0.998"}, {"asset_id": "20976114661621715860645243051991645946734532418059434954111576177898236905114", "price": "0.698", "size": "6", "side": "SELL", "hash": "143c3c1bda5a3324fbc4e93e0f5ffb5c80d00c40", "best_bid": "0.002", "best_ask": "0.003"}], "timestamp": "1769385079898", "event_type": "price_change"}}
