{"_local_timestamp": "2026-01-25T23:33:17.078799+00:00", "data": [{"market": "0x5533fb9ab797777a243c75b1bf3882c54b1ee91f794730c090bf701598993529", "asset_id": "99478074208094578615268494931219682040135218828258512927013036335093067688695", "timestamp": "1769383990751", "hash": "395d685fd634d65104f9257aaaac18a21f9a03ff", "bids": [{"price": "0.001", "size": "103798.37"}, {"price": "0.002", "size": "6256.17"}, {"price": "0.003", "size": "6400"}, {"price": "0.004", "size": "10.67"}, {"price": "0.006", "size": "200"}, {"price": "0.01", "size": "23"}, {"price": "0.011", "size": "10.68"}, {"price": "0.03", "size": "300"}, {"price": "0.031", "size": "8.88"}, {"price": "0.05", "size": "10"}, {"price": "0.051", "size": "9.8"}, {"price": "0.1", "size": "360"}, {"price": "0.124", "size": "3000"}, {"price": "0.15", "size": "226.66"}, {"price": "0.2", "size": "160"}, {"price": "0.201", "size": "5.2"}, {"price": "0.223", "size": "165"}, {"price": "0.25", "size": "112"}, {"price": "0.3", "size": "86.66"}, {"price": "0.321", "size": "800"}, {"price": "0.35", "size": "68.57"}, {"price": "0.4", "size": "1050"}, {"price": "0.404", "size": "3000"}, {"price": "0.523", "size": "150"}, {"price": "0.524", "size": "5"}, {"price": "0.723", "size": "24"}, {"price": "0.823", "size": "190"}, {"price": "0.923", "size": "432"}, {"price": "0.924", "size": "20"}, {"price": "0.979", "size": "75.5"}, {"price": "0.98", "size": "228.24"}, {"price": "0.982", "size": "198.02"}, {"price": "0.986", "size": "1081.93"}, {"price": "0.987", "size": "60"}, {"price": "0.99", "size": "35"}, {"price": "0.991", "size": "45"}], "asks": [{"price": "0.999", "size": "5000"}, {"price": "0.998", "size": "16.38"}], "event_type": "book", "last_trade_price": "0.002"}, {"market": "0xea644975be7b2ad32b536a94ae21b707ecb2f84290225b24e60ca46dd77903dd", "asset_id": "110044455628775971785618539427229099821815416148768008176051068105157446559241", "timestamp": "1769383775780", "hash": "ce0de1ec248ff277ddeeb4729e4703e5c6573527", "bids": [{"price": "0.001", "size": "4979.22"}, {"price": "0.002", "size": "262.59"}, {"price": "0.003", "size": "54.9"}, {"price": "0.004", "size": "21.72"}, {"price": "0.01", "size": "32.65"}], "asks": [{"price": "0.999", "size": "203624.7"}, {"price": "0.998", "size": "1256.18"}, {"price": "0.997", "size": "51400"}, {"price": "0.996", "size": "10.68"}, {"price": "0.994", "size": "200"}, {"price": "0.99", "size": "41"}, {"price": "0.989", "size": "10.69"}, {"price": "0.97", "size": "300"}, {"price": "0.969", "size": "8.88"}, {"price": "0.957", "size": "2000"}, {"price": "0.95", "size": "10"}, {"price": "0.949", "size": "9.8"}, {"price": "0.9", "size": "360"}, {"price": "0.85", "size": "226.66"}, {"price": "0.846", "size": "500"}, {"price": "0.8", "size": "160"}, {"price": "0.799", "size": "5.2"}, {"price": "0.777", "size": "134"}, {"price": "0.75", "size": "112"}, {"price": "0.7", "size": "86.66"}, {"price": "0.699", "size": "6"}, {"price": "0.65", "size": "68.57"}, {"price": "0.6", "size": "50"}, {"price": "0.477", "size": "226"}, {"price": "0.277", "size": "83"}, {"price": "0.177", "size": "280"}, {"price": "0.077", "size": "765"}, {"price": "0.076", "size": "20"}, {"price": "0.026", "size": "499.98"}, {"price": "0.02", "size": "198.02"}, {"price": "0.014", "size": "3261.97"}, {"price": "0.013", "size": "163"}, {"price": "0.012", "size": "12"}], "event_type": "book", "last_trade_price": "0.010"}, {"market": "0x9d24d9f9b5995949cb158d943793dea20bd448e1b3971cb6f7418bb15e719661", "asset_id": "79516121807256184736227920754945730465880754940725759201193439378549308939672", "timestamp": "1769383995576", "hash": "d73739ed7094258297d3c7a86c72bf129c16223f", "bids": [{"price": "0.001", "size": "303682.61"}, {"price": "0.002", "size": "1259.24"}, {"price": "0.003", "size": "1400"}, {"price": "0.004", "size": "5000"}, {"price": "0.005", "size": "7.3"}, {"price": "0.006", "size": "200"}, {"price": "0.01", "size": "23"}, {"price": "0.011", "size": "5.41"}, {"price": "0.02", "size": "15"}, {"price": "0.021", "size": "5.44"}, {"price": "0.03", "size": "300"}, {"price": "0.04", "size": "1000"}, {"price": "0.041", "size": "5.33"}, {"price": "0.05", "size": "10"}, {"price": "0.051", "size": "9.8"}, {"price": "0.1", "size": "360"}, {"price": "0.15", "size": "226.66"}, {"price": "0.2", "size": "160"}, {"price": "0.201", "size": "5.2"}, {"price": "0.223", "size": "165"}, {"price": "0.25", "size": "112"}, {"price": "0.3", "size": "86.66"}, {"price": "0.35", "size": "68.57"}, {"price": "0.4", "size": "50"}, {"price": "0.47", "size": "500"}, {"price": "0.523", "size": "146"}, {"price": "0.524", "size": "5"}, {"price": "0.823", "size": "189"}, {"price": "0.923", "size": "439"}, {"price": "0.924", "size": "20"}, {"price": "0.97", "size": "500"}, {"price": "0.98", "size": "801.16"}, {"price": "0.982", "size": "594.06"}, {"price": "0.986", "size": "7886.36"}, {"price": "0.987", "size": "73.91"}], "asks": [{"price": "0.999", "size": "4926.38"}, {"price": "0.998", "size": "330.65"}], "event_type": "book", "last_trade_price": "0.998"}, {"market": "0x50e477f0b316a3d97d60486479657c63be0763834d0e2e8a30b1b86dc3c1c001", "asset_id": "60573178197991590327120832143415406583517170365625050489007297367895074266641", "timestamp": "1769383956001", "hash": "44a83ee62a3803776c0063060d0c018de9ca74a0", "bids": [{"price": "0.001", "size": "5000"}, {"price": "0.002", "size": "133"}, {"price": "0.01", "size": "74.66"}], "asks": [{"price": "0.999", "size": "203613.46"}, {"price": "0.998", "size": "1256.19"}, {"price": "0.997", "size": "41400"}, {"price": "0.996", "size": "10.69"}, {"price": "0.994", "size": "200"}, {"price": "0.99", "size": "23"}, {"price": "0.989", "size": "20.84"}, {"price": "0.97", "size": "300"}, {"price": "0.95", "size": "30"}, {"price": "0.949", "size": "13.03"}, {"price": "0.9", "size": "5360"}, {"price": "0.85", "size": "226.66"}, {"price": "0.8", "size": "160"}, {"price": "0.799", "size": "5.19"}, {"price": "0.777", "size": "78"}, {"price": "0.75", "size": "112"}, {"price": "0.7", "size": "86.66"}, {"price": "0.65", "size": "68.57"}, {"price": "0.648", "size": "800"}, {"price": "0.647", "size": "5"}, {"price": "0.6", "size": "50"}, {"price": "0.477", "size": "150"}, {"price": "0.277", "size": "90"}, {"price": "0.177", "size": "109.21"}, {"price": "0.176", "size": "20"}, {"price": "0.05", "size": "1578.33"}, {"price": "0.04", "size": "526.11"}, {"price": "0.03", "size": "701.47"}, {"price": "0.018", "size": "297.02"}, {"price": "0.014", "size": "1548.58"}], "event_type": "book", "last_trade_price": "0.010"}, {"market": "0xe68594f1350f5535532b24979b5b5c1948432cbfc0c363802c32a8f9ab4e6509", "asset_id": "3074032031589250926591186368301243337494992039402397918135503567058257050088", "timestamp": "1769383643287", "hash": "9a1fde5e18fb497b0ef4c8ab8941e9bc179a7f24", "bids": [{"price": "0.001", "size": "203734.57"}, {"price": "0.002", "size": "1256.17"}, {"price": "0.003", "size": "41400"}, {"price": "0.004", "size": "10.67"}, {"price": "0.006", "size": "200"}, {"price": "0.01", "size": "23"}, {"price": "0.011", "size": "11.72"}, {"price": "0.03", "size": "300"}, {"price": "0.032", "size": "5000"}, {"price": "0.033", "size": "7.99"}, {"price": "0.05", "size": "10"}, {"price": "0.051", "size": "9.8"}, {"price": "0.1", "size": "360"}, {"price": "0.15", "size": "226.66"}, {"price": "0.2", "size": "160"}, {"price": "0.201", "size": "5.2"}, {"price": "0.223", "size": "165"}, {"price": "0.25", "size": "112"}, {"price": "0.3", "size": "86.66"}, {"price": "0.303", "size": "445"}, {"price": "0.35", "size": "68.57"}, {"price": "0.351", "size": "5"}, {"price": "0.4", "size": "50"}, {"price": "0.523", "size": "150"}, {"price": "0.723", "size": "181"}, {"price": "0.823", "size": "189"}, {"price": "0.923", "size": "438"}, {"price": "0.924", "size": "20"}, {"price": "0.955", "size": "259.98"}, {"price": "0.961", "size": "14.79"}, {"price": "0.98", "size": "198.02"}, {"price": "0.982", "size": "297.02"}, {"price": "0.986", "size": "861.67"}, {"price": "0.987", "size": "53.75"}, {"price": "0.988", "size": "45"}, {"price": "0.991", "size": "7.5"}, {"price": "0.992", "size": "11.25"}], "asks": [{"price": "0.999", "size": "4997.98"}], "event_type": "book", "last_trade_price": "0.002"}, {"market": "0xc0e6b917320a47228fb96e3b5ae0e5c93773a5ae2662ae4e1f37807cfe47ce98", "asset_id": "58656358377246279051017109359677190749228949103591068167284263961542487110215", "timestamp": "1769383977978", "hash": "ceb9c46c98b686d3168eb8c3a05bd77ed10d1ae3", "bids": [{"price": "0.001", "size": "433.77"}, {"price": "0.002", "size": "3299.96"}, {"price": "0.003", "size": "1327.6"}, {"price": "0.004", "size": "47.44"}, {"price": "0.005", "size": "1000"}, {"price": "0.006", "size": "132.58"}, {"price": "0.007", "size": "79.96"}, {"price": "0.012", "size": "13.62"}, {"price": "0.013", "size": "15.2"}, {"price": "0.02", "size": "63"}, {"price": "0.021", "size": "77.77"}], "asks": [{"price": "0.999", "size": "44769.2"}, {"price": "0.998", "size": "11250"}, {"price": "0.997", "size": "1844"}, {"price": "0.994", "size": "200"}, {"price": "0.99", "size": "23"}, {"price": "0.97", "size": "300"}, {"price": "0.95", "size": "30"}, {"price": "0.948", "size": "400"}, {"price": "0.806", "size": "5"}, {"price": "0.777", "size": "165"}, {"price": "0.65", "size": "500"}, {"price": "0.52", "size": "10"}, {"price": "0.477", "size": "150"}, {"price": "0.43", "size": "392.01"}, {"price": "0.41", "size": "500"}, {"price": "0.177", "size": "188"}, {"price": "0.077", "size": "289"}, {"price": "0.075", "size": "300"}, {"price": "0.065", "size": "10"}, {"price": "0.06", "size": "82.5"}, {"price": "0.05", "size": "78"}, {"price": "0.034", "size": "2185.91"}], "event_type": "book", "last_trade_price": "0.022"}, {"market": "0xe68594f1350f5535532b24979b5b5c1948432cbfc0c363802c32a8f9ab4e6509", "asset_id": "47459180813047899567328389455747872955901265556145057896316155826890276004242", "timestamp": "1769383643287", "hash": "410394fa6c597328f6db07dc14587463db57eb83", "bids": [{"price": "0.001", "size": "4997.98"}], "asks": [{"price": "0.999", "size": "203734.57"}, {"price": "0.998", "size": "1256.17"}, {"price": "0.997", "size": "41400"}, {"price": "0.996", "size": "10.67"}, {"price": "0.994", "size": "200"}, {"price": "0.99", "size": "23"}, {"price": "0.989", "size": "11.72"}, {"price": "0.97", "size": "300"}, {"price": "0.968", "size": "5000"}, {"price": "0.967", "size": "7.99"}, {"price": "0.95", "size": "10"}, {"price": "0.949", "size": "9.8"}, {"price": "0.9", "size": "360"}, {"price": "0.85", "size": "226.66"}, {"price": "0.8", "size": "160"}, {"price": "0.799", "size": "5.2"}, {"price": "0.777", "size": "165"}, {"price": "0.75", "size": "112"}, {"price": "0.7", "size": "86.66"}, {"price": "0.697", "size": "445"}, {"price": "0.65", "size": "68.57"}, {"price": "0.649", "size": "5"}, {"price": "0.6", "size": "50"}, {"price": "0.477", "size": "150"}, {"price": "0.277", "size": "181"}, {"price": "0.177", "size": "189"}, {"price": "0.077", "size": "438"}, {"price": "0.076", "size": "20"}, {"price": "0.045", "size": "259.98"}, {"price": "0.039", "size": "14.79"}, {"price": "0.02", "size": "198.02"}, {"price": "0.018", "size": "297.02"}, {"price": "0.014", "size": "861.67"}, {"price": "0.013", "size": "53.75"}, {"price": "0.012", "size": "45"}, {"price": "0.009", "size": "7.5"}, {"price": "0.008", "size": "11.25"}], "event_type": "book", "last_trade_price": "0.002"}, {"market": "0x5533fb9ab797777a243c75b1bf3882c54b1ee91f794730c090bf701598993529", "asset_id": "22532055631814907447535815649879981046415248231878961745474659705989546420934", "timestamp": "1769383990751", "hash": "4ad47454bd10ba712be27797c83aa3c70f9703bf", "bids": [{"price": "0.001", "size": "5000"}, {"price": "0.002", "size": "16.38"}], "asks": [{"price": "0.999", "size": "103798.37"}, {"price": "0.998", "size": "6256.17"}, {"price": "0.997", "size": "6400"}, {"price": "0.996", "size": "10.67"}, {"price": "0.994", "size": "200"}, {"price": "0.99", "size": "23"}, {"price": "0.989", "size": "10.68"}, {"price": "0.97", "size": "300"}, {"price": "0.969", "size": "8.88"}, {"price": "0.95", "size": "10"}, {"price": "0.949", "size": "9.8"}, {"price": "0.9", "size": "360"}, {"price": "0.876", "size": "3000"}, {"price": "0.85", "size": "226.66"}, {"price": "0.8", "size": "160"}, {"price": "0.799", "size": "5.2"}, {"price": "0.777", "size": "165"}, {"price": "0.75", "size": "112"}, {"price": "0.7", "size": "86.66"}, {"price": "0.679", "size": "800"}, {"price": "0.65", "size": "68.57"}, {"price": "0.6", "size": "1050"}, {"price": "0.596", "size": "3000"}, {"price": "0.477", "size": "150"}, {"price": "0.476", "size": "5"}, {"price": "0.277", "size": "24"}, {"price": "0.177", "size": "190"}, {"price": "0.077", "size": "432"}, {"price": "0.076", "size": "20"}, {"price": "0.021", "size": "75.5"}, {"price": "0.02", "size": "228.24"}, {"price": "0.018", "size": "198.02"}, {"price": "0.014", "size": "1081.93"}, {"price": "0.013", "size": "60"}, {"price": "0.01", "size": "35"}, {"price": "0.009", "size": "45"}], "event_type": "book", "last_trade_price": "0.002"}, {"market": "0xc0e6b917320a47228fb96e3b5ae0e5c93773a5ae2662ae4e1f37807cfe47ce98", "asset_id": "81647294538046680798858716589766492074338758116170717123345952330712416337530", "timestamp": "1769383977978", "hash": "1fb9f810ef9e6a4d663ba66cae9dd64c162bdc4f", "bids": [{"price": "0.001", "size": "44769.2"}, {"price": "0.002", "size": "11250"}, {"price": "0.003", "size": "1844"}, {"price": "0.006", "size": "200"}, {"price": "0.01", "size": "23"}, {"price": "0.03", "size": "300"}, {"price": "0.05", "size": "30"}, {"price": "0.052", "size": "400"}, {"price": "0.194", "size": "5"}, {"price": "0.223", "size": "165"}, {"price": "0.35", "size": "500"}, {"price": "0.48", "size": "10"}, {"price": "0.523", "size": "150"}, {"price": "0.57", "size": "392.01"}, {"price": "0.59", "size": "500"}, {"price": "0.823", "size": "188"}, {"price": "0.923", "size": "289"}, {"price": "0.925", "size": "300"}, {"price": "0.935", "size": "10"}, {"price": "0.94", "size": "82.5"}, {"price": "0.95", "size": "78"}, {"price": "0.966", "size": "2185.91"}], "asks": [{"price": "0.999", "size": "433.77"}, {"price": "0.998", "size": "3299.96"}, {"price": "0.997", "size": "1327.6"}, {"price": "0.996", "size": "47.44"}, {"price": "0.995", "size": "1000"}, {"price": "0.994", "size": "132.58"}, {"price": "0.993", "size": "79.96"}, {"price": "0.988", "size": "13.62"}, {"price": "0.987", "size": "15.2"}, {"price": "0.98", "size": "63"}, {"price": "0.979", "size": "77.77"}], "event_type": "book", "last_trade_price": "0.022"}, {"market": "0x9d24d9f9b5995949cb158d943793dea20bd448e1b3971cb6f7418bb15e719661", "asset_id": "70512916946285526357165287373537570327431985324385225788636160168740471920430", "timestamp": "1769383995576", "hash": "5f2c218913b4edde229af0c206c516034341ce52", "bids": [{"price": "0.001", "size": "4926.38"}, {"price": "0.002", "size": "330.65"}], "asks": [{"price": "0.999", "size": "303682.61"}, {"price": "0.998", "size": "1259.24"}, {"price": "0.997", "size": "1400"}, {"price": "0.996", "size": "5000"}, {"price": "0.995", "size": "7.3"}, {"price": "0.994", "size": "200"}, {"price": "0.99", "size": "23"}, {"price": "0.989", "size": "5.41"}, {"price": "0.98", "size": "15"}, {"price": "0.979", "size": "5.44"}, {"price": "0.97", "size": "300"}, {"price": "0.96", "size": "1000"}, {"price": "0.959", "size": "5.33"}, {"price": "0.95", "size": "10"}, {"price": "0.949", "size": "9.8"}, {"price": "0.9", "size": "360"}, {"price": "0.85", "size": "226.66"}, {"price": "0.8", "size": "160"}, {"price": "0.799", "size": "5.2"}, {"price": "0.777", "size": "165"}, {"price": "0.75", "size": "112"}, {"price": "0.7", "size": "86.66"}, {"price": "0.65", "size": "68.57"}, {"price": "0.6", "size": "50"}, {"price": "0.53", "size": "500"}, {"price": "0.477", "size": "146"}, {"price": "0.476", "size": "5"}, {"price": "0.177", "size": "189"}, {"price": "0.077", "size": "439"}, {"price": "0.076", "size": "20"}, {"price": "0.03", "size": "500"}, {"price": "0.02", "size": "801.16"}, {"price": "0.018", "size": "594.06"}, {"price": "0.014", "size": "7886.36"}, {"price": "0.013", "size": "73.91"}], "event_type": "book", "last_trade_price": "0.998"}, {"market": "0x50e477f0b316a3d97d60486479657c63be0763834d0e2e8a30b1b86dc3c1c001", "asset_id": "39981134260608444876865205057565852475343967395624370698967311821208058420507", "timestamp": "1769383956001", "hash": "7883beb9e76c78b2d584e9cba3fa86e93e85acec", "bids": [{"price": "0.001", "size": "203613.46"}, {"price": "0.002", "size": "1256.19"}, {"price": "0.003", "size": "41400"}, {"price": "0.004", "size": "10.69"}, {"price": "0.006", "size": "200"}, {"price": "0.01", "size": "23"}, {"price": "0.011", "size": "20.84"}, {"price": "0.03", "size": "300"}, {"price": "0.05", "size": "30"}, {"price": "0.051", "size": "13.03"}, {"price": "0.1", "size": "5360"}, {"price": "0.15", "size": "226.66"}, {"price": "0.2", "size": "160"}, {"price": "0.201", "size": "5.19"}, {"price": "0.223", "size": "78"}, {"price": "0.25", "size": "112"}, {"price": "0.3", "size": "86.66"}, {"price": "0.35", "size": "68.57"}, {"price": "0.352", "size": "800"}, {"price": "0.353", "size": "5"}, {"price": "0.4", "size": "50"}, {"price": "0.523", "size": "150"}, {"price": "0.723", "size": "90"}, {"price": "0.823", "size": "109.21"}, {"price": "0.824", "size": "20"}, {"price": "0.95", "size": "1578.33"}, {"price": "0.96", "size": "526.11"}, {"price": "0.97", "size": "701.47"}, {"price": "0.982", "size": "297.02"}, {"price": "0.986", "size": "1548.58"}], "asks": [{"price": "0.999", "size": "5000"}, {"price": "0.998", "size": "133"}, {"price": "0.99", "size": "74.66"}], "event_type": "book", "last_trade_price": "0.010"}, {"market": "0xea644975be7b2ad32b536a94ae21b707ecb2f84290225b24e60ca46dd77903dd", "asset_id": "19255594762111702415265750364124818677094538461124581923455280001407159960455", "timestamp": "1769383775780", "hash": "5ac46b7eff9df0d3b6eb6865e1c20f8c34067d5d", "bids": [{"price": "0.001", "size": "203624.7"}, {"price": "0.002", "size": "1256.18"}, {"price": "0.003", "size": "51400"}, {"price": "0.004", "size": "10.68"}, {"price": "0.006", "size": "200"}, {"price": "0.01", "size": "41"}, {"price": "0.011", "size": "10.69"}, {"price": "0.03", "size": "300"}, {"price": "0.031", "size": "8.88"}, {"price": "0.043", "size": "2000"}, {"price": "0.05", "size": "10"}, {"price": "0.051", "size": "9.8"}, {"price": "0.1", "size": "360"}, {"price": "0.15", "size": "226.66"}, {"price": "0.154", "size": "500"}, {"price": "0.2", "size": "160"}, {"price": "0.201", "size": "5.2"}, {"price": "0.223", "size": "134"}, {"price": "0.25", "size": "112"}, {"price": "0.3", "size": "86.66"}, {"price": "0.301", "size": "6"}, {"price": "0.35", "size": "68.57"}, {"price": "0.4", "size": "50"}, {"price": "0.523", "size": "226"}, {"price": "0.723", "size": "83"}, {"price": "0.823", "size": "280"}, {"price": "0.923", "size": "765"}, {"price": "0.924", "size": "20"}, {"price": "0.974", "size": "499.98"}, {"price": "0.98", "size": "198.02"}, {"price": "0.986", "size": "3261.97"}, {"price": "0.987", "size": "163"}, {"price": "0.988", "size": "12"}], "asks": [{"price": "0.999", "size": "4979.22"}, {"price": "0.998", "size": "262.59"}, {"price": "0.997", "size": "54.9"}, {"price": "0.996", "size": "21.72"}, {"price": "0.99", "size": "32.65"}], "event_type": "book", "last_trade_price": "0.010"}]}
{"_local_timestamp": "2026-01-25T23:33:17.159606+00:00", "data": {"market": "0x9d24d9f9b5995949cb158d943793dea20bd448e1b3971cb6f7418bb15e719661", "price_changes": [{"asset_id": "70512916946285526357165287373537570327431985324385225788636160168740471920430", "price": "0.013", "size": "33.91", "side": "SELL", "hash": "698caf36e5422579dd0cadbff81f553b01d2b32c", "best_bid": "0.002", "best_ask": "0.013"}, {"asset_id": "79516121807256184736227920754945730465880754940725759201193439378549308939672", "price": "0.987", "size": "33.91", "side": "BUY", "hash": "80d1fbd98464e576d58b6fc67ccb4586e04661f8", "best_bid": "0.987", "best_ask": "0.998"}], "timestamp": "1769383997087", "event_type": "price_change"}}
{"_local_timestamp": "2026-01-25T23:33:17.186248+00:00", "data": {"market": "0x9d24d9f9b5995949cb158d943793dea20bd448e1b3971cb6f7418bb15e719661", "price_changes": [{"asset_id": "70512916946285526357165287373537570327431985324385225788636160168740471920430", "price": "0.013", "size": "73.91", "side": "SELL", "hash": "17773730544ff668cbf9fcf4914b3b80273daea9", "best_bid": "0.002", "best_ask": "0.013"}, {"asset_id": "79516121807256184736227920754945730465880754940725759201193439378549308939672", "price": "0.987", "size": "73.91", "side": "BUY", "hash": "16797a9e910f175e95ba7b8ce2fc5b0de39c7215", "best_bid": "0.987", "best_ask": "0.998"}], "timestamp": "1769383997113", "event_type": "price_change"}}
{"_local_timestamp": "2026-01-25T23:33:18.638180+00:00", "data": {"market": "0x9d24d9f9b5995949cb158d943793dea20bd448e1b3971cb6f7418bb15e719661", "price_changes": [{"asset_id": "70512916946285526357165287373537570327431985324385225788636160168740471920430", "price": "0.013", "size": "33.91", "side": "SELL", "hash": "8456911636d290b3ed9524d7a57a10b815671cc4", "best_bid": "0.002", "best_ask": "0.013"}, {"asset_id": "79516121807256184736227920754945730465880754940725759201193439378549308939672", "price": "0.987", "size": "33.91", "side": "BUY", "hash": "6b55e56bc471c079dce8cf9b33f06fed908e3cad", "best_bid": "0.987", "best_ask": "0.998"}], "timestamp": "1769383998554", "event_type": "price_change"}}
{"_local_timestamp": "2026-01-25T23:33:18.669008+00:00", "data": {"market": "0x9d24d9f9b5995949cb158d943793dea20bd448e1b3971cb6f7418bb15e719661", "price_changes": [{"asset_id": "70512916946285526357165287373537570327431985324385225788636160168740471920430", "price": "0.013", "size": "73.91", "side": "SELL", "hash": "4fdb204c3c7c0f6cadbacc38daaaf20e4a748d12", "best_bid": "0.002", "best_ask": "0.013"}, {"asset_id": "79516121807256184736227920754945730465880754940725759201193439378549308939672", "price": "0.987", "size": "73.91", "side": "BUY", "hash": "a463033ffe8361cadfb0df8cef0722c1c062f26f", "best_bid": "0.987", "best_ask": "0.998"}], "timestamp": "1769383998597", "event_type": "price_change"}}
{"_local_timestamp": "2026-01-25T23:33:20.131340+00:00", "data": {"market": "0x9d24d9f9b5995949cb158d943793dea20bd448e1b3971cb6f7418bb15e719661", "price_changes": [{"asset_id": "70512916946285526357165287373537570327431985324385225788636160168740471920430", "price": "0.013", "size": "33.91", "side": "SELL", "hash": "92a36c265d6d6ffc39cf45365b423ba5893b95b0", "best_bid": "0.002", "best_ask": "0.013"}, {"asset_id": "79516121807256184736227920754945730465880754940725759201193439378549308939672", "price": "0.987", "size": "33.91", "side": "BUY", "hash": "9d087fc61d8824065026973fc92ae66d6fa22569", "best_bid": "0.987", "best_ask": "0.998"}], "timestamp": "1769384000061", "event_type": "price_change"}}
{"_local_timestamp": "2026-01-25T23:33:20.159912+00:00", "data": {"market": "0x9d24d9f9b5995949cb158d943793dea20bd448e1b3971cb6f7418bb15e719661", "price_changes": [{"asset_id": "70512916946285526357165287373537570327431985324385225788636160168740471920430", "price": "0.013", "size": "73.91", "side": "SELL", "hash": "417853132e23e7580a6fd09f7048a8eb9c783a70", "best_bid": "0.002", "best_ask": "0.013"}, {"asset_id": "79516121807256184736227920754945730465880754940725759201193439378549308939672", "price": "0.987", "size": "73.91", "side": "BUY", "hash": "de90fa89f2eb75e58064d3c103343103376223e7", "best_bid": "0.987", "best_ask": "0.998"}], "timestamp": "1769384000086", "event_type": "price_change"}}
{"_local_timestamp": "2026-01-25T23:33:21.629299+00:00", "data": {"market": "0x9d24d9f9b5995949cb158d943793dea20bd448e1b3971cb6f7418bb15e719661", "price_changes": [{"asset_id": "70512916946285526357165287373537570327431985324385225788636160168740471920430", "price": "0.013", "size": "33.91", "side": "SELL", "hash": "90e34cb561c92b249b988a85376f2a64c1bf5972", "best_bid": "0.002", "best_ask": "0.013"}, {"asset_id": "79516121807256184736227920754945730465880754940725759201193439378549308939672", "price": "0.987", "size": "33.91", "side": "BUY", "hash": "0d433ecf0dbd576e3ce55042b315914b648adb84", "best_bid": "0.987", "best_ask": "0.998"}], "timestamp": "1769384001554", "event_type": "price_change"}}
{"_local_timestamp": "2026-01-25T23:33:21.657106+00:00", "data": {"market": "0x9d24d9f9b5995949cb158d943793dea20bd448e1b3971cb6f7418bb15e719661", "price_changes": [{"asset_id": "70512916946285526357165287373537570327431985324385225788636160168740471920430", "price": "0.013", "size": "73.91", "side": "SELL", "hash": "1295bc98869c6a289ad62f5db64bafaec1994880", "best_bid": "0.002", "best_ask": "0.013"}, {"asset_id": "79516121807256184736227920754945730465880754940725759201193439378549308939672", "price": "0.987", "size": "73.91", "side": "BUY", "hash": "3b7d1d390d8b8b4af47ff9d6e2a9c7eea6dc0dcb", "best_bid": "0.987", "best_ask": "0.998"}], "timestamp": "1769384001585", "event_type": "price_change"}}
{"_local_timestamp": "2026-01-25T23:33:23.144194+00:00", "data": {"market": "0x9d24d9f9b5995949cb158d943793dea20bd448e1b3971cb6f7418bb15e719661", "price_changes": [{"asset_id": "70512916946285526357165287373537570327431985324385225788636160168740471920430", "price": "0.013", "size": "33.91", "side": "SELL", "hash": "969d46b27f9fff8e8347225b1ea3ded36f07d6e9", "best_bid": "0.002", "best_ask": "0.013"}, {"asset_id": "79516121807256184736227920754945730465880754940725759201193439378549308939672", "price": "0.987", "size": "33.91", "side": "BUY", "hash": "a60a9b4dde7f35dc821097bb649dcd2b1da6fec7", "best_bid": "0.987", "best_ask": "0.998"}], "timestamp": "1769384003054", "event_type": "price_change"}}
{"_local_timestamp": "2026-01-25T23:33:23.150078+00:00", "data": {"market": "0x9d24d9f9b5995949cb158d943793dea20bd448e1b3971cb6f7418bb15e719661", "price_changes": [{"asset_id": "70512916946285526357165287373537570327431985324385225788636160168740471920430", "price": "0.013", "size": "73.91", "side": "SELL", "hash": "f4044265b209046cece3a3145e7508c7d0459961", "best_bid": "0.002", "best_ask": "0.013"}, {"asset_id": "79516121807256184736227920754945730465880754940725759201193439378549308939672", "price": "0.987", "size": "73.91", "side": "BUY", "hash": "30c1640c3b58fb878dbc10f371891476651ed4e8", "best_bid": "0.987", "best_ask": "0.998"}], "timestamp": "1769384003080", "event_type": "price_change"}}
{"_local_timestamp": "2026-01-25T23:33:24.635256+00:00", "data": {"market": "0x9d24d9f9b5995949cb158d943793dea20bd448e1b3971cb6f7418bb15e719661", "price_changes": [{"asset_id": "70512916946285526357165287373537570327431985324385225788636160168740471920430", "price": "0.013", "size": "33.91", "side": "SELL", "hash": "2a954864a99822b5b22d4c225e59a36cb9e637ed", "best_bid": "0.002", "best_ask": "0.013"}, {"asset_id": "79516121807256184736227920754945730465880754940725759201193439378549308939672", "price": "0.987", "size": "33.91", "side": "BUY", "hash": "1d78f1e85544d20a0af76a90a3118b49f86f8d77", "best_bid": "0.987", "best_ask": "0.998"}], "timestamp": "1769384004566", "event_type": "price_change"}}
{"_local_timestamp": "2026-01-25T23:33:24.673762+00:00", "data": {"market": "0x9d24d9f9b5995949cb158d943793dea20bd448e1b3971cb6f7418bb15e719661", "price_changes": [{"asset_id": "70512916946285526357165287373537570327431985324385225788636160168740471920430", "price": "0.013", "size": "73.91", "side": "SELL", "hash": "dd2d9ec010b83c38a3fb0a1a9fba4646f4e0297e", "best_bid": "0.002", "best_ask": "0.013"}, {"asset_id": "79516121807256184736227920754945730465880754940725759201193439378549308939672", "price": "0.987", "size": "73.91", "side": "BUY", "hash": "631bf902138060a4ee620a5ba503b0121dc5d77f", "best_bid": "0.987", "best_ask": "0.998"}], "timestamp": "1769384004599", "event_type": "price_change"}}
{"_local_timestamp": "2026-01-25T23:33:26.121523+00:00", "data": {"market": "0x9d24d9f9b5995949cb158d943793dea20bd448e1b3971cb6f7418bb15e719661", "price_changes": [{"asset_id": "70512916946285526357165287373537570327431985324385225788636160168740471920430", "price": "0.013", "size": "33.91", "side": "SELL", "hash": "607ccef1900996a2e1ab35b7e54b9f34143e423d", "best_bid": "0.002", "best_ask": "0.013"}, {"asset_id": "79516121807256184736227920754945730465880754940725759201193439378549308939672", "price": "0.987", "size": "33.91", "side": "BUY", "hash": "f517f3b3d0c5e76bf55fcc7fd00c37674ccafe38", "best_bid": "0.987", "best_ask": "0.998"}], "timestamp": "1769384006053", "event_type": "price_change"}}
{"_local_timestamp": "2026-01-25T23:33:26.156736+00:00", "data": {"market": "0x9d24d9f9b5995949cb158d943793dea20bd448e1b3971cb6f7418bb15e719661", "price_changes": [{"asset_id": "70512916946285526357165287373537570327431985324385225788636160168740471920430", "price": "0.013", "size": "73.91", "side": "SELL", "hash": "dc4f7a26b3e8cdb6d2ef685f3c55e6458ad0280b", "best_bid": "0.002", "best_ask": "0.013"}, {"asset_id": "79516121807256184736227920754945730465880754940725759201193439378549308939672", "price": "0.987", "size": "73.91", "side": "BUY", "hash": "e01ebf0fdbd12dbb1d1baac885156cf5ce1ae2ae", "best_bid": "0.987", "best_ask": "0.998"}], "timestamp": "1769384006079", "event_type": "price_change"}}
{"_local_timestamp": "2026-01-25T23:33:27.044055+00:00", "data": {"market": "0xc0e6b917320a47228fb96e3b5ae0e5c93773a5ae2662ae4e1f37807cfe47ce98", "price_changes": [{"asset_id": "58656358377246279051017109359677190749228949103591068167284263961542487110215", "price": "0.007", "size": "0", "side": "BUY", "hash": "5681e19215ad6baf8cd748ae16a69b2460d94212", "best_bid": "0.021", "best_ask": "0.034"}, {"asset_id": "81647294538046680798858716589766492074338758116170717123345952330712416337530", "price": "0.993", "size": "0", "side": "SELL", "hash": "4092968da7b3ab498bae22a43c7d05d5bda6f448", "best_bid": "0.966", "best_ask": "0.979"}], "timestamp": "1769384006919", "event_type": "price_change"}}
{"_local_timestamp": "2026-01-25T23:33:27.385730+00:00", "data": {"market": "0xc0e6b917320a47228fb96e3b5ae0e5c93773a5ae2662ae4e1f37807cfe47ce98", "price_changes": [{"asset_id": "58656358377246279051017109359677190749228949103591068167284263961542487110215", "price": "0.006", "size": "217.57", "side": "BUY", "hash": "190c653e149ec83f1b385f767f29b767a53e1983", "best_bid": "0.021", "best_ask": "0.034"}, {"asset_id": "81647294538046680798858716589766492074338758116170717123345952330712416337530", "price": "0.994", "size": "217.57", "side": "SELL", "hash": "727d818798d5320582dd65aa9914a773378aae98", "best_bid": "0.966", "best_ask": "0.979"}], "timestamp": "1769384007313", "event_type": "price_change"}}
{"_local_timestamp": "2026-01-25T23:33:27.634760+00:00", "data": {"market": "0x9d24d9f9b5995949cb158d943793dea20bd448e1b3971cb6f7418bb15e719661", "price_changes": [{"asset_id": "70512916946285526357165287373537570327431985324385225788636160168740471920430", "price": "0.013", "size": "33.91", "side": "SELL", "hash": "ba0ad426083052852ff91a5bf0510f8ac55525b5", "best_bid": "0.002", "best_ask": "0.013"}, {"asset_id": "79516121807256184736227920754945730465880754940725759201193439378549308939672", "price": "0.987", "size": "33.91", "side": "BUY", "hash": "6f2fd00d1cc21dea601d4d4fdf1dbed2e8febfbb", "best_bid": "0.987", "best_ask": "0.998"}], "timestamp": "1769384007564", "event_type": "price_change"}}
{"_local_timestamp": "2026-01-25T23:33:27.671096+00:00", "data": {"market": "0x9d24d9f9b5995949cb158d943793dea20bd448e1b3971cb6f7418bb15e719661", "price_changes": [{"asset_id": "70512916946285526357165287373537570327431985324385225788636160168740471920430", "price": "0.013", "size": "73.91", "side": "SELL", "hash": "ff646262ba5b11647ffc0c6cbede79261afde032", "best_bid": "0.002", "best_ask": "0.013"}, {"asset_id": "79516121807256184736227920754945730465880754940725759201193439378549308939672", "price": "0.987", "size": "73.91", "side": "BUY", "hash": "8f18bb613e842257d593ec9aa7758fca096d29ed", "best_bid": "0.987", "best_ask": "0.998"}], "timestamp": "1769384007594", "event_type": "price_change"}}
{"_local_timestamp": "2026-01-25T23:33:29.129100+00:00", "data": {"market": "0x9d24d9f9b5995949cb158d943793dea20bd448e1b3971cb6f7418bb15e719661", "price_changes": [{"asset_id": "70512916946285526357165287373537570327431985324385225788636160168740471920430", "price": "0.013", "size": "33.91", "side": "SELL", "hash": "7b89f51ac40a34054633905a13db32eee2a15e38", "best_bid": "0.002", "best_ask": "0.013"}, {"asset_id": "79516121807256184736227920754945730465880754940725759201193439378549308939672", "price": "0.987", "size": "33.91", "side": "BUY", "hash": "e0a488fb905634e7279913d6acbb2f8365bcb4ad", "best_bid": "0.987", "best_ask": "0.998"}], "timestamp": "1769384009055", "event_type": "price_change"}}
{"_local_timestamp": "2026-01-25T23:33:29.155886+00:00", "data": {"market": "0x9d24d9f9b5995949cb158d943793dea20bd448e1b3971cb6f7418bb15e719661", "price_changes": [{"asset_id": "70512916946285526357165287373537570327431985324385225788636160168740471920430", "price": "0.013", "size": "73.91", "side": "SELL", "hash": "0b5434d4556b7a9b00ea2f17a4681a1859730735", "best_bid": "0.002", "best_ask": "0.013"}, {"asset_id": "79516121807256184736227920754945730465880754940725759201193439378549308939672", "price": "0.987", "size": "73.91", "side": "BUY", "hash": "0e1bfb24d434a489f2fd00b340cbddc6f66e2d0a", "best_bid": "0.987", "best_ask": "0.998"}], "timestamp": "1769384009088", "event_type": "price_change"}}
{"_local_timestamp": "2026-01-25T23:33:29.491753+00:00", "data": {"market": "0xe68594f1350f5535532b24979b5b5c1948432cbfc0c363802c32a8f9ab4e6509", "price_changes": [{"asset_id": "3074032031589250926591186368301243337494992039402397918135503567058257050088", "price": "0.961", "size": "173.12", "side": "BUY", "hash": "5997c4d9607aa3ca8c3d9c20daac48a630af77e7", "best_bid": "0.992", "best_ask": "0.999"}, {"asset_id": "47459180813047899567328389455747872955901265556145057896316155826890276004242", "price": "0.039", "size": "173.12", "side": "SELL", "hash": "ebfbc252233332b59ec44d29bcf32aeb554f2cce", "best_bid": "0.001", "best_ask": "0.008"}], "timestamp": "1769384009422", "event_type": "price_change"}}
{"_local_timestamp": "2026-01-25T23:33:29.492705+00:00", "data": {"market": "0x5533fb9ab797777a243c75b1bf3882c54b1ee91f794730c090bf701598993529", "price_changes": [{"asset_id": "99478074208094578615268494931219682040135218828258512927013036335093067688695", "price": "0.96", "size": "158.33", "side": "BUY", "hash": "2e9d648cc874eb72c9680ac650fad3c45e3b894d", "best_bid": "0.991", "best_ask": "0.998"}, {"asset_id": "22532055631814907447535815649879981046415248231878961745474659705989546420934", "price": "0.04", "size": "158.33", "side": "SELL", "hash": "c15f79c36354e12e4e370aa828ede7c18656309a", "best_bid": "0.002", "best_ask": "0.009"}], "timestamp": "1769384009422", "event_type": "price_change"}}
{"_local_timestamp": "2026-01-25T23:33:30.204505+00:00", "data": {"market": "0x50e477f0b316a3d97d60486479657c63be0763834d0e2e8a30b1b86dc3c1c001", "price_changes": [{"asset_id": "60573178197991590327120832143415406583517170365625050489007297367895074266641", "price": "0.002", "size": "166.66", "side": "BUY", "hash": "7f4c192049525bf8fc15d9ac1fde2a396797e2c8", "best_bid": "0.01", "best_ask": "0.014"}, {"asset_id": "39981134260608444876865205057565852475343967395624370698967311821208058420507", "price": "0.998", "size": "166.66", "side": "SELL", "hash": "4e18c5f9c81d6e401119101c105f58798dc603ef", "best_bid": "0.986", "best_ask": "0.99"}], "timestamp": "1769384010124", "event_type": "price_change"}}
{"_local_timestamp": "2026-01-25T23:33:30.632461+00:00", "data": {"market": "0x9d24d9f9b5995949cb158d943793dea20bd448e1b3971cb6f7418bb15e719661", "price_changes": [{"asset_id": "70512916946285526357165287373537570327431985324385225788636160168740471920430", "price": "0.013", "size": "33.91", "side": "SELL", "hash": "66466efdfc61183495972af432e6f6929cbea0ac", "best_bid": "0.002", "best_ask": "0.013"}, {"asset_id": "79516121807256184736227920754945730465880754940725759201193439378549308939672", "price": "0.987", "size": "33.91", "side": "BUY", "hash": "32d8b7af0364ba9ab9bd12e5331c8b924f802077", "best_bid": "0.987", "best_ask": "0.998"}], "timestamp": "1769384010560", "event_type": "price_change"}}
{"_local_timestamp": "2026-01-25T23:33:30.662139+00:00", "data": {"market": "0x9d24d9f9b5995949cb158d943793dea20bd448e1b3971cb6f7418bb15e719661", "price_changes": [{"asset_id": "70512916946285526357165287373537570327431985324385225788636160168740471920430", "price": "0.013", "size": "73.91", "side": "SELL", "hash": "ab3b85888fcaffe72587d0db734ec475e6cef305", "best_bid": "0.002", "best_ask": "0.013"}, {"asset_id": "79516121807256184736227920754945730465880754940725759201193439378549308939672", "price": "0.987", "size": "73.91", "side": "BUY", "hash": "b08517c963a6c1c69547ab8a19310146d86bc026", "best_bid": "0.987", "best_ask": "0.998"}], "timestamp": "1769384010586", "event_type": "price_change"}}
{"_local_timestamp": "2026-01-25T23:33:32.141971+00:00", "data": {"market": "0x9d24d9f9b5995949cb158d943793dea20bd448e1b3971cb6f7418bb15e719661", "price_changes": [{"asset_id": "70512916946285526357165287373537570327431985324385225788636160168740471920430", "price": "0.013", "size": "33.91", "side": "SELL", "hash": "3f4426f73276f364dcf8a8d29adc1a6e63ac6685", "best_bid": "0.002", "best_ask": "0.013"}, {"asset_id": "79516121807256184736227920754945730465880754940725759201193439378549308939672", "price": "0.987", "size": "33.91", "side": "BUY", "hash": "2f82a3b5aec0313e4aa627dfd650528a421b940e", "best_bid": "0.987", "best_ask": "0.998"}], "timestamp": "1769384012053", "event_type": "price_change"}}
{"_local_timestamp": "2026-01-25T23:33:32.154635+00:00", "data": {"market": "0x9d24d9f9b5995949cb158d943793dea20bd448e1b3971cb6f7418bb15e719661", "price_changes": [{"asset_id": "70512916946285526357165287373537570327431985324385225788636160168740471920430", "price": "0.013", "size": "73.91", "side": "SELL", "hash": "40cd4f83b1ed36262a431e3300b61efa15eb0bac", "best_bid": "0.002", "best_ask": "0.013"}, {"asset_id": "79516121807256184736227920754945730465880754940725759201193439378549308939672", "price": "0.987", "size": "73.91", "side": "BUY", "hash": "b5f211e7992b452a9e3e5c63555bc4361402b395", "best_bid": "0.987", "best_ask": "0.998"}], "timestamp": "1769384012078", "event_type": "price_change"}}
{"_local_timestamp": "2026-01-25T23:33:33.440956+00:00", "data": {"market": "0xc0e6b917320a47228fb96e3b5ae0e5c93773a5ae2662ae4e1f37807cfe47ce98", "price_changes": [{"asset_id": "81647294538046680798858716589766492074338758116170717123345952330712416337530", "price": "0.194", "size": "0", "side": "BUY", "hash": "6a9735e7f5a4bc205dee51d12013432a13fd5a46", "best_bid": "0.966", "best_ask": "0.979"}, {"asset_id": "58656358377246279051017109359677190749228949103591068167284263961542487110215", "price": "0.806", "size": "0", "side": "SELL", "hash": "cfba951a6884822cde2867bf817933e7419fc35e", "best_bid": "0.021", "best_ask": "0.034"}], "timestamp": "1769384013237", "event_type": "price_change"}}
{"_local_timestamp": "2026-01-25T23:33:33.697446+00:00", "data": {"market": "0x9d24d9f9b5995949cb158d943793dea20bd448e1b3971cb6f7418bb15e719661", "price_changes": [{"asset_id": "70512916946285526357165287373537570327431985324385225788636160168740471920430", "price": "0.013", "size": "33.91", "side": "SELL", "hash": "932ddebb805683219720d3b8868be9b5114be5e5", "best_bid": "0.002", "best_ask": "0.013"}, {"asset_id": "79516121807256184736227920754945730465880754940725759201193439378549308939672", "price": "0.987", "size": "33.91", "side": "BUY", "hash": "28bef5d363a46a38d6ec7f9857523cfb67f480ac", "best_bid": "0.987", "best_ask": "0.998"}], "timestamp": "1769384013561", "event_type": "price_change"}}
{"_local_timestamp": "2026-01-25T23:33:33.734038+00:00", "data": {"market": "0x9d24d9f9b5995949cb158d943793dea20bd448e1b3971cb6f7418bb15e719661", "price_changes": [{"asset_id": "70512916946285526357165287373537570327431985324385225788636160168740471920430", "price": "0.013", "size": "73.91", "side": "SELL", "hash": "9885f719b47b5f37fae666753fa2bf0102406a82", "best_bid": "0.002", "best_ask": "0.013"}, {"asset_id": "79516121807256184736227920754945730465880754940725759201193439378549308939672", "price": "0.987", "size": "73.91", "side": "BUY", "hash": "5ce46b302b794ec43ade865d4cad94dc010e988d", "best_bid": "0.987", "best_ask": "0.998"}], "timestamp": "1769384013595", "event_type": "price_change"}}
{"_local_timestamp": "2026-01-25T23:33:33.743603+00:00", "data": {"market": "0xc0e6b917320a47228fb96e3b5ae0e5c93773a5ae2662ae4e1f37807cfe47ce98", "price_changes": [{"asset_id": "81647294538046680798858716589766492074338758116170717123345952330712416337530", "price": "0.011", "size": "5.35", "side": "BUY", "hash": "34b830aad10570da8431d185733419c5808a223d", "best_bid": "0.966", "best_ask": "0.979"}, {"asset_id": "58656358377246279051017109359677190749228949103591068167284263961542487110215", "price": "0.989", "size": "5.35", "side": "SELL", "hash": "2f2b2ab686a648ba807c57b999d72b2cbc30860a", "best_bid": "0.021", "best_ask": "0.034"}], "timestamp": "1769384013658", "event_type": "price_change"}}
{"_local_timestamp": "2026-01-25T23:33:33.745222+00:00", "data": {"market": "0xc0e6b917320a47228fb96e3b5ae0e5c93773a5ae2662ae4e1f37807cfe47ce98", "price_changes": [{"asset_id": "81647294538046680798858716589766492074338758116170717123345952330712416337530", "price": "0.002", "size": "11257.47", "side": "BUY", "hash": "de9777b941591f09053fbfcd190ef9ec5fb036ff", "best_bid": "0.966", "best_ask": "0.979"}, {"asset_id": "58656358377246279051017109359677190749228949103591068167284263961542487110215", "price": "0.998", "size": "11257.47", "side": "SELL", "hash": "d933f4fd70f359c715401408dbbc8bd3e9561da4", "best_bid": "0.021", "best_ask": "0.034"}], "timestamp": "1769384013660", "event_type": "price_change"}}
{"_local_timestamp": "2026-01-25T23:33:33.772378+00:00", "data": {"market": "0xc0e6b917320a47228fb96e3b5ae0e5c93773a5ae2662ae4e1f37807cfe47ce98", "price_changes": [{"asset_id": "81647294538046680798858716589766492074338758116170717123345952330712416337530", "price": "0.194", "size": "5", "side": "BUY", "hash": "7b5c363b201d18934167f77a659cfb02ca6edf15", "best_bid": "0.966", "best_ask": "0.979"}, {"asset_id": "58656358377246279051017109359677190749228949103591068167284263961542487110215", "price": "0.806", "size": "5", "side": "SELL", "hash": "0da4d19c7db441d0f916a09b0c4de75369771b0d", "best_bid": "0.021", "best_ask": "0.034"}], "timestamp": "1769384013694", "event_type": "price_change"}}
{"_local_timestamp": "2026-01-25T23:33:33.773257+00:00", "data": {"market": "0xc0e6b917320a47228fb96e3b5ae0e5c93773a5ae2662ae4e1f37807cfe47ce98", "price_changes": [{"asset_id": "81647294538046680798858716589766492074338758116170717123345952330712416337530", "price": "0.051", "size": "5.08", "side": "BUY", "hash": "57ed3b9ef5e4892a3bbaed1b0ed681752f892d2f", "best_bid": "0.966", "best_ask": "0.979"}, {"asset_id": "58656358377246279051017109359677190749228949103591068167284263961542487110215", "price": "0.949", "size": "5.08", "side": "SELL", "hash": "bc0e963152fa564e23a15423fed7031fdb3379e0", "best_bid": "0.021", "best_ask": "0.034"}], "timestamp": "1769384013695", "event_type": "price_change"}}
{"_local_timestamp": "2026-01-25T23:33:35.133250+00:00", "data": {"market": "0x9d24d9f9b5995949cb158d943793dea20bd448e1b3971cb6f7418bb15e719661", "price_changes": [{"asset_id": "70512916946285526357165287373537570327431985324385225788636160168740471920430", "price": "0.013", "size": "33.91", "side": "SELL", "hash": "90d5444df83c75abed4761935644cfb5964567b5", "best_bid": "0.002", "best_ask": "0.013"}, {"asset_id": "79516121807256184736227920754945730465880754940725759201193439378549308939672", "price": "0.987", "size": "33.91", "side": "BUY", "hash": "3a82e117f763e5ee97e0575f3b4d9dc6d46d8c25", "best_bid": "0.987", "best_ask": "0.998"}], "timestamp": "1769384015054", "event_type": "price_change"}}
{"_local_timestamp": "2026-01-25T23:33:35.166293+00:00", "data": {"market": "0x9d24d9f9b5995949cb158d943793dea20bd448e1b3971cb6f7418bb15e719661", "price_changes": [{"asset_id": "70512916946285526357165287373537570327431985324385225788636160168740471920430", "price": "0.013", "size": "73.91", "side": "SELL", "hash": "5f19df963242d5f349b362437945c901e5accda5", "best_bid": "0.002", "best_ask": "0.013"}, {"asset_id": "79516121807256184736227920754945730465880754940725759201193439378549308939672", "price": "0.987", "size": "73.91", "side": "BUY", "hash": "9e3b9a3929f66c01231252d8c0407900ae7758fb", "best_bid": "0.987", "best_ask": "0.998"}], "timestamp": "1769384015083", "event_type": "price_change"}}
{"_local_timestamp": "2026-01-25T23:33:36.640571+00:00", "data": {"market": "0x9d24d9f9b5995949cb158d943793dea20bd448e1b3971cb6f7418bb15e719661", "price_changes": [{"asset_id": "70512916946285526357165287373537570327431985324385225788636160168740471920430", "price": "0.013", "size": "33.91", "side": "SELL", "hash": "162b2fe5a46c4c094b4346532332079b83b75117", "best_bid": "0.002", "best_ask": "0.013"}, {"asset_id": "79516121807256184736227920754945730465880754940725759201193439378549308939672", "price": "0.987", "size": "33.91", "side": "BUY", "hash": "28a5675f6af17072f263a2f356a5faa9bcf66215", "best_bid": "0.987", "best_ask": "0.998"}], "timestamp": "1769384016555", "event_type": "price_change"}}
{"_local_timestamp": "2026-01-25T23:33:36.659992+00:00", "data": {"market": "0x9d24d9f9b5995949cb158d943793dea20bd448e1b3971cb6f7418bb15e719661", "price_changes": [{"asset_id": "70512916946285526357165287373537570327431985324385225788636160168740471920430", "price": "0.013", "size": "73.91", "side": "SELL", "hash": "b3bb7b1b78ca1decb5dc75425a76ba527465fcc2", "best_bid": "0.002", "best_ask": "0.013"}, {"asset_id": "79516121807256184736227920754945730465880754940725759201193439378549308939672", "price": "0.987", "size": "73.91", "side": "BUY", "hash": "afbbb855321b2cd91036de08e3e9657e569f77d6", "best_bid": "0.987", "best_ask": "0.998"}], "timestamp": "1769384016581", "event_type": "price_change"}}
{"_local_timestamp": "2026-01-25T23:33:38.130344+00:00", "data": {"market": "0x9d24d9f9b5995949cb158d943793dea20bd448e1b3971cb6f7418bb15e719661", "price_changes": [{"asset_id": "70512916946285526357165287373537570327431985324385225788636160168740471920430", "price": "0.013", "size": "33.91", "side": "SELL", "hash": "78688dffd5db766e5594e26444bb13f26e7dfd56", "best_bid": "0.002", "best_ask": "0.013"}, {"asset_id": "79516121807256184736227920754945730465880754940725759201193439378549308939672", "price": "0.987", "size": "33.91", "side": "BUY", "hash": "205355585db8b8e83bb6de73dd72b787cfa4ec4c", "best_bid": "0.987", "best_ask": "0.998"}], "timestamp": "1769384018054", "event_type": "price_change"}}
{"_local_timestamp": "2026-01-25T23:33:38.155723+00:00", "data": {"market": "0x9d24d9f9b5995949cb158d943793dea20bd448e1b3971cb6f7418bb15e719661", "price_changes": [{"asset_id": "70512916946285526357165287373537570327431985324385225788636160168740471920430", "price": "0.013", "size": "73.91", "side": "SELL", "hash": "6fff5fdc23f796240a90615678815ed0266f792d", "best_bid": "0.002", "best_ask": "0.013"}, {"asset_id": "79516121807256184736227920754945730465880754940725759201193439378549308939672", "price": "0.987", "size": "73.91", "side": "BUY", "hash": "fcea04855b82859fe82ec4f7f78ad1565ba24f3b", "best_bid": "0.987", "best_ask": "0.998"}], "timestamp": "1769384018079", "event_type": "price_change"}}
{"_local_timestamp": "2026-01-25T23:33:39.634170+00:00", "data": {"market": "0x9d24d9f9b5995949cb158d943793dea20bd448e1b3971cb6f7418bb15e719661", "price_changes": [{"asset_id": "70512916946285526357165287373537570327431985324385225788636160168740471920430", "price": "0.013", "size": "33.91", "side": "SELL", "hash": "f13a588eca7c86fa4ba3b6425c270b69a1845f49", "best_bid": "0.002", "best_ask": "0.013"}, {"asset_id": "79516121807256184736227920754945730465880754940725759201193439378549308939672", "price": "0.987", "size": "33.91", "side": "BUY", "hash": "ad528eb6112f38565e6750c435f39533cf553a9a", "best_bid": "0.987", "best_ask": "0.998"}], "timestamp": "1769384019555", "event_type": "price_change"}}
{"_local_timestamp": "2026-01-25T23:33:39.653015+00:00", "data": {"market": "0x9d24d9f9b5995949cb158d943793dea20bd448e1b3971cb6f7418bb15e719661", "price_changes": [{"asset_id": "70512916946285526357165287373537570327431985324385225788636160168740471920430", "price": "0.013", "size": "73.91", "side": "SELL", "hash": "99d8d565611f522b3ceabf203473f95e9aca460f", "best_bid": "0.002", "best_ask": "0.013"}, {"asset_id": "79516121807256184736227920754945730465880754940725759201193439378549308939672", "price": "0.987", "size": "73.91", "side": "BUY", "hash": "e9fad39c90d642bee33ac6ee905a8afb744f2a9b", "best_bid": "0.987", "best_ask": "0.998"}], "timestamp": "1769384019583", "event_type": "price_change"}}
{"_local_timestamp": "2026-01-25T23:33:41.133894+00:00", "data": {"market": "0x9d24d9f9b5995949cb158d943793dea20bd448e1b3971cb6f7418bb15e719661", "price_changes": [{"asset_id": "70512916946285526357165287373537570327431985324385225788636160168740471920430", "price": "0.013", "size": "33.91", "side": "SELL", "hash": "ad7914fa293384afbf4c7660b487a4378bca5e51", "best_bid": "0.002", "best_ask": "0.013"}, {"asset_id": "79516121807256184736227920754945730465880754940725759201193439378549308939672", "price": "0.987", "size": "33.91", "side": "BUY", "hash": "fc3f1e0af36a681314966cf5f98b3c8e116d40a6", "best_bid": "0.987", "best_ask": "0.998"}], "timestamp": "1769384021059", "event_type": "price_change"}}
{"_local_timestamp": "2026-01-25T23:33:41.162247+00:00", "data": {"market": "0x9d24d9f9b5995949cb158d943793dea20bd448e1b3971cb6f7418bb15e719661", "price_changes": [{"asset_id": "70512916946285526357165287373537570327431985324385225788636160168740471920430", "price": "0.013", "size": "73.91", "side": "SELL", "hash": "4362a885f23d022ad3d2c481cbd422839acbf42f", "best_bid": "0.002", "best_ask": "0.013"}, {"asset_id": "79516121807256184736227920754945730465880754940725759201193439378549308939672", "price": "0.987", "size": "73.91", "side": "BUY", "hash": "e7de43b3935b506eb9d332d6d0dd38694b8dced9", "best_bid": "0.987", "best_ask": "0.998"}], "timestamp": "1769384021085", "event_type": "price_change"}}
{"_local_timestamp": "2026-01-25T23:33:42.623842+00:00", "data": {"market": "0x9d24d9f9b5995949cb158d943793dea20bd448e1b3971cb6f7418bb15e719661", "price_changes": [{"asset_id": "70512916946285526357165287373537570327431985324385225788636160168740471920430", "price": "0.013", "size": "33.91", "side": "SELL", "hash": "ec85e8b11ce90195b20f40781cc7450ff53aceb6", "best_bid": "0.002", "best_ask": "0.013"}, {"asset_id": "79516121807256184736227920754945730465880754940725759201193439378549308939672", "price": "0.987", "size": "33.91", "side": "BUY", "hash": "dc75b67e5740d61bcf141e7a64e2940230f5a204", "best_bid": "0.987", "best_ask": "0.998"}], "timestamp": "1769384022553", "event_type": "price_change"}}
{"_local_timestamp": "2026-01-25T23:33:42.649948+00:00", "data": {"market": "0x9d24d9f9b5995949cb158d943793dea20bd448e1b3971cb6f7418bb15e719661", "price_changes": [{"asset_id": "70512916946285526357165287373537570327431985324385225788636160168740471920430", "price": "0.013", "size": "73.91", "side": "SELL", "hash": "e8f1858320c327b2a104ae182079e73be655156f", "best_bid": "0.002", "best_ask": "0.013"}, {"asset_id": "79516121807256184736227920754945730465880754940725759201193439378549308939672", "price": "0.987", "size": "73.91", "side": "BUY", "hash": "7124e33b9c3a0a48e41d1adfa6f5796fa73a1c11", "best_bid": "0.987", "best_ask": "0.998"}], "timestamp": "1769384022579", "event_type": "price_change"}}
{"_local_timestamp": "2026-01-25T23:33:44.134759+00:00", "data": {"market": "0x9d24d9f9b5995949cb158d943793dea20bd448e1b3971cb6f7418bb15e719661", "price_changes": [{"asset_id": "70512916946285526357165287373537570327431985324385225788636160168740471920430", "price": "0.013", "size": "33.91", "side": "SELL", "hash": "24bd3506fdaff8d691a73aa1c679d6f87a1ac581", "best_bid": "0.002", "best_ask": "0.013"}, {"asset_id": "79516121807256184736227920754945730465880754940725759201193439378549308939672", "price": "0.987", "size": "33.91", "side": "BUY", "hash": "9edb2ed57af3a3c3b7acc770eae7bb39b57786d8", "best_bid": "0.987", "best_ask": "0.998"}], "timestamp": "1769384024054", "event_type": "price_change"}}
{"_local_timestamp": "2026-01-25T23:33:44.151545+00:00", "data": {"market": "0x9d24d9f9b5995949cb158d943793dea20bd448e1b3971cb6f7418bb15e719661", "price_changes": [{"asset_id": "70512916946285526357165287373537570327431985324385225788636160168740471920430", "price": "0.013", "size": "73.91", "side": "SELL", "hash": "42e7954ddb84a6d6834c10bab2f5032f5a7979a3", "best_bid": "0.002", "best_ask": "0.013"}, {"asset_id": "79516121807256184736227920754945730465880754940725759201193439378549308939672", "price": "0.987", "size": "73.91", "side": "BUY", "hash": "55ac80a28a15d7987c60cf154638ba949c926626", "best_bid": "0.987", "best_ask": "0.998"}], "timestamp": "1769384024083", "event_type": "price_change"}}
{"_local_timestamp": "2026-01-25T23:33:45.621315+00:00", "data": {"market": "0x9d24d9f9b5995949cb158d943793dea20bd448e1b3971cb6f7418bb15e719661", "price_changes": [{"asset_id": "70512916946285526357165287373537570327431985324385225788636160168740471920430", "price": "0.013", "size": "33.91", "side": "SELL", "hash": "144a17bdd9d36f73f87a4d7b1b2781e906ded0f1", "best_bid": "0.002", "best_ask": "0.013"}, {"asset_id": "79516121807256184736227920754945730465880754940725759201193439378549308939672", "price": "0.987", "size": "33.91", "side": "BUY", "hash": "07a028b94e3125153d296545018597cb434cbba3", "best_bid": "0.987", "best_ask": "0.998"}], "timestamp": "1769384025554", "event_type": "price_change"}}
{"_local_timestamp": "2026-01-25T23:33:45.649580+00:00", "data": {"market": "0x9d24d9f9b5995949cb158d943793dea20bd448e1b3971cb6f7418bb15e719661", "price_changes": [{"asset_id": "70512916946285526357165287373537570327431985324385225788636160168740471920430", "price": "0.013", "size": "73.91", "side": "SELL", "hash": "94660fe41d642c79cd1644f47863ee7b923067d4", "best_bid": "0.002", "best_ask": "0.013"}, {"asset_id": "79516121807256184736227920754945730465880754940725759201193439378549308939672", "price": "0.987", "size": "73.91", "side": "BUY", "hash": "70a7eb33e59f1e4ddf56dd41ac9e578c3b991276", "best_bid": "0.987", "best_ask": "0.998"}], "timestamp": "1769384025577", "event_type": "price_change"}}
{"_local_timestamp": "2026-01-25T23:33:47.133611+00:00", "data": {"market": "0x9d24d9f9b5995949cb158d943793dea20bd448e1b3971cb6f7418bb15e719661", "price_changes": [{"asset_id": "70512916946285526357165287373537570327431985324385225788636160168740471920430", "price": "0.013", "size": "33.91", "side": "SELL", "hash": "10f62b1e7df46d89ba19e289df6f290f98f47e01", "best_bid": "0.002", "best_ask": "0.013"}, {"asset_id": "79516121807256184736227920754945730465880754940725759201193439378549308939672", "price": "0.987", "size": "33.91", "side": "BUY", "hash": "3a289c4e92f46843bd04a520071ed2ec1e2852e4", "best_bid": "0.987", "best_ask": "0.998"}], "timestamp": "1769384027055", "event_type": "price_change"}}
{"_local_timestamp": "2026-01-25T23:33:47.151507+00:00", "data": {"market": "0x9d24d9f9b5995949cb158d943793dea20bd448e1b3971cb6f7418bb15e719661", "price_changes": [{"asset_id": "70512916946285526357165287373537570327431985324385225788636160168740471920430", "price": "0.013", "size": "73.91", "side": "SELL", "hash": "aba3a1291f9db8e1dc16893f63786d3eb903466a", "best_bid": "0.002", "best_ask": "0.013"}, {"asset_id": "79516121807256184736227920754945730465880754940725759201193439378549308939672", "price": "0.987", "size": "73.91", "side": "BUY", "hash": "8d4b9bdae3038f3a09084c96e98290cc8200bce7", "best_bid": "0.987", "best_ask": "0.998"}], "timestamp": "1769384027083", "event_type": "price_change"}}
{"_local_timestamp": "2026-01-25T23:33:48.628968+00:00", "data": {"market": "0x9d24d9f9b5995949cb158d943793dea20bd448e1b3971cb6f7418bb15e719661", "price_changes": [{"asset_id": "70512916946285526357165287373537570327431985324385225788636160168740471920430", "price": "0.013", "size": "33.91", "side": "SELL", "hash": "3835506d8818408b87d85226b39470544e84a9e9", "best_bid": "0.002", "best_ask": "0.013"}, {"asset_id": "79516121807256184736227920754945730465880754940725759201193439378549308939672", "price": "0.987", "size": "33.91", "side": "BUY", "hash": "9eef20d05fcda09f3d3b7c3c5c0585d670297cc6", "best_bid": "0.987", "best_ask": "0.998"}], "timestamp": "1769384028555", "event_type": "price_change"}}
{"_local_timestamp": "2026-01-25T23:33:48.659993+00:00", "data": {"market": "0x9d24d9f9b5995949cb158d943793dea20bd448e1b3971cb6f7418bb15e719661", "price_changes": [{"asset_id": "70512916946285526357165287373537570327431985324385225788636160168740471920430", "price": "0.013", "size": "73.91", "side": "SELL", "hash": "d23e6fd323cc1b22a7c7411ce54dad8e2fed65a1", "best_bid": "0.002", "best_ask": "0.013"}, {"asset_id": "79516121807256184736227920754945730465880754940725759201193439378549308939672", "price": "0.987", "size": "73.91", "side": "BUY", "hash": "de89ff4fb61fe6e8dbfcd196ccc19a77232419a1", "best_bid": "0.987", "best_ask": "0.998"}], "timestamp": "1769384028590", "event_type": "price_change"}}
{"_local_timestamp": "2026-01-25T23:33:50.130250+00:00", "data": {"market": "0x9d24d9f9b5995949cb158d943793dea20bd448e1b3971cb6f7418bb15e719661", "price_changes": [{"asset_id": "70512916946285526357165287373537570327431985324385225788636160168740471920430", "price": "0.013", "size": "33.91", "side": "SELL", "hash": "eb3af2959396a648934bcfe10b842d14ceadc617", "best_bid": "0.002", "best_ask": "0.013"}, {"asset_id": "79516121807256184736227920754945730465880754940725759201193439378549308939672", "price": "0.987", "size": "33.91", "side": "BUY", "hash": "fac577f640999aabbc9cbfb76f3f0d46eac37fd8", "best_bid": "0.987", "best_ask": "0.998"}], "timestamp": "1769384030054", "event_type": "price_change"}}
{"_local_timestamp": "2026-01-25T23:33:50.150415+00:00", "data": {"market": "0x9d24d9f9b5995949cb158d943793dea20bd448e1b3971cb6f7418bb15e719661", "price_changes": [{"asset_id": "70512916946285526357165287373537570327431985324385225788636160168740471920430", "price": "0.013", "size": "73.91", "side": "SELL", "hash": "ed84a426df5f411d07ae988155880b55d5ed6ca5", "best_bid": "0.002", "best_ask": "0.013"}, {"asset_id": "79516121807256184736227920754945730465880754940725759201193439378549308939672", "price": "0.987", "size": "73.91", "side": "BUY", "hash": "2d09fc8e85f313d4f3b4b2d136c30e75d55db39f", "best_bid": "0.987", "best_ask": "0.998"}], "timestamp": "1769384030081", "event_type": "price_change"}}
{"_local_timestamp": "2026-01-25T23:33:51.638992+00:00", "data": {"market": "0x9d24d9f9b5995949cb158d943793dea20bd448e1b3971cb6f7418bb15e719661", "price_changes": [{"asset_id": "70512916946285526357165287373537570327431985324385225788636160168740471920430", "price": "0.013", "size": "33.91", "side": "SELL", "hash": "6eaee298828636e6bb7132ea91253b688a45b781", "best_bid": "0.002", "best_ask": "0.013"}, {"asset_id": "79516121807256184736227920754945730465880754940725759201193439378549308939672", "price": "0.987", "size": "33.91", "side": "BUY", "hash": "e3077bc13d7b9eb50aa4371ddaba01f32f05b17b", "best_bid": "0.987", "best_ask": "0.998"}], "timestamp": "1769384031555", "event_type": "price_change"}}
{"_local_timestamp": "2026-01-25T23:33:51.676293+00:00", "data": {"market": "0x9d24d9f9b5995949cb158d943793dea20bd448e1b3971cb6f7418bb15e719661", "price_changes": [{"asset_id": "70512916946285526357165287373537570327431985324385225788636160168740471920430", "price": "0.013", "size": "73.91", "side": "SELL", "hash": "75a358d22953097f4bd20c4f0b92e06ef8197188", "best_bid": "0.002", "best_ask": "0.013"}, {"asset_id": "79516121807256184736227920754945730465880754940725759201193439378549308939672", "price": "0.987", "size": "73.91", "side": "BUY", "hash": "c2fdcf6149e5473b10fdf79d85835295989d852e", "best_bid": "0.987", "best_ask": "0.998"}], "timestamp": "1769384031582", "event_type": "price_change"}}
{"_local_timestamp": "2026-01-25T23:33:53.118486+00:00", "data": {"market": "0xc0e6b917320a47228fb96e3b5ae0e5c93773a5ae2662ae4e1f37807cfe47ce98", "price_changes": [{"asset_id": "58656358377246279051017109359677190749228949103591068167284263961542487110215", "price": "0.006", "size": "132.58", "side": "BUY", "hash": "eae524f0e5ca262fbe21794b66bfe1b781c7f6b7", "best_bid": "0.021", "best_ask": "0.034"}, {"asset_id": "81647294538046680798858716589766492074338758116170717123345952330712416337530", "price": "0.994", "size": "132.58", "side": "SELL", "hash": "3cf035bb2dc3f1c95c5e8b7648d0192651be3362", "best_bid": "0.966", "best_ask": "0.979"}], "timestamp": "1769384033050", "event_type": "price_change"}}
{"_local_timestamp": "2026-01-25T23:33:53.123842+00:00", "data": {"market": "0x9d24d9f9b5995949cb158d943793dea20bd448e1b3971cb6f7418bb15e719661", "price_changes": [{"asset_id": "70512916946285526357165287373537570327431985324385225788636160168740471920430", "price": "0.013", "size": "33.91", "side": "SELL", "hash": "25ce29091810f796f4676cc88501333915c57f40", "best_bid": "0.002", "best_ask": "0.013"}, {"asset_id": "79516121807256184736227920754945730465880754940725759201193439378549308939672", "price": "0.987", "size": "33.91", "side": "BUY", "hash": "2dc2716d631d5c7d5c3a07e5c59ad806f656d27a", "best_bid": "0.987", "best_ask": "0.998"}], "timestamp": "1769384033055", "event_type": "price_change"}}
{"_local_timestamp": "2026-01-25T23:33:53.158449+00:00", "data": {"market": "0x9d24d9f9b5995949cb158d943793dea20bd448e1b3971cb6f7418bb15e719661", "price_changes": [{"asset_id": "70512916946285526357165287373537570327431985324385225788636160168740471920430", "price": "0.013", "size": "73.91", "side": "SELL", "hash": "c7a7dc387bc4d707e3b91d1bb9fc7851430ddc52", "best_bid": "0.002", "best_ask": "0.013"}, {"asset_id": "79516121807256184736227920754945730465880754940725759201193439378549308939672", "price": "0.987", "size": "73.91", "side": "BUY", "hash": "d5e1837e296992ceaacae82801d8028d0fca3b0c", "best_bid": "0.987", "best_ask": "0.998"}], "timestamp": "1769384033086", "event_type": "price_change"}}
{"_local_timestamp": "2026-01-25T23:33:54.217612+00:00", "data": {"market": "0xe68594f1350f5535532b24979b5b5c1948432cbfc0c363802c32a8f9ab4e6509", "price_changes": [{"asset_id": "3074032031589250926591186368301243337494992039402397918135503567058257050088", "price": "0.961", "size": "14.79", "side": "BUY", "hash": "a117117a2250d30c5f2e68dcd5cf8d406368ddda", "best_bid": "0.992", "best_ask": "0.999"}, {"asset_id": "47459180813047899567328389455747872955901265556145057896316155826890276004242", "price": "0.039", "size": "14.79", "side": "SELL", "hash": "c4bb0ec19aeae3305417aab385b4fd2a833c7144", "best_bid": "0.001", "best_ask": "0.008"}], "timestamp": "1769384034133", "event_type": "price_change"}}
{"_local_timestamp": "2026-01-25T23:33:54.222572+00:00", "data": {"market": "0x5533fb9ab797777a243c75b1bf3882c54b1ee91f794730c090bf701598993529", "price_changes": [{"asset_id": "99478074208094578615268494931219682040135218828258512927013036335093067688695", "price": "0.96", "size": "0", "side": "BUY", "hash": "e526b57b75fad9cc3c1d1f27c844b05447535697", "best_bid": "0.991", "best_ask": "0.998"}, {"asset_id": "22532055631814907447535815649879981046415248231878961745474659705989546420934", "price": "0.04", "size": "0", "side": "SELL", "hash": "0eca789c6ff4df22648ca6c7f2f7c987d9a4dd02", "best_bid": "0.002", "best_ask": "0.009"}], "timestamp": "1769384034132", "event_type": "price_change"}}
{"_local_timestamp": "2026-01-25T23:33:54.623828+00:00", "data": {"market": "0x9d24d9f9b5995949cb158d943793dea20bd448e1b3971cb6f7418bb15e719661", "price_changes": [{"asset_id": "70512916946285526357165287373537570327431985324385225788636160168740471920430", "price": "0.013", "size": "33.91", "side": "SELL", "hash": "94954eaa2ab11ca54fba93e96677d104a4189b65", "best_bid": "0.002", "best_ask": "0.013"}, {"asset_id": "79516121807256184736227920754945730465880754940725759201193439378549308939672", "price": "0.987", "size": "33.91", "side": "BUY", "hash": "3e23c723a290c1a4c87a30c91ec49e11eb595ff3", "best_bid": "0.987", "best_ask": "0.998"}], "timestamp": "1769384034553", "event_type": "price_change"}}
{"_local_timestamp": "2026-01-25T23:33:54.654151+00:00", "data": {"market": "0x9d24d9f9b5995949cb158d943793dea20bd448e1b3971cb6f7418bb15e719661", "price_changes": [{"asset_id": "70512916946285526357165287373537570327431985324385225788636160168740471920430", "price": "0.013", "size": "73.91", "side": "SELL", "hash": "8de0ac037ed2bdfe7cd8d7c04fe34f44211b5efb", "best_bid": "0.002", "best_ask": "0.013"}, {"asset_id": "79516121807256184736227920754945730465880754940725759201193439378549308939672", "price": "0.987", "size": "73.91", "side": "BUY", "hash": "4aa8662cee3345aba156f84e13e52754bf2ae1a8", "best_bid": "0.987", "best_ask": "0.998"}], "timestamp": "1769384034580", "event_type": "price_change"}}
{"_local_timestamp": "2026-01-25T23:33:56.128790+00:00", "data": {"market": "0x9d24d9f9b5995949cb158d943793dea20bd448e1b3971cb6f7418bb15e719661", "price_changes": [{"asset_id": "70512916946285526357165287373537570327431985324385225788636160168740471920430", "price": "0.013", "size": "33.91", "side": "SELL", "hash": "db15485e7ef5d56eeabce14ab5240a9b8a109f2d", "best_bid": "0.002", "best_ask": "0.013"}, {"asset_id": "79516121807256184736227920754945730465880754940725759201193439378549308939672", "price": "0.987", "size": "33.91", "side": "BUY", "hash": "77e27d00b47618b2317de5ac543a2a4b0f58c447", "best_bid": "0.987", "best_ask": "0.998"}], "timestamp": "1769384036054", "event_type": "price_change"}}
{"_local_timestamp": "2026-01-25T23:33:56.151845+00:00", "data": {"market": "0x9d24d9f9b5995949cb158d943793dea20bd448e1b3971cb6f7418bb15e719661", "price_changes": [{"asset_id": "70512916946285526357165287373537570327431985324385225788636160168740471920430", "price": "0.013", "size": "73.91", "side": "SELL", "hash": "7962fe5592d696aeddd14c69754de9d38c57c913", "best_bid": "0.002", "best_ask": "0.013"}, {"asset_id": "79516121807256184736227920754945730465880754940725759201193439378549308939672", "price": "0.987", "size": "73.91", "side": "BUY", "hash": "1b8f1de0ef0efaade02d07c62a4d5be710091560", "best_bid": "0.987", "best_ask": "0.998"}], "timestamp": "1769384036081", "event_type": "price_change"}}
{"_local_timestamp": "2026-01-25T23:33:56.380523+00:00", "data": {"market": "0xc0e6b917320a47228fb96e3b5ae0e5c93773a5ae2662ae4e1f37807cfe47ce98", "price_changes": [{"asset_id": "58656358377246279051017109359677190749228949103591068167284263961542487110215", "price": "0.006", "size": "217.57", "side": "BUY", "hash": "c70113a7e1df87fed9e863e7ff4bf2078df0b5e3", "best_bid": "0.021", "best_ask": "0.034"}, {"asset_id": "81647294538046680798858716589766492074338758116170717123345952330712416337530", "price": "0.994", "size": "217.57", "side": "SELL", "hash": "8376266b0473fbc27971ed3ceaa909b2c05a5fa4", "best_bid": "0.966", "best_ask": "0.979"}], "timestamp": "1769384036303", "event_type": "price_change"}}
{"_local_timestamp": "2026-01-25T23:33:57.627560+00:00", "data": {"market": "0x9d24d9f9b5995949cb158d943793dea20bd448e1b3971cb6f7418bb15e719661", "price_changes": [{"asset_id": "70512916946285526357165287373537570327431985324385225788636160168740471920430", "price": "0.013", "size": "33.91", "side": "SELL", "hash": "25b1e86daf23a66cedd46fca48e0248444bde1f6", "best_bid": "0.002", "best_ask": "0.013"}, {"asset_id": "79516121807256184736227920754945730465880754940725759201193439378549308939672", "price": "0.987", "size": "33.91", "side": "BUY", "hash": "3e4eab302f57a2a568de52e97ba0a4cdceec7d74", "best_bid": "0.987", "best_ask": "0.998"}], "timestamp": "1769384037555", "event_type": "price_change"}}
{"_local_timestamp": "2026-01-25T23:33:57.659539+00:00", "data": {"market": "0x9d24d9f9b5995949cb158d943793dea20bd448e1b3971cb6f7418bb15e719661", "price_changes": [{"asset_id": "70512916946285526357165287373537570327431985324385225788636160168740471920430", "price": "0.013", "size": "73.91", "side": "SELL", "hash": "e04101b020442500354d21159bfe1145b95f2ad1", "best_bid": "0.002", "best_ask": "0.013"}, {"asset_id": "79516121807256184736227920754945730465880754940725759201193439378549308939672", "price": "0.987", "size": "73.91", "side": "BUY", "hash": "b4314de599dec90879d7f612a50ad959b8dd0275", "best_bid": "0.987", "best_ask": "0.998"}], "timestamp": "1769384037588", "event_type": "price_change"}}
{"_local_timestamp": "2026-01-25T23:33:59.126530+00:00", "data": {"market": "0x9d24d9f9b5995949cb158d943793dea20bd448e1b3971cb6f7418bb15e719661", "price_changes": [{"asset_id": "70512916946285526357165287373537570327431985324385225788636160168740471920430", "price": "0.013", "size": "33.91", "side": "SELL", "hash": "e74a3dd821a9b7d8aafa22ad95880586977b7882", "best_bid": "0.002", "best_ask": "0.013"}, {"asset_id": "79516121807256184736227920754945730465880754940725759201193439378549308939672", "price": "0.987", "size": "33.91", "side": "BUY", "hash": "53a8d90ca8f8b60ba50ac8affb3203c24b0b339a", "best_bid": "0.987", "best_ask": "0.998"}], "timestamp": "1769384039055", "event_type": "price_change"}}
{"_local_timestamp": "2026-01-25T23:33:59.150529+00:00", "data": {"market": "0x9d24d9f9b5995949cb158d943793dea20bd448e1b3971cb6f7418bb15e719661", "price_changes": [{"asset_id": "70512916946285526357165287373537570327431985324385225788636160168740471920430", "price": "0.013", "size": "73.91", "side": "SELL", "hash": "a97a6c574b65c9f57ac39d73ea164b2f71d027aa", "best_bid": "0.002", "best_ask": "0.013"}, {"asset_id": "79516121807256184736227920754945730465880754940725759201193439378549308939672", "price": "0.987", "size": "73.91", "side": "BUY", "hash": "e6aee9ee0990fa523da7cbf44ddd18a7923236fb", "best_bid": "0.987", "best_ask": "0.998"}], "timestamp": "1769384039081", "event_type": "price_change"}}
{"_local_timestamp": "2026-01-25T23:34:00.634698+00:00", "data": {"market": "0x9d24d9f9b5995949cb158d943793dea20bd448e1b3971cb6f7418bb15e719661", "price_changes": [{"asset_id": "70512916946285526357165287373537570327431985324385225788636160168740471920430", "price": "0.013", "size": "33.91", "side": "SELL", "hash": "2542b6492c12f8c19e27f9abee86bec45d3f9841", "best_bid": "0.002", "best_ask": "0.013"}, {"asset_id": "79516121807256184736227920754945730465880754940725759201193439378549308939672", "price": "0.987", "size": "33.91", "side": "BUY", "hash": "1641c9c77fc48a4dc4e4a786df77929dcf34d13f", "best_bid": "0.987", "best_ask": "0.998"}], "timestamp": "1769384040559", "event_type": "price_change"}}
{"_local_timestamp": "2026-01-25T23:34:00.665048+00:00", "data": {"market": "0x9d24d9f9b5995949cb158d943793dea20bd448e1b3971cb6f7418bb15e719661", "price_changes": [{"asset_id": "70512916946285526357165287373537570327431985324385225788636160168740471920430", "price": "0.013", "size": "73.91", "side": "SELL", "hash": "7552efaf5641c365dea33b308d5f694e43722a82", "best_bid": "0.002", "best_ask": "0.013"}, {"asset_id": "79516121807256184736227920754945730465880754940725759201193439378549308939672", "price": "0.987", "size": "73.91", "side": "BUY", "hash": "196d557589a4056f08dcbe153aafd92a621f4602", "best_bid": "0.987", "best_ask": "0.998"}], "timestamp": "1769384040587", "event_type": "price_change"}}
{"_local_timestamp": "2026-01-25T23:34:02.145749+00:00", "data": {"market": "0x9d24d9f9b5995949cb158d943793dea20bd448e1b3971cb6f7418bb15e719661", "price_changes": [{"asset_id": "70512916946285526357165287373537570327431985324385225788636160168740471920430", "price": "0.013", "size": "33.91", "side": "SELL", "hash": "14b78e73c11fb65ab87740e3c3fee53b55788064", "best_bid": "0.002", "best_ask": "0.013"}, {"asset_id": "79516121807256184736227920754945730465880754940725759201193439378549308939672", "price": "0.987", "size": "33.91", "side": "BUY", "hash": "bcdd38fab321cf22890f0a1a080ab34b6e6612e7", "best_bid": "0.987", "best_ask": "0.998"}], "timestamp": "1769384042068", "event_type": "price_change"}}
{"_local_timestamp": "2026-01-25T23:34:02.172381+00:00", "data": {"market": "0x9d24d9f9b5995949cb158d943793dea20bd448e1b3971cb6f7418bb15e719661", "price_changes": [{"asset_id": "70512916946285526357165287373537570327431985324385225788636160168740471920430", "price": "0.013", "size": "73.91", "side": "SELL", "hash": "c9fedf1e52d48ea4d5b7980a46b9975d8aaec93b", "best_bid": "0.002", "best_ask": "0.013"}, {"asset_id": "79516121807256184736227920754945730465880754940725759201193439378549308939672", "price": "0.987", "size": "73.91", "side": "BUY", "hash": "21c31c4dc503d9590efb81eee1b74047ee8f44f1", "best_bid": "0.987", "best_ask": "0.998"}], "timestamp": "1769384042102", "event_type": "price_change"}}
{"_local_timestamp": "2026-01-25T23:34:03.259532+00:00", "data": {"market": "0xc0e6b917320a47228fb96e3b5ae0e5c93773a5ae2662ae4e1f37807cfe47ce98", "price_changes": [{"asset_id": "81647294538046680798858716589766492074338758116170717123345952330712416337530", "price": "0.194", "size": "0", "side": "BUY", "hash": "a6fc8e0ce89e662199fd702da8f3d86b581dae73", "best_bid": "0.966", "best_ask": "0.979"}, {"asset_id": "58656358377246279051017109359677190749228949103591068167284263961542487110215", "price": "0.806", "size": "0", "side": "SELL", "hash": "33520e7381a7486fd7bd5e41954e059d69e31a97", "best_bid": "0.021", "best_ask": "0.034"}], "timestamp": "1769384043180", "event_type": "price_change"}}
{"_local_timestamp": "2026-01-25T23:34:03.627235+00:00", "data": {"market": "0x9d24d9f9b5995949cb158d943793dea20bd448e1b3971cb6f7418bb15e719661", "price_changes": [{"asset_id": "70512916946285526357165287373537570327431985324385225788636160168740471920430", "price": "0.013", "size": "33.91", "side": "SELL", "hash": "b317280a346b72822a9a311f19581205f26e6bf5", "best_bid": "0.002", "best_ask": "0.013"}, {"asset_id": "79516121807256184736227920754945730465880754940725759201193439378549308939672", "price": "0.987", "size": "33.91", "side": "BUY", "hash": "f35557c73270b26ec848dbf8e564f0c752d0cc70", "best_bid": "0.987", "best_ask": "0.998"}], "timestamp": "1769384043556", "event_type": "price_change"}}
{"_local_timestamp": "2026-01-25T23:34:03.656775+00:00", "data": {"market": "0x9d24d9f9b5995949cb158d943793dea20bd448e1b3971cb6f7418bb15e719661", "price_changes": [{"asset_id": "70512916946285526357165287373537570327431985324385225788636160168740471920430", "price": "0.013", "size": "73.91", "side": "SELL", "hash": "2bd0109561babc66fd5c4e4fc7ea8edba259e880", "best_bid": "0.002", "best_ask": "0.013"}, {"asset_id": "79516121807256184736227920754945730465880754940725759201193439378549308939672", "price": "0.987", "size": "73.91", "side": "BUY", "hash": "9dd4fca99b0bd75a07a2684c1d997dc845e12c51", "best_bid": "0.987", "best_ask": "0.998"}], "timestamp": "1769384043586", "event_type": "price_change"}}
{"_local_timestamp": "2026-01-25T23:34:03.675333+00:00", "data": {"market": "0xea644975be7b2ad32b536a94ae21b707ecb2f84290225b24e60ca46dd77903dd", "price_changes": [{"asset_id": "110044455628775971785618539427229099821815416148768008176051068105157446559241", "price": "0.002", "size": "195", "side": "BUY", "hash": "96e66160a206a7ce8b1ecbe3a7a2e32f76fe3f15", "best_bid": "0.01", "best_ask": "0.012"}, {"asset_id": "19255594762111702415265750364124818677094538461124581923455280001407159960455", "price": "0.998", "size": "195", "side": "SELL", "hash": "1064ab1ebe0e4c94cb7fd75372ebf8e441678c1a", "best_bid": "0.988", "best_ask": "0.99"}], "timestamp": "1769384043604", "event_type": "price_change"}}
{"_local_timestamp": "2026-01-25T23:34:03.678701+00:00", "data": {"market": "0xea644975be7b2ad32b536a94ae21b707ecb2f84290225b24e60ca46dd77903dd", "price_changes": [{"asset_id": "110044455628775971785618539427229099821815416148768008176051068105157446559241", "price": "0.004", "size": "0", "side": "BUY", "hash": "96e66160a206a7ce8b1ecbe3a7a2e32f76fe3f15", "best_bid": "0.01", "best_ask": "0.012"}, {"asset_id": "19255594762111702415265750364124818677094538461124581923455280001407159960455", "price": "0.996", "size": "0", "side": "SELL", "hash": "1064ab1ebe0e4c94cb7fd75372ebf8e441678c1a", "best_bid": "0.988", "best_ask": "0.99"}], "timestamp": "1769384043604", "event_type": "price_change"}}
{"_local_timestamp": "2026-01-25T23:34:04.317223+00:00", "data": {"market": "0xc0e6b917320a47228fb96e3b5ae0e5c93773a5ae2662ae4e1f37807cfe47ce98", "price_changes": [{"asset_id": "81647294538046680798858716589766492074338758116170717123345952330712416337530", "price": "0.194", "size": "5", "side": "BUY", "hash": "ae42e80ba848a61ec72adbee2e5ab304075637c0", "best_bid": "0.966", "best_ask": "0.979"}, {"asset_id": "58656358377246279051017109359677190749228949103591068167284263961542487110215", "price": "0.806", "size": "5", "side": "SELL", "hash": "aec07669455e715d10ec4188806224ccd9c3bbf8", "best_bid": "0.021", "best_ask": "0.034"}], "timestamp": "1769384044248", "event_type": "price_change"}}
{"_local_timestamp": "2026-01-25T23:34:05.195756+00:00", "data": {"market": "0x9d24d9f9b5995949cb158d943793dea20bd448e1b3971cb6f7418bb15e719661", "price_changes": [{"asset_id": "70512916946285526357165287373537570327431985324385225788636160168740471920430", "price": "0.013", "size": "33.91", "side": "SELL", "hash": "84b190cd1e189a277135ab816187a18829d1fa66", "best_bid": "0.002", "best_ask": "0.013"}, {"asset_id": "79516121807256184736227920754945730465880754940725759201193439378549308939672", "price": "0.987", "size": "33.91", "side": "BUY", "hash": "6c9001ba659359e0411572079ae7a69ea5efabe2", "best_bid": "0.987", "best_ask": "0.998"}], "timestamp": "1769384045055", "event_type": "price_change"}}
{"_local_timestamp": "2026-01-25T23:34:05.223603+00:00", "data": {"market": "0x9d24d9f9b5995949cb158d943793dea20bd448e1b3971cb6f7418bb15e719661", "price_changes": [{"asset_id": "70512916946285526357165287373537570327431985324385225788636160168740471920430", "price": "0.013", "size": "73.91", "side": "SELL", "hash": "d38be020dce2c5eb862ef99d5d9b34b053819105", "best_bid": "0.002", "best_ask": "0.013"}, {"asset_id": "79516121807256184736227920754945730465880754940725759201193439378549308939672", "price": "0.987", "size": "73.91", "side": "BUY", "hash": "f2c9e3747af84a5f4675885bee62ec5d29720638", "best_bid": "0.987", "best_ask": "0.998"}], "timestamp": "1769384045088", "event_type": "price_change"}}
{"_local_timestamp": "2026-01-25T23:34:06.633001+00:00", "data": {"market": "0x9d24d9f9b5995949cb158d943793dea20bd448e1b3971cb6f7418bb15e719661", "price_changes": [{"asset_id": "70512916946285526357165287373537570327431985324385225788636160168740471920430", "price": "0.013", "size": "33.91", "side": "SELL", "hash": "0497efa2e25094d7b19c19b2ac7dec3fcd5bf7ee", "best_bid": "0.002", "best_ask": "0.013"}, {"asset_id": "79516121807256184736227920754945730465880754940725759201193439378549308939672", "price": "0.987", "size": "33.91", "side": "BUY", "hash": "1b5088d6b2d163d9fddb8eef13810e5ed5459b0d", "best_bid": "0.987", "best_ask": "0.998"}], "timestamp": "1769384046565", "event_type": "price_change"}}
{"_local_timestamp": "2026-01-25T23:34:06.657878+00:00", "data": {"market": "0x9d24d9f9b5995949cb158d943793dea20bd448e1b3971cb6f7418bb15e719661", "price_changes": [{"asset_id": "70512916946285526357165287373537570327431985324385225788636160168740471920430", "price": "0.013", "size": "73.91", "side": "SELL", "hash": "3e03dd86c1a0e1648737c0dc4022df74bea60130", "best_bid": "0.002", "best_ask": "0.013"}, {"asset_id": "79516121807256184736227920754945730465880754940725759201193439378549308939672", "price": "0.987", "size": "73.91", "side": "BUY", "hash": "d53ea8ad7963d36ccf9b4de294a06692b2a0475a", "best_bid": "0.987", "best_ask": "0.998"}], "timestamp": "1769384046591", "event_type": "price_change"}}
{"_local_timestamp": "2026-01-25T23:34:06.779713+00:00", "data": {"market": "0xea644975be7b2ad32b536a94ae21b707ecb2f84290225b24e60ca46dd77903dd", "price_changes": [{"asset_id": "110044455628775971785618539427229099821815416148768008176051068105157446559241", "price": "0.004", "size": "21.72", "side": "BUY", "hash": "19056f829cd5ef7b570216049b3e428cadcaf76c", "best_bid": "0.01", "best_ask": "0.012"}, {"asset_id": "19255594762111702415265750364124818677094538461124581923455280001407159960455", "price": "0.996", "size": "21.72", "side": "SELL", "hash": "473c18b665bbf7c1642c7daf3ff49ff5eb37e59f", "best_bid": "0.988", "best_ask": "0.99"}], "timestamp": "1769384046711", "event_type": "price_change"}}
{"_local_timestamp": "2026-01-25T23:34:06.781953+00:00", "data": {"market": "0xea644975be7b2ad32b536a94ae21b707ecb2f84290225b24e60ca46dd77903dd", "price_changes": [{"asset_id": "110044455628775971785618539427229099821815416148768008176051068105157446559241", "price": "0.002", "size": "262.59", "side": "BUY", "hash": "fb8cd58a59a349a0fc41a6b3014bce137f360330", "best_bid": "0.01", "best_ask": "0.012"}, {"asset_id": "19255594762111702415265750364124818677094538461124581923455280001407159960455", "price": "0.998", "size": "262.59", "side": "SELL", "hash": "caa6e3749dd752240bf75f5f479d3dbace8529aa", "best_bid": "0.988", "best_ask": "0.99"}], "timestamp": "1769384046712", "event_type": "price_change"}}
{"_local_timestamp": "2026-01-25T23:34:08.137791+00:00", "data": {"market": "0x9d24d9f9b5995949cb158d943793dea20bd448e1b3971cb6f7418bb15e719661", "price_changes": [{"asset_id": "70512916946285526357165287373537570327431985324385225788636160168740471920430", "price": "0.013", "size": "33.91", "side": "SELL", "hash": "6d548d70b3b0ce1c5e7b2f6bc0233cc0cb861df9", "best_bid": "0.002", "best_ask": "0.013"}, {"asset_id": "79516121807256184736227920754945730465880754940725759201193439378549308939672", "price": "0.987", "size": "33.91", "side": "BUY", "hash": "414849ed7d84d6c01042a8435971fa74a94b58d5", "best_bid": "0.987", "best_ask": "0.998"}], "timestamp": "1769384048056", "event_type": "price_change"}}
{"_local_timestamp": "2026-01-25T23:34:08.155033+00:00", "data": {"market": "0x9d24d9f9b5995949cb158d943793dea20bd448e1b3971cb6f7418bb15e719661", "price_changes": [{"asset_id": "70512916946285526357165287373537570327431985324385225788636160168740471920430", "price": "0.013", "size": "73.91", "side": "SELL", "hash": "4d43aa263e7a9e3123683442286e4b2657956a9b", "best_bid": "0.002", "best_ask": "0.013"}, {"asset_id": "79516121807256184736227920754945730465880754940725759201193439378549308939672", "price": "0.987", "size": "73.91", "side": "BUY", "hash": "d6f5c78f3cbd5b68f71704a28a9b14fba7c46855", "best_bid": "0.987", "best_ask": "0.998"}], "timestamp": "1769384048082", "event_type": "price_change"}}
{"_local_timestamp": "2026-01-25T23:34:09.019954+00:00", "data": {"market": "0x5533fb9ab797777a243c75b1bf3882c54b1ee91f794730c090bf701598993529", "price_changes": [{"asset_id": "22532055631814907447535815649879981046415248231878961745474659705989546420934", "price": "0.009", "size": "0", "side": "SELL", "hash": "3a065221629cbdb466611233ed437dc002f0fc0f", "best_bid": "0.002", "best_ask": "0.013"}, {"asset_id": "99478074208094578615268494931219682040135218828258512927013036335093067688695", "price": "0.991", "size": "0", "side": "BUY", "hash": "42a687e2b04fd195c6bb101dc36262ad8553f3cb", "best_bid": "0.987", "best_ask": "0.998"}], "timestamp": "1769384048937", "event_type": "price_change"}}
{"_local_timestamp": "2026-01-25T23:34:09.021931+00:00", "data": {"market": "0x5533fb9ab797777a243c75b1bf3882c54b1ee91f794730c090bf701598993529", "price_changes": [{"asset_id": "22532055631814907447535815649879981046415248231878961745474659705989546420934", "price": "0.01", "size": "0", "side": "SELL", "hash": "3a065221629cbdb466611233ed437dc002f0fc0f", "best_bid": "0.002", "best_ask": "0.013"}, {"asset_id": "99478074208094578615268494931219682040135218828258512927013036335093067688695", "price": "0.99", "size": "0", "side": "BUY", "hash": "42a687e2b04fd195c6bb101dc36262ad8553f3cb", "best_bid": "0.987", "best_ask": "0.998"}], "timestamp": "1769384048937", "event_type": "price_change"}}
{"_local_timestamp": "2026-01-25T23:34:09.625649+00:00", "data": {"market": "0x9d24d9f9b5995949cb158d943793dea20bd448e1b3971cb6f7418bb15e719661", "price_changes": [{"asset_id": "70512916946285526357165287373537570327431985324385225788636160168740471920430", "price": "0.013", "size": "33.91", "side": "SELL", "hash": "24fd5624174d9ac571f6a3c5b1f4bc6dac1c9908", "best_bid": "0.002", "best_ask": "0.013"}, {"asset_id": "79516121807256184736227920754945730465880754940725759201193439378549308939672", "price": "0.987", "size": "33.91", "side": "BUY", "hash": "9d37ccc0993927b149ad90882df78cb9b64658e7", "best_bid": "0.987", "best_ask": "0.998"}], "timestamp": "1769384049553", "event_type": "price_change"}}
{"_local_timestamp": "2026-01-25T23:34:09.652041+00:00", "data": {"market": "0x9d24d9f9b5995949cb158d943793dea20bd448e1b3971cb6f7418bb15e719661", "price_changes": [{"asset_id": "70512916946285526357165287373537570327431985324385225788636160168740471920430", "price": "0.013", "size": "73.91", "side": "SELL", "hash": "65f5e1e0a4a95f8447f3240a22841408cc5d99a6", "best_bid": "0.002", "best_ask": "0.013"}, {"asset_id": "79516121807256184736227920754945730465880754940725759201193439378549308939672", "price": "0.987", "size": "73.91", "side": "BUY", "hash": "5f4f5b64eaf564e2c534a9e660fdffc98e260fde", "best_bid": "0.987", "best_ask": "0.998"}], "timestamp": "1769384049582", "event_type": "price_change"}}
{"_local_timestamp": "2026-01-25T23:34:10.761837+00:00", "data": {"market": "0x5533fb9ab797777a243c75b1bf3882c54b1ee91f794730c090bf701598993529", "price_changes": [{"asset_id": "22532055631814907447535815649879981046415248231878961745474659705989546420934", "price": "0.008", "size": "67.5", "side": "SELL", "hash": "12ec7bdbfff56fd6724d6ba56c553ef608f89be0", "best_bid": "0.002", "best_ask": "0.008"}, {"asset_id": "99478074208094578615268494931219682040135218828258512927013036335093067688695", "price": "0.992", "size": "67.5", "side": "BUY", "hash": "e9c8689623787ecd35d645d3fc51b3e124da32b9", "best_bid": "0.992", "best_ask": "0.998"}], "timestamp": "1769384050692", "event_type": "price_change"}}
{"_local_timestamp": "2026-01-25T23:34:10.765511+00:00", "data": {"market": "0x5533fb9ab797777a243c75b1bf3882c54b1ee91f794730c090bf701598993529", "price_changes": [{"asset_id": "22532055631814907447535815649879981046415248231878961745474659705989546420934", "price": "0.009", "size": "12.5", "side": "SELL", "hash": "6be6f3b1012372159525f53f57b5a2b4d28ff7f5", "best_bid": "0.002", "best_ask": "0.008"}, {"asset_id": "99478074208094578615268494931219682040135218828258512927013036335093067688695", "price": "0.991", "size": "12.5", "side": "BUY", "hash": "565b0c85055acad55826ea81c2fdf5868647e99b", "best_bid": "0.992", "best_ask": "0.998"}], "timestamp": "1769384050693", "event_type": "price_change"}}
{"_local_timestamp": "2026-01-25T23:34:11.133938+00:00", "data": {"market": "0x9d24d9f9b5995949cb158d943793dea20bd448e1b3971cb6f7418bb15e719661", "price_changes": [{"asset_id": "70512916946285526357165287373537570327431985324385225788636160168740471920430", "price": "0.013", "size": "33.91", "side": "SELL", "hash": "bc5ff869f87ba0ebd1ffab3b19758d790e1efd04", "best_bid": "0.002", "best_ask": "0.013"}, {"asset_id": "79516121807256184736227920754945730465880754940725759201193439378549308939672", "price": "0.987", "size": "33.91", "side": "BUY", "hash": "15c3d77071cdf67e564ee8b55f1a36bc7f0fc67f", "best_bid": "0.987", "best_ask": "0.998"}], "timestamp": "1769384051054", "event_type": "price_change"}}
{"_local_timestamp": "2026-01-25T23:34:11.153580+00:00", "data": {"market": "0x9d24d9f9b5995949cb158d943793dea20bd448e1b3971cb6f7418bb15e719661", "price_changes": [{"asset_id": "70512916946285526357165287373537570327431985324385225788636160168740471920430", "price": "0.013", "size": "73.91", "side": "SELL", "hash": "d94c11d53314c8d1cc611c3b8ad2b573f4cbdb80", "best_bid": "0.002", "best_ask": "0.013"}, {"asset_id": "79516121807256184736227920754945730465880754940725759201193439378549308939672", "price": "0.987", "size": "73.91", "side": "BUY", "hash": "f6a64a38ed06745a07389c617e2dc91c9f9cffaa", "best_bid": "0.987", "best_ask": "0.998"}], "timestamp": "1769384051084", "event_type": "price_change"}}
{"_local_timestamp": "2026-01-25T23:34:11.443476+00:00", "data": {"market": "0x5533fb9ab797777a243c75b1bf3882c54b1ee91f794730c090bf701598993529", "price_changes": [{"asset_id": "99478074208094578615268494931219682040135218828258512927013036335093067688695", "price": "0.987", "size": "30", "side": "BUY", "hash": "0235ff4e29c260ca8d3cf5948a3b5f5edd637f34", "best_bid": "0.992", "best_ask": "0.998"}, {"asset_id": "22532055631814907447535815649879981046415248231878961745474659705989546420934", "price": "0.013", "size": "30", "side": "SELL", "hash": "4e5d8de0f2dd32dd7f1f61628f55abdb1869a249", "best_bid": "0.002", "best_ask": "0.008"}], "timestamp": "1769384051358", "event_type": "price_change"}}
{"_local_timestamp": "2026-01-25T23:34:11.497527+00:00", "data": {"market": "0x5533fb9ab797777a243c75b1bf3882c54b1ee91f794730c090bf701598993529", "price_changes": [{"asset_id": "99478074208094578615268494931219682040135218828258512927013036335093067688695", "price": "0.992", "size": "97.5", "side": "BUY", "hash": "73dd1b85fe7c98104cd14a9c3c8408f46db70e11", "best_bid": "0.992", "best_ask": "0.998"}, {"asset_id": "22532055631814907447535815649879981046415248231878961745474659705989546420934", "price": "0.008", "size": "97.5", "side": "SELL", "hash": "5297c9f4844c9a85a287ce705fed8fee2eee3afd", "best_bid": "0.002", "best_ask": "0.008"}], "timestamp": "1769384051426", "event_type": "price_change"}}
{"_local_timestamp": "2026-01-25T23:34:12.626487+00:00", "data": {"market": "0x9d24d9f9b5995949cb158d943793dea20bd448e1b3971cb6f7418bb15e719661", "price_changes": [{"asset_id": "70512916946285526357165287373537570327431985324385225788636160168740471920430", "price": "0.013", "size": "33.91", "side": "SELL", "hash": "6d7e0864d556093f99556bad248abdb5ffc8f6d4", "best_bid": "0.002", "best_ask": "0.013"}, {"asset_id": "79516121807256184736227920754945730465880754940725759201193439378549308939672", "price": "0.987", "size": "33.91", "side": "BUY", "hash": "501acf97ce14b8cf982b2ac27d6821d2ac324fba", "best_bid": "0.987", "best_ask": "0.998"}], "timestamp": "1769384052552", "event_type": "price_change"}}
{"_local_timestamp": "2026-01-25T23:34:12.652093+00:00", "data": {"market": "0x9d24d9f9b5995949cb158d943793dea20bd448e1b3971cb6f7418bb15e719661", "price_changes": [{"asset_id": "70512916946285526357165287373537570327431985324385225788636160168740471920430", "price": "0.013", "size": "73.91", "side": "SELL", "hash": "2938a7dd9148b5e332d043462d3187888029481e", "best_bid": "0.002", "best_ask": "0.013"}, {"asset_id": "79516121807256184736227920754945730465880754940725759201193439378549308939672", "price": "0.987", "size": "73.91", "side": "BUY", "hash": "3ea35f08a10b5d0c83e36a6f06e7d4231ba96569", "best_bid": "0.987", "best_ask": "0.998"}], "timestamp": "1769384052578", "event_type": "price_change"}}
{"_local_timestamp": "2026-01-25T23:34:14.126951+00:00", "data": {"market": "0x9d24d9f9b5995949cb158d943793dea20bd448e1b3971cb6f7418bb15e719661", "price_changes": [{"asset_id": "70512916946285526357165287373537570327431985324385225788636160168740471920430", "price": "0.013", "size": "33.91", "side": "SELL", "hash": "764385fb73c4bfd9231e73183b44d52882eec7f2", "best_bid": "0.002", "best_ask": "0.013"}, {"asset_id": "79516121807256184736227920754945730465880754940725759201193439378549308939672", "price": "0.987", "size": "33.91", "side": "BUY", "hash": "21703a4240d0636b8830a24555f52250326b757e", "best_bid": "0.987", "best_ask": "0.998"}], "timestamp": "1769384054055", "event_type": "price_change"}}
{"_local_timestamp": "2026-01-25T23:34:14.156408+00:00", "data": {"market": "0x9d24d9f9b5995949cb158d943793dea20bd448e1b3971cb6f7418bb15e719661", "price_changes": [{"asset_id": "70512916946285526357165287373537570327431985324385225788636160168740471920430", "price": "0.013", "size": "73.91", "side": "SELL", "hash": "7bb60a99cda304063185b932d7208121071a8b58", "best_bid": "0.002", "best_ask": "0.013"}, {"asset_id": "79516121807256184736227920754945730465880754940725759201193439378549308939672", "price": "0.987", "size": "73.91", "side": "BUY", "hash": "7e730c6ff5b3d3fd4d7c4e33983cd7207f921779", "best_bid": "0.987", "best_ask": "0.998"}], "timestamp": "1769384054081", "event_type": "price_change"}}
{"_local_timestamp": "2026-01-25T23:34:15.625548+00:00", "data": {"market": "0x9d24d9f9b5995949cb158d943793dea20bd448e1b3971cb6f7418bb15e719661", "price_changes": [{"asset_id": "70512916946285526357165287373537570327431985324385225788636160168740471920430", "price": "0.013", "size": "33.91", "side": "SELL", "hash": "da78b4636e6e41766a21a8307a924a04f9f57769", "best_bid": "0.002", "best_ask": "0.013"}, {"asset_id": "79516121807256184736227920754945730465880754940725759201193439378549308939672", "price": "0.987", "size": "33.91", "side": "BUY", "hash": "3b26c02e3b3d9854de043146ad91d1aff5da54a1", "best_bid": "0.987", "best_ask": "0.998"}], "timestamp": "1769384055554", "event_type": "price_change"}}
{"_local_timestamp": "2026-01-25T23:34:15.659191+00:00", "data": {"market": "0x9d24d9f9b5995949cb158d943793dea20bd448e1b3971cb6f7418bb15e719661", "price_changes": [{"asset_id": "70512916946285526357165287373537570327431985324385225788636160168740471920430", "price": "0.013", "size": "73.91", "side": "SELL", "hash": "64829ed0645133acdbd4f1a1f31b74030c9129b1", "best_bid": "0.002", "best_ask": "0.013"}, {"asset_id": "79516121807256184736227920754945730465880754940725759201193439378549308939672", "price": "0.987", "size": "73.91", "side": "BUY", "hash": "b5928d8b8e60738c0ba43795fcef235910031cae", "best_bid": "0.987", "best_ask": "0.998"}], "timestamp": "1769384055585", "event_type": "price_change"}}
{"_local_timestamp": "2026-01-25T23:34:17.145266+00:00", "data": {"market": "0x9d24d9f9b5995949cb158d943793dea20bd448e1b3971cb6f7418bb15e719661", "price_changes": [{"asset_id": "70512916946285526357165287373537570327431985324385225788636160168740471920430", "price": "0.013", "size": "33.91", "side": "SELL", "hash": "c3c8f16945304a943efb5fbea10c322fe6ecab52", "best_bid": "0.002", "best_ask": "0.013"}, {"asset_id": "79516121807256184736227920754945730465880754940725759201193439378549308939672", "price": "0.987", "size": "33.91", "side": "BUY", "hash": "ffbec072198d974733e7450c08f21cadebfcd1cd", "best_bid": "0.987", "best_ask": "0.998"}], "timestamp": "1769384057056", "event_type": "price_change"}}
{"_local_timestamp": "2026-01-25T23:34:17.161233+00:00", "data": {"market": "0x9d24d9f9b5995949cb158d943793dea20bd448e1b3971cb6f7418bb15e719661", "price_changes": [{"asset_id": "70512916946285526357165287373537570327431985324385225788636160168740471920430", "price": "0.013", "size": "73.91", "side": "SELL", "hash": "f639561a3383ea9662498f8608fa65167e79e912", "best_bid": "0.002", "best_ask": "0.013"}, {"asset_id": "79516121807256184736227920754945730465880754940725759201193439378549308939672", "price": "0.987", "size": "73.91", "side": "BUY", "hash": "fd1f3b142c3f188aa2592e64b827ce8b70d6d911", "best_bid": "0.987", "best_ask": "0.998"}], "timestamp": "1769384057084", "event_type": "price_change"}}
{"_local_timestamp": "2026-01-25T23:34:18.608096+00:00", "data": {"market": "0x5533fb9ab797777a243c75b1bf3882c54b1ee91f794730c090bf701598993529", "price_changes": [{"asset_id": "99478074208094578615268494931219682040135218828258512927013036335093067688695", "price": "0.987", "size": "0", "side": "BUY", "hash": "887c4d7f38c73e82d406ce7e5a1aa2978a5ccf4d", "best_bid": "0.992", "best_ask": "0.998"}, {"asset_id": "22532055631814907447535815649879981046415248231878961745474659705989546420934", "price": "0.013", "size": "0", "side": "SELL", "hash": "52b2b44c0e991f95fba026c2597924a7c82fc077", "best_bid": "0.002", "best_ask": "0.008"}], "timestamp": "1769384058537", "event_type": "price_change"}}
{"_local_timestamp": "2026-01-25T23:34:18.619695+00:00", "data": {"market": "0x9d24d9f9b5995949cb158d943793dea20bd448e1b3971cb6f7418bb15e719661", "price_changes": [{"asset_id": "70512916946285526357165287373537570327431985324385225788636160168740471920430", "price": "0.013", "size": "33.91", "side": "SELL", "hash": "ad757cd0da2da9f0598ee99b6dad4bf3110856db", "best_bid": "0.002", "best_ask": "0.013"}, {"asset_id": "79516121807256184736227920754945730465880754940725759201193439378549308939672", "price": "0.987", "size": "33.91", "side": "BUY", "hash": "3b20afe5de1c0b016bc842ccdeee5467d7089711", "best_bid": "0.987", "best_ask": "0.998"}], "timestamp": "1769384058554", "event_type": "price_change"}}
{"_local_timestamp": "2026-01-25T23:34:18.663685+00:00", "data": {"market": "0x9d24d9f9b5995949cb158d943793dea20bd448e1b3971cb6f7418bb15e719661", "price_changes": [{"asset_id": "70512916946285526357165287373537570327431985324385225788636160168740471920430", "price": "0.013", "size": "73.91", "side": "SELL", "hash": "e25ef37e1536fff420d020c43074399e92a9261d", "best_bid": "0.002", "best_ask": "0.013"}, {"asset_id": "79516121807256184736227920754945730465880754940725759201193439378549308939672", "price": "0.987", "size": "73.91", "side": "BUY", "hash": "624b565702adcbed5d8af1d25b703e299f7406f8", "best_bid": "0.987", "best_ask": "0.998"}], "timestamp": "1769384058591", "event_type": "price_change"}}
{"_local_timestamp": "2026-01-25T23:34:20.137934+00:00", "data": {"market": "0x9d24d9f9b5995949cb158d943793dea20bd448e1b3971cb6f7418bb15e719661", "price_changes": [{"asset_id": "70512916946285526357165287373537570327431985324385225788636160168740471920430", "price": "0.013", "size": "33.91", "side": "SELL", "hash": "3922a82db20f5ea6ecdd0c36869419ee46da3662", "best_bid": "0.002", "best_ask": "0.013"}, {"asset_id": "79516121807256184736227920754945730465880754940725759201193439378549308939672", "price": "0.987", "size": "33.91", "side": "BUY", "hash": "ddb74ad8db01545323770c44a34e735d435284f6", "best_bid": "0.987", "best_ask": "0.998"}], "timestamp": "1769384060055", "event_type": "price_change"}}
{"_local_timestamp": "2026-01-25T23:34:20.151643+00:00", "data": {"market": "0x9d24d9f9b5995949cb158d943793dea20bd448e1b3971cb6f7418bb15e719661", "price_changes": [{"asset_id": "70512916946285526357165287373537570327431985324385225788636160168740471920430", "price": "0.013", "size": "73.91", "side": "SELL", "hash": "2faf8746b39eb19e95deb477ef2e1a36c0274021", "best_bid": "0.002", "best_ask": "0.013"}, {"asset_id": "79516121807256184736227920754945730465880754940725759201193439378549308939672", "price": "0.987", "size": "73.91", "side": "BUY", "hash": "93e262b48296bccc928aaf6e24a0f406a78b9b86", "best_bid": "0.987", "best_ask": "0.998"}], "timestamp": "1769384060083", "event_type": "price_change"}}
{"_local_timestamp": "2026-01-25T23:34:21.639850+00:00", "data": {"market": "0x9d24d9f9b5995949cb158d943793dea20bd448e1b3971cb6f7418bb15e719661", "price_changes": [{"asset_id": "70512916946285526357165287373537570327431985324385225788636160168740471920430", "price": "0.013", "size": "33.91", "side": "SELL", "hash": "47c73e4670c743d510fbd34e952080fd995d685c", "best_bid": "0.002", "best_ask": "0.013"}, {"asset_id": "79516121807256184736227920754945730465880754940725759201193439378549308939672", "price": "0.987", "size": "33.91", "side": "BUY", "hash": "e8575695f9af3c8e2cc2d63c71d9b598f3e307f7", "best_bid": "0.987", "best_ask": "0.998"}], "timestamp": "1769384061554", "event_type": "price_change"}}
{"_local_timestamp": "2026-01-25T23:34:21.650307+00:00", "data": {"market": "0x9d24d9f9b5995949cb158d943793dea20bd448e1b3971cb6f7418bb15e719661", "price_changes": [{"asset_id": "70512916946285526357165287373537570327431985324385225788636160168740471920430", "price": "0.013", "size": "73.91", "side": "SELL", "hash": "4b78e5dd0f1a5f48926b727ed7cabc54628ba0ed", "best_bid": "0.002", "best_ask": "0.013"}, {"asset_id": "79516121807256184736227920754945730465880754940725759201193439378549308939672", "price": "0.987", "size": "73.91", "side": "BUY", "hash": "adcff6a3a2a81f39eb8fbcd6141aa558f4a2550a", "best_bid": "0.987", "best_ask": "0.998"}], "timestamp": "1769384061580", "event_type": "price_change"}}
{"_local_timestamp": "2026-01-25T23:34:23.152610+00:00", "data": {"market": "0x9d24d9f9b5995949cb158d943793dea20bd448e1b3971cb6f7418bb15e719661", "price_changes": [{"asset_id": "70512916946285526357165287373537570327431985324385225788636160168740471920430", "price": "0.013", "size": "33.91", "side": "SELL", "hash": "09e29912d07bc6ebadb82c3186b180991ea57de5", "best_bid": "0.002", "best_ask": "0.013"}, {"asset_id": "79516121807256184736227920754945730465880754940725759201193439378549308939672", "price": "0.987", "size": "33.91", "side": "BUY", "hash": "954183f8511f7923655a378adae7aaf925de9144", "best_bid": "0.987", "best_ask": "0.998"}], "timestamp": "1769384063061", "event_type": "price_change"}}
{"_local_timestamp": "2026-01-25T23:34:23.161907+00:00", "data": {"market": "0x9d24d9f9b5995949cb158d943793dea20bd448e1b3971cb6f7418bb15e719661", "price_changes": [{"asset_id": "70512916946285526357165287373537570327431985324385225788636160168740471920430", "price": "0.013", "size": "73.91", "side": "SELL", "hash": "0d8d7867404573ef5a02e634a96ce11483f99045", "best_bid": "0.002", "best_ask": "0.013"}, {"asset_id": "79516121807256184736227920754945730465880754940725759201193439378549308939672", "price": "0.987", "size": "73.91", "side": "BUY", "hash": "664b35472b22ad2945f478e5890a80801955ee3e", "best_bid": "0.987", "best_ask": "0.998"}], "timestamp": "1769384063090", "event_type": "price_change"}}
{"_local_timestamp": "2026-01-25T23:34:24.629013+00:00", "data": {"market": "0x9d24d9f9b5995949cb158d943793dea20bd448e1b3971cb6f7418bb15e719661", "price_changes": [{"asset_id": "70512916946285526357165287373537570327431985324385225788636160168740471920430", "price": "0.013", "size": "33.91", "side": "SELL", "hash": "e7ea31550e5e3d12dd3cc1bc4bfaf08b11ef3175", "best_bid": "0.002", "best_ask": "0.013"}, {"asset_id": "79516121807256184736227920754945730465880754940725759201193439378549308939672", "price": "0.987", "size": "33.91", "side": "BUY", "hash": "11781b4404169c7581f0fa4ce597da1761502c40", "best_bid": "0.987", "best_ask": "0.998"}], "timestamp": "1769384064559", "event_type": "price_change"}}
{"_local_timestamp": "2026-01-25T23:34:24.656371+00:00", "data": {"market": "0x9d24d9f9b5995949cb158d943793dea20bd448e1b3971cb6f7418bb15e719661", "price_changes": [{"asset_id": "70512916946285526357165287373537570327431985324385225788636160168740471920430", "price": "0.013", "size": "73.91", "side": "SELL", "hash": "c2dbd4da82c6a0fcabeaa19b83bd766fdd905ba0", "best_bid": "0.002", "best_ask": "0.013"}, {"asset_id": "79516121807256184736227920754945730465880754940725759201193439378549308939672", "price": "0.987", "size": "73.91", "side": "BUY", "hash": "9a8bc6529a8a4500ba84031cbfa8f4396672cad2", "best_bid": "0.987", "best_ask": "0.998"}], "timestamp": "1769384064589", "event_type": "price_change"}}
{"_local_timestamp": "2026-01-25T23:34:26.130699+00:00", "data": {"market": "0x9d24d9f9b5995949cb158d943793dea20bd448e1b3971cb6f7418bb15e719661", "price_changes": [{"asset_id": "70512916946285526357165287373537570327431985324385225788636160168740471920430", "price": "0.013", "size": "33.91", "side": "SELL", "hash": "f29c12c2752902f45aca30fdc1f0a0a018945eea", "best_bid": "0.002", "best_ask": "0.013"}, {"asset_id": "79516121807256184736227920754945730465880754940725759201193439378549308939672", "price": "0.987", "size": "33.91", "side": "BUY", "hash": "dd91264484265e84b66f09776d02a591e454f66e", "best_bid": "0.987", "best_ask": "0.998"}], "timestamp": "1769384066053", "event_type": "price_change"}}
{"_local_timestamp": "2026-01-25T23:34:26.157314+00:00", "data": {"market": "0x9d24d9f9b5995949cb158d943793dea20bd448e1b3971cb6f7418bb15e719661", "price_changes": [{"asset_id": "70512916946285526357165287373537570327431985324385225788636160168740471920430", "price": "0.013", "size": "73.91", "side": "SELL", "hash": "b73e3fc147eb7a166941c7272239a0c1cd6cebc8", "best_bid": "0.002", "best_ask": "0.013"}, {"asset_id": "79516121807256184736227920754945730465880754940725759201193439378549308939672", "price": "0.987", "size": "73.91", "side": "BUY", "hash": "3f7c0b2c46165b9af07179bfb8ba0d99adb69365", "best_bid": "0.987", "best_ask": "0.998"}], "timestamp": "1769384066082", "event_type": "price_change"}}
{"_local_timestamp": "2026-01-25T23:34:27.621386+00:00", "data": {"market": "0x9d24d9f9b5995949cb158d943793dea20bd448e1b3971cb6f7418bb15e719661", "price_changes": [{"asset_id": "70512916946285526357165287373537570327431985324385225788636160168740471920430", "price": "0.013", "size": "33.91", "side": "SELL", "hash": "d7bd9ae118192b398bc03372dfe9a2e92aac5d69", "best_bid": "0.002", "best_ask": "0.013"}, {"asset_id": "79516121807256184736227920754945730465880754940725759201193439378549308939672", "price": "0.987", "size": "33.91", "side": "BUY", "hash": "3b24bf2506f6e48c34f52952c312b62e8e41234b", "best_bid": "0.987", "best_ask": "0.998"}], "timestamp": "1769384067553", "event_type": "price_change"}}
{"_local_timestamp": "2026-01-25T23:34:27.861158+00:00", "data": {"market": "0x9d24d9f9b5995949cb158d943793dea20bd448e1b3971cb6f7418bb15e719661", "price_changes": [{"asset_id": "70512916946285526357165287373537570327431985324385225788636160168740471920430", "price": "0.013", "size": "73.91", "side": "SELL", "hash": "8cf9128fe7a80e5cc3319046f16298b2b2508f47", "best_bid": "0.002", "best_ask": "0.013"}, {"asset_id": "79516121807256184736227920754945730465880754940725759201193439378549308939672", "price": "0.987", "size": "73.91", "side": "BUY", "hash": "a77fa883142069eb68190b80ae49a7dc5d514919", "best_bid": "0.987", "best_ask": "0.998"}], "timestamp": "1769384067611", "event_type": "price_change"}}
{"_local_timestamp": "2026-01-25T23:34:29.192279+00:00", "data": {"market": "0x9d24d9f9b5995949cb158d943793dea20bd448e1b3971cb6f7418bb15e719661", "price_changes": [{"asset_id": "70512916946285526357165287373537570327431985324385225788636160168740471920430", "price": "0.013", "size": "33.91", "side": "SELL", "hash": "d658021f09824cd3aa23a3d403d6682e4275b72b", "best_bid": "0.002", "best_ask": "0.013"}, {"asset_id": "79516121807256184736227920754945730465880754940725759201193439378549308939672", "price": "0.987", "size": "33.91", "side": "BUY", "hash": "1bf30310fe7a5d7c79aef06e3a71cfc63fe238e0", "best_bid": "0.987", "best_ask": "0.998"}], "timestamp": "1769384069059", "event_type": "price_change"}}
{"_local_timestamp": "2026-01-25T23:34:29.201862+00:00", "data": {"market": "0x9d24d9f9b5995949cb158d943793dea20bd448e1b3971cb6f7418bb15e719661", "price_changes": [{"asset_id": "70512916946285526357165287373537570327431985324385225788636160168740471920430", "price": "0.013", "size": "73.91", "side": "SELL", "hash": "d122dd231b4166cc43d6cf8c313bb3001ccf0fae", "best_bid": "0.002", "best_ask": "0.013"}, {"asset_id": "79516121807256184736227920754945730465880754940725759201193439378549308939672", "price": "0.987", "size": "73.91", "side": "BUY", "hash": "6a5d01da0a89db06e665db99c4724daa61545f92", "best_bid": "0.987", "best_ask": "0.998"}], "timestamp": "1769384069091", "event_type": "price_change"}}
{"_local_timestamp": "2026-01-25T23:34:30.687613+00:00", "data": {"market": "0x9d24d9f9b5995949cb158d943793dea20bd448e1b3971cb6f7418bb15e719661", "price_changes": [{"asset_id": "70512916946285526357165287373537570327431985324385225788636160168740471920430", "price": "0.013", "size": "33.91", "side": "SELL", "hash": "9a42fb207108a64925ea037acc38b50383d01e26", "best_bid": "0.002", "best_ask": "0.013"}, {"asset_id": "79516121807256184736227920754945730465880754940725759201193439378549308939672", "price": "0.987", "size": "33.91", "side": "BUY", "hash": "14116de7976de70363c68bca266093e03c640d42", "best_bid": "0.987", "best_ask": "0.998"}], "timestamp": "1769384070556", "event_type": "price_change"}}
{"_local_timestamp": "2026-01-25T23:34:30.718521+00:00", "data": {"market": "0x9d24d9f9b5995949cb158d943793dea20bd448e1b3971cb6f7418bb15e719661", "price_changes": [{"asset_id": "70512916946285526357165287373537570327431985324385225788636160168740471920430", "price": "0.013", "size": "73.91", "side": "SELL", "hash": "625bd3f4c92a1611b116623dc7e3351307d449ce", "best_bid": "0.002", "best_ask": "0.013"}, {"asset_id": "79516121807256184736227920754945730465880754940725759201193439378549308939672", "price": "0.987", "size": "73.91", "side": "BUY", "hash": "3986ae6cb9f955651e67c53e4529f48186d02fe5", "best_bid": "0.987", "best_ask": "0.998"}], "timestamp": "1769384070582", "event_type": "price_change"}}
{"_local_timestamp": "2026-01-25T23:34:32.187419+00:00", "data": {"market": "0x9d24d9f9b5995949cb158d943793dea20bd448e1b3971cb6f7418bb15e719661", "price_changes": [{"asset_id": "70512916946285526357165287373537570327431985324385225788636160168740471920430", "price": "0.013", "size": "33.91", "side": "SELL", "hash": "92a413931bfd015efe327cefa158fca602449aec", "best_bid": "0.002", "best_ask": "0.013"}, {"asset_id": "79516121807256184736227920754945730465880754940725759201193439378549308939672", "price": "0.987", "size": "33.91", "side": "BUY", "hash": "50bdac84a7212bf29486f88cb5ff256a46766325", "best_bid": "0.987", "best_ask": "0.998"}], "timestamp": "1769384072077", "event_type": "price_change"}}
{"_local_timestamp": "2026-01-25T23:34:32.219557+00:00", "data": {"market": "0x9d24d9f9b5995949cb158d943793dea20bd448e1b3971cb6f7418bb15e719661", "price_changes": [{"asset_id": "70512916946285526357165287373537570327431985324385225788636160168740471920430", "price": "0.013", "size": "73.91", "side": "SELL", "hash": "b36dcca078a8ffdaf4c39b6179129a29e691c039", "best_bid": "0.002", "best_ask": "0.013"}, {"asset_id": "79516121807256184736227920754945730465880754940725759201193439378549308939672", "price": "0.987", "size": "73.91", "side": "BUY", "hash": "10d4fc64dea9679ccaf69418a69980caadf5a5ab", "best_bid": "0.987", "best_ask": "0.998"}], "timestamp": "1769384072109", "event_type": "price_change"}}
{"_local_timestamp": "2026-01-25T23:34:33.629720+00:00", "data": {"market": "0x9d24d9f9b5995949cb158d943793dea20bd448e1b3971cb6f7418bb15e719661", "price_changes": [{"asset_id": "70512916946285526357165287373537570327431985324385225788636160168740471920430", "price": "0.013", "size": "33.91", "side": "SELL", "hash": "6793966dffbcde73e40a895c559e73016d1de9c3", "best_bid": "0.002", "best_ask": "0.013"}, {"asset_id": "79516121807256184736227920754945730465880754940725759201193439378549308939672", "price": "0.987", "size": "33.91", "side": "BUY", "hash": "25b5b1b17d376ca06fa36ab5cfceddf9d4823230", "best_bid": "0.987", "best_ask": "0.998"}], "timestamp": "1769384073554", "event_type": "price_change"}}
{"_local_timestamp": "2026-01-25T23:34:33.658975+00:00", "data": {"market": "0x9d24d9f9b5995949cb158d943793dea20bd448e1b3971cb6f7418bb15e719661", "price_changes": [{"asset_id": "70512916946285526357165287373537570327431985324385225788636160168740471920430", "price": "0.013", "size": "73.91", "side": "SELL", "hash": "7c0ec9f404c5c967c480be677b4bc9c70b5c4c6b", "best_bid": "0.002", "best_ask": "0.013"}, {"asset_id": "79516121807256184736227920754945730465880754940725759201193439378549308939672", "price": "0.987", "size": "73.91", "side": "BUY", "hash": "08b6b72001530ff9cbce2891e56a5f2ad3d3dcac", "best_bid": "0.987", "best_ask": "0.998"}], "timestamp": "1769384073589", "event_type": "price_change"}}
{"_local_timestamp": "2026-01-25T23:34:35.145184+00:00", "data": {"market": "0x9d24d9f9b5995949cb158d943793dea20bd448e1b3971cb6f7418bb15e719661", "price_changes": [{"asset_id": "70512916946285526357165287373537570327431985324385225788636160168740471920430", "price": "0.013", "size": "33.91", "side": "SELL", "hash": "3991646a27b3259015d7cb16b9400e0ecf0d1d08", "best_bid": "0.002", "best_ask": "0.013"}, {"asset_id": "79516121807256184736227920754945730465880754940725759201193439378549308939672", "price": "0.987", "size": "33.91", "side": "BUY", "hash": "e24d7ba1b83c62e201cce6dac6c85ff156071727", "best_bid": "0.987", "best_ask": "0.998"}], "timestamp": "1769384075066", "event_type": "price_change"}}
{"_local_timestamp": "2026-01-25T23:34:35.203068+00:00", "data": {"market": "0x9d24d9f9b5995949cb158d943793dea20bd448e1b3971cb6f7418bb15e719661", "price_changes": [{"asset_id": "70512916946285526357165287373537570327431985324385225788636160168740471920430", "price": "0.013", "size": "73.91", "side": "SELL", "hash": "f3bb36d58b03017c96aedf9fd095eab651663819", "best_bid": "0.002", "best_ask": "0.013"}, {"asset_id": "79516121807256184736227920754945730465880754940725759201193439378549308939672", "price": "0.987", "size": "73.91", "side": "BUY", "hash": "6386ebcc683f318b0a78c993c0ea5b531edc11c5", "best_bid": "0.987", "best_ask": "0.998"}], "timestamp": "1769384075098", "event_type": "price_change"}}
{"_local_timestamp": "2026-01-25T23:34:36.628843+00:00", "data": {"market": "0x9d24d9f9b5995949cb158d943793dea20bd448e1b3971cb6f7418bb15e719661", "price_changes": [{"asset_id": "70512916946285526357165287373537570327431985324385225788636160168740471920430", "price": "0.013", "size": "33.91", "side": "SELL", "hash": "2c0d5624b741ed8b0226591a961b4e1e59fb0521", "best_bid": "0.002", "best_ask": "0.013"}, {"asset_id": "79516121807256184736227920754945730465880754940725759201193439378549308939672", "price": "0.987", "size": "33.91", "side": "BUY", "hash": "2306219b8b10758c5cd0e7e452b464566fcf49ae", "best_bid": "0.987", "best_ask": "0.998"}], "timestamp": "1769384076556", "event_type": "price_change"}}
{"_local_timestamp": "2026-01-25T23:34:36.649607+00:00", "data": {"market": "0x9d24d9f9b5995949cb158d943793dea20bd448e1b3971cb6f7418bb15e719661", "price_changes": [{"asset_id": "70512916946285526357165287373537570327431985324385225788636160168740471920430", "price": "0.013", "size": "73.91", "side": "SELL", "hash": "a0be47e7afe07a4fa36d93b5e0b56ad7a3243105", "best_bid": "0.002", "best_ask": "0.013"}, {"asset_id": "79516121807256184736227920754945730465880754940725759201193439378549308939672", "price": "0.987", "size": "73.91", "side": "BUY", "hash": "49f93a2919ed6b084d1889ee6d2dff41c78a110b", "best_bid": "0.987", "best_ask": "0.998"}], "timestamp": "1769384076581", "event_type": "price_change"}}
{"_local_timestamp": "2026-01-25T23:34:38.139053+00:00", "data": {"market": "0x9d24d9f9b5995949cb158d943793dea20bd448e1b3971cb6f7418bb15e719661", "price_changes": [{"asset_id": "70512916946285526357165287373537570327431985324385225788636160168740471920430", "price": "0.013", "size": "33.91", "side": "SELL", "hash": "ecc57c96b784f16116112210413e97a32194fffd", "best_bid": "0.002", "best_ask": "0.013"}, {"asset_id": "79516121807256184736227920754945730465880754940725759201193439378549308939672", "price": "0.987", "size": "33.91", "side": "BUY", "hash": "9b79fe469e2ae4b72347eda9b6c95e7b55a39a07", "best_bid": "0.987", "best_ask": "0.998"}], "timestamp": "1769384078057", "event_type": "price_change"}}
{"_local_timestamp": "2026-01-25T23:34:38.162654+00:00", "data": {"market": "0x9d24d9f9b5995949cb158d943793dea20bd448e1b3971cb6f7418bb15e719661", "price_changes": [{"asset_id": "70512916946285526357165287373537570327431985324385225788636160168740471920430", "price": "0.013", "size": "73.91", "side": "SELL", "hash": "dfddba1ff534b07571f324964a282ce8768c17b2", "best_bid": "0.002", "best_ask": "0.013"}, {"asset_id": "79516121807256184736227920754945730465880754940725759201193439378549308939672", "price": "0.987", "size": "73.91", "side": "BUY", "hash": "da0d8da7a6f6f0ae78ad8596d9badc3961342cf0", "best_bid": "0.987", "best_ask": "0.998"}], "timestamp": "1769384078093", "event_type": "price_change"}}
{"_local_timestamp": "2026-01-25T23:34:39.621335+00:00", "data": {"market": "0x9d24d9f9b5995949cb158d943793dea20bd448e1b3971cb6f7418bb15e719661", "price_changes": [{"asset_id": "70512916946285526357165287373537570327431985324385225788636160168740471920430", "price": "0.013", "size": "33.91", "side": "SELL", "hash": "ad22ef8e22d2e7e820e3e76ea93eae7c5b8267c0", "best_bid": "0.002", "best_ask": "0.013"}, {"asset_id": "79516121807256184736227920754945730465880754940725759201193439378549308939672", "price": "0.987", "size": "33.91", "side": "BUY", "hash": "c528b54551f1ed386b8084af20ac7a25d7ec802f", "best_bid": "0.987", "best_ask": "0.998"}], "timestamp": "1769384079555", "event_type": "price_change"}}
{"_local_timestamp": "2026-01-25T23:34:39.665312+00:00", "data": {"market": "0x9d24d9f9b5995949cb158d943793dea20bd448e1b3971cb6f7418bb15e719661", "price_changes": [{"asset_id": "70512916946285526357165287373537570327431985324385225788636160168740471920430", "price": "0.013", "size": "73.91", "side": "SELL", "hash": "841b2577a16dc02d1956b4b816e79e3f0fabf2fc", "best_bid": "0.002", "best_ask": "0.013"}, {"asset_id": "79516121807256184736227920754945730465880754940725759201193439378549308939672", "price": "0.987", "size": "73.91", "side": "BUY", "hash": "6b6251d0c6fca8e3b1bc03a2ad97cc5141c93260", "best_bid": "0.987", "best_ask": "0.998"}], "timestamp": "1769384079596", "event_type": "price_change"}}
{"_local_timestamp": "2026-01-25T23:34:40.790012+00:00", "data": {"market": "0x50e477f0b316a3d97d60486479657c63be0763834d0e2e8a30b1b86dc3c1c001", "price_changes": [{"asset_id": "60573178197991590327120832143415406583517170365625050489007297367895074266641", "price": "0.002", "size": "108.81", "side": "BUY", "hash": "b80d28f67431133f9a6e7496f5c27e6ef61054dc", "best_bid": "0.01", "best_ask": "0.014"}, {"asset_id": "39981134260608444876865205057565852475343967395624370698967311821208058420507", "price": "0.998", "size": "108.81", "side": "SELL", "hash": "893188c39dfeb16112dcc96dcc48797849781531", "best_bid": "0.986", "best_ask": "0.99"}], "timestamp": "1769384080704", "event_type": "price_change"}}
{"_local_timestamp": "2026-01-25T23:34:41.129153+00:00", "data": {"market": "0x9d24d9f9b5995949cb158d943793dea20bd448e1b3971cb6f7418bb15e719661", "price_changes": [{"asset_id": "70512916946285526357165287373537570327431985324385225788636160168740471920430", "price": "0.013", "size": "33.91", "side": "SELL", "hash": "bec4978b68c9336280e888a4285b998bcdb9c2f7", "best_bid": "0.002", "best_ask": "0.013"}, {"asset_id": "79516121807256184736227920754945730465880754940725759201193439378549308939672", "price": "0.987", "size": "33.91", "side": "BUY", "hash": "6d1efba8533178fe815e70a042da150c988f7ce5", "best_bid": "0.987", "best_ask": "0.998"}], "timestamp": "1769384081052", "event_type": "price_change"}}
{"_local_timestamp": "2026-01-25T23:34:41.150814+00:00", "data": {"market": "0x9d24d9f9b5995949cb158d943793dea20bd448e1b3971cb6f7418bb15e719661", "price_changes": [{"asset_id": "70512916946285526357165287373537570327431985324385225788636160168740471920430", "price": "0.013", "size": "73.91", "side": "SELL", "hash": "cb65290882f1dfacae2116c72e72dd9be861a3af", "best_bid": "0.002", "best_ask": "0.013"}, {"asset_id": "79516121807256184736227920754945730465880754940725759201193439378549308939672", "price": "0.987", "size": "73.91", "side": "BUY", "hash": "207d46a50c1cb4d3da1c7f594b2b85c8ac8aabad", "best_bid": "0.987", "best_ask": "0.998"}], "timestamp": "1769384081083", "event_type": "price_change"}}
{"_local_timestamp": "2026-01-25T23:34:42.641934+00:00", "data": {"market": "0x9d24d9f9b5995949cb158d943793dea20bd448e1b3971cb6f7418bb15e719661", "price_changes": [{"asset_id": "70512916946285526357165287373537570327431985324385225788636160168740471920430", "price": "0.013", "size": "33.91", "side": "SELL", "hash": "59bb092648221ecb66aeb34cc57f1012d8b5f1c4", "best_bid": "0.002", "best_ask": "0.013"}, {"asset_id": "79516121807256184736227920754945730465880754940725759201193439378549308939672", "price": "0.987", "size": "33.91", "side": "BUY", "hash": "9b77212545d72c87b91d04393da4e78aeeb5d547", "best_bid": "0.987", "best_ask": "0.998"}], "timestamp": "1769384082563", "event_type": "price_change"}}
{"_local_timestamp": "2026-01-25T23:34:42.666608+00:00", "data": {"market": "0x9d24d9f9b5995949cb158d943793dea20bd448e1b3971cb6f7418bb15e719661", "price_changes": [{"asset_id": "70512916946285526357165287373537570327431985324385225788636160168740471920430", "price": "0.013", "size": "73.91", "side": "SELL", "hash": "43b56ba2829047466d1aecc7707d12cb824ee255", "best_bid": "0.002", "best_ask": "0.013"}, {"asset_id": "79516121807256184736227920754945730465880754940725759201193439378549308939672", "price": "0.987", "size": "73.91", "side": "BUY", "hash": "565452348723058916078b7d37bf4bcb4c627370", "best_bid": "0.987", "best_ask": "0.998"}], "timestamp": "1769384082589", "event_type": "price_change"}}
{"_local_timestamp": "2026-01-25T23:34:43.831562+00:00", "data": {"market": "0x50e477f0b316a3d97d60486479657c63be0763834d0e2e8a30b1b86dc3c1c001", "price_changes": [{"asset_id": "60573178197991590327120832143415406583517170365625050489007297367895074266641", "price": "0.002", "size": "166.66", "side": "BUY", "hash": "0f862f25c76643d9c20d8f6c3225950f113e1650", "best_bid": "0.01", "best_ask": "0.014"}, {"asset_id": "39981134260608444876865205057565852475343967395624370698967311821208058420507", "price": "0.998", "size": "166.66", "side": "SELL", "hash": "4305ef5589469f130deeb87a559cd8e77d275416", "best_bid": "0.986", "best_ask": "0.99"}], "timestamp": "1769384083758", "event_type": "price_change"}}
{"_local_timestamp": "2026-01-25T23:34:44.150116+00:00", "data": {"market": "0x9d24d9f9b5995949cb158d943793dea20bd448e1b3971cb6f7418bb15e719661", "price_changes": [{"asset_id": "70512916946285526357165287373537570327431985324385225788636160168740471920430", "price": "0.013", "size": "33.91", "side": "SELL", "hash": "da00e585142f0d2b40a78af8bc57d52954b1efe0", "best_bid": "0.002", "best_ask": "0.013"}, {"asset_id": "79516121807256184736227920754945730465880754940725759201193439378549308939672", "price": "0.987", "size": "33.91", "side": "BUY", "hash": "44fc65b2bfaedd50c7b3f6689a58e2ad20438151", "best_bid": "0.987", "best_ask": "0.998"}], "timestamp": "1769384084054", "event_type": "price_change"}}
{"_local_timestamp": "2026-01-25T23:34:44.159817+00:00", "data": {"market": "0x9d24d9f9b5995949cb158d943793dea20bd448e1b3971cb6f7418bb15e719661", "price_changes": [{"asset_id": "70512916946285526357165287373537570327431985324385225788636160168740471920430", "price": "0.013", "size": "73.91", "side": "SELL", "hash": "e0b39267c51d6ac34c2d11a12e37923c84704742", "best_bid": "0.002", "best_ask": "0.013"}, {"asset_id": "79516121807256184736227920754945730465880754940725759201193439378549308939672", "price": "0.987", "size": "73.91", "side": "BUY", "hash": "219d534160733b94e4676ce523c7a20ba6b6b5d7", "best_bid": "0.987", "best_ask": "0.998"}], "timestamp": "1769384084085", "event_type": "price_change"}}
{"_local_timestamp": "2026-01-25T23:34:45.634794+00:00", "data": {"market": "0x9d24d9f9b5995949cb158d943793dea20bd448e1b3971cb6f7418bb15e719661", "price_changes": [{"asset_id": "70512916946285526357165287373537570327431985324385225788636160168740471920430", "price": "0.013", "size": "33.91", "side": "SELL", "hash": "c7aa32ba8ce1a931d961f95d5c88b1d7ee56b28e", "best_bid": "0.002", "best_ask": "0.013"}, {"asset_id": "79516121807256184736227920754945730465880754940725759201193439378549308939672", "price": "0.987", "size": "33.91", "side": "BUY", "hash": "d2c622add70956f29f0502b225091498f099c59d", "best_bid": "0.987", "best_ask": "0.998"}], "timestamp": "1769384085560", "event_type": "price_change"}}
{"_local_timestamp": "2026-01-25T23:34:45.662767+00:00", "data": {"market": "0x9d24d9f9b5995949cb158d943793dea20bd448e1b3971cb6f7418bb15e719661", "price_changes": [{"asset_id": "70512916946285526357165287373537570327431985324385225788636160168740471920430", "price": "0.013", "size": "73.91", "side": "SELL", "hash": "d568bf5de2cc89c0c5d5e1e629272d4dc8c9087e", "best_bid": "0.002", "best_ask": "0.013"}, {"asset_id": "79516121807256184736227920754945730465880754940725759201193439378549308939672", "price": "0.987", "size": "73.91", "side": "BUY", "hash": "6cc7b4741c8d00384e49f46efcb53a8375f2df7e", "best_bid": "0.987", "best_ask": "0.998"}], "timestamp": "1769384085591", "event_type": "price_change"}}
{"_local_timestamp": "2026-01-25T23:34:47.130416+00:00", "data": {"market": "0x9d24d9f9b5995949cb158d943793dea20bd448e1b3971cb6f7418bb15e719661", "price_changes": [{"asset_id": "70512916946285526357165287373537570327431985324385225788636160168740471920430", "price": "0.013", "size": "33.91", "side": "SELL", "hash": "295fd2607f7578e02d2e94a5df47da8d95845bc2", "best_bid": "0.002", "best_ask": "0.013"}, {"asset_id": "79516121807256184736227920754945730465880754940725759201193439378549308939672", "price": "0.987", "size": "33.91", "side": "BUY", "hash": "b0fa36be0b65293be68ddc422688c9048d725ec1", "best_bid": "0.987", "best_ask": "0.998"}], "timestamp": "1769384087060", "event_type": "price_change"}}
{"_local_timestamp": "2026-01-25T23:34:47.156983+00:00", "data": {"market": "0x9d24d9f9b5995949cb158d943793dea20bd448e1b3971cb6f7418bb15e719661", "price_changes": [{"asset_id": "70512916946285526357165287373537570327431985324385225788636160168740471920430", "price": "0.013", "size": "73.91", "side": "SELL", "hash": "ec51204bcb3b4dca7108c9fa248f868a6d1ef24b", "best_bid": "0.002", "best_ask": "0.013"}, {"asset_id": "79516121807256184736227920754945730465880754940725759201193439378549308939672", "price": "0.987", "size": "73.91", "side": "BUY", "hash": "26623a6d029704787670eae3fd31f8a96657c21a", "best_bid": "0.987", "best_ask": "0.998"}], "timestamp": "1769384087085", "event_type": "price_change"}}
{"_local_timestamp": "2026-01-25T23:34:48.626580+00:00", "data": {"market": "0x9d24d9f9b5995949cb158d943793dea20bd448e1b3971cb6f7418bb15e719661", "price_changes": [{"asset_id": "70512916946285526357165287373537570327431985324385225788636160168740471920430", "price": "0.013", "size": "33.91", "side": "SELL", "hash": "1dbd76bcfe580a9551cb217bd2b34b1f4262774b", "best_bid": "0.002", "best_ask": "0.013"}, {"asset_id": "79516121807256184736227920754945730465880754940725759201193439378549308939672", "price": "0.987", "size": "33.91", "side": "BUY", "hash": "29a98f74b3d16b1f40dd1d3bb5a826bf6198f7c9", "best_bid": "0.987", "best_ask": "0.998"}], "timestamp": "1769384088555", "event_type": "price_change"}}
{"_local_timestamp": "2026-01-25T23:34:48.653903+00:00", "data": {"market": "0x9d24d9f9b5995949cb158d943793dea20bd448e1b3971cb6f7418bb15e719661", "price_changes": [{"asset_id": "70512916946285526357165287373537570327431985324385225788636160168740471920430", "price": "0.013", "size": "73.91", "side": "SELL", "hash": "2fc2d04013c7f84a411c4e0d109e24c06f8c3fdd", "best_bid": "0.002", "best_ask": "0.013"}, {"asset_id": "79516121807256184736227920754945730465880754940725759201193439378549308939672", "price": "0.987", "size": "73.91", "side": "BUY", "hash": "894ae014fca35e5e2bffbd6478981948cbff3697", "best_bid": "0.987", "best_ask": "0.998"}], "timestamp": "1769384088585", "event_type": "price_change"}}
{"_local_timestamp": "2026-01-25T23:34:50.123464+00:00", "data": {"market": "0x9d24d9f9b5995949cb158d943793dea20bd448e1b3971cb6f7418bb15e719661", "price_changes": [{"asset_id": "70512916946285526357165287373537570327431985324385225788636160168740471920430", "price": "0.013", "size": "33.91", "side": "SELL", "hash": "62f7ba3e81bca44e9226aceb3695ff46f2e16c70", "best_bid": "0.002", "best_ask": "0.013"}, {"asset_id": "79516121807256184736227920754945730465880754940725759201193439378549308939672", "price": "0.987", "size": "33.91", "side": "BUY", "hash": "a7b6816bd6292b4b3fe5ecdb4241001a734b7006", "best_bid": "0.987", "best_ask": "0.998"}], "timestamp": "1769384090053", "event_type": "price_change"}}
{"_local_timestamp": "2026-01-25T23:34:50.149625+00:00", "data": {"market": "0x9d24d9f9b5995949cb158d943793dea20bd448e1b3971cb6f7418bb15e719661", "price_changes": [{"asset_id": "70512916946285526357165287373537570327431985324385225788636160168740471920430", "price": "0.013", "size": "73.91", "side": "SELL", "hash": "276ea87fd34da8c66d67fa4ba9601059cf4d3ef5", "best_bid": "0.002", "best_ask": "0.013"}, {"asset_id": "79516121807256184736227920754945730465880754940725759201193439378549308939672", "price": "0.987", "size": "73.91", "side": "BUY", "hash": "02381b6f1fd07fdf849b4ae431c78ff633012196", "best_bid": "0.987", "best_ask": "0.998"}], "timestamp": "1769384090078", "event_type": "price_change"}}
{"_local_timestamp": "2026-01-25T23:34:51.642963+00:00", "data": {"market": "0x9d24d9f9b5995949cb158d943793dea20bd448e1b3971cb6f7418bb15e719661", "price_changes": [{"asset_id": "70512916946285526357165287373537570327431985324385225788636160168740471920430", "price": "0.013", "size": "33.91", "side": "SELL", "hash": "e7f26de944e148f359b7b9d50016bcecdb8e0838", "best_bid": "0.002", "best_ask": "0.013"}, {"asset_id": "79516121807256184736227920754945730465880754940725759201193439378549308939672", "price": "0.987", "size": "33.91", "side": "BUY", "hash": "915a4b0151ab85b2b4afc58d8c9186541032c75e", "best_bid": "0.987", "best_ask": "0.998"}], "timestamp": "1769384091558", "event_type": "price_change"}}
{"_local_timestamp": "2026-01-25T23:34:51.652887+00:00", "data": {"market": "0x9d24d9f9b5995949cb158d943793dea20bd448e1b3971cb6f7418bb15e719661", "price_changes": [{"asset_id": "70512916946285526357165287373537570327431985324385225788636160168740471920430", "price": "0.013", "size": "73.91", "side": "SELL", "hash": "272c2dfca32c6f4cc68eab24a25356653675fb81", "best_bid": "0.002", "best_ask": "0.013"}, {"asset_id": "79516121807256184736227920754945730465880754940725759201193439378549308939672", "price": "0.987", "size": "73.91", "side": "BUY", "hash": "2b2d558a99dc286c9b39076f95327fdd4dfdaf51", "best_bid": "0.987", "best_ask": "0.998"}], "timestamp": "1769384091585", "event_type": "price_change"}}
{"_local_timestamp": "2026-01-25T23:34:53.125623+00:00", "data": {"market": "0x9d24d9f9b5995949cb158d943793dea20bd448e1b3971cb6f7418bb15e719661", "price_changes": [{"asset_id": "70512916946285526357165287373537570327431985324385225788636160168740471920430", "price": "0.013", "size": "33.91", "side": "SELL", "hash": "b50eb28ad3bdc0425982e4d1f9e1fa767fc70386", "best_bid": "0.002", "best_ask": "0.013"}, {"asset_id": "79516121807256184736227920754945730465880754940725759201193439378549308939672", "price": "0.987", "size": "33.91", "side": "BUY", "hash": "f3c0011bb2c9fb5169a799cf5056be09b56c2ffc", "best_bid": "0.987", "best_ask": "0.998"}], "timestamp": "1769384093053", "event_type": "price_change"}}
{"_local_timestamp": "2026-01-25T23:34:53.148419+00:00", "data": {"market": "0x9d24d9f9b5995949cb158d943793dea20bd448e1b3971cb6f7418bb15e719661", "price_changes": [{"asset_id": "70512916946285526357165287373537570327431985324385225788636160168740471920430", "price": "0.013", "size": "73.91", "side": "SELL", "hash": "48c26b511808fc3bd8c7abb22147d74e51aa9186", "best_bid": "0.002", "best_ask": "0.013"}, {"asset_id": "79516121807256184736227920754945730465880754940725759201193439378549308939672", "price": "0.987", "size": "73.91", "side": "BUY", "hash": "4c48af3b3a946ef70428eeb45bb3abd37aea4b27", "best_bid": "0.987", "best_ask": "0.998"}], "timestamp": "1769384093077", "event_type": "price_change"}}
{"_local_timestamp": "2026-01-25T23:34:54.674639+00:00", "data": {"market": "0x9d24d9f9b5995949cb158d943793dea20bd448e1b3971cb6f7418bb15e719661", "price_changes": [{"asset_id": "70512916946285526357165287373537570327431985324385225788636160168740471920430", "price": "0.013", "size": "33.91", "side": "SELL", "hash": "278185fcb30f9bb6cdb41aaac9a8dde71cc4ea69", "best_bid": "0.002", "best_ask": "0.013"}, {"asset_id": "79516121807256184736227920754945730465880754940725759201193439378549308939672", "price": "0.987", "size": "33.91", "side": "BUY", "hash": "f3d3a8c9f04f37edf523f4f9fe2c391d72cc4c07", "best_bid": "0.987", "best_ask": "0.998"}], "timestamp": "1769384094581", "event_type": "price_change"}}
{"_local_timestamp": "2026-01-25T23:34:54.682727+00:00", "data": {"market": "0x9d24d9f9b5995949cb158d943793dea20bd448e1b3971cb6f7418bb15e719661", "price_changes": [{"asset_id": "70512916946285526357165287373537570327431985324385225788636160168740471920430", "price": "0.013", "size": "73.91", "side": "SELL", "hash": "31acb8d3807ae99c6749d500817aeec74dcdb486", "best_bid": "0.002", "best_ask": "0.013"}, {"asset_id": "79516121807256184736227920754945730465880754940725759201193439378549308939672", "price": "0.987", "size": "73.91", "side": "BUY", "hash": "394c5be19a2c41fa02b70a565242deb03c88aeca", "best_bid": "0.987", "best_ask": "0.998"}], "timestamp": "1769384094615", "event_type": "price_change"}}
{"_local_timestamp": "2026-01-25T23:34:56.197696+00:00", "data": {"market": "0x9d24d9f9b5995949cb158d943793dea20bd448e1b3971cb6f7418bb15e719661", "price_changes": [{"asset_id": "70512916946285526357165287373537570327431985324385225788636160168740471920430", "price": "0.013", "size": "33.91", "side": "SELL", "hash": "bac2658aee44f87eaf1761b9b7947052fdfdcd88", "best_bid": "0.002", "best_ask": "0.013"}, {"asset_id": "79516121807256184736227920754945730465880754940725759201193439378549308939672", "price": "0.987", "size": "33.91", "side": "BUY", "hash": "c28ee140114951239edcfd9711ad6306da6d3f4d", "best_bid": "0.987", "best_ask": "0.998"}], "timestamp": "1769384096055", "event_type": "price_change"}}
{"_local_timestamp": "2026-01-25T23:34:56.225450+00:00", "data": {"market": "0x9d24d9f9b5995949cb158d943793dea20bd448e1b3971cb6f7418bb15e719661", "price_changes": [{"asset_id": "70512916946285526357165287373537570327431985324385225788636160168740471920430", "price": "0.013", "size": "73.91", "side": "SELL", "hash": "0d68daf9a299a8aa3e00bfa313919a1ec1e9795b", "best_bid": "0.002", "best_ask": "0.013"}, {"asset_id": "79516121807256184736227920754945730465880754940725759201193439378549308939672", "price": "0.987", "size": "73.91", "side": "BUY", "hash": "48313eade77e1b01dd6ec07f26349dbdb058e5fb", "best_bid": "0.987", "best_ask": "0.998"}], "timestamp": "1769384096095", "event_type": "price_change"}}
{"_local_timestamp": "2026-01-25T23:34:57.621691+00:00", "data": {"market": "0x9d24d9f9b5995949cb158d943793dea20bd448e1b3971cb6f7418bb15e719661", "price_changes": [{"asset_id": "70512916946285526357165287373537570327431985324385225788636160168740471920430", "price": "0.013", "size": "33.91", "side": "SELL", "hash": "b56b9345b0e72ef2332e7837c32ad013a42ae297", "best_bid": "0.002", "best_ask": "0.013"}, {"asset_id": "79516121807256184736227920754945730465880754940725759201193439378549308939672", "price": "0.987", "size": "33.91", "side": "BUY", "hash": "f3b35988d4e0ee1d2b0ddbace526aa8b0cb18065", "best_bid": "0.987", "best_ask": "0.998"}], "timestamp": "1769384097553", "event_type": "price_change"}}
{"_local_timestamp": "2026-01-25T23:34:57.652424+00:00", "data": {"market": "0x9d24d9f9b5995949cb158d943793dea20bd448e1b3971cb6f7418bb15e719661", "price_changes": [{"asset_id": "70512916946285526357165287373537570327431985324385225788636160168740471920430", "price": "0.013", "size": "73.91", "side": "SELL", "hash": "49544f63bf7fe53fb3f5653f7d21534de9c97368", "best_bid": "0.002", "best_ask": "0.013"}, {"asset_id": "79516121807256184736227920754945730465880754940725759201193439378549308939672", "price": "0.987", "size": "73.91", "side": "BUY", "hash": "63c5042a8e4bec89a91830de675ab0a70d20e06b", "best_bid": "0.987", "best_ask": "0.998"}], "timestamp": "1769384097581", "event_type": "price_change"}}
{"_local_timestamp": "2026-01-25T23:34:59.120699+00:00", "data": {"market": "0x9d24d9f9b5995949cb158d943793dea20bd448e1b3971cb6f7418bb15e719661", "price_changes": [{"asset_id": "70512916946285526357165287373537570327431985324385225788636160168740471920430", "price": "0.013", "size": "33.91", "side": "SELL", "hash": "5cd63ea4754c5330efb24e04cfafcf26c8c45fe1", "best_bid": "0.002", "best_ask": "0.013"}, {"asset_id": "79516121807256184736227920754945730465880754940725759201193439378549308939672", "price": "0.987", "size": "33.91", "side": "BUY", "hash": "d08979b5269de32cd9bc678194a850b50ab7b3b2", "best_bid": "0.987", "best_ask": "0.998"}], "timestamp": "1769384099054", "event_type": "price_change"}}
{"_local_timestamp": "2026-01-25T23:34:59.150234+00:00", "data": {"market": "0x9d24d9f9b5995949cb158d943793dea20bd448e1b3971cb6f7418bb15e719661", "price_changes": [{"asset_id": "70512916946285526357165287373537570327431985324385225788636160168740471920430", "price": "0.013", "size": "73.91", "side": "SELL", "hash": "7789c2d760a3d671b7ced2afd306e11e80406e05", "best_bid": "0.002", "best_ask": "0.013"}, {"asset_id": "79516121807256184736227920754945730465880754940725759201193439378549308939672", "price": "0.987", "size": "73.91", "side": "BUY", "hash": "7f07ae61c998cfec789b2cae9329c9ce75a624ff", "best_bid": "0.987", "best_ask": "0.998"}], "timestamp": "1769384099080", "event_type": "price_change"}}
{"_local_timestamp": "2026-01-25T23:35:00.628388+00:00", "data": {"market": "0x9d24d9f9b5995949cb158d943793dea20bd448e1b3971cb6f7418bb15e719661", "price_changes": [{"asset_id": "70512916946285526357165287373537570327431985324385225788636160168740471920430", "price": "0.013", "size": "33.91", "side": "SELL", "hash": "c0a27d45c31ec4730b943163846b0fe0abd9bdad", "best_bid": "0.002", "best_ask": "0.013"}, {"asset_id": "79516121807256184736227920754945730465880754940725759201193439378549308939672", "price": "0.987", "size": "33.91", "side": "BUY", "hash": "35760198ec7a71899d56cffd8b1ae8c5bb67622b", "best_bid": "0.987", "best_ask": "0.998"}], "timestamp": "1769384100560", "event_type": "price_change"}}
{"_local_timestamp": "2026-01-25T23:35:00.656100+00:00", "data": {"market": "0x9d24d9f9b5995949cb158d943793dea20bd448e1b3971cb6f7418bb15e719661", "price_changes": [{"asset_id": "70512916946285526357165287373537570327431985324385225788636160168740471920430", "price": "0.013", "size": "73.91", "side": "SELL", "hash": "3e01536da75d8838ba2eaee71f7a3fe60cfd3940", "best_bid": "0.002", "best_ask": "0.013"}, {"asset_id": "79516121807256184736227920754945730465880754940725759201193439378549308939672", "price": "0.987", "size": "73.91", "side": "BUY", "hash": "1a5533a70e5864a49ff1f078a080ac8963df231a", "best_bid": "0.987", "best_ask": "0.998"}], "timestamp": "1769384100588", "event_type": "price_change"}}
{"_local_timestamp": "2026-01-25T23:35:02.128174+00:00", "data": {"market": "0x9d24d9f9b5995949cb158d943793dea20bd448e1b3971cb6f7418bb15e719661", "price_changes": [{"asset_id": "70512916946285526357165287373537570327431985324385225788636160168740471920430", "price": "0.013", "size": "33.91", "side": "SELL", "hash": "092f2bf347df761ee630faa95d454a7291719131", "best_bid": "0.002", "best_ask": "0.013"}, {"asset_id": "79516121807256184736227920754945730465880754940725759201193439378549308939672", "price": "0.987", "size": "33.91", "side": "BUY", "hash": "974a2ff448174f5c0dc3b54e2d13544663dae1a3", "best_bid": "0.987", "best_ask": "0.998"}], "timestamp": "1769384102060", "event_type": "price_change"}}
{"_local_timestamp": "2026-01-25T23:35:02.159092+00:00", "data": {"market": "0x9d24d9f9b5995949cb158d943793dea20bd448e1b3971cb6f7418bb15e719661", "price_changes": [{"asset_id": "70512916946285526357165287373537570327431985324385225788636160168740471920430", "price": "0.013", "size": "73.91", "side": "SELL", "hash": "f383dce1a5b4342170fd2595b2f5b5d211db1092", "best_bid": "0.002", "best_ask": "0.013"}, {"asset_id": "79516121807256184736227920754945730465880754940725759201193439378549308939672", "price": "0.987", "size": "73.91", "side": "BUY", "hash": "cc8c0c2caf111893b904fb7fd92c5d8fa51caf62", "best_bid": "0.987", "best_ask": "0.998"}], "timestamp": "1769384102087", "event_type": "price_change"}}
{"_local_timestamp": "2026-01-25T23:35:03.621375+00:00", "data": {"market": "0x9d24d9f9b5995949cb158d943793dea20bd448e1b3971cb6f7418bb15e719661", "price_changes": [{"asset_id": "70512916946285526357165287373537570327431985324385225788636160168740471920430", "price": "0.013", "size": "33.91", "side": "SELL", "hash": "341453ab3c34b805f4db75faa2f36286240c5b73", "best_bid": "0.002", "best_ask": "0.013"}, {"asset_id": "79516121807256184736227920754945730465880754940725759201193439378549308939672", "price": "0.987", "size": "33.91", "side": "BUY", "hash": "ecd44753234f41717bbcd949f0e6ac380a81e9f7", "best_bid": "0.987", "best_ask": "0.998"}], "timestamp": "1769384103554", "event_type": "price_change"}}
{"_local_timestamp": "2026-01-25T23:35:03.657769+00:00", "data": {"market": "0x9d24d9f9b5995949cb158d943793dea20bd448e1b3971cb6f7418bb15e719661", "price_changes": [{"asset_id": "70512916946285526357165287373537570327431985324385225788636160168740471920430", "price": "0.013", "size": "73.91", "side": "SELL", "hash": "1dbc6d251c939ed4bfc6ecc5dcd70dc0a86adb2c", "best_bid": "0.002", "best_ask": "0.013"}, {"asset_id": "79516121807256184736227920754945730465880754940725759201193439378549308939672", "price": "0.987", "size": "73.91", "side": "BUY", "hash": "1220bbe4bf535a7cb23a896b8adbb53e964c3001", "best_bid": "0.987", "best_ask": "0.998"}], "timestamp": "1769384103581", "event_type": "price_change"}}
{"_local_timestamp": "2026-01-25T23:35:05.137073+00:00", "data": {"market": "0x9d24d9f9b5995949cb158d943793dea20bd448e1b3971cb6f7418bb15e719661", "price_changes": [{"asset_id": "70512916946285526357165287373537570327431985324385225788636160168740471920430", "price": "0.013", "size": "33.91", "side": "SELL", "hash": "c8446c04653d655ea1247003bee03bbe42cf60f3", "best_bid": "0.002", "best_ask": "0.013"}, {"asset_id": "79516121807256184736227920754945730465880754940725759201193439378549308939672", "price": "0.987", "size": "33.91", "side": "BUY", "hash": "2c18ffb2db0fdf7ac6d95e80f7a95ee7557c4248", "best_bid": "0.987", "best_ask": "0.998"}], "timestamp": "1769384105063", "event_type": "price_change"}}
{"_local_timestamp": "2026-01-25T23:35:05.202403+00:00", "data": {"market": "0x9d24d9f9b5995949cb158d943793dea20bd448e1b3971cb6f7418bb15e719661", "price_changes": [{"asset_id": "70512916946285526357165287373537570327431985324385225788636160168740471920430", "price": "0.013", "size": "73.91", "side": "SELL", "hash": "3e718679b8490cb296046971671bc3e5d69463fa", "best_bid": "0.002", "best_ask": "0.013"}, {"asset_id": "79516121807256184736227920754945730465880754940725759201193439378549308939672", "price": "0.987", "size": "73.91", "side": "BUY", "hash": "af8b2a83ac73ee4d03cb5d04e5ff0a207b379fbe", "best_bid": "0.987", "best_ask": "0.998"}], "timestamp": "1769384105122", "event_type": "price_change"}}
{"_local_timestamp": "2026-01-25T23:35:06.629136+00:00", "data": {"market": "0x9d24d9f9b5995949cb158d943793dea20bd448e1b3971cb6f7418bb15e719661", "price_changes": [{"asset_id": "70512916946285526357165287373537570327431985324385225788636160168740471920430", "price": "0.013", "size": "33.91", "side": "SELL", "hash": "ae91c4a3d7c4138779472de0e1709926d19ada95", "best_bid": "0.002", "best_ask": "0.013"}, {"asset_id": "79516121807256184736227920754945730465880754940725759201193439378549308939672", "price": "0.987", "size": "33.91", "side": "BUY", "hash": "db5629758f185d6e1fdd3b35beff34623907dfd5", "best_bid": "0.987", "best_ask": "0.998"}], "timestamp": "1769384106558", "event_type": "price_change"}}
{"_local_timestamp": "2026-01-25T23:35:06.663926+00:00", "data": {"market": "0x9d24d9f9b5995949cb158d943793dea20bd448e1b3971cb6f7418bb15e719661", "price_changes": [{"asset_id": "70512916946285526357165287373537570327431985324385225788636160168740471920430", "price": "0.013", "size": "73.91", "side": "SELL", "hash": "e41b94b4b453746c25fbf3738419c4ae01576464", "best_bid": "0.002", "best_ask": "0.013"}, {"asset_id": "79516121807256184736227920754945730465880754940725759201193439378549308939672", "price": "0.987", "size": "73.91", "side": "BUY", "hash": "7b4b85a405cffadd7c039ea8a315bb2d177d6ef6", "best_bid": "0.987", "best_ask": "0.998"}], "timestamp": "1769384106587", "event_type": "price_change"}}
{"_local_timestamp": "2026-01-25T23:35:08.149776+00:00", "data": {"market": "0x9d24d9f9b5995949cb158d943793dea20bd448e1b3971cb6f7418bb15e719661", "price_changes": [{"asset_id": "70512916946285526357165287373537570327431985324385225788636160168740471920430", "price": "0.013", "size": "33.91", "side": "SELL", "hash": "81bbb07f387daf81c771c57dd6dc1fc1cd2b18f5", "best_bid": "0.002", "best_ask": "0.013"}, {"asset_id": "79516121807256184736227920754945730465880754940725759201193439378549308939672", "price": "0.987", "size": "33.91", "side": "BUY", "hash": "24ab68a01d9de320050dbe58c92d69fa93462d8b", "best_bid": "0.987", "best_ask": "0.998"}], "timestamp": "1769384108058", "event_type": "price_change"}}
{"_local_timestamp": "2026-01-25T23:35:08.158453+00:00", "data": {"market": "0x9d24d9f9b5995949cb158d943793dea20bd448e1b3971cb6f7418bb15e719661", "price_changes": [{"asset_id": "70512916946285526357165287373537570327431985324385225788636160168740471920430", "price": "0.013", "size": "73.91", "side": "SELL", "hash": "d41ab7362d93ee965013db8d88e3524e970a5d68", "best_bid": "0.002", "best_ask": "0.013"}, {"asset_id": "79516121807256184736227920754945730465880754940725759201193439378549308939672", "price": "0.987", "size": "73.91", "side": "BUY", "hash": "e37d78dbb4a0db68dfbd29b2b0bc10b5bd264d33", "best_bid": "0.987", "best_ask": "0.998"}], "timestamp": "1769384108087", "event_type": "price_change"}}
{"_local_timestamp": "2026-01-25T23:35:09.619935+00:00", "data": {"market": "0x9d24d9f9b5995949cb158d943793dea20bd448e1b3971cb6f7418bb15e719661", "price_changes": [{"asset_id": "70512916946285526357165287373537570327431985324385225788636160168740471920430", "price": "0.013", "size": "33.91", "side": "SELL", "hash": "79f7bd0be54874fd2aa8dd3208961da3ba2e7d5d", "best_bid": "0.002", "best_ask": "0.013"}, {"asset_id": "79516121807256184736227920754945730465880754940725759201193439378549308939672", "price": "0.987", "size": "33.91", "side": "BUY", "hash": "4f3d38a08392c56ebb636cdcf6c812065f7f6a05", "best_bid": "0.987", "best_ask": "0.998"}], "timestamp": "1769384109555", "event_type": "price_change"}}
{"_local_timestamp": "2026-01-25T23:35:09.653730+00:00", "data": {"market": "0x9d24d9f9b5995949cb158d943793dea20bd448e1b3971cb6f7418bb15e719661", "price_changes": [{"asset_id": "70512916946285526357165287373537570327431985324385225788636160168740471920430", "price": "0.013", "size": "73.91", "side": "SELL", "hash": "946634ec2f68f5993e53542a4721aea057605c2a", "best_bid": "0.002", "best_ask": "0.013"}, {"asset_id": "79516121807256184736227920754945730465880754940725759201193439378549308939672", "price": "0.987", "size": "73.91", "side": "BUY", "hash": "09451e8219e2b5a882a04951caccc9a1273d1a54", "best_bid": "0.987", "best_ask": "0.998"}], "timestamp": "1769384109582", "event_type": "price_change"}}
{"_local_timestamp": "2026-01-25T23:35:11.133462+00:00", "data": {"market": "0x9d24d9f9b5995949cb158d943793dea20bd448e1b3971cb6f7418bb15e719661", "price_changes": [{"asset_id": "70512916946285526357165287373537570327431985324385225788636160168740471920430", "price": "0.013", "size": "33.91", "side": "SELL", "hash": "f044b6c368beb7c7286ec990d29c35503473df16", "best_bid": "0.002", "best_ask": "0.013"}, {"asset_id": "79516121807256184736227920754945730465880754940725759201193439378549308939672", "price": "0.987", "size": "33.91", "side": "BUY", "hash": "8343f5abfb790fad608695689e05512a29461f67", "best_bid": "0.987", "best_ask": "0.998"}], "timestamp": "1769384111057", "event_type": "price_change"}}
{"_local_timestamp": "2026-01-25T23:35:11.169389+00:00", "data": {"market": "0x9d24d9f9b5995949cb158d943793dea20bd448e1b3971cb6f7418bb15e719661", "price_changes": [{"asset_id": "70512916946285526357165287373537570327431985324385225788636160168740471920430", "price": "0.013", "size": "73.91", "side": "SELL", "hash": "54c65aae5595237e234e5d6e89fd8c1c5ed8b579", "best_bid": "0.002", "best_ask": "0.013"}, {"asset_id": "79516121807256184736227920754945730465880754940725759201193439378549308939672", "price": "0.987", "size": "73.91", "side": "BUY", "hash": "54cbd668b35596d27e9b94655912fc2c467007e3", "best_bid": "0.987", "best_ask": "0.998"}], "timestamp": "1769384111092", "event_type": "price_change"}}
{"_local_timestamp": "2026-01-25T23:35:12.638427+00:00", "data": {"market": "0x9d24d9f9b5995949cb158d943793dea20bd448e1b3971cb6f7418bb15e719661", "price_changes": [{"asset_id": "70512916946285526357165287373537570327431985324385225788636160168740471920430", "price": "0.013", "size": "33.91", "side": "SELL", "hash": "b2884c80b1e778e292d8ad3d262feddf27ec243e", "best_bid": "0.002", "best_ask": "0.013"}, {"asset_id": "79516121807256184736227920754945730465880754940725759201193439378549308939672", "price": "0.987", "size": "33.91", "side": "BUY", "hash": "4eba39ed524a03c7644f9964dc50671dc9b0c523", "best_bid": "0.987", "best_ask": "0.998"}], "timestamp": "1769384112558", "event_type": "price_change"}}
{"_local_timestamp": "2026-01-25T23:35:12.663966+00:00", "data": {"market": "0x9d24d9f9b5995949cb158d943793dea20bd448e1b3971cb6f7418bb15e719661", "price_changes": [{"asset_id": "70512916946285526357165287373537570327431985324385225788636160168740471920430", "price": "0.013", "size": "73.91", "side": "SELL", "hash": "babc1a882a1e9ba3f32188aeddab375c26473b9d", "best_bid": "0.002", "best_ask": "0.013"}, {"asset_id": "79516121807256184736227920754945730465880754940725759201193439378549308939672", "price": "0.987", "size": "73.91", "side": "BUY", "hash": "99593beafe5fd83105bf6bb76142ec57716cb06f", "best_bid": "0.987", "best_ask": "0.998"}], "timestamp": "1769384112584", "event_type": "price_change"}}
{"_local_timestamp": "2026-01-25T23:35:14.128159+00:00", "data": {"market": "0x9d24d9f9b5995949cb158d943793dea20bd448e1b3971cb6f7418bb15e719661", "price_changes": [{"asset_id": "70512916946285526357165287373537570327431985324385225788636160168740471920430", "price": "0.013", "size": "33.91", "side": "SELL", "hash": "a8e51c9a3729932d49453954eeaf8a87960f1850", "best_bid": "0.002", "best_ask": "0.013"}, {"asset_id": "79516121807256184736227920754945730465880754940725759201193439378549308939672", "price": "0.987", "size": "33.91", "side": "BUY", "hash": "0eaf0b290fa7e08c00ef91461415cf3055b64937", "best_bid": "0.987", "best_ask": "0.998"}], "timestamp": "1769384114054", "event_type": "price_change"}}
{"_local_timestamp": "2026-01-25T23:35:14.151651+00:00", "data": {"market": "0x9d24d9f9b5995949cb158d943793dea20bd448e1b3971cb6f7418bb15e719661", "price_changes": [{"asset_id": "70512916946285526357165287373537570327431985324385225788636160168740471920430", "price": "0.013", "size": "73.91", "side": "SELL", "hash": "66b19696ac0e9b8187d4574f6f107614e23f9945", "best_bid": "0.002", "best_ask": "0.013"}, {"asset_id": "79516121807256184736227920754945730465880754940725759201193439378549308939672", "price": "0.987", "size": "73.91", "side": "BUY", "hash": "23f2a5d1cb25521b17c909f2df3884f551be53b4", "best_bid": "0.987", "best_ask": "0.998"}], "timestamp": "1769384114080", "event_type": "price_change"}}
{"_local_timestamp": "2026-01-25T23:35:15.627293+00:00", "data": {"market": "0x9d24d9f9b5995949cb158d943793dea20bd448e1b3971cb6f7418bb15e719661", "price_changes": [{"asset_id": "70512916946285526357165287373537570327431985324385225788636160168740471920430", "price": "0.013", "size": "33.91", "side": "SELL", "hash": "b2769e2ef5f1245f5e58dc1417c27dcbc63ea9ed", "best_bid": "0.002", "best_ask": "0.013"}, {"asset_id": "79516121807256184736227920754945730465880754940725759201193439378549308939672", "price": "0.987", "size": "33.91", "side": "BUY", "hash": "2915f8ba3b51625a74a24d8e52478ab7d9422045", "best_bid": "0.987", "best_ask": "0.998"}], "timestamp": "1769384115555", "event_type": "price_change"}}
{"_local_timestamp": "2026-01-25T23:35:15.650190+00:00", "data": {"market": "0x9d24d9f9b5995949cb158d943793dea20bd448e1b3971cb6f7418bb15e719661", "price_changes": [{"asset_id": "70512916946285526357165287373537570327431985324385225788636160168740471920430", "price": "0.013", "size": "73.91", "side": "SELL", "hash": "351b3779b05f3e4aa9e22d18df9e216005b66364", "best_bid": "0.002", "best_ask": "0.013"}, {"asset_id": "79516121807256184736227920754945730465880754940725759201193439378549308939672", "price": "0.987", "size": "73.91", "side": "BUY", "hash": "ec5d36e04394bfabc70050be2d5bb968610b673a", "best_bid": "0.987", "best_ask": "0.998"}], "timestamp": "1769384115583", "event_type": "price_change"}}
{"_local_timestamp": "2026-01-25T23:35:17.155278+00:00", "data": {"market": "0x9d24d9f9b5995949cb158d943793dea20bd448e1b3971cb6f7418bb15e719661", "price_changes": [{"asset_id": "70512916946285526357165287373537570327431985324385225788636160168740471920430", "price": "0.013", "size": "33.91", "side": "SELL", "hash": "78619c9c50a975b8d6ba6e58f6845e4f1f18906c", "best_bid": "0.002", "best_ask": "0.013"}, {"asset_id": "79516121807256184736227920754945730465880754940725759201193439378549308939672", "price": "0.987", "size": "33.91", "side": "BUY", "hash": "54a1d0cfb76053159f3188fd3f9c0ea58bd9426d", "best_bid": "0.987", "best_ask": "0.998"}], "timestamp": "1769384117056", "event_type": "price_change"}}
{"_local_timestamp": "2026-01-25T23:35:17.162130+00:00", "data": {"market": "0x9d24d9f9b5995949cb158d943793dea20bd448e1b3971cb6f7418bb15e719661", "price_changes": [{"asset_id": "70512916946285526357165287373537570327431985324385225788636160168740471920430", "price": "0.013", "size": "73.91", "side": "SELL", "hash": "853a11c0a559e526edc4bd5d51945a55644afeaf", "best_bid": "0.002", "best_ask": "0.013"}, {"asset_id": "79516121807256184736227920754945730465880754940725759201193439378549308939672", "price": "0.987", "size": "73.91", "side": "BUY", "hash": "00aba426dcc0ba06640210eb79b232f28b1d263f", "best_bid": "0.987", "best_ask": "0.998"}], "timestamp": "1769384117088", "event_type": "price_change"}}
{"_local_timestamp": "2026-01-25T23:35:18.633680+00:00", "data": {"market": "0x9d24d9f9b5995949cb158d943793dea20bd448e1b3971cb6f7418bb15e719661", "price_changes": [{"asset_id": "70512916946285526357165287373537570327431985324385225788636160168740471920430", "price": "0.013", "size": "33.91", "side": "SELL", "hash": "49b5623b3d6849457dad8055eceb2c82919fbb6f", "best_bid": "0.002", "best_ask": "0.013"}, {"asset_id": "79516121807256184736227920754945730465880754940725759201193439378549308939672", "price": "0.987", "size": "33.91", "side": "BUY", "hash": "9c4404d1abb15ae0f07f84e68be52deb5fceab05", "best_bid": "0.987", "best_ask": "0.998"}], "timestamp": "1769384118567", "event_type": "price_change"}}
{"_local_timestamp": "2026-01-25T23:35:18.667946+00:00", "data": {"market": "0x9d24d9f9b5995949cb158d943793dea20bd448e1b3971cb6f7418bb15e719661", "price_changes": [{"asset_id": "70512916946285526357165287373537570327431985324385225788636160168740471920430", "price": "0.013", "size": "73.91", "side": "SELL", "hash": "99bf318c441422fd8358c4e1b2db53eaabaa348d", "best_bid": "0.002", "best_ask": "0.013"}, {"asset_id": "79516121807256184736227920754945730465880754940725759201193439378549308939672", "price": "0.987", "size": "73.91", "side": "BUY", "hash": "7670f395c90b36d90682bdc15599da7b8da778fb", "best_bid": "0.987", "best_ask": "0.998"}], "timestamp": "1769384118596", "event_type": "price_change"}}
{"_local_timestamp": "2026-01-25T23:35:20.146708+00:00", "data": {"market": "0x9d24d9f9b5995949cb158d943793dea20bd448e1b3971cb6f7418bb15e719661", "price_changes": [{"asset_id": "70512916946285526357165287373537570327431985324385225788636160168740471920430", "price": "0.013", "size": "33.91", "side": "SELL", "hash": "5a5e9d26de52694278e84d4fdd128d38ca774f37", "best_bid": "0.002", "best_ask": "0.013"}, {"asset_id": "79516121807256184736227920754945730465880754940725759201193439378549308939672", "price": "0.987", "size": "33.91", "side": "BUY", "hash": "109ccb96bbdef994a71ef6726bd64bae378876ed", "best_bid": "0.987", "best_ask": "0.998"}], "timestamp": "1769384120060", "event_type": "price_change"}}
{"_local_timestamp": "2026-01-25T23:35:20.186093+00:00", "data": {"market": "0x9d24d9f9b5995949cb158d943793dea20bd448e1b3971cb6f7418bb15e719661", "price_changes": [{"asset_id": "70512916946285526357165287373537570327431985324385225788636160168740471920430", "price": "0.013", "size": "73.91", "side": "SELL", "hash": "8d7a6267a98be80b7cee2ddf27cb7bb51029b2a7", "best_bid": "0.002", "best_ask": "0.013"}, {"asset_id": "79516121807256184736227920754945730465880754940725759201193439378549308939672", "price": "0.987", "size": "73.91", "side": "BUY", "hash": "d75334a25fa426ec5ed4481a144bcf3f355d1805", "best_bid": "0.987", "best_ask": "0.998"}], "timestamp": "1769384120094", "event_type": "price_change"}}
{"_local_timestamp": "2026-01-25T23:35:21.629516+00:00", "data": {"market": "0x9d24d9f9b5995949cb158d943793dea20bd448e1b3971cb6f7418bb15e719661", "price_changes": [{"asset_id": "70512916946285526357165287373537570327431985324385225788636160168740471920430", "price": "0.013", "size": "33.91", "side": "SELL", "hash": "0bf49f35cfdf06957a6bb108ce7e6e8c1100cba8", "best_bid": "0.002", "best_ask": "0.013"}, {"asset_id": "79516121807256184736227920754945730465880754940725759201193439378549308939672", "price": "0.987", "size": "33.91", "side": "BUY", "hash": "02697e4acd8c3a8463268d377a6ad8ce63a264a7", "best_bid": "0.987", "best_ask": "0.998"}], "timestamp": "1769384121554", "event_type": "price_change"}}
{"_local_timestamp": "2026-01-25T23:35:21.656066+00:00", "data": {"market": "0x9d24d9f9b5995949cb158d943793dea20bd448e1b3971cb6f7418bb15e719661", "price_changes": [{"asset_id": "70512916946285526357165287373537570327431985324385225788636160168740471920430", "price": "0.013", "size": "73.91", "side": "SELL", "hash": "93dbc2a510da3aedb909e3f99e87fcb9280c772a", "best_bid": "0.002", "best_ask": "0.013"}, {"asset_id": "79516121807256184736227920754945730465880754940725759201193439378549308939672", "price": "0.987", "size": "73.91", "side": "BUY", "hash": "d6a66196d93ca9be53e917367ded4399fa8ea51a", "best_bid": "0.987", "best_ask": "0.998"}], "timestamp": "1769384121585", "event_type": "price_change"}}
{"_local_timestamp": "2026-01-25T23:35:23.168575+00:00", "data": {"market": "0x9d24d9f9b5995949cb158d943793dea20bd448e1b3971cb6f7418bb15e719661", "price_changes": [{"asset_id": "70512916946285526357165287373537570327431985324385225788636160168740471920430", "price": "0.013", "size": "33.91", "side": "SELL", "hash": "887f25c3f6c75ff871607a51bb048d9c323bbabc", "best_bid": "0.002", "best_ask": "0.013"}, {"asset_id": "79516121807256184736227920754945730465880754940725759201193439378549308939672", "price": "0.987", "size": "33.91", "side": "BUY", "hash": "40a7ead1459ebad952fed0a27be5ac2abdbf9c5b", "best_bid": "0.987", "best_ask": "0.998"}], "timestamp": "1769384123054", "event_type": "price_change"}}
{"_local_timestamp": "2026-01-25T23:35:23.173102+00:00", "data": {"market": "0x9d24d9f9b5995949cb158d943793dea20bd448e1b3971cb6f7418bb15e719661", "price_changes": [{"asset_id": "70512916946285526357165287373537570327431985324385225788636160168740471920430", "price": "0.013", "size": "73.91", "side": "SELL", "hash": "b2c8ecb5e140a4279801674c2ddfba30d3fb8428", "best_bid": "0.002", "best_ask": "0.013"}, {"asset_id": "79516121807256184736227920754945730465880754940725759201193439378549308939672", "price": "0.987", "size": "73.91", "side": "BUY", "hash": "d0a848d9933dfdbb54a77d0de98b5bde82056edf", "best_bid": "0.987", "best_ask": "0.998"}], "timestamp": "1769384123083", "event_type": "price_change"}}
{"_local_timestamp": "2026-01-25T23:35:24.726160+00:00", "data": {"market": "0x9d24d9f9b5995949cb158d943793dea20bd448e1b3971cb6f7418bb15e719661", "price_changes": [{"asset_id": "70512916946285526357165287373537570327431985324385225788636160168740471920430", "price": "0.013", "size": "33.91", "side": "SELL", "hash": "cee6d0297d3402eff03fc8a9d7922dd91cd97a59", "best_bid": "0.002", "best_ask": "0.013"}, {"asset_id": "79516121807256184736227920754945730465880754940725759201193439378549308939672", "price": "0.987", "size": "33.91", "side": "BUY", "hash": "2ff23ba3bdbf0bf142dc459a65f8b8483f76fffa", "best_bid": "0.987", "best_ask": "0.998"}], "timestamp": "1769384124553", "event_type": "price_change"}}
{"_local_timestamp": "2026-01-25T23:35:24.751691+00:00", "data": {"market": "0x9d24d9f9b5995949cb158d943793dea20bd448e1b3971cb6f7418bb15e719661", "price_changes": [{"asset_id": "70512916946285526357165287373537570327431985324385225788636160168740471920430", "price": "0.013", "size": "73.91", "side": "SELL", "hash": "26615c74651c02b700a6e39b076b79d3b1155f16", "best_bid": "0.002", "best_ask": "0.013"}, {"asset_id": "79516121807256184736227920754945730465880754940725759201193439378549308939672", "price": "0.987", "size": "73.91", "side": "BUY", "hash": "eb318a4ecab5b4c9f07592fc46eb4a5c49487719", "best_bid": "0.987", "best_ask": "0.998"}], "timestamp": "1769384124580", "event_type": "price_change"}}
{"_local_timestamp": "2026-01-25T23:35:26.127015+00:00", "data": {"market": "0x9d24d9f9b5995949cb158d943793dea20bd448e1b3971cb6f7418bb15e719661", "price_changes": [{"asset_id": "70512916946285526357165287373537570327431985324385225788636160168740471920430", "price": "0.013", "size": "33.91", "side": "SELL", "hash": "7be9ad10c86da444281e6bb4d5ca2086c9b56f4c", "best_bid": "0.002", "best_ask": "0.013"}, {"asset_id": "79516121807256184736227920754945730465880754940725759201193439378549308939672", "price": "0.987", "size": "33.91", "side": "BUY", "hash": "17d8884c7e7c596786051ba3b8e9b7cd75a27214", "best_bid": "0.987", "best_ask": "0.998"}], "timestamp": "1769384126059", "event_type": "price_change"}}
{"_local_timestamp": "2026-01-25T23:35:26.150209+00:00", "data": {"market": "0x9d24d9f9b5995949cb158d943793dea20bd448e1b3971cb6f7418bb15e719661", "price_changes": [{"asset_id": "70512916946285526357165287373537570327431985324385225788636160168740471920430", "price": "0.013", "size": "73.91", "side": "SELL", "hash": "6cc205ce20aa9367f4041614c02d68410e2cba10", "best_bid": "0.002", "best_ask": "0.013"}, {"asset_id": "79516121807256184736227920754945730465880754940725759201193439378549308939672", "price": "0.987", "size": "73.91", "side": "BUY", "hash": "c00e0d3f6f66684fd0c5a4e98a8155fc551affbe", "best_bid": "0.987", "best_ask": "0.998"}], "timestamp": "1769384126085", "event_type": "price_change"}}
{"_local_timestamp": "2026-01-25T23:35:27.625198+00:00", "data": {"market": "0x9d24d9f9b5995949cb158d943793dea20bd448e1b3971cb6f7418bb15e719661", "price_changes": [{"asset_id": "70512916946285526357165287373537570327431985324385225788636160168740471920430", "price": "0.013", "size": "33.91", "side": "SELL", "hash": "62b0e927da3d59951f8154a182a88a46cfe772a6", "best_bid": "0.002", "best_ask": "0.013"}, {"asset_id": "79516121807256184736227920754945730465880754940725759201193439378549308939672", "price": "0.987", "size": "33.91", "side": "BUY", "hash": "ee24f87a80b911eda4026eb89a36ea6d5998e8eb", "best_bid": "0.987", "best_ask": "0.998"}], "timestamp": "1769384127552", "event_type": "price_change"}}
{"_local_timestamp": "2026-01-25T23:35:27.648413+00:00", "data": {"market": "0x9d24d9f9b5995949cb158d943793dea20bd448e1b3971cb6f7418bb15e719661", "price_changes": [{"asset_id": "70512916946285526357165287373537570327431985324385225788636160168740471920430", "price": "0.013", "size": "73.91", "side": "SELL", "hash": "0d462265ba8a8fa5a8298a3f1546da9acd7e6d04", "best_bid": "0.002", "best_ask": "0.013"}, {"asset_id": "79516121807256184736227920754945730465880754940725759201193439378549308939672", "price": "0.987", "size": "73.91", "side": "BUY", "hash": "a74f17553f67076ae65f449168d391dbc64ab0e4", "best_bid": "0.987", "best_ask": "0.998"}], "timestamp": "1769384127578", "event_type": "price_change"}}
{"_local_timestamp": "2026-01-25T23:35:29.126969+00:00", "data": {"market": "0x9d24d9f9b5995949cb158d943793dea20bd448e1b3971cb6f7418bb15e719661", "price_changes": [{"asset_id": "70512916946285526357165287373537570327431985324385225788636160168740471920430", "price": "0.013", "size": "33.91", "side": "SELL", "hash": "6d5f83e6aec0d58db07ba5330a61375cd33cde33", "best_bid": "0.002", "best_ask": "0.013"}, {"asset_id": "79516121807256184736227920754945730465880754940725759201193439378549308939672", "price": "0.987", "size": "33.91", "side": "BUY", "hash": "6587f86e41e42992cebc99ad97d9d5d606497c33", "best_bid": "0.987", "best_ask": "0.998"}], "timestamp": "1769384129054", "event_type": "price_change"}}
{"_local_timestamp": "2026-01-25T23:35:29.151723+00:00", "data": {"market": "0x9d24d9f9b5995949cb158d943793dea20bd448e1b3971cb6f7418bb15e719661", "price_changes": [{"asset_id": "70512916946285526357165287373537570327431985324385225788636160168740471920430", "price": "0.013", "size": "73.91", "side": "SELL", "hash": "716c9433678d918dbe09e5fcfc9ca2ec4b8c16de", "best_bid": "0.002", "best_ask": "0.013"}, {"asset_id": "79516121807256184736227920754945730465880754940725759201193439378549308939672", "price": "0.987", "size": "73.91", "side": "BUY", "hash": "2f34632f3c8d46839b1d38a0786ac013e03751eb", "best_bid": "0.987", "best_ask": "0.998"}], "timestamp": "1769384129085", "event_type": "price_change"}}
{"_local_timestamp": "2026-01-25T23:35:30.629446+00:00", "data": {"market": "0x9d24d9f9b5995949cb158d943793dea20bd448e1b3971cb6f7418bb15e719661", "price_changes": [{"asset_id": "70512916946285526357165287373537570327431985324385225788636160168740471920430", "price": "0.013", "size": "33.91", "side": "SELL", "hash": "9185e37cca58d62065f20597f09f42d142e18a05", "best_bid": "0.002", "best_ask": "0.013"}, {"asset_id": "79516121807256184736227920754945730465880754940725759201193439378549308939672", "price": "0.987", "size": "33.91", "side": "BUY", "hash": "c47d1bdcaa82403fc774221b5ef135e7b5b1ef61", "best_bid": "0.987", "best_ask": "0.998"}], "timestamp": "1769384130554", "event_type": "price_change"}}
{"_local_timestamp": "2026-01-25T23:35:30.664858+00:00", "data": {"market": "0x9d24d9f9b5995949cb158d943793dea20bd448e1b3971cb6f7418bb15e719661", "price_changes": [{"asset_id": "70512916946285526357165287373537570327431985324385225788636160168740471920430", "price": "0.013", "size": "73.91", "side": "SELL", "hash": "b4877830d0090011a0bd2e424d8aab2f87e0bb10", "best_bid": "0.002", "best_ask": "0.013"}, {"asset_id": "79516121807256184736227920754945730465880754940725759201193439378549308939672", "price": "0.987", "size": "73.91", "side": "BUY", "hash": "124022e8c6d6015a9448051d216d4dcdf21497b5", "best_bid": "0.987", "best_ask": "0.998"}], "timestamp": "1769384130581", "event_type": "price_change"}}
{"_local_timestamp": "2026-01-25T23:35:32.137244+00:00", "data": {"market": "0x9d24d9f9b5995949cb158d943793dea20bd448e1b3971cb6f7418bb15e719661", "price_changes": [{"asset_id": "70512916946285526357165287373537570327431985324385225788636160168740471920430", "price": "0.013", "size": "33.91", "side": "SELL", "hash": "40548ec140493a54e9585fe171ac641ebe2c3bef", "best_bid": "0.002", "best_ask": "0.013"}, {"asset_id": "79516121807256184736227920754945730465880754940725759201193439378549308939672", "price": "0.987", "size": "33.91", "side": "BUY", "hash": "509895c6caae327c35a0c4d23278ef3f26611b60", "best_bid": "0.987", "best_ask": "0.998"}], "timestamp": "1769384132066", "event_type": "price_change"}}
{"_local_timestamp": "2026-01-25T23:35:32.167176+00:00", "data": {"market": "0x9d24d9f9b5995949cb158d943793dea20bd448e1b3971cb6f7418bb15e719661", "price_changes": [{"asset_id": "70512916946285526357165287373537570327431985324385225788636160168740471920430", "price": "0.013", "size": "73.91", "side": "SELL", "hash": "a216306fb22614149507fb17ba2411373d382d0c", "best_bid": "0.002", "best_ask": "0.013"}, {"asset_id": "79516121807256184736227920754945730465880754940725759201193439378549308939672", "price": "0.987", "size": "73.91", "side": "BUY", "hash": "2a8bff2b242dd9e914eed79c84d4c76099085039", "best_bid": "0.987", "best_ask": "0.998"}], "timestamp": "1769384132094", "event_type": "price_change"}}
{"_local_timestamp": "2026-01-25T23:35:33.639856+00:00", "data": {"market": "0x9d24d9f9b5995949cb158d943793dea20bd448e1b3971cb6f7418bb15e719661", "price_changes": [{"asset_id": "70512916946285526357165287373537570327431985324385225788636160168740471920430", "price": "0.013", "size": "33.91", "side": "SELL", "hash": "74414f87285be9a8aa3f2e4941719ee634fd7e1e", "best_bid": "0.002", "best_ask": "0.013"}, {"asset_id": "79516121807256184736227920754945730465880754940725759201193439378549308939672", "price": "0.987", "size": "33.91", "side": "BUY", "hash": "7a74cff5a322379a5f8e4b6b9889b624982a8024", "best_bid": "0.987", "best_ask": "0.998"}], "timestamp": "1769384133560", "event_type": "price_change"}}
{"_local_timestamp": "2026-01-25T23:35:33.663236+00:00", "data": {"market": "0x9d24d9f9b5995949cb158d943793dea20bd448e1b3971cb6f7418bb15e719661", "price_changes": [{"asset_id": "70512916946285526357165287373537570327431985324385225788636160168740471920430", "price": "0.013", "size": "73.91", "side": "SELL", "hash": "412f807446a3fcebee663af945929a2b4db02a02", "best_bid": "0.002", "best_ask": "0.013"}, {"asset_id": "79516121807256184736227920754945730465880754940725759201193439378549308939672", "price": "0.987", "size": "73.91", "side": "BUY", "hash": "32abbe3910f0db7b6ad724bb81c2e07dab092a8c", "best_bid": "0.987", "best_ask": "0.998"}], "timestamp": "1769384133586", "event_type": "price_change"}}
{"_local_timestamp": "2026-01-25T23:35:35.181102+00:00", "data": {"market": "0x9d24d9f9b5995949cb158d943793dea20bd448e1b3971cb6f7418bb15e719661", "price_changes": [{"asset_id": "70512916946285526357165287373537570327431985324385225788636160168740471920430", "price": "0.013", "size": "33.91", "side": "SELL", "hash": "bc8732e3534a1df975e7d59d8887f30fe494ec76", "best_bid": "0.002", "best_ask": "0.013"}, {"asset_id": "79516121807256184736227920754945730465880754940725759201193439378549308939672", "price": "0.987", "size": "33.91", "side": "BUY", "hash": "19a931ef1e2c159c55e60125beb937bfe1809c59", "best_bid": "0.987", "best_ask": "0.998"}], "timestamp": "1769384135067", "event_type": "price_change"}}
{"_local_timestamp": "2026-01-25T23:35:35.202498+00:00", "data": {"market": "0x9d24d9f9b5995949cb158d943793dea20bd448e1b3971cb6f7418bb15e719661", "price_changes": [{"asset_id": "70512916946285526357165287373537570327431985324385225788636160168740471920430", "price": "0.013", "size": "73.91", "side": "SELL", "hash": "24365f23c37e439ce796095928de300f94991907", "best_bid": "0.002", "best_ask": "0.013"}, {"asset_id": "79516121807256184736227920754945730465880754940725759201193439378549308939672", "price": "0.987", "size": "73.91", "side": "BUY", "hash": "eec5c77837d2354721b24e54eeb7f8d9a75f3cbe", "best_bid": "0.987", "best_ask": "0.998"}], "timestamp": "1769384135103", "event_type": "price_change"}}
{"_local_timestamp": "2026-01-25T23:35:36.631485+00:00", "data": {"market": "0x9d24d9f9b5995949cb158d943793dea20bd448e1b3971cb6f7418bb15e719661", "price_changes": [{"asset_id": "70512916946285526357165287373537570327431985324385225788636160168740471920430", "price": "0.013", "size": "33.91", "side": "SELL", "hash": "88f26bc5b99248ef5ced8bfe5bc4bf8fbaa153c9", "best_bid": "0.002", "best_ask": "0.013"}, {"asset_id": "79516121807256184736227920754945730465880754940725759201193439378549308939672", "price": "0.987", "size": "33.91", "side": "BUY", "hash": "c15023f76a343feb77957ce7136fe4cfb39b7e67", "best_bid": "0.987", "best_ask": "0.998"}], "timestamp": "1769384136562", "event_type": "price_change"}}
{"_local_timestamp": "2026-01-25T23:35:36.667560+00:00", "data": {"market": "0x9d24d9f9b5995949cb158d943793dea20bd448e1b3971cb6f7418bb15e719661", "price_changes": [{"asset_id": "70512916946285526357165287373537570327431985324385225788636160168740471920430", "price": "0.013", "size": "73.91", "side": "SELL", "hash": "69e79a2166fc1e708976286c2e5fdb0e3037d5f4", "best_bid": "0.002", "best_ask": "0.013"}, {"asset_id": "79516121807256184736227920754945730465880754940725759201193439378549308939672", "price": "0.987", "size": "73.91", "side": "BUY", "hash": "cc623d1b9b37e689d71a7982045a3bd41483e8e4", "best_bid": "0.987", "best_ask": "0.998"}], "timestamp": "1769384136591", "event_type": "price_change"}}
{"_local_timestamp": "2026-01-25T23:35:38.140317+00:00", "data": {"market": "0x9d24d9f9b5995949cb158d943793dea20bd448e1b3971cb6f7418bb15e719661", "price_changes": [{"asset_id": "70512916946285526357165287373537570327431985324385225788636160168740471920430", "price": "0.013", "size": "33.91", "side": "SELL", "hash": "af90d41a634c6f37104546c7c0c7a73aade43358", "best_bid": "0.002", "best_ask": "0.013"}, {"asset_id": "79516121807256184736227920754945730465880754940725759201193439378549308939672", "price": "0.987", "size": "33.91", "side": "BUY", "hash": "9b92c1e7f80234fa3fe77863ac788d79a454be5b", "best_bid": "0.987", "best_ask": "0.998"}], "timestamp": "1769384138069", "event_type": "price_change"}}
{"_local_timestamp": "2026-01-25T23:35:38.166968+00:00", "data": {"market": "0x9d24d9f9b5995949cb158d943793dea20bd448e1b3971cb6f7418bb15e719661", "price_changes": [{"asset_id": "70512916946285526357165287373537570327431985324385225788636160168740471920430", "price": "0.013", "size": "73.91", "side": "SELL", "hash": "aa6ea4bf141321917538bd3ad1ba573639629ca9", "best_bid": "0.002", "best_ask": "0.013"}, {"asset_id": "79516121807256184736227920754945730465880754940725759201193439378549308939672", "price": "0.987", "size": "73.91", "side": "BUY", "hash": "f4e137ca7042d66fa44b3fbe0fc9d96a7755a0af", "best_bid": "0.987", "best_ask": "0.998"}], "timestamp": "1769384138100", "event_type": "price_change"}}
{"_local_timestamp": "2026-01-25T23:35:39.627875+00:00", "data": {"market": "0x9d24d9f9b5995949cb158d943793dea20bd448e1b3971cb6f7418bb15e719661", "price_changes": [{"asset_id": "70512916946285526357165287373537570327431985324385225788636160168740471920430", "price": "0.013", "size": "33.91", "side": "SELL", "hash": "8ccc9a78caeeb111b8f269375395361de6bd12bf", "best_bid": "0.002", "best_ask": "0.013"}, {"asset_id": "79516121807256184736227920754945730465880754940725759201193439378549308939672", "price": "0.987", "size": "33.91", "side": "BUY", "hash": "c1693421ae20dbee08da1b966758010bf884de6d", "best_bid": "0.987", "best_ask": "0.998"}], "timestamp": "1769384139559", "event_type": "price_change"}}
{"_local_timestamp": "2026-01-25T23:35:39.662609+00:00", "data": {"market": "0x9d24d9f9b5995949cb158d943793dea20bd448e1b3971cb6f7418bb15e719661", "price_changes": [{"asset_id": "70512916946285526357165287373537570327431985324385225788636160168740471920430", "price": "0.013", "size": "73.91", "side": "SELL", "hash": "1339708d825cd3aeed6e9fe35b6d1834b2f22dff", "best_bid": "0.002", "best_ask": "0.013"}, {"asset_id": "79516121807256184736227920754945730465880754940725759201193439378549308939672", "price": "0.987", "size": "73.91", "side": "BUY", "hash": "23ae617b991c0f69ea09b230f861ce1952cb034e", "best_bid": "0.987", "best_ask": "0.998"}], "timestamp": "1769384139591", "event_type": "price_change"}}
{"_local_timestamp": "2026-01-25T23:35:41.134640+00:00", "data": {"market": "0x9d24d9f9b5995949cb158d943793dea20bd448e1b3971cb6f7418bb15e719661", "price_changes": [{"asset_id": "70512916946285526357165287373537570327431985324385225788636160168740471920430", "price": "0.013", "size": "33.91", "side": "SELL", "hash": "161461e747b6d3144afe24bbe9afa2dc068ba8eb", "best_bid": "0.002", "best_ask": "0.013"}, {"asset_id": "79516121807256184736227920754945730465880754940725759201193439378549308939672", "price": "0.987", "size": "33.91", "side": "BUY", "hash": "feb6bbc3ababe53a1525e5571eb3520895de9943", "best_bid": "0.987", "best_ask": "0.998"}], "timestamp": "1769384141065", "event_type": "price_change"}}
{"_local_timestamp": "2026-01-25T23:35:41.162426+00:00", "data": {"market": "0x9d24d9f9b5995949cb158d943793dea20bd448e1b3971cb6f7418bb15e719661", "price_changes": [{"asset_id": "70512916946285526357165287373537570327431985324385225788636160168740471920430", "price": "0.013", "size": "73.91", "side": "SELL", "hash": "4240b82fccd208c24e9f5002605f289acc0cb31b", "best_bid": "0.002", "best_ask": "0.013"}, {"asset_id": "79516121807256184736227920754945730465880754940725759201193439378549308939672", "price": "0.987", "size": "73.91", "side": "BUY", "hash": "3b2059bf502f8f139b16e71ff5d717209b87f6c2", "best_bid": "0.987", "best_ask": "0.998"}], "timestamp": "1769384141095", "event_type": "price_change"}}
{"_local_timestamp": "2026-01-25T23:35:42.623427+00:00", "data": {"market": "0x9d24d9f9b5995949cb158d943793dea20bd448e1b3971cb6f7418bb15e719661", "price_changes": [{"asset_id": "70512916946285526357165287373537570327431985324385225788636160168740471920430", "price": "0.013", "size": "33.91", "side": "SELL", "hash": "2cd3cd20a75492256e5ea69d339435ca2d0a0d40", "best_bid": "0.002", "best_ask": "0.013"}, {"asset_id": "79516121807256184736227920754945730465880754940725759201193439378549308939672", "price": "0.987", "size": "33.91", "side": "BUY", "hash": "59e2c84453be8550bf70b494f509f9d643eb9861", "best_bid": "0.987", "best_ask": "0.998"}], "timestamp": "1769384142553", "event_type": "price_change"}}
{"_local_timestamp": "2026-01-25T23:35:42.655401+00:00", "data": {"market": "0x9d24d9f9b5995949cb158d943793dea20bd448e1b3971cb6f7418bb15e719661", "price_changes": [{"asset_id": "70512916946285526357165287373537570327431985324385225788636160168740471920430", "price": "0.013", "size": "73.91", "side": "SELL", "hash": "caa01da521ddd46a9585ef06476e72fdd8dd1f4a", "best_bid": "0.002", "best_ask": "0.013"}, {"asset_id": "79516121807256184736227920754945730465880754940725759201193439378549308939672", "price": "0.987", "size": "73.91", "side": "BUY", "hash": "b30f4d88add6bd20eb6c495425d893fb70d182bc", "best_bid": "0.987", "best_ask": "0.998"}], "timestamp": "1769384142581", "event_type": "price_change"}}
{"_local_timestamp": "2026-01-25T23:35:44.124632+00:00", "data": {"market": "0x9d24d9f9b5995949cb158d943793dea20bd448e1b3971cb6f7418bb15e719661", "price_changes": [{"asset_id": "70512916946285526357165287373537570327431985324385225788636160168740471920430", "price": "0.013", "size": "33.91", "side": "SELL", "hash": "c3d9236845b46395615c1140ed95b6e9e3ac52e2", "best_bid": "0.002", "best_ask": "0.013"}, {"asset_id": "79516121807256184736227920754945730465880754940725759201193439378549308939672", "price": "0.987", "size": "33.91", "side": "BUY", "hash": "09f72debe7392dcb34cb0c2d71fa477133793f7c", "best_bid": "0.987", "best_ask": "0.998"}], "timestamp": "1769384144053", "event_type": "price_change"}}
{"_local_timestamp": "2026-01-25T23:35:44.146105+00:00", "data": {"market": "0x9d24d9f9b5995949cb158d943793dea20bd448e1b3971cb6f7418bb15e719661", "price_changes": [{"asset_id": "70512916946285526357165287373537570327431985324385225788636160168740471920430", "price": "0.013", "size": "73.91", "side": "SELL", "hash": "49d5dc221bbcc5fb2f2ba7616eefae95d902b0a7", "best_bid": "0.002", "best_ask": "0.013"}, {"asset_id": "79516121807256184736227920754945730465880754940725759201193439378549308939672", "price": "0.987", "size": "73.91", "side": "BUY", "hash": "3b277c0cd17ce249b84d4753de9e5ecfb5c038fc", "best_bid": "0.987", "best_ask": "0.998"}], "timestamp": "1769384144078", "event_type": "price_change"}}
{"_local_timestamp": "2026-01-25T23:35:45.624325+00:00", "data": {"market": "0x9d24d9f9b5995949cb158d943793dea20bd448e1b3971cb6f7418bb15e719661", "price_changes": [{"asset_id": "70512916946285526357165287373537570327431985324385225788636160168740471920430", "price": "0.013", "size": "33.91", "side": "SELL", "hash": "0c7c762d2348828b4309a7160c921adad4047dd3", "best_bid": "0.002", "best_ask": "0.013"}, {"asset_id": "79516121807256184736227920754945730465880754940725759201193439378549308939672", "price": "0.987", "size": "33.91", "side": "BUY", "hash": "b6821cdf691452da5509c3a3dc496bf5a29af29f", "best_bid": "0.987", "best_ask": "0.998"}], "timestamp": "1769384145555", "event_type": "price_change"}}
{"_local_timestamp": "2026-01-25T23:35:45.650818+00:00", "data": {"market": "0x9d24d9f9b5995949cb158d943793dea20bd448e1b3971cb6f7418bb15e719661", "price_changes": [{"asset_id": "70512916946285526357165287373537570327431985324385225788636160168740471920430", "price": "0.013", "size": "73.91", "side": "SELL", "hash": "cb6fc041c201a73bea7679028f4f6e7aba50991f", "best_bid": "0.002", "best_ask": "0.013"}, {"asset_id": "79516121807256184736227920754945730465880754940725759201193439378549308939672", "price": "0.987", "size": "73.91", "side": "BUY", "hash": "14f77637d4291cc1ba8b18605be7708d5afedfd8", "best_bid": "0.987", "best_ask": "0.998"}], "timestamp": "1769384145582", "event_type": "price_change"}}
{"_local_timestamp": "2026-01-25T23:35:47.130580+00:00", "data": {"market": "0x9d24d9f9b5995949cb158d943793dea20bd448e1b3971cb6f7418bb15e719661", "price_changes": [{"asset_id": "70512916946285526357165287373537570327431985324385225788636160168740471920430", "price": "0.013", "size": "33.91", "side": "SELL", "hash": "00217d0073d0bfd0dcdc72989214b5b4b66f54c9", "best_bid": "0.002", "best_ask": "0.013"}, {"asset_id": "79516121807256184736227920754945730465880754940725759201193439378549308939672", "price": "0.987", "size": "33.91", "side": "BUY", "hash": "d45079751af998e5683a5ce1dbd54c095464f47e", "best_bid": "0.987", "best_ask": "0.998"}], "timestamp": "1769384147055", "event_type": "price_change"}}
{"_local_timestamp": "2026-01-25T23:35:47.158548+00:00", "data": {"market": "0x9d24d9f9b5995949cb158d943793dea20bd448e1b3971cb6f7418bb15e719661", "price_changes": [{"asset_id": "70512916946285526357165287373537570327431985324385225788636160168740471920430", "price": "0.013", "size": "73.91", "side": "SELL", "hash": "fa6ee63502cdf1b326a0a6ec4b30de2ae0c0b468", "best_bid": "0.002", "best_ask": "0.013"}, {"asset_id": "79516121807256184736227920754945730465880754940725759201193439378549308939672", "price": "0.987", "size": "73.91", "side": "BUY", "hash": "5b94be96259c422721534c4ea4836ddadc6b67f5", "best_bid": "0.987", "best_ask": "0.998"}], "timestamp": "1769384147090", "event_type": "price_change"}}
{"_local_timestamp": "2026-01-25T23:35:48.618781+00:00", "data": {"market": "0x9d24d9f9b5995949cb158d943793dea20bd448e1b3971cb6f7418bb15e719661", "price_changes": [{"asset_id": "70512916946285526357165287373537570327431985324385225788636160168740471920430", "price": "0.013", "size": "33.91", "side": "SELL", "hash": "8e6bbddee2c1545bcf7bd415d558fec560b79190", "best_bid": "0.002", "best_ask": "0.013"}, {"asset_id": "79516121807256184736227920754945730465880754940725759201193439378549308939672", "price": "0.987", "size": "33.91", "side": "BUY", "hash": "affc1c70fae36a9bb149a7bf1617865353dea570", "best_bid": "0.987", "best_ask": "0.998"}], "timestamp": "1769384148553", "event_type": "price_change"}}
{"_local_timestamp": "2026-01-25T23:35:48.654580+00:00", "data": {"market": "0x9d24d9f9b5995949cb158d943793dea20bd448e1b3971cb6f7418bb15e719661", "price_changes": [{"asset_id": "70512916946285526357165287373537570327431985324385225788636160168740471920430", "price": "0.013", "size": "73.91", "side": "SELL", "hash": "badea8dc12864ac7ad560ed5eb6636f8165c5827", "best_bid": "0.002", "best_ask": "0.013"}, {"asset_id": "79516121807256184736227920754945730465880754940725759201193439378549308939672", "price": "0.987", "size": "73.91", "side": "BUY", "hash": "e02707281437defe0b9a828e719cb837373f9691", "best_bid": "0.987", "best_ask": "0.998"}], "timestamp": "1769384148580", "event_type": "price_change"}}
{"_local_timestamp": "2026-01-25T23:35:50.138618+00:00", "data": {"market": "0x9d24d9f9b5995949cb158d943793dea20bd448e1b3971cb6f7418bb15e719661", "price_changes": [{"asset_id": "70512916946285526357165287373537570327431985324385225788636160168740471920430", "price": "0.013", "size": "33.91", "side": "SELL", "hash": "1b0ddba18e5eeedce1261da7c15d5285fb33d228", "best_bid": "0.002", "best_ask": "0.013"}, {"asset_id": "79516121807256184736227920754945730465880754940725759201193439378549308939672", "price": "0.987", "size": "33.91", "side": "BUY", "hash": "7b79edaece7dc753d432bc04a900b29d8a954a9a", "best_bid": "0.987", "best_ask": "0.998"}], "timestamp": "1769384150052", "event_type": "price_change"}}
{"_local_timestamp": "2026-01-25T23:35:50.148848+00:00", "data": {"market": "0x9d24d9f9b5995949cb158d943793dea20bd448e1b3971cb6f7418bb15e719661", "price_changes": [{"asset_id": "70512916946285526357165287373537570327431985324385225788636160168740471920430", "price": "0.013", "size": "73.91", "side": "SELL", "hash": "f518e0591b61217a3633cf6d359dd1e52db6cefd", "best_bid": "0.002", "best_ask": "0.013"}, {"asset_id": "79516121807256184736227920754945730465880754940725759201193439378549308939672", "price": "0.987", "size": "73.91", "side": "BUY", "hash": "3be124e53a9826fa506d8a1d0ade85534209b2be", "best_bid": "0.987", "best_ask": "0.998"}], "timestamp": "1769384150080", "event_type": "price_change"}}
{"_local_timestamp": "2026-01-25T23:35:51.630899+00:00", "data": {"market": "0x9d24d9f9b5995949cb158d943793dea20bd448e1b3971cb6f7418bb15e719661", "price_changes": [{"asset_id": "70512916946285526357165287373537570327431985324385225788636160168740471920430", "price": "0.013", "size": "33.91", "side": "SELL", "hash": "96c1a4ac442e606bf1f2912debd23494fa47a0b9", "best_bid": "0.002", "best_ask": "0.013"}, {"asset_id": "79516121807256184736227920754945730465880754940725759201193439378549308939672", "price": "0.987", "size": "33.91", "side": "BUY", "hash": "d734e01afd419a5f3eb3358b43996d577f344561", "best_bid": "0.987", "best_ask": "0.998"}], "timestamp": "1769384151554", "event_type": "price_change"}}
{"_local_timestamp": "2026-01-25T23:35:51.646108+00:00", "data": {"market": "0x9d24d9f9b5995949cb158d943793dea20bd448e1b3971cb6f7418bb15e719661", "price_changes": [{"asset_id": "70512916946285526357165287373537570327431985324385225788636160168740471920430", "price": "0.013", "size": "73.91", "side": "SELL", "hash": "3020dd856fd2debfcdcd93b71608af3c9cea2078", "best_bid": "0.002", "best_ask": "0.013"}, {"asset_id": "79516121807256184736227920754945730465880754940725759201193439378549308939672", "price": "0.987", "size": "73.91", "side": "BUY", "hash": "9f4949c6c049670fe7ca79c1dc260d05408a458a", "best_bid": "0.987", "best_ask": "0.998"}], "timestamp": "1769384151579", "event_type": "price_change"}}
{"_local_timestamp": "2026-01-25T23:35:53.122849+00:00", "data": {"market": "0x9d24d9f9b5995949cb158d943793dea20bd448e1b3971cb6f7418bb15e719661", "price_changes": [{"asset_id": "70512916946285526357165287373537570327431985324385225788636160168740471920430", "price": "0.013", "size": "33.91", "side": "SELL", "hash": "1aae9cb71730f0f6eab51d8ff132aefdd9960b80", "best_bid": "0.002", "best_ask": "0.013"}, {"asset_id": "79516121807256184736227920754945730465880754940725759201193439378549308939672", "price": "0.987", "size": "33.91", "side": "BUY", "hash": "bb23006e0be0a776f033ee96a2bab800f1e51dfb", "best_bid": "0.987", "best_ask": "0.998"}], "timestamp": "1769384153053", "event_type": "price_change"}}
{"_local_timestamp": "2026-01-25T23:35:53.151356+00:00", "data": {"market": "0x9d24d9f9b5995949cb158d943793dea20bd448e1b3971cb6f7418bb15e719661", "price_changes": [{"asset_id": "70512916946285526357165287373537570327431985324385225788636160168740471920430", "price": "0.013", "size": "73.91", "side": "SELL", "hash": "4053f0513c04fde0d0e1fd8108c2538f9d3e9c74", "best_bid": "0.002", "best_ask": "0.013"}, {"asset_id": "79516121807256184736227920754945730465880754940725759201193439378549308939672", "price": "0.987", "size": "73.91", "side": "BUY", "hash": "21c88fb5e3f51e9c3b80f3c24cf5f17c8589b9f6", "best_bid": "0.987", "best_ask": "0.998"}], "timestamp": "1769384153078", "event_type": "price_change"}}
{"_local_timestamp": "2026-01-25T23:35:54.628067+00:00", "data": {"market": "0x9d24d9f9b5995949cb158d943793dea20bd448e1b3971cb6f7418bb15e719661", "price_changes": [{"asset_id": "70512916946285526357165287373537570327431985324385225788636160168740471920430", "price": "0.013", "size": "33.91", "side": "SELL", "hash": "58dbe837f54de584082e1ae20cd26987407780ab", "best_bid": "0.002", "best_ask": "0.013"}, {"asset_id": "79516121807256184736227920754945730465880754940725759201193439378549308939672", "price": "0.987", "size": "33.91", "side": "BUY", "hash": "c55430f556576202d19fe46041558b92a28e3dd5", "best_bid": "0.987", "best_ask": "0.998"}], "timestamp": "1769384154554", "event_type": "price_change"}}
{"_local_timestamp": "2026-01-25T23:35:54.661494+00:00", "data": {"market": "0x9d24d9f9b5995949cb158d943793dea20bd448e1b3971cb6f7418bb15e719661", "price_changes": [{"asset_id": "70512916946285526357165287373537570327431985324385225788636160168740471920430", "price": "0.013", "size": "73.91", "side": "SELL", "hash": "a32b40f256b3dbd36400f033babdd60610e9c998", "best_bid": "0.002", "best_ask": "0.013"}, {"asset_id": "79516121807256184736227920754945730465880754940725759201193439378549308939672", "price": "0.987", "size": "73.91", "side": "BUY", "hash": "48b3c3b2e192a25f7c19aa89d94a0e4434efe039", "best_bid": "0.987", "best_ask": "0.998"}], "timestamp": "1769384154589", "event_type": "price_change"}}
{"_local_timestamp": "2026-01-25T23:35:56.120224+00:00", "data": {"market": "0x9d24d9f9b5995949cb158d943793dea20bd448e1b3971cb6f7418bb15e719661", "price_changes": [{"asset_id": "70512916946285526357165287373537570327431985324385225788636160168740471920430", "price": "0.013", "size": "33.91", "side": "SELL", "hash": "eb4e4bcffbb1da16c925eb40e2947580eb23d8aa", "best_bid": "0.002", "best_ask": "0.013"}, {"asset_id": "79516121807256184736227920754945730465880754940725759201193439378549308939672", "price": "0.987", "size": "33.91", "side": "BUY", "hash": "6c853abb3f9a425e7d199de89d7879dc78c41198", "best_bid": "0.987", "best_ask": "0.998"}], "timestamp": "1769384156053", "event_type": "price_change"}}
{"_local_timestamp": "2026-01-25T23:35:56.150909+00:00", "data": {"market": "0x9d24d9f9b5995949cb158d943793dea20bd448e1b3971cb6f7418bb15e719661", "price_changes": [{"asset_id": "70512916946285526357165287373537570327431985324385225788636160168740471920430", "price": "0.013", "size": "73.91", "side": "SELL", "hash": "eeb4fc4bbac8ae046cd614e31c6cf50817b2897b", "best_bid": "0.002", "best_ask": "0.013"}, {"asset_id": "79516121807256184736227920754945730465880754940725759201193439378549308939672", "price": "0.987", "size": "73.91", "side": "BUY", "hash": "4f631df2141ffa2bfc81cb81d21c5fc161be4c2b", "best_bid": "0.987", "best_ask": "0.998"}], "timestamp": "1769384156081", "event_type": "price_change"}}
{"_local_timestamp": "2026-01-25T23:35:57.622320+00:00", "data": {"market": "0x9d24d9f9b5995949cb158d943793dea20bd448e1b3971cb6f7418bb15e719661", "price_changes": [{"asset_id": "70512916946285526357165287373537570327431985324385225788636160168740471920430", "price": "0.013", "size": "33.91", "side": "SELL", "hash": "37967b76df6eaa659ab56164890a59ff2e89b5e3", "best_bid": "0.002", "best_ask": "0.013"}, {"asset_id": "79516121807256184736227920754945730465880754940725759201193439378549308939672", "price": "0.987", "size": "33.91", "side": "BUY", "hash": "4961368939442da87d90692aa35c9c6644daf6e8", "best_bid": "0.987", "best_ask": "0.998"}], "timestamp": "1769384157553", "event_type": "price_change"}}
{"_local_timestamp": "2026-01-25T23:35:57.645852+00:00", "data": {"market": "0x9d24d9f9b5995949cb158d943793dea20bd448e1b3971cb6f7418bb15e719661", "price_changes": [{"asset_id": "70512916946285526357165287373537570327431985324385225788636160168740471920430", "price": "0.013", "size": "73.91", "side": "SELL", "hash": "179d493bada52d7995e12ea3a64f3df286aab957", "best_bid": "0.002", "best_ask": "0.013"}, {"asset_id": "79516121807256184736227920754945730465880754940725759201193439378549308939672", "price": "0.987", "size": "73.91", "side": "BUY", "hash": "7c5565f005e68dc0e97854309049553dfa01eab7", "best_bid": "0.987", "best_ask": "0.998"}], "timestamp": "1769384157579", "event_type": "price_change"}}
{"_local_timestamp": "2026-01-25T23:35:59.183835+00:00", "data": {"market": "0x9d24d9f9b5995949cb158d943793dea20bd448e1b3971cb6f7418bb15e719661", "price_changes": [{"asset_id": "70512916946285526357165287373537570327431985324385225788636160168740471920430", "price": "0.013", "size": "33.91", "side": "SELL", "hash": "a5967a0d2de24e8883e4b240f13c0d403d972a99", "best_bid": "0.002", "best_ask": "0.013"}, {"asset_id": "79516121807256184736227920754945730465880754940725759201193439378549308939672", "price": "0.987", "size": "33.91", "side": "BUY", "hash": "8feebb543a6c2daa6b2177d01d5bdab59db4c52b", "best_bid": "0.987", "best_ask": "0.998"}], "timestamp": "1769384159061", "event_type": "price_change"}}
{"_local_timestamp": "2026-01-25T23:35:59.195963+00:00", "data": {"market": "0x9d24d9f9b5995949cb158d943793dea20bd448e1b3971cb6f7418bb15e719661", "price_changes": [{"asset_id": "70512916946285526357165287373537570327431985324385225788636160168740471920430", "price": "0.013", "size": "73.91", "side": "SELL", "hash": "cbe476d63b43ad58efb635b78018467b714ffa27", "best_bid": "0.002", "best_ask": "0.013"}, {"asset_id": "79516121807256184736227920754945730465880754940725759201193439378549308939672", "price": "0.987", "size": "73.91", "side": "BUY", "hash": "dd8d3a489c68f39ce21a805941afbc1b6b9b3f7c", "best_bid": "0.987", "best_ask": "0.998"}], "timestamp": "1769384159088", "event_type": "price_change"}}
{"_local_timestamp": "2026-01-25T23:36:00.628398+00:00", "data": {"market": "0x9d24d9f9b5995949cb158d943793dea20bd448e1b3971cb6f7418bb15e719661", "price_changes": [{"asset_id": "70512916946285526357165287373537570327431985324385225788636160168740471920430", "price": "0.013", "size": "33.91", "side": "SELL", "hash": "f323ed41c4964d44d39b1474e96faa1275a8fa83", "best_bid": "0.002", "best_ask": "0.013"}, {"asset_id": "79516121807256184736227920754945730465880754940725759201193439378549308939672", "price": "0.987", "size": "33.91", "side": "BUY", "hash": "a5d1b3e6344ca90e7e668106dd6dbd01403f4313", "best_bid": "0.987", "best_ask": "0.998"}], "timestamp": "1769384160559", "event_type": "price_change"}}
{"_local_timestamp": "2026-01-25T23:36:00.653965+00:00", "data": {"market": "0x9d24d9f9b5995949cb158d943793dea20bd448e1b3971cb6f7418bb15e719661", "price_changes": [{"asset_id": "70512916946285526357165287373537570327431985324385225788636160168740471920430", "price": "0.013", "size": "73.91", "side": "SELL", "hash": "98c731d4d3b4cab8846f75ed37828e9b8c7b7e0d", "best_bid": "0.002", "best_ask": "0.013"}, {"asset_id": "79516121807256184736227920754945730465880754940725759201193439378549308939672", "price": "0.987", "size": "73.91", "side": "BUY", "hash": "ac8c91afb1b174b9575af06f6e8bd32c75fc22c7", "best_bid": "0.987", "best_ask": "0.998"}], "timestamp": "1769384160587", "event_type": "price_change"}}
{"_local_timestamp": "2026-01-25T23:36:02.156302+00:00", "data": {"market": "0x9d24d9f9b5995949cb158d943793dea20bd448e1b3971cb6f7418bb15e719661", "price_changes": [{"asset_id": "70512916946285526357165287373537570327431985324385225788636160168740471920430", "price": "0.013", "size": "33.91", "side": "SELL", "hash": "66b85a52249c7e6be34cd8090e0e290998274052", "best_bid": "0.002", "best_ask": "0.013"}, {"asset_id": "79516121807256184736227920754945730465880754940725759201193439378549308939672", "price": "0.987", "size": "33.91", "side": "BUY", "hash": "b63f3d6927ecb2d1ce6f09eee5f6b9b6208907eb", "best_bid": "0.987", "best_ask": "0.998"}], "timestamp": "1769384162071", "event_type": "price_change"}}
{"_local_timestamp": "2026-01-25T23:36:02.170008+00:00", "data": {"market": "0x9d24d9f9b5995949cb158d943793dea20bd448e1b3971cb6f7418bb15e719661", "price_changes": [{"asset_id": "70512916946285526357165287373537570327431985324385225788636160168740471920430", "price": "0.013", "size": "73.91", "side": "SELL", "hash": "30688d6f5522e4cf5336ff95514bd8dfd3d98142", "best_bid": "0.002", "best_ask": "0.013"}, {"asset_id": "79516121807256184736227920754945730465880754940725759201193439378549308939672", "price": "0.987", "size": "73.91", "side": "BUY", "hash": "e08198449298dde08ad0b3991f5e32e065473d46", "best_bid": "0.987", "best_ask": "0.998"}], "timestamp": "1769384162097", "event_type": "price_change"}}
{"_local_timestamp": "2026-01-25T23:36:03.621537+00:00", "data": {"market": "0x9d24d9f9b5995949cb158d943793dea20bd448e1b3971cb6f7418bb15e719661", "price_changes": [{"asset_id": "70512916946285526357165287373537570327431985324385225788636160168740471920430", "price": "0.013", "size": "33.91", "side": "SELL", "hash": "93d97b229414b8615c94b9eab0bb8efe4c2367c1", "best_bid": "0.002", "best_ask": "0.013"}, {"asset_id": "79516121807256184736227920754945730465880754940725759201193439378549308939672", "price": "0.987", "size": "33.91", "side": "BUY", "hash": "d1300b40497c9958b94e4c20f8b8c2cbf26ad78b", "best_bid": "0.987", "best_ask": "0.998"}], "timestamp": "1769384163555", "event_type": "price_change"}}
{"_local_timestamp": "2026-01-25T23:36:03.667282+00:00", "data": {"market": "0x9d24d9f9b5995949cb158d943793dea20bd448e1b3971cb6f7418bb15e719661", "price_changes": [{"asset_id": "70512916946285526357165287373537570327431985324385225788636160168740471920430", "price": "0.013", "size": "73.91", "side": "SELL", "hash": "a2e1d916ebec3a993ec271fbbecb556f73148222", "best_bid": "0.002", "best_ask": "0.013"}, {"asset_id": "79516121807256184736227920754945730465880754940725759201193439378549308939672", "price": "0.987", "size": "73.91", "side": "BUY", "hash": "8ff11e6a2c0304c93c099307a5d8bc236f9adc4d", "best_bid": "0.987", "best_ask": "0.998"}], "timestamp": "1769384163586", "event_type": "price_change"}}
{"_local_timestamp": "2026-01-25T23:36:04.191363+00:00", "data": {"market": "0xc0e6b917320a47228fb96e3b5ae0e5c93773a5ae2662ae4e1f37807cfe47ce98", "price_changes": [{"asset_id": "58656358377246279051017109359677190749228949103591068167284263961542487110215", "price": "0.006", "size": "132.58", "side": "BUY", "hash": "627f8545521494bcc43ccef742e5ce09fcb56e1e", "best_bid": "0.021", "best_ask": "0.034"}, {"asset_id": "81647294538046680798858716589766492074338758116170717123345952330712416337530", "price": "0.994", "size": "132.58", "side": "SELL", "hash": "59d491d36d29f4a3e48ef7e6b60ea3705fff4034", "best_bid": "0.966", "best_ask": "0.979"}], "timestamp": "1769384164123", "event_type": "price_change"}}
{"_local_timestamp": "2026-01-25T23:36:04.569592+00:00", "data": {"market": "0xc0e6b917320a47228fb96e3b5ae0e5c93773a5ae2662ae4e1f37807cfe47ce98", "price_changes": [{"asset_id": "58656358377246279051017109359677190749228949103591068167284263961542487110215", "price": "0.006", "size": "217.57", "side": "BUY", "hash": "4c1f088767418f1723ffd3ae6b93e657cec0128d", "best_bid": "0.021", "best_ask": "0.034"}, {"asset_id": "81647294538046680798858716589766492074338758116170717123345952330712416337530", "price": "0.994", "size": "217.57", "side": "SELL", "hash": "e5a1d3bc7c92a9f5b63e15900486726e5feba29d", "best_bid": "0.966", "best_ask": "0.979"}], "timestamp": "1769384164502", "event_type": "price_change"}}
{"_local_timestamp": "2026-01-25T23:36:05.125539+00:00", "data": {"market": "0x9d24d9f9b5995949cb158d943793dea20bd448e1b3971cb6f7418bb15e719661", "price_changes": [{"asset_id": "70512916946285526357165287373537570327431985324385225788636160168740471920430", "price": "0.013", "size": "33.91", "side": "SELL", "hash": "755e23ed98bde26ab520c3b58c6dd3b9a82c29ef", "best_bid": "0.002", "best_ask": "0.013"}, {"asset_id": "79516121807256184736227920754945730465880754940725759201193439378549308939672", "price": "0.987", "size": "33.91", "side": "BUY", "hash": "9a21f0af175379b7bd083ae0a4f3edc0837014cf", "best_bid": "0.987", "best_ask": "0.998"}], "timestamp": "1769384165054", "event_type": "price_change"}}
