{"_local_timestamp": "2026-01-25T23:41:27.490688+00:00", "data": [{"market": "0x360b5ab61e12806d96430a792f43d4c38fa7a33345c7c99db897accb59983db6", "asset_id": "101138268140267284344946310498458459688833372731909500410366045847576281737159", "timestamp": "1769384486676", "hash": "6687a385a471256e2f782c32549e31b78fbbc83a", "bids": [{"price": "0.01", "size": "9460.39"}, {"price": "0.02", "size": "4200"}, {"price": "0.03", "size": "7.36"}, {"price": "0.04", "size": "750"}, {"price": "0.05", "size": "100"}, {"price": "0.06", "size": "133"}, {"price": "0.08", "size": "850"}, {"price": "0.09", "size": "7.5"}, {"price": "0.12", "size": "833.33"}, {"price": "0.16", "size": "200"}, {"price": "0.17", "size": "1390"}, {"price": "0.2", "size": "140"}, {"price": "0.25", "size": "204"}, {"price": "0.26", "size": "1864"}, {"price": "0.27", "size": "57"}, {"price": "0.29", "size": "82.75"}, {"price": "0.33", "size": "60.6"}, {"price": "0.34", "size": "175"}, {"price": "0.42", "size": "30.95"}, {"price": "0.46", "size": "23.91"}, {"price": "0.48", "size": "250"}, {"price": "0.5", "size": "1276.23"}, {"price": "0.53", "size": "250"}, {"price": "0.55", "size": "5"}, {"price": "0.57", "size": "30"}, {"price": "0.58", "size": "250"}, {"price": "0.63", "size": "171.24"}, {"price": "0.67", "size": "200"}, {"price": "0.68", "size": "25"}, {"price": "0.75", "size": "20"}, {"price": "0.76", "size": "56"}, {"price": "0.77", "size": "868"}, {"price": "0.78", "size": "120"}, {"price": "0.79", "size": "1007"}, {"price": "0.8", "size": "1638.09"}], "asks": [{"price": "0.99", "size": "10662.65"}, {"price": "0.98", "size": "856.65"}, {"price": "0.97", "size": "13.93"}, {"price": "0.96", "size": "325"}, {"price": "0.95", "size": "1221"}, {"price": "0.94", "size": "700"}, {"price": "0.93", "size": "1259.26"}, {"price": "0.92", "size": "1687.33"}, {"price": "0.91", "size": "2247.36"}, {"price": "0.9", "size": "298.25"}, {"price": "0.89", "size": "5680"}, {"price": "0.88", "size": "5204"}, {"price": "0.87", "size": "1111"}, {"price": "0.85", "size": "793.67"}, {"price": "0.84", "size": "1249"}, {"price": "0.83", "size": "2237"}, {"price": "0.82", "size": "250.32"}], "event_type": "book", "last_trade_price": "0.800"}, {"market": "0xd2cf2ac9bf4caf3995f8d8ff4649688430c6733df13ab2d03e3e0756f36f2acb", "asset_id": "8865170260028111071866974003576531745326850065489847482638010827443159829381", "timestamp": "1769384469802", "hash": "3e123d20ab264c6dea9387cc107ce27de7c3c65b", "bids": [{"price": "0.01", "size": "8955.18"}, {"price": "0.02", "size": "3450"}, {"price": "0.03", "size": "10.24"}, {"price": "0.04", "size": "500"}, {"price": "0.05", "size": "20"}, {"price": "0.06", "size": "600"}, {"price": "0.09", "size": "777.77"}, {"price": "0.1", "size": "6.41"}, {"price": "0.11", "size": "290.9"}, {"price": "0.12", "size": "100"}, {"price": "0.14", "size": "200"}, {"price": "0.15", "size": "1666"}, {"price": "0.16", "size": "150"}, {"price": "0.17", "size": "2822.94"}, {"price": "0.18", "size": "100"}, {"price": "0.2", "size": "150"}, {"price": "0.23", "size": "86.95"}, {"price": "0.25", "size": "200"}, {"price": "0.26", "size": "1150"}, {"price": "0.27", "size": "150"}, {"price": "0.28", "size": "7"}, {"price": "0.3", "size": "18"}, {"price": "0.38", "size": "20"}, {"price": "0.39", "size": "20"}, {"price": "0.4", "size": "18"}, {"price": "0.44", "size": "12"}, {"price": "0.45", "size": "20"}, {"price": "0.46", "size": "20"}, {"price": "0.47", "size": "20"}, {"price": "0.48", "size": "20"}, {"price": "0.51", "size": "408.2"}, {"price": "0.52", "size": "200"}, {"price": "0.53", "size": "23.87"}, {"price": "0.58", "size": "366"}, {"price": "0.59", "size": "220.77"}], "asks": [{"price": "0.99", "size": "45808.4"}, {"price": "0.98", "size": "1500"}, {"price": "0.97", "size": "9.59"}, {"price": "0.96", "size": "2400"}, {"price": "0.95", "size": "70"}, {"price": "0.94", "size": "216.66"}, {"price": "0.93", "size": "1085.71"}, {"price": "0.91", "size": "355.55"}, {"price": "0.9", "size": "6.28"}, {"price": "0.89", "size": "254.54"}, {"price": "0.88", "size": "4141.66"}, {"price": "0.87", "size": "1516"}, {"price": "0.86", "size": "185.71"}, {"price": "0.84", "size": "300"}, {"price": "0.82", "size": "111.11"}, {"price": "0.81", "size": "10"}, {"price": "0.78", "size": "10"}, {"price": "0.75", "size": "20015"}, {"price": "0.74", "size": "381"}, {"price": "0.72", "size": "10"}, {"price": "0.71", "size": "20"}, {"price": "0.7", "size": "20"}, {"price": "0.69", "size": "10"}, {"price": "0.66", "size": "2000"}, {"price": "0.65", "size": "243.74"}, {"price": "0.64", "size": "10"}, {"price": "0.63", "size": "1288"}, {"price": "0.62", "size": "1995.89"}, {"price": "0.61", "size": "65.71"}], "event_type": "book", "last_trade_price": "0.580"}, {"market": "0xeb0f640f8e6979495efb462bca18e491a8624c07aecd89b9cea0ba62a4164226", "asset_id": "67044993355929871917109997788450094017244283163136736213822945937563487769385", "timestamp": "1769384477512", "hash": "91a01ce935c84d294170339b05f100cd76494d88", "bids": [{"price": "0.01", "size": "24807.76"}, {"price": "0.02", "size": "2050"}, {"price": "0.03", "size": "3140.58"}, {"price": "0.05", "size": "20"}, {"price": "0.07", "size": "10.35"}, {"price": "0.08", "size": "200"}, {"price": "0.09", "size": "523"}, {"price": "0.18", "size": "72.22"}, {"price": "0.19", "size": "40.6"}, {"price": "0.2", "size": "1030"}, {"price": "0.21", "size": "815"}, {"price": "0.22", "size": "57"}, {"price": "0.23", "size": "355.48"}, {"price": "0.24", "size": "1630"}, {"price": "0.25", "size": "1306.02"}], "asks": [{"price": "0.99", "size": "6409.79"}, {"price": "0.98", "size": "2700"}, {"price": "0.97", "size": "100"}, {"price": "0.96", "size": "6.87"}, {"price": "0.95", "size": "80"}, {"price": "0.93", "size": "1414.28"}, {"price": "0.9", "size": "21"}, {"price": "0.89", "size": "314.78"}, {"price": "0.88", "size": "550"}, {"price": "0.85", "size": "213.33"}, {"price": "0.82", "size": "1188"}, {"price": "0.81", "size": "197.36"}, {"price": "0.8", "size": "150"}, {"price": "0.77", "size": "213.04"}, {"price": "0.74", "size": "92.3"}, {"price": "0.7", "size": "316.66"}, {"price": "0.6", "size": "185"}, {"price": "0.56", "size": "10"}, {"price": "0.52", "size": "10"}, {"price": "0.48", "size": "10"}, {"price": "0.42", "size": "10"}, {"price": "0.39", "size": "21.31"}, {"price": "0.38", "size": "17.74"}, {"price": "0.37", "size": "10"}, {"price": "0.35", "size": "77.75"}, {"price": "0.34", "size": "516"}, {"price": "0.32", "size": "200"}, {"price": "0.31", "size": "10"}, {"price": "0.29", "size": "10"}, {"price": "0.28", "size": "1208.99"}, {"price": "0.27", "size": "6541.39"}, {"price": "0.26", "size": "786.79"}], "event_type": "book", "last_trade_price": "0.260"}, {"market": "0x5a4bae5b326d8ad4ef51e29b140afd57dc1dfb3c44e1c805209eacb65a656dd7", "asset_id": "86247848522476811956744818668364574835142715064162362411756221076437767369255", "timestamp": "1769384468831", "hash": "a2cb55544f2e7532827d55a786f22426e14d01cc", "bids": [{"price": "0.01", "size": "8309.66"}, {"price": "0.02", "size": "3450"}, {"price": "0.03", "size": "10.73"}, {"price": "0.04", "size": "900"}, {"price": "0.05", "size": "20"}, {"price": "0.06", "size": "1166.66"}, {"price": "0.08", "size": "400"}, {"price": "0.09", "size": "6.46"}, {"price": "0.1", "size": "280"}, {"price": "0.11", "size": "236.36"}, {"price": "0.12", "size": "4050"}, {"price": "0.13", "size": "184.61"}, {"price": "0.15", "size": "143.33"}, {"price": "0.2", "size": "527.8"}, {"price": "0.21", "size": "967.74"}, {"price": "0.24", "size": "32"}, {"price": "0.25", "size": "30"}, {"price": "0.26", "size": "28"}, {"price": "0.27", "size": "26"}, {"price": "0.28", "size": "24"}, {"price": "0.29", "size": "22"}, {"price": "0.3", "size": "20"}, {"price": "0.31", "size": "13"}, {"price": "0.32", "size": "32"}, {"price": "0.33", "size": "176"}, {"price": "0.34", "size": "1200"}, {"price": "0.35", "size": "200"}, {"price": "0.36", "size": "705.46"}, {"price": "0.37", "size": "1385"}, {"price": "0.38", "size": "1169.05"}], "asks": [{"price": "0.99", "size": "6410.41"}, {"price": "0.98", "size": "2800"}, {"price": "0.97", "size": "5.69"}, {"price": "0.95", "size": "80"}, {"price": "0.94", "size": "1500"}, {"price": "0.9", "size": "340"}, {"price": "0.89", "size": "6.59"}, {"price": "0.87", "size": "246.15"}, {"price": "0.85", "size": "1616"}, {"price": "0.84", "size": "175"}, {"price": "0.83", "size": "2920"}, {"price": "0.81", "size": "136.84"}, {"price": "0.78", "size": "409.09"}, {"price": "0.74", "size": "126.92"}, {"price": "0.73", "size": "50"}, {"price": "0.64", "size": "550"}, {"price": "0.63", "size": "540"}, {"price": "0.62", "size": "1300"}, {"price": "0.6", "size": "1168.5"}, {"price": "0.59", "size": "603"}, {"price": "0.58", "size": "26.19"}, {"price": "0.55", "size": "5"}, {"price": "0.54", "size": "708.8"}, {"price": "0.53", "size": "600.1"}, {"price": "0.5", "size": "1364"}, {"price": "0.48", "size": "50"}, {"price": "0.47", "size": "117"}, {"price": "0.44", "size": "106"}, {"price": "0.41", "size": "68"}, {"price": "0.4", "size": "3095"}, {"price": "0.39", "size": "4170.41"}], "event_type": "book", "last_trade_price": "0.390"}, {"market": "0xeb0f640f8e6979495efb462bca18e491a8624c07aecd89b9cea0ba62a4164226", "asset_id": "45834992705311952325019110769074251045520613427860944634211713333639342925215", "timestamp": "1769384477512", "hash": "3d99134e4b83b43f11599f5ba442830de70fe8c2", "bids": [{"price": "0.01", "size": "6409.79"}, {"price": "0.02", "size": "2700"}, {"price": "0.03", "size": "100"}, {"price": "0.04", "size": "6.87"}, {"price": "0.05", "size": "80"}, {"price": "0.07", "size": "1414.28"}, {"price": "0.1", "size": "21"}, {"price": "0.11", "size": "314.78"}, {"price": "0.12", "size": "550"}, {"price": "0.15", "size": "213.33"}, {"price": "0.18", "size": "1188"}, {"price": "0.19", "size": "197.36"}, {"price": "0.2", "size": "150"}, {"price": "0.23", "size": "213.04"}, {"price": "0.26", "size": "92.3"}, {"price": "0.3", "size": "316.66"}, {"price": "0.4", "size": "185"}, {"price": "0.44", "size": "10"}, {"price": "0.48", "size": "10"}, {"price": "0.52", "size": "10"}, {"price": "0.58", "size": "10"}, {"price": "0.61", "size": "21.31"}, {"price": "0.62", "size": "17.74"}, {"price": "0.63", "size": "10"}, {"price": "0.65", "size": "77.75"}, {"price": "0.66", "size": "516"}, {"price": "0.68", "size": "200"}, {"price": "0.69", "size": "10"}, {"price": "0.71", "size": "10"}, {"price": "0.72", "size": "1208.99"}, {"price": "0.73", "size": "6541.39"}, {"price": "0.74", "size": "786.79"}], "asks": [{"price": "0.99", "size": "24807.76"}, {"price": "0.98", "size": "2050"}, {"price": "0.97", "size": "3140.58"}, {"price": "0.95", "size": "20"}, {"price": "0.93", "size": "10.35"}, {"price": "0.92", "size": "200"}, {"price": "0.91", "size": "523"}, {"price": "0.82", "size": "72.22"}, {"price": "0.81", "size": "40.6"}, {"price": "0.8", "size": "1030"}, {"price": "0.79", "size": "815"}, {"price": "0.78", "size": "57"}, {"price": "0.77", "size": "355.48"}, {"price": "0.76", "size": "1630"}, {"price": "0.75", "size": "1306.02"}], "event_type": "book", "last_trade_price": "0.260"}, {"market": "0xd2cf2ac9bf4caf3995f8d8ff4649688430c6733df13ab2d03e3e0756f36f2acb", "asset_id": "112139909108928670085933588651092403343948617179385187166440073666455678398436", "timestamp": "1769384469802", "hash": "4567a6b371ec980d859634ce02edbc10dd244ea4", "bids": [{"price": "0.01", "size": "45808.4"}, {"price": "0.02", "size": "1500"}, {"price": "0.03", "size": "9.59"}, {"price": "0.04", "size": "2400"}, {"price": "0.05", "size": "70"}, {"price": "0.06", "size": "216.66"}, {"price": "0.07", "size": "1085.71"}, {"price": "0.09", "size": "355.55"}, {"price": "0.1", "size": "6.28"}, {"price": "0.11", "size": "254.54"}, {"price": "0.12", "size": "4141.66"}, {"price": "0.13", "size": "1516"}, {"price": "0.14", "size": "185.71"}, {"price": "0.16", "size": "300"}, {"price": "0.18", "size": "111.11"}, {"price": "0.19", "size": "10"}, {"price": "0.22", "size": "10"}, {"price": "0.25", "size": "20015"}, {"price": "0.26", "size": "381"}, {"price": "0.28", "size": "10"}, {"price": "0.29", "size": "20"}, {"price": "0.3", "size": "20"}, {"price": "0.31", "size": "10"}, {"price": "0.34", "size": "2000"}, {"price": "0.35", "size": "243.74"}, {"price": "0.36", "size": "10"}, {"price": "0.37", "size": "1288"}, {"price": "0.38", "size": "1995.89"}, {"price": "0.39", "size": "65.71"}], "asks": [{"price": "0.99", "size": "8955.18"}, {"price": "0.98", "size": "3450"}, {"price": "0.97", "size": "10.24"}, {"price": "0.96", "size": "500"}, {"price": "0.95", "size": "20"}, {"price": "0.94", "size": "600"}, {"price": "0.91", "size": "777.77"}, {"price": "0.9", "size": "6.41"}, {"price": "0.89", "size": "290.9"}, {"price": "0.88", "size": "100"}, {"price": "0.86", "size": "200"}, {"price": "0.85", "size": "1666"}, {"price": "0.84", "size": "150"}, {"price": "0.83", "size": "2822.94"}, {"price": "0.82", "size": "100"}, {"price": "0.8", "size": "150"}, {"price": "0.77", "size": "86.95"}, {"price": "0.75", "size": "200"}, {"price": "0.74", "size": "1150"}, {"price": "0.73", "size": "150"}, {"price": "0.72", "size": "7"}, {"price": "0.7", "size": "18"}, {"price": "0.62", "size": "20"}, {"price": "0.61", "size": "20"}, {"price": "0.6", "size": "18"}, {"price": "0.56", "size": "12"}, {"price": "0.55", "size": "20"}, {"price": "0.54", "size": "20"}, {"price": "0.53", "size": "20"}, {"price": "0.52", "size": "20"}, {"price": "0.49", "size": "408.2"}, {"price": "0.48", "size": "200"}, {"price": "0.47", "size": "23.87"}, {"price": "0.42", "size": "366"}, {"price": "0.41", "size": "220.77"}], "event_type": "book", "last_trade_price": "0.580"}, {"market": "0x360b5ab61e12806d96430a792f43d4c38fa7a33345c7c99db897accb59983db6", "asset_id": "26609800537692465524771607284115123570169751799662193302165096740333425504635", "timestamp": "1769384486676", "hash": "f066d76859c2e09e9c37e0fcf6c9a8d28fb4b097", "bids": [{"price": "0.01", "size": "10662.65"}, {"price": "0.02", "size": "856.65"}, {"price": "0.03", "size": "13.93"}, {"price": "0.04", "size": "325"}, {"price": "0.05", "size": "1221"}, {"price": "0.06", "size": "700"}, {"price": "0.07", "size": "1259.26"}, {"price": "0.08", "size": "1687.33"}, {"price": "0.09", "size": "2247.36"}, {"price": "0.1", "size": "298.25"}, {"price": "0.11", "size": "5680"}, {"price": "0.12", "size": "5204"}, {"price": "0.13", "size": "1111"}, {"price": "0.15", "size": "793.67"}, {"price": "0.16", "size": "1249"}, {"price": "0.17", "size": "2237"}, {"price": "0.18", "size": "250.32"}], "asks": [{"price": "0.99", "size": "9460.39"}, {"price": "0.98", "size": "4200"}, {"price": "0.97", "size": "7.36"}, {"price": "0.96", "size": "750"}, {"price": "0.95", "size": "100"}, {"price": "0.94", "size": "133"}, {"price": "0.92", "size": "850"}, {"price": "0.91", "size": "7.5"}, {"price": "0.88", "size": "833.33"}, {"price": "0.84", "size": "200"}, {"price": "0.83", "size": "1390"}, {"price": "0.8", "size": "140"}, {"price": "0.75", "size": "204"}, {"price": "0.74", "size": "1864"}, {"price": "0.73", "size": "57"}, {"price": "0.71", "size": "82.75"}, {"price": "0.67", "size": "60.6"}, {"price": "0.66", "size": "175"}, {"price": "0.58", "size": "30.95"}, {"price": "0.54", "size": "23.91"}, {"price": "0.52", "size": "250"}, {"price": "0.5", "size": "1276.23"}, {"price": "0.47", "size": "250"}, {"price": "0.45", "size": "5"}, {"price": "0.43", "size": "30"}, {"price": "0.42", "size": "250"}, {"price": "0.37", "size": "171.24"}, {"price": "0.33", "size": "200"}, {"price": "0.32", "size": "25"}, {"price": "0.25", "size": "20"}, {"price": "0.24", "size": "56"}, {"price": "0.23", "size": "868"}, {"price": "0.22", "size": "120"}, {"price": "0.21", "size": "1007"}, {"price": "0.2", "size": "1638.09"}], "event_type": "book", "last_trade_price": "0.800"}, {"market": "0x8f055b9db0a2d64b59b33e03bc8885f05a7c5116b3e2b6bb458011d6e18fb5d0", "asset_id": "61714042345592991242650283207041161607044873748774685082589583786302809304151", "timestamp": "1769384484002", "hash": "42a90c077e8e722c36741e07ffe15af72e9e0dcf", "bids": [{"price": "0.001", "size": "1030609.99"}, {"price": "0.002", "size": "1678.27"}, {"price": "0.003", "size": "20010.13"}, {"price": "0.004", "size": "11.35"}, {"price": "0.005", "size": "55659"}, {"price": "0.006", "size": "11691.23"}, {"price": "0.007", "size": "20"}, {"price": "0.008", "size": "5.52"}, {"price": "0.01", "size": "1856.68"}, {"price": "0.011", "size": "3007.3"}, {"price": "0.012", "size": "3500"}, {"price": "0.013", "size": "20"}, {"price": "0.014", "size": "6562.52"}, {"price": "0.015", "size": "3267.33"}, {"price": "0.017", "size": "6849.68"}, {"price": "0.018", "size": "33164.55"}, {"price": "0.02", "size": "820"}, {"price": "0.021", "size": "1334"}, {"price": "0.023", "size": "5792.39"}, {"price": "0.024", "size": "924.68"}, {"price": "0.027", "size": "575"}, {"price": "0.028", "size": "571"}, {"price": "0.03", "size": "330"}, {"price": "0.031", "size": "452"}, {"price": "0.032", "size": "8.82"}, {"price": "0.033", "size": "175"}, {"price": "0.035", "size": "142.85"}, {"price": "0.036", "size": "648.23"}, {"price": "0.037", "size": "423"}, {"price": "0.039", "size": "1064.71"}, {"price": "0.04", "size": "2347"}, {"price": "0.042", "size": "260"}, {"price": "0.043", "size": "163"}, {"price": "0.045", "size": "1220"}, {"price": "0.047", "size": "250"}, {"price": "0.048", "size": "490.81"}, {"price": "0.05", "size": "2200"}, {"price": "0.051", "size": "300"}, {"price": "0.052", "size": "300"}, {"price": "0.055", "size": "25"}], "asks": [{"price": "0.999", "size": "5931.07"}, {"price": "0.998", "size": "5.04"}, {"price": "0.997", "size": "1000"}, {"price": "0.996", "size": "20.44"}, {"price": "0.99", "size": "9450"}, {"price": "0.989", "size": "500"}, {"price": "0.98", "size": "3950"}, {"price": "0.979", "size": "12.96"}, {"price": "0.96", "size": "750"}, {"price": "0.95", "size": "100"}, {"price": "0.94", "size": "33"}, {"price": "0.91", "size": "800"}, {"price": "0.909", "size": "6.93"}, {"price": "0.878", "size": "550"}, {"price": "0.86", "size": "242.85"}, {"price": "0.81", "size": "168.42"}, {"price": "0.8", "size": "13500"}, {"price": "0.799", "size": "796"}, {"price": "0.76", "size": "216.66"}, {"price": "0.71", "size": "89.65"}, {"price": "0.7", "size": "3250"}, {"price": "0.67", "size": "72.72"}, {"price": "0.66", "size": "50"}, {"price": "0.62", "size": "52.63"}, {"price": "0.55", "size": "100"}, {"price": "0.549", "size": "1330"}, {"price": "0.548", "size": "5"}, {"price": "0.49", "size": "100"}, {"price": "0.09", "size": "40"}, {"price": "0.08", "size": "120"}, {"price": "0.078", "size": "120"}, {"price": "0.075", "size": "200"}, {"price": "0.07", "size": "3291.68"}, {"price": "0.068", "size": "250"}, {"price": "0.067", "size": "1114.38"}, {"price": "0.064", "size": "512"}, {"price": "0.063", "size": "100"}, {"price": "0.06", "size": "100"}], "event_type": "book", "last_trade_price": "0.945"}, {"market": "0x3da8ac5a617e2b32fbda49cbc5060917ab770abe9f74b11ffa36dcdb5b7a1195", "asset_id": "83722296194861509737807492105325276806804014660137138811708463053968062687084", "timestamp": "1769384486001", "hash": "a478b9b4b9ecc8071e8f0b9e26faf70f143f08c0", "bids": [{"price": "0.01", "size": "45007.47"}, {"price": "0.02", "size": "1250"}, {"price": "0.03", "size": "7.5"}, {"price": "0.05", "size": "100"}, {"price": "0.06", "size": "11.66"}, {"price": "0.09", "size": "10"}, {"price": "0.1", "size": "3220"}, {"price": "0.11", "size": "500"}, {"price": "0.12", "size": "34"}, {"price": "0.15", "size": "86.66"}, {"price": "0.17", "size": "20"}, {"price": "0.18", "size": "622"}, {"price": "0.19", "size": "1588.61"}, {"price": "0.2", "size": "2725"}, {"price": "0.21", "size": "1534.85"}], "asks": [{"price": "0.99", "size": "6414.28"}, {"price": "0.98", "size": "3200"}, {"price": "0.97", "size": "100"}, {"price": "0.96", "size": "6.51"}, {"price": "0.95", "size": "20"}, {"price": "0.92", "size": "1150"}, {"price": "0.9", "size": "20"}, {"price": "0.89", "size": "5.42"}, {"price": "0.87", "size": "261.53"}, {"price": "0.86", "size": "550"}, {"price": "0.83", "size": "188.23"}, {"price": "0.81", "size": "1292"}, {"price": "0.79", "size": "233.33"}, {"price": "0.77", "size": "200"}, {"price": "0.74", "size": "100"}, {"price": "0.7", "size": "180"}, {"price": "0.66", "size": "183.82"}, {"price": "0.36", "size": "20"}, {"price": "0.34", "size": "10"}, {"price": "0.33", "size": "19.4"}, {"price": "0.32", "size": "187.66"}, {"price": "0.31", "size": "16"}, {"price": "0.27", "size": "1150"}, {"price": "0.26", "size": "756.61"}, {"price": "0.25", "size": "1790"}, {"price": "0.24", "size": "1570.5"}, {"price": "0.23", "size": "160"}, {"price": "0.22", "size": "36.55"}], "event_type": "book", "last_trade_price": "0.220"}, {"market": "0x8f055b9db0a2d64b59b33e03bc8885f05a7c5116b3e2b6bb458011d6e18fb5d0", "asset_id": "56848224247430609127378739012316303221353695236865761552990703763581756323619", "timestamp": "1769384484002", "hash": "4240148eba4cdce4e99645e4767dd399d28d4d11", "bids": [{"price": "0.001", "size": "5931.07"}, {"price": "0.002", "size": "5.04"}, {"price": "0.003", "size": "1000"}, {"price": "0.004", "size": "20.44"}, {"price": "0.01", "size": "9450"}, {"price": "0.011", "size": "500"}, {"price": "0.02", "size": "3950"}, {"price": "0.021", "size": "12.96"}, {"price": "0.04", "size": "750"}, {"price": "0.05", "size": "100"}, {"price": "0.06", "size": "33"}, {"price": "0.09", "size": "800"}, {"price": "0.091", "size": "6.93"}, {"price": "0.122", "size": "550"}, {"price": "0.14", "size": "242.85"}, {"price": "0.19", "size": "168.42"}, {"price": "0.2", "size": "13500"}, {"price": "0.201", "size": "796"}, {"price": "0.24", "size": "216.66"}, {"price": "0.29", "size": "89.65"}, {"price": "0.3", "size": "3250"}, {"price": "0.33", "size": "72.72"}, {"price": "0.34", "size": "50"}, {"price": "0.38", "size": "52.63"}, {"price": "0.45", "size": "100"}, {"price": "0.451", "size": "1330"}, {"price": "0.452", "size": "5"}, {"price": "0.51", "size": "100"}, {"price": "0.91", "size": "40"}, {"price": "0.92", "size": "120"}, {"price": "0.922", "size": "120"}, {"price": "0.925", "size": "200"}, {"price": "0.93", "size": "3291.68"}, {"price": "0.932", "size": "250"}, {"price": "0.933", "size": "1114.38"}, {"price": "0.936", "size": "512"}, {"price": "0.937", "size": "100"}, {"price": "0.94", "size": "100"}], "asks": [{"price": "0.999", "size": "1030609.99"}, {"price": "0.998", "size": "1678.27"}, {"price": "0.997", "size": "20010.13"}, {"price": "0.996", "size": "11.35"}, {"price": "0.995", "size": "55659"}, {"price": "0.994", "size": "11691.23"}, {"price": "0.993", "size": "20"}, {"price": "0.992", "size": "5.52"}, {"price": "0.99", "size": "1856.68"}, {"price": "0.989", "size": "3007.3"}, {"price": "0.988", "size": "3500"}, {"price": "0.987", "size": "20"}, {"price": "0.986", "size": "6562.52"}, {"price": "0.985", "size": "3267.33"}, {"price": "0.983", "size": "6849.68"}, {"price": "0.982", "size": "33164.55"}, {"price": "0.98", "size": "820"}, {"price": "0.979", "size": "1334"}, {"price": "0.977", "size": "5792.39"}, {"price": "0.976", "size": "924.68"}, {"price": "0.973", "size": "575"}, {"price": "0.972", "size": "571"}, {"price": "0.97", "size": "330"}, {"price": "0.969", "size": "452"}, {"price": "0.968", "size": "8.82"}, {"price": "0.967", "size": "175"}, {"price": "0.965", "size": "142.85"}, {"price": "0.964", "size": "648.23"}, {"price": "0.963", "size": "423"}, {"price": "0.961", "size": "1064.71"}, {"price": "0.96", "size": "2347"}, {"price": "0.958", "size": "260"}, {"price": "0.957", "size": "163"}, {"price": "0.955", "size": "1220"}, {"price": "0.953", "size": "250"}, {"price": "0.952", "size": "490.81"}, {"price": "0.95", "size": "2200"}, {"price": "0.949", "size": "300"}, {"price": "0.948", "size": "300"}, {"price": "0.945", "size": "25"}], "event_type": "book", "last_trade_price": "0.945"}, {"market": "0x3da8ac5a617e2b32fbda49cbc5060917ab770abe9f74b11ffa36dcdb5b7a1195", "asset_id": "77932413699591385582408402058209008716103068377990837601822992291811637364241", "timestamp": "1769384486001", "hash": "edf49d866183c6b3818b920d189aa23c47077a09", "bids": [{"price": "0.01", "size": "6414.28"}, {"price": "0.02", "size": "3200"}, {"price": "0.03", "size": "100"}, {"price": "0.04", "size": "6.51"}, {"price": "0.05", "size": "20"}, {"price": "0.08", "size": "1150"}, {"price": "0.1", "size": "20"}, {"price": "0.11", "size": "5.42"}, {"price": "0.13", "size": "261.53"}, {"price": "0.14", "size": "550"}, {"price": "0.17", "size": "188.23"}, {"price": "0.19", "size": "1292"}, {"price": "0.21", "size": "233.33"}, {"price": "0.23", "size": "200"}, {"price": "0.26", "size": "100"}, {"price": "0.3", "size": "180"}, {"price": "0.34", "size": "183.82"}, {"price": "0.64", "size": "20"}, {"price": "0.66", "size": "10"}, {"price": "0.67", "size": "19.4"}, {"price": "0.68", "size": "187.66"}, {"price": "0.69", "size": "16"}, {"price": "0.73", "size": "1150"}, {"price": "0.74", "size": "756.61"}, {"price": "0.75", "size": "1790"}, {"price": "0.76", "size": "1570.5"}, {"price": "0.77", "size": "160"}, {"price": "0.78", "size": "36.55"}], "asks": [{"price": "0.99", "size": "45007.47"}, {"price": "0.98", "size": "1250"}, {"price": "0.97", "size": "7.5"}, {"price": "0.95", "size": "100"}, {"price": "0.94", "size": "11.66"}, {"price": "0.91", "size": "10"}, {"price": "0.9", "size": "3220"}, {"price": "0.89", "size": "500"}, {"price": "0.88", "size": "34"}, {"price": "0.85", "size": "86.66"}, {"price": "0.83", "size": "20"}, {"price": "0.82", "size": "622"}, {"price": "0.81", "size": "1588.61"}, {"price": "0.8", "size": "2725"}, {"price": "0.79", "size": "1534.85"}], "event_type": "book", "last_trade_price": "0.220"}, {"market": "0x5a4bae5b326d8ad4ef51e29b140afd57dc1dfb3c44e1c805209eacb65a656dd7", "asset_id": "59504136924064087795648081133235705846655371799758292499235575393658009825596", "timestamp": "1769384468831", "hash": "1cd4e85f0196dfd268c65ee1c47931b5514ca0ce", "bids": [{"price": "0.01", "size": "6410.41"}, {"price": "0.02", "size": "2800"}, {"price": "0.03", "size": "5.69"}, {"price": "0.05", "size": "80"}, {"price": "0.06", "size": "1500"}, {"price": "0.1", "size": "340"}, {"price": "0.11", "size": "6.59"}, {"price": "0.13", "size": "246.15"}, {"price": "0.15", "size": "1616"}, {"price": "0.16", "size": "175"}, {"price": "0.17", "size": "2920"}, {"price": "0.19", "size": "136.84"}, {"price": "0.22", "size": "409.09"}, {"price": "0.26", "size": "126.92"}, {"price": "0.27", "size": "50"}, {"price": "0.36", "size": "550"}, {"price": "0.37", "size": "540"}, {"price": "0.38", "size": "1300"}, {"price": "0.4", "size": "1168.5"}, {"price": "0.41", "size": "603"}, {"price": "0.42", "size": "26.19"}, {"price": "0.45", "size": "5"}, {"price": "0.46", "size": "708.8"}, {"price": "0.47", "size": "600.1"}, {"price": "0.5", "size": "1364"}, {"price": "0.52", "size": "50"}, {"price": "0.53", "size": "117"}, {"price": "0.56", "size": "106"}, {"price": "0.59", "size": "68"}, {"price": "0.6", "size": "3095"}, {"price": "0.61", "size": "4170.41"}], "asks": [{"price": "0.99", "size": "8309.66"}, {"price": "0.98", "size": "3450"}, {"price": "0.97", "size": "10.73"}, {"price": "0.96", "size": "900"}, {"price": "0.95", "size": "20"}, {"price": "0.94", "size": "1166.66"}, {"price": "0.92", "size": "400"}, {"price": "0.91", "size": "6.46"}, {"price": "0.9", "size": "280"}, {"price": "0.89", "size": "236.36"}, {"price": "0.88", "size": "4050"}, {"price": "0.87", "size": "184.61"}, {"price": "0.85", "size": "143.33"}, {"price": "0.8", "size": "527.8"}, {"price": "0.79", "size": "967.74"}, {"price": "0.76", "size": "32"}, {"price": "0.75", "size": "30"}, {"price": "0.74", "size": "28"}, {"price": "0.73", "size": "26"}, {"price": "0.72", "size": "24"}, {"price": "0.71", "size": "22"}, {"price": "0.7", "size": "20"}, {"price": "0.69", "size": "13"}, {"price": "0.68", "size": "32"}, {"price": "0.67", "size": "176"}, {"price": "0.66", "size": "1200"}, {"price": "0.65", "size": "200"}, {"price": "0.64", "size": "705.46"}, {"price": "0.63", "size": "1385"}, {"price": "0.62", "size": "1169.05"}], "event_type": "book", "last_trade_price": "0.390"}]}
{"_local_timestamp": "2026-01-25T23:41:28.388692+00:00", "data": {"market": "0x8f055b9db0a2d64b59b33e03bc8885f05a7c5116b3e2b6bb458011d6e18fb5d0", "price_changes": [{"asset_id": "61714042345592991242650283207041161607044873748774685082589583786302809304151", "price": "0.037", "size": "125", "side": "BUY", "hash": "524d1afa1b1be81e4884ea7f33c73e7c717d8b43", "best_bid": "0.055", "best_ask": "0.06"}, {"asset_id": "56848224247430609127378739012316303221353695236865761552990703763581756323619", "price": "0.963", "size": "125", "side": "SELL", "hash": "e2528f4fa52f988491cc629d0810b6813156bf27", "best_bid": "0.94", "best_ask": "0.945"}], "timestamp": "1769384488309", "event_type": "price_change"}}
{"_local_timestamp": "2026-01-25T23:41:28.389268+00:00", "data": {"market": "0x8f055b9db0a2d64b59b33e03bc8885f05a7c5116b3e2b6bb458011d6e18fb5d0", "price_changes": [{"asset_id": "61714042345592991242650283207041161607044873748774685082589583786302809304151", "price": "0.043", "size": "0", "side": "BUY", "hash": "524d1afa1b1be81e4884ea7f33c73e7c717d8b43", "best_bid": "0.055", "best_ask": "0.06"}, {"asset_id": "56848224247430609127378739012316303221353695236865761552990703763581756323619", "price": "0.957", "size": "0", "side": "SELL", "hash": "e2528f4fa52f988491cc629d0810b6813156bf27", "best_bid": "0.94", "best_ask": "0.945"}], "timestamp": "1769384488309", "event_type": "price_change"}}
{"_local_timestamp": "2026-01-25T23:41:28.389604+00:00", "data": {"market": "0x8f055b9db0a2d64b59b33e03bc8885f05a7c5116b3e2b6bb458011d6e18fb5d0", "price_changes": [{"asset_id": "61714042345592991242650283207041161607044873748774685082589583786302809304151", "price": "0.04", "size": "2122", "side": "BUY", "hash": "524d1afa1b1be81e4884ea7f33c73e7c717d8b43", "best_bid": "0.055", "best_ask": "0.06"}, {"asset_id": "56848224247430609127378739012316303221353695236865761552990703763581756323619", "price": "0.96", "size": "2122", "side": "SELL", "hash": "e2528f4fa52f988491cc629d0810b6813156bf27", "best_bid": "0.94", "best_ask": "0.945"}], "timestamp": "1769384488309", "event_type": "price_change"}}
{"_local_timestamp": "2026-01-25T23:41:28.395981+00:00", "data": {"market": "0x8f055b9db0a2d64b59b33e03bc8885f05a7c5116b3e2b6bb458011d6e18fb5d0", "price_changes": [{"asset_id": "61714042345592991242650283207041161607044873748774685082589583786302809304151", "price": "0.006", "size": "24.23", "side": "BUY", "hash": "524d1afa1b1be81e4884ea7f33c73e7c717d8b43", "best_bid": "0.055", "best_ask": "0.06"}, {"asset_id": "56848224247430609127378739012316303221353695236865761552990703763581756323619", "price": "0.994", "size": "24.23", "side": "SELL", "hash": "e2528f4fa52f988491cc629d0810b6813156bf27", "best_bid": "0.94", "best_ask": "0.945"}], "timestamp": "1769384488309", "event_type": "price_change"}}
{"_local_timestamp": "2026-01-25T23:41:28.586057+00:00", "data": {"market": "0x8f055b9db0a2d64b59b33e03bc8885f05a7c5116b3e2b6bb458011d6e18fb5d0", "price_changes": [{"asset_id": "61714042345592991242650283207041161607044873748774685082589583786302809304151", "price": "0.039", "size": "1347.71", "side": "BUY", "hash": "7f67ac3c6dd84d09ebcd041a9cf216e481e7ca16", "best_bid": "0.055", "best_ask": "0.06"}, {"asset_id": "56848224247430609127378739012316303221353695236865761552990703763581756323619", "price": "0.961", "size": "1347.71", "side": "SELL", "hash": "b4c2e972fe351f1cad182fbfcdfea87f197cd71f", "best_bid": "0.94", "best_ask": "0.945"}], "timestamp": "1769384488510", "event_type": "price_change"}}
{"_local_timestamp": "2026-01-25T23:41:28.586473+00:00", "data": {"market": "0x8f055b9db0a2d64b59b33e03bc8885f05a7c5116b3e2b6bb458011d6e18fb5d0", "price_changes": [{"asset_id": "61714042345592991242650283207041161607044873748774685082589583786302809304151", "price": "0.021", "size": "1667", "side": "BUY", "hash": "b9b2c945de1d989327ed1632d4713afef6e4db29", "best_bid": "0.055", "best_ask": "0.06"}, {"asset_id": "56848224247430609127378739012316303221353695236865761552990703763581756323619", "price": "0.979", "size": "1667", "side": "SELL", "hash": "b577c1d1773b6319d5022a475daa4d514e872517", "best_bid": "0.94", "best_ask": "0.945"}], "timestamp": "1769384488514", "event_type": "price_change"}}
{"_local_timestamp": "2026-01-25T23:41:28.586765+00:00", "data": {"market": "0x8f055b9db0a2d64b59b33e03bc8885f05a7c5116b3e2b6bb458011d6e18fb5d0", "price_changes": [{"asset_id": "61714042345592991242650283207041161607044873748774685082589583786302809304151", "price": "0.036", "size": "1037.23", "side": "BUY", "hash": "741ee808e2085eafab975f66e96d70e817e04826", "best_bid": "0.055", "best_ask": "0.06"}, {"asset_id": "56848224247430609127378739012316303221353695236865761552990703763581756323619", "price": "0.964", "size": "1037.23", "side": "SELL", "hash": "6abebde02cf86a81108de9197b2f6d384ecb2d50", "best_bid": "0.94", "best_ask": "0.945"}], "timestamp": "1769384488517", "event_type": "price_change"}}
{"_local_timestamp": "2026-01-25T23:41:28.591459+00:00", "data": {"market": "0x8f055b9db0a2d64b59b33e03bc8885f05a7c5116b3e2b6bb458011d6e18fb5d0", "price_changes": [{"asset_id": "61714042345592991242650283207041161607044873748774685082589583786302809304151", "price": "0.012", "size": "5834", "side": "BUY", "hash": "a70b7e6944ff7c4c22338ce4491133e9a1d0449c", "best_bid": "0.055", "best_ask": "0.06"}, {"asset_id": "56848224247430609127378739012316303221353695236865761552990703763581756323619", "price": "0.988", "size": "5834", "side": "SELL", "hash": "05268c1f6a3e90c7da735931507492742b9bfdaf", "best_bid": "0.94", "best_ask": "0.945"}], "timestamp": "1769384488520", "event_type": "price_change"}}
{"_local_timestamp": "2026-01-25T23:41:28.592422+00:00", "data": {"market": "0x8f055b9db0a2d64b59b33e03bc8885f05a7c5116b3e2b6bb458011d6e18fb5d0", "price_changes": [{"asset_id": "61714042345592991242650283207041161607044873748774685082589583786302809304151", "price": "0.028", "size": "786", "side": "BUY", "hash": "a040a88efcd4ace0a9932d27dc030af119289973", "best_bid": "0.055", "best_ask": "0.06"}, {"asset_id": "56848224247430609127378739012316303221353695236865761552990703763581756323619", "price": "0.972", "size": "786", "side": "SELL", "hash": "022fa0a864c2bfc0977a02a26f4e6c8cadf0dd28", "best_bid": "0.94", "best_ask": "0.945"}], "timestamp": "1769384488522", "event_type": "price_change"}}
{"_local_timestamp": "2026-01-25T23:41:28.596027+00:00", "data": {"market": "0x8f055b9db0a2d64b59b33e03bc8885f05a7c5116b3e2b6bb458011d6e18fb5d0", "price_changes": [{"asset_id": "61714042345592991242650283207041161607044873748774685082589583786302809304151", "price": "0.024", "size": "1174.68", "side": "BUY", "hash": "032d6f6e99141a63ade4f9f6e92918c62f003a97", "best_bid": "0.055", "best_ask": "0.06"}, {"asset_id": "56848224247430609127378739012316303221353695236865761552990703763581756323619", "price": "0.976", "size": "1174.68", "side": "SELL", "hash": "3f91351c4c04560e35e9f0c8859a328d94578b86", "best_bid": "0.94", "best_ask": "0.945"}], "timestamp": "1769384488525", "event_type": "price_change"}}
{"_local_timestamp": "2026-01-25T23:41:28.596470+00:00", "data": {"market": "0x8f055b9db0a2d64b59b33e03bc8885f05a7c5116b3e2b6bb458011d6e18fb5d0", "price_changes": [{"asset_id": "61714042345592991242650283207041161607044873748774685082589583786302809304151", "price": "0.015", "size": "4067.33", "side": "BUY", "hash": "9f2e5bc5a98b7c6ac56ca46d6fa526a82c83d90d", "best_bid": "0.055", "best_ask": "0.06"}, {"asset_id": "56848224247430609127378739012316303221353695236865761552990703763581756323619", "price": "0.985", "size": "4067.33", "side": "SELL", "hash": "a31f11b8549d05a7518fb7ac972a9ce1cd8bfdb0", "best_bid": "0.94", "best_ask": "0.945"}], "timestamp": "1769384488528", "event_type": "price_change"}}
{"_local_timestamp": "2026-01-25T23:41:28.596789+00:00", "data": {"market": "0x8f055b9db0a2d64b59b33e03bc8885f05a7c5116b3e2b6bb458011d6e18fb5d0", "price_changes": [{"asset_id": "61714042345592991242650283207041161607044873748774685082589583786302809304151", "price": "0.018", "size": "33664.55", "side": "BUY", "hash": "893b8c9538237f81d8f9178d1156a51b846450d9", "best_bid": "0.055", "best_ask": "0.06"}, {"asset_id": "56848224247430609127378739012316303221353695236865761552990703763581756323619", "price": "0.982", "size": "33664.55", "side": "SELL", "hash": "45aaa353af6be3a4532d2bdc3d78dc84164e7f25", "best_bid": "0.94", "best_ask": "0.945"}], "timestamp": "1769384488530", "event_type": "price_change"}}
{"_local_timestamp": "2026-01-25T23:41:28.599932+00:00", "data": {"market": "0x8f055b9db0a2d64b59b33e03bc8885f05a7c5116b3e2b6bb458011d6e18fb5d0", "price_changes": [{"asset_id": "61714042345592991242650283207041161607044873748774685082589583786302809304151", "price": "0.042", "size": "475", "side": "BUY", "hash": "d3ce9d586e3cf030f011878c3c959c7e8c5f5b3d", "best_bid": "0.055", "best_ask": "0.06"}, {"asset_id": "56848224247430609127378739012316303221353695236865761552990703763581756323619", "price": "0.958", "size": "475", "side": "SELL", "hash": "8cd2bd3cf6b390db029dee141ed81ad0518e49f4", "best_bid": "0.94", "best_ask": "0.945"}], "timestamp": "1769384488532", "event_type": "price_change"}}
{"_local_timestamp": "2026-01-25T23:41:28.603815+00:00", "data": {"market": "0x8f055b9db0a2d64b59b33e03bc8885f05a7c5116b3e2b6bb458011d6e18fb5d0", "price_changes": [{"asset_id": "61714042345592991242650283207041161607044873748774685082589583786302809304151", "price": "0.031", "size": "581", "side": "BUY", "hash": "da8de70a3914d1a87d2673fc9bd0e9fd3a826f92", "best_bid": "0.055", "best_ask": "0.06"}, {"asset_id": "56848224247430609127378739012316303221353695236865761552990703763581756323619", "price": "0.969", "size": "581", "side": "SELL", "hash": "dfabee703ee6681e6297c727c2460a70469e6771", "best_bid": "0.94", "best_ask": "0.945"}], "timestamp": "1769384488535", "event_type": "price_change"}}
{"_local_timestamp": "2026-01-25T23:41:28.720146+00:00", "data": {"market": "0x8f055b9db0a2d64b59b33e03bc8885f05a7c5116b3e2b6bb458011d6e18fb5d0", "price_changes": [{"asset_id": "61714042345592991242650283207041161607044873748774685082589583786302809304151", "price": "0.045", "size": "1376", "side": "BUY", "hash": "966336e118764934043b66c3c3ef536c87b2e2bb", "best_bid": "0.055", "best_ask": "0.06"}, {"asset_id": "56848224247430609127378739012316303221353695236865761552990703763581756323619", "price": "0.955", "size": "1376", "side": "SELL", "hash": "f5a5e99353c0b92cd46a19a5c172fd19ced04a92", "best_bid": "0.94", "best_ask": "0.945"}], "timestamp": "1769384488537", "event_type": "price_change"}}
{"_local_timestamp": "2026-01-25T23:41:28.970496+00:00", "data": {"market": "0x8f055b9db0a2d64b59b33e03bc8885f05a7c5116b3e2b6bb458011d6e18fb5d0", "price_changes": [{"asset_id": "56848224247430609127378739012316303221353695236865761552990703763581756323619", "price": "0.955", "size": "1251", "side": "SELL", "hash": "574292aa14a9f532281c429547369828b5c57e48", "best_bid": "0.94", "best_ask": "0.945"}, {"asset_id": "61714042345592991242650283207041161607044873748774685082589583786302809304151", "price": "0.045", "size": "1251", "side": "BUY", "hash": "7660e52a173c5ecb7fcaee6d63fbd6f097f3fd72", "best_bid": "0.055", "best_ask": "0.06"}], "timestamp": "1769384488900", "event_type": "price_change"}}
{"_local_timestamp": "2026-01-25T23:41:29.067561+00:00", "data": {"market": "0x8f055b9db0a2d64b59b33e03bc8885f05a7c5116b3e2b6bb458011d6e18fb5d0", "price_changes": [{"asset_id": "56848224247430609127378739012316303221353695236865761552990703763581756323619", "price": "0.957", "size": "125", "side": "SELL", "hash": "7e4ebf33fc539512cda20ad55c25f61c949135b3", "best_bid": "0.94", "best_ask": "0.945"}, {"asset_id": "61714042345592991242650283207041161607044873748774685082589583786302809304151", "price": "0.043", "size": "125", "side": "BUY", "hash": "41f870a3d088f141ab475d5100f92724f0040e0d", "best_bid": "0.055", "best_ask": "0.06"}], "timestamp": "1769384488996", "event_type": "price_change"}}
{"_local_timestamp": "2026-01-25T23:41:29.601158+00:00", "data": {"market": "0x8f055b9db0a2d64b59b33e03bc8885f05a7c5116b3e2b6bb458011d6e18fb5d0", "price_changes": [{"asset_id": "56848224247430609127378739012316303221353695236865761552990703763581756323619", "price": "0.97", "size": "270", "side": "SELL", "hash": "e0e07d1d5e32ae35411f45ad9bb03eda83aa01d4", "best_bid": "0.94", "best_ask": "0.945"}, {"asset_id": "61714042345592991242650283207041161607044873748774685082589583786302809304151", "price": "0.03", "size": "270", "side": "BUY", "hash": "ea540b3b888e20d84f54dbc9ddbdef53f7e4e9e5", "best_bid": "0.055", "best_ask": "0.06"}], "timestamp": "1769384489536", "event_type": "price_change"}}
{"_local_timestamp": "2026-01-25T23:41:29.765906+00:00", "data": {"market": "0x8f055b9db0a2d64b59b33e03bc8885f05a7c5116b3e2b6bb458011d6e18fb5d0", "price_changes": [{"asset_id": "56848224247430609127378739012316303221353695236865761552990703763581756323619", "price": "0.97", "size": "330", "side": "SELL", "hash": "527d32cf76d3ed219318c83bf14636fad83dd951", "best_bid": "0.94", "best_ask": "0.945"}, {"asset_id": "61714042345592991242650283207041161607044873748774685082589583786302809304151", "price": "0.03", "size": "330", "side": "BUY", "hash": "6979af68afa36b21ffb85649451fc19d0d1efdd5", "best_bid": "0.055", "best_ask": "0.06"}], "timestamp": "1769384489647", "event_type": "price_change"}}
{"_local_timestamp": "2026-01-25T23:41:29.779276+00:00", "data": {"market": "0x3da8ac5a617e2b32fbda49cbc5060917ab770abe9f74b11ffa36dcdb5b7a1195", "price_changes": [{"asset_id": "83722296194861509737807492105325276806804014660137138811708463053968062687084", "price": "0.12", "size": "817", "side": "BUY", "hash": "db9857aad4bc2645b0d56cf75854faffc1273fba", "best_bid": "0.21", "best_ask": "0.22"}, {"asset_id": "77932413699591385582408402058209008716103068377990837601822992291811637364241", "price": "0.88", "size": "817", "side": "SELL", "hash": "6ddfbb133701183892f5487c98e641f6c2ad7202", "best_bid": "0.78", "best_ask": "0.79"}], "timestamp": "1769384489702", "event_type": "price_change"}}
{"_local_timestamp": "2026-01-25T23:41:29.779770+00:00", "data": {"market": "0x3da8ac5a617e2b32fbda49cbc5060917ab770abe9f74b11ffa36dcdb5b7a1195", "price_changes": [{"asset_id": "83722296194861509737807492105325276806804014660137138811708463053968062687084", "price": "0.18", "size": "883", "side": "BUY", "hash": "136a2171a7513edad7ef38a90a4cea6fbdbe8a42", "best_bid": "0.21", "best_ask": "0.22"}, {"asset_id": "77932413699591385582408402058209008716103068377990837601822992291811637364241", "price": "0.82", "size": "883", "side": "SELL", "hash": "b78e3b9606a46e3565e2484d1ac74dcb7e81eb63", "best_bid": "0.78", "best_ask": "0.79"}], "timestamp": "1769384489703", "event_type": "price_change"}}
{"_local_timestamp": "2026-01-25T23:41:29.971584+00:00", "data": {"market": "0x8f055b9db0a2d64b59b33e03bc8885f05a7c5116b3e2b6bb458011d6e18fb5d0", "price_changes": [{"asset_id": "56848224247430609127378739012316303221353695236865761552990703763581756323619", "price": "0.957", "size": "0", "side": "SELL", "hash": "624fb6651a86898097ac1ddbe44d4c2fbdb3c5b0", "best_bid": "0.94", "best_ask": "0.945"}, {"asset_id": "61714042345592991242650283207041161607044873748774685082589583786302809304151", "price": "0.043", "size": "0", "side": "BUY", "hash": "6555367216014b429fe1a52ce02702d8c76936b9", "best_bid": "0.055", "best_ask": "0.06"}], "timestamp": "1769384489898", "event_type": "price_change"}}
{"_local_timestamp": "2026-01-25T23:41:29.986190+00:00", "data": {"market": "0x8f055b9db0a2d64b59b33e03bc8885f05a7c5116b3e2b6bb458011d6e18fb5d0", "price_changes": [{"asset_id": "56848224247430609127378739012316303221353695236865761552990703763581756323619", "price": "0.97", "size": "270", "side": "SELL", "hash": "9432343f2a2be9d889257b8a630227b3705a9617", "best_bid": "0.94", "best_ask": "0.945"}, {"asset_id": "61714042345592991242650283207041161607044873748774685082589583786302809304151", "price": "0.03", "size": "270", "side": "BUY", "hash": "d0dc96f6fafbb7ce39006944831678104102a437", "best_bid": "0.055", "best_ask": "0.06"}], "timestamp": "1769384489917", "event_type": "price_change"}}
{"_local_timestamp": "2026-01-25T23:41:30.036991+00:00", "data": {"market": "0x8f055b9db0a2d64b59b33e03bc8885f05a7c5116b3e2b6bb458011d6e18fb5d0", "price_changes": [{"asset_id": "56848224247430609127378739012316303221353695236865761552990703763581756323619", "price": "0.955", "size": "1376", "side": "SELL", "hash": "792740a8660d79ea77872a8fdf692e0ebc489094", "best_bid": "0.94", "best_ask": "0.945"}, {"asset_id": "61714042345592991242650283207041161607044873748774685082589583786302809304151", "price": "0.045", "size": "1376", "side": "BUY", "hash": "5db427b6dbe682f6cb588867b3f68a05bf1756f3", "best_bid": "0.055", "best_ask": "0.06"}], "timestamp": "1769384489965", "event_type": "price_change"}}
{"_local_timestamp": "2026-01-25T23:41:30.089419+00:00", "data": {"market": "0x8f055b9db0a2d64b59b33e03bc8885f05a7c5116b3e2b6bb458011d6e18fb5d0", "price_changes": [{"asset_id": "56848224247430609127378739012316303221353695236865761552990703763581756323619", "price": "0.97", "size": "330", "side": "SELL", "hash": "d3dfadd24ab5506a51bb41cfde3405e817e4bb1d", "best_bid": "0.94", "best_ask": "0.945"}, {"asset_id": "61714042345592991242650283207041161607044873748774685082589583786302809304151", "price": "0.03", "size": "330", "side": "BUY", "hash": "ee95ef8bdf6a9188b7c43bd91c1cd93f3f5140ea", "best_bid": "0.055", "best_ask": "0.06"}], "timestamp": "1769384490011", "event_type": "price_change"}}
{"_local_timestamp": "2026-01-25T23:41:30.953714+00:00", "data": {"market": "0x8f055b9db0a2d64b59b33e03bc8885f05a7c5116b3e2b6bb458011d6e18fb5d0", "price_changes": [{"asset_id": "56848224247430609127378739012316303221353695236865761552990703763581756323619", "price": "0.955", "size": "1251", "side": "SELL", "hash": "28d2a78da3bcb71581e1b41e503cbfaee618c2e7", "best_bid": "0.94", "best_ask": "0.945"}, {"asset_id": "61714042345592991242650283207041161607044873748774685082589583786302809304151", "price": "0.045", "size": "1251", "side": "BUY", "hash": "78da119b25adfca4f03aa5ff6cbcfb330ff182b1", "best_bid": "0.055", "best_ask": "0.06"}], "timestamp": "1769384490886", "event_type": "price_change"}}
{"_local_timestamp": "2026-01-25T23:41:31.045394+00:00", "data": {"market": "0x8f055b9db0a2d64b59b33e03bc8885f05a7c5116b3e2b6bb458011d6e18fb5d0", "price_changes": [{"asset_id": "56848224247430609127378739012316303221353695236865761552990703763581756323619", "price": "0.957", "size": "125", "side": "SELL", "hash": "e6929da3673b2b1ec488f2db88fa8b4c75ed5f0e", "best_bid": "0.94", "best_ask": "0.945"}, {"asset_id": "61714042345592991242650283207041161607044873748774685082589583786302809304151", "price": "0.043", "size": "125", "side": "BUY", "hash": "2d59ace08f12e23201a52a81903b5c11535d0f2d", "best_bid": "0.055", "best_ask": "0.06"}], "timestamp": "1769384490978", "event_type": "price_change"}}
{"_local_timestamp": "2026-01-25T23:41:31.251871+00:00", "data": {"market": "0x8f055b9db0a2d64b59b33e03bc8885f05a7c5116b3e2b6bb458011d6e18fb5d0", "price_changes": [{"asset_id": "61714042345592991242650283207041161607044873748774685082589583786302809304151", "price": "0.031", "size": "0", "side": "BUY", "hash": "7715b90e27d239ff306139cef4ac3b7d27ad999c", "best_bid": "0.055", "best_ask": "0.06"}, {"asset_id": "56848224247430609127378739012316303221353695236865761552990703763581756323619", "price": "0.969", "size": "0", "side": "SELL", "hash": "5354222665779f3338ed2159f64bcd88f32019f0", "best_bid": "0.94", "best_ask": "0.945"}], "timestamp": "1769384491183", "event_type": "price_change"}}
{"_local_timestamp": "2026-01-25T23:41:31.252397+00:00", "data": {"market": "0x8f055b9db0a2d64b59b33e03bc8885f05a7c5116b3e2b6bb458011d6e18fb5d0", "price_changes": [{"asset_id": "61714042345592991242650283207041161607044873748774685082589583786302809304151", "price": "0.021", "size": "1334", "side": "BUY", "hash": "7715b90e27d239ff306139cef4ac3b7d27ad999c", "best_bid": "0.055", "best_ask": "0.06"}, {"asset_id": "56848224247430609127378739012316303221353695236865761552990703763581756323619", "price": "0.979", "size": "1334", "side": "SELL", "hash": "5354222665779f3338ed2159f64bcd88f32019f0", "best_bid": "0.94", "best_ask": "0.945"}], "timestamp": "1769384491183", "event_type": "price_change"}}
{"_local_timestamp": "2026-01-25T23:41:31.252737+00:00", "data": {"market": "0x8f055b9db0a2d64b59b33e03bc8885f05a7c5116b3e2b6bb458011d6e18fb5d0", "price_changes": [{"asset_id": "61714042345592991242650283207041161607044873748774685082589583786302809304151", "price": "0.012", "size": "3500", "side": "BUY", "hash": "7715b90e27d239ff306139cef4ac3b7d27ad999c", "best_bid": "0.055", "best_ask": "0.06"}, {"asset_id": "56848224247430609127378739012316303221353695236865761552990703763581756323619", "price": "0.988", "size": "3500", "side": "SELL", "hash": "5354222665779f3338ed2159f64bcd88f32019f0", "best_bid": "0.94", "best_ask": "0.945"}], "timestamp": "1769384491183", "event_type": "price_change"}}
{"_local_timestamp": "2026-01-25T23:41:31.253776+00:00", "data": {"market": "0x8f055b9db0a2d64b59b33e03bc8885f05a7c5116b3e2b6bb458011d6e18fb5d0", "price_changes": [{"asset_id": "61714042345592991242650283207041161607044873748774685082589583786302809304151", "price": "0.028", "size": "571", "side": "BUY", "hash": "7715b90e27d239ff306139cef4ac3b7d27ad999c", "best_bid": "0.055", "best_ask": "0.06"}, {"asset_id": "56848224247430609127378739012316303221353695236865761552990703763581756323619", "price": "0.972", "size": "571", "side": "SELL", "hash": "5354222665779f3338ed2159f64bcd88f32019f0", "best_bid": "0.94", "best_ask": "0.945"}], "timestamp": "1769384491183", "event_type": "price_change"}}
{"_local_timestamp": "2026-01-25T23:41:31.256458+00:00", "data": {"market": "0x8f055b9db0a2d64b59b33e03bc8885f05a7c5116b3e2b6bb458011d6e18fb5d0", "price_changes": [{"asset_id": "61714042345592991242650283207041161607044873748774685082589583786302809304151", "price": "0.024", "size": "924.68", "side": "BUY", "hash": "7715b90e27d239ff306139cef4ac3b7d27ad999c", "best_bid": "0.055", "best_ask": "0.06"}, {"asset_id": "56848224247430609127378739012316303221353695236865761552990703763581756323619", "price": "0.976", "size": "924.68", "side": "SELL", "hash": "5354222665779f3338ed2159f64bcd88f32019f0", "best_bid": "0.94", "best_ask": "0.945"}], "timestamp": "1769384491183", "event_type": "price_change"}}
{"_local_timestamp": "2026-01-25T23:41:31.258528+00:00", "data": {"market": "0x8f055b9db0a2d64b59b33e03bc8885f05a7c5116b3e2b6bb458011d6e18fb5d0", "price_changes": [{"asset_id": "61714042345592991242650283207041161607044873748774685082589583786302809304151", "price": "0.015", "size": "3267.33", "side": "BUY", "hash": "7715b90e27d239ff306139cef4ac3b7d27ad999c", "best_bid": "0.055", "best_ask": "0.06"}, {"asset_id": "56848224247430609127378739012316303221353695236865761552990703763581756323619", "price": "0.985", "size": "3267.33", "side": "SELL", "hash": "5354222665779f3338ed2159f64bcd88f32019f0", "best_bid": "0.94", "best_ask": "0.945"}], "timestamp": "1769384491183", "event_type": "price_change"}}
{"_local_timestamp": "2026-01-25T23:41:31.259012+00:00", "data": {"market": "0x8f055b9db0a2d64b59b33e03bc8885f05a7c5116b3e2b6bb458011d6e18fb5d0", "price_changes": [{"asset_id": "61714042345592991242650283207041161607044873748774685082589583786302809304151", "price": "0.018", "size": "33164.55", "side": "BUY", "hash": "7715b90e27d239ff306139cef4ac3b7d27ad999c", "best_bid": "0.055", "best_ask": "0.06"}, {"asset_id": "56848224247430609127378739012316303221353695236865761552990703763581756323619", "price": "0.982", "size": "33164.55", "side": "SELL", "hash": "5354222665779f3338ed2159f64bcd88f32019f0", "best_bid": "0.94", "best_ask": "0.945"}], "timestamp": "1769384491183", "event_type": "price_change"}}
{"_local_timestamp": "2026-01-25T23:41:31.315178+00:00", "data": {"market": "0x8f055b9db0a2d64b59b33e03bc8885f05a7c5116b3e2b6bb458011d6e18fb5d0", "price_changes": [{"asset_id": "61714042345592991242650283207041161607044873748774685082589583786302809304151", "price": "0.006", "size": "11691.23", "side": "BUY", "hash": "8089824dc1a014a15b5e2f941180f59a330f105f", "best_bid": "0.055", "best_ask": "0.06"}, {"asset_id": "56848224247430609127378739012316303221353695236865761552990703763581756323619", "price": "0.994", "size": "11691.23", "side": "SELL", "hash": "5da2650aba2502078a4cea21975edc02fac9bc3c", "best_bid": "0.94", "best_ask": "0.945"}], "timestamp": "1769384491241", "event_type": "price_change"}}
{"_local_timestamp": "2026-01-25T23:41:31.316660+00:00", "data": {"market": "0x8f055b9db0a2d64b59b33e03bc8885f05a7c5116b3e2b6bb458011d6e18fb5d0", "price_changes": [{"asset_id": "61714042345592991242650283207041161607044873748774685082589583786302809304151", "price": "0.012", "size": "4667", "side": "BUY", "hash": "af13af4ce0d35d9c7f7ff640c5e521b23780e897", "best_bid": "0.055", "best_ask": "0.06"}, {"asset_id": "56848224247430609127378739012316303221353695236865761552990703763581756323619", "price": "0.988", "size": "4667", "side": "SELL", "hash": "1695a48b60dc186eab606f17b5c03902279c2f61", "best_bid": "0.94", "best_ask": "0.945"}], "timestamp": "1769384491242", "event_type": "price_change"}}
{"_local_timestamp": "2026-01-25T23:41:31.317877+00:00", "data": {"market": "0x8f055b9db0a2d64b59b33e03bc8885f05a7c5116b3e2b6bb458011d6e18fb5d0", "price_changes": [{"asset_id": "61714042345592991242650283207041161607044873748774685082589583786302809304151", "price": "0.028", "size": "643", "side": "BUY", "hash": "ad55a09d73df6acbf7315c9c06c77f10513ecf6e", "best_bid": "0.055", "best_ask": "0.06"}, {"asset_id": "56848224247430609127378739012316303221353695236865761552990703763581756323619", "price": "0.972", "size": "643", "side": "SELL", "hash": "79060650f23ad9e61966a105591638c59f81f1af", "best_bid": "0.94", "best_ask": "0.945"}], "timestamp": "1769384491243", "event_type": "price_change"}}
{"_local_timestamp": "2026-01-25T23:41:31.516101+00:00", "data": {"market": "0xeb0f640f8e6979495efb462bca18e491a8624c07aecd89b9cea0ba62a4164226", "price_changes": [{"asset_id": "45834992705311952325019110769074251045520613427860944634211713333639342925215", "price": "0.71", "size": "0", "side": "BUY", "hash": "1688056b10cbd9e03abb76a545194d3a8f45a83f", "best_bid": "0.74", "best_ask": "0.75"}, {"asset_id": "67044993355929871917109997788450094017244283163136736213822945937563487769385", "price": "0.29", "size": "0", "side": "SELL", "hash": "8a69263d22c14848a0c0275462fd41bb9c5fbafb", "best_bid": "0.25", "best_ask": "0.26"}], "timestamp": "1769384491443", "event_type": "price_change"}}
{"_local_timestamp": "2026-01-25T23:41:31.697486+00:00", "data": {"market": "0xeb0f640f8e6979495efb462bca18e491a8624c07aecd89b9cea0ba62a4164226", "price_changes": [{"asset_id": "45834992705311952325019110769074251045520613427860944634211713333639342925215", "price": "0.7", "size": "10", "side": "BUY", "hash": "76136b85401c6ddf5154fa0ae5fdd3077c267bf7", "best_bid": "0.74", "best_ask": "0.75"}, {"asset_id": "67044993355929871917109997788450094017244283163136736213822945937563487769385", "price": "0.3", "size": "10", "side": "SELL", "hash": "c1cb7d6e83b43e7cf2e702b67db7a6c97bd0979a", "best_bid": "0.25", "best_ask": "0.26"}], "timestamp": "1769384491614", "event_type": "price_change"}}
{"_local_timestamp": "2026-01-25T23:41:31.730116+00:00", "data": {"market": "0x8f055b9db0a2d64b59b33e03bc8885f05a7c5116b3e2b6bb458011d6e18fb5d0", "price_changes": [{"asset_id": "56848224247430609127378739012316303221353695236865761552990703763581756323619", "price": "0.97", "size": "270", "side": "SELL", "hash": "63c4fea7a35a2049136a8f9f850e9cd89c1a68b6", "best_bid": "0.94", "best_ask": "0.945"}, {"asset_id": "61714042345592991242650283207041161607044873748774685082589583786302809304151", "price": "0.03", "size": "270", "side": "BUY", "hash": "de002c82d7f9e343089a6422fe72756ef599b6c9", "best_bid": "0.055", "best_ask": "0.06"}], "timestamp": "1769384491663", "event_type": "price_change"}}
{"_local_timestamp": "2026-01-25T23:41:31.964500+00:00", "data": {"market": "0x8f055b9db0a2d64b59b33e03bc8885f05a7c5116b3e2b6bb458011d6e18fb5d0", "price_changes": [{"asset_id": "56848224247430609127378739012316303221353695236865761552990703763581756323619", "price": "0.957", "size": "0", "side": "SELL", "hash": "7620746866754da8fc0f6d51be8b7f48010460e8", "best_bid": "0.94", "best_ask": "0.945"}, {"asset_id": "61714042345592991242650283207041161607044873748774685082589583786302809304151", "price": "0.043", "size": "0", "side": "BUY", "hash": "65eeb47b7918e4b5992821fccee0826bc5110668", "best_bid": "0.055", "best_ask": "0.06"}], "timestamp": "1769384491891", "event_type": "price_change"}}
{"_local_timestamp": "2026-01-25T23:41:32.041315+00:00", "data": {"market": "0x8f055b9db0a2d64b59b33e03bc8885f05a7c5116b3e2b6bb458011d6e18fb5d0", "price_changes": [{"asset_id": "56848224247430609127378739012316303221353695236865761552990703763581756323619", "price": "0.955", "size": "1376", "side": "SELL", "hash": "b5c88f4b416bc69732ff074216b1267e64f0739e", "best_bid": "0.94", "best_ask": "0.945"}, {"asset_id": "61714042345592991242650283207041161607044873748774685082589583786302809304151", "price": "0.045", "size": "1376", "side": "BUY", "hash": "095ee06ab61cde2f4b40672aadbd52f332424135", "best_bid": "0.055", "best_ask": "0.06"}], "timestamp": "1769384491976", "event_type": "price_change"}}
{"_local_timestamp": "2026-01-25T23:41:32.127379+00:00", "data": {"market": "0x8f055b9db0a2d64b59b33e03bc8885f05a7c5116b3e2b6bb458011d6e18fb5d0", "price_changes": [{"asset_id": "56848224247430609127378739012316303221353695236865761552990703763581756323619", "price": "0.97", "size": "330", "side": "SELL", "hash": "b6992231a90dd0a780cc0e9c5dbcafedf47fcf24", "best_bid": "0.94", "best_ask": "0.945"}, {"asset_id": "61714042345592991242650283207041161607044873748774685082589583786302809304151", "price": "0.03", "size": "330", "side": "BUY", "hash": "53df178bdaa3dbde830dbae8f7ca5b9b38e39ee1", "best_bid": "0.055", "best_ask": "0.06"}], "timestamp": "1769384492048", "event_type": "price_change"}}
{"_local_timestamp": "2026-01-25T23:41:32.823430+00:00", "data": {"market": "0x8f055b9db0a2d64b59b33e03bc8885f05a7c5116b3e2b6bb458011d6e18fb5d0", "price_changes": [{"asset_id": "56848224247430609127378739012316303221353695236865761552990703763581756323619", "price": "0.97", "size": "270", "side": "SELL", "hash": "1c79b8824c5f94f0bf084728b00e59771c0792cd", "best_bid": "0.94", "best_ask": "0.945"}, {"asset_id": "61714042345592991242650283207041161607044873748774685082589583786302809304151", "price": "0.03", "size": "270", "side": "BUY", "hash": "76b6d0df7c5b3e70905840f41fd72400154219e2", "best_bid": "0.055", "best_ask": "0.06"}], "timestamp": "1769384492744", "event_type": "price_change"}}
{"_local_timestamp": "2026-01-25T23:41:32.955075+00:00", "data": {"market": "0x8f055b9db0a2d64b59b33e03bc8885f05a7c5116b3e2b6bb458011d6e18fb5d0", "price_changes": [{"asset_id": "56848224247430609127378739012316303221353695236865761552990703763581756323619", "price": "0.955", "size": "1251", "side": "SELL", "hash": "814447aa66deb1156dfb42e6e7a8376479f1222d", "best_bid": "0.94", "best_ask": "0.945"}, {"asset_id": "61714042345592991242650283207041161607044873748774685082589583786302809304151", "price": "0.045", "size": "1251", "side": "BUY", "hash": "f05a793ff584e36f85660863db5cc9b8de41d1cb", "best_bid": "0.055", "best_ask": "0.06"}], "timestamp": "1769384492889", "event_type": "price_change"}}
{"_local_timestamp": "2026-01-25T23:41:33.035302+00:00", "data": {"market": "0x8f055b9db0a2d64b59b33e03bc8885f05a7c5116b3e2b6bb458011d6e18fb5d0", "price_changes": [{"asset_id": "56848224247430609127378739012316303221353695236865761552990703763581756323619", "price": "0.957", "size": "125", "side": "SELL", "hash": "710821336b98376d88c41694f0f5445f382aa717", "best_bid": "0.94", "best_ask": "0.945"}, {"asset_id": "61714042345592991242650283207041161607044873748774685082589583786302809304151", "price": "0.043", "size": "125", "side": "BUY", "hash": "7776a07d3bb217992eeed966284ed85793120599", "best_bid": "0.055", "best_ask": "0.06"}], "timestamp": "1769384492965", "event_type": "price_change"}}
{"_local_timestamp": "2026-01-25T23:41:33.233355+00:00", "data": {"market": "0x8f055b9db0a2d64b59b33e03bc8885f05a7c5116b3e2b6bb458011d6e18fb5d0", "price_changes": [{"asset_id": "56848224247430609127378739012316303221353695236865761552990703763581756323619", "price": "0.97", "size": "330", "side": "SELL", "hash": "3e98d689805c25a3a0f63c53eb66919f9fc4667f", "best_bid": "0.94", "best_ask": "0.945"}, {"asset_id": "61714042345592991242650283207041161607044873748774685082589583786302809304151", "price": "0.03", "size": "330", "side": "BUY", "hash": "aa9d29de1f107a98d7e07448599a8ba7598439c9", "best_bid": "0.055", "best_ask": "0.06"}], "timestamp": "1769384493149", "event_type": "price_change"}}
{"_local_timestamp": "2026-01-25T23:41:33.897759+00:00", "data": {"market": "0x8f055b9db0a2d64b59b33e03bc8885f05a7c5116b3e2b6bb458011d6e18fb5d0", "price_changes": [{"asset_id": "56848224247430609127378739012316303221353695236865761552990703763581756323619", "price": "0.97", "size": "270", "side": "SELL", "hash": "c6f0f623204c097538c45c28dbcc443b46c191e7", "best_bid": "0.94", "best_ask": "0.945"}, {"asset_id": "61714042345592991242650283207041161607044873748774685082589583786302809304151", "price": "0.03", "size": "270", "side": "BUY", "hash": "44851eba7cb556fffb143bf0ffa7f996270913ee", "best_bid": "0.055", "best_ask": "0.06"}], "timestamp": "1769384493828", "event_type": "price_change"}}
{"_local_timestamp": "2026-01-25T23:41:33.956072+00:00", "data": {"market": "0x8f055b9db0a2d64b59b33e03bc8885f05a7c5116b3e2b6bb458011d6e18fb5d0", "price_changes": [{"asset_id": "56848224247430609127378739012316303221353695236865761552990703763581756323619", "price": "0.957", "size": "0", "side": "SELL", "hash": "99b0bbc5297ef1206538bac68c8678b5bb3290e0", "best_bid": "0.94", "best_ask": "0.945"}, {"asset_id": "61714042345592991242650283207041161607044873748774685082589583786302809304151", "price": "0.043", "size": "0", "side": "BUY", "hash": "96773b7d4bff8dd10e7ae74eb19a7e08a4964bb6", "best_bid": "0.055", "best_ask": "0.06"}], "timestamp": "1769384493890", "event_type": "price_change"}}
{"_local_timestamp": "2026-01-25T23:41:34.010195+00:00", "data": {"market": "0x8f055b9db0a2d64b59b33e03bc8885f05a7c5116b3e2b6bb458011d6e18fb5d0", "price_changes": [{"asset_id": "56848224247430609127378739012316303221353695236865761552990703763581756323619", "price": "0.955", "size": "1376", "side": "SELL", "hash": "484e4700981b12992ab2f74c87622b536418375f", "best_bid": "0.94", "best_ask": "0.945"}, {"asset_id": "61714042345592991242650283207041161607044873748774685082589583786302809304151", "price": "0.045", "size": "1376", "side": "BUY", "hash": "31bea9f6ebe64632f09900ca616e3109b3f9285d", "best_bid": "0.055", "best_ask": "0.06"}], "timestamp": "1769384493941", "event_type": "price_change"}}
{"_local_timestamp": "2026-01-25T23:41:34.108304+00:00", "data": {"market": "0x8f055b9db0a2d64b59b33e03bc8885f05a7c5116b3e2b6bb458011d6e18fb5d0", "price_changes": [{"asset_id": "61714042345592991242650283207041161607044873748774685082589583786302809304151", "price": "0.006", "size": "24.23", "side": "BUY", "hash": "ca33b92326fa81b534ceed4b3e9f347489b4ef58", "best_bid": "0.055", "best_ask": "0.06"}, {"asset_id": "56848224247430609127378739012316303221353695236865761552990703763581756323619", "price": "0.994", "size": "24.23", "side": "SELL", "hash": "84be8c91935729cc5f88695da88251e0455c3b5c", "best_bid": "0.94", "best_ask": "0.945"}], "timestamp": "1769384494037", "event_type": "price_change"}}
{"_local_timestamp": "2026-01-25T23:41:34.287562+00:00", "data": {"market": "0x8f055b9db0a2d64b59b33e03bc8885f05a7c5116b3e2b6bb458011d6e18fb5d0", "price_changes": [{"asset_id": "61714042345592991242650283207041161607044873748774685082589583786302809304151", "price": "0.012", "size": "5834", "side": "BUY", "hash": "e72812aefec654c6dfff3bee3b4de601d0b575c9", "best_bid": "0.055", "best_ask": "0.06"}, {"asset_id": "56848224247430609127378739012316303221353695236865761552990703763581756323619", "price": "0.988", "size": "5834", "side": "SELL", "hash": "301a319c93b4b63b10d2575f11da372ce025e945", "best_bid": "0.94", "best_ask": "0.945"}], "timestamp": "1769384494203", "event_type": "price_change"}}
{"_local_timestamp": "2026-01-25T23:41:34.288098+00:00", "data": {"market": "0x8f055b9db0a2d64b59b33e03bc8885f05a7c5116b3e2b6bb458011d6e18fb5d0", "price_changes": [{"asset_id": "61714042345592991242650283207041161607044873748774685082589583786302809304151", "price": "0.018", "size": "33664.55", "side": "BUY", "hash": "4480d62dfcef3b1e4ccc7aa6bd6df878c784dd22", "best_bid": "0.055", "best_ask": "0.06"}, {"asset_id": "56848224247430609127378739012316303221353695236865761552990703763581756323619", "price": "0.982", "size": "33664.55", "side": "SELL", "hash": "3d2bf73d669df8a9911d125e25edbe0a1ebbdd58", "best_bid": "0.94", "best_ask": "0.945"}], "timestamp": "1769384494205", "event_type": "price_change"}}
{"_local_timestamp": "2026-01-25T23:41:34.288516+00:00", "data": {"market": "0x8f055b9db0a2d64b59b33e03bc8885f05a7c5116b3e2b6bb458011d6e18fb5d0", "price_changes": [{"asset_id": "61714042345592991242650283207041161607044873748774685082589583786302809304151", "price": "0.024", "size": "1174.68", "side": "BUY", "hash": "a0132234d33ba677d9ef1e3466809d79d3fc3928", "best_bid": "0.055", "best_ask": "0.06"}, {"asset_id": "56848224247430609127378739012316303221353695236865761552990703763581756323619", "price": "0.976", "size": "1174.68", "side": "SELL", "hash": "84d18d79f19f810bc8741a25be69174e695c9d2f", "best_bid": "0.94", "best_ask": "0.945"}], "timestamp": "1769384494206", "event_type": "price_change"}}
{"_local_timestamp": "2026-01-25T23:41:34.288949+00:00", "data": {"market": "0x8f055b9db0a2d64b59b33e03bc8885f05a7c5116b3e2b6bb458011d6e18fb5d0", "price_changes": [{"asset_id": "61714042345592991242650283207041161607044873748774685082589583786302809304151", "price": "0.015", "size": "4067.33", "side": "BUY", "hash": "2def7ea28ca4f2b2b84f9f3a630bda43ed290969", "best_bid": "0.055", "best_ask": "0.06"}, {"asset_id": "56848224247430609127378739012316303221353695236865761552990703763581756323619", "price": "0.985", "size": "4067.33", "side": "SELL", "hash": "1e141a5cb10ab2458a2d14f7015d7e2073d14d14", "best_bid": "0.94", "best_ask": "0.945"}], "timestamp": "1769384494207", "event_type": "price_change"}}
{"_local_timestamp": "2026-01-25T23:41:34.289379+00:00", "data": {"market": "0x8f055b9db0a2d64b59b33e03bc8885f05a7c5116b3e2b6bb458011d6e18fb5d0", "price_changes": [{"asset_id": "61714042345592991242650283207041161607044873748774685082589583786302809304151", "price": "0.021", "size": "1667", "side": "BUY", "hash": "5eaa259b85e57688d26dfb6bdfaff05279a85e83", "best_bid": "0.055", "best_ask": "0.06"}, {"asset_id": "56848224247430609127378739012316303221353695236865761552990703763581756323619", "price": "0.979", "size": "1667", "side": "SELL", "hash": "386bbe200b3834c9530b1e7e158ef3761b4fff0c", "best_bid": "0.94", "best_ask": "0.945"}], "timestamp": "1769384494207", "event_type": "price_change"}}
{"_local_timestamp": "2026-01-25T23:41:34.292222+00:00", "data": {"market": "0x8f055b9db0a2d64b59b33e03bc8885f05a7c5116b3e2b6bb458011d6e18fb5d0", "price_changes": [{"asset_id": "61714042345592991242650283207041161607044873748774685082589583786302809304151", "price": "0.031", "size": "581", "side": "BUY", "hash": "c5e53f0a2ab14cc0cd73fbc5e3ac41da9c8ba126", "best_bid": "0.055", "best_ask": "0.06"}, {"asset_id": "56848224247430609127378739012316303221353695236865761552990703763581756323619", "price": "0.969", "size": "581", "side": "SELL", "hash": "fd4fccc34e68ffc275e14966daecf7c9e790bc19", "best_bid": "0.94", "best_ask": "0.945"}], "timestamp": "1769384494208", "event_type": "price_change"}}
{"_local_timestamp": "2026-01-25T23:41:34.292733+00:00", "data": {"market": "0x8f055b9db0a2d64b59b33e03bc8885f05a7c5116b3e2b6bb458011d6e18fb5d0", "price_changes": [{"asset_id": "61714042345592991242650283207041161607044873748774685082589583786302809304151", "price": "0.028", "size": "786", "side": "BUY", "hash": "a01a957c222618ba0287a296ef1477b8e59c5d4a", "best_bid": "0.055", "best_ask": "0.06"}, {"asset_id": "56848224247430609127378739012316303221353695236865761552990703763581756323619", "price": "0.972", "size": "786", "side": "SELL", "hash": "bc29c0d0017cdbbf243c74b72f62f4b0c0f5b02d", "best_bid": "0.94", "best_ask": "0.945"}], "timestamp": "1769384494209", "event_type": "price_change"}}
{"_local_timestamp": "2026-01-25T23:41:34.474057+00:00", "data": {"market": "0x8f055b9db0a2d64b59b33e03bc8885f05a7c5116b3e2b6bb458011d6e18fb5d0", "price_changes": [{"asset_id": "56848224247430609127378739012316303221353695236865761552990703763581756323619", "price": "0.97", "size": "330", "side": "SELL", "hash": "53530a2251ba5650f4e3b21b52180977977937cf", "best_bid": "0.94", "best_ask": "0.945"}, {"asset_id": "61714042345592991242650283207041161607044873748774685082589583786302809304151", "price": "0.03", "size": "330", "side": "BUY", "hash": "72cf2394f06172d04c2efc9ec0373cc37eb9b622", "best_bid": "0.055", "best_ask": "0.06"}], "timestamp": "1769384494394", "event_type": "price_change"}}
{"_local_timestamp": "2026-01-25T23:41:34.968120+00:00", "data": {"market": "0x8f055b9db0a2d64b59b33e03bc8885f05a7c5116b3e2b6bb458011d6e18fb5d0", "price_changes": [{"asset_id": "56848224247430609127378739012316303221353695236865761552990703763581756323619", "price": "0.955", "size": "1251", "side": "SELL", "hash": "775797dfde7635ec9e4b340c79e857968d42aff4", "best_bid": "0.94", "best_ask": "0.945"}, {"asset_id": "61714042345592991242650283207041161607044873748774685082589583786302809304151", "price": "0.045", "size": "1251", "side": "BUY", "hash": "cac4d0545f230571e7e2f5fb74e69a22108a8bfe", "best_bid": "0.055", "best_ask": "0.06"}], "timestamp": "1769384494896", "event_type": "price_change"}}
{"_local_timestamp": "2026-01-25T23:41:35.075278+00:00", "data": {"market": "0x8f055b9db0a2d64b59b33e03bc8885f05a7c5116b3e2b6bb458011d6e18fb5d0", "price_changes": [{"asset_id": "56848224247430609127378739012316303221353695236865761552990703763581756323619", "price": "0.957", "size": "125", "side": "SELL", "hash": "c64231f96225f18f2de8c851f432c35b43f66989", "best_bid": "0.94", "best_ask": "0.945"}, {"asset_id": "61714042345592991242650283207041161607044873748774685082589583786302809304151", "price": "0.043", "size": "125", "side": "BUY", "hash": "cc1c876fc49ebdb7b3a9eeae6b1ca72cdd8f5750", "best_bid": "0.055", "best_ask": "0.06"}], "timestamp": "1769384494997", "event_type": "price_change"}}
{"_local_timestamp": "2026-01-25T23:41:35.130818+00:00", "data": {"market": "0x8f055b9db0a2d64b59b33e03bc8885f05a7c5116b3e2b6bb458011d6e18fb5d0", "price_changes": [{"asset_id": "56848224247430609127378739012316303221353695236865761552990703763581756323619", "price": "0.97", "size": "270", "side": "SELL", "hash": "80d9a64ac36a843e3733f0743d5085d89d708ef8", "best_bid": "0.94", "best_ask": "0.945"}, {"asset_id": "61714042345592991242650283207041161607044873748774685082589583786302809304151", "price": "0.03", "size": "270", "side": "BUY", "hash": "e2de6de0adc88a4ca2e8d0ba1de602c977261645", "best_bid": "0.055", "best_ask": "0.06"}], "timestamp": "1769384495042", "event_type": "price_change"}}
{"_local_timestamp": "2026-01-25T23:41:35.487790+00:00", "data": {"market": "0x8f055b9db0a2d64b59b33e03bc8885f05a7c5116b3e2b6bb458011d6e18fb5d0", "price_changes": [{"asset_id": "56848224247430609127378739012316303221353695236865761552990703763581756323619", "price": "0.97", "size": "330", "side": "SELL", "hash": "618c7b0d0ebc11448cb3231bb155bd7a4dc8db42", "best_bid": "0.94", "best_ask": "0.945"}, {"asset_id": "61714042345592991242650283207041161607044873748774685082589583786302809304151", "price": "0.03", "size": "330", "side": "BUY", "hash": "f32fce70eb40761a92e8c64c7eac87f4f07879bd", "best_bid": "0.055", "best_ask": "0.06"}], "timestamp": "1769384495417", "event_type": "price_change"}}
{"_local_timestamp": "2026-01-25T23:41:35.965169+00:00", "data": {"market": "0x8f055b9db0a2d64b59b33e03bc8885f05a7c5116b3e2b6bb458011d6e18fb5d0", "price_changes": [{"asset_id": "56848224247430609127378739012316303221353695236865761552990703763581756323619", "price": "0.957", "size": "0", "side": "SELL", "hash": "5ac5acc2b35351d2be61fa9347aa16907ff293db", "best_bid": "0.94", "best_ask": "0.945"}, {"asset_id": "61714042345592991242650283207041161607044873748774685082589583786302809304151", "price": "0.043", "size": "0", "side": "BUY", "hash": "939d966782c11c42cb8746ce8f1f5d567aab5fbe", "best_bid": "0.055", "best_ask": "0.06"}], "timestamp": "1769384495898", "event_type": "price_change"}}
{"_local_timestamp": "2026-01-25T23:41:36.038429+00:00", "data": {"market": "0x8f055b9db0a2d64b59b33e03bc8885f05a7c5116b3e2b6bb458011d6e18fb5d0", "price_changes": [{"asset_id": "56848224247430609127378739012316303221353695236865761552990703763581756323619", "price": "0.955", "size": "1376", "side": "SELL", "hash": "c13c5372b477728f5fa0f27c194efde378b1044b", "best_bid": "0.94", "best_ask": "0.945"}, {"asset_id": "61714042345592991242650283207041161607044873748774685082589583786302809304151", "price": "0.045", "size": "1376", "side": "BUY", "hash": "26bef5c3b6b62f4c9d47729b03d5f3b3a009d15e", "best_bid": "0.055", "best_ask": "0.06"}], "timestamp": "1769384495972", "event_type": "price_change"}}
{"_local_timestamp": "2026-01-25T23:41:36.185968+00:00", "data": {"market": "0x8f055b9db0a2d64b59b33e03bc8885f05a7c5116b3e2b6bb458011d6e18fb5d0", "price_changes": [{"asset_id": "61714042345592991242650283207041161607044873748774685082589583786302809304151", "price": "0.012", "size": "4667", "side": "BUY", "hash": "cfe49bf50ce4bdae20375f3d924831520e1dd665", "best_bid": "0.055", "best_ask": "0.06"}, {"asset_id": "56848224247430609127378739012316303221353695236865761552990703763581756323619", "price": "0.988", "size": "4667", "side": "SELL", "hash": "186362542e4b66f24c2d68fe81b922a5ba6aefe5", "best_bid": "0.94", "best_ask": "0.945"}], "timestamp": "1769384496117", "event_type": "price_change"}}
{"_local_timestamp": "2026-01-25T23:41:36.188143+00:00", "data": {"market": "0x8f055b9db0a2d64b59b33e03bc8885f05a7c5116b3e2b6bb458011d6e18fb5d0", "price_changes": [{"asset_id": "61714042345592991242650283207041161607044873748774685082589583786302809304151", "price": "0.018", "size": "33164.55", "side": "BUY", "hash": "cfe49bf50ce4bdae20375f3d924831520e1dd665", "best_bid": "0.055", "best_ask": "0.06"}, {"asset_id": "56848224247430609127378739012316303221353695236865761552990703763581756323619", "price": "0.982", "size": "33164.55", "side": "SELL", "hash": "186362542e4b66f24c2d68fe81b922a5ba6aefe5", "best_bid": "0.94", "best_ask": "0.945"}], "timestamp": "1769384496117", "event_type": "price_change"}}
{"_local_timestamp": "2026-01-25T23:41:36.188748+00:00", "data": {"market": "0x8f055b9db0a2d64b59b33e03bc8885f05a7c5116b3e2b6bb458011d6e18fb5d0", "price_changes": [{"asset_id": "61714042345592991242650283207041161607044873748774685082589583786302809304151", "price": "0.024", "size": "924.68", "side": "BUY", "hash": "cfe49bf50ce4bdae20375f3d924831520e1dd665", "best_bid": "0.055", "best_ask": "0.06"}, {"asset_id": "56848224247430609127378739012316303221353695236865761552990703763581756323619", "price": "0.976", "size": "924.68", "side": "SELL", "hash": "186362542e4b66f24c2d68fe81b922a5ba6aefe5", "best_bid": "0.94", "best_ask": "0.945"}], "timestamp": "1769384496117", "event_type": "price_change"}}
{"_local_timestamp": "2026-01-25T23:41:36.201274+00:00", "data": {"market": "0x8f055b9db0a2d64b59b33e03bc8885f05a7c5116b3e2b6bb458011d6e18fb5d0", "price_changes": [{"asset_id": "61714042345592991242650283207041161607044873748774685082589583786302809304151", "price": "0.015", "size": "3267.33", "side": "BUY", "hash": "cfe49bf50ce4bdae20375f3d924831520e1dd665", "best_bid": "0.055", "best_ask": "0.06"}, {"asset_id": "56848224247430609127378739012316303221353695236865761552990703763581756323619", "price": "0.985", "size": "3267.33", "side": "SELL", "hash": "186362542e4b66f24c2d68fe81b922a5ba6aefe5", "best_bid": "0.94", "best_ask": "0.945"}], "timestamp": "1769384496117", "event_type": "price_change"}}
{"_local_timestamp": "2026-01-25T23:41:36.201977+00:00", "data": {"market": "0x8f055b9db0a2d64b59b33e03bc8885f05a7c5116b3e2b6bb458011d6e18fb5d0", "price_changes": [{"asset_id": "61714042345592991242650283207041161607044873748774685082589583786302809304151", "price": "0.021", "size": "1334", "side": "BUY", "hash": "cfe49bf50ce4bdae20375f3d924831520e1dd665", "best_bid": "0.055", "best_ask": "0.06"}, {"asset_id": "56848224247430609127378739012316303221353695236865761552990703763581756323619", "price": "0.979", "size": "1334", "side": "SELL", "hash": "186362542e4b66f24c2d68fe81b922a5ba6aefe5", "best_bid": "0.94", "best_ask": "0.945"}], "timestamp": "1769384496117", "event_type": "price_change"}}
{"_local_timestamp": "2026-01-25T23:41:36.202448+00:00", "data": {"market": "0x8f055b9db0a2d64b59b33e03bc8885f05a7c5116b3e2b6bb458011d6e18fb5d0", "price_changes": [{"asset_id": "61714042345592991242650283207041161607044873748774685082589583786302809304151", "price": "0.031", "size": "0", "side": "BUY", "hash": "cfe49bf50ce4bdae20375f3d924831520e1dd665", "best_bid": "0.055", "best_ask": "0.06"}, {"asset_id": "56848224247430609127378739012316303221353695236865761552990703763581756323619", "price": "0.969", "size": "0", "side": "SELL", "hash": "186362542e4b66f24c2d68fe81b922a5ba6aefe5", "best_bid": "0.94", "best_ask": "0.945"}], "timestamp": "1769384496117", "event_type": "price_change"}}
{"_local_timestamp": "2026-01-25T23:41:36.202895+00:00", "data": {"market": "0x8f055b9db0a2d64b59b33e03bc8885f05a7c5116b3e2b6bb458011d6e18fb5d0", "price_changes": [{"asset_id": "61714042345592991242650283207041161607044873748774685082589583786302809304151", "price": "0.028", "size": "643", "side": "BUY", "hash": "cfe49bf50ce4bdae20375f3d924831520e1dd665", "best_bid": "0.055", "best_ask": "0.06"}, {"asset_id": "56848224247430609127378739012316303221353695236865761552990703763581756323619", "price": "0.972", "size": "643", "side": "SELL", "hash": "186362542e4b66f24c2d68fe81b922a5ba6aefe5", "best_bid": "0.94", "best_ask": "0.945"}], "timestamp": "1769384496117", "event_type": "price_change"}}
{"_local_timestamp": "2026-01-25T23:41:36.203380+00:00", "data": {"market": "0x8f055b9db0a2d64b59b33e03bc8885f05a7c5116b3e2b6bb458011d6e18fb5d0", "price_changes": [{"asset_id": "56848224247430609127378739012316303221353695236865761552990703763581756323619", "price": "0.97", "size": "270", "side": "SELL", "hash": "af04887f2849139fa4a0d6f3f1625c5f65eafe7a", "best_bid": "0.94", "best_ask": "0.945"}, {"asset_id": "61714042345592991242650283207041161607044873748774685082589583786302809304151", "price": "0.03", "size": "270", "side": "BUY", "hash": "2c7cecca84b2da9b95013ed3cdc2aa85e6520823", "best_bid": "0.055", "best_ask": "0.06"}], "timestamp": "1769384496132", "event_type": "price_change"}}
{"_local_timestamp": "2026-01-25T23:41:36.223488+00:00", "data": {"market": "0x8f055b9db0a2d64b59b33e03bc8885f05a7c5116b3e2b6bb458011d6e18fb5d0", "price_changes": [{"asset_id": "61714042345592991242650283207041161607044873748774685082589583786302809304151", "price": "0.006", "size": "11691.23", "side": "BUY", "hash": "758398be1c94e496c9a74e823fb36885226f63bc", "best_bid": "0.055", "best_ask": "0.06"}, {"asset_id": "56848224247430609127378739012316303221353695236865761552990703763581756323619", "price": "0.994", "size": "11691.23", "side": "SELL", "hash": "a13e0c3e006ca3bbb6957182ba85a14a4e801193", "best_bid": "0.94", "best_ask": "0.945"}], "timestamp": "1769384496152", "event_type": "price_change"}}
{"_local_timestamp": "2026-01-25T23:41:36.608956+00:00", "data": {"market": "0x8f055b9db0a2d64b59b33e03bc8885f05a7c5116b3e2b6bb458011d6e18fb5d0", "price_changes": [{"asset_id": "56848224247430609127378739012316303221353695236865761552990703763581756323619", "price": "0.97", "size": "330", "side": "SELL", "hash": "e0b31590a10477357d65d23955ac485717f6ea70", "best_bid": "0.94", "best_ask": "0.945"}, {"asset_id": "61714042345592991242650283207041161607044873748774685082589583786302809304151", "price": "0.03", "size": "330", "side": "BUY", "hash": "a89cdb305235815e011df2122c66e3b6c2da84ed", "best_bid": "0.055", "best_ask": "0.06"}], "timestamp": "1769384496524", "event_type": "price_change"}}
{"_local_timestamp": "2026-01-25T23:41:36.656684+00:00", "data": {"market": "0x5a4bae5b326d8ad4ef51e29b140afd57dc1dfb3c44e1c805209eacb65a656dd7", "price_changes": [{"asset_id": "86247848522476811956744818668364574835142715064162362411756221076437767369255", "price": "0.53", "size": "571.3", "side": "SELL", "hash": "8b8409d2b4fd47327a515293dc8e905f36407fc1", "best_bid": "0.38", "best_ask": "0.39"}, {"asset_id": "59504136924064087795648081133235705846655371799758292499235575393658009825596", "price": "0.47", "size": "571.3", "side": "BUY", "hash": "a29fc08a42aa9576032cf0322619f2a84adfbc2c", "best_bid": "0.61", "best_ask": "0.62"}], "timestamp": "1769384496591", "event_type": "price_change"}}
{"_local_timestamp": "2026-01-25T23:41:36.740546+00:00", "data": {"market": "0x5a4bae5b326d8ad4ef51e29b140afd57dc1dfb3c44e1c805209eacb65a656dd7", "price_changes": [{"asset_id": "86247848522476811956744818668364574835142715064162362411756221076437767369255", "price": "0.52", "size": "28.8", "side": "SELL", "hash": "e7d07854a7ad08f1c0129fb46dfb724074149ac4", "best_bid": "0.38", "best_ask": "0.39"}, {"asset_id": "59504136924064087795648081133235705846655371799758292499235575393658009825596", "price": "0.48", "size": "28.8", "side": "BUY", "hash": "fdfaca6f72d8536ea7e2a2f94221ae54354fc049", "best_bid": "0.61", "best_ask": "0.62"}], "timestamp": "1769384496673", "event_type": "price_change"}}
{"_local_timestamp": "2026-01-25T23:41:36.961340+00:00", "data": {"market": "0x8f055b9db0a2d64b59b33e03bc8885f05a7c5116b3e2b6bb458011d6e18fb5d0", "price_changes": [{"asset_id": "56848224247430609127378739012316303221353695236865761552990703763581756323619", "price": "0.955", "size": "1251", "side": "SELL", "hash": "b6cbac9bb04eae871d9dca317e915193b007ed51", "best_bid": "0.94", "best_ask": "0.945"}, {"asset_id": "61714042345592991242650283207041161607044873748774685082589583786302809304151", "price": "0.045", "size": "1251", "side": "BUY", "hash": "c4c7975afefbc9c49c2f3994fb0aa822ae83f96a", "best_bid": "0.055", "best_ask": "0.06"}], "timestamp": "1769384496897", "event_type": "price_change"}}
{"_local_timestamp": "2026-01-25T23:41:37.036217+00:00", "data": {"market": "0x8f055b9db0a2d64b59b33e03bc8885f05a7c5116b3e2b6bb458011d6e18fb5d0", "price_changes": [{"asset_id": "56848224247430609127378739012316303221353695236865761552990703763581756323619", "price": "0.957", "size": "125", "side": "SELL", "hash": "b86b3fe245220ae85945203793e2a1a25ee19f5b", "best_bid": "0.94", "best_ask": "0.945"}, {"asset_id": "61714042345592991242650283207041161607044873748774685082589583786302809304151", "price": "0.043", "size": "125", "side": "BUY", "hash": "8319af0030d49d400a64e4f3ebcb4f5f4418bef4", "best_bid": "0.055", "best_ask": "0.06"}], "timestamp": "1769384496966", "event_type": "price_change"}}
{"_local_timestamp": "2026-01-25T23:41:37.281432+00:00", "data": {"market": "0x8f055b9db0a2d64b59b33e03bc8885f05a7c5116b3e2b6bb458011d6e18fb5d0", "price_changes": [{"asset_id": "56848224247430609127378739012316303221353695236865761552990703763581756323619", "price": "0.97", "size": "270", "side": "SELL", "hash": "8a46e2d3660258075324aac160bebe4500d51873", "best_bid": "0.94", "best_ask": "0.945"}, {"asset_id": "61714042345592991242650283207041161607044873748774685082589583786302809304151", "price": "0.03", "size": "270", "side": "BUY", "hash": "40afc648364a276c76f700ca4b584968a3502350", "best_bid": "0.055", "best_ask": "0.06"}], "timestamp": "1769384497216", "event_type": "price_change"}}
{"_local_timestamp": "2026-01-25T23:41:37.653788+00:00", "data": {"market": "0x8f055b9db0a2d64b59b33e03bc8885f05a7c5116b3e2b6bb458011d6e18fb5d0", "price_changes": [{"asset_id": "56848224247430609127378739012316303221353695236865761552990703763581756323619", "price": "0.97", "size": "330", "side": "SELL", "hash": "ec3ab17fe1c011307d8ce2778958a038ac448888", "best_bid": "0.94", "best_ask": "0.945"}, {"asset_id": "61714042345592991242650283207041161607044873748774685082589583786302809304151", "price": "0.03", "size": "330", "side": "BUY", "hash": "84b840c989559158c5fc77f6fb01bdced723ff46", "best_bid": "0.055", "best_ask": "0.06"}], "timestamp": "1769384497568", "event_type": "price_change"}}
{"_local_timestamp": "2026-01-25T23:41:37.886194+00:00", "data": {"market": "0x8f055b9db0a2d64b59b33e03bc8885f05a7c5116b3e2b6bb458011d6e18fb5d0", "price_changes": [{"asset_id": "61714042345592991242650283207041161607044873748774685082589583786302809304151", "price": "0.006", "size": "24.23", "side": "BUY", "hash": "3bdd5b0dca32d0b05b87518a69fb7b6b04a2b86f", "best_bid": "0.055", "best_ask": "0.06"}, {"asset_id": "56848224247430609127378739012316303221353695236865761552990703763581756323619", "price": "0.994", "size": "24.23", "side": "SELL", "hash": "3285942d4b62ea35e276651af842161ff4c86555", "best_bid": "0.94", "best_ask": "0.945"}], "timestamp": "1769384497802", "event_type": "price_change"}}
{"_local_timestamp": "2026-01-25T23:41:37.984688+00:00", "data": {"market": "0x8f055b9db0a2d64b59b33e03bc8885f05a7c5116b3e2b6bb458011d6e18fb5d0", "price_changes": [{"asset_id": "56848224247430609127378739012316303221353695236865761552990703763581756323619", "price": "0.957", "size": "0", "side": "SELL", "hash": "ed4ddad3b393aace8c1b4bb610e2b4dbaf5018b3", "best_bid": "0.94", "best_ask": "0.945"}, {"asset_id": "61714042345592991242650283207041161607044873748774685082589583786302809304151", "price": "0.043", "size": "0", "side": "BUY", "hash": "c1022ab088d9c300b02938755a5e3f0bc3319724", "best_bid": "0.055", "best_ask": "0.06"}], "timestamp": "1769384497895", "event_type": "price_change"}}
{"_local_timestamp": "2026-01-25T23:41:38.043675+00:00", "data": {"market": "0x8f055b9db0a2d64b59b33e03bc8885f05a7c5116b3e2b6bb458011d6e18fb5d0", "price_changes": [{"asset_id": "56848224247430609127378739012316303221353695236865761552990703763581756323619", "price": "0.955", "size": "1376", "side": "SELL", "hash": "c06da8fd3efd10dc04ad0b7f0fe939aafe2559d1", "best_bid": "0.94", "best_ask": "0.945"}, {"asset_id": "61714042345592991242650283207041161607044873748774685082589583786302809304151", "price": "0.045", "size": "1376", "side": "BUY", "hash": "f67337789b57ba09cd237e2ce5694b2cdf51d61a", "best_bid": "0.055", "best_ask": "0.06"}], "timestamp": "1769384497945", "event_type": "price_change"}}
{"_local_timestamp": "2026-01-25T23:41:38.091522+00:00", "data": {"market": "0x8f055b9db0a2d64b59b33e03bc8885f05a7c5116b3e2b6bb458011d6e18fb5d0", "price_changes": [{"asset_id": "61714042345592991242650283207041161607044873748774685082589583786302809304151", "price": "0.012", "size": "5834", "side": "BUY", "hash": "09dfc42648bdaf8e8e9cb86c78e8b8337f8358a7", "best_bid": "0.055", "best_ask": "0.06"}, {"asset_id": "56848224247430609127378739012316303221353695236865761552990703763581756323619", "price": "0.988", "size": "5834", "side": "SELL", "hash": "49f3df777ebffed3a050b840c554b4525f6c478b", "best_bid": "0.94", "best_ask": "0.945"}], "timestamp": "1769384498000", "event_type": "price_change"}}
{"_local_timestamp": "2026-01-25T23:41:38.115092+00:00", "data": {"market": "0x8f055b9db0a2d64b59b33e03bc8885f05a7c5116b3e2b6bb458011d6e18fb5d0", "price_changes": [{"asset_id": "61714042345592991242650283207041161607044873748774685082589583786302809304151", "price": "0.031", "size": "581", "side": "BUY", "hash": "7b3dde3d8e46b5c8c22e25c2d01f2a41c563bc34", "best_bid": "0.055", "best_ask": "0.06"}, {"asset_id": "56848224247430609127378739012316303221353695236865761552990703763581756323619", "price": "0.969", "size": "581", "side": "SELL", "hash": "b8ef7afbce0dfb9199b58f3e4dbdae8e2afebaa4", "best_bid": "0.94", "best_ask": "0.945"}], "timestamp": "1769384498001", "event_type": "price_change"}}
{"_local_timestamp": "2026-01-25T23:41:38.126326+00:00", "data": {"market": "0x8f055b9db0a2d64b59b33e03bc8885f05a7c5116b3e2b6bb458011d6e18fb5d0", "price_changes": [{"asset_id": "61714042345592991242650283207041161607044873748774685082589583786302809304151", "price": "0.024", "size": "1174.68", "side": "BUY", "hash": "1d03759baea794f329dec6aae22473915772ee40", "best_bid": "0.055", "best_ask": "0.06"}, {"asset_id": "56848224247430609127378739012316303221353695236865761552990703763581756323619", "price": "0.976", "size": "1174.68", "side": "SELL", "hash": "15565aaa6334103d31cb682942ea3559206d21ee", "best_bid": "0.94", "best_ask": "0.945"}], "timestamp": "1769384498003", "event_type": "price_change"}}
{"_local_timestamp": "2026-01-25T23:41:38.127977+00:00", "data": {"market": "0x8f055b9db0a2d64b59b33e03bc8885f05a7c5116b3e2b6bb458011d6e18fb5d0", "price_changes": [{"asset_id": "61714042345592991242650283207041161607044873748774685082589583786302809304151", "price": "0.021", "size": "1667", "side": "BUY", "hash": "8496c16194786b9c1403979cd018d2919fee2806", "best_bid": "0.055", "best_ask": "0.06"}, {"asset_id": "56848224247430609127378739012316303221353695236865761552990703763581756323619", "price": "0.979", "size": "1667", "side": "SELL", "hash": "59e87db766a741f97ad39498398b2ca92a640fa8", "best_bid": "0.94", "best_ask": "0.945"}], "timestamp": "1769384498004", "event_type": "price_change"}}
{"_local_timestamp": "2026-01-25T23:41:38.129019+00:00", "data": {"market": "0x8f055b9db0a2d64b59b33e03bc8885f05a7c5116b3e2b6bb458011d6e18fb5d0", "price_changes": [{"asset_id": "61714042345592991242650283207041161607044873748774685082589583786302809304151", "price": "0.028", "size": "786", "side": "BUY", "hash": "6caca64a3d4b1a3de1ff3f49504d94857f832452", "best_bid": "0.055", "best_ask": "0.06"}, {"asset_id": "56848224247430609127378739012316303221353695236865761552990703763581756323619", "price": "0.972", "size": "786", "side": "SELL", "hash": "35aa5363352b677a523646142a40903de5d22f04", "best_bid": "0.94", "best_ask": "0.945"}], "timestamp": "1769384498005", "event_type": "price_change"}}
{"_local_timestamp": "2026-01-25T23:41:38.129540+00:00", "data": {"market": "0x8f055b9db0a2d64b59b33e03bc8885f05a7c5116b3e2b6bb458011d6e18fb5d0", "price_changes": [{"asset_id": "61714042345592991242650283207041161607044873748774685082589583786302809304151", "price": "0.018", "size": "33664.55", "side": "BUY", "hash": "847299c0a91a9d43218643fa4f42247bb6dc11b2", "best_bid": "0.055", "best_ask": "0.06"}, {"asset_id": "56848224247430609127378739012316303221353695236865761552990703763581756323619", "price": "0.982", "size": "33664.55", "side": "SELL", "hash": "eb5748fa154667feb60406e23acecf98df2b8134", "best_bid": "0.94", "best_ask": "0.945"}], "timestamp": "1769384498006", "event_type": "price_change"}}
{"_local_timestamp": "2026-01-25T23:41:38.132397+00:00", "data": {"market": "0x8f055b9db0a2d64b59b33e03bc8885f05a7c5116b3e2b6bb458011d6e18fb5d0", "price_changes": [{"asset_id": "61714042345592991242650283207041161607044873748774685082589583786302809304151", "price": "0.015", "size": "4067.33", "side": "BUY", "hash": "7e6da1bd64fd125c48b846259d045e296a916c10", "best_bid": "0.055", "best_ask": "0.06"}, {"asset_id": "56848224247430609127378739012316303221353695236865761552990703763581756323619", "price": "0.985", "size": "4067.33", "side": "SELL", "hash": "07637bcf33c95ebd6fc9f9aa427a6bac77428f1d", "best_bid": "0.94", "best_ask": "0.945"}], "timestamp": "1769384498007", "event_type": "price_change"}}
{"_local_timestamp": "2026-01-25T23:41:38.407727+00:00", "data": {"market": "0x8f055b9db0a2d64b59b33e03bc8885f05a7c5116b3e2b6bb458011d6e18fb5d0", "price_changes": [{"asset_id": "56848224247430609127378739012316303221353695236865761552990703763581756323619", "price": "0.97", "size": "270", "side": "SELL", "hash": "f3838175da62932990dc9595f4cdf8d19d838b98", "best_bid": "0.94", "best_ask": "0.945"}, {"asset_id": "61714042345592991242650283207041161607044873748774685082589583786302809304151", "price": "0.03", "size": "270", "side": "BUY", "hash": "9da00fbb3f768949d048ef6f3a19036063ff0615", "best_bid": "0.055", "best_ask": "0.06"}], "timestamp": "1769384498337", "event_type": "price_change"}}
{"_local_timestamp": "2026-01-25T23:41:38.769087+00:00", "data": {"market": "0x8f055b9db0a2d64b59b33e03bc8885f05a7c5116b3e2b6bb458011d6e18fb5d0", "price_changes": [{"asset_id": "56848224247430609127378739012316303221353695236865761552990703763581756323619", "price": "0.97", "size": "330", "side": "SELL", "hash": "8ef4a24c7478eebfdd2bd72c4f612cb67bc8fba1", "best_bid": "0.94", "best_ask": "0.945"}, {"asset_id": "61714042345592991242650283207041161607044873748774685082589583786302809304151", "price": "0.03", "size": "330", "side": "BUY", "hash": "d8a3fcfad16bafb53e7ac48d611f923911e54544", "best_bid": "0.055", "best_ask": "0.06"}], "timestamp": "1769384498698", "event_type": "price_change"}}
{"_local_timestamp": "2026-01-25T23:41:38.970269+00:00", "data": {"market": "0x8f055b9db0a2d64b59b33e03bc8885f05a7c5116b3e2b6bb458011d6e18fb5d0", "price_changes": [{"asset_id": "56848224247430609127378739012316303221353695236865761552990703763581756323619", "price": "0.955", "size": "1251", "side": "SELL", "hash": "bea4a91395f72d8c8c98daee9a504727234c7d03", "best_bid": "0.94", "best_ask": "0.945"}, {"asset_id": "61714042345592991242650283207041161607044873748774685082589583786302809304151", "price": "0.045", "size": "1251", "side": "BUY", "hash": "4d4692c9d41a03963fa3a18cd232d4350f066519", "best_bid": "0.055", "best_ask": "0.06"}], "timestamp": "1769384498900", "event_type": "price_change"}}
{"_local_timestamp": "2026-01-25T23:41:39.030485+00:00", "data": {"market": "0x8f055b9db0a2d64b59b33e03bc8885f05a7c5116b3e2b6bb458011d6e18fb5d0", "price_changes": [{"asset_id": "56848224247430609127378739012316303221353695236865761552990703763581756323619", "price": "0.957", "size": "125", "side": "SELL", "hash": "f7eb124e810173952f952ea3e14a1c5932c531ac", "best_bid": "0.94", "best_ask": "0.945"}, {"asset_id": "61714042345592991242650283207041161607044873748774685082589583786302809304151", "price": "0.043", "size": "125", "side": "BUY", "hash": "59780324ee3acca8aa6dbe023773128196c5e960", "best_bid": "0.055", "best_ask": "0.06"}], "timestamp": "1769384498963", "event_type": "price_change"}}
{"_local_timestamp": "2026-01-25T23:41:39.336339+00:00", "data": {"market": "0x8f055b9db0a2d64b59b33e03bc8885f05a7c5116b3e2b6bb458011d6e18fb5d0", "price_changes": [{"asset_id": "56848224247430609127378739012316303221353695236865761552990703763581756323619", "price": "0.97", "size": "270", "side": "SELL", "hash": "e463f4e62ae02c9d415bd680983eea4f7c135b26", "best_bid": "0.94", "best_ask": "0.945"}, {"asset_id": "61714042345592991242650283207041161607044873748774685082589583786302809304151", "price": "0.03", "size": "270", "side": "BUY", "hash": "c163cf89dca08498a04443c43822c80b62ea9826", "best_bid": "0.055", "best_ask": "0.06"}], "timestamp": "1769384499268", "event_type": "price_change"}}
{"_local_timestamp": "2026-01-25T23:41:39.410767+00:00", "data": {"market": "0xeb0f640f8e6979495efb462bca18e491a8624c07aecd89b9cea0ba62a4164226", "price_changes": [{"asset_id": "67044993355929871917109997788450094017244283163136736213822945937563487769385", "price": "0.02", "size": "1250", "side": "BUY", "hash": "5ec895ea5085d408c992b79c9ccb066bd9d75482", "best_bid": "0.25", "best_ask": "0.26"}, {"asset_id": "45834992705311952325019110769074251045520613427860944634211713333639342925215", "price": "0.98", "size": "1250", "side": "SELL", "hash": "f03789ff140ba2a6bccc91ee8379a19fe9fc0540", "best_bid": "0.74", "best_ask": "0.75"}], "timestamp": "1769384499295", "event_type": "price_change"}}
{"_local_timestamp": "2026-01-25T23:41:39.418391+00:00", "data": {"market": "0xeb0f640f8e6979495efb462bca18e491a8624c07aecd89b9cea0ba62a4164226", "price_changes": [{"asset_id": "67044993355929871917109997788450094017244283163136736213822945937563487769385", "price": "0.08", "size": "0", "side": "BUY", "hash": "5ec895ea5085d408c992b79c9ccb066bd9d75482", "best_bid": "0.25", "best_ask": "0.26"}, {"asset_id": "45834992705311952325019110769074251045520613427860944634211713333639342925215", "price": "0.92", "size": "0", "side": "SELL", "hash": "f03789ff140ba2a6bccc91ee8379a19fe9fc0540", "best_bid": "0.74", "best_ask": "0.75"}], "timestamp": "1769384499295", "event_type": "price_change"}}
{"_local_timestamp": "2026-01-25T23:41:39.424491+00:00", "data": {"market": "0xeb0f640f8e6979495efb462bca18e491a8624c07aecd89b9cea0ba62a4164226", "price_changes": [{"asset_id": "45834992705311952325019110769074251045520613427860944634211713333639342925215", "price": "0.19", "size": "147.36", "side": "BUY", "hash": "cd81d77c4d1314f413b79b81ee2d34b3cd6926e3", "best_bid": "0.74", "best_ask": "0.75"}, {"asset_id": "67044993355929871917109997788450094017244283163136736213822945937563487769385", "price": "0.81", "size": "147.36", "side": "SELL", "hash": "11392973f8dbe37be574c84ffce3eac153fbdbd7", "best_bid": "0.25", "best_ask": "0.26"}], "timestamp": "1769384499337", "event_type": "price_change"}}
{"_local_timestamp": "2026-01-25T23:41:39.696575+00:00", "data": {"market": "0xeb0f640f8e6979495efb462bca18e491a8624c07aecd89b9cea0ba62a4164226", "price_changes": [{"asset_id": "45834992705311952325019110769074251045520613427860944634211713333639342925215", "price": "0.18", "size": "1238", "side": "BUY", "hash": "40b5b0bb8f988ff04c41564184b03b96ba63c721", "best_bid": "0.74", "best_ask": "0.75"}, {"asset_id": "67044993355929871917109997788450094017244283163136736213822945937563487769385", "price": "0.82", "size": "1238", "side": "SELL", "hash": "cf1d63bbb2437ad7da64c390bc20893ed4459cb3", "best_bid": "0.25", "best_ask": "0.26"}], "timestamp": "1769384499607", "event_type": "price_change"}}
{"_local_timestamp": "2026-01-25T23:41:39.697232+00:00", "data": {"market": "0xeb0f640f8e6979495efb462bca18e491a8624c07aecd89b9cea0ba62a4164226", "price_changes": [{"asset_id": "67044993355929871917109997788450094017244283163136736213822945937563487769385", "price": "0.09", "size": "723", "side": "BUY", "hash": "3b5c9e062362b84b612bf38b1200a711c3f16755", "best_bid": "0.25", "best_ask": "0.26"}, {"asset_id": "45834992705311952325019110769074251045520613427860944634211713333639342925215", "price": "0.91", "size": "723", "side": "SELL", "hash": "0c31ed3f924e41529ad39f07a15781e8cf4e1e53", "best_bid": "0.74", "best_ask": "0.75"}], "timestamp": "1769384499611", "event_type": "price_change"}}
{"_local_timestamp": "2026-01-25T23:41:39.697885+00:00", "data": {"market": "0xeb0f640f8e6979495efb462bca18e491a8624c07aecd89b9cea0ba62a4164226", "price_changes": [{"asset_id": "67044993355929871917109997788450094017244283163136736213822945937563487769385", "price": "0.03", "size": "3940.58", "side": "BUY", "hash": "ff04f5bc259929b9324d3e9e04540cbf70c6a2b5", "best_bid": "0.25", "best_ask": "0.26"}, {"asset_id": "45834992705311952325019110769074251045520613427860944634211713333639342925215", "price": "0.97", "size": "3940.58", "side": "SELL", "hash": "446405434b740058c45699bbf4bb02520f05d0b0", "best_bid": "0.74", "best_ask": "0.75"}], "timestamp": "1769384499613", "event_type": "price_change"}}
{"_local_timestamp": "2026-01-25T23:41:39.764188+00:00", "data": {"market": "0xeb0f640f8e6979495efb462bca18e491a8624c07aecd89b9cea0ba62a4164226", "price_changes": [{"asset_id": "45834992705311952325019110769074251045520613427860944634211713333639342925215", "price": "0.24", "size": "1748", "side": "BUY", "hash": "c83a02e84bd63821493dc52c71ddfb90d344fbc2", "best_bid": "0.74", "best_ask": "0.75"}, {"asset_id": "67044993355929871917109997788450094017244283163136736213822945937563487769385", "price": "0.76", "size": "1748", "side": "SELL", "hash": "fd4fb15a7cf25feff72919c30e8e292e66ca83dd", "best_bid": "0.25", "best_ask": "0.26"}], "timestamp": "1769384499699", "event_type": "price_change"}}
{"_local_timestamp": "2026-01-25T23:41:39.885298+00:00", "data": {"market": "0x8f055b9db0a2d64b59b33e03bc8885f05a7c5116b3e2b6bb458011d6e18fb5d0", "price_changes": [{"asset_id": "56848224247430609127378739012316303221353695236865761552990703763581756323619", "price": "0.97", "size": "330", "side": "SELL", "hash": "fdfc7052287143714fbb8ec87125bd76965d6f6d", "best_bid": "0.94", "best_ask": "0.945"}, {"asset_id": "61714042345592991242650283207041161607044873748774685082589583786302809304151", "price": "0.03", "size": "330", "side": "BUY", "hash": "16f406630f84bd6ea12e79885575944e78da068b", "best_bid": "0.055", "best_ask": "0.06"}], "timestamp": "1769384499814", "event_type": "price_change"}}
{"_local_timestamp": "2026-01-25T23:41:39.973306+00:00", "data": {"market": "0x3da8ac5a617e2b32fbda49cbc5060917ab770abe9f74b11ffa36dcdb5b7a1195", "price_changes": [{"asset_id": "77932413699591385582408402058209008716103068377990837601822992291811637364241", "price": "0.22", "size": "1908", "side": "BUY", "hash": "3f2752e0b2d84b2a0887af66a2f3fb5f91eb913a", "best_bid": "0.78", "best_ask": "0.79"}, {"asset_id": "83722296194861509737807492105325276806804014660137138811708463053968062687084", "price": "0.78", "size": "1908", "side": "SELL", "hash": "184e12bc0d13e9e32ca7a0ba8adb83d743f06179", "best_bid": "0.21", "best_ask": "0.22"}], "timestamp": "1769384499906", "event_type": "price_change"}}
{"_local_timestamp": "2026-01-25T23:41:39.989620+00:00", "data": {"market": "0x8f055b9db0a2d64b59b33e03bc8885f05a7c5116b3e2b6bb458011d6e18fb5d0", "price_changes": [{"asset_id": "56848224247430609127378739012316303221353695236865761552990703763581756323619", "price": "0.957", "size": "0", "side": "SELL", "hash": "637e1965a68681e6ccf1840baca853aaa2c02c32", "best_bid": "0.94", "best_ask": "0.945"}, {"asset_id": "61714042345592991242650283207041161607044873748774685082589583786302809304151", "price": "0.043", "size": "0", "side": "BUY", "hash": "02d7dcd25aca719953fcdcf9b1196afe4cbe7dc6", "best_bid": "0.055", "best_ask": "0.06"}], "timestamp": "1769384499914", "event_type": "price_change"}}
{"_local_timestamp": "2026-01-25T23:41:40.050152+00:00", "data": {"market": "0x8f055b9db0a2d64b59b33e03bc8885f05a7c5116b3e2b6bb458011d6e18fb5d0", "price_changes": [{"asset_id": "56848224247430609127378739012316303221353695236865761552990703763581756323619", "price": "0.955", "size": "1376", "side": "SELL", "hash": "40076bc8bfee92677737cba1faf07451141115fa", "best_bid": "0.94", "best_ask": "0.945"}, {"asset_id": "61714042345592991242650283207041161607044873748774685082589583786302809304151", "price": "0.045", "size": "1376", "side": "BUY", "hash": "35648d35565200acbcfcc80efc13255bb50eb8f6", "best_bid": "0.055", "best_ask": "0.06"}], "timestamp": "1769384499978", "event_type": "price_change"}}
{"_local_timestamp": "2026-01-25T23:41:40.177498+00:00", "data": {"market": "0x8f055b9db0a2d64b59b33e03bc8885f05a7c5116b3e2b6bb458011d6e18fb5d0", "price_changes": [{"asset_id": "56848224247430609127378739012316303221353695236865761552990703763581756323619", "price": "0.241", "size": "1742", "side": "BUY", "hash": "1a13aa33b6e45fbee2dbe5247d4bd14e6a50b591", "best_bid": "0.94", "best_ask": "0.945"}, {"asset_id": "61714042345592991242650283207041161607044873748774685082589583786302809304151", "price": "0.759", "size": "1742", "side": "SELL", "hash": "6756fcf91224db64e14a46d021b61167c4fbd1b4", "best_bid": "0.055", "best_ask": "0.06"}], "timestamp": "1769384500109", "event_type": "price_change"}}
{"_local_timestamp": "2026-01-25T23:41:40.465762+00:00", "data": {"market": "0x8f055b9db0a2d64b59b33e03bc8885f05a7c5116b3e2b6bb458011d6e18fb5d0", "price_changes": [{"asset_id": "56848224247430609127378739012316303221353695236865761552990703763581756323619", "price": "0.97", "size": "270", "side": "SELL", "hash": "15c974ee4adce0364d8530e33eba2523ab381d34", "best_bid": "0.94", "best_ask": "0.945"}, {"asset_id": "61714042345592991242650283207041161607044873748774685082589583786302809304151", "price": "0.03", "size": "270", "side": "BUY", "hash": "25bfd85657a4d09eb740766f71e4dc3f6364f25a", "best_bid": "0.055", "best_ask": "0.06"}], "timestamp": "1769384500366", "event_type": "price_change"}}
{"_local_timestamp": "2026-01-25T23:41:40.716156+00:00", "data": {"market": "0x8f055b9db0a2d64b59b33e03bc8885f05a7c5116b3e2b6bb458011d6e18fb5d0", "price_changes": [{"asset_id": "56848224247430609127378739012316303221353695236865761552990703763581756323619", "price": "0.97", "size": "330", "side": "SELL", "hash": "9c028441134bcf773f7f13d14c0973073100518d", "best_bid": "0.94", "best_ask": "0.945"}, {"asset_id": "61714042345592991242650283207041161607044873748774685082589583786302809304151", "price": "0.03", "size": "330", "side": "BUY", "hash": "5349e8b74293b9b6670b7ddb78564a143a3e6cd7", "best_bid": "0.055", "best_ask": "0.06"}], "timestamp": "1769384500642", "event_type": "price_change"}}
{"_local_timestamp": "2026-01-25T23:41:40.978654+00:00", "data": {"market": "0x8f055b9db0a2d64b59b33e03bc8885f05a7c5116b3e2b6bb458011d6e18fb5d0", "price_changes": [{"asset_id": "56848224247430609127378739012316303221353695236865761552990703763581756323619", "price": "0.955", "size": "1251", "side": "SELL", "hash": "caa5263b84e75a1f4d4c7f02b4179129a0163ebe", "best_bid": "0.94", "best_ask": "0.945"}, {"asset_id": "61714042345592991242650283207041161607044873748774685082589583786302809304151", "price": "0.045", "size": "1251", "side": "BUY", "hash": "c3bdf7f0b75297183c51d1d777b9fb2db9356820", "best_bid": "0.055", "best_ask": "0.06"}], "timestamp": "1769384500904", "event_type": "price_change"}}
{"_local_timestamp": "2026-01-25T23:41:41.034711+00:00", "data": {"market": "0x8f055b9db0a2d64b59b33e03bc8885f05a7c5116b3e2b6bb458011d6e18fb5d0", "price_changes": [{"asset_id": "56848224247430609127378739012316303221353695236865761552990703763581756323619", "price": "0.957", "size": "125", "side": "SELL", "hash": "4a206e4541880577a33327db5fd91322a8ed85d8", "best_bid": "0.94", "best_ask": "0.945"}, {"asset_id": "61714042345592991242650283207041161607044873748774685082589583786302809304151", "price": "0.043", "size": "125", "side": "BUY", "hash": "5bf01aef8f3a6be3205e6d1aacce00ce730946ad", "best_bid": "0.055", "best_ask": "0.06"}], "timestamp": "1769384500958", "event_type": "price_change"}}
{"_local_timestamp": "2026-01-25T23:41:41.360082+00:00", "data": {"market": "0x8f055b9db0a2d64b59b33e03bc8885f05a7c5116b3e2b6bb458011d6e18fb5d0", "price_changes": [{"asset_id": "56848224247430609127378739012316303221353695236865761552990703763581756323619", "price": "0.97", "size": "270", "side": "SELL", "hash": "bf2ad5d47d9ddba200ad34208110eb054fb89add", "best_bid": "0.94", "best_ask": "0.945"}, {"asset_id": "61714042345592991242650283207041161607044873748774685082589583786302809304151", "price": "0.03", "size": "270", "side": "BUY", "hash": "cc3c47bc1e5cda726bc6c13fd56ecc0e355d603f", "best_bid": "0.055", "best_ask": "0.06"}], "timestamp": "1769384501290", "event_type": "price_change"}}
{"_local_timestamp": "2026-01-25T23:41:41.706540+00:00", "data": {"market": "0x8f055b9db0a2d64b59b33e03bc8885f05a7c5116b3e2b6bb458011d6e18fb5d0", "price_changes": [{"asset_id": "56848224247430609127378739012316303221353695236865761552990703763581756323619", "price": "0.97", "size": "330", "side": "SELL", "hash": "6529192c1a7ed7a887ee442fee29ead168548eff", "best_bid": "0.94", "best_ask": "0.945"}, {"asset_id": "61714042345592991242650283207041161607044873748774685082589583786302809304151", "price": "0.03", "size": "330", "side": "BUY", "hash": "cac82cb62f9d562b4ede67a5e7bf740d04e74891", "best_bid": "0.055", "best_ask": "0.06"}], "timestamp": "1769384501640", "event_type": "price_change"}}
{"_local_timestamp": "2026-01-25T23:41:41.965776+00:00", "data": {"market": "0x8f055b9db0a2d64b59b33e03bc8885f05a7c5116b3e2b6bb458011d6e18fb5d0", "price_changes": [{"asset_id": "56848224247430609127378739012316303221353695236865761552990703763581756323619", "price": "0.957", "size": "0", "side": "SELL", "hash": "48848ca8aa120c277d5f6aceaebfa32bf205c363", "best_bid": "0.94", "best_ask": "0.945"}, {"asset_id": "61714042345592991242650283207041161607044873748774685082589583786302809304151", "price": "0.043", "size": "0", "side": "BUY", "hash": "523af07cd35f50942aa1236c8e4ad0932b6c695a", "best_bid": "0.055", "best_ask": "0.06"}], "timestamp": "1769384501899", "event_type": "price_change"}}
{"_local_timestamp": "2026-01-25T23:41:42.044387+00:00", "data": {"market": "0xeb0f640f8e6979495efb462bca18e491a8624c07aecd89b9cea0ba62a4164226", "price_changes": [{"asset_id": "67044993355929871917109997788450094017244283163136736213822945937563487769385", "price": "0.01", "size": "6007.76", "side": "BUY", "hash": "d417008fb66141040b5fd0902b65f00a17e2b828", "best_bid": "0.25", "best_ask": "0.26"}, {"asset_id": "45834992705311952325019110769074251045520613427860944634211713333639342925215", "price": "0.99", "size": "6007.76", "side": "SELL", "hash": "b1deffabc33df3f425939d7bef5abfc3649a108d", "best_bid": "0.74", "best_ask": "0.75"}], "timestamp": "1769384501939", "event_type": "price_change"}}
{"_local_timestamp": "2026-01-25T23:41:42.045089+00:00", "data": {"market": "0xeb0f640f8e6979495efb462bca18e491a8624c07aecd89b9cea0ba62a4164226", "price_changes": [{"asset_id": "67044993355929871917109997788450094017244283163136736213822945937563487769385", "price": "0.03", "size": "806.58", "side": "BUY", "hash": "d417008fb66141040b5fd0902b65f00a17e2b828", "best_bid": "0.25", "best_ask": "0.26"}, {"asset_id": "45834992705311952325019110769074251045520613427860944634211713333639342925215", "price": "0.97", "size": "806.58", "side": "SELL", "hash": "b1deffabc33df3f425939d7bef5abfc3649a108d", "best_bid": "0.74", "best_ask": "0.75"}], "timestamp": "1769384501939", "event_type": "price_change"}}
{"_local_timestamp": "2026-01-25T23:41:42.046022+00:00", "data": {"market": "0xeb0f640f8e6979495efb462bca18e491a8624c07aecd89b9cea0ba62a4164226", "price_changes": [{"asset_id": "67044993355929871917109997788450094017244283163136736213822945937563487769385", "price": "0.09", "size": "200", "side": "BUY", "hash": "d417008fb66141040b5fd0902b65f00a17e2b828", "best_bid": "0.25", "best_ask": "0.26"}, {"asset_id": "45834992705311952325019110769074251045520613427860944634211713333639342925215", "price": "0.91", "size": "200", "side": "SELL", "hash": "b1deffabc33df3f425939d7bef5abfc3649a108d", "best_bid": "0.74", "best_ask": "0.75"}], "timestamp": "1769384501939", "event_type": "price_change"}}
{"_local_timestamp": "2026-01-25T23:41:42.046717+00:00", "data": {"market": "0x8f055b9db0a2d64b59b33e03bc8885f05a7c5116b3e2b6bb458011d6e18fb5d0", "price_changes": [{"asset_id": "56848224247430609127378739012316303221353695236865761552990703763581756323619", "price": "0.955", "size": "1376", "side": "SELL", "hash": "3e9084572007b5bb0c3b47c0bc7cec8a8608e19d", "best_bid": "0.94", "best_ask": "0.945"}, {"asset_id": "61714042345592991242650283207041161607044873748774685082589583786302809304151", "price": "0.045", "size": "1376", "side": "BUY", "hash": "2ac0b168651bc7f12be9e8af5b3a7287fcfc083c", "best_bid": "0.055", "best_ask": "0.06"}], "timestamp": "1769384501962", "event_type": "price_change"}}
{"_local_timestamp": "2026-01-25T23:41:42.060761+00:00", "data": {"market": "0xeb0f640f8e6979495efb462bca18e491a8624c07aecd89b9cea0ba62a4164226", "price_changes": [{"asset_id": "67044993355929871917109997788450094017244283163136736213822945937563487769385", "price": "0.02", "size": "10650", "side": "BUY", "hash": "daf59b91e4802595730a6bd31963a65a17b93a14", "best_bid": "0.25", "best_ask": "0.26"}, {"asset_id": "45834992705311952325019110769074251045520613427860944634211713333639342925215", "price": "0.98", "size": "10650", "side": "SELL", "hash": "23e8c6dc1218a40a507be4b77b77ea943a928f3a", "best_bid": "0.74", "best_ask": "0.75"}], "timestamp": "1769384501998", "event_type": "price_change"}}
{"_local_timestamp": "2026-01-25T23:41:42.064512+00:00", "data": {"market": "0xeb0f640f8e6979495efb462bca18e491a8624c07aecd89b9cea0ba62a4164226", "price_changes": [{"asset_id": "67044993355929871917109997788450094017244283163136736213822945937563487769385", "price": "0.1", "size": "471", "side": "BUY", "hash": "e0c517161a6517e38e96b2b782ca0ab4f7e365a7", "best_bid": "0.25", "best_ask": "0.26"}, {"asset_id": "45834992705311952325019110769074251045520613427860944634211713333639342925215", "price": "0.9", "size": "471", "side": "SELL", "hash": "c311ed37bc6f387f1f9b344d8d1b51e0f907eb4c", "best_bid": "0.74", "best_ask": "0.75"}], "timestamp": "1769384501999", "event_type": "price_change"}}
{"_local_timestamp": "2026-01-25T23:41:42.088363+00:00", "data": {"market": "0xeb0f640f8e6979495efb462bca18e491a8624c07aecd89b9cea0ba62a4164226", "price_changes": [{"asset_id": "67044993355929871917109997788450094017244283163136736213822945937563487769385", "price": "0.04", "size": "2350", "side": "BUY", "hash": "daa4d1ae8125e0a087af3a01dd55482eac9b921b", "best_bid": "0.25", "best_ask": "0.26"}, {"asset_id": "45834992705311952325019110769074251045520613427860944634211713333639342925215", "price": "0.96", "size": "2350", "side": "SELL", "hash": "663fd4ae3b903c9cfd67c5f9aab17a85386ffd9e", "best_bid": "0.74", "best_ask": "0.75"}], "timestamp": "1769384502003", "event_type": "price_change"}}
{"_local_timestamp": "2026-01-25T23:41:42.317849+00:00", "data": {"market": "0x8f055b9db0a2d64b59b33e03bc8885f05a7c5116b3e2b6bb458011d6e18fb5d0", "price_changes": [{"asset_id": "56848224247430609127378739012316303221353695236865761552990703763581756323619", "price": "0.97", "size": "270", "side": "SELL", "hash": "17a62364e1e85b33656c843f9fafd27ab1c0f03b", "best_bid": "0.94", "best_ask": "0.945"}, {"asset_id": "61714042345592991242650283207041161607044873748774685082589583786302809304151", "price": "0.03", "size": "270", "side": "BUY", "hash": "196e39978a8f8d5d53b109bed9824876fa38f40f", "best_bid": "0.055", "best_ask": "0.06"}], "timestamp": "1769384502243", "event_type": "price_change"}}
{"_local_timestamp": "2026-01-25T23:41:42.661521+00:00", "data": {"market": "0x8f055b9db0a2d64b59b33e03bc8885f05a7c5116b3e2b6bb458011d6e18fb5d0", "price_changes": [{"asset_id": "56848224247430609127378739012316303221353695236865761552990703763581756323619", "price": "0.97", "size": "330", "side": "SELL", "hash": "0af5e7cea72c4cb4d41dfeee2511397422c24a0d", "best_bid": "0.94", "best_ask": "0.945"}, {"asset_id": "61714042345592991242650283207041161607044873748774685082589583786302809304151", "price": "0.03", "size": "330", "side": "BUY", "hash": "7a702d1e240b7074d33dccceae8cd49952b21c3b", "best_bid": "0.055", "best_ask": "0.06"}], "timestamp": "1769384502594", "event_type": "price_change"}}
{"_local_timestamp": "2026-01-25T23:41:42.973532+00:00", "data": {"market": "0x8f055b9db0a2d64b59b33e03bc8885f05a7c5116b3e2b6bb458011d6e18fb5d0", "price_changes": [{"asset_id": "56848224247430609127378739012316303221353695236865761552990703763581756323619", "price": "0.955", "size": "1251", "side": "SELL", "hash": "6ea4f868a8895ca1fb34da01d9b779aa89aee1e2", "best_bid": "0.94", "best_ask": "0.945"}, {"asset_id": "61714042345592991242650283207041161607044873748774685082589583786302809304151", "price": "0.045", "size": "1251", "side": "BUY", "hash": "9e455ddc603b19d4635adb668b7b1cd1065b6964", "best_bid": "0.055", "best_ask": "0.06"}], "timestamp": "1769384502909", "event_type": "price_change"}}
{"_local_timestamp": "2026-01-25T23:41:43.046001+00:00", "data": {"market": "0x8f055b9db0a2d64b59b33e03bc8885f05a7c5116b3e2b6bb458011d6e18fb5d0", "price_changes": [{"asset_id": "56848224247430609127378739012316303221353695236865761552990703763581756323619", "price": "0.957", "size": "125", "side": "SELL", "hash": "2a060dc2338e59226eb44a594865dae7743f18ee", "best_bid": "0.94", "best_ask": "0.945"}, {"asset_id": "61714042345592991242650283207041161607044873748774685082589583786302809304151", "price": "0.043", "size": "125", "side": "BUY", "hash": "ccbac81c50dcf8c16d7ea172ba9b97cc9ede7fcd", "best_bid": "0.055", "best_ask": "0.06"}], "timestamp": "1769384502973", "event_type": "price_change"}}
{"_local_timestamp": "2026-01-25T23:41:43.335206+00:00", "data": {"market": "0x8f055b9db0a2d64b59b33e03bc8885f05a7c5116b3e2b6bb458011d6e18fb5d0", "price_changes": [{"asset_id": "56848224247430609127378739012316303221353695236865761552990703763581756323619", "price": "0.97", "size": "270", "side": "SELL", "hash": "bbffd71af62090c108fed1d4956accb7f464bd9f", "best_bid": "0.94", "best_ask": "0.945"}, {"asset_id": "61714042345592991242650283207041161607044873748774685082589583786302809304151", "price": "0.03", "size": "270", "side": "BUY", "hash": "86dd1ec150b363257771ff791502b5d244796188", "best_bid": "0.055", "best_ask": "0.06"}], "timestamp": "1769384503267", "event_type": "price_change"}}
{"_local_timestamp": "2026-01-25T23:41:43.697998+00:00", "data": {"market": "0x8f055b9db0a2d64b59b33e03bc8885f05a7c5116b3e2b6bb458011d6e18fb5d0", "price_changes": [{"asset_id": "56848224247430609127378739012316303221353695236865761552990703763581756323619", "price": "0.97", "size": "330", "side": "SELL", "hash": "b8d61f01694694243323e16b83fa58cec4b210c7", "best_bid": "0.94", "best_ask": "0.945"}, {"asset_id": "61714042345592991242650283207041161607044873748774685082589583786302809304151", "price": "0.03", "size": "330", "side": "BUY", "hash": "f209e66e0e98a2719e6bbfa0d94413bb69f01231", "best_bid": "0.055", "best_ask": "0.06"}], "timestamp": "1769384503631", "event_type": "price_change"}}
{"_local_timestamp": "2026-01-25T23:41:43.980284+00:00", "data": {"market": "0x8f055b9db0a2d64b59b33e03bc8885f05a7c5116b3e2b6bb458011d6e18fb5d0", "price_changes": [{"asset_id": "56848224247430609127378739012316303221353695236865761552990703763581756323619", "price": "0.957", "size": "0", "side": "SELL", "hash": "c1b39567978156e7c72c69a55477a2e45c751e4f", "best_bid": "0.94", "best_ask": "0.945"}, {"asset_id": "61714042345592991242650283207041161607044873748774685082589583786302809304151", "price": "0.043", "size": "0", "side": "BUY", "hash": "ab6e582b208416ae67efdb19cc377ec999f351e9", "best_bid": "0.055", "best_ask": "0.06"}], "timestamp": "1769384503910", "event_type": "price_change"}}
{"_local_timestamp": "2026-01-25T23:41:44.053390+00:00", "data": {"market": "0x8f055b9db0a2d64b59b33e03bc8885f05a7c5116b3e2b6bb458011d6e18fb5d0", "price_changes": [{"asset_id": "56848224247430609127378739012316303221353695236865761552990703763581756323619", "price": "0.955", "size": "1376", "side": "SELL", "hash": "cd80668c248607297ace2cde205d57a974143f47", "best_bid": "0.94", "best_ask": "0.945"}, {"asset_id": "61714042345592991242650283207041161607044873748774685082589583786302809304151", "price": "0.045", "size": "1376", "side": "BUY", "hash": "dc13067dc5030ffe142e23c0d948832d2907b511", "best_bid": "0.055", "best_ask": "0.06"}], "timestamp": "1769384503983", "event_type": "price_change"}}
{"_local_timestamp": "2026-01-25T23:41:44.351175+00:00", "data": {"market": "0x8f055b9db0a2d64b59b33e03bc8885f05a7c5116b3e2b6bb458011d6e18fb5d0", "price_changes": [{"asset_id": "56848224247430609127378739012316303221353695236865761552990703763581756323619", "price": "0.97", "size": "270", "side": "SELL", "hash": "cf9d9298fc902612ad1a19cfcb09ecdc0084847a", "best_bid": "0.94", "best_ask": "0.945"}, {"asset_id": "61714042345592991242650283207041161607044873748774685082589583786302809304151", "price": "0.03", "size": "270", "side": "BUY", "hash": "7348e93f22724517116a7d11db460d485c6ed949", "best_bid": "0.055", "best_ask": "0.06"}], "timestamp": "1769384504284", "event_type": "price_change"}}
{"_local_timestamp": "2026-01-25T23:41:44.775913+00:00", "data": {"market": "0x8f055b9db0a2d64b59b33e03bc8885f05a7c5116b3e2b6bb458011d6e18fb5d0", "price_changes": [{"asset_id": "56848224247430609127378739012316303221353695236865761552990703763581756323619", "price": "0.97", "size": "330", "side": "SELL", "hash": "e50e45d7234c7cf085e85ce97adeb71728d3074d", "best_bid": "0.94", "best_ask": "0.945"}, {"asset_id": "61714042345592991242650283207041161607044873748774685082589583786302809304151", "price": "0.03", "size": "330", "side": "BUY", "hash": "d7f056e92ee1a849fdb140e0eeb75efc38c7ccbd", "best_bid": "0.055", "best_ask": "0.06"}], "timestamp": "1769384504701", "event_type": "price_change"}}
{"_local_timestamp": "2026-01-25T23:41:44.972884+00:00", "data": {"market": "0x8f055b9db0a2d64b59b33e03bc8885f05a7c5116b3e2b6bb458011d6e18fb5d0", "price_changes": [{"asset_id": "56848224247430609127378739012316303221353695236865761552990703763581756323619", "price": "0.955", "size": "1251", "side": "SELL", "hash": "47e7fbaddb6d2a9f163c83b042de9f78b1179c19", "best_bid": "0.94", "best_ask": "0.945"}, {"asset_id": "61714042345592991242650283207041161607044873748774685082589583786302809304151", "price": "0.045", "size": "1251", "side": "BUY", "hash": "4c93abee00dad96c38fa61a62fb2046d125e5942", "best_bid": "0.055", "best_ask": "0.06"}], "timestamp": "1769384504910", "event_type": "price_change"}}
{"_local_timestamp": "2026-01-25T23:41:45.034912+00:00", "data": {"market": "0x8f055b9db0a2d64b59b33e03bc8885f05a7c5116b3e2b6bb458011d6e18fb5d0", "price_changes": [{"asset_id": "56848224247430609127378739012316303221353695236865761552990703763581756323619", "price": "0.957", "size": "125", "side": "SELL", "hash": "9a80ce08ea392e43bad5aa3ea5859a7ffdd7ee16", "best_bid": "0.94", "best_ask": "0.945"}, {"asset_id": "61714042345592991242650283207041161607044873748774685082589583786302809304151", "price": "0.043", "size": "125", "side": "BUY", "hash": "3d488c8766ba4f62dd3122d72c5349c37b1529eb", "best_bid": "0.055", "best_ask": "0.06"}], "timestamp": "1769384504970", "event_type": "price_change"}}
{"_local_timestamp": "2026-01-25T23:41:45.141821+00:00", "data": {"market": "0x3da8ac5a617e2b32fbda49cbc5060917ab770abe9f74b11ffa36dcdb5b7a1195", "price_changes": [{"asset_id": "77932413699591385582408402058209008716103068377990837601822992291811637364241", "price": "0.77", "size": "1010", "side": "BUY", "hash": "a607dca6804f2e1a2aebbe312a5f9a7416e7b3d9", "best_bid": "0.78", "best_ask": "0.79"}, {"asset_id": "83722296194861509737807492105325276806804014660137138811708463053968062687084", "price": "0.23", "size": "1010", "side": "SELL", "hash": "df5ba962ec8c912f9e026db925710dbdebd02622", "best_bid": "0.21", "best_ask": "0.22"}], "timestamp": "1769384505071", "event_type": "price_change"}}
{"_local_timestamp": "2026-01-25T23:41:45.142499+00:00", "data": {"market": "0x3da8ac5a617e2b32fbda49cbc5060917ab770abe9f74b11ffa36dcdb5b7a1195", "price_changes": [{"asset_id": "83722296194861509737807492105325276806804014660137138811708463053968062687084", "price": "0.2", "size": "3575", "side": "BUY", "hash": "b66935aae306534c637e63c3a151f77d05534df6", "best_bid": "0.21", "best_ask": "0.22"}, {"asset_id": "77932413699591385582408402058209008716103068377990837601822992291811637364241", "price": "0.8", "size": "3575", "side": "SELL", "hash": "a7e94ee3fe840d66dab8f6d52b2fbaeb0ea30e42", "best_bid": "0.78", "best_ask": "0.79"}], "timestamp": "1769384505072", "event_type": "price_change"}}
{"_local_timestamp": "2026-01-25T23:41:45.166024+00:00", "data": {"market": "0xeb0f640f8e6979495efb462bca18e491a8624c07aecd89b9cea0ba62a4164226", "price_changes": [{"asset_id": "45834992705311952325019110769074251045520613427860944634211713333639342925215", "price": "0.72", "size": "958.99", "side": "BUY", "hash": "fdbd354095384b40a314a5c528058b5ce419c8c5", "best_bid": "0.74", "best_ask": "0.75"}, {"asset_id": "67044993355929871917109997788450094017244283163136736213822945937563487769385", "price": "0.28", "size": "958.99", "side": "SELL", "hash": "4b70b68198307a1ddf7722656bfc7b3fd6be2ebc", "best_bid": "0.25", "best_ask": "0.26"}], "timestamp": "1769384505099", "event_type": "price_change"}}
{"_local_timestamp": "2026-01-25T23:41:45.189503+00:00", "data": {"market": "0xeb0f640f8e6979495efb462bca18e491a8624c07aecd89b9cea0ba62a4164226", "price_changes": [{"asset_id": "45834992705311952325019110769074251045520613427860944634211713333639342925215", "price": "0.72", "size": "2158.99", "side": "BUY", "hash": "df1f32c63b2d6a7c0a3f0f9d7ea2af732af4aea1", "best_bid": "0.74", "best_ask": "0.75"}, {"asset_id": "67044993355929871917109997788450094017244283163136736213822945937563487769385", "price": "0.28", "size": "2158.99", "side": "SELL", "hash": "618e36a3b21d01b008184f62ee34e5d9f40a5a1d", "best_bid": "0.25", "best_ask": "0.26"}], "timestamp": "1769384505125", "event_type": "price_change"}}
{"_local_timestamp": "2026-01-25T23:41:45.319208+00:00", "data": {"market": "0x8f055b9db0a2d64b59b33e03bc8885f05a7c5116b3e2b6bb458011d6e18fb5d0", "price_changes": [{"asset_id": "56848224247430609127378739012316303221353695236865761552990703763581756323619", "price": "0.97", "size": "270", "side": "SELL", "hash": "c4922497691fab4d0958f10a92040dfeb6a27f2b", "best_bid": "0.94", "best_ask": "0.945"}, {"asset_id": "61714042345592991242650283207041161607044873748774685082589583786302809304151", "price": "0.03", "size": "270", "side": "BUY", "hash": "3481bac0dc964dad99e417ff05e195902e4d03fb", "best_bid": "0.055", "best_ask": "0.06"}], "timestamp": "1769384505245", "event_type": "price_change"}}
{"_local_timestamp": "2026-01-25T23:41:45.586147+00:00", "data": {"market": "0x3da8ac5a617e2b32fbda49cbc5060917ab770abe9f74b11ffa36dcdb5b7a1195", "price_changes": [{"asset_id": "83722296194861509737807492105325276806804014660137138811708463053968062687084", "price": "0.2", "size": "3395", "side": "BUY", "hash": "d901ca4c40622a6f7bd114e912cb9fab57b2df8c", "best_bid": "0.21", "best_ask": "0.22"}, {"asset_id": "77932413699591385582408402058209008716103068377990837601822992291811637364241", "price": "0.8", "size": "3395", "side": "SELL", "hash": "7e17d6427de5521b20569c6deb4e505d997f6f98", "best_bid": "0.78", "best_ask": "0.79"}], "timestamp": "1769384505520", "event_type": "price_change"}}
{"_local_timestamp": "2026-01-25T23:41:45.586879+00:00", "data": {"market": "0x3da8ac5a617e2b32fbda49cbc5060917ab770abe9f74b11ffa36dcdb5b7a1195", "price_changes": [{"asset_id": "77932413699591385582408402058209008716103068377990837601822992291811637364241", "price": "0.77", "size": "880", "side": "BUY", "hash": "7735529923ec650dd0d1c6af86f87e1daf03a986", "best_bid": "0.78", "best_ask": "0.79"}, {"asset_id": "83722296194861509737807492105325276806804014660137138811708463053968062687084", "price": "0.23", "size": "880", "side": "SELL", "hash": "4c26930b0b04cec133bc6c6485f7acbaaf4e78d3", "best_bid": "0.21", "best_ask": "0.22"}], "timestamp": "1769384505521", "event_type": "price_change"}}
{"_local_timestamp": "2026-01-25T23:41:45.587481+00:00", "data": {"market": "0x3da8ac5a617e2b32fbda49cbc5060917ab770abe9f74b11ffa36dcdb5b7a1195", "price_changes": [{"asset_id": "77932413699591385582408402058209008716103068377990837601822992291811637364241", "price": "0.76", "size": "1450.5", "side": "BUY", "hash": "7735529923ec650dd0d1c6af86f87e1daf03a986", "best_bid": "0.78", "best_ask": "0.79"}, {"asset_id": "83722296194861509737807492105325276806804014660137138811708463053968062687084", "price": "0.24", "size": "1450.5", "side": "SELL", "hash": "4c26930b0b04cec133bc6c6485f7acbaaf4e78d3", "best_bid": "0.21", "best_ask": "0.22"}], "timestamp": "1769384505521", "event_type": "price_change"}}
{"_local_timestamp": "2026-01-25T23:41:45.689966+00:00", "data": {"market": "0x8f055b9db0a2d64b59b33e03bc8885f05a7c5116b3e2b6bb458011d6e18fb5d0", "price_changes": [{"asset_id": "56848224247430609127378739012316303221353695236865761552990703763581756323619", "price": "0.97", "size": "330", "side": "SELL", "hash": "2856e8728cc9e9a43561e6c0cbae347f47324c17", "best_bid": "0.94", "best_ask": "0.945"}, {"asset_id": "61714042345592991242650283207041161607044873748774685082589583786302809304151", "price": "0.03", "size": "330", "side": "BUY", "hash": "fb8383ccef67429b6ad9f3ac943ab7605572a977", "best_bid": "0.055", "best_ask": "0.06"}], "timestamp": "1769384505625", "event_type": "price_change"}}
{"_local_timestamp": "2026-01-25T23:41:45.722752+00:00", "data": {"market": "0xeb0f640f8e6979495efb462bca18e491a8624c07aecd89b9cea0ba62a4164226", "price_changes": [{"asset_id": "45834992705311952325019110769074251045520613427860944634211713333639342925215", "price": "0.72", "size": "958.99", "side": "BUY", "hash": "74563515b6d8e588c0714a446806a8f68ebaf29d", "best_bid": "0.74", "best_ask": "0.75"}, {"asset_id": "67044993355929871917109997788450094017244283163136736213822945937563487769385", "price": "0.28", "size": "958.99", "side": "SELL", "hash": "8c236ee63f36e1e1022716f0d093b6516337be7e", "best_bid": "0.25", "best_ask": "0.26"}], "timestamp": "1769384505657", "event_type": "price_change"}}
{"_local_timestamp": "2026-01-25T23:41:45.754760+00:00", "data": {"market": "0xeb0f640f8e6979495efb462bca18e491a8624c07aecd89b9cea0ba62a4164226", "price_changes": [{"asset_id": "45834992705311952325019110769074251045520613427860944634211713333639342925215", "price": "0.72", "size": "2008.99", "side": "BUY", "hash": "410eb5002f8423ff7407138080874844fb04c5ea", "best_bid": "0.74", "best_ask": "0.75"}, {"asset_id": "67044993355929871917109997788450094017244283163136736213822945937563487769385", "price": "0.28", "size": "2008.99", "side": "SELL", "hash": "e7aa6b3b7f8d2f46e4cd99d71681105e5137c0b8", "best_bid": "0.25", "best_ask": "0.26"}], "timestamp": "1769384505685", "event_type": "price_change"}}
{"_local_timestamp": "2026-01-25T23:41:45.884002+00:00", "data": {"market": "0x3da8ac5a617e2b32fbda49cbc5060917ab770abe9f74b11ffa36dcdb5b7a1195", "price_changes": [{"asset_id": "77932413699591385582408402058209008716103068377990837601822992291811637364241", "price": "0.77", "size": "1130", "side": "BUY", "hash": "f80b03be5e0a54488481b375875126094eca655d", "best_bid": "0.78", "best_ask": "0.79"}, {"asset_id": "83722296194861509737807492105325276806804014660137138811708463053968062687084", "price": "0.23", "size": "1130", "side": "SELL", "hash": "81a8e2f0b729908886637257ef115e5b3a60bfc6", "best_bid": "0.21", "best_ask": "0.22"}], "timestamp": "1769384505816", "event_type": "price_change"}}
{"_local_timestamp": "2026-01-25T23:41:45.884949+00:00", "data": {"market": "0x3da8ac5a617e2b32fbda49cbc5060917ab770abe9f74b11ffa36dcdb5b7a1195", "price_changes": [{"asset_id": "83722296194861509737807492105325276806804014660137138811708463053968062687084", "price": "0.2", "size": "3645", "side": "BUY", "hash": "15a92ed6b38a611c3d5ec9bd797f2165fd21986c", "best_bid": "0.21", "best_ask": "0.22"}, {"asset_id": "77932413699591385582408402058209008716103068377990837601822992291811637364241", "price": "0.8", "size": "3645", "side": "SELL", "hash": "e6052d6d2938fc2e0f59877fdaffab0788573f93", "best_bid": "0.78", "best_ask": "0.79"}], "timestamp": "1769384505816", "event_type": "price_change"}}
{"_local_timestamp": "2026-01-25T23:41:45.982142+00:00", "data": {"market": "0x8f055b9db0a2d64b59b33e03bc8885f05a7c5116b3e2b6bb458011d6e18fb5d0", "price_changes": [{"asset_id": "56848224247430609127378739012316303221353695236865761552990703763581756323619", "price": "0.957", "size": "0", "side": "SELL", "hash": "51a0a4a99ada6b223090cbc69f25a0d15c0553b3", "best_bid": "0.94", "best_ask": "0.945"}, {"asset_id": "61714042345592991242650283207041161607044873748774685082589583786302809304151", "price": "0.043", "size": "0", "side": "BUY", "hash": "fced122d94ccfe2f17bba63503b1290a33a4fb35", "best_bid": "0.055", "best_ask": "0.06"}], "timestamp": "1769384505910", "event_type": "price_change"}}
{"_local_timestamp": "2026-01-25T23:41:46.284935+00:00", "data": {"market": "0x8f055b9db0a2d64b59b33e03bc8885f05a7c5116b3e2b6bb458011d6e18fb5d0", "price_changes": [{"asset_id": "56848224247430609127378739012316303221353695236865761552990703763581756323619", "price": "0.955", "size": "1376", "side": "SELL", "hash": "7e10955364dcb70684abf864c23d1cc8ad037e60", "best_bid": "0.94", "best_ask": "0.945"}, {"asset_id": "61714042345592991242650283207041161607044873748774685082589583786302809304151", "price": "0.045", "size": "1376", "side": "BUY", "hash": "71d1a2edb29b2ae7573872827f54bd5445c561db", "best_bid": "0.055", "best_ask": "0.06"}], "timestamp": "1769384505973", "event_type": "price_change"}}
{"_local_timestamp": "2026-01-25T23:41:46.327955+00:00", "data": {"market": "0x8f055b9db0a2d64b59b33e03bc8885f05a7c5116b3e2b6bb458011d6e18fb5d0", "price_changes": [{"asset_id": "56848224247430609127378739012316303221353695236865761552990703763581756323619", "price": "0.97", "size": "270", "side": "SELL", "hash": "ff1cce90c7e106e4b8d013fc2ca997d0be242868", "best_bid": "0.94", "best_ask": "0.945"}, {"asset_id": "61714042345592991242650283207041161607044873748774685082589583786302809304151", "price": "0.03", "size": "270", "side": "BUY", "hash": "b59af5f81523cd1ca08bbfcbc77d446cfe63b7fd", "best_bid": "0.055", "best_ask": "0.06"}], "timestamp": "1769384506254", "event_type": "price_change"}}
{"_local_timestamp": "2026-01-25T23:41:46.746718+00:00", "data": {"market": "0x8f055b9db0a2d64b59b33e03bc8885f05a7c5116b3e2b6bb458011d6e18fb5d0", "price_changes": [{"asset_id": "56848224247430609127378739012316303221353695236865761552990703763581756323619", "price": "0.97", "size": "330", "side": "SELL", "hash": "827d84059d97097936e3546c5b85de036920809e", "best_bid": "0.94", "best_ask": "0.945"}, {"asset_id": "61714042345592991242650283207041161607044873748774685082589583786302809304151", "price": "0.03", "size": "330", "side": "BUY", "hash": "1029b03194077f3ec5702ebf08c74030ad2ef69f", "best_bid": "0.055", "best_ask": "0.06"}], "timestamp": "1769384506682", "event_type": "price_change"}}
{"_local_timestamp": "2026-01-25T23:41:46.975639+00:00", "data": {"market": "0x8f055b9db0a2d64b59b33e03bc8885f05a7c5116b3e2b6bb458011d6e18fb5d0", "price_changes": [{"asset_id": "56848224247430609127378739012316303221353695236865761552990703763581756323619", "price": "0.955", "size": "1251", "side": "SELL", "hash": "7acbcabf8b55cbc790aba7fc732200f3fa321d28", "best_bid": "0.94", "best_ask": "0.945"}, {"asset_id": "61714042345592991242650283207041161607044873748774685082589583786302809304151", "price": "0.045", "size": "1251", "side": "BUY", "hash": "c345ad719f185fe34050a89f0cf0555e9249243e", "best_bid": "0.055", "best_ask": "0.06"}], "timestamp": "1769384506908", "event_type": "price_change"}}
{"_local_timestamp": "2026-01-25T23:41:47.051673+00:00", "data": {"market": "0x8f055b9db0a2d64b59b33e03bc8885f05a7c5116b3e2b6bb458011d6e18fb5d0", "price_changes": [{"asset_id": "56848224247430609127378739012316303221353695236865761552990703763581756323619", "price": "0.957", "size": "125", "side": "SELL", "hash": "0021c51a00e70860894a7199f168fab6cb39ae6d", "best_bid": "0.94", "best_ask": "0.945"}, {"asset_id": "61714042345592991242650283207041161607044873748774685082589583786302809304151", "price": "0.043", "size": "125", "side": "BUY", "hash": "98165198175f4ffa1d1b6b1a3b16bc68e5d6acff", "best_bid": "0.055", "best_ask": "0.06"}], "timestamp": "1769384506979", "event_type": "price_change"}}
{"_local_timestamp": "2026-01-25T23:41:47.102201+00:00", "data": {"market": "0x360b5ab61e12806d96430a792f43d4c38fa7a33345c7c99db897accb59983db6", "price_changes": [{"asset_id": "26609800537692465524771607284115123570169751799662193302165096740333425504635", "price": "0.08", "size": "1162.33", "side": "BUY", "hash": "b6573532c8eb814298b9e5ccca5bdb5535a33518", "best_bid": "0.18", "best_ask": "0.2"}, {"asset_id": "101138268140267284344946310498458459688833372731909500410366045847576281737159", "price": "0.92", "size": "1162.33", "side": "SELL", "hash": "afe5d42780cb064d6ae1863e49966f511147fdee", "best_bid": "0.8", "best_ask": "0.82"}], "timestamp": "1769384507003", "event_type": "price_change"}}
{"_local_timestamp": "2026-01-25T23:41:47.374828+00:00", "data": {"market": "0x8f055b9db0a2d64b59b33e03bc8885f05a7c5116b3e2b6bb458011d6e18fb5d0", "price_changes": [{"asset_id": "56848224247430609127378739012316303221353695236865761552990703763581756323619", "price": "0.97", "size": "270", "side": "SELL", "hash": "bb8bf6489d7d921adf855fc24952bf91cd2a3020", "best_bid": "0.94", "best_ask": "0.945"}, {"asset_id": "61714042345592991242650283207041161607044873748774685082589583786302809304151", "price": "0.03", "size": "270", "side": "BUY", "hash": "19ffeff0809cae54a451a9adb604b3bcd681cdb6", "best_bid": "0.055", "best_ask": "0.06"}], "timestamp": "1769384507300", "event_type": "price_change"}}
{"_local_timestamp": "2026-01-25T23:41:47.706796+00:00", "data": {"market": "0x8f055b9db0a2d64b59b33e03bc8885f05a7c5116b3e2b6bb458011d6e18fb5d0", "price_changes": [{"asset_id": "56848224247430609127378739012316303221353695236865761552990703763581756323619", "price": "0.97", "size": "330", "side": "SELL", "hash": "07402913e60a1d58df1df71b26a4666cbd8d1a65", "best_bid": "0.94", "best_ask": "0.945"}, {"asset_id": "61714042345592991242650283207041161607044873748774685082589583786302809304151", "price": "0.03", "size": "330", "side": "BUY", "hash": "9a2da7ef57b0fa8fa4edab5a26df412050bafcb2", "best_bid": "0.055", "best_ask": "0.06"}], "timestamp": "1769384507637", "event_type": "price_change"}}
{"_local_timestamp": "2026-01-25T23:41:47.977962+00:00", "data": {"market": "0x8f055b9db0a2d64b59b33e03bc8885f05a7c5116b3e2b6bb458011d6e18fb5d0", "price_changes": [{"asset_id": "56848224247430609127378739012316303221353695236865761552990703763581756323619", "price": "0.957", "size": "0", "side": "SELL", "hash": "4671b124a5a97055c9201ac3c89085e921c6efde", "best_bid": "0.94", "best_ask": "0.945"}, {"asset_id": "61714042345592991242650283207041161607044873748774685082589583786302809304151", "price": "0.043", "size": "0", "side": "BUY", "hash": "da9d971fd6bf8e02afd9a3fe01320c5b1b7a38af", "best_bid": "0.055", "best_ask": "0.06"}], "timestamp": "1769384507913", "event_type": "price_change"}}
{"_local_timestamp": "2026-01-25T23:41:48.042856+00:00", "data": {"market": "0x8f055b9db0a2d64b59b33e03bc8885f05a7c5116b3e2b6bb458011d6e18fb5d0", "price_changes": [{"asset_id": "56848224247430609127378739012316303221353695236865761552990703763581756323619", "price": "0.955", "size": "1376", "side": "SELL", "hash": "8250da47c5bed3c9d72a97a18986cd3f5bc36b7f", "best_bid": "0.94", "best_ask": "0.945"}, {"asset_id": "61714042345592991242650283207041161607044873748774685082589583786302809304151", "price": "0.045", "size": "1376", "side": "BUY", "hash": "05c19954cd99fc37478dc822117df87e94031e50", "best_bid": "0.055", "best_ask": "0.06"}], "timestamp": "1769384507976", "event_type": "price_change"}}
{"_local_timestamp": "2026-01-25T23:41:48.300973+00:00", "data": {"market": "0x8f055b9db0a2d64b59b33e03bc8885f05a7c5116b3e2b6bb458011d6e18fb5d0", "price_changes": [{"asset_id": "56848224247430609127378739012316303221353695236865761552990703763581756323619", "price": "0.97", "size": "270", "side": "SELL", "hash": "93e5776ebce25bada3387b9fc6eb32d5342ebbea", "best_bid": "0.94", "best_ask": "0.945"}, {"asset_id": "61714042345592991242650283207041161607044873748774685082589583786302809304151", "price": "0.03", "size": "270", "side": "BUY", "hash": "3512607f352d847d0a1a8575b23014d92e3ef8fd", "best_bid": "0.055", "best_ask": "0.06"}], "timestamp": "1769384508238", "event_type": "price_change"}}
{"_local_timestamp": "2026-01-25T23:41:48.803835+00:00", "data": {"market": "0x8f055b9db0a2d64b59b33e03bc8885f05a7c5116b3e2b6bb458011d6e18fb5d0", "price_changes": [{"asset_id": "56848224247430609127378739012316303221353695236865761552990703763581756323619", "price": "0.97", "size": "330", "side": "SELL", "hash": "7473e84f9702680fa0373eb2769e485e57f05a3b", "best_bid": "0.94", "best_ask": "0.945"}, {"asset_id": "61714042345592991242650283207041161607044873748774685082589583786302809304151", "price": "0.03", "size": "330", "side": "BUY", "hash": "fd0daebd13748ed465bffb057b2ee026a942b8e0", "best_bid": "0.055", "best_ask": "0.06"}], "timestamp": "1769384508726", "event_type": "price_change"}}
{"_local_timestamp": "2026-01-25T23:41:48.978214+00:00", "data": {"market": "0x8f055b9db0a2d64b59b33e03bc8885f05a7c5116b3e2b6bb458011d6e18fb5d0", "price_changes": [{"asset_id": "56848224247430609127378739012316303221353695236865761552990703763581756323619", "price": "0.955", "size": "1251", "side": "SELL", "hash": "e81115fc73032d3e957acffe4f4a8dea3af93881", "best_bid": "0.94", "best_ask": "0.945"}, {"asset_id": "61714042345592991242650283207041161607044873748774685082589583786302809304151", "price": "0.045", "size": "1251", "side": "BUY", "hash": "483d49252e4f88030069dddff1bf5790c7759d3f", "best_bid": "0.055", "best_ask": "0.06"}], "timestamp": "1769384508912", "event_type": "price_change"}}
{"_local_timestamp": "2026-01-25T23:41:49.082431+00:00", "data": {"market": "0x8f055b9db0a2d64b59b33e03bc8885f05a7c5116b3e2b6bb458011d6e18fb5d0", "price_changes": [{"asset_id": "56848224247430609127378739012316303221353695236865761552990703763581756323619", "price": "0.957", "size": "125", "side": "SELL", "hash": "a65ebf1ab9cd35a92672dbbf9fd458729b1f0732", "best_bid": "0.94", "best_ask": "0.945"}, {"asset_id": "61714042345592991242650283207041161607044873748774685082589583786302809304151", "price": "0.043", "size": "125", "side": "BUY", "hash": "f8cd40c9cc08a3da255abbf3a462ecc4e9aa7bf3", "best_bid": "0.055", "best_ask": "0.06"}], "timestamp": "1769384508976", "event_type": "price_change"}}
{"_local_timestamp": "2026-01-25T23:41:49.399036+00:00", "data": {"market": "0x8f055b9db0a2d64b59b33e03bc8885f05a7c5116b3e2b6bb458011d6e18fb5d0", "price_changes": [{"asset_id": "56848224247430609127378739012316303221353695236865761552990703763581756323619", "price": "0.97", "size": "270", "side": "SELL", "hash": "9e23bce261e141ef4020e20049ea1ddccd63da9e", "best_bid": "0.94", "best_ask": "0.945"}, {"asset_id": "61714042345592991242650283207041161607044873748774685082589583786302809304151", "price": "0.03", "size": "270", "side": "BUY", "hash": "2ab9dfcb00e00688d4e088834f28618d056f72cd", "best_bid": "0.055", "best_ask": "0.06"}], "timestamp": "1769384509328", "event_type": "price_change"}}
{"_local_timestamp": "2026-01-25T23:41:49.478751+00:00", "data": {"market": "0x3da8ac5a617e2b32fbda49cbc5060917ab770abe9f74b11ffa36dcdb5b7a1195", "price_changes": [{"asset_id": "77932413699591385582408402058209008716103068377990837601822992291811637364241", "price": "0.23", "size": "100", "side": "BUY", "hash": "4a60c9a71d39300cd113cb69beb0dc4b23046533", "best_bid": "0.78", "best_ask": "0.79"}, {"asset_id": "83722296194861509737807492105325276806804014660137138811708463053968062687084", "price": "0.77", "size": "100", "side": "SELL", "hash": "9d786d963e00b3b85d8309cb8c024c638ed74eb6", "best_bid": "0.21", "best_ask": "0.22"}], "timestamp": "1769384509400", "event_type": "price_change"}}
{"_local_timestamp": "2026-01-25T23:41:49.574605+00:00", "data": {"market": "0x3da8ac5a617e2b32fbda49cbc5060917ab770abe9f74b11ffa36dcdb5b7a1195", "price_changes": [{"asset_id": "77932413699591385582408402058209008716103068377990837601822992291811637364241", "price": "0.76", "size": "1325.5", "side": "BUY", "hash": "ef7cd7261496e8d75435c61097ec3a8219d1644a", "best_bid": "0.78", "best_ask": "0.79"}, {"asset_id": "83722296194861509737807492105325276806804014660137138811708463053968062687084", "price": "0.24", "size": "1325.5", "side": "SELL", "hash": "5ce7af597cd9703fbea5671181399220de376c4a", "best_bid": "0.21", "best_ask": "0.22"}], "timestamp": "1769384509505", "event_type": "price_change"}}
{"_local_timestamp": "2026-01-25T23:41:49.583528+00:00", "data": {"market": "0x3da8ac5a617e2b32fbda49cbc5060917ab770abe9f74b11ffa36dcdb5b7a1195", "price_changes": [{"asset_id": "77932413699591385582408402058209008716103068377990837601822992291811637364241", "price": "0.76", "size": "1250.5", "side": "BUY", "hash": "d80f0e3e552b4503826c3447bd02cd47beb6dd4d", "best_bid": "0.78", "best_ask": "0.79"}, {"asset_id": "83722296194861509737807492105325276806804014660137138811708463053968062687084", "price": "0.24", "size": "1250.5", "side": "SELL", "hash": "a1237fae295dd1e827de1123ab3ee268625be58d", "best_bid": "0.21", "best_ask": "0.22"}], "timestamp": "1769384509511", "event_type": "price_change"}}
{"_local_timestamp": "2026-01-25T23:41:49.623236+00:00", "data": {"market": "0x3da8ac5a617e2b32fbda49cbc5060917ab770abe9f74b11ffa36dcdb5b7a1195", "price_changes": [{"asset_id": "77932413699591385582408402058209008716103068377990837601822992291811637364241", "price": "0.77", "size": "1205", "side": "BUY", "hash": "09d629bc0a69eecf1fe9a69e963d7f9b32c7b2db", "best_bid": "0.78", "best_ask": "0.79"}, {"asset_id": "83722296194861509737807492105325276806804014660137138811708463053968062687084", "price": "0.23", "size": "1205", "side": "SELL", "hash": "4f203fb2666342b8b2dd971406d0b940dc97d295", "best_bid": "0.21", "best_ask": "0.22"}], "timestamp": "1769384509557", "event_type": "price_change"}}
{"_local_timestamp": "2026-01-25T23:41:49.630296+00:00", "data": {"market": "0x3da8ac5a617e2b32fbda49cbc5060917ab770abe9f74b11ffa36dcdb5b7a1195", "price_changes": [{"asset_id": "77932413699591385582408402058209008716103068377990837601822992291811637364241", "price": "0.77", "size": "1330", "side": "BUY", "hash": "a0b08272924a5903b9560436679db8b8ccb66b01", "best_bid": "0.78", "best_ask": "0.79"}, {"asset_id": "83722296194861509737807492105325276806804014660137138811708463053968062687084", "price": "0.23", "size": "1330", "side": "SELL", "hash": "dbd79099238ea38291b3b780b51f131bbd7155ed", "best_bid": "0.21", "best_ask": "0.22"}], "timestamp": "1769384509564", "event_type": "price_change"}}
{"_local_timestamp": "2026-01-25T23:41:49.746857+00:00", "data": {"market": "0x3da8ac5a617e2b32fbda49cbc5060917ab770abe9f74b11ffa36dcdb5b7a1195", "price_changes": [{"asset_id": "77932413699591385582408402058209008716103068377990837601822992291811637364241", "price": "0.21", "size": "333.33", "side": "BUY", "hash": "ea8121fcdb0e49a843106b8fad6d0c65b63a9ba1", "best_bid": "0.78", "best_ask": "0.79"}, {"asset_id": "83722296194861509737807492105325276806804014660137138811708463053968062687084", "price": "0.79", "size": "333.33", "side": "SELL", "hash": "5616586059934cbe7c0d4b1128c4684399b28cc8", "best_bid": "0.21", "best_ask": "0.22"}], "timestamp": "1769384509658", "event_type": "price_change"}}
{"_local_timestamp": "2026-01-25T23:41:49.809878+00:00", "data": {"market": "0x8f055b9db0a2d64b59b33e03bc8885f05a7c5116b3e2b6bb458011d6e18fb5d0", "price_changes": [{"asset_id": "56848224247430609127378739012316303221353695236865761552990703763581756323619", "price": "0.97", "size": "330", "side": "SELL", "hash": "044fe622f03796e8dfcdd7cd482a60137d34e4b9", "best_bid": "0.94", "best_ask": "0.945"}, {"asset_id": "61714042345592991242650283207041161607044873748774685082589583786302809304151", "price": "0.03", "size": "330", "side": "BUY", "hash": "86a2b52442fdddcbd42a601d82f52d5bca7d3506", "best_bid": "0.055", "best_ask": "0.06"}], "timestamp": "1769384509683", "event_type": "price_change"}}
{"_local_timestamp": "2026-01-25T23:41:49.989262+00:00", "data": {"market": "0x8f055b9db0a2d64b59b33e03bc8885f05a7c5116b3e2b6bb458011d6e18fb5d0", "price_changes": [{"asset_id": "56848224247430609127378739012316303221353695236865761552990703763581756323619", "price": "0.957", "size": "0", "side": "SELL", "hash": "c4ff4839964be1bba1864418c29c5908e8a8f00f", "best_bid": "0.94", "best_ask": "0.945"}, {"asset_id": "61714042345592991242650283207041161607044873748774685082589583786302809304151", "price": "0.043", "size": "0", "side": "BUY", "hash": "e9afc4c51b3c9ea499de74fb9e4843578a027fc9", "best_bid": "0.055", "best_ask": "0.06"}], "timestamp": "1769384509917", "event_type": "price_change"}}
{"_local_timestamp": "2026-01-25T23:41:50.039665+00:00", "data": {"market": "0x8f055b9db0a2d64b59b33e03bc8885f05a7c5116b3e2b6bb458011d6e18fb5d0", "price_changes": [{"asset_id": "56848224247430609127378739012316303221353695236865761552990703763581756323619", "price": "0.955", "size": "1376", "side": "SELL", "hash": "d456874c0dc81b6c1031c643932ff515f9593d19", "best_bid": "0.94", "best_ask": "0.945"}, {"asset_id": "61714042345592991242650283207041161607044873748774685082589583786302809304151", "price": "0.045", "size": "1376", "side": "BUY", "hash": "2cb67b12477162aec9d95e673bd113182d7f8055", "best_bid": "0.055", "best_ask": "0.06"}], "timestamp": "1769384509967", "event_type": "price_change"}}
{"_local_timestamp": "2026-01-25T23:41:50.078756+00:00", "data": {"market": "0x5a4bae5b326d8ad4ef51e29b140afd57dc1dfb3c44e1c805209eacb65a656dd7", "price_changes": [{"asset_id": "59504136924064087795648081133235705846655371799758292499235575393658009825596", "price": "0.53", "size": "7", "side": "BUY", "hash": "637eb0d761e2b5a263ac31ab0e3c3abf0a6cdff2", "best_bid": "0.61", "best_ask": "0.62"}, {"asset_id": "86247848522476811956744818668364574835142715064162362411756221076437767369255", "price": "0.47", "size": "7", "side": "SELL", "hash": "2ee0d0533da9a0135c97b536053882c0284c4a0f", "best_bid": "0.38", "best_ask": "0.39"}], "timestamp": "1769384510000", "event_type": "price_change"}}
{"_local_timestamp": "2026-01-25T23:41:50.094783+00:00", "data": {"market": "0x5a4bae5b326d8ad4ef51e29b140afd57dc1dfb3c44e1c805209eacb65a656dd7", "price_changes": [{"asset_id": "59504136924064087795648081133235705846655371799758292499235575393658009825596", "price": "0.38", "size": "646", "side": "BUY", "hash": "55039811594f2ebe7629f0fdaf5ff3b4df4ae260", "best_bid": "0.61", "best_ask": "0.62"}, {"asset_id": "86247848522476811956744818668364574835142715064162362411756221076437767369255", "price": "0.62", "size": "646", "side": "SELL", "hash": "003e211e62a2e92d20c2eb19c7ddee8701bf600f", "best_bid": "0.38", "best_ask": "0.39"}], "timestamp": "1769384510002", "event_type": "price_change"}}
{"_local_timestamp": "2026-01-25T23:41:50.174550+00:00", "data": {"market": "0x360b5ab61e12806d96430a792f43d4c38fa7a33345c7c99db897accb59983db6", "price_changes": [{"asset_id": "26609800537692465524771607284115123570169751799662193302165096740333425504635", "price": "0.08", "size": "1687.33", "side": "BUY", "hash": "a300faf434237dfd8c4f7174f29b7811ebe100d2", "best_bid": "0.18", "best_ask": "0.2"}, {"asset_id": "101138268140267284344946310498458459688833372731909500410366045847576281737159", "price": "0.92", "size": "1687.33", "side": "SELL", "hash": "472e3aa58680e2c874ecb774cdab28ad91bfb5f6", "best_bid": "0.8", "best_ask": "0.82"}], "timestamp": "1769384510106", "event_type": "price_change"}}
{"_local_timestamp": "2026-01-25T23:41:50.446370+00:00", "data": {"market": "0x8f055b9db0a2d64b59b33e03bc8885f05a7c5116b3e2b6bb458011d6e18fb5d0", "price_changes": [{"asset_id": "56848224247430609127378739012316303221353695236865761552990703763581756323619", "price": "0.97", "size": "270", "side": "SELL", "hash": "c357c841f3e827c996ef8b89d71871d86131955f", "best_bid": "0.94", "best_ask": "0.945"}, {"asset_id": "61714042345592991242650283207041161607044873748774685082589583786302809304151", "price": "0.03", "size": "270", "side": "BUY", "hash": "53eb4abab5cd1f30a4bd37569b917370f974d14c", "best_bid": "0.055", "best_ask": "0.06"}], "timestamp": "1769384510368", "event_type": "price_change"}}
{"_local_timestamp": "2026-01-25T23:41:50.545706+00:00", "data": {"market": "0x5a4bae5b326d8ad4ef51e29b140afd57dc1dfb3c44e1c805209eacb65a656dd7", "price_changes": [{"asset_id": "59504136924064087795648081133235705846655371799758292499235575393658009825596", "price": "0.64", "size": "455.46", "side": "SELL", "hash": "8ff152afc6f9b66d9ee37ecef0ee141db9960de7", "best_bid": "0.61", "best_ask": "0.62"}, {"asset_id": "86247848522476811956744818668364574835142715064162362411756221076437767369255", "price": "0.36", "size": "455.46", "side": "BUY", "hash": "6d70f60f835abc856a03b7f688a03710af1b5a73", "best_bid": "0.38", "best_ask": "0.39"}], "timestamp": "1769384510474", "event_type": "price_change"}}
{"_local_timestamp": "2026-01-25T23:41:50.618601+00:00", "data": {"market": "0x5a4bae5b326d8ad4ef51e29b140afd57dc1dfb3c44e1c805209eacb65a656dd7", "price_changes": [{"asset_id": "59504136924064087795648081133235705846655371799758292499235575393658009825596", "price": "0.62", "size": "1419.05", "side": "SELL", "hash": "29ff875862aafbf314413055fbe5116ce9adcf24", "best_bid": "0.61", "best_ask": "0.62"}, {"asset_id": "86247848522476811956744818668364574835142715064162362411756221076437767369255", "price": "0.38", "size": "1419.05", "side": "BUY", "hash": "920e6dba09bd97d6c6cbffb5992eccf99cbb627a", "best_bid": "0.38", "best_ask": "0.39"}], "timestamp": "1769384510546", "event_type": "price_change"}}
{"_local_timestamp": "2026-01-25T23:41:50.640357+00:00", "data": {"market": "0x3da8ac5a617e2b32fbda49cbc5060917ab770abe9f74b11ffa36dcdb5b7a1195", "price_changes": [{"asset_id": "77932413699591385582408402058209008716103068377990837601822992291811637364241", "price": "0.21", "size": "233.33", "side": "BUY", "hash": "12a9174a25c2c82ea4df9da5c7538d41085c6e12", "best_bid": "0.78", "best_ask": "0.79"}, {"asset_id": "83722296194861509737807492105325276806804014660137138811708463053968062687084", "price": "0.79", "size": "233.33", "side": "SELL", "hash": "5d67f921ee4afed56ffffe4177826f15fd6710b0", "best_bid": "0.21", "best_ask": "0.22"}], "timestamp": "1769384510566", "event_type": "price_change"}}
{"_local_timestamp": "2026-01-25T23:41:50.643762+00:00", "data": {"market": "0xd2cf2ac9bf4caf3995f8d8ff4649688430c6733df13ab2d03e3e0756f36f2acb", "price_changes": [{"asset_id": "112139909108928670085933588651092403343948617179385187166440073666455678398436", "price": "0.04", "size": "2100", "side": "BUY", "hash": "4265d27a96085e19b48483138b50299b6b198535", "best_bid": "0.39", "best_ask": "0.41"}, {"asset_id": "8865170260028111071866974003576531745326850065489847482638010827443159829381", "price": "0.96", "size": "2100", "side": "SELL", "hash": "0faa8fce447f4527b82db63b5109304aa5b7c94d", "best_bid": "0.59", "best_ask": "0.61"}], "timestamp": "1769384510566", "event_type": "price_change"}}
{"_local_timestamp": "2026-01-25T23:41:50.645761+00:00", "data": {"market": "0xd2cf2ac9bf4caf3995f8d8ff4649688430c6733df13ab2d03e3e0756f36f2acb", "price_changes": [{"asset_id": "8865170260028111071866974003576531745326850065489847482638010827443159829381", "price": "0.16", "size": "0", "side": "BUY", "hash": "ea6595d25ae28e9115a9d43897b38220d844970e", "best_bid": "0.59", "best_ask": "0.61"}, {"asset_id": "112139909108928670085933588651092403343948617179385187166440073666455678398436", "price": "0.84", "size": "0", "side": "SELL", "hash": "4fd6f72050ea5673622926d44ed209f00e16ddcb", "best_bid": "0.39", "best_ask": "0.41"}], "timestamp": "1769384510567", "event_type": "price_change"}}
{"_local_timestamp": "2026-01-25T23:41:50.842414+00:00", "data": {"market": "0x8f055b9db0a2d64b59b33e03bc8885f05a7c5116b3e2b6bb458011d6e18fb5d0", "price_changes": [{"asset_id": "56848224247430609127378739012316303221353695236865761552990703763581756323619", "price": "0.97", "size": "330", "side": "SELL", "hash": "0d5d9f5d63e7b456a27b8eb8948470b02601ffed", "best_bid": "0.94", "best_ask": "0.945"}, {"asset_id": "61714042345592991242650283207041161607044873748774685082589583786302809304151", "price": "0.03", "size": "330", "side": "BUY", "hash": "9c04a1bf92933878838e87f02745e6825d3dfb4e", "best_bid": "0.055", "best_ask": "0.06"}], "timestamp": "1769384510732", "event_type": "price_change"}}
{"_local_timestamp": "2026-01-25T23:41:51.004141+00:00", "data": {"market": "0x8f055b9db0a2d64b59b33e03bc8885f05a7c5116b3e2b6bb458011d6e18fb5d0", "price_changes": [{"asset_id": "56848224247430609127378739012316303221353695236865761552990703763581756323619", "price": "0.955", "size": "1251", "side": "SELL", "hash": "00798c63e7ec2b72a49856e9962c696ce7d0f7c9", "best_bid": "0.94", "best_ask": "0.945"}, {"asset_id": "61714042345592991242650283207041161607044873748774685082589583786302809304151", "price": "0.045", "size": "1251", "side": "BUY", "hash": "7e663fa4665ad8514b9ab986e2fa9649b31c02e9", "best_bid": "0.055", "best_ask": "0.06"}], "timestamp": "1769384510931", "event_type": "price_change"}}
{"_local_timestamp": "2026-01-25T23:41:51.052032+00:00", "data": {"market": "0x8f055b9db0a2d64b59b33e03bc8885f05a7c5116b3e2b6bb458011d6e18fb5d0", "price_changes": [{"asset_id": "56848224247430609127378739012316303221353695236865761552990703763581756323619", "price": "0.957", "size": "125", "side": "SELL", "hash": "babb6ce05aed27d6171fca27306ed1725a7a359e", "best_bid": "0.94", "best_ask": "0.945"}, {"asset_id": "61714042345592991242650283207041161607044873748774685082589583786302809304151", "price": "0.043", "size": "125", "side": "BUY", "hash": "25bc1041222d7376f6bf5eaa0843dcd320e58367", "best_bid": "0.055", "best_ask": "0.06"}], "timestamp": "1769384510983", "event_type": "price_change"}}
{"_local_timestamp": "2026-01-25T23:41:51.539226+00:00", "data": {"market": "0x8f055b9db0a2d64b59b33e03bc8885f05a7c5116b3e2b6bb458011d6e18fb5d0", "price_changes": [{"asset_id": "56848224247430609127378739012316303221353695236865761552990703763581756323619", "price": "0.97", "size": "270", "side": "SELL", "hash": "c76ce3a6d7cd469175f4929beac9fc7ce2bc1de4", "best_bid": "0.94", "best_ask": "0.945"}, {"asset_id": "61714042345592991242650283207041161607044873748774685082589583786302809304151", "price": "0.03", "size": "270", "side": "BUY", "hash": "bccc02f964a00a59cd6a8ccc1c9302da0e1f3651", "best_bid": "0.055", "best_ask": "0.06"}], "timestamp": "1769384511455", "event_type": "price_change"}}
{"_local_timestamp": "2026-01-25T23:41:52.006869+00:00", "data": {"market": "0x8f055b9db0a2d64b59b33e03bc8885f05a7c5116b3e2b6bb458011d6e18fb5d0", "price_changes": [{"asset_id": "56848224247430609127378739012316303221353695236865761552990703763581756323619", "price": "0.957", "size": "0", "side": "SELL", "hash": "9974e970a3c5568c6ddc4efa03c03038e9932452", "best_bid": "0.94", "best_ask": "0.945"}, {"asset_id": "61714042345592991242650283207041161607044873748774685082589583786302809304151", "price": "0.043", "size": "0", "side": "BUY", "hash": "724026d4fa280b6b7e8a97ab6291e5de1b7917c2", "best_bid": "0.055", "best_ask": "0.06"}], "timestamp": "1769384511923", "event_type": "price_change"}}
{"_local_timestamp": "2026-01-25T23:41:52.007894+00:00", "data": {"market": "0x8f055b9db0a2d64b59b33e03bc8885f05a7c5116b3e2b6bb458011d6e18fb5d0", "price_changes": [{"asset_id": "56848224247430609127378739012316303221353695236865761552990703763581756323619", "price": "0.97", "size": "330", "side": "SELL", "hash": "2c2894f581e5190e7ced41906a33ffdfe72f5716", "best_bid": "0.94", "best_ask": "0.945"}, {"asset_id": "61714042345592991242650283207041161607044873748774685082589583786302809304151", "price": "0.03", "size": "330", "side": "BUY", "hash": "c98dba9cd5d689825b6bdcc429d71fd7fda16f2d", "best_bid": "0.055", "best_ask": "0.06"}], "timestamp": "1769384511930", "event_type": "price_change"}}
{"_local_timestamp": "2026-01-25T23:41:52.049234+00:00", "data": {"market": "0xd2cf2ac9bf4caf3995f8d8ff4649688430c6733df13ab2d03e3e0756f36f2acb", "price_changes": [{"asset_id": "8865170260028111071866974003576531745326850065489847482638010827443159829381", "price": "0.18", "size": "250", "side": "BUY", "hash": "1c9f7bde512c334875d23d9decfe28a6c275229a", "best_bid": "0.59", "best_ask": "0.61"}, {"asset_id": "112139909108928670085933588651092403343948617179385187166440073666455678398436", "price": "0.82", "size": "250", "side": "SELL", "hash": "54e776766b54d8f3759e786587c7c2d79b5ce418", "best_bid": "0.39", "best_ask": "0.41"}], "timestamp": "1769384511698", "event_type": "price_change"}}
{"_local_timestamp": "2026-01-25T23:41:52.098013+00:00", "data": {"market": "0x3da8ac5a617e2b32fbda49cbc5060917ab770abe9f74b11ffa36dcdb5b7a1195", "price_changes": [{"asset_id": "77932413699591385582408402058209008716103068377990837601822992291811637364241", "price": "0.23", "size": "200", "side": "BUY", "hash": "e3664b572695fb4a068429d5e9cd94b37ab6fd9e", "best_bid": "0.78", "best_ask": "0.79"}, {"asset_id": "83722296194861509737807492105325276806804014660137138811708463053968062687084", "price": "0.77", "size": "200", "side": "SELL", "hash": "462f93dd44b9db251eb2fb44322b73813dd8f4b8", "best_bid": "0.21", "best_ask": "0.22"}], "timestamp": "1769384511703", "event_type": "price_change"}}
{"_local_timestamp": "2026-01-25T23:41:52.126963+00:00", "data": {"market": "0xeb0f640f8e6979495efb462bca18e491a8624c07aecd89b9cea0ba62a4164226", "price_changes": [{"asset_id": "45834992705311952325019110769074251045520613427860944634211713333639342925215", "price": "0.72", "size": "958.99", "side": "BUY", "hash": "8bc73cde874ed9d36a08c3c0d5cfb3b929eb8686", "best_bid": "0.74", "best_ask": "0.75"}, {"asset_id": "67044993355929871917109997788450094017244283163136736213822945937563487769385", "price": "0.28", "size": "958.99", "side": "SELL", "hash": "5803794ec375b4d5b5ece20cfcd4b5f9674e5bab", "best_bid": "0.25", "best_ask": "0.26"}], "timestamp": "1769384512053", "event_type": "price_change"}}
{"_local_timestamp": "2026-01-25T23:41:52.152923+00:00", "data": {"market": "0xeb0f640f8e6979495efb462bca18e491a8624c07aecd89b9cea0ba62a4164226", "price_changes": [{"asset_id": "45834992705311952325019110769074251045520613427860944634211713333639342925215", "price": "0.72", "size": "2458.99", "side": "BUY", "hash": "3d8d160f8f850dae1e7d6ebb3810a62e811331f7", "best_bid": "0.74", "best_ask": "0.75"}, {"asset_id": "67044993355929871917109997788450094017244283163136736213822945937563487769385", "price": "0.28", "size": "2458.99", "side": "SELL", "hash": "4c6a9c7d779e13f3e2aa625653cb04697801d9ad", "best_bid": "0.25", "best_ask": "0.26"}], "timestamp": "1769384512082", "event_type": "price_change"}}
{"_local_timestamp": "2026-01-25T23:41:52.650258+00:00", "data": {"market": "0x8f055b9db0a2d64b59b33e03bc8885f05a7c5116b3e2b6bb458011d6e18fb5d0", "price_changes": [{"asset_id": "56848224247430609127378739012316303221353695236865761552990703763581756323619", "price": "0.955", "size": "1376", "side": "SELL", "hash": "205d7c96cbe619dc5d0db4fae44c9a5883b03e45", "best_bid": "0.94", "best_ask": "0.945"}, {"asset_id": "61714042345592991242650283207041161607044873748774685082589583786302809304151", "price": "0.045", "size": "1376", "side": "BUY", "hash": "f431016c411c27214500b027d4ca6f37acc3bbc9", "best_bid": "0.055", "best_ask": "0.06"}], "timestamp": "1769384512569", "event_type": "price_change"}}
{"_local_timestamp": "2026-01-25T23:41:52.708550+00:00", "data": {"market": "0x8f055b9db0a2d64b59b33e03bc8885f05a7c5116b3e2b6bb458011d6e18fb5d0", "price_changes": [{"asset_id": "56848224247430609127378739012316303221353695236865761552990703763581756323619", "price": "0.97", "size": "270", "side": "SELL", "hash": "700ad3811a020e8e00c8a1a72c58187dafd6da61", "best_bid": "0.94", "best_ask": "0.945"}, {"asset_id": "61714042345592991242650283207041161607044873748774685082589583786302809304151", "price": "0.03", "size": "270", "side": "BUY", "hash": "5cdf79872aa5dfedf51f36fa19393c80e77d42af", "best_bid": "0.055", "best_ask": "0.06"}], "timestamp": "1769384512624", "event_type": "price_change"}}
{"_local_timestamp": "2026-01-25T23:41:52.926817+00:00", "data": {"market": "0xd2cf2ac9bf4caf3995f8d8ff4649688430c6733df13ab2d03e3e0756f36f2acb", "price_changes": [{"asset_id": "112139909108928670085933588651092403343948617179385187166440073666455678398436", "price": "0.07", "size": "1385.71", "side": "BUY", "hash": "0090bfeb43c00c783c32fb3347c3572fe68e48d7", "best_bid": "0.39", "best_ask": "0.41"}, {"asset_id": "8865170260028111071866974003576531745326850065489847482638010827443159829381", "price": "0.93", "size": "1385.71", "side": "SELL", "hash": "2b6fa281ab5f999846e77d3311ae10f5ddecf8ca", "best_bid": "0.59", "best_ask": "0.61"}], "timestamp": "1769384511967", "event_type": "price_change"}}
{"_local_timestamp": "2026-01-25T23:41:53.198276+00:00", "data": {"market": "0x8f055b9db0a2d64b59b33e03bc8885f05a7c5116b3e2b6bb458011d6e18fb5d0", "price_changes": [{"asset_id": "56848224247430609127378739012316303221353695236865761552990703763581756323619", "price": "0.955", "size": "1251", "side": "SELL", "hash": "a5aeae1608af3f9cf375e93bfc418f272cbaaa77", "best_bid": "0.94", "best_ask": "0.945"}, {"asset_id": "61714042345592991242650283207041161607044873748774685082589583786302809304151", "price": "0.045", "size": "1251", "side": "BUY", "hash": "47ac41748a64d9da6c3f5312285270c3ef81cbef", "best_bid": "0.055", "best_ask": "0.06"}], "timestamp": "1769384512929", "event_type": "price_change"}}
{"_local_timestamp": "2026-01-25T23:41:53.238561+00:00", "data": {"market": "0x8f055b9db0a2d64b59b33e03bc8885f05a7c5116b3e2b6bb458011d6e18fb5d0", "price_changes": [{"asset_id": "56848224247430609127378739012316303221353695236865761552990703763581756323619", "price": "0.97", "size": "330", "side": "SELL", "hash": "476b76f2024fb25e4afb982f5aa54afcfbeac675", "best_bid": "0.94", "best_ask": "0.945"}, {"asset_id": "61714042345592991242650283207041161607044873748774685082589583786302809304151", "price": "0.03", "size": "330", "side": "BUY", "hash": "3de4424032a6cd9b41dae2557eca5429bf578e9b", "best_bid": "0.055", "best_ask": "0.06"}], "timestamp": "1769384512959", "event_type": "price_change"}}
{"_local_timestamp": "2026-01-25T23:41:53.247470+00:00", "data": {"market": "0x8f055b9db0a2d64b59b33e03bc8885f05a7c5116b3e2b6bb458011d6e18fb5d0", "price_changes": [{"asset_id": "56848224247430609127378739012316303221353695236865761552990703763581756323619", "price": "0.957", "size": "125", "side": "SELL", "hash": "b770b999af84a43bc5c6522570ce7f25938bc569", "best_bid": "0.94", "best_ask": "0.945"}, {"asset_id": "61714042345592991242650283207041161607044873748774685082589583786302809304151", "price": "0.043", "size": "125", "side": "BUY", "hash": "8f60aa4ba340b928d0e9742ca5e253fa3d18eaf7", "best_bid": "0.055", "best_ask": "0.06"}], "timestamp": "1769384512979", "event_type": "price_change"}}
{"_local_timestamp": "2026-01-25T23:41:53.331596+00:00", "data": {"market": "0x5a4bae5b326d8ad4ef51e29b140afd57dc1dfb3c44e1c805209eacb65a656dd7", "price_changes": [{"asset_id": "59504136924064087795648081133235705846655371799758292499235575393658009825596", "price": "0.53", "size": "117", "side": "BUY", "hash": "72a675a61328ded4732a988ee97fcfae31e4db26", "best_bid": "0.61", "best_ask": "0.62"}, {"asset_id": "86247848522476811956744818668364574835142715064162362411756221076437767369255", "price": "0.47", "size": "117", "side": "SELL", "hash": "631bef85adff471105bbd01780ee9cc72edae1bc", "best_bid": "0.38", "best_ask": "0.39"}], "timestamp": "1769384513218", "event_type": "price_change"}}
{"_local_timestamp": "2026-01-25T23:41:53.332436+00:00", "data": {"market": "0x5a4bae5b326d8ad4ef51e29b140afd57dc1dfb3c44e1c805209eacb65a656dd7", "price_changes": [{"asset_id": "59504136924064087795648081133235705846655371799758292499235575393658009825596", "price": "0.38", "size": "1300", "side": "BUY", "hash": "53e7108a932e18e060cd247172fa235bc8aafdfe", "best_bid": "0.61", "best_ask": "0.62"}, {"asset_id": "86247848522476811956744818668364574835142715064162362411756221076437767369255", "price": "0.62", "size": "1300", "side": "SELL", "hash": "f7f6f8264d2570d100f9c9692b41579b0b515797", "best_bid": "0.38", "best_ask": "0.39"}], "timestamp": "1769384513219", "event_type": "price_change"}}
{"_local_timestamp": "2026-01-25T23:41:53.779983+00:00", "data": {"market": "0x8f055b9db0a2d64b59b33e03bc8885f05a7c5116b3e2b6bb458011d6e18fb5d0", "price_changes": [{"asset_id": "56848224247430609127378739012316303221353695236865761552990703763581756323619", "price": "0.97", "size": "270", "side": "SELL", "hash": "f87c31abc35670c6a9bc70ecc4e5f8dad863e9f0", "best_bid": "0.94", "best_ask": "0.945"}, {"asset_id": "61714042345592991242650283207041161607044873748774685082589583786302809304151", "price": "0.03", "size": "270", "side": "BUY", "hash": "0b7df096aa7746bb9bb9495c274a1aefc3dbde5c", "best_bid": "0.055", "best_ask": "0.06"}], "timestamp": "1769384513639", "event_type": "price_change"}}
{"_local_timestamp": "2026-01-25T23:41:54.034135+00:00", "data": {"market": "0x8f055b9db0a2d64b59b33e03bc8885f05a7c5116b3e2b6bb458011d6e18fb5d0", "price_changes": [{"asset_id": "56848224247430609127378739012316303221353695236865761552990703763581756323619", "price": "0.957", "size": "0", "side": "SELL", "hash": "9bb3a2b16f5a48862e5dcac58203a601663350aa", "best_bid": "0.94", "best_ask": "0.945"}, {"asset_id": "61714042345592991242650283207041161607044873748774685082589583786302809304151", "price": "0.043", "size": "0", "side": "BUY", "hash": "871934a06e0c446ba3cbbd67af5dd3183e746f13", "best_bid": "0.055", "best_ask": "0.06"}], "timestamp": "1769384513954", "event_type": "price_change"}}
{"_local_timestamp": "2026-01-25T23:41:54.082226+00:00", "data": {"market": "0x8f055b9db0a2d64b59b33e03bc8885f05a7c5116b3e2b6bb458011d6e18fb5d0", "price_changes": [{"asset_id": "56848224247430609127378739012316303221353695236865761552990703763581756323619", "price": "0.955", "size": "1376", "side": "SELL", "hash": "dc9bf2000ba3b19e11c6a2adba129eb54a8dad2f", "best_bid": "0.94", "best_ask": "0.945"}, {"asset_id": "61714042345592991242650283207041161607044873748774685082589583786302809304151", "price": "0.045", "size": "1376", "side": "BUY", "hash": "47eeb7b28e2f71f3282803574420323e8658728c", "best_bid": "0.055", "best_ask": "0.06"}], "timestamp": "1769384514017", "event_type": "price_change"}}
{"_local_timestamp": "2026-01-25T23:41:54.100136+00:00", "data": {"market": "0x8f055b9db0a2d64b59b33e03bc8885f05a7c5116b3e2b6bb458011d6e18fb5d0", "price_changes": [{"asset_id": "56848224247430609127378739012316303221353695236865761552990703763581756323619", "price": "0.97", "size": "330", "side": "SELL", "hash": "9340e5a553c7741a4b67740908494e9636308c0b", "best_bid": "0.94", "best_ask": "0.945"}, {"asset_id": "61714042345592991242650283207041161607044873748774685082589583786302809304151", "price": "0.03", "size": "330", "side": "BUY", "hash": "16ed4de0d3d8536ab23bf3e9ac6abbbf043d68fb", "best_bid": "0.055", "best_ask": "0.06"}], "timestamp": "1769384514030", "event_type": "price_change"}}
{"_local_timestamp": "2026-01-25T23:41:54.710619+00:00", "data": {"market": "0x8f055b9db0a2d64b59b33e03bc8885f05a7c5116b3e2b6bb458011d6e18fb5d0", "price_changes": [{"asset_id": "56848224247430609127378739012316303221353695236865761552990703763581756323619", "price": "0.97", "size": "270", "side": "SELL", "hash": "57a764255be68e2f83342c157d26ce85b7673c1a", "best_bid": "0.94", "best_ask": "0.945"}, {"asset_id": "61714042345592991242650283207041161607044873748774685082589583786302809304151", "price": "0.03", "size": "270", "side": "BUY", "hash": "c517d4d8cdded55962ab4f6a86d41682c3e17fe9", "best_bid": "0.055", "best_ask": "0.06"}], "timestamp": "1769384514637", "event_type": "price_change"}}
{"_local_timestamp": "2026-01-25T23:41:55.014643+00:00", "data": {"market": "0x8f055b9db0a2d64b59b33e03bc8885f05a7c5116b3e2b6bb458011d6e18fb5d0", "price_changes": [{"asset_id": "56848224247430609127378739012316303221353695236865761552990703763581756323619", "price": "0.955", "size": "1251", "side": "SELL", "hash": "b6b2beba6fc545ece39e819b5654797fd31df951", "best_bid": "0.94", "best_ask": "0.945"}, {"asset_id": "61714042345592991242650283207041161607044873748774685082589583786302809304151", "price": "0.045", "size": "1251", "side": "BUY", "hash": "2e0abc2507fb72ae54bb23649f77d1805aa0edd3", "best_bid": "0.055", "best_ask": "0.06"}], "timestamp": "1769384514950", "event_type": "price_change"}}
{"_local_timestamp": "2026-01-25T23:41:55.070731+00:00", "data": {"market": "0x8f055b9db0a2d64b59b33e03bc8885f05a7c5116b3e2b6bb458011d6e18fb5d0", "price_changes": [{"asset_id": "56848224247430609127378739012316303221353695236865761552990703763581756323619", "price": "0.957", "size": "125", "side": "SELL", "hash": "c63dd992e553d8ee693387bdeb0fac4f390b1177", "best_bid": "0.94", "best_ask": "0.945"}, {"asset_id": "61714042345592991242650283207041161607044873748774685082589583786302809304151", "price": "0.043", "size": "125", "side": "BUY", "hash": "ebbee171e939458edbd17b5d5f324ca553482029", "best_bid": "0.055", "best_ask": "0.06"}], "timestamp": "1769384515005", "event_type": "price_change"}}
{"_local_timestamp": "2026-01-25T23:41:55.202034+00:00", "data": {"market": "0x8f055b9db0a2d64b59b33e03bc8885f05a7c5116b3e2b6bb458011d6e18fb5d0", "price_changes": [{"asset_id": "56848224247430609127378739012316303221353695236865761552990703763581756323619", "price": "0.97", "size": "330", "side": "SELL", "hash": "8f0f80e57dc1182adda90fedbdc85398cc8342a6", "best_bid": "0.94", "best_ask": "0.945"}, {"asset_id": "61714042345592991242650283207041161607044873748774685082589583786302809304151", "price": "0.03", "size": "330", "side": "BUY", "hash": "c8818aa269b10f547a5b883b8084788c230c5cd4", "best_bid": "0.055", "best_ask": "0.06"}], "timestamp": "1769384515132", "event_type": "price_change"}}
{"_local_timestamp": "2026-01-25T23:41:55.434165+00:00", "data": {"market": "0x3da8ac5a617e2b32fbda49cbc5060917ab770abe9f74b11ffa36dcdb5b7a1195", "price_changes": [{"asset_id": "77932413699591385582408402058209008716103068377990837601822992291811637364241", "price": "0.76", "size": "1230.5", "side": "BUY", "hash": "ca1c62277d040a43be5071adf63a42cd4af7f2a4", "best_bid": "0.78", "best_ask": "0.79"}, {"asset_id": "83722296194861509737807492105325276806804014660137138811708463053968062687084", "price": "0.24", "size": "1230.5", "side": "SELL", "hash": "55ffaa9dd474dc73566716457b3de91421a71bb3", "best_bid": "0.21", "best_ask": "0.22"}], "timestamp": "1769384515365", "event_type": "price_change"}}
{"_local_timestamp": "2026-01-25T23:41:55.546989+00:00", "data": {"market": "0x3da8ac5a617e2b32fbda49cbc5060917ab770abe9f74b11ffa36dcdb5b7a1195", "price_changes": [{"asset_id": "77932413699591385582408402058209008716103068377990837601822992291811637364241", "price": "0.77", "size": "1350", "side": "BUY", "hash": "4a7e2908e804a34d43800efc6848d5d5579a1ec7", "best_bid": "0.78", "best_ask": "0.79"}, {"asset_id": "83722296194861509737807492105325276806804014660137138811708463053968062687084", "price": "0.23", "size": "1350", "side": "SELL", "hash": "80b0879d47f2887508ba92392d9221d9120e476a", "best_bid": "0.21", "best_ask": "0.22"}], "timestamp": "1769384515479", "event_type": "price_change"}}
{"_local_timestamp": "2026-01-25T23:41:55.947191+00:00", "data": {"market": "0x8f055b9db0a2d64b59b33e03bc8885f05a7c5116b3e2b6bb458011d6e18fb5d0", "price_changes": [{"asset_id": "56848224247430609127378739012316303221353695236865761552990703763581756323619", "price": "0.97", "size": "270", "side": "SELL", "hash": "4e624c59290efbb30378cbc9532601ce1172f143", "best_bid": "0.94", "best_ask": "0.945"}, {"asset_id": "61714042345592991242650283207041161607044873748774685082589583786302809304151", "price": "0.03", "size": "270", "side": "BUY", "hash": "c3ce3f1feda70a621eed717c415edd15b925d3be", "best_bid": "0.055", "best_ask": "0.06"}], "timestamp": "1769384515863", "event_type": "price_change"}}
{"_local_timestamp": "2026-01-25T23:41:56.038579+00:00", "data": {"market": "0x8f055b9db0a2d64b59b33e03bc8885f05a7c5116b3e2b6bb458011d6e18fb5d0", "price_changes": [{"asset_id": "56848224247430609127378739012316303221353695236865761552990703763581756323619", "price": "0.957", "size": "0", "side": "SELL", "hash": "114e20e0ac17012f10ca4ea7767b521c1ffa66d9", "best_bid": "0.94", "best_ask": "0.945"}, {"asset_id": "61714042345592991242650283207041161607044873748774685082589583786302809304151", "price": "0.043", "size": "0", "side": "BUY", "hash": "0008d9111929fb3da5c919246ed1a1563ae02ab0", "best_bid": "0.055", "best_ask": "0.06"}], "timestamp": "1769384515950", "event_type": "price_change"}}
{"_local_timestamp": "2026-01-25T23:41:56.126489+00:00", "data": {"market": "0x8f055b9db0a2d64b59b33e03bc8885f05a7c5116b3e2b6bb458011d6e18fb5d0", "price_changes": [{"asset_id": "56848224247430609127378739012316303221353695236865761552990703763581756323619", "price": "0.955", "size": "1376", "side": "SELL", "hash": "661625bdcac3605a42a69cd2ef6f26d88df898d8", "best_bid": "0.94", "best_ask": "0.945"}, {"asset_id": "61714042345592991242650283207041161607044873748774685082589583786302809304151", "price": "0.045", "size": "1376", "side": "BUY", "hash": "d56cfa015ce3cc974a9ef26bd3400c8fd38ca4a7", "best_bid": "0.055", "best_ask": "0.06"}], "timestamp": "1769384516008", "event_type": "price_change"}}
{"_local_timestamp": "2026-01-25T23:41:56.174431+00:00", "data": {"market": "0x8f055b9db0a2d64b59b33e03bc8885f05a7c5116b3e2b6bb458011d6e18fb5d0", "price_changes": [{"asset_id": "56848224247430609127378739012316303221353695236865761552990703763581756323619", "price": "0.97", "size": "330", "side": "SELL", "hash": "f9b010f64e1f657ffe1d01ac52df846856092a71", "best_bid": "0.94", "best_ask": "0.945"}, {"asset_id": "61714042345592991242650283207041161607044873748774685082589583786302809304151", "price": "0.03", "size": "330", "side": "BUY", "hash": "1eae9773d094a9d080010d74487af61b1ff45813", "best_bid": "0.055", "best_ask": "0.06"}], "timestamp": "1769384516072", "event_type": "price_change"}}
{"_local_timestamp": "2026-01-25T23:41:56.589745+00:00", "data": {"market": "0x8f055b9db0a2d64b59b33e03bc8885f05a7c5116b3e2b6bb458011d6e18fb5d0", "price_changes": [{"asset_id": "56848224247430609127378739012316303221353695236865761552990703763581756323619", "price": "0.97", "size": "270", "side": "SELL", "hash": "a642ff19a73fcec63208922edca3bf8d754fc35c", "best_bid": "0.94", "best_ask": "0.945"}, {"asset_id": "61714042345592991242650283207041161607044873748774685082589583786302809304151", "price": "0.03", "size": "270", "side": "BUY", "hash": "fb071787da17dfe5531ce4142e488afabeb9e2bb", "best_bid": "0.055", "best_ask": "0.06"}], "timestamp": "1769384516522", "event_type": "price_change"}}
{"_local_timestamp": "2026-01-25T23:41:56.837155+00:00", "data": {"market": "0x8f055b9db0a2d64b59b33e03bc8885f05a7c5116b3e2b6bb458011d6e18fb5d0", "price_changes": [{"asset_id": "56848224247430609127378739012316303221353695236865761552990703763581756323619", "price": "0.97", "size": "330", "side": "SELL", "hash": "4430c4eaa9a70e518a6cd89c1fc84be4fb7331f8", "best_bid": "0.94", "best_ask": "0.945"}, {"asset_id": "61714042345592991242650283207041161607044873748774685082589583786302809304151", "price": "0.03", "size": "330", "side": "BUY", "hash": "d5abd091169a03a3f8d18a009b99a0d61e1bd4fb", "best_bid": "0.055", "best_ask": "0.06"}], "timestamp": "1769384516770", "event_type": "price_change"}}
{"_local_timestamp": "2026-01-25T23:41:57.036653+00:00", "data": {"market": "0x8f055b9db0a2d64b59b33e03bc8885f05a7c5116b3e2b6bb458011d6e18fb5d0", "price_changes": [{"asset_id": "56848224247430609127378739012316303221353695236865761552990703763581756323619", "price": "0.955", "size": "1251", "side": "SELL", "hash": "6c67012c53e8e179da6e6026454b11de14a27cda", "best_bid": "0.94", "best_ask": "0.945"}, {"asset_id": "61714042345592991242650283207041161607044873748774685082589583786302809304151", "price": "0.045", "size": "1251", "side": "BUY", "hash": "65850361a4682c72153fb6b6fc1443773c902336", "best_bid": "0.055", "best_ask": "0.06"}], "timestamp": "1769384516951", "event_type": "price_change"}}
{"_local_timestamp": "2026-01-25T23:41:57.126192+00:00", "data": {"market": "0x8f055b9db0a2d64b59b33e03bc8885f05a7c5116b3e2b6bb458011d6e18fb5d0", "price_changes": [{"asset_id": "56848224247430609127378739012316303221353695236865761552990703763581756323619", "price": "0.957", "size": "125", "side": "SELL", "hash": "91f34bcfc3973bcb14fb79660437a606059ab902", "best_bid": "0.94", "best_ask": "0.945"}, {"asset_id": "61714042345592991242650283207041161607044873748774685082589583786302809304151", "price": "0.043", "size": "125", "side": "BUY", "hash": "93f9e62776e02ac1111bf71d29390f60ca5b9710", "best_bid": "0.055", "best_ask": "0.06"}], "timestamp": "1769384517030", "event_type": "price_change"}}
{"_local_timestamp": "2026-01-25T23:41:57.204632+00:00", "data": {"market": "0x8f055b9db0a2d64b59b33e03bc8885f05a7c5116b3e2b6bb458011d6e18fb5d0", "price_changes": [{"asset_id": "56848224247430609127378739012316303221353695236865761552990703763581756323619", "price": "0.97", "size": "270", "side": "SELL", "hash": "37306703679be9524d94b4ec92af4ea4ac7e79c5", "best_bid": "0.94", "best_ask": "0.945"}, {"asset_id": "61714042345592991242650283207041161607044873748774685082589583786302809304151", "price": "0.03", "size": "270", "side": "BUY", "hash": "de34ac2097a8d1b20093b01f550894ac672f54b5", "best_bid": "0.055", "best_ask": "0.06"}], "timestamp": "1769384517137", "event_type": "price_change"}}
{"_local_timestamp": "2026-01-25T23:41:57.381227+00:00", "data": {"market": "0x8f055b9db0a2d64b59b33e03bc8885f05a7c5116b3e2b6bb458011d6e18fb5d0", "price_changes": [{"asset_id": "56848224247430609127378739012316303221353695236865761552990703763581756323619", "price": "0.97", "size": "330", "side": "SELL", "hash": "a50fa04405993edae294f034ceb32b53a31b4511", "best_bid": "0.94", "best_ask": "0.945"}, {"asset_id": "61714042345592991242650283207041161607044873748774685082589583786302809304151", "price": "0.03", "size": "330", "side": "BUY", "hash": "a88f37ba6230b5c8e040581b75a133a2aa92d340", "best_bid": "0.055", "best_ask": "0.06"}], "timestamp": "1769384517311", "event_type": "price_change"}}
{"_local_timestamp": "2026-01-25T23:41:58.029467+00:00", "data": {"market": "0x8f055b9db0a2d64b59b33e03bc8885f05a7c5116b3e2b6bb458011d6e18fb5d0", "price_changes": [{"asset_id": "56848224247430609127378739012316303221353695236865761552990703763581756323619", "price": "0.957", "size": "0", "side": "SELL", "hash": "de502de037b2debca8269500a1c426b0b9d338d5", "best_bid": "0.94", "best_ask": "0.945"}, {"asset_id": "61714042345592991242650283207041161607044873748774685082589583786302809304151", "price": "0.043", "size": "0", "side": "BUY", "hash": "f7d0461e17733a23259645129586ccbab557d8ff", "best_bid": "0.055", "best_ask": "0.06"}], "timestamp": "1769384517955", "event_type": "price_change"}}
{"_local_timestamp": "2026-01-25T23:41:58.104880+00:00", "data": {"market": "0x8f055b9db0a2d64b59b33e03bc8885f05a7c5116b3e2b6bb458011d6e18fb5d0", "price_changes": [{"asset_id": "56848224247430609127378739012316303221353695236865761552990703763581756323619", "price": "0.955", "size": "1376", "side": "SELL", "hash": "a60286776902e4d021a4f8e0dbdaa093efb6871d", "best_bid": "0.94", "best_ask": "0.945"}, {"asset_id": "61714042345592991242650283207041161607044873748774685082589583786302809304151", "price": "0.045", "size": "1376", "side": "BUY", "hash": "0ff337cf484e0d5c4d76e7118a2d3100e2a1a5cc", "best_bid": "0.055", "best_ask": "0.06"}], "timestamp": "1769384518020", "event_type": "price_change"}}
{"_local_timestamp": "2026-01-25T23:41:59.035005+00:00", "data": {"market": "0x8f055b9db0a2d64b59b33e03bc8885f05a7c5116b3e2b6bb458011d6e18fb5d0", "price_changes": [{"asset_id": "56848224247430609127378739012316303221353695236865761552990703763581756323619", "price": "0.955", "size": "1251", "side": "SELL", "hash": "d04259606f6bffc368a34a9209d849eda6264257", "best_bid": "0.94", "best_ask": "0.945"}, {"asset_id": "61714042345592991242650283207041161607044873748774685082589583786302809304151", "price": "0.045", "size": "1251", "side": "BUY", "hash": "7803d3b16b5ec7ad6f71b9470f3d752455a8280d", "best_bid": "0.055", "best_ask": "0.06"}], "timestamp": "1769384518964", "event_type": "price_change"}}
{"_local_timestamp": "2026-01-25T23:41:59.157027+00:00", "data": {"market": "0x8f055b9db0a2d64b59b33e03bc8885f05a7c5116b3e2b6bb458011d6e18fb5d0", "price_changes": [{"asset_id": "56848224247430609127378739012316303221353695236865761552990703763581756323619", "price": "0.957", "size": "125", "side": "SELL", "hash": "7f1a00fd0e12fcf701293b58b1f794072f0419af", "best_bid": "0.94", "best_ask": "0.945"}, {"asset_id": "61714042345592991242650283207041161607044873748774685082589583786302809304151", "price": "0.043", "size": "125", "side": "BUY", "hash": "0f6246ab55908a28e5ada6ef161ec834b233f426", "best_bid": "0.055", "best_ask": "0.06"}], "timestamp": "1769384519070", "event_type": "price_change"}}
{"_local_timestamp": "2026-01-25T23:41:59.835590+00:00", "data": {"market": "0xd2cf2ac9bf4caf3995f8d8ff4649688430c6733df13ab2d03e3e0756f36f2acb", "price_changes": [{"asset_id": "8865170260028111071866974003576531745326850065489847482638010827443159829381", "price": "0.52", "size": "0", "side": "BUY", "hash": "4a17d7a616a44f8ec248e795a60f04474e8b5e62", "best_bid": "0.59", "best_ask": "0.61"}, {"asset_id": "112139909108928670085933588651092403343948617179385187166440073666455678398436", "price": "0.48", "size": "0", "side": "SELL", "hash": "acc9d81168eaa50461735bc2393ae57168f197df", "best_bid": "0.39", "best_ask": "0.41"}], "timestamp": "1769384519768", "event_type": "price_change"}}
{"_local_timestamp": "2026-01-25T23:42:00.034337+00:00", "data": {"market": "0x8f055b9db0a2d64b59b33e03bc8885f05a7c5116b3e2b6bb458011d6e18fb5d0", "price_changes": [{"asset_id": "56848224247430609127378739012316303221353695236865761552990703763581756323619", "price": "0.957", "size": "0", "side": "SELL", "hash": "6b715ea124430b94e5100580b814eb41cbdc187e", "best_bid": "0.94", "best_ask": "0.945"}, {"asset_id": "61714042345592991242650283207041161607044873748774685082589583786302809304151", "price": "0.043", "size": "0", "side": "BUY", "hash": "c20e62fb192ddda4d490af510f83697a8880f1ba", "best_bid": "0.055", "best_ask": "0.06"}], "timestamp": "1769384519960", "event_type": "price_change"}}
{"_local_timestamp": "2026-01-25T23:42:00.135627+00:00", "data": {"market": "0x8f055b9db0a2d64b59b33e03bc8885f05a7c5116b3e2b6bb458011d6e18fb5d0", "price_changes": [{"asset_id": "56848224247430609127378739012316303221353695236865761552990703763581756323619", "price": "0.955", "size": "1376", "side": "SELL", "hash": "1542791ce9a48dab5d990e0e1daa29c2eef1ca97", "best_bid": "0.94", "best_ask": "0.945"}, {"asset_id": "61714042345592991242650283207041161607044873748774685082589583786302809304151", "price": "0.045", "size": "1376", "side": "BUY", "hash": "7d361820b75a668b7ed78721e8dc719fa117c376", "best_bid": "0.055", "best_ask": "0.06"}], "timestamp": "1769384520034", "event_type": "price_change"}}
{"_local_timestamp": "2026-01-25T23:42:00.324175+00:00", "data": {"market": "0x8f055b9db0a2d64b59b33e03bc8885f05a7c5116b3e2b6bb458011d6e18fb5d0", "price_changes": [{"asset_id": "56848224247430609127378739012316303221353695236865761552990703763581756323619", "price": "0.97", "size": "270", "side": "SELL", "hash": "88f72fa79319772d534e92021b63189f758e89c0", "best_bid": "0.94", "best_ask": "0.945"}, {"asset_id": "61714042345592991242650283207041161607044873748774685082589583786302809304151", "price": "0.03", "size": "270", "side": "BUY", "hash": "2cbb0ac17ba99ed144ddcab65cb816c5529f1ca6", "best_bid": "0.055", "best_ask": "0.06"}], "timestamp": "1769384520251", "event_type": "price_change"}}
{"_local_timestamp": "2026-01-25T23:42:00.416254+00:00", "data": {"market": "0x8f055b9db0a2d64b59b33e03bc8885f05a7c5116b3e2b6bb458011d6e18fb5d0", "price_changes": [{"asset_id": "56848224247430609127378739012316303221353695236865761552990703763581756323619", "price": "0.97", "size": "330", "side": "SELL", "hash": "853fa0f95610ab9b90735fdbdbc716ff63935420", "best_bid": "0.94", "best_ask": "0.945"}, {"asset_id": "61714042345592991242650283207041161607044873748774685082589583786302809304151", "price": "0.03", "size": "330", "side": "BUY", "hash": "6d5292f6cef04bbbc06155513c5d722f5138eea9", "best_bid": "0.055", "best_ask": "0.06"}], "timestamp": "1769384520346", "event_type": "price_change"}}
{"_local_timestamp": "2026-01-25T23:42:01.036898+00:00", "data": {"market": "0x8f055b9db0a2d64b59b33e03bc8885f05a7c5116b3e2b6bb458011d6e18fb5d0", "price_changes": [{"asset_id": "56848224247430609127378739012316303221353695236865761552990703763581756323619", "price": "0.955", "size": "1251", "side": "SELL", "hash": "19c30a28965cc0ad5af270e49b5bcd2dc779106c", "best_bid": "0.94", "best_ask": "0.945"}, {"asset_id": "61714042345592991242650283207041161607044873748774685082589583786302809304151", "price": "0.045", "size": "1251", "side": "BUY", "hash": "006ddd5044932512a28720359b74e7a39f4fec03", "best_bid": "0.055", "best_ask": "0.06"}], "timestamp": "1769384520966", "event_type": "price_change"}}
{"_local_timestamp": "2026-01-25T23:42:01.138282+00:00", "data": {"market": "0x8f055b9db0a2d64b59b33e03bc8885f05a7c5116b3e2b6bb458011d6e18fb5d0", "price_changes": [{"asset_id": "56848224247430609127378739012316303221353695236865761552990703763581756323619", "price": "0.957", "size": "125", "side": "SELL", "hash": "78eb64513911c643f490f654d66be912be81cf1c", "best_bid": "0.94", "best_ask": "0.945"}, {"asset_id": "61714042345592991242650283207041161607044873748774685082589583786302809304151", "price": "0.043", "size": "125", "side": "BUY", "hash": "6d2401b106ae64c6ea3a88435f0ccce223c49bea", "best_bid": "0.055", "best_ask": "0.06"}], "timestamp": "1769384521054", "event_type": "price_change"}}
{"_local_timestamp": "2026-01-25T23:42:02.036993+00:00", "data": {"market": "0x8f055b9db0a2d64b59b33e03bc8885f05a7c5116b3e2b6bb458011d6e18fb5d0", "price_changes": [{"asset_id": "56848224247430609127378739012316303221353695236865761552990703763581756323619", "price": "0.957", "size": "0", "side": "SELL", "hash": "bbab2584bb42451e74d2fe5411390777348c408f", "best_bid": "0.94", "best_ask": "0.945"}, {"asset_id": "61714042345592991242650283207041161607044873748774685082589583786302809304151", "price": "0.043", "size": "0", "side": "BUY", "hash": "96d301e851083e312b838573bd839bf321faf4c4", "best_bid": "0.055", "best_ask": "0.06"}], "timestamp": "1769384521970", "event_type": "price_change"}}
{"_local_timestamp": "2026-01-25T23:42:02.108034+00:00", "data": {"market": "0x8f055b9db0a2d64b59b33e03bc8885f05a7c5116b3e2b6bb458011d6e18fb5d0", "price_changes": [{"asset_id": "56848224247430609127378739012316303221353695236865761552990703763581756323619", "price": "0.955", "size": "1376", "side": "SELL", "hash": "3ddece5557a149574aa8b68a050e3b0e25353594", "best_bid": "0.94", "best_ask": "0.945"}, {"asset_id": "61714042345592991242650283207041161607044873748774685082589583786302809304151", "price": "0.045", "size": "1376", "side": "BUY", "hash": "b4cbb860975a3da66bf7ba0bbd3c780b4b940a0b", "best_bid": "0.055", "best_ask": "0.06"}], "timestamp": "1769384522038", "event_type": "price_change"}}
{"_local_timestamp": "2026-01-25T23:42:03.045392+00:00", "data": {"market": "0x8f055b9db0a2d64b59b33e03bc8885f05a7c5116b3e2b6bb458011d6e18fb5d0", "price_changes": [{"asset_id": "56848224247430609127378739012316303221353695236865761552990703763581756323619", "price": "0.955", "size": "1251", "side": "SELL", "hash": "191031520d11f50a11a6b367dd2ee3d5bff62196", "best_bid": "0.94", "best_ask": "0.945"}, {"asset_id": "61714042345592991242650283207041161607044873748774685082589583786302809304151", "price": "0.045", "size": "1251", "side": "BUY", "hash": "47d323796443bec82eed086185b701ba957c43a3", "best_bid": "0.055", "best_ask": "0.06"}], "timestamp": "1769384522973", "event_type": "price_change"}}
{"_local_timestamp": "2026-01-25T23:42:03.103001+00:00", "data": {"market": "0x8f055b9db0a2d64b59b33e03bc8885f05a7c5116b3e2b6bb458011d6e18fb5d0", "price_changes": [{"asset_id": "56848224247430609127378739012316303221353695236865761552990703763581756323619", "price": "0.957", "size": "125", "side": "SELL", "hash": "e3f3c974efa8b96c381bad7127d58095dd139362", "best_bid": "0.94", "best_ask": "0.945"}, {"asset_id": "61714042345592991242650283207041161607044873748774685082589583786302809304151", "price": "0.043", "size": "125", "side": "BUY", "hash": "09812cf4b0bcb7adfd95ee8e292b419c579d42fc", "best_bid": "0.055", "best_ask": "0.06"}], "timestamp": "1769384523028", "event_type": "price_change"}}
{"_local_timestamp": "2026-01-25T23:42:03.485321+00:00", "data": {"market": "0xd2cf2ac9bf4caf3995f8d8ff4649688430c6733df13ab2d03e3e0756f36f2acb", "price_changes": [{"asset_id": "112139909108928670085933588651092403343948617179385187166440073666455678398436", "price": "0.39", "size": "31.71", "side": "BUY", "hash": "40d28f98c647b793aa74d407d8d302eaf3bcbdf4", "best_bid": "0.39", "best_ask": "0.41"}, {"asset_id": "8865170260028111071866974003576531745326850065489847482638010827443159829381", "price": "0.61", "size": "31.71", "side": "SELL", "hash": "c5e1945d038d619940f9d0a4846d33fbac6d39fd", "best_bid": "0.59", "best_ask": "0.61"}], "timestamp": "1769384523419", "event_type": "price_change"}}
{"_local_timestamp": "2026-01-25T23:42:03.486392+00:00", "data": {"market": "0xd2cf2ac9bf4caf3995f8d8ff4649688430c6733df13ab2d03e3e0756f36f2acb", "price_changes": [{"asset_id": "112139909108928670085933588651092403343948617179385187166440073666455678398436", "price": "0.37", "size": "1220", "side": "BUY", "hash": "40d28f98c647b793aa74d407d8d302eaf3bcbdf4", "best_bid": "0.39", "best_ask": "0.41"}, {"asset_id": "8865170260028111071866974003576531745326850065489847482638010827443159829381", "price": "0.63", "size": "1220", "side": "SELL", "hash": "c5e1945d038d619940f9d0a4846d33fbac6d39fd", "best_bid": "0.59", "best_ask": "0.61"}], "timestamp": "1769384523419", "event_type": "price_change"}}
{"_local_timestamp": "2026-01-25T23:42:03.487422+00:00", "data": {"market": "0xd2cf2ac9bf4caf3995f8d8ff4649688430c6733df13ab2d03e3e0756f36f2acb", "price_changes": [{"asset_id": "112139909108928670085933588651092403343948617179385187166440073666455678398436", "price": "0.35", "size": "100.74", "side": "BUY", "hash": "40d28f98c647b793aa74d407d8d302eaf3bcbdf4", "best_bid": "0.39", "best_ask": "0.41"}, {"asset_id": "8865170260028111071866974003576531745326850065489847482638010827443159829381", "price": "0.65", "size": "100.74", "side": "SELL", "hash": "c5e1945d038d619940f9d0a4846d33fbac6d39fd", "best_bid": "0.59", "best_ask": "0.61"}], "timestamp": "1769384523419", "event_type": "price_change"}}
{"_local_timestamp": "2026-01-25T23:42:03.488343+00:00", "data": {"market": "0xd2cf2ac9bf4caf3995f8d8ff4649688430c6733df13ab2d03e3e0756f36f2acb", "price_changes": [{"asset_id": "112139909108928670085933588651092403343948617179385187166440073666455678398436", "price": "0.01", "size": "6508.4", "side": "BUY", "hash": "40d28f98c647b793aa74d407d8d302eaf3bcbdf4", "best_bid": "0.39", "best_ask": "0.41"}, {"asset_id": "8865170260028111071866974003576531745326850065489847482638010827443159829381", "price": "0.99", "size": "6508.4", "side": "SELL", "hash": "c5e1945d038d619940f9d0a4846d33fbac6d39fd", "best_bid": "0.59", "best_ask": "0.61"}], "timestamp": "1769384523419", "event_type": "price_change"}}
{"_local_timestamp": "2026-01-25T23:42:03.489337+00:00", "data": {"market": "0xd2cf2ac9bf4caf3995f8d8ff4649688430c6733df13ab2d03e3e0756f36f2acb", "price_changes": [{"asset_id": "112139909108928670085933588651092403343948617179385187166440073666455678398436", "price": "0.26", "size": "219", "side": "BUY", "hash": "40d28f98c647b793aa74d407d8d302eaf3bcbdf4", "best_bid": "0.39", "best_ask": "0.41"}, {"asset_id": "8865170260028111071866974003576531745326850065489847482638010827443159829381", "price": "0.74", "size": "219", "side": "SELL", "hash": "c5e1945d038d619940f9d0a4846d33fbac6d39fd", "best_bid": "0.59", "best_ask": "0.61"}], "timestamp": "1769384523419", "event_type": "price_change"}}
{"_local_timestamp": "2026-01-25T23:42:03.491180+00:00", "data": {"market": "0xd2cf2ac9bf4caf3995f8d8ff4649688430c6733df13ab2d03e3e0756f36f2acb", "price_changes": [{"asset_id": "112139909108928670085933588651092403343948617179385187166440073666455678398436", "price": "0.42", "size": "335", "side": "SELL", "hash": "40d28f98c647b793aa74d407d8d302eaf3bcbdf4", "best_bid": "0.39", "best_ask": "0.41"}, {"asset_id": "8865170260028111071866974003576531745326850065489847482638010827443159829381", "price": "0.58", "size": "335", "side": "BUY", "hash": "c5e1945d038d619940f9d0a4846d33fbac6d39fd", "best_bid": "0.59", "best_ask": "0.61"}], "timestamp": "1769384523419", "event_type": "price_change"}}
{"_local_timestamp": "2026-01-25T23:42:03.492128+00:00", "data": {"market": "0xd2cf2ac9bf4caf3995f8d8ff4649688430c6733df13ab2d03e3e0756f36f2acb", "price_changes": [{"asset_id": "112139909108928670085933588651092403343948617179385187166440073666455678398436", "price": "0.47", "size": "10", "side": "SELL", "hash": "40d28f98c647b793aa74d407d8d302eaf3bcbdf4", "best_bid": "0.39", "best_ask": "0.41"}, {"asset_id": "8865170260028111071866974003576531745326850065489847482638010827443159829381", "price": "0.53", "size": "10", "side": "BUY", "hash": "c5e1945d038d619940f9d0a4846d33fbac6d39fd", "best_bid": "0.59", "best_ask": "0.61"}], "timestamp": "1769384523419", "event_type": "price_change"}}
{"_local_timestamp": "2026-01-25T23:42:03.612403+00:00", "data": {"market": "0xd2cf2ac9bf4caf3995f8d8ff4649688430c6733df13ab2d03e3e0756f36f2acb", "price_changes": [{"asset_id": "112139909108928670085933588651092403343948617179385187166440073666455678398436", "price": "0.48", "size": "15.87", "side": "SELL", "hash": "ea9e3f8c20e701d85c7d610f5bff96adc10697c2", "best_bid": "0.39", "best_ask": "0.41"}, {"asset_id": "8865170260028111071866974003576531745326850065489847482638010827443159829381", "price": "0.52", "size": "15.87", "side": "BUY", "hash": "7081a361c7fa44a453fc96776139a12e4bb281f1", "best_bid": "0.59", "best_ask": "0.61"}], "timestamp": "1769384523543", "event_type": "price_change"}}
{"_local_timestamp": "2026-01-25T23:42:03.613528+00:00", "data": {"market": "0xd2cf2ac9bf4caf3995f8d8ff4649688430c6733df13ab2d03e3e0756f36f2acb", "price_changes": [{"asset_id": "112139909108928670085933588651092403343948617179385187166440073666455678398436", "price": "0.39", "size": "62.71", "side": "BUY", "hash": "afb09a51a745b742ebed69a1e5a44fa57a61d7cf", "best_bid": "0.39", "best_ask": "0.41"}, {"asset_id": "8865170260028111071866974003576531745326850065489847482638010827443159829381", "price": "0.61", "size": "62.71", "side": "SELL", "hash": "e53400c2b0c9204ec91dfe8e0d5b3608480c18fa", "best_bid": "0.59", "best_ask": "0.61"}], "timestamp": "1769384523544", "event_type": "price_change"}}
{"_local_timestamp": "2026-01-25T23:42:03.614497+00:00", "data": {"market": "0xd2cf2ac9bf4caf3995f8d8ff4649688430c6733df13ab2d03e3e0756f36f2acb", "price_changes": [{"asset_id": "112139909108928670085933588651092403343948617179385187166440073666455678398436", "price": "0.17", "size": "1112", "side": "BUY", "hash": "deb93085bcc86b57e687001897122790780c2e39", "best_bid": "0.39", "best_ask": "0.41"}, {"asset_id": "8865170260028111071866974003576531745326850065489847482638010827443159829381", "price": "0.83", "size": "1112", "side": "SELL", "hash": "7ddeb9c8fd7f1c65bb9725b0b746353253f3960d", "best_bid": "0.59", "best_ask": "0.61"}], "timestamp": "1769384523545", "event_type": "price_change"}}
{"_local_timestamp": "2026-01-25T23:42:03.615455+00:00", "data": {"market": "0xd2cf2ac9bf4caf3995f8d8ff4649688430c6733df13ab2d03e3e0756f36f2acb", "price_changes": [{"asset_id": "112139909108928670085933588651092403343948617179385187166440073666455678398436", "price": "0.26", "size": "366", "side": "BUY", "hash": "c3ebca06f706599fd1207ee31ac33ef81d3684e8", "best_bid": "0.39", "best_ask": "0.41"}, {"asset_id": "8865170260028111071866974003576531745326850065489847482638010827443159829381", "price": "0.74", "size": "366", "side": "SELL", "hash": "a120ba90dafb091af094011ada93dfe6f9bb1a59", "best_bid": "0.59", "best_ask": "0.61"}], "timestamp": "1769384523546", "event_type": "price_change"}}
