{"_local_timestamp": "2026-01-25T23:40:29.769120+00:00", "data": [{"market": "0x9472be65457510b7fc3477b20ba90910e99d92eac8421a14bf4b7b7a08ef31dc", "asset_id": "43311793366960417907757893276427136943959788721376762326430771171648759300146", "timestamp": "1769384429199", "hash": "78dd5fbf054a15d8fe1dd1ba93b957ac073eec08", "bids": [{"price": "0.001", "size": "7393.14"}, {"price": "0.002", "size": "5.24"}, {"price": "0.003", "size": "1400"}, {"price": "0.004", "size": "9.09"}, {"price": "0.006", "size": "200"}, {"price": "0.01", "size": "23"}, {"price": "0.011", "size": "17.96"}, {"price": "0.03", "size": "2500"}, {"price": "0.037", "size": "3000"}, {"price": "0.05", "size": "380"}, {"price": "0.051", "size": "11.87"}, {"price": "0.1", "size": "360"}, {"price": "0.15", "size": "226.66"}, {"price": "0.2", "size": "160"}, {"price": "0.201", "size": "5.69"}, {"price": "0.223", "size": "165"}, {"price": "0.25", "size": "112"}, {"price": "0.3", "size": "86.66"}, {"price": "0.35", "size": "68.57"}, {"price": "0.4", "size": "50"}, {"price": "0.447", "size": "1000"}, {"price": "0.46", "size": "5181"}, {"price": "0.461", "size": "191"}, {"price": "0.462", "size": "5"}, {"price": "0.48", "size": "5"}, {"price": "0.523", "size": "150"}, {"price": "0.67", "size": "5"}, {"price": "0.723", "size": "88"}, {"price": "0.823", "size": "190"}, {"price": "0.87", "size": "10"}, {"price": "0.871", "size": "20"}, {"price": "0.883", "size": "25"}, {"price": "0.923", "size": "399"}, {"price": "0.925", "size": "756"}, {"price": "0.938", "size": "408.81"}, {"price": "0.959", "size": "613.23"}, {"price": "0.975", "size": "1796.98"}, {"price": "0.977", "size": "150"}, {"price": "0.978", "size": "306.61"}, {"price": "0.979", "size": "145"}, {"price": "0.98", "size": "460.33"}, {"price": "0.982", "size": "376.79"}, {"price": "0.985", "size": "88.12"}, {"price": "0.986", "size": "1796.98"}, {"price": "0.987", "size": "341.69"}, {"price": "0.99", "size": "50"}, {"price": "0.991", "size": "263.98"}, {"price": "0.993", "size": "495.05"}, {"price": "0.994", "size": "1580.14"}, {"price": "0.995", "size": "973.54"}], "asks": [{"price": "0.999", "size": "13015.1"}, {"price": "0.998", "size": "139.66"}], "event_type": "book", "last_trade_price": "0.002"}, {"market": "0x50c669f178da4e5bbea7f1be25041fd278914712fa87a6a6f8e57d5923d88dee", "asset_id": "74040420326294854165772767082819937451857852955603897473157746262672057685461", "timestamp": "1769384345478", "hash": "322d93fdcef521aa0c05cbd69fabdc4e28b9bb04", "bids": [{"price": "0.001", "size": "7167.15"}, {"price": "0.002", "size": "5.24"}, {"price": "0.003", "size": "1400"}, {"price": "0.004", "size": "9.09"}, {"price": "0.006", "size": "200"}, {"price": "0.01", "size": "23"}, {"price": "0.011", "size": "17.96"}, {"price": "0.029", "size": "3000"}, {"price": "0.05", "size": "40"}, {"price": "0.051", "size": "11.87"}, {"price": "0.1", "size": "360"}, {"price": "0.15", "size": "226.66"}, {"price": "0.2", "size": "165"}, {"price": "0.201", "size": "5.69"}, {"price": "0.223", "size": "154"}, {"price": "0.25", "size": "112"}, {"price": "0.3", "size": "86.66"}, {"price": "0.35", "size": "68.57"}, {"price": "0.4", "size": "50"}, {"price": "0.42", "size": "555"}, {"price": "0.467", "size": "1000"}, {"price": "0.468", "size": "5098"}, {"price": "0.469", "size": "5"}, {"price": "0.523", "size": "158"}, {"price": "0.6", "size": "5"}, {"price": "0.723", "size": "256"}, {"price": "0.823", "size": "219"}, {"price": "0.87", "size": "10"}, {"price": "0.871", "size": "25"}, {"price": "0.878", "size": "295.98"}, {"price": "0.879", "size": "20"}, {"price": "0.908", "size": "282.51"}, {"price": "0.909", "size": "30"}, {"price": "0.923", "size": "1785"}, {"price": "0.931", "size": "856"}, {"price": "0.95", "size": "62.24"}, {"price": "0.968", "size": "44.99"}, {"price": "0.975", "size": "1202.94"}, {"price": "0.977", "size": "100"}, {"price": "0.98", "size": "403.96"}, {"price": "0.984", "size": "100.1"}, {"price": "0.986", "size": "2905.56"}, {"price": "0.992", "size": "996.44"}, {"price": "0.993", "size": "991.09"}, {"price": "0.995", "size": "815.95"}], "asks": [{"price": "0.999", "size": "10101.55"}, {"price": "0.998", "size": "141.7"}], "event_type": "book", "last_trade_price": "0.002"}, {"market": "0x50c669f178da4e5bbea7f1be25041fd278914712fa87a6a6f8e57d5923d88dee", "asset_id": "24682525479474221428144937281315825971983904267399062415430320764754931667953", "timestamp": "1769384345478", "hash": "8561990949cabc9e4a601152561236d87de35b0e", "bids": [{"price": "0.001", "size": "10101.55"}, {"price": "0.002", "size": "141.7"}], "asks": [{"price": "0.999", "size": "7167.15"}, {"price": "0.998", "size": "5.24"}, {"price": "0.997", "size": "1400"}, {"price": "0.996", "size": "9.09"}, {"price": "0.994", "size": "200"}, {"price": "0.99", "size": "23"}, {"price": "0.989", "size": "17.96"}, {"price": "0.971", "size": "3000"}, {"price": "0.95", "size": "40"}, {"price": "0.949", "size": "11.87"}, {"price": "0.9", "size": "360"}, {"price": "0.85", "size": "226.66"}, {"price": "0.8", "size": "165"}, {"price": "0.799", "size": "5.69"}, {"price": "0.777", "size": "154"}, {"price": "0.75", "size": "112"}, {"price": "0.7", "size": "86.66"}, {"price": "0.65", "size": "68.57"}, {"price": "0.6", "size": "50"}, {"price": "0.58", "size": "555"}, {"price": "0.533", "size": "1000"}, {"price": "0.532", "size": "5098"}, {"price": "0.531", "size": "5"}, {"price": "0.477", "size": "158"}, {"price": "0.4", "size": "5"}, {"price": "0.277", "size": "256"}, {"price": "0.177", "size": "219"}, {"price": "0.13", "size": "10"}, {"price": "0.129", "size": "25"}, {"price": "0.122", "size": "295.98"}, {"price": "0.121", "size": "20"}, {"price": "0.092", "size": "282.51"}, {"price": "0.091", "size": "30"}, {"price": "0.077", "size": "1785"}, {"price": "0.069", "size": "856"}, {"price": "0.05", "size": "62.24"}, {"price": "0.032", "size": "44.99"}, {"price": "0.025", "size": "1202.94"}, {"price": "0.023", "size": "100"}, {"price": "0.02", "size": "403.96"}, {"price": "0.016", "size": "100.1"}, {"price": "0.014", "size": "2905.56"}, {"price": "0.008", "size": "996.44"}, {"price": "0.007", "size": "991.09"}, {"price": "0.005", "size": "815.95"}], "event_type": "book", "last_trade_price": "0.002"}, {"market": "0x9472be65457510b7fc3477b20ba90910e99d92eac8421a14bf4b7b7a08ef31dc", "asset_id": "73414222381656326204771753454630063673548497164758947581648273905027617570612", "timestamp": "1769384429199", "hash": "e17fce61d46cce2eea09f9089128fcaa8860b7e4", "bids": [{"price": "0.001", "size": "13015.1"}, {"price": "0.002", "size": "139.66"}], "asks": [{"price": "0.999", "size": "7393.14"}, {"price": "0.998", "size": "5.24"}, {"price": "0.997", "size": "1400"}, {"price": "0.996", "size": "9.09"}, {"price": "0.994", "size": "200"}, {"price": "0.99", "size": "23"}, {"price": "0.989", "size": "17.96"}, {"price": "0.97", "size": "2500"}, {"price": "0.963", "size": "3000"}, {"price": "0.95", "size": "380"}, {"price": "0.949", "size": "11.87"}, {"price": "0.9", "size": "360"}, {"price": "0.85", "size": "226.66"}, {"price": "0.8", "size": "160"}, {"price": "0.799", "size": "5.69"}, {"price": "0.777", "size": "165"}, {"price": "0.75", "size": "112"}, {"price": "0.7", "size": "86.66"}, {"price": "0.65", "size": "68.57"}, {"price": "0.6", "size": "50"}, {"price": "0.553", "size": "1000"}, {"price": "0.54", "size": "5181"}, {"price": "0.539", "size": "191"}, {"price": "0.538", "size": "5"}, {"price": "0.52", "size": "5"}, {"price": "0.477", "size": "150"}, {"price": "0.33", "size": "5"}, {"price": "0.277", "size": "88"}, {"price": "0.177", "size": "190"}, {"price": "0.13", "size": "10"}, {"price": "0.129", "size": "20"}, {"price": "0.117", "size": "25"}, {"price": "0.077", "size": "399"}, {"price": "0.075", "size": "756"}, {"price": "0.062", "size": "408.81"}, {"price": "0.041", "size": "613.23"}, {"price": "0.025", "size": "1796.98"}, {"price": "0.023", "size": "150"}, {"price": "0.022", "size": "306.61"}, {"price": "0.021", "size": "145"}, {"price": "0.02", "size": "460.33"}, {"price": "0.018", "size": "376.79"}, {"price": "0.015", "size": "88.12"}, {"price": "0.014", "size": "1796.98"}, {"price": "0.013", "size": "341.69"}, {"price": "0.01", "size": "50"}, {"price": "0.009", "size": "263.98"}, {"price": "0.007", "size": "495.05"}, {"price": "0.006", "size": "1580.14"}, {"price": "0.005", "size": "973.54"}], "event_type": "book", "last_trade_price": "0.002"}, {"market": "0x2393ed0b0fdc450054c7b9071907eca75cf4fc36e385adf4a0a5f99ee62243e8", "asset_id": "32769749367306925959219403371425714180265458150646381231272229429098460625924", "timestamp": "1769384429322", "hash": "fee93dab3268c23cd2f8dd6a91aa0ff9de37fb49", "bids": [{"price": "0.001", "size": "4369.63"}, {"price": "0.002", "size": "1255.29"}, {"price": "0.003", "size": "1400"}, {"price": "0.004", "size": "9.17"}, {"price": "0.006", "size": "200"}, {"price": "0.01", "size": "453"}, {"price": "0.011", "size": "21.1"}, {"price": "0.03", "size": "1561.08"}, {"price": "0.05", "size": "210"}, {"price": "0.057", "size": "1821.72"}, {"price": "0.058", "size": "9.32"}, {"price": "0.1", "size": "365.12"}, {"price": "0.14", "size": "242.85"}, {"price": "0.19", "size": "168.42"}, {"price": "0.191", "size": "6.14"}, {"price": "0.24", "size": "116.66"}, {"price": "0.25", "size": "700"}, {"price": "0.259", "size": "300"}, {"price": "0.26", "size": "5317"}, {"price": "0.29", "size": "89.65"}, {"price": "0.34", "size": "70.58"}, {"price": "0.38", "size": "52.63"}, {"price": "0.4", "size": "16.54"}, {"price": "0.477", "size": "284.58"}, {"price": "0.51", "size": "399"}, {"price": "0.511", "size": "400"}, {"price": "0.512", "size": "5"}, {"price": "0.829", "size": "120"}, {"price": "0.835", "size": "119"}, {"price": "0.836", "size": "20"}, {"price": "0.847", "size": "25"}, {"price": "0.883", "size": "259.4"}, {"price": "0.889", "size": "453.84"}, {"price": "0.895", "size": "30"}, {"price": "0.906", "size": "55"}, {"price": "0.907", "size": "37.81"}], "asks": [{"price": "0.999", "size": "832.39"}, {"price": "0.998", "size": "2100"}, {"price": "0.997", "size": "3507.68"}, {"price": "0.995", "size": "1311"}, {"price": "0.994", "size": "6.27"}, {"price": "0.993", "size": "50"}, {"price": "0.99", "size": "457.99"}, {"price": "0.989", "size": "14.68"}, {"price": "0.975", "size": "30.53"}, {"price": "0.972", "size": "9.4"}, {"price": "0.967", "size": "199.82"}, {"price": "0.966", "size": "112.19"}, {"price": "0.961", "size": "88.8"}, {"price": "0.96", "size": "60"}], "event_type": "book", "last_trade_price": "0.111"}, {"market": "0x2393ed0b0fdc450054c7b9071907eca75cf4fc36e385adf4a0a5f99ee62243e8", "asset_id": "100074770378634056601572485653252702850363676459996771990439989989293515601975", "timestamp": "1769384429322", "hash": "a128f5eefdab07c6e7ed5c11f0b83fc331fcc460", "bids": [{"price": "0.001", "size": "832.39"}, {"price": "0.002", "size": "2100"}, {"price": "0.003", "size": "3507.68"}, {"price": "0.005", "size": "1311"}, {"price": "0.006", "size": "6.27"}, {"price": "0.007", "size": "50"}, {"price": "0.01", "size": "457.99"}, {"price": "0.011", "size": "14.68"}, {"price": "0.025", "size": "30.53"}, {"price": "0.028", "size": "9.4"}, {"price": "0.033", "size": "199.82"}, {"price": "0.034", "size": "112.19"}, {"price": "0.039", "size": "88.8"}, {"price": "0.04", "size": "60"}], "asks": [{"price": "0.999", "size": "4369.63"}, {"price": "0.998", "size": "1255.29"}, {"price": "0.997", "size": "1400"}, {"price": "0.996", "size": "9.17"}, {"price": "0.994", "size": "200"}, {"price": "0.99", "size": "453"}, {"price": "0.989", "size": "21.1"}, {"price": "0.97", "size": "1561.08"}, {"price": "0.95", "size": "210"}, {"price": "0.943", "size": "1821.72"}, {"price": "0.942", "size": "9.32"}, {"price": "0.9", "size": "365.12"}, {"price": "0.86", "size": "242.85"}, {"price": "0.81", "size": "168.42"}, {"price": "0.809", "size": "6.14"}, {"price": "0.76", "size": "116.66"}, {"price": "0.75", "size": "700"}, {"price": "0.741", "size": "300"}, {"price": "0.74", "size": "5317"}, {"price": "0.71", "size": "89.65"}, {"price": "0.66", "size": "70.58"}, {"price": "0.62", "size": "52.63"}, {"price": "0.6", "size": "16.54"}, {"price": "0.523", "size": "284.58"}, {"price": "0.49", "size": "399"}, {"price": "0.489", "size": "400"}, {"price": "0.488", "size": "5"}, {"price": "0.171", "size": "120"}, {"price": "0.165", "size": "119"}, {"price": "0.164", "size": "20"}, {"price": "0.153", "size": "25"}, {"price": "0.117", "size": "259.4"}, {"price": "0.111", "size": "453.84"}, {"price": "0.105", "size": "30"}, {"price": "0.094", "size": "55"}, {"price": "0.093", "size": "37.81"}], "event_type": "book", "last_trade_price": "0.111"}, {"market": "0x49686d26fb712515cd5e12c23f0a1c7e10214c7faa3cb0a730aabe0c33694082", "asset_id": "13244681086321087932946246027856416106585284024824496763706748621681543444582", "timestamp": "1769384321069", "hash": "29b56a0d0bbedea3717c7eb1502b01a3eb03af90", "bids": [{"price": "0.001", "size": "4291.7"}, {"price": "0.002", "size": "1250"}, {"price": "0.003", "size": "1000"}, {"price": "0.004", "size": "7.14"}, {"price": "0.01", "size": "23"}, {"price": "0.03", "size": "2000"}, {"price": "0.031", "size": "6.24"}, {"price": "0.05", "size": "30"}, {"price": "0.09", "size": "400"}, {"price": "0.091", "size": "3296"}, {"price": "0.14", "size": "242.85"}, {"price": "0.141", "size": "1134"}, {"price": "0.18", "size": "177.77"}, {"price": "0.181", "size": "882"}, {"price": "0.23", "size": "121.73"}, {"price": "0.248", "size": "300"}, {"price": "0.25", "size": "400"}, {"price": "0.251", "size": "1672"}, {"price": "0.27", "size": "96.29"}, {"price": "0.28", "size": "204.64"}, {"price": "0.32", "size": "2075"}, {"price": "0.35", "size": "5"}, {"price": "0.36", "size": "55.55"}, {"price": "0.635", "size": "30"}, {"price": "0.75", "size": "40"}, {"price": "0.751", "size": "10"}, {"price": "0.83", "size": "1500"}, {"price": "0.85", "size": "15"}, {"price": "0.86", "size": "948.91"}, {"price": "0.862", "size": "178.68"}, {"price": "0.865", "size": "103.1"}, {"price": "0.867", "size": "265.14"}], "asks": [{"price": "0.999", "size": "2020.07"}, {"price": "0.998", "size": "2361.62"}, {"price": "0.997", "size": "24.6"}, {"price": "0.995", "size": "99.51"}, {"price": "0.994", "size": "7.67"}, {"price": "0.993", "size": "150"}, {"price": "0.992", "size": "8.58"}, {"price": "0.99", "size": "376.91"}, {"price": "0.989", "size": "10.31"}, {"price": "0.988", "size": "5401.42"}, {"price": "0.985", "size": "131"}, {"price": "0.984", "size": "7.01"}, {"price": "0.98", "size": "41"}, {"price": "0.979", "size": "22.53"}, {"price": "0.97", "size": "363.11"}, {"price": "0.969", "size": "5.73"}, {"price": "0.963", "size": "137.49"}, {"price": "0.962", "size": "500"}, {"price": "0.96", "size": "272.33"}, {"price": "0.959", "size": "25"}, {"price": "0.958", "size": "10.42"}, {"price": "0.95", "size": "204.25"}, {"price": "0.94", "size": "153.18"}, {"price": "0.939", "size": "70"}, {"price": "0.93", "size": "114.89"}, {"price": "0.92", "size": "86.17"}, {"price": "0.919", "size": "5.78"}, {"price": "0.91", "size": "64.62"}, {"price": "0.904", "size": "36.5"}, {"price": "0.9", "size": "48.47"}, {"price": "0.898", "size": "134.85"}, {"price": "0.897", "size": "30"}, {"price": "0.896", "size": "40.31"}], "event_type": "book", "last_trade_price": "0.867"}, {"market": "0x49a20c7523c271099008f3ef9a31521263b24d637959852a391e6b4697b1a437", "asset_id": "13018971792603393862521629014128024641178044618205296260525674415067194037856", "timestamp": "1769384092489", "hash": "b12dec82ecad9a440ace0d0a50b72de76b4a1068", "bids": [{"price": "0.001", "size": "3144.68"}, {"price": "0.002", "size": "2137.18"}], "asks": [{"price": "0.999", "size": "5769.67"}, {"price": "0.998", "size": "5.25"}, {"price": "0.997", "size": "1400"}, {"price": "0.996", "size": "9.09"}, {"price": "0.994", "size": "200"}, {"price": "0.99", "size": "23"}, {"price": "0.989", "size": "17.97"}, {"price": "0.97", "size": "2500"}, {"price": "0.967", "size": "2950.95"}, {"price": "0.95", "size": "715"}, {"price": "0.949", "size": "11.87"}, {"price": "0.9", "size": "360"}, {"price": "0.88", "size": "1400"}, {"price": "0.85", "size": "226.66"}, {"price": "0.8", "size": "160"}, {"price": "0.799", "size": "5.69"}, {"price": "0.777", "size": "165"}, {"price": "0.75", "size": "209.57"}, {"price": "0.7", "size": "86.66"}, {"price": "0.65", "size": "68.57"}, {"price": "0.6", "size": "50"}, {"price": "0.596", "size": "400"}, {"price": "0.477", "size": "325"}, {"price": "0.468", "size": "300"}, {"price": "0.466", "size": "862.5"}, {"price": "0.462", "size": "646.87"}, {"price": "0.461", "size": "3523"}, {"price": "0.459", "size": "5"}, {"price": "0.277", "size": "89"}, {"price": "0.253", "size": "97.56"}, {"price": "0.177", "size": "189"}, {"price": "0.154", "size": "299.79"}, {"price": "0.153", "size": "531"}, {"price": "0.13", "size": "10"}, {"price": "0.128", "size": "25"}, {"price": "0.127", "size": "20"}, {"price": "0.077", "size": "439"}, {"price": "0.075", "size": "486"}, {"price": "0.074", "size": "430.15"}, {"price": "0.057", "size": "155.3"}, {"price": "0.04", "size": "43.47"}, {"price": "0.031", "size": "217.65"}, {"price": "0.028", "size": "73.73"}, {"price": "0.027", "size": "114.7"}, {"price": "0.021", "size": "509.48"}, {"price": "0.019", "size": "516.76"}, {"price": "0.015", "size": "775.15"}, {"price": "0.014", "size": "783.61"}, {"price": "0.013", "size": "509.47"}, {"price": "0.012", "size": "304.24"}, {"price": "0.011", "size": "101.85"}, {"price": "0.009", "size": "91.98"}], "event_type": "book", "last_trade_price": "0.002"}, {"market": "0xc55db914f0fd1fee18997706712c0dfd8d0369cdbef93a9fef12bd001914ca77", "asset_id": "114600293444080540179603459515770723592661967180480327891296353898330242622833", "timestamp": "1769384268370", "hash": "dc6298d719a69394a5897c335cb9b1b17c4a7a8b", "bids": [{"price": "0.001", "size": "8674.77"}, {"price": "0.002", "size": "5.25"}, {"price": "0.003", "size": "1400"}, {"price": "0.004", "size": "9.09"}, {"price": "0.006", "size": "200"}, {"price": "0.01", "size": "23"}, {"price": "0.011", "size": "17.97"}, {"price": "0.03", "size": "2500"}, {"price": "0.035", "size": "2999.96"}, {"price": "0.05", "size": "540"}, {"price": "0.051", "size": "11.87"}, {"price": "0.1", "size": "360"}, {"price": "0.15", "size": "226.66"}, {"price": "0.2", "size": "160"}, {"price": "0.201", "size": "5.69"}, {"price": "0.223", "size": "165"}, {"price": "0.25", "size": "112"}, {"price": "0.3", "size": "86.66"}, {"price": "0.35", "size": "68.57"}, {"price": "0.4", "size": "50"}, {"price": "0.435", "size": "586.12"}, {"price": "0.48", "size": "5"}, {"price": "0.523", "size": "350"}, {"price": "0.524", "size": "3639"}, {"price": "0.525", "size": "5"}, {"price": "0.723", "size": "179"}, {"price": "0.823", "size": "189"}, {"price": "0.836", "size": "231.9"}, {"price": "0.837", "size": "298"}, {"price": "0.838", "size": "238"}, {"price": "0.88", "size": "10"}, {"price": "0.881", "size": "20"}, {"price": "0.885", "size": "25"}, {"price": "0.923", "size": "762"}, {"price": "0.959", "size": "486"}, {"price": "0.975", "size": "1202.94"}, {"price": "0.977", "size": "100"}, {"price": "0.98", "size": "1699.98"}, {"price": "0.982", "size": "300"}, {"price": "0.984", "size": "160"}, {"price": "0.985", "size": "148.52"}, {"price": "0.986", "size": "1396"}, {"price": "0.988", "size": "526.11"}, {"price": "0.989", "size": "256.36"}, {"price": "0.99", "size": "99.99"}, {"price": "0.991", "size": "531.88"}, {"price": "0.993", "size": "28.91"}], "asks": [{"price": "0.999", "size": "13733.28"}], "event_type": "book", "last_trade_price": "0.001"}, {"market": "0xb9bbdd34304344dcc45803780a34c97d73a00133a5ecf70f63e1008b8abb2fca", "asset_id": "72012724360700510767037780555710363830014634797787940282136454146828040926557", "timestamp": "1769384094826", "hash": "e80c199aff4614ea2db156ad76b800a38aef529e", "bids": [{"price": "0.001", "size": "11594.04"}, {"price": "0.002", "size": "6666.38"}, {"price": "0.003", "size": "4421.14"}, {"price": "0.004", "size": "1.7"}], "asks": [{"price": "0.999", "size": "6103.59"}, {"price": "0.998", "size": "5.25"}, {"price": "0.997", "size": "1400"}, {"price": "0.996", "size": "9.09"}, {"price": "0.994", "size": "200"}, {"price": "0.99", "size": "23"}, {"price": "0.989", "size": "18.4"}, {"price": "0.95", "size": "40"}, {"price": "0.949", "size": "2942.02"}, {"price": "0.948", "size": "11.55"}, {"price": "0.9", "size": "637.06"}, {"price": "0.85", "size": "226.66"}, {"price": "0.8", "size": "160"}, {"price": "0.799", "size": "5.69"}, {"price": "0.777", "size": "165"}, {"price": "0.75", "size": "112"}, {"price": "0.7", "size": "86.66"}, {"price": "0.65", "size": "68.57"}, {"price": "0.6", "size": "50"}, {"price": "0.477", "size": "150"}, {"price": "0.449", "size": "500"}, {"price": "0.436", "size": "547.97"}, {"price": "0.425", "size": "444"}, {"price": "0.419", "size": "900"}, {"price": "0.418", "size": "3250"}, {"price": "0.417", "size": "5"}, {"price": "0.357", "size": "225.22"}, {"price": "0.277", "size": "88"}, {"price": "0.177", "size": "190"}, {"price": "0.162", "size": "148.24"}, {"price": "0.161", "size": "297"}, {"price": "0.16", "size": "238"}, {"price": "0.13", "size": "10"}, {"price": "0.129", "size": "20"}, {"price": "0.121", "size": "186.29"}, {"price": "0.119", "size": "25"}, {"price": "0.091", "size": "244.69"}, {"price": "0.077", "size": "407"}, {"price": "0.055", "size": "237.37"}, {"price": "0.049", "size": "200"}, {"price": "0.048", "size": "300.29"}, {"price": "0.025", "size": "990.09"}, {"price": "0.02", "size": "178.16"}, {"price": "0.019", "size": "703.11"}, {"price": "0.018", "size": "107.39"}, {"price": "0.014", "size": "127.22"}, {"price": "0.013", "size": "566.69"}, {"price": "0.012", "size": "619.99"}, {"price": "0.011", "size": "1034.38"}, {"price": "0.01", "size": "97.84"}, {"price": "0.009", "size": "30"}], "event_type": "book", "last_trade_price": "0.008"}, {"market": "0xb9bbdd34304344dcc45803780a34c97d73a00133a5ecf70f63e1008b8abb2fca", "asset_id": "8682484153073832526711485265636767086525069344085206423986003504588877767339", "timestamp": "1769384094826", "hash": "26440026d30a4704be2d3ff00f5910df249c6aee", "bids": [{"price": "0.001", "size": "6103.59"}, {"price": "0.002", "size": "5.25"}, {"price": "0.003", "size": "1400"}, {"price": "0.004", "size": "9.09"}, {"price": "0.006", "size": "200"}, {"price": "0.01", "size": "23"}, {"price": "0.011", "size": "18.4"}, {"price": "0.05", "size": "40"}, {"price": "0.051", "size": "2942.02"}, {"price": "0.052", "size": "11.55"}, {"price": "0.1", "size": "637.06"}, {"price": "0.15", "size": "226.66"}, {"price": "0.2", "size": "160"}, {"price": "0.201", "size": "5.69"}, {"price": "0.223", "size": "165"}, {"price": "0.25", "size": "112"}, {"price": "0.3", "size": "86.66"}, {"price": "0.35", "size": "68.57"}, {"price": "0.4", "size": "50"}, {"price": "0.523", "size": "150"}, {"price": "0.551", "size": "500"}, {"price": "0.564", "size": "547.97"}, {"price": "0.575", "size": "444"}, {"price": "0.581", "size": "900"}, {"price": "0.582", "size": "3250"}, {"price": "0.583", "size": "5"}, {"price": "0.643", "size": "225.22"}, {"price": "0.723", "size": "88"}, {"price": "0.823", "size": "190"}, {"price": "0.838", "size": "148.24"}, {"price": "0.839", "size": "297"}, {"price": "0.84", "size": "238"}, {"price": "0.87", "size": "10"}, {"price": "0.871", "size": "20"}, {"price": "0.879", "size": "186.29"}, {"price": "0.881", "size": "25"}, {"price": "0.909", "size": "244.69"}, {"price": "0.923", "size": "407"}, {"price": "0.945", "size": "237.37"}, {"price": "0.951", "size": "200"}, {"price": "0.952", "size": "300.29"}, {"price": "0.975", "size": "990.09"}, {"price": "0.98", "size": "178.16"}, {"price": "0.981", "size": "703.11"}, {"price": "0.982", "size": "107.39"}, {"price": "0.986", "size": "127.22"}, {"price": "0.987", "size": "566.69"}, {"price": "0.988", "size": "619.99"}, {"price": "0.989", "size": "1034.38"}, {"price": "0.99", "size": "97.84"}, {"price": "0.991", "size": "30"}], "asks": [{"price": "0.999", "size": "11594.04"}, {"price": "0.998", "size": "6666.38"}, {"price": "0.997", "size": "4421.14"}, {"price": "0.996", "size": "1.7"}], "event_type": "book", "last_trade_price": "0.008"}, {"market": "0x49686d26fb712515cd5e12c23f0a1c7e10214c7faa3cb0a730aabe0c33694082", "asset_id": "30442780799048074404860985387051749017905070253466005720364298335239299761065", "timestamp": "1769384321069", "hash": "cd8a1ca5f9552fe05ab85361bd9028a49044b016", "bids": [{"price": "0.001", "size": "2020.07"}, {"price": "0.002", "size": "2361.62"}, {"price": "0.003", "size": "24.6"}, {"price": "0.005", "size": "99.51"}, {"price": "0.006", "size": "7.67"}, {"price": "0.007", "size": "150"}, {"price": "0.008", "size": "8.58"}, {"price": "0.01", "size": "376.91"}, {"price": "0.011", "size": "10.31"}, {"price": "0.012", "size": "5401.42"}, {"price": "0.015", "size": "131"}, {"price": "0.016", "size": "7.01"}, {"price": "0.02", "size": "41"}, {"price": "0.021", "size": "22.53"}, {"price": "0.03", "size": "363.11"}, {"price": "0.031", "size": "5.73"}, {"price": "0.037", "size": "137.49"}, {"price": "0.038", "size": "500"}, {"price": "0.04", "size": "272.33"}, {"price": "0.041", "size": "25"}, {"price": "0.042", "size": "10.42"}, {"price": "0.05", "size": "204.25"}, {"price": "0.06", "size": "153.18"}, {"price": "0.061", "size": "70"}, {"price": "0.07", "size": "114.89"}, {"price": "0.08", "size": "86.17"}, {"price": "0.081", "size": "5.78"}, {"price": "0.09", "size": "64.62"}, {"price": "0.096", "size": "36.5"}, {"price": "0.1", "size": "48.47"}, {"price": "0.102", "size": "134.85"}, {"price": "0.103", "size": "30"}, {"price": "0.104", "size": "40.31"}], "asks": [{"price": "0.999", "size": "4291.7"}, {"price": "0.998", "size": "1250"}, {"price": "0.997", "size": "1000"}, {"price": "0.996", "size": "7.14"}, {"price": "0.99", "size": "23"}, {"price": "0.97", "size": "2000"}, {"price": "0.969", "size": "6.24"}, {"price": "0.95", "size": "30"}, {"price": "0.91", "size": "400"}, {"price": "0.909", "size": "3296"}, {"price": "0.86", "size": "242.85"}, {"price": "0.859", "size": "1134"}, {"price": "0.82", "size": "177.77"}, {"price": "0.819", "size": "882"}, {"price": "0.77", "size": "121.73"}, {"price": "0.752", "size": "300"}, {"price": "0.75", "size": "400"}, {"price": "0.749", "size": "1672"}, {"price": "0.73", "size": "96.29"}, {"price": "0.72", "size": "204.64"}, {"price": "0.68", "size": "2075"}, {"price": "0.65", "size": "5"}, {"price": "0.64", "size": "55.55"}, {"price": "0.365", "size": "30"}, {"price": "0.25", "size": "40"}, {"price": "0.249", "size": "10"}, {"price": "0.17", "size": "1500"}, {"price": "0.15", "size": "15"}, {"price": "0.14", "size": "948.91"}, {"price": "0.138", "size": "178.68"}, {"price": "0.135", "size": "103.1"}, {"price": "0.133", "size": "265.14"}], "event_type": "book", "last_trade_price": "0.867"}, {"market": "0x44f08744458b8896620cd3330bc5e1ea69df4199b02d4fc583b3fc96e5d314ce", "asset_id": "49194009556504828848509244326501559253829462790583873936160989575507522044057", "timestamp": "1769384369376", "hash": "5361a0a230109d579d4128614b9eeb1a2af7b57f", "bids": [{"price": "0.001", "size": "7843.07"}, {"price": "0.002", "size": "2570.71"}, {"price": "0.003", "size": "2000"}], "asks": [{"price": "0.999", "size": "3630.98"}, {"price": "0.998", "size": "1255.25"}, {"price": "0.997", "size": "1400"}, {"price": "0.996", "size": "9.1"}, {"price": "0.994", "size": "200"}, {"price": "0.99", "size": "23"}, {"price": "0.989", "size": "7.83"}, {"price": "0.973", "size": "777"}, {"price": "0.972", "size": "5.16"}, {"price": "0.968", "size": "510"}, {"price": "0.967", "size": "420"}, {"price": "0.95", "size": "650"}, {"price": "0.948", "size": "353"}, {"price": "0.946", "size": "450"}, {"price": "0.944", "size": "377"}, {"price": "0.943", "size": "3200"}, {"price": "0.942", "size": "9.87"}, {"price": "0.9", "size": "360"}, {"price": "0.85", "size": "226.66"}, {"price": "0.8", "size": "160"}, {"price": "0.799", "size": "5.69"}, {"price": "0.75", "size": "600.64"}, {"price": "0.7", "size": "86.66"}, {"price": "0.65", "size": "68.57"}, {"price": "0.6", "size": "200"}, {"price": "0.599", "size": "4727"}, {"price": "0.598", "size": "5"}, {"price": "0.52", "size": "85"}, {"price": "0.46", "size": "30"}, {"price": "0.45", "size": "50"}, {"price": "0.42", "size": "30"}, {"price": "0.38", "size": "40"}, {"price": "0.32", "size": "30"}, {"price": "0.29", "size": "30"}, {"price": "0.28", "size": "111.11"}, {"price": "0.275", "size": "200"}, {"price": "0.24", "size": "40"}, {"price": "0.21", "size": "30"}, {"price": "0.196", "size": "261.26"}, {"price": "0.19", "size": "30"}, {"price": "0.17", "size": "406.49"}, {"price": "0.14", "size": "50"}, {"price": "0.13", "size": "10"}, {"price": "0.126", "size": "125.46"}, {"price": "0.125", "size": "20"}, {"price": "0.101", "size": "651.53"}, {"price": "0.099", "size": "25"}, {"price": "0.098", "size": "30"}, {"price": "0.075", "size": "868.7"}, {"price": "0.065", "size": "732.97"}, {"price": "0.051", "size": "385"}, {"price": "0.048", "size": "539.8"}, {"price": "0.037", "size": "809.7"}, {"price": "0.028", "size": "404.86"}, {"price": "0.027", "size": "114.7"}, {"price": "0.021", "size": "304.49"}, {"price": "0.02", "size": "319"}, {"price": "0.017", "size": "367.57"}, {"price": "0.016", "size": "60"}, {"price": "0.015", "size": "10.6"}], "event_type": "book", "last_trade_price": "0.006"}, {"market": "0x44f08744458b8896620cd3330bc5e1ea69df4199b02d4fc583b3fc96e5d314ce", "asset_id": "72327831507226612545928776794104143393438710920370371172884559893525100761096", "timestamp": "1769384369376", "hash": "3d06056b7a712f64048e4630c53546fc80fad283", "bids": [{"price": "0.001", "size": "3630.98"}, {"price": "0.002", "size": "1255.25"}, {"price": "0.003", "size": "1400"}, {"price": "0.004", "size": "9.1"}, {"price": "0.006", "size": "200"}, {"price": "0.01", "size": "23"}, {"price": "0.011", "size": "7.83"}, {"price": "0.027", "size": "777"}, {"price": "0.028", "size": "5.16"}, {"price": "0.032", "size": "510"}, {"price": "0.033", "size": "420"}, {"price": "0.05", "size": "650"}, {"price": "0.052", "size": "353"}, {"price": "0.054", "size": "450"}, {"price": "0.056", "size": "377"}, {"price": "0.057", "size": "3200"}, {"price": "0.058", "size": "9.87"}, {"price": "0.1", "size": "360"}, {"price": "0.15", "size": "226.66"}, {"price": "0.2", "size": "160"}, {"price": "0.201", "size": "5.69"}, {"price": "0.25", "size": "600.64"}, {"price": "0.3", "size": "86.66"}, {"price": "0.35", "size": "68.57"}, {"price": "0.4", "size": "200"}, {"price": "0.401", "size": "4727"}, {"price": "0.402", "size": "5"}, {"price": "0.48", "size": "85"}, {"price": "0.54", "size": "30"}, {"price": "0.55", "size": "50"}, {"price": "0.58", "size": "30"}, {"price": "0.62", "size": "40"}, {"price": "0.68", "size": "30"}, {"price": "0.71", "size": "30"}, {"price": "0.72", "size": "111.11"}, {"price": "0.725", "size": "200"}, {"price": "0.76", "size": "40"}, {"price": "0.79", "size": "30"}, {"price": "0.804", "size": "261.26"}, {"price": "0.81", "size": "30"}, {"price": "0.83", "size": "406.49"}, {"price": "0.86", "size": "50"}, {"price": "0.87", "size": "10"}, {"price": "0.874", "size": "125.46"}, {"price": "0.875", "size": "20"}, {"price": "0.899", "size": "651.53"}, {"price": "0.901", "size": "25"}, {"price": "0.902", "size": "30"}, {"price": "0.925", "size": "868.7"}, {"price": "0.935", "size": "732.97"}, {"price": "0.949", "size": "385"}, {"price": "0.952", "size": "539.8"}, {"price": "0.963", "size": "809.7"}, {"price": "0.972", "size": "404.86"}, {"price": "0.973", "size": "114.7"}, {"price": "0.979", "size": "304.49"}, {"price": "0.98", "size": "319"}, {"price": "0.983", "size": "367.57"}, {"price": "0.984", "size": "60"}, {"price": "0.985", "size": "10.6"}], "asks": [{"price": "0.999", "size": "7843.07"}, {"price": "0.998", "size": "2570.71"}, {"price": "0.997", "size": "2000"}], "event_type": "book", "last_trade_price": "0.006"}, {"market": "0xaf9d0e448129a9f657f851d49495ba4742055d80e0ef1166ba0ee81d4d594214", "asset_id": "101676997363687199724245607342877036148401850938023978421879460310389391082353", "timestamp": "1769384309968", "hash": "1226d2ff2eeef23b23e44937ce48e9216defd180", "bids": [{"price": "0.001", "size": "14571.68"}, {"price": "0.002", "size": "11638.12"}, {"price": "0.003", "size": "1030.11"}, {"price": "0.004", "size": "1224.47"}, {"price": "0.005", "size": "1531.11"}, {"price": "0.01", "size": "20362.82"}, {"price": "0.011", "size": "1649.9"}, {"price": "0.012", "size": "311.88"}], "asks": [{"price": "0.999", "size": "3726.29"}, {"price": "0.998", "size": "1250"}, {"price": "0.997", "size": "1407"}, {"price": "0.994", "size": "200"}, {"price": "0.993", "size": "10.29"}, {"price": "0.99", "size": "28"}, {"price": "0.98", "size": "5000"}, {"price": "0.979", "size": "10.56"}, {"price": "0.95", "size": "120"}, {"price": "0.934", "size": "1800"}, {"price": "0.933", "size": "7.94"}, {"price": "0.91", "size": "706.18"}, {"price": "0.9", "size": "360"}, {"price": "0.85", "size": "226.66"}, {"price": "0.849", "size": "13"}, {"price": "0.8", "size": "160"}, {"price": "0.799", "size": "5.68"}, {"price": "0.75", "size": "112"}, {"price": "0.7", "size": "86.66"}, {"price": "0.66", "size": "70.58"}, {"price": "0.62", "size": "50.27"}, {"price": "0.61", "size": "51.28"}, {"price": "0.52", "size": "143.54"}, {"price": "0.5", "size": "5"}, {"price": "0.39", "size": "900"}, {"price": "0.38", "size": "10.94"}, {"price": "0.303", "size": "300"}, {"price": "0.302", "size": "67.05"}, {"price": "0.301", "size": "400"}, {"price": "0.214", "size": "107.66"}, {"price": "0.139", "size": "58.53"}, {"price": "0.13", "size": "72.47"}, {"price": "0.114", "size": "215.33"}, {"price": "0.113", "size": "25"}, {"price": "0.112", "size": "30"}, {"price": "0.088", "size": "908"}, {"price": "0.08", "size": "637.13"}, {"price": "0.068", "size": "348.57"}, {"price": "0.067", "size": "348.58"}, {"price": "0.066", "size": "1540.04"}, {"price": "0.065", "size": "60"}, {"price": "0.064", "size": "17.08"}], "event_type": "book", "last_trade_price": "0.988"}, {"market": "0x49a20c7523c271099008f3ef9a31521263b24d637959852a391e6b4697b1a437", "asset_id": "55881023621710858558280545117465775643848233756850602339827152783696837905531", "timestamp": "1769384092489", "hash": "dd50868d3f7f2174bece3aabed904e12ca61f977", "bids": [{"price": "0.001", "size": "5769.67"}, {"price": "0.002", "size": "5.25"}, {"price": "0.003", "size": "1400"}, {"price": "0.004", "size": "9.09"}, {"price": "0.006", "size": "200"}, {"price": "0.01", "size": "23"}, {"price": "0.011", "size": "17.97"}, {"price": "0.03", "size": "2500"}, {"price": "0.033", "size": "2950.95"}, {"price": "0.05", "size": "715"}, {"price": "0.051", "size": "11.87"}, {"price": "0.1", "size": "360"}, {"price": "0.12", "size": "1400"}, {"price": "0.15", "size": "226.66"}, {"price": "0.2", "size": "160"}, {"price": "0.201", "size": "5.69"}, {"price": "0.223", "size": "165"}, {"price": "0.25", "size": "209.57"}, {"price": "0.3", "size": "86.66"}, {"price": "0.35", "size": "68.57"}, {"price": "0.4", "size": "50"}, {"price": "0.404", "size": "400"}, {"price": "0.523", "size": "325"}, {"price": "0.532", "size": "300"}, {"price": "0.534", "size": "862.5"}, {"price": "0.538", "size": "646.87"}, {"price": "0.539", "size": "3523"}, {"price": "0.541", "size": "5"}, {"price": "0.723", "size": "89"}, {"price": "0.747", "size": "97.56"}, {"price": "0.823", "size": "189"}, {"price": "0.846", "size": "299.79"}, {"price": "0.847", "size": "531"}, {"price": "0.87", "size": "10"}, {"price": "0.872", "size": "25"}, {"price": "0.873", "size": "20"}, {"price": "0.923", "size": "439"}, {"price": "0.925", "size": "486"}, {"price": "0.926", "size": "430.15"}, {"price": "0.943", "size": "155.3"}, {"price": "0.96", "size": "43.47"}, {"price": "0.969", "size": "217.65"}, {"price": "0.972", "size": "73.73"}, {"price": "0.973", "size": "114.7"}, {"price": "0.979", "size": "509.48"}, {"price": "0.981", "size": "516.76"}, {"price": "0.985", "size": "775.15"}, {"price": "0.986", "size": "783.61"}, {"price": "0.987", "size": "509.47"}, {"price": "0.988", "size": "304.24"}, {"price": "0.989", "size": "101.85"}, {"price": "0.991", "size": "91.98"}], "asks": [{"price": "0.999", "size": "3144.68"}, {"price": "0.998", "size": "2137.18"}], "event_type": "book", "last_trade_price": "0.002"}, {"market": "0xaf9d0e448129a9f657f851d49495ba4742055d80e0ef1166ba0ee81d4d594214", "asset_id": "4153292802911610701832309484716814274802943278345248636922528170020319407796", "timestamp": "1769384309968", "hash": "6159613ce04ffc8653d4cbbe86380e044ddc0db8", "bids": [{"price": "0.001", "size": "3726.29"}, {"price": "0.002", "size": "1250"}, {"price": "0.003", "size": "1407"}, {"price": "0.006", "size": "200"}, {"price": "0.007", "size": "10.29"}, {"price": "0.01", "size": "28"}, {"price": "0.02", "size": "5000"}, {"price": "0.021", "size": "10.56"}, {"price": "0.05", "size": "120"}, {"price": "0.066", "size": "1800"}, {"price": "0.067", "size": "7.94"}, {"price": "0.09", "size": "706.18"}, {"price": "0.1", "size": "360"}, {"price": "0.15", "size": "226.66"}, {"price": "0.151", "size": "13"}, {"price": "0.2", "size": "160"}, {"price": "0.201", "size": "5.68"}, {"price": "0.25", "size": "112"}, {"price": "0.3", "size": "86.66"}, {"price": "0.34", "size": "70.58"}, {"price": "0.38", "size": "50.27"}, {"price": "0.39", "size": "51.28"}, {"price": "0.48", "size": "143.54"}, {"price": "0.5", "size": "5"}, {"price": "0.61", "size": "900"}, {"price": "0.62", "size": "10.94"}, {"price": "0.697", "size": "300"}, {"price": "0.698", "size": "67.05"}, {"price": "0.699", "size": "400"}, {"price": "0.786", "size": "107.66"}, {"price": "0.861", "size": "58.53"}, {"price": "0.87", "size": "72.47"}, {"price": "0.886", "size": "215.33"}, {"price": "0.887", "size": "25"}, {"price": "0.888", "size": "30"}, {"price": "0.912", "size": "908"}, {"price": "0.92", "size": "637.13"}, {"price": "0.932", "size": "348.57"}, {"price": "0.933", "size": "348.58"}, {"price": "0.934", "size": "1540.04"}, {"price": "0.935", "size": "60"}, {"price": "0.936", "size": "17.08"}], "asks": [{"price": "0.999", "size": "14571.68"}, {"price": "0.998", "size": "11638.12"}, {"price": "0.997", "size": "1030.11"}, {"price": "0.996", "size": "1224.47"}, {"price": "0.995", "size": "1531.11"}, {"price": "0.99", "size": "20362.82"}, {"price": "0.989", "size": "1649.9"}, {"price": "0.988", "size": "311.88"}], "event_type": "book", "last_trade_price": "0.988"}, {"market": "0xc55db914f0fd1fee18997706712c0dfd8d0369cdbef93a9fef12bd001914ca77", "asset_id": "72354723612769247426741660426331235762851940382312402276325808095604519806766", "timestamp": "1769384268370", "hash": "32770c6021205d0f87f4cdc1a4096f605a3e8e58", "bids": [{"price": "0.001", "size": "13733.28"}], "asks": [{"price": "0.999", "size": "8674.77"}, {"price": "0.998", "size": "5.25"}, {"price": "0.997", "size": "1400"}, {"price": "0.996", "size": "9.09"}, {"price": "0.994", "size": "200"}, {"price": "0.99", "size": "23"}, {"price": "0.989", "size": "17.97"}, {"price": "0.97", "size": "2500"}, {"price": "0.965", "size": "2999.96"}, {"price": "0.95", "size": "540"}, {"price": "0.949", "size": "11.87"}, {"price": "0.9", "size": "360"}, {"price": "0.85", "size": "226.66"}, {"price": "0.8", "size": "160"}, {"price": "0.799", "size": "5.69"}, {"price": "0.777", "size": "165"}, {"price": "0.75", "size": "112"}, {"price": "0.7", "size": "86.66"}, {"price": "0.65", "size": "68.57"}, {"price": "0.6", "size": "50"}, {"price": "0.565", "size": "586.12"}, {"price": "0.52", "size": "5"}, {"price": "0.477", "size": "350"}, {"price": "0.476", "size": "3639"}, {"price": "0.475", "size": "5"}, {"price": "0.277", "size": "179"}, {"price": "0.177", "size": "189"}, {"price": "0.164", "size": "231.9"}, {"price": "0.163", "size": "298"}, {"price": "0.162", "size": "238"}, {"price": "0.12", "size": "10"}, {"price": "0.119", "size": "20"}, {"price": "0.115", "size": "25"}, {"price": "0.077", "size": "762"}, {"price": "0.041", "size": "486"}, {"price": "0.025", "size": "1202.94"}, {"price": "0.023", "size": "100"}, {"price": "0.02", "size": "1699.98"}, {"price": "0.018", "size": "300"}, {"price": "0.016", "size": "160"}, {"price": "0.015", "size": "148.52"}, {"price": "0.014", "size": "1396"}, {"price": "0.012", "size": "526.11"}, {"price": "0.011", "size": "256.36"}, {"price": "0.01", "size": "99.99"}, {"price": "0.009", "size": "531.88"}, {"price": "0.007", "size": "28.91"}], "event_type": "book", "last_trade_price": "0.001"}]}
{"_local_timestamp": "2026-01-25T23:40:30.218161+00:00", "data": {"market": "0x2393ed0b0fdc450054c7b9071907eca75cf4fc36e385adf4a0a5f99ee62243e8", "price_changes": [{"asset_id": "32769749367306925959219403371425714180265458150646381231272229429098460625924", "price": "0.906", "size": "85", "side": "BUY", "hash": "b4b7227645d9fbbc35d27fd9edd3e79e4677595f", "best_bid": "0.907", "best_ask": "0.96"}, {"asset_id": "100074770378634056601572485653252702850363676459996771990439989989293515601975", "price": "0.094", "size": "85", "side": "SELL", "hash": "8d8665f3f8b33eb526887c10ba6cd01c2b1f7566", "best_bid": "0.04", "best_ask": "0.093"}], "timestamp": "1769384430151", "event_type": "price_change"}}
{"_local_timestamp": "2026-01-25T23:40:31.528224+00:00", "data": {"market": "0x9472be65457510b7fc3477b20ba90910e99d92eac8421a14bf4b7b7a08ef31dc", "price_changes": [{"asset_id": "43311793366960417907757893276427136943959788721376762326430771171648759300146", "price": "0.67", "size": "0", "side": "BUY", "hash": "498f14c301e868822c64aba99cb96c525ae333c5", "best_bid": "0.995", "best_ask": "0.998"}, {"asset_id": "73414222381656326204771753454630063673548497164758947581648273905027617570612", "price": "0.33", "size": "0", "side": "SELL", "hash": "b234083ac6499656661138d69330c34809a821b2", "best_bid": "0.002", "best_ask": "0.005"}], "timestamp": "1769384431459", "event_type": "price_change"}}
{"_local_timestamp": "2026-01-25T23:40:31.825966+00:00", "data": {"market": "0x9472be65457510b7fc3477b20ba90910e99d92eac8421a14bf4b7b7a08ef31dc", "price_changes": [{"asset_id": "43311793366960417907757893276427136943959788721376762326430771171648759300146", "price": "0.67", "size": "5", "side": "BUY", "hash": "83973e9fbc97969e050c59a82722e1f677144dde", "best_bid": "0.995", "best_ask": "0.998"}, {"asset_id": "73414222381656326204771753454630063673548497164758947581648273905027617570612", "price": "0.33", "size": "5", "side": "SELL", "hash": "02c1f4664dee1c155ce2a86d2e77b9146e58d9d3", "best_bid": "0.002", "best_ask": "0.005"}], "timestamp": "1769384431740", "event_type": "price_change"}}
{"_local_timestamp": "2026-01-25T23:40:33.837760+00:00", "data": {"market": "0x9472be65457510b7fc3477b20ba90910e99d92eac8421a14bf4b7b7a08ef31dc", "price_changes": [{"asset_id": "43311793366960417907757893276427136943959788721376762326430771171648759300146", "price": "0.67", "size": "0", "side": "BUY", "hash": "78337f73a6a7a48aef419306d660b61301713506", "best_bid": "0.995", "best_ask": "0.998"}, {"asset_id": "73414222381656326204771753454630063673548497164758947581648273905027617570612", "price": "0.33", "size": "0", "side": "SELL", "hash": "ebf9e09e52001199971273f899845ceafd28796e", "best_bid": "0.002", "best_ask": "0.005"}], "timestamp": "1769384433771", "event_type": "price_change"}}
{"_local_timestamp": "2026-01-25T23:40:34.174003+00:00", "data": {"market": "0x9472be65457510b7fc3477b20ba90910e99d92eac8421a14bf4b7b7a08ef31dc", "price_changes": [{"asset_id": "43311793366960417907757893276427136943959788721376762326430771171648759300146", "price": "0.67", "size": "5", "side": "BUY", "hash": "44a4958a01a3f5b0636eb1895013bbf99d354ba0", "best_bid": "0.995", "best_ask": "0.998"}, {"asset_id": "73414222381656326204771753454630063673548497164758947581648273905027617570612", "price": "0.33", "size": "5", "side": "SELL", "hash": "e48cea14707ec000f37e3f1edb9d5047bfda5a1f", "best_bid": "0.002", "best_ask": "0.005"}], "timestamp": "1769384434103", "event_type": "price_change"}}
{"_local_timestamp": "2026-01-25T23:40:34.834122+00:00", "data": {"market": "0x2393ed0b0fdc450054c7b9071907eca75cf4fc36e385adf4a0a5f99ee62243e8", "price_changes": [{"asset_id": "32769749367306925959219403371425714180265458150646381231272229429098460625924", "price": "0.908", "size": "50", "side": "BUY", "hash": "c5cb03f57d2b8736b883c51c4bf14b23bc05ce26", "best_bid": "0.908", "best_ask": "0.96"}, {"asset_id": "100074770378634056601572485653252702850363676459996771990439989989293515601975", "price": "0.092", "size": "50", "side": "SELL", "hash": "e5b46fb833821af402abf4d902722f8fe6bac3f7", "best_bid": "0.04", "best_ask": "0.092"}], "timestamp": "1769384434760", "event_type": "price_change"}}
{"_local_timestamp": "2026-01-25T23:40:35.129643+00:00", "data": {"market": "0x2393ed0b0fdc450054c7b9071907eca75cf4fc36e385adf4a0a5f99ee62243e8", "price_changes": [{"asset_id": "32769749367306925959219403371425714180265458150646381231272229429098460625924", "price": "0.907", "size": "0", "side": "BUY", "hash": "397d1cf185e4e3be153bbc379e5e62c5d41eb1a3", "best_bid": "0.908", "best_ask": "0.96"}, {"asset_id": "100074770378634056601572485653252702850363676459996771990439989989293515601975", "price": "0.093", "size": "0", "side": "SELL", "hash": "cfc43f9b7dafa7a53032cd5b4dedc41b86089a97", "best_bid": "0.04", "best_ask": "0.092"}], "timestamp": "1769384435066", "event_type": "price_change"}}
{"_local_timestamp": "2026-01-25T23:40:35.179528+00:00", "data": {"market": "0x2393ed0b0fdc450054c7b9071907eca75cf4fc36e385adf4a0a5f99ee62243e8", "price_changes": [{"asset_id": "32769749367306925959219403371425714180265458150646381231272229429098460625924", "price": "0.906", "size": "35", "side": "BUY", "hash": "b7835c853c27f6acebc2df6cbffca7b33c23cb06", "best_bid": "0.908", "best_ask": "0.96"}, {"asset_id": "100074770378634056601572485653252702850363676459996771990439989989293515601975", "price": "0.094", "size": "35", "side": "SELL", "hash": "119a80be74d11917fbad2f6703f1809e6c7443a6", "best_bid": "0.04", "best_ask": "0.092"}], "timestamp": "1769384435108", "event_type": "price_change"}}
{"_local_timestamp": "2026-01-25T23:40:35.386355+00:00", "data": {"market": "0x2393ed0b0fdc450054c7b9071907eca75cf4fc36e385adf4a0a5f99ee62243e8", "price_changes": [{"asset_id": "32769749367306925959219403371425714180265458150646381231272229429098460625924", "price": "0.909", "size": "37.81", "side": "BUY", "hash": "be5406afcc4707085fcb7d38c330f340bbc95865", "best_bid": "0.909", "best_ask": "0.96"}, {"asset_id": "100074770378634056601572485653252702850363676459996771990439989989293515601975", "price": "0.091", "size": "37.81", "side": "SELL", "hash": "cbe5175b0653b9b2dbf142c901b5cfa801087fcb", "best_bid": "0.04", "best_ask": "0.091"}], "timestamp": "1769384435321", "event_type": "price_change"}}
{"_local_timestamp": "2026-01-25T23:40:36.517201+00:00", "data": {"market": "0x9472be65457510b7fc3477b20ba90910e99d92eac8421a14bf4b7b7a08ef31dc", "price_changes": [{"asset_id": "43311793366960417907757893276427136943959788721376762326430771171648759300146", "price": "0.67", "size": "0", "side": "BUY", "hash": "f9a8811660a59d0ae4a717aacc5c3de44615b2be", "best_bid": "0.995", "best_ask": "0.998"}, {"asset_id": "73414222381656326204771753454630063673548497164758947581648273905027617570612", "price": "0.33", "size": "0", "side": "SELL", "hash": "f0e382a69a3d670e12cfe64c5105f2d492755687", "best_bid": "0.002", "best_ask": "0.005"}], "timestamp": "1769384436446", "event_type": "price_change"}}
{"_local_timestamp": "2026-01-25T23:40:36.930098+00:00", "data": {"market": "0x9472be65457510b7fc3477b20ba90910e99d92eac8421a14bf4b7b7a08ef31dc", "price_changes": [{"asset_id": "43311793366960417907757893276427136943959788721376762326430771171648759300146", "price": "0.67", "size": "5", "side": "BUY", "hash": "475b0d6c33149c58ed7cb0fa1b42758d3d1df6dd", "best_bid": "0.995", "best_ask": "0.998"}, {"asset_id": "73414222381656326204771753454630063673548497164758947581648273905027617570612", "price": "0.33", "size": "5", "side": "SELL", "hash": "210ee4bc12838ca49e36f42b17bc1c4e6f95be03", "best_bid": "0.002", "best_ask": "0.005"}], "timestamp": "1769384436844", "event_type": "price_change"}}
{"_local_timestamp": "2026-01-25T23:40:39.209992+00:00", "data": {"market": "0x2393ed0b0fdc450054c7b9071907eca75cf4fc36e385adf4a0a5f99ee62243e8", "price_changes": [{"asset_id": "32769749367306925959219403371425714180265458150646381231272229429098460625924", "price": "0.906", "size": "5", "side": "BUY", "hash": "2c65954ceb4114e9acb8f3163a6e655e32a3f140", "best_bid": "0.909", "best_ask": "0.96"}, {"asset_id": "100074770378634056601572485653252702850363676459996771990439989989293515601975", "price": "0.094", "size": "5", "side": "SELL", "hash": "091c470c223c148b69b7924fde21b72ea10b6af7", "best_bid": "0.04", "best_ask": "0.091"}], "timestamp": "1769384439145", "event_type": "price_change"}}
{"_local_timestamp": "2026-01-25T23:40:39.454772+00:00", "data": {"market": "0x9472be65457510b7fc3477b20ba90910e99d92eac8421a14bf4b7b7a08ef31dc", "price_changes": [{"asset_id": "43311793366960417907757893276427136943959788721376762326430771171648759300146", "price": "0.67", "size": "0", "side": "BUY", "hash": "cb63a728fb6d1b2530cbf428b0c89c5bb130adb8", "best_bid": "0.995", "best_ask": "0.998"}, {"asset_id": "73414222381656326204771753454630063673548497164758947581648273905027617570612", "price": "0.33", "size": "0", "side": "SELL", "hash": "496bc66769cf2c0df62f9bcea80e55468b793e4b", "best_bid": "0.002", "best_ask": "0.005"}], "timestamp": "1769384439382", "event_type": "price_change"}}
{"_local_timestamp": "2026-01-25T23:40:39.737945+00:00", "data": {"market": "0x9472be65457510b7fc3477b20ba90910e99d92eac8421a14bf4b7b7a08ef31dc", "price_changes": [{"asset_id": "43311793366960417907757893276427136943959788721376762326430771171648759300146", "price": "0.67", "size": "5", "side": "BUY", "hash": "2b558f61f21b949ab6c981c377aea1f749903bec", "best_bid": "0.995", "best_ask": "0.998"}, {"asset_id": "73414222381656326204771753454630063673548497164758947581648273905027617570612", "price": "0.33", "size": "5", "side": "SELL", "hash": "6f26d7ec7486069ecf493e1681793614f3ddeb92", "best_bid": "0.002", "best_ask": "0.005"}], "timestamp": "1769384439663", "event_type": "price_change"}}
{"_local_timestamp": "2026-01-25T23:40:40.941740+00:00", "data": {"market": "0x2393ed0b0fdc450054c7b9071907eca75cf4fc36e385adf4a0a5f99ee62243e8", "price_changes": [{"asset_id": "32769749367306925959219403371425714180265458150646381231272229429098460625924", "price": "0.91", "size": "50", "side": "BUY", "hash": "2a1cb3fd1c68e71b9022aa38f717aca77921b837", "best_bid": "0.91", "best_ask": "0.96"}, {"asset_id": "100074770378634056601572485653252702850363676459996771990439989989293515601975", "price": "0.09", "size": "50", "side": "SELL", "hash": "39ca2e1ba563f1ec73392c573323a5110046b045", "best_bid": "0.04", "best_ask": "0.09"}], "timestamp": "1769384440871", "event_type": "price_change"}}
{"_local_timestamp": "2026-01-25T23:40:41.295702+00:00", "data": {"market": "0x2393ed0b0fdc450054c7b9071907eca75cf4fc36e385adf4a0a5f99ee62243e8", "price_changes": [{"asset_id": "32769749367306925959219403371425714180265458150646381231272229429098460625924", "price": "0.908", "size": "0", "side": "BUY", "hash": "271402c8aa6784f2bcbcf21891f399dcc46ab67b", "best_bid": "0.91", "best_ask": "0.96"}, {"asset_id": "100074770378634056601572485653252702850363676459996771990439989989293515601975", "price": "0.092", "size": "0", "side": "SELL", "hash": "24bef92d42e2ef3cd821464b7250ca2302429eb0", "best_bid": "0.04", "best_ask": "0.09"}], "timestamp": "1769384441224", "event_type": "price_change"}}
{"_local_timestamp": "2026-01-25T23:40:41.338318+00:00", "data": {"market": "0x2393ed0b0fdc450054c7b9071907eca75cf4fc36e385adf4a0a5f99ee62243e8", "price_changes": [{"asset_id": "32769749367306925959219403371425714180265458150646381231272229429098460625924", "price": "0.909", "size": "0", "side": "BUY", "hash": "3fcfa68fb60780937ddf79de4db9508c1aecf9a5", "best_bid": "0.91", "best_ask": "0.96"}, {"asset_id": "100074770378634056601572485653252702850363676459996771990439989989293515601975", "price": "0.091", "size": "0", "side": "SELL", "hash": "44b8cdcb9c3f18490f875abf6a462eaf5e40a1a2", "best_bid": "0.04", "best_ask": "0.09"}], "timestamp": "1769384441265", "event_type": "price_change"}}
{"_local_timestamp": "2026-01-25T23:40:41.597882+00:00", "data": {"market": "0x9472be65457510b7fc3477b20ba90910e99d92eac8421a14bf4b7b7a08ef31dc", "price_changes": [{"asset_id": "43311793366960417907757893276427136943959788721376762326430771171648759300146", "price": "0.67", "size": "0", "side": "BUY", "hash": "0abf7bb6852a851037127a49985c43214819d634", "best_bid": "0.995", "best_ask": "0.998"}, {"asset_id": "73414222381656326204771753454630063673548497164758947581648273905027617570612", "price": "0.33", "size": "0", "side": "SELL", "hash": "7c90d256196e067ff311287077d792cb4c47a06f", "best_bid": "0.002", "best_ask": "0.005"}], "timestamp": "1769384441523", "event_type": "price_change"}}
{"_local_timestamp": "2026-01-25T23:40:41.959749+00:00", "data": {"market": "0x9472be65457510b7fc3477b20ba90910e99d92eac8421a14bf4b7b7a08ef31dc", "price_changes": [{"asset_id": "43311793366960417907757893276427136943959788721376762326430771171648759300146", "price": "0.67", "size": "5", "side": "BUY", "hash": "cd05d40252d9b3d7a0bbfb501fe29b18caf5b47f", "best_bid": "0.995", "best_ask": "0.998"}, {"asset_id": "73414222381656326204771753454630063673548497164758947581648273905027617570612", "price": "0.33", "size": "5", "side": "SELL", "hash": "903299c1d8b0dab25be9af7444280ce600c11949", "best_bid": "0.002", "best_ask": "0.005"}], "timestamp": "1769384441892", "event_type": "price_change"}}
{"_local_timestamp": "2026-01-25T23:40:42.104411+00:00", "data": {"market": "0x2393ed0b0fdc450054c7b9071907eca75cf4fc36e385adf4a0a5f99ee62243e8", "price_changes": [{"asset_id": "32769749367306925959219403371425714180265458150646381231272229429098460625924", "price": "0.911", "size": "37.81", "side": "BUY", "hash": "adbec260ddc3acb03aaf63331e3f7fd69c05dc95", "best_bid": "0.911", "best_ask": "0.96"}, {"asset_id": "100074770378634056601572485653252702850363676459996771990439989989293515601975", "price": "0.089", "size": "37.81", "side": "SELL", "hash": "3dc8e9fddd8aef4757aa6fe6cda3108f3f0505c2", "best_bid": "0.04", "best_ask": "0.089"}], "timestamp": "1769384442023", "event_type": "price_change"}}
{"_local_timestamp": "2026-01-25T23:40:44.392696+00:00", "data": {"market": "0x9472be65457510b7fc3477b20ba90910e99d92eac8421a14bf4b7b7a08ef31dc", "price_changes": [{"asset_id": "43311793366960417907757893276427136943959788721376762326430771171648759300146", "price": "0.67", "size": "0", "side": "BUY", "hash": "f70d33c26fae35349a55809e200069c619d4bfff", "best_bid": "0.995", "best_ask": "0.998"}, {"asset_id": "73414222381656326204771753454630063673548497164758947581648273905027617570612", "price": "0.33", "size": "0", "side": "SELL", "hash": "223bc37cb300addade7525fc13c9eda472c95c4b", "best_bid": "0.002", "best_ask": "0.005"}], "timestamp": "1769384444260", "event_type": "price_change"}}
{"_local_timestamp": "2026-01-25T23:40:44.769133+00:00", "data": {"market": "0x9472be65457510b7fc3477b20ba90910e99d92eac8421a14bf4b7b7a08ef31dc", "price_changes": [{"asset_id": "43311793366960417907757893276427136943959788721376762326430771171648759300146", "price": "0.67", "size": "5", "side": "BUY", "hash": "648462c4c809b29c209a29d156c809e28ff16864", "best_bid": "0.995", "best_ask": "0.998"}, {"asset_id": "73414222381656326204771753454630063673548497164758947581648273905027617570612", "price": "0.33", "size": "5", "side": "SELL", "hash": "831d9acf4da20e7c19aa1faf28158ecb6dbc7b1a", "best_bid": "0.002", "best_ask": "0.005"}], "timestamp": "1769384444695", "event_type": "price_change"}}
{"_local_timestamp": "2026-01-25T23:40:46.962931+00:00", "data": {"market": "0x2393ed0b0fdc450054c7b9071907eca75cf4fc36e385adf4a0a5f99ee62243e8", "price_changes": [{"asset_id": "32769749367306925959219403371425714180265458150646381231272229429098460625924", "price": "0.912", "size": "50", "side": "BUY", "hash": "edce0280b9b18779fc109a3a35c4c1516c9a047b", "best_bid": "0.912", "best_ask": "0.96"}, {"asset_id": "100074770378634056601572485653252702850363676459996771990439989989293515601975", "price": "0.088", "size": "50", "side": "SELL", "hash": "cd11c357b32ec4ae33bc60faeba86fda3decfe70", "best_bid": "0.04", "best_ask": "0.088"}], "timestamp": "1769384446890", "event_type": "price_change"}}
{"_local_timestamp": "2026-01-25T23:40:47.054499+00:00", "data": {"market": "0x9472be65457510b7fc3477b20ba90910e99d92eac8421a14bf4b7b7a08ef31dc", "price_changes": [{"asset_id": "43311793366960417907757893276427136943959788721376762326430771171648759300146", "price": "0.67", "size": "0", "side": "BUY", "hash": "399f8af17b6bcb251cdce673bd762f02691ab342", "best_bid": "0.995", "best_ask": "0.998"}, {"asset_id": "73414222381656326204771753454630063673548497164758947581648273905027617570612", "price": "0.33", "size": "0", "side": "SELL", "hash": "f50b405198162984b61d43822ca0d21d54210650", "best_bid": "0.002", "best_ask": "0.005"}], "timestamp": "1769384446972", "event_type": "price_change"}}
{"_local_timestamp": "2026-01-25T23:40:47.312120+00:00", "data": {"market": "0x2393ed0b0fdc450054c7b9071907eca75cf4fc36e385adf4a0a5f99ee62243e8", "price_changes": [{"asset_id": "32769749367306925959219403371425714180265458150646381231272229429098460625924", "price": "0.91", "size": "0", "side": "BUY", "hash": "8010408af5c4af35e756e9d14dbf5a8cfce7d8d7", "best_bid": "0.912", "best_ask": "0.96"}, {"asset_id": "100074770378634056601572485653252702850363676459996771990439989989293515601975", "price": "0.09", "size": "0", "side": "SELL", "hash": "21a82c21fa55c8d134b5d6c21285ddbdae3e25cc", "best_bid": "0.04", "best_ask": "0.088"}], "timestamp": "1769384447241", "event_type": "price_change"}}
{"_local_timestamp": "2026-01-25T23:40:47.370514+00:00", "data": {"market": "0x9472be65457510b7fc3477b20ba90910e99d92eac8421a14bf4b7b7a08ef31dc", "price_changes": [{"asset_id": "43311793366960417907757893276427136943959788721376762326430771171648759300146", "price": "0.67", "size": "5", "side": "BUY", "hash": "909e7afc885a582105f1e8b03bd3d03c2b84242a", "best_bid": "0.995", "best_ask": "0.998"}, {"asset_id": "73414222381656326204771753454630063673548497164758947581648273905027617570612", "price": "0.33", "size": "5", "side": "SELL", "hash": "0ddbee4198f9b12fd6a37f60d7a354f32615d043", "best_bid": "0.002", "best_ask": "0.005"}], "timestamp": "1769384447298", "event_type": "price_change"}}
{"_local_timestamp": "2026-01-25T23:40:47.537967+00:00", "data": {"market": "0x2393ed0b0fdc450054c7b9071907eca75cf4fc36e385adf4a0a5f99ee62243e8", "price_changes": [{"asset_id": "32769749367306925959219403371425714180265458150646381231272229429098460625924", "price": "0.911", "size": "0", "side": "BUY", "hash": "24ea5c5fdc4ecabb8c12fa8702fe3827f3cf3de9", "best_bid": "0.912", "best_ask": "0.96"}, {"asset_id": "100074770378634056601572485653252702850363676459996771990439989989293515601975", "price": "0.089", "size": "0", "side": "SELL", "hash": "1100146d1bb56d8bb2ad104370da424e0669ac4b", "best_bid": "0.04", "best_ask": "0.088"}], "timestamp": "1769384447469", "event_type": "price_change"}}
{"_local_timestamp": "2026-01-25T23:40:48.227327+00:00", "data": {"market": "0x2393ed0b0fdc450054c7b9071907eca75cf4fc36e385adf4a0a5f99ee62243e8", "price_changes": [{"asset_id": "32769749367306925959219403371425714180265458150646381231272229429098460625924", "price": "0.913", "size": "37.81", "side": "BUY", "hash": "b37246d57aaf2420ce5ab16a9cf3e110312d2620", "best_bid": "0.913", "best_ask": "0.96"}, {"asset_id": "100074770378634056601572485653252702850363676459996771990439989989293515601975", "price": "0.087", "size": "37.81", "side": "SELL", "hash": "34e369037c02a94464ee202e0c7d055e21ecf65c", "best_bid": "0.04", "best_ask": "0.087"}], "timestamp": "1769384448158", "event_type": "price_change"}}
{"_local_timestamp": "2026-01-25T23:40:49.638363+00:00", "data": {"market": "0x9472be65457510b7fc3477b20ba90910e99d92eac8421a14bf4b7b7a08ef31dc", "price_changes": [{"asset_id": "43311793366960417907757893276427136943959788721376762326430771171648759300146", "price": "0.67", "size": "0", "side": "BUY", "hash": "18b33aa88c2e666832f959c23071565344efcc73", "best_bid": "0.995", "best_ask": "0.998"}, {"asset_id": "73414222381656326204771753454630063673548497164758947581648273905027617570612", "price": "0.33", "size": "0", "side": "SELL", "hash": "8fb3327592d996841b8cf80f9b0a4b041198e4f4", "best_bid": "0.002", "best_ask": "0.005"}], "timestamp": "1769384449568", "event_type": "price_change"}}
{"_local_timestamp": "2026-01-25T23:40:49.985622+00:00", "data": {"market": "0x9472be65457510b7fc3477b20ba90910e99d92eac8421a14bf4b7b7a08ef31dc", "price_changes": [{"asset_id": "43311793366960417907757893276427136943959788721376762326430771171648759300146", "price": "0.67", "size": "5", "side": "BUY", "hash": "5a4a09001142139e32a356c545397b323e7379e2", "best_bid": "0.995", "best_ask": "0.998"}, {"asset_id": "73414222381656326204771753454630063673548497164758947581648273905027617570612", "price": "0.33", "size": "5", "side": "SELL", "hash": "b94007e05bac5d6847fea0e0246c4e64388ecde2", "best_bid": "0.002", "best_ask": "0.005"}], "timestamp": "1769384449898", "event_type": "price_change"}}
{"_local_timestamp": "2026-01-25T23:40:51.613650+00:00", "data": {"market": "0x9472be65457510b7fc3477b20ba90910e99d92eac8421a14bf4b7b7a08ef31dc", "price_changes": [{"asset_id": "43311793366960417907757893276427136943959788721376762326430771171648759300146", "price": "0.67", "size": "0", "side": "BUY", "hash": "7c54cb186411a6f00af30abda0de488237b8b399", "best_bid": "0.995", "best_ask": "0.998"}, {"asset_id": "73414222381656326204771753454630063673548497164758947581648273905027617570612", "price": "0.33", "size": "0", "side": "SELL", "hash": "55b803af10a140a7e42ce8fe8c7259e6338a2390", "best_bid": "0.002", "best_ask": "0.005"}], "timestamp": "1769384451537", "event_type": "price_change"}}
{"_local_timestamp": "2026-01-25T23:40:52.054511+00:00", "data": {"market": "0x9472be65457510b7fc3477b20ba90910e99d92eac8421a14bf4b7b7a08ef31dc", "price_changes": [{"asset_id": "43311793366960417907757893276427136943959788721376762326430771171648759300146", "price": "0.67", "size": "5", "side": "BUY", "hash": "d6dc76f47df1250b6d11c6b30d9b59e47b19dfab", "best_bid": "0.995", "best_ask": "0.998"}, {"asset_id": "73414222381656326204771753454630063673548497164758947581648273905027617570612", "price": "0.33", "size": "5", "side": "SELL", "hash": "7fd7d0f930d329d318a34a0381f78336b97e3212", "best_bid": "0.002", "best_ask": "0.005"}], "timestamp": "1769384451980", "event_type": "price_change"}}
{"_local_timestamp": "2026-01-25T23:40:53.003386+00:00", "data": {"market": "0x2393ed0b0fdc450054c7b9071907eca75cf4fc36e385adf4a0a5f99ee62243e8", "price_changes": [{"asset_id": "32769749367306925959219403371425714180265458150646381231272229429098460625924", "price": "0.914", "size": "50", "side": "BUY", "hash": "9d7659e34e075d6c1520442e9ba15665cd13ccee", "best_bid": "0.914", "best_ask": "0.96"}, {"asset_id": "100074770378634056601572485653252702850363676459996771990439989989293515601975", "price": "0.086", "size": "50", "side": "SELL", "hash": "69dde6d1e7ccc3138793d8c741e753c350beb9f4", "best_bid": "0.04", "best_ask": "0.086"}], "timestamp": "1769384452928", "event_type": "price_change"}}
{"_local_timestamp": "2026-01-25T23:40:53.332048+00:00", "data": {"market": "0x2393ed0b0fdc450054c7b9071907eca75cf4fc36e385adf4a0a5f99ee62243e8", "price_changes": [{"asset_id": "32769749367306925959219403371425714180265458150646381231272229429098460625924", "price": "0.912", "size": "0", "side": "BUY", "hash": "d6e9d52d2643bfa78bf85955c4448ea459a8db66", "best_bid": "0.914", "best_ask": "0.96"}, {"asset_id": "100074770378634056601572485653252702850363676459996771990439989989293515601975", "price": "0.088", "size": "0", "side": "SELL", "hash": "f7268de65b675ff874d11df76ea3b0689a479bb0", "best_bid": "0.04", "best_ask": "0.086"}], "timestamp": "1769384453262", "event_type": "price_change"}}
{"_local_timestamp": "2026-01-25T23:40:53.808549+00:00", "data": {"market": "0x9472be65457510b7fc3477b20ba90910e99d92eac8421a14bf4b7b7a08ef31dc", "price_changes": [{"asset_id": "43311793366960417907757893276427136943959788721376762326430771171648759300146", "price": "0.67", "size": "0", "side": "BUY", "hash": "f08deb22580432289858fa4ac07b3eef48e31c47", "best_bid": "0.995", "best_ask": "0.998"}, {"asset_id": "73414222381656326204771753454630063673548497164758947581648273905027617570612", "price": "0.33", "size": "0", "side": "SELL", "hash": "4da17b2b30b0a4b1c6034576f44d899b7ce19899", "best_bid": "0.002", "best_ask": "0.005"}], "timestamp": "1769384453735", "event_type": "price_change"}}
{"_local_timestamp": "2026-01-25T23:40:53.988311+00:00", "data": {"market": "0x2393ed0b0fdc450054c7b9071907eca75cf4fc36e385adf4a0a5f99ee62243e8", "price_changes": [{"asset_id": "32769749367306925959219403371425714180265458150646381231272229429098460625924", "price": "0.913", "size": "0", "side": "BUY", "hash": "5145b1337b0720e2b07757c72946fab9bc02998e", "best_bid": "0.914", "best_ask": "0.96"}, {"asset_id": "100074770378634056601572485653252702850363676459996771990439989989293515601975", "price": "0.087", "size": "0", "side": "SELL", "hash": "81baac585923e2443654104d7d33a97eaca4d7c9", "best_bid": "0.04", "best_ask": "0.086"}], "timestamp": "1769384453914", "event_type": "price_change"}}
{"_local_timestamp": "2026-01-25T23:40:54.240054+00:00", "data": {"market": "0x9472be65457510b7fc3477b20ba90910e99d92eac8421a14bf4b7b7a08ef31dc", "price_changes": [{"asset_id": "43311793366960417907757893276427136943959788721376762326430771171648759300146", "price": "0.67", "size": "5", "side": "BUY", "hash": "53ae22acb4b1c58d354fe4a910527ca8bef5f7e2", "best_bid": "0.995", "best_ask": "0.998"}, {"asset_id": "73414222381656326204771753454630063673548497164758947581648273905027617570612", "price": "0.33", "size": "5", "side": "SELL", "hash": "87685908c2113add8c94b819d765f7590a8a3613", "best_bid": "0.002", "best_ask": "0.005"}], "timestamp": "1769384454173", "event_type": "price_change"}}
{"_local_timestamp": "2026-01-25T23:40:55.327319+00:00", "data": {"market": "0x2393ed0b0fdc450054c7b9071907eca75cf4fc36e385adf4a0a5f99ee62243e8", "price_changes": [{"asset_id": "32769749367306925959219403371425714180265458150646381231272229429098460625924", "price": "0.915", "size": "37.81", "side": "BUY", "hash": "932e00dc56edef2da7f19c48d86b0e0bf66d2839", "best_bid": "0.915", "best_ask": "0.96"}, {"asset_id": "100074770378634056601572485653252702850363676459996771990439989989293515601975", "price": "0.085", "size": "37.81", "side": "SELL", "hash": "86cd2f02b448fdfc555b5dc75b5449d55fe8456a", "best_bid": "0.04", "best_ask": "0.085"}], "timestamp": "1769384455250", "event_type": "price_change"}}
{"_local_timestamp": "2026-01-25T23:40:56.222506+00:00", "data": {"market": "0x9472be65457510b7fc3477b20ba90910e99d92eac8421a14bf4b7b7a08ef31dc", "price_changes": [{"asset_id": "43311793366960417907757893276427136943959788721376762326430771171648759300146", "price": "0.67", "size": "0", "side": "BUY", "hash": "ea44bb0eaf1668fc018f4ed453fde167ae78c8ee", "best_bid": "0.995", "best_ask": "0.998"}, {"asset_id": "73414222381656326204771753454630063673548497164758947581648273905027617570612", "price": "0.33", "size": "0", "side": "SELL", "hash": "229153db332a767d46f024da1f7b6511dc9f1195", "best_bid": "0.002", "best_ask": "0.005"}], "timestamp": "1769384456150", "event_type": "price_change"}}
{"_local_timestamp": "2026-01-25T23:40:56.600317+00:00", "data": {"market": "0x9472be65457510b7fc3477b20ba90910e99d92eac8421a14bf4b7b7a08ef31dc", "price_changes": [{"asset_id": "43311793366960417907757893276427136943959788721376762326430771171648759300146", "price": "0.67", "size": "5", "side": "BUY", "hash": "9b86f914398be3b6d4708e7641464ecd834ceb41", "best_bid": "0.995", "best_ask": "0.998"}, {"asset_id": "73414222381656326204771753454630063673548497164758947581648273905027617570612", "price": "0.33", "size": "5", "side": "SELL", "hash": "528f9414c8611f61724dcdf5bfd713e58578179f", "best_bid": "0.002", "best_ask": "0.005"}], "timestamp": "1769384456533", "event_type": "price_change"}}
{"_local_timestamp": "2026-01-25T23:40:58.994336+00:00", "data": {"market": "0x2393ed0b0fdc450054c7b9071907eca75cf4fc36e385adf4a0a5f99ee62243e8", "price_changes": [{"asset_id": "32769749367306925959219403371425714180265458150646381231272229429098460625924", "price": "0.916", "size": "50", "side": "BUY", "hash": "42cdac041a4cd4df86e227f93ddf7c61314a44ea", "best_bid": "0.916", "best_ask": "0.96"}, {"asset_id": "100074770378634056601572485653252702850363676459996771990439989989293515601975", "price": "0.084", "size": "50", "side": "SELL", "hash": "40ab94c378d8a66054d222f9948000263b3d2324", "best_bid": "0.04", "best_ask": "0.084"}], "timestamp": "1769384458927", "event_type": "price_change"}}
{"_local_timestamp": "2026-01-25T23:40:59.230869+00:00", "data": {"market": "0x9472be65457510b7fc3477b20ba90910e99d92eac8421a14bf4b7b7a08ef31dc", "price_changes": [{"asset_id": "43311793366960417907757893276427136943959788721376762326430771171648759300146", "price": "0.67", "size": "0", "side": "BUY", "hash": "ae9cefd7fe7a9eed80a83d06d7fccd0a5baffd26", "best_bid": "0.995", "best_ask": "0.998"}, {"asset_id": "73414222381656326204771753454630063673548497164758947581648273905027617570612", "price": "0.33", "size": "0", "side": "SELL", "hash": "8d1a867a43f70a63c6cd49d4f2de5204b8f982a7", "best_bid": "0.002", "best_ask": "0.005"}], "timestamp": "1769384459147", "event_type": "price_change"}}
{"_local_timestamp": "2026-01-25T23:40:59.338533+00:00", "data": {"market": "0x2393ed0b0fdc450054c7b9071907eca75cf4fc36e385adf4a0a5f99ee62243e8", "price_changes": [{"asset_id": "32769749367306925959219403371425714180265458150646381231272229429098460625924", "price": "0.914", "size": "0", "side": "BUY", "hash": "60120de4291813b0302bacabea5b6bb0e25cec8d", "best_bid": "0.916", "best_ask": "0.96"}, {"asset_id": "100074770378634056601572485653252702850363676459996771990439989989293515601975", "price": "0.086", "size": "0", "side": "SELL", "hash": "0735ba4124ff92e23c5f2dea61019b0fb869f04b", "best_bid": "0.04", "best_ask": "0.084"}], "timestamp": "1769384459268", "event_type": "price_change"}}
{"_local_timestamp": "2026-01-25T23:40:59.623812+00:00", "data": {"market": "0x9472be65457510b7fc3477b20ba90910e99d92eac8421a14bf4b7b7a08ef31dc", "price_changes": [{"asset_id": "43311793366960417907757893276427136943959788721376762326430771171648759300146", "price": "0.67", "size": "5", "side": "BUY", "hash": "d8315e45a54da0f0536fc3b2acc5f9e2fca4fc6f", "best_bid": "0.995", "best_ask": "0.998"}, {"asset_id": "73414222381656326204771753454630063673548497164758947581648273905027617570612", "price": "0.33", "size": "5", "side": "SELL", "hash": "2b094eaf1d8284531efeb86308fb3f8858aa0ede", "best_bid": "0.002", "best_ask": "0.005"}], "timestamp": "1769384459548", "event_type": "price_change"}}
{"_local_timestamp": "2026-01-25T23:40:59.898606+00:00", "data": {"market": "0x2393ed0b0fdc450054c7b9071907eca75cf4fc36e385adf4a0a5f99ee62243e8", "price_changes": [{"asset_id": "32769749367306925959219403371425714180265458150646381231272229429098460625924", "price": "0.915", "size": "0", "side": "BUY", "hash": "047e36c471f460f99a960cc98de19246dd3e15e0", "best_bid": "0.916", "best_ask": "0.96"}, {"asset_id": "100074770378634056601572485653252702850363676459996771990439989989293515601975", "price": "0.085", "size": "0", "side": "SELL", "hash": "8b5e17a386875e7019f4f2fa83d38491ba46a256", "best_bid": "0.04", "best_ask": "0.084"}], "timestamp": "1769384459830", "event_type": "price_change"}}
{"_local_timestamp": "2026-01-25T23:41:00.843456+00:00", "data": {"market": "0x2393ed0b0fdc450054c7b9071907eca75cf4fc36e385adf4a0a5f99ee62243e8", "price_changes": [{"asset_id": "32769749367306925959219403371425714180265458150646381231272229429098460625924", "price": "0.917", "size": "37.81", "side": "BUY", "hash": "883b810e92676d6c264995c8735ec1e298a5befb", "best_bid": "0.917", "best_ask": "0.96"}, {"asset_id": "100074770378634056601572485653252702850363676459996771990439989989293515601975", "price": "0.083", "size": "37.81", "side": "SELL", "hash": "175dc5e9ca658edbb3d2e4ad1371427e624fb7ec", "best_bid": "0.04", "best_ask": "0.083"}], "timestamp": "1769384460775", "event_type": "price_change"}}
{"_local_timestamp": "2026-01-25T23:41:02.483575+00:00", "data": {"market": "0x9472be65457510b7fc3477b20ba90910e99d92eac8421a14bf4b7b7a08ef31dc", "price_changes": [{"asset_id": "43311793366960417907757893276427136943959788721376762326430771171648759300146", "price": "0.67", "size": "0", "side": "BUY", "hash": "f92e3eb1df5a12e15114fc4b0a79af5846be4504", "best_bid": "0.995", "best_ask": "0.998"}, {"asset_id": "73414222381656326204771753454630063673548497164758947581648273905027617570612", "price": "0.33", "size": "0", "side": "SELL", "hash": "3b711695f227cafc27e3c5ec4b9787377a2713b3", "best_bid": "0.002", "best_ask": "0.005"}], "timestamp": "1769384462407", "event_type": "price_change"}}
{"_local_timestamp": "2026-01-25T23:41:02.865191+00:00", "data": {"market": "0x9472be65457510b7fc3477b20ba90910e99d92eac8421a14bf4b7b7a08ef31dc", "price_changes": [{"asset_id": "43311793366960417907757893276427136943959788721376762326430771171648759300146", "price": "0.67", "size": "5", "side": "BUY", "hash": "767ba0b15f5b81d3f58b56492871ae9ebc2ccf0a", "best_bid": "0.995", "best_ask": "0.998"}, {"asset_id": "73414222381656326204771753454630063673548497164758947581648273905027617570612", "price": "0.33", "size": "5", "side": "SELL", "hash": "c3131142fb960cb2c2c95ffbdc8cdb8280584875", "best_bid": "0.002", "best_ask": "0.005"}], "timestamp": "1769384462789", "event_type": "price_change"}}
{"_local_timestamp": "2026-01-25T23:41:04.944181+00:00", "data": {"market": "0x2393ed0b0fdc450054c7b9071907eca75cf4fc36e385adf4a0a5f99ee62243e8", "price_changes": [{"asset_id": "32769749367306925959219403371425714180265458150646381231272229429098460625924", "price": "0.896", "size": "50", "side": "BUY", "hash": "05bb95e5d83387510732e971fd569651444be335", "best_bid": "0.917", "best_ask": "0.96"}, {"asset_id": "100074770378634056601572485653252702850363676459996771990439989989293515601975", "price": "0.104", "size": "50", "side": "SELL", "hash": "349704e3ce22a9240d4530cf46b28397f50b6f98", "best_bid": "0.04", "best_ask": "0.083"}], "timestamp": "1769384464874", "event_type": "price_change"}}
{"_local_timestamp": "2026-01-25T23:41:05.101989+00:00", "data": {"market": "0x9472be65457510b7fc3477b20ba90910e99d92eac8421a14bf4b7b7a08ef31dc", "price_changes": [{"asset_id": "43311793366960417907757893276427136943959788721376762326430771171648759300146", "price": "0.67", "size": "0", "side": "BUY", "hash": "e418316a97a14c9477d52d60a3cb66808a09f731", "best_bid": "0.995", "best_ask": "0.998"}, {"asset_id": "73414222381656326204771753454630063673548497164758947581648273905027617570612", "price": "0.33", "size": "0", "side": "SELL", "hash": "5148b41fd8e4d569eae5bc902353a0a5a0a98163", "best_bid": "0.002", "best_ask": "0.005"}], "timestamp": "1769384465018", "event_type": "price_change"}}
{"_local_timestamp": "2026-01-25T23:41:05.240891+00:00", "data": {"market": "0x2393ed0b0fdc450054c7b9071907eca75cf4fc36e385adf4a0a5f99ee62243e8", "price_changes": [{"asset_id": "32769749367306925959219403371425714180265458150646381231272229429098460625924", "price": "0.916", "size": "0", "side": "BUY", "hash": "56a31096c9f9998d89d0f074f00ca8619c34ada3", "best_bid": "0.917", "best_ask": "0.96"}, {"asset_id": "100074770378634056601572485653252702850363676459996771990439989989293515601975", "price": "0.084", "size": "0", "side": "SELL", "hash": "4575ad3c75772ba27076bfc7527630894b077dd4", "best_bid": "0.04", "best_ask": "0.083"}], "timestamp": "1769384465162", "event_type": "price_change"}}
{"_local_timestamp": "2026-01-25T23:41:05.417403+00:00", "data": {"market": "0x9472be65457510b7fc3477b20ba90910e99d92eac8421a14bf4b7b7a08ef31dc", "price_changes": [{"asset_id": "43311793366960417907757893276427136943959788721376762326430771171648759300146", "price": "0.67", "size": "5", "side": "BUY", "hash": "c6b2ea897881c86cf5524b04ea2136f7debfd7a3", "best_bid": "0.995", "best_ask": "0.998"}, {"asset_id": "73414222381656326204771753454630063673548497164758947581648273905027617570612", "price": "0.33", "size": "5", "side": "SELL", "hash": "6f189c32fea5e09cd81c432b864a1009f4dfec2d", "best_bid": "0.002", "best_ask": "0.005"}], "timestamp": "1769384465347", "event_type": "price_change"}}
{"_local_timestamp": "2026-01-25T23:41:06.964993+00:00", "data": {"market": "0x9472be65457510b7fc3477b20ba90910e99d92eac8421a14bf4b7b7a08ef31dc", "price_changes": [{"asset_id": "43311793366960417907757893276427136943959788721376762326430771171648759300146", "price": "0.67", "size": "0", "side": "BUY", "hash": "a909c65c99de63c3604e570da453df939381b8f1", "best_bid": "0.995", "best_ask": "0.998"}, {"asset_id": "73414222381656326204771753454630063673548497164758947581648273905027617570612", "price": "0.33", "size": "0", "side": "SELL", "hash": "8e2d08c699a95e0a5eb08ac31b0904b52cacc691", "best_bid": "0.002", "best_ask": "0.005"}], "timestamp": "1769384466880", "event_type": "price_change"}}
{"_local_timestamp": "2026-01-25T23:41:07.223205+00:00", "data": {"market": "0x2393ed0b0fdc450054c7b9071907eca75cf4fc36e385adf4a0a5f99ee62243e8", "price_changes": [{"asset_id": "32769749367306925959219403371425714180265458150646381231272229429098460625924", "price": "0.917", "size": "0", "side": "BUY", "hash": "2db018d0c2f3f0cb21fbc55d0a8a9ac4e6a8cec2", "best_bid": "0.906", "best_ask": "0.96"}, {"asset_id": "100074770378634056601572485653252702850363676459996771990439989989293515601975", "price": "0.083", "size": "0", "side": "SELL", "hash": "bda3a429e927a575144e929eccc196bdd302afb7", "best_bid": "0.04", "best_ask": "0.094"}], "timestamp": "1769384467156", "event_type": "price_change"}}
{"_local_timestamp": "2026-01-25T23:41:07.341924+00:00", "data": {"market": "0x9472be65457510b7fc3477b20ba90910e99d92eac8421a14bf4b7b7a08ef31dc", "price_changes": [{"asset_id": "43311793366960417907757893276427136943959788721376762326430771171648759300146", "price": "0.67", "size": "5", "side": "BUY", "hash": "f0910f3026e232b16631ea88b261a0a60e79a789", "best_bid": "0.995", "best_ask": "0.998"}, {"asset_id": "73414222381656326204771753454630063673548497164758947581648273905027617570612", "price": "0.33", "size": "5", "side": "SELL", "hash": "0fac0b9bf59702d18b9039e111a27af971f24f75", "best_bid": "0.002", "best_ask": "0.005"}], "timestamp": "1769384467271", "event_type": "price_change"}}
{"_local_timestamp": "2026-01-25T23:41:09.554609+00:00", "data": {"market": "0x9472be65457510b7fc3477b20ba90910e99d92eac8421a14bf4b7b7a08ef31dc", "price_changes": [{"asset_id": "43311793366960417907757893276427136943959788721376762326430771171648759300146", "price": "0.67", "size": "0", "side": "BUY", "hash": "613fc6b49f79c6d57d826a3ff9cb829a66055f28", "best_bid": "0.995", "best_ask": "0.998"}, {"asset_id": "73414222381656326204771753454630063673548497164758947581648273905027617570612", "price": "0.33", "size": "0", "side": "SELL", "hash": "b248ebea819518bb896a37597610ba5e27072259", "best_bid": "0.002", "best_ask": "0.005"}], "timestamp": "1769384469486", "event_type": "price_change"}}
{"_local_timestamp": "2026-01-25T23:41:09.942187+00:00", "data": {"market": "0x9472be65457510b7fc3477b20ba90910e99d92eac8421a14bf4b7b7a08ef31dc", "price_changes": [{"asset_id": "43311793366960417907757893276427136943959788721376762326430771171648759300146", "price": "0.67", "size": "5", "side": "BUY", "hash": "a72a2f1a6c6321bc4132ef843b375b251b75f7f8", "best_bid": "0.995", "best_ask": "0.998"}, {"asset_id": "73414222381656326204771753454630063673548497164758947581648273905027617570612", "price": "0.33", "size": "5", "side": "SELL", "hash": "f665b63407173e8fa536fc5766dad887e8a126a4", "best_bid": "0.002", "best_ask": "0.005"}], "timestamp": "1769384469866", "event_type": "price_change"}}
{"_local_timestamp": "2026-01-25T23:41:10.039915+00:00", "data": {"market": "0x2393ed0b0fdc450054c7b9071907eca75cf4fc36e385adf4a0a5f99ee62243e8", "price_changes": [{"asset_id": "32769749367306925959219403371425714180265458150646381231272229429098460625924", "price": "0.897", "size": "37.81", "side": "BUY", "hash": "5c4f14e56e6fb19adf047363a32dbd06aee4a3ae", "best_bid": "0.906", "best_ask": "0.96"}, {"asset_id": "100074770378634056601572485653252702850363676459996771990439989989293515601975", "price": "0.103", "size": "37.81", "side": "SELL", "hash": "4a17db9c45fe112fac45524a9eb9b89e788c1681", "best_bid": "0.04", "best_ask": "0.094"}], "timestamp": "1769384469971", "event_type": "price_change"}}
{"_local_timestamp": "2026-01-25T23:41:11.050415+00:00", "data": {"market": "0x2393ed0b0fdc450054c7b9071907eca75cf4fc36e385adf4a0a5f99ee62243e8", "price_changes": [{"asset_id": "32769749367306925959219403371425714180265458150646381231272229429098460625924", "price": "0.898", "size": "50", "side": "BUY", "hash": "25f0f3c12bbc63019e1483fc15f928c3366d8a2e", "best_bid": "0.906", "best_ask": "0.96"}, {"asset_id": "100074770378634056601572485653252702850363676459996771990439989989293515601975", "price": "0.102", "size": "50", "side": "SELL", "hash": "86032bcb8ea59e22020ac326e694943519626104", "best_bid": "0.04", "best_ask": "0.094"}], "timestamp": "1769384470955", "event_type": "price_change"}}
{"_local_timestamp": "2026-01-25T23:41:11.378637+00:00", "data": {"market": "0x2393ed0b0fdc450054c7b9071907eca75cf4fc36e385adf4a0a5f99ee62243e8", "price_changes": [{"asset_id": "32769749367306925959219403371425714180265458150646381231272229429098460625924", "price": "0.896", "size": "0", "side": "BUY", "hash": "baa00b1fad8dc407852373aca798e4a979c5f4c6", "best_bid": "0.906", "best_ask": "0.96"}, {"asset_id": "100074770378634056601572485653252702850363676459996771990439989989293515601975", "price": "0.104", "size": "0", "side": "SELL", "hash": "95b604f8807893ea4f11e1c3853a22281e7fb175", "best_bid": "0.04", "best_ask": "0.094"}], "timestamp": "1769384471239", "event_type": "price_change"}}
{"_local_timestamp": "2026-01-25T23:41:11.939538+00:00", "data": {"market": "0x2393ed0b0fdc450054c7b9071907eca75cf4fc36e385adf4a0a5f99ee62243e8", "price_changes": [{"asset_id": "32769749367306925959219403371425714180265458150646381231272229429098460625924", "price": "0.897", "size": "0", "side": "BUY", "hash": "9daf87679cb50282bae0d2f2bc931d5b6622a086", "best_bid": "0.906", "best_ask": "0.96"}, {"asset_id": "100074770378634056601572485653252702850363676459996771990439989989293515601975", "price": "0.103", "size": "0", "side": "SELL", "hash": "8b0163ea3da5dc940ece3b70765a664002343495", "best_bid": "0.04", "best_ask": "0.094"}], "timestamp": "1769384471866", "event_type": "price_change"}}
{"_local_timestamp": "2026-01-25T23:41:11.960302+00:00", "data": {"market": "0x9472be65457510b7fc3477b20ba90910e99d92eac8421a14bf4b7b7a08ef31dc", "price_changes": [{"asset_id": "43311793366960417907757893276427136943959788721376762326430771171648759300146", "price": "0.67", "size": "0", "side": "BUY", "hash": "cb40e7e70b6de6fbf2e2b9d9f80d73d43be5a599", "best_bid": "0.995", "best_ask": "0.998"}, {"asset_id": "73414222381656326204771753454630063673548497164758947581648273905027617570612", "price": "0.33", "size": "0", "side": "SELL", "hash": "49935b2c5e00d1dbfaef9346abec95cfdf71ea16", "best_bid": "0.002", "best_ask": "0.005"}], "timestamp": "1769384471891", "event_type": "price_change"}}
{"_local_timestamp": "2026-01-25T23:41:12.391092+00:00", "data": {"market": "0x9472be65457510b7fc3477b20ba90910e99d92eac8421a14bf4b7b7a08ef31dc", "price_changes": [{"asset_id": "43311793366960417907757893276427136943959788721376762326430771171648759300146", "price": "0.67", "size": "5", "side": "BUY", "hash": "28d8208ba039525b48ccd357f5528ed1c7309cc5", "best_bid": "0.995", "best_ask": "0.998"}, {"asset_id": "73414222381656326204771753454630063673548497164758947581648273905027617570612", "price": "0.33", "size": "5", "side": "SELL", "hash": "71c4ed35db7e74344667c0220ae857e5a32faf78", "best_bid": "0.002", "best_ask": "0.005"}], "timestamp": "1769384472315", "event_type": "price_change"}}
{"_local_timestamp": "2026-01-25T23:41:13.295082+00:00", "data": {"market": "0x2393ed0b0fdc450054c7b9071907eca75cf4fc36e385adf4a0a5f99ee62243e8", "price_changes": [{"asset_id": "32769749367306925959219403371425714180265458150646381231272229429098460625924", "price": "0.899", "size": "37.81", "side": "BUY", "hash": "5b1438e7f44f35ea45f72d6035ed5198d3fa0679", "best_bid": "0.906", "best_ask": "0.96"}, {"asset_id": "100074770378634056601572485653252702850363676459996771990439989989293515601975", "price": "0.101", "size": "37.81", "side": "SELL", "hash": "2d575ebc89c5f2b5205e7cdfd58e6b10a67711e8", "best_bid": "0.04", "best_ask": "0.094"}], "timestamp": "1769384473225", "event_type": "price_change"}}
{"_local_timestamp": "2026-01-25T23:41:14.366412+00:00", "data": {"market": "0x9472be65457510b7fc3477b20ba90910e99d92eac8421a14bf4b7b7a08ef31dc", "price_changes": [{"asset_id": "43311793366960417907757893276427136943959788721376762326430771171648759300146", "price": "0.67", "size": "0", "side": "BUY", "hash": "54aab80bf01410f4f5821b7a1e2d76482a6213aa", "best_bid": "0.995", "best_ask": "0.998"}, {"asset_id": "73414222381656326204771753454630063673548497164758947581648273905027617570612", "price": "0.33", "size": "0", "side": "SELL", "hash": "f9df2a454030ac76e7b96b4f30b5d37b14926050", "best_bid": "0.002", "best_ask": "0.005"}], "timestamp": "1769384474294", "event_type": "price_change"}}
{"_local_timestamp": "2026-01-25T23:41:14.865379+00:00", "data": {"market": "0x9472be65457510b7fc3477b20ba90910e99d92eac8421a14bf4b7b7a08ef31dc", "price_changes": [{"asset_id": "43311793366960417907757893276427136943959788721376762326430771171648759300146", "price": "0.67", "size": "5", "side": "BUY", "hash": "fbfb9cbbf9fe7655e679fc7767e66ff0c5562836", "best_bid": "0.995", "best_ask": "0.998"}, {"asset_id": "73414222381656326204771753454630063673548497164758947581648273905027617570612", "price": "0.33", "size": "5", "side": "SELL", "hash": "284e4c40054d157fd926429e84a8cf38816491b5", "best_bid": "0.002", "best_ask": "0.005"}], "timestamp": "1769384474739", "event_type": "price_change"}}
{"_local_timestamp": "2026-01-25T23:41:17.035016+00:00", "data": {"market": "0x2393ed0b0fdc450054c7b9071907eca75cf4fc36e385adf4a0a5f99ee62243e8", "price_changes": [{"asset_id": "32769749367306925959219403371425714180265458150646381231272229429098460625924", "price": "0.9", "size": "50", "side": "BUY", "hash": "ad7d4065d2f08599540f7ccb6a80b2a96f8783ee", "best_bid": "0.906", "best_ask": "0.96"}, {"asset_id": "100074770378634056601572485653252702850363676459996771990439989989293515601975", "price": "0.1", "size": "50", "side": "SELL", "hash": "9c1a5ce130fdd8387bc6a1170d87dec42df70dad", "best_bid": "0.04", "best_ask": "0.094"}], "timestamp": "1769384476964", "event_type": "price_change"}}
{"_local_timestamp": "2026-01-25T23:41:17.318187+00:00", "data": {"market": "0x2393ed0b0fdc450054c7b9071907eca75cf4fc36e385adf4a0a5f99ee62243e8", "price_changes": [{"asset_id": "32769749367306925959219403371425714180265458150646381231272229429098460625924", "price": "0.898", "size": "0", "side": "BUY", "hash": "d709073a420733ae2a93a82cd1d1c596c7a65d1e", "best_bid": "0.906", "best_ask": "0.96"}, {"asset_id": "100074770378634056601572485653252702850363676459996771990439989989293515601975", "price": "0.102", "size": "0", "side": "SELL", "hash": "2500a957c478d2b691e05de02865a050fa826ecd", "best_bid": "0.04", "best_ask": "0.094"}], "timestamp": "1769384477243", "event_type": "price_change"}}
{"_local_timestamp": "2026-01-25T23:41:18.392042+00:00", "data": {"market": "0x9472be65457510b7fc3477b20ba90910e99d92eac8421a14bf4b7b7a08ef31dc", "price_changes": [{"asset_id": "43311793366960417907757893276427136943959788721376762326430771171648759300146", "price": "0.67", "size": "0", "side": "BUY", "hash": "e9b1057a4c00408f861f13623edb82efc194d4be", "best_bid": "0.995", "best_ask": "0.998"}, {"asset_id": "73414222381656326204771753454630063673548497164758947581648273905027617570612", "price": "0.33", "size": "0", "side": "SELL", "hash": "1efc2b52922bb4e4fa8dff220652f916c4899e68", "best_bid": "0.002", "best_ask": "0.005"}], "timestamp": "1769384478266", "event_type": "price_change"}}
{"_local_timestamp": "2026-01-25T23:41:18.680681+00:00", "data": {"market": "0x9472be65457510b7fc3477b20ba90910e99d92eac8421a14bf4b7b7a08ef31dc", "price_changes": [{"asset_id": "43311793366960417907757893276427136943959788721376762326430771171648759300146", "price": "0.67", "size": "5", "side": "BUY", "hash": "6fcf1101e7c8c2085c095d12b9092932c2c6fe05", "best_bid": "0.995", "best_ask": "0.998"}, {"asset_id": "73414222381656326204771753454630063673548497164758947581648273905027617570612", "price": "0.33", "size": "5", "side": "SELL", "hash": "0e409f6c9e526f01e902259c8595047401153c47", "best_bid": "0.002", "best_ask": "0.005"}], "timestamp": "1769384478602", "event_type": "price_change"}}
{"_local_timestamp": "2026-01-25T23:41:18.732500+00:00", "data": {"market": "0x2393ed0b0fdc450054c7b9071907eca75cf4fc36e385adf4a0a5f99ee62243e8", "price_changes": [{"asset_id": "32769749367306925959219403371425714180265458150646381231272229429098460625924", "price": "0.899", "size": "0", "side": "BUY", "hash": "b42b33e4dfbce7050d15fd7b38443e02ac8a03dd", "best_bid": "0.906", "best_ask": "0.96"}, {"asset_id": "100074770378634056601572485653252702850363676459996771990439989989293515601975", "price": "0.101", "size": "0", "side": "SELL", "hash": "9a7ae5ba067391303c01004b7c7ae37320ffc127", "best_bid": "0.04", "best_ask": "0.094"}], "timestamp": "1769384478665", "event_type": "price_change"}}
{"_local_timestamp": "2026-01-25T23:41:19.984385+00:00", "data": {"market": "0x9472be65457510b7fc3477b20ba90910e99d92eac8421a14bf4b7b7a08ef31dc", "price_changes": [{"asset_id": "43311793366960417907757893276427136943959788721376762326430771171648759300146", "price": "0.67", "size": "0", "side": "BUY", "hash": "a114aacd2d176e5b1c30272e0ccacac2fb82ed06", "best_bid": "0.995", "best_ask": "0.998"}, {"asset_id": "73414222381656326204771753454630063673548497164758947581648273905027617570612", "price": "0.33", "size": "0", "side": "SELL", "hash": "553f4e5ba8e99a08abf1701b0898a62e4f485128", "best_bid": "0.002", "best_ask": "0.005"}], "timestamp": "1769384479911", "event_type": "price_change"}}
{"_local_timestamp": "2026-01-25T23:41:20.062235+00:00", "data": {"market": "0x2393ed0b0fdc450054c7b9071907eca75cf4fc36e385adf4a0a5f99ee62243e8", "price_changes": [{"asset_id": "32769749367306925959219403371425714180265458150646381231272229429098460625924", "price": "0.901", "size": "37.81", "side": "BUY", "hash": "f35df2494f8d7d79584a24f82bda1288ee743814", "best_bid": "0.906", "best_ask": "0.96"}, {"asset_id": "100074770378634056601572485653252702850363676459996771990439989989293515601975", "price": "0.099", "size": "37.81", "side": "SELL", "hash": "aeef62c104046adf9dcf797cf3c9467f9a9aa48a", "best_bid": "0.04", "best_ask": "0.094"}], "timestamp": "1769384479988", "event_type": "price_change"}}
{"_local_timestamp": "2026-01-25T23:41:20.392400+00:00", "data": {"market": "0x9472be65457510b7fc3477b20ba90910e99d92eac8421a14bf4b7b7a08ef31dc", "price_changes": [{"asset_id": "43311793366960417907757893276427136943959788721376762326430771171648759300146", "price": "0.67", "size": "5", "side": "BUY", "hash": "3bb9fa45ef6238066a607b106d1ed0fdb0a7f2aa", "best_bid": "0.995", "best_ask": "0.998"}, {"asset_id": "73414222381656326204771753454630063673548497164758947581648273905027617570612", "price": "0.33", "size": "5", "side": "SELL", "hash": "557ee8cdf4d8d27ae51d070b55c4ebc40298605d", "best_bid": "0.002", "best_ask": "0.005"}], "timestamp": "1769384480312", "event_type": "price_change"}}
{"_local_timestamp": "2026-01-25T23:41:21.951399+00:00", "data": {"market": "0x9472be65457510b7fc3477b20ba90910e99d92eac8421a14bf4b7b7a08ef31dc", "price_changes": [{"asset_id": "43311793366960417907757893276427136943959788721376762326430771171648759300146", "price": "0.67", "size": "0", "side": "BUY", "hash": "8184a003bdb702eda4f4bf63e30730772033d866", "best_bid": "0.995", "best_ask": "0.998"}, {"asset_id": "73414222381656326204771753454630063673548497164758947581648273905027617570612", "price": "0.33", "size": "0", "side": "SELL", "hash": "e5521edb4d78f80060cf47613e948570d58cd802", "best_bid": "0.002", "best_ask": "0.005"}], "timestamp": "1769384481879", "event_type": "price_change"}}
{"_local_timestamp": "2026-01-25T23:41:22.173468+00:00", "data": {"market": "0x9472be65457510b7fc3477b20ba90910e99d92eac8421a14bf4b7b7a08ef31dc", "price_changes": [{"asset_id": "43311793366960417907757893276427136943959788721376762326430771171648759300146", "price": "0.67", "size": "5", "side": "BUY", "hash": "204cfd280da6a6d8fbeb29488262c869c119eafc", "best_bid": "0.995", "best_ask": "0.998"}, {"asset_id": "73414222381656326204771753454630063673548497164758947581648273905027617570612", "price": "0.33", "size": "5", "side": "SELL", "hash": "62c6ae8e721fbad6c6e3adc873963ddf4814103d", "best_bid": "0.002", "best_ask": "0.005"}], "timestamp": "1769384482097", "event_type": "price_change"}}
{"_local_timestamp": "2026-01-25T23:41:23.155732+00:00", "data": {"market": "0x2393ed0b0fdc450054c7b9071907eca75cf4fc36e385adf4a0a5f99ee62243e8", "price_changes": [{"asset_id": "32769749367306925959219403371425714180265458150646381231272229429098460625924", "price": "0.902", "size": "50", "side": "BUY", "hash": "a533b5859b3bdf6e09f06fe769f42c79b874b505", "best_bid": "0.906", "best_ask": "0.96"}, {"asset_id": "100074770378634056601572485653252702850363676459996771990439989989293515601975", "price": "0.098", "size": "50", "side": "SELL", "hash": "8f04c9f6926ef80e191aa9d3b82320f327be598b", "best_bid": "0.04", "best_ask": "0.094"}], "timestamp": "1769384483053", "event_type": "price_change"}}
{"_local_timestamp": "2026-01-25T23:41:23.243569+00:00", "data": {"market": "0x9472be65457510b7fc3477b20ba90910e99d92eac8421a14bf4b7b7a08ef31dc", "price_changes": [{"asset_id": "43311793366960417907757893276427136943959788721376762326430771171648759300146", "price": "0.67", "size": "0", "side": "BUY", "hash": "421113a5d68c2412812da2c544171132936b7e1a", "best_bid": "0.995", "best_ask": "0.998"}, {"asset_id": "73414222381656326204771753454630063673548497164758947581648273905027617570612", "price": "0.33", "size": "0", "side": "SELL", "hash": "73c45a47f2835877de11b1ae355a34be46fadfe4", "best_bid": "0.002", "best_ask": "0.005"}], "timestamp": "1769384483175", "event_type": "price_change"}}
{"_local_timestamp": "2026-01-25T23:41:23.356282+00:00", "data": {"market": "0x2393ed0b0fdc450054c7b9071907eca75cf4fc36e385adf4a0a5f99ee62243e8", "price_changes": [{"asset_id": "32769749367306925959219403371425714180265458150646381231272229429098460625924", "price": "0.89", "size": "30", "side": "BUY", "hash": "607618204cbaac73b316f90f92025edd94d7c0e7", "best_bid": "0.906", "best_ask": "0.96"}, {"asset_id": "100074770378634056601572485653252702850363676459996771990439989989293515601975", "price": "0.11", "size": "30", "side": "SELL", "hash": "f899b6b307a6ec1176ce65132a52b64c3cdade79", "best_bid": "0.04", "best_ask": "0.094"}], "timestamp": "1769384483279", "event_type": "price_change"}}
{"_local_timestamp": "2026-01-25T23:41:23.463351+00:00", "data": {"market": "0x9472be65457510b7fc3477b20ba90910e99d92eac8421a14bf4b7b7a08ef31dc", "price_changes": [{"asset_id": "43311793366960417907757893276427136943959788721376762326430771171648759300146", "price": "0.67", "size": "5", "side": "BUY", "hash": "7b93ecc68d77540ace2466b6176637ce027f4356", "best_bid": "0.995", "best_ask": "0.998"}, {"asset_id": "73414222381656326204771753454630063673548497164758947581648273905027617570612", "price": "0.33", "size": "5", "side": "SELL", "hash": "144de934a688830ea7e1ee05d9aa57f75bbe61f9", "best_bid": "0.002", "best_ask": "0.005"}], "timestamp": "1769384483392", "event_type": "price_change"}}
{"_local_timestamp": "2026-01-25T23:41:23.758729+00:00", "data": {"market": "0x2393ed0b0fdc450054c7b9071907eca75cf4fc36e385adf4a0a5f99ee62243e8", "price_changes": [{"asset_id": "32769749367306925959219403371425714180265458150646381231272229429098460625924", "price": "0.9", "size": "0", "side": "BUY", "hash": "ed708f2113c3e9d7e41b6b08a258ff06bd9740e2", "best_bid": "0.906", "best_ask": "0.96"}, {"asset_id": "100074770378634056601572485653252702850363676459996771990439989989293515601975", "price": "0.1", "size": "0", "side": "SELL", "hash": "1c21bc92e5e3ad9a83d737a148aa5f3ac1c5fa4f", "best_bid": "0.04", "best_ask": "0.094"}], "timestamp": "1769384483684", "event_type": "price_change"}}
{"_local_timestamp": "2026-01-25T23:41:23.826298+00:00", "data": {"market": "0x2393ed0b0fdc450054c7b9071907eca75cf4fc36e385adf4a0a5f99ee62243e8", "price_changes": [{"asset_id": "32769749367306925959219403371425714180265458150646381231272229429098460625924", "price": "0.901", "size": "0", "side": "BUY", "hash": "c618771c6c32d13c133f914950341eee9e5cf6cf", "best_bid": "0.906", "best_ask": "0.96"}, {"asset_id": "100074770378634056601572485653252702850363676459996771990439989989293515601975", "price": "0.099", "size": "0", "side": "SELL", "hash": "7aa2cefe058282fec08dfa90d2e5c6f08d196c95", "best_bid": "0.04", "best_ask": "0.094"}], "timestamp": "1769384483763", "event_type": "price_change"}}
{"_local_timestamp": "2026-01-25T23:41:24.321628+00:00", "data": {"market": "0x2393ed0b0fdc450054c7b9071907eca75cf4fc36e385adf4a0a5f99ee62243e8", "price_changes": [{"asset_id": "32769749367306925959219403371425714180265458150646381231272229429098460625924", "price": "0.89", "size": "0", "side": "BUY", "hash": "53bf46cbdc1fde984b21990ff970aea41154d0ab", "best_bid": "0.906", "best_ask": "0.96"}, {"asset_id": "100074770378634056601572485653252702850363676459996771990439989989293515601975", "price": "0.11", "size": "0", "side": "SELL", "hash": "9dffd2508aa25d66745a1afaf19da961a12c6ca7", "best_bid": "0.04", "best_ask": "0.094"}], "timestamp": "1769384484236", "event_type": "price_change"}}
{"_local_timestamp": "2026-01-25T23:41:24.550097+00:00", "data": {"market": "0x9472be65457510b7fc3477b20ba90910e99d92eac8421a14bf4b7b7a08ef31dc", "price_changes": [{"asset_id": "43311793366960417907757893276427136943959788721376762326430771171648759300146", "price": "0.67", "size": "0", "side": "BUY", "hash": "c9729b178327288a16b5339699153127376d0e95", "best_bid": "0.995", "best_ask": "0.998"}, {"asset_id": "73414222381656326204771753454630063673548497164758947581648273905027617570612", "price": "0.33", "size": "0", "side": "SELL", "hash": "02fea4921189b1d2d63a5d540281a28ddd3b1fe2", "best_bid": "0.002", "best_ask": "0.005"}], "timestamp": "1769384484479", "event_type": "price_change"}}
{"_local_timestamp": "2026-01-25T23:41:24.775352+00:00", "data": {"market": "0x9472be65457510b7fc3477b20ba90910e99d92eac8421a14bf4b7b7a08ef31dc", "price_changes": [{"asset_id": "43311793366960417907757893276427136943959788721376762326430771171648759300146", "price": "0.67", "size": "5", "side": "BUY", "hash": "e4cf40c2e1bd80f8f12adce2119a673703b0c9cd", "best_bid": "0.995", "best_ask": "0.998"}, {"asset_id": "73414222381656326204771753454630063673548497164758947581648273905027617570612", "price": "0.33", "size": "5", "side": "SELL", "hash": "c029cdda2d17a6dd67b473812d075f5379a6b54d", "best_bid": "0.002", "best_ask": "0.005"}], "timestamp": "1769384484706", "event_type": "price_change"}}
{"_local_timestamp": "2026-01-25T23:41:24.902382+00:00", "data": {"market": "0x2393ed0b0fdc450054c7b9071907eca75cf4fc36e385adf4a0a5f99ee62243e8", "price_changes": [{"asset_id": "32769749367306925959219403371425714180265458150646381231272229429098460625924", "price": "0.903", "size": "37.81", "side": "BUY", "hash": "ea0eb863def1d32d76dd5ba38fb7753b635cc343", "best_bid": "0.906", "best_ask": "0.96"}, {"asset_id": "100074770378634056601572485653252702850363676459996771990439989989293515601975", "price": "0.097", "size": "37.81", "side": "SELL", "hash": "e761df158daeda62ce535a2ef1b17dad5c63f34f", "best_bid": "0.04", "best_ask": "0.094"}], "timestamp": "1769384484834", "event_type": "price_change"}}
{"_local_timestamp": "2026-01-25T23:41:26.331934+00:00", "data": {"market": "0x9472be65457510b7fc3477b20ba90910e99d92eac8421a14bf4b7b7a08ef31dc", "price_changes": [{"asset_id": "43311793366960417907757893276427136943959788721376762326430771171648759300146", "price": "0.67", "size": "0", "side": "BUY", "hash": "f4d62c75cc7c7f69bebfb32eeff703c71e36d457", "best_bid": "0.995", "best_ask": "0.998"}, {"asset_id": "73414222381656326204771753454630063673548497164758947581648273905027617570612", "price": "0.33", "size": "0", "side": "SELL", "hash": "431db7d02b325298d22174292120aebb055e12d8", "best_bid": "0.002", "best_ask": "0.005"}], "timestamp": "1769384486254", "event_type": "price_change"}}
{"_local_timestamp": "2026-01-25T23:41:26.635199+00:00", "data": {"market": "0x9472be65457510b7fc3477b20ba90910e99d92eac8421a14bf4b7b7a08ef31dc", "price_changes": [{"asset_id": "43311793366960417907757893276427136943959788721376762326430771171648759300146", "price": "0.67", "size": "5", "side": "BUY", "hash": "c76eeecacef5f7e6ac81588295921d2302a3ff08", "best_bid": "0.995", "best_ask": "0.998"}, {"asset_id": "73414222381656326204771753454630063673548497164758947581648273905027617570612", "price": "0.33", "size": "5", "side": "SELL", "hash": "7fb77357419744d5538c36be4a42ae014dfc88e1", "best_bid": "0.002", "best_ask": "0.005"}], "timestamp": "1769384486564", "event_type": "price_change"}}
{"_local_timestamp": "2026-01-25T23:41:27.971618+00:00", "data": {"market": "0x9472be65457510b7fc3477b20ba90910e99d92eac8421a14bf4b7b7a08ef31dc", "price_changes": [{"asset_id": "43311793366960417907757893276427136943959788721376762326430771171648759300146", "price": "0.67", "size": "0", "side": "BUY", "hash": "d7d6c10e98dd49e7948538ad5282afa8e7de7fe2", "best_bid": "0.995", "best_ask": "0.998"}, {"asset_id": "73414222381656326204771753454630063673548497164758947581648273905027617570612", "price": "0.33", "size": "0", "side": "SELL", "hash": "bbc4b620846d9e783e33108af83e55aef6e1ad19", "best_bid": "0.002", "best_ask": "0.005"}], "timestamp": "1769384487897", "event_type": "price_change"}}
{"_local_timestamp": "2026-01-25T23:41:28.395672+00:00", "data": {"market": "0x9472be65457510b7fc3477b20ba90910e99d92eac8421a14bf4b7b7a08ef31dc", "price_changes": [{"asset_id": "43311793366960417907757893276427136943959788721376762326430771171648759300146", "price": "0.67", "size": "5", "side": "BUY", "hash": "b22c5238aa844be9a051d4703db8b4155f2d9966", "best_bid": "0.995", "best_ask": "0.998"}, {"asset_id": "73414222381656326204771753454630063673548497164758947581648273905027617570612", "price": "0.33", "size": "5", "side": "SELL", "hash": "349feb5b1d6314cbf184df3277a228660cc434f3", "best_bid": "0.002", "best_ask": "0.005"}], "timestamp": "1769384488318", "event_type": "price_change"}}
{"_local_timestamp": "2026-01-25T23:41:29.496411+00:00", "data": {"market": "0x2393ed0b0fdc450054c7b9071907eca75cf4fc36e385adf4a0a5f99ee62243e8", "price_changes": [{"asset_id": "32769749367306925959219403371425714180265458150646381231272229429098460625924", "price": "0.904", "size": "50", "side": "BUY", "hash": "cb11757a85c92174dcd6e6dbbc030e726b456c27", "best_bid": "0.906", "best_ask": "0.96"}, {"asset_id": "100074770378634056601572485653252702850363676459996771990439989989293515601975", "price": "0.096", "size": "50", "side": "SELL", "hash": "4ccfa09f614e9214d7f4211c2fb60597efa952a9", "best_bid": "0.04", "best_ask": "0.094"}], "timestamp": "1769384489414", "event_type": "price_change"}}
{"_local_timestamp": "2026-01-25T23:41:29.850767+00:00", "data": {"market": "0x2393ed0b0fdc450054c7b9071907eca75cf4fc36e385adf4a0a5f99ee62243e8", "price_changes": [{"asset_id": "32769749367306925959219403371425714180265458150646381231272229429098460625924", "price": "0.902", "size": "0", "side": "BUY", "hash": "d644888198d60089ef835855b4e9bfaaa9e8d879", "best_bid": "0.906", "best_ask": "0.96"}, {"asset_id": "100074770378634056601572485653252702850363676459996771990439989989293515601975", "price": "0.098", "size": "0", "side": "SELL", "hash": "34cf2810e37d9a42697738fe89ae432cd1613f60", "best_bid": "0.04", "best_ask": "0.094"}], "timestamp": "1769384489761", "event_type": "price_change"}}
{"_local_timestamp": "2026-01-25T23:41:30.009630+00:00", "data": {"market": "0x9472be65457510b7fc3477b20ba90910e99d92eac8421a14bf4b7b7a08ef31dc", "price_changes": [{"asset_id": "43311793366960417907757893276427136943959788721376762326430771171648759300146", "price": "0.67", "size": "0", "side": "BUY", "hash": "6a6d843acd787c58082a5cc390f80d2295893aed", "best_bid": "0.995", "best_ask": "0.998"}, {"asset_id": "73414222381656326204771753454630063673548497164758947581648273905027617570612", "price": "0.33", "size": "0", "side": "SELL", "hash": "00a6cd6b5cfcc0a45e3e769dca683d4cb5101687", "best_bid": "0.002", "best_ask": "0.005"}], "timestamp": "1769384489934", "event_type": "price_change"}}
{"_local_timestamp": "2026-01-25T23:41:30.121928+00:00", "data": {"market": "0x2393ed0b0fdc450054c7b9071907eca75cf4fc36e385adf4a0a5f99ee62243e8", "price_changes": [{"asset_id": "32769749367306925959219403371425714180265458150646381231272229429098460625924", "price": "0.903", "size": "0", "side": "BUY", "hash": "c9659601a414c1c6d706b71920fa4cf7efd4323e", "best_bid": "0.906", "best_ask": "0.96"}, {"asset_id": "100074770378634056601572485653252702850363676459996771990439989989293515601975", "price": "0.097", "size": "0", "side": "SELL", "hash": "950ad6b36ff2c6bf72ed3011cd75d319012db166", "best_bid": "0.04", "best_ask": "0.094"}], "timestamp": "1769384490048", "event_type": "price_change"}}
{"_local_timestamp": "2026-01-25T23:41:30.362798+00:00", "data": {"market": "0x9472be65457510b7fc3477b20ba90910e99d92eac8421a14bf4b7b7a08ef31dc", "price_changes": [{"asset_id": "43311793366960417907757893276427136943959788721376762326430771171648759300146", "price": "0.67", "size": "5", "side": "BUY", "hash": "4cc564b7cf08528fd6fe77df4276997ccdb4c61c", "best_bid": "0.995", "best_ask": "0.998"}, {"asset_id": "73414222381656326204771753454630063673548497164758947581648273905027617570612", "price": "0.33", "size": "5", "side": "SELL", "hash": "e487bea62e6f8e9ee4c373e632a07cf8a4238ab6", "best_bid": "0.002", "best_ask": "0.005"}], "timestamp": "1769384490283", "event_type": "price_change"}}
{"_local_timestamp": "2026-01-25T23:41:31.963363+00:00", "data": {"market": "0x2393ed0b0fdc450054c7b9071907eca75cf4fc36e385adf4a0a5f99ee62243e8", "price_changes": [{"asset_id": "32769749367306925959219403371425714180265458150646381231272229429098460625924", "price": "0.905", "size": "37.81", "side": "BUY", "hash": "c34414383e0ceeabce120f35d1ae468a22cd66f4", "best_bid": "0.906", "best_ask": "0.96"}, {"asset_id": "100074770378634056601572485653252702850363676459996771990439989989293515601975", "price": "0.095", "size": "37.81", "side": "SELL", "hash": "3e44af586dbfad35ed865f28ae6d4a0fdaedcc00", "best_bid": "0.04", "best_ask": "0.094"}], "timestamp": "1769384491890", "event_type": "price_change"}}
{"_local_timestamp": "2026-01-25T23:41:32.677964+00:00", "data": {"market": "0x9472be65457510b7fc3477b20ba90910e99d92eac8421a14bf4b7b7a08ef31dc", "price_changes": [{"asset_id": "43311793366960417907757893276427136943959788721376762326430771171648759300146", "price": "0.67", "size": "0", "side": "BUY", "hash": "82a2aacc624f5697439c213393941ec4808bbfaf", "best_bid": "0.995", "best_ask": "0.998"}, {"asset_id": "73414222381656326204771753454630063673548497164758947581648273905027617570612", "price": "0.33", "size": "0", "side": "SELL", "hash": "f2880014ea8c8fa84b4de3849b457804c610a86b", "best_bid": "0.002", "best_ask": "0.005"}], "timestamp": "1769384492608", "event_type": "price_change"}}
{"_local_timestamp": "2026-01-25T23:41:33.065365+00:00", "data": {"market": "0x9472be65457510b7fc3477b20ba90910e99d92eac8421a14bf4b7b7a08ef31dc", "price_changes": [{"asset_id": "43311793366960417907757893276427136943959788721376762326430771171648759300146", "price": "0.67", "size": "5", "side": "BUY", "hash": "4cf5bb7b334a9de89f77da471d5e22b0198b14eb", "best_bid": "0.995", "best_ask": "0.998"}, {"asset_id": "73414222381656326204771753454630063673548497164758947581648273905027617570612", "price": "0.33", "size": "5", "side": "SELL", "hash": "4d30d828f726c88b968e456b6261925177ccec22", "best_bid": "0.002", "best_ask": "0.005"}], "timestamp": "1769384492995", "event_type": "price_change"}}
{"_local_timestamp": "2026-01-25T23:41:35.513689+00:00", "data": {"market": "0x2393ed0b0fdc450054c7b9071907eca75cf4fc36e385adf4a0a5f99ee62243e8", "price_changes": [{"asset_id": "32769749367306925959219403371425714180265458150646381231272229429098460625924", "price": "0.906", "size": "55", "side": "BUY", "hash": "3a1ce15dfb2c7465de03f01cbbe2259250e5057f", "best_bid": "0.906", "best_ask": "0.96"}, {"asset_id": "100074770378634056601572485653252702850363676459996771990439989989293515601975", "price": "0.094", "size": "55", "side": "SELL", "hash": "50d704f1a03115a11814093aecb06d5352d4fecf", "best_bid": "0.04", "best_ask": "0.094"}], "timestamp": "1769384495400", "event_type": "price_change"}}
{"_local_timestamp": "2026-01-25T23:41:35.592330+00:00", "data": {"market": "0x9472be65457510b7fc3477b20ba90910e99d92eac8421a14bf4b7b7a08ef31dc", "price_changes": [{"asset_id": "43311793366960417907757893276427136943959788721376762326430771171648759300146", "price": "0.67", "size": "0", "side": "BUY", "hash": "f6f2c21798d551b147acf50e9ba65ef5a7829ad9", "best_bid": "0.995", "best_ask": "0.998"}, {"asset_id": "73414222381656326204771753454630063673548497164758947581648273905027617570612", "price": "0.33", "size": "0", "side": "SELL", "hash": "3985b288e7f90831bdf0fe5987a862c472bdaec3", "best_bid": "0.002", "best_ask": "0.005"}], "timestamp": "1769384495515", "event_type": "price_change"}}
{"_local_timestamp": "2026-01-25T23:41:35.796007+00:00", "data": {"market": "0x2393ed0b0fdc450054c7b9071907eca75cf4fc36e385adf4a0a5f99ee62243e8", "price_changes": [{"asset_id": "32769749367306925959219403371425714180265458150646381231272229429098460625924", "price": "0.904", "size": "0", "side": "BUY", "hash": "669f44e7b83f58e9db2174526a592168ba6a5fe5", "best_bid": "0.906", "best_ask": "0.96"}, {"asset_id": "100074770378634056601572485653252702850363676459996771990439989989293515601975", "price": "0.096", "size": "0", "side": "SELL", "hash": "45b945a3d91a3b441107d973b47728dc4437294d", "best_bid": "0.04", "best_ask": "0.094"}], "timestamp": "1769384495722", "event_type": "price_change"}}
{"_local_timestamp": "2026-01-25T23:41:36.010342+00:00", "data": {"market": "0x9472be65457510b7fc3477b20ba90910e99d92eac8421a14bf4b7b7a08ef31dc", "price_changes": [{"asset_id": "43311793366960417907757893276427136943959788721376762326430771171648759300146", "price": "0.67", "size": "5", "side": "BUY", "hash": "aa23399eccbe0d4e25759e2cd42f3e40c499b607", "best_bid": "0.995", "best_ask": "0.998"}, {"asset_id": "73414222381656326204771753454630063673548497164758947581648273905027617570612", "price": "0.33", "size": "5", "side": "SELL", "hash": "2d4af2b392a59c89606370f4dd371eb2dfbee0aa", "best_bid": "0.002", "best_ask": "0.005"}], "timestamp": "1769384495937", "event_type": "price_change"}}
{"_local_timestamp": "2026-01-25T23:41:37.137595+00:00", "data": {"market": "0x2393ed0b0fdc450054c7b9071907eca75cf4fc36e385adf4a0a5f99ee62243e8", "price_changes": [{"asset_id": "32769749367306925959219403371425714180265458150646381231272229429098460625924", "price": "0.905", "size": "0", "side": "BUY", "hash": "87e6100db936421b1cfdc81f79185d9966629cad", "best_bid": "0.906", "best_ask": "0.96"}, {"asset_id": "100074770378634056601572485653252702850363676459996771990439989989293515601975", "price": "0.095", "size": "0", "side": "SELL", "hash": "2a4c801e69cb875be53798b9fbe42c92e38177ff", "best_bid": "0.04", "best_ask": "0.094"}], "timestamp": "1769384497052", "event_type": "price_change"}}
{"_local_timestamp": "2026-01-25T23:41:37.371392+00:00", "data": {"market": "0x9472be65457510b7fc3477b20ba90910e99d92eac8421a14bf4b7b7a08ef31dc", "price_changes": [{"asset_id": "43311793366960417907757893276427136943959788721376762326430771171648759300146", "price": "0.67", "size": "0", "side": "BUY", "hash": "12f00fb2c6cc04acc27f011594d0324f205c752d", "best_bid": "0.995", "best_ask": "0.998"}, {"asset_id": "73414222381656326204771753454630063673548497164758947581648273905027617570612", "price": "0.33", "size": "0", "side": "SELL", "hash": "eab71fc38b0462522dc731a4568659ad7cd26420", "best_bid": "0.002", "best_ask": "0.005"}], "timestamp": "1769384497298", "event_type": "price_change"}}
{"_local_timestamp": "2026-01-25T23:41:37.750387+00:00", "data": {"market": "0x9472be65457510b7fc3477b20ba90910e99d92eac8421a14bf4b7b7a08ef31dc", "price_changes": [{"asset_id": "43311793366960417907757893276427136943959788721376762326430771171648759300146", "price": "0.67", "size": "5", "side": "BUY", "hash": "fc8a4c1fa3b87f2e0cf4e5556bfdbcf992687826", "best_bid": "0.995", "best_ask": "0.998"}, {"asset_id": "73414222381656326204771753454630063673548497164758947581648273905027617570612", "price": "0.33", "size": "5", "side": "SELL", "hash": "d61602603a1e661f01ba8f01c0a268df3de342fc", "best_bid": "0.002", "best_ask": "0.005"}], "timestamp": "1769384497676", "event_type": "price_change"}}
{"_local_timestamp": "2026-01-25T23:41:39.215322+00:00", "data": {"market": "0x2393ed0b0fdc450054c7b9071907eca75cf4fc36e385adf4a0a5f99ee62243e8", "price_changes": [{"asset_id": "32769749367306925959219403371425714180265458150646381231272229429098460625924", "price": "0.907", "size": "37.81", "side": "BUY", "hash": "9db5cd06f45ac4d6adedbef9db14a6f16e46c94f", "best_bid": "0.907", "best_ask": "0.96"}, {"asset_id": "100074770378634056601572485653252702850363676459996771990439989989293515601975", "price": "0.093", "size": "37.81", "side": "SELL", "hash": "b13ea24b592cb0a3bfe0d2212581038cd4d7c1a8", "best_bid": "0.04", "best_ask": "0.093"}], "timestamp": "1769384499139", "event_type": "price_change"}}
{"_local_timestamp": "2026-01-25T23:41:40.137958+00:00", "data": {"market": "0x9472be65457510b7fc3477b20ba90910e99d92eac8421a14bf4b7b7a08ef31dc", "price_changes": [{"asset_id": "43311793366960417907757893276427136943959788721376762326430771171648759300146", "price": "0.67", "size": "0", "side": "BUY", "hash": "c78ff75b519180cd6566761a756150f9d0e0b71f", "best_bid": "0.995", "best_ask": "0.998"}, {"asset_id": "73414222381656326204771753454630063673548497164758947581648273905027617570612", "price": "0.33", "size": "0", "side": "SELL", "hash": "c5883f43f09492cab6e709727846d596208a17ba", "best_bid": "0.002", "best_ask": "0.005"}], "timestamp": "1769384500057", "event_type": "price_change"}}
{"_local_timestamp": "2026-01-25T23:41:40.480291+00:00", "data": {"market": "0x9472be65457510b7fc3477b20ba90910e99d92eac8421a14bf4b7b7a08ef31dc", "price_changes": [{"asset_id": "43311793366960417907757893276427136943959788721376762326430771171648759300146", "price": "0.67", "size": "5", "side": "BUY", "hash": "641d1f00ba911d5175422b32ec31fcbf6fe26c04", "best_bid": "0.995", "best_ask": "0.998"}, {"asset_id": "73414222381656326204771753454630063673548497164758947581648273905027617570612", "price": "0.33", "size": "5", "side": "SELL", "hash": "7753fbc1a8363645bb11fbd9459fcb2bf5e82096", "best_bid": "0.002", "best_ask": "0.005"}], "timestamp": "1769384500381", "event_type": "price_change"}}
{"_local_timestamp": "2026-01-25T23:41:40.924393+00:00", "data": {"market": "0x2393ed0b0fdc450054c7b9071907eca75cf4fc36e385adf4a0a5f99ee62243e8", "price_changes": [{"asset_id": "32769749367306925959219403371425714180265458150646381231272229429098460625924", "price": "0.906", "size": "85", "side": "BUY", "hash": "ef6dd835be4e8523b36341d30ae94392bd9851fe", "best_bid": "0.907", "best_ask": "0.96"}, {"asset_id": "100074770378634056601572485653252702850363676459996771990439989989293515601975", "price": "0.094", "size": "85", "side": "SELL", "hash": "385bedb4475be323e9ea01c264d2d08d3c4712ae", "best_bid": "0.04", "best_ask": "0.093"}], "timestamp": "1769384500853", "event_type": "price_change"}}
{"_local_timestamp": "2026-01-25T23:41:41.325379+00:00", "data": {"market": "0x2393ed0b0fdc450054c7b9071907eca75cf4fc36e385adf4a0a5f99ee62243e8", "price_changes": [{"asset_id": "32769749367306925959219403371425714180265458150646381231272229429098460625924", "price": "0.908", "size": "50", "side": "BUY", "hash": "4f7f027210c38be5574314a0efa166f440827c3d", "best_bid": "0.908", "best_ask": "0.96"}, {"asset_id": "100074770378634056601572485653252702850363676459996771990439989989293515601975", "price": "0.092", "size": "50", "side": "SELL", "hash": "0997304960a677bdadb2b3c2736caf88402f105c", "best_bid": "0.04", "best_ask": "0.092"}], "timestamp": "1769384501257", "event_type": "price_change"}}
{"_local_timestamp": "2026-01-25T23:41:41.680926+00:00", "data": {"market": "0x2393ed0b0fdc450054c7b9071907eca75cf4fc36e385adf4a0a5f99ee62243e8", "price_changes": [{"asset_id": "32769749367306925959219403371425714180265458150646381231272229429098460625924", "price": "0.906", "size": "35", "side": "BUY", "hash": "e0ddd1d8dba91494aaff4e1d6e7731bfe1c5a6a8", "best_bid": "0.908", "best_ask": "0.96"}, {"asset_id": "100074770378634056601572485653252702850363676459996771990439989989293515601975", "price": "0.094", "size": "35", "side": "SELL", "hash": "a404dd9b9d1728c9cb0002681ffd0fe365193d46", "best_bid": "0.04", "best_ask": "0.092"}], "timestamp": "1769384501609", "event_type": "price_change"}}
{"_local_timestamp": "2026-01-25T23:41:42.582914+00:00", "data": {"market": "0x2393ed0b0fdc450054c7b9071907eca75cf4fc36e385adf4a0a5f99ee62243e8", "price_changes": [{"asset_id": "32769749367306925959219403371425714180265458150646381231272229429098460625924", "price": "0.907", "size": "0", "side": "BUY", "hash": "2823ac08e732019dcdf4e386d93df8e8f27c179e", "best_bid": "0.908", "best_ask": "0.96"}, {"asset_id": "100074770378634056601572485653252702850363676459996771990439989989293515601975", "price": "0.093", "size": "0", "side": "SELL", "hash": "886dd6fb8487c97f97669bf9992d32eade4bbca9", "best_bid": "0.04", "best_ask": "0.092"}], "timestamp": "1769384502516", "event_type": "price_change"}}
{"_local_timestamp": "2026-01-25T23:41:42.698574+00:00", "data": {"market": "0x9472be65457510b7fc3477b20ba90910e99d92eac8421a14bf4b7b7a08ef31dc", "price_changes": [{"asset_id": "43311793366960417907757893276427136943959788721376762326430771171648759300146", "price": "0.67", "size": "0", "side": "BUY", "hash": "54e5a4cd90dd6c7feb091fb7ad5568a03f393ae0", "best_bid": "0.995", "best_ask": "0.998"}, {"asset_id": "73414222381656326204771753454630063673548497164758947581648273905027617570612", "price": "0.33", "size": "0", "side": "SELL", "hash": "4b343f4023b005573f1d1e18cdbda6ca0b44758e", "best_bid": "0.002", "best_ask": "0.005"}], "timestamp": "1769384502626", "event_type": "price_change"}}
{"_local_timestamp": "2026-01-25T23:41:43.140445+00:00", "data": {"market": "0x9472be65457510b7fc3477b20ba90910e99d92eac8421a14bf4b7b7a08ef31dc", "price_changes": [{"asset_id": "43311793366960417907757893276427136943959788721376762326430771171648759300146", "price": "0.67", "size": "5", "side": "BUY", "hash": "07dcc9598ceb2aeea43818ffd6079743477e98c7", "best_bid": "0.995", "best_ask": "0.998"}, {"asset_id": "73414222381656326204771753454630063673548497164758947581648273905027617570612", "price": "0.33", "size": "5", "side": "SELL", "hash": "55d56f7c30e6930f95c2a815df156c2e8b7350c7", "best_bid": "0.002", "best_ask": "0.005"}], "timestamp": "1769384503073", "event_type": "price_change"}}
{"_local_timestamp": "2026-01-25T23:41:44.088644+00:00", "data": {"market": "0x2393ed0b0fdc450054c7b9071907eca75cf4fc36e385adf4a0a5f99ee62243e8", "price_changes": [{"asset_id": "32769749367306925959219403371425714180265458150646381231272229429098460625924", "price": "0.909", "size": "37.81", "side": "BUY", "hash": "637c80999210fbc85493909bf03d016de4a50204", "best_bid": "0.909", "best_ask": "0.96"}, {"asset_id": "100074770378634056601572485653252702850363676459996771990439989989293515601975", "price": "0.091", "size": "37.81", "side": "SELL", "hash": "75676d36d79d7934f9bb3342af81d9e5608c72af", "best_bid": "0.04", "best_ask": "0.091"}], "timestamp": "1769384504020", "event_type": "price_change"}}
{"_local_timestamp": "2026-01-25T23:41:44.130297+00:00", "data": {"market": "0x9472be65457510b7fc3477b20ba90910e99d92eac8421a14bf4b7b7a08ef31dc", "price_changes": [{"asset_id": "43311793366960417907757893276427136943959788721376762326430771171648759300146", "price": "0.67", "size": "0", "side": "BUY", "hash": "bf00e941d87457a266d77b74863794adfc34609b", "best_bid": "0.995", "best_ask": "0.998"}, {"asset_id": "73414222381656326204771753454630063673548497164758947581648273905027617570612", "price": "0.33", "size": "0", "side": "SELL", "hash": "a8ab6132c21e134370a00cdab1cf766da69de745", "best_bid": "0.002", "best_ask": "0.005"}], "timestamp": "1769384504060", "event_type": "price_change"}}
{"_local_timestamp": "2026-01-25T23:41:44.411032+00:00", "data": {"market": "0x9472be65457510b7fc3477b20ba90910e99d92eac8421a14bf4b7b7a08ef31dc", "price_changes": [{"asset_id": "43311793366960417907757893276427136943959788721376762326430771171648759300146", "price": "0.67", "size": "5", "side": "BUY", "hash": "d64b5d868d366e7b0c0886b97bddf0105d68141c", "best_bid": "0.995", "best_ask": "0.998"}, {"asset_id": "73414222381656326204771753454630063673548497164758947581648273905027617570612", "price": "0.33", "size": "5", "side": "SELL", "hash": "a70856cb1a7d9f6860578cfc2329461123cedd7a", "best_bid": "0.002", "best_ask": "0.005"}], "timestamp": "1769384504330", "event_type": "price_change"}}
{"_local_timestamp": "2026-01-25T23:41:46.931480+00:00", "data": {"market": "0x9472be65457510b7fc3477b20ba90910e99d92eac8421a14bf4b7b7a08ef31dc", "price_changes": [{"asset_id": "43311793366960417907757893276427136943959788721376762326430771171648759300146", "price": "0.67", "size": "0", "side": "BUY", "hash": "86f94104d1d469236008328e0818827f9c33726c", "best_bid": "0.995", "best_ask": "0.998"}, {"asset_id": "73414222381656326204771753454630063673548497164758947581648273905027617570612", "price": "0.33", "size": "0", "side": "SELL", "hash": "147843f13ab6180b9c42812e9d2814f5c314c098", "best_bid": "0.002", "best_ask": "0.005"}], "timestamp": "1769384506847", "event_type": "price_change"}}
{"_local_timestamp": "2026-01-25T23:41:47.342517+00:00", "data": {"market": "0x9472be65457510b7fc3477b20ba90910e99d92eac8421a14bf4b7b7a08ef31dc", "price_changes": [{"asset_id": "43311793366960417907757893276427136943959788721376762326430771171648759300146", "price": "0.67", "size": "5", "side": "BUY", "hash": "8d4bb1e7d4dc486214568dbba3cad546b79f8b4f", "best_bid": "0.995", "best_ask": "0.998"}, {"asset_id": "73414222381656326204771753454630063673548497164758947581648273905027617570612", "price": "0.33", "size": "5", "side": "SELL", "hash": "25e8ad8f85c56a42672f03890b286bc8422027b5", "best_bid": "0.002", "best_ask": "0.005"}], "timestamp": "1769384507273", "event_type": "price_change"}}
{"_local_timestamp": "2026-01-25T23:41:47.400352+00:00", "data": {"market": "0x2393ed0b0fdc450054c7b9071907eca75cf4fc36e385adf4a0a5f99ee62243e8", "price_changes": [{"asset_id": "32769749367306925959219403371425714180265458150646381231272229429098460625924", "price": "0.91", "size": "50", "side": "BUY", "hash": "67f313b973e278459b75450120cecda33aa7c77c", "best_bid": "0.91", "best_ask": "0.96"}, {"asset_id": "100074770378634056601572485653252702850363676459996771990439989989293515601975", "price": "0.09", "size": "50", "side": "SELL", "hash": "a1517d00f7ee251e1205fa640c327b0cee6b9a7e", "best_bid": "0.04", "best_ask": "0.09"}], "timestamp": "1769384507332", "event_type": "price_change"}}
{"_local_timestamp": "2026-01-25T23:41:47.597026+00:00", "data": {"market": "0x2393ed0b0fdc450054c7b9071907eca75cf4fc36e385adf4a0a5f99ee62243e8", "price_changes": [{"asset_id": "32769749367306925959219403371425714180265458150646381231272229429098460625924", "price": "0.906", "size": "5", "side": "BUY", "hash": "76143735d573c86fc76d658af45b12849e43d999", "best_bid": "0.91", "best_ask": "0.96"}, {"asset_id": "100074770378634056601572485653252702850363676459996771990439989989293515601975", "price": "0.094", "size": "5", "side": "SELL", "hash": "2ea3f9ecfce48b247f58eac45729b04ea00b4bdc", "best_bid": "0.04", "best_ask": "0.09"}], "timestamp": "1769384507524", "event_type": "price_change"}}
{"_local_timestamp": "2026-01-25T23:41:47.769544+00:00", "data": {"market": "0x2393ed0b0fdc450054c7b9071907eca75cf4fc36e385adf4a0a5f99ee62243e8", "price_changes": [{"asset_id": "32769749367306925959219403371425714180265458150646381231272229429098460625924", "price": "0.908", "size": "0", "side": "BUY", "hash": "351b15c168851e8a107abc4db10f20e8c5271c2b", "best_bid": "0.91", "best_ask": "0.96"}, {"asset_id": "100074770378634056601572485653252702850363676459996771990439989989293515601975", "price": "0.092", "size": "0", "side": "SELL", "hash": "d5f271a7198b3d3f788c3ad9c7be0fd9be569e83", "best_bid": "0.04", "best_ask": "0.09"}], "timestamp": "1769384507696", "event_type": "price_change"}}
{"_local_timestamp": "2026-01-25T23:41:48.481411+00:00", "data": {"market": "0x2393ed0b0fdc450054c7b9071907eca75cf4fc36e385adf4a0a5f99ee62243e8", "price_changes": [{"asset_id": "32769749367306925959219403371425714180265458150646381231272229429098460625924", "price": "0.909", "size": "0", "side": "BUY", "hash": "2b0b5edc9ebb185accf3425241fcacd3397c0fc3", "best_bid": "0.91", "best_ask": "0.96"}, {"asset_id": "100074770378634056601572485653252702850363676459996771990439989989293515601975", "price": "0.091", "size": "0", "side": "SELL", "hash": "7723fce13a1f0d203a6b054238a8c72d38526db9", "best_bid": "0.04", "best_ask": "0.09"}], "timestamp": "1769384508412", "event_type": "price_change"}}
{"_local_timestamp": "2026-01-25T23:41:48.562625+00:00", "data": {"market": "0x9472be65457510b7fc3477b20ba90910e99d92eac8421a14bf4b7b7a08ef31dc", "price_changes": [{"asset_id": "43311793366960417907757893276427136943959788721376762326430771171648759300146", "price": "0.67", "size": "0", "side": "BUY", "hash": "4884f1c199fdcf752d598af585d8e2c960c2af90", "best_bid": "0.995", "best_ask": "0.998"}, {"asset_id": "73414222381656326204771753454630063673548497164758947581648273905027617570612", "price": "0.33", "size": "0", "side": "SELL", "hash": "0fb6cd30113977582cc107da628b81e32ff11643", "best_bid": "0.002", "best_ask": "0.005"}], "timestamp": "1769384508492", "event_type": "price_change"}}
{"_local_timestamp": "2026-01-25T23:41:48.910503+00:00", "data": {"market": "0x9472be65457510b7fc3477b20ba90910e99d92eac8421a14bf4b7b7a08ef31dc", "price_changes": [{"asset_id": "43311793366960417907757893276427136943959788721376762326430771171648759300146", "price": "0.67", "size": "5", "side": "BUY", "hash": "75e154c15f81ead75cbdaa163e8402031f77a79e", "best_bid": "0.995", "best_ask": "0.998"}, {"asset_id": "73414222381656326204771753454630063673548497164758947581648273905027617570612", "price": "0.33", "size": "5", "side": "SELL", "hash": "c6715fd31fb15e25166e8bccd553c475dde9cd89", "best_bid": "0.002", "best_ask": "0.005"}], "timestamp": "1769384508842", "event_type": "price_change"}}
{"_local_timestamp": "2026-01-25T23:41:49.507529+00:00", "data": {"market": "0x2393ed0b0fdc450054c7b9071907eca75cf4fc36e385adf4a0a5f99ee62243e8", "price_changes": [{"asset_id": "32769749367306925959219403371425714180265458150646381231272229429098460625924", "price": "0.911", "size": "37.81", "side": "BUY", "hash": "6760ba14dba1690daac8ce9748716660447e66b0", "best_bid": "0.911", "best_ask": "0.96"}, {"asset_id": "100074770378634056601572485653252702850363676459996771990439989989293515601975", "price": "0.089", "size": "37.81", "side": "SELL", "hash": "ce980ebcf32c1a03ab175910139d498249a9fd52", "best_bid": "0.04", "best_ask": "0.089"}], "timestamp": "1769384509429", "event_type": "price_change"}}
{"_local_timestamp": "2026-01-25T23:41:51.150027+00:00", "data": {"market": "0x9472be65457510b7fc3477b20ba90910e99d92eac8421a14bf4b7b7a08ef31dc", "price_changes": [{"asset_id": "43311793366960417907757893276427136943959788721376762326430771171648759300146", "price": "0.67", "size": "0", "side": "BUY", "hash": "c2a84ef69c511d6bc58b4387ac772ad29ea9f4ce", "best_bid": "0.995", "best_ask": "0.998"}, {"asset_id": "73414222381656326204771753454630063673548497164758947581648273905027617570612", "price": "0.33", "size": "0", "side": "SELL", "hash": "79fdb38eb502f89fbbc00433e244a472b2316b18", "best_bid": "0.002", "best_ask": "0.005"}], "timestamp": "1769384511070", "event_type": "price_change"}}
{"_local_timestamp": "2026-01-25T23:41:51.521541+00:00", "data": {"market": "0x9472be65457510b7fc3477b20ba90910e99d92eac8421a14bf4b7b7a08ef31dc", "price_changes": [{"asset_id": "43311793366960417907757893276427136943959788721376762326430771171648759300146", "price": "0.67", "size": "5", "side": "BUY", "hash": "dcc00ac91a225daa208600901fb265b3821cdda1", "best_bid": "0.995", "best_ask": "0.998"}, {"asset_id": "73414222381656326204771753454630063673548497164758947581648273905027617570612", "price": "0.33", "size": "5", "side": "SELL", "hash": "189888c52cee9c2c72b26c8c18152a1577738c46", "best_bid": "0.002", "best_ask": "0.005"}], "timestamp": "1769384511448", "event_type": "price_change"}}
{"_local_timestamp": "2026-01-25T23:41:53.112865+00:00", "data": {"market": "0x9472be65457510b7fc3477b20ba90910e99d92eac8421a14bf4b7b7a08ef31dc", "price_changes": [{"asset_id": "43311793366960417907757893276427136943959788721376762326430771171648759300146", "price": "0.67", "size": "0", "side": "BUY", "hash": "0a8d076fdbcd86a52da7f4db8a8abcda097d6d9f", "best_bid": "0.995", "best_ask": "0.998"}, {"asset_id": "73414222381656326204771753454630063673548497164758947581648273905027617570612", "price": "0.33", "size": "0", "side": "SELL", "hash": "1605ade132e56121c830518ba9f2b3338d8dd248", "best_bid": "0.002", "best_ask": "0.005"}], "timestamp": "1769384512807", "event_type": "price_change"}}
{"_local_timestamp": "2026-01-25T23:41:53.311217+00:00", "data": {"market": "0x9472be65457510b7fc3477b20ba90910e99d92eac8421a14bf4b7b7a08ef31dc", "price_changes": [{"asset_id": "43311793366960417907757893276427136943959788721376762326430771171648759300146", "price": "0.67", "size": "5", "side": "BUY", "hash": "196e8554d076fb9273ba6d2c3fd86fd03123c5d0", "best_bid": "0.995", "best_ask": "0.998"}, {"asset_id": "73414222381656326204771753454630063673548497164758947581648273905027617570612", "price": "0.33", "size": "5", "side": "SELL", "hash": "42d76ec15996099c201b14dc531eb95e49ce6c50", "best_bid": "0.002", "best_ask": "0.005"}], "timestamp": "1769384513205", "event_type": "price_change"}}
{"_local_timestamp": "2026-01-25T23:41:53.377923+00:00", "data": {"market": "0x2393ed0b0fdc450054c7b9071907eca75cf4fc36e385adf4a0a5f99ee62243e8", "price_changes": [{"asset_id": "32769749367306925959219403371425714180265458150646381231272229429098460625924", "price": "0.912", "size": "50", "side": "BUY", "hash": "059c396c4e0a181e73b7c9e40949c08e9eb73533", "best_bid": "0.912", "best_ask": "0.96"}, {"asset_id": "100074770378634056601572485653252702850363676459996771990439989989293515601975", "price": "0.088", "size": "50", "side": "SELL", "hash": "1d9e7faecf98fcf5408d87561c9fa51bf7d3d054", "best_bid": "0.04", "best_ask": "0.088"}], "timestamp": "1769384513307", "event_type": "price_change"}}
{"_local_timestamp": "2026-01-25T23:41:53.784650+00:00", "data": {"market": "0x2393ed0b0fdc450054c7b9071907eca75cf4fc36e385adf4a0a5f99ee62243e8", "price_changes": [{"asset_id": "32769749367306925959219403371425714180265458150646381231272229429098460625924", "price": "0.91", "size": "0", "side": "BUY", "hash": "bd693ed5247855b0d9ec5e15a6146f7495299034", "best_bid": "0.912", "best_ask": "0.96"}, {"asset_id": "100074770378634056601572485653252702850363676459996771990439989989293515601975", "price": "0.09", "size": "0", "side": "SELL", "hash": "b3ab5ca8a86c3d1125f788ae96c4a2ae2a0ffebe", "best_bid": "0.04", "best_ask": "0.088"}], "timestamp": "1769384513715", "event_type": "price_change"}}
{"_local_timestamp": "2026-01-25T23:41:54.232659+00:00", "data": {"market": "0x9472be65457510b7fc3477b20ba90910e99d92eac8421a14bf4b7b7a08ef31dc", "price_changes": [{"asset_id": "43311793366960417907757893276427136943959788721376762326430771171648759300146", "price": "0.67", "size": "0", "side": "BUY", "hash": "56c121ceea0ae7b7c664a529ca20ec721378f46c", "best_bid": "0.995", "best_ask": "0.998"}, {"asset_id": "73414222381656326204771753454630063673548497164758947581648273905027617570612", "price": "0.33", "size": "0", "side": "SELL", "hash": "0f0429ae4161efbada4368b47032357424fe2a00", "best_bid": "0.002", "best_ask": "0.005"}], "timestamp": "1769384514169", "event_type": "price_change"}}
{"_local_timestamp": "2026-01-25T23:41:54.444366+00:00", "data": {"market": "0x2393ed0b0fdc450054c7b9071907eca75cf4fc36e385adf4a0a5f99ee62243e8", "price_changes": [{"asset_id": "32769749367306925959219403371425714180265458150646381231272229429098460625924", "price": "0.911", "size": "0", "side": "BUY", "hash": "7bda8c27094b82cef74d2a7fae724d86a22147ab", "best_bid": "0.912", "best_ask": "0.96"}, {"asset_id": "100074770378634056601572485653252702850363676459996771990439989989293515601975", "price": "0.089", "size": "0", "side": "SELL", "hash": "41d688b6c20a8283442f71c1a9f01b86aa50ca33", "best_bid": "0.04", "best_ask": "0.088"}], "timestamp": "1769384514367", "event_type": "price_change"}}
{"_local_timestamp": "2026-01-25T23:41:54.481525+00:00", "data": {"market": "0x9472be65457510b7fc3477b20ba90910e99d92eac8421a14bf4b7b7a08ef31dc", "price_changes": [{"asset_id": "43311793366960417907757893276427136943959788721376762326430771171648759300146", "price": "0.67", "size": "5", "side": "BUY", "hash": "ad158eba57000317021a2a5cfa36f3fa5d567e65", "best_bid": "0.995", "best_ask": "0.998"}, {"asset_id": "73414222381656326204771753454630063673548497164758947581648273905027617570612", "price": "0.33", "size": "5", "side": "SELL", "hash": "a48f052a1c60ae8d031c6d4cf23c6f7ee66f234c", "best_bid": "0.002", "best_ask": "0.005"}], "timestamp": "1769384514410", "event_type": "price_change"}}
{"_local_timestamp": "2026-01-25T23:41:55.873349+00:00", "data": {"market": "0x2393ed0b0fdc450054c7b9071907eca75cf4fc36e385adf4a0a5f99ee62243e8", "price_changes": [{"asset_id": "32769749367306925959219403371425714180265458150646381231272229429098460625924", "price": "0.913", "size": "37.81", "side": "BUY", "hash": "04a6a6aad6628f4d68e306828f42bbcd0b226c9d", "best_bid": "0.913", "best_ask": "0.96"}, {"asset_id": "100074770378634056601572485653252702850363676459996771990439989989293515601975", "price": "0.087", "size": "37.81", "side": "SELL", "hash": "b52b8981200f3c12b936ff8269cc5d6950cab550", "best_bid": "0.04", "best_ask": "0.087"}], "timestamp": "1769384515806", "event_type": "price_change"}}
{"_local_timestamp": "2026-01-25T23:41:56.446700+00:00", "data": {"market": "0x9472be65457510b7fc3477b20ba90910e99d92eac8421a14bf4b7b7a08ef31dc", "price_changes": [{"asset_id": "43311793366960417907757893276427136943959788721376762326430771171648759300146", "price": "0.67", "size": "0", "side": "BUY", "hash": "aa4d607dd5ae7843e7399def1c89cb19ee6be61b", "best_bid": "0.995", "best_ask": "0.998"}, {"asset_id": "73414222381656326204771753454630063673548497164758947581648273905027617570612", "price": "0.33", "size": "0", "side": "SELL", "hash": "f7e6f80bc45feea97a2f271a79f837bf41066940", "best_bid": "0.002", "best_ask": "0.005"}], "timestamp": "1769384516372", "event_type": "price_change"}}
{"_local_timestamp": "2026-01-25T23:41:56.836489+00:00", "data": {"market": "0x9472be65457510b7fc3477b20ba90910e99d92eac8421a14bf4b7b7a08ef31dc", "price_changes": [{"asset_id": "43311793366960417907757893276427136943959788721376762326430771171648759300146", "price": "0.67", "size": "5", "side": "BUY", "hash": "a8bcd448d772bbd67c1e22c2d561597c496a03be", "best_bid": "0.995", "best_ask": "0.998"}, {"asset_id": "73414222381656326204771753454630063673548497164758947581648273905027617570612", "price": "0.33", "size": "5", "side": "SELL", "hash": "18b6eb9bbc006acd5689e16e09ce8ae95a6ee3dc", "best_bid": "0.002", "best_ask": "0.005"}], "timestamp": "1769384516766", "event_type": "price_change"}}
{"_local_timestamp": "2026-01-25T23:41:59.477135+00:00", "data": {"market": "0x2393ed0b0fdc450054c7b9071907eca75cf4fc36e385adf4a0a5f99ee62243e8", "price_changes": [{"asset_id": "32769749367306925959219403371425714180265458150646381231272229429098460625924", "price": "0.914", "size": "50", "side": "BUY", "hash": "b5e9b1fe3dc8dc8fbda3447bbd0ab8b4dc2e12ff", "best_bid": "0.914", "best_ask": "0.96"}, {"asset_id": "100074770378634056601572485653252702850363676459996771990439989989293515601975", "price": "0.086", "size": "50", "side": "SELL", "hash": "1941a1f4c5d46fe372440f3f9830dd14eadba590", "best_bid": "0.04", "best_ask": "0.086"}], "timestamp": "1769384519402", "event_type": "price_change"}}
{"_local_timestamp": "2026-01-25T23:41:59.781206+00:00", "data": {"market": "0x2393ed0b0fdc450054c7b9071907eca75cf4fc36e385adf4a0a5f99ee62243e8", "price_changes": [{"asset_id": "32769749367306925959219403371425714180265458150646381231272229429098460625924", "price": "0.912", "size": "0", "side": "BUY", "hash": "2caf71b6acd170c6395402391e79eac51a1dd237", "best_bid": "0.914", "best_ask": "0.96"}, {"asset_id": "100074770378634056601572485653252702850363676459996771990439989989293515601975", "price": "0.088", "size": "0", "side": "SELL", "hash": "4c79cae6e3830bbbe78a1363e84afa46048e2d6f", "best_bid": "0.04", "best_ask": "0.086"}], "timestamp": "1769384519710", "event_type": "price_change"}}
{"_local_timestamp": "2026-01-25T23:41:59.896958+00:00", "data": {"market": "0x9472be65457510b7fc3477b20ba90910e99d92eac8421a14bf4b7b7a08ef31dc", "price_changes": [{"asset_id": "43311793366960417907757893276427136943959788721376762326430771171648759300146", "price": "0.67", "size": "0", "side": "BUY", "hash": "a0967f7b5b2613582890ebc3a12d452ada41088e", "best_bid": "0.995", "best_ask": "0.998"}, {"asset_id": "73414222381656326204771753454630063673548497164758947581648273905027617570612", "price": "0.33", "size": "0", "side": "SELL", "hash": "6601be778bd8ee6bb3b3b843f2d17bfe2bb8872d", "best_bid": "0.002", "best_ask": "0.005"}], "timestamp": "1769384519825", "event_type": "price_change"}}
{"_local_timestamp": "2026-01-25T23:42:00.170650+00:00", "data": {"market": "0x2393ed0b0fdc450054c7b9071907eca75cf4fc36e385adf4a0a5f99ee62243e8", "price_changes": [{"asset_id": "32769749367306925959219403371425714180265458150646381231272229429098460625924", "price": "0.913", "size": "0", "side": "BUY", "hash": "a9861c9bd2074e1a96fc606a7d8a9e83ae347f84", "best_bid": "0.914", "best_ask": "0.96"}, {"asset_id": "100074770378634056601572485653252702850363676459996771990439989989293515601975", "price": "0.087", "size": "0", "side": "SELL", "hash": "c88f57ee6efcee0df012d4225ef74f55c3c81423", "best_bid": "0.04", "best_ask": "0.086"}], "timestamp": "1769384520098", "event_type": "price_change"}}
{"_local_timestamp": "2026-01-25T23:42:00.246557+00:00", "data": {"market": "0x9472be65457510b7fc3477b20ba90910e99d92eac8421a14bf4b7b7a08ef31dc", "price_changes": [{"asset_id": "43311793366960417907757893276427136943959788721376762326430771171648759300146", "price": "0.67", "size": "5", "side": "BUY", "hash": "07c14521ccd02191e555c3c727b13d40f5b1bf27", "best_bid": "0.995", "best_ask": "0.998"}, {"asset_id": "73414222381656326204771753454630063673548497164758947581648273905027617570612", "price": "0.33", "size": "5", "side": "SELL", "hash": "38ce1bbe50e833425af3b95342e35198b4e20c5a", "best_bid": "0.002", "best_ask": "0.005"}], "timestamp": "1769384520170", "event_type": "price_change"}}
{"_local_timestamp": "2026-01-25T23:42:01.584704+00:00", "data": {"market": "0x2393ed0b0fdc450054c7b9071907eca75cf4fc36e385adf4a0a5f99ee62243e8", "price_changes": [{"asset_id": "32769749367306925959219403371425714180265458150646381231272229429098460625924", "price": "0.915", "size": "37.81", "side": "BUY", "hash": "b5d1db8dbb38f0e50489e249323f71e9ddfb8df0", "best_bid": "0.915", "best_ask": "0.96"}, {"asset_id": "100074770378634056601572485653252702850363676459996771990439989989293515601975", "price": "0.085", "size": "37.81", "side": "SELL", "hash": "cd8c181325865523aa3bfd2d14898e12c403c241", "best_bid": "0.04", "best_ask": "0.085"}], "timestamp": "1769384521517", "event_type": "price_change"}}
{"_local_timestamp": "2026-01-25T23:42:03.144973+00:00", "data": {"market": "0x9472be65457510b7fc3477b20ba90910e99d92eac8421a14bf4b7b7a08ef31dc", "price_changes": [{"asset_id": "43311793366960417907757893276427136943959788721376762326430771171648759300146", "price": "0.67", "size": "0", "side": "BUY", "hash": "b670bcea8daf34f8b361210c9ad21f7360af55cd", "best_bid": "0.995", "best_ask": "0.998"}, {"asset_id": "73414222381656326204771753454630063673548497164758947581648273905027617570612", "price": "0.33", "size": "0", "side": "SELL", "hash": "b2cafa7d88f5106db1e2428ab23cb176ad73e9c0", "best_bid": "0.002", "best_ask": "0.005"}], "timestamp": "1769384523053", "event_type": "price_change"}}
{"_local_timestamp": "2026-01-25T23:42:03.402620+00:00", "data": {"market": "0x9472be65457510b7fc3477b20ba90910e99d92eac8421a14bf4b7b7a08ef31dc", "price_changes": [{"asset_id": "43311793366960417907757893276427136943959788721376762326430771171648759300146", "price": "0.67", "size": "5", "side": "BUY", "hash": "9a79ef59856de5ac30eb6f82fd2124cbca879e2a", "best_bid": "0.995", "best_ask": "0.998"}, {"asset_id": "73414222381656326204771753454630063673548497164758947581648273905027617570612", "price": "0.33", "size": "5", "side": "SELL", "hash": "7ab0b16f9618b26b137d02140eb30994b1abf3eb", "best_bid": "0.002", "best_ask": "0.005"}], "timestamp": "1769384523326", "event_type": "price_change"}}
{"_local_timestamp": "2026-01-25T23:42:05.286665+00:00", "data": {"market": "0x2393ed0b0fdc450054c7b9071907eca75cf4fc36e385adf4a0a5f99ee62243e8", "price_changes": [{"asset_id": "32769749367306925959219403371425714180265458150646381231272229429098460625924", "price": "0.916", "size": "50", "side": "BUY", "hash": "635c02773f3f706993fd75543c320fb9ad658a4e", "best_bid": "0.916", "best_ask": "0.96"}, {"asset_id": "100074770378634056601572485653252702850363676459996771990439989989293515601975", "price": "0.084", "size": "50", "side": "SELL", "hash": "082d4da80a2c43b6725e3cf5e3872f7642a90421", "best_bid": "0.04", "best_ask": "0.084"}], "timestamp": "1769384525209", "event_type": "price_change"}}
{"_local_timestamp": "2026-01-25T23:42:05.636173+00:00", "data": {"market": "0x2393ed0b0fdc450054c7b9071907eca75cf4fc36e385adf4a0a5f99ee62243e8", "price_changes": [{"asset_id": "32769749367306925959219403371425714180265458150646381231272229429098460625924", "price": "0.914", "size": "0", "side": "BUY", "hash": "6b32ab1d6f5636c335e11589b60ead61f5f537e0", "best_bid": "0.916", "best_ask": "0.96"}, {"asset_id": "100074770378634056601572485653252702850363676459996771990439989989293515601975", "price": "0.086", "size": "0", "side": "SELL", "hash": "96ea5e94fc5a4a8838a42eafd5a0edb9e903a3c4", "best_bid": "0.04", "best_ask": "0.084"}], "timestamp": "1769384525569", "event_type": "price_change"}}
{"_local_timestamp": "2026-01-25T23:42:05.806828+00:00", "data": {"market": "0x9472be65457510b7fc3477b20ba90910e99d92eac8421a14bf4b7b7a08ef31dc", "price_changes": [{"asset_id": "43311793366960417907757893276427136943959788721376762326430771171648759300146", "price": "0.67", "size": "0", "side": "BUY", "hash": "2d889ddb5dd33ac02791b944a2d7ce0bf339a374", "best_bid": "0.995", "best_ask": "0.998"}, {"asset_id": "73414222381656326204771753454630063673548497164758947581648273905027617570612", "price": "0.33", "size": "0", "side": "SELL", "hash": "8cfd69245028dd0ede0f52350e22d08fd97052d2", "best_bid": "0.002", "best_ask": "0.005"}], "timestamp": "1769384525739", "event_type": "price_change"}}
{"_local_timestamp": "2026-01-25T23:42:06.287072+00:00", "data": {"market": "0x9472be65457510b7fc3477b20ba90910e99d92eac8421a14bf4b7b7a08ef31dc", "price_changes": [{"asset_id": "43311793366960417907757893276427136943959788721376762326430771171648759300146", "price": "0.67", "size": "5", "side": "BUY", "hash": "c55097476f107583b53935129f2da57d2880d32e", "best_bid": "0.995", "best_ask": "0.998"}, {"asset_id": "73414222381656326204771753454630063673548497164758947581648273905027617570612", "price": "0.33", "size": "5", "side": "SELL", "hash": "9660a02f4ae29fd44a6fcd40a8c5add9477bbe50", "best_bid": "0.002", "best_ask": "0.005"}], "timestamp": "1769384526222", "event_type": "price_change"}}
{"_local_timestamp": "2026-01-25T23:42:06.928179+00:00", "data": {"market": "0x2393ed0b0fdc450054c7b9071907eca75cf4fc36e385adf4a0a5f99ee62243e8", "price_changes": [{"asset_id": "32769749367306925959219403371425714180265458150646381231272229429098460625924", "price": "0.915", "size": "0", "side": "BUY", "hash": "7a31bb595fa0d17dd1c463c37477e0d39e3a9c08", "best_bid": "0.916", "best_ask": "0.96"}, {"asset_id": "100074770378634056601572485653252702850363676459996771990439989989293515601975", "price": "0.085", "size": "0", "side": "SELL", "hash": "97bc1113c21663ce6aa2c5b9580a43413a0da097", "best_bid": "0.04", "best_ask": "0.084"}], "timestamp": "1769384526859", "event_type": "price_change"}}
{"_local_timestamp": "2026-01-25T23:42:08.090982+00:00", "data": {"market": "0x9472be65457510b7fc3477b20ba90910e99d92eac8421a14bf4b7b7a08ef31dc", "price_changes": [{"asset_id": "43311793366960417907757893276427136943959788721376762326430771171648759300146", "price": "0.67", "size": "0", "side": "BUY", "hash": "cdc00c62f2404728782bc1fed3d27fcff8984c33", "best_bid": "0.995", "best_ask": "0.998"}, {"asset_id": "73414222381656326204771753454630063673548497164758947581648273905027617570612", "price": "0.33", "size": "0", "side": "SELL", "hash": "439d571292f67f5978add455de4865f7473cfb56", "best_bid": "0.002", "best_ask": "0.005"}], "timestamp": "1769384528022", "event_type": "price_change"}}
{"_local_timestamp": "2026-01-25T23:42:08.426934+00:00", "data": {"market": "0x9472be65457510b7fc3477b20ba90910e99d92eac8421a14bf4b7b7a08ef31dc", "price_changes": [{"asset_id": "43311793366960417907757893276427136943959788721376762326430771171648759300146", "price": "0.67", "size": "5", "side": "BUY", "hash": "9835c0cb0bd9f51834a816a60a0cc9bb414c2995", "best_bid": "0.995", "best_ask": "0.998"}, {"asset_id": "73414222381656326204771753454630063673548497164758947581648273905027617570612", "price": "0.33", "size": "5", "side": "SELL", "hash": "c6d9ed849707eb49977d9ed71d6dd9dbb3e66581", "best_bid": "0.002", "best_ask": "0.005"}], "timestamp": "1769384528357", "event_type": "price_change"}}
{"_local_timestamp": "2026-01-25T23:42:08.549340+00:00", "data": {"market": "0x2393ed0b0fdc450054c7b9071907eca75cf4fc36e385adf4a0a5f99ee62243e8", "price_changes": [{"asset_id": "32769749367306925959219403371425714180265458150646381231272229429098460625924", "price": "0.917", "size": "37.81", "side": "BUY", "hash": "e15694508eca116f2a51bfcdffbb41ec4727ecac", "best_bid": "0.917", "best_ask": "0.96"}, {"asset_id": "100074770378634056601572485653252702850363676459996771990439989989293515601975", "price": "0.083", "size": "37.81", "side": "SELL", "hash": "91dd7991c07e5ff25a7c992585aab98ebfb9693d", "best_bid": "0.04", "best_ask": "0.083"}], "timestamp": "1769384528478", "event_type": "price_change"}}
{"_local_timestamp": "2026-01-25T23:42:11.124672+00:00", "data": {"market": "0x9472be65457510b7fc3477b20ba90910e99d92eac8421a14bf4b7b7a08ef31dc", "price_changes": [{"asset_id": "43311793366960417907757893276427136943959788721376762326430771171648759300146", "price": "0.67", "size": "0", "side": "BUY", "hash": "e36fa3bddfd6effd92cb9de11b577632d974532f", "best_bid": "0.995", "best_ask": "0.998"}, {"asset_id": "73414222381656326204771753454630063673548497164758947581648273905027617570612", "price": "0.33", "size": "0", "side": "SELL", "hash": "52980fe4de1f31db59b44b8943abe992cd354fb8", "best_bid": "0.002", "best_ask": "0.005"}], "timestamp": "1769384531051", "event_type": "price_change"}}
{"_local_timestamp": "2026-01-25T23:42:11.200493+00:00", "data": {"market": "0xaf9d0e448129a9f657f851d49495ba4742055d80e0ef1166ba0ee81d4d594214", "price_changes": [{"asset_id": "4153292802911610701832309484716814274802943278345248636922528170020319407796", "price": "0.888", "size": "0", "side": "BUY", "hash": "5dc6d3fe5b72fd9398fa5681b34caad7a4cb1e0d", "best_bid": "0.936", "best_ask": "0.988"}, {"asset_id": "101676997363687199724245607342877036148401850938023978421879460310389391082353", "price": "0.112", "size": "0", "side": "SELL", "hash": "5b7d0a2e62503144ab7852a2baab287bdb0d0437", "best_bid": "0.012", "best_ask": "0.064"}], "timestamp": "1769384531128", "event_type": "price_change"}}
{"_local_timestamp": "2026-01-25T23:42:11.255133+00:00", "data": {"market": "0x2393ed0b0fdc450054c7b9071907eca75cf4fc36e385adf4a0a5f99ee62243e8", "price_changes": [{"asset_id": "32769749367306925959219403371425714180265458150646381231272229429098460625924", "price": "0.896", "size": "50", "side": "BUY", "hash": "af8d96c2e82a60c2a0ba9a191165ccb579b46772", "best_bid": "0.917", "best_ask": "0.96"}, {"asset_id": "100074770378634056601572485653252702850363676459996771990439989989293515601975", "price": "0.104", "size": "50", "side": "SELL", "hash": "04a39efb093ccba9e3391fb464c7d94aa97da1b4", "best_bid": "0.04", "best_ask": "0.083"}], "timestamp": "1769384531188", "event_type": "price_change"}}
{"_local_timestamp": "2026-01-25T23:42:11.350910+00:00", "data": {"market": "0x9472be65457510b7fc3477b20ba90910e99d92eac8421a14bf4b7b7a08ef31dc", "price_changes": [{"asset_id": "43311793366960417907757893276427136943959788721376762326430771171648759300146", "price": "0.67", "size": "5", "side": "BUY", "hash": "fb62e2eae78e4104887814233b588a45ede0cc4f", "best_bid": "0.995", "best_ask": "0.998"}, {"asset_id": "73414222381656326204771753454630063673548497164758947581648273905027617570612", "price": "0.33", "size": "5", "side": "SELL", "hash": "6e7ad85fc364deea3dd88de67d54ed6a22014405", "best_bid": "0.002", "best_ask": "0.005"}], "timestamp": "1769384531280", "event_type": "price_change"}}
{"_local_timestamp": "2026-01-25T23:42:11.361536+00:00", "data": {"market": "0xaf9d0e448129a9f657f851d49495ba4742055d80e0ef1166ba0ee81d4d594214", "price_changes": [{"asset_id": "4153292802911610701832309484716814274802943278345248636922528170020319407796", "price": "0.888", "size": "30", "side": "BUY", "hash": "7da1b910f4947f329f0580ea6ee9e28a04231a51", "best_bid": "0.936", "best_ask": "0.988"}, {"asset_id": "101676997363687199724245607342877036148401850938023978421879460310389391082353", "price": "0.112", "size": "30", "side": "SELL", "hash": "477654f5c51db6b4091ec6a777bf1512698ea546", "best_bid": "0.012", "best_ask": "0.064"}], "timestamp": "1769384531294", "event_type": "price_change"}}
{"_local_timestamp": "2026-01-25T23:42:11.590901+00:00", "data": {"market": "0x2393ed0b0fdc450054c7b9071907eca75cf4fc36e385adf4a0a5f99ee62243e8", "price_changes": [{"asset_id": "32769749367306925959219403371425714180265458150646381231272229429098460625924", "price": "0.916", "size": "0", "side": "BUY", "hash": "7fd52f9c632c646091b824f02ad7b33be9c01411", "best_bid": "0.917", "best_ask": "0.96"}, {"asset_id": "100074770378634056601572485653252702850363676459996771990439989989293515601975", "price": "0.084", "size": "0", "side": "SELL", "hash": "01962ffb17638e9051efb9e65c71681081163d20", "best_bid": "0.04", "best_ask": "0.083"}], "timestamp": "1769384531521", "event_type": "price_change"}}
{"_local_timestamp": "2026-01-25T23:42:12.403814+00:00", "data": {"market": "0x2393ed0b0fdc450054c7b9071907eca75cf4fc36e385adf4a0a5f99ee62243e8", "price_changes": [{"asset_id": "32769749367306925959219403371425714180265458150646381231272229429098460625924", "price": "0.917", "size": "0", "side": "BUY", "hash": "544daf63bb6985353720840e5be98175128ef48d", "best_bid": "0.906", "best_ask": "0.96"}, {"asset_id": "100074770378634056601572485653252702850363676459996771990439989989293515601975", "price": "0.083", "size": "0", "side": "SELL", "hash": "1c9f5aa37cc4aff06993dc9567a66255e0b77e34", "best_bid": "0.04", "best_ask": "0.094"}], "timestamp": "1769384532336", "event_type": "price_change"}}
{"_local_timestamp": "2026-01-25T23:42:13.112567+00:00", "data": {"market": "0x9472be65457510b7fc3477b20ba90910e99d92eac8421a14bf4b7b7a08ef31dc", "price_changes": [{"asset_id": "43311793366960417907757893276427136943959788721376762326430771171648759300146", "price": "0.67", "size": "0", "side": "BUY", "hash": "5594debbe38a5ecc5b6a4f7b5482f0019c6287dc", "best_bid": "0.995", "best_ask": "0.998"}, {"asset_id": "73414222381656326204771753454630063673548497164758947581648273905027617570612", "price": "0.33", "size": "0", "side": "SELL", "hash": "2c1953a21ffe5e275b3426982925c1ca9d208187", "best_bid": "0.002", "best_ask": "0.005"}], "timestamp": "1769384533016", "event_type": "price_change"}}
{"_local_timestamp": "2026-01-25T23:42:13.331134+00:00", "data": {"market": "0x2393ed0b0fdc450054c7b9071907eca75cf4fc36e385adf4a0a5f99ee62243e8", "price_changes": [{"asset_id": "32769749367306925959219403371425714180265458150646381231272229429098460625924", "price": "0.897", "size": "37.81", "side": "BUY", "hash": "c06860cf7bdf25f4bc1ace4e2422baa4d3934214", "best_bid": "0.906", "best_ask": "0.96"}, {"asset_id": "100074770378634056601572485653252702850363676459996771990439989989293515601975", "price": "0.103", "size": "37.81", "side": "SELL", "hash": "c5f1de75a48c752145a19a1d729c454fbb63d3cc", "best_bid": "0.04", "best_ask": "0.094"}], "timestamp": "1769384533263", "event_type": "price_change"}}
{"_local_timestamp": "2026-01-25T23:42:13.417797+00:00", "data": {"market": "0x9472be65457510b7fc3477b20ba90910e99d92eac8421a14bf4b7b7a08ef31dc", "price_changes": [{"asset_id": "43311793366960417907757893276427136943959788721376762326430771171648759300146", "price": "0.67", "size": "5", "side": "BUY", "hash": "a422845af04de7b27e84c6b732060462f765181d", "best_bid": "0.995", "best_ask": "0.998"}, {"asset_id": "73414222381656326204771753454630063673548497164758947581648273905027617570612", "price": "0.33", "size": "5", "side": "SELL", "hash": "b00c1f7a5d1a93f8f0469701c074ede7effcae7d", "best_bid": "0.002", "best_ask": "0.005"}], "timestamp": "1769384533346", "event_type": "price_change"}}
{"_local_timestamp": "2026-01-25T23:42:15.762736+00:00", "data": {"market": "0x9472be65457510b7fc3477b20ba90910e99d92eac8421a14bf4b7b7a08ef31dc", "price_changes": [{"asset_id": "43311793366960417907757893276427136943959788721376762326430771171648759300146", "price": "0.67", "size": "0", "side": "BUY", "hash": "69ae38c41d642b5cd90c571a32fd535f025e7bfc", "best_bid": "0.995", "best_ask": "0.998"}, {"asset_id": "73414222381656326204771753454630063673548497164758947581648273905027617570612", "price": "0.33", "size": "0", "side": "SELL", "hash": "c26c35f48ace6c000f5de62b8229c227455ae875", "best_bid": "0.002", "best_ask": "0.005"}], "timestamp": "1769384535655", "event_type": "price_change"}}
{"_local_timestamp": "2026-01-25T23:42:16.181740+00:00", "data": {"market": "0x9472be65457510b7fc3477b20ba90910e99d92eac8421a14bf4b7b7a08ef31dc", "price_changes": [{"asset_id": "43311793366960417907757893276427136943959788721376762326430771171648759300146", "price": "0.67", "size": "5", "side": "BUY", "hash": "c349d3e30f8a56872480783786fd964feff30004", "best_bid": "0.995", "best_ask": "0.998"}, {"asset_id": "73414222381656326204771753454630063673548497164758947581648273905027617570612", "price": "0.33", "size": "5", "side": "SELL", "hash": "f1fe5ce3d486a7befe2dfcf4cdf989108d821f9e", "best_bid": "0.002", "best_ask": "0.005"}], "timestamp": "1769384536067", "event_type": "price_change"}}
{"_local_timestamp": "2026-01-25T23:42:17.343832+00:00", "data": {"market": "0x2393ed0b0fdc450054c7b9071907eca75cf4fc36e385adf4a0a5f99ee62243e8", "price_changes": [{"asset_id": "32769749367306925959219403371425714180265458150646381231272229429098460625924", "price": "0.898", "size": "50", "side": "BUY", "hash": "0515cd8ea96cf5ae89b85490e39f29a7dcd9fa8e", "best_bid": "0.906", "best_ask": "0.96"}, {"asset_id": "100074770378634056601572485653252702850363676459996771990439989989293515601975", "price": "0.102", "size": "50", "side": "SELL", "hash": "8b018eb419b5745fa6a45bc4763a652898a06ee3", "best_bid": "0.04", "best_ask": "0.094"}], "timestamp": "1769384537256", "event_type": "price_change"}}
{"_local_timestamp": "2026-01-25T23:42:17.564413+00:00", "data": {"market": "0x9472be65457510b7fc3477b20ba90910e99d92eac8421a14bf4b7b7a08ef31dc", "price_changes": [{"asset_id": "43311793366960417907757893276427136943959788721376762326430771171648759300146", "price": "0.67", "size": "0", "side": "BUY", "hash": "0e8fb29431f3ed49d5a879816a4cd36f0ca1c351", "best_bid": "0.995", "best_ask": "0.998"}, {"asset_id": "73414222381656326204771753454630063673548497164758947581648273905027617570612", "price": "0.33", "size": "0", "side": "SELL", "hash": "b8ee751ea6f9ad60794fb369fdaede20624658d7", "best_bid": "0.002", "best_ask": "0.005"}], "timestamp": "1769384537478", "event_type": "price_change"}}
{"_local_timestamp": "2026-01-25T23:42:17.671374+00:00", "data": {"market": "0x2393ed0b0fdc450054c7b9071907eca75cf4fc36e385adf4a0a5f99ee62243e8", "price_changes": [{"asset_id": "32769749367306925959219403371425714180265458150646381231272229429098460625924", "price": "0.896", "size": "0", "side": "BUY", "hash": "427dc6ae5db58bcf8d3d7eeba3a96df0ac91df41", "best_bid": "0.906", "best_ask": "0.96"}, {"asset_id": "100074770378634056601572485653252702850363676459996771990439989989293515601975", "price": "0.104", "size": "0", "side": "SELL", "hash": "c188b19dec5bcd59959a102d63a173739a53e305", "best_bid": "0.04", "best_ask": "0.094"}], "timestamp": "1769384537583", "event_type": "price_change"}}
{"_local_timestamp": "2026-01-25T23:42:18.012550+00:00", "data": {"market": "0x9472be65457510b7fc3477b20ba90910e99d92eac8421a14bf4b7b7a08ef31dc", "price_changes": [{"asset_id": "43311793366960417907757893276427136943959788721376762326430771171648759300146", "price": "0.67", "size": "5", "side": "BUY", "hash": "ddc1e30cf8f7f2366268c25048c9221bc1eb86e2", "best_bid": "0.995", "best_ask": "0.998"}, {"asset_id": "73414222381656326204771753454630063673548497164758947581648273905027617570612", "price": "0.33", "size": "5", "side": "SELL", "hash": "a7e30fdf2ed13605f2535cc70c2c3d835053f60d", "best_bid": "0.002", "best_ask": "0.005"}], "timestamp": "1769384537908", "event_type": "price_change"}}
{"_local_timestamp": "2026-01-25T23:42:18.095549+00:00", "data": {"market": "0x2393ed0b0fdc450054c7b9071907eca75cf4fc36e385adf4a0a5f99ee62243e8", "price_changes": [{"asset_id": "32769749367306925959219403371425714180265458150646381231272229429098460625924", "price": "0.897", "size": "0", "side": "BUY", "hash": "930fea49b671b5f28cee6a5f07a416b5a8356ed8", "best_bid": "0.906", "best_ask": "0.96"}, {"asset_id": "100074770378634056601572485653252702850363676459996771990439989989293515601975", "price": "0.103", "size": "0", "side": "SELL", "hash": "ca7d2b233cb52b2d0ea93844d38950b0241c02c2", "best_bid": "0.04", "best_ask": "0.094"}], "timestamp": "1769384537985", "event_type": "price_change"}}
{"_local_timestamp": "2026-01-25T23:42:18.834355+00:00", "data": {"market": "0x2393ed0b0fdc450054c7b9071907eca75cf4fc36e385adf4a0a5f99ee62243e8", "price_changes": [{"asset_id": "32769749367306925959219403371425714180265458150646381231272229429098460625924", "price": "0.899", "size": "37.81", "side": "BUY", "hash": "46ed515d98d24573ab369a3bd0396c3272620063", "best_bid": "0.906", "best_ask": "0.96"}, {"asset_id": "100074770378634056601572485653252702850363676459996771990439989989293515601975", "price": "0.101", "size": "37.81", "side": "SELL", "hash": "339ef6f81fcadbe47db6a0cf3212579ec0ec3a1d", "best_bid": "0.04", "best_ask": "0.094"}], "timestamp": "1769384538725", "event_type": "price_change"}}
{"_local_timestamp": "2026-01-25T23:42:21.530098+00:00", "data": {"market": "0x9472be65457510b7fc3477b20ba90910e99d92eac8421a14bf4b7b7a08ef31dc", "price_changes": [{"asset_id": "43311793366960417907757893276427136943959788721376762326430771171648759300146", "price": "0.67", "size": "0", "side": "BUY", "hash": "8c22a2f93d7fdf70f2b64a25ae8c47eece65becf", "best_bid": "0.995", "best_ask": "0.998"}, {"asset_id": "73414222381656326204771753454630063673548497164758947581648273905027617570612", "price": "0.33", "size": "0", "side": "SELL", "hash": "63bf8515a9175d2d66d42bdf97b5309af3657ca8", "best_bid": "0.002", "best_ask": "0.005"}], "timestamp": "1769384541368", "event_type": "price_change"}}
{"_local_timestamp": "2026-01-25T23:42:21.870110+00:00", "data": {"market": "0x9472be65457510b7fc3477b20ba90910e99d92eac8421a14bf4b7b7a08ef31dc", "price_changes": [{"asset_id": "43311793366960417907757893276427136943959788721376762326430771171648759300146", "price": "0.67", "size": "5", "side": "BUY", "hash": "31c502334697bde5fc1d216f074767faa51c1168", "best_bid": "0.995", "best_ask": "0.998"}, {"asset_id": "73414222381656326204771753454630063673548497164758947581648273905027617570612", "price": "0.33", "size": "5", "side": "SELL", "hash": "414646b25bf45372e8af5713b831ffec08fbf60f", "best_bid": "0.002", "best_ask": "0.005"}], "timestamp": "1769384541694", "event_type": "price_change"}}
{"_local_timestamp": "2026-01-25T23:42:23.523267+00:00", "data": {"market": "0x2393ed0b0fdc450054c7b9071907eca75cf4fc36e385adf4a0a5f99ee62243e8", "price_changes": [{"asset_id": "32769749367306925959219403371425714180265458150646381231272229429098460625924", "price": "0.9", "size": "50", "side": "BUY", "hash": "f7a5cfef5d11da444c19791dfc2f21afa1ff9b91", "best_bid": "0.906", "best_ask": "0.96"}, {"asset_id": "100074770378634056601572485653252702850363676459996771990439989989293515601975", "price": "0.1", "size": "50", "side": "SELL", "hash": "e18207b5a8b425deef152b72aadd22aa9ee602db", "best_bid": "0.04", "best_ask": "0.094"}], "timestamp": "1769384543362", "event_type": "price_change"}}
{"_local_timestamp": "2026-01-25T23:42:23.870475+00:00", "data": {"market": "0x2393ed0b0fdc450054c7b9071907eca75cf4fc36e385adf4a0a5f99ee62243e8", "price_changes": [{"asset_id": "32769749367306925959219403371425714180265458150646381231272229429098460625924", "price": "0.898", "size": "0", "side": "BUY", "hash": "73ca3bcf7a007d44c17fdd9f0b3d7c29fc1f2a71", "best_bid": "0.906", "best_ask": "0.96"}, {"asset_id": "100074770378634056601572485653252702850363676459996771990439989989293515601975", "price": "0.102", "size": "0", "side": "SELL", "hash": "6d642c667785298ddca165241e111390613991ae", "best_bid": "0.04", "best_ask": "0.094"}], "timestamp": "1769384543696", "event_type": "price_change"}}
{"_local_timestamp": "2026-01-25T23:42:24.370532+00:00", "data": {"market": "0x2393ed0b0fdc450054c7b9071907eca75cf4fc36e385adf4a0a5f99ee62243e8", "price_changes": [{"asset_id": "32769749367306925959219403371425714180265458150646381231272229429098460625924", "price": "0.899", "size": "0", "side": "BUY", "hash": "2d20804307bd7a8ee13510b7e718114d4d907547", "best_bid": "0.906", "best_ask": "0.96"}, {"asset_id": "100074770378634056601572485653252702850363676459996771990439989989293515601975", "price": "0.101", "size": "0", "side": "SELL", "hash": "3b53b1b5fa44f1ee8731a37491a00b0b036e89bd", "best_bid": "0.04", "best_ask": "0.094"}], "timestamp": "1769384544204", "event_type": "price_change"}}
{"_local_timestamp": "2026-01-25T23:42:25.280512+00:00", "data": {"market": "0x2393ed0b0fdc450054c7b9071907eca75cf4fc36e385adf4a0a5f99ee62243e8", "price_changes": [{"asset_id": "32769749367306925959219403371425714180265458150646381231272229429098460625924", "price": "0.901", "size": "37.81", "side": "BUY", "hash": "66ffce9087e53b5bb749541902925977e6068060", "best_bid": "0.906", "best_ask": "0.96"}, {"asset_id": "100074770378634056601572485653252702850363676459996771990439989989293515601975", "price": "0.099", "size": "37.81", "side": "SELL", "hash": "857518531a4776836e3b8c6124bfacd8690384f4", "best_bid": "0.04", "best_ask": "0.094"}], "timestamp": "1769384545090", "event_type": "price_change"}}
{"_local_timestamp": "2026-01-25T23:42:27.286829+00:00", "data": {"market": "0xaf9d0e448129a9f657f851d49495ba4742055d80e0ef1166ba0ee81d4d594214", "price_changes": [{"asset_id": "101676997363687199724245607342877036148401850938023978421879460310389391082353", "price": "0.002", "size": "11611", "side": "BUY", "hash": "10f077733b624e0554db93da81f5b23ae169c0c4", "best_bid": "0.012", "best_ask": "0.064"}, {"asset_id": "4153292802911610701832309484716814274802943278345248636922528170020319407796", "price": "0.998", "size": "11611", "side": "SELL", "hash": "34498a5e3014bf83bf38fa790d77469854acfe0d", "best_bid": "0.936", "best_ask": "0.988"}], "timestamp": "1769384547084", "event_type": "price_change"}}
{"_local_timestamp": "2026-01-25T23:42:27.289532+00:00", "data": {"market": "0xaf9d0e448129a9f657f851d49495ba4742055d80e0ef1166ba0ee81d4d594214", "price_changes": [{"asset_id": "101676997363687199724245607342877036148401850938023978421879460310389391082353", "price": "0.003", "size": "1012.12", "side": "BUY", "hash": "10f077733b624e0554db93da81f5b23ae169c0c4", "best_bid": "0.012", "best_ask": "0.064"}, {"asset_id": "4153292802911610701832309484716814274802943278345248636922528170020319407796", "price": "0.997", "size": "1012.12", "side": "SELL", "hash": "34498a5e3014bf83bf38fa790d77469854acfe0d", "best_bid": "0.936", "best_ask": "0.988"}], "timestamp": "1769384547084", "event_type": "price_change"}}
{"_local_timestamp": "2026-01-25T23:42:27.292109+00:00", "data": {"market": "0x9472be65457510b7fc3477b20ba90910e99d92eac8421a14bf4b7b7a08ef31dc", "price_changes": [{"asset_id": "43311793366960417907757893276427136943959788721376762326430771171648759300146", "price": "0.67", "size": "0", "side": "BUY", "hash": "a4943be83ca8bc9ce72d811af7788ff00a088926", "best_bid": "0.995", "best_ask": "0.998"}, {"asset_id": "73414222381656326204771753454630063673548497164758947581648273905027617570612", "price": "0.33", "size": "0", "side": "SELL", "hash": "05b213a1398dc55a89e006af74c1efcfe4ac7d25", "best_bid": "0.002", "best_ask": "0.005"}], "timestamp": "1769384547085", "event_type": "price_change"}}
{"_local_timestamp": "2026-01-25T23:42:27.715025+00:00", "data": {"market": "0xaf9d0e448129a9f657f851d49495ba4742055d80e0ef1166ba0ee81d4d594214", "price_changes": [{"asset_id": "101676997363687199724245607342877036148401850938023978421879460310389391082353", "price": "0.003", "size": "1030.11", "side": "BUY", "hash": "dedb8051a7f7661403876f7a223f42f08ef5a181", "best_bid": "0.012", "best_ask": "0.064"}, {"asset_id": "4153292802911610701832309484716814274802943278345248636922528170020319407796", "price": "0.997", "size": "1030.11", "side": "SELL", "hash": "8aab0356dc767ef69618c5aa983d6be2f08a40dd", "best_bid": "0.936", "best_ask": "0.988"}], "timestamp": "1769384547513", "event_type": "price_change"}}
{"_local_timestamp": "2026-01-25T23:42:27.717928+00:00", "data": {"market": "0x9472be65457510b7fc3477b20ba90910e99d92eac8421a14bf4b7b7a08ef31dc", "price_changes": [{"asset_id": "43311793366960417907757893276427136943959788721376762326430771171648759300146", "price": "0.67", "size": "5", "side": "BUY", "hash": "fdbb328b8d87aacdfce2fa83d7c6b825752942ff", "best_bid": "0.995", "best_ask": "0.998"}, {"asset_id": "73414222381656326204771753454630063673548497164758947581648273905027617570612", "price": "0.33", "size": "5", "side": "SELL", "hash": "5e5c0eceb5f8f7bb211b750a0dbb85d2d8916c98", "best_bid": "0.002", "best_ask": "0.005"}], "timestamp": "1769384547513", "event_type": "price_change"}}
{"_local_timestamp": "2026-01-25T23:42:27.720731+00:00", "data": {"market": "0xaf9d0e448129a9f657f851d49495ba4742055d80e0ef1166ba0ee81d4d594214", "price_changes": [{"asset_id": "101676997363687199724245607342877036148401850938023978421879460310389391082353", "price": "0.002", "size": "11638.12", "side": "BUY", "hash": "eb404d4ed75b48fe41e705f58892483e1ef4a53d", "best_bid": "0.012", "best_ask": "0.064"}, {"asset_id": "4153292802911610701832309484716814274802943278345248636922528170020319407796", "price": "0.998", "size": "11638.12", "side": "SELL", "hash": "bb5565f30cc212a61b34a5d64ab5bb05007a5a11", "best_bid": "0.936", "best_ask": "0.988"}], "timestamp": "1769384547517", "event_type": "price_change"}}
{"_local_timestamp": "2026-01-25T23:42:29.477345+00:00", "data": {"market": "0x2393ed0b0fdc450054c7b9071907eca75cf4fc36e385adf4a0a5f99ee62243e8", "price_changes": [{"asset_id": "32769749367306925959219403371425714180265458150646381231272229429098460625924", "price": "0.902", "size": "50", "side": "BUY", "hash": "55f6c70a38345a3300c1e056daca8994ebd638c8", "best_bid": "0.906", "best_ask": "0.96"}, {"asset_id": "100074770378634056601572485653252702850363676459996771990439989989293515601975", "price": "0.098", "size": "50", "side": "SELL", "hash": "67204490343a0afd5a4defc15452f2dd202cb003", "best_bid": "0.04", "best_ask": "0.094"}], "timestamp": "1769384549309", "event_type": "price_change"}}
{"_local_timestamp": "2026-01-25T23:42:29.859658+00:00", "data": {"market": "0x2393ed0b0fdc450054c7b9071907eca75cf4fc36e385adf4a0a5f99ee62243e8", "price_changes": [{"asset_id": "32769749367306925959219403371425714180265458150646381231272229429098460625924", "price": "0.9", "size": "0", "side": "BUY", "hash": "fdd6d4828e6a737fa0467325584ac567a4d46463", "best_bid": "0.906", "best_ask": "0.96"}, {"asset_id": "100074770378634056601572485653252702850363676459996771990439989989293515601975", "price": "0.1", "size": "0", "side": "SELL", "hash": "8cc0caf788cbdded8981d2e4c093cac9a50c91eb", "best_bid": "0.04", "best_ask": "0.094"}], "timestamp": "1769384549678", "event_type": "price_change"}}
{"_local_timestamp": "2026-01-25T23:42:30.168954+00:00", "data": {"market": "0x2393ed0b0fdc450054c7b9071907eca75cf4fc36e385adf4a0a5f99ee62243e8", "price_changes": [{"asset_id": "32769749367306925959219403371425714180265458150646381231272229429098460625924", "price": "0.901", "size": "0", "side": "BUY", "hash": "310b0f230fe6263b28cc77b29fe2106e216144e6", "best_bid": "0.906", "best_ask": "0.96"}, {"asset_id": "100074770378634056601572485653252702850363676459996771990439989989293515601975", "price": "0.099", "size": "0", "side": "SELL", "hash": "b6b9397b2424cce9fc202565d6f57c82958f929c", "best_bid": "0.04", "best_ask": "0.094"}], "timestamp": "1769384550000", "event_type": "price_change"}}
{"_local_timestamp": "2026-01-25T23:42:31.061946+00:00", "data": {"market": "0x2393ed0b0fdc450054c7b9071907eca75cf4fc36e385adf4a0a5f99ee62243e8", "price_changes": [{"asset_id": "32769749367306925959219403371425714180265458150646381231272229429098460625924", "price": "0.903", "size": "37.81", "side": "BUY", "hash": "c9f28408d957cb7caa29e3f2aae8d3d2b30f82e2", "best_bid": "0.906", "best_ask": "0.96"}, {"asset_id": "100074770378634056601572485653252702850363676459996771990439989989293515601975", "price": "0.097", "size": "37.81", "side": "SELL", "hash": "077ae5f0f29298c570308160bab7e0d841426253", "best_bid": "0.04", "best_ask": "0.094"}], "timestamp": "1769384550895", "event_type": "price_change"}}
{"_local_timestamp": "2026-01-25T23:42:32.315996+00:00", "data": {"market": "0x2393ed0b0fdc450054c7b9071907eca75cf4fc36e385adf4a0a5f99ee62243e8", "price_changes": [{"asset_id": "32769749367306925959219403371425714180265458150646381231272229429098460625924", "price": "0.906", "size": "0", "side": "BUY", "hash": "1462f0e660b22e18f6ec4080128d9ceff21650c6", "best_bid": "0.903", "best_ask": "0.96"}, {"asset_id": "100074770378634056601572485653252702850363676459996771990439989989293515601975", "price": "0.094", "size": "0", "side": "SELL", "hash": "3498469e8c8e6e64cb4718df321e3331eb6da3f9", "best_bid": "0.04", "best_ask": "0.097"}], "timestamp": "1769384552147", "event_type": "price_change"}}
{"_local_timestamp": "2026-01-25T23:42:32.616597+00:00", "data": {"market": "0x9472be65457510b7fc3477b20ba90910e99d92eac8421a14bf4b7b7a08ef31dc", "price_changes": [{"asset_id": "43311793366960417907757893276427136943959788721376762326430771171648759300146", "price": "0.67", "size": "0", "side": "BUY", "hash": "a4e402235a276979da9bf301636918811bd1f921", "best_bid": "0.995", "best_ask": "0.998"}, {"asset_id": "73414222381656326204771753454630063673548497164758947581648273905027617570612", "price": "0.33", "size": "0", "side": "SELL", "hash": "0b16bfb238b6380d50e48a6b770770bdeff6ec05", "best_bid": "0.002", "best_ask": "0.005"}], "timestamp": "1769384552455", "event_type": "price_change"}}
{"_local_timestamp": "2026-01-25T23:42:32.852920+00:00", "data": {"market": "0x2393ed0b0fdc450054c7b9071907eca75cf4fc36e385adf4a0a5f99ee62243e8", "price_changes": [{"asset_id": "32769749367306925959219403371425714180265458150646381231272229429098460625924", "price": "0.904", "size": "5", "side": "BUY", "hash": "f490b49647ea335ebd7aa1538ceb619ac17a9e8d", "best_bid": "0.904", "best_ask": "0.96"}, {"asset_id": "100074770378634056601572485653252702850363676459996771990439989989293515601975", "price": "0.096", "size": "5", "side": "SELL", "hash": "379074891b7a1fc9ba81094c3ebc18a340998f89", "best_bid": "0.04", "best_ask": "0.096"}], "timestamp": "1769384552690", "event_type": "price_change"}}
{"_local_timestamp": "2026-01-25T23:42:32.992828+00:00", "data": {"market": "0x9472be65457510b7fc3477b20ba90910e99d92eac8421a14bf4b7b7a08ef31dc", "price_changes": [{"asset_id": "43311793366960417907757893276427136943959788721376762326430771171648759300146", "price": "0.67", "size": "5", "side": "BUY", "hash": "0d8a7883f9b72b910a16995271d2cd23a4ccd916", "best_bid": "0.995", "best_ask": "0.998"}, {"asset_id": "73414222381656326204771753454630063673548497164758947581648273905027617570612", "price": "0.33", "size": "5", "side": "SELL", "hash": "5fdcf36acd9058fb1833125a288e84c05ad2c376", "best_bid": "0.002", "best_ask": "0.005"}], "timestamp": "1769384552825", "event_type": "price_change"}}
{"_local_timestamp": "2026-01-25T23:42:34.904799+00:00", "data": {"market": "0x49686d26fb712515cd5e12c23f0a1c7e10214c7faa3cb0a730aabe0c33694082", "price_changes": [{"asset_id": "30442780799048074404860985387051749017905070253466005720364298335239299761065", "price": "0.003", "size": "14.23", "side": "BUY", "hash": "374d590fe74016d303cad174afbd8ca9c8917bf4", "best_bid": "0.104", "best_ask": "0.133"}, {"asset_id": "13244681086321087932946246027856416106585284024824496763706748621681543444582", "price": "0.997", "size": "14.23", "side": "SELL", "hash": "bf936a68cf7d4d404b843f61aaf95688923357ac", "best_bid": "0.867", "best_ask": "0.896"}], "timestamp": "1769384554731", "event_type": "price_change"}}
{"_local_timestamp": "2026-01-25T23:42:34.907774+00:00", "data": {"market": "0x49686d26fb712515cd5e12c23f0a1c7e10214c7faa3cb0a730aabe0c33694082", "price_changes": [{"asset_id": "30442780799048074404860985387051749017905070253466005720364298335239299761065", "price": "0.021", "size": "0", "side": "BUY", "hash": "374d590fe74016d303cad174afbd8ca9c8917bf4", "best_bid": "0.104", "best_ask": "0.133"}, {"asset_id": "13244681086321087932946246027856416106585284024824496763706748621681543444582", "price": "0.979", "size": "0", "side": "SELL", "hash": "bf936a68cf7d4d404b843f61aaf95688923357ac", "best_bid": "0.867", "best_ask": "0.896"}], "timestamp": "1769384554731", "event_type": "price_change"}}
{"_local_timestamp": "2026-01-25T23:42:35.078873+00:00", "data": {"market": "0x49686d26fb712515cd5e12c23f0a1c7e10214c7faa3cb0a730aabe0c33694082", "price_changes": [{"asset_id": "30442780799048074404860985387051749017905070253466005720364298335239299761065", "price": "0.041", "size": "0", "side": "BUY", "hash": "eeb1dc0f1780a0da6ae6b4c22b965953e5cd629b", "best_bid": "0.104", "best_ask": "0.133"}, {"asset_id": "13244681086321087932946246027856416106585284024824496763706748621681543444582", "price": "0.959", "size": "0", "side": "SELL", "hash": "ecf03dec55359adbcda6e24102ca27978ea7bbd5", "best_bid": "0.867", "best_ask": "0.896"}], "timestamp": "1769384554887", "event_type": "price_change"}}
{"_local_timestamp": "2026-01-25T23:42:35.234496+00:00", "data": {"market": "0x49686d26fb712515cd5e12c23f0a1c7e10214c7faa3cb0a730aabe0c33694082", "price_changes": [{"asset_id": "30442780799048074404860985387051749017905070253466005720364298335239299761065", "price": "0.04", "size": "297.33", "side": "BUY", "hash": "973f227ad084f5fbf6938cdb054e59d094e58755", "best_bid": "0.104", "best_ask": "0.133"}, {"asset_id": "13244681086321087932946246027856416106585284024824496763706748621681543444582", "price": "0.96", "size": "297.33", "side": "SELL", "hash": "c091bffb3fc1a973e90cece70397a51d61167328", "best_bid": "0.867", "best_ask": "0.896"}], "timestamp": "1769384555040", "event_type": "price_change"}}
{"_local_timestamp": "2026-01-25T23:42:35.351851+00:00", "data": {"market": "0x49686d26fb712515cd5e12c23f0a1c7e10214c7faa3cb0a730aabe0c33694082", "price_changes": [{"asset_id": "30442780799048074404860985387051749017905070253466005720364298335239299761065", "price": "0.021", "size": "21.78", "side": "BUY", "hash": "a75cf342ea385765ac527dc2d2ebd278569c70a8", "best_bid": "0.104", "best_ask": "0.133"}, {"asset_id": "13244681086321087932946246027856416106585284024824496763706748621681543444582", "price": "0.979", "size": "21.78", "side": "SELL", "hash": "50b9ebca2794ba443d6342aa58eb6b93bb35327c", "best_bid": "0.867", "best_ask": "0.896"}], "timestamp": "1769384555172", "event_type": "price_change"}}
{"_local_timestamp": "2026-01-25T23:42:35.366030+00:00", "data": {"market": "0x49686d26fb712515cd5e12c23f0a1c7e10214c7faa3cb0a730aabe0c33694082", "price_changes": [{"asset_id": "30442780799048074404860985387051749017905070253466005720364298335239299761065", "price": "0.003", "size": "29.89", "side": "BUY", "hash": "7dd604230eb7ba4f481ac68e2977740eb6990163", "best_bid": "0.104", "best_ask": "0.133"}, {"asset_id": "13244681086321087932946246027856416106585284024824496763706748621681543444582", "price": "0.997", "size": "29.89", "side": "SELL", "hash": "35dc84d39a5d1d379ddf8af5231d52271b989cf0", "best_bid": "0.867", "best_ask": "0.896"}], "timestamp": "1769384555173", "event_type": "price_change"}}
{"_local_timestamp": "2026-01-25T23:42:35.504450+00:00", "data": {"market": "0x2393ed0b0fdc450054c7b9071907eca75cf4fc36e385adf4a0a5f99ee62243e8", "price_changes": [{"asset_id": "32769749367306925959219403371425714180265458150646381231272229429098460625924", "price": "0.904", "size": "55", "side": "BUY", "hash": "72fb6370189508e070f0bace1748788db11af58f", "best_bid": "0.904", "best_ask": "0.96"}, {"asset_id": "100074770378634056601572485653252702850363676459996771990439989989293515601975", "price": "0.096", "size": "55", "side": "SELL", "hash": "a570115a0ff0a5d08bbc8ca3958f5c563caf0a4c", "best_bid": "0.04", "best_ask": "0.096"}], "timestamp": "1769384555332", "event_type": "price_change"}}
{"_local_timestamp": "2026-01-25T23:42:35.841066+00:00", "data": {"market": "0x2393ed0b0fdc450054c7b9071907eca75cf4fc36e385adf4a0a5f99ee62243e8", "price_changes": [{"asset_id": "32769749367306925959219403371425714180265458150646381231272229429098460625924", "price": "0.902", "size": "0", "side": "BUY", "hash": "721fd99e47a80349974d52bc10ba0539dc5fd705", "best_bid": "0.904", "best_ask": "0.96"}, {"asset_id": "100074770378634056601572485653252702850363676459996771990439989989293515601975", "price": "0.098", "size": "0", "side": "SELL", "hash": "ecfb2dba659fc3bebd091ba28d41e1a8f7759651", "best_bid": "0.04", "best_ask": "0.096"}], "timestamp": "1769384555664", "event_type": "price_change"}}
{"_local_timestamp": "2026-01-25T23:42:36.514519+00:00", "data": {"market": "0x2393ed0b0fdc450054c7b9071907eca75cf4fc36e385adf4a0a5f99ee62243e8", "price_changes": [{"asset_id": "32769749367306925959219403371425714180265458150646381231272229429098460625924", "price": "0.903", "size": "0", "side": "BUY", "hash": "3ba2cd4d0666d2c87b30399d0f067cce741943b7", "best_bid": "0.904", "best_ask": "0.96"}, {"asset_id": "100074770378634056601572485653252702850363676459996771990439989989293515601975", "price": "0.097", "size": "0", "side": "SELL", "hash": "ec5ad76ff7ae93b5bbb9f6f448f4b1f085b6af55", "best_bid": "0.04", "best_ask": "0.096"}], "timestamp": "1769384556331", "event_type": "price_change"}}
{"_local_timestamp": "2026-01-25T23:42:37.508129+00:00", "data": {"market": "0x2393ed0b0fdc450054c7b9071907eca75cf4fc36e385adf4a0a5f99ee62243e8", "price_changes": [{"asset_id": "32769749367306925959219403371425714180265458150646381231272229429098460625924", "price": "0.905", "size": "37.81", "side": "BUY", "hash": "d6ecbf4fee42ff3cc0e25cb2ad8fc5c9311236ef", "best_bid": "0.905", "best_ask": "0.96"}, {"asset_id": "100074770378634056601572485653252702850363676459996771990439989989293515601975", "price": "0.095", "size": "37.81", "side": "SELL", "hash": "200977e7a6096947e11bedc3ed0a63dc21cd963e", "best_bid": "0.04", "best_ask": "0.095"}], "timestamp": "1769384557321", "event_type": "price_change"}}
{"_local_timestamp": "2026-01-25T23:42:39.558198+00:00", "data": {"market": "0x9472be65457510b7fc3477b20ba90910e99d92eac8421a14bf4b7b7a08ef31dc", "price_changes": [{"asset_id": "43311793366960417907757893276427136943959788721376762326430771171648759300146", "price": "0.67", "size": "0", "side": "BUY", "hash": "a5af81f4305ebca8fe318ddddda5e6fd3e93811c", "best_bid": "0.995", "best_ask": "0.998"}, {"asset_id": "73414222381656326204771753454630063673548497164758947581648273905027617570612", "price": "0.33", "size": "0", "side": "SELL", "hash": "907c4eedeb6798a823c7ad877c47a5ac20411198", "best_bid": "0.002", "best_ask": "0.005"}], "timestamp": "1769384559403", "event_type": "price_change"}}
{"_local_timestamp": "2026-01-25T23:42:40.322406+00:00", "data": {"market": "0x9472be65457510b7fc3477b20ba90910e99d92eac8421a14bf4b7b7a08ef31dc", "price_changes": [{"asset_id": "43311793366960417907757893276427136943959788721376762326430771171648759300146", "price": "0.67", "size": "5", "side": "BUY", "hash": "fd65c56ea8120714d66a7ab94fc98cdfa1f1ec07", "best_bid": "0.995", "best_ask": "0.998"}, {"asset_id": "73414222381656326204771753454630063673548497164758947581648273905027617570612", "price": "0.33", "size": "5", "side": "SELL", "hash": "1a47663fe7469b971fa751de677dc896b97b4412", "best_bid": "0.002", "best_ask": "0.005"}], "timestamp": "1769384560128", "event_type": "price_change"}}
{"_local_timestamp": "2026-01-25T23:42:40.724965+00:00", "data": {"market": "0x2393ed0b0fdc450054c7b9071907eca75cf4fc36e385adf4a0a5f99ee62243e8", "price_changes": [{"asset_id": "32769749367306925959219403371425714180265458150646381231272229429098460625924", "price": "0.904", "size": "85", "side": "BUY", "hash": "d6ab2662163d07ada2938884af84cdc041bac2fe", "best_bid": "0.905", "best_ask": "0.96"}, {"asset_id": "100074770378634056601572485653252702850363676459996771990439989989293515601975", "price": "0.096", "size": "85", "side": "SELL", "hash": "0cd8d75d97bf89681f6a95e2595a5e2794678c23", "best_bid": "0.04", "best_ask": "0.095"}], "timestamp": "1769384560591", "event_type": "price_change"}}
{"_local_timestamp": "2026-01-25T23:42:41.344289+00:00", "data": {"market": "0x2393ed0b0fdc450054c7b9071907eca75cf4fc36e385adf4a0a5f99ee62243e8", "price_changes": [{"asset_id": "32769749367306925959219403371425714180265458150646381231272229429098460625924", "price": "0.906", "size": "50", "side": "BUY", "hash": "e0d25540b048feb873992bc376cb7e57967b1fbf", "best_bid": "0.906", "best_ask": "0.96"}, {"asset_id": "100074770378634056601572485653252702850363676459996771990439989989293515601975", "price": "0.094", "size": "50", "side": "SELL", "hash": "477eb806fcf2e506e972891805ab97d53417f2cd", "best_bid": "0.04", "best_ask": "0.094"}], "timestamp": "1769384561223", "event_type": "price_change"}}
{"_local_timestamp": "2026-01-25T23:42:41.689758+00:00", "data": {"market": "0x2393ed0b0fdc450054c7b9071907eca75cf4fc36e385adf4a0a5f99ee62243e8", "price_changes": [{"asset_id": "32769749367306925959219403371425714180265458150646381231272229429098460625924", "price": "0.904", "size": "35", "side": "BUY", "hash": "2c0ef264f4ddab793d43eadea31e584fa1bad185", "best_bid": "0.906", "best_ask": "0.96"}, {"asset_id": "100074770378634056601572485653252702850363676459996771990439989989293515601975", "price": "0.096", "size": "35", "side": "SELL", "hash": "b5161b9021594bb0b870dc2429d5ec2117590f3b", "best_bid": "0.04", "best_ask": "0.094"}], "timestamp": "1769384561562", "event_type": "price_change"}}
{"_local_timestamp": "2026-01-25T23:42:42.393245+00:00", "data": {"market": "0x2393ed0b0fdc450054c7b9071907eca75cf4fc36e385adf4a0a5f99ee62243e8", "price_changes": [{"asset_id": "32769749367306925959219403371425714180265458150646381231272229429098460625924", "price": "0.905", "size": "0", "side": "BUY", "hash": "51e4fea294bbbb2e17b6cecd82dcff4a468f86e1", "best_bid": "0.906", "best_ask": "0.96"}, {"asset_id": "100074770378634056601572485653252702850363676459996771990439989989293515601975", "price": "0.095", "size": "0", "side": "SELL", "hash": "748bfe9e75a950c47a2ea271f2196a60dcbec8d0", "best_bid": "0.04", "best_ask": "0.094"}], "timestamp": "1769384562277", "event_type": "price_change"}}
{"_local_timestamp": "2026-01-25T23:42:43.216954+00:00", "data": {"market": "0x2393ed0b0fdc450054c7b9071907eca75cf4fc36e385adf4a0a5f99ee62243e8", "price_changes": [{"asset_id": "32769749367306925959219403371425714180265458150646381231272229429098460625924", "price": "0.904", "size": "5", "side": "BUY", "hash": "c11dbcfd9d262cdf261bd310c4ce5d938304a186", "best_bid": "0.906", "best_ask": "0.96"}, {"asset_id": "100074770378634056601572485653252702850363676459996771990439989989293515601975", "price": "0.096", "size": "5", "side": "SELL", "hash": "e1ec0cf96f6e72207ceb970ded8930085cbecc63", "best_bid": "0.04", "best_ask": "0.094"}], "timestamp": "1769384563104", "event_type": "price_change"}}
{"_local_timestamp": "2026-01-25T23:42:43.476101+00:00", "data": {"market": "0x2393ed0b0fdc450054c7b9071907eca75cf4fc36e385adf4a0a5f99ee62243e8", "price_changes": [{"asset_id": "32769749367306925959219403371425714180265458150646381231272229429098460625924", "price": "0.907", "size": "37.81", "side": "BUY", "hash": "3e00a9eabd60c6c09345fe7730d3c68840e8571e", "best_bid": "0.907", "best_ask": "0.96"}, {"asset_id": "100074770378634056601572485653252702850363676459996771990439989989293515601975", "price": "0.093", "size": "37.81", "side": "SELL", "hash": "a9180238710727dd9b31e5d9568f254a2c6bee19", "best_bid": "0.04", "best_ask": "0.093"}], "timestamp": "1769384563361", "event_type": "price_change"}}
{"_local_timestamp": "2026-01-25T23:42:44.167203+00:00", "data": {"market": "0x9472be65457510b7fc3477b20ba90910e99d92eac8421a14bf4b7b7a08ef31dc", "price_changes": [{"asset_id": "43311793366960417907757893276427136943959788721376762326430771171648759300146", "price": "0.67", "size": "0", "side": "BUY", "hash": "d4bc14efbb7f3943ca4e37b37b3f65be785b1e4f", "best_bid": "0.995", "best_ask": "0.998"}, {"asset_id": "73414222381656326204771753454630063673548497164758947581648273905027617570612", "price": "0.33", "size": "0", "side": "SELL", "hash": "8f0184ebb9d4855b4282e68b785d6e5aa2724b16", "best_bid": "0.002", "best_ask": "0.005"}], "timestamp": "1769384564055", "event_type": "price_change"}}
{"_local_timestamp": "2026-01-25T23:42:44.561453+00:00", "data": {"market": "0x9472be65457510b7fc3477b20ba90910e99d92eac8421a14bf4b7b7a08ef31dc", "price_changes": [{"asset_id": "43311793366960417907757893276427136943959788721376762326430771171648759300146", "price": "0.67", "size": "5", "side": "BUY", "hash": "81a4df920fb0423e916f095834971f1568c4995f", "best_bid": "0.995", "best_ask": "0.998"}, {"asset_id": "73414222381656326204771753454630063673548497164758947581648273905027617570612", "price": "0.33", "size": "5", "side": "SELL", "hash": "4c12584b91a0e0dfd4cb7c9da55c0a4ecd6e0554", "best_bid": "0.002", "best_ask": "0.005"}], "timestamp": "1769384564446", "event_type": "price_change"}}
{"_local_timestamp": "2026-01-25T23:42:47.330870+00:00", "data": {"market": "0x2393ed0b0fdc450054c7b9071907eca75cf4fc36e385adf4a0a5f99ee62243e8", "price_changes": [{"asset_id": "32769749367306925959219403371425714180265458150646381231272229429098460625924", "price": "0.908", "size": "50", "side": "BUY", "hash": "368e75576983d5833a4e2b91ef054aceb8e661a9", "best_bid": "0.908", "best_ask": "0.96"}, {"asset_id": "100074770378634056601572485653252702850363676459996771990439989989293515601975", "price": "0.092", "size": "50", "side": "SELL", "hash": "3e040267cded6e31a541191f95bf443d396663df", "best_bid": "0.04", "best_ask": "0.092"}], "timestamp": "1769384567121", "event_type": "price_change"}}
{"_local_timestamp": "2026-01-25T23:42:47.577108+00:00", "data": {"market": "0x2393ed0b0fdc450054c7b9071907eca75cf4fc36e385adf4a0a5f99ee62243e8", "price_changes": [{"asset_id": "32769749367306925959219403371425714180265458150646381231272229429098460625924", "price": "0.906", "size": "0", "side": "BUY", "hash": "ade52598c7a2193b19951f5925be11b2ffe1445d", "best_bid": "0.908", "best_ask": "0.96"}, {"asset_id": "100074770378634056601572485653252702850363676459996771990439989989293515601975", "price": "0.094", "size": "0", "side": "SELL", "hash": "a27fd07b76bdf40fa9ff055da005aa3a8bdc462a", "best_bid": "0.04", "best_ask": "0.092"}], "timestamp": "1769384567457", "event_type": "price_change"}}
{"_local_timestamp": "2026-01-25T23:42:48.189312+00:00", "data": {"market": "0x2393ed0b0fdc450054c7b9071907eca75cf4fc36e385adf4a0a5f99ee62243e8", "price_changes": [{"asset_id": "32769749367306925959219403371425714180265458150646381231272229429098460625924", "price": "0.907", "size": "0", "side": "BUY", "hash": "928d8c0bf4084fd727d8def0b4c893a7007a5b0f", "best_bid": "0.908", "best_ask": "0.96"}, {"asset_id": "100074770378634056601572485653252702850363676459996771990439989989293515601975", "price": "0.093", "size": "0", "side": "SELL", "hash": "ca6104009347d45e78819575cb74ed50b31081bf", "best_bid": "0.04", "best_ask": "0.092"}], "timestamp": "1769384568072", "event_type": "price_change"}}
{"_local_timestamp": "2026-01-25T23:42:48.925225+00:00", "data": {"market": "0x2393ed0b0fdc450054c7b9071907eca75cf4fc36e385adf4a0a5f99ee62243e8", "price_changes": [{"asset_id": "32769749367306925959219403371425714180265458150646381231272229429098460625924", "price": "0.909", "size": "37.81", "side": "BUY", "hash": "8a0450fee033dd4fc8c64b1f524a17d8046fb203", "best_bid": "0.909", "best_ask": "0.96"}, {"asset_id": "100074770378634056601572485653252702850363676459996771990439989989293515601975", "price": "0.091", "size": "37.81", "side": "SELL", "hash": "af339e26ff91f7d4eecc1f28b1dfc1eed306df26", "best_bid": "0.04", "best_ask": "0.091"}], "timestamp": "1769384568810", "event_type": "price_change"}}
{"_local_timestamp": "2026-01-25T23:42:50.613536+00:00", "data": {"market": "0x9472be65457510b7fc3477b20ba90910e99d92eac8421a14bf4b7b7a08ef31dc", "price_changes": [{"asset_id": "43311793366960417907757893276427136943959788721376762326430771171648759300146", "price": "0.67", "size": "0", "side": "BUY", "hash": "c5b32003d9470c72787cc946881a9abb24e0b723", "best_bid": "0.995", "best_ask": "0.998"}, {"asset_id": "73414222381656326204771753454630063673548497164758947581648273905027617570612", "price": "0.33", "size": "0", "side": "SELL", "hash": "6f0265db93209bf5c9c7684ac91ca4d26d76a641", "best_bid": "0.002", "best_ask": "0.005"}], "timestamp": "1769384570513", "event_type": "price_change"}}
{"_local_timestamp": "2026-01-25T23:42:50.911574+00:00", "data": {"market": "0x9472be65457510b7fc3477b20ba90910e99d92eac8421a14bf4b7b7a08ef31dc", "price_changes": [{"asset_id": "43311793366960417907757893276427136943959788721376762326430771171648759300146", "price": "0.67", "size": "5", "side": "BUY", "hash": "ff534d212289fcc9723edae8817a64c2db925642", "best_bid": "0.995", "best_ask": "0.998"}, {"asset_id": "73414222381656326204771753454630063673548497164758947581648273905027617570612", "price": "0.33", "size": "5", "side": "SELL", "hash": "181606051073d4fe4db04986b3fd43e1d8d9f743", "best_bid": "0.002", "best_ask": "0.005"}], "timestamp": "1769384570809", "event_type": "price_change"}}
{"_local_timestamp": "2026-01-25T23:42:53.235364+00:00", "data": {"market": "0x2393ed0b0fdc450054c7b9071907eca75cf4fc36e385adf4a0a5f99ee62243e8", "price_changes": [{"asset_id": "32769749367306925959219403371425714180265458150646381231272229429098460625924", "price": "0.91", "size": "50", "side": "BUY", "hash": "63afbba7721c30d94047d6043aecdc1b75314018", "best_bid": "0.91", "best_ask": "0.96"}, {"asset_id": "100074770378634056601572485653252702850363676459996771990439989989293515601975", "price": "0.09", "size": "50", "side": "SELL", "hash": "c676b6a964c3b5179892b2e9792b2fb0f8173f46", "best_bid": "0.04", "best_ask": "0.09"}], "timestamp": "1769384573119", "event_type": "price_change"}}
{"_local_timestamp": "2026-01-25T23:42:53.549257+00:00", "data": {"market": "0x2393ed0b0fdc450054c7b9071907eca75cf4fc36e385adf4a0a5f99ee62243e8", "price_changes": [{"asset_id": "32769749367306925959219403371425714180265458150646381231272229429098460625924", "price": "0.908", "size": "0", "side": "BUY", "hash": "d2243c6d01f146733eb55c108fe1d6298d4eef39", "best_bid": "0.91", "best_ask": "0.96"}, {"asset_id": "100074770378634056601572485653252702850363676459996771990439989989293515601975", "price": "0.092", "size": "0", "side": "SELL", "hash": "d1bb468c7569c9147b3f198870911e90601f72bb", "best_bid": "0.04", "best_ask": "0.09"}], "timestamp": "1769384573453", "event_type": "price_change"}}
{"_local_timestamp": "2026-01-25T23:42:54.242942+00:00", "data": {"market": "0x2393ed0b0fdc450054c7b9071907eca75cf4fc36e385adf4a0a5f99ee62243e8", "price_changes": [{"asset_id": "32769749367306925959219403371425714180265458150646381231272229429098460625924", "price": "0.909", "size": "0", "side": "BUY", "hash": "1d7d44d99bd72fd4162c3118a993068884501517", "best_bid": "0.91", "best_ask": "0.96"}, {"asset_id": "100074770378634056601572485653252702850363676459996771990439989989293515601975", "price": "0.091", "size": "0", "side": "SELL", "hash": "2ce8c21567eef6ddba12785f4e8161c8f5661add", "best_bid": "0.04", "best_ask": "0.09"}], "timestamp": "1769384574146", "event_type": "price_change"}}
{"_local_timestamp": "2026-01-25T23:42:55.293694+00:00", "data": {"market": "0x2393ed0b0fdc450054c7b9071907eca75cf4fc36e385adf4a0a5f99ee62243e8", "price_changes": [{"asset_id": "32769749367306925959219403371425714180265458150646381231272229429098460625924", "price": "0.911", "size": "37.81", "side": "BUY", "hash": "2ef631b7b531b4504624dc794f929f282e5dd945", "best_bid": "0.911", "best_ask": "0.96"}, {"asset_id": "100074770378634056601572485653252702850363676459996771990439989989293515601975", "price": "0.089", "size": "37.81", "side": "SELL", "hash": "e2f7ef3564ce13376a2e0b9830385faf223b3091", "best_bid": "0.04", "best_ask": "0.089"}], "timestamp": "1769384575194", "event_type": "price_change"}}
{"_local_timestamp": "2026-01-25T23:42:55.505711+00:00", "data": {"market": "0x50c669f178da4e5bbea7f1be25041fd278914712fa87a6a6f8e57d5923d88dee", "price_changes": [{"asset_id": "74040420326294854165772767082819937451857852955603897473157746262672057685461", "price": "0.909", "size": "0", "side": "BUY", "hash": "7fbf33ba6c30456526c454eeb15b0b7a793f7e60", "best_bid": "0.995", "best_ask": "0.998"}, {"asset_id": "24682525479474221428144937281315825971983904267399062415430320764754931667953", "price": "0.091", "size": "0", "side": "SELL", "hash": "58f78c62e97e5708f235e4e15c09541d2f034588", "best_bid": "0.002", "best_ask": "0.005"}], "timestamp": "1769384575386", "event_type": "price_change"}}
{"_local_timestamp": "2026-01-25T23:42:55.720842+00:00", "data": {"market": "0x50c669f178da4e5bbea7f1be25041fd278914712fa87a6a6f8e57d5923d88dee", "price_changes": [{"asset_id": "74040420326294854165772767082819937451857852955603897473157746262672057685461", "price": "0.909", "size": "30", "side": "BUY", "hash": "8421354e1d83bf06a44ac779ee18c929a329d377", "best_bid": "0.995", "best_ask": "0.998"}, {"asset_id": "24682525479474221428144937281315825971983904267399062415430320764754931667953", "price": "0.091", "size": "30", "side": "SELL", "hash": "08af88bddc4608b1143b51ac597a3fcd285f25ae", "best_bid": "0.002", "best_ask": "0.005"}], "timestamp": "1769384575615", "event_type": "price_change"}}
{"_local_timestamp": "2026-01-25T23:42:57.196318+00:00", "data": {"market": "0x9472be65457510b7fc3477b20ba90910e99d92eac8421a14bf4b7b7a08ef31dc", "price_changes": [{"asset_id": "43311793366960417907757893276427136943959788721376762326430771171648759300146", "price": "0.67", "size": "0", "side": "BUY", "hash": "8b438ad7ca935fe1ead614a7b197670e9fee925a", "best_bid": "0.995", "best_ask": "0.998"}, {"asset_id": "73414222381656326204771753454630063673548497164758947581648273905027617570612", "price": "0.33", "size": "0", "side": "SELL", "hash": "2700a09b70b764a8813cda4ec84a1fc80937bbe3", "best_bid": "0.002", "best_ask": "0.005"}], "timestamp": "1769384577103", "event_type": "price_change"}}
{"_local_timestamp": "2026-01-25T23:42:57.528381+00:00", "data": {"market": "0x9472be65457510b7fc3477b20ba90910e99d92eac8421a14bf4b7b7a08ef31dc", "price_changes": [{"asset_id": "43311793366960417907757893276427136943959788721376762326430771171648759300146", "price": "0.67", "size": "5", "side": "BUY", "hash": "da8e52e0baa6ae80ef475b7d53ba408c4b8db11e", "best_bid": "0.995", "best_ask": "0.998"}, {"asset_id": "73414222381656326204771753454630063673548497164758947581648273905027617570612", "price": "0.33", "size": "5", "side": "SELL", "hash": "e600724a1cfbf50b6ab7d91419049fa21d9a2fab", "best_bid": "0.002", "best_ask": "0.005"}], "timestamp": "1769384577437", "event_type": "price_change"}}
{"_local_timestamp": "2026-01-25T23:42:58.732963+00:00", "data": {"market": "0xaf9d0e448129a9f657f851d49495ba4742055d80e0ef1166ba0ee81d4d594214", "price_changes": [{"asset_id": "4153292802911610701832309484716814274802943278345248636922528170020319407796", "price": "0.151", "size": "0", "side": "BUY", "hash": "42a5fd1e32fe8b9ac3b4baafe5a3fb3c22b720e1", "best_bid": "0.936", "best_ask": "0.988"}, {"asset_id": "101676997363687199724245607342877036148401850938023978421879460310389391082353", "price": "0.849", "size": "0", "side": "SELL", "hash": "40ac379ad839cb5c0a81293a307220273f057773", "best_bid": "0.012", "best_ask": "0.064"}], "timestamp": "1769384578627", "event_type": "price_change"}}
{"_local_timestamp": "2026-01-25T23:42:58.781477+00:00", "data": {"market": "0xaf9d0e448129a9f657f851d49495ba4742055d80e0ef1166ba0ee81d4d594214", "price_changes": [{"asset_id": "4153292802911610701832309484716814274802943278345248636922528170020319407796", "price": "0.151", "size": "13", "side": "BUY", "hash": "393948adad4552f99df68381566ad04a534dd3f1", "best_bid": "0.936", "best_ask": "0.988"}, {"asset_id": "101676997363687199724245607342877036148401850938023978421879460310389391082353", "price": "0.849", "size": "13", "side": "SELL", "hash": "a8a4557a25dceeee2c331cb2f796f4e6c61ccb66", "best_bid": "0.012", "best_ask": "0.064"}], "timestamp": "1769384578674", "event_type": "price_change"}}
