{"_local_timestamp": "2026-01-25T23:40:41.670906+00:00", "data": [{"market": "0x23e782e8db3eb990b48ff37432f9f0899e73ea737e68d2934bd09b34934dc0d0", "asset_id": "42382535584090931070184963017291726037912989687255284323203344679942164276749", "timestamp": "1769384428180", "hash": "7473c0c8df42b1a2c812228f1118657e45528160", "bids": [{"price": "0.001", "size": "3393.92"}, {"price": "0.002", "size": "1255.9"}, {"price": "0.003", "size": "1166"}, {"price": "0.004", "size": "10.2"}, {"price": "0.006", "size": "83"}, {"price": "0.01", "size": "5500"}, {"price": "0.011", "size": "5.18"}, {"price": "0.02", "size": "1000"}, {"price": "0.026", "size": "7279"}, {"price": "0.027", "size": "7.36"}, {"price": "0.05", "size": "30"}, {"price": "0.051", "size": "39"}, {"price": "0.06", "size": "500"}, {"price": "0.061", "size": "7.9"}, {"price": "0.11", "size": "225"}, {"price": "0.161", "size": "395"}, {"price": "0.162", "size": "7.43"}, {"price": "0.21", "size": "150"}, {"price": "0.281", "size": "7"}, {"price": "0.282", "size": "666"}, {"price": "0.566", "size": "100"}, {"price": "0.639", "size": "30"}, {"price": "0.641", "size": "10"}, {"price": "0.643", "size": "25"}, {"price": "0.644", "size": "20"}, {"price": "0.832", "size": "5"}, {"price": "0.833", "size": "30"}, {"price": "0.85", "size": "21.33"}], "asks": [{"price": "0.999", "size": "16767.11"}, {"price": "0.998", "size": "676.29"}, {"price": "0.997", "size": "39.31"}, {"price": "0.996", "size": "16.11"}, {"price": "0.99", "size": "1500"}, {"price": "0.989", "size": "400"}, {"price": "0.988", "size": "225.87"}, {"price": "0.987", "size": "124.36"}, {"price": "0.985", "size": "169.2"}, {"price": "0.983", "size": "24.36"}, {"price": "0.98", "size": "59.23"}], "event_type": "book", "last_trade_price": ""}, {"market": "0x16478811d537afdfadaacef3bf1fc8b61ed86385968321b7d9250bdce2a49748", "asset_id": "92269994048518357863385104036810846326684031835851654275504679077189526944972", "timestamp": "1769384358588", "hash": "e5c41f21fcc28ea5558201fc4fb01430657c650e", "bids": [{"price": "0.001", "size": "3989.6"}, {"price": "0.002", "size": "1255.85"}, {"price": "0.003", "size": "1400"}, {"price": "0.004", "size": "10.13"}, {"price": "0.006", "size": "200"}, {"price": "0.01", "size": "5500"}, {"price": "0.011", "size": "5.15"}, {"price": "0.02", "size": "2200"}, {"price": "0.021", "size": "11.31"}, {"price": "0.05", "size": "30"}, {"price": "0.051", "size": "39"}, {"price": "0.062", "size": "5853"}, {"price": "0.063", "size": "8.92"}, {"price": "0.1", "size": "360"}, {"price": "0.15", "size": "776.66"}, {"price": "0.2", "size": "660"}, {"price": "0.201", "size": "5.4"}, {"price": "0.25", "size": "212"}, {"price": "0.3", "size": "336.66"}, {"price": "0.301", "size": "100"}, {"price": "0.349", "size": "150"}, {"price": "0.35", "size": "68.57"}, {"price": "0.351", "size": "34"}, {"price": "0.4", "size": "82"}, {"price": "0.401", "size": "5"}, {"price": "0.64", "size": "105"}, {"price": "0.74", "size": "5"}, {"price": "0.767", "size": "10"}, {"price": "0.771", "size": "30"}, {"price": "0.773", "size": "25"}, {"price": "0.774", "size": "20"}, {"price": "0.834", "size": "20"}, {"price": "0.835", "size": "20"}, {"price": "0.836", "size": "30"}, {"price": "0.876", "size": "127.24"}, {"price": "0.928", "size": "25"}, {"price": "0.929", "size": "10"}], "asks": [{"price": "0.999", "size": "19336"}, {"price": "0.998", "size": "112.32"}, {"price": "0.99", "size": "750"}, {"price": "0.989", "size": "400"}, {"price": "0.988", "size": "116.66"}, {"price": "0.987", "size": "100"}, {"price": "0.986", "size": "182.66"}, {"price": "0.985", "size": "41.66"}], "event_type": "book", "last_trade_price": ""}, {"market": "0xfacaaf8ca81b788f8da594acaf23af2ef90037d82580b91357be35f97229e3a5", "asset_id": "49741609004781342711179849070128334110798460232218737742146637694522428416234", "timestamp": "1769384426830", "hash": "07ec0bded558f58e2b1d8a3d29fb853010906cbe", "bids": [{"price": "0.01", "size": "5512"}, {"price": "0.02", "size": "2200"}, {"price": "0.03", "size": "10.83"}, {"price": "0.05", "size": "10"}, {"price": "0.07", "size": "514.28"}, {"price": "0.08", "size": "4580"}, {"price": "0.09", "size": "5.34"}, {"price": "0.11", "size": "309.09"}, {"price": "0.12", "size": "550"}, {"price": "0.15", "size": "213.33"}, {"price": "0.18", "size": "888"}, {"price": "0.19", "size": "2807.36"}, {"price": "0.2", "size": "5.37"}, {"price": "0.23", "size": "263.04"}, {"price": "0.26", "size": "92.3"}, {"price": "0.29", "size": "687.76"}, {"price": "0.3", "size": "66.66"}, {"price": "0.31", "size": "208"}, {"price": "0.35", "size": "230"}, {"price": "0.53", "size": "100"}, {"price": "0.58", "size": "235.56"}, {"price": "0.59", "size": "52.03"}, {"price": "0.6", "size": "18.33"}, {"price": "0.68", "size": "50"}, {"price": "0.7", "size": "130"}], "asks": [{"price": "0.99", "size": "3998.93"}, {"price": "0.98", "size": "900"}, {"price": "0.97", "size": "9.52"}, {"price": "0.96", "size": "54"}, {"price": "0.9", "size": "457.26"}, {"price": "0.84", "size": "81.25"}, {"price": "0.83", "size": "64.7"}, {"price": "0.82", "size": "57.26"}, {"price": "0.76", "size": "100"}, {"price": "0.75", "size": "50"}, {"price": "0.74", "size": "137.26"}], "event_type": "book", "last_trade_price": ""}, {"market": "0xe7d699841d03f695da20c8935f4cdf809057f3b27fa4f382e327ff731b8d75a7", "asset_id": "86720801120812523206375862885554727968671842048571953285734439150624995757719", "timestamp": "1769384431891", "hash": "1ed16296ca0269ddf8a1d747497e5ad971cd46cc", "bids": [{"price": "0.01", "size": "5553.42"}, {"price": "0.02", "size": "2200"}, {"price": "0.03", "size": "7.08"}, {"price": "0.05", "size": "30"}, {"price": "0.06", "size": "533"}, {"price": "0.07", "size": "8.48"}, {"price": "0.1", "size": "1160"}, {"price": "0.14", "size": "242.85"}, {"price": "0.15", "size": "550"}, {"price": "0.19", "size": "168.42"}, {"price": "0.2", "size": "400"}, {"price": "0.21", "size": "815.13"}, {"price": "0.23", "size": "1926"}, {"price": "0.24", "size": "116.66"}, {"price": "0.29", "size": "89.65"}, {"price": "0.3", "size": "250"}, {"price": "0.34", "size": "70.58"}, {"price": "0.38", "size": "52.63"}, {"price": "0.39", "size": "1588"}, {"price": "0.41", "size": "3971"}, {"price": "0.42", "size": "300"}, {"price": "0.49", "size": "169"}, {"price": "0.53", "size": "70"}, {"price": "0.54", "size": "5"}, {"price": "0.69", "size": "5"}, {"price": "0.81", "size": "73.33"}, {"price": "0.82", "size": "30"}, {"price": "0.92", "size": "50"}, {"price": "0.93", "size": "125"}, {"price": "0.94", "size": "580.01"}, {"price": "0.95", "size": "198"}], "asks": [{"price": "0.99", "size": "1800"}, {"price": "0.98", "size": "425"}, {"price": "0.97", "size": "763.3"}], "event_type": "book", "last_trade_price": ""}, {"market": "0xfacaaf8ca81b788f8da594acaf23af2ef90037d82580b91357be35f97229e3a5", "asset_id": "94754153121378446077535791604860675458774881690932146680120328837949383988913", "timestamp": "1769384426830", "hash": "4a705d328e7c055d4b4695af360f3f099898a2c1", "bids": [{"price": "0.01", "size": "3998.93"}, {"price": "0.02", "size": "900"}, {"price": "0.03", "size": "9.52"}, {"price": "0.04", "size": "54"}, {"price": "0.1", "size": "457.26"}, {"price": "0.16", "size": "81.25"}, {"price": "0.17", "size": "64.7"}, {"price": "0.18", "size": "57.26"}, {"price": "0.24", "size": "100"}, {"price": "0.25", "size": "50"}, {"price": "0.26", "size": "137.26"}], "asks": [{"price": "0.99", "size": "5512"}, {"price": "0.98", "size": "2200"}, {"price": "0.97", "size": "10.83"}, {"price": "0.95", "size": "10"}, {"price": "0.93", "size": "514.28"}, {"price": "0.92", "size": "4580"}, {"price": "0.91", "size": "5.34"}, {"price": "0.89", "size": "309.09"}, {"price": "0.88", "size": "550"}, {"price": "0.85", "size": "213.33"}, {"price": "0.82", "size": "888"}, {"price": "0.81", "size": "2807.36"}, {"price": "0.8", "size": "5.37"}, {"price": "0.77", "size": "263.04"}, {"price": "0.74", "size": "92.3"}, {"price": "0.71", "size": "687.76"}, {"price": "0.7", "size": "66.66"}, {"price": "0.69", "size": "208"}, {"price": "0.65", "size": "230"}, {"price": "0.47", "size": "100"}, {"price": "0.42", "size": "235.56"}, {"price": "0.41", "size": "52.03"}, {"price": "0.4", "size": "18.33"}, {"price": "0.32", "size": "50"}, {"price": "0.3", "size": "130"}], "event_type": "book", "last_trade_price": ""}, {"market": "0x2649d46f6793c9847cc30659f7bcbec94578a23eda4c8cb86f31473173561986", "asset_id": "37921534922010226146703074549600791269918801302227759309433381423805138270558", "timestamp": "1769384418506", "hash": "9e9b83b19eb2c63b2383cdd2f690eacbc9a04080", "bids": [{"price": "0.001", "size": "3860.86"}, {"price": "0.002", "size": "1255.84"}, {"price": "0.003", "size": "1400"}, {"price": "0.004", "size": "10.1"}, {"price": "0.006", "size": "200"}, {"price": "0.01", "size": "5500"}, {"price": "0.011", "size": "5.13"}, {"price": "0.02", "size": "2200"}, {"price": "0.021", "size": "9.72"}, {"price": "0.05", "size": "30"}, {"price": "0.051", "size": "39"}, {"price": "0.062", "size": "5864"}, {"price": "0.063", "size": "9.55"}, {"price": "0.1", "size": "360"}, {"price": "0.15", "size": "776.66"}, {"price": "0.2", "size": "660"}, {"price": "0.201", "size": "5.37"}, {"price": "0.25", "size": "409"}, {"price": "0.3", "size": "186.66"}, {"price": "0.303", "size": "100"}, {"price": "0.304", "size": "50"}, {"price": "0.35", "size": "68.57"}, {"price": "0.4", "size": "143"}, {"price": "0.401", "size": "5"}, {"price": "0.621", "size": "100"}, {"price": "0.69", "size": "13.33"}, {"price": "0.694", "size": "30"}, {"price": "0.695", "size": "30"}, {"price": "0.697", "size": "10"}, {"price": "0.7", "size": "25"}, {"price": "0.701", "size": "20"}, {"price": "0.875", "size": "78.11"}, {"price": "0.88", "size": "10.5"}, {"price": "0.938", "size": "25"}, {"price": "0.939", "size": "10"}], "asks": [{"price": "0.999", "size": "16477"}, {"price": "0.998", "size": "2014.19"}, {"price": "0.997", "size": "84.44"}, {"price": "0.99", "size": "1700"}, {"price": "0.989", "size": "400"}, {"price": "0.988", "size": "226.04"}, {"price": "0.987", "size": "126.04"}, {"price": "0.986", "size": "176"}, {"price": "0.985", "size": "26.04"}], "event_type": "book", "last_trade_price": ""}, {"market": "0xeafc8d47725546039800fe78eb06c0af5d9f982134515b9250ea376b7c258afb", "asset_id": "39436446463164291051085103274433078121544260678753625430845203266295844561591", "timestamp": "1769384218486", "hash": "345e80f27159914fbac76eaa6576f2762db14ae7", "bids": [{"price": "0.001", "size": "4340"}, {"price": "0.002", "size": "285.4"}, {"price": "0.003", "size": "40.43"}, {"price": "0.004", "size": "23.4"}, {"price": "0.01", "size": "1500"}, {"price": "0.011", "size": "770.68"}, {"price": "0.012", "size": "111.21"}], "asks": [{"price": "0.999", "size": "3623.87"}, {"price": "0.998", "size": "1255.85"}, {"price": "0.997", "size": "1166"}, {"price": "0.996", "size": "10.13"}, {"price": "0.994", "size": "83"}, {"price": "0.99", "size": "55800"}, {"price": "0.989", "size": "5.14"}, {"price": "0.98", "size": "2200"}, {"price": "0.979", "size": "8.93"}, {"price": "0.95", "size": "30"}, {"price": "0.949", "size": "39"}, {"price": "0.94", "size": "500"}, {"price": "0.939", "size": "10.17"}, {"price": "0.9", "size": "560"}, {"price": "0.85", "size": "776.66"}, {"price": "0.849", "size": "4072"}, {"price": "0.8", "size": "610"}, {"price": "0.799", "size": "5.36"}, {"price": "0.75", "size": "362"}, {"price": "0.749", "size": "46.89"}, {"price": "0.7", "size": "186.66"}, {"price": "0.66", "size": "50"}, {"price": "0.65", "size": "68.57"}, {"price": "0.6", "size": "50"}, {"price": "0.585", "size": "250"}, {"price": "0.584", "size": "208"}, {"price": "0.583", "size": "5"}, {"price": "0.3", "size": "100"}, {"price": "0.23", "size": "5.85"}, {"price": "0.229", "size": "10"}, {"price": "0.18", "size": "5.85"}, {"price": "0.179", "size": "30"}, {"price": "0.178", "size": "20"}, {"price": "0.163", "size": "74.52"}, {"price": "0.161", "size": "13.33"}, {"price": "0.16", "size": "20"}, {"price": "0.158", "size": "30"}, {"price": "0.015", "size": "10"}, {"price": "0.014", "size": "70"}], "event_type": "book", "last_trade_price": ""}, {"market": "0xeafc8d47725546039800fe78eb06c0af5d9f982134515b9250ea376b7c258afb", "asset_id": "102282495724728145503590068938456419856338447487625172072096551524174375085545", "timestamp": "1769384218486", "hash": "97893676148fbd3237777aceb2cf3a0d794bb9e7", "bids": [{"price": "0.001", "size": "3623.87"}, {"price": "0.002", "size": "1255.85"}, {"price": "0.003", "size": "1166"}, {"price": "0.004", "size": "10.13"}, {"price": "0.006", "size": "83"}, {"price": "0.01", "size": "55800"}, {"price": "0.011", "size": "5.14"}, {"price": "0.02", "size": "2200"}, {"price": "0.021", "size": "8.93"}, {"price": "0.05", "size": "30"}, {"price": "0.051", "size": "39"}, {"price": "0.06", "size": "500"}, {"price": "0.061", "size": "10.17"}, {"price": "0.1", "size": "560"}, {"price": "0.15", "size": "776.66"}, {"price": "0.151", "size": "4072"}, {"price": "0.2", "size": "610"}, {"price": "0.201", "size": "5.36"}, {"price": "0.25", "size": "362"}, {"price": "0.251", "size": "46.89"}, {"price": "0.3", "size": "186.66"}, {"price": "0.34", "size": "50"}, {"price": "0.35", "size": "68.57"}, {"price": "0.4", "size": "50"}, {"price": "0.415", "size": "250"}, {"price": "0.416", "size": "208"}, {"price": "0.417", "size": "5"}, {"price": "0.7", "size": "100"}, {"price": "0.77", "size": "5.85"}, {"price": "0.771", "size": "10"}, {"price": "0.82", "size": "5.85"}, {"price": "0.821", "size": "30"}, {"price": "0.822", "size": "20"}, {"price": "0.837", "size": "74.52"}, {"price": "0.839", "size": "13.33"}, {"price": "0.84", "size": "20"}, {"price": "0.842", "size": "30"}, {"price": "0.985", "size": "10"}, {"price": "0.986", "size": "70"}], "asks": [{"price": "0.999", "size": "4340"}, {"price": "0.998", "size": "285.4"}, {"price": "0.997", "size": "40.43"}, {"price": "0.996", "size": "23.4"}, {"price": "0.99", "size": "1500"}, {"price": "0.989", "size": "770.68"}, {"price": "0.988", "size": "111.21"}], "event_type": "book", "last_trade_price": ""}, {"market": "0xad1f282f187c4748fe6eb51153a39557c66856cd14408bc3d509d3b23c047d41", "asset_id": "26089319074590795210476289468934414386490143191167179409102092139417103170837", "timestamp": "1769384396610", "hash": "f1d88b3eff5111497670b0ac7a2cf8994c9b7d08", "bids": [{"price": "0.01", "size": "3514.94"}, {"price": "0.02", "size": "4546"}, {"price": "0.03", "size": "259.24"}, {"price": "0.04", "size": "50"}, {"price": "0.05", "size": "10"}, {"price": "0.06", "size": "6.82"}, {"price": "0.11", "size": "225"}, {"price": "0.12", "size": "9.7"}, {"price": "0.18", "size": "695.54"}, {"price": "0.19", "size": "66.66"}, {"price": "0.28", "size": "39.28"}, {"price": "0.29", "size": "44.82"}, {"price": "0.3", "size": "136.66"}, {"price": "0.31", "size": "50"}, {"price": "0.34", "size": "29"}, {"price": "0.35", "size": "66.66"}], "asks": [{"price": "0.99", "size": "7000"}, {"price": "0.98", "size": "1000"}, {"price": "0.96", "size": "4990.14"}, {"price": "0.92", "size": "2800"}, {"price": "0.86", "size": "550"}, {"price": "0.8", "size": "466.66"}, {"price": "0.78", "size": "100"}, {"price": "0.76", "size": "200"}, {"price": "0.62", "size": "66.66"}, {"price": "0.58", "size": "30.95"}, {"price": "0.57", "size": "25.58"}, {"price": "0.51", "size": "100"}, {"price": "0.49", "size": "80"}, {"price": "0.46", "size": "81.44"}], "event_type": "book", "last_trade_price": ""}, {"market": "0x2649d46f6793c9847cc30659f7bcbec94578a23eda4c8cb86f31473173561986", "asset_id": "36826320465768064966532909273686181587790905146292730121626683737598046568291", "timestamp": "1769384418506", "hash": "3d0ef90e6d711678c88d0cb91b102c7ce2f25819", "bids": [{"price": "0.001", "size": "16477"}, {"price": "0.002", "size": "2014.19"}, {"price": "0.003", "size": "84.44"}, {"price": "0.01", "size": "1700"}, {"price": "0.011", "size": "400"}, {"price": "0.012", "size": "226.04"}, {"price": "0.013", "size": "126.04"}, {"price": "0.014", "size": "176"}, {"price": "0.015", "size": "26.04"}], "asks": [{"price": "0.999", "size": "3860.86"}, {"price": "0.998", "size": "1255.84"}, {"price": "0.997", "size": "1400"}, {"price": "0.996", "size": "10.1"}, {"price": "0.994", "size": "200"}, {"price": "0.99", "size": "5500"}, {"price": "0.989", "size": "5.13"}, {"price": "0.98", "size": "2200"}, {"price": "0.979", "size": "9.72"}, {"price": "0.95", "size": "30"}, {"price": "0.949", "size": "39"}, {"price": "0.938", "size": "5864"}, {"price": "0.937", "size": "9.55"}, {"price": "0.9", "size": "360"}, {"price": "0.85", "size": "776.66"}, {"price": "0.8", "size": "660"}, {"price": "0.799", "size": "5.37"}, {"price": "0.75", "size": "409"}, {"price": "0.7", "size": "186.66"}, {"price": "0.697", "size": "100"}, {"price": "0.696", "size": "50"}, {"price": "0.65", "size": "68.57"}, {"price": "0.6", "size": "143"}, {"price": "0.599", "size": "5"}, {"price": "0.379", "size": "100"}, {"price": "0.31", "size": "13.33"}, {"price": "0.306", "size": "30"}, {"price": "0.305", "size": "30"}, {"price": "0.303", "size": "10"}, {"price": "0.3", "size": "25"}, {"price": "0.299", "size": "20"}, {"price": "0.125", "size": "78.11"}, {"price": "0.12", "size": "10.5"}, {"price": "0.062", "size": "25"}, {"price": "0.061", "size": "10"}], "event_type": "book", "last_trade_price": ""}, {"market": "0xad1f282f187c4748fe6eb51153a39557c66856cd14408bc3d509d3b23c047d41", "asset_id": "86814839478893548397184492422021698202794732526767012779986423826365559163504", "timestamp": "1769384396610", "hash": "4230f665fa89d502fc5fbacbeaa2831a100d1164", "bids": [{"price": "0.01", "size": "7000"}, {"price": "0.02", "size": "1000"}, {"price": "0.04", "size": "4990.14"}, {"price": "0.08", "size": "2800"}, {"price": "0.14", "size": "550"}, {"price": "0.2", "size": "466.66"}, {"price": "0.22", "size": "100"}, {"price": "0.24", "size": "200"}, {"price": "0.38", "size": "66.66"}, {"price": "0.42", "size": "30.95"}, {"price": "0.43", "size": "25.58"}, {"price": "0.49", "size": "100"}, {"price": "0.51", "size": "80"}, {"price": "0.54", "size": "81.44"}], "asks": [{"price": "0.99", "size": "3514.94"}, {"price": "0.98", "size": "4546"}, {"price": "0.97", "size": "259.24"}, {"price": "0.96", "size": "50"}, {"price": "0.95", "size": "10"}, {"price": "0.94", "size": "6.82"}, {"price": "0.89", "size": "225"}, {"price": "0.88", "size": "9.7"}, {"price": "0.82", "size": "695.54"}, {"price": "0.81", "size": "66.66"}, {"price": "0.72", "size": "39.28"}, {"price": "0.71", "size": "44.82"}, {"price": "0.7", "size": "136.66"}, {"price": "0.69", "size": "50"}, {"price": "0.66", "size": "29"}, {"price": "0.65", "size": "66.66"}], "event_type": "book", "last_trade_price": ""}, {"market": "0x16478811d537afdfadaacef3bf1fc8b61ed86385968321b7d9250bdce2a49748", "asset_id": "19197134752918366634342328847356807761591702594573815533235857894615009285668", "timestamp": "1769384358588", "hash": "ff06677039a4d6cbeafc7858909165713fb38929", "bids": [{"price": "0.001", "size": "19336"}, {"price": "0.002", "size": "112.32"}, {"price": "0.01", "size": "750"}, {"price": "0.011", "size": "400"}, {"price": "0.012", "size": "116.66"}, {"price": "0.013", "size": "100"}, {"price": "0.014", "size": "182.66"}, {"price": "0.015", "size": "41.66"}], "asks": [{"price": "0.999", "size": "3989.6"}, {"price": "0.998", "size": "1255.85"}, {"price": "0.997", "size": "1400"}, {"price": "0.996", "size": "10.13"}, {"price": "0.994", "size": "200"}, {"price": "0.99", "size": "5500"}, {"price": "0.989", "size": "5.15"}, {"price": "0.98", "size": "2200"}, {"price": "0.979", "size": "11.31"}, {"price": "0.95", "size": "30"}, {"price": "0.949", "size": "39"}, {"price": "0.938", "size": "5853"}, {"price": "0.937", "size": "8.92"}, {"price": "0.9", "size": "360"}, {"price": "0.85", "size": "776.66"}, {"price": "0.8", "size": "660"}, {"price": "0.799", "size": "5.4"}, {"price": "0.75", "size": "212"}, {"price": "0.7", "size": "336.66"}, {"price": "0.699", "size": "100"}, {"price": "0.651", "size": "150"}, {"price": "0.65", "size": "68.57"}, {"price": "0.649", "size": "34"}, {"price": "0.6", "size": "82"}, {"price": "0.599", "size": "5"}, {"price": "0.36", "size": "105"}, {"price": "0.26", "size": "5"}, {"price": "0.233", "size": "10"}, {"price": "0.229", "size": "30"}, {"price": "0.227", "size": "25"}, {"price": "0.226", "size": "20"}, {"price": "0.166", "size": "20"}, {"price": "0.165", "size": "20"}, {"price": "0.164", "size": "30"}, {"price": "0.124", "size": "127.24"}, {"price": "0.072", "size": "25"}, {"price": "0.071", "size": "10"}], "event_type": "book", "last_trade_price": ""}, {"market": "0x23e782e8db3eb990b48ff37432f9f0899e73ea737e68d2934bd09b34934dc0d0", "asset_id": "35728543926876832227758010997325479102150155332621985448512538195119929531554", "timestamp": "1769384428180", "hash": "631109c17929d4ba8e737fa801b8dc52b0332eee", "bids": [{"price": "0.001", "size": "16767.11"}, {"price": "0.002", "size": "676.29"}, {"price": "0.003", "size": "39.31"}, {"price": "0.004", "size": "16.11"}, {"price": "0.01", "size": "1500"}, {"price": "0.011", "size": "400"}, {"price": "0.012", "size": "225.87"}, {"price": "0.013", "size": "124.36"}, {"price": "0.015", "size": "169.2"}, {"price": "0.017", "size": "24.36"}, {"price": "0.02", "size": "59.23"}], "asks": [{"price": "0.999", "size": "3393.92"}, {"price": "0.998", "size": "1255.9"}, {"price": "0.997", "size": "1166"}, {"price": "0.996", "size": "10.2"}, {"price": "0.994", "size": "83"}, {"price": "0.99", "size": "5500"}, {"price": "0.989", "size": "5.18"}, {"price": "0.98", "size": "1000"}, {"price": "0.974", "size": "7279"}, {"price": "0.973", "size": "7.36"}, {"price": "0.95", "size": "30"}, {"price": "0.949", "size": "39"}, {"price": "0.94", "size": "500"}, {"price": "0.939", "size": "7.9"}, {"price": "0.89", "size": "225"}, {"price": "0.839", "size": "395"}, {"price": "0.838", "size": "7.43"}, {"price": "0.79", "size": "150"}, {"price": "0.719", "size": "7"}, {"price": "0.718", "size": "666"}, {"price": "0.434", "size": "100"}, {"price": "0.361", "size": "30"}, {"price": "0.359", "size": "10"}, {"price": "0.357", "size": "25"}, {"price": "0.356", "size": "20"}, {"price": "0.168", "size": "5"}, {"price": "0.167", "size": "30"}, {"price": "0.15", "size": "21.33"}], "event_type": "book", "last_trade_price": ""}, {"market": "0xe7d699841d03f695da20c8935f4cdf809057f3b27fa4f382e327ff731b8d75a7", "asset_id": "40666723045616055650551965571535047681860486685123797401746526747593369094525", "timestamp": "1769384431891", "hash": "07106809f6059a79f8805945a81186d27c0aa338", "bids": [{"price": "0.01", "size": "1800"}, {"price": "0.02", "size": "425"}, {"price": "0.03", "size": "763.3"}], "asks": [{"price": "0.99", "size": "5553.42"}, {"price": "0.98", "size": "2200"}, {"price": "0.97", "size": "7.08"}, {"price": "0.95", "size": "30"}, {"price": "0.94", "size": "533"}, {"price": "0.93", "size": "8.48"}, {"price": "0.9", "size": "1160"}, {"price": "0.86", "size": "242.85"}, {"price": "0.85", "size": "550"}, {"price": "0.81", "size": "168.42"}, {"price": "0.8", "size": "400"}, {"price": "0.79", "size": "815.13"}, {"price": "0.77", "size": "1926"}, {"price": "0.76", "size": "116.66"}, {"price": "0.71", "size": "89.65"}, {"price": "0.7", "size": "250"}, {"price": "0.66", "size": "70.58"}, {"price": "0.62", "size": "52.63"}, {"price": "0.61", "size": "1588"}, {"price": "0.59", "size": "3971"}, {"price": "0.58", "size": "300"}, {"price": "0.51", "size": "169"}, {"price": "0.47", "size": "70"}, {"price": "0.46", "size": "5"}, {"price": "0.31", "size": "5"}, {"price": "0.19", "size": "73.33"}, {"price": "0.18", "size": "30"}, {"price": "0.08", "size": "50"}, {"price": "0.07", "size": "125"}, {"price": "0.06", "size": "580.01"}, {"price": "0.05", "size": "198"}], "event_type": "book", "last_trade_price": ""}]}
{"_local_timestamp": "2026-01-25T23:40:47.929595+00:00", "data": {"market": "0xad1f282f187c4748fe6eb51153a39557c66856cd14408bc3d509d3b23c047d41", "price_changes": [{"asset_id": "26089319074590795210476289468934414386490143191167179409102092139417103170837", "price": "0.35", "size": "86.66", "side": "BUY", "hash": "5465c614e76244fbb5860c1f821dabd1dd3fa785", "best_bid": "0.35", "best_ask": "0.46"}, {"asset_id": "86814839478893548397184492422021698202794732526767012779986423826365559163504", "price": "0.65", "size": "86.66", "side": "SELL", "hash": "f38ce5fc00bb422346290289b763492e39c22b9c", "best_bid": "0.54", "best_ask": "0.65"}], "timestamp": "1769384447845", "event_type": "price_change"}}
{"_local_timestamp": "2026-01-25T23:40:59.240490+00:00", "data": {"market": "0xfacaaf8ca81b788f8da594acaf23af2ef90037d82580b91357be35f97229e3a5", "price_changes": [{"asset_id": "49741609004781342711179849070128334110798460232218737742146637694522428416234", "price": "0.76", "size": "50", "side": "SELL", "hash": "bc1b971c915fd967b11a112e62bcd0d9fd2e2f17", "best_bid": "0.7", "best_ask": "0.74"}, {"asset_id": "94754153121378446077535791604860675458774881690932146680120328837949383988913", "price": "0.24", "size": "50", "side": "BUY", "hash": "32ac4f696aff2e0802ba6816d30bd0962e4fe3c1", "best_bid": "0.26", "best_ask": "0.3"}], "timestamp": "1769384459165", "event_type": "price_change"}}
{"_local_timestamp": "2026-01-25T23:40:59.265251+00:00", "data": {"market": "0xfacaaf8ca81b788f8da594acaf23af2ef90037d82580b91357be35f97229e3a5", "price_changes": [{"asset_id": "49741609004781342711179849070128334110798460232218737742146637694522428416234", "price": "0.76", "size": "100", "side": "SELL", "hash": "b01212c6942a7d4ae95fa804fcd401dad79a0de4", "best_bid": "0.7", "best_ask": "0.74"}, {"asset_id": "94754153121378446077535791604860675458774881690932146680120328837949383988913", "price": "0.24", "size": "100", "side": "BUY", "hash": "1704c379f9b9c7c597efd4742899b32332dbe1b4", "best_bid": "0.26", "best_ask": "0.3"}], "timestamp": "1769384459191", "event_type": "price_change"}}
{"_local_timestamp": "2026-01-25T23:40:59.384128+00:00", "data": {"market": "0xad1f282f187c4748fe6eb51153a39557c66856cd14408bc3d509d3b23c047d41", "price_changes": [{"asset_id": "26089319074590795210476289468934414386490143191167179409102092139417103170837", "price": "0.3", "size": "116.66", "side": "BUY", "hash": "a48b5a493bebcef8925cf4d066fbb9487791c02b", "best_bid": "0.35", "best_ask": "0.46"}, {"asset_id": "86814839478893548397184492422021698202794732526767012779986423826365559163504", "price": "0.7", "size": "116.66", "side": "SELL", "hash": "f4b90469b19752628ee1509f2da2f692ededd5c9", "best_bid": "0.54", "best_ask": "0.65"}], "timestamp": "1769384459313", "event_type": "price_change"}}
{"_local_timestamp": "2026-01-25T23:40:59.444481+00:00", "data": {"market": "0xad1f282f187c4748fe6eb51153a39557c66856cd14408bc3d509d3b23c047d41", "price_changes": [{"asset_id": "26089319074590795210476289468934414386490143191167179409102092139417103170837", "price": "0.2", "size": "25", "side": "BUY", "hash": "20020662ddc64e3a6c2bf0d2cb0b5fed9bc4678e", "best_bid": "0.35", "best_ask": "0.46"}, {"asset_id": "86814839478893548397184492422021698202794732526767012779986423826365559163504", "price": "0.8", "size": "25", "side": "SELL", "hash": "34a8eba93ad4ac1c9ae37784b0909a49cfc38e5e", "best_bid": "0.54", "best_ask": "0.65"}], "timestamp": "1769384459374", "event_type": "price_change"}}
{"_local_timestamp": "2026-01-25T23:40:59.446059+00:00", "data": {"market": "0xad1f282f187c4748fe6eb51153a39557c66856cd14408bc3d509d3b23c047d41", "price_changes": [{"asset_id": "26089319074590795210476289468934414386490143191167179409102092139417103170837", "price": "0.3", "size": "136.66", "side": "BUY", "hash": "4b921f9dde4681a63e990a5e6d1b40173be59bd3", "best_bid": "0.35", "best_ask": "0.46"}, {"asset_id": "86814839478893548397184492422021698202794732526767012779986423826365559163504", "price": "0.7", "size": "136.66", "side": "SELL", "hash": "2a11830a022bd87507f17241ef270338cab581ee", "best_bid": "0.54", "best_ask": "0.65"}], "timestamp": "1769384459375", "event_type": "price_change"}}
{"_local_timestamp": "2026-01-25T23:41:06.735683+00:00", "data": {"market": "0x16478811d537afdfadaacef3bf1fc8b61ed86385968321b7d9250bdce2a49748", "price_changes": [{"asset_id": "19197134752918366634342328847356807761591702594573815533235857894615009285668", "price": "0.011", "size": "300", "side": "BUY", "hash": "db66037cf144c84ad7b100e13dbc0291268a34ed", "best_bid": "0.015", "best_ask": "0.071"}, {"asset_id": "92269994048518357863385104036810846326684031835851654275504679077189526944972", "price": "0.989", "size": "300", "side": "SELL", "hash": "1871ddfb57ab1e43638ddc556d18aff883f3f7c6", "best_bid": "0.929", "best_ask": "0.985"}], "timestamp": "1769384466638", "event_type": "price_change"}}
{"_local_timestamp": "2026-01-25T23:41:06.813305+00:00", "data": {"market": "0x23e782e8db3eb990b48ff37432f9f0899e73ea737e68d2934bd09b34934dc0d0", "price_changes": [{"asset_id": "35728543926876832227758010997325479102150155332621985448512538195119929531554", "price": "0.011", "size": "300", "side": "BUY", "hash": "634ab6a5a89c0d3709a540a25ad0dbabf4c890dc", "best_bid": "0.02", "best_ask": "0.15"}, {"asset_id": "42382535584090931070184963017291726037912989687255284323203344679942164276749", "price": "0.989", "size": "300", "side": "SELL", "hash": "4bf4fedae42c3b6105a208fb8e4cfde41f112ddb", "best_bid": "0.85", "best_ask": "0.98"}], "timestamp": "1769384466639", "event_type": "price_change"}}
{"_local_timestamp": "2026-01-25T23:41:06.897617+00:00", "data": {"market": "0xeafc8d47725546039800fe78eb06c0af5d9f982134515b9250ea376b7c258afb", "price_changes": [{"asset_id": "39436446463164291051085103274433078121544260678753625430845203266295844561591", "price": "0.011", "size": "670.68", "side": "BUY", "hash": "6e1c5f0010e280389117a7a0fc9823e8d83db52d", "best_bid": "0.012", "best_ask": "0.014"}, {"asset_id": "102282495724728145503590068938456419856338447487625172072096551524174375085545", "price": "0.989", "size": "670.68", "side": "SELL", "hash": "2a499b83489b6189caa63181bac11daab999ea84", "best_bid": "0.986", "best_ask": "0.988"}], "timestamp": "1769384466655", "event_type": "price_change"}}
{"_local_timestamp": "2026-01-25T23:41:06.921466+00:00", "data": {"market": "0x2649d46f6793c9847cc30659f7bcbec94578a23eda4c8cb86f31473173561986", "price_changes": [{"asset_id": "36826320465768064966532909273686181587790905146292730121626683737598046568291", "price": "0.011", "size": "300", "side": "BUY", "hash": "65b1640406aae3f0b9dc4bc4712decc268b95b0b", "best_bid": "0.015", "best_ask": "0.061"}, {"asset_id": "37921534922010226146703074549600791269918801302227759309433381423805138270558", "price": "0.989", "size": "300", "side": "SELL", "hash": "ccb94e8b6e89740f8063d6af4f52008f3cad602c", "best_bid": "0.939", "best_ask": "0.985"}], "timestamp": "1769384466659", "event_type": "price_change"}}
{"_local_timestamp": "2026-01-25T23:41:14.737727+00:00", "data": {"market": "0xe7d699841d03f695da20c8935f4cdf809057f3b27fa4f382e327ff731b8d75a7", "price_changes": [{"asset_id": "86720801120812523206375862885554727968671842048571953285734439150624995757719", "price": "0.23", "size": "100", "side": "BUY", "hash": "d5e662c90c1921343891ed2820607d3a4d56b848", "best_bid": "0.95", "best_ask": "0.97"}, {"asset_id": "40666723045616055650551965571535047681860486685123797401746526747593369094525", "price": "0.77", "size": "100", "side": "SELL", "hash": "d2b28052bf76e0bcb5557f27560dd133f059148f", "best_bid": "0.03", "best_ask": "0.05"}], "timestamp": "1769384474536", "event_type": "price_change"}}
{"_local_timestamp": "2026-01-25T23:41:28.276790+00:00", "data": {"market": "0xe7d699841d03f695da20c8935f4cdf809057f3b27fa4f382e327ff731b8d75a7", "price_changes": [{"asset_id": "86720801120812523206375862885554727968671842048571953285734439150624995757719", "price": "0.22", "size": "1908", "side": "BUY", "hash": "c2010335e7878a9f7910c9aa1bfc334c3be7a2e7", "best_bid": "0.95", "best_ask": "0.97"}, {"asset_id": "40666723045616055650551965571535047681860486685123797401746526747593369094525", "price": "0.78", "size": "1908", "side": "SELL", "hash": "6e97e1d28a476a572b37ab165cfd9248d34540b6", "best_bid": "0.03", "best_ask": "0.05"}], "timestamp": "1769384488163", "event_type": "price_change"}}
{"_local_timestamp": "2026-01-25T23:41:37.941260+00:00", "data": {"market": "0x23e782e8db3eb990b48ff37432f9f0899e73ea737e68d2934bd09b34934dc0d0", "price_changes": [{"asset_id": "42382535584090931070184963017291726037912989687255284323203344679942164276749", "price": "0.87", "size": "20", "side": "BUY", "hash": "6de5f3e07c2e57784571d026cf5cc5ed9f0abcd7", "best_bid": "0.87", "best_ask": "0.98"}, {"asset_id": "35728543926876832227758010997325479102150155332621985448512538195119929531554", "price": "0.13", "size": "20", "side": "SELL", "hash": "474b0e5b5ca612d4f64e61717b27c3d19c2da443", "best_bid": "0.02", "best_ask": "0.13"}], "timestamp": "1769384497861", "event_type": "price_change"}}
{"_local_timestamp": "2026-01-25T23:41:37.950114+00:00", "data": {"market": "0xfacaaf8ca81b788f8da594acaf23af2ef90037d82580b91357be35f97229e3a5", "price_changes": [{"asset_id": "49741609004781342711179849070128334110798460232218737742146637694522428416234", "price": "0.63", "size": "20", "side": "BUY", "hash": "998736a4d84f6da9e3bf974a2a0c0e72bc018e34", "best_bid": "0.7", "best_ask": "0.74"}, {"asset_id": "94754153121378446077535791604860675458774881690932146680120328837949383988913", "price": "0.37", "size": "20", "side": "SELL", "hash": "cc761537e79cc61cfcb5b868a33810e26ca6c49e", "best_bid": "0.26", "best_ask": "0.3"}], "timestamp": "1769384497884", "event_type": "price_change"}}
{"_local_timestamp": "2026-01-25T23:41:49.489264+00:00", "data": {"market": "0xe7d699841d03f695da20c8935f4cdf809057f3b27fa4f382e327ff731b8d75a7", "price_changes": [{"asset_id": "86720801120812523206375862885554727968671842048571953285734439150624995757719", "price": "0.23", "size": "0", "side": "BUY", "hash": "af040a87c3bd2ef13e0039c11b2ece8eaa203afc", "best_bid": "0.95", "best_ask": "0.97"}, {"asset_id": "40666723045616055650551965571535047681860486685123797401746526747593369094525", "price": "0.77", "size": "0", "side": "SELL", "hash": "2f602914c4e26b45f524196b3169e5fe1b86fa9c", "best_bid": "0.03", "best_ask": "0.05"}], "timestamp": "1769384509408", "event_type": "price_change"}}
{"_local_timestamp": "2026-01-25T23:41:49.790746+00:00", "data": {"market": "0xe7d699841d03f695da20c8935f4cdf809057f3b27fa4f382e327ff731b8d75a7", "price_changes": [{"asset_id": "86720801120812523206375862885554727968671842048571953285734439150624995757719", "price": "0.21", "size": "915.13", "side": "BUY", "hash": "7779c817a9e9e1438b0aa1dcc537e414d657b134", "best_bid": "0.95", "best_ask": "0.97"}, {"asset_id": "40666723045616055650551965571535047681860486685123797401746526747593369094525", "price": "0.79", "size": "915.13", "side": "SELL", "hash": "4ca945cb9bbd084c1bb2e4abd5dc7e3240027a0f", "best_bid": "0.03", "best_ask": "0.05"}], "timestamp": "1769384509669", "event_type": "price_change"}}
{"_local_timestamp": "2026-01-25T23:41:50.914854+00:00", "data": {"market": "0xe7d699841d03f695da20c8935f4cdf809057f3b27fa4f382e327ff731b8d75a7", "price_changes": [{"asset_id": "86720801120812523206375862885554727968671842048571953285734439150624995757719", "price": "0.3", "size": "150", "side": "BUY", "hash": "5ba9ed713b612dbbbc61d71ed0d8fb0873c01a76", "best_bid": "0.95", "best_ask": "0.97"}, {"asset_id": "40666723045616055650551965571535047681860486685123797401746526747593369094525", "price": "0.7", "size": "150", "side": "SELL", "hash": "4d30bb3e84b3f9988393b2eaeb71354f8936b116", "best_bid": "0.03", "best_ask": "0.05"}], "timestamp": "1769384510753", "event_type": "price_change"}}
{"_local_timestamp": "2026-01-25T23:41:50.924575+00:00", "data": {"market": "0xad1f282f187c4748fe6eb51153a39557c66856cd14408bc3d509d3b23c047d41", "price_changes": [{"asset_id": "86814839478893548397184492422021698202794732526767012779986423826365559163504", "price": "0.24", "size": "100", "side": "BUY", "hash": "51408243129f108eeb1bc4e94a959a352b006c82", "best_bid": "0.54", "best_ask": "0.65"}, {"asset_id": "26089319074590795210476289468934414386490143191167179409102092139417103170837", "price": "0.76", "size": "100", "side": "SELL", "hash": "069a0a7e4fe9326374c0eefe1297793ceb3bc8cf", "best_bid": "0.35", "best_ask": "0.46"}], "timestamp": "1769384510753", "event_type": "price_change"}}
{"_local_timestamp": "2026-01-25T23:41:51.199794+00:00", "data": {"market": "0x2649d46f6793c9847cc30659f7bcbec94578a23eda4c8cb86f31473173561986", "price_changes": [{"asset_id": "37921534922010226146703074549600791269918801302227759309433381423805138270558", "price": "0.7", "size": "0", "side": "BUY", "hash": "12a808f85d297b7c98bb1107bcc06e2ae372055c", "best_bid": "0.939", "best_ask": "0.985"}, {"asset_id": "36826320465768064966532909273686181587790905146292730121626683737598046568291", "price": "0.3", "size": "0", "side": "SELL", "hash": "81ad884e5a06b49d2f5a9b564f6c7e15c533a6fe", "best_bid": "0.015", "best_ask": "0.061"}], "timestamp": "1769384511103", "event_type": "price_change"}}
{"_local_timestamp": "2026-01-25T23:41:52.439467+00:00", "data": {"market": "0x2649d46f6793c9847cc30659f7bcbec94578a23eda4c8cb86f31473173561986", "price_changes": [{"asset_id": "37921534922010226146703074549600791269918801302227759309433381423805138270558", "price": "0.701", "size": "0", "side": "BUY", "hash": "f9cb312d5b69da84e52045886d4dfdc34fd86022", "best_bid": "0.939", "best_ask": "0.985"}, {"asset_id": "36826320465768064966532909273686181587790905146292730121626683737598046568291", "price": "0.299", "size": "0", "side": "SELL", "hash": "445090d244331c66d950ed141cc504d485eef942", "best_bid": "0.015", "best_ask": "0.061"}], "timestamp": "1769384512368", "event_type": "price_change"}}
{"_local_timestamp": "2026-01-25T23:41:52.483159+00:00", "data": {"market": "0x2649d46f6793c9847cc30659f7bcbec94578a23eda4c8cb86f31473173561986", "price_changes": [{"asset_id": "37921534922010226146703074549600791269918801302227759309433381423805138270558", "price": "0.698", "size": "20", "side": "BUY", "hash": "dc8fddbe073015bd01b89a63645308b6f7c72ac0", "best_bid": "0.939", "best_ask": "0.985"}, {"asset_id": "36826320465768064966532909273686181587790905146292730121626683737598046568291", "price": "0.302", "size": "20", "side": "SELL", "hash": "7a98317ddd121ef0dce20eee1de5633d15a60e83", "best_bid": "0.015", "best_ask": "0.061"}], "timestamp": "1769384512402", "event_type": "price_change"}}
{"_local_timestamp": "2026-01-25T23:41:52.717191+00:00", "data": {"market": "0xad1f282f187c4748fe6eb51153a39557c66856cd14408bc3d509d3b23c047d41", "price_changes": [{"asset_id": "86814839478893548397184492422021698202794732526767012779986423826365559163504", "price": "0.22", "size": "200", "side": "BUY", "hash": "2089f163485f73bd0f5f222886162e4527d66760", "best_bid": "0.54", "best_ask": "0.65"}, {"asset_id": "26089319074590795210476289468934414386490143191167179409102092139417103170837", "price": "0.78", "size": "200", "side": "SELL", "hash": "297f18dcc5a9b3709381a2470bc97d744c8c4954", "best_bid": "0.35", "best_ask": "0.46"}], "timestamp": "1769384511765", "event_type": "price_change"}}
{"_local_timestamp": "2026-01-25T23:41:52.918823+00:00", "data": {"market": "0xe7d699841d03f695da20c8935f4cdf809057f3b27fa4f382e327ff731b8d75a7", "price_changes": [{"asset_id": "86720801120812523206375862885554727968671842048571953285734439150624995757719", "price": "0.23", "size": "100", "side": "BUY", "hash": "fe15bb1f78ffc2cc2c0a541fe7835756af6cfca1", "best_bid": "0.95", "best_ask": "0.97"}, {"asset_id": "40666723045616055650551965571535047681860486685123797401746526747593369094525", "price": "0.77", "size": "100", "side": "SELL", "hash": "f8ed1ced49e26ccb8ee23295b03c33db6ae070f7", "best_bid": "0.03", "best_ask": "0.05"}], "timestamp": "1769384511846", "event_type": "price_change"}}
{"_local_timestamp": "2026-01-25T23:42:24.739588+00:00", "data": {"market": "0xe7d699841d03f695da20c8935f4cdf809057f3b27fa4f382e327ff731b8d75a7", "price_changes": [{"asset_id": "86720801120812523206375862885554727968671842048571953285734439150624995757719", "price": "0.3", "size": "100", "side": "BUY", "hash": "ac45a7e6533b9924af157a95006dde684fa0c215", "best_bid": "0.95", "best_ask": "0.97"}, {"asset_id": "40666723045616055650551965571535047681860486685123797401746526747593369094525", "price": "0.7", "size": "100", "side": "SELL", "hash": "3bece25914ffc3466af3dea7bad65fe4ad7da471", "best_bid": "0.03", "best_ask": "0.05"}], "timestamp": "1769384544488", "event_type": "price_change"}}
{"_local_timestamp": "2026-01-25T23:42:24.839659+00:00", "data": {"market": "0x23e782e8db3eb990b48ff37432f9f0899e73ea737e68d2934bd09b34934dc0d0", "price_changes": [{"asset_id": "42382535584090931070184963017291726037912989687255284323203344679942164276749", "price": "0.87", "size": "46", "side": "BUY", "hash": "dabad23244e5d2e73891db2b46a745c38ecbafcd", "best_bid": "0.87", "best_ask": "0.98"}, {"asset_id": "35728543926876832227758010997325479102150155332621985448512538195119929531554", "price": "0.13", "size": "46", "side": "SELL", "hash": "b93f2cadc4d7b8ffb35883e183c2a98567a1ab2b", "best_bid": "0.02", "best_ask": "0.13"}], "timestamp": "1769384544616", "event_type": "price_change"}}
{"_local_timestamp": "2026-01-25T23:42:24.840922+00:00", "data": {"market": "0x2649d46f6793c9847cc30659f7bcbec94578a23eda4c8cb86f31473173561986", "price_changes": [{"asset_id": "37921534922010226146703074549600791269918801302227759309433381423805138270558", "price": "0.874", "size": "41", "side": "BUY", "hash": "1337ccd127cb78ab9c2dd2659fd468aac46c1060", "best_bid": "0.939", "best_ask": "0.985"}, {"asset_id": "36826320465768064966532909273686181587790905146292730121626683737598046568291", "price": "0.126", "size": "41", "side": "SELL", "hash": "4d6414fc6e75bd0bc2488f12e32581305a391d83", "best_bid": "0.015", "best_ask": "0.061"}], "timestamp": "1769384544617", "event_type": "price_change"}}
{"_local_timestamp": "2026-01-25T23:42:24.842005+00:00", "data": {"market": "0xe7d699841d03f695da20c8935f4cdf809057f3b27fa4f382e327ff731b8d75a7", "price_changes": [{"asset_id": "86720801120812523206375862885554727968671842048571953285734439150624995757719", "price": "0.86", "size": "26", "side": "BUY", "hash": "fe4987538c41e52aea682fddd2fd4bd2012325fc", "best_bid": "0.95", "best_ask": "0.97"}, {"asset_id": "40666723045616055650551965571535047681860486685123797401746526747593369094525", "price": "0.14", "size": "26", "side": "SELL", "hash": "ee6853dd0e9c8e53b2053a7f9309f9a3941f489f", "best_bid": "0.03", "best_ask": "0.05"}], "timestamp": "1769384544618", "event_type": "price_change"}}
{"_local_timestamp": "2026-01-25T23:42:24.843181+00:00", "data": {"market": "0x16478811d537afdfadaacef3bf1fc8b61ed86385968321b7d9250bdce2a49748", "price_changes": [{"asset_id": "92269994048518357863385104036810846326684031835851654275504679077189526944972", "price": "0.874", "size": "26", "side": "BUY", "hash": "1e01d644e2890b15565fad8e73372aedb85db6ca", "best_bid": "0.929", "best_ask": "0.985"}, {"asset_id": "19197134752918366634342328847356807761591702594573815533235857894615009285668", "price": "0.126", "size": "26", "side": "SELL", "hash": "d64e2e46b84eb5a745454faee58c25f498254fd5", "best_bid": "0.015", "best_ask": "0.071"}], "timestamp": "1769384544620", "event_type": "price_change"}}
{"_local_timestamp": "2026-01-25T23:42:24.844279+00:00", "data": {"market": "0xeafc8d47725546039800fe78eb06c0af5d9f982134515b9250ea376b7c258afb", "price_changes": [{"asset_id": "102282495724728145503590068938456419856338447487625172072096551524174375085545", "price": "0.878", "size": "26", "side": "BUY", "hash": "a378b46f5abe45df883f3e86af0f17b3b3c26003", "best_bid": "0.986", "best_ask": "0.988"}, {"asset_id": "39436446463164291051085103274433078121544260678753625430845203266295844561591", "price": "0.122", "size": "26", "side": "SELL", "hash": "23c6df0af4290f7902813f452e3ea28a79462f62", "best_bid": "0.012", "best_ask": "0.014"}], "timestamp": "1769384544623", "event_type": "price_change"}}
{"_local_timestamp": "2026-01-25T23:42:24.875993+00:00", "data": {"market": "0x23e782e8db3eb990b48ff37432f9f0899e73ea737e68d2934bd09b34934dc0d0", "price_changes": [{"asset_id": "42382535584090931070184963017291726037912989687255284323203344679942164276749", "price": "0.639", "size": "0", "side": "BUY", "hash": "bfe0c4e8d3a423a3266fefa08e2715ce81356146", "best_bid": "0.87", "best_ask": "0.98"}, {"asset_id": "35728543926876832227758010997325479102150155332621985448512538195119929531554", "price": "0.361", "size": "0", "side": "SELL", "hash": "b48ce9cbc10f6c3dbd9432930dc7cfe1ac2eb63e", "best_bid": "0.02", "best_ask": "0.13"}], "timestamp": "1769384544683", "event_type": "price_change"}}
{"_local_timestamp": "2026-01-25T23:42:24.973225+00:00", "data": {"market": "0x23e782e8db3eb990b48ff37432f9f0899e73ea737e68d2934bd09b34934dc0d0", "price_changes": [{"asset_id": "42382535584090931070184963017291726037912989687255284323203344679942164276749", "price": "0.645", "size": "30", "side": "BUY", "hash": "7cb5f1325fbdaa12b71c916433b7e0b1ccfd7c18", "best_bid": "0.87", "best_ask": "0.98"}, {"asset_id": "35728543926876832227758010997325479102150155332621985448512538195119929531554", "price": "0.355", "size": "30", "side": "SELL", "hash": "9b9c785a722c6807502953482d386592436b6d97", "best_bid": "0.02", "best_ask": "0.13"}], "timestamp": "1769384544831", "event_type": "price_change"}}
{"_local_timestamp": "2026-01-25T23:42:25.011940+00:00", "data": {"market": "0xad1f282f187c4748fe6eb51153a39557c66856cd14408bc3d509d3b23c047d41", "price_changes": [{"asset_id": "86814839478893548397184492422021698202794732526767012779986423826365559163504", "price": "0.24", "size": "0", "side": "BUY", "hash": "7e7208c8951675e3313c643531dab2ee954241d1", "best_bid": "0.54", "best_ask": "0.65"}, {"asset_id": "26089319074590795210476289468934414386490143191167179409102092139417103170837", "price": "0.76", "size": "0", "side": "SELL", "hash": "edf8a1510b524d69c1c3ad941484610ced842b02", "best_bid": "0.35", "best_ask": "0.46"}], "timestamp": "1769384544877", "event_type": "price_change"}}
{"_local_timestamp": "2026-01-25T23:42:25.015611+00:00", "data": {"market": "0xe7d699841d03f695da20c8935f4cdf809057f3b27fa4f382e327ff731b8d75a7", "price_changes": [{"asset_id": "86720801120812523206375862885554727968671842048571953285734439150624995757719", "price": "0.21", "size": "815.13", "side": "BUY", "hash": "f309f6c15c0e6ad7d2141c19dbade5d19dadf9f9", "best_bid": "0.95", "best_ask": "0.97"}, {"asset_id": "40666723045616055650551965571535047681860486685123797401746526747593369094525", "price": "0.79", "size": "815.13", "side": "SELL", "hash": "2cef7be40f2ed54b4fdffd47a01b5114843f893e", "best_bid": "0.03", "best_ask": "0.05"}], "timestamp": "1769384544877", "event_type": "price_change"}}
{"_local_timestamp": "2026-01-25T23:42:25.076006+00:00", "data": {"market": "0x16478811d537afdfadaacef3bf1fc8b61ed86385968321b7d9250bdce2a49748", "price_changes": [{"asset_id": "92269994048518357863385104036810846326684031835851654275504679077189526944972", "price": "0.773", "size": "15", "side": "BUY", "hash": "a4886d2128019ea60345a824dda903a0c9efed94", "best_bid": "0.929", "best_ask": "0.985"}, {"asset_id": "19197134752918366634342328847356807761591702594573815533235857894615009285668", "price": "0.227", "size": "15", "side": "SELL", "hash": "d026e69e33faf620a8aa04c51a49465f40f2483c", "best_bid": "0.015", "best_ask": "0.071"}], "timestamp": "1769384544925", "event_type": "price_change"}}
{"_local_timestamp": "2026-01-25T23:42:25.117324+00:00", "data": {"market": "0xe7d699841d03f695da20c8935f4cdf809057f3b27fa4f382e327ff731b8d75a7", "price_changes": [{"asset_id": "86720801120812523206375862885554727968671842048571953285734439150624995757719", "price": "0.23", "size": "150", "side": "BUY", "hash": "8eaa10fdfc075a0a34b34ab4d4668ed08828ba42", "best_bid": "0.95", "best_ask": "0.97"}, {"asset_id": "40666723045616055650551965571535047681860486685123797401746526747593369094525", "price": "0.77", "size": "150", "side": "SELL", "hash": "2991ab435c9b179ffd3382fabee4d0bfd40b535b", "best_bid": "0.03", "best_ask": "0.05"}], "timestamp": "1769384544918", "event_type": "price_change"}}
{"_local_timestamp": "2026-01-25T23:42:25.288242+00:00", "data": {"market": "0xe7d699841d03f695da20c8935f4cdf809057f3b27fa4f382e327ff731b8d75a7", "price_changes": [{"asset_id": "86720801120812523206375862885554727968671842048571953285734439150624995757719", "price": "0.22", "size": "2008", "side": "BUY", "hash": "5c34201599bf8c68717819b37ae437bd69ef3312", "best_bid": "0.95", "best_ask": "0.97"}, {"asset_id": "40666723045616055650551965571535047681860486685123797401746526747593369094525", "price": "0.78", "size": "2008", "side": "SELL", "hash": "efbf9440bc0122082dc087c4051149144cfa09be", "best_bid": "0.03", "best_ask": "0.05"}], "timestamp": "1769384545149", "event_type": "price_change"}}
{"_local_timestamp": "2026-01-25T23:42:25.309049+00:00", "data": {"market": "0xad1f282f187c4748fe6eb51153a39557c66856cd14408bc3d509d3b23c047d41", "price_changes": [{"asset_id": "86814839478893548397184492422021698202794732526767012779986423826365559163504", "price": "0.22", "size": "300", "side": "BUY", "hash": "9500b1eff10ce172f710e1c117a95c2de51d0dea", "best_bid": "0.54", "best_ask": "0.65"}, {"asset_id": "26089319074590795210476289468934414386490143191167179409102092139417103170837", "price": "0.78", "size": "300", "side": "SELL", "hash": "77c9757e0a1bd49095fbef6aa4c3191f7e403036", "best_bid": "0.35", "best_ask": "0.46"}], "timestamp": "1769384545151", "event_type": "price_change"}}
{"_local_timestamp": "2026-01-25T23:42:25.435917+00:00", "data": {"market": "0x16478811d537afdfadaacef3bf1fc8b61ed86385968321b7d9250bdce2a49748", "price_changes": [{"asset_id": "92269994048518357863385104036810846326684031835851654275504679077189526944972", "price": "0.773", "size": "0", "side": "BUY", "hash": "d4dbf19e3f05f138a272c90a598d0c4982b14f6e", "best_bid": "0.929", "best_ask": "0.985"}, {"asset_id": "19197134752918366634342328847356807761591702594573815533235857894615009285668", "price": "0.227", "size": "0", "side": "SELL", "hash": "85ec4b7174eee9452dd48f9bea4c02d8e80e88d7", "best_bid": "0.015", "best_ask": "0.071"}], "timestamp": "1769384545292", "event_type": "price_change"}}
{"_local_timestamp": "2026-01-25T23:42:26.594768+00:00", "data": {"market": "0x23e782e8db3eb990b48ff37432f9f0899e73ea737e68d2934bd09b34934dc0d0", "price_changes": [{"asset_id": "42382535584090931070184963017291726037912989687255284323203344679942164276749", "price": "0.644", "size": "0", "side": "BUY", "hash": "483ec7e5e2c93f7728030062c6ff8ed3bea43a29", "best_bid": "0.87", "best_ask": "0.98"}, {"asset_id": "35728543926876832227758010997325479102150155332621985448512538195119929531554", "price": "0.356", "size": "0", "side": "SELL", "hash": "2f7ef638ac25377a6af93661fe4225d56e6abeba", "best_bid": "0.02", "best_ask": "0.13"}], "timestamp": "1769384546460", "event_type": "price_change"}}
{"_local_timestamp": "2026-01-25T23:42:26.600370+00:00", "data": {"market": "0x16478811d537afdfadaacef3bf1fc8b61ed86385968321b7d9250bdce2a49748", "price_changes": [{"asset_id": "92269994048518357863385104036810846326684031835851654275504679077189526944972", "price": "0.774", "size": "0", "side": "BUY", "hash": "6a8062f10262e34c49630f341d48844ba6ada588", "best_bid": "0.929", "best_ask": "0.985"}, {"asset_id": "19197134752918366634342328847356807761591702594573815533235857894615009285668", "price": "0.226", "size": "0", "side": "SELL", "hash": "1c7cc699ca73cf9711ea3ad307754e945020059e", "best_bid": "0.015", "best_ask": "0.071"}], "timestamp": "1769384546460", "event_type": "price_change"}}
{"_local_timestamp": "2026-01-25T23:42:26.625007+00:00", "data": {"market": "0x23e782e8db3eb990b48ff37432f9f0899e73ea737e68d2934bd09b34934dc0d0", "price_changes": [{"asset_id": "42382535584090931070184963017291726037912989687255284323203344679942164276749", "price": "0.646", "size": "20", "side": "BUY", "hash": "6409f2def2e57eded5a60c339c4a80fec216ae5d", "best_bid": "0.87", "best_ask": "0.98"}, {"asset_id": "35728543926876832227758010997325479102150155332621985448512538195119929531554", "price": "0.354", "size": "20", "side": "SELL", "hash": "3fe6166e2bc5af7e83a54bb666ec98b4a84f4df2", "best_bid": "0.02", "best_ask": "0.13"}], "timestamp": "1769384546489", "event_type": "price_change"}}
{"_local_timestamp": "2026-01-25T23:42:26.626139+00:00", "data": {"market": "0x16478811d537afdfadaacef3bf1fc8b61ed86385968321b7d9250bdce2a49748", "price_changes": [{"asset_id": "92269994048518357863385104036810846326684031835851654275504679077189526944972", "price": "0.772", "size": "20", "side": "BUY", "hash": "4271ba7dfe1a6b6a2ba6ed61a091be140cc7e249", "best_bid": "0.929", "best_ask": "0.985"}, {"asset_id": "19197134752918366634342328847356807761591702594573815533235857894615009285668", "price": "0.228", "size": "20", "side": "SELL", "hash": "f9bfd6a1062d450bf3ed2ca67ee6f4a72ce7d7d1", "best_bid": "0.015", "best_ask": "0.071"}], "timestamp": "1769384546489", "event_type": "price_change"}}
{"_local_timestamp": "2026-01-25T23:42:43.406301+00:00", "data": {"market": "0xeafc8d47725546039800fe78eb06c0af5d9f982134515b9250ea376b7c258afb", "price_changes": [{"asset_id": "102282495724728145503590068938456419856338447487625172072096551524174375085545", "price": "0.839", "size": "0", "side": "BUY", "hash": "e54f5028a4fdb0096e4f9a581094ce4e8227f112", "best_bid": "0.986", "best_ask": "0.988"}, {"asset_id": "39436446463164291051085103274433078121544260678753625430845203266295844561591", "price": "0.161", "size": "0", "side": "SELL", "hash": "b688cfe41a72b1563a7fc7cdcbfbf752f1cdcf1d", "best_bid": "0.012", "best_ask": "0.014"}], "timestamp": "1769384563259", "event_type": "price_change"}}
{"_local_timestamp": "2026-01-25T23:42:43.476100+00:00", "data": {"market": "0xeafc8d47725546039800fe78eb06c0af5d9f982134515b9250ea376b7c258afb", "price_changes": [{"asset_id": "102282495724728145503590068938456419856338447487625172072096551524174375085545", "price": "0.84", "size": "0", "side": "BUY", "hash": "0dea2f6397298d8b9b3b912d8b81931214a67705", "best_bid": "0.986", "best_ask": "0.988"}, {"asset_id": "39436446463164291051085103274433078121544260678753625430845203266295844561591", "price": "0.16", "size": "0", "side": "SELL", "hash": "2716e709bd4a84210804ec4d1874fc51e60e2f9a", "best_bid": "0.012", "best_ask": "0.014"}], "timestamp": "1769384563330", "event_type": "price_change"}}
{"_local_timestamp": "2026-01-25T23:42:43.544126+00:00", "data": {"market": "0xeafc8d47725546039800fe78eb06c0af5d9f982134515b9250ea376b7c258afb", "price_changes": [{"asset_id": "102282495724728145503590068938456419856338447487625172072096551524174375085545", "price": "0.842", "size": "50", "side": "BUY", "hash": "dde12c77973b4b716cc878bc32cce9433d5dc08e", "best_bid": "0.986", "best_ask": "0.988"}, {"asset_id": "39436446463164291051085103274433078121544260678753625430845203266295844561591", "price": "0.158", "size": "50", "side": "SELL", "hash": "da995dbcea1e9f3f14c7cba02a3db61209019531", "best_bid": "0.012", "best_ask": "0.014"}], "timestamp": "1769384563398", "event_type": "price_change"}}
{"_local_timestamp": "2026-01-25T23:42:43.582902+00:00", "data": {"market": "0xeafc8d47725546039800fe78eb06c0af5d9f982134515b9250ea376b7c258afb", "price_changes": [{"asset_id": "102282495724728145503590068938456419856338447487625172072096551524174375085545", "price": "0.84", "size": "13.33", "side": "BUY", "hash": "ee81c13423e637d5d3e73f1179fe2e2e569f33eb", "best_bid": "0.986", "best_ask": "0.988"}, {"asset_id": "39436446463164291051085103274433078121544260678753625430845203266295844561591", "price": "0.16", "size": "13.33", "side": "SELL", "hash": "6d7b3a92ed22df3fb202de1341f1de30acd4dccf", "best_bid": "0.012", "best_ask": "0.014"}], "timestamp": "1769384563444", "event_type": "price_change"}}
{"_local_timestamp": "2026-01-25T23:42:43.635458+00:00", "data": {"market": "0x16478811d537afdfadaacef3bf1fc8b61ed86385968321b7d9250bdce2a49748", "price_changes": [{"asset_id": "92269994048518357863385104036810846326684031835851654275504679077189526944972", "price": "0.767", "size": "0", "side": "BUY", "hash": "590b242e507a6bba2a8ea7688f4b6c91dbb85f06", "best_bid": "0.929", "best_ask": "0.985"}, {"asset_id": "19197134752918366634342328847356807761591702594573815533235857894615009285668", "price": "0.233", "size": "0", "side": "SELL", "hash": "4f561faf1948fd95ef432e07bbb061769bc9c93d", "best_bid": "0.015", "best_ask": "0.071"}], "timestamp": "1769384563496", "event_type": "price_change"}}
{"_local_timestamp": "2026-01-25T23:42:44.343221+00:00", "data": {"market": "0x16478811d537afdfadaacef3bf1fc8b61ed86385968321b7d9250bdce2a49748", "price_changes": [{"asset_id": "92269994048518357863385104036810846326684031835851654275504679077189526944972", "price": "0.835", "size": "0", "side": "BUY", "hash": "fd70bd0e12ff948f60d6cd9801f3c9cda0e6ad10", "best_bid": "0.929", "best_ask": "0.985"}, {"asset_id": "19197134752918366634342328847356807761591702594573815533235857894615009285668", "price": "0.165", "size": "0", "side": "SELL", "hash": "6707c7e7151848554d9ac207ac1b0a85b552c645", "best_bid": "0.015", "best_ask": "0.071"}], "timestamp": "1769384564204", "event_type": "price_change"}}
{"_local_timestamp": "2026-01-25T23:42:44.379310+00:00", "data": {"market": "0x16478811d537afdfadaacef3bf1fc8b61ed86385968321b7d9250bdce2a49748", "price_changes": [{"asset_id": "92269994048518357863385104036810846326684031835851654275504679077189526944972", "price": "0.834", "size": "0", "side": "BUY", "hash": "d613c62c65ed3223650bf9699b5087ae17af63a2", "best_bid": "0.929", "best_ask": "0.985"}, {"asset_id": "19197134752918366634342328847356807761591702594573815533235857894615009285668", "price": "0.166", "size": "0", "side": "SELL", "hash": "09e4f55d36c49f6b080ba6f9d604e92fbb69bc35", "best_bid": "0.015", "best_ask": "0.071"}], "timestamp": "1769384564236", "event_type": "price_change"}}
{"_local_timestamp": "2026-01-25T23:42:44.505341+00:00", "data": {"market": "0x16478811d537afdfadaacef3bf1fc8b61ed86385968321b7d9250bdce2a49748", "price_changes": [{"asset_id": "92269994048518357863385104036810846326684031835851654275504679077189526944972", "price": "0.773", "size": "10", "side": "BUY", "hash": "dadda4cdebb899ed1bb09f61b832687555171643", "best_bid": "0.929", "best_ask": "0.985"}, {"asset_id": "19197134752918366634342328847356807761591702594573815533235857894615009285668", "price": "0.227", "size": "10", "side": "SELL", "hash": "04688d42afda522dc6a9cc5fa0b93af5c2e55827", "best_bid": "0.015", "best_ask": "0.071"}], "timestamp": "1769384564366", "event_type": "price_change"}}
{"_local_timestamp": "2026-01-25T23:42:44.506535+00:00", "data": {"market": "0x16478811d537afdfadaacef3bf1fc8b61ed86385968321b7d9250bdce2a49748", "price_changes": [{"asset_id": "92269994048518357863385104036810846326684031835851654275504679077189526944972", "price": "0.836", "size": "50", "side": "BUY", "hash": "be99cab3ff293917e90e9c04d2f0568d79337551", "best_bid": "0.929", "best_ask": "0.985"}, {"asset_id": "19197134752918366634342328847356807761591702594573815533235857894615009285668", "price": "0.164", "size": "50", "side": "SELL", "hash": "2ecc585b2ceac5891d76b6566fa076080506f65e", "best_bid": "0.015", "best_ask": "0.071"}], "timestamp": "1769384564368", "event_type": "price_change"}}
{"_local_timestamp": "2026-01-25T23:42:44.842080+00:00", "data": {"market": "0xe7d699841d03f695da20c8935f4cdf809057f3b27fa4f382e327ff731b8d75a7", "price_changes": [{"asset_id": "86720801120812523206375862885554727968671842048571953285734439150624995757719", "price": "0.81", "size": "60", "side": "BUY", "hash": "6ba95145080d5ab3200d4bc2c4a1de704b5c443c", "best_bid": "0.95", "best_ask": "0.97"}, {"asset_id": "40666723045616055650551965571535047681860486685123797401746526747593369094525", "price": "0.19", "size": "60", "side": "SELL", "hash": "322bc34ba53398c671d1bc670315e8ffa4543d40", "best_bid": "0.03", "best_ask": "0.05"}], "timestamp": "1769384564691", "event_type": "price_change"}}
{"_local_timestamp": "2026-01-25T23:42:45.117951+00:00", "data": {"market": "0xfacaaf8ca81b788f8da594acaf23af2ef90037d82580b91357be35f97229e3a5", "price_changes": [{"asset_id": "49741609004781342711179849070128334110798460232218737742146637694522428416234", "price": "0.6", "size": "30.33", "side": "BUY", "hash": "7cab13ec7fab77455778d36c8f9b395123d2601c", "best_bid": "0.7", "best_ask": "0.74"}, {"asset_id": "94754153121378446077535791604860675458774881690932146680120328837949383988913", "price": "0.4", "size": "30.33", "side": "SELL", "hash": "f6249350c788010c8994445104f8390a89a74c50", "best_bid": "0.26", "best_ask": "0.3"}], "timestamp": "1769384564967", "event_type": "price_change"}}
{"_local_timestamp": "2026-01-25T23:42:45.177394+00:00", "data": {"market": "0xfacaaf8ca81b788f8da594acaf23af2ef90037d82580b91357be35f97229e3a5", "price_changes": [{"asset_id": "49741609004781342711179849070128334110798460232218737742146637694522428416234", "price": "0.59", "size": "86.71", "side": "BUY", "hash": "2f11b908a764dd956d26a3821fa81a5217aa6e39", "best_bid": "0.7", "best_ask": "0.74"}, {"asset_id": "94754153121378446077535791604860675458774881690932146680120328837949383988913", "price": "0.41", "size": "86.71", "side": "SELL", "hash": "b0f5dd8c95783b11e1faa0e22901723c0269cd91", "best_bid": "0.26", "best_ask": "0.3"}], "timestamp": "1769384565011", "event_type": "price_change"}}
{"_local_timestamp": "2026-01-25T23:42:45.319730+00:00", "data": {"market": "0xfacaaf8ca81b788f8da594acaf23af2ef90037d82580b91357be35f97229e3a5", "price_changes": [{"asset_id": "49741609004781342711179849070128334110798460232218737742146637694522428416234", "price": "0.58", "size": "225.56", "side": "BUY", "hash": "8cfaf4a01061320ce58827254cf4584d08645e98", "best_bid": "0.7", "best_ask": "0.74"}, {"asset_id": "94754153121378446077535791604860675458774881690932146680120328837949383988913", "price": "0.42", "size": "225.56", "side": "SELL", "hash": "1c0438c4c36e69b705069b5d918ef16e640c56fe", "best_bid": "0.26", "best_ask": "0.3"}], "timestamp": "1769384565179", "event_type": "price_change"}}
{"_local_timestamp": "2026-01-25T23:42:45.417377+00:00", "data": {"market": "0xe7d699841d03f695da20c8935f4cdf809057f3b27fa4f382e327ff731b8d75a7", "price_changes": [{"asset_id": "86720801120812523206375862885554727968671842048571953285734439150624995757719", "price": "0.21", "size": "765.13", "side": "BUY", "hash": "c9ccfafa9aa61c4a9be808df06627e18429bb2b0", "best_bid": "0.95", "best_ask": "0.97"}, {"asset_id": "40666723045616055650551965571535047681860486685123797401746526747593369094525", "price": "0.79", "size": "765.13", "side": "SELL", "hash": "c474b7d05d9b3cfc4d2aeb944f67e034f508dacb", "best_bid": "0.03", "best_ask": "0.05"}], "timestamp": "1769384565214", "event_type": "price_change"}}
{"_local_timestamp": "2026-01-25T23:42:45.524478+00:00", "data": {"market": "0x2649d46f6793c9847cc30659f7bcbec94578a23eda4c8cb86f31473173561986", "price_changes": [{"asset_id": "37921534922010226146703074549600791269918801302227759309433381423805138270558", "price": "0.69", "size": "0", "side": "BUY", "hash": "aa5570ff7f8255548381131c2c2bf7163db40a2b", "best_bid": "0.939", "best_ask": "0.985"}, {"asset_id": "36826320465768064966532909273686181587790905146292730121626683737598046568291", "price": "0.31", "size": "0", "side": "SELL", "hash": "5d1d33de9f1ca23e6ac966bf61240e23b398c2b7", "best_bid": "0.015", "best_ask": "0.061"}], "timestamp": "1769384565294", "event_type": "price_change"}}
{"_local_timestamp": "2026-01-25T23:42:45.604246+00:00", "data": {"market": "0xfacaaf8ca81b788f8da594acaf23af2ef90037d82580b91357be35f97229e3a5", "price_changes": [{"asset_id": "49741609004781342711179849070128334110798460232218737742146637694522428416234", "price": "0.36", "size": "10", "side": "BUY", "hash": "893e4c10b41f073f12d73915293e3b77de6926e0", "best_bid": "0.7", "best_ask": "0.74"}, {"asset_id": "94754153121378446077535791604860675458774881690932146680120328837949383988913", "price": "0.64", "size": "10", "side": "SELL", "hash": "7c130fa0014f36c2d8d24384c1fae89641fa6d73", "best_bid": "0.26", "best_ask": "0.3"}], "timestamp": "1769384565452", "event_type": "price_change"}}
{"_local_timestamp": "2026-01-25T23:42:45.795895+00:00", "data": {"market": "0xe7d699841d03f695da20c8935f4cdf809057f3b27fa4f382e327ff731b8d75a7", "price_changes": [{"asset_id": "86720801120812523206375862885554727968671842048571953285734439150624995757719", "price": "0.23", "size": "200", "side": "BUY", "hash": "ac5c0f7a27a4e6aaa5ee619a29e8094fd04472da", "best_bid": "0.95", "best_ask": "0.97"}, {"asset_id": "40666723045616055650551965571535047681860486685123797401746526747593369094525", "price": "0.77", "size": "200", "side": "SELL", "hash": "6dac6860a2cd3bb25b1f13f37a310de236ea1ebe", "best_bid": "0.03", "best_ask": "0.05"}], "timestamp": "1769384565614", "event_type": "price_change"}}
{"_local_timestamp": "2026-01-25T23:42:45.965233+00:00", "data": {"market": "0xad1f282f187c4748fe6eb51153a39557c66856cd14408bc3d509d3b23c047d41", "price_changes": [{"asset_id": "26089319074590795210476289468934414386490143191167179409102092139417103170837", "price": "0.04", "size": "0", "side": "BUY", "hash": "1509e9281226aae93e0118b7fbc4ea440d11823b", "best_bid": "0.35", "best_ask": "0.46"}, {"asset_id": "86814839478893548397184492422021698202794732526767012779986423826365559163504", "price": "0.96", "size": "0", "side": "SELL", "hash": "d5b89faaf36775cdd5b4a9baaabe0a19981e65aa", "best_bid": "0.54", "best_ask": "0.65"}], "timestamp": "1769384565839", "event_type": "price_change"}}
{"_local_timestamp": "2026-01-25T23:42:46.006100+00:00", "data": {"market": "0xad1f282f187c4748fe6eb51153a39557c66856cd14408bc3d509d3b23c047d41", "price_changes": [{"asset_id": "26089319074590795210476289468934414386490143191167179409102092139417103170837", "price": "0.04", "size": "50", "side": "BUY", "hash": "6a6da6344e00308d9322dd98a11c9ace4bbc6265", "best_bid": "0.35", "best_ask": "0.46"}, {"asset_id": "86814839478893548397184492422021698202794732526767012779986423826365559163504", "price": "0.96", "size": "50", "side": "SELL", "hash": "b766189262a802063f621fa9e59acd539babbe98", "best_bid": "0.54", "best_ask": "0.65"}], "timestamp": "1769384565887", "event_type": "price_change"}}
{"_local_timestamp": "2026-01-25T23:42:46.075069+00:00", "data": {"market": "0x16478811d537afdfadaacef3bf1fc8b61ed86385968321b7d9250bdce2a49748", "price_changes": [{"asset_id": "92269994048518357863385104036810846326684031835851654275504679077189526944972", "price": "0.772", "size": "0", "side": "BUY", "hash": "2018bea5a7207e1abed803d6caa3964f98c3643e", "best_bid": "0.929", "best_ask": "0.985"}, {"asset_id": "19197134752918366634342328847356807761591702594573815533235857894615009285668", "price": "0.228", "size": "0", "side": "SELL", "hash": "fb1508a6e6c337e57c9def75f70732a0d3d01eec", "best_bid": "0.015", "best_ask": "0.071"}], "timestamp": "1769384565954", "event_type": "price_change"}}
{"_local_timestamp": "2026-01-25T23:42:46.098701+00:00", "data": {"market": "0x16478811d537afdfadaacef3bf1fc8b61ed86385968321b7d9250bdce2a49748", "price_changes": [{"asset_id": "92269994048518357863385104036810846326684031835851654275504679077189526944972", "price": "0.774", "size": "20", "side": "BUY", "hash": "b576387215d27bd549d0bf36d7f21cabce4f6629", "best_bid": "0.929", "best_ask": "0.985"}, {"asset_id": "19197134752918366634342328847356807761591702594573815533235857894615009285668", "price": "0.226", "size": "20", "side": "SELL", "hash": "3d2c29edb864c23b9af352b0d5cab50ee0790fcc", "best_bid": "0.015", "best_ask": "0.071"}], "timestamp": "1769384565977", "event_type": "price_change"}}
{"_local_timestamp": "2026-01-25T23:42:47.172005+00:00", "data": {"market": "0xe7d699841d03f695da20c8935f4cdf809057f3b27fa4f382e327ff731b8d75a7", "price_changes": [{"asset_id": "86720801120812523206375862885554727968671842048571953285734439150624995757719", "price": "0.22", "size": "100", "side": "BUY", "hash": "5cdc4fb0e0a62d84a2dfc3ab1002a7816b7099d4", "best_bid": "0.95", "best_ask": "0.97"}, {"asset_id": "40666723045616055650551965571535047681860486685123797401746526747593369094525", "price": "0.78", "size": "100", "side": "SELL", "hash": "44667bf4aa2d15555f6767f2bf9b4ceda333d185", "best_bid": "0.03", "best_ask": "0.05"}], "timestamp": "1769384566991", "event_type": "price_change"}}
{"_local_timestamp": "2026-01-25T23:42:58.858475+00:00", "data": {"market": "0xe7d699841d03f695da20c8935f4cdf809057f3b27fa4f382e327ff731b8d75a7", "price_changes": [{"asset_id": "86720801120812523206375862885554727968671842048571953285734439150624995757719", "price": "0.3", "size": "50", "side": "BUY", "hash": "b238e7ef2b35bf5bd497cfcf258c6a228e11a293", "best_bid": "0.95", "best_ask": "0.97"}, {"asset_id": "40666723045616055650551965571535047681860486685123797401746526747593369094525", "price": "0.7", "size": "50", "side": "SELL", "hash": "3b6091004849117c8905e053991883b64d5f370a", "best_bid": "0.03", "best_ask": "0.05"}], "timestamp": "1769384578725", "event_type": "price_change"}}
{"_local_timestamp": "2026-01-25T23:42:59.109706+00:00", "data": {"market": "0xe7d699841d03f695da20c8935f4cdf809057f3b27fa4f382e327ff731b8d75a7", "price_changes": [{"asset_id": "86720801120812523206375862885554727968671842048571953285734439150624995757719", "price": "0.29", "size": "139.65", "side": "BUY", "hash": "3f7bc6e8f0495d119cb76e303b98fd458c9f2ded", "best_bid": "0.95", "best_ask": "0.97"}, {"asset_id": "40666723045616055650551965571535047681860486685123797401746526747593369094525", "price": "0.71", "size": "139.65", "side": "SELL", "hash": "07a7f588091ded814923cf2979340dc4679503f0", "best_bid": "0.03", "best_ask": "0.05"}], "timestamp": "1769384578978", "event_type": "price_change"}}
{"_local_timestamp": "2026-01-25T23:43:05.651455+00:00", "data": {"market": "0x23e782e8db3eb990b48ff37432f9f0899e73ea737e68d2934bd09b34934dc0d0", "price_changes": [{"asset_id": "42382535584090931070184963017291726037912989687255284323203344679942164276749", "price": "0.566", "size": "0", "side": "BUY", "hash": "86b2f666fc9647d0bbb1fec7ba680be8e781eacd", "best_bid": "0.87", "best_ask": "0.98"}, {"asset_id": "35728543926876832227758010997325479102150155332621985448512538195119929531554", "price": "0.434", "size": "0", "side": "SELL", "hash": "0f25b48c8533b6f9d5f90a8184cb4cdbb7490945", "best_bid": "0.02", "best_ask": "0.13"}], "timestamp": "1769384585505", "event_type": "price_change"}}
{"_local_timestamp": "2026-01-25T23:43:05.652594+00:00", "data": {"market": "0xfacaaf8ca81b788f8da594acaf23af2ef90037d82580b91357be35f97229e3a5", "price_changes": [{"asset_id": "49741609004781342711179849070128334110798460232218737742146637694522428416234", "price": "0.53", "size": "0", "side": "BUY", "hash": "82d394f1106b41a27ade7b5125855026fa33ad7a", "best_bid": "0.7", "best_ask": "0.74"}, {"asset_id": "94754153121378446077535791604860675458774881690932146680120328837949383988913", "price": "0.47", "size": "0", "side": "SELL", "hash": "ef2272dd3641a8d3bf97522b8d30dcd0443703dc", "best_bid": "0.26", "best_ask": "0.3"}], "timestamp": "1769384585505", "event_type": "price_change"}}
{"_local_timestamp": "2026-01-25T23:43:05.653578+00:00", "data": {"market": "0xfacaaf8ca81b788f8da594acaf23af2ef90037d82580b91357be35f97229e3a5", "price_changes": [{"asset_id": "49741609004781342711179849070128334110798460232218737742146637694522428416234", "price": "0.35", "size": "130", "side": "BUY", "hash": "82d394f1106b41a27ade7b5125855026fa33ad7a", "best_bid": "0.7", "best_ask": "0.74"}, {"asset_id": "94754153121378446077535791604860675458774881690932146680120328837949383988913", "price": "0.65", "size": "130", "side": "SELL", "hash": "ef2272dd3641a8d3bf97522b8d30dcd0443703dc", "best_bid": "0.26", "best_ask": "0.3"}], "timestamp": "1769384585505", "event_type": "price_change"}}
{"_local_timestamp": "2026-01-25T23:43:06.286605+00:00", "data": {"market": "0x23e782e8db3eb990b48ff37432f9f0899e73ea737e68d2934bd09b34934dc0d0", "price_changes": [{"asset_id": "42382535584090931070184963017291726037912989687255284323203344679942164276749", "price": "0.576", "size": "100", "side": "BUY", "hash": "a6aec64d9b31f6951b2ca476967bfa1df901dc04", "best_bid": "0.87", "best_ask": "0.98"}, {"asset_id": "35728543926876832227758010997325479102150155332621985448512538195119929531554", "price": "0.424", "size": "100", "side": "SELL", "hash": "bd020db116a9b9a1e22ca4842364ead495eae131", "best_bid": "0.02", "best_ask": "0.13"}], "timestamp": "1769384586139", "event_type": "price_change"}}
{"_local_timestamp": "2026-01-25T23:43:06.349139+00:00", "data": {"market": "0xfacaaf8ca81b788f8da594acaf23af2ef90037d82580b91357be35f97229e3a5", "price_changes": [{"asset_id": "49741609004781342711179849070128334110798460232218737742146637694522428416234", "price": "0.64", "size": "100", "side": "BUY", "hash": "5a9c13b24f49d4d9a14bf072f97eb79e08563323", "best_bid": "0.7", "best_ask": "0.74"}, {"asset_id": "94754153121378446077535791604860675458774881690932146680120328837949383988913", "price": "0.36", "size": "100", "side": "SELL", "hash": "4be91be87153dcf046b6ee9c2fe31679586ed73f", "best_bid": "0.26", "best_ask": "0.3"}], "timestamp": "1769384586199", "event_type": "price_change"}}
{"_local_timestamp": "2026-01-25T23:43:06.561067+00:00", "data": {"market": "0xfacaaf8ca81b788f8da594acaf23af2ef90037d82580b91357be35f97229e3a5", "price_changes": [{"asset_id": "49741609004781342711179849070128334110798460232218737742146637694522428416234", "price": "0.57", "size": "100", "side": "BUY", "hash": "0acd499c72fe44f21674a35eea8f2dd9a5513d29", "best_bid": "0.7", "best_ask": "0.74"}, {"asset_id": "94754153121378446077535791604860675458774881690932146680120328837949383988913", "price": "0.43", "size": "100", "side": "SELL", "hash": "04a9de9a16a35f1082060efd7005b13fed65df45", "best_bid": "0.26", "best_ask": "0.3"}], "timestamp": "1769384586421", "event_type": "price_change"}}
{"_local_timestamp": "2026-01-25T23:43:07.150523+00:00", "data": {"market": "0xfacaaf8ca81b788f8da594acaf23af2ef90037d82580b91357be35f97229e3a5", "price_changes": [{"asset_id": "94754153121378446077535791604860675458774881690932146680120328837949383988913", "price": "0.26", "size": "57.26", "side": "BUY", "hash": "2099496c27a6c8b4ff74ea03398a9b3afd8400e1", "best_bid": "0.26", "best_ask": "0.3"}, {"asset_id": "49741609004781342711179849070128334110798460232218737742146637694522428416234", "price": "0.74", "size": "57.26", "side": "SELL", "hash": "fb99a030bfe5b8e9b9bcd11080d368391c212b7f", "best_bid": "0.7", "best_ask": "0.74"}], "timestamp": "1769384587001", "event_type": "price_change"}}
{"_local_timestamp": "2026-01-25T23:43:07.159580+00:00", "data": {"market": "0xfacaaf8ca81b788f8da594acaf23af2ef90037d82580b91357be35f97229e3a5", "price_changes": [{"asset_id": "49741609004781342711179849070128334110798460232218737742146637694522428416234", "price": "0.7", "size": "50", "side": "BUY", "hash": "fffb5ab842df0c621a5c9fa55c2a905668905288", "best_bid": "0.7", "best_ask": "0.74"}, {"asset_id": "94754153121378446077535791604860675458774881690932146680120328837949383988913", "price": "0.3", "size": "50", "side": "SELL", "hash": "5590c4d17a409e046754766c2278af5fdedc1b9b", "best_bid": "0.26", "best_ask": "0.3"}], "timestamp": "1769384587003", "event_type": "price_change"}}
{"_local_timestamp": "2026-01-25T23:43:07.271632+00:00", "data": {"market": "0x2649d46f6793c9847cc30659f7bcbec94578a23eda4c8cb86f31473173561986", "price_changes": [{"asset_id": "37921534922010226146703074549600791269918801302227759309433381423805138270558", "price": "0.4", "size": "50", "side": "BUY", "hash": "81abd4389075a0f6ea0a7752bc713d516c461ed2", "best_bid": "0.939", "best_ask": "0.985"}, {"asset_id": "36826320465768064966532909273686181587790905146292730121626683737598046568291", "price": "0.6", "size": "50", "side": "SELL", "hash": "30c977005214aa96aca4aa5bc9ea44226f48c3e7", "best_bid": "0.015", "best_ask": "0.061"}], "timestamp": "1769384587126", "event_type": "price_change"}}
{"_local_timestamp": "2026-01-25T23:43:07.272984+00:00", "data": {"market": "0x16478811d537afdfadaacef3bf1fc8b61ed86385968321b7d9250bdce2a49748", "price_changes": [{"asset_id": "92269994048518357863385104036810846326684031835851654275504679077189526944972", "price": "0.4", "size": "50", "side": "BUY", "hash": "ad4fbf80d7c5956493db3a8d3fd8c47ee5ad6a4e", "best_bid": "0.929", "best_ask": "0.985"}, {"asset_id": "19197134752918366634342328847356807761591702594573815533235857894615009285668", "price": "0.6", "size": "50", "side": "SELL", "hash": "7f27c178bd51f4fddcd6f3b65c904422a1fd89b1", "best_bid": "0.015", "best_ask": "0.071"}], "timestamp": "1769384587126", "event_type": "price_change"}}
{"_local_timestamp": "2026-01-25T23:43:07.479120+00:00", "data": {"market": "0x16478811d537afdfadaacef3bf1fc8b61ed86385968321b7d9250bdce2a49748", "price_changes": [{"asset_id": "92269994048518357863385104036810846326684031835851654275504679077189526944972", "price": "0.775", "size": "15", "side": "BUY", "hash": "3dceb45b88bd7f7953324d27c3ac8cbee8f15932", "best_bid": "0.929", "best_ask": "0.985"}, {"asset_id": "19197134752918366634342328847356807761591702594573815533235857894615009285668", "price": "0.225", "size": "15", "side": "SELL", "hash": "f375d61d2c9afd5249348525632ef7d1d9cb9cd9", "best_bid": "0.015", "best_ask": "0.071"}], "timestamp": "1769384587330", "event_type": "price_change"}}
{"_local_timestamp": "2026-01-25T23:43:07.480468+00:00", "data": {"market": "0x2649d46f6793c9847cc30659f7bcbec94578a23eda4c8cb86f31473173561986", "price_changes": [{"asset_id": "37921534922010226146703074549600791269918801302227759309433381423805138270558", "price": "0.699", "size": "10", "side": "BUY", "hash": "f3c6c065c97866c11cafbf64915ac35e1cfa828d", "best_bid": "0.939", "best_ask": "0.985"}, {"asset_id": "36826320465768064966532909273686181587790905146292730121626683737598046568291", "price": "0.301", "size": "10", "side": "SELL", "hash": "a9b109183d5f613332be33ac56f43cf849b4e360", "best_bid": "0.015", "best_ask": "0.061"}], "timestamp": "1769384587330", "event_type": "price_change"}}
{"_local_timestamp": "2026-01-25T23:43:07.481515+00:00", "data": {"market": "0x16478811d537afdfadaacef3bf1fc8b61ed86385968321b7d9250bdce2a49748", "price_changes": [{"asset_id": "92269994048518357863385104036810846326684031835851654275504679077189526944972", "price": "0.775", "size": "25", "side": "BUY", "hash": "f661be028c570900b7915b7dfeaae338b7b399dd", "best_bid": "0.929", "best_ask": "0.985"}, {"asset_id": "19197134752918366634342328847356807761591702594573815533235857894615009285668", "price": "0.225", "size": "25", "side": "SELL", "hash": "7a91f758da6f5e413c15221163e329583f0947bd", "best_bid": "0.015", "best_ask": "0.071"}], "timestamp": "1769384587331", "event_type": "price_change"}}
{"_local_timestamp": "2026-01-25T23:43:07.482543+00:00", "data": {"market": "0x2649d46f6793c9847cc30659f7bcbec94578a23eda4c8cb86f31473173561986", "price_changes": [{"asset_id": "37921534922010226146703074549600791269918801302227759309433381423805138270558", "price": "0.699", "size": "25", "side": "BUY", "hash": "f7b9fadfb3d54ee6fd7f1acc0a9b73a43bc7e5b5", "best_bid": "0.939", "best_ask": "0.985"}, {"asset_id": "36826320465768064966532909273686181587790905146292730121626683737598046568291", "price": "0.301", "size": "25", "side": "SELL", "hash": "6b072898a994c7c5e0b8669934d37ca012eea0ca", "best_bid": "0.015", "best_ask": "0.061"}], "timestamp": "1769384587331", "event_type": "price_change"}}
{"_local_timestamp": "2026-01-25T23:43:07.483641+00:00", "data": {"market": "0x2649d46f6793c9847cc30659f7bcbec94578a23eda4c8cb86f31473173561986", "price_changes": [{"asset_id": "37921534922010226146703074549600791269918801302227759309433381423805138270558", "price": "0.4", "size": "78", "side": "BUY", "hash": "e4cb233b8a83b3daa7c7feecfc53f707c7d66b4a", "best_bid": "0.939", "best_ask": "0.985"}, {"asset_id": "36826320465768064966532909273686181587790905146292730121626683737598046568291", "price": "0.6", "size": "78", "side": "SELL", "hash": "ae569242d8d2b06fc8cbc4df4399dfb040718a34", "best_bid": "0.015", "best_ask": "0.061"}], "timestamp": "1769384587332", "event_type": "price_change"}}
{"_local_timestamp": "2026-01-25T23:43:08.974297+00:00", "data": {"market": "0x2649d46f6793c9847cc30659f7bcbec94578a23eda4c8cb86f31473173561986", "price_changes": [{"asset_id": "37921534922010226146703074549600791269918801302227759309433381423805138270558", "price": "0.698", "size": "0", "side": "BUY", "hash": "01e3743e136abeef19eaf849613e6ef26d601858", "best_bid": "0.939", "best_ask": "0.985"}, {"asset_id": "36826320465768064966532909273686181587790905146292730121626683737598046568291", "price": "0.302", "size": "0", "side": "SELL", "hash": "71d13ef85320877e3ce7963a1dd44c19d8697097", "best_bid": "0.015", "best_ask": "0.061"}], "timestamp": "1769384588826", "event_type": "price_change"}}
{"_local_timestamp": "2026-01-25T23:43:08.975435+00:00", "data": {"market": "0x16478811d537afdfadaacef3bf1fc8b61ed86385968321b7d9250bdce2a49748", "price_changes": [{"asset_id": "92269994048518357863385104036810846326684031835851654275504679077189526944972", "price": "0.774", "size": "0", "side": "BUY", "hash": "54a3898cba8a3a2ea080865d97796bf68e327877", "best_bid": "0.929", "best_ask": "0.985"}, {"asset_id": "19197134752918366634342328847356807761591702594573815533235857894615009285668", "price": "0.226", "size": "0", "side": "SELL", "hash": "1b9d5f3526ebc8ac1f44d236a404b6f1011fa415", "best_bid": "0.015", "best_ask": "0.071"}], "timestamp": "1769384588826", "event_type": "price_change"}}
{"_local_timestamp": "2026-01-25T23:43:08.988787+00:00", "data": {"market": "0x2649d46f6793c9847cc30659f7bcbec94578a23eda4c8cb86f31473173561986", "price_changes": [{"asset_id": "37921534922010226146703074549600791269918801302227759309433381423805138270558", "price": "0.7", "size": "20", "side": "BUY", "hash": "1ad480aa8d91fa19ee5785523fb64140390334fd", "best_bid": "0.939", "best_ask": "0.985"}, {"asset_id": "36826320465768064966532909273686181587790905146292730121626683737598046568291", "price": "0.3", "size": "20", "side": "SELL", "hash": "f709e3bd51c3285f29403d1f14f50963a1189a7b", "best_bid": "0.015", "best_ask": "0.061"}], "timestamp": "1769384588852", "event_type": "price_change"}}
{"_local_timestamp": "2026-01-25T23:43:08.989968+00:00", "data": {"market": "0x16478811d537afdfadaacef3bf1fc8b61ed86385968321b7d9250bdce2a49748", "price_changes": [{"asset_id": "92269994048518357863385104036810846326684031835851654275504679077189526944972", "price": "0.776", "size": "20", "side": "BUY", "hash": "e7b429c546d6e63f15891024639d46bea0f212f6", "best_bid": "0.929", "best_ask": "0.985"}, {"asset_id": "19197134752918366634342328847356807761591702594573815533235857894615009285668", "price": "0.224", "size": "20", "side": "SELL", "hash": "e31cc74bd07ce777a303ce12d2b3be57f52cc018", "best_bid": "0.015", "best_ask": "0.071"}], "timestamp": "1769384588852", "event_type": "price_change"}}
{"_local_timestamp": "2026-01-25T23:43:09.193940+00:00", "data": {"market": "0x23e782e8db3eb990b48ff37432f9f0899e73ea737e68d2934bd09b34934dc0d0", "price_changes": [{"asset_id": "42382535584090931070184963017291726037912989687255284323203344679942164276749", "price": "0.643", "size": "15", "side": "BUY", "hash": "d7359b83c32965b8ace9ffe36d6eb1e48ae75682", "best_bid": "0.87", "best_ask": "0.98"}, {"asset_id": "35728543926876832227758010997325479102150155332621985448512538195119929531554", "price": "0.357", "size": "15", "side": "SELL", "hash": "f2e46e88fe3a29e3e495cb567d4d4ac9bc99fcd9", "best_bid": "0.02", "best_ask": "0.13"}], "timestamp": "1769384589006", "event_type": "price_change"}}
{"_local_timestamp": "2026-01-25T23:43:13.009281+00:00", "data": {"market": "0xfacaaf8ca81b788f8da594acaf23af2ef90037d82580b91357be35f97229e3a5", "price_changes": [{"asset_id": "94754153121378446077535791604860675458774881690932146680120328837949383988913", "price": "0.02", "size": "800", "side": "BUY", "hash": "422c1a87fe8195b8d071f084b63d62a0777ae98e", "best_bid": "0.26", "best_ask": "0.3"}, {"asset_id": "49741609004781342711179849070128334110798460232218737742146637694522428416234", "price": "0.98", "size": "800", "side": "SELL", "hash": "b2165095a1ae9aad333ecd278e0bd382640019df", "best_bid": "0.7", "best_ask": "0.74"}], "timestamp": "1769384592869", "event_type": "price_change"}}
{"_local_timestamp": "2026-01-25T23:43:38.515698+00:00", "data": {"market": "0xe7d699841d03f695da20c8935f4cdf809057f3b27fa4f382e327ff731b8d75a7", "price_changes": [{"asset_id": "86720801120812523206375862885554727968671842048571953285734439150624995757719", "price": "0.22", "size": "0", "side": "BUY", "hash": "186724f858553afe80e943a09a7f0098e2f1ed21", "best_bid": "0.95", "best_ask": "0.97"}, {"asset_id": "40666723045616055650551965571535047681860486685123797401746526747593369094525", "price": "0.78", "size": "0", "side": "SELL", "hash": "1461e3d3dc0962ab903d3eace507de0810eab523", "best_bid": "0.03", "best_ask": "0.05"}], "timestamp": "1769384618445", "event_type": "price_change"}}
{"_local_timestamp": "2026-01-25T23:43:38.556984+00:00", "data": {"market": "0x2649d46f6793c9847cc30659f7bcbec94578a23eda4c8cb86f31473173561986", "price_changes": [{"asset_id": "37921534922010226146703074549600791269918801302227759309433381423805138270558", "price": "0.874", "size": "0", "side": "BUY", "hash": "4d3f7ae1d79f30c7aae76c538374725ff8b91f28", "best_bid": "0.939", "best_ask": "0.985"}, {"asset_id": "36826320465768064966532909273686181587790905146292730121626683737598046568291", "price": "0.126", "size": "0", "side": "SELL", "hash": "68f8ad111546b329b86f23e223bcc6a011a7f268", "best_bid": "0.015", "best_ask": "0.061"}], "timestamp": "1769384618470", "event_type": "price_change"}}
{"_local_timestamp": "2026-01-25T23:43:38.777325+00:00", "data": {"market": "0xe7d699841d03f695da20c8935f4cdf809057f3b27fa4f382e327ff731b8d75a7", "price_changes": [{"asset_id": "86720801120812523206375862885554727968671842048571953285734439150624995757719", "price": "0.21", "size": "865.13", "side": "BUY", "hash": "7d5a93db02a9b31b17bac82e2e014e34108f5b8d", "best_bid": "0.95", "best_ask": "0.97"}, {"asset_id": "40666723045616055650551965571535047681860486685123797401746526747593369094525", "price": "0.79", "size": "865.13", "side": "SELL", "hash": "5a51dbc6e4104de5fa4ffb685c9dc2a439858a12", "best_bid": "0.03", "best_ask": "0.05"}], "timestamp": "1769384618709", "event_type": "price_change"}}
{"_local_timestamp": "2026-01-25T23:43:42.259337+00:00", "data": {"market": "0xe7d699841d03f695da20c8935f4cdf809057f3b27fa4f382e327ff731b8d75a7", "price_changes": [{"asset_id": "86720801120812523206375862885554727968671842048571953285734439150624995757719", "price": "0.24", "size": "1864.66", "side": "BUY", "hash": "fca4c16c4e0d979ce0eb4325f5cb1576dca2242b", "best_bid": "0.95", "best_ask": "0.97"}, {"asset_id": "40666723045616055650551965571535047681860486685123797401746526747593369094525", "price": "0.76", "size": "1864.66", "side": "SELL", "hash": "327eb165190071b8dafc05d27f19501e2951caac", "best_bid": "0.03", "best_ask": "0.05"}], "timestamp": "1769384622174", "event_type": "price_change"}}
{"_local_timestamp": "2026-01-25T23:43:42.433423+00:00", "data": {"market": "0x23e782e8db3eb990b48ff37432f9f0899e73ea737e68d2934bd09b34934dc0d0", "price_changes": [{"asset_id": "42382535584090931070184963017291726037912989687255284323203344679942164276749", "price": "0.643", "size": "0", "side": "BUY", "hash": "ff0185f7e897373da4f8acefee2a9dc8846e54f9", "best_bid": "0.87", "best_ask": "0.98"}, {"asset_id": "35728543926876832227758010997325479102150155332621985448512538195119929531554", "price": "0.357", "size": "0", "side": "SELL", "hash": "f4941ad7d8c90b351aa396194610eb4bc26b933b", "best_bid": "0.02", "best_ask": "0.13"}], "timestamp": "1769384622357", "event_type": "price_change"}}
{"_local_timestamp": "2026-01-25T23:43:54.965242+00:00", "data": {"market": "0x23e782e8db3eb990b48ff37432f9f0899e73ea737e68d2934bd09b34934dc0d0", "price_changes": [{"asset_id": "35728543926876832227758010997325479102150155332621985448512538195119929531554", "price": "0.004", "size": "0", "side": "BUY", "hash": "a4574413b1be55f83dd1000b795d8172741ff077", "best_bid": "0.02", "best_ask": "0.13"}, {"asset_id": "42382535584090931070184963017291726037912989687255284323203344679942164276749", "price": "0.996", "size": "0", "side": "SELL", "hash": "07b9493057b0e3187f7b50e49ec4d857f5e7e50f", "best_bid": "0.87", "best_ask": "0.98"}], "timestamp": "1769384634834", "event_type": "price_change"}}
{"_local_timestamp": "2026-01-25T23:43:56.400266+00:00", "data": {"market": "0xeafc8d47725546039800fe78eb06c0af5d9f982134515b9250ea376b7c258afb", "price_changes": [{"asset_id": "39436446463164291051085103274433078121544260678753625430845203266295844561591", "price": "0.002", "size": "250", "side": "BUY", "hash": "c33c8204df1cb71dff9238bb20777ac7da1c1307", "best_bid": "0.012", "best_ask": "0.014"}, {"asset_id": "102282495724728145503590068938456419856338447487625172072096551524174375085545", "price": "0.998", "size": "250", "side": "SELL", "hash": "f973c766dd9b9b588325f96a032dcc03c50b3848", "best_bid": "0.986", "best_ask": "0.988"}], "timestamp": "1769384636234", "event_type": "price_change"}}
{"_local_timestamp": "2026-01-25T23:43:56.401347+00:00", "data": {"market": "0xeafc8d47725546039800fe78eb06c0af5d9f982134515b9250ea376b7c258afb", "price_changes": [{"asset_id": "39436446463164291051085103274433078121544260678753625430845203266295844561591", "price": "0.004", "size": "0", "side": "BUY", "hash": "c33c8204df1cb71dff9238bb20777ac7da1c1307", "best_bid": "0.012", "best_ask": "0.014"}, {"asset_id": "102282495724728145503590068938456419856338447487625172072096551524174375085545", "price": "0.996", "size": "0", "side": "SELL", "hash": "f973c766dd9b9b588325f96a032dcc03c50b3848", "best_bid": "0.986", "best_ask": "0.988"}], "timestamp": "1769384636234", "event_type": "price_change"}}
{"_local_timestamp": "2026-01-25T23:43:56.402356+00:00", "data": {"market": "0xad1f282f187c4748fe6eb51153a39557c66856cd14408bc3d509d3b23c047d41", "price_changes": [{"asset_id": "86814839478893548397184492422021698202794732526767012779986423826365559163504", "price": "0.04", "size": "4983", "side": "BUY", "hash": "5d1c2bf77a2b56b0986ce617770b046f2d741ef7", "best_bid": "0.54", "best_ask": "0.65"}, {"asset_id": "26089319074590795210476289468934414386490143191167179409102092139417103170837", "price": "0.96", "size": "4983", "side": "SELL", "hash": "ab8407383bdae63fa981850c3083682d19528f0e", "best_bid": "0.35", "best_ask": "0.46"}], "timestamp": "1769384636235", "event_type": "price_change"}}
{"_local_timestamp": "2026-01-25T23:43:56.543310+00:00", "data": {"market": "0x23e782e8db3eb990b48ff37432f9f0899e73ea737e68d2934bd09b34934dc0d0", "price_changes": [{"asset_id": "35728543926876832227758010997325479102150155332621985448512538195119929531554", "price": "0.003", "size": "60.79", "side": "BUY", "hash": "667213b2764ae9253f5ef93d76cc71d1598be84c", "best_bid": "0.02", "best_ask": "0.13"}, {"asset_id": "42382535584090931070184963017291726037912989687255284323203344679942164276749", "price": "0.997", "size": "60.79", "side": "SELL", "hash": "5643e5fef1225bc3658436eadc6e3c086df87917", "best_bid": "0.87", "best_ask": "0.98"}], "timestamp": "1769384636404", "event_type": "price_change"}}
{"_local_timestamp": "2026-01-25T23:43:57.893476+00:00", "data": {"market": "0xfacaaf8ca81b788f8da594acaf23af2ef90037d82580b91357be35f97229e3a5", "price_changes": [{"asset_id": "49741609004781342711179849070128334110798460232218737742146637694522428416234", "price": "0.76", "size": "50", "side": "SELL", "hash": "a877a9e7b0367829d160341e4041fa44fa789bb0", "best_bid": "0.7", "best_ask": "0.74"}, {"asset_id": "94754153121378446077535791604860675458774881690932146680120328837949383988913", "price": "0.24", "size": "50", "side": "BUY", "hash": "e62b0cfa07e4b36b9919bc93c2db7de91ee966c6", "best_bid": "0.26", "best_ask": "0.3"}], "timestamp": "1769384637770", "event_type": "price_change"}}
{"_local_timestamp": "2026-01-25T23:43:57.916755+00:00", "data": {"market": "0xfacaaf8ca81b788f8da594acaf23af2ef90037d82580b91357be35f97229e3a5", "price_changes": [{"asset_id": "49741609004781342711179849070128334110798460232218737742146637694522428416234", "price": "0.76", "size": "100", "side": "SELL", "hash": "3804382410ca7d6ab0f534b59b5a25b66ac77c99", "best_bid": "0.7", "best_ask": "0.74"}, {"asset_id": "94754153121378446077535791604860675458774881690932146680120328837949383988913", "price": "0.24", "size": "100", "side": "BUY", "hash": "d7f581b2aa93c7404fabfda4e76881616afa0033", "best_bid": "0.26", "best_ask": "0.3"}], "timestamp": "1769384637793", "event_type": "price_change"}}
{"_local_timestamp": "2026-01-25T23:43:58.031154+00:00", "data": {"market": "0xeafc8d47725546039800fe78eb06c0af5d9f982134515b9250ea376b7c258afb", "price_changes": [{"asset_id": "102282495724728145503590068938456419856338447487625172072096551524174375085545", "price": "0.821", "size": "0", "side": "BUY", "hash": "189dcc4c78fb9e02d6bbb0b04ce0d80d505f5dd6", "best_bid": "0.986", "best_ask": "0.988"}, {"asset_id": "39436446463164291051085103274433078121544260678753625430845203266295844561591", "price": "0.179", "size": "0", "side": "SELL", "hash": "9892aba1aafcdd94a26d2b6c39bc84e0f3c95e27", "best_bid": "0.012", "best_ask": "0.014"}], "timestamp": "1769384637911", "event_type": "price_change"}}
{"_local_timestamp": "2026-01-25T23:43:58.186064+00:00", "data": {"market": "0xeafc8d47725546039800fe78eb06c0af5d9f982134515b9250ea376b7c258afb", "price_changes": [{"asset_id": "102282495724728145503590068938456419856338447487625172072096551524174375085545", "price": "0.823", "size": "30", "side": "BUY", "hash": "1631c1e96a94c99c1891dba68b2cfdacdefbb2ab", "best_bid": "0.986", "best_ask": "0.988"}, {"asset_id": "39436446463164291051085103274433078121544260678753625430845203266295844561591", "price": "0.177", "size": "30", "side": "SELL", "hash": "2f2c819c9dbbcf0377c1ba56eb86b1bf474f97ad", "best_bid": "0.012", "best_ask": "0.014"}], "timestamp": "1769384638063", "event_type": "price_change"}}
{"_local_timestamp": "2026-01-25T23:43:58.722914+00:00", "data": {"market": "0xeafc8d47725546039800fe78eb06c0af5d9f982134515b9250ea376b7c258afb", "price_changes": [{"asset_id": "39436446463164291051085103274433078121544260678753625430845203266295844561591", "price": "0.002", "size": "294.24", "side": "BUY", "hash": "de281feef7aeab147543b180cc9e5e8a6837aa79", "best_bid": "0.012", "best_ask": "0.014"}, {"asset_id": "102282495724728145503590068938456419856338447487625172072096551524174375085545", "price": "0.998", "size": "294.24", "side": "SELL", "hash": "03856d462c2e8d6e9d6289c80d532d6e86c45056", "best_bid": "0.986", "best_ask": "0.988"}], "timestamp": "1769384638591", "event_type": "price_change"}}
{"_local_timestamp": "2026-01-25T23:43:58.724034+00:00", "data": {"market": "0xad1f282f187c4748fe6eb51153a39557c66856cd14408bc3d509d3b23c047d41", "price_changes": [{"asset_id": "86814839478893548397184492422021698202794732526767012779986423826365559163504", "price": "0.03", "size": "9.52", "side": "BUY", "hash": "005a92ec226023fd405f9c3c73a7d91555a628fb", "best_bid": "0.54", "best_ask": "0.65"}, {"asset_id": "26089319074590795210476289468934414386490143191167179409102092139417103170837", "price": "0.97", "size": "9.52", "side": "SELL", "hash": "e5df52166e7845f0b6109c766b7c5de5b22ed436", "best_bid": "0.35", "best_ask": "0.46"}], "timestamp": "1769384638591", "event_type": "price_change"}}
{"_local_timestamp": "2026-01-25T23:43:58.725068+00:00", "data": {"market": "0xeafc8d47725546039800fe78eb06c0af5d9f982134515b9250ea376b7c258afb", "price_changes": [{"asset_id": "39436446463164291051085103274433078121544260678753625430845203266295844561591", "price": "0.003", "size": "65.74", "side": "BUY", "hash": "174f7e190cbe8465b45a79f40051df877596e0fa", "best_bid": "0.012", "best_ask": "0.014"}, {"asset_id": "102282495724728145503590068938456419856338447487625172072096551524174375085545", "price": "0.997", "size": "65.74", "side": "SELL", "hash": "b505fcaea77a07a3720244a6798492847ca4996a", "best_bid": "0.986", "best_ask": "0.988"}], "timestamp": "1769384638592", "event_type": "price_change"}}
{"_local_timestamp": "2026-01-25T23:43:58.870127+00:00", "data": {"market": "0xeafc8d47725546039800fe78eb06c0af5d9f982134515b9250ea376b7c258afb", "price_changes": [{"asset_id": "102282495724728145503590068938456419856338447487625172072096551524174375085545", "price": "0.822", "size": "0", "side": "BUY", "hash": "4a78a9d2b7c5a74891a7050955400b90c77ec834", "best_bid": "0.986", "best_ask": "0.988"}, {"asset_id": "39436446463164291051085103274433078121544260678753625430845203266295844561591", "price": "0.178", "size": "0", "side": "SELL", "hash": "8f038033206bb0016719dd1d549d5a6268536e01", "best_bid": "0.012", "best_ask": "0.014"}], "timestamp": "1769384638745", "event_type": "price_change"}}
{"_local_timestamp": "2026-01-25T23:43:58.886235+00:00", "data": {"market": "0xeafc8d47725546039800fe78eb06c0af5d9f982134515b9250ea376b7c258afb", "price_changes": [{"asset_id": "102282495724728145503590068938456419856338447487625172072096551524174375085545", "price": "0.824", "size": "20", "side": "BUY", "hash": "963a1773ededae8ddb5444145d5610c2c65de380", "best_bid": "0.986", "best_ask": "0.988"}, {"asset_id": "39436446463164291051085103274433078121544260678753625430845203266295844561591", "price": "0.176", "size": "20", "side": "SELL", "hash": "8418d9a7966fb85b8a60c7d1bc2bdc3a1a854dc4", "best_bid": "0.012", "best_ask": "0.014"}], "timestamp": "1769384638768", "event_type": "price_change"}}
{"_local_timestamp": "2026-01-25T23:44:06.249393+00:00", "data": {"market": "0x2649d46f6793c9847cc30659f7bcbec94578a23eda4c8cb86f31473173561986", "price_changes": [{"asset_id": "37921534922010226146703074549600791269918801302227759309433381423805138270558", "price": "0.401", "size": "0", "side": "BUY", "hash": "4b03273b08bff26e7d3fcc56317845ff5142b938", "best_bid": "0.939", "best_ask": "0.985"}, {"asset_id": "36826320465768064966532909273686181587790905146292730121626683737598046568291", "price": "0.599", "size": "0", "side": "SELL", "hash": "3750c4f1e2193b968ee7d64cf2ff061a089433dd", "best_bid": "0.015", "best_ask": "0.061"}], "timestamp": "1769384646111", "event_type": "price_change"}}
{"_local_timestamp": "2026-01-25T23:44:06.312309+00:00", "data": {"market": "0x2649d46f6793c9847cc30659f7bcbec94578a23eda4c8cb86f31473173561986", "price_changes": [{"asset_id": "37921534922010226146703074549600791269918801302227759309433381423805138270558", "price": "0.401", "size": "5", "side": "BUY", "hash": "5bf50fdc9f27074ed172cd7ac4e750812027352f", "best_bid": "0.939", "best_ask": "0.985"}, {"asset_id": "36826320465768064966532909273686181587790905146292730121626683737598046568291", "price": "0.599", "size": "5", "side": "SELL", "hash": "7d18c915b970ab426bddabfb2651d13beedb587a", "best_bid": "0.015", "best_ask": "0.061"}], "timestamp": "1769384646161", "event_type": "price_change"}}
{"_local_timestamp": "2026-01-25T23:44:08.722605+00:00", "data": {"market": "0xe7d699841d03f695da20c8935f4cdf809057f3b27fa4f382e327ff731b8d75a7", "price_changes": [{"asset_id": "86720801120812523206375862885554727968671842048571953285734439150624995757719", "price": "0.23", "size": "150", "side": "BUY", "hash": "5dc6f8b4334b6fca45ac117be86a057eb17566de", "best_bid": "0.95", "best_ask": "0.97"}, {"asset_id": "40666723045616055650551965571535047681860486685123797401746526747593369094525", "price": "0.77", "size": "150", "side": "SELL", "hash": "8bae74f6ada9a3a6684fee90684ab464efb126e8", "best_bid": "0.03", "best_ask": "0.05"}], "timestamp": "1769384648436", "event_type": "price_change"}}
{"_local_timestamp": "2026-01-25T23:44:09.058072+00:00", "data": {"market": "0xe7d699841d03f695da20c8935f4cdf809057f3b27fa4f382e327ff731b8d75a7", "price_changes": [{"asset_id": "86720801120812523206375862885554727968671842048571953285734439150624995757719", "price": "0.22", "size": "50", "side": "BUY", "hash": "829f06c01ca32c10ceb9670e8aa2ce8f622faf6d", "best_bid": "0.95", "best_ask": "0.97"}, {"asset_id": "40666723045616055650551965571535047681860486685123797401746526747593369094525", "price": "0.78", "size": "50", "side": "SELL", "hash": "e407e5c85333669188211e680063a58040e897aa", "best_bid": "0.03", "best_ask": "0.05"}], "timestamp": "1769384648748", "event_type": "price_change"}}
{"_local_timestamp": "2026-01-25T23:44:16.174750+00:00", "data": {"market": "0xeafc8d47725546039800fe78eb06c0af5d9f982134515b9250ea376b7c258afb", "price_changes": [{"asset_id": "39436446463164291051085103274433078121544260678753625430845203266295844561591", "price": "0.014", "size": "20", "side": "SELL", "hash": "3a401fa1fd3ae5d2d8d0943bf48a15cfdf1db918", "best_bid": "0.012", "best_ask": "0.014"}, {"asset_id": "102282495724728145503590068938456419856338447487625172072096551524174375085545", "price": "0.986", "size": "20", "side": "BUY", "hash": "2960326c293be4b462eb0110049bdd4c197b1445", "best_bid": "0.986", "best_ask": "0.988"}], "timestamp": "1769384656001", "event_type": "price_change"}}
{"_local_timestamp": "2026-01-25T23:44:18.036060+00:00", "data": {"market": "0xe7d699841d03f695da20c8935f4cdf809057f3b27fa4f382e327ff731b8d75a7", "price_changes": [{"asset_id": "86720801120812523206375862885554727968671842048571953285734439150624995757719", "price": "0.21", "size": "765.13", "side": "BUY", "hash": "16dfc4138661455d3ef0f2d15a2cb56463d2f0c6", "best_bid": "0.95", "best_ask": "0.97"}, {"asset_id": "40666723045616055650551965571535047681860486685123797401746526747593369094525", "price": "0.79", "size": "765.13", "side": "SELL", "hash": "c2ad15b4f34e6903a2320d16924060134831818b", "best_bid": "0.03", "best_ask": "0.05"}], "timestamp": "1769384657934", "event_type": "price_change"}}
{"_local_timestamp": "2026-01-25T23:44:18.261086+00:00", "data": {"market": "0xe7d699841d03f695da20c8935f4cdf809057f3b27fa4f382e327ff731b8d75a7", "price_changes": [{"asset_id": "86720801120812523206375862885554727968671842048571953285734439150624995757719", "price": "0.24", "size": "1964.66", "side": "BUY", "hash": "1017ffcaec3e4e82f404d45aa23efce93043f636", "best_bid": "0.95", "best_ask": "0.97"}, {"asset_id": "40666723045616055650551965571535047681860486685123797401746526747593369094525", "price": "0.76", "size": "1964.66", "side": "SELL", "hash": "401a22237b4c8bcb43ca61a7764d79da8dc062c8", "best_bid": "0.03", "best_ask": "0.05"}], "timestamp": "1769384658178", "event_type": "price_change"}}
{"_local_timestamp": "2026-01-25T23:44:20.917069+00:00", "data": {"market": "0xad1f282f187c4748fe6eb51153a39557c66856cd14408bc3d509d3b23c047d41", "price_changes": [{"asset_id": "86814839478893548397184492422021698202794732526767012779986423826365559163504", "price": "0.22", "size": "200", "side": "BUY", "hash": "6df09c5484618539e3f6af4f80e4eacf6c251d04", "best_bid": "0.54", "best_ask": "0.65"}, {"asset_id": "26089319074590795210476289468934414386490143191167179409102092139417103170837", "price": "0.78", "size": "200", "side": "SELL", "hash": "39f84f2356bdbd5b9d3576eedb1dc1d01656f261", "best_bid": "0.35", "best_ask": "0.46"}], "timestamp": "1769384660480", "event_type": "price_change"}}
{"_local_timestamp": "2026-01-25T23:44:20.994073+00:00", "data": {"market": "0xe7d699841d03f695da20c8935f4cdf809057f3b27fa4f382e327ff731b8d75a7", "price_changes": [{"asset_id": "86720801120812523206375862885554727968671842048571953285734439150624995757719", "price": "0.23", "size": "50", "side": "BUY", "hash": "a7eefced5a1347a3422b1ed8f20652febf62ef03", "best_bid": "0.95", "best_ask": "0.97"}, {"asset_id": "40666723045616055650551965571535047681860486685123797401746526747593369094525", "price": "0.77", "size": "50", "side": "SELL", "hash": "57c62a7a403f654111e557828c0ff2e979314a18", "best_bid": "0.03", "best_ask": "0.05"}], "timestamp": "1769384660480", "event_type": "price_change"}}
{"_local_timestamp": "2026-01-25T23:44:21.453391+00:00", "data": {"market": "0xad1f282f187c4748fe6eb51153a39557c66856cd14408bc3d509d3b23c047d41", "price_changes": [{"asset_id": "86814839478893548397184492422021698202794732526767012779986423826365559163504", "price": "0.24", "size": "100", "side": "BUY", "hash": "4561c188eaa91c2c7b039dac89a5e328165121b9", "best_bid": "0.54", "best_ask": "0.65"}, {"asset_id": "26089319074590795210476289468934414386490143191167179409102092139417103170837", "price": "0.76", "size": "100", "side": "SELL", "hash": "e78b04ba2777feab4d0dc1c815983a918f0d5011", "best_bid": "0.35", "best_ask": "0.46"}], "timestamp": "1769384660921", "event_type": "price_change"}}
{"_local_timestamp": "2026-01-25T23:44:21.485313+00:00", "data": {"market": "0xe7d699841d03f695da20c8935f4cdf809057f3b27fa4f382e327ff731b8d75a7", "price_changes": [{"asset_id": "86720801120812523206375862885554727968671842048571953285734439150624995757719", "price": "0.22", "size": "150", "side": "BUY", "hash": "7cd6e6b427cf2e7dbf15efe105375128706ee50f", "best_bid": "0.95", "best_ask": "0.97"}, {"asset_id": "40666723045616055650551965571535047681860486685123797401746526747593369094525", "price": "0.78", "size": "150", "side": "SELL", "hash": "0a3ee8633a89b5c6285b72b782c74ed5e9469be6", "best_bid": "0.03", "best_ask": "0.05"}], "timestamp": "1769384660921", "event_type": "price_change"}}
{"_local_timestamp": "2026-01-25T23:44:25.851844+00:00", "data": {"market": "0xeafc8d47725546039800fe78eb06c0af5d9f982134515b9250ea376b7c258afb", "price_changes": [{"asset_id": "39436446463164291051085103274433078121544260678753625430845203266295844561591", "price": "0.014", "size": "70", "side": "SELL", "hash": "cefeabcc7c602ab8b7ba806056b35f674ada27c8", "best_bid": "0.012", "best_ask": "0.014"}, {"asset_id": "102282495724728145503590068938456419856338447487625172072096551524174375085545", "price": "0.986", "size": "70", "side": "BUY", "hash": "3959094e7bd02faa7adc48e920beb0998ae78712", "best_bid": "0.986", "best_ask": "0.988"}], "timestamp": "1769384665761", "event_type": "price_change"}}
{"_local_timestamp": "2026-01-25T23:44:32.606775+00:00", "data": {"market": "0xe7d699841d03f695da20c8935f4cdf809057f3b27fa4f382e327ff731b8d75a7", "price_changes": [{"asset_id": "86720801120812523206375862885554727968671842048571953285734439150624995757719", "price": "0.24", "size": "216.66", "side": "BUY", "hash": "3b187b1c39296ee6a865b8ef603feccb669ada29", "best_bid": "0.95", "best_ask": "0.97"}, {"asset_id": "40666723045616055650551965571535047681860486685123797401746526747593369094525", "price": "0.76", "size": "216.66", "side": "SELL", "hash": "85826ae7cb63919630aa1ab81509b35be04ff80a", "best_bid": "0.03", "best_ask": "0.05"}], "timestamp": "1769384672292", "event_type": "price_change"}}
{"_local_timestamp": "2026-01-25T23:44:46.563520+00:00", "data": {"market": "0x16478811d537afdfadaacef3bf1fc8b61ed86385968321b7d9250bdce2a49748", "price_changes": [{"asset_id": "92269994048518357863385104036810846326684031835851654275504679077189526944972", "price": "0.64", "size": "100", "side": "BUY", "hash": "57ba91fce7a7ed4c9471fbe2cf9055e8c0df254f", "best_bid": "0.929", "best_ask": "0.985"}, {"asset_id": "19197134752918366634342328847356807761591702594573815533235857894615009285668", "price": "0.36", "size": "100", "side": "SELL", "hash": "d8b614d4f63ce25b69aad9183b4b54d713f11f42", "best_bid": "0.015", "best_ask": "0.071"}], "timestamp": "1769384686365", "event_type": "price_change"}}
{"_local_timestamp": "2026-01-25T23:44:46.584072+00:00", "data": {"market": "0xeafc8d47725546039800fe78eb06c0af5d9f982134515b9250ea376b7c258afb", "price_changes": [{"asset_id": "102282495724728145503590068938456419856338447487625172072096551524174375085545", "price": "0.878", "size": "0", "side": "BUY", "hash": "32caf7ad1f361eb548b6ed174dd31c5756ac391a", "best_bid": "0.986", "best_ask": "0.988"}, {"asset_id": "39436446463164291051085103274433078121544260678753625430845203266295844561591", "price": "0.122", "size": "0", "side": "SELL", "hash": "3c03effdc8d1154cbe5d2852135096568ffdf031", "best_bid": "0.012", "best_ask": "0.014"}], "timestamp": "1769384686389", "event_type": "price_change"}}
{"_local_timestamp": "2026-01-25T23:44:46.588991+00:00", "data": {"market": "0x16478811d537afdfadaacef3bf1fc8b61ed86385968321b7d9250bdce2a49748", "price_changes": [{"asset_id": "92269994048518357863385104036810846326684031835851654275504679077189526944972", "price": "0.874", "size": "0", "side": "BUY", "hash": "3e35940e67350db84b64190412c156c8c2da10e2", "best_bid": "0.929", "best_ask": "0.985"}, {"asset_id": "19197134752918366634342328847356807761591702594573815533235857894615009285668", "price": "0.126", "size": "0", "side": "SELL", "hash": "1138024ccc164ecec764f2a87c1f4e6c0a94259b", "best_bid": "0.015", "best_ask": "0.071"}], "timestamp": "1769384686391", "event_type": "price_change"}}
{"_local_timestamp": "2026-01-25T23:44:46.590076+00:00", "data": {"market": "0xe7d699841d03f695da20c8935f4cdf809057f3b27fa4f382e327ff731b8d75a7", "price_changes": [{"asset_id": "86720801120812523206375862885554727968671842048571953285734439150624995757719", "price": "0.86", "size": "0", "side": "BUY", "hash": "e9f39817d95fb9dd7c33884f2002f15ee86ef60f", "best_bid": "0.95", "best_ask": "0.97"}, {"asset_id": "40666723045616055650551965571535047681860486685123797401746526747593369094525", "price": "0.14", "size": "0", "side": "SELL", "hash": "cea0ebd7b026bf8229fcfa09eb07fac696808df7", "best_bid": "0.03", "best_ask": "0.05"}], "timestamp": "1769384686392", "event_type": "price_change"}}
{"_local_timestamp": "2026-01-25T23:44:46.591137+00:00", "data": {"market": "0x23e782e8db3eb990b48ff37432f9f0899e73ea737e68d2934bd09b34934dc0d0", "price_changes": [{"asset_id": "42382535584090931070184963017291726037912989687255284323203344679942164276749", "price": "0.87", "size": "20", "side": "BUY", "hash": "3d4b567e34c46ce6043b49e57460a05141681ea2", "best_bid": "0.87", "best_ask": "0.98"}, {"asset_id": "35728543926876832227758010997325479102150155332621985448512538195119929531554", "price": "0.13", "size": "20", "side": "SELL", "hash": "59cc18f5e09f6336958125a04ca0c53c67f27a2f", "best_bid": "0.02", "best_ask": "0.13"}], "timestamp": "1769384686392", "event_type": "price_change"}}
{"_local_timestamp": "2026-01-25T23:44:46.731689+00:00", "data": {"market": "0xad1f282f187c4748fe6eb51153a39557c66856cd14408bc3d509d3b23c047d41", "price_changes": [{"asset_id": "26089319074590795210476289468934414386490143191167179409102092139417103170837", "price": "0.3", "size": "116.66", "side": "BUY", "hash": "784e26f684c05003d741199f07c41132890effe4", "best_bid": "0.35", "best_ask": "0.46"}, {"asset_id": "86814839478893548397184492422021698202794732526767012779986423826365559163504", "price": "0.7", "size": "116.66", "side": "SELL", "hash": "ef6e9a635764ec6b718279e9a7b30fb43bc730ef", "best_bid": "0.54", "best_ask": "0.65"}], "timestamp": "1769384686527", "event_type": "price_change"}}
{"_local_timestamp": "2026-01-25T23:44:46.797605+00:00", "data": {"market": "0x16478811d537afdfadaacef3bf1fc8b61ed86385968321b7d9250bdce2a49748", "price_changes": [{"asset_id": "92269994048518357863385104036810846326684031835851654275504679077189526944972", "price": "0.64", "size": "105", "side": "BUY", "hash": "0b29854dd8cd71ab712bb8cdfe426e66ee98133d", "best_bid": "0.929", "best_ask": "0.985"}, {"asset_id": "19197134752918366634342328847356807761591702594573815533235857894615009285668", "price": "0.36", "size": "105", "side": "SELL", "hash": "b8282baa44c9dfa98bb833b92acee5344817f1f9", "best_bid": "0.015", "best_ask": "0.071"}], "timestamp": "1769384686596", "event_type": "price_change"}}
{"_local_timestamp": "2026-01-25T23:44:57.036729+00:00", "data": {"market": "0xfacaaf8ca81b788f8da594acaf23af2ef90037d82580b91357be35f97229e3a5", "price_changes": [{"asset_id": "94754153121378446077535791604860675458774881690932146680120328837949383988913", "price": "0.24", "size": "50", "side": "BUY", "hash": "46f3d0208771c9c862b5c7b32265246a7be13877", "best_bid": "0.26", "best_ask": "0.3"}, {"asset_id": "49741609004781342711179849070128334110798460232218737742146637694522428416234", "price": "0.76", "size": "50", "side": "SELL", "hash": "570b61cf6d4f825a5f918f9d6ac3a4c5c3378876", "best_bid": "0.7", "best_ask": "0.74"}], "timestamp": "1769384696918", "event_type": "price_change"}}
{"_local_timestamp": "2026-01-25T23:44:57.555073+00:00", "data": {"market": "0xad1f282f187c4748fe6eb51153a39557c66856cd14408bc3d509d3b23c047d41", "price_changes": [{"asset_id": "86814839478893548397184492422021698202794732526767012779986423826365559163504", "price": "0.22", "size": "100", "side": "BUY", "hash": "3ac10dec1bb66772412d425ac918eb3eaf52825f", "best_bid": "0.54", "best_ask": "0.65"}, {"asset_id": "26089319074590795210476289468934414386490143191167179409102092139417103170837", "price": "0.78", "size": "100", "side": "SELL", "hash": "10ca5c8a4848a97f3830a52672edeb7da42e82a3", "best_bid": "0.35", "best_ask": "0.46"}], "timestamp": "1769384697466", "event_type": "price_change"}}
{"_local_timestamp": "2026-01-25T23:44:57.717952+00:00", "data": {"market": "0xe7d699841d03f695da20c8935f4cdf809057f3b27fa4f382e327ff731b8d75a7", "price_changes": [{"asset_id": "86720801120812523206375862885554727968671842048571953285734439150624995757719", "price": "0.3", "size": "0", "side": "BUY", "hash": "d230e4cd41c14ad98704667e4ec3cd9850de861d", "best_bid": "0.95", "best_ask": "0.97"}, {"asset_id": "40666723045616055650551965571535047681860486685123797401746526747593369094525", "price": "0.7", "size": "0", "side": "SELL", "hash": "f26fae7a3ae091ec535bd183777784bbc5256cab", "best_bid": "0.03", "best_ask": "0.05"}], "timestamp": "1769384697640", "event_type": "price_change"}}
{"_local_timestamp": "2026-01-25T23:44:57.719141+00:00", "data": {"market": "0xe7d699841d03f695da20c8935f4cdf809057f3b27fa4f382e327ff731b8d75a7", "price_changes": [{"asset_id": "86720801120812523206375862885554727968671842048571953285734439150624995757719", "price": "0.23", "size": "0", "side": "BUY", "hash": "d230e4cd41c14ad98704667e4ec3cd9850de861d", "best_bid": "0.95", "best_ask": "0.97"}, {"asset_id": "40666723045616055650551965571535047681860486685123797401746526747593369094525", "price": "0.77", "size": "0", "side": "SELL", "hash": "f26fae7a3ae091ec535bd183777784bbc5256cab", "best_bid": "0.03", "best_ask": "0.05"}], "timestamp": "1769384697640", "event_type": "price_change"}}
{"_local_timestamp": "2026-01-25T23:44:57.872388+00:00", "data": {"market": "0xad1f282f187c4748fe6eb51153a39557c66856cd14408bc3d509d3b23c047d41", "price_changes": [{"asset_id": "86814839478893548397184492422021698202794732526767012779986423826365559163504", "price": "0.24", "size": "200", "side": "BUY", "hash": "909e412198ce6eab20899f2af7e5c39582220856", "best_bid": "0.54", "best_ask": "0.65"}, {"asset_id": "26089319074590795210476289468934414386490143191167179409102092139417103170837", "price": "0.76", "size": "200", "side": "SELL", "hash": "7951d68597cbf7a2e2438b1c7a7c993d0d999bcb", "best_bid": "0.35", "best_ask": "0.46"}], "timestamp": "1769384697734", "event_type": "price_change"}}
{"_local_timestamp": "2026-01-25T23:44:58.360337+00:00", "data": {"market": "0xe7d699841d03f695da20c8935f4cdf809057f3b27fa4f382e327ff731b8d75a7", "price_changes": [{"asset_id": "86720801120812523206375862885554727968671842048571953285734439150624995757719", "price": "0.29", "size": "189.65", "side": "BUY", "hash": "4dac871adf041ae07fdda1fa2f367ed257f4b8a6", "best_bid": "0.95", "best_ask": "0.97"}, {"asset_id": "40666723045616055650551965571535047681860486685123797401746526747593369094525", "price": "0.71", "size": "189.65", "side": "SELL", "hash": "b6090015dc6698552c73a060a6b4e2bbc442569b", "best_bid": "0.03", "best_ask": "0.05"}], "timestamp": "1769384698225", "event_type": "price_change"}}
{"_local_timestamp": "2026-01-25T23:44:58.449833+00:00", "data": {"market": "0xe7d699841d03f695da20c8935f4cdf809057f3b27fa4f382e327ff731b8d75a7", "price_changes": [{"asset_id": "86720801120812523206375862885554727968671842048571953285734439150624995757719", "price": "0.21", "size": "815.13", "side": "BUY", "hash": "c96afd7f0ec00c26c50ad3be97a32c4870077c5d", "best_bid": "0.95", "best_ask": "0.97"}, {"asset_id": "40666723045616055650551965571535047681860486685123797401746526747593369094525", "price": "0.79", "size": "815.13", "side": "SELL", "hash": "a8eee150c92ddf358a176106b240129618353a73", "best_bid": "0.03", "best_ask": "0.05"}], "timestamp": "1769384698251", "event_type": "price_change"}}
{"_local_timestamp": "2026-01-25T23:45:08.669306+00:00", "data": {"market": "0xe7d699841d03f695da20c8935f4cdf809057f3b27fa4f382e327ff731b8d75a7", "price_changes": [{"asset_id": "86720801120812523206375862885554727968671842048571953285734439150624995757719", "price": "0.25", "size": "1680", "side": "BUY", "hash": "3d8a4d2769500041abd76c207d17dcfd74d18d58", "best_bid": "0.95", "best_ask": "0.97"}, {"asset_id": "40666723045616055650551965571535047681860486685123797401746526747593369094525", "price": "0.75", "size": "1680", "side": "SELL", "hash": "1adb5547452933de75f149cf7669c8a8403e4187", "best_bid": "0.03", "best_ask": "0.05"}], "timestamp": "1769384708597", "event_type": "price_change"}}
{"_local_timestamp": "2026-01-25T23:45:18.977694+00:00", "data": {"market": "0x2649d46f6793c9847cc30659f7bcbec94578a23eda4c8cb86f31473173561986", "price_changes": [{"asset_id": "36826320465768064966532909273686181587790905146292730121626683737598046568291", "price": "0.003", "size": "59.61", "side": "BUY", "hash": "df907ba514179bf6359af2be7dff4857a3818ebc", "best_bid": "0.015", "best_ask": "0.061"}, {"asset_id": "37921534922010226146703074549600791269918801302227759309433381423805138270558", "price": "0.997", "size": "59.61", "side": "SELL", "hash": "7b624a30104175cf947b5b2c95538f40aada4275", "best_bid": "0.939", "best_ask": "0.985"}], "timestamp": "1769384718894", "event_type": "price_change"}}
{"_local_timestamp": "2026-01-25T23:45:19.139491+00:00", "data": {"market": "0xad1f282f187c4748fe6eb51153a39557c66856cd14408bc3d509d3b23c047d41", "price_changes": [{"asset_id": "26089319074590795210476289468934414386490143191167179409102092139417103170837", "price": "0.2", "size": "0", "side": "BUY", "hash": "d0fa2568f80122f9cc5742e4a8f9a4d957ee0adf", "best_bid": "0.35", "best_ask": "0.46"}, {"asset_id": "86814839478893548397184492422021698202794732526767012779986423826365559163504", "price": "0.8", "size": "0", "side": "SELL", "hash": "7a7e2b20a59f186124a6e8a5a8cd8dbe89908add", "best_bid": "0.54", "best_ask": "0.65"}], "timestamp": "1769384719039", "event_type": "price_change"}}
{"_local_timestamp": "2026-01-25T23:45:19.241351+00:00", "data": {"market": "0xad1f282f187c4748fe6eb51153a39557c66856cd14408bc3d509d3b23c047d41", "price_changes": [{"asset_id": "26089319074590795210476289468934414386490143191167179409102092139417103170837", "price": "0.3", "size": "136.66", "side": "BUY", "hash": "56796523dd4878897481decf4512a86ad9152d8e", "best_bid": "0.35", "best_ask": "0.46"}, {"asset_id": "86814839478893548397184492422021698202794732526767012779986423826365559163504", "price": "0.7", "size": "136.66", "side": "SELL", "hash": "17b46736d1852c02757bd026a99c69dfb0be3b4b", "best_bid": "0.54", "best_ask": "0.65"}], "timestamp": "1769384719171", "event_type": "price_change"}}
{"_local_timestamp": "2026-01-25T23:45:19.242541+00:00", "data": {"market": "0xad1f282f187c4748fe6eb51153a39557c66856cd14408bc3d509d3b23c047d41", "price_changes": [{"asset_id": "26089319074590795210476289468934414386490143191167179409102092139417103170837", "price": "0.2", "size": "25", "side": "BUY", "hash": "8aa2211cd33966e586180740c4968e1e25354844", "best_bid": "0.35", "best_ask": "0.46"}, {"asset_id": "86814839478893548397184492422021698202794732526767012779986423826365559163504", "price": "0.8", "size": "25", "side": "SELL", "hash": "cfa34620049982dc80f555b64c81f1bf1c3cd468", "best_bid": "0.54", "best_ask": "0.65"}], "timestamp": "1769384719172", "event_type": "price_change"}}
{"_local_timestamp": "2026-01-25T23:45:19.270195+00:00", "data": {"market": "0x2649d46f6793c9847cc30659f7bcbec94578a23eda4c8cb86f31473173561986", "price_changes": [{"asset_id": "36826320465768064966532909273686181587790905146292730121626683737598046568291", "price": "0.004", "size": "18.62", "side": "BUY", "hash": "b5987364dfb30c1f9f5e681d0e6d2f0443777967", "best_bid": "0.015", "best_ask": "0.061"}, {"asset_id": "37921534922010226146703074549600791269918801302227759309433381423805138270558", "price": "0.996", "size": "18.62", "side": "SELL", "hash": "d1c30d91ec8fb5b574880ff0b8a0f55cead452b6", "best_bid": "0.939", "best_ask": "0.985"}], "timestamp": "1769384719199", "event_type": "price_change"}}
{"_local_timestamp": "2026-01-25T23:45:22.780812+00:00", "data": {"market": "0xfacaaf8ca81b788f8da594acaf23af2ef90037d82580b91357be35f97229e3a5", "price_changes": [{"asset_id": "49741609004781342711179849070128334110798460232218737742146637694522428416234", "price": "0.7", "size": "133.92", "side": "BUY", "hash": "5ec4ae3e9c73a1fb8ce1ef4e56975e996dd15812", "best_bid": "0.7", "best_ask": "0.74"}, {"asset_id": "94754153121378446077535791604860675458774881690932146680120328837949383988913", "price": "0.3", "size": "133.92", "side": "SELL", "hash": "0ae2eb9ed8c4c5dc7e9ecc8a7ce22ee98befc226", "best_bid": "0.26", "best_ask": "0.3"}], "timestamp": "1769384722707", "event_type": "price_change"}}
{"_local_timestamp": "2026-01-25T23:45:22.850460+00:00", "data": {"market": "0xe7d699841d03f695da20c8935f4cdf809057f3b27fa4f382e327ff731b8d75a7", "price_changes": [{"asset_id": "86720801120812523206375862885554727968671842048571953285734439150624995757719", "price": "0.93", "size": "75", "side": "BUY", "hash": "86bc41a5a84c829345f0b5e47412d4b57aacdfb5", "best_bid": "0.95", "best_ask": "0.97"}, {"asset_id": "40666723045616055650551965571535047681860486685123797401746526747593369094525", "price": "0.07", "size": "75", "side": "SELL", "hash": "f6c9aa7ff37635f9938620a9ba10e3367672e882", "best_bid": "0.03", "best_ask": "0.05"}], "timestamp": "1769384722772", "event_type": "price_change"}}
{"_local_timestamp": "2026-01-25T23:45:22.855613+00:00", "data": {"market": "0xe7d699841d03f695da20c8935f4cdf809057f3b27fa4f382e327ff731b8d75a7", "price_changes": [{"asset_id": "40666723045616055650551965571535047681860486685123797401746526747593369094525", "price": "0.01", "size": "1750", "side": "BUY", "hash": "8db8706c63665af860b2280ea016cdeda1784415", "best_bid": "0.03", "best_ask": "0.05"}, {"asset_id": "86720801120812523206375862885554727968671842048571953285734439150624995757719", "price": "0.99", "size": "1750", "side": "SELL", "hash": "5d61a44906a35d9054c59d43c32ee5f6987daa5f", "best_bid": "0.95", "best_ask": "0.97"}], "timestamp": "1769384722773", "event_type": "price_change"}}
{"_local_timestamp": "2026-01-25T23:45:25.427847+00:00", "data": {"market": "0xfacaaf8ca81b788f8da594acaf23af2ef90037d82580b91357be35f97229e3a5", "price_changes": [{"asset_id": "94754153121378446077535791604860675458774881690932146680120328837949383988913", "price": "0.24", "size": "100", "side": "BUY", "hash": "e9447bccac652a265a5cd4245cb589d66fc60499", "best_bid": "0.26", "best_ask": "0.3"}, {"asset_id": "49741609004781342711179849070128334110798460232218737742146637694522428416234", "price": "0.76", "size": "100", "side": "SELL", "hash": "40e924a570a9c4f4a23b562ee979a0129bbd6dc9", "best_bid": "0.7", "best_ask": "0.74"}], "timestamp": "1769384725358", "event_type": "price_change"}}
{"_local_timestamp": "2026-01-25T23:45:38.908405+00:00", "data": {"market": "0xe7d699841d03f695da20c8935f4cdf809057f3b27fa4f382e327ff731b8d75a7", "price_changes": [{"asset_id": "86720801120812523206375862885554727968671842048571953285734439150624995757719", "price": "0.24", "size": "116.66", "side": "BUY", "hash": "f5399620874ff575b95e6f6693111409f38a17bc", "best_bid": "0.95", "best_ask": "0.97"}, {"asset_id": "40666723045616055650551965571535047681860486685123797401746526747593369094525", "price": "0.76", "size": "116.66", "side": "SELL", "hash": "a00c08ae55fe7b4c7a8e161d32b69d23413d2fbb", "best_bid": "0.03", "best_ask": "0.05"}], "timestamp": "1769384738813", "event_type": "price_change"}}
{"_local_timestamp": "2026-01-25T23:45:39.217528+00:00", "data": {"market": "0xe7d699841d03f695da20c8935f4cdf809057f3b27fa4f382e327ff731b8d75a7", "price_changes": [{"asset_id": "86720801120812523206375862885554727968671842048571953285734439150624995757719", "price": "0.21", "size": "915.13", "side": "BUY", "hash": "197915c3a1612e27ed86d3f42c157a02b9197f8f", "best_bid": "0.95", "best_ask": "0.97"}, {"asset_id": "40666723045616055650551965571535047681860486685123797401746526747593369094525", "price": "0.79", "size": "915.13", "side": "SELL", "hash": "2bdc50cb91c0f8b61d5c75d8250175d7e98ba29e", "best_bid": "0.03", "best_ask": "0.05"}], "timestamp": "1769384739077", "event_type": "price_change"}}
{"_local_timestamp": "2026-01-25T23:45:40.135427+00:00", "data": {"market": "0xe7d699841d03f695da20c8935f4cdf809057f3b27fa4f382e327ff731b8d75a7", "price_changes": [{"asset_id": "40666723045616055650551965571535047681860486685123797401746526747593369094525", "price": "0.01", "size": "1800", "side": "BUY", "hash": "a1b76e59c2438f765a5e3a5b04a3496de4e56b79", "best_bid": "0.03", "best_ask": "0.05"}, {"asset_id": "86720801120812523206375862885554727968671842048571953285734439150624995757719", "price": "0.99", "size": "1800", "side": "SELL", "hash": "310d372199875025c2d200b7535fbc7a3cda1b85", "best_bid": "0.95", "best_ask": "0.97"}], "timestamp": "1769384740059", "event_type": "price_change"}}
{"_local_timestamp": "2026-01-25T23:45:51.400620+00:00", "data": {"market": "0xfacaaf8ca81b788f8da594acaf23af2ef90037d82580b91357be35f97229e3a5", "price_changes": [{"asset_id": "49741609004781342711179849070128334110798460232218737742146637694522428416234", "price": "0.64", "size": "0", "side": "BUY", "hash": "386a35194efeb3f44acd1eaf41aa336d66998696", "best_bid": "0.7", "best_ask": "0.74"}, {"asset_id": "94754153121378446077535791604860675458774881690932146680120328837949383988913", "price": "0.36", "size": "0", "side": "SELL", "hash": "16595cc69c2758c876f98573655038fe3215153d", "best_bid": "0.26", "best_ask": "0.3"}], "timestamp": "1769384751324", "event_type": "price_change"}}
{"_local_timestamp": "2026-01-25T23:45:51.401875+00:00", "data": {"market": "0xfacaaf8ca81b788f8da594acaf23af2ef90037d82580b91357be35f97229e3a5", "price_changes": [{"asset_id": "49741609004781342711179849070128334110798460232218737742146637694522428416234", "price": "0.57", "size": "0", "side": "BUY", "hash": "386a35194efeb3f44acd1eaf41aa336d66998696", "best_bid": "0.7", "best_ask": "0.74"}, {"asset_id": "94754153121378446077535791604860675458774881690932146680120328837949383988913", "price": "0.43", "size": "0", "side": "SELL", "hash": "16595cc69c2758c876f98573655038fe3215153d", "best_bid": "0.26", "best_ask": "0.3"}], "timestamp": "1769384751324", "event_type": "price_change"}}
{"_local_timestamp": "2026-01-25T23:45:51.425685+00:00", "data": {"market": "0xfacaaf8ca81b788f8da594acaf23af2ef90037d82580b91357be35f97229e3a5", "price_changes": [{"asset_id": "49741609004781342711179849070128334110798460232218737742146637694522428416234", "price": "0.7", "size": "50", "side": "BUY", "hash": "03bf70f6a0ed1c53501399df970f454c5277a9aa", "best_bid": "0.7", "best_ask": "0.74"}, {"asset_id": "94754153121378446077535791604860675458774881690932146680120328837949383988913", "price": "0.3", "size": "50", "side": "SELL", "hash": "baeb4f64962d1b35f8f74608da11b3d4e47bc1ac", "best_bid": "0.26", "best_ask": "0.3"}], "timestamp": "1769384751358", "event_type": "price_change"}}
{"_local_timestamp": "2026-01-25T23:45:52.054560+00:00", "data": {"market": "0xfacaaf8ca81b788f8da594acaf23af2ef90037d82580b91357be35f97229e3a5", "price_changes": [{"asset_id": "49741609004781342711179849070128334110798460232218737742146637694522428416234", "price": "0.57", "size": "66.66", "side": "BUY", "hash": "eff8cc9ea8333863072cda9dcbb5f344428e6cd3", "best_bid": "0.7", "best_ask": "0.74"}, {"asset_id": "94754153121378446077535791604860675458774881690932146680120328837949383988913", "price": "0.43", "size": "66.66", "side": "SELL", "hash": "0a618ce45426744f0d940f1f2ad8fb3f3bfe2e44", "best_bid": "0.26", "best_ask": "0.3"}], "timestamp": "1769384751986", "event_type": "price_change"}}
{"_local_timestamp": "2026-01-25T23:45:52.225650+00:00", "data": {"market": "0xfacaaf8ca81b788f8da594acaf23af2ef90037d82580b91357be35f97229e3a5", "price_changes": [{"asset_id": "49741609004781342711179849070128334110798460232218737742146637694522428416234", "price": "0.71", "size": "66.66", "side": "BUY", "hash": "c09fa8828831c4e574687b28ef1219a6756f6ae6", "best_bid": "0.71", "best_ask": "0.74"}, {"asset_id": "94754153121378446077535791604860675458774881690932146680120328837949383988913", "price": "0.29", "size": "66.66", "side": "SELL", "hash": "6ef839bcf4b39e2c45e5872a1bfee69aa4187d01", "best_bid": "0.26", "best_ask": "0.29"}], "timestamp": "1769384752158", "event_type": "price_change"}}
{"_local_timestamp": "2026-01-25T23:45:52.309077+00:00", "data": {"market": "0xfacaaf8ca81b788f8da594acaf23af2ef90037d82580b91357be35f97229e3a5", "price_changes": [{"asset_id": "49741609004781342711179849070128334110798460232218737742146637694522428416234", "price": "0.64", "size": "66.66", "side": "BUY", "hash": "c6efa94a90109d4f4d6db391535aafc0da1c6e88", "best_bid": "0.71", "best_ask": "0.74"}, {"asset_id": "94754153121378446077535791604860675458774881690932146680120328837949383988913", "price": "0.36", "size": "66.66", "side": "SELL", "hash": "5af2f1d1e62cf2ba99e070631538562944955d36", "best_bid": "0.26", "best_ask": "0.29"}], "timestamp": "1769384752240", "event_type": "price_change"}}
{"_local_timestamp": "2026-01-25T23:45:53.211050+00:00", "data": {"market": "0xe7d699841d03f695da20c8935f4cdf809057f3b27fa4f382e327ff731b8d75a7", "price_changes": [{"asset_id": "86720801120812523206375862885554727968671842048571953285734439150624995757719", "price": "0.22", "size": "100", "side": "BUY", "hash": "9fff4c79cd1d214ad03a73fc76a6838866fe504c", "best_bid": "0.95", "best_ask": "0.97"}, {"asset_id": "40666723045616055650551965571535047681860486685123797401746526747593369094525", "price": "0.78", "size": "100", "side": "SELL", "hash": "72c311aef6bf539702af6bdc50bec694cd7c482e", "best_bid": "0.03", "best_ask": "0.05"}], "timestamp": "1769384753014", "event_type": "price_change"}}
{"_local_timestamp": "2026-01-25T23:45:53.702693+00:00", "data": {"market": "0xe7d699841d03f695da20c8935f4cdf809057f3b27fa4f382e327ff731b8d75a7", "price_changes": [{"asset_id": "86720801120812523206375862885554727968671842048571953285734439150624995757719", "price": "0.24", "size": "166.66", "side": "BUY", "hash": "2e56f41671be684b5d39382a91d10615073fb091", "best_bid": "0.95", "best_ask": "0.97"}, {"asset_id": "40666723045616055650551965571535047681860486685123797401746526747593369094525", "price": "0.76", "size": "166.66", "side": "SELL", "hash": "b21c291e4ef98fc03ba34f964546ce8ce0b99d87", "best_bid": "0.03", "best_ask": "0.05"}], "timestamp": "1769384753521", "event_type": "price_change"}}
{"_local_timestamp": "2026-01-25T23:45:54.704308+00:00", "data": {"market": "0x16478811d537afdfadaacef3bf1fc8b61ed86385968321b7d9250bdce2a49748", "price_changes": [{"asset_id": "92269994048518357863385104036810846326684031835851654275504679077189526944972", "price": "0.64", "size": "100", "side": "BUY", "hash": "9d8035236ad38be6f39073d6f4af975a5586fdf7", "best_bid": "0.929", "best_ask": "0.985"}, {"asset_id": "19197134752918366634342328847356807761591702594573815533235857894615009285668", "price": "0.36", "size": "100", "side": "SELL", "hash": "fe59ef19b666896bd46adc59fddacb3df87b64b8", "best_bid": "0.015", "best_ask": "0.071"}], "timestamp": "1769384754619", "event_type": "price_change"}}
{"_local_timestamp": "2026-01-25T23:45:54.893908+00:00", "data": {"market": "0x16478811d537afdfadaacef3bf1fc8b61ed86385968321b7d9250bdce2a49748", "price_changes": [{"asset_id": "92269994048518357863385104036810846326684031835851654275504679077189526944972", "price": "0.64", "size": "105", "side": "BUY", "hash": "3cd4eb08d5da6bd033f98ab6e90809a17373234e", "best_bid": "0.929", "best_ask": "0.985"}, {"asset_id": "19197134752918366634342328847356807761591702594573815533235857894615009285668", "price": "0.36", "size": "105", "side": "SELL", "hash": "e60e6df67782b61da85036547f9c235855a3eb6c", "best_bid": "0.015", "best_ask": "0.071"}], "timestamp": "1769384754828", "event_type": "price_change"}}
{"_local_timestamp": "2026-01-25T23:45:56.537973+00:00", "data": {"market": "0x23e782e8db3eb990b48ff37432f9f0899e73ea737e68d2934bd09b34934dc0d0", "price_changes": [{"asset_id": "42382535584090931070184963017291726037912989687255284323203344679942164276749", "price": "0.282", "size": "436", "side": "BUY", "hash": "badd6ca34c7bb44767a1ae696a1aae90d9bd23d0", "best_bid": "0.87", "best_ask": "0.98"}, {"asset_id": "35728543926876832227758010997325479102150155332621985448512538195119929531554", "price": "0.718", "size": "436", "side": "SELL", "hash": "56b0694e196c08c05c05b9bdd8c2a5fb213f26b9", "best_bid": "0.02", "best_ask": "0.13"}], "timestamp": "1769384756085", "event_type": "price_change"}}
{"_local_timestamp": "2026-01-25T23:45:59.040633+00:00", "data": {"market": "0xe7d699841d03f695da20c8935f4cdf809057f3b27fa4f382e327ff731b8d75a7", "price_changes": [{"asset_id": "86720801120812523206375862885554727968671842048571953285734439150624995757719", "price": "0.93", "size": "125", "side": "BUY", "hash": "fdfc2cb24b0f75f970c3b13eeaabd727fbc5043a", "best_bid": "0.95", "best_ask": "0.97"}, {"asset_id": "40666723045616055650551965571535047681860486685123797401746526747593369094525", "price": "0.07", "size": "125", "side": "SELL", "hash": "e68cbddd72c801bb4a59ad127d2e3ef0e082fbf8", "best_bid": "0.03", "best_ask": "0.05"}], "timestamp": "1769384758967", "event_type": "price_change"}}
{"_local_timestamp": "2026-01-25T23:46:02.801359+00:00", "data": {"market": "0xfacaaf8ca81b788f8da594acaf23af2ef90037d82580b91357be35f97229e3a5", "price_changes": [{"asset_id": "49741609004781342711179849070128334110798460232218737742146637694522428416234", "price": "0.68", "size": "100", "side": "BUY", "hash": "1990feb59820a8ab1c30546db6a49cedf0bf479d", "best_bid": "0.71", "best_ask": "0.74"}, {"asset_id": "94754153121378446077535791604860675458774881690932146680120328837949383988913", "price": "0.32", "size": "100", "side": "SELL", "hash": "6c1a429bbf0cc473114cc80ad907858c3b39227d", "best_bid": "0.26", "best_ask": "0.29"}], "timestamp": "1769384762730", "event_type": "price_change"}}
{"_local_timestamp": "2026-01-25T23:46:10.642253+00:00", "data": {"market": "0xe7d699841d03f695da20c8935f4cdf809057f3b27fa4f382e327ff731b8d75a7", "price_changes": [{"asset_id": "86720801120812523206375862885554727968671842048571953285734439150624995757719", "price": "0.25", "size": "0", "side": "BUY", "hash": "acd4fc629f406f5544a51852bbb8b72e2fdd3e01", "best_bid": "0.95", "best_ask": "0.97"}, {"asset_id": "40666723045616055650551965571535047681860486685123797401746526747593369094525", "price": "0.75", "size": "0", "side": "SELL", "hash": "1498685170754b999b7c2d95565a80bff2a1f849", "best_bid": "0.03", "best_ask": "0.05"}], "timestamp": "1769384770462", "event_type": "price_change"}}
{"_local_timestamp": "2026-01-25T23:46:11.245766+00:00", "data": {"market": "0x2649d46f6793c9847cc30659f7bcbec94578a23eda4c8cb86f31473173561986", "price_changes": [{"asset_id": "36826320465768064966532909273686181587790905146292730121626683737598046568291", "price": "0.013", "size": "26.04", "side": "BUY", "hash": "abe22690666476ad107dc61638224630a7f4e2ed", "best_bid": "0.015", "best_ask": "0.061"}, {"asset_id": "37921534922010226146703074549600791269918801302227759309433381423805138270558", "price": "0.987", "size": "26.04", "side": "SELL", "hash": "670116f345a477c32add534dfed94ce5f7a9caee", "best_bid": "0.939", "best_ask": "0.985"}], "timestamp": "1769384771120", "event_type": "price_change"}}
{"_local_timestamp": "2026-01-25T23:46:11.247353+00:00", "data": {"market": "0x16478811d537afdfadaacef3bf1fc8b61ed86385968321b7d9250bdce2a49748", "price_changes": [{"asset_id": "19197134752918366634342328847356807761591702594573815533235857894615009285668", "price": "0.013", "size": "0", "side": "BUY", "hash": "196ab8e17484aa641ea81d2344c5d882bef35d55", "best_bid": "0.015", "best_ask": "0.071"}, {"asset_id": "92269994048518357863385104036810846326684031835851654275504679077189526944972", "price": "0.987", "size": "0", "side": "SELL", "hash": "84e679c60cb55b93929883217a1d1783e068852e", "best_bid": "0.929", "best_ask": "0.985"}], "timestamp": "1769384771120", "event_type": "price_change"}}
{"_local_timestamp": "2026-01-25T23:46:11.687957+00:00", "data": {"market": "0x16478811d537afdfadaacef3bf1fc8b61ed86385968321b7d9250bdce2a49748", "price_changes": [{"asset_id": "19197134752918366634342328847356807761591702594573815533235857894615009285668", "price": "0.012", "size": "216.66", "side": "BUY", "hash": "741ec19785163b8519d5f6e6ef084d0585feaf56", "best_bid": "0.015", "best_ask": "0.071"}, {"asset_id": "92269994048518357863385104036810846326684031835851654275504679077189526944972", "price": "0.988", "size": "216.66", "side": "SELL", "hash": "6e40ae744512d14d51f905f5b81656fa9d0079e5", "best_bid": "0.929", "best_ask": "0.985"}], "timestamp": "1769384771581", "event_type": "price_change"}}
{"_local_timestamp": "2026-01-25T23:46:11.689227+00:00", "data": {"market": "0x2649d46f6793c9847cc30659f7bcbec94578a23eda4c8cb86f31473173561986", "price_changes": [{"asset_id": "36826320465768064966532909273686181587790905146292730121626683737598046568291", "price": "0.012", "size": "326.04", "side": "BUY", "hash": "ddf3ed58f0943b2da5c0ec814ee61422691eebaa", "best_bid": "0.015", "best_ask": "0.061"}, {"asset_id": "37921534922010226146703074549600791269918801302227759309433381423805138270558", "price": "0.988", "size": "326.04", "side": "SELL", "hash": "e4bfd91e08a164cfec6fc6a6da3b8797526833ab", "best_bid": "0.939", "best_ask": "0.985"}], "timestamp": "1769384771581", "event_type": "price_change"}}
{"_local_timestamp": "2026-01-25T23:46:16.582062+00:00", "data": {"market": "0x23e782e8db3eb990b48ff37432f9f0899e73ea737e68d2934bd09b34934dc0d0", "price_changes": [{"asset_id": "42382535584090931070184963017291726037912989687255284323203344679942164276749", "price": "0.283", "size": "300", "side": "BUY", "hash": "d19c1c2883c9487762b35dfd0448b696b1d18834", "best_bid": "0.87", "best_ask": "0.98"}, {"asset_id": "35728543926876832227758010997325479102150155332621985448512538195119929531554", "price": "0.717", "size": "300", "side": "SELL", "hash": "5e9d2c139dc0e344bd62b0cfc4859a897cf9652e", "best_bid": "0.02", "best_ask": "0.13"}], "timestamp": "1769384776514", "event_type": "price_change"}}
{"_local_timestamp": "2026-01-25T23:46:16.773214+00:00", "data": {"market": "0x23e782e8db3eb990b48ff37432f9f0899e73ea737e68d2934bd09b34934dc0d0", "price_changes": [{"asset_id": "42382535584090931070184963017291726037912989687255284323203344679942164276749", "price": "0.282", "size": "100", "side": "BUY", "hash": "427fc327165eed42674aec93939fa582e8d9a038", "best_bid": "0.87", "best_ask": "0.98"}, {"asset_id": "35728543926876832227758010997325479102150155332621985448512538195119929531554", "price": "0.718", "size": "100", "side": "SELL", "hash": "c5fb50f8dd053dfac5cc089f18cce34221650015", "best_bid": "0.02", "best_ask": "0.13"}], "timestamp": "1769384776701", "event_type": "price_change"}}
{"_local_timestamp": "2026-01-25T23:46:17.445179+00:00", "data": {"market": "0xe7d699841d03f695da20c8935f4cdf809057f3b27fa4f382e327ff731b8d75a7", "price_changes": [{"asset_id": "86720801120812523206375862885554727968671842048571953285734439150624995757719", "price": "0.21", "size": "815.13", "side": "BUY", "hash": "91a044e4c4db0d29675aa57a69dd89df6bc239ee", "best_bid": "0.95", "best_ask": "0.97"}, {"asset_id": "40666723045616055650551965571535047681860486685123797401746526747593369094525", "price": "0.79", "size": "815.13", "side": "SELL", "hash": "2d81d5167c03d018f5ed726329638219a0ebb50d", "best_bid": "0.03", "best_ask": "0.05"}], "timestamp": "1769384777373", "event_type": "price_change"}}
{"_local_timestamp": "2026-01-25T23:46:17.657110+00:00", "data": {"market": "0x23e782e8db3eb990b48ff37432f9f0899e73ea737e68d2934bd09b34934dc0d0", "price_changes": [{"asset_id": "42382535584090931070184963017291726037912989687255284323203344679942164276749", "price": "0.647", "size": "15", "side": "BUY", "hash": "8ef548093e73ce7fc2bf52acae0afe93c23b8cf3", "best_bid": "0.87", "best_ask": "0.98"}, {"asset_id": "35728543926876832227758010997325479102150155332621985448512538195119929531554", "price": "0.353", "size": "15", "side": "SELL", "hash": "afdd70965e73297cb4c0d82641b68e749dbb8395", "best_bid": "0.02", "best_ask": "0.13"}], "timestamp": "1769384777587", "event_type": "price_change"}}
{"_local_timestamp": "2026-01-25T23:46:17.658572+00:00", "data": {"market": "0x23e782e8db3eb990b48ff37432f9f0899e73ea737e68d2934bd09b34934dc0d0", "price_changes": [{"asset_id": "42382535584090931070184963017291726037912989687255284323203344679942164276749", "price": "0.283", "size": "533", "side": "BUY", "hash": "75c680e2e3bc2a3609f45936097cb5c03303867a", "best_bid": "0.87", "best_ask": "0.98"}, {"asset_id": "35728543926876832227758010997325479102150155332621985448512538195119929531554", "price": "0.717", "size": "533", "side": "SELL", "hash": "eb4d5d9312f1d8331f3ea626082dfdf493b2e1a4", "best_bid": "0.02", "best_ask": "0.13"}], "timestamp": "1769384777588", "event_type": "price_change"}}
{"_local_timestamp": "2026-01-25T23:46:17.662459+00:00", "data": {"market": "0x23e782e8db3eb990b48ff37432f9f0899e73ea737e68d2934bd09b34934dc0d0", "price_changes": [{"asset_id": "42382535584090931070184963017291726037912989687255284323203344679942164276749", "price": "0.647", "size": "25", "side": "BUY", "hash": "7cb53d62230302c25799cb932d48dee13df2d939", "best_bid": "0.87", "best_ask": "0.98"}, {"asset_id": "35728543926876832227758010997325479102150155332621985448512538195119929531554", "price": "0.353", "size": "25", "side": "SELL", "hash": "9c2712f97596549d70eba1eb8b78bb166f13dd6d", "best_bid": "0.02", "best_ask": "0.13"}], "timestamp": "1769384777589", "event_type": "price_change"}}
{"_local_timestamp": "2026-01-25T23:46:17.706913+00:00", "data": {"market": "0xe7d699841d03f695da20c8935f4cdf809057f3b27fa4f382e327ff731b8d75a7", "price_changes": [{"asset_id": "86720801120812523206375862885554727968671842048571953285734439150624995757719", "price": "0.25", "size": "100", "side": "BUY", "hash": "391b0bda230c5def0c8d168c3c4a073866684c4d", "best_bid": "0.95", "best_ask": "0.97"}, {"asset_id": "40666723045616055650551965571535047681860486685123797401746526747593369094525", "price": "0.75", "size": "100", "side": "SELL", "hash": "d3835e5fe6ac4005c18dc4597f7747f9ccf22d5f", "best_bid": "0.03", "best_ask": "0.05"}], "timestamp": "1769384777632", "event_type": "price_change"}}
{"_local_timestamp": "2026-01-25T23:46:20.973510+00:00", "data": {"market": "0x23e782e8db3eb990b48ff37432f9f0899e73ea737e68d2934bd09b34934dc0d0", "price_changes": [{"asset_id": "42382535584090931070184963017291726037912989687255284323203344679942164276749", "price": "0.646", "size": "0", "side": "BUY", "hash": "94aaa03e626d48645e0a9e9821762b8447be5ab8", "best_bid": "0.87", "best_ask": "0.98"}, {"asset_id": "35728543926876832227758010997325479102150155332621985448512538195119929531554", "price": "0.354", "size": "0", "side": "SELL", "hash": "c5658bc68ca4c03456940ccaa53b0e4a1c07c48a", "best_bid": "0.02", "best_ask": "0.13"}], "timestamp": "1769384780900", "event_type": "price_change"}}
{"_local_timestamp": "2026-01-25T23:46:21.005682+00:00", "data": {"market": "0x23e782e8db3eb990b48ff37432f9f0899e73ea737e68d2934bd09b34934dc0d0", "price_changes": [{"asset_id": "42382535584090931070184963017291726037912989687255284323203344679942164276749", "price": "0.648", "size": "20", "side": "BUY", "hash": "8cb94f322a0a0954d6b0d9a8882b9a6fc46c5f90", "best_bid": "0.87", "best_ask": "0.98"}, {"asset_id": "35728543926876832227758010997325479102150155332621985448512538195119929531554", "price": "0.352", "size": "20", "side": "SELL", "hash": "89367847558034c9f8a7258538972b14bf42b581", "best_bid": "0.02", "best_ask": "0.13"}], "timestamp": "1769384780933", "event_type": "price_change"}}
{"_local_timestamp": "2026-01-25T23:46:27.033894+00:00", "data": {"market": "0xe7d699841d03f695da20c8935f4cdf809057f3b27fa4f382e327ff731b8d75a7", "price_changes": [{"asset_id": "86720801120812523206375862885554727968671842048571953285734439150624995757719", "price": "0.3", "size": "1400", "side": "BUY", "hash": "d35aac999b38d5a8a6ca4eef94628156650c3b04", "best_bid": "0.95", "best_ask": "0.97"}, {"asset_id": "40666723045616055650551965571535047681860486685123797401746526747593369094525", "price": "0.7", "size": "1400", "side": "SELL", "hash": "27a3731c50fd126baa5f96e83331b2b4e672c153", "best_bid": "0.03", "best_ask": "0.05"}], "timestamp": "1769384786949", "event_type": "price_change"}}
{"_local_timestamp": "2026-01-25T23:46:50.955932+00:00", "data": {"market": "0xad1f282f187c4748fe6eb51153a39557c66856cd14408bc3d509d3b23c047d41", "price_changes": [{"asset_id": "86814839478893548397184492422021698202794732526767012779986423826365559163504", "price": "0.24", "size": "100", "side": "BUY", "hash": "1c3c42e201b9557d44b2738d523f37d80afe3e75", "best_bid": "0.54", "best_ask": "0.65"}, {"asset_id": "26089319074590795210476289468934414386490143191167179409102092139417103170837", "price": "0.76", "size": "100", "side": "SELL", "hash": "b05e519986fff723a8775a4c7fe1a8fde1484ab8", "best_bid": "0.35", "best_ask": "0.46"}], "timestamp": "1769384810670", "event_type": "price_change"}}
{"_local_timestamp": "2026-01-25T23:46:50.957571+00:00", "data": {"market": "0xe7d699841d03f695da20c8935f4cdf809057f3b27fa4f382e327ff731b8d75a7", "price_changes": [{"asset_id": "86720801120812523206375862885554727968671842048571953285734439150624995757719", "price": "0.22", "size": "0", "side": "BUY", "hash": "8c993fbced0a29fc8ce0be2a0b9fe02443edb343", "best_bid": "0.95", "best_ask": "0.97"}, {"asset_id": "40666723045616055650551965571535047681860486685123797401746526747593369094525", "price": "0.78", "size": "0", "side": "SELL", "hash": "7a529bd3f1b0f60d5389345595ef2fef745233a3", "best_bid": "0.03", "best_ask": "0.05"}], "timestamp": "1769384810670", "event_type": "price_change"}}
{"_local_timestamp": "2026-01-25T23:46:51.633473+00:00", "data": {"market": "0xe7d699841d03f695da20c8935f4cdf809057f3b27fa4f382e327ff731b8d75a7", "price_changes": [{"asset_id": "86720801120812523206375862885554727968671842048571953285734439150624995757719", "price": "0.24", "size": "266.66", "side": "BUY", "hash": "34c4601acdb0b5e582650e948679e5b8f717bf9b", "best_bid": "0.95", "best_ask": "0.97"}, {"asset_id": "40666723045616055650551965571535047681860486685123797401746526747593369094525", "price": "0.76", "size": "266.66", "side": "SELL", "hash": "c6367cb66f2e675a2ebefa69fc65c090c69baf1e", "best_bid": "0.03", "best_ask": "0.05"}], "timestamp": "1769384811241", "event_type": "price_change"}}
{"_local_timestamp": "2026-01-25T23:46:51.634949+00:00", "data": {"market": "0x16478811d537afdfadaacef3bf1fc8b61ed86385968321b7d9250bdce2a49748", "price_changes": [{"asset_id": "92269994048518357863385104036810846326684031835851654275504679077189526944972", "price": "0.4", "size": "125", "side": "BUY", "hash": "5a4014c6f0366e985a8d863c542a0f1870adefb0", "best_bid": "0.929", "best_ask": "0.985"}, {"asset_id": "19197134752918366634342328847356807761591702594573815533235857894615009285668", "price": "0.6", "size": "125", "side": "SELL", "hash": "78d63e016426ff0cbface053d6526ff99f75e061", "best_bid": "0.015", "best_ask": "0.071"}], "timestamp": "1769384811240", "event_type": "price_change"}}
{"_local_timestamp": "2026-01-25T23:46:51.650568+00:00", "data": {"market": "0xad1f282f187c4748fe6eb51153a39557c66856cd14408bc3d509d3b23c047d41", "price_changes": [{"asset_id": "86814839478893548397184492422021698202794732526767012779986423826365559163504", "price": "0.22", "size": "200", "side": "BUY", "hash": "9d5593f34ddeff12cb3d63e77d7c24461d468c07", "best_bid": "0.54", "best_ask": "0.65"}, {"asset_id": "26089319074590795210476289468934414386490143191167179409102092139417103170837", "price": "0.78", "size": "200", "side": "SELL", "hash": "49164c2c3d347645e64f467d0f2f9eb32fec0c93", "best_bid": "0.35", "best_ask": "0.46"}], "timestamp": "1769384811238", "event_type": "price_change"}}
{"_local_timestamp": "2026-01-25T23:46:55.707590+00:00", "data": {"market": "0x16478811d537afdfadaacef3bf1fc8b61ed86385968321b7d9250bdce2a49748", "price_changes": [{"asset_id": "92269994048518357863385104036810846326684031835851654275504679077189526944972", "price": "0.64", "size": "100", "side": "BUY", "hash": "7bd5dd7967f499959bcc029a54d6ef2ba357aec6", "best_bid": "0.929", "best_ask": "0.985"}, {"asset_id": "19197134752918366634342328847356807761591702594573815533235857894615009285668", "price": "0.36", "size": "100", "side": "SELL", "hash": "781d51df784ba0b5f75f03118c40c77f3e37a99e", "best_bid": "0.015", "best_ask": "0.071"}], "timestamp": "1769384815640", "event_type": "price_change"}}
{"_local_timestamp": "2026-01-25T23:46:56.059828+00:00", "data": {"market": "0x16478811d537afdfadaacef3bf1fc8b61ed86385968321b7d9250bdce2a49748", "price_changes": [{"asset_id": "92269994048518357863385104036810846326684031835851654275504679077189526944972", "price": "0.64", "size": "105", "side": "BUY", "hash": "928ac0612aac4d5693be03569c9cb23142969225", "best_bid": "0.929", "best_ask": "0.985"}, {"asset_id": "19197134752918366634342328847356807761591702594573815533235857894615009285668", "price": "0.36", "size": "105", "side": "SELL", "hash": "3dd4a9e367ab9a532484019fd21898652726816e", "best_bid": "0.015", "best_ask": "0.071"}], "timestamp": "1769384815992", "event_type": "price_change"}}
{"_local_timestamp": "2026-01-25T23:46:57.849240+00:00", "data": {"market": "0xfacaaf8ca81b788f8da594acaf23af2ef90037d82580b91357be35f97229e3a5", "price_changes": [{"asset_id": "49741609004781342711179849070128334110798460232218737742146637694522428416234", "price": "0.76", "size": "50", "side": "SELL", "hash": "1cd34341ce0d8a9773cdb11707557b2b832f3198", "best_bid": "0.71", "best_ask": "0.74"}, {"asset_id": "94754153121378446077535791604860675458774881690932146680120328837949383988913", "price": "0.24", "size": "50", "side": "BUY", "hash": "29cfbd544e3522494484c196c0847c039b6cc5f4", "best_bid": "0.26", "best_ask": "0.29"}], "timestamp": "1769384817770", "event_type": "price_change"}}
{"_local_timestamp": "2026-01-25T23:46:57.863347+00:00", "data": {"market": "0xfacaaf8ca81b788f8da594acaf23af2ef90037d82580b91357be35f97229e3a5", "price_changes": [{"asset_id": "49741609004781342711179849070128334110798460232218737742146637694522428416234", "price": "0.76", "size": "100", "side": "SELL", "hash": "619470ca4a529932ca5101c414ef2f3ef06ba114", "best_bid": "0.71", "best_ask": "0.74"}, {"asset_id": "94754153121378446077535791604860675458774881690932146680120328837949383988913", "price": "0.24", "size": "100", "side": "BUY", "hash": "b6e3b83dad7dc5eb6aa78e1cfc9fa12f5b4e8d73", "best_bid": "0.26", "best_ask": "0.29"}], "timestamp": "1769384817794", "event_type": "price_change"}}
{"_local_timestamp": "2026-01-25T23:46:57.950806+00:00", "data": {"market": "0x16478811d537afdfadaacef3bf1fc8b61ed86385968321b7d9250bdce2a49748", "price_changes": [{"asset_id": "92269994048518357863385104036810846326684031835851654275504679077189526944972", "price": "0.775", "size": "15", "side": "BUY", "hash": "2fdd97bad8926958409baf12ff235a8a11e559e4", "best_bid": "0.929", "best_ask": "0.985"}, {"asset_id": "19197134752918366634342328847356807761591702594573815533235857894615009285668", "price": "0.225", "size": "15", "side": "SELL", "hash": "92198e1450be23d8af2fda1a8ac9245a73382bf4", "best_bid": "0.015", "best_ask": "0.071"}], "timestamp": "1769384817875", "event_type": "price_change"}}
{"_local_timestamp": "2026-01-25T23:46:58.975226+00:00", "data": {"market": "0xe7d699841d03f695da20c8935f4cdf809057f3b27fa4f382e327ff731b8d75a7", "price_changes": [{"asset_id": "86720801120812523206375862885554727968671842048571953285734439150624995757719", "price": "0.25", "size": "0", "side": "BUY", "hash": "1245918ad1d7449ef78e953e8574f5f5504f19bd", "best_bid": "0.95", "best_ask": "0.97"}, {"asset_id": "40666723045616055650551965571535047681860486685123797401746526747593369094525", "price": "0.75", "size": "0", "side": "SELL", "hash": "4919f6c41ada667ee79d34a64d1dd175401e0adc", "best_bid": "0.03", "best_ask": "0.05"}], "timestamp": "1769384818866", "event_type": "price_change"}}
{"_local_timestamp": "2026-01-25T23:46:59.321466+00:00", "data": {"market": "0xe7d699841d03f695da20c8935f4cdf809057f3b27fa4f382e327ff731b8d75a7", "price_changes": [{"asset_id": "86720801120812523206375862885554727968671842048571953285734439150624995757719", "price": "0.21", "size": "915.13", "side": "BUY", "hash": "cc57239146e898c9f21f6e1d9bb4c241d426d061", "best_bid": "0.95", "best_ask": "0.97"}, {"asset_id": "40666723045616055650551965571535047681860486685123797401746526747593369094525", "price": "0.79", "size": "915.13", "side": "SELL", "hash": "32cf0055f4e58dc5fe03652e2fa36cb19212615c", "best_bid": "0.03", "best_ask": "0.05"}], "timestamp": "1769384819186", "event_type": "price_change"}}
{"_local_timestamp": "2026-01-25T23:47:23.506118+00:00", "data": {"market": "0xfacaaf8ca81b788f8da594acaf23af2ef90037d82580b91357be35f97229e3a5", "price_changes": [{"asset_id": "49741609004781342711179849070128334110798460232218737742146637694522428416234", "price": "0.35", "size": "80", "side": "BUY", "hash": "0ebce219d1bb2de88ac72ce8749273f340c13251", "best_bid": "0.71", "best_ask": "0.74"}, {"asset_id": "94754153121378446077535791604860675458774881690932146680120328837949383988913", "price": "0.65", "size": "80", "side": "SELL", "hash": "7943600994329f84ec21dc017147c98f7d65963c", "best_bid": "0.26", "best_ask": "0.29"}], "timestamp": "1769384843392", "event_type": "price_change"}}
{"_local_timestamp": "2026-01-25T23:47:23.507719+00:00", "data": {"market": "0xe7d699841d03f695da20c8935f4cdf809057f3b27fa4f382e327ff731b8d75a7", "price_changes": [{"asset_id": "86720801120812523206375862885554727968671842048571953285734439150624995757719", "price": "0.21", "size": "865.13", "side": "BUY", "hash": "4af42144d05d295195c4e8bd2dea93206c2b32a5", "best_bid": "0.95", "best_ask": "0.97"}, {"asset_id": "40666723045616055650551965571535047681860486685123797401746526747593369094525", "price": "0.79", "size": "865.13", "side": "SELL", "hash": "97631ce02130ada81251f8d7b70b6586ece8f2eb", "best_bid": "0.03", "best_ask": "0.05"}], "timestamp": "1769384843392", "event_type": "price_change"}}
{"_local_timestamp": "2026-01-25T23:47:23.685757+00:00", "data": {"market": "0x2649d46f6793c9847cc30659f7bcbec94578a23eda4c8cb86f31473173561986", "price_changes": [{"asset_id": "37921534922010226146703074549600791269918801302227759309433381423805138270558", "price": "0.699", "size": "15", "side": "BUY", "hash": "d64cbddb333d7f51263ac0b99495c1aac5ea9157", "best_bid": "0.939", "best_ask": "0.985"}, {"asset_id": "36826320465768064966532909273686181587790905146292730121626683737598046568291", "price": "0.301", "size": "15", "side": "SELL", "hash": "38779c19485e066e5d3c4442455155a20100d45b", "best_bid": "0.015", "best_ask": "0.061"}], "timestamp": "1769384843569", "event_type": "price_change"}}
{"_local_timestamp": "2026-01-25T23:47:23.687108+00:00", "data": {"market": "0x2649d46f6793c9847cc30659f7bcbec94578a23eda4c8cb86f31473173561986", "price_changes": [{"asset_id": "37921534922010226146703074549600791269918801302227759309433381423805138270558", "price": "0.697", "size": "0", "side": "BUY", "hash": "d00625d47d4f7e9519733b97d334a86192f776ee", "best_bid": "0.939", "best_ask": "0.985"}, {"asset_id": "36826320465768064966532909273686181587790905146292730121626683737598046568291", "price": "0.303", "size": "0", "side": "SELL", "hash": "63cce775c07d38585de73b4f8b8d82bcd672af0e", "best_bid": "0.015", "best_ask": "0.061"}], "timestamp": "1769384843575", "event_type": "price_change"}}
{"_local_timestamp": "2026-01-25T23:47:23.723429+00:00", "data": {"market": "0x2649d46f6793c9847cc30659f7bcbec94578a23eda4c8cb86f31473173561986", "price_changes": [{"asset_id": "37921534922010226146703074549600791269918801302227759309433381423805138270558", "price": "0.701", "size": "94", "side": "BUY", "hash": "17e29624447de8fc3a90ede71068e99f0f9208e1", "best_bid": "0.939", "best_ask": "0.985"}, {"asset_id": "36826320465768064966532909273686181587790905146292730121626683737598046568291", "price": "0.299", "size": "94", "side": "SELL", "hash": "ca4a04bc86377ed781228256a7dd7587169b0cef", "best_bid": "0.015", "best_ask": "0.061"}], "timestamp": "1769384843654", "event_type": "price_change"}}
{"_local_timestamp": "2026-01-25T23:47:23.732921+00:00", "data": {"market": "0x2649d46f6793c9847cc30659f7bcbec94578a23eda4c8cb86f31473173561986", "price_changes": [{"asset_id": "37921534922010226146703074549600791269918801302227759309433381423805138270558", "price": "0.701", "size": "104", "side": "BUY", "hash": "e8fb1ddeb16de390f4bd1aecee053b4c8e3be0d0", "best_bid": "0.939", "best_ask": "0.985"}, {"asset_id": "36826320465768064966532909273686181587790905146292730121626683737598046568291", "price": "0.299", "size": "104", "side": "SELL", "hash": "b966edc31c03435b26db16884ccd9e554ffe8476", "best_bid": "0.015", "best_ask": "0.061"}], "timestamp": "1769384843655", "event_type": "price_change"}}
{"_local_timestamp": "2026-01-25T23:47:23.925845+00:00", "data": {"market": "0xe7d699841d03f695da20c8935f4cdf809057f3b27fa4f382e327ff731b8d75a7", "price_changes": [{"asset_id": "86720801120812523206375862885554727968671842048571953285734439150624995757719", "price": "0.25", "size": "50", "side": "BUY", "hash": "9bc51a6d8ed52f0c23f293a2c514e90d130e1205", "best_bid": "0.95", "best_ask": "0.97"}, {"asset_id": "40666723045616055650551965571535047681860486685123797401746526747593369094525", "price": "0.75", "size": "50", "side": "SELL", "hash": "5314f6d4dbea8c0c1e17a167e4a72689705ec49b", "best_bid": "0.03", "best_ask": "0.05"}], "timestamp": "1769384843822", "event_type": "price_change"}}
{"_local_timestamp": "2026-01-25T23:47:23.930706+00:00", "data": {"market": "0xfacaaf8ca81b788f8da594acaf23af2ef90037d82580b91357be35f97229e3a5", "price_changes": [{"asset_id": "49741609004781342711179849070128334110798460232218737742146637694522428416234", "price": "0.34", "size": "50", "side": "BUY", "hash": "311d5ea90533757d2958b8c41b84ed58efdf81eb", "best_bid": "0.71", "best_ask": "0.74"}, {"asset_id": "94754153121378446077535791604860675458774881690932146680120328837949383988913", "price": "0.66", "size": "50", "side": "SELL", "hash": "04784fcecfee8d13586e9ea99836743d48d95916", "best_bid": "0.26", "best_ask": "0.29"}], "timestamp": "1769384843822", "event_type": "price_change"}}
{"_local_timestamp": "2026-01-25T23:47:30.716632+00:00", "data": {"market": "0x2649d46f6793c9847cc30659f7bcbec94578a23eda4c8cb86f31473173561986", "price_changes": [{"asset_id": "37921534922010226146703074549600791269918801302227759309433381423805138270558", "price": "0.7", "size": "0", "side": "BUY", "hash": "83c13e955caa30a0b29996ba01d79eae0caae285", "best_bid": "0.939", "best_ask": "0.985"}, {"asset_id": "36826320465768064966532909273686181587790905146292730121626683737598046568291", "price": "0.3", "size": "0", "side": "SELL", "hash": "59964590230db9dc1d00d0f158228d620ca77788", "best_bid": "0.015", "best_ask": "0.061"}], "timestamp": "1769384850635", "event_type": "price_change"}}
{"_local_timestamp": "2026-01-25T23:47:30.735907+00:00", "data": {"market": "0x2649d46f6793c9847cc30659f7bcbec94578a23eda4c8cb86f31473173561986", "price_changes": [{"asset_id": "37921534922010226146703074549600791269918801302227759309433381423805138270558", "price": "0.702", "size": "20", "side": "BUY", "hash": "f6d4c47e6683ef6cc1dc1390fce6deb98b4c1919", "best_bid": "0.939", "best_ask": "0.985"}, {"asset_id": "36826320465768064966532909273686181587790905146292730121626683737598046568291", "price": "0.298", "size": "20", "side": "SELL", "hash": "ba77f978ff1328a08e7a7ede849787ffdf3ea233", "best_bid": "0.015", "best_ask": "0.061"}], "timestamp": "1769384850670", "event_type": "price_change"}}
{"_local_timestamp": "2026-01-25T23:47:37.366813+00:00", "data": {"market": "0xad1f282f187c4748fe6eb51153a39557c66856cd14408bc3d509d3b23c047d41", "price_changes": [{"asset_id": "86814839478893548397184492422021698202794732526767012779986423826365559163504", "price": "0.24", "size": "0", "side": "BUY", "hash": "7810548de997cad8355844dc2bdc4eb463aa1e1e", "best_bid": "0.54", "best_ask": "0.65"}, {"asset_id": "26089319074590795210476289468934414386490143191167179409102092139417103170837", "price": "0.76", "size": "0", "side": "SELL", "hash": "a89f12371b30d7d324524579adf5192b270a02ce", "best_bid": "0.35", "best_ask": "0.46"}], "timestamp": "1769384857291", "event_type": "price_change"}}
{"_local_timestamp": "2026-01-25T23:47:37.374801+00:00", "data": {"market": "0xe7d699841d03f695da20c8935f4cdf809057f3b27fa4f382e327ff731b8d75a7", "price_changes": [{"asset_id": "86720801120812523206375862885554727968671842048571953285734439150624995757719", "price": "0.29", "size": "139.65", "side": "BUY", "hash": "578a48265ba42a0bce020dbd4fe470078cb486d0", "best_bid": "0.95", "best_ask": "0.97"}, {"asset_id": "40666723045616055650551965571535047681860486685123797401746526747593369094525", "price": "0.71", "size": "139.65", "side": "SELL", "hash": "01e3742887849182d9d6984598d276ef9260c79c", "best_bid": "0.03", "best_ask": "0.05"}], "timestamp": "1769384857292", "event_type": "price_change"}}
{"_local_timestamp": "2026-01-25T23:47:37.483478+00:00", "data": {"market": "0x16478811d537afdfadaacef3bf1fc8b61ed86385968321b7d9250bdce2a49748", "price_changes": [{"asset_id": "92269994048518357863385104036810846326684031835851654275504679077189526944972", "price": "0.775", "size": "0", "side": "BUY", "hash": "876941aedd2445d9a01a83b5da0e021163b02d2f", "best_bid": "0.929", "best_ask": "0.985"}, {"asset_id": "19197134752918366634342328847356807761591702594573815533235857894615009285668", "price": "0.225", "size": "0", "side": "SELL", "hash": "214a61de7e13f798c26aabfa43299a6f7b24163b", "best_bid": "0.015", "best_ask": "0.071"}], "timestamp": "1769384857357", "event_type": "price_change"}}
{"_local_timestamp": "2026-01-25T23:47:37.484980+00:00", "data": {"market": "0x2649d46f6793c9847cc30659f7bcbec94578a23eda4c8cb86f31473173561986", "price_changes": [{"asset_id": "37921534922010226146703074549600791269918801302227759309433381423805138270558", "price": "0.4", "size": "50", "side": "BUY", "hash": "3ab31d4dc5d54782bc53e07d12281fd08d90aa5a", "best_bid": "0.939", "best_ask": "0.985"}, {"asset_id": "36826320465768064966532909273686181587790905146292730121626683737598046568291", "price": "0.6", "size": "50", "side": "SELL", "hash": "8d23a12aa8d36a809fe1ce48a61230ecb176c829", "best_bid": "0.015", "best_ask": "0.061"}], "timestamp": "1769384857358", "event_type": "price_change"}}
{"_local_timestamp": "2026-01-25T23:47:37.710115+00:00", "data": {"market": "0xe7d699841d03f695da20c8935f4cdf809057f3b27fa4f382e327ff731b8d75a7", "price_changes": [{"asset_id": "86720801120812523206375862885554727968671842048571953285734439150624995757719", "price": "0.24", "size": "216.66", "side": "BUY", "hash": "334df102390e728b2897fdbecdfd591dfb283ffc", "best_bid": "0.95", "best_ask": "0.97"}, {"asset_id": "40666723045616055650551965571535047681860486685123797401746526747593369094525", "price": "0.76", "size": "216.66", "side": "SELL", "hash": "8d504d8f19b2c407ecc8c108619411b26a8e7e99", "best_bid": "0.03", "best_ask": "0.05"}], "timestamp": "1769384857536", "event_type": "price_change"}}
{"_local_timestamp": "2026-01-25T23:47:37.834891+00:00", "data": {"market": "0x16478811d537afdfadaacef3bf1fc8b61ed86385968321b7d9250bdce2a49748", "price_changes": [{"asset_id": "92269994048518357863385104036810846326684031835851654275504679077189526944972", "price": "0.777", "size": "10", "side": "BUY", "hash": "ee1ed48b028085bcfb25e652b133929fefe145a0", "best_bid": "0.929", "best_ask": "0.985"}, {"asset_id": "19197134752918366634342328847356807761591702594573815533235857894615009285668", "price": "0.223", "size": "10", "side": "SELL", "hash": "4d6f87b5dc18f6486511d5bd73bcd838f7836a4d", "best_bid": "0.015", "best_ask": "0.071"}], "timestamp": "1769384857598", "event_type": "price_change"}}
{"_local_timestamp": "2026-01-25T23:47:37.838827+00:00", "data": {"market": "0x16478811d537afdfadaacef3bf1fc8b61ed86385968321b7d9250bdce2a49748", "price_changes": [{"asset_id": "92269994048518357863385104036810846326684031835851654275504679077189526944972", "price": "0.777", "size": "25", "side": "BUY", "hash": "122e5a4227a48cdf6277e2c1974f59756c52bf15", "best_bid": "0.929", "best_ask": "0.985"}, {"asset_id": "19197134752918366634342328847356807761591702594573815533235857894615009285668", "price": "0.223", "size": "25", "side": "SELL", "hash": "e9ae6de9b8c3b0a2f87de04f9ad78957f22d6517", "best_bid": "0.015", "best_ask": "0.071"}], "timestamp": "1769384857602", "event_type": "price_change"}}
{"_local_timestamp": "2026-01-25T23:47:37.850065+00:00", "data": {"market": "0xad1f282f187c4748fe6eb51153a39557c66856cd14408bc3d509d3b23c047d41", "price_changes": [{"asset_id": "86814839478893548397184492422021698202794732526767012779986423826365559163504", "price": "0.22", "size": "300", "side": "BUY", "hash": "c77b2a17513d441c99d57a5a6c3130f9388958ac", "best_bid": "0.54", "best_ask": "0.65"}, {"asset_id": "26089319074590795210476289468934414386490143191167179409102092139417103170837", "price": "0.78", "size": "300", "side": "SELL", "hash": "37c6b4cfd9e9fdfab9c2f02a4b7b04eea63993ac", "best_bid": "0.35", "best_ask": "0.46"}], "timestamp": "1769384857612", "event_type": "price_change"}}
{"_local_timestamp": "2026-01-25T23:47:37.964333+00:00", "data": {"market": "0xe7d699841d03f695da20c8935f4cdf809057f3b27fa4f382e327ff731b8d75a7", "price_changes": [{"asset_id": "86720801120812523206375862885554727968671842048571953285734439150624995757719", "price": "0.3", "size": "1450", "side": "BUY", "hash": "7123b43f047342aa5b779f840b744d722f01df42", "best_bid": "0.95", "best_ask": "0.97"}, {"asset_id": "40666723045616055650551965571535047681860486685123797401746526747593369094525", "price": "0.7", "size": "1450", "side": "SELL", "hash": "b0b6bb6f41ea5a63cabd72ce071717cb79193130", "best_bid": "0.03", "best_ask": "0.05"}], "timestamp": "1769384857613", "event_type": "price_change"}}
{"_local_timestamp": "2026-01-25T23:47:38.343556+00:00", "data": {"market": "0xe7d699841d03f695da20c8935f4cdf809057f3b27fa4f382e327ff731b8d75a7", "price_changes": [{"asset_id": "86720801120812523206375862885554727968671842048571953285734439150624995757719", "price": "0.25", "size": "100", "side": "BUY", "hash": "27c6397a88d0ba901425cf137397b3d010a4ba7d", "best_bid": "0.95", "best_ask": "0.97"}, {"asset_id": "40666723045616055650551965571535047681860486685123797401746526747593369094525", "price": "0.75", "size": "100", "side": "SELL", "hash": "0d91677f706173584c34594deb9843d55cb043c5", "best_bid": "0.03", "best_ask": "0.05"}], "timestamp": "1769384858065", "event_type": "price_change"}}
{"_local_timestamp": "2026-01-25T23:47:39.393365+00:00", "data": {"market": "0x16478811d537afdfadaacef3bf1fc8b61ed86385968321b7d9250bdce2a49748", "price_changes": [{"asset_id": "92269994048518357863385104036810846326684031835851654275504679077189526944972", "price": "0.64", "size": "100", "side": "BUY", "hash": "7f5c8d5b1b11b75dd9f55deff5476db87779e53d", "best_bid": "0.929", "best_ask": "0.985"}, {"asset_id": "19197134752918366634342328847356807761591702594573815533235857894615009285668", "price": "0.36", "size": "100", "side": "SELL", "hash": "0a84bd9254173f3b79bc3d9d0f59e49c02c97382", "best_bid": "0.015", "best_ask": "0.071"}], "timestamp": "1769384859315", "event_type": "price_change"}}
{"_local_timestamp": "2026-01-25T23:47:39.510581+00:00", "data": {"market": "0x2649d46f6793c9847cc30659f7bcbec94578a23eda4c8cb86f31473173561986", "price_changes": [{"asset_id": "37921534922010226146703074549600791269918801302227759309433381423805138270558", "price": "0.699", "size": "0", "side": "BUY", "hash": "f69fe12e9d76c1986d6fd6b4fc82aa8e32969e4d", "best_bid": "0.939", "best_ask": "0.985"}, {"asset_id": "36826320465768064966532909273686181587790905146292730121626683737598046568291", "price": "0.301", "size": "0", "side": "SELL", "hash": "0097f26c3cf7585591a9189b394e701906d05295", "best_bid": "0.015", "best_ask": "0.061"}], "timestamp": "1769384859437", "event_type": "price_change"}}
{"_local_timestamp": "2026-01-25T23:47:39.629740+00:00", "data": {"market": "0x2649d46f6793c9847cc30659f7bcbec94578a23eda4c8cb86f31473173561986", "price_changes": [{"asset_id": "37921534922010226146703074549600791269918801302227759309433381423805138270558", "price": "0.703", "size": "15", "side": "BUY", "hash": "1fef07e73467b8d46f56451a206f560701580d62", "best_bid": "0.939", "best_ask": "0.985"}, {"asset_id": "36826320465768064966532909273686181587790905146292730121626683737598046568291", "price": "0.297", "size": "15", "side": "SELL", "hash": "7a1e1cdbd23106f0466be5245634323bf0c60d57", "best_bid": "0.015", "best_ask": "0.061"}], "timestamp": "1769384859550", "event_type": "price_change"}}
{"_local_timestamp": "2026-01-25T23:47:39.631361+00:00", "data": {"market": "0x2649d46f6793c9847cc30659f7bcbec94578a23eda4c8cb86f31473173561986", "price_changes": [{"asset_id": "37921534922010226146703074549600791269918801302227759309433381423805138270558", "price": "0.703", "size": "25", "side": "BUY", "hash": "d0c7924fccf62ae942d69b99e1347f9288eced10", "best_bid": "0.939", "best_ask": "0.985"}, {"asset_id": "36826320465768064966532909273686181587790905146292730121626683737598046568291", "price": "0.297", "size": "25", "side": "SELL", "hash": "bcff4c0c8d346f77ac1f9c773c9f12ec8965a6ed", "best_bid": "0.015", "best_ask": "0.061"}], "timestamp": "1769384859551", "event_type": "price_change"}}
{"_local_timestamp": "2026-01-25T23:47:39.823183+00:00", "data": {"market": "0x16478811d537afdfadaacef3bf1fc8b61ed86385968321b7d9250bdce2a49748", "price_changes": [{"asset_id": "92269994048518357863385104036810846326684031835851654275504679077189526944972", "price": "0.64", "size": "105", "side": "BUY", "hash": "a887fc2e46ade96075cc349bc8220aef227d50c1", "best_bid": "0.929", "best_ask": "0.985"}, {"asset_id": "19197134752918366634342328847356807761591702594573815533235857894615009285668", "price": "0.36", "size": "105", "side": "SELL", "hash": "acde4b71b2687158e8afa3be7601202c65d005a5", "best_bid": "0.015", "best_ask": "0.071"}], "timestamp": "1769384859747", "event_type": "price_change"}}
{"_local_timestamp": "2026-01-25T23:47:40.155499+00:00", "data": {"market": "0x2649d46f6793c9847cc30659f7bcbec94578a23eda4c8cb86f31473173561986", "price_changes": [{"asset_id": "37921534922010226146703074549600791269918801302227759309433381423805138270558", "price": "0.702", "size": "0", "side": "BUY", "hash": "6b0470885379a964ca3b22b35c37986eaf90686f", "best_bid": "0.939", "best_ask": "0.985"}, {"asset_id": "36826320465768064966532909273686181587790905146292730121626683737598046568291", "price": "0.298", "size": "0", "side": "SELL", "hash": "d504bf758da9c1f5d2ea37e26bcf8f2c7226d8aa", "best_bid": "0.015", "best_ask": "0.061"}], "timestamp": "1769384860045", "event_type": "price_change"}}
{"_local_timestamp": "2026-01-25T23:47:40.156908+00:00", "data": {"market": "0x16478811d537afdfadaacef3bf1fc8b61ed86385968321b7d9250bdce2a49748", "price_changes": [{"asset_id": "92269994048518357863385104036810846326684031835851654275504679077189526944972", "price": "0.776", "size": "0", "side": "BUY", "hash": "1ad0af5741839306bfb356fd4a7ac2086aba645c", "best_bid": "0.929", "best_ask": "0.985"}, {"asset_id": "19197134752918366634342328847356807761591702594573815533235857894615009285668", "price": "0.224", "size": "0", "side": "SELL", "hash": "c1618865b45cf93f9aa6cf755f4bba17841cec92", "best_bid": "0.015", "best_ask": "0.071"}], "timestamp": "1769384860045", "event_type": "price_change"}}
{"_local_timestamp": "2026-01-25T23:47:40.174668+00:00", "data": {"market": "0x2649d46f6793c9847cc30659f7bcbec94578a23eda4c8cb86f31473173561986", "price_changes": [{"asset_id": "37921534922010226146703074549600791269918801302227759309433381423805138270558", "price": "0.704", "size": "20", "side": "BUY", "hash": "3aa81bd5bc1f8e77ba3c675dd33fb37b202b02f3", "best_bid": "0.939", "best_ask": "0.985"}, {"asset_id": "36826320465768064966532909273686181587790905146292730121626683737598046568291", "price": "0.296", "size": "20", "side": "SELL", "hash": "8d75d1cd2dba70cd499b2ae6844ca8fd59e8212c", "best_bid": "0.015", "best_ask": "0.061"}], "timestamp": "1769384860074", "event_type": "price_change"}}
{"_local_timestamp": "2026-01-25T23:47:40.175930+00:00", "data": {"market": "0x16478811d537afdfadaacef3bf1fc8b61ed86385968321b7d9250bdce2a49748", "price_changes": [{"asset_id": "92269994048518357863385104036810846326684031835851654275504679077189526944972", "price": "0.778", "size": "20", "side": "BUY", "hash": "c4b5e5a2d32807feb84b2bd702cfc513f9e01526", "best_bid": "0.929", "best_ask": "0.985"}, {"asset_id": "19197134752918366634342328847356807761591702594573815533235857894615009285668", "price": "0.222", "size": "20", "side": "SELL", "hash": "94c6fd4b0b66cdd6173099d44694fdde047b96a8", "best_bid": "0.015", "best_ask": "0.071"}], "timestamp": "1769384860075", "event_type": "price_change"}}
{"_local_timestamp": "2026-01-25T23:48:00.356670+00:00", "data": {"market": "0x23e782e8db3eb990b48ff37432f9f0899e73ea737e68d2934bd09b34934dc0d0", "price_changes": [{"asset_id": "35728543926876832227758010997325479102150155332621985448512538195119929531554", "price": "0.003", "size": "39.31", "side": "BUY", "hash": "3d8759f136d933220e4c366562e56d7c75f3b678", "best_bid": "0.02", "best_ask": "0.13"}, {"asset_id": "42382535584090931070184963017291726037912989687255284323203344679942164276749", "price": "0.997", "size": "39.31", "side": "SELL", "hash": "bc34ae3de972a09f5848edaafff6b7c2d68c8d1d", "best_bid": "0.87", "best_ask": "0.98"}], "timestamp": "1769384880292", "event_type": "price_change"}}
{"_local_timestamp": "2026-01-25T23:48:00.671080+00:00", "data": {"market": "0x23e782e8db3eb990b48ff37432f9f0899e73ea737e68d2934bd09b34934dc0d0", "price_changes": [{"asset_id": "35728543926876832227758010997325479102150155332621985448512538195119929531554", "price": "0.003", "size": "60.79", "side": "BUY", "hash": "3d0c7556795427e1c8068424dc7e1598bf2ee5f6", "best_bid": "0.02", "best_ask": "0.13"}, {"asset_id": "42382535584090931070184963017291726037912989687255284323203344679942164276749", "price": "0.997", "size": "60.79", "side": "SELL", "hash": "56f570b811c5518d031c75c8abaaf779e3189b6c", "best_bid": "0.87", "best_ask": "0.98"}], "timestamp": "1769384880603", "event_type": "price_change"}}
{"_local_timestamp": "2026-01-25T23:48:01.706026+00:00", "data": {"market": "0xeafc8d47725546039800fe78eb06c0af5d9f982134515b9250ea376b7c258afb", "price_changes": [{"asset_id": "39436446463164291051085103274433078121544260678753625430845203266295844561591", "price": "0.002", "size": "250", "side": "BUY", "hash": "25fbc73debc8850b24f1555c8475e105467da383", "best_bid": "0.012", "best_ask": "0.014"}, {"asset_id": "102282495724728145503590068938456419856338447487625172072096551524174375085545", "price": "0.998", "size": "250", "side": "SELL", "hash": "6fbd51012fe28dba38b1b85526f7986db2fed40c", "best_bid": "0.986", "best_ask": "0.988"}], "timestamp": "1769384881641", "event_type": "price_change"}}
{"_local_timestamp": "2026-01-25T23:48:01.707400+00:00", "data": {"market": "0xeafc8d47725546039800fe78eb06c0af5d9f982134515b9250ea376b7c258afb", "price_changes": [{"asset_id": "39436446463164291051085103274433078121544260678753625430845203266295844561591", "price": "0.003", "size": "40.43", "side": "BUY", "hash": "25fbc73debc8850b24f1555c8475e105467da383", "best_bid": "0.012", "best_ask": "0.014"}, {"asset_id": "102282495724728145503590068938456419856338447487625172072096551524174375085545", "price": "0.997", "size": "40.43", "side": "SELL", "hash": "6fbd51012fe28dba38b1b85526f7986db2fed40c", "best_bid": "0.986", "best_ask": "0.988"}], "timestamp": "1769384881641", "event_type": "price_change"}}
{"_local_timestamp": "2026-01-25T23:48:02.333336+00:00", "data": {"market": "0xeafc8d47725546039800fe78eb06c0af5d9f982134515b9250ea376b7c258afb", "price_changes": [{"asset_id": "39436446463164291051085103274433078121544260678753625430845203266295844561591", "price": "0.002", "size": "294.24", "side": "BUY", "hash": "14d92d4b6649c9e643c4deb0cf4779d419f65958", "best_bid": "0.012", "best_ask": "0.014"}, {"asset_id": "102282495724728145503590068938456419856338447487625172072096551524174375085545", "price": "0.998", "size": "294.24", "side": "SELL", "hash": "beb6850476026a00a224814a2d247d7f15e982aa", "best_bid": "0.986", "best_ask": "0.988"}], "timestamp": "1769384882252", "event_type": "price_change"}}
{"_local_timestamp": "2026-01-25T23:48:02.334716+00:00", "data": {"market": "0xeafc8d47725546039800fe78eb06c0af5d9f982134515b9250ea376b7c258afb", "price_changes": [{"asset_id": "39436446463164291051085103274433078121544260678753625430845203266295844561591", "price": "0.003", "size": "65.74", "side": "BUY", "hash": "328a39c4b68647e989fb30e5e32f79d16cc01a70", "best_bid": "0.012", "best_ask": "0.014"}, {"asset_id": "102282495724728145503590068938456419856338447487625172072096551524174375085545", "price": "0.997", "size": "65.74", "side": "SELL", "hash": "5668edce49a3debe528142958adb1a6df692743b", "best_bid": "0.986", "best_ask": "0.988"}], "timestamp": "1769384882253", "event_type": "price_change"}}
{"_local_timestamp": "2026-01-25T23:48:17.578069+00:00", "data": {"market": "0x16478811d537afdfadaacef3bf1fc8b61ed86385968321b7d9250bdce2a49748", "price_changes": [{"asset_id": "92269994048518357863385104036810846326684031835851654275504679077189526944972", "price": "0.64", "size": "100", "side": "BUY", "hash": "d5575c69c7f08aec168ad557b80afa4e45c136a6", "best_bid": "0.929", "best_ask": "0.985"}, {"asset_id": "19197134752918366634342328847356807761591702594573815533235857894615009285668", "price": "0.36", "size": "100", "side": "SELL", "hash": "edaf4dc23946d7c5834825d63941462b9939b589", "best_bid": "0.015", "best_ask": "0.071"}], "timestamp": "1769384897511", "event_type": "price_change"}}
{"_local_timestamp": "2026-01-25T23:48:18.024324+00:00", "data": {"market": "0x16478811d537afdfadaacef3bf1fc8b61ed86385968321b7d9250bdce2a49748", "price_changes": [{"asset_id": "92269994048518357863385104036810846326684031835851654275504679077189526944972", "price": "0.64", "size": "105", "side": "BUY", "hash": "bfd74c05aca6bad5ae714ee5f7e161268dc0bb0a", "best_bid": "0.929", "best_ask": "0.985"}, {"asset_id": "19197134752918366634342328847356807761591702594573815533235857894615009285668", "price": "0.36", "size": "105", "side": "SELL", "hash": "9fa8a723d282bb4c06ef0f182838c27eb8a507a8", "best_bid": "0.015", "best_ask": "0.071"}], "timestamp": "1769384897941", "event_type": "price_change"}}
{"_local_timestamp": "2026-01-25T23:48:29.512597+00:00", "data": {"market": "0xfacaaf8ca81b788f8da594acaf23af2ef90037d82580b91357be35f97229e3a5", "price_changes": [{"asset_id": "49741609004781342711179849070128334110798460232218737742146637694522428416234", "price": "0.71", "size": "0", "side": "BUY", "hash": "a60339e8b0488c78d3471f29851f49ab54dcd4c5", "best_bid": "0.7", "best_ask": "0.74"}, {"asset_id": "94754153121378446077535791604860675458774881690932146680120328837949383988913", "price": "0.29", "size": "0", "side": "SELL", "hash": "e967b63b0357531d08cb4afb7057cd86046f1c3e", "best_bid": "0.26", "best_ask": "0.3"}], "timestamp": "1769384908794", "event_type": "price_change"}}
{"_local_timestamp": "2026-01-25T23:48:29.514133+00:00", "data": {"market": "0xfacaaf8ca81b788f8da594acaf23af2ef90037d82580b91357be35f97229e3a5", "price_changes": [{"asset_id": "49741609004781342711179849070128334110798460232218737742146637694522428416234", "price": "0.64", "size": "0", "side": "BUY", "hash": "a60339e8b0488c78d3471f29851f49ab54dcd4c5", "best_bid": "0.7", "best_ask": "0.74"}, {"asset_id": "94754153121378446077535791604860675458774881690932146680120328837949383988913", "price": "0.36", "size": "0", "side": "SELL", "hash": "e967b63b0357531d08cb4afb7057cd86046f1c3e", "best_bid": "0.26", "best_ask": "0.3"}], "timestamp": "1769384908794", "event_type": "price_change"}}
{"_local_timestamp": "2026-01-25T23:48:29.605791+00:00", "data": {"market": "0xfacaaf8ca81b788f8da594acaf23af2ef90037d82580b91357be35f97229e3a5", "price_changes": [{"asset_id": "49741609004781342711179849070128334110798460232218737742146637694522428416234", "price": "0.57", "size": "0", "side": "BUY", "hash": "a60339e8b0488c78d3471f29851f49ab54dcd4c5", "best_bid": "0.7", "best_ask": "0.74"}, {"asset_id": "94754153121378446077535791604860675458774881690932146680120328837949383988913", "price": "0.43", "size": "0", "side": "SELL", "hash": "e967b63b0357531d08cb4afb7057cd86046f1c3e", "best_bid": "0.26", "best_ask": "0.3"}], "timestamp": "1769384908794", "event_type": "price_change"}}
{"_local_timestamp": "2026-01-25T23:48:29.607693+00:00", "data": {"market": "0x23e782e8db3eb990b48ff37432f9f0899e73ea737e68d2934bd09b34934dc0d0", "price_changes": [{"asset_id": "42382535584090931070184963017291726037912989687255284323203344679942164276749", "price": "0.645", "size": "0", "side": "BUY", "hash": "9f6bc7db18777354440ca917f8b483246581454e", "best_bid": "0.87", "best_ask": "0.98"}, {"asset_id": "35728543926876832227758010997325479102150155332621985448512538195119929531554", "price": "0.355", "size": "0", "side": "SELL", "hash": "c1868fcc3b14dc59c63f97c1a7fb16be7b8b37b9", "best_bid": "0.02", "best_ask": "0.13"}], "timestamp": "1769384908982", "event_type": "price_change"}}
{"_local_timestamp": "2026-01-25T23:48:29.613530+00:00", "data": {"market": "0x23e782e8db3eb990b48ff37432f9f0899e73ea737e68d2934bd09b34934dc0d0", "price_changes": [{"asset_id": "42382535584090931070184963017291726037912989687255284323203344679942164276749", "price": "0.649", "size": "30", "side": "BUY", "hash": "c28a87cb5264a1056ca26a4d43584cc74aa054c9", "best_bid": "0.87", "best_ask": "0.98"}, {"asset_id": "35728543926876832227758010997325479102150155332621985448512538195119929531554", "price": "0.351", "size": "30", "side": "SELL", "hash": "36da1212beb0b458bd12890ca040101fe818e223", "best_bid": "0.02", "best_ask": "0.13"}], "timestamp": "1769384909060", "event_type": "price_change"}}
{"_local_timestamp": "2026-01-25T23:48:29.704345+00:00", "data": {"market": "0xfacaaf8ca81b788f8da594acaf23af2ef90037d82580b91357be35f97229e3a5", "price_changes": [{"asset_id": "49741609004781342711179849070128334110798460232218737742146637694522428416234", "price": "0.64", "size": "100", "side": "BUY", "hash": "b1d03ebb4781943ff199a514b6ea0d7b3de90605", "best_bid": "0.7", "best_ask": "0.74"}, {"asset_id": "94754153121378446077535791604860675458774881690932146680120328837949383988913", "price": "0.36", "size": "100", "side": "SELL", "hash": "5a39c6c095cc9b23c9b7bd1d85131d5af42c3a52", "best_bid": "0.26", "best_ask": "0.3"}], "timestamp": "1769384909465", "event_type": "price_change"}}
{"_local_timestamp": "2026-01-25T23:48:29.841710+00:00", "data": {"market": "0xfacaaf8ca81b788f8da594acaf23af2ef90037d82580b91357be35f97229e3a5", "price_changes": [{"asset_id": "49741609004781342711179849070128334110798460232218737742146637694522428416234", "price": "0.57", "size": "100", "side": "BUY", "hash": "0bcb18a1bcb9f9db422183045b655b543534ff59", "best_bid": "0.7", "best_ask": "0.74"}, {"asset_id": "94754153121378446077535791604860675458774881690932146680120328837949383988913", "price": "0.43", "size": "100", "side": "SELL", "hash": "36a6364e5dbedbb4e687be67fc6a03c0bc09eb6a", "best_bid": "0.26", "best_ask": "0.3"}], "timestamp": "1769384909603", "event_type": "price_change"}}
{"_local_timestamp": "2026-01-25T23:48:29.879460+00:00", "data": {"market": "0xeafc8d47725546039800fe78eb06c0af5d9f982134515b9250ea376b7c258afb", "price_changes": [{"asset_id": "102282495724728145503590068938456419856338447487625172072096551524174375085545", "price": "0.771", "size": "0", "side": "BUY", "hash": "170bc36c78c765a0ea597b40960deeeaedd0cc62", "best_bid": "0.986", "best_ask": "0.988"}, {"asset_id": "39436446463164291051085103274433078121544260678753625430845203266295844561591", "price": "0.229", "size": "0", "side": "SELL", "hash": "07f15308ec489e6f49a969d45c585acba60e21da", "best_bid": "0.012", "best_ask": "0.014"}], "timestamp": "1769384909633", "event_type": "price_change"}}
{"_local_timestamp": "2026-01-25T23:48:30.007542+00:00", "data": {"market": "0xeafc8d47725546039800fe78eb06c0af5d9f982134515b9250ea376b7c258afb", "price_changes": [{"asset_id": "102282495724728145503590068938456419856338447487625172072096551524174375085545", "price": "0.771", "size": "10", "side": "BUY", "hash": "0e8e4aacfb80424251a115d262ff093530870bdd", "best_bid": "0.986", "best_ask": "0.988"}, {"asset_id": "39436446463164291051085103274433078121544260678753625430845203266295844561591", "price": "0.229", "size": "10", "side": "SELL", "hash": "9eb03bb9b6dfc9acf1819c04169135852ed58e00", "best_bid": "0.012", "best_ask": "0.014"}], "timestamp": "1769384909759", "event_type": "price_change"}}
{"_local_timestamp": "2026-01-25T23:48:30.817547+00:00", "data": {"market": "0x23e782e8db3eb990b48ff37432f9f0899e73ea737e68d2934bd09b34934dc0d0", "price_changes": [{"asset_id": "42382535584090931070184963017291726037912989687255284323203344679942164276749", "price": "0.85", "size": "54.33", "side": "BUY", "hash": "9d4284524925195a3a8707bc02cf29bcc5cd293c", "best_bid": "0.87", "best_ask": "0.98"}, {"asset_id": "35728543926876832227758010997325479102150155332621985448512538195119929531554", "price": "0.15", "size": "54.33", "side": "SELL", "hash": "02baa5d4643a1b4317c22896334855efe3059fe1", "best_bid": "0.02", "best_ask": "0.13"}], "timestamp": "1769384910564", "event_type": "price_change"}}
{"_local_timestamp": "2026-01-25T23:48:30.820484+00:00", "data": {"market": "0x23e782e8db3eb990b48ff37432f9f0899e73ea737e68d2934bd09b34934dc0d0", "price_changes": [{"asset_id": "42382535584090931070184963017291726037912989687255284323203344679942164276749", "price": "0.851", "size": "67", "side": "BUY", "hash": "e4c47b6c45b085aac3e6c3daa54a4da540b8dd7f", "best_bid": "0.87", "best_ask": "0.98"}, {"asset_id": "35728543926876832227758010997325479102150155332621985448512538195119929531554", "price": "0.149", "size": "67", "side": "SELL", "hash": "9f222ba41adc9b92dbf3f7674e47654fd4125d32", "best_bid": "0.02", "best_ask": "0.13"}], "timestamp": "1769384910564", "event_type": "price_change"}}
{"_local_timestamp": "2026-01-25T23:48:32.040219+00:00", "data": {"market": "0xfacaaf8ca81b788f8da594acaf23af2ef90037d82580b91357be35f97229e3a5", "price_changes": [{"asset_id": "49741609004781342711179849070128334110798460232218737742146637694522428416234", "price": "0.68", "size": "50", "side": "BUY", "hash": "d5d4ff2ac475bc12d8fce52813f047cdca87faab", "best_bid": "0.7", "best_ask": "0.74"}, {"asset_id": "94754153121378446077535791604860675458774881690932146680120328837949383988913", "price": "0.32", "size": "50", "side": "SELL", "hash": "a11f88ec5ef78a149d03fc1a3e678344c69326c7", "best_bid": "0.26", "best_ask": "0.3"}], "timestamp": "1769384911785", "event_type": "price_change"}}
{"_local_timestamp": "2026-01-25T23:48:36.560571+00:00", "data": {"market": "0x23e782e8db3eb990b48ff37432f9f0899e73ea737e68d2934bd09b34934dc0d0", "price_changes": [{"asset_id": "42382535584090931070184963017291726037912989687255284323203344679942164276749", "price": "0.648", "size": "0", "side": "BUY", "hash": "04f52d70a173e2ca8f0f74e870c7939b45cb3735", "best_bid": "0.87", "best_ask": "0.98"}, {"asset_id": "35728543926876832227758010997325479102150155332621985448512538195119929531554", "price": "0.352", "size": "0", "side": "SELL", "hash": "8395101c87b6006c28f34576d64b1b5842879b6e", "best_bid": "0.02", "best_ask": "0.13"}], "timestamp": "1769384916317", "event_type": "price_change"}}
{"_local_timestamp": "2026-01-25T23:48:36.588466+00:00", "data": {"market": "0x23e782e8db3eb990b48ff37432f9f0899e73ea737e68d2934bd09b34934dc0d0", "price_changes": [{"asset_id": "42382535584090931070184963017291726037912989687255284323203344679942164276749", "price": "0.65", "size": "20", "side": "BUY", "hash": "0de11c8c9d7697c4017cb273e1810a244b5a3166", "best_bid": "0.87", "best_ask": "0.98"}, {"asset_id": "35728543926876832227758010997325479102150155332621985448512538195119929531554", "price": "0.35", "size": "20", "side": "SELL", "hash": "aeb680cd8c156b02e9a884aaa2be10efba984b7a", "best_bid": "0.02", "best_ask": "0.13"}], "timestamp": "1769384916345", "event_type": "price_change"}}
{"_local_timestamp": "2026-01-25T23:48:42.942270+00:00", "data": {"market": "0x23e782e8db3eb990b48ff37432f9f0899e73ea737e68d2934bd09b34934dc0d0", "price_changes": [{"asset_id": "42382535584090931070184963017291726037912989687255284323203344679942164276749", "price": "0.85", "size": "21.33", "side": "BUY", "hash": "97ef702021a9fb5cce745ab0a9601027b612766c", "best_bid": "0.87", "best_ask": "0.98"}, {"asset_id": "35728543926876832227758010997325479102150155332621985448512538195119929531554", "price": "0.15", "size": "21.33", "side": "SELL", "hash": "b87fca4dcf5eefbf0a3eb3f5f543b32510fbf94f", "best_bid": "0.02", "best_ask": "0.13"}], "timestamp": "1769384922843", "event_type": "price_change"}}
{"_local_timestamp": "2026-01-25T23:48:57.032658+00:00", "data": {"market": "0x16478811d537afdfadaacef3bf1fc8b61ed86385968321b7d9250bdce2a49748", "price_changes": [{"asset_id": "92269994048518357863385104036810846326684031835851654275504679077189526944972", "price": "0.64", "size": "100", "side": "BUY", "hash": "ac1794ecf5d8ae42b92c99f90a9245f57a33b3a4", "best_bid": "0.929", "best_ask": "0.985"}, {"asset_id": "19197134752918366634342328847356807761591702594573815533235857894615009285668", "price": "0.36", "size": "100", "side": "SELL", "hash": "8084f8114b40a8a90724177741ccbfd5186b2245", "best_bid": "0.015", "best_ask": "0.071"}], "timestamp": "1769384936953", "event_type": "price_change"}}
{"_local_timestamp": "2026-01-25T23:48:57.583799+00:00", "data": {"market": "0x16478811d537afdfadaacef3bf1fc8b61ed86385968321b7d9250bdce2a49748", "price_changes": [{"asset_id": "92269994048518357863385104036810846326684031835851654275504679077189526944972", "price": "0.64", "size": "105", "side": "BUY", "hash": "c4fdda47f1e6f2291284a42ac5c826739f882557", "best_bid": "0.929", "best_ask": "0.985"}, {"asset_id": "19197134752918366634342328847356807761591702594573815533235857894615009285668", "price": "0.36", "size": "105", "side": "SELL", "hash": "d2e78f3046b2087ad404a3bbc6cf3a812b496bbe", "best_bid": "0.015", "best_ask": "0.071"}], "timestamp": "1769384937502", "event_type": "price_change"}}
{"_local_timestamp": "2026-01-25T23:49:02.101425+00:00", "data": {"market": "0xad1f282f187c4748fe6eb51153a39557c66856cd14408bc3d509d3b23c047d41", "price_changes": [{"asset_id": "26089319074590795210476289468934414386490143191167179409102092139417103170837", "price": "0.35", "size": "66.66", "side": "BUY", "hash": "ec34f9890a2a551f936a01b4a37d2c90b660cf00", "best_bid": "0.35", "best_ask": "0.46"}, {"asset_id": "86814839478893548397184492422021698202794732526767012779986423826365559163504", "price": "0.65", "size": "66.66", "side": "SELL", "hash": "ad99ab9ddaa72589ece8a01f9e23701de55b876e", "best_bid": "0.54", "best_ask": "0.65"}], "timestamp": "1769384942000", "event_type": "price_change"}}
{"_local_timestamp": "2026-01-25T23:49:02.180910+00:00", "data": {"market": "0xad1f282f187c4748fe6eb51153a39557c66856cd14408bc3d509d3b23c047d41", "price_changes": [{"asset_id": "26089319074590795210476289468934414386490143191167179409102092139417103170837", "price": "0.35", "size": "86.66", "side": "BUY", "hash": "fb1b8920375733b221a103ce0554610a19250973", "best_bid": "0.35", "best_ask": "0.46"}, {"asset_id": "86814839478893548397184492422021698202794732526767012779986423826365559163504", "price": "0.65", "size": "86.66", "side": "SELL", "hash": "ccc9779c879cc87499911043550bf03c9be5d531", "best_bid": "0.54", "best_ask": "0.65"}], "timestamp": "1769384942053", "event_type": "price_change"}}
{"_local_timestamp": "2026-01-25T23:49:17.073349+00:00", "data": {"market": "0xe7d699841d03f695da20c8935f4cdf809057f3b27fa4f382e327ff731b8d75a7", "price_changes": [{"asset_id": "40666723045616055650551965571535047681860486685123797401746526747593369094525", "price": "0.02", "size": "375", "side": "BUY", "hash": "f62916e4728c20d66d483f6edf7f6b4eacbd88e0", "best_bid": "0.03", "best_ask": "0.05"}, {"asset_id": "86720801120812523206375862885554727968671842048571953285734439150624995757719", "price": "0.98", "size": "375", "side": "SELL", "hash": "539884971febe5be0f9a5fa85d09b1d11ef56563", "best_bid": "0.95", "best_ask": "0.97"}], "timestamp": "1769384957000", "event_type": "price_change"}}
{"_local_timestamp": "2026-01-25T23:49:17.105158+00:00", "data": {"market": "0xe7d699841d03f695da20c8935f4cdf809057f3b27fa4f382e327ff731b8d75a7", "price_changes": [{"asset_id": "40666723045616055650551965571535047681860486685123797401746526747593369094525", "price": "0.06", "size": "530.01", "side": "SELL", "hash": "772d324f169f18d8cb964bbf3eb89e7ea4f604f9", "best_bid": "0.03", "best_ask": "0.05"}, {"asset_id": "86720801120812523206375862885554727968671842048571953285734439150624995757719", "price": "0.94", "size": "530.01", "side": "BUY", "hash": "bcf54150a3fd2190cd7a74d953fbb0c11f4d22b4", "best_bid": "0.95", "best_ask": "0.97"}], "timestamp": "1769384957000", "event_type": "price_change"}}
{"_local_timestamp": "2026-01-25T23:49:20.151552+00:00", "data": {"market": "0xe7d699841d03f695da20c8935f4cdf809057f3b27fa4f382e327ff731b8d75a7", "price_changes": [{"asset_id": "40666723045616055650551965571535047681860486685123797401746526747593369094525", "price": "0.06", "size": "580.01", "side": "SELL", "hash": "ce07eb2e6f0eb20a5af6c7d9b9aad738b1e803fd", "best_bid": "0.03", "best_ask": "0.05"}, {"asset_id": "86720801120812523206375862885554727968671842048571953285734439150624995757719", "price": "0.94", "size": "580.01", "side": "BUY", "hash": "9b244346ddc4aa0f589876f79801fa34b4e0ec6e", "best_bid": "0.95", "best_ask": "0.97"}], "timestamp": "1769384960070", "event_type": "price_change"}}
{"_local_timestamp": "2026-01-25T23:49:20.152979+00:00", "data": {"market": "0xe7d699841d03f695da20c8935f4cdf809057f3b27fa4f382e327ff731b8d75a7", "price_changes": [{"asset_id": "40666723045616055650551965571535047681860486685123797401746526747593369094525", "price": "0.02", "size": "425", "side": "BUY", "hash": "f897cf7a11a9c9660a75bd791eb72445ea2eff3b", "best_bid": "0.03", "best_ask": "0.05"}, {"asset_id": "86720801120812523206375862885554727968671842048571953285734439150624995757719", "price": "0.98", "size": "425", "side": "SELL", "hash": "c5edd2cdc510225842a55dcc538ca37ce7403e87", "best_bid": "0.95", "best_ask": "0.97"}], "timestamp": "1769384960071", "event_type": "price_change"}}
{"_local_timestamp": "2026-01-25T23:49:24.786226+00:00", "data": {"market": "0x23e782e8db3eb990b48ff37432f9f0899e73ea737e68d2934bd09b34934dc0d0", "price_changes": [{"asset_id": "42382535584090931070184963017291726037912989687255284323203344679942164276749", "price": "0.283", "size": "583", "side": "BUY", "hash": "0bc8631714bfbc23d7fb8899db98978010b9413a", "best_bid": "0.87", "best_ask": "0.98"}, {"asset_id": "35728543926876832227758010997325479102150155332621985448512538195119929531554", "price": "0.717", "size": "583", "side": "SELL", "hash": "94bd294b72f42992a5f377cdddd45f7fd68d6746", "best_bid": "0.02", "best_ask": "0.13"}], "timestamp": "1769384964682", "event_type": "price_change"}}
{"_local_timestamp": "2026-01-25T23:49:25.596369+00:00", "data": {"market": "0xe7d699841d03f695da20c8935f4cdf809057f3b27fa4f382e327ff731b8d75a7", "price_changes": [{"asset_id": "86720801120812523206375862885554727968671842048571953285734439150624995757719", "price": "0.25", "size": "50", "side": "BUY", "hash": "2febc4592bfb7ad5b5b99b623abc9452d55dcdd4", "best_bid": "0.95", "best_ask": "0.97"}, {"asset_id": "40666723045616055650551965571535047681860486685123797401746526747593369094525", "price": "0.75", "size": "50", "side": "SELL", "hash": "26114d8025185ac653653e6150d8059acebde95a", "best_bid": "0.03", "best_ask": "0.05"}], "timestamp": "1769384965494", "event_type": "price_change"}}
{"_local_timestamp": "2026-01-25T23:49:25.857759+00:00", "data": {"market": "0xe7d699841d03f695da20c8935f4cdf809057f3b27fa4f382e327ff731b8d75a7", "price_changes": [{"asset_id": "86720801120812523206375862885554727968671842048571953285734439150624995757719", "price": "0.3", "size": "1500", "side": "BUY", "hash": "32efa77c01add7dc1e0658fdb76b9ff47cccf1e8", "best_bid": "0.95", "best_ask": "0.97"}, {"asset_id": "40666723045616055650551965571535047681860486685123797401746526747593369094525", "price": "0.7", "size": "1500", "side": "SELL", "hash": "24a0c049733aaa60ec7d4a0eba2dc6dce5ba0321", "best_bid": "0.03", "best_ask": "0.05"}], "timestamp": "1769384965763", "event_type": "price_change"}}
{"_local_timestamp": "2026-01-25T23:49:28.127034+00:00", "data": {"market": "0x23e782e8db3eb990b48ff37432f9f0899e73ea737e68d2934bd09b34934dc0d0", "price_changes": [{"asset_id": "42382535584090931070184963017291726037912989687255284323203344679942164276749", "price": "0.87", "size": "0", "side": "BUY", "hash": "fd9fa20dbce8997b919c78c95f326ddb6bf76290", "best_bid": "0.851", "best_ask": "0.98"}, {"asset_id": "35728543926876832227758010997325479102150155332621985448512538195119929531554", "price": "0.13", "size": "0", "side": "SELL", "hash": "c2239bdc2732c54a254cdfa2fa75697147a74d7c", "best_bid": "0.02", "best_ask": "0.149"}], "timestamp": "1769384968004", "event_type": "price_change"}}
{"_local_timestamp": "2026-01-25T23:49:28.169082+00:00", "data": {"market": "0x23e782e8db3eb990b48ff37432f9f0899e73ea737e68d2934bd09b34934dc0d0", "price_changes": [{"asset_id": "42382535584090931070184963017291726037912989687255284323203344679942164276749", "price": "0.854", "size": "20", "side": "BUY", "hash": "794c202520899a7ec9c0be29bf3a4cd26c189d97", "best_bid": "0.854", "best_ask": "0.98"}, {"asset_id": "35728543926876832227758010997325479102150155332621985448512538195119929531554", "price": "0.146", "size": "20", "side": "SELL", "hash": "3f1d68d6cc49d4e48d6bfbc8499d1173455e3c8c", "best_bid": "0.02", "best_ask": "0.146"}], "timestamp": "1769384968078", "event_type": "price_change"}}
{"_local_timestamp": "2026-01-25T23:49:30.291082+00:00", "data": {"market": "0xad1f282f187c4748fe6eb51153a39557c66856cd14408bc3d509d3b23c047d41", "price_changes": [{"asset_id": "86814839478893548397184492422021698202794732526767012779986423826365559163504", "price": "0.22", "size": "200", "side": "BUY", "hash": "a166af0d7b5b727b2af9bffef7616b10db31eae6", "best_bid": "0.54", "best_ask": "0.65"}, {"asset_id": "26089319074590795210476289468934414386490143191167179409102092139417103170837", "price": "0.78", "size": "200", "side": "SELL", "hash": "989d0e1637f819c6601bcfa1b7c532545c20f995", "best_bid": "0.35", "best_ask": "0.46"}], "timestamp": "1769384970053", "event_type": "price_change"}}
