{"_local_timestamp": "2026-01-25T23:40:33.174254+00:00", "data": [{"market": "0x960324c7d2db73740836bbd97eec770fcb9b5372e5b46d98b2999fdbbd017f7a", "asset_id": "80664742764535144927724195537615142554527026640240245478342373307617044724467", "timestamp": "1769384402803", "hash": "d09c74a1b335789a19b66dce5a78daa1225f4608", "bids": [{"price": "0.001", "size": "6104567.27"}, {"price": "0.002", "size": "31257.87"}, {"price": "0.003", "size": "1166"}, {"price": "0.004", "size": "6000"}, {"price": "0.005", "size": "6.23"}, {"price": "0.006", "size": "83"}, {"price": "0.01", "size": "7000"}, {"price": "0.011", "size": "20005.1"}, {"price": "0.02", "size": "3500"}, {"price": "0.021", "size": "20400"}, {"price": "0.022", "size": "12.88"}, {"price": "0.04", "size": "1750"}, {"price": "0.041", "size": "6000"}, {"price": "0.05", "size": "20"}, {"price": "0.051", "size": "39"}, {"price": "0.08", "size": "1250"}, {"price": "0.081", "size": "3200"}, {"price": "0.082", "size": "5.78"}, {"price": "0.1", "size": "360"}, {"price": "0.105", "size": "6000"}, {"price": "0.14", "size": "242.85"}, {"price": "0.15", "size": "1300"}, {"price": "0.19", "size": "168.42"}, {"price": "0.192", "size": "3537"}, {"price": "0.2", "size": "500"}, {"price": "0.202", "size": "900"}, {"price": "0.203", "size": "788"}, {"price": "0.204", "size": "5.56"}, {"price": "0.231", "size": "2300"}, {"price": "0.232", "size": "1810"}, {"price": "0.24", "size": "116.66"}, {"price": "0.29", "size": "189.65"}, {"price": "0.34", "size": "70.58"}, {"price": "0.371", "size": "1050"}, {"price": "0.39", "size": "51.28"}, {"price": "0.431", "size": "1397"}, {"price": "0.432", "size": "607"}, {"price": "0.433", "size": "226"}, {"price": "0.709", "size": "100"}, {"price": "0.711", "size": "30"}, {"price": "0.712", "size": "40"}, {"price": "0.714", "size": "20"}, {"price": "0.715", "size": "45"}, {"price": "0.716", "size": "20"}, {"price": "0.802", "size": "37"}, {"price": "0.813", "size": "100"}, {"price": "0.91", "size": "200"}, {"price": "0.911", "size": "20"}, {"price": "0.917", "size": "23"}], "asks": [{"price": "0.999", "size": "143452"}, {"price": "0.998", "size": "3166"}, {"price": "0.997", "size": "7.45"}, {"price": "0.995", "size": "400"}, {"price": "0.994", "size": "9.67"}, {"price": "0.992", "size": "250"}, {"price": "0.99", "size": "400"}, {"price": "0.987", "size": "200"}, {"price": "0.986", "size": "10.12"}, {"price": "0.977", "size": "100"}, {"price": "0.966", "size": "3.87"}, {"price": "0.965", "size": "500"}, {"price": "0.964", "size": "300"}, {"price": "0.963", "size": "300"}, {"price": "0.962", "size": "269.3"}, {"price": "0.961", "size": "30"}, {"price": "0.96", "size": "34.65"}], "event_type": "book", "last_trade_price": ""}, {"market": "0xa32587f6a3b3fa89d71c5648c526fe69791ef6593159e682f1ca5d4dc364f974", "asset_id": "54074938701699388770795173053719001491386817666951566814225682866135668313701", "timestamp": "1769384426839", "hash": "a74b8d724343cc794f7d32c82fcbe8ce1fdc661b", "bids": [{"price": "0.001", "size": "1104267.26"}, {"price": "0.002", "size": "7257.86"}, {"price": "0.003", "size": "1400"}, {"price": "0.004", "size": "6000"}, {"price": "0.005", "size": "6.23"}, {"price": "0.006", "size": "200"}, {"price": "0.01", "size": "7000"}, {"price": "0.011", "size": "15005.09"}, {"price": "0.02", "size": "3900"}, {"price": "0.021", "size": "3000"}, {"price": "0.022", "size": "12.87"}, {"price": "0.04", "size": "1750"}, {"price": "0.05", "size": "20"}, {"price": "0.051", "size": "39"}, {"price": "0.08", "size": "1250"}, {"price": "0.081", "size": "3200"}, {"price": "0.082", "size": "5.69"}, {"price": "0.1", "size": "360"}, {"price": "0.105", "size": "6000"}, {"price": "0.14", "size": "242.85"}, {"price": "0.15", "size": "1300"}, {"price": "0.19", "size": "168.42"}, {"price": "0.2", "size": "900"}, {"price": "0.201", "size": "796"}, {"price": "0.202", "size": "5.65"}, {"price": "0.24", "size": "116.66"}, {"price": "0.241", "size": "2042"}, {"price": "0.29", "size": "189.65"}, {"price": "0.34", "size": "70.58"}, {"price": "0.38", "size": "52.63"}, {"price": "0.388", "size": "1671"}, {"price": "0.401", "size": "20"}, {"price": "0.501", "size": "20"}, {"price": "0.512", "size": "3189"}, {"price": "0.513", "size": "1723"}, {"price": "0.68", "size": "20"}, {"price": "0.682", "size": "30"}, {"price": "0.683", "size": "40"}, {"price": "0.685", "size": "20"}, {"price": "0.686", "size": "20"}, {"price": "0.916", "size": "117.98"}, {"price": "0.921", "size": "200"}, {"price": "0.922", "size": "289.73"}, {"price": "0.923", "size": "495"}, {"price": "0.924", "size": "191.64"}, {"price": "0.927", "size": "361.3"}, {"price": "0.928", "size": "100"}, {"price": "0.929", "size": "259.18"}, {"price": "0.93", "size": "119.89"}, {"price": "0.931", "size": "67.9"}], "asks": [{"price": "0.999", "size": "47995"}, {"price": "0.998", "size": "13166"}, {"price": "0.997", "size": "1007.25"}, {"price": "0.996", "size": "2400"}, {"price": "0.995", "size": "400"}, {"price": "0.994", "size": "12.83"}, {"price": "0.99", "size": "100"}, {"price": "0.988", "size": "2000"}, {"price": "0.987", "size": "110"}, {"price": "0.984", "size": "7109.47"}, {"price": "0.983", "size": "7.26"}, {"price": "0.981", "size": "100"}, {"price": "0.974", "size": "395"}, {"price": "0.972", "size": "1650"}, {"price": "0.971", "size": "120"}, {"price": "0.97", "size": "319.14"}, {"price": "0.959", "size": "300"}, {"price": "0.958", "size": "237.8"}], "event_type": "book", "last_trade_price": ""}, {"market": "0xab77a311c7c175ff91707a06dcd358db7a7d7f4258fb7756b05b4f44d175914f", "asset_id": "96433559971245993197815501880637705319986922684384749364193086888126378928132", "timestamp": "1769384431343", "hash": "626f2aba7f853c1ef88378878af90014a9f88642", "bids": [{"price": "0.001", "size": "3103901.27"}, {"price": "0.002", "size": "31257.86"}, {"price": "0.003", "size": "1400"}, {"price": "0.004", "size": "10000"}, {"price": "0.005", "size": "6.23"}, {"price": "0.006", "size": "200"}, {"price": "0.01", "size": "7000"}, {"price": "0.011", "size": "30005.09"}, {"price": "0.02", "size": "3500"}, {"price": "0.021", "size": "20400"}, {"price": "0.022", "size": "12.88"}, {"price": "0.04", "size": "1750"}, {"price": "0.041", "size": "6000"}, {"price": "0.05", "size": "20"}, {"price": "0.051", "size": "39"}, {"price": "0.08", "size": "1250"}, {"price": "0.081", "size": "3000"}, {"price": "0.082", "size": "5.94"}, {"price": "0.09", "size": "400"}, {"price": "0.095", "size": "6200"}, {"price": "0.096", "size": "3142"}, {"price": "0.13", "size": "261.53"}, {"price": "0.15", "size": "1300"}, {"price": "0.18", "size": "177.77"}, {"price": "0.2", "size": "900"}, {"price": "0.206", "size": "3050"}, {"price": "0.207", "size": "772"}, {"price": "0.208", "size": "2023.39"}, {"price": "0.22", "size": "227.27"}, {"price": "0.27", "size": "96.29"}, {"price": "0.279", "size": "150"}, {"price": "0.28", "size": "410"}, {"price": "0.31", "size": "77.41"}, {"price": "0.36", "size": "605.55"}, {"price": "0.381", "size": "337"}, {"price": "0.433", "size": "5"}, {"price": "0.468", "size": "40"}, {"price": "0.47", "size": "30"}, {"price": "0.472", "size": "20"}, {"price": "0.473", "size": "20"}, {"price": "0.735", "size": "180.76"}, {"price": "0.755", "size": "17.21"}, {"price": "0.756", "size": "14.55"}, {"price": "0.857", "size": "200"}, {"price": "0.861", "size": "200"}, {"price": "0.862", "size": "101.02"}, {"price": "0.868", "size": "23.06"}, {"price": "0.869", "size": "20.98"}], "asks": [{"price": "0.999", "size": "163777"}, {"price": "0.998", "size": "1671.59"}, {"price": "0.997", "size": "2700"}, {"price": "0.996", "size": "800"}, {"price": "0.995", "size": "800"}, {"price": "0.994", "size": "8.78"}, {"price": "0.979", "size": "200"}, {"price": "0.978", "size": "1000"}, {"price": "0.977", "size": "100"}, {"price": "0.976", "size": "541.66"}, {"price": "0.975", "size": "220"}, {"price": "0.974", "size": "6.09"}, {"price": "0.963", "size": "500"}, {"price": "0.96", "size": "100"}, {"price": "0.959", "size": "25"}, {"price": "0.944", "size": "40"}, {"price": "0.942", "size": "100"}, {"price": "0.941", "size": "100"}, {"price": "0.922", "size": "100"}, {"price": "0.912", "size": "1161.62"}, {"price": "0.906", "size": "135"}, {"price": "0.903", "size": "1000"}, {"price": "0.902", "size": "300"}, {"price": "0.901", "size": "200"}, {"price": "0.9", "size": "300"}, {"price": "0.893", "size": "110.36"}, {"price": "0.892", "size": "9.77"}], "event_type": "book", "last_trade_price": ""}, {"market": "0xab77a311c7c175ff91707a06dcd358db7a7d7f4258fb7756b05b4f44d175914f", "asset_id": "100716705141639838044649900187335811063814165386716787647982371091165872129354", "timestamp": "1769384431343", "hash": "c0e0ce28c20147a4365124e7f83715c5d3810552", "bids": [{"price": "0.001", "size": "163777"}, {"price": "0.002", "size": "1671.59"}, {"price": "0.003", "size": "2700"}, {"price": "0.004", "size": "800"}, {"price": "0.005", "size": "800"}, {"price": "0.006", "size": "8.78"}, {"price": "0.021", "size": "200"}, {"price": "0.022", "size": "1000"}, {"price": "0.023", "size": "100"}, {"price": "0.024", "size": "541.66"}, {"price": "0.025", "size": "220"}, {"price": "0.026", "size": "6.09"}, {"price": "0.037", "size": "500"}, {"price": "0.04", "size": "100"}, {"price": "0.041", "size": "25"}, {"price": "0.056", "size": "40"}, {"price": "0.058", "size": "100"}, {"price": "0.059", "size": "100"}, {"price": "0.078", "size": "100"}, {"price": "0.088", "size": "1161.62"}, {"price": "0.094", "size": "135"}, {"price": "0.097", "size": "1000"}, {"price": "0.098", "size": "300"}, {"price": "0.099", "size": "200"}, {"price": "0.1", "size": "300"}, {"price": "0.107", "size": "110.36"}, {"price": "0.108", "size": "9.77"}], "asks": [{"price": "0.999", "size": "3103901.27"}, {"price": "0.998", "size": "31257.86"}, {"price": "0.997", "size": "1400"}, {"price": "0.996", "size": "10000"}, {"price": "0.995", "size": "6.23"}, {"price": "0.994", "size": "200"}, {"price": "0.99", "size": "7000"}, {"price": "0.989", "size": "30005.09"}, {"price": "0.98", "size": "3500"}, {"price": "0.979", "size": "20400"}, {"price": "0.978", "size": "12.88"}, {"price": "0.96", "size": "1750"}, {"price": "0.959", "size": "6000"}, {"price": "0.95", "size": "20"}, {"price": "0.949", "size": "39"}, {"price": "0.92", "size": "1250"}, {"price": "0.919", "size": "3000"}, {"price": "0.918", "size": "5.94"}, {"price": "0.91", "size": "400"}, {"price": "0.905", "size": "6200"}, {"price": "0.904", "size": "3142"}, {"price": "0.87", "size": "261.53"}, {"price": "0.85", "size": "1300"}, {"price": "0.82", "size": "177.77"}, {"price": "0.8", "size": "900"}, {"price": "0.794", "size": "3050"}, {"price": "0.793", "size": "772"}, {"price": "0.792", "size": "2023.39"}, {"price": "0.78", "size": "227.27"}, {"price": "0.73", "size": "96.29"}, {"price": "0.721", "size": "150"}, {"price": "0.72", "size": "410"}, {"price": "0.69", "size": "77.41"}, {"price": "0.64", "size": "605.55"}, {"price": "0.619", "size": "337"}, {"price": "0.567", "size": "5"}, {"price": "0.532", "size": "40"}, {"price": "0.53", "size": "30"}, {"price": "0.528", "size": "20"}, {"price": "0.527", "size": "20"}, {"price": "0.265", "size": "180.76"}, {"price": "0.245", "size": "17.21"}, {"price": "0.244", "size": "14.55"}, {"price": "0.143", "size": "200"}, {"price": "0.139", "size": "200"}, {"price": "0.138", "size": "101.02"}, {"price": "0.132", "size": "23.06"}, {"price": "0.131", "size": "20.98"}], "event_type": "book", "last_trade_price": ""}, {"market": "0xa32587f6a3b3fa89d71c5648c526fe69791ef6593159e682f1ca5d4dc364f974", "asset_id": "46775328864914034111636027140584666041009849439098120541770590397117980620796", "timestamp": "1769384426839", "hash": "3903efd63b360a116c5d3c4cfa80363e056432b8", "bids": [{"price": "0.001", "size": "47995"}, {"price": "0.002", "size": "13166"}, {"price": "0.003", "size": "1007.25"}, {"price": "0.004", "size": "2400"}, {"price": "0.005", "size": "400"}, {"price": "0.006", "size": "12.83"}, {"price": "0.01", "size": "100"}, {"price": "0.012", "size": "2000"}, {"price": "0.013", "size": "110"}, {"price": "0.016", "size": "7109.47"}, {"price": "0.017", "size": "7.26"}, {"price": "0.019", "size": "100"}, {"price": "0.026", "size": "395"}, {"price": "0.028", "size": "1650"}, {"price": "0.029", "size": "120"}, {"price": "0.03", "size": "319.14"}, {"price": "0.041", "size": "300"}, {"price": "0.042", "size": "237.8"}], "asks": [{"price": "0.999", "size": "1104267.26"}, {"price": "0.998", "size": "7257.86"}, {"price": "0.997", "size": "1400"}, {"price": "0.996", "size": "6000"}, {"price": "0.995", "size": "6.23"}, {"price": "0.994", "size": "200"}, {"price": "0.99", "size": "7000"}, {"price": "0.989", "size": "15005.09"}, {"price": "0.98", "size": "3900"}, {"price": "0.979", "size": "3000"}, {"price": "0.978", "size": "12.87"}, {"price": "0.96", "size": "1750"}, {"price": "0.95", "size": "20"}, {"price": "0.949", "size": "39"}, {"price": "0.92", "size": "1250"}, {"price": "0.919", "size": "3200"}, {"price": "0.918", "size": "5.69"}, {"price": "0.9", "size": "360"}, {"price": "0.895", "size": "6000"}, {"price": "0.86", "size": "242.85"}, {"price": "0.85", "size": "1300"}, {"price": "0.81", "size": "168.42"}, {"price": "0.8", "size": "900"}, {"price": "0.799", "size": "796"}, {"price": "0.798", "size": "5.65"}, {"price": "0.76", "size": "116.66"}, {"price": "0.759", "size": "2042"}, {"price": "0.71", "size": "189.65"}, {"price": "0.66", "size": "70.58"}, {"price": "0.62", "size": "52.63"}, {"price": "0.612", "size": "1671"}, {"price": "0.599", "size": "20"}, {"price": "0.499", "size": "20"}, {"price": "0.488", "size": "3189"}, {"price": "0.487", "size": "1723"}, {"price": "0.32", "size": "20"}, {"price": "0.318", "size": "30"}, {"price": "0.317", "size": "40"}, {"price": "0.315", "size": "20"}, {"price": "0.314", "size": "20"}, {"price": "0.084", "size": "117.98"}, {"price": "0.079", "size": "200"}, {"price": "0.078", "size": "289.73"}, {"price": "0.077", "size": "495"}, {"price": "0.076", "size": "191.64"}, {"price": "0.073", "size": "361.3"}, {"price": "0.072", "size": "100"}, {"price": "0.071", "size": "259.18"}, {"price": "0.07", "size": "119.89"}, {"price": "0.069", "size": "67.9"}], "event_type": "book", "last_trade_price": ""}, {"market": "0xaca5aedf274be4876eed3441d1cd4c9f5f3908ee2d5dff4c838ba89cd69365d8", "asset_id": "82834542816241625492514061227288286309604590623265497797502039631748808662467", "timestamp": "1769384356794", "hash": "8e469c339166bda6e47fab2f1280fe1af3a53c50", "bids": [{"price": "0.001", "size": "3107196.27"}, {"price": "0.002", "size": "31255.25"}, {"price": "0.003", "size": "1400"}, {"price": "0.004", "size": "9.1"}, {"price": "0.006", "size": "200"}, {"price": "0.01", "size": "7000"}, {"price": "0.011", "size": "14.07"}, {"price": "0.02", "size": "3500"}, {"price": "0.04", "size": "1750"}, {"price": "0.041", "size": "12400"}, {"price": "0.042", "size": "5.34"}, {"price": "0.08", "size": "1250"}, {"price": "0.09", "size": "400"}, {"price": "0.091", "size": "5.07"}, {"price": "0.095", "size": "3200"}, {"price": "0.13", "size": "261.53"}, {"price": "0.15", "size": "1300"}, {"price": "0.17", "size": "188.23"}, {"price": "0.2", "size": "900"}, {"price": "0.201", "size": "796"}, {"price": "0.21", "size": "6433.33"}, {"price": "0.211", "size": "1990"}, {"price": "0.212", "size": "5.22"}, {"price": "0.26", "size": "150"}, {"price": "0.27", "size": "50"}, {"price": "0.3", "size": "80"}, {"price": "0.34", "size": "108.82"}, {"price": "0.406", "size": "5"}, {"price": "0.408", "size": "3429"}, {"price": "0.409", "size": "1941"}, {"price": "0.513", "size": "20"}, {"price": "0.521", "size": "30"}, {"price": "0.523", "size": "40"}, {"price": "0.524", "size": "20"}, {"price": "0.685", "size": "18.97"}, {"price": "0.686", "size": "16.03"}, {"price": "0.805", "size": "8.98"}, {"price": "0.809", "size": "399.99"}, {"price": "0.81", "size": "619"}, {"price": "0.821", "size": "178"}, {"price": "0.822", "size": "400"}, {"price": "0.827", "size": "100"}, {"price": "0.835", "size": "65.86"}], "asks": [{"price": "0.999", "size": "48927"}, {"price": "0.998", "size": "4416"}, {"price": "0.996", "size": "5000"}, {"price": "0.995", "size": "1200"}, {"price": "0.994", "size": "6.31"}, {"price": "0.988", "size": "100"}, {"price": "0.98", "size": "2000"}, {"price": "0.978", "size": "150"}, {"price": "0.977", "size": "8.01"}, {"price": "0.954", "size": "50"}, {"price": "0.942", "size": "224.13"}, {"price": "0.941", "size": "93.22"}, {"price": "0.873", "size": "516.27"}, {"price": "0.866", "size": "100"}, {"price": "0.861", "size": "177"}, {"price": "0.86", "size": "831.42"}, {"price": "0.859", "size": "200"}, {"price": "0.858", "size": "37.04"}], "event_type": "book", "last_trade_price": ""}, {"market": "0xfff9fd2422f8e3b878a2701c4eb1e9e182a35d9a71ec2d4233ccd2cac834f887", "asset_id": "2095798660633756262303834783492337010518543450973961053424376028794255397244", "timestamp": "1769384426839", "hash": "d2d041f4e16725e449fb3b578fc329ebb3a30c6b", "bids": [{"price": "0.001", "size": "71889"}, {"price": "0.002", "size": "3166"}, {"price": "0.003", "size": "6.65"}, {"price": "0.004", "size": "2000"}, {"price": "0.005", "size": "600"}, {"price": "0.008", "size": "500"}, {"price": "0.009", "size": "22.47"}, {"price": "0.05", "size": "200"}, {"price": "0.051", "size": "400"}, {"price": "0.052", "size": "90"}, {"price": "0.066", "size": "240"}, {"price": "0.067", "size": "70"}, {"price": "0.084", "size": "100"}, {"price": "0.086", "size": "131.25"}, {"price": "0.088", "size": "300"}, {"price": "0.089", "size": "101"}], "asks": [{"price": "0.999", "size": "6104140.35"}, {"price": "0.998", "size": "31255.33"}, {"price": "0.997", "size": "1400"}, {"price": "0.996", "size": "10.55"}, {"price": "0.994", "size": "200"}, {"price": "0.99", "size": "7000"}, {"price": "0.989", "size": "30000"}, {"price": "0.988", "size": "12.23"}, {"price": "0.98", "size": "3500"}, {"price": "0.979", "size": "9400"}, {"price": "0.96", "size": "1750"}, {"price": "0.959", "size": "5.65"}, {"price": "0.95", "size": "20"}, {"price": "0.949", "size": "39"}, {"price": "0.92", "size": "1250"}, {"price": "0.919", "size": "3000"}, {"price": "0.91", "size": "400"}, {"price": "0.909", "size": "5.25"}, {"price": "0.905", "size": "6200"}, {"price": "0.86", "size": "242.85"}, {"price": "0.85", "size": "1300"}, {"price": "0.848", "size": "9000"}, {"price": "0.82", "size": "177.77"}, {"price": "0.8", "size": "900"}, {"price": "0.79", "size": "3000"}, {"price": "0.788", "size": "754"}, {"price": "0.787", "size": "3863"}, {"price": "0.785", "size": "5.04"}, {"price": "0.77", "size": "121.73"}, {"price": "0.73", "size": "96.29"}, {"price": "0.72", "size": "2051"}, {"price": "0.68", "size": "75"}, {"price": "0.64", "size": "180.55"}, {"price": "0.529", "size": "326"}, {"price": "0.506", "size": "5"}, {"price": "0.484", "size": "390"}, {"price": "0.483", "size": "193"}, {"price": "0.482", "size": "20"}, {"price": "0.48", "size": "30"}, {"price": "0.478", "size": "66.66"}, {"price": "0.477", "size": "13"}, {"price": "0.476", "size": "20"}, {"price": "0.144", "size": "294.58"}, {"price": "0.124", "size": "200"}, {"price": "0.119", "size": "133"}], "event_type": "book", "last_trade_price": "0.090"}, {"market": "0xfff9fd2422f8e3b878a2701c4eb1e9e182a35d9a71ec2d4233ccd2cac834f887", "asset_id": "97579963624866678731903283461280009667266517428659356160462670347995084766428", "timestamp": "1769384426839", "hash": "035d854a511e39be62b0f7b3de05e552be72ee4b", "bids": [{"price": "0.001", "size": "6104140.35"}, {"price": "0.002", "size": "31255.33"}, {"price": "0.003", "size": "1400"}, {"price": "0.004", "size": "10.55"}, {"price": "0.006", "size": "200"}, {"price": "0.01", "size": "7000"}, {"price": "0.011", "size": "30000"}, {"price": "0.012", "size": "12.23"}, {"price": "0.02", "size": "3500"}, {"price": "0.021", "size": "9400"}, {"price": "0.04", "size": "1750"}, {"price": "0.041", "size": "5.65"}, {"price": "0.05", "size": "20"}, {"price": "0.051", "size": "39"}, {"price": "0.08", "size": "1250"}, {"price": "0.081", "size": "3000"}, {"price": "0.09", "size": "400"}, {"price": "0.091", "size": "5.25"}, {"price": "0.095", "size": "6200"}, {"price": "0.14", "size": "242.85"}, {"price": "0.15", "size": "1300"}, {"price": "0.152", "size": "9000"}, {"price": "0.18", "size": "177.77"}, {"price": "0.2", "size": "900"}, {"price": "0.21", "size": "3000"}, {"price": "0.212", "size": "754"}, {"price": "0.213", "size": "3863"}, {"price": "0.215", "size": "5.04"}, {"price": "0.23", "size": "121.73"}, {"price": "0.27", "size": "96.29"}, {"price": "0.28", "size": "2051"}, {"price": "0.32", "size": "75"}, {"price": "0.36", "size": "180.55"}, {"price": "0.471", "size": "326"}, {"price": "0.494", "size": "5"}, {"price": "0.516", "size": "390"}, {"price": "0.517", "size": "193"}, {"price": "0.518", "size": "20"}, {"price": "0.52", "size": "30"}, {"price": "0.522", "size": "66.66"}, {"price": "0.523", "size": "13"}, {"price": "0.524", "size": "20"}, {"price": "0.856", "size": "294.58"}, {"price": "0.876", "size": "200"}, {"price": "0.881", "size": "133"}], "asks": [{"price": "0.999", "size": "71889"}, {"price": "0.998", "size": "3166"}, {"price": "0.997", "size": "6.65"}, {"price": "0.996", "size": "2000"}, {"price": "0.995", "size": "600"}, {"price": "0.992", "size": "500"}, {"price": "0.991", "size": "22.47"}, {"price": "0.95", "size": "200"}, {"price": "0.949", "size": "400"}, {"price": "0.948", "size": "90"}, {"price": "0.934", "size": "240"}, {"price": "0.933", "size": "70"}, {"price": "0.916", "size": "100"}, {"price": "0.914", "size": "131.25"}, {"price": "0.912", "size": "300"}, {"price": "0.911", "size": "101"}], "event_type": "book", "last_trade_price": "0.090"}, {"market": "0x326df6a10a6cdd74bdc1ef77906037e90b1f1d6dd1fdcbf6580aea62de094a96", "asset_id": "111947356992305187589428447311248216731582641625774563053368133120784997422919", "timestamp": "1769384401775", "hash": "b5837b18ec9a6e5668a72acf8bbc2222460b037f", "bids": [{"price": "0.001", "size": "1104040.26"}, {"price": "0.002", "size": "1257.86"}, {"price": "0.003", "size": "1400"}, {"price": "0.004", "size": "6000"}, {"price": "0.005", "size": "6.23"}, {"price": "0.006", "size": "200"}, {"price": "0.01", "size": "7000"}, {"price": "0.011", "size": "15005.09"}, {"price": "0.02", "size": "3500"}, {"price": "0.021", "size": "20400"}, {"price": "0.022", "size": "12.88"}, {"price": "0.04", "size": "1750"}, {"price": "0.05", "size": "20"}, {"price": "0.051", "size": "39"}, {"price": "0.08", "size": "1250"}, {"price": "0.081", "size": "3000"}, {"price": "0.082", "size": "5.9"}, {"price": "0.09", "size": "400"}, {"price": "0.096", "size": "6200"}, {"price": "0.14", "size": "242.85"}, {"price": "0.15", "size": "1300"}, {"price": "0.18", "size": "177.77"}, {"price": "0.181", "size": "3756"}, {"price": "0.2", "size": "500"}, {"price": "0.205", "size": "3050"}, {"price": "0.206", "size": "776"}, {"price": "0.207", "size": "2033.43"}, {"price": "0.23", "size": "221.73"}, {"price": "0.27", "size": "96.29"}, {"price": "0.29", "size": "609"}, {"price": "0.32", "size": "75"}, {"price": "0.36", "size": "55.55"}, {"price": "0.362", "size": "550"}, {"price": "0.363", "size": "175"}, {"price": "0.409", "size": "20"}, {"price": "0.41", "size": "5"}, {"price": "0.509", "size": "20"}, {"price": "0.609", "size": "20"}, {"price": "0.654", "size": "252"}, {"price": "0.713", "size": "40"}, {"price": "0.715", "size": "20"}, {"price": "0.717", "size": "30"}, {"price": "0.718", "size": "33.33"}, {"price": "0.777", "size": "100"}, {"price": "0.877", "size": "20"}, {"price": "0.885", "size": "40"}, {"price": "0.898", "size": "217.44"}], "asks": [{"price": "0.999", "size": "44114"}, {"price": "0.998", "size": "3516"}, {"price": "0.997", "size": "1300"}, {"price": "0.996", "size": "6.04"}, {"price": "0.99", "size": "5000"}, {"price": "0.989", "size": "18"}, {"price": "0.97", "size": "500"}, {"price": "0.965", "size": "200"}, {"price": "0.95", "size": "100"}, {"price": "0.949", "size": "117.28"}, {"price": "0.941", "size": "232.32"}, {"price": "0.94", "size": "57"}, {"price": "0.939", "size": "50"}, {"price": "0.92", "size": "500"}, {"price": "0.919", "size": "312.55"}, {"price": "0.918", "size": "300"}, {"price": "0.917", "size": "153.33"}, {"price": "0.916", "size": "53.33"}, {"price": "0.915", "size": "73.33"}, {"price": "0.914", "size": "114.61"}], "event_type": "book", "last_trade_price": ""}, {"market": "0xcfaa155abdb4c4447285c3fb08ce11273ad7b648cbc29b26bbc99a5d50a57688", "asset_id": "107532164421846439086348783344173461119922836080219299112376014605456903082560", "timestamp": "1769384339913", "hash": "b6a4087d996ff29817b269f9dffa1b22ac51a3d1", "bids": [{"price": "0.001", "size": "2104075.36"}, {"price": "0.002", "size": "61258.01"}, {"price": "0.003", "size": "1400"}, {"price": "0.004", "size": "21000"}, {"price": "0.005", "size": "7.39"}, {"price": "0.006", "size": "200"}, {"price": "0.01", "size": "6000"}, {"price": "0.011", "size": "20000"}, {"price": "0.012", "size": "12.28"}, {"price": "0.02", "size": "3500"}, {"price": "0.021", "size": "20400"}, {"price": "0.04", "size": "1750"}, {"price": "0.041", "size": "9005.14"}, {"price": "0.08", "size": "1700"}, {"price": "0.085", "size": "9200"}, {"price": "0.086", "size": "5.32"}, {"price": "0.12", "size": "283.33"}, {"price": "0.15", "size": "1300"}, {"price": "0.16", "size": "200"}, {"price": "0.166", "size": "6400"}, {"price": "0.167", "size": "958"}, {"price": "0.2", "size": "690"}, {"price": "0.201", "size": "2093.6"}, {"price": "0.24", "size": "208.33"}, {"price": "0.28", "size": "85.71"}, {"price": "0.281", "size": "3495"}, {"price": "0.282", "size": "346"}, {"price": "0.32", "size": "62.5"}, {"price": "0.34", "size": "125"}, {"price": "0.341", "size": "5"}, {"price": "0.542", "size": "500"}, {"price": "0.543", "size": "460"}, {"price": "0.604", "size": "20"}, {"price": "0.605", "size": "20"}, {"price": "0.607", "size": "30"}, {"price": "0.608", "size": "40"}, {"price": "0.655", "size": "19.84"}, {"price": "0.656", "size": "16.76"}, {"price": "0.781", "size": "425.57"}, {"price": "0.782", "size": "100"}, {"price": "0.801", "size": "321.32"}], "asks": [{"price": "0.999", "size": "52833"}, {"price": "0.998", "size": "4516"}, {"price": "0.996", "size": "2000"}, {"price": "0.995", "size": "600"}, {"price": "0.994", "size": "7.99"}, {"price": "0.992", "size": "2000"}, {"price": "0.991", "size": "400"}, {"price": "0.985", "size": "300"}, {"price": "0.968", "size": "100"}, {"price": "0.967", "size": "5.28"}, {"price": "0.9", "size": "101"}, {"price": "0.898", "size": "50"}, {"price": "0.887", "size": "115.04"}, {"price": "0.886", "size": "96.49"}, {"price": "0.832", "size": "516.27"}, {"price": "0.821", "size": "100"}, {"price": "0.811", "size": "10"}, {"price": "0.802", "size": "150.14"}], "event_type": "book", "last_trade_price": ""}, {"market": "0xac0e8cc2c1194bd79bfee4d944134a22a470dabf9a44973078931586ec2b4713", "asset_id": "7465944841767583018291499747334711307126986423404813304527234412438530575641", "timestamp": "1769384389753", "hash": "3b48a73946816737005dfeeca6e932872da1afbd", "bids": [{"price": "0.01", "size": "1031.24"}, {"price": "0.02", "size": "200"}, {"price": "0.05", "size": "120"}, {"price": "0.07", "size": "921.65"}, {"price": "0.08", "size": "172.92"}], "asks": [{"price": "0.99", "size": "218305.22"}, {"price": "0.98", "size": "18905.06"}, {"price": "0.97", "size": "12000"}, {"price": "0.96", "size": "1755.86"}, {"price": "0.95", "size": "20"}, {"price": "0.94", "size": "33"}, {"price": "0.92", "size": "1250"}, {"price": "0.91", "size": "3605.58"}, {"price": "0.89", "size": "3818"}, {"price": "0.86", "size": "242.85"}, {"price": "0.85", "size": "3300"}, {"price": "0.84", "size": "1400"}, {"price": "0.82", "size": "177.77"}, {"price": "0.8", "size": "500"}, {"price": "0.79", "size": "5.28"}, {"price": "0.77", "size": "121.73"}, {"price": "0.75", "size": "3325"}, {"price": "0.72", "size": "192.85"}, {"price": "0.68", "size": "75"}, {"price": "0.63", "size": "54.05"}, {"price": "0.62", "size": "869"}, {"price": "0.61", "size": "5"}, {"price": "0.55", "size": "20"}, {"price": "0.46", "size": "100"}, {"price": "0.45", "size": "120"}, {"price": "0.35", "size": "120"}, {"price": "0.34", "size": "126"}, {"price": "0.31", "size": "100"}, {"price": "0.3", "size": "20"}, {"price": "0.28", "size": "50"}, {"price": "0.27", "size": "40"}, {"price": "0.26", "size": "20"}, {"price": "0.25", "size": "50"}, {"price": "0.22", "size": "100"}, {"price": "0.14", "size": "20"}, {"price": "0.1", "size": "59.68"}, {"price": "0.09", "size": "29.5"}], "event_type": "book", "last_trade_price": "0.080"}, {"market": "0xb51d73fb402680d320b8ae1a1450c17c90eb5c5061d7d406c1f86465276adb60", "asset_id": "58858731796442679222989272055454043286056057669744610936854497026401512278651", "timestamp": "1769384431890", "hash": "1ebff169d6204fb6edd3923ed3b30883f8965124", "bids": [{"price": "0.001", "size": "47945"}, {"price": "0.002", "size": "3522.2"}, {"price": "0.004", "size": "2000"}, {"price": "0.005", "size": "505.64"}, {"price": "0.008", "size": "1000"}, {"price": "0.011", "size": "400"}, {"price": "0.012", "size": "15.13"}, {"price": "0.056", "size": "200"}, {"price": "0.062", "size": "500"}, {"price": "0.063", "size": "300"}, {"price": "0.064", "size": "100"}, {"price": "0.065", "size": "300"}, {"price": "0.066", "size": "200"}, {"price": "0.068", "size": "180"}, {"price": "0.069", "size": "36"}, {"price": "0.07", "size": "42"}], "asks": [{"price": "0.999", "size": "2104272.52"}, {"price": "0.998", "size": "61250"}, {"price": "0.997", "size": "1406.96"}, {"price": "0.994", "size": "200"}, {"price": "0.993", "size": "10.25"}, {"price": "0.99", "size": "7000"}, {"price": "0.989", "size": "20000"}, {"price": "0.98", "size": "3500"}, {"price": "0.979", "size": "13.52"}, {"price": "0.96", "size": "1750"}, {"price": "0.959", "size": "9400"}, {"price": "0.95", "size": "20"}, {"price": "0.949", "size": "39"}, {"price": "0.92", "size": "1250"}, {"price": "0.919", "size": "5.9"}, {"price": "0.912", "size": "12200"}, {"price": "0.91", "size": "400"}, {"price": "0.909", "size": "3296"}, {"price": "0.908", "size": "3282"}, {"price": "0.86", "size": "242.85"}, {"price": "0.85", "size": "1300"}, {"price": "0.849", "size": "2000"}, {"price": "0.81", "size": "168.42"}, {"price": "0.8", "size": "900"}, {"price": "0.798", "size": "3050"}, {"price": "0.797", "size": "788"}, {"price": "0.796", "size": "5.56"}, {"price": "0.77", "size": "221.73"}, {"price": "0.72", "size": "92.85"}, {"price": "0.711", "size": "200"}, {"price": "0.71", "size": "1498"}, {"price": "0.67", "size": "72.72"}, {"price": "0.63", "size": "934.05"}, {"price": "0.613", "size": "5"}, {"price": "0.602", "size": "30"}, {"price": "0.601", "size": "20"}, {"price": "0.258", "size": "244.92"}, {"price": "0.255", "size": "54.82"}, {"price": "0.254", "size": "106.66"}, {"price": "0.252", "size": "3.53"}, {"price": "0.251", "size": "20"}, {"price": "0.177", "size": "66.66"}, {"price": "0.105", "size": "100.25"}, {"price": "0.101", "size": "179"}, {"price": "0.1", "size": "150.17"}, {"price": "0.099", "size": "71.66"}], "event_type": "book", "last_trade_price": ""}, {"market": "0x326df6a10a6cdd74bdc1ef77906037e90b1f1d6dd1fdcbf6580aea62de094a96", "asset_id": "80615165254308476859697533076369001631861513127578482097071314558553613438129", "timestamp": "1769384401775", "hash": "9d97a2bbd6933d74a0429d857404b7613c793c6c", "bids": [{"price": "0.001", "size": "44114"}, {"price": "0.002", "size": "3516"}, {"price": "0.003", "size": "1300"}, {"price": "0.004", "size": "6.04"}, {"price": "0.01", "size": "5000"}, {"price": "0.011", "size": "18"}, {"price": "0.03", "size": "500"}, {"price": "0.035", "size": "200"}, {"price": "0.05", "size": "100"}, {"price": "0.051", "size": "117.28"}, {"price": "0.059", "size": "232.32"}, {"price": "0.06", "size": "57"}, {"price": "0.061", "size": "50"}, {"price": "0.08", "size": "500"}, {"price": "0.081", "size": "312.55"}, {"price": "0.082", "size": "300"}, {"price": "0.083", "size": "153.33"}, {"price": "0.084", "size": "53.33"}, {"price": "0.085", "size": "73.33"}, {"price": "0.086", "size": "114.61"}], "asks": [{"price": "0.999", "size": "1104040.26"}, {"price": "0.998", "size": "1257.86"}, {"price": "0.997", "size": "1400"}, {"price": "0.996", "size": "6000"}, {"price": "0.995", "size": "6.23"}, {"price": "0.994", "size": "200"}, {"price": "0.99", "size": "7000"}, {"price": "0.989", "size": "15005.09"}, {"price": "0.98", "size": "3500"}, {"price": "0.979", "size": "20400"}, {"price": "0.978", "size": "12.88"}, {"price": "0.96", "size": "1750"}, {"price": "0.95", "size": "20"}, {"price": "0.949", "size": "39"}, {"price": "0.92", "size": "1250"}, {"price": "0.919", "size": "3000"}, {"price": "0.918", "size": "5.9"}, {"price": "0.91", "size": "400"}, {"price": "0.904", "size": "6200"}, {"price": "0.86", "size": "242.85"}, {"price": "0.85", "size": "1300"}, {"price": "0.82", "size": "177.77"}, {"price": "0.819", "size": "3756"}, {"price": "0.8", "size": "500"}, {"price": "0.795", "size": "3050"}, {"price": "0.794", "size": "776"}, {"price": "0.793", "size": "2033.43"}, {"price": "0.77", "size": "221.73"}, {"price": "0.73", "size": "96.29"}, {"price": "0.71", "size": "609"}, {"price": "0.68", "size": "75"}, {"price": "0.64", "size": "55.55"}, {"price": "0.638", "size": "550"}, {"price": "0.637", "size": "175"}, {"price": "0.591", "size": "20"}, {"price": "0.59", "size": "5"}, {"price": "0.491", "size": "20"}, {"price": "0.391", "size": "20"}, {"price": "0.346", "size": "252"}, {"price": "0.287", "size": "40"}, {"price": "0.285", "size": "20"}, {"price": "0.283", "size": "30"}, {"price": "0.282", "size": "33.33"}, {"price": "0.223", "size": "100"}, {"price": "0.123", "size": "20"}, {"price": "0.115", "size": "40"}, {"price": "0.102", "size": "217.44"}], "event_type": "book", "last_trade_price": ""}, {"market": "0xcfaa155abdb4c4447285c3fb08ce11273ad7b648cbc29b26bbc99a5d50a57688", "asset_id": "102123833290224736028606807214973577470974985146136880562573223000412048646565", "timestamp": "1769384339913", "hash": "a476c9f4f4ff6c6a4b87a48aa14d7595dd41af3e", "bids": [{"price": "0.001", "size": "52833"}, {"price": "0.002", "size": "4516"}, {"price": "0.004", "size": "2000"}, {"price": "0.005", "size": "600"}, {"price": "0.006", "size": "7.99"}, {"price": "0.008", "size": "2000"}, {"price": "0.009", "size": "400"}, {"price": "0.015", "size": "300"}, {"price": "0.032", "size": "100"}, {"price": "0.033", "size": "5.28"}, {"price": "0.1", "size": "101"}, {"price": "0.102", "size": "50"}, {"price": "0.113", "size": "115.04"}, {"price": "0.114", "size": "96.49"}, {"price": "0.168", "size": "516.27"}, {"price": "0.179", "size": "100"}, {"price": "0.189", "size": "10"}, {"price": "0.198", "size": "150.14"}], "asks": [{"price": "0.999", "size": "2104075.36"}, {"price": "0.998", "size": "61258.01"}, {"price": "0.997", "size": "1400"}, {"price": "0.996", "size": "21000"}, {"price": "0.995", "size": "7.39"}, {"price": "0.994", "size": "200"}, {"price": "0.99", "size": "6000"}, {"price": "0.989", "size": "20000"}, {"price": "0.988", "size": "12.28"}, {"price": "0.98", "size": "3500"}, {"price": "0.979", "size": "20400"}, {"price": "0.96", "size": "1750"}, {"price": "0.959", "size": "9005.14"}, {"price": "0.92", "size": "1700"}, {"price": "0.915", "size": "9200"}, {"price": "0.914", "size": "5.32"}, {"price": "0.88", "size": "283.33"}, {"price": "0.85", "size": "1300"}, {"price": "0.84", "size": "200"}, {"price": "0.834", "size": "6400"}, {"price": "0.833", "size": "958"}, {"price": "0.8", "size": "690"}, {"price": "0.799", "size": "2093.6"}, {"price": "0.76", "size": "208.33"}, {"price": "0.72", "size": "85.71"}, {"price": "0.719", "size": "3495"}, {"price": "0.718", "size": "346"}, {"price": "0.68", "size": "62.5"}, {"price": "0.66", "size": "125"}, {"price": "0.659", "size": "5"}, {"price": "0.458", "size": "500"}, {"price": "0.457", "size": "460"}, {"price": "0.396", "size": "20"}, {"price": "0.395", "size": "20"}, {"price": "0.393", "size": "30"}, {"price": "0.392", "size": "40"}, {"price": "0.345", "size": "19.84"}, {"price": "0.344", "size": "16.76"}, {"price": "0.219", "size": "425.57"}, {"price": "0.218", "size": "100"}, {"price": "0.199", "size": "321.32"}], "event_type": "book", "last_trade_price": ""}, {"market": "0xaca5aedf274be4876eed3441d1cd4c9f5f3908ee2d5dff4c838ba89cd69365d8", "asset_id": "29737896427505913579373080975459102667589461703616780283220419284622020368836", "timestamp": "1769384356794", "hash": "7fd797b2fda942c1a96871faeeddcb37c7146ad8", "bids": [{"price": "0.001", "size": "48927"}, {"price": "0.002", "size": "4416"}, {"price": "0.004", "size": "5000"}, {"price": "0.005", "size": "1200"}, {"price": "0.006", "size": "6.31"}, {"price": "0.012", "size": "100"}, {"price": "0.02", "size": "2000"}, {"price": "0.022", "size": "150"}, {"price": "0.023", "size": "8.01"}, {"price": "0.046", "size": "50"}, {"price": "0.058", "size": "224.13"}, {"price": "0.059", "size": "93.22"}, {"price": "0.127", "size": "516.27"}, {"price": "0.134", "size": "100"}, {"price": "0.139", "size": "177"}, {"price": "0.14", "size": "831.42"}, {"price": "0.141", "size": "200"}, {"price": "0.142", "size": "37.04"}], "asks": [{"price": "0.999", "size": "3107196.27"}, {"price": "0.998", "size": "31255.25"}, {"price": "0.997", "size": "1400"}, {"price": "0.996", "size": "9.1"}, {"price": "0.994", "size": "200"}, {"price": "0.99", "size": "7000"}, {"price": "0.989", "size": "14.07"}, {"price": "0.98", "size": "3500"}, {"price": "0.96", "size": "1750"}, {"price": "0.959", "size": "12400"}, {"price": "0.958", "size": "5.34"}, {"price": "0.92", "size": "1250"}, {"price": "0.91", "size": "400"}, {"price": "0.909", "size": "5.07"}, {"price": "0.905", "size": "3200"}, {"price": "0.87", "size": "261.53"}, {"price": "0.85", "size": "1300"}, {"price": "0.83", "size": "188.23"}, {"price": "0.8", "size": "900"}, {"price": "0.799", "size": "796"}, {"price": "0.79", "size": "6433.33"}, {"price": "0.789", "size": "1990"}, {"price": "0.788", "size": "5.22"}, {"price": "0.74", "size": "150"}, {"price": "0.73", "size": "50"}, {"price": "0.7", "size": "80"}, {"price": "0.66", "size": "108.82"}, {"price": "0.594", "size": "5"}, {"price": "0.592", "size": "3429"}, {"price": "0.591", "size": "1941"}, {"price": "0.487", "size": "20"}, {"price": "0.479", "size": "30"}, {"price": "0.477", "size": "40"}, {"price": "0.476", "size": "20"}, {"price": "0.315", "size": "18.97"}, {"price": "0.314", "size": "16.03"}, {"price": "0.195", "size": "8.98"}, {"price": "0.191", "size": "399.99"}, {"price": "0.19", "size": "619"}, {"price": "0.179", "size": "178"}, {"price": "0.178", "size": "400"}, {"price": "0.173", "size": "100"}, {"price": "0.165", "size": "65.86"}], "event_type": "book", "last_trade_price": ""}, {"market": "0x960324c7d2db73740836bbd97eec770fcb9b5372e5b46d98b2999fdbbd017f7a", "asset_id": "40004664463047048443131162836045703174545321215871022010023173925320272282862", "timestamp": "1769384402803", "hash": "8876087eb8e13c10fc3168508c9f87401962b88b", "bids": [{"price": "0.001", "size": "143452"}, {"price": "0.002", "size": "3166"}, {"price": "0.003", "size": "7.45"}, {"price": "0.005", "size": "400"}, {"price": "0.006", "size": "9.67"}, {"price": "0.008", "size": "250"}, {"price": "0.01", "size": "400"}, {"price": "0.013", "size": "200"}, {"price": "0.014", "size": "10.12"}, {"price": "0.023", "size": "100"}, {"price": "0.034", "size": "3.87"}, {"price": "0.035", "size": "500"}, {"price": "0.036", "size": "300"}, {"price": "0.037", "size": "300"}, {"price": "0.038", "size": "269.3"}, {"price": "0.039", "size": "30"}, {"price": "0.04", "size": "34.65"}], "asks": [{"price": "0.999", "size": "6104567.27"}, {"price": "0.998", "size": "31257.87"}, {"price": "0.997", "size": "1166"}, {"price": "0.996", "size": "6000"}, {"price": "0.995", "size": "6.23"}, {"price": "0.994", "size": "83"}, {"price": "0.99", "size": "7000"}, {"price": "0.989", "size": "20005.1"}, {"price": "0.98", "size": "3500"}, {"price": "0.979", "size": "20400"}, {"price": "0.978", "size": "12.88"}, {"price": "0.96", "size": "1750"}, {"price": "0.959", "size": "6000"}, {"price": "0.95", "size": "20"}, {"price": "0.949", "size": "39"}, {"price": "0.92", "size": "1250"}, {"price": "0.919", "size": "3200"}, {"price": "0.918", "size": "5.78"}, {"price": "0.9", "size": "360"}, {"price": "0.895", "size": "6000"}, {"price": "0.86", "size": "242.85"}, {"price": "0.85", "size": "1300"}, {"price": "0.81", "size": "168.42"}, {"price": "0.808", "size": "3537"}, {"price": "0.8", "size": "500"}, {"price": "0.798", "size": "900"}, {"price": "0.797", "size": "788"}, {"price": "0.796", "size": "5.56"}, {"price": "0.769", "size": "2300"}, {"price": "0.768", "size": "1810"}, {"price": "0.76", "size": "116.66"}, {"price": "0.71", "size": "189.65"}, {"price": "0.66", "size": "70.58"}, {"price": "0.629", "size": "1050"}, {"price": "0.61", "size": "51.28"}, {"price": "0.569", "size": "1397"}, {"price": "0.568", "size": "607"}, {"price": "0.567", "size": "226"}, {"price": "0.291", "size": "100"}, {"price": "0.289", "size": "30"}, {"price": "0.288", "size": "40"}, {"price": "0.286", "size": "20"}, {"price": "0.285", "size": "45"}, {"price": "0.284", "size": "20"}, {"price": "0.198", "size": "37"}, {"price": "0.187", "size": "100"}, {"price": "0.09", "size": "200"}, {"price": "0.089", "size": "20"}, {"price": "0.083", "size": "23"}], "event_type": "book", "last_trade_price": ""}, {"market": "0xac0e8cc2c1194bd79bfee4d944134a22a470dabf9a44973078931586ec2b4713", "asset_id": "6949439350204552418128687543998149261828101838617755026479239514017283314200", "timestamp": "1769384389753", "hash": "253335d7185238ebd37c384915b686ddd8b3464f", "bids": [{"price": "0.01", "size": "218305.22"}, {"price": "0.02", "size": "18905.06"}, {"price": "0.03", "size": "12000"}, {"price": "0.04", "size": "1755.86"}, {"price": "0.05", "size": "20"}, {"price": "0.06", "size": "33"}, {"price": "0.08", "size": "1250"}, {"price": "0.09", "size": "3605.58"}, {"price": "0.11", "size": "3818"}, {"price": "0.14", "size": "242.85"}, {"price": "0.15", "size": "3300"}, {"price": "0.16", "size": "1400"}, {"price": "0.18", "size": "177.77"}, {"price": "0.2", "size": "500"}, {"price": "0.21", "size": "5.28"}, {"price": "0.23", "size": "121.73"}, {"price": "0.25", "size": "3325"}, {"price": "0.28", "size": "192.85"}, {"price": "0.32", "size": "75"}, {"price": "0.37", "size": "54.05"}, {"price": "0.38", "size": "869"}, {"price": "0.39", "size": "5"}, {"price": "0.45", "size": "20"}, {"price": "0.54", "size": "100"}, {"price": "0.55", "size": "120"}, {"price": "0.65", "size": "120"}, {"price": "0.66", "size": "126"}, {"price": "0.69", "size": "100"}, {"price": "0.7", "size": "20"}, {"price": "0.72", "size": "50"}, {"price": "0.73", "size": "40"}, {"price": "0.74", "size": "20"}, {"price": "0.75", "size": "50"}, {"price": "0.78", "size": "100"}, {"price": "0.86", "size": "20"}, {"price": "0.9", "size": "59.68"}, {"price": "0.91", "size": "29.5"}], "asks": [{"price": "0.99", "size": "1031.24"}, {"price": "0.98", "size": "200"}, {"price": "0.95", "size": "120"}, {"price": "0.93", "size": "921.65"}, {"price": "0.92", "size": "172.92"}], "event_type": "book", "last_trade_price": "0.080"}, {"market": "0xb51d73fb402680d320b8ae1a1450c17c90eb5c5061d7d406c1f86465276adb60", "asset_id": "5798682250465986989350076675203301795837240505688895325567849193712450372007", "timestamp": "1769384431890", "hash": "8f7f9a2bf13c3630f313522df37af00247d537d9", "bids": [{"price": "0.001", "size": "2104272.52"}, {"price": "0.002", "size": "61250"}, {"price": "0.003", "size": "1406.96"}, {"price": "0.006", "size": "200"}, {"price": "0.007", "size": "10.25"}, {"price": "0.01", "size": "7000"}, {"price": "0.011", "size": "20000"}, {"price": "0.02", "size": "3500"}, {"price": "0.021", "size": "13.52"}, {"price": "0.04", "size": "1750"}, {"price": "0.041", "size": "9400"}, {"price": "0.05", "size": "20"}, {"price": "0.051", "size": "39"}, {"price": "0.08", "size": "1250"}, {"price": "0.081", "size": "5.9"}, {"price": "0.088", "size": "12200"}, {"price": "0.09", "size": "400"}, {"price": "0.091", "size": "3296"}, {"price": "0.092", "size": "3282"}, {"price": "0.14", "size": "242.85"}, {"price": "0.15", "size": "1300"}, {"price": "0.151", "size": "2000"}, {"price": "0.19", "size": "168.42"}, {"price": "0.2", "size": "900"}, {"price": "0.202", "size": "3050"}, {"price": "0.203", "size": "788"}, {"price": "0.204", "size": "5.56"}, {"price": "0.23", "size": "221.73"}, {"price": "0.28", "size": "92.85"}, {"price": "0.289", "size": "200"}, {"price": "0.29", "size": "1498"}, {"price": "0.33", "size": "72.72"}, {"price": "0.37", "size": "934.05"}, {"price": "0.387", "size": "5"}, {"price": "0.398", "size": "30"}, {"price": "0.399", "size": "20"}, {"price": "0.742", "size": "244.92"}, {"price": "0.745", "size": "54.82"}, {"price": "0.746", "size": "106.66"}, {"price": "0.748", "size": "3.53"}, {"price": "0.749", "size": "20"}, {"price": "0.823", "size": "66.66"}, {"price": "0.895", "size": "100.25"}, {"price": "0.899", "size": "179"}, {"price": "0.9", "size": "150.17"}, {"price": "0.901", "size": "71.66"}], "asks": [{"price": "0.999", "size": "47945"}, {"price": "0.998", "size": "3522.2"}, {"price": "0.996", "size": "2000"}, {"price": "0.995", "size": "505.64"}, {"price": "0.992", "size": "1000"}, {"price": "0.989", "size": "400"}, {"price": "0.988", "size": "15.13"}, {"price": "0.944", "size": "200"}, {"price": "0.938", "size": "500"}, {"price": "0.937", "size": "300"}, {"price": "0.936", "size": "100"}, {"price": "0.935", "size": "300"}, {"price": "0.934", "size": "200"}, {"price": "0.932", "size": "180"}, {"price": "0.931", "size": "36"}, {"price": "0.93", "size": "42"}], "event_type": "book", "last_trade_price": ""}]}
{"_local_timestamp": "2026-01-25T23:40:40.318395+00:00", "data": {"market": "0xab77a311c7c175ff91707a06dcd358db7a7d7f4258fb7756b05b4f44d175914f", "price_changes": [{"asset_id": "96433559971245993197815501880637705319986922684384749364193086888126378928132", "price": "0.279", "size": "100", "side": "BUY", "hash": "00a4f1b3aaf62b00e9a0ce8b59914e1ebe8e42a5", "best_bid": "0.869", "best_ask": "0.892"}, {"asset_id": "100716705141639838044649900187335811063814165386716787647982371091165872129354", "price": "0.721", "size": "100", "side": "SELL", "hash": "adbf47d8ea8674575285a432a7ea94b5d8d895a7", "best_bid": "0.108", "best_ask": "0.131"}], "timestamp": "1769384440245", "event_type": "price_change"}}
{"_local_timestamp": "2026-01-25T23:40:40.318998+00:00", "data": {"market": "0xb51d73fb402680d320b8ae1a1450c17c90eb5c5061d7d406c1f86465276adb60", "price_changes": [{"asset_id": "5798682250465986989350076675203301795837240505688895325567849193712450372007", "price": "0.289", "size": "150", "side": "BUY", "hash": "e65c5e80bb9efdac8d7be8b21e15f73d6d5ad2fb", "best_bid": "0.901", "best_ask": "0.93"}, {"asset_id": "58858731796442679222989272055454043286056057669744610936854497026401512278651", "price": "0.711", "size": "150", "side": "SELL", "hash": "740e0322dabf7677ad661ad2c906f24687e7c8e8", "best_bid": "0.07", "best_ask": "0.099"}], "timestamp": "1769384440245", "event_type": "price_change"}}
{"_local_timestamp": "2026-01-25T23:40:40.334434+00:00", "data": {"market": "0x326df6a10a6cdd74bdc1ef77906037e90b1f1d6dd1fdcbf6580aea62de094a96", "price_changes": [{"asset_id": "111947356992305187589428447311248216731582641625774563053368133120784997422919", "price": "0.29", "size": "559", "side": "BUY", "hash": "4c3fbe71f8819e83c4205eeab352f89b93b53e19", "best_bid": "0.898", "best_ask": "0.914"}, {"asset_id": "80615165254308476859697533076369001631861513127578482097071314558553613438129", "price": "0.71", "size": "559", "side": "SELL", "hash": "45395568530f9441ebfe89caf2834598137a8012", "best_bid": "0.086", "best_ask": "0.102"}], "timestamp": "1769384440246", "event_type": "price_change"}}
{"_local_timestamp": "2026-01-25T23:40:40.739376+00:00", "data": {"market": "0x326df6a10a6cdd74bdc1ef77906037e90b1f1d6dd1fdcbf6580aea62de094a96", "price_changes": [{"asset_id": "111947356992305187589428447311248216731582641625774563053368133120784997422919", "price": "0.233", "size": "50", "side": "BUY", "hash": "706fb5974f333499db25f321c3ef0741d3bceeb3", "best_bid": "0.898", "best_ask": "0.914"}, {"asset_id": "80615165254308476859697533076369001631861513127578482097071314558553613438129", "price": "0.767", "size": "50", "side": "SELL", "hash": "ea3e453cad08d4c23453dcc55ec7cd09f93aa266", "best_bid": "0.086", "best_ask": "0.102"}], "timestamp": "1769384440574", "event_type": "price_change"}}
{"_local_timestamp": "2026-01-25T23:40:40.746545+00:00", "data": {"market": "0xb51d73fb402680d320b8ae1a1450c17c90eb5c5061d7d406c1f86465276adb60", "price_changes": [{"asset_id": "5798682250465986989350076675203301795837240505688895325567849193712450372007", "price": "0.231", "size": "50", "side": "BUY", "hash": "750b0ec559f9c4e695fc6a7c678852e69d6f2b78", "best_bid": "0.901", "best_ask": "0.93"}, {"asset_id": "58858731796442679222989272055454043286056057669744610936854497026401512278651", "price": "0.769", "size": "50", "side": "SELL", "hash": "40130794a00ce390d3af7d81514604092ecb4c50", "best_bid": "0.07", "best_ask": "0.099"}], "timestamp": "1769384440572", "event_type": "price_change"}}
{"_local_timestamp": "2026-01-25T23:40:40.746989+00:00", "data": {"market": "0xab77a311c7c175ff91707a06dcd358db7a7d7f4258fb7756b05b4f44d175914f", "price_changes": [{"asset_id": "96433559971245993197815501880637705319986922684384749364193086888126378928132", "price": "0.222", "size": "50", "side": "BUY", "hash": "bb9b48a4df4d6b6f79a9db8869d36e16afca1599", "best_bid": "0.869", "best_ask": "0.892"}, {"asset_id": "100716705141639838044649900187335811063814165386716787647982371091165872129354", "price": "0.778", "size": "50", "side": "SELL", "hash": "2dc26fcde5a860f61e0bf5c4b7cf40a19527557f", "best_bid": "0.108", "best_ask": "0.131"}], "timestamp": "1769384440572", "event_type": "price_change"}}
{"_local_timestamp": "2026-01-25T23:40:40.899292+00:00", "data": {"market": "0xfff9fd2422f8e3b878a2701c4eb1e9e182a35d9a71ec2d4233ccd2cac834f887", "price_changes": [{"asset_id": "97579963624866678731903283461280009667266517428659356160462670347995084766428", "price": "0.518", "size": "0", "side": "BUY", "hash": "a3d8febad0de92a7cfeb51fff378eca205526cbc", "best_bid": "0.881", "best_ask": "0.911"}, {"asset_id": "2095798660633756262303834783492337010518543450973961053424376028794255397244", "price": "0.482", "size": "0", "side": "SELL", "hash": "34c4f199a859b480d984fe9b675b700c55084aac", "best_bid": "0.089", "best_ask": "0.119"}], "timestamp": "1769384440790", "event_type": "price_change"}}
{"_local_timestamp": "2026-01-25T23:41:14.635929+00:00", "data": {"market": "0xac0e8cc2c1194bd79bfee4d944134a22a470dabf9a44973078931586ec2b4713", "price_changes": [{"asset_id": "6949439350204552418128687543998149261828101838617755026479239514017283314200", "price": "0.11", "size": "0", "side": "BUY", "hash": "deb9fe8f705a823b5e5707c7df3ac1b693c9bcac", "best_bid": "0.91", "best_ask": "0.92"}, {"asset_id": "7465944841767583018291499747334711307126986423404813304527234412438530575641", "price": "0.89", "size": "0", "side": "SELL", "hash": "6f97c4ad6ecec9e1204063b03520da1a4ac8a250", "best_bid": "0.08", "best_ask": "0.09"}], "timestamp": "1769384474532", "event_type": "price_change"}}
{"_local_timestamp": "2026-01-25T23:41:14.693149+00:00", "data": {"market": "0x326df6a10a6cdd74bdc1ef77906037e90b1f1d6dd1fdcbf6580aea62de094a96", "price_changes": [{"asset_id": "111947356992305187589428447311248216731582641625774563053368133120784997422919", "price": "0.207", "size": "5.43", "side": "BUY", "hash": "5e2e3b1cb0f6d1efe0d5feaa3e6c7a8addb6c44a", "best_bid": "0.898", "best_ask": "0.914"}, {"asset_id": "80615165254308476859697533076369001631861513127578482097071314558553613438129", "price": "0.793", "size": "5.43", "side": "SELL", "hash": "05775eb8a8ffbc63ea350c0d8c7c79596b6388d8", "best_bid": "0.086", "best_ask": "0.102"}], "timestamp": "1769384474535", "event_type": "price_change"}}
{"_local_timestamp": "2026-01-25T23:41:14.711979+00:00", "data": {"market": "0xa32587f6a3b3fa89d71c5648c526fe69791ef6593159e682f1ca5d4dc364f974", "price_changes": [{"asset_id": "54074938701699388770795173053719001491386817666951566814225682866135668313701", "price": "0.241", "size": "300", "side": "BUY", "hash": "f4ac5e8aaf7da9df6a58ed884c64998c184a4675", "best_bid": "0.931", "best_ask": "0.958"}, {"asset_id": "46775328864914034111636027140584666041009849439098120541770590397117980620796", "price": "0.759", "size": "300", "side": "SELL", "hash": "04b7d24fecd4d03342c5410cdfb6d250828b89c5", "best_bid": "0.042", "best_ask": "0.069"}], "timestamp": "1769384474540", "event_type": "price_change"}}
{"_local_timestamp": "2026-01-25T23:41:14.713069+00:00", "data": {"market": "0xab77a311c7c175ff91707a06dcd358db7a7d7f4258fb7756b05b4f44d175914f", "price_changes": [{"asset_id": "96433559971245993197815501880637705319986922684384749364193086888126378928132", "price": "0.208", "size": "5.39", "side": "BUY", "hash": "7c81d65cd644523211e78b6a241ff7f061222100", "best_bid": "0.869", "best_ask": "0.892"}, {"asset_id": "100716705141639838044649900187335811063814165386716787647982371091165872129354", "price": "0.792", "size": "5.39", "side": "SELL", "hash": "602cee5c4746ec823476e84a88825c87cb308b11", "best_bid": "0.108", "best_ask": "0.131"}], "timestamp": "1769384474535", "event_type": "price_change"}}
{"_local_timestamp": "2026-01-25T23:41:14.737077+00:00", "data": {"market": "0xcfaa155abdb4c4447285c3fb08ce11273ad7b648cbc29b26bbc99a5d50a57688", "price_changes": [{"asset_id": "107532164421846439086348783344173461119922836080219299112376014605456903082560", "price": "0.201", "size": "5.6", "side": "BUY", "hash": "5ecc65618d3fd88c08844c13f33103f7b5ebba0c", "best_bid": "0.801", "best_ask": "0.802"}, {"asset_id": "102123833290224736028606807214973577470974985146136880562573223000412048646565", "price": "0.799", "size": "5.6", "side": "SELL", "hash": "c8d854eec4070f25c00f34fc7cf33dc77fe58498", "best_bid": "0.198", "best_ask": "0.199"}], "timestamp": "1769384474537", "event_type": "price_change"}}
{"_local_timestamp": "2026-01-25T23:41:14.750721+00:00", "data": {"market": "0xfff9fd2422f8e3b878a2701c4eb1e9e182a35d9a71ec2d4233ccd2cac834f887", "price_changes": [{"asset_id": "97579963624866678731903283461280009667266517428659356160462670347995084766428", "price": "0.28", "size": "553", "side": "BUY", "hash": "9965b343999de2f302a6e9e62593d078818e1e97", "best_bid": "0.881", "best_ask": "0.911"}, {"asset_id": "2095798660633756262303834783492337010518543450973961053424376028794255397244", "price": "0.72", "size": "553", "side": "SELL", "hash": "6f09254cf4afc62e93e628a704b88e82ed4e3ce4", "best_bid": "0.089", "best_ask": "0.119"}], "timestamp": "1769384474536", "event_type": "price_change"}}
{"_local_timestamp": "2026-01-25T23:41:50.965519+00:00", "data": {"market": "0xab77a311c7c175ff91707a06dcd358db7a7d7f4258fb7756b05b4f44d175914f", "price_changes": [{"asset_id": "96433559971245993197815501880637705319986922684384749364193086888126378928132", "price": "0.279", "size": "0", "side": "BUY", "hash": "40c862ea999b6eb3bf41078486f17d4c80f55b79", "best_bid": "0.869", "best_ask": "0.892"}, {"asset_id": "100716705141639838044649900187335811063814165386716787647982371091165872129354", "price": "0.721", "size": "0", "side": "SELL", "hash": "7e262128c64f453777a7d2d387ebc73142d8d28e", "best_bid": "0.108", "best_ask": "0.131"}], "timestamp": "1769384510774", "event_type": "price_change"}}
{"_local_timestamp": "2026-01-25T23:41:51.150065+00:00", "data": {"market": "0xaca5aedf274be4876eed3441d1cd4c9f5f3908ee2d5dff4c838ba89cd69365d8", "price_changes": [{"asset_id": "82834542816241625492514061227288286309604590623265497797502039631748808662467", "price": "0.513", "size": "0", "side": "BUY", "hash": "840abcee92597c24c1c85db472938c7c92bb5e5a", "best_bid": "0.835", "best_ask": "0.858"}, {"asset_id": "29737896427505913579373080975459102667589461703616780283220419284622020368836", "price": "0.487", "size": "0", "side": "SELL", "hash": "0292a01449ec5d51c19bb1eafd7c480a70ebd4e8", "best_bid": "0.142", "best_ask": "0.165"}], "timestamp": "1769384511066", "event_type": "price_change"}}
{"_local_timestamp": "2026-01-25T23:41:51.318348+00:00", "data": {"market": "0xaca5aedf274be4876eed3441d1cd4c9f5f3908ee2d5dff4c838ba89cd69365d8", "price_changes": [{"asset_id": "82834542816241625492514061227288286309604590623265497797502039631748808662467", "price": "0.525", "size": "20", "side": "BUY", "hash": "7647a3d043d3fdfb6f8b1c88e0cfe1b2aa38953d", "best_bid": "0.835", "best_ask": "0.858"}, {"asset_id": "29737896427505913579373080975459102667589461703616780283220419284622020368836", "price": "0.475", "size": "20", "side": "SELL", "hash": "6bbdbe2aee25a778eec707bbbc687939572fa62a", "best_bid": "0.142", "best_ask": "0.165"}], "timestamp": "1769384511248", "event_type": "price_change"}}
{"_local_timestamp": "2026-01-25T23:41:52.768074+00:00", "data": {"market": "0xab77a311c7c175ff91707a06dcd358db7a7d7f4258fb7756b05b4f44d175914f", "price_changes": [{"asset_id": "96433559971245993197815501880637705319986922684384749364193086888126378928132", "price": "0.28", "size": "510", "side": "BUY", "hash": "8d81f6c533295a6a0c6671ec03bb7d9bf4e57715", "best_bid": "0.869", "best_ask": "0.892"}, {"asset_id": "100716705141639838044649900187335811063814165386716787647982371091165872129354", "price": "0.72", "size": "510", "side": "SELL", "hash": "b52fd521e7164fc9be898ac597658cc37d7b531d", "best_bid": "0.108", "best_ask": "0.131"}], "timestamp": "1769384511771", "event_type": "price_change"}}
{"_local_timestamp": "2026-01-25T23:41:53.311294+00:00", "data": {"market": "0xaca5aedf274be4876eed3441d1cd4c9f5f3908ee2d5dff4c838ba89cd69365d8", "price_changes": [{"asset_id": "82834542816241625492514061227288286309604590623265497797502039631748808662467", "price": "0.524", "size": "0", "side": "BUY", "hash": "70bb18f97d4fbd84c85ae282c5d01caa295c574e", "best_bid": "0.835", "best_ask": "0.858"}, {"asset_id": "29737896427505913579373080975459102667589461703616780283220419284622020368836", "price": "0.476", "size": "0", "side": "SELL", "hash": "05d3bd90ce55e213818c304b05fbbdf2cc009da6", "best_bid": "0.142", "best_ask": "0.165"}], "timestamp": "1769384513178", "event_type": "price_change"}}
{"_local_timestamp": "2026-01-25T23:41:53.311784+00:00", "data": {"market": "0xaca5aedf274be4876eed3441d1cd4c9f5f3908ee2d5dff4c838ba89cd69365d8", "price_changes": [{"asset_id": "82834542816241625492514061227288286309604590623265497797502039631748808662467", "price": "0.526", "size": "20", "side": "BUY", "hash": "09613c1664909544722c7851f76aacede49a23c8", "best_bid": "0.835", "best_ask": "0.858"}, {"asset_id": "29737896427505913579373080975459102667589461703616780283220419284622020368836", "price": "0.474", "size": "20", "side": "SELL", "hash": "adb18147b2aa7cf4d9db1a2040f4ccc445f46928", "best_bid": "0.142", "best_ask": "0.165"}], "timestamp": "1769384513211", "event_type": "price_change"}}
{"_local_timestamp": "2026-01-25T23:41:55.898514+00:00", "data": {"market": "0xa32587f6a3b3fa89d71c5648c526fe69791ef6593159e682f1ca5d4dc364f974", "price_changes": [{"asset_id": "54074938701699388770795173053719001491386817666951566814225682866135668313701", "price": "0.291", "size": "1442", "side": "BUY", "hash": "eb3dbca96069373f3fce0a884d25a451b369e9bb", "best_bid": "0.931", "best_ask": "0.958"}, {"asset_id": "46775328864914034111636027140584666041009849439098120541770590397117980620796", "price": "0.709", "size": "1442", "side": "SELL", "hash": "7a6c038e6cf03e5e75823927f68a34bdb3d2bdff", "best_bid": "0.042", "best_ask": "0.069"}], "timestamp": "1769384515832", "event_type": "price_change"}}
{"_local_timestamp": "2026-01-25T23:41:56.358300+00:00", "data": {"market": "0xcfaa155abdb4c4447285c3fb08ce11273ad7b648cbc29b26bbc99a5d50a57688", "price_changes": [{"asset_id": "107532164421846439086348783344173461119922836080219299112376014605456903082560", "price": "0.241", "size": "1742", "side": "BUY", "hash": "7b4db6c1d974b0090bcb4d456750f4a7539eb7d7", "best_bid": "0.801", "best_ask": "0.802"}, {"asset_id": "102123833290224736028606807214973577470974985146136880562573223000412048646565", "price": "0.759", "size": "1742", "side": "SELL", "hash": "65eeb4b3fecfe2c904722c2a3b12d20961d45762", "best_bid": "0.198", "best_ask": "0.199"}], "timestamp": "1769384516294", "event_type": "price_change"}}
{"_local_timestamp": "2026-01-25T23:41:57.174396+00:00", "data": {"market": "0x326df6a10a6cdd74bdc1ef77906037e90b1f1d6dd1fdcbf6580aea62de094a96", "price_changes": [{"asset_id": "111947356992305187589428447311248216731582641625774563053368133120784997422919", "price": "0.231", "size": "1818", "side": "BUY", "hash": "a88ff14940af3eed2fa8414e4a1f1121950d68a2", "best_bid": "0.898", "best_ask": "0.914"}, {"asset_id": "80615165254308476859697533076369001631861513127578482097071314558553613438129", "price": "0.769", "size": "1818", "side": "SELL", "hash": "5b270e4caba59a68f1d1f3750a622e76d4ecdcd0", "best_bid": "0.086", "best_ask": "0.102"}], "timestamp": "1769384517110", "event_type": "price_change"}}
{"_local_timestamp": "2026-01-25T23:41:57.984859+00:00", "data": {"market": "0xab77a311c7c175ff91707a06dcd358db7a7d7f4258fb7756b05b4f44d175914f", "price_changes": [{"asset_id": "96433559971245993197815501880637705319986922684384749364193086888126378928132", "price": "0.28", "size": "2008", "side": "BUY", "hash": "314c08fc6d8429e39b6b741dd6cbc4c622f114c9", "best_bid": "0.869", "best_ask": "0.892"}, {"asset_id": "100716705141639838044649900187335811063814165386716787647982371091165872129354", "price": "0.72", "size": "2008", "side": "SELL", "hash": "24a8c089279b6dfded87645684985a1ad1032b59", "best_bid": "0.108", "best_ask": "0.131"}], "timestamp": "1769384517920", "event_type": "price_change"}}
{"_local_timestamp": "2026-01-25T23:41:58.712980+00:00", "data": {"market": "0xfff9fd2422f8e3b878a2701c4eb1e9e182a35d9a71ec2d4233ccd2cac834f887", "price_changes": [{"asset_id": "97579963624866678731903283461280009667266517428659356160462670347995084766428", "price": "0.214", "size": "1962", "side": "BUY", "hash": "e174f28257b9c9b9c7898c9953f44e7c49fd9b14", "best_bid": "0.881", "best_ask": "0.911"}, {"asset_id": "2095798660633756262303834783492337010518543450973961053424376028794255397244", "price": "0.786", "size": "1962", "side": "SELL", "hash": "32ef178e788a662d001c7ee58798c18eb9e140cb", "best_bid": "0.089", "best_ask": "0.119"}], "timestamp": "1769384518639", "event_type": "price_change"}}
{"_local_timestamp": "2026-01-25T23:42:03.980989+00:00", "data": {"market": "0xac0e8cc2c1194bd79bfee4d944134a22a470dabf9a44973078931586ec2b4713", "price_changes": [{"asset_id": "6949439350204552418128687543998149261828101838617755026479239514017283314200", "price": "0.1", "size": "4200", "side": "BUY", "hash": "91ea8ae30f7668a17671b53d0e9193c7ba3af7b2", "best_bid": "0.91", "best_ask": "0.92"}, {"asset_id": "7465944841767583018291499747334711307126986423404813304527234412438530575641", "price": "0.9", "size": "4200", "side": "SELL", "hash": "bfa7a3e4491b99840550a98494b0b4fc0d1e5dbe", "best_bid": "0.08", "best_ask": "0.09"}], "timestamp": "1769384523913", "event_type": "price_change"}}
{"_local_timestamp": "2026-01-25T23:42:23.982615+00:00", "data": {"market": "0x960324c7d2db73740836bbd97eec770fcb9b5372e5b46d98b2999fdbbd017f7a", "price_changes": [{"asset_id": "80664742764535144927724195537615142554527026640240245478342373307617044724467", "price": "0.813", "size": "0", "side": "BUY", "hash": "6d30b3ec5271a375da4328371f07001f32f9bb74", "best_bid": "0.917", "best_ask": "0.96"}, {"asset_id": "40004664463047048443131162836045703174545321215871022010023173925320272282862", "price": "0.187", "size": "0", "side": "SELL", "hash": "fbcfceeaa4cdd761ef58a3a3dcb463ab065cec1a", "best_bid": "0.04", "best_ask": "0.083"}], "timestamp": "1769384543878", "event_type": "price_change"}}
{"_local_timestamp": "2026-01-25T23:42:23.985407+00:00", "data": {"market": "0x960324c7d2db73740836bbd97eec770fcb9b5372e5b46d98b2999fdbbd017f7a", "price_changes": [{"asset_id": "80664742764535144927724195537615142554527026640240245478342373307617044724467", "price": "0.709", "size": "0", "side": "BUY", "hash": "6d30b3ec5271a375da4328371f07001f32f9bb74", "best_bid": "0.917", "best_ask": "0.96"}, {"asset_id": "40004664463047048443131162836045703174545321215871022010023173925320272282862", "price": "0.291", "size": "0", "side": "SELL", "hash": "fbcfceeaa4cdd761ef58a3a3dcb463ab065cec1a", "best_bid": "0.04", "best_ask": "0.083"}], "timestamp": "1769384543878", "event_type": "price_change"}}
{"_local_timestamp": "2026-01-25T23:42:24.004119+00:00", "data": {"market": "0x960324c7d2db73740836bbd97eec770fcb9b5372e5b46d98b2999fdbbd017f7a", "price_changes": [{"asset_id": "80664742764535144927724195537615142554527026640240245478342373307617044724467", "price": "0.813", "size": "20", "side": "BUY", "hash": "ccfe1bed1c58923fe4d35850119d43ef6e87882a", "best_bid": "0.917", "best_ask": "0.96"}, {"asset_id": "40004664463047048443131162836045703174545321215871022010023173925320272282862", "price": "0.187", "size": "20", "side": "SELL", "hash": "8f48ddf9fa4d632d6e1e102e46355fafe8727d08", "best_bid": "0.04", "best_ask": "0.083"}], "timestamp": "1769384543903", "event_type": "price_change"}}
{"_local_timestamp": "2026-01-25T23:42:24.004656+00:00", "data": {"market": "0xac0e8cc2c1194bd79bfee4d944134a22a470dabf9a44973078931586ec2b4713", "price_changes": [{"asset_id": "6949439350204552418128687543998149261828101838617755026479239514017283314200", "price": "0.77", "size": "20", "side": "BUY", "hash": "d0990a9ba9e88cba7652c509c9e825fa3358696c", "best_bid": "0.91", "best_ask": "0.92"}, {"asset_id": "7465944841767583018291499747334711307126986423404813304527234412438530575641", "price": "0.23", "size": "20", "side": "SELL", "hash": "24ce1f60cc847ef9432b163ab66bef8c95d2fbc4", "best_bid": "0.08", "best_ask": "0.09"}], "timestamp": "1769384543903", "event_type": "price_change"}}
{"_local_timestamp": "2026-01-25T23:42:24.005029+00:00", "data": {"market": "0x326df6a10a6cdd74bdc1ef77906037e90b1f1d6dd1fdcbf6580aea62de094a96", "price_changes": [{"asset_id": "111947356992305187589428447311248216731582641625774563053368133120784997422919", "price": "0.767", "size": "20", "side": "BUY", "hash": "670e58e0f5e92b2e1a3e3586da7be7330985b1b8", "best_bid": "0.898", "best_ask": "0.914"}, {"asset_id": "80615165254308476859697533076369001631861513127578482097071314558553613438129", "price": "0.233", "size": "20", "side": "SELL", "hash": "7534c0323ac533d0afe93ced5972a8120a92aa31", "best_bid": "0.086", "best_ask": "0.102"}], "timestamp": "1769384543904", "event_type": "price_change"}}
{"_local_timestamp": "2026-01-25T23:42:24.014814+00:00", "data": {"market": "0xb51d73fb402680d320b8ae1a1450c17c90eb5c5061d7d406c1f86465276adb60", "price_changes": [{"asset_id": "5798682250465986989350076675203301795837240505688895325567849193712450372007", "price": "0.783", "size": "20", "side": "BUY", "hash": "d365f6d9ebd0f0cfc2e922a018e0e98c06c742f7", "best_bid": "0.901", "best_ask": "0.93"}, {"asset_id": "58858731796442679222989272055454043286056057669744610936854497026401512278651", "price": "0.217", "size": "20", "side": "SELL", "hash": "03330a15c42ac2faccc72af64d8a4105715f4b60", "best_bid": "0.07", "best_ask": "0.099"}], "timestamp": "1769384543906", "event_type": "price_change"}}
{"_local_timestamp": "2026-01-25T23:42:24.535979+00:00", "data": {"market": "0x326df6a10a6cdd74bdc1ef77906037e90b1f1d6dd1fdcbf6580aea62de094a96", "price_changes": [{"asset_id": "111947356992305187589428447311248216731582641625774563053368133120784997422919", "price": "0.233", "size": "0", "side": "BUY", "hash": "3a8801fa947e61be8ea08edfdb7ac874a6e4ba8a", "best_bid": "0.898", "best_ask": "0.914"}, {"asset_id": "80615165254308476859697533076369001631861513127578482097071314558553613438129", "price": "0.767", "size": "0", "side": "SELL", "hash": "d79ac20679237c280534972c1c1412187d39b594", "best_bid": "0.086", "best_ask": "0.102"}], "timestamp": "1769384544441", "event_type": "price_change"}}
{"_local_timestamp": "2026-01-25T23:42:24.536432+00:00", "data": {"market": "0xab77a311c7c175ff91707a06dcd358db7a7d7f4258fb7756b05b4f44d175914f", "price_changes": [{"asset_id": "96433559971245993197815501880637705319986922684384749364193086888126378928132", "price": "0.222", "size": "0", "side": "BUY", "hash": "44a4a9abdd5fffd40205c77ae23851c94bf02637", "best_bid": "0.869", "best_ask": "0.892"}, {"asset_id": "100716705141639838044649900187335811063814165386716787647982371091165872129354", "price": "0.778", "size": "0", "side": "SELL", "hash": "98278eb54a494ea9633e1073c749d710af33105e", "best_bid": "0.108", "best_ask": "0.131"}], "timestamp": "1769384544441", "event_type": "price_change"}}
{"_local_timestamp": "2026-01-25T23:42:24.536754+00:00", "data": {"market": "0xb51d73fb402680d320b8ae1a1450c17c90eb5c5061d7d406c1f86465276adb60", "price_changes": [{"asset_id": "5798682250465986989350076675203301795837240505688895325567849193712450372007", "price": "0.231", "size": "0", "side": "BUY", "hash": "1309fedca8db5b679ea2fe27b4c2246aeeedc50a", "best_bid": "0.901", "best_ask": "0.93"}, {"asset_id": "58858731796442679222989272055454043286056057669744610936854497026401512278651", "price": "0.769", "size": "0", "side": "SELL", "hash": "90549be81cd19629b93decbacef3ba2868b46340", "best_bid": "0.07", "best_ask": "0.099"}], "timestamp": "1769384544441", "event_type": "price_change"}}
{"_local_timestamp": "2026-01-25T23:42:25.068123+00:00", "data": {"market": "0xb51d73fb402680d320b8ae1a1450c17c90eb5c5061d7d406c1f86465276adb60", "price_changes": [{"asset_id": "5798682250465986989350076675203301795837240505688895325567849193712450372007", "price": "0.29", "size": "1548", "side": "BUY", "hash": "c49e3abf4b8c2f088439351be177ce24756188a9", "best_bid": "0.901", "best_ask": "0.93"}, {"asset_id": "58858731796442679222989272055454043286056057669744610936854497026401512278651", "price": "0.71", "size": "1548", "side": "SELL", "hash": "22418b719911466b4b94c57fb7685f432afffbfd", "best_bid": "0.07", "best_ask": "0.099"}], "timestamp": "1769384544907", "event_type": "price_change"}}
{"_local_timestamp": "2026-01-25T23:42:25.071764+00:00", "data": {"market": "0x326df6a10a6cdd74bdc1ef77906037e90b1f1d6dd1fdcbf6580aea62de094a96", "price_changes": [{"asset_id": "111947356992305187589428447311248216731582641625774563053368133120784997422919", "price": "0.29", "size": "609", "side": "BUY", "hash": "3c8768e48189b611547890f56fcc2f3d8fa95d8d", "best_bid": "0.898", "best_ask": "0.914"}, {"asset_id": "80615165254308476859697533076369001631861513127578482097071314558553613438129", "price": "0.71", "size": "609", "side": "SELL", "hash": "58dbb7bd049d7839bc1f5ffce0a612eff3eed8af", "best_bid": "0.086", "best_ask": "0.102"}], "timestamp": "1769384544907", "event_type": "price_change"}}
{"_local_timestamp": "2026-01-25T23:42:25.075947+00:00", "data": {"market": "0xab77a311c7c175ff91707a06dcd358db7a7d7f4258fb7756b05b4f44d175914f", "price_changes": [{"asset_id": "96433559971245993197815501880637705319986922684384749364193086888126378928132", "price": "0.28", "size": "2058", "side": "BUY", "hash": "d23269fa7637192c49ae9baebf96515affbdbd2c", "best_bid": "0.869", "best_ask": "0.892"}, {"asset_id": "100716705141639838044649900187335811063814165386716787647982371091165872129354", "price": "0.72", "size": "2058", "side": "SELL", "hash": "67531cb29307edde4e8abcdfbfbfd4a8cb0e45b9", "best_bid": "0.108", "best_ask": "0.131"}], "timestamp": "1769384544910", "event_type": "price_change"}}
{"_local_timestamp": "2026-01-25T23:42:25.148207+00:00", "data": {"market": "0x960324c7d2db73740836bbd97eec770fcb9b5372e5b46d98b2999fdbbd017f7a", "price_changes": [{"asset_id": "80664742764535144927724195537615142554527026640240245478342373307617044724467", "price": "0.676", "size": "100", "side": "BUY", "hash": "9e81cd0f4a800a7e3fc68524cce06e42d1c6906b", "best_bid": "0.917", "best_ask": "0.96"}, {"asset_id": "40004664463047048443131162836045703174545321215871022010023173925320272282862", "price": "0.324", "size": "100", "side": "SELL", "hash": "c18e1c24740c4eb661e3f20a31e4554e88289f33", "best_bid": "0.04", "best_ask": "0.083"}], "timestamp": "1769384544965", "event_type": "price_change"}}
{"_local_timestamp": "2026-01-25T23:42:25.149055+00:00", "data": {"market": "0x960324c7d2db73740836bbd97eec770fcb9b5372e5b46d98b2999fdbbd017f7a", "price_changes": [{"asset_id": "80664742764535144927724195537615142554527026640240245478342373307617044724467", "price": "0.434", "size": "100", "side": "BUY", "hash": "7e324bf069b41373e7874ecbacf4327eb9348bd5", "best_bid": "0.917", "best_ask": "0.96"}, {"asset_id": "40004664463047048443131162836045703174545321215871022010023173925320272282862", "price": "0.566", "size": "100", "side": "SELL", "hash": "fc3d8b4c0d48647a21e7128a2bcced5ba9361aa3", "best_bid": "0.04", "best_ask": "0.083"}], "timestamp": "1769384544974", "event_type": "price_change"}}
{"_local_timestamp": "2026-01-25T23:42:44.701132+00:00", "data": {"market": "0xcfaa155abdb4c4447285c3fb08ce11273ad7b648cbc29b26bbc99a5d50a57688", "price_changes": [{"asset_id": "107532164421846439086348783344173461119922836080219299112376014605456903082560", "price": "0.2", "size": "640", "side": "BUY", "hash": "ef44b72ed1094369ad6b638e4a547c0a5b1d6706", "best_bid": "0.801", "best_ask": "0.802"}, {"asset_id": "102123833290224736028606807214973577470974985146136880562573223000412048646565", "price": "0.8", "size": "640", "side": "SELL", "hash": "04e5353ed63135190709e474e8ada9ed1a208a2e", "best_bid": "0.198", "best_ask": "0.199"}], "timestamp": "1769384564589", "event_type": "price_change"}}
{"_local_timestamp": "2026-01-25T23:42:44.701838+00:00", "data": {"market": "0xb51d73fb402680d320b8ae1a1450c17c90eb5c5061d7d406c1f86465276adb60", "price_changes": [{"asset_id": "5798682250465986989350076675203301795837240505688895325567849193712450372007", "price": "0.289", "size": "100", "side": "BUY", "hash": "f64eaba017c222d0d46a426335ea0b1510c590ae", "best_bid": "0.901", "best_ask": "0.93"}, {"asset_id": "58858731796442679222989272055454043286056057669744610936854497026401512278651", "price": "0.711", "size": "100", "side": "SELL", "hash": "5589f6ccfbbc1b226e62d0d583c792824d1f938b", "best_bid": "0.07", "best_ask": "0.099"}], "timestamp": "1769384564589", "event_type": "price_change"}}
{"_local_timestamp": "2026-01-25T23:42:45.783555+00:00", "data": {"market": "0xb51d73fb402680d320b8ae1a1450c17c90eb5c5061d7d406c1f86465276adb60", "price_changes": [{"asset_id": "5798682250465986989350076675203301795837240505688895325567849193712450372007", "price": "0.29", "size": "1598", "side": "BUY", "hash": "6ef38e503db6f97cdb16410142b059ffdbb3030c", "best_bid": "0.901", "best_ask": "0.93"}, {"asset_id": "58858731796442679222989272055454043286056057669744610936854497026401512278651", "price": "0.71", "size": "1598", "side": "SELL", "hash": "969d71b6b12d9ae0696360aa7744d29b0aa470ec", "best_bid": "0.07", "best_ask": "0.099"}], "timestamp": "1769384565608", "event_type": "price_change"}}
{"_local_timestamp": "2026-01-25T23:42:45.784017+00:00", "data": {"market": "0xcfaa155abdb4c4447285c3fb08ce11273ad7b648cbc29b26bbc99a5d50a57688", "price_changes": [{"asset_id": "107532164421846439086348783344173461119922836080219299112376014605456903082560", "price": "0.201", "size": "55.6", "side": "BUY", "hash": "ffb35d942037148e0ecbc42da0f74b227531e2df", "best_bid": "0.801", "best_ask": "0.802"}, {"asset_id": "102123833290224736028606807214973577470974985146136880562573223000412048646565", "price": "0.799", "size": "55.6", "side": "SELL", "hash": "e15163706d578b0c3cb62f4123878ad655acfdfa", "best_bid": "0.198", "best_ask": "0.199"}], "timestamp": "1769384565607", "event_type": "price_change"}}
{"_local_timestamp": "2026-01-25T23:42:47.189421+00:00", "data": {"market": "0xab77a311c7c175ff91707a06dcd358db7a7d7f4258fb7756b05b4f44d175914f", "price_changes": [{"asset_id": "96433559971245993197815501880637705319986922684384749364193086888126378928132", "price": "0.28", "size": "560", "side": "BUY", "hash": "e136e3c719ba1ccd94f592b15e729a111382cf0d", "best_bid": "0.869", "best_ask": "0.892"}, {"asset_id": "100716705141639838044649900187335811063814165386716787647982371091165872129354", "price": "0.72", "size": "560", "side": "SELL", "hash": "f9bf75203c73faa9ccc935c36e51b63d2d287546", "best_bid": "0.108", "best_ask": "0.131"}], "timestamp": "1769384566994", "event_type": "price_change"}}
{"_local_timestamp": "2026-01-25T23:42:58.828210+00:00", "data": {"market": "0xcfaa155abdb4c4447285c3fb08ce11273ad7b648cbc29b26bbc99a5d50a57688", "price_changes": [{"asset_id": "107532164421846439086348783344173461119922836080219299112376014605456903082560", "price": "0.24", "size": "108.33", "side": "BUY", "hash": "4599e57adba9e885a01bab873cf2c4daeefc2167", "best_bid": "0.801", "best_ask": "0.802"}, {"asset_id": "102123833290224736028606807214973577470974985146136880562573223000412048646565", "price": "0.76", "size": "108.33", "side": "SELL", "hash": "52a6ebc618bfb4cfb6096738345cf35955e777d1", "best_bid": "0.198", "best_ask": "0.199"}], "timestamp": "1769384578710", "event_type": "price_change"}}
{"_local_timestamp": "2026-01-25T23:42:58.829022+00:00", "data": {"market": "0x326df6a10a6cdd74bdc1ef77906037e90b1f1d6dd1fdcbf6580aea62de094a96", "price_changes": [{"asset_id": "111947356992305187589428447311248216731582641625774563053368133120784997422919", "price": "0.23", "size": "121.73", "side": "BUY", "hash": "70821aa84535a08be3e67a4b0b361f577cf19de3", "best_bid": "0.898", "best_ask": "0.914"}, {"asset_id": "80615165254308476859697533076369001631861513127578482097071314558553613438129", "price": "0.77", "size": "121.73", "side": "SELL", "hash": "7962566fce0e8019cb1e7477e8cf32ff083b1d12", "best_bid": "0.086", "best_ask": "0.102"}], "timestamp": "1769384578710", "event_type": "price_change"}}
{"_local_timestamp": "2026-01-25T23:42:58.829386+00:00", "data": {"market": "0xa32587f6a3b3fa89d71c5648c526fe69791ef6593159e682f1ca5d4dc364f974", "price_changes": [{"asset_id": "54074938701699388770795173053719001491386817666951566814225682866135668313701", "price": "0.29", "size": "139.65", "side": "BUY", "hash": "e7a66ee8264d230fa0de83c0c730280b1634c3ca", "best_bid": "0.931", "best_ask": "0.958"}, {"asset_id": "46775328864914034111636027140584666041009849439098120541770590397117980620796", "price": "0.71", "size": "139.65", "side": "SELL", "hash": "056532632616c1c71a47cb1f93a6bf579497de71", "best_bid": "0.042", "best_ask": "0.069"}], "timestamp": "1769384578710", "event_type": "price_change"}}
{"_local_timestamp": "2026-01-25T23:42:58.915690+00:00", "data": {"market": "0xb51d73fb402680d320b8ae1a1450c17c90eb5c5061d7d406c1f86465276adb60", "price_changes": [{"asset_id": "5798682250465986989350076675203301795837240505688895325567849193712450372007", "price": "0.749", "size": "0", "side": "BUY", "hash": "7b4a3cd30764e7571d72bf3f1b35bce02574111f", "best_bid": "0.901", "best_ask": "0.93"}, {"asset_id": "58858731796442679222989272055454043286056057669744610936854497026401512278651", "price": "0.251", "size": "0", "side": "SELL", "hash": "756d97c24acc783d4b4cbf43f8296f55f600b43b", "best_bid": "0.07", "best_ask": "0.099"}], "timestamp": "1769384578809", "event_type": "price_change"}}
{"_local_timestamp": "2026-01-25T23:42:58.992958+00:00", "data": {"market": "0xfff9fd2422f8e3b878a2701c4eb1e9e182a35d9a71ec2d4233ccd2cac834f887", "price_changes": [{"asset_id": "97579963624866678731903283461280009667266517428659356160462670347995084766428", "price": "0.52", "size": "0", "side": "BUY", "hash": "fbb0bbf089626343ad34133081976d20c3f48991", "best_bid": "0.881", "best_ask": "0.911"}, {"asset_id": "2095798660633756262303834783492337010518543450973961053424376028794255397244", "price": "0.48", "size": "0", "side": "SELL", "hash": "2afe4775e9e6e99f15a747c0972eb0c321cbaefd", "best_bid": "0.089", "best_ask": "0.119"}], "timestamp": "1769384578885", "event_type": "price_change"}}
{"_local_timestamp": "2026-01-25T23:42:59.041086+00:00", "data": {"market": "0xb51d73fb402680d320b8ae1a1450c17c90eb5c5061d7d406c1f86465276adb60", "price_changes": [{"asset_id": "5798682250465986989350076675203301795837240505688895325567849193712450372007", "price": "0.749", "size": "20", "side": "BUY", "hash": "a02d755ebf968d6859c2dddb6eb07a6bed1b7912", "best_bid": "0.901", "best_ask": "0.93"}, {"asset_id": "58858731796442679222989272055454043286056057669744610936854497026401512278651", "price": "0.251", "size": "20", "side": "SELL", "hash": "6c61f62c4ff200b84a2ee5d406cb69d081daf0bc", "best_bid": "0.07", "best_ask": "0.099"}], "timestamp": "1769384578929", "event_type": "price_change"}}
{"_local_timestamp": "2026-01-25T23:42:59.119421+00:00", "data": {"market": "0xcfaa155abdb4c4447285c3fb08ce11273ad7b648cbc29b26bbc99a5d50a57688", "price_changes": [{"asset_id": "107532164421846439086348783344173461119922836080219299112376014605456903082560", "price": "0.241", "size": "1842", "side": "BUY", "hash": "802538979fc894e62d08f9b51b1f21d3b286490f", "best_bid": "0.801", "best_ask": "0.802"}, {"asset_id": "102123833290224736028606807214973577470974985146136880562573223000412048646565", "price": "0.759", "size": "1842", "side": "SELL", "hash": "03a725c8fb80ee6adffc900de3ada5be1e3505c0", "best_bid": "0.198", "best_ask": "0.199"}], "timestamp": "1769384578987", "event_type": "price_change"}}
{"_local_timestamp": "2026-01-25T23:42:59.119886+00:00", "data": {"market": "0x326df6a10a6cdd74bdc1ef77906037e90b1f1d6dd1fdcbf6580aea62de094a96", "price_changes": [{"asset_id": "111947356992305187589428447311248216731582641625774563053368133120784997422919", "price": "0.231", "size": "1918", "side": "BUY", "hash": "c8ccea6058db3ab976f796200e40a9b606375628", "best_bid": "0.898", "best_ask": "0.914"}, {"asset_id": "80615165254308476859697533076369001631861513127578482097071314558553613438129", "price": "0.769", "size": "1918", "side": "SELL", "hash": "c85e1e3f40156d234b2295ebc84ebe2eb48180b9", "best_bid": "0.086", "best_ask": "0.102"}], "timestamp": "1769384578987", "event_type": "price_change"}}
{"_local_timestamp": "2026-01-25T23:42:59.120291+00:00", "data": {"market": "0xa32587f6a3b3fa89d71c5648c526fe69791ef6593159e682f1ca5d4dc364f974", "price_changes": [{"asset_id": "54074938701699388770795173053719001491386817666951566814225682866135668313701", "price": "0.291", "size": "1492", "side": "BUY", "hash": "b3057d809c26c008b2848961bb506e96f9a25526", "best_bid": "0.931", "best_ask": "0.958"}, {"asset_id": "46775328864914034111636027140584666041009849439098120541770590397117980620796", "price": "0.709", "size": "1492", "side": "SELL", "hash": "810d6b37354fedb4028f5a8410023eb89942c424", "best_bid": "0.042", "best_ask": "0.069"}], "timestamp": "1769384578987", "event_type": "price_change"}}
{"_local_timestamp": "2026-01-25T23:42:59.167021+00:00", "data": {"market": "0xfff9fd2422f8e3b878a2701c4eb1e9e182a35d9a71ec2d4233ccd2cac834f887", "price_changes": [{"asset_id": "97579963624866678731903283461280009667266517428659356160462670347995084766428", "price": "0.525", "size": "30", "side": "BUY", "hash": "4d9291d8aa631bcd5da8f99ad83d7ede5f8aa6e6", "best_bid": "0.881", "best_ask": "0.911"}, {"asset_id": "2095798660633756262303834783492337010518543450973961053424376028794255397244", "price": "0.475", "size": "30", "side": "SELL", "hash": "63df7b0b8d859aebea823b0d90f60d2bc8a09bf7", "best_bid": "0.089", "best_ask": "0.119"}], "timestamp": "1769384579057", "event_type": "price_change"}}
{"_local_timestamp": "2026-01-25T23:42:59.890201+00:00", "data": {"market": "0xfff9fd2422f8e3b878a2701c4eb1e9e182a35d9a71ec2d4233ccd2cac834f887", "price_changes": [{"asset_id": "97579963624866678731903283461280009667266517428659356160462670347995084766428", "price": "0.524", "size": "0", "side": "BUY", "hash": "abd9bfd1c429eec10b205f6c022d4818ad78904e", "best_bid": "0.881", "best_ask": "0.911"}, {"asset_id": "2095798660633756262303834783492337010518543450973961053424376028794255397244", "price": "0.476", "size": "0", "side": "SELL", "hash": "87be08fc19ba622983e094bb7f9687e73ea66c65", "best_bid": "0.089", "best_ask": "0.119"}], "timestamp": "1769384579781", "event_type": "price_change"}}
{"_local_timestamp": "2026-01-25T23:42:59.930645+00:00", "data": {"market": "0xfff9fd2422f8e3b878a2701c4eb1e9e182a35d9a71ec2d4233ccd2cac834f887", "price_changes": [{"asset_id": "97579963624866678731903283461280009667266517428659356160462670347995084766428", "price": "0.526", "size": "20", "side": "BUY", "hash": "c6636f1ce8b9c69ee0767d7d96149f07d403e888", "best_bid": "0.881", "best_ask": "0.911"}, {"asset_id": "2095798660633756262303834783492337010518543450973961053424376028794255397244", "price": "0.474", "size": "20", "side": "SELL", "hash": "d439317051616fdf35e22b8329e079084fa4006d", "best_bid": "0.089", "best_ask": "0.119"}], "timestamp": "1769384579812", "event_type": "price_change"}}
{"_local_timestamp": "2026-01-25T23:43:00.121958+00:00", "data": {"market": "0xab77a311c7c175ff91707a06dcd358db7a7d7f4258fb7756b05b4f44d175914f", "price_changes": [{"asset_id": "96433559971245993197815501880637705319986922684384749364193086888126378928132", "price": "0.861", "size": "100", "side": "BUY", "hash": "64dbe8d9f896d08b732e39de80a92e4a98dba0b3", "best_bid": "0.869", "best_ask": "0.892"}, {"asset_id": "100716705141639838044649900187335811063814165386716787647982371091165872129354", "price": "0.139", "size": "100", "side": "SELL", "hash": "fb07851bc7708d0c6d9f37486ac5e59c18b716b0", "best_bid": "0.108", "best_ask": "0.131"}], "timestamp": "1769384580000", "event_type": "price_change"}}
{"_local_timestamp": "2026-01-25T23:43:00.136855+00:00", "data": {"market": "0xab77a311c7c175ff91707a06dcd358db7a7d7f4258fb7756b05b4f44d175914f", "price_changes": [{"asset_id": "100716705141639838044649900187335811063814165386716787647982371091165872129354", "price": "0.1", "size": "200", "side": "BUY", "hash": "9046583eb8e1df853f039ca849f76fadfeaab552", "best_bid": "0.108", "best_ask": "0.131"}, {"asset_id": "96433559971245993197815501880637705319986922684384749364193086888126378928132", "price": "0.9", "size": "200", "side": "SELL", "hash": "aee6c5b7580bc6d19f5f3b5154d33f480a6b54b6", "best_bid": "0.869", "best_ask": "0.892"}], "timestamp": "1769384580003", "event_type": "price_change"}}
{"_local_timestamp": "2026-01-25T23:43:00.253186+00:00", "data": {"market": "0xab77a311c7c175ff91707a06dcd358db7a7d7f4258fb7756b05b4f44d175914f", "price_changes": [{"asset_id": "96433559971245993197815501880637705319986922684384749364193086888126378928132", "price": "0.861", "size": "0", "side": "BUY", "hash": "95f749fb84072770878219bb77f23cd2a3457539", "best_bid": "0.869", "best_ask": "0.892"}, {"asset_id": "100716705141639838044649900187335811063814165386716787647982371091165872129354", "price": "0.139", "size": "0", "side": "SELL", "hash": "b40ccd624fb2ce04f9b409bf8e9a79bacb1e9764", "best_bid": "0.108", "best_ask": "0.131"}], "timestamp": "1769384580146", "event_type": "price_change"}}
{"_local_timestamp": "2026-01-25T23:43:00.253703+00:00", "data": {"market": "0xab77a311c7c175ff91707a06dcd358db7a7d7f4258fb7756b05b4f44d175914f", "price_changes": [{"asset_id": "100716705141639838044649900187335811063814165386716787647982371091165872129354", "price": "0.1", "size": "100", "side": "BUY", "hash": "d01d3c2bd8b950353fa72b8c8dcbbc2c4e7341c2", "best_bid": "0.108", "best_ask": "0.131"}, {"asset_id": "96433559971245993197815501880637705319986922684384749364193086888126378928132", "price": "0.9", "size": "100", "side": "SELL", "hash": "5af709f55299c7ec59c846d0c25c57511fc493da", "best_bid": "0.869", "best_ask": "0.892"}], "timestamp": "1769384580146", "event_type": "price_change"}}
{"_local_timestamp": "2026-01-25T23:43:00.415558+00:00", "data": {"market": "0xab77a311c7c175ff91707a06dcd358db7a7d7f4258fb7756b05b4f44d175914f", "price_changes": [{"asset_id": "96433559971245993197815501880637705319986922684384749364193086888126378928132", "price": "0.857", "size": "300", "side": "BUY", "hash": "5e6978b594e1021ef1b2d71bb447a88d3cdc26b8", "best_bid": "0.869", "best_ask": "0.892"}, {"asset_id": "100716705141639838044649900187335811063814165386716787647982371091165872129354", "price": "0.143", "size": "300", "side": "SELL", "hash": "25be7597cfd9b51c5502cfba858244ea06236cf8", "best_bid": "0.108", "best_ask": "0.131"}], "timestamp": "1769384580310", "event_type": "price_change"}}
{"_local_timestamp": "2026-01-25T23:43:00.416124+00:00", "data": {"market": "0xab77a311c7c175ff91707a06dcd358db7a7d7f4258fb7756b05b4f44d175914f", "price_changes": [{"asset_id": "100716705141639838044649900187335811063814165386716787647982371091165872129354", "price": "0.1", "size": "200", "side": "BUY", "hash": "778fc7bcfdc0302ceee55e876035bbb80db9561f", "best_bid": "0.108", "best_ask": "0.131"}, {"asset_id": "96433559971245993197815501880637705319986922684384749364193086888126378928132", "price": "0.9", "size": "200", "side": "SELL", "hash": "90704095c48431c9e6c2991a2a113937149c2c20", "best_bid": "0.869", "best_ask": "0.892"}], "timestamp": "1769384580310", "event_type": "price_change"}}
{"_local_timestamp": "2026-01-25T23:43:02.112903+00:00", "data": {"market": "0xcfaa155abdb4c4447285c3fb08ce11273ad7b648cbc29b26bbc99a5d50a57688", "price_changes": [{"asset_id": "102123833290224736028606807214973577470974985146136880562573223000412048646565", "price": "0.179", "size": "0", "side": "BUY", "hash": "26856256af4fd1ad1cfa8780672e712e41b176d6", "best_bid": "0.198", "best_ask": "0.199"}, {"asset_id": "107532164421846439086348783344173461119922836080219299112376014605456903082560", "price": "0.821", "size": "0", "side": "SELL", "hash": "34dc9095a063187ac2b1396c1b5bfc26da054e7d", "best_bid": "0.801", "best_ask": "0.802"}], "timestamp": "1769384582000", "event_type": "price_change"}}
{"_local_timestamp": "2026-01-25T23:43:02.136082+00:00", "data": {"market": "0xcfaa155abdb4c4447285c3fb08ce11273ad7b648cbc29b26bbc99a5d50a57688", "price_changes": [{"asset_id": "107532164421846439086348783344173461119922836080219299112376014605456903082560", "price": "0.782", "size": "0", "side": "BUY", "hash": "7794966b28238215734710562c4fd62ce3a6900d", "best_bid": "0.801", "best_ask": "0.802"}, {"asset_id": "102123833290224736028606807214973577470974985146136880562573223000412048646565", "price": "0.218", "size": "0", "side": "SELL", "hash": "05a0bf1e38e0f30384a788592d5e1a835f3acd56", "best_bid": "0.198", "best_ask": "0.199"}], "timestamp": "1769384582001", "event_type": "price_change"}}
{"_local_timestamp": "2026-01-25T23:43:03.108832+00:00", "data": {"market": "0xaca5aedf274be4876eed3441d1cd4c9f5f3908ee2d5dff4c838ba89cd69365d8", "price_changes": [{"asset_id": "82834542816241625492514061227288286309604590623265497797502039631748808662467", "price": "0.827", "size": "0", "side": "BUY", "hash": "5c18ede4697d838885bf12afb025fba0dbd7bd33", "best_bid": "0.835", "best_ask": "0.858"}, {"asset_id": "29737896427505913579373080975459102667589461703616780283220419284622020368836", "price": "0.173", "size": "0", "side": "SELL", "hash": "f5a301b93fa183df6bf4d26398117465da6cdd21", "best_bid": "0.142", "best_ask": "0.165"}], "timestamp": "1769384583000", "event_type": "price_change"}}
{"_local_timestamp": "2026-01-25T23:43:03.144856+00:00", "data": {"market": "0xaca5aedf274be4876eed3441d1cd4c9f5f3908ee2d5dff4c838ba89cd69365d8", "price_changes": [{"asset_id": "29737896427505913579373080975459102667589461703616780283220419284622020368836", "price": "0.134", "size": "0", "side": "BUY", "hash": "1153c34bc61d79c4f14fa5579cd4e38f938a4c46", "best_bid": "0.142", "best_ask": "0.165"}, {"asset_id": "82834542816241625492514061227288286309604590623265497797502039631748808662467", "price": "0.866", "size": "0", "side": "SELL", "hash": "6fc5cee96ee813cbca0c3ae3a11872ac40fbec48", "best_bid": "0.835", "best_ask": "0.858"}], "timestamp": "1769384583008", "event_type": "price_change"}}
{"_local_timestamp": "2026-01-25T23:43:03.290731+00:00", "data": {"market": "0xaca5aedf274be4876eed3441d1cd4c9f5f3908ee2d5dff4c838ba89cd69365d8", "price_changes": [{"asset_id": "82834542816241625492514061227288286309604590623265497797502039631748808662467", "price": "0.822", "size": "300", "side": "BUY", "hash": "1fcd48cda2b033857540ab82d4c99426fec0e0a1", "best_bid": "0.835", "best_ask": "0.858"}, {"asset_id": "29737896427505913579373080975459102667589461703616780283220419284622020368836", "price": "0.178", "size": "300", "side": "SELL", "hash": "e4c094cc18c511a63c6f698f2caea071d9c0b868", "best_bid": "0.142", "best_ask": "0.165"}], "timestamp": "1769384583193", "event_type": "price_change"}}
{"_local_timestamp": "2026-01-25T23:43:03.291300+00:00", "data": {"market": "0xaca5aedf274be4876eed3441d1cd4c9f5f3908ee2d5dff4c838ba89cd69365d8", "price_changes": [{"asset_id": "29737896427505913579373080975459102667589461703616780283220419284622020368836", "price": "0.14", "size": "731.42", "side": "BUY", "hash": "a06947b61f15509bbebc62a19ccec403bc19e300", "best_bid": "0.142", "best_ask": "0.165"}, {"asset_id": "82834542816241625492514061227288286309604590623265497797502039631748808662467", "price": "0.86", "size": "731.42", "side": "SELL", "hash": "78f6031161b0e729f19604e7ae9d600ae8bcaae0", "best_bid": "0.835", "best_ask": "0.858"}], "timestamp": "1769384583194", "event_type": "price_change"}}
{"_local_timestamp": "2026-01-25T23:43:03.462114+00:00", "data": {"market": "0xaca5aedf274be4876eed3441d1cd4c9f5f3908ee2d5dff4c838ba89cd69365d8", "price_changes": [{"asset_id": "29737896427505913579373080975459102667589461703616780283220419284622020368836", "price": "0.14", "size": "831.42", "side": "BUY", "hash": "1858e028fcd6552c2d7e7be0f88159fe382a68e8", "best_bid": "0.142", "best_ask": "0.165"}, {"asset_id": "82834542816241625492514061227288286309604590623265497797502039631748808662467", "price": "0.86", "size": "831.42", "side": "SELL", "hash": "90973aa93ef2a322a14bba699f98d187db424b43", "best_bid": "0.835", "best_ask": "0.858"}], "timestamp": "1769384583360", "event_type": "price_change"}}
{"_local_timestamp": "2026-01-25T23:43:03.462759+00:00", "data": {"market": "0xaca5aedf274be4876eed3441d1cd4c9f5f3908ee2d5dff4c838ba89cd69365d8", "price_changes": [{"asset_id": "82834542816241625492514061227288286309604590623265497797502039631748808662467", "price": "0.821", "size": "278", "side": "BUY", "hash": "0613e407fca83ea470beb3ca2283448d4b9a60a4", "best_bid": "0.835", "best_ask": "0.858"}, {"asset_id": "29737896427505913579373080975459102667589461703616780283220419284622020368836", "price": "0.179", "size": "278", "side": "SELL", "hash": "82797957fef842d6788023d6adebe6388ab6f92d", "best_bid": "0.142", "best_ask": "0.165"}], "timestamp": "1769384583361", "event_type": "price_change"}}
{"_local_timestamp": "2026-01-25T23:43:03.726459+00:00", "data": {"market": "0xaca5aedf274be4876eed3441d1cd4c9f5f3908ee2d5dff4c838ba89cd69365d8", "price_changes": [{"asset_id": "29737896427505913579373080975459102667589461703616780283220419284622020368836", "price": "0.142", "size": "7.04", "side": "BUY", "hash": "c666f5a39c14c7e4059937f5b84f3b8eaf38725e", "best_bid": "0.142", "best_ask": "0.165"}, {"asset_id": "82834542816241625492514061227288286309604590623265497797502039631748808662467", "price": "0.858", "size": "7.04", "side": "SELL", "hash": "1717d31f474f065357d0ac31b26b7f89787c2479", "best_bid": "0.835", "best_ask": "0.858"}], "timestamp": "1769384583628", "event_type": "price_change"}}
{"_local_timestamp": "2026-01-25T23:43:03.749430+00:00", "data": {"market": "0x960324c7d2db73740836bbd97eec770fcb9b5372e5b46d98b2999fdbbd017f7a", "price_changes": [{"asset_id": "80664742764535144927724195537615142554527026640240245478342373307617044724467", "price": "0.813", "size": "0", "side": "BUY", "hash": "a61d33072da568530ea03e12b4834ce1eccc33bc", "best_bid": "0.917", "best_ask": "0.96"}, {"asset_id": "40004664463047048443131162836045703174545321215871022010023173925320272282862", "price": "0.187", "size": "0", "side": "SELL", "hash": "356d8909c4150e0085a747e79a4f9871217ee178", "best_bid": "0.04", "best_ask": "0.083"}], "timestamp": "1769384583652", "event_type": "price_change"}}
{"_local_timestamp": "2026-01-25T23:43:03.756837+00:00", "data": {"market": "0xb51d73fb402680d320b8ae1a1450c17c90eb5c5061d7d406c1f86465276adb60", "price_changes": [{"asset_id": "5798682250465986989350076675203301795837240505688895325567849193712450372007", "price": "0.783", "size": "0", "side": "BUY", "hash": "f8e72862c0cb5f68572114d5d2093110fa9107b9", "best_bid": "0.901", "best_ask": "0.93"}, {"asset_id": "58858731796442679222989272055454043286056057669744610936854497026401512278651", "price": "0.217", "size": "0", "side": "SELL", "hash": "7e116f64f39a7ffdb1af0926708afe8175ba6512", "best_bid": "0.07", "best_ask": "0.099"}], "timestamp": "1769384583654", "event_type": "price_change"}}
{"_local_timestamp": "2026-01-25T23:43:03.757362+00:00", "data": {"market": "0x326df6a10a6cdd74bdc1ef77906037e90b1f1d6dd1fdcbf6580aea62de094a96", "price_changes": [{"asset_id": "111947356992305187589428447311248216731582641625774563053368133120784997422919", "price": "0.767", "size": "0", "side": "BUY", "hash": "9e3f1e08d4959a77a4dcc25b6a4e98ae0347fc59", "best_bid": "0.898", "best_ask": "0.914"}, {"asset_id": "80615165254308476859697533076369001631861513127578482097071314558553613438129", "price": "0.233", "size": "0", "side": "SELL", "hash": "03ef1e0dce4735aeb900085ad57658148f84b221", "best_bid": "0.086", "best_ask": "0.102"}], "timestamp": "1769384583655", "event_type": "price_change"}}
{"_local_timestamp": "2026-01-25T23:43:03.881097+00:00", "data": {"market": "0x960324c7d2db73740836bbd97eec770fcb9b5372e5b46d98b2999fdbbd017f7a", "price_changes": [{"asset_id": "80664742764535144927724195537615142554527026640240245478342373307617044724467", "price": "0.812", "size": "20", "side": "BUY", "hash": "6430c5b429d7e1e4b46446fac9fa3566861dbd3a", "best_bid": "0.917", "best_ask": "0.96"}, {"asset_id": "40004664463047048443131162836045703174545321215871022010023173925320272282862", "price": "0.188", "size": "20", "side": "SELL", "hash": "ea58c2579d6891fc8859274762f06b46334e4fbb", "best_bid": "0.04", "best_ask": "0.083"}], "timestamp": "1769384583780", "event_type": "price_change"}}
{"_local_timestamp": "2026-01-25T23:43:03.881746+00:00", "data": {"market": "0xb51d73fb402680d320b8ae1a1450c17c90eb5c5061d7d406c1f86465276adb60", "price_changes": [{"asset_id": "5798682250465986989350076675203301795837240505688895325567849193712450372007", "price": "0.782", "size": "20", "side": "BUY", "hash": "51a45e61794ef6f823d78716050f564b36088581", "best_bid": "0.901", "best_ask": "0.93"}, {"asset_id": "58858731796442679222989272055454043286056057669744610936854497026401512278651", "price": "0.218", "size": "20", "side": "SELL", "hash": "17777d7226e41318bebb26ca0598a8cda5e7074d", "best_bid": "0.07", "best_ask": "0.099"}], "timestamp": "1769384583784", "event_type": "price_change"}}
{"_local_timestamp": "2026-01-25T23:43:03.900790+00:00", "data": {"market": "0x326df6a10a6cdd74bdc1ef77906037e90b1f1d6dd1fdcbf6580aea62de094a96", "price_changes": [{"asset_id": "111947356992305187589428447311248216731582641625774563053368133120784997422919", "price": "0.766", "size": "20", "side": "BUY", "hash": "3389a8e8013eaa285981435ace25f905f3380a6f", "best_bid": "0.898", "best_ask": "0.914"}, {"asset_id": "80615165254308476859697533076369001631861513127578482097071314558553613438129", "price": "0.234", "size": "20", "side": "SELL", "hash": "92421491ede30b997923ef99198f2af0f0f44e15", "best_bid": "0.086", "best_ask": "0.102"}], "timestamp": "1769384583802", "event_type": "price_change"}}
{"_local_timestamp": "2026-01-25T23:43:04.119178+00:00", "data": {"market": "0xfff9fd2422f8e3b878a2701c4eb1e9e182a35d9a71ec2d4233ccd2cac834f887", "price_changes": [{"asset_id": "2095798660633756262303834783492337010518543450973961053424376028794255397244", "price": "0.084", "size": "0", "side": "BUY", "hash": "63da01771fc44bcea32cf6ffa0841d75ae8f3bf8", "best_bid": "0.089", "best_ask": "0.119"}, {"asset_id": "97579963624866678731903283461280009667266517428659356160462670347995084766428", "price": "0.916", "size": "0", "side": "SELL", "hash": "fe56cbf5b2e3e9dd3407b6155f1a5eb08be76312", "best_bid": "0.881", "best_ask": "0.911"}], "timestamp": "1769384584004", "event_type": "price_change"}}
{"_local_timestamp": "2026-01-25T23:43:04.125009+00:00", "data": {"market": "0xfff9fd2422f8e3b878a2701c4eb1e9e182a35d9a71ec2d4233ccd2cac834f887", "price_changes": [{"asset_id": "97579963624866678731903283461280009667266517428659356160462670347995084766428", "price": "0.876", "size": "100", "side": "BUY", "hash": "1609167af3bf1e9f2ba2a229fbe663e5d4b2a7b0", "best_bid": "0.881", "best_ask": "0.911"}, {"asset_id": "2095798660633756262303834783492337010518543450973961053424376028794255397244", "price": "0.124", "size": "100", "side": "SELL", "hash": "c9a05014f2c59d3ab29941b8c08ac36f9cc47449", "best_bid": "0.089", "best_ask": "0.119"}], "timestamp": "1769384584006", "event_type": "price_change"}}
{"_local_timestamp": "2026-01-25T23:43:04.215202+00:00", "data": {"market": "0x326df6a10a6cdd74bdc1ef77906037e90b1f1d6dd1fdcbf6580aea62de094a96", "price_changes": [{"asset_id": "111947356992305187589428447311248216731582641625774563053368133120784997422919", "price": "0.718", "size": "13.33", "side": "BUY", "hash": "b37c3864ce64b43f91a481e45759f64fb6d335bd", "best_bid": "0.898", "best_ask": "0.914"}, {"asset_id": "80615165254308476859697533076369001631861513127578482097071314558553613438129", "price": "0.282", "size": "13.33", "side": "SELL", "hash": "7b906f1a1099e3fa1a2c44dfde6d96f8f4ab1695", "best_bid": "0.086", "best_ask": "0.102"}], "timestamp": "1769384584096", "event_type": "price_change"}}
{"_local_timestamp": "2026-01-25T23:43:04.255202+00:00", "data": {"market": "0x326df6a10a6cdd74bdc1ef77906037e90b1f1d6dd1fdcbf6580aea62de094a96", "price_changes": [{"asset_id": "111947356992305187589428447311248216731582641625774563053368133120784997422919", "price": "0.717", "size": "50", "side": "BUY", "hash": "55853db96035c3938bc6aed672fa4a6bee34d931", "best_bid": "0.898", "best_ask": "0.914"}, {"asset_id": "80615165254308476859697533076369001631861513127578482097071314558553613438129", "price": "0.283", "size": "50", "side": "SELL", "hash": "f2bef6237c4bd2e7f84bd0056613a302c91a4107", "best_bid": "0.086", "best_ask": "0.102"}], "timestamp": "1769384584136", "event_type": "price_change"}}
{"_local_timestamp": "2026-01-25T23:43:05.169141+00:00", "data": {"market": "0xfff9fd2422f8e3b878a2701c4eb1e9e182a35d9a71ec2d4233ccd2cac834f887", "price_changes": [{"asset_id": "97579963624866678731903283461280009667266517428659356160462670347995084766428", "price": "0.876", "size": "0", "side": "BUY", "hash": "34c4566d406e14182cb0e0216f5f635558475f55", "best_bid": "0.881", "best_ask": "0.911"}, {"asset_id": "2095798660633756262303834783492337010518543450973961053424376028794255397244", "price": "0.124", "size": "0", "side": "SELL", "hash": "7852adbb939ef771541869a607dc81a023f20000", "best_bid": "0.089", "best_ask": "0.119"}], "timestamp": "1769384585011", "event_type": "price_change"}}
{"_local_timestamp": "2026-01-25T23:43:05.169701+00:00", "data": {"market": "0xfff9fd2422f8e3b878a2701c4eb1e9e182a35d9a71ec2d4233ccd2cac834f887", "price_changes": [{"asset_id": "2095798660633756262303834783492337010518543450973961053424376028794255397244", "price": "0.088", "size": "200", "side": "BUY", "hash": "7def151d09a1382c09c7476df793aec8e1de9e7b", "best_bid": "0.089", "best_ask": "0.119"}, {"asset_id": "97579963624866678731903283461280009667266517428659356160462670347995084766428", "price": "0.912", "size": "200", "side": "SELL", "hash": "c293a40185307c7df0245add2fbc7bc2920c9180", "best_bid": "0.881", "best_ask": "0.911"}], "timestamp": "1769384585012", "event_type": "price_change"}}
{"_local_timestamp": "2026-01-25T23:43:05.372883+00:00", "data": {"market": "0xfff9fd2422f8e3b878a2701c4eb1e9e182a35d9a71ec2d4233ccd2cac834f887", "price_changes": [{"asset_id": "97579963624866678731903283461280009667266517428659356160462670347995084766428", "price": "0.516", "size": "0", "side": "BUY", "hash": "75b68fcbfcaec543b4690ba833107d5b3a21be8b", "best_bid": "0.881", "best_ask": "0.911"}, {"asset_id": "2095798660633756262303834783492337010518543450973961053424376028794255397244", "price": "0.484", "size": "0", "side": "SELL", "hash": "1ce43f96da03b79c579f1e8460dae43085d61891", "best_bid": "0.089", "best_ask": "0.119"}], "timestamp": "1769384585273", "event_type": "price_change"}}
{"_local_timestamp": "2026-01-25T23:43:05.383894+00:00", "data": {"market": "0xfff9fd2422f8e3b878a2701c4eb1e9e182a35d9a71ec2d4233ccd2cac834f887", "price_changes": [{"asset_id": "2095798660633756262303834783492337010518543450973961053424376028794255397244", "price": "0.088", "size": "300", "side": "BUY", "hash": "63946193e303e15655cdc51444da0326fcde587b", "best_bid": "0.089", "best_ask": "0.119"}, {"asset_id": "97579963624866678731903283461280009667266517428659356160462670347995084766428", "price": "0.912", "size": "300", "side": "SELL", "hash": "1bbd4578c6d9b65aeea7c0a46e561e9184f791d2", "best_bid": "0.881", "best_ask": "0.911"}], "timestamp": "1769384585280", "event_type": "price_change"}}
{"_local_timestamp": "2026-01-25T23:43:05.384521+00:00", "data": {"market": "0xfff9fd2422f8e3b878a2701c4eb1e9e182a35d9a71ec2d4233ccd2cac834f887", "price_changes": [{"asset_id": "97579963624866678731903283461280009667266517428659356160462670347995084766428", "price": "0.856", "size": "394.58", "side": "BUY", "hash": "9b6e25a3b8ec727fb1f0ba543cd6c5fa9e3318d3", "best_bid": "0.881", "best_ask": "0.911"}, {"asset_id": "2095798660633756262303834783492337010518543450973961053424376028794255397244", "price": "0.144", "size": "394.58", "side": "SELL", "hash": "410bf266d39c49f33865f6534a8655cf39178b99", "best_bid": "0.089", "best_ask": "0.119"}], "timestamp": "1769384585280", "event_type": "price_change"}}
{"_local_timestamp": "2026-01-25T23:43:05.516796+00:00", "data": {"market": "0xfff9fd2422f8e3b878a2701c4eb1e9e182a35d9a71ec2d4233ccd2cac834f887", "price_changes": [{"asset_id": "97579963624866678731903283461280009667266517428659356160462670347995084766428", "price": "0.527", "size": "364", "side": "BUY", "hash": "3ad4ef5019f082858474aed9bced38fd1d07faff", "best_bid": "0.881", "best_ask": "0.911"}, {"asset_id": "2095798660633756262303834783492337010518543450973961053424376028794255397244", "price": "0.473", "size": "364", "side": "SELL", "hash": "03e809b31cb6060b1392b039efe101082b4f8598", "best_bid": "0.089", "best_ask": "0.119"}], "timestamp": "1769384585415", "event_type": "price_change"}}
{"_local_timestamp": "2026-01-25T23:43:05.517401+00:00", "data": {"market": "0xfff9fd2422f8e3b878a2701c4eb1e9e182a35d9a71ec2d4233ccd2cac834f887", "price_changes": [{"asset_id": "97579963624866678731903283461280009667266517428659356160462670347995084766428", "price": "0.527", "size": "384", "side": "BUY", "hash": "8a8d9810c0ee7844f5f82c25afbbbe03c1637343", "best_bid": "0.881", "best_ask": "0.911"}, {"asset_id": "2095798660633756262303834783492337010518543450973961053424376028794255397244", "price": "0.473", "size": "384", "side": "SELL", "hash": "4afe1611a7ab1a4c087223bed4228103decc87fa", "best_bid": "0.089", "best_ask": "0.119"}], "timestamp": "1769384585416", "event_type": "price_change"}}
{"_local_timestamp": "2026-01-25T23:43:06.321110+00:00", "data": {"market": "0xfff9fd2422f8e3b878a2701c4eb1e9e182a35d9a71ec2d4233ccd2cac834f887", "price_changes": [{"asset_id": "97579963624866678731903283461280009667266517428659356160462670347995084766428", "price": "0.526", "size": "0", "side": "BUY", "hash": "2f534a3b40fcdc80055b70127cd4376b5d0367fe", "best_bid": "0.881", "best_ask": "0.911"}, {"asset_id": "2095798660633756262303834783492337010518543450973961053424376028794255397244", "price": "0.474", "size": "0", "side": "SELL", "hash": "d5e3d04e61ad32c5999d97873942b8f6d4399cc1", "best_bid": "0.089", "best_ask": "0.119"}], "timestamp": "1769384586225", "event_type": "price_change"}}
{"_local_timestamp": "2026-01-25T23:43:06.354896+00:00", "data": {"market": "0xfff9fd2422f8e3b878a2701c4eb1e9e182a35d9a71ec2d4233ccd2cac834f887", "price_changes": [{"asset_id": "97579963624866678731903283461280009667266517428659356160462670347995084766428", "price": "0.528", "size": "20", "side": "BUY", "hash": "3912af22de2c6880bc2bfc1492fb4aadc6981e6c", "best_bid": "0.881", "best_ask": "0.911"}, {"asset_id": "2095798660633756262303834783492337010518543450973961053424376028794255397244", "price": "0.472", "size": "20", "side": "SELL", "hash": "532c372eacd11a867da2b7ecf8eb6f0bc241bb30", "best_bid": "0.089", "best_ask": "0.119"}], "timestamp": "1769384586258", "event_type": "price_change"}}
{"_local_timestamp": "2026-01-25T23:43:25.768973+00:00", "data": {"market": "0x326df6a10a6cdd74bdc1ef77906037e90b1f1d6dd1fdcbf6580aea62de094a96", "price_changes": [{"asset_id": "80615165254308476859697533076369001631861513127578482097071314558553613438129", "price": "0.05", "size": "121", "side": "BUY", "hash": "93c5f30278a638e3747fca8a59c885a42f54bbde", "best_bid": "0.086", "best_ask": "0.102"}, {"asset_id": "111947356992305187589428447311248216731582641625774563053368133120784997422919", "price": "0.95", "size": "121", "side": "SELL", "hash": "40adbac841bfe61bfa16e58126b2f28f57baeaf7", "best_bid": "0.898", "best_ask": "0.914"}], "timestamp": "1769384605623", "event_type": "price_change"}}
{"_local_timestamp": "2026-01-25T23:43:35.366095+00:00", "data": {"market": "0xab77a311c7c175ff91707a06dcd358db7a7d7f4258fb7756b05b4f44d175914f", "price_changes": [{"asset_id": "96433559971245993197815501880637705319986922684384749364193086888126378928132", "price": "0.221", "size": "1900", "side": "BUY", "hash": "86781028c7009d74f07f76abad479d035cfe4b39", "best_bid": "0.869", "best_ask": "0.892"}, {"asset_id": "100716705141639838044649900187335811063814165386716787647982371091165872129354", "price": "0.779", "size": "1900", "side": "SELL", "hash": "8834e555cce70eb4a7d05a56a30c0eb813d7a9fb", "best_bid": "0.108", "best_ask": "0.131"}], "timestamp": "1769384615245", "event_type": "price_change"}}
{"_local_timestamp": "2026-01-25T23:44:05.338273+00:00", "data": {"market": "0xaca5aedf274be4876eed3441d1cd4c9f5f3908ee2d5dff4c838ba89cd69365d8", "price_changes": [{"asset_id": "29737896427505913579373080975459102667589461703616780283220419284622020368836", "price": "0.127", "size": "0", "side": "BUY", "hash": "7a9a367efc4e94f0503ed38afd8953a2965d5912", "best_bid": "0.142", "best_ask": "0.165"}, {"asset_id": "82834542816241625492514061227288286309604590623265497797502039631748808662467", "price": "0.873", "size": "0", "side": "SELL", "hash": "a29cdc36e39c5f7f66f45ab750235c2201ceef15", "best_bid": "0.835", "best_ask": "0.858"}], "timestamp": "1769384645195", "event_type": "price_change"}}
{"_local_timestamp": "2026-01-25T23:44:05.482143+00:00", "data": {"market": "0x326df6a10a6cdd74bdc1ef77906037e90b1f1d6dd1fdcbf6580aea62de094a96", "price_changes": [{"asset_id": "111947356992305187589428447311248216731582641625774563053368133120784997422919", "price": "0.29", "size": "250", "side": "BUY", "hash": "e8cf0d2f4c9bd1163106a7e4113011874d8212ff", "best_bid": "0.898", "best_ask": "0.914"}, {"asset_id": "80615165254308476859697533076369001631861513127578482097071314558553613438129", "price": "0.71", "size": "250", "side": "SELL", "hash": "018336f1c6d9f0d9f54d150bfa772de1b1c995a0", "best_bid": "0.086", "best_ask": "0.102"}], "timestamp": "1769384645342", "event_type": "price_change"}}
{"_local_timestamp": "2026-01-25T23:44:05.482844+00:00", "data": {"market": "0xab77a311c7c175ff91707a06dcd358db7a7d7f4258fb7756b05b4f44d175914f", "price_changes": [{"asset_id": "96433559971245993197815501880637705319986922684384749364193086888126378928132", "price": "0.28", "size": "250", "side": "BUY", "hash": "1da4264fe41ae0d69bbafb789749b28af5bd87b8", "best_bid": "0.869", "best_ask": "0.892"}, {"asset_id": "100716705141639838044649900187335811063814165386716787647982371091165872129354", "price": "0.72", "size": "250", "side": "SELL", "hash": "f629b63e3b969696fb4fe662e14d4ad137e3d5ff", "best_bid": "0.108", "best_ask": "0.131"}], "timestamp": "1769384645342", "event_type": "price_change"}}
{"_local_timestamp": "2026-01-25T23:44:05.623364+00:00", "data": {"market": "0x960324c7d2db73740836bbd97eec770fcb9b5372e5b46d98b2999fdbbd017f7a", "price_changes": [{"asset_id": "80664742764535144927724195537615142554527026640240245478342373307617044724467", "price": "0.715", "size": "25", "side": "BUY", "hash": "2161f37e9eb2f8c5395d0b19fa4fb2c95d5eca34", "best_bid": "0.917", "best_ask": "0.96"}, {"asset_id": "40004664463047048443131162836045703174545321215871022010023173925320272282862", "price": "0.285", "size": "25", "side": "SELL", "hash": "7234a87a4a5f8c7e2d6f4a938dd01dd3bc8db993", "best_bid": "0.04", "best_ask": "0.083"}], "timestamp": "1769384645486", "event_type": "price_change"}}
{"_local_timestamp": "2026-01-25T23:44:06.097816+00:00", "data": {"market": "0xaca5aedf274be4876eed3441d1cd4c9f5f3908ee2d5dff4c838ba89cd69365d8", "price_changes": [{"asset_id": "82834542816241625492514061227288286309604590623265497797502039631748808662467", "price": "0.822", "size": "100", "side": "BUY", "hash": "c50ede3b193e341bc704199b8524103885f70230", "best_bid": "0.835", "best_ask": "0.858"}, {"asset_id": "29737896427505913579373080975459102667589461703616780283220419284622020368836", "price": "0.178", "size": "100", "side": "SELL", "hash": "e5277249c98594943bd4383e61afe8d89e330e26", "best_bid": "0.142", "best_ask": "0.165"}], "timestamp": "1769384645947", "event_type": "price_change"}}
{"_local_timestamp": "2026-01-25T23:44:07.334832+00:00", "data": {"market": "0xaca5aedf274be4876eed3441d1cd4c9f5f3908ee2d5dff4c838ba89cd69365d8", "price_changes": [{"asset_id": "29737896427505913579373080975459102667589461703616780283220419284622020368836", "price": "0.129", "size": "516.27", "side": "BUY", "hash": "5f7d66e16def9b707f6649bfd47f0362266fe033", "best_bid": "0.142", "best_ask": "0.165"}, {"asset_id": "82834542816241625492514061227288286309604590623265497797502039631748808662467", "price": "0.871", "size": "516.27", "side": "SELL", "hash": "c59db4ddb67edb16d8e3bb32e4a2b7d3e9446015", "best_bid": "0.835", "best_ask": "0.858"}], "timestamp": "1769384647187", "event_type": "price_change"}}
{"_local_timestamp": "2026-01-25T23:44:07.335532+00:00", "data": {"market": "0xaca5aedf274be4876eed3441d1cd4c9f5f3908ee2d5dff4c838ba89cd69365d8", "price_changes": [{"asset_id": "82834542816241625492514061227288286309604590623265497797502039631748808662467", "price": "0.82", "size": "200", "side": "BUY", "hash": "a015c07b9d1a531f1b105834b546b13d527e547f", "best_bid": "0.835", "best_ask": "0.858"}, {"asset_id": "29737896427505913579373080975459102667589461703616780283220419284622020368836", "price": "0.18", "size": "200", "side": "SELL", "hash": "03ce713eb1a37789f15738826926f882e2a20b0b", "best_bid": "0.142", "best_ask": "0.165"}], "timestamp": "1769384647187", "event_type": "price_change"}}
{"_local_timestamp": "2026-01-25T23:44:07.466827+00:00", "data": {"market": "0xab77a311c7c175ff91707a06dcd358db7a7d7f4258fb7756b05b4f44d175914f", "price_changes": [{"asset_id": "96433559971245993197815501880637705319986922684384749364193086888126378928132", "price": "0.28", "size": "360", "side": "BUY", "hash": "9463af47d0677760e6bf46a33a149e2eadb32594", "best_bid": "0.869", "best_ask": "0.892"}, {"asset_id": "100716705141639838044649900187335811063814165386716787647982371091165872129354", "price": "0.72", "size": "360", "side": "SELL", "hash": "022f45fb4c2d4a3ded222477386de589f253d0fe", "best_bid": "0.108", "best_ask": "0.131"}], "timestamp": "1769384647317", "event_type": "price_change"}}
{"_local_timestamp": "2026-01-25T23:44:07.467436+00:00", "data": {"market": "0x326df6a10a6cdd74bdc1ef77906037e90b1f1d6dd1fdcbf6580aea62de094a96", "price_changes": [{"asset_id": "111947356992305187589428447311248216731582641625774563053368133120784997422919", "price": "0.27", "size": "226.29", "side": "BUY", "hash": "adfe234f5af65ddcae3942281a3ff29341c3cb16", "best_bid": "0.898", "best_ask": "0.914"}, {"asset_id": "80615165254308476859697533076369001631861513127578482097071314558553613438129", "price": "0.73", "size": "226.29", "side": "SELL", "hash": "342cd2d2fce872777a44c272a00a0c9147c6c075", "best_bid": "0.086", "best_ask": "0.102"}], "timestamp": "1769384647317", "event_type": "price_change"}}
{"_local_timestamp": "2026-01-25T23:44:08.440871+00:00", "data": {"market": "0x326df6a10a6cdd74bdc1ef77906037e90b1f1d6dd1fdcbf6580aea62de094a96", "price_changes": [{"asset_id": "111947356992305187589428447311248216731582641625774563053368133120784997422919", "price": "0.29", "size": "200", "side": "BUY", "hash": "0782e18c95aca4ffe757098d8a4353b244e11230", "best_bid": "0.898", "best_ask": "0.914"}, {"asset_id": "80615165254308476859697533076369001631861513127578482097071314558553613438129", "price": "0.71", "size": "200", "side": "SELL", "hash": "6602f586a87f9118e4c8be32098c0d491660bf23", "best_bid": "0.086", "best_ask": "0.102"}], "timestamp": "1769384648227", "event_type": "price_change"}}
{"_local_timestamp": "2026-01-25T23:44:08.441792+00:00", "data": {"market": "0xa32587f6a3b3fa89d71c5648c526fe69791ef6593159e682f1ca5d4dc364f974", "price_changes": [{"asset_id": "54074938701699388770795173053719001491386817666951566814225682866135668313701", "price": "0.241", "size": "250", "side": "BUY", "hash": "976380ef44658c318e61e4cb4f3d6fcdd90195f2", "best_bid": "0.931", "best_ask": "0.958"}, {"asset_id": "46775328864914034111636027140584666041009849439098120541770590397117980620796", "price": "0.759", "size": "250", "side": "SELL", "hash": "b8ac418ff7d24605346171ec6e8ef4891c4d99be", "best_bid": "0.042", "best_ask": "0.069"}], "timestamp": "1769384648227", "event_type": "price_change"}}
{"_local_timestamp": "2026-01-25T23:44:08.762588+00:00", "data": {"market": "0xab77a311c7c175ff91707a06dcd358db7a7d7f4258fb7756b05b4f44d175914f", "price_changes": [{"asset_id": "96433559971245993197815501880637705319986922684384749364193086888126378928132", "price": "0.468", "size": "0", "side": "BUY", "hash": "0dc0ca3e65959c52abcc054e251519046c3322e8", "best_bid": "0.869", "best_ask": "0.892"}, {"asset_id": "100716705141639838044649900187335811063814165386716787647982371091165872129354", "price": "0.532", "size": "0", "side": "SELL", "hash": "68baa9a648b2cfe62b439ee85ac56dc4832b2a54", "best_bid": "0.108", "best_ask": "0.131"}], "timestamp": "1769384648444", "event_type": "price_change"}}
{"_local_timestamp": "2026-01-25T23:44:08.763191+00:00", "data": {"market": "0xfff9fd2422f8e3b878a2701c4eb1e9e182a35d9a71ec2d4233ccd2cac834f887", "price_changes": [{"asset_id": "97579963624866678731903283461280009667266517428659356160462670347995084766428", "price": "0.522", "size": "26.66", "side": "BUY", "hash": "37d65328fa76d4182da889987525489971f5e3ea", "best_bid": "0.881", "best_ask": "0.911"}, {"asset_id": "2095798660633756262303834783492337010518543450973961053424376028794255397244", "price": "0.478", "size": "26.66", "side": "SELL", "hash": "8f1e5432b8ac5365bbf5f17b6d59f5b06f774260", "best_bid": "0.089", "best_ask": "0.119"}], "timestamp": "1769384648444", "event_type": "price_change"}}
{"_local_timestamp": "2026-01-25T23:44:08.969969+00:00", "data": {"market": "0x960324c7d2db73740836bbd97eec770fcb9b5372e5b46d98b2999fdbbd017f7a", "price_changes": [{"asset_id": "80664742764535144927724195537615142554527026640240245478342373307617044724467", "price": "0.715", "size": "0", "side": "BUY", "hash": "35b8559c4bbd4657a6ea4f1c031196f2770d3b54", "best_bid": "0.917", "best_ask": "0.96"}, {"asset_id": "40004664463047048443131162836045703174545321215871022010023173925320272282862", "price": "0.285", "size": "0", "side": "SELL", "hash": "13eda415281e283ee9f5574d874405c8c7a85cf1", "best_bid": "0.04", "best_ask": "0.083"}], "timestamp": "1769384648720", "event_type": "price_change"}}
{"_local_timestamp": "2026-01-25T23:44:08.985918+00:00", "data": {"market": "0xab77a311c7c175ff91707a06dcd358db7a7d7f4258fb7756b05b4f44d175914f", "price_changes": [{"asset_id": "96433559971245993197815501880637705319986922684384749364193086888126378928132", "price": "0.474", "size": "40", "side": "BUY", "hash": "ce1c1eaaaac28823068eec6c8618580af09e3afd", "best_bid": "0.869", "best_ask": "0.892"}, {"asset_id": "100716705141639838044649900187335811063814165386716787647982371091165872129354", "price": "0.526", "size": "40", "side": "SELL", "hash": "c1cc0d769c0a70f95a9a0508b27d437bb26f98d0", "best_bid": "0.108", "best_ask": "0.131"}], "timestamp": "1769384648763", "event_type": "price_change"}}
{"_local_timestamp": "2026-01-25T23:44:08.993176+00:00", "data": {"market": "0xfff9fd2422f8e3b878a2701c4eb1e9e182a35d9a71ec2d4233ccd2cac834f887", "price_changes": [{"asset_id": "97579963624866678731903283461280009667266517428659356160462670347995084766428", "price": "0.529", "size": "40", "side": "BUY", "hash": "1cde7aa1bfb004d4e0096789520799379d0f0921", "best_bid": "0.881", "best_ask": "0.911"}, {"asset_id": "2095798660633756262303834783492337010518543450973961053424376028794255397244", "price": "0.471", "size": "40", "side": "SELL", "hash": "7d80de4c8676ad78d114d64d1c1c41094decf2ad", "best_bid": "0.089", "best_ask": "0.119"}], "timestamp": "1769384648763", "event_type": "price_change"}}
{"_local_timestamp": "2026-01-25T23:44:09.025707+00:00", "data": {"market": "0x326df6a10a6cdd74bdc1ef77906037e90b1f1d6dd1fdcbf6580aea62de094a96", "price_changes": [{"asset_id": "111947356992305187589428447311248216731582641625774563053368133120784997422919", "price": "0.231", "size": "1968", "side": "BUY", "hash": "3395fe674530485d5173763fd6d98095a1dead00", "best_bid": "0.898", "best_ask": "0.914"}, {"asset_id": "80615165254308476859697533076369001631861513127578482097071314558553613438129", "price": "0.769", "size": "1968", "side": "SELL", "hash": "3d79aa6c95d6197c516d6aac94c46e985169bce9", "best_bid": "0.086", "best_ask": "0.102"}], "timestamp": "1769384648723", "event_type": "price_change"}}
{"_local_timestamp": "2026-01-25T23:44:09.041769+00:00", "data": {"market": "0xa32587f6a3b3fa89d71c5648c526fe69791ef6593159e682f1ca5d4dc364f974", "price_changes": [{"asset_id": "54074938701699388770795173053719001491386817666951566814225682866135668313701", "price": "0.291", "size": "1542", "side": "BUY", "hash": "44c0bdd4f7a23c591d893ba8129686357ee80d05", "best_bid": "0.931", "best_ask": "0.958"}, {"asset_id": "46775328864914034111636027140584666041009849439098120541770590397117980620796", "price": "0.709", "size": "1542", "side": "SELL", "hash": "5fe20123aa065cd46ad71e2e17640bcbb0583ae3", "best_bid": "0.042", "best_ask": "0.069"}], "timestamp": "1769384648725", "event_type": "price_change"}}
{"_local_timestamp": "2026-01-25T23:44:09.369790+00:00", "data": {"market": "0xab77a311c7c175ff91707a06dcd358db7a7d7f4258fb7756b05b4f44d175914f", "price_changes": [{"asset_id": "96433559971245993197815501880637705319986922684384749364193086888126378928132", "price": "0.473", "size": "0", "side": "BUY", "hash": "aa0fd514ca2064c4ce195a3dace848105c68f70e", "best_bid": "0.869", "best_ask": "0.892"}, {"asset_id": "100716705141639838044649900187335811063814165386716787647982371091165872129354", "price": "0.527", "size": "0", "side": "SELL", "hash": "cc1d420ffa06115c163bc08aa1dca440c6a9f9fc", "best_bid": "0.108", "best_ask": "0.131"}], "timestamp": "1769384649218", "event_type": "price_change"}}
{"_local_timestamp": "2026-01-25T23:44:09.370403+00:00", "data": {"market": "0x960324c7d2db73740836bbd97eec770fcb9b5372e5b46d98b2999fdbbd017f7a", "price_changes": [{"asset_id": "80664742764535144927724195537615142554527026640240245478342373307617044724467", "price": "0.716", "size": "0", "side": "BUY", "hash": "98aed22a18ea6eb4e9f0f3b9241f66a6b83a9b48", "best_bid": "0.917", "best_ask": "0.96"}, {"asset_id": "40004664463047048443131162836045703174545321215871022010023173925320272282862", "price": "0.284", "size": "0", "side": "SELL", "hash": "3a73090db9553af59add64b71b0571bbc1946ca5", "best_bid": "0.04", "best_ask": "0.083"}], "timestamp": "1769384649218", "event_type": "price_change"}}
{"_local_timestamp": "2026-01-25T23:44:09.370939+00:00", "data": {"market": "0xfff9fd2422f8e3b878a2701c4eb1e9e182a35d9a71ec2d4233ccd2cac834f887", "price_changes": [{"asset_id": "97579963624866678731903283461280009667266517428659356160462670347995084766428", "price": "0.528", "size": "0", "side": "BUY", "hash": "b6a7092c71f23c0262fee7f4e82592009c59deed", "best_bid": "0.881", "best_ask": "0.911"}, {"asset_id": "2095798660633756262303834783492337010518543450973961053424376028794255397244", "price": "0.472", "size": "0", "side": "SELL", "hash": "1311f00fc3b324c09cae84de338b5bbf4e884a13", "best_bid": "0.089", "best_ask": "0.119"}], "timestamp": "1769384649218", "event_type": "price_change"}}
{"_local_timestamp": "2026-01-25T23:44:09.390422+00:00", "data": {"market": "0xab77a311c7c175ff91707a06dcd358db7a7d7f4258fb7756b05b4f44d175914f", "price_changes": [{"asset_id": "96433559971245993197815501880637705319986922684384749364193086888126378928132", "price": "0.475", "size": "20", "side": "BUY", "hash": "70a5b7e92265797500ec7236be729b5f54a6e068", "best_bid": "0.869", "best_ask": "0.892"}, {"asset_id": "100716705141639838044649900187335811063814165386716787647982371091165872129354", "price": "0.525", "size": "20", "side": "SELL", "hash": "b6cb33509bc0335cdb2d3da3b2c37751a6021148", "best_bid": "0.108", "best_ask": "0.131"}], "timestamp": "1769384649251", "event_type": "price_change"}}
{"_local_timestamp": "2026-01-25T23:44:09.391054+00:00", "data": {"market": "0xfff9fd2422f8e3b878a2701c4eb1e9e182a35d9a71ec2d4233ccd2cac834f887", "price_changes": [{"asset_id": "97579963624866678731903283461280009667266517428659356160462670347995084766428", "price": "0.53", "size": "20", "side": "BUY", "hash": "8cc52130c34e871338609bb37c6e4beb3c3b2143", "best_bid": "0.881", "best_ask": "0.911"}, {"asset_id": "2095798660633756262303834783492337010518543450973961053424376028794255397244", "price": "0.47", "size": "20", "side": "SELL", "hash": "da9e9dc4bb62262d4d3505a50d9a9a4d8df40193", "best_bid": "0.089", "best_ask": "0.119"}], "timestamp": "1769384649251", "event_type": "price_change"}}
{"_local_timestamp": "2026-01-25T23:44:09.393704+00:00", "data": {"market": "0x960324c7d2db73740836bbd97eec770fcb9b5372e5b46d98b2999fdbbd017f7a", "price_changes": [{"asset_id": "80664742764535144927724195537615142554527026640240245478342373307617044724467", "price": "0.715", "size": "20", "side": "BUY", "hash": "9c08a3da6eea182fee714dd57442aae26b33f31e", "best_bid": "0.917", "best_ask": "0.96"}, {"asset_id": "40004664463047048443131162836045703174545321215871022010023173925320272282862", "price": "0.285", "size": "20", "side": "SELL", "hash": "182f60e5d110e8355e5c9c57b9f550af4ef2472f", "best_bid": "0.04", "best_ask": "0.083"}], "timestamp": "1769384649252", "event_type": "price_change"}}
{"_local_timestamp": "2026-01-25T23:44:18.195808+00:00", "data": {"market": "0xab77a311c7c175ff91707a06dcd358db7a7d7f4258fb7756b05b4f44d175914f", "price_changes": [{"asset_id": "96433559971245993197815501880637705319986922684384749364193086888126378928132", "price": "0.22", "size": "127.27", "side": "BUY", "hash": "5a2728a1dd4f42db0b77022b96f52808b3c7cc44", "best_bid": "0.869", "best_ask": "0.892"}, {"asset_id": "100716705141639838044649900187335811063814165386716787647982371091165872129354", "price": "0.78", "size": "127.27", "side": "SELL", "hash": "8bbb58ea7e19d6daff83a67ea7cd7edfa78ae09e", "best_bid": "0.108", "best_ask": "0.131"}], "timestamp": "1769384657928", "event_type": "price_change"}}
{"_local_timestamp": "2026-01-25T23:44:18.344180+00:00", "data": {"market": "0xcfaa155abdb4c4447285c3fb08ce11273ad7b648cbc29b26bbc99a5d50a57688", "price_changes": [{"asset_id": "107532164421846439086348783344173461119922836080219299112376014605456903082560", "price": "0.604", "size": "0", "side": "BUY", "hash": "04b8f4adccdbe6ce927f71004483315a25b1a41f", "best_bid": "0.801", "best_ask": "0.802"}, {"asset_id": "102123833290224736028606807214973577470974985146136880562573223000412048646565", "price": "0.396", "size": "0", "side": "SELL", "hash": "0648e36ec1140229b8b3508d2f76a5c8c49b6b38", "best_bid": "0.198", "best_ask": "0.199"}], "timestamp": "1769384658098", "event_type": "price_change"}}
{"_local_timestamp": "2026-01-25T23:44:18.444475+00:00", "data": {"market": "0xab77a311c7c175ff91707a06dcd358db7a7d7f4258fb7756b05b4f44d175914f", "price_changes": [{"asset_id": "96433559971245993197815501880637705319986922684384749364193086888126378928132", "price": "0.221", "size": "2000", "side": "BUY", "hash": "38d9cfbdfd0339e5d0250ba7f61c13b2bee10d22", "best_bid": "0.869", "best_ask": "0.892"}, {"asset_id": "100716705141639838044649900187335811063814165386716787647982371091165872129354", "price": "0.779", "size": "2000", "side": "SELL", "hash": "3b8eb2d27a636024bc031d6504893e24b9b11f0d", "best_bid": "0.108", "best_ask": "0.131"}], "timestamp": "1769384658189", "event_type": "price_change"}}
{"_local_timestamp": "2026-01-25T23:44:18.482993+00:00", "data": {"market": "0xcfaa155abdb4c4447285c3fb08ce11273ad7b648cbc29b26bbc99a5d50a57688", "price_changes": [{"asset_id": "107532164421846439086348783344173461119922836080219299112376014605456903082560", "price": "0.609", "size": "20", "side": "BUY", "hash": "05dc9005c4eda5f5cded40c0478a0e03da354af7", "best_bid": "0.801", "best_ask": "0.802"}, {"asset_id": "102123833290224736028606807214973577470974985146136880562573223000412048646565", "price": "0.391", "size": "20", "side": "SELL", "hash": "fdb3e52c2a6ec680653e711031d4fa844f65246f", "best_bid": "0.198", "best_ask": "0.199"}], "timestamp": "1769384658242", "event_type": "price_change"}}
{"_local_timestamp": "2026-01-25T23:44:19.983661+00:00", "data": {"market": "0xcfaa155abdb4c4447285c3fb08ce11273ad7b648cbc29b26bbc99a5d50a57688", "price_changes": [{"asset_id": "107532164421846439086348783344173461119922836080219299112376014605456903082560", "price": "0.605", "size": "0", "side": "BUY", "hash": "eb3eab1ddf2ecfa156ee74a3b84d22c2f321d6a3", "best_bid": "0.801", "best_ask": "0.802"}, {"asset_id": "102123833290224736028606807214973577470974985146136880562573223000412048646565", "price": "0.395", "size": "0", "side": "SELL", "hash": "f434cd06068a26d00e648f84d2bfd7ce1410d08b", "best_bid": "0.198", "best_ask": "0.199"}], "timestamp": "1769384659313", "event_type": "price_change"}}
{"_local_timestamp": "2026-01-25T23:44:19.985260+00:00", "data": {"market": "0xcfaa155abdb4c4447285c3fb08ce11273ad7b648cbc29b26bbc99a5d50a57688", "price_changes": [{"asset_id": "107532164421846439086348783344173461119922836080219299112376014605456903082560", "price": "0.544", "size": "20", "side": "BUY", "hash": "108b019802bac6804de901551a85d8e0932a4a3a", "best_bid": "0.801", "best_ask": "0.802"}, {"asset_id": "102123833290224736028606807214973577470974985146136880562573223000412048646565", "price": "0.456", "size": "20", "side": "SELL", "hash": "dab95660a0fce1a0a44b7821e0f02d2a1f929099", "best_bid": "0.198", "best_ask": "0.199"}], "timestamp": "1769384659344", "event_type": "price_change"}}
{"_local_timestamp": "2026-01-25T23:44:20.908601+00:00", "data": {"market": "0xa32587f6a3b3fa89d71c5648c526fe69791ef6593159e682f1ca5d4dc364f974", "price_changes": [{"asset_id": "54074938701699388770795173053719001491386817666951566814225682866135668313701", "price": "0.241", "size": "150", "side": "BUY", "hash": "f0892dc63c2c4508a87c9c6044065136ed30d50f", "best_bid": "0.931", "best_ask": "0.958"}, {"asset_id": "46775328864914034111636027140584666041009849439098120541770590397117980620796", "price": "0.759", "size": "150", "side": "SELL", "hash": "8217ac8844ecdd3b478d49d3963808b55df76b2e", "best_bid": "0.042", "best_ask": "0.069"}], "timestamp": "1769384660499", "event_type": "price_change"}}
{"_local_timestamp": "2026-01-25T23:44:20.974560+00:00", "data": {"market": "0x960324c7d2db73740836bbd97eec770fcb9b5372e5b46d98b2999fdbbd017f7a", "price_changes": [{"asset_id": "80664742764535144927724195537615142554527026640240245478342373307617044724467", "price": "0.432", "size": "547", "side": "BUY", "hash": "b02cbdeaf4e5a61c346864051b1b4f9d381d9f10", "best_bid": "0.917", "best_ask": "0.96"}, {"asset_id": "40004664463047048443131162836045703174545321215871022010023173925320272282862", "price": "0.568", "size": "547", "side": "SELL", "hash": "90fa8d5e9e6b124c7ddee0e039bce1e646b421ae", "best_bid": "0.04", "best_ask": "0.083"}], "timestamp": "1769384660493", "event_type": "price_change"}}
{"_local_timestamp": "2026-01-25T23:44:20.995519+00:00", "data": {"market": "0xb51d73fb402680d320b8ae1a1450c17c90eb5c5061d7d406c1f86465276adb60", "price_changes": [{"asset_id": "5798682250465986989350076675203301795837240505688895325567849193712450372007", "price": "0.289", "size": "0", "side": "BUY", "hash": "08ac9e93936dd8c3e5d5a1e93a22614ef1fe1a0a", "best_bid": "0.901", "best_ask": "0.93"}, {"asset_id": "58858731796442679222989272055454043286056057669744610936854497026401512278651", "price": "0.711", "size": "0", "side": "SELL", "hash": "df1b0efb68d883d466672556a06690db4456a5e8", "best_bid": "0.07", "best_ask": "0.099"}], "timestamp": "1769384660492", "event_type": "price_change"}}
{"_local_timestamp": "2026-01-25T23:44:20.996583+00:00", "data": {"market": "0x326df6a10a6cdd74bdc1ef77906037e90b1f1d6dd1fdcbf6580aea62de094a96", "price_changes": [{"asset_id": "111947356992305187589428447311248216731582641625774563053368133120784997422919", "price": "0.29", "size": "100", "side": "BUY", "hash": "f32d692e490d761dfa76277899da03010c306ea0", "best_bid": "0.898", "best_ask": "0.914"}, {"asset_id": "80615165254308476859697533076369001631861513127578482097071314558553613438129", "price": "0.71", "size": "100", "side": "SELL", "hash": "5fb4c92dc824144fa200675c94f43836ed17e2cc", "best_bid": "0.086", "best_ask": "0.102"}], "timestamp": "1769384660495", "event_type": "price_change"}}
{"_local_timestamp": "2026-01-25T23:44:21.474318+00:00", "data": {"market": "0x326df6a10a6cdd74bdc1ef77906037e90b1f1d6dd1fdcbf6580aea62de094a96", "price_changes": [{"asset_id": "111947356992305187589428447311248216731582641625774563053368133120784997422919", "price": "0.231", "size": "2068", "side": "BUY", "hash": "95d4823de1826ba8ebd1a4a512afa3707b38fa36", "best_bid": "0.898", "best_ask": "0.914"}, {"asset_id": "80615165254308476859697533076369001631861513127578482097071314558553613438129", "price": "0.769", "size": "2068", "side": "SELL", "hash": "4b07f731708fbd1414160f14ffc37872aeb3076a", "best_bid": "0.086", "best_ask": "0.102"}], "timestamp": "1769384660877", "event_type": "price_change"}}
{"_local_timestamp": "2026-01-25T23:44:21.540466+00:00", "data": {"market": "0xb51d73fb402680d320b8ae1a1450c17c90eb5c5061d7d406c1f86465276adb60", "price_changes": [{"asset_id": "5798682250465986989350076675203301795837240505688895325567849193712450372007", "price": "0.29", "size": "1698", "side": "BUY", "hash": "b297de9330a74077b332a634ac41df7b730e5661", "best_bid": "0.901", "best_ask": "0.93"}, {"asset_id": "58858731796442679222989272055454043286056057669744610936854497026401512278651", "price": "0.71", "size": "1698", "side": "SELL", "hash": "bc2339edbb4a0cd094b9024770a759a1320e8021", "best_bid": "0.07", "best_ask": "0.099"}], "timestamp": "1769384660888", "event_type": "price_change"}}
{"_local_timestamp": "2026-01-25T23:44:21.654196+00:00", "data": {"market": "0xa32587f6a3b3fa89d71c5648c526fe69791ef6593159e682f1ca5d4dc364f974", "price_changes": [{"asset_id": "54074938701699388770795173053719001491386817666951566814225682866135668313701", "price": "0.291", "size": "1642", "side": "BUY", "hash": "24b7e3d94a978581cad1983437fb91777e3f4ab6", "best_bid": "0.931", "best_ask": "0.958"}, {"asset_id": "46775328864914034111636027140584666041009849439098120541770590397117980620796", "price": "0.709", "size": "1642", "side": "SELL", "hash": "3c1882747e152f1be0d9c5a44eea1a51c05c6bac", "best_bid": "0.042", "best_ask": "0.069"}], "timestamp": "1769384660918", "event_type": "price_change"}}
{"_local_timestamp": "2026-01-25T23:44:21.655114+00:00", "data": {"market": "0x960324c7d2db73740836bbd97eec770fcb9b5372e5b46d98b2999fdbbd017f7a", "price_changes": [{"asset_id": "80664742764535144927724195537615142554527026640240245478342373307617044724467", "price": "0.433", "size": "286", "side": "BUY", "hash": "0730649b7b94ab9040048fe733db03c132128caf", "best_bid": "0.917", "best_ask": "0.96"}, {"asset_id": "40004664463047048443131162836045703174545321215871022010023173925320272282862", "price": "0.567", "size": "286", "side": "SELL", "hash": "2653a87bf0fd5be1f9828ee185fbb6ee29a4081a", "best_bid": "0.04", "best_ask": "0.083"}], "timestamp": "1769384660920", "event_type": "price_change"}}
{"_local_timestamp": "2026-01-25T23:44:24.982901+00:00", "data": {"market": "0xfff9fd2422f8e3b878a2701c4eb1e9e182a35d9a71ec2d4233ccd2cac834f887", "price_changes": [{"asset_id": "97579963624866678731903283461280009667266517428659356160462670347995084766428", "price": "0.876", "size": "100", "side": "BUY", "hash": "8dadefa6feaa9f9104777ff8747115c33d9374ce", "best_bid": "0.881", "best_ask": "0.911"}, {"asset_id": "2095798660633756262303834783492337010518543450973961053424376028794255397244", "price": "0.124", "size": "100", "side": "SELL", "hash": "e5c75812e4f8afce90dc96a131faab8293640cee", "best_bid": "0.089", "best_ask": "0.119"}], "timestamp": "1769384664710", "event_type": "price_change"}}
{"_local_timestamp": "2026-01-25T23:44:24.984055+00:00", "data": {"market": "0xfff9fd2422f8e3b878a2701c4eb1e9e182a35d9a71ec2d4233ccd2cac834f887", "price_changes": [{"asset_id": "2095798660633756262303834783492337010518543450973961053424376028794255397244", "price": "0.084", "size": "100", "side": "BUY", "hash": "0c32e8015c2382d12598da791322ffab21fef96b", "best_bid": "0.089", "best_ask": "0.119"}, {"asset_id": "97579963624866678731903283461280009667266517428659356160462670347995084766428", "price": "0.916", "size": "100", "side": "SELL", "hash": "f4ce98bc84e102854c060409611fd6b718ed952d", "best_bid": "0.881", "best_ask": "0.911"}], "timestamp": "1769384664711", "event_type": "price_change"}}
{"_local_timestamp": "2026-01-25T23:44:25.132609+00:00", "data": {"market": "0xfff9fd2422f8e3b878a2701c4eb1e9e182a35d9a71ec2d4233ccd2cac834f887", "price_changes": [{"asset_id": "97579963624866678731903283461280009667266517428659356160462670347995084766428", "price": "0.856", "size": "294.58", "side": "BUY", "hash": "fad6e2af3b634eba29b97a4ac0757304fbd53437", "best_bid": "0.881", "best_ask": "0.911"}, {"asset_id": "2095798660633756262303834783492337010518543450973961053424376028794255397244", "price": "0.144", "size": "294.58", "side": "SELL", "hash": "019087157756954dbc2af54a210d3a7bd803d25e", "best_bid": "0.089", "best_ask": "0.119"}], "timestamp": "1769384664863", "event_type": "price_change"}}
{"_local_timestamp": "2026-01-25T23:44:25.133327+00:00", "data": {"market": "0xfff9fd2422f8e3b878a2701c4eb1e9e182a35d9a71ec2d4233ccd2cac834f887", "price_changes": [{"asset_id": "2095798660633756262303834783492337010518543450973961053424376028794255397244", "price": "0.088", "size": "200", "side": "BUY", "hash": "25468de99bd22bc0e03f890e79590f697480dde1", "best_bid": "0.089", "best_ask": "0.119"}, {"asset_id": "97579963624866678731903283461280009667266517428659356160462670347995084766428", "price": "0.912", "size": "200", "side": "SELL", "hash": "e4577ffeb29f21665d09e76796bfe222276a2bca", "best_bid": "0.881", "best_ask": "0.911"}], "timestamp": "1769384664864", "event_type": "price_change"}}
{"_local_timestamp": "2026-01-25T23:44:25.313329+00:00", "data": {"market": "0xfff9fd2422f8e3b878a2701c4eb1e9e182a35d9a71ec2d4233ccd2cac834f887", "price_changes": [{"asset_id": "2095798660633756262303834783492337010518543450973961053424376028794255397244", "price": "0.088", "size": "300", "side": "BUY", "hash": "67fa20c9db7b76a9933fec2a196d71e70ed09eae", "best_bid": "0.089", "best_ask": "0.119"}, {"asset_id": "97579963624866678731903283461280009667266517428659356160462670347995084766428", "price": "0.912", "size": "300", "side": "SELL", "hash": "c5bf9f17ca4fc9c21d7445185bf2a73c07881510", "best_bid": "0.881", "best_ask": "0.911"}], "timestamp": "1769384665053", "event_type": "price_change"}}
{"_local_timestamp": "2026-01-25T23:44:25.316459+00:00", "data": {"market": "0xfff9fd2422f8e3b878a2701c4eb1e9e182a35d9a71ec2d4233ccd2cac834f887", "price_changes": [{"asset_id": "97579963624866678731903283461280009667266517428659356160462670347995084766428", "price": "0.876", "size": "200", "side": "BUY", "hash": "6f64dda577819f289d2c2ce6f0896ad9a76d705e", "best_bid": "0.881", "best_ask": "0.911"}, {"asset_id": "2095798660633756262303834783492337010518543450973961053424376028794255397244", "price": "0.124", "size": "200", "side": "SELL", "hash": "ccb1fc2f2bdc3ca17215ed288bb87915a31fc219", "best_bid": "0.089", "best_ask": "0.119"}], "timestamp": "1769384665053", "event_type": "price_change"}}
{"_local_timestamp": "2026-01-25T23:44:26.335484+00:00", "data": {"market": "0xaca5aedf274be4876eed3441d1cd4c9f5f3908ee2d5dff4c838ba89cd69365d8", "price_changes": [{"asset_id": "82834542816241625492514061227288286309604590623265497797502039631748808662467", "price": "0.827", "size": "100", "side": "BUY", "hash": "e77a63efeb731ec798684dc72bf069fb48f5840d", "best_bid": "0.835", "best_ask": "0.858"}, {"asset_id": "29737896427505913579373080975459102667589461703616780283220419284622020368836", "price": "0.173", "size": "100", "side": "SELL", "hash": "745dfad94f620c42c48d04c101e587597be78e36", "best_bid": "0.142", "best_ask": "0.165"}], "timestamp": "1769384666096", "event_type": "price_change"}}
{"_local_timestamp": "2026-01-25T23:44:26.340693+00:00", "data": {"market": "0xaca5aedf274be4876eed3441d1cd4c9f5f3908ee2d5dff4c838ba89cd69365d8", "price_changes": [{"asset_id": "29737896427505913579373080975459102667589461703616780283220419284622020368836", "price": "0.134", "size": "100", "side": "BUY", "hash": "9f2b3eadf17a538796f30bcdfc4c4a9254840548", "best_bid": "0.142", "best_ask": "0.165"}, {"asset_id": "82834542816241625492514061227288286309604590623265497797502039631748808662467", "price": "0.866", "size": "100", "side": "SELL", "hash": "50cd1e36ca0408f4c38dd2706c492439f46ec879", "best_bid": "0.835", "best_ask": "0.858"}], "timestamp": "1769384666096", "event_type": "price_change"}}
{"_local_timestamp": "2026-01-25T23:44:26.462792+00:00", "data": {"market": "0xaca5aedf274be4876eed3441d1cd4c9f5f3908ee2d5dff4c838ba89cd69365d8", "price_changes": [{"asset_id": "82834542816241625492514061227288286309604590623265497797502039631748808662467", "price": "0.821", "size": "178", "side": "BUY", "hash": "73978f196ab4bf9c014445352535c1cfee2e3aa7", "best_bid": "0.835", "best_ask": "0.858"}, {"asset_id": "29737896427505913579373080975459102667589461703616780283220419284622020368836", "price": "0.179", "size": "178", "side": "SELL", "hash": "614c883d602be48caf68d0a1c473c299a4ad75ee", "best_bid": "0.142", "best_ask": "0.165"}], "timestamp": "1769384666216", "event_type": "price_change"}}
{"_local_timestamp": "2026-01-25T23:44:26.463735+00:00", "data": {"market": "0xaca5aedf274be4876eed3441d1cd4c9f5f3908ee2d5dff4c838ba89cd69365d8", "price_changes": [{"asset_id": "29737896427505913579373080975459102667589461703616780283220419284622020368836", "price": "0.14", "size": "731.42", "side": "BUY", "hash": "5b17279e8c43c55283e739915091a37b4069d8e0", "best_bid": "0.142", "best_ask": "0.165"}, {"asset_id": "82834542816241625492514061227288286309604590623265497797502039631748808662467", "price": "0.86", "size": "731.42", "side": "SELL", "hash": "f11885958e4a24aaf3ab8edf59fd85c039e80a7f", "best_bid": "0.835", "best_ask": "0.858"}], "timestamp": "1769384666216", "event_type": "price_change"}}
{"_local_timestamp": "2026-01-25T23:44:26.622575+00:00", "data": {"market": "0xaca5aedf274be4876eed3441d1cd4c9f5f3908ee2d5dff4c838ba89cd69365d8", "price_changes": [{"asset_id": "29737896427505913579373080975459102667589461703616780283220419284622020368836", "price": "0.14", "size": "831.42", "side": "BUY", "hash": "79aa7a6d937308763c2e8428d7a15fc02fbf8cfe", "best_bid": "0.142", "best_ask": "0.165"}, {"asset_id": "82834542816241625492514061227288286309604590623265497797502039631748808662467", "price": "0.86", "size": "831.42", "side": "SELL", "hash": "9c8f7fd94553156d19f7b1d2a97ed51ac17b4d85", "best_bid": "0.835", "best_ask": "0.858"}], "timestamp": "1769384666372", "event_type": "price_change"}}
{"_local_timestamp": "2026-01-25T23:44:26.623285+00:00", "data": {"market": "0xaca5aedf274be4876eed3441d1cd4c9f5f3908ee2d5dff4c838ba89cd69365d8", "price_changes": [{"asset_id": "82834542816241625492514061227288286309604590623265497797502039631748808662467", "price": "0.822", "size": "200", "side": "BUY", "hash": "6031cdb3811a407d1841acac06fe62d12c08410b", "best_bid": "0.835", "best_ask": "0.858"}, {"asset_id": "29737896427505913579373080975459102667589461703616780283220419284622020368836", "price": "0.178", "size": "200", "side": "SELL", "hash": "f1af7a833d0f199bda78d0e687973c5ff024d313", "best_bid": "0.142", "best_ask": "0.165"}], "timestamp": "1769384666372", "event_type": "price_change"}}
{"_local_timestamp": "2026-01-25T23:44:26.698547+00:00", "data": {"market": "0xaca5aedf274be4876eed3441d1cd4c9f5f3908ee2d5dff4c838ba89cd69365d8", "price_changes": [{"asset_id": "29737896427505913579373080975459102667589461703616780283220419284622020368836", "price": "0.141", "size": "230", "side": "BUY", "hash": "f60832ce71a6f678cfb3995ba30b373b5d27fe18", "best_bid": "0.142", "best_ask": "0.165"}, {"asset_id": "82834542816241625492514061227288286309604590623265497797502039631748808662467", "price": "0.859", "size": "230", "side": "SELL", "hash": "bf2dfad045a3c3125367dc5afd5db017f75ab82b", "best_bid": "0.835", "best_ask": "0.858"}], "timestamp": "1769384666440", "event_type": "price_change"}}
{"_local_timestamp": "2026-01-25T23:44:26.932714+00:00", "data": {"market": "0xa32587f6a3b3fa89d71c5648c526fe69791ef6593159e682f1ca5d4dc364f974", "price_changes": [{"asset_id": "54074938701699388770795173053719001491386817666951566814225682866135668313701", "price": "0.925", "size": "100", "side": "BUY", "hash": "48c07b93ed87e08da86375c6fb8bb48d729c7f41", "best_bid": "0.931", "best_ask": "0.958"}, {"asset_id": "46775328864914034111636027140584666041009849439098120541770590397117980620796", "price": "0.075", "size": "100", "side": "SELL", "hash": "8e90b73fcce3696c9ee15fc626bce0add0e4f83d", "best_bid": "0.042", "best_ask": "0.069"}], "timestamp": "1769384666656", "event_type": "price_change"}}
{"_local_timestamp": "2026-01-25T23:44:26.933624+00:00", "data": {"market": "0xa32587f6a3b3fa89d71c5648c526fe69791ef6593159e682f1ca5d4dc364f974", "price_changes": [{"asset_id": "46775328864914034111636027140584666041009849439098120541770590397117980620796", "price": "0.036", "size": "100", "side": "BUY", "hash": "c28fc1beafe9731b2f636bad871487b026e3554f", "best_bid": "0.042", "best_ask": "0.069"}, {"asset_id": "54074938701699388770795173053719001491386817666951566814225682866135668313701", "price": "0.964", "size": "100", "side": "SELL", "hash": "0107796ef1d09a03ac51391897b7f7d993caf447", "best_bid": "0.931", "best_ask": "0.958"}], "timestamp": "1769384666656", "event_type": "price_change"}}
{"_local_timestamp": "2026-01-25T23:44:27.646769+00:00", "data": {"market": "0xa32587f6a3b3fa89d71c5648c526fe69791ef6593159e682f1ca5d4dc364f974", "price_changes": [{"asset_id": "54074938701699388770795173053719001491386817666951566814225682866135668313701", "price": "0.685", "size": "0", "side": "BUY", "hash": "c691e5a48137dbab862e872cc8dd47363978b42d", "best_bid": "0.931", "best_ask": "0.958"}, {"asset_id": "46775328864914034111636027140584666041009849439098120541770590397117980620796", "price": "0.315", "size": "0", "side": "SELL", "hash": "35f56b9d9520fb7386c3b6a345dbfbe84ee65acd", "best_bid": "0.042", "best_ask": "0.069"}], "timestamp": "1769384666757", "event_type": "price_change"}}
{"_local_timestamp": "2026-01-25T23:44:27.647574+00:00", "data": {"market": "0xaca5aedf274be4876eed3441d1cd4c9f5f3908ee2d5dff4c838ba89cd69365d8", "price_changes": [{"asset_id": "29737896427505913579373080975459102667589461703616780283220419284622020368836", "price": "0.141", "size": "200", "side": "BUY", "hash": "c311fa922beb1ed8176905cbf7e895d8fb80cbdf", "best_bid": "0.142", "best_ask": "0.165"}, {"asset_id": "82834542816241625492514061227288286309604590623265497797502039631748808662467", "price": "0.859", "size": "200", "side": "SELL", "hash": "5a945957df3e765dc2f4051a3f47803c18620a6a", "best_bid": "0.835", "best_ask": "0.858"}], "timestamp": "1769384667061", "event_type": "price_change"}}
{"_local_timestamp": "2026-01-25T23:44:27.720611+00:00", "data": {"market": "0xaca5aedf274be4876eed3441d1cd4c9f5f3908ee2d5dff4c838ba89cd69365d8", "price_changes": [{"asset_id": "29737896427505913579373080975459102667589461703616780283220419284622020368836", "price": "0.142", "size": "37.04", "side": "BUY", "hash": "9742f05866c25e0c09b6bc32744443038a14351f", "best_bid": "0.142", "best_ask": "0.165"}, {"asset_id": "82834542816241625492514061227288286309604590623265497797502039631748808662467", "price": "0.858", "size": "37.04", "side": "SELL", "hash": "79f962936016e90a114a057fbd31a5d6883f4666", "best_bid": "0.835", "best_ask": "0.858"}], "timestamp": "1769384667111", "event_type": "price_change"}}
{"_local_timestamp": "2026-01-25T23:44:27.721985+00:00", "data": {"market": "0x326df6a10a6cdd74bdc1ef77906037e90b1f1d6dd1fdcbf6580aea62de094a96", "price_changes": [{"asset_id": "111947356992305187589428447311248216731582641625774563053368133120784997422919", "price": "0.766", "size": "0", "side": "BUY", "hash": "39ec6ec6df5228023f7a5f8fcbd4ca915add553d", "best_bid": "0.898", "best_ask": "0.914"}, {"asset_id": "80615165254308476859697533076369001631861513127578482097071314558553613438129", "price": "0.234", "size": "0", "side": "SELL", "hash": "45911494cac9ed3ee7e6968f8d781a0d422f9394", "best_bid": "0.086", "best_ask": "0.102"}], "timestamp": "1769384667138", "event_type": "price_change"}}
{"_local_timestamp": "2026-01-25T23:44:27.722630+00:00", "data": {"market": "0x960324c7d2db73740836bbd97eec770fcb9b5372e5b46d98b2999fdbbd017f7a", "price_changes": [{"asset_id": "80664742764535144927724195537615142554527026640240245478342373307617044724467", "price": "0.812", "size": "0", "side": "BUY", "hash": "844abf1fa32eccd4ff0813e6625b2a99cc9d1ad6", "best_bid": "0.917", "best_ask": "0.96"}, {"asset_id": "40004664463047048443131162836045703174545321215871022010023173925320272282862", "price": "0.188", "size": "0", "side": "SELL", "hash": "a8caa833bcde559de8a046b81ee128139321720b", "best_bid": "0.04", "best_ask": "0.083"}], "timestamp": "1769384667139", "event_type": "price_change"}}
{"_local_timestamp": "2026-01-25T23:44:27.723231+00:00", "data": {"market": "0xb51d73fb402680d320b8ae1a1450c17c90eb5c5061d7d406c1f86465276adb60", "price_changes": [{"asset_id": "5798682250465986989350076675203301795837240505688895325567849193712450372007", "price": "0.782", "size": "0", "side": "BUY", "hash": "e52bcb8c0ffcbc729fa906a1f745c2f033231d65", "best_bid": "0.901", "best_ask": "0.93"}, {"asset_id": "58858731796442679222989272055454043286056057669744610936854497026401512278651", "price": "0.218", "size": "0", "side": "SELL", "hash": "0ca2066da4e87f7a35ad0cce0cc71689c980ce68", "best_bid": "0.07", "best_ask": "0.099"}], "timestamp": "1769384667140", "event_type": "price_change"}}
{"_local_timestamp": "2026-01-25T23:44:27.723814+00:00", "data": {"market": "0x326df6a10a6cdd74bdc1ef77906037e90b1f1d6dd1fdcbf6580aea62de094a96", "price_changes": [{"asset_id": "111947356992305187589428447311248216731582641625774563053368133120784997422919", "price": "0.767", "size": "20", "side": "BUY", "hash": "a0daeb10a5a7d9a104416865df1b52735edd3247", "best_bid": "0.898", "best_ask": "0.914"}, {"asset_id": "80615165254308476859697533076369001631861513127578482097071314558553613438129", "price": "0.233", "size": "20", "side": "SELL", "hash": "adf4400f36dfc2c4424656f97b4ff68bd2de5754", "best_bid": "0.086", "best_ask": "0.102"}], "timestamp": "1769384667262", "event_type": "price_change"}}
{"_local_timestamp": "2026-01-25T23:44:27.724386+00:00", "data": {"market": "0x960324c7d2db73740836bbd97eec770fcb9b5372e5b46d98b2999fdbbd017f7a", "price_changes": [{"asset_id": "80664742764535144927724195537615142554527026640240245478342373307617044724467", "price": "0.813", "size": "20", "side": "BUY", "hash": "0af673807bd6acc7f2b5675cc3705879aebce171", "best_bid": "0.917", "best_ask": "0.96"}, {"asset_id": "40004664463047048443131162836045703174545321215871022010023173925320272282862", "price": "0.187", "size": "20", "side": "SELL", "hash": "67f822d9604877ab57340b8ac521ddad969ca0e2", "best_bid": "0.04", "best_ask": "0.083"}], "timestamp": "1769384667263", "event_type": "price_change"}}
{"_local_timestamp": "2026-01-25T23:44:27.725023+00:00", "data": {"market": "0xb51d73fb402680d320b8ae1a1450c17c90eb5c5061d7d406c1f86465276adb60", "price_changes": [{"asset_id": "5798682250465986989350076675203301795837240505688895325567849193712450372007", "price": "0.783", "size": "20", "side": "BUY", "hash": "41347d88f749dc540959a4a3a24351d3cd05094e", "best_bid": "0.901", "best_ask": "0.93"}, {"asset_id": "58858731796442679222989272055454043286056057669744610936854497026401512278651", "price": "0.217", "size": "20", "side": "SELL", "hash": "f8fe690aee88362f4a780b1787ba3e21a29ae68f", "best_bid": "0.07", "best_ask": "0.099"}], "timestamp": "1769384667267", "event_type": "price_change"}}
{"_local_timestamp": "2026-01-25T23:44:27.976174+00:00", "data": {"market": "0x326df6a10a6cdd74bdc1ef77906037e90b1f1d6dd1fdcbf6580aea62de094a96", "price_changes": [{"asset_id": "111947356992305187589428447311248216731582641625774563053368133120784997422919", "price": "0.717", "size": "30", "side": "BUY", "hash": "168b7246d5dbe863ac283580ae0e58fd2ec6da6c", "best_bid": "0.898", "best_ask": "0.914"}, {"asset_id": "80615165254308476859697533076369001631861513127578482097071314558553613438129", "price": "0.283", "size": "30", "side": "SELL", "hash": "e66b101d22b8c710f3c59b8434723dde95b1edb1", "best_bid": "0.086", "best_ask": "0.102"}], "timestamp": "1769384667700", "event_type": "price_change"}}
{"_local_timestamp": "2026-01-25T23:44:27.977063+00:00", "data": {"market": "0xa32587f6a3b3fa89d71c5648c526fe69791ef6593159e682f1ca5d4dc364f974", "price_changes": [{"asset_id": "54074938701699388770795173053719001491386817666951566814225682866135668313701", "price": "0.686", "size": "0", "side": "BUY", "hash": "0a3dfdc503efcc209387c84cbce14bc4c8d5f17b", "best_bid": "0.931", "best_ask": "0.958"}, {"asset_id": "46775328864914034111636027140584666041009849439098120541770590397117980620796", "price": "0.314", "size": "0", "side": "SELL", "hash": "ed33a337bcdaa57da21dab322b1e0794f7f814fd", "best_bid": "0.042", "best_ask": "0.069"}], "timestamp": "1769384667700", "event_type": "price_change"}}
{"_local_timestamp": "2026-01-25T23:44:27.984934+00:00", "data": {"market": "0x326df6a10a6cdd74bdc1ef77906037e90b1f1d6dd1fdcbf6580aea62de094a96", "price_changes": [{"asset_id": "111947356992305187589428447311248216731582641625774563053368133120784997422919", "price": "0.718", "size": "33.33", "side": "BUY", "hash": "364d05cb0e4a57489e60b46a0663021dbb1227af", "best_bid": "0.898", "best_ask": "0.914"}, {"asset_id": "80615165254308476859697533076369001631861513127578482097071314558553613438129", "price": "0.282", "size": "33.33", "side": "SELL", "hash": "c8c855bf1090200b353182887ecbe24e403cfba0", "best_bid": "0.086", "best_ask": "0.102"}], "timestamp": "1769384667730", "event_type": "price_change"}}
{"_local_timestamp": "2026-01-25T23:44:28.054350+00:00", "data": {"market": "0xa32587f6a3b3fa89d71c5648c526fe69791ef6593159e682f1ca5d4dc364f974", "price_changes": [{"asset_id": "54074938701699388770795173053719001491386817666951566814225682866135668313701", "price": "0.684", "size": "20", "side": "BUY", "hash": "aac42c1c521b41981b4f564cb9dce61189f56768", "best_bid": "0.931", "best_ask": "0.958"}, {"asset_id": "46775328864914034111636027140584666041009849439098120541770590397117980620796", "price": "0.316", "size": "20", "side": "SELL", "hash": "c52a80853474423aebb3e602d953fb512a62952b", "best_bid": "0.042", "best_ask": "0.069"}], "timestamp": "1769384667730", "event_type": "price_change"}}
{"_local_timestamp": "2026-01-25T23:44:28.298135+00:00", "data": {"market": "0xa32587f6a3b3fa89d71c5648c526fe69791ef6593159e682f1ca5d4dc364f974", "price_changes": [{"asset_id": "54074938701699388770795173053719001491386817666951566814225682866135668313701", "price": "0.923", "size": "395", "side": "BUY", "hash": "e62f273155695834deaec45cf848de304d80aae5", "best_bid": "0.931", "best_ask": "0.958"}, {"asset_id": "46775328864914034111636027140584666041009849439098120541770590397117980620796", "price": "0.077", "size": "395", "side": "SELL", "hash": "59a83afea1ae391fbdbd4fc32fe8bbf7920a712f", "best_bid": "0.042", "best_ask": "0.069"}], "timestamp": "1769384668023", "event_type": "price_change"}}
{"_local_timestamp": "2026-01-25T23:44:28.298944+00:00", "data": {"market": "0xa32587f6a3b3fa89d71c5648c526fe69791ef6593159e682f1ca5d4dc364f974", "price_changes": [{"asset_id": "46775328864914034111636027140584666041009849439098120541770590397117980620796", "price": "0.019", "size": "0", "side": "BUY", "hash": "7c17412ca86ac21d73b35cb3c6de17d19754b5dc", "best_bid": "0.042", "best_ask": "0.069"}, {"asset_id": "54074938701699388770795173053719001491386817666951566814225682866135668313701", "price": "0.981", "size": "0", "side": "SELL", "hash": "f6af88bdab4d0bae19cf742849aa50eafa8c203d", "best_bid": "0.931", "best_ask": "0.958"}], "timestamp": "1769384668024", "event_type": "price_change"}}
{"_local_timestamp": "2026-01-25T23:44:29.276551+00:00", "data": {"market": "0xa32587f6a3b3fa89d71c5648c526fe69791ef6593159e682f1ca5d4dc364f974", "price_changes": [{"asset_id": "46775328864914034111636027140584666041009849439098120541770590397117980620796", "price": "0.026", "size": "200", "side": "BUY", "hash": "aabbc55dd238f40ca607b031bd34a229d3d908b6", "best_bid": "0.042", "best_ask": "0.069"}, {"asset_id": "54074938701699388770795173053719001491386817666951566814225682866135668313701", "price": "0.974", "size": "200", "side": "SELL", "hash": "f70b1bb796470db5682a2f813d73af8563ecc054", "best_bid": "0.931", "best_ask": "0.958"}], "timestamp": "1769384669008", "event_type": "price_change"}}
{"_local_timestamp": "2026-01-25T23:44:29.286303+00:00", "data": {"market": "0xa32587f6a3b3fa89d71c5648c526fe69791ef6593159e682f1ca5d4dc364f974", "price_changes": [{"asset_id": "54074938701699388770795173053719001491386817666951566814225682866135668313701", "price": "0.923", "size": "200", "side": "BUY", "hash": "14346574b907dcd1213ec12165c65d7567c097d2", "best_bid": "0.931", "best_ask": "0.958"}, {"asset_id": "46775328864914034111636027140584666041009849439098120541770590397117980620796", "price": "0.077", "size": "200", "side": "SELL", "hash": "38785aece78e1d9f6fdc749958e8c5fff782f936", "best_bid": "0.042", "best_ask": "0.069"}], "timestamp": "1769384669008", "event_type": "price_change"}}
{"_local_timestamp": "2026-01-25T23:44:32.340947+00:00", "data": {"market": "0xa32587f6a3b3fa89d71c5648c526fe69791ef6593159e682f1ca5d4dc364f974", "price_changes": [{"asset_id": "46775328864914034111636027140584666041009849439098120541770590397117980620796", "price": "0.026", "size": "300", "side": "BUY", "hash": "c3df51459cd88cb47716dec68fba16944b659f8a", "best_bid": "0.042", "best_ask": "0.069"}, {"asset_id": "54074938701699388770795173053719001491386817666951566814225682866135668313701", "price": "0.974", "size": "300", "side": "SELL", "hash": "f37618224bc509b1607cf98d1846a4c94cd16ce5", "best_bid": "0.931", "best_ask": "0.958"}], "timestamp": "1769384672031", "event_type": "price_change"}}
{"_local_timestamp": "2026-01-25T23:44:32.341739+00:00", "data": {"market": "0xa32587f6a3b3fa89d71c5648c526fe69791ef6593159e682f1ca5d4dc364f974", "price_changes": [{"asset_id": "54074938701699388770795173053719001491386817666951566814225682866135668313701", "price": "0.924", "size": "291.64", "side": "BUY", "hash": "57ab5aa7a8af2a5dac5a0be2538070876fbc1bdf", "best_bid": "0.931", "best_ask": "0.958"}, {"asset_id": "46775328864914034111636027140584666041009849439098120541770590397117980620796", "price": "0.076", "size": "291.64", "side": "SELL", "hash": "ae6c87fe64d07e1a6cfcbe59e97173de4dad57c7", "best_bid": "0.042", "best_ask": "0.069"}], "timestamp": "1769384672032", "event_type": "price_change"}}
{"_local_timestamp": "2026-01-25T23:44:32.596403+00:00", "data": {"market": "0xac0e8cc2c1194bd79bfee4d944134a22a470dabf9a44973078931586ec2b4713", "price_changes": [{"asset_id": "6949439350204552418128687543998149261828101838617755026479239514017283314200", "price": "0.1", "size": "0", "side": "BUY", "hash": "0a4b9e344ada4613af28f458c0190ddba0624b73", "best_bid": "0.91", "best_ask": "0.92"}, {"asset_id": "7465944841767583018291499747334711307126986423404813304527234412438530575641", "price": "0.9", "size": "0", "side": "SELL", "hash": "ad56a169f5377bdbf0f18656c06a11a46fa5e652", "best_bid": "0.08", "best_ask": "0.09"}], "timestamp": "1769384672291", "event_type": "price_change"}}
{"_local_timestamp": "2026-01-25T23:44:32.646414+00:00", "data": {"market": "0xab77a311c7c175ff91707a06dcd358db7a7d7f4258fb7756b05b4f44d175914f", "price_changes": [{"asset_id": "96433559971245993197815501880637705319986922684384749364193086888126378928132", "price": "0.221", "size": "100", "side": "BUY", "hash": "94cac3e9cf2f05f046f1c7736d8438913f4156c6", "best_bid": "0.869", "best_ask": "0.892"}, {"asset_id": "100716705141639838044649900187335811063814165386716787647982371091165872129354", "price": "0.779", "size": "100", "side": "SELL", "hash": "ed734398fdccfc5ff65a77aa62b6826f9489495f", "best_bid": "0.108", "best_ask": "0.131"}], "timestamp": "1769384672295", "event_type": "price_change"}}
{"_local_timestamp": "2026-01-25T23:44:33.034421+00:00", "data": {"market": "0xb51d73fb402680d320b8ae1a1450c17c90eb5c5061d7d406c1f86465276adb60", "price_changes": [{"asset_id": "5798682250465986989350076675203301795837240505688895325567849193712450372007", "price": "0.29", "size": "250", "side": "BUY", "hash": "50298cf893e5fb2dea896df2d8ab70712c256727", "best_bid": "0.901", "best_ask": "0.93"}, {"asset_id": "58858731796442679222989272055454043286056057669744610936854497026401512278651", "price": "0.71", "size": "250", "side": "SELL", "hash": "73c99735d39c80ed15352b2c12f6e5e90668a236", "best_bid": "0.07", "best_ask": "0.099"}], "timestamp": "1769384672295", "event_type": "price_change"}}
{"_local_timestamp": "2026-01-25T23:44:33.035176+00:00", "data": {"market": "0x326df6a10a6cdd74bdc1ef77906037e90b1f1d6dd1fdcbf6580aea62de094a96", "price_changes": [{"asset_id": "111947356992305187589428447311248216731582641625774563053368133120784997422919", "price": "0.231", "size": "250", "side": "BUY", "hash": "a24d290d215c8c2de394a2994b1d770546eb81bc", "best_bid": "0.898", "best_ask": "0.914"}, {"asset_id": "80615165254308476859697533076369001631861513127578482097071314558553613438129", "price": "0.769", "size": "250", "side": "SELL", "hash": "5155c1fa68a32f0f24403c3ef6126bfc4a5487b9", "best_bid": "0.086", "best_ask": "0.102"}], "timestamp": "1769384672300", "event_type": "price_change"}}
{"_local_timestamp": "2026-01-25T23:44:33.035948+00:00", "data": {"market": "0xa32587f6a3b3fa89d71c5648c526fe69791ef6593159e682f1ca5d4dc364f974", "price_changes": [{"asset_id": "54074938701699388770795173053719001491386817666951566814225682866135668313701", "price": "0.291", "size": "200", "side": "BUY", "hash": "eff85c437b3273edcca8cb8341428066c6e49818", "best_bid": "0.931", "best_ask": "0.958"}, {"asset_id": "46775328864914034111636027140584666041009849439098120541770590397117980620796", "price": "0.709", "size": "200", "side": "SELL", "hash": "e059ebbf9d785c4e2a51fc111e05004655696701", "best_bid": "0.042", "best_ask": "0.069"}], "timestamp": "1769384672297", "event_type": "price_change"}}
{"_local_timestamp": "2026-01-25T23:44:33.036615+00:00", "data": {"market": "0xcfaa155abdb4c4447285c3fb08ce11273ad7b648cbc29b26bbc99a5d50a57688", "price_changes": [{"asset_id": "107532164421846439086348783344173461119922836080219299112376014605456903082560", "price": "0.241", "size": "100", "side": "BUY", "hash": "5c8d10a1e733bef548053c17caf3857f03fa1231", "best_bid": "0.801", "best_ask": "0.802"}, {"asset_id": "102123833290224736028606807214973577470974985146136880562573223000412048646565", "price": "0.759", "size": "100", "side": "SELL", "hash": "f2dcfcde861f46f092af40ed64656c7a875d04ad", "best_bid": "0.198", "best_ask": "0.199"}], "timestamp": "1769384672301", "event_type": "price_change"}}
{"_local_timestamp": "2026-01-25T23:44:33.368042+00:00", "data": {"market": "0xa32587f6a3b3fa89d71c5648c526fe69791ef6593159e682f1ca5d4dc364f974", "price_changes": [{"asset_id": "46775328864914034111636027140584666041009849439098120541770590397117980620796", "price": "0.028", "size": "1845", "side": "BUY", "hash": "9ed02b80d00537be6b672da93209a362900b77d9", "best_bid": "0.042", "best_ask": "0.069"}, {"asset_id": "54074938701699388770795173053719001491386817666951566814225682866135668313701", "price": "0.972", "size": "1845", "side": "SELL", "hash": "85c2adc50d5ca076a94f35a8d3c5421a9016fce0", "best_bid": "0.931", "best_ask": "0.958"}], "timestamp": "1769384672809", "event_type": "price_change"}}
{"_local_timestamp": "2026-01-25T23:44:33.368926+00:00", "data": {"market": "0xa32587f6a3b3fa89d71c5648c526fe69791ef6593159e682f1ca5d4dc364f974", "price_changes": [{"asset_id": "54074938701699388770795173053719001491386817666951566814225682866135668313701", "price": "0.924", "size": "486.64", "side": "BUY", "hash": "77e7be5bd6160e4329bc6cb8d10b95f5559d4cd7", "best_bid": "0.931", "best_ask": "0.958"}, {"asset_id": "46775328864914034111636027140584666041009849439098120541770590397117980620796", "price": "0.076", "size": "486.64", "side": "SELL", "hash": "feea113ae82ae3647f018885073d1566e4d1368b", "best_bid": "0.042", "best_ask": "0.069"}], "timestamp": "1769384672810", "event_type": "price_change"}}
{"_local_timestamp": "2026-01-25T23:44:33.369741+00:00", "data": {"market": "0xac0e8cc2c1194bd79bfee4d944134a22a470dabf9a44973078931586ec2b4713", "price_changes": [{"asset_id": "6949439350204552418128687543998149261828101838617755026479239514017283314200", "price": "0.77", "size": "0", "side": "BUY", "hash": "432b376498e52e4fc4cb7a6219ba03a0a3e787af", "best_bid": "0.91", "best_ask": "0.92"}, {"asset_id": "7465944841767583018291499747334711307126986423404813304527234412438530575641", "price": "0.23", "size": "0", "side": "SELL", "hash": "ce173a9e0077c005592436d9087566a3dd1943ec", "best_bid": "0.08", "best_ask": "0.09"}], "timestamp": "1769384672832", "event_type": "price_change"}}
{"_local_timestamp": "2026-01-25T23:44:33.370411+00:00", "data": {"market": "0x326df6a10a6cdd74bdc1ef77906037e90b1f1d6dd1fdcbf6580aea62de094a96", "price_changes": [{"asset_id": "111947356992305187589428447311248216731582641625774563053368133120784997422919", "price": "0.767", "size": "0", "side": "BUY", "hash": "e3146d66d2682587b201ab98657ec271ca75e0cb", "best_bid": "0.898", "best_ask": "0.914"}, {"asset_id": "80615165254308476859697533076369001631861513127578482097071314558553613438129", "price": "0.233", "size": "0", "side": "SELL", "hash": "6f66370c89a0073aa1ea52bfd22b81ad381987f4", "best_bid": "0.086", "best_ask": "0.102"}], "timestamp": "1769384672833", "event_type": "price_change"}}
{"_local_timestamp": "2026-01-25T23:44:33.371050+00:00", "data": {"market": "0xb51d73fb402680d320b8ae1a1450c17c90eb5c5061d7d406c1f86465276adb60", "price_changes": [{"asset_id": "5798682250465986989350076675203301795837240505688895325567849193712450372007", "price": "0.783", "size": "0", "side": "BUY", "hash": "c93c6fc38120f16512f2f8fc8fdb3ec1ca21969c", "best_bid": "0.901", "best_ask": "0.93"}, {"asset_id": "58858731796442679222989272055454043286056057669744610936854497026401512278651", "price": "0.217", "size": "0", "side": "SELL", "hash": "50dae9f8b8d271996e09193cad7a7090bf1d191a", "best_bid": "0.07", "best_ask": "0.099"}], "timestamp": "1769384672834", "event_type": "price_change"}}
{"_local_timestamp": "2026-01-25T23:44:33.371700+00:00", "data": {"market": "0x960324c7d2db73740836bbd97eec770fcb9b5372e5b46d98b2999fdbbd017f7a", "price_changes": [{"asset_id": "80664742764535144927724195537615142554527026640240245478342373307617044724467", "price": "0.813", "size": "0", "side": "BUY", "hash": "6defed2e81eeeb097c4a8a6776f3f5eac7c9540d", "best_bid": "0.917", "best_ask": "0.96"}, {"asset_id": "40004664463047048443131162836045703174545321215871022010023173925320272282862", "price": "0.187", "size": "0", "side": "SELL", "hash": "68334bb96681eea47fd6bd1e7b8d8621dad270cc", "best_bid": "0.04", "best_ask": "0.083"}], "timestamp": "1769384672838", "event_type": "price_change"}}
{"_local_timestamp": "2026-01-25T23:44:35.766480+00:00", "data": {"market": "0xac0e8cc2c1194bd79bfee4d944134a22a470dabf9a44973078931586ec2b4713", "price_changes": [{"asset_id": "6949439350204552418128687543998149261828101838617755026479239514017283314200", "price": "0.09", "size": "3405.58", "side": "BUY", "hash": "0cc158391fd3cb72fdf2b33274d4720056d4275e", "best_bid": "0.91", "best_ask": "0.92"}, {"asset_id": "7465944841767583018291499747334711307126986423404813304527234412438530575641", "price": "0.91", "size": "3405.58", "side": "SELL", "hash": "e0c836468967936a3a10dbf4b4476de2e8e403b5", "best_bid": "0.08", "best_ask": "0.09"}], "timestamp": "1769384675484", "event_type": "price_change"}}
{"_local_timestamp": "2026-01-25T23:44:36.065102+00:00", "data": {"market": "0xac0e8cc2c1194bd79bfee4d944134a22a470dabf9a44973078931586ec2b4713", "price_changes": [{"asset_id": "6949439350204552418128687543998149261828101838617755026479239514017283314200", "price": "0.1", "size": "200", "side": "BUY", "hash": "8d4a46a79de471ac060fee04678edc98f316f26f", "best_bid": "0.91", "best_ask": "0.92"}, {"asset_id": "7465944841767583018291499747334711307126986423404813304527234412438530575641", "price": "0.9", "size": "200", "side": "SELL", "hash": "1b92a66100ceeafbf7a2888b74536a120b3a2a90", "best_bid": "0.08", "best_ask": "0.09"}], "timestamp": "1769384675791", "event_type": "price_change"}}
{"_local_timestamp": "2026-01-25T23:44:40.724107+00:00", "data": {"market": "0xab77a311c7c175ff91707a06dcd358db7a7d7f4258fb7756b05b4f44d175914f", "price_changes": [{"asset_id": "96433559971245993197815501880637705319986922684384749364193086888126378928132", "price": "0.433", "size": "0", "side": "BUY", "hash": "9749d1485ff706525d90550e1b6ccaac55449518", "best_bid": "0.869", "best_ask": "0.892"}, {"asset_id": "100716705141639838044649900187335811063814165386716787647982371091165872129354", "price": "0.567", "size": "0", "side": "SELL", "hash": "af8f6b2765786ec43b6d991160032ce293a1e5fd", "best_bid": "0.108", "best_ask": "0.131"}], "timestamp": "1769384680438", "event_type": "price_change"}}
{"_local_timestamp": "2026-01-25T23:44:40.764107+00:00", "data": {"market": "0xab77a311c7c175ff91707a06dcd358db7a7d7f4258fb7756b05b4f44d175914f", "price_changes": [{"asset_id": "96433559971245993197815501880637705319986922684384749364193086888126378928132", "price": "0.382", "size": "5", "side": "BUY", "hash": "b2b337f27f76b1d35ec0619efd70a4be29243f02", "best_bid": "0.869", "best_ask": "0.892"}, {"asset_id": "100716705141639838044649900187335811063814165386716787647982371091165872129354", "price": "0.618", "size": "5", "side": "SELL", "hash": "feb72a1e26fc326b300baf5431ce44415f0016fa", "best_bid": "0.108", "best_ask": "0.131"}], "timestamp": "1769384680484", "event_type": "price_change"}}
{"_local_timestamp": "2026-01-25T23:44:43.194676+00:00", "data": {"market": "0xac0e8cc2c1194bd79bfee4d944134a22a470dabf9a44973078931586ec2b4713", "price_changes": [{"asset_id": "6949439350204552418128687543998149261828101838617755026479239514017283314200", "price": "0.11", "size": "3818", "side": "BUY", "hash": "28ef8d146184a790012c47b524b767d7481aa204", "best_bid": "0.91", "best_ask": "0.92"}, {"asset_id": "7465944841767583018291499747334711307126986423404813304527234412438530575641", "price": "0.89", "size": "3818", "side": "SELL", "hash": "25a7f50a16e2ac91e7a8f45f0ae5f58f430cd198", "best_bid": "0.08", "best_ask": "0.09"}], "timestamp": "1769384683038", "event_type": "price_change"}}
{"_local_timestamp": "2026-01-25T23:44:49.816866+00:00", "data": {"market": "0xb51d73fb402680d320b8ae1a1450c17c90eb5c5061d7d406c1f86465276adb60", "price_changes": [{"asset_id": "5798682250465986989350076675203301795837240505688895325567849193712450372007", "price": "0.231", "size": "1818", "side": "BUY", "hash": "e60c9e279a96aaa82ecfb43c549af87f6e0d7358", "best_bid": "0.901", "best_ask": "0.93"}, {"asset_id": "58858731796442679222989272055454043286056057669744610936854497026401512278651", "price": "0.769", "size": "1818", "side": "SELL", "hash": "4a430449d5de112ed98c76909ace9a2d6d6a0aa7", "best_bid": "0.07", "best_ask": "0.099"}], "timestamp": "1769384689635", "event_type": "price_change"}}
{"_local_timestamp": "2026-01-25T23:44:49.914304+00:00", "data": {"market": "0xa32587f6a3b3fa89d71c5648c526fe69791ef6593159e682f1ca5d4dc364f974", "price_changes": [{"asset_id": "54074938701699388770795173053719001491386817666951566814225682866135668313701", "price": "0.68", "size": "0", "side": "BUY", "hash": "8899fb59f317437de764f951d67632b30d711bf4", "best_bid": "0.931", "best_ask": "0.958"}, {"asset_id": "46775328864914034111636027140584666041009849439098120541770590397117980620796", "price": "0.32", "size": "0", "side": "SELL", "hash": "0b3cff477d9abd6844f2cac83e93b21894c0da16", "best_bid": "0.042", "best_ask": "0.069"}], "timestamp": "1769384689739", "event_type": "price_change"}}
{"_local_timestamp": "2026-01-25T23:44:50.046504+00:00", "data": {"market": "0xa32587f6a3b3fa89d71c5648c526fe69791ef6593159e682f1ca5d4dc364f974", "price_changes": [{"asset_id": "54074938701699388770795173053719001491386817666951566814225682866135668313701", "price": "0.685", "size": "20", "side": "BUY", "hash": "7a929dff3a041c9118bf14831562923b936120cc", "best_bid": "0.931", "best_ask": "0.958"}, {"asset_id": "46775328864914034111636027140584666041009849439098120541770590397117980620796", "price": "0.315", "size": "20", "side": "SELL", "hash": "ebbd39e47e4f9e0dc4b17731e742ac2edf768440", "best_bid": "0.042", "best_ask": "0.069"}], "timestamp": "1769384689893", "event_type": "price_change"}}
{"_local_timestamp": "2026-01-25T23:44:51.563043+00:00", "data": {"market": "0xa32587f6a3b3fa89d71c5648c526fe69791ef6593159e682f1ca5d4dc364f974", "price_changes": [{"asset_id": "54074938701699388770795173053719001491386817666951566814225682866135668313701", "price": "0.684", "size": "0", "side": "BUY", "hash": "9a891991ff2cfea5186fa09312e92fd3c2f2712d", "best_bid": "0.931", "best_ask": "0.958"}, {"asset_id": "46775328864914034111636027140584666041009849439098120541770590397117980620796", "price": "0.316", "size": "0", "side": "SELL", "hash": "ed2618cda3ff593d861d8fe421727cb0071f62a6", "best_bid": "0.042", "best_ask": "0.069"}], "timestamp": "1769384691438", "event_type": "price_change"}}
{"_local_timestamp": "2026-01-25T23:44:51.590931+00:00", "data": {"market": "0xa32587f6a3b3fa89d71c5648c526fe69791ef6593159e682f1ca5d4dc364f974", "price_changes": [{"asset_id": "54074938701699388770795173053719001491386817666951566814225682866135668313701", "price": "0.686", "size": "20", "side": "BUY", "hash": "475d821d0c78b16ec8c05b9d466505e6a8c522e6", "best_bid": "0.931", "best_ask": "0.958"}, {"asset_id": "46775328864914034111636027140584666041009849439098120541770590397117980620796", "price": "0.314", "size": "20", "side": "SELL", "hash": "2cb52af9fb3c18f396209d50acce6bd7a0bc3bef", "best_bid": "0.042", "best_ask": "0.069"}], "timestamp": "1769384691465", "event_type": "price_change"}}
{"_local_timestamp": "2026-01-25T23:44:57.533536+00:00", "data": {"market": "0x326df6a10a6cdd74bdc1ef77906037e90b1f1d6dd1fdcbf6580aea62de094a96", "price_changes": [{"asset_id": "111947356992305187589428447311248216731582641625774563053368133120784997422919", "price": "0.29", "size": "50", "side": "BUY", "hash": "c58370fca8c461d55555bfdb766d6dc215e1cba6", "best_bid": "0.898", "best_ask": "0.914"}, {"asset_id": "80615165254308476859697533076369001631861513127578482097071314558553613438129", "price": "0.71", "size": "50", "side": "SELL", "hash": "381d7abf94cf38712291bb45ebec622fabab67f8", "best_bid": "0.086", "best_ask": "0.102"}], "timestamp": "1769384697459", "event_type": "price_change"}}
{"_local_timestamp": "2026-01-25T23:44:57.534354+00:00", "data": {"market": "0xa32587f6a3b3fa89d71c5648c526fe69791ef6593159e682f1ca5d4dc364f974", "price_changes": [{"asset_id": "54074938701699388770795173053719001491386817666951566814225682866135668313701", "price": "0.241", "size": "50", "side": "BUY", "hash": "1f2ab2d9fcdaeca4158c2def76c456668fdf7b51", "best_bid": "0.931", "best_ask": "0.958"}, {"asset_id": "46775328864914034111636027140584666041009849439098120541770590397117980620796", "price": "0.759", "size": "50", "side": "SELL", "hash": "ef0bdc91794123d9cdb9ec134ad8be2b60f0e523", "best_bid": "0.042", "best_ask": "0.069"}], "timestamp": "1769384697459", "event_type": "price_change"}}
{"_local_timestamp": "2026-01-25T23:44:57.683254+00:00", "data": {"market": "0xcfaa155abdb4c4447285c3fb08ce11273ad7b648cbc29b26bbc99a5d50a57688", "price_changes": [{"asset_id": "107532164421846439086348783344173461119922836080219299112376014605456903082560", "price": "0.201", "size": "5.6", "side": "BUY", "hash": "f9f914f02c509ef2f6086aa7267d152070f245dc", "best_bid": "0.801", "best_ask": "0.802"}, {"asset_id": "102123833290224736028606807214973577470974985146136880562573223000412048646565", "price": "0.799", "size": "5.6", "side": "SELL", "hash": "acfaa3eca7f0908f81eb67d3cf440e955c699d88", "best_bid": "0.198", "best_ask": "0.199"}], "timestamp": "1769384697618", "event_type": "price_change"}}
{"_local_timestamp": "2026-01-25T23:44:57.688485+00:00", "data": {"market": "0xa32587f6a3b3fa89d71c5648c526fe69791ef6593159e682f1ca5d4dc364f974", "price_changes": [{"asset_id": "54074938701699388770795173053719001491386817666951566814225682866135668313701", "price": "0.241", "size": "0", "side": "BUY", "hash": "26b8b103b2cfad93f07033d1aeb9f20b3a74424a", "best_bid": "0.931", "best_ask": "0.958"}, {"asset_id": "46775328864914034111636027140584666041009849439098120541770590397117980620796", "price": "0.759", "size": "0", "side": "SELL", "hash": "f07c6e46461738e20bd4e1548495800d443b48f6", "best_bid": "0.042", "best_ask": "0.069"}], "timestamp": "1769384697618", "event_type": "price_change"}}
{"_local_timestamp": "2026-01-25T23:44:57.689175+00:00", "data": {"market": "0xa32587f6a3b3fa89d71c5648c526fe69791ef6593159e682f1ca5d4dc364f974", "price_changes": [{"asset_id": "54074938701699388770795173053719001491386817666951566814225682866135668313701", "price": "0.29", "size": "89.65", "side": "BUY", "hash": "26b8b103b2cfad93f07033d1aeb9f20b3a74424a", "best_bid": "0.931", "best_ask": "0.958"}, {"asset_id": "46775328864914034111636027140584666041009849439098120541770590397117980620796", "price": "0.71", "size": "89.65", "side": "SELL", "hash": "f07c6e46461738e20bd4e1548495800d443b48f6", "best_bid": "0.042", "best_ask": "0.069"}], "timestamp": "1769384697618", "event_type": "price_change"}}
{"_local_timestamp": "2026-01-25T23:44:57.852393+00:00", "data": {"market": "0xa32587f6a3b3fa89d71c5648c526fe69791ef6593159e682f1ca5d4dc364f974", "price_changes": [{"asset_id": "54074938701699388770795173053719001491386817666951566814225682866135668313701", "price": "0.24", "size": "216.66", "side": "BUY", "hash": "565ad8c06512ee5fc3e5b681e4bc1780efda624b", "best_bid": "0.931", "best_ask": "0.958"}, {"asset_id": "46775328864914034111636027140584666041009849439098120541770590397117980620796", "price": "0.76", "size": "216.66", "side": "SELL", "hash": "1f5d9f84bbac72a13ece5932df0c828bb9434332", "best_bid": "0.042", "best_ask": "0.069"}], "timestamp": "1769384697742", "event_type": "price_change"}}
{"_local_timestamp": "2026-01-25T23:44:57.853376+00:00", "data": {"market": "0x326df6a10a6cdd74bdc1ef77906037e90b1f1d6dd1fdcbf6580aea62de094a96", "price_changes": [{"asset_id": "111947356992305187589428447311248216731582641625774563053368133120784997422919", "price": "0.27", "size": "276.29", "side": "BUY", "hash": "76fa66a6dc04592f8eab2f26681a3cdc4b68cf40", "best_bid": "0.898", "best_ask": "0.914"}, {"asset_id": "80615165254308476859697533076369001631861513127578482097071314558553613438129", "price": "0.73", "size": "276.29", "side": "SELL", "hash": "342894ccdc1f4ecc33de69c687472c752a39efd7", "best_bid": "0.086", "best_ask": "0.102"}], "timestamp": "1769384697742", "event_type": "price_change"}}
{"_local_timestamp": "2026-01-25T23:44:58.370092+00:00", "data": {"market": "0xcfaa155abdb4c4447285c3fb08ce11273ad7b648cbc29b26bbc99a5d50a57688", "price_changes": [{"asset_id": "107532164421846439086348783344173461119922836080219299112376014605456903082560", "price": "0.241", "size": "150", "side": "BUY", "hash": "78f0c9d610b93bdd9b5760a8256b78578c275868", "best_bid": "0.801", "best_ask": "0.802"}, {"asset_id": "102123833290224736028606807214973577470974985146136880562573223000412048646565", "price": "0.759", "size": "150", "side": "SELL", "hash": "01aeaf508d266d9ca3883b1b793c2459c4f801bc", "best_bid": "0.198", "best_ask": "0.199"}], "timestamp": "1769384698222", "event_type": "price_change"}}
{"_local_timestamp": "2026-01-25T23:44:58.370853+00:00", "data": {"market": "0xa32587f6a3b3fa89d71c5648c526fe69791ef6593159e682f1ca5d4dc364f974", "price_changes": [{"asset_id": "54074938701699388770795173053719001491386817666951566814225682866135668313701", "price": "0.291", "size": "250", "side": "BUY", "hash": "12fb6f01a3189aa94da4fe3f292beb9a926f28dd", "best_bid": "0.931", "best_ask": "0.958"}, {"asset_id": "46775328864914034111636027140584666041009849439098120541770590397117980620796", "price": "0.709", "size": "250", "side": "SELL", "hash": "e12aea1083ce638fb6edf601a78cbf1715b93fbd", "best_bid": "0.042", "best_ask": "0.069"}], "timestamp": "1769384698224", "event_type": "price_change"}}
{"_local_timestamp": "2026-01-25T23:44:58.476558+00:00", "data": {"market": "0xa32587f6a3b3fa89d71c5648c526fe69791ef6593159e682f1ca5d4dc364f974", "price_changes": [{"asset_id": "54074938701699388770795173053719001491386817666951566814225682866135668313701", "price": "0.2", "size": "950", "side": "BUY", "hash": "0e25c3bf201e1c1d4a2f0285c0be1640a9c761ac", "best_bid": "0.931", "best_ask": "0.958"}, {"asset_id": "46775328864914034111636027140584666041009849439098120541770590397117980620796", "price": "0.8", "size": "950", "side": "SELL", "hash": "73bd2d681a026dde42ae5f8198f04295945adcb3", "best_bid": "0.042", "best_ask": "0.069"}], "timestamp": "1769384698252", "event_type": "price_change"}}
{"_local_timestamp": "2026-01-25T23:45:08.311957+00:00", "data": {"market": "0xab77a311c7c175ff91707a06dcd358db7a7d7f4258fb7756b05b4f44d175914f", "price_changes": [{"asset_id": "96433559971245993197815501880637705319986922684384749364193086888126378928132", "price": "0.208", "size": "2023.39", "side": "BUY", "hash": "9eac58a4c4bfe4e2addd2a775f7f8ad66499171a", "best_bid": "0.869", "best_ask": "0.892"}, {"asset_id": "100716705141639838044649900187335811063814165386716787647982371091165872129354", "price": "0.792", "size": "2023.39", "side": "SELL", "hash": "691c589edf209f0f0ca02aaaff5ac7fd1b2f077e", "best_bid": "0.108", "best_ask": "0.131"}], "timestamp": "1769384708242", "event_type": "price_change"}}
{"_local_timestamp": "2026-01-25T23:45:11.452679+00:00", "data": {"market": "0xab77a311c7c175ff91707a06dcd358db7a7d7f4258fb7756b05b4f44d175914f", "price_changes": [{"asset_id": "100716705141639838044649900187335811063814165386716787647982371091165872129354", "price": "0.104", "size": "23.33", "side": "BUY", "hash": "31958109077839a1649d155c439a15cb73c30f50", "best_bid": "0.108", "best_ask": "0.131"}, {"asset_id": "96433559971245993197815501880637705319986922684384749364193086888126378928132", "price": "0.896", "size": "23.33", "side": "SELL", "hash": "5d080dd5176c6effb3bcafeaa8b6e652b01bedca", "best_bid": "0.869", "best_ask": "0.892"}], "timestamp": "1769384711351", "event_type": "price_change"}}
{"_local_timestamp": "2026-01-25T23:45:11.505051+00:00", "data": {"market": "0xab77a311c7c175ff91707a06dcd358db7a7d7f4258fb7756b05b4f44d175914f", "price_changes": [{"asset_id": "100716705141639838044649900187335811063814165386716787647982371091165872129354", "price": "0.1", "size": "223.33", "side": "BUY", "hash": "dc48b1ef4b906c282f66ff267ca91507fd53e5f7", "best_bid": "0.108", "best_ask": "0.131"}, {"asset_id": "96433559971245993197815501880637705319986922684384749364193086888126378928132", "price": "0.9", "size": "223.33", "side": "SELL", "hash": "6f537b661578ab5fdbf595ee0c151043d1e438f9", "best_bid": "0.869", "best_ask": "0.892"}], "timestamp": "1769384711418", "event_type": "price_change"}}
{"_local_timestamp": "2026-01-25T23:45:11.555738+00:00", "data": {"market": "0xab77a311c7c175ff91707a06dcd358db7a7d7f4258fb7756b05b4f44d175914f", "price_changes": [{"asset_id": "100716705141639838044649900187335811063814165386716787647982371091165872129354", "price": "0.109", "size": "23.33", "side": "BUY", "hash": "50542b4b36d85583971e0c3399ca86bd0d651d61", "best_bid": "0.109", "best_ask": "0.131"}, {"asset_id": "96433559971245993197815501880637705319986922684384749364193086888126378928132", "price": "0.891", "size": "23.33", "side": "SELL", "hash": "6a848f91ab84a3e51c4d8ec4dc628825ce0b92ea", "best_bid": "0.869", "best_ask": "0.891"}], "timestamp": "1769384711455", "event_type": "price_change"}}
{"_local_timestamp": "2026-01-25T23:45:11.775565+00:00", "data": {"market": "0xab77a311c7c175ff91707a06dcd358db7a7d7f4258fb7756b05b4f44d175914f", "price_changes": [{"asset_id": "96433559971245993197815501880637705319986922684384749364193086888126378928132", "price": "0.87", "size": "66.66", "side": "BUY", "hash": "57fba2fd7952af92ad76ca63333e25f29388ab4e", "best_bid": "0.87", "best_ask": "0.891"}, {"asset_id": "100716705141639838044649900187335811063814165386716787647982371091165872129354", "price": "0.13", "size": "66.66", "side": "SELL", "hash": "14e9fb18fe3e4888b6b9a7f0d8713a0be4709598", "best_bid": "0.109", "best_ask": "0.13"}], "timestamp": "1769384711692", "event_type": "price_change"}}
{"_local_timestamp": "2026-01-25T23:45:11.793284+00:00", "data": {"market": "0xab77a311c7c175ff91707a06dcd358db7a7d7f4258fb7756b05b4f44d175914f", "price_changes": [{"asset_id": "96433559971245993197815501880637705319986922684384749364193086888126378928132", "price": "0.802", "size": "66.66", "side": "BUY", "hash": "009f30387e4983d9c8af943676e606ee894c332e", "best_bid": "0.87", "best_ask": "0.891"}, {"asset_id": "100716705141639838044649900187335811063814165386716787647982371091165872129354", "price": "0.198", "size": "66.66", "side": "SELL", "hash": "bc905be8dbbfbba9f0fb0fd0dac58e29755cc80b", "best_bid": "0.109", "best_ask": "0.13"}], "timestamp": "1769384711715", "event_type": "price_change"}}
{"_local_timestamp": "2026-01-25T23:45:11.871758+00:00", "data": {"market": "0xab77a311c7c175ff91707a06dcd358db7a7d7f4258fb7756b05b4f44d175914f", "price_changes": [{"asset_id": "96433559971245993197815501880637705319986922684384749364193086888126378928132", "price": "0.736", "size": "66.66", "side": "BUY", "hash": "d210fe121edf53ab82944d754dfe74a437ea45b2", "best_bid": "0.87", "best_ask": "0.891"}, {"asset_id": "100716705141639838044649900187335811063814165386716787647982371091165872129354", "price": "0.264", "size": "66.66", "side": "SELL", "hash": "1e8b6a2924842658a5f3a14a0007150572739ca9", "best_bid": "0.109", "best_ask": "0.13"}], "timestamp": "1769384711782", "event_type": "price_change"}}
{"_local_timestamp": "2026-01-25T23:45:12.044459+00:00", "data": {"market": "0xab77a311c7c175ff91707a06dcd358db7a7d7f4258fb7756b05b4f44d175914f", "price_changes": [{"asset_id": "100716705141639838044649900187335811063814165386716787647982371091165872129354", "price": "0.107", "size": "140.36", "side": "BUY", "hash": "a6babe6788a791dc4d7ad6780f9095f7929732d5", "best_bid": "0.109", "best_ask": "0.13"}, {"asset_id": "96433559971245993197815501880637705319986922684384749364193086888126378928132", "price": "0.893", "size": "140.36", "side": "SELL", "hash": "8481ec1de82409ec8f0de922dfd4a264bd657293", "best_bid": "0.87", "best_ask": "0.891"}], "timestamp": "1769384711932", "event_type": "price_change"}}
{"_local_timestamp": "2026-01-25T23:45:12.498812+00:00", "data": {"market": "0xab77a311c7c175ff91707a06dcd358db7a7d7f4258fb7756b05b4f44d175914f", "price_changes": [{"asset_id": "100716705141639838044649900187335811063814165386716787647982371091165872129354", "price": "0.131", "size": "0", "side": "SELL", "hash": "47638dd67a6dbf7a958cf6ab05b4a3f19d2aa392", "best_bid": "0.109", "best_ask": "0.13"}, {"asset_id": "96433559971245993197815501880637705319986922684384749364193086888126378928132", "price": "0.869", "size": "0", "side": "BUY", "hash": "80fcadfa6bd0b7718cebf78fa7c3ea9def3017f9", "best_bid": "0.87", "best_ask": "0.891"}], "timestamp": "1769384712429", "event_type": "price_change"}}
{"_local_timestamp": "2026-01-25T23:45:12.906609+00:00", "data": {"market": "0xab77a311c7c175ff91707a06dcd358db7a7d7f4258fb7756b05b4f44d175914f", "price_changes": [{"asset_id": "100716705141639838044649900187335811063814165386716787647982371091165872129354", "price": "0.094", "size": "35", "side": "BUY", "hash": "20e26e6cd085ab61f384344e4089e3c503b8737d", "best_bid": "0.109", "best_ask": "0.13"}, {"asset_id": "96433559971245993197815501880637705319986922684384749364193086888126378928132", "price": "0.906", "size": "35", "side": "SELL", "hash": "a7ff008ce8f8fa35cfc2793d5a8047d589dcc292", "best_bid": "0.87", "best_ask": "0.891"}], "timestamp": "1769384712840", "event_type": "price_change"}}
{"_local_timestamp": "2026-01-25T23:45:13.728320+00:00", "data": {"market": "0xcfaa155abdb4c4447285c3fb08ce11273ad7b648cbc29b26bbc99a5d50a57688", "price_changes": [{"asset_id": "107532164421846439086348783344173461119922836080219299112376014605456903082560", "price": "0.544", "size": "0", "side": "BUY", "hash": "4a5e93e9acbe99150fc0a41e288bd4d92dd9bf5b", "best_bid": "0.801", "best_ask": "0.802"}, {"asset_id": "102123833290224736028606807214973577470974985146136880562573223000412048646565", "price": "0.456", "size": "0", "side": "SELL", "hash": "726846b9594ea16005697e01d2e78d3905dfae5a", "best_bid": "0.198", "best_ask": "0.199"}], "timestamp": "1769384713663", "event_type": "price_change"}}
{"_local_timestamp": "2026-01-25T23:45:13.729114+00:00", "data": {"market": "0x326df6a10a6cdd74bdc1ef77906037e90b1f1d6dd1fdcbf6580aea62de094a96", "price_changes": [{"asset_id": "111947356992305187589428447311248216731582641625774563053368133120784997422919", "price": "0.718", "size": "13.33", "side": "BUY", "hash": "8b51b35993edf54476f06facedc3f7b390c00b62", "best_bid": "0.898", "best_ask": "0.914"}, {"asset_id": "80615165254308476859697533076369001631861513127578482097071314558553613438129", "price": "0.282", "size": "13.33", "side": "SELL", "hash": "b126062f2851ebb2213f9856e8081d896510070a", "best_bid": "0.086", "best_ask": "0.102"}], "timestamp": "1769384713663", "event_type": "price_change"}}
{"_local_timestamp": "2026-01-25T23:45:13.766081+00:00", "data": {"market": "0xcfaa155abdb4c4447285c3fb08ce11273ad7b648cbc29b26bbc99a5d50a57688", "price_changes": [{"asset_id": "107532164421846439086348783344173461119922836080219299112376014605456903082560", "price": "0.608", "size": "60", "side": "BUY", "hash": "1cd9aecaab6b4d3cfa02c7838edb6d86474705ba", "best_bid": "0.801", "best_ask": "0.802"}, {"asset_id": "102123833290224736028606807214973577470974985146136880562573223000412048646565", "price": "0.392", "size": "60", "side": "SELL", "hash": "eb4bb9ef9740a18b712cda99dbca7633adbf183b", "best_bid": "0.198", "best_ask": "0.199"}], "timestamp": "1769384713697", "event_type": "price_change"}}
{"_local_timestamp": "2026-01-25T23:45:13.766861+00:00", "data": {"market": "0x326df6a10a6cdd74bdc1ef77906037e90b1f1d6dd1fdcbf6580aea62de094a96", "price_changes": [{"asset_id": "111947356992305187589428447311248216731582641625774563053368133120784997422919", "price": "0.719", "size": "20", "side": "BUY", "hash": "4ec3bd8c706a813dc8d5d6886885d487b63051bb", "best_bid": "0.898", "best_ask": "0.914"}, {"asset_id": "80615165254308476859697533076369001631861513127578482097071314558553613438129", "price": "0.281", "size": "20", "side": "SELL", "hash": "43516be9659e6b7519e20c340b1a94fed0cd6574", "best_bid": "0.086", "best_ask": "0.102"}], "timestamp": "1769384713697", "event_type": "price_change"}}
{"_local_timestamp": "2026-01-25T23:45:16.556703+00:00", "data": {"market": "0xab77a311c7c175ff91707a06dcd358db7a7d7f4258fb7756b05b4f44d175914f", "price_changes": [{"asset_id": "100716705141639838044649900187335811063814165386716787647982371091165872129354", "price": "0.098", "size": "400", "side": "BUY", "hash": "83650f832abbe26a9d1d52b423564c0bae3e1d11", "best_bid": "0.109", "best_ask": "0.13"}, {"asset_id": "96433559971245993197815501880637705319986922684384749364193086888126378928132", "price": "0.902", "size": "400", "side": "SELL", "hash": "9d4d54e94a0207eadf6e977d97fa6d80d3f43bd2", "best_bid": "0.87", "best_ask": "0.891"}], "timestamp": "1769384716487", "event_type": "price_change"}}
{"_local_timestamp": "2026-01-25T23:45:16.849012+00:00", "data": {"market": "0xa32587f6a3b3fa89d71c5648c526fe69791ef6593159e682f1ca5d4dc364f974", "price_changes": [{"asset_id": "54074938701699388770795173053719001491386817666951566814225682866135668313701", "price": "0.242", "size": "1734", "side": "BUY", "hash": "d231c9bf3ecc7a65366f6bb74d43adc300ae01aa", "best_bid": "0.931", "best_ask": "0.958"}, {"asset_id": "46775328864914034111636027140584666041009849439098120541770590397117980620796", "price": "0.758", "size": "1734", "side": "SELL", "hash": "624937721b58bdf6e502e18d5d6c774dfd4ef5d6", "best_bid": "0.042", "best_ask": "0.069"}], "timestamp": "1769384716776", "event_type": "price_change"}}
{"_local_timestamp": "2026-01-25T23:45:18.655417+00:00", "data": {"market": "0x326df6a10a6cdd74bdc1ef77906037e90b1f1d6dd1fdcbf6580aea62de094a96", "price_changes": [{"asset_id": "111947356992305187589428447311248216731582641625774563053368133120784997422919", "price": "0.271", "size": "1548", "side": "BUY", "hash": "467ef1c68294178362d1589ae5e2c9f9270d94b8", "best_bid": "0.898", "best_ask": "0.914"}, {"asset_id": "80615165254308476859697533076369001631861513127578482097071314558553613438129", "price": "0.729", "size": "1548", "side": "SELL", "hash": "dcac8b6cec84d3718814cfb6f93452636a61e1c9", "best_bid": "0.086", "best_ask": "0.102"}], "timestamp": "1769384718585", "event_type": "price_change"}}
{"_local_timestamp": "2026-01-25T23:45:18.813439+00:00", "data": {"market": "0xab77a311c7c175ff91707a06dcd358db7a7d7f4258fb7756b05b4f44d175914f", "price_changes": [{"asset_id": "96433559971245993197815501880637705319986922684384749364193086888126378928132", "price": "0.47", "size": "0", "side": "BUY", "hash": "e33622aa8cd981109fd448f852c247323665c4b7", "best_bid": "0.87", "best_ask": "0.891"}, {"asset_id": "100716705141639838044649900187335811063814165386716787647982371091165872129354", "price": "0.53", "size": "0", "side": "SELL", "hash": "903edfd6adc461649e6f11a3c011e79b0438000a", "best_bid": "0.109", "best_ask": "0.13"}], "timestamp": "1769384718736", "event_type": "price_change"}}
{"_local_timestamp": "2026-01-25T23:45:18.841418+00:00", "data": {"market": "0x326df6a10a6cdd74bdc1ef77906037e90b1f1d6dd1fdcbf6580aea62de094a96", "price_changes": [{"asset_id": "111947356992305187589428447311248216731582641625774563053368133120784997422919", "price": "0.27", "size": "146.29", "side": "BUY", "hash": "3596ebf554a8759665755f6529a3b9541206c0ac", "best_bid": "0.898", "best_ask": "0.914"}, {"asset_id": "80615165254308476859697533076369001631861513127578482097071314558553613438129", "price": "0.73", "size": "146.29", "side": "SELL", "hash": "4cbcc927a791dec29ede67192479db05358bdff0", "best_bid": "0.086", "best_ask": "0.102"}], "timestamp": "1769384718773", "event_type": "price_change"}}
{"_local_timestamp": "2026-01-25T23:45:18.946404+00:00", "data": {"market": "0xab77a311c7c175ff91707a06dcd358db7a7d7f4258fb7756b05b4f44d175914f", "price_changes": [{"asset_id": "96433559971245993197815501880637705319986922684384749364193086888126378928132", "price": "0.476", "size": "30", "side": "BUY", "hash": "1d3900332402c6d236c44b062e1d144188f4cd8d", "best_bid": "0.87", "best_ask": "0.891"}, {"asset_id": "100716705141639838044649900187335811063814165386716787647982371091165872129354", "price": "0.524", "size": "30", "side": "SELL", "hash": "370a954b2d4cc661122066439ada4d7c0851d3ff", "best_bid": "0.109", "best_ask": "0.13"}], "timestamp": "1769384718856", "event_type": "price_change"}}
{"_local_timestamp": "2026-01-25T23:45:18.985932+00:00", "data": {"market": "0x326df6a10a6cdd74bdc1ef77906037e90b1f1d6dd1fdcbf6580aea62de094a96", "price_changes": [{"asset_id": "111947356992305187589428447311248216731582641625774563053368133120784997422919", "price": "0.272", "size": "343", "side": "BUY", "hash": "80a62df570406768ae0b5718a4883dd05ff42922", "best_bid": "0.898", "best_ask": "0.914"}, {"asset_id": "80615165254308476859697533076369001631861513127578482097071314558553613438129", "price": "0.728", "size": "343", "side": "SELL", "hash": "ba04e330f7ce968547b74290553745d4adad4e2f", "best_bid": "0.086", "best_ask": "0.102"}], "timestamp": "1769384718921", "event_type": "price_change"}}
{"_local_timestamp": "2026-01-25T23:45:22.517062+00:00", "data": {"market": "0xab77a311c7c175ff91707a06dcd358db7a7d7f4258fb7756b05b4f44d175914f", "price_changes": [{"asset_id": "100716705141639838044649900187335811063814165386716787647982371091165872129354", "price": "0.129", "size": "20.98", "side": "SELL", "hash": "852b6093c16a08477c0e36f646e3518783d8fb65", "best_bid": "0.109", "best_ask": "0.129"}, {"asset_id": "96433559971245993197815501880637705319986922684384749364193086888126378928132", "price": "0.871", "size": "20.98", "side": "BUY", "hash": "28303c24c93078523cc01658eecde090e6a69497", "best_bid": "0.871", "best_ask": "0.891"}], "timestamp": "1769384722448", "event_type": "price_change"}}
{"_local_timestamp": "2026-01-25T23:45:22.689655+00:00", "data": {"market": "0xab77a311c7c175ff91707a06dcd358db7a7d7f4258fb7756b05b4f44d175914f", "price_changes": [{"asset_id": "96433559971245993197815501880637705319986922684384749364193086888126378928132", "price": "0.475", "size": "0", "side": "BUY", "hash": "0768a23a8920418d565c8e3a3c15cfa66e9ce2d8", "best_bid": "0.871", "best_ask": "0.891"}, {"asset_id": "100716705141639838044649900187335811063814165386716787647982371091165872129354", "price": "0.525", "size": "0", "side": "SELL", "hash": "3defee652ebe9ef816ec324dc79f45a711baec80", "best_bid": "0.109", "best_ask": "0.129"}], "timestamp": "1769384722616", "event_type": "price_change"}}
{"_local_timestamp": "2026-01-25T23:45:22.709750+00:00", "data": {"market": "0xab77a311c7c175ff91707a06dcd358db7a7d7f4258fb7756b05b4f44d175914f", "price_changes": [{"asset_id": "96433559971245993197815501880637705319986922684384749364193086888126378928132", "price": "0.477", "size": "20", "side": "BUY", "hash": "fe4ebf77015143ef407a1d03809a0769ffb6ab9f", "best_bid": "0.871", "best_ask": "0.891"}, {"asset_id": "100716705141639838044649900187335811063814165386716787647982371091165872129354", "price": "0.523", "size": "20", "side": "SELL", "hash": "d3e2f76c964367f12c2c95ca993de86b5b46dd85", "best_bid": "0.109", "best_ask": "0.129"}], "timestamp": "1769384722644", "event_type": "price_change"}}
