{"_local_timestamp": "2026-01-25T23:33:17.031400+00:00", "data": [{"market": "0xc55db914f0fd1fee18997706712c0dfd8d0369cdbef93a9fef12bd001914ca77", "asset_id": "114600293444080540179603459515770723592661967180480327891296353898330242622833", "timestamp": "1769383920514", "hash": "248ee2c60300141ae9b73ea25a94ef90fc622b75", "bids": [{"price": "0.001", "size": "8674.77"}, {"price": "0.002", "size": "5.25"}, {"price": "0.003", "size": "1400"}, {"price": "0.004", "size": "9.09"}, {"price": "0.006", "size": "200"}, {"price": "0.01", "size": "23"}, {"price": "0.011", "size": "17.97"}, {"price": "0.03", "size": "2500"}, {"price": "0.035", "size": "2999.96"}, {"price": "0.05", "size": "540"}, {"price": "0.051", "size": "11.87"}, {"price": "0.1", "size": "360"}, {"price": "0.15", "size": "226.66"}, {"price": "0.2", "size": "160"}, {"price": "0.201", "size": "5.69"}, {"price": "0.223", "size": "165"}, {"price": "0.25", "size": "112"}, {"price": "0.3", "size": "86.66"}, {"price": "0.35", "size": "68.57"}, {"price": "0.4", "size": "50"}, {"price": "0.435", "size": "586.12"}, {"price": "0.48", "size": "5"}, {"price": "0.523", "size": "350"}, {"price": "0.524", "size": "3620"}, {"price": "0.525", "size": "5"}, {"price": "0.723", "size": "179"}, {"price": "0.823", "size": "189"}, {"price": "0.836", "size": "231.9"}, {"price": "0.837", "size": "298"}, {"price": "0.838", "size": "238"}, {"price": "0.88", "size": "10"}, {"price": "0.881", "size": "20"}, {"price": "0.885", "size": "25"}, {"price": "0.923", "size": "762"}, {"price": "0.959", "size": "486"}, {"price": "0.975", "size": "1202.94"}, {"price": "0.977", "size": "100"}, {"price": "0.98", "size": "1699.98"}, {"price": "0.982", "size": "300"}, {"price": "0.984", "size": "160"}, {"price": "0.985", "size": "148.52"}, {"price": "0.986", "size": "1396"}, {"price": "0.988", "size": "526.11"}, {"price": "0.989", "size": "256.36"}, {"price": "0.99", "size": "99.99"}, {"price": "0.991", "size": "531.88"}, {"price": "0.993", "size": "28.91"}], "asks": [{"price": "0.999", "size": "13733.28"}], "event_type": "book", "last_trade_price": "0.001"}, {"market": "0x9472be65457510b7fc3477b20ba90910e99d92eac8421a14bf4b7b7a08ef31dc", "asset_id": "73414222381656326204771753454630063673548497164758947581648273905027617570612", "timestamp": "1769383961076", "hash": "72796f51684aa7d64eaaacc8b158612ecb13f93d", "bids": [{"price": "0.001", "size": "13015.1"}, {"price": "0.002", "size": "139.66"}], "asks": [{"price": "0.999", "size": "7393.14"}, {"price": "0.998", "size": "5.24"}, {"price": "0.997", "size": "1400"}, {"price": "0.996", "size": "9.09"}, {"price": "0.994", "size": "200"}, {"price": "0.99", "size": "23"}, {"price": "0.989", "size": "17.96"}, {"price": "0.97", "size": "2500"}, {"price": "0.963", "size": "3000"}, {"price": "0.95", "size": "380"}, {"price": "0.949", "size": "11.87"}, {"price": "0.9", "size": "360"}, {"price": "0.85", "size": "226.66"}, {"price": "0.8", "size": "160"}, {"price": "0.799", "size": "5.69"}, {"price": "0.777", "size": "165"}, {"price": "0.75", "size": "112"}, {"price": "0.7", "size": "86.66"}, {"price": "0.65", "size": "68.57"}, {"price": "0.6", "size": "50"}, {"price": "0.553", "size": "1000"}, {"price": "0.542", "size": "5197"}, {"price": "0.541", "size": "268"}, {"price": "0.52", "size": "5"}, {"price": "0.477", "size": "150"}, {"price": "0.33", "size": "5"}, {"price": "0.277", "size": "88"}, {"price": "0.177", "size": "190"}, {"price": "0.13", "size": "10"}, {"price": "0.129", "size": "20"}, {"price": "0.117", "size": "25"}, {"price": "0.077", "size": "399"}, {"price": "0.075", "size": "756"}, {"price": "0.062", "size": "408.81"}, {"price": "0.041", "size": "613.23"}, {"price": "0.025", "size": "1796.98"}, {"price": "0.023", "size": "150"}, {"price": "0.022", "size": "306.61"}, {"price": "0.021", "size": "145"}, {"price": "0.02", "size": "460.33"}, {"price": "0.018", "size": "376.79"}, {"price": "0.015", "size": "88.12"}, {"price": "0.014", "size": "1796.98"}, {"price": "0.013", "size": "341.69"}, {"price": "0.01", "size": "50"}, {"price": "0.009", "size": "263.98"}, {"price": "0.007", "size": "495.05"}, {"price": "0.006", "size": "1580.14"}, {"price": "0.005", "size": "973.54"}], "event_type": "book", "last_trade_price": "0.002"}, {"market": "0x2393ed0b0fdc450054c7b9071907eca75cf4fc36e385adf4a0a5f99ee62243e8", "asset_id": "32769749367306925959219403371425714180265458150646381231272229429098460625924", "timestamp": "1769383996591", "hash": "0109a740579b937cc9a6c03b75870be712ee3ac8", "bids": [{"price": "0.001", "size": "4369.63"}, {"price": "0.002", "size": "1255.29"}, {"price": "0.003", "size": "1400"}, {"price": "0.004", "size": "9.17"}, {"price": "0.006", "size": "200"}, {"price": "0.01", "size": "453"}, {"price": "0.011", "size": "21.1"}, {"price": "0.03", "size": "1561.08"}, {"price": "0.05", "size": "210"}, {"price": "0.057", "size": "1821.72"}, {"price": "0.058", "size": "9.32"}, {"price": "0.1", "size": "365.12"}, {"price": "0.14", "size": "242.85"}, {"price": "0.19", "size": "168.42"}, {"price": "0.191", "size": "6.14"}, {"price": "0.24", "size": "116.66"}, {"price": "0.25", "size": "700"}, {"price": "0.259", "size": "300"}, {"price": "0.26", "size": "5341"}, {"price": "0.29", "size": "89.65"}, {"price": "0.34", "size": "70.58"}, {"price": "0.38", "size": "52.63"}, {"price": "0.4", "size": "16.54"}, {"price": "0.477", "size": "284.58"}, {"price": "0.51", "size": "399"}, {"price": "0.511", "size": "400"}, {"price": "0.512", "size": "5"}, {"price": "0.829", "size": "120"}, {"price": "0.835", "size": "119"}, {"price": "0.836", "size": "20"}, {"price": "0.847", "size": "25"}, {"price": "0.883", "size": "259.4"}, {"price": "0.889", "size": "453.84"}, {"price": "0.895", "size": "30"}, {"price": "0.897", "size": "30"}, {"price": "0.9", "size": "141"}, {"price": "0.917", "size": "50"}, {"price": "0.918", "size": "5"}], "asks": [{"price": "0.999", "size": "832.39"}, {"price": "0.998", "size": "2100"}, {"price": "0.997", "size": "3507.68"}, {"price": "0.995", "size": "1311"}, {"price": "0.994", "size": "6.27"}, {"price": "0.993", "size": "50"}, {"price": "0.99", "size": "457.99"}, {"price": "0.989", "size": "14.68"}, {"price": "0.975", "size": "30.53"}, {"price": "0.972", "size": "9.4"}, {"price": "0.967", "size": "199.82"}, {"price": "0.961", "size": "88.8"}, {"price": "0.96", "size": "60"}, {"price": "0.959", "size": "118"}], "event_type": "book", "last_trade_price": "0.111"}, {"market": "0x44f08744458b8896620cd3330bc5e1ea69df4199b02d4fc583b3fc96e5d314ce", "asset_id": "72327831507226612545928776794104143393438710920370371172884559893525100761096", "timestamp": "1769383922452", "hash": "839ff033371daa5b581e84d5f43e9a1fb2436a56", "bids": [{"price": "0.001", "size": "3630.98"}, {"price": "0.002", "size": "1255.25"}, {"price": "0.003", "size": "1400"}, {"price": "0.004", "size": "9.1"}, {"price": "0.006", "size": "200"}, {"price": "0.01", "size": "23"}, {"price": "0.011", "size": "7.83"}, {"price": "0.027", "size": "777"}, {"price": "0.028", "size": "5.16"}, {"price": "0.032", "size": "510"}, {"price": "0.033", "size": "420"}, {"price": "0.05", "size": "650"}, {"price": "0.052", "size": "353"}, {"price": "0.054", "size": "450"}, {"price": "0.056", "size": "377"}, {"price": "0.057", "size": "3200"}, {"price": "0.058", "size": "9.87"}, {"price": "0.1", "size": "360"}, {"price": "0.15", "size": "226.66"}, {"price": "0.2", "size": "160"}, {"price": "0.201", "size": "5.69"}, {"price": "0.25", "size": "600.64"}, {"price": "0.3", "size": "86.66"}, {"price": "0.35", "size": "68.57"}, {"price": "0.4", "size": "200"}, {"price": "0.401", "size": "4735"}, {"price": "0.402", "size": "5"}, {"price": "0.48", "size": "85"}, {"price": "0.54", "size": "30"}, {"price": "0.55", "size": "50"}, {"price": "0.58", "size": "30"}, {"price": "0.62", "size": "40"}, {"price": "0.68", "size": "30"}, {"price": "0.71", "size": "30"}, {"price": "0.72", "size": "111.11"}, {"price": "0.725", "size": "200"}, {"price": "0.76", "size": "40"}, {"price": "0.79", "size": "30"}, {"price": "0.804", "size": "261.26"}, {"price": "0.81", "size": "30"}, {"price": "0.83", "size": "406.49"}, {"price": "0.86", "size": "50"}, {"price": "0.861", "size": "10"}, {"price": "0.87", "size": "10"}, {"price": "0.874", "size": "125.46"}, {"price": "0.876", "size": "20"}, {"price": "0.877", "size": "20"}, {"price": "0.899", "size": "651.53"}, {"price": "0.901", "size": "25"}, {"price": "0.925", "size": "868.7"}, {"price": "0.935", "size": "732.97"}, {"price": "0.949", "size": "385"}, {"price": "0.952", "size": "539.8"}, {"price": "0.963", "size": "809.7"}, {"price": "0.972", "size": "404.86"}, {"price": "0.973", "size": "114.7"}, {"price": "0.979", "size": "304.49"}, {"price": "0.98", "size": "319"}, {"price": "0.983", "size": "367.57"}, {"price": "0.984", "size": "60"}, {"price": "0.985", "size": "10.6"}], "asks": [{"price": "0.999", "size": "7843.07"}, {"price": "0.998", "size": "2570.71"}, {"price": "0.997", "size": "2000"}], "event_type": "book", "last_trade_price": "0.006"}, {"market": "0x49686d26fb712515cd5e12c23f0a1c7e10214c7faa3cb0a730aabe0c33694082", "asset_id": "13244681086321087932946246027856416106585284024824496763706748621681543444582", "timestamp": "1769383996116", "hash": "ba9f7f354d841eb91f4fc3077f4bfe7440d7d6cb", "bids": [{"price": "0.001", "size": "4291.7"}, {"price": "0.002", "size": "1250"}, {"price": "0.003", "size": "1000"}, {"price": "0.004", "size": "7.14"}, {"price": "0.01", "size": "23"}, {"price": "0.03", "size": "2000"}, {"price": "0.031", "size": "6.24"}, {"price": "0.05", "size": "30"}, {"price": "0.09", "size": "400"}, {"price": "0.091", "size": "3296"}, {"price": "0.14", "size": "242.85"}, {"price": "0.141", "size": "1134"}, {"price": "0.18", "size": "177.77"}, {"price": "0.181", "size": "882"}, {"price": "0.23", "size": "121.73"}, {"price": "0.248", "size": "300"}, {"price": "0.25", "size": "400"}, {"price": "0.251", "size": "1672"}, {"price": "0.27", "size": "96.29"}, {"price": "0.28", "size": "204.64"}, {"price": "0.32", "size": "2075"}, {"price": "0.35", "size": "5"}, {"price": "0.36", "size": "55.55"}, {"price": "0.635", "size": "30"}, {"price": "0.75", "size": "40"}, {"price": "0.751", "size": "10"}, {"price": "0.83", "size": "1500"}, {"price": "0.85", "size": "15"}, {"price": "0.86", "size": "948.91"}, {"price": "0.862", "size": "178.68"}, {"price": "0.865", "size": "103.1"}, {"price": "0.867", "size": "265.14"}], "asks": [{"price": "0.999", "size": "2020.07"}, {"price": "0.998", "size": "2361.62"}, {"price": "0.997", "size": "18.57"}, {"price": "0.995", "size": "99.51"}, {"price": "0.994", "size": "7.67"}, {"price": "0.993", "size": "150"}, {"price": "0.992", "size": "8.58"}, {"price": "0.99", "size": "376.91"}, {"price": "0.989", "size": "10.31"}, {"price": "0.988", "size": "5401.42"}, {"price": "0.985", "size": "111"}, {"price": "0.984", "size": "27.01"}, {"price": "0.98", "size": "41"}, {"price": "0.979", "size": "6.24"}, {"price": "0.97", "size": "363.11"}, {"price": "0.969", "size": "5.73"}, {"price": "0.963", "size": "137.49"}, {"price": "0.962", "size": "500"}, {"price": "0.96", "size": "272.33"}, {"price": "0.959", "size": "25"}, {"price": "0.958", "size": "10.42"}, {"price": "0.95", "size": "204.25"}, {"price": "0.94", "size": "153.18"}, {"price": "0.939", "size": "70"}, {"price": "0.937", "size": "5.71"}, {"price": "0.93", "size": "114.89"}, {"price": "0.92", "size": "86.17"}, {"price": "0.919", "size": "5.78"}, {"price": "0.91", "size": "64.62"}, {"price": "0.904", "size": "36.5"}, {"price": "0.9", "size": "48.47"}, {"price": "0.898", "size": "134.85"}, {"price": "0.897", "size": "30"}, {"price": "0.896", "size": "40.31"}], "event_type": "book", "last_trade_price": "0.867"}, {"market": "0x2393ed0b0fdc450054c7b9071907eca75cf4fc36e385adf4a0a5f99ee62243e8", "asset_id": "100074770378634056601572485653252702850363676459996771990439989989293515601975", "timestamp": "1769383996591", "hash": "26395006d15fd04aec29cde6e15d19770759020f", "bids": [{"price": "0.001", "size": "832.39"}, {"price": "0.002", "size": "2100"}, {"price": "0.003", "size": "3507.68"}, {"price": "0.005", "size": "1311"}, {"price": "0.006", "size": "6.27"}, {"price": "0.007", "size": "50"}, {"price": "0.01", "size": "457.99"}, {"price": "0.011", "size": "14.68"}, {"price": "0.025", "size": "30.53"}, {"price": "0.028", "size": "9.4"}, {"price": "0.033", "size": "199.82"}, {"price": "0.039", "size": "88.8"}, {"price": "0.04", "size": "60"}, {"price": "0.041", "size": "118"}], "asks": [{"price": "0.999", "size": "4369.63"}, {"price": "0.998", "size": "1255.29"}, {"price": "0.997", "size": "1400"}, {"price": "0.996", "size": "9.17"}, {"price": "0.994", "size": "200"}, {"price": "0.99", "size": "453"}, {"price": "0.989", "size": "21.1"}, {"price": "0.97", "size": "1561.08"}, {"price": "0.95", "size": "210"}, {"price": "0.943", "size": "1821.72"}, {"price": "0.942", "size": "9.32"}, {"price": "0.9", "size": "365.12"}, {"price": "0.86", "size": "242.85"}, {"price": "0.81", "size": "168.42"}, {"price": "0.809", "size": "6.14"}, {"price": "0.76", "size": "116.66"}, {"price": "0.75", "size": "700"}, {"price": "0.741", "size": "300"}, {"price": "0.74", "size": "5341"}, {"price": "0.71", "size": "89.65"}, {"price": "0.66", "size": "70.58"}, {"price": "0.62", "size": "52.63"}, {"price": "0.6", "size": "16.54"}, {"price": "0.523", "size": "284.58"}, {"price": "0.49", "size": "399"}, {"price": "0.489", "size": "400"}, {"price": "0.488", "size": "5"}, {"price": "0.171", "size": "120"}, {"price": "0.165", "size": "119"}, {"price": "0.164", "size": "20"}, {"price": "0.153", "size": "25"}, {"price": "0.117", "size": "259.4"}, {"price": "0.111", "size": "453.84"}, {"price": "0.105", "size": "30"}, {"price": "0.103", "size": "30"}, {"price": "0.1", "size": "141"}, {"price": "0.083", "size": "50"}, {"price": "0.082", "size": "5"}], "event_type": "book", "last_trade_price": "0.111"}, {"market": "0x50c669f178da4e5bbea7f1be25041fd278914712fa87a6a6f8e57d5923d88dee", "asset_id": "74040420326294854165772767082819937451857852955603897473157746262672057685461", "timestamp": "1769383994676", "hash": "a4b5c262a1a1471da2f16a76554d77dfa693b282", "bids": [{"price": "0.001", "size": "7167.15"}, {"price": "0.002", "size": "5.24"}, {"price": "0.003", "size": "1400"}, {"price": "0.004", "size": "9.09"}, {"price": "0.006", "size": "200"}, {"price": "0.01", "size": "23"}, {"price": "0.011", "size": "17.96"}, {"price": "0.029", "size": "3000"}, {"price": "0.05", "size": "40"}, {"price": "0.051", "size": "11.87"}, {"price": "0.1", "size": "360"}, {"price": "0.15", "size": "226.66"}, {"price": "0.2", "size": "165"}, {"price": "0.201", "size": "5.69"}, {"price": "0.223", "size": "154"}, {"price": "0.25", "size": "112"}, {"price": "0.3", "size": "86.66"}, {"price": "0.35", "size": "68.57"}, {"price": "0.4", "size": "50"}, {"price": "0.42", "size": "555"}, {"price": "0.467", "size": "1000"}, {"price": "0.468", "size": "5089"}, {"price": "0.469", "size": "5"}, {"price": "0.523", "size": "158"}, {"price": "0.6", "size": "5"}, {"price": "0.723", "size": "256"}, {"price": "0.823", "size": "219"}, {"price": "0.824", "size": "10"}, {"price": "0.87", "size": "10"}, {"price": "0.871", "size": "25"}, {"price": "0.878", "size": "295.98"}, {"price": "0.881", "size": "40"}, {"price": "0.908", "size": "282.51"}, {"price": "0.923", "size": "1785"}, {"price": "0.931", "size": "856"}, {"price": "0.95", "size": "62.24"}, {"price": "0.968", "size": "44.99"}, {"price": "0.975", "size": "1202.94"}, {"price": "0.977", "size": "100"}, {"price": "0.98", "size": "403.96"}, {"price": "0.984", "size": "100.1"}, {"price": "0.986", "size": "2905.56"}, {"price": "0.992", "size": "996.44"}, {"price": "0.993", "size": "991.09"}, {"price": "0.995", "size": "815.95"}], "asks": [{"price": "0.999", "size": "10101.55"}, {"price": "0.998", "size": "141.7"}], "event_type": "book", "last_trade_price": "0.002"}, {"market": "0xb9bbdd34304344dcc45803780a34c97d73a00133a5ecf70f63e1008b8abb2fca", "asset_id": "8682484153073832526711485265636767086525069344085206423986003504588877767339", "timestamp": "1769383994676", "hash": "24a91b8be472fe9418fe70251c466b98ff696978", "bids": [{"price": "0.001", "size": "6098.33"}, {"price": "0.003", "size": "1400"}, {"price": "0.006", "size": "200"}, {"price": "0.01", "size": "23"}, {"price": "0.05", "size": "40"}, {"price": "0.051", "size": "2942.02"}, {"price": "0.1", "size": "637.06"}, {"price": "0.15", "size": "226.66"}, {"price": "0.2", "size": "160"}, {"price": "0.223", "size": "165"}, {"price": "0.25", "size": "112"}, {"price": "0.3", "size": "86.66"}, {"price": "0.35", "size": "68.57"}, {"price": "0.4", "size": "50"}, {"price": "0.523", "size": "150"}, {"price": "0.551", "size": "500"}, {"price": "0.564", "size": "547.97"}, {"price": "0.575", "size": "444"}, {"price": "0.581", "size": "900"}, {"price": "0.582", "size": "3295"}, {"price": "0.583", "size": "5"}, {"price": "0.643", "size": "225.22"}, {"price": "0.723", "size": "88"}, {"price": "0.823", "size": "190"}, {"price": "0.838", "size": "148.24"}, {"price": "0.839", "size": "297"}, {"price": "0.84", "size": "238"}, {"price": "0.87", "size": "10"}, {"price": "0.879", "size": "186.29"}, {"price": "0.88", "size": "20"}, {"price": "0.881", "size": "25"}, {"price": "0.909", "size": "244.69"}, {"price": "0.923", "size": "407"}, {"price": "0.945", "size": "237.37"}, {"price": "0.951", "size": "200"}, {"price": "0.952", "size": "300.29"}, {"price": "0.975", "size": "990.09"}, {"price": "0.98", "size": "178.16"}, {"price": "0.981", "size": "703.11"}, {"price": "0.982", "size": "107.39"}, {"price": "0.986", "size": "127.22"}, {"price": "0.987", "size": "566.69"}, {"price": "0.988", "size": "619.99"}, {"price": "0.989", "size": "1034.38"}, {"price": "0.99", "size": "97.84"}, {"price": "0.991", "size": "30"}], "asks": [{"price": "0.999", "size": "11594.04"}, {"price": "0.998", "size": "6666.38"}, {"price": "0.997", "size": "4421.14"}, {"price": "0.996", "size": "1.7"}], "event_type": "book", "last_trade_price": "0.008"}, {"market": "0xc55db914f0fd1fee18997706712c0dfd8d0369cdbef93a9fef12bd001914ca77", "asset_id": "72354723612769247426741660426331235762851940382312402276325808095604519806766", "timestamp": "1769383920514", "hash": "8b78bdd2524a2559a20d2b24fb66e7fb7614d7eb", "bids": [{"price": "0.001", "size": "13733.28"}], "asks": [{"price": "0.999", "size": "8674.77"}, {"price": "0.998", "size": "5.25"}, {"price": "0.997", "size": "1400"}, {"price": "0.996", "size": "9.09"}, {"price": "0.994", "size": "200"}, {"price": "0.99", "size": "23"}, {"price": "0.989", "size": "17.97"}, {"price": "0.97", "size": "2500"}, {"price": "0.965", "size": "2999.96"}, {"price": "0.95", "size": "540"}, {"price": "0.949", "size": "11.87"}, {"price": "0.9", "size": "360"}, {"price": "0.85", "size": "226.66"}, {"price": "0.8", "size": "160"}, {"price": "0.799", "size": "5.69"}, {"price": "0.777", "size": "165"}, {"price": "0.75", "size": "112"}, {"price": "0.7", "size": "86.66"}, {"price": "0.65", "size": "68.57"}, {"price": "0.6", "size": "50"}, {"price": "0.565", "size": "586.12"}, {"price": "0.52", "size": "5"}, {"price": "0.477", "size": "350"}, {"price": "0.476", "size": "3620"}, {"price": "0.475", "size": "5"}, {"price": "0.277", "size": "179"}, {"price": "0.177", "size": "189"}, {"price": "0.164", "size": "231.9"}, {"price": "0.163", "size": "298"}, {"price": "0.162", "size": "238"}, {"price": "0.12", "size": "10"}, {"price": "0.119", "size": "20"}, {"price": "0.115", "size": "25"}, {"price": "0.077", "size": "762"}, {"price": "0.041", "size": "486"}, {"price": "0.025", "size": "1202.94"}, {"price": "0.023", "size": "100"}, {"price": "0.02", "size": "1699.98"}, {"price": "0.018", "size": "300"}, {"price": "0.016", "size": "160"}, {"price": "0.015", "size": "148.52"}, {"price": "0.014", "size": "1396"}, {"price": "0.012", "size": "526.11"}, {"price": "0.011", "size": "256.36"}, {"price": "0.01", "size": "99.99"}, {"price": "0.009", "size": "531.88"}, {"price": "0.007", "size": "28.91"}], "event_type": "book", "last_trade_price": "0.001"}, {"market": "0xb9bbdd34304344dcc45803780a34c97d73a00133a5ecf70f63e1008b8abb2fca", "asset_id": "72012724360700510767037780555710363830014634797787940282136454146828040926557", "timestamp": "1769383994676", "hash": "eed5b4f96f28e35fe24840223ff5fe216a0f2ed0", "bids": [{"price": "0.001", "size": "11594.04"}, {"price": "0.002", "size": "6666.38"}, {"price": "0.003", "size": "4421.14"}, {"price": "0.004", "size": "1.7"}], "asks": [{"price": "0.999", "size": "6098.33"}, {"price": "0.997", "size": "1400"}, {"price": "0.994", "size": "200"}, {"price": "0.99", "size": "23"}, {"price": "0.95", "size": "40"}, {"price": "0.949", "size": "2942.02"}, {"price": "0.9", "size": "637.06"}, {"price": "0.85", "size": "226.66"}, {"price": "0.8", "size": "160"}, {"price": "0.777", "size": "165"}, {"price": "0.75", "size": "112"}, {"price": "0.7", "size": "86.66"}, {"price": "0.65", "size": "68.57"}, {"price": "0.6", "size": "50"}, {"price": "0.477", "size": "150"}, {"price": "0.449", "size": "500"}, {"price": "0.436", "size": "547.97"}, {"price": "0.425", "size": "444"}, {"price": "0.419", "size": "900"}, {"price": "0.418", "size": "3295"}, {"price": "0.417", "size": "5"}, {"price": "0.357", "size": "225.22"}, {"price": "0.277", "size": "88"}, {"price": "0.177", "size": "190"}, {"price": "0.162", "size": "148.24"}, {"price": "0.161", "size": "297"}, {"price": "0.16", "size": "238"}, {"price": "0.13", "size": "10"}, {"price": "0.121", "size": "186.29"}, {"price": "0.12", "size": "20"}, {"price": "0.119", "size": "25"}, {"price": "0.091", "size": "244.69"}, {"price": "0.077", "size": "407"}, {"price": "0.055", "size": "237.37"}, {"price": "0.049", "size": "200"}, {"price": "0.048", "size": "300.29"}, {"price": "0.025", "size": "990.09"}, {"price": "0.02", "size": "178.16"}, {"price": "0.019", "size": "703.11"}, {"price": "0.018", "size": "107.39"}, {"price": "0.014", "size": "127.22"}, {"price": "0.013", "size": "566.69"}, {"price": "0.012", "size": "619.99"}, {"price": "0.011", "size": "1034.38"}, {"price": "0.01", "size": "97.84"}, {"price": "0.009", "size": "30"}], "event_type": "book", "last_trade_price": "0.008"}, {"market": "0xaf9d0e448129a9f657f851d49495ba4742055d80e0ef1166ba0ee81d4d594214", "asset_id": "101676997363687199724245607342877036148401850938023978421879460310389391082353", "timestamp": "1769383994675", "hash": "8ec6eed1687af36a1570abc5c40590fd5d6faaa2", "bids": [{"price": "0.001", "size": "14571.68"}, {"price": "0.002", "size": "11638.12"}, {"price": "0.003", "size": "1030.11"}, {"price": "0.004", "size": "1224.47"}, {"price": "0.005", "size": "1531.11"}, {"price": "0.01", "size": "20362.82"}, {"price": "0.011", "size": "1649.9"}, {"price": "0.012", "size": "311.88"}], "asks": [{"price": "0.999", "size": "3726.29"}, {"price": "0.998", "size": "1250"}, {"price": "0.997", "size": "1407"}, {"price": "0.994", "size": "200"}, {"price": "0.993", "size": "10.29"}, {"price": "0.99", "size": "28"}, {"price": "0.98", "size": "5000"}, {"price": "0.979", "size": "10.56"}, {"price": "0.95", "size": "120"}, {"price": "0.934", "size": "1800"}, {"price": "0.933", "size": "7.94"}, {"price": "0.91", "size": "706.18"}, {"price": "0.9", "size": "360"}, {"price": "0.85", "size": "226.66"}, {"price": "0.849", "size": "13"}, {"price": "0.8", "size": "160"}, {"price": "0.799", "size": "5.68"}, {"price": "0.75", "size": "112"}, {"price": "0.7", "size": "86.66"}, {"price": "0.66", "size": "70.58"}, {"price": "0.62", "size": "50.27"}, {"price": "0.61", "size": "51.28"}, {"price": "0.52", "size": "143.54"}, {"price": "0.5", "size": "5"}, {"price": "0.39", "size": "900"}, {"price": "0.38", "size": "10.94"}, {"price": "0.303", "size": "700"}, {"price": "0.302", "size": "67.05"}, {"price": "0.214", "size": "107.66"}, {"price": "0.213", "size": "10"}, {"price": "0.139", "size": "58.53"}, {"price": "0.13", "size": "52.47"}, {"price": "0.129", "size": "20"}, {"price": "0.127", "size": "20"}, {"price": "0.114", "size": "215.33"}, {"price": "0.113", "size": "25"}, {"price": "0.088", "size": "908"}, {"price": "0.08", "size": "637.13"}, {"price": "0.068", "size": "348.57"}, {"price": "0.067", "size": "348.58"}, {"price": "0.066", "size": "1540.04"}, {"price": "0.065", "size": "60"}, {"price": "0.064", "size": "17.08"}], "event_type": "book", "last_trade_price": "0.988"}, {"market": "0x49a20c7523c271099008f3ef9a31521263b24d637959852a391e6b4697b1a437", "asset_id": "13018971792603393862521629014128024641178044618205296260525674415067194037856", "timestamp": "1769383922137", "hash": "f0dcf98448a1d9988bf95e5fb8d9cbaf5b20c5a8", "bids": [{"price": "0.001", "size": "3144.68"}, {"price": "0.002", "size": "2137.18"}], "asks": [{"price": "0.999", "size": "5769.67"}, {"price": "0.998", "size": "5.25"}, {"price": "0.997", "size": "1400"}, {"price": "0.996", "size": "9.09"}, {"price": "0.994", "size": "200"}, {"price": "0.99", "size": "23"}, {"price": "0.989", "size": "17.97"}, {"price": "0.97", "size": "2500"}, {"price": "0.967", "size": "2950.95"}, {"price": "0.95", "size": "715"}, {"price": "0.949", "size": "11.87"}, {"price": "0.9", "size": "360"}, {"price": "0.88", "size": "1400"}, {"price": "0.85", "size": "226.66"}, {"price": "0.8", "size": "160"}, {"price": "0.799", "size": "5.69"}, {"price": "0.777", "size": "165"}, {"price": "0.75", "size": "209.57"}, {"price": "0.7", "size": "86.66"}, {"price": "0.65", "size": "68.57"}, {"price": "0.6", "size": "50"}, {"price": "0.596", "size": "400"}, {"price": "0.477", "size": "325"}, {"price": "0.468", "size": "300"}, {"price": "0.466", "size": "862.5"}, {"price": "0.462", "size": "646.87"}, {"price": "0.461", "size": "3510"}, {"price": "0.459", "size": "5"}, {"price": "0.277", "size": "89"}, {"price": "0.253", "size": "97.56"}, {"price": "0.177", "size": "189"}, {"price": "0.154", "size": "299.79"}, {"price": "0.153", "size": "531"}, {"price": "0.13", "size": "10"}, {"price": "0.128", "size": "25"}, {"price": "0.127", "size": "20"}, {"price": "0.077", "size": "439"}, {"price": "0.075", "size": "486"}, {"price": "0.074", "size": "430.15"}, {"price": "0.057", "size": "155.3"}, {"price": "0.04", "size": "43.47"}, {"price": "0.031", "size": "217.65"}, {"price": "0.028", "size": "73.73"}, {"price": "0.027", "size": "114.7"}, {"price": "0.021", "size": "509.48"}, {"price": "0.019", "size": "516.76"}, {"price": "0.015", "size": "775.15"}, {"price": "0.014", "size": "783.61"}, {"price": "0.013", "size": "509.47"}, {"price": "0.012", "size": "304.24"}, {"price": "0.011", "size": "101.85"}, {"price": "0.009", "size": "91.98"}], "event_type": "book", "last_trade_price": "0.002"}, {"market": "0x49a20c7523c271099008f3ef9a31521263b24d637959852a391e6b4697b1a437", "asset_id": "55881023621710858558280545117465775643848233756850602339827152783696837905531", "timestamp": "1769383922137", "hash": "a6960c84464760406c35953a48cbf28a0245e99f", "bids": [{"price": "0.001", "size": "5769.67"}, {"price": "0.002", "size": "5.25"}, {"price": "0.003", "size": "1400"}, {"price": "0.004", "size": "9.09"}, {"price": "0.006", "size": "200"}, {"price": "0.01", "size": "23"}, {"price": "0.011", "size": "17.97"}, {"price": "0.03", "size": "2500"}, {"price": "0.033", "size": "2950.95"}, {"price": "0.05", "size": "715"}, {"price": "0.051", "size": "11.87"}, {"price": "0.1", "size": "360"}, {"price": "0.12", "size": "1400"}, {"price": "0.15", "size": "226.66"}, {"price": "0.2", "size": "160"}, {"price": "0.201", "size": "5.69"}, {"price": "0.223", "size": "165"}, {"price": "0.25", "size": "209.57"}, {"price": "0.3", "size": "86.66"}, {"price": "0.35", "size": "68.57"}, {"price": "0.4", "size": "50"}, {"price": "0.404", "size": "400"}, {"price": "0.523", "size": "325"}, {"price": "0.532", "size": "300"}, {"price": "0.534", "size": "862.5"}, {"price": "0.538", "size": "646.87"}, {"price": "0.539", "size": "3510"}, {"price": "0.541", "size": "5"}, {"price": "0.723", "size": "89"}, {"price": "0.747", "size": "97.56"}, {"price": "0.823", "size": "189"}, {"price": "0.846", "size": "299.79"}, {"price": "0.847", "size": "531"}, {"price": "0.87", "size": "10"}, {"price": "0.872", "size": "25"}, {"price": "0.873", "size": "20"}, {"price": "0.923", "size": "439"}, {"price": "0.925", "size": "486"}, {"price": "0.926", "size": "430.15"}, {"price": "0.943", "size": "155.3"}, {"price": "0.96", "size": "43.47"}, {"price": "0.969", "size": "217.65"}, {"price": "0.972", "size": "73.73"}, {"price": "0.973", "size": "114.7"}, {"price": "0.979", "size": "509.48"}, {"price": "0.981", "size": "516.76"}, {"price": "0.985", "size": "775.15"}, {"price": "0.986", "size": "783.61"}, {"price": "0.987", "size": "509.47"}, {"price": "0.988", "size": "304.24"}, {"price": "0.989", "size": "101.85"}, {"price": "0.991", "size": "91.98"}], "asks": [{"price": "0.999", "size": "3144.68"}, {"price": "0.998", "size": "2137.18"}], "event_type": "book", "last_trade_price": "0.002"}, {"market": "0x44f08744458b8896620cd3330bc5e1ea69df4199b02d4fc583b3fc96e5d314ce", "asset_id": "49194009556504828848509244326501559253829462790583873936160989575507522044057", "timestamp": "1769383922452", "hash": "558c555d22e9d7a4e5537dd84d06568740cecaf7", "bids": [{"price": "0.001", "size": "7843.07"}, {"price": "0.002", "size": "2570.71"}, {"price": "0.003", "size": "2000"}], "asks": [{"price": "0.999", "size": "3630.98"}, {"price": "0.998", "size": "1255.25"}, {"price": "0.997", "size": "1400"}, {"price": "0.996", "size": "9.1"}, {"price": "0.994", "size": "200"}, {"price": "0.99", "size": "23"}, {"price": "0.989", "size": "7.83"}, {"price": "0.973", "size": "777"}, {"price": "0.972", "size": "5.16"}, {"price": "0.968", "size": "510"}, {"price": "0.967", "size": "420"}, {"price": "0.95", "size": "650"}, {"price": "0.948", "size": "353"}, {"price": "0.946", "size": "450"}, {"price": "0.944", "size": "377"}, {"price": "0.943", "size": "3200"}, {"price": "0.942", "size": "9.87"}, {"price": "0.9", "size": "360"}, {"price": "0.85", "size": "226.66"}, {"price": "0.8", "size": "160"}, {"price": "0.799", "size": "5.69"}, {"price": "0.75", "size": "600.64"}, {"price": "0.7", "size": "86.66"}, {"price": "0.65", "size": "68.57"}, {"price": "0.6", "size": "200"}, {"price": "0.599", "size": "4735"}, {"price": "0.598", "size": "5"}, {"price": "0.52", "size": "85"}, {"price": "0.46", "size": "30"}, {"price": "0.45", "size": "50"}, {"price": "0.42", "size": "30"}, {"price": "0.38", "size": "40"}, {"price": "0.32", "size": "30"}, {"price": "0.29", "size": "30"}, {"price": "0.28", "size": "111.11"}, {"price": "0.275", "size": "200"}, {"price": "0.24", "size": "40"}, {"price": "0.21", "size": "30"}, {"price": "0.196", "size": "261.26"}, {"price": "0.19", "size": "30"}, {"price": "0.17", "size": "406.49"}, {"price": "0.14", "size": "50"}, {"price": "0.139", "size": "10"}, {"price": "0.13", "size": "10"}, {"price": "0.126", "size": "125.46"}, {"price": "0.124", "size": "20"}, {"price": "0.123", "size": "20"}, {"price": "0.101", "size": "651.53"}, {"price": "0.099", "size": "25"}, {"price": "0.075", "size": "868.7"}, {"price": "0.065", "size": "732.97"}, {"price": "0.051", "size": "385"}, {"price": "0.048", "size": "539.8"}, {"price": "0.037", "size": "809.7"}, {"price": "0.028", "size": "404.86"}, {"price": "0.027", "size": "114.7"}, {"price": "0.021", "size": "304.49"}, {"price": "0.02", "size": "319"}, {"price": "0.017", "size": "367.57"}, {"price": "0.016", "size": "60"}, {"price": "0.015", "size": "10.6"}], "event_type": "book", "last_trade_price": "0.006"}, {"market": "0x49686d26fb712515cd5e12c23f0a1c7e10214c7faa3cb0a730aabe0c33694082", "asset_id": "30442780799048074404860985387051749017905070253466005720364298335239299761065", "timestamp": "1769383996116", "hash": "711c868fdd7e1cdd839f454350703124b7cc2826", "bids": [{"price": "0.001", "size": "2020.07"}, {"price": "0.002", "size": "2361.62"}, {"price": "0.003", "size": "18.57"}, {"price": "0.005", "size": "99.51"}, {"price": "0.006", "size": "7.67"}, {"price": "0.007", "size": "150"}, {"price": "0.008", "size": "8.58"}, {"price": "0.01", "size": "376.91"}, {"price": "0.011", "size": "10.31"}, {"price": "0.012", "size": "5401.42"}, {"price": "0.015", "size": "111"}, {"price": "0.016", "size": "27.01"}, {"price": "0.02", "size": "41"}, {"price": "0.021", "size": "6.24"}, {"price": "0.03", "size": "363.11"}, {"price": "0.031", "size": "5.73"}, {"price": "0.037", "size": "137.49"}, {"price": "0.038", "size": "500"}, {"price": "0.04", "size": "272.33"}, {"price": "0.041", "size": "25"}, {"price": "0.042", "size": "10.42"}, {"price": "0.05", "size": "204.25"}, {"price": "0.06", "size": "153.18"}, {"price": "0.061", "size": "70"}, {"price": "0.063", "size": "5.71"}, {"price": "0.07", "size": "114.89"}, {"price": "0.08", "size": "86.17"}, {"price": "0.081", "size": "5.78"}, {"price": "0.09", "size": "64.62"}, {"price": "0.096", "size": "36.5"}, {"price": "0.1", "size": "48.47"}, {"price": "0.102", "size": "134.85"}, {"price": "0.103", "size": "30"}, {"price": "0.104", "size": "40.31"}], "asks": [{"price": "0.999", "size": "4291.7"}, {"price": "0.998", "size": "1250"}, {"price": "0.997", "size": "1000"}, {"price": "0.996", "size": "7.14"}, {"price": "0.99", "size": "23"}, {"price": "0.97", "size": "2000"}, {"price": "0.969", "size": "6.24"}, {"price": "0.95", "size": "30"}, {"price": "0.91", "size": "400"}, {"price": "0.909", "size": "3296"}, {"price": "0.86", "size": "242.85"}, {"price": "0.859", "size": "1134"}, {"price": "0.82", "size": "177.77"}, {"price": "0.819", "size": "882"}, {"price": "0.77", "size": "121.73"}, {"price": "0.752", "size": "300"}, {"price": "0.75", "size": "400"}, {"price": "0.749", "size": "1672"}, {"price": "0.73", "size": "96.29"}, {"price": "0.72", "size": "204.64"}, {"price": "0.68", "size": "2075"}, {"price": "0.65", "size": "5"}, {"price": "0.64", "size": "55.55"}, {"price": "0.365", "size": "30"}, {"price": "0.25", "size": "40"}, {"price": "0.249", "size": "10"}, {"price": "0.17", "size": "1500"}, {"price": "0.15", "size": "15"}, {"price": "0.14", "size": "948.91"}, {"price": "0.138", "size": "178.68"}, {"price": "0.135", "size": "103.1"}, {"price": "0.133", "size": "265.14"}], "event_type": "book", "last_trade_price": "0.867"}, {"market": "0x9472be65457510b7fc3477b20ba90910e99d92eac8421a14bf4b7b7a08ef31dc", "asset_id": "43311793366960417907757893276427136943959788721376762326430771171648759300146", "timestamp": "1769383961076", "hash": "0600a9a03431712361289c96d0dfd0062d571651", "bids": [{"price": "0.001", "size": "7393.14"}, {"price": "0.002", "size": "5.24"}, {"price": "0.003", "size": "1400"}, {"price": "0.004", "size": "9.09"}, {"price": "0.006", "size": "200"}, {"price": "0.01", "size": "23"}, {"price": "0.011", "size": "17.96"}, {"price": "0.03", "size": "2500"}, {"price": "0.037", "size": "3000"}, {"price": "0.05", "size": "380"}, {"price": "0.051", "size": "11.87"}, {"price": "0.1", "size": "360"}, {"price": "0.15", "size": "226.66"}, {"price": "0.2", "size": "160"}, {"price": "0.201", "size": "5.69"}, {"price": "0.223", "size": "165"}, {"price": "0.25", "size": "112"}, {"price": "0.3", "size": "86.66"}, {"price": "0.35", "size": "68.57"}, {"price": "0.4", "size": "50"}, {"price": "0.447", "size": "1000"}, {"price": "0.458", "size": "5197"}, {"price": "0.459", "size": "268"}, {"price": "0.48", "size": "5"}, {"price": "0.523", "size": "150"}, {"price": "0.67", "size": "5"}, {"price": "0.723", "size": "88"}, {"price": "0.823", "size": "190"}, {"price": "0.87", "size": "10"}, {"price": "0.871", "size": "20"}, {"price": "0.883", "size": "25"}, {"price": "0.923", "size": "399"}, {"price": "0.925", "size": "756"}, {"price": "0.938", "size": "408.81"}, {"price": "0.959", "size": "613.23"}, {"price": "0.975", "size": "1796.98"}, {"price": "0.977", "size": "150"}, {"price": "0.978", "size": "306.61"}, {"price": "0.979", "size": "145"}, {"price": "0.98", "size": "460.33"}, {"price": "0.982", "size": "376.79"}, {"price": "0.985", "size": "88.12"}, {"price": "0.986", "size": "1796.98"}, {"price": "0.987", "size": "341.69"}, {"price": "0.99", "size": "50"}, {"price": "0.991", "size": "263.98"}, {"price": "0.993", "size": "495.05"}, {"price": "0.994", "size": "1580.14"}, {"price": "0.995", "size": "973.54"}], "asks": [{"price": "0.999", "size": "13015.1"}, {"price": "0.998", "size": "139.66"}], "event_type": "book", "last_trade_price": "0.002"}, {"market": "0xaf9d0e448129a9f657f851d49495ba4742055d80e0ef1166ba0ee81d4d594214", "asset_id": "4153292802911610701832309484716814274802943278345248636922528170020319407796", "timestamp": "1769383994675", "hash": "bc28edb281c5f9758e427974781eb5c177319a22", "bids": [{"price": "0.001", "size": "3726.29"}, {"price": "0.002", "size": "1250"}, {"price": "0.003", "size": "1407"}, {"price": "0.006", "size": "200"}, {"price": "0.007", "size": "10.29"}, {"price": "0.01", "size": "28"}, {"price": "0.02", "size": "5000"}, {"price": "0.021", "size": "10.56"}, {"price": "0.05", "size": "120"}, {"price": "0.066", "size": "1800"}, {"price": "0.067", "size": "7.94"}, {"price": "0.09", "size": "706.18"}, {"price": "0.1", "size": "360"}, {"price": "0.15", "size": "226.66"}, {"price": "0.151", "size": "13"}, {"price": "0.2", "size": "160"}, {"price": "0.201", "size": "5.68"}, {"price": "0.25", "size": "112"}, {"price": "0.3", "size": "86.66"}, {"price": "0.34", "size": "70.58"}, {"price": "0.38", "size": "50.27"}, {"price": "0.39", "size": "51.28"}, {"price": "0.48", "size": "143.54"}, {"price": "0.5", "size": "5"}, {"price": "0.61", "size": "900"}, {"price": "0.62", "size": "10.94"}, {"price": "0.697", "size": "700"}, {"price": "0.698", "size": "67.05"}, {"price": "0.786", "size": "107.66"}, {"price": "0.787", "size": "10"}, {"price": "0.861", "size": "58.53"}, {"price": "0.87", "size": "52.47"}, {"price": "0.871", "size": "20"}, {"price": "0.873", "size": "20"}, {"price": "0.886", "size": "215.33"}, {"price": "0.887", "size": "25"}, {"price": "0.912", "size": "908"}, {"price": "0.92", "size": "637.13"}, {"price": "0.932", "size": "348.57"}, {"price": "0.933", "size": "348.58"}, {"price": "0.934", "size": "1540.04"}, {"price": "0.935", "size": "60"}, {"price": "0.936", "size": "17.08"}], "asks": [{"price": "0.999", "size": "14571.68"}, {"price": "0.998", "size": "11638.12"}, {"price": "0.997", "size": "1030.11"}, {"price": "0.996", "size": "1224.47"}, {"price": "0.995", "size": "1531.11"}, {"price": "0.99", "size": "20362.82"}, {"price": "0.989", "size": "1649.9"}, {"price": "0.988", "size": "311.88"}], "event_type": "book", "last_trade_price": "0.988"}, {"market": "0x50c669f178da4e5bbea7f1be25041fd278914712fa87a6a6f8e57d5923d88dee", "asset_id": "24682525479474221428144937281315825971983904267399062415430320764754931667953", "timestamp": "1769383994676", "hash": "7eaf6614f090b1a74a647b569f75f29902ec012a", "bids": [{"price": "0.001", "size": "10101.55"}, {"price": "0.002", "size": "141.7"}], "asks": [{"price": "0.999", "size": "7167.15"}, {"price": "0.998", "size": "5.24"}, {"price": "0.997", "size": "1400"}, {"price": "0.996", "size": "9.09"}, {"price": "0.994", "size": "200"}, {"price": "0.99", "size": "23"}, {"price": "0.989", "size": "17.96"}, {"price": "0.971", "size": "3000"}, {"price": "0.95", "size": "40"}, {"price": "0.949", "size": "11.87"}, {"price": "0.9", "size": "360"}, {"price": "0.85", "size": "226.66"}, {"price": "0.8", "size": "165"}, {"price": "0.799", "size": "5.69"}, {"price": "0.777", "size": "154"}, {"price": "0.75", "size": "112"}, {"price": "0.7", "size": "86.66"}, {"price": "0.65", "size": "68.57"}, {"price": "0.6", "size": "50"}, {"price": "0.58", "size": "555"}, {"price": "0.533", "size": "1000"}, {"price": "0.532", "size": "5089"}, {"price": "0.531", "size": "5"}, {"price": "0.477", "size": "158"}, {"price": "0.4", "size": "5"}, {"price": "0.277", "size": "256"}, {"price": "0.177", "size": "219"}, {"price": "0.176", "size": "10"}, {"price": "0.13", "size": "10"}, {"price": "0.129", "size": "25"}, {"price": "0.122", "size": "295.98"}, {"price": "0.119", "size": "40"}, {"price": "0.092", "size": "282.51"}, {"price": "0.077", "size": "1785"}, {"price": "0.069", "size": "856"}, {"price": "0.05", "size": "62.24"}, {"price": "0.032", "size": "44.99"}, {"price": "0.025", "size": "1202.94"}, {"price": "0.023", "size": "100"}, {"price": "0.02", "size": "403.96"}, {"price": "0.016", "size": "100.1"}, {"price": "0.014", "size": "2905.56"}, {"price": "0.008", "size": "996.44"}, {"price": "0.007", "size": "991.09"}, {"price": "0.005", "size": "815.95"}], "event_type": "book", "last_trade_price": "0.002"}]}
{"_local_timestamp": "2026-01-25T23:33:17.035910+00:00", "data": {"market": "0x49686d26fb712515cd5e12c23f0a1c7e10214c7faa3cb0a730aabe0c33694082", "price_changes": [{"asset_id": "13244681086321087932946246027856416106585284024824496763706748621681543444582", "price": "0.939", "size": "0", "side": "SELL", "hash": "3a179ad9da964318e44b0000742fc4a7c4876576", "best_bid": "0.867", "best_ask": "0.896"}, {"asset_id": "30442780799048074404860985387051749017905070253466005720364298335239299761065", "price": "0.061", "size": "0", "side": "BUY", "hash": "6172e0d0f015f8871aec2ad8d6c10a86b54f607d", "best_bid": "0.104", "best_ask": "0.133"}], "timestamp": "1769383996833", "event_type": "price_change"}}
{"_local_timestamp": "2026-01-25T23:33:17.123222+00:00", "data": {"market": "0x2393ed0b0fdc450054c7b9071907eca75cf4fc36e385adf4a0a5f99ee62243e8", "price_changes": [{"asset_id": "32769749367306925959219403371425714180265458150646381231272229429098460625924", "price": "0.966", "size": "112.19", "side": "SELL", "hash": "30fd6665aa4273e2d9bdd0c4ac059789a2542d4d", "best_bid": "0.918", "best_ask": "0.959"}, {"asset_id": "100074770378634056601572485653252702850363676459996771990439989989293515601975", "price": "0.034", "size": "112.19", "side": "BUY", "hash": "ef190fecdf75cbc0d03605a75d3351a53c5de8b0", "best_bid": "0.041", "best_ask": "0.082"}], "timestamp": "1769383997054", "event_type": "price_change"}}
{"_local_timestamp": "2026-01-25T23:33:17.127367+00:00", "data": {"market": "0x2393ed0b0fdc450054c7b9071907eca75cf4fc36e385adf4a0a5f99ee62243e8", "price_changes": [{"asset_id": "32769749367306925959219403371425714180265458150646381231272229429098460625924", "price": "0.901", "size": "37.81", "side": "BUY", "hash": "21ab4b4b5ac4881ea58d06d2093857bce826a289", "best_bid": "0.918", "best_ask": "0.959"}, {"asset_id": "100074770378634056601572485653252702850363676459996771990439989989293515601975", "price": "0.099", "size": "37.81", "side": "SELL", "hash": "89df16592ea16ef5a87aba72656514fc72c8ad68", "best_bid": "0.041", "best_ask": "0.082"}], "timestamp": "1769383997061", "event_type": "price_change"}}
{"_local_timestamp": "2026-01-25T23:33:17.162850+00:00", "data": {"market": "0x2393ed0b0fdc450054c7b9071907eca75cf4fc36e385adf4a0a5f99ee62243e8", "price_changes": [{"asset_id": "32769749367306925959219403371425714180265458150646381231272229429098460625924", "price": "0.96", "size": "0", "side": "SELL", "hash": "a499abd8fcc72cc4cc526c1e690dd6c31a842178", "best_bid": "0.918", "best_ask": "0.959"}, {"asset_id": "100074770378634056601572485653252702850363676459996771990439989989293515601975", "price": "0.04", "size": "0", "side": "BUY", "hash": "9914519c17bdcee896c4544845dbb56f482ec48f", "best_bid": "0.041", "best_ask": "0.082"}], "timestamp": "1769383997087", "event_type": "price_change"}}
{"_local_timestamp": "2026-01-25T23:33:17.256993+00:00", "data": {"market": "0x49686d26fb712515cd5e12c23f0a1c7e10214c7faa3cb0a730aabe0c33694082", "price_changes": [{"asset_id": "13244681086321087932946246027856416106585284024824496763706748621681543444582", "price": "0.936", "size": "70", "side": "SELL", "hash": "98a0d574715c80ada1477e6316bc0bbc62bb4749", "best_bid": "0.867", "best_ask": "0.896"}, {"asset_id": "30442780799048074404860985387051749017905070253466005720364298335239299761065", "price": "0.064", "size": "70", "side": "BUY", "hash": "586424e8e1e7c3ff31ef83046cae48b8ba0b07de", "best_bid": "0.104", "best_ask": "0.133"}], "timestamp": "1769383997192", "event_type": "price_change"}}
{"_local_timestamp": "2026-01-25T23:33:17.331962+00:00", "data": {"market": "0x2393ed0b0fdc450054c7b9071907eca75cf4fc36e385adf4a0a5f99ee62243e8", "price_changes": [{"asset_id": "32769749367306925959219403371425714180265458150646381231272229429098460625924", "price": "0.897", "size": "0", "side": "BUY", "hash": "aa395cdf69246182eaae3862291c06bc6d790a31", "best_bid": "0.918", "best_ask": "0.959"}, {"asset_id": "100074770378634056601572485653252702850363676459996771990439989989293515601975", "price": "0.103", "size": "0", "side": "SELL", "hash": "32b630b7dd9e945cf040a1f3bb3179b82496ec04", "best_bid": "0.041", "best_ask": "0.082"}], "timestamp": "1769383997263", "event_type": "price_change"}}
{"_local_timestamp": "2026-01-25T23:33:17.362413+00:00", "data": {"market": "0x2393ed0b0fdc450054c7b9071907eca75cf4fc36e385adf4a0a5f99ee62243e8", "price_changes": [{"asset_id": "100074770378634056601572485653252702850363676459996771990439989989293515601975", "price": "0.1", "size": "0", "side": "SELL", "hash": "3f15cbcbcb10585d90ecc5dfc4de346d0181df0b", "best_bid": "0.041", "best_ask": "0.082"}, {"asset_id": "32769749367306925959219403371425714180265458150646381231272229429098460625924", "price": "0.9", "size": "0", "side": "BUY", "hash": "49820a6f5636fa91cdf83534bd939c61cde54684", "best_bid": "0.918", "best_ask": "0.959"}], "timestamp": "1769383997291", "event_type": "price_change"}}
{"_local_timestamp": "2026-01-25T23:33:17.386436+00:00", "data": {"market": "0x2393ed0b0fdc450054c7b9071907eca75cf4fc36e385adf4a0a5f99ee62243e8", "price_changes": [{"asset_id": "100074770378634056601572485653252702850363676459996771990439989989293515601975", "price": "0.098", "size": "207", "side": "SELL", "hash": "f9079d69bed134a5ee6abc372d749909c2ebb5c0", "best_bid": "0.041", "best_ask": "0.082"}, {"asset_id": "32769749367306925959219403371425714180265458150646381231272229429098460625924", "price": "0.902", "size": "207", "side": "BUY", "hash": "9e53e68c2a2033b0c0e757372a606a7292e8630e", "best_bid": "0.918", "best_ask": "0.959"}], "timestamp": "1769383997317", "event_type": "price_change"}}
{"_local_timestamp": "2026-01-25T23:33:17.409775+00:00", "data": {"market": "0x2393ed0b0fdc450054c7b9071907eca75cf4fc36e385adf4a0a5f99ee62243e8", "price_changes": [{"asset_id": "32769749367306925959219403371425714180265458150646381231272229429098460625924", "price": "0.901", "size": "67.81", "side": "BUY", "hash": "f0bfa9a34224a1fdea751191e023839c3e6d3b1f", "best_bid": "0.918", "best_ask": "0.959"}, {"asset_id": "100074770378634056601572485653252702850363676459996771990439989989293515601975", "price": "0.099", "size": "67.81", "side": "SELL", "hash": "8c00bb8cab5f5c2c9bb305b91b0e27ecb608942a", "best_bid": "0.041", "best_ask": "0.082"}], "timestamp": "1769383997337", "event_type": "price_change"}}
{"_local_timestamp": "2026-01-25T23:33:17.529333+00:00", "data": {"market": "0x2393ed0b0fdc450054c7b9071907eca75cf4fc36e385adf4a0a5f99ee62243e8", "price_changes": [{"asset_id": "32769749367306925959219403371425714180265458150646381231272229429098460625924", "price": "0.902", "size": "257", "side": "BUY", "hash": "b5170f1c0a809c42c73fcdbfdee079eb627a4782", "best_bid": "0.918", "best_ask": "0.959"}, {"asset_id": "100074770378634056601572485653252702850363676459996771990439989989293515601975", "price": "0.098", "size": "257", "side": "SELL", "hash": "d005ce3a1c3b40be0f2c70b8682a65caf7395da9", "best_bid": "0.041", "best_ask": "0.082"}], "timestamp": "1769383997467", "event_type": "price_change"}}
{"_local_timestamp": "2026-01-25T23:33:17.571109+00:00", "data": {"market": "0x2393ed0b0fdc450054c7b9071907eca75cf4fc36e385adf4a0a5f99ee62243e8", "price_changes": [{"asset_id": "32769749367306925959219403371425714180265458150646381231272229429098460625924", "price": "0.901", "size": "30", "side": "BUY", "hash": "b451746a409364fe9676ae1c5ede7a78d896f3a2", "best_bid": "0.918", "best_ask": "0.959"}, {"asset_id": "100074770378634056601572485653252702850363676459996771990439989989293515601975", "price": "0.099", "size": "30", "side": "SELL", "hash": "f5e7f9eea204c6597fd74c9cad1c13b1e83465a1", "best_bid": "0.041", "best_ask": "0.082"}], "timestamp": "1769383997506", "event_type": "price_change"}}
{"_local_timestamp": "2026-01-25T23:33:17.604219+00:00", "data": {"market": "0x2393ed0b0fdc450054c7b9071907eca75cf4fc36e385adf4a0a5f99ee62243e8", "price_changes": [{"asset_id": "32769749367306925959219403371425714180265458150646381231272229429098460625924", "price": "0.958", "size": "60", "side": "SELL", "hash": "9e8d5dfdff4ea204ac280d4ad88a06f005aa54a1", "best_bid": "0.918", "best_ask": "0.958"}, {"asset_id": "100074770378634056601572485653252702850363676459996771990439989989293515601975", "price": "0.042", "size": "60", "side": "BUY", "hash": "fa599ed202bfad3d60e3ae1a8f716ec4e8fa866d", "best_bid": "0.042", "best_ask": "0.082"}], "timestamp": "1769383997534", "event_type": "price_change"}}
{"_local_timestamp": "2026-01-25T23:33:17.788599+00:00", "data": {"market": "0x2393ed0b0fdc450054c7b9071907eca75cf4fc36e385adf4a0a5f99ee62243e8", "price_changes": [{"asset_id": "32769749367306925959219403371425714180265458150646381231272229429098460625924", "price": "0.896", "size": "37.81", "side": "BUY", "hash": "bcae85f193db2640b48fd99b9faea0ee82014985", "best_bid": "0.918", "best_ask": "0.958"}, {"asset_id": "100074770378634056601572485653252702850363676459996771990439989989293515601975", "price": "0.104", "size": "37.81", "side": "SELL", "hash": "c07b59a53a90e9fea3f8523c7adeeb74b863fde9", "best_bid": "0.042", "best_ask": "0.082"}], "timestamp": "1769383997719", "event_type": "price_change"}}
{"_local_timestamp": "2026-01-25T23:33:17.809294+00:00", "data": {"market": "0x2393ed0b0fdc450054c7b9071907eca75cf4fc36e385adf4a0a5f99ee62243e8", "price_changes": [{"asset_id": "100074770378634056601572485653252702850363676459996771990439989989293515601975", "price": "0.041", "size": "0", "side": "BUY", "hash": "038d2659ac6c2c62c9abd236957f907e3bf2b313", "best_bid": "0.042", "best_ask": "0.082"}, {"asset_id": "32769749367306925959219403371425714180265458150646381231272229429098460625924", "price": "0.959", "size": "0", "side": "SELL", "hash": "455b4e7a5114ec1f27ae2b0a0d8843fec23a5ec0", "best_bid": "0.918", "best_ask": "0.958"}], "timestamp": "1769383997742", "event_type": "price_change"}}
{"_local_timestamp": "2026-01-25T23:33:17.858745+00:00", "data": {"market": "0x49686d26fb712515cd5e12c23f0a1c7e10214c7faa3cb0a730aabe0c33694082", "price_changes": [{"asset_id": "30442780799048074404860985387051749017905070253466005720364298335239299761065", "price": "0.016", "size": "7.01", "side": "BUY", "hash": "7682070842e03ccb63d6ad81cb771b78101b28f3", "best_bid": "0.104", "best_ask": "0.133"}, {"asset_id": "13244681086321087932946246027856416106585284024824496763706748621681543444582", "price": "0.984", "size": "7.01", "side": "SELL", "hash": "27248fb5e0f11002ccf5f2ca8e1e9c58311a45ad", "best_bid": "0.867", "best_ask": "0.896"}], "timestamp": "1769383997791", "event_type": "price_change"}}
{"_local_timestamp": "2026-01-25T23:33:18.221197+00:00", "data": {"market": "0x50c669f178da4e5bbea7f1be25041fd278914712fa87a6a6f8e57d5923d88dee", "price_changes": [{"asset_id": "74040420326294854165772767082819937451857852955603897473157746262672057685461", "price": "0.881", "size": "20", "side": "BUY", "hash": "a1c978024d651882b6b5a08f10f26cc4bba5cafb", "best_bid": "0.995", "best_ask": "0.998"}, {"asset_id": "24682525479474221428144937281315825971983904267399062415430320764754931667953", "price": "0.119", "size": "20", "side": "SELL", "hash": "1e049cb388a7144ded767a7adb0a3845f838c6ae", "best_bid": "0.002", "best_ask": "0.005"}], "timestamp": "1769383997791", "event_type": "price_change"}}
{"_local_timestamp": "2026-01-25T23:33:18.223828+00:00", "data": {"market": "0x49686d26fb712515cd5e12c23f0a1c7e10214c7faa3cb0a730aabe0c33694082", "price_changes": [{"asset_id": "30442780799048074404860985387051749017905070253466005720364298335239299761065", "price": "0.017", "size": "20", "side": "BUY", "hash": "6a72996a1fabc61dba0a3221463a6356ab71b61d", "best_bid": "0.104", "best_ask": "0.133"}, {"asset_id": "13244681086321087932946246027856416106585284024824496763706748621681543444582", "price": "0.983", "size": "20", "side": "SELL", "hash": "dda932ae2debd1532f07fdea01e6a6074b2013b9", "best_bid": "0.867", "best_ask": "0.896"}], "timestamp": "1769383997817", "event_type": "price_change"}}
{"_local_timestamp": "2026-01-25T23:33:18.226098+00:00", "data": {"market": "0x50c669f178da4e5bbea7f1be25041fd278914712fa87a6a6f8e57d5923d88dee", "price_changes": [{"asset_id": "74040420326294854165772767082819937451857852955603897473157746262672057685461", "price": "0.882", "size": "20", "side": "BUY", "hash": "ad7975066c4d4e284baec21a3c2489157cbe012e", "best_bid": "0.995", "best_ask": "0.998"}, {"asset_id": "24682525479474221428144937281315825971983904267399062415430320764754931667953", "price": "0.118", "size": "20", "side": "SELL", "hash": "39bb4114bbc841bfd2566cfdaadca5ead1499eaf", "best_bid": "0.002", "best_ask": "0.005"}], "timestamp": "1769383997817", "event_type": "price_change"}}
{"_local_timestamp": "2026-01-25T23:33:18.227575+00:00", "data": {"market": "0x2393ed0b0fdc450054c7b9071907eca75cf4fc36e385adf4a0a5f99ee62243e8", "price_changes": [{"asset_id": "32769749367306925959219403371425714180265458150646381231272229429098460625924", "price": "0.917", "size": "0", "side": "BUY", "hash": "f0eeaa92ca157ba6bc4a1d51043220a27494ef06", "best_bid": "0.918", "best_ask": "0.958"}, {"asset_id": "100074770378634056601572485653252702850363676459996771990439989989293515601975", "price": "0.083", "size": "0", "side": "SELL", "hash": "820b85c16a44d1ac167e33686e88b22289da8c31", "best_bid": "0.042", "best_ask": "0.082"}], "timestamp": "1769383997821", "event_type": "price_change"}}
{"_local_timestamp": "2026-01-25T23:33:18.228345+00:00", "data": {"market": "0x2393ed0b0fdc450054c7b9071907eca75cf4fc36e385adf4a0a5f99ee62243e8", "price_changes": [{"asset_id": "32769749367306925959219403371425714180265458150646381231272229429098460625924", "price": "0.896", "size": "0", "side": "BUY", "hash": "6d0a517c8b9d1e539e09e17df94423bd015e30bb", "best_bid": "0.918", "best_ask": "0.958"}, {"asset_id": "100074770378634056601572485653252702850363676459996771990439989989293515601975", "price": "0.104", "size": "0", "side": "SELL", "hash": "fbab6dff0a996609688b4b056e61103133089db4", "best_bid": "0.042", "best_ask": "0.082"}], "timestamp": "1769383997995", "event_type": "price_change"}}
{"_local_timestamp": "2026-01-25T23:33:18.229190+00:00", "data": {"market": "0x2393ed0b0fdc450054c7b9071907eca75cf4fc36e385adf4a0a5f99ee62243e8", "price_changes": [{"asset_id": "100074770378634056601572485653252702850363676459996771990439989989293515601975", "price": "0.035", "size": "46", "side": "BUY", "hash": "39066f80ea6f6dd7aa76550a5ff97a499a667435", "best_bid": "0.042", "best_ask": "0.082"}, {"asset_id": "32769749367306925959219403371425714180265458150646381231272229429098460625924", "price": "0.965", "size": "46", "side": "SELL", "hash": "967308c4eccaaa01017d958dbd67ef8d21aa7406", "best_bid": "0.918", "best_ask": "0.958"}], "timestamp": "1769383998021", "event_type": "price_change"}}
{"_local_timestamp": "2026-01-25T23:33:18.283554+00:00", "data": {"market": "0x2393ed0b0fdc450054c7b9071907eca75cf4fc36e385adf4a0a5f99ee62243e8", "price_changes": [{"asset_id": "32769749367306925959219403371425714180265458150646381231272229429098460625924", "price": "0.903", "size": "37.81", "side": "BUY", "hash": "9f6ca8ca43dad8e3ab43da2bfcb275b341f4489f", "best_bid": "0.918", "best_ask": "0.958"}, {"asset_id": "100074770378634056601572485653252702850363676459996771990439989989293515601975", "price": "0.097", "size": "37.81", "side": "SELL", "hash": "0cada7732e5bea951b178d05424bac022b93da15", "best_bid": "0.042", "best_ask": "0.082"}], "timestamp": "1769383998200", "event_type": "price_change"}}
{"_local_timestamp": "2026-01-25T23:33:18.361724+00:00", "data": {"market": "0x2393ed0b0fdc450054c7b9071907eca75cf4fc36e385adf4a0a5f99ee62243e8", "price_changes": [{"asset_id": "32769749367306925959219403371425714180265458150646381231272229429098460625924", "price": "0.966", "size": "0", "side": "SELL", "hash": "8fa8996e1722c7f8e04dc81c4bd3975dcd6f6b12", "best_bid": "0.918", "best_ask": "0.958"}, {"asset_id": "100074770378634056601572485653252702850363676459996771990439989989293515601975", "price": "0.034", "size": "0", "side": "BUY", "hash": "327009afdccde0a67dcbdfccc466a0738e947412", "best_bid": "0.042", "best_ask": "0.082"}], "timestamp": "1769383998296", "event_type": "price_change"}}
{"_local_timestamp": "2026-01-25T23:33:18.605362+00:00", "data": {"market": "0x2393ed0b0fdc450054c7b9071907eca75cf4fc36e385adf4a0a5f99ee62243e8", "price_changes": [{"asset_id": "32769749367306925959219403371425714180265458150646381231272229429098460625924", "price": "0.964", "size": "112.19", "side": "SELL", "hash": "03cf6b4ab1f295d9c9cb834d3ffdf136463ff4d4", "best_bid": "0.918", "best_ask": "0.958"}, {"asset_id": "100074770378634056601572485653252702850363676459996771990439989989293515601975", "price": "0.036", "size": "112.19", "side": "BUY", "hash": "c74da24cd2661b4e07aa2e3e8aac0bdcf3ff362a", "best_bid": "0.042", "best_ask": "0.082"}], "timestamp": "1769383998539", "event_type": "price_change"}}
{"_local_timestamp": "2026-01-25T23:33:18.646439+00:00", "data": {"market": "0x2393ed0b0fdc450054c7b9071907eca75cf4fc36e385adf4a0a5f99ee62243e8", "price_changes": [{"asset_id": "100074770378634056601572485653252702850363676459996771990439989989293515601975", "price": "0.098", "size": "50", "side": "SELL", "hash": "6607a2b1b9bceb9dd7ff3b1cc3157356e87a244f", "best_bid": "0.042", "best_ask": "0.082"}, {"asset_id": "32769749367306925959219403371425714180265458150646381231272229429098460625924", "price": "0.902", "size": "50", "side": "BUY", "hash": "784641a490e81e8d0abe1a6c928faa0e7f7c1b0c", "best_bid": "0.918", "best_ask": "0.958"}], "timestamp": "1769383998565", "event_type": "price_change"}}
{"_local_timestamp": "2026-01-25T23:33:18.657753+00:00", "data": {"market": "0x2393ed0b0fdc450054c7b9071907eca75cf4fc36e385adf4a0a5f99ee62243e8", "price_changes": [{"asset_id": "100074770378634056601572485653252702850363676459996771990439989989293515601975", "price": "0.096", "size": "191", "side": "SELL", "hash": "d1708ba705ff838a86d02d9136fedde6b6c45e6c", "best_bid": "0.042", "best_ask": "0.082"}, {"asset_id": "32769749367306925959219403371425714180265458150646381231272229429098460625924", "price": "0.904", "size": "191", "side": "BUY", "hash": "95a2bf45e9f0864ac691e39776f20ee0dcd01de4", "best_bid": "0.918", "best_ask": "0.958"}], "timestamp": "1769383998592", "event_type": "price_change"}}
{"_local_timestamp": "2026-01-25T23:33:18.857179+00:00", "data": {"market": "0x2393ed0b0fdc450054c7b9071907eca75cf4fc36e385adf4a0a5f99ee62243e8", "price_changes": [{"asset_id": "32769749367306925959219403371425714180265458150646381231272229429098460625924", "price": "0.903", "size": "0", "side": "BUY", "hash": "a6201adf927e749d742695b37af216adf0eab977", "best_bid": "0.918", "best_ask": "0.958"}, {"asset_id": "100074770378634056601572485653252702850363676459996771990439989989293515601975", "price": "0.097", "size": "0", "side": "SELL", "hash": "a48f4d1e622910bf09e9ee483d53a402779db77b", "best_bid": "0.042", "best_ask": "0.082"}], "timestamp": "1769383998791", "event_type": "price_change"}}
{"_local_timestamp": "2026-01-25T23:33:19.105665+00:00", "data": {"market": "0x2393ed0b0fdc450054c7b9071907eca75cf4fc36e385adf4a0a5f99ee62243e8", "price_changes": [{"asset_id": "32769749367306925959219403371425714180265458150646381231272229429098460625924", "price": "0.905", "size": "37.81", "side": "BUY", "hash": "a1ff2b5114eee9a9b12f0d8914d8e2c0f563abe8", "best_bid": "0.918", "best_ask": "0.958"}, {"asset_id": "100074770378634056601572485653252702850363676459996771990439989989293515601975", "price": "0.095", "size": "37.81", "side": "SELL", "hash": "0bbacd705c742cdef0b36cffa6ac21649caad121", "best_bid": "0.042", "best_ask": "0.082"}], "timestamp": "1769383999042", "event_type": "price_change"}}
{"_local_timestamp": "2026-01-25T23:33:19.149028+00:00", "data": {"market": "0x2393ed0b0fdc450054c7b9071907eca75cf4fc36e385adf4a0a5f99ee62243e8", "price_changes": [{"asset_id": "100074770378634056601572485653252702850363676459996771990439989989293515601975", "price": "0.035", "size": "0", "side": "BUY", "hash": "39962db4a83b154f461beb9458054eb84cf10671", "best_bid": "0.042", "best_ask": "0.082"}, {"asset_id": "32769749367306925959219403371425714180265458150646381231272229429098460625924", "price": "0.965", "size": "0", "side": "SELL", "hash": "5996c84fdaf43a46c3cd0881dd1c3b75b09cecce", "best_bid": "0.918", "best_ask": "0.958"}], "timestamp": "1769383999074", "event_type": "price_change"}}
{"_local_timestamp": "2026-01-25T23:33:19.452502+00:00", "data": {"market": "0x2393ed0b0fdc450054c7b9071907eca75cf4fc36e385adf4a0a5f99ee62243e8", "price_changes": [{"asset_id": "32769749367306925959219403371425714180265458150646381231272229429098460625924", "price": "0.964", "size": "0", "side": "SELL", "hash": "3068b8ca84100cb7e57da936b41afe2dda7ef886", "best_bid": "0.918", "best_ask": "0.958"}, {"asset_id": "100074770378634056601572485653252702850363676459996771990439989989293515601975", "price": "0.036", "size": "0", "side": "BUY", "hash": "cfa1552b47b18684c347a2da52dc5c01d9bf739e", "best_bid": "0.042", "best_ask": "0.082"}], "timestamp": "1769383999387", "event_type": "price_change"}}
{"_local_timestamp": "2026-01-25T23:33:19.477948+00:00", "data": {"market": "0x2393ed0b0fdc450054c7b9071907eca75cf4fc36e385adf4a0a5f99ee62243e8", "price_changes": [{"asset_id": "100074770378634056601572485653252702850363676459996771990439989989293515601975", "price": "0.029", "size": "54", "side": "BUY", "hash": "c778cd7f69dc98b92233627a4af82ff29d9059b6", "best_bid": "0.042", "best_ask": "0.082"}, {"asset_id": "32769749367306925959219403371425714180265458150646381231272229429098460625924", "price": "0.971", "size": "54", "side": "SELL", "hash": "f74eeb07a351ef46ad4fd211b7c84516c3bb8fda", "best_bid": "0.918", "best_ask": "0.958"}], "timestamp": "1769383999416", "event_type": "price_change"}}
{"_local_timestamp": "2026-01-25T23:33:19.721011+00:00", "data": {"market": "0x2393ed0b0fdc450054c7b9071907eca75cf4fc36e385adf4a0a5f99ee62243e8", "price_changes": [{"asset_id": "32769749367306925959219403371425714180265458150646381231272229429098460625924", "price": "0.966", "size": "112.19", "side": "SELL", "hash": "19dd909c653385446009b50d455d686243cb85ad", "best_bid": "0.918", "best_ask": "0.958"}, {"asset_id": "100074770378634056601572485653252702850363676459996771990439989989293515601975", "price": "0.034", "size": "112.19", "side": "BUY", "hash": "11f751298fa08aa1aecc87d79b29d1d1e2fae50a", "best_bid": "0.042", "best_ask": "0.082"}], "timestamp": "1769383999655", "event_type": "price_change"}}
{"_local_timestamp": "2026-01-25T23:33:20.886173+00:00", "data": {"market": "0x2393ed0b0fdc450054c7b9071907eca75cf4fc36e385adf4a0a5f99ee62243e8", "price_changes": [{"asset_id": "100074770378634056601572485653252702850363676459996771990439989989293515601975", "price": "0.029", "size": "0", "side": "BUY", "hash": "6744e685f0f9534308dcb24deae95a9c61804d6b", "best_bid": "0.042", "best_ask": "0.082"}, {"asset_id": "32769749367306925959219403371425714180265458150646381231272229429098460625924", "price": "0.971", "size": "0", "side": "SELL", "hash": "637d25a2857474ca92f0cadf568494d8606cd5f8", "best_bid": "0.918", "best_ask": "0.958"}], "timestamp": "1769384000816", "event_type": "price_change"}}
{"_local_timestamp": "2026-01-25T23:33:23.243942+00:00", "data": {"market": "0x2393ed0b0fdc450054c7b9071907eca75cf4fc36e385adf4a0a5f99ee62243e8", "price_changes": [{"asset_id": "32769749367306925959219403371425714180265458150646381231272229429098460625924", "price": "0.958", "size": "0", "side": "SELL", "hash": "a43d2c164dda599eb00246d88f88bffe30af61ee", "best_bid": "0.918", "best_ask": "0.961"}, {"asset_id": "100074770378634056601572485653252702850363676459996771990439989989293515601975", "price": "0.042", "size": "0", "side": "BUY", "hash": "673fbe205079827e32c922e1da17519194259082", "best_bid": "0.039", "best_ask": "0.082"}], "timestamp": "1769384003162", "event_type": "price_change"}}
{"_local_timestamp": "2026-01-25T23:33:23.616795+00:00", "data": {"market": "0x2393ed0b0fdc450054c7b9071907eca75cf4fc36e385adf4a0a5f99ee62243e8", "price_changes": [{"asset_id": "32769749367306925959219403371425714180265458150646381231272229429098460625924", "price": "0.906", "size": "50", "side": "BUY", "hash": "f78937b4ef4b7371d7e6727be4fee6bb7e35a4ff", "best_bid": "0.918", "best_ask": "0.961"}, {"asset_id": "100074770378634056601572485653252702850363676459996771990439989989293515601975", "price": "0.094", "size": "50", "side": "SELL", "hash": "d95e743e19a30443103f81c91b6177ea1d0228d1", "best_bid": "0.039", "best_ask": "0.082"}], "timestamp": "1769384003540", "event_type": "price_change"}}
{"_local_timestamp": "2026-01-25T23:33:23.649253+00:00", "data": {"market": "0x2393ed0b0fdc450054c7b9071907eca75cf4fc36e385adf4a0a5f99ee62243e8", "price_changes": [{"asset_id": "100074770378634056601572485653252702850363676459996771990439989989293515601975", "price": "0.096", "size": "0", "side": "SELL", "hash": "608bb41a23eadce8b77c4d94c41f4be4bb9e6269", "best_bid": "0.039", "best_ask": "0.082"}, {"asset_id": "32769749367306925959219403371425714180265458150646381231272229429098460625924", "price": "0.904", "size": "0", "side": "BUY", "hash": "fad208839c2d3e501f27dd691d02cd96dfd6a5c6", "best_bid": "0.918", "best_ask": "0.961"}], "timestamp": "1769384003581", "event_type": "price_change"}}
{"_local_timestamp": "2026-01-25T23:33:23.672764+00:00", "data": {"market": "0x2393ed0b0fdc450054c7b9071907eca75cf4fc36e385adf4a0a5f99ee62243e8", "price_changes": [{"asset_id": "100074770378634056601572485653252702850363676459996771990439989989293515601975", "price": "0.093", "size": "145", "side": "SELL", "hash": "d94daca53ae4650bfa3bdb65f8470d55eb4ccc76", "best_bid": "0.039", "best_ask": "0.082"}, {"asset_id": "32769749367306925959219403371425714180265458150646381231272229429098460625924", "price": "0.907", "size": "145", "side": "BUY", "hash": "d8459d79afb12fbb430a452717fba1ea8c81c79c", "best_bid": "0.918", "best_ask": "0.961"}], "timestamp": "1769384003606", "event_type": "price_change"}}
{"_local_timestamp": "2026-01-25T23:33:23.713566+00:00", "data": {"market": "0x2393ed0b0fdc450054c7b9071907eca75cf4fc36e385adf4a0a5f99ee62243e8", "price_changes": [{"asset_id": "32769749367306925959219403371425714180265458150646381231272229429098460625924", "price": "0.96", "size": "60", "side": "SELL", "hash": "66c83e935792c80f08c73f254d8e6d4c429bed47", "best_bid": "0.918", "best_ask": "0.96"}, {"asset_id": "100074770378634056601572485653252702850363676459996771990439989989293515601975", "price": "0.04", "size": "60", "side": "BUY", "hash": "6a156f5d8a97ea5e0b2a99fe9c71f3cb22d18e51", "best_bid": "0.04", "best_ask": "0.082"}], "timestamp": "1769384003647", "event_type": "price_change"}}
{"_local_timestamp": "2026-01-25T23:33:23.897520+00:00", "data": {"market": "0x2393ed0b0fdc450054c7b9071907eca75cf4fc36e385adf4a0a5f99ee62243e8", "price_changes": [{"asset_id": "32769749367306925959219403371425714180265458150646381231272229429098460625924", "price": "0.905", "size": "0", "side": "BUY", "hash": "0e1e564beacd1c95c6745dec4a69d7b5551119a1", "best_bid": "0.918", "best_ask": "0.96"}, {"asset_id": "100074770378634056601572485653252702850363676459996771990439989989293515601975", "price": "0.095", "size": "0", "side": "SELL", "hash": "968b5b75e771c41a3ae8512cdaef3a0196caeab7", "best_bid": "0.04", "best_ask": "0.082"}], "timestamp": "1769384003800", "event_type": "price_change"}}
{"_local_timestamp": "2026-01-25T23:33:23.909951+00:00", "data": {"market": "0x50c669f178da4e5bbea7f1be25041fd278914712fa87a6a6f8e57d5923d88dee", "price_changes": [{"asset_id": "74040420326294854165772767082819937451857852955603897473157746262672057685461", "price": "0.882", "size": "0", "side": "BUY", "hash": "a43e1f4f9c5421ecf2c8b72eb8835fa52b21308b", "best_bid": "0.995", "best_ask": "0.998"}, {"asset_id": "24682525479474221428144937281315825971983904267399062415430320764754931667953", "price": "0.118", "size": "0", "side": "SELL", "hash": "1019525a1551a9d29cd6ff2f2ff9dfc9b1b83bda", "best_bid": "0.002", "best_ask": "0.005"}], "timestamp": "1769384003834", "event_type": "price_change"}}
{"_local_timestamp": "2026-01-25T23:33:23.911491+00:00", "data": {"market": "0xb9bbdd34304344dcc45803780a34c97d73a00133a5ecf70f63e1008b8abb2fca", "price_changes": [{"asset_id": "8682484153073832526711485265636767086525069344085206423986003504588877767339", "price": "0.88", "size": "0", "side": "BUY", "hash": "dc3aefde1359416cbbb09b67a864e9af9c62a8cc", "best_bid": "0.991", "best_ask": "0.996"}, {"asset_id": "72012724360700510767037780555710363830014634797787940282136454146828040926557", "price": "0.12", "size": "0", "side": "SELL", "hash": "2bb7ac3baf2ea73f4fc7762b0b463e2634bbacf5", "best_bid": "0.004", "best_ask": "0.009"}], "timestamp": "1769384003834", "event_type": "price_change"}}
{"_local_timestamp": "2026-01-25T23:33:23.913402+00:00", "data": {"market": "0xaf9d0e448129a9f657f851d49495ba4742055d80e0ef1166ba0ee81d4d594214", "price_changes": [{"asset_id": "4153292802911610701832309484716814274802943278345248636922528170020319407796", "price": "0.871", "size": "0", "side": "BUY", "hash": "69d80a75bd3c4dcd75b5dca937f53224550cf694", "best_bid": "0.936", "best_ask": "0.988"}, {"asset_id": "101676997363687199724245607342877036148401850938023978421879460310389391082353", "price": "0.129", "size": "0", "side": "SELL", "hash": "2abe10d5a09c5c74136909fa858e98a1f48f0871", "best_bid": "0.012", "best_ask": "0.064"}], "timestamp": "1769384003834", "event_type": "price_change"}}
{"_local_timestamp": "2026-01-25T23:33:23.913923+00:00", "data": {"market": "0x49686d26fb712515cd5e12c23f0a1c7e10214c7faa3cb0a730aabe0c33694082", "price_changes": [{"asset_id": "30442780799048074404860985387051749017905070253466005720364298335239299761065", "price": "0.017", "size": "0", "side": "BUY", "hash": "8446a7a23b4e64ef24452a6dd91f6a0c901780fe", "best_bid": "0.104", "best_ask": "0.133"}, {"asset_id": "13244681086321087932946246027856416106585284024824496763706748621681543444582", "price": "0.983", "size": "0", "side": "SELL", "hash": "f177c89c02ba299a8d7d0f5e145e631fc85c1a2d", "best_bid": "0.867", "best_ask": "0.896"}], "timestamp": "1769384003834", "event_type": "price_change"}}
{"_local_timestamp": "2026-01-25T23:33:23.943706+00:00", "data": {"market": "0xb9bbdd34304344dcc45803780a34c97d73a00133a5ecf70f63e1008b8abb2fca", "price_changes": [{"asset_id": "8682484153073832526711485265636767086525069344085206423986003504588877767339", "price": "0.871", "size": "20", "side": "BUY", "hash": "21890805a99cdabc6709329c2113b33615774507", "best_bid": "0.991", "best_ask": "0.996"}, {"asset_id": "72012724360700510767037780555710363830014634797787940282136454146828040926557", "price": "0.129", "size": "20", "side": "SELL", "hash": "652c22105754bd3ba7a2c9c3de82b762c88c847c", "best_bid": "0.004", "best_ask": "0.009"}], "timestamp": "1769384003865", "event_type": "price_change"}}
{"_local_timestamp": "2026-01-25T23:33:23.945865+00:00", "data": {"market": "0xaf9d0e448129a9f657f851d49495ba4742055d80e0ef1166ba0ee81d4d594214", "price_changes": [{"asset_id": "4153292802911610701832309484716814274802943278345248636922528170020319407796", "price": "0.87", "size": "72.47", "side": "BUY", "hash": "1d2acdbb8746ff5847705c435a65708b93c89e84", "best_bid": "0.936", "best_ask": "0.988"}, {"asset_id": "101676997363687199724245607342877036148401850938023978421879460310389391082353", "price": "0.13", "size": "72.47", "side": "SELL", "hash": "1dd03920a1eeed0c7cd4e58ef913bdcee3f961c8", "best_bid": "0.012", "best_ask": "0.064"}], "timestamp": "1769384003865", "event_type": "price_change"}}
{"_local_timestamp": "2026-01-25T23:33:23.947242+00:00", "data": {"market": "0x50c669f178da4e5bbea7f1be25041fd278914712fa87a6a6f8e57d5923d88dee", "price_changes": [{"asset_id": "74040420326294854165772767082819937451857852955603897473157746262672057685461", "price": "0.879", "size": "20", "side": "BUY", "hash": "763c6978f39440470e3af518b874eb1e6184f273", "best_bid": "0.995", "best_ask": "0.998"}, {"asset_id": "24682525479474221428144937281315825971983904267399062415430320764754931667953", "price": "0.121", "size": "20", "side": "SELL", "hash": "65f07ed1dc7d3a14cafbfa5e75d3d1e64fdf855b", "best_bid": "0.002", "best_ask": "0.005"}], "timestamp": "1769384003865", "event_type": "price_change"}}
{"_local_timestamp": "2026-01-25T23:33:23.947778+00:00", "data": {"market": "0x49686d26fb712515cd5e12c23f0a1c7e10214c7faa3cb0a730aabe0c33694082", "price_changes": [{"asset_id": "30442780799048074404860985387051749017905070253466005720364298335239299761065", "price": "0.015", "size": "131", "side": "BUY", "hash": "1fa8adc531f69431b408d00bc5bcb7d344018166", "best_bid": "0.104", "best_ask": "0.133"}, {"asset_id": "13244681086321087932946246027856416106585284024824496763706748621681543444582", "price": "0.985", "size": "131", "side": "SELL", "hash": "e189c11f82d3b741c9e654a91aeae5107cb21eda", "best_bid": "0.867", "best_ask": "0.896"}], "timestamp": "1769384003865", "event_type": "price_change"}}
{"_local_timestamp": "2026-01-25T23:33:23.993845+00:00", "data": {"market": "0x2393ed0b0fdc450054c7b9071907eca75cf4fc36e385adf4a0a5f99ee62243e8", "price_changes": [{"asset_id": "32769749367306925959219403371425714180265458150646381231272229429098460625924", "price": "0.902", "size": "0", "side": "BUY", "hash": "b3fdb2b90f9bd341743506804f426d59d8c5b263", "best_bid": "0.918", "best_ask": "0.96"}, {"asset_id": "100074770378634056601572485653252702850363676459996771990439989989293515601975", "price": "0.098", "size": "0", "side": "SELL", "hash": "e07307cafdae23f75bf14d9dff2f780b79f37c8a", "best_bid": "0.04", "best_ask": "0.082"}], "timestamp": "1769384003918", "event_type": "price_change"}}
{"_local_timestamp": "2026-01-25T23:33:24.025618+00:00", "data": {"market": "0x2393ed0b0fdc450054c7b9071907eca75cf4fc36e385adf4a0a5f99ee62243e8", "price_changes": [{"asset_id": "100074770378634056601572485653252702850363676459996771990439989989293515601975", "price": "0.041", "size": "131", "side": "BUY", "hash": "15adf0d44bd53423eb0c793602087ae43d53933c", "best_bid": "0.041", "best_ask": "0.082"}, {"asset_id": "32769749367306925959219403371425714180265458150646381231272229429098460625924", "price": "0.959", "size": "131", "side": "SELL", "hash": "b1cbc0371eb91ac9323f4ce25ac2b7f3dc9d30fa", "best_bid": "0.918", "best_ask": "0.959"}], "timestamp": "1769384003953", "event_type": "price_change"}}
{"_local_timestamp": "2026-01-25T23:33:24.121015+00:00", "data": {"market": "0x2393ed0b0fdc450054c7b9071907eca75cf4fc36e385adf4a0a5f99ee62243e8", "price_changes": [{"asset_id": "32769749367306925959219403371425714180265458150646381231272229429098460625924", "price": "0.907", "size": "182.81", "side": "BUY", "hash": "4d36b589d8e15710388d39df0610c01e527296e7", "best_bid": "0.918", "best_ask": "0.959"}, {"asset_id": "100074770378634056601572485653252702850363676459996771990439989989293515601975", "price": "0.093", "size": "182.81", "side": "SELL", "hash": "f2c91c15b3493e12126a660ae5b417d74660afc6", "best_bid": "0.041", "best_ask": "0.082"}], "timestamp": "1769384004055", "event_type": "price_change"}}
{"_local_timestamp": "2026-01-25T23:33:24.497179+00:00", "data": {"market": "0x2393ed0b0fdc450054c7b9071907eca75cf4fc36e385adf4a0a5f99ee62243e8", "price_changes": [{"asset_id": "32769749367306925959219403371425714180265458150646381231272229429098460625924", "price": "0.907", "size": "145", "side": "BUY", "hash": "147d129f45cb26ff260cd3328e58505ab267c4e4", "best_bid": "0.918", "best_ask": "0.959"}, {"asset_id": "100074770378634056601572485653252702850363676459996771990439989989293515601975", "price": "0.093", "size": "145", "side": "SELL", "hash": "87fbf04bad0fa78694dbfee28f1fd8f4242ab0c2", "best_bid": "0.041", "best_ask": "0.082"}], "timestamp": "1769384004431", "event_type": "price_change"}}
{"_local_timestamp": "2026-01-25T23:33:24.831150+00:00", "data": {"market": "0x2393ed0b0fdc450054c7b9071907eca75cf4fc36e385adf4a0a5f99ee62243e8", "price_changes": [{"asset_id": "32769749367306925959219403371425714180265458150646381231272229429098460625924", "price": "0.908", "size": "37.81", "side": "BUY", "hash": "e0e34fae4d6f28ca85ace9c7c251e9ed0849902e", "best_bid": "0.918", "best_ask": "0.959"}, {"asset_id": "100074770378634056601572485653252702850363676459996771990439989989293515601975", "price": "0.092", "size": "37.81", "side": "SELL", "hash": "11bdd739e8d120a6af4346a9d8cd94237454b636", "best_bid": "0.041", "best_ask": "0.082"}], "timestamp": "1769384004761", "event_type": "price_change"}}
{"_local_timestamp": "2026-01-25T23:33:24.861091+00:00", "data": {"market": "0x2393ed0b0fdc450054c7b9071907eca75cf4fc36e385adf4a0a5f99ee62243e8", "price_changes": [{"asset_id": "100074770378634056601572485653252702850363676459996771990439989989293515601975", "price": "0.093", "size": "0", "side": "SELL", "hash": "70ebb4ce83af689df84f8f41f6e5b10608ecf05c", "best_bid": "0.041", "best_ask": "0.082"}, {"asset_id": "32769749367306925959219403371425714180265458150646381231272229429098460625924", "price": "0.907", "size": "0", "side": "BUY", "hash": "f4db1127f742a45e8d8cda5cfa7f6c2a7d996cab", "best_bid": "0.918", "best_ask": "0.959"}], "timestamp": "1769384004785", "event_type": "price_change"}}
{"_local_timestamp": "2026-01-25T23:33:24.885117+00:00", "data": {"market": "0x2393ed0b0fdc450054c7b9071907eca75cf4fc36e385adf4a0a5f99ee62243e8", "price_changes": [{"asset_id": "100074770378634056601572485653252702850363676459996771990439989989293515601975", "price": "0.091", "size": "141", "side": "SELL", "hash": "ffd8afef0e8a0746d00a6b20c52a77cac7d11180", "best_bid": "0.041", "best_ask": "0.082"}, {"asset_id": "32769749367306925959219403371425714180265458150646381231272229429098460625924", "price": "0.909", "size": "141", "side": "BUY", "hash": "46ec5c5db7cc0cbd7853171f441574f48f36f659", "best_bid": "0.918", "best_ask": "0.959"}], "timestamp": "1769384004811", "event_type": "price_change"}}
{"_local_timestamp": "2026-01-25T23:33:25.248976+00:00", "data": {"market": "0x2393ed0b0fdc450054c7b9071907eca75cf4fc36e385adf4a0a5f99ee62243e8", "price_changes": [{"asset_id": "32769749367306925959219403371425714180265458150646381231272229429098460625924", "price": "0.908", "size": "0", "side": "BUY", "hash": "6eba068cf7d2e49332e1be5b9b2d14addf4344f9", "best_bid": "0.918", "best_ask": "0.959"}, {"asset_id": "100074770378634056601572485653252702850363676459996771990439989989293515601975", "price": "0.092", "size": "0", "side": "SELL", "hash": "1c622bed02b127f1015fafd8727e084bd51059c2", "best_bid": "0.041", "best_ask": "0.082"}], "timestamp": "1769384005182", "event_type": "price_change"}}
{"_local_timestamp": "2026-01-25T23:33:25.686328+00:00", "data": {"market": "0x2393ed0b0fdc450054c7b9071907eca75cf4fc36e385adf4a0a5f99ee62243e8", "price_changes": [{"asset_id": "32769749367306925959219403371425714180265458150646381231272229429098460625924", "price": "0.91", "size": "37.81", "side": "BUY", "hash": "b896a5c3df97e53debd49414f651630ae7bcc133", "best_bid": "0.918", "best_ask": "0.959"}, {"asset_id": "100074770378634056601572485653252702850363676459996771990439989989293515601975", "price": "0.09", "size": "37.81", "side": "SELL", "hash": "dd425262fb2adb2020fbc07ed3e6c36614a6b6db", "best_bid": "0.041", "best_ask": "0.082"}], "timestamp": "1769384005617", "event_type": "price_change"}}
{"_local_timestamp": "2026-01-25T23:33:25.717662+00:00", "data": {"market": "0x2393ed0b0fdc450054c7b9071907eca75cf4fc36e385adf4a0a5f99ee62243e8", "price_changes": [{"asset_id": "100074770378634056601572485653252702850363676459996771990439989989293515601975", "price": "0.041", "size": "0", "side": "BUY", "hash": "28eeb7bf2ae898a3c541daa4e875a736544e3dc8", "best_bid": "0.04", "best_ask": "0.082"}, {"asset_id": "32769749367306925959219403371425714180265458150646381231272229429098460625924", "price": "0.959", "size": "0", "side": "SELL", "hash": "5eced72659a48c84668eebfa7170157847fb25ad", "best_bid": "0.918", "best_ask": "0.96"}], "timestamp": "1769384005648", "event_type": "price_change"}}
{"_local_timestamp": "2026-01-25T23:33:26.384126+00:00", "data": {"market": "0x2393ed0b0fdc450054c7b9071907eca75cf4fc36e385adf4a0a5f99ee62243e8", "price_changes": [{"asset_id": "100074770378634056601572485653252702850363676459996771990439989989293515601975", "price": "0.091", "size": "0", "side": "SELL", "hash": "022c32cccee09d7775f87dd93aa63fc27bf3cf8a", "best_bid": "0.04", "best_ask": "0.082"}, {"asset_id": "32769749367306925959219403371425714180265458150646381231272229429098460625924", "price": "0.909", "size": "0", "side": "BUY", "hash": "58d4b55453ac1fdc82f339292c6ea92aa4ea990a", "best_bid": "0.918", "best_ask": "0.96"}], "timestamp": "1769384006315", "event_type": "price_change"}}
{"_local_timestamp": "2026-01-25T23:33:26.406112+00:00", "data": {"market": "0x2393ed0b0fdc450054c7b9071907eca75cf4fc36e385adf4a0a5f99ee62243e8", "price_changes": [{"asset_id": "100074770378634056601572485653252702850363676459996771990439989989293515601975", "price": "0.035", "size": "35", "side": "BUY", "hash": "90a30c6d5adf940a07b209de4e3d4361a6aa5f14", "best_bid": "0.04", "best_ask": "0.082"}, {"asset_id": "32769749367306925959219403371425714180265458150646381231272229429098460625924", "price": "0.965", "size": "35", "side": "SELL", "hash": "2afc739ff8d5a096c014114e8de4e731f11a9219", "best_bid": "0.918", "best_ask": "0.96"}], "timestamp": "1769384006340", "event_type": "price_change"}}
{"_local_timestamp": "2026-01-25T23:33:26.421887+00:00", "data": {"market": "0x2393ed0b0fdc450054c7b9071907eca75cf4fc36e385adf4a0a5f99ee62243e8", "price_changes": [{"asset_id": "100074770378634056601572485653252702850363676459996771990439989989293515601975", "price": "0.089", "size": "141", "side": "SELL", "hash": "cd8bbe5635dd2a7542d56665d10838ffca3b014b", "best_bid": "0.04", "best_ask": "0.082"}, {"asset_id": "32769749367306925959219403371425714180265458150646381231272229429098460625924", "price": "0.911", "size": "141", "side": "BUY", "hash": "6d284acc70ce7b37f1fa99fb02e46c189af97b55", "best_bid": "0.918", "best_ask": "0.96"}], "timestamp": "1769384006351", "event_type": "price_change"}}
{"_local_timestamp": "2026-01-25T23:33:26.521468+00:00", "data": {"market": "0xb9bbdd34304344dcc45803780a34c97d73a00133a5ecf70f63e1008b8abb2fca", "price_changes": [{"asset_id": "8682484153073832526711485265636767086525069344085206423986003504588877767339", "price": "0.002", "size": "5.25", "side": "BUY", "hash": "e787b99c3d58542ed9fbe35acea503274a61253c", "best_bid": "0.991", "best_ask": "0.996"}, {"asset_id": "72012724360700510767037780555710363830014634797787940282136454146828040926557", "price": "0.998", "size": "5.25", "side": "SELL", "hash": "d1089d7478d5aabb843c2cee5e6cc605f0254cee", "best_bid": "0.004", "best_ask": "0.009"}], "timestamp": "1769384006454", "event_type": "price_change"}}
{"_local_timestamp": "2026-01-25T23:33:26.522119+00:00", "data": {"market": "0xb9bbdd34304344dcc45803780a34c97d73a00133a5ecf70f63e1008b8abb2fca", "price_changes": [{"asset_id": "8682484153073832526711485265636767086525069344085206423986003504588877767339", "price": "0.011", "size": "18.4", "side": "BUY", "hash": "253901d9f66bfb38d623609c17ccf652388d0537", "best_bid": "0.991", "best_ask": "0.996"}, {"asset_id": "72012724360700510767037780555710363830014634797787940282136454146828040926557", "price": "0.989", "size": "18.4", "side": "SELL", "hash": "80e106edf27f6ad5a199f2c1a251ef7da6168a63", "best_bid": "0.004", "best_ask": "0.009"}], "timestamp": "1769384006455", "event_type": "price_change"}}
{"_local_timestamp": "2026-01-25T23:33:26.524702+00:00", "data": {"market": "0xb9bbdd34304344dcc45803780a34c97d73a00133a5ecf70f63e1008b8abb2fca", "price_changes": [{"asset_id": "8682484153073832526711485265636767086525069344085206423986003504588877767339", "price": "0.004", "size": "9.09", "side": "BUY", "hash": "84c81d155820d762aad965dacb56903a4ac6de27", "best_bid": "0.991", "best_ask": "0.996"}, {"asset_id": "72012724360700510767037780555710363830014634797787940282136454146828040926557", "price": "0.996", "size": "9.09", "side": "SELL", "hash": "72b75c8a7f1063a334b047cb45efcb02790e50e6", "best_bid": "0.004", "best_ask": "0.009"}], "timestamp": "1769384006456", "event_type": "price_change"}}
{"_local_timestamp": "2026-01-25T23:33:26.525450+00:00", "data": {"market": "0xb9bbdd34304344dcc45803780a34c97d73a00133a5ecf70f63e1008b8abb2fca", "price_changes": [{"asset_id": "8682484153073832526711485265636767086525069344085206423986003504588877767339", "price": "0.001", "size": "6103.59", "side": "BUY", "hash": "9814e5ff3abaf52358965126d73271b4c49e7d40", "best_bid": "0.991", "best_ask": "0.996"}, {"asset_id": "72012724360700510767037780555710363830014634797787940282136454146828040926557", "price": "0.999", "size": "6103.59", "side": "SELL", "hash": "701ba0a95d89197c02e5a5719f7151ded68ddab7", "best_bid": "0.004", "best_ask": "0.009"}], "timestamp": "1769384006457", "event_type": "price_change"}}
{"_local_timestamp": "2026-01-25T23:33:26.525958+00:00", "data": {"market": "0xb9bbdd34304344dcc45803780a34c97d73a00133a5ecf70f63e1008b8abb2fca", "price_changes": [{"asset_id": "8682484153073832526711485265636767086525069344085206423986003504588877767339", "price": "0.201", "size": "5.69", "side": "BUY", "hash": "f3a77b92e24c065a8cd2b034af1adf25b7227a4d", "best_bid": "0.991", "best_ask": "0.996"}, {"asset_id": "72012724360700510767037780555710363830014634797787940282136454146828040926557", "price": "0.799", "size": "5.69", "side": "SELL", "hash": "b7bad4fa4abfa2a14a9c6fd50a67505a20b81464", "best_bid": "0.004", "best_ask": "0.009"}], "timestamp": "1769384006458", "event_type": "price_change"}}
{"_local_timestamp": "2026-01-25T23:33:26.526395+00:00", "data": {"market": "0xb9bbdd34304344dcc45803780a34c97d73a00133a5ecf70f63e1008b8abb2fca", "price_changes": [{"asset_id": "8682484153073832526711485265636767086525069344085206423986003504588877767339", "price": "0.052", "size": "11.55", "side": "BUY", "hash": "0636ef6da51ed465e35738050e70da9bdb43c9a8", "best_bid": "0.991", "best_ask": "0.996"}, {"asset_id": "72012724360700510767037780555710363830014634797787940282136454146828040926557", "price": "0.948", "size": "11.55", "side": "SELL", "hash": "e30e4ffc47f467a1f9e06fbffc7ba44ddb32dd0b", "best_bid": "0.004", "best_ask": "0.009"}], "timestamp": "1769384006458", "event_type": "price_change"}}
{"_local_timestamp": "2026-01-25T23:33:26.782737+00:00", "data": {"market": "0x2393ed0b0fdc450054c7b9071907eca75cf4fc36e385adf4a0a5f99ee62243e8", "price_changes": [{"asset_id": "32769749367306925959219403371425714180265458150646381231272229429098460625924", "price": "0.91", "size": "0", "side": "BUY", "hash": "9c652d69133bbfbe62281e4112b76181199201ac", "best_bid": "0.918", "best_ask": "0.96"}, {"asset_id": "100074770378634056601572485653252702850363676459996771990439989989293515601975", "price": "0.09", "size": "0", "side": "SELL", "hash": "b7d0a50425bc376548daece3db9064bd8dd7cb86", "best_bid": "0.04", "best_ask": "0.082"}], "timestamp": "1769384006708", "event_type": "price_change"}}
{"_local_timestamp": "2026-01-25T23:33:26.841818+00:00", "data": {"market": "0x2393ed0b0fdc450054c7b9071907eca75cf4fc36e385adf4a0a5f99ee62243e8", "price_changes": [{"asset_id": "32769749367306925959219403371425714180265458150646381231272229429098460625924", "price": "0.966", "size": "0", "side": "SELL", "hash": "ee1e458128658de5d6785bf41a00b731226f7ec9", "best_bid": "0.918", "best_ask": "0.96"}, {"asset_id": "100074770378634056601572485653252702850363676459996771990439989989293515601975", "price": "0.034", "size": "0", "side": "BUY", "hash": "62cae07242414f787e8b14c78f86db022adb9761", "best_bid": "0.04", "best_ask": "0.082"}], "timestamp": "1769384006775", "event_type": "price_change"}}
{"_local_timestamp": "2026-01-25T23:33:27.300005+00:00", "data": {"market": "0x2393ed0b0fdc450054c7b9071907eca75cf4fc36e385adf4a0a5f99ee62243e8", "price_changes": [{"asset_id": "32769749367306925959219403371425714180265458150646381231272229429098460625924", "price": "0.912", "size": "37.81", "side": "BUY", "hash": "a633dba8f63ff6f520d552fb902000ee813d602d", "best_bid": "0.918", "best_ask": "0.96"}, {"asset_id": "100074770378634056601572485653252702850363676459996771990439989989293515601975", "price": "0.088", "size": "37.81", "side": "SELL", "hash": "f6be13d43e878171192516dc484a9dfc3ba2f18b", "best_bid": "0.04", "best_ask": "0.082"}], "timestamp": "1769384007235", "event_type": "price_change"}}
{"_local_timestamp": "2026-01-25T23:33:27.408108+00:00", "data": {"market": "0x2393ed0b0fdc450054c7b9071907eca75cf4fc36e385adf4a0a5f99ee62243e8", "price_changes": [{"asset_id": "32769749367306925959219403371425714180265458150646381231272229429098460625924", "price": "0.964", "size": "112.19", "side": "SELL", "hash": "9f405559109776a38fe9c8b1966b42204a689bb4", "best_bid": "0.918", "best_ask": "0.96"}, {"asset_id": "100074770378634056601572485653252702850363676459996771990439989989293515601975", "price": "0.036", "size": "112.19", "side": "BUY", "hash": "7046d832832fa326c7d5d11a0effc087cfce8c65", "best_bid": "0.04", "best_ask": "0.082"}], "timestamp": "1769384007330", "event_type": "price_change"}}
{"_local_timestamp": "2026-01-25T23:33:27.881474+00:00", "data": {"market": "0x2393ed0b0fdc450054c7b9071907eca75cf4fc36e385adf4a0a5f99ee62243e8", "price_changes": [{"asset_id": "100074770378634056601572485653252702850363676459996771990439989989293515601975", "price": "0.035", "size": "0", "side": "BUY", "hash": "b5ea6088240894664ecdb402c0b8fc11d98f673e", "best_bid": "0.04", "best_ask": "0.082"}, {"asset_id": "32769749367306925959219403371425714180265458150646381231272229429098460625924", "price": "0.965", "size": "0", "side": "SELL", "hash": "c821b1b40706505f7f644a33705b488959317df2", "best_bid": "0.918", "best_ask": "0.96"}], "timestamp": "1769384007813", "event_type": "price_change"}}
{"_local_timestamp": "2026-01-25T23:33:28.264091+00:00", "data": {"market": "0x2393ed0b0fdc450054c7b9071907eca75cf4fc36e385adf4a0a5f99ee62243e8", "price_changes": [{"asset_id": "32769749367306925959219403371425714180265458150646381231272229429098460625924", "price": "0.964", "size": "0", "side": "SELL", "hash": "652431749957903f585f8e9459ff0748f1a420d7", "best_bid": "0.918", "best_ask": "0.96"}, {"asset_id": "100074770378634056601572485653252702850363676459996771990439989989293515601975", "price": "0.036", "size": "0", "side": "BUY", "hash": "17ec6a06f4e77c2892144b3fcd8e97545026debd", "best_bid": "0.04", "best_ask": "0.082"}], "timestamp": "1769384008175", "event_type": "price_change"}}
{"_local_timestamp": "2026-01-25T23:33:28.269985+00:00", "data": {"market": "0x2393ed0b0fdc450054c7b9071907eca75cf4fc36e385adf4a0a5f99ee62243e8", "price_changes": [{"asset_id": "100074770378634056601572485653252702850363676459996771990439989989293515601975", "price": "0.089", "size": "0", "side": "SELL", "hash": "ebce5d17fb569a94bea7642bfee9ecfe571cbffb", "best_bid": "0.04", "best_ask": "0.082"}, {"asset_id": "32769749367306925959219403371425714180265458150646381231272229429098460625924", "price": "0.911", "size": "0", "side": "BUY", "hash": "2ce1170dfe18acc3abfdedb2f740368af94d4478", "best_bid": "0.918", "best_ask": "0.96"}], "timestamp": "1769384008203", "event_type": "price_change"}}
{"_local_timestamp": "2026-01-25T23:33:28.272097+00:00", "data": {"market": "0x2393ed0b0fdc450054c7b9071907eca75cf4fc36e385adf4a0a5f99ee62243e8", "price_changes": [{"asset_id": "100074770378634056601572485653252702850363676459996771990439989989293515601975", "price": "0.028", "size": "27.4", "side": "BUY", "hash": "d8ca95cce39cf6b0f785d59bde86aa062fe32889", "best_bid": "0.04", "best_ask": "0.082"}, {"asset_id": "32769749367306925959219403371425714180265458150646381231272229429098460625924", "price": "0.972", "size": "27.4", "side": "SELL", "hash": "2a4f9f347cf10a24cd247ba2eb2bf4bdac3e27a0", "best_bid": "0.918", "best_ask": "0.96"}], "timestamp": "1769384008204", "event_type": "price_change"}}
{"_local_timestamp": "2026-01-25T23:33:28.297264+00:00", "data": {"market": "0x2393ed0b0fdc450054c7b9071907eca75cf4fc36e385adf4a0a5f99ee62243e8", "price_changes": [{"asset_id": "100074770378634056601572485653252702850363676459996771990439989989293515601975", "price": "0.087", "size": "145", "side": "SELL", "hash": "8cde9ff95ff2501772b6a0f62d6eb619646ad9f4", "best_bid": "0.04", "best_ask": "0.082"}, {"asset_id": "32769749367306925959219403371425714180265458150646381231272229429098460625924", "price": "0.913", "size": "145", "side": "BUY", "hash": "a9d212150183da00a16a72bd76743d774bbb9d06", "best_bid": "0.918", "best_ask": "0.96"}], "timestamp": "1769384008232", "event_type": "price_change"}}
{"_local_timestamp": "2026-01-25T23:33:28.723446+00:00", "data": {"market": "0x2393ed0b0fdc450054c7b9071907eca75cf4fc36e385adf4a0a5f99ee62243e8", "price_changes": [{"asset_id": "32769749367306925959219403371425714180265458150646381231272229429098460625924", "price": "0.966", "size": "112.19", "side": "SELL", "hash": "601f6e8f185380bf7f0dbcf268f047a126146d7a", "best_bid": "0.918", "best_ask": "0.96"}, {"asset_id": "100074770378634056601572485653252702850363676459996771990439989989293515601975", "price": "0.034", "size": "112.19", "side": "BUY", "hash": "9e64ab0d9ce31da44b08c34dfc4449afa0b6d431", "best_bid": "0.04", "best_ask": "0.082"}], "timestamp": "1769384008657", "event_type": "price_change"}}
{"_local_timestamp": "2026-01-25T23:33:28.752047+00:00", "data": {"market": "0x2393ed0b0fdc450054c7b9071907eca75cf4fc36e385adf4a0a5f99ee62243e8", "price_changes": [{"asset_id": "32769749367306925959219403371425714180265458150646381231272229429098460625924", "price": "0.912", "size": "0", "side": "BUY", "hash": "8a0f6a8ddb69f004890b3df858bf7888b01dc0b5", "best_bid": "0.918", "best_ask": "0.96"}, {"asset_id": "100074770378634056601572485653252702850363676459996771990439989989293515601975", "price": "0.088", "size": "0", "side": "SELL", "hash": "adb08c991951e74b93be394b7ad4fcd60ae7f423", "best_bid": "0.04", "best_ask": "0.082"}], "timestamp": "1769384008677", "event_type": "price_change"}}
{"_local_timestamp": "2026-01-25T23:33:29.049504+00:00", "data": {"market": "0x2393ed0b0fdc450054c7b9071907eca75cf4fc36e385adf4a0a5f99ee62243e8", "price_changes": [{"asset_id": "32769749367306925959219403371425714180265458150646381231272229429098460625924", "price": "0.901", "size": "0", "side": "BUY", "hash": "4678e654a35483e18f93ffef24ff2b152594613e", "best_bid": "0.918", "best_ask": "0.96"}, {"asset_id": "100074770378634056601572485653252702850363676459996771990439989989293515601975", "price": "0.099", "size": "0", "side": "SELL", "hash": "3940577b1e7387fd704201394c7bccf70d8e817a", "best_bid": "0.04", "best_ask": "0.082"}], "timestamp": "1769384008982", "event_type": "price_change"}}
{"_local_timestamp": "2026-01-25T23:33:29.129101+00:00", "data": {"market": "0x2393ed0b0fdc450054c7b9071907eca75cf4fc36e385adf4a0a5f99ee62243e8", "price_changes": [{"asset_id": "32769749367306925959219403371425714180265458150646381231272229429098460625924", "price": "0.914", "size": "30", "side": "BUY", "hash": "dd57624d50b19da126763d2b099c6673c531f910", "best_bid": "0.918", "best_ask": "0.96"}, {"asset_id": "100074770378634056601572485653252702850363676459996771990439989989293515601975", "price": "0.086", "size": "30", "side": "SELL", "hash": "21e4bf213d61f806f8027806363ba5ad009d53bc", "best_bid": "0.04", "best_ask": "0.082"}], "timestamp": "1769384009059", "event_type": "price_change"}}
{"_local_timestamp": "2026-01-25T23:33:29.246584+00:00", "data": {"market": "0x2393ed0b0fdc450054c7b9071907eca75cf4fc36e385adf4a0a5f99ee62243e8", "price_changes": [{"asset_id": "32769749367306925959219403371425714180265458150646381231272229429098460625924", "price": "0.914", "size": "67.81", "side": "BUY", "hash": "b5073297852c477146a51d291b8f61f24f14a0ba", "best_bid": "0.918", "best_ask": "0.96"}, {"asset_id": "100074770378634056601572485653252702850363676459996771990439989989293515601975", "price": "0.086", "size": "67.81", "side": "SELL", "hash": "0a1d98f37bfba54eebc677575ee814d55aab16c6", "best_bid": "0.04", "best_ask": "0.082"}], "timestamp": "1769384009176", "event_type": "price_change"}}
{"_local_timestamp": "2026-01-25T23:33:29.389276+00:00", "data": {"market": "0x2393ed0b0fdc450054c7b9071907eca75cf4fc36e385adf4a0a5f99ee62243e8", "price_changes": [{"asset_id": "100074770378634056601572485653252702850363676459996771990439989989293515601975", "price": "0.028", "size": "9.4", "side": "BUY", "hash": "489bc4ed3ddf8d7c99531a0495e00360906a9c1d", "best_bid": "0.04", "best_ask": "0.082"}, {"asset_id": "32769749367306925959219403371425714180265458150646381231272229429098460625924", "price": "0.972", "size": "9.4", "side": "SELL", "hash": "5c5260afada66dac5f5c622dba0e51dce4fa99a1", "best_bid": "0.918", "best_ask": "0.96"}], "timestamp": "1769384009316", "event_type": "price_change"}}
{"_local_timestamp": "2026-01-25T23:33:29.406229+00:00", "data": {"market": "0x2393ed0b0fdc450054c7b9071907eca75cf4fc36e385adf4a0a5f99ee62243e8", "price_changes": [{"asset_id": "100074770378634056601572485653252702850363676459996771990439989989293515601975", "price": "0.035", "size": "170", "side": "BUY", "hash": "e391fce270193f27cfb26a002c7a4acfd9cc7aba", "best_bid": "0.04", "best_ask": "0.082"}, {"asset_id": "32769749367306925959219403371425714180265458150646381231272229429098460625924", "price": "0.965", "size": "170", "side": "SELL", "hash": "ee1e8894bd105234c8d7dce3ecadd45f27201d89", "best_bid": "0.918", "best_ask": "0.96"}], "timestamp": "1769384009341", "event_type": "price_change"}}
{"_local_timestamp": "2026-01-25T23:33:29.794915+00:00", "data": {"market": "0x2393ed0b0fdc450054c7b9071907eca75cf4fc36e385adf4a0a5f99ee62243e8", "price_changes": [{"asset_id": "32769749367306925959219403371425714180265458150646381231272229429098460625924", "price": "0.915", "size": "50", "side": "BUY", "hash": "61342cc72df39866e14df30b37549ca0215566ab", "best_bid": "0.918", "best_ask": "0.96"}, {"asset_id": "100074770378634056601572485653252702850363676459996771990439989989293515601975", "price": "0.085", "size": "50", "side": "SELL", "hash": "55acfd7652b10dea24e566c55eedaef987631b7c", "best_bid": "0.04", "best_ask": "0.082"}], "timestamp": "1769384009719", "event_type": "price_change"}}
{"_local_timestamp": "2026-01-25T23:33:29.950459+00:00", "data": {"market": "0x2393ed0b0fdc450054c7b9071907eca75cf4fc36e385adf4a0a5f99ee62243e8", "price_changes": [{"asset_id": "32769749367306925959219403371425714180265458150646381231272229429098460625924", "price": "0.914", "size": "30", "side": "BUY", "hash": "06e8917801b40d017c5a42fe9dc31df551321c4e", "best_bid": "0.918", "best_ask": "0.96"}, {"asset_id": "100074770378634056601572485653252702850363676459996771990439989989293515601975", "price": "0.086", "size": "30", "side": "SELL", "hash": "a5513f2e167bfd7df5d3152be09a82298a9fa272", "best_bid": "0.04", "best_ask": "0.082"}], "timestamp": "1769384009882", "event_type": "price_change"}}
{"_local_timestamp": "2026-01-25T23:33:30.088742+00:00", "data": {"market": "0x2393ed0b0fdc450054c7b9071907eca75cf4fc36e385adf4a0a5f99ee62243e8", "price_changes": [{"asset_id": "32769749367306925959219403371425714180265458150646381231272229429098460625924", "price": "0.966", "size": "0", "side": "SELL", "hash": "f5584e44576780e41de3edc02f1e2f62421b5017", "best_bid": "0.918", "best_ask": "0.96"}, {"asset_id": "100074770378634056601572485653252702850363676459996771990439989989293515601975", "price": "0.034", "size": "0", "side": "BUY", "hash": "7c97dc175c8b512938dada9fb09740dfb214cf74", "best_bid": "0.04", "best_ask": "0.082"}], "timestamp": "1769384010007", "event_type": "price_change"}}
{"_local_timestamp": "2026-01-25T23:33:30.101298+00:00", "data": {"market": "0x2393ed0b0fdc450054c7b9071907eca75cf4fc36e385adf4a0a5f99ee62243e8", "price_changes": [{"asset_id": "32769749367306925959219403371425714180265458150646381231272229429098460625924", "price": "0.906", "size": "0", "side": "BUY", "hash": "bd7e189930cea1255346341ca855d0ffe71da02c", "best_bid": "0.918", "best_ask": "0.96"}, {"asset_id": "100074770378634056601572485653252702850363676459996771990439989989293515601975", "price": "0.094", "size": "0", "side": "SELL", "hash": "4bb56436f9c0cdb9bf55a240a114e748c127a842", "best_bid": "0.04", "best_ask": "0.082"}], "timestamp": "1769384010012", "event_type": "price_change"}}
{"_local_timestamp": "2026-01-25T23:33:30.800955+00:00", "data": {"market": "0x2393ed0b0fdc450054c7b9071907eca75cf4fc36e385adf4a0a5f99ee62243e8", "price_changes": [{"asset_id": "32769749367306925959219403371425714180265458150646381231272229429098460625924", "price": "0.915", "size": "87.81", "side": "BUY", "hash": "46ebbdc60574f8308c22a882dba695dc0c233bcf", "best_bid": "0.918", "best_ask": "0.96"}, {"asset_id": "100074770378634056601572485653252702850363676459996771990439989989293515601975", "price": "0.085", "size": "87.81", "side": "SELL", "hash": "b5fd39bac9a230b3501e83a34b019eba023f80cb", "best_bid": "0.04", "best_ask": "0.082"}], "timestamp": "1769384010729", "event_type": "price_change"}}
{"_local_timestamp": "2026-01-25T23:33:30.822909+00:00", "data": {"market": "0x2393ed0b0fdc450054c7b9071907eca75cf4fc36e385adf4a0a5f99ee62243e8", "price_changes": [{"asset_id": "100074770378634056601572485653252702850363676459996771990439989989293515601975", "price": "0.035", "size": "0", "side": "BUY", "hash": "8a6df05e0e302692bbcae785c8ae5c33d15a504e", "best_bid": "0.04", "best_ask": "0.082"}, {"asset_id": "32769749367306925959219403371425714180265458150646381231272229429098460625924", "price": "0.965", "size": "0", "side": "SELL", "hash": "92a3aa7b17de6729548a3be0cb332f3e1c928a7f", "best_bid": "0.918", "best_ask": "0.96"}], "timestamp": "1769384010753", "event_type": "price_change"}}
{"_local_timestamp": "2026-01-25T23:33:30.846219+00:00", "data": {"market": "0x2393ed0b0fdc450054c7b9071907eca75cf4fc36e385adf4a0a5f99ee62243e8", "price_changes": [{"asset_id": "100074770378634056601572485653252702850363676459996771990439989989293515601975", "price": "0.034", "size": "194", "side": "BUY", "hash": "c6d72df5183661a2d3e659041a409d33b13750c4", "best_bid": "0.04", "best_ask": "0.082"}, {"asset_id": "32769749367306925959219403371425714180265458150646381231272229429098460625924", "price": "0.966", "size": "194", "side": "SELL", "hash": "54b014763f2fbf74474e1bf3558957aa7a816646", "best_bid": "0.918", "best_ask": "0.96"}], "timestamp": "1769384010781", "event_type": "price_change"}}
{"_local_timestamp": "2026-01-25T23:33:30.990457+00:00", "data": {"market": "0x2393ed0b0fdc450054c7b9071907eca75cf4fc36e385adf4a0a5f99ee62243e8", "price_changes": [{"asset_id": "32769749367306925959219403371425714180265458150646381231272229429098460625924", "price": "0.964", "size": "112.19", "side": "SELL", "hash": "2925f4345f810e4e4048ba0a3cda8b425529dca9", "best_bid": "0.918", "best_ask": "0.96"}, {"asset_id": "100074770378634056601572485653252702850363676459996771990439989989293515601975", "price": "0.036", "size": "112.19", "side": "BUY", "hash": "2a48e7af1ee13e5efedcc7e2e95f1fceed804e14", "best_bid": "0.04", "best_ask": "0.082"}], "timestamp": "1769384010924", "event_type": "price_change"}}
{"_local_timestamp": "2026-01-25T23:33:31.675521+00:00", "data": {"market": "0x2393ed0b0fdc450054c7b9071907eca75cf4fc36e385adf4a0a5f99ee62243e8", "price_changes": [{"asset_id": "32769749367306925959219403371425714180265458150646381231272229429098460625924", "price": "0.915", "size": "50", "side": "BUY", "hash": "6c608c1bf9328913b9def96cd2f73a8670fc2d63", "best_bid": "0.918", "best_ask": "0.96"}, {"asset_id": "100074770378634056601572485653252702850363676459996771990439989989293515601975", "price": "0.085", "size": "50", "side": "SELL", "hash": "8ae4af7f03a3f90e942005410bd77f373fc86b2e", "best_bid": "0.04", "best_ask": "0.082"}], "timestamp": "1769384011610", "event_type": "price_change"}}
{"_local_timestamp": "2026-01-25T23:33:31.886649+00:00", "data": {"market": "0x2393ed0b0fdc450054c7b9071907eca75cf4fc36e385adf4a0a5f99ee62243e8", "price_changes": [{"asset_id": "100074770378634056601572485653252702850363676459996771990439989989293515601975", "price": "0.034", "size": "0", "side": "BUY", "hash": "ec5fa0433da0d1f55dd950488bbe5398a5e4bd98", "best_bid": "0.04", "best_ask": "0.082"}, {"asset_id": "32769749367306925959219403371425714180265458150646381231272229429098460625924", "price": "0.966", "size": "0", "side": "SELL", "hash": "ab5c7a3168dc9c6aad95e6420f5990c715f1bb83", "best_bid": "0.918", "best_ask": "0.96"}], "timestamp": "1769384011815", "event_type": "price_change"}}
{"_local_timestamp": "2026-01-25T23:33:31.923346+00:00", "data": {"market": "0x2393ed0b0fdc450054c7b9071907eca75cf4fc36e385adf4a0a5f99ee62243e8", "price_changes": [{"asset_id": "100074770378634056601572485653252702850363676459996771990439989989293515601975", "price": "0.041", "size": "58", "side": "BUY", "hash": "49574c9d07c122103cd8504c42066a7dd4cdefa7", "best_bid": "0.041", "best_ask": "0.082"}, {"asset_id": "32769749367306925959219403371425714180265458150646381231272229429098460625924", "price": "0.959", "size": "58", "side": "SELL", "hash": "ccffbb4ed6bfc3b2fff2067790151dc242ed67c3", "best_bid": "0.918", "best_ask": "0.959"}], "timestamp": "1769384011847", "event_type": "price_change"}}
{"_local_timestamp": "2026-01-25T23:33:31.966563+00:00", "data": {"market": "0x2393ed0b0fdc450054c7b9071907eca75cf4fc36e385adf4a0a5f99ee62243e8", "price_changes": [{"asset_id": "32769749367306925959219403371425714180265458150646381231272229429098460625924", "price": "0.964", "size": "0", "side": "SELL", "hash": "69864949177bfac30e9932b8b8727b82b9bb431a", "best_bid": "0.918", "best_ask": "0.959"}, {"asset_id": "100074770378634056601572485653252702850363676459996771990439989989293515601975", "price": "0.036", "size": "0", "side": "BUY", "hash": "29046ed64a59ecb337486b98b016e553fc9bd4c9", "best_bid": "0.041", "best_ask": "0.082"}], "timestamp": "1769384011902", "event_type": "price_change"}}
{"_local_timestamp": "2026-01-25T23:33:32.242541+00:00", "data": {"market": "0x50c669f178da4e5bbea7f1be25041fd278914712fa87a6a6f8e57d5923d88dee", "price_changes": [{"asset_id": "74040420326294854165772767082819937451857852955603897473157746262672057685461", "price": "0.879", "size": "0", "side": "BUY", "hash": "10074e75b4931c4d7b96c9aa74aa9a020f3fa7e7", "best_bid": "0.995", "best_ask": "0.998"}, {"asset_id": "24682525479474221428144937281315825971983904267399062415430320764754931667953", "price": "0.121", "size": "0", "side": "SELL", "hash": "99703171d0a889a183a6c319cfcc1ec0f9892788", "best_bid": "0.002", "best_ask": "0.005"}], "timestamp": "1769384012172", "event_type": "price_change"}}
{"_local_timestamp": "2026-01-25T23:33:32.243804+00:00", "data": {"market": "0xb9bbdd34304344dcc45803780a34c97d73a00133a5ecf70f63e1008b8abb2fca", "price_changes": [{"asset_id": "8682484153073832526711485265636767086525069344085206423986003504588877767339", "price": "0.871", "size": "0", "side": "BUY", "hash": "b695d5ad890d0438ea5baf3ca93dedfaa23e1bb3", "best_bid": "0.991", "best_ask": "0.996"}, {"asset_id": "72012724360700510767037780555710363830014634797787940282136454146828040926557", "price": "0.129", "size": "0", "side": "SELL", "hash": "03eef236fdcfe29b9bcefb240fddccadbfe78c39", "best_bid": "0.004", "best_ask": "0.009"}], "timestamp": "1769384012172", "event_type": "price_change"}}
{"_local_timestamp": "2026-01-25T23:33:32.244758+00:00", "data": {"market": "0x49686d26fb712515cd5e12c23f0a1c7e10214c7faa3cb0a730aabe0c33694082", "price_changes": [{"asset_id": "30442780799048074404860985387051749017905070253466005720364298335239299761065", "price": "0.015", "size": "111", "side": "BUY", "hash": "7a1391f3d1be87925b1b329de70c816554412b89", "best_bid": "0.104", "best_ask": "0.133"}, {"asset_id": "13244681086321087932946246027856416106585284024824496763706748621681543444582", "price": "0.985", "size": "111", "side": "SELL", "hash": "43597e11ae202b868d3e00928d3c701d22ffac84", "best_bid": "0.867", "best_ask": "0.896"}], "timestamp": "1769384012172", "event_type": "price_change"}}
{"_local_timestamp": "2026-01-25T23:33:32.245319+00:00", "data": {"market": "0xaf9d0e448129a9f657f851d49495ba4742055d80e0ef1166ba0ee81d4d594214", "price_changes": [{"asset_id": "4153292802911610701832309484716814274802943278345248636922528170020319407796", "price": "0.87", "size": "52.47", "side": "BUY", "hash": "ee5299fef880ccaa13bbb1bb5e7c7385c89f8e38", "best_bid": "0.936", "best_ask": "0.988"}, {"asset_id": "101676997363687199724245607342877036148401850938023978421879460310389391082353", "price": "0.13", "size": "52.47", "side": "SELL", "hash": "dff82f7c8ad54efc0270b9158bcb09d07c54d3d1", "best_bid": "0.012", "best_ask": "0.064"}], "timestamp": "1769384012172", "event_type": "price_change"}}
{"_local_timestamp": "2026-01-25T23:33:32.287512+00:00", "data": {"market": "0xaf9d0e448129a9f657f851d49495ba4742055d80e0ef1166ba0ee81d4d594214", "price_changes": [{"asset_id": "4153292802911610701832309484716814274802943278345248636922528170020319407796", "price": "0.871", "size": "20", "side": "BUY", "hash": "a500f096b5b333f4a7ea1c9a78e38152e649afea", "best_bid": "0.936", "best_ask": "0.988"}, {"asset_id": "101676997363687199724245607342877036148401850938023978421879460310389391082353", "price": "0.129", "size": "20", "side": "SELL", "hash": "2ba6876ee61cee3fc48b775efa42fd20591e26b5", "best_bid": "0.012", "best_ask": "0.064"}], "timestamp": "1769384012203", "event_type": "price_change"}}
{"_local_timestamp": "2026-01-25T23:33:32.288523+00:00", "data": {"market": "0x49686d26fb712515cd5e12c23f0a1c7e10214c7faa3cb0a730aabe0c33694082", "price_changes": [{"asset_id": "30442780799048074404860985387051749017905070253466005720364298335239299761065", "price": "0.016", "size": "27.01", "side": "BUY", "hash": "4dd496b63efb963f6c5d5888d583cc0353aee258", "best_bid": "0.104", "best_ask": "0.133"}, {"asset_id": "13244681086321087932946246027856416106585284024824496763706748621681543444582", "price": "0.984", "size": "27.01", "side": "SELL", "hash": "e7ac355a7f0fb1971bacf0bd3eb2655f037080a8", "best_bid": "0.867", "best_ask": "0.896"}], "timestamp": "1769384012204", "event_type": "price_change"}}
{"_local_timestamp": "2026-01-25T23:33:32.290533+00:00", "data": {"market": "0x50c669f178da4e5bbea7f1be25041fd278914712fa87a6a6f8e57d5923d88dee", "price_changes": [{"asset_id": "74040420326294854165772767082819937451857852955603897473157746262672057685461", "price": "0.881", "size": "40", "side": "BUY", "hash": "737fefb30e1cdda3b6fe964ad81a24a582ce8ecf", "best_bid": "0.995", "best_ask": "0.998"}, {"asset_id": "24682525479474221428144937281315825971983904267399062415430320764754931667953", "price": "0.119", "size": "40", "side": "SELL", "hash": "35c7ab874f6a932100ee829b42f55e5c35aa4ce3", "best_bid": "0.002", "best_ask": "0.005"}], "timestamp": "1769384012204", "event_type": "price_change"}}
{"_local_timestamp": "2026-01-25T23:33:32.299346+00:00", "data": {"market": "0xb9bbdd34304344dcc45803780a34c97d73a00133a5ecf70f63e1008b8abb2fca", "price_changes": [{"asset_id": "8682484153073832526711485265636767086525069344085206423986003504588877767339", "price": "0.88", "size": "20", "side": "BUY", "hash": "87b5f069194bdedcc42735bd5bdc91a707eaf407", "best_bid": "0.991", "best_ask": "0.996"}, {"asset_id": "72012724360700510767037780555710363830014634797787940282136454146828040926557", "price": "0.12", "size": "20", "side": "SELL", "hash": "42b0e1c3c5b8e065537f21505218b34cf9be54ca", "best_bid": "0.004", "best_ask": "0.009"}], "timestamp": "1769384012204", "event_type": "price_change"}}
{"_local_timestamp": "2026-01-25T23:33:32.622215+00:00", "data": {"market": "0x2393ed0b0fdc450054c7b9071907eca75cf4fc36e385adf4a0a5f99ee62243e8", "price_changes": [{"asset_id": "32769749367306925959219403371425714180265458150646381231272229429098460625924", "price": "0.916", "size": "37.81", "side": "BUY", "hash": "16c7899cda5536ab9e52cd215e870803b4abc8b3", "best_bid": "0.918", "best_ask": "0.959"}, {"asset_id": "100074770378634056601572485653252702850363676459996771990439989989293515601975", "price": "0.084", "size": "37.81", "side": "SELL", "hash": "e0e560d9f7ad076e4078b384cf28d1faaa260dff", "best_bid": "0.041", "best_ask": "0.082"}], "timestamp": "1769384012557", "event_type": "price_change"}}
{"_local_timestamp": "2026-01-25T23:33:32.649167+00:00", "data": {"market": "0x2393ed0b0fdc450054c7b9071907eca75cf4fc36e385adf4a0a5f99ee62243e8", "price_changes": [{"asset_id": "100074770378634056601572485653252702850363676459996771990439989989293515601975", "price": "0.087", "size": "0", "side": "SELL", "hash": "3bf313f8606ddaea9333f89a7b37a135a4b29bcd", "best_bid": "0.041", "best_ask": "0.082"}, {"asset_id": "32769749367306925959219403371425714180265458150646381231272229429098460625924", "price": "0.913", "size": "0", "side": "BUY", "hash": "9999098188d9e7232ea427c37865f5baf3198430", "best_bid": "0.918", "best_ask": "0.959"}], "timestamp": "1769384012581", "event_type": "price_change"}}
{"_local_timestamp": "2026-01-25T23:33:32.857387+00:00", "data": {"market": "0xaf9d0e448129a9f657f851d49495ba4742055d80e0ef1166ba0ee81d4d594214", "price_changes": [{"asset_id": "101676997363687199724245607342877036148401850938023978421879460310389391082353", "price": "0.002", "size": "11611", "side": "BUY", "hash": "d20fce7e69b71a3736e245ed316f7b3fbfb8a4a6", "best_bid": "0.012", "best_ask": "0.064"}, {"asset_id": "4153292802911610701832309484716814274802943278345248636922528170020319407796", "price": "0.998", "size": "11611", "side": "SELL", "hash": "013ac5d7fc844e493e94e21bea40cc00fcc3b7da", "best_bid": "0.936", "best_ask": "0.988"}], "timestamp": "1769384012787", "event_type": "price_change"}}
{"_local_timestamp": "2026-01-25T23:33:32.858746+00:00", "data": {"market": "0xaf9d0e448129a9f657f851d49495ba4742055d80e0ef1166ba0ee81d4d594214", "price_changes": [{"asset_id": "101676997363687199724245607342877036148401850938023978421879460310389391082353", "price": "0.003", "size": "1012.12", "side": "BUY", "hash": "d20fce7e69b71a3736e245ed316f7b3fbfb8a4a6", "best_bid": "0.012", "best_ask": "0.064"}, {"asset_id": "4153292802911610701832309484716814274802943278345248636922528170020319407796", "price": "0.997", "size": "1012.12", "side": "SELL", "hash": "013ac5d7fc844e493e94e21bea40cc00fcc3b7da", "best_bid": "0.936", "best_ask": "0.988"}], "timestamp": "1769384012787", "event_type": "price_change"}}
{"_local_timestamp": "2026-01-25T23:33:33.006492+00:00", "data": {"market": "0x2393ed0b0fdc450054c7b9071907eca75cf4fc36e385adf4a0a5f99ee62243e8", "price_changes": [{"asset_id": "32769749367306925959219403371425714180265458150646381231272229429098460625924", "price": "0.965", "size": "112.19", "side": "SELL", "hash": "ad2c650451a6d21a6b4f1dcbe5bbca1203eedaed", "best_bid": "0.918", "best_ask": "0.959"}, {"asset_id": "100074770378634056601572485653252702850363676459996771990439989989293515601975", "price": "0.035", "size": "112.19", "side": "BUY", "hash": "6ff963b1056d03b99bdd7d6b1f15577478792808", "best_bid": "0.041", "best_ask": "0.082"}], "timestamp": "1769384012909", "event_type": "price_change"}}
{"_local_timestamp": "2026-01-25T23:33:33.049717+00:00", "data": {"market": "0x2393ed0b0fdc450054c7b9071907eca75cf4fc36e385adf4a0a5f99ee62243e8", "price_changes": [{"asset_id": "100074770378634056601572485653252702850363676459996771990439989989293515601975", "price": "0.041", "size": "0", "side": "BUY", "hash": "db0cb83757ef7d69612280cf61f8f2085868ae6a", "best_bid": "0.04", "best_ask": "0.082"}, {"asset_id": "32769749367306925959219403371425714180265458150646381231272229429098460625924", "price": "0.959", "size": "0", "side": "SELL", "hash": "cde4db3dab139bd78e49d82242b1c7fbbcad12e7", "best_bid": "0.918", "best_ask": "0.96"}], "timestamp": "1769384012969", "event_type": "price_change"}}
{"_local_timestamp": "2026-01-25T23:33:33.337836+00:00", "data": {"market": "0x2393ed0b0fdc450054c7b9071907eca75cf4fc36e385adf4a0a5f99ee62243e8", "price_changes": [{"asset_id": "32769749367306925959219403371425714180265458150646381231272229429098460625924", "price": "0.914", "size": "0", "side": "BUY", "hash": "a8ddddaa502e052c9b423656f95805010398158b", "best_bid": "0.918", "best_ask": "0.96"}, {"asset_id": "100074770378634056601572485653252702850363676459996771990439989989293515601975", "price": "0.086", "size": "0", "side": "SELL", "hash": "7f62f8ae020a3019f8af085c01e45f6fb45478bc", "best_bid": "0.04", "best_ask": "0.082"}], "timestamp": "1769384013151", "event_type": "price_change"}}
{"_local_timestamp": "2026-01-25T23:33:33.427960+00:00", "data": {"market": "0xaf9d0e448129a9f657f851d49495ba4742055d80e0ef1166ba0ee81d4d594214", "price_changes": [{"asset_id": "101676997363687199724245607342877036148401850938023978421879460310389391082353", "price": "0.003", "size": "1030.11", "side": "BUY", "hash": "66cb8427f59f5fc8df4a7bdc203a49ea52277910", "best_bid": "0.012", "best_ask": "0.064"}, {"asset_id": "4153292802911610701832309484716814274802943278345248636922528170020319407796", "price": "0.997", "size": "1030.11", "side": "SELL", "hash": "d1b2d34bbe98536e9c49d53b1277a1af47cbaa46", "best_bid": "0.936", "best_ask": "0.988"}], "timestamp": "1769384013213", "event_type": "price_change"}}
{"_local_timestamp": "2026-01-25T23:33:33.430009+00:00", "data": {"market": "0xaf9d0e448129a9f657f851d49495ba4742055d80e0ef1166ba0ee81d4d594214", "price_changes": [{"asset_id": "101676997363687199724245607342877036148401850938023978421879460310389391082353", "price": "0.002", "size": "11638.12", "side": "BUY", "hash": "695eec0cc0152de61048b4494a0f0194e1fe195c", "best_bid": "0.012", "best_ask": "0.064"}, {"asset_id": "4153292802911610701832309484716814274802943278345248636922528170020319407796", "price": "0.998", "size": "11638.12", "side": "SELL", "hash": "8b4c69aa5a425794e748ded6491936d90aba3feb", "best_bid": "0.936", "best_ask": "0.988"}], "timestamp": "1769384013214", "event_type": "price_change"}}
{"_local_timestamp": "2026-01-25T23:33:33.460326+00:00", "data": {"market": "0x2393ed0b0fdc450054c7b9071907eca75cf4fc36e385adf4a0a5f99ee62243e8", "price_changes": [{"asset_id": "100074770378634056601572485653252702850363676459996771990439989989293515601975", "price": "0.104", "size": "197", "side": "SELL", "hash": "7e53ac261c1c604ea1825858c3f5e15271bd749f", "best_bid": "0.04", "best_ask": "0.082"}, {"asset_id": "32769749367306925959219403371425714180265458150646381231272229429098460625924", "price": "0.896", "size": "197", "side": "BUY", "hash": "4982f22bedd3e4e268aa166a9d88fcf2c788215e", "best_bid": "0.918", "best_ask": "0.96"}], "timestamp": "1769384013296", "event_type": "price_change"}}
{"_local_timestamp": "2026-01-25T23:33:33.461182+00:00", "data": {"market": "0x2393ed0b0fdc450054c7b9071907eca75cf4fc36e385adf4a0a5f99ee62243e8", "price_changes": [{"asset_id": "100074770378634056601572485653252702850363676459996771990439989989293515601975", "price": "0.036", "size": "29", "side": "BUY", "hash": "ff85fde3c4094f91f34c8e88c9f9225cd5e28550", "best_bid": "0.04", "best_ask": "0.082"}, {"asset_id": "32769749367306925959219403371425714180265458150646381231272229429098460625924", "price": "0.964", "size": "29", "side": "SELL", "hash": "05d898ae2ceacc141c607af34a9f19ba02c4e239", "best_bid": "0.918", "best_ask": "0.96"}], "timestamp": "1769384013297", "event_type": "price_change"}}
{"_local_timestamp": "2026-01-25T23:33:33.518906+00:00", "data": {"market": "0xb9bbdd34304344dcc45803780a34c97d73a00133a5ecf70f63e1008b8abb2fca", "price_changes": [{"asset_id": "8682484153073832526711485265636767086525069344085206423986003504588877767339", "price": "0.88", "size": "0", "side": "BUY", "hash": "2980a01050ebe662f30eebe48c9692c105fdfbe2", "best_bid": "0.991", "best_ask": "0.996"}, {"asset_id": "72012724360700510767037780555710363830014634797787940282136454146828040926557", "price": "0.12", "size": "0", "side": "SELL", "hash": "7f29652ef4e0efd382cc7e348e020bcea36e8dcc", "best_bid": "0.004", "best_ask": "0.009"}], "timestamp": "1769384013392", "event_type": "price_change"}}
{"_local_timestamp": "2026-01-25T23:33:33.520028+00:00", "data": {"market": "0x50c669f178da4e5bbea7f1be25041fd278914712fa87a6a6f8e57d5923d88dee", "price_changes": [{"asset_id": "74040420326294854165772767082819937451857852955603897473157746262672057685461", "price": "0.881", "size": "20", "side": "BUY", "hash": "155bdce11f27e81dd33c53bde230c5ec98b1ab5c", "best_bid": "0.995", "best_ask": "0.998"}, {"asset_id": "24682525479474221428144937281315825971983904267399062415430320764754931667953", "price": "0.119", "size": "20", "side": "SELL", "hash": "1e5f20614375fc2eb23221441101eb28bbec35ba", "best_bid": "0.002", "best_ask": "0.005"}], "timestamp": "1769384013392", "event_type": "price_change"}}
{"_local_timestamp": "2026-01-25T23:33:33.520655+00:00", "data": {"market": "0x49686d26fb712515cd5e12c23f0a1c7e10214c7faa3cb0a730aabe0c33694082", "price_changes": [{"asset_id": "30442780799048074404860985387051749017905070253466005720364298335239299761065", "price": "0.016", "size": "7.01", "side": "BUY", "hash": "eacc573ccf22dd0c45eec716167dbd1f1b5e663c", "best_bid": "0.104", "best_ask": "0.133"}, {"asset_id": "13244681086321087932946246027856416106585284024824496763706748621681543444582", "price": "0.984", "size": "7.01", "side": "SELL", "hash": "51cdd2d6f2ab65742e12c530240ef9f4682fa3f9", "best_bid": "0.867", "best_ask": "0.896"}], "timestamp": "1769384013392", "event_type": "price_change"}}
{"_local_timestamp": "2026-01-25T23:33:33.521233+00:00", "data": {"market": "0xaf9d0e448129a9f657f851d49495ba4742055d80e0ef1166ba0ee81d4d594214", "price_changes": [{"asset_id": "4153292802911610701832309484716814274802943278345248636922528170020319407796", "price": "0.871", "size": "0", "side": "BUY", "hash": "38fdbfd2d8ce3a60bf07fa03ad33f88c002f28c8", "best_bid": "0.936", "best_ask": "0.988"}, {"asset_id": "101676997363687199724245607342877036148401850938023978421879460310389391082353", "price": "0.129", "size": "0", "side": "SELL", "hash": "11d9dee676ac796dcca12191d7cac2b05453b64e", "best_bid": "0.012", "best_ask": "0.064"}], "timestamp": "1769384013392", "event_type": "price_change"}}
{"_local_timestamp": "2026-01-25T23:33:33.534553+00:00", "data": {"market": "0xaf9d0e448129a9f657f851d49495ba4742055d80e0ef1166ba0ee81d4d594214", "price_changes": [{"asset_id": "4153292802911610701832309484716814274802943278345248636922528170020319407796", "price": "0.87", "size": "72.47", "side": "BUY", "hash": "45116988916006872dbb120326652f3cf1518137", "best_bid": "0.936", "best_ask": "0.988"}, {"asset_id": "101676997363687199724245607342877036148401850938023978421879460310389391082353", "price": "0.13", "size": "72.47", "side": "SELL", "hash": "6485a3a02c851b7c62ee412a788a83dea4d7bb8f", "best_bid": "0.012", "best_ask": "0.064"}], "timestamp": "1769384013422", "event_type": "price_change"}}
{"_local_timestamp": "2026-01-25T23:33:33.535282+00:00", "data": {"market": "0xb9bbdd34304344dcc45803780a34c97d73a00133a5ecf70f63e1008b8abb2fca", "price_changes": [{"asset_id": "8682484153073832526711485265636767086525069344085206423986003504588877767339", "price": "0.871", "size": "20", "side": "BUY", "hash": "e755ccf6b0a9882fd1d4cc51267c0ddb23c0969e", "best_bid": "0.991", "best_ask": "0.996"}, {"asset_id": "72012724360700510767037780555710363830014634797787940282136454146828040926557", "price": "0.129", "size": "20", "side": "SELL", "hash": "0178010295e23f5f4d9c2ff6c27750f17fd699d0", "best_bid": "0.004", "best_ask": "0.009"}], "timestamp": "1769384013422", "event_type": "price_change"}}
{"_local_timestamp": "2026-01-25T23:33:33.535904+00:00", "data": {"market": "0x50c669f178da4e5bbea7f1be25041fd278914712fa87a6a6f8e57d5923d88dee", "price_changes": [{"asset_id": "74040420326294854165772767082819937451857852955603897473157746262672057685461", "price": "0.879", "size": "20", "side": "BUY", "hash": "03bb5c38ec2b7224d6565aaf4295e85e0470dde2", "best_bid": "0.995", "best_ask": "0.998"}, {"asset_id": "24682525479474221428144937281315825971983904267399062415430320764754931667953", "price": "0.121", "size": "20", "side": "SELL", "hash": "1132c5df49d2a4eb1501ce00a31ba75752d0c639", "best_bid": "0.002", "best_ask": "0.005"}], "timestamp": "1769384013422", "event_type": "price_change"}}
{"_local_timestamp": "2026-01-25T23:33:33.551092+00:00", "data": {"market": "0x49686d26fb712515cd5e12c23f0a1c7e10214c7faa3cb0a730aabe0c33694082", "price_changes": [{"asset_id": "30442780799048074404860985387051749017905070253466005720364298335239299761065", "price": "0.015", "size": "131", "side": "BUY", "hash": "85d200353799afa78dace400248f731ba94b75fc", "best_bid": "0.104", "best_ask": "0.133"}, {"asset_id": "13244681086321087932946246027856416106585284024824496763706748621681543444582", "price": "0.985", "size": "131", "side": "SELL", "hash": "ffb1b3ab66892d2b881d419560e52c18113e2b58", "best_bid": "0.867", "best_ask": "0.896"}], "timestamp": "1769384013422", "event_type": "price_change"}}
{"_local_timestamp": "2026-01-25T23:33:34.193181+00:00", "data": {"market": "0x2393ed0b0fdc450054c7b9071907eca75cf4fc36e385adf4a0a5f99ee62243e8", "price_changes": [{"asset_id": "32769749367306925959219403371425714180265458150646381231272229429098460625924", "price": "0.965", "size": "0", "side": "SELL", "hash": "bfc91da496a1266e418c27f4a8af3cfcad41516f", "best_bid": "0.918", "best_ask": "0.96"}, {"asset_id": "100074770378634056601572485653252702850363676459996771990439989989293515601975", "price": "0.035", "size": "0", "side": "BUY", "hash": "306035703bd6f1dce0b6915d6fe29e35abc13ff0", "best_bid": "0.04", "best_ask": "0.082"}], "timestamp": "1769384014123", "event_type": "price_change"}}
{"_local_timestamp": "2026-01-25T23:33:34.462708+00:00", "data": {"market": "0xaf9d0e448129a9f657f851d49495ba4742055d80e0ef1166ba0ee81d4d594214", "price_changes": [{"asset_id": "4153292802911610701832309484716814274802943278345248636922528170020319407796", "price": "0.873", "size": "0", "side": "BUY", "hash": "c94e3bc8ab4562f753b826a37080a4b10ccd2b96", "best_bid": "0.936", "best_ask": "0.988"}, {"asset_id": "101676997363687199724245607342877036148401850938023978421879460310389391082353", "price": "0.127", "size": "0", "side": "SELL", "hash": "ce9cab61884ec44b512d620cb4f734f24ca3acbe", "best_bid": "0.012", "best_ask": "0.064"}], "timestamp": "1769384014398", "event_type": "price_change"}}
{"_local_timestamp": "2026-01-25T23:33:34.891080+00:00", "data": {"market": "0x2393ed0b0fdc450054c7b9071907eca75cf4fc36e385adf4a0a5f99ee62243e8", "price_changes": [{"asset_id": "100074770378634056601572485653252702850363676459996771990439989989293515601975", "price": "0.036", "size": "0", "side": "BUY", "hash": "fc1dfa7520ccf8cd4452be6035f47eff3d4a76df", "best_bid": "0.04", "best_ask": "0.082"}, {"asset_id": "32769749367306925959219403371425714180265458150646381231272229429098460625924", "price": "0.964", "size": "0", "side": "SELL", "hash": "007539ad07f613494a8212be672f129636121b0d", "best_bid": "0.918", "best_ask": "0.96"}], "timestamp": "1769384014819", "event_type": "price_change"}}
{"_local_timestamp": "2026-01-25T23:33:34.926821+00:00", "data": {"market": "0x2393ed0b0fdc450054c7b9071907eca75cf4fc36e385adf4a0a5f99ee62243e8", "price_changes": [{"asset_id": "100074770378634056601572485653252702850363676459996771990439989989293515601975", "price": "0.028", "size": "215.4", "side": "BUY", "hash": "9331f1f1319afac6dda8bb24a278bbf27ad00c93", "best_bid": "0.04", "best_ask": "0.082"}, {"asset_id": "32769749367306925959219403371425714180265458150646381231272229429098460625924", "price": "0.972", "size": "215.4", "side": "SELL", "hash": "d0400e233a3bd18095dbfc9447c6bfc24dde19c9", "best_bid": "0.918", "best_ask": "0.96"}], "timestamp": "1769384014847", "event_type": "price_change"}}
{"_local_timestamp": "2026-01-25T23:33:35.337547+00:00", "data": {"market": "0x2393ed0b0fdc450054c7b9071907eca75cf4fc36e385adf4a0a5f99ee62243e8", "price_changes": [{"asset_id": "32769749367306925959219403371425714180265458150646381231272229429098460625924", "price": "0.966", "size": "112.19", "side": "SELL", "hash": "54805d552e71fb1830ef6a6c399bfda44f314531", "best_bid": "0.918", "best_ask": "0.96"}, {"asset_id": "100074770378634056601572485653252702850363676459996771990439989989293515601975", "price": "0.034", "size": "112.19", "side": "BUY", "hash": "5f00913d2fab8fefca3567d60e70bfda000b7855", "best_bid": "0.04", "best_ask": "0.082"}], "timestamp": "1769384015268", "event_type": "price_change"}}
{"_local_timestamp": "2026-01-25T23:33:35.803171+00:00", "data": {"market": "0x2393ed0b0fdc450054c7b9071907eca75cf4fc36e385adf4a0a5f99ee62243e8", "price_changes": [{"asset_id": "32769749367306925959219403371425714180265458150646381231272229429098460625924", "price": "0.917", "size": "50", "side": "BUY", "hash": "5bbddfc6249b4d5a66b28dc9c667c37b6903f338", "best_bid": "0.918", "best_ask": "0.96"}, {"asset_id": "100074770378634056601572485653252702850363676459996771990439989989293515601975", "price": "0.083", "size": "50", "side": "SELL", "hash": "cc584123781939575a133c9ff2efb5a8783ef731", "best_bid": "0.04", "best_ask": "0.082"}], "timestamp": "1769384015737", "event_type": "price_change"}}
{"_local_timestamp": "2026-01-25T23:33:35.823837+00:00", "data": {"market": "0x2393ed0b0fdc450054c7b9071907eca75cf4fc36e385adf4a0a5f99ee62243e8", "price_changes": [{"asset_id": "100074770378634056601572485653252702850363676459996771990439989989293515601975", "price": "0.104", "size": "0", "side": "SELL", "hash": "26455780c83aa14f16a0d04950245e549308eec6", "best_bid": "0.04", "best_ask": "0.082"}, {"asset_id": "32769749367306925959219403371425714180265458150646381231272229429098460625924", "price": "0.896", "size": "0", "side": "BUY", "hash": "1795f30e2b731f6d3420be8e1024bb32577f53cd", "best_bid": "0.918", "best_ask": "0.96"}], "timestamp": "1769384015760", "event_type": "price_change"}}
{"_local_timestamp": "2026-01-25T23:33:35.841137+00:00", "data": {"market": "0x2393ed0b0fdc450054c7b9071907eca75cf4fc36e385adf4a0a5f99ee62243e8", "price_changes": [{"asset_id": "32769749367306925959219403371425714180265458150646381231272229429098460625924", "price": "0.897", "size": "30", "side": "BUY", "hash": "81f841417585fcef5db1f2e41d2cdf66134b657d", "best_bid": "0.918", "best_ask": "0.96"}, {"asset_id": "100074770378634056601572485653252702850363676459996771990439989989293515601975", "price": "0.103", "size": "30", "side": "SELL", "hash": "f35c4301cef56fbb5ced67fb4c567f38c4def770", "best_bid": "0.04", "best_ask": "0.082"}], "timestamp": "1769384015771", "event_type": "price_change"}}
{"_local_timestamp": "2026-01-25T23:33:36.161487+00:00", "data": {"market": "0x2393ed0b0fdc450054c7b9071907eca75cf4fc36e385adf4a0a5f99ee62243e8", "price_changes": [{"asset_id": "32769749367306925959219403371425714180265458150646381231272229429098460625924", "price": "0.915", "size": "0", "side": "BUY", "hash": "267a8cfd396960dfa663f815ea69c195ffbfd6ff", "best_bid": "0.918", "best_ask": "0.96"}, {"asset_id": "100074770378634056601572485653252702850363676459996771990439989989293515601975", "price": "0.085", "size": "0", "side": "SELL", "hash": "a42dc6ded0f1454d1ffa2446c336cf90fd669223", "best_bid": "0.04", "best_ask": "0.082"}], "timestamp": "1769384016069", "event_type": "price_change"}}
{"_local_timestamp": "2026-01-25T23:33:36.179946+00:00", "data": {"market": "0x2393ed0b0fdc450054c7b9071907eca75cf4fc36e385adf4a0a5f99ee62243e8", "price_changes": [{"asset_id": "100074770378634056601572485653252702850363676459996771990439989989293515601975", "price": "0.028", "size": "9.4", "side": "BUY", "hash": "5b34477d7c500f4e1e91665fc7dde39030f244ac", "best_bid": "0.04", "best_ask": "0.082"}, {"asset_id": "32769749367306925959219403371425714180265458150646381231272229429098460625924", "price": "0.972", "size": "9.4", "side": "SELL", "hash": "6dde0ce2fd3b849d06a6cb2082e8196950bc9ea5", "best_bid": "0.918", "best_ask": "0.96"}], "timestamp": "1769384016112", "event_type": "price_change"}}
{"_local_timestamp": "2026-01-25T23:33:36.180827+00:00", "data": {"market": "0x2393ed0b0fdc450054c7b9071907eca75cf4fc36e385adf4a0a5f99ee62243e8", "price_changes": [{"asset_id": "100074770378634056601572485653252702850363676459996771990439989989293515601975", "price": "0.102", "size": "191", "side": "SELL", "hash": "d523de130ac7bd95d9c1b50df75aee9060af0b1e", "best_bid": "0.04", "best_ask": "0.082"}, {"asset_id": "32769749367306925959219403371425714180265458150646381231272229429098460625924", "price": "0.898", "size": "191", "side": "BUY", "hash": "d1239cf01bea06c7632822b5bd41c73164c24a25", "best_bid": "0.918", "best_ask": "0.96"}], "timestamp": "1769384016114", "event_type": "price_change"}}
{"_local_timestamp": "2026-01-25T23:33:36.323571+00:00", "data": {"market": "0xaf9d0e448129a9f657f851d49495ba4742055d80e0ef1166ba0ee81d4d594214", "price_changes": [{"asset_id": "4153292802911610701832309484716814274802943278345248636922528170020319407796", "price": "0.787", "size": "0", "side": "BUY", "hash": "e372415e4487ee8b6cb7ae9e5ae838ad0a8e6cb2", "best_bid": "0.936", "best_ask": "0.988"}, {"asset_id": "101676997363687199724245607342877036148401850938023978421879460310389391082353", "price": "0.213", "size": "0", "side": "SELL", "hash": "f4b0b5ef97e4d3124ae64b141ada4b5b1473c0e8", "best_bid": "0.012", "best_ask": "0.064"}], "timestamp": "1769384016254", "event_type": "price_change"}}
{"_local_timestamp": "2026-01-25T23:33:36.392720+00:00", "data": {"market": "0xaf9d0e448129a9f657f851d49495ba4742055d80e0ef1166ba0ee81d4d594214", "price_changes": [{"asset_id": "4153292802911610701832309484716814274802943278345248636922528170020319407796", "price": "0.888", "size": "30", "side": "BUY", "hash": "90b44e80566e06c4f3d4dcb75b1d57030b1bc50c", "best_bid": "0.936", "best_ask": "0.988"}, {"asset_id": "101676997363687199724245607342877036148401850938023978421879460310389391082353", "price": "0.112", "size": "30", "side": "SELL", "hash": "81d8b166bccbad3e18cb404f826c1bc13b4380db", "best_bid": "0.012", "best_ask": "0.064"}], "timestamp": "1769384016327", "event_type": "price_change"}}
{"_local_timestamp": "2026-01-25T23:33:37.230182+00:00", "data": {"market": "0x2393ed0b0fdc450054c7b9071907eca75cf4fc36e385adf4a0a5f99ee62243e8", "price_changes": [{"asset_id": "32769749367306925959219403371425714180265458150646381231272229429098460625924", "price": "0.916", "size": "0", "side": "BUY", "hash": "aefd017f5a9a602250fe8daf5c06247f823b86e0", "best_bid": "0.918", "best_ask": "0.96"}, {"asset_id": "100074770378634056601572485653252702850363676459996771990439989989293515601975", "price": "0.084", "size": "0", "side": "SELL", "hash": "e17b565b98ab9411f6530575d84c89c3709ecd32", "best_bid": "0.04", "best_ask": "0.082"}], "timestamp": "1769384017166", "event_type": "price_change"}}
{"_local_timestamp": "2026-01-25T23:33:37.298947+00:00", "data": {"market": "0x2393ed0b0fdc450054c7b9071907eca75cf4fc36e385adf4a0a5f99ee62243e8", "price_changes": [{"asset_id": "100074770378634056601572485653252702850363676459996771990439989989293515601975", "price": "0.035", "size": "161", "side": "BUY", "hash": "bcd4a24e6932420baea793ee34ec44720a5dd515", "best_bid": "0.04", "best_ask": "0.082"}, {"asset_id": "32769749367306925959219403371425714180265458150646381231272229429098460625924", "price": "0.965", "size": "161", "side": "SELL", "hash": "629f29e9f951e69093f7989082acfdefa1df1001", "best_bid": "0.918", "best_ask": "0.96"}], "timestamp": "1769384017196", "event_type": "price_change"}}
{"_local_timestamp": "2026-01-25T23:33:38.518594+00:00", "data": {"market": "0x2393ed0b0fdc450054c7b9071907eca75cf4fc36e385adf4a0a5f99ee62243e8", "price_changes": [{"asset_id": "32769749367306925959219403371425714180265458150646381231272229429098460625924", "price": "0.897", "size": "0", "side": "BUY", "hash": "413f27741403012b4a7578888464c847090f35a9", "best_bid": "0.918", "best_ask": "0.96"}, {"asset_id": "100074770378634056601572485653252702850363676459996771990439989989293515601975", "price": "0.103", "size": "0", "side": "SELL", "hash": "148238f418d3b7822e4c0ea58b2b2b5312906551", "best_bid": "0.04", "best_ask": "0.082"}], "timestamp": "1769384018452", "event_type": "price_change"}}
{"_local_timestamp": "2026-01-25T23:33:38.542279+00:00", "data": {"market": "0x2393ed0b0fdc450054c7b9071907eca75cf4fc36e385adf4a0a5f99ee62243e8", "price_changes": [{"asset_id": "100074770378634056601572485653252702850363676459996771990439989989293515601975", "price": "0.035", "size": "0", "side": "BUY", "hash": "99771cf8c60692d542e473691e501ea065b12108", "best_bid": "0.04", "best_ask": "0.082"}, {"asset_id": "32769749367306925959219403371425714180265458150646381231272229429098460625924", "price": "0.965", "size": "0", "side": "SELL", "hash": "9553e5ad799639a360339cee9eac2b131dffb0c3", "best_bid": "0.918", "best_ask": "0.96"}], "timestamp": "1769384018476", "event_type": "price_change"}}
{"_local_timestamp": "2026-01-25T23:33:38.581291+00:00", "data": {"market": "0x2393ed0b0fdc450054c7b9071907eca75cf4fc36e385adf4a0a5f99ee62243e8", "price_changes": [{"asset_id": "100074770378634056601572485653252702850363676459996771990439989989293515601975", "price": "0.04", "size": "191", "side": "BUY", "hash": "53813f4ecb6754212343a2ee643435eee06354f9", "best_bid": "0.04", "best_ask": "0.082"}, {"asset_id": "32769749367306925959219403371425714180265458150646381231272229429098460625924", "price": "0.96", "size": "191", "side": "SELL", "hash": "1bc5ade58eeefc820da55257ccca2b34541c6695", "best_bid": "0.918", "best_ask": "0.96"}], "timestamp": "1769384018509", "event_type": "price_change"}}
{"_local_timestamp": "2026-01-25T23:33:38.620052+00:00", "data": {"market": "0x2393ed0b0fdc450054c7b9071907eca75cf4fc36e385adf4a0a5f99ee62243e8", "price_changes": [{"asset_id": "32769749367306925959219403371425714180265458150646381231272229429098460625924", "price": "0.966", "size": "0", "side": "SELL", "hash": "6d9dc970c2e937074e45495e98c6e2b4e6a8ec60", "best_bid": "0.918", "best_ask": "0.96"}, {"asset_id": "100074770378634056601572485653252702850363676459996771990439989989293515601975", "price": "0.034", "size": "0", "side": "BUY", "hash": "8f2b6426afd491b2a7b4ddd3d72625f22baba000", "best_bid": "0.04", "best_ask": "0.082"}], "timestamp": "1769384018552", "event_type": "price_change"}}
{"_local_timestamp": "2026-01-25T23:33:38.640238+00:00", "data": {"market": "0x2393ed0b0fdc450054c7b9071907eca75cf4fc36e385adf4a0a5f99ee62243e8", "price_changes": [{"asset_id": "32769749367306925959219403371425714180265458150646381231272229429098460625924", "price": "0.899", "size": "30", "side": "BUY", "hash": "426874607113d9025d20739cbb76d50d652d71b2", "best_bid": "0.918", "best_ask": "0.96"}, {"asset_id": "100074770378634056601572485653252702850363676459996771990439989989293515601975", "price": "0.101", "size": "30", "side": "SELL", "hash": "a8dd6a6cd0d4dcda2c29780187c8f29cd1c541ec", "best_bid": "0.04", "best_ask": "0.082"}], "timestamp": "1769384018557", "event_type": "price_change"}}
{"_local_timestamp": "2026-01-25T23:33:38.653721+00:00", "data": {"market": "0x2393ed0b0fdc450054c7b9071907eca75cf4fc36e385adf4a0a5f99ee62243e8", "price_changes": [{"asset_id": "100074770378634056601572485653252702850363676459996771990439989989293515601975", "price": "0.102", "size": "0", "side": "SELL", "hash": "0e54923fa0b490bf4b43403b49abf00152b67ab7", "best_bid": "0.04", "best_ask": "0.082"}, {"asset_id": "32769749367306925959219403371425714180265458150646381231272229429098460625924", "price": "0.898", "size": "0", "side": "BUY", "hash": "db0c82f4db83ff5a3f7330df89e8aa038a5ddb3c", "best_bid": "0.918", "best_ask": "0.96"}], "timestamp": "1769384018584", "event_type": "price_change"}}
{"_local_timestamp": "2026-01-25T23:33:38.670750+00:00", "data": {"market": "0x2393ed0b0fdc450054c7b9071907eca75cf4fc36e385adf4a0a5f99ee62243e8", "price_changes": [{"asset_id": "100074770378634056601572485653252702850363676459996771990439989989293515601975", "price": "0.1", "size": "206", "side": "SELL", "hash": "f44ab6a21c94ef533e548f45bfba0a5b93d42f70", "best_bid": "0.04", "best_ask": "0.082"}, {"asset_id": "32769749367306925959219403371425714180265458150646381231272229429098460625924", "price": "0.9", "size": "206", "side": "BUY", "hash": "542e3c9afd73c2146e568890acc14018a90b1422", "best_bid": "0.918", "best_ask": "0.96"}], "timestamp": "1769384018608", "event_type": "price_change"}}
{"_local_timestamp": "2026-01-25T23:33:38.777968+00:00", "data": {"market": "0x2393ed0b0fdc450054c7b9071907eca75cf4fc36e385adf4a0a5f99ee62243e8", "price_changes": [{"asset_id": "32769749367306925959219403371425714180265458150646381231272229429098460625924", "price": "0.898", "size": "37.81", "side": "BUY", "hash": "cb324731d84e3384826e604d0f6bc97a63fd0d47", "best_bid": "0.918", "best_ask": "0.96"}, {"asset_id": "100074770378634056601572485653252702850363676459996771990439989989293515601975", "price": "0.102", "size": "37.81", "side": "SELL", "hash": "1d2a4b47ac6277ff79a63450667e536c0d2aacf7", "best_bid": "0.04", "best_ask": "0.082"}], "timestamp": "1769384018704", "event_type": "price_change"}}
{"_local_timestamp": "2026-01-25T23:33:39.876899+00:00", "data": {"market": "0x2393ed0b0fdc450054c7b9071907eca75cf4fc36e385adf4a0a5f99ee62243e8", "price_changes": [{"asset_id": "100074770378634056601572485653252702850363676459996771990439989989293515601975", "price": "0.04", "size": "60", "side": "BUY", "hash": "13a653d2fe51e432c516638c3d2d1005dc45427d", "best_bid": "0.04", "best_ask": "0.082"}, {"asset_id": "32769749367306925959219403371425714180265458150646381231272229429098460625924", "price": "0.96", "size": "60", "side": "SELL", "hash": "bd42079d4552b65c156b411d3b46947b6e2bc89d", "best_bid": "0.918", "best_ask": "0.96"}], "timestamp": "1769384019812", "event_type": "price_change"}}
{"_local_timestamp": "2026-01-25T23:33:39.919194+00:00", "data": {"market": "0x2393ed0b0fdc450054c7b9071907eca75cf4fc36e385adf4a0a5f99ee62243e8", "price_changes": [{"asset_id": "100074770378634056601572485653252702850363676459996771990439989989293515601975", "price": "0.028", "size": "20.4", "side": "BUY", "hash": "3f57b2442226c09bfd21aefa4c7c842cb0947f39", "best_bid": "0.04", "best_ask": "0.082"}, {"asset_id": "32769749367306925959219403371425714180265458150646381231272229429098460625924", "price": "0.972", "size": "20.4", "side": "SELL", "hash": "f9e5b97d413cdd6afa784840741ce84a106c9908", "best_bid": "0.918", "best_ask": "0.96"}], "timestamp": "1769384019842", "event_type": "price_change"}}
{"_local_timestamp": "2026-01-25T23:33:39.977288+00:00", "data": {"market": "0x2393ed0b0fdc450054c7b9071907eca75cf4fc36e385adf4a0a5f99ee62243e8", "price_changes": [{"asset_id": "32769749367306925959219403371425714180265458150646381231272229429098460625924", "price": "0.964", "size": "112.19", "side": "SELL", "hash": "e0759857803cac8f0cc19f762348ade1dc968b67", "best_bid": "0.918", "best_ask": "0.96"}, {"asset_id": "100074770378634056601572485653252702850363676459996771990439989989293515601975", "price": "0.036", "size": "112.19", "side": "BUY", "hash": "aafcc729f1dbffc51d9761623b95994beb2d4292", "best_bid": "0.04", "best_ask": "0.082"}], "timestamp": "1769384019914", "event_type": "price_change"}}
{"_local_timestamp": "2026-01-25T23:33:40.009499+00:00", "data": {"market": "0x2393ed0b0fdc450054c7b9071907eca75cf4fc36e385adf4a0a5f99ee62243e8", "price_changes": [{"asset_id": "32769749367306925959219403371425714180265458150646381231272229429098460625924", "price": "0.898", "size": "0", "side": "BUY", "hash": "7585d2ab520e7c5dafb0edfa6a368c11f45ba67d", "best_bid": "0.918", "best_ask": "0.96"}, {"asset_id": "100074770378634056601572485653252702850363676459996771990439989989293515601975", "price": "0.102", "size": "0", "side": "SELL", "hash": "db6740a946568b2c5633a4a5a4c43b2af4dce192", "best_bid": "0.04", "best_ask": "0.082"}], "timestamp": "1769384019943", "event_type": "price_change"}}
{"_local_timestamp": "2026-01-25T23:33:40.064109+00:00", "data": {"market": "0xaf9d0e448129a9f657f851d49495ba4742055d80e0ef1166ba0ee81d4d594214", "price_changes": [{"asset_id": "4153292802911610701832309484716814274802943278345248636922528170020319407796", "price": "0.888", "size": "0", "side": "BUY", "hash": "08f735876f0d023ea163668d6ec742e57d17545a", "best_bid": "0.936", "best_ask": "0.988"}, {"asset_id": "101676997363687199724245607342877036148401850938023978421879460310389391082353", "price": "0.112", "size": "0", "side": "SELL", "hash": "7044838cd26084cddc705a481d73ba8cf2edf351", "best_bid": "0.012", "best_ask": "0.064"}], "timestamp": "1769384019996", "event_type": "price_change"}}
{"_local_timestamp": "2026-01-25T23:33:40.160945+00:00", "data": {"market": "0xaf9d0e448129a9f657f851d49495ba4742055d80e0ef1166ba0ee81d4d594214", "price_changes": [{"asset_id": "4153292802911610701832309484716814274802943278345248636922528170020319407796", "price": "0.871", "size": "30", "side": "BUY", "hash": "692569c355c4c7913bf9812a239c7630ee4d22d4", "best_bid": "0.936", "best_ask": "0.988"}, {"asset_id": "101676997363687199724245607342877036148401850938023978421879460310389391082353", "price": "0.129", "size": "30", "side": "SELL", "hash": "2d17852042b419f074474043501375a191119f65", "best_bid": "0.012", "best_ask": "0.064"}], "timestamp": "1769384020078", "event_type": "price_change"}}
{"_local_timestamp": "2026-01-25T23:33:41.379857+00:00", "data": {"market": "0x2393ed0b0fdc450054c7b9071907eca75cf4fc36e385adf4a0a5f99ee62243e8", "price_changes": [{"asset_id": "100074770378634056601572485653252702850363676459996771990439989989293515601975", "price": "0.028", "size": "9.4", "side": "BUY", "hash": "32c4934df0b3d94f82bb99d7f59cc5427a6f84c9", "best_bid": "0.04", "best_ask": "0.082"}, {"asset_id": "32769749367306925959219403371425714180265458150646381231272229429098460625924", "price": "0.972", "size": "9.4", "side": "SELL", "hash": "ec7fcf962031e43e083b5f4a3d15b903fb9ee3dd", "best_bid": "0.918", "best_ask": "0.96"}], "timestamp": "1769384021314", "event_type": "price_change"}}
{"_local_timestamp": "2026-01-25T23:33:41.411544+00:00", "data": {"market": "0x2393ed0b0fdc450054c7b9071907eca75cf4fc36e385adf4a0a5f99ee62243e8", "price_changes": [{"asset_id": "100074770378634056601572485653252702850363676459996771990439989989293515601975", "price": "0.041", "size": "87", "side": "BUY", "hash": "e5b2eb3068226e700d461a740a4ba39d98c9feb9", "best_bid": "0.041", "best_ask": "0.082"}, {"asset_id": "32769749367306925959219403371425714180265458150646381231272229429098460625924", "price": "0.959", "size": "87", "side": "SELL", "hash": "b5d1cdacb155451a705313b366dc0791bd66a418", "best_bid": "0.918", "best_ask": "0.959"}], "timestamp": "1769384021346", "event_type": "price_change"}}
{"_local_timestamp": "2026-01-25T23:33:41.542656+00:00", "data": {"market": "0x2393ed0b0fdc450054c7b9071907eca75cf4fc36e385adf4a0a5f99ee62243e8", "price_changes": [{"asset_id": "32769749367306925959219403371425714180265458150646381231272229429098460625924", "price": "0.901", "size": "37.81", "side": "BUY", "hash": "bccd9156c3e1b6746167a8d16c825e7b7d1abf99", "best_bid": "0.918", "best_ask": "0.959"}, {"asset_id": "100074770378634056601572485653252702850363676459996771990439989989293515601975", "price": "0.099", "size": "37.81", "side": "SELL", "hash": "21e9d1c608871fe4d0e296dd0690419ad4115496", "best_bid": "0.041", "best_ask": "0.082"}], "timestamp": "1769384021473", "event_type": "price_change"}}
{"_local_timestamp": "2026-01-25T23:33:41.622838+00:00", "data": {"market": "0x2393ed0b0fdc450054c7b9071907eca75cf4fc36e385adf4a0a5f99ee62243e8", "price_changes": [{"asset_id": "32769749367306925959219403371425714180265458150646381231272229429098460625924", "price": "0.964", "size": "0", "side": "SELL", "hash": "d24e3f8d8dd979a90b2e2fbd5037fb25a11568be", "best_bid": "0.918", "best_ask": "0.959"}, {"asset_id": "100074770378634056601572485653252702850363676459996771990439989989293515601975", "price": "0.036", "size": "0", "side": "BUY", "hash": "59405946673a29fe170754970d5fa335a1fe9bb3", "best_bid": "0.041", "best_ask": "0.082"}], "timestamp": "1769384021480", "event_type": "price_change"}}
{"_local_timestamp": "2026-01-25T23:33:41.625912+00:00", "data": {"market": "0x2393ed0b0fdc450054c7b9071907eca75cf4fc36e385adf4a0a5f99ee62243e8", "price_changes": [{"asset_id": "100074770378634056601572485653252702850363676459996771990439989989293515601975", "price": "0.1", "size": "0", "side": "SELL", "hash": "29c574772a75e0c301d4e2cbd8da14dbe89948ff", "best_bid": "0.041", "best_ask": "0.082"}, {"asset_id": "32769749367306925959219403371425714180265458150646381231272229429098460625924", "price": "0.9", "size": "0", "side": "BUY", "hash": "9bb018bfb4596c9d9102f2e48e0aad2c3dd0e370", "best_bid": "0.918", "best_ask": "0.959"}], "timestamp": "1769384021502", "event_type": "price_change"}}
{"_local_timestamp": "2026-01-25T23:33:41.629594+00:00", "data": {"market": "0x2393ed0b0fdc450054c7b9071907eca75cf4fc36e385adf4a0a5f99ee62243e8", "price_changes": [{"asset_id": "100074770378634056601572485653252702850363676459996771990439989989293515601975", "price": "0.098", "size": "151", "side": "SELL", "hash": "3f29dca1cf2fbc09955dabe97f288e46e60c707b", "best_bid": "0.041", "best_ask": "0.082"}, {"asset_id": "32769749367306925959219403371425714180265458150646381231272229429098460625924", "price": "0.902", "size": "151", "side": "BUY", "hash": "ae69da9c901dcef2e2c3330480cc3d5d5773960d", "best_bid": "0.918", "best_ask": "0.959"}], "timestamp": "1769384021536", "event_type": "price_change"}}
{"_local_timestamp": "2026-01-25T23:33:41.821446+00:00", "data": {"market": "0x2393ed0b0fdc450054c7b9071907eca75cf4fc36e385adf4a0a5f99ee62243e8", "price_changes": [{"asset_id": "32769749367306925959219403371425714180265458150646381231272229429098460625924", "price": "0.901", "size": "87.81", "side": "BUY", "hash": "8ee400af01dfa28ab9d04eb53c30d1cd4d211c2b", "best_bid": "0.918", "best_ask": "0.959"}, {"asset_id": "100074770378634056601572485653252702850363676459996771990439989989293515601975", "price": "0.099", "size": "87.81", "side": "SELL", "hash": "c09be7cf6f45cfded65549f17e3a75121c62d603", "best_bid": "0.041", "best_ask": "0.082"}], "timestamp": "1769384021755", "event_type": "price_change"}}
{"_local_timestamp": "2026-01-25T23:33:42.183600+00:00", "data": {"market": "0x2393ed0b0fdc450054c7b9071907eca75cf4fc36e385adf4a0a5f99ee62243e8", "price_changes": [{"asset_id": "32769749367306925959219403371425714180265458150646381231272229429098460625924", "price": "0.917", "size": "0", "side": "BUY", "hash": "029741be2a35101d084e04cfdf94cf30c3b94b78", "best_bid": "0.918", "best_ask": "0.959"}, {"asset_id": "100074770378634056601572485653252702850363676459996771990439989989293515601975", "price": "0.083", "size": "0", "side": "SELL", "hash": "5e3381902e3b169a260bf63e0d812f4edb328110", "best_bid": "0.041", "best_ask": "0.082"}], "timestamp": "1769384022112", "event_type": "price_change"}}
{"_local_timestamp": "2026-01-25T23:33:43.082330+00:00", "data": {"market": "0x2393ed0b0fdc450054c7b9071907eca75cf4fc36e385adf4a0a5f99ee62243e8", "price_changes": [{"asset_id": "32769749367306925959219403371425714180265458150646381231272229429098460625924", "price": "0.901", "size": "50", "side": "BUY", "hash": "37ac1206e41ec691fd8e69e8fdca216a5e17ff70", "best_bid": "0.918", "best_ask": "0.959"}, {"asset_id": "100074770378634056601572485653252702850363676459996771990439989989293515601975", "price": "0.099", "size": "50", "side": "SELL", "hash": "94179d9a8b30ab2996d4fc7e8d3f0c108959dc37", "best_bid": "0.041", "best_ask": "0.082"}], "timestamp": "1769384023002", "event_type": "price_change"}}
{"_local_timestamp": "2026-01-25T23:33:43.109922+00:00", "data": {"market": "0x2393ed0b0fdc450054c7b9071907eca75cf4fc36e385adf4a0a5f99ee62243e8", "price_changes": [{"asset_id": "32769749367306925959219403371425714180265458150646381231272229429098460625924", "price": "0.966", "size": "112.19", "side": "SELL", "hash": "0da31d4dc8c366ad82d0d4052ad96e6894417c36", "best_bid": "0.918", "best_ask": "0.959"}, {"asset_id": "100074770378634056601572485653252702850363676459996771990439989989293515601975", "price": "0.034", "size": "112.19", "side": "BUY", "hash": "29569a759b92d3977d3f1af0085c6cf58d83df7f", "best_bid": "0.041", "best_ask": "0.082"}], "timestamp": "1769384023015", "event_type": "price_change"}}
{"_local_timestamp": "2026-01-25T23:33:43.137816+00:00", "data": {"market": "0x2393ed0b0fdc450054c7b9071907eca75cf4fc36e385adf4a0a5f99ee62243e8", "price_changes": [{"asset_id": "100074770378634056601572485653252702850363676459996771990439989989293515601975", "price": "0.041", "size": "0", "side": "BUY", "hash": "2aae8f1359e4fafcb260653dba04ef44ef7e4088", "best_bid": "0.04", "best_ask": "0.082"}, {"asset_id": "32769749367306925959219403371425714180265458150646381231272229429098460625924", "price": "0.959", "size": "0", "side": "SELL", "hash": "3c2ed4e91af29164ee62144ebb7dc8f1e4476e62", "best_bid": "0.918", "best_ask": "0.96"}], "timestamp": "1769384023072", "event_type": "price_change"}}
{"_local_timestamp": "2026-01-25T23:33:43.161844+00:00", "data": {"market": "0x2393ed0b0fdc450054c7b9071907eca75cf4fc36e385adf4a0a5f99ee62243e8", "price_changes": [{"asset_id": "100074770378634056601572485653252702850363676459996771990439989989293515601975", "price": "0.041", "size": "162", "side": "BUY", "hash": "b4ed428d72f622a13b8a3faa1fc4459b155b1a36", "best_bid": "0.041", "best_ask": "0.082"}, {"asset_id": "32769749367306925959219403371425714180265458150646381231272229429098460625924", "price": "0.959", "size": "162", "side": "SELL", "hash": "39544e209eb6fe2627bebc4107c567af1e836e45", "best_bid": "0.918", "best_ask": "0.959"}], "timestamp": "1769384023097", "event_type": "price_change"}}
{"_local_timestamp": "2026-01-25T23:33:43.577897+00:00", "data": {"market": "0xb9bbdd34304344dcc45803780a34c97d73a00133a5ecf70f63e1008b8abb2fca", "price_changes": [{"asset_id": "8682484153073832526711485265636767086525069344085206423986003504588877767339", "price": "0.871", "size": "0", "side": "BUY", "hash": "f7937c6c97c47b2bcdb3c7d88b1e325b8db8a03f", "best_bid": "0.991", "best_ask": "0.996"}, {"asset_id": "72012724360700510767037780555710363830014634797787940282136454146828040926557", "price": "0.129", "size": "0", "side": "SELL", "hash": "d809aec83703c34cc08b30e29eb39c8a2f4931fd", "best_bid": "0.004", "best_ask": "0.009"}], "timestamp": "1769384023510", "event_type": "price_change"}}
{"_local_timestamp": "2026-01-25T23:33:43.579170+00:00", "data": {"market": "0x50c669f178da4e5bbea7f1be25041fd278914712fa87a6a6f8e57d5923d88dee", "price_changes": [{"asset_id": "74040420326294854165772767082819937451857852955603897473157746262672057685461", "price": "0.879", "size": "0", "side": "BUY", "hash": "ab77f2829d71f3e10642731f0f629b6c567fb23a", "best_bid": "0.995", "best_ask": "0.998"}, {"asset_id": "24682525479474221428144937281315825971983904267399062415430320764754931667953", "price": "0.121", "size": "0", "side": "SELL", "hash": "448bc429a7afdb832afef5eb50b43ccf158c8c19", "best_bid": "0.002", "best_ask": "0.005"}], "timestamp": "1769384023510", "event_type": "price_change"}}
{"_local_timestamp": "2026-01-25T23:33:43.580257+00:00", "data": {"market": "0x49686d26fb712515cd5e12c23f0a1c7e10214c7faa3cb0a730aabe0c33694082", "price_changes": [{"asset_id": "30442780799048074404860985387051749017905070253466005720364298335239299761065", "price": "0.015", "size": "111", "side": "BUY", "hash": "abadd3de83410a270af3fc33941774a8d61201f1", "best_bid": "0.104", "best_ask": "0.133"}, {"asset_id": "13244681086321087932946246027856416106585284024824496763706748621681543444582", "price": "0.985", "size": "111", "side": "SELL", "hash": "ae6eb4ff7192e1d038dbf53b7a6dca31d2234514", "best_bid": "0.867", "best_ask": "0.896"}], "timestamp": "1769384023510", "event_type": "price_change"}}
{"_local_timestamp": "2026-01-25T23:33:43.581256+00:00", "data": {"market": "0xaf9d0e448129a9f657f851d49495ba4742055d80e0ef1166ba0ee81d4d594214", "price_changes": [{"asset_id": "4153292802911610701832309484716814274802943278345248636922528170020319407796", "price": "0.87", "size": "52.47", "side": "BUY", "hash": "625ba73f0ad7b24aa45bc5950ccfbfc6c7a05c9f", "best_bid": "0.936", "best_ask": "0.988"}, {"asset_id": "101676997363687199724245607342877036148401850938023978421879460310389391082353", "price": "0.13", "size": "52.47", "side": "SELL", "hash": "d09c555af115c51f83dc31228fe5f25752ea04da", "best_bid": "0.012", "best_ask": "0.064"}], "timestamp": "1769384023510", "event_type": "price_change"}}
{"_local_timestamp": "2026-01-25T23:33:43.606212+00:00", "data": {"market": "0xaf9d0e448129a9f657f851d49495ba4742055d80e0ef1166ba0ee81d4d594214", "price_changes": [{"asset_id": "4153292802911610701832309484716814274802943278345248636922528170020319407796", "price": "0.871", "size": "50", "side": "BUY", "hash": "4c3ee62bc4af92b51aed9dc72b19715436bb34eb", "best_bid": "0.936", "best_ask": "0.988"}, {"asset_id": "101676997363687199724245607342877036148401850938023978421879460310389391082353", "price": "0.129", "size": "50", "side": "SELL", "hash": "dbf1532e67cae6f173ece39a0db0b061215def6a", "best_bid": "0.012", "best_ask": "0.064"}], "timestamp": "1769384023540", "event_type": "price_change"}}
{"_local_timestamp": "2026-01-25T23:33:43.607183+00:00", "data": {"market": "0xb9bbdd34304344dcc45803780a34c97d73a00133a5ecf70f63e1008b8abb2fca", "price_changes": [{"asset_id": "8682484153073832526711485265636767086525069344085206423986003504588877767339", "price": "0.88", "size": "20", "side": "BUY", "hash": "188693624658d22053dd52d0f8710dd076a0d936", "best_bid": "0.991", "best_ask": "0.996"}, {"asset_id": "72012724360700510767037780555710363830014634797787940282136454146828040926557", "price": "0.12", "size": "20", "side": "SELL", "hash": "a80b8addf499f0cb5413360b618c17a468436052", "best_bid": "0.004", "best_ask": "0.009"}], "timestamp": "1769384023540", "event_type": "price_change"}}
{"_local_timestamp": "2026-01-25T23:33:43.608015+00:00", "data": {"market": "0x49686d26fb712515cd5e12c23f0a1c7e10214c7faa3cb0a730aabe0c33694082", "price_changes": [{"asset_id": "30442780799048074404860985387051749017905070253466005720364298335239299761065", "price": "0.016", "size": "27.01", "side": "BUY", "hash": "f2f7dcb2edca2c52e8d20c7b75b73044fa1b660b", "best_bid": "0.104", "best_ask": "0.133"}, {"asset_id": "13244681086321087932946246027856416106585284024824496763706748621681543444582", "price": "0.984", "size": "27.01", "side": "SELL", "hash": "a5c7c8c35452984645b14f2c5aa3f13705ad7bcc", "best_bid": "0.867", "best_ask": "0.896"}], "timestamp": "1769384023540", "event_type": "price_change"}}
{"_local_timestamp": "2026-01-25T23:33:43.608897+00:00", "data": {"market": "0x50c669f178da4e5bbea7f1be25041fd278914712fa87a6a6f8e57d5923d88dee", "price_changes": [{"asset_id": "74040420326294854165772767082819937451857852955603897473157746262672057685461", "price": "0.881", "size": "40", "side": "BUY", "hash": "86b9413fc704488e9c57274395898a4c6fd83891", "best_bid": "0.995", "best_ask": "0.998"}, {"asset_id": "24682525479474221428144937281315825971983904267399062415430320764754931667953", "price": "0.119", "size": "40", "side": "SELL", "hash": "cbd883694d75ee9dff4442ffff86f3ccd1adc537", "best_bid": "0.002", "best_ask": "0.005"}], "timestamp": "1769384023540", "event_type": "price_change"}}
{"_local_timestamp": "2026-01-25T23:33:44.330898+00:00", "data": {"market": "0x2393ed0b0fdc450054c7b9071907eca75cf4fc36e385adf4a0a5f99ee62243e8", "price_changes": [{"asset_id": "32769749367306925959219403371425714180265458150646381231272229429098460625924", "price": "0.903", "size": "37.81", "side": "BUY", "hash": "b8b9905ed34d480cc433186d65a27dec9da51a5d", "best_bid": "0.918", "best_ask": "0.959"}, {"asset_id": "100074770378634056601572485653252702850363676459996771990439989989293515601975", "price": "0.097", "size": "37.81", "side": "SELL", "hash": "cee983c7302bd3fd51af6a6a07072728fbc11448", "best_bid": "0.041", "best_ask": "0.082"}], "timestamp": "1769384024256", "event_type": "price_change"}}
{"_local_timestamp": "2026-01-25T23:33:44.348587+00:00", "data": {"market": "0x2393ed0b0fdc450054c7b9071907eca75cf4fc36e385adf4a0a5f99ee62243e8", "price_changes": [{"asset_id": "100074770378634056601572485653252702850363676459996771990439989989293515601975", "price": "0.041", "size": "0", "side": "BUY", "hash": "05a33f74850d547273c87dd87bb602f5c578a50b", "best_bid": "0.04", "best_ask": "0.082"}, {"asset_id": "32769749367306925959219403371425714180265458150646381231272229429098460625924", "price": "0.959", "size": "0", "side": "SELL", "hash": "416fb55146d42f78b5d4c6868445d1552677db84", "best_bid": "0.918", "best_ask": "0.96"}], "timestamp": "1769384024280", "event_type": "price_change"}}
{"_local_timestamp": "2026-01-25T23:33:44.349721+00:00", "data": {"market": "0x2393ed0b0fdc450054c7b9071907eca75cf4fc36e385adf4a0a5f99ee62243e8", "price_changes": [{"asset_id": "100074770378634056601572485653252702850363676459996771990439989989293515601975", "price": "0.098", "size": "0", "side": "SELL", "hash": "05a33f74850d547273c87dd87bb602f5c578a50b", "best_bid": "0.04", "best_ask": "0.082"}, {"asset_id": "32769749367306925959219403371425714180265458150646381231272229429098460625924", "price": "0.902", "size": "0", "side": "BUY", "hash": "416fb55146d42f78b5d4c6868445d1552677db84", "best_bid": "0.918", "best_ask": "0.96"}], "timestamp": "1769384024280", "event_type": "price_change"}}
{"_local_timestamp": "2026-01-25T23:33:44.377375+00:00", "data": {"market": "0x2393ed0b0fdc450054c7b9071907eca75cf4fc36e385adf4a0a5f99ee62243e8", "price_changes": [{"asset_id": "100074770378634056601572485653252702850363676459996771990439989989293515601975", "price": "0.096", "size": "141", "side": "SELL", "hash": "9c60668b95ec6a2c58dc0ba4ed5b83c0177e51d9", "best_bid": "0.04", "best_ask": "0.082"}, {"asset_id": "32769749367306925959219403371425714180265458150646381231272229429098460625924", "price": "0.904", "size": "141", "side": "BUY", "hash": "508116b343fc4c16ca13e63bc8cbefce83d23f22", "best_bid": "0.918", "best_ask": "0.96"}], "timestamp": "1769384024312", "event_type": "price_change"}}
{"_local_timestamp": "2026-01-25T23:33:44.389856+00:00", "data": {"market": "0x2393ed0b0fdc450054c7b9071907eca75cf4fc36e385adf4a0a5f99ee62243e8", "price_changes": [{"asset_id": "100074770378634056601572485653252702850363676459996771990439989989293515601975", "price": "0.041", "size": "38", "side": "BUY", "hash": "058ba9d601479369f8141921e643a55239f654f3", "best_bid": "0.041", "best_ask": "0.082"}, {"asset_id": "32769749367306925959219403371425714180265458150646381231272229429098460625924", "price": "0.959", "size": "38", "side": "SELL", "hash": "791f8561302185d00de3d96bcf6774bd899f068f", "best_bid": "0.918", "best_ask": "0.959"}], "timestamp": "1769384024322", "event_type": "price_change"}}
{"_local_timestamp": "2026-01-25T23:33:45.378930+00:00", "data": {"market": "0x2393ed0b0fdc450054c7b9071907eca75cf4fc36e385adf4a0a5f99ee62243e8", "price_changes": [{"asset_id": "32769749367306925959219403371425714180265458150646381231272229429098460625924", "price": "0.903", "size": "0", "side": "BUY", "hash": "6bf046e5f96b5f12aa023b70491b4e3f9257c7fe", "best_bid": "0.918", "best_ask": "0.959"}, {"asset_id": "100074770378634056601572485653252702850363676459996771990439989989293515601975", "price": "0.097", "size": "0", "side": "SELL", "hash": "cdffec043d7d4563edd3b3727f531c23a305ea29", "best_bid": "0.041", "best_ask": "0.082"}], "timestamp": "1769384025307", "event_type": "price_change"}}
{"_local_timestamp": "2026-01-25T23:33:45.930428+00:00", "data": {"market": "0x2393ed0b0fdc450054c7b9071907eca75cf4fc36e385adf4a0a5f99ee62243e8", "price_changes": [{"asset_id": "100074770378634056601572485653252702850363676459996771990439989989293515601975", "price": "0.041", "size": "0", "side": "BUY", "hash": "0d7f30004cbcab1154d59148514e9dc1776be049", "best_bid": "0.04", "best_ask": "0.082"}, {"asset_id": "32769749367306925959219403371425714180265458150646381231272229429098460625924", "price": "0.959", "size": "0", "side": "SELL", "hash": "0b352c6b85048d6fca21dbd2e4c01b7eb428d87e", "best_bid": "0.918", "best_ask": "0.96"}], "timestamp": "1769384025817", "event_type": "price_change"}}
{"_local_timestamp": "2026-01-25T23:33:45.937563+00:00", "data": {"market": "0x2393ed0b0fdc450054c7b9071907eca75cf4fc36e385adf4a0a5f99ee62243e8", "price_changes": [{"asset_id": "100074770378634056601572485653252702850363676459996771990439989989293515601975", "price": "0.041", "size": "162", "side": "BUY", "hash": "c93c9970f155e6741f18716bb633f776b9dec0e7", "best_bid": "0.041", "best_ask": "0.082"}, {"asset_id": "32769749367306925959219403371425714180265458150646381231272229429098460625924", "price": "0.959", "size": "162", "side": "SELL", "hash": "7f97b75fa4ef1baabf5d878b5fc0edb0561a0842", "best_bid": "0.918", "best_ask": "0.959"}], "timestamp": "1769384025842", "event_type": "price_change"}}
{"_local_timestamp": "2026-01-25T23:33:47.123588+00:00", "data": {"market": "0x2393ed0b0fdc450054c7b9071907eca75cf4fc36e385adf4a0a5f99ee62243e8", "price_changes": [{"asset_id": "32769749367306925959219403371425714180265458150646381231272229429098460625924", "price": "0.905", "size": "37.81", "side": "BUY", "hash": "263636a6891df31354e6e29ba2882135a42c9b6b", "best_bid": "0.918", "best_ask": "0.959"}, {"asset_id": "100074770378634056601572485653252702850363676459996771990439989989293515601975", "price": "0.095", "size": "37.81", "side": "SELL", "hash": "73ced598813373df327769fe88b424cd2dfecd62", "best_bid": "0.041", "best_ask": "0.082"}], "timestamp": "1769384027057", "event_type": "price_change"}}
{"_local_timestamp": "2026-01-25T23:33:47.149250+00:00", "data": {"market": "0x2393ed0b0fdc450054c7b9071907eca75cf4fc36e385adf4a0a5f99ee62243e8", "price_changes": [{"asset_id": "100074770378634056601572485653252702850363676459996771990439989989293515601975", "price": "0.041", "size": "0", "side": "BUY", "hash": "92fa34e9288195b37bec59889f8cd01546ecaa50", "best_bid": "0.04", "best_ask": "0.082"}, {"asset_id": "32769749367306925959219403371425714180265458150646381231272229429098460625924", "price": "0.959", "size": "0", "side": "SELL", "hash": "25858d1adedc36744ccca5b6fa5ffea0029fbf9f", "best_bid": "0.918", "best_ask": "0.96"}], "timestamp": "1769384027082", "event_type": "price_change"}}
{"_local_timestamp": "2026-01-25T23:33:47.150140+00:00", "data": {"market": "0x2393ed0b0fdc450054c7b9071907eca75cf4fc36e385adf4a0a5f99ee62243e8", "price_changes": [{"asset_id": "100074770378634056601572485653252702850363676459996771990439989989293515601975", "price": "0.096", "size": "0", "side": "SELL", "hash": "92fa34e9288195b37bec59889f8cd01546ecaa50", "best_bid": "0.04", "best_ask": "0.082"}, {"asset_id": "32769749367306925959219403371425714180265458150646381231272229429098460625924", "price": "0.904", "size": "0", "side": "BUY", "hash": "25858d1adedc36744ccca5b6fa5ffea0029fbf9f", "best_bid": "0.918", "best_ask": "0.96"}], "timestamp": "1769384027082", "event_type": "price_change"}}
{"_local_timestamp": "2026-01-25T23:33:47.174061+00:00", "data": {"market": "0x2393ed0b0fdc450054c7b9071907eca75cf4fc36e385adf4a0a5f99ee62243e8", "price_changes": [{"asset_id": "100074770378634056601572485653252702850363676459996771990439989989293515601975", "price": "0.041", "size": "38", "side": "BUY", "hash": "1ed2860be162ef3be5e40cb77105187c1694cc42", "best_bid": "0.041", "best_ask": "0.082"}, {"asset_id": "32769749367306925959219403371425714180265458150646381231272229429098460625924", "price": "0.959", "size": "38", "side": "SELL", "hash": "1b98a1d6306914ce4d6fc38c9128f08f7578ce35", "best_bid": "0.918", "best_ask": "0.959"}], "timestamp": "1769384027108", "event_type": "price_change"}}
{"_local_timestamp": "2026-01-25T23:33:47.176949+00:00", "data": {"market": "0x2393ed0b0fdc450054c7b9071907eca75cf4fc36e385adf4a0a5f99ee62243e8", "price_changes": [{"asset_id": "100074770378634056601572485653252702850363676459996771990439989989293515601975", "price": "0.094", "size": "141", "side": "SELL", "hash": "f8e8938fcbaed5a4afbe8e019b1318c74cbb0c1b", "best_bid": "0.041", "best_ask": "0.082"}, {"asset_id": "32769749367306925959219403371425714180265458150646381231272229429098460625924", "price": "0.906", "size": "141", "side": "BUY", "hash": "b46d24db49b5c7981492eec8c03db64b8cdf231f", "best_bid": "0.918", "best_ask": "0.959"}], "timestamp": "1769384027110", "event_type": "price_change"}}
{"_local_timestamp": "2026-01-25T23:33:47.482031+00:00", "data": {"market": "0x2393ed0b0fdc450054c7b9071907eca75cf4fc36e385adf4a0a5f99ee62243e8", "price_changes": [{"asset_id": "32769749367306925959219403371425714180265458150646381231272229429098460625924", "price": "0.96", "size": "0", "side": "SELL", "hash": "d0818cd899bb7e44187857d5cb0a5a6103ba80ec", "best_bid": "0.918", "best_ask": "0.959"}, {"asset_id": "100074770378634056601572485653252702850363676459996771990439989989293515601975", "price": "0.04", "size": "0", "side": "BUY", "hash": "6d2e58e791a463cee8c514728df3b884960cebdc", "best_bid": "0.041", "best_ask": "0.082"}], "timestamp": "1769384027418", "event_type": "price_change"}}
{"_local_timestamp": "2026-01-25T23:33:47.638383+00:00", "data": {"market": "0x2393ed0b0fdc450054c7b9071907eca75cf4fc36e385adf4a0a5f99ee62243e8", "price_changes": [{"asset_id": "32769749367306925959219403371425714180265458150646381231272229429098460625924", "price": "0.958", "size": "60", "side": "SELL", "hash": "d8bba9d53c3419d55a5c16433b839ffc660463a6", "best_bid": "0.918", "best_ask": "0.958"}, {"asset_id": "100074770378634056601572485653252702850363676459996771990439989989293515601975", "price": "0.042", "size": "60", "side": "BUY", "hash": "ebefbdeb2ceae8cc85549b82831d3f31bc87f900", "best_bid": "0.042", "best_ask": "0.082"}], "timestamp": "1769384027560", "event_type": "price_change"}}
{"_local_timestamp": "2026-01-25T23:33:47.761702+00:00", "data": {"market": "0x2393ed0b0fdc450054c7b9071907eca75cf4fc36e385adf4a0a5f99ee62243e8", "price_changes": [{"asset_id": "32769749367306925959219403371425714180265458150646381231272229429098460625924", "price": "0.899", "size": "0", "side": "BUY", "hash": "346941f40a413cc3965eeabc4da8a5a19296fb86", "best_bid": "0.918", "best_ask": "0.958"}, {"asset_id": "100074770378634056601572485653252702850363676459996771990439989989293515601975", "price": "0.101", "size": "0", "side": "SELL", "hash": "8f5decacdbe922847c4931457b29f5b71ee9a9fb", "best_bid": "0.042", "best_ask": "0.082"}], "timestamp": "1769384027698", "event_type": "price_change"}}
{"_local_timestamp": "2026-01-25T23:33:47.899397+00:00", "data": {"market": "0x2393ed0b0fdc450054c7b9071907eca75cf4fc36e385adf4a0a5f99ee62243e8", "price_changes": [{"asset_id": "32769749367306925959219403371425714180265458150646381231272229429098460625924", "price": "0.907", "size": "50", "side": "BUY", "hash": "c9b8ccd098b9eba91ae2a2b3c8ff30ae7dc7cbc8", "best_bid": "0.918", "best_ask": "0.958"}, {"asset_id": "100074770378634056601572485653252702850363676459996771990439989989293515601975", "price": "0.093", "size": "50", "side": "SELL", "hash": "d805b437f7ba29c9d270ad577b13bdef88274035", "best_bid": "0.042", "best_ask": "0.082"}], "timestamp": "1769384027834", "event_type": "price_change"}}
{"_local_timestamp": "2026-01-25T23:33:48.205473+00:00", "data": {"market": "0x2393ed0b0fdc450054c7b9071907eca75cf4fc36e385adf4a0a5f99ee62243e8", "price_changes": [{"asset_id": "32769749367306925959219403371425714180265458150646381231272229429098460625924", "price": "0.905", "size": "0", "side": "BUY", "hash": "d099772fe310c6607649666855a7171675b88a26", "best_bid": "0.918", "best_ask": "0.958"}, {"asset_id": "100074770378634056601572485653252702850363676459996771990439989989293515601975", "price": "0.095", "size": "0", "side": "SELL", "hash": "ead0ab1e7c44ee8271e702c6520db2a0151e0822", "best_bid": "0.042", "best_ask": "0.082"}], "timestamp": "1769384028140", "event_type": "price_change"}}
{"_local_timestamp": "2026-01-25T23:33:48.222996+00:00", "data": {"market": "0x2393ed0b0fdc450054c7b9071907eca75cf4fc36e385adf4a0a5f99ee62243e8", "price_changes": [{"asset_id": "32769749367306925959219403371425714180265458150646381231272229429098460625924", "price": "0.901", "size": "0", "side": "BUY", "hash": "e9ba54ef0c8330f8f3ad37103d1c8d0c4687e15d", "best_bid": "0.918", "best_ask": "0.958"}, {"asset_id": "100074770378634056601572485653252702850363676459996771990439989989293515601975", "price": "0.099", "size": "0", "side": "SELL", "hash": "00a33173a933b84f48eb6cfd00b622ee5d78e00a", "best_bid": "0.042", "best_ask": "0.082"}], "timestamp": "1769384028158", "event_type": "price_change"}}
{"_local_timestamp": "2026-01-25T23:33:48.233166+00:00", "data": {"market": "0x2393ed0b0fdc450054c7b9071907eca75cf4fc36e385adf4a0a5f99ee62243e8", "price_changes": [{"asset_id": "100074770378634056601572485653252702850363676459996771990439989989293515601975", "price": "0.094", "size": "0", "side": "SELL", "hash": "c6d6c1377527dd89aa16fffe11426f20e14c62df", "best_bid": "0.042", "best_ask": "0.082"}, {"asset_id": "32769749367306925959219403371425714180265458150646381231272229429098460625924", "price": "0.906", "size": "0", "side": "BUY", "hash": "70e10efb236fab4aa391205f00322eabe5076544", "best_bid": "0.918", "best_ask": "0.958"}], "timestamp": "1769384028165", "event_type": "price_change"}}
{"_local_timestamp": "2026-01-25T23:33:48.250136+00:00", "data": {"market": "0x2393ed0b0fdc450054c7b9071907eca75cf4fc36e385adf4a0a5f99ee62243e8", "price_changes": [{"asset_id": "100074770378634056601572485653252702850363676459996771990439989989293515601975", "price": "0.041", "size": "0", "side": "BUY", "hash": "56ae6229001a01a7a96030238a104e8ed7b97510", "best_bid": "0.042", "best_ask": "0.082"}, {"asset_id": "32769749367306925959219403371425714180265458150646381231272229429098460625924", "price": "0.959", "size": "0", "side": "SELL", "hash": "74a39c339f9a309477c9db1be049e2ed15d2b7cb", "best_bid": "0.918", "best_ask": "0.958"}], "timestamp": "1769384028187", "event_type": "price_change"}}
{"_local_timestamp": "2026-01-25T23:33:48.262083+00:00", "data": {"market": "0x2393ed0b0fdc450054c7b9071907eca75cf4fc36e385adf4a0a5f99ee62243e8", "price_changes": [{"asset_id": "100074770378634056601572485653252702850363676459996771990439989989293515601975", "price": "0.104", "size": "204", "side": "SELL", "hash": "129c2a66451deeb148ac2f48d85a3bf538bb5f1c", "best_bid": "0.042", "best_ask": "0.082"}, {"asset_id": "32769749367306925959219403371425714180265458150646381231272229429098460625924", "price": "0.896", "size": "204", "side": "BUY", "hash": "9437901752e96c98201291ff5ea5ea6456b56400", "best_bid": "0.918", "best_ask": "0.958"}], "timestamp": "1769384028197", "event_type": "price_change"}}
{"_local_timestamp": "2026-01-25T23:33:48.287483+00:00", "data": {"market": "0x2393ed0b0fdc450054c7b9071907eca75cf4fc36e385adf4a0a5f99ee62243e8", "price_changes": [{"asset_id": "100074770378634056601572485653252702850363676459996771990439989989293515601975", "price": "0.035", "size": "209", "side": "BUY", "hash": "520da91ea04d5fb0842aeb2514e15a26ccbf80f3", "best_bid": "0.042", "best_ask": "0.082"}, {"asset_id": "32769749367306925959219403371425714180265458150646381231272229429098460625924", "price": "0.965", "size": "209", "side": "SELL", "hash": "8803e7682bdeae12ec6a4d85d47bccf3ba5f28f1", "best_bid": "0.918", "best_ask": "0.958"}], "timestamp": "1769384028212", "event_type": "price_change"}}
{"_local_timestamp": "2026-01-25T23:33:48.676906+00:00", "data": {"market": "0x50c669f178da4e5bbea7f1be25041fd278914712fa87a6a6f8e57d5923d88dee", "price_changes": [{"asset_id": "74040420326294854165772767082819937451857852955603897473157746262672057685461", "price": "0.881", "size": "20", "side": "BUY", "hash": "776f61ac4fdaf9e5b7c58395e53f8e9e7835ce2d", "best_bid": "0.995", "best_ask": "0.998"}, {"asset_id": "24682525479474221428144937281315825971983904267399062415430320764754931667953", "price": "0.119", "size": "20", "side": "SELL", "hash": "7acd3917bcfb0597ae1988f7f9149068543fadfd", "best_bid": "0.002", "best_ask": "0.005"}], "timestamp": "1769384028612", "event_type": "price_change"}}
{"_local_timestamp": "2026-01-25T23:33:48.678358+00:00", "data": {"market": "0x49686d26fb712515cd5e12c23f0a1c7e10214c7faa3cb0a730aabe0c33694082", "price_changes": [{"asset_id": "30442780799048074404860985387051749017905070253466005720364298335239299761065", "price": "0.016", "size": "7.01", "side": "BUY", "hash": "d8a5679aa4fb893e4eabd68df2fd51188bb29316", "best_bid": "0.104", "best_ask": "0.133"}, {"asset_id": "13244681086321087932946246027856416106585284024824496763706748621681543444582", "price": "0.984", "size": "7.01", "side": "SELL", "hash": "f1a10c2ff26ef8f8a5f4f0cb8eaf77682f6a2c57", "best_bid": "0.867", "best_ask": "0.896"}], "timestamp": "1769384028612", "event_type": "price_change"}}
{"_local_timestamp": "2026-01-25T23:33:48.679106+00:00", "data": {"market": "0xaf9d0e448129a9f657f851d49495ba4742055d80e0ef1166ba0ee81d4d594214", "price_changes": [{"asset_id": "4153292802911610701832309484716814274802943278345248636922528170020319407796", "price": "0.871", "size": "30", "side": "BUY", "hash": "9001a399749097062c45e977030c7f9d8aa59865", "best_bid": "0.936", "best_ask": "0.988"}, {"asset_id": "101676997363687199724245607342877036148401850938023978421879460310389391082353", "price": "0.129", "size": "30", "side": "SELL", "hash": "5a513ec71a4fdaaf7cb1617dcf3ca1f9b94f0d7f", "best_bid": "0.012", "best_ask": "0.064"}], "timestamp": "1769384028612", "event_type": "price_change"}}
{"_local_timestamp": "2026-01-25T23:33:48.705148+00:00", "data": {"market": "0xaf9d0e448129a9f657f851d49495ba4742055d80e0ef1166ba0ee81d4d594214", "price_changes": [{"asset_id": "4153292802911610701832309484716814274802943278345248636922528170020319407796", "price": "0.872", "size": "20", "side": "BUY", "hash": "4cccfd901e1e04b7241c2ec09b063f4155365ae3", "best_bid": "0.936", "best_ask": "0.988"}, {"asset_id": "101676997363687199724245607342877036148401850938023978421879460310389391082353", "price": "0.128", "size": "20", "side": "SELL", "hash": "db66d877e3fc1739d83f136eb303a4b01f792781", "best_bid": "0.012", "best_ask": "0.064"}], "timestamp": "1769384028642", "event_type": "price_change"}}
{"_local_timestamp": "2026-01-25T23:33:48.705986+00:00", "data": {"market": "0x49686d26fb712515cd5e12c23f0a1c7e10214c7faa3cb0a730aabe0c33694082", "price_changes": [{"asset_id": "30442780799048074404860985387051749017905070253466005720364298335239299761065", "price": "0.017", "size": "20", "side": "BUY", "hash": "7fd798f6a0a4fa5f1e480ba3f6edc522247cffe2", "best_bid": "0.104", "best_ask": "0.133"}, {"asset_id": "13244681086321087932946246027856416106585284024824496763706748621681543444582", "price": "0.983", "size": "20", "side": "SELL", "hash": "19f2d23546c5bf9b1daa529eefd35fc601d8d71c", "best_bid": "0.867", "best_ask": "0.896"}], "timestamp": "1769384028642", "event_type": "price_change"}}
{"_local_timestamp": "2026-01-25T23:33:48.706721+00:00", "data": {"market": "0x50c669f178da4e5bbea7f1be25041fd278914712fa87a6a6f8e57d5923d88dee", "price_changes": [{"asset_id": "74040420326294854165772767082819937451857852955603897473157746262672057685461", "price": "0.882", "size": "20", "side": "BUY", "hash": "844c9e4b02b8b2bda28d689aaba171dfe25f1967", "best_bid": "0.995", "best_ask": "0.998"}, {"asset_id": "24682525479474221428144937281315825971983904267399062415430320764754931667953", "price": "0.118", "size": "20", "side": "SELL", "hash": "7a09939ae8bb8cc47c78db2a3e7085e42f090277", "best_bid": "0.002", "best_ask": "0.005"}], "timestamp": "1769384028642", "event_type": "price_change"}}
{"_local_timestamp": "2026-01-25T23:33:50.666674+00:00", "data": {"market": "0x2393ed0b0fdc450054c7b9071907eca75cf4fc36e385adf4a0a5f99ee62243e8", "price_changes": [{"asset_id": "32769749367306925959219403371425714180265458150646381231272229429098460625924", "price": "0.966", "size": "0", "side": "SELL", "hash": "eb6567295e30343f0f25f509966c47fdb2377944", "best_bid": "0.918", "best_ask": "0.958"}, {"asset_id": "100074770378634056601572485653252702850363676459996771990439989989293515601975", "price": "0.034", "size": "0", "side": "BUY", "hash": "c93183ddf1d86bb49c61c40750bf401455f129d9", "best_bid": "0.042", "best_ask": "0.082"}], "timestamp": "1769384030564", "event_type": "price_change"}}
{"_local_timestamp": "2026-01-25T23:33:50.963371+00:00", "data": {"market": "0x2393ed0b0fdc450054c7b9071907eca75cf4fc36e385adf4a0a5f99ee62243e8", "price_changes": [{"asset_id": "32769749367306925959219403371425714180265458150646381231272229429098460625924", "price": "0.907", "size": "87.81", "side": "BUY", "hash": "7393caecb82213c231e75faf6dcefc5256431d4b", "best_bid": "0.918", "best_ask": "0.958"}, {"asset_id": "100074770378634056601572485653252702850363676459996771990439989989293515601975", "price": "0.093", "size": "87.81", "side": "SELL", "hash": "6017c9f0eb464df1a932c97898412aac60ac1743", "best_bid": "0.042", "best_ask": "0.082"}], "timestamp": "1769384030895", "event_type": "price_change"}}
{"_local_timestamp": "2026-01-25T23:33:50.997775+00:00", "data": {"market": "0x2393ed0b0fdc450054c7b9071907eca75cf4fc36e385adf4a0a5f99ee62243e8", "price_changes": [{"asset_id": "100074770378634056601572485653252702850363676459996771990439989989293515601975", "price": "0.035", "size": "0", "side": "BUY", "hash": "14685832491889507056b1a08c0c37262a7f1874", "best_bid": "0.042", "best_ask": "0.082"}, {"asset_id": "32769749367306925959219403371425714180265458150646381231272229429098460625924", "price": "0.965", "size": "0", "side": "SELL", "hash": "6252ce68707893902893fe7ca23da78b44417dc6", "best_bid": "0.918", "best_ask": "0.958"}], "timestamp": "1769384030919", "event_type": "price_change"}}
{"_local_timestamp": "2026-01-25T23:33:51.011959+00:00", "data": {"market": "0x2393ed0b0fdc450054c7b9071907eca75cf4fc36e385adf4a0a5f99ee62243e8", "price_changes": [{"asset_id": "100074770378634056601572485653252702850363676459996771990439989989293515601975", "price": "0.034", "size": "92", "side": "BUY", "hash": "f51f45ee5e037d1cbdddfb6c39616bf2ff39a450", "best_bid": "0.042", "best_ask": "0.082"}, {"asset_id": "32769749367306925959219403371425714180265458150646381231272229429098460625924", "price": "0.966", "size": "92", "side": "SELL", "hash": "5c608583ddbf7ce00dad16dee644cc9757d4a992", "best_bid": "0.918", "best_ask": "0.958"}], "timestamp": "1769384030945", "event_type": "price_change"}}
{"_local_timestamp": "2026-01-25T23:33:51.142556+00:00", "data": {"market": "0xaf9d0e448129a9f657f851d49495ba4742055d80e0ef1166ba0ee81d4d594214", "price_changes": [{"asset_id": "4153292802911610701832309484716814274802943278345248636922528170020319407796", "price": "0.871", "size": "0", "side": "BUY", "hash": "8626f1a8653cc792ca590677be21b8ccb5f772bd", "best_bid": "0.936", "best_ask": "0.988"}, {"asset_id": "101676997363687199724245607342877036148401850938023978421879460310389391082353", "price": "0.129", "size": "0", "side": "SELL", "hash": "fb2b0e004cf11aa0f43ef8615deb919801d81a83", "best_bid": "0.012", "best_ask": "0.064"}], "timestamp": "1769384031064", "event_type": "price_change"}}
{"_local_timestamp": "2026-01-25T23:33:51.250045+00:00", "data": {"market": "0xaf9d0e448129a9f657f851d49495ba4742055d80e0ef1166ba0ee81d4d594214", "price_changes": [{"asset_id": "4153292802911610701832309484716814274802943278345248636922528170020319407796", "price": "0.873", "size": "30", "side": "BUY", "hash": "f7a688aed5ac52f05b55f7c5619942d2d6314881", "best_bid": "0.936", "best_ask": "0.988"}, {"asset_id": "101676997363687199724245607342877036148401850938023978421879460310389391082353", "price": "0.127", "size": "30", "side": "SELL", "hash": "0b002fed43413618745cf687a5975a10fd904f0b", "best_bid": "0.012", "best_ask": "0.064"}], "timestamp": "1769384031188", "event_type": "price_change"}}
{"_local_timestamp": "2026-01-25T23:33:52.728472+00:00", "data": {"market": "0xaf9d0e448129a9f657f851d49495ba4742055d80e0ef1166ba0ee81d4d594214", "price_changes": [{"asset_id": "4153292802911610701832309484716814274802943278345248636922528170020319407796", "price": "0.872", "size": "0", "side": "BUY", "hash": "3940066c3eb65afa14dc13a351f52e4e9edaec5d", "best_bid": "0.936", "best_ask": "0.988"}, {"asset_id": "101676997363687199724245607342877036148401850938023978421879460310389391082353", "price": "0.128", "size": "0", "side": "SELL", "hash": "65c9cabccf58c3bce36b2d49d5473651935c855f", "best_bid": "0.012", "best_ask": "0.064"}], "timestamp": "1769384032659", "event_type": "price_change"}}
{"_local_timestamp": "2026-01-25T23:33:52.754651+00:00", "data": {"market": "0xaf9d0e448129a9f657f851d49495ba4742055d80e0ef1166ba0ee81d4d594214", "price_changes": [{"asset_id": "4153292802911610701832309484716814274802943278345248636922528170020319407796", "price": "0.871", "size": "20", "side": "BUY", "hash": "f073f5a66627df4e310a0db9196431726a1623c3", "best_bid": "0.936", "best_ask": "0.988"}, {"asset_id": "101676997363687199724245607342877036148401850938023978421879460310389391082353", "price": "0.129", "size": "20", "side": "SELL", "hash": "e6daaf59f76bacc24dd008af8613b32e41090540", "best_bid": "0.012", "best_ask": "0.064"}], "timestamp": "1769384032688", "event_type": "price_change"}}
{"_local_timestamp": "2026-01-25T23:33:53.451982+00:00", "data": {"market": "0x2393ed0b0fdc450054c7b9071907eca75cf4fc36e385adf4a0a5f99ee62243e8", "price_changes": [{"asset_id": "32769749367306925959219403371425714180265458150646381231272229429098460625924", "price": "0.907", "size": "50", "side": "BUY", "hash": "b36e8bb6b370318b5212c5059a230df33273abe5", "best_bid": "0.918", "best_ask": "0.958"}, {"asset_id": "100074770378634056601572485653252702850363676459996771990439989989293515601975", "price": "0.093", "size": "50", "side": "SELL", "hash": "68b892a667c1da1caab27c0c1393abf543d8e5d0", "best_bid": "0.042", "best_ask": "0.082"}], "timestamp": "1769384033387", "event_type": "price_change"}}
{"_local_timestamp": "2026-01-25T23:33:53.479582+00:00", "data": {"market": "0x2393ed0b0fdc450054c7b9071907eca75cf4fc36e385adf4a0a5f99ee62243e8", "price_changes": [{"asset_id": "100074770378634056601572485653252702850363676459996771990439989989293515601975", "price": "0.034", "size": "0", "side": "BUY", "hash": "24950db30e9564ad8ad083fbde305f92fcfd5643", "best_bid": "0.042", "best_ask": "0.082"}, {"asset_id": "32769749367306925959219403371425714180265458150646381231272229429098460625924", "price": "0.966", "size": "0", "side": "SELL", "hash": "910ad3afcc6379dfbe44986c64f912b1c008586f", "best_bid": "0.918", "best_ask": "0.958"}], "timestamp": "1769384033414", "event_type": "price_change"}}
{"_local_timestamp": "2026-01-25T23:33:53.507459+00:00", "data": {"market": "0x2393ed0b0fdc450054c7b9071907eca75cf4fc36e385adf4a0a5f99ee62243e8", "price_changes": [{"asset_id": "100074770378634056601572485653252702850363676459996771990439989989293515601975", "price": "0.034", "size": "109", "side": "BUY", "hash": "a62357addae9220abc268093b2f19e74eb6cb0e6", "best_bid": "0.042", "best_ask": "0.082"}, {"asset_id": "32769749367306925959219403371425714180265458150646381231272229429098460625924", "price": "0.966", "size": "109", "side": "SELL", "hash": "9f8a192b66511b81e7186b034d747ed2a5fef7f3", "best_bid": "0.918", "best_ask": "0.958"}], "timestamp": "1769384033444", "event_type": "price_change"}}
{"_local_timestamp": "2026-01-25T23:33:53.521297+00:00", "data": {"market": "0x2393ed0b0fdc450054c7b9071907eca75cf4fc36e385adf4a0a5f99ee62243e8", "price_changes": [{"asset_id": "32769749367306925959219403371425714180265458150646381231272229429098460625924", "price": "0.958", "size": "0", "side": "SELL", "hash": "3833653de99d1974899e4c19d7d314369b1ba377", "best_bid": "0.918", "best_ask": "0.961"}, {"asset_id": "100074770378634056601572485653252702850363676459996771990439989989293515601975", "price": "0.042", "size": "0", "side": "BUY", "hash": "7774c51cdb82f840185dcb77d37029c48ef1c3b8", "best_bid": "0.039", "best_ask": "0.082"}], "timestamp": "1769384033457", "event_type": "price_change"}}
{"_local_timestamp": "2026-01-25T23:33:53.669474+00:00", "data": {"market": "0xaf9d0e448129a9f657f851d49495ba4742055d80e0ef1166ba0ee81d4d594214", "price_changes": [{"asset_id": "4153292802911610701832309484716814274802943278345248636922528170020319407796", "price": "0.873", "size": "0", "side": "BUY", "hash": "7e2b73c2f753a0461b68bbd99cd37a9a13d45036", "best_bid": "0.936", "best_ask": "0.988"}, {"asset_id": "101676997363687199724245607342877036148401850938023978421879460310389391082353", "price": "0.127", "size": "0", "side": "SELL", "hash": "cc97417255390a88a54584ab198e98b939a16faa", "best_bid": "0.012", "best_ask": "0.064"}], "timestamp": "1769384033604", "event_type": "price_change"}}
{"_local_timestamp": "2026-01-25T23:33:53.810289+00:00", "data": {"market": "0xaf9d0e448129a9f657f851d49495ba4742055d80e0ef1166ba0ee81d4d594214", "price_changes": [{"asset_id": "4153292802911610701832309484716814274802943278345248636922528170020319407796", "price": "0.872", "size": "30", "side": "BUY", "hash": "8439e850f93737bfb51008197a15cfbae4aeb408", "best_bid": "0.936", "best_ask": "0.988"}, {"asset_id": "101676997363687199724245607342877036148401850938023978421879460310389391082353", "price": "0.128", "size": "30", "side": "SELL", "hash": "55d86c4c9650677b826f94f3ca56f4e50c5adac8", "best_bid": "0.012", "best_ask": "0.064"}], "timestamp": "1769384033744", "event_type": "price_change"}}
{"_local_timestamp": "2026-01-25T23:33:53.818217+00:00", "data": {"market": "0xaf9d0e448129a9f657f851d49495ba4742055d80e0ef1166ba0ee81d4d594214", "price_changes": [{"asset_id": "4153292802911610701832309484716814274802943278345248636922528170020319407796", "price": "0.698", "size": "532.05", "side": "BUY", "hash": "04932cfa37ff74a42920e9e857db157aed8e2325", "best_bid": "0.936", "best_ask": "0.988"}, {"asset_id": "101676997363687199724245607342877036148401850938023978421879460310389391082353", "price": "0.302", "size": "532.05", "side": "SELL", "hash": "ebaff66b5b1230b840d53a40d08950512daf455a", "best_bid": "0.012", "best_ask": "0.064"}], "timestamp": "1769384033745", "event_type": "price_change"}}
{"_local_timestamp": "2026-01-25T23:33:53.838036+00:00", "data": {"market": "0xaf9d0e448129a9f657f851d49495ba4742055d80e0ef1166ba0ee81d4d594214", "price_changes": [{"asset_id": "4153292802911610701832309484716814274802943278345248636922528170020319407796", "price": "0.697", "size": "300", "side": "BUY", "hash": "d840a10acb16b53549f2f392f20d23a1239e9ae8", "best_bid": "0.936", "best_ask": "0.988"}, {"asset_id": "101676997363687199724245607342877036148401850938023978421879460310389391082353", "price": "0.303", "size": "300", "side": "SELL", "hash": "76d24ebece4cdd6a7a795b5b5c38836b7a2ed674", "best_bid": "0.012", "best_ask": "0.064"}], "timestamp": "1769384033774", "event_type": "price_change"}}
{"_local_timestamp": "2026-01-25T23:33:53.894567+00:00", "data": {"market": "0xaf9d0e448129a9f657f851d49495ba4742055d80e0ef1166ba0ee81d4d594214", "price_changes": [{"asset_id": "4153292802911610701832309484716814274802943278345248636922528170020319407796", "price": "0.699", "size": "400", "side": "BUY", "hash": "63373746edbc531db844db851fe8c37995c64e33", "best_bid": "0.936", "best_ask": "0.988"}, {"asset_id": "101676997363687199724245607342877036148401850938023978421879460310389391082353", "price": "0.301", "size": "400", "side": "SELL", "hash": "72c63bd361498cc577d41381bf0f1362c04010d2", "best_bid": "0.012", "best_ask": "0.064"}], "timestamp": "1769384033830", "event_type": "price_change"}}
{"_local_timestamp": "2026-01-25T23:33:53.995736+00:00", "data": {"market": "0x50c669f178da4e5bbea7f1be25041fd278914712fa87a6a6f8e57d5923d88dee", "price_changes": [{"asset_id": "74040420326294854165772767082819937451857852955603897473157746262672057685461", "price": "0.882", "size": "0", "side": "BUY", "hash": "d571cba1486e72a2744a0379e0136aa4686ead0a", "best_bid": "0.995", "best_ask": "0.998"}, {"asset_id": "24682525479474221428144937281315825971983904267399062415430320764754931667953", "price": "0.118", "size": "0", "side": "SELL", "hash": "8c995996d46285bf6c011af677b4a7877315f70e", "best_bid": "0.002", "best_ask": "0.005"}], "timestamp": "1769384033924", "event_type": "price_change"}}
{"_local_timestamp": "2026-01-25T23:33:53.996750+00:00", "data": {"market": "0xb9bbdd34304344dcc45803780a34c97d73a00133a5ecf70f63e1008b8abb2fca", "price_changes": [{"asset_id": "8682484153073832526711485265636767086525069344085206423986003504588877767339", "price": "0.88", "size": "0", "side": "BUY", "hash": "6d6fb8b60fed51d2b4342985efaa25c8caf8b6ee", "best_bid": "0.991", "best_ask": "0.996"}, {"asset_id": "72012724360700510767037780555710363830014634797787940282136454146828040926557", "price": "0.12", "size": "0", "side": "SELL", "hash": "e816b0cf5ae87586791ea86f169ab9280fb4a923", "best_bid": "0.004", "best_ask": "0.009"}], "timestamp": "1769384033924", "event_type": "price_change"}}
{"_local_timestamp": "2026-01-25T23:33:53.999593+00:00", "data": {"market": "0xaf9d0e448129a9f657f851d49495ba4742055d80e0ef1166ba0ee81d4d594214", "price_changes": [{"asset_id": "4153292802911610701832309484716814274802943278345248636922528170020319407796", "price": "0.871", "size": "0", "side": "BUY", "hash": "779a3718e3305cd93d6214b628226fefdea11537", "best_bid": "0.936", "best_ask": "0.988"}, {"asset_id": "101676997363687199724245607342877036148401850938023978421879460310389391082353", "price": "0.129", "size": "0", "side": "SELL", "hash": "ddd3271525b45ac91a923d3720cf60ac67a46b11", "best_bid": "0.012", "best_ask": "0.064"}], "timestamp": "1769384033924", "event_type": "price_change"}}
{"_local_timestamp": "2026-01-25T23:33:54.000644+00:00", "data": {"market": "0x49686d26fb712515cd5e12c23f0a1c7e10214c7faa3cb0a730aabe0c33694082", "price_changes": [{"asset_id": "30442780799048074404860985387051749017905070253466005720364298335239299761065", "price": "0.017", "size": "0", "side": "BUY", "hash": "db8f64f73aa5b66a8c7a6173ed8def5e448b4b8b", "best_bid": "0.104", "best_ask": "0.133"}, {"asset_id": "13244681086321087932946246027856416106585284024824496763706748621681543444582", "price": "0.983", "size": "0", "side": "SELL", "hash": "46df7c9f1a9c026aa29d27427d831be7e5adfc3e", "best_bid": "0.867", "best_ask": "0.896"}], "timestamp": "1769384033924", "event_type": "price_change"}}
{"_local_timestamp": "2026-01-25T23:33:54.001916+00:00", "data": {"market": "0xc55db914f0fd1fee18997706712c0dfd8d0369cdbef93a9fef12bd001914ca77", "price_changes": [{"asset_id": "114600293444080540179603459515770723592661967180480327891296353898330242622833", "price": "0.881", "size": "0", "side": "BUY", "hash": "d53776e3f278f4798fc30449b5a07f5f0ff225a6", "best_bid": "0.993", "best_ask": "0.999"}, {"asset_id": "72354723612769247426741660426331235762851940382312402276325808095604519806766", "price": "0.119", "size": "0", "side": "SELL", "hash": "79332628b473a1005cbe8ebcfc14a56f558c4e55", "best_bid": "0.001", "best_ask": "0.007"}], "timestamp": "1769384033924", "event_type": "price_change"}}
{"_local_timestamp": "2026-01-25T23:33:54.003174+00:00", "data": {"market": "0x2393ed0b0fdc450054c7b9071907eca75cf4fc36e385adf4a0a5f99ee62243e8", "price_changes": [{"asset_id": "32769749367306925959219403371425714180265458150646381231272229429098460625924", "price": "0.964", "size": "112.19", "side": "SELL", "hash": "54b142883916cdea965cba89acb2ce057fc5eaf6", "best_bid": "0.918", "best_ask": "0.961"}, {"asset_id": "100074770378634056601572485653252702850363676459996771990439989989293515601975", "price": "0.036", "size": "112.19", "side": "BUY", "hash": "b28355b9b12b1a8aca0e3b38e817d17333338e11", "best_bid": "0.039", "best_ask": "0.082"}], "timestamp": "1769384033936", "event_type": "price_change"}}
{"_local_timestamp": "2026-01-25T23:33:54.023501+00:00", "data": {"market": "0xaf9d0e448129a9f657f851d49495ba4742055d80e0ef1166ba0ee81d4d594214", "price_changes": [{"asset_id": "4153292802911610701832309484716814274802943278345248636922528170020319407796", "price": "0.862", "size": "20", "side": "BUY", "hash": "1aa310b4104d73d6c8ac0c588cce7229a9c6fead", "best_bid": "0.936", "best_ask": "0.988"}, {"asset_id": "101676997363687199724245607342877036148401850938023978421879460310389391082353", "price": "0.138", "size": "20", "side": "SELL", "hash": "49fc40611141b971cf0760fb09a84e752c5b8cb6", "best_bid": "0.012", "best_ask": "0.064"}], "timestamp": "1769384033959", "event_type": "price_change"}}
{"_local_timestamp": "2026-01-25T23:33:54.025610+00:00", "data": {"market": "0x49686d26fb712515cd5e12c23f0a1c7e10214c7faa3cb0a730aabe0c33694082", "price_changes": [{"asset_id": "30442780799048074404860985387051749017905070253466005720364298335239299761065", "price": "0.013", "size": "20", "side": "BUY", "hash": "46e682580e01d9ce79919773de52a6606134bd59", "best_bid": "0.104", "best_ask": "0.133"}, {"asset_id": "13244681086321087932946246027856416106585284024824496763706748621681543444582", "price": "0.987", "size": "20", "side": "SELL", "hash": "1e2ff5a64e8279b69a8164a8044a499b965f6e6f", "best_bid": "0.867", "best_ask": "0.896"}], "timestamp": "1769384033959", "event_type": "price_change"}}
{"_local_timestamp": "2026-01-25T23:33:54.030382+00:00", "data": {"market": "0xb9bbdd34304344dcc45803780a34c97d73a00133a5ecf70f63e1008b8abb2fca", "price_changes": [{"asset_id": "8682484153073832526711485265636767086525069344085206423986003504588877767339", "price": "0.871", "size": "20", "side": "BUY", "hash": "14575a1af20bc7d0839be97cd17c4830d0ddd5f5", "best_bid": "0.991", "best_ask": "0.996"}, {"asset_id": "72012724360700510767037780555710363830014634797787940282136454146828040926557", "price": "0.129", "size": "20", "side": "SELL", "hash": "441113bea2a3f71d828decf1ddeaa49623d492dd", "best_bid": "0.004", "best_ask": "0.009"}], "timestamp": "1769384033959", "event_type": "price_change"}}
{"_local_timestamp": "2026-01-25T23:33:54.035811+00:00", "data": {"market": "0x50c669f178da4e5bbea7f1be25041fd278914712fa87a6a6f8e57d5923d88dee", "price_changes": [{"asset_id": "74040420326294854165772767082819937451857852955603897473157746262672057685461", "price": "0.879", "size": "20", "side": "BUY", "hash": "ad6ba3584b50114c661c42cc666a4f19331ecef2", "best_bid": "0.995", "best_ask": "0.998"}, {"asset_id": "24682525479474221428144937281315825971983904267399062415430320764754931667953", "price": "0.121", "size": "20", "side": "SELL", "hash": "13221c8e052860095e9ebaf953805887c3864b83", "best_bid": "0.002", "best_ask": "0.005"}], "timestamp": "1769384033959", "event_type": "price_change"}}
{"_local_timestamp": "2026-01-25T23:33:54.041936+00:00", "data": {"market": "0xc55db914f0fd1fee18997706712c0dfd8d0369cdbef93a9fef12bd001914ca77", "price_changes": [{"asset_id": "114600293444080540179603459515770723592661967180480327891296353898330242622833", "price": "0.88", "size": "30", "side": "BUY", "hash": "f4b72f55a1f64ef9de32b80c46af35759dc58e81", "best_bid": "0.993", "best_ask": "0.999"}, {"asset_id": "72354723612769247426741660426331235762851940382312402276325808095604519806766", "price": "0.12", "size": "30", "side": "SELL", "hash": "6d76e611ecb617a6b8c5453b9b19d404503021f6", "best_bid": "0.001", "best_ask": "0.007"}], "timestamp": "1769384033959", "event_type": "price_change"}}
