{"_local_timestamp": "2026-01-25T23:33:31.988603+00:00", "data": [{"market": "0x0be3d4cc20250a7105206bc352af8b1c087df2ebd4f3b3927fabcdd8c81d792e", "asset_id": "63149403073928211890844841868361708990331353150804831882114276975252031214656", "timestamp": "1769383979959", "hash": "1b63177d8ca08ef13aef5e6b8f5fd801b8b6343c", "bids": [{"price": "0.01", "size": "5535.4"}, {"price": "0.03", "size": "1200"}, {"price": "0.04", "size": "8.65"}, {"price": "0.05", "size": "3280"}, {"price": "0.07", "size": "457.14"}, {"price": "0.08", "size": "228"}, {"price": "0.09", "size": "311.11"}, {"price": "0.11", "size": "236.36"}, {"price": "0.12", "size": "200"}, {"price": "0.14", "size": "242.85"}, {"price": "0.27", "size": "50"}, {"price": "0.29", "size": "500"}, {"price": "0.3", "size": "457.49"}, {"price": "0.31", "size": "57.49"}, {"price": "0.33", "size": "69.15"}], "asks": [{"price": "0.99", "size": "8793.7"}, {"price": "0.98", "size": "3750"}, {"price": "0.97", "size": "10.28"}, {"price": "0.96", "size": "250"}, {"price": "0.95", "size": "10"}, {"price": "0.93", "size": "1914.28"}, {"price": "0.92", "size": "6.16"}, {"price": "0.9", "size": "340"}, {"price": "0.87", "size": "550"}, {"price": "0.86", "size": "228.57"}, {"price": "0.83", "size": "664.7"}, {"price": "0.82", "size": "5.89"}, {"price": "0.79", "size": "608.8"}, {"price": "0.76", "size": "100"}, {"price": "0.74", "size": "100"}, {"price": "0.73", "size": "196"}, {"price": "0.72", "size": "71.42"}, {"price": "0.71", "size": "35"}, {"price": "0.7", "size": "6"}, {"price": "0.53", "size": "100"}, {"price": "0.51", "size": "10"}, {"price": "0.49", "size": "40"}, {"price": "0.48", "size": "30"}, {"price": "0.47", "size": "20"}, {"price": "0.43", "size": "73"}, {"price": "0.36", "size": "26.72"}, {"price": "0.35", "size": "40"}], "event_type": "book", "last_trade_price": "0.640"}, {"market": "0x9cacc164f8e79d815cc6714b0e5a04055f3bd5f6d05dc25f4265e7ffaa08dadc", "asset_id": "58983570136035430006949575067833187006601843982035390064418024195691336080349", "timestamp": "1769383694005", "hash": "aa83e497ae7588eb38cd1eed8b657ef1151a7f43", "bids": [{"price": "0.01", "size": "9087.5"}, {"price": "0.02", "size": "3760.6"}, {"price": "0.04", "size": "250"}, {"price": "0.05", "size": "15.08"}, {"price": "0.08", "size": "700"}, {"price": "0.09", "size": "5.24"}, {"price": "0.11", "size": "550"}, {"price": "0.17", "size": "1500"}, {"price": "0.18", "size": "255.48"}, {"price": "0.19", "size": "10"}, {"price": "0.23", "size": "200"}, {"price": "0.39", "size": "445"}, {"price": "0.4", "size": "10"}, {"price": "0.41", "size": "50"}, {"price": "0.42", "size": "40"}, {"price": "0.45", "size": "39"}, {"price": "0.49", "size": "555"}, {"price": "0.51", "size": "833"}, {"price": "0.52", "size": "400"}], "asks": [{"price": "0.99", "size": "39.84"}, {"price": "0.98", "size": "15.07"}, {"price": "0.95", "size": "720"}, {"price": "0.93", "size": "485.71"}, {"price": "0.9", "size": "320"}, {"price": "0.88", "size": "458.33"}, {"price": "0.86", "size": "185.71"}, {"price": "0.83", "size": "141.17"}, {"price": "0.81", "size": "455.26"}, {"price": "0.8", "size": "227"}, {"price": "0.77", "size": "5"}, {"price": "0.67", "size": "3.36"}, {"price": "0.55", "size": "99"}], "event_type": "book", "last_trade_price": "0.510"}, {"market": "0x46e08dad4b1370947613b81f2ba28a23226504a333ec7e42de877d6ba6cc59d0", "asset_id": "113369140136913812777925497644561662667789653912765877043929720445901767848122", "timestamp": "1769383979825", "hash": "01fb261567a74db29ca132e7c0ba3195d3165194", "bids": [{"price": "0.001", "size": "12070"}, {"price": "0.002", "size": "256.19"}, {"price": "0.003", "size": "12.26"}, {"price": "0.005", "size": "432.16"}, {"price": "0.006", "size": "10.01"}, {"price": "0.007", "size": "786.73"}, {"price": "0.01", "size": "30"}, {"price": "0.011", "size": "11.54"}, {"price": "0.021", "size": "4877.19"}, {"price": "0.022", "size": "5.94"}, {"price": "0.023", "size": "500"}, {"price": "0.035", "size": "365.33"}, {"price": "0.036", "size": "249"}], "asks": [{"price": "0.999", "size": "4533.59"}, {"price": "0.998", "size": "1256.56"}, {"price": "0.997", "size": "1400"}, {"price": "0.996", "size": "11.34"}, {"price": "0.994", "size": "200"}, {"price": "0.99", "size": "9080"}, {"price": "0.989", "size": "5.74"}, {"price": "0.98", "size": "3750"}, {"price": "0.979", "size": "11.16"}, {"price": "0.96", "size": "250"}, {"price": "0.95", "size": "30"}, {"price": "0.949", "size": "39"}, {"price": "0.94", "size": "1100"}, {"price": "0.939", "size": "9.79"}, {"price": "0.9", "size": "360"}, {"price": "0.85", "size": "876.66"}, {"price": "0.81", "size": "568.42"}, {"price": "0.809", "size": "234"}, {"price": "0.808", "size": "5.41"}, {"price": "0.76", "size": "416.66"}, {"price": "0.71", "size": "189.65"}, {"price": "0.66", "size": "70.58"}, {"price": "0.61", "size": "51.28"}, {"price": "0.6", "size": "500"}, {"price": "0.496", "size": "5"}, {"price": "0.479", "size": "567"}, {"price": "0.478", "size": "191"}, {"price": "0.468", "size": "10"}, {"price": "0.466", "size": "25"}, {"price": "0.464", "size": "30"}, {"price": "0.463", "size": "40"}, {"price": "0.462", "size": "20"}, {"price": "0.064", "size": "358.22"}, {"price": "0.06", "size": "10"}, {"price": "0.055", "size": "10"}, {"price": "0.052", "size": "486.33"}, {"price": "0.042", "size": "66.1"}], "event_type": "book", "last_trade_price": "0.042"}, {"market": "0x44f67876759c44b763bb53f89b3c738756331b0a208672fc8db8a5f389230950", "asset_id": "1582298976410585403069729422280265608038484032857579102122167925665102997608", "timestamp": "1769383979825", "hash": "72c7aa3a20842bae6ba23e6817ac49e7e543804c", "bids": [{"price": "0.001", "size": "10886.99"}, {"price": "0.002", "size": "676.11"}, {"price": "0.003", "size": "12.86"}, {"price": "0.004", "size": "12.4"}, {"price": "0.005", "size": "134.04"}, {"price": "0.006", "size": "67"}, {"price": "0.007", "size": "11.18"}, {"price": "0.012", "size": "52.93"}, {"price": "0.013", "size": "18.4"}, {"price": "0.014", "size": "50.51"}], "asks": [{"price": "0.999", "size": "3236.84"}, {"price": "0.998", "size": "1256.56"}, {"price": "0.997", "size": "1000"}, {"price": "0.996", "size": "11.33"}, {"price": "0.99", "size": "9080"}, {"price": "0.989", "size": "5.73"}, {"price": "0.98", "size": "3750"}, {"price": "0.979", "size": "11.16"}, {"price": "0.96", "size": "250"}, {"price": "0.95", "size": "30"}, {"price": "0.949", "size": "39"}, {"price": "0.94", "size": "1100"}, {"price": "0.939", "size": "10.33"}, {"price": "0.9", "size": "360"}, {"price": "0.85", "size": "876.66"}, {"price": "0.8", "size": "610"}, {"price": "0.799", "size": "5.01"}, {"price": "0.75", "size": "312"}, {"price": "0.7", "size": "136.66"}, {"price": "0.698", "size": "821"}, {"price": "0.697", "size": "211.28"}, {"price": "0.66", "size": "50"}, {"price": "0.65", "size": "68.57"}, {"price": "0.649", "size": "34"}, {"price": "0.6", "size": "50"}, {"price": "0.599", "size": "66.66"}, {"price": "0.549", "size": "172"}, {"price": "0.548", "size": "5"}, {"price": "0.33", "size": "66.66"}, {"price": "0.271", "size": "13.33"}, {"price": "0.267", "size": "10"}, {"price": "0.265", "size": "30"}, {"price": "0.264", "size": "40"}, {"price": "0.263", "size": "20"}, {"price": "0.1", "size": "5"}, {"price": "0.07", "size": "50"}, {"price": "0.061", "size": "116.66"}, {"price": "0.06", "size": "40.06"}], "event_type": "book", "last_trade_price": "0.013"}, {"market": "0x5b782c35d9cbd6e9d38597bd0af4e53d3263bde143e4d4ffdbd76d0a094f4be4", "asset_id": "48123308101524452666134421526726361469113858451786831367632481270457773825485", "timestamp": "1769383994965", "hash": "96cca62a031a0e1a7087fe926210014468dee062", "bids": [{"price": "0.01", "size": "8792.93"}, {"price": "0.02", "size": "3750"}, {"price": "0.03", "size": "7.87"}, {"price": "0.04", "size": "250"}, {"price": "0.05", "size": "30"}, {"price": "0.06", "size": "33"}, {"price": "0.07", "size": "7.97"}, {"price": "0.09", "size": "1400"}, {"price": "0.14", "size": "792.85"}, {"price": "0.18", "size": "677.77"}, {"price": "0.19", "size": "5.66"}, {"price": "0.23", "size": "271.73"}, {"price": "0.28", "size": "342.85"}, {"price": "0.29", "size": "171"}, {"price": "0.32", "size": "75"}, {"price": "0.33", "size": "65"}, {"price": "0.34", "size": "50"}, {"price": "0.37", "size": "54.05"}, {"price": "0.38", "size": "5"}, {"price": "0.47", "size": "212"}, {"price": "0.48", "size": "170"}, {"price": "0.69", "size": "100"}, {"price": "0.7", "size": "20"}, {"price": "0.78", "size": "30"}, {"price": "0.79", "size": "40"}, {"price": "0.8", "size": "8.75"}, {"price": "0.82", "size": "57"}, {"price": "0.83", "size": "36.39"}, {"price": "0.85", "size": "23"}, {"price": "0.91", "size": "10.64"}], "asks": [{"price": "0.99", "size": "115"}, {"price": "0.97", "size": "290"}, {"price": "0.96", "size": "500"}, {"price": "0.94", "size": "10"}, {"price": "0.92", "size": "1891.31"}], "event_type": "book", "last_trade_price": "0.080"}, {"market": "0x44f67876759c44b763bb53f89b3c738756331b0a208672fc8db8a5f389230950", "asset_id": "32592218374784909301050372254273467546998719384564620545871759434640468645973", "timestamp": "1769383979825", "hash": "b85fcca6f50fd024df7099059e1919d6e6077d02", "bids": [{"price": "0.001", "size": "3236.84"}, {"price": "0.002", "size": "1256.56"}, {"price": "0.003", "size": "1000"}, {"price": "0.004", "size": "11.33"}, {"price": "0.01", "size": "9080"}, {"price": "0.011", "size": "5.73"}, {"price": "0.02", "size": "3750"}, {"price": "0.021", "size": "11.16"}, {"price": "0.04", "size": "250"}, {"price": "0.05", "size": "30"}, {"price": "0.051", "size": "39"}, {"price": "0.06", "size": "1100"}, {"price": "0.061", "size": "10.33"}, {"price": "0.1", "size": "360"}, {"price": "0.15", "size": "876.66"}, {"price": "0.2", "size": "610"}, {"price": "0.201", "size": "5.01"}, {"price": "0.25", "size": "312"}, {"price": "0.3", "size": "136.66"}, {"price": "0.302", "size": "821"}, {"price": "0.303", "size": "211.28"}, {"price": "0.34", "size": "50"}, {"price": "0.35", "size": "68.57"}, {"price": "0.351", "size": "34"}, {"price": "0.4", "size": "50"}, {"price": "0.401", "size": "66.66"}, {"price": "0.451", "size": "172"}, {"price": "0.452", "size": "5"}, {"price": "0.67", "size": "66.66"}, {"price": "0.729", "size": "13.33"}, {"price": "0.733", "size": "10"}, {"price": "0.735", "size": "30"}, {"price": "0.736", "size": "40"}, {"price": "0.737", "size": "20"}, {"price": "0.9", "size": "5"}, {"price": "0.93", "size": "50"}, {"price": "0.939", "size": "116.66"}, {"price": "0.94", "size": "40.06"}], "asks": [{"price": "0.999", "size": "10886.99"}, {"price": "0.998", "size": "676.11"}, {"price": "0.997", "size": "12.86"}, {"price": "0.996", "size": "12.4"}, {"price": "0.995", "size": "134.04"}, {"price": "0.994", "size": "67"}, {"price": "0.993", "size": "11.18"}, {"price": "0.988", "size": "52.93"}, {"price": "0.987", "size": "18.4"}, {"price": "0.986", "size": "50.51"}], "event_type": "book", "last_trade_price": "0.013"}, {"market": "0x5b782c35d9cbd6e9d38597bd0af4e53d3263bde143e4d4ffdbd76d0a094f4be4", "asset_id": "111803189967461986329215432128898000701874058405628301712422758141213653452479", "timestamp": "1769383994965", "hash": "fa15dd7da1a36ef6fca23a49a0d754dc22936741", "bids": [{"price": "0.01", "size": "115"}, {"price": "0.03", "size": "290"}, {"price": "0.04", "size": "500"}, {"price": "0.06", "size": "10"}, {"price": "0.08", "size": "1891.31"}], "asks": [{"price": "0.99", "size": "8792.93"}, {"price": "0.98", "size": "3750"}, {"price": "0.97", "size": "7.87"}, {"price": "0.96", "size": "250"}, {"price": "0.95", "size": "30"}, {"price": "0.94", "size": "33"}, {"price": "0.93", "size": "7.97"}, {"price": "0.91", "size": "1400"}, {"price": "0.86", "size": "792.85"}, {"price": "0.82", "size": "677.77"}, {"price": "0.81", "size": "5.66"}, {"price": "0.77", "size": "271.73"}, {"price": "0.72", "size": "342.85"}, {"price": "0.71", "size": "171"}, {"price": "0.68", "size": "75"}, {"price": "0.67", "size": "65"}, {"price": "0.66", "size": "50"}, {"price": "0.63", "size": "54.05"}, {"price": "0.62", "size": "5"}, {"price": "0.53", "size": "212"}, {"price": "0.52", "size": "170"}, {"price": "0.31", "size": "100"}, {"price": "0.3", "size": "20"}, {"price": "0.22", "size": "30"}, {"price": "0.21", "size": "40"}, {"price": "0.2", "size": "8.75"}, {"price": "0.18", "size": "57"}, {"price": "0.17", "size": "36.39"}, {"price": "0.15", "size": "23"}, {"price": "0.09", "size": "10.64"}], "event_type": "book", "last_trade_price": "0.080"}, {"market": "0x0be3d4cc20250a7105206bc352af8b1c087df2ebd4f3b3927fabcdd8c81d792e", "asset_id": "87528913053522501048749446605646222127999765893905568199883777953288580503567", "timestamp": "1769383979959", "hash": "0fe1bcdae1de5dc5eb62542e858691738b7d7997", "bids": [{"price": "0.01", "size": "8793.7"}, {"price": "0.02", "size": "3750"}, {"price": "0.03", "size": "10.28"}, {"price": "0.04", "size": "250"}, {"price": "0.05", "size": "10"}, {"price": "0.07", "size": "1914.28"}, {"price": "0.08", "size": "6.16"}, {"price": "0.1", "size": "340"}, {"price": "0.13", "size": "550"}, {"price": "0.14", "size": "228.57"}, {"price": "0.17", "size": "664.7"}, {"price": "0.18", "size": "5.89"}, {"price": "0.21", "size": "608.8"}, {"price": "0.24", "size": "100"}, {"price": "0.26", "size": "100"}, {"price": "0.27", "size": "196"}, {"price": "0.28", "size": "71.42"}, {"price": "0.29", "size": "35"}, {"price": "0.3", "size": "6"}, {"price": "0.47", "size": "100"}, {"price": "0.49", "size": "10"}, {"price": "0.51", "size": "40"}, {"price": "0.52", "size": "30"}, {"price": "0.53", "size": "20"}, {"price": "0.57", "size": "73"}, {"price": "0.64", "size": "26.72"}, {"price": "0.65", "size": "40"}], "asks": [{"price": "0.99", "size": "5535.4"}, {"price": "0.97", "size": "1200"}, {"price": "0.96", "size": "8.65"}, {"price": "0.95", "size": "3280"}, {"price": "0.93", "size": "457.14"}, {"price": "0.92", "size": "228"}, {"price": "0.91", "size": "311.11"}, {"price": "0.89", "size": "236.36"}, {"price": "0.88", "size": "200"}, {"price": "0.86", "size": "242.85"}, {"price": "0.73", "size": "50"}, {"price": "0.71", "size": "500"}, {"price": "0.7", "size": "457.49"}, {"price": "0.69", "size": "57.49"}, {"price": "0.67", "size": "69.15"}], "event_type": "book", "last_trade_price": "0.640"}, {"market": "0x46e08dad4b1370947613b81f2ba28a23226504a333ec7e42de877d6ba6cc59d0", "asset_id": "85467679028197532287128360159828743243379157810773026071193309107969652317045", "timestamp": "1769383979825", "hash": "a52cc2d54b042d916eafff45b081c6188d1050f2", "bids": [{"price": "0.001", "size": "4533.59"}, {"price": "0.002", "size": "1256.56"}, {"price": "0.003", "size": "1400"}, {"price": "0.004", "size": "11.34"}, {"price": "0.006", "size": "200"}, {"price": "0.01", "size": "9080"}, {"price": "0.011", "size": "5.74"}, {"price": "0.02", "size": "3750"}, {"price": "0.021", "size": "11.16"}, {"price": "0.04", "size": "250"}, {"price": "0.05", "size": "30"}, {"price": "0.051", "size": "39"}, {"price": "0.06", "size": "1100"}, {"price": "0.061", "size": "9.79"}, {"price": "0.1", "size": "360"}, {"price": "0.15", "size": "876.66"}, {"price": "0.19", "size": "568.42"}, {"price": "0.191", "size": "234"}, {"price": "0.192", "size": "5.41"}, {"price": "0.24", "size": "416.66"}, {"price": "0.29", "size": "189.65"}, {"price": "0.34", "size": "70.58"}, {"price": "0.39", "size": "51.28"}, {"price": "0.4", "size": "500"}, {"price": "0.504", "size": "5"}, {"price": "0.521", "size": "567"}, {"price": "0.522", "size": "191"}, {"price": "0.532", "size": "10"}, {"price": "0.534", "size": "25"}, {"price": "0.536", "size": "30"}, {"price": "0.537", "size": "40"}, {"price": "0.538", "size": "20"}, {"price": "0.936", "size": "358.22"}, {"price": "0.94", "size": "10"}, {"price": "0.945", "size": "10"}, {"price": "0.948", "size": "486.33"}, {"price": "0.958", "size": "66.1"}], "asks": [{"price": "0.999", "size": "12070"}, {"price": "0.998", "size": "256.19"}, {"price": "0.997", "size": "12.26"}, {"price": "0.995", "size": "432.16"}, {"price": "0.994", "size": "10.01"}, {"price": "0.993", "size": "786.73"}, {"price": "0.99", "size": "30"}, {"price": "0.989", "size": "11.54"}, {"price": "0.979", "size": "4877.19"}, {"price": "0.978", "size": "5.94"}, {"price": "0.977", "size": "500"}, {"price": "0.965", "size": "365.33"}, {"price": "0.964", "size": "249"}], "event_type": "book", "last_trade_price": "0.042"}, {"market": "0x9cacc164f8e79d815cc6714b0e5a04055f3bd5f6d05dc25f4265e7ffaa08dadc", "asset_id": "75665317756971232401732022054678279748154632967705732846841215435558615055352", "timestamp": "1769383694005", "hash": "dfd8b99d94a28e2c2f92aa9850a04310d9e63d63", "bids": [{"price": "0.01", "size": "39.84"}, {"price": "0.02", "size": "15.07"}, {"price": "0.05", "size": "720"}, {"price": "0.07", "size": "485.71"}, {"price": "0.1", "size": "320"}, {"price": "0.12", "size": "458.33"}, {"price": "0.14", "size": "185.71"}, {"price": "0.17", "size": "141.17"}, {"price": "0.19", "size": "455.26"}, {"price": "0.2", "size": "227"}, {"price": "0.23", "size": "5"}, {"price": "0.33", "size": "3.36"}, {"price": "0.45", "size": "99"}], "asks": [{"price": "0.99", "size": "9087.5"}, {"price": "0.98", "size": "3760.6"}, {"price": "0.96", "size": "250"}, {"price": "0.95", "size": "15.08"}, {"price": "0.92", "size": "700"}, {"price": "0.91", "size": "5.24"}, {"price": "0.89", "size": "550"}, {"price": "0.83", "size": "1500"}, {"price": "0.82", "size": "255.48"}, {"price": "0.81", "size": "10"}, {"price": "0.77", "size": "200"}, {"price": "0.61", "size": "445"}, {"price": "0.6", "size": "10"}, {"price": "0.59", "size": "50"}, {"price": "0.58", "size": "40"}, {"price": "0.55", "size": "39"}, {"price": "0.51", "size": "555"}, {"price": "0.49", "size": "833"}, {"price": "0.48", "size": "400"}], "event_type": "book", "last_trade_price": "0.510"}]}
{"_local_timestamp": "2026-01-25T23:33:36.079199+00:00", "data": {"market": "0x5b782c35d9cbd6e9d38597bd0af4e53d3263bde143e4d4ffdbd76d0a094f4be4", "price_changes": [{"asset_id": "111803189967461986329215432128898000701874058405628301712422758141213653452479", "price": "0.03", "size": "270", "side": "BUY", "hash": "041c730bf5dab5781d20777cadfbbd71632019ab", "best_bid": "0.08", "best_ask": "0.09"}, {"asset_id": "48123308101524452666134421526726361469113858451786831367632481270457773825485", "price": "0.97", "size": "270", "side": "SELL", "hash": "c926f5eb4dd0373a2add669a0cd02919eed3cee5", "best_bid": "0.91", "best_ask": "0.92"}], "timestamp": "1769384016001", "event_type": "price_change"}}
{"_local_timestamp": "2026-01-25T23:33:36.165237+00:00", "data": {"market": "0x46e08dad4b1370947613b81f2ba28a23226504a333ec7e42de877d6ba6cc59d0", "price_changes": [{"asset_id": "85467679028197532287128360159828743243379157810773026071193309107969652317045", "price": "0.534", "size": "15", "side": "BUY", "hash": "77d32c48e344a74bd44008047d4b36e6f5e2cd26", "best_bid": "0.958", "best_ask": "0.964"}, {"asset_id": "113369140136913812777925497644561662667789653912765877043929720445901767848122", "price": "0.466", "size": "15", "side": "SELL", "hash": "fe87564b45907e01a55fee2c5f5f9001da662329", "best_bid": "0.036", "best_ask": "0.042"}], "timestamp": "1769384016082", "event_type": "price_change"}}
{"_local_timestamp": "2026-01-25T23:33:38.081391+00:00", "data": {"market": "0x5b782c35d9cbd6e9d38597bd0af4e53d3263bde143e4d4ffdbd76d0a094f4be4", "price_changes": [{"asset_id": "48123308101524452666134421526726361469113858451786831367632481270457773825485", "price": "0.82", "size": "37", "side": "BUY", "hash": "c660774f35521478514e451e5686c467bde8cb46", "best_bid": "0.91", "best_ask": "0.92"}, {"asset_id": "111803189967461986329215432128898000701874058405628301712422758141213653452479", "price": "0.18", "size": "37", "side": "SELL", "hash": "1db298ab5621580f2e9de9cef8d56a04cc7f8ad5", "best_bid": "0.08", "best_ask": "0.09"}], "timestamp": "1769384018000", "event_type": "price_change"}}
{"_local_timestamp": "2026-01-25T23:33:38.200020+00:00", "data": {"market": "0x46e08dad4b1370947613b81f2ba28a23226504a333ec7e42de877d6ba6cc59d0", "price_changes": [{"asset_id": "85467679028197532287128360159828743243379157810773026071193309107969652317045", "price": "0.534", "size": "0", "side": "BUY", "hash": "6be350e1817c50372388f12fdf299bfe85df65ba", "best_bid": "0.958", "best_ask": "0.964"}, {"asset_id": "113369140136913812777925497644561662667789653912765877043929720445901767848122", "price": "0.466", "size": "0", "side": "SELL", "hash": "fc409c6feba11918f83fdf10533d03c963e9e3d1", "best_bid": "0.036", "best_ask": "0.042"}], "timestamp": "1769384018124", "event_type": "price_change"}}
{"_local_timestamp": "2026-01-25T23:33:39.478187+00:00", "data": {"market": "0x5b782c35d9cbd6e9d38597bd0af4e53d3263bde143e4d4ffdbd76d0a094f4be4", "price_changes": [{"asset_id": "111803189967461986329215432128898000701874058405628301712422758141213653452479", "price": "0.17", "size": "7.15", "side": "SELL", "hash": "5b2e4148df974605fb7e4279a72710666d7b1170", "best_bid": "0.08", "best_ask": "0.09"}, {"asset_id": "48123308101524452666134421526726361469113858451786831367632481270457773825485", "price": "0.83", "size": "7.15", "side": "BUY", "hash": "1f4418adbb8a3fb3f38124aba54231e099c2f69a", "best_bid": "0.91", "best_ask": "0.92"}], "timestamp": "1769384019404", "event_type": "price_change"}}
{"_local_timestamp": "2026-01-25T23:33:39.523102+00:00", "data": {"market": "0x5b782c35d9cbd6e9d38597bd0af4e53d3263bde143e4d4ffdbd76d0a094f4be4", "price_changes": [{"asset_id": "111803189967461986329215432128898000701874058405628301712422758141213653452479", "price": "0.3", "size": "49.24", "side": "SELL", "hash": "04e10ffe062c54a19c51fe827b43ab60675803fc", "best_bid": "0.08", "best_ask": "0.09"}, {"asset_id": "48123308101524452666134421526726361469113858451786831367632481270457773825485", "price": "0.7", "size": "49.24", "side": "BUY", "hash": "f9313bfa083fd55ed68e4dda4bd487a73f0a1731", "best_bid": "0.91", "best_ask": "0.92"}], "timestamp": "1769384019455", "event_type": "price_change"}}
{"_local_timestamp": "2026-01-25T23:33:40.039964+00:00", "data": {"market": "0x5b782c35d9cbd6e9d38597bd0af4e53d3263bde143e4d4ffdbd76d0a094f4be4", "price_changes": [{"asset_id": "48123308101524452666134421526726361469113858451786831367632481270457773825485", "price": "0.82", "size": "57", "side": "BUY", "hash": "a52ea35166b162075d8cb10a38a124f4837793a6", "best_bid": "0.91", "best_ask": "0.92"}, {"asset_id": "111803189967461986329215432128898000701874058405628301712422758141213653452479", "price": "0.18", "size": "57", "side": "SELL", "hash": "91a9e23ca9f7b2e990dd186bd7afe031e6eb0bcf", "best_bid": "0.08", "best_ask": "0.09"}], "timestamp": "1769384019962", "event_type": "price_change"}}
{"_local_timestamp": "2026-01-25T23:33:40.060854+00:00", "data": {"market": "0x5b782c35d9cbd6e9d38597bd0af4e53d3263bde143e4d4ffdbd76d0a094f4be4", "price_changes": [{"asset_id": "111803189967461986329215432128898000701874058405628301712422758141213653452479", "price": "0.03", "size": "290", "side": "BUY", "hash": "eb23958e023972084d4e071f850d3a9ae5830c39", "best_bid": "0.08", "best_ask": "0.09"}, {"asset_id": "48123308101524452666134421526726361469113858451786831367632481270457773825485", "price": "0.97", "size": "290", "side": "SELL", "hash": "54050791938188fac51fa01fd91c2c1b4bbb88c6", "best_bid": "0.91", "best_ask": "0.92"}], "timestamp": "1769384019982", "event_type": "price_change"}}
{"_local_timestamp": "2026-01-25T23:33:40.484461+00:00", "data": {"market": "0x5b782c35d9cbd6e9d38597bd0af4e53d3263bde143e4d4ffdbd76d0a094f4be4", "price_changes": [{"asset_id": "111803189967461986329215432128898000701874058405628301712422758141213653452479", "price": "0.3", "size": "20", "side": "SELL", "hash": "24f7dc599211ed730f362f55892c1f1932e10c95", "best_bid": "0.08", "best_ask": "0.09"}, {"asset_id": "48123308101524452666134421526726361469113858451786831367632481270457773825485", "price": "0.7", "size": "20", "side": "BUY", "hash": "fc4f2a051c4b9028742ae0670f659ddc0f161956", "best_bid": "0.91", "best_ask": "0.92"}], "timestamp": "1769384020381", "event_type": "price_change"}}
{"_local_timestamp": "2026-01-25T23:33:40.528853+00:00", "data": {"market": "0x5b782c35d9cbd6e9d38597bd0af4e53d3263bde143e4d4ffdbd76d0a094f4be4", "price_changes": [{"asset_id": "111803189967461986329215432128898000701874058405628301712422758141213653452479", "price": "0.17", "size": "36.39", "side": "SELL", "hash": "3605f4773f273249315096428abd9fd325ab7a08", "best_bid": "0.08", "best_ask": "0.09"}, {"asset_id": "48123308101524452666134421526726361469113858451786831367632481270457773825485", "price": "0.83", "size": "36.39", "side": "BUY", "hash": "323cb6de7a238dcc33e09c62b2dd75108897a05b", "best_bid": "0.91", "best_ask": "0.92"}], "timestamp": "1769384020455", "event_type": "price_change"}}
{"_local_timestamp": "2026-01-25T23:33:48.793798+00:00", "data": {"market": "0x44f67876759c44b763bb53f89b3c738756331b0a208672fc8db8a5f389230950", "price_changes": [{"asset_id": "1582298976410585403069729422280265608038484032857579102122167925665102997608", "price": "0.004", "size": "0", "side": "BUY", "hash": "61be3dbb6b327ac6787fbdd9f5ed278e9a3dc6a2", "best_bid": "0.014", "best_ask": "0.06"}, {"asset_id": "32592218374784909301050372254273467546998719384564620545871759434640468645973", "price": "0.996", "size": "0", "side": "SELL", "hash": "d518407ef0dac52a9c7d64aeb28e13893d4bcbb9", "best_bid": "0.94", "best_ask": "0.986"}], "timestamp": "1769384028731", "event_type": "price_change"}}
{"_local_timestamp": "2026-01-25T23:33:48.939860+00:00", "data": {"market": "0x46e08dad4b1370947613b81f2ba28a23226504a333ec7e42de877d6ba6cc59d0", "price_changes": [{"asset_id": "85467679028197532287128360159828743243379157810773026071193309107969652317045", "price": "0.532", "size": "0", "side": "BUY", "hash": "e1e32a97a3e940a64ebf642cf154dc10236c3796", "best_bid": "0.958", "best_ask": "0.964"}, {"asset_id": "113369140136913812777925497644561662667789653912765877043929720445901767848122", "price": "0.468", "size": "0", "side": "SELL", "hash": "b54288b6329f116e427f6e796e62cbe91805e5ef", "best_bid": "0.036", "best_ask": "0.042"}], "timestamp": "1769384028865", "event_type": "price_change"}}
{"_local_timestamp": "2026-01-25T23:33:48.994409+00:00", "data": {"market": "0x46e08dad4b1370947613b81f2ba28a23226504a333ec7e42de877d6ba6cc59d0", "price_changes": [{"asset_id": "85467679028197532287128360159828743243379157810773026071193309107969652317045", "price": "0.539", "size": "10", "side": "BUY", "hash": "b3524126f83f4abd0def027cdd47e64121a3d64f", "best_bid": "0.958", "best_ask": "0.964"}, {"asset_id": "113369140136913812777925497644561662667789653912765877043929720445901767848122", "price": "0.461", "size": "10", "side": "SELL", "hash": "fcd73b07b875f4fb1f42fcbe9f306169624373b4", "best_bid": "0.036", "best_ask": "0.042"}], "timestamp": "1769384028929", "event_type": "price_change"}}
{"_local_timestamp": "2026-01-25T23:33:48.998386+00:00", "data": {"market": "0x46e08dad4b1370947613b81f2ba28a23226504a333ec7e42de877d6ba6cc59d0", "price_changes": [{"asset_id": "85467679028197532287128360159828743243379157810773026071193309107969652317045", "price": "0.539", "size": "349", "side": "BUY", "hash": "d0efaf1c2aafd25a845efc05675606367fb47b9e", "best_bid": "0.958", "best_ask": "0.964"}, {"asset_id": "113369140136913812777925497644561662667789653912765877043929720445901767848122", "price": "0.461", "size": "349", "side": "SELL", "hash": "38ecd359a6af6e366fb52745ef04a40fd2209f28", "best_bid": "0.036", "best_ask": "0.042"}], "timestamp": "1769384028930", "event_type": "price_change"}}
{"_local_timestamp": "2026-01-25T23:33:49.109932+00:00", "data": {"market": "0x44f67876759c44b763bb53f89b3c738756331b0a208672fc8db8a5f389230950", "price_changes": [{"asset_id": "1582298976410585403069729422280265608038484032857579102122167925665102997608", "price": "0.003", "size": "29.39", "side": "BUY", "hash": "07a07e32bb389af5669de5e2a1898f3e17e75c23", "best_bid": "0.014", "best_ask": "0.06"}, {"asset_id": "32592218374784909301050372254273467546998719384564620545871759434640468645973", "price": "0.997", "size": "29.39", "side": "SELL", "hash": "78b1de42a61d6d2aa3f7d1d79afd6cd167540524", "best_bid": "0.94", "best_ask": "0.986"}], "timestamp": "1769384029011", "event_type": "price_change"}}
{"_local_timestamp": "2026-01-25T23:33:49.115293+00:00", "data": {"market": "0x46e08dad4b1370947613b81f2ba28a23226504a333ec7e42de877d6ba6cc59d0", "price_changes": [{"asset_id": "85467679028197532287128360159828743243379157810773026071193309107969652317045", "price": "0.521", "size": "184", "side": "BUY", "hash": "e4bdd0a66d3d76f5ada358a4630b2b5a45bbfa08", "best_bid": "0.958", "best_ask": "0.964"}, {"asset_id": "113369140136913812777925497644561662667789653912765877043929720445901767848122", "price": "0.479", "size": "184", "side": "SELL", "hash": "0502e2ff2771c3dc3af99a5773c6c49d8d865106", "best_bid": "0.036", "best_ask": "0.042"}], "timestamp": "1769384029015", "event_type": "price_change"}}
{"_local_timestamp": "2026-01-25T23:33:49.247158+00:00", "data": {"market": "0x46e08dad4b1370947613b81f2ba28a23226504a333ec7e42de877d6ba6cc59d0", "price_changes": [{"asset_id": "85467679028197532287128360159828743243379157810773026071193309107969652317045", "price": "0.539", "size": "720", "side": "BUY", "hash": "52fc291459739ba699f7556520cb20979d798f3b", "best_bid": "0.958", "best_ask": "0.964"}, {"asset_id": "113369140136913812777925497644561662667789653912765877043929720445901767848122", "price": "0.461", "size": "720", "side": "SELL", "hash": "8bb8e4a897a66b8245f7944dc24166cb184ef506", "best_bid": "0.036", "best_ask": "0.042"}], "timestamp": "1769384029177", "event_type": "price_change"}}
{"_local_timestamp": "2026-01-25T23:33:49.362606+00:00", "data": {"market": "0x46e08dad4b1370947613b81f2ba28a23226504a333ec7e42de877d6ba6cc59d0", "price_changes": [{"asset_id": "85467679028197532287128360159828743243379157810773026071193309107969652317045", "price": "0.521", "size": "0", "side": "BUY", "hash": "25152c386f9958bde82764d175cc7df4735a645b", "best_bid": "0.958", "best_ask": "0.964"}, {"asset_id": "113369140136913812777925497644561662667789653912765877043929720445901767848122", "price": "0.479", "size": "0", "side": "SELL", "hash": "0b0092492b83d9269c37384bc2a4b417df820e9b", "best_bid": "0.036", "best_ask": "0.042"}], "timestamp": "1769384029292", "event_type": "price_change"}}
{"_local_timestamp": "2026-01-25T23:33:49.426336+00:00", "data": {"market": "0x46e08dad4b1370947613b81f2ba28a23226504a333ec7e42de877d6ba6cc59d0", "price_changes": [{"asset_id": "85467679028197532287128360159828743243379157810773026071193309107969652317045", "price": "0.522", "size": "0", "side": "BUY", "hash": "b2d74de2dd9f458b5109318e3aff265fc92b5750", "best_bid": "0.958", "best_ask": "0.964"}, {"asset_id": "113369140136913812777925497644561662667789653912765877043929720445901767848122", "price": "0.478", "size": "0", "side": "SELL", "hash": "0115be5cc134abe45a386a89f35f40874e77e3e0", "best_bid": "0.036", "best_ask": "0.042"}], "timestamp": "1769384029352", "event_type": "price_change"}}
{"_local_timestamp": "2026-01-25T23:33:49.437845+00:00", "data": {"market": "0x46e08dad4b1370947613b81f2ba28a23226504a333ec7e42de877d6ba6cc59d0", "price_changes": [{"asset_id": "85467679028197532287128360159828743243379157810773026071193309107969652317045", "price": "0.539", "size": "381", "side": "BUY", "hash": "4500bca5a4e8922ec12345811d578d1f56efec54", "best_bid": "0.958", "best_ask": "0.964"}, {"asset_id": "113369140136913812777925497644561662667789653912765877043929720445901767848122", "price": "0.461", "size": "381", "side": "SELL", "hash": "cabaf2a36aec11c44d095cd09464de47ed7a8d74", "best_bid": "0.036", "best_ask": "0.042"}], "timestamp": "1769384029372", "event_type": "price_change"}}
{"_local_timestamp": "2026-01-25T23:33:49.611841+00:00", "data": {"market": "0x46e08dad4b1370947613b81f2ba28a23226504a333ec7e42de877d6ba6cc59d0", "price_changes": [{"asset_id": "85467679028197532287128360159828743243379157810773026071193309107969652317045", "price": "0.54", "size": "10", "side": "BUY", "hash": "f15687207a1967fcf0942554e35ef67068e40cfe", "best_bid": "0.958", "best_ask": "0.964"}, {"asset_id": "113369140136913812777925497644561662667789653912765877043929720445901767848122", "price": "0.46", "size": "10", "side": "SELL", "hash": "b1fbf0e8b6758da2a4bf058c685ee36f395e5adc", "best_bid": "0.036", "best_ask": "0.042"}], "timestamp": "1769384029547", "event_type": "price_change"}}
{"_local_timestamp": "2026-01-25T23:33:49.612437+00:00", "data": {"market": "0x46e08dad4b1370947613b81f2ba28a23226504a333ec7e42de877d6ba6cc59d0", "price_changes": [{"asset_id": "85467679028197532287128360159828743243379157810773026071193309107969652317045", "price": "0.54", "size": "195", "side": "BUY", "hash": "5435207e157a12b2ce5c295586887411b7fc15ff", "best_bid": "0.958", "best_ask": "0.964"}, {"asset_id": "113369140136913812777925497644561662667789653912765877043929720445901767848122", "price": "0.46", "size": "195", "side": "SELL", "hash": "b377c1bf1d8dcae62c5781c06316df1e07467c95", "best_bid": "0.036", "best_ask": "0.042"}], "timestamp": "1769384029548", "event_type": "price_change"}}
{"_local_timestamp": "2026-01-25T23:33:49.615528+00:00", "data": {"market": "0x46e08dad4b1370947613b81f2ba28a23226504a333ec7e42de877d6ba6cc59d0", "price_changes": [{"asset_id": "85467679028197532287128360159828743243379157810773026071193309107969652317045", "price": "0.54", "size": "210", "side": "BUY", "hash": "617396af91e76bfeca67e0479daf0c64c4f7c12d", "best_bid": "0.958", "best_ask": "0.964"}, {"asset_id": "113369140136913812777925497644561662667789653912765877043929720445901767848122", "price": "0.46", "size": "210", "side": "SELL", "hash": "00a3f6640963607f8274cfcaba51bf92f25b7abc", "best_bid": "0.036", "best_ask": "0.042"}], "timestamp": "1769384029549", "event_type": "price_change"}}
{"_local_timestamp": "2026-01-25T23:33:49.619855+00:00", "data": {"market": "0x46e08dad4b1370947613b81f2ba28a23226504a333ec7e42de877d6ba6cc59d0", "price_changes": [{"asset_id": "85467679028197532287128360159828743243379157810773026071193309107969652317045", "price": "0.54", "size": "580", "side": "BUY", "hash": "cb659abdb9f00905335b33e9c34643434d6d373d", "best_bid": "0.958", "best_ask": "0.964"}, {"asset_id": "113369140136913812777925497644561662667789653912765877043929720445901767848122", "price": "0.46", "size": "580", "side": "SELL", "hash": "329322b1e6e56d7c7de8c3376ecdf478c440c212", "best_bid": "0.036", "best_ask": "0.042"}], "timestamp": "1769384029552", "event_type": "price_change"}}
{"_local_timestamp": "2026-01-25T23:33:50.162217+00:00", "data": {"market": "0x46e08dad4b1370947613b81f2ba28a23226504a333ec7e42de877d6ba6cc59d0", "price_changes": [{"asset_id": "85467679028197532287128360159828743243379157810773026071193309107969652317045", "price": "0.538", "size": "0", "side": "BUY", "hash": "08343d1969261f7e414d5e71048e760e964dda2d", "best_bid": "0.958", "best_ask": "0.964"}, {"asset_id": "113369140136913812777925497644561662667789653912765877043929720445901767848122", "price": "0.462", "size": "0", "side": "SELL", "hash": "9f3d6ce147ad1366419d3d98743eda09e25eb06a", "best_bid": "0.036", "best_ask": "0.042"}], "timestamp": "1769384030095", "event_type": "price_change"}}
{"_local_timestamp": "2026-01-25T23:33:50.193338+00:00", "data": {"market": "0x46e08dad4b1370947613b81f2ba28a23226504a333ec7e42de877d6ba6cc59d0", "price_changes": [{"asset_id": "85467679028197532287128360159828743243379157810773026071193309107969652317045", "price": "0.541", "size": "20", "side": "BUY", "hash": "12666f55afc5d055f8843bb246683ac533013f99", "best_bid": "0.958", "best_ask": "0.964"}, {"asset_id": "113369140136913812777925497644561662667789653912765877043929720445901767848122", "price": "0.459", "size": "20", "side": "SELL", "hash": "cb09325803346a118ce6d2f8c1bf5a6a0a5b7e98", "best_bid": "0.036", "best_ask": "0.042"}], "timestamp": "1769384030126", "event_type": "price_change"}}
{"_local_timestamp": "2026-01-25T23:34:04.163002+00:00", "data": {"market": "0x46e08dad4b1370947613b81f2ba28a23226504a333ec7e42de877d6ba6cc59d0", "price_changes": [{"asset_id": "85467679028197532287128360159828743243379157810773026071193309107969652317045", "price": "0.504", "size": "0", "side": "BUY", "hash": "d71404642687c220a38fa24eb76999646b0a8e41", "best_bid": "0.958", "best_ask": "0.964"}, {"asset_id": "113369140136913812777925497644561662667789653912765877043929720445901767848122", "price": "0.496", "size": "0", "side": "SELL", "hash": "4cd4e95ff85db173b3fb10c74fd4fc9c752b70c7", "best_bid": "0.036", "best_ask": "0.042"}], "timestamp": "1769384043938", "event_type": "price_change"}}
{"_local_timestamp": "2026-01-25T23:34:04.209189+00:00", "data": {"market": "0x46e08dad4b1370947613b81f2ba28a23226504a333ec7e42de877d6ba6cc59d0", "price_changes": [{"asset_id": "85467679028197532287128360159828743243379157810773026071193309107969652317045", "price": "0.542", "size": "5", "side": "BUY", "hash": "e10379b0b38eb0cc4f6978acf635e6d754660b58", "best_bid": "0.958", "best_ask": "0.964"}, {"asset_id": "113369140136913812777925497644561662667789653912765877043929720445901767848122", "price": "0.458", "size": "5", "side": "SELL", "hash": "d2794388f5748a177804da0b7182a77052a31168", "best_bid": "0.036", "best_ask": "0.042"}], "timestamp": "1769384043984", "event_type": "price_change"}}
{"_local_timestamp": "2026-01-25T23:34:28.661043+00:00", "data": {"market": "0x5b782c35d9cbd6e9d38597bd0af4e53d3263bde143e4d4ffdbd76d0a094f4be4", "price_changes": [{"asset_id": "48123308101524452666134421526726361469113858451786831367632481270457773825485", "price": "0.37", "size": "129.05", "side": "BUY", "hash": "00a9aea84b3991f749c99e1560065685d2e297bc", "best_bid": "0.91", "best_ask": "0.92"}, {"asset_id": "111803189967461986329215432128898000701874058405628301712422758141213653452479", "price": "0.63", "size": "129.05", "side": "SELL", "hash": "cdce70e79b9142838326312dbb4d5e7d414ac37d", "best_bid": "0.08", "best_ask": "0.09"}], "timestamp": "1769384068133", "event_type": "price_change"}}
{"_local_timestamp": "2026-01-25T23:34:47.083167+00:00", "data": {"market": "0x9cacc164f8e79d815cc6714b0e5a04055f3bd5f6d05dc25f4265e7ffaa08dadc", "price_changes": [{"asset_id": "58983570136035430006949575067833187006601843982035390064418024195691336080349", "price": "0.45", "size": "19", "side": "BUY", "hash": "0534e19ac065d933b4fe46d9a8b242052fb064b2", "best_bid": "0.52", "best_ask": "0.55"}, {"asset_id": "75665317756971232401732022054678279748154632967705732846841215435558615055352", "price": "0.55", "size": "19", "side": "SELL", "hash": "5a41825620d8fe4e60ab09e1c00dab840a7dcbc5", "best_bid": "0.45", "best_ask": "0.48"}], "timestamp": "1769384087000", "event_type": "price_change"}}
{"_local_timestamp": "2026-01-25T23:34:50.080304+00:00", "data": {"market": "0x9cacc164f8e79d815cc6714b0e5a04055f3bd5f6d05dc25f4265e7ffaa08dadc", "price_changes": [{"asset_id": "58983570136035430006949575067833187006601843982035390064418024195691336080349", "price": "0.45", "size": "39", "side": "BUY", "hash": "8d250d2978ff36fe1d70f6fbfd479b4ee123732d", "best_bid": "0.52", "best_ask": "0.55"}, {"asset_id": "75665317756971232401732022054678279748154632967705732846841215435558615055352", "price": "0.55", "size": "39", "side": "SELL", "hash": "06ac64389dc2a3cdf7e3e3c5088c88048bb18d4e", "best_bid": "0.45", "best_ask": "0.48"}], "timestamp": "1769384089958", "event_type": "price_change"}}
{"_local_timestamp": "2026-01-25T23:35:02.062253+00:00", "data": {"market": "0x44f67876759c44b763bb53f89b3c738756331b0a208672fc8db8a5f389230950", "price_changes": [{"asset_id": "32592218374784909301050372254273467546998719384564620545871759434640468645973", "price": "0.67", "size": "0", "side": "BUY", "hash": "faabff7c78453fc31305f1b91900cc55abd30600", "best_bid": "0.94", "best_ask": "0.986"}, {"asset_id": "1582298976410585403069729422280265608038484032857579102122167925665102997608", "price": "0.33", "size": "0", "side": "SELL", "hash": "7d5a78de5b2c23b6652ee936e4c2277aaa6b4ef8", "best_bid": "0.014", "best_ask": "0.06"}], "timestamp": "1769384101990", "event_type": "price_change"}}
{"_local_timestamp": "2026-01-25T23:35:02.063646+00:00", "data": {"market": "0x44f67876759c44b763bb53f89b3c738756331b0a208672fc8db8a5f389230950", "price_changes": [{"asset_id": "32592218374784909301050372254273467546998719384564620545871759434640468645973", "price": "0.401", "size": "0", "side": "BUY", "hash": "faabff7c78453fc31305f1b91900cc55abd30600", "best_bid": "0.94", "best_ask": "0.986"}, {"asset_id": "1582298976410585403069729422280265608038484032857579102122167925665102997608", "price": "0.599", "size": "0", "side": "SELL", "hash": "7d5a78de5b2c23b6652ee936e4c2277aaa6b4ef8", "best_bid": "0.014", "best_ask": "0.06"}], "timestamp": "1769384101990", "event_type": "price_change"}}
{"_local_timestamp": "2026-01-25T23:35:02.637383+00:00", "data": {"market": "0x44f67876759c44b763bb53f89b3c738756331b0a208672fc8db8a5f389230950", "price_changes": [{"asset_id": "32592218374784909301050372254273467546998719384564620545871759434640468645973", "price": "0.645", "size": "66.66", "side": "BUY", "hash": "503fba531f7fe18aee406c461214c84197a6eba4", "best_bid": "0.94", "best_ask": "0.986"}, {"asset_id": "1582298976410585403069729422280265608038484032857579102122167925665102997608", "price": "0.355", "size": "66.66", "side": "SELL", "hash": "ed46e051aa62f8408222294698b00be8aa48126a", "best_bid": "0.014", "best_ask": "0.06"}], "timestamp": "1769384102570", "event_type": "price_change"}}
{"_local_timestamp": "2026-01-25T23:35:02.718127+00:00", "data": {"market": "0x44f67876759c44b763bb53f89b3c738756331b0a208672fc8db8a5f389230950", "price_changes": [{"asset_id": "32592218374784909301050372254273467546998719384564620545871759434640468645973", "price": "0.352", "size": "66.66", "side": "BUY", "hash": "7debed6a70a216af714dfee2b4b4380d19c29e20", "best_bid": "0.94", "best_ask": "0.986"}, {"asset_id": "1582298976410585403069729422280265608038484032857579102122167925665102997608", "price": "0.648", "size": "66.66", "side": "SELL", "hash": "c950dc69751ba9c5967a5f19a2d3bbbc4f7fec55", "best_bid": "0.014", "best_ask": "0.06"}], "timestamp": "1769384102648", "event_type": "price_change"}}
{"_local_timestamp": "2026-01-25T23:35:31.348905+00:00", "data": {"market": "0x46e08dad4b1370947613b81f2ba28a23226504a333ec7e42de877d6ba6cc59d0", "price_changes": [{"asset_id": "113369140136913812777925497644561662667789653912765877043929720445901767848122", "price": "0.036", "size": "0", "side": "BUY", "hash": "f3e7aedf18162fc3c75ed2fa8f02cf54e447b07f", "best_bid": "0.035", "best_ask": "0.042"}, {"asset_id": "85467679028197532287128360159828743243379157810773026071193309107969652317045", "price": "0.964", "size": "0", "side": "SELL", "hash": "54386a2f4c3f5c9a116bfedcfbc23810c6dff4bb", "best_bid": "0.958", "best_ask": "0.965"}], "timestamp": "1769384131242", "event_type": "price_change"}}
{"_local_timestamp": "2026-01-25T23:35:33.741184+00:00", "data": {"market": "0x9cacc164f8e79d815cc6714b0e5a04055f3bd5f6d05dc25f4265e7ffaa08dadc", "price_changes": [{"asset_id": "58983570136035430006949575067833187006601843982035390064418024195691336080349", "price": "0.41", "size": "30", "side": "BUY", "hash": "021521e294f9069393e84b1cdd3912faf234a876", "best_bid": "0.52", "best_ask": "0.55"}, {"asset_id": "75665317756971232401732022054678279748154632967705732846841215435558615055352", "price": "0.59", "size": "30", "side": "SELL", "hash": "47a3f4059300242962371657658674410123199f", "best_bid": "0.45", "best_ask": "0.48"}], "timestamp": "1769384133675", "event_type": "price_change"}}
{"_local_timestamp": "2026-01-25T23:35:33.741743+00:00", "data": {"market": "0x0be3d4cc20250a7105206bc352af8b1c087df2ebd4f3b3927fabcdd8c81d792e", "price_changes": [{"asset_id": "87528913053522501048749446605646222127999765893905568199883777953288580503567", "price": "0.53", "size": "0", "side": "BUY", "hash": "fac91ef23e31329b7798262949b92ea26d29b745", "best_bid": "0.65", "best_ask": "0.67"}, {"asset_id": "63149403073928211890844841868361708990331353150804831882114276975252031214656", "price": "0.47", "size": "0", "side": "SELL", "hash": "a57fb9306e1e36338a31c0be66d14a8b14388e11", "best_bid": "0.33", "best_ask": "0.35"}], "timestamp": "1769384133675", "event_type": "price_change"}}
{"_local_timestamp": "2026-01-25T23:35:33.773232+00:00", "data": {"market": "0x9cacc164f8e79d815cc6714b0e5a04055f3bd5f6d05dc25f4265e7ffaa08dadc", "price_changes": [{"asset_id": "58983570136035430006949575067833187006601843982035390064418024195691336080349", "price": "0.4", "size": "30", "side": "BUY", "hash": "3145a36f606b9203a34fa776c0113bb2b318ab12", "best_bid": "0.52", "best_ask": "0.55"}, {"asset_id": "75665317756971232401732022054678279748154632967705732846841215435558615055352", "price": "0.6", "size": "30", "side": "SELL", "hash": "50f0c3486ab8a834c5892ed84a89b6a62104a23e", "best_bid": "0.45", "best_ask": "0.48"}], "timestamp": "1769384133704", "event_type": "price_change"}}
{"_local_timestamp": "2026-01-25T23:35:33.773819+00:00", "data": {"market": "0x0be3d4cc20250a7105206bc352af8b1c087df2ebd4f3b3927fabcdd8c81d792e", "price_changes": [{"asset_id": "87528913053522501048749446605646222127999765893905568199883777953288580503567", "price": "0.52", "size": "50", "side": "BUY", "hash": "5271eb31f3cd5c331db865429dd910645957ac93", "best_bid": "0.65", "best_ask": "0.67"}, {"asset_id": "63149403073928211890844841868361708990331353150804831882114276975252031214656", "price": "0.48", "size": "50", "side": "SELL", "hash": "2c2695ddb2c9b7d6a72c6473564719621d2315d4", "best_bid": "0.33", "best_ask": "0.35"}], "timestamp": "1769384133704", "event_type": "price_change"}}
{"_local_timestamp": "2026-01-25T23:35:55.412313+00:00", "data": {"market": "0x5b782c35d9cbd6e9d38597bd0af4e53d3263bde143e4d4ffdbd76d0a094f4be4", "price_changes": [{"asset_id": "111803189967461986329215432128898000701874058405628301712422758141213653452479", "price": "0.02", "size": "20", "side": "BUY", "hash": "392c980246f2113836c80eb818e077e46b67fda9", "best_bid": "0.08", "best_ask": "0.09"}, {"asset_id": "48123308101524452666134421526726361469113858451786831367632481270457773825485", "price": "0.98", "size": "20", "side": "SELL", "hash": "20523900e42061ddc0866735b583352c12e558f9", "best_bid": "0.91", "best_ask": "0.92"}], "timestamp": "1769384155349", "event_type": "price_change"}}
{"_local_timestamp": "2026-01-25T23:36:16.671580+00:00", "data": {"market": "0x5b782c35d9cbd6e9d38597bd0af4e53d3263bde143e4d4ffdbd76d0a094f4be4", "price_changes": [{"asset_id": "111803189967461986329215432128898000701874058405628301712422758141213653452479", "price": "0.02", "size": "0", "side": "BUY", "hash": "0fe3f309dbce5a2587374328908c85292edf9738", "best_bid": "0.08", "best_ask": "0.09"}, {"asset_id": "48123308101524452666134421526726361469113858451786831367632481270457773825485", "price": "0.98", "size": "0", "side": "SELL", "hash": "99eb77471012fdec6cc33cacb8737e67b7618b93", "best_bid": "0.91", "best_ask": "0.92"}], "timestamp": "1769384176607", "event_type": "price_change"}}
{"_local_timestamp": "2026-01-25T23:36:34.055244+00:00", "data": {"market": "0x46e08dad4b1370947613b81f2ba28a23226504a333ec7e42de877d6ba6cc59d0", "price_changes": [{"asset_id": "113369140136913812777925497644561662667789653912765877043929720445901767848122", "price": "0.036", "size": "249", "side": "BUY", "hash": "5804ea4094f0b8a487ad8f7fb78fea6f23c69828", "best_bid": "0.036", "best_ask": "0.042"}, {"asset_id": "85467679028197532287128360159828743243379157810773026071193309107969652317045", "price": "0.964", "size": "249", "side": "SELL", "hash": "52bb17bbd8194bd474e0300f827e1830684358d7", "best_bid": "0.958", "best_ask": "0.964"}], "timestamp": "1769384193983", "event_type": "price_change"}}
{"_local_timestamp": "2026-01-25T23:36:35.650117+00:00", "data": {"market": "0x0be3d4cc20250a7105206bc352af8b1c087df2ebd4f3b3927fabcdd8c81d792e", "price_changes": [{"asset_id": "87528913053522501048749446605646222127999765893905568199883777953288580503567", "price": "0.52", "size": "30", "side": "BUY", "hash": "1c8fb3df4ec3a4f0ba7ae22c539064bf8c3f41fc", "best_bid": "0.65", "best_ask": "0.67"}, {"asset_id": "63149403073928211890844841868361708990331353150804831882114276975252031214656", "price": "0.48", "size": "30", "side": "SELL", "hash": "c3446e4a76bb0fae59433dc5ce55eb07c339c23a", "best_bid": "0.33", "best_ask": "0.35"}], "timestamp": "1769384195579", "event_type": "price_change"}}
{"_local_timestamp": "2026-01-25T23:36:35.651458+00:00", "data": {"market": "0x9cacc164f8e79d815cc6714b0e5a04055f3bd5f6d05dc25f4265e7ffaa08dadc", "price_changes": [{"asset_id": "58983570136035430006949575067833187006601843982035390064418024195691336080349", "price": "0.4", "size": "10", "side": "BUY", "hash": "a17e078ca4e284d9b3ea36e183abfad6b2b1f634", "best_bid": "0.52", "best_ask": "0.55"}, {"asset_id": "75665317756971232401732022054678279748154632967705732846841215435558615055352", "price": "0.6", "size": "10", "side": "SELL", "hash": "0e812c20e7bf3f9724e9bde24074b8385c1d73a7", "best_bid": "0.45", "best_ask": "0.48"}], "timestamp": "1769384195579", "event_type": "price_change"}}
{"_local_timestamp": "2026-01-25T23:36:35.681873+00:00", "data": {"market": "0x0be3d4cc20250a7105206bc352af8b1c087df2ebd4f3b3927fabcdd8c81d792e", "price_changes": [{"asset_id": "87528913053522501048749446605646222127999765893905568199883777953288580503567", "price": "0.53", "size": "20", "side": "BUY", "hash": "5b67b79a0da62cc6208bb932a1217ce552b4db13", "best_bid": "0.65", "best_ask": "0.67"}, {"asset_id": "63149403073928211890844841868361708990331353150804831882114276975252031214656", "price": "0.47", "size": "20", "side": "SELL", "hash": "0477bfee5639aee5ebefec5eae28422ad5848636", "best_bid": "0.33", "best_ask": "0.35"}], "timestamp": "1769384195610", "event_type": "price_change"}}
{"_local_timestamp": "2026-01-25T23:36:35.683325+00:00", "data": {"market": "0x9cacc164f8e79d815cc6714b0e5a04055f3bd5f6d05dc25f4265e7ffaa08dadc", "price_changes": [{"asset_id": "58983570136035430006949575067833187006601843982035390064418024195691336080349", "price": "0.41", "size": "50", "side": "BUY", "hash": "c194f74537ab16edd524b2074add9dea402587d4", "best_bid": "0.52", "best_ask": "0.55"}, {"asset_id": "75665317756971232401732022054678279748154632967705732846841215435558615055352", "price": "0.59", "size": "50", "side": "SELL", "hash": "621df05c657a61c4231b381c42830bb87c1df966", "best_bid": "0.45", "best_ask": "0.48"}], "timestamp": "1769384195610", "event_type": "price_change"}}
{"_local_timestamp": "2026-01-25T23:36:55.123353+00:00", "data": {"market": "0x5b782c35d9cbd6e9d38597bd0af4e53d3263bde143e4d4ffdbd76d0a094f4be4", "price_changes": [{"asset_id": "48123308101524452666134421526726361469113858451786831367632481270457773825485", "price": "0.48", "size": "110", "side": "BUY", "hash": "58f8937c5adcfea9af28a20a30be5a95eb89e27e", "best_bid": "0.91", "best_ask": "0.92"}, {"asset_id": "111803189967461986329215432128898000701874058405628301712422758141213653452479", "price": "0.52", "size": "110", "side": "SELL", "hash": "8b757a1f1e8fef364fc534b5ba5ee1178f8bc57f", "best_bid": "0.08", "best_ask": "0.09"}], "timestamp": "1769384215013", "event_type": "price_change"}}
{"_local_timestamp": "2026-01-25T23:37:13.500239+00:00", "data": {"market": "0x0be3d4cc20250a7105206bc352af8b1c087df2ebd4f3b3927fabcdd8c81d792e", "price_changes": [{"asset_id": "87528913053522501048749446605646222127999765893905568199883777953288580503567", "price": "0.21", "size": "658.8", "side": "BUY", "hash": "10c2cb6818aa69e3f74516994509a282a6a57d61", "best_bid": "0.65", "best_ask": "0.67"}, {"asset_id": "63149403073928211890844841868361708990331353150804831882114276975252031214656", "price": "0.79", "size": "658.8", "side": "SELL", "hash": "da09f9fb3cee1830acbcf8b1ef5ceddbf346bbf2", "best_bid": "0.33", "best_ask": "0.35"}], "timestamp": "1769384233375", "event_type": "price_change"}}
{"_local_timestamp": "2026-01-25T23:37:31.757822+00:00", "data": {"market": "0x0be3d4cc20250a7105206bc352af8b1c087df2ebd4f3b3927fabcdd8c81d792e", "price_changes": [{"asset_id": "87528913053522501048749446605646222127999765893905568199883777953288580503567", "price": "0.57", "size": "53", "side": "BUY", "hash": "7a34c9fb9dba7de8f3bdc37838f8ec8a803e9f4e", "best_bid": "0.65", "best_ask": "0.67"}, {"asset_id": "63149403073928211890844841868361708990331353150804831882114276975252031214656", "price": "0.43", "size": "53", "side": "SELL", "hash": "5d332af571238f376e0b78e5e9aa2f6d08b94363", "best_bid": "0.33", "best_ask": "0.35"}], "timestamp": "1769384251656", "event_type": "price_change"}}
{"_local_timestamp": "2026-01-25T23:37:32.037153+00:00", "data": {"market": "0x9cacc164f8e79d815cc6714b0e5a04055f3bd5f6d05dc25f4265e7ffaa08dadc", "price_changes": [{"asset_id": "58983570136035430006949575067833187006601843982035390064418024195691336080349", "price": "0.45", "size": "19", "side": "BUY", "hash": "704ed718cad23e0dd435ecfd744554e5d4f2132e", "best_bid": "0.52", "best_ask": "0.55"}, {"asset_id": "75665317756971232401732022054678279748154632967705732846841215435558615055352", "price": "0.55", "size": "19", "side": "SELL", "hash": "ff06c1470a7ddcc4bdf378762d5afae7a8e705ed", "best_bid": "0.45", "best_ask": "0.48"}], "timestamp": "1769384251913", "event_type": "price_change"}}
{"_local_timestamp": "2026-01-25T23:37:32.037663+00:00", "data": {"market": "0x5b782c35d9cbd6e9d38597bd0af4e53d3263bde143e4d4ffdbd76d0a094f4be4", "price_changes": [{"asset_id": "48123308101524452666134421526726361469113858451786831367632481270457773825485", "price": "0.82", "size": "37", "side": "BUY", "hash": "44ff98971a9ca8dd7404601b9523983a01e0141f", "best_bid": "0.91", "best_ask": "0.92"}, {"asset_id": "111803189967461986329215432128898000701874058405628301712422758141213653452479", "price": "0.18", "size": "37", "side": "SELL", "hash": "96c70a32876b4912330820ca4ea66a1ca074519e", "best_bid": "0.08", "best_ask": "0.09"}], "timestamp": "1769384251914", "event_type": "price_change"}}
{"_local_timestamp": "2026-01-25T23:37:32.077497+00:00", "data": {"market": "0x5b782c35d9cbd6e9d38597bd0af4e53d3263bde143e4d4ffdbd76d0a094f4be4", "price_changes": [{"asset_id": "111803189967461986329215432128898000701874058405628301712422758141213653452479", "price": "0.03", "size": "250", "side": "BUY", "hash": "3f89e4e0168600fff49d3e11f1cfb121caaf5214", "best_bid": "0.08", "best_ask": "0.09"}, {"asset_id": "48123308101524452666134421526726361469113858451786831367632481270457773825485", "price": "0.97", "size": "250", "side": "SELL", "hash": "02c21cb77fe7bfe2e53c554f5ff4e7c717df4173", "best_bid": "0.91", "best_ask": "0.92"}], "timestamp": "1769384251915", "event_type": "price_change"}}
{"_local_timestamp": "2026-01-25T23:37:32.804967+00:00", "data": {"market": "0x5b782c35d9cbd6e9d38597bd0af4e53d3263bde143e4d4ffdbd76d0a094f4be4", "price_changes": [{"asset_id": "111803189967461986329215432128898000701874058405628301712422758141213653452479", "price": "0.17", "size": "7.15", "side": "SELL", "hash": "2a938ad3cbda87ed410c7cc0d84762b4990fc759", "best_bid": "0.08", "best_ask": "0.09"}, {"asset_id": "48123308101524452666134421526726361469113858451786831367632481270457773825485", "price": "0.83", "size": "7.15", "side": "BUY", "hash": "b51f82603218af99d89a0b6f0b17994a200b0b48", "best_bid": "0.91", "best_ask": "0.92"}], "timestamp": "1769384252733", "event_type": "price_change"}}
{"_local_timestamp": "2026-01-25T23:37:32.863314+00:00", "data": {"market": "0x5b782c35d9cbd6e9d38597bd0af4e53d3263bde143e4d4ffdbd76d0a094f4be4", "price_changes": [{"asset_id": "111803189967461986329215432128898000701874058405628301712422758141213653452479", "price": "0.3", "size": "49.24", "side": "SELL", "hash": "d07dcf4cbd2eb86c8aee315d7a09d20c6977f06b", "best_bid": "0.08", "best_ask": "0.09"}, {"asset_id": "48123308101524452666134421526726361469113858451786831367632481270457773825485", "price": "0.7", "size": "49.24", "side": "BUY", "hash": "4e15aa7a361262e7bc511e798fa8916f841f43c1", "best_bid": "0.91", "best_ask": "0.92"}], "timestamp": "1769384252796", "event_type": "price_change"}}
{"_local_timestamp": "2026-01-25T23:37:33.369368+00:00", "data": {"market": "0x5b782c35d9cbd6e9d38597bd0af4e53d3263bde143e4d4ffdbd76d0a094f4be4", "price_changes": [{"asset_id": "48123308101524452666134421526726361469113858451786831367632481270457773825485", "price": "0.7", "size": "29.24", "side": "BUY", "hash": "bde2ad844b0609f7bd5c98f58d9e1e440421d7c6", "best_bid": "0.91", "best_ask": "0.92"}, {"asset_id": "111803189967461986329215432128898000701874058405628301712422758141213653452479", "price": "0.3", "size": "29.24", "side": "SELL", "hash": "07f48c2e9d7c055452647aaa7c2475ead71d4875", "best_bid": "0.08", "best_ask": "0.09"}], "timestamp": "1769384253305", "event_type": "price_change"}}
{"_local_timestamp": "2026-01-25T23:37:33.407146+00:00", "data": {"market": "0x5b782c35d9cbd6e9d38597bd0af4e53d3263bde143e4d4ffdbd76d0a094f4be4", "price_changes": [{"asset_id": "48123308101524452666134421526726361469113858451786831367632481270457773825485", "price": "0.71", "size": "20", "side": "BUY", "hash": "7041300e09780e208a236d8eddad847317886ba6", "best_bid": "0.91", "best_ask": "0.92"}, {"asset_id": "111803189967461986329215432128898000701874058405628301712422758141213653452479", "price": "0.29", "size": "20", "side": "SELL", "hash": "4319bbf215307a1433e0979ced2ade2cffef2150", "best_bid": "0.08", "best_ask": "0.09"}], "timestamp": "1769384253338", "event_type": "price_change"}}
{"_local_timestamp": "2026-01-25T23:37:47.052017+00:00", "data": {"market": "0x5b782c35d9cbd6e9d38597bd0af4e53d3263bde143e4d4ffdbd76d0a094f4be4", "price_changes": [{"asset_id": "48123308101524452666134421526726361469113858451786831367632481270457773825485", "price": "0.69", "size": "0", "side": "BUY", "hash": "601665719b3e924db634b37356b7ac88a97f9d4b", "best_bid": "0.91", "best_ask": "0.92"}, {"asset_id": "111803189967461986329215432128898000701874058405628301712422758141213653452479", "price": "0.31", "size": "0", "side": "SELL", "hash": "174bacf3ef84ccc6e2cc03f698d210cb1ceefb81", "best_bid": "0.08", "best_ask": "0.09"}], "timestamp": "1769384266972", "event_type": "price_change"}}
{"_local_timestamp": "2026-01-25T23:37:47.052553+00:00", "data": {"market": "0x5b782c35d9cbd6e9d38597bd0af4e53d3263bde143e4d4ffdbd76d0a094f4be4", "price_changes": [{"asset_id": "48123308101524452666134421526726361469113858451786831367632481270457773825485", "price": "0.48", "size": "10", "side": "BUY", "hash": "601665719b3e924db634b37356b7ac88a97f9d4b", "best_bid": "0.91", "best_ask": "0.92"}, {"asset_id": "111803189967461986329215432128898000701874058405628301712422758141213653452479", "price": "0.52", "size": "10", "side": "SELL", "hash": "174bacf3ef84ccc6e2cc03f698d210cb1ceefb81", "best_bid": "0.08", "best_ask": "0.09"}], "timestamp": "1769384266972", "event_type": "price_change"}}
{"_local_timestamp": "2026-01-25T23:37:47.752234+00:00", "data": {"market": "0x5b782c35d9cbd6e9d38597bd0af4e53d3263bde143e4d4ffdbd76d0a094f4be4", "price_changes": [{"asset_id": "48123308101524452666134421526726361469113858451786831367632481270457773825485", "price": "0.64", "size": "100", "side": "BUY", "hash": "da413375b80a8ec95f174445290301fe59055fdf", "best_bid": "0.91", "best_ask": "0.92"}, {"asset_id": "111803189967461986329215432128898000701874058405628301712422758141213653452479", "price": "0.36", "size": "100", "side": "SELL", "hash": "468c8344700b07f08adaa6e4dee4394941f281ea", "best_bid": "0.08", "best_ask": "0.09"}], "timestamp": "1769384267678", "event_type": "price_change"}}
{"_local_timestamp": "2026-01-25T23:37:47.830327+00:00", "data": {"market": "0x5b782c35d9cbd6e9d38597bd0af4e53d3263bde143e4d4ffdbd76d0a094f4be4", "price_changes": [{"asset_id": "48123308101524452666134421526726361469113858451786831367632481270457773825485", "price": "0.38", "size": "105", "side": "BUY", "hash": "7458e5dfa485899c494a20de3d23d99f401ea334", "best_bid": "0.91", "best_ask": "0.92"}, {"asset_id": "111803189967461986329215432128898000701874058405628301712422758141213653452479", "price": "0.62", "size": "105", "side": "SELL", "hash": "ed9d9790b01ad1ca8386933b7a2a79650737e7d1", "best_bid": "0.08", "best_ask": "0.09"}], "timestamp": "1769384267760", "event_type": "price_change"}}
{"_local_timestamp": "2026-01-25T23:37:47.972823+00:00", "data": {"market": "0x46e08dad4b1370947613b81f2ba28a23226504a333ec7e42de877d6ba6cc59d0", "price_changes": [{"asset_id": "85467679028197532287128360159828743243379157810773026071193309107969652317045", "price": "0.54", "size": "570", "side": "BUY", "hash": "6ce60a808c8f30da8a6451584ac68e7a22de5e01", "best_bid": "0.958", "best_ask": "0.964"}, {"asset_id": "113369140136913812777925497644561662667789653912765877043929720445901767848122", "price": "0.46", "size": "570", "side": "SELL", "hash": "2af28aa304885506c5b9a97f3fed05eed4ad1ce9", "best_bid": "0.036", "best_ask": "0.042"}], "timestamp": "1769384267895", "event_type": "price_change"}}
{"_local_timestamp": "2026-01-25T23:37:48.023954+00:00", "data": {"market": "0x5b782c35d9cbd6e9d38597bd0af4e53d3263bde143e4d4ffdbd76d0a094f4be4", "price_changes": [{"asset_id": "111803189967461986329215432128898000701874058405628301712422758141213653452479", "price": "0.3", "size": "0", "side": "SELL", "hash": "970372dd78ba2361a8cdf0c9897f5719bc2232ad", "best_bid": "0.08", "best_ask": "0.09"}, {"asset_id": "48123308101524452666134421526726361469113858451786831367632481270457773825485", "price": "0.7", "size": "0", "side": "BUY", "hash": "359ba15d2915f1cbc296385673abef7ad3998bdc", "best_bid": "0.91", "best_ask": "0.92"}], "timestamp": "1769384267923", "event_type": "price_change"}}
{"_local_timestamp": "2026-01-25T23:37:48.039338+00:00", "data": {"market": "0x5b782c35d9cbd6e9d38597bd0af4e53d3263bde143e4d4ffdbd76d0a094f4be4", "price_changes": [{"asset_id": "111803189967461986329215432128898000701874058405628301712422758141213653452479", "price": "0.52", "size": "39.24", "side": "SELL", "hash": "1a76784c8bbab26258fee6f12dcebeda362a529e", "best_bid": "0.08", "best_ask": "0.09"}, {"asset_id": "48123308101524452666134421526726361469113858451786831367632481270457773825485", "price": "0.48", "size": "39.24", "side": "BUY", "hash": "206abc47efe210c498d762afb74c24f76ebc6c37", "best_bid": "0.91", "best_ask": "0.92"}], "timestamp": "1769384267966", "event_type": "price_change"}}
{"_local_timestamp": "2026-01-25T23:37:48.159988+00:00", "data": {"market": "0x5b782c35d9cbd6e9d38597bd0af4e53d3263bde143e4d4ffdbd76d0a094f4be4", "price_changes": [{"asset_id": "48123308101524452666134421526726361469113858451786831367632481270457773825485", "price": "0.71", "size": "0", "side": "BUY", "hash": "aa24352ab010f994a73dcdeceb33be32b6f92385", "best_bid": "0.91", "best_ask": "0.92"}, {"asset_id": "111803189967461986329215432128898000701874058405628301712422758141213653452479", "price": "0.29", "size": "0", "side": "SELL", "hash": "7733c4502669432cc4d6eb9c721dbf80bc3fa301", "best_bid": "0.08", "best_ask": "0.09"}], "timestamp": "1769384268088", "event_type": "price_change"}}
{"_local_timestamp": "2026-01-25T23:37:48.191703+00:00", "data": {"market": "0x5b782c35d9cbd6e9d38597bd0af4e53d3263bde143e4d4ffdbd76d0a094f4be4", "price_changes": [{"asset_id": "48123308101524452666134421526726361469113858451786831367632481270457773825485", "price": "0.65", "size": "20", "side": "BUY", "hash": "d0d53eb95fc7440a6cdbf0da47b68c64e9d4a8fb", "best_bid": "0.91", "best_ask": "0.92"}, {"asset_id": "111803189967461986329215432128898000701874058405628301712422758141213653452479", "price": "0.35", "size": "20", "side": "SELL", "hash": "5a7b28466a0c0f5992ef5195501fb220f4032277", "best_bid": "0.08", "best_ask": "0.09"}], "timestamp": "1769384268120", "event_type": "price_change"}}
{"_local_timestamp": "2026-01-25T23:37:48.958143+00:00", "data": {"market": "0x5b782c35d9cbd6e9d38597bd0af4e53d3263bde143e4d4ffdbd76d0a094f4be4", "price_changes": [{"asset_id": "111803189967461986329215432128898000701874058405628301712422758141213653452479", "price": "0.52", "size": "10", "side": "SELL", "hash": "2eaab06842f5adbead41c2b17e87355634a1bdaa", "best_bid": "0.08", "best_ask": "0.09"}, {"asset_id": "48123308101524452666134421526726361469113858451786831367632481270457773825485", "price": "0.48", "size": "10", "side": "BUY", "hash": "14375529a3ad16e7af08a2ef6c32308b0fb21611", "best_bid": "0.91", "best_ask": "0.92"}], "timestamp": "1769384268891", "event_type": "price_change"}}
{"_local_timestamp": "2026-01-25T23:37:49.042030+00:00", "data": {"market": "0x5b782c35d9cbd6e9d38597bd0af4e53d3263bde143e4d4ffdbd76d0a094f4be4", "price_changes": [{"asset_id": "111803189967461986329215432128898000701874058405628301712422758141213653452479", "price": "0.35", "size": "49.24", "side": "SELL", "hash": "2a11258779ec0af49acebfb223cb6902bac47d67", "best_bid": "0.08", "best_ask": "0.09"}, {"asset_id": "48123308101524452666134421526726361469113858451786831367632481270457773825485", "price": "0.65", "size": "49.24", "side": "BUY", "hash": "ed27c0834d75003642d4e3e9c89428ec2557e0fb", "best_bid": "0.91", "best_ask": "0.92"}], "timestamp": "1769384268974", "event_type": "price_change"}}
{"_local_timestamp": "2026-01-25T23:37:50.046524+00:00", "data": {"market": "0x5b782c35d9cbd6e9d38597bd0af4e53d3263bde143e4d4ffdbd76d0a094f4be4", "price_changes": [{"asset_id": "48123308101524452666134421526726361469113858451786831367632481270457773825485", "price": "0.65", "size": "29.24", "side": "BUY", "hash": "1a23ff63ea618ffe3183ec643c2e0e0b1e9fbc65", "best_bid": "0.91", "best_ask": "0.92"}, {"asset_id": "111803189967461986329215432128898000701874058405628301712422758141213653452479", "price": "0.35", "size": "29.24", "side": "SELL", "hash": "5530d927bbfb3f6f8fc137088e4c2d9da734f0bb", "best_bid": "0.08", "best_ask": "0.09"}], "timestamp": "1769384269979", "event_type": "price_change"}}
{"_local_timestamp": "2026-01-25T23:37:50.122889+00:00", "data": {"market": "0x5b782c35d9cbd6e9d38597bd0af4e53d3263bde143e4d4ffdbd76d0a094f4be4", "price_changes": [{"asset_id": "48123308101524452666134421526726361469113858451786831367632481270457773825485", "price": "0.66", "size": "20", "side": "BUY", "hash": "0a4606a14d5b49bed0b08fa2804546bdfaf9b257", "best_bid": "0.91", "best_ask": "0.92"}, {"asset_id": "111803189967461986329215432128898000701874058405628301712422758141213653452479", "price": "0.34", "size": "20", "side": "SELL", "hash": "4173395d8d32b90955d930e35790f0e5b0e4e561", "best_bid": "0.08", "best_ask": "0.09"}], "timestamp": "1769384270013", "event_type": "price_change"}}
{"_local_timestamp": "2026-01-25T23:37:52.154488+00:00", "data": {"market": "0x44f67876759c44b763bb53f89b3c738756331b0a208672fc8db8a5f389230950", "price_changes": [{"asset_id": "1582298976410585403069729422280265608038484032857579102122167925665102997608", "price": "0.003", "size": "12.86", "side": "BUY", "hash": "247feab3f5e9bd4bd1655c4832244fd368a49728", "best_bid": "0.014", "best_ask": "0.06"}, {"asset_id": "32592218374784909301050372254273467546998719384564620545871759434640468645973", "price": "0.997", "size": "12.86", "side": "SELL", "hash": "2c043eec46fd952c2e896c6261bea9fbfea12acd", "best_bid": "0.94", "best_ask": "0.986"}], "timestamp": "1769384272084", "event_type": "price_change"}}
{"_local_timestamp": "2026-01-25T23:37:52.531687+00:00", "data": {"market": "0x44f67876759c44b763bb53f89b3c738756331b0a208672fc8db8a5f389230950", "price_changes": [{"asset_id": "1582298976410585403069729422280265608038484032857579102122167925665102997608", "price": "0.003", "size": "29.39", "side": "BUY", "hash": "91476a4b06480009b82d13c0757f449267e090d9", "best_bid": "0.014", "best_ask": "0.06"}, {"asset_id": "32592218374784909301050372254273467546998719384564620545871759434640468645973", "price": "0.997", "size": "29.39", "side": "SELL", "hash": "6847d58d3411706b6b3bf9af28683546fb6356ec", "best_bid": "0.94", "best_ask": "0.986"}], "timestamp": "1769384272447", "event_type": "price_change"}}
{"_local_timestamp": "2026-01-25T23:37:52.787287+00:00", "data": {"market": "0x44f67876759c44b763bb53f89b3c738756331b0a208672fc8db8a5f389230950", "price_changes": [{"asset_id": "1582298976410585403069729422280265608038484032857579102122167925665102997608", "price": "0.003", "size": "45.92", "side": "BUY", "hash": "17e76d5f157b34059e2ec5555ceb1b3c9f5aced2", "best_bid": "0.014", "best_ask": "0.06"}, {"asset_id": "32592218374784909301050372254273467546998719384564620545871759434640468645973", "price": "0.997", "size": "45.92", "side": "SELL", "hash": "2187c7d6c78d276c7269e08c1e0cda5a59f18c9d", "best_bid": "0.94", "best_ask": "0.986"}], "timestamp": "1769384272698", "event_type": "price_change"}}
{"_local_timestamp": "2026-01-25T23:38:01.979351+00:00", "data": {"market": "0x5b782c35d9cbd6e9d38597bd0af4e53d3263bde143e4d4ffdbd76d0a094f4be4", "price_changes": [{"asset_id": "48123308101524452666134421526726361469113858451786831367632481270457773825485", "price": "0.18", "size": "627.77", "side": "BUY", "hash": "ee27f56cfd5c8cfbeb8a59aca911f1268bf625f9", "best_bid": "0.91", "best_ask": "0.92"}, {"asset_id": "111803189967461986329215432128898000701874058405628301712422758141213653452479", "price": "0.82", "size": "627.77", "side": "SELL", "hash": "151d8486a355bcc41853186fec25ea23fe3e5805", "best_bid": "0.08", "best_ask": "0.09"}], "timestamp": "1769384281907", "event_type": "price_change"}}
{"_local_timestamp": "2026-01-25T23:38:02.172910+00:00", "data": {"market": "0x0be3d4cc20250a7105206bc352af8b1c087df2ebd4f3b3927fabcdd8c81d792e", "price_changes": [{"asset_id": "87528913053522501048749446605646222127999765893905568199883777953288580503567", "price": "0.49", "size": "0", "side": "BUY", "hash": "82e5e9141756aa347c511dc35c837fd204dbc28f", "best_bid": "0.65", "best_ask": "0.67"}, {"asset_id": "63149403073928211890844841868361708990331353150804831882114276975252031214656", "price": "0.51", "size": "0", "side": "SELL", "hash": "7fca70ffa23ce5eb351c917216646395db35c4a9", "best_bid": "0.33", "best_ask": "0.35"}], "timestamp": "1769384282102", "event_type": "price_change"}}
{"_local_timestamp": "2026-01-25T23:38:02.299909+00:00", "data": {"market": "0x0be3d4cc20250a7105206bc352af8b1c087df2ebd4f3b3927fabcdd8c81d792e", "price_changes": [{"asset_id": "87528913053522501048749446605646222127999765893905568199883777953288580503567", "price": "0.53", "size": "30", "side": "BUY", "hash": "462dc43e0247183622a7b279cabd902c3fe66a95", "best_bid": "0.65", "best_ask": "0.67"}, {"asset_id": "63149403073928211890844841868361708990331353150804831882114276975252031214656", "price": "0.47", "size": "30", "side": "SELL", "hash": "3314ee45bd5a4c3f851d01203c9f46046b11b59f", "best_bid": "0.33", "best_ask": "0.35"}], "timestamp": "1769384282223", "event_type": "price_change"}}
{"_local_timestamp": "2026-01-25T23:38:19.449605+00:00", "data": {"market": "0x44f67876759c44b763bb53f89b3c738756331b0a208672fc8db8a5f389230950", "price_changes": [{"asset_id": "1582298976410585403069729422280265608038484032857579102122167925665102997608", "price": "0.003", "size": "12.86", "side": "BUY", "hash": "fe28e33ce86235caa38371977f107c710a209737", "best_bid": "0.014", "best_ask": "0.06"}, {"asset_id": "32592218374784909301050372254273467546998719384564620545871759434640468645973", "price": "0.997", "size": "12.86", "side": "SELL", "hash": "435adf115c51ba33d637da887199276bc362771d", "best_bid": "0.94", "best_ask": "0.986"}], "timestamp": "1769384299382", "event_type": "price_change"}}
{"_local_timestamp": "2026-01-25T23:38:19.863034+00:00", "data": {"market": "0x44f67876759c44b763bb53f89b3c738756331b0a208672fc8db8a5f389230950", "price_changes": [{"asset_id": "1582298976410585403069729422280265608038484032857579102122167925665102997608", "price": "0.004", "size": "12.4", "side": "BUY", "hash": "0e79c2fcd057b8302788ec56c56afd4f4738f729", "best_bid": "0.014", "best_ask": "0.06"}, {"asset_id": "32592218374784909301050372254273467546998719384564620545871759434640468645973", "price": "0.996", "size": "12.4", "side": "SELL", "hash": "5c6b41c6d17409d1d9172ef5e2ecd84f734f6254", "best_bid": "0.94", "best_ask": "0.986"}], "timestamp": "1769384299785", "event_type": "price_change"}}
{"_local_timestamp": "2026-01-25T23:38:19.939407+00:00", "data": {"market": "0x46e08dad4b1370947613b81f2ba28a23226504a333ec7e42de877d6ba6cc59d0", "price_changes": [{"asset_id": "85467679028197532287128360159828743243379157810773026071193309107969652317045", "price": "0.54", "size": "555", "side": "BUY", "hash": "20d202de388e69086f8d81e0791b233fe3c09f02", "best_bid": "0.958", "best_ask": "0.964"}, {"asset_id": "113369140136913812777925497644561662667789653912765877043929720445901767848122", "price": "0.46", "size": "555", "side": "SELL", "hash": "634a041d62006d485f237bab04f18cd968479d2c", "best_bid": "0.036", "best_ask": "0.042"}], "timestamp": "1769384299876", "event_type": "price_change"}}
{"_local_timestamp": "2026-01-25T23:38:21.260782+00:00", "data": {"market": "0x5b782c35d9cbd6e9d38597bd0af4e53d3263bde143e4d4ffdbd76d0a094f4be4", "price_changes": [{"asset_id": "48123308101524452666134421526726361469113858451786831367632481270457773825485", "price": "0.34", "size": "0", "side": "BUY", "hash": "8a0f17bdc6f35c47e64d89eccc3d93eef2075333", "best_bid": "0.91", "best_ask": "0.92"}, {"asset_id": "111803189967461986329215432128898000701874058405628301712422758141213653452479", "price": "0.66", "size": "0", "side": "SELL", "hash": "3b9ced34ee90d1cf12a9ab2c93c07d703ffc3876", "best_bid": "0.08", "best_ask": "0.09"}], "timestamp": "1769384301122", "event_type": "price_change"}}
{"_local_timestamp": "2026-01-25T23:38:21.621929+00:00", "data": {"market": "0x5b782c35d9cbd6e9d38597bd0af4e53d3263bde143e4d4ffdbd76d0a094f4be4", "price_changes": [{"asset_id": "48123308101524452666134421526726361469113858451786831367632481270457773825485", "price": "0.37", "size": "179.05", "side": "BUY", "hash": "ac0263056820a2b8d43405778b2ca9f78cc861b1", "best_bid": "0.91", "best_ask": "0.92"}, {"asset_id": "111803189967461986329215432128898000701874058405628301712422758141213653452479", "price": "0.63", "size": "179.05", "side": "SELL", "hash": "6fda31cf3954376b52fa80d25e50a6c9798bc8be", "best_bid": "0.08", "best_ask": "0.09"}], "timestamp": "1769384301461", "event_type": "price_change"}}
{"_local_timestamp": "2026-01-25T23:38:26.421763+00:00", "data": {"market": "0x5b782c35d9cbd6e9d38597bd0af4e53d3263bde143e4d4ffdbd76d0a094f4be4", "price_changes": [{"asset_id": "48123308101524452666134421526726361469113858451786831367632481270457773825485", "price": "0.18", "size": "677.77", "side": "BUY", "hash": "f8480ca31fb65af6fcd74a651a1ae51246aac2ea", "best_bid": "0.91", "best_ask": "0.92"}, {"asset_id": "111803189967461986329215432128898000701874058405628301712422758141213653452479", "price": "0.82", "size": "677.77", "side": "SELL", "hash": "626a71c715f9d03cc88abcf9ffe375a097624cc9", "best_bid": "0.08", "best_ask": "0.09"}], "timestamp": "1769384306354", "event_type": "price_change"}}
{"_local_timestamp": "2026-01-25T23:38:58.374419+00:00", "data": {"market": "0x0be3d4cc20250a7105206bc352af8b1c087df2ebd4f3b3927fabcdd8c81d792e", "price_changes": [{"asset_id": "87528913053522501048749446605646222127999765893905568199883777953288580503567", "price": "0.21", "size": "608.8", "side": "BUY", "hash": "fb4e1509d807e47d3a8ec62149f7b8fee06a1950", "best_bid": "0.65", "best_ask": "0.67"}, {"asset_id": "63149403073928211890844841868361708990331353150804831882114276975252031214656", "price": "0.79", "size": "608.8", "side": "SELL", "hash": "1f171b8e08be48b8cc465eb022166f0e2aa97409", "best_bid": "0.33", "best_ask": "0.35"}], "timestamp": "1769384338217", "event_type": "price_change"}}
{"_local_timestamp": "2026-01-25T23:38:58.650736+00:00", "data": {"market": "0x46e08dad4b1370947613b81f2ba28a23226504a333ec7e42de877d6ba6cc59d0", "price_changes": [{"asset_id": "85467679028197532287128360159828743243379157810773026071193309107969652317045", "price": "0.536", "size": "0", "side": "BUY", "hash": "1f1b9d91aebef196df2bb4092182e37b7698caf2", "best_bid": "0.958", "best_ask": "0.964"}, {"asset_id": "113369140136913812777925497644561662667789653912765877043929720445901767848122", "price": "0.464", "size": "0", "side": "SELL", "hash": "260d31a913c82521f5931b9b6d1ad2fca3e316a0", "best_bid": "0.036", "best_ask": "0.042"}], "timestamp": "1769384338499", "event_type": "price_change"}}
{"_local_timestamp": "2026-01-25T23:38:58.756977+00:00", "data": {"market": "0x46e08dad4b1370947613b81f2ba28a23226504a333ec7e42de877d6ba6cc59d0", "price_changes": [{"asset_id": "85467679028197532287128360159828743243379157810773026071193309107969652317045", "price": "0.543", "size": "30", "side": "BUY", "hash": "dcf264861cb6236e6408edcf43fe5b703d3d5071", "best_bid": "0.958", "best_ask": "0.964"}, {"asset_id": "113369140136913812777925497644561662667789653912765877043929720445901767848122", "price": "0.457", "size": "30", "side": "SELL", "hash": "d718fffaf3e35dd43d0016c845218d8b307365e2", "best_bid": "0.036", "best_ask": "0.042"}], "timestamp": "1769384338678", "event_type": "price_change"}}
{"_local_timestamp": "2026-01-25T23:38:58.852799+00:00", "data": {"market": "0x46e08dad4b1370947613b81f2ba28a23226504a333ec7e42de877d6ba6cc59d0", "price_changes": [{"asset_id": "85467679028197532287128360159828743243379157810773026071193309107969652317045", "price": "0.537", "size": "0", "side": "BUY", "hash": "1f16786df583388f694b64e9c1d983963fc36cf4", "best_bid": "0.958", "best_ask": "0.964"}, {"asset_id": "113369140136913812777925497644561662667789653912765877043929720445901767848122", "price": "0.463", "size": "0", "side": "SELL", "hash": "de127d02395fe46bef8430912a43fa577c08b24c", "best_bid": "0.036", "best_ask": "0.042"}], "timestamp": "1769384338786", "event_type": "price_change"}}
{"_local_timestamp": "2026-01-25T23:38:58.984600+00:00", "data": {"market": "0x46e08dad4b1370947613b81f2ba28a23226504a333ec7e42de877d6ba6cc59d0", "price_changes": [{"asset_id": "85467679028197532287128360159828743243379157810773026071193309107969652317045", "price": "0.544", "size": "40", "side": "BUY", "hash": "6d9a99437ee60c43d5b85474a2b30e56753f33d9", "best_bid": "0.958", "best_ask": "0.964"}, {"asset_id": "113369140136913812777925497644561662667789653912765877043929720445901767848122", "price": "0.456", "size": "40", "side": "SELL", "hash": "a27c34d6d36f60470545782171338cc169e958c5", "best_bid": "0.036", "best_ask": "0.042"}], "timestamp": "1769384338922", "event_type": "price_change"}}
{"_local_timestamp": "2026-01-25T23:38:59.189967+00:00", "data": {"market": "0x46e08dad4b1370947613b81f2ba28a23226504a333ec7e42de877d6ba6cc59d0", "price_changes": [{"asset_id": "85467679028197532287128360159828743243379157810773026071193309107969652317045", "price": "0.539", "size": "10", "side": "BUY", "hash": "0038c6edab03225c29e1db8229c1f24c9bef7c17", "best_bid": "0.958", "best_ask": "0.964"}, {"asset_id": "113369140136913812777925497644561662667789653912765877043929720445901767848122", "price": "0.461", "size": "10", "side": "SELL", "hash": "2866688ca2591c333bc3ca6b04ff6fc87b26b8a2", "best_bid": "0.036", "best_ask": "0.042"}], "timestamp": "1769384339020", "event_type": "price_change"}}
{"_local_timestamp": "2026-01-25T23:38:59.326715+00:00", "data": {"market": "0x46e08dad4b1370947613b81f2ba28a23226504a333ec7e42de877d6ba6cc59d0", "price_changes": [{"asset_id": "85467679028197532287128360159828743243379157810773026071193309107969652317045", "price": "0.541", "size": "389", "side": "BUY", "hash": "c5d55c9ccf1cdb79f92a6c84ede311b774c1f4ef", "best_bid": "0.958", "best_ask": "0.964"}, {"asset_id": "113369140136913812777925497644561662667789653912765877043929720445901767848122", "price": "0.459", "size": "389", "side": "SELL", "hash": "c2b88fb3bc1b5926406da109cfbad0e716a857a3", "best_bid": "0.036", "best_ask": "0.042"}], "timestamp": "1769384339259", "event_type": "price_change"}}
{"_local_timestamp": "2026-01-25T23:38:59.423096+00:00", "data": {"market": "0x46e08dad4b1370947613b81f2ba28a23226504a333ec7e42de877d6ba6cc59d0", "price_changes": [{"asset_id": "85467679028197532287128360159828743243379157810773026071193309107969652317045", "price": "0.54", "size": "370", "side": "BUY", "hash": "7680e8999a3f19514f6132b869c19a7e1c09d5b0", "best_bid": "0.958", "best_ask": "0.964"}, {"asset_id": "113369140136913812777925497644561662667789653912765877043929720445901767848122", "price": "0.46", "size": "370", "side": "SELL", "hash": "86df4371ca29dcc3d9c7efe2fe01c027144ea0cf", "best_bid": "0.036", "best_ask": "0.042"}], "timestamp": "1769384339352", "event_type": "price_change"}}
{"_local_timestamp": "2026-01-25T23:38:59.538185+00:00", "data": {"market": "0x46e08dad4b1370947613b81f2ba28a23226504a333ec7e42de877d6ba6cc59d0", "price_changes": [{"asset_id": "85467679028197532287128360159828743243379157810773026071193309107969652317045", "price": "0.542", "size": "189", "side": "BUY", "hash": "48131682bbebda499e2f6f3a4c3992a69c9a41f7", "best_bid": "0.958", "best_ask": "0.964"}, {"asset_id": "113369140136913812777925497644561662667789653912765877043929720445901767848122", "price": "0.458", "size": "189", "side": "SELL", "hash": "eeca2b190c3a033d3721e9ea684f190ffd6c7ed3", "best_bid": "0.036", "best_ask": "0.042"}], "timestamp": "1769384339416", "event_type": "price_change"}}
{"_local_timestamp": "2026-01-25T23:38:59.546750+00:00", "data": {"market": "0x46e08dad4b1370947613b81f2ba28a23226504a333ec7e42de877d6ba6cc59d0", "price_changes": [{"asset_id": "85467679028197532287128360159828743243379157810773026071193309107969652317045", "price": "0.545", "size": "10", "side": "BUY", "hash": "fad44b36a9396604cebcf4104537499733b5cd96", "best_bid": "0.958", "best_ask": "0.964"}, {"asset_id": "113369140136913812777925497644561662667789653912765877043929720445901767848122", "price": "0.455", "size": "10", "side": "SELL", "hash": "ecf73df247afe806815749b5d6c6c035f3c67c1a", "best_bid": "0.036", "best_ask": "0.042"}], "timestamp": "1769384339417", "event_type": "price_change"}}
{"_local_timestamp": "2026-01-25T23:38:59.605027+00:00", "data": {"market": "0x46e08dad4b1370947613b81f2ba28a23226504a333ec7e42de877d6ba6cc59d0", "price_changes": [{"asset_id": "85467679028197532287128360159828743243379157810773026071193309107969652317045", "price": "0.545", "size": "25", "side": "BUY", "hash": "78debae0149999a9e9ff8cede51a281a187201ed", "best_bid": "0.958", "best_ask": "0.964"}, {"asset_id": "113369140136913812777925497644561662667789653912765877043929720445901767848122", "price": "0.455", "size": "25", "side": "SELL", "hash": "f99b98fa09777dfbb93ed3f6fce87fd3d9ee4ec2", "best_bid": "0.036", "best_ask": "0.042"}], "timestamp": "1769384339418", "event_type": "price_change"}}
{"_local_timestamp": "2026-01-25T23:38:59.605588+00:00", "data": {"market": "0x46e08dad4b1370947613b81f2ba28a23226504a333ec7e42de877d6ba6cc59d0", "price_changes": [{"asset_id": "85467679028197532287128360159828743243379157810773026071193309107969652317045", "price": "0.54", "size": "0", "side": "BUY", "hash": "c7d7e300ad2c2864d03d5cbdce5829c2bef87335", "best_bid": "0.958", "best_ask": "0.964"}, {"asset_id": "113369140136913812777925497644561662667789653912765877043929720445901767848122", "price": "0.46", "size": "0", "side": "SELL", "hash": "af6bc9f37a46b9d1f686611afd7f5cec2e2cc4c5", "best_bid": "0.036", "best_ask": "0.042"}], "timestamp": "1769384339519", "event_type": "price_change"}}
{"_local_timestamp": "2026-01-25T23:38:59.634589+00:00", "data": {"market": "0x46e08dad4b1370947613b81f2ba28a23226504a333ec7e42de877d6ba6cc59d0", "price_changes": [{"asset_id": "85467679028197532287128360159828743243379157810773026071193309107969652317045", "price": "0.542", "size": "558", "side": "BUY", "hash": "2a8de11c73441f20ffc3e84a1bb3dd89b2c20799", "best_bid": "0.958", "best_ask": "0.964"}, {"asset_id": "113369140136913812777925497644561662667789653912765877043929720445901767848122", "price": "0.458", "size": "558", "side": "SELL", "hash": "48a6c9efa47266502ba19c5460e2926159af4a6c", "best_bid": "0.036", "best_ask": "0.042"}], "timestamp": "1769384339568", "event_type": "price_change"}}
{"_local_timestamp": "2026-01-25T23:38:59.756742+00:00", "data": {"market": "0x46e08dad4b1370947613b81f2ba28a23226504a333ec7e42de877d6ba6cc59d0", "price_changes": [{"asset_id": "85467679028197532287128360159828743243379157810773026071193309107969652317045", "price": "0.541", "size": "20", "side": "BUY", "hash": "b9fbb756b345c00c573a112f63d13eca3a6484ea", "best_bid": "0.958", "best_ask": "0.964"}, {"asset_id": "113369140136913812777925497644561662667789653912765877043929720445901767848122", "price": "0.459", "size": "20", "side": "SELL", "hash": "0e73212db144ff0ed4b5fdfc800ca0b9356e6c5b", "best_bid": "0.036", "best_ask": "0.042"}], "timestamp": "1769384339693", "event_type": "price_change"}}
{"_local_timestamp": "2026-01-25T23:38:59.921193+00:00", "data": {"market": "0x46e08dad4b1370947613b81f2ba28a23226504a333ec7e42de877d6ba6cc59d0", "price_changes": [{"asset_id": "85467679028197532287128360159828743243379157810773026071193309107969652317045", "price": "0.543", "size": "398", "side": "BUY", "hash": "6f9662e77d696742a11439264dec8e13221be7ba", "best_bid": "0.958", "best_ask": "0.964"}, {"asset_id": "113369140136913812777925497644561662667789653912765877043929720445901767848122", "price": "0.457", "size": "398", "side": "SELL", "hash": "04aaf531c564f2f856b1ba6e449b0983ecb5ae47", "best_bid": "0.036", "best_ask": "0.042"}], "timestamp": "1769384339854", "event_type": "price_change"}}
{"_local_timestamp": "2026-01-25T23:39:02.336862+00:00", "data": {"market": "0x46e08dad4b1370947613b81f2ba28a23226504a333ec7e42de877d6ba6cc59d0", "price_changes": [{"asset_id": "85467679028197532287128360159828743243379157810773026071193309107969652317045", "price": "0.541", "size": "0", "side": "BUY", "hash": "07cf9aeb011fb54509ad75b6b0ba186f640ec320", "best_bid": "0.958", "best_ask": "0.964"}, {"asset_id": "113369140136913812777925497644561662667789653912765877043929720445901767848122", "price": "0.459", "size": "0", "side": "SELL", "hash": "8eb952510c4ab8a8655dc2beefaaa20ebffa427f", "best_bid": "0.036", "best_ask": "0.042"}], "timestamp": "1769384342270", "event_type": "price_change"}}
{"_local_timestamp": "2026-01-25T23:39:02.377418+00:00", "data": {"market": "0x46e08dad4b1370947613b81f2ba28a23226504a333ec7e42de877d6ba6cc59d0", "price_changes": [{"asset_id": "85467679028197532287128360159828743243379157810773026071193309107969652317045", "price": "0.546", "size": "20", "side": "BUY", "hash": "d4a021bd0739cf74108e1a2bd94af7cfa75c8fb7", "best_bid": "0.958", "best_ask": "0.964"}, {"asset_id": "113369140136913812777925497644561662667789653912765877043929720445901767848122", "price": "0.454", "size": "20", "side": "SELL", "hash": "91d9aacfa0670bde58eca6e6ac110ad4006c30de", "best_bid": "0.036", "best_ask": "0.042"}], "timestamp": "1769384342296", "event_type": "price_change"}}
{"_local_timestamp": "2026-01-25T23:39:37.475653+00:00", "data": {"market": "0x5b782c35d9cbd6e9d38597bd0af4e53d3263bde143e4d4ffdbd76d0a094f4be4", "price_changes": [{"asset_id": "111803189967461986329215432128898000701874058405628301712422758141213653452479", "price": "0.02", "size": "20", "side": "BUY", "hash": "9938d60b585a8a82653220ade4f1b7f204cac997", "best_bid": "0.08", "best_ask": "0.09"}, {"asset_id": "48123308101524452666134421526726361469113858451786831367632481270457773825485", "price": "0.98", "size": "20", "side": "SELL", "hash": "ada19629b6f0d3d34ef2172b11720d8dd5d3f066", "best_bid": "0.91", "best_ask": "0.92"}], "timestamp": "1769384377411", "event_type": "price_change"}}
{"_local_timestamp": "2026-01-25T23:39:54.532113+00:00", "data": {"market": "0x9cacc164f8e79d815cc6714b0e5a04055f3bd5f6d05dc25f4265e7ffaa08dadc", "price_changes": [{"asset_id": "75665317756971232401732022054678279748154632967705732846841215435558615055352", "price": "0.45", "size": "0", "side": "BUY", "hash": "7ba92455c869b5fe3dab7f3c741e6056c8c2b883", "best_bid": "0.33", "best_ask": "0.48"}, {"asset_id": "58983570136035430006949575067833187006601843982035390064418024195691336080349", "price": "0.55", "size": "0", "side": "SELL", "hash": "2df6292f923036ec384a1ad66ccfd97565c4c13b", "best_bid": "0.52", "best_ask": "0.67"}], "timestamp": "1769384394457", "event_type": "price_change"}}
{"_local_timestamp": "2026-01-25T23:39:54.557224+00:00", "data": {"market": "0x46e08dad4b1370947613b81f2ba28a23226504a333ec7e42de877d6ba6cc59d0", "price_changes": [{"asset_id": "85467679028197532287128360159828743243379157810773026071193309107969652317045", "price": "0.652", "size": "20", "side": "BUY", "hash": "22b34170618f55a37c2a43b7df7d1eae51654607", "best_bid": "0.958", "best_ask": "0.964"}, {"asset_id": "113369140136913812777925497644561662667789653912765877043929720445901767848122", "price": "0.348", "size": "20", "side": "SELL", "hash": "096ed26e67261e11d6809e461dc8fe8928e06b75", "best_bid": "0.036", "best_ask": "0.042"}], "timestamp": "1769384394492", "event_type": "price_change"}}
{"_local_timestamp": "2026-01-25T23:39:54.616874+00:00", "data": {"market": "0x44f67876759c44b763bb53f89b3c738756331b0a208672fc8db8a5f389230950", "price_changes": [{"asset_id": "32592218374784909301050372254273467546998719384564620545871759434640468645973", "price": "0.736", "size": "0", "side": "BUY", "hash": "b1db773a394529db2046ee888a53702b867e145a", "best_bid": "0.94", "best_ask": "0.986"}, {"asset_id": "1582298976410585403069729422280265608038484032857579102122167925665102997608", "price": "0.264", "size": "0", "side": "SELL", "hash": "9c262fe704d6bb020c39cb237309f22e2650b48c", "best_bid": "0.014", "best_ask": "0.06"}], "timestamp": "1769384394549", "event_type": "price_change"}}
{"_local_timestamp": "2026-01-25T23:39:54.617596+00:00", "data": {"market": "0x46e08dad4b1370947613b81f2ba28a23226504a333ec7e42de877d6ba6cc59d0", "price_changes": [{"asset_id": "85467679028197532287128360159828743243379157810773026071193309107969652317045", "price": "0.542", "size": "189", "side": "BUY", "hash": "a804ea287076e5d14fe1c187c19634474d14611d", "best_bid": "0.958", "best_ask": "0.964"}, {"asset_id": "113369140136913812777925497644561662667789653912765877043929720445901767848122", "price": "0.458", "size": "189", "side": "SELL", "hash": "72cd158051dafa8bc6e31e431870c60b08510de9", "best_bid": "0.036", "best_ask": "0.042"}], "timestamp": "1769384394549", "event_type": "price_change"}}
{"_local_timestamp": "2026-01-25T23:39:54.618159+00:00", "data": {"market": "0x5b782c35d9cbd6e9d38597bd0af4e53d3263bde143e4d4ffdbd76d0a094f4be4", "price_changes": [{"asset_id": "48123308101524452666134421526726361469113858451786831367632481270457773825485", "price": "0.79", "size": "0", "side": "BUY", "hash": "8a15a89627a477cb1ce935fb494e08a613c1d617", "best_bid": "0.91", "best_ask": "0.92"}, {"asset_id": "111803189967461986329215432128898000701874058405628301712422758141213653452479", "price": "0.21", "size": "0", "side": "SELL", "hash": "516863f2959948fbffcae5e37996f9effb99c2b7", "best_bid": "0.08", "best_ask": "0.09"}], "timestamp": "1769384394549", "event_type": "price_change"}}
{"_local_timestamp": "2026-01-25T23:39:54.618801+00:00", "data": {"market": "0x0be3d4cc20250a7105206bc352af8b1c087df2ebd4f3b3927fabcdd8c81d792e", "price_changes": [{"asset_id": "87528913053522501048749446605646222127999765893905568199883777953288580503567", "price": "0.51", "size": "0", "side": "BUY", "hash": "a70f296eb3ae0c279c189a96dbc064928561489a", "best_bid": "0.65", "best_ask": "0.67"}, {"asset_id": "63149403073928211890844841868361708990331353150804831882114276975252031214656", "price": "0.49", "size": "0", "side": "SELL", "hash": "bee4c4673b43d9c346a2c786895609517e0149a9", "best_bid": "0.33", "best_ask": "0.35"}], "timestamp": "1769384394549", "event_type": "price_change"}}
{"_local_timestamp": "2026-01-25T23:39:54.619360+00:00", "data": {"market": "0x0be3d4cc20250a7105206bc352af8b1c087df2ebd4f3b3927fabcdd8c81d792e", "price_changes": [{"asset_id": "87528913053522501048749446605646222127999765893905568199883777953288580503567", "price": "0.21", "size": "541.8", "side": "BUY", "hash": "a70f296eb3ae0c279c189a96dbc064928561489a", "best_bid": "0.65", "best_ask": "0.67"}, {"asset_id": "63149403073928211890844841868361708990331353150804831882114276975252031214656", "price": "0.79", "size": "541.8", "side": "SELL", "hash": "bee4c4673b43d9c346a2c786895609517e0149a9", "best_bid": "0.33", "best_ask": "0.35"}], "timestamp": "1769384394549", "event_type": "price_change"}}
{"_local_timestamp": "2026-01-25T23:39:54.670730+00:00", "data": {"market": "0x9cacc164f8e79d815cc6714b0e5a04055f3bd5f6d05dc25f4265e7ffaa08dadc", "price_changes": [{"asset_id": "58983570136035430006949575067833187006601843982035390064418024195691336080349", "price": "0.23", "size": "286.95", "side": "BUY", "hash": "8487c4dcc5b2d3793105b15cf28a9f218789a18e", "best_bid": "0.52", "best_ask": "0.67"}, {"asset_id": "75665317756971232401732022054678279748154632967705732846841215435558615055352", "price": "0.77", "size": "286.95", "side": "SELL", "hash": "dc4a2606b4339bf68f7a73f8eddb74393c849a03", "best_bid": "0.33", "best_ask": "0.48"}], "timestamp": "1769384394599", "event_type": "price_change"}}
{"_local_timestamp": "2026-01-25T23:39:54.688934+00:00", "data": {"market": "0x0be3d4cc20250a7105206bc352af8b1c087df2ebd4f3b3927fabcdd8c81d792e", "price_changes": [{"asset_id": "87528913053522501048749446605646222127999765893905568199883777953288580503567", "price": "0.53", "size": "20", "side": "BUY", "hash": "8a315bff37c2192fdccd3af99855df21c396cdc5", "best_bid": "0.65", "best_ask": "0.67"}, {"asset_id": "63149403073928211890844841868361708990331353150804831882114276975252031214656", "price": "0.47", "size": "20", "side": "SELL", "hash": "ac630929e7055b6b434b43b1af523a846a236725", "best_bid": "0.33", "best_ask": "0.35"}], "timestamp": "1769384394625", "event_type": "price_change"}}
{"_local_timestamp": "2026-01-25T23:39:54.689567+00:00", "data": {"market": "0x44f67876759c44b763bb53f89b3c738756331b0a208672fc8db8a5f389230950", "price_changes": [{"asset_id": "32592218374784909301050372254273467546998719384564620545871759434640468645973", "price": "0.733", "size": "0", "side": "BUY", "hash": "1e9c81f42fda50c0f9ba33d7503161237e5a7a8b", "best_bid": "0.94", "best_ask": "0.986"}, {"asset_id": "1582298976410585403069729422280265608038484032857579102122167925665102997608", "price": "0.267", "size": "0", "side": "SELL", "hash": "138cae92dcc0aff67a2f5a6e3a0108cebc32ff86", "best_bid": "0.014", "best_ask": "0.06"}], "timestamp": "1769384394625", "event_type": "price_change"}}
{"_local_timestamp": "2026-01-25T23:39:54.707778+00:00", "data": {"market": "0x5b782c35d9cbd6e9d38597bd0af4e53d3263bde143e4d4ffdbd76d0a094f4be4", "price_changes": [{"asset_id": "48123308101524452666134421526726361469113858451786831367632481270457773825485", "price": "0.78", "size": "0", "side": "BUY", "hash": "3ebb3234625f5d591237539efcd91292b827dcc3", "best_bid": "0.91", "best_ask": "0.92"}, {"asset_id": "111803189967461986329215432128898000701874058405628301712422758141213653452479", "price": "0.22", "size": "0", "side": "SELL", "hash": "bc08fd5cc40c605003fa8058ab27254f97e0dcae", "best_bid": "0.08", "best_ask": "0.09"}], "timestamp": "1769384394635", "event_type": "price_change"}}
{"_local_timestamp": "2026-01-25T23:39:54.709286+00:00", "data": {"market": "0x44f67876759c44b763bb53f89b3c738756331b0a208672fc8db8a5f389230950", "price_changes": [{"asset_id": "32592218374784909301050372254273467546998719384564620545871759434640468645973", "price": "0.735", "size": "0", "side": "BUY", "hash": "a3127fc21d6f9ece31647f3f495eded94b5626ab", "best_bid": "0.94", "best_ask": "0.986"}, {"asset_id": "1582298976410585403069729422280265608038484032857579102122167925665102997608", "price": "0.265", "size": "0", "side": "SELL", "hash": "d239fccc516eb912b236fa25bddfef2be953d101", "best_bid": "0.014", "best_ask": "0.06"}], "timestamp": "1769384394635", "event_type": "price_change"}}
{"_local_timestamp": "2026-01-25T23:39:54.709925+00:00", "data": {"market": "0x0be3d4cc20250a7105206bc352af8b1c087df2ebd4f3b3927fabcdd8c81d792e", "price_changes": [{"asset_id": "87528913053522501048749446605646222127999765893905568199883777953288580503567", "price": "0.52", "size": "0", "side": "BUY", "hash": "7363e42690b0f7e427c8da4bd554d6b359c4057b", "best_bid": "0.65", "best_ask": "0.67"}, {"asset_id": "63149403073928211890844841868361708990331353150804831882114276975252031214656", "price": "0.48", "size": "0", "side": "SELL", "hash": "6f7e1a91e9027e58f84922cbe4706e400d04e4f0", "best_bid": "0.33", "best_ask": "0.35"}], "timestamp": "1769384394635", "event_type": "price_change"}}
{"_local_timestamp": "2026-01-25T23:39:54.710816+00:00", "data": {"market": "0x0be3d4cc20250a7105206bc352af8b1c087df2ebd4f3b3927fabcdd8c81d792e", "price_changes": [{"asset_id": "87528913053522501048749446605646222127999765893905568199883777953288580503567", "price": "0.21", "size": "323.8", "side": "BUY", "hash": "7363e42690b0f7e427c8da4bd554d6b359c4057b", "best_bid": "0.65", "best_ask": "0.67"}, {"asset_id": "63149403073928211890844841868361708990331353150804831882114276975252031214656", "price": "0.79", "size": "323.8", "side": "SELL", "hash": "6f7e1a91e9027e58f84922cbe4706e400d04e4f0", "best_bid": "0.33", "best_ask": "0.35"}], "timestamp": "1769384394635", "event_type": "price_change"}}
{"_local_timestamp": "2026-01-25T23:39:54.747395+00:00", "data": {"market": "0x9cacc164f8e79d815cc6714b0e5a04055f3bd5f6d05dc25f4265e7ffaa08dadc", "price_changes": [{"asset_id": "58983570136035430006949575067833187006601843982035390064418024195691336080349", "price": "0.2", "size": "120", "side": "BUY", "hash": "7b2aeff204d9372ec75cd9bd531522ea32f5dd8a", "best_bid": "0.52", "best_ask": "0.67"}, {"asset_id": "75665317756971232401732022054678279748154632967705732846841215435558615055352", "price": "0.8", "size": "120", "side": "SELL", "hash": "26732e0b2afc75515d5b93099eb24d5481fd937a", "best_bid": "0.33", "best_ask": "0.48"}], "timestamp": "1769384394650", "event_type": "price_change"}}
{"_local_timestamp": "2026-01-25T23:39:54.748160+00:00", "data": {"market": "0x44f67876759c44b763bb53f89b3c738756331b0a208672fc8db8a5f389230950", "price_changes": [{"asset_id": "32592218374784909301050372254273467546998719384564620545871759434640468645973", "price": "0.646", "size": "30", "side": "BUY", "hash": "1d42d907645dce77739a5ce627d7681d8f4279e8", "best_bid": "0.94", "best_ask": "0.986"}, {"asset_id": "1582298976410585403069729422280265608038484032857579102122167925665102997608", "price": "0.354", "size": "30", "side": "SELL", "hash": "b03f9c45825f39bb264f11dd876c77b0803518d1", "best_bid": "0.014", "best_ask": "0.06"}], "timestamp": "1769384394662", "event_type": "price_change"}}
{"_local_timestamp": "2026-01-25T23:39:54.748793+00:00", "data": {"market": "0x0be3d4cc20250a7105206bc352af8b1c087df2ebd4f3b3927fabcdd8c81d792e", "price_changes": [{"asset_id": "87528913053522501048749446605646222127999765893905568199883777953288580503567", "price": "0.31", "size": "25", "side": "BUY", "hash": "2207b7f0e790730589e33ae4b3739c41c544c6e4", "best_bid": "0.65", "best_ask": "0.67"}, {"asset_id": "63149403073928211890844841868361708990331353150804831882114276975252031214656", "price": "0.69", "size": "25", "side": "SELL", "hash": "f3bd4668443f870868309ac397e6902458b3b7ab", "best_bid": "0.33", "best_ask": "0.35"}], "timestamp": "1769384394662", "event_type": "price_change"}}
{"_local_timestamp": "2026-01-25T23:39:54.749365+00:00", "data": {"market": "0x5b782c35d9cbd6e9d38597bd0af4e53d3263bde143e4d4ffdbd76d0a094f4be4", "price_changes": [{"asset_id": "48123308101524452666134421526726361469113858451786831367632481270457773825485", "price": "0.49", "size": "30", "side": "BUY", "hash": "b409bb77dc195218c34407fcaad261348265252e", "best_bid": "0.91", "best_ask": "0.92"}, {"asset_id": "111803189967461986329215432128898000701874058405628301712422758141213653452479", "price": "0.51", "size": "30", "side": "SELL", "hash": "3c213fb70924f0d76053025be6f6da824317af88", "best_bid": "0.08", "best_ask": "0.09"}], "timestamp": "1769384394662", "event_type": "price_change"}}
{"_local_timestamp": "2026-01-25T23:39:54.750096+00:00", "data": {"market": "0x0be3d4cc20250a7105206bc352af8b1c087df2ebd4f3b3927fabcdd8c81d792e", "price_changes": [{"asset_id": "87528913053522501048749446605646222127999765893905568199883777953288580503567", "price": "0.35", "size": "20", "side": "BUY", "hash": "7ac8c6aecbf8ec95c5ad1fb29b6496befd9ab644", "best_bid": "0.65", "best_ask": "0.67"}, {"asset_id": "63149403073928211890844841868361708990331353150804831882114276975252031214656", "price": "0.65", "size": "20", "side": "SELL", "hash": "97885bde0d24743f757edba6ce362a37f4f5884c", "best_bid": "0.33", "best_ask": "0.35"}], "timestamp": "1769384394663", "event_type": "price_change"}}
{"_local_timestamp": "2026-01-25T23:39:54.750716+00:00", "data": {"market": "0x44f67876759c44b763bb53f89b3c738756331b0a208672fc8db8a5f389230950", "price_changes": [{"asset_id": "32592218374784909301050372254273467546998719384564620545871759434640468645973", "price": "0.453", "size": "500", "side": "BUY", "hash": "9e2406ee8ad6fcf18ca1b5691289a74672be7336", "best_bid": "0.94", "best_ask": "0.986"}, {"asset_id": "1582298976410585403069729422280265608038484032857579102122167925665102997608", "price": "0.547", "size": "500", "side": "SELL", "hash": "fa49818c8bfc01d92f2c29763a6dde74fc461fca", "best_bid": "0.014", "best_ask": "0.06"}], "timestamp": "1769384394682", "event_type": "price_change"}}
{"_local_timestamp": "2026-01-25T23:39:54.751404+00:00", "data": {"market": "0x0be3d4cc20250a7105206bc352af8b1c087df2ebd4f3b3927fabcdd8c81d792e", "price_changes": [{"asset_id": "87528913053522501048749446605646222127999765893905568199883777953288580503567", "price": "0.28", "size": "81.42", "side": "BUY", "hash": "b883a1830d0d5cebb80929f6839d395e03c86891", "best_bid": "0.65", "best_ask": "0.67"}, {"asset_id": "63149403073928211890844841868361708990331353150804831882114276975252031214656", "price": "0.72", "size": "81.42", "side": "SELL", "hash": "4396750a3cf690a5bf114453d0b931d93ef141f9", "best_bid": "0.33", "best_ask": "0.35"}], "timestamp": "1769384394682", "event_type": "price_change"}}
{"_local_timestamp": "2026-01-25T23:39:54.752183+00:00", "data": {"market": "0x44f67876759c44b763bb53f89b3c738756331b0a208672fc8db8a5f389230950", "price_changes": [{"asset_id": "32592218374784909301050372254273467546998719384564620545871759434640468645973", "price": "0.453", "size": "510", "side": "BUY", "hash": "2cafa74ec5f7c6eb9833f34d464fe4eda762246e", "best_bid": "0.94", "best_ask": "0.986"}, {"asset_id": "1582298976410585403069729422280265608038484032857579102122167925665102997608", "price": "0.547", "size": "510", "side": "SELL", "hash": "76d4f871aa47bdb2864f6e298ad7dd9774770ce4", "best_bid": "0.014", "best_ask": "0.06"}], "timestamp": "1769384394683", "event_type": "price_change"}}
{"_local_timestamp": "2026-01-25T23:39:54.773625+00:00", "data": {"market": "0x9cacc164f8e79d815cc6714b0e5a04055f3bd5f6d05dc25f4265e7ffaa08dadc", "price_changes": [{"asset_id": "58983570136035430006949575067833187006601843982035390064418024195691336080349", "price": "0.17", "size": "1652.94", "side": "BUY", "hash": "17a9de46fecf8d8e0a81a4311fa6834dcd8e73f8", "best_bid": "0.52", "best_ask": "0.67"}, {"asset_id": "75665317756971232401732022054678279748154632967705732846841215435558615055352", "price": "0.83", "size": "1652.94", "side": "SELL", "hash": "d0baedb56c3f9bc3c176ed396c709fc7b55d68ee", "best_bid": "0.33", "best_ask": "0.48"}], "timestamp": "1769384394708", "event_type": "price_change"}}
{"_local_timestamp": "2026-01-25T23:39:54.795232+00:00", "data": {"market": "0x44f67876759c44b763bb53f89b3c738756331b0a208672fc8db8a5f389230950", "price_changes": [{"asset_id": "32592218374784909301050372254273467546998719384564620545871759434640468645973", "price": "0.302", "size": "223", "side": "BUY", "hash": "e99ef54ff12f2dd8aa4a78b2db7277ea7a91e548", "best_bid": "0.94", "best_ask": "0.986"}, {"asset_id": "1582298976410585403069729422280265608038484032857579102122167925665102997608", "price": "0.698", "size": "223", "side": "SELL", "hash": "4c531fe247674e196ce9e35e72e4ffe8426626ef", "best_bid": "0.014", "best_ask": "0.06"}], "timestamp": "1769384394724", "event_type": "price_change"}}
{"_local_timestamp": "2026-01-25T23:39:54.827376+00:00", "data": {"market": "0x5b782c35d9cbd6e9d38597bd0af4e53d3263bde143e4d4ffdbd76d0a094f4be4", "price_changes": [{"asset_id": "48123308101524452666134421526726361469113858451786831367632481270457773825485", "price": "0.49", "size": "70", "side": "BUY", "hash": "644fa257492a4dcf995b6bb3ee1fefa32f3f2278", "best_bid": "0.91", "best_ask": "0.92"}, {"asset_id": "111803189967461986329215432128898000701874058405628301712422758141213653452479", "price": "0.51", "size": "70", "side": "SELL", "hash": "a48b801d77f867ff43df2bbe79618ee622bd0426", "best_bid": "0.08", "best_ask": "0.09"}], "timestamp": "1769384394750", "event_type": "price_change"}}
{"_local_timestamp": "2026-01-25T23:39:54.829148+00:00", "data": {"market": "0x44f67876759c44b763bb53f89b3c738756331b0a208672fc8db8a5f389230950", "price_changes": [{"asset_id": "32592218374784909301050372254273467546998719384564620545871759434640468645973", "price": "0.646", "size": "70", "side": "BUY", "hash": "c5eab6db063aff2ed5a6aa3954d1b68d376f0a53", "best_bid": "0.94", "best_ask": "0.986"}, {"asset_id": "1582298976410585403069729422280265608038484032857579102122167925665102997608", "price": "0.354", "size": "70", "side": "SELL", "hash": "f4585892a8ce24c4806f1a6af6ff43f5a89dc360", "best_bid": "0.014", "best_ask": "0.06"}], "timestamp": "1769384394750", "event_type": "price_change"}}
{"_local_timestamp": "2026-01-25T23:39:54.831699+00:00", "data": {"market": "0x0be3d4cc20250a7105206bc352af8b1c087df2ebd4f3b3927fabcdd8c81d792e", "price_changes": [{"asset_id": "87528913053522501048749446605646222127999765893905568199883777953288580503567", "price": "0.31", "size": "50", "side": "BUY", "hash": "0b559f71f80e6120e251911b6ad4afa8c5bdec4c", "best_bid": "0.65", "best_ask": "0.67"}, {"asset_id": "63149403073928211890844841868361708990331353150804831882114276975252031214656", "price": "0.69", "size": "50", "side": "SELL", "hash": "43927b7b9f43aac5330af44d2bcabec014d9ad5a", "best_bid": "0.33", "best_ask": "0.35"}], "timestamp": "1769384394750", "event_type": "price_change"}}
{"_local_timestamp": "2026-01-25T23:39:54.832374+00:00", "data": {"market": "0x46e08dad4b1370947613b81f2ba28a23226504a333ec7e42de877d6ba6cc59d0", "price_changes": [{"asset_id": "85467679028197532287128360159828743243379157810773026071193309107969652317045", "price": "0.544", "size": "407", "side": "BUY", "hash": "d29e8f4c0193b052ce8b79d0e419daf4274801ab", "best_bid": "0.958", "best_ask": "0.964"}, {"asset_id": "113369140136913812777925497644561662667789653912765877043929720445901767848122", "price": "0.456", "size": "407", "side": "SELL", "hash": "2e46a04fc0332b81e808aa0e54cde4139356df3c", "best_bid": "0.036", "best_ask": "0.042"}], "timestamp": "1769384394750", "event_type": "price_change"}}
{"_local_timestamp": "2026-01-25T23:39:54.832981+00:00", "data": {"market": "0x9cacc164f8e79d815cc6714b0e5a04055f3bd5f6d05dc25f4265e7ffaa08dadc", "price_changes": [{"asset_id": "58983570136035430006949575067833187006601843982035390064418024195691336080349", "price": "0.79", "size": "30", "side": "SELL", "hash": "bc8dea5c8e2068ba98b793eb6e1b7c2df99fd3f0", "best_bid": "0.52", "best_ask": "0.67"}, {"asset_id": "75665317756971232401732022054678279748154632967705732846841215435558615055352", "price": "0.21", "size": "30", "side": "BUY", "hash": "c32301bfe1d7f8417eb5bcb0dc1657c0e7dd9a45", "best_bid": "0.33", "best_ask": "0.48"}], "timestamp": "1769384394755", "event_type": "price_change"}}
{"_local_timestamp": "2026-01-25T23:39:54.834504+00:00", "data": {"market": "0x9cacc164f8e79d815cc6714b0e5a04055f3bd5f6d05dc25f4265e7ffaa08dadc", "price_changes": [{"asset_id": "58983570136035430006949575067833187006601843982035390064418024195691336080349", "price": "0.15", "size": "186.66", "side": "BUY", "hash": "97854e938d66edf3fc6dd22b102da90b14cf0963", "best_bid": "0.52", "best_ask": "0.67"}, {"asset_id": "75665317756971232401732022054678279748154632967705732846841215435558615055352", "price": "0.85", "size": "186.66", "side": "SELL", "hash": "7e3d0362fb236eefc472e802326d8f4c6e80a2e3", "best_bid": "0.33", "best_ask": "0.48"}], "timestamp": "1769384394767", "event_type": "price_change"}}
{"_local_timestamp": "2026-01-25T23:39:54.866833+00:00", "data": {"market": "0x9cacc164f8e79d815cc6714b0e5a04055f3bd5f6d05dc25f4265e7ffaa08dadc", "price_changes": [{"asset_id": "75665317756971232401732022054678279748154632967705732846841215435558615055352", "price": "0.12", "size": "225", "side": "BUY", "hash": "bdab075cc2c91e22c859c303375a4c30a3d41827", "best_bid": "0.33", "best_ask": "0.48"}, {"asset_id": "58983570136035430006949575067833187006601843982035390064418024195691336080349", "price": "0.88", "size": "225", "side": "SELL", "hash": "e0c58d2584cdf6f2664af723685602d28c185531", "best_bid": "0.52", "best_ask": "0.67"}], "timestamp": "1769384394803", "event_type": "price_change"}}
{"_local_timestamp": "2026-01-25T23:39:54.874546+00:00", "data": {"market": "0x9cacc164f8e79d815cc6714b0e5a04055f3bd5f6d05dc25f4265e7ffaa08dadc", "price_changes": [{"asset_id": "75665317756971232401732022054678279748154632967705732846841215435558615055352", "price": "0.07", "size": "0", "side": "BUY", "hash": "bdab075cc2c91e22c859c303375a4c30a3d41827", "best_bid": "0.33", "best_ask": "0.48"}, {"asset_id": "58983570136035430006949575067833187006601843982035390064418024195691336080349", "price": "0.93", "size": "0", "side": "SELL", "hash": "e0c58d2584cdf6f2664af723685602d28c185531", "best_bid": "0.52", "best_ask": "0.67"}], "timestamp": "1769384394803", "event_type": "price_change"}}
{"_local_timestamp": "2026-01-25T23:39:54.875239+00:00", "data": {"market": "0x9cacc164f8e79d815cc6714b0e5a04055f3bd5f6d05dc25f4265e7ffaa08dadc", "price_changes": [{"asset_id": "75665317756971232401732022054678279748154632967705732846841215435558615055352", "price": "0.17", "size": "0", "side": "BUY", "hash": "bdab075cc2c91e22c859c303375a4c30a3d41827", "best_bid": "0.33", "best_ask": "0.48"}, {"asset_id": "58983570136035430006949575067833187006601843982035390064418024195691336080349", "price": "0.83", "size": "0", "side": "SELL", "hash": "e0c58d2584cdf6f2664af723685602d28c185531", "best_bid": "0.52", "best_ask": "0.67"}], "timestamp": "1769384394803", "event_type": "price_change"}}
{"_local_timestamp": "2026-01-25T23:39:54.875847+00:00", "data": {"market": "0x9cacc164f8e79d815cc6714b0e5a04055f3bd5f6d05dc25f4265e7ffaa08dadc", "price_changes": [{"asset_id": "75665317756971232401732022054678279748154632967705732846841215435558615055352", "price": "0.05", "size": "0", "side": "BUY", "hash": "bdab075cc2c91e22c859c303375a4c30a3d41827", "best_bid": "0.33", "best_ask": "0.48"}, {"asset_id": "58983570136035430006949575067833187006601843982035390064418024195691336080349", "price": "0.95", "size": "0", "side": "SELL", "hash": "e0c58d2584cdf6f2664af723685602d28c185531", "best_bid": "0.52", "best_ask": "0.67"}], "timestamp": "1769384394803", "event_type": "price_change"}}
{"_local_timestamp": "2026-01-25T23:39:54.876422+00:00", "data": {"market": "0x9cacc164f8e79d815cc6714b0e5a04055f3bd5f6d05dc25f4265e7ffaa08dadc", "price_changes": [{"asset_id": "75665317756971232401732022054678279748154632967705732846841215435558615055352", "price": "0.1", "size": "0", "side": "BUY", "hash": "bdab075cc2c91e22c859c303375a4c30a3d41827", "best_bid": "0.33", "best_ask": "0.48"}, {"asset_id": "58983570136035430006949575067833187006601843982035390064418024195691336080349", "price": "0.9", "size": "0", "side": "SELL", "hash": "e0c58d2584cdf6f2664af723685602d28c185531", "best_bid": "0.52", "best_ask": "0.67"}], "timestamp": "1769384394803", "event_type": "price_change"}}
{"_local_timestamp": "2026-01-25T23:39:54.877002+00:00", "data": {"market": "0x9cacc164f8e79d815cc6714b0e5a04055f3bd5f6d05dc25f4265e7ffaa08dadc", "price_changes": [{"asset_id": "75665317756971232401732022054678279748154632967705732846841215435558615055352", "price": "0.19", "size": "350", "side": "BUY", "hash": "bdab075cc2c91e22c859c303375a4c30a3d41827", "best_bid": "0.33", "best_ask": "0.48"}, {"asset_id": "58983570136035430006949575067833187006601843982035390064418024195691336080349", "price": "0.81", "size": "350", "side": "SELL", "hash": "e0c58d2584cdf6f2664af723685602d28c185531", "best_bid": "0.52", "best_ask": "0.67"}], "timestamp": "1769384394803", "event_type": "price_change"}}
{"_local_timestamp": "2026-01-25T23:39:54.877587+00:00", "data": {"market": "0x9cacc164f8e79d815cc6714b0e5a04055f3bd5f6d05dc25f4265e7ffaa08dadc", "price_changes": [{"asset_id": "75665317756971232401732022054678279748154632967705732846841215435558615055352", "price": "0.14", "size": "0", "side": "BUY", "hash": "bdab075cc2c91e22c859c303375a4c30a3d41827", "best_bid": "0.33", "best_ask": "0.48"}, {"asset_id": "58983570136035430006949575067833187006601843982035390064418024195691336080349", "price": "0.86", "size": "0", "side": "SELL", "hash": "e0c58d2584cdf6f2664af723685602d28c185531", "best_bid": "0.52", "best_ask": "0.67"}], "timestamp": "1769384394803", "event_type": "price_change"}}
{"_local_timestamp": "2026-01-25T23:39:54.878252+00:00", "data": {"market": "0x44f67876759c44b763bb53f89b3c738756331b0a208672fc8db8a5f389230950", "price_changes": [{"asset_id": "32592218374784909301050372254273467546998719384564620545871759434640468645973", "price": "0.302", "size": "100", "side": "BUY", "hash": "29f3feb73d4aeadd459464c485915298cda8647e", "best_bid": "0.94", "best_ask": "0.986"}, {"asset_id": "1582298976410585403069729422280265608038484032857579102122167925665102997608", "price": "0.698", "size": "100", "side": "SELL", "hash": "c8fc0cb73420108247d3d3dc482f3da77acb95f4", "best_bid": "0.014", "best_ask": "0.06"}], "timestamp": "1769384394805", "event_type": "price_change"}}
{"_local_timestamp": "2026-01-25T23:39:54.878894+00:00", "data": {"market": "0x46e08dad4b1370947613b81f2ba28a23226504a333ec7e42de877d6ba6cc59d0", "price_changes": [{"asset_id": "85467679028197532287128360159828743243379157810773026071193309107969652317045", "price": "0.543", "size": "30", "side": "BUY", "hash": "2cff2cfddd95b6c69fc7a1a65b72c05b71647776", "best_bid": "0.958", "best_ask": "0.964"}, {"asset_id": "113369140136913812777925497644561662667789653912765877043929720445901767848122", "price": "0.457", "size": "30", "side": "SELL", "hash": "4b7df87fe1ae2063027f50cee2ba4baecfd9b55c", "best_bid": "0.036", "best_ask": "0.042"}], "timestamp": "1769384394805", "event_type": "price_change"}}
{"_local_timestamp": "2026-01-25T23:39:54.891322+00:00", "data": {"market": "0x9cacc164f8e79d815cc6714b0e5a04055f3bd5f6d05dc25f4265e7ffaa08dadc", "price_changes": [{"asset_id": "58983570136035430006949575067833187006601843982035390064418024195691336080349", "price": "0.12", "size": "266.66", "side": "BUY", "hash": "31255d8e17171e02867e2856057ae40395b8c9bb", "best_bid": "0.52", "best_ask": "0.67"}, {"asset_id": "75665317756971232401732022054678279748154632967705732846841215435558615055352", "price": "0.88", "size": "266.66", "side": "SELL", "hash": "4a62f5902ccf3288c7c9cef3604364cee5a3a3a9", "best_bid": "0.33", "best_ask": "0.48"}], "timestamp": "1769384394823", "event_type": "price_change"}}
{"_local_timestamp": "2026-01-25T23:39:54.906134+00:00", "data": {"market": "0x9cacc164f8e79d815cc6714b0e5a04055f3bd5f6d05dc25f4265e7ffaa08dadc", "price_changes": [{"asset_id": "58983570136035430006949575067833187006601843982035390064418024195691336080349", "price": "0.15", "size": "0", "side": "BUY", "hash": "77c0d38f1d68a9c587187e1e3e81349277ab6d77", "best_bid": "0.52", "best_ask": "0.67"}, {"asset_id": "75665317756971232401732022054678279748154632967705732846841215435558615055352", "price": "0.85", "size": "0", "side": "SELL", "hash": "88b0cc905ad891679f08b6d49e5d91e693a1a1f3", "best_bid": "0.33", "best_ask": "0.48"}], "timestamp": "1769384394836", "event_type": "price_change"}}
{"_local_timestamp": "2026-01-25T23:39:54.906804+00:00", "data": {"market": "0x9cacc164f8e79d815cc6714b0e5a04055f3bd5f6d05dc25f4265e7ffaa08dadc", "price_changes": [{"asset_id": "58983570136035430006949575067833187006601843982035390064418024195691336080349", "price": "0.17", "size": "1500", "side": "BUY", "hash": "77c0d38f1d68a9c587187e1e3e81349277ab6d77", "best_bid": "0.52", "best_ask": "0.67"}, {"asset_id": "75665317756971232401732022054678279748154632967705732846841215435558615055352", "price": "0.83", "size": "1500", "side": "SELL", "hash": "88b0cc905ad891679f08b6d49e5d91e693a1a1f3", "best_bid": "0.33", "best_ask": "0.48"}], "timestamp": "1769384394836", "event_type": "price_change"}}
{"_local_timestamp": "2026-01-25T23:39:54.907388+00:00", "data": {"market": "0x9cacc164f8e79d815cc6714b0e5a04055f3bd5f6d05dc25f4265e7ffaa08dadc", "price_changes": [{"asset_id": "58983570136035430006949575067833187006601843982035390064418024195691336080349", "price": "0.12", "size": "0", "side": "BUY", "hash": "77c0d38f1d68a9c587187e1e3e81349277ab6d77", "best_bid": "0.52", "best_ask": "0.67"}, {"asset_id": "75665317756971232401732022054678279748154632967705732846841215435558615055352", "price": "0.88", "size": "0", "side": "SELL", "hash": "88b0cc905ad891679f08b6d49e5d91e693a1a1f3", "best_bid": "0.33", "best_ask": "0.48"}], "timestamp": "1769384394836", "event_type": "price_change"}}
{"_local_timestamp": "2026-01-25T23:39:54.907968+00:00", "data": {"market": "0x9cacc164f8e79d815cc6714b0e5a04055f3bd5f6d05dc25f4265e7ffaa08dadc", "price_changes": [{"asset_id": "58983570136035430006949575067833187006601843982035390064418024195691336080349", "price": "0.2", "size": "0", "side": "BUY", "hash": "77c0d38f1d68a9c587187e1e3e81349277ab6d77", "best_bid": "0.52", "best_ask": "0.67"}, {"asset_id": "75665317756971232401732022054678279748154632967705732846841215435558615055352", "price": "0.8", "size": "0", "side": "SELL", "hash": "88b0cc905ad891679f08b6d49e5d91e693a1a1f3", "best_bid": "0.33", "best_ask": "0.48"}], "timestamp": "1769384394836", "event_type": "price_change"}}
{"_local_timestamp": "2026-01-25T23:39:54.908543+00:00", "data": {"market": "0x9cacc164f8e79d815cc6714b0e5a04055f3bd5f6d05dc25f4265e7ffaa08dadc", "price_changes": [{"asset_id": "58983570136035430006949575067833187006601843982035390064418024195691336080349", "price": "0.23", "size": "200", "side": "BUY", "hash": "77c0d38f1d68a9c587187e1e3e81349277ab6d77", "best_bid": "0.52", "best_ask": "0.67"}, {"asset_id": "75665317756971232401732022054678279748154632967705732846841215435558615055352", "price": "0.77", "size": "200", "side": "SELL", "hash": "88b0cc905ad891679f08b6d49e5d91e693a1a1f3", "best_bid": "0.33", "best_ask": "0.48"}], "timestamp": "1769384394836", "event_type": "price_change"}}
{"_local_timestamp": "2026-01-25T23:39:54.909127+00:00", "data": {"market": "0x44f67876759c44b763bb53f89b3c738756331b0a208672fc8db8a5f389230950", "price_changes": [{"asset_id": "32592218374784909301050372254273467546998719384564620545871759434640468645973", "price": "0.451", "size": "60", "side": "BUY", "hash": "fcd117839acec1c4156dc0d855afcf3df39fba91", "best_bid": "0.94", "best_ask": "0.986"}, {"asset_id": "1582298976410585403069729422280265608038484032857579102122167925665102997608", "price": "0.549", "size": "60", "side": "SELL", "hash": "fdc83ef9f4a39d6cc9957e528822bc5620ff1f7b", "best_bid": "0.014", "best_ask": "0.06"}], "timestamp": "1769384394839", "event_type": "price_change"}}
{"_local_timestamp": "2026-01-25T23:39:54.909783+00:00", "data": {"market": "0x46e08dad4b1370947613b81f2ba28a23226504a333ec7e42de877d6ba6cc59d0", "price_changes": [{"asset_id": "85467679028197532287128360159828743243379157810773026071193309107969652317045", "price": "0.542", "size": "5", "side": "BUY", "hash": "434fc28745697861fbce11bbe30f6c2cb26fe0a4", "best_bid": "0.958", "best_ask": "0.964"}, {"asset_id": "113369140136913812777925497644561662667789653912765877043929720445901767848122", "price": "0.458", "size": "5", "side": "SELL", "hash": "fa7f5afd82abf322635d40bc065b647683dac3c0", "best_bid": "0.036", "best_ask": "0.042"}], "timestamp": "1769384394839", "event_type": "price_change"}}
{"_local_timestamp": "2026-01-25T23:39:54.945484+00:00", "data": {"market": "0x9cacc164f8e79d815cc6714b0e5a04055f3bd5f6d05dc25f4265e7ffaa08dadc", "price_changes": [{"asset_id": "58983570136035430006949575067833187006601843982035390064418024195691336080349", "price": "0.09", "size": "383.01", "side": "BUY", "hash": "4a612bacdc6d1c5f393c255103f80f679f352718", "best_bid": "0.52", "best_ask": "0.67"}, {"asset_id": "75665317756971232401732022054678279748154632967705732846841215435558615055352", "price": "0.91", "size": "383.01", "side": "SELL", "hash": "88044e385a1929ccf7afcb7e544f9287b013bf23", "best_bid": "0.33", "best_ask": "0.48"}], "timestamp": "1769384394875", "event_type": "price_change"}}
{"_local_timestamp": "2026-01-25T23:39:54.953051+00:00", "data": {"market": "0x44f67876759c44b763bb53f89b3c738756331b0a208672fc8db8a5f389230950", "price_changes": [{"asset_id": "32592218374784909301050372254273467546998719384564620545871759434640468645973", "price": "0.352", "size": "357.66", "side": "BUY", "hash": "246fa966be6e4f7ed6c7aacbd0d8fc11cd289182", "best_bid": "0.94", "best_ask": "0.986"}, {"asset_id": "1582298976410585403069729422280265608038484032857579102122167925665102997608", "price": "0.648", "size": "357.66", "side": "SELL", "hash": "e83ae8ad457d05cbcc5fae09cffbab6c2cb220e1", "best_bid": "0.014", "best_ask": "0.06"}], "timestamp": "1769384394885", "event_type": "price_change"}}
{"_local_timestamp": "2026-01-25T23:39:54.991628+00:00", "data": {"market": "0x9cacc164f8e79d815cc6714b0e5a04055f3bd5f6d05dc25f4265e7ffaa08dadc", "price_changes": [{"asset_id": "58983570136035430006949575067833187006601843982035390064418024195691336080349", "price": "0.06", "size": "600", "side": "BUY", "hash": "0a915ccd44815658719082233228bcb42c534fb9", "best_bid": "0.52", "best_ask": "0.67"}, {"asset_id": "75665317756971232401732022054678279748154632967705732846841215435558615055352", "price": "0.94", "size": "600", "side": "SELL", "hash": "3c5e5b1fdb3e9e8eb923a6ab64ba9b72922d16b4", "best_bid": "0.33", "best_ask": "0.48"}], "timestamp": "1769384394924", "event_type": "price_change"}}
{"_local_timestamp": "2026-01-25T23:39:55.035409+00:00", "data": {"market": "0x46e08dad4b1370947613b81f2ba28a23226504a333ec7e42de877d6ba6cc59d0", "price_changes": [{"asset_id": "85467679028197532287128360159828743243379157810773026071193309107969652317045", "price": "0.545", "size": "391", "side": "BUY", "hash": "96a07951d4870917380e040430eb3122975924b4", "best_bid": "0.958", "best_ask": "0.964"}, {"asset_id": "113369140136913812777925497644561662667789653912765877043929720445901767848122", "price": "0.455", "size": "391", "side": "SELL", "hash": "c2caef4720f09a93843ee3df7ebc938f06c97a7b", "best_bid": "0.036", "best_ask": "0.042"}], "timestamp": "1769384394962", "event_type": "price_change"}}
{"_local_timestamp": "2026-01-25T23:39:55.069977+00:00", "data": {"market": "0x44f67876759c44b763bb53f89b3c738756331b0a208672fc8db8a5f389230950", "price_changes": [{"asset_id": "32592218374784909301050372254273467546998719384564620545871759434640468645973", "price": "0.352", "size": "490.66", "side": "BUY", "hash": "85689054debc2ae3267457cdb021d5d0b0725d54", "best_bid": "0.94", "best_ask": "0.986"}, {"asset_id": "1582298976410585403069729422280265608038484032857579102122167925665102997608", "price": "0.648", "size": "490.66", "side": "SELL", "hash": "ee3dc782a1c0c0f7e1ab87bd66e218f2023f97a5", "best_bid": "0.014", "best_ask": "0.06"}], "timestamp": "1769384394962", "event_type": "price_change"}}
{"_local_timestamp": "2026-01-25T23:39:55.071808+00:00", "data": {"market": "0x44f67876759c44b763bb53f89b3c738756331b0a208672fc8db8a5f389230950", "price_changes": [{"asset_id": "32592218374784909301050372254273467546998719384564620545871759434640468645973", "price": "0.454", "size": "220", "side": "BUY", "hash": "0638ad889983f636c703d80430b69e706956e914", "best_bid": "0.94", "best_ask": "0.986"}, {"asset_id": "1582298976410585403069729422280265608038484032857579102122167925665102997608", "price": "0.546", "size": "220", "side": "SELL", "hash": "a3a26d36205dedd62b6677c5289ffd2bcb95ebf9", "best_bid": "0.014", "best_ask": "0.06"}], "timestamp": "1769384394963", "event_type": "price_change"}}
{"_local_timestamp": "2026-01-25T23:39:55.072460+00:00", "data": {"market": "0x44f67876759c44b763bb53f89b3c738756331b0a208672fc8db8a5f389230950", "price_changes": [{"asset_id": "32592218374784909301050372254273467546998719384564620545871759434640468645973", "price": "0.454", "size": "230", "side": "BUY", "hash": "305d296ea1a83f7611baca2dc0cf2ef038abdee2", "best_bid": "0.94", "best_ask": "0.986"}, {"asset_id": "1582298976410585403069729422280265608038484032857579102122167925665102997608", "price": "0.546", "size": "230", "side": "SELL", "hash": "bf32b8909d31a892732ec1b3816218495f30d9ea", "best_bid": "0.014", "best_ask": "0.06"}], "timestamp": "1769384394964", "event_type": "price_change"}}
{"_local_timestamp": "2026-01-25T23:39:55.073076+00:00", "data": {"market": "0x44f67876759c44b763bb53f89b3c738756331b0a208672fc8db8a5f389230950", "price_changes": [{"asset_id": "32592218374784909301050372254273467546998719384564620545871759434640468645973", "price": "0.454", "size": "245", "side": "BUY", "hash": "b965202a7eb1eab37b7e8decf3f3a38b1d6739a5", "best_bid": "0.94", "best_ask": "0.986"}, {"asset_id": "1582298976410585403069729422280265608038484032857579102122167925665102997608", "price": "0.546", "size": "245", "side": "SELL", "hash": "7dbc2d8cbf8def850337b87eb88ecd4f1f44e0f2", "best_bid": "0.014", "best_ask": "0.06"}], "timestamp": "1769384394965", "event_type": "price_change"}}
{"_local_timestamp": "2026-01-25T23:39:55.203334+00:00", "data": {"market": "0x44f67876759c44b763bb53f89b3c738756331b0a208672fc8db8a5f389230950", "price_changes": [{"asset_id": "32592218374784909301050372254273467546998719384564620545871759434640468645973", "price": "0.453", "size": "10", "side": "BUY", "hash": "ae2603a7eda3bb2b51fbac7f4562795a2f773c34", "best_bid": "0.94", "best_ask": "0.986"}, {"asset_id": "1582298976410585403069729422280265608038484032857579102122167925665102997608", "price": "0.547", "size": "10", "side": "SELL", "hash": "0dd6d1c7ff9554f79e2e6597e40999a2019663b6", "best_bid": "0.014", "best_ask": "0.06"}], "timestamp": "1769384395133", "event_type": "price_change"}}
{"_local_timestamp": "2026-01-25T23:39:55.314039+00:00", "data": {"market": "0x46e08dad4b1370947613b81f2ba28a23226504a333ec7e42de877d6ba6cc59d0", "price_changes": [{"asset_id": "85467679028197532287128360159828743243379157810773026071193309107969652317045", "price": "0.544", "size": "40", "side": "BUY", "hash": "394a42e56a967ae1ba355c8668e707fa68f5bad6", "best_bid": "0.958", "best_ask": "0.964"}, {"asset_id": "113369140136913812777925497644561662667789653912765877043929720445901767848122", "price": "0.456", "size": "40", "side": "SELL", "hash": "902a08221d48413a71c21f8a1fdec0c639df736e", "best_bid": "0.036", "best_ask": "0.042"}], "timestamp": "1769384395249", "event_type": "price_change"}}
{"_local_timestamp": "2026-01-25T23:39:55.453284+00:00", "data": {"market": "0x46e08dad4b1370947613b81f2ba28a23226504a333ec7e42de877d6ba6cc59d0", "price_changes": [{"asset_id": "85467679028197532287128360159828743243379157810773026071193309107969652317045", "price": "0.546", "size": "386", "side": "BUY", "hash": "4e6ceba7a097aa1e3adead87a6de8055105a6d08", "best_bid": "0.958", "best_ask": "0.964"}, {"asset_id": "113369140136913812777925497644561662667789653912765877043929720445901767848122", "price": "0.454", "size": "386", "side": "SELL", "hash": "37862cf0aaed70d44aa165dd7465257f1eef4379", "best_bid": "0.036", "best_ask": "0.042"}], "timestamp": "1769384395380", "event_type": "price_change"}}
{"_local_timestamp": "2026-01-25T23:39:55.486662+00:00", "data": {"market": "0x44f67876759c44b763bb53f89b3c738756331b0a208672fc8db8a5f389230950", "price_changes": [{"asset_id": "32592218374784909301050372254273467546998719384564620545871759434640468645973", "price": "0.352", "size": "199.66", "side": "BUY", "hash": "86fecf33e626d1e76f4d27a05fe15e943a65aed4", "best_bid": "0.94", "best_ask": "0.986"}, {"asset_id": "1582298976410585403069729422280265608038484032857579102122167925665102997608", "price": "0.648", "size": "199.66", "side": "SELL", "hash": "58efff143daff0330eb6d73a7370a37515942ece", "best_bid": "0.014", "best_ask": "0.06"}], "timestamp": "1769384395422", "event_type": "price_change"}}
{"_local_timestamp": "2026-01-25T23:39:55.554474+00:00", "data": {"market": "0x46e08dad4b1370947613b81f2ba28a23226504a333ec7e42de877d6ba6cc59d0", "price_changes": [{"asset_id": "85467679028197532287128360159828743243379157810773026071193309107969652317045", "price": "0.545", "size": "25", "side": "BUY", "hash": "856f76f69f02b52eac3317a0244eedcf67c215eb", "best_bid": "0.958", "best_ask": "0.964"}, {"asset_id": "113369140136913812777925497644561662667789653912765877043929720445901767848122", "price": "0.455", "size": "25", "side": "SELL", "hash": "cfa2a29344f5fb1ade05d52b026e0d55b4a4209b", "best_bid": "0.036", "best_ask": "0.042"}], "timestamp": "1769384395485", "event_type": "price_change"}}
{"_local_timestamp": "2026-01-25T23:39:55.600526+00:00", "data": {"market": "0x44f67876759c44b763bb53f89b3c738756331b0a208672fc8db8a5f389230950", "price_changes": [{"asset_id": "32592218374784909301050372254273467546998719384564620545871759434640468645973", "price": "0.34", "size": "233", "side": "BUY", "hash": "a9c7f1e78c5404f37e15b50db88ad95d8d4f3ad4", "best_bid": "0.94", "best_ask": "0.986"}, {"asset_id": "1582298976410585403069729422280265608038484032857579102122167925665102997608", "price": "0.66", "size": "233", "side": "SELL", "hash": "4e2e2d7ad58a5a450e7ba323b233463364606f9e", "best_bid": "0.014", "best_ask": "0.06"}], "timestamp": "1769384395537", "event_type": "price_change"}}
{"_local_timestamp": "2026-01-25T23:39:55.641911+00:00", "data": {"market": "0x46e08dad4b1370947613b81f2ba28a23226504a333ec7e42de877d6ba6cc59d0", "price_changes": [{"asset_id": "85467679028197532287128360159828743243379157810773026071193309107969652317045", "price": "0.547", "size": "365", "side": "BUY", "hash": "0e3a6ee0dd7725842b379a6c2294d25e3f9c0437", "best_bid": "0.958", "best_ask": "0.964"}, {"asset_id": "113369140136913812777925497644561662667789653912765877043929720445901767848122", "price": "0.453", "size": "365", "side": "SELL", "hash": "ea18ddee8f3eee182e0483feedd516875503f8c4", "best_bid": "0.036", "best_ask": "0.042"}], "timestamp": "1769384395562", "event_type": "price_change"}}
{"_local_timestamp": "2026-01-25T23:39:55.930765+00:00", "data": {"market": "0x0be3d4cc20250a7105206bc352af8b1c087df2ebd4f3b3927fabcdd8c81d792e", "price_changes": [{"asset_id": "87528913053522501048749446605646222127999765893905568199883777953288580503567", "price": "0.53", "size": "0", "side": "BUY", "hash": "25f5b20886eee630e81d032e395f267800d12833", "best_bid": "0.65", "best_ask": "0.67"}, {"asset_id": "63149403073928211890844841868361708990331353150804831882114276975252031214656", "price": "0.47", "size": "0", "side": "SELL", "hash": "3a80dffd655b7b0e8261ae5e89ff576280c16299", "best_bid": "0.33", "best_ask": "0.35"}], "timestamp": "1769384395865", "event_type": "price_change"}}
{"_local_timestamp": "2026-01-25T23:39:55.931618+00:00", "data": {"market": "0x44f67876759c44b763bb53f89b3c738756331b0a208672fc8db8a5f389230950", "price_changes": [{"asset_id": "32592218374784909301050372254273467546998719384564620545871759434640468645973", "price": "0.737", "size": "0", "side": "BUY", "hash": "afbe5cdb21d9f81e58ce5e9a0a9bffcd910c4ac0", "best_bid": "0.94", "best_ask": "0.986"}, {"asset_id": "1582298976410585403069729422280265608038484032857579102122167925665102997608", "price": "0.263", "size": "0", "side": "SELL", "hash": "b57b74abbd3a59cb603dd4b1cf6164a6c56f8939", "best_bid": "0.014", "best_ask": "0.06"}], "timestamp": "1769384395865", "event_type": "price_change"}}
{"_local_timestamp": "2026-01-25T23:39:55.932285+00:00", "data": {"market": "0x5b782c35d9cbd6e9d38597bd0af4e53d3263bde143e4d4ffdbd76d0a094f4be4", "price_changes": [{"asset_id": "48123308101524452666134421526726361469113858451786831367632481270457773825485", "price": "0.66", "size": "0", "side": "BUY", "hash": "afc91971f71e38f24074e271e5254a620d543326", "best_bid": "0.91", "best_ask": "0.92"}, {"asset_id": "111803189967461986329215432128898000701874058405628301712422758141213653452479", "price": "0.34", "size": "0", "side": "SELL", "hash": "67e70f56236e5d034fae72f9b9b38417911ec940", "best_bid": "0.08", "best_ask": "0.09"}], "timestamp": "1769384395865", "event_type": "price_change"}}
{"_local_timestamp": "2026-01-25T23:39:55.939987+00:00", "data": {"market": "0x46e08dad4b1370947613b81f2ba28a23226504a333ec7e42de877d6ba6cc59d0", "price_changes": [{"asset_id": "85467679028197532287128360159828743243379157810773026071193309107969652317045", "price": "0.546", "size": "366", "side": "BUY", "hash": "e3826b23329b3c9d28a3813192f90c9df4ca6e28", "best_bid": "0.958", "best_ask": "0.964"}, {"asset_id": "113369140136913812777925497644561662667789653912765877043929720445901767848122", "price": "0.454", "size": "366", "side": "SELL", "hash": "5ecf23b2bfe724e47b88e0c19150f85bd114dd2d", "best_bid": "0.036", "best_ask": "0.042"}], "timestamp": "1769384395865", "event_type": "price_change"}}
{"_local_timestamp": "2026-01-25T23:39:55.962091+00:00", "data": {"market": "0x44f67876759c44b763bb53f89b3c738756331b0a208672fc8db8a5f389230950", "price_changes": [{"asset_id": "32592218374784909301050372254273467546998719384564620545871759434640468645973", "price": "0.68", "size": "20", "side": "BUY", "hash": "307d0071c1e8817b2d1ed1a14cb147b6fd55efc5", "best_bid": "0.94", "best_ask": "0.986"}, {"asset_id": "1582298976410585403069729422280265608038484032857579102122167925665102997608", "price": "0.32", "size": "20", "side": "SELL", "hash": "748854416c0fc2080345780015e043d36f6a4b1d", "best_bid": "0.014", "best_ask": "0.06"}], "timestamp": "1769384395892", "event_type": "price_change"}}
{"_local_timestamp": "2026-01-25T23:39:55.969514+00:00", "data": {"market": "0x0be3d4cc20250a7105206bc352af8b1c087df2ebd4f3b3927fabcdd8c81d792e", "price_changes": [{"asset_id": "87528913053522501048749446605646222127999765893905568199883777953288580503567", "price": "0.31", "size": "70", "side": "BUY", "hash": "e3fc0b6df149a86839c69c1d555dda7442daa7ca", "best_bid": "0.65", "best_ask": "0.67"}, {"asset_id": "63149403073928211890844841868361708990331353150804831882114276975252031214656", "price": "0.69", "size": "70", "side": "SELL", "hash": "4bef2f0376f79eed07c3ede9560320d6ca5b6534", "best_bid": "0.33", "best_ask": "0.35"}], "timestamp": "1769384395897", "event_type": "price_change"}}
{"_local_timestamp": "2026-01-25T23:39:55.970223+00:00", "data": {"market": "0x5b782c35d9cbd6e9d38597bd0af4e53d3263bde143e4d4ffdbd76d0a094f4be4", "price_changes": [{"asset_id": "48123308101524452666134421526726361469113858451786831367632481270457773825485", "price": "0.5", "size": "20", "side": "BUY", "hash": "dd946595867d1750573a9cbbb81556896b89f82e", "best_bid": "0.91", "best_ask": "0.92"}, {"asset_id": "111803189967461986329215432128898000701874058405628301712422758141213653452479", "price": "0.5", "size": "20", "side": "SELL", "hash": "4b37fb54bbfeb7a79cde17f9b7231f52deafbff7", "best_bid": "0.08", "best_ask": "0.09"}], "timestamp": "1769384395897", "event_type": "price_change"}}
{"_local_timestamp": "2026-01-25T23:39:55.970935+00:00", "data": {"market": "0x46e08dad4b1370947613b81f2ba28a23226504a333ec7e42de877d6ba6cc59d0", "price_changes": [{"asset_id": "85467679028197532287128360159828743243379157810773026071193309107969652317045", "price": "0.548", "size": "20", "side": "BUY", "hash": "d1188c8454e2fba79792be15cb25ca826dd2a26a", "best_bid": "0.958", "best_ask": "0.964"}, {"asset_id": "113369140136913812777925497644561662667789653912765877043929720445901767848122", "price": "0.452", "size": "20", "side": "SELL", "hash": "0b422a2fc158280adf00142a190bb279f53bb533", "best_bid": "0.036", "best_ask": "0.042"}], "timestamp": "1769384395897", "event_type": "price_change"}}
{"_local_timestamp": "2026-01-25T23:39:55.971582+00:00", "data": {"market": "0x44f67876759c44b763bb53f89b3c738756331b0a208672fc8db8a5f389230950", "price_changes": [{"asset_id": "32592218374784909301050372254273467546998719384564620545871759434640468645973", "price": "0.455", "size": "20", "side": "BUY", "hash": "8c5bec18fb2dc8f817ffff0f9cf2e331d9de6d19", "best_bid": "0.94", "best_ask": "0.986"}, {"asset_id": "1582298976410585403069729422280265608038484032857579102122167925665102997608", "price": "0.545", "size": "20", "side": "SELL", "hash": "492f04db25b6b11cb638d115b0db4e3c935e6d2e", "best_bid": "0.014", "best_ask": "0.06"}], "timestamp": "1769384395897", "event_type": "price_change"}}
{"_local_timestamp": "2026-01-25T23:39:56.046181+00:00", "data": {"market": "0x46e08dad4b1370947613b81f2ba28a23226504a333ec7e42de877d6ba6cc59d0", "price_changes": [{"asset_id": "85467679028197532287128360159828743243379157810773026071193309107969652317045", "price": "0.546", "size": "0", "side": "BUY", "hash": "a72fc865f6c75b549909c07f9e1fb2c5609c87f4", "best_bid": "0.958", "best_ask": "0.964"}, {"asset_id": "113369140136913812777925497644561662667789653912765877043929720445901767848122", "price": "0.454", "size": "0", "side": "SELL", "hash": "9e0ee42ab8aad8f9ead94e62239ea21d4b593fe2", "best_bid": "0.036", "best_ask": "0.042"}], "timestamp": "1769384395977", "event_type": "price_change"}}
{"_local_timestamp": "2026-01-25T23:39:56.258721+00:00", "data": {"market": "0x46e08dad4b1370947613b81f2ba28a23226504a333ec7e42de877d6ba6cc59d0", "price_changes": [{"asset_id": "85467679028197532287128360159828743243379157810773026071193309107969652317045", "price": "0.547", "size": "505", "side": "BUY", "hash": "1a2f2b22374c485801482a39b60d26e970f89f69", "best_bid": "0.958", "best_ask": "0.964"}, {"asset_id": "113369140136913812777925497644561662667789653912765877043929720445901767848122", "price": "0.453", "size": "505", "side": "SELL", "hash": "7adf2bd9ee17defecefd8db8af5c7ac3e05052b2", "best_bid": "0.036", "best_ask": "0.042"}], "timestamp": "1769384396181", "event_type": "price_change"}}
{"_local_timestamp": "2026-01-25T23:40:12.892782+00:00", "data": {"market": "0x0be3d4cc20250a7105206bc352af8b1c087df2ebd4f3b3927fabcdd8c81d792e", "price_changes": [{"asset_id": "87528913053522501048749446605646222127999765893905568199883777953288580503567", "price": "0.3", "size": "0", "side": "BUY", "hash": "478d6741c1e7984b62169a7aebe6b3d5ccc85776", "best_bid": "0.65", "best_ask": "0.67"}, {"asset_id": "63149403073928211890844841868361708990331353150804831882114276975252031214656", "price": "0.7", "size": "0", "side": "SELL", "hash": "0b112cd5e21eaa1fc3b02fbc02af5a9466c6a787", "best_bid": "0.33", "best_ask": "0.35"}], "timestamp": "1769384412828", "event_type": "price_change"}}
{"_local_timestamp": "2026-01-25T23:40:12.947570+00:00", "data": {"market": "0x0be3d4cc20250a7105206bc352af8b1c087df2ebd4f3b3927fabcdd8c81d792e", "price_changes": [{"asset_id": "87528913053522501048749446605646222127999765893905568199883777953288580503567", "price": "0.32", "size": "6", "side": "BUY", "hash": "498a160e23667127ef3e7518ea490ed87902e373", "best_bid": "0.65", "best_ask": "0.67"}, {"asset_id": "63149403073928211890844841868361708990331353150804831882114276975252031214656", "price": "0.68", "size": "6", "side": "SELL", "hash": "491f4e3f33e172c848875d64a49b84dc1fcb6036", "best_bid": "0.33", "best_ask": "0.35"}], "timestamp": "1769384412872", "event_type": "price_change"}}
{"_local_timestamp": "2026-01-25T23:40:13.110137+00:00", "data": {"market": "0x5b782c35d9cbd6e9d38597bd0af4e53d3263bde143e4d4ffdbd76d0a094f4be4", "price_changes": [{"asset_id": "48123308101524452666134421526726361469113858451786831367632481270457773825485", "price": "0.48", "size": "0", "side": "BUY", "hash": "8e83d1486f6da8282868ccfcc223378c4576ae05", "best_bid": "0.91", "best_ask": "0.92"}, {"asset_id": "111803189967461986329215432128898000701874058405628301712422758141213653452479", "price": "0.52", "size": "0", "side": "SELL", "hash": "0e1d2b248081367588643208fb4e4d12c13db960", "best_bid": "0.08", "best_ask": "0.09"}], "timestamp": "1769384413050", "event_type": "price_change"}}
{"_local_timestamp": "2026-01-25T23:40:13.220006+00:00", "data": {"market": "0x5b782c35d9cbd6e9d38597bd0af4e53d3263bde143e4d4ffdbd76d0a094f4be4", "price_changes": [{"asset_id": "48123308101524452666134421526726361469113858451786831367632481270457773825485", "price": "0.51", "size": "10", "side": "BUY", "hash": "adabc2d865ebbd93675095adecec03e6c0390d3d", "best_bid": "0.91", "best_ask": "0.92"}, {"asset_id": "111803189967461986329215432128898000701874058405628301712422758141213653452479", "price": "0.49", "size": "10", "side": "SELL", "hash": "9a3041a07c9c57265a1a5838cf51c0892df22548", "best_bid": "0.08", "best_ask": "0.09"}], "timestamp": "1769384413155", "event_type": "price_change"}}
{"_local_timestamp": "2026-01-25T23:40:13.570552+00:00", "data": {"market": "0x5b782c35d9cbd6e9d38597bd0af4e53d3263bde143e4d4ffdbd76d0a094f4be4", "price_changes": [{"asset_id": "48123308101524452666134421526726361469113858451786831367632481270457773825485", "price": "0.5", "size": "0", "side": "BUY", "hash": "904b2268c369a4954fdd3633d592fea7a25c38f1", "best_bid": "0.91", "best_ask": "0.92"}, {"asset_id": "111803189967461986329215432128898000701874058405628301712422758141213653452479", "price": "0.5", "size": "0", "side": "SELL", "hash": "85672254c91c220ee4329f6a0cec86d0d1480f8e", "best_bid": "0.08", "best_ask": "0.09"}], "timestamp": "1769384413504", "event_type": "price_change"}}
{"_local_timestamp": "2026-01-25T23:40:13.594757+00:00", "data": {"market": "0x5b782c35d9cbd6e9d38597bd0af4e53d3263bde143e4d4ffdbd76d0a094f4be4", "price_changes": [{"asset_id": "48123308101524452666134421526726361469113858451786831367632481270457773825485", "price": "0.52", "size": "20", "side": "BUY", "hash": "a8b1280c66ab150e4fe748c686cba0b291f15046", "best_bid": "0.91", "best_ask": "0.92"}, {"asset_id": "111803189967461986329215432128898000701874058405628301712422758141213653452479", "price": "0.48", "size": "20", "side": "SELL", "hash": "99482d0e63183a2454e34da35f265bb535e16e3a", "best_bid": "0.08", "best_ask": "0.09"}], "timestamp": "1769384413531", "event_type": "price_change"}}
