{"_local_timestamp": "2026-01-25T23:40:41.775872+00:00", "data": [{"market": "0xf852f41bdf9d034e15419d91ac6c382ba0b62ad66a7917377a42e5754b4c0148", "asset_id": "88465769861562630556131621934483265527611329201800499925788756789237440971941", "timestamp": "1769384347605", "hash": "541600559ed5ee1d5aa7e9d6c6a2887d1171eda4", "bids": [{"price": "0.01", "size": "4006.86"}, {"price": "0.02", "size": "248.35"}, {"price": "0.03", "size": "33.33"}, {"price": "0.04", "size": "77.79"}, {"price": "0.05", "size": "33.33"}, {"price": "0.06", "size": "186.48"}], "asks": [{"price": "0.99", "size": "5509.75"}, {"price": "0.98", "size": "2200"}, {"price": "0.97", "size": "9.11"}, {"price": "0.95", "size": "30"}, {"price": "0.93", "size": "2000"}, {"price": "0.92", "size": "7.86"}, {"price": "0.87", "size": "550"}, {"price": "0.8", "size": "500"}, {"price": "0.78", "size": "200"}, {"price": "0.73", "size": "250"}, {"price": "0.72", "size": "7"}, {"price": "0.62", "size": "191.66"}, {"price": "0.46", "size": "66.66"}, {"price": "0.31", "size": "207.41"}, {"price": "0.3", "size": "200"}, {"price": "0.29", "size": "75.06"}], "event_type": "book", "last_trade_price": ""}, {"market": "0x46d3552e03b57d3dd99685973c0e2df2e1f177c70c3641fe17d539e3a4a23a22", "asset_id": "69077213090861213291798671442886078635426003289643187464198454581300481451295", "timestamp": "1769382039533", "hash": "269127b95d090a0cc8220ea8084748799de085f1", "bids": [{"price": "0.01", "size": "14.3"}, {"price": "0.02", "size": "2000"}, {"price": "0.03", "size": "28.56"}, {"price": "0.1", "size": "500"}, {"price": "0.11", "size": "184.84"}, {"price": "0.12", "size": "91.66"}, {"price": "0.13", "size": "120"}, {"price": "0.14", "size": "8.5"}, {"price": "0.15", "size": "66.66"}, {"price": "0.19", "size": "71.92"}], "asks": [{"price": "0.99", "size": "5810.24"}, {"price": "0.98", "size": "2200"}, {"price": "0.97", "size": "5.87"}, {"price": "0.95", "size": "10"}, {"price": "0.94", "size": "700"}, {"price": "0.93", "size": "10.3"}, {"price": "0.89", "size": "550"}, {"price": "0.82", "size": "450"}, {"price": "0.81", "size": "66.66"}, {"price": "0.76", "size": "200"}, {"price": "0.75", "size": "33"}, {"price": "0.74", "size": "7"}, {"price": "0.64", "size": "66.66"}, {"price": "0.61", "size": "33.33"}, {"price": "0.6", "size": "27.5"}, {"price": "0.59", "size": "8.5"}, {"price": "0.5", "size": "100"}, {"price": "0.48", "size": "5"}, {"price": "0.47", "size": "66.66"}], "event_type": "book", "last_trade_price": ""}, {"market": "0xa37825e901df9f970d64e5bebff36d5f50027ed79044d9a59814148a24ed45d8", "asset_id": "68589691256148111185361911986089660157908545588549058270073629013322196617109", "timestamp": "1769384428444", "hash": "88bd9a299cdba184dd7c5e1f826d09fb117dde83", "bids": [{"price": "0.01", "size": "6500"}, {"price": "0.02", "size": "3809.59"}, {"price": "0.03", "size": "300"}, {"price": "0.04", "size": "100"}, {"price": "0.05", "size": "16.16"}, {"price": "0.12", "size": "200"}, {"price": "0.17", "size": "300"}, {"price": "0.18", "size": "72.22"}, {"price": "0.19", "size": "124.55"}, {"price": "0.22", "size": "297.07"}, {"price": "0.24", "size": "100"}, {"price": "0.25", "size": "25"}, {"price": "0.26", "size": "66.66"}], "asks": [{"price": "0.99", "size": "5809.94"}, {"price": "0.98", "size": "2200"}, {"price": "0.97", "size": "5.7"}, {"price": "0.94", "size": "700"}, {"price": "0.93", "size": "10.41"}, {"price": "0.87", "size": "650"}, {"price": "0.8", "size": "500"}, {"price": "0.78", "size": "150"}, {"price": "0.77", "size": "8"}, {"price": "0.71", "size": "250"}, {"price": "0.66", "size": "125"}, {"price": "0.51", "size": "42.14"}, {"price": "0.49", "size": "5"}, {"price": "0.44", "size": "23.21"}, {"price": "0.42", "size": "40.38"}, {"price": "0.41", "size": "62.62"}, {"price": "0.4", "size": "500"}, {"price": "0.39", "size": "66.66"}, {"price": "0.35", "size": "66.66"}, {"price": "0.34", "size": "200"}, {"price": "0.32", "size": "66.66"}], "event_type": "book", "last_trade_price": "0.640"}, {"market": "0xa37825e901df9f970d64e5bebff36d5f50027ed79044d9a59814148a24ed45d8", "asset_id": "62801282190387947418073628087853293191213121936477202785404599643206749110396", "timestamp": "1769384428444", "hash": "0fb15507aa2e0df138f6169600dad2c51c3ae554", "bids": [{"price": "0.01", "size": "5809.94"}, {"price": "0.02", "size": "2200"}, {"price": "0.03", "size": "5.7"}, {"price": "0.06", "size": "700"}, {"price": "0.07", "size": "10.41"}, {"price": "0.13", "size": "650"}, {"price": "0.2", "size": "500"}, {"price": "0.22", "size": "150"}, {"price": "0.23", "size": "8"}, {"price": "0.29", "size": "250"}, {"price": "0.34", "size": "125"}, {"price": "0.49", "size": "42.14"}, {"price": "0.51", "size": "5"}, {"price": "0.56", "size": "23.21"}, {"price": "0.58", "size": "40.38"}, {"price": "0.59", "size": "62.62"}, {"price": "0.6", "size": "500"}, {"price": "0.61", "size": "66.66"}, {"price": "0.65", "size": "66.66"}, {"price": "0.66", "size": "200"}, {"price": "0.68", "size": "66.66"}], "asks": [{"price": "0.99", "size": "6500"}, {"price": "0.98", "size": "3809.59"}, {"price": "0.97", "size": "300"}, {"price": "0.96", "size": "100"}, {"price": "0.95", "size": "16.16"}, {"price": "0.88", "size": "200"}, {"price": "0.83", "size": "300"}, {"price": "0.82", "size": "72.22"}, {"price": "0.81", "size": "124.55"}, {"price": "0.78", "size": "297.07"}, {"price": "0.76", "size": "100"}, {"price": "0.75", "size": "25"}, {"price": "0.74", "size": "66.66"}], "event_type": "book", "last_trade_price": "0.640"}, {"market": "0x501dc0fabe1a2a06eb5b7a286926f549cf43cf7dea944bcbf5e172c25dbca42c", "asset_id": "25614982935962741476358496118717074444114700227719714638569458374703346029046", "timestamp": "1769384239248", "hash": "ee4dad53163a8d7e1d81c982a1c0a60ef3f2c7cb", "bids": [{"price": "0.01", "size": "2000"}, {"price": "0.02", "size": "314.44"}, {"price": "0.03", "size": "305"}, {"price": "0.04", "size": "306.53"}, {"price": "0.05", "size": "200"}, {"price": "0.06", "size": "133.03"}, {"price": "0.08", "size": "89.74"}], "asks": [{"price": "0.99", "size": "10809.72"}, {"price": "0.98", "size": "2200"}, {"price": "0.97", "size": "5.58"}, {"price": "0.95", "size": "30"}, {"price": "0.94", "size": "733"}, {"price": "0.93", "size": "10.5"}, {"price": "0.89", "size": "550"}, {"price": "0.84", "size": "450"}, {"price": "0.79", "size": "150"}, {"price": "0.7", "size": "350"}, {"price": "0.69", "size": "175"}, {"price": "0.4", "size": "100"}, {"price": "0.38", "size": "200"}, {"price": "0.37", "size": "13.33"}, {"price": "0.13", "size": "5"}], "event_type": "book", "last_trade_price": ""}, {"market": "0x4279c24023b1ee38227683e58b756d7fe4f5983ef663dee91acb4fd5be32a4c6", "asset_id": "49187455212138718981392696671235531935114325385110772275618585685189509151160", "timestamp": "1769384417168", "hash": "9185402355f1dffb185b67278471ab46a01ad8cb", "bids": [{"price": "0.001", "size": "3837.39"}, {"price": "0.002", "size": "1250"}, {"price": "0.003", "size": "1406.82"}, {"price": "0.006", "size": "200"}, {"price": "0.007", "size": "9.77"}, {"price": "0.01", "size": "5800"}, {"price": "0.02", "size": "2200"}, {"price": "0.021", "size": "8.12"}, {"price": "0.05", "size": "30"}, {"price": "0.051", "size": "39"}, {"price": "0.06", "size": "700"}, {"price": "0.061", "size": "11.96"}, {"price": "0.111", "size": "550"}, {"price": "0.162", "size": "450"}, {"price": "0.163", "size": "100"}, {"price": "0.164", "size": "45"}, {"price": "0.21", "size": "150"}, {"price": "0.27", "size": "100"}, {"price": "0.292", "size": "6"}, {"price": "0.298", "size": "22"}, {"price": "0.457", "size": "100"}, {"price": "0.6", "size": "100"}, {"price": "0.75", "size": "30"}], "asks": [{"price": "0.999", "size": "41810.34"}, {"price": "0.998", "size": "925.29"}, {"price": "0.997", "size": "66.13"}, {"price": "0.99", "size": "4000"}, {"price": "0.989", "size": "400"}, {"price": "0.988", "size": "335.84"}, {"price": "0.987", "size": "200"}, {"price": "0.986", "size": "15.31"}, {"price": "0.985", "size": "12"}, {"price": "0.984", "size": "11.35"}, {"price": "0.963", "size": "35.84"}, {"price": "0.962", "size": "9.93"}, {"price": "0.952", "size": "72.44"}, {"price": "0.94", "size": "125"}, {"price": "0.938", "size": "68"}], "event_type": "book", "last_trade_price": ""}, {"market": "0xf852f41bdf9d034e15419d91ac6c382ba0b62ad66a7917377a42e5754b4c0148", "asset_id": "77739792140141342052066893726047244075612025863067454737418214817057021056423", "timestamp": "1769384347605", "hash": "ed7ebf8236fddb7b4b6a6bd4859074e1103f0aa2", "bids": [{"price": "0.01", "size": "5509.75"}, {"price": "0.02", "size": "2200"}, {"price": "0.03", "size": "9.11"}, {"price": "0.05", "size": "30"}, {"price": "0.07", "size": "2000"}, {"price": "0.08", "size": "7.86"}, {"price": "0.13", "size": "550"}, {"price": "0.2", "size": "500"}, {"price": "0.22", "size": "200"}, {"price": "0.27", "size": "250"}, {"price": "0.28", "size": "7"}, {"price": "0.38", "size": "191.66"}, {"price": "0.54", "size": "66.66"}, {"price": "0.69", "size": "207.41"}, {"price": "0.7", "size": "200"}, {"price": "0.71", "size": "75.06"}], "asks": [{"price": "0.99", "size": "4006.86"}, {"price": "0.98", "size": "248.35"}, {"price": "0.97", "size": "33.33"}, {"price": "0.96", "size": "77.79"}, {"price": "0.95", "size": "33.33"}, {"price": "0.94", "size": "186.48"}], "event_type": "book", "last_trade_price": ""}, {"market": "0xb21c480a978a1ad358430a026aa4a7208999550eb1cdcc48a8c6698f9ad4f522", "asset_id": "100521412873072524619586955833305791995196575825307712552822954850256098375950", "timestamp": "1769384218468", "hash": "49418e99bd6eafc135712a38069dc73fead95031", "bids": [{"price": "0.001", "size": "3910.17"}, {"price": "0.002", "size": "1250"}, {"price": "0.003", "size": "1172.68"}, {"price": "0.006", "size": "83"}, {"price": "0.007", "size": "9.58"}, {"price": "0.01", "size": "5800"}, {"price": "0.02", "size": "2200"}, {"price": "0.021", "size": "15.95"}, {"price": "0.05", "size": "30"}, {"price": "0.051", "size": "39"}, {"price": "0.06", "size": "700"}, {"price": "0.11", "size": "550"}, {"price": "0.111", "size": "5.11"}, {"price": "0.169", "size": "450"}, {"price": "0.244", "size": "300"}, {"price": "0.271", "size": "150"}, {"price": "0.34", "size": "125"}, {"price": "0.5", "size": "300"}, {"price": "0.501", "size": "66.66"}, {"price": "0.502", "size": "5"}, {"price": "0.657", "size": "66.66"}, {"price": "0.7", "size": "100"}, {"price": "0.75", "size": "5"}, {"price": "0.771", "size": "200"}, {"price": "0.812", "size": "66.66"}, {"price": "0.813", "size": "16.61"}], "asks": [{"price": "0.999", "size": "51496.23"}, {"price": "0.998", "size": "263.46"}, {"price": "0.997", "size": "70.23"}, {"price": "0.99", "size": "3000"}, {"price": "0.989", "size": "406.98"}, {"price": "0.988", "size": "300"}, {"price": "0.987", "size": "271.58"}, {"price": "0.986", "size": "97.4"}, {"price": "0.984", "size": "40.16"}, {"price": "0.983", "size": "5.83"}, {"price": "0.981", "size": "40.16"}], "event_type": "book", "last_trade_price": ""}, {"market": "0x501dc0fabe1a2a06eb5b7a286926f549cf43cf7dea944bcbf5e172c25dbca42c", "asset_id": "88270481898024393117980660140080765211712224069713439592911137624132878325317", "timestamp": "1769384239248", "hash": "409d8e9cda11cdcab90e2762c68cc3bef6d24005", "bids": [{"price": "0.01", "size": "10809.72"}, {"price": "0.02", "size": "2200"}, {"price": "0.03", "size": "5.58"}, {"price": "0.05", "size": "30"}, {"price": "0.06", "size": "733"}, {"price": "0.07", "size": "10.5"}, {"price": "0.11", "size": "550"}, {"price": "0.16", "size": "450"}, {"price": "0.21", "size": "150"}, {"price": "0.3", "size": "350"}, {"price": "0.31", "size": "175"}, {"price": "0.6", "size": "100"}, {"price": "0.62", "size": "200"}, {"price": "0.63", "size": "13.33"}, {"price": "0.87", "size": "5"}], "asks": [{"price": "0.99", "size": "2000"}, {"price": "0.98", "size": "314.44"}, {"price": "0.97", "size": "305"}, {"price": "0.96", "size": "306.53"}, {"price": "0.95", "size": "200"}, {"price": "0.94", "size": "133.03"}, {"price": "0.92", "size": "89.74"}], "event_type": "book", "last_trade_price": ""}, {"market": "0x616ac22e1e151c3822e00ef50bb3b4ef1a9c934659aa26f3dc541f25fc60aeb5", "asset_id": "62104662568640384841874849194900354084748315841291727326743209171472911537452", "timestamp": "1769384373531", "hash": "ee903de8969b29269e3a5de43d7b8d160fb6c725", "bids": [{"price": "0.01", "size": "4505.08"}, {"price": "0.02", "size": "1800"}, {"price": "0.03", "size": "307.33"}, {"price": "0.04", "size": "300"}, {"price": "0.05", "size": "205.67"}, {"price": "0.06", "size": "100"}, {"price": "0.07", "size": "10.41"}, {"price": "0.11", "size": "275"}, {"price": "0.12", "size": "8.5"}, {"price": "0.18", "size": "50"}, {"price": "0.2", "size": "10"}, {"price": "0.3", "size": "10"}, {"price": "0.35", "size": "105.67"}, {"price": "0.36", "size": "5"}, {"price": "0.4", "size": "10"}, {"price": "0.5", "size": "10"}, {"price": "0.55", "size": "23.63"}, {"price": "0.56", "size": "19.64"}, {"price": "0.6", "size": "10"}, {"price": "0.63", "size": "5"}], "asks": [{"price": "0.99", "size": "17.86"}, {"price": "0.98", "size": "2000"}, {"price": "0.97", "size": "300"}, {"price": "0.96", "size": "6.76"}, {"price": "0.95", "size": "260"}, {"price": "0.94", "size": "130"}, {"price": "0.93", "size": "78.57"}, {"price": "0.92", "size": "66.66"}, {"price": "0.91", "size": "6.12"}, {"price": "0.88", "size": "300"}, {"price": "0.87", "size": "66.66"}, {"price": "0.86", "size": "8.5"}, {"price": "0.84", "size": "150"}, {"price": "0.82", "size": "92.88"}], "event_type": "book", "last_trade_price": ""}, {"market": "0xb21c480a978a1ad358430a026aa4a7208999550eb1cdcc48a8c6698f9ad4f522", "asset_id": "51757660295264421930879595392856885308963777035598389067220840018166822346259", "timestamp": "1769384218468", "hash": "d336a5e9db9afd474959a2d1d9730f55d7046905", "bids": [{"price": "0.001", "size": "51496.23"}, {"price": "0.002", "size": "263.46"}, {"price": "0.003", "size": "70.23"}, {"price": "0.01", "size": "3000"}, {"price": "0.011", "size": "406.98"}, {"price": "0.012", "size": "300"}, {"price": "0.013", "size": "271.58"}, {"price": "0.014", "size": "97.4"}, {"price": "0.016", "size": "40.16"}, {"price": "0.017", "size": "5.83"}, {"price": "0.019", "size": "40.16"}], "asks": [{"price": "0.999", "size": "3910.17"}, {"price": "0.998", "size": "1250"}, {"price": "0.997", "size": "1172.68"}, {"price": "0.994", "size": "83"}, {"price": "0.993", "size": "9.58"}, {"price": "0.99", "size": "5800"}, {"price": "0.98", "size": "2200"}, {"price": "0.979", "size": "15.95"}, {"price": "0.95", "size": "30"}, {"price": "0.949", "size": "39"}, {"price": "0.94", "size": "700"}, {"price": "0.89", "size": "550"}, {"price": "0.889", "size": "5.11"}, {"price": "0.831", "size": "450"}, {"price": "0.756", "size": "300"}, {"price": "0.729", "size": "150"}, {"price": "0.66", "size": "125"}, {"price": "0.5", "size": "300"}, {"price": "0.499", "size": "66.66"}, {"price": "0.498", "size": "5"}, {"price": "0.343", "size": "66.66"}, {"price": "0.3", "size": "100"}, {"price": "0.25", "size": "5"}, {"price": "0.229", "size": "200"}, {"price": "0.188", "size": "66.66"}, {"price": "0.187", "size": "16.61"}], "event_type": "book", "last_trade_price": ""}, {"market": "0x4279c24023b1ee38227683e58b756d7fe4f5983ef663dee91acb4fd5be32a4c6", "asset_id": "106861838123794260064278131160173263831884433187059003819004489350782868266329", "timestamp": "1769384417168", "hash": "8ede6f163320bb1f120ff462545a803afa5b6aeb", "bids": [{"price": "0.001", "size": "41810.34"}, {"price": "0.002", "size": "925.29"}, {"price": "0.003", "size": "66.13"}, {"price": "0.01", "size": "4000"}, {"price": "0.011", "size": "400"}, {"price": "0.012", "size": "335.84"}, {"price": "0.013", "size": "200"}, {"price": "0.014", "size": "15.31"}, {"price": "0.015", "size": "12"}, {"price": "0.016", "size": "11.35"}, {"price": "0.037", "size": "35.84"}, {"price": "0.038", "size": "9.93"}, {"price": "0.048", "size": "72.44"}, {"price": "0.06", "size": "125"}, {"price": "0.062", "size": "68"}], "asks": [{"price": "0.999", "size": "3837.39"}, {"price": "0.998", "size": "1250"}, {"price": "0.997", "size": "1406.82"}, {"price": "0.994", "size": "200"}, {"price": "0.993", "size": "9.77"}, {"price": "0.99", "size": "5800"}, {"price": "0.98", "size": "2200"}, {"price": "0.979", "size": "8.12"}, {"price": "0.95", "size": "30"}, {"price": "0.949", "size": "39"}, {"price": "0.94", "size": "700"}, {"price": "0.939", "size": "11.96"}, {"price": "0.889", "size": "550"}, {"price": "0.838", "size": "450"}, {"price": "0.837", "size": "100"}, {"price": "0.836", "size": "45"}, {"price": "0.79", "size": "150"}, {"price": "0.73", "size": "100"}, {"price": "0.708", "size": "6"}, {"price": "0.702", "size": "22"}, {"price": "0.543", "size": "100"}, {"price": "0.4", "size": "100"}, {"price": "0.25", "size": "30"}], "event_type": "book", "last_trade_price": ""}, {"market": "0x616ac22e1e151c3822e00ef50bb3b4ef1a9c934659aa26f3dc541f25fc60aeb5", "asset_id": "69146441980971872531726202639159846147336475886279343694387966359232571623725", "timestamp": "1769384373531", "hash": "42d7b76784d9c1a2a87caad24e4b269e128b007b", "bids": [{"price": "0.01", "size": "17.86"}, {"price": "0.02", "size": "2000"}, {"price": "0.03", "size": "300"}, {"price": "0.04", "size": "6.76"}, {"price": "0.05", "size": "260"}, {"price": "0.06", "size": "130"}, {"price": "0.07", "size": "78.57"}, {"price": "0.08", "size": "66.66"}, {"price": "0.09", "size": "6.12"}, {"price": "0.12", "size": "300"}, {"price": "0.13", "size": "66.66"}, {"price": "0.14", "size": "8.5"}, {"price": "0.16", "size": "150"}, {"price": "0.18", "size": "92.88"}], "asks": [{"price": "0.99", "size": "4505.08"}, {"price": "0.98", "size": "1800"}, {"price": "0.97", "size": "307.33"}, {"price": "0.96", "size": "300"}, {"price": "0.95", "size": "205.67"}, {"price": "0.94", "size": "100"}, {"price": "0.93", "size": "10.41"}, {"price": "0.89", "size": "275"}, {"price": "0.88", "size": "8.5"}, {"price": "0.82", "size": "50"}, {"price": "0.8", "size": "10"}, {"price": "0.7", "size": "10"}, {"price": "0.65", "size": "105.67"}, {"price": "0.64", "size": "5"}, {"price": "0.6", "size": "10"}, {"price": "0.5", "size": "10"}, {"price": "0.45", "size": "23.63"}, {"price": "0.44", "size": "19.64"}, {"price": "0.4", "size": "10"}, {"price": "0.37", "size": "5"}], "event_type": "book", "last_trade_price": ""}, {"market": "0x46d3552e03b57d3dd99685973c0e2df2e1f177c70c3641fe17d539e3a4a23a22", "asset_id": "63579552197509143589959693779993809440480166595009463744830254978620312708977", "timestamp": "1769382039533", "hash": "a436f8a6bb12565bd2f2a68de5f81f8e06bfc0d8", "bids": [{"price": "0.01", "size": "5810.24"}, {"price": "0.02", "size": "2200"}, {"price": "0.03", "size": "5.87"}, {"price": "0.05", "size": "10"}, {"price": "0.06", "size": "700"}, {"price": "0.07", "size": "10.3"}, {"price": "0.11", "size": "550"}, {"price": "0.18", "size": "450"}, {"price": "0.19", "size": "66.66"}, {"price": "0.24", "size": "200"}, {"price": "0.25", "size": "33"}, {"price": "0.26", "size": "7"}, {"price": "0.36", "size": "66.66"}, {"price": "0.39", "size": "33.33"}, {"price": "0.4", "size": "27.5"}, {"price": "0.41", "size": "8.5"}, {"price": "0.5", "size": "100"}, {"price": "0.52", "size": "5"}, {"price": "0.53", "size": "66.66"}], "asks": [{"price": "0.99", "size": "14.3"}, {"price": "0.98", "size": "2000"}, {"price": "0.97", "size": "28.56"}, {"price": "0.9", "size": "500"}, {"price": "0.89", "size": "184.84"}, {"price": "0.88", "size": "91.66"}, {"price": "0.87", "size": "120"}, {"price": "0.86", "size": "8.5"}, {"price": "0.85", "size": "66.66"}, {"price": "0.81", "size": "71.92"}], "event_type": "book", "last_trade_price": ""}]}
{"_local_timestamp": "2026-01-25T23:41:06.695882+00:00", "data": {"market": "0x616ac22e1e151c3822e00ef50bb3b4ef1a9c934659aa26f3dc541f25fc60aeb5", "price_changes": [{"asset_id": "62104662568640384841874849194900354084748315841291727326743209171472911537452", "price": "0.36", "size": "0", "side": "BUY", "hash": "a6698a7b7f54bbe70a88165e0f9d490f9d6acc2e", "best_bid": "0.63", "best_ask": "0.82"}, {"asset_id": "69146441980971872531726202639159846147336475886279343694387966359232571623725", "price": "0.64", "size": "0", "side": "SELL", "hash": "0f99df2361652f3fc6837b1603cfa4df34bd87d4", "best_bid": "0.18", "best_ask": "0.37"}], "timestamp": "1769384466460", "event_type": "price_change"}}
{"_local_timestamp": "2026-01-25T23:41:06.799025+00:00", "data": {"market": "0x616ac22e1e151c3822e00ef50bb3b4ef1a9c934659aa26f3dc541f25fc60aeb5", "price_changes": [{"asset_id": "62104662568640384841874849194900354084748315841291727326743209171472911537452", "price": "0.36", "size": "5", "side": "BUY", "hash": "a7751caec548480523265083f8273405306dbcbb", "best_bid": "0.63", "best_ask": "0.82"}, {"asset_id": "69146441980971872531726202639159846147336475886279343694387966359232571623725", "price": "0.64", "size": "5", "side": "SELL", "hash": "dcf3a0e0ba1c2c01074fded98aebe585415f4306", "best_bid": "0.18", "best_ask": "0.37"}], "timestamp": "1769384466506", "event_type": "price_change"}}
{"_local_timestamp": "2026-01-25T23:41:06.838419+00:00", "data": {"market": "0xb21c480a978a1ad358430a026aa4a7208999550eb1cdcc48a8c6698f9ad4f522", "price_changes": [{"asset_id": "51757660295264421930879595392856885308963777035598389067220840018166822346259", "price": "0.011", "size": "306.98", "side": "BUY", "hash": "ec90d41533316673bde72331cc6e523ed2c60d3a", "best_bid": "0.019", "best_ask": "0.187"}, {"asset_id": "100521412873072524619586955833305791995196575825307712552822954850256098375950", "price": "0.989", "size": "306.98", "side": "SELL", "hash": "67f3eda5c27587aae9a75bc8bfbe3771b2af52f0", "best_bid": "0.813", "best_ask": "0.981"}], "timestamp": "1769384466648", "event_type": "price_change"}}
{"_local_timestamp": "2026-01-25T23:41:06.869818+00:00", "data": {"market": "0x4279c24023b1ee38227683e58b756d7fe4f5983ef663dee91acb4fd5be32a4c6", "price_changes": [{"asset_id": "106861838123794260064278131160173263831884433187059003819004489350782868266329", "price": "0.011", "size": "300", "side": "BUY", "hash": "6e7efff5be8a7212d61884b3840ad2264ffc5608", "best_bid": "0.062", "best_ask": "0.25"}, {"asset_id": "49187455212138718981392696671235531935114325385110772275618585685189509151160", "price": "0.989", "size": "300", "side": "SELL", "hash": "0d12643e7bce743376c9d197d916c21f1b9d9978", "best_bid": "0.75", "best_ask": "0.938"}], "timestamp": "1769384466647", "event_type": "price_change"}}
{"_local_timestamp": "2026-01-25T23:41:34.742175+00:00", "data": {"market": "0x46d3552e03b57d3dd99685973c0e2df2e1f177c70c3641fe17d539e3a4a23a22", "price_changes": [{"asset_id": "63579552197509143589959693779993809440480166595009463744830254978620312708977", "price": "0.26", "size": "0", "side": "BUY", "hash": "de127b21ef557d8cb9ecea46579e91d8e186af73", "best_bid": "0.53", "best_ask": "0.81"}, {"asset_id": "69077213090861213291798671442886078635426003289643187464198454581300481451295", "price": "0.74", "size": "0", "side": "SELL", "hash": "953082a1652a201a2195945bcadaa8644a7e23e4", "best_bid": "0.19", "best_ask": "0.47"}], "timestamp": "1769384494672", "event_type": "price_change"}}
{"_local_timestamp": "2026-01-25T23:41:34.785513+00:00", "data": {"market": "0x46d3552e03b57d3dd99685973c0e2df2e1f177c70c3641fe17d539e3a4a23a22", "price_changes": [{"asset_id": "63579552197509143589959693779993809440480166595009463744830254978620312708977", "price": "0.26", "size": "7", "side": "BUY", "hash": "7a99d87162b3c0076ad5d6ac9d36c42e02ea587e", "best_bid": "0.53", "best_ask": "0.81"}, {"asset_id": "69077213090861213291798671442886078635426003289643187464198454581300481451295", "price": "0.74", "size": "7", "side": "SELL", "hash": "14f6d4dc4bfc825bd137bd307fd795d2709a5db8", "best_bid": "0.19", "best_ask": "0.47"}], "timestamp": "1769384494719", "event_type": "price_change"}}
{"_local_timestamp": "2026-01-25T23:41:52.037144+00:00", "data": {"market": "0x501dc0fabe1a2a06eb5b7a286926f549cf43cf7dea944bcbf5e172c25dbca42c", "price_changes": [{"asset_id": "88270481898024393117980660140080765211712224069713439592911137624132878325317", "price": "0.31", "size": "250", "side": "BUY", "hash": "1cd7886f35911af1e7e7793f79d2bbe5ed14a5cf", "best_bid": "0.87", "best_ask": "0.92"}, {"asset_id": "25614982935962741476358496118717074444114700227719714638569458374703346029046", "price": "0.69", "size": "250", "side": "SELL", "hash": "9a2405318dea885950153f9d7f824607b45ccbb9", "best_bid": "0.08", "best_ask": "0.13"}], "timestamp": "1769384511701", "event_type": "price_change"}}
{"_local_timestamp": "2026-01-25T23:43:31.059919+00:00", "data": {"market": "0x616ac22e1e151c3822e00ef50bb3b4ef1a9c934659aa26f3dc541f25fc60aeb5", "price_changes": [{"asset_id": "69146441980971872531726202639159846147336475886279343694387966359232571623725", "price": "0.09", "size": "0", "side": "BUY", "hash": "622aeafa191e7b822567fd74b2aaa3543891f0fa", "best_bid": "0.18", "best_ask": "0.37"}, {"asset_id": "62104662568640384841874849194900354084748315841291727326743209171472911537452", "price": "0.91", "size": "0", "side": "SELL", "hash": "eb31d73caec6f765e8efcdcdb966c8e18e14d567", "best_bid": "0.63", "best_ask": "0.82"}], "timestamp": "1769384610937", "event_type": "price_change"}}
{"_local_timestamp": "2026-01-25T23:43:31.447877+00:00", "data": {"market": "0x616ac22e1e151c3822e00ef50bb3b4ef1a9c934659aa26f3dc541f25fc60aeb5", "price_changes": [{"asset_id": "69146441980971872531726202639159846147336475886279343694387966359232571623725", "price": "0.09", "size": "6.12", "side": "BUY", "hash": "8de5481a5a89890662f3f464ecf3131cd2fed02e", "best_bid": "0.18", "best_ask": "0.37"}, {"asset_id": "62104662568640384841874849194900354084748315841291727326743209171472911537452", "price": "0.91", "size": "6.12", "side": "SELL", "hash": "2620b2a6dc619cab40915019d98073f85a08b339", "best_bid": "0.63", "best_ask": "0.82"}], "timestamp": "1769384611324", "event_type": "price_change"}}
{"_local_timestamp": "2026-01-25T23:44:47.602484+00:00", "data": {"market": "0x4279c24023b1ee38227683e58b756d7fe4f5983ef663dee91acb4fd5be32a4c6", "price_changes": [{"asset_id": "49187455212138718981392696671235531935114325385110772275618585685189509151160", "price": "0.164", "size": "0", "side": "BUY", "hash": "8beb6470f4284085150bfe1e3087a59fa145bb76", "best_bid": "0.75", "best_ask": "0.938"}, {"asset_id": "106861838123794260064278131160173263831884433187059003819004489350782868266329", "price": "0.836", "size": "0", "side": "SELL", "hash": "d702f7ffc330b8186b1386b82a5befdd71de02fe", "best_bid": "0.062", "best_ask": "0.25"}], "timestamp": "1769384687467", "event_type": "price_change"}}
{"_local_timestamp": "2026-01-25T23:45:19.130854+00:00", "data": {"market": "0x4279c24023b1ee38227683e58b756d7fe4f5983ef663dee91acb4fd5be32a4c6", "price_changes": [{"asset_id": "49187455212138718981392696671235531935114325385110772275618585685189509151160", "price": "0.164", "size": "45", "side": "BUY", "hash": "fd6b90839bfc60245afb15c397258b5e92f2c91f", "best_bid": "0.75", "best_ask": "0.938"}, {"asset_id": "106861838123794260064278131160173263831884433187059003819004489350782868266329", "price": "0.836", "size": "45", "side": "SELL", "hash": "819f977af1187b4614503d613ebb851b4dc69aa8", "best_bid": "0.062", "best_ask": "0.25"}], "timestamp": "1769384719027", "event_type": "price_change"}}
{"_local_timestamp": "2026-01-25T23:45:56.639062+00:00", "data": {"market": "0x501dc0fabe1a2a06eb5b7a286926f549cf43cf7dea944bcbf5e172c25dbca42c", "price_changes": [{"asset_id": "88270481898024393117980660140080765211712224069713439592911137624132878325317", "price": "0.31", "size": "75", "side": "BUY", "hash": "dc7de488043c2fc3f4a4b6748bdf124e21b58184", "best_bid": "0.87", "best_ask": "0.92"}, {"asset_id": "25614982935962741476358496118717074444114700227719714638569458374703346029046", "price": "0.69", "size": "75", "side": "SELL", "hash": "ad45d52f854f88fdae27a9351dd241b43c7edeed", "best_bid": "0.08", "best_ask": "0.13"}], "timestamp": "1769384756087", "event_type": "price_change"}}
{"_local_timestamp": "2026-01-25T23:46:11.222870+00:00", "data": {"market": "0x616ac22e1e151c3822e00ef50bb3b4ef1a9c934659aa26f3dc541f25fc60aeb5", "price_changes": [{"asset_id": "62104662568640384841874849194900354084748315841291727326743209171472911537452", "price": "0.06", "size": "0", "side": "BUY", "hash": "835cd05cb533d60edfa7d242db35c1d68e7875eb", "best_bid": "0.63", "best_ask": "0.82"}, {"asset_id": "69146441980971872531726202639159846147336475886279343694387966359232571623725", "price": "0.94", "size": "0", "side": "SELL", "hash": "5ae3813f05a0cdd87e71319bdbdf8063ce3acc3f", "best_bid": "0.18", "best_ask": "0.37"}], "timestamp": "1769384771120", "event_type": "price_change"}}
{"_local_timestamp": "2026-01-25T23:46:11.659868+00:00", "data": {"market": "0x616ac22e1e151c3822e00ef50bb3b4ef1a9c934659aa26f3dc541f25fc60aeb5", "price_changes": [{"asset_id": "62104662568640384841874849194900354084748315841291727326743209171472911537452", "price": "0.05", "size": "305.67", "side": "BUY", "hash": "aed465140514911b0e9b76a1244cb292c722a222", "best_bid": "0.63", "best_ask": "0.82"}, {"asset_id": "69146441980971872531726202639159846147336475886279343694387966359232571623725", "price": "0.95", "size": "305.67", "side": "SELL", "hash": "d6e2ba6a54d2865efcb66476bfe3e058e6b4cf4d", "best_bid": "0.18", "best_ask": "0.37"}], "timestamp": "1769384771581", "event_type": "price_change"}}
{"_local_timestamp": "2026-01-25T23:46:13.657392+00:00", "data": {"market": "0x4279c24023b1ee38227683e58b756d7fe4f5983ef663dee91acb4fd5be32a4c6", "price_changes": [{"asset_id": "49187455212138718981392696671235531935114325385110772275618585685189509151160", "price": "0.292", "size": "0", "side": "BUY", "hash": "18a59be7d9b9712d8f12062bebf58d07884ac6a8", "best_bid": "0.75", "best_ask": "0.938"}, {"asset_id": "106861838123794260064278131160173263831884433187059003819004489350782868266329", "price": "0.708", "size": "0", "side": "SELL", "hash": "42dab4c22e8a89392c8eaed5ed34e00d5ea326d2", "best_bid": "0.062", "best_ask": "0.25"}], "timestamp": "1769384773589", "event_type": "price_change"}}
{"_local_timestamp": "2026-01-25T23:46:13.717854+00:00", "data": {"market": "0x4279c24023b1ee38227683e58b756d7fe4f5983ef663dee91acb4fd5be32a4c6", "price_changes": [{"asset_id": "49187455212138718981392696671235531935114325385110772275618585685189509151160", "price": "0.299", "size": "6", "side": "BUY", "hash": "28ec1c9d86a056246564ef30e4a52971baa049a3", "best_bid": "0.75", "best_ask": "0.938"}, {"asset_id": "106861838123794260064278131160173263831884433187059003819004489350782868266329", "price": "0.701", "size": "6", "side": "SELL", "hash": "a72c6dead26cb6f87fa3ae046f24c74f7297a932", "best_bid": "0.062", "best_ask": "0.25"}], "timestamp": "1769384773644", "event_type": "price_change"}}
{"_local_timestamp": "2026-01-25T23:46:16.886476+00:00", "data": {"market": "0x501dc0fabe1a2a06eb5b7a286926f549cf43cf7dea944bcbf5e172c25dbca42c", "price_changes": [{"asset_id": "88270481898024393117980660140080765211712224069713439592911137624132878325317", "price": "0.32", "size": "125", "side": "BUY", "hash": "666ff7a1cab31b0300bd43104707b58ec9a2c3f5", "best_bid": "0.87", "best_ask": "0.92"}, {"asset_id": "25614982935962741476358496118717074444114700227719714638569458374703346029046", "price": "0.68", "size": "125", "side": "SELL", "hash": "c49d48fa066df5e43b646e95490c4803a01aae5b", "best_bid": "0.08", "best_ask": "0.13"}], "timestamp": "1769384776820", "event_type": "price_change"}}
{"_local_timestamp": "2026-01-25T23:47:33.893795+00:00", "data": {"market": "0x616ac22e1e151c3822e00ef50bb3b4ef1a9c934659aa26f3dc541f25fc60aeb5", "price_changes": [{"asset_id": "62104662568640384841874849194900354084748315841291727326743209171472911537452", "price": "0.03", "size": "300", "side": "BUY", "hash": "2e6f3afb24812d023a19df37c38618e30eec34df", "best_bid": "0.63", "best_ask": "0.82"}, {"asset_id": "69146441980971872531726202639159846147336475886279343694387966359232571623725", "price": "0.97", "size": "300", "side": "SELL", "hash": "6c9f56a41f63eb5562b74aed7b8f50bea595bf13", "best_bid": "0.18", "best_ask": "0.37"}], "timestamp": "1769384853783", "event_type": "price_change"}}
{"_local_timestamp": "2026-01-25T23:47:33.900648+00:00", "data": {"market": "0x616ac22e1e151c3822e00ef50bb3b4ef1a9c934659aa26f3dc541f25fc60aeb5", "price_changes": [{"asset_id": "62104662568640384841874849194900354084748315841291727326743209171472911537452", "price": "0.07", "size": "0", "side": "BUY", "hash": "2e6f3afb24812d023a19df37c38618e30eec34df", "best_bid": "0.63", "best_ask": "0.82"}, {"asset_id": "69146441980971872531726202639159846147336475886279343694387966359232571623725", "price": "0.93", "size": "0", "side": "SELL", "hash": "6c9f56a41f63eb5562b74aed7b8f50bea595bf13", "best_bid": "0.18", "best_ask": "0.37"}], "timestamp": "1769384853783", "event_type": "price_change"}}
{"_local_timestamp": "2026-01-25T23:47:34.600030+00:00", "data": {"market": "0x616ac22e1e151c3822e00ef50bb3b4ef1a9c934659aa26f3dc541f25fc60aeb5", "price_changes": [{"asset_id": "62104662568640384841874849194900354084748315841291727326743209171472911537452", "price": "0.02", "size": "1808.99", "side": "BUY", "hash": "c1f4e9227ca40aa4f6f8217eaa99c7daebbf1571", "best_bid": "0.63", "best_ask": "0.82"}, {"asset_id": "69146441980971872531726202639159846147336475886279343694387966359232571623725", "price": "0.98", "size": "1808.99", "side": "SELL", "hash": "ba3ab93de20e8cde26a8c7d328a9b328bdcf156c", "best_bid": "0.18", "best_ask": "0.37"}], "timestamp": "1769384854513", "event_type": "price_change"}}
{"_local_timestamp": "2026-01-25T23:47:34.600473+00:00", "data": {"market": "0x616ac22e1e151c3822e00ef50bb3b4ef1a9c934659aa26f3dc541f25fc60aeb5", "price_changes": [{"asset_id": "62104662568640384841874849194900354084748315841291727326743209171472911537452", "price": "0.06", "size": "12.82", "side": "BUY", "hash": "cfad48cc2462db593665ac45cfc0de47176fb9cc", "best_bid": "0.63", "best_ask": "0.82"}, {"asset_id": "69146441980971872531726202639159846147336475886279343694387966359232571623725", "price": "0.94", "size": "12.82", "side": "SELL", "hash": "de3ea16fc9d545cafc3f984b619a096168dd96cf", "best_bid": "0.18", "best_ask": "0.37"}], "timestamp": "1769384854514", "event_type": "price_change"}}
{"_local_timestamp": "2026-01-25T23:47:40.971955+00:00", "data": {"market": "0x616ac22e1e151c3822e00ef50bb3b4ef1a9c934659aa26f3dc541f25fc60aeb5", "price_changes": [{"asset_id": "69146441980971872531726202639159846147336475886279343694387966359232571623725", "price": "0.09", "size": "0", "side": "BUY", "hash": "bebec6d8835eb5c41b1af01094a3af62e816fc08", "best_bid": "0.18", "best_ask": "0.37"}, {"asset_id": "62104662568640384841874849194900354084748315841291727326743209171472911537452", "price": "0.91", "size": "0", "side": "SELL", "hash": "18d66afa94021c0a9897c30ac28dd95a1f717de0", "best_bid": "0.63", "best_ask": "0.82"}], "timestamp": "1769384860901", "event_type": "price_change"}}
{"_local_timestamp": "2026-01-25T23:47:41.318404+00:00", "data": {"market": "0x616ac22e1e151c3822e00ef50bb3b4ef1a9c934659aa26f3dc541f25fc60aeb5", "price_changes": [{"asset_id": "69146441980971872531726202639159846147336475886279343694387966359232571623725", "price": "0.09", "size": "6.12", "side": "BUY", "hash": "dda84b727b8436223010898b1c7f4fe312f68767", "best_bid": "0.18", "best_ask": "0.37"}, {"asset_id": "62104662568640384841874849194900354084748315841291727326743209171472911537452", "price": "0.91", "size": "6.12", "side": "SELL", "hash": "fade89040c81b8e14ce37cfc19f94c4216507473", "best_bid": "0.63", "best_ask": "0.82"}], "timestamp": "1769384861251", "event_type": "price_change"}}
{"_local_timestamp": "2026-01-25T23:49:30.329916+00:00", "data": {"market": "0x501dc0fabe1a2a06eb5b7a286926f549cf43cf7dea944bcbf5e172c25dbca42c", "price_changes": [{"asset_id": "88270481898024393117980660140080765211712224069713439592911137624132878325317", "price": "0.31", "size": "0", "side": "BUY", "hash": "5c48a773e83fd662df67e9b355678ebd99dc16f6", "best_bid": "0.87", "best_ask": "0.92"}, {"asset_id": "25614982935962741476358496118717074444114700227719714638569458374703346029046", "price": "0.69", "size": "0", "side": "SELL", "hash": "f1c76965a93bb8e82aa8edc8cfc09f5eb552759c", "best_bid": "0.08", "best_ask": "0.13"}], "timestamp": "1769384970060", "event_type": "price_change"}}
{"_local_timestamp": "2026-01-25T23:49:31.176397+00:00", "data": {"market": "0x501dc0fabe1a2a06eb5b7a286926f549cf43cf7dea944bcbf5e172c25dbca42c", "price_changes": [{"asset_id": "88270481898024393117980660140080765211712224069713439592911137624132878325317", "price": "0.32", "size": "200", "side": "BUY", "hash": "1c7312cc4a58e6adf0560eef18f987cd76e847b2", "best_bid": "0.87", "best_ask": "0.92"}, {"asset_id": "25614982935962741476358496118717074444114700227719714638569458374703346029046", "price": "0.68", "size": "200", "side": "SELL", "hash": "1ff576cb3a26217cc677f28de91117be2e657c41", "best_bid": "0.08", "best_ask": "0.13"}], "timestamp": "1769384970806", "event_type": "price_change"}}
{"_local_timestamp": "2026-01-25T23:49:50.135828+00:00", "data": {"market": "0x4279c24023b1ee38227683e58b756d7fe4f5983ef663dee91acb4fd5be32a4c6", "price_changes": [{"asset_id": "49187455212138718981392696671235531935114325385110772275618585685189509151160", "price": "0.164", "size": "0", "side": "BUY", "hash": "29f5e016be115958fb4eb99bbc0fbe3a2c62a2f1", "best_bid": "0.75", "best_ask": "0.938"}, {"asset_id": "106861838123794260064278131160173263831884433187059003819004489350782868266329", "price": "0.836", "size": "0", "side": "SELL", "hash": "c91cd342d9b9a4057bffb1f599b1928e3f483d28", "best_bid": "0.062", "best_ask": "0.25"}], "timestamp": "1769384989972", "event_type": "price_change"}}
{"_local_timestamp": "2026-01-25T23:50:22.401196+00:00", "data": {"market": "0x4279c24023b1ee38227683e58b756d7fe4f5983ef663dee91acb4fd5be32a4c6", "price_changes": [{"asset_id": "49187455212138718981392696671235531935114325385110772275618585685189509151160", "price": "0.3", "size": "45", "side": "BUY", "hash": "745dbf93bb8e82b73d84d6ce56900a959671f20a", "best_bid": "0.75", "best_ask": "0.938"}, {"asset_id": "106861838123794260064278131160173263831884433187059003819004489350782868266329", "price": "0.7", "size": "45", "side": "SELL", "hash": "15010b5aa191f97b93c2d4f5d270299e2f4faa20", "best_bid": "0.062", "best_ask": "0.25"}], "timestamp": "1769385022336", "event_type": "price_change"}}
