{"_local_timestamp": "2026-01-25T23:33:28.440050+00:00", "data": [{"market": "0xf829129cd05db888741ad290c786a1d71db5f8bb8493d8bc07e21b826db4d328", "asset_id": "90685511192998551789516562849422906363784901518167369632157413860597087715433", "timestamp": "1769384008206", "hash": "39e4f3c6283a6e40db1c95529f8389fe2d9902bb", "bids": [{"price": "0.001", "size": "60441"}, {"price": "0.002", "size": "4660"}, {"price": "0.003", "size": "172.56"}, {"price": "0.004", "size": "45.87"}, {"price": "0.007", "size": "14"}, {"price": "0.008", "size": "12.77"}, {"price": "0.033", "size": "41.2"}, {"price": "0.095", "size": "10"}, {"price": "0.096", "size": "13"}], "asks": [{"price": "0.999", "size": "3999.91"}, {"price": "0.998", "size": "1255.89"}, {"price": "0.997", "size": "1400"}, {"price": "0.996", "size": "10.18"}, {"price": "0.994", "size": "200"}, {"price": "0.99", "size": "5000"}, {"price": "0.989", "size": "5.17"}, {"price": "0.98", "size": "4300"}, {"price": "0.979", "size": "300"}, {"price": "0.978", "size": "7.62"}, {"price": "0.95", "size": "330"}, {"price": "0.949", "size": "39"}, {"price": "0.948", "size": "10.95"}, {"price": "0.91", "size": "700"}, {"price": "0.86", "size": "567.85"}, {"price": "0.82", "size": "427.77"}, {"price": "0.819", "size": "6.34"}, {"price": "0.77", "size": "321.73"}, {"price": "0.73", "size": "146.29"}, {"price": "0.68", "size": "75"}, {"price": "0.66", "size": "20"}, {"price": "0.64", "size": "55.55"}, {"price": "0.626", "size": "3818"}, {"price": "0.526", "size": "1800"}, {"price": "0.525", "size": "5"}, {"price": "0.481", "size": "120"}, {"price": "0.48", "size": "10"}, {"price": "0.408", "size": "40"}, {"price": "0.407", "size": "30"}, {"price": "0.34", "size": "100"}, {"price": "0.18", "size": "10"}, {"price": "0.167", "size": "20"}, {"price": "0.148", "size": "25"}, {"price": "0.141", "size": "80.86"}, {"price": "0.13", "size": "1000"}, {"price": "0.129", "size": "126.48"}, {"price": "0.125", "size": "25"}, {"price": "0.121", "size": "66.66"}, {"price": "0.113", "size": "100.66"}], "event_type": "book", "last_trade_price": ""}, {"market": "0xdf4e0e5a4825e829490808d950849cc1350263c38aeafaa7ef9207fd61fb0ad8", "asset_id": "57077847438061429385815585675632165160097486485394403036399997772083935128934", "timestamp": "1769383938665", "hash": "92fdb76835238434e9066a1f9d14fc120f1ae755", "bids": [{"price": "0.001", "size": "27566.99"}, {"price": "0.002", "size": "1000"}, {"price": "0.003", "size": "6.33"}, {"price": "0.004", "size": "5020"}, {"price": "0.005", "size": "250"}, {"price": "0.006", "size": "8.21"}, {"price": "0.013", "size": "100"}, {"price": "0.014", "size": "15.53"}, {"price": "0.034", "size": "600"}, {"price": "0.035", "size": "318.87"}, {"price": "0.048", "size": "74.24"}, {"price": "0.061", "size": "25"}, {"price": "0.062", "size": "74.17"}], "asks": [{"price": "0.999", "size": "4076.55"}, {"price": "0.998", "size": "1255.9"}, {"price": "0.997", "size": "1400"}, {"price": "0.996", "size": "10.21"}, {"price": "0.994", "size": "200"}, {"price": "0.99", "size": "5000"}, {"price": "0.989", "size": "5.19"}, {"price": "0.98", "size": "4300"}, {"price": "0.979", "size": "7.99"}, {"price": "0.95", "size": "330"}, {"price": "0.949", "size": "39"}, {"price": "0.948", "size": "11.73"}, {"price": "0.91", "size": "700"}, {"price": "0.86", "size": "567.85"}, {"price": "0.81", "size": "168.42"}, {"price": "0.806", "size": "4142"}, {"price": "0.805", "size": "5.67"}, {"price": "0.76", "size": "116.66"}, {"price": "0.749", "size": "450"}, {"price": "0.73", "size": "50"}, {"price": "0.71", "size": "89.65"}, {"price": "0.67", "size": "72.72"}, {"price": "0.62", "size": "177.63"}, {"price": "0.481", "size": "1763"}, {"price": "0.48", "size": "100"}, {"price": "0.479", "size": "100"}, {"price": "0.478", "size": "5"}, {"price": "0.336", "size": "150"}, {"price": "0.286", "size": "100"}, {"price": "0.285", "size": "10"}, {"price": "0.21", "size": "76.92"}, {"price": "0.2", "size": "5"}, {"price": "0.185", "size": "5"}, {"price": "0.181", "size": "40"}, {"price": "0.18", "size": "30"}, {"price": "0.15", "size": "10"}, {"price": "0.149", "size": "20"}, {"price": "0.114", "size": "7.45"}, {"price": "0.095", "size": "8"}, {"price": "0.093", "size": "60"}], "event_type": "book", "last_trade_price": "0.063"}, {"market": "0x3acc06a95895e69efeeaae4dfdce738b91702c94556b230208b4f0438be8e4e5", "asset_id": "21289083487946615228722872362957627606235323101425284673989025264460245605601", "timestamp": "1769384000703", "hash": "2b96758dc95d363ba58619e1a56f152f687ef148", "bids": [{"price": "0.01", "size": "5005.66"}, {"price": "0.02", "size": "4305.6"}, {"price": "0.03", "size": "250"}, {"price": "0.04", "size": "6.4"}, {"price": "0.05", "size": "310"}, {"price": "0.08", "size": "750"}, {"price": "0.09", "size": "5.51"}, {"price": "0.13", "size": "586.53"}, {"price": "0.17", "size": "188.23"}, {"price": "0.2", "size": "1050"}, {"price": "0.21", "size": "138.46"}, {"price": "0.22", "size": "2108"}, {"price": "0.26", "size": "100"}, {"price": "0.27", "size": "50"}, {"price": "0.28", "size": "20"}, {"price": "0.3", "size": "80"}, {"price": "0.34", "size": "108.82"}, {"price": "0.41", "size": "3408"}, {"price": "0.42", "size": "1000"}, {"price": "0.5", "size": "800"}, {"price": "0.51", "size": "490"}, {"price": "0.52", "size": "5"}, {"price": "0.53", "size": "10"}, {"price": "0.54", "size": "30"}, {"price": "0.55", "size": "40"}, {"price": "0.76", "size": "100"}, {"price": "0.77", "size": "25.26"}, {"price": "0.79", "size": "310"}, {"price": "0.8", "size": "210"}, {"price": "0.81", "size": "326"}, {"price": "0.82", "size": "287"}], "asks": [{"price": "0.98", "size": "98"}, {"price": "0.97", "size": "29.52"}, {"price": "0.96", "size": "70"}, {"price": "0.95", "size": "60"}, {"price": "0.88", "size": "120"}, {"price": "0.87", "size": "210"}, {"price": "0.86", "size": "131.11"}, {"price": "0.85", "size": "526.78"}, {"price": "0.84", "size": "21"}], "event_type": "book", "last_trade_price": ""}, {"market": "0x897a2f88e1b65776ac5af0440833eea638395f0af0df4bed47e83f64c9b9a1e3", "asset_id": "67301121905355380418923087513498375592166001657797903147689423172757844806122", "timestamp": "1769384002484", "hash": "d480b70417b0c16a8a5371dc935c04ccb5c564e9", "bids": [{"price": "0.01", "size": "5313.97"}, {"price": "0.02", "size": "3000"}, {"price": "0.03", "size": "11.55"}, {"price": "0.05", "size": "1020"}, {"price": "0.07", "size": "1285.71"}, {"price": "0.08", "size": "7.13"}, {"price": "0.09", "size": "355.55"}, {"price": "0.11", "size": "1454"}, {"price": "0.12", "size": "233.33"}, {"price": "0.13", "size": "3555"}, {"price": "0.14", "size": "205.71"}, {"price": "0.15", "size": "20"}, {"price": "0.16", "size": "2420"}, {"price": "0.17", "size": "264.45"}, {"price": "0.18", "size": "25.23"}, {"price": "0.19", "size": "245.26"}, {"price": "0.2", "size": "25"}, {"price": "0.23", "size": "50"}, {"price": "0.24", "size": "40"}, {"price": "0.26", "size": "48"}, {"price": "0.28", "size": "575"}, {"price": "0.29", "size": "15"}, {"price": "0.33", "size": "85"}, {"price": "0.34", "size": "40"}, {"price": "0.37", "size": "7"}, {"price": "0.39", "size": "30"}, {"price": "0.42", "size": "620"}, {"price": "0.43", "size": "583.04"}, {"price": "0.44", "size": "31"}], "asks": [{"price": "0.99", "size": "5000"}, {"price": "0.98", "size": "3300"}, {"price": "0.97", "size": "250"}, {"price": "0.96", "size": "7.14"}, {"price": "0.95", "size": "1020"}, {"price": "0.92", "size": "725"}, {"price": "0.89", "size": "290.9"}, {"price": "0.87", "size": "1555"}, {"price": "0.86", "size": "200"}, {"price": "0.85", "size": "2798"}, {"price": "0.84", "size": "250"}, {"price": "0.83", "size": "152.94"}, {"price": "0.81", "size": "126.31"}, {"price": "0.78", "size": "90.9"}, {"price": "0.76", "size": "3246"}, {"price": "0.55", "size": "225"}, {"price": "0.52", "size": "1693.72"}, {"price": "0.51", "size": "333"}, {"price": "0.49", "size": "410"}, {"price": "0.48", "size": "2214.49"}, {"price": "0.47", "size": "583"}, {"price": "0.46", "size": "67.37"}], "event_type": "book", "last_trade_price": "0.550"}, {"market": "0xf829129cd05db888741ad290c786a1d71db5f8bb8493d8bc07e21b826db4d328", "asset_id": "105495516848871865829093849779907676478444075202002902600889102615883909197041", "timestamp": "1769384008206", "hash": "f34126f89291477f1a7627acd47783719a4ac827", "bids": [{"price": "0.001", "size": "3999.91"}, {"price": "0.002", "size": "1255.89"}, {"price": "0.003", "size": "1400"}, {"price": "0.004", "size": "10.18"}, {"price": "0.006", "size": "200"}, {"price": "0.01", "size": "5000"}, {"price": "0.011", "size": "5.17"}, {"price": "0.02", "size": "4300"}, {"price": "0.021", "size": "300"}, {"price": "0.022", "size": "7.62"}, {"price": "0.05", "size": "330"}, {"price": "0.051", "size": "39"}, {"price": "0.052", "size": "10.95"}, {"price": "0.09", "size": "700"}, {"price": "0.14", "size": "567.85"}, {"price": "0.18", "size": "427.77"}, {"price": "0.181", "size": "6.34"}, {"price": "0.23", "size": "321.73"}, {"price": "0.27", "size": "146.29"}, {"price": "0.32", "size": "75"}, {"price": "0.34", "size": "20"}, {"price": "0.36", "size": "55.55"}, {"price": "0.374", "size": "3818"}, {"price": "0.474", "size": "1800"}, {"price": "0.475", "size": "5"}, {"price": "0.519", "size": "120"}, {"price": "0.52", "size": "10"}, {"price": "0.592", "size": "40"}, {"price": "0.593", "size": "30"}, {"price": "0.66", "size": "100"}, {"price": "0.82", "size": "10"}, {"price": "0.833", "size": "20"}, {"price": "0.852", "size": "25"}, {"price": "0.859", "size": "80.86"}, {"price": "0.87", "size": "1000"}, {"price": "0.871", "size": "126.48"}, {"price": "0.875", "size": "25"}, {"price": "0.879", "size": "66.66"}, {"price": "0.887", "size": "100.66"}], "asks": [{"price": "0.999", "size": "60441"}, {"price": "0.998", "size": "4660"}, {"price": "0.997", "size": "172.56"}, {"price": "0.996", "size": "45.87"}, {"price": "0.993", "size": "14"}, {"price": "0.992", "size": "12.77"}, {"price": "0.967", "size": "41.2"}, {"price": "0.905", "size": "10"}, {"price": "0.904", "size": "13"}], "event_type": "book", "last_trade_price": ""}, {"market": "0xc24eb4117f0afd9c6f7d7d141500ef960e472a04baab50b1645ea2147d6d82cf", "asset_id": "84756279960216148559351094969736065857910692755202009808624524112488209810204", "timestamp": "1769384002484", "hash": "961333cf796bbc50e03f1b71caee6e80c99e30e9", "bids": [{"price": "0.001", "size": "3805"}, {"price": "0.002", "size": "45.44"}, {"price": "0.003", "size": "7.24"}, {"price": "0.007", "size": "1537.9"}, {"price": "0.008", "size": "1125"}, {"price": "0.009", "size": "257.13"}, {"price": "0.014", "size": "579.8"}, {"price": "0.017", "size": "30"}], "asks": [{"price": "0.999", "size": "3912.85"}, {"price": "0.998", "size": "504555.85"}, {"price": "0.997", "size": "1400"}, {"price": "0.996", "size": "10.12"}, {"price": "0.994", "size": "200"}, {"price": "0.99", "size": "2000"}, {"price": "0.989", "size": "5.14"}, {"price": "0.98", "size": "4000"}, {"price": "0.979", "size": "12.48"}, {"price": "0.96", "size": "500"}, {"price": "0.95", "size": "330"}, {"price": "0.949", "size": "39"}, {"price": "0.948", "size": "19"}, {"price": "0.93", "size": "300"}, {"price": "0.929", "size": "7.65"}, {"price": "0.9", "size": "560"}, {"price": "0.85", "size": "551.66"}, {"price": "0.8", "size": "460"}, {"price": "0.799", "size": "5.37"}, {"price": "0.75", "size": "262"}, {"price": "0.73", "size": "50"}, {"price": "0.7", "size": "86.66"}, {"price": "0.66", "size": "50"}, {"price": "0.65", "size": "68.57"}, {"price": "0.6", "size": "50"}, {"price": "0.529", "size": "4049"}, {"price": "0.523", "size": "10"}, {"price": "0.522", "size": "60"}, {"price": "0.52", "size": "5"}, {"price": "0.518", "size": "454"}, {"price": "0.517", "size": "931"}, {"price": "0.516", "size": "30"}, {"price": "0.24", "size": "20"}, {"price": "0.186", "size": "300"}, {"price": "0.115", "size": "10"}, {"price": "0.113", "size": "16"}, {"price": "0.112", "size": "20"}, {"price": "0.06", "size": "944.94"}, {"price": "0.059", "size": "500"}, {"price": "0.035", "size": "220.32"}, {"price": "0.034", "size": "400"}, {"price": "0.03", "size": "500"}, {"price": "0.029", "size": "109.74"}, {"price": "0.028", "size": "247"}, {"price": "0.027", "size": "30"}, {"price": "0.025", "size": "15"}], "event_type": "book", "last_trade_price": "0.017"}, {"market": "0xdf4e0e5a4825e829490808d950849cc1350263c38aeafaa7ef9207fd61fb0ad8", "asset_id": "83810221696024064577133768191341496793714910843496960551410909910739617026704", "timestamp": "1769383938665", "hash": "61b0fc2a84388bfb7227dd882b372729bed518f0", "bids": [{"price": "0.001", "size": "4076.55"}, {"price": "0.002", "size": "1255.9"}, {"price": "0.003", "size": "1400"}, {"price": "0.004", "size": "10.21"}, {"price": "0.006", "size": "200"}, {"price": "0.01", "size": "5000"}, {"price": "0.011", "size": "5.19"}, {"price": "0.02", "size": "4300"}, {"price": "0.021", "size": "7.99"}, {"price": "0.05", "size": "330"}, {"price": "0.051", "size": "39"}, {"price": "0.052", "size": "11.73"}, {"price": "0.09", "size": "700"}, {"price": "0.14", "size": "567.85"}, {"price": "0.19", "size": "168.42"}, {"price": "0.194", "size": "4142"}, {"price": "0.195", "size": "5.67"}, {"price": "0.24", "size": "116.66"}, {"price": "0.251", "size": "450"}, {"price": "0.27", "size": "50"}, {"price": "0.29", "size": "89.65"}, {"price": "0.33", "size": "72.72"}, {"price": "0.38", "size": "177.63"}, {"price": "0.519", "size": "1763"}, {"price": "0.52", "size": "100"}, {"price": "0.521", "size": "100"}, {"price": "0.522", "size": "5"}, {"price": "0.664", "size": "150"}, {"price": "0.714", "size": "100"}, {"price": "0.715", "size": "10"}, {"price": "0.79", "size": "76.92"}, {"price": "0.8", "size": "5"}, {"price": "0.815", "size": "5"}, {"price": "0.819", "size": "40"}, {"price": "0.82", "size": "30"}, {"price": "0.85", "size": "10"}, {"price": "0.851", "size": "20"}, {"price": "0.886", "size": "7.45"}, {"price": "0.905", "size": "8"}, {"price": "0.907", "size": "60"}], "asks": [{"price": "0.999", "size": "27566.99"}, {"price": "0.998", "size": "1000"}, {"price": "0.997", "size": "6.33"}, {"price": "0.996", "size": "5020"}, {"price": "0.995", "size": "250"}, {"price": "0.994", "size": "8.21"}, {"price": "0.987", "size": "100"}, {"price": "0.986", "size": "15.53"}, {"price": "0.966", "size": "600"}, {"price": "0.965", "size": "318.87"}, {"price": "0.952", "size": "74.24"}, {"price": "0.939", "size": "25"}, {"price": "0.938", "size": "74.17"}], "event_type": "book", "last_trade_price": "0.063"}, {"market": "0x42c5b40ce67dd7730d4bd522c2971217e4071c0a1c814ba0998fa8fa59bcfa3b", "asset_id": "81326650125094809268080637938129269014671684967955856212777724369859659142892", "timestamp": "1769384000538", "hash": "f21b0025e6b94f0d183c15931e06154a4d12881b", "bids": [{"price": "0.01", "size": "5"}, {"price": "0.02", "size": "270"}, {"price": "0.03", "size": "436.66"}, {"price": "0.04", "size": "193.73"}, {"price": "0.05", "size": "200"}, {"price": "0.06", "size": "430"}, {"price": "0.07", "size": "1169.54"}, {"price": "0.08", "size": "303.56"}], "asks": [{"price": "0.99", "size": "5024.97"}, {"price": "0.98", "size": "4300"}, {"price": "0.97", "size": "7.07"}, {"price": "0.95", "size": "330"}, {"price": "0.94", "size": "33"}, {"price": "0.93", "size": "7.96"}, {"price": "0.91", "size": "700"}, {"price": "0.86", "size": "567.85"}, {"price": "0.81", "size": "418.42"}, {"price": "0.8", "size": "5.58"}, {"price": "0.79", "size": "760"}, {"price": "0.77", "size": "121.73"}, {"price": "0.76", "size": "3334"}, {"price": "0.75", "size": "1680"}, {"price": "0.72", "size": "392.85"}, {"price": "0.67", "size": "72.72"}, {"price": "0.63", "size": "179.05"}, {"price": "0.47", "size": "1484"}, {"price": "0.46", "size": "134.3"}, {"price": "0.45", "size": "5"}, {"price": "0.42", "size": "10"}, {"price": "0.27", "size": "100"}, {"price": "0.26", "size": "40"}, {"price": "0.25", "size": "30"}, {"price": "0.22", "size": "105"}, {"price": "0.18", "size": "100"}, {"price": "0.17", "size": "20"}, {"price": "0.16", "size": "5"}, {"price": "0.13", "size": "162.19"}, {"price": "0.12", "size": "69.75"}, {"price": "0.11", "size": "34"}, {"price": "0.1", "size": "36"}], "event_type": "book", "last_trade_price": "0.110"}, {"market": "0xc24eb4117f0afd9c6f7d7d141500ef960e472a04baab50b1645ea2147d6d82cf", "asset_id": "14668335989719155721356955488155430077949621963536264077024658800820273637531", "timestamp": "1769384002484", "hash": "a5797e3714509ef277f8f0c36fcaa6e13861011b", "bids": [{"price": "0.001", "size": "3912.85"}, {"price": "0.002", "size": "504555.85"}, {"price": "0.003", "size": "1400"}, {"price": "0.004", "size": "10.12"}, {"price": "0.006", "size": "200"}, {"price": "0.01", "size": "2000"}, {"price": "0.011", "size": "5.14"}, {"price": "0.02", "size": "4000"}, {"price": "0.021", "size": "12.48"}, {"price": "0.04", "size": "500"}, {"price": "0.05", "size": "330"}, {"price": "0.051", "size": "39"}, {"price": "0.052", "size": "19"}, {"price": "0.07", "size": "300"}, {"price": "0.071", "size": "7.65"}, {"price": "0.1", "size": "560"}, {"price": "0.15", "size": "551.66"}, {"price": "0.2", "size": "460"}, {"price": "0.201", "size": "5.37"}, {"price": "0.25", "size": "262"}, {"price": "0.27", "size": "50"}, {"price": "0.3", "size": "86.66"}, {"price": "0.34", "size": "50"}, {"price": "0.35", "size": "68.57"}, {"price": "0.4", "size": "50"}, {"price": "0.471", "size": "4049"}, {"price": "0.477", "size": "10"}, {"price": "0.478", "size": "60"}, {"price": "0.48", "size": "5"}, {"price": "0.482", "size": "454"}, {"price": "0.483", "size": "931"}, {"price": "0.484", "size": "30"}, {"price": "0.76", "size": "20"}, {"price": "0.814", "size": "300"}, {"price": "0.885", "size": "10"}, {"price": "0.887", "size": "16"}, {"price": "0.888", "size": "20"}, {"price": "0.94", "size": "944.94"}, {"price": "0.941", "size": "500"}, {"price": "0.965", "size": "220.32"}, {"price": "0.966", "size": "400"}, {"price": "0.97", "size": "500"}, {"price": "0.971", "size": "109.74"}, {"price": "0.972", "size": "247"}, {"price": "0.973", "size": "30"}, {"price": "0.975", "size": "15"}], "asks": [{"price": "0.999", "size": "3805"}, {"price": "0.998", "size": "45.44"}, {"price": "0.997", "size": "7.24"}, {"price": "0.993", "size": "1537.9"}, {"price": "0.992", "size": "1125"}, {"price": "0.991", "size": "257.13"}, {"price": "0.986", "size": "579.8"}, {"price": "0.983", "size": "30"}], "event_type": "book", "last_trade_price": "0.017"}, {"market": "0x28123eb9eff2b8939327a7c4cda4f4b248579a46e988ac5ff1c78289bc270f4a", "asset_id": "104728087695427500082120491580204426891505246697057675663586272922687336585193", "timestamp": "1769384002484", "hash": "bfc41232810b177d77be51ba679c03717cd80951", "bids": [{"price": "0.001", "size": "3988.55"}, {"price": "0.002", "size": "504555.84"}, {"price": "0.003", "size": "1400"}, {"price": "0.004", "size": "10.1"}, {"price": "0.006", "size": "200"}, {"price": "0.01", "size": "2000"}, {"price": "0.011", "size": "5.13"}, {"price": "0.02", "size": "4000"}, {"price": "0.021", "size": "12.47"}, {"price": "0.05", "size": "330"}, {"price": "0.051", "size": "39"}, {"price": "0.07", "size": "300"}, {"price": "0.071", "size": "7.69"}, {"price": "0.1", "size": "560"}, {"price": "0.15", "size": "551.66"}, {"price": "0.2", "size": "410"}, {"price": "0.201", "size": "5.36"}, {"price": "0.216", "size": "3704"}, {"price": "0.217", "size": "250"}, {"price": "0.25", "size": "112"}, {"price": "0.27", "size": "50"}, {"price": "0.3", "size": "86.66"}, {"price": "0.35", "size": "68.57"}, {"price": "0.37", "size": "20"}, {"price": "0.4", "size": "175"}, {"price": "0.534", "size": "5"}, {"price": "0.539", "size": "12.5"}, {"price": "0.54", "size": "1508"}, {"price": "0.541", "size": "452.35"}, {"price": "0.542", "size": "100"}, {"price": "0.544", "size": "183"}, {"price": "0.545", "size": "100"}, {"price": "0.742", "size": "100"}, {"price": "0.743", "size": "10"}, {"price": "0.794", "size": "137.5"}, {"price": "0.86", "size": "10"}, {"price": "0.862", "size": "30"}, {"price": "0.863", "size": "40"}, {"price": "0.89", "size": "5"}, {"price": "0.891", "size": "8"}, {"price": "0.892", "size": "20"}, {"price": "0.91", "size": "3.32"}, {"price": "0.942", "size": "53.62"}], "asks": [{"price": "0.999", "size": "9556"}, {"price": "0.998", "size": "11668.01"}, {"price": "0.997", "size": "35.82"}, {"price": "0.992", "size": "43.05"}, {"price": "0.991", "size": "1189.6"}, {"price": "0.988", "size": "121.54"}, {"price": "0.987", "size": "7.85"}, {"price": "0.981", "size": "55.88"}, {"price": "0.973", "size": "60.88"}], "event_type": "book", "last_trade_price": "0.013"}, {"market": "0x3acc06a95895e69efeeaae4dfdce738b91702c94556b230208b4f0438be8e4e5", "asset_id": "83704131174101958386167453703299325546481597640863540368605877922778589412742", "timestamp": "1769384000703", "hash": "7f5dc170b612dfd748dde955d9f95719ef786675", "bids": [{"price": "0.02", "size": "98"}, {"price": "0.03", "size": "29.52"}, {"price": "0.04", "size": "70"}, {"price": "0.05", "size": "60"}, {"price": "0.12", "size": "120"}, {"price": "0.13", "size": "210"}, {"price": "0.14", "size": "131.11"}, {"price": "0.15", "size": "526.78"}, {"price": "0.16", "size": "21"}], "asks": [{"price": "0.99", "size": "5005.66"}, {"price": "0.98", "size": "4305.6"}, {"price": "0.97", "size": "250"}, {"price": "0.96", "size": "6.4"}, {"price": "0.95", "size": "310"}, {"price": "0.92", "size": "750"}, {"price": "0.91", "size": "5.51"}, {"price": "0.87", "size": "586.53"}, {"price": "0.83", "size": "188.23"}, {"price": "0.8", "size": "1050"}, {"price": "0.79", "size": "138.46"}, {"price": "0.78", "size": "2108"}, {"price": "0.74", "size": "100"}, {"price": "0.73", "size": "50"}, {"price": "0.72", "size": "20"}, {"price": "0.7", "size": "80"}, {"price": "0.66", "size": "108.82"}, {"price": "0.59", "size": "3408"}, {"price": "0.58", "size": "1000"}, {"price": "0.5", "size": "800"}, {"price": "0.49", "size": "490"}, {"price": "0.48", "size": "5"}, {"price": "0.47", "size": "10"}, {"price": "0.46", "size": "30"}, {"price": "0.45", "size": "40"}, {"price": "0.24", "size": "100"}, {"price": "0.23", "size": "25.26"}, {"price": "0.21", "size": "310"}, {"price": "0.2", "size": "210"}, {"price": "0.19", "size": "326"}, {"price": "0.18", "size": "287"}], "event_type": "book", "last_trade_price": ""}, {"market": "0x42c5b40ce67dd7730d4bd522c2971217e4071c0a1c814ba0998fa8fa59bcfa3b", "asset_id": "27360908173410110529670070736001232422485421937616132330605471045429078161694", "timestamp": "1769384000538", "hash": "a28e2ce21fec33f9eb618674cbe3d86d7d0ebe04", "bids": [{"price": "0.01", "size": "5024.97"}, {"price": "0.02", "size": "4300"}, {"price": "0.03", "size": "7.07"}, {"price": "0.05", "size": "330"}, {"price": "0.06", "size": "33"}, {"price": "0.07", "size": "7.96"}, {"price": "0.09", "size": "700"}, {"price": "0.14", "size": "567.85"}, {"price": "0.19", "size": "418.42"}, {"price": "0.2", "size": "5.58"}, {"price": "0.21", "size": "760"}, {"price": "0.23", "size": "121.73"}, {"price": "0.24", "size": "3334"}, {"price": "0.25", "size": "1680"}, {"price": "0.28", "size": "392.85"}, {"price": "0.33", "size": "72.72"}, {"price": "0.37", "size": "179.05"}, {"price": "0.53", "size": "1484"}, {"price": "0.54", "size": "134.3"}, {"price": "0.55", "size": "5"}, {"price": "0.58", "size": "10"}, {"price": "0.73", "size": "100"}, {"price": "0.74", "size": "40"}, {"price": "0.75", "size": "30"}, {"price": "0.78", "size": "105"}, {"price": "0.82", "size": "100"}, {"price": "0.83", "size": "20"}, {"price": "0.84", "size": "5"}, {"price": "0.87", "size": "162.19"}, {"price": "0.88", "size": "69.75"}, {"price": "0.89", "size": "34"}, {"price": "0.9", "size": "36"}], "asks": [{"price": "0.99", "size": "5"}, {"price": "0.98", "size": "270"}, {"price": "0.97", "size": "436.66"}, {"price": "0.96", "size": "193.73"}, {"price": "0.95", "size": "200"}, {"price": "0.94", "size": "430"}, {"price": "0.93", "size": "1169.54"}, {"price": "0.92", "size": "303.56"}], "event_type": "book", "last_trade_price": "0.110"}, {"market": "0x28123eb9eff2b8939327a7c4cda4f4b248579a46e988ac5ff1c78289bc270f4a", "asset_id": "89418427142329680204104945771724971195245381529529701350965460000652874020293", "timestamp": "1769384002484", "hash": "f45a4fec89e6468e1fee64607e6cf52ee5bce3fd", "bids": [{"price": "0.001", "size": "9556"}, {"price": "0.002", "size": "11668.01"}, {"price": "0.003", "size": "35.82"}, {"price": "0.008", "size": "43.05"}, {"price": "0.009", "size": "1189.6"}, {"price": "0.012", "size": "121.54"}, {"price": "0.013", "size": "7.85"}, {"price": "0.019", "size": "55.88"}, {"price": "0.027", "size": "60.88"}], "asks": [{"price": "0.999", "size": "3988.55"}, {"price": "0.998", "size": "504555.84"}, {"price": "0.997", "size": "1400"}, {"price": "0.996", "size": "10.1"}, {"price": "0.994", "size": "200"}, {"price": "0.99", "size": "2000"}, {"price": "0.989", "size": "5.13"}, {"price": "0.98", "size": "4000"}, {"price": "0.979", "size": "12.47"}, {"price": "0.95", "size": "330"}, {"price": "0.949", "size": "39"}, {"price": "0.93", "size": "300"}, {"price": "0.929", "size": "7.69"}, {"price": "0.9", "size": "560"}, {"price": "0.85", "size": "551.66"}, {"price": "0.8", "size": "410"}, {"price": "0.799", "size": "5.36"}, {"price": "0.784", "size": "3704"}, {"price": "0.783", "size": "250"}, {"price": "0.75", "size": "112"}, {"price": "0.73", "size": "50"}, {"price": "0.7", "size": "86.66"}, {"price": "0.65", "size": "68.57"}, {"price": "0.63", "size": "20"}, {"price": "0.6", "size": "175"}, {"price": "0.466", "size": "5"}, {"price": "0.461", "size": "12.5"}, {"price": "0.46", "size": "1508"}, {"price": "0.459", "size": "452.35"}, {"price": "0.458", "size": "100"}, {"price": "0.456", "size": "183"}, {"price": "0.455", "size": "100"}, {"price": "0.258", "size": "100"}, {"price": "0.257", "size": "10"}, {"price": "0.206", "size": "137.5"}, {"price": "0.14", "size": "10"}, {"price": "0.138", "size": "30"}, {"price": "0.137", "size": "40"}, {"price": "0.11", "size": "5"}, {"price": "0.109", "size": "8"}, {"price": "0.108", "size": "20"}, {"price": "0.09", "size": "3.32"}, {"price": "0.058", "size": "53.62"}], "event_type": "book", "last_trade_price": "0.013"}, {"market": "0x897a2f88e1b65776ac5af0440833eea638395f0af0df4bed47e83f64c9b9a1e3", "asset_id": "11824574045576628150612194967948587889530003270004521491303323671815597832573", "timestamp": "1769384002484", "hash": "a10af4c8bb400d49492450133ae8dccadd2a474d", "bids": [{"price": "0.01", "size": "5000"}, {"price": "0.02", "size": "3300"}, {"price": "0.03", "size": "250"}, {"price": "0.04", "size": "7.14"}, {"price": "0.05", "size": "1020"}, {"price": "0.08", "size": "725"}, {"price": "0.11", "size": "290.9"}, {"price": "0.13", "size": "1555"}, {"price": "0.14", "size": "200"}, {"price": "0.15", "size": "2798"}, {"price": "0.16", "size": "250"}, {"price": "0.17", "size": "152.94"}, {"price": "0.19", "size": "126.31"}, {"price": "0.22", "size": "90.9"}, {"price": "0.24", "size": "3246"}, {"price": "0.45", "size": "225"}, {"price": "0.48", "size": "1693.72"}, {"price": "0.49", "size": "333"}, {"price": "0.51", "size": "410"}, {"price": "0.52", "size": "2214.49"}, {"price": "0.53", "size": "583"}, {"price": "0.54", "size": "67.37"}], "asks": [{"price": "0.99", "size": "5313.97"}, {"price": "0.98", "size": "3000"}, {"price": "0.97", "size": "11.55"}, {"price": "0.95", "size": "1020"}, {"price": "0.93", "size": "1285.71"}, {"price": "0.92", "size": "7.13"}, {"price": "0.91", "size": "355.55"}, {"price": "0.89", "size": "1454"}, {"price": "0.88", "size": "233.33"}, {"price": "0.87", "size": "3555"}, {"price": "0.86", "size": "205.71"}, {"price": "0.85", "size": "20"}, {"price": "0.84", "size": "2420"}, {"price": "0.83", "size": "264.45"}, {"price": "0.82", "size": "25.23"}, {"price": "0.81", "size": "245.26"}, {"price": "0.8", "size": "25"}, {"price": "0.77", "size": "50"}, {"price": "0.76", "size": "40"}, {"price": "0.74", "size": "48"}, {"price": "0.72", "size": "575"}, {"price": "0.71", "size": "15"}, {"price": "0.67", "size": "85"}, {"price": "0.66", "size": "40"}, {"price": "0.63", "size": "7"}, {"price": "0.61", "size": "30"}, {"price": "0.58", "size": "620"}, {"price": "0.57", "size": "583.04"}, {"price": "0.56", "size": "31"}], "event_type": "book", "last_trade_price": "0.550"}]}
{"_local_timestamp": "2026-01-25T23:33:28.622793+00:00", "data": {"market": "0xf829129cd05db888741ad290c786a1d71db5f8bb8493d8bc07e21b826db4d328", "price_changes": [{"asset_id": "105495516848871865829093849779907676478444075202002902600889102615883909197041", "price": "0.833", "size": "0", "side": "BUY", "hash": "981c7907f7e5e95f86087d0326d3e35ac4a912c5", "best_bid": "0.887", "best_ask": "0.904"}, {"asset_id": "90685511192998551789516562849422906363784901518167369632157413860597087715433", "price": "0.167", "size": "0", "side": "SELL", "hash": "a69e0695764a93c77cf9f5400eaf0413337cdefa", "best_bid": "0.096", "best_ask": "0.113"}], "timestamp": "1769384008560", "event_type": "price_change"}}
{"_local_timestamp": "2026-01-25T23:33:28.651536+00:00", "data": {"market": "0xf829129cd05db888741ad290c786a1d71db5f8bb8493d8bc07e21b826db4d328", "price_changes": [{"asset_id": "105495516848871865829093849779907676478444075202002902600889102615883909197041", "price": "0.821", "size": "20", "side": "BUY", "hash": "8fd31f819610c4fd14ac1147270c476d1a610d62", "best_bid": "0.887", "best_ask": "0.904"}, {"asset_id": "90685511192998551789516562849422906363784901518167369632157413860597087715433", "price": "0.179", "size": "20", "side": "SELL", "hash": "58595d912afea11815f85ec6aa4675d7557cc2e6", "best_bid": "0.096", "best_ask": "0.113"}], "timestamp": "1769384008584", "event_type": "price_change"}}
{"_local_timestamp": "2026-01-25T23:33:28.741241+00:00", "data": {"market": "0xf829129cd05db888741ad290c786a1d71db5f8bb8493d8bc07e21b826db4d328", "price_changes": [{"asset_id": "105495516848871865829093849779907676478444075202002902600889102615883909197041", "price": "0.852", "size": "0", "side": "BUY", "hash": "e56538b61dd7a0c042f987fe6b7d0dbea3cd413c", "best_bid": "0.887", "best_ask": "0.904"}, {"asset_id": "90685511192998551789516562849422906363784901518167369632157413860597087715433", "price": "0.148", "size": "0", "side": "SELL", "hash": "0ac4dd5b9e6bce6edaa4b38eb45c80d465e05543", "best_bid": "0.096", "best_ask": "0.113"}], "timestamp": "1769384008668", "event_type": "price_change"}}
{"_local_timestamp": "2026-01-25T23:33:28.752307+00:00", "data": {"market": "0xf829129cd05db888741ad290c786a1d71db5f8bb8493d8bc07e21b826db4d328", "price_changes": [{"asset_id": "105495516848871865829093849779907676478444075202002902600889102615883909197041", "price": "0.832", "size": "51", "side": "BUY", "hash": "5cf4c581433c34fcf91ba3fefe6f59827ea7f568", "best_bid": "0.887", "best_ask": "0.904"}, {"asset_id": "90685511192998551789516562849422906363784901518167369632157413860597087715433", "price": "0.168", "size": "51", "side": "SELL", "hash": "a26d544205ca6bb5b1fd4fab74e8b5d20c49c474", "best_bid": "0.096", "best_ask": "0.113"}], "timestamp": "1769384008684", "event_type": "price_change"}}
{"_local_timestamp": "2026-01-25T23:33:29.450553+00:00", "data": {"market": "0xf829129cd05db888741ad290c786a1d71db5f8bb8493d8bc07e21b826db4d328", "price_changes": [{"asset_id": "105495516848871865829093849779907676478444075202002902600889102615883909197041", "price": "0.821", "size": "0", "side": "BUY", "hash": "7450fa3635e842353a2ece171e315bfb24d96e11", "best_bid": "0.887", "best_ask": "0.904"}, {"asset_id": "90685511192998551789516562849422906363784901518167369632157413860597087715433", "price": "0.179", "size": "0", "side": "SELL", "hash": "034d67a24597264f65001a6a42f926828fdcad4d", "best_bid": "0.096", "best_ask": "0.113"}], "timestamp": "1769384009377", "event_type": "price_change"}}
{"_local_timestamp": "2026-01-25T23:33:29.486334+00:00", "data": {"market": "0xf829129cd05db888741ad290c786a1d71db5f8bb8493d8bc07e21b826db4d328", "price_changes": [{"asset_id": "105495516848871865829093849779907676478444075202002902600889102615883909197041", "price": "0.833", "size": "20", "side": "BUY", "hash": "4cb546682b837479c2f4b57d8bbb2236177440ec", "best_bid": "0.887", "best_ask": "0.904"}, {"asset_id": "90685511192998551789516562849422906363784901518167369632157413860597087715433", "price": "0.167", "size": "20", "side": "SELL", "hash": "744a2ab46549d2b60c7d917d498290510894a9d4", "best_bid": "0.096", "best_ask": "0.113"}], "timestamp": "1769384009415", "event_type": "price_change"}}
{"_local_timestamp": "2026-01-25T23:33:29.566942+00:00", "data": {"market": "0xf829129cd05db888741ad290c786a1d71db5f8bb8493d8bc07e21b826db4d328", "price_changes": [{"asset_id": "105495516848871865829093849779907676478444075202002902600889102615883909197041", "price": "0.832", "size": "0", "side": "BUY", "hash": "b35e976d2645b5d659161eabd68d85055417d1d0", "best_bid": "0.887", "best_ask": "0.904"}, {"asset_id": "90685511192998551789516562849422906363784901518167369632157413860597087715433", "price": "0.168", "size": "0", "side": "SELL", "hash": "3463c439f99c4d2919757c4bf90ac9a82cebaf0c", "best_bid": "0.096", "best_ask": "0.113"}], "timestamp": "1769384009484", "event_type": "price_change"}}
{"_local_timestamp": "2026-01-25T23:33:29.568465+00:00", "data": {"market": "0xf829129cd05db888741ad290c786a1d71db5f8bb8493d8bc07e21b826db4d328", "price_changes": [{"asset_id": "105495516848871865829093849779907676478444075202002902600889102615883909197041", "price": "0.832", "size": "51", "side": "BUY", "hash": "9b873de1575676e425bd6df6c3e706cd8285810d", "best_bid": "0.887", "best_ask": "0.904"}, {"asset_id": "90685511192998551789516562849422906363784901518167369632157413860597087715433", "price": "0.168", "size": "51", "side": "SELL", "hash": "d9cffe2a007c449a94002175c450c7c95a76fdb3", "best_bid": "0.096", "best_ask": "0.113"}], "timestamp": "1769384009491", "event_type": "price_change"}}
{"_local_timestamp": "2026-01-25T23:33:29.599272+00:00", "data": {"market": "0xf829129cd05db888741ad290c786a1d71db5f8bb8493d8bc07e21b826db4d328", "price_changes": [{"asset_id": "105495516848871865829093849779907676478444075202002902600889102615883909197041", "price": "0.852", "size": "25", "side": "BUY", "hash": "0e9495c7cd25d18b132b375ac0d7a6312389657f", "best_bid": "0.887", "best_ask": "0.904"}, {"asset_id": "90685511192998551789516562849422906363784901518167369632157413860597087715433", "price": "0.148", "size": "25", "side": "SELL", "hash": "83b7b41c32ae6284888068d9a09f4f043a121e5d", "best_bid": "0.096", "best_ask": "0.113"}], "timestamp": "1769384009529", "event_type": "price_change"}}
{"_local_timestamp": "2026-01-25T23:33:29.678229+00:00", "data": {"market": "0xf829129cd05db888741ad290c786a1d71db5f8bb8493d8bc07e21b826db4d328", "price_changes": [{"asset_id": "105495516848871865829093849779907676478444075202002902600889102615883909197041", "price": "0.832", "size": "0", "side": "BUY", "hash": "cff022245931c119e27526449e1e2307aa2ecc9b", "best_bid": "0.887", "best_ask": "0.904"}, {"asset_id": "90685511192998551789516562849422906363784901518167369632157413860597087715433", "price": "0.168", "size": "0", "side": "SELL", "hash": "30f7d6393e362cbdcfec6219adba4d7a0eb3bbb7", "best_bid": "0.096", "best_ask": "0.113"}], "timestamp": "1769384009609", "event_type": "price_change"}}
{"_local_timestamp": "2026-01-25T23:33:29.941712+00:00", "data": {"market": "0xf829129cd05db888741ad290c786a1d71db5f8bb8493d8bc07e21b826db4d328", "price_changes": [{"asset_id": "105495516848871865829093849779907676478444075202002902600889102615883909197041", "price": "0.833", "size": "0", "side": "BUY", "hash": "6c4db15fce25e65b2dc70d25cb9429a577f1bc7c", "best_bid": "0.887", "best_ask": "0.904"}, {"asset_id": "90685511192998551789516562849422906363784901518167369632157413860597087715433", "price": "0.167", "size": "0", "side": "SELL", "hash": "cc572769e5654f20bc844e998d89e5a0a5af53fa", "best_bid": "0.096", "best_ask": "0.113"}], "timestamp": "1769384009866", "event_type": "price_change"}}
{"_local_timestamp": "2026-01-25T23:33:29.967088+00:00", "data": {"market": "0xf829129cd05db888741ad290c786a1d71db5f8bb8493d8bc07e21b826db4d328", "price_changes": [{"asset_id": "105495516848871865829093849779907676478444075202002902600889102615883909197041", "price": "0.821", "size": "20", "side": "BUY", "hash": "f6871bcedbf3e34ee669f12eebc145a6fb7726e6", "best_bid": "0.887", "best_ask": "0.904"}, {"asset_id": "90685511192998551789516562849422906363784901518167369632157413860597087715433", "price": "0.179", "size": "20", "side": "SELL", "hash": "d0516984e25f074376d49402f1490983930cf94b", "best_bid": "0.096", "best_ask": "0.113"}], "timestamp": "1769384009888", "event_type": "price_change"}}
{"_local_timestamp": "2026-01-25T23:33:30.034247+00:00", "data": {"market": "0xf829129cd05db888741ad290c786a1d71db5f8bb8493d8bc07e21b826db4d328", "price_changes": [{"asset_id": "105495516848871865829093849779907676478444075202002902600889102615883909197041", "price": "0.852", "size": "0", "side": "BUY", "hash": "0a993b7f415aed203a8c0782235776862e62480a", "best_bid": "0.887", "best_ask": "0.904"}, {"asset_id": "90685511192998551789516562849422906363784901518167369632157413860597087715433", "price": "0.148", "size": "0", "side": "SELL", "hash": "14d891cfaef5db4579a0e5e03376bcf2b0f0134a", "best_bid": "0.096", "best_ask": "0.113"}], "timestamp": "1769384009968", "event_type": "price_change"}}
{"_local_timestamp": "2026-01-25T23:33:30.149769+00:00", "data": {"market": "0xf829129cd05db888741ad290c786a1d71db5f8bb8493d8bc07e21b826db4d328", "price_changes": [{"asset_id": "105495516848871865829093849779907676478444075202002902600889102615883909197041", "price": "0.832", "size": "51", "side": "BUY", "hash": "829eaf3bc79cd7a57baad5366b26bdd2cef1b275", "best_bid": "0.887", "best_ask": "0.904"}, {"asset_id": "90685511192998551789516562849422906363784901518167369632157413860597087715433", "price": "0.168", "size": "51", "side": "SELL", "hash": "5de4bf020b683004fc284eb75d993b5c2313b586", "best_bid": "0.096", "best_ask": "0.113"}], "timestamp": "1769384010075", "event_type": "price_change"}}
{"_local_timestamp": "2026-01-25T23:33:30.635298+00:00", "data": {"market": "0xf829129cd05db888741ad290c786a1d71db5f8bb8493d8bc07e21b826db4d328", "price_changes": [{"asset_id": "105495516848871865829093849779907676478444075202002902600889102615883909197041", "price": "0.821", "size": "0", "side": "BUY", "hash": "e8ca035e40f6d9e0b8dcd621790d4b1f3005ddf6", "best_bid": "0.887", "best_ask": "0.904"}, {"asset_id": "90685511192998551789516562849422906363784901518167369632157413860597087715433", "price": "0.179", "size": "0", "side": "SELL", "hash": "8b98c31ea874cb20c9e6ff29caae9726af40c3c2", "best_bid": "0.096", "best_ask": "0.113"}], "timestamp": "1769384010568", "event_type": "price_change"}}
{"_local_timestamp": "2026-01-25T23:33:30.662136+00:00", "data": {"market": "0xf829129cd05db888741ad290c786a1d71db5f8bb8493d8bc07e21b826db4d328", "price_changes": [{"asset_id": "105495516848871865829093849779907676478444075202002902600889102615883909197041", "price": "0.833", "size": "20", "side": "BUY", "hash": "1aae1bb15b8523bb8af0c1b2f15c278dd0b13ea7", "best_bid": "0.887", "best_ask": "0.904"}, {"asset_id": "90685511192998551789516562849422906363784901518167369632157413860597087715433", "price": "0.167", "size": "20", "side": "SELL", "hash": "b97a8c7cb8e1a2874c32033216e1ba8ff893b5a8", "best_bid": "0.096", "best_ask": "0.113"}], "timestamp": "1769384010592", "event_type": "price_change"}}
{"_local_timestamp": "2026-01-25T23:33:30.755311+00:00", "data": {"market": "0xf829129cd05db888741ad290c786a1d71db5f8bb8493d8bc07e21b826db4d328", "price_changes": [{"asset_id": "105495516848871865829093849779907676478444075202002902600889102615883909197041", "price": "0.832", "size": "0", "side": "BUY", "hash": "000297193c296a2fe196827854c63952a21327f5", "best_bid": "0.887", "best_ask": "0.904"}, {"asset_id": "90685511192998551789516562849422906363784901518167369632157413860597087715433", "price": "0.168", "size": "0", "side": "SELL", "hash": "540e1694efbb5d77a210d12bf23fdbe2122deb72", "best_bid": "0.096", "best_ask": "0.113"}], "timestamp": "1769384010686", "event_type": "price_change"}}
{"_local_timestamp": "2026-01-25T23:33:30.767189+00:00", "data": {"market": "0xf829129cd05db888741ad290c786a1d71db5f8bb8493d8bc07e21b826db4d328", "price_changes": [{"asset_id": "105495516848871865829093849779907676478444075202002902600889102615883909197041", "price": "0.852", "size": "25", "side": "BUY", "hash": "3b1dcfb1e40be306bb0b864b44453467f47d08b4", "best_bid": "0.887", "best_ask": "0.904"}, {"asset_id": "90685511192998551789516562849422906363784901518167369632157413860597087715433", "price": "0.148", "size": "25", "side": "SELL", "hash": "2f6db359cb8a4eb516e57afa5efc6b39923d299c", "best_bid": "0.096", "best_ask": "0.113"}], "timestamp": "1769384010697", "event_type": "price_change"}}
{"_local_timestamp": "2026-01-25T23:33:30.857496+00:00", "data": {"market": "0xf829129cd05db888741ad290c786a1d71db5f8bb8493d8bc07e21b826db4d328", "price_changes": [{"asset_id": "105495516848871865829093849779907676478444075202002902600889102615883909197041", "price": "0.852", "size": "50", "side": "BUY", "hash": "f49b974b78290c34d81bbc64c80e8c0221a57f95", "best_bid": "0.887", "best_ask": "0.904"}, {"asset_id": "90685511192998551789516562849422906363784901518167369632157413860597087715433", "price": "0.148", "size": "50", "side": "SELL", "hash": "4924102b3ad9b77fa96db586497630bf3427e7f3", "best_bid": "0.096", "best_ask": "0.113"}], "timestamp": "1769384010789", "event_type": "price_change"}}
{"_local_timestamp": "2026-01-25T23:33:31.007130+00:00", "data": {"market": "0xf829129cd05db888741ad290c786a1d71db5f8bb8493d8bc07e21b826db4d328", "price_changes": [{"asset_id": "105495516848871865829093849779907676478444075202002902600889102615883909197041", "price": "0.852", "size": "25", "side": "BUY", "hash": "f043eadeb266b7a5babe17363616ac39aec4a57a", "best_bid": "0.887", "best_ask": "0.904"}, {"asset_id": "90685511192998551789516562849422906363784901518167369632157413860597087715433", "price": "0.148", "size": "25", "side": "SELL", "hash": "52c3f4415d48cd8728ed2fa2b97e98df5f999fb2", "best_bid": "0.096", "best_ask": "0.113"}], "timestamp": "1769384010929", "event_type": "price_change"}}
{"_local_timestamp": "2026-01-25T23:33:31.248424+00:00", "data": {"market": "0xf829129cd05db888741ad290c786a1d71db5f8bb8493d8bc07e21b826db4d328", "price_changes": [{"asset_id": "105495516848871865829093849779907676478444075202002902600889102615883909197041", "price": "0.833", "size": "0", "side": "BUY", "hash": "2b12cfcdabcc1efde9148af4837c975bd4f14967", "best_bid": "0.887", "best_ask": "0.904"}, {"asset_id": "90685511192998551789516562849422906363784901518167369632157413860597087715433", "price": "0.167", "size": "0", "side": "SELL", "hash": "890de8b65e98f9e3c16c76c7229c9ae4bbf27309", "best_bid": "0.096", "best_ask": "0.113"}], "timestamp": "1769384011174", "event_type": "price_change"}}
{"_local_timestamp": "2026-01-25T23:33:31.269746+00:00", "data": {"market": "0xf829129cd05db888741ad290c786a1d71db5f8bb8493d8bc07e21b826db4d328", "price_changes": [{"asset_id": "105495516848871865829093849779907676478444075202002902600889102615883909197041", "price": "0.821", "size": "20", "side": "BUY", "hash": "4d4f6c5f030c4ec629e2082de8c34e1da9cb0f1c", "best_bid": "0.887", "best_ask": "0.904"}, {"asset_id": "90685511192998551789516562849422906363784901518167369632157413860597087715433", "price": "0.179", "size": "20", "side": "SELL", "hash": "68e90a5a45713f27dc8992fa589748f8896fefec", "best_bid": "0.096", "best_ask": "0.113"}], "timestamp": "1769384011200", "event_type": "price_change"}}
{"_local_timestamp": "2026-01-25T23:33:31.392940+00:00", "data": {"market": "0xf829129cd05db888741ad290c786a1d71db5f8bb8493d8bc07e21b826db4d328", "price_changes": [{"asset_id": "105495516848871865829093849779907676478444075202002902600889102615883909197041", "price": "0.852", "size": "0", "side": "BUY", "hash": "928befd561dc1af7fa3a18ed7725cc68bfb2851d", "best_bid": "0.887", "best_ask": "0.904"}, {"asset_id": "90685511192998551789516562849422906363784901518167369632157413860597087715433", "price": "0.148", "size": "0", "side": "SELL", "hash": "5a48ad52b7453e13daa40740e5a6768a6e53e307", "best_bid": "0.096", "best_ask": "0.113"}], "timestamp": "1769384011324", "event_type": "price_change"}}
{"_local_timestamp": "2026-01-25T23:33:31.432156+00:00", "data": {"market": "0xf829129cd05db888741ad290c786a1d71db5f8bb8493d8bc07e21b826db4d328", "price_changes": [{"asset_id": "105495516848871865829093849779907676478444075202002902600889102615883909197041", "price": "0.832", "size": "51", "side": "BUY", "hash": "e366a22fb8676b767777f869adcc950ae76a4120", "best_bid": "0.887", "best_ask": "0.904"}, {"asset_id": "90685511192998551789516562849422906363784901518167369632157413860597087715433", "price": "0.168", "size": "51", "side": "SELL", "hash": "35813ca0fe99a79d55efe1986542b2212e820583", "best_bid": "0.096", "best_ask": "0.113"}], "timestamp": "1769384011346", "event_type": "price_change"}}
{"_local_timestamp": "2026-01-25T23:33:32.433353+00:00", "data": {"market": "0xf829129cd05db888741ad290c786a1d71db5f8bb8493d8bc07e21b826db4d328", "price_changes": [{"asset_id": "105495516848871865829093849779907676478444075202002902600889102615883909197041", "price": "0.821", "size": "0", "side": "BUY", "hash": "f14cf586d145731d4be1ea0c283ac85413293f38", "best_bid": "0.887", "best_ask": "0.904"}, {"asset_id": "90685511192998551789516562849422906363784901518167369632157413860597087715433", "price": "0.179", "size": "0", "side": "SELL", "hash": "4f577bbf29b5ddc2da941f6d950384ae1b435877", "best_bid": "0.096", "best_ask": "0.113"}], "timestamp": "1769384012365", "event_type": "price_change"}}
{"_local_timestamp": "2026-01-25T23:33:32.466372+00:00", "data": {"market": "0xf829129cd05db888741ad290c786a1d71db5f8bb8493d8bc07e21b826db4d328", "price_changes": [{"asset_id": "105495516848871865829093849779907676478444075202002902600889102615883909197041", "price": "0.833", "size": "20", "side": "BUY", "hash": "a58aaab0d7806099d30e384adaeed360723e0366", "best_bid": "0.887", "best_ask": "0.904"}, {"asset_id": "90685511192998551789516562849422906363784901518167369632157413860597087715433", "price": "0.167", "size": "20", "side": "SELL", "hash": "0d575cc732d812d470706128709f459bd9f24a66", "best_bid": "0.096", "best_ask": "0.113"}], "timestamp": "1769384012390", "event_type": "price_change"}}
{"_local_timestamp": "2026-01-25T23:33:32.548351+00:00", "data": {"market": "0xf829129cd05db888741ad290c786a1d71db5f8bb8493d8bc07e21b826db4d328", "price_changes": [{"asset_id": "105495516848871865829093849779907676478444075202002902600889102615883909197041", "price": "0.832", "size": "0", "side": "BUY", "hash": "b35c7f7a4c7addcfe8743dd995e4cb7af6ac30cb", "best_bid": "0.887", "best_ask": "0.904"}, {"asset_id": "90685511192998551789516562849422906363784901518167369632157413860597087715433", "price": "0.168", "size": "0", "side": "SELL", "hash": "aa3d270d862bd99782b82222d3f6597082eb7907", "best_bid": "0.096", "best_ask": "0.113"}], "timestamp": "1769384012479", "event_type": "price_change"}}
{"_local_timestamp": "2026-01-25T23:33:32.580796+00:00", "data": {"market": "0xf829129cd05db888741ad290c786a1d71db5f8bb8493d8bc07e21b826db4d328", "price_changes": [{"asset_id": "105495516848871865829093849779907676478444075202002902600889102615883909197041", "price": "0.852", "size": "25", "side": "BUY", "hash": "bacb46d7874454618dd2591aef233392deeeb6b1", "best_bid": "0.887", "best_ask": "0.904"}, {"asset_id": "90685511192998551789516562849422906363784901518167369632157413860597087715433", "price": "0.148", "size": "25", "side": "SELL", "hash": "a894567b585fda2ce04693303763a44c9139ecf2", "best_bid": "0.096", "best_ask": "0.113"}], "timestamp": "1769384012504", "event_type": "price_change"}}
{"_local_timestamp": "2026-01-25T23:33:32.617433+00:00", "data": {"market": "0xf829129cd05db888741ad290c786a1d71db5f8bb8493d8bc07e21b826db4d328", "price_changes": [{"asset_id": "105495516848871865829093849779907676478444075202002902600889102615883909197041", "price": "0.852", "size": "50", "side": "BUY", "hash": "e678e8730dba5dc624e0bfe56283693decbeb41a", "best_bid": "0.887", "best_ask": "0.904"}, {"asset_id": "90685511192998551789516562849422906363784901518167369632157413860597087715433", "price": "0.148", "size": "50", "side": "SELL", "hash": "6580d7514005a4e63b63853c92026dab802bfc96", "best_bid": "0.096", "best_ask": "0.113"}], "timestamp": "1769384012553", "event_type": "price_change"}}
{"_local_timestamp": "2026-01-25T23:33:32.742823+00:00", "data": {"market": "0xf829129cd05db888741ad290c786a1d71db5f8bb8493d8bc07e21b826db4d328", "price_changes": [{"asset_id": "105495516848871865829093849779907676478444075202002902600889102615883909197041", "price": "0.852", "size": "25", "side": "BUY", "hash": "988196adb0fd63976ac559f86735e5feb7752caa", "best_bid": "0.887", "best_ask": "0.904"}, {"asset_id": "90685511192998551789516562849422906363784901518167369632157413860597087715433", "price": "0.148", "size": "25", "side": "SELL", "hash": "e7ac5f0fd6aa020d558aa97a12841074f8ee04dd", "best_bid": "0.096", "best_ask": "0.113"}], "timestamp": "1769384012668", "event_type": "price_change"}}
{"_local_timestamp": "2026-01-25T23:33:34.024478+00:00", "data": {"market": "0xf829129cd05db888741ad290c786a1d71db5f8bb8493d8bc07e21b826db4d328", "price_changes": [{"asset_id": "105495516848871865829093849779907676478444075202002902600889102615883909197041", "price": "0.833", "size": "0", "side": "BUY", "hash": "3028c4ccb332ca60962e2ac78d6336533dcfff01", "best_bid": "0.887", "best_ask": "0.904"}, {"asset_id": "90685511192998551789516562849422906363784901518167369632157413860597087715433", "price": "0.167", "size": "0", "side": "SELL", "hash": "545b72fe864902dd65482671c7c92fb12d5902ef", "best_bid": "0.096", "best_ask": "0.113"}], "timestamp": "1769384013957", "event_type": "price_change"}}
{"_local_timestamp": "2026-01-25T23:33:34.061820+00:00", "data": {"market": "0xf829129cd05db888741ad290c786a1d71db5f8bb8493d8bc07e21b826db4d328", "price_changes": [{"asset_id": "105495516848871865829093849779907676478444075202002902600889102615883909197041", "price": "0.821", "size": "20", "side": "BUY", "hash": "5da6e50c0be2c28772b4be12f7a26c950bfaf4bb", "best_bid": "0.887", "best_ask": "0.904"}, {"asset_id": "90685511192998551789516562849422906363784901518167369632157413860597087715433", "price": "0.179", "size": "20", "side": "SELL", "hash": "a7db8f574c6d8dee0814346f829175b987b5ff56", "best_bid": "0.096", "best_ask": "0.113"}], "timestamp": "1769384013984", "event_type": "price_change"}}
{"_local_timestamp": "2026-01-25T23:33:34.139629+00:00", "data": {"market": "0xf829129cd05db888741ad290c786a1d71db5f8bb8493d8bc07e21b826db4d328", "price_changes": [{"asset_id": "105495516848871865829093849779907676478444075202002902600889102615883909197041", "price": "0.852", "size": "0", "side": "BUY", "hash": "4c16267b1d970e266ec67e35c0b84850c7510d5e", "best_bid": "0.887", "best_ask": "0.904"}, {"asset_id": "90685511192998551789516562849422906363784901518167369632157413860597087715433", "price": "0.148", "size": "0", "side": "SELL", "hash": "9cc1a230e2996401e58ea5e0e89a0b18c9a0699f", "best_bid": "0.096", "best_ask": "0.113"}], "timestamp": "1769384014068", "event_type": "price_change"}}
{"_local_timestamp": "2026-01-25T23:33:34.159264+00:00", "data": {"market": "0xf829129cd05db888741ad290c786a1d71db5f8bb8493d8bc07e21b826db4d328", "price_changes": [{"asset_id": "105495516848871865829093849779907676478444075202002902600889102615883909197041", "price": "0.832", "size": "51", "side": "BUY", "hash": "2c8ce6e8b55c4d2393d5c65b5d42a99668e8809e", "best_bid": "0.887", "best_ask": "0.904"}, {"asset_id": "90685511192998551789516562849422906363784901518167369632157413860597087715433", "price": "0.168", "size": "51", "side": "SELL", "hash": "4ff555793fea5b5f4be6ecc1982c2a2ebd6eb459", "best_bid": "0.096", "best_ask": "0.113"}], "timestamp": "1769384014093", "event_type": "price_change"}}
{"_local_timestamp": "2026-01-25T23:33:34.166935+00:00", "data": {"market": "0xf829129cd05db888741ad290c786a1d71db5f8bb8493d8bc07e21b826db4d328", "price_changes": [{"asset_id": "105495516848871865829093849779907676478444075202002902600889102615883909197041", "price": "0.832", "size": "102", "side": "BUY", "hash": "ddf6699ba913aebbaf008cf6445ec38219a370dc", "best_bid": "0.887", "best_ask": "0.904"}, {"asset_id": "90685511192998551789516562849422906363784901518167369632157413860597087715433", "price": "0.168", "size": "102", "side": "SELL", "hash": "86753e04b17de822b77c9d4160b3d554a0ca7122", "best_bid": "0.096", "best_ask": "0.113"}], "timestamp": "1769384014100", "event_type": "price_change"}}
{"_local_timestamp": "2026-01-25T23:33:34.380790+00:00", "data": {"market": "0xf829129cd05db888741ad290c786a1d71db5f8bb8493d8bc07e21b826db4d328", "price_changes": [{"asset_id": "105495516848871865829093849779907676478444075202002902600889102615883909197041", "price": "0.832", "size": "51", "side": "BUY", "hash": "ba97efd5d9bac2505c5358a2af7a809675fb6c0b", "best_bid": "0.887", "best_ask": "0.904"}, {"asset_id": "90685511192998551789516562849422906363784901518167369632157413860597087715433", "price": "0.168", "size": "51", "side": "SELL", "hash": "1b4ee67a2402aa515b736b9a2f7372de5b2b6bf8", "best_bid": "0.096", "best_ask": "0.113"}], "timestamp": "1769384014310", "event_type": "price_change"}}
{"_local_timestamp": "2026-01-25T23:33:35.551162+00:00", "data": {"market": "0xf829129cd05db888741ad290c786a1d71db5f8bb8493d8bc07e21b826db4d328", "price_changes": [{"asset_id": "105495516848871865829093849779907676478444075202002902600889102615883909197041", "price": "0.821", "size": "0", "side": "BUY", "hash": "67f0e8f0df07e11e33a5282119a38fe8f97295a8", "best_bid": "0.887", "best_ask": "0.904"}, {"asset_id": "90685511192998551789516562849422906363784901518167369632157413860597087715433", "price": "0.179", "size": "0", "side": "SELL", "hash": "d7e29391394ce48e19e62932538b5465e05e0464", "best_bid": "0.096", "best_ask": "0.113"}], "timestamp": "1769384015486", "event_type": "price_change"}}
{"_local_timestamp": "2026-01-25T23:33:35.577531+00:00", "data": {"market": "0xf829129cd05db888741ad290c786a1d71db5f8bb8493d8bc07e21b826db4d328", "price_changes": [{"asset_id": "105495516848871865829093849779907676478444075202002902600889102615883909197041", "price": "0.833", "size": "20", "side": "BUY", "hash": "594e6a46833918fd51840592079b7681fbe1f8de", "best_bid": "0.887", "best_ask": "0.904"}, {"asset_id": "90685511192998551789516562849422906363784901518167369632157413860597087715433", "price": "0.167", "size": "20", "side": "SELL", "hash": "261ffac41fdb22174fa37a3c3e0212540a48e58b", "best_bid": "0.096", "best_ask": "0.113"}], "timestamp": "1769384015509", "event_type": "price_change"}}
{"_local_timestamp": "2026-01-25T23:33:35.675379+00:00", "data": {"market": "0xf829129cd05db888741ad290c786a1d71db5f8bb8493d8bc07e21b826db4d328", "price_changes": [{"asset_id": "105495516848871865829093849779907676478444075202002902600889102615883909197041", "price": "0.832", "size": "0", "side": "BUY", "hash": "8d2bec39df5936b4bf25c3ed5062e068e9de9a1b", "best_bid": "0.887", "best_ask": "0.904"}, {"asset_id": "90685511192998551789516562849422906363784901518167369632157413860597087715433", "price": "0.168", "size": "0", "side": "SELL", "hash": "db8e46515ce96bc5ae4451ad2e94aa0ea34e36d1", "best_bid": "0.096", "best_ask": "0.113"}], "timestamp": "1769384015605", "event_type": "price_change"}}
{"_local_timestamp": "2026-01-25T23:33:35.679374+00:00", "data": {"market": "0xf829129cd05db888741ad290c786a1d71db5f8bb8493d8bc07e21b826db4d328", "price_changes": [{"asset_id": "105495516848871865829093849779907676478444075202002902600889102615883909197041", "price": "0.852", "size": "25", "side": "BUY", "hash": "b8420fef17f9ebd79da1351b17d6cffbc7d61099", "best_bid": "0.887", "best_ask": "0.904"}, {"asset_id": "90685511192998551789516562849422906363784901518167369632157413860597087715433", "price": "0.148", "size": "25", "side": "SELL", "hash": "d0174e247dc56d45855c9ede1d9aa47870ecd35c", "best_bid": "0.096", "best_ask": "0.113"}], "timestamp": "1769384015614", "event_type": "price_change"}}
{"_local_timestamp": "2026-01-25T23:33:35.711653+00:00", "data": {"market": "0xf829129cd05db888741ad290c786a1d71db5f8bb8493d8bc07e21b826db4d328", "price_changes": [{"asset_id": "105495516848871865829093849779907676478444075202002902600889102615883909197041", "price": "0.852", "size": "50", "side": "BUY", "hash": "dec76bfeb2e9f6a295a9d4d90c31832ccab2c1dc", "best_bid": "0.887", "best_ask": "0.904"}, {"asset_id": "90685511192998551789516562849422906363784901518167369632157413860597087715433", "price": "0.148", "size": "50", "side": "SELL", "hash": "42e5e95820886fd6960e0fb0647653e605179846", "best_bid": "0.096", "best_ask": "0.113"}], "timestamp": "1769384015628", "event_type": "price_change"}}
{"_local_timestamp": "2026-01-25T23:33:35.807111+00:00", "data": {"market": "0xf829129cd05db888741ad290c786a1d71db5f8bb8493d8bc07e21b826db4d328", "price_changes": [{"asset_id": "105495516848871865829093849779907676478444075202002902600889102615883909197041", "price": "0.852", "size": "25", "side": "BUY", "hash": "f629059b631506d586991b2de926381d20252648", "best_bid": "0.887", "best_ask": "0.904"}, {"asset_id": "90685511192998551789516562849422906363784901518167369632157413860597087715433", "price": "0.148", "size": "25", "side": "SELL", "hash": "31273bb837412b068071b3254bd35ac910ffc25a", "best_bid": "0.096", "best_ask": "0.113"}], "timestamp": "1769384015741", "event_type": "price_change"}}
{"_local_timestamp": "2026-01-25T23:33:37.188256+00:00", "data": {"market": "0xf829129cd05db888741ad290c786a1d71db5f8bb8493d8bc07e21b826db4d328", "price_changes": [{"asset_id": "105495516848871865829093849779907676478444075202002902600889102615883909197041", "price": "0.833", "size": "0", "side": "BUY", "hash": "d3f0a1f8ac1e0919a762fed3a5be7ac96e4473af", "best_bid": "0.887", "best_ask": "0.904"}, {"asset_id": "90685511192998551789516562849422906363784901518167369632157413860597087715433", "price": "0.167", "size": "0", "side": "SELL", "hash": "9609904944f423daa903bd6861dfd570a15f2250", "best_bid": "0.096", "best_ask": "0.113"}], "timestamp": "1769384017122", "event_type": "price_change"}}
{"_local_timestamp": "2026-01-25T23:33:37.214716+00:00", "data": {"market": "0xf829129cd05db888741ad290c786a1d71db5f8bb8493d8bc07e21b826db4d328", "price_changes": [{"asset_id": "105495516848871865829093849779907676478444075202002902600889102615883909197041", "price": "0.821", "size": "20", "side": "BUY", "hash": "febd07f2bfc22b5d5654ace6b109572ca4a4d361", "best_bid": "0.887", "best_ask": "0.904"}, {"asset_id": "90685511192998551789516562849422906363784901518167369632157413860597087715433", "price": "0.179", "size": "20", "side": "SELL", "hash": "347add3cc989692b8b1f9babe1cbb61a9aa57864", "best_bid": "0.096", "best_ask": "0.113"}], "timestamp": "1769384017151", "event_type": "price_change"}}
{"_local_timestamp": "2026-01-25T23:33:37.301909+00:00", "data": {"market": "0xf829129cd05db888741ad290c786a1d71db5f8bb8493d8bc07e21b826db4d328", "price_changes": [{"asset_id": "105495516848871865829093849779907676478444075202002902600889102615883909197041", "price": "0.852", "size": "0", "side": "BUY", "hash": "64b0422ef6363af5c2c78b61c5285cfeb2a31ad0", "best_bid": "0.887", "best_ask": "0.904"}, {"asset_id": "90685511192998551789516562849422906363784901518167369632157413860597087715433", "price": "0.148", "size": "0", "side": "SELL", "hash": "9a34a799a21cb1b59435ccdc2a2d6c1af78b24e1", "best_bid": "0.096", "best_ask": "0.113"}], "timestamp": "1769384017234", "event_type": "price_change"}}
{"_local_timestamp": "2026-01-25T23:33:37.337781+00:00", "data": {"market": "0xf829129cd05db888741ad290c786a1d71db5f8bb8493d8bc07e21b826db4d328", "price_changes": [{"asset_id": "105495516848871865829093849779907676478444075202002902600889102615883909197041", "price": "0.832", "size": "51", "side": "BUY", "hash": "3837955f69f4bb5f9058d70f256b7521e4de900c", "best_bid": "0.887", "best_ask": "0.904"}, {"asset_id": "90685511192998551789516562849422906363784901518167369632157413860597087715433", "price": "0.168", "size": "51", "side": "SELL", "hash": "ca0cc4a799100cf2789b284f95a942107dfee562", "best_bid": "0.096", "best_ask": "0.113"}], "timestamp": "1769384017264", "event_type": "price_change"}}
{"_local_timestamp": "2026-01-25T23:33:37.376678+00:00", "data": {"market": "0xf829129cd05db888741ad290c786a1d71db5f8bb8493d8bc07e21b826db4d328", "price_changes": [{"asset_id": "105495516848871865829093849779907676478444075202002902600889102615883909197041", "price": "0.832", "size": "102", "side": "BUY", "hash": "d65d762113ef06c602f0c616232cb05310aac4bf", "best_bid": "0.887", "best_ask": "0.904"}, {"asset_id": "90685511192998551789516562849422906363784901518167369632157413860597087715433", "price": "0.168", "size": "102", "side": "SELL", "hash": "0256d61d29951d3e00e68d40bd9497cc50390a9f", "best_bid": "0.096", "best_ask": "0.113"}], "timestamp": "1769384017289", "event_type": "price_change"}}
{"_local_timestamp": "2026-01-25T23:33:37.460479+00:00", "data": {"market": "0xf829129cd05db888741ad290c786a1d71db5f8bb8493d8bc07e21b826db4d328", "price_changes": [{"asset_id": "105495516848871865829093849779907676478444075202002902600889102615883909197041", "price": "0.832", "size": "51", "side": "BUY", "hash": "b529191791502323b2df798d2b8c82b949ba310e", "best_bid": "0.887", "best_ask": "0.904"}, {"asset_id": "90685511192998551789516562849422906363784901518167369632157413860597087715433", "price": "0.168", "size": "51", "side": "SELL", "hash": "ecc75241af8654232e0d0d80173e9e1da8ab78cd", "best_bid": "0.096", "best_ask": "0.113"}], "timestamp": "1769384017370", "event_type": "price_change"}}
{"_local_timestamp": "2026-01-25T23:33:38.334990+00:00", "data": {"market": "0xf829129cd05db888741ad290c786a1d71db5f8bb8493d8bc07e21b826db4d328", "price_changes": [{"asset_id": "105495516848871865829093849779907676478444075202002902600889102615883909197041", "price": "0.821", "size": "0", "side": "BUY", "hash": "a5556c688057002671bfbe30de937f6bf3ed3095", "best_bid": "0.887", "best_ask": "0.904"}, {"asset_id": "90685511192998551789516562849422906363784901518167369632157413860597087715433", "price": "0.179", "size": "0", "side": "SELL", "hash": "415bacac392b37f7a87be097fc435c94699f286a", "best_bid": "0.096", "best_ask": "0.113"}], "timestamp": "1769384018268", "event_type": "price_change"}}
{"_local_timestamp": "2026-01-25T23:33:38.357809+00:00", "data": {"market": "0xf829129cd05db888741ad290c786a1d71db5f8bb8493d8bc07e21b826db4d328", "price_changes": [{"asset_id": "105495516848871865829093849779907676478444075202002902600889102615883909197041", "price": "0.833", "size": "20", "side": "BUY", "hash": "80b81d5e24a7a58e1206d5fe4a4ed1a748ead870", "best_bid": "0.887", "best_ask": "0.904"}, {"asset_id": "90685511192998551789516562849422906363784901518167369632157413860597087715433", "price": "0.167", "size": "20", "side": "SELL", "hash": "8b8f72591df35bac0334ad3cea274aef1c70f735", "best_bid": "0.096", "best_ask": "0.113"}], "timestamp": "1769384018292", "event_type": "price_change"}}
{"_local_timestamp": "2026-01-25T23:33:38.437443+00:00", "data": {"market": "0xf829129cd05db888741ad290c786a1d71db5f8bb8493d8bc07e21b826db4d328", "price_changes": [{"asset_id": "105495516848871865829093849779907676478444075202002902600889102615883909197041", "price": "0.832", "size": "0", "side": "BUY", "hash": "9cfb91f7ce7cabb6e7f0fb348bfc1a4a0f70092b", "best_bid": "0.887", "best_ask": "0.904"}, {"asset_id": "90685511192998551789516562849422906363784901518167369632157413860597087715433", "price": "0.168", "size": "0", "side": "SELL", "hash": "15dc1987a2be32d04e56dacc3c735560fa2e8947", "best_bid": "0.096", "best_ask": "0.113"}], "timestamp": "1769384018371", "event_type": "price_change"}}
{"_local_timestamp": "2026-01-25T23:33:38.483099+00:00", "data": {"market": "0xf829129cd05db888741ad290c786a1d71db5f8bb8493d8bc07e21b826db4d328", "price_changes": [{"asset_id": "105495516848871865829093849779907676478444075202002902600889102615883909197041", "price": "0.852", "size": "25", "side": "BUY", "hash": "148e3dfe8925eb1f1b3634c304670218d9d343b5", "best_bid": "0.887", "best_ask": "0.904"}, {"asset_id": "90685511192998551789516562849422906363784901518167369632157413860597087715433", "price": "0.148", "size": "25", "side": "SELL", "hash": "369b03b235324a76b1a7f7510cdac7b0cd7314b5", "best_bid": "0.096", "best_ask": "0.113"}], "timestamp": "1769384018410", "event_type": "price_change"}}
{"_local_timestamp": "2026-01-25T23:33:38.494880+00:00", "data": {"market": "0xf829129cd05db888741ad290c786a1d71db5f8bb8493d8bc07e21b826db4d328", "price_changes": [{"asset_id": "105495516848871865829093849779907676478444075202002902600889102615883909197041", "price": "0.852", "size": "50", "side": "BUY", "hash": "427948aceca8be321793ab74f4532b276e724869", "best_bid": "0.887", "best_ask": "0.904"}, {"asset_id": "90685511192998551789516562849422906363784901518167369632157413860597087715433", "price": "0.148", "size": "50", "side": "SELL", "hash": "58f03202be5105cd1a73027982627d610cdba080", "best_bid": "0.096", "best_ask": "0.113"}], "timestamp": "1769384018419", "event_type": "price_change"}}
{"_local_timestamp": "2026-01-25T23:33:38.598006+00:00", "data": {"market": "0xf829129cd05db888741ad290c786a1d71db5f8bb8493d8bc07e21b826db4d328", "price_changes": [{"asset_id": "105495516848871865829093849779907676478444075202002902600889102615883909197041", "price": "0.852", "size": "25", "side": "BUY", "hash": "2097bab4ad77421c755ed736b60fd30a2efeed83", "best_bid": "0.887", "best_ask": "0.904"}, {"asset_id": "90685511192998551789516562849422906363784901518167369632157413860597087715433", "price": "0.148", "size": "25", "side": "SELL", "hash": "6d852652ac858573b86ad7790bb66ec4a8dd70eb", "best_bid": "0.096", "best_ask": "0.113"}], "timestamp": "1769384018527", "event_type": "price_change"}}
{"_local_timestamp": "2026-01-25T23:33:39.792503+00:00", "data": {"market": "0xf829129cd05db888741ad290c786a1d71db5f8bb8493d8bc07e21b826db4d328", "price_changes": [{"asset_id": "105495516848871865829093849779907676478444075202002902600889102615883909197041", "price": "0.833", "size": "0", "side": "BUY", "hash": "915e2bf6722bc23aeb2fcab9af492399bd724899", "best_bid": "0.887", "best_ask": "0.904"}, {"asset_id": "90685511192998551789516562849422906363784901518167369632157413860597087715433", "price": "0.167", "size": "0", "side": "SELL", "hash": "90da7be3be63d91b2a00a724d6cc29a12f4e9760", "best_bid": "0.096", "best_ask": "0.113"}], "timestamp": "1769384019726", "event_type": "price_change"}}
{"_local_timestamp": "2026-01-25T23:33:39.817970+00:00", "data": {"market": "0xf829129cd05db888741ad290c786a1d71db5f8bb8493d8bc07e21b826db4d328", "price_changes": [{"asset_id": "105495516848871865829093849779907676478444075202002902600889102615883909197041", "price": "0.821", "size": "20", "side": "BUY", "hash": "27051dd9486ff49571b677f91bef1e7637cced46", "best_bid": "0.887", "best_ask": "0.904"}, {"asset_id": "90685511192998551789516562849422906363784901518167369632157413860597087715433", "price": "0.179", "size": "20", "side": "SELL", "hash": "90290c0468527027a06c4e358a4f769457706882", "best_bid": "0.096", "best_ask": "0.113"}], "timestamp": "1769384019749", "event_type": "price_change"}}
{"_local_timestamp": "2026-01-25T23:33:39.910543+00:00", "data": {"market": "0xf829129cd05db888741ad290c786a1d71db5f8bb8493d8bc07e21b826db4d328", "price_changes": [{"asset_id": "105495516848871865829093849779907676478444075202002902600889102615883909197041", "price": "0.852", "size": "0", "side": "BUY", "hash": "0bc7b44a799c4580207f86fdc22aa93fe1bc5af3", "best_bid": "0.887", "best_ask": "0.904"}, {"asset_id": "90685511192998551789516562849422906363784901518167369632157413860597087715433", "price": "0.148", "size": "0", "side": "SELL", "hash": "c8024d953c297e590d347e70ced5d576edcdfbc3", "best_bid": "0.096", "best_ask": "0.113"}], "timestamp": "1769384019836", "event_type": "price_change"}}
{"_local_timestamp": "2026-01-25T23:33:39.930916+00:00", "data": {"market": "0xf829129cd05db888741ad290c786a1d71db5f8bb8493d8bc07e21b826db4d328", "price_changes": [{"asset_id": "105495516848871865829093849779907676478444075202002902600889102615883909197041", "price": "0.832", "size": "51", "side": "BUY", "hash": "f186db0b24ce81cfbff57f6e00a6a4193b9d79d2", "best_bid": "0.887", "best_ask": "0.904"}, {"asset_id": "90685511192998551789516562849422906363784901518167369632157413860597087715433", "price": "0.168", "size": "51", "side": "SELL", "hash": "963e0a58938cb0cc52797a0aba21c99ce4b4b610", "best_bid": "0.096", "best_ask": "0.113"}], "timestamp": "1769384019862", "event_type": "price_change"}}
{"_local_timestamp": "2026-01-25T23:33:39.969332+00:00", "data": {"market": "0xf829129cd05db888741ad290c786a1d71db5f8bb8493d8bc07e21b826db4d328", "price_changes": [{"asset_id": "105495516848871865829093849779907676478444075202002902600889102615883909197041", "price": "0.832", "size": "102", "side": "BUY", "hash": "b929f6cb64e697fbb6feac1c6e1def1ced6ed065", "best_bid": "0.887", "best_ask": "0.904"}, {"asset_id": "90685511192998551789516562849422906363784901518167369632157413860597087715433", "price": "0.168", "size": "102", "side": "SELL", "hash": "18a571ca3f65e8a79afcaec80a22076fc64c21ea", "best_bid": "0.096", "best_ask": "0.113"}], "timestamp": "1769384019901", "event_type": "price_change"}}
{"_local_timestamp": "2026-01-25T23:33:40.110584+00:00", "data": {"market": "0xf829129cd05db888741ad290c786a1d71db5f8bb8493d8bc07e21b826db4d328", "price_changes": [{"asset_id": "105495516848871865829093849779907676478444075202002902600889102615883909197041", "price": "0.832", "size": "51", "side": "BUY", "hash": "b955f0d9474922293b35f06ee123b8aa31c3c633", "best_bid": "0.887", "best_ask": "0.904"}, {"asset_id": "90685511192998551789516562849422906363784901518167369632157413860597087715433", "price": "0.168", "size": "51", "side": "SELL", "hash": "9a190aaeb87598a68695f1a76a3b33cc32bd5da4", "best_bid": "0.096", "best_ask": "0.113"}], "timestamp": "1769384020020", "event_type": "price_change"}}
{"_local_timestamp": "2026-01-25T23:33:40.331343+00:00", "data": {"market": "0x897a2f88e1b65776ac5af0440833eea638395f0af0df4bed47e83f64c9b9a1e3", "price_changes": [{"asset_id": "11824574045576628150612194967948587889530003270004521491303323671815597832573", "price": "0.13", "size": "1430", "side": "BUY", "hash": "b87eec190a6b3ff81e3502b7c7e95a66a5b50914", "best_bid": "0.54", "best_ask": "0.56"}, {"asset_id": "67301121905355380418923087513498375592166001657797903147689423172757844806122", "price": "0.87", "size": "1430", "side": "SELL", "hash": "aed7f2762137fd659ab82335cc8ff561d633ca71", "best_bid": "0.44", "best_ask": "0.46"}], "timestamp": "1769384020103", "event_type": "price_change"}}
{"_local_timestamp": "2026-01-25T23:33:40.347141+00:00", "data": {"market": "0x897a2f88e1b65776ac5af0440833eea638395f0af0df4bed47e83f64c9b9a1e3", "price_changes": [{"asset_id": "11824574045576628150612194967948587889530003270004521491303323671815597832573", "price": "0.16", "size": "150", "side": "BUY", "hash": "b87eec190a6b3ff81e3502b7c7e95a66a5b50914", "best_bid": "0.54", "best_ask": "0.56"}, {"asset_id": "67301121905355380418923087513498375592166001657797903147689423172757844806122", "price": "0.84", "size": "150", "side": "SELL", "hash": "aed7f2762137fd659ab82335cc8ff561d633ca71", "best_bid": "0.44", "best_ask": "0.46"}], "timestamp": "1769384020103", "event_type": "price_change"}}
{"_local_timestamp": "2026-01-25T23:33:40.650094+00:00", "data": {"market": "0xf829129cd05db888741ad290c786a1d71db5f8bb8493d8bc07e21b826db4d328", "price_changes": [{"asset_id": "105495516848871865829093849779907676478444075202002902600889102615883909197041", "price": "0.821", "size": "0", "side": "BUY", "hash": "05b80b0e867739181e2f0defdbe4ed7d667366c9", "best_bid": "0.887", "best_ask": "0.904"}, {"asset_id": "90685511192998551789516562849422906363784901518167369632157413860597087715433", "price": "0.179", "size": "0", "side": "SELL", "hash": "5e389bacdf0ae1c4f7ae1d8e4631fc819057573f", "best_bid": "0.096", "best_ask": "0.113"}], "timestamp": "1769384020565", "event_type": "price_change"}}
{"_local_timestamp": "2026-01-25T23:33:40.710318+00:00", "data": {"market": "0x897a2f88e1b65776ac5af0440833eea638395f0af0df4bed47e83f64c9b9a1e3", "price_changes": [{"asset_id": "11824574045576628150612194967948587889530003270004521491303323671815597832573", "price": "0.17", "size": "252.94", "side": "BUY", "hash": "8b109ea8152959352017e2002a27812554e6a1fa", "best_bid": "0.54", "best_ask": "0.56"}, {"asset_id": "67301121905355380418923087513498375592166001657797903147689423172757844806122", "price": "0.83", "size": "252.94", "side": "SELL", "hash": "207e8cf617c8e8ed16b53f0e16575d71bbf25ec0", "best_bid": "0.44", "best_ask": "0.46"}], "timestamp": "1769384020540", "event_type": "price_change"}}
{"_local_timestamp": "2026-01-25T23:33:40.762901+00:00", "data": {"market": "0xf829129cd05db888741ad290c786a1d71db5f8bb8493d8bc07e21b826db4d328", "price_changes": [{"asset_id": "105495516848871865829093849779907676478444075202002902600889102615883909197041", "price": "0.833", "size": "20", "side": "BUY", "hash": "f52f21cbb54031973f4fe86425c0054a61e2321b", "best_bid": "0.887", "best_ask": "0.904"}, {"asset_id": "90685511192998551789516562849422906363784901518167369632157413860597087715433", "price": "0.167", "size": "20", "side": "SELL", "hash": "a70a74525596d61564763eaa9fb8d1a43ba1ba96", "best_bid": "0.096", "best_ask": "0.113"}], "timestamp": "1769384020589", "event_type": "price_change"}}
{"_local_timestamp": "2026-01-25T23:33:40.835355+00:00", "data": {"market": "0x897a2f88e1b65776ac5af0440833eea638395f0af0df4bed47e83f64c9b9a1e3", "price_changes": [{"asset_id": "11824574045576628150612194967948587889530003270004521491303323671815597832573", "price": "0.15", "size": "2923", "side": "BUY", "hash": "836aa617c41b13be072d97bcbd6c95aad6ce511e", "best_bid": "0.54", "best_ask": "0.56"}, {"asset_id": "67301121905355380418923087513498375592166001657797903147689423172757844806122", "price": "0.85", "size": "2923", "side": "SELL", "hash": "611e69ba915654f5589ed3f402e00d1f2a3366e2", "best_bid": "0.44", "best_ask": "0.46"}], "timestamp": "1769384020577", "event_type": "price_change"}}
{"_local_timestamp": "2026-01-25T23:33:40.892221+00:00", "data": {"market": "0xf829129cd05db888741ad290c786a1d71db5f8bb8493d8bc07e21b826db4d328", "price_changes": [{"asset_id": "105495516848871865829093849779907676478444075202002902600889102615883909197041", "price": "0.832", "size": "0", "side": "BUY", "hash": "0a1f3bd977ce2c3fbb69793dacd8fecf5500e029", "best_bid": "0.887", "best_ask": "0.904"}, {"asset_id": "90685511192998551789516562849422906363784901518167369632157413860597087715433", "price": "0.168", "size": "0", "side": "SELL", "hash": "2062488bb67fed3dd66c77757d3beb2643921d86", "best_bid": "0.096", "best_ask": "0.113"}], "timestamp": "1769384020689", "event_type": "price_change"}}
{"_local_timestamp": "2026-01-25T23:33:40.919942+00:00", "data": {"market": "0xf829129cd05db888741ad290c786a1d71db5f8bb8493d8bc07e21b826db4d328", "price_changes": [{"asset_id": "105495516848871865829093849779907676478444075202002902600889102615883909197041", "price": "0.852", "size": "25", "side": "BUY", "hash": "1fbb7ebdabc42c56f7c997a66c5febeab6db3834", "best_bid": "0.887", "best_ask": "0.904"}, {"asset_id": "90685511192998551789516562849422906363784901518167369632157413860597087715433", "price": "0.148", "size": "25", "side": "SELL", "hash": "db35924d7bbdee7d836b814c72fb230c52f68501", "best_bid": "0.096", "best_ask": "0.113"}], "timestamp": "1769384020797", "event_type": "price_change"}}
{"_local_timestamp": "2026-01-25T23:33:40.994875+00:00", "data": {"market": "0xf829129cd05db888741ad290c786a1d71db5f8bb8493d8bc07e21b826db4d328", "price_changes": [{"asset_id": "105495516848871865829093849779907676478444075202002902600889102615883909197041", "price": "0.852", "size": "50", "side": "BUY", "hash": "8e81f58f0f9fa08e86ed1bc8640eea2f4b406f1c", "best_bid": "0.887", "best_ask": "0.904"}, {"asset_id": "90685511192998551789516562849422906363784901518167369632157413860597087715433", "price": "0.148", "size": "50", "side": "SELL", "hash": "fc12f588dfef5b34e28b58b331310b7a0d1fa070", "best_bid": "0.096", "best_ask": "0.113"}], "timestamp": "1769384020928", "event_type": "price_change"}}
{"_local_timestamp": "2026-01-25T23:33:41.118735+00:00", "data": {"market": "0xf829129cd05db888741ad290c786a1d71db5f8bb8493d8bc07e21b826db4d328", "price_changes": [{"asset_id": "105495516848871865829093849779907676478444075202002902600889102615883909197041", "price": "0.852", "size": "25", "side": "BUY", "hash": "3f17891c0c58b9545adc9a6aae3688ef01c3e7f7", "best_bid": "0.887", "best_ask": "0.904"}, {"asset_id": "90685511192998551789516562849422906363784901518167369632157413860597087715433", "price": "0.148", "size": "25", "side": "SELL", "hash": "f855e10d99cfd6a46c9d555932961ca404179867", "best_bid": "0.096", "best_ask": "0.113"}], "timestamp": "1769384021039", "event_type": "price_change"}}
{"_local_timestamp": "2026-01-25T23:33:41.513931+00:00", "data": {"market": "0xf829129cd05db888741ad290c786a1d71db5f8bb8493d8bc07e21b826db4d328", "price_changes": [{"asset_id": "105495516848871865829093849779907676478444075202002902600889102615883909197041", "price": "0.833", "size": "0", "side": "BUY", "hash": "0fb633fc63e9e6f1cf939d8aa1a68c97b7baf400", "best_bid": "0.887", "best_ask": "0.904"}, {"asset_id": "90685511192998551789516562849422906363784901518167369632157413860597087715433", "price": "0.167", "size": "0", "side": "SELL", "hash": "0c1e31584bf78ee633a3c20492c632d086379a25", "best_bid": "0.096", "best_ask": "0.113"}], "timestamp": "1769384021445", "event_type": "price_change"}}
{"_local_timestamp": "2026-01-25T23:33:41.542296+00:00", "data": {"market": "0xf829129cd05db888741ad290c786a1d71db5f8bb8493d8bc07e21b826db4d328", "price_changes": [{"asset_id": "105495516848871865829093849779907676478444075202002902600889102615883909197041", "price": "0.821", "size": "20", "side": "BUY", "hash": "e8ebc68518d195278994a551017af2ac10638038", "best_bid": "0.887", "best_ask": "0.904"}, {"asset_id": "90685511192998551789516562849422906363784901518167369632157413860597087715433", "price": "0.179", "size": "20", "side": "SELL", "hash": "fef72c36331d3810a6056f69970a75d2f583be2b", "best_bid": "0.096", "best_ask": "0.113"}], "timestamp": "1769384021469", "event_type": "price_change"}}
{"_local_timestamp": "2026-01-25T23:33:41.637703+00:00", "data": {"market": "0xf829129cd05db888741ad290c786a1d71db5f8bb8493d8bc07e21b826db4d328", "price_changes": [{"asset_id": "105495516848871865829093849779907676478444075202002902600889102615883909197041", "price": "0.852", "size": "0", "side": "BUY", "hash": "58dc41b5869080f110edbdd2275bab9507c46caf", "best_bid": "0.887", "best_ask": "0.904"}, {"asset_id": "90685511192998551789516562849422906363784901518167369632157413860597087715433", "price": "0.148", "size": "0", "side": "SELL", "hash": "88bcb0b0880bddbab16dfd36027a5fe03aad33b5", "best_bid": "0.096", "best_ask": "0.113"}], "timestamp": "1769384021566", "event_type": "price_change"}}
{"_local_timestamp": "2026-01-25T23:33:41.661201+00:00", "data": {"market": "0xf829129cd05db888741ad290c786a1d71db5f8bb8493d8bc07e21b826db4d328", "price_changes": [{"asset_id": "105495516848871865829093849779907676478444075202002902600889102615883909197041", "price": "0.832", "size": "51", "side": "BUY", "hash": "912b4451c9537a527deb574c1b56c9df9da35f98", "best_bid": "0.887", "best_ask": "0.904"}, {"asset_id": "90685511192998551789516562849422906363784901518167369632157413860597087715433", "price": "0.168", "size": "51", "side": "SELL", "hash": "ba33c91b09ea4512f4202c317969bf486330fe0f", "best_bid": "0.096", "best_ask": "0.113"}], "timestamp": "1769384021586", "event_type": "price_change"}}
{"_local_timestamp": "2026-01-25T23:33:43.582589+00:00", "data": {"market": "0xf829129cd05db888741ad290c786a1d71db5f8bb8493d8bc07e21b826db4d328", "price_changes": [{"asset_id": "105495516848871865829093849779907676478444075202002902600889102615883909197041", "price": "0.821", "size": "0", "side": "BUY", "hash": "11b69caf38609f2d130844a4b3b9fc6ea141dad7", "best_bid": "0.887", "best_ask": "0.904"}, {"asset_id": "90685511192998551789516562849422906363784901518167369632157413860597087715433", "price": "0.179", "size": "0", "side": "SELL", "hash": "6151cdfca0d24728ea84508a1a4a1a9196c35838", "best_bid": "0.096", "best_ask": "0.113"}], "timestamp": "1769384023517", "event_type": "price_change"}}
{"_local_timestamp": "2026-01-25T23:33:43.609503+00:00", "data": {"market": "0xf829129cd05db888741ad290c786a1d71db5f8bb8493d8bc07e21b826db4d328", "price_changes": [{"asset_id": "105495516848871865829093849779907676478444075202002902600889102615883909197041", "price": "0.833", "size": "20", "side": "BUY", "hash": "a58125fd4a941f1795a2e9c4123ae6d30331a3e5", "best_bid": "0.887", "best_ask": "0.904"}, {"asset_id": "90685511192998551789516562849422906363784901518167369632157413860597087715433", "price": "0.167", "size": "20", "side": "SELL", "hash": "c1e27ea6383efad580e891cd04cd02ea3df4fe7b", "best_bid": "0.096", "best_ask": "0.113"}], "timestamp": "1769384023543", "event_type": "price_change"}}
{"_local_timestamp": "2026-01-25T23:33:43.685578+00:00", "data": {"market": "0xf829129cd05db888741ad290c786a1d71db5f8bb8493d8bc07e21b826db4d328", "price_changes": [{"asset_id": "105495516848871865829093849779907676478444075202002902600889102615883909197041", "price": "0.832", "size": "102", "side": "BUY", "hash": "8da2321e52ea2d929f7ca80476b8a82a16b5cce0", "best_bid": "0.887", "best_ask": "0.904"}, {"asset_id": "90685511192998551789516562849422906363784901518167369632157413860597087715433", "price": "0.168", "size": "102", "side": "SELL", "hash": "da87f8c8565e2cea8dfa4130425d507b94d7f0fa", "best_bid": "0.096", "best_ask": "0.113"}], "timestamp": "1769384023621", "event_type": "price_change"}}
{"_local_timestamp": "2026-01-25T23:33:43.729870+00:00", "data": {"market": "0xf829129cd05db888741ad290c786a1d71db5f8bb8493d8bc07e21b826db4d328", "price_changes": [{"asset_id": "105495516848871865829093849779907676478444075202002902600889102615883909197041", "price": "0.852", "size": "25", "side": "BUY", "hash": "ad274df1a98f020d24b3406e5bc1936d157a3e5d", "best_bid": "0.887", "best_ask": "0.904"}, {"asset_id": "90685511192998551789516562849422906363784901518167369632157413860597087715433", "price": "0.148", "size": "25", "side": "SELL", "hash": "495d36dff1c07095bd5141f645ba0b1517225894", "best_bid": "0.096", "best_ask": "0.113"}], "timestamp": "1769384023649", "event_type": "price_change"}}
{"_local_timestamp": "2026-01-25T23:33:43.802432+00:00", "data": {"market": "0xf829129cd05db888741ad290c786a1d71db5f8bb8493d8bc07e21b826db4d328", "price_changes": [{"asset_id": "105495516848871865829093849779907676478444075202002902600889102615883909197041", "price": "0.832", "size": "51", "side": "BUY", "hash": "26dbf32d309527be12644dcbb1d46166221beeb1", "best_bid": "0.887", "best_ask": "0.904"}, {"asset_id": "90685511192998551789516562849422906363784901518167369632157413860597087715433", "price": "0.168", "size": "51", "side": "SELL", "hash": "a95885c61b1bc54735153bd65938cfdd91f0a08c", "best_bid": "0.096", "best_ask": "0.113"}], "timestamp": "1769384023713", "event_type": "price_change"}}
{"_local_timestamp": "2026-01-25T23:33:43.829529+00:00", "data": {"market": "0xf829129cd05db888741ad290c786a1d71db5f8bb8493d8bc07e21b826db4d328", "price_changes": [{"asset_id": "105495516848871865829093849779907676478444075202002902600889102615883909197041", "price": "0.832", "size": "0", "side": "BUY", "hash": "200637f53c569b0c90ccbbd71537497157dc40ac", "best_bid": "0.887", "best_ask": "0.904"}, {"asset_id": "90685511192998551789516562849422906363784901518167369632157413860597087715433", "price": "0.168", "size": "0", "side": "SELL", "hash": "b8130b318e09c25664bcba617e6d0823b608c21c", "best_bid": "0.096", "best_ask": "0.113"}], "timestamp": "1769384023733", "event_type": "price_change"}}
{"_local_timestamp": "2026-01-25T23:33:44.920673+00:00", "data": {"market": "0xf829129cd05db888741ad290c786a1d71db5f8bb8493d8bc07e21b826db4d328", "price_changes": [{"asset_id": "105495516848871865829093849779907676478444075202002902600889102615883909197041", "price": "0.833", "size": "0", "side": "BUY", "hash": "edd1e446575b7fc729efff137ed238decadf4fd1", "best_bid": "0.887", "best_ask": "0.904"}, {"asset_id": "90685511192998551789516562849422906363784901518167369632157413860597087715433", "price": "0.167", "size": "0", "side": "SELL", "hash": "a9a4287eaae479c11bcebf34c4059cb04725c15d", "best_bid": "0.096", "best_ask": "0.113"}], "timestamp": "1769384024854", "event_type": "price_change"}}
{"_local_timestamp": "2026-01-25T23:33:44.953800+00:00", "data": {"market": "0xf829129cd05db888741ad290c786a1d71db5f8bb8493d8bc07e21b826db4d328", "price_changes": [{"asset_id": "105495516848871865829093849779907676478444075202002902600889102615883909197041", "price": "0.821", "size": "20", "side": "BUY", "hash": "08e8f24a7b53acc712628c0520c6015ec0e98cc3", "best_bid": "0.887", "best_ask": "0.904"}, {"asset_id": "90685511192998551789516562849422906363784901518167369632157413860597087715433", "price": "0.179", "size": "20", "side": "SELL", "hash": "f6288ec11b4bf1bd5a1191a52f6eb2639e93af75", "best_bid": "0.096", "best_ask": "0.113"}], "timestamp": "1769384024887", "event_type": "price_change"}}
{"_local_timestamp": "2026-01-25T23:33:45.026485+00:00", "data": {"market": "0xf829129cd05db888741ad290c786a1d71db5f8bb8493d8bc07e21b826db4d328", "price_changes": [{"asset_id": "105495516848871865829093849779907676478444075202002902600889102615883909197041", "price": "0.852", "size": "50", "side": "BUY", "hash": "93947445abf9707a32ab3497f96ccba8bb6c3df0", "best_bid": "0.887", "best_ask": "0.904"}, {"asset_id": "90685511192998551789516562849422906363784901518167369632157413860597087715433", "price": "0.148", "size": "50", "side": "SELL", "hash": "549ba1d937c717fb993a0dcfe2fef292087d3f7d", "best_bid": "0.096", "best_ask": "0.113"}], "timestamp": "1769384024961", "event_type": "price_change"}}
{"_local_timestamp": "2026-01-25T23:33:45.027141+00:00", "data": {"market": "0xf829129cd05db888741ad290c786a1d71db5f8bb8493d8bc07e21b826db4d328", "price_changes": [{"asset_id": "105495516848871865829093849779907676478444075202002902600889102615883909197041", "price": "0.852", "size": "25", "side": "BUY", "hash": "888b7079f67b41f73fff53a964d40a326c4d7439", "best_bid": "0.887", "best_ask": "0.904"}, {"asset_id": "90685511192998551789516562849422906363784901518167369632157413860597087715433", "price": "0.148", "size": "25", "side": "SELL", "hash": "7cf964389a50547ad9d850c5809afefdd60a3465", "best_bid": "0.096", "best_ask": "0.113"}], "timestamp": "1769384024964", "event_type": "price_change"}}
{"_local_timestamp": "2026-01-25T23:33:45.058587+00:00", "data": {"market": "0xf829129cd05db888741ad290c786a1d71db5f8bb8493d8bc07e21b826db4d328", "price_changes": [{"asset_id": "105495516848871865829093849779907676478444075202002902600889102615883909197041", "price": "0.832", "size": "51", "side": "BUY", "hash": "406deccece637cdf4b4aaf1185032949c3999f01", "best_bid": "0.887", "best_ask": "0.904"}, {"asset_id": "90685511192998551789516562849422906363784901518167369632157413860597087715433", "price": "0.168", "size": "51", "side": "SELL", "hash": "37ba2ea7a13590351ae1f1c6ec025699f94e8532", "best_bid": "0.096", "best_ask": "0.113"}], "timestamp": "1769384024994", "event_type": "price_change"}}
{"_local_timestamp": "2026-01-25T23:33:45.131008+00:00", "data": {"market": "0xf829129cd05db888741ad290c786a1d71db5f8bb8493d8bc07e21b826db4d328", "price_changes": [{"asset_id": "105495516848871865829093849779907676478444075202002902600889102615883909197041", "price": "0.852", "size": "0", "side": "BUY", "hash": "0ffa0fc0659159b81b4370b4b659d75696574850", "best_bid": "0.887", "best_ask": "0.904"}, {"asset_id": "90685511192998551789516562849422906363784901518167369632157413860597087715433", "price": "0.148", "size": "0", "side": "SELL", "hash": "396fdaf8a475188534428dddd4f93c2fa8b49609", "best_bid": "0.096", "best_ask": "0.113"}], "timestamp": "1769384025068", "event_type": "price_change"}}
{"_local_timestamp": "2026-01-25T23:33:45.592291+00:00", "data": {"market": "0xf829129cd05db888741ad290c786a1d71db5f8bb8493d8bc07e21b826db4d328", "price_changes": [{"asset_id": "105495516848871865829093849779907676478444075202002902600889102615883909197041", "price": "0.821", "size": "0", "side": "BUY", "hash": "96a76236d48d894a9b45a0a9e6dc7b652d793cfc", "best_bid": "0.887", "best_ask": "0.904"}, {"asset_id": "90685511192998551789516562849422906363784901518167369632157413860597087715433", "price": "0.179", "size": "0", "side": "SELL", "hash": "06ceec2737c5d4226c28caa0c077214f7a5fc220", "best_bid": "0.096", "best_ask": "0.113"}], "timestamp": "1769384025520", "event_type": "price_change"}}
{"_local_timestamp": "2026-01-25T23:33:45.614473+00:00", "data": {"market": "0xf829129cd05db888741ad290c786a1d71db5f8bb8493d8bc07e21b826db4d328", "price_changes": [{"asset_id": "105495516848871865829093849779907676478444075202002902600889102615883909197041", "price": "0.833", "size": "20", "side": "BUY", "hash": "f28d1facec35dcafcc39cfe3bd5416018a1fe30f", "best_bid": "0.887", "best_ask": "0.904"}, {"asset_id": "90685511192998551789516562849422906363784901518167369632157413860597087715433", "price": "0.167", "size": "20", "side": "SELL", "hash": "4c0964a56ccb1b477db49c4a9ef07bfac3b8f541", "best_bid": "0.096", "best_ask": "0.113"}], "timestamp": "1769384025543", "event_type": "price_change"}}
{"_local_timestamp": "2026-01-25T23:33:45.690507+00:00", "data": {"market": "0xf829129cd05db888741ad290c786a1d71db5f8bb8493d8bc07e21b826db4d328", "price_changes": [{"asset_id": "105495516848871865829093849779907676478444075202002902600889102615883909197041", "price": "0.832", "size": "0", "side": "BUY", "hash": "80921429a3464db9b4563a148304b7046fb62108", "best_bid": "0.887", "best_ask": "0.904"}, {"asset_id": "90685511192998551789516562849422906363784901518167369632157413860597087715433", "price": "0.168", "size": "0", "side": "SELL", "hash": "8036d2c2af33530245a1b9c7428888a53f9148cd", "best_bid": "0.096", "best_ask": "0.113"}], "timestamp": "1769384025625", "event_type": "price_change"}}
{"_local_timestamp": "2026-01-25T23:33:45.720080+00:00", "data": {"market": "0xf829129cd05db888741ad290c786a1d71db5f8bb8493d8bc07e21b826db4d328", "price_changes": [{"asset_id": "105495516848871865829093849779907676478444075202002902600889102615883909197041", "price": "0.852", "size": "25", "side": "BUY", "hash": "1ae031bf03907738d8ae48cfc5a8fbda5c50a930", "best_bid": "0.887", "best_ask": "0.904"}, {"asset_id": "90685511192998551789516562849422906363784901518167369632157413860597087715433", "price": "0.148", "size": "25", "side": "SELL", "hash": "83d1626d0252a95598cbe2b8e693c6c83b8b9a19", "best_bid": "0.096", "best_ask": "0.113"}], "timestamp": "1769384025655", "event_type": "price_change"}}
{"_local_timestamp": "2026-01-25T23:33:46.416764+00:00", "data": {"market": "0xf829129cd05db888741ad290c786a1d71db5f8bb8493d8bc07e21b826db4d328", "price_changes": [{"asset_id": "105495516848871865829093849779907676478444075202002902600889102615883909197041", "price": "0.833", "size": "0", "side": "BUY", "hash": "94a9edbe33cd86d16392c2066bd334ec777dcd5a", "best_bid": "0.887", "best_ask": "0.904"}, {"asset_id": "90685511192998551789516562849422906363784901518167369632157413860597087715433", "price": "0.167", "size": "0", "side": "SELL", "hash": "6cd4809f712e93675f1edacb0f11e7c043fe8620", "best_bid": "0.096", "best_ask": "0.113"}], "timestamp": "1769384026350", "event_type": "price_change"}}
{"_local_timestamp": "2026-01-25T23:33:46.443018+00:00", "data": {"market": "0xf829129cd05db888741ad290c786a1d71db5f8bb8493d8bc07e21b826db4d328", "price_changes": [{"asset_id": "105495516848871865829093849779907676478444075202002902600889102615883909197041", "price": "0.821", "size": "20", "side": "BUY", "hash": "2d049bdd3308a7a40c96fb84964a015e84fe6616", "best_bid": "0.887", "best_ask": "0.904"}, {"asset_id": "90685511192998551789516562849422906363784901518167369632157413860597087715433", "price": "0.179", "size": "20", "side": "SELL", "hash": "977b9282b2d25d6833fc02d308f6068f9a49909b", "best_bid": "0.096", "best_ask": "0.113"}], "timestamp": "1769384026373", "event_type": "price_change"}}
{"_local_timestamp": "2026-01-25T23:33:46.540256+00:00", "data": {"market": "0xf829129cd05db888741ad290c786a1d71db5f8bb8493d8bc07e21b826db4d328", "price_changes": [{"asset_id": "105495516848871865829093849779907676478444075202002902600889102615883909197041", "price": "0.852", "size": "0", "side": "BUY", "hash": "eda49154f7ef1b1aea740b13f76b4f2083b08fba", "best_bid": "0.887", "best_ask": "0.904"}, {"asset_id": "90685511192998551789516562849422906363784901518167369632157413860597087715433", "price": "0.148", "size": "0", "side": "SELL", "hash": "fc92d7fcb2ff2cdd15d700bd004b7e4e254ffee1", "best_bid": "0.096", "best_ask": "0.113"}], "timestamp": "1769384026473", "event_type": "price_change"}}
{"_local_timestamp": "2026-01-25T23:33:46.562459+00:00", "data": {"market": "0xf829129cd05db888741ad290c786a1d71db5f8bb8493d8bc07e21b826db4d328", "price_changes": [{"asset_id": "105495516848871865829093849779907676478444075202002902600889102615883909197041", "price": "0.832", "size": "51", "side": "BUY", "hash": "03608173bbfc1ca95255659de98272f26af57b5e", "best_bid": "0.887", "best_ask": "0.904"}, {"asset_id": "90685511192998551789516562849422906363784901518167369632157413860597087715433", "price": "0.168", "size": "51", "side": "SELL", "hash": "689986b34d243b59966414bc3965aa8e778499c2", "best_bid": "0.096", "best_ask": "0.113"}], "timestamp": "1769384026497", "event_type": "price_change"}}
{"_local_timestamp": "2026-01-25T23:33:46.564263+00:00", "data": {"market": "0xf829129cd05db888741ad290c786a1d71db5f8bb8493d8bc07e21b826db4d328", "price_changes": [{"asset_id": "105495516848871865829093849779907676478444075202002902600889102615883909197041", "price": "0.832", "size": "102", "side": "BUY", "hash": "dac1874b1b1a305657f05766043fcba9d23a16d0", "best_bid": "0.887", "best_ask": "0.904"}, {"asset_id": "90685511192998551789516562849422906363784901518167369632157413860597087715433", "price": "0.168", "size": "102", "side": "SELL", "hash": "bcbef0a96226bc2acfb0e5c37b3616e00b02e36e", "best_bid": "0.096", "best_ask": "0.113"}], "timestamp": "1769384026500", "event_type": "price_change"}}
{"_local_timestamp": "2026-01-25T23:33:46.663484+00:00", "data": {"market": "0xf829129cd05db888741ad290c786a1d71db5f8bb8493d8bc07e21b826db4d328", "price_changes": [{"asset_id": "105495516848871865829093849779907676478444075202002902600889102615883909197041", "price": "0.832", "size": "51", "side": "BUY", "hash": "806b456928efe3e95abcd61ff2b8d9af8a2f650d", "best_bid": "0.887", "best_ask": "0.904"}, {"asset_id": "90685511192998551789516562849422906363784901518167369632157413860597087715433", "price": "0.168", "size": "51", "side": "SELL", "hash": "46623f8020994b5d6779a136d090f1324faff0c9", "best_bid": "0.096", "best_ask": "0.113"}], "timestamp": "1769384026599", "event_type": "price_change"}}
{"_local_timestamp": "2026-01-25T23:33:47.135203+00:00", "data": {"market": "0xf829129cd05db888741ad290c786a1d71db5f8bb8493d8bc07e21b826db4d328", "price_changes": [{"asset_id": "105495516848871865829093849779907676478444075202002902600889102615883909197041", "price": "0.821", "size": "0", "side": "BUY", "hash": "64e1ab58c10e7a071a44fa2f32d27d230f6830b1", "best_bid": "0.887", "best_ask": "0.904"}, {"asset_id": "90685511192998551789516562849422906363784901518167369632157413860597087715433", "price": "0.179", "size": "0", "side": "SELL", "hash": "a561fc824748d90c012a905d1a5aafe07a69c8f1", "best_bid": "0.096", "best_ask": "0.113"}], "timestamp": "1769384027058", "event_type": "price_change"}}
{"_local_timestamp": "2026-01-25T23:33:47.153821+00:00", "data": {"market": "0xf829129cd05db888741ad290c786a1d71db5f8bb8493d8bc07e21b826db4d328", "price_changes": [{"asset_id": "105495516848871865829093849779907676478444075202002902600889102615883909197041", "price": "0.833", "size": "20", "side": "BUY", "hash": "b621a4ad6115b9cd2d83ce7f397ebf802431bc17", "best_bid": "0.887", "best_ask": "0.904"}, {"asset_id": "90685511192998551789516562849422906363784901518167369632157413860597087715433", "price": "0.167", "size": "20", "side": "SELL", "hash": "365462024bb81ea2431b6447d2f08f497c54a060", "best_bid": "0.096", "best_ask": "0.113"}], "timestamp": "1769384027083", "event_type": "price_change"}}
{"_local_timestamp": "2026-01-25T23:33:47.228153+00:00", "data": {"market": "0xf829129cd05db888741ad290c786a1d71db5f8bb8493d8bc07e21b826db4d328", "price_changes": [{"asset_id": "105495516848871865829093849779907676478444075202002902600889102615883909197041", "price": "0.832", "size": "0", "side": "BUY", "hash": "fd57d02f6f91aa1a198cc86a58bc2cfc4fd77eb6", "best_bid": "0.887", "best_ask": "0.904"}, {"asset_id": "90685511192998551789516562849422906363784901518167369632157413860597087715433", "price": "0.168", "size": "0", "side": "SELL", "hash": "f07f937678faab5c2d6f67d667ae451163bc354b", "best_bid": "0.096", "best_ask": "0.113"}], "timestamp": "1769384027161", "event_type": "price_change"}}
{"_local_timestamp": "2026-01-25T23:33:47.271926+00:00", "data": {"market": "0xf829129cd05db888741ad290c786a1d71db5f8bb8493d8bc07e21b826db4d328", "price_changes": [{"asset_id": "105495516848871865829093849779907676478444075202002902600889102615883909197041", "price": "0.852", "size": "25", "side": "BUY", "hash": "a247d02541e664397af5ef982b3a751920bb3d93", "best_bid": "0.887", "best_ask": "0.904"}, {"asset_id": "90685511192998551789516562849422906363784901518167369632157413860597087715433", "price": "0.148", "size": "25", "side": "SELL", "hash": "4f809fb7494bfe5cb0380095bd6c7d2b00e4e060", "best_bid": "0.096", "best_ask": "0.113"}], "timestamp": "1769384027205", "event_type": "price_change"}}
{"_local_timestamp": "2026-01-25T23:33:48.739351+00:00", "data": {"market": "0xf829129cd05db888741ad290c786a1d71db5f8bb8493d8bc07e21b826db4d328", "price_changes": [{"asset_id": "105495516848871865829093849779907676478444075202002902600889102615883909197041", "price": "0.833", "size": "0", "side": "BUY", "hash": "06609f23e2cdc1967986b5a418cc00f97aa13e45", "best_bid": "0.887", "best_ask": "0.904"}, {"asset_id": "90685511192998551789516562849422906363784901518167369632157413860597087715433", "price": "0.167", "size": "0", "side": "SELL", "hash": "deb498452a6c406f3a1b74a1fd51b84f5b64af13", "best_bid": "0.096", "best_ask": "0.113"}], "timestamp": "1769384028673", "event_type": "price_change"}}
{"_local_timestamp": "2026-01-25T23:33:48.759289+00:00", "data": {"market": "0xf829129cd05db888741ad290c786a1d71db5f8bb8493d8bc07e21b826db4d328", "price_changes": [{"asset_id": "105495516848871865829093849779907676478444075202002902600889102615883909197041", "price": "0.821", "size": "20", "side": "BUY", "hash": "f54e4639b913d876ceeeaeadf2ddc332e8e35d23", "best_bid": "0.887", "best_ask": "0.904"}, {"asset_id": "90685511192998551789516562849422906363784901518167369632157413860597087715433", "price": "0.179", "size": "20", "side": "SELL", "hash": "0171bff193bfa3b670c802480f45576a85dcbe4c", "best_bid": "0.096", "best_ask": "0.113"}], "timestamp": "1769384028696", "event_type": "price_change"}}
{"_local_timestamp": "2026-01-25T23:33:48.845472+00:00", "data": {"market": "0xf829129cd05db888741ad290c786a1d71db5f8bb8493d8bc07e21b826db4d328", "price_changes": [{"asset_id": "105495516848871865829093849779907676478444075202002902600889102615883909197041", "price": "0.852", "size": "0", "side": "BUY", "hash": "b4a7f23831e8515d4af3d5a8596b98b13a6e176b", "best_bid": "0.887", "best_ask": "0.904"}, {"asset_id": "90685511192998551789516562849422906363784901518167369632157413860597087715433", "price": "0.148", "size": "0", "side": "SELL", "hash": "f809d30abf8a09a33f5c1e56028c96bb9f661162", "best_bid": "0.096", "best_ask": "0.113"}], "timestamp": "1769384028778", "event_type": "price_change"}}
{"_local_timestamp": "2026-01-25T23:33:48.846156+00:00", "data": {"market": "0xf829129cd05db888741ad290c786a1d71db5f8bb8493d8bc07e21b826db4d328", "price_changes": [{"asset_id": "105495516848871865829093849779907676478444075202002902600889102615883909197041", "price": "0.852", "size": "25", "side": "BUY", "hash": "ebabc21695bed3e3b6b52a19740fdb2ffceec1b2", "best_bid": "0.887", "best_ask": "0.904"}, {"asset_id": "90685511192998551789516562849422906363784901518167369632157413860597087715433", "price": "0.148", "size": "25", "side": "SELL", "hash": "72e20d26137d90d96fe0e9688d750c72f4bab6ca", "best_bid": "0.096", "best_ask": "0.113"}], "timestamp": "1769384028780", "event_type": "price_change"}}
{"_local_timestamp": "2026-01-25T23:33:48.865748+00:00", "data": {"market": "0xf829129cd05db888741ad290c786a1d71db5f8bb8493d8bc07e21b826db4d328", "price_changes": [{"asset_id": "105495516848871865829093849779907676478444075202002902600889102615883909197041", "price": "0.832", "size": "51", "side": "BUY", "hash": "2f8abd097c3d911594d6398f2fed79bb5a664f03", "best_bid": "0.887", "best_ask": "0.904"}, {"asset_id": "90685511192998551789516562849422906363784901518167369632157413860597087715433", "price": "0.168", "size": "51", "side": "SELL", "hash": "6a9d1b0acf9effa8caf38e100fd0c2e6c91f4fd2", "best_bid": "0.096", "best_ask": "0.113"}], "timestamp": "1769384028802", "event_type": "price_change"}}
{"_local_timestamp": "2026-01-25T23:33:48.948972+00:00", "data": {"market": "0xf829129cd05db888741ad290c786a1d71db5f8bb8493d8bc07e21b826db4d328", "price_changes": [{"asset_id": "105495516848871865829093849779907676478444075202002902600889102615883909197041", "price": "0.852", "size": "0", "side": "BUY", "hash": "9c45c880220512d15c8ce2b020f16fde9de95df1", "best_bid": "0.887", "best_ask": "0.904"}, {"asset_id": "90685511192998551789516562849422906363784901518167369632157413860597087715433", "price": "0.148", "size": "0", "side": "SELL", "hash": "db0415bc8aa3cee8e69c07ceb46db7fd6d2a3eb1", "best_bid": "0.096", "best_ask": "0.113"}], "timestamp": "1769384028883", "event_type": "price_change"}}
{"_local_timestamp": "2026-01-25T23:33:49.777157+00:00", "data": {"market": "0xf829129cd05db888741ad290c786a1d71db5f8bb8493d8bc07e21b826db4d328", "price_changes": [{"asset_id": "105495516848871865829093849779907676478444075202002902600889102615883909197041", "price": "0.821", "size": "0", "side": "BUY", "hash": "016b5ac004f9ddc1bcd712ff44b2c306df63849e", "best_bid": "0.887", "best_ask": "0.904"}, {"asset_id": "90685511192998551789516562849422906363784901518167369632157413860597087715433", "price": "0.179", "size": "0", "side": "SELL", "hash": "3ed6be0bd872d0447ce8380f3ca0ebf38baaf02a", "best_bid": "0.096", "best_ask": "0.113"}], "timestamp": "1769384029710", "event_type": "price_change"}}
{"_local_timestamp": "2026-01-25T23:33:49.815811+00:00", "data": {"market": "0xf829129cd05db888741ad290c786a1d71db5f8bb8493d8bc07e21b826db4d328", "price_changes": [{"asset_id": "105495516848871865829093849779907676478444075202002902600889102615883909197041", "price": "0.833", "size": "20", "side": "BUY", "hash": "026a691a7d3113eabf512031b5df1df5bbdcf4f0", "best_bid": "0.887", "best_ask": "0.904"}, {"asset_id": "90685511192998551789516562849422906363784901518167369632157413860597087715433", "price": "0.167", "size": "20", "side": "SELL", "hash": "f21e73d92621320af656431f754f26951d1f51f4", "best_bid": "0.096", "best_ask": "0.113"}], "timestamp": "1769384029737", "event_type": "price_change"}}
{"_local_timestamp": "2026-01-25T23:33:49.885022+00:00", "data": {"market": "0xf829129cd05db888741ad290c786a1d71db5f8bb8493d8bc07e21b826db4d328", "price_changes": [{"asset_id": "105495516848871865829093849779907676478444075202002902600889102615883909197041", "price": "0.832", "size": "102", "side": "BUY", "hash": "e29843bb2eb788af5c4f9713e34a929f345070f2", "best_bid": "0.887", "best_ask": "0.904"}, {"asset_id": "90685511192998551789516562849422906363784901518167369632157413860597087715433", "price": "0.168", "size": "102", "side": "SELL", "hash": "7e3a711484c9f3c5adce15c01b5a1c1f34bbfbfd", "best_bid": "0.096", "best_ask": "0.113"}], "timestamp": "1769384029816", "event_type": "price_change"}}
{"_local_timestamp": "2026-01-25T23:33:49.885824+00:00", "data": {"market": "0xf829129cd05db888741ad290c786a1d71db5f8bb8493d8bc07e21b826db4d328", "price_changes": [{"asset_id": "105495516848871865829093849779907676478444075202002902600889102615883909197041", "price": "0.832", "size": "51", "side": "BUY", "hash": "e31278f2ecf8d921a84556f15eec38ae8490d1b4", "best_bid": "0.887", "best_ask": "0.904"}, {"asset_id": "90685511192998551789516562849422906363784901518167369632157413860597087715433", "price": "0.168", "size": "51", "side": "SELL", "hash": "7042fd8d1b7c2b77ae0bc1fd1c217bc8b7f59844", "best_bid": "0.096", "best_ask": "0.113"}], "timestamp": "1769384029821", "event_type": "price_change"}}
{"_local_timestamp": "2026-01-25T23:33:49.929688+00:00", "data": {"market": "0xf829129cd05db888741ad290c786a1d71db5f8bb8493d8bc07e21b826db4d328", "price_changes": [{"asset_id": "105495516848871865829093849779907676478444075202002902600889102615883909197041", "price": "0.852", "size": "25", "side": "BUY", "hash": "0fbf5b940e062048b522d2a9d0aefd698f179cdc", "best_bid": "0.887", "best_ask": "0.904"}, {"asset_id": "90685511192998551789516562849422906363784901518167369632157413860597087715433", "price": "0.148", "size": "25", "side": "SELL", "hash": "520c2629328c74f58a05338e4ae4c450948d1635", "best_bid": "0.096", "best_ask": "0.113"}], "timestamp": "1769384029868", "event_type": "price_change"}}
{"_local_timestamp": "2026-01-25T23:33:49.992362+00:00", "data": {"market": "0xf829129cd05db888741ad290c786a1d71db5f8bb8493d8bc07e21b826db4d328", "price_changes": [{"asset_id": "105495516848871865829093849779907676478444075202002902600889102615883909197041", "price": "0.832", "size": "0", "side": "BUY", "hash": "87df2ad787f38d22eb3d90793bed2162bcb96aa9", "best_bid": "0.887", "best_ask": "0.904"}, {"asset_id": "90685511192998551789516562849422906363784901518167369632157413860597087715433", "price": "0.168", "size": "0", "side": "SELL", "hash": "0bbb08f2744ef1424b3147e2b0761993eb6be844", "best_bid": "0.096", "best_ask": "0.113"}], "timestamp": "1769384029926", "event_type": "price_change"}}
{"_local_timestamp": "2026-01-25T23:33:51.108149+00:00", "data": {"market": "0xf829129cd05db888741ad290c786a1d71db5f8bb8493d8bc07e21b826db4d328", "price_changes": [{"asset_id": "105495516848871865829093849779907676478444075202002902600889102615883909197041", "price": "0.833", "size": "0", "side": "BUY", "hash": "fa70606518f1618df8da25a4ffda6977e2490e0b", "best_bid": "0.887", "best_ask": "0.904"}, {"asset_id": "90685511192998551789516562849422906363784901518167369632157413860597087715433", "price": "0.167", "size": "0", "side": "SELL", "hash": "0bf845ed69bb4631854fbbbf37d23caff9686152", "best_bid": "0.096", "best_ask": "0.113"}], "timestamp": "1769384031043", "event_type": "price_change"}}
{"_local_timestamp": "2026-01-25T23:33:51.149250+00:00", "data": {"market": "0xf829129cd05db888741ad290c786a1d71db5f8bb8493d8bc07e21b826db4d328", "price_changes": [{"asset_id": "105495516848871865829093849779907676478444075202002902600889102615883909197041", "price": "0.821", "size": "20", "side": "BUY", "hash": "f5a278c95bc1ece6168595050a020dd842c976b4", "best_bid": "0.887", "best_ask": "0.904"}, {"asset_id": "90685511192998551789516562849422906363784901518167369632157413860597087715433", "price": "0.179", "size": "20", "side": "SELL", "hash": "c5b127155e62dbe1e79c5492c63d5f9ee9668ec4", "best_bid": "0.096", "best_ask": "0.113"}], "timestamp": "1769384031067", "event_type": "price_change"}}
{"_local_timestamp": "2026-01-25T23:33:51.210989+00:00", "data": {"market": "0xf829129cd05db888741ad290c786a1d71db5f8bb8493d8bc07e21b826db4d328", "price_changes": [{"asset_id": "105495516848871865829093849779907676478444075202002902600889102615883909197041", "price": "0.852", "size": "50", "side": "BUY", "hash": "22f0d007de5b32f6511652af751213fbcb73ee22", "best_bid": "0.887", "best_ask": "0.904"}, {"asset_id": "90685511192998551789516562849422906363784901518167369632157413860597087715433", "price": "0.148", "size": "50", "side": "SELL", "hash": "ad143d1364b7b6eaab30906de944b2b6504f0392", "best_bid": "0.096", "best_ask": "0.113"}], "timestamp": "1769384031147", "event_type": "price_change"}}
{"_local_timestamp": "2026-01-25T23:33:51.259237+00:00", "data": {"market": "0xf829129cd05db888741ad290c786a1d71db5f8bb8493d8bc07e21b826db4d328", "price_changes": [{"asset_id": "105495516848871865829093849779907676478444075202002902600889102615883909197041", "price": "0.852", "size": "25", "side": "BUY", "hash": "0ba110ec959cd01dabd9e58dc12fb6edad8d5d9f", "best_bid": "0.887", "best_ask": "0.904"}, {"asset_id": "90685511192998551789516562849422906363784901518167369632157413860597087715433", "price": "0.148", "size": "25", "side": "SELL", "hash": "3eb20a0dfc049411ed57a67ec4e01ba639d0a474", "best_bid": "0.096", "best_ask": "0.113"}], "timestamp": "1769384031192", "event_type": "price_change"}}
{"_local_timestamp": "2026-01-25T23:33:51.260193+00:00", "data": {"market": "0xf829129cd05db888741ad290c786a1d71db5f8bb8493d8bc07e21b826db4d328", "price_changes": [{"asset_id": "105495516848871865829093849779907676478444075202002902600889102615883909197041", "price": "0.832", "size": "51", "side": "BUY", "hash": "891770cff335b6eade30f8c8917674a697d58b80", "best_bid": "0.887", "best_ask": "0.904"}, {"asset_id": "90685511192998551789516562849422906363784901518167369632157413860597087715433", "price": "0.168", "size": "51", "side": "SELL", "hash": "549509eb806772b9aad19029db427ece3f529626", "best_bid": "0.096", "best_ask": "0.113"}], "timestamp": "1769384031194", "event_type": "price_change"}}
{"_local_timestamp": "2026-01-25T23:33:51.314261+00:00", "data": {"market": "0xf829129cd05db888741ad290c786a1d71db5f8bb8493d8bc07e21b826db4d328", "price_changes": [{"asset_id": "105495516848871865829093849779907676478444075202002902600889102615883909197041", "price": "0.852", "size": "0", "side": "BUY", "hash": "fabe6037b74c5a5e2b4920ef7d585e105a130680", "best_bid": "0.887", "best_ask": "0.904"}, {"asset_id": "90685511192998551789516562849422906363784901518167369632157413860597087715433", "price": "0.148", "size": "0", "side": "SELL", "hash": "31faec34bf3d4e85c649a18a054ff23cfb07c0c0", "best_bid": "0.096", "best_ask": "0.113"}], "timestamp": "1769384031250", "event_type": "price_change"}}
{"_local_timestamp": "2026-01-25T23:33:51.975438+00:00", "data": {"market": "0xf829129cd05db888741ad290c786a1d71db5f8bb8493d8bc07e21b826db4d328", "price_changes": [{"asset_id": "105495516848871865829093849779907676478444075202002902600889102615883909197041", "price": "0.821", "size": "0", "side": "BUY", "hash": "922c123dfaaf817ef2a4ef171ce63037119e1f51", "best_bid": "0.887", "best_ask": "0.904"}, {"asset_id": "90685511192998551789516562849422906363784901518167369632157413860597087715433", "price": "0.179", "size": "0", "side": "SELL", "hash": "d0848723fe5976c103eb4bc602e731330d1ad445", "best_bid": "0.096", "best_ask": "0.113"}], "timestamp": "1769384031906", "event_type": "price_change"}}
{"_local_timestamp": "2026-01-25T23:33:51.996660+00:00", "data": {"market": "0xf829129cd05db888741ad290c786a1d71db5f8bb8493d8bc07e21b826db4d328", "price_changes": [{"asset_id": "105495516848871865829093849779907676478444075202002902600889102615883909197041", "price": "0.833", "size": "20", "side": "BUY", "hash": "e3d6b3e6004c67050077be869f327414f14c3903", "best_bid": "0.887", "best_ask": "0.904"}, {"asset_id": "90685511192998551789516562849422906363784901518167369632157413860597087715433", "price": "0.167", "size": "20", "side": "SELL", "hash": "aa506abc8c533d41b506b9109e653f1ebaaf533c", "best_bid": "0.096", "best_ask": "0.113"}], "timestamp": "1769384031931", "event_type": "price_change"}}
{"_local_timestamp": "2026-01-25T23:33:52.105791+00:00", "data": {"market": "0xf829129cd05db888741ad290c786a1d71db5f8bb8493d8bc07e21b826db4d328", "price_changes": [{"asset_id": "105495516848871865829093849779907676478444075202002902600889102615883909197041", "price": "0.832", "size": "0", "side": "BUY", "hash": "be794d6fb530c04f26c6b1467c4c172626232573", "best_bid": "0.887", "best_ask": "0.904"}, {"asset_id": "90685511192998551789516562849422906363784901518167369632157413860597087715433", "price": "0.168", "size": "0", "side": "SELL", "hash": "8286e622939320280ede1491317adfd0f844d70d", "best_bid": "0.096", "best_ask": "0.113"}], "timestamp": "1769384032018", "event_type": "price_change"}}
{"_local_timestamp": "2026-01-25T23:33:52.121326+00:00", "data": {"market": "0xf829129cd05db888741ad290c786a1d71db5f8bb8493d8bc07e21b826db4d328", "price_changes": [{"asset_id": "105495516848871865829093849779907676478444075202002902600889102615883909197041", "price": "0.852", "size": "25", "side": "BUY", "hash": "83d8e31f82f74271575439cd92912ed245cbf058", "best_bid": "0.887", "best_ask": "0.904"}, {"asset_id": "90685511192998551789516562849422906363784901518167369632157413860597087715433", "price": "0.148", "size": "25", "side": "SELL", "hash": "9bd0469ef972cd246afaa22d71d0fbb83af707f7", "best_bid": "0.096", "best_ask": "0.113"}], "timestamp": "1769384032041", "event_type": "price_change"}}
{"_local_timestamp": "2026-01-25T23:33:52.219685+00:00", "data": {"market": "0xf829129cd05db888741ad290c786a1d71db5f8bb8493d8bc07e21b826db4d328", "price_changes": [{"asset_id": "105495516848871865829093849779907676478444075202002902600889102615883909197041", "price": "0.852", "size": "50", "side": "BUY", "hash": "d434db794d05dc55d7afe3cc4325b89926445827", "best_bid": "0.887", "best_ask": "0.904"}, {"asset_id": "90685511192998551789516562849422906363784901518167369632157413860597087715433", "price": "0.148", "size": "50", "side": "SELL", "hash": "33bb582c955cbafc9c07e88120272f94ba33b30d", "best_bid": "0.096", "best_ask": "0.113"}], "timestamp": "1769384032153", "event_type": "price_change"}}
{"_local_timestamp": "2026-01-25T23:33:52.334628+00:00", "data": {"market": "0xf829129cd05db888741ad290c786a1d71db5f8bb8493d8bc07e21b826db4d328", "price_changes": [{"asset_id": "105495516848871865829093849779907676478444075202002902600889102615883909197041", "price": "0.852", "size": "25", "side": "BUY", "hash": "ea0f51a98bed0a0c2ffb29dace38ce1227f7ecc9", "best_bid": "0.887", "best_ask": "0.904"}, {"asset_id": "90685511192998551789516562849422906363784901518167369632157413860597087715433", "price": "0.148", "size": "25", "side": "SELL", "hash": "89ea8c27f0f41136b3c2426edb9192071f6156e5", "best_bid": "0.096", "best_ask": "0.113"}], "timestamp": "1769384032270", "event_type": "price_change"}}
{"_local_timestamp": "2026-01-25T23:33:52.492758+00:00", "data": {"market": "0x897a2f88e1b65776ac5af0440833eea638395f0af0df4bed47e83f64c9b9a1e3", "price_changes": [{"asset_id": "67301121905355380418923087513498375592166001657797903147689423172757844806122", "price": "0.29", "size": "0", "side": "BUY", "hash": "0c05c8f7ce5b0a8c8d0fb79f8e334fab8e87384d", "best_bid": "0.44", "best_ask": "0.46"}, {"asset_id": "11824574045576628150612194967948587889530003270004521491303323671815597832573", "price": "0.71", "size": "0", "side": "SELL", "hash": "a94bd43975adadc23df256d9cd7dcc675ea8d7fd", "best_bid": "0.54", "best_ask": "0.56"}], "timestamp": "1769384032410", "event_type": "price_change"}}
{"_local_timestamp": "2026-01-25T23:33:52.888499+00:00", "data": {"market": "0xf829129cd05db888741ad290c786a1d71db5f8bb8493d8bc07e21b826db4d328", "price_changes": [{"asset_id": "105495516848871865829093849779907676478444075202002902600889102615883909197041", "price": "0.833", "size": "0", "side": "BUY", "hash": "62a6b18d0ff26108bb94d72b6b3b0317605f6e3a", "best_bid": "0.887", "best_ask": "0.904"}, {"asset_id": "90685511192998551789516562849422906363784901518167369632157413860597087715433", "price": "0.167", "size": "0", "side": "SELL", "hash": "da54fa60b8b46721ca2f59b0a5d22bb2cf8507ab", "best_bid": "0.096", "best_ask": "0.113"}], "timestamp": "1769384032821", "event_type": "price_change"}}
{"_local_timestamp": "2026-01-25T23:33:52.909148+00:00", "data": {"market": "0xf829129cd05db888741ad290c786a1d71db5f8bb8493d8bc07e21b826db4d328", "price_changes": [{"asset_id": "105495516848871865829093849779907676478444075202002902600889102615883909197041", "price": "0.821", "size": "20", "side": "BUY", "hash": "59a0ae5ff7f96d2511ce0e7af50c038300b0ce75", "best_bid": "0.887", "best_ask": "0.904"}, {"asset_id": "90685511192998551789516562849422906363784901518167369632157413860597087715433", "price": "0.179", "size": "20", "side": "SELL", "hash": "9fa5676b3a0e7c1e2643f10ebd99d4227841b630", "best_bid": "0.096", "best_ask": "0.113"}], "timestamp": "1769384032843", "event_type": "price_change"}}
{"_local_timestamp": "2026-01-25T23:33:53.031552+00:00", "data": {"market": "0xf829129cd05db888741ad290c786a1d71db5f8bb8493d8bc07e21b826db4d328", "price_changes": [{"asset_id": "105495516848871865829093849779907676478444075202002902600889102615883909197041", "price": "0.852", "size": "0", "side": "BUY", "hash": "716256e8ca11137fc6f108fee4787c73208b0618", "best_bid": "0.887", "best_ask": "0.904"}, {"asset_id": "90685511192998551789516562849422906363784901518167369632157413860597087715433", "price": "0.148", "size": "0", "side": "SELL", "hash": "9e070fdcb4e44c737e668066d061c7ceb8373251", "best_bid": "0.096", "best_ask": "0.113"}], "timestamp": "1769384032966", "event_type": "price_change"}}
{"_local_timestamp": "2026-01-25T23:33:53.042439+00:00", "data": {"market": "0xf829129cd05db888741ad290c786a1d71db5f8bb8493d8bc07e21b826db4d328", "price_changes": [{"asset_id": "105495516848871865829093849779907676478444075202002902600889102615883909197041", "price": "0.832", "size": "51", "side": "BUY", "hash": "2e7695727dc0ca5cd57534205a08f20489e18d93", "best_bid": "0.887", "best_ask": "0.904"}, {"asset_id": "90685511192998551789516562849422906363784901518167369632157413860597087715433", "price": "0.168", "size": "51", "side": "SELL", "hash": "abb345979867dc8fc9c38aa2be57320f90751057", "best_bid": "0.096", "best_ask": "0.113"}], "timestamp": "1769384032970", "event_type": "price_change"}}
{"_local_timestamp": "2026-01-25T23:33:53.637705+00:00", "data": {"market": "0xf829129cd05db888741ad290c786a1d71db5f8bb8493d8bc07e21b826db4d328", "price_changes": [{"asset_id": "105495516848871865829093849779907676478444075202002902600889102615883909197041", "price": "0.821", "size": "0", "side": "BUY", "hash": "c3594f4937d0f2a69ebf5563381686c65c346ce9", "best_bid": "0.887", "best_ask": "0.904"}, {"asset_id": "90685511192998551789516562849422906363784901518167369632157413860597087715433", "price": "0.179", "size": "0", "side": "SELL", "hash": "342fc9e904885cdcc73d1d2f60ab5c4c7722252c", "best_bid": "0.096", "best_ask": "0.113"}], "timestamp": "1769384033575", "event_type": "price_change"}}
{"_local_timestamp": "2026-01-25T23:33:53.670121+00:00", "data": {"market": "0xf829129cd05db888741ad290c786a1d71db5f8bb8493d8bc07e21b826db4d328", "price_changes": [{"asset_id": "105495516848871865829093849779907676478444075202002902600889102615883909197041", "price": "0.833", "size": "20", "side": "BUY", "hash": "e4cb387c9a9302cfbd6cddacf71909cc40d59b48", "best_bid": "0.887", "best_ask": "0.904"}, {"asset_id": "90685511192998551789516562849422906363784901518167369632157413860597087715433", "price": "0.167", "size": "20", "side": "SELL", "hash": "ed2e61dd97525251c90b4dcc6985364b493deeb6", "best_bid": "0.096", "best_ask": "0.113"}], "timestamp": "1769384033600", "event_type": "price_change"}}
{"_local_timestamp": "2026-01-25T23:33:53.770940+00:00", "data": {"market": "0xf829129cd05db888741ad290c786a1d71db5f8bb8493d8bc07e21b826db4d328", "price_changes": [{"asset_id": "105495516848871865829093849779907676478444075202002902600889102615883909197041", "price": "0.832", "size": "0", "side": "BUY", "hash": "77af5b9be3877723ee02d737de82a8df3c3c7347", "best_bid": "0.887", "best_ask": "0.904"}, {"asset_id": "90685511192998551789516562849422906363784901518167369632157413860597087715433", "price": "0.168", "size": "0", "side": "SELL", "hash": "410ee1497c1e1c987c86eeeaa8504ca92a2ad068", "best_bid": "0.096", "best_ask": "0.113"}], "timestamp": "1769384033706", "event_type": "price_change"}}
{"_local_timestamp": "2026-01-25T23:33:53.773489+00:00", "data": {"market": "0xf829129cd05db888741ad290c786a1d71db5f8bb8493d8bc07e21b826db4d328", "price_changes": [{"asset_id": "105495516848871865829093849779907676478444075202002902600889102615883909197041", "price": "0.852", "size": "25", "side": "BUY", "hash": "468534b54845047e0c1da659c063e9398348f985", "best_bid": "0.887", "best_ask": "0.904"}, {"asset_id": "90685511192998551789516562849422906363784901518167369632157413860597087715433", "price": "0.148", "size": "25", "side": "SELL", "hash": "57d15a54cd07a16b03839c7d80d9ad8e9797717e", "best_bid": "0.096", "best_ask": "0.113"}], "timestamp": "1769384033707", "event_type": "price_change"}}
{"_local_timestamp": "2026-01-25T23:33:53.802545+00:00", "data": {"market": "0xf829129cd05db888741ad290c786a1d71db5f8bb8493d8bc07e21b826db4d328", "price_changes": [{"asset_id": "105495516848871865829093849779907676478444075202002902600889102615883909197041", "price": "0.832", "size": "51", "side": "BUY", "hash": "5e1bfa6af42dcef094ed73188ba940f774ec5740", "best_bid": "0.887", "best_ask": "0.904"}, {"asset_id": "90685511192998551789516562849422906363784901518167369632157413860597087715433", "price": "0.168", "size": "51", "side": "SELL", "hash": "d9fe79b0c5ef0a3b9dc30ca8eacaaaadcf452d9c", "best_bid": "0.096", "best_ask": "0.113"}], "timestamp": "1769384033737", "event_type": "price_change"}}
{"_local_timestamp": "2026-01-25T23:33:53.922531+00:00", "data": {"market": "0xf829129cd05db888741ad290c786a1d71db5f8bb8493d8bc07e21b826db4d328", "price_changes": [{"asset_id": "105495516848871865829093849779907676478444075202002902600889102615883909197041", "price": "0.832", "size": "0", "side": "BUY", "hash": "f28d97c8fc0e6fb8c2b0956d26be56abf6f205a5", "best_bid": "0.887", "best_ask": "0.904"}, {"asset_id": "90685511192998551789516562849422906363784901518167369632157413860597087715433", "price": "0.168", "size": "0", "side": "SELL", "hash": "723bbf574b147d4f9d9c1f79144e4b3cf190b938", "best_bid": "0.096", "best_ask": "0.113"}], "timestamp": "1769384033859", "event_type": "price_change"}}
{"_local_timestamp": "2026-01-25T23:33:54.595219+00:00", "data": {"market": "0xf829129cd05db888741ad290c786a1d71db5f8bb8493d8bc07e21b826db4d328", "price_changes": [{"asset_id": "105495516848871865829093849779907676478444075202002902600889102615883909197041", "price": "0.833", "size": "0", "side": "BUY", "hash": "7b79da6fe8ba029db3c3f4e7251c0bc39148e4bc", "best_bid": "0.887", "best_ask": "0.904"}, {"asset_id": "90685511192998551789516562849422906363784901518167369632157413860597087715433", "price": "0.167", "size": "0", "side": "SELL", "hash": "43d568f0cbfdd39533bbd3e5ccc6de9a978a873f", "best_bid": "0.096", "best_ask": "0.113"}], "timestamp": "1769384034515", "event_type": "price_change"}}
{"_local_timestamp": "2026-01-25T23:33:54.619805+00:00", "data": {"market": "0xf829129cd05db888741ad290c786a1d71db5f8bb8493d8bc07e21b826db4d328", "price_changes": [{"asset_id": "105495516848871865829093849779907676478444075202002902600889102615883909197041", "price": "0.821", "size": "20", "side": "BUY", "hash": "00a9a7905f1d0951ed9128b437f32f12d9905b56", "best_bid": "0.887", "best_ask": "0.904"}, {"asset_id": "90685511192998551789516562849422906363784901518167369632157413860597087715433", "price": "0.179", "size": "20", "side": "SELL", "hash": "96420a65a5ccc41fcb325ba204d56afce0efd653", "best_bid": "0.096", "best_ask": "0.113"}], "timestamp": "1769384034548", "event_type": "price_change"}}
{"_local_timestamp": "2026-01-25T23:33:54.714030+00:00", "data": {"market": "0xf829129cd05db888741ad290c786a1d71db5f8bb8493d8bc07e21b826db4d328", "price_changes": [{"asset_id": "105495516848871865829093849779907676478444075202002902600889102615883909197041", "price": "0.852", "size": "0", "side": "BUY", "hash": "85e105066271f22736301a450aa9d42eb79833d2", "best_bid": "0.887", "best_ask": "0.904"}, {"asset_id": "90685511192998551789516562849422906363784901518167369632157413860597087715433", "price": "0.148", "size": "0", "side": "SELL", "hash": "c2e2102e7b07b7704b9c544ebb828afa5d3952dc", "best_bid": "0.096", "best_ask": "0.113"}], "timestamp": "1769384034647", "event_type": "price_change"}}
{"_local_timestamp": "2026-01-25T23:33:54.721572+00:00", "data": {"market": "0xf829129cd05db888741ad290c786a1d71db5f8bb8493d8bc07e21b826db4d328", "price_changes": [{"asset_id": "105495516848871865829093849779907676478444075202002902600889102615883909197041", "price": "0.832", "size": "51", "side": "BUY", "hash": "57347fc5a5725763b501d5b8b8a21674ab097dd7", "best_bid": "0.887", "best_ask": "0.904"}, {"asset_id": "90685511192998551789516562849422906363784901518167369632157413860597087715433", "price": "0.168", "size": "51", "side": "SELL", "hash": "96f0c9d30cb12723f4709be7831ff8b9c8e762a1", "best_bid": "0.096", "best_ask": "0.113"}], "timestamp": "1769384034655", "event_type": "price_change"}}
{"_local_timestamp": "2026-01-25T23:33:54.824059+00:00", "data": {"market": "0xf829129cd05db888741ad290c786a1d71db5f8bb8493d8bc07e21b826db4d328", "price_changes": [{"asset_id": "105495516848871865829093849779907676478444075202002902600889102615883909197041", "price": "0.832", "size": "102", "side": "BUY", "hash": "953a619998d2f8cff2b2f4e218253513397e64a4", "best_bid": "0.887", "best_ask": "0.904"}, {"asset_id": "90685511192998551789516562849422906363784901518167369632157413860597087715433", "price": "0.168", "size": "102", "side": "SELL", "hash": "9a191cac1748215ac41c4a856c7f0ce304db3aa7", "best_bid": "0.096", "best_ask": "0.113"}], "timestamp": "1769384034753", "event_type": "price_change"}}
{"_local_timestamp": "2026-01-25T23:33:54.924050+00:00", "data": {"market": "0xf829129cd05db888741ad290c786a1d71db5f8bb8493d8bc07e21b826db4d328", "price_changes": [{"asset_id": "105495516848871865829093849779907676478444075202002902600889102615883909197041", "price": "0.832", "size": "51", "side": "BUY", "hash": "b71f42043aa2914dc0ff20665d7b856033e1815d", "best_bid": "0.887", "best_ask": "0.904"}, {"asset_id": "90685511192998551789516562849422906363784901518167369632157413860597087715433", "price": "0.168", "size": "51", "side": "SELL", "hash": "76557da7ba780d42960a7366be4ba29e4a9c7664", "best_bid": "0.096", "best_ask": "0.113"}], "timestamp": "1769384034856", "event_type": "price_change"}}
{"_local_timestamp": "2026-01-25T23:33:55.663262+00:00", "data": {"market": "0xf829129cd05db888741ad290c786a1d71db5f8bb8493d8bc07e21b826db4d328", "price_changes": [{"asset_id": "105495516848871865829093849779907676478444075202002902600889102615883909197041", "price": "0.821", "size": "0", "side": "BUY", "hash": "88eac634740332861d7632b97a17ffd532ea1e44", "best_bid": "0.887", "best_ask": "0.904"}, {"asset_id": "90685511192998551789516562849422906363784901518167369632157413860597087715433", "price": "0.179", "size": "0", "side": "SELL", "hash": "bb1c7bd5fc5afb0e7ab2c18271b5b64a5fc3d8b4", "best_bid": "0.096", "best_ask": "0.113"}], "timestamp": "1769384035583", "event_type": "price_change"}}
{"_local_timestamp": "2026-01-25T23:33:55.678904+00:00", "data": {"market": "0xf829129cd05db888741ad290c786a1d71db5f8bb8493d8bc07e21b826db4d328", "price_changes": [{"asset_id": "105495516848871865829093849779907676478444075202002902600889102615883909197041", "price": "0.833", "size": "20", "side": "BUY", "hash": "ed96130807d556b896d7673f0e184ee64c31a06f", "best_bid": "0.887", "best_ask": "0.904"}, {"asset_id": "90685511192998551789516562849422906363784901518167369632157413860597087715433", "price": "0.167", "size": "20", "side": "SELL", "hash": "19b48cb02dcde6fbf9e9fae615a3cee5bdd83dc4", "best_bid": "0.096", "best_ask": "0.113"}], "timestamp": "1769384035612", "event_type": "price_change"}}
{"_local_timestamp": "2026-01-25T23:33:55.809292+00:00", "data": {"market": "0xf829129cd05db888741ad290c786a1d71db5f8bb8493d8bc07e21b826db4d328", "price_changes": [{"asset_id": "105495516848871865829093849779907676478444075202002902600889102615883909197041", "price": "0.852", "size": "25", "side": "BUY", "hash": "b8a7330ac1d5f7f07ce1db9392b2aa982d7d417e", "best_bid": "0.887", "best_ask": "0.904"}, {"asset_id": "90685511192998551789516562849422906363784901518167369632157413860597087715433", "price": "0.148", "size": "25", "side": "SELL", "hash": "613721dee527bddb5f13a2075230975b86597eee", "best_bid": "0.096", "best_ask": "0.113"}], "timestamp": "1769384035740", "event_type": "price_change"}}
{"_local_timestamp": "2026-01-25T23:33:55.817319+00:00", "data": {"market": "0xf829129cd05db888741ad290c786a1d71db5f8bb8493d8bc07e21b826db4d328", "price_changes": [{"asset_id": "105495516848871865829093849779907676478444075202002902600889102615883909197041", "price": "0.832", "size": "0", "side": "BUY", "hash": "6da4581cc8c3db66a9fafb1e2b2bd2f4a70376de", "best_bid": "0.887", "best_ask": "0.904"}, {"asset_id": "90685511192998551789516562849422906363784901518167369632157413860597087715433", "price": "0.168", "size": "0", "side": "SELL", "hash": "e2fddf53abb85ed82afc70f5d7647dc12c372217", "best_bid": "0.096", "best_ask": "0.113"}], "timestamp": "1769384035750", "event_type": "price_change"}}
{"_local_timestamp": "2026-01-25T23:33:55.916245+00:00", "data": {"market": "0xf829129cd05db888741ad290c786a1d71db5f8bb8493d8bc07e21b826db4d328", "price_changes": [{"asset_id": "105495516848871865829093849779907676478444075202002902600889102615883909197041", "price": "0.852", "size": "50", "side": "BUY", "hash": "f7f99eb1c3d8b14a6d1fd652b04faa1aa2512f27", "best_bid": "0.887", "best_ask": "0.904"}, {"asset_id": "90685511192998551789516562849422906363784901518167369632157413860597087715433", "price": "0.148", "size": "50", "side": "SELL", "hash": "d51dfec92d705308384acbd42a847b427d40924f", "best_bid": "0.096", "best_ask": "0.113"}], "timestamp": "1769384035844", "event_type": "price_change"}}
{"_local_timestamp": "2026-01-25T23:33:56.027428+00:00", "data": {"market": "0xf829129cd05db888741ad290c786a1d71db5f8bb8493d8bc07e21b826db4d328", "price_changes": [{"asset_id": "105495516848871865829093849779907676478444075202002902600889102615883909197041", "price": "0.852", "size": "25", "side": "BUY", "hash": "4f1c82b2338cd3c6f4ade950cb182c8708e43621", "best_bid": "0.887", "best_ask": "0.904"}, {"asset_id": "90685511192998551789516562849422906363784901518167369632157413860597087715433", "price": "0.148", "size": "25", "side": "SELL", "hash": "d5102acbb3326ab96e892ea5a99557f715930ae2", "best_bid": "0.096", "best_ask": "0.113"}], "timestamp": "1769384035959", "event_type": "price_change"}}
{"_local_timestamp": "2026-01-25T23:33:57.035927+00:00", "data": {"market": "0xf829129cd05db888741ad290c786a1d71db5f8bb8493d8bc07e21b826db4d328", "price_changes": [{"asset_id": "105495516848871865829093849779907676478444075202002902600889102615883909197041", "price": "0.833", "size": "0", "side": "BUY", "hash": "529151421633c6cad9b3b1ca10ae6d6234617404", "best_bid": "0.887", "best_ask": "0.904"}, {"asset_id": "90685511192998551789516562849422906363784901518167369632157413860597087715433", "price": "0.167", "size": "0", "side": "SELL", "hash": "bafe8f9c507364305560aef4c4c97873eea1cf4e", "best_bid": "0.096", "best_ask": "0.113"}], "timestamp": "1769384036969", "event_type": "price_change"}}
{"_local_timestamp": "2026-01-25T23:33:57.064049+00:00", "data": {"market": "0xf829129cd05db888741ad290c786a1d71db5f8bb8493d8bc07e21b826db4d328", "price_changes": [{"asset_id": "105495516848871865829093849779907676478444075202002902600889102615883909197041", "price": "0.821", "size": "20", "side": "BUY", "hash": "09f35fba845ee1d05e72f166f654a4d8cd8fa240", "best_bid": "0.887", "best_ask": "0.904"}, {"asset_id": "90685511192998551789516562849422906363784901518167369632157413860597087715433", "price": "0.179", "size": "20", "side": "SELL", "hash": "92e32a8f90942179fe016de945a6af884a154c6e", "best_bid": "0.096", "best_ask": "0.113"}], "timestamp": "1769384036995", "event_type": "price_change"}}
{"_local_timestamp": "2026-01-25T23:33:57.143156+00:00", "data": {"market": "0xf829129cd05db888741ad290c786a1d71db5f8bb8493d8bc07e21b826db4d328", "price_changes": [{"asset_id": "105495516848871865829093849779907676478444075202002902600889102615883909197041", "price": "0.852", "size": "0", "side": "BUY", "hash": "2ec1b1459dcc4e8441627ae4267b44a60a5b8875", "best_bid": "0.887", "best_ask": "0.904"}, {"asset_id": "90685511192998551789516562849422906363784901518167369632157413860597087715433", "price": "0.148", "size": "0", "side": "SELL", "hash": "e7afd3bd5ce6c4cc5dde13376b14f349cb888dbb", "best_bid": "0.096", "best_ask": "0.113"}], "timestamp": "1769384037070", "event_type": "price_change"}}
{"_local_timestamp": "2026-01-25T23:33:57.165027+00:00", "data": {"market": "0xf829129cd05db888741ad290c786a1d71db5f8bb8493d8bc07e21b826db4d328", "price_changes": [{"asset_id": "105495516848871865829093849779907676478444075202002902600889102615883909197041", "price": "0.832", "size": "51", "side": "BUY", "hash": "0ce55125e825e7832a2a381d1d1e5e17e0fe9def", "best_bid": "0.887", "best_ask": "0.904"}, {"asset_id": "90685511192998551789516562849422906363784901518167369632157413860597087715433", "price": "0.168", "size": "51", "side": "SELL", "hash": "f1d7ef7d2a1cc24d049ca394b231be90abd2553f", "best_bid": "0.096", "best_ask": "0.113"}], "timestamp": "1769384037098", "event_type": "price_change"}}
{"_local_timestamp": "2026-01-25T23:33:57.173125+00:00", "data": {"market": "0xf829129cd05db888741ad290c786a1d71db5f8bb8493d8bc07e21b826db4d328", "price_changes": [{"asset_id": "105495516848871865829093849779907676478444075202002902600889102615883909197041", "price": "0.832", "size": "102", "side": "BUY", "hash": "c60f4c762c117d13881a089725fb30dc55c9a95b", "best_bid": "0.887", "best_ask": "0.904"}, {"asset_id": "90685511192998551789516562849422906363784901518167369632157413860597087715433", "price": "0.168", "size": "102", "side": "SELL", "hash": "ce747f69dd986384933164f19cf9c37722449a91", "best_bid": "0.096", "best_ask": "0.113"}], "timestamp": "1769384037105", "event_type": "price_change"}}
{"_local_timestamp": "2026-01-25T23:33:57.277288+00:00", "data": {"market": "0xf829129cd05db888741ad290c786a1d71db5f8bb8493d8bc07e21b826db4d328", "price_changes": [{"asset_id": "105495516848871865829093849779907676478444075202002902600889102615883909197041", "price": "0.832", "size": "51", "side": "BUY", "hash": "d96b8d72b8b12e4a2b22f76e32910f41bf17236d", "best_bid": "0.887", "best_ask": "0.904"}, {"asset_id": "90685511192998551789516562849422906363784901518167369632157413860597087715433", "price": "0.168", "size": "51", "side": "SELL", "hash": "69e2e0303d35b54f597ed1a2c7a3d2a861064cb2", "best_bid": "0.096", "best_ask": "0.113"}], "timestamp": "1769384037214", "event_type": "price_change"}}
{"_local_timestamp": "2026-01-25T23:33:58.498641+00:00", "data": {"market": "0xf829129cd05db888741ad290c786a1d71db5f8bb8493d8bc07e21b826db4d328", "price_changes": [{"asset_id": "105495516848871865829093849779907676478444075202002902600889102615883909197041", "price": "0.821", "size": "0", "side": "BUY", "hash": "8283093c05dd054778bd2856115aff8e9bba506c", "best_bid": "0.887", "best_ask": "0.904"}, {"asset_id": "90685511192998551789516562849422906363784901518167369632157413860597087715433", "price": "0.179", "size": "0", "side": "SELL", "hash": "a0a31f244df9a1bdd7f8d386a56f89cd460b601d", "best_bid": "0.096", "best_ask": "0.113"}], "timestamp": "1769384038424", "event_type": "price_change"}}
{"_local_timestamp": "2026-01-25T23:33:58.515943+00:00", "data": {"market": "0xf829129cd05db888741ad290c786a1d71db5f8bb8493d8bc07e21b826db4d328", "price_changes": [{"asset_id": "105495516848871865829093849779907676478444075202002902600889102615883909197041", "price": "0.833", "size": "20", "side": "BUY", "hash": "cf57e7acfa1572154ea6ad6eb4a305226ea12bf6", "best_bid": "0.887", "best_ask": "0.904"}, {"asset_id": "90685511192998551789516562849422906363784901518167369632157413860597087715433", "price": "0.167", "size": "20", "side": "SELL", "hash": "3d11ee86ec9227f24b0a4ffeab150285110d2b88", "best_bid": "0.096", "best_ask": "0.113"}], "timestamp": "1769384038449", "event_type": "price_change"}}
{"_local_timestamp": "2026-01-25T23:33:58.593459+00:00", "data": {"market": "0xf829129cd05db888741ad290c786a1d71db5f8bb8493d8bc07e21b826db4d328", "price_changes": [{"asset_id": "105495516848871865829093849779907676478444075202002902600889102615883909197041", "price": "0.832", "size": "0", "side": "BUY", "hash": "f41a4570e80cf8058f190d4114b5d325a5442e76", "best_bid": "0.887", "best_ask": "0.904"}, {"asset_id": "90685511192998551789516562849422906363784901518167369632157413860597087715433", "price": "0.168", "size": "0", "side": "SELL", "hash": "367f57113afcda92cf65445c273dd3df9b955470", "best_bid": "0.096", "best_ask": "0.113"}], "timestamp": "1769384038528", "event_type": "price_change"}}
{"_local_timestamp": "2026-01-25T23:33:58.622097+00:00", "data": {"market": "0xf829129cd05db888741ad290c786a1d71db5f8bb8493d8bc07e21b826db4d328", "price_changes": [{"asset_id": "105495516848871865829093849779907676478444075202002902600889102615883909197041", "price": "0.852", "size": "25", "side": "BUY", "hash": "ae5d1d9682c13ad0ba7f7a7e4704bc5b99940f7b", "best_bid": "0.887", "best_ask": "0.904"}, {"asset_id": "90685511192998551789516562849422906363784901518167369632157413860597087715433", "price": "0.148", "size": "25", "side": "SELL", "hash": "e0d486c28831759e6ba3d58d4d08193af0d2d799", "best_bid": "0.096", "best_ask": "0.113"}], "timestamp": "1769384038559", "event_type": "price_change"}}
{"_local_timestamp": "2026-01-25T23:33:58.696628+00:00", "data": {"market": "0xf829129cd05db888741ad290c786a1d71db5f8bb8493d8bc07e21b826db4d328", "price_changes": [{"asset_id": "105495516848871865829093849779907676478444075202002902600889102615883909197041", "price": "0.852", "size": "50", "side": "BUY", "hash": "6f9b556c8fe5fe532e08baa24debbbb6f5b8ef2e", "best_bid": "0.887", "best_ask": "0.904"}, {"asset_id": "90685511192998551789516562849422906363784901518167369632157413860597087715433", "price": "0.148", "size": "50", "side": "SELL", "hash": "727cc085a1a6b875b6502212272e08155bac6ecb", "best_bid": "0.096", "best_ask": "0.113"}], "timestamp": "1769384038622", "event_type": "price_change"}}
{"_local_timestamp": "2026-01-25T23:33:58.770345+00:00", "data": {"market": "0xc24eb4117f0afd9c6f7d7d141500ef960e472a04baab50b1645ea2147d6d82cf", "price_changes": [{"asset_id": "14668335989719155721356955488155430077949621963536264077024658800820273637531", "price": "0.471", "size": "0", "side": "BUY", "hash": "ec726209757aa48495d21029d832c6e478c1bfcc", "best_bid": "0.975", "best_ask": "0.983"}, {"asset_id": "84756279960216148559351094969736065857910692755202009808624524112488209810204", "price": "0.529", "size": "0", "side": "SELL", "hash": "e4573fbf8ff1628e4da472bb766ba5dec7ee410a", "best_bid": "0.017", "best_ask": "0.025"}], "timestamp": "1769384038698", "event_type": "price_change"}}
{"_local_timestamp": "2026-01-25T23:33:58.811507+00:00", "data": {"market": "0xf829129cd05db888741ad290c786a1d71db5f8bb8493d8bc07e21b826db4d328", "price_changes": [{"asset_id": "105495516848871865829093849779907676478444075202002902600889102615883909197041", "price": "0.852", "size": "25", "side": "BUY", "hash": "e4d44c60194ca2bab3c3c161f7c61c4bbcbb05b8", "best_bid": "0.887", "best_ask": "0.904"}, {"asset_id": "90685511192998551789516562849422906363784901518167369632157413860597087715433", "price": "0.148", "size": "25", "side": "SELL", "hash": "deeeecdfaf6e2c128af2d7b351203995e6023518", "best_bid": "0.096", "best_ask": "0.113"}], "timestamp": "1769384038745", "event_type": "price_change"}}
{"_local_timestamp": "2026-01-25T23:33:58.941186+00:00", "data": {"market": "0xc24eb4117f0afd9c6f7d7d141500ef960e472a04baab50b1645ea2147d6d82cf", "price_changes": [{"asset_id": "14668335989719155721356955488155430077949621963536264077024658800820273637531", "price": "0.484", "size": "3937", "side": "BUY", "hash": "969b097b9e2cd6b39ae6b3334137f6401368d3d9", "best_bid": "0.975", "best_ask": "0.983"}, {"asset_id": "84756279960216148559351094969736065857910692755202009808624524112488209810204", "price": "0.516", "size": "3937", "side": "SELL", "hash": "81fc72cc91a84030ae327135aa2acce1714b3aa0", "best_bid": "0.017", "best_ask": "0.025"}], "timestamp": "1769384038868", "event_type": "price_change"}}
{"_local_timestamp": "2026-01-25T23:33:59.010277+00:00", "data": {"market": "0xc24eb4117f0afd9c6f7d7d141500ef960e472a04baab50b1645ea2147d6d82cf", "price_changes": [{"asset_id": "14668335989719155721356955488155430077949621963536264077024658800820273637531", "price": "0.482", "size": "40", "side": "BUY", "hash": "585167661a1fa33851dfd29afb9cbaa53239a90b", "best_bid": "0.975", "best_ask": "0.983"}, {"asset_id": "84756279960216148559351094969736065857910692755202009808624524112488209810204", "price": "0.518", "size": "40", "side": "SELL", "hash": "c1ced584803705d21f6c6418c446e9b183fb039a", "best_bid": "0.017", "best_ask": "0.025"}], "timestamp": "1769384038943", "event_type": "price_change"}}
{"_local_timestamp": "2026-01-25T23:33:59.107771+00:00", "data": {"market": "0xc24eb4117f0afd9c6f7d7d141500ef960e472a04baab50b1645ea2147d6d82cf", "price_changes": [{"asset_id": "14668335989719155721356955488155430077949621963536264077024658800820273637531", "price": "0.485", "size": "412", "side": "BUY", "hash": "2b3ae20b2bc9fcfb568d3c2c38614f17277f7520", "best_bid": "0.975", "best_ask": "0.983"}, {"asset_id": "84756279960216148559351094969736065857910692755202009808624524112488209810204", "price": "0.515", "size": "412", "side": "SELL", "hash": "9c6af6dc84f6a0d0b0796c47f1145ca610c13125", "best_bid": "0.017", "best_ask": "0.025"}], "timestamp": "1769384039032", "event_type": "price_change"}}
{"_local_timestamp": "2026-01-25T23:33:59.112768+00:00", "data": {"market": "0xc24eb4117f0afd9c6f7d7d141500ef960e472a04baab50b1645ea2147d6d82cf", "price_changes": [{"asset_id": "14668335989719155721356955488155430077949621963536264077024658800820273637531", "price": "0.483", "size": "414", "side": "BUY", "hash": "2ba8a370a8eea12a2e8f95a4e961b032a3c905ce", "best_bid": "0.975", "best_ask": "0.983"}, {"asset_id": "84756279960216148559351094969736065857910692755202009808624524112488209810204", "price": "0.517", "size": "414", "side": "SELL", "hash": "16f311e24ecf4818ec558745decc4f814a4320b0", "best_bid": "0.017", "best_ask": "0.025"}], "timestamp": "1769384039043", "event_type": "price_change"}}
{"_local_timestamp": "2026-01-25T23:33:59.121551+00:00", "data": {"market": "0xc24eb4117f0afd9c6f7d7d141500ef960e472a04baab50b1645ea2147d6d82cf", "price_changes": [{"asset_id": "14668335989719155721356955488155430077949621963536264077024658800820273637531", "price": "0.483", "size": "0", "side": "BUY", "hash": "5d3d00ee4caf80ca57d897d4c6ffabd9db71f4ca", "best_bid": "0.975", "best_ask": "0.983"}, {"asset_id": "84756279960216148559351094969736065857910692755202009808624524112488209810204", "price": "0.517", "size": "0", "side": "SELL", "hash": "da6637efcb06763e224e12216467f0a66b3edb3a", "best_bid": "0.017", "best_ask": "0.025"}], "timestamp": "1769384039049", "event_type": "price_change"}}
{"_local_timestamp": "2026-01-25T23:33:59.133157+00:00", "data": {"market": "0xdf4e0e5a4825e829490808d950849cc1350263c38aeafaa7ef9207fd61fb0ad8", "price_changes": [{"asset_id": "83810221696024064577133768191341496793714910843496960551410909910739617026704", "price": "0.194", "size": "250", "side": "BUY", "hash": "9be0bfbc1c7d83fb76b83cfe41a32f85105fe127", "best_bid": "0.907", "best_ask": "0.938"}, {"asset_id": "57077847438061429385815585675632165160097486485394403036399997772083935128934", "price": "0.806", "size": "250", "side": "SELL", "hash": "b81a82b4093383e7b28898320ed984ed7230fc36", "best_bid": "0.062", "best_ask": "0.093"}], "timestamp": "1769384039066", "event_type": "price_change"}}
{"_local_timestamp": "2026-01-25T23:33:59.294928+00:00", "data": {"market": "0xdf4e0e5a4825e829490808d950849cc1350263c38aeafaa7ef9207fd61fb0ad8", "price_changes": [{"asset_id": "83810221696024064577133768191341496793714910843496960551410909910739617026704", "price": "0.195", "size": "3894.67", "side": "BUY", "hash": "6e6ae021079ee2db3f7da7fcb2fdcd84fb0f0fe2", "best_bid": "0.907", "best_ask": "0.938"}, {"asset_id": "57077847438061429385815585675632165160097486485394403036399997772083935128934", "price": "0.805", "size": "3894.67", "side": "SELL", "hash": "b67915844f78b9d9d8e890bb762c444b73e331fb", "best_bid": "0.062", "best_ask": "0.093"}], "timestamp": "1769384039230", "event_type": "price_change"}}
{"_local_timestamp": "2026-01-25T23:33:59.309156+00:00", "data": {"market": "0xc24eb4117f0afd9c6f7d7d141500ef960e472a04baab50b1645ea2147d6d82cf", "price_changes": [{"asset_id": "14668335989719155721356955488155430077949621963536264077024658800820273637531", "price": "0.485", "size": "824", "side": "BUY", "hash": "80ba8ccd7cb978452655a4267f18fd7364c04129", "best_bid": "0.975", "best_ask": "0.983"}, {"asset_id": "84756279960216148559351094969736065857910692755202009808624524112488209810204", "price": "0.515", "size": "824", "side": "SELL", "hash": "c7dcbe77d0170aa09ca3520da7e9357ef63a65b3", "best_bid": "0.017", "best_ask": "0.025"}], "timestamp": "1769384039235", "event_type": "price_change"}}
{"_local_timestamp": "2026-01-25T23:33:59.413705+00:00", "data": {"market": "0xf829129cd05db888741ad290c786a1d71db5f8bb8493d8bc07e21b826db4d328", "price_changes": [{"asset_id": "105495516848871865829093849779907676478444075202002902600889102615883909197041", "price": "0.833", "size": "0", "side": "BUY", "hash": "744f6b54686b09a4d4e2bc29d586fb07f2ccd318", "best_bid": "0.887", "best_ask": "0.904"}, {"asset_id": "90685511192998551789516562849422906363784901518167369632157413860597087715433", "price": "0.167", "size": "0", "side": "SELL", "hash": "0cb9f6c9ca13c8779ca74f0b376a79f30736b4b8", "best_bid": "0.096", "best_ask": "0.113"}], "timestamp": "1769384039347", "event_type": "price_change"}}
{"_local_timestamp": "2026-01-25T23:33:59.440418+00:00", "data": {"market": "0xf829129cd05db888741ad290c786a1d71db5f8bb8493d8bc07e21b826db4d328", "price_changes": [{"asset_id": "105495516848871865829093849779907676478444075202002902600889102615883909197041", "price": "0.821", "size": "20", "side": "BUY", "hash": "6d51ffb9de996a31f8ef58bd72ba58fb56cf379a", "best_bid": "0.887", "best_ask": "0.904"}, {"asset_id": "90685511192998551789516562849422906363784901518167369632157413860597087715433", "price": "0.179", "size": "20", "side": "SELL", "hash": "ae97c10d1902f9b081d678e3fe9a3a6933b25726", "best_bid": "0.096", "best_ask": "0.113"}], "timestamp": "1769384039374", "event_type": "price_change"}}
{"_local_timestamp": "2026-01-25T23:33:59.519534+00:00", "data": {"market": "0xf829129cd05db888741ad290c786a1d71db5f8bb8493d8bc07e21b826db4d328", "price_changes": [{"asset_id": "105495516848871865829093849779907676478444075202002902600889102615883909197041", "price": "0.852", "size": "0", "side": "BUY", "hash": "0be0f73f9dc0813800e8d01e77b150994c141194", "best_bid": "0.887", "best_ask": "0.904"}, {"asset_id": "90685511192998551789516562849422906363784901518167369632157413860597087715433", "price": "0.148", "size": "0", "side": "SELL", "hash": "62cfab23adedfd3a99888dc7dc65c3b88fec127a", "best_bid": "0.096", "best_ask": "0.113"}], "timestamp": "1769384039453", "event_type": "price_change"}}
{"_local_timestamp": "2026-01-25T23:33:59.555561+00:00", "data": {"market": "0xf829129cd05db888741ad290c786a1d71db5f8bb8493d8bc07e21b826db4d328", "price_changes": [{"asset_id": "105495516848871865829093849779907676478444075202002902600889102615883909197041", "price": "0.832", "size": "51", "side": "BUY", "hash": "8439c8d5de460ce4e78bcb593da57568a1466322", "best_bid": "0.887", "best_ask": "0.904"}, {"asset_id": "90685511192998551789516562849422906363784901518167369632157413860597087715433", "price": "0.168", "size": "51", "side": "SELL", "hash": "17d657f914447ab8689a4fe720f7cf2bbcc65a61", "best_bid": "0.096", "best_ask": "0.113"}], "timestamp": "1769384039485", "event_type": "price_change"}}
{"_local_timestamp": "2026-01-25T23:33:59.783658+00:00", "data": {"market": "0x28123eb9eff2b8939327a7c4cda4f4b248579a46e988ac5ff1c78289bc270f4a", "price_changes": [{"asset_id": "104728087695427500082120491580204426891505246697057675663586272922687336585193", "price": "0.216", "size": "200", "side": "BUY", "hash": "eb8e6b131e6abb2f5b95b317496f081bd966e57e", "best_bid": "0.942", "best_ask": "0.973"}, {"asset_id": "89418427142329680204104945771724971195245381529529701350965460000652874020293", "price": "0.784", "size": "200", "side": "SELL", "hash": "55d9992642e479093573190e6ee118c8ccab11c1", "best_bid": "0.027", "best_ask": "0.058"}], "timestamp": "1769384039713", "event_type": "price_change"}}
{"_local_timestamp": "2026-01-25T23:33:59.867001+00:00", "data": {"market": "0xf829129cd05db888741ad290c786a1d71db5f8bb8493d8bc07e21b826db4d328", "price_changes": [{"asset_id": "105495516848871865829093849779907676478444075202002902600889102615883909197041", "price": "0.821", "size": "0", "side": "BUY", "hash": "a2f3696cf7e21627e7051b420b44ebc51a12e3a5", "best_bid": "0.887", "best_ask": "0.904"}, {"asset_id": "90685511192998551789516562849422906363784901518167369632157413860597087715433", "price": "0.179", "size": "0", "side": "SELL", "hash": "b062d4f6b9ec3b45f98bbaeac00ce856b44222a0", "best_bid": "0.096", "best_ask": "0.113"}], "timestamp": "1769384039801", "event_type": "price_change"}}
{"_local_timestamp": "2026-01-25T23:33:59.898463+00:00", "data": {"market": "0xf829129cd05db888741ad290c786a1d71db5f8bb8493d8bc07e21b826db4d328", "price_changes": [{"asset_id": "105495516848871865829093849779907676478444075202002902600889102615883909197041", "price": "0.833", "size": "20", "side": "BUY", "hash": "8411faf253fc20879866dfbc71a1dccea29487fd", "best_bid": "0.887", "best_ask": "0.904"}, {"asset_id": "90685511192998551789516562849422906363784901518167369632157413860597087715433", "price": "0.167", "size": "20", "side": "SELL", "hash": "43f27a625f4b82899ba04167b0dc1ff2e894242a", "best_bid": "0.096", "best_ask": "0.113"}], "timestamp": "1769384039827", "event_type": "price_change"}}
{"_local_timestamp": "2026-01-25T23:33:59.902485+00:00", "data": {"market": "0xf829129cd05db888741ad290c786a1d71db5f8bb8493d8bc07e21b826db4d328", "price_changes": [{"asset_id": "105495516848871865829093849779907676478444075202002902600889102615883909197041", "price": "0.832", "size": "102", "side": "BUY", "hash": "2a4245cf934846d6b333932da391c1126c08d7f9", "best_bid": "0.887", "best_ask": "0.904"}, {"asset_id": "90685511192998551789516562849422906363784901518167369632157413860597087715433", "price": "0.168", "size": "102", "side": "SELL", "hash": "d6327f0125ba9e91c708fabe4198e5da7c0ad906", "best_bid": "0.096", "best_ask": "0.113"}], "timestamp": "1769384039827", "event_type": "price_change"}}
{"_local_timestamp": "2026-01-25T23:33:59.953706+00:00", "data": {"market": "0x28123eb9eff2b8939327a7c4cda4f4b248579a46e988ac5ff1c78289bc270f4a", "price_changes": [{"asset_id": "104728087695427500082120491580204426891505246697057675663586272922687336585193", "price": "0.218", "size": "3455", "side": "BUY", "hash": "87b4986dee37c4520fd5a99c0200521fdff3fd07", "best_bid": "0.942", "best_ask": "0.973"}, {"asset_id": "89418427142329680204104945771724971195245381529529701350965460000652874020293", "price": "0.782", "size": "3455", "side": "SELL", "hash": "b42b202ac9d933f42b155e5a947cb897adc19d2d", "best_bid": "0.027", "best_ask": "0.058"}], "timestamp": "1769384039886", "event_type": "price_change"}}
{"_local_timestamp": "2026-01-25T23:33:59.979344+00:00", "data": {"market": "0xf829129cd05db888741ad290c786a1d71db5f8bb8493d8bc07e21b826db4d328", "price_changes": [{"asset_id": "105495516848871865829093849779907676478444075202002902600889102615883909197041", "price": "0.832", "size": "51", "side": "BUY", "hash": "2d6f92faa20a906e11fd3254d6af0b848cb7bef4", "best_bid": "0.887", "best_ask": "0.904"}, {"asset_id": "90685511192998551789516562849422906363784901518167369632157413860597087715433", "price": "0.168", "size": "51", "side": "SELL", "hash": "3bf4d1483e8ec17054b64d731cd5ac9106bb4f30", "best_bid": "0.096", "best_ask": "0.113"}], "timestamp": "1769384039907", "event_type": "price_change"}}
{"_local_timestamp": "2026-01-25T23:33:59.998702+00:00", "data": {"market": "0xf829129cd05db888741ad290c786a1d71db5f8bb8493d8bc07e21b826db4d328", "price_changes": [{"asset_id": "105495516848871865829093849779907676478444075202002902600889102615883909197041", "price": "0.832", "size": "0", "side": "BUY", "hash": "21122f83f1dd4ebac05a13c1bf8deb8a382767f7", "best_bid": "0.887", "best_ask": "0.904"}, {"asset_id": "90685511192998551789516562849422906363784901518167369632157413860597087715433", "price": "0.168", "size": "0", "side": "SELL", "hash": "a8038e287213b02a4f82e7526fe2308d8debb333", "best_bid": "0.096", "best_ask": "0.113"}], "timestamp": "1769384039932", "event_type": "price_change"}}
{"_local_timestamp": "2026-01-25T23:34:00.094600+00:00", "data": {"market": "0x3acc06a95895e69efeeaae4dfdce738b91702c94556b230208b4f0438be8e4e5", "price_changes": [{"asset_id": "21289083487946615228722872362957627606235323101425284673989025264460245605601", "price": "0.81", "size": "286", "side": "BUY", "hash": "d3b3ba85acf86d2533f8fdf83d450c477563635e", "best_bid": "0.82", "best_ask": "0.84"}, {"asset_id": "83704131174101958386167453703299325546481597640863540368605877922778589412742", "price": "0.19", "size": "286", "side": "SELL", "hash": "fdf57bcc596dcd33f91dd48f440ce102ee2ca6c2", "best_bid": "0.16", "best_ask": "0.18"}], "timestamp": "1769384040003", "event_type": "price_change"}}
{"_local_timestamp": "2026-01-25T23:34:00.106377+00:00", "data": {"market": "0xf829129cd05db888741ad290c786a1d71db5f8bb8493d8bc07e21b826db4d328", "price_changes": [{"asset_id": "105495516848871865829093849779907676478444075202002902600889102615883909197041", "price": "0.852", "size": "25", "side": "BUY", "hash": "6aca2cde182f3d7c2d7d1d75ca032203976d860c", "best_bid": "0.887", "best_ask": "0.904"}, {"asset_id": "90685511192998551789516562849422906363784901518167369632157413860597087715433", "price": "0.148", "size": "25", "side": "SELL", "hash": "6a8175ab55aafa4c61bac1c09618940571b99c64", "best_bid": "0.096", "best_ask": "0.113"}], "timestamp": "1769384040012", "event_type": "price_change"}}
{"_local_timestamp": "2026-01-25T23:34:00.194557+00:00", "data": {"market": "0xf829129cd05db888741ad290c786a1d71db5f8bb8493d8bc07e21b826db4d328", "price_changes": [{"asset_id": "105495516848871865829093849779907676478444075202002902600889102615883909197041", "price": "0.374", "size": "125", "side": "BUY", "hash": "d551f02169bc0a2e8c54f4c04a20b163421243e2", "best_bid": "0.887", "best_ask": "0.904"}, {"asset_id": "90685511192998551789516562849422906363784901518167369632157413860597087715433", "price": "0.626", "size": "125", "side": "SELL", "hash": "90e776e071fb76bc55c42e5f8d3d8b567610e18e", "best_bid": "0.096", "best_ask": "0.113"}], "timestamp": "1769384040131", "event_type": "price_change"}}
{"_local_timestamp": "2026-01-25T23:34:00.392172+00:00", "data": {"market": "0xf829129cd05db888741ad290c786a1d71db5f8bb8493d8bc07e21b826db4d328", "price_changes": [{"asset_id": "105495516848871865829093849779907676478444075202002902600889102615883909197041", "price": "0.271", "size": "5093", "side": "BUY", "hash": "67d327680588193b57e8355180361efa404aab01", "best_bid": "0.887", "best_ask": "0.904"}, {"asset_id": "90685511192998551789516562849422906363784901518167369632157413860597087715433", "price": "0.729", "size": "5093", "side": "SELL", "hash": "5b04f4c4a781861ac1259c50d6c134db15eaeef8", "best_bid": "0.096", "best_ask": "0.113"}], "timestamp": "1769384040315", "event_type": "price_change"}}
{"_local_timestamp": "2026-01-25T23:34:00.586229+00:00", "data": {"market": "0x897a2f88e1b65776ac5af0440833eea638395f0af0df4bed47e83f64c9b9a1e3", "price_changes": [{"asset_id": "11824574045576628150612194967948587889530003270004521491303323671815597832573", "price": "0.24", "size": "100", "side": "BUY", "hash": "1cefd89746452f9850d05d7847dc1cbd77bd558a", "best_bid": "0.54", "best_ask": "0.56"}, {"asset_id": "67301121905355380418923087513498375592166001657797903147689423172757844806122", "price": "0.76", "size": "100", "side": "SELL", "hash": "3fd76c4dfc02657361890c2821e2de6e086733d1", "best_bid": "0.44", "best_ask": "0.46"}], "timestamp": "1769384040518", "event_type": "price_change"}}
{"_local_timestamp": "2026-01-25T23:34:00.699069+00:00", "data": {"market": "0xf829129cd05db888741ad290c786a1d71db5f8bb8493d8bc07e21b826db4d328", "price_changes": [{"asset_id": "105495516848871865829093849779907676478444075202002902600889102615883909197041", "price": "0.518", "size": "800", "side": "BUY", "hash": "bd2d2729e51f4829205b6bf2cf7a8b3225fa2019", "best_bid": "0.887", "best_ask": "0.904"}, {"asset_id": "90685511192998551789516562849422906363784901518167369632157413860597087715433", "price": "0.482", "size": "800", "side": "SELL", "hash": "594b2245d97c58afec4888045388f1fafa1c02c6", "best_bid": "0.096", "best_ask": "0.113"}], "timestamp": "1769384040631", "event_type": "price_change"}}
{"_local_timestamp": "2026-01-25T23:34:00.747668+00:00", "data": {"market": "0x897a2f88e1b65776ac5af0440833eea638395f0af0df4bed47e83f64c9b9a1e3", "price_changes": [{"asset_id": "11824574045576628150612194967948587889530003270004521491303323671815597832573", "price": "0.2", "size": "3774", "side": "BUY", "hash": "c737f15fd41628312428523c6293d1da6ad5db9c", "best_bid": "0.54", "best_ask": "0.56"}, {"asset_id": "67301121905355380418923087513498375592166001657797903147689423172757844806122", "price": "0.8", "size": "3774", "side": "SELL", "hash": "ab15bc7bd7f643d7ba915b2391db80068ebfc498", "best_bid": "0.44", "best_ask": "0.46"}], "timestamp": "1769384040684", "event_type": "price_change"}}
{"_local_timestamp": "2026-01-25T23:34:00.878273+00:00", "data": {"market": "0xf829129cd05db888741ad290c786a1d71db5f8bb8493d8bc07e21b826db4d328", "price_changes": [{"asset_id": "105495516848871865829093849779907676478444075202002902600889102615883909197041", "price": "0.518", "size": "0", "side": "BUY", "hash": "15483d3dd33382e81336cce44b52b39e590b749a", "best_bid": "0.887", "best_ask": "0.904"}, {"asset_id": "90685511192998551789516562849422906363784901518167369632157413860597087715433", "price": "0.482", "size": "0", "side": "SELL", "hash": "45b6c94f9386d5138d430d48ca05075cfc5ab70a", "best_bid": "0.096", "best_ask": "0.113"}], "timestamp": "1769384040810", "event_type": "price_change"}}
{"_local_timestamp": "2026-01-25T23:34:00.949359+00:00", "data": {"market": "0x3acc06a95895e69efeeaae4dfdce738b91702c94556b230208b4f0438be8e4e5", "price_changes": [{"asset_id": "21289083487946615228722872362957627606235323101425284673989025264460245605601", "price": "0.41", "size": "0", "side": "BUY", "hash": "2d76f9761920b91660a6aff1e1ac673be1fe7130", "best_bid": "0.82", "best_ask": "0.84"}, {"asset_id": "83704131174101958386167453703299325546481597640863540368605877922778589412742", "price": "0.59", "size": "0", "side": "SELL", "hash": "61005075881b66837b32ac9b1b3c5e36933d97e5", "best_bid": "0.16", "best_ask": "0.18"}], "timestamp": "1769384040880", "event_type": "price_change"}}
{"_local_timestamp": "2026-01-25T23:34:00.991805+00:00", "data": {"market": "0xf829129cd05db888741ad290c786a1d71db5f8bb8493d8bc07e21b826db4d328", "price_changes": [{"asset_id": "105495516848871865829093849779907676478444075202002902600889102615883909197041", "price": "0.852", "size": "50", "side": "BUY", "hash": "e56319527aab5f0cffa9621741bcdebe5e7be610", "best_bid": "0.887", "best_ask": "0.904"}, {"asset_id": "90685511192998551789516562849422906363784901518167369632157413860597087715433", "price": "0.148", "size": "50", "side": "SELL", "hash": "5c2afe74b43d44cb45a787954c529d4a04eb8487", "best_bid": "0.096", "best_ask": "0.113"}], "timestamp": "1769384040925", "event_type": "price_change"}}
{"_local_timestamp": "2026-01-25T23:34:01.002892+00:00", "data": {"market": "0xf829129cd05db888741ad290c786a1d71db5f8bb8493d8bc07e21b826db4d328", "price_changes": [{"asset_id": "105495516848871865829093849779907676478444075202002902600889102615883909197041", "price": "0.833", "size": "0", "side": "BUY", "hash": "ef20c949992a08255fa5dbe36b6b8d8bb69aa0dc", "best_bid": "0.887", "best_ask": "0.904"}, {"asset_id": "90685511192998551789516562849422906363784901518167369632157413860597087715433", "price": "0.167", "size": "0", "side": "SELL", "hash": "d96758740c7c2fdef1344510036fb8a35fd8bc1c", "best_bid": "0.096", "best_ask": "0.113"}], "timestamp": "1769384040935", "event_type": "price_change"}}
{"_local_timestamp": "2026-01-25T23:34:01.027979+00:00", "data": {"market": "0xf829129cd05db888741ad290c786a1d71db5f8bb8493d8bc07e21b826db4d328", "price_changes": [{"asset_id": "105495516848871865829093849779907676478444075202002902600889102615883909197041", "price": "0.821", "size": "20", "side": "BUY", "hash": "06e05ed813b74fc89414fce291d49e5196e3f16e", "best_bid": "0.887", "best_ask": "0.904"}, {"asset_id": "90685511192998551789516562849422906363784901518167369632157413860597087715433", "price": "0.179", "size": "20", "side": "SELL", "hash": "3e487c726bc091a5c6c8fa0095f7f56541a72a48", "best_bid": "0.096", "best_ask": "0.113"}], "timestamp": "1769384040958", "event_type": "price_change"}}
{"_local_timestamp": "2026-01-25T23:34:01.106922+00:00", "data": {"market": "0xf829129cd05db888741ad290c786a1d71db5f8bb8493d8bc07e21b826db4d328", "price_changes": [{"asset_id": "105495516848871865829093849779907676478444075202002902600889102615883909197041", "price": "0.852", "size": "25", "side": "BUY", "hash": "9f85201124bbed7fde7d43b3b5ba93f049b6cf73", "best_bid": "0.887", "best_ask": "0.904"}, {"asset_id": "90685511192998551789516562849422906363784901518167369632157413860597087715433", "price": "0.148", "size": "25", "side": "SELL", "hash": "eb69948b5db6045f1ded8bdbf67752d53798d223", "best_bid": "0.096", "best_ask": "0.113"}], "timestamp": "1769384041036", "event_type": "price_change"}}
{"_local_timestamp": "2026-01-25T23:34:01.110391+00:00", "data": {"market": "0xf829129cd05db888741ad290c786a1d71db5f8bb8493d8bc07e21b826db4d328", "price_changes": [{"asset_id": "105495516848871865829093849779907676478444075202002902600889102615883909197041", "price": "0.852", "size": "0", "side": "BUY", "hash": "72d6d132ebaf1519f9a9efdbf68aee001515800f", "best_bid": "0.887", "best_ask": "0.904"}, {"asset_id": "90685511192998551789516562849422906363784901518167369632157413860597087715433", "price": "0.148", "size": "0", "side": "SELL", "hash": "5b47601462f6f8544c1e329f3d7d4f1d1a250cfa", "best_bid": "0.096", "best_ask": "0.113"}], "timestamp": "1769384041039", "event_type": "price_change"}}
{"_local_timestamp": "2026-01-25T23:34:01.129956+00:00", "data": {"market": "0x3acc06a95895e69efeeaae4dfdce738b91702c94556b230208b4f0438be8e4e5", "price_changes": [{"asset_id": "21289083487946615228722872362957627606235323101425284673989025264460245605601", "price": "0.23", "size": "4857", "side": "BUY", "hash": "de6310ea8fecc8f7f49acd72807f498ed96a976a", "best_bid": "0.82", "best_ask": "0.84"}, {"asset_id": "83704131174101958386167453703299325546481597640863540368605877922778589412742", "price": "0.77", "size": "4857", "side": "SELL", "hash": "1a7e07f4e377a5dd9d092145e2a45300cfc3d16a", "best_bid": "0.16", "best_ask": "0.18"}], "timestamp": "1769384041050", "event_type": "price_change"}}
{"_local_timestamp": "2026-01-25T23:34:01.218237+00:00", "data": {"market": "0xf829129cd05db888741ad290c786a1d71db5f8bb8493d8bc07e21b826db4d328", "price_changes": [{"asset_id": "105495516848871865829093849779907676478444075202002902600889102615883909197041", "price": "0.832", "size": "51", "side": "BUY", "hash": "67e2830da82de1368e2eb7aaa2948c74e9a980a3", "best_bid": "0.887", "best_ask": "0.904"}, {"asset_id": "90685511192998551789516562849422906363784901518167369632157413860597087715433", "price": "0.168", "size": "51", "side": "SELL", "hash": "9f52b11ceac5c1a4fa2c87bb87dfebba360bfdfe", "best_bid": "0.096", "best_ask": "0.113"}], "timestamp": "1769384041145", "event_type": "price_change"}}
{"_local_timestamp": "2026-01-25T23:34:01.387077+00:00", "data": {"market": "0x42c5b40ce67dd7730d4bd522c2971217e4071c0a1c814ba0998fa8fa59bcfa3b", "price_changes": [{"asset_id": "27360908173410110529670070736001232422485421937616132330605471045429078161694", "price": "0.24", "size": "200", "side": "BUY", "hash": "1c0bf9305aee1f9ffdc4d009a01c24ed8455833c", "best_bid": "0.9", "best_ask": "0.92"}, {"asset_id": "81326650125094809268080637938129269014671684967955856212777724369859659142892", "price": "0.76", "size": "200", "side": "SELL", "hash": "bab54b425ca674da1bf139b4bb7f62748bb301f8", "best_bid": "0.08", "best_ask": "0.1"}], "timestamp": "1769384041292", "event_type": "price_change"}}
{"_local_timestamp": "2026-01-25T23:34:01.532277+00:00", "data": {"market": "0x42c5b40ce67dd7730d4bd522c2971217e4071c0a1c814ba0998fa8fa59bcfa3b", "price_changes": [{"asset_id": "27360908173410110529670070736001232422485421937616132330605471045429078161694", "price": "0.25", "size": "4686", "side": "BUY", "hash": "0e299a859fdc4030eecf1e0ffef5748d576cbc3a", "best_bid": "0.9", "best_ask": "0.92"}, {"asset_id": "81326650125094809268080637938129269014671684967955856212777724369859659142892", "price": "0.75", "size": "4686", "side": "SELL", "hash": "68982bddeea6a952c4b084410291378c85cdb38c", "best_bid": "0.08", "best_ask": "0.1"}], "timestamp": "1769384041462", "event_type": "price_change"}}
{"_local_timestamp": "2026-01-25T23:34:02.144025+00:00", "data": {"market": "0xf829129cd05db888741ad290c786a1d71db5f8bb8493d8bc07e21b826db4d328", "price_changes": [{"asset_id": "105495516848871865829093849779907676478444075202002902600889102615883909197041", "price": "0.821", "size": "0", "side": "BUY", "hash": "9bf7d5ce7e9e4b9646496d78fbff8b4706b59350", "best_bid": "0.887", "best_ask": "0.904"}, {"asset_id": "90685511192998551789516562849422906363784901518167369632157413860597087715433", "price": "0.179", "size": "0", "side": "SELL", "hash": "d950467cd068c6978ffcdf2f7f1628cba23edefd", "best_bid": "0.096", "best_ask": "0.113"}], "timestamp": "1769384042072", "event_type": "price_change"}}
{"_local_timestamp": "2026-01-25T23:34:02.162553+00:00", "data": {"market": "0xf829129cd05db888741ad290c786a1d71db5f8bb8493d8bc07e21b826db4d328", "price_changes": [{"asset_id": "105495516848871865829093849779907676478444075202002902600889102615883909197041", "price": "0.833", "size": "20", "side": "BUY", "hash": "e2f4e3212319d78266a25444520d646127cf5634", "best_bid": "0.887", "best_ask": "0.904"}, {"asset_id": "90685511192998551789516562849422906363784901518167369632157413860597087715433", "price": "0.167", "size": "20", "side": "SELL", "hash": "2a8f1dc078a009025674fa284ee0fa26a8e191ca", "best_bid": "0.096", "best_ask": "0.113"}], "timestamp": "1769384042098", "event_type": "price_change"}}
{"_local_timestamp": "2026-01-25T23:34:02.259651+00:00", "data": {"market": "0xf829129cd05db888741ad290c786a1d71db5f8bb8493d8bc07e21b826db4d328", "price_changes": [{"asset_id": "105495516848871865829093849779907676478444075202002902600889102615883909197041", "price": "0.832", "size": "102", "side": "BUY", "hash": "5042bec55c440981a62cfde4cba2dc866a3bcbfa", "best_bid": "0.887", "best_ask": "0.904"}, {"asset_id": "90685511192998551789516562849422906363784901518167369632157413860597087715433", "price": "0.168", "size": "102", "side": "SELL", "hash": "2a874ccc83ce3c96c67e05b273548fcf3229a830", "best_bid": "0.096", "best_ask": "0.113"}], "timestamp": "1769384042194", "event_type": "price_change"}}
{"_local_timestamp": "2026-01-25T23:34:02.273710+00:00", "data": {"market": "0xf829129cd05db888741ad290c786a1d71db5f8bb8493d8bc07e21b826db4d328", "price_changes": [{"asset_id": "105495516848871865829093849779907676478444075202002902600889102615883909197041", "price": "0.832", "size": "51", "side": "BUY", "hash": "421a8f86f3a700a575a3bb57d33fa46aaa0f3bc8", "best_bid": "0.887", "best_ask": "0.904"}, {"asset_id": "90685511192998551789516562849422906363784901518167369632157413860597087715433", "price": "0.168", "size": "51", "side": "SELL", "hash": "a1e6fe59344823213fa9ae966ffa3eee4a01160e", "best_bid": "0.096", "best_ask": "0.113"}], "timestamp": "1769384042206", "event_type": "price_change"}}
{"_local_timestamp": "2026-01-25T23:34:02.274692+00:00", "data": {"market": "0xf829129cd05db888741ad290c786a1d71db5f8bb8493d8bc07e21b826db4d328", "price_changes": [{"asset_id": "105495516848871865829093849779907676478444075202002902600889102615883909197041", "price": "0.852", "size": "25", "side": "BUY", "hash": "f69082f88bed666a8e52a37edecc6f61310205b9", "best_bid": "0.887", "best_ask": "0.904"}, {"asset_id": "90685511192998551789516562849422906363784901518167369632157413860597087715433", "price": "0.148", "size": "25", "side": "SELL", "hash": "325116825d39f7c9644035c74255dfbc0bd98692", "best_bid": "0.096", "best_ask": "0.113"}], "timestamp": "1769384042207", "event_type": "price_change"}}
{"_local_timestamp": "2026-01-25T23:34:02.398647+00:00", "data": {"market": "0xf829129cd05db888741ad290c786a1d71db5f8bb8493d8bc07e21b826db4d328", "price_changes": [{"asset_id": "105495516848871865829093849779907676478444075202002902600889102615883909197041", "price": "0.832", "size": "0", "side": "BUY", "hash": "a7e88eb1e92eac41f6e2f9b4a4d63cafd482959a", "best_bid": "0.887", "best_ask": "0.904"}, {"asset_id": "90685511192998551789516562849422906363784901518167369632157413860597087715433", "price": "0.168", "size": "0", "side": "SELL", "hash": "7cdb89fadd1ba9b0488b73583a517fb4af165d21", "best_bid": "0.096", "best_ask": "0.113"}], "timestamp": "1769384042326", "event_type": "price_change"}}
{"_local_timestamp": "2026-01-25T23:34:03.378470+00:00", "data": {"market": "0xf829129cd05db888741ad290c786a1d71db5f8bb8493d8bc07e21b826db4d328", "price_changes": [{"asset_id": "105495516848871865829093849779907676478444075202002902600889102615883909197041", "price": "0.833", "size": "0", "side": "BUY", "hash": "0ccc13eb21feb8c3f0253d43822ecda223ef1db3", "best_bid": "0.887", "best_ask": "0.904"}, {"asset_id": "90685511192998551789516562849422906363784901518167369632157413860597087715433", "price": "0.167", "size": "0", "side": "SELL", "hash": "0e522f5e309c3c484b81afe75f3c588a01a6317b", "best_bid": "0.096", "best_ask": "0.113"}], "timestamp": "1769384043278", "event_type": "price_change"}}
{"_local_timestamp": "2026-01-25T23:34:03.387105+00:00", "data": {"market": "0xf829129cd05db888741ad290c786a1d71db5f8bb8493d8bc07e21b826db4d328", "price_changes": [{"asset_id": "105495516848871865829093849779907676478444075202002902600889102615883909197041", "price": "0.821", "size": "20", "side": "BUY", "hash": "63b66d3db07e2a9b2191f2533f332e74533f0dd3", "best_bid": "0.887", "best_ask": "0.904"}, {"asset_id": "90685511192998551789516562849422906363784901518167369632157413860597087715433", "price": "0.179", "size": "20", "side": "SELL", "hash": "e56116d89a1d66c4148cee2140b631252faa0540", "best_bid": "0.096", "best_ask": "0.113"}], "timestamp": "1769384043303", "event_type": "price_change"}}
{"_local_timestamp": "2026-01-25T23:34:03.479858+00:00", "data": {"market": "0xf829129cd05db888741ad290c786a1d71db5f8bb8493d8bc07e21b826db4d328", "price_changes": [{"asset_id": "105495516848871865829093849779907676478444075202002902600889102615883909197041", "price": "0.852", "size": "0", "side": "BUY", "hash": "a119351e30e40bbc774fc2a6ce3f70746cdf2c43", "best_bid": "0.887", "best_ask": "0.904"}, {"asset_id": "90685511192998551789516562849422906363784901518167369632157413860597087715433", "price": "0.148", "size": "0", "side": "SELL", "hash": "55d6bf886aed4a544a18181f3df94b08c973a793", "best_bid": "0.096", "best_ask": "0.113"}], "timestamp": "1769384043414", "event_type": "price_change"}}
{"_local_timestamp": "2026-01-25T23:34:03.498140+00:00", "data": {"market": "0xf829129cd05db888741ad290c786a1d71db5f8bb8493d8bc07e21b826db4d328", "price_changes": [{"asset_id": "105495516848871865829093849779907676478444075202002902600889102615883909197041", "price": "0.832", "size": "51", "side": "BUY", "hash": "14b07c1dbfcefc4a9e0dc7bae6bb380a0cdbaeb4", "best_bid": "0.887", "best_ask": "0.904"}, {"asset_id": "90685511192998551789516562849422906363784901518167369632157413860597087715433", "price": "0.168", "size": "51", "side": "SELL", "hash": "ba25486a53f6440b4d494c3d87979bf5b5b0f97b", "best_bid": "0.096", "best_ask": "0.113"}], "timestamp": "1769384043434", "event_type": "price_change"}}
{"_local_timestamp": "2026-01-25T23:34:03.512528+00:00", "data": {"market": "0xf829129cd05db888741ad290c786a1d71db5f8bb8493d8bc07e21b826db4d328", "price_changes": [{"asset_id": "105495516848871865829093849779907676478444075202002902600889102615883909197041", "price": "0.852", "size": "25", "side": "BUY", "hash": "d1c485424a5618f8b2aec701a2592e9590cc828d", "best_bid": "0.887", "best_ask": "0.904"}, {"asset_id": "90685511192998551789516562849422906363784901518167369632157413860597087715433", "price": "0.148", "size": "25", "side": "SELL", "hash": "88c3d8ca3511a89232bf64eca666b0e324ab8aac", "best_bid": "0.096", "best_ask": "0.113"}], "timestamp": "1769384043446", "event_type": "price_change"}}
{"_local_timestamp": "2026-01-25T23:34:03.618506+00:00", "data": {"market": "0xf829129cd05db888741ad290c786a1d71db5f8bb8493d8bc07e21b826db4d328", "price_changes": [{"asset_id": "105495516848871865829093849779907676478444075202002902600889102615883909197041", "price": "0.852", "size": "0", "side": "BUY", "hash": "75fbcb4ba29c6ea30258b43a45f409f5bb416350", "best_bid": "0.887", "best_ask": "0.904"}, {"asset_id": "90685511192998551789516562849422906363784901518167369632157413860597087715433", "price": "0.148", "size": "0", "side": "SELL", "hash": "db93c1ddeea2c83b36abe588f61dc9749ac44df3", "best_bid": "0.096", "best_ask": "0.113"}], "timestamp": "1769384043552", "event_type": "price_change"}}
{"_local_timestamp": "2026-01-25T23:34:04.750038+00:00", "data": {"market": "0xf829129cd05db888741ad290c786a1d71db5f8bb8493d8bc07e21b826db4d328", "price_changes": [{"asset_id": "105495516848871865829093849779907676478444075202002902600889102615883909197041", "price": "0.821", "size": "0", "side": "BUY", "hash": "22f08f54a4d834410b11d1a06d3697ea8338d5c4", "best_bid": "0.887", "best_ask": "0.904"}, {"asset_id": "90685511192998551789516562849422906363784901518167369632157413860597087715433", "price": "0.179", "size": "0", "side": "SELL", "hash": "d1981a47d0e05e1ccab639f5875e0fce5a411771", "best_bid": "0.096", "best_ask": "0.113"}], "timestamp": "1769384044687", "event_type": "price_change"}}
{"_local_timestamp": "2026-01-25T23:34:04.780197+00:00", "data": {"market": "0xf829129cd05db888741ad290c786a1d71db5f8bb8493d8bc07e21b826db4d328", "price_changes": [{"asset_id": "105495516848871865829093849779907676478444075202002902600889102615883909197041", "price": "0.833", "size": "20", "side": "BUY", "hash": "49a5795e77835318df1bec4c6b66e717e057e54f", "best_bid": "0.887", "best_ask": "0.904"}, {"asset_id": "90685511192998551789516562849422906363784901518167369632157413860597087715433", "price": "0.167", "size": "20", "side": "SELL", "hash": "f4d6f169b63f187c78f7883ece4da295223830bf", "best_bid": "0.096", "best_ask": "0.113"}], "timestamp": "1769384044710", "event_type": "price_change"}}
{"_local_timestamp": "2026-01-25T23:34:04.904815+00:00", "data": {"market": "0xf829129cd05db888741ad290c786a1d71db5f8bb8493d8bc07e21b826db4d328", "price_changes": [{"asset_id": "105495516848871865829093849779907676478444075202002902600889102615883909197041", "price": "0.832", "size": "0", "side": "BUY", "hash": "47a06e2fcbc52bb65f6bfef3559cbc9c139e91ba", "best_bid": "0.887", "best_ask": "0.904"}, {"asset_id": "90685511192998551789516562849422906363784901518167369632157413860597087715433", "price": "0.168", "size": "0", "side": "SELL", "hash": "35a362698efaab3d39de6ea1d4103f6583412bda", "best_bid": "0.096", "best_ask": "0.113"}], "timestamp": "1769384044835", "event_type": "price_change"}}
{"_local_timestamp": "2026-01-25T23:34:04.918040+00:00", "data": {"market": "0xf829129cd05db888741ad290c786a1d71db5f8bb8493d8bc07e21b826db4d328", "price_changes": [{"asset_id": "105495516848871865829093849779907676478444075202002902600889102615883909197041", "price": "0.832", "size": "51", "side": "BUY", "hash": "1f3201626ad6deddb9f127aac212e71b293834c3", "best_bid": "0.887", "best_ask": "0.904"}, {"asset_id": "90685511192998551789516562849422906363784901518167369632157413860597087715433", "price": "0.168", "size": "51", "side": "SELL", "hash": "fd62b7d4cba17c35eab7124d8b625aae878f9857", "best_bid": "0.096", "best_ask": "0.113"}], "timestamp": "1769384044839", "event_type": "price_change"}}
{"_local_timestamp": "2026-01-25T23:34:04.977844+00:00", "data": {"market": "0xf829129cd05db888741ad290c786a1d71db5f8bb8493d8bc07e21b826db4d328", "price_changes": [{"asset_id": "105495516848871865829093849779907676478444075202002902600889102615883909197041", "price": "0.852", "size": "25", "side": "BUY", "hash": "1db1a94d97babcb4f387ce84ac963bf6d77893f5", "best_bid": "0.887", "best_ask": "0.904"}, {"asset_id": "90685511192998551789516562849422906363784901518167369632157413860597087715433", "price": "0.148", "size": "25", "side": "SELL", "hash": "20eaa721020af0cd6f7c6ddfde2519eb7bd3e1c4", "best_bid": "0.096", "best_ask": "0.113"}], "timestamp": "1769384044874", "event_type": "price_change"}}
{"_local_timestamp": "2026-01-25T23:34:05.099040+00:00", "data": {"market": "0xf829129cd05db888741ad290c786a1d71db5f8bb8493d8bc07e21b826db4d328", "price_changes": [{"asset_id": "105495516848871865829093849779907676478444075202002902600889102615883909197041", "price": "0.832", "size": "0", "side": "BUY", "hash": "1822dba12e560b037698b22807bc9e1ab26aa35e", "best_bid": "0.887", "best_ask": "0.904"}, {"asset_id": "90685511192998551789516562849422906363784901518167369632157413860597087715433", "price": "0.168", "size": "0", "side": "SELL", "hash": "87203f0d67388e1f2c642ccd2b5be3456328786d", "best_bid": "0.096", "best_ask": "0.113"}], "timestamp": "1769384044945", "event_type": "price_change"}}
{"_local_timestamp": "2026-01-25T23:34:06.362736+00:00", "data": {"market": "0xf829129cd05db888741ad290c786a1d71db5f8bb8493d8bc07e21b826db4d328", "price_changes": [{"asset_id": "105495516848871865829093849779907676478444075202002902600889102615883909197041", "price": "0.833", "size": "0", "side": "BUY", "hash": "0cd665c2be9563ee4541d63d109d11603a66985c", "best_bid": "0.887", "best_ask": "0.904"}, {"asset_id": "90685511192998551789516562849422906363784901518167369632157413860597087715433", "price": "0.167", "size": "0", "side": "SELL", "hash": "9b1cd7a668a42e49ca879c465200ce2edc770b99", "best_bid": "0.096", "best_ask": "0.113"}], "timestamp": "1769384046296", "event_type": "price_change"}}
{"_local_timestamp": "2026-01-25T23:34:06.389698+00:00", "data": {"market": "0xf829129cd05db888741ad290c786a1d71db5f8bb8493d8bc07e21b826db4d328", "price_changes": [{"asset_id": "105495516848871865829093849779907676478444075202002902600889102615883909197041", "price": "0.821", "size": "20", "side": "BUY", "hash": "ab07e0af83c6e4c64c161ba16aa485922d89834f", "best_bid": "0.887", "best_ask": "0.904"}, {"asset_id": "90685511192998551789516562849422906363784901518167369632157413860597087715433", "price": "0.179", "size": "20", "side": "SELL", "hash": "2caaea91a530ffd6e73770fbe346eec27067d01d", "best_bid": "0.096", "best_ask": "0.113"}], "timestamp": "1769384046327", "event_type": "price_change"}}
{"_local_timestamp": "2026-01-25T23:34:06.495914+00:00", "data": {"market": "0xf829129cd05db888741ad290c786a1d71db5f8bb8493d8bc07e21b826db4d328", "price_changes": [{"asset_id": "105495516848871865829093849779907676478444075202002902600889102615883909197041", "price": "0.852", "size": "0", "side": "BUY", "hash": "fd2855b4d222b2f1484dbe76008ec163e8392c27", "best_bid": "0.887", "best_ask": "0.904"}, {"asset_id": "90685511192998551789516562849422906363784901518167369632157413860597087715433", "price": "0.148", "size": "0", "side": "SELL", "hash": "6b7e4915861ddda8b371219622613498866562fe", "best_bid": "0.096", "best_ask": "0.113"}], "timestamp": "1769384046428", "event_type": "price_change"}}
{"_local_timestamp": "2026-01-25T23:34:06.497644+00:00", "data": {"market": "0xf829129cd05db888741ad290c786a1d71db5f8bb8493d8bc07e21b826db4d328", "price_changes": [{"asset_id": "105495516848871865829093849779907676478444075202002902600889102615883909197041", "price": "0.852", "size": "25", "side": "BUY", "hash": "0381534fd7ea8b1019edb1873aa3717f7205267a", "best_bid": "0.887", "best_ask": "0.904"}, {"asset_id": "90685511192998551789516562849422906363784901518167369632157413860597087715433", "price": "0.148", "size": "25", "side": "SELL", "hash": "e4c33f159d25cd9206e5d5b1d4a6a4d47c0303ba", "best_bid": "0.096", "best_ask": "0.113"}], "timestamp": "1769384046429", "event_type": "price_change"}}
{"_local_timestamp": "2026-01-25T23:34:06.506063+00:00", "data": {"market": "0xf829129cd05db888741ad290c786a1d71db5f8bb8493d8bc07e21b826db4d328", "price_changes": [{"asset_id": "105495516848871865829093849779907676478444075202002902600889102615883909197041", "price": "0.832", "size": "51", "side": "BUY", "hash": "0af873967ded0cf0c6be7d7b07700ac15a90172f", "best_bid": "0.887", "best_ask": "0.904"}, {"asset_id": "90685511192998551789516562849422906363784901518167369632157413860597087715433", "price": "0.168", "size": "51", "side": "SELL", "hash": "41ca0499a99a820e9df94df5f105d40e02ae2beb", "best_bid": "0.096", "best_ask": "0.113"}], "timestamp": "1769384046440", "event_type": "price_change"}}
{"_local_timestamp": "2026-01-25T23:34:06.626727+00:00", "data": {"market": "0xf829129cd05db888741ad290c786a1d71db5f8bb8493d8bc07e21b826db4d328", "price_changes": [{"asset_id": "105495516848871865829093849779907676478444075202002902600889102615883909197041", "price": "0.852", "size": "0", "side": "BUY", "hash": "625ca490f445f12e2eea19334844ddc0186d0c5c", "best_bid": "0.887", "best_ask": "0.904"}, {"asset_id": "90685511192998551789516562849422906363784901518167369632157413860597087715433", "price": "0.148", "size": "0", "side": "SELL", "hash": "6cea32c5777779f0c86b089798785f5225feaea6", "best_bid": "0.096", "best_ask": "0.113"}], "timestamp": "1769384046563", "event_type": "price_change"}}
{"_local_timestamp": "2026-01-25T23:34:07.361981+00:00", "data": {"market": "0xf829129cd05db888741ad290c786a1d71db5f8bb8493d8bc07e21b826db4d328", "price_changes": [{"asset_id": "105495516848871865829093849779907676478444075202002902600889102615883909197041", "price": "0.821", "size": "0", "side": "BUY", "hash": "fe06d5b801b9c9c7e32d4c45efd50ecd9a61efba", "best_bid": "0.887", "best_ask": "0.904"}, {"asset_id": "90685511192998551789516562849422906363784901518167369632157413860597087715433", "price": "0.179", "size": "0", "side": "SELL", "hash": "83d5299baa0a5e49ab52ce7f95cd10d88ab59bf9", "best_bid": "0.096", "best_ask": "0.113"}], "timestamp": "1769384047297", "event_type": "price_change"}}
{"_local_timestamp": "2026-01-25T23:34:07.395501+00:00", "data": {"market": "0xf829129cd05db888741ad290c786a1d71db5f8bb8493d8bc07e21b826db4d328", "price_changes": [{"asset_id": "105495516848871865829093849779907676478444075202002902600889102615883909197041", "price": "0.833", "size": "20", "side": "BUY", "hash": "a7ee2100a4759b7d5b733cc6e96fa2ca8bc74a4e", "best_bid": "0.887", "best_ask": "0.904"}, {"asset_id": "90685511192998551789516562849422906363784901518167369632157413860597087715433", "price": "0.167", "size": "20", "side": "SELL", "hash": "1a1ce4b8e1869bc780666d616466a2a12be63cfa", "best_bid": "0.096", "best_ask": "0.113"}], "timestamp": "1769384047321", "event_type": "price_change"}}
{"_local_timestamp": "2026-01-25T23:34:07.481006+00:00", "data": {"market": "0xf829129cd05db888741ad290c786a1d71db5f8bb8493d8bc07e21b826db4d328", "price_changes": [{"asset_id": "105495516848871865829093849779907676478444075202002902600889102615883909197041", "price": "0.832", "size": "0", "side": "BUY", "hash": "f454a5d6e3be3beae36b0868eddd6ddbb1f4a9d8", "best_bid": "0.887", "best_ask": "0.904"}, {"asset_id": "90685511192998551789516562849422906363784901518167369632157413860597087715433", "price": "0.168", "size": "0", "side": "SELL", "hash": "e5889849fe034b7cfb27537fdc27c505c7eb64a9", "best_bid": "0.096", "best_ask": "0.113"}], "timestamp": "1769384047412", "event_type": "price_change"}}
{"_local_timestamp": "2026-01-25T23:34:07.517835+00:00", "data": {"market": "0xf829129cd05db888741ad290c786a1d71db5f8bb8493d8bc07e21b826db4d328", "price_changes": [{"asset_id": "105495516848871865829093849779907676478444075202002902600889102615883909197041", "price": "0.852", "size": "25", "side": "BUY", "hash": "7adf597707a31963812aef150ba5b02a9f2c1132", "best_bid": "0.887", "best_ask": "0.904"}, {"asset_id": "90685511192998551789516562849422906363784901518167369632157413860597087715433", "price": "0.148", "size": "25", "side": "SELL", "hash": "7626dea87846c5413f3e08f369db4d3b2814d59f", "best_bid": "0.096", "best_ask": "0.113"}], "timestamp": "1769384047451", "event_type": "price_change"}}
{"_local_timestamp": "2026-01-25T23:34:07.543413+00:00", "data": {"market": "0xf829129cd05db888741ad290c786a1d71db5f8bb8493d8bc07e21b826db4d328", "price_changes": [{"asset_id": "105495516848871865829093849779907676478444075202002902600889102615883909197041", "price": "0.852", "size": "50", "side": "BUY", "hash": "c22812e6357fb818465cb4afdf0480240a832cf4", "best_bid": "0.887", "best_ask": "0.904"}, {"asset_id": "90685511192998551789516562849422906363784901518167369632157413860597087715433", "price": "0.148", "size": "50", "side": "SELL", "hash": "661f791f9d7376fb6b2b7545421336369ffcbfb1", "best_bid": "0.096", "best_ask": "0.113"}], "timestamp": "1769384047471", "event_type": "price_change"}}
{"_local_timestamp": "2026-01-25T23:34:07.663859+00:00", "data": {"market": "0xf829129cd05db888741ad290c786a1d71db5f8bb8493d8bc07e21b826db4d328", "price_changes": [{"asset_id": "105495516848871865829093849779907676478444075202002902600889102615883909197041", "price": "0.852", "size": "25", "side": "BUY", "hash": "1466634d0b343f150cea410df6d402de255f3f95", "best_bid": "0.887", "best_ask": "0.904"}, {"asset_id": "90685511192998551789516562849422906363784901518167369632157413860597087715433", "price": "0.148", "size": "25", "side": "SELL", "hash": "33fb55e95116ddd9bcdcfd0bda8e96f44e90ea27", "best_bid": "0.096", "best_ask": "0.113"}], "timestamp": "1769384047597", "event_type": "price_change"}}
{"_local_timestamp": "2026-01-25T23:34:08.433832+00:00", "data": {"market": "0xf829129cd05db888741ad290c786a1d71db5f8bb8493d8bc07e21b826db4d328", "price_changes": [{"asset_id": "105495516848871865829093849779907676478444075202002902600889102615883909197041", "price": "0.833", "size": "0", "side": "BUY", "hash": "2f5ee82775778cbf0c4b662364fe40e9f49f8bfe", "best_bid": "0.887", "best_ask": "0.904"}, {"asset_id": "90685511192998551789516562849422906363784901518167369632157413860597087715433", "price": "0.167", "size": "0", "side": "SELL", "hash": "9c72e2d3b00aed3a24b11e7dfa6e82aa4bcb8ddc", "best_bid": "0.096", "best_ask": "0.113"}], "timestamp": "1769384048371", "event_type": "price_change"}}
{"_local_timestamp": "2026-01-25T23:34:08.461729+00:00", "data": {"market": "0xf829129cd05db888741ad290c786a1d71db5f8bb8493d8bc07e21b826db4d328", "price_changes": [{"asset_id": "105495516848871865829093849779907676478444075202002902600889102615883909197041", "price": "0.821", "size": "20", "side": "BUY", "hash": "47329f090db4460f016151f9b5fca803acc5813d", "best_bid": "0.887", "best_ask": "0.904"}, {"asset_id": "90685511192998551789516562849422906363784901518167369632157413860597087715433", "price": "0.179", "size": "20", "side": "SELL", "hash": "abbff94776817b8c35b144d011e27742ca8d092a", "best_bid": "0.096", "best_ask": "0.113"}], "timestamp": "1769384048396", "event_type": "price_change"}}
{"_local_timestamp": "2026-01-25T23:34:08.545539+00:00", "data": {"market": "0xf829129cd05db888741ad290c786a1d71db5f8bb8493d8bc07e21b826db4d328", "price_changes": [{"asset_id": "105495516848871865829093849779907676478444075202002902600889102615883909197041", "price": "0.852", "size": "0", "side": "BUY", "hash": "408d9fb5244cc03d77ae1f9c5ba904c52ed2c4b9", "best_bid": "0.887", "best_ask": "0.904"}, {"asset_id": "90685511192998551789516562849422906363784901518167369632157413860597087715433", "price": "0.148", "size": "0", "side": "SELL", "hash": "eb51666072e8362da10409cdf5975f60ff86aa64", "best_bid": "0.096", "best_ask": "0.113"}], "timestamp": "1769384048478", "event_type": "price_change"}}
{"_local_timestamp": "2026-01-25T23:34:08.576307+00:00", "data": {"market": "0xf829129cd05db888741ad290c786a1d71db5f8bb8493d8bc07e21b826db4d328", "price_changes": [{"asset_id": "105495516848871865829093849779907676478444075202002902600889102615883909197041", "price": "0.832", "size": "51", "side": "BUY", "hash": "4a89798b3b2b1ead3062d6d50b372ee4cdfa3678", "best_bid": "0.887", "best_ask": "0.904"}, {"asset_id": "90685511192998551789516562849422906363784901518167369632157413860597087715433", "price": "0.168", "size": "51", "side": "SELL", "hash": "44fe0bef8e839c5a72ad7ff71a79ed237cd12af9", "best_bid": "0.096", "best_ask": "0.113"}], "timestamp": "1769384048506", "event_type": "price_change"}}
{"_local_timestamp": "2026-01-25T23:34:08.586095+00:00", "data": {"market": "0xf829129cd05db888741ad290c786a1d71db5f8bb8493d8bc07e21b826db4d328", "price_changes": [{"asset_id": "105495516848871865829093849779907676478444075202002902600889102615883909197041", "price": "0.832", "size": "102", "side": "BUY", "hash": "f6f2cdbcd867eaec83825bd3322b48ecf3bcb69c", "best_bid": "0.887", "best_ask": "0.904"}, {"asset_id": "90685511192998551789516562849422906363784901518167369632157413860597087715433", "price": "0.168", "size": "102", "side": "SELL", "hash": "26593bf2526b02bc42a18f3de6586c403ffbc0aa", "best_bid": "0.096", "best_ask": "0.113"}], "timestamp": "1769384048520", "event_type": "price_change"}}
{"_local_timestamp": "2026-01-25T23:34:08.691752+00:00", "data": {"market": "0xf829129cd05db888741ad290c786a1d71db5f8bb8493d8bc07e21b826db4d328", "price_changes": [{"asset_id": "105495516848871865829093849779907676478444075202002902600889102615883909197041", "price": "0.832", "size": "51", "side": "BUY", "hash": "48adf6677091cba8bbf35c6c452f42edbbef6e16", "best_bid": "0.887", "best_ask": "0.904"}, {"asset_id": "90685511192998551789516562849422906363784901518167369632157413860597087715433", "price": "0.168", "size": "51", "side": "SELL", "hash": "6d5bf21e710c55808f4fd7d4be5dc6aee1d92d27", "best_bid": "0.096", "best_ask": "0.113"}], "timestamp": "1769384048616", "event_type": "price_change"}}
{"_local_timestamp": "2026-01-25T23:34:08.812985+00:00", "data": {"market": "0x28123eb9eff2b8939327a7c4cda4f4b248579a46e988ac5ff1c78289bc270f4a", "price_changes": [{"asset_id": "104728087695427500082120491580204426891505246697057675663586272922687336585193", "price": "0.862", "size": "0", "side": "BUY", "hash": "3cb7435e7bffe7c820e64aab5047b271127d90ec", "best_bid": "0.942", "best_ask": "0.973"}, {"asset_id": "89418427142329680204104945771724971195245381529529701350965460000652874020293", "price": "0.138", "size": "0", "side": "SELL", "hash": "1b2b0ef8ea77cf08e1a450c21d06d77e0b210cc7", "best_bid": "0.027", "best_ask": "0.058"}], "timestamp": "1769384048745", "event_type": "price_change"}}
{"_local_timestamp": "2026-01-25T23:34:08.915343+00:00", "data": {"market": "0x28123eb9eff2b8939327a7c4cda4f4b248579a46e988ac5ff1c78289bc270f4a", "price_changes": [{"asset_id": "104728087695427500082120491580204426891505246697057675663586272922687336585193", "price": "0.864", "size": "30", "side": "BUY", "hash": "7078e1c8a049f8d49466c417c35bd9ef4c7f438f", "best_bid": "0.942", "best_ask": "0.973"}, {"asset_id": "89418427142329680204104945771724971195245381529529701350965460000652874020293", "price": "0.136", "size": "30", "side": "SELL", "hash": "018bc84b3a94c048d056e695d24dd765cec5ca31", "best_bid": "0.027", "best_ask": "0.058"}], "timestamp": "1769384048839", "event_type": "price_change"}}
{"_local_timestamp": "2026-01-25T23:34:09.409513+00:00", "data": {"market": "0xf829129cd05db888741ad290c786a1d71db5f8bb8493d8bc07e21b826db4d328", "price_changes": [{"asset_id": "105495516848871865829093849779907676478444075202002902600889102615883909197041", "price": "0.821", "size": "0", "side": "BUY", "hash": "9bde9672992ecd0c7fd7aebaa33c3eacc92f31e9", "best_bid": "0.887", "best_ask": "0.904"}, {"asset_id": "90685511192998551789516562849422906363784901518167369632157413860597087715433", "price": "0.179", "size": "0", "side": "SELL", "hash": "775ca394c0d6906b695d7deb853e1cad7bde6539", "best_bid": "0.096", "best_ask": "0.113"}], "timestamp": "1769384049346", "event_type": "price_change"}}
{"_local_timestamp": "2026-01-25T23:34:09.433968+00:00", "data": {"market": "0xf829129cd05db888741ad290c786a1d71db5f8bb8493d8bc07e21b826db4d328", "price_changes": [{"asset_id": "105495516848871865829093849779907676478444075202002902600889102615883909197041", "price": "0.833", "size": "20", "side": "BUY", "hash": "6e0d82e9b62b59db9b97a5a0655f828eb56226b2", "best_bid": "0.887", "best_ask": "0.904"}, {"asset_id": "90685511192998551789516562849422906363784901518167369632157413860597087715433", "price": "0.167", "size": "20", "side": "SELL", "hash": "d59bfe844a7b651db1f23e0eb6b3d4b4212e0468", "best_bid": "0.096", "best_ask": "0.113"}], "timestamp": "1769384049370", "event_type": "price_change"}}
{"_local_timestamp": "2026-01-25T23:34:09.523412+00:00", "data": {"market": "0xf829129cd05db888741ad290c786a1d71db5f8bb8493d8bc07e21b826db4d328", "price_changes": [{"asset_id": "105495516848871865829093849779907676478444075202002902600889102615883909197041", "price": "0.832", "size": "0", "side": "BUY", "hash": "764894e81b4a11b8c6e40884258de6548351b171", "best_bid": "0.887", "best_ask": "0.904"}, {"asset_id": "90685511192998551789516562849422906363784901518167369632157413860597087715433", "price": "0.168", "size": "0", "side": "SELL", "hash": "00f4b7dc231d9ac7e59344664dbe9055fc512b25", "best_bid": "0.096", "best_ask": "0.113"}], "timestamp": "1769384049451", "event_type": "price_change"}}
{"_local_timestamp": "2026-01-25T23:34:09.552830+00:00", "data": {"market": "0xf829129cd05db888741ad290c786a1d71db5f8bb8493d8bc07e21b826db4d328", "price_changes": [{"asset_id": "105495516848871865829093849779907676478444075202002902600889102615883909197041", "price": "0.852", "size": "25", "side": "BUY", "hash": "3eeeb3630c499b20234fae6b595ad58ee6b0c0db", "best_bid": "0.887", "best_ask": "0.904"}, {"asset_id": "90685511192998551789516562849422906363784901518167369632157413860597087715433", "price": "0.148", "size": "25", "side": "SELL", "hash": "7cffa56f2b5477fb160cb3d4ba969dc34a4a4713", "best_bid": "0.096", "best_ask": "0.113"}], "timestamp": "1769384049482", "event_type": "price_change"}}
{"_local_timestamp": "2026-01-25T23:34:09.669796+00:00", "data": {"market": "0xf829129cd05db888741ad290c786a1d71db5f8bb8493d8bc07e21b826db4d328", "price_changes": [{"asset_id": "105495516848871865829093849779907676478444075202002902600889102615883909197041", "price": "0.852", "size": "50", "side": "BUY", "hash": "77fd227bc5eb80c9ab966da9ba301550eb5d39a7", "best_bid": "0.887", "best_ask": "0.904"}, {"asset_id": "90685511192998551789516562849422906363784901518167369632157413860597087715433", "price": "0.148", "size": "50", "side": "SELL", "hash": "d43214784bf6dd88bfdd57032f9016073994b42a", "best_bid": "0.096", "best_ask": "0.113"}], "timestamp": "1769384049600", "event_type": "price_change"}}
{"_local_timestamp": "2026-01-25T23:34:09.781265+00:00", "data": {"market": "0xf829129cd05db888741ad290c786a1d71db5f8bb8493d8bc07e21b826db4d328", "price_changes": [{"asset_id": "105495516848871865829093849779907676478444075202002902600889102615883909197041", "price": "0.852", "size": "25", "side": "BUY", "hash": "ea46fc30887d08bd6909d960beb83362924d8d7b", "best_bid": "0.887", "best_ask": "0.904"}, {"asset_id": "90685511192998551789516562849422906363784901518167369632157413860597087715433", "price": "0.148", "size": "25", "side": "SELL", "hash": "4dcd5e75aa6182620d96a0d03c132df19806e3f7", "best_bid": "0.096", "best_ask": "0.113"}], "timestamp": "1769384049714", "event_type": "price_change"}}
{"_local_timestamp": "2026-01-25T23:34:09.999118+00:00", "data": {"market": "0xf829129cd05db888741ad290c786a1d71db5f8bb8493d8bc07e21b826db4d328", "price_changes": [{"asset_id": "105495516848871865829093849779907676478444075202002902600889102615883909197041", "price": "0.833", "size": "0", "side": "BUY", "hash": "583f09f3e847a0fe99eaab40aeea018be264ed26", "best_bid": "0.887", "best_ask": "0.904"}, {"asset_id": "90685511192998551789516562849422906363784901518167369632157413860597087715433", "price": "0.167", "size": "0", "side": "SELL", "hash": "2997466a070d4337eb4cfa9b26ada348503fdcd7", "best_bid": "0.096", "best_ask": "0.113"}], "timestamp": "1769384049929", "event_type": "price_change"}}
{"_local_timestamp": "2026-01-25T23:34:10.019670+00:00", "data": {"market": "0xf829129cd05db888741ad290c786a1d71db5f8bb8493d8bc07e21b826db4d328", "price_changes": [{"asset_id": "105495516848871865829093849779907676478444075202002902600889102615883909197041", "price": "0.821", "size": "20", "side": "BUY", "hash": "007998f3ced3362887eef7c8957f229f79ea52b8", "best_bid": "0.887", "best_ask": "0.904"}, {"asset_id": "90685511192998551789516562849422906363784901518167369632157413860597087715433", "price": "0.179", "size": "20", "side": "SELL", "hash": "bd21f3ac3f823c9742e54ad7c7bf27f1048e1c4b", "best_bid": "0.096", "best_ask": "0.113"}], "timestamp": "1769384049955", "event_type": "price_change"}}
{"_local_timestamp": "2026-01-25T23:34:10.106429+00:00", "data": {"market": "0xf829129cd05db888741ad290c786a1d71db5f8bb8493d8bc07e21b826db4d328", "price_changes": [{"asset_id": "105495516848871865829093849779907676478444075202002902600889102615883909197041", "price": "0.852", "size": "0", "side": "BUY", "hash": "0c851676c0888cb3ec7c22e6f957137a166f98e7", "best_bid": "0.887", "best_ask": "0.904"}, {"asset_id": "90685511192998551789516562849422906363784901518167369632157413860597087715433", "price": "0.148", "size": "0", "side": "SELL", "hash": "3a7b9a23cacd5b2bc181fd09f89b95b8b6073f67", "best_bid": "0.096", "best_ask": "0.113"}], "timestamp": "1769384050036", "event_type": "price_change"}}
{"_local_timestamp": "2026-01-25T23:34:10.139560+00:00", "data": {"market": "0xf829129cd05db888741ad290c786a1d71db5f8bb8493d8bc07e21b826db4d328", "price_changes": [{"asset_id": "105495516848871865829093849779907676478444075202002902600889102615883909197041", "price": "0.832", "size": "51", "side": "BUY", "hash": "58a8b474049479b5dac79507e6e975fcd9d01c19", "best_bid": "0.887", "best_ask": "0.904"}, {"asset_id": "90685511192998551789516562849422906363784901518167369632157413860597087715433", "price": "0.168", "size": "51", "side": "SELL", "hash": "b37eab24f87a25482035f3ddb3d4f7009172b12b", "best_bid": "0.096", "best_ask": "0.113"}], "timestamp": "1769384050069", "event_type": "price_change"}}
