{"_local_timestamp": "2026-01-25T23:40:31.243422+00:00", "data": [{"market": "0x26ebe9f65bd68ddedda46fd178b35f849aae4607e1265df3ef7243f99829f195", "asset_id": "86353192546542495916641527487272540176875193724127522627725581591930228417624", "timestamp": "1769384426830", "hash": "e0af07ffe4fe0a3fc6d10c490d8f7e8c3fc267f3", "bids": [{"price": "0.01", "size": "7560.12"}, {"price": "0.02", "size": "3000"}, {"price": "0.03", "size": "9.46"}, {"price": "0.05", "size": "10"}, {"price": "0.06", "size": "2000"}, {"price": "0.09", "size": "377.77"}, {"price": "0.1", "size": "6.14"}, {"price": "0.12", "size": "266.66"}, {"price": "0.15", "size": "1816.57"}, {"price": "0.18", "size": "144.44"}, {"price": "0.19", "size": "447"}, {"price": "0.2", "size": "10"}, {"price": "0.21", "size": "114.28"}, {"price": "0.24", "size": "233.33"}, {"price": "0.41", "size": "120"}, {"price": "0.46", "size": "28.26"}, {"price": "0.47", "size": "23.4"}, {"price": "0.5", "size": "1000"}, {"price": "0.51", "size": "23"}, {"price": "0.53", "size": "135.89"}, {"price": "0.54", "size": "30"}, {"price": "0.55", "size": "23"}, {"price": "0.56", "size": "8.5"}], "asks": [{"price": "0.99", "size": "4555.36"}, {"price": "0.98", "size": "19.57"}, {"price": "0.96", "size": "11600"}, {"price": "0.95", "size": "10"}, {"price": "0.94", "size": "10000"}, {"price": "0.93", "size": "300"}, {"price": "0.92", "size": "200"}, {"price": "0.91", "size": "100"}, {"price": "0.9", "size": "90.54"}, {"price": "0.84", "size": "222"}, {"price": "0.83", "size": "66.66"}, {"price": "0.8", "size": "65"}, {"price": "0.79", "size": "52.38"}, {"price": "0.76", "size": "266.66"}, {"price": "0.75", "size": "8.5"}, {"price": "0.72", "size": "91.66"}], "event_type": "book", "last_trade_price": ""}, {"market": "0x22cb289f07f3da4d3525f1c3944010a05c77d21ecf451719959ae54d24edcdb3", "asset_id": "63319160664943786518939060358909912675713743438409851354160257846337485458777", "timestamp": "1769384335230", "hash": "3f093855a1cf70d7314fc1dc84eb3c6a4d86f703", "bids": [{"price": "0.01", "size": "23"}, {"price": "0.02", "size": "2258.01"}, {"price": "0.03", "size": "10500"}, {"price": "0.04", "size": "508.46"}, {"price": "0.05", "size": "15000"}, {"price": "0.08", "size": "3000"}, {"price": "0.09", "size": "560.57"}, {"price": "0.1", "size": "110"}, {"price": "0.11", "size": "9.48"}, {"price": "0.12", "size": "108.33"}, {"price": "0.17", "size": "183"}, {"price": "0.18", "size": "421.19"}, {"price": "0.19", "size": "89.3"}], "asks": [{"price": "0.99", "size": "57"}, {"price": "0.98", "size": "18.01"}, {"price": "0.95", "size": "10"}, {"price": "0.94", "size": "8.33"}, {"price": "0.73", "size": "222"}, {"price": "0.72", "size": "7"}, {"price": "0.5", "size": "100"}, {"price": "0.4", "size": "12"}, {"price": "0.34", "size": "86.8"}, {"price": "0.31", "size": "18.84"}, {"price": "0.3", "size": "15.71"}, {"price": "0.29", "size": "17.35"}, {"price": "0.22", "size": "60.83"}], "event_type": "book", "last_trade_price": ""}, {"market": "0x26ebe9f65bd68ddedda46fd178b35f849aae4607e1265df3ef7243f99829f195", "asset_id": "63808367585655921040786645798394416641162584754134130888507371817017552687973", "timestamp": "1769384426830", "hash": "4efc3566b4212ca3668f1116bba18049f2249589", "bids": [{"price": "0.01", "size": "4555.36"}, {"price": "0.02", "size": "19.57"}, {"price": "0.04", "size": "11600"}, {"price": "0.05", "size": "10"}, {"price": "0.06", "size": "10000"}, {"price": "0.07", "size": "300"}, {"price": "0.08", "size": "200"}, {"price": "0.09", "size": "100"}, {"price": "0.1", "size": "90.54"}, {"price": "0.16", "size": "222"}, {"price": "0.17", "size": "66.66"}, {"price": "0.2", "size": "65"}, {"price": "0.21", "size": "52.38"}, {"price": "0.24", "size": "266.66"}, {"price": "0.25", "size": "8.5"}, {"price": "0.28", "size": "91.66"}], "asks": [{"price": "0.99", "size": "7560.12"}, {"price": "0.98", "size": "3000"}, {"price": "0.97", "size": "9.46"}, {"price": "0.95", "size": "10"}, {"price": "0.94", "size": "2000"}, {"price": "0.91", "size": "377.77"}, {"price": "0.9", "size": "6.14"}, {"price": "0.88", "size": "266.66"}, {"price": "0.85", "size": "1816.57"}, {"price": "0.82", "size": "144.44"}, {"price": "0.81", "size": "447"}, {"price": "0.8", "size": "10"}, {"price": "0.79", "size": "114.28"}, {"price": "0.76", "size": "233.33"}, {"price": "0.59", "size": "120"}, {"price": "0.54", "size": "28.26"}, {"price": "0.53", "size": "23.4"}, {"price": "0.5", "size": "1000"}, {"price": "0.49", "size": "23"}, {"price": "0.47", "size": "135.89"}, {"price": "0.46", "size": "30"}, {"price": "0.45", "size": "23"}, {"price": "0.44", "size": "8.5"}], "event_type": "book", "last_trade_price": ""}, {"market": "0x22cb289f07f3da4d3525f1c3944010a05c77d21ecf451719959ae54d24edcdb3", "asset_id": "87804592479196466711777128999586900823008283860411163575393570799751833246120", "timestamp": "1769384335230", "hash": "e86b56559af21af80dc10b7515a1fdab2d9245c9", "bids": [{"price": "0.01", "size": "57"}, {"price": "0.02", "size": "18.01"}, {"price": "0.05", "size": "10"}, {"price": "0.06", "size": "8.33"}, {"price": "0.27", "size": "222"}, {"price": "0.28", "size": "7"}, {"price": "0.5", "size": "100"}, {"price": "0.6", "size": "12"}, {"price": "0.66", "size": "86.8"}, {"price": "0.69", "size": "18.84"}, {"price": "0.7", "size": "15.71"}, {"price": "0.71", "size": "17.35"}, {"price": "0.78", "size": "60.83"}], "asks": [{"price": "0.99", "size": "23"}, {"price": "0.98", "size": "2258.01"}, {"price": "0.97", "size": "10500"}, {"price": "0.96", "size": "508.46"}, {"price": "0.95", "size": "15000"}, {"price": "0.92", "size": "3000"}, {"price": "0.91", "size": "560.57"}, {"price": "0.9", "size": "110"}, {"price": "0.89", "size": "9.48"}, {"price": "0.88", "size": "108.33"}, {"price": "0.83", "size": "183"}, {"price": "0.82", "size": "421.19"}, {"price": "0.81", "size": "89.3"}], "event_type": "book", "last_trade_price": ""}]}
{"_local_timestamp": "2026-01-25T23:41:51.972616+00:00", "data": {"market": "0x26ebe9f65bd68ddedda46fd178b35f849aae4607e1265df3ef7243f99829f195", "price_changes": [{"asset_id": "86353192546542495916641527487272540176875193724127522627725581591930228417624", "price": "0.56", "size": "76.35", "side": "BUY", "hash": "74fae872e7039de9e63fce3e4cbb0ba031481dae", "best_bid": "0.56", "best_ask": "0.72"}, {"asset_id": "63808367585655921040786645798394416641162584754134130888507371817017552687973", "price": "0.44", "size": "76.35", "side": "SELL", "hash": "e7f4acff6ddfa25a3b9ca153e1cc230eeee9917d", "best_bid": "0.28", "best_ask": "0.44"}], "timestamp": "1769384511864", "event_type": "price_change"}}
{"_local_timestamp": "2026-01-25T23:41:52.666684+00:00", "data": {"market": "0x26ebe9f65bd68ddedda46fd178b35f849aae4607e1265df3ef7243f99829f195", "price_changes": [{"asset_id": "86353192546542495916641527487272540176875193724127522627725581591930228417624", "price": "0.54", "size": "0", "side": "BUY", "hash": "d408b030a49688ddb09dbede262cf89bfeddbf07", "best_bid": "0.56", "best_ask": "0.72"}, {"asset_id": "63808367585655921040786645798394416641162584754134130888507371817017552687973", "price": "0.46", "size": "0", "side": "SELL", "hash": "200a33fedabe482d43bb84b1cb4d81dfa5a9f6e6", "best_bid": "0.28", "best_ask": "0.44"}], "timestamp": "1769384512585", "event_type": "price_change"}}
{"_local_timestamp": "2026-01-25T23:41:53.158173+00:00", "data": {"market": "0x26ebe9f65bd68ddedda46fd178b35f849aae4607e1265df3ef7243f99829f195", "price_changes": [{"asset_id": "86353192546542495916641527487272540176875193724127522627725581591930228417624", "price": "0.56", "size": "106.35", "side": "BUY", "hash": "4c5e5d98726939d07efea629fcef8a1be8d69f01", "best_bid": "0.56", "best_ask": "0.72"}, {"asset_id": "63808367585655921040786645798394416641162584754134130888507371817017552687973", "price": "0.44", "size": "106.35", "side": "SELL", "hash": "3cf8d4bc158c779381aaaa5d98bb7fcf39c3e863", "best_bid": "0.28", "best_ask": "0.44"}], "timestamp": "1769384512894", "event_type": "price_change"}}
{"_local_timestamp": "2026-01-25T23:42:00.761897+00:00", "data": {"market": "0x26ebe9f65bd68ddedda46fd178b35f849aae4607e1265df3ef7243f99829f195", "price_changes": [{"asset_id": "86353192546542495916641527487272540176875193724127522627725581591930228417624", "price": "0.56", "size": "97.85", "side": "BUY", "hash": "ed101efa87e30f6962f1aaa89e91c452b3f2612b", "best_bid": "0.56", "best_ask": "0.72"}, {"asset_id": "63808367585655921040786645798394416641162584754134130888507371817017552687973", "price": "0.44", "size": "97.85", "side": "SELL", "hash": "e28480f34e9136a807e40d20df3c1bb90ab05bea", "best_bid": "0.28", "best_ask": "0.44"}], "timestamp": "1769384520687", "event_type": "price_change"}}
{"_local_timestamp": "2026-01-25T23:42:00.790531+00:00", "data": {"market": "0x26ebe9f65bd68ddedda46fd178b35f849aae4607e1265df3ef7243f99829f195", "price_changes": [{"asset_id": "86353192546542495916641527487272540176875193724127522627725581591930228417624", "price": "0.52", "size": "8.5", "side": "BUY", "hash": "6315d2f7782340dbf164a7feeaf83ca835b9dae3", "best_bid": "0.56", "best_ask": "0.72"}, {"asset_id": "63808367585655921040786645798394416641162584754134130888507371817017552687973", "price": "0.48", "size": "8.5", "side": "SELL", "hash": "244133b1f8f8154b2a5993ef18b988003a258d59", "best_bid": "0.28", "best_ask": "0.44"}], "timestamp": "1769384520723", "event_type": "price_change"}}
{"_local_timestamp": "2026-01-25T23:42:03.756113+00:00", "data": {"market": "0x26ebe9f65bd68ddedda46fd178b35f849aae4607e1265df3ef7243f99829f195", "price_changes": [{"asset_id": "86353192546542495916641527487272540176875193724127522627725581591930228417624", "price": "0.52", "size": "0", "side": "BUY", "hash": "eaad133dc7fac459463e159a663e837f1b25c231", "best_bid": "0.56", "best_ask": "0.72"}, {"asset_id": "63808367585655921040786645798394416641162584754134130888507371817017552687973", "price": "0.48", "size": "0", "side": "SELL", "hash": "a70f65b8eb6f5b6ea53b6e1c1b0dc68b05a53036", "best_bid": "0.28", "best_ask": "0.44"}], "timestamp": "1769384523679", "event_type": "price_change"}}
{"_local_timestamp": "2026-01-25T23:42:03.791419+00:00", "data": {"market": "0x26ebe9f65bd68ddedda46fd178b35f849aae4607e1265df3ef7243f99829f195", "price_changes": [{"asset_id": "86353192546542495916641527487272540176875193724127522627725581591930228417624", "price": "0.57", "size": "8.5", "side": "BUY", "hash": "eac6c1294bb270652644131fefd1cf21ba980869", "best_bid": "0.57", "best_ask": "0.72"}, {"asset_id": "63808367585655921040786645798394416641162584754134130888507371817017552687973", "price": "0.43", "size": "8.5", "side": "SELL", "hash": "193aa730c972b049821d36f3e0ff6e2ad526fe82", "best_bid": "0.28", "best_ask": "0.43"}], "timestamp": "1769384523718", "event_type": "price_change"}}
{"_local_timestamp": "2026-01-25T23:42:45.460360+00:00", "data": {"market": "0x26ebe9f65bd68ddedda46fd178b35f849aae4607e1265df3ef7243f99829f195", "price_changes": [{"asset_id": "86353192546542495916641527487272540176875193724127522627725581591930228417624", "price": "0.24", "size": "183.33", "side": "BUY", "hash": "578a2bc351a601c4e241bb287a9fe2dbd1060a79", "best_bid": "0.57", "best_ask": "0.72"}, {"asset_id": "63808367585655921040786645798394416641162584754134130888507371817017552687973", "price": "0.76", "size": "183.33", "side": "SELL", "hash": "7ab28704d1957f533fbc7729df4187808eec7bc6", "best_bid": "0.28", "best_ask": "0.43"}], "timestamp": "1769384565222", "event_type": "price_change"}}
{"_local_timestamp": "2026-01-25T23:43:04.921092+00:00", "data": {"market": "0x22cb289f07f3da4d3525f1c3944010a05c77d21ecf451719959ae54d24edcdb3", "price_changes": [{"asset_id": "87804592479196466711777128999586900823008283860411163575393570799751833246120", "price": "0.01", "size": "49.99", "side": "BUY", "hash": "850a1fc5620f67ac9751077e4cf9252dcca9aeab", "best_bid": "0.78", "best_ask": "0.81"}, {"asset_id": "63319160664943786518939060358909912675713743438409851354160257846337485458777", "price": "0.99", "size": "49.99", "side": "SELL", "hash": "4163dd3fda8cea944df234dfe3b2c6f1b66332f3", "best_bid": "0.19", "best_ask": "0.22"}], "timestamp": "1769384584706", "event_type": "price_change"}}
{"_local_timestamp": "2026-01-25T23:43:05.325416+00:00", "data": {"market": "0x22cb289f07f3da4d3525f1c3944010a05c77d21ecf451719959ae54d24edcdb3", "price_changes": [{"asset_id": "87804592479196466711777128999586900823008283860411163575393570799751833246120", "price": "0.01", "size": "57", "side": "BUY", "hash": "c6f83f8ebd195dc9ac491ca20d86f72bbffa0e4d", "best_bid": "0.78", "best_ask": "0.81"}, {"asset_id": "63319160664943786518939060358909912675713743438409851354160257846337485458777", "price": "0.99", "size": "57", "side": "SELL", "hash": "eff05cc060cb80a327f6bf5f225154eb814af73d", "best_bid": "0.19", "best_ask": "0.22"}], "timestamp": "1769384585115", "event_type": "price_change"}}
{"_local_timestamp": "2026-01-25T23:43:42.361009+00:00", "data": {"market": "0x26ebe9f65bd68ddedda46fd178b35f849aae4607e1265df3ef7243f99829f195", "price_changes": [{"asset_id": "86353192546542495916641527487272540176875193724127522627725581591930228417624", "price": "0.56", "size": "30", "side": "BUY", "hash": "647340fa3d2fe56fa2ef2d80fe02e54b3a85bc7b", "best_bid": "0.57", "best_ask": "0.72"}, {"asset_id": "63808367585655921040786645798394416641162584754134130888507371817017552687973", "price": "0.44", "size": "30", "side": "SELL", "hash": "e62ca35ee055c05b2ed9e849c37847e26b5598a0", "best_bid": "0.28", "best_ask": "0.43"}], "timestamp": "1769384622276", "event_type": "price_change"}}
{"_local_timestamp": "2026-01-25T23:43:42.786477+00:00", "data": {"market": "0x26ebe9f65bd68ddedda46fd178b35f849aae4607e1265df3ef7243f99829f195", "price_changes": [{"asset_id": "86353192546542495916641527487272540176875193724127522627725581591930228417624", "price": "0.56", "size": "0", "side": "BUY", "hash": "fcd9693c6620f34ae087ae333c71ba0974cc4c3b", "best_bid": "0.57", "best_ask": "0.72"}, {"asset_id": "63808367585655921040786645798394416641162584754134130888507371817017552687973", "price": "0.44", "size": "0", "side": "SELL", "hash": "9f7c55d00a3c54bde5e96338689d71d73dfafd48", "best_bid": "0.28", "best_ask": "0.43"}], "timestamp": "1769384622688", "event_type": "price_change"}}
{"_local_timestamp": "2026-01-25T23:43:42.848495+00:00", "data": {"market": "0x26ebe9f65bd68ddedda46fd178b35f849aae4607e1265df3ef7243f99829f195", "price_changes": [{"asset_id": "86353192546542495916641527487272540176875193724127522627725581591930228417624", "price": "0.53", "size": "165.89", "side": "BUY", "hash": "d9231eff0efe01e3be7bc9e8c8e767d3f16bda4a", "best_bid": "0.57", "best_ask": "0.72"}, {"asset_id": "63808367585655921040786645798394416641162584754134130888507371817017552687973", "price": "0.47", "size": "165.89", "side": "SELL", "hash": "057acfd3a8a23d39ce3b91df97b1898ed25f1b5d", "best_bid": "0.28", "best_ask": "0.43"}], "timestamp": "1769384622769", "event_type": "price_change"}}
{"_local_timestamp": "2026-01-25T23:43:53.345255+00:00", "data": {"market": "0x26ebe9f65bd68ddedda46fd178b35f849aae4607e1265df3ef7243f99829f195", "price_changes": [{"asset_id": "86353192546542495916641527487272540176875193724127522627725581591930228417624", "price": "0.57", "size": "0", "side": "BUY", "hash": "10b890bddae9f8fe729c262cde8f01b4b1514b88", "best_bid": "0.55", "best_ask": "0.72"}, {"asset_id": "63808367585655921040786645798394416641162584754134130888507371817017552687973", "price": "0.43", "size": "0", "side": "SELL", "hash": "c19c50c203bfea461818bc497b60b68e1c41e151", "best_bid": "0.28", "best_ask": "0.45"}], "timestamp": "1769384633272", "event_type": "price_change"}}
{"_local_timestamp": "2026-01-25T23:43:53.375571+00:00", "data": {"market": "0x26ebe9f65bd68ddedda46fd178b35f849aae4607e1265df3ef7243f99829f195", "price_changes": [{"asset_id": "86353192546542495916641527487272540176875193724127522627725581591930228417624", "price": "0.52", "size": "8.5", "side": "BUY", "hash": "86fac2c78e338b9abc2efc375ebc5267dd9727f4", "best_bid": "0.55", "best_ask": "0.72"}, {"asset_id": "63808367585655921040786645798394416641162584754134130888507371817017552687973", "price": "0.48", "size": "8.5", "side": "SELL", "hash": "316ea569035097d6d09ae3d023ea14e5cc8ced90", "best_bid": "0.28", "best_ask": "0.45"}], "timestamp": "1769384633309", "event_type": "price_change"}}
{"_local_timestamp": "2026-01-25T23:43:53.741989+00:00", "data": {"market": "0x26ebe9f65bd68ddedda46fd178b35f849aae4607e1265df3ef7243f99829f195", "price_changes": [{"asset_id": "63808367585655921040786645798394416641162584754134130888507371817017552687973", "price": "0.15", "size": "133.33", "side": "BUY", "hash": "00ca0081c4e171c7ba72ef256915923b4e61475f", "best_bid": "0.28", "best_ask": "0.45"}, {"asset_id": "86353192546542495916641527487272540176875193724127522627725581591930228417624", "price": "0.85", "size": "133.33", "side": "SELL", "hash": "5ce8c3a1887786042a6956eaa0c112fcb231e99e", "best_bid": "0.55", "best_ask": "0.72"}], "timestamp": "1769384633670", "event_type": "price_change"}}
{"_local_timestamp": "2026-01-25T23:43:53.788321+00:00", "data": {"market": "0x26ebe9f65bd68ddedda46fd178b35f849aae4607e1265df3ef7243f99829f195", "price_changes": [{"asset_id": "63808367585655921040786645798394416641162584754134130888507371817017552687973", "price": "0.13", "size": "184.61", "side": "BUY", "hash": "d58caf6a5a4ed434048736adbbf2d2721bb74484", "best_bid": "0.28", "best_ask": "0.45"}, {"asset_id": "86353192546542495916641527487272540176875193724127522627725581591930228417624", "price": "0.87", "size": "184.61", "side": "SELL", "hash": "bfcab1b57f60e2b784f19693368178add0826bea", "best_bid": "0.55", "best_ask": "0.72"}], "timestamp": "1769384633719", "event_type": "price_change"}}
{"_local_timestamp": "2026-01-25T23:43:53.840350+00:00", "data": {"market": "0x26ebe9f65bd68ddedda46fd178b35f849aae4607e1265df3ef7243f99829f195", "price_changes": [{"asset_id": "63808367585655921040786645798394416641162584754134130888507371817017552687973", "price": "0.11", "size": "236.36", "side": "BUY", "hash": "54cae8d7885b8a83b402636b414ca039f7bedfb2", "best_bid": "0.28", "best_ask": "0.45"}, {"asset_id": "86353192546542495916641527487272540176875193724127522627725581591930228417624", "price": "0.89", "size": "236.36", "side": "SELL", "hash": "0f029282c5321cc03b1764c450eff37a2a8a3b19", "best_bid": "0.55", "best_ask": "0.72"}], "timestamp": "1769384633768", "event_type": "price_change"}}
{"_local_timestamp": "2026-01-25T23:43:53.894797+00:00", "data": {"market": "0x26ebe9f65bd68ddedda46fd178b35f849aae4607e1265df3ef7243f99829f195", "price_changes": [{"asset_id": "63808367585655921040786645798394416641162584754134130888507371817017552687973", "price": "0.1", "size": "370.54", "side": "BUY", "hash": "db030d460d2d23e7c68dbf71d93a4b407a5e2a97", "best_bid": "0.28", "best_ask": "0.45"}, {"asset_id": "86353192546542495916641527487272540176875193724127522627725581591930228417624", "price": "0.9", "size": "370.54", "side": "SELL", "hash": "d997883965c5aff92ee9bd7ae13b6b69581079a4", "best_bid": "0.55", "best_ask": "0.72"}], "timestamp": "1769384633820", "event_type": "price_change"}}
{"_local_timestamp": "2026-01-25T23:43:53.939485+00:00", "data": {"market": "0x26ebe9f65bd68ddedda46fd178b35f849aae4607e1265df3ef7243f99829f195", "price_changes": [{"asset_id": "63808367585655921040786645798394416641162584754134130888507371817017552687973", "price": "0.08", "size": "600", "side": "BUY", "hash": "7e2555768c7219e7360df243b5adf4fecc72affe", "best_bid": "0.28", "best_ask": "0.45"}, {"asset_id": "86353192546542495916641527487272540176875193724127522627725581591930228417624", "price": "0.92", "size": "600", "side": "SELL", "hash": "cbad638f303cd605768c5ec4c19a50baaf01243f", "best_bid": "0.55", "best_ask": "0.72"}], "timestamp": "1769384633869", "event_type": "price_change"}}
{"_local_timestamp": "2026-01-25T23:43:53.998819+00:00", "data": {"market": "0x26ebe9f65bd68ddedda46fd178b35f849aae4607e1265df3ef7243f99829f195", "price_changes": [{"asset_id": "63808367585655921040786645798394416641162584754134130888507371817017552687973", "price": "0.06", "size": "10566.66", "side": "BUY", "hash": "ad961767e2c7679c1fea791b513365e03b4d30f3", "best_bid": "0.28", "best_ask": "0.45"}, {"asset_id": "86353192546542495916641527487272540176875193724127522627725581591930228417624", "price": "0.94", "size": "10566.66", "side": "SELL", "hash": "2f66d13b0aa0eb7b4c2d3fee56ed8dce6368eaa8", "best_bid": "0.55", "best_ask": "0.72"}], "timestamp": "1769384633916", "event_type": "price_change"}}
{"_local_timestamp": "2026-01-25T23:43:54.045975+00:00", "data": {"market": "0x26ebe9f65bd68ddedda46fd178b35f849aae4607e1265df3ef7243f99829f195", "price_changes": [{"asset_id": "63808367585655921040786645798394416641162584754134130888507371817017552687973", "price": "0.04", "size": "12500", "side": "BUY", "hash": "bd2a7e765d19760026e272e4f2ff678849495223", "best_bid": "0.28", "best_ask": "0.45"}, {"asset_id": "86353192546542495916641527487272540176875193724127522627725581591930228417624", "price": "0.96", "size": "12500", "side": "SELL", "hash": "dc4b19d61e7519350a042d64a646310304fa1a22", "best_bid": "0.55", "best_ask": "0.72"}], "timestamp": "1769384633967", "event_type": "price_change"}}
{"_local_timestamp": "2026-01-25T23:45:12.476530+00:00", "data": {"market": "0x26ebe9f65bd68ddedda46fd178b35f849aae4607e1265df3ef7243f99829f195", "price_changes": [{"asset_id": "86353192546542495916641527487272540176875193724127522627725581591930228417624", "price": "0.54", "size": "70.37", "side": "BUY", "hash": "a7dad1995e7881063a50b1010c7f20a3066b247c", "best_bid": "0.55", "best_ask": "0.72"}, {"asset_id": "63808367585655921040786645798394416641162584754134130888507371817017552687973", "price": "0.46", "size": "70.37", "side": "SELL", "hash": "7bf90495421a4af4df64aaa9c65173fff860b654", "best_bid": "0.28", "best_ask": "0.45"}], "timestamp": "1769384712405", "event_type": "price_change"}}
{"_local_timestamp": "2026-01-25T23:45:13.438417+00:00", "data": {"market": "0x26ebe9f65bd68ddedda46fd178b35f849aae4607e1265df3ef7243f99829f195", "price_changes": [{"asset_id": "86353192546542495916641527487272540176875193724127522627725581591930228417624", "price": "0.53", "size": "135.89", "side": "BUY", "hash": "e93f2d5eba33b5cb173c92a7bb8e1a3f0e25d4ba", "best_bid": "0.55", "best_ask": "0.72"}, {"asset_id": "63808367585655921040786645798394416641162584754134130888507371817017552687973", "price": "0.47", "size": "135.89", "side": "SELL", "hash": "f9fc99a6dba4990f5dbde80228e926240f74a64d", "best_bid": "0.28", "best_ask": "0.45"}], "timestamp": "1769384713367", "event_type": "price_change"}}
{"_local_timestamp": "2026-01-25T23:45:13.510106+00:00", "data": {"market": "0x26ebe9f65bd68ddedda46fd178b35f849aae4607e1265df3ef7243f99829f195", "price_changes": [{"asset_id": "86353192546542495916641527487272540176875193724127522627725581591930228417624", "price": "0.54", "size": "100.37", "side": "BUY", "hash": "9cc6b4b59156f7b4326ec330be91de6294b20aee", "best_bid": "0.55", "best_ask": "0.72"}, {"asset_id": "63808367585655921040786645798394416641162584754134130888507371817017552687973", "price": "0.46", "size": "100.37", "side": "SELL", "hash": "931dc10d2ab232c4fdcbc114fc40710ece1423e9", "best_bid": "0.28", "best_ask": "0.45"}], "timestamp": "1769384713443", "event_type": "price_change"}}
{"_local_timestamp": "2026-01-25T23:45:32.466495+00:00", "data": {"market": "0x26ebe9f65bd68ddedda46fd178b35f849aae4607e1265df3ef7243f99829f195", "price_changes": [{"asset_id": "86353192546542495916641527487272540176875193724127522627725581591930228417624", "price": "0.2", "size": "0", "side": "BUY", "hash": "986b55be008974eceab93e31a90a0eb7f805dc6c", "best_bid": "0.55", "best_ask": "0.72"}, {"asset_id": "63808367585655921040786645798394416641162584754134130888507371817017552687973", "price": "0.8", "size": "0", "side": "SELL", "hash": "ff40db5bce37b04a71e6a969fcc567846d93242a", "best_bid": "0.28", "best_ask": "0.45"}], "timestamp": "1769384732398", "event_type": "price_change"}}
{"_local_timestamp": "2026-01-25T23:45:32.515226+00:00", "data": {"market": "0x26ebe9f65bd68ddedda46fd178b35f849aae4607e1265df3ef7243f99829f195", "price_changes": [{"asset_id": "86353192546542495916641527487272540176875193724127522627725581591930228417624", "price": "0.2", "size": "10", "side": "BUY", "hash": "b4e3a64e438ba377ccbb28cad05f56e16e3c0fd4", "best_bid": "0.55", "best_ask": "0.72"}, {"asset_id": "63808367585655921040786645798394416641162584754134130888507371817017552687973", "price": "0.8", "size": "10", "side": "SELL", "hash": "bb9db3b26ec83b5ecfa7b99bca9e6573616efbd0", "best_bid": "0.28", "best_ask": "0.45"}], "timestamp": "1769384732446", "event_type": "price_change"}}
{"_local_timestamp": "2026-01-25T23:45:47.513862+00:00", "data": {"market": "0x26ebe9f65bd68ddedda46fd178b35f849aae4607e1265df3ef7243f99829f195", "price_changes": [{"asset_id": "86353192546542495916641527487272540176875193724127522627725581591930228417624", "price": "0.52", "size": "0", "side": "BUY", "hash": "44ea8e5ccbfc135aac19f0a5aea6aae4fc21be77", "best_bid": "0.55", "best_ask": "0.72"}, {"asset_id": "63808367585655921040786645798394416641162584754134130888507371817017552687973", "price": "0.48", "size": "0", "side": "SELL", "hash": "8b3696dfc5dbcaeb513715a0ffc5eb64384af654", "best_bid": "0.28", "best_ask": "0.45"}], "timestamp": "1769384747449", "event_type": "price_change"}}
{"_local_timestamp": "2026-01-25T23:45:47.556577+00:00", "data": {"market": "0x26ebe9f65bd68ddedda46fd178b35f849aae4607e1265df3ef7243f99829f195", "price_changes": [{"asset_id": "86353192546542495916641527487272540176875193724127522627725581591930228417624", "price": "0.56", "size": "8.5", "side": "BUY", "hash": "274841c2d956fe3fa6e58bdcbe13839300fcfeda", "best_bid": "0.56", "best_ask": "0.72"}, {"asset_id": "63808367585655921040786645798394416641162584754134130888507371817017552687973", "price": "0.44", "size": "8.5", "side": "SELL", "hash": "0c23069d9fbe102a43ea7b3bd8e06b4249aea18b", "best_bid": "0.28", "best_ask": "0.44"}], "timestamp": "1769384747489", "event_type": "price_change"}}
{"_local_timestamp": "2026-01-25T23:45:47.600976+00:00", "data": {"market": "0x26ebe9f65bd68ddedda46fd178b35f849aae4607e1265df3ef7243f99829f195", "price_changes": [{"asset_id": "63808367585655921040786645798394416641162584754134130888507371817017552687973", "price": "0.13", "size": "0", "side": "BUY", "hash": "53d629a8272b361f96224f95e969e2b6a736ff53", "best_bid": "0.28", "best_ask": "0.44"}, {"asset_id": "86353192546542495916641527487272540176875193724127522627725581591930228417624", "price": "0.87", "size": "0", "side": "SELL", "hash": "74440501252a8d780cfc2d361a67903291950267", "best_bid": "0.56", "best_ask": "0.72"}], "timestamp": "1769384747535", "event_type": "price_change"}}
{"_local_timestamp": "2026-01-25T23:45:47.601371+00:00", "data": {"market": "0x26ebe9f65bd68ddedda46fd178b35f849aae4607e1265df3ef7243f99829f195", "price_changes": [{"asset_id": "63808367585655921040786645798394416641162584754134130888507371817017552687973", "price": "0.15", "size": "0", "side": "BUY", "hash": "53d629a8272b361f96224f95e969e2b6a736ff53", "best_bid": "0.28", "best_ask": "0.44"}, {"asset_id": "86353192546542495916641527487272540176875193724127522627725581591930228417624", "price": "0.85", "size": "0", "side": "SELL", "hash": "74440501252a8d780cfc2d361a67903291950267", "best_bid": "0.56", "best_ask": "0.72"}], "timestamp": "1769384747535", "event_type": "price_change"}}
{"_local_timestamp": "2026-01-25T23:45:47.601701+00:00", "data": {"market": "0x26ebe9f65bd68ddedda46fd178b35f849aae4607e1265df3ef7243f99829f195", "price_changes": [{"asset_id": "63808367585655921040786645798394416641162584754134130888507371817017552687973", "price": "0.06", "size": "10000", "side": "BUY", "hash": "53d629a8272b361f96224f95e969e2b6a736ff53", "best_bid": "0.28", "best_ask": "0.44"}, {"asset_id": "86353192546542495916641527487272540176875193724127522627725581591930228417624", "price": "0.94", "size": "10000", "side": "SELL", "hash": "74440501252a8d780cfc2d361a67903291950267", "best_bid": "0.56", "best_ask": "0.72"}], "timestamp": "1769384747535", "event_type": "price_change"}}
{"_local_timestamp": "2026-01-25T23:45:47.602382+00:00", "data": {"market": "0x26ebe9f65bd68ddedda46fd178b35f849aae4607e1265df3ef7243f99829f195", "price_changes": [{"asset_id": "63808367585655921040786645798394416641162584754134130888507371817017552687973", "price": "0.11", "size": "0", "side": "BUY", "hash": "53d629a8272b361f96224f95e969e2b6a736ff53", "best_bid": "0.28", "best_ask": "0.44"}, {"asset_id": "86353192546542495916641527487272540176875193724127522627725581591930228417624", "price": "0.89", "size": "0", "side": "SELL", "hash": "74440501252a8d780cfc2d361a67903291950267", "best_bid": "0.56", "best_ask": "0.72"}], "timestamp": "1769384747535", "event_type": "price_change"}}
{"_local_timestamp": "2026-01-25T23:45:47.602719+00:00", "data": {"market": "0x26ebe9f65bd68ddedda46fd178b35f849aae4607e1265df3ef7243f99829f195", "price_changes": [{"asset_id": "63808367585655921040786645798394416641162584754134130888507371817017552687973", "price": "0.04", "size": "11600", "side": "BUY", "hash": "53d629a8272b361f96224f95e969e2b6a736ff53", "best_bid": "0.28", "best_ask": "0.44"}, {"asset_id": "86353192546542495916641527487272540176875193724127522627725581591930228417624", "price": "0.96", "size": "11600", "side": "SELL", "hash": "74440501252a8d780cfc2d361a67903291950267", "best_bid": "0.56", "best_ask": "0.72"}], "timestamp": "1769384747535", "event_type": "price_change"}}
{"_local_timestamp": "2026-01-25T23:45:47.603048+00:00", "data": {"market": "0x26ebe9f65bd68ddedda46fd178b35f849aae4607e1265df3ef7243f99829f195", "price_changes": [{"asset_id": "63808367585655921040786645798394416641162584754134130888507371817017552687973", "price": "0.1", "size": "90.54", "side": "BUY", "hash": "53d629a8272b361f96224f95e969e2b6a736ff53", "best_bid": "0.28", "best_ask": "0.44"}, {"asset_id": "86353192546542495916641527487272540176875193724127522627725581591930228417624", "price": "0.9", "size": "90.54", "side": "SELL", "hash": "74440501252a8d780cfc2d361a67903291950267", "best_bid": "0.56", "best_ask": "0.72"}], "timestamp": "1769384747535", "event_type": "price_change"}}
{"_local_timestamp": "2026-01-25T23:45:47.603401+00:00", "data": {"market": "0x26ebe9f65bd68ddedda46fd178b35f849aae4607e1265df3ef7243f99829f195", "price_changes": [{"asset_id": "63808367585655921040786645798394416641162584754134130888507371817017552687973", "price": "0.08", "size": "200", "side": "BUY", "hash": "53d629a8272b361f96224f95e969e2b6a736ff53", "best_bid": "0.28", "best_ask": "0.44"}, {"asset_id": "86353192546542495916641527487272540176875193724127522627725581591930228417624", "price": "0.92", "size": "200", "side": "SELL", "hash": "74440501252a8d780cfc2d361a67903291950267", "best_bid": "0.56", "best_ask": "0.72"}], "timestamp": "1769384747535", "event_type": "price_change"}}
{"_local_timestamp": "2026-01-25T23:47:02.009302+00:00", "data": {"market": "0x26ebe9f65bd68ddedda46fd178b35f849aae4607e1265df3ef7243f99829f195", "price_changes": [{"asset_id": "86353192546542495916641527487272540176875193724127522627725581591930228417624", "price": "0.54", "size": "30", "side": "BUY", "hash": "b2dc9b80e5a46fd91f15e517035b1b6f1aa08e55", "best_bid": "0.56", "best_ask": "0.72"}, {"asset_id": "63808367585655921040786645798394416641162584754134130888507371817017552687973", "price": "0.46", "size": "30", "side": "SELL", "hash": "ce0d050cce17a6ddf69fefe4c2d1e1bfae953a27", "best_bid": "0.28", "best_ask": "0.44"}], "timestamp": "1769384821883", "event_type": "price_change"}}
{"_local_timestamp": "2026-01-25T23:47:11.226306+00:00", "data": {"market": "0x22cb289f07f3da4d3525f1c3944010a05c77d21ecf451719959ae54d24edcdb3", "price_changes": [{"asset_id": "87804592479196466711777128999586900823008283860411163575393570799751833246120", "price": "0.01", "size": "49.99", "side": "BUY", "hash": "4a54e55b57bbe3d9abe48d54429d3fbaa661148b", "best_bid": "0.78", "best_ask": "0.81"}, {"asset_id": "63319160664943786518939060358909912675713743438409851354160257846337485458777", "price": "0.99", "size": "49.99", "side": "SELL", "hash": "bd06b8cf8bbe83016e169c15baa1687f56e729ed", "best_bid": "0.19", "best_ask": "0.22"}], "timestamp": "1769384831082", "event_type": "price_change"}}
{"_local_timestamp": "2026-01-25T23:47:11.610109+00:00", "data": {"market": "0x22cb289f07f3da4d3525f1c3944010a05c77d21ecf451719959ae54d24edcdb3", "price_changes": [{"asset_id": "87804592479196466711777128999586900823008283860411163575393570799751833246120", "price": "0.01", "size": "57", "side": "BUY", "hash": "01ed10bb282de53fc500679051157c5f0f0119ef", "best_bid": "0.78", "best_ask": "0.81"}, {"asset_id": "63319160664943786518939060358909912675713743438409851354160257846337485458777", "price": "0.99", "size": "57", "side": "SELL", "hash": "92c296da0ba2e08e820ff0d3ba656c2894b86589", "best_bid": "0.19", "best_ask": "0.22"}], "timestamp": "1769384831487", "event_type": "price_change"}}
{"_local_timestamp": "2026-01-25T23:47:24.051123+00:00", "data": {"market": "0x26ebe9f65bd68ddedda46fd178b35f849aae4607e1265df3ef7243f99829f195", "price_changes": [{"asset_id": "86353192546542495916641527487272540176875193724127522627725581591930228417624", "price": "0.24", "size": "233.33", "side": "BUY", "hash": "c3f236c557669752cf4d2525e4623ba9e4192114", "best_bid": "0.56", "best_ask": "0.72"}, {"asset_id": "63808367585655921040786645798394416641162584754134130888507371817017552687973", "price": "0.76", "size": "233.33", "side": "SELL", "hash": "1008a2a8154167eccb9823c3b9ba9c7ef361b83d", "best_bid": "0.28", "best_ask": "0.44"}], "timestamp": "1769384843815", "event_type": "price_change"}}
{"_local_timestamp": "2026-01-25T23:48:16.863340+00:00", "data": {"market": "0x26ebe9f65bd68ddedda46fd178b35f849aae4607e1265df3ef7243f99829f195", "price_changes": [{"asset_id": "63808367585655921040786645798394416641162584754134130888507371817017552687973", "price": "0.09", "size": "0", "side": "BUY", "hash": "1607252cc8d7462c7791d262ad98f4314e77ea23", "best_bid": "0.28", "best_ask": "0.44"}, {"asset_id": "86353192546542495916641527487272540176875193724127522627725581591930228417624", "price": "0.91", "size": "0", "side": "SELL", "hash": "f8bdb0d9f8cef0648a5cfe198753d2eb76d72d1f", "best_bid": "0.56", "best_ask": "0.72"}], "timestamp": "1769384896786", "event_type": "price_change"}}
{"_local_timestamp": "2026-01-25T23:48:17.114072+00:00", "data": {"market": "0x26ebe9f65bd68ddedda46fd178b35f849aae4607e1265df3ef7243f99829f195", "price_changes": [{"asset_id": "63808367585655921040786645798394416641162584754134130888507371817017552687973", "price": "0.08", "size": "300", "side": "BUY", "hash": "3352b1b774b00e3c81a227167a18336467799f47", "best_bid": "0.28", "best_ask": "0.44"}, {"asset_id": "86353192546542495916641527487272540176875193724127522627725581591930228417624", "price": "0.92", "size": "300", "side": "SELL", "hash": "597b14661d6c5c8870fce4623b00b0547467a934", "best_bid": "0.56", "best_ask": "0.72"}], "timestamp": "1769384897022", "event_type": "price_change"}}
{"_local_timestamp": "2026-01-25T23:48:33.260684+00:00", "data": {"market": "0x26ebe9f65bd68ddedda46fd178b35f849aae4607e1265df3ef7243f99829f195", "price_changes": [{"asset_id": "86353192546542495916641527487272540176875193724127522627725581591930228417624", "price": "0.56", "size": "76.35", "side": "BUY", "hash": "915df70f8ba0633d256739a3ddbdf3a4ab96bfae", "best_bid": "0.56", "best_ask": "0.72"}, {"asset_id": "63808367585655921040786645798394416641162584754134130888507371817017552687973", "price": "0.44", "size": "76.35", "side": "SELL", "hash": "9392c3dd2f32ed804729493cba911b242f1ad77b", "best_bid": "0.28", "best_ask": "0.44"}], "timestamp": "1769384913179", "event_type": "price_change"}}
{"_local_timestamp": "2026-01-25T23:48:34.508577+00:00", "data": {"market": "0x26ebe9f65bd68ddedda46fd178b35f849aae4607e1265df3ef7243f99829f195", "price_changes": [{"asset_id": "86353192546542495916641527487272540176875193724127522627725581591930228417624", "price": "0.54", "size": "0", "side": "BUY", "hash": "a0c3648b01964a3c6ee2300382f73dccdc9cb633", "best_bid": "0.56", "best_ask": "0.72"}, {"asset_id": "63808367585655921040786645798394416641162584754134130888507371817017552687973", "price": "0.46", "size": "0", "side": "SELL", "hash": "35a04e19a96c5b79a2b14c804dd7a3c23cc95db0", "best_bid": "0.28", "best_ask": "0.44"}], "timestamp": "1769384914421", "event_type": "price_change"}}
{"_local_timestamp": "2026-01-25T23:48:34.567431+00:00", "data": {"market": "0x26ebe9f65bd68ddedda46fd178b35f849aae4607e1265df3ef7243f99829f195", "price_changes": [{"asset_id": "86353192546542495916641527487272540176875193724127522627725581591930228417624", "price": "0.56", "size": "106.35", "side": "BUY", "hash": "0af9243ae72bdb185da417bb65a7095962f4cdb2", "best_bid": "0.56", "best_ask": "0.72"}, {"asset_id": "63808367585655921040786645798394416641162584754134130888507371817017552687973", "price": "0.44", "size": "106.35", "side": "SELL", "hash": "ef83de789b3c9faf4969f7e983da970bef4ff614", "best_bid": "0.28", "best_ask": "0.44"}], "timestamp": "1769384914484", "event_type": "price_change"}}
{"_local_timestamp": "2026-01-25T23:49:21.718950+00:00", "data": {"market": "0x26ebe9f65bd68ddedda46fd178b35f849aae4607e1265df3ef7243f99829f195", "price_changes": [{"asset_id": "86353192546542495916641527487272540176875193724127522627725581591930228417624", "price": "0.56", "size": "97.85", "side": "BUY", "hash": "0f3697bf1d2eb61b66b7875538e912bc853ad6aa", "best_bid": "0.56", "best_ask": "0.72"}, {"asset_id": "63808367585655921040786645798394416641162584754134130888507371817017552687973", "price": "0.44", "size": "97.85", "side": "SELL", "hash": "412bd2d09aa36c33509383408b8507bd4df74eae", "best_bid": "0.28", "best_ask": "0.44"}], "timestamp": "1769384961640", "event_type": "price_change"}}
{"_local_timestamp": "2026-01-25T23:49:21.749113+00:00", "data": {"market": "0x26ebe9f65bd68ddedda46fd178b35f849aae4607e1265df3ef7243f99829f195", "price_changes": [{"asset_id": "86353192546542495916641527487272540176875193724127522627725581591930228417624", "price": "0.52", "size": "8.5", "side": "BUY", "hash": "c5419349e8eb32f0a5c8a584563d738f82792cec", "best_bid": "0.56", "best_ask": "0.72"}, {"asset_id": "63808367585655921040786645798394416641162584754134130888507371817017552687973", "price": "0.48", "size": "8.5", "side": "SELL", "hash": "bb96c1d3a61e00d7e6f3c5847f1ac376c3e77b08", "best_bid": "0.28", "best_ask": "0.44"}], "timestamp": "1769384961678", "event_type": "price_change"}}
{"_local_timestamp": "2026-01-25T23:49:25.801310+00:00", "data": {"market": "0x26ebe9f65bd68ddedda46fd178b35f849aae4607e1265df3ef7243f99829f195", "price_changes": [{"asset_id": "86353192546542495916641527487272540176875193724127522627725581591930228417624", "price": "0.52", "size": "0", "side": "BUY", "hash": "73ee1580077aeadd99520dcc0baa8c55517fcef5", "best_bid": "0.56", "best_ask": "0.72"}, {"asset_id": "63808367585655921040786645798394416641162584754134130888507371817017552687973", "price": "0.48", "size": "0", "side": "SELL", "hash": "fe3b0893fe6b02328ec6b4d4fce68f45d7d44514", "best_bid": "0.28", "best_ask": "0.44"}], "timestamp": "1769384965723", "event_type": "price_change"}}
{"_local_timestamp": "2026-01-25T23:49:25.835021+00:00", "data": {"market": "0x26ebe9f65bd68ddedda46fd178b35f849aae4607e1265df3ef7243f99829f195", "price_changes": [{"asset_id": "86353192546542495916641527487272540176875193724127522627725581591930228417624", "price": "0.57", "size": "8.5", "side": "BUY", "hash": "b31ef4044f9e41bcf31d6219ad69c76d960f6cae", "best_bid": "0.57", "best_ask": "0.72"}, {"asset_id": "63808367585655921040786645798394416641162584754134130888507371817017552687973", "price": "0.43", "size": "8.5", "side": "SELL", "hash": "34a76e2d39fe066830bb47ab86c2658c3de742e1", "best_bid": "0.28", "best_ask": "0.43"}], "timestamp": "1769384965760", "event_type": "price_change"}}
{"_local_timestamp": "2026-01-25T23:49:41.821437+00:00", "data": {"market": "0x26ebe9f65bd68ddedda46fd178b35f849aae4607e1265df3ef7243f99829f195", "price_changes": [{"asset_id": "86353192546542495916641527487272540176875193724127522627725581591930228417624", "price": "0.24", "size": "183.33", "side": "BUY", "hash": "cbb7399058ab78c5ff48ec2f57e32da449eb21ca", "best_bid": "0.57", "best_ask": "0.72"}, {"asset_id": "63808367585655921040786645798394416641162584754134130888507371817017552687973", "price": "0.76", "size": "183.33", "side": "SELL", "hash": "50f22be172ea3127350da54b40ef6cb8c06e79c4", "best_bid": "0.28", "best_ask": "0.43"}], "timestamp": "1769384981672", "event_type": "price_change"}}
{"_local_timestamp": "2026-01-25T23:50:18.791130+00:00", "data": {"market": "0x26ebe9f65bd68ddedda46fd178b35f849aae4607e1265df3ef7243f99829f195", "price_changes": [{"asset_id": "86353192546542495916641527487272540176875193724127522627725581591930228417624", "price": "0.56", "size": "30", "side": "BUY", "hash": "8e8b0a0372106879903a889d7ff9d398179607ef", "best_bid": "0.57", "best_ask": "0.72"}, {"asset_id": "63808367585655921040786645798394416641162584754134130888507371817017552687973", "price": "0.44", "size": "30", "side": "SELL", "hash": "1ecaaf56ffe8a5f97e23d86478922f75ab8bf53c", "best_bid": "0.28", "best_ask": "0.43"}], "timestamp": "1769385018719", "event_type": "price_change"}}
{"_local_timestamp": "2026-01-25T23:50:19.496393+00:00", "data": {"market": "0x26ebe9f65bd68ddedda46fd178b35f849aae4607e1265df3ef7243f99829f195", "price_changes": [{"asset_id": "86353192546542495916641527487272540176875193724127522627725581591930228417624", "price": "0.56", "size": "0", "side": "BUY", "hash": "bc555826d7a28fc2c44195224723cb02bd013e6a", "best_bid": "0.57", "best_ask": "0.72"}, {"asset_id": "63808367585655921040786645798394416641162584754134130888507371817017552687973", "price": "0.44", "size": "0", "side": "SELL", "hash": "ef60d7fa630874b76c0fd3222c740e5732735f5e", "best_bid": "0.28", "best_ask": "0.43"}], "timestamp": "1769385019422", "event_type": "price_change"}}
{"_local_timestamp": "2026-01-25T23:50:19.570071+00:00", "data": {"market": "0x26ebe9f65bd68ddedda46fd178b35f849aae4607e1265df3ef7243f99829f195", "price_changes": [{"asset_id": "86353192546542495916641527487272540176875193724127522627725581591930228417624", "price": "0.53", "size": "165.89", "side": "BUY", "hash": "ae3b8f0942f767a74b105dd3f3dc9362cc0ed249", "best_bid": "0.57", "best_ask": "0.72"}, {"asset_id": "63808367585655921040786645798394416641162584754134130888507371817017552687973", "price": "0.47", "size": "165.89", "side": "SELL", "hash": "4c50eb066e8d5cccf762b721d3083fa4a0a0ff79", "best_bid": "0.28", "best_ask": "0.43"}], "timestamp": "1769385019499", "event_type": "price_change"}}
{"_local_timestamp": "2026-01-25T23:50:38.007989+00:00", "data": {"market": "0x26ebe9f65bd68ddedda46fd178b35f849aae4607e1265df3ef7243f99829f195", "price_changes": [{"asset_id": "63808367585655921040786645798394416641162584754134130888507371817017552687973", "price": "0.1", "size": "85", "side": "BUY", "hash": "348ea8fabcf23b0cefa8b4446d0b5a144582c700", "best_bid": "0.28", "best_ask": "0.43"}, {"asset_id": "86353192546542495916641527487272540176875193724127522627725581591930228417624", "price": "0.9", "size": "85", "side": "SELL", "hash": "81746090cf9e128768d34be9f11021bb570b94ca", "best_bid": "0.57", "best_ask": "0.72"}], "timestamp": "1769385037934", "event_type": "price_change"}}
{"_local_timestamp": "2026-01-25T23:50:38.008512+00:00", "data": {"market": "0x22cb289f07f3da4d3525f1c3944010a05c77d21ecf451719959ae54d24edcdb3", "price_changes": [{"asset_id": "87804592479196466711777128999586900823008283860411163575393570799751833246120", "price": "0.01", "size": "49.99", "side": "BUY", "hash": "f17e51cf69cda34c779543b1a09b148bb886673b", "best_bid": "0.78", "best_ask": "0.81"}, {"asset_id": "63319160664943786518939060358909912675713743438409851354160257846337485458777", "price": "0.99", "size": "49.99", "side": "SELL", "hash": "2abdc94498a09330f26988d60c46f32be58e0e0f", "best_bid": "0.19", "best_ask": "0.22"}], "timestamp": "1769385037934", "event_type": "price_change"}}
{"_local_timestamp": "2026-01-25T23:50:38.730698+00:00", "data": {"market": "0x26ebe9f65bd68ddedda46fd178b35f849aae4607e1265df3ef7243f99829f195", "price_changes": [{"asset_id": "63808367585655921040786645798394416641162584754134130888507371817017552687973", "price": "0.09", "size": "6.16", "side": "BUY", "hash": "7424be60c4d10deacca9c059b92f24e4a22b2f7f", "best_bid": "0.28", "best_ask": "0.43"}, {"asset_id": "86353192546542495916641527487272540176875193724127522627725581591930228417624", "price": "0.91", "size": "6.16", "side": "SELL", "hash": "3b508349af7c6f09d9bd619af9ee2124ff56b832", "best_bid": "0.57", "best_ask": "0.72"}], "timestamp": "1769385038643", "event_type": "price_change"}}
{"_local_timestamp": "2026-01-25T23:50:38.731263+00:00", "data": {"market": "0x22cb289f07f3da4d3525f1c3944010a05c77d21ecf451719959ae54d24edcdb3", "price_changes": [{"asset_id": "87804592479196466711777128999586900823008283860411163575393570799751833246120", "price": "0.01", "size": "57", "side": "BUY", "hash": "ef0717551e3063293b325151e33b8a963809f065", "best_bid": "0.78", "best_ask": "0.81"}, {"asset_id": "63319160664943786518939060358909912675713743438409851354160257846337485458777", "price": "0.99", "size": "57", "side": "SELL", "hash": "6d2ef336e2b8bd5347ba024567b6e085aa353357", "best_bid": "0.19", "best_ask": "0.22"}], "timestamp": "1769385038643", "event_type": "price_change"}}
{"_local_timestamp": "2026-01-25T23:51:09.685949+00:00", "data": {"market": "0x26ebe9f65bd68ddedda46fd178b35f849aae4607e1265df3ef7243f99829f195", "price_changes": [{"asset_id": "86353192546542495916641527487272540176875193724127522627725581591930228417624", "price": "0.57", "size": "0", "side": "BUY", "hash": "c3d7b30a39052f67443c31f37ed9e882a6d063c0", "best_bid": "0.55", "best_ask": "0.72"}, {"asset_id": "63808367585655921040786645798394416641162584754134130888507371817017552687973", "price": "0.43", "size": "0", "side": "SELL", "hash": "0a2a0514bb0ae861cccc3407bb0ff379d6a53be1", "best_bid": "0.28", "best_ask": "0.45"}], "timestamp": "1769385069610", "event_type": "price_change"}}
{"_local_timestamp": "2026-01-25T23:51:09.722939+00:00", "data": {"market": "0x26ebe9f65bd68ddedda46fd178b35f849aae4607e1265df3ef7243f99829f195", "price_changes": [{"asset_id": "86353192546542495916641527487272540176875193724127522627725581591930228417624", "price": "0.52", "size": "8.5", "side": "BUY", "hash": "686b8428ffaccf37a97a54441957f520470ee3a8", "best_bid": "0.55", "best_ask": "0.72"}, {"asset_id": "63808367585655921040786645798394416641162584754134130888507371817017552687973", "price": "0.48", "size": "8.5", "side": "SELL", "hash": "421c47f518821926e5068ec303b801ed2c55e866", "best_bid": "0.28", "best_ask": "0.45"}], "timestamp": "1769385069650", "event_type": "price_change"}}
{"_local_timestamp": "2026-01-25T23:51:09.823781+00:00", "data": {"market": "0x26ebe9f65bd68ddedda46fd178b35f849aae4607e1265df3ef7243f99829f195", "price_changes": [{"asset_id": "63808367585655921040786645798394416641162584754134130888507371817017552687973", "price": "0.15", "size": "133.33", "side": "BUY", "hash": "43d8b6b8bbc8b52407fcc9c8c3db4ed9e31f3cfd", "best_bid": "0.28", "best_ask": "0.45"}, {"asset_id": "86353192546542495916641527487272540176875193724127522627725581591930228417624", "price": "0.85", "size": "133.33", "side": "SELL", "hash": "4a646b18d2c80d365d4b6b19459280d2188b338d", "best_bid": "0.55", "best_ask": "0.72"}], "timestamp": "1769385069750", "event_type": "price_change"}}
{"_local_timestamp": "2026-01-25T23:51:09.883028+00:00", "data": {"market": "0x26ebe9f65bd68ddedda46fd178b35f849aae4607e1265df3ef7243f99829f195", "price_changes": [{"asset_id": "63808367585655921040786645798394416641162584754134130888507371817017552687973", "price": "0.13", "size": "184.61", "side": "BUY", "hash": "35f964171f4b5562b0cdd01fc5c326659028d5de", "best_bid": "0.28", "best_ask": "0.45"}, {"asset_id": "86353192546542495916641527487272540176875193724127522627725581591930228417624", "price": "0.87", "size": "184.61", "side": "SELL", "hash": "735ed91e6654355907433b5e3b696108030fab21", "best_bid": "0.55", "best_ask": "0.72"}], "timestamp": "1769385069808", "event_type": "price_change"}}
{"_local_timestamp": "2026-01-25T23:51:09.938672+00:00", "data": {"market": "0x26ebe9f65bd68ddedda46fd178b35f849aae4607e1265df3ef7243f99829f195", "price_changes": [{"asset_id": "63808367585655921040786645798394416641162584754134130888507371817017552687973", "price": "0.11", "size": "236.36", "side": "BUY", "hash": "cb4218881bf63d5147f9c19eeddfa1286f2d6297", "best_bid": "0.28", "best_ask": "0.45"}, {"asset_id": "86353192546542495916641527487272540176875193724127522627725581591930228417624", "price": "0.89", "size": "236.36", "side": "SELL", "hash": "d48b6eb06d14aeeb100d8a7d3916cff292e14ce4", "best_bid": "0.55", "best_ask": "0.72"}], "timestamp": "1769385069867", "event_type": "price_change"}}
{"_local_timestamp": "2026-01-25T23:51:09.996250+00:00", "data": {"market": "0x26ebe9f65bd68ddedda46fd178b35f849aae4607e1265df3ef7243f99829f195", "price_changes": [{"asset_id": "63808367585655921040786645798394416641162584754134130888507371817017552687973", "price": "0.1", "size": "365", "side": "BUY", "hash": "8c2100f4a120783ffd0b08b4bb279ea78de29c68", "best_bid": "0.28", "best_ask": "0.45"}, {"asset_id": "86353192546542495916641527487272540176875193724127522627725581591930228417624", "price": "0.9", "size": "365", "side": "SELL", "hash": "075f99fae5d69de588e10b279a4ef8438bb04ffa", "best_bid": "0.55", "best_ask": "0.72"}], "timestamp": "1769385069926", "event_type": "price_change"}}
{"_local_timestamp": "2026-01-25T23:51:10.056481+00:00", "data": {"market": "0x26ebe9f65bd68ddedda46fd178b35f849aae4607e1265df3ef7243f99829f195", "price_changes": [{"asset_id": "63808367585655921040786645798394416641162584754134130888507371817017552687973", "price": "0.08", "size": "700", "side": "BUY", "hash": "684b0196d3387f47b853251a2144269b1b984c43", "best_bid": "0.28", "best_ask": "0.45"}, {"asset_id": "86353192546542495916641527487272540176875193724127522627725581591930228417624", "price": "0.92", "size": "700", "side": "SELL", "hash": "dcc3e5881aea824d48d3d8a08e6fbf32bb57b999", "best_bid": "0.55", "best_ask": "0.72"}], "timestamp": "1769385069988", "event_type": "price_change"}}
{"_local_timestamp": "2026-01-25T23:51:10.133655+00:00", "data": {"market": "0x26ebe9f65bd68ddedda46fd178b35f849aae4607e1265df3ef7243f99829f195", "price_changes": [{"asset_id": "63808367585655921040786645798394416641162584754134130888507371817017552687973", "price": "0.06", "size": "10566.66", "side": "BUY", "hash": "a6b6810b489cd90f466cc99168f8fb8623c20352", "best_bid": "0.28", "best_ask": "0.45"}, {"asset_id": "86353192546542495916641527487272540176875193724127522627725581591930228417624", "price": "0.94", "size": "10566.66", "side": "SELL", "hash": "e7150588ae0f5249ae81be6406ecf3fc2fe31ef9", "best_bid": "0.55", "best_ask": "0.72"}], "timestamp": "1769385070046", "event_type": "price_change"}}
{"_local_timestamp": "2026-01-25T23:51:10.166961+00:00", "data": {"market": "0x26ebe9f65bd68ddedda46fd178b35f849aae4607e1265df3ef7243f99829f195", "price_changes": [{"asset_id": "63808367585655921040786645798394416641162584754134130888507371817017552687973", "price": "0.04", "size": "12500", "side": "BUY", "hash": "fe77ba3a5e6409abb33da67f28db123edf344409", "best_bid": "0.28", "best_ask": "0.45"}, {"asset_id": "86353192546542495916641527487272540176875193724127522627725581591930228417624", "price": "0.96", "size": "12500", "side": "SELL", "hash": "8a32abd48eddadc6d2e5f57cf3fda2369f3099c8", "best_bid": "0.55", "best_ask": "0.72"}], "timestamp": "1769385070096", "event_type": "price_change"}}
