{"_local_timestamp": "2026-01-25T23:40:59.811224+00:00", "data": [{"market": "0x607a934e2b8c4275c4cb5a74c2ad7d9064554eb296fb4e2971cf3b7d76a927cc", "asset_id": "25975914361944378835569532810779694498194030305365204669451325469087977433544", "timestamp": "1769384440645", "hash": "72390d41f1081c0b3f6376bcce96b2566ad4c33e", "bids": [{"price": "0.001", "size": "2200.99"}, {"price": "0.002", "size": "250"}, {"price": "0.003", "size": "9.14"}, {"price": "0.01", "size": "103.98"}, {"price": "0.011", "size": "11.18"}, {"price": "0.019", "size": "684.21"}, {"price": "0.02", "size": "33.17"}, {"price": "0.021", "size": "6"}, {"price": "0.023", "size": "10.88"}, {"price": "0.024", "size": "6"}, {"price": "0.041", "size": "134.14"}, {"price": "0.043", "size": "6"}, {"price": "0.066", "size": "33.17"}, {"price": "0.07", "size": "6"}, {"price": "0.11", "size": "31"}, {"price": "0.112", "size": "28.36"}], "asks": [{"price": "0.999", "size": "6105.84"}, {"price": "0.998", "size": "1255.95"}, {"price": "0.997", "size": "1000"}, {"price": "0.996", "size": "12.59"}, {"price": "0.99", "size": "7900"}, {"price": "0.989", "size": "5.13"}, {"price": "0.98", "size": "3250"}, {"price": "0.979", "size": "10.09"}, {"price": "0.96", "size": "500"}, {"price": "0.95", "size": "30"}, {"price": "0.94", "size": "433"}, {"price": "0.939", "size": "8.52"}, {"price": "0.91", "size": "700"}, {"price": "0.87", "size": "586.53"}, {"price": "0.82", "size": "177.77"}, {"price": "0.817", "size": "1024"}, {"price": "0.816", "size": "100"}, {"price": "0.815", "size": "6.18"}, {"price": "0.78", "size": "127.27"}, {"price": "0.775", "size": "150"}, {"price": "0.774", "size": "1858"}, {"price": "0.73", "size": "96.29"}, {"price": "0.69", "size": "77.41"}, {"price": "0.689", "size": "163"}, {"price": "0.66", "size": "150"}, {"price": "0.64", "size": "105.55"}, {"price": "0.639", "size": "75"}, {"price": "0.638", "size": "5"}, {"price": "0.39", "size": "100"}, {"price": "0.222", "size": "16.7"}, {"price": "0.221", "size": "6"}, {"price": "0.217", "size": "14.04"}, {"price": "0.216", "size": "20"}, {"price": "0.215", "size": "6"}, {"price": "0.157", "size": "100"}, {"price": "0.156", "size": "163.71"}, {"price": "0.144", "size": "13"}, {"price": "0.143", "size": "6"}, {"price": "0.122", "size": "12.4"}], "event_type": "book", "last_trade_price": "0.114"}, {"market": "0x36352906a435bb57bbce5c12b8a016b42beee442645c27e025a6b605f167dbe1", "asset_id": "24865128979064458140408638815995003118177598043357620452530421257540758944225", "timestamp": "1769384444333", "hash": "f183540423169061f41359ee747b8e8e1f95e6b8", "bids": [{"price": "0.001", "size": "3081.88"}, {"price": "0.002", "size": "1255.87"}, {"price": "0.003", "size": "1000"}, {"price": "0.004", "size": "10.16"}, {"price": "0.01", "size": "7900"}, {"price": "0.011", "size": "5.16"}, {"price": "0.02", "size": "2000"}, {"price": "0.021", "size": "12.53"}, {"price": "0.05", "size": "30"}, {"price": "0.051", "size": "39"}, {"price": "0.06", "size": "400"}, {"price": "0.07", "size": "300"}, {"price": "0.071", "size": "7.37"}, {"price": "0.1", "size": "560"}, {"price": "0.14", "size": "567.85"}, {"price": "0.19", "size": "168.42"}, {"price": "0.194", "size": "974"}, {"price": "0.195", "size": "105.63"}, {"price": "0.24", "size": "116.66"}, {"price": "0.244", "size": "200"}, {"price": "0.245", "size": "1714"}, {"price": "0.27", "size": "50"}, {"price": "0.29", "size": "89.65"}, {"price": "0.33", "size": "72.72"}, {"price": "0.38", "size": "52.63"}, {"price": "0.385", "size": "1683"}, {"price": "0.388", "size": "10"}, {"price": "0.389", "size": "20"}, {"price": "0.392", "size": "5"}, {"price": "0.912", "size": "29.06"}, {"price": "0.92", "size": "200"}, {"price": "0.931", "size": "132"}, {"price": "0.944", "size": "20"}, {"price": "0.946", "size": "104"}, {"price": "0.947", "size": "99.55"}], "asks": [{"price": "0.999", "size": "6473.99"}, {"price": "0.998", "size": "37.42"}, {"price": "0.992", "size": "1858.59"}, {"price": "0.991", "size": "250"}, {"price": "0.99", "size": "105"}, {"price": "0.989", "size": "6.98"}, {"price": "0.988", "size": "11.17"}, {"price": "0.971", "size": "20"}, {"price": "0.97", "size": "500"}, {"price": "0.968", "size": "121.68"}, {"price": "0.958", "size": "404"}, {"price": "0.957", "size": "173"}], "event_type": "book", "last_trade_price": "0.043"}, {"market": "0xa9707d0632a18e9496ef040de9b74c5c61ccc606ac451405386d79572eb9f166", "asset_id": "19957097729009409865126104158146797340316615617946360478599220326663878583242", "timestamp": "1769384106355", "hash": "0c2c7f6dc2d748952083e6d11e60c2ca090a6d24", "bids": [{"price": "0.01", "size": "7911.46"}, {"price": "0.02", "size": "3250"}, {"price": "0.03", "size": "8.73"}, {"price": "0.04", "size": "500"}, {"price": "0.05", "size": "30"}, {"price": "0.06", "size": "433"}, {"price": "0.07", "size": "6.72"}, {"price": "0.09", "size": "700"}, {"price": "0.14", "size": "567.85"}, {"price": "0.18", "size": "177.77"}, {"price": "0.19", "size": "1092"}, {"price": "0.2", "size": "5.76"}, {"price": "0.23", "size": "171.73"}, {"price": "0.27", "size": "96.29"}, {"price": "0.28", "size": "250"}, {"price": "0.29", "size": "50"}, {"price": "0.32", "size": "75"}, {"price": "0.36", "size": "130.55"}, {"price": "0.37", "size": "5"}, {"price": "0.57", "size": "100"}, {"price": "0.58", "size": "6"}, {"price": "0.78", "size": "16.66"}, {"price": "0.79", "size": "13.92"}, {"price": "0.8", "size": "66"}, {"price": "0.81", "size": "6"}, {"price": "0.82", "size": "12.66"}, {"price": "0.83", "size": "20.66"}, {"price": "0.84", "size": "6"}, {"price": "0.85", "size": "13"}, {"price": "0.86", "size": "71.21"}], "asks": [{"price": "0.99", "size": "105"}, {"price": "0.98", "size": "14.28"}, {"price": "0.97", "size": "6"}, {"price": "0.96", "size": "200"}, {"price": "0.95", "size": "260"}, {"price": "0.94", "size": "97.66"}, {"price": "0.92", "size": "6"}, {"price": "0.91", "size": "40"}, {"price": "0.9", "size": "1180"}, {"price": "0.89", "size": "241.66"}, {"price": "0.88", "size": "7.86"}], "event_type": "book", "last_trade_price": "0.120"}, {"market": "0xf65b917d7c4c2d6e01266807b8b7fa49eb9fd00bad3b7413529c264261470a44", "asset_id": "114083583916459364671762732480092206829910491378286392673263703828161447677389", "timestamp": "1769384420172", "hash": "0c2f76fbb5e129666f7e145eb2c612ccc2391668", "bids": [{"price": "0.01", "size": "7911.97"}, {"price": "0.02", "size": "3250"}, {"price": "0.03", "size": "7.37"}, {"price": "0.04", "size": "500"}, {"price": "0.05", "size": "30"}, {"price": "0.06", "size": "400"}, {"price": "0.07", "size": "7.27"}, {"price": "0.08", "size": "750"}, {"price": "0.12", "size": "608.33"}, {"price": "0.16", "size": "200"}, {"price": "0.17", "size": "1190"}, {"price": "0.18", "size": "6.38"}, {"price": "0.2", "size": "140"}, {"price": "0.21", "size": "9"}, {"price": "0.22", "size": "200"}, {"price": "0.23", "size": "300"}, {"price": "0.24", "size": "1748"}, {"price": "0.25", "size": "104"}, {"price": "0.27", "size": "50"}, {"price": "0.29", "size": "82.75"}, {"price": "0.33", "size": "60.6"}, {"price": "0.34", "size": "125"}, {"price": "0.66", "size": "19.69"}, {"price": "0.67", "size": "16.41"}, {"price": "0.7", "size": "30"}, {"price": "0.73", "size": "1592"}, {"price": "0.74", "size": "828"}], "asks": [{"price": "0.99", "size": "2105"}, {"price": "0.98", "size": "52"}, {"price": "0.97", "size": "9.52"}, {"price": "0.94", "size": "20"}, {"price": "0.87", "size": "100"}, {"price": "0.85", "size": "73.33"}, {"price": "0.84", "size": "10"}, {"price": "0.8", "size": "1288"}, {"price": "0.79", "size": "2064"}, {"price": "0.78", "size": "468.18"}], "event_type": "book", "last_trade_price": "0.230"}, {"market": "0xa9707d0632a18e9496ef040de9b74c5c61ccc606ac451405386d79572eb9f166", "asset_id": "34597002803401285682259130297309092388381875227212304953516939814034307296564", "timestamp": "1769384106355", "hash": "729be8973792ccb20547eff3da83e0fc114dfc2a", "bids": [{"price": "0.01", "size": "105"}, {"price": "0.02", "size": "14.28"}, {"price": "0.03", "size": "6"}, {"price": "0.04", "size": "200"}, {"price": "0.05", "size": "260"}, {"price": "0.06", "size": "97.66"}, {"price": "0.08", "size": "6"}, {"price": "0.09", "size": "40"}, {"price": "0.1", "size": "1180"}, {"price": "0.11", "size": "241.66"}, {"price": "0.12", "size": "7.86"}], "asks": [{"price": "0.99", "size": "7911.46"}, {"price": "0.98", "size": "3250"}, {"price": "0.97", "size": "8.73"}, {"price": "0.96", "size": "500"}, {"price": "0.95", "size": "30"}, {"price": "0.94", "size": "433"}, {"price": "0.93", "size": "6.72"}, {"price": "0.91", "size": "700"}, {"price": "0.86", "size": "567.85"}, {"price": "0.82", "size": "177.77"}, {"price": "0.81", "size": "1092"}, {"price": "0.8", "size": "5.76"}, {"price": "0.77", "size": "171.73"}, {"price": "0.73", "size": "96.29"}, {"price": "0.72", "size": "250"}, {"price": "0.71", "size": "50"}, {"price": "0.68", "size": "75"}, {"price": "0.64", "size": "130.55"}, {"price": "0.63", "size": "5"}, {"price": "0.43", "size": "100"}, {"price": "0.42", "size": "6"}, {"price": "0.22", "size": "16.66"}, {"price": "0.21", "size": "13.92"}, {"price": "0.2", "size": "66"}, {"price": "0.19", "size": "6"}, {"price": "0.18", "size": "12.66"}, {"price": "0.17", "size": "20.66"}, {"price": "0.16", "size": "6"}, {"price": "0.15", "size": "13"}, {"price": "0.14", "size": "71.21"}], "event_type": "book", "last_trade_price": "0.120"}, {"market": "0xf65b917d7c4c2d6e01266807b8b7fa49eb9fd00bad3b7413529c264261470a44", "asset_id": "21935961644840571543456790578994599010779256576943062204718832399472703918846", "timestamp": "1769384420172", "hash": "28f9027a5953c935e241f4794952cc666c5a97e2", "bids": [{"price": "0.01", "size": "2105"}, {"price": "0.02", "size": "52"}, {"price": "0.03", "size": "9.52"}, {"price": "0.06", "size": "20"}, {"price": "0.13", "size": "100"}, {"price": "0.15", "size": "73.33"}, {"price": "0.16", "size": "10"}, {"price": "0.2", "size": "1288"}, {"price": "0.21", "size": "2064"}, {"price": "0.22", "size": "468.18"}], "asks": [{"price": "0.99", "size": "7911.97"}, {"price": "0.98", "size": "3250"}, {"price": "0.97", "size": "7.37"}, {"price": "0.96", "size": "500"}, {"price": "0.95", "size": "30"}, {"price": "0.94", "size": "400"}, {"price": "0.93", "size": "7.27"}, {"price": "0.92", "size": "750"}, {"price": "0.88", "size": "608.33"}, {"price": "0.84", "size": "200"}, {"price": "0.83", "size": "1190"}, {"price": "0.82", "size": "6.38"}, {"price": "0.8", "size": "140"}, {"price": "0.79", "size": "9"}, {"price": "0.78", "size": "200"}, {"price": "0.77", "size": "300"}, {"price": "0.76", "size": "1748"}, {"price": "0.75", "size": "104"}, {"price": "0.73", "size": "50"}, {"price": "0.71", "size": "82.75"}, {"price": "0.67", "size": "60.6"}, {"price": "0.66", "size": "125"}, {"price": "0.34", "size": "19.69"}, {"price": "0.33", "size": "16.41"}, {"price": "0.3", "size": "30"}, {"price": "0.27", "size": "1592"}, {"price": "0.26", "size": "828"}], "event_type": "book", "last_trade_price": "0.230"}, {"market": "0x607a934e2b8c4275c4cb5a74c2ad7d9064554eb296fb4e2971cf3b7d76a927cc", "asset_id": "68148598936481792878619902635048180980784414819164814468271718813144330892107", "timestamp": "1769384440645", "hash": "7b4bef6e3aaddbd3ab811a2cfcd43f7093341f44", "bids": [{"price": "0.001", "size": "6105.84"}, {"price": "0.002", "size": "1255.95"}, {"price": "0.003", "size": "1000"}, {"price": "0.004", "size": "12.59"}, {"price": "0.01", "size": "7900"}, {"price": "0.011", "size": "5.13"}, {"price": "0.02", "size": "3250"}, {"price": "0.021", "size": "10.09"}, {"price": "0.04", "size": "500"}, {"price": "0.05", "size": "30"}, {"price": "0.06", "size": "433"}, {"price": "0.061", "size": "8.52"}, {"price": "0.09", "size": "700"}, {"price": "0.13", "size": "586.53"}, {"price": "0.18", "size": "177.77"}, {"price": "0.183", "size": "1024"}, {"price": "0.184", "size": "100"}, {"price": "0.185", "size": "6.18"}, {"price": "0.22", "size": "127.27"}, {"price": "0.225", "size": "150"}, {"price": "0.226", "size": "1858"}, {"price": "0.27", "size": "96.29"}, {"price": "0.31", "size": "77.41"}, {"price": "0.311", "size": "163"}, {"price": "0.34", "size": "150"}, {"price": "0.36", "size": "105.55"}, {"price": "0.361", "size": "75"}, {"price": "0.362", "size": "5"}, {"price": "0.61", "size": "100"}, {"price": "0.778", "size": "16.7"}, {"price": "0.779", "size": "6"}, {"price": "0.783", "size": "14.04"}, {"price": "0.784", "size": "20"}, {"price": "0.785", "size": "6"}, {"price": "0.843", "size": "100"}, {"price": "0.844", "size": "163.71"}, {"price": "0.856", "size": "13"}, {"price": "0.857", "size": "6"}, {"price": "0.878", "size": "12.4"}], "asks": [{"price": "0.999", "size": "2200.99"}, {"price": "0.998", "size": "250"}, {"price": "0.997", "size": "9.14"}, {"price": "0.99", "size": "103.98"}, {"price": "0.989", "size": "11.18"}, {"price": "0.981", "size": "684.21"}, {"price": "0.98", "size": "33.17"}, {"price": "0.979", "size": "6"}, {"price": "0.977", "size": "10.88"}, {"price": "0.976", "size": "6"}, {"price": "0.959", "size": "134.14"}, {"price": "0.957", "size": "6"}, {"price": "0.934", "size": "33.17"}, {"price": "0.93", "size": "6"}, {"price": "0.89", "size": "31"}, {"price": "0.888", "size": "28.36"}], "event_type": "book", "last_trade_price": "0.114"}, {"market": "0x7587cc4497fc03e6bc20a2b9579d1a5cafd7778fcbd077f91f2c50fe5924259f", "asset_id": "113316597975241725413150018775135425644758743759237570300130816995662490799104", "timestamp": "1769384444376", "hash": "81ffb16513928f311cdc1b7bd55eccda84d34d42", "bids": [{"price": "0.01", "size": "105"}, {"price": "0.03", "size": "250"}, {"price": "0.04", "size": "325"}, {"price": "0.05", "size": "110"}, {"price": "0.06", "size": "10"}, {"price": "0.11", "size": "222.22"}, {"price": "0.12", "size": "1244.3"}, {"price": "0.13", "size": "1335"}], "asks": [{"price": "0.99", "size": "7911.71"}, {"price": "0.98", "size": "3250"}, {"price": "0.97", "size": "7.21"}, {"price": "0.96", "size": "500"}, {"price": "0.95", "size": "30"}, {"price": "0.94", "size": "400"}, {"price": "0.93", "size": "6.47"}, {"price": "0.91", "size": "700"}, {"price": "0.87", "size": "586.53"}, {"price": "0.83", "size": "188.23"}, {"price": "0.82", "size": "1138"}, {"price": "0.81", "size": "2216.38"}, {"price": "0.78", "size": "127.27"}, {"price": "0.76", "size": "100"}, {"price": "0.75", "size": "100"}, {"price": "0.74", "size": "100"}, {"price": "0.72", "size": "300"}, {"price": "0.7", "size": "80"}, {"price": "0.65", "size": "182.14"}, {"price": "0.64", "size": "5"}, {"price": "0.23", "size": "16.88"}, {"price": "0.22", "size": "14.1"}, {"price": "0.21", "size": "20"}, {"price": "0.18", "size": "876"}, {"price": "0.16", "size": "160"}, {"price": "0.15", "size": "122.36"}], "event_type": "book", "last_trade_price": "0.130"}, {"market": "0x36352906a435bb57bbce5c12b8a016b42beee442645c27e025a6b605f167dbe1", "asset_id": "31663847607839846905140169558614872784381523935014554710770021196634945212335", "timestamp": "1769384444333", "hash": "becc4dce73b03269f868c05d464237f653ffacea", "bids": [{"price": "0.001", "size": "6473.99"}, {"price": "0.002", "size": "37.42"}, {"price": "0.008", "size": "1858.59"}, {"price": "0.009", "size": "250"}, {"price": "0.01", "size": "105"}, {"price": "0.011", "size": "6.98"}, {"price": "0.012", "size": "11.17"}, {"price": "0.029", "size": "20"}, {"price": "0.03", "size": "500"}, {"price": "0.032", "size": "121.68"}, {"price": "0.042", "size": "404"}, {"price": "0.043", "size": "173"}], "asks": [{"price": "0.999", "size": "3081.88"}, {"price": "0.998", "size": "1255.87"}, {"price": "0.997", "size": "1000"}, {"price": "0.996", "size": "10.16"}, {"price": "0.99", "size": "7900"}, {"price": "0.989", "size": "5.16"}, {"price": "0.98", "size": "2000"}, {"price": "0.979", "size": "12.53"}, {"price": "0.95", "size": "30"}, {"price": "0.949", "size": "39"}, {"price": "0.94", "size": "400"}, {"price": "0.93", "size": "300"}, {"price": "0.929", "size": "7.37"}, {"price": "0.9", "size": "560"}, {"price": "0.86", "size": "567.85"}, {"price": "0.81", "size": "168.42"}, {"price": "0.806", "size": "974"}, {"price": "0.805", "size": "105.63"}, {"price": "0.76", "size": "116.66"}, {"price": "0.756", "size": "200"}, {"price": "0.755", "size": "1714"}, {"price": "0.73", "size": "50"}, {"price": "0.71", "size": "89.65"}, {"price": "0.67", "size": "72.72"}, {"price": "0.62", "size": "52.63"}, {"price": "0.615", "size": "1683"}, {"price": "0.612", "size": "10"}, {"price": "0.611", "size": "20"}, {"price": "0.608", "size": "5"}, {"price": "0.088", "size": "29.06"}, {"price": "0.08", "size": "200"}, {"price": "0.069", "size": "132"}, {"price": "0.056", "size": "20"}, {"price": "0.054", "size": "104"}, {"price": "0.053", "size": "99.55"}], "event_type": "book", "last_trade_price": "0.043"}, {"market": "0x4ae33b3cb1b0af888ea00e0a035376c0319a56a8c28fb3521b22d28ecebbd94e", "asset_id": "42198988154346812250834138785680555306267908473427754988530622923073091857651", "timestamp": "1769384440636", "hash": "2d303df413ffac21a3edf5efc71f6cd5e652781e", "bids": [{"price": "0.001", "size": "5566.99"}, {"price": "0.002", "size": "1250"}, {"price": "0.003", "size": "7.36"}, {"price": "0.006", "size": "83"}, {"price": "0.01", "size": "82.38"}, {"price": "0.011", "size": "10.61"}, {"price": "0.012", "size": "12"}, {"price": "0.013", "size": "11.29"}, {"price": "0.044", "size": "295.45"}, {"price": "0.045", "size": "122.22"}, {"price": "0.1", "size": "101"}, {"price": "0.129", "size": "20"}, {"price": "0.14", "size": "2366"}, {"price": "0.15", "size": "85.07"}, {"price": "0.188", "size": "523.61"}, {"price": "0.189", "size": "66.11"}], "asks": [{"price": "0.999", "size": "2037.93"}, {"price": "0.998", "size": "1256.03"}, {"price": "0.997", "size": "1000"}, {"price": "0.996", "size": "10.43"}, {"price": "0.99", "size": "7900"}, {"price": "0.989", "size": "5.29"}, {"price": "0.98", "size": "2000"}, {"price": "0.979", "size": "15.17"}, {"price": "0.95", "size": "30"}, {"price": "0.949", "size": "39"}, {"price": "0.94", "size": "400"}, {"price": "0.92", "size": "750"}, {"price": "0.919", "size": "6.04"}, {"price": "0.87", "size": "586.53"}, {"price": "0.83", "size": "188.23"}, {"price": "0.805", "size": "970"}, {"price": "0.804", "size": "105.48"}, {"price": "0.79", "size": "133.33"}, {"price": "0.785", "size": "100"}, {"price": "0.784", "size": "400"}, {"price": "0.783", "size": "1934"}, {"price": "0.74", "size": "100"}, {"price": "0.73", "size": "50"}, {"price": "0.7", "size": "80"}, {"price": "0.66", "size": "183.82"}, {"price": "0.659", "size": "5"}, {"price": "0.4", "size": "5"}, {"price": "0.287", "size": "18.23"}, {"price": "0.285", "size": "15.38"}, {"price": "0.284", "size": "20"}, {"price": "0.23", "size": "1011"}, {"price": "0.221", "size": "8.66"}, {"price": "0.22", "size": "26"}, {"price": "0.219", "size": "40"}, {"price": "0.2", "size": "708"}], "event_type": "book", "last_trade_price": "0.815"}, {"market": "0x4ae33b3cb1b0af888ea00e0a035376c0319a56a8c28fb3521b22d28ecebbd94e", "asset_id": "107400623134616690037387608110271592167652294064537261328022766347776836196386", "timestamp": "1769384440636", "hash": "28522eea283a2c308936e1f250acec908173a14b", "bids": [{"price": "0.001", "size": "2037.93"}, {"price": "0.002", "size": "1256.03"}, {"price": "0.003", "size": "1000"}, {"price": "0.004", "size": "10.43"}, {"price": "0.01", "size": "7900"}, {"price": "0.011", "size": "5.29"}, {"price": "0.02", "size": "2000"}, {"price": "0.021", "size": "15.17"}, {"price": "0.05", "size": "30"}, {"price": "0.051", "size": "39"}, {"price": "0.06", "size": "400"}, {"price": "0.08", "size": "750"}, {"price": "0.081", "size": "6.04"}, {"price": "0.13", "size": "586.53"}, {"price": "0.17", "size": "188.23"}, {"price": "0.195", "size": "970"}, {"price": "0.196", "size": "105.48"}, {"price": "0.21", "size": "133.33"}, {"price": "0.215", "size": "100"}, {"price": "0.216", "size": "400"}, {"price": "0.217", "size": "1934"}, {"price": "0.26", "size": "100"}, {"price": "0.27", "size": "50"}, {"price": "0.3", "size": "80"}, {"price": "0.34", "size": "183.82"}, {"price": "0.341", "size": "5"}, {"price": "0.6", "size": "5"}, {"price": "0.713", "size": "18.23"}, {"price": "0.715", "size": "15.38"}, {"price": "0.716", "size": "20"}, {"price": "0.77", "size": "1011"}, {"price": "0.779", "size": "8.66"}, {"price": "0.78", "size": "26"}, {"price": "0.781", "size": "40"}, {"price": "0.8", "size": "708"}], "asks": [{"price": "0.999", "size": "5566.99"}, {"price": "0.998", "size": "1250"}, {"price": "0.997", "size": "7.36"}, {"price": "0.994", "size": "83"}, {"price": "0.99", "size": "82.38"}, {"price": "0.989", "size": "10.61"}, {"price": "0.988", "size": "12"}, {"price": "0.987", "size": "11.29"}, {"price": "0.956", "size": "295.45"}, {"price": "0.955", "size": "122.22"}, {"price": "0.9", "size": "101"}, {"price": "0.871", "size": "20"}, {"price": "0.86", "size": "2366"}, {"price": "0.85", "size": "85.07"}, {"price": "0.812", "size": "523.61"}, {"price": "0.811", "size": "66.11"}], "event_type": "book", "last_trade_price": "0.815"}, {"market": "0x6bbe585f51aedf96a92a4395f195633858a50a7ee9d5961a183b2fd858e2217c", "asset_id": "56479600937284047243744777367008101014255165543721437768956239217955454610653", "timestamp": "1769384434518", "hash": "51886e675d1f1bd10dc095da690d4eca9f8dcfad", "bids": [{"price": "0.01", "size": "7911.65"}, {"price": "0.02", "size": "3250"}, {"price": "0.03", "size": "10.51"}, {"price": "0.04", "size": "500"}, {"price": "0.05", "size": "30"}, {"price": "0.06", "size": "433"}, {"price": "0.08", "size": "750"}, {"price": "0.09", "size": "5.56"}, {"price": "0.12", "size": "608.33"}, {"price": "0.16", "size": "200"}, {"price": "0.17", "size": "1190"}, {"price": "0.18", "size": "2332"}, {"price": "0.2", "size": "140"}, {"price": "0.21", "size": "5.08"}, {"price": "0.25", "size": "104"}, {"price": "0.26", "size": "200"}, {"price": "0.27", "size": "350"}, {"price": "0.29", "size": "82.75"}, {"price": "0.33", "size": "60.6"}, {"price": "0.34", "size": "125"}, {"price": "0.35", "size": "5"}, {"price": "0.65", "size": "49.42"}, {"price": "0.66", "size": "16.66"}, {"price": "0.73", "size": "17.8"}, {"price": "0.74", "size": "20"}, {"price": "0.76", "size": "10"}, {"price": "0.78", "size": "1937"}, {"price": "0.79", "size": "6"}, {"price": "0.8", "size": "191.87"}], "asks": [{"price": "0.99", "size": "105"}, {"price": "0.98", "size": "14.28"}, {"price": "0.94", "size": "250"}, {"price": "0.93", "size": "185.71"}, {"price": "0.92", "size": "68.75"}, {"price": "0.91", "size": "10"}, {"price": "0.85", "size": "20"}, {"price": "0.84", "size": "1950"}, {"price": "0.83", "size": "5.88"}], "event_type": "book", "last_trade_price": "0.170"}, {"market": "0x6bbe585f51aedf96a92a4395f195633858a50a7ee9d5961a183b2fd858e2217c", "asset_id": "75977696589176706909494914683666626840477786548124398411155958119219599758391", "timestamp": "1769384434518", "hash": "b4f30b7fd640d09f0b2651e1b36c58c663a6cd25", "bids": [{"price": "0.01", "size": "105"}, {"price": "0.02", "size": "14.28"}, {"price": "0.06", "size": "250"}, {"price": "0.07", "size": "185.71"}, {"price": "0.08", "size": "68.75"}, {"price": "0.09", "size": "10"}, {"price": "0.15", "size": "20"}, {"price": "0.16", "size": "1950"}, {"price": "0.17", "size": "5.88"}], "asks": [{"price": "0.99", "size": "7911.65"}, {"price": "0.98", "size": "3250"}, {"price": "0.97", "size": "10.51"}, {"price": "0.96", "size": "500"}, {"price": "0.95", "size": "30"}, {"price": "0.94", "size": "433"}, {"price": "0.92", "size": "750"}, {"price": "0.91", "size": "5.56"}, {"price": "0.88", "size": "608.33"}, {"price": "0.84", "size": "200"}, {"price": "0.83", "size": "1190"}, {"price": "0.82", "size": "2332"}, {"price": "0.8", "size": "140"}, {"price": "0.79", "size": "5.08"}, {"price": "0.75", "size": "104"}, {"price": "0.74", "size": "200"}, {"price": "0.73", "size": "350"}, {"price": "0.71", "size": "82.75"}, {"price": "0.67", "size": "60.6"}, {"price": "0.66", "size": "125"}, {"price": "0.65", "size": "5"}, {"price": "0.35", "size": "49.42"}, {"price": "0.34", "size": "16.66"}, {"price": "0.27", "size": "17.8"}, {"price": "0.26", "size": "20"}, {"price": "0.24", "size": "10"}, {"price": "0.22", "size": "1937"}, {"price": "0.21", "size": "6"}, {"price": "0.2", "size": "191.87"}], "event_type": "book", "last_trade_price": "0.170"}, {"market": "0x7587cc4497fc03e6bc20a2b9579d1a5cafd7778fcbd077f91f2c50fe5924259f", "asset_id": "28134581219669032059806644497841080110865577915276558812300476779313627788834", "timestamp": "1769384444376", "hash": "7cc4bbe41856198257dace97e549e0d59d93bada", "bids": [{"price": "0.01", "size": "7911.71"}, {"price": "0.02", "size": "3250"}, {"price": "0.03", "size": "7.21"}, {"price": "0.04", "size": "500"}, {"price": "0.05", "size": "30"}, {"price": "0.06", "size": "400"}, {"price": "0.07", "size": "6.47"}, {"price": "0.09", "size": "700"}, {"price": "0.13", "size": "586.53"}, {"price": "0.17", "size": "188.23"}, {"price": "0.18", "size": "1138"}, {"price": "0.19", "size": "2216.38"}, {"price": "0.22", "size": "127.27"}, {"price": "0.24", "size": "100"}, {"price": "0.25", "size": "100"}, {"price": "0.26", "size": "100"}, {"price": "0.28", "size": "300"}, {"price": "0.3", "size": "80"}, {"price": "0.35", "size": "182.14"}, {"price": "0.36", "size": "5"}, {"price": "0.77", "size": "16.88"}, {"price": "0.78", "size": "14.1"}, {"price": "0.79", "size": "20"}, {"price": "0.82", "size": "876"}, {"price": "0.84", "size": "160"}, {"price": "0.85", "size": "122.36"}], "asks": [{"price": "0.99", "size": "105"}, {"price": "0.97", "size": "250"}, {"price": "0.96", "size": "325"}, {"price": "0.95", "size": "110"}, {"price": "0.94", "size": "10"}, {"price": "0.89", "size": "222.22"}, {"price": "0.88", "size": "1244.3"}, {"price": "0.87", "size": "1335"}], "event_type": "book", "last_trade_price": "0.130"}]}
{"_local_timestamp": "2026-01-25T23:41:14.758099+00:00", "data": {"market": "0x7587cc4497fc03e6bc20a2b9579d1a5cafd7778fcbd077f91f2c50fe5924259f", "price_changes": [{"asset_id": "28134581219669032059806644497841080110865577915276558812300476779313627788834", "price": "0.19", "size": "6.38", "side": "BUY", "hash": "3ea8985d64a16fe8ca6447613a567597a6bdb8ed", "best_bid": "0.85", "best_ask": "0.87"}, {"asset_id": "113316597975241725413150018775135425644758743759237570300130816995662490799104", "price": "0.81", "size": "6.38", "side": "SELL", "hash": "2c493a6b6a0712a415197fce6f242c7c1e0c52cc", "best_bid": "0.13", "best_ask": "0.15"}], "timestamp": "1769384474537", "event_type": "price_change"}}
{"_local_timestamp": "2026-01-25T23:41:40.826806+00:00", "data": {"market": "0x607a934e2b8c4275c4cb5a74c2ad7d9064554eb296fb4e2971cf3b7d76a927cc", "price_changes": [{"asset_id": "68148598936481792878619902635048180980784414819164814468271718813144330892107", "price": "0.61", "size": "0", "side": "BUY", "hash": "3c4a249ab78919c0182f0c07d3c7c215545bf76e", "best_bid": "0.878", "best_ask": "0.888"}, {"asset_id": "25975914361944378835569532810779694498194030305365204669451325469087977433544", "price": "0.39", "size": "0", "side": "SELL", "hash": "c4d0078074d976433af795548f2ff7039658ff69", "best_bid": "0.112", "best_ask": "0.122"}], "timestamp": "1769384500754", "event_type": "price_change"}}
{"_local_timestamp": "2026-01-25T23:41:40.828298+00:00", "data": {"market": "0x607a934e2b8c4275c4cb5a74c2ad7d9064554eb296fb4e2971cf3b7d76a927cc", "price_changes": [{"asset_id": "68148598936481792878619902635048180980784414819164814468271718813144330892107", "price": "0.34", "size": "50", "side": "BUY", "hash": "3c4a249ab78919c0182f0c07d3c7c215545bf76e", "best_bid": "0.878", "best_ask": "0.888"}, {"asset_id": "25975914361944378835569532810779694498194030305365204669451325469087977433544", "price": "0.66", "size": "50", "side": "SELL", "hash": "c4d0078074d976433af795548f2ff7039658ff69", "best_bid": "0.112", "best_ask": "0.122"}], "timestamp": "1769384500754", "event_type": "price_change"}}
{"_local_timestamp": "2026-01-25T23:41:41.275201+00:00", "data": {"market": "0x607a934e2b8c4275c4cb5a74c2ad7d9064554eb296fb4e2971cf3b7d76a927cc", "price_changes": [{"asset_id": "68148598936481792878619902635048180980784414819164814468271718813144330892107", "price": "0.62", "size": "100", "side": "BUY", "hash": "7c190615d2022f2605b868fcae997ee3820ef22e", "best_bid": "0.878", "best_ask": "0.888"}, {"asset_id": "25975914361944378835569532810779694498194030305365204669451325469087977433544", "price": "0.38", "size": "100", "side": "SELL", "hash": "c1c0916575a6171a98b988d9632670aff6d9aaa6", "best_bid": "0.112", "best_ask": "0.122"}], "timestamp": "1769384501202", "event_type": "price_change"}}
{"_local_timestamp": "2026-01-25T23:41:41.394381+00:00", "data": {"market": "0x607a934e2b8c4275c4cb5a74c2ad7d9064554eb296fb4e2971cf3b7d76a927cc", "price_changes": [{"asset_id": "68148598936481792878619902635048180980784414819164814468271718813144330892107", "price": "0.361", "size": "175", "side": "BUY", "hash": "8c7960950f03129cd4ed4bc4ae8bf048b06efacb", "best_bid": "0.878", "best_ask": "0.888"}, {"asset_id": "25975914361944378835569532810779694498194030305365204669451325469087977433544", "price": "0.639", "size": "175", "side": "SELL", "hash": "7d40547851a1634bbbd83edb8dc0d306136935be", "best_bid": "0.112", "best_ask": "0.122"}], "timestamp": "1769384501324", "event_type": "price_change"}}
{"_local_timestamp": "2026-01-25T23:41:50.860098+00:00", "data": {"market": "0x36352906a435bb57bbce5c12b8a016b42beee442645c27e025a6b605f167dbe1", "price_changes": [{"asset_id": "24865128979064458140408638815995003118177598043357620452530421257540758944225", "price": "0.244", "size": "100", "side": "BUY", "hash": "ac3c6e42b98cc12413273dd12d66ff9b72808686", "best_bid": "0.947", "best_ask": "0.957"}, {"asset_id": "31663847607839846905140169558614872784381523935014554710770021196634945212335", "price": "0.756", "size": "100", "side": "SELL", "hash": "285c8096f33038cda8f15f7fae64c5f7bd7ea012", "best_bid": "0.043", "best_ask": "0.053"}], "timestamp": "1769384510737", "event_type": "price_change"}}
{"_local_timestamp": "2026-01-25T23:41:50.861063+00:00", "data": {"market": "0x607a934e2b8c4275c4cb5a74c2ad7d9064554eb296fb4e2971cf3b7d76a927cc", "price_changes": [{"asset_id": "68148598936481792878619902635048180980784414819164814468271718813144330892107", "price": "0.225", "size": "50", "side": "BUY", "hash": "d3a509f63b6c8e113655fb9188fb273a6f83ed70", "best_bid": "0.878", "best_ask": "0.888"}, {"asset_id": "25975914361944378835569532810779694498194030305365204669451325469087977433544", "price": "0.775", "size": "50", "side": "SELL", "hash": "cb80b45ff75d2c7fa93d15158fb9068e4aa9cfc9", "best_bid": "0.112", "best_ask": "0.122"}], "timestamp": "1769384510737", "event_type": "price_change"}}
{"_local_timestamp": "2026-01-25T23:41:50.861760+00:00", "data": {"market": "0x607a934e2b8c4275c4cb5a74c2ad7d9064554eb296fb4e2971cf3b7d76a927cc", "price_changes": [{"asset_id": "68148598936481792878619902635048180980784414819164814468271718813144330892107", "price": "0.361", "size": "100", "side": "BUY", "hash": "d3a509f63b6c8e113655fb9188fb273a6f83ed70", "best_bid": "0.878", "best_ask": "0.888"}, {"asset_id": "25975914361944378835569532810779694498194030305365204669451325469087977433544", "price": "0.639", "size": "100", "side": "SELL", "hash": "cb80b45ff75d2c7fa93d15158fb9068e4aa9cfc9", "best_bid": "0.112", "best_ask": "0.122"}], "timestamp": "1769384510737", "event_type": "price_change"}}
{"_local_timestamp": "2026-01-25T23:41:50.862445+00:00", "data": {"market": "0xf65b917d7c4c2d6e01266807b8b7fa49eb9fd00bad3b7413529c264261470a44", "price_changes": [{"asset_id": "114083583916459364671762732480092206829910491378286392673263703828161447677389", "price": "0.22", "size": "100", "side": "BUY", "hash": "0fc3e7b32188cde48dc83ed551a16eef4c27296f", "best_bid": "0.74", "best_ask": "0.78"}, {"asset_id": "21935961644840571543456790578994599010779256576943062204718832399472703918846", "price": "0.78", "size": "100", "side": "SELL", "hash": "da0cff14f0de95ea8272b1e28e54a6625cb2eb61", "best_bid": "0.22", "best_ask": "0.26"}], "timestamp": "1769384510737", "event_type": "price_change"}}
{"_local_timestamp": "2026-01-25T23:41:50.863163+00:00", "data": {"market": "0x6bbe585f51aedf96a92a4395f195633858a50a7ee9d5961a183b2fd858e2217c", "price_changes": [{"asset_id": "56479600937284047243744777367008101014255165543721437768956239217955454610653", "price": "0.26", "size": "100", "side": "BUY", "hash": "e7e8bffe20883123f844ec3c56dfadd141dd48f9", "best_bid": "0.8", "best_ask": "0.83"}, {"asset_id": "75977696589176706909494914683666626840477786548124398411155958119219599758391", "price": "0.74", "size": "100", "side": "SELL", "hash": "6d4946d73dd1eff42c8797f9dbc121762fac1dee", "best_bid": "0.17", "best_ask": "0.2"}], "timestamp": "1769384510737", "event_type": "price_change"}}
{"_local_timestamp": "2026-01-25T23:41:50.863830+00:00", "data": {"market": "0x4ae33b3cb1b0af888ea00e0a035376c0319a56a8c28fb3521b22d28ecebbd94e", "price_changes": [{"asset_id": "107400623134616690037387608110271592167652294064537261328022766347776836196386", "price": "0.215", "size": "0", "side": "BUY", "hash": "777a86dd4c5cc455113c2bc0e9ed8863504e7f06", "best_bid": "0.8", "best_ask": "0.811"}, {"asset_id": "42198988154346812250834138785680555306267908473427754988530622923073091857651", "price": "0.785", "size": "0", "side": "SELL", "hash": "03ae979652e0682448944cf64b730586f1a4dcc9", "best_bid": "0.189", "best_ask": "0.2"}], "timestamp": "1769384510737", "event_type": "price_change"}}
{"_local_timestamp": "2026-01-25T23:41:50.867366+00:00", "data": {"market": "0x7587cc4497fc03e6bc20a2b9579d1a5cafd7778fcbd077f91f2c50fe5924259f", "price_changes": [{"asset_id": "28134581219669032059806644497841080110865577915276558812300476779313627788834", "price": "0.24", "size": "0", "side": "BUY", "hash": "db5ff33f73769ec07499d28bd58e1df177c833fc", "best_bid": "0.85", "best_ask": "0.87"}, {"asset_id": "113316597975241725413150018775135425644758743759237570300130816995662490799104", "price": "0.76", "size": "0", "side": "SELL", "hash": "9e673298971f1beb648faa74fd98344576819f8b", "best_bid": "0.13", "best_ask": "0.15"}], "timestamp": "1769384510737", "event_type": "price_change"}}
{"_local_timestamp": "2026-01-25T23:41:52.103104+00:00", "data": {"market": "0x607a934e2b8c4275c4cb5a74c2ad7d9064554eb296fb4e2971cf3b7d76a927cc", "price_changes": [{"asset_id": "68148598936481792878619902635048180980784414819164814468271718813144330892107", "price": "0.36", "size": "180.55", "side": "BUY", "hash": "86593ecc9e19b08106d9f883eb0cffe31a257594", "best_bid": "0.878", "best_ask": "0.888"}, {"asset_id": "25975914361944378835569532810779694498194030305365204669451325469087977433544", "price": "0.64", "size": "180.55", "side": "SELL", "hash": "fb19e787a20b3562b08f06172a5f865719162d13", "best_bid": "0.112", "best_ask": "0.122"}], "timestamp": "1769384511714", "event_type": "price_change"}}
{"_local_timestamp": "2026-01-25T23:41:52.178431+00:00", "data": {"market": "0x4ae33b3cb1b0af888ea00e0a035376c0319a56a8c28fb3521b22d28ecebbd94e", "price_changes": [{"asset_id": "107400623134616690037387608110271592167652294064537261328022766347776836196386", "price": "0.216", "size": "500", "side": "BUY", "hash": "c9c520d0606bb721e139169904c7783dae8c230d", "best_bid": "0.8", "best_ask": "0.811"}, {"asset_id": "42198988154346812250834138785680555306267908473427754988530622923073091857651", "price": "0.784", "size": "500", "side": "SELL", "hash": "3878ecb38341b4d9f1e1b9795c7dd141bf6789b9", "best_bid": "0.189", "best_ask": "0.2"}], "timestamp": "1769384511722", "event_type": "price_change"}}
{"_local_timestamp": "2026-01-25T23:41:52.214501+00:00", "data": {"market": "0x6bbe585f51aedf96a92a4395f195633858a50a7ee9d5961a183b2fd858e2217c", "price_changes": [{"asset_id": "56479600937284047243744777367008101014255165543721437768956239217955454610653", "price": "0.27", "size": "450", "side": "BUY", "hash": "0f3fe06ddd5c030f3a9271e3fa0408cd9f43497d", "best_bid": "0.8", "best_ask": "0.83"}, {"asset_id": "75977696589176706909494914683666626840477786548124398411155958119219599758391", "price": "0.73", "size": "450", "side": "SELL", "hash": "ed2934dbcf1fc133c7a9fe44562fc25ecf6fc7df", "best_bid": "0.17", "best_ask": "0.2"}], "timestamp": "1769384511726", "event_type": "price_change"}}
{"_local_timestamp": "2026-01-25T23:41:52.358426+00:00", "data": {"market": "0xf65b917d7c4c2d6e01266807b8b7fa49eb9fd00bad3b7413529c264261470a44", "price_changes": [{"asset_id": "114083583916459364671762732480092206829910491378286392673263703828161447677389", "price": "0.23", "size": "400", "side": "BUY", "hash": "954a047e5285ea2f9f7cd41bca9a98ee928b756c", "best_bid": "0.74", "best_ask": "0.78"}, {"asset_id": "21935961644840571543456790578994599010779256576943062204718832399472703918846", "price": "0.77", "size": "400", "side": "SELL", "hash": "ee7299559d72557bba7ec17f5af6fc10fb72e48f", "best_bid": "0.22", "best_ask": "0.26"}], "timestamp": "1769384511729", "event_type": "price_change"}}
{"_local_timestamp": "2026-01-25T23:41:52.590740+00:00", "data": {"market": "0x7587cc4497fc03e6bc20a2b9579d1a5cafd7778fcbd077f91f2c50fe5924259f", "price_changes": [{"asset_id": "28134581219669032059806644497841080110865577915276558812300476779313627788834", "price": "0.28", "size": "400", "side": "BUY", "hash": "a4054590b5926183a0663980943b46fa777ff478", "best_bid": "0.85", "best_ask": "0.87"}, {"asset_id": "113316597975241725413150018775135425644758743759237570300130816995662490799104", "price": "0.72", "size": "400", "side": "SELL", "hash": "b9edcdc2dd07d7d3b2579ac00aaeb2060e852e30", "best_bid": "0.13", "best_ask": "0.15"}], "timestamp": "1769384511757", "event_type": "price_change"}}
{"_local_timestamp": "2026-01-25T23:41:52.621963+00:00", "data": {"market": "0x36352906a435bb57bbce5c12b8a016b42beee442645c27e025a6b605f167dbe1", "price_changes": [{"asset_id": "24865128979064458140408638815995003118177598043357620452530421257540758944225", "price": "0.24", "size": "216.66", "side": "BUY", "hash": "1c8d3b3c5aeeb29448dc9f737a13489a26e0ca81", "best_bid": "0.947", "best_ask": "0.957"}, {"asset_id": "31663847607839846905140169558614872784381523935014554710770021196634945212335", "price": "0.76", "size": "216.66", "side": "SELL", "hash": "c21166e68055bf23823935b91dc5bbebe5293e94", "best_bid": "0.043", "best_ask": "0.053"}], "timestamp": "1769384511751", "event_type": "price_change"}}
{"_local_timestamp": "2026-01-25T23:41:52.934372+00:00", "data": {"market": "0x607a934e2b8c4275c4cb5a74c2ad7d9064554eb296fb4e2971cf3b7d76a927cc", "price_changes": [{"asset_id": "68148598936481792878619902635048180980784414819164814468271718813144330892107", "price": "0.22", "size": "227.27", "side": "BUY", "hash": "72a284880c3a34033c6ddab4f78b85e14b1d9cfa", "best_bid": "0.878", "best_ask": "0.888"}, {"asset_id": "25975914361944378835569532810779694498194030305365204669451325469087977433544", "price": "0.78", "size": "227.27", "side": "SELL", "hash": "22055ca2a2528fc26f0bf6d483f932142a240b8e", "best_bid": "0.112", "best_ask": "0.122"}], "timestamp": "1769384512029", "event_type": "price_change"}}
{"_local_timestamp": "2026-01-25T23:42:08.142547+00:00", "data": {"market": "0x7587cc4497fc03e6bc20a2b9579d1a5cafd7778fcbd077f91f2c50fe5924259f", "price_changes": [{"asset_id": "28134581219669032059806644497841080110865577915276558812300476779313627788834", "price": "0.26", "size": "1714", "side": "BUY", "hash": "a00db178320975bd237dd3c46104d7824cd8b323", "best_bid": "0.85", "best_ask": "0.87"}, {"asset_id": "113316597975241725413150018775135425644758743759237570300130816995662490799104", "price": "0.74", "size": "1714", "side": "SELL", "hash": "9fc864b1560ac405184430d6e60bf2a67c1e40ca", "best_bid": "0.13", "best_ask": "0.15"}], "timestamp": "1769384528070", "event_type": "price_change"}}
{"_local_timestamp": "2026-01-25T23:42:08.164438+00:00", "data": {"market": "0x36352906a435bb57bbce5c12b8a016b42beee442645c27e025a6b605f167dbe1", "price_changes": [{"asset_id": "24865128979064458140408638815995003118177598043357620452530421257540758944225", "price": "0.926", "size": "20", "side": "BUY", "hash": "c00db1f17cf1da3a89a7de199728d682bcf17145", "best_bid": "0.947", "best_ask": "0.957"}, {"asset_id": "31663847607839846905140169558614872784381523935014554710770021196634945212335", "price": "0.074", "size": "20", "side": "SELL", "hash": "9b8e9ef5929f9755f802b5abd3607236d91c15f9", "best_bid": "0.043", "best_ask": "0.053"}], "timestamp": "1769384528094", "event_type": "price_change"}}
{"_local_timestamp": "2026-01-25T23:42:08.165364+00:00", "data": {"market": "0xf65b917d7c4c2d6e01266807b8b7fa49eb9fd00bad3b7413529c264261470a44", "price_changes": [{"asset_id": "114083583916459364671762732480092206829910491378286392673263703828161447677389", "price": "0.74", "size": "848", "side": "BUY", "hash": "379a16f80b75446a2d11c51057b315c7b3de65fb", "best_bid": "0.74", "best_ask": "0.78"}, {"asset_id": "21935961644840571543456790578994599010779256576943062204718832399472703918846", "price": "0.26", "size": "848", "side": "SELL", "hash": "e857f16c35edc9f9d7db3aca7df9945cc9e1dd1f", "best_bid": "0.22", "best_ask": "0.26"}], "timestamp": "1769384528095", "event_type": "price_change"}}
{"_local_timestamp": "2026-01-25T23:42:08.166179+00:00", "data": {"market": "0x7587cc4497fc03e6bc20a2b9579d1a5cafd7778fcbd077f91f2c50fe5924259f", "price_changes": [{"asset_id": "28134581219669032059806644497841080110865577915276558812300476779313627788834", "price": "0.83", "size": "20", "side": "BUY", "hash": "99cf946281d54a9ed1f7e11ed5e9f3ffe4b39f64", "best_bid": "0.85", "best_ask": "0.87"}, {"asset_id": "113316597975241725413150018775135425644758743759237570300130816995662490799104", "price": "0.17", "size": "20", "side": "SELL", "hash": "84962a07d99b918d27c12bf96cfd2f5756bebd19", "best_bid": "0.13", "best_ask": "0.15"}], "timestamp": "1769384528095", "event_type": "price_change"}}
{"_local_timestamp": "2026-01-25T23:42:08.167021+00:00", "data": {"market": "0x6bbe585f51aedf96a92a4395f195633858a50a7ee9d5961a183b2fd858e2217c", "price_changes": [{"asset_id": "56479600937284047243744777367008101014255165543721437768956239217955454610653", "price": "0.8", "size": "211.87", "side": "BUY", "hash": "48fdffba0cc2a4f3c5d09511f8ade4e9e7e61d11", "best_bid": "0.8", "best_ask": "0.83"}, {"asset_id": "75977696589176706909494914683666626840477786548124398411155958119219599758391", "price": "0.2", "size": "211.87", "side": "SELL", "hash": "37c71d9d6bc2f106e6b5af4f6d26712a61ff269e", "best_bid": "0.17", "best_ask": "0.2"}], "timestamp": "1769384528096", "event_type": "price_change"}}
{"_local_timestamp": "2026-01-25T23:42:08.168361+00:00", "data": {"market": "0x607a934e2b8c4275c4cb5a74c2ad7d9064554eb296fb4e2971cf3b7d76a927cc", "price_changes": [{"asset_id": "68148598936481792878619902635048180980784414819164814468271718813144330892107", "price": "0.857", "size": "26", "side": "BUY", "hash": "81eaac6ca357f3a9f88b76d2b3da53cf4d70bf11", "best_bid": "0.878", "best_ask": "0.888"}, {"asset_id": "25975914361944378835569532810779694498194030305365204669451325469087977433544", "price": "0.143", "size": "26", "side": "SELL", "hash": "5b7e8eb583611699414b7d60a3a3f541b80f532b", "best_bid": "0.112", "best_ask": "0.122"}], "timestamp": "1769384528099", "event_type": "price_change"}}
{"_local_timestamp": "2026-01-25T23:42:08.184534+00:00", "data": {"market": "0xa9707d0632a18e9496ef040de9b74c5c61ccc606ac451405386d79572eb9f166", "price_changes": [{"asset_id": "19957097729009409865126104158146797340316615617946360478599220326663878583242", "price": "0.85", "size": "33", "side": "BUY", "hash": "6f144299bd381f4bf2f028e892decc8ec04c7cbd", "best_bid": "0.86", "best_ask": "0.88"}, {"asset_id": "34597002803401285682259130297309092388381875227212304953516939814034307296564", "price": "0.15", "size": "33", "side": "SELL", "hash": "53f3bcbac4b63f6512d61b743726fa996e99b1c4", "best_bid": "0.12", "best_ask": "0.14"}], "timestamp": "1769384528111", "event_type": "price_change"}}
{"_local_timestamp": "2026-01-25T23:42:08.185465+00:00", "data": {"market": "0x4ae33b3cb1b0af888ea00e0a035376c0319a56a8c28fb3521b22d28ecebbd94e", "price_changes": [{"asset_id": "107400623134616690037387608110271592167652294064537261328022766347776836196386", "price": "0.78", "size": "46", "side": "BUY", "hash": "07f58248f552f9b74a4d44dc550e0f837d386f78", "best_bid": "0.8", "best_ask": "0.811"}, {"asset_id": "42198988154346812250834138785680555306267908473427754988530622923073091857651", "price": "0.22", "size": "46", "side": "SELL", "hash": "0715314ec21d5d059de74e69cf7b0f9634af4ea6", "best_bid": "0.189", "best_ask": "0.2"}], "timestamp": "1769384528117", "event_type": "price_change"}}
{"_local_timestamp": "2026-01-25T23:42:08.293239+00:00", "data": {"market": "0x6bbe585f51aedf96a92a4395f195633858a50a7ee9d5961a183b2fd858e2217c", "price_changes": [{"asset_id": "56479600937284047243744777367008101014255165543721437768956239217955454610653", "price": "0.79", "size": "56", "side": "BUY", "hash": "5d4f5ce9baf23a8847bd3094efaf740d5a19cb43", "best_bid": "0.8", "best_ask": "0.83"}, {"asset_id": "75977696589176706909494914683666626840477786548124398411155958119219599758391", "price": "0.21", "size": "56", "side": "SELL", "hash": "bbac90f17fe8dfc089a2ea2eada1332fba04a375", "best_bid": "0.17", "best_ask": "0.2"}], "timestamp": "1769384528205", "event_type": "price_change"}}
{"_local_timestamp": "2026-01-25T23:42:22.655049+00:00", "data": {"market": "0x607a934e2b8c4275c4cb5a74c2ad7d9064554eb296fb4e2971cf3b7d76a927cc", "price_changes": [{"asset_id": "68148598936481792878619902635048180980784414819164814468271718813144330892107", "price": "0.843", "size": "33", "side": "BUY", "hash": "9e822dcb588939f7b169701b75a53ceb21832940", "best_bid": "0.878", "best_ask": "0.888"}, {"asset_id": "25975914361944378835569532810779694498194030305365204669451325469087977433544", "price": "0.157", "size": "33", "side": "SELL", "hash": "1bb30c6bd069e33404e3f79e1256f06775b018a2", "best_bid": "0.112", "best_ask": "0.122"}], "timestamp": "1769384542581", "event_type": "price_change"}}
{"_local_timestamp": "2026-01-25T23:42:24.563852+00:00", "data": {"market": "0x607a934e2b8c4275c4cb5a74c2ad7d9064554eb296fb4e2971cf3b7d76a927cc", "price_changes": [{"asset_id": "68148598936481792878619902635048180980784414819164814468271718813144330892107", "price": "0.34", "size": "0", "side": "BUY", "hash": "e2bb05c594c820470935b07489a904d293e9f154", "best_bid": "0.878", "best_ask": "0.888"}, {"asset_id": "25975914361944378835569532810779694498194030305365204669451325469087977433544", "price": "0.66", "size": "0", "side": "SELL", "hash": "4ab53b7f498e46f8483eccb86169814f334bcf69", "best_bid": "0.112", "best_ask": "0.122"}], "timestamp": "1769384544476", "event_type": "price_change"}}
{"_local_timestamp": "2026-01-25T23:42:24.564706+00:00", "data": {"market": "0x7587cc4497fc03e6bc20a2b9579d1a5cafd7778fcbd077f91f2c50fe5924259f", "price_changes": [{"asset_id": "28134581219669032059806644497841080110865577915276558812300476779313627788834", "price": "0.18", "size": "1038", "side": "BUY", "hash": "730c98364b056ed46b984d3197ee5b92b40a0b98", "best_bid": "0.85", "best_ask": "0.87"}, {"asset_id": "113316597975241725413150018775135425644758743759237570300130816995662490799104", "price": "0.82", "size": "1038", "side": "SELL", "hash": "4775373dee57ab19334eee5575c9fc92838a4c59", "best_bid": "0.13", "best_ask": "0.15"}], "timestamp": "1769384544476", "event_type": "price_change"}}
{"_local_timestamp": "2026-01-25T23:42:24.565472+00:00", "data": {"market": "0x7587cc4497fc03e6bc20a2b9579d1a5cafd7778fcbd077f91f2c50fe5924259f", "price_changes": [{"asset_id": "28134581219669032059806644497841080110865577915276558812300476779313627788834", "price": "0.25", "size": "50", "side": "BUY", "hash": "730c98364b056ed46b984d3197ee5b92b40a0b98", "best_bid": "0.85", "best_ask": "0.87"}, {"asset_id": "113316597975241725413150018775135425644758743759237570300130816995662490799104", "price": "0.75", "size": "50", "side": "SELL", "hash": "4775373dee57ab19334eee5575c9fc92838a4c59", "best_bid": "0.13", "best_ask": "0.15"}], "timestamp": "1769384544476", "event_type": "price_change"}}
{"_local_timestamp": "2026-01-25T23:42:24.566246+00:00", "data": {"market": "0x607a934e2b8c4275c4cb5a74c2ad7d9064554eb296fb4e2971cf3b7d76a927cc", "price_changes": [{"asset_id": "68148598936481792878619902635048180980784414819164814468271718813144330892107", "price": "0.184", "size": "0", "side": "BUY", "hash": "e2bb05c594c820470935b07489a904d293e9f154", "best_bid": "0.878", "best_ask": "0.888"}, {"asset_id": "25975914361944378835569532810779694498194030305365204669451325469087977433544", "price": "0.816", "size": "0", "side": "SELL", "hash": "4ab53b7f498e46f8483eccb86169814f334bcf69", "best_bid": "0.112", "best_ask": "0.122"}], "timestamp": "1769384544476", "event_type": "price_change"}}
{"_local_timestamp": "2026-01-25T23:42:24.570395+00:00", "data": {"market": "0x6bbe585f51aedf96a92a4395f195633858a50a7ee9d5961a183b2fd858e2217c", "price_changes": [{"asset_id": "56479600937284047243744777367008101014255165543721437768956239217955454610653", "price": "0.17", "size": "1090", "side": "BUY", "hash": "f2790dcf026528e9692155860bd99b13b2bb2bcc", "best_bid": "0.8", "best_ask": "0.83"}, {"asset_id": "75977696589176706909494914683666626840477786548124398411155958119219599758391", "price": "0.83", "size": "1090", "side": "SELL", "hash": "33794ae1756018d61c8f9c577e11ec39246f68b2", "best_bid": "0.17", "best_ask": "0.2"}], "timestamp": "1769384544476", "event_type": "price_change"}}
{"_local_timestamp": "2026-01-25T23:42:24.571334+00:00", "data": {"market": "0x36352906a435bb57bbce5c12b8a016b42beee442645c27e025a6b605f167dbe1", "price_changes": [{"asset_id": "24865128979064458140408638815995003118177598043357620452530421257540758944225", "price": "0.244", "size": "50", "side": "BUY", "hash": "03f5a34b0ba7adfdc5697f71c2cd3204fee94049", "best_bid": "0.947", "best_ask": "0.957"}, {"asset_id": "31663847607839846905140169558614872784381523935014554710770021196634945212335", "price": "0.756", "size": "50", "side": "SELL", "hash": "c03ffdd7e62592fd69a9ea630c4b9532e7821ddf", "best_bid": "0.043", "best_ask": "0.053"}], "timestamp": "1769384544476", "event_type": "price_change"}}
{"_local_timestamp": "2026-01-25T23:42:24.572122+00:00", "data": {"market": "0x6bbe585f51aedf96a92a4395f195633858a50a7ee9d5961a183b2fd858e2217c", "price_changes": [{"asset_id": "56479600937284047243744777367008101014255165543721437768956239217955454610653", "price": "0.26", "size": "50", "side": "BUY", "hash": "f2790dcf026528e9692155860bd99b13b2bb2bcc", "best_bid": "0.8", "best_ask": "0.83"}, {"asset_id": "75977696589176706909494914683666626840477786548124398411155958119219599758391", "price": "0.74", "size": "50", "side": "SELL", "hash": "33794ae1756018d61c8f9c577e11ec39246f68b2", "best_bid": "0.17", "best_ask": "0.2"}], "timestamp": "1769384544476", "event_type": "price_change"}}
{"_local_timestamp": "2026-01-25T23:42:24.572881+00:00", "data": {"market": "0x36352906a435bb57bbce5c12b8a016b42beee442645c27e025a6b605f167dbe1", "price_changes": [{"asset_id": "24865128979064458140408638815995003118177598043357620452530421257540758944225", "price": "0.195", "size": "5.63", "side": "BUY", "hash": "03f5a34b0ba7adfdc5697f71c2cd3204fee94049", "best_bid": "0.947", "best_ask": "0.957"}, {"asset_id": "31663847607839846905140169558614872784381523935014554710770021196634945212335", "price": "0.805", "size": "5.63", "side": "SELL", "hash": "c03ffdd7e62592fd69a9ea630c4b9532e7821ddf", "best_bid": "0.043", "best_ask": "0.053"}], "timestamp": "1769384544476", "event_type": "price_change"}}
{"_local_timestamp": "2026-01-25T23:42:24.573706+00:00", "data": {"market": "0xf65b917d7c4c2d6e01266807b8b7fa49eb9fd00bad3b7413529c264261470a44", "price_changes": [{"asset_id": "114083583916459364671762732480092206829910491378286392673263703828161447677389", "price": "0.22", "size": "50", "side": "BUY", "hash": "d2b67a6575e900c245b2876ab9a911891995089a", "best_bid": "0.74", "best_ask": "0.78"}, {"asset_id": "21935961644840571543456790578994599010779256576943062204718832399472703918846", "price": "0.78", "size": "50", "side": "SELL", "hash": "18d7020d74a5ae74e991f620123fc9e7ad8a2c1b", "best_bid": "0.22", "best_ask": "0.26"}], "timestamp": "1769384544477", "event_type": "price_change"}}
{"_local_timestamp": "2026-01-25T23:42:24.574564+00:00", "data": {"market": "0x4ae33b3cb1b0af888ea00e0a035376c0319a56a8c28fb3521b22d28ecebbd94e", "price_changes": [{"asset_id": "107400623134616690037387608110271592167652294064537261328022766347776836196386", "price": "0.216", "size": "450", "side": "BUY", "hash": "562b918633ab1643aea3c5a2a2b84dc6d00b3532", "best_bid": "0.8", "best_ask": "0.811"}, {"asset_id": "42198988154346812250834138785680555306267908473427754988530622923073091857651", "price": "0.784", "size": "450", "side": "SELL", "hash": "2a2833b6d05cb056f12a8498213d092b867146a3", "best_bid": "0.189", "best_ask": "0.2"}], "timestamp": "1769384544477", "event_type": "price_change"}}
{"_local_timestamp": "2026-01-25T23:42:24.575440+00:00", "data": {"market": "0x4ae33b3cb1b0af888ea00e0a035376c0319a56a8c28fb3521b22d28ecebbd94e", "price_changes": [{"asset_id": "107400623134616690037387608110271592167652294064537261328022766347776836196386", "price": "0.196", "size": "5.48", "side": "BUY", "hash": "562b918633ab1643aea3c5a2a2b84dc6d00b3532", "best_bid": "0.8", "best_ask": "0.811"}, {"asset_id": "42198988154346812250834138785680555306267908473427754988530622923073091857651", "price": "0.804", "size": "5.48", "side": "SELL", "hash": "2a2833b6d05cb056f12a8498213d092b867146a3", "best_bid": "0.189", "best_ask": "0.2"}], "timestamp": "1769384544477", "event_type": "price_change"}}
{"_local_timestamp": "2026-01-25T23:42:25.052905+00:00", "data": {"market": "0x607a934e2b8c4275c4cb5a74c2ad7d9064554eb296fb4e2971cf3b7d76a927cc", "price_changes": [{"asset_id": "68148598936481792878619902635048180980784414819164814468271718813144330892107", "price": "0.183", "size": "1124", "side": "BUY", "hash": "f0f80191d173f689f3da4ec3d967a4fca25e779b", "best_bid": "0.878", "best_ask": "0.888"}, {"asset_id": "25975914361944378835569532810779694498194030305365204669451325469087977433544", "price": "0.817", "size": "1124", "side": "SELL", "hash": "a3be1176a45be4cdf12d83745e9d3bb34b0fd5be", "best_bid": "0.112", "best_ask": "0.122"}], "timestamp": "1769384544918", "event_type": "price_change"}}
{"_local_timestamp": "2026-01-25T23:42:25.062608+00:00", "data": {"market": "0xf65b917d7c4c2d6e01266807b8b7fa49eb9fd00bad3b7413529c264261470a44", "price_changes": [{"asset_id": "114083583916459364671762732480092206829910491378286392673263703828161447677389", "price": "0.24", "size": "1798", "side": "BUY", "hash": "4f9143f2c789fc112c65602cfcf3069fb1702ed2", "best_bid": "0.74", "best_ask": "0.78"}, {"asset_id": "21935961644840571543456790578994599010779256576943062204718832399472703918846", "price": "0.76", "size": "1798", "side": "SELL", "hash": "1352e4d20f273d6e04e7d50ccbd56ce0e9556271", "best_bid": "0.22", "best_ask": "0.26"}], "timestamp": "1769384544922", "event_type": "price_change"}}
{"_local_timestamp": "2026-01-25T23:42:25.063854+00:00", "data": {"market": "0x6bbe585f51aedf96a92a4395f195633858a50a7ee9d5961a183b2fd858e2217c", "price_changes": [{"asset_id": "56479600937284047243744777367008101014255165543721437768956239217955454610653", "price": "0.18", "size": "2432", "side": "BUY", "hash": "cfd5a3440f536eb52452d83dbb10d6dc8dff5249", "best_bid": "0.8", "best_ask": "0.83"}, {"asset_id": "75977696589176706909494914683666626840477786548124398411155958119219599758391", "price": "0.82", "size": "2432", "side": "SELL", "hash": "d6aac7cfd7ed9c97244df54407d1edd52349c6cd", "best_bid": "0.17", "best_ask": "0.2"}], "timestamp": "1769384544925", "event_type": "price_change"}}
{"_local_timestamp": "2026-01-25T23:42:25.064651+00:00", "data": {"market": "0x4ae33b3cb1b0af888ea00e0a035376c0319a56a8c28fb3521b22d28ecebbd94e", "price_changes": [{"asset_id": "107400623134616690037387608110271592167652294064537261328022766347776836196386", "price": "0.195", "size": "1070", "side": "BUY", "hash": "f5793a8ddd296df551f50810fc0891bea6a644ec", "best_bid": "0.8", "best_ask": "0.811"}, {"asset_id": "42198988154346812250834138785680555306267908473427754988530622923073091857651", "price": "0.805", "size": "1070", "side": "SELL", "hash": "60295e57e3c4b4cd67baa64fca017e72c0d6b836", "best_bid": "0.189", "best_ask": "0.2"}], "timestamp": "1769384544924", "event_type": "price_change"}}
{"_local_timestamp": "2026-01-25T23:42:25.080033+00:00", "data": {"market": "0x7587cc4497fc03e6bc20a2b9579d1a5cafd7778fcbd077f91f2c50fe5924259f", "price_changes": [{"asset_id": "28134581219669032059806644497841080110865577915276558812300476779313627788834", "price": "0.19", "size": "106.38", "side": "BUY", "hash": "d5bd68c6e001230ec38debe801c152c3c0a41e2b", "best_bid": "0.85", "best_ask": "0.87"}, {"asset_id": "113316597975241725413150018775135425644758743759237570300130816995662490799104", "price": "0.81", "size": "106.38", "side": "SELL", "hash": "931b3beab30459ccdb0cc29dccc345ad124e5f0d", "best_bid": "0.13", "best_ask": "0.15"}], "timestamp": "1769384544926", "event_type": "price_change"}}
{"_local_timestamp": "2026-01-25T23:42:25.092675+00:00", "data": {"market": "0x36352906a435bb57bbce5c12b8a016b42beee442645c27e025a6b605f167dbe1", "price_changes": [{"asset_id": "24865128979064458140408638815995003118177598043357620452530421257540758944225", "price": "0.245", "size": "1764", "side": "BUY", "hash": "3c8175ba25169d008444c8feed2af0e138515c30", "best_bid": "0.947", "best_ask": "0.957"}, {"asset_id": "31663847607839846905140169558614872784381523935014554710770021196634945212335", "price": "0.755", "size": "1764", "side": "SELL", "hash": "d8e91d9ad8ec6705bc0ec8d6c90e21be92c0e706", "best_bid": "0.043", "best_ask": "0.053"}], "timestamp": "1769384544936", "event_type": "price_change"}}
{"_local_timestamp": "2026-01-25T23:42:25.093836+00:00", "data": {"market": "0x607a934e2b8c4275c4cb5a74c2ad7d9064554eb296fb4e2971cf3b7d76a927cc", "price_changes": [{"asset_id": "68148598936481792878619902635048180980784414819164814468271718813144330892107", "price": "0.226", "size": "1908", "side": "BUY", "hash": "27681737d75e5cd9bff91bcf177f76f13e7073e3", "best_bid": "0.878", "best_ask": "0.888"}, {"asset_id": "25975914361944378835569532810779694498194030305365204669451325469087977433544", "price": "0.774", "size": "1908", "side": "SELL", "hash": "f78ce316a6336a4f150808096e72db6365c3f4c3", "best_bid": "0.112", "best_ask": "0.122"}], "timestamp": "1769384544946", "event_type": "price_change"}}
{"_local_timestamp": "2026-01-25T23:42:25.100543+00:00", "data": {"market": "0x4ae33b3cb1b0af888ea00e0a035376c0319a56a8c28fb3521b22d28ecebbd94e", "price_changes": [{"asset_id": "107400623134616690037387608110271592167652294064537261328022766347776836196386", "price": "0.217", "size": "1984", "side": "BUY", "hash": "c1fe3b2b2361212684d8236f4a8a41ca76d3f9f9", "best_bid": "0.8", "best_ask": "0.811"}, {"asset_id": "42198988154346812250834138785680555306267908473427754988530622923073091857651", "price": "0.783", "size": "1984", "side": "SELL", "hash": "aefc20e52b74247c70df9d921e7c0298e97c6a6a", "best_bid": "0.189", "best_ask": "0.2"}], "timestamp": "1769384544949", "event_type": "price_change"}}
{"_local_timestamp": "2026-01-25T23:42:25.106324+00:00", "data": {"market": "0x7587cc4497fc03e6bc20a2b9579d1a5cafd7778fcbd077f91f2c50fe5924259f", "price_changes": [{"asset_id": "28134581219669032059806644497841080110865577915276558812300476779313627788834", "price": "0.28", "size": "450", "side": "BUY", "hash": "bacd19b1cbc1b7fd5cdc86971b5290ee45460eba", "best_bid": "0.85", "best_ask": "0.87"}, {"asset_id": "113316597975241725413150018775135425644758743759237570300130816995662490799104", "price": "0.72", "size": "450", "side": "SELL", "hash": "ef0fdbb9d5cae36d0a857ab17d59ef6982417aa6", "best_bid": "0.13", "best_ask": "0.15"}], "timestamp": "1769384544951", "event_type": "price_change"}}
{"_local_timestamp": "2026-01-25T23:42:25.107958+00:00", "data": {"market": "0x36352906a435bb57bbce5c12b8a016b42beee442645c27e025a6b605f167dbe1", "price_changes": [{"asset_id": "24865128979064458140408638815995003118177598043357620452530421257540758944225", "price": "0.194", "size": "1074", "side": "BUY", "hash": "c9d183a2f6352588c3ddd6123e5a428e21391203", "best_bid": "0.947", "best_ask": "0.957"}, {"asset_id": "31663847607839846905140169558614872784381523935014554710770021196634945212335", "price": "0.806", "size": "1074", "side": "SELL", "hash": "4e18681f4403522ab287345eeb9ebb298a2f62df", "best_bid": "0.043", "best_ask": "0.053"}], "timestamp": "1769384544956", "event_type": "price_change"}}
{"_local_timestamp": "2026-01-25T23:42:25.123919+00:00", "data": {"market": "0x6bbe585f51aedf96a92a4395f195633858a50a7ee9d5961a183b2fd858e2217c", "price_changes": [{"asset_id": "56479600937284047243744777367008101014255165543721437768956239217955454610653", "price": "0.27", "size": "500", "side": "BUY", "hash": "86a598e28790d584a59faa668c7a08377b133bb4", "best_bid": "0.8", "best_ask": "0.83"}, {"asset_id": "75977696589176706909494914683666626840477786548124398411155958119219599758391", "price": "0.73", "size": "500", "side": "SELL", "hash": "0ff09dc48b27fc9bbf6895246e00c8575d68eb16", "best_bid": "0.17", "best_ask": "0.2"}], "timestamp": "1769384544950", "event_type": "price_change"}}
{"_local_timestamp": "2026-01-25T23:42:45.347986+00:00", "data": {"market": "0x4ae33b3cb1b0af888ea00e0a035376c0319a56a8c28fb3521b22d28ecebbd94e", "price_changes": [{"asset_id": "107400623134616690037387608110271592167652294064537261328022766347776836196386", "price": "0.216", "size": "400", "side": "BUY", "hash": "21998f0eb4a6685d5f66e67815c36f5087e28ecd", "best_bid": "0.8", "best_ask": "0.811"}, {"asset_id": "42198988154346812250834138785680555306267908473427754988530622923073091857651", "price": "0.784", "size": "400", "side": "SELL", "hash": "72869167c5fbe92dddd5fe3cab4ab82a25d29647", "best_bid": "0.189", "best_ask": "0.2"}], "timestamp": "1769384565200", "event_type": "price_change"}}
{"_local_timestamp": "2026-01-25T23:42:45.349015+00:00", "data": {"market": "0xf65b917d7c4c2d6e01266807b8b7fa49eb9fd00bad3b7413529c264261470a44", "price_changes": [{"asset_id": "114083583916459364671762732480092206829910491378286392673263703828161447677389", "price": "0.22", "size": "0", "side": "BUY", "hash": "13e18c742ba341c46458337beef40d73e131341f", "best_bid": "0.74", "best_ask": "0.78"}, {"asset_id": "21935961644840571543456790578994599010779256576943062204718832399472703918846", "price": "0.78", "size": "0", "side": "SELL", "hash": "3622ed1d8a0342d0929095cc34582eacb01b300b", "best_bid": "0.22", "best_ask": "0.26"}], "timestamp": "1769384565201", "event_type": "price_change"}}
{"_local_timestamp": "2026-01-25T23:42:45.349829+00:00", "data": {"market": "0x607a934e2b8c4275c4cb5a74c2ad7d9064554eb296fb4e2971cf3b7d76a927cc", "price_changes": [{"asset_id": "68148598936481792878619902635048180980784414819164814468271718813144330892107", "price": "0.225", "size": "0", "side": "BUY", "hash": "a79a6071e05f87b9d8df985fbcc3bce26cea0b4c", "best_bid": "0.878", "best_ask": "0.888"}, {"asset_id": "25975914361944378835569532810779694498194030305365204669451325469087977433544", "price": "0.775", "size": "0", "side": "SELL", "hash": "314b8a3c1629d7cd177b00e4a7fa7092462f53d0", "best_bid": "0.112", "best_ask": "0.122"}], "timestamp": "1769384565201", "event_type": "price_change"}}
{"_local_timestamp": "2026-01-25T23:42:45.350656+00:00", "data": {"market": "0x607a934e2b8c4275c4cb5a74c2ad7d9064554eb296fb4e2971cf3b7d76a927cc", "price_changes": [{"asset_id": "68148598936481792878619902635048180980784414819164814468271718813144330892107", "price": "0.36", "size": "130.55", "side": "BUY", "hash": "a79a6071e05f87b9d8df985fbcc3bce26cea0b4c", "best_bid": "0.878", "best_ask": "0.888"}, {"asset_id": "25975914361944378835569532810779694498194030305365204669451325469087977433544", "price": "0.64", "size": "130.55", "side": "SELL", "hash": "314b8a3c1629d7cd177b00e4a7fa7092462f53d0", "best_bid": "0.112", "best_ask": "0.122"}], "timestamp": "1769384565201", "event_type": "price_change"}}
{"_local_timestamp": "2026-01-25T23:42:45.395591+00:00", "data": {"market": "0x7587cc4497fc03e6bc20a2b9579d1a5cafd7778fcbd077f91f2c50fe5924259f", "price_changes": [{"asset_id": "28134581219669032059806644497841080110865577915276558812300476779313627788834", "price": "0.25", "size": "0", "side": "BUY", "hash": "a95722da4d5ed2f63f2c589e26e63dc9a11ebaae", "best_bid": "0.85", "best_ask": "0.87"}, {"asset_id": "113316597975241725413150018775135425644758743759237570300130816995662490799104", "price": "0.75", "size": "0", "side": "SELL", "hash": "a3730d22ca73248ce32bc8ec949d6962a436aedd", "best_bid": "0.13", "best_ask": "0.15"}], "timestamp": "1769384565211", "event_type": "price_change"}}
{"_local_timestamp": "2026-01-25T23:42:45.396507+00:00", "data": {"market": "0x36352906a435bb57bbce5c12b8a016b42beee442645c27e025a6b605f167dbe1", "price_changes": [{"asset_id": "24865128979064458140408638815995003118177598043357620452530421257540758944225", "price": "0.244", "size": "0", "side": "BUY", "hash": "54d52255c9e4311861993ef26db023afbd04c497", "best_bid": "0.947", "best_ask": "0.957"}, {"asset_id": "31663847607839846905140169558614872784381523935014554710770021196634945212335", "price": "0.756", "size": "0", "side": "SELL", "hash": "58f52d08337dca463c438957a1a1c8f90d9fd9c2", "best_bid": "0.043", "best_ask": "0.053"}], "timestamp": "1769384565211", "event_type": "price_change"}}
{"_local_timestamp": "2026-01-25T23:42:45.791624+00:00", "data": {"market": "0x4ae33b3cb1b0af888ea00e0a035376c0319a56a8c28fb3521b22d28ecebbd94e", "price_changes": [{"asset_id": "107400623134616690037387608110271592167652294064537261328022766347776836196386", "price": "0.217", "size": "2034", "side": "BUY", "hash": "a2ac82b90ec4b669c88401d7cd2a7eb5b678e1f6", "best_bid": "0.8", "best_ask": "0.811"}, {"asset_id": "42198988154346812250834138785680555306267908473427754988530622923073091857651", "price": "0.783", "size": "2034", "side": "SELL", "hash": "9c21b299448d80575ec3e9d0029b7afbc684244a", "best_bid": "0.189", "best_ask": "0.2"}], "timestamp": "1769384565599", "event_type": "price_change"}}
{"_local_timestamp": "2026-01-25T23:42:45.792614+00:00", "data": {"market": "0x7587cc4497fc03e6bc20a2b9579d1a5cafd7778fcbd077f91f2c50fe5924259f", "price_changes": [{"asset_id": "28134581219669032059806644497841080110865577915276558812300476779313627788834", "price": "0.22", "size": "177.27", "side": "BUY", "hash": "11eefc2da45790155dcfe15f20878129a926b37d", "best_bid": "0.85", "best_ask": "0.87"}, {"asset_id": "113316597975241725413150018775135425644758743759237570300130816995662490799104", "price": "0.78", "size": "177.27", "side": "SELL", "hash": "dd58c66bc0ac8d9c20aea212c29363518004c375", "best_bid": "0.13", "best_ask": "0.15"}], "timestamp": "1769384565599", "event_type": "price_change"}}
{"_local_timestamp": "2026-01-25T23:42:45.795724+00:00", "data": {"market": "0x607a934e2b8c4275c4cb5a74c2ad7d9064554eb296fb4e2971cf3b7d76a927cc", "price_changes": [{"asset_id": "68148598936481792878619902635048180980784414819164814468271718813144330892107", "price": "0.34", "size": "50", "side": "BUY", "hash": "e16402f83810984c0cf7d9c3069db82ee1a79810", "best_bid": "0.878", "best_ask": "0.888"}, {"asset_id": "25975914361944378835569532810779694498194030305365204669451325469087977433544", "price": "0.66", "size": "50", "side": "SELL", "hash": "4db22b3d765ce349bd8266e55884c73923bfdbfc", "best_bid": "0.112", "best_ask": "0.122"}], "timestamp": "1769384565600", "event_type": "price_change"}}
{"_local_timestamp": "2026-01-25T23:42:45.799457+00:00", "data": {"market": "0xf65b917d7c4c2d6e01266807b8b7fa49eb9fd00bad3b7413529c264261470a44", "price_changes": [{"asset_id": "114083583916459364671762732480092206829910491378286392673263703828161447677389", "price": "0.24", "size": "1848", "side": "BUY", "hash": "d5649525b43088f4c869fbbff0e3d5e93c60ed58", "best_bid": "0.74", "best_ask": "0.78"}, {"asset_id": "21935961644840571543456790578994599010779256576943062204718832399472703918846", "price": "0.76", "size": "1848", "side": "SELL", "hash": "7d5ebe5b83cd49555634e7e27f04747c177e78ab", "best_bid": "0.22", "best_ask": "0.26"}], "timestamp": "1769384565605", "event_type": "price_change"}}
{"_local_timestamp": "2026-01-25T23:42:45.808378+00:00", "data": {"market": "0x607a934e2b8c4275c4cb5a74c2ad7d9064554eb296fb4e2971cf3b7d76a927cc", "price_changes": [{"asset_id": "68148598936481792878619902635048180980784414819164814468271718813144330892107", "price": "0.226", "size": "1958", "side": "BUY", "hash": "c28d9cdd46d232f589e516e5606b7db0764639ab", "best_bid": "0.878", "best_ask": "0.888"}, {"asset_id": "25975914361944378835569532810779694498194030305365204669451325469087977433544", "price": "0.774", "size": "1958", "side": "SELL", "hash": "90646510c7229d64c5a7fd99d2d334baacf9cb7a", "best_bid": "0.112", "best_ask": "0.122"}], "timestamp": "1769384565626", "event_type": "price_change"}}
{"_local_timestamp": "2026-01-25T23:42:45.827215+00:00", "data": {"market": "0x36352906a435bb57bbce5c12b8a016b42beee442645c27e025a6b605f167dbe1", "price_changes": [{"asset_id": "24865128979064458140408638815995003118177598043357620452530421257540758944225", "price": "0.245", "size": "1814", "side": "BUY", "hash": "e6352aebc9d4a5737f9f9b17984e8bb3b7aa4ffe", "best_bid": "0.947", "best_ask": "0.957"}, {"asset_id": "31663847607839846905140169558614872784381523935014554710770021196634945212335", "price": "0.755", "size": "1814", "side": "SELL", "hash": "510fb0567e2d4990de9838eb2cfad50d229436a0", "best_bid": "0.043", "best_ask": "0.053"}], "timestamp": "1769384565601", "event_type": "price_change"}}
{"_local_timestamp": "2026-01-25T23:42:45.869609+00:00", "data": {"market": "0x6bbe585f51aedf96a92a4395f195633858a50a7ee9d5961a183b2fd858e2217c", "price_changes": [{"asset_id": "56479600937284047243744777367008101014255165543721437768956239217955454610653", "price": "0.76", "size": "0", "side": "BUY", "hash": "b14e333d1b775d6b29512b87a4350f1e7c94a459", "best_bid": "0.8", "best_ask": "0.83"}, {"asset_id": "75977696589176706909494914683666626840477786548124398411155958119219599758391", "price": "0.24", "size": "0", "side": "SELL", "hash": "554d790f50ae3c9fad39c5b7d30e3f9446b010f1", "best_bid": "0.17", "best_ask": "0.2"}], "timestamp": "1769384565717", "event_type": "price_change"}}
{"_local_timestamp": "2026-01-25T23:42:45.961467+00:00", "data": {"market": "0x6bbe585f51aedf96a92a4395f195633858a50a7ee9d5961a183b2fd858e2217c", "price_changes": [{"asset_id": "56479600937284047243744777367008101014255165543721437768956239217955454610653", "price": "0.75", "size": "10", "side": "BUY", "hash": "ad2a22949735fe74e21c9de7c016060ea06f48f5", "best_bid": "0.8", "best_ask": "0.83"}, {"asset_id": "75977696589176706909494914683666626840477786548124398411155958119219599758391", "price": "0.25", "size": "10", "side": "SELL", "hash": "25163713a0bdf27543dbd3c744d33e24cf1110df", "best_bid": "0.17", "best_ask": "0.2"}], "timestamp": "1769384565807", "event_type": "price_change"}}
{"_local_timestamp": "2026-01-25T23:42:47.189387+00:00", "data": {"market": "0x7587cc4497fc03e6bc20a2b9579d1a5cafd7778fcbd077f91f2c50fe5924259f", "price_changes": [{"asset_id": "28134581219669032059806644497841080110865577915276558812300476779313627788834", "price": "0.26", "size": "100", "side": "BUY", "hash": "561f0900455c18eff51ba698b9124d21bb86eeae", "best_bid": "0.85", "best_ask": "0.87"}, {"asset_id": "113316597975241725413150018775135425644758743759237570300130816995662490799104", "price": "0.74", "size": "100", "side": "SELL", "hash": "1ad9c83be6aeab642b2a9ca63518a15c0dc8c383", "best_bid": "0.13", "best_ask": "0.15"}], "timestamp": "1769384566987", "event_type": "price_change"}}
{"_local_timestamp": "2026-01-25T23:42:47.283687+00:00", "data": {"market": "0x6bbe585f51aedf96a92a4395f195633858a50a7ee9d5961a183b2fd858e2217c", "price_changes": [{"asset_id": "56479600937284047243744777367008101014255165543721437768956239217955454610653", "price": "0.18", "size": "100", "side": "BUY", "hash": "79137aea688b6fd7532a89ebcb9128d5e307047e", "best_bid": "0.8", "best_ask": "0.83"}, {"asset_id": "75977696589176706909494914683666626840477786548124398411155958119219599758391", "price": "0.82", "size": "100", "side": "SELL", "hash": "53081414d86c8f3d2e2aa643c0013928f3b098ba", "best_bid": "0.17", "best_ask": "0.2"}], "timestamp": "1769384566997", "event_type": "price_change"}}
{"_local_timestamp": "2026-01-25T23:42:47.601497+00:00", "data": {"market": "0x6bbe585f51aedf96a92a4395f195633858a50a7ee9d5961a183b2fd858e2217c", "price_changes": [{"asset_id": "56479600937284047243744777367008101014255165543721437768956239217955454610653", "price": "0.74", "size": "0", "side": "BUY", "hash": "b8ab4918887babef6642923476944c3bafd28db1", "best_bid": "0.8", "best_ask": "0.83"}, {"asset_id": "75977696589176706909494914683666626840477786548124398411155958119219599758391", "price": "0.26", "size": "0", "side": "SELL", "hash": "28ff2a579896dd125447298cba9ebddb424ef7e3", "best_bid": "0.17", "best_ask": "0.2"}], "timestamp": "1769384567416", "event_type": "price_change"}}
{"_local_timestamp": "2026-01-25T23:42:47.635614+00:00", "data": {"market": "0x6bbe585f51aedf96a92a4395f195633858a50a7ee9d5961a183b2fd858e2217c", "price_changes": [{"asset_id": "56479600937284047243744777367008101014255165543721437768956239217955454610653", "price": "0.75", "size": "30", "side": "BUY", "hash": "e792d92ea82a26b21f18fd3533a5ad251f5e6afd", "best_bid": "0.8", "best_ask": "0.83"}, {"asset_id": "75977696589176706909494914683666626840477786548124398411155958119219599758391", "price": "0.25", "size": "30", "side": "SELL", "hash": "5b8ef04529c526006a387c30cbd73c6b880be89c", "best_bid": "0.17", "best_ask": "0.2"}], "timestamp": "1769384567450", "event_type": "price_change"}}
{"_local_timestamp": "2026-01-25T23:42:48.038546+00:00", "data": {"market": "0x607a934e2b8c4275c4cb5a74c2ad7d9064554eb296fb4e2971cf3b7d76a927cc", "price_changes": [{"asset_id": "68148598936481792878619902635048180980784414819164814468271718813144330892107", "price": "0.838", "size": "135.71", "side": "BUY", "hash": "6035c270650c0c195b5b27838dbf76dd0cba5830", "best_bid": "0.878", "best_ask": "0.888"}, {"asset_id": "25975914361944378835569532810779694498194030305365204669451325469087977433544", "price": "0.162", "size": "135.71", "side": "SELL", "hash": "a6233f8639bf51b4cf3dcc12450e19e2e979c58b", "best_bid": "0.112", "best_ask": "0.122"}], "timestamp": "1769384567861", "event_type": "price_change"}}
{"_local_timestamp": "2026-01-25T23:42:48.045240+00:00", "data": {"market": "0x607a934e2b8c4275c4cb5a74c2ad7d9064554eb296fb4e2971cf3b7d76a927cc", "price_changes": [{"asset_id": "68148598936481792878619902635048180980784414819164814468271718813144330892107", "price": "0.786", "size": "135.71", "side": "BUY", "hash": "d97958d404058903df99d060d45fe7887476a85e", "best_bid": "0.878", "best_ask": "0.888"}, {"asset_id": "25975914361944378835569532810779694498194030305365204669451325469087977433544", "price": "0.214", "size": "135.71", "side": "SELL", "hash": "c42160b4efcb27b49101c4d98c1fd416947dfeae", "best_bid": "0.112", "best_ask": "0.122"}], "timestamp": "1769384567862", "event_type": "price_change"}}
{"_local_timestamp": "2026-01-25T23:42:49.799008+00:00", "data": {"market": "0x7587cc4497fc03e6bc20a2b9579d1a5cafd7778fcbd077f91f2c50fe5924259f", "price_changes": [{"asset_id": "28134581219669032059806644497841080110865577915276558812300476779313627788834", "price": "0.2", "size": "2100", "side": "BUY", "hash": "2d2ec54bf771a6e22c5e07756f4a0159d6212e8e", "best_bid": "0.85", "best_ask": "0.87"}, {"asset_id": "113316597975241725413150018775135425644758743759237570300130816995662490799104", "price": "0.8", "size": "2100", "side": "SELL", "hash": "d3542ca09857c5c6ce7280aae6812f48d5dfdd42", "best_bid": "0.13", "best_ask": "0.15"}], "timestamp": "1769384569607", "event_type": "price_change"}}
{"_local_timestamp": "2026-01-25T23:42:50.207225+00:00", "data": {"market": "0x607a934e2b8c4275c4cb5a74c2ad7d9064554eb296fb4e2971cf3b7d76a927cc", "price_changes": [{"asset_id": "68148598936481792878619902635048180980784414819164814468271718813144330892107", "price": "0.784", "size": "0", "side": "BUY", "hash": "93712d89749c4e1795796b6afd16523007543de1", "best_bid": "0.878", "best_ask": "0.888"}, {"asset_id": "25975914361944378835569532810779694498194030305365204669451325469087977433544", "price": "0.216", "size": "0", "side": "SELL", "hash": "c598836af9e961c9fd9bcfbc00d7fbddf140f8b8", "best_bid": "0.112", "best_ask": "0.122"}], "timestamp": "1769384570048", "event_type": "price_change"}}
{"_local_timestamp": "2026-01-25T23:42:50.257207+00:00", "data": {"market": "0x607a934e2b8c4275c4cb5a74c2ad7d9064554eb296fb4e2971cf3b7d76a927cc", "price_changes": [{"asset_id": "68148598936481792878619902635048180980784414819164814468271718813144330892107", "price": "0.787", "size": "20", "side": "BUY", "hash": "2635d2c9b6ca16ba4ae412cdccc467b291d618c3", "best_bid": "0.878", "best_ask": "0.888"}, {"asset_id": "25975914361944378835569532810779694498194030305365204669451325469087977433544", "price": "0.213", "size": "20", "side": "SELL", "hash": "b6271c093b5956839e7df83628dfdb5f4c632ee1", "best_bid": "0.112", "best_ask": "0.122"}], "timestamp": "1769384570080", "event_type": "price_change"}}
{"_local_timestamp": "2026-01-25T23:43:16.978373+00:00", "data": {"market": "0x6bbe585f51aedf96a92a4395f195633858a50a7ee9d5961a183b2fd858e2217c", "price_changes": [{"asset_id": "56479600937284047243744777367008101014255165543721437768956239217955454610653", "price": "0.19", "size": "2210", "side": "BUY", "hash": "8ec3c1fae7b9613b8c135a33ee819fa961d63273", "best_bid": "0.8", "best_ask": "0.83"}, {"asset_id": "75977696589176706909494914683666626840477786548124398411155958119219599758391", "price": "0.81", "size": "2210", "side": "SELL", "hash": "564bde9eb644a00ee1622ee81c60170cd6369a74", "best_bid": "0.17", "best_ask": "0.2"}], "timestamp": "1769384596906", "event_type": "price_change"}}
{"_local_timestamp": "2026-01-25T23:43:36.835328+00:00", "data": {"market": "0x607a934e2b8c4275c4cb5a74c2ad7d9064554eb296fb4e2971cf3b7d76a927cc", "price_changes": [{"asset_id": "68148598936481792878619902635048180980784414819164814468271718813144330892107", "price": "0.838", "size": "0", "side": "BUY", "hash": "abe70123065780ca3d665b2a4087fd0e2cdb4a85", "best_bid": "0.878", "best_ask": "0.888"}, {"asset_id": "25975914361944378835569532810779694498194030305365204669451325469087977433544", "price": "0.162", "size": "0", "side": "SELL", "hash": "2e84dadb6e5b09b0b08ffe851df807fe5b5debc1", "best_bid": "0.112", "best_ask": "0.122"}], "timestamp": "1769384616741", "event_type": "price_change"}}
{"_local_timestamp": "2026-01-25T23:43:36.836331+00:00", "data": {"market": "0x607a934e2b8c4275c4cb5a74c2ad7d9064554eb296fb4e2971cf3b7d76a927cc", "price_changes": [{"asset_id": "68148598936481792878619902635048180980784414819164814468271718813144330892107", "price": "0.786", "size": "0", "side": "BUY", "hash": "abe70123065780ca3d665b2a4087fd0e2cdb4a85", "best_bid": "0.878", "best_ask": "0.888"}, {"asset_id": "25975914361944378835569532810779694498194030305365204669451325469087977433544", "price": "0.214", "size": "0", "side": "SELL", "hash": "2e84dadb6e5b09b0b08ffe851df807fe5b5debc1", "best_bid": "0.112", "best_ask": "0.122"}], "timestamp": "1769384616741", "event_type": "price_change"}}
{"_local_timestamp": "2026-01-25T23:43:39.743006+00:00", "data": {"market": "0x607a934e2b8c4275c4cb5a74c2ad7d9064554eb296fb4e2971cf3b7d76a927cc", "price_changes": [{"asset_id": "68148598936481792878619902635048180980784414819164814468271718813144330892107", "price": "0.787", "size": "0", "side": "BUY", "hash": "ccb55aa80d46c5015e0e3fb5861393d531016e02", "best_bid": "0.878", "best_ask": "0.888"}, {"asset_id": "25975914361944378835569532810779694498194030305365204669451325469087977433544", "price": "0.213", "size": "0", "side": "SELL", "hash": "5e48c72a75fa9924e8167a33dd1e68f274be9061", "best_bid": "0.112", "best_ask": "0.122"}], "timestamp": "1769384619674", "event_type": "price_change"}}
{"_local_timestamp": "2026-01-25T23:43:39.769149+00:00", "data": {"market": "0x607a934e2b8c4275c4cb5a74c2ad7d9064554eb296fb4e2971cf3b7d76a927cc", "price_changes": [{"asset_id": "68148598936481792878619902635048180980784414819164814468271718813144330892107", "price": "0.784", "size": "20", "side": "BUY", "hash": "caacf951f259f1564e2dc2c6f0c663f9030b59df", "best_bid": "0.878", "best_ask": "0.888"}, {"asset_id": "25975914361944378835569532810779694498194030305365204669451325469087977433544", "price": "0.216", "size": "20", "side": "SELL", "hash": "df99699444ff1d0ca66f9e985ac0ceff52393c07", "best_bid": "0.112", "best_ask": "0.122"}], "timestamp": "1769384619701", "event_type": "price_change"}}
{"_local_timestamp": "2026-01-25T23:43:41.032342+00:00", "data": {"market": "0x6bbe585f51aedf96a92a4395f195633858a50a7ee9d5961a183b2fd858e2217c", "price_changes": [{"asset_id": "56479600937284047243744777367008101014255165543721437768956239217955454610653", "price": "0.75", "size": "20", "side": "BUY", "hash": "d0ff8e81fd7a4109a9a6cd74b113611180de0f8d", "best_bid": "0.8", "best_ask": "0.83"}, {"asset_id": "75977696589176706909494914683666626840477786548124398411155958119219599758391", "price": "0.25", "size": "20", "side": "SELL", "hash": "b7e7a06975913066605eded76ab097d54e282f00", "best_bid": "0.17", "best_ask": "0.2"}], "timestamp": "1769384620960", "event_type": "price_change"}}
{"_local_timestamp": "2026-01-25T23:43:41.128058+00:00", "data": {"market": "0x6bbe585f51aedf96a92a4395f195633858a50a7ee9d5961a183b2fd858e2217c", "price_changes": [{"asset_id": "56479600937284047243744777367008101014255165543721437768956239217955454610653", "price": "0.76", "size": "10", "side": "BUY", "hash": "bb6bb2c3ec0b9d43f83a6a17699b1a2d5f7423a9", "best_bid": "0.8", "best_ask": "0.83"}, {"asset_id": "75977696589176706909494914683666626840477786548124398411155958119219599758391", "price": "0.24", "size": "10", "side": "SELL", "hash": "1d8fdd3acd54b3e130f656ce980a2bfd32ad3534", "best_bid": "0.17", "best_ask": "0.2"}], "timestamp": "1769384621048", "event_type": "price_change"}}
{"_local_timestamp": "2026-01-25T23:43:41.508859+00:00", "data": {"market": "0x6bbe585f51aedf96a92a4395f195633858a50a7ee9d5961a183b2fd858e2217c", "price_changes": [{"asset_id": "56479600937284047243744777367008101014255165543721437768956239217955454610653", "price": "0.75", "size": "0", "side": "BUY", "hash": "89d093e02b9465392016c54e72025aeee24bb5f2", "best_bid": "0.8", "best_ask": "0.83"}, {"asset_id": "75977696589176706909494914683666626840477786548124398411155958119219599758391", "price": "0.25", "size": "0", "side": "SELL", "hash": "a7ac527cc925501a3b895cc3fbbd15c37b26b948", "best_bid": "0.17", "best_ask": "0.2"}], "timestamp": "1769384621441", "event_type": "price_change"}}
{"_local_timestamp": "2026-01-25T23:43:41.534960+00:00", "data": {"market": "0x6bbe585f51aedf96a92a4395f195633858a50a7ee9d5961a183b2fd858e2217c", "price_changes": [{"asset_id": "56479600937284047243744777367008101014255165543721437768956239217955454610653", "price": "0.74", "size": "20", "side": "BUY", "hash": "e9775654a5b3de60e225cea2b6c2701adc1b5391", "best_bid": "0.8", "best_ask": "0.83"}, {"asset_id": "75977696589176706909494914683666626840477786548124398411155958119219599758391", "price": "0.26", "size": "20", "side": "SELL", "hash": "f7c73e6d55d01507904d25b7bdcdbef2572b5339", "best_bid": "0.17", "best_ask": "0.2"}], "timestamp": "1769384621468", "event_type": "price_change"}}
{"_local_timestamp": "2026-01-25T23:44:08.522715+00:00", "data": {"market": "0x7587cc4497fc03e6bc20a2b9579d1a5cafd7778fcbd077f91f2c50fe5924259f", "price_changes": [{"asset_id": "28134581219669032059806644497841080110865577915276558812300476779313627788834", "price": "0.19", "size": "6.38", "side": "BUY", "hash": "a582cdd4fc0cd57bf15800eec7d26e043e6e4871", "best_bid": "0.85", "best_ask": "0.87"}, {"asset_id": "113316597975241725413150018775135425644758743759237570300130816995662490799104", "price": "0.81", "size": "6.38", "side": "SELL", "hash": "0d9a01451c533ff3d7436bcb10760c99c920d690", "best_bid": "0.13", "best_ask": "0.15"}], "timestamp": "1769384648362", "event_type": "price_change"}}
{"_local_timestamp": "2026-01-25T23:44:08.523807+00:00", "data": {"market": "0x7587cc4497fc03e6bc20a2b9579d1a5cafd7778fcbd077f91f2c50fe5924259f", "price_changes": [{"asset_id": "28134581219669032059806644497841080110865577915276558812300476779313627788834", "price": "0.28", "size": "400", "side": "BUY", "hash": "a582cdd4fc0cd57bf15800eec7d26e043e6e4871", "best_bid": "0.85", "best_ask": "0.87"}, {"asset_id": "113316597975241725413150018775135425644758743759237570300130816995662490799104", "price": "0.72", "size": "400", "side": "SELL", "hash": "0d9a01451c533ff3d7436bcb10760c99c920d690", "best_bid": "0.13", "best_ask": "0.15"}], "timestamp": "1769384648362", "event_type": "price_change"}}
{"_local_timestamp": "2026-01-25T23:44:08.993053+00:00", "data": {"market": "0x7587cc4497fc03e6bc20a2b9579d1a5cafd7778fcbd077f91f2c50fe5924259f", "price_changes": [{"asset_id": "28134581219669032059806644497841080110865577915276558812300476779313627788834", "price": "0.26", "size": "150", "side": "BUY", "hash": "bd32c754153face8f5ea9e2dac036a18a2209600", "best_bid": "0.85", "best_ask": "0.87"}, {"asset_id": "113316597975241725413150018775135425644758743759237570300130816995662490799104", "price": "0.74", "size": "150", "side": "SELL", "hash": "93820dfe84a1de211930dcc889015fc87d7c48fe", "best_bid": "0.13", "best_ask": "0.15"}], "timestamp": "1769384648750", "event_type": "price_change"}}
{"_local_timestamp": "2026-01-25T23:44:09.082787+00:00", "data": {"market": "0x7587cc4497fc03e6bc20a2b9579d1a5cafd7778fcbd077f91f2c50fe5924259f", "price_changes": [{"asset_id": "28134581219669032059806644497841080110865577915276558812300476779313627788834", "price": "0.18", "size": "1138", "side": "BUY", "hash": "5d67bf6c023eacc104bb83ff952fd46e4a7d8172", "best_bid": "0.85", "best_ask": "0.87"}, {"asset_id": "113316597975241725413150018775135425644758743759237570300130816995662490799104", "price": "0.82", "size": "1138", "side": "SELL", "hash": "e6cf115ceee2939c499f804834fde0a7779d8eb1", "best_bid": "0.13", "best_ask": "0.15"}], "timestamp": "1769384648830", "event_type": "price_change"}}
{"_local_timestamp": "2026-01-25T23:44:20.576957+00:00", "data": {"market": "0x6bbe585f51aedf96a92a4395f195633858a50a7ee9d5961a183b2fd858e2217c", "price_changes": [{"asset_id": "56479600937284047243744777367008101014255165543721437768956239217955454610653", "price": "0.17", "size": "940", "side": "BUY", "hash": "2272d09359119030ef57624bf3c09e7c145d6ac8", "best_bid": "0.8", "best_ask": "0.83"}, {"asset_id": "75977696589176706909494914683666626840477786548124398411155958119219599758391", "price": "0.83", "size": "940", "side": "SELL", "hash": "3305479d5d6d3053c164da56ddf5c8822843f260", "best_bid": "0.17", "best_ask": "0.2"}], "timestamp": "1769384660464", "event_type": "price_change"}}
{"_local_timestamp": "2026-01-25T23:44:20.581377+00:00", "data": {"market": "0xf65b917d7c4c2d6e01266807b8b7fa49eb9fd00bad3b7413529c264261470a44", "price_changes": [{"asset_id": "114083583916459364671762732480092206829910491378286392673263703828161447677389", "price": "0.23", "size": "300", "side": "BUY", "hash": "76d9fd71b33c5fa61ee183b734c11cb12d9a3ac4", "best_bid": "0.74", "best_ask": "0.78"}, {"asset_id": "21935961644840571543456790578994599010779256576943062204718832399472703918846", "price": "0.77", "size": "300", "side": "SELL", "hash": "55357edb0fd9dac07b4958fcb310bf91b660d57f", "best_bid": "0.22", "best_ask": "0.26"}], "timestamp": "1769384660464", "event_type": "price_change"}}
{"_local_timestamp": "2026-01-25T23:44:20.583436+00:00", "data": {"market": "0x4ae33b3cb1b0af888ea00e0a035376c0319a56a8c28fb3521b22d28ecebbd94e", "price_changes": [{"asset_id": "107400623134616690037387608110271592167652294064537261328022766347776836196386", "price": "0.216", "size": "300", "side": "BUY", "hash": "f68e473e0aea6b7a24ae1de20dc9d9465da61280", "best_bid": "0.8", "best_ask": "0.811"}, {"asset_id": "42198988154346812250834138785680555306267908473427754988530622923073091857651", "price": "0.784", "size": "300", "side": "SELL", "hash": "98b84c99f56a973c8561f11985014e3acd5da2cf", "best_bid": "0.189", "best_ask": "0.2"}], "timestamp": "1769384660464", "event_type": "price_change"}}
{"_local_timestamp": "2026-01-25T23:44:20.587174+00:00", "data": {"market": "0x36352906a435bb57bbce5c12b8a016b42beee442645c27e025a6b605f167dbe1", "price_changes": [{"asset_id": "24865128979064458140408638815995003118177598043357620452530421257540758944225", "price": "0.24", "size": "116.66", "side": "BUY", "hash": "65be456127616437a381e5622046a1901eaf54c9", "best_bid": "0.947", "best_ask": "0.957"}, {"asset_id": "31663847607839846905140169558614872784381523935014554710770021196634945212335", "price": "0.76", "size": "116.66", "side": "SELL", "hash": "ed4a69bb90bb1282ed4a517a9e40e6b45e3ffcda", "best_bid": "0.043", "best_ask": "0.053"}], "timestamp": "1769384660464", "event_type": "price_change"}}
{"_local_timestamp": "2026-01-25T23:44:20.594941+00:00", "data": {"market": "0x607a934e2b8c4275c4cb5a74c2ad7d9064554eb296fb4e2971cf3b7d76a927cc", "price_changes": [{"asset_id": "68148598936481792878619902635048180980784414819164814468271718813144330892107", "price": "0.36", "size": "55.55", "side": "BUY", "hash": "98c691f8c08f0bca7c9a4fa4b329ebb58d777f07", "best_bid": "0.878", "best_ask": "0.888"}, {"asset_id": "25975914361944378835569532810779694498194030305365204669451325469087977433544", "price": "0.64", "size": "55.55", "side": "SELL", "hash": "842f8ee16fc16e582ec85fd6d98d82e53e693b43", "best_bid": "0.112", "best_ask": "0.122"}], "timestamp": "1769384660464", "event_type": "price_change"}}
{"_local_timestamp": "2026-01-25T23:44:20.596943+00:00", "data": {"market": "0x607a934e2b8c4275c4cb5a74c2ad7d9064554eb296fb4e2971cf3b7d76a927cc", "price_changes": [{"asset_id": "68148598936481792878619902635048180980784414819164814468271718813144330892107", "price": "0.22", "size": "127.27", "side": "BUY", "hash": "98c691f8c08f0bca7c9a4fa4b329ebb58d777f07", "best_bid": "0.878", "best_ask": "0.888"}, {"asset_id": "25975914361944378835569532810779694498194030305365204669451325469087977433544", "price": "0.78", "size": "127.27", "side": "SELL", "hash": "842f8ee16fc16e582ec85fd6d98d82e53e693b43", "best_bid": "0.112", "best_ask": "0.122"}], "timestamp": "1769384660464", "event_type": "price_change"}}
{"_local_timestamp": "2026-01-25T23:44:21.235052+00:00", "data": {"market": "0xf65b917d7c4c2d6e01266807b8b7fa49eb9fd00bad3b7413529c264261470a44", "price_changes": [{"asset_id": "114083583916459364671762732480092206829910491378286392673263703828161447677389", "price": "0.24", "size": "1948", "side": "BUY", "hash": "97d2e20b8f19941edd923a603b9d4055b9bff4fb", "best_bid": "0.74", "best_ask": "0.78"}, {"asset_id": "21935961644840571543456790578994599010779256576943062204718832399472703918846", "price": "0.76", "size": "1948", "side": "SELL", "hash": "892800c303a93c548df8f46240685043c9118697", "best_bid": "0.22", "best_ask": "0.26"}], "timestamp": "1769384660839", "event_type": "price_change"}}
{"_local_timestamp": "2026-01-25T23:44:21.302056+00:00", "data": {"market": "0x607a934e2b8c4275c4cb5a74c2ad7d9064554eb296fb4e2971cf3b7d76a927cc", "price_changes": [{"asset_id": "68148598936481792878619902635048180980784414819164814468271718813144330892107", "price": "0.361", "size": "175", "side": "BUY", "hash": "0308c1448be8a7734fbcdcc3ed1d72913343e232", "best_bid": "0.878", "best_ask": "0.888"}, {"asset_id": "25975914361944378835569532810779694498194030305365204669451325469087977433544", "price": "0.639", "size": "175", "side": "SELL", "hash": "3bcbe73d22e38893a2fcc12c00b9993fcdda7d94", "best_bid": "0.112", "best_ask": "0.122"}], "timestamp": "1769384660870", "event_type": "price_change"}}
{"_local_timestamp": "2026-01-25T23:44:21.362964+00:00", "data": {"market": "0x36352906a435bb57bbce5c12b8a016b42beee442645c27e025a6b605f167dbe1", "price_changes": [{"asset_id": "24865128979064458140408638815995003118177598043357620452530421257540758944225", "price": "0.245", "size": "1914", "side": "BUY", "hash": "b593b3923e4d2d5ee41c9fdd49ba8ebd9b31aeb5", "best_bid": "0.947", "best_ask": "0.957"}, {"asset_id": "31663847607839846905140169558614872784381523935014554710770021196634945212335", "price": "0.755", "size": "1914", "side": "SELL", "hash": "32a4a3ac6acf038c4485c638572db0e8d8909d22", "best_bid": "0.043", "best_ask": "0.053"}], "timestamp": "1769384660869", "event_type": "price_change"}}
{"_local_timestamp": "2026-01-25T23:44:21.492814+00:00", "data": {"market": "0x4ae33b3cb1b0af888ea00e0a035376c0319a56a8c28fb3521b22d28ecebbd94e", "price_changes": [{"asset_id": "107400623134616690037387608110271592167652294064537261328022766347776836196386", "price": "0.217", "size": "2134", "side": "BUY", "hash": "86e8bc55907a6a14fffa3797913b63a608d7b415", "best_bid": "0.8", "best_ask": "0.811"}, {"asset_id": "42198988154346812250834138785680555306267908473427754988530622923073091857651", "price": "0.783", "size": "2134", "side": "SELL", "hash": "784b4c91a92bad8953c105ccd3df296f8983c196", "best_bid": "0.189", "best_ask": "0.2"}], "timestamp": "1769384660873", "event_type": "price_change"}}
{"_local_timestamp": "2026-01-25T23:44:21.543554+00:00", "data": {"market": "0x6bbe585f51aedf96a92a4395f195633858a50a7ee9d5961a183b2fd858e2217c", "price_changes": [{"asset_id": "56479600937284047243744777367008101014255165543721437768956239217955454610653", "price": "0.18", "size": "250", "side": "BUY", "hash": "af76442a7b81a20ec38e100fa9170e7ce91d6b97", "best_bid": "0.8", "best_ask": "0.83"}, {"asset_id": "75977696589176706909494914683666626840477786548124398411155958119219599758391", "price": "0.82", "size": "250", "side": "SELL", "hash": "08c13f7058b52b5578bceb9ed7e5a1c586fc6fe4", "best_bid": "0.17", "best_ask": "0.2"}], "timestamp": "1769384660892", "event_type": "price_change"}}
{"_local_timestamp": "2026-01-25T23:44:21.695180+00:00", "data": {"market": "0x607a934e2b8c4275c4cb5a74c2ad7d9064554eb296fb4e2971cf3b7d76a927cc", "price_changes": [{"asset_id": "68148598936481792878619902635048180980784414819164814468271718813144330892107", "price": "0.226", "size": "2058", "side": "BUY", "hash": "f00fb89363a29f3ce8e51d49abd389e7b76f5d94", "best_bid": "0.878", "best_ask": "0.888"}, {"asset_id": "25975914361944378835569532810779694498194030305365204669451325469087977433544", "price": "0.774", "size": "2058", "side": "SELL", "hash": "2fed8b110bc7ef52e1c65a666935b9f279d70d4c", "best_bid": "0.112", "best_ask": "0.122"}], "timestamp": "1769384660944", "event_type": "price_change"}}
{"_local_timestamp": "2026-01-25T23:44:22.852649+00:00", "data": {"market": "0x4ae33b3cb1b0af888ea00e0a035376c0319a56a8c28fb3521b22d28ecebbd94e", "price_changes": [{"asset_id": "107400623134616690037387608110271592167652294064537261328022766347776836196386", "price": "0.799", "size": "20", "side": "BUY", "hash": "2fa0fc6e691ebb5ce291958597e5984f895b0385", "best_bid": "0.8", "best_ask": "0.811"}, {"asset_id": "42198988154346812250834138785680555306267908473427754988530622923073091857651", "price": "0.201", "size": "20", "side": "SELL", "hash": "91bfbe49695a3c606dc52793ea05ea7334a19c8b", "best_bid": "0.189", "best_ask": "0.2"}], "timestamp": "1769384662774", "event_type": "price_change"}}
{"_local_timestamp": "2026-01-25T23:44:25.118415+00:00", "data": {"market": "0x607a934e2b8c4275c4cb5a74c2ad7d9064554eb296fb4e2971cf3b7d76a927cc", "price_changes": [{"asset_id": "68148598936481792878619902635048180980784414819164814468271718813144330892107", "price": "0.62", "size": "0", "side": "BUY", "hash": "5e8c94f713c9a0992d01abd3a7751d74454d3bc9", "best_bid": "0.878", "best_ask": "0.888"}, {"asset_id": "25975914361944378835569532810779694498194030305365204669451325469087977433544", "price": "0.38", "size": "0", "side": "SELL", "hash": "7f5bc9164553b79e6e180e591e57e3650e084c5f", "best_bid": "0.112", "best_ask": "0.122"}], "timestamp": "1769384665043", "event_type": "price_change"}}
{"_local_timestamp": "2026-01-25T23:44:25.119400+00:00", "data": {"market": "0x607a934e2b8c4275c4cb5a74c2ad7d9064554eb296fb4e2971cf3b7d76a927cc", "price_changes": [{"asset_id": "68148598936481792878619902635048180980784414819164814468271718813144330892107", "price": "0.361", "size": "75", "side": "BUY", "hash": "5e8c94f713c9a0992d01abd3a7751d74454d3bc9", "best_bid": "0.878", "best_ask": "0.888"}, {"asset_id": "25975914361944378835569532810779694498194030305365204669451325469087977433544", "price": "0.639", "size": "75", "side": "SELL", "hash": "7f5bc9164553b79e6e180e591e57e3650e084c5f", "best_bid": "0.112", "best_ask": "0.122"}], "timestamp": "1769384665043", "event_type": "price_change"}}
{"_local_timestamp": "2026-01-25T23:44:25.976754+00:00", "data": {"market": "0x607a934e2b8c4275c4cb5a74c2ad7d9064554eb296fb4e2971cf3b7d76a927cc", "price_changes": [{"asset_id": "68148598936481792878619902635048180980784414819164814468271718813144330892107", "price": "0.312", "size": "100", "side": "BUY", "hash": "399c2a64fe7e9fde019405f737d6d2d5825f319e", "best_bid": "0.878", "best_ask": "0.888"}, {"asset_id": "25975914361944378835569532810779694498194030305365204669451325469087977433544", "price": "0.688", "size": "100", "side": "SELL", "hash": "ee65f84a780a4bd1e6330602e18d2097a2db4f39", "best_bid": "0.112", "best_ask": "0.122"}], "timestamp": "1769384665907", "event_type": "price_change"}}
{"_local_timestamp": "2026-01-25T23:44:25.995827+00:00", "data": {"market": "0x607a934e2b8c4275c4cb5a74c2ad7d9064554eb296fb4e2971cf3b7d76a927cc", "price_changes": [{"asset_id": "68148598936481792878619902635048180980784414819164814468271718813144330892107", "price": "0.595", "size": "100", "side": "BUY", "hash": "f160a9430ebd1848632c8de6c8289f1fa5dee129", "best_bid": "0.878", "best_ask": "0.888"}, {"asset_id": "25975914361944378835569532810779694498194030305365204669451325469087977433544", "price": "0.405", "size": "100", "side": "SELL", "hash": "dfc1eef34ad442d2b2f9f01454beb63730e34dab", "best_bid": "0.112", "best_ask": "0.122"}], "timestamp": "1769384665921", "event_type": "price_change"}}
{"_local_timestamp": "2026-01-25T23:44:32.375565+00:00", "data": {"market": "0x6bbe585f51aedf96a92a4395f195633858a50a7ee9d5961a183b2fd858e2217c", "price_changes": [{"asset_id": "56479600937284047243744777367008101014255165543721437768956239217955454610653", "price": "0.19", "size": "0", "side": "BUY", "hash": "75ac657e85f90de5aa91fb02f7f0c70a6ef2aaf5", "best_bid": "0.8", "best_ask": "0.83"}, {"asset_id": "75977696589176706909494914683666626840477786548124398411155958119219599758391", "price": "0.81", "size": "0", "side": "SELL", "hash": "496580ebde8946d0fcef728fd365222caf3862d0", "best_bid": "0.17", "best_ask": "0.2"}], "timestamp": "1769384672291", "event_type": "price_change"}}
{"_local_timestamp": "2026-01-25T23:44:32.446493+00:00", "data": {"market": "0x7587cc4497fc03e6bc20a2b9579d1a5cafd7778fcbd077f91f2c50fe5924259f", "price_changes": [{"asset_id": "28134581219669032059806644497841080110865577915276558812300476779313627788834", "price": "0.2", "size": "0", "side": "BUY", "hash": "ca398dc42c40d71fe6e683257b16f82df0f8ef09", "best_bid": "0.85", "best_ask": "0.87"}, {"asset_id": "113316597975241725413150018775135425644758743759237570300130816995662490799104", "price": "0.8", "size": "0", "side": "SELL", "hash": "a505e713b39d47c680c2c14ca9ee1b116ff0cdca", "best_bid": "0.13", "best_ask": "0.15"}], "timestamp": "1769384672299", "event_type": "price_change"}}
{"_local_timestamp": "2026-01-25T23:44:32.450193+00:00", "data": {"market": "0x607a934e2b8c4275c4cb5a74c2ad7d9064554eb296fb4e2971cf3b7d76a927cc", "price_changes": [{"asset_id": "68148598936481792878619902635048180980784414819164814468271718813144330892107", "price": "0.226", "size": "200", "side": "BUY", "hash": "67197f8981fd83fa93bdf51f6dded3a8b164638f", "best_bid": "0.878", "best_ask": "0.888"}, {"asset_id": "25975914361944378835569532810779694498194030305365204669451325469087977433544", "price": "0.774", "size": "200", "side": "SELL", "hash": "b8735d6239ac15f0c94650872e78ac45e78a10ed", "best_bid": "0.112", "best_ask": "0.122"}], "timestamp": "1769384672293", "event_type": "price_change"}}
{"_local_timestamp": "2026-01-25T23:44:32.459860+00:00", "data": {"market": "0x36352906a435bb57bbce5c12b8a016b42beee442645c27e025a6b605f167dbe1", "price_changes": [{"asset_id": "24865128979064458140408638815995003118177598043357620452530421257540758944225", "price": "0.245", "size": "200", "side": "BUY", "hash": "d4a99c5c428b10263d9f6071760e7c8769d3cdcf", "best_bid": "0.947", "best_ask": "0.957"}, {"asset_id": "31663847607839846905140169558614872784381523935014554710770021196634945212335", "price": "0.755", "size": "200", "side": "SELL", "hash": "84b008e21d92f6933fa3a5ac4ab2a89845ee9200", "best_bid": "0.043", "best_ask": "0.053"}], "timestamp": "1769384672293", "event_type": "price_change"}}
{"_local_timestamp": "2026-01-25T23:44:34.998565+00:00", "data": {"market": "0x607a934e2b8c4275c4cb5a74c2ad7d9064554eb296fb4e2971cf3b7d76a927cc", "price_changes": [{"asset_id": "68148598936481792878619902635048180980784414819164814468271718813144330892107", "price": "0.221", "size": "1900", "side": "BUY", "hash": "f6438369322bd277734ba14887807437ad1ce9bc", "best_bid": "0.878", "best_ask": "0.888"}, {"asset_id": "25975914361944378835569532810779694498194030305365204669451325469087977433544", "price": "0.779", "size": "1900", "side": "SELL", "hash": "272ae78ae58d283a8df66a8e2b040d2cf85d60e2", "best_bid": "0.112", "best_ask": "0.122"}], "timestamp": "1769384674920", "event_type": "price_change"}}
{"_local_timestamp": "2026-01-25T23:44:42.635913+00:00", "data": {"market": "0x6bbe585f51aedf96a92a4395f195633858a50a7ee9d5961a183b2fd858e2217c", "price_changes": [{"asset_id": "56479600937284047243744777367008101014255165543721437768956239217955454610653", "price": "0.18", "size": "2582", "side": "BUY", "hash": "f82d466400eedc95259249f9d3a0698ffd1a1830", "best_bid": "0.8", "best_ask": "0.83"}, {"asset_id": "75977696589176706909494914683666626840477786548124398411155958119219599758391", "price": "0.82", "size": "2582", "side": "SELL", "hash": "55d0dca61ae3735fc8054819d36e58908038f178", "best_bid": "0.17", "best_ask": "0.2"}], "timestamp": "1769384682562", "event_type": "price_change"}}
{"_local_timestamp": "2026-01-25T23:44:43.266836+00:00", "data": {"market": "0x6bbe585f51aedf96a92a4395f195633858a50a7ee9d5961a183b2fd858e2217c", "price_changes": [{"asset_id": "56479600937284047243744777367008101014255165543721437768956239217955454610653", "price": "0.76", "size": "0", "side": "BUY", "hash": "84e21b716b3142f11011bb18b8d4a5a49166ac7c", "best_bid": "0.8", "best_ask": "0.83"}, {"asset_id": "75977696589176706909494914683666626840477786548124398411155958119219599758391", "price": "0.24", "size": "0", "side": "SELL", "hash": "2ffcfef7a33ca16cc629d624872fdfe6a6a20451", "best_bid": "0.17", "best_ask": "0.2"}], "timestamp": "1769384683198", "event_type": "price_change"}}
{"_local_timestamp": "2026-01-25T23:44:43.362255+00:00", "data": {"market": "0x6bbe585f51aedf96a92a4395f195633858a50a7ee9d5961a183b2fd858e2217c", "price_changes": [{"asset_id": "56479600937284047243744777367008101014255165543721437768956239217955454610653", "price": "0.75", "size": "10", "side": "BUY", "hash": "71271972a89245e7e7dc19875367223ca755e345", "best_bid": "0.8", "best_ask": "0.83"}, {"asset_id": "75977696589176706909494914683666626840477786548124398411155958119219599758391", "price": "0.25", "size": "10", "side": "SELL", "hash": "531f538845609d85bd176774a2ffb119bcc5299b", "best_bid": "0.17", "best_ask": "0.2"}], "timestamp": "1769384683289", "event_type": "price_change"}}
{"_local_timestamp": "2026-01-25T23:44:45.852681+00:00", "data": {"market": "0x6bbe585f51aedf96a92a4395f195633858a50a7ee9d5961a183b2fd858e2217c", "price_changes": [{"asset_id": "56479600937284047243744777367008101014255165543721437768956239217955454610653", "price": "0.74", "size": "0", "side": "BUY", "hash": "ce1eb0b62da903e452ecacda85db8fc5664a1bf8", "best_bid": "0.8", "best_ask": "0.83"}, {"asset_id": "75977696589176706909494914683666626840477786548124398411155958119219599758391", "price": "0.26", "size": "0", "side": "SELL", "hash": "e499f775740e009ef9175a45c60d982cb2eba958", "best_bid": "0.17", "best_ask": "0.2"}], "timestamp": "1769384685778", "event_type": "price_change"}}
{"_local_timestamp": "2026-01-25T23:44:45.871537+00:00", "data": {"market": "0x6bbe585f51aedf96a92a4395f195633858a50a7ee9d5961a183b2fd858e2217c", "price_changes": [{"asset_id": "56479600937284047243744777367008101014255165543721437768956239217955454610653", "price": "0.75", "size": "30", "side": "BUY", "hash": "7d98dcf037efdb50a8ac523a56f72088e8e5adb6", "best_bid": "0.8", "best_ask": "0.83"}, {"asset_id": "75977696589176706909494914683666626840477786548124398411155958119219599758391", "price": "0.25", "size": "30", "side": "SELL", "hash": "e501333436fae1ce8e482ab0959e51d6e3fbc033", "best_bid": "0.17", "best_ask": "0.2"}], "timestamp": "1769384685805", "event_type": "price_change"}}
{"_local_timestamp": "2026-01-25T23:44:47.644021+00:00", "data": {"market": "0x4ae33b3cb1b0af888ea00e0a035376c0319a56a8c28fb3521b22d28ecebbd94e", "price_changes": [{"asset_id": "107400623134616690037387608110271592167652294064537261328022766347776836196386", "price": "0.781", "size": "0", "side": "BUY", "hash": "2fbdfb7121f8b29eb53fb576667d90613e3411f5", "best_bid": "0.8", "best_ask": "0.811"}, {"asset_id": "42198988154346812250834138785680555306267908473427754988530622923073091857651", "price": "0.219", "size": "0", "side": "SELL", "hash": "abb9d77d00f29ce7a437ac118aa7d36591a0a241", "best_bid": "0.189", "best_ask": "0.2"}], "timestamp": "1769384687468", "event_type": "price_change"}}
{"_local_timestamp": "2026-01-25T23:44:51.200830+00:00", "data": {"market": "0x607a934e2b8c4275c4cb5a74c2ad7d9064554eb296fb4e2971cf3b7d76a927cc", "price_changes": [{"asset_id": "68148598936481792878619902635048180980784414819164814468271718813144330892107", "price": "0.185", "size": "0", "side": "BUY", "hash": "47c4ff647f90395faf73445f69e7383c20fe9a83", "best_bid": "0.878", "best_ask": "0.888"}, {"asset_id": "25975914361944378835569532810779694498194030305365204669451325469087977433544", "price": "0.815", "size": "0", "side": "SELL", "hash": "371775be30b97b5b6f521dfd4175a6a39a0b4a26", "best_bid": "0.112", "best_ask": "0.122"}], "timestamp": "1769384691130", "event_type": "price_change"}}
{"_local_timestamp": "2026-01-25T23:44:51.796136+00:00", "data": {"market": "0x607a934e2b8c4275c4cb5a74c2ad7d9064554eb296fb4e2971cf3b7d76a927cc", "price_changes": [{"asset_id": "68148598936481792878619902635048180980784414819164814468271718813144330892107", "price": "0.184", "size": "6.21", "side": "BUY", "hash": "471ba66194891ba6524eca743a34de2c0be0c749", "best_bid": "0.878", "best_ask": "0.888"}, {"asset_id": "25975914361944378835569532810779694498194030305365204669451325469087977433544", "price": "0.816", "size": "6.21", "side": "SELL", "hash": "d290b2b0eb9ad5753c27aa539dad18e5363f10b8", "best_bid": "0.112", "best_ask": "0.122"}], "timestamp": "1769384691719", "event_type": "price_change"}}
{"_local_timestamp": "2026-01-25T23:44:57.814599+00:00", "data": {"market": "0x607a934e2b8c4275c4cb5a74c2ad7d9064554eb296fb4e2971cf3b7d76a927cc", "price_changes": [{"asset_id": "68148598936481792878619902635048180980784414819164814468271718813144330892107", "price": "0.34", "size": "0", "side": "BUY", "hash": "9ef6ecd386fb6573bcd36c0f24b1b554142a98ad", "best_bid": "0.878", "best_ask": "0.888"}, {"asset_id": "25975914361944378835569532810779694498194030305365204669451325469087977433544", "price": "0.66", "size": "0", "side": "SELL", "hash": "86c365ffcbecb5eb924f2d6d5d28e31be283ca46", "best_bid": "0.112", "best_ask": "0.122"}], "timestamp": "1769384697730", "event_type": "price_change"}}
{"_local_timestamp": "2026-01-25T23:44:57.824831+00:00", "data": {"market": "0x6bbe585f51aedf96a92a4395f195633858a50a7ee9d5961a183b2fd858e2217c", "price_changes": [{"asset_id": "56479600937284047243744777367008101014255165543721437768956239217955454610653", "price": "0.26", "size": "0", "side": "BUY", "hash": "f27aa734a82a2ba9561eab44efb35d9e5512a15e", "best_bid": "0.8", "best_ask": "0.83"}, {"asset_id": "75977696589176706909494914683666626840477786548124398411155958119219599758391", "price": "0.74", "size": "0", "side": "SELL", "hash": "e21e704a32f260670efdb326f529f413075c9b90", "best_bid": "0.17", "best_ask": "0.2"}], "timestamp": "1769384697730", "event_type": "price_change"}}
{"_local_timestamp": "2026-01-25T23:44:57.825824+00:00", "data": {"market": "0x7587cc4497fc03e6bc20a2b9579d1a5cafd7778fcbd077f91f2c50fe5924259f", "price_changes": [{"asset_id": "28134581219669032059806644497841080110865577915276558812300476779313627788834", "price": "0.22", "size": "127.27", "side": "BUY", "hash": "e624a8d5afd1184edb9ca2fce05f073b49619f4b", "best_bid": "0.85", "best_ask": "0.87"}, {"asset_id": "113316597975241725413150018775135425644758743759237570300130816995662490799104", "price": "0.78", "size": "127.27", "side": "SELL", "hash": "d4be929bf2c6bf991e0146648b97c343060a7f2c", "best_bid": "0.13", "best_ask": "0.15"}], "timestamp": "1769384697730", "event_type": "price_change"}}
{"_local_timestamp": "2026-01-25T23:44:58.383043+00:00", "data": {"market": "0x6bbe585f51aedf96a92a4395f195633858a50a7ee9d5961a183b2fd858e2217c", "price_changes": [{"asset_id": "56479600937284047243744777367008101014255165543721437768956239217955454610653", "price": "0.2", "size": "190", "side": "BUY", "hash": "cbbcf42d9d967869e9407fe31e22149d2c50a189", "best_bid": "0.8", "best_ask": "0.83"}, {"asset_id": "75977696589176706909494914683666626840477786548124398411155958119219599758391", "price": "0.8", "size": "190", "side": "SELL", "hash": "5728a193979c21bc62f7855c6d829663ddba61d0", "best_bid": "0.17", "best_ask": "0.2"}], "timestamp": "1769384698233", "event_type": "price_change"}}
{"_local_timestamp": "2026-01-25T23:44:58.395938+00:00", "data": {"market": "0x607a934e2b8c4275c4cb5a74c2ad7d9064554eb296fb4e2971cf3b7d76a927cc", "price_changes": [{"asset_id": "68148598936481792878619902635048180980784414819164814468271718813144330892107", "price": "0.36", "size": "105.55", "side": "BUY", "hash": "422ec9314ec245f6ce21053377d4c8b406341844", "best_bid": "0.878", "best_ask": "0.888"}, {"asset_id": "25975914361944378835569532810779694498194030305365204669451325469087977433544", "price": "0.64", "size": "105.55", "side": "SELL", "hash": "b653ab707a7686dd8af6bc6ffa919b44bf03fd0a", "best_bid": "0.112", "best_ask": "0.122"}], "timestamp": "1769384698234", "event_type": "price_change"}}
{"_local_timestamp": "2026-01-25T23:44:58.424281+00:00", "data": {"market": "0x7587cc4497fc03e6bc20a2b9579d1a5cafd7778fcbd077f91f2c50fe5924259f", "price_changes": [{"asset_id": "28134581219669032059806644497841080110865577915276558812300476779313627788834", "price": "0.2", "size": "50", "side": "BUY", "hash": "5876cf3ef7f6a32b164185c909ba6048794d8c2a", "best_bid": "0.85", "best_ask": "0.87"}, {"asset_id": "113316597975241725413150018775135425644758743759237570300130816995662490799104", "price": "0.8", "size": "50", "side": "SELL", "hash": "11d1133275fedd4222cc095e4806564e104dcb68", "best_bid": "0.13", "best_ask": "0.15"}], "timestamp": "1769384698239", "event_type": "price_change"}}
{"_local_timestamp": "2026-01-25T23:44:58.849807+00:00", "data": {"market": "0x7587cc4497fc03e6bc20a2b9579d1a5cafd7778fcbd077f91f2c50fe5924259f", "price_changes": [{"asset_id": "28134581219669032059806644497841080110865577915276558812300476779313627788834", "price": "0.23", "size": "1826", "side": "BUY", "hash": "5100f7b6a2e78114c9482762ce2f99be157c698e", "best_bid": "0.85", "best_ask": "0.87"}, {"asset_id": "113316597975241725413150018775135425644758743759237570300130816995662490799104", "price": "0.77", "size": "1826", "side": "SELL", "hash": "4c29c7b057092cc753385e28b5586e1e2bf0ac19", "best_bid": "0.13", "best_ask": "0.15"}], "timestamp": "1769384698767", "event_type": "price_change"}}
{"_local_timestamp": "2026-01-25T23:45:18.875226+00:00", "data": {"market": "0x4ae33b3cb1b0af888ea00e0a035376c0319a56a8c28fb3521b22d28ecebbd94e", "price_changes": [{"asset_id": "107400623134616690037387608110271592167652294064537261328022766347776836196386", "price": "0.801", "size": "40", "side": "BUY", "hash": "0fae6207ed70ba0b6ee3f2f411221659003b33cb", "best_bid": "0.801", "best_ask": "0.811"}, {"asset_id": "42198988154346812250834138785680555306267908473427754988530622923073091857651", "price": "0.199", "size": "40", "side": "SELL", "hash": "5b13306bc08f06d351a4419a18a331d74fab6093", "best_bid": "0.189", "best_ask": "0.199"}], "timestamp": "1769384718803", "event_type": "price_change"}}
{"_local_timestamp": "2026-01-25T23:45:22.401861+00:00", "data": {"market": "0x4ae33b3cb1b0af888ea00e0a035376c0319a56a8c28fb3521b22d28ecebbd94e", "price_changes": [{"asset_id": "107400623134616690037387608110271592167652294064537261328022766347776836196386", "price": "0.799", "size": "0", "side": "BUY", "hash": "2901fae136fef3cc70952bcc203d261a9885340f", "best_bid": "0.801", "best_ask": "0.811"}, {"asset_id": "42198988154346812250834138785680555306267908473427754988530622923073091857651", "price": "0.201", "size": "0", "side": "SELL", "hash": "0f3d8756172c40011b0882a3d48def21928c0608", "best_bid": "0.189", "best_ask": "0.199"}], "timestamp": "1769384722328", "event_type": "price_change"}}
{"_local_timestamp": "2026-01-25T23:45:22.641835+00:00", "data": {"market": "0x4ae33b3cb1b0af888ea00e0a035376c0319a56a8c28fb3521b22d28ecebbd94e", "price_changes": [{"asset_id": "107400623134616690037387608110271592167652294064537261328022766347776836196386", "price": "0.8", "size": "728", "side": "BUY", "hash": "37413005f2e38eb33b317937a0b6abcd5e472c05", "best_bid": "0.801", "best_ask": "0.811"}, {"asset_id": "42198988154346812250834138785680555306267908473427754988530622923073091857651", "price": "0.2", "size": "728", "side": "SELL", "hash": "e2f9e40990320e5d7282cf1346edd348caa68dd9", "best_bid": "0.189", "best_ask": "0.199"}], "timestamp": "1769384722574", "event_type": "price_change"}}
{"_local_timestamp": "2026-01-25T23:45:25.351629+00:00", "data": {"market": "0x4ae33b3cb1b0af888ea00e0a035376c0319a56a8c28fb3521b22d28ecebbd94e", "price_changes": [{"asset_id": "107400623134616690037387608110271592167652294064537261328022766347776836196386", "price": "0.801", "size": "0", "side": "BUY", "hash": "ebd8160379510d1f8a8848331214324de30c7026", "best_bid": "0.8", "best_ask": "0.811"}, {"asset_id": "42198988154346812250834138785680555306267908473427754988530622923073091857651", "price": "0.199", "size": "0", "side": "SELL", "hash": "19664718e1b42107d1a153866716a5f45fefa778", "best_bid": "0.189", "best_ask": "0.2"}], "timestamp": "1769384725277", "event_type": "price_change"}}
{"_local_timestamp": "2026-01-25T23:45:26.717131+00:00", "data": {"market": "0x36352906a435bb57bbce5c12b8a016b42beee442645c27e025a6b605f167dbe1", "price_changes": [{"asset_id": "24865128979064458140408638815995003118177598043357620452530421257540758944225", "price": "0.241", "size": "1742", "side": "BUY", "hash": "e8d9c2cfda98384f71d439c2d6f16a1f4ecb1d55", "best_bid": "0.947", "best_ask": "0.957"}, {"asset_id": "31663847607839846905140169558614872784381523935014554710770021196634945212335", "price": "0.759", "size": "1742", "side": "SELL", "hash": "0e776d894dbf68a90753c18ba3c9d5dc9ddc4556", "best_bid": "0.043", "best_ask": "0.053"}], "timestamp": "1769384726643", "event_type": "price_change"}}
{"_local_timestamp": "2026-01-25T23:45:27.085942+00:00", "data": {"market": "0x36352906a435bb57bbce5c12b8a016b42beee442645c27e025a6b605f167dbe1", "price_changes": [{"asset_id": "31663847607839846905140169558614872784381523935014554710770021196634945212335", "price": "0.008", "size": "0", "side": "BUY", "hash": "c7047e384c99dff00bc5731ddead546df87ef5ae", "best_bid": "0.043", "best_ask": "0.053"}, {"asset_id": "24865128979064458140408638815995003118177598043357620452530421257540758944225", "price": "0.992", "size": "0", "side": "SELL", "hash": "c5eaeb9d0049d2bbd0c2f46b4d95401aa816c763", "best_bid": "0.947", "best_ask": "0.957"}], "timestamp": "1769384727002", "event_type": "price_change"}}
{"_local_timestamp": "2026-01-25T23:45:27.086951+00:00", "data": {"market": "0x36352906a435bb57bbce5c12b8a016b42beee442645c27e025a6b605f167dbe1", "price_changes": [{"asset_id": "24865128979064458140408638815995003118177598043357620452530421257540758944225", "price": "0.931", "size": "52", "side": "BUY", "hash": "878667c37d90f03b567731a13837be256d72644a", "best_bid": "0.947", "best_ask": "0.957"}, {"asset_id": "31663847607839846905140169558614872784381523935014554710770021196634945212335", "price": "0.069", "size": "52", "side": "SELL", "hash": "3272942c013a2bc536559b24dc81a1e27ff24e2b", "best_bid": "0.043", "best_ask": "0.053"}], "timestamp": "1769384727003", "event_type": "price_change"}}
{"_local_timestamp": "2026-01-25T23:45:27.113991+00:00", "data": {"market": "0x36352906a435bb57bbce5c12b8a016b42beee442645c27e025a6b605f167dbe1", "price_changes": [{"asset_id": "31663847607839846905140169558614872784381523935014554710770021196634945212335", "price": "0.043", "size": "20", "side": "BUY", "hash": "4f43bbb3a02b193c6839ca7aca78c4af00993118", "best_bid": "0.043", "best_ask": "0.053"}, {"asset_id": "24865128979064458140408638815995003118177598043357620452530421257540758944225", "price": "0.957", "size": "20", "side": "SELL", "hash": "d02bfb60672e5cd8d84c7d77f3ce58cc8950bcbb", "best_bid": "0.947", "best_ask": "0.957"}], "timestamp": "1769384727043", "event_type": "price_change"}}
{"_local_timestamp": "2026-01-25T23:45:27.134366+00:00", "data": {"market": "0x36352906a435bb57bbce5c12b8a016b42beee442645c27e025a6b605f167dbe1", "price_changes": [{"asset_id": "31663847607839846905140169558614872784381523935014554710770021196634945212335", "price": "0.043", "size": "85", "side": "BUY", "hash": "bddf8fbccb568c97c1293a21e6f8ad23b76e2a7d", "best_bid": "0.043", "best_ask": "0.053"}, {"asset_id": "24865128979064458140408638815995003118177598043357620452530421257540758944225", "price": "0.957", "size": "85", "side": "SELL", "hash": "26b50dc0dc3d2f5db4b0200f6de4479d97d98f79", "best_bid": "0.947", "best_ask": "0.957"}], "timestamp": "1769384727069", "event_type": "price_change"}}
{"_local_timestamp": "2026-01-25T23:45:29.401967+00:00", "data": {"market": "0x36352906a435bb57bbce5c12b8a016b42beee442645c27e025a6b605f167dbe1", "price_changes": [{"asset_id": "24865128979064458140408638815995003118177598043357620452530421257540758944225", "price": "0.931", "size": "32", "side": "BUY", "hash": "7f3d854c7211d45840212a2e39a9dba1f3272754", "best_bid": "0.947", "best_ask": "0.957"}, {"asset_id": "31663847607839846905140169558614872784381523935014554710770021196634945212335", "price": "0.069", "size": "32", "side": "SELL", "hash": "27ec49541b34829fb12ccfc712504fad469882f6", "best_bid": "0.043", "best_ask": "0.053"}], "timestamp": "1769384729323", "event_type": "price_change"}}
{"_local_timestamp": "2026-01-25T23:45:29.550850+00:00", "data": {"market": "0x36352906a435bb57bbce5c12b8a016b42beee442645c27e025a6b605f167dbe1", "price_changes": [{"asset_id": "31663847607839846905140169558614872784381523935014554710770021196634945212335", "price": "0.042", "size": "300", "side": "BUY", "hash": "f0811e1d89da05db5e8211174cc9cb46cfe5aff1", "best_bid": "0.043", "best_ask": "0.053"}, {"asset_id": "24865128979064458140408638815995003118177598043357620452530421257540758944225", "price": "0.958", "size": "300", "side": "SELL", "hash": "ba1e70bd1a391586372c5945b65ca605488a4e19", "best_bid": "0.947", "best_ask": "0.957"}], "timestamp": "1769384729475", "event_type": "price_change"}}
{"_local_timestamp": "2026-01-25T23:45:29.753184+00:00", "data": {"market": "0x4ae33b3cb1b0af888ea00e0a035376c0319a56a8c28fb3521b22d28ecebbd94e", "price_changes": [{"asset_id": "107400623134616690037387608110271592167652294064537261328022766347776836196386", "price": "0.8", "size": "708", "side": "BUY", "hash": "ccf127f4b0dc08207ec6cfd33015ac02ea785723", "best_bid": "0.8", "best_ask": "0.811"}, {"asset_id": "42198988154346812250834138785680555306267908473427754988530622923073091857651", "price": "0.2", "size": "708", "side": "SELL", "hash": "e64a5c922c58cbfba30bc568b00993f1b4c0c223", "best_bid": "0.189", "best_ask": "0.2"}], "timestamp": "1769384729682", "event_type": "price_change"}}
{"_local_timestamp": "2026-01-25T23:45:29.793018+00:00", "data": {"market": "0x36352906a435bb57bbce5c12b8a016b42beee442645c27e025a6b605f167dbe1", "price_changes": [{"asset_id": "31663847607839846905140169558614872784381523935014554710770021196634945212335", "price": "0.042", "size": "372", "side": "BUY", "hash": "23cd87f99fdd63545a72baf1ce4dd5185b7c56c3", "best_bid": "0.043", "best_ask": "0.053"}, {"asset_id": "24865128979064458140408638815995003118177598043357620452530421257540758944225", "price": "0.958", "size": "372", "side": "SELL", "hash": "9a86b0ff78c0532f3745486bca3fe0c4d05e71e4", "best_bid": "0.947", "best_ask": "0.957"}], "timestamp": "1769384729717", "event_type": "price_change"}}
{"_local_timestamp": "2026-01-25T23:45:29.990771+00:00", "data": {"market": "0x4ae33b3cb1b0af888ea00e0a035376c0319a56a8c28fb3521b22d28ecebbd94e", "price_changes": [{"asset_id": "107400623134616690037387608110271592167652294064537261328022766347776836196386", "price": "0.799", "size": "20", "side": "BUY", "hash": "ab4991f267eb0eaff6c787cfd6eedd5f037c946a", "best_bid": "0.8", "best_ask": "0.811"}, {"asset_id": "42198988154346812250834138785680555306267908473427754988530622923073091857651", "price": "0.201", "size": "20", "side": "SELL", "hash": "c5e466ddc35466ab502b661762af3876a0c3a60a", "best_bid": "0.189", "best_ask": "0.2"}], "timestamp": "1769384729912", "event_type": "price_change"}}
{"_local_timestamp": "2026-01-25T23:45:30.006406+00:00", "data": {"market": "0x36352906a435bb57bbce5c12b8a016b42beee442645c27e025a6b605f167dbe1", "price_changes": [{"asset_id": "24865128979064458140408638815995003118177598043357620452530421257540758944225", "price": "0.926", "size": "40", "side": "BUY", "hash": "6ee97fdef379da55bd8a5a9a98db75915eb4d013", "best_bid": "0.947", "best_ask": "0.957"}, {"asset_id": "31663847607839846905140169558614872784381523935014554710770021196634945212335", "price": "0.074", "size": "40", "side": "SELL", "hash": "0e9d072108f5229ecb9fe4cc38c1242152c822d9", "best_bid": "0.043", "best_ask": "0.053"}], "timestamp": "1769384729934", "event_type": "price_change"}}
{"_local_timestamp": "2026-01-25T23:45:30.021585+00:00", "data": {"market": "0x36352906a435bb57bbce5c12b8a016b42beee442645c27e025a6b605f167dbe1", "price_changes": [{"asset_id": "24865128979064458140408638815995003118177598043357620452530421257540758944225", "price": "0.946", "size": "0", "side": "BUY", "hash": "d15551049b1336e6881a161e20142dbb3863cb23", "best_bid": "0.947", "best_ask": "0.957"}, {"asset_id": "31663847607839846905140169558614872784381523935014554710770021196634945212335", "price": "0.054", "size": "0", "side": "SELL", "hash": "dc1e5481d0c7cde244a3ce92eeffb7cd29de24ee", "best_bid": "0.043", "best_ask": "0.053"}], "timestamp": "1769384729949", "event_type": "price_change"}}
{"_local_timestamp": "2026-01-25T23:45:30.041326+00:00", "data": {"market": "0x36352906a435bb57bbce5c12b8a016b42beee442645c27e025a6b605f167dbe1", "price_changes": [{"asset_id": "31663847607839846905140169558614872784381523935014554710770021196634945212335", "price": "0.043", "size": "20", "side": "BUY", "hash": "5c03c722736aeae6f32cfbb5ba4a5d180f3d7f33", "best_bid": "0.043", "best_ask": "0.053"}, {"asset_id": "24865128979064458140408638815995003118177598043357620452530421257540758944225", "price": "0.957", "size": "20", "side": "SELL", "hash": "82f49e8055017173474e96010c7038dada31b883", "best_bid": "0.947", "best_ask": "0.957"}], "timestamp": "1769384729974", "event_type": "price_change"}}
{"_local_timestamp": "2026-01-25T23:45:30.097621+00:00", "data": {"market": "0x36352906a435bb57bbce5c12b8a016b42beee442645c27e025a6b605f167dbe1", "price_changes": [{"asset_id": "31663847607839846905140169558614872784381523935014554710770021196634945212335", "price": "0.043", "size": "130", "side": "BUY", "hash": "970e4dd695e09d6b07d795588137cdade094cf54", "best_bid": "0.043", "best_ask": "0.053"}, {"asset_id": "24865128979064458140408638815995003118177598043357620452530421257540758944225", "price": "0.957", "size": "130", "side": "SELL", "hash": "c1be1ded2682331e4ead516ece7ebbfca63f62c2", "best_bid": "0.947", "best_ask": "0.957"}], "timestamp": "1769384730004", "event_type": "price_change"}}
{"_local_timestamp": "2026-01-25T23:45:30.254635+00:00", "data": {"market": "0x36352906a435bb57bbce5c12b8a016b42beee442645c27e025a6b605f167dbe1", "price_changes": [{"asset_id": "24865128979064458140408638815995003118177598043357620452530421257540758944225", "price": "0.946", "size": "72", "side": "BUY", "hash": "adc9d23aa4409ebd41b1a3e84a385299db0a162f", "best_bid": "0.947", "best_ask": "0.957"}, {"asset_id": "31663847607839846905140169558614872784381523935014554710770021196634945212335", "price": "0.054", "size": "72", "side": "SELL", "hash": "8d1f286f98a8f675056899d19c5af354e569f320", "best_bid": "0.043", "best_ask": "0.053"}], "timestamp": "1769384730179", "event_type": "price_change"}}
{"_local_timestamp": "2026-01-25T23:45:45.616972+00:00", "data": {"market": "0x6bbe585f51aedf96a92a4395f195633858a50a7ee9d5961a183b2fd858e2217c", "price_changes": [{"asset_id": "56479600937284047243744777367008101014255165543721437768956239217955454610653", "price": "0.75", "size": "20", "side": "BUY", "hash": "911e322b46c2d4c189bd20d0d34e183e7f0a5cb8", "best_bid": "0.8", "best_ask": "0.83"}, {"asset_id": "75977696589176706909494914683666626840477786548124398411155958119219599758391", "price": "0.25", "size": "20", "side": "SELL", "hash": "0e2e68e6bd27defa9133ce02c9f2aeff27df0d2d", "best_bid": "0.17", "best_ask": "0.2"}], "timestamp": "1769384745550", "event_type": "price_change"}}
{"_local_timestamp": "2026-01-25T23:45:45.646642+00:00", "data": {"market": "0x4ae33b3cb1b0af888ea00e0a035376c0319a56a8c28fb3521b22d28ecebbd94e", "price_changes": [{"asset_id": "107400623134616690037387608110271592167652294064537261328022766347776836196386", "price": "0.78", "size": "26", "side": "BUY", "hash": "e89c4c5138dcb05bd736ffaef4595ad0ab6579e4", "best_bid": "0.8", "best_ask": "0.811"}, {"asset_id": "42198988154346812250834138785680555306267908473427754988530622923073091857651", "price": "0.22", "size": "26", "side": "SELL", "hash": "48d68936a8f9bdc608b6c0f98b96a4b0ebb38003", "best_bid": "0.189", "best_ask": "0.2"}], "timestamp": "1769384745572", "event_type": "price_change"}}
{"_local_timestamp": "2026-01-25T23:45:45.647940+00:00", "data": {"market": "0xf65b917d7c4c2d6e01266807b8b7fa49eb9fd00bad3b7413529c264261470a44", "price_changes": [{"asset_id": "114083583916459364671762732480092206829910491378286392673263703828161447677389", "price": "0.74", "size": "828", "side": "BUY", "hash": "35a2ad95cffc91fc9d108e365abccc35194f4c06", "best_bid": "0.74", "best_ask": "0.78"}, {"asset_id": "21935961644840571543456790578994599010779256576943062204718832399472703918846", "price": "0.26", "size": "828", "side": "SELL", "hash": "ac753c0491a37e2f2b939bf9b4fd004185907e0c", "best_bid": "0.22", "best_ask": "0.26"}], "timestamp": "1769384745572", "event_type": "price_change"}}
{"_local_timestamp": "2026-01-25T23:45:45.648923+00:00", "data": {"market": "0x607a934e2b8c4275c4cb5a74c2ad7d9064554eb296fb4e2971cf3b7d76a927cc", "price_changes": [{"asset_id": "68148598936481792878619902635048180980784414819164814468271718813144330892107", "price": "0.857", "size": "6", "side": "BUY", "hash": "f9f0b2b993d00756832d9513f1de0ff1a24ddc24", "best_bid": "0.878", "best_ask": "0.888"}, {"asset_id": "25975914361944378835569532810779694498194030305365204669451325469087977433544", "price": "0.143", "size": "6", "side": "SELL", "hash": "492d7f0316fe1f7677819fed894080ac2851167c", "best_bid": "0.112", "best_ask": "0.122"}], "timestamp": "1769384745573", "event_type": "price_change"}}
{"_local_timestamp": "2026-01-25T23:45:45.651195+00:00", "data": {"market": "0xa9707d0632a18e9496ef040de9b74c5c61ccc606ac451405386d79572eb9f166", "price_changes": [{"asset_id": "19957097729009409865126104158146797340316615617946360478599220326663878583242", "price": "0.85", "size": "13", "side": "BUY", "hash": "a5923bc0f91053b3cd70d91e1087076d4466c33f", "best_bid": "0.86", "best_ask": "0.88"}, {"asset_id": "34597002803401285682259130297309092388381875227212304953516939814034307296564", "price": "0.15", "size": "13", "side": "SELL", "hash": "3407667b093d46b326f507a1ef82b81f305e7dfd", "best_bid": "0.12", "best_ask": "0.14"}], "timestamp": "1769384745574", "event_type": "price_change"}}
{"_local_timestamp": "2026-01-25T23:45:45.652165+00:00", "data": {"market": "0x7587cc4497fc03e6bc20a2b9579d1a5cafd7778fcbd077f91f2c50fe5924259f", "price_changes": [{"asset_id": "28134581219669032059806644497841080110865577915276558812300476779313627788834", "price": "0.83", "size": "0", "side": "BUY", "hash": "e71aa2d71954b89969e7b898ab1616e77a947101", "best_bid": "0.85", "best_ask": "0.87"}, {"asset_id": "113316597975241725413150018775135425644758743759237570300130816995662490799104", "price": "0.17", "size": "0", "side": "SELL", "hash": "c00b3763b204eb27645402fc49431447371b2c9c", "best_bid": "0.13", "best_ask": "0.15"}], "timestamp": "1769384745575", "event_type": "price_change"}}
{"_local_timestamp": "2026-01-25T23:45:45.653142+00:00", "data": {"market": "0x6bbe585f51aedf96a92a4395f195633858a50a7ee9d5961a183b2fd858e2217c", "price_changes": [{"asset_id": "56479600937284047243744777367008101014255165543721437768956239217955454610653", "price": "0.8", "size": "191.87", "side": "BUY", "hash": "0f70b6b9b7409158e6e45e90c12e99e47a72d180", "best_bid": "0.8", "best_ask": "0.83"}, {"asset_id": "75977696589176706909494914683666626840477786548124398411155958119219599758391", "price": "0.2", "size": "191.87", "side": "SELL", "hash": "9a432e883775b06bcb0bc1d5a33317332251d7c6", "best_bid": "0.17", "best_ask": "0.2"}], "timestamp": "1769384745579", "event_type": "price_change"}}
{"_local_timestamp": "2026-01-25T23:45:45.657616+00:00", "data": {"market": "0x36352906a435bb57bbce5c12b8a016b42beee442645c27e025a6b605f167dbe1", "price_changes": [{"asset_id": "24865128979064458140408638815995003118177598043357620452530421257540758944225", "price": "0.926", "size": "20", "side": "BUY", "hash": "69cc6a4958649e07258e3a61225d7a9d20b49d64", "best_bid": "0.947", "best_ask": "0.957"}, {"asset_id": "31663847607839846905140169558614872784381523935014554710770021196634945212335", "price": "0.074", "size": "20", "side": "SELL", "hash": "bb37d17dd57861ec6fbb060ab7c2abc606c4f2d6", "best_bid": "0.043", "best_ask": "0.053"}], "timestamp": "1769384745586", "event_type": "price_change"}}
{"_local_timestamp": "2026-01-25T23:45:45.717678+00:00", "data": {"market": "0x6bbe585f51aedf96a92a4395f195633858a50a7ee9d5961a183b2fd858e2217c", "price_changes": [{"asset_id": "56479600937284047243744777367008101014255165543721437768956239217955454610653", "price": "0.76", "size": "10", "side": "BUY", "hash": "653dfe64b4ea9278f5ebd925ec1630e7ded13202", "best_bid": "0.8", "best_ask": "0.83"}, {"asset_id": "75977696589176706909494914683666626840477786548124398411155958119219599758391", "price": "0.24", "size": "10", "side": "SELL", "hash": "14f80812fc801f085f3e979fa526441bd3affabc", "best_bid": "0.17", "best_ask": "0.2"}], "timestamp": "1769384745649", "event_type": "price_change"}}
{"_local_timestamp": "2026-01-25T23:45:45.732328+00:00", "data": {"market": "0x6bbe585f51aedf96a92a4395f195633858a50a7ee9d5961a183b2fd858e2217c", "price_changes": [{"asset_id": "56479600937284047243744777367008101014255165543721437768956239217955454610653", "price": "0.79", "size": "6", "side": "BUY", "hash": "db9be465dcf186f0390c20c76dc0aeadb67707b9", "best_bid": "0.8", "best_ask": "0.83"}, {"asset_id": "75977696589176706909494914683666626840477786548124398411155958119219599758391", "price": "0.21", "size": "6", "side": "SELL", "hash": "fbb9bbe15f8051acad165a4da3ab6b5960129df3", "best_bid": "0.17", "best_ask": "0.2"}], "timestamp": "1769384745663", "event_type": "price_change"}}
{"_local_timestamp": "2026-01-25T23:45:46.484396+00:00", "data": {"market": "0x36352906a435bb57bbce5c12b8a016b42beee442645c27e025a6b605f167dbe1", "price_changes": [{"asset_id": "31663847607839846905140169558614872784381523935014554710770021196634945212335", "price": "0.042", "size": "300", "side": "BUY", "hash": "2e33ce6618510a4d833f653f1b3625f5c103f0de", "best_bid": "0.043", "best_ask": "0.053"}, {"asset_id": "24865128979064458140408638815995003118177598043357620452530421257540758944225", "price": "0.958", "size": "300", "side": "SELL", "hash": "cfc9502d33a00ebc87a9ef273cebbef59de69eec", "best_bid": "0.947", "best_ask": "0.957"}], "timestamp": "1769384746414", "event_type": "price_change"}}
{"_local_timestamp": "2026-01-25T23:45:46.493024+00:00", "data": {"market": "0x4ae33b3cb1b0af888ea00e0a035376c0319a56a8c28fb3521b22d28ecebbd94e", "price_changes": [{"asset_id": "107400623134616690037387608110271592167652294064537261328022766347776836196386", "price": "0.799", "size": "0", "side": "BUY", "hash": "ffb9e4addec569852261d64922f46c5a96f4a5b1", "best_bid": "0.8", "best_ask": "0.811"}, {"asset_id": "42198988154346812250834138785680555306267908473427754988530622923073091857651", "price": "0.201", "size": "0", "side": "SELL", "hash": "694b05ba8d34e8a6398e2d512d664a07d55a239a", "best_bid": "0.189", "best_ask": "0.2"}], "timestamp": "1769384746427", "event_type": "price_change"}}
{"_local_timestamp": "2026-01-25T23:45:46.725426+00:00", "data": {"market": "0x36352906a435bb57bbce5c12b8a016b42beee442645c27e025a6b605f167dbe1", "price_changes": [{"asset_id": "31663847607839846905140169558614872784381523935014554710770021196634945212335", "price": "0.042", "size": "352", "side": "BUY", "hash": "f17522b02ea882dee141cebc97d580a5ea16c6a4", "best_bid": "0.043", "best_ask": "0.053"}, {"asset_id": "24865128979064458140408638815995003118177598043357620452530421257540758944225", "price": "0.958", "size": "352", "side": "SELL", "hash": "538725256f19f337df7fba4a107c0194afaeebe0", "best_bid": "0.947", "best_ask": "0.957"}], "timestamp": "1769384746659", "event_type": "price_change"}}
{"_local_timestamp": "2026-01-25T23:45:46.948640+00:00", "data": {"market": "0x36352906a435bb57bbce5c12b8a016b42beee442645c27e025a6b605f167dbe1", "price_changes": [{"asset_id": "24865128979064458140408638815995003118177598043357620452530421257540758944225", "price": "0.946", "size": "0", "side": "BUY", "hash": "8ba8ce723bb8e4292052ee40691d92484c66f058", "best_bid": "0.947", "best_ask": "0.957"}, {"asset_id": "31663847607839846905140169558614872784381523935014554710770021196634945212335", "price": "0.054", "size": "0", "side": "SELL", "hash": "fad78b2a041480c0089e1a59aeb067ed78440a18", "best_bid": "0.043", "best_ask": "0.053"}], "timestamp": "1769384746882", "event_type": "price_change"}}
{"_local_timestamp": "2026-01-25T23:45:47.182413+00:00", "data": {"market": "0x36352906a435bb57bbce5c12b8a016b42beee442645c27e025a6b605f167dbe1", "price_changes": [{"asset_id": "24865128979064458140408638815995003118177598043357620452530421257540758944225", "price": "0.946", "size": "52", "side": "BUY", "hash": "42efaea0d179f94ee80303531c6287ac859a81cb", "best_bid": "0.947", "best_ask": "0.957"}, {"asset_id": "31663847607839846905140169558614872784381523935014554710770021196634945212335", "price": "0.054", "size": "52", "side": "SELL", "hash": "df89f6b980bfe8e2bb7a520375dd574f8b83bad5", "best_bid": "0.043", "best_ask": "0.053"}], "timestamp": "1769384747107", "event_type": "price_change"}}
{"_local_timestamp": "2026-01-25T23:45:47.328492+00:00", "data": {"market": "0x6bbe585f51aedf96a92a4395f195633858a50a7ee9d5961a183b2fd858e2217c", "price_changes": [{"asset_id": "56479600937284047243744777367008101014255165543721437768956239217955454610653", "price": "0.75", "size": "0", "side": "BUY", "hash": "70a86bb9108c6d0bda41256699d3d6d76aff81f3", "best_bid": "0.8", "best_ask": "0.83"}, {"asset_id": "75977696589176706909494914683666626840477786548124398411155958119219599758391", "price": "0.25", "size": "0", "side": "SELL", "hash": "d3490bff3f13db92e1a67fbb35a202940fbdd03d", "best_bid": "0.17", "best_ask": "0.2"}], "timestamp": "1769384747261", "event_type": "price_change"}}
{"_local_timestamp": "2026-01-25T23:45:47.358039+00:00", "data": {"market": "0x6bbe585f51aedf96a92a4395f195633858a50a7ee9d5961a183b2fd858e2217c", "price_changes": [{"asset_id": "56479600937284047243744777367008101014255165543721437768956239217955454610653", "price": "0.74", "size": "20", "side": "BUY", "hash": "482bdda997b2776f3a6da362362e7f07c838f129", "best_bid": "0.8", "best_ask": "0.83"}, {"asset_id": "75977696589176706909494914683666626840477786548124398411155958119219599758391", "price": "0.26", "size": "20", "side": "SELL", "hash": "ad7c8aaee7f76062c6056483ece41c16e0481afd", "best_bid": "0.17", "best_ask": "0.2"}], "timestamp": "1769384747291", "event_type": "price_change"}}
{"_local_timestamp": "2026-01-25T23:45:53.142635+00:00", "data": {"market": "0x6bbe585f51aedf96a92a4395f195633858a50a7ee9d5961a183b2fd858e2217c", "price_changes": [{"asset_id": "56479600937284047243744777367008101014255165543721437768956239217955454610653", "price": "0.18", "size": "2482", "side": "BUY", "hash": "23fa1eb33ac7b26b6e9aaba91dad5b0dd9f7b6e4", "best_bid": "0.8", "best_ask": "0.83"}, {"asset_id": "75977696589176706909494914683666626840477786548124398411155958119219599758391", "price": "0.82", "size": "2482", "side": "SELL", "hash": "d9d1c715da3b296c150642ccb25a04074f4aff9e", "best_bid": "0.17", "best_ask": "0.2"}], "timestamp": "1769384753002", "event_type": "price_change"}}
{"_local_timestamp": "2026-01-25T23:45:53.219412+00:00", "data": {"market": "0x7587cc4497fc03e6bc20a2b9579d1a5cafd7778fcbd077f91f2c50fe5924259f", "price_changes": [{"asset_id": "28134581219669032059806644497841080110865577915276558812300476779313627788834", "price": "0.26", "size": "100", "side": "BUY", "hash": "00b0eebeb87ad0cdde60c90206718552e922889d", "best_bid": "0.85", "best_ask": "0.87"}, {"asset_id": "113316597975241725413150018775135425644758743759237570300130816995662490799104", "price": "0.74", "size": "100", "side": "SELL", "hash": "c7ec324bb4fd997107e51a785b9edcf19fb663a2", "best_bid": "0.13", "best_ask": "0.15"}], "timestamp": "1769384753012", "event_type": "price_change"}}
{"_local_timestamp": "2026-01-25T23:45:53.220536+00:00", "data": {"market": "0x7587cc4497fc03e6bc20a2b9579d1a5cafd7778fcbd077f91f2c50fe5924259f", "price_changes": [{"asset_id": "28134581219669032059806644497841080110865577915276558812300476779313627788834", "price": "0.18", "size": "1038", "side": "BUY", "hash": "00b0eebeb87ad0cdde60c90206718552e922889d", "best_bid": "0.85", "best_ask": "0.87"}, {"asset_id": "113316597975241725413150018775135425644758743759237570300130816995662490799104", "price": "0.82", "size": "1038", "side": "SELL", "hash": "c7ec324bb4fd997107e51a785b9edcf19fb663a2", "best_bid": "0.13", "best_ask": "0.15"}], "timestamp": "1769384753012", "event_type": "price_change"}}
{"_local_timestamp": "2026-01-25T23:45:53.633306+00:00", "data": {"market": "0x6bbe585f51aedf96a92a4395f195633858a50a7ee9d5961a183b2fd858e2217c", "price_changes": [{"asset_id": "56479600937284047243744777367008101014255165543721437768956239217955454610653", "price": "0.19", "size": "100", "side": "BUY", "hash": "779273774092ac10a1b1acf386aa77455116695a", "best_bid": "0.8", "best_ask": "0.83"}, {"asset_id": "75977696589176706909494914683666626840477786548124398411155958119219599758391", "price": "0.81", "size": "100", "side": "SELL", "hash": "f6f925464946b1edf9da98bcec4b39672bcfa69f", "best_bid": "0.17", "best_ask": "0.2"}], "timestamp": "1769384753510", "event_type": "price_change"}}
{"_local_timestamp": "2026-01-25T23:45:53.647084+00:00", "data": {"market": "0x7587cc4497fc03e6bc20a2b9579d1a5cafd7778fcbd077f91f2c50fe5924259f", "price_changes": [{"asset_id": "28134581219669032059806644497841080110865577915276558812300476779313627788834", "price": "0.2", "size": "150", "side": "BUY", "hash": "d08632dc07e2a4577a41f4fca7f7e2459bca0647", "best_bid": "0.85", "best_ask": "0.87"}, {"asset_id": "113316597975241725413150018775135425644758743759237570300130816995662490799104", "price": "0.8", "size": "150", "side": "SELL", "hash": "70a65c63a6797e8ab73415a2831a9fb0eb8d7617", "best_bid": "0.13", "best_ask": "0.15"}], "timestamp": "1769384753514", "event_type": "price_change"}}
{"_local_timestamp": "2026-01-25T23:45:53.767940+00:00", "data": {"market": "0x7587cc4497fc03e6bc20a2b9579d1a5cafd7778fcbd077f91f2c50fe5924259f", "price_changes": [{"asset_id": "28134581219669032059806644497841080110865577915276558812300476779313627788834", "price": "0.28", "size": "450", "side": "BUY", "hash": "7dcfecdc26de81c6119db3e9868d034ca99accb2", "best_bid": "0.85", "best_ask": "0.87"}, {"asset_id": "113316597975241725413150018775135425644758743759237570300130816995662490799104", "price": "0.72", "size": "450", "side": "SELL", "hash": "1fda13f615a2dbe93c512bc53570c69f48604de1", "best_bid": "0.13", "best_ask": "0.15"}], "timestamp": "1769384753546", "event_type": "price_change"}}
{"_local_timestamp": "2026-01-25T23:45:56.223132+00:00", "data": {"market": "0x6bbe585f51aedf96a92a4395f195633858a50a7ee9d5961a183b2fd858e2217c", "price_changes": [{"asset_id": "56479600937284047243744777367008101014255165543721437768956239217955454610653", "price": "0.27", "size": "200", "side": "BUY", "hash": "f82c56b20c60bee7258d1c274b67f67b012f3e3b", "best_bid": "0.8", "best_ask": "0.83"}, {"asset_id": "75977696589176706909494914683666626840477786548124398411155958119219599758391", "price": "0.73", "size": "200", "side": "SELL", "hash": "fe8355016eb3789cd11bd9169b9b2989d064773d", "best_bid": "0.17", "best_ask": "0.2"}], "timestamp": "1769384756077", "event_type": "price_change"}}
{"_local_timestamp": "2026-01-25T23:45:56.613248+00:00", "data": {"market": "0xf65b917d7c4c2d6e01266807b8b7fa49eb9fd00bad3b7413529c264261470a44", "price_changes": [{"asset_id": "114083583916459364671762732480092206829910491378286392673263703828161447677389", "price": "0.23", "size": "0", "side": "BUY", "hash": "5dfb83e7192ab98670923a56ae657ba4165b1a55", "best_bid": "0.74", "best_ask": "0.78"}, {"asset_id": "21935961644840571543456790578994599010779256576943062204718832399472703918846", "price": "0.77", "size": "0", "side": "SELL", "hash": "981ebccb8284d0f57e5e0041f3a06741f1da366f", "best_bid": "0.22", "best_ask": "0.26"}], "timestamp": "1769384756086", "event_type": "price_change"}}
{"_local_timestamp": "2026-01-25T23:45:56.771873+00:00", "data": {"market": "0x4ae33b3cb1b0af888ea00e0a035376c0319a56a8c28fb3521b22d28ecebbd94e", "price_changes": [{"asset_id": "107400623134616690037387608110271592167652294064537261328022766347776836196386", "price": "0.216", "size": "0", "side": "BUY", "hash": "2a1c46f8d19a3742f0c164c2e2c62ff9a9d4e499", "best_bid": "0.8", "best_ask": "0.811"}, {"asset_id": "42198988154346812250834138785680555306267908473427754988530622923073091857651", "price": "0.784", "size": "0", "side": "SELL", "hash": "3a5526bf1674f87fc033d8df429a3ea307908f75", "best_bid": "0.189", "best_ask": "0.2"}], "timestamp": "1769384756097", "event_type": "price_change"}}
{"_local_timestamp": "2026-01-25T23:46:10.560111+00:00", "data": {"market": "0x7587cc4497fc03e6bc20a2b9579d1a5cafd7778fcbd077f91f2c50fe5924259f", "price_changes": [{"asset_id": "28134581219669032059806644497841080110865577915276558812300476779313627788834", "price": "0.23", "size": "0", "side": "BUY", "hash": "53972304a1a9c66992857c56f0d92e5781dd3cf7", "best_bid": "0.85", "best_ask": "0.87"}, {"asset_id": "113316597975241725413150018775135425644758743759237570300130816995662490799104", "price": "0.77", "size": "0", "side": "SELL", "hash": "a528178562d50f41865ea7946819cc2ceb17b23f", "best_bid": "0.13", "best_ask": "0.15"}], "timestamp": "1769384770459", "event_type": "price_change"}}
{"_local_timestamp": "2026-01-25T23:46:10.626881+00:00", "data": {"market": "0x607a934e2b8c4275c4cb5a74c2ad7d9064554eb296fb4e2971cf3b7d76a927cc", "price_changes": [{"asset_id": "68148598936481792878619902635048180980784414819164814468271718813144330892107", "price": "0.221", "size": "0", "side": "BUY", "hash": "82664a546be2d50c5e712a8a00447fa3d06a4105", "best_bid": "0.878", "best_ask": "0.888"}, {"asset_id": "25975914361944378835569532810779694498194030305365204669451325469087977433544", "price": "0.779", "size": "0", "side": "SELL", "hash": "4d9d7ee49a3eeb415e85cb5aa84d08a54a85bb04", "best_bid": "0.112", "best_ask": "0.122"}], "timestamp": "1769384770468", "event_type": "price_change"}}
{"_local_timestamp": "2026-01-25T23:46:10.647276+00:00", "data": {"market": "0x36352906a435bb57bbce5c12b8a016b42beee442645c27e025a6b605f167dbe1", "price_changes": [{"asset_id": "24865128979064458140408638815995003118177598043357620452530421257540758944225", "price": "0.241", "size": "0", "side": "BUY", "hash": "ced46854316dc6ce7cebadc19812a33bf6c7dca2", "best_bid": "0.947", "best_ask": "0.957"}, {"asset_id": "31663847607839846905140169558614872784381523935014554710770021196634945212335", "price": "0.759", "size": "0", "side": "SELL", "hash": "4e2f12f99d637e777ebad03490ccd6b6930f0325", "best_bid": "0.043", "best_ask": "0.053"}], "timestamp": "1769384770461", "event_type": "price_change"}}
{"_local_timestamp": "2026-01-25T23:46:10.658661+00:00", "data": {"market": "0x6bbe585f51aedf96a92a4395f195633858a50a7ee9d5961a183b2fd858e2217c", "price_changes": [{"asset_id": "56479600937284047243744777367008101014255165543721437768956239217955454610653", "price": "0.18", "size": "150", "side": "BUY", "hash": "19c2f93c4e1e3b5489740e3d617cbe7d6e3b4aa1", "best_bid": "0.8", "best_ask": "0.83"}, {"asset_id": "75977696589176706909494914683666626840477786548124398411155958119219599758391", "price": "0.82", "size": "150", "side": "SELL", "hash": "7153904ea6e7ab1a7e62755148db213baeee1651", "best_bid": "0.17", "best_ask": "0.2"}], "timestamp": "1769384770459", "event_type": "price_change"}}
{"_local_timestamp": "2026-01-25T23:46:10.779945+00:00", "data": {"market": "0x36352906a435bb57bbce5c12b8a016b42beee442645c27e025a6b605f167dbe1", "price_changes": [{"asset_id": "31663847607839846905140169558614872784381523935014554710770021196634945212335", "price": "0.043", "size": "20", "side": "BUY", "hash": "9456a21f0db2622c787d5edacd95ce05b2899df6", "best_bid": "0.043", "best_ask": "0.053"}, {"asset_id": "24865128979064458140408638815995003118177598043357620452530421257540758944225", "price": "0.957", "size": "20", "side": "SELL", "hash": "0195008e76332015225f979027873e19b4ae709b", "best_bid": "0.947", "best_ask": "0.957"}], "timestamp": "1769384770578", "event_type": "price_change"}}
{"_local_timestamp": "2026-01-25T23:46:10.807167+00:00", "data": {"market": "0x36352906a435bb57bbce5c12b8a016b42beee442645c27e025a6b605f167dbe1", "price_changes": [{"asset_id": "31663847607839846905140169558614872784381523935014554710770021196634945212335", "price": "0.043", "size": "51", "side": "BUY", "hash": "d4312096fc6a8b0372e69a807c389f0e149c63f3", "best_bid": "0.043", "best_ask": "0.053"}, {"asset_id": "24865128979064458140408638815995003118177598043357620452530421257540758944225", "price": "0.957", "size": "51", "side": "SELL", "hash": "520fcfe94a0b21e60e78d325275775ff33d855e3", "best_bid": "0.947", "best_ask": "0.957"}], "timestamp": "1769384770603", "event_type": "price_change"}}
{"_local_timestamp": "2026-01-25T23:46:13.272907+00:00", "data": {"market": "0x7587cc4497fc03e6bc20a2b9579d1a5cafd7778fcbd077f91f2c50fe5924259f", "price_changes": [{"asset_id": "28134581219669032059806644497841080110865577915276558812300476779313627788834", "price": "0.27", "size": "1554", "side": "BUY", "hash": "1eda87868142fbdafc64e98a50bfc3cc082a2923", "best_bid": "0.85", "best_ask": "0.87"}, {"asset_id": "113316597975241725413150018775135425644758743759237570300130816995662490799104", "price": "0.73", "size": "1554", "side": "SELL", "hash": "d9ccbaa7d74e7285fa028a0991229af278331580", "best_bid": "0.13", "best_ask": "0.15"}], "timestamp": "1769384773202", "event_type": "price_change"}}
{"_local_timestamp": "2026-01-25T23:46:14.897613+00:00", "data": {"market": "0x36352906a435bb57bbce5c12b8a016b42beee442645c27e025a6b605f167dbe1", "price_changes": [{"asset_id": "31663847607839846905140169558614872784381523935014554710770021196634945212335", "price": "0.043", "size": "31", "side": "BUY", "hash": "f06a9afcef6bab9f4e0bb222a8c99af4f9e0a3bf", "best_bid": "0.043", "best_ask": "0.053"}, {"asset_id": "24865128979064458140408638815995003118177598043357620452530421257540758944225", "price": "0.957", "size": "31", "side": "SELL", "hash": "ff9f69977eaf0d8abc128af0c14838857380b386", "best_bid": "0.947", "best_ask": "0.957"}], "timestamp": "1769384774827", "event_type": "price_change"}}
{"_local_timestamp": "2026-01-25T23:46:15.485533+00:00", "data": {"market": "0x36352906a435bb57bbce5c12b8a016b42beee442645c27e025a6b605f167dbe1", "price_changes": [{"asset_id": "31663847607839846905140169558614872784381523935014554710770021196634945212335", "price": "0.032", "size": "141.68", "side": "BUY", "hash": "26c49d30d31f0a8ad5c16e8890f541d70d2c3e5f", "best_bid": "0.043", "best_ask": "0.053"}, {"asset_id": "24865128979064458140408638815995003118177598043357620452530421257540758944225", "price": "0.968", "size": "141.68", "side": "SELL", "hash": "bef138a57c67b9fead4fc7c863c2528dccc218e8", "best_bid": "0.947", "best_ask": "0.957"}], "timestamp": "1769384775414", "event_type": "price_change"}}
{"_local_timestamp": "2026-01-25T23:46:22.010751+00:00", "data": {"market": "0x7587cc4497fc03e6bc20a2b9579d1a5cafd7778fcbd077f91f2c50fe5924259f", "price_changes": [{"asset_id": "113316597975241725413150018775135425644758743759237570300130816995662490799104", "price": "0.1", "size": "21", "side": "BUY", "hash": "f5a1ea1792c36fd5d67e5a63875aabac878d3a46", "best_bid": "0.13", "best_ask": "0.15"}, {"asset_id": "28134581219669032059806644497841080110865577915276558812300476779313627788834", "price": "0.9", "size": "21", "side": "SELL", "hash": "076a9c2fbbd756b486f785fbfbf84ca00fe1106a", "best_bid": "0.85", "best_ask": "0.87"}], "timestamp": "1769384781946", "event_type": "price_change"}}
{"_local_timestamp": "2026-01-25T23:46:24.030328+00:00", "data": {"market": "0x36352906a435bb57bbce5c12b8a016b42beee442645c27e025a6b605f167dbe1", "price_changes": [{"asset_id": "24865128979064458140408638815995003118177598043357620452530421257540758944225", "price": "0.246", "size": "1706", "side": "BUY", "hash": "25359702e985f1868a60f84438814983b673e168", "best_bid": "0.947", "best_ask": "0.957"}, {"asset_id": "31663847607839846905140169558614872784381523935014554710770021196634945212335", "price": "0.754", "size": "1706", "side": "SELL", "hash": "973bb6ee748ec01ec99779f6b93a16f36e753cc3", "best_bid": "0.043", "best_ask": "0.053"}], "timestamp": "1769384783950", "event_type": "price_change"}}
{"_local_timestamp": "2026-01-25T23:46:24.050099+00:00", "data": {"market": "0x36352906a435bb57bbce5c12b8a016b42beee442645c27e025a6b605f167dbe1", "price_changes": [{"asset_id": "31663847607839846905140169558614872784381523935014554710770021196634945212335", "price": "0.043", "size": "0", "side": "BUY", "hash": "da55707039192081b37ea194ea8fd2283911a886", "best_bid": "0.042", "best_ask": "0.053"}, {"asset_id": "24865128979064458140408638815995003118177598043357620452530421257540758944225", "price": "0.957", "size": "0", "side": "SELL", "hash": "a939bd606a2b49fcd27858518fd525eb01c65b2e", "best_bid": "0.947", "best_ask": "0.958"}], "timestamp": "1769384783978", "event_type": "price_change"}}
{"_local_timestamp": "2026-01-25T23:46:24.089905+00:00", "data": {"market": "0x36352906a435bb57bbce5c12b8a016b42beee442645c27e025a6b605f167dbe1", "price_changes": [{"asset_id": "31663847607839846905140169558614872784381523935014554710770021196634945212335", "price": "0.043", "size": "92", "side": "BUY", "hash": "87f45fa26c4ad3f58b9808a10d25b3eadec496dc", "best_bid": "0.043", "best_ask": "0.053"}, {"asset_id": "24865128979064458140408638815995003118177598043357620452530421257540758944225", "price": "0.957", "size": "92", "side": "SELL", "hash": "8cec49f49bc1a797431f50d863aa23d541f97e50", "best_bid": "0.947", "best_ask": "0.957"}], "timestamp": "1769384784004", "event_type": "price_change"}}
{"_local_timestamp": "2026-01-25T23:46:24.479347+00:00", "data": {"market": "0x6bbe585f51aedf96a92a4395f195633858a50a7ee9d5961a183b2fd858e2217c", "price_changes": [{"asset_id": "56479600937284047243744777367008101014255165543721437768956239217955454610653", "price": "0.19", "size": "2310", "side": "BUY", "hash": "af23bd203a72aaff85db32ed28083019958ca6c6", "best_bid": "0.8", "best_ask": "0.83"}, {"asset_id": "75977696589176706909494914683666626840477786548124398411155958119219599758391", "price": "0.81", "size": "2310", "side": "SELL", "hash": "75ac1798296bb83029ff78f29143ce9c475bbb70", "best_bid": "0.17", "best_ask": "0.2"}], "timestamp": "1769384784411", "event_type": "price_change"}}
{"_local_timestamp": "2026-01-25T23:46:24.566713+00:00", "data": {"market": "0xf65b917d7c4c2d6e01266807b8b7fa49eb9fd00bad3b7413529c264261470a44", "price_changes": [{"asset_id": "114083583916459364671762732480092206829910491378286392673263703828161447677389", "price": "0.7", "size": "10", "side": "BUY", "hash": "8d26d4f464dc661a59985f4d38df23cbfbe4f17e", "best_bid": "0.74", "best_ask": "0.78"}, {"asset_id": "21935961644840571543456790578994599010779256576943062204718832399472703918846", "price": "0.3", "size": "10", "side": "SELL", "hash": "82da1c8545bd6d68617e511255eb7e2889184aea", "best_bid": "0.22", "best_ask": "0.26"}], "timestamp": "1769384784500", "event_type": "price_change"}}
{"_local_timestamp": "2026-01-25T23:46:24.574318+00:00", "data": {"market": "0x7587cc4497fc03e6bc20a2b9579d1a5cafd7778fcbd077f91f2c50fe5924259f", "price_changes": [{"asset_id": "28134581219669032059806644497841080110865577915276558812300476779313627788834", "price": "0.79", "size": "0", "side": "BUY", "hash": "30883c4dead948ec1b83cfe18097c0aa2c95f905", "best_bid": "0.85", "best_ask": "0.87"}, {"asset_id": "113316597975241725413150018775135425644758743759237570300130816995662490799104", "price": "0.21", "size": "0", "side": "SELL", "hash": "efaf6d044ce2a1c60fd1ed914179df1e64b122e7", "best_bid": "0.13", "best_ask": "0.15"}], "timestamp": "1769384784500", "event_type": "price_change"}}
{"_local_timestamp": "2026-01-25T23:46:24.605077+00:00", "data": {"market": "0xf65b917d7c4c2d6e01266807b8b7fa49eb9fd00bad3b7413529c264261470a44", "price_changes": [{"asset_id": "114083583916459364671762732480092206829910491378286392673263703828161447677389", "price": "0.68", "size": "20", "side": "BUY", "hash": "b8b9f945e5a8b2c72304826cb2e96d8de38fcb48", "best_bid": "0.74", "best_ask": "0.78"}, {"asset_id": "21935961644840571543456790578994599010779256576943062204718832399472703918846", "price": "0.32", "size": "20", "side": "SELL", "hash": "a336fc82271def3ba4e656953688a4cd29d98130", "best_bid": "0.22", "best_ask": "0.26"}], "timestamp": "1769384784532", "event_type": "price_change"}}
{"_local_timestamp": "2026-01-25T23:46:24.606222+00:00", "data": {"market": "0x7587cc4497fc03e6bc20a2b9579d1a5cafd7778fcbd077f91f2c50fe5924259f", "price_changes": [{"asset_id": "28134581219669032059806644497841080110865577915276558812300476779313627788834", "price": "0.78", "size": "34.1", "side": "BUY", "hash": "da636239eca96718152f4894ee67993a8ade9e09", "best_bid": "0.85", "best_ask": "0.87"}, {"asset_id": "113316597975241725413150018775135425644758743759237570300130816995662490799104", "price": "0.22", "size": "34.1", "side": "SELL", "hash": "a31da0d8209443c660ab34a86cac582e1878cb77", "best_bid": "0.13", "best_ask": "0.15"}], "timestamp": "1769384784532", "event_type": "price_change"}}
{"_local_timestamp": "2026-01-25T23:46:25.543690+00:00", "data": {"market": "0x7587cc4497fc03e6bc20a2b9579d1a5cafd7778fcbd077f91f2c50fe5924259f", "price_changes": [{"asset_id": "28134581219669032059806644497841080110865577915276558812300476779313627788834", "price": "0.78", "size": "14.1", "side": "BUY", "hash": "7f399e32eded853fa6ce83c9f07e84620d5176e2", "best_bid": "0.85", "best_ask": "0.87"}, {"asset_id": "113316597975241725413150018775135425644758743759237570300130816995662490799104", "price": "0.22", "size": "14.1", "side": "SELL", "hash": "674daeffb2f2ed69b87ce0efe33f3d68d5a9bb80", "best_bid": "0.13", "best_ask": "0.15"}], "timestamp": "1769384785473", "event_type": "price_change"}}
{"_local_timestamp": "2026-01-25T23:46:25.544836+00:00", "data": {"market": "0xf65b917d7c4c2d6e01266807b8b7fa49eb9fd00bad3b7413529c264261470a44", "price_changes": [{"asset_id": "114083583916459364671762732480092206829910491378286392673263703828161447677389", "price": "0.68", "size": "0", "side": "BUY", "hash": "722f6ecb96b96824ecb5ddb831d40d4f2ba7290c", "best_bid": "0.74", "best_ask": "0.78"}, {"asset_id": "21935961644840571543456790578994599010779256576943062204718832399472703918846", "price": "0.32", "size": "0", "side": "SELL", "hash": "af2bc539563bd6729da851d9d2bde007d20420c6", "best_bid": "0.22", "best_ask": "0.26"}], "timestamp": "1769384785473", "event_type": "price_change"}}
{"_local_timestamp": "2026-01-25T23:46:25.579935+00:00", "data": {"market": "0x7587cc4497fc03e6bc20a2b9579d1a5cafd7778fcbd077f91f2c50fe5924259f", "price_changes": [{"asset_id": "28134581219669032059806644497841080110865577915276558812300476779313627788834", "price": "0.79", "size": "20", "side": "BUY", "hash": "9fe22968577b401a32c45946ea2c8c85aadc67f3", "best_bid": "0.85", "best_ask": "0.87"}, {"asset_id": "113316597975241725413150018775135425644758743759237570300130816995662490799104", "price": "0.21", "size": "20", "side": "SELL", "hash": "55201548451e8d324200c7ca13c38e83ed3d58a2", "best_bid": "0.13", "best_ask": "0.15"}], "timestamp": "1769384785508", "event_type": "price_change"}}
{"_local_timestamp": "2026-01-25T23:46:25.581120+00:00", "data": {"market": "0xf65b917d7c4c2d6e01266807b8b7fa49eb9fd00bad3b7413529c264261470a44", "price_changes": [{"asset_id": "114083583916459364671762732480092206829910491378286392673263703828161447677389", "price": "0.7", "size": "30", "side": "BUY", "hash": "8da432c2e01611d1315ddedf761218e0cdca2d3e", "best_bid": "0.74", "best_ask": "0.78"}, {"asset_id": "21935961644840571543456790578994599010779256576943062204718832399472703918846", "price": "0.3", "size": "30", "side": "SELL", "hash": "5853c56b521cc41bfa8236e6279dd3a84a4e28d8", "best_bid": "0.22", "best_ask": "0.26"}], "timestamp": "1769384785508", "event_type": "price_change"}}
{"_local_timestamp": "2026-01-25T23:46:30.579549+00:00", "data": {"market": "0x36352906a435bb57bbce5c12b8a016b42beee442645c27e025a6b605f167dbe1", "price_changes": [{"asset_id": "31663847607839846905140169558614872784381523935014554710770021196634945212335", "price": "0.032", "size": "121.68", "side": "BUY", "hash": "297e9fe2784ef4dcc51e010ec9b63ade0c15e95b", "best_bid": "0.043", "best_ask": "0.053"}, {"asset_id": "24865128979064458140408638815995003118177598043357620452530421257540758944225", "price": "0.968", "size": "121.68", "side": "SELL", "hash": "0c7804695db540a468b7e9d09569fb7349bc4f5b", "best_bid": "0.947", "best_ask": "0.957"}], "timestamp": "1769384790462", "event_type": "price_change"}}
{"_local_timestamp": "2026-01-25T23:46:30.641580+00:00", "data": {"market": "0x36352906a435bb57bbce5c12b8a016b42beee442645c27e025a6b605f167dbe1", "price_changes": [{"asset_id": "31663847607839846905140169558614872784381523935014554710770021196634945212335", "price": "0.043", "size": "112", "side": "BUY", "hash": "73adee509b832cc55f43324ecc8466d5c5bd9644", "best_bid": "0.043", "best_ask": "0.053"}, {"asset_id": "24865128979064458140408638815995003118177598043357620452530421257540758944225", "price": "0.957", "size": "112", "side": "SELL", "hash": "7ad128f33720cc49a51885d9537714ecbd72ad3a", "best_bid": "0.947", "best_ask": "0.957"}], "timestamp": "1769384790510", "event_type": "price_change"}}
{"_local_timestamp": "2026-01-25T23:46:37.299777+00:00", "data": {"market": "0x6bbe585f51aedf96a92a4395f195633858a50a7ee9d5961a183b2fd858e2217c", "price_changes": [{"asset_id": "56479600937284047243744777367008101014255165543721437768956239217955454610653", "price": "0.19", "size": "2610", "side": "BUY", "hash": "a2ac7afe86a0b4645af95607b1283d2a380b5108", "best_bid": "0.8", "best_ask": "0.83"}, {"asset_id": "75977696589176706909494914683666626840477786548124398411155958119219599758391", "price": "0.81", "size": "2610", "side": "SELL", "hash": "f45f597b644304bcae748c800ea000a161183f7a", "best_bid": "0.17", "best_ask": "0.2"}], "timestamp": "1769384797025", "event_type": "price_change"}}
{"_local_timestamp": "2026-01-25T23:46:37.321158+00:00", "data": {"market": "0x4ae33b3cb1b0af888ea00e0a035376c0319a56a8c28fb3521b22d28ecebbd94e", "price_changes": [{"asset_id": "107400623134616690037387608110271592167652294064537261328022766347776836196386", "price": "0.218", "size": "300", "side": "BUY", "hash": "5efdd0991ff075c370e25b2ddbc8ed1d0c5354c0", "best_bid": "0.8", "best_ask": "0.811"}, {"asset_id": "42198988154346812250834138785680555306267908473427754988530622923073091857651", "price": "0.782", "size": "300", "side": "SELL", "hash": "c96f2a19adc94aa1455a39c8e4dfc4b81efad93b", "best_bid": "0.189", "best_ask": "0.2"}], "timestamp": "1769384797027", "event_type": "price_change"}}
{"_local_timestamp": "2026-01-25T23:46:37.322440+00:00", "data": {"market": "0xf65b917d7c4c2d6e01266807b8b7fa49eb9fd00bad3b7413529c264261470a44", "price_changes": [{"asset_id": "114083583916459364671762732480092206829910491378286392673263703828161447677389", "price": "0.25", "size": "404", "side": "BUY", "hash": "1481e3655b97513acd97a9062ff52272bc4b83eb", "best_bid": "0.74", "best_ask": "0.78"}, {"asset_id": "21935961644840571543456790578994599010779256576943062204718832399472703918846", "price": "0.75", "size": "404", "side": "SELL", "hash": "7c4992047482f0283b5e8ab218cf222702db5334", "best_bid": "0.22", "best_ask": "0.26"}], "timestamp": "1769384797027", "event_type": "price_change"}}
{"_local_timestamp": "2026-01-25T23:46:46.129712+00:00", "data": {"market": "0xa9707d0632a18e9496ef040de9b74c5c61ccc606ac451405386d79572eb9f166", "price_changes": [{"asset_id": "19957097729009409865126104158146797340316615617946360478599220326663878583242", "price": "0.83", "size": "10.66", "side": "BUY", "hash": "0a61589c41b93d8fa8f056cf4067c384231aa15b", "best_bid": "0.86", "best_ask": "0.88"}, {"asset_id": "34597002803401285682259130297309092388381875227212304953516939814034307296564", "price": "0.17", "size": "10.66", "side": "SELL", "hash": "989b9ceedfd1587d414116a4e3ec5b1992fae68b", "best_bid": "0.12", "best_ask": "0.14"}], "timestamp": "1769384805999", "event_type": "price_change"}}
{"_local_timestamp": "2026-01-25T23:46:46.131023+00:00", "data": {"market": "0xa9707d0632a18e9496ef040de9b74c5c61ccc606ac451405386d79572eb9f166", "price_changes": [{"asset_id": "34597002803401285682259130297309092388381875227212304953516939814034307296564", "price": "0.09", "size": "30", "side": "BUY", "hash": "08729f1fe20eb31f468a6f9f86a9717e5eeb9d86", "best_bid": "0.12", "best_ask": "0.14"}, {"asset_id": "19957097729009409865126104158146797340316615617946360478599220326663878583242", "price": "0.91", "size": "30", "side": "SELL", "hash": "a576da9331c3ecd56eaf4b80aab61d9abb6fe4b1", "best_bid": "0.86", "best_ask": "0.88"}], "timestamp": "1769384805999", "event_type": "price_change"}}
{"_local_timestamp": "2026-01-25T23:46:50.859551+00:00", "data": {"market": "0x607a934e2b8c4275c4cb5a74c2ad7d9064554eb296fb4e2971cf3b7d76a927cc", "price_changes": [{"asset_id": "68148598936481792878619902635048180980784414819164814468271718813144330892107", "price": "0.361", "size": "0", "side": "BUY", "hash": "ed082dfb69ff0762d39026d3c7a584de8210aad8", "best_bid": "0.878", "best_ask": "0.888"}, {"asset_id": "25975914361944378835569532810779694498194030305365204669451325469087977433544", "price": "0.639", "size": "0", "side": "SELL", "hash": "b592a2c34ef7ed7ead500bc1b10336bdc8ac16b6", "best_bid": "0.112", "best_ask": "0.122"}], "timestamp": "1769384810648", "event_type": "price_change"}}
{"_local_timestamp": "2026-01-25T23:46:50.861040+00:00", "data": {"market": "0x7587cc4497fc03e6bc20a2b9579d1a5cafd7778fcbd077f91f2c50fe5924259f", "price_changes": [{"asset_id": "28134581219669032059806644497841080110865577915276558812300476779313627788834", "price": "0.18", "size": "888", "side": "BUY", "hash": "7ea35bc7d1636c627db2f39bbc56dee193aba7d8", "best_bid": "0.85", "best_ask": "0.87"}, {"asset_id": "113316597975241725413150018775135425644758743759237570300130816995662490799104", "price": "0.82", "size": "888", "side": "SELL", "hash": "c0dd4ab259262d0c1528f178b47a6e307eb95fba", "best_bid": "0.13", "best_ask": "0.15"}], "timestamp": "1769384810648", "event_type": "price_change"}}
{"_local_timestamp": "2026-01-25T23:46:50.862196+00:00", "data": {"market": "0x6bbe585f51aedf96a92a4395f195633858a50a7ee9d5961a183b2fd858e2217c", "price_changes": [{"asset_id": "56479600937284047243744777367008101014255165543721437768956239217955454610653", "price": "0.18", "size": "0", "side": "BUY", "hash": "5f077a0a9412cbfcd5ca372635c0be46228ff8d3", "best_bid": "0.8", "best_ask": "0.83"}, {"asset_id": "75977696589176706909494914683666626840477786548124398411155958119219599758391", "price": "0.82", "size": "0", "side": "SELL", "hash": "07f1be9c583f6ad5e62c7af1dba248cf1b6af0be", "best_bid": "0.17", "best_ask": "0.2"}], "timestamp": "1769384810648", "event_type": "price_change"}}
{"_local_timestamp": "2026-01-25T23:46:51.662032+00:00", "data": {"market": "0x6bbe585f51aedf96a92a4395f195633858a50a7ee9d5961a183b2fd858e2217c", "price_changes": [{"asset_id": "56479600937284047243744777367008101014255165543721437768956239217955454610653", "price": "0.19", "size": "2760", "side": "BUY", "hash": "0b852a92d4b261676056b0fb6af660fc1e66ad5b", "best_bid": "0.8", "best_ask": "0.83"}, {"asset_id": "75977696589176706909494914683666626840477786548124398411155958119219599758391", "price": "0.81", "size": "2760", "side": "SELL", "hash": "e5ff11cd6de1156ccdb5204f221ba256e693d269", "best_bid": "0.17", "best_ask": "0.2"}], "timestamp": "1769384811226", "event_type": "price_change"}}
{"_local_timestamp": "2026-01-25T23:46:51.675265+00:00", "data": {"market": "0x7587cc4497fc03e6bc20a2b9579d1a5cafd7778fcbd077f91f2c50fe5924259f", "price_changes": [{"asset_id": "28134581219669032059806644497841080110865577915276558812300476779313627788834", "price": "0.2", "size": "300", "side": "BUY", "hash": "d03602f2d758fc8419175c0571d66d353f187e8f", "best_bid": "0.85", "best_ask": "0.87"}, {"asset_id": "113316597975241725413150018775135425644758743759237570300130816995662490799104", "price": "0.8", "size": "300", "side": "SELL", "hash": "e1d386ff1adb9fc63556a911b2e3cff965b2b67a", "best_bid": "0.13", "best_ask": "0.15"}], "timestamp": "1769384811226", "event_type": "price_change"}}
{"_local_timestamp": "2026-01-25T23:46:54.095435+00:00", "data": {"market": "0x6bbe585f51aedf96a92a4395f195633858a50a7ee9d5961a183b2fd858e2217c", "price_changes": [{"asset_id": "75977696589176706909494914683666626840477786548124398411155958119219599758391", "price": "0.1", "size": "21", "side": "BUY", "hash": "51aff08307082e833e1990895ebda1e7b3f57143", "best_bid": "0.17", "best_ask": "0.2"}, {"asset_id": "56479600937284047243744777367008101014255165543721437768956239217955454610653", "price": "0.9", "size": "21", "side": "SELL", "hash": "65e9b4385f957e1fabfb7dad2f989f8b034100b2", "best_bid": "0.8", "best_ask": "0.83"}], "timestamp": "1769384813969", "event_type": "price_change"}}
{"_local_timestamp": "2026-01-25T23:46:56.059790+00:00", "data": {"market": "0x6bbe585f51aedf96a92a4395f195633858a50a7ee9d5961a183b2fd858e2217c", "price_changes": [{"asset_id": "75977696589176706909494914683666626840477786548124398411155958119219599758391", "price": "0.09", "size": "0", "side": "BUY", "hash": "bd40d93bb8ba7e081151798bc3d77e6a55032dbe", "best_bid": "0.17", "best_ask": "0.2"}, {"asset_id": "56479600937284047243744777367008101014255165543721437768956239217955454610653", "price": "0.91", "size": "0", "side": "SELL", "hash": "9af279056fc8ee3feda661bbfb9b4726e33763d0", "best_bid": "0.8", "best_ask": "0.83"}], "timestamp": "1769384815967", "event_type": "price_change"}}
{"_local_timestamp": "2026-01-25T23:46:56.148871+00:00", "data": {"market": "0x6bbe585f51aedf96a92a4395f195633858a50a7ee9d5961a183b2fd858e2217c", "price_changes": [{"asset_id": "75977696589176706909494914683666626840477786548124398411155958119219599758391", "price": "0.11", "size": "10", "side": "BUY", "hash": "b3faeb19e2981e6dbd40b73c3537c478ae9c237f", "best_bid": "0.17", "best_ask": "0.2"}, {"asset_id": "56479600937284047243744777367008101014255165543721437768956239217955454610653", "price": "0.89", "size": "10", "side": "SELL", "hash": "03c3a63ee3375278b895ecb2323346d9828e5aaf", "best_bid": "0.8", "best_ask": "0.83"}], "timestamp": "1769384816057", "event_type": "price_change"}}
{"_local_timestamp": "2026-01-25T23:46:56.240342+00:00", "data": {"market": "0x6bbe585f51aedf96a92a4395f195633858a50a7ee9d5961a183b2fd858e2217c", "price_changes": [{"asset_id": "56479600937284047243744777367008101014255165543721437768956239217955454610653", "price": "0.76", "size": "0", "side": "BUY", "hash": "965d2dc1c5db6df88a6d2dade4e547467d3fdf93", "best_bid": "0.8", "best_ask": "0.83"}, {"asset_id": "75977696589176706909494914683666626840477786548124398411155958119219599758391", "price": "0.24", "size": "0", "side": "SELL", "hash": "92ad8cee6565cbe533fb6abdebcafa7727aada48", "best_bid": "0.17", "best_ask": "0.2"}], "timestamp": "1769384816136", "event_type": "price_change"}}
{"_local_timestamp": "2026-01-25T23:46:56.318781+00:00", "data": {"market": "0x6bbe585f51aedf96a92a4395f195633858a50a7ee9d5961a183b2fd858e2217c", "price_changes": [{"asset_id": "56479600937284047243744777367008101014255165543721437768956239217955454610653", "price": "0.75", "size": "10", "side": "BUY", "hash": "414b2a568d5ae857aba04f043ac370ab373ab74e", "best_bid": "0.8", "best_ask": "0.83"}, {"asset_id": "75977696589176706909494914683666626840477786548124398411155958119219599758391", "price": "0.25", "size": "10", "side": "SELL", "hash": "3bf5f0f34fcf31c04b0f37413c710a6557f23a52", "best_bid": "0.17", "best_ask": "0.2"}], "timestamp": "1769384816227", "event_type": "price_change"}}
{"_local_timestamp": "2026-01-25T23:46:58.505867+00:00", "data": {"market": "0x6bbe585f51aedf96a92a4395f195633858a50a7ee9d5961a183b2fd858e2217c", "price_changes": [{"asset_id": "56479600937284047243744777367008101014255165543721437768956239217955454610653", "price": "0.74", "size": "0", "side": "BUY", "hash": "18973944b61223f365e193ca6bc20c21ee6f3918", "best_bid": "0.8", "best_ask": "0.83"}, {"asset_id": "75977696589176706909494914683666626840477786548124398411155958119219599758391", "price": "0.26", "size": "0", "side": "SELL", "hash": "bcaaeac6dcee6fd0b173401e6ffa99264df3b6ed", "best_bid": "0.17", "best_ask": "0.2"}], "timestamp": "1769384818382", "event_type": "price_change"}}
{"_local_timestamp": "2026-01-25T23:46:58.617318+00:00", "data": {"market": "0x6bbe585f51aedf96a92a4395f195633858a50a7ee9d5961a183b2fd858e2217c", "price_changes": [{"asset_id": "56479600937284047243744777367008101014255165543721437768956239217955454610653", "price": "0.75", "size": "30", "side": "BUY", "hash": "af8f62eb46b6f8a112361a5e881286a0400565a1", "best_bid": "0.8", "best_ask": "0.83"}, {"asset_id": "75977696589176706909494914683666626840477786548124398411155958119219599758391", "price": "0.25", "size": "30", "side": "SELL", "hash": "1c876c1c1f777ece0d8c85e732c5303af4b2c8a5", "best_bid": "0.17", "best_ask": "0.2"}], "timestamp": "1769384818424", "event_type": "price_change"}}
{"_local_timestamp": "2026-01-25T23:47:00.862131+00:00", "data": {"market": "0x607a934e2b8c4275c4cb5a74c2ad7d9064554eb296fb4e2971cf3b7d76a927cc", "price_changes": [{"asset_id": "68148598936481792878619902635048180980784414819164814468271718813144330892107", "price": "0.843", "size": "100", "side": "BUY", "hash": "4f3f7a76c68e1b66c139750cf4d030f9fdc06118", "best_bid": "0.878", "best_ask": "0.888"}, {"asset_id": "25975914361944378835569532810779694498194030305365204669451325469087977433544", "price": "0.157", "size": "100", "side": "SELL", "hash": "d3abafc9482f6b53c657b2b0564bd38dced78668", "best_bid": "0.112", "best_ask": "0.122"}], "timestamp": "1769384820727", "event_type": "price_change"}}
{"_local_timestamp": "2026-01-25T23:47:00.871645+00:00", "data": {"market": "0x607a934e2b8c4275c4cb5a74c2ad7d9064554eb296fb4e2971cf3b7d76a927cc", "price_changes": [{"asset_id": "68148598936481792878619902635048180980784414819164814468271718813144330892107", "price": "0.838", "size": "135.71", "side": "BUY", "hash": "edb726404935ab70fbc5a5f80189eaf41ff38bbd", "best_bid": "0.878", "best_ask": "0.888"}, {"asset_id": "25975914361944378835569532810779694498194030305365204669451325469087977433544", "price": "0.162", "size": "135.71", "side": "SELL", "hash": "c22645485e3a748a94c5e3ccdbfa3c3ce7216df7", "best_bid": "0.112", "best_ask": "0.122"}], "timestamp": "1769384820728", "event_type": "price_change"}}
{"_local_timestamp": "2026-01-25T23:47:01.421386+00:00", "data": {"market": "0x36352906a435bb57bbce5c12b8a016b42beee442645c27e025a6b605f167dbe1", "price_changes": [{"asset_id": "24865128979064458140408638815995003118177598043357620452530421257540758944225", "price": "0.931", "size": "112", "side": "BUY", "hash": "e08cfa871d2f4703a5c158d059e13baa747fe21b", "best_bid": "0.947", "best_ask": "0.957"}, {"asset_id": "31663847607839846905140169558614872784381523935014554710770021196634945212335", "price": "0.069", "size": "112", "side": "SELL", "hash": "cd8a6fb478273308c8d02df024341114d14afd57", "best_bid": "0.043", "best_ask": "0.053"}], "timestamp": "1769384821294", "event_type": "price_change"}}
{"_local_timestamp": "2026-01-25T23:47:01.523979+00:00", "data": {"market": "0x36352906a435bb57bbce5c12b8a016b42beee442645c27e025a6b605f167dbe1", "price_changes": [{"asset_id": "31663847607839846905140169558614872784381523935014554710770021196634945212335", "price": "0.008", "size": "1858.59", "side": "BUY", "hash": "e7c328b09a674cf7e4807527e29636a2d58015df", "best_bid": "0.043", "best_ask": "0.053"}, {"asset_id": "24865128979064458140408638815995003118177598043357620452530421257540758944225", "price": "0.992", "size": "1858.59", "side": "SELL", "hash": "69e88dc4efc703788372db0b019ab650ff7018fa", "best_bid": "0.947", "best_ask": "0.957"}], "timestamp": "1769384821380", "event_type": "price_change"}}
{"_local_timestamp": "2026-01-25T23:47:01.556340+00:00", "data": {"market": "0x36352906a435bb57bbce5c12b8a016b42beee442645c27e025a6b605f167dbe1", "price_changes": [{"asset_id": "31663847607839846905140169558614872784381523935014554710770021196634945212335", "price": "0.043", "size": "20", "side": "BUY", "hash": "b62aea444b2324ccf16cab87d4e73ee19dc8bcc4", "best_bid": "0.043", "best_ask": "0.053"}, {"asset_id": "24865128979064458140408638815995003118177598043357620452530421257540758944225", "price": "0.957", "size": "20", "side": "SELL", "hash": "a6ecf29558d78091e777c7e2478046f63e443164", "best_bid": "0.947", "best_ask": "0.957"}], "timestamp": "1769384821410", "event_type": "price_change"}}
{"_local_timestamp": "2026-01-25T23:47:01.575450+00:00", "data": {"market": "0x36352906a435bb57bbce5c12b8a016b42beee442645c27e025a6b605f167dbe1", "price_changes": [{"asset_id": "31663847607839846905140169558614872784381523935014554710770021196634945212335", "price": "0.043", "size": "195", "side": "BUY", "hash": "d04e6341ea389091970acb723ec6025e18897922", "best_bid": "0.043", "best_ask": "0.053"}, {"asset_id": "24865128979064458140408638815995003118177598043357620452530421257540758944225", "price": "0.957", "size": "195", "side": "SELL", "hash": "8661fad31b96084ee98fdf25c0b70747fc97889b", "best_bid": "0.947", "best_ask": "0.957"}], "timestamp": "1769384821435", "event_type": "price_change"}}
{"_local_timestamp": "2026-01-25T23:47:04.612257+00:00", "data": {"market": "0x607a934e2b8c4275c4cb5a74c2ad7d9064554eb296fb4e2971cf3b7d76a927cc", "price_changes": [{"asset_id": "68148598936481792878619902635048180980784414819164814468271718813144330892107", "price": "0.595", "size": "0", "side": "BUY", "hash": "f84f0514368fac53da6b5fed4cc7d70f95bed6a6", "best_bid": "0.878", "best_ask": "0.888"}, {"asset_id": "25975914361944378835569532810779694498194030305365204669451325469087977433544", "price": "0.405", "size": "0", "side": "SELL", "hash": "2913dc6071f239892029b10d05d1f0b474e759c7", "best_bid": "0.112", "best_ask": "0.122"}], "timestamp": "1769384824469", "event_type": "price_change"}}
{"_local_timestamp": "2026-01-25T23:47:04.615228+00:00", "data": {"market": "0x607a934e2b8c4275c4cb5a74c2ad7d9064554eb296fb4e2971cf3b7d76a927cc", "price_changes": [{"asset_id": "68148598936481792878619902635048180980784414819164814468271718813144330892107", "price": "0.312", "size": "0", "side": "BUY", "hash": "f84f0514368fac53da6b5fed4cc7d70f95bed6a6", "best_bid": "0.878", "best_ask": "0.888"}, {"asset_id": "25975914361944378835569532810779694498194030305365204669451325469087977433544", "price": "0.688", "size": "0", "side": "SELL", "hash": "2913dc6071f239892029b10d05d1f0b474e759c7", "best_bid": "0.112", "best_ask": "0.122"}], "timestamp": "1769384824469", "event_type": "price_change"}}
{"_local_timestamp": "2026-01-25T23:47:05.010165+00:00", "data": {"market": "0x36352906a435bb57bbce5c12b8a016b42beee442645c27e025a6b605f167dbe1", "price_changes": [{"asset_id": "31663847607839846905140169558614872784381523935014554710770021196634945212335", "price": "0.042", "size": "300", "side": "BUY", "hash": "d5e2e7fbc2df8e5a330aa228ae709681c312a736", "best_bid": "0.043", "best_ask": "0.053"}, {"asset_id": "24865128979064458140408638815995003118177598043357620452530421257540758944225", "price": "0.958", "size": "300", "side": "SELL", "hash": "e3da7731902b3ca3e0c31577554f73b6093c3e52", "best_bid": "0.947", "best_ask": "0.957"}], "timestamp": "1769384824863", "event_type": "price_change"}}
{"_local_timestamp": "2026-01-25T23:47:05.092774+00:00", "data": {"market": "0x607a934e2b8c4275c4cb5a74c2ad7d9064554eb296fb4e2971cf3b7d76a927cc", "price_changes": [{"asset_id": "68148598936481792878619902635048180980784414819164814468271718813144330892107", "price": "0.361", "size": "100", "side": "BUY", "hash": "89a60ee8e446ef7b8e10e573d295e7e3d5a16c4d", "best_bid": "0.878", "best_ask": "0.888"}, {"asset_id": "25975914361944378835569532810779694498194030305365204669451325469087977433544", "price": "0.639", "size": "100", "side": "SELL", "hash": "652e47295fcebb16c9349729e9c48804813cc648", "best_bid": "0.112", "best_ask": "0.122"}], "timestamp": "1769384824948", "event_type": "price_change"}}
{"_local_timestamp": "2026-01-25T23:47:05.094320+00:00", "data": {"market": "0x607a934e2b8c4275c4cb5a74c2ad7d9064554eb296fb4e2971cf3b7d76a927cc", "price_changes": [{"asset_id": "68148598936481792878619902635048180980784414819164814468271718813144330892107", "price": "0.62", "size": "100", "side": "BUY", "hash": "c9f428a06dc4171e0318fdb5725abca29970f6ef", "best_bid": "0.878", "best_ask": "0.888"}, {"asset_id": "25975914361944378835569532810779694498194030305365204669451325469087977433544", "price": "0.38", "size": "100", "side": "SELL", "hash": "036f129cdf187a6bbe6747a5f5c1971f9cc0bea0", "best_bid": "0.112", "best_ask": "0.122"}], "timestamp": "1769384824953", "event_type": "price_change"}}
{"_local_timestamp": "2026-01-25T23:47:05.210250+00:00", "data": {"market": "0x36352906a435bb57bbce5c12b8a016b42beee442645c27e025a6b605f167dbe1", "price_changes": [{"asset_id": "31663847607839846905140169558614872784381523935014554710770021196634945212335", "price": "0.042", "size": "404", "side": "BUY", "hash": "c0f6cbe6ab01cb93e879c86f1432c2dfeeba4d38", "best_bid": "0.043", "best_ask": "0.053"}, {"asset_id": "24865128979064458140408638815995003118177598043357620452530421257540758944225", "price": "0.958", "size": "404", "side": "SELL", "hash": "a753b253eda9a06da0d9a2d027890b6748621cf6", "best_bid": "0.947", "best_ask": "0.957"}], "timestamp": "1769384825078", "event_type": "price_change"}}
{"_local_timestamp": "2026-01-25T23:47:05.419722+00:00", "data": {"market": "0x607a934e2b8c4275c4cb5a74c2ad7d9064554eb296fb4e2971cf3b7d76a927cc", "price_changes": [{"asset_id": "68148598936481792878619902635048180980784414819164814468271718813144330892107", "price": "0.227", "size": "1850", "side": "BUY", "hash": "f7143e2c2ee06d92e6c5ba236318bee38e1b7fb9", "best_bid": "0.878", "best_ask": "0.888"}, {"asset_id": "25975914361944378835569532810779694498194030305365204669451325469087977433544", "price": "0.773", "size": "1850", "side": "SELL", "hash": "8363f55f04d58f7a34f35ed259df421f7b157ce6", "best_bid": "0.112", "best_ask": "0.122"}], "timestamp": "1769384825279", "event_type": "price_change"}}
{"_local_timestamp": "2026-01-25T23:47:05.439447+00:00", "data": {"market": "0x36352906a435bb57bbce5c12b8a016b42beee442645c27e025a6b605f167dbe1", "price_changes": [{"asset_id": "24865128979064458140408638815995003118177598043357620452530421257540758944225", "price": "0.946", "size": "0", "side": "BUY", "hash": "73bea6df4c94888d7218a87381f145f122a102a6", "best_bid": "0.947", "best_ask": "0.957"}, {"asset_id": "31663847607839846905140169558614872784381523935014554710770021196634945212335", "price": "0.054", "size": "0", "side": "SELL", "hash": "afee3da685ddc08e0997ea8b35cc4e719162da72", "best_bid": "0.043", "best_ask": "0.053"}], "timestamp": "1769384825296", "event_type": "price_change"}}
{"_local_timestamp": "2026-01-25T23:47:05.723968+00:00", "data": {"market": "0x36352906a435bb57bbce5c12b8a016b42beee442645c27e025a6b605f167dbe1", "price_changes": [{"asset_id": "24865128979064458140408638815995003118177598043357620452530421257540758944225", "price": "0.946", "size": "104", "side": "BUY", "hash": "7343b99b7e70932b36a4ee691cdaad970d261a61", "best_bid": "0.947", "best_ask": "0.957"}, {"asset_id": "31663847607839846905140169558614872784381523935014554710770021196634945212335", "price": "0.054", "size": "104", "side": "SELL", "hash": "bd288f3e41b9555df91aaa3ee139bfb22ef1ee2c", "best_bid": "0.043", "best_ask": "0.053"}], "timestamp": "1769384825590", "event_type": "price_change"}}
{"_local_timestamp": "2026-01-25T23:47:07.111833+00:00", "data": {"market": "0x607a934e2b8c4275c4cb5a74c2ad7d9064554eb296fb4e2971cf3b7d76a927cc", "price_changes": [{"asset_id": "25975914361944378835569532810779694498194030305365204669451325469087977433544", "price": "0.11", "size": "0", "side": "BUY", "hash": "350fc5b6930f104ca8726c182270130a911b6db9", "best_bid": "0.112", "best_ask": "0.122"}, {"asset_id": "68148598936481792878619902635048180980784414819164814468271718813144330892107", "price": "0.89", "size": "0", "side": "SELL", "hash": "8a169dbdbd76e9b98aefd57dbc44f688bfb8771e", "best_bid": "0.878", "best_ask": "0.888"}], "timestamp": "1769384827007", "event_type": "price_change"}}
{"_local_timestamp": "2026-01-25T23:47:07.113080+00:00", "data": {"market": "0x607a934e2b8c4275c4cb5a74c2ad7d9064554eb296fb4e2971cf3b7d76a927cc", "price_changes": [{"asset_id": "68148598936481792878619902635048180980784414819164814468271718813144330892107", "price": "0.843", "size": "67", "side": "BUY", "hash": "5130a8cac31e2462b60ed4ccba23c28df7f9bd96", "best_bid": "0.878", "best_ask": "0.888"}, {"asset_id": "25975914361944378835569532810779694498194030305365204669451325469087977433544", "price": "0.157", "size": "67", "side": "SELL", "hash": "899acaea3af430d07c10b7f15775b70fbfec32aa", "best_bid": "0.112", "best_ask": "0.122"}], "timestamp": "1769384827008", "event_type": "price_change"}}
{"_local_timestamp": "2026-01-25T23:47:10.985401+00:00", "data": {"market": "0x6bbe585f51aedf96a92a4395f195633858a50a7ee9d5961a183b2fd858e2217c", "price_changes": [{"asset_id": "75977696589176706909494914683666626840477786548124398411155958119219599758391", "price": "0.2", "size": "158.87", "side": "SELL", "hash": "982e6471a47142539998a3af8e6acfa8ca34d3c1", "best_bid": "0.17", "best_ask": "0.2"}, {"asset_id": "56479600937284047243744777367008101014255165543721437768956239217955454610653", "price": "0.8", "size": "158.87", "side": "BUY", "hash": "575e61197864671dc86a775cb4816023bddd4347", "best_bid": "0.8", "best_ask": "0.83"}], "timestamp": "1769384830827", "event_type": "price_change"}}
{"_local_timestamp": "2026-01-25T23:47:11.742882+00:00", "data": {"market": "0xf65b917d7c4c2d6e01266807b8b7fa49eb9fd00bad3b7413529c264261470a44", "price_changes": [{"asset_id": "21935961644840571543456790578994599010779256576943062204718832399472703918846", "price": "0.26", "size": "788", "side": "SELL", "hash": "02491934606c860f40e71e41d7007f3d799c2cf6", "best_bid": "0.22", "best_ask": "0.26"}, {"asset_id": "114083583916459364671762732480092206829910491378286392673263703828161447677389", "price": "0.74", "size": "788", "side": "BUY", "hash": "83974a1e6299f2027627b011670de11be77b9c61", "best_bid": "0.74", "best_ask": "0.78"}], "timestamp": "1769384831631", "event_type": "price_change"}}
{"_local_timestamp": "2026-01-25T23:47:15.896220+00:00", "data": {"market": "0x36352906a435bb57bbce5c12b8a016b42beee442645c27e025a6b605f167dbe1", "price_changes": [{"asset_id": "24865128979064458140408638815995003118177598043357620452530421257540758944225", "price": "0.926", "size": "0", "side": "BUY", "hash": "aace80e393925f92b918de1a306fed48285c31e6", "best_bid": "0.947", "best_ask": "0.957"}, {"asset_id": "31663847607839846905140169558614872784381523935014554710770021196634945212335", "price": "0.074", "size": "0", "side": "SELL", "hash": "1065358004570cd832b424e036d1aca6caaa6760", "best_bid": "0.043", "best_ask": "0.053"}], "timestamp": "1769384835728", "event_type": "price_change"}}
{"_local_timestamp": "2026-01-25T23:47:15.946261+00:00", "data": {"market": "0x36352906a435bb57bbce5c12b8a016b42beee442645c27e025a6b605f167dbe1", "price_changes": [{"asset_id": "24865128979064458140408638815995003118177598043357620452530421257540758944225", "price": "0.931", "size": "132", "side": "BUY", "hash": "57a0b7b72759845b5aa430d0c2dda16a67e015e6", "best_bid": "0.947", "best_ask": "0.957"}, {"asset_id": "31663847607839846905140169558614872784381523935014554710770021196634945212335", "price": "0.069", "size": "132", "side": "SELL", "hash": "c3b661c057dbb842c63f0a148dec16f425459839", "best_bid": "0.043", "best_ask": "0.053"}], "timestamp": "1769384835779", "event_type": "price_change"}}
{"_local_timestamp": "2026-01-25T23:47:23.587277+00:00", "data": {"market": "0x36352906a435bb57bbce5c12b8a016b42beee442645c27e025a6b605f167dbe1", "price_changes": [{"asset_id": "24865128979064458140408638815995003118177598043357620452530421257540758944225", "price": "0.245", "size": "150", "side": "BUY", "hash": "798d6a94d39c743cda432d10ce0d10658ceca26d", "best_bid": "0.947", "best_ask": "0.957"}, {"asset_id": "31663847607839846905140169558614872784381523935014554710770021196634945212335", "price": "0.755", "size": "150", "side": "SELL", "hash": "969355137b71fb843d778c5f041bbdf1bbe23f5f", "best_bid": "0.043", "best_ask": "0.053"}], "timestamp": "1769384843382", "event_type": "price_change"}}
{"_local_timestamp": "2026-01-25T23:47:23.592703+00:00", "data": {"market": "0x7587cc4497fc03e6bc20a2b9579d1a5cafd7778fcbd077f91f2c50fe5924259f", "price_changes": [{"asset_id": "28134581219669032059806644497841080110865577915276558812300476779313627788834", "price": "0.2", "size": "250", "side": "BUY", "hash": "a6d509dfdfa937e4847769ff6f3ad0e4194b0280", "best_bid": "0.85", "best_ask": "0.87"}, {"asset_id": "113316597975241725413150018775135425644758743759237570300130816995662490799104", "price": "0.8", "size": "250", "side": "SELL", "hash": "a0b8b7015430c8f91b9f5f455b7eaaa2549f2aa2", "best_bid": "0.13", "best_ask": "0.15"}], "timestamp": "1769384843382", "event_type": "price_change"}}
{"_local_timestamp": "2026-01-25T23:47:23.598875+00:00", "data": {"market": "0x607a934e2b8c4275c4cb5a74c2ad7d9064554eb296fb4e2971cf3b7d76a927cc", "price_changes": [{"asset_id": "68148598936481792878619902635048180980784414819164814468271718813144330892107", "price": "0.36", "size": "55.55", "side": "BUY", "hash": "fd220908119484a4c778da9cb0839705d7f54187", "best_bid": "0.878", "best_ask": "0.888"}, {"asset_id": "25975914361944378835569532810779694498194030305365204669451325469087977433544", "price": "0.64", "size": "55.55", "side": "SELL", "hash": "dc32bd7eb82406096cd2c20d9b00824e97289028", "best_bid": "0.112", "best_ask": "0.122"}], "timestamp": "1769384843382", "event_type": "price_change"}}
{"_local_timestamp": "2026-01-25T23:47:23.741065+00:00", "data": {"market": "0x607a934e2b8c4275c4cb5a74c2ad7d9064554eb296fb4e2971cf3b7d76a927cc", "price_changes": [{"asset_id": "68148598936481792878619902635048180980784414819164814468271718813144330892107", "price": "0.226", "size": "150", "side": "BUY", "hash": "286816fd234df644088f1b7532849347cc810f8e", "best_bid": "0.878", "best_ask": "0.888"}, {"asset_id": "25975914361944378835569532810779694498194030305365204669451325469087977433544", "price": "0.774", "size": "150", "side": "SELL", "hash": "d40c22e6b7d6d41b8be1e0f684c05f3f72e0aefa", "best_bid": "0.112", "best_ask": "0.122"}], "timestamp": "1769384843410", "event_type": "price_change"}}
{"_local_timestamp": "2026-01-25T23:47:24.077911+00:00", "data": {"market": "0x607a934e2b8c4275c4cb5a74c2ad7d9064554eb296fb4e2971cf3b7d76a927cc", "price_changes": [{"asset_id": "68148598936481792878619902635048180980784414819164814468271718813144330892107", "price": "0.34", "size": "50", "side": "BUY", "hash": "9e55b9cfe7e913a5265ca1da410989dd0ae4c3f0", "best_bid": "0.878", "best_ask": "0.888"}, {"asset_id": "25975914361944378835569532810779694498194030305365204669451325469087977433544", "price": "0.66", "size": "50", "side": "SELL", "hash": "85ac8481cdc8cbcddeb9815fabc9509af09b7a14", "best_bid": "0.112", "best_ask": "0.122"}], "timestamp": "1769384843824", "event_type": "price_change"}}
{"_local_timestamp": "2026-01-25T23:47:24.088881+00:00", "data": {"market": "0x7587cc4497fc03e6bc20a2b9579d1a5cafd7778fcbd077f91f2c50fe5924259f", "price_changes": [{"asset_id": "28134581219669032059806644497841080110865577915276558812300476779313627788834", "price": "0.23", "size": "50", "side": "BUY", "hash": "e61391ecb64d03807597b49767b128d3b6e327ec", "best_bid": "0.85", "best_ask": "0.87"}, {"asset_id": "113316597975241725413150018775135425644758743759237570300130816995662490799104", "price": "0.77", "size": "50", "side": "SELL", "hash": "db5454464e413960cd88aae3e056193a1390c72f", "best_bid": "0.13", "best_ask": "0.15"}], "timestamp": "1769384843837", "event_type": "price_change"}}
{"_local_timestamp": "2026-01-25T23:47:24.102402+00:00", "data": {"market": "0x36352906a435bb57bbce5c12b8a016b42beee442645c27e025a6b605f167dbe1", "price_changes": [{"asset_id": "24865128979064458140408638815995003118177598043357620452530421257540758944225", "price": "0.241", "size": "50", "side": "BUY", "hash": "176f893e898d5ec7d06346a6d63db11b75034c2c", "best_bid": "0.947", "best_ask": "0.957"}, {"asset_id": "31663847607839846905140169558614872784381523935014554710770021196634945212335", "price": "0.759", "size": "50", "side": "SELL", "hash": "5a9c5eeab097f9d0db1ef756a2f0bfe43c141a57", "best_bid": "0.043", "best_ask": "0.053"}], "timestamp": "1769384843837", "event_type": "price_change"}}
{"_local_timestamp": "2026-01-25T23:47:24.114025+00:00", "data": {"market": "0x607a934e2b8c4275c4cb5a74c2ad7d9064554eb296fb4e2971cf3b7d76a927cc", "price_changes": [{"asset_id": "68148598936481792878619902635048180980784414819164814468271718813144330892107", "price": "0.221", "size": "50", "side": "BUY", "hash": "47f74d39bdd2976da8878aca0c3499916acdfb28", "best_bid": "0.878", "best_ask": "0.888"}, {"asset_id": "25975914361944378835569532810779694498194030305365204669451325469087977433544", "price": "0.779", "size": "50", "side": "SELL", "hash": "f935e328e01facb560e6348b94f337f88d486026", "best_bid": "0.112", "best_ask": "0.122"}], "timestamp": "1769384843850", "event_type": "price_change"}}
{"_local_timestamp": "2026-01-25T23:47:28.221797+00:00", "data": {"market": "0x7587cc4497fc03e6bc20a2b9579d1a5cafd7778fcbd077f91f2c50fe5924259f", "price_changes": [{"asset_id": "113316597975241725413150018775135425644758743759237570300130816995662490799104", "price": "0.06", "size": "0", "side": "BUY", "hash": "06fa7c69e56e6e053622d2395d0e4494229f0c4c", "best_bid": "0.13", "best_ask": "0.15"}, {"asset_id": "28134581219669032059806644497841080110865577915276558812300476779313627788834", "price": "0.94", "size": "0", "side": "SELL", "hash": "9cb81b67ef288400031c1ec5dac190f9f5679449", "best_bid": "0.85", "best_ask": "0.87"}], "timestamp": "1769384847963", "event_type": "price_change"}}
{"_local_timestamp": "2026-01-25T23:47:29.182736+00:00", "data": {"market": "0x607a934e2b8c4275c4cb5a74c2ad7d9064554eb296fb4e2971cf3b7d76a927cc", "price_changes": [{"asset_id": "68148598936481792878619902635048180980784414819164814468271718813144330892107", "price": "0.838", "size": "0", "side": "BUY", "hash": "f3fd1f6789cbebc9e1020f40e9df5ca844d6f059", "best_bid": "0.878", "best_ask": "0.888"}, {"asset_id": "25975914361944378835569532810779694498194030305365204669451325469087977433544", "price": "0.162", "size": "0", "side": "SELL", "hash": "911c19cf4a201d07a262784ddb67085ce63e1fa2", "best_bid": "0.112", "best_ask": "0.122"}], "timestamp": "1769384848940", "event_type": "price_change"}}
{"_local_timestamp": "2026-01-25T23:47:37.872474+00:00", "data": {"market": "0x7587cc4497fc03e6bc20a2b9579d1a5cafd7778fcbd077f91f2c50fe5924259f", "price_changes": [{"asset_id": "28134581219669032059806644497841080110865577915276558812300476779313627788834", "price": "0.2", "size": "150", "side": "BUY", "hash": "a62531f3b44c8167e9f9e4d80b7e54128dc71f6d", "best_bid": "0.85", "best_ask": "0.87"}, {"asset_id": "113316597975241725413150018775135425644758743759237570300130816995662490799104", "price": "0.8", "size": "150", "side": "SELL", "hash": "e2390cc3e2827af15710ebeebdb8c4e38154fe95", "best_bid": "0.13", "best_ask": "0.15"}], "timestamp": "1769384857532", "event_type": "price_change"}}
{"_local_timestamp": "2026-01-25T23:47:37.873814+00:00", "data": {"market": "0x7587cc4497fc03e6bc20a2b9579d1a5cafd7778fcbd077f91f2c50fe5924259f", "price_changes": [{"asset_id": "28134581219669032059806644497841080110865577915276558812300476779313627788834", "price": "0.28", "size": "400", "side": "BUY", "hash": "a62531f3b44c8167e9f9e4d80b7e54128dc71f6d", "best_bid": "0.85", "best_ask": "0.87"}, {"asset_id": "113316597975241725413150018775135425644758743759237570300130816995662490799104", "price": "0.72", "size": "400", "side": "SELL", "hash": "e2390cc3e2827af15710ebeebdb8c4e38154fe95", "best_bid": "0.13", "best_ask": "0.15"}], "timestamp": "1769384857532", "event_type": "price_change"}}
{"_local_timestamp": "2026-01-25T23:47:37.923494+00:00", "data": {"market": "0x607a934e2b8c4275c4cb5a74c2ad7d9064554eb296fb4e2971cf3b7d76a927cc", "price_changes": [{"asset_id": "68148598936481792878619902635048180980784414819164814468271718813144330892107", "price": "0.226", "size": "100", "side": "BUY", "hash": "198a4ac78e09fb504ba5fd2f7a9de03ebf50638b", "best_bid": "0.878", "best_ask": "0.888"}, {"asset_id": "25975914361944378835569532810779694498194030305365204669451325469087977433544", "price": "0.774", "size": "100", "side": "SELL", "hash": "ec972826c23e628e756fd3fb77325e08dbd20bf7", "best_bid": "0.112", "best_ask": "0.122"}], "timestamp": "1769384857542", "event_type": "price_change"}}
{"_local_timestamp": "2026-01-25T23:47:37.931803+00:00", "data": {"market": "0x6bbe585f51aedf96a92a4395f195633858a50a7ee9d5961a183b2fd858e2217c", "price_changes": [{"asset_id": "56479600937284047243744777367008101014255165543721437768956239217955454610653", "price": "0.27", "size": "150", "side": "BUY", "hash": "cec65eed21c5d0a5d06188859d2d075a3cdb5e35", "best_bid": "0.8", "best_ask": "0.83"}, {"asset_id": "75977696589176706909494914683666626840477786548124398411155958119219599758391", "price": "0.73", "size": "150", "side": "SELL", "hash": "c820404e2524a4f6101ddd30e2ee08fcc76556b3", "best_bid": "0.17", "best_ask": "0.2"}], "timestamp": "1769384857543", "event_type": "price_change"}}
{"_local_timestamp": "2026-01-25T23:47:37.933048+00:00", "data": {"market": "0x6bbe585f51aedf96a92a4395f195633858a50a7ee9d5961a183b2fd858e2217c", "price_changes": [{"asset_id": "56479600937284047243744777367008101014255165543721437768956239217955454610653", "price": "0.19", "size": "2660", "side": "BUY", "hash": "cec65eed21c5d0a5d06188859d2d075a3cdb5e35", "best_bid": "0.8", "best_ask": "0.83"}, {"asset_id": "75977696589176706909494914683666626840477786548124398411155958119219599758391", "price": "0.81", "size": "2660", "side": "SELL", "hash": "c820404e2524a4f6101ddd30e2ee08fcc76556b3", "best_bid": "0.17", "best_ask": "0.2"}], "timestamp": "1769384857543", "event_type": "price_change"}}
{"_local_timestamp": "2026-01-25T23:47:37.948735+00:00", "data": {"market": "0x36352906a435bb57bbce5c12b8a016b42beee442645c27e025a6b605f167dbe1", "price_changes": [{"asset_id": "24865128979064458140408638815995003118177598043357620452530421257540758944225", "price": "0.245", "size": "100", "side": "BUY", "hash": "6a80a2db7e1df07bd40cd0868fddbf58d234c751", "best_bid": "0.947", "best_ask": "0.957"}, {"asset_id": "31663847607839846905140169558614872784381523935014554710770021196634945212335", "price": "0.755", "size": "100", "side": "SELL", "hash": "dbb2b75d37345747ffdc43e3f9e3b8fc01919edc", "best_bid": "0.043", "best_ask": "0.053"}], "timestamp": "1769384857542", "event_type": "price_change"}}
{"_local_timestamp": "2026-01-25T23:47:38.436517+00:00", "data": {"market": "0x7587cc4497fc03e6bc20a2b9579d1a5cafd7778fcbd077f91f2c50fe5924259f", "price_changes": [{"asset_id": "28134581219669032059806644497841080110865577915276558812300476779313627788834", "price": "0.18", "size": "988", "side": "BUY", "hash": "dd559b9e85f2e20ca05a2c7a0a78d150c2bd9b4e", "best_bid": "0.85", "best_ask": "0.87"}, {"asset_id": "113316597975241725413150018775135425644758743759237570300130816995662490799104", "price": "0.82", "size": "988", "side": "SELL", "hash": "4da9a8c1b1d581135c6c2d331b1c86161e80f361", "best_bid": "0.13", "best_ask": "0.15"}], "timestamp": "1769384858053", "event_type": "price_change"}}
{"_local_timestamp": "2026-01-25T23:47:38.438012+00:00", "data": {"market": "0x607a934e2b8c4275c4cb5a74c2ad7d9064554eb296fb4e2971cf3b7d76a927cc", "price_changes": [{"asset_id": "68148598936481792878619902635048180980784414819164814468271718813144330892107", "price": "0.221", "size": "100", "side": "BUY", "hash": "c039a7d68199102141bc42d4e0a719ccec993521", "best_bid": "0.878", "best_ask": "0.888"}, {"asset_id": "25975914361944378835569532810779694498194030305365204669451325469087977433544", "price": "0.779", "size": "100", "side": "SELL", "hash": "0368d5e6fbe2778cdb7a0c665eb219ec7f782938", "best_bid": "0.112", "best_ask": "0.122"}], "timestamp": "1769384858058", "event_type": "price_change"}}
