{"_local_timestamp": "2026-01-25T23:33:33.826016+00:00", "data": [{"market": "0xff8bf331f7ddbdd2e92e27dcd273612ec45fefde3cf70039c4f043eaec0000c6", "asset_id": "60105600458079862676305161094044862147301593956294543970688990037138503709415", "timestamp": "1769384013522", "hash": "826f98aedd3161d8ca9d137de7c7afa8c4549003", "bids": [{"price": "0.01", "size": "10305.44"}, {"price": "0.02", "size": "1000"}, {"price": "0.03", "size": "16"}, {"price": "0.04", "size": "2100"}, {"price": "0.05", "size": "6.91"}, {"price": "0.06", "size": "816.66"}, {"price": "0.08", "size": "400"}, {"price": "0.1", "size": "280"}, {"price": "0.11", "size": "236.36"}, {"price": "0.13", "size": "184.61"}, {"price": "0.15", "size": "133.33"}, {"price": "0.21", "size": "500"}, {"price": "0.24", "size": "54.16"}, {"price": "0.25", "size": "544"}, {"price": "0.27", "size": "6"}, {"price": "0.28", "size": "500"}, {"price": "0.29", "size": "326.57"}, {"price": "0.3", "size": "316"}, {"price": "0.31", "size": "221.72"}, {"price": "0.32", "size": "36"}, {"price": "0.33", "size": "60"}, {"price": "0.34", "size": "1032.42"}, {"price": "0.36", "size": "50.97"}], "asks": [{"price": "0.99", "size": "16313.59"}, {"price": "0.98", "size": "2200"}, {"price": "0.97", "size": "8.37"}, {"price": "0.95", "size": "10"}, {"price": "0.94", "size": "1200"}, {"price": "0.93", "size": "7.91"}, {"price": "0.9", "size": "340"}, {"price": "0.87", "size": "571.15"}, {"price": "0.85", "size": "266"}, {"price": "0.84", "size": "175"}, {"price": "0.83", "size": "2770"}, {"price": "0.82", "size": "5.88"}, {"price": "0.8", "size": "180"}, {"price": "0.77", "size": "104.34"}, {"price": "0.74", "size": "76.92"}, {"price": "0.72", "size": "1300"}, {"price": "0.71", "size": "756"}, {"price": "0.67", "size": "6"}, {"price": "0.62", "size": "34.21"}, {"price": "0.6", "size": "27.5"}, {"price": "0.59", "size": "20"}, {"price": "0.56", "size": "6"}, {"price": "0.47", "size": "6"}, {"price": "0.41", "size": "6"}, {"price": "0.4", "size": "90"}, {"price": "0.39", "size": "56"}, {"price": "0.38", "size": "270"}, {"price": "0.37", "size": "219.93"}], "event_type": "book", "last_trade_price": "0.360"}, {"market": "0xb83cf6cdfe9973219d19fb70f863ec9b713a313609db51839eeb34f7acf275ad", "asset_id": "101837527728017183708561627155221790735931039980484062356872287158739556672077", "timestamp": "1769383869145", "hash": "76477baa9a4396901d5eda4bf7bd1a164792c339", "bids": [{"price": "0.001", "size": "14491.99"}, {"price": "0.002", "size": "313.3"}, {"price": "0.003", "size": "1014.2"}, {"price": "0.004", "size": "260.6"}, {"price": "0.005", "size": "508.44"}, {"price": "0.007", "size": "300"}, {"price": "0.01", "size": "1037.33"}], "asks": [{"price": "0.999", "size": "4997.23"}, {"price": "0.998", "size": "1256.56"}, {"price": "0.997", "size": "1000"}, {"price": "0.996", "size": "11.33"}, {"price": "0.99", "size": "16300"}, {"price": "0.989", "size": "5.74"}, {"price": "0.98", "size": "2200"}, {"price": "0.979", "size": "11.16"}, {"price": "0.95", "size": "30"}, {"price": "0.949", "size": "39"}, {"price": "0.94", "size": "400"}, {"price": "0.939", "size": "10.33"}, {"price": "0.9", "size": "560"}, {"price": "0.85", "size": "551.66"}, {"price": "0.8", "size": "510"}, {"price": "0.799", "size": "160"}, {"price": "0.75", "size": "262"}, {"price": "0.73", "size": "50"}, {"price": "0.7", "size": "86.66"}, {"price": "0.66", "size": "50"}, {"price": "0.65", "size": "68.57"}, {"price": "0.6", "size": "50"}, {"price": "0.561", "size": "1197"}, {"price": "0.559", "size": "5"}, {"price": "0.558", "size": "20"}, {"price": "0.557", "size": "25"}, {"price": "0.15", "size": "5"}, {"price": "0.147", "size": "25"}, {"price": "0.146", "size": "20"}, {"price": "0.028", "size": "451.27"}, {"price": "0.027", "size": "107.13"}, {"price": "0.025", "size": "10"}, {"price": "0.024", "size": "10"}, {"price": "0.023", "size": "10"}, {"price": "0.022", "size": "10"}, {"price": "0.021", "size": "372"}, {"price": "0.02", "size": "235.14"}, {"price": "0.015", "size": "25"}, {"price": "0.012", "size": "20"}], "event_type": "book", "last_trade_price": "0.010"}, {"market": "0xff8bf331f7ddbdd2e92e27dcd273612ec45fefde3cf70039c4f043eaec0000c6", "asset_id": "65943623919755331891504362129239742473111951663283351342808117545053994127220", "timestamp": "1769384013522", "hash": "57da0cc9ed445cada17e27ce0724f1acf94cc0c3", "bids": [{"price": "0.01", "size": "16313.59"}, {"price": "0.02", "size": "2200"}, {"price": "0.03", "size": "8.37"}, {"price": "0.05", "size": "10"}, {"price": "0.06", "size": "1200"}, {"price": "0.07", "size": "7.91"}, {"price": "0.1", "size": "340"}, {"price": "0.13", "size": "571.15"}, {"price": "0.15", "size": "266"}, {"price": "0.16", "size": "175"}, {"price": "0.17", "size": "2770"}, {"price": "0.18", "size": "5.88"}, {"price": "0.2", "size": "180"}, {"price": "0.23", "size": "104.34"}, {"price": "0.26", "size": "76.92"}, {"price": "0.28", "size": "1300"}, {"price": "0.29", "size": "756"}, {"price": "0.33", "size": "6"}, {"price": "0.38", "size": "34.21"}, {"price": "0.4", "size": "27.5"}, {"price": "0.41", "size": "20"}, {"price": "0.44", "size": "6"}, {"price": "0.53", "size": "6"}, {"price": "0.59", "size": "6"}, {"price": "0.6", "size": "90"}, {"price": "0.61", "size": "56"}, {"price": "0.62", "size": "270"}, {"price": "0.63", "size": "219.93"}], "asks": [{"price": "0.99", "size": "10305.44"}, {"price": "0.98", "size": "1000"}, {"price": "0.97", "size": "16"}, {"price": "0.96", "size": "2100"}, {"price": "0.95", "size": "6.91"}, {"price": "0.94", "size": "816.66"}, {"price": "0.92", "size": "400"}, {"price": "0.9", "size": "280"}, {"price": "0.89", "size": "236.36"}, {"price": "0.87", "size": "184.61"}, {"price": "0.85", "size": "133.33"}, {"price": "0.79", "size": "500"}, {"price": "0.76", "size": "54.16"}, {"price": "0.75", "size": "544"}, {"price": "0.73", "size": "6"}, {"price": "0.72", "size": "500"}, {"price": "0.71", "size": "326.57"}, {"price": "0.7", "size": "316"}, {"price": "0.69", "size": "221.72"}, {"price": "0.68", "size": "36"}, {"price": "0.67", "size": "60"}, {"price": "0.66", "size": "1032.42"}, {"price": "0.64", "size": "50.97"}], "event_type": "book", "last_trade_price": "0.360"}, {"market": "0xa7e1a7561e1866aa345c0be640df952e1d41decf0a5c4bb571f077142fed025d", "asset_id": "76541116657039469088410437026264202489719024425044998810802876826622732617598", "timestamp": "1769383922806", "hash": "ef30959751727c2835766b573c65b98489dd7801", "bids": [{"price": "0.01", "size": "16313.27"}, {"price": "0.02", "size": "2200"}, {"price": "0.03", "size": "11.78"}, {"price": "0.05", "size": "10"}, {"price": "0.07", "size": "1114.28"}, {"price": "0.08", "size": "400"}, {"price": "0.09", "size": "5.58"}, {"price": "0.11", "size": "634.09"}, {"price": "0.15", "size": "213.33"}, {"price": "0.16", "size": "250"}, {"price": "0.19", "size": "147.36"}, {"price": "0.2", "size": "2455.05"}, {"price": "0.23", "size": "113.04"}, {"price": "0.24", "size": "8"}, {"price": "0.26", "size": "92.3"}, {"price": "0.27", "size": "1792"}, {"price": "0.28", "size": "300"}, {"price": "0.3", "size": "66.66"}, {"price": "0.34", "size": "125"}, {"price": "0.35", "size": "20"}, {"price": "0.62", "size": "190.16"}, {"price": "0.63", "size": "20.63"}, {"price": "0.65", "size": "16.92"}, {"price": "0.7", "size": "1020"}, {"price": "0.71", "size": "80"}, {"price": "0.72", "size": "10"}, {"price": "0.73", "size": "50"}, {"price": "0.74", "size": "505.19"}, {"price": "0.75", "size": "70"}], "asks": [{"price": "0.99", "size": "7000"}, {"price": "0.98", "size": "1050"}, {"price": "0.97", "size": "13.33"}, {"price": "0.95", "size": "10"}, {"price": "0.84", "size": "5000"}, {"price": "0.83", "size": "96.47"}, {"price": "0.82", "size": "2500"}, {"price": "0.81", "size": "133.89"}, {"price": "0.79", "size": "5010"}, {"price": "0.78", "size": "1806.84"}, {"price": "0.77", "size": "298.88"}, {"price": "0.76", "size": "1578.22"}], "event_type": "book", "last_trade_price": "0.240"}, {"market": "0x892231e7fd3ac31a3b321002f909e011180b709af074808908d27a2a32a7b546", "asset_id": "89791260670398307279783201184852534466650260912467648915456704380491810882664", "timestamp": "1769384013523", "hash": "b67646883e5ba5c850e0bbfe7643b691523d1dc0", "bids": [{"price": "0.01", "size": "85"}, {"price": "0.03", "size": "400"}, {"price": "0.04", "size": "5210"}, {"price": "0.05", "size": "50"}, {"price": "0.06", "size": "450"}, {"price": "0.07", "size": "427.48"}], "asks": [{"price": "0.99", "size": "16412.87"}, {"price": "0.98", "size": "2200"}, {"price": "0.97", "size": "9.65"}, {"price": "0.95", "size": "30"}, {"price": "0.94", "size": "33"}, {"price": "0.93", "size": "7.74"}, {"price": "0.91", "size": "800"}, {"price": "0.86", "size": "567.85"}, {"price": "0.81", "size": "468.42"}, {"price": "0.8", "size": "255.2"}, {"price": "0.79", "size": "150"}, {"price": "0.77", "size": "121.73"}, {"price": "0.72", "size": "392.85"}, {"price": "0.71", "size": "1498"}, {"price": "0.67", "size": "72.72"}, {"price": "0.66", "size": "491"}, {"price": "0.62", "size": "127.63"}, {"price": "0.54", "size": "5"}, {"price": "0.52", "size": "800"}, {"price": "0.51", "size": "860"}, {"price": "0.5", "size": "348"}, {"price": "0.2", "size": "5"}, {"price": "0.19", "size": "65"}, {"price": "0.18", "size": "20"}, {"price": "0.12", "size": "89"}, {"price": "0.11", "size": "260"}, {"price": "0.1", "size": "502"}, {"price": "0.09", "size": "81.19"}, {"price": "0.08", "size": "33"}], "event_type": "book", "last_trade_price": "0.070"}, {"market": "0x8253528e603b5cabb8ab45d1e1209bda57aa2a9f6f0d61aba7ad0a38147a86ee", "asset_id": "17667700649974143765639286018245659141526847671421069760676398956961689778433", "timestamp": "1769383979491", "hash": "9af26b9a91c901aafc8f616500d824e8f461516d", "bids": [{"price": "0.01", "size": "16313.64"}, {"price": "0.02", "size": "2200"}, {"price": "0.03", "size": "9.92"}, {"price": "0.05", "size": "10"}, {"price": "0.07", "size": "1114.28"}, {"price": "0.08", "size": "6.18"}, {"price": "0.1", "size": "340"}, {"price": "0.14", "size": "553.57"}, {"price": "0.15", "size": "266"}, {"price": "0.17", "size": "164.7"}, {"price": "0.19", "size": "2265.64"}, {"price": "0.2", "size": "250"}, {"price": "0.21", "size": "123.8"}, {"price": "0.22", "size": "400"}, {"price": "0.24", "size": "100"}, {"price": "0.27", "size": "50"}, {"price": "0.28", "size": "71.42"}, {"price": "0.34", "size": "975"}, {"price": "0.35", "size": "5"}, {"price": "0.51", "size": "322"}, {"price": "0.53", "size": "48"}, {"price": "0.6", "size": "21.66"}, {"price": "0.61", "size": "18.03"}, {"price": "0.62", "size": "20"}, {"price": "0.63", "size": "300"}, {"price": "0.64", "size": "410.99"}, {"price": "0.65", "size": "126"}, {"price": "0.66", "size": "458.6"}, {"price": "0.67", "size": "30"}], "asks": [{"price": "0.99", "size": "10305.39"}, {"price": "0.98", "size": "2200"}, {"price": "0.97", "size": "266"}, {"price": "0.96", "size": "8.65"}, {"price": "0.89", "size": "168.18"}, {"price": "0.88", "size": "91.66"}, {"price": "0.75", "size": "20"}, {"price": "0.71", "size": "87"}, {"price": "0.7", "size": "600"}, {"price": "0.69", "size": "39.45"}, {"price": "0.68", "size": "248.36"}], "event_type": "book", "last_trade_price": "0.320"}, {"market": "0x892231e7fd3ac31a3b321002f909e011180b709af074808908d27a2a32a7b546", "asset_id": "64317448978406417981854076458164286249844965670717306181829295801409919530695", "timestamp": "1769384013523", "hash": "398d3c5840da6f5881facaef15b6f8a44f9bb137", "bids": [{"price": "0.01", "size": "16412.87"}, {"price": "0.02", "size": "2200"}, {"price": "0.03", "size": "9.65"}, {"price": "0.05", "size": "30"}, {"price": "0.06", "size": "33"}, {"price": "0.07", "size": "7.74"}, {"price": "0.09", "size": "800"}, {"price": "0.14", "size": "567.85"}, {"price": "0.19", "size": "468.42"}, {"price": "0.2", "size": "255.2"}, {"price": "0.21", "size": "150"}, {"price": "0.23", "size": "121.73"}, {"price": "0.28", "size": "392.85"}, {"price": "0.29", "size": "1498"}, {"price": "0.33", "size": "72.72"}, {"price": "0.34", "size": "491"}, {"price": "0.38", "size": "127.63"}, {"price": "0.46", "size": "5"}, {"price": "0.48", "size": "800"}, {"price": "0.49", "size": "860"}, {"price": "0.5", "size": "348"}, {"price": "0.8", "size": "5"}, {"price": "0.81", "size": "65"}, {"price": "0.82", "size": "20"}, {"price": "0.88", "size": "89"}, {"price": "0.89", "size": "260"}, {"price": "0.9", "size": "502"}, {"price": "0.91", "size": "81.19"}, {"price": "0.92", "size": "33"}], "asks": [{"price": "0.99", "size": "85"}, {"price": "0.97", "size": "400"}, {"price": "0.96", "size": "5210"}, {"price": "0.95", "size": "50"}, {"price": "0.94", "size": "450"}, {"price": "0.93", "size": "427.48"}], "event_type": "book", "last_trade_price": "0.070"}, {"market": "0xb83cf6cdfe9973219d19fb70f863ec9b713a313609db51839eeb34f7acf275ad", "asset_id": "31464892460544164986335006004080412271316454788455556340430054002451576894443", "timestamp": "1769383869145", "hash": "7ca367b0caa0cdab988dc42aea3df83fe0f4d74d", "bids": [{"price": "0.001", "size": "4997.23"}, {"price": "0.002", "size": "1256.56"}, {"price": "0.003", "size": "1000"}, {"price": "0.004", "size": "11.33"}, {"price": "0.01", "size": "16300"}, {"price": "0.011", "size": "5.74"}, {"price": "0.02", "size": "2200"}, {"price": "0.021", "size": "11.16"}, {"price": "0.05", "size": "30"}, {"price": "0.051", "size": "39"}, {"price": "0.06", "size": "400"}, {"price": "0.061", "size": "10.33"}, {"price": "0.1", "size": "560"}, {"price": "0.15", "size": "551.66"}, {"price": "0.2", "size": "510"}, {"price": "0.201", "size": "160"}, {"price": "0.25", "size": "262"}, {"price": "0.27", "size": "50"}, {"price": "0.3", "size": "86.66"}, {"price": "0.34", "size": "50"}, {"price": "0.35", "size": "68.57"}, {"price": "0.4", "size": "50"}, {"price": "0.439", "size": "1197"}, {"price": "0.441", "size": "5"}, {"price": "0.442", "size": "20"}, {"price": "0.443", "size": "25"}, {"price": "0.85", "size": "5"}, {"price": "0.853", "size": "25"}, {"price": "0.854", "size": "20"}, {"price": "0.972", "size": "451.27"}, {"price": "0.973", "size": "107.13"}, {"price": "0.975", "size": "10"}, {"price": "0.976", "size": "10"}, {"price": "0.977", "size": "10"}, {"price": "0.978", "size": "10"}, {"price": "0.979", "size": "372"}, {"price": "0.98", "size": "235.14"}, {"price": "0.985", "size": "25"}, {"price": "0.988", "size": "20"}], "asks": [{"price": "0.999", "size": "14491.99"}, {"price": "0.998", "size": "313.3"}, {"price": "0.997", "size": "1014.2"}, {"price": "0.996", "size": "260.6"}, {"price": "0.995", "size": "508.44"}, {"price": "0.993", "size": "300"}, {"price": "0.99", "size": "1037.33"}], "event_type": "book", "last_trade_price": "0.010"}, {"market": "0x8253528e603b5cabb8ab45d1e1209bda57aa2a9f6f0d61aba7ad0a38147a86ee", "asset_id": "54160287404732698543970249280129195630418658913727451612951061485607934781689", "timestamp": "1769383979491", "hash": "5c0cf3ebd1681d50bc293358dc1cc4584a28daa3", "bids": [{"price": "0.01", "size": "10305.39"}, {"price": "0.02", "size": "2200"}, {"price": "0.03", "size": "266"}, {"price": "0.04", "size": "8.65"}, {"price": "0.11", "size": "168.18"}, {"price": "0.12", "size": "91.66"}, {"price": "0.25", "size": "20"}, {"price": "0.29", "size": "87"}, {"price": "0.3", "size": "600"}, {"price": "0.31", "size": "39.45"}, {"price": "0.32", "size": "248.36"}], "asks": [{"price": "0.99", "size": "16313.64"}, {"price": "0.98", "size": "2200"}, {"price": "0.97", "size": "9.92"}, {"price": "0.95", "size": "10"}, {"price": "0.93", "size": "1114.28"}, {"price": "0.92", "size": "6.18"}, {"price": "0.9", "size": "340"}, {"price": "0.86", "size": "553.57"}, {"price": "0.85", "size": "266"}, {"price": "0.83", "size": "164.7"}, {"price": "0.81", "size": "2265.64"}, {"price": "0.8", "size": "250"}, {"price": "0.79", "size": "123.8"}, {"price": "0.78", "size": "400"}, {"price": "0.76", "size": "100"}, {"price": "0.73", "size": "50"}, {"price": "0.72", "size": "71.42"}, {"price": "0.66", "size": "975"}, {"price": "0.65", "size": "5"}, {"price": "0.49", "size": "322"}, {"price": "0.47", "size": "48"}, {"price": "0.4", "size": "21.66"}, {"price": "0.39", "size": "18.03"}, {"price": "0.38", "size": "20"}, {"price": "0.37", "size": "300"}, {"price": "0.36", "size": "410.99"}, {"price": "0.35", "size": "126"}, {"price": "0.34", "size": "458.6"}, {"price": "0.33", "size": "30"}], "event_type": "book", "last_trade_price": "0.320"}, {"market": "0xa7e1a7561e1866aa345c0be640df952e1d41decf0a5c4bb571f077142fed025d", "asset_id": "115679112821476364794223653408101005434638325681840410280875053954587147234523", "timestamp": "1769383922806", "hash": "0643dddf718cebb88b0f893e9634c18723a4912a", "bids": [{"price": "0.01", "size": "7000"}, {"price": "0.02", "size": "1050"}, {"price": "0.03", "size": "13.33"}, {"price": "0.05", "size": "10"}, {"price": "0.16", "size": "5000"}, {"price": "0.17", "size": "96.47"}, {"price": "0.18", "size": "2500"}, {"price": "0.19", "size": "133.89"}, {"price": "0.21", "size": "5010"}, {"price": "0.22", "size": "1806.84"}, {"price": "0.23", "size": "298.88"}, {"price": "0.24", "size": "1578.22"}], "asks": [{"price": "0.99", "size": "16313.27"}, {"price": "0.98", "size": "2200"}, {"price": "0.97", "size": "11.78"}, {"price": "0.95", "size": "10"}, {"price": "0.93", "size": "1114.28"}, {"price": "0.92", "size": "400"}, {"price": "0.91", "size": "5.58"}, {"price": "0.89", "size": "634.09"}, {"price": "0.85", "size": "213.33"}, {"price": "0.84", "size": "250"}, {"price": "0.81", "size": "147.36"}, {"price": "0.8", "size": "2455.05"}, {"price": "0.77", "size": "113.04"}, {"price": "0.76", "size": "8"}, {"price": "0.74", "size": "92.3"}, {"price": "0.73", "size": "1792"}, {"price": "0.72", "size": "300"}, {"price": "0.7", "size": "66.66"}, {"price": "0.66", "size": "125"}, {"price": "0.65", "size": "20"}, {"price": "0.38", "size": "190.16"}, {"price": "0.37", "size": "20.63"}, {"price": "0.35", "size": "16.92"}, {"price": "0.3", "size": "1020"}, {"price": "0.29", "size": "80"}, {"price": "0.28", "size": "10"}, {"price": "0.27", "size": "50"}, {"price": "0.26", "size": "505.19"}, {"price": "0.25", "size": "70"}], "event_type": "book", "last_trade_price": "0.240"}]}
{"_local_timestamp": "2026-01-25T23:33:37.073368+00:00", "data": {"market": "0xff8bf331f7ddbdd2e92e27dcd273612ec45fefde3cf70039c4f043eaec0000c6", "price_changes": [{"asset_id": "65943623919755331891504362129239742473111951663283351342808117545053994127220", "price": "0.63", "size": "199.93", "side": "BUY", "hash": "abe391bd1c3fcf743a1d40bc2c0c811d0936d90b", "best_bid": "0.63", "best_ask": "0.64"}, {"asset_id": "60105600458079862676305161094044862147301593956294543970688990037138503709415", "price": "0.37", "size": "199.93", "side": "SELL", "hash": "3cfcfc711b9dc6e600be1773f262f82e41b94b5e", "best_bid": "0.36", "best_ask": "0.37"}], "timestamp": "1769384017002", "event_type": "price_change"}}
{"_local_timestamp": "2026-01-25T23:33:37.099157+00:00", "data": {"market": "0xff8bf331f7ddbdd2e92e27dcd273612ec45fefde3cf70039c4f043eaec0000c6", "price_changes": [{"asset_id": "65943623919755331891504362129239742473111951663283351342808117545053994127220", "price": "0.63", "size": "219.93", "side": "BUY", "hash": "38b3cde5bc8d2b5e2eb8564d2fa2f01bf7afc222", "best_bid": "0.63", "best_ask": "0.64"}, {"asset_id": "60105600458079862676305161094044862147301593956294543970688990037138503709415", "price": "0.37", "size": "219.93", "side": "SELL", "hash": "ff00830dfe63e227da8eb45384ec070c398a1488", "best_bid": "0.36", "best_ask": "0.37"}], "timestamp": "1769384017023", "event_type": "price_change"}}
{"_local_timestamp": "2026-01-25T23:33:40.304766+00:00", "data": {"market": "0x892231e7fd3ac31a3b321002f909e011180b709af074808908d27a2a32a7b546", "price_changes": [{"asset_id": "64317448978406417981854076458164286249844965670717306181829295801409919530695", "price": "0.21", "size": "100", "side": "BUY", "hash": "467c3d7b93ce442357ab2e0039e4435c75fe66d4", "best_bid": "0.92", "best_ask": "0.93"}, {"asset_id": "89791260670398307279783201184852534466650260912467648915456704380491810882664", "price": "0.79", "size": "100", "side": "SELL", "hash": "b76beaf5c96ed8520436523eeed3aac43690f81e", "best_bid": "0.07", "best_ask": "0.08"}], "timestamp": "1769384020098", "event_type": "price_change"}}
{"_local_timestamp": "2026-01-25T23:33:40.315566+00:00", "data": {"market": "0x8253528e603b5cabb8ab45d1e1209bda57aa2a9f6f0d61aba7ad0a38147a86ee", "price_changes": [{"asset_id": "17667700649974143765639286018245659141526847671421069760676398956961689778433", "price": "0.2", "size": "150", "side": "BUY", "hash": "8a4d00f26cb643e7a481e40395cb98d786884bd1", "best_bid": "0.67", "best_ask": "0.68"}, {"asset_id": "54160287404732698543970249280129195630418658913727451612951061485607934781689", "price": "0.8", "size": "150", "side": "SELL", "hash": "27a7158501aa74121a343dd1b8a4d9b37fef9add", "best_bid": "0.32", "best_ask": "0.33"}], "timestamp": "1769384020098", "event_type": "price_change"}}
{"_local_timestamp": "2026-01-25T23:33:40.742264+00:00", "data": {"market": "0x892231e7fd3ac31a3b321002f909e011180b709af074808908d27a2a32a7b546", "price_changes": [{"asset_id": "64317448978406417981854076458164286249844965670717306181829295801409919530695", "price": "0.29", "size": "1548", "side": "BUY", "hash": "23b52c2c5e31d2f8dc0c9ab6c6b2a4961ae36b1b", "best_bid": "0.92", "best_ask": "0.93"}, {"asset_id": "89791260670398307279783201184852534466650260912467648915456704380491810882664", "price": "0.71", "size": "1548", "side": "SELL", "hash": "5d190a816ffbaad9fd25db2c5bf4a82624fffbda", "best_bid": "0.07", "best_ask": "0.08"}], "timestamp": "1769384020547", "event_type": "price_change"}}
{"_local_timestamp": "2026-01-25T23:33:40.827163+00:00", "data": {"market": "0x8253528e603b5cabb8ab45d1e1209bda57aa2a9f6f0d61aba7ad0a38147a86ee", "price_changes": [{"asset_id": "17667700649974143765639286018245659141526847671421069760676398956961689778433", "price": "0.18", "size": "100", "side": "BUY", "hash": "dcf4f0cee495f902529d12a4310bf2dea068a6f3", "best_bid": "0.67", "best_ask": "0.68"}, {"asset_id": "54160287404732698543970249280129195630418658913727451612951061485607934781689", "price": "0.82", "size": "100", "side": "SELL", "hash": "259593da897307656849048a3960cd4a332917be", "best_bid": "0.32", "best_ask": "0.33"}], "timestamp": "1769384020567", "event_type": "price_change"}}
{"_local_timestamp": "2026-01-25T23:34:19.147035+00:00", "data": {"market": "0xa7e1a7561e1866aa345c0be640df952e1d41decf0a5c4bb571f077142fed025d", "price_changes": [{"asset_id": "76541116657039469088410437026264202489719024425044998810802876826622732617598", "price": "0.81", "size": "57.89", "side": "SELL", "hash": "20653b8440775f52611a300167997b7eec2407f5", "best_bid": "0.75", "best_ask": "0.76"}, {"asset_id": "115679112821476364794223653408101005434638325681840410280875053954587147234523", "price": "0.19", "size": "57.89", "side": "BUY", "hash": "35fceae62d9335778bb209131c1d636a155db981", "best_bid": "0.24", "best_ask": "0.25"}], "timestamp": "1769384058878", "event_type": "price_change"}}
{"_local_timestamp": "2026-01-25T23:34:19.307510+00:00", "data": {"market": "0xa7e1a7561e1866aa345c0be640df952e1d41decf0a5c4bb571f077142fed025d", "price_changes": [{"asset_id": "76541116657039469088410437026264202489719024425044998810802876826622732617598", "price": "0.81", "size": "133.89", "side": "SELL", "hash": "2a2aa6ea4e27b57eb293327d7925eef3630df308", "best_bid": "0.75", "best_ask": "0.76"}, {"asset_id": "115679112821476364794223653408101005434638325681840410280875053954587147234523", "price": "0.19", "size": "133.89", "side": "BUY", "hash": "2bd285a8e140b8ebfd9f5071cf16ad1f3ba38f53", "best_bid": "0.24", "best_ask": "0.25"}], "timestamp": "1769384059058", "event_type": "price_change"}}
{"_local_timestamp": "2026-01-25T23:34:20.037554+00:00", "data": {"market": "0x8253528e603b5cabb8ab45d1e1209bda57aa2a9f6f0d61aba7ad0a38147a86ee", "price_changes": [{"asset_id": "17667700649974143765639286018245659141526847671421069760676398956961689778433", "price": "0.19", "size": "55.64", "side": "BUY", "hash": "7fa6aa01c4842817f04dd6d7b4883a226ad3b2e2", "best_bid": "0.67", "best_ask": "0.68"}, {"asset_id": "54160287404732698543970249280129195630418658913727451612951061485607934781689", "price": "0.81", "size": "55.64", "side": "SELL", "hash": "29d38721e44ebe2d0fb0300f88df49e235443086", "best_bid": "0.32", "best_ask": "0.33"}], "timestamp": "1769384059762", "event_type": "price_change"}}
{"_local_timestamp": "2026-01-25T23:34:20.043741+00:00", "data": {"market": "0xa7e1a7561e1866aa345c0be640df952e1d41decf0a5c4bb571f077142fed025d", "price_changes": [{"asset_id": "76541116657039469088410437026264202489719024425044998810802876826622732617598", "price": "0.2", "size": "355.05", "side": "BUY", "hash": "844af87345ea9550230e99edc4a3ca0ba86c2704", "best_bid": "0.75", "best_ask": "0.76"}, {"asset_id": "115679112821476364794223653408101005434638325681840410280875053954587147234523", "price": "0.8", "size": "355.05", "side": "SELL", "hash": "7bf29d844c12a2db59fc8e249c6bf37e60ed5062", "best_bid": "0.24", "best_ask": "0.25"}], "timestamp": "1769384059760", "event_type": "price_change"}}
{"_local_timestamp": "2026-01-25T23:34:27.852156+00:00", "data": {"market": "0x892231e7fd3ac31a3b321002f909e011180b709af074808908d27a2a32a7b546", "price_changes": [{"asset_id": "64317448978406417981854076458164286249844965670717306181829295801409919530695", "price": "0.49", "size": "800", "side": "BUY", "hash": "f767a7d4360137980b936a3cd6cc60c94c5ca009", "best_bid": "0.92", "best_ask": "0.93"}, {"asset_id": "89791260670398307279783201184852534466650260912467648915456704380491810882664", "price": "0.51", "size": "800", "side": "SELL", "hash": "cb70d817ef051bcc0a3601366a9369c9e5aa143d", "best_bid": "0.07", "best_ask": "0.08"}], "timestamp": "1769384067570", "event_type": "price_change"}}
{"_local_timestamp": "2026-01-25T23:34:27.855197+00:00", "data": {"market": "0x892231e7fd3ac31a3b321002f909e011180b709af074808908d27a2a32a7b546", "price_changes": [{"asset_id": "64317448978406417981854076458164286249844965670717306181829295801409919530695", "price": "0.21", "size": "0", "side": "BUY", "hash": "f767a7d4360137980b936a3cd6cc60c94c5ca009", "best_bid": "0.92", "best_ask": "0.93"}, {"asset_id": "89791260670398307279783201184852534466650260912467648915456704380491810882664", "price": "0.79", "size": "0", "side": "SELL", "hash": "cb70d817ef051bcc0a3601366a9369c9e5aa143d", "best_bid": "0.07", "best_ask": "0.08"}], "timestamp": "1769384067570", "event_type": "price_change"}}
{"_local_timestamp": "2026-01-25T23:34:27.912218+00:00", "data": {"market": "0xff8bf331f7ddbdd2e92e27dcd273612ec45fefde3cf70039c4f043eaec0000c6", "price_changes": [{"asset_id": "65943623919755331891504362129239742473111951663283351342808117545053994127220", "price": "0.28", "size": "1200", "side": "BUY", "hash": "fe5bda00d9cd1e2d92c17a24950ada7e2b0f43b9", "best_bid": "0.63", "best_ask": "0.64"}, {"asset_id": "60105600458079862676305161094044862147301593956294543970688990037138503709415", "price": "0.72", "size": "1200", "side": "SELL", "hash": "0aec8e98fee8f8a784db46ba8fc9e42e3373f4c4", "best_bid": "0.36", "best_ask": "0.37"}], "timestamp": "1769384067579", "event_type": "price_change"}}
{"_local_timestamp": "2026-01-25T23:34:27.918829+00:00", "data": {"market": "0x8253528e603b5cabb8ab45d1e1209bda57aa2a9f6f0d61aba7ad0a38147a86ee", "price_changes": [{"asset_id": "17667700649974143765639286018245659141526847671421069760676398956961689778433", "price": "0.2", "size": "0", "side": "BUY", "hash": "f676881680be8c7f05581cbdccca6859949f45b5", "best_bid": "0.67", "best_ask": "0.68"}, {"asset_id": "54160287404732698543970249280129195630418658913727451612951061485607934781689", "price": "0.8", "size": "0", "side": "SELL", "hash": "594a605c69fa3fad0eab5fa5652a0debf4ebc4fa", "best_bid": "0.32", "best_ask": "0.33"}], "timestamp": "1769384067580", "event_type": "price_change"}}
{"_local_timestamp": "2026-01-25T23:34:28.067435+00:00", "data": {"market": "0xa7e1a7561e1866aa345c0be640df952e1d41decf0a5c4bb571f077142fed025d", "price_changes": [{"asset_id": "76541116657039469088410437026264202489719024425044998810802876826622732617598", "price": "0.27", "size": "1000", "side": "BUY", "hash": "ec6c4dfbdf8ce340445e85e2044a0fc19195e334", "best_bid": "0.75", "best_ask": "0.76"}, {"asset_id": "115679112821476364794223653408101005434638325681840410280875053954587147234523", "price": "0.73", "size": "1000", "side": "SELL", "hash": "f93ac829304802c4304a3ae3c5c6d2816431fdb3", "best_bid": "0.24", "best_ask": "0.25"}], "timestamp": "1769384067691", "event_type": "price_change"}}
{"_local_timestamp": "2026-01-25T23:34:28.119093+00:00", "data": {"market": "0xa7e1a7561e1866aa345c0be640df952e1d41decf0a5c4bb571f077142fed025d", "price_changes": [{"asset_id": "76541116657039469088410437026264202489719024425044998810802876826622732617598", "price": "0.27", "size": "200", "side": "BUY", "hash": "115884d1b1bdb47a75d37ce8175a88f8f5e7631a", "best_bid": "0.75", "best_ask": "0.76"}, {"asset_id": "115679112821476364794223653408101005434638325681840410280875053954587147234523", "price": "0.73", "size": "200", "side": "SELL", "hash": "c3bed398af03ce80f71530aa967fb3b4a37184c6", "best_bid": "0.24", "best_ask": "0.25"}], "timestamp": "1769384067820", "event_type": "price_change"}}
{"_local_timestamp": "2026-01-25T23:34:28.196546+00:00", "data": {"market": "0xa7e1a7561e1866aa345c0be640df952e1d41decf0a5c4bb571f077142fed025d", "price_changes": [{"asset_id": "76541116657039469088410437026264202489719024425044998810802876826622732617598", "price": "0.28", "size": "764", "side": "BUY", "hash": "6327a025b513e934d3d07f56843e3f811bc9559c", "best_bid": "0.75", "best_ask": "0.76"}, {"asset_id": "115679112821476364794223653408101005434638325681840410280875053954587147234523", "price": "0.72", "size": "764", "side": "SELL", "hash": "c82c075b5c62fc65540c24ff9346a3999e2f1d0b", "best_bid": "0.24", "best_ask": "0.25"}], "timestamp": "1769384067958", "event_type": "price_change"}}
{"_local_timestamp": "2026-01-25T23:34:28.270002+00:00", "data": {"market": "0xa7e1a7561e1866aa345c0be640df952e1d41decf0a5c4bb571f077142fed025d", "price_changes": [{"asset_id": "76541116657039469088410437026264202489719024425044998810802876826622732617598", "price": "0.28", "size": "1212", "side": "BUY", "hash": "e0bcb4e0297b99b46a8791f01b07d1e0dc71a836", "best_bid": "0.75", "best_ask": "0.76"}, {"asset_id": "115679112821476364794223653408101005434638325681840410280875053954587147234523", "price": "0.72", "size": "1212", "side": "SELL", "hash": "7f7eea00b8ce566004509c588809d292997b2e92", "best_bid": "0.24", "best_ask": "0.25"}], "timestamp": "1769384068025", "event_type": "price_change"}}
{"_local_timestamp": "2026-01-25T23:34:28.478867+00:00", "data": {"market": "0xff8bf331f7ddbdd2e92e27dcd273612ec45fefde3cf70039c4f043eaec0000c6", "price_changes": [{"asset_id": "65943623919755331891504362129239742473111951663283351342808117545053994127220", "price": "0.29", "size": "856", "side": "BUY", "hash": "13f1c93fb18657b746185882a45133e1855bef39", "best_bid": "0.63", "best_ask": "0.64"}, {"asset_id": "60105600458079862676305161094044862147301593956294543970688990037138503709415", "price": "0.71", "size": "856", "side": "SELL", "hash": "8f29fd44911bd0df37285d8941cb1e06af8a970c", "best_bid": "0.36", "best_ask": "0.37"}], "timestamp": "1769384068090", "event_type": "price_change"}}
{"_local_timestamp": "2026-01-25T23:34:28.482597+00:00", "data": {"market": "0x892231e7fd3ac31a3b321002f909e011180b709af074808908d27a2a32a7b546", "price_changes": [{"asset_id": "64317448978406417981854076458164286249844965670717306181829295801409919530695", "price": "0.29", "size": "1648", "side": "BUY", "hash": "372cba9abed31670e2eedfc73a3879a4065d18ea", "best_bid": "0.92", "best_ask": "0.93"}, {"asset_id": "89791260670398307279783201184852534466650260912467648915456704380491810882664", "price": "0.71", "size": "1648", "side": "SELL", "hash": "624a7d2f64b063bc9bc1b53dc300c30c8917f6b7", "best_bid": "0.07", "best_ask": "0.08"}], "timestamp": "1769384068090", "event_type": "price_change"}}
{"_local_timestamp": "2026-01-25T23:34:28.496135+00:00", "data": {"market": "0x8253528e603b5cabb8ab45d1e1209bda57aa2a9f6f0d61aba7ad0a38147a86ee", "price_changes": [{"asset_id": "17667700649974143765639286018245659141526847671421069760676398956961689778433", "price": "0.18", "size": "250", "side": "BUY", "hash": "9d76dbdf1d832eb4816d446fc9e9b03a5d1fbdbb", "best_bid": "0.67", "best_ask": "0.68"}, {"asset_id": "54160287404732698543970249280129195630418658913727451612951061485607934781689", "price": "0.82", "size": "250", "side": "SELL", "hash": "8484d696144b16caa3030ecae0e10f34fbc702f2", "best_bid": "0.32", "best_ask": "0.33"}], "timestamp": "1769384068090", "event_type": "price_change"}}
{"_local_timestamp": "2026-01-25T23:34:28.786948+00:00", "data": {"market": "0x892231e7fd3ac31a3b321002f909e011180b709af074808908d27a2a32a7b546", "price_changes": [{"asset_id": "64317448978406417981854076458164286249844965670717306181829295801409919530695", "price": "0.5", "size": "408", "side": "BUY", "hash": "1811c45db3c0b549207e7b9904705cef9cfd2301", "best_bid": "0.92", "best_ask": "0.93"}, {"asset_id": "89791260670398307279783201184852534466650260912467648915456704380491810882664", "price": "0.5", "size": "408", "side": "SELL", "hash": "09e706e6c626fba0f36da8e2756b6659635f0d4d", "best_bid": "0.07", "best_ask": "0.08"}], "timestamp": "1769384068190", "event_type": "price_change"}}
{"_local_timestamp": "2026-01-25T23:34:29.721214+00:00", "data": {"market": "0x8253528e603b5cabb8ab45d1e1209bda57aa2a9f6f0d61aba7ad0a38147a86ee", "price_changes": [{"asset_id": "17667700649974143765639286018245659141526847671421069760676398956961689778433", "price": "0.21", "size": "2121.8", "side": "BUY", "hash": "8216213be8f3d2d7cc91726327c49fbbacfd0c64", "best_bid": "0.67", "best_ask": "0.68"}, {"asset_id": "54160287404732698543970249280129195630418658913727451612951061485607934781689", "price": "0.79", "size": "2121.8", "side": "SELL", "hash": "46c64f05d972aa0b4a939c7b0063e62a45b0c0eb", "best_bid": "0.32", "best_ask": "0.33"}], "timestamp": "1769384069489", "event_type": "price_change"}}
{"_local_timestamp": "2026-01-25T23:34:48.559331+00:00", "data": {"market": "0x8253528e603b5cabb8ab45d1e1209bda57aa2a9f6f0d61aba7ad0a38147a86ee", "price_changes": [{"asset_id": "17667700649974143765639286018245659141526847671421069760676398956961689778433", "price": "0.19", "size": "5.64", "side": "BUY", "hash": "52a687221cbc53a0c125b46ff24fa36dc154616c", "best_bid": "0.67", "best_ask": "0.68"}, {"asset_id": "54160287404732698543970249280129195630418658913727451612951061485607934781689", "price": "0.81", "size": "5.64", "side": "SELL", "hash": "7f1936859d9df33a0a0a5fc7fbf0e197602e3d82", "best_bid": "0.32", "best_ask": "0.33"}], "timestamp": "1769384088487", "event_type": "price_change"}}
{"_local_timestamp": "2026-01-25T23:34:48.573647+00:00", "data": {"market": "0xa7e1a7561e1866aa345c0be640df952e1d41decf0a5c4bb571f077142fed025d", "price_changes": [{"asset_id": "76541116657039469088410437026264202489719024425044998810802876826622732617598", "price": "0.2", "size": "305.05", "side": "BUY", "hash": "4ad244a34bc593f88caf600cf47c92ce25ba9e8e", "best_bid": "0.75", "best_ask": "0.76"}, {"asset_id": "115679112821476364794223653408101005434638325681840410280875053954587147234523", "price": "0.8", "size": "305.05", "side": "SELL", "hash": "4840c4a1714c2ec6db1acbc31fbdc6ca0e71f1c6", "best_bid": "0.24", "best_ask": "0.25"}], "timestamp": "1769384088487", "event_type": "price_change"}}
{"_local_timestamp": "2026-01-25T23:34:48.857591+00:00", "data": {"market": "0xa7e1a7561e1866aa345c0be640df952e1d41decf0a5c4bb571f077142fed025d", "price_changes": [{"asset_id": "76541116657039469088410437026264202489719024425044998810802876826622732617598", "price": "0.11", "size": "684.09", "side": "BUY", "hash": "8a5e6d045049dbc191139985d8a6f0437bb89bcb", "best_bid": "0.75", "best_ask": "0.76"}, {"asset_id": "115679112821476364794223653408101005434638325681840410280875053954587147234523", "price": "0.89", "size": "684.09", "side": "SELL", "hash": "0fdc779649983efe7b549496b46c6eea05da5f47", "best_bid": "0.24", "best_ask": "0.25"}], "timestamp": "1769384088777", "event_type": "price_change"}}
{"_local_timestamp": "2026-01-25T23:34:48.858053+00:00", "data": {"market": "0x8253528e603b5cabb8ab45d1e1209bda57aa2a9f6f0d61aba7ad0a38147a86ee", "price_changes": [{"asset_id": "17667700649974143765639286018245659141526847671421069760676398956961689778433", "price": "0.14", "size": "603.57", "side": "BUY", "hash": "a01ee2ae9246dc52fd746409af9aab64c13fd943", "best_bid": "0.67", "best_ask": "0.68"}, {"asset_id": "54160287404732698543970249280129195630418658913727451612951061485607934781689", "price": "0.86", "size": "603.57", "side": "SELL", "hash": "45551cfcc05fa926d45a7aa81e76f5ce62a9ac75", "best_bid": "0.32", "best_ask": "0.33"}], "timestamp": "1769384088775", "event_type": "price_change"}}
{"_local_timestamp": "2026-01-25T23:34:52.720717+00:00", "data": {"market": "0xb83cf6cdfe9973219d19fb70f863ec9b713a313609db51839eeb34f7acf275ad", "price_changes": [{"asset_id": "101837527728017183708561627155221790735931039980484062356872287158739556672077", "price": "0.003", "size": "1000", "side": "BUY", "hash": "ca6551eacc91f4dc714b5491a28dbb8d0077a2f4", "best_bid": "0.01", "best_ask": "0.012"}, {"asset_id": "31464892460544164986335006004080412271316454788455556340430054002451576894443", "price": "0.997", "size": "1000", "side": "SELL", "hash": "bf660ecfc8e7d62c502208fe796811328b350a68", "best_bid": "0.988", "best_ask": "0.99"}], "timestamp": "1769384092559", "event_type": "price_change"}}
{"_local_timestamp": "2026-01-25T23:34:52.721202+00:00", "data": {"market": "0xb83cf6cdfe9973219d19fb70f863ec9b713a313609db51839eeb34f7acf275ad", "price_changes": [{"asset_id": "101837527728017183708561627155221790735931039980484062356872287158739556672077", "price": "0.004", "size": "250", "side": "BUY", "hash": "ca6551eacc91f4dc714b5491a28dbb8d0077a2f4", "best_bid": "0.01", "best_ask": "0.012"}, {"asset_id": "31464892460544164986335006004080412271316454788455556340430054002451576894443", "price": "0.996", "size": "250", "side": "SELL", "hash": "bf660ecfc8e7d62c502208fe796811328b350a68", "best_bid": "0.988", "best_ask": "0.99"}], "timestamp": "1769384092559", "event_type": "price_change"}}
{"_local_timestamp": "2026-01-25T23:34:53.044435+00:00", "data": {"market": "0xb83cf6cdfe9973219d19fb70f863ec9b713a313609db51839eeb34f7acf275ad", "price_changes": [{"asset_id": "101837527728017183708561627155221790735931039980484062356872287158739556672077", "price": "0.004", "size": "260.6", "side": "BUY", "hash": "0fd4e69b677e8129eca0937ca69689502c94679e", "best_bid": "0.01", "best_ask": "0.012"}, {"asset_id": "31464892460544164986335006004080412271316454788455556340430054002451576894443", "price": "0.996", "size": "260.6", "side": "SELL", "hash": "671f29c604617dcff20a3fec9fc7ecbd9ef65bc6", "best_bid": "0.988", "best_ask": "0.99"}], "timestamp": "1769384092879", "event_type": "price_change"}}
{"_local_timestamp": "2026-01-25T23:34:53.044837+00:00", "data": {"market": "0xb83cf6cdfe9973219d19fb70f863ec9b713a313609db51839eeb34f7acf275ad", "price_changes": [{"asset_id": "101837527728017183708561627155221790735931039980484062356872287158739556672077", "price": "0.003", "size": "1014.2", "side": "BUY", "hash": "cd711d7ece90c923744fa0778724c09c35a2c858", "best_bid": "0.01", "best_ask": "0.012"}, {"asset_id": "31464892460544164986335006004080412271316454788455556340430054002451576894443", "price": "0.997", "size": "1014.2", "side": "SELL", "hash": "603ddc9eddf55d6ad42771bbc54d8c3a5f4a2d8a", "best_bid": "0.988", "best_ask": "0.99"}], "timestamp": "1769384092881", "event_type": "price_change"}}
{"_local_timestamp": "2026-01-25T23:34:56.153919+00:00", "data": {"market": "0x8253528e603b5cabb8ab45d1e1209bda57aa2a9f6f0d61aba7ad0a38147a86ee", "price_changes": [{"asset_id": "17667700649974143765639286018245659141526847671421069760676398956961689778433", "price": "0.68", "size": "205.36", "side": "SELL", "hash": "2b1f08acd3019435eefc50e275aea306f54a20db", "best_bid": "0.67", "best_ask": "0.68"}, {"asset_id": "54160287404732698543970249280129195630418658913727451612951061485607934781689", "price": "0.32", "size": "205.36", "side": "BUY", "hash": "c8c6e7386ed36e727c786c148585aa20ee3f802a", "best_bid": "0.32", "best_ask": "0.33"}], "timestamp": "1769384096012", "event_type": "price_change"}}
{"_local_timestamp": "2026-01-25T23:34:56.288388+00:00", "data": {"market": "0x8253528e603b5cabb8ab45d1e1209bda57aa2a9f6f0d61aba7ad0a38147a86ee", "price_changes": [{"asset_id": "17667700649974143765639286018245659141526847671421069760676398956961689778433", "price": "0.68", "size": "248.36", "side": "SELL", "hash": "f6df624c4533dadea05bae0863330e30352dadda", "best_bid": "0.67", "best_ask": "0.68"}, {"asset_id": "54160287404732698543970249280129195630418658913727451612951061485607934781689", "price": "0.32", "size": "248.36", "side": "BUY", "hash": "ee209c81effe92efbf0af44dfb88bce9b04b7a48", "best_bid": "0.32", "best_ask": "0.33"}], "timestamp": "1769384096199", "event_type": "price_change"}}
{"_local_timestamp": "2026-01-25T23:35:18.958491+00:00", "data": {"market": "0xa7e1a7561e1866aa345c0be640df952e1d41decf0a5c4bb571f077142fed025d", "price_changes": [{"asset_id": "76541116657039469088410437026264202489719024425044998810802876826622732617598", "price": "0.17", "size": "2470", "side": "BUY", "hash": "04cc51c36822a0b1b8936588e1395520160d57f0", "best_bid": "0.75", "best_ask": "0.76"}, {"asset_id": "115679112821476364794223653408101005434638325681840410280875053954587147234523", "price": "0.83", "size": "2470", "side": "SELL", "hash": "6ec10fde6639906569756bb39880f164fae2e51d", "best_bid": "0.24", "best_ask": "0.25"}], "timestamp": "1769384118873", "event_type": "price_change"}}
{"_local_timestamp": "2026-01-25T23:35:24.499224+00:00", "data": {"market": "0xff8bf331f7ddbdd2e92e27dcd273612ec45fefde3cf70039c4f043eaec0000c6", "price_changes": [{"asset_id": "65943623919755331891504362129239742473111951663283351342808117545053994127220", "price": "0.6", "size": "280", "side": "BUY", "hash": "28ebb75d9b2e9d25f8fb43b94b91a6b96220606b", "best_bid": "0.63", "best_ask": "0.64"}, {"asset_id": "60105600458079862676305161094044862147301593956294543970688990037138503709415", "price": "0.4", "size": "280", "side": "SELL", "hash": "77b044b4b67626c7166d37126bc8e768de18cbeb", "best_bid": "0.36", "best_ask": "0.37"}], "timestamp": "1769384124274", "event_type": "price_change"}}
{"_local_timestamp": "2026-01-25T23:35:24.501545+00:00", "data": {"market": "0x892231e7fd3ac31a3b321002f909e011180b709af074808908d27a2a32a7b546", "price_changes": [{"asset_id": "64317448978406417981854076458164286249844965670717306181829295801409919530695", "price": "0.83", "size": "47", "side": "BUY", "hash": "d92740c91d8869d255d45635ba7d235d9b3be8ad", "best_bid": "0.92", "best_ask": "0.93"}, {"asset_id": "89791260670398307279783201184852534466650260912467648915456704380491810882664", "price": "0.17", "size": "47", "side": "SELL", "hash": "d1e7ff368cce7d6b928a60b85fa9950b45b9dbc2", "best_bid": "0.07", "best_ask": "0.08"}], "timestamp": "1769384124274", "event_type": "price_change"}}
{"_local_timestamp": "2026-01-25T23:35:24.502052+00:00", "data": {"market": "0xff8bf331f7ddbdd2e92e27dcd273612ec45fefde3cf70039c4f043eaec0000c6", "price_changes": [{"asset_id": "65943623919755331891504362129239742473111951663283351342808117545053994127220", "price": "0.59", "size": "196", "side": "BUY", "hash": "51af4ded361432b6793fddd6c0e35f95f239cf18", "best_bid": "0.63", "best_ask": "0.64"}, {"asset_id": "60105600458079862676305161094044862147301593956294543970688990037138503709415", "price": "0.41", "size": "196", "side": "SELL", "hash": "56ed46dca881241dea63cd602b1dd2a48d6a6bbe", "best_bid": "0.36", "best_ask": "0.37"}], "timestamp": "1769384124276", "event_type": "price_change"}}
{"_local_timestamp": "2026-01-25T23:35:24.655114+00:00", "data": {"market": "0x892231e7fd3ac31a3b321002f909e011180b709af074808908d27a2a32a7b546", "price_changes": [{"asset_id": "64317448978406417981854076458164286249844965670717306181829295801409919530695", "price": "0.81", "size": "45", "side": "BUY", "hash": "cb0690c91ecf06b43b4beebfdfbeaa60f0fb1611", "best_bid": "0.92", "best_ask": "0.93"}, {"asset_id": "89791260670398307279783201184852534466650260912467648915456704380491810882664", "price": "0.19", "size": "45", "side": "SELL", "hash": "83050849697c083804e5beb613531d1c9c7f21d4", "best_bid": "0.07", "best_ask": "0.08"}], "timestamp": "1769384124455", "event_type": "price_change"}}
{"_local_timestamp": "2026-01-25T23:35:24.655674+00:00", "data": {"market": "0xff8bf331f7ddbdd2e92e27dcd273612ec45fefde3cf70039c4f043eaec0000c6", "price_changes": [{"asset_id": "60105600458079862676305161094044862147301593956294543970688990037138503709415", "price": "0.32", "size": "6", "side": "BUY", "hash": "ca6e8c715eb00cd30493a961a85026b67137da1c", "best_bid": "0.36", "best_ask": "0.37"}, {"asset_id": "65943623919755331891504362129239742473111951663283351342808117545053994127220", "price": "0.68", "size": "6", "side": "SELL", "hash": "aca18bf827e93a06dfdfebfa1f917a8ddaf51e0a", "best_bid": "0.63", "best_ask": "0.64"}], "timestamp": "1769384124457", "event_type": "price_change"}}
{"_local_timestamp": "2026-01-25T23:35:24.711476+00:00", "data": {"market": "0xb83cf6cdfe9973219d19fb70f863ec9b713a313609db51839eeb34f7acf275ad", "price_changes": [{"asset_id": "31464892460544164986335006004080412271316454788455556340430054002451576894443", "price": "0.853", "size": "0", "side": "BUY", "hash": "b1976342fdd0593feb59d586974583ca2a2d2a25", "best_bid": "0.988", "best_ask": "0.99"}, {"asset_id": "101837527728017183708561627155221790735931039980484062356872287158739556672077", "price": "0.147", "size": "0", "side": "SELL", "hash": "246c98a1353aca02ddd95acdb2166cd74c144bc0", "best_bid": "0.01", "best_ask": "0.012"}], "timestamp": "1769384124530", "event_type": "price_change"}}
{"_local_timestamp": "2026-01-25T23:35:24.882479+00:00", "data": {"market": "0xb83cf6cdfe9973219d19fb70f863ec9b713a313609db51839eeb34f7acf275ad", "price_changes": [{"asset_id": "31464892460544164986335006004080412271316454788455556340430054002451576894443", "price": "0.442", "size": "0", "side": "BUY", "hash": "d835d6d36409e421eaeec32b374ab7fd9558b7d4", "best_bid": "0.988", "best_ask": "0.99"}, {"asset_id": "101837527728017183708561627155221790735931039980484062356872287158739556672077", "price": "0.558", "size": "0", "side": "SELL", "hash": "5ddaf60b1be0afe7b4fb75f124b765bb6705d073", "best_bid": "0.01", "best_ask": "0.012"}], "timestamp": "1769384124678", "event_type": "price_change"}}
{"_local_timestamp": "2026-01-25T23:35:24.998292+00:00", "data": {"market": "0x892231e7fd3ac31a3b321002f909e011180b709af074808908d27a2a32a7b546", "price_changes": [{"asset_id": "64317448978406417981854076458164286249844965670717306181829295801409919530695", "price": "0.81", "size": "20", "side": "BUY", "hash": "7892ee827ee0d1036f31ac673882697cdd23f136", "best_bid": "0.92", "best_ask": "0.93"}, {"asset_id": "89791260670398307279783201184852534466650260912467648915456704380491810882664", "price": "0.19", "size": "20", "side": "SELL", "hash": "c4c92b60d60b46034e23b2d43c08594d0a21846a", "best_bid": "0.07", "best_ask": "0.08"}], "timestamp": "1769384124798", "event_type": "price_change"}}
{"_local_timestamp": "2026-01-25T23:35:25.004039+00:00", "data": {"market": "0xb83cf6cdfe9973219d19fb70f863ec9b713a313609db51839eeb34f7acf275ad", "price_changes": [{"asset_id": "31464892460544164986335006004080412271316454788455556340430054002451576894443", "price": "0.855", "size": "25", "side": "BUY", "hash": "633b13ae068142edc227daded3c0010943bfbd87", "best_bid": "0.988", "best_ask": "0.99"}, {"asset_id": "101837527728017183708561627155221790735931039980484062356872287158739556672077", "price": "0.145", "size": "25", "side": "SELL", "hash": "5078f46dd6d9d752a3f4d901f379c2a259b4b870", "best_bid": "0.01", "best_ask": "0.012"}], "timestamp": "1769384124803", "event_type": "price_change"}}
{"_local_timestamp": "2026-01-25T23:35:25.043351+00:00", "data": {"market": "0xb83cf6cdfe9973219d19fb70f863ec9b713a313609db51839eeb34f7acf275ad", "price_changes": [{"asset_id": "31464892460544164986335006004080412271316454788455556340430054002451576894443", "price": "0.855", "size": "45", "side": "BUY", "hash": "3a84a5cf5fa4d2da7705cfc61d3f3b2ed8111c2f", "best_bid": "0.988", "best_ask": "0.99"}, {"asset_id": "101837527728017183708561627155221790735931039980484062356872287158739556672077", "price": "0.145", "size": "45", "side": "SELL", "hash": "b4b38c42b335ff86a7a54ce09590339fabc49570", "best_bid": "0.01", "best_ask": "0.012"}], "timestamp": "1769384124881", "event_type": "price_change"}}
{"_local_timestamp": "2026-01-25T23:35:26.609606+00:00", "data": {"market": "0xb83cf6cdfe9973219d19fb70f863ec9b713a313609db51839eeb34f7acf275ad", "price_changes": [{"asset_id": "31464892460544164986335006004080412271316454788455556340430054002451576894443", "price": "0.854", "size": "0", "side": "BUY", "hash": "958ddb44adb7456e045b68a832a36ee3b003dc25", "best_bid": "0.988", "best_ask": "0.99"}, {"asset_id": "101837527728017183708561627155221790735931039980484062356872287158739556672077", "price": "0.146", "size": "0", "side": "SELL", "hash": "ce8ad8354c6bbd94220fdba25ffb04bc44d9629c", "best_bid": "0.01", "best_ask": "0.012"}], "timestamp": "1769384126539", "event_type": "price_change"}}
{"_local_timestamp": "2026-01-25T23:35:26.610088+00:00", "data": {"market": "0x892231e7fd3ac31a3b321002f909e011180b709af074808908d27a2a32a7b546", "price_changes": [{"asset_id": "64317448978406417981854076458164286249844965670717306181829295801409919530695", "price": "0.82", "size": "0", "side": "BUY", "hash": "7eaa80f9580663b3a86dc3bb7d55ec93cdfb1571", "best_bid": "0.92", "best_ask": "0.93"}, {"asset_id": "89791260670398307279783201184852534466650260912467648915456704380491810882664", "price": "0.18", "size": "0", "side": "SELL", "hash": "eb6be3a40d043f80dfd91883a151d16375b351e2", "best_bid": "0.07", "best_ask": "0.08"}], "timestamp": "1769384126539", "event_type": "price_change"}}
{"_local_timestamp": "2026-01-25T23:35:26.650777+00:00", "data": {"market": "0x8253528e603b5cabb8ab45d1e1209bda57aa2a9f6f0d61aba7ad0a38147a86ee", "price_changes": [{"asset_id": "17667700649974143765639286018245659141526847671421069760676398956961689778433", "price": "0.18", "size": "150", "side": "BUY", "hash": "2de8ab7cb890608435ad90c5f3d37d0b87249466", "best_bid": "0.67", "best_ask": "0.68"}, {"asset_id": "54160287404732698543970249280129195630418658913727451612951061485607934781689", "price": "0.82", "size": "150", "side": "SELL", "hash": "5f227102b3ce9d0125f005d01d545c22f9cd3a75", "best_bid": "0.32", "best_ask": "0.33"}], "timestamp": "1769384126560", "event_type": "price_change"}}
{"_local_timestamp": "2026-01-25T23:35:26.692002+00:00", "data": {"market": "0x892231e7fd3ac31a3b321002f909e011180b709af074808908d27a2a32a7b546", "price_changes": [{"asset_id": "64317448978406417981854076458164286249844965670717306181829295801409919530695", "price": "0.84", "size": "20", "side": "BUY", "hash": "53cb2001da225520a7627adb80499299bf07298e", "best_bid": "0.92", "best_ask": "0.93"}, {"asset_id": "89791260670398307279783201184852534466650260912467648915456704380491810882664", "price": "0.16", "size": "20", "side": "SELL", "hash": "dc8ea1439fe09b71910929be68c1affacde564a0", "best_bid": "0.07", "best_ask": "0.08"}], "timestamp": "1769384126566", "event_type": "price_change"}}
{"_local_timestamp": "2026-01-25T23:35:26.692456+00:00", "data": {"market": "0xb83cf6cdfe9973219d19fb70f863ec9b713a313609db51839eeb34f7acf275ad", "price_changes": [{"asset_id": "31464892460544164986335006004080412271316454788455556340430054002451576894443", "price": "0.856", "size": "20", "side": "BUY", "hash": "4c95cb57eaab49d4526f7bb5913b469639bc6dfd", "best_bid": "0.988", "best_ask": "0.99"}, {"asset_id": "101837527728017183708561627155221790735931039980484062356872287158739556672077", "price": "0.144", "size": "20", "side": "SELL", "hash": "5325a49494ad8c9574e27cc361d13d7afe178a42", "best_bid": "0.01", "best_ask": "0.012"}], "timestamp": "1769384126566", "event_type": "price_change"}}
{"_local_timestamp": "2026-01-25T23:35:27.099559+00:00", "data": {"market": "0x8253528e603b5cabb8ab45d1e1209bda57aa2a9f6f0d61aba7ad0a38147a86ee", "price_changes": [{"asset_id": "17667700649974143765639286018245659141526847671421069760676398956961689778433", "price": "0.19", "size": "105.64", "side": "BUY", "hash": "ba84d7857f563616646e712d93c8b2d06025deec", "best_bid": "0.67", "best_ask": "0.68"}, {"asset_id": "54160287404732698543970249280129195630418658913727451612951061485607934781689", "price": "0.81", "size": "105.64", "side": "SELL", "hash": "3f6c66763ba4e3b96790af95bdb86211e859e6ce", "best_bid": "0.32", "best_ask": "0.33"}], "timestamp": "1769384126900", "event_type": "price_change"}}
{"_local_timestamp": "2026-01-25T23:35:42.258347+00:00", "data": {"market": "0x892231e7fd3ac31a3b321002f909e011180b709af074808908d27a2a32a7b546", "price_changes": [{"asset_id": "64317448978406417981854076458164286249844965670717306181829295801409919530695", "price": "0.83", "size": "0", "side": "BUY", "hash": "8f787d6133535fd379f2ef0ae81c33f1d20b68e0", "best_bid": "0.92", "best_ask": "0.93"}, {"asset_id": "89791260670398307279783201184852534466650260912467648915456704380491810882664", "price": "0.17", "size": "0", "side": "SELL", "hash": "764503451539e7ee52e2cb1f87c38da481bb9be9", "best_bid": "0.07", "best_ask": "0.08"}], "timestamp": "1769384142169", "event_type": "price_change"}}
{"_local_timestamp": "2026-01-25T23:35:42.513015+00:00", "data": {"market": "0x892231e7fd3ac31a3b321002f909e011180b709af074808908d27a2a32a7b546", "price_changes": [{"asset_id": "64317448978406417981854076458164286249844965670717306181829295801409919530695", "price": "0.84", "size": "0", "side": "BUY", "hash": "21931f76224762c3685e43d041b6656fa35aaabc", "best_bid": "0.92", "best_ask": "0.93"}, {"asset_id": "89791260670398307279783201184852534466650260912467648915456704380491810882664", "price": "0.16", "size": "0", "side": "SELL", "hash": "0a32e30aa06460ee33f71037cfd2c524e06daeb9", "best_bid": "0.07", "best_ask": "0.08"}], "timestamp": "1769384142433", "event_type": "price_change"}}
{"_local_timestamp": "2026-01-25T23:35:42.556097+00:00", "data": {"market": "0x892231e7fd3ac31a3b321002f909e011180b709af074808908d27a2a32a7b546", "price_changes": [{"asset_id": "64317448978406417981854076458164286249844965670717306181829295801409919530695", "price": "0.82", "size": "20", "side": "BUY", "hash": "634abaf3d72a5fb531e4e557a854c22141e2131f", "best_bid": "0.92", "best_ask": "0.93"}, {"asset_id": "89791260670398307279783201184852534466650260912467648915456704380491810882664", "price": "0.18", "size": "20", "side": "SELL", "hash": "12e6814d2e2097bf8b688008b1a335fad824b3e4", "best_bid": "0.07", "best_ask": "0.08"}], "timestamp": "1769384142477", "event_type": "price_change"}}
{"_local_timestamp": "2026-01-25T23:35:53.588916+00:00", "data": {"market": "0xa7e1a7561e1866aa345c0be640df952e1d41decf0a5c4bb571f077142fed025d", "price_changes": [{"asset_id": "76541116657039469088410437026264202489719024425044998810802876826622732617598", "price": "0.11", "size": "634.09", "side": "BUY", "hash": "1e1b0c0ec09ad63b4424b7bcb609ecb2f74e2933", "best_bid": "0.75", "best_ask": "0.76"}, {"asset_id": "115679112821476364794223653408101005434638325681840410280875053954587147234523", "price": "0.89", "size": "634.09", "side": "SELL", "hash": "f58d8c4e004c4d0fcff552609f30063bb369f05d", "best_bid": "0.24", "best_ask": "0.25"}], "timestamp": "1769384153515", "event_type": "price_change"}}
{"_local_timestamp": "2026-01-25T23:35:53.852867+00:00", "data": {"market": "0xa7e1a7561e1866aa345c0be640df952e1d41decf0a5c4bb571f077142fed025d", "price_changes": [{"asset_id": "76541116657039469088410437026264202489719024425044998810802876826622732617598", "price": "0.17", "size": "2520", "side": "BUY", "hash": "c7afe490c6aa19f92ac8753bf5e575cd5e8f85ec", "best_bid": "0.75", "best_ask": "0.76"}, {"asset_id": "115679112821476364794223653408101005434638325681840410280875053954587147234523", "price": "0.83", "size": "2520", "side": "SELL", "hash": "f09d2953d517de02f2952b6b90a7bf098a1b60bc", "best_bid": "0.24", "best_ask": "0.25"}], "timestamp": "1769384153783", "event_type": "price_change"}}
{"_local_timestamp": "2026-01-25T23:35:58.180148+00:00", "data": {"market": "0xa7e1a7561e1866aa345c0be640df952e1d41decf0a5c4bb571f077142fed025d", "price_changes": [{"asset_id": "76541116657039469088410437026264202489719024425044998810802876826622732617598", "price": "0.17", "size": "50", "side": "BUY", "hash": "a0c8bcf01ec39856973ed247a6a309733415dddd", "best_bid": "0.75", "best_ask": "0.76"}, {"asset_id": "115679112821476364794223653408101005434638325681840410280875053954587147234523", "price": "0.83", "size": "50", "side": "SELL", "hash": "fc962f9a8048683938bbe93066d9c33b2cba5734", "best_bid": "0.24", "best_ask": "0.25"}], "timestamp": "1769384158070", "event_type": "price_change"}}
{"_local_timestamp": "2026-01-25T23:35:58.181107+00:00", "data": {"market": "0x8253528e603b5cabb8ab45d1e1209bda57aa2a9f6f0d61aba7ad0a38147a86ee", "price_changes": [{"asset_id": "17667700649974143765639286018245659141526847671421069760676398956961689778433", "price": "0.21", "size": "123.8", "side": "BUY", "hash": "1bab0f17d7b9bf64c79aec78a37b2f7553f19d5a", "best_bid": "0.67", "best_ask": "0.68"}, {"asset_id": "54160287404732698543970249280129195630418658913727451612951061485607934781689", "price": "0.79", "size": "123.8", "side": "SELL", "hash": "6a78e9d0e50aa464b989f05e98a6af7fffa09f90", "best_bid": "0.32", "best_ask": "0.33"}], "timestamp": "1769384158069", "event_type": "price_change"}}
{"_local_timestamp": "2026-01-25T23:35:58.269473+00:00", "data": {"market": "0xa7e1a7561e1866aa345c0be640df952e1d41decf0a5c4bb571f077142fed025d", "price_changes": [{"asset_id": "76541116657039469088410437026264202489719024425044998810802876826622732617598", "price": "0.35", "size": "0", "side": "BUY", "hash": "10474550c827ba8e2b53d57a8dc89241d325c26d", "best_bid": "0.75", "best_ask": "0.76"}, {"asset_id": "115679112821476364794223653408101005434638325681840410280875053954587147234523", "price": "0.65", "size": "0", "side": "SELL", "hash": "2459c4987b96c2e5f06ba29b7a1e14311aed84e0", "best_bid": "0.24", "best_ask": "0.25"}], "timestamp": "1769384158196", "event_type": "price_change"}}
{"_local_timestamp": "2026-01-25T23:35:58.422080+00:00", "data": {"market": "0xa7e1a7561e1866aa345c0be640df952e1d41decf0a5c4bb571f077142fed025d", "price_changes": [{"asset_id": "76541116657039469088410437026264202489719024425044998810802876826622732617598", "price": "0.35", "size": "20", "side": "BUY", "hash": "10ff69220f86b1bc9cdcec9519fd0a4a6e02efca", "best_bid": "0.75", "best_ask": "0.76"}, {"asset_id": "115679112821476364794223653408101005434638325681840410280875053954587147234523", "price": "0.65", "size": "20", "side": "SELL", "hash": "12047a255d2d04e348e31350dad9ff6429dc5561", "best_bid": "0.24", "best_ask": "0.25"}], "timestamp": "1769384158355", "event_type": "price_change"}}
{"_local_timestamp": "2026-01-25T23:35:58.566513+00:00", "data": {"market": "0x892231e7fd3ac31a3b321002f909e011180b709af074808908d27a2a32a7b546", "price_changes": [{"asset_id": "64317448978406417981854076458164286249844965670717306181829295801409919530695", "price": "0.48", "size": "0", "side": "BUY", "hash": "30b24954ab515cafbbf4c0ebb13c699ae72e7bd2", "best_bid": "0.92", "best_ask": "0.93"}, {"asset_id": "89791260670398307279783201184852534466650260912467648915456704380491810882664", "price": "0.52", "size": "0", "side": "SELL", "hash": "cb81848a37a314f75ff0dc563050b673b2e99312", "best_bid": "0.07", "best_ask": "0.08"}], "timestamp": "1769384158499", "event_type": "price_change"}}
{"_local_timestamp": "2026-01-25T23:35:58.694754+00:00", "data": {"market": "0x892231e7fd3ac31a3b321002f909e011180b709af074808908d27a2a32a7b546", "price_changes": [{"asset_id": "64317448978406417981854076458164286249844965670717306181829295801409919530695", "price": "0.5", "size": "1167", "side": "BUY", "hash": "f10f8962d5ed93eb27003d1ac306d0f2bdc5aa46", "best_bid": "0.92", "best_ask": "0.93"}, {"asset_id": "89791260670398307279783201184852534466650260912467648915456704380491810882664", "price": "0.5", "size": "1167", "side": "SELL", "hash": "67614ed08d52d49cf414470574e8f62316d2b5d4", "best_bid": "0.07", "best_ask": "0.08"}], "timestamp": "1769384158621", "event_type": "price_change"}}
{"_local_timestamp": "2026-01-25T23:35:58.856422+00:00", "data": {"market": "0x892231e7fd3ac31a3b321002f909e011180b709af074808908d27a2a32a7b546", "price_changes": [{"asset_id": "64317448978406417981854076458164286249844965670717306181829295801409919530695", "price": "0.49", "size": "0", "side": "BUY", "hash": "ebb42aba76c7f192538b9e1595342ba22da27b90", "best_bid": "0.92", "best_ask": "0.93"}, {"asset_id": "89791260670398307279783201184852534466650260912467648915456704380491810882664", "price": "0.51", "size": "0", "side": "SELL", "hash": "1906881fc6a5787b87f2304034ca0456c57a36b7", "best_bid": "0.07", "best_ask": "0.08"}], "timestamp": "1769384158783", "event_type": "price_change"}}
{"_local_timestamp": "2026-01-25T23:35:58.921642+00:00", "data": {"market": "0x892231e7fd3ac31a3b321002f909e011180b709af074808908d27a2a32a7b546", "price_changes": [{"asset_id": "64317448978406417981854076458164286249844965670717306181829295801409919530695", "price": "0.51", "size": "800", "side": "BUY", "hash": "3cad9f3a3f8a1265de450126ef1208341aec6af0", "best_bid": "0.92", "best_ask": "0.93"}, {"asset_id": "89791260670398307279783201184852534466650260912467648915456704380491810882664", "price": "0.49", "size": "800", "side": "SELL", "hash": "0c84026e9593e256924d80fd5ecd5d9b90a1a267", "best_bid": "0.07", "best_ask": "0.08"}], "timestamp": "1769384158850", "event_type": "price_change"}}
{"_local_timestamp": "2026-01-25T23:36:00.914575+00:00", "data": {"market": "0x8253528e603b5cabb8ab45d1e1209bda57aa2a9f6f0d61aba7ad0a38147a86ee", "price_changes": [{"asset_id": "17667700649974143765639286018245659141526847671421069760676398956961689778433", "price": "0.19", "size": "2315.64", "side": "BUY", "hash": "2d33884c2970835be0c4dac86ec966d56d41e270", "best_bid": "0.67", "best_ask": "0.68"}, {"asset_id": "54160287404732698543970249280129195630418658913727451612951061485607934781689", "price": "0.81", "size": "2315.64", "side": "SELL", "hash": "cd1f5e92b1b98530b6c9f06bba2fde12519aa2c4", "best_bid": "0.32", "best_ask": "0.33"}], "timestamp": "1769384160848", "event_type": "price_change"}}
{"_local_timestamp": "2026-01-25T23:36:02.002657+00:00", "data": {"market": "0xa7e1a7561e1866aa345c0be640df952e1d41decf0a5c4bb571f077142fed025d", "price_changes": [{"asset_id": "76541116657039469088410437026264202489719024425044998810802876826622732617598", "price": "0.21", "size": "1998", "side": "BUY", "hash": "8555e03531463e0226182a64f05847b9ddf61fac", "best_bid": "0.75", "best_ask": "0.76"}, {"asset_id": "115679112821476364794223653408101005434638325681840410280875053954587147234523", "price": "0.79", "size": "1998", "side": "SELL", "hash": "4cad005bcae339672a86d77d3a192ca4b9dd1ae3", "best_bid": "0.24", "best_ask": "0.25"}], "timestamp": "1769384161927", "event_type": "price_change"}}
{"_local_timestamp": "2026-01-25T23:36:04.068629+00:00", "data": {"market": "0x8253528e603b5cabb8ab45d1e1209bda57aa2a9f6f0d61aba7ad0a38147a86ee", "price_changes": [{"asset_id": "54160287404732698543970249280129195630418658913727451612951061485607934781689", "price": "0.25", "size": "0", "side": "BUY", "hash": "1655d2afd9b0ac0d2799c03137b309209c8e2628", "best_bid": "0.32", "best_ask": "0.33"}, {"asset_id": "17667700649974143765639286018245659141526847671421069760676398956961689778433", "price": "0.75", "size": "0", "side": "SELL", "hash": "e0ff0120d9ece168f248780fc4ed839552ebf3b2", "best_bid": "0.67", "best_ask": "0.68"}], "timestamp": "1769384164000", "event_type": "price_change"}}
{"_local_timestamp": "2026-01-25T23:36:05.037390+00:00", "data": {"market": "0x8253528e603b5cabb8ab45d1e1209bda57aa2a9f6f0d61aba7ad0a38147a86ee", "price_changes": [{"asset_id": "54160287404732698543970249280129195630418658913727451612951061485607934781689", "price": "0.25", "size": "20", "side": "BUY", "hash": "79dbb4c3638f07241341edfbbd3703b6e31b4057", "best_bid": "0.32", "best_ask": "0.33"}, {"asset_id": "17667700649974143765639286018245659141526847671421069760676398956961689778433", "price": "0.75", "size": "20", "side": "SELL", "hash": "8a25916ee24fd2bccb64fccdeb2d1ee6524bd521", "best_bid": "0.67", "best_ask": "0.68"}], "timestamp": "1769384164962", "event_type": "price_change"}}
{"_local_timestamp": "2026-01-25T23:36:14.135701+00:00", "data": {"market": "0xa7e1a7561e1866aa345c0be640df952e1d41decf0a5c4bb571f077142fed025d", "price_changes": [{"asset_id": "115679112821476364794223653408101005434638325681840410280875053954587147234523", "price": "0.24", "size": "1533.04", "side": "BUY", "hash": "8ff577a0c6f24a320ca04320004b26bf1a843655", "best_bid": "0.24", "best_ask": "0.25"}, {"asset_id": "76541116657039469088410437026264202489719024425044998810802876826622732617598", "price": "0.76", "size": "1533.04", "side": "SELL", "hash": "1008b38d5ff59b34d6f4ca1edfaf99abce80266a", "best_bid": "0.75", "best_ask": "0.76"}], "timestamp": "1769384174065", "event_type": "price_change"}}
{"_local_timestamp": "2026-01-25T23:36:14.152646+00:00", "data": {"market": "0xa7e1a7561e1866aa345c0be640df952e1d41decf0a5c4bb571f077142fed025d", "price_changes": [{"asset_id": "115679112821476364794223653408101005434638325681840410280875053954587147234523", "price": "0.24", "size": "1517.98", "side": "BUY", "hash": "859e2301c97b785ac1aac61b6c7b6f0047bbfc2a", "best_bid": "0.24", "best_ask": "0.25"}, {"asset_id": "76541116657039469088410437026264202489719024425044998810802876826622732617598", "price": "0.76", "size": "1517.98", "side": "SELL", "hash": "31bf40de64550e2170e3c6674045a5475157801b", "best_bid": "0.75", "best_ask": "0.76"}], "timestamp": "1769384174078", "event_type": "price_change"}}
{"_local_timestamp": "2026-01-25T23:36:14.310144+00:00", "data": {"market": "0x892231e7fd3ac31a3b321002f909e011180b709af074808908d27a2a32a7b546", "price_changes": [{"asset_id": "64317448978406417981854076458164286249844965670717306181829295801409919530695", "price": "0.5", "size": "819", "side": "BUY", "hash": "344989273e211d70b4d7f5543785c8a3dc67b4a2", "best_bid": "0.92", "best_ask": "0.93"}, {"asset_id": "89791260670398307279783201184852534466650260912467648915456704380491810882664", "price": "0.5", "size": "819", "side": "SELL", "hash": "ac4b1f1ab4d0313f4f7f749d20078ea9388c72f4", "best_bid": "0.07", "best_ask": "0.08"}], "timestamp": "1769384174187", "event_type": "price_change"}}
{"_local_timestamp": "2026-01-25T23:36:14.482123+00:00", "data": {"market": "0x892231e7fd3ac31a3b321002f909e011180b709af074808908d27a2a32a7b546", "price_changes": [{"asset_id": "64317448978406417981854076458164286249844965670717306181829295801409919530695", "price": "0.83", "size": "20", "side": "BUY", "hash": "78c73c2cadb163fad860f29b6809f8c72f17e0fe", "best_bid": "0.92", "best_ask": "0.93"}, {"asset_id": "89791260670398307279783201184852534466650260912467648915456704380491810882664", "price": "0.17", "size": "20", "side": "SELL", "hash": "3206b67a24878da62f388105395012ce8a27a8f9", "best_bid": "0.07", "best_ask": "0.08"}], "timestamp": "1769384174408", "event_type": "price_change"}}
{"_local_timestamp": "2026-01-25T23:36:14.483003+00:00", "data": {"market": "0x892231e7fd3ac31a3b321002f909e011180b709af074808908d27a2a32a7b546", "price_changes": [{"asset_id": "64317448978406417981854076458164286249844965670717306181829295801409919530695", "price": "0.52", "size": "323", "side": "BUY", "hash": "12406a527eeb66f48e00e7171fa419e445196319", "best_bid": "0.92", "best_ask": "0.93"}, {"asset_id": "89791260670398307279783201184852534466650260912467648915456704380491810882664", "price": "0.48", "size": "323", "side": "SELL", "hash": "df3205f56530d7788f33a9d2c94fb9a24f766ed4", "best_bid": "0.07", "best_ask": "0.08"}], "timestamp": "1769384174411", "event_type": "price_change"}}
{"_local_timestamp": "2026-01-25T23:36:14.484887+00:00", "data": {"market": "0x892231e7fd3ac31a3b321002f909e011180b709af074808908d27a2a32a7b546", "price_changes": [{"asset_id": "64317448978406417981854076458164286249844965670717306181829295801409919530695", "price": "0.83", "size": "45", "side": "BUY", "hash": "2e0e249f5d0b8f6c751c78403c5118925ca71c39", "best_bid": "0.92", "best_ask": "0.93"}, {"asset_id": "89791260670398307279783201184852534466650260912467648915456704380491810882664", "price": "0.17", "size": "45", "side": "SELL", "hash": "6ecb88caa29df8709bec291cc094775821205510", "best_bid": "0.07", "best_ask": "0.08"}], "timestamp": "1769384174414", "event_type": "price_change"}}
{"_local_timestamp": "2026-01-25T23:36:14.532186+00:00", "data": {"market": "0x892231e7fd3ac31a3b321002f909e011180b709af074808908d27a2a32a7b546", "price_changes": [{"asset_id": "64317448978406417981854076458164286249844965670717306181829295801409919530695", "price": "0.5", "size": "60", "side": "BUY", "hash": "2c5d4c3519801dad28f1675ad914a552a73e7fed", "best_bid": "0.92", "best_ask": "0.93"}, {"asset_id": "89791260670398307279783201184852534466650260912467648915456704380491810882664", "price": "0.5", "size": "60", "side": "SELL", "hash": "aea9d0c9e5d57f626134a57a64755d41e9e3657d", "best_bid": "0.07", "best_ask": "0.08"}], "timestamp": "1769384174464", "event_type": "price_change"}}
{"_local_timestamp": "2026-01-25T23:36:14.611279+00:00", "data": {"market": "0x892231e7fd3ac31a3b321002f909e011180b709af074808908d27a2a32a7b546", "price_changes": [{"asset_id": "64317448978406417981854076458164286249844965670717306181829295801409919530695", "price": "0.52", "size": "1106", "side": "BUY", "hash": "5ca1c8d032641e7418555302c8368d000b761e51", "best_bid": "0.92", "best_ask": "0.93"}, {"asset_id": "89791260670398307279783201184852534466650260912467648915456704380491810882664", "price": "0.48", "size": "1106", "side": "SELL", "hash": "22409a46855a29b34a3e7d28c0b454cb6d0209b5", "best_bid": "0.07", "best_ask": "0.08"}], "timestamp": "1769384174539", "event_type": "price_change"}}
{"_local_timestamp": "2026-01-25T23:36:14.667161+00:00", "data": {"market": "0x892231e7fd3ac31a3b321002f909e011180b709af074808908d27a2a32a7b546", "price_changes": [{"asset_id": "64317448978406417981854076458164286249844965670717306181829295801409919530695", "price": "0.82", "size": "0", "side": "BUY", "hash": "170d85d9f6b71448abddd27827b7379d61e1ef91", "best_bid": "0.92", "best_ask": "0.93"}, {"asset_id": "89791260670398307279783201184852534466650260912467648915456704380491810882664", "price": "0.18", "size": "0", "side": "SELL", "hash": "f0e537366ede0d4589be5a0df8186ce4957cf1c2", "best_bid": "0.07", "best_ask": "0.08"}], "timestamp": "1769384174596", "event_type": "price_change"}}
{"_local_timestamp": "2026-01-25T23:36:14.700167+00:00", "data": {"market": "0x892231e7fd3ac31a3b321002f909e011180b709af074808908d27a2a32a7b546", "price_changes": [{"asset_id": "64317448978406417981854076458164286249844965670717306181829295801409919530695", "price": "0.84", "size": "20", "side": "BUY", "hash": "3fbf4e36208b7979874456fe45fbd68b26334ded", "best_bid": "0.92", "best_ask": "0.93"}, {"asset_id": "89791260670398307279783201184852534466650260912467648915456704380491810882664", "price": "0.16", "size": "20", "side": "SELL", "hash": "e0510db31fe165c834ee458c10d481a30f509ba0", "best_bid": "0.07", "best_ask": "0.08"}], "timestamp": "1769384174629", "event_type": "price_change"}}
{"_local_timestamp": "2026-01-25T23:36:14.839263+00:00", "data": {"market": "0x892231e7fd3ac31a3b321002f909e011180b709af074808908d27a2a32a7b546", "price_changes": [{"asset_id": "64317448978406417981854076458164286249844965670717306181829295801409919530695", "price": "0.51", "size": "0", "side": "BUY", "hash": "76baacdb07328dc92e157f4da16fc42742c7ad27", "best_bid": "0.92", "best_ask": "0.93"}, {"asset_id": "89791260670398307279783201184852534466650260912467648915456704380491810882664", "price": "0.49", "size": "0", "side": "SELL", "hash": "438e1832133b22fb01910ae81afdb8c3712c13c4", "best_bid": "0.07", "best_ask": "0.08"}], "timestamp": "1769384174770", "event_type": "price_change"}}
{"_local_timestamp": "2026-01-25T23:36:14.924837+00:00", "data": {"market": "0x892231e7fd3ac31a3b321002f909e011180b709af074808908d27a2a32a7b546", "price_changes": [{"asset_id": "64317448978406417981854076458164286249844965670717306181829295801409919530695", "price": "0.53", "size": "638", "side": "BUY", "hash": "451bb0604794321166ff2163734b1c02788eea8f", "best_bid": "0.92", "best_ask": "0.93"}, {"asset_id": "89791260670398307279783201184852534466650260912467648915456704380491810882664", "price": "0.47", "size": "638", "side": "SELL", "hash": "53b53a3d2e3b8484fe58f304dcba89ff6a9b06a7", "best_bid": "0.07", "best_ask": "0.08"}], "timestamp": "1769384174853", "event_type": "price_change"}}
{"_local_timestamp": "2026-01-25T23:36:15.050555+00:00", "data": {"market": "0xb83cf6cdfe9973219d19fb70f863ec9b713a313609db51839eeb34f7acf275ad", "price_changes": [{"asset_id": "31464892460544164986335006004080412271316454788455556340430054002451576894443", "price": "0.443", "size": "0", "side": "BUY", "hash": "793abc8f336364f2c7a3f51aa4a824fa9a47f6da", "best_bid": "0.988", "best_ask": "0.99"}, {"asset_id": "101837527728017183708561627155221790735931039980484062356872287158739556672077", "price": "0.557", "size": "0", "side": "SELL", "hash": "ddb6463472d5c674cc5808c9bf3cc44b39621034", "best_bid": "0.01", "best_ask": "0.012"}], "timestamp": "1769384174981", "event_type": "price_change"}}
{"_local_timestamp": "2026-01-25T23:36:15.357988+00:00", "data": {"market": "0xb83cf6cdfe9973219d19fb70f863ec9b713a313609db51839eeb34f7acf275ad", "price_changes": [{"asset_id": "31464892460544164986335006004080412271316454788455556340430054002451576894443", "price": "0.857", "size": "25", "side": "BUY", "hash": "d208a21e46778d026da5cfcf60af9792211dcd73", "best_bid": "0.988", "best_ask": "0.99"}, {"asset_id": "101837527728017183708561627155221790735931039980484062356872287158739556672077", "price": "0.143", "size": "25", "side": "SELL", "hash": "bed0b4816095fa1f0c3bd98c4a757bc9485d6477", "best_bid": "0.01", "best_ask": "0.012"}], "timestamp": "1769384175291", "event_type": "price_change"}}
{"_local_timestamp": "2026-01-25T23:36:15.446237+00:00", "data": {"market": "0xb83cf6cdfe9973219d19fb70f863ec9b713a313609db51839eeb34f7acf275ad", "price_changes": [{"asset_id": "31464892460544164986335006004080412271316454788455556340430054002451576894443", "price": "0.855", "size": "25", "side": "BUY", "hash": "4f943856fcb95d35cfbec7fcbdef8060668c669e", "best_bid": "0.988", "best_ask": "0.99"}, {"asset_id": "101837527728017183708561627155221790735931039980484062356872287158739556672077", "price": "0.145", "size": "25", "side": "SELL", "hash": "4df00035c8ba510ccf9d715b7dbd5339e1b4df29", "best_bid": "0.01", "best_ask": "0.012"}], "timestamp": "1769384175377", "event_type": "price_change"}}
{"_local_timestamp": "2026-01-25T23:36:15.563497+00:00", "data": {"market": "0xb83cf6cdfe9973219d19fb70f863ec9b713a313609db51839eeb34f7acf275ad", "price_changes": [{"asset_id": "31464892460544164986335006004080412271316454788455556340430054002451576894443", "price": "0.442", "size": "20", "side": "BUY", "hash": "86d81a3cd02f051d77d56baa31fbd3e42f87b06e", "best_bid": "0.988", "best_ask": "0.99"}, {"asset_id": "101837527728017183708561627155221790735931039980484062356872287158739556672077", "price": "0.558", "size": "20", "side": "SELL", "hash": "da2fb7bbde650db1562d3561062a0129c083fb1d", "best_bid": "0.01", "best_ask": "0.012"}], "timestamp": "1769384175475", "event_type": "price_change"}}
{"_local_timestamp": "2026-01-25T23:36:15.639959+00:00", "data": {"market": "0xb83cf6cdfe9973219d19fb70f863ec9b713a313609db51839eeb34f7acf275ad", "price_changes": [{"asset_id": "31464892460544164986335006004080412271316454788455556340430054002451576894443", "price": "0.856", "size": "0", "side": "BUY", "hash": "a799eae8e101ae39c131a89f4e22d565eed2dfb3", "best_bid": "0.988", "best_ask": "0.99"}, {"asset_id": "101837527728017183708561627155221790735931039980484062356872287158739556672077", "price": "0.144", "size": "0", "side": "SELL", "hash": "c0b5254c4418bb556ee3da9d791f355df26f7c64", "best_bid": "0.01", "best_ask": "0.012"}], "timestamp": "1769384175569", "event_type": "price_change"}}
{"_local_timestamp": "2026-01-25T23:36:15.667887+00:00", "data": {"market": "0xb83cf6cdfe9973219d19fb70f863ec9b713a313609db51839eeb34f7acf275ad", "price_changes": [{"asset_id": "31464892460544164986335006004080412271316454788455556340430054002451576894443", "price": "0.858", "size": "20", "side": "BUY", "hash": "7017cf882b386345c023c416766172d76f24a2c1", "best_bid": "0.988", "best_ask": "0.99"}, {"asset_id": "101837527728017183708561627155221790735931039980484062356872287158739556672077", "price": "0.142", "size": "20", "side": "SELL", "hash": "e6584db09129e4335c6d85ca311e60cc2f3f1418", "best_bid": "0.01", "best_ask": "0.012"}], "timestamp": "1769384175601", "event_type": "price_change"}}
{"_local_timestamp": "2026-01-25T23:36:16.970125+00:00", "data": {"market": "0xa7e1a7561e1866aa345c0be640df952e1d41decf0a5c4bb571f077142fed025d", "price_changes": [{"asset_id": "76541116657039469088410437026264202489719024425044998810802876826622732617598", "price": "0.17", "size": "0", "side": "BUY", "hash": "b9d19b359aa7cb891cb878440333607457d37f41", "best_bid": "0.75", "best_ask": "0.76"}, {"asset_id": "115679112821476364794223653408101005434638325681840410280875053954587147234523", "price": "0.83", "size": "0", "side": "SELL", "hash": "0df7ccde4703ab21d55b34242cb799442ddb1229", "best_bid": "0.24", "best_ask": "0.25"}], "timestamp": "1769384176901", "event_type": "price_change"}}
{"_local_timestamp": "2026-01-25T23:36:17.370773+00:00", "data": {"market": "0xa7e1a7561e1866aa345c0be640df952e1d41decf0a5c4bb571f077142fed025d", "price_changes": [{"asset_id": "76541116657039469088410437026264202489719024425044998810802876826622732617598", "price": "0.11", "size": "684.09", "side": "BUY", "hash": "93ba21d3429d5f27065854b5fc414300e6785618", "best_bid": "0.75", "best_ask": "0.76"}, {"asset_id": "115679112821476364794223653408101005434638325681840410280875053954587147234523", "price": "0.89", "size": "684.09", "side": "SELL", "hash": "6157530d977e840469475b218829708144e78a7b", "best_bid": "0.24", "best_ask": "0.25"}], "timestamp": "1769384177301", "event_type": "price_change"}}
{"_local_timestamp": "2026-01-25T23:36:18.464126+00:00", "data": {"market": "0xa7e1a7561e1866aa345c0be640df952e1d41decf0a5c4bb571f077142fed025d", "price_changes": [{"asset_id": "76541116657039469088410437026264202489719024425044998810802876826622732617598", "price": "0.24", "size": "0", "side": "BUY", "hash": "56ad6e775433d3712375af11551d10a397d906e8", "best_bid": "0.75", "best_ask": "0.76"}, {"asset_id": "115679112821476364794223653408101005434638325681840410280875053954587147234523", "price": "0.76", "size": "0", "side": "SELL", "hash": "7a7767810a34ec329b647a466fddf82707213f11", "best_bid": "0.24", "best_ask": "0.25"}], "timestamp": "1769384178396", "event_type": "price_change"}}
{"_local_timestamp": "2026-01-25T23:36:18.514577+00:00", "data": {"market": "0xa7e1a7561e1866aa345c0be640df952e1d41decf0a5c4bb571f077142fed025d", "price_changes": [{"asset_id": "76541116657039469088410437026264202489719024425044998810802876826622732617598", "price": "0.29", "size": "6", "side": "BUY", "hash": "7a2cf4b8bfce854753f1fecb62c2113e551f8d11", "best_bid": "0.75", "best_ask": "0.76"}, {"asset_id": "115679112821476364794223653408101005434638325681840410280875053954587147234523", "price": "0.71", "size": "6", "side": "SELL", "hash": "d85e2f0c2f79b8bed9520d39f4c0c04a7fedcb15", "best_bid": "0.24", "best_ask": "0.25"}], "timestamp": "1769384178444", "event_type": "price_change"}}
{"_local_timestamp": "2026-01-25T23:36:28.324060+00:00", "data": {"market": "0xa7e1a7561e1866aa345c0be640df952e1d41decf0a5c4bb571f077142fed025d", "price_changes": [{"asset_id": "115679112821476364794223653408101005434638325681840410280875053954587147234523", "price": "0.24", "size": "1533.04", "side": "BUY", "hash": "deabca180475279a09c36e0857b36ad8d5397a18", "best_bid": "0.24", "best_ask": "0.25"}, {"asset_id": "76541116657039469088410437026264202489719024425044998810802876826622732617598", "price": "0.76", "size": "1533.04", "side": "SELL", "hash": "029272c829c8b9dc07c51cccc6e57aea81cb107d", "best_bid": "0.75", "best_ask": "0.76"}], "timestamp": "1769384188253", "event_type": "price_change"}}
{"_local_timestamp": "2026-01-25T23:36:28.324661+00:00", "data": {"market": "0xa7e1a7561e1866aa345c0be640df952e1d41decf0a5c4bb571f077142fed025d", "price_changes": [{"asset_id": "115679112821476364794223653408101005434638325681840410280875053954587147234523", "price": "0.24", "size": "1548.1", "side": "BUY", "hash": "ce8b1aea7b13fc5854bf80c4fc2c096c7cc57e17", "best_bid": "0.24", "best_ask": "0.25"}, {"asset_id": "76541116657039469088410437026264202489719024425044998810802876826622732617598", "price": "0.76", "size": "1548.1", "side": "SELL", "hash": "dfd13419ca27bb961450c92a174bb43201b6cab9", "best_bid": "0.75", "best_ask": "0.76"}], "timestamp": "1769384188253", "event_type": "price_change"}}
{"_local_timestamp": "2026-01-25T23:36:28.333594+00:00", "data": {"market": "0xa7e1a7561e1866aa345c0be640df952e1d41decf0a5c4bb571f077142fed025d", "price_changes": [{"asset_id": "115679112821476364794223653408101005434638325681840410280875053954587147234523", "price": "0.24", "size": "1563.16", "side": "BUY", "hash": "9f2b5d526c64759c2cba08295bdaf5d2100b6d9e", "best_bid": "0.24", "best_ask": "0.25"}, {"asset_id": "76541116657039469088410437026264202489719024425044998810802876826622732617598", "price": "0.76", "size": "1563.16", "side": "SELL", "hash": "04d2257bb70b4367d2f8cf15fcffaad79a909f65", "best_bid": "0.75", "best_ask": "0.76"}], "timestamp": "1769384188254", "event_type": "price_change"}}
{"_local_timestamp": "2026-01-25T23:36:31.789500+00:00", "data": {"market": "0xa7e1a7561e1866aa345c0be640df952e1d41decf0a5c4bb571f077142fed025d", "price_changes": [{"asset_id": "115679112821476364794223653408101005434638325681840410280875053954587147234523", "price": "0.24", "size": "1578.22", "side": "BUY", "hash": "5b2a35a9dbebd979626de9579bb8ff4cc8a52282", "best_bid": "0.24", "best_ask": "0.25"}, {"asset_id": "76541116657039469088410437026264202489719024425044998810802876826622732617598", "price": "0.76", "size": "1578.22", "side": "SELL", "hash": "8fc503cd5523bbf48911de7de52c8c3edb488205", "best_bid": "0.75", "best_ask": "0.76"}], "timestamp": "1769384191711", "event_type": "price_change"}}
{"_local_timestamp": "2026-01-25T23:36:36.912815+00:00", "data": {"market": "0x8253528e603b5cabb8ab45d1e1209bda57aa2a9f6f0d61aba7ad0a38147a86ee", "price_changes": [{"asset_id": "17667700649974143765639286018245659141526847671421069760676398956961689778433", "price": "0.14", "size": "553.57", "side": "BUY", "hash": "b44faa89ae4df4f1063b51702cf09373ce5c740f", "best_bid": "0.67", "best_ask": "0.68"}, {"asset_id": "54160287404732698543970249280129195630418658913727451612951061485607934781689", "price": "0.86", "size": "553.57", "side": "SELL", "hash": "a5e120ca6b5b2f04310779459004c652139edc23", "best_bid": "0.32", "best_ask": "0.33"}], "timestamp": "1769384196844", "event_type": "price_change"}}
{"_local_timestamp": "2026-01-25T23:36:37.114892+00:00", "data": {"market": "0x892231e7fd3ac31a3b321002f909e011180b709af074808908d27a2a32a7b546", "price_changes": [{"asset_id": "64317448978406417981854076458164286249844965670717306181829295801409919530695", "price": "0.92", "size": "13", "side": "BUY", "hash": "7c620179dd44596873b09b0a6451f90f1a168b33", "best_bid": "0.92", "best_ask": "0.93"}, {"asset_id": "89791260670398307279783201184852534466650260912467648915456704380491810882664", "price": "0.08", "size": "13", "side": "SELL", "hash": "4684fbf25b15e3d9a714ce79df54640f7993197e", "best_bid": "0.07", "best_ask": "0.08"}], "timestamp": "1769384197004", "event_type": "price_change"}}
{"_local_timestamp": "2026-01-25T23:36:37.174597+00:00", "data": {"market": "0xa7e1a7561e1866aa345c0be640df952e1d41decf0a5c4bb571f077142fed025d", "price_changes": [{"asset_id": "115679112821476364794223653408101005434638325681840410280875053954587147234523", "price": "0.17", "size": "76.47", "side": "BUY", "hash": "0129cf80af53f41957c87db08a896eb9430cb05d", "best_bid": "0.24", "best_ask": "0.25"}, {"asset_id": "76541116657039469088410437026264202489719024425044998810802876826622732617598", "price": "0.83", "size": "76.47", "side": "SELL", "hash": "d0f2206a9c2aeeb476377e6d22589edf98e2d498", "best_bid": "0.75", "best_ask": "0.76"}], "timestamp": "1769384197069", "event_type": "price_change"}}
{"_local_timestamp": "2026-01-25T23:36:37.175256+00:00", "data": {"market": "0x8253528e603b5cabb8ab45d1e1209bda57aa2a9f6f0d61aba7ad0a38147a86ee", "price_changes": [{"asset_id": "54160287404732698543970249280129195630418658913727451612951061485607934781689", "price": "0.25", "size": "0", "side": "BUY", "hash": "486ca8b681a85d99c2e3d001b86cc0c04cad7a59", "best_bid": "0.32", "best_ask": "0.33"}, {"asset_id": "17667700649974143765639286018245659141526847671421069760676398956961689778433", "price": "0.75", "size": "0", "side": "SELL", "hash": "0ee6267914a342d733bb5d38cd8c93420e38307e", "best_bid": "0.67", "best_ask": "0.68"}], "timestamp": "1769384197069", "event_type": "price_change"}}
{"_local_timestamp": "2026-01-25T23:36:37.175920+00:00", "data": {"market": "0xff8bf331f7ddbdd2e92e27dcd273612ec45fefde3cf70039c4f043eaec0000c6", "price_changes": [{"asset_id": "60105600458079862676305161094044862147301593956294543970688990037138503709415", "price": "0.29", "size": "306.57", "side": "BUY", "hash": "2e0eaf9984062d0467af8f7f2a3105e9aebfa7ff", "best_bid": "0.36", "best_ask": "0.37"}, {"asset_id": "65943623919755331891504362129239742473111951663283351342808117545053994127220", "price": "0.71", "size": "306.57", "side": "SELL", "hash": "c5b8e4f1f1abd7e0591f6c5e159a12b840b032e6", "best_bid": "0.63", "best_ask": "0.64"}], "timestamp": "1769384197069", "event_type": "price_change"}}
{"_local_timestamp": "2026-01-25T23:36:37.176396+00:00", "data": {"market": "0x892231e7fd3ac31a3b321002f909e011180b709af074808908d27a2a32a7b546", "price_changes": [{"asset_id": "64317448978406417981854076458164286249844965670717306181829295801409919530695", "price": "0.92", "size": "33", "side": "BUY", "hash": "dd2c3ba8adda8bbbe4c99654bccaa5e72dc45a56", "best_bid": "0.92", "best_ask": "0.93"}, {"asset_id": "89791260670398307279783201184852534466650260912467648915456704380491810882664", "price": "0.08", "size": "33", "side": "SELL", "hash": "80c0f5b91fa334a7f991886680757082f690c208", "best_bid": "0.07", "best_ask": "0.08"}], "timestamp": "1769384197090", "event_type": "price_change"}}
{"_local_timestamp": "2026-01-25T23:36:37.196002+00:00", "data": {"market": "0x8253528e603b5cabb8ab45d1e1209bda57aa2a9f6f0d61aba7ad0a38147a86ee", "price_changes": [{"asset_id": "17667700649974143765639286018245659141526847671421069760676398956961689778433", "price": "0.19", "size": "2365.64", "side": "BUY", "hash": "688a0f03aca4014d8b7d3c250dca5c6034cd5239", "best_bid": "0.67", "best_ask": "0.68"}, {"asset_id": "54160287404732698543970249280129195630418658913727451612951061485607934781689", "price": "0.81", "size": "2365.64", "side": "SELL", "hash": "81b0b68fbc8df374f8e9e6a71ab443a436d5a78d", "best_bid": "0.32", "best_ask": "0.33"}], "timestamp": "1769384197120", "event_type": "price_change"}}
{"_local_timestamp": "2026-01-25T23:36:37.206713+00:00", "data": {"market": "0xa7e1a7561e1866aa345c0be640df952e1d41decf0a5c4bb571f077142fed025d", "price_changes": [{"asset_id": "115679112821476364794223653408101005434638325681840410280875053954587147234523", "price": "0.17", "size": "96.47", "side": "BUY", "hash": "0e939fbf418ab47e26c5bc3da526b973207d8e1e", "best_bid": "0.24", "best_ask": "0.25"}, {"asset_id": "76541116657039469088410437026264202489719024425044998810802876826622732617598", "price": "0.83", "size": "96.47", "side": "SELL", "hash": "bdb42e7692179d93a8037228c78c172f1c2059ea", "best_bid": "0.75", "best_ask": "0.76"}], "timestamp": "1769384197127", "event_type": "price_change"}}
{"_local_timestamp": "2026-01-25T23:36:37.216583+00:00", "data": {"market": "0x8253528e603b5cabb8ab45d1e1209bda57aa2a9f6f0d61aba7ad0a38147a86ee", "price_changes": [{"asset_id": "54160287404732698543970249280129195630418658913727451612951061485607934781689", "price": "0.25", "size": "20", "side": "BUY", "hash": "47ce05f234a394c12ff7f886bc93210e73f74cf1", "best_bid": "0.32", "best_ask": "0.33"}, {"asset_id": "17667700649974143765639286018245659141526847671421069760676398956961689778433", "price": "0.75", "size": "20", "side": "SELL", "hash": "81bebcdc8301ea67578435150ae6e256e755037e", "best_bid": "0.67", "best_ask": "0.68"}], "timestamp": "1769384197149", "event_type": "price_change"}}
{"_local_timestamp": "2026-01-25T23:36:37.239020+00:00", "data": {"market": "0xff8bf331f7ddbdd2e92e27dcd273612ec45fefde3cf70039c4f043eaec0000c6", "price_changes": [{"asset_id": "60105600458079862676305161094044862147301593956294543970688990037138503709415", "price": "0.29", "size": "326.57", "side": "BUY", "hash": "2ee84b64af09c57488126c5072453137b31d5013", "best_bid": "0.36", "best_ask": "0.37"}, {"asset_id": "65943623919755331891504362129239742473111951663283351342808117545053994127220", "price": "0.71", "size": "326.57", "side": "SELL", "hash": "fdccde264a1cd42c2acb904686159c090cff8815", "best_bid": "0.63", "best_ask": "0.64"}], "timestamp": "1769384197171", "event_type": "price_change"}}
{"_local_timestamp": "2026-01-25T23:36:55.140250+00:00", "data": {"market": "0xa7e1a7561e1866aa345c0be640df952e1d41decf0a5c4bb571f077142fed025d", "price_changes": [{"asset_id": "76541116657039469088410437026264202489719024425044998810802876826622732617598", "price": "0.27", "size": "100", "side": "BUY", "hash": "4680271451fc0cf8435b2944a6f4816106f3a431", "best_bid": "0.75", "best_ask": "0.76"}, {"asset_id": "115679112821476364794223653408101005434638325681840410280875053954587147234523", "price": "0.73", "size": "100", "side": "SELL", "hash": "02bc75b1fd8e8fefe5bf143fbef96e1fd341e5fd", "best_bid": "0.24", "best_ask": "0.25"}], "timestamp": "1769384215016", "event_type": "price_change"}}
{"_local_timestamp": "2026-01-25T23:36:55.153823+00:00", "data": {"market": "0x8253528e603b5cabb8ab45d1e1209bda57aa2a9f6f0d61aba7ad0a38147a86ee", "price_changes": [{"asset_id": "17667700649974143765639286018245659141526847671421069760676398956961689778433", "price": "0.18", "size": "0", "side": "BUY", "hash": "ff43af8fed95999b46083eaeb3b8019db20d6b75", "best_bid": "0.67", "best_ask": "0.68"}, {"asset_id": "54160287404732698543970249280129195630418658913727451612951061485607934781689", "price": "0.82", "size": "0", "side": "SELL", "hash": "329fffc20e3cc7541eba5ca487b84e6f351df8df", "best_bid": "0.32", "best_ask": "0.33"}], "timestamp": "1769384215016", "event_type": "price_change"}}
{"_local_timestamp": "2026-01-25T23:36:55.165065+00:00", "data": {"market": "0x8253528e603b5cabb8ab45d1e1209bda57aa2a9f6f0d61aba7ad0a38147a86ee", "price_changes": [{"asset_id": "17667700649974143765639286018245659141526847671421069760676398956961689778433", "price": "0.22", "size": "300", "side": "BUY", "hash": "9ae8baf9398737b3d3f01a6c66ec8d478d89ad4a", "best_bid": "0.67", "best_ask": "0.68"}, {"asset_id": "54160287404732698543970249280129195630418658913727451612951061485607934781689", "price": "0.78", "size": "300", "side": "SELL", "hash": "bce38c35d3dd34698dd586b110b799669cc3299e", "best_bid": "0.32", "best_ask": "0.33"}], "timestamp": "1769384215022", "event_type": "price_change"}}
{"_local_timestamp": "2026-01-25T23:36:55.877095+00:00", "data": {"market": "0x8253528e603b5cabb8ab45d1e1209bda57aa2a9f6f0d61aba7ad0a38147a86ee", "price_changes": [{"asset_id": "17667700649974143765639286018245659141526847671421069760676398956961689778433", "price": "0.17", "size": "314.7", "side": "BUY", "hash": "2eca11cbdf7135d763039ef8c5e0a110d0d9a9e0", "best_bid": "0.67", "best_ask": "0.68"}, {"asset_id": "54160287404732698543970249280129195630418658913727451612951061485607934781689", "price": "0.83", "size": "314.7", "side": "SELL", "hash": "2656bb2393115bc77b92385c8eabe2bf00aec89d", "best_bid": "0.32", "best_ask": "0.33"}], "timestamp": "1769384215640", "event_type": "price_change"}}
{"_local_timestamp": "2026-01-25T23:36:55.881270+00:00", "data": {"market": "0xa7e1a7561e1866aa345c0be640df952e1d41decf0a5c4bb571f077142fed025d", "price_changes": [{"asset_id": "76541116657039469088410437026264202489719024425044998810802876826622732617598", "price": "0.28", "size": "1312", "side": "BUY", "hash": "55dcd405e70af305b0bcf1f39d4661083945199e", "best_bid": "0.75", "best_ask": "0.76"}, {"asset_id": "115679112821476364794223653408101005434638325681840410280875053954587147234523", "price": "0.72", "size": "1312", "side": "SELL", "hash": "a8c831c09819d654959a801cd170ca2ae4ddefe7", "best_bid": "0.24", "best_ask": "0.25"}], "timestamp": "1769384215638", "event_type": "price_change"}}
{"_local_timestamp": "2026-01-25T23:36:56.108672+00:00", "data": {"market": "0x8253528e603b5cabb8ab45d1e1209bda57aa2a9f6f0d61aba7ad0a38147a86ee", "price_changes": [{"asset_id": "17667700649974143765639286018245659141526847671421069760676398956961689778433", "price": "0.21", "size": "223.8", "side": "BUY", "hash": "5bc3663b4013dc9e40dde523e57b377d2530ab09", "best_bid": "0.67", "best_ask": "0.68"}, {"asset_id": "54160287404732698543970249280129195630418658913727451612951061485607934781689", "price": "0.79", "size": "223.8", "side": "SELL", "hash": "0ce8addf74af740bf8863b1ab970a3c986da5da3", "best_bid": "0.32", "best_ask": "0.33"}], "timestamp": "1769384215701", "event_type": "price_change"}}
{"_local_timestamp": "2026-01-25T23:36:57.615683+00:00", "data": {"market": "0x892231e7fd3ac31a3b321002f909e011180b709af074808908d27a2a32a7b546", "price_changes": [{"asset_id": "64317448978406417981854076458164286249844965670717306181829295801409919530695", "price": "0.28", "size": "92.85", "side": "BUY", "hash": "65bfe08bd90d63bf70c7a9c2f3f0042346b3fd28", "best_bid": "0.92", "best_ask": "0.93"}, {"asset_id": "89791260670398307279783201184852534466650260912467648915456704380491810882664", "price": "0.72", "size": "92.85", "side": "SELL", "hash": "2ffa181110f6df00d7cd3b1e657510fe7fd96489", "best_bid": "0.07", "best_ask": "0.08"}], "timestamp": "1769384217233", "event_type": "price_change"}}
{"_local_timestamp": "2026-01-25T23:36:57.730829+00:00", "data": {"market": "0xff8bf331f7ddbdd2e92e27dcd273612ec45fefde3cf70039c4f043eaec0000c6", "price_changes": [{"asset_id": "65943623919755331891504362129239742473111951663283351342808117545053994127220", "price": "0.28", "size": "900", "side": "BUY", "hash": "8aa2bebe9edecd169aba2fa82552c174443fef3f", "best_bid": "0.63", "best_ask": "0.64"}, {"asset_id": "60105600458079862676305161094044862147301593956294543970688990037138503709415", "price": "0.72", "size": "900", "side": "SELL", "hash": "bac5b325774ddcdded012500251929d0586c6c60", "best_bid": "0.36", "best_ask": "0.37"}], "timestamp": "1769384217245", "event_type": "price_change"}}
{"_local_timestamp": "2026-01-25T23:36:57.731635+00:00", "data": {"market": "0xa7e1a7561e1866aa345c0be640df952e1d41decf0a5c4bb571f077142fed025d", "price_changes": [{"asset_id": "76541116657039469088410437026264202489719024425044998810802876826622732617598", "price": "0.28", "size": "1012", "side": "BUY", "hash": "45c9fc2f15e8a5ec21e4f88b60f0d5ce158d0630", "best_bid": "0.75", "best_ask": "0.76"}, {"asset_id": "115679112821476364794223653408101005434638325681840410280875053954587147234523", "price": "0.72", "size": "1012", "side": "SELL", "hash": "73b71160fe6702addb75a0c453ad00496969ffc9", "best_bid": "0.24", "best_ask": "0.25"}], "timestamp": "1769384217245", "event_type": "price_change"}}
{"_local_timestamp": "2026-01-25T23:36:57.830139+00:00", "data": {"market": "0xff8bf331f7ddbdd2e92e27dcd273612ec45fefde3cf70039c4f043eaec0000c6", "price_changes": [{"asset_id": "65943623919755331891504362129239742473111951663283351342808117545053994127220", "price": "0.66", "size": "1018.42", "side": "SELL", "hash": "a8db630d9db478843d5629a3c9abce61db93cf0d", "best_bid": "0.63", "best_ask": "0.64"}, {"asset_id": "60105600458079862676305161094044862147301593956294543970688990037138503709415", "price": "0.34", "size": "1018.42", "side": "BUY", "hash": "480832b48e93a882f8d7b34a54922fd0b0b2bdb9", "best_bid": "0.36", "best_ask": "0.37"}], "timestamp": "1769384217448", "event_type": "price_change"}}
{"_local_timestamp": "2026-01-25T23:36:57.891005+00:00", "data": {"market": "0xff8bf331f7ddbdd2e92e27dcd273612ec45fefde3cf70039c4f043eaec0000c6", "price_changes": [{"asset_id": "65943623919755331891504362129239742473111951663283351342808117545053994127220", "price": "0.66", "size": "1032.42", "side": "SELL", "hash": "a9403f13f3f4b3b21df06d981b2ed28f52313fdc", "best_bid": "0.63", "best_ask": "0.64"}, {"asset_id": "60105600458079862676305161094044862147301593956294543970688990037138503709415", "price": "0.34", "size": "1032.42", "side": "BUY", "hash": "e7912304813e43eaddf0a1804d6aa16b67526fea", "best_bid": "0.36", "best_ask": "0.37"}], "timestamp": "1769384217634", "event_type": "price_change"}}
{"_local_timestamp": "2026-01-25T23:36:57.980853+00:00", "data": {"market": "0xff8bf331f7ddbdd2e92e27dcd273612ec45fefde3cf70039c4f043eaec0000c6", "price_changes": [{"asset_id": "60105600458079862676305161094044862147301593956294543970688990037138503709415", "price": "0.34", "size": "650.07", "side": "BUY", "hash": "69c303f27d26df6643665de78fb52c2a2e73ffe3", "best_bid": "0.36", "best_ask": "0.37"}, {"asset_id": "65943623919755331891504362129239742473111951663283351342808117545053994127220", "price": "0.66", "size": "650.07", "side": "SELL", "hash": "d3da84f542aa7570f6b5baf96a406fda34882134", "best_bid": "0.63", "best_ask": "0.64"}], "timestamp": "1769384217898", "event_type": "price_change"}}
{"_local_timestamp": "2026-01-25T23:36:58.396630+00:00", "data": {"market": "0x892231e7fd3ac31a3b321002f909e011180b709af074808908d27a2a32a7b546", "price_changes": [{"asset_id": "64317448978406417981854076458164286249844965670717306181829295801409919530695", "price": "0.52", "size": "323", "side": "BUY", "hash": "887b94b99d7c0df20c630c80ec14d8644afef4c7", "best_bid": "0.92", "best_ask": "0.93"}, {"asset_id": "89791260670398307279783201184852534466650260912467648915456704380491810882664", "price": "0.48", "size": "323", "side": "SELL", "hash": "e478af2a649589496f42223a1c05ca5573666f10", "best_bid": "0.07", "best_ask": "0.08"}], "timestamp": "1769384218258", "event_type": "price_change"}}
{"_local_timestamp": "2026-01-25T23:36:58.915092+00:00", "data": {"market": "0x892231e7fd3ac31a3b321002f909e011180b709af074808908d27a2a32a7b546", "price_changes": [{"asset_id": "64317448978406417981854076458164286249844965670717306181829295801409919530695", "price": "0.52", "size": "402", "side": "BUY", "hash": "00620af0245dcf0784212423bd01cb0b517ce186", "best_bid": "0.92", "best_ask": "0.93"}, {"asset_id": "89791260670398307279783201184852534466650260912467648915456704380491810882664", "price": "0.48", "size": "402", "side": "SELL", "hash": "924837745e74a1017a235b3b34ded0730b2791c1", "best_bid": "0.07", "best_ask": "0.08"}], "timestamp": "1769384218677", "event_type": "price_change"}}
{"_local_timestamp": "2026-01-25T23:37:13.146029+00:00", "data": {"market": "0x8253528e603b5cabb8ab45d1e1209bda57aa2a9f6f0d61aba7ad0a38147a86ee", "price_changes": [{"asset_id": "17667700649974143765639286018245659141526847671421069760676398956961689778433", "price": "0.34", "size": "925", "side": "BUY", "hash": "6a22ba461838f9de13423035bbc5f896ad784f8e", "best_bid": "0.67", "best_ask": "0.68"}, {"asset_id": "54160287404732698543970249280129195630418658913727451612951061485607934781689", "price": "0.66", "size": "925", "side": "SELL", "hash": "56d6f058122bf96a8d51f61c1ca602ce6475db43", "best_bid": "0.32", "best_ask": "0.33"}], "timestamp": "1769384233016", "event_type": "price_change"}}
{"_local_timestamp": "2026-01-25T23:37:13.162199+00:00", "data": {"market": "0x8253528e603b5cabb8ab45d1e1209bda57aa2a9f6f0d61aba7ad0a38147a86ee", "price_changes": [{"asset_id": "17667700649974143765639286018245659141526847671421069760676398956961689778433", "price": "0.19", "size": "2265.64", "side": "BUY", "hash": "6a22ba461838f9de13423035bbc5f896ad784f8e", "best_bid": "0.67", "best_ask": "0.68"}, {"asset_id": "54160287404732698543970249280129195630418658913727451612951061485607934781689", "price": "0.81", "size": "2265.64", "side": "SELL", "hash": "56d6f058122bf96a8d51f61c1ca602ce6475db43", "best_bid": "0.32", "best_ask": "0.33"}], "timestamp": "1769384233016", "event_type": "price_change"}}
{"_local_timestamp": "2026-01-25T23:37:13.163485+00:00", "data": {"market": "0xa7e1a7561e1866aa345c0be640df952e1d41decf0a5c4bb571f077142fed025d", "price_changes": [{"asset_id": "76541116657039469088410437026264202489719024425044998810802876826622732617598", "price": "0.27", "size": "50", "side": "BUY", "hash": "d662245918063eb920f2acb563739bb18d76b6c3", "best_bid": "0.75", "best_ask": "0.76"}, {"asset_id": "115679112821476364794223653408101005434638325681840410280875053954587147234523", "price": "0.73", "size": "50", "side": "SELL", "hash": "9f246577d757c607dafd2b46972ec1d851b132d8", "best_bid": "0.24", "best_ask": "0.25"}], "timestamp": "1769384233015", "event_type": "price_change"}}
{"_local_timestamp": "2026-01-25T23:37:13.164162+00:00", "data": {"market": "0xa7e1a7561e1866aa345c0be640df952e1d41decf0a5c4bb571f077142fed025d", "price_changes": [{"asset_id": "76541116657039469088410437026264202489719024425044998810802876826622732617598", "price": "0.2", "size": "205.05", "side": "BUY", "hash": "d662245918063eb920f2acb563739bb18d76b6c3", "best_bid": "0.75", "best_ask": "0.76"}, {"asset_id": "115679112821476364794223653408101005434638325681840410280875053954587147234523", "price": "0.8", "size": "205.05", "side": "SELL", "hash": "9f246577d757c607dafd2b46972ec1d851b132d8", "best_bid": "0.24", "best_ask": "0.25"}], "timestamp": "1769384233015", "event_type": "price_change"}}
{"_local_timestamp": "2026-01-25T23:37:13.484857+00:00", "data": {"market": "0x8253528e603b5cabb8ab45d1e1209bda57aa2a9f6f0d61aba7ad0a38147a86ee", "price_changes": [{"asset_id": "17667700649974143765639286018245659141526847671421069760676398956961689778433", "price": "0.17", "size": "414.7", "side": "BUY", "hash": "7117dfcd2824f3689b5b6dd5a2663a8b29184ba1", "best_bid": "0.67", "best_ask": "0.68"}, {"asset_id": "54160287404732698543970249280129195630418658913727451612951061485607934781689", "price": "0.83", "size": "414.7", "side": "SELL", "hash": "81ff8a8eebb4ef0ad36ad48389aba8839f27e79e", "best_bid": "0.32", "best_ask": "0.33"}], "timestamp": "1769384233362", "event_type": "price_change"}}
{"_local_timestamp": "2026-01-25T23:37:13.508216+00:00", "data": {"market": "0xa7e1a7561e1866aa345c0be640df952e1d41decf0a5c4bb571f077142fed025d", "price_changes": [{"asset_id": "76541116657039469088410437026264202489719024425044998810802876826622732617598", "price": "0.17", "size": "100", "side": "BUY", "hash": "046381841f2d5ba2604364cab5d7a4ff686a2589", "best_bid": "0.75", "best_ask": "0.76"}, {"asset_id": "115679112821476364794223653408101005434638325681840410280875053954587147234523", "price": "0.83", "size": "100", "side": "SELL", "hash": "51b4b75b779e1a459147a88e657ed5cf9f7c5c1b", "best_bid": "0.24", "best_ask": "0.25"}], "timestamp": "1769384233369", "event_type": "price_change"}}
{"_local_timestamp": "2026-01-25T23:37:13.548999+00:00", "data": {"market": "0x8253528e603b5cabb8ab45d1e1209bda57aa2a9f6f0d61aba7ad0a38147a86ee", "price_changes": [{"asset_id": "17667700649974143765639286018245659141526847671421069760676398956961689778433", "price": "0.21", "size": "273.8", "side": "BUY", "hash": "27f9c7725507df516e1ff00291d65c782e196598", "best_bid": "0.67", "best_ask": "0.68"}, {"asset_id": "54160287404732698543970249280129195630418658913727451612951061485607934781689", "price": "0.79", "size": "273.8", "side": "SELL", "hash": "4c6b01100f300b502fc4a22a71215511de0cdc14", "best_bid": "0.32", "best_ask": "0.33"}], "timestamp": "1769384233396", "event_type": "price_change"}}
{"_local_timestamp": "2026-01-25T23:37:13.549744+00:00", "data": {"market": "0xa7e1a7561e1866aa345c0be640df952e1d41decf0a5c4bb571f077142fed025d", "price_changes": [{"asset_id": "76541116657039469088410437026264202489719024425044998810802876826622732617598", "price": "0.28", "size": "1062", "side": "BUY", "hash": "8fb08cb20b39d7899111f54860647ef4c444ffc7", "best_bid": "0.75", "best_ask": "0.76"}, {"asset_id": "115679112821476364794223653408101005434638325681840410280875053954587147234523", "price": "0.72", "size": "1062", "side": "SELL", "hash": "7ea82540003fb52e2574d8619049df1f32700c30", "best_bid": "0.24", "best_ask": "0.25"}], "timestamp": "1769384233400", "event_type": "price_change"}}
{"_local_timestamp": "2026-01-25T23:37:20.489597+00:00", "data": {"market": "0xa7e1a7561e1866aa345c0be640df952e1d41decf0a5c4bb571f077142fed025d", "price_changes": [{"asset_id": "76541116657039469088410437026264202489719024425044998810802876826622732617598", "price": "0.29", "size": "306", "side": "BUY", "hash": "b1395980c0d6cd0204a2fb89910cae84a52fdbff", "best_bid": "0.75", "best_ask": "0.76"}, {"asset_id": "115679112821476364794223653408101005434638325681840410280875053954587147234523", "price": "0.71", "size": "306", "side": "SELL", "hash": "ff93305fac5ed2a2aaac6414b122c74da775d1fe", "best_bid": "0.24", "best_ask": "0.25"}], "timestamp": "1769384240421", "event_type": "price_change"}}
{"_local_timestamp": "2026-01-25T23:37:20.500509+00:00", "data": {"market": "0xff8bf331f7ddbdd2e92e27dcd273612ec45fefde3cf70039c4f043eaec0000c6", "price_changes": [{"asset_id": "65943623919755331891504362129239742473111951663283351342808117545053994127220", "price": "0.18", "size": "305.88", "side": "BUY", "hash": "36e7038ce1545e5cb4f87592db9ca37d135c42ae", "best_bid": "0.63", "best_ask": "0.64"}, {"asset_id": "60105600458079862676305161094044862147301593956294543970688990037138503709415", "price": "0.82", "size": "305.88", "side": "SELL", "hash": "04ef7e1dd627f62203826e87393af74c04449b2a", "best_bid": "0.36", "best_ask": "0.37"}], "timestamp": "1769384240422", "event_type": "price_change"}}
{"_local_timestamp": "2026-01-25T23:37:20.571225+00:00", "data": {"market": "0xa7e1a7561e1866aa345c0be640df952e1d41decf0a5c4bb571f077142fed025d", "price_changes": [{"asset_id": "76541116657039469088410437026264202489719024425044998810802876826622732617598", "price": "0.28", "size": "598", "side": "BUY", "hash": "2783c2efb319bbea9dbb0de55df0fc6758a4a290", "best_bid": "0.75", "best_ask": "0.76"}, {"asset_id": "115679112821476364794223653408101005434638325681840410280875053954587147234523", "price": "0.72", "size": "598", "side": "SELL", "hash": "01c2eb3c7c0be04bcc1557740605fcc5ff787fc0", "best_bid": "0.24", "best_ask": "0.25"}], "timestamp": "1769384240506", "event_type": "price_change"}}
{"_local_timestamp": "2026-01-25T23:37:20.599017+00:00", "data": {"market": "0xa7e1a7561e1866aa345c0be640df952e1d41decf0a5c4bb571f077142fed025d", "price_changes": [{"asset_id": "76541116657039469088410437026264202489719024425044998810802876826622732617598", "price": "0.28", "size": "150", "side": "BUY", "hash": "3b048840bcc471bfae6c8ae022404813427cceef", "best_bid": "0.75", "best_ask": "0.76"}, {"asset_id": "115679112821476364794223653408101005434638325681840410280875053954587147234523", "price": "0.72", "size": "150", "side": "SELL", "hash": "d387a1b8fadfdc890e4de2aa757a013f444ab85f", "best_bid": "0.24", "best_ask": "0.25"}], "timestamp": "1769384240528", "event_type": "price_change"}}
{"_local_timestamp": "2026-01-25T23:37:20.674314+00:00", "data": {"market": "0xa7e1a7561e1866aa345c0be640df952e1d41decf0a5c4bb571f077142fed025d", "price_changes": [{"asset_id": "76541116657039469088410437026264202489719024425044998810802876826622732617598", "price": "0.29", "size": "481", "side": "BUY", "hash": "2fb8321ca6e339983a6f972ad81e37a118c5e443", "best_bid": "0.75", "best_ask": "0.76"}, {"asset_id": "115679112821476364794223653408101005434638325681840410280875053954587147234523", "price": "0.71", "size": "481", "side": "SELL", "hash": "d42fbffec9bde6cf0124c5474b43c74a09b38fb1", "best_bid": "0.24", "best_ask": "0.25"}], "timestamp": "1769384240601", "event_type": "price_change"}}
{"_local_timestamp": "2026-01-25T23:37:20.732102+00:00", "data": {"market": "0xa7e1a7561e1866aa345c0be640df952e1d41decf0a5c4bb571f077142fed025d", "price_changes": [{"asset_id": "76541116657039469088410437026264202489719024425044998810802876826622732617598", "price": "0.29", "size": "650", "side": "BUY", "hash": "f11277710782b0ec2910c7aca79fefa2f041b376", "best_bid": "0.75", "best_ask": "0.76"}, {"asset_id": "115679112821476364794223653408101005434638325681840410280875053954587147234523", "price": "0.71", "size": "650", "side": "SELL", "hash": "4ea8263e74d926d65cb8667e74b97607c6a15fb8", "best_bid": "0.24", "best_ask": "0.25"}], "timestamp": "1769384240664", "event_type": "price_change"}}
{"_local_timestamp": "2026-01-25T23:37:21.688909+00:00", "data": {"market": "0x8253528e603b5cabb8ab45d1e1209bda57aa2a9f6f0d61aba7ad0a38147a86ee", "price_changes": [{"asset_id": "17667700649974143765639286018245659141526847671421069760676398956961689778433", "price": "0.64", "size": "220.99", "side": "BUY", "hash": "65cc3c01ec3728be3f72d6742624a372c2af44a7", "best_bid": "0.67", "best_ask": "0.68"}, {"asset_id": "54160287404732698543970249280129195630418658913727451612951061485607934781689", "price": "0.36", "size": "220.99", "side": "SELL", "hash": "5299c3a4610f0e0d754d52fefa562aa5c1a2e36f", "best_bid": "0.32", "best_ask": "0.33"}], "timestamp": "1769384241619", "event_type": "price_change"}}
{"_local_timestamp": "2026-01-25T23:37:29.112849+00:00", "data": {"market": "0xff8bf331f7ddbdd2e92e27dcd273612ec45fefde3cf70039c4f043eaec0000c6", "price_changes": [{"asset_id": "65943623919755331891504362129239742473111951663283351342808117545053994127220", "price": "0.18", "size": "300", "side": "BUY", "hash": "d0a079027a2c5a1d71990f4bd40914faf548ddf3", "best_bid": "0.63", "best_ask": "0.64"}, {"asset_id": "60105600458079862676305161094044862147301593956294543970688990037138503709415", "price": "0.82", "size": "300", "side": "SELL", "hash": "d17cbb7c31615e260381158568b4943b2a4c8248", "best_bid": "0.36", "best_ask": "0.37"}], "timestamp": "1769384249012", "event_type": "price_change"}}
{"_local_timestamp": "2026-01-25T23:37:29.417207+00:00", "data": {"market": "0xff8bf331f7ddbdd2e92e27dcd273612ec45fefde3cf70039c4f043eaec0000c6", "price_changes": [{"asset_id": "65943623919755331891504362129239742473111951663283351342808117545053994127220", "price": "0.19", "size": "5.57", "side": "BUY", "hash": "b3b0ba48ec1a7e99597d11224be56c9c8106fd36", "best_bid": "0.63", "best_ask": "0.64"}, {"asset_id": "60105600458079862676305161094044862147301593956294543970688990037138503709415", "price": "0.81", "size": "5.57", "side": "SELL", "hash": "cf57863d05bbad0f475f908e99baef3be38387a6", "best_bid": "0.36", "best_ask": "0.37"}], "timestamp": "1769384249343", "event_type": "price_change"}}
{"_local_timestamp": "2026-01-25T23:37:29.520428+00:00", "data": {"market": "0x8253528e603b5cabb8ab45d1e1209bda57aa2a9f6f0d61aba7ad0a38147a86ee", "price_changes": [{"asset_id": "17667700649974143765639286018245659141526847671421069760676398956961689778433", "price": "0.19", "size": "2260", "side": "BUY", "hash": "143a0eab4a030a421dff9ebd2e872d1e0d6bc007", "best_bid": "0.67", "best_ask": "0.68"}, {"asset_id": "54160287404732698543970249280129195630418658913727451612951061485607934781689", "price": "0.81", "size": "2260", "side": "SELL", "hash": "5689fc4c045b0ad10073fd53ee578cfde1bc85e4", "best_bid": "0.32", "best_ask": "0.33"}], "timestamp": "1769384249447", "event_type": "price_change"}}
{"_local_timestamp": "2026-01-25T23:37:29.892258+00:00", "data": {"market": "0x8253528e603b5cabb8ab45d1e1209bda57aa2a9f6f0d61aba7ad0a38147a86ee", "price_changes": [{"asset_id": "17667700649974143765639286018245659141526847671421069760676398956961689778433", "price": "0.18", "size": "5.95", "side": "BUY", "hash": "a00b0109cd89db86b9c7b50ca14980d814defa1f", "best_bid": "0.67", "best_ask": "0.68"}, {"asset_id": "54160287404732698543970249280129195630418658913727451612951061485607934781689", "price": "0.82", "size": "5.95", "side": "SELL", "hash": "7a6c89c08526a87b4e8fa6b731f651f71b217a82", "best_bid": "0.32", "best_ask": "0.33"}], "timestamp": "1769384249815", "event_type": "price_change"}}
{"_local_timestamp": "2026-01-25T23:37:30.844778+00:00", "data": {"market": "0x892231e7fd3ac31a3b321002f909e011180b709af074808908d27a2a32a7b546", "price_changes": [{"asset_id": "64317448978406417981854076458164286249844965670717306181829295801409919530695", "price": "0.3", "size": "300", "side": "BUY", "hash": "cafc3099ddb742e636ca3323921e80f6c4d65691", "best_bid": "0.92", "best_ask": "0.93"}, {"asset_id": "89791260670398307279783201184852534466650260912467648915456704380491810882664", "price": "0.7", "size": "300", "side": "SELL", "hash": "669754c363b64bccc7b47505c59afc644800d537", "best_bid": "0.07", "best_ask": "0.08"}], "timestamp": "1769384250755", "event_type": "price_change"}}
{"_local_timestamp": "2026-01-25T23:37:31.756675+00:00", "data": {"market": "0xa7e1a7561e1866aa345c0be640df952e1d41decf0a5c4bb571f077142fed025d", "price_changes": [{"asset_id": "76541116657039469088410437026264202489719024425044998810802876826622732617598", "price": "0.75", "size": "50", "side": "BUY", "hash": "80734a92463225ee1d84d29464779ce0bb355fef", "best_bid": "0.75", "best_ask": "0.76"}, {"asset_id": "115679112821476364794223653408101005434638325681840410280875053954587147234523", "price": "0.25", "size": "50", "side": "SELL", "hash": "bc79cf19cfa12ce5de622c6856ebf383ef83c5ba", "best_bid": "0.24", "best_ask": "0.25"}], "timestamp": "1769384251658", "event_type": "price_change"}}
{"_local_timestamp": "2026-01-25T23:37:31.772820+00:00", "data": {"market": "0x892231e7fd3ac31a3b321002f909e011180b709af074808908d27a2a32a7b546", "price_changes": [{"asset_id": "64317448978406417981854076458164286249844965670717306181829295801409919530695", "price": "0.92", "size": "13", "side": "BUY", "hash": "daabb5396de85a5230f17fff868df8028568130e", "best_bid": "0.92", "best_ask": "0.93"}, {"asset_id": "89791260670398307279783201184852534466650260912467648915456704380491810882664", "price": "0.08", "size": "13", "side": "SELL", "hash": "d21d1a0584ae6f25410f4e54c289a45a84cf9e86", "best_bid": "0.07", "best_ask": "0.08"}], "timestamp": "1769384251653", "event_type": "price_change"}}
{"_local_timestamp": "2026-01-25T23:37:31.783565+00:00", "data": {"market": "0xb83cf6cdfe9973219d19fb70f863ec9b713a313609db51839eeb34f7acf275ad", "price_changes": [{"asset_id": "31464892460544164986335006004080412271316454788455556340430054002451576894443", "price": "0.988", "size": "0", "side": "BUY", "hash": "6c0aae566c0866d0bb61a83394121878ac05f4b1", "best_bid": "0.985", "best_ask": "0.99"}, {"asset_id": "101837527728017183708561627155221790735931039980484062356872287158739556672077", "price": "0.012", "size": "0", "side": "SELL", "hash": "81ea19823359744001cf034377e84046560ad336", "best_bid": "0.01", "best_ask": "0.015"}], "timestamp": "1769384251655", "event_type": "price_change"}}
{"_local_timestamp": "2026-01-25T23:37:31.784199+00:00", "data": {"market": "0xff8bf331f7ddbdd2e92e27dcd273612ec45fefde3cf70039c4f043eaec0000c6", "price_changes": [{"asset_id": "65943623919755331891504362129239742473111951663283351342808117545053994127220", "price": "0.63", "size": "199.93", "side": "BUY", "hash": "5a34c0b5a35f4237df56e90762b4baf8773a9feb", "best_bid": "0.63", "best_ask": "0.64"}, {"asset_id": "60105600458079862676305161094044862147301593956294543970688990037138503709415", "price": "0.37", "size": "199.93", "side": "SELL", "hash": "f868cd597694d21129677491a90e75be59df087f", "best_bid": "0.36", "best_ask": "0.37"}], "timestamp": "1769384251657", "event_type": "price_change"}}
{"_local_timestamp": "2026-01-25T23:37:32.029736+00:00", "data": {"market": "0xff8bf331f7ddbdd2e92e27dcd273612ec45fefde3cf70039c4f043eaec0000c6", "price_changes": [{"asset_id": "60105600458079862676305161094044862147301593956294543970688990037138503709415", "price": "0.29", "size": "306.57", "side": "BUY", "hash": "7764823cb58cf997b6607e6863c5297bf142aae8", "best_bid": "0.36", "best_ask": "0.37"}, {"asset_id": "65943623919755331891504362129239742473111951663283351342808117545053994127220", "price": "0.71", "size": "306.57", "side": "SELL", "hash": "147757c0e4a1436d343e8d690513c7e20d6a4f9f", "best_bid": "0.63", "best_ask": "0.64"}], "timestamp": "1769384251912", "event_type": "price_change"}}
{"_local_timestamp": "2026-01-25T23:37:32.037155+00:00", "data": {"market": "0x8253528e603b5cabb8ab45d1e1209bda57aa2a9f6f0d61aba7ad0a38147a86ee", "price_changes": [{"asset_id": "17667700649974143765639286018245659141526847671421069760676398956961689778433", "price": "0.67", "size": "10", "side": "BUY", "hash": "bddc0797bb144063c851a8b07ffc53103a875812", "best_bid": "0.67", "best_ask": "0.68"}, {"asset_id": "54160287404732698543970249280129195630418658913727451612951061485607934781689", "price": "0.33", "size": "10", "side": "SELL", "hash": "1ce810ac7eadd92462b36d4f2b4f6af4e119f492", "best_bid": "0.32", "best_ask": "0.33"}], "timestamp": "1769384251912", "event_type": "price_change"}}
{"_local_timestamp": "2026-01-25T23:37:32.069258+00:00", "data": {"market": "0x8253528e603b5cabb8ab45d1e1209bda57aa2a9f6f0d61aba7ad0a38147a86ee", "price_changes": [{"asset_id": "54160287404732698543970249280129195630418658913727451612951061485607934781689", "price": "0.25", "size": "0", "side": "BUY", "hash": "c8ccebdf32e07f481911944c062c44116454493c", "best_bid": "0.32", "best_ask": "0.33"}, {"asset_id": "17667700649974143765639286018245659141526847671421069760676398956961689778433", "price": "0.75", "size": "0", "side": "SELL", "hash": "1ea38d88469605f2a9f62c41a741738cf53a9b1b", "best_bid": "0.67", "best_ask": "0.68"}], "timestamp": "1769384251914", "event_type": "price_change"}}
{"_local_timestamp": "2026-01-25T23:37:32.077631+00:00", "data": {"market": "0xa7e1a7561e1866aa345c0be640df952e1d41decf0a5c4bb571f077142fed025d", "price_changes": [{"asset_id": "115679112821476364794223653408101005434638325681840410280875053954587147234523", "price": "0.17", "size": "76.47", "side": "BUY", "hash": "5b13d07ea1d840fbcea01a3e3693102e4419af64", "best_bid": "0.24", "best_ask": "0.25"}, {"asset_id": "76541116657039469088410437026264202489719024425044998810802876826622732617598", "price": "0.83", "size": "76.47", "side": "SELL", "hash": "57ba373263e4bd9582e2ce2421ee0bfe0de14b9b", "best_bid": "0.75", "best_ask": "0.76"}], "timestamp": "1769384251914", "event_type": "price_change"}}
{"_local_timestamp": "2026-01-25T23:37:32.213511+00:00", "data": {"market": "0x8253528e603b5cabb8ab45d1e1209bda57aa2a9f6f0d61aba7ad0a38147a86ee", "price_changes": [{"asset_id": "17667700649974143765639286018245659141526847671421069760676398956961689778433", "price": "0.66", "size": "261.64", "side": "BUY", "hash": "a81f5adfb448d30f6d59dac0430639ea35612848", "best_bid": "0.67", "best_ask": "0.68"}, {"asset_id": "54160287404732698543970249280129195630418658913727451612951061485607934781689", "price": "0.34", "size": "261.64", "side": "SELL", "hash": "105b9b1059e1e7c59b889b2d23540a118253d7e3", "best_bid": "0.32", "best_ask": "0.33"}], "timestamp": "1769384252043", "event_type": "price_change"}}
{"_local_timestamp": "2026-01-25T23:37:32.463718+00:00", "data": {"market": "0xb83cf6cdfe9973219d19fb70f863ec9b713a313609db51839eeb34f7acf275ad", "price_changes": [{"asset_id": "31464892460544164986335006004080412271316454788455556340430054002451576894443", "price": "0.981", "size": "30", "side": "BUY", "hash": "89ee9d6df16d86907cfb182deb4f882d83e73502", "best_bid": "0.985", "best_ask": "0.99"}, {"asset_id": "101837527728017183708561627155221790735931039980484062356872287158739556672077", "price": "0.019", "size": "30", "side": "SELL", "hash": "af9e57a369406e6372e2ad00b99b764790bf1a00", "best_bid": "0.01", "best_ask": "0.015"}], "timestamp": "1769384252392", "event_type": "price_change"}}
{"_local_timestamp": "2026-01-25T23:37:34.537281+00:00", "data": {"market": "0x8253528e603b5cabb8ab45d1e1209bda57aa2a9f6f0d61aba7ad0a38147a86ee", "price_changes": [{"asset_id": "17667700649974143765639286018245659141526847671421069760676398956961689778433", "price": "0.64", "size": "143.99", "side": "BUY", "hash": "5631ccd83160aaef56652209af31e904ed4cccbb", "best_bid": "0.67", "best_ask": "0.68"}, {"asset_id": "54160287404732698543970249280129195630418658913727451612951061485607934781689", "price": "0.36", "size": "143.99", "side": "SELL", "hash": "40040a7809e6cbbf3d42c04309c11c082653acdc", "best_bid": "0.32", "best_ask": "0.33"}], "timestamp": "1769384254469", "event_type": "price_change"}}
{"_local_timestamp": "2026-01-25T23:37:34.560398+00:00", "data": {"market": "0x8253528e603b5cabb8ab45d1e1209bda57aa2a9f6f0d61aba7ad0a38147a86ee", "price_changes": [{"asset_id": "54160287404732698543970249280129195630418658913727451612951061485607934781689", "price": "0.34", "size": "32.64", "side": "SELL", "hash": "1b185f4cdf21ff16daf3341e6c3a020f56067ba9", "best_bid": "0.32", "best_ask": "0.33"}, {"asset_id": "17667700649974143765639286018245659141526847671421069760676398956961689778433", "price": "0.66", "size": "32.64", "side": "BUY", "hash": "5342a250fc7ff4b1a1868bacbe6997fd4f8942b2", "best_bid": "0.67", "best_ask": "0.68"}], "timestamp": "1769384254493", "event_type": "price_change"}}
{"_local_timestamp": "2026-01-25T23:37:35.221302+00:00", "data": {"market": "0xa7e1a7561e1866aa345c0be640df952e1d41decf0a5c4bb571f077142fed025d", "price_changes": [{"asset_id": "76541116657039469088410437026264202489719024425044998810802876826622732617598", "price": "0.21", "size": "0", "side": "BUY", "hash": "2e5fcdbaeff3621f495172a5f1f37c8648e5235e", "best_bid": "0.75", "best_ask": "0.76"}, {"asset_id": "115679112821476364794223653408101005434638325681840410280875053954587147234523", "price": "0.79", "size": "0", "side": "SELL", "hash": "bb1ed3df938797db45b73e8f7269679f1cc8e928", "best_bid": "0.24", "best_ask": "0.25"}], "timestamp": "1769384255121", "event_type": "price_change"}}
{"_local_timestamp": "2026-01-25T23:37:35.530891+00:00", "data": {"market": "0x8253528e603b5cabb8ab45d1e1209bda57aa2a9f6f0d61aba7ad0a38147a86ee", "price_changes": [{"asset_id": "54160287404732698543970249280129195630418658913727451612951061485607934781689", "price": "0.3", "size": "550", "side": "BUY", "hash": "2019c873d2cdd459741c42bf7334ed7ffabc706f", "best_bid": "0.32", "best_ask": "0.33"}, {"asset_id": "17667700649974143765639286018245659141526847671421069760676398956961689778433", "price": "0.7", "size": "550", "side": "SELL", "hash": "c5413a4934ed5dd34b7f956ca7a459d37916fcfd", "best_bid": "0.67", "best_ask": "0.68"}], "timestamp": "1769384255460", "event_type": "price_change"}}
{"_local_timestamp": "2026-01-25T23:37:35.540767+00:00", "data": {"market": "0x8253528e603b5cabb8ab45d1e1209bda57aa2a9f6f0d61aba7ad0a38147a86ee", "price_changes": [{"asset_id": "17667700649974143765639286018245659141526847671421069760676398956961689778433", "price": "0.65", "size": "76", "side": "BUY", "hash": "505d12b0c0a206d1ec588e99a8a4755e883c95a8", "best_bid": "0.67", "best_ask": "0.68"}, {"asset_id": "54160287404732698543970249280129195630418658913727451612951061485607934781689", "price": "0.35", "size": "76", "side": "SELL", "hash": "abda1c30c796bb4d8e8839242a70b64fb72c174d", "best_bid": "0.32", "best_ask": "0.33"}], "timestamp": "1769384255460", "event_type": "price_change"}}
{"_local_timestamp": "2026-01-25T23:37:35.742582+00:00", "data": {"market": "0x8253528e603b5cabb8ab45d1e1209bda57aa2a9f6f0d61aba7ad0a38147a86ee", "price_changes": [{"asset_id": "17667700649974143765639286018245659141526847671421069760676398956961689778433", "price": "0.64", "size": "193.99", "side": "BUY", "hash": "06f26c833b2301dfd50deeeddfd6e3b995c09e44", "best_bid": "0.67", "best_ask": "0.68"}, {"asset_id": "54160287404732698543970249280129195630418658913727451612951061485607934781689", "price": "0.36", "size": "193.99", "side": "SELL", "hash": "f39c259ddeb545f3573aba0c9c96fd03f4f7801b", "best_bid": "0.32", "best_ask": "0.33"}], "timestamp": "1769384255677", "event_type": "price_change"}}
{"_local_timestamp": "2026-01-25T23:37:35.743276+00:00", "data": {"market": "0x8253528e603b5cabb8ab45d1e1209bda57aa2a9f6f0d61aba7ad0a38147a86ee", "price_changes": [{"asset_id": "54160287404732698543970249280129195630418658913727451612951061485607934781689", "price": "0.3", "size": "600", "side": "BUY", "hash": "7d096658e9df8ad6c2cd490a9b442c60d5271a0d", "best_bid": "0.32", "best_ask": "0.33"}, {"asset_id": "17667700649974143765639286018245659141526847671421069760676398956961689778433", "price": "0.7", "size": "600", "side": "SELL", "hash": "f9f58b26e2cf5f459b08c053ed00fb1a43d9236c", "best_bid": "0.67", "best_ask": "0.68"}], "timestamp": "1769384255678", "event_type": "price_change"}}
{"_local_timestamp": "2026-01-25T23:37:57.553724+00:00", "data": {"market": "0x8253528e603b5cabb8ab45d1e1209bda57aa2a9f6f0d61aba7ad0a38147a86ee", "price_changes": [{"asset_id": "17667700649974143765639286018245659141526847671421069760676398956961689778433", "price": "0.64", "size": "293.99", "side": "BUY", "hash": "b17d49a8827395e8c884bfc7bc4ac26bf8746582", "best_bid": "0.67", "best_ask": "0.68"}, {"asset_id": "54160287404732698543970249280129195630418658913727451612951061485607934781689", "price": "0.36", "size": "293.99", "side": "SELL", "hash": "930959639ea3fdd77fe7612e77a3c2173047993f", "best_bid": "0.32", "best_ask": "0.33"}], "timestamp": "1769384277473", "event_type": "price_change"}}
{"_local_timestamp": "2026-01-25T23:37:57.554433+00:00", "data": {"market": "0x8253528e603b5cabb8ab45d1e1209bda57aa2a9f6f0d61aba7ad0a38147a86ee", "price_changes": [{"asset_id": "17667700649974143765639286018245659141526847671421069760676398956961689778433", "price": "0.65", "size": "176", "side": "BUY", "hash": "72aa677d4adde25c39a2322117e7fa58478cc1d3", "best_bid": "0.67", "best_ask": "0.68"}, {"asset_id": "54160287404732698543970249280129195630418658913727451612951061485607934781689", "price": "0.35", "size": "176", "side": "SELL", "hash": "391ffcee1403f69d12df333c7fcdf8247f3bda42", "best_bid": "0.32", "best_ask": "0.33"}], "timestamp": "1769384277476", "event_type": "price_change"}}
{"_local_timestamp": "2026-01-25T23:38:01.130668+00:00", "data": {"market": "0xb83cf6cdfe9973219d19fb70f863ec9b713a313609db51839eeb34f7acf275ad", "price_changes": [{"asset_id": "101837527728017183708561627155221790735931039980484062356872287158739556672077", "price": "0.002", "size": "13.3", "side": "BUY", "hash": "116abdc028b7c9d3da6860dde0b6233c1cea84f2", "best_bid": "0.01", "best_ask": "0.015"}, {"asset_id": "31464892460544164986335006004080412271316454788455556340430054002451576894443", "price": "0.998", "size": "13.3", "side": "SELL", "hash": "3437f7acec1798e1a7569cc199c4ba3df55c00c3", "best_bid": "0.985", "best_ask": "0.99"}], "timestamp": "1769384281062", "event_type": "price_change"}}
{"_local_timestamp": "2026-01-25T23:38:01.239399+00:00", "data": {"market": "0xb83cf6cdfe9973219d19fb70f863ec9b713a313609db51839eeb34f7acf275ad", "price_changes": [{"asset_id": "31464892460544164986335006004080412271316454788455556340430054002451576894443", "price": "0.979", "size": "72", "side": "BUY", "hash": "50e287554f398d7dd8382bcedd9bb7cb995ee1a2", "best_bid": "0.985", "best_ask": "0.99"}, {"asset_id": "101837527728017183708561627155221790735931039980484062356872287158739556672077", "price": "0.021", "size": "72", "side": "SELL", "hash": "0baaab05797c48c9e4a7b61f9dd9fdb29e0e2b62", "best_bid": "0.01", "best_ask": "0.015"}], "timestamp": "1769384281165", "event_type": "price_change"}}
{"_local_timestamp": "2026-01-25T23:38:14.301568+00:00", "data": {"market": "0x8253528e603b5cabb8ab45d1e1209bda57aa2a9f6f0d61aba7ad0a38147a86ee", "price_changes": [{"asset_id": "17667700649974143765639286018245659141526847671421069760676398956961689778433", "price": "0.63", "size": "377", "side": "BUY", "hash": "e28a8c958e109f93223cbfe74633aaaaf288662e", "best_bid": "0.67", "best_ask": "0.68"}, {"asset_id": "54160287404732698543970249280129195630418658913727451612951061485607934781689", "price": "0.37", "size": "377", "side": "SELL", "hash": "199dc1eb6d0bd16de9096b42d1ce0127fbac0191", "best_bid": "0.32", "best_ask": "0.33"}], "timestamp": "1769384294228", "event_type": "price_change"}}
{"_local_timestamp": "2026-01-25T23:38:21.271713+00:00", "data": {"market": "0xa7e1a7561e1866aa345c0be640df952e1d41decf0a5c4bb571f077142fed025d", "price_changes": [{"asset_id": "76541116657039469088410437026264202489719024425044998810802876826622732617598", "price": "0.27", "size": "0", "side": "BUY", "hash": "fb9e0bc0ef1a14e651c7105bc3d289b631cb27d9", "best_bid": "0.75", "best_ask": "0.76"}, {"asset_id": "115679112821476364794223653408101005434638325681840410280875053954587147234523", "price": "0.73", "size": "0", "side": "SELL", "hash": "13be4d4f250294e1b3d9eaa4a36adb881017ba3e", "best_bid": "0.24", "best_ask": "0.25"}], "timestamp": "1769384301122", "event_type": "price_change"}}
{"_local_timestamp": "2026-01-25T23:38:21.272528+00:00", "data": {"market": "0xa7e1a7561e1866aa345c0be640df952e1d41decf0a5c4bb571f077142fed025d", "price_changes": [{"asset_id": "76541116657039469088410437026264202489719024425044998810802876826622732617598", "price": "0.2", "size": "155.05", "side": "BUY", "hash": "fb9e0bc0ef1a14e651c7105bc3d289b631cb27d9", "best_bid": "0.75", "best_ask": "0.76"}, {"asset_id": "115679112821476364794223653408101005434638325681840410280875053954587147234523", "price": "0.8", "size": "155.05", "side": "SELL", "hash": "13be4d4f250294e1b3d9eaa4a36adb881017ba3e", "best_bid": "0.24", "best_ask": "0.25"}], "timestamp": "1769384301122", "event_type": "price_change"}}
{"_local_timestamp": "2026-01-25T23:38:21.605918+00:00", "data": {"market": "0xa7e1a7561e1866aa345c0be640df952e1d41decf0a5c4bb571f077142fed025d", "price_changes": [{"asset_id": "76541116657039469088410437026264202489719024425044998810802876826622732617598", "price": "0.28", "size": "200", "side": "BUY", "hash": "797e3090d31726e2858bd7967a5d5e30f410a41c", "best_bid": "0.75", "best_ask": "0.76"}, {"asset_id": "115679112821476364794223653408101005434638325681840410280875053954587147234523", "price": "0.72", "size": "200", "side": "SELL", "hash": "11af7ea4ae82ba12bc118218c96043ec07bc8536", "best_bid": "0.24", "best_ask": "0.25"}], "timestamp": "1769384301458", "event_type": "price_change"}}
{"_local_timestamp": "2026-01-25T23:38:21.682617+00:00", "data": {"market": "0xa7e1a7561e1866aa345c0be640df952e1d41decf0a5c4bb571f077142fed025d", "price_changes": [{"asset_id": "76541116657039469088410437026264202489719024425044998810802876826622732617598", "price": "0.21", "size": "50", "side": "BUY", "hash": "aebe342c4deeddee764d4ad9f8e784c53c5890a3", "best_bid": "0.75", "best_ask": "0.76"}, {"asset_id": "115679112821476364794223653408101005434638325681840410280875053954587147234523", "price": "0.79", "size": "50", "side": "SELL", "hash": "1567e11daa9a28881575bc86f0fbaeb9ad2b0a0b", "best_bid": "0.24", "best_ask": "0.25"}], "timestamp": "1769384301492", "event_type": "price_change"}}
{"_local_timestamp": "2026-01-25T23:38:36.764428+00:00", "data": {"market": "0xb83cf6cdfe9973219d19fb70f863ec9b713a313609db51839eeb34f7acf275ad", "price_changes": [{"asset_id": "101837527728017183708561627155221790735931039980484062356872287158739556672077", "price": "0.003", "size": "1000", "side": "BUY", "hash": "3df87e9077f3febb9b02b33b14a636d5cc0c0de7", "best_bid": "0.01", "best_ask": "0.015"}, {"asset_id": "31464892460544164986335006004080412271316454788455556340430054002451576894443", "price": "0.997", "size": "1000", "side": "SELL", "hash": "ed69fd5b04d36845776970d172d5c311ba7df043", "best_bid": "0.985", "best_ask": "0.99"}], "timestamp": "1769384316691", "event_type": "price_change"}}
{"_local_timestamp": "2026-01-25T23:38:36.765623+00:00", "data": {"market": "0xb83cf6cdfe9973219d19fb70f863ec9b713a313609db51839eeb34f7acf275ad", "price_changes": [{"asset_id": "101837527728017183708561627155221790735931039980484062356872287158739556672077", "price": "0.005", "size": "500", "side": "BUY", "hash": "3df87e9077f3febb9b02b33b14a636d5cc0c0de7", "best_bid": "0.01", "best_ask": "0.015"}, {"asset_id": "31464892460544164986335006004080412271316454788455556340430054002451576894443", "price": "0.995", "size": "500", "side": "SELL", "hash": "ed69fd5b04d36845776970d172d5c311ba7df043", "best_bid": "0.985", "best_ask": "0.99"}], "timestamp": "1769384316691", "event_type": "price_change"}}
{"_local_timestamp": "2026-01-25T23:38:37.161074+00:00", "data": {"market": "0xb83cf6cdfe9973219d19fb70f863ec9b713a313609db51839eeb34f7acf275ad", "price_changes": [{"asset_id": "101837527728017183708561627155221790735931039980484062356872287158739556672077", "price": "0.002", "size": "25.58", "side": "BUY", "hash": "be948e88aa2dc7a1a5da126dbb7223e94fd0b2b4", "best_bid": "0.01", "best_ask": "0.015"}, {"asset_id": "31464892460544164986335006004080412271316454788455556340430054002451576894443", "price": "0.998", "size": "25.58", "side": "SELL", "hash": "fed6615f8d40e022bd06d36824d2ee2b1e78df49", "best_bid": "0.985", "best_ask": "0.99"}], "timestamp": "1769384317090", "event_type": "price_change"}}
{"_local_timestamp": "2026-01-25T23:38:37.161938+00:00", "data": {"market": "0xb83cf6cdfe9973219d19fb70f863ec9b713a313609db51839eeb34f7acf275ad", "price_changes": [{"asset_id": "101837527728017183708561627155221790735931039980484062356872287158739556672077", "price": "0.006", "size": "10.04", "side": "BUY", "hash": "5062885d42d487e326a71bf17e4379ddcab30ad9", "best_bid": "0.01", "best_ask": "0.015"}, {"asset_id": "31464892460544164986335006004080412271316454788455556340430054002451576894443", "price": "0.994", "size": "10.04", "side": "SELL", "hash": "2ab32ac7a4d6ce6dbc5bbf078438baf4cd35cdd3", "best_bid": "0.985", "best_ask": "0.99"}], "timestamp": "1769384317091", "event_type": "price_change"}}
{"_local_timestamp": "2026-01-25T23:38:48.216722+00:00", "data": {"market": "0xa7e1a7561e1866aa345c0be640df952e1d41decf0a5c4bb571f077142fed025d", "price_changes": [{"asset_id": "76541116657039469088410437026264202489719024425044998810802876826622732617598", "price": "0.22", "size": "1908", "side": "BUY", "hash": "2d4d85f386de0adcd719b9d3acf5ffbd1623125f", "best_bid": "0.75", "best_ask": "0.76"}, {"asset_id": "115679112821476364794223653408101005434638325681840410280875053954587147234523", "price": "0.78", "size": "1908", "side": "SELL", "hash": "fa11c039522c11b1e0d9048fdb6e665a032be4af", "best_bid": "0.24", "best_ask": "0.25"}], "timestamp": "1769384328150", "event_type": "price_change"}}
{"_local_timestamp": "2026-01-25T23:38:58.431707+00:00", "data": {"market": "0xa7e1a7561e1866aa345c0be640df952e1d41decf0a5c4bb571f077142fed025d", "price_changes": [{"asset_id": "76541116657039469088410437026264202489719024425044998810802876826622732617598", "price": "0.17", "size": "0", "side": "BUY", "hash": "fc1e4ea487730f49e45afe6bfd7ddb2f5350bd5f", "best_bid": "0.75", "best_ask": "0.76"}, {"asset_id": "115679112821476364794223653408101005434638325681840410280875053954587147234523", "price": "0.83", "size": "0", "side": "SELL", "hash": "6e67e36554dad2beb9fa6a5499a4edf8975e298d", "best_bid": "0.24", "best_ask": "0.25"}], "timestamp": "1769384338224", "event_type": "price_change"}}
{"_local_timestamp": "2026-01-25T23:38:58.432542+00:00", "data": {"market": "0xa7e1a7561e1866aa345c0be640df952e1d41decf0a5c4bb571f077142fed025d", "price_changes": [{"asset_id": "76541116657039469088410437026264202489719024425044998810802876826622732617598", "price": "0.28", "size": "150", "side": "BUY", "hash": "fc1e4ea487730f49e45afe6bfd7ddb2f5350bd5f", "best_bid": "0.75", "best_ask": "0.76"}, {"asset_id": "115679112821476364794223653408101005434638325681840410280875053954587147234523", "price": "0.72", "size": "150", "side": "SELL", "hash": "6e67e36554dad2beb9fa6a5499a4edf8975e298d", "best_bid": "0.24", "best_ask": "0.25"}], "timestamp": "1769384338224", "event_type": "price_change"}}
{"_local_timestamp": "2026-01-25T23:38:58.433184+00:00", "data": {"market": "0xff8bf331f7ddbdd2e92e27dcd273612ec45fefde3cf70039c4f043eaec0000c6", "price_changes": [{"asset_id": "65943623919755331891504362129239742473111951663283351342808117545053994127220", "price": "0.28", "size": "850", "side": "BUY", "hash": "2a81629dc3f24fbe07309c920efae02e58b52109", "best_bid": "0.63", "best_ask": "0.64"}, {"asset_id": "60105600458079862676305161094044862147301593956294543970688990037138503709415", "price": "0.72", "size": "850", "side": "SELL", "hash": "933540ee81055aadfa3cbc41f723476284014bd5", "best_bid": "0.36", "best_ask": "0.37"}], "timestamp": "1769384338224", "event_type": "price_change"}}
{"_local_timestamp": "2026-01-25T23:38:58.434167+00:00", "data": {"market": "0x8253528e603b5cabb8ab45d1e1209bda57aa2a9f6f0d61aba7ad0a38147a86ee", "price_changes": [{"asset_id": "17667700649974143765639286018245659141526847671421069760676398956961689778433", "price": "0.17", "size": "314.7", "side": "BUY", "hash": "88da69512e7876329e549f3b0a7355c958ddf6e9", "best_bid": "0.67", "best_ask": "0.68"}, {"asset_id": "54160287404732698543970249280129195630418658913727451612951061485607934781689", "price": "0.83", "size": "314.7", "side": "SELL", "hash": "53f5ed2d9c5a43d56b05e386565aa7adb9418c6d", "best_bid": "0.32", "best_ask": "0.33"}], "timestamp": "1769384338224", "event_type": "price_change"}}
{"_local_timestamp": "2026-01-25T23:38:58.434838+00:00", "data": {"market": "0x8253528e603b5cabb8ab45d1e1209bda57aa2a9f6f0d61aba7ad0a38147a86ee", "price_changes": [{"asset_id": "17667700649974143765639286018245659141526847671421069760676398956961689778433", "price": "0.21", "size": "223.8", "side": "BUY", "hash": "88da69512e7876329e549f3b0a7355c958ddf6e9", "best_bid": "0.67", "best_ask": "0.68"}, {"asset_id": "54160287404732698543970249280129195630418658913727451612951061485607934781689", "price": "0.79", "size": "223.8", "side": "SELL", "hash": "53f5ed2d9c5a43d56b05e386565aa7adb9418c6d", "best_bid": "0.32", "best_ask": "0.33"}], "timestamp": "1769384338224", "event_type": "price_change"}}
{"_local_timestamp": "2026-01-25T23:38:58.654244+00:00", "data": {"market": "0xff8bf331f7ddbdd2e92e27dcd273612ec45fefde3cf70039c4f043eaec0000c6", "price_changes": [{"asset_id": "65943623919755331891504362129239742473111951663283351342808117545053994127220", "price": "0.28", "size": "50", "side": "BUY", "hash": "22b8f35601c62d5ce24be8d0e2d5d5c88d0cb48d", "best_bid": "0.63", "best_ask": "0.64"}, {"asset_id": "60105600458079862676305161094044862147301593956294543970688990037138503709415", "price": "0.72", "size": "50", "side": "SELL", "hash": "40e32a39acf8afa3ce0d55e22690e2ded23ae1fb", "best_bid": "0.36", "best_ask": "0.37"}], "timestamp": "1769384338499", "event_type": "price_change"}}
{"_local_timestamp": "2026-01-25T23:38:58.752637+00:00", "data": {"market": "0x8253528e603b5cabb8ab45d1e1209bda57aa2a9f6f0d61aba7ad0a38147a86ee", "price_changes": [{"asset_id": "17667700649974143765639286018245659141526847671421069760676398956961689778433", "price": "0.34", "size": "975", "side": "BUY", "hash": "83aeaca1a2c4de3a4c03e52628747c552d18de2b", "best_bid": "0.67", "best_ask": "0.68"}, {"asset_id": "54160287404732698543970249280129195630418658913727451612951061485607934781689", "price": "0.66", "size": "975", "side": "SELL", "hash": "a2bdc107d6d23e1ae5a6dceef0da47a51004876a", "best_bid": "0.32", "best_ask": "0.33"}], "timestamp": "1769384338649", "event_type": "price_change"}}
{"_local_timestamp": "2026-01-25T23:38:58.844230+00:00", "data": {"market": "0xa7e1a7561e1866aa345c0be640df952e1d41decf0a5c4bb571f077142fed025d", "price_changes": [{"asset_id": "76541116657039469088410437026264202489719024425044998810802876826622732617598", "price": "0.21", "size": "100", "side": "BUY", "hash": "cdba610e8e28c701e70882bd822a96df84c7a395", "best_bid": "0.75", "best_ask": "0.76"}, {"asset_id": "115679112821476364794223653408101005434638325681840410280875053954587147234523", "price": "0.79", "size": "100", "side": "SELL", "hash": "ebc1ebd0a71e4b8d361390c837fa27f88e998956", "best_bid": "0.24", "best_ask": "0.25"}], "timestamp": "1769384338646", "event_type": "price_change"}}
{"_local_timestamp": "2026-01-25T23:38:58.858389+00:00", "data": {"market": "0xff8bf331f7ddbdd2e92e27dcd273612ec45fefde3cf70039c4f043eaec0000c6", "price_changes": [{"asset_id": "65943623919755331891504362129239742473111951663283351342808117545053994127220", "price": "0.29", "size": "906", "side": "BUY", "hash": "e52298a33133d797e08a13a85673312b481c3171", "best_bid": "0.63", "best_ask": "0.64"}, {"asset_id": "60105600458079862676305161094044862147301593956294543970688990037138503709415", "price": "0.71", "size": "906", "side": "SELL", "hash": "feafe689905c945fef423f76c1dbe24082402041", "best_bid": "0.36", "best_ask": "0.37"}], "timestamp": "1769384338647", "event_type": "price_change"}}
{"_local_timestamp": "2026-01-25T23:38:58.860661+00:00", "data": {"market": "0xff8bf331f7ddbdd2e92e27dcd273612ec45fefde3cf70039c4f043eaec0000c6", "price_changes": [{"asset_id": "65943623919755331891504362129239742473111951663283351342808117545053994127220", "price": "0.3", "size": "328", "side": "BUY", "hash": "cc8cf27bee05e5177b96329621ca1bc5e1d2f15c", "best_bid": "0.63", "best_ask": "0.64"}, {"asset_id": "60105600458079862676305161094044862147301593956294543970688990037138503709415", "price": "0.7", "size": "328", "side": "SELL", "hash": "afa62e2e99853d1ce9c2341a3a1c9b5f08351e6c", "best_bid": "0.36", "best_ask": "0.37"}], "timestamp": "1769384338793", "event_type": "price_change"}}
{"_local_timestamp": "2026-01-25T23:38:59.078490+00:00", "data": {"market": "0x8253528e603b5cabb8ab45d1e1209bda57aa2a9f6f0d61aba7ad0a38147a86ee", "price_changes": [{"asset_id": "17667700649974143765639286018245659141526847671421069760676398956961689778433", "price": "0.19", "size": "2360", "side": "BUY", "hash": "4fba66dab97b23636b58bbdb007cfa931fa859ea", "best_bid": "0.67", "best_ask": "0.68"}, {"asset_id": "54160287404732698543970249280129195630418658913727451612951061485607934781689", "price": "0.81", "size": "2360", "side": "SELL", "hash": "ffc46478f8fc16975520605a1d9c624114d562ab", "best_bid": "0.32", "best_ask": "0.33"}], "timestamp": "1769384338676", "event_type": "price_change"}}
{"_local_timestamp": "2026-01-25T23:38:59.150128+00:00", "data": {"market": "0xa7e1a7561e1866aa345c0be640df952e1d41decf0a5c4bb571f077142fed025d", "price_changes": [{"asset_id": "76541116657039469088410437026264202489719024425044998810802876826622732617598", "price": "0.2", "size": "255.05", "side": "BUY", "hash": "9f61338632e6e41499f72060bc072b130a3e7d2b", "best_bid": "0.75", "best_ask": "0.76"}, {"asset_id": "115679112821476364794223653408101005434638325681840410280875053954587147234523", "price": "0.8", "size": "255.05", "side": "SELL", "hash": "a8f551d493392196e5c844fde58e0f0453a03b8c", "best_bid": "0.24", "best_ask": "0.25"}], "timestamp": "1769384338782", "event_type": "price_change"}}
{"_local_timestamp": "2026-01-25T23:38:59.150901+00:00", "data": {"market": "0xff8bf331f7ddbdd2e92e27dcd273612ec45fefde3cf70039c4f043eaec0000c6", "price_changes": [{"asset_id": "65943623919755331891504362129239742473111951663283351342808117545053994127220", "price": "0.29", "size": "150", "side": "BUY", "hash": "c952383f30218ac0b44af7af960d05dafc1c915c", "best_bid": "0.63", "best_ask": "0.64"}, {"asset_id": "60105600458079862676305161094044862147301593956294543970688990037138503709415", "price": "0.71", "size": "150", "side": "SELL", "hash": "dee1221bbcd02c99d0ee206dad6baf33c754b593", "best_bid": "0.36", "best_ask": "0.37"}], "timestamp": "1769384338964", "event_type": "price_change"}}
{"_local_timestamp": "2026-01-25T23:38:59.221203+00:00", "data": {"market": "0xff8bf331f7ddbdd2e92e27dcd273612ec45fefde3cf70039c4f043eaec0000c6", "price_changes": [{"asset_id": "65943623919755331891504362129239742473111951663283351342808117545053994127220", "price": "0.3", "size": "427", "side": "BUY", "hash": "9ed3b4b53c9d2b4de765f709210b3e54ea6e1b29", "best_bid": "0.63", "best_ask": "0.64"}, {"asset_id": "60105600458079862676305161094044862147301593956294543970688990037138503709415", "price": "0.7", "size": "427", "side": "SELL", "hash": "10e1ad9fa55d50b616ee1493b1ff3b88a4e1b5ee", "best_bid": "0.36", "best_ask": "0.37"}], "timestamp": "1769384339093", "event_type": "price_change"}}
{"_local_timestamp": "2026-01-25T23:39:20.460492+00:00", "data": {"market": "0x892231e7fd3ac31a3b321002f909e011180b709af074808908d27a2a32a7b546", "price_changes": [{"asset_id": "64317448978406417981854076458164286249844965670717306181829295801409919530695", "price": "0.29", "size": "200", "side": "BUY", "hash": "93f18c2affa087e8fddf593a375d1bdc0101ac22", "best_bid": "0.92", "best_ask": "0.93"}, {"asset_id": "89791260670398307279783201184852534466650260912467648915456704380491810882664", "price": "0.71", "size": "200", "side": "SELL", "hash": "f0cfc6206d3495188c379147ac9ede5940dc5dcc", "best_bid": "0.07", "best_ask": "0.08"}], "timestamp": "1769384360335", "event_type": "price_change"}}
{"_local_timestamp": "2026-01-25T23:39:20.476123+00:00", "data": {"market": "0x8253528e603b5cabb8ab45d1e1209bda57aa2a9f6f0d61aba7ad0a38147a86ee", "price_changes": [{"asset_id": "17667700649974143765639286018245659141526847671421069760676398956961689778433", "price": "0.19", "size": "150", "side": "BUY", "hash": "908dd44ff05ba3a2d6ecda7e41098e8d24becfbf", "best_bid": "0.67", "best_ask": "0.68"}, {"asset_id": "54160287404732698543970249280129195630418658913727451612951061485607934781689", "price": "0.81", "size": "150", "side": "SELL", "hash": "c8edac3f54f5cefd10774a203ef2e1b2eabad033", "best_bid": "0.32", "best_ask": "0.33"}], "timestamp": "1769384360333", "event_type": "price_change"}}
{"_local_timestamp": "2026-01-25T23:39:20.520749+00:00", "data": {"market": "0xa7e1a7561e1866aa345c0be640df952e1d41decf0a5c4bb571f077142fed025d", "price_changes": [{"asset_id": "76541116657039469088410437026264202489719024425044998810802876826622732617598", "price": "0.22", "size": "0", "side": "BUY", "hash": "cd89d4f542c8e64ba9f60b3fc753acc020db8b77", "best_bid": "0.75", "best_ask": "0.76"}, {"asset_id": "115679112821476364794223653408101005434638325681840410280875053954587147234523", "price": "0.78", "size": "0", "side": "SELL", "hash": "a710446db325c51ba2188158f7736dc8b4a03cd9", "best_bid": "0.24", "best_ask": "0.25"}], "timestamp": "1769384360341", "event_type": "price_change"}}
{"_local_timestamp": "2026-01-25T23:39:20.567312+00:00", "data": {"market": "0xff8bf331f7ddbdd2e92e27dcd273612ec45fefde3cf70039c4f043eaec0000c6", "price_changes": [{"asset_id": "65943623919755331891504362129239742473111951663283351342808117545053994127220", "price": "0.17", "size": "300", "side": "BUY", "hash": "5d01c44750b44c959efcd8e6f071e28f9d42787a", "best_bid": "0.63", "best_ask": "0.64"}, {"asset_id": "60105600458079862676305161094044862147301593956294543970688990037138503709415", "price": "0.83", "size": "300", "side": "SELL", "hash": "f2eb52914759ebfdd787ba53800e541f2be4e53c", "best_bid": "0.36", "best_ask": "0.37"}], "timestamp": "1769384360340", "event_type": "price_change"}}
{"_local_timestamp": "2026-01-25T23:39:22.413430+00:00", "data": {"market": "0xa7e1a7561e1866aa345c0be640df952e1d41decf0a5c4bb571f077142fed025d", "price_changes": [{"asset_id": "76541116657039469088410437026264202489719024425044998810802876826622732617598", "price": "0.2", "size": "105.05", "side": "BUY", "hash": "32959981e3fe192ef606a08e050d6ecd1fc8918b", "best_bid": "0.75", "best_ask": "0.76"}, {"asset_id": "115679112821476364794223653408101005434638325681840410280875053954587147234523", "price": "0.8", "size": "105.05", "side": "SELL", "hash": "cc1684fdc4dbed79bb3ecf1542857d9196a1de12", "best_bid": "0.24", "best_ask": "0.25"}], "timestamp": "1769384362208", "event_type": "price_change"}}
{"_local_timestamp": "2026-01-25T23:39:22.415212+00:00", "data": {"market": "0x8253528e603b5cabb8ab45d1e1209bda57aa2a9f6f0d61aba7ad0a38147a86ee", "price_changes": [{"asset_id": "17667700649974143765639286018245659141526847671421069760676398956961689778433", "price": "0.17", "size": "164.7", "side": "BUY", "hash": "aff5c6c1f0b170cf536021dfd6e345a984358806", "best_bid": "0.67", "best_ask": "0.68"}, {"asset_id": "54160287404732698543970249280129195630418658913727451612951061485607934781689", "price": "0.83", "size": "164.7", "side": "SELL", "hash": "3302d9fcca6619dd418a4eca67bb81d8d6ad4545", "best_bid": "0.32", "best_ask": "0.33"}], "timestamp": "1769384362208", "event_type": "price_change"}}
{"_local_timestamp": "2026-01-25T23:39:22.416333+00:00", "data": {"market": "0x8253528e603b5cabb8ab45d1e1209bda57aa2a9f6f0d61aba7ad0a38147a86ee", "price_changes": [{"asset_id": "17667700649974143765639286018245659141526847671421069760676398956961689778433", "price": "0.21", "size": "123.8", "side": "BUY", "hash": "aff5c6c1f0b170cf536021dfd6e345a984358806", "best_bid": "0.67", "best_ask": "0.68"}, {"asset_id": "54160287404732698543970249280129195630418658913727451612951061485607934781689", "price": "0.79", "size": "123.8", "side": "SELL", "hash": "3302d9fcca6619dd418a4eca67bb81d8d6ad4545", "best_bid": "0.32", "best_ask": "0.33"}], "timestamp": "1769384362208", "event_type": "price_change"}}
{"_local_timestamp": "2026-01-25T23:39:22.434068+00:00", "data": {"market": "0x892231e7fd3ac31a3b321002f909e011180b709af074808908d27a2a32a7b546", "price_changes": [{"asset_id": "64317448978406417981854076458164286249844965670717306181829295801409919530695", "price": "0.5", "size": "0", "side": "BUY", "hash": "e4b2705b101ff462f5ca1bde47d285fea0f098fb", "best_bid": "0.92", "best_ask": "0.93"}, {"asset_id": "89791260670398307279783201184852534466650260912467648915456704380491810882664", "price": "0.5", "size": "0", "side": "SELL", "hash": "ff132b077c931de6f2b5bd1af54190f781f09b25", "best_bid": "0.07", "best_ask": "0.08"}], "timestamp": "1769384362208", "event_type": "price_change"}}
{"_local_timestamp": "2026-01-25T23:39:22.476418+00:00", "data": {"market": "0xa7e1a7561e1866aa345c0be640df952e1d41decf0a5c4bb571f077142fed025d", "price_changes": [{"asset_id": "76541116657039469088410437026264202489719024425044998810802876826622732617598", "price": "0.28", "size": "50", "side": "BUY", "hash": "77e57681ef09e20bec41dc431429a62afa50f8af", "best_bid": "0.75", "best_ask": "0.76"}, {"asset_id": "115679112821476364794223653408101005434638325681840410280875053954587147234523", "price": "0.72", "size": "50", "side": "SELL", "hash": "a19f5753100ef8905ea9426fcca2e2b2aef25367", "best_bid": "0.24", "best_ask": "0.25"}], "timestamp": "1769384362215", "event_type": "price_change"}}
{"_local_timestamp": "2026-01-25T23:39:22.930175+00:00", "data": {"market": "0x8253528e603b5cabb8ab45d1e1209bda57aa2a9f6f0d61aba7ad0a38147a86ee", "price_changes": [{"asset_id": "17667700649974143765639286018245659141526847671421069760676398956961689778433", "price": "0.19", "size": "300", "side": "BUY", "hash": "7de0768a3f8baf965d19c0735ab75aec9029cd4b", "best_bid": "0.67", "best_ask": "0.68"}, {"asset_id": "54160287404732698543970249280129195630418658913727451612951061485607934781689", "price": "0.81", "size": "300", "side": "SELL", "hash": "9d6e83950237690304e7c4112b3b87f128a73aaa", "best_bid": "0.32", "best_ask": "0.33"}], "timestamp": "1769384362722", "event_type": "price_change"}}
{"_local_timestamp": "2026-01-25T23:39:22.931066+00:00", "data": {"market": "0xa7e1a7561e1866aa345c0be640df952e1d41decf0a5c4bb571f077142fed025d", "price_changes": [{"asset_id": "76541116657039469088410437026264202489719024425044998810802876826622732617598", "price": "0.16", "size": "400", "side": "BUY", "hash": "b107d3e37c5a8a038784bc15f6b2aff4496fb98a", "best_bid": "0.75", "best_ask": "0.76"}, {"asset_id": "115679112821476364794223653408101005434638325681840410280875053954587147234523", "price": "0.84", "size": "400", "side": "SELL", "hash": "949f40cd61ce7f78f8d8e839552b09e24caa93bd", "best_bid": "0.24", "best_ask": "0.25"}], "timestamp": "1769384362721", "event_type": "price_change"}}
{"_local_timestamp": "2026-01-25T23:39:23.021851+00:00", "data": {"market": "0xa7e1a7561e1866aa345c0be640df952e1d41decf0a5c4bb571f077142fed025d", "price_changes": [{"asset_id": "76541116657039469088410437026264202489719024425044998810802876826622732617598", "price": "0.21", "size": "200", "side": "BUY", "hash": "54cc8a235afc5b83475138a7bb42338bff21b446", "best_bid": "0.75", "best_ask": "0.76"}, {"asset_id": "115679112821476364794223653408101005434638325681840410280875053954587147234523", "price": "0.79", "size": "200", "side": "SELL", "hash": "33355a3610b2d947df35da4578d89c216484f3d6", "best_bid": "0.24", "best_ask": "0.25"}], "timestamp": "1769384362795", "event_type": "price_change"}}
{"_local_timestamp": "2026-01-25T23:39:23.027788+00:00", "data": {"market": "0x8253528e603b5cabb8ab45d1e1209bda57aa2a9f6f0d61aba7ad0a38147a86ee", "price_changes": [{"asset_id": "17667700649974143765639286018245659141526847671421069760676398956961689778433", "price": "0.22", "size": "400", "side": "BUY", "hash": "7aef8640a92194220e0fe24476ff0b18368a7d7b", "best_bid": "0.67", "best_ask": "0.68"}, {"asset_id": "54160287404732698543970249280129195630418658913727451612951061485607934781689", "price": "0.78", "size": "400", "side": "SELL", "hash": "d2c349130284a71eb0b3694554b16debae920390", "best_bid": "0.32", "best_ask": "0.33"}], "timestamp": "1769384362795", "event_type": "price_change"}}
{"_local_timestamp": "2026-01-25T23:39:49.182994+00:00", "data": {"market": "0x8253528e603b5cabb8ab45d1e1209bda57aa2a9f6f0d61aba7ad0a38147a86ee", "price_changes": [{"asset_id": "17667700649974143765639286018245659141526847671421069760676398956961689778433", "price": "0.67", "size": "60", "side": "BUY", "hash": "1feb078947475db75a657ac3da33ff60478217c6", "best_bid": "0.67", "best_ask": "0.68"}, {"asset_id": "54160287404732698543970249280129195630418658913727451612951061485607934781689", "price": "0.33", "size": "60", "side": "SELL", "hash": "777460eba8c6cc73e9e2a6ed98df7e5971e90372", "best_bid": "0.32", "best_ask": "0.33"}], "timestamp": "1769384389112", "event_type": "price_change"}}
{"_local_timestamp": "2026-01-25T23:39:49.184125+00:00", "data": {"market": "0x892231e7fd3ac31a3b321002f909e011180b709af074808908d27a2a32a7b546", "price_changes": [{"asset_id": "64317448978406417981854076458164286249844965670717306181829295801409919530695", "price": "0.92", "size": "63", "side": "BUY", "hash": "73b98efc648d228628de84246e86f701c40892fb", "best_bid": "0.92", "best_ask": "0.93"}, {"asset_id": "89791260670398307279783201184852534466650260912467648915456704380491810882664", "price": "0.08", "size": "63", "side": "SELL", "hash": "05a4c89dec44d5c3ee7e844b0aaf16a27c7e587d", "best_bid": "0.07", "best_ask": "0.08"}], "timestamp": "1769384389112", "event_type": "price_change"}}
{"_local_timestamp": "2026-01-25T23:39:49.184853+00:00", "data": {"market": "0x8253528e603b5cabb8ab45d1e1209bda57aa2a9f6f0d61aba7ad0a38147a86ee", "price_changes": [{"asset_id": "17667700649974143765639286018245659141526847671421069760676398956961689778433", "price": "0.66", "size": "222.64", "side": "BUY", "hash": "7d16dcd029aa49d581dcb42259016404cafe57e3", "best_bid": "0.67", "best_ask": "0.68"}, {"asset_id": "54160287404732698543970249280129195630418658913727451612951061485607934781689", "price": "0.34", "size": "222.64", "side": "SELL", "hash": "0a0b06c0d973fcc719547276f762e2398d02e7bb", "best_bid": "0.32", "best_ask": "0.33"}], "timestamp": "1769384389113", "event_type": "price_change"}}
{"_local_timestamp": "2026-01-25T23:39:49.242684+00:00", "data": {"market": "0x8253528e603b5cabb8ab45d1e1209bda57aa2a9f6f0d61aba7ad0a38147a86ee", "price_changes": [{"asset_id": "17667700649974143765639286018245659141526847671421069760676398956961689778433", "price": "0.66", "size": "192.64", "side": "BUY", "hash": "1ef72fb61d3f5f98f91cdc46ffe9aaaa67b96281", "best_bid": "0.67", "best_ask": "0.68"}, {"asset_id": "54160287404732698543970249280129195630418658913727451612951061485607934781689", "price": "0.34", "size": "192.64", "side": "SELL", "hash": "8115fd4654d9bb9fdd64a27d4cc603a3010167d0", "best_bid": "0.32", "best_ask": "0.33"}], "timestamp": "1769384389170", "event_type": "price_change"}}
{"_local_timestamp": "2026-01-25T23:39:49.274820+00:00", "data": {"market": "0x892231e7fd3ac31a3b321002f909e011180b709af074808908d27a2a32a7b546", "price_changes": [{"asset_id": "64317448978406417981854076458164286249844965670717306181829295801409919530695", "price": "0.52", "size": "79", "side": "BUY", "hash": "fb782383415865aea51d2b4a532dfd0ac1ce30e1", "best_bid": "0.92", "best_ask": "0.93"}, {"asset_id": "89791260670398307279783201184852534466650260912467648915456704380491810882664", "price": "0.48", "size": "79", "side": "SELL", "hash": "290dc86837fcdf66143c8e13fcfd123affe18fd9", "best_bid": "0.07", "best_ask": "0.08"}], "timestamp": "1769384389205", "event_type": "price_change"}}
{"_local_timestamp": "2026-01-25T23:39:49.346874+00:00", "data": {"market": "0x8253528e603b5cabb8ab45d1e1209bda57aa2a9f6f0d61aba7ad0a38147a86ee", "price_changes": [{"asset_id": "17667700649974143765639286018245659141526847671421069760676398956961689778433", "price": "0.64", "size": "323.99", "side": "BUY", "hash": "6432c9b1783b73ec3f6077e8c59a299a736b4880", "best_bid": "0.67", "best_ask": "0.68"}, {"asset_id": "54160287404732698543970249280129195630418658913727451612951061485607934781689", "price": "0.36", "size": "323.99", "side": "SELL", "hash": "02a1de1e0245a1de405d9251d4ce46be2b86794b", "best_bid": "0.32", "best_ask": "0.33"}], "timestamp": "1769384389275", "event_type": "price_change"}}
{"_local_timestamp": "2026-01-25T23:39:49.352209+00:00", "data": {"market": "0x892231e7fd3ac31a3b321002f909e011180b709af074808908d27a2a32a7b546", "price_changes": [{"asset_id": "64317448978406417981854076458164286249844965670717306181829295801409919530695", "price": "0.9", "size": "452", "side": "BUY", "hash": "1ef927b90b50681d6e03e762cce0846f3251ab80", "best_bid": "0.92", "best_ask": "0.93"}, {"asset_id": "89791260670398307279783201184852534466650260912467648915456704380491810882664", "price": "0.1", "size": "452", "side": "SELL", "hash": "c56d92777727e25af5861affc8c28ce0caf5cbaf", "best_bid": "0.07", "best_ask": "0.08"}], "timestamp": "1769384389281", "event_type": "price_change"}}
{"_local_timestamp": "2026-01-25T23:39:49.354385+00:00", "data": {"market": "0x892231e7fd3ac31a3b321002f909e011180b709af074808908d27a2a32a7b546", "price_changes": [{"asset_id": "89791260670398307279783201184852534466650260912467648915456704380491810882664", "price": "0.06", "size": "400", "side": "BUY", "hash": "0e8025100d53754778f42dbb75c06af815143fc3", "best_bid": "0.07", "best_ask": "0.08"}, {"asset_id": "64317448978406417981854076458164286249844965670717306181829295801409919530695", "price": "0.94", "size": "400", "side": "SELL", "hash": "b30392a5a2051d01da5245a25a685bf00303764c", "best_bid": "0.92", "best_ask": "0.93"}], "timestamp": "1769384389281", "event_type": "price_change"}}
{"_local_timestamp": "2026-01-25T23:39:49.356895+00:00", "data": {"market": "0x8253528e603b5cabb8ab45d1e1209bda57aa2a9f6f0d61aba7ad0a38147a86ee", "price_changes": [{"asset_id": "17667700649974143765639286018245659141526847671421069760676398956961689778433", "price": "0.64", "size": "273.99", "side": "BUY", "hash": "61acc28f017cd046aaf78e20f67902ea16fd1f59", "best_bid": "0.67", "best_ask": "0.68"}, {"asset_id": "54160287404732698543970249280129195630418658913727451612951061485607934781689", "price": "0.36", "size": "273.99", "side": "SELL", "hash": "3be14de8a1b9111c4017600c07d34ff5cddac141", "best_bid": "0.32", "best_ask": "0.33"}], "timestamp": "1769384389285", "event_type": "price_change"}}
{"_local_timestamp": "2026-01-25T23:39:49.358437+00:00", "data": {"market": "0x8253528e603b5cabb8ab45d1e1209bda57aa2a9f6f0d61aba7ad0a38147a86ee", "price_changes": [{"asset_id": "54160287404732698543970249280129195630418658913727451612951061485607934781689", "price": "0.3", "size": "550", "side": "BUY", "hash": "467e12923bdb23b46d68352540aaaff14c7d7347", "best_bid": "0.32", "best_ask": "0.33"}, {"asset_id": "17667700649974143765639286018245659141526847671421069760676398956961689778433", "price": "0.7", "size": "550", "side": "SELL", "hash": "40ace3125b0f9c177d0133488c4b208e1ec02a79", "best_bid": "0.67", "best_ask": "0.68"}], "timestamp": "1769384389286", "event_type": "price_change"}}
{"_local_timestamp": "2026-01-25T23:39:49.578866+00:00", "data": {"market": "0x8253528e603b5cabb8ab45d1e1209bda57aa2a9f6f0d61aba7ad0a38147a86ee", "price_changes": [{"asset_id": "17667700649974143765639286018245659141526847671421069760676398956961689778433", "price": "0.66", "size": "242.64", "side": "BUY", "hash": "dab1ba2c7208f0eb6d749770e3e0602f8c6f1d09", "best_bid": "0.67", "best_ask": "0.68"}, {"asset_id": "54160287404732698543970249280129195630418658913727451612951061485607934781689", "price": "0.34", "size": "242.64", "side": "SELL", "hash": "c3ae15c51bf2f5b6e26f3f6a2ee203a070cf23f8", "best_bid": "0.32", "best_ask": "0.33"}], "timestamp": "1769384389498", "event_type": "price_change"}}
{"_local_timestamp": "2026-01-25T23:39:49.579719+00:00", "data": {"market": "0x8253528e603b5cabb8ab45d1e1209bda57aa2a9f6f0d61aba7ad0a38147a86ee", "price_changes": [{"asset_id": "54160287404732698543970249280129195630418658913727451612951061485607934781689", "price": "0.3", "size": "600", "side": "BUY", "hash": "a426172a02f00ed201a30a625e8e50551efe2536", "best_bid": "0.32", "best_ask": "0.33"}, {"asset_id": "17667700649974143765639286018245659141526847671421069760676398956961689778433", "price": "0.7", "size": "600", "side": "SELL", "hash": "b474df6e8f9c2ce6fb3940225944457e0356a4dc", "best_bid": "0.67", "best_ask": "0.68"}], "timestamp": "1769384389499", "event_type": "price_change"}}
{"_local_timestamp": "2026-01-25T23:39:49.586923+00:00", "data": {"market": "0x892231e7fd3ac31a3b321002f909e011180b709af074808908d27a2a32a7b546", "price_changes": [{"asset_id": "64317448978406417981854076458164286249844965670717306181829295801409919530695", "price": "0.91", "size": "131.19", "side": "BUY", "hash": "3e60e796b8e1d02365aa444759d13368f3481012", "best_bid": "0.92", "best_ask": "0.93"}, {"asset_id": "89791260670398307279783201184852534466650260912467648915456704380491810882664", "price": "0.09", "size": "131.19", "side": "SELL", "hash": "d1ece8660e802d2b267c19c6336f38476e417088", "best_bid": "0.07", "best_ask": "0.08"}], "timestamp": "1769384389502", "event_type": "price_change"}}
{"_local_timestamp": "2026-01-25T23:39:49.587768+00:00", "data": {"market": "0x892231e7fd3ac31a3b321002f909e011180b709af074808908d27a2a32a7b546", "price_changes": [{"asset_id": "89791260670398307279783201184852534466650260912467648915456704380491810882664", "price": "0.06", "size": "450", "side": "BUY", "hash": "46bf5d4b1aea47fcee4d975b8e2dba1fe56fd77b", "best_bid": "0.07", "best_ask": "0.08"}, {"asset_id": "64317448978406417981854076458164286249844965670717306181829295801409919530695", "price": "0.94", "size": "450", "side": "SELL", "hash": "f3f63dc900d74a520b3988a6c1c81fff1c9e50fc", "best_bid": "0.92", "best_ask": "0.93"}], "timestamp": "1769384389502", "event_type": "price_change"}}
{"_local_timestamp": "2026-01-25T23:39:51.958697+00:00", "data": {"market": "0x8253528e603b5cabb8ab45d1e1209bda57aa2a9f6f0d61aba7ad0a38147a86ee", "price_changes": [{"asset_id": "17667700649974143765639286018245659141526847671421069760676398956961689778433", "price": "0.19", "size": "250", "side": "BUY", "hash": "ccf885fbff77373e916ba4f19c175dc1bc4b8738", "best_bid": "0.67", "best_ask": "0.68"}, {"asset_id": "54160287404732698543970249280129195630418658913727451612951061485607934781689", "price": "0.81", "size": "250", "side": "SELL", "hash": "93fcf100654890083245093242c69ba7f74b57d9", "best_bid": "0.32", "best_ask": "0.33"}], "timestamp": "1769384391883", "event_type": "price_change"}}
{"_local_timestamp": "2026-01-25T23:39:51.959542+00:00", "data": {"market": "0xff8bf331f7ddbdd2e92e27dcd273612ec45fefde3cf70039c4f043eaec0000c6", "price_changes": [{"asset_id": "65943623919755331891504362129239742473111951663283351342808117545053994127220", "price": "0.17", "size": "250", "side": "BUY", "hash": "1f678a111e4afc8af7d181ef371d77f7f20a82f1", "best_bid": "0.63", "best_ask": "0.64"}, {"asset_id": "60105600458079862676305161094044862147301593956294543970688990037138503709415", "price": "0.83", "size": "250", "side": "SELL", "hash": "6c54a15aed2f7c9c9ac80cadf28156e6a19840f2", "best_bid": "0.36", "best_ask": "0.37"}], "timestamp": "1769384391883", "event_type": "price_change"}}
{"_local_timestamp": "2026-01-25T23:39:52.262981+00:00", "data": {"market": "0xff8bf331f7ddbdd2e92e27dcd273612ec45fefde3cf70039c4f043eaec0000c6", "price_changes": [{"asset_id": "65943623919755331891504362129239742473111951663283351342808117545053994127220", "price": "0.13", "size": "621.15", "side": "BUY", "hash": "cc6760abf68593e0073c3e34edec569cdccf2f43", "best_bid": "0.63", "best_ask": "0.64"}, {"asset_id": "60105600458079862676305161094044862147301593956294543970688990037138503709415", "price": "0.87", "size": "621.15", "side": "SELL", "hash": "b96f7082370b61367fb2bf6b217ee9f077e37b07", "best_bid": "0.36", "best_ask": "0.37"}], "timestamp": "1769384392168", "event_type": "price_change"}}
{"_local_timestamp": "2026-01-25T23:39:52.263851+00:00", "data": {"market": "0x8253528e603b5cabb8ab45d1e1209bda57aa2a9f6f0d61aba7ad0a38147a86ee", "price_changes": [{"asset_id": "17667700649974143765639286018245659141526847671421069760676398956961689778433", "price": "0.14", "size": "603.57", "side": "BUY", "hash": "6ad107694aec6a14370318f127d9cb7f33aa2f06", "best_bid": "0.67", "best_ask": "0.68"}, {"asset_id": "54160287404732698543970249280129195630418658913727451612951061485607934781689", "price": "0.86", "size": "603.57", "side": "SELL", "hash": "6574725ad9544f24beb5fa150917a629e58c326f", "best_bid": "0.32", "best_ask": "0.33"}], "timestamp": "1769384392168", "event_type": "price_change"}}
{"_local_timestamp": "2026-01-25T23:39:57.108296+00:00", "data": {"market": "0xff8bf331f7ddbdd2e92e27dcd273612ec45fefde3cf70039c4f043eaec0000c6", "price_changes": [{"asset_id": "60105600458079862676305161094044862147301593956294543970688990037138503709415", "price": "0.34", "size": "644.07", "side": "BUY", "hash": "15bac00a41ef66d86482a9e1764577fd5c386783", "best_bid": "0.36", "best_ask": "0.37"}, {"asset_id": "65943623919755331891504362129239742473111951663283351342808117545053994127220", "price": "0.66", "size": "644.07", "side": "SELL", "hash": "19033bee9155020d02d3388f6678e19d1427d55f", "best_bid": "0.63", "best_ask": "0.64"}], "timestamp": "1769384397000", "event_type": "price_change"}}
{"_local_timestamp": "2026-01-25T23:39:57.117998+00:00", "data": {"market": "0xff8bf331f7ddbdd2e92e27dcd273612ec45fefde3cf70039c4f043eaec0000c6", "price_changes": [{"asset_id": "60105600458079862676305161094044862147301593956294543970688990037138503709415", "price": "0.32", "size": "0", "side": "BUY", "hash": "d682026f56cf3f9c64a9e8eced4566f361acbd60", "best_bid": "0.36", "best_ask": "0.37"}, {"asset_id": "65943623919755331891504362129239742473111951663283351342808117545053994127220", "price": "0.68", "size": "0", "side": "SELL", "hash": "13f7a924b4323bcb7182a4a14de0ede967525270", "best_bid": "0.63", "best_ask": "0.64"}], "timestamp": "1769384397002", "event_type": "price_change"}}
{"_local_timestamp": "2026-01-25T23:39:57.118861+00:00", "data": {"market": "0xff8bf331f7ddbdd2e92e27dcd273612ec45fefde3cf70039c4f043eaec0000c6", "price_changes": [{"asset_id": "60105600458079862676305161094044862147301593956294543970688990037138503709415", "price": "0.3", "size": "310", "side": "BUY", "hash": "800e73f200a7e1d12cd5ee06d040f47d1e57933e", "best_bid": "0.36", "best_ask": "0.37"}, {"asset_id": "65943623919755331891504362129239742473111951663283351342808117545053994127220", "price": "0.7", "size": "310", "side": "SELL", "hash": "d4be784ad0118c2a8c1ecaa1aaaea1fcac40c588", "best_bid": "0.63", "best_ask": "0.64"}], "timestamp": "1769384397003", "event_type": "price_change"}}
{"_local_timestamp": "2026-01-25T23:39:58.083506+00:00", "data": {"market": "0xff8bf331f7ddbdd2e92e27dcd273612ec45fefde3cf70039c4f043eaec0000c6", "price_changes": [{"asset_id": "65943623919755331891504362129239742473111951663283351342808117545053994127220", "price": "0.59", "size": "190", "side": "BUY", "hash": "a6798cf7a254e712962b29f9858d09c82f8948c9", "best_bid": "0.63", "best_ask": "0.64"}, {"asset_id": "60105600458079862676305161094044862147301593956294543970688990037138503709415", "price": "0.41", "size": "190", "side": "SELL", "hash": "9e028c5a4683f8c6ac611284e7ed45d6c254d5d0", "best_bid": "0.36", "best_ask": "0.37"}], "timestamp": "1769384398003", "event_type": "price_change"}}
{"_local_timestamp": "2026-01-25T23:40:09.246708+00:00", "data": {"market": "0xff8bf331f7ddbdd2e92e27dcd273612ec45fefde3cf70039c4f043eaec0000c6", "price_changes": [{"asset_id": "65943623919755331891504362129239742473111951663283351342808117545053994127220", "price": "0.19", "size": "2215.57", "side": "BUY", "hash": "9d14d5a15a1bd31188167c3fa91d8e06c54eda60", "best_bid": "0.63", "best_ask": "0.64"}, {"asset_id": "60105600458079862676305161094044862147301593956294543970688990037138503709415", "price": "0.81", "size": "2215.57", "side": "SELL", "hash": "cf9c47d27c340d55eaf116a5fde3144d35cb4adb", "best_bid": "0.36", "best_ask": "0.37"}], "timestamp": "1769384409171", "event_type": "price_change"}}
{"_local_timestamp": "2026-01-25T23:40:13.532056+00:00", "data": {"market": "0x8253528e603b5cabb8ab45d1e1209bda57aa2a9f6f0d61aba7ad0a38147a86ee", "price_changes": [{"asset_id": "17667700649974143765639286018245659141526847671421069760676398956961689778433", "price": "0.66", "size": "52.64", "side": "BUY", "hash": "b3e276b0677b06ffcbcaa9ec1c60ee92c65a956f", "best_bid": "0.67", "best_ask": "0.68"}, {"asset_id": "54160287404732698543970249280129195630418658913727451612951061485607934781689", "price": "0.34", "size": "52.64", "side": "SELL", "hash": "ecb97bdee8e140a06e5af097ed7290aeb8923132", "best_bid": "0.32", "best_ask": "0.33"}], "timestamp": "1769384413461", "event_type": "price_change"}}
{"_local_timestamp": "2026-01-25T23:40:13.594766+00:00", "data": {"market": "0x892231e7fd3ac31a3b321002f909e011180b709af074808908d27a2a32a7b546", "price_changes": [{"asset_id": "64317448978406417981854076458164286249844965670717306181829295801409919530695", "price": "0.83", "size": "25", "side": "BUY", "hash": "af112ca588b97c8f180a11570884f808a463b545", "best_bid": "0.92", "best_ask": "0.93"}, {"asset_id": "89791260670398307279783201184852534466650260912467648915456704380491810882664", "price": "0.17", "size": "25", "side": "SELL", "hash": "4c37f3bf9dc7cdfd38f33dfac26873cc979a2602", "best_bid": "0.07", "best_ask": "0.08"}], "timestamp": "1769384413527", "event_type": "price_change"}}
{"_local_timestamp": "2026-01-25T23:40:13.671949+00:00", "data": {"market": "0x8253528e603b5cabb8ab45d1e1209bda57aa2a9f6f0d61aba7ad0a38147a86ee", "price_changes": [{"asset_id": "54160287404732698543970249280129195630418658913727451612951061485607934781689", "price": "0.3", "size": "550", "side": "BUY", "hash": "2de3c03629b7a2642fb7c117460dec3625fdb2d0", "best_bid": "0.32", "best_ask": "0.33"}, {"asset_id": "17667700649974143765639286018245659141526847671421069760676398956961689778433", "price": "0.7", "size": "550", "side": "SELL", "hash": "b4f2a1df1a3278a8c94f94c805a90f43a6457ff3", "best_bid": "0.67", "best_ask": "0.68"}], "timestamp": "1769384413604", "event_type": "price_change"}}
{"_local_timestamp": "2026-01-25T23:40:13.672996+00:00", "data": {"market": "0x8253528e603b5cabb8ab45d1e1209bda57aa2a9f6f0d61aba7ad0a38147a86ee", "price_changes": [{"asset_id": "17667700649974143765639286018245659141526847671421069760676398956961689778433", "price": "0.66", "size": "2.64", "side": "BUY", "hash": "989a2d87f981dd183c2f5472ff367d0eb507d8e4", "best_bid": "0.67", "best_ask": "0.68"}, {"asset_id": "54160287404732698543970249280129195630418658913727451612951061485607934781689", "price": "0.34", "size": "2.64", "side": "SELL", "hash": "2a82d07e50064087b0904e5d3a7a8fe5598f207c", "best_bid": "0.32", "best_ask": "0.33"}], "timestamp": "1769384413604", "event_type": "price_change"}}
{"_local_timestamp": "2026-01-25T23:40:13.835887+00:00", "data": {"market": "0x8253528e603b5cabb8ab45d1e1209bda57aa2a9f6f0d61aba7ad0a38147a86ee", "price_changes": [{"asset_id": "17667700649974143765639286018245659141526847671421069760676398956961689778433", "price": "0.65", "size": "226", "side": "BUY", "hash": "66401fd0c9e877377f4eedea0b08c638f50c0042", "best_bid": "0.67", "best_ask": "0.68"}, {"asset_id": "54160287404732698543970249280129195630418658913727451612951061485607934781689", "price": "0.35", "size": "226", "side": "SELL", "hash": "85bded36d01ad4d8f31cdb275833289165df435d", "best_bid": "0.32", "best_ask": "0.33"}], "timestamp": "1769384413760", "event_type": "price_change"}}
{"_local_timestamp": "2026-01-25T23:40:13.836926+00:00", "data": {"market": "0x8253528e603b5cabb8ab45d1e1209bda57aa2a9f6f0d61aba7ad0a38147a86ee", "price_changes": [{"asset_id": "54160287404732698543970249280129195630418658913727451612951061485607934781689", "price": "0.3", "size": "600", "side": "BUY", "hash": "3a624cb902f6b3401cf0b5ea5b782ec61a2f16bd", "best_bid": "0.32", "best_ask": "0.33"}, {"asset_id": "17667700649974143765639286018245659141526847671421069760676398956961689778433", "price": "0.7", "size": "600", "side": "SELL", "hash": "cd8a883e5ef1963eacac92576f2d65075be93a2e", "best_bid": "0.67", "best_ask": "0.68"}], "timestamp": "1769384413761", "event_type": "price_change"}}
