{"_local_timestamp": "2026-01-25T23:34:01.852276+00:00", "data": [{"market": "0x6fbec2c3327fe7b5392b94fe48ccb41c7404a4a793957804b4b8fe8239376d12", "asset_id": "69250819494674008903342626376731306359291370006377470819342000624771511803405", "timestamp": "1769384020409", "hash": "3eb03f6b7676dc6657a5c0c25a809deec6f02beb", "bids": [{"price": "0.001", "size": "6274.99"}, {"price": "0.002", "size": "15.81"}, {"price": "0.003", "size": "250"}, {"price": "0.004", "size": "12.43"}, {"price": "0.006", "size": "1244.2"}, {"price": "0.007", "size": "16.94"}, {"price": "0.01", "size": "116.08"}, {"price": "0.012", "size": "1111"}, {"price": "0.014", "size": "1111"}, {"price": "0.015", "size": "600"}, {"price": "0.016", "size": "391.87"}, {"price": "0.017", "size": "300"}, {"price": "0.018", "size": "200"}, {"price": "0.019", "size": "111"}, {"price": "0.02", "size": "250"}, {"price": "0.021", "size": "169"}], "asks": [{"price": "0.999", "size": "4651.99"}, {"price": "0.998", "size": "1250"}, {"price": "0.997", "size": "1172.62"}, {"price": "0.994", "size": "83"}, {"price": "0.993", "size": "9.76"}, {"price": "0.99", "size": "12450"}, {"price": "0.98", "size": "4750"}, {"price": "0.979", "size": "8.81"}, {"price": "0.96", "size": "250"}, {"price": "0.95", "size": "30"}, {"price": "0.94", "size": "1100"}, {"price": "0.939", "size": "8.89"}, {"price": "0.9", "size": "360"}, {"price": "0.85", "size": "876.66"}, {"price": "0.8", "size": "610"}, {"price": "0.799", "size": "5.84"}, {"price": "0.75", "size": "212"}, {"price": "0.7", "size": "1586.66"}, {"price": "0.65", "size": "68.57"}, {"price": "0.6", "size": "600"}, {"price": "0.596", "size": "353"}, {"price": "0.595", "size": "246"}, {"price": "0.5", "size": "10"}, {"price": "0.487", "size": "5"}, {"price": "0.48", "size": "30"}, {"price": "0.478", "size": "30"}, {"price": "0.476", "size": "75"}, {"price": "0.475", "size": "20"}, {"price": "0.079", "size": "40"}, {"price": "0.056", "size": "28.33"}, {"price": "0.054", "size": "120"}, {"price": "0.053", "size": "465.83"}, {"price": "0.052", "size": "30"}, {"price": "0.046", "size": "50"}, {"price": "0.043", "size": "15"}], "event_type": "book", "last_trade_price": "0.035"}, {"market": "0x361332f8ab0a017e877b225e96c6a35456bc1dc5d4db796c472d4f71e7a79d54", "asset_id": "63660917184917833894774068366011139137101685355449306463901993722479265901077", "timestamp": "1769383931859", "hash": "7de4fe9fcf65c90bbffa6eb9ce3619e32a9a02b1", "bids": [{"price": "0.001", "size": "4666.43"}, {"price": "0.002", "size": "1250"}, {"price": "0.003", "size": "1172.62"}, {"price": "0.006", "size": "83"}, {"price": "0.007", "size": "9.76"}, {"price": "0.01", "size": "12450"}, {"price": "0.02", "size": "4750"}, {"price": "0.021", "size": "8.81"}, {"price": "0.04", "size": "250"}, {"price": "0.05", "size": "30"}, {"price": "0.06", "size": "1100"}, {"price": "0.061", "size": "8.89"}, {"price": "0.1", "size": "360"}, {"price": "0.15", "size": "876.66"}, {"price": "0.2", "size": "610"}, {"price": "0.201", "size": "5.84"}, {"price": "0.223", "size": "40"}, {"price": "0.25", "size": "212"}, {"price": "0.3", "size": "1586.66"}, {"price": "0.301", "size": "250"}, {"price": "0.35", "size": "68.57"}, {"price": "0.4", "size": "675"}, {"price": "0.5", "size": "10"}, {"price": "0.523", "size": "19"}, {"price": "0.53", "size": "754"}, {"price": "0.531", "size": "5"}, {"price": "0.723", "size": "8"}, {"price": "0.823", "size": "30"}, {"price": "0.831", "size": "120"}, {"price": "0.832", "size": "30"}, {"price": "0.923", "size": "9"}, {"price": "0.929", "size": "30"}, {"price": "0.93", "size": "60"}, {"price": "0.95", "size": "10"}, {"price": "0.951", "size": "40"}, {"price": "0.98", "size": "20"}, {"price": "0.995", "size": "214"}, {"price": "0.996", "size": "753.82"}, {"price": "0.997", "size": "1075.18"}], "asks": [{"price": "0.999", "size": "2353"}], "event_type": "book", "last_trade_price": "0.001"}, {"market": "0xfebf77a5fafe69270ae88267592d6af563d5fb8038167c1e5f0f84389a180b24", "asset_id": "108070880530079055956658493954731541905445967268057229566528793256732992302888", "timestamp": "1769383994558", "hash": "472d2fc717946e61c80fab184839c26e682304ab", "bids": [{"price": "0.001", "size": "4651.99"}, {"price": "0.002", "size": "1250"}, {"price": "0.003", "size": "1172.62"}, {"price": "0.006", "size": "83"}, {"price": "0.007", "size": "9.76"}, {"price": "0.01", "size": "12450"}, {"price": "0.02", "size": "4750"}, {"price": "0.021", "size": "8.81"}, {"price": "0.04", "size": "250"}, {"price": "0.05", "size": "30"}, {"price": "0.06", "size": "1100"}, {"price": "0.061", "size": "8.34"}, {"price": "0.1", "size": "360"}, {"price": "0.11", "size": "152"}, {"price": "0.15", "size": "876.66"}, {"price": "0.19", "size": "568.42"}, {"price": "0.191", "size": "6.32"}, {"price": "0.24", "size": "266.66"}, {"price": "0.29", "size": "89.65"}, {"price": "0.3", "size": "1500"}, {"price": "0.301", "size": "250"}, {"price": "0.34", "size": "70.58"}, {"price": "0.39", "size": "51.28"}, {"price": "0.4", "size": "625"}, {"price": "0.5", "size": "570"}, {"price": "0.501", "size": "5"}, {"price": "0.737", "size": "542"}, {"price": "0.738", "size": "100"}, {"price": "0.867", "size": "115"}, {"price": "0.871", "size": "70"}, {"price": "0.872", "size": "20"}, {"price": "0.907", "size": "100"}, {"price": "0.908", "size": "60"}, {"price": "0.937", "size": "169"}, {"price": "0.945", "size": "20"}, {"price": "0.949", "size": "120"}, {"price": "0.95", "size": "18.75"}, {"price": "0.955", "size": "139.4"}, {"price": "0.956", "size": "1.04"}], "asks": [{"price": "0.999", "size": "9653.1"}, {"price": "0.998", "size": "1167.2"}, {"price": "0.997", "size": "250"}, {"price": "0.996", "size": "21.56"}, {"price": "0.99", "size": "255"}, {"price": "0.989", "size": "214"}, {"price": "0.988", "size": "184"}, {"price": "0.987", "size": "228"}, {"price": "0.986", "size": "4024.12"}, {"price": "0.985", "size": "317"}, {"price": "0.984", "size": "263"}, {"price": "0.983", "size": "278.84"}, {"price": "0.982", "size": "128"}, {"price": "0.981", "size": "102"}, {"price": "0.98", "size": "278"}, {"price": "0.979", "size": "102"}, {"price": "0.978", "size": "118"}, {"price": "0.977", "size": "237"}, {"price": "0.976", "size": "51"}, {"price": "0.975", "size": "213"}, {"price": "0.974", "size": "77"}, {"price": "0.973", "size": "51"}, {"price": "0.972", "size": "178"}, {"price": "0.971", "size": "110"}, {"price": "0.97", "size": "188"}, {"price": "0.969", "size": "177"}, {"price": "0.968", "size": "184"}, {"price": "0.967", "size": "127"}, {"price": "0.966", "size": "46"}, {"price": "0.965", "size": "138"}, {"price": "0.964", "size": "62"}, {"price": "0.963", "size": "133.2"}, {"price": "0.962", "size": "86.2"}, {"price": "0.961", "size": "63.7"}, {"price": "0.96", "size": "44"}, {"price": "0.959", "size": "50"}, {"price": "0.958", "size": "20"}, {"price": "0.957", "size": "25"}], "event_type": "book", "last_trade_price": "0.042"}, {"market": "0xb33b725b5d036ea8a985e48575741a80fdd03c62594c4fd50a78262a8828f3bc", "asset_id": "31149081762088969942763379802686427337613385334314243033011263865324034142513", "timestamp": "1769383991925", "hash": "cb46f935a497d8122726301d6734fba5a5fac249", "bids": [{"price": "0.001", "size": "4666.43"}, {"price": "0.002", "size": "1250"}, {"price": "0.003", "size": "1172.62"}, {"price": "0.006", "size": "83"}, {"price": "0.007", "size": "9.76"}, {"price": "0.01", "size": "12450"}, {"price": "0.02", "size": "4750"}, {"price": "0.021", "size": "8.81"}, {"price": "0.04", "size": "250"}, {"price": "0.05", "size": "30"}, {"price": "0.06", "size": "1100"}, {"price": "0.061", "size": "8.89"}, {"price": "0.1", "size": "360"}, {"price": "0.15", "size": "876.66"}, {"price": "0.193", "size": "400"}, {"price": "0.2", "size": "160"}, {"price": "0.201", "size": "5.84"}, {"price": "0.223", "size": "22"}, {"price": "0.25", "size": "262"}, {"price": "0.3", "size": "1586.66"}, {"price": "0.301", "size": "250"}, {"price": "0.35", "size": "68.57"}, {"price": "0.4", "size": "675"}, {"price": "0.5", "size": "10"}, {"price": "0.523", "size": "44"}, {"price": "0.542", "size": "5"}, {"price": "0.544", "size": "917"}, {"price": "0.545", "size": "30"}, {"price": "0.92", "size": "10"}, {"price": "0.923", "size": "28"}, {"price": "0.924", "size": "20"}, {"price": "0.931", "size": "30"}, {"price": "0.932", "size": "40"}, {"price": "0.943", "size": "20"}, {"price": "0.99", "size": "20"}, {"price": "0.995", "size": "406"}, {"price": "0.996", "size": "1833.29"}], "asks": [{"price": "0.999", "size": "2746"}], "event_type": "book", "last_trade_price": "0.001"}, {"market": "0x6fbec2c3327fe7b5392b94fe48ccb41c7404a4a793957804b4b8fe8239376d12", "asset_id": "74232891440125659542320690757580411929973234713273124974412544144242477879854", "timestamp": "1769384020409", "hash": "a886300aaa9f563cb51c0163fa431c29b2d4eaa8", "bids": [{"price": "0.001", "size": "4651.99"}, {"price": "0.002", "size": "1250"}, {"price": "0.003", "size": "1172.62"}, {"price": "0.006", "size": "83"}, {"price": "0.007", "size": "9.76"}, {"price": "0.01", "size": "12450"}, {"price": "0.02", "size": "4750"}, {"price": "0.021", "size": "8.81"}, {"price": "0.04", "size": "250"}, {"price": "0.05", "size": "30"}, {"price": "0.06", "size": "1100"}, {"price": "0.061", "size": "8.89"}, {"price": "0.1", "size": "360"}, {"price": "0.15", "size": "876.66"}, {"price": "0.2", "size": "610"}, {"price": "0.201", "size": "5.84"}, {"price": "0.25", "size": "212"}, {"price": "0.3", "size": "1586.66"}, {"price": "0.35", "size": "68.57"}, {"price": "0.4", "size": "600"}, {"price": "0.404", "size": "353"}, {"price": "0.405", "size": "246"}, {"price": "0.5", "size": "10"}, {"price": "0.513", "size": "5"}, {"price": "0.52", "size": "30"}, {"price": "0.522", "size": "30"}, {"price": "0.524", "size": "75"}, {"price": "0.525", "size": "20"}, {"price": "0.921", "size": "40"}, {"price": "0.944", "size": "28.33"}, {"price": "0.946", "size": "120"}, {"price": "0.947", "size": "465.83"}, {"price": "0.948", "size": "30"}, {"price": "0.954", "size": "50"}, {"price": "0.957", "size": "15"}], "asks": [{"price": "0.999", "size": "6274.99"}, {"price": "0.998", "size": "15.81"}, {"price": "0.997", "size": "250"}, {"price": "0.996", "size": "12.43"}, {"price": "0.994", "size": "1244.2"}, {"price": "0.993", "size": "16.94"}, {"price": "0.99", "size": "116.08"}, {"price": "0.988", "size": "1111"}, {"price": "0.986", "size": "1111"}, {"price": "0.985", "size": "600"}, {"price": "0.984", "size": "391.87"}, {"price": "0.983", "size": "300"}, {"price": "0.982", "size": "200"}, {"price": "0.981", "size": "111"}, {"price": "0.98", "size": "250"}, {"price": "0.979", "size": "169"}], "event_type": "book", "last_trade_price": "0.035"}, {"market": "0x420515ec56344b733661a732c2076be30c1e781a8ac0be429e7922dd1300f79e", "asset_id": "39911463294518973837477734365182517604962845619791762903432415094009656664664", "timestamp": "1769383990224", "hash": "b91c6944e8c1f4f10befc8bc7f613091367ad02a", "bids": [{"price": "0.001", "size": "9811.83"}, {"price": "0.002", "size": "3960"}, {"price": "0.003", "size": "250"}, {"price": "0.004", "size": "275"}, {"price": "0.007", "size": "1000"}, {"price": "0.008", "size": "752.5"}, {"price": "0.009", "size": "300"}, {"price": "0.01", "size": "416"}], "asks": [{"price": "0.999", "size": "4651.99"}, {"price": "0.998", "size": "1250"}, {"price": "0.997", "size": "1172.62"}, {"price": "0.994", "size": "83"}, {"price": "0.993", "size": "9.76"}, {"price": "0.99", "size": "12450"}, {"price": "0.98", "size": "4750"}, {"price": "0.979", "size": "8.81"}, {"price": "0.96", "size": "250"}, {"price": "0.95", "size": "30"}, {"price": "0.94", "size": "1100"}, {"price": "0.939", "size": "8.89"}, {"price": "0.9", "size": "360"}, {"price": "0.85", "size": "876.66"}, {"price": "0.8", "size": "610"}, {"price": "0.799", "size": "5.84"}, {"price": "0.777", "size": "41"}, {"price": "0.75", "size": "212"}, {"price": "0.7", "size": "1586.66"}, {"price": "0.699", "size": "250"}, {"price": "0.65", "size": "68.57"}, {"price": "0.6", "size": "675"}, {"price": "0.5", "size": "10"}, {"price": "0.477", "size": "185"}, {"price": "0.277", "size": "8"}, {"price": "0.275", "size": "550"}, {"price": "0.177", "size": "24"}, {"price": "0.155", "size": "118"}, {"price": "0.153", "size": "30"}, {"price": "0.152", "size": "20"}, {"price": "0.077", "size": "93"}, {"price": "0.074", "size": "30"}, {"price": "0.072", "size": "40"}, {"price": "0.05", "size": "10"}, {"price": "0.03", "size": "303.71"}, {"price": "0.029", "size": "100"}, {"price": "0.025", "size": "300"}, {"price": "0.024", "size": "155"}, {"price": "0.018", "size": "91.05"}, {"price": "0.017", "size": "0.5"}, {"price": "0.016", "size": "111"}, {"price": "0.015", "size": "11.25"}], "event_type": "book", "last_trade_price": "0.009"}, {"market": "0xfebf77a5fafe69270ae88267592d6af563d5fb8038167c1e5f0f84389a180b24", "asset_id": "22601624556062096769343443867020199590792651484414597499875211914147125190628", "timestamp": "1769383994558", "hash": "30f878b1dd9cfd559cb3ce78994c4bd780dff5ae", "bids": [{"price": "0.001", "size": "9653.1"}, {"price": "0.002", "size": "1167.2"}, {"price": "0.003", "size": "250"}, {"price": "0.004", "size": "21.56"}, {"price": "0.01", "size": "255"}, {"price": "0.011", "size": "214"}, {"price": "0.012", "size": "184"}, {"price": "0.013", "size": "228"}, {"price": "0.014", "size": "4024.12"}, {"price": "0.015", "size": "317"}, {"price": "0.016", "size": "263"}, {"price": "0.017", "size": "278.84"}, {"price": "0.018", "size": "128"}, {"price": "0.019", "size": "102"}, {"price": "0.02", "size": "278"}, {"price": "0.021", "size": "102"}, {"price": "0.022", "size": "118"}, {"price": "0.023", "size": "237"}, {"price": "0.024", "size": "51"}, {"price": "0.025", "size": "213"}, {"price": "0.026", "size": "77"}, {"price": "0.027", "size": "51"}, {"price": "0.028", "size": "178"}, {"price": "0.029", "size": "110"}, {"price": "0.03", "size": "188"}, {"price": "0.031", "size": "177"}, {"price": "0.032", "size": "184"}, {"price": "0.033", "size": "127"}, {"price": "0.034", "size": "46"}, {"price": "0.035", "size": "138"}, {"price": "0.036", "size": "62"}, {"price": "0.037", "size": "133.2"}, {"price": "0.038", "size": "86.2"}, {"price": "0.039", "size": "63.7"}, {"price": "0.04", "size": "44"}, {"price": "0.041", "size": "50"}, {"price": "0.042", "size": "20"}, {"price": "0.043", "size": "25"}], "asks": [{"price": "0.999", "size": "4651.99"}, {"price": "0.998", "size": "1250"}, {"price": "0.997", "size": "1172.62"}, {"price": "0.994", "size": "83"}, {"price": "0.993", "size": "9.76"}, {"price": "0.99", "size": "12450"}, {"price": "0.98", "size": "4750"}, {"price": "0.979", "size": "8.81"}, {"price": "0.96", "size": "250"}, {"price": "0.95", "size": "30"}, {"price": "0.94", "size": "1100"}, {"price": "0.939", "size": "8.34"}, {"price": "0.9", "size": "360"}, {"price": "0.89", "size": "152"}, {"price": "0.85", "size": "876.66"}, {"price": "0.81", "size": "568.42"}, {"price": "0.809", "size": "6.32"}, {"price": "0.76", "size": "266.66"}, {"price": "0.71", "size": "89.65"}, {"price": "0.7", "size": "1500"}, {"price": "0.699", "size": "250"}, {"price": "0.66", "size": "70.58"}, {"price": "0.61", "size": "51.28"}, {"price": "0.6", "size": "625"}, {"price": "0.5", "size": "570"}, {"price": "0.499", "size": "5"}, {"price": "0.263", "size": "542"}, {"price": "0.262", "size": "100"}, {"price": "0.133", "size": "115"}, {"price": "0.129", "size": "70"}, {"price": "0.128", "size": "20"}, {"price": "0.093", "size": "100"}, {"price": "0.092", "size": "60"}, {"price": "0.063", "size": "169"}, {"price": "0.055", "size": "20"}, {"price": "0.051", "size": "120"}, {"price": "0.05", "size": "18.75"}, {"price": "0.045", "size": "139.4"}, {"price": "0.044", "size": "1.04"}], "event_type": "book", "last_trade_price": "0.042"}, {"market": "0x9bc5720d23d592694c23887fcd8b6d35539e92af075b2728f657759e2c5e052a", "asset_id": "48643754635794126190539156998000748582503350780297050847722155145066582538948", "timestamp": "1769384016254", "hash": "c7c4bdddc9a24b720b622d9c08345be9be333ca3", "bids": [{"price": "0.001", "size": "2853"}], "asks": [{"price": "0.999", "size": "4666.43"}, {"price": "0.998", "size": "1250"}, {"price": "0.997", "size": "1172.62"}, {"price": "0.994", "size": "83"}, {"price": "0.993", "size": "9.76"}, {"price": "0.99", "size": "12450"}, {"price": "0.98", "size": "4750"}, {"price": "0.979", "size": "8.81"}, {"price": "0.96", "size": "250"}, {"price": "0.95", "size": "30"}, {"price": "0.94", "size": "1100"}, {"price": "0.939", "size": "8.89"}, {"price": "0.9", "size": "360"}, {"price": "0.85", "size": "876.66"}, {"price": "0.8", "size": "610"}, {"price": "0.799", "size": "5.84"}, {"price": "0.777", "size": "19"}, {"price": "0.75", "size": "212"}, {"price": "0.7", "size": "1586.66"}, {"price": "0.699", "size": "250"}, {"price": "0.65", "size": "68.57"}, {"price": "0.6", "size": "675"}, {"price": "0.5", "size": "10"}, {"price": "0.477", "size": "8"}, {"price": "0.472", "size": "756"}, {"price": "0.471", "size": "5"}, {"price": "0.277", "size": "7"}, {"price": "0.177", "size": "20"}, {"price": "0.165", "size": "119"}, {"price": "0.164", "size": "30"}, {"price": "0.077", "size": "15"}, {"price": "0.076", "size": "20"}, {"price": "0.067", "size": "30"}, {"price": "0.066", "size": "40"}, {"price": "0.05", "size": "10"}, {"price": "0.02", "size": "20"}, {"price": "0.005", "size": "117.35"}, {"price": "0.004", "size": "942.82"}, {"price": "0.003", "size": "845.18"}, {"price": "0.002", "size": "310"}], "event_type": "book", "last_trade_price": "0.001"}, {"market": "0x2bc8904e63111922dbb8aa2ecbd935c10130ceeb5167c3a1cd48989e504d65cd", "asset_id": "43967046964650296862718544762979896408581681199546182297336634987235910393568", "timestamp": "1769383927791", "hash": "e3e884c83d8cfedb42e2b495541987b9007b8b4d", "bids": [{"price": "0.001", "size": "4666.43"}, {"price": "0.002", "size": "1250"}, {"price": "0.003", "size": "1172.62"}, {"price": "0.006", "size": "83"}, {"price": "0.007", "size": "9.76"}, {"price": "0.01", "size": "12450"}, {"price": "0.02", "size": "4750"}, {"price": "0.021", "size": "8.81"}, {"price": "0.04", "size": "250"}, {"price": "0.05", "size": "30"}, {"price": "0.06", "size": "1100"}, {"price": "0.061", "size": "8.89"}, {"price": "0.1", "size": "360"}, {"price": "0.15", "size": "876.66"}, {"price": "0.2", "size": "610"}, {"price": "0.201", "size": "5.84"}, {"price": "0.223", "size": "14"}, {"price": "0.25", "size": "212"}, {"price": "0.3", "size": "1586.66"}, {"price": "0.301", "size": "250"}, {"price": "0.35", "size": "68.57"}, {"price": "0.4", "size": "675"}, {"price": "0.5", "size": "10"}, {"price": "0.523", "size": "85"}, {"price": "0.526", "size": "760"}, {"price": "0.723", "size": "44"}, {"price": "0.823", "size": "42"}, {"price": "0.833", "size": "120"}, {"price": "0.834", "size": "30"}, {"price": "0.835", "size": "20"}, {"price": "0.923", "size": "5"}, {"price": "0.93", "size": "70"}, {"price": "0.95", "size": "16.66"}, {"price": "0.99", "size": "20"}, {"price": "0.995", "size": "241.36"}, {"price": "0.996", "size": "190.82"}, {"price": "0.998", "size": "1000"}], "asks": [{"price": "0.999", "size": "1361"}], "event_type": "book", "last_trade_price": "0.001"}, {"market": "0x50e54348ebdc5218e17ab7cec6c6d1bda4816f979984717cf462d816921255d6", "asset_id": "82547212645026470525278120787743350118721505496069116064469109192086879778892", "timestamp": "1769384005402", "hash": "135ff91c739a16fdbcf109cfdcccaf322dc6952a", "bids": [{"price": "0.01", "size": "7650"}, {"price": "0.02", "size": "3000"}, {"price": "0.03", "size": "6.66"}, {"price": "0.05", "size": "30"}, {"price": "0.09", "size": "1400"}, {"price": "0.14", "size": "792.85"}, {"price": "0.19", "size": "668.42"}, {"price": "0.23", "size": "421.73"}, {"price": "0.24", "size": "160"}, {"price": "0.28", "size": "192.85"}, {"price": "0.33", "size": "72.72"}, {"price": "0.38", "size": "177.63"}, {"price": "0.85", "size": "100"}, {"price": "0.89", "size": "120"}, {"price": "0.9", "size": "1990.91"}], "asks": [{"price": "0.99", "size": "4637.36"}, {"price": "0.98", "size": "2303.6"}, {"price": "0.97", "size": "1310.69"}, {"price": "0.96", "size": "75.14"}, {"price": "0.95", "size": "10.86"}, {"price": "0.94", "size": "30"}, {"price": "0.93", "size": "205.29"}, {"price": "0.92", "size": "1638"}], "event_type": "book", "last_trade_price": "0.090"}, {"market": "0x37d7295a17db461c15867862afe90bfad6cd46436b0d121a7c96c37e166103b4", "asset_id": "48325180813773997762337012603425087662105904105229463158116317479132765545801", "timestamp": "1769384038796", "hash": "b5a0924e1d6ac2422736f08aff5b759f9405538e", "bids": [{"price": "0.001", "size": "4651.99"}, {"price": "0.002", "size": "1250"}, {"price": "0.003", "size": "1172.62"}, {"price": "0.006", "size": "83"}, {"price": "0.007", "size": "9.76"}, {"price": "0.01", "size": "12450"}, {"price": "0.02", "size": "4750"}, {"price": "0.021", "size": "8.81"}, {"price": "0.04", "size": "250"}, {"price": "0.05", "size": "30"}, {"price": "0.06", "size": "1100"}, {"price": "0.061", "size": "8.89"}, {"price": "0.1", "size": "360"}, {"price": "0.15", "size": "876.66"}, {"price": "0.2", "size": "610"}, {"price": "0.201", "size": "5.84"}, {"price": "0.25", "size": "212"}, {"price": "0.3", "size": "1486.66"}, {"price": "0.301", "size": "1764.15"}, {"price": "0.302", "size": "250"}, {"price": "0.35", "size": "68.57"}, {"price": "0.4", "size": "675"}, {"price": "0.5", "size": "10"}, {"price": "0.504", "size": "100"}, {"price": "0.508", "size": "5"}, {"price": "0.511", "size": "232.49"}, {"price": "0.512", "size": "500"}, {"price": "0.513", "size": "389"}, {"price": "0.878", "size": "81"}, {"price": "0.918", "size": "108"}, {"price": "0.92", "size": "100"}, {"price": "0.921", "size": "20"}, {"price": "0.933", "size": "101.39"}, {"price": "0.934", "size": "30"}, {"price": "0.935", "size": "40"}, {"price": "0.96", "size": "3.75"}, {"price": "0.962", "size": "20"}, {"price": "0.973", "size": "100"}, {"price": "0.988", "size": "28.75"}, {"price": "0.989", "size": "16"}], "asks": [{"price": "0.999", "size": "10440.99"}, {"price": "0.998", "size": "7790.17"}], "event_type": "book", "last_trade_price": "0.005"}, {"market": "0x361332f8ab0a017e877b225e96c6a35456bc1dc5d4db796c472d4f71e7a79d54", "asset_id": "78192483840796682442570224034600338690521812139428085048513940589175925504286", "timestamp": "1769383931859", "hash": "2f97b55c63aec1dc26543c8e50b7417a127538b9", "bids": [{"price": "0.001", "size": "2353"}], "asks": [{"price": "0.999", "size": "4666.43"}, {"price": "0.998", "size": "1250"}, {"price": "0.997", "size": "1172.62"}, {"price": "0.994", "size": "83"}, {"price": "0.993", "size": "9.76"}, {"price": "0.99", "size": "12450"}, {"price": "0.98", "size": "4750"}, {"price": "0.979", "size": "8.81"}, {"price": "0.96", "size": "250"}, {"price": "0.95", "size": "30"}, {"price": "0.94", "size": "1100"}, {"price": "0.939", "size": "8.89"}, {"price": "0.9", "size": "360"}, {"price": "0.85", "size": "876.66"}, {"price": "0.8", "size": "610"}, {"price": "0.799", "size": "5.84"}, {"price": "0.777", "size": "40"}, {"price": "0.75", "size": "212"}, {"price": "0.7", "size": "1586.66"}, {"price": "0.699", "size": "250"}, {"price": "0.65", "size": "68.57"}, {"price": "0.6", "size": "675"}, {"price": "0.5", "size": "10"}, {"price": "0.477", "size": "19"}, {"price": "0.47", "size": "754"}, {"price": "0.469", "size": "5"}, {"price": "0.277", "size": "8"}, {"price": "0.177", "size": "30"}, {"price": "0.169", "size": "120"}, {"price": "0.168", "size": "30"}, {"price": "0.077", "size": "9"}, {"price": "0.071", "size": "30"}, {"price": "0.07", "size": "60"}, {"price": "0.05", "size": "10"}, {"price": "0.049", "size": "40"}, {"price": "0.02", "size": "20"}, {"price": "0.005", "size": "214"}, {"price": "0.004", "size": "753.82"}, {"price": "0.003", "size": "1075.18"}], "event_type": "book", "last_trade_price": "0.001"}, {"market": "0xe21927aed7f37b97b3da0f8dae29844554a0c06b695ee58c1465a105185eb33e", "asset_id": "27205696394091557108638912684699554725755342634915120683096364284362973612843", "timestamp": "1769383925225", "hash": "757c01c6de8b6a92e7925605f84274f6946b3bce", "bids": [{"price": "0.001", "size": "2854"}], "asks": [{"price": "0.999", "size": "4666.43"}, {"price": "0.998", "size": "1250"}, {"price": "0.997", "size": "1172.62"}, {"price": "0.994", "size": "83"}, {"price": "0.993", "size": "9.76"}, {"price": "0.99", "size": "12450"}, {"price": "0.98", "size": "4750"}, {"price": "0.979", "size": "8.81"}, {"price": "0.96", "size": "250"}, {"price": "0.95", "size": "30"}, {"price": "0.94", "size": "1100"}, {"price": "0.939", "size": "8.89"}, {"price": "0.9", "size": "360"}, {"price": "0.85", "size": "876.66"}, {"price": "0.8", "size": "610"}, {"price": "0.799", "size": "5.84"}, {"price": "0.777", "size": "41"}, {"price": "0.75", "size": "212"}, {"price": "0.7", "size": "1586.66"}, {"price": "0.699", "size": "250"}, {"price": "0.65", "size": "68.57"}, {"price": "0.6", "size": "675"}, {"price": "0.5", "size": "10"}, {"price": "0.477", "size": "51"}, {"price": "0.471", "size": "5"}, {"price": "0.469", "size": "752"}, {"price": "0.277", "size": "44"}, {"price": "0.177", "size": "8"}, {"price": "0.173", "size": "120"}, {"price": "0.172", "size": "30"}, {"price": "0.077", "size": "60"}, {"price": "0.076", "size": "20"}, {"price": "0.065", "size": "30"}, {"price": "0.064", "size": "40"}, {"price": "0.012", "size": "20"}, {"price": "0.011", "size": "200"}, {"price": "0.005", "size": "232.29"}, {"price": "0.004", "size": "290.82"}, {"price": "0.003", "size": "522"}, {"price": "0.002", "size": "489.18"}], "event_type": "book", "last_trade_price": "0.002"}, {"market": "0x37d7295a17db461c15867862afe90bfad6cd46436b0d121a7c96c37e166103b4", "asset_id": "65341950601583802479848929397121491003949963027873255906537010617800365051709", "timestamp": "1769384038796", "hash": "487a7e3e99adc55a8d469a31bebdeaa0e2f5aa3a", "bids": [{"price": "0.001", "size": "10440.99"}, {"price": "0.002", "size": "7790.17"}], "asks": [{"price": "0.999", "size": "4651.99"}, {"price": "0.998", "size": "1250"}, {"price": "0.997", "size": "1172.62"}, {"price": "0.994", "size": "83"}, {"price": "0.993", "size": "9.76"}, {"price": "0.99", "size": "12450"}, {"price": "0.98", "size": "4750"}, {"price": "0.979", "size": "8.81"}, {"price": "0.96", "size": "250"}, {"price": "0.95", "size": "30"}, {"price": "0.94", "size": "1100"}, {"price": "0.939", "size": "8.89"}, {"price": "0.9", "size": "360"}, {"price": "0.85", "size": "876.66"}, {"price": "0.8", "size": "610"}, {"price": "0.799", "size": "5.84"}, {"price": "0.75", "size": "212"}, {"price": "0.7", "size": "1486.66"}, {"price": "0.699", "size": "1764.15"}, {"price": "0.698", "size": "250"}, {"price": "0.65", "size": "68.57"}, {"price": "0.6", "size": "675"}, {"price": "0.5", "size": "10"}, {"price": "0.496", "size": "100"}, {"price": "0.492", "size": "5"}, {"price": "0.489", "size": "232.49"}, {"price": "0.488", "size": "500"}, {"price": "0.487", "size": "389"}, {"price": "0.122", "size": "81"}, {"price": "0.082", "size": "108"}, {"price": "0.08", "size": "100"}, {"price": "0.079", "size": "20"}, {"price": "0.067", "size": "101.39"}, {"price": "0.066", "size": "30"}, {"price": "0.065", "size": "40"}, {"price": "0.04", "size": "3.75"}, {"price": "0.038", "size": "20"}, {"price": "0.027", "size": "100"}, {"price": "0.012", "size": "28.75"}, {"price": "0.011", "size": "16"}], "event_type": "book", "last_trade_price": "0.005"}, {"market": "0x50e54348ebdc5218e17ab7cec6c6d1bda4816f979984717cf462d816921255d6", "asset_id": "68807170344581978269785042777291531812907438296702298129119130028792894246621", "timestamp": "1769384005402", "hash": "2d00becd270f773f942ddd5b9161e489e72bed22", "bids": [{"price": "0.01", "size": "4637.36"}, {"price": "0.02", "size": "2303.6"}, {"price": "0.03", "size": "1310.69"}, {"price": "0.04", "size": "75.14"}, {"price": "0.05", "size": "10.86"}, {"price": "0.06", "size": "30"}, {"price": "0.07", "size": "205.29"}, {"price": "0.08", "size": "1638"}], "asks": [{"price": "0.99", "size": "7650"}, {"price": "0.98", "size": "3000"}, {"price": "0.97", "size": "6.66"}, {"price": "0.95", "size": "30"}, {"price": "0.91", "size": "1400"}, {"price": "0.86", "size": "792.85"}, {"price": "0.81", "size": "668.42"}, {"price": "0.77", "size": "421.73"}, {"price": "0.76", "size": "160"}, {"price": "0.72", "size": "192.85"}, {"price": "0.67", "size": "72.72"}, {"price": "0.62", "size": "177.63"}, {"price": "0.15", "size": "100"}, {"price": "0.11", "size": "120"}, {"price": "0.1", "size": "1990.91"}], "event_type": "book", "last_trade_price": "0.090"}, {"market": "0x9bc5720d23d592694c23887fcd8b6d35539e92af075b2728f657759e2c5e052a", "asset_id": "46500736585935410722878126879156721902246353798527200657348291352172318380877", "timestamp": "1769384016254", "hash": "8a88862a4b477e4de5b82083b25e408c1590a0ac", "bids": [{"price": "0.001", "size": "4666.43"}, {"price": "0.002", "size": "1250"}, {"price": "0.003", "size": "1172.62"}, {"price": "0.006", "size": "83"}, {"price": "0.007", "size": "9.76"}, {"price": "0.01", "size": "12450"}, {"price": "0.02", "size": "4750"}, {"price": "0.021", "size": "8.81"}, {"price": "0.04", "size": "250"}, {"price": "0.05", "size": "30"}, {"price": "0.06", "size": "1100"}, {"price": "0.061", "size": "8.89"}, {"price": "0.1", "size": "360"}, {"price": "0.15", "size": "876.66"}, {"price": "0.2", "size": "610"}, {"price": "0.201", "size": "5.84"}, {"price": "0.223", "size": "19"}, {"price": "0.25", "size": "212"}, {"price": "0.3", "size": "1586.66"}, {"price": "0.301", "size": "250"}, {"price": "0.35", "size": "68.57"}, {"price": "0.4", "size": "675"}, {"price": "0.5", "size": "10"}, {"price": "0.523", "size": "8"}, {"price": "0.528", "size": "756"}, {"price": "0.529", "size": "5"}, {"price": "0.723", "size": "7"}, {"price": "0.823", "size": "20"}, {"price": "0.835", "size": "119"}, {"price": "0.836", "size": "30"}, {"price": "0.923", "size": "15"}, {"price": "0.924", "size": "20"}, {"price": "0.933", "size": "30"}, {"price": "0.934", "size": "40"}, {"price": "0.95", "size": "10"}, {"price": "0.98", "size": "20"}, {"price": "0.995", "size": "117.35"}, {"price": "0.996", "size": "942.82"}, {"price": "0.997", "size": "845.18"}, {"price": "0.998", "size": "310"}], "asks": [{"price": "0.999", "size": "2853"}], "event_type": "book", "last_trade_price": "0.001"}, {"market": "0xe21927aed7f37b97b3da0f8dae29844554a0c06b695ee58c1465a105185eb33e", "asset_id": "17611564877584596451721564718932558734242755214633070878064166531195879985090", "timestamp": "1769383925225", "hash": "016dec6d30585e6177c28534f33272eec0de1dda", "bids": [{"price": "0.001", "size": "4666.43"}, {"price": "0.002", "size": "1250"}, {"price": "0.003", "size": "1172.62"}, {"price": "0.006", "size": "83"}, {"price": "0.007", "size": "9.76"}, {"price": "0.01", "size": "12450"}, {"price": "0.02", "size": "4750"}, {"price": "0.021", "size": "8.81"}, {"price": "0.04", "size": "250"}, {"price": "0.05", "size": "30"}, {"price": "0.06", "size": "1100"}, {"price": "0.061", "size": "8.89"}, {"price": "0.1", "size": "360"}, {"price": "0.15", "size": "876.66"}, {"price": "0.2", "size": "610"}, {"price": "0.201", "size": "5.84"}, {"price": "0.223", "size": "41"}, {"price": "0.25", "size": "212"}, {"price": "0.3", "size": "1586.66"}, {"price": "0.301", "size": "250"}, {"price": "0.35", "size": "68.57"}, {"price": "0.4", "size": "675"}, {"price": "0.5", "size": "10"}, {"price": "0.523", "size": "51"}, {"price": "0.529", "size": "5"}, {"price": "0.531", "size": "752"}, {"price": "0.723", "size": "44"}, {"price": "0.823", "size": "8"}, {"price": "0.827", "size": "120"}, {"price": "0.828", "size": "30"}, {"price": "0.923", "size": "60"}, {"price": "0.924", "size": "20"}, {"price": "0.935", "size": "30"}, {"price": "0.936", "size": "40"}, {"price": "0.988", "size": "20"}, {"price": "0.989", "size": "200"}, {"price": "0.995", "size": "232.29"}, {"price": "0.996", "size": "290.82"}, {"price": "0.997", "size": "522"}, {"price": "0.998", "size": "489.18"}], "asks": [{"price": "0.999", "size": "2854"}], "event_type": "book", "last_trade_price": "0.002"}, {"market": "0x2bc8904e63111922dbb8aa2ecbd935c10130ceeb5167c3a1cd48989e504d65cd", "asset_id": "11968900827408027706057371039694540476481122819980191101376609555175318452594", "timestamp": "1769383927791", "hash": "d3d5e725f1c8d4926b541d6ce02afdf9504c93da", "bids": [{"price": "0.001", "size": "1361"}], "asks": [{"price": "0.999", "size": "4666.43"}, {"price": "0.998", "size": "1250"}, {"price": "0.997", "size": "1172.62"}, {"price": "0.994", "size": "83"}, {"price": "0.993", "size": "9.76"}, {"price": "0.99", "size": "12450"}, {"price": "0.98", "size": "4750"}, {"price": "0.979", "size": "8.81"}, {"price": "0.96", "size": "250"}, {"price": "0.95", "size": "30"}, {"price": "0.94", "size": "1100"}, {"price": "0.939", "size": "8.89"}, {"price": "0.9", "size": "360"}, {"price": "0.85", "size": "876.66"}, {"price": "0.8", "size": "610"}, {"price": "0.799", "size": "5.84"}, {"price": "0.777", "size": "14"}, {"price": "0.75", "size": "212"}, {"price": "0.7", "size": "1586.66"}, {"price": "0.699", "size": "250"}, {"price": "0.65", "size": "68.57"}, {"price": "0.6", "size": "675"}, {"price": "0.5", "size": "10"}, {"price": "0.477", "size": "85"}, {"price": "0.474", "size": "760"}, {"price": "0.277", "size": "44"}, {"price": "0.177", "size": "42"}, {"price": "0.167", "size": "120"}, {"price": "0.166", "size": "30"}, {"price": "0.165", "size": "20"}, {"price": "0.077", "size": "5"}, {"price": "0.07", "size": "70"}, {"price": "0.05", "size": "16.66"}, {"price": "0.01", "size": "20"}, {"price": "0.005", "size": "241.36"}, {"price": "0.004", "size": "190.82"}, {"price": "0.002", "size": "1000"}], "event_type": "book", "last_trade_price": "0.001"}, {"market": "0x420515ec56344b733661a732c2076be30c1e781a8ac0be429e7922dd1300f79e", "asset_id": "90650468439874736440446229920104878218500894514970167199833753801761553782125", "timestamp": "1769383990224", "hash": "c9d7270c42c6810284bbed07ca0c8e40f6c44782", "bids": [{"price": "0.001", "size": "4651.99"}, {"price": "0.002", "size": "1250"}, {"price": "0.003", "size": "1172.62"}, {"price": "0.006", "size": "83"}, {"price": "0.007", "size": "9.76"}, {"price": "0.01", "size": "12450"}, {"price": "0.02", "size": "4750"}, {"price": "0.021", "size": "8.81"}, {"price": "0.04", "size": "250"}, {"price": "0.05", "size": "30"}, {"price": "0.06", "size": "1100"}, {"price": "0.061", "size": "8.89"}, {"price": "0.1", "size": "360"}, {"price": "0.15", "size": "876.66"}, {"price": "0.2", "size": "610"}, {"price": "0.201", "size": "5.84"}, {"price": "0.223", "size": "41"}, {"price": "0.25", "size": "212"}, {"price": "0.3", "size": "1586.66"}, {"price": "0.301", "size": "250"}, {"price": "0.35", "size": "68.57"}, {"price": "0.4", "size": "675"}, {"price": "0.5", "size": "10"}, {"price": "0.523", "size": "185"}, {"price": "0.723", "size": "8"}, {"price": "0.725", "size": "550"}, {"price": "0.823", "size": "24"}, {"price": "0.845", "size": "118"}, {"price": "0.847", "size": "30"}, {"price": "0.848", "size": "20"}, {"price": "0.923", "size": "93"}, {"price": "0.926", "size": "30"}, {"price": "0.928", "size": "40"}, {"price": "0.95", "size": "10"}, {"price": "0.97", "size": "303.71"}, {"price": "0.971", "size": "100"}, {"price": "0.975", "size": "300"}, {"price": "0.976", "size": "155"}, {"price": "0.982", "size": "91.05"}, {"price": "0.983", "size": "0.5"}, {"price": "0.984", "size": "111"}, {"price": "0.985", "size": "11.25"}], "asks": [{"price": "0.999", "size": "9811.83"}, {"price": "0.998", "size": "3960"}, {"price": "0.997", "size": "250"}, {"price": "0.996", "size": "275"}, {"price": "0.993", "size": "1000"}, {"price": "0.992", "size": "752.5"}, {"price": "0.991", "size": "300"}, {"price": "0.99", "size": "416"}], "event_type": "book", "last_trade_price": "0.009"}, {"market": "0xb33b725b5d036ea8a985e48575741a80fdd03c62594c4fd50a78262a8828f3bc", "asset_id": "115484983885083639931615892302004279949181365513683946338210143705715836386623", "timestamp": "1769383991925", "hash": "d2d37f1d7139831a767dd7349e64d68f0ff83d44", "bids": [{"price": "0.001", "size": "2746"}], "asks": [{"price": "0.999", "size": "4666.43"}, {"price": "0.998", "size": "1250"}, {"price": "0.997", "size": "1172.62"}, {"price": "0.994", "size": "83"}, {"price": "0.993", "size": "9.76"}, {"price": "0.99", "size": "12450"}, {"price": "0.98", "size": "4750"}, {"price": "0.979", "size": "8.81"}, {"price": "0.96", "size": "250"}, {"price": "0.95", "size": "30"}, {"price": "0.94", "size": "1100"}, {"price": "0.939", "size": "8.89"}, {"price": "0.9", "size": "360"}, {"price": "0.85", "size": "876.66"}, {"price": "0.807", "size": "400"}, {"price": "0.8", "size": "160"}, {"price": "0.799", "size": "5.84"}, {"price": "0.777", "size": "22"}, {"price": "0.75", "size": "262"}, {"price": "0.7", "size": "1586.66"}, {"price": "0.699", "size": "250"}, {"price": "0.65", "size": "68.57"}, {"price": "0.6", "size": "675"}, {"price": "0.5", "size": "10"}, {"price": "0.477", "size": "44"}, {"price": "0.458", "size": "5"}, {"price": "0.456", "size": "917"}, {"price": "0.455", "size": "30"}, {"price": "0.08", "size": "10"}, {"price": "0.077", "size": "28"}, {"price": "0.076", "size": "20"}, {"price": "0.069", "size": "30"}, {"price": "0.068", "size": "40"}, {"price": "0.057", "size": "20"}, {"price": "0.01", "size": "20"}, {"price": "0.005", "size": "406"}, {"price": "0.004", "size": "1833.29"}], "event_type": "book", "last_trade_price": "0.001"}]}
{"_local_timestamp": "2026-01-25T23:34:16.174639+00:00", "data": {"market": "0x50e54348ebdc5218e17ab7cec6c6d1bda4816f979984717cf462d816921255d6", "price_changes": [{"asset_id": "68807170344581978269785042777291531812907438296702298129119130028792894246621", "price": "0.1", "size": "2068.91", "side": "SELL", "hash": "0136d38c3a0d672a5aa3f84edbac974b9a4ec60a", "best_bid": "0.08", "best_ask": "0.1"}, {"asset_id": "82547212645026470525278120787743350118721505496069116064469109192086879778892", "price": "0.9", "size": "2068.91", "side": "BUY", "hash": "40099f8d2998decebb96a04c76c0394c9391a69e", "best_bid": "0.9", "best_ask": "0.92"}], "timestamp": "1769384055930", "event_type": "price_change"}}
{"_local_timestamp": "2026-01-25T23:34:16.288973+00:00", "data": {"market": "0x6fbec2c3327fe7b5392b94fe48ccb41c7404a4a793957804b4b8fe8239376d12", "price_changes": [{"asset_id": "74232891440125659542320690757580411929973234713273124974412544144242477879854", "price": "0.948", "size": "449", "side": "BUY", "hash": "f1f7df3af8237aa5611d2c90d053aae51bdc11b9", "best_bid": "0.957", "best_ask": "0.979"}, {"asset_id": "69250819494674008903342626376731306359291370006377470819342000624771511803405", "price": "0.052", "size": "449", "side": "SELL", "hash": "46a0819295e3aae454723e7c0180cc8ebcb21048", "best_bid": "0.021", "best_ask": "0.043"}], "timestamp": "1769384056044", "event_type": "price_change"}}
{"_local_timestamp": "2026-01-25T23:34:16.293714+00:00", "data": {"market": "0x37d7295a17db461c15867862afe90bfad6cd46436b0d121a7c96c37e166103b4", "price_changes": [{"asset_id": "48325180813773997762337012603425087662105904105229463158116317479132765545801", "price": "0.973", "size": "150", "side": "BUY", "hash": "f73ae527e6ca2c9f65e82ded3f34206ebf2d3338", "best_bid": "0.989", "best_ask": "0.998"}, {"asset_id": "65341950601583802479848929397121491003949963027873255906537010617800365051709", "price": "0.027", "size": "150", "side": "SELL", "hash": "783d181823d9d4eea555d40afe96c7a43593a197", "best_bid": "0.002", "best_ask": "0.011"}], "timestamp": "1769384056054", "event_type": "price_change"}}
{"_local_timestamp": "2026-01-25T23:34:27.867158+00:00", "data": {"market": "0x6fbec2c3327fe7b5392b94fe48ccb41c7404a4a793957804b4b8fe8239376d12", "price_changes": [{"asset_id": "74232891440125659542320690757580411929973234713273124974412544144242477879854", "price": "0.404", "size": "293", "side": "BUY", "hash": "c598a117dd71bd96f9fb16e1a23f2edf5900677c", "best_bid": "0.957", "best_ask": "0.979"}, {"asset_id": "69250819494674008903342626376731306359291370006377470819342000624771511803405", "price": "0.596", "size": "293", "side": "SELL", "hash": "b6ddd3e2fd5201c6317646301115c483c046a302", "best_bid": "0.021", "best_ask": "0.043"}], "timestamp": "1769384067572", "event_type": "price_change"}}
{"_local_timestamp": "2026-01-25T23:34:28.088333+00:00", "data": {"market": "0x6fbec2c3327fe7b5392b94fe48ccb41c7404a4a793957804b4b8fe8239376d12", "price_changes": [{"asset_id": "74232891440125659542320690757580411929973234713273124974412544144242477879854", "price": "0.948", "size": "30", "side": "BUY", "hash": "15faead004fe902270a96b7bfec846ea1d09450d", "best_bid": "0.957", "best_ask": "0.979"}, {"asset_id": "69250819494674008903342626376731306359291370006377470819342000624771511803405", "price": "0.052", "size": "30", "side": "SELL", "hash": "144227243d5e1e8d222d291f0473b32b4373837f", "best_bid": "0.021", "best_ask": "0.043"}], "timestamp": "1769384067749", "event_type": "price_change"}}
{"_local_timestamp": "2026-01-25T23:34:28.089367+00:00", "data": {"market": "0x37d7295a17db461c15867862afe90bfad6cd46436b0d121a7c96c37e166103b4", "price_changes": [{"asset_id": "48325180813773997762337012603425087662105904105229463158116317479132765545801", "price": "0.926", "size": "400", "side": "BUY", "hash": "fdc1318c7973a86801041b81d40258af3770200c", "best_bid": "0.989", "best_ask": "0.998"}, {"asset_id": "65341950601583802479848929397121491003949963027873255906537010617800365051709", "price": "0.074", "size": "400", "side": "SELL", "hash": "4f01267aac68a84479d2f170666f9c5efc1f376d", "best_bid": "0.002", "best_ask": "0.011"}], "timestamp": "1769384067755", "event_type": "price_change"}}
{"_local_timestamp": "2026-01-25T23:34:28.092972+00:00", "data": {"market": "0x6fbec2c3327fe7b5392b94fe48ccb41c7404a4a793957804b4b8fe8239376d12", "price_changes": [{"asset_id": "74232891440125659542320690757580411929973234713273124974412544144242477879854", "price": "0.913", "size": "400", "side": "BUY", "hash": "0d0a72931c0f77b6cb8bbee193149ba8fbba7f52", "best_bid": "0.957", "best_ask": "0.979"}, {"asset_id": "69250819494674008903342626376731306359291370006377470819342000624771511803405", "price": "0.087", "size": "400", "side": "SELL", "hash": "ab8e0b381da67eb1935d48028d49b21f98f70c0e", "best_bid": "0.021", "best_ask": "0.043"}], "timestamp": "1769384067761", "event_type": "price_change"}}
{"_local_timestamp": "2026-01-25T23:34:28.098281+00:00", "data": {"market": "0x6fbec2c3327fe7b5392b94fe48ccb41c7404a4a793957804b4b8fe8239376d12", "price_changes": [{"asset_id": "74232891440125659542320690757580411929973234713273124974412544144242477879854", "price": "0.954", "size": "100", "side": "BUY", "hash": "c055aafbc7897b68c2d839c77046076ae0d31885", "best_bid": "0.957", "best_ask": "0.979"}, {"asset_id": "69250819494674008903342626376731306359291370006377470819342000624771511803405", "price": "0.046", "size": "100", "side": "SELL", "hash": "3b5a8df210b6734b430fd0ee45d3d74b4914d348", "best_bid": "0.021", "best_ask": "0.043"}], "timestamp": "1769384067790", "event_type": "price_change"}}
{"_local_timestamp": "2026-01-25T23:34:28.212749+00:00", "data": {"market": "0x6fbec2c3327fe7b5392b94fe48ccb41c7404a4a793957804b4b8fe8239376d12", "price_changes": [{"asset_id": "74232891440125659542320690757580411929973234713273124974412544144242477879854", "price": "0.913", "size": "0", "side": "BUY", "hash": "10d06f2d9240e90f8f3f40c37fe593e57d8d680d", "best_bid": "0.957", "best_ask": "0.979"}, {"asset_id": "69250819494674008903342626376731306359291370006377470819342000624771511803405", "price": "0.087", "size": "0", "side": "SELL", "hash": "f5ece6aac65f9ba6de67d75e0016f3d8bb48e319", "best_bid": "0.021", "best_ask": "0.043"}], "timestamp": "1769384067973", "event_type": "price_change"}}
{"_local_timestamp": "2026-01-25T23:34:28.496330+00:00", "data": {"market": "0x6fbec2c3327fe7b5392b94fe48ccb41c7404a4a793957804b4b8fe8239376d12", "price_changes": [{"asset_id": "74232891440125659542320690757580411929973234713273124974412544144242477879854", "price": "0.405", "size": "306", "side": "BUY", "hash": "3ef6ad817e727a7fc09c0a68a92349d4bf3330f1", "best_bid": "0.957", "best_ask": "0.979"}, {"asset_id": "69250819494674008903342626376731306359291370006377470819342000624771511803405", "price": "0.595", "size": "306", "side": "SELL", "hash": "4e1ae295ea304bdf1fa6d66697fcbe81d67475b0", "best_bid": "0.021", "best_ask": "0.043"}], "timestamp": "1769384068085", "event_type": "price_change"}}
{"_local_timestamp": "2026-01-25T23:34:29.352581+00:00", "data": {"market": "0x6fbec2c3327fe7b5392b94fe48ccb41c7404a4a793957804b4b8fe8239376d12", "price_changes": [{"asset_id": "69250819494674008903342626376731306359291370006377470819342000624771511803405", "price": "0.052", "size": "0", "side": "SELL", "hash": "3dc3fb31c4a6b98e7fa29c81b44c0936d0be3e5b", "best_bid": "0.021", "best_ask": "0.043"}, {"asset_id": "74232891440125659542320690757580411929973234713273124974412544144242477879854", "price": "0.948", "size": "0", "side": "BUY", "hash": "100d71f7a09db4d16d079a37a4c7a658cdc51da8", "best_bid": "0.957", "best_ask": "0.979"}], "timestamp": "1769384069003", "event_type": "price_change"}}
{"_local_timestamp": "2026-01-25T23:34:29.743961+00:00", "data": {"market": "0x6fbec2c3327fe7b5392b94fe48ccb41c7404a4a793957804b4b8fe8239376d12", "price_changes": [{"asset_id": "69250819494674008903342626376731306359291370006377470819342000624771511803405", "price": "0.045", "size": "30", "side": "SELL", "hash": "7b4a4d3b45330a25d5663270c183911792489a03", "best_bid": "0.021", "best_ask": "0.043"}, {"asset_id": "74232891440125659542320690757580411929973234713273124974412544144242477879854", "price": "0.955", "size": "30", "side": "BUY", "hash": "c273c0b3d0477286d952b18807338fb441e32c96", "best_bid": "0.957", "best_ask": "0.979"}], "timestamp": "1769384069121", "event_type": "price_change"}}
{"_local_timestamp": "2026-01-25T23:34:29.744719+00:00", "data": {"market": "0x6fbec2c3327fe7b5392b94fe48ccb41c7404a4a793957804b4b8fe8239376d12", "price_changes": [{"asset_id": "74232891440125659542320690757580411929973234713273124974412544144242477879854", "price": "0.913", "size": "400", "side": "BUY", "hash": "ef27d8f53d94203b46f6917e29840e2b17498633", "best_bid": "0.957", "best_ask": "0.979"}, {"asset_id": "69250819494674008903342626376731306359291370006377470819342000624771511803405", "price": "0.087", "size": "400", "side": "SELL", "hash": "70ce992e5c133aec1620b3e69d9273ef9c47ed04", "best_bid": "0.021", "best_ask": "0.043"}], "timestamp": "1769384069215", "event_type": "price_change"}}
{"_local_timestamp": "2026-01-25T23:34:33.684385+00:00", "data": {"market": "0x6fbec2c3327fe7b5392b94fe48ccb41c7404a4a793957804b4b8fe8239376d12", "price_changes": [{"asset_id": "74232891440125659542320690757580411929973234713273124974412544144242477879854", "price": "0.946", "size": "0", "side": "BUY", "hash": "024791e52eafa8a3444775b2a8ce0e0120eec6f2", "best_bid": "0.957", "best_ask": "0.979"}, {"asset_id": "69250819494674008903342626376731306359291370006377470819342000624771511803405", "price": "0.054", "size": "0", "side": "SELL", "hash": "d5dda59ccc7c6cd10b9046cc7cec8bd30be83e6c", "best_bid": "0.021", "best_ask": "0.043"}], "timestamp": "1769384073445", "event_type": "price_change"}}
{"_local_timestamp": "2026-01-25T23:34:33.811795+00:00", "data": {"market": "0x6fbec2c3327fe7b5392b94fe48ccb41c7404a4a793957804b4b8fe8239376d12", "price_changes": [{"asset_id": "74232891440125659542320690757580411929973234713273124974412544144242477879854", "price": "0.913", "size": "0", "side": "BUY", "hash": "51295fe42bc753f3aabea1a17f07143b524a742a", "best_bid": "0.957", "best_ask": "0.979"}, {"asset_id": "69250819494674008903342626376731306359291370006377470819342000624771511803405", "price": "0.087", "size": "0", "side": "SELL", "hash": "1e692478017afca472b33f83f9ddc772a65a8d21", "best_bid": "0.021", "best_ask": "0.043"}], "timestamp": "1769384073577", "event_type": "price_change"}}
{"_local_timestamp": "2026-01-25T23:34:33.825310+00:00", "data": {"market": "0x6fbec2c3327fe7b5392b94fe48ccb41c7404a4a793957804b4b8fe8239376d12", "price_changes": [{"asset_id": "74232891440125659542320690757580411929973234713273124974412544144242477879854", "price": "0.956", "size": "25", "side": "BUY", "hash": "a8c4a407304d92087824ef0edac23228e7b74b29", "best_bid": "0.957", "best_ask": "0.979"}, {"asset_id": "69250819494674008903342626376731306359291370006377470819342000624771511803405", "price": "0.044", "size": "25", "side": "SELL", "hash": "84d62421392324196ad27397bdc623efe8e5a4b3", "best_bid": "0.021", "best_ask": "0.043"}], "timestamp": "1769384073582", "event_type": "price_change"}}
{"_local_timestamp": "2026-01-25T23:34:33.939338+00:00", "data": {"market": "0x6fbec2c3327fe7b5392b94fe48ccb41c7404a4a793957804b4b8fe8239376d12", "price_changes": [{"asset_id": "74232891440125659542320690757580411929973234713273124974412544144242477879854", "price": "0.954", "size": "50", "side": "BUY", "hash": "8796d5dbe20773a8c91f2e6171faf630d0eab320", "best_bid": "0.957", "best_ask": "0.979"}, {"asset_id": "69250819494674008903342626376731306359291370006377470819342000624771511803405", "price": "0.046", "size": "50", "side": "SELL", "hash": "f9a86f2930fdaa35a810d6b23285b16ad36f188e", "best_bid": "0.021", "best_ask": "0.043"}], "timestamp": "1769384073694", "event_type": "price_change"}}
{"_local_timestamp": "2026-01-25T23:34:33.971763+00:00", "data": {"market": "0x6fbec2c3327fe7b5392b94fe48ccb41c7404a4a793957804b4b8fe8239376d12", "price_changes": [{"asset_id": "69250819494674008903342626376731306359291370006377470819342000624771511803405", "price": "0.006", "size": "0", "side": "BUY", "hash": "a103dff4d2a19c37a6c3caeae7c19f7cec26f4c3", "best_bid": "0.021", "best_ask": "0.043"}, {"asset_id": "74232891440125659542320690757580411929973234713273124974412544144242477879854", "price": "0.994", "size": "0", "side": "SELL", "hash": "5aa1ce63564bd70dc81444240afbbd889bbd8923", "best_bid": "0.957", "best_ask": "0.979"}], "timestamp": "1769384073732", "event_type": "price_change"}}
{"_local_timestamp": "2026-01-25T23:34:34.192530+00:00", "data": {"market": "0x6fbec2c3327fe7b5392b94fe48ccb41c7404a4a793957804b4b8fe8239376d12", "price_changes": [{"asset_id": "74232891440125659542320690757580411929973234713273124974412544144242477879854", "price": "0.954", "size": "0", "side": "BUY", "hash": "8015df1bebb36fa809c5c12f6861ed7fa2321f78", "best_bid": "0.957", "best_ask": "0.979"}, {"asset_id": "69250819494674008903342626376731306359291370006377470819342000624771511803405", "price": "0.046", "size": "0", "side": "SELL", "hash": "3a7e90a1c9f030fe0a1401e3ebe168368e67c052", "best_bid": "0.021", "best_ask": "0.043"}], "timestamp": "1769384073964", "event_type": "price_change"}}
{"_local_timestamp": "2026-01-25T23:34:34.705702+00:00", "data": {"market": "0x37d7295a17db461c15867862afe90bfad6cd46436b0d121a7c96c37e166103b4", "price_changes": [{"asset_id": "48325180813773997762337012603425087662105904105229463158116317479132765545801", "price": "0.921", "size": "0", "side": "BUY", "hash": "3d163e00affb3a1b753bb83e69a7541d20c7061d", "best_bid": "0.989", "best_ask": "0.998"}, {"asset_id": "65341950601583802479848929397121491003949963027873255906537010617800365051709", "price": "0.079", "size": "0", "side": "SELL", "hash": "af973663ec51b49f9d997108dbb4827378b2ce1b", "best_bid": "0.002", "best_ask": "0.011"}], "timestamp": "1769384074500", "event_type": "price_change"}}
{"_local_timestamp": "2026-01-25T23:34:34.739660+00:00", "data": {"market": "0x37d7295a17db461c15867862afe90bfad6cd46436b0d121a7c96c37e166103b4", "price_changes": [{"asset_id": "48325180813773997762337012603425087662105904105229463158116317479132765545801", "price": "0.927", "size": "20", "side": "BUY", "hash": "b35b00c473a0bd44493bf1e4d00cb9e1695a6b23", "best_bid": "0.989", "best_ask": "0.998"}, {"asset_id": "65341950601583802479848929397121491003949963027873255906537010617800365051709", "price": "0.073", "size": "20", "side": "SELL", "hash": "9fa42e444d8bd3270d89dfb8aac3c1bd7ad96f42", "best_bid": "0.002", "best_ask": "0.011"}], "timestamp": "1769384074531", "event_type": "price_change"}}
{"_local_timestamp": "2026-01-25T23:34:34.845222+00:00", "data": {"market": "0x37d7295a17db461c15867862afe90bfad6cd46436b0d121a7c96c37e166103b4", "price_changes": [{"asset_id": "48325180813773997762337012603425087662105904105229463158116317479132765545801", "price": "0.926", "size": "0", "side": "BUY", "hash": "0567ca2f5d5030ac3ff34c6538429e32a31dc664", "best_bid": "0.989", "best_ask": "0.998"}, {"asset_id": "65341950601583802479848929397121491003949963027873255906537010617800365051709", "price": "0.074", "size": "0", "side": "SELL", "hash": "16f8735f177088fc860b55a3ad2546dcd5f3c7e4", "best_bid": "0.002", "best_ask": "0.011"}], "timestamp": "1769384074634", "event_type": "price_change"}}
{"_local_timestamp": "2026-01-25T23:34:34.857140+00:00", "data": {"market": "0x37d7295a17db461c15867862afe90bfad6cd46436b0d121a7c96c37e166103b4", "price_changes": [{"asset_id": "48325180813773997762337012603425087662105904105229463158116317479132765545801", "price": "0.931", "size": "150", "side": "BUY", "hash": "370ec223804d4f6929ec96231d6c3fccb1192e5c", "best_bid": "0.989", "best_ask": "0.998"}, {"asset_id": "65341950601583802479848929397121491003949963027873255906537010617800365051709", "price": "0.069", "size": "150", "side": "SELL", "hash": "6d0c26184c0594ebfa9254008d90884d7fbdfd0a", "best_bid": "0.002", "best_ask": "0.011"}], "timestamp": "1769384074640", "event_type": "price_change"}}
{"_local_timestamp": "2026-01-25T23:34:35.515101+00:00", "data": {"market": "0x6fbec2c3327fe7b5392b94fe48ccb41c7404a4a793957804b4b8fe8239376d12", "price_changes": [{"asset_id": "69250819494674008903342626376731306359291370006377470819342000624771511803405", "price": "0.045", "size": "0", "side": "SELL", "hash": "27a3ce1a1ea3f5131cb0369724d0a36c216ffa32", "best_bid": "0.021", "best_ask": "0.043"}, {"asset_id": "74232891440125659542320690757580411929973234713273124974412544144242477879854", "price": "0.955", "size": "0", "side": "BUY", "hash": "cc174cda93b9004d437de9c216d42d03303d4756", "best_bid": "0.957", "best_ask": "0.979"}], "timestamp": "1769384075272", "event_type": "price_change"}}
{"_local_timestamp": "2026-01-25T23:34:35.638209+00:00", "data": {"market": "0x6fbec2c3327fe7b5392b94fe48ccb41c7404a4a793957804b4b8fe8239376d12", "price_changes": [{"asset_id": "69250819494674008903342626376731306359291370006377470819342000624771511803405", "price": "0.052", "size": "30", "side": "SELL", "hash": "57dbbacfe4e44bb33c952ee6865fdc6e4af97916", "best_bid": "0.021", "best_ask": "0.043"}, {"asset_id": "74232891440125659542320690757580411929973234713273124974412544144242477879854", "price": "0.948", "size": "30", "side": "BUY", "hash": "4786c11d8709affa90311f9da97b556ccd117c33", "best_bid": "0.957", "best_ask": "0.979"}], "timestamp": "1769384075383", "event_type": "price_change"}}
{"_local_timestamp": "2026-01-25T23:34:35.645487+00:00", "data": {"market": "0x6fbec2c3327fe7b5392b94fe48ccb41c7404a4a793957804b4b8fe8239376d12", "price_changes": [{"asset_id": "74232891440125659542320690757580411929973234713273124974412544144242477879854", "price": "0.956", "size": "0", "side": "BUY", "hash": "1589b87b9fa3c1dcfc4c4c71a0c945a2ed6d4410", "best_bid": "0.957", "best_ask": "0.979"}, {"asset_id": "69250819494674008903342626376731306359291370006377470819342000624771511803405", "price": "0.044", "size": "0", "side": "SELL", "hash": "5bed1896ca02b66a14ab8892e6adc470cb0f9492", "best_bid": "0.021", "best_ask": "0.043"}], "timestamp": "1769384075400", "event_type": "price_change"}}
{"_local_timestamp": "2026-01-25T23:34:35.743123+00:00", "data": {"market": "0x6fbec2c3327fe7b5392b94fe48ccb41c7404a4a793957804b4b8fe8239376d12", "price_changes": [{"asset_id": "74232891440125659542320690757580411929973234713273124974412544144242477879854", "price": "0.954", "size": "50", "side": "BUY", "hash": "64df81f7c31c87e0bd877b24ddf6e30fd3966ca7", "best_bid": "0.957", "best_ask": "0.979"}, {"asset_id": "69250819494674008903342626376731306359291370006377470819342000624771511803405", "price": "0.046", "size": "50", "side": "SELL", "hash": "1a093492c09caff0ea70195cab16a433e07c6b68", "best_bid": "0.021", "best_ask": "0.043"}], "timestamp": "1769384075500", "event_type": "price_change"}}
{"_local_timestamp": "2026-01-25T23:34:36.160442+00:00", "data": {"market": "0x6fbec2c3327fe7b5392b94fe48ccb41c7404a4a793957804b4b8fe8239376d12", "price_changes": [{"asset_id": "74232891440125659542320690757580411929973234713273124974412544144242477879854", "price": "0.948", "size": "150", "side": "BUY", "hash": "752c5f42ec3b7f915e437760457c45abbaa7d1b0", "best_bid": "0.957", "best_ask": "0.979"}, {"asset_id": "69250819494674008903342626376731306359291370006377470819342000624771511803405", "price": "0.052", "size": "150", "side": "SELL", "hash": "6d4806e69b4df2a31bfabc9155bcd281960a09f6", "best_bid": "0.021", "best_ask": "0.043"}], "timestamp": "1769384075940", "event_type": "price_change"}}
{"_local_timestamp": "2026-01-25T23:34:36.161053+00:00", "data": {"market": "0x6fbec2c3327fe7b5392b94fe48ccb41c7404a4a793957804b4b8fe8239376d12", "price_changes": [{"asset_id": "69250819494674008903342626376731306359291370006377470819342000624771511803405", "price": "0.004", "size": "1256.63", "side": "BUY", "hash": "2d7181f99ace963a9fa063cc6fc3ecd4dc71fd1c", "best_bid": "0.021", "best_ask": "0.043"}, {"asset_id": "74232891440125659542320690757580411929973234713273124974412544144242477879854", "price": "0.996", "size": "1256.63", "side": "SELL", "hash": "3b6562e465affaba53058422b8d8d07e81d9f71f", "best_bid": "0.957", "best_ask": "0.979"}], "timestamp": "1769384075941", "event_type": "price_change"}}
{"_local_timestamp": "2026-01-25T23:34:39.043559+00:00", "data": {"market": "0x37d7295a17db461c15867862afe90bfad6cd46436b0d121a7c96c37e166103b4", "price_changes": [{"asset_id": "48325180813773997762337012603425087662105904105229463158116317479132765545801", "price": "0.927", "size": "0", "side": "BUY", "hash": "a878ef80d43cb2a47926d3625c91565da644a0b9", "best_bid": "0.989", "best_ask": "0.998"}, {"asset_id": "65341950601583802479848929397121491003949963027873255906537010617800365051709", "price": "0.073", "size": "0", "side": "SELL", "hash": "cf7013d60b79b477fc9b2cf5c804294b32a0bab3", "best_bid": "0.002", "best_ask": "0.011"}], "timestamp": "1769384078955", "event_type": "price_change"}}
{"_local_timestamp": "2026-01-25T23:34:39.067290+00:00", "data": {"market": "0x37d7295a17db461c15867862afe90bfad6cd46436b0d121a7c96c37e166103b4", "price_changes": [{"asset_id": "48325180813773997762337012603425087662105904105229463158116317479132765545801", "price": "0.921", "size": "20", "side": "BUY", "hash": "df778c3fc2f8e0846996cfe23d43b68b78cf6507", "best_bid": "0.989", "best_ask": "0.998"}, {"asset_id": "65341950601583802479848929397121491003949963027873255906537010617800365051709", "price": "0.079", "size": "20", "side": "SELL", "hash": "e4c1bee8cc7c887fd63248f96b415c1d677d130c", "best_bid": "0.002", "best_ask": "0.011"}], "timestamp": "1769384078986", "event_type": "price_change"}}
{"_local_timestamp": "2026-01-25T23:34:39.177230+00:00", "data": {"market": "0x50e54348ebdc5218e17ab7cec6c6d1bda4816f979984717cf462d816921255d6", "price_changes": [{"asset_id": "68807170344581978269785042777291531812907438296702298129119130028792894246621", "price": "0.07", "size": "255.29", "side": "BUY", "hash": "c4cce801bc11a60d2828536d8914cafda12216d9", "best_bid": "0.08", "best_ask": "0.1"}, {"asset_id": "82547212645026470525278120787743350118721505496069116064469109192086879778892", "price": "0.93", "size": "255.29", "side": "SELL", "hash": "8947cf8af4bbc8c96273ef199126a32e34e26008", "best_bid": "0.9", "best_ask": "0.92"}], "timestamp": "1769384079079", "event_type": "price_change"}}
{"_local_timestamp": "2026-01-25T23:34:39.207183+00:00", "data": {"market": "0x37d7295a17db461c15867862afe90bfad6cd46436b0d121a7c96c37e166103b4", "price_changes": [{"asset_id": "48325180813773997762337012603425087662105904105229463158116317479132765545801", "price": "0.926", "size": "400", "side": "BUY", "hash": "cbc177f39a9d9b4f1ad2a2181231e74c0012303a", "best_bid": "0.989", "best_ask": "0.998"}, {"asset_id": "65341950601583802479848929397121491003949963027873255906537010617800365051709", "price": "0.074", "size": "400", "side": "SELL", "hash": "5ad47f838e455a26894d95440ad77ea1336a3312", "best_bid": "0.002", "best_ask": "0.011"}], "timestamp": "1769384079105", "event_type": "price_change"}}
{"_local_timestamp": "2026-01-25T23:34:39.207688+00:00", "data": {"market": "0x37d7295a17db461c15867862afe90bfad6cd46436b0d121a7c96c37e166103b4", "price_changes": [{"asset_id": "48325180813773997762337012603425087662105904105229463158116317479132765545801", "price": "0.931", "size": "0", "side": "BUY", "hash": "27783dbcf81ce413e79506c1e275de3dc99b11dd", "best_bid": "0.989", "best_ask": "0.998"}, {"asset_id": "65341950601583802479848929397121491003949963027873255906537010617800365051709", "price": "0.069", "size": "0", "side": "SELL", "hash": "5ab56157a278b0cdd59f29639892061ddac3ef4f", "best_bid": "0.002", "best_ask": "0.011"}], "timestamp": "1769384079106", "event_type": "price_change"}}
{"_local_timestamp": "2026-01-25T23:34:43.973858+00:00", "data": {"market": "0x37d7295a17db461c15867862afe90bfad6cd46436b0d121a7c96c37e166103b4", "price_changes": [{"asset_id": "48325180813773997762337012603425087662105904105229463158116317479132765545801", "price": "0.921", "size": "0", "side": "BUY", "hash": "02301b169bc5ab2ca25159b5f1cf15f0b351d1f9", "best_bid": "0.989", "best_ask": "0.998"}, {"asset_id": "65341950601583802479848929397121491003949963027873255906537010617800365051709", "price": "0.079", "size": "0", "side": "SELL", "hash": "e38a2c763b9095ca492a78f8c630e049ee631531", "best_bid": "0.002", "best_ask": "0.011"}], "timestamp": "1769384083901", "event_type": "price_change"}}
{"_local_timestamp": "2026-01-25T23:34:44.013402+00:00", "data": {"market": "0x37d7295a17db461c15867862afe90bfad6cd46436b0d121a7c96c37e166103b4", "price_changes": [{"asset_id": "48325180813773997762337012603425087662105904105229463158116317479132765545801", "price": "0.927", "size": "20", "side": "BUY", "hash": "64032e40ad9e1e934e75ff786d50e0fc647ea8dc", "best_bid": "0.989", "best_ask": "0.998"}, {"asset_id": "65341950601583802479848929397121491003949963027873255906537010617800365051709", "price": "0.073", "size": "20", "side": "SELL", "hash": "4ad08288ccd6d7e9536c61e9c862fc38ca1d81f0", "best_bid": "0.002", "best_ask": "0.011"}], "timestamp": "1769384083929", "event_type": "price_change"}}
{"_local_timestamp": "2026-01-25T23:34:44.039708+00:00", "data": {"market": "0x6fbec2c3327fe7b5392b94fe48ccb41c7404a4a793957804b4b8fe8239376d12", "price_changes": [{"asset_id": "74232891440125659542320690757580411929973234713273124974412544144242477879854", "price": "0.524", "size": "45", "side": "BUY", "hash": "39e30cac2aa98c217d09ae79a0465bf83fc17403", "best_bid": "0.957", "best_ask": "0.979"}, {"asset_id": "69250819494674008903342626376731306359291370006377470819342000624771511803405", "price": "0.476", "size": "45", "side": "SELL", "hash": "def99f700d8cb457747d764e8ba957a22c277e6a", "best_bid": "0.021", "best_ask": "0.043"}], "timestamp": "1769384083964", "event_type": "price_change"}}
{"_local_timestamp": "2026-01-25T23:34:44.137499+00:00", "data": {"market": "0x37d7295a17db461c15867862afe90bfad6cd46436b0d121a7c96c37e166103b4", "price_changes": [{"asset_id": "48325180813773997762337012603425087662105904105229463158116317479132765545801", "price": "0.926", "size": "0", "side": "BUY", "hash": "f79fe79b71f82d8c41c16029eef162a6fe5e233a", "best_bid": "0.989", "best_ask": "0.998"}, {"asset_id": "65341950601583802479848929397121491003949963027873255906537010617800365051709", "price": "0.074", "size": "0", "side": "SELL", "hash": "4ff69497fec4130e9db431bd1b61e0f0fda98e18", "best_bid": "0.002", "best_ask": "0.011"}], "timestamp": "1769384084026", "event_type": "price_change"}}
{"_local_timestamp": "2026-01-25T23:34:44.159946+00:00", "data": {"market": "0x6fbec2c3327fe7b5392b94fe48ccb41c7404a4a793957804b4b8fe8239376d12", "price_changes": [{"asset_id": "74232891440125659542320690757580411929973234713273124974412544144242477879854", "price": "0.913", "size": "400", "side": "BUY", "hash": "8b4eb3173d2053954c3f197eea63bcbd95f93de5", "best_bid": "0.957", "best_ask": "0.979"}, {"asset_id": "69250819494674008903342626376731306359291370006377470819342000624771511803405", "price": "0.087", "size": "400", "side": "SELL", "hash": "edcb00cb8b78f0a1a5781f48110772000bb8545f", "best_bid": "0.021", "best_ask": "0.043"}], "timestamp": "1769384084078", "event_type": "price_change"}}
{"_local_timestamp": "2026-01-25T23:34:44.160443+00:00", "data": {"market": "0x37d7295a17db461c15867862afe90bfad6cd46436b0d121a7c96c37e166103b4", "price_changes": [{"asset_id": "48325180813773997762337012603425087662105904105229463158116317479132765545801", "price": "0.931", "size": "150", "side": "BUY", "hash": "443b46d104eec4dd708ddb0c81605ad7e28e77b1", "best_bid": "0.989", "best_ask": "0.998"}, {"asset_id": "65341950601583802479848929397121491003949963027873255906537010617800365051709", "price": "0.069", "size": "150", "side": "SELL", "hash": "f890f03b8f9e2805a1ef83edec505cd15ce7f0c5", "best_bid": "0.002", "best_ask": "0.011"}], "timestamp": "1769384084089", "event_type": "price_change"}}
{"_local_timestamp": "2026-01-25T23:34:48.133459+00:00", "data": {"market": "0x37d7295a17db461c15867862afe90bfad6cd46436b0d121a7c96c37e166103b4", "price_changes": [{"asset_id": "48325180813773997762337012603425087662105904105229463158116317479132765545801", "price": "0.927", "size": "0", "side": "BUY", "hash": "864a7af90f37ddee81c57b9a9ccc92a56be08a1f", "best_bid": "0.989", "best_ask": "0.998"}, {"asset_id": "65341950601583802479848929397121491003949963027873255906537010617800365051709", "price": "0.073", "size": "0", "side": "SELL", "hash": "e5be1b976d7b78561fcbc53679be471e309f3549", "best_bid": "0.002", "best_ask": "0.011"}], "timestamp": "1769384088058", "event_type": "price_change"}}
{"_local_timestamp": "2026-01-25T23:34:48.166835+00:00", "data": {"market": "0x37d7295a17db461c15867862afe90bfad6cd46436b0d121a7c96c37e166103b4", "price_changes": [{"asset_id": "48325180813773997762337012603425087662105904105229463158116317479132765545801", "price": "0.921", "size": "20", "side": "BUY", "hash": "983f38eac970d22131aa2dd8e071695e3e609b0e", "best_bid": "0.989", "best_ask": "0.998"}, {"asset_id": "65341950601583802479848929397121491003949963027873255906537010617800365051709", "price": "0.079", "size": "20", "side": "SELL", "hash": "0d619792c9b37712ffc4f2c0b738f915e7405293", "best_bid": "0.002", "best_ask": "0.011"}], "timestamp": "1769384088090", "event_type": "price_change"}}
{"_local_timestamp": "2026-01-25T23:34:48.243673+00:00", "data": {"market": "0x37d7295a17db461c15867862afe90bfad6cd46436b0d121a7c96c37e166103b4", "price_changes": [{"asset_id": "48325180813773997762337012603425087662105904105229463158116317479132765545801", "price": "0.931", "size": "0", "side": "BUY", "hash": "08761dbf57a04129f7bf6509df478487d82ed83f", "best_bid": "0.989", "best_ask": "0.998"}, {"asset_id": "65341950601583802479848929397121491003949963027873255906537010617800365051709", "price": "0.069", "size": "0", "side": "SELL", "hash": "ccb71d1e1bf911def7c74ddb33885d39b3f8c640", "best_bid": "0.002", "best_ask": "0.011"}], "timestamp": "1769384088165", "event_type": "price_change"}}
{"_local_timestamp": "2026-01-25T23:34:48.289603+00:00", "data": {"market": "0x37d7295a17db461c15867862afe90bfad6cd46436b0d121a7c96c37e166103b4", "price_changes": [{"asset_id": "48325180813773997762337012603425087662105904105229463158116317479132765545801", "price": "0.926", "size": "400", "side": "BUY", "hash": "0712f321d0a6c4cfc1d17c67cf3613051435833d", "best_bid": "0.989", "best_ask": "0.998"}, {"asset_id": "65341950601583802479848929397121491003949963027873255906537010617800365051709", "price": "0.074", "size": "400", "side": "SELL", "hash": "a941edc0f54393c2c6f37b79da138bdf381cb9bb", "best_bid": "0.002", "best_ask": "0.011"}], "timestamp": "1769384088220", "event_type": "price_change"}}
{"_local_timestamp": "2026-01-25T23:34:51.176976+00:00", "data": {"market": "0x37d7295a17db461c15867862afe90bfad6cd46436b0d121a7c96c37e166103b4", "price_changes": [{"asset_id": "48325180813773997762337012603425087662105904105229463158116317479132765545801", "price": "0.921", "size": "0", "side": "BUY", "hash": "afe7a4f2340208d7da5f1e57f360a2d53a0bbda3", "best_bid": "0.989", "best_ask": "0.998"}, {"asset_id": "65341950601583802479848929397121491003949963027873255906537010617800365051709", "price": "0.079", "size": "0", "side": "SELL", "hash": "530b466c63c5f6c2d6e45bd806d492836cf09f78", "best_bid": "0.002", "best_ask": "0.011"}], "timestamp": "1769384091027", "event_type": "price_change"}}
{"_local_timestamp": "2026-01-25T23:34:51.209654+00:00", "data": {"market": "0x37d7295a17db461c15867862afe90bfad6cd46436b0d121a7c96c37e166103b4", "price_changes": [{"asset_id": "48325180813773997762337012603425087662105904105229463158116317479132765545801", "price": "0.927", "size": "20", "side": "BUY", "hash": "a30f7a5ad5eb862f9c1fb03849a00a884d0fa8c2", "best_bid": "0.989", "best_ask": "0.998"}, {"asset_id": "65341950601583802479848929397121491003949963027873255906537010617800365051709", "price": "0.073", "size": "20", "side": "SELL", "hash": "e42f747731f2f62739bc6ccdfdf7e8ac8734b85e", "best_bid": "0.002", "best_ask": "0.011"}], "timestamp": "1769384091055", "event_type": "price_change"}}
{"_local_timestamp": "2026-01-25T23:34:51.360649+00:00", "data": {"market": "0x37d7295a17db461c15867862afe90bfad6cd46436b0d121a7c96c37e166103b4", "price_changes": [{"asset_id": "48325180813773997762337012603425087662105904105229463158116317479132765545801", "price": "0.931", "size": "150", "side": "BUY", "hash": "55d1324178601c48abd8b1aa7401698974e526f7", "best_bid": "0.989", "best_ask": "0.998"}, {"asset_id": "65341950601583802479848929397121491003949963027873255906537010617800365051709", "price": "0.069", "size": "150", "side": "SELL", "hash": "aef10c9eb97cd989269cb2fcd1a229b0b8b6fffe", "best_bid": "0.002", "best_ask": "0.011"}], "timestamp": "1769384091196", "event_type": "price_change"}}
{"_local_timestamp": "2026-01-25T23:34:51.460742+00:00", "data": {"market": "0x37d7295a17db461c15867862afe90bfad6cd46436b0d121a7c96c37e166103b4", "price_changes": [{"asset_id": "48325180813773997762337012603425087662105904105229463158116317479132765545801", "price": "0.926", "size": "0", "side": "BUY", "hash": "328ddedd7050949aab879640c41c2b5dc7b1c19b", "best_bid": "0.989", "best_ask": "0.998"}, {"asset_id": "65341950601583802479848929397121491003949963027873255906537010617800365051709", "price": "0.074", "size": "0", "side": "SELL", "hash": "0bfaf1d9fc4c56514e0c1f56df9edfd7208e1f03", "best_bid": "0.002", "best_ask": "0.011"}], "timestamp": "1769384091286", "event_type": "price_change"}}
{"_local_timestamp": "2026-01-25T23:34:51.500377+00:00", "data": {"market": "0x37d7295a17db461c15867862afe90bfad6cd46436b0d121a7c96c37e166103b4", "price_changes": [{"asset_id": "48325180813773997762337012603425087662105904105229463158116317479132765545801", "price": "0.512", "size": "0", "side": "BUY", "hash": "5a3e09cbf5e52b83e8b8575e52ea78f4a1ded8b2", "best_bid": "0.989", "best_ask": "0.998"}, {"asset_id": "65341950601583802479848929397121491003949963027873255906537010617800365051709", "price": "0.488", "size": "0", "side": "SELL", "hash": "858782f8cc37908805e4a1bdd25bd693a030902a", "best_bid": "0.002", "best_ask": "0.011"}], "timestamp": "1769384091322", "event_type": "price_change"}}
{"_local_timestamp": "2026-01-25T23:34:51.754553+00:00", "data": {"market": "0x37d7295a17db461c15867862afe90bfad6cd46436b0d121a7c96c37e166103b4", "price_changes": [{"asset_id": "48325180813773997762337012603425087662105904105229463158116317479132765545801", "price": "0.936", "size": "60", "side": "BUY", "hash": "dcb4b2671605d8dd04a9a980d402073afbf4e139", "best_bid": "0.989", "best_ask": "0.998"}, {"asset_id": "65341950601583802479848929397121491003949963027873255906537010617800365051709", "price": "0.064", "size": "60", "side": "SELL", "hash": "5856169fccbbd0d6ef4a5e5e9792624cb0238ca9", "best_bid": "0.002", "best_ask": "0.011"}], "timestamp": "1769384091539", "event_type": "price_change"}}
{"_local_timestamp": "2026-01-25T23:34:51.755061+00:00", "data": {"market": "0x37d7295a17db461c15867862afe90bfad6cd46436b0d121a7c96c37e166103b4", "price_changes": [{"asset_id": "48325180813773997762337012603425087662105904105229463158116317479132765545801", "price": "0.921", "size": "500", "side": "BUY", "hash": "a56eb083ad72f31875762a4d19e8fe9609c58954", "best_bid": "0.989", "best_ask": "0.998"}, {"asset_id": "65341950601583802479848929397121491003949963027873255906537010617800365051709", "price": "0.079", "size": "500", "side": "SELL", "hash": "fce900b32dec21a26d018de8cf475d07bc8f6168", "best_bid": "0.002", "best_ask": "0.011"}], "timestamp": "1769384091540", "event_type": "price_change"}}
{"_local_timestamp": "2026-01-25T23:34:52.221622+00:00", "data": {"market": "0x37d7295a17db461c15867862afe90bfad6cd46436b0d121a7c96c37e166103b4", "price_changes": [{"asset_id": "48325180813773997762337012603425087662105904105229463158116317479132765545801", "price": "0.921", "size": "0", "side": "BUY", "hash": "2de3da384e5459934e2f64e28a16816229c44424", "best_bid": "0.989", "best_ask": "0.998"}, {"asset_id": "65341950601583802479848929397121491003949963027873255906537010617800365051709", "price": "0.079", "size": "0", "side": "SELL", "hash": "5a830c5fd93db07069e0977a4af89eaab778d179", "best_bid": "0.002", "best_ask": "0.011"}], "timestamp": "1769384092013", "event_type": "price_change"}}
{"_local_timestamp": "2026-01-25T23:34:52.323452+00:00", "data": {"market": "0x6fbec2c3327fe7b5392b94fe48ccb41c7404a4a793957804b4b8fe8239376d12", "price_changes": [{"asset_id": "74232891440125659542320690757580411929973234713273124974412544144242477879854", "price": "0.524", "size": "0", "side": "BUY", "hash": "74bb24a4b3b3e58455f6ad21459931b6c0035199", "best_bid": "0.957", "best_ask": "0.979"}, {"asset_id": "69250819494674008903342626376731306359291370006377470819342000624771511803405", "price": "0.476", "size": "0", "side": "SELL", "hash": "93920437989fb375d9346292706e83e663f4f975", "best_bid": "0.021", "best_ask": "0.043"}], "timestamp": "1769384092132", "event_type": "price_change"}}
{"_local_timestamp": "2026-01-25T23:34:52.336952+00:00", "data": {"market": "0x37d7295a17db461c15867862afe90bfad6cd46436b0d121a7c96c37e166103b4", "price_changes": [{"asset_id": "48325180813773997762337012603425087662105904105229463158116317479132765545801", "price": "0.931", "size": "0", "side": "BUY", "hash": "6eceb0139da9d66aa78956294ea4884b8db3a0b0", "best_bid": "0.989", "best_ask": "0.998"}, {"asset_id": "65341950601583802479848929397121491003949963027873255906537010617800365051709", "price": "0.069", "size": "0", "side": "SELL", "hash": "d78c8ab6115118afd07967a6a6b8bf54948a52a7", "best_bid": "0.002", "best_ask": "0.011"}], "timestamp": "1769384092154", "event_type": "price_change"}}
{"_local_timestamp": "2026-01-25T23:34:52.427594+00:00", "data": {"market": "0x6fbec2c3327fe7b5392b94fe48ccb41c7404a4a793957804b4b8fe8239376d12", "price_changes": [{"asset_id": "74232891440125659542320690757580411929973234713273124974412544144242477879854", "price": "0.913", "size": "0", "side": "BUY", "hash": "228d8a7f58aaa424ce87146de46be68269ab9296", "best_bid": "0.957", "best_ask": "0.979"}, {"asset_id": "69250819494674008903342626376731306359291370006377470819342000624771511803405", "price": "0.087", "size": "0", "side": "SELL", "hash": "aaf6a6673aa7c0c9f5e19fe7cd9e11a3e01963dd", "best_bid": "0.021", "best_ask": "0.043"}], "timestamp": "1769384092254", "event_type": "price_change"}}
{"_local_timestamp": "2026-01-25T23:34:54.074667+00:00", "data": {"market": "0x37d7295a17db461c15867862afe90bfad6cd46436b0d121a7c96c37e166103b4", "price_changes": [{"asset_id": "48325180813773997762337012603425087662105904105229463158116317479132765545801", "price": "0.927", "size": "0", "side": "BUY", "hash": "4ccf9d1b67f748551db6d3728e00cb08f8a1f2b0", "best_bid": "0.989", "best_ask": "0.998"}, {"asset_id": "65341950601583802479848929397121491003949963027873255906537010617800365051709", "price": "0.073", "size": "0", "side": "SELL", "hash": "6f2157530abfed5f54663e20f87bd6dc97d1d25a", "best_bid": "0.002", "best_ask": "0.011"}], "timestamp": "1769384093993", "event_type": "price_change"}}
{"_local_timestamp": "2026-01-25T23:34:54.075512+00:00", "data": {"market": "0x6fbec2c3327fe7b5392b94fe48ccb41c7404a4a793957804b4b8fe8239376d12", "price_changes": [{"asset_id": "74232891440125659542320690757580411929973234713273124974412544144242477879854", "price": "0.525", "size": "0", "side": "BUY", "hash": "3bf1d6ac963d889b30cf45b8345b336989317898", "best_bid": "0.957", "best_ask": "0.979"}, {"asset_id": "69250819494674008903342626376731306359291370006377470819342000624771511803405", "price": "0.475", "size": "0", "side": "SELL", "hash": "493c1c2d10ef13241e5fc490fa4f11367833b88f", "best_bid": "0.021", "best_ask": "0.043"}], "timestamp": "1769384093993", "event_type": "price_change"}}
{"_local_timestamp": "2026-01-25T23:34:54.101070+00:00", "data": {"market": "0x6fbec2c3327fe7b5392b94fe48ccb41c7404a4a793957804b4b8fe8239376d12", "price_changes": [{"asset_id": "74232891440125659542320690757580411929973234713273124974412544144242477879854", "price": "0.523", "size": "20", "side": "BUY", "hash": "d42d9ac2323420acc41c127f6a8712589f22d51c", "best_bid": "0.957", "best_ask": "0.979"}, {"asset_id": "69250819494674008903342626376731306359291370006377470819342000624771511803405", "price": "0.477", "size": "20", "side": "SELL", "hash": "7d6e1231e4b4e34cc14507438e47c87a5b4ebefb", "best_bid": "0.021", "best_ask": "0.043"}], "timestamp": "1769384094025", "event_type": "price_change"}}
{"_local_timestamp": "2026-01-25T23:34:54.102237+00:00", "data": {"market": "0x37d7295a17db461c15867862afe90bfad6cd46436b0d121a7c96c37e166103b4", "price_changes": [{"asset_id": "48325180813773997762337012603425087662105904105229463158116317479132765545801", "price": "0.921", "size": "20", "side": "BUY", "hash": "aeaf4190c4be4628099ee8b6384ac5ad9a96aec1", "best_bid": "0.989", "best_ask": "0.998"}, {"asset_id": "65341950601583802479848929397121491003949963027873255906537010617800365051709", "price": "0.079", "size": "20", "side": "SELL", "hash": "4f2deafca538df730d3414c6aee8b6ab4e4d7f57", "best_bid": "0.002", "best_ask": "0.011"}], "timestamp": "1769384094025", "event_type": "price_change"}}
{"_local_timestamp": "2026-01-25T23:34:54.341482+00:00", "data": {"market": "0x6fbec2c3327fe7b5392b94fe48ccb41c7404a4a793957804b4b8fe8239376d12", "price_changes": [{"asset_id": "74232891440125659542320690757580411929973234713273124974412544144242477879854", "price": "0.913", "size": "400", "side": "BUY", "hash": "c6521092f2f3c0021f6baa77665a0793f8153917", "best_bid": "0.957", "best_ask": "0.979"}, {"asset_id": "69250819494674008903342626376731306359291370006377470819342000624771511803405", "price": "0.087", "size": "400", "side": "SELL", "hash": "4da6859142c38023f4db6aa1c4612d1e1ee2a1c8", "best_bid": "0.021", "best_ask": "0.043"}], "timestamp": "1769384094237", "event_type": "price_change"}}
{"_local_timestamp": "2026-01-25T23:35:42.040490+00:00", "data": {"market": "0x420515ec56344b733661a732c2076be30c1e781a8ac0be429e7922dd1300f79e", "price_changes": [{"asset_id": "39911463294518973837477734365182517604962845619791762903432415094009656664664", "price": "0.002", "size": "4060", "side": "BUY", "hash": "57e2fe49836b50ab163bd45cecd87d6580ba02e2", "best_bid": "0.01", "best_ask": "0.015"}, {"asset_id": "90650468439874736440446229920104878218500894514970167199833753801761553782125", "price": "0.998", "size": "4060", "side": "SELL", "hash": "8b73e43c6f8191aa8546e339b17661c71a9159c3", "best_bid": "0.985", "best_ask": "0.99"}], "timestamp": "1769384141943", "event_type": "price_change"}}
{"_local_timestamp": "2026-01-25T23:35:42.111108+00:00", "data": {"market": "0x6fbec2c3327fe7b5392b94fe48ccb41c7404a4a793957804b4b8fe8239376d12", "price_changes": [{"asset_id": "74232891440125659542320690757580411929973234713273124974412544144242477879854", "price": "0.52", "size": "0", "side": "BUY", "hash": "093ae25db4ec48b2f108286b5c9daa5aad46000c", "best_bid": "0.957", "best_ask": "0.979"}, {"asset_id": "69250819494674008903342626376731306359291370006377470819342000624771511803405", "price": "0.48", "size": "0", "side": "SELL", "hash": "025b4cd545fdbeeb5809f14ea707bf6b51d893f6", "best_bid": "0.021", "best_ask": "0.043"}], "timestamp": "1769384142035", "event_type": "price_change"}}
{"_local_timestamp": "2026-01-25T23:35:42.128634+00:00", "data": {"market": "0x6fbec2c3327fe7b5392b94fe48ccb41c7404a4a793957804b4b8fe8239376d12", "price_changes": [{"asset_id": "74232891440125659542320690757580411929973234713273124974412544144242477879854", "price": "0.954", "size": "469", "side": "BUY", "hash": "b7517e175134a33bf67e5234743a93da368c81f5", "best_bid": "0.957", "best_ask": "0.979"}, {"asset_id": "69250819494674008903342626376731306359291370006377470819342000624771511803405", "price": "0.046", "size": "469", "side": "SELL", "hash": "996eb78818b1c3b27e8bffa5ebc40dc48b8c86e0", "best_bid": "0.021", "best_ask": "0.043"}], "timestamp": "1769384142046", "event_type": "price_change"}}
{"_local_timestamp": "2026-01-25T23:35:42.203733+00:00", "data": {"market": "0x6fbec2c3327fe7b5392b94fe48ccb41c7404a4a793957804b4b8fe8239376d12", "price_changes": [{"asset_id": "74232891440125659542320690757580411929973234713273124974412544144242477879854", "price": "0.922", "size": "60", "side": "BUY", "hash": "babc408c57a00385e760c72550469391b4d7557c", "best_bid": "0.957", "best_ask": "0.979"}, {"asset_id": "69250819494674008903342626376731306359291370006377470819342000624771511803405", "price": "0.078", "size": "60", "side": "SELL", "hash": "15b0439cb5b1110eb47c587b1a001a4ebd96e4d2", "best_bid": "0.021", "best_ask": "0.043"}], "timestamp": "1769384142136", "event_type": "price_change"}}
{"_local_timestamp": "2026-01-25T23:35:42.204286+00:00", "data": {"market": "0x6fbec2c3327fe7b5392b94fe48ccb41c7404a4a793957804b4b8fe8239376d12", "price_changes": [{"asset_id": "74232891440125659542320690757580411929973234713273124974412544144242477879854", "price": "0.524", "size": "445", "side": "BUY", "hash": "55040dec600e862c3dfea60f2db33c7b50286a20", "best_bid": "0.957", "best_ask": "0.979"}, {"asset_id": "69250819494674008903342626376731306359291370006377470819342000624771511803405", "price": "0.476", "size": "445", "side": "SELL", "hash": "61f187f96e45413f472caab9b25b3c0f1a0652ed", "best_bid": "0.021", "best_ask": "0.043"}], "timestamp": "1769384142137", "event_type": "price_change"}}
{"_local_timestamp": "2026-01-25T23:35:42.322601+00:00", "data": {"market": "0x6fbec2c3327fe7b5392b94fe48ccb41c7404a4a793957804b4b8fe8239376d12", "price_changes": [{"asset_id": "74232891440125659542320690757580411929973234713273124974412544144242477879854", "price": "0.913", "size": "0", "side": "BUY", "hash": "98f1fb63c25cbfc3878892cd07eca0f99b1ba940", "best_bid": "0.957", "best_ask": "0.979"}, {"asset_id": "69250819494674008903342626376731306359291370006377470819342000624771511803405", "price": "0.087", "size": "0", "side": "SELL", "hash": "c5ae287239532a4756e3cd50ab9373c41b5a0877", "best_bid": "0.021", "best_ask": "0.043"}], "timestamp": "1769384142254", "event_type": "price_change"}}
{"_local_timestamp": "2026-01-25T23:35:42.779022+00:00", "data": {"market": "0x6fbec2c3327fe7b5392b94fe48ccb41c7404a4a793957804b4b8fe8239376d12", "price_changes": [{"asset_id": "74232891440125659542320690757580411929973234713273124974412544144242477879854", "price": "0.524", "size": "0", "side": "BUY", "hash": "86d6f9ad2192030a7924a6189b7fc134bcaac13d", "best_bid": "0.957", "best_ask": "0.979"}, {"asset_id": "69250819494674008903342626376731306359291370006377470819342000624771511803405", "price": "0.476", "size": "0", "side": "SELL", "hash": "89cf9fceb59fb06ee7a0677cf935b9e16a04cd75", "best_bid": "0.021", "best_ask": "0.043"}], "timestamp": "1769384142711", "event_type": "price_change"}}
{"_local_timestamp": "2026-01-25T23:35:43.240209+00:00", "data": {"market": "0x6fbec2c3327fe7b5392b94fe48ccb41c7404a4a793957804b4b8fe8239376d12", "price_changes": [{"asset_id": "69250819494674008903342626376731306359291370006377470819342000624771511803405", "price": "0.052", "size": "120", "side": "SELL", "hash": "1b4b44f3e2f2af52f7cadb81c7a5c8f2b6475e31", "best_bid": "0.021", "best_ask": "0.043"}, {"asset_id": "74232891440125659542320690757580411929973234713273124974412544144242477879854", "price": "0.948", "size": "120", "side": "BUY", "hash": "4ed39b1ea112c35684ab4fb0477065155207f98e", "best_bid": "0.957", "best_ask": "0.979"}], "timestamp": "1769384143169", "event_type": "price_change"}}
{"_local_timestamp": "2026-01-25T23:35:43.295724+00:00", "data": {"market": "0x6fbec2c3327fe7b5392b94fe48ccb41c7404a4a793957804b4b8fe8239376d12", "price_changes": [{"asset_id": "69250819494674008903342626376731306359291370006377470819342000624771511803405", "price": "0.045", "size": "30", "side": "SELL", "hash": "426aaad8e0b4fa5d85ec12caf60166bfd8d9f224", "best_bid": "0.021", "best_ask": "0.043"}, {"asset_id": "74232891440125659542320690757580411929973234713273124974412544144242477879854", "price": "0.955", "size": "30", "side": "BUY", "hash": "83ebfa684fecba18e60883fe49eec106b525cd1c", "best_bid": "0.957", "best_ask": "0.979"}], "timestamp": "1769384143226", "event_type": "price_change"}}
{"_local_timestamp": "2026-01-25T23:35:43.406041+00:00", "data": {"market": "0x6fbec2c3327fe7b5392b94fe48ccb41c7404a4a793957804b4b8fe8239376d12", "price_changes": [{"asset_id": "74232891440125659542320690757580411929973234713273124974412544144242477879854", "price": "0.956", "size": "25", "side": "BUY", "hash": "c80c5312e285d04616f883059d6b1b16a2703fb1", "best_bid": "0.957", "best_ask": "0.979"}, {"asset_id": "69250819494674008903342626376731306359291370006377470819342000624771511803405", "price": "0.044", "size": "25", "side": "SELL", "hash": "f84b3556eb57e203dbf62b1f4f59a597fd825ff3", "best_bid": "0.021", "best_ask": "0.043"}], "timestamp": "1769384143333", "event_type": "price_change"}}
{"_local_timestamp": "2026-01-25T23:35:56.947926+00:00", "data": {"market": "0x50e54348ebdc5218e17ab7cec6c6d1bda4816f979984717cf462d816921255d6", "price_changes": [{"asset_id": "68807170344581978269785042777291531812907438296702298129119130028792894246621", "price": "0.07", "size": "263.36", "side": "BUY", "hash": "7154564acff7eb23585c18e20a474b822df7014f", "best_bid": "0.08", "best_ask": "0.1"}, {"asset_id": "82547212645026470525278120787743350118721505496069116064469109192086879778892", "price": "0.93", "size": "263.36", "side": "SELL", "hash": "5ce62aedbe81e1e4185a9105935f8eb08369e61f", "best_bid": "0.9", "best_ask": "0.92"}], "timestamp": "1769384156861", "event_type": "price_change"}}
{"_local_timestamp": "2026-01-25T23:35:58.845312+00:00", "data": {"market": "0x50e54348ebdc5218e17ab7cec6c6d1bda4816f979984717cf462d816921255d6", "price_changes": [{"asset_id": "68807170344581978269785042777291531812907438296702298129119130028792894246621", "price": "0.07", "size": "238.36", "side": "BUY", "hash": "5ace5e51b37459162c05a584b68b83c51a81bc65", "best_bid": "0.08", "best_ask": "0.1"}, {"asset_id": "82547212645026470525278120787743350118721505496069116064469109192086879778892", "price": "0.93", "size": "238.36", "side": "SELL", "hash": "1a6aa1d4d5b1b7547dfbae99a3fb7999fded1cf6", "best_bid": "0.9", "best_ask": "0.92"}], "timestamp": "1769384158768", "event_type": "price_change"}}
{"_local_timestamp": "2026-01-25T23:35:58.845901+00:00", "data": {"market": "0xfebf77a5fafe69270ae88267592d6af563d5fb8038167c1e5f0f84389a180b24", "price_changes": [{"asset_id": "108070880530079055956658493954731541905445967268057229566528793256732992302888", "price": "0.937", "size": "0", "side": "BUY", "hash": "4b5c7ca58aa1a837affa707d439dfc593e660400", "best_bid": "0.956", "best_ask": "0.957"}, {"asset_id": "22601624556062096769343443867020199590792651484414597499875211914147125190628", "price": "0.063", "size": "0", "side": "SELL", "hash": "d094a8538b1efe45534b98283f6b05eaa8ab6f38", "best_bid": "0.043", "best_ask": "0.044"}], "timestamp": "1769384158768", "event_type": "price_change"}}
{"_local_timestamp": "2026-01-25T23:36:05.242204+00:00", "data": {"market": "0x420515ec56344b733661a732c2076be30c1e781a8ac0be429e7922dd1300f79e", "price_changes": [{"asset_id": "39911463294518973837477734365182517604962845619791762903432415094009656664664", "price": "0.009", "size": "200", "side": "BUY", "hash": "6a664e277ac2119183991f46c6178427ce7ef4de", "best_bid": "0.01", "best_ask": "0.015"}, {"asset_id": "90650468439874736440446229920104878218500894514970167199833753801761553782125", "price": "0.991", "size": "200", "side": "SELL", "hash": "812fd1eb74581a8278beebc8eb893094975ce237", "best_bid": "0.985", "best_ask": "0.99"}], "timestamp": "1769384165167", "event_type": "price_change"}}
{"_local_timestamp": "2026-01-25T23:36:09.339039+00:00", "data": {"market": "0x420515ec56344b733661a732c2076be30c1e781a8ac0be429e7922dd1300f79e", "price_changes": [{"asset_id": "39911463294518973837477734365182517604962845619791762903432415094009656664664", "price": "0.011", "size": "100", "side": "BUY", "hash": "8c1b62d17879a84ac8ba0c22f7685b541fed4198", "best_bid": "0.011", "best_ask": "0.015"}, {"asset_id": "90650468439874736440446229920104878218500894514970167199833753801761553782125", "price": "0.989", "size": "100", "side": "SELL", "hash": "d594907ba319e570c7ca0d21286250f8b39d80f8", "best_bid": "0.985", "best_ask": "0.989"}], "timestamp": "1769384169260", "event_type": "price_change"}}
{"_local_timestamp": "2026-01-25T23:36:09.442619+00:00", "data": {"market": "0x6fbec2c3327fe7b5392b94fe48ccb41c7404a4a793957804b4b8fe8239376d12", "price_changes": [{"asset_id": "74232891440125659542320690757580411929973234713273124974412544144242477879854", "price": "0.957", "size": "40", "side": "BUY", "hash": "910216289a015da25c853f18b65e85d54cd2fa2c", "best_bid": "0.957", "best_ask": "0.979"}, {"asset_id": "69250819494674008903342626376731306359291370006377470819342000624771511803405", "price": "0.043", "size": "40", "side": "SELL", "hash": "f6ecc88f973ade7dd48db5dd8ba5e3e978284666", "best_bid": "0.021", "best_ask": "0.043"}], "timestamp": "1769384169372", "event_type": "price_change"}}
{"_local_timestamp": "2026-01-25T23:36:09.449103+00:00", "data": {"market": "0x6fbec2c3327fe7b5392b94fe48ccb41c7404a4a793957804b4b8fe8239376d12", "price_changes": [{"asset_id": "74232891440125659542320690757580411929973234713273124974412544144242477879854", "price": "0.956", "size": "0", "side": "BUY", "hash": "0a2bf0e9788acf9b86d63448fbc79a38c9840ffe", "best_bid": "0.957", "best_ask": "0.979"}, {"asset_id": "69250819494674008903342626376731306359291370006377470819342000624771511803405", "price": "0.044", "size": "0", "side": "SELL", "hash": "4a2f85383f2c3e4eef9a9fc1422d3543d7ecd7bc", "best_bid": "0.021", "best_ask": "0.043"}], "timestamp": "1769384169381", "event_type": "price_change"}}
{"_local_timestamp": "2026-01-25T23:36:09.555450+00:00", "data": {"market": "0x6fbec2c3327fe7b5392b94fe48ccb41c7404a4a793957804b4b8fe8239376d12", "price_changes": [{"asset_id": "74232891440125659542320690757580411929973234713273124974412544144242477879854", "price": "0.957", "size": "15", "side": "BUY", "hash": "558e453059c77510b279669dcb9c7df6211c2089", "best_bid": "0.957", "best_ask": "0.979"}, {"asset_id": "69250819494674008903342626376731306359291370006377470819342000624771511803405", "price": "0.043", "size": "15", "side": "SELL", "hash": "0752da6749217db402d45642a3de46eb93d7c833", "best_bid": "0.021", "best_ask": "0.043"}], "timestamp": "1769384169482", "event_type": "price_change"}}
{"_local_timestamp": "2026-01-25T23:36:10.580783+00:00", "data": {"market": "0x2bc8904e63111922dbb8aa2ecbd935c10130ceeb5167c3a1cd48989e504d65cd", "price_changes": [{"asset_id": "43967046964650296862718544762979896408581681199546182297336634987235910393568", "price": "0.835", "size": "0", "side": "BUY", "hash": "3eb2d60ed68f4115e480642c8b12f95e2b894bf1", "best_bid": "0.998", "best_ask": "0.999"}, {"asset_id": "11968900827408027706057371039694540476481122819980191101376609555175318452594", "price": "0.165", "size": "0", "side": "SELL", "hash": "d11c092f87dfa15b06c5162779fe0b952be6bf37", "best_bid": "0.001", "best_ask": "0.002"}], "timestamp": "1769384170510", "event_type": "price_change"}}
{"_local_timestamp": "2026-01-25T23:36:10.581414+00:00", "data": {"market": "0x361332f8ab0a017e877b225e96c6a35456bc1dc5d4db796c472d4f71e7a79d54", "price_changes": [{"asset_id": "63660917184917833894774068366011139137101685355449306463901993722479265901077", "price": "0.93", "size": "40", "side": "BUY", "hash": "2d5a8aa224a5d8a4876b78e6e8a2e266867c1a18", "best_bid": "0.997", "best_ask": "0.999"}, {"asset_id": "78192483840796682442570224034600338690521812139428085048513940589175925504286", "price": "0.07", "size": "40", "side": "SELL", "hash": "4296b5fbb52570a33de3001419026493ff60daee", "best_bid": "0.001", "best_ask": "0.003"}], "timestamp": "1769384170510", "event_type": "price_change"}}
{"_local_timestamp": "2026-01-25T23:36:10.611450+00:00", "data": {"market": "0x361332f8ab0a017e877b225e96c6a35456bc1dc5d4db796c472d4f71e7a79d54", "price_changes": [{"asset_id": "63660917184917833894774068366011139137101685355449306463901993722479265901077", "price": "0.931", "size": "20", "side": "BUY", "hash": "f8c9b717182dcb8ef5ec50d9668f04855f65a6c2", "best_bid": "0.997", "best_ask": "0.999"}, {"asset_id": "78192483840796682442570224034600338690521812139428085048513940589175925504286", "price": "0.069", "size": "20", "side": "SELL", "hash": "217dc6b518e1df17749ae601e607de094d15f3a2", "best_bid": "0.001", "best_ask": "0.003"}], "timestamp": "1769384170537", "event_type": "price_change"}}
{"_local_timestamp": "2026-01-25T23:36:10.612129+00:00", "data": {"market": "0x2bc8904e63111922dbb8aa2ecbd935c10130ceeb5167c3a1cd48989e504d65cd", "price_changes": [{"asset_id": "43967046964650296862718544762979896408581681199546182297336634987235910393568", "price": "0.931", "size": "20", "side": "BUY", "hash": "b26b233f976eec7a1f3d96d63b02a18ad942ddf1", "best_bid": "0.998", "best_ask": "0.999"}, {"asset_id": "11968900827408027706057371039694540476481122819980191101376609555175318452594", "price": "0.069", "size": "20", "side": "SELL", "hash": "c25e2fb8ffdcec1c47b2b7150819c0f3eb5dcae9", "best_bid": "0.001", "best_ask": "0.002"}], "timestamp": "1769384170538", "event_type": "price_change"}}
{"_local_timestamp": "2026-01-25T23:36:10.696423+00:00", "data": {"market": "0x6fbec2c3327fe7b5392b94fe48ccb41c7404a4a793957804b4b8fe8239376d12", "price_changes": [{"asset_id": "74232891440125659542320690757580411929973234713273124974412544144242477879854", "price": "0.956", "size": "25", "side": "BUY", "hash": "307f32ccc6711d660fb9a5c8269b53655ddf95d6", "best_bid": "0.957", "best_ask": "0.979"}, {"asset_id": "69250819494674008903342626376731306359291370006377470819342000624771511803405", "price": "0.044", "size": "25", "side": "SELL", "hash": "db48af94dbd6d43e5b05da7890424d57a21abc8a", "best_bid": "0.021", "best_ask": "0.043"}], "timestamp": "1769384170617", "event_type": "price_change"}}
{"_local_timestamp": "2026-01-25T23:36:22.453739+00:00", "data": {"market": "0x6fbec2c3327fe7b5392b94fe48ccb41c7404a4a793957804b4b8fe8239376d12", "price_changes": [{"asset_id": "74232891440125659542320690757580411929973234713273124974412544144242477879854", "price": "0.956", "size": "0", "side": "BUY", "hash": "8048cac3ce0f7a98988404f190c7bc577bbf8261", "best_bid": "0.957", "best_ask": "0.979"}, {"asset_id": "69250819494674008903342626376731306359291370006377470819342000624771511803405", "price": "0.044", "size": "0", "side": "SELL", "hash": "e7744d6b1e11f0029cd57f1067b09b13181ff114", "best_bid": "0.021", "best_ask": "0.043"}], "timestamp": "1769384182386", "event_type": "price_change"}}
{"_local_timestamp": "2026-01-25T23:36:22.466550+00:00", "data": {"market": "0x6fbec2c3327fe7b5392b94fe48ccb41c7404a4a793957804b4b8fe8239376d12", "price_changes": [{"asset_id": "74232891440125659542320690757580411929973234713273124974412544144242477879854", "price": "0.957", "size": "40", "side": "BUY", "hash": "6732a11f97d939881a507f1638bf9fa07fb95835", "best_bid": "0.957", "best_ask": "0.979"}, {"asset_id": "69250819494674008903342626376731306359291370006377470819342000624771511803405", "price": "0.043", "size": "40", "side": "SELL", "hash": "197cfea0e576893c8b200fa7f56db656854cc4ef", "best_bid": "0.021", "best_ask": "0.043"}], "timestamp": "1769384182397", "event_type": "price_change"}}
{"_local_timestamp": "2026-01-25T23:36:22.526138+00:00", "data": {"market": "0x6fbec2c3327fe7b5392b94fe48ccb41c7404a4a793957804b4b8fe8239376d12", "price_changes": [{"asset_id": "74232891440125659542320690757580411929973234713273124974412544144242477879854", "price": "0.522", "size": "0", "side": "BUY", "hash": "5f16f7332e4c747b917cf24fd725883f7ca8ddc4", "best_bid": "0.957", "best_ask": "0.979"}, {"asset_id": "69250819494674008903342626376731306359291370006377470819342000624771511803405", "price": "0.478", "size": "0", "side": "SELL", "hash": "d7997fff7c6a14c45dc54859bd1a0b82b5934079", "best_bid": "0.021", "best_ask": "0.043"}], "timestamp": "1769384182460", "event_type": "price_change"}}
{"_local_timestamp": "2026-01-25T23:36:22.582355+00:00", "data": {"market": "0x6fbec2c3327fe7b5392b94fe48ccb41c7404a4a793957804b4b8fe8239376d12", "price_changes": [{"asset_id": "74232891440125659542320690757580411929973234713273124974412544144242477879854", "price": "0.957", "size": "15", "side": "BUY", "hash": "fad87bf421dafc765ac6f44cb8b0d57cea602b9c", "best_bid": "0.957", "best_ask": "0.979"}, {"asset_id": "69250819494674008903342626376731306359291370006377470819342000624771511803405", "price": "0.043", "size": "15", "side": "SELL", "hash": "984d03355d6679f9bf37862189544f51c04c04a1", "best_bid": "0.021", "best_ask": "0.043"}], "timestamp": "1769384182511", "event_type": "price_change"}}
{"_local_timestamp": "2026-01-25T23:36:22.747199+00:00", "data": {"market": "0x6fbec2c3327fe7b5392b94fe48ccb41c7404a4a793957804b4b8fe8239376d12", "price_changes": [{"asset_id": "74232891440125659542320690757580411929973234713273124974412544144242477879854", "price": "0.524", "size": "30", "side": "BUY", "hash": "48b55b28e1fd8d04703d02711412bf2b65025f23", "best_bid": "0.957", "best_ask": "0.979"}, {"asset_id": "69250819494674008903342626376731306359291370006377470819342000624771511803405", "price": "0.476", "size": "30", "side": "SELL", "hash": "305758d4ca668296ba0888551de86833de1d6407", "best_bid": "0.021", "best_ask": "0.043"}], "timestamp": "1769384182665", "event_type": "price_change"}}
{"_local_timestamp": "2026-01-25T23:36:26.162618+00:00", "data": {"market": "0x6fbec2c3327fe7b5392b94fe48ccb41c7404a4a793957804b4b8fe8239376d12", "price_changes": [{"asset_id": "74232891440125659542320690757580411929973234713273124974412544144242477879854", "price": "0.523", "size": "0", "side": "BUY", "hash": "169df9a37daf0dfccfe64caac3748cc348ffb0e0", "best_bid": "0.957", "best_ask": "0.979"}, {"asset_id": "69250819494674008903342626376731306359291370006377470819342000624771511803405", "price": "0.477", "size": "0", "side": "SELL", "hash": "6fb315f8589460e2fad1f7559cbea0d169f09e63", "best_bid": "0.021", "best_ask": "0.043"}], "timestamp": "1769384186071", "event_type": "price_change"}}
{"_local_timestamp": "2026-01-25T23:36:26.189215+00:00", "data": {"market": "0x6fbec2c3327fe7b5392b94fe48ccb41c7404a4a793957804b4b8fe8239376d12", "price_changes": [{"asset_id": "74232891440125659542320690757580411929973234713273124974412544144242477879854", "price": "0.525", "size": "20", "side": "BUY", "hash": "747087efc5f3715d9d52004aeb78d51e43b1481e", "best_bid": "0.957", "best_ask": "0.979"}, {"asset_id": "69250819494674008903342626376731306359291370006377470819342000624771511803405", "price": "0.475", "size": "20", "side": "SELL", "hash": "14af43043f84374fee9f16e6e5572fd79c22b01e", "best_bid": "0.021", "best_ask": "0.043"}], "timestamp": "1769384186103", "event_type": "price_change"}}
{"_local_timestamp": "2026-01-25T23:36:26.259691+00:00", "data": {"market": "0x6fbec2c3327fe7b5392b94fe48ccb41c7404a4a793957804b4b8fe8239376d12", "price_changes": [{"asset_id": "74232891440125659542320690757580411929973234713273124974412544144242477879854", "price": "0.957", "size": "40", "side": "BUY", "hash": "503a25fffe52f63dc9b0ce73b84f6d427834223b", "best_bid": "0.957", "best_ask": "0.979"}, {"asset_id": "69250819494674008903342626376731306359291370006377470819342000624771511803405", "price": "0.043", "size": "40", "side": "SELL", "hash": "8daaef64576a96b8e316f48ab6aa9757ef02479c", "best_bid": "0.021", "best_ask": "0.043"}], "timestamp": "1769384186187", "event_type": "price_change"}}
{"_local_timestamp": "2026-01-25T23:36:27.131647+00:00", "data": {"market": "0x50e54348ebdc5218e17ab7cec6c6d1bda4816f979984717cf462d816921255d6", "price_changes": [{"asset_id": "68807170344581978269785042777291531812907438296702298129119130028792894246621", "price": "0.07", "size": "263.36", "side": "BUY", "hash": "e982dac730c316ba9b99700d9ffe4d3a30724b7a", "best_bid": "0.08", "best_ask": "0.1"}, {"asset_id": "82547212645026470525278120787743350118721505496069116064469109192086879778892", "price": "0.93", "size": "263.36", "side": "SELL", "hash": "0af00d993a75cc06bc3ffca5781512ce2d162706", "best_bid": "0.9", "best_ask": "0.92"}], "timestamp": "1769384187007", "event_type": "price_change"}}
{"_local_timestamp": "2026-01-25T23:36:27.132296+00:00", "data": {"market": "0xfebf77a5fafe69270ae88267592d6af563d5fb8038167c1e5f0f84389a180b24", "price_changes": [{"asset_id": "108070880530079055956658493954731541905445967268057229566528793256732992302888", "price": "0.938", "size": "61.04", "side": "BUY", "hash": "5f82018cfdf76502de882da8b13ed7dc03888bad", "best_bid": "0.956", "best_ask": "0.957"}, {"asset_id": "22601624556062096769343443867020199590792651484414597499875211914147125190628", "price": "0.062", "size": "61.04", "side": "SELL", "hash": "b675ba11f24f21d165bb429773cd3f2cb9277c8a", "best_bid": "0.043", "best_ask": "0.044"}], "timestamp": "1769384187010", "event_type": "price_change"}}
{"_local_timestamp": "2026-01-25T23:36:27.288278+00:00", "data": {"market": "0xfebf77a5fafe69270ae88267592d6af563d5fb8038167c1e5f0f84389a180b24", "price_changes": [{"asset_id": "108070880530079055956658493954731541905445967268057229566528793256732992302888", "price": "0.938", "size": "0", "side": "BUY", "hash": "86580a091f9f13c857152f284a94bff7a8977b75", "best_bid": "0.956", "best_ask": "0.957"}, {"asset_id": "22601624556062096769343443867020199590792651484414597499875211914147125190628", "price": "0.062", "size": "0", "side": "SELL", "hash": "8787ae17bd7e4416873122176fbf5d001539dc19", "best_bid": "0.043", "best_ask": "0.044"}], "timestamp": "1769384187219", "event_type": "price_change"}}
{"_local_timestamp": "2026-01-25T23:36:27.402904+00:00", "data": {"market": "0xfebf77a5fafe69270ae88267592d6af563d5fb8038167c1e5f0f84389a180b24", "price_changes": [{"asset_id": "108070880530079055956658493954731541905445967268057229566528793256732992302888", "price": "0.938", "size": "61.04", "side": "BUY", "hash": "9d8c784c182a9d67a76eda6a038c3a0b4c740486", "best_bid": "0.956", "best_ask": "0.957"}, {"asset_id": "22601624556062096769343443867020199590792651484414597499875211914147125190628", "price": "0.062", "size": "61.04", "side": "SELL", "hash": "4baac43b7af0d5ee032538e5b69f9559970d1ee9", "best_bid": "0.043", "best_ask": "0.044"}], "timestamp": "1769384187332", "event_type": "price_change"}}
{"_local_timestamp": "2026-01-25T23:36:27.713747+00:00", "data": {"market": "0xfebf77a5fafe69270ae88267592d6af563d5fb8038167c1e5f0f84389a180b24", "price_changes": [{"asset_id": "108070880530079055956658493954731541905445967268057229566528793256732992302888", "price": "0.938", "size": "0", "side": "BUY", "hash": "6249cf5556afc90c9b2e410d103e35d7294ff992", "best_bid": "0.956", "best_ask": "0.957"}, {"asset_id": "22601624556062096769343443867020199590792651484414597499875211914147125190628", "price": "0.062", "size": "0", "side": "SELL", "hash": "0efc1f6d42f8708f3dd4bb5e9fc657e2026de49d", "best_bid": "0.043", "best_ask": "0.044"}], "timestamp": "1769384187644", "event_type": "price_change"}}
{"_local_timestamp": "2026-01-25T23:36:27.853274+00:00", "data": {"market": "0xfebf77a5fafe69270ae88267592d6af563d5fb8038167c1e5f0f84389a180b24", "price_changes": [{"asset_id": "108070880530079055956658493954731541905445967268057229566528793256732992302888", "price": "0.938", "size": "61.04", "side": "BUY", "hash": "2b8e2e7fc89344fc829da7ae954e2e72cd34add3", "best_bid": "0.956", "best_ask": "0.957"}, {"asset_id": "22601624556062096769343443867020199590792651484414597499875211914147125190628", "price": "0.062", "size": "61.04", "side": "SELL", "hash": "436982e107e3151d5a5b04bd0bfc7e22e5c483a0", "best_bid": "0.043", "best_ask": "0.044"}], "timestamp": "1769384187775", "event_type": "price_change"}}
{"_local_timestamp": "2026-01-25T23:36:27.890012+00:00", "data": {"market": "0xfebf77a5fafe69270ae88267592d6af563d5fb8038167c1e5f0f84389a180b24", "price_changes": [{"asset_id": "108070880530079055956658493954731541905445967268057229566528793256732992302888", "price": "0.913", "size": "66.66", "side": "BUY", "hash": "238593ba22b1ccba8205a9cdbe3ae3f2576b3c4f", "best_bid": "0.956", "best_ask": "0.957"}, {"asset_id": "22601624556062096769343443867020199590792651484414597499875211914147125190628", "price": "0.087", "size": "66.66", "side": "SELL", "hash": "461cda6d7a5c61336058b97de100c95ce75848c1", "best_bid": "0.043", "best_ask": "0.044"}], "timestamp": "1769384187821", "event_type": "price_change"}}
{"_local_timestamp": "2026-01-25T23:36:27.899661+00:00", "data": {"market": "0xfebf77a5fafe69270ae88267592d6af563d5fb8038167c1e5f0f84389a180b24", "price_changes": [{"asset_id": "108070880530079055956658493954731541905445967268057229566528793256732992302888", "price": "0.954", "size": "66.66", "side": "BUY", "hash": "48f027e733977b14505cc17528339070487bca35", "best_bid": "0.956", "best_ask": "0.957"}, {"asset_id": "22601624556062096769343443867020199590792651484414597499875211914147125190628", "price": "0.046", "size": "66.66", "side": "SELL", "hash": "1962d42532b36ef569d245be864820e9dcf9cd4b", "best_bid": "0.043", "best_ask": "0.044"}], "timestamp": "1769384187830", "event_type": "price_change"}}
{"_local_timestamp": "2026-01-25T23:36:27.911690+00:00", "data": {"market": "0xfebf77a5fafe69270ae88267592d6af563d5fb8038167c1e5f0f84389a180b24", "price_changes": [{"asset_id": "108070880530079055956658493954731541905445967268057229566528793256732992302888", "price": "0.872", "size": "86.66", "side": "BUY", "hash": "0f3ea1b425e5941cd9c5deadeadbe77a82f2c5ef", "best_bid": "0.956", "best_ask": "0.957"}, {"asset_id": "22601624556062096769343443867020199590792651484414597499875211914147125190628", "price": "0.128", "size": "86.66", "side": "SELL", "hash": "1f6196bf2e6242a6dcb775d2ff1737458731321e", "best_bid": "0.043", "best_ask": "0.044"}], "timestamp": "1769384187834", "event_type": "price_change"}}
{"_local_timestamp": "2026-01-25T23:36:27.933307+00:00", "data": {"market": "0xfebf77a5fafe69270ae88267592d6af563d5fb8038167c1e5f0f84389a180b24", "price_changes": [{"asset_id": "22601624556062096769343443867020199590792651484414597499875211914147125190628", "price": "0.04", "size": "26", "side": "BUY", "hash": "412f4fa32824c190b31c2d25409f9074dea8f9cf", "best_bid": "0.043", "best_ask": "0.044"}, {"asset_id": "108070880530079055956658493954731541905445967268057229566528793256732992302888", "price": "0.96", "size": "26", "side": "SELL", "hash": "2b5e108f40bc9ae55c0ddda4a8fb2e1fc8b28e0f", "best_bid": "0.956", "best_ask": "0.957"}], "timestamp": "1769384187864", "event_type": "price_change"}}
{"_local_timestamp": "2026-01-25T23:36:28.363781+00:00", "data": {"market": "0xfebf77a5fafe69270ae88267592d6af563d5fb8038167c1e5f0f84389a180b24", "price_changes": [{"asset_id": "108070880530079055956658493954731541905445967268057229566528793256732992302888", "price": "0.872", "size": "66.66", "side": "BUY", "hash": "8e29c391112e277bb83ef152bd3db10dc8a9b34f", "best_bid": "0.956", "best_ask": "0.957"}, {"asset_id": "22601624556062096769343443867020199590792651484414597499875211914147125190628", "price": "0.128", "size": "66.66", "side": "SELL", "hash": "4d0230ba3f20dbf4246bfee4e0ebb8341f64e6cd", "best_bid": "0.043", "best_ask": "0.044"}], "timestamp": "1769384188292", "event_type": "price_change"}}
{"_local_timestamp": "2026-01-25T23:36:28.397665+00:00", "data": {"market": "0xfebf77a5fafe69270ae88267592d6af563d5fb8038167c1e5f0f84389a180b24", "price_changes": [{"asset_id": "108070880530079055956658493954731541905445967268057229566528793256732992302888", "price": "0.873", "size": "20", "side": "BUY", "hash": "ca92a42d47c4fe6d5d8609bc8afc2fec0133601d", "best_bid": "0.956", "best_ask": "0.957"}, {"asset_id": "22601624556062096769343443867020199590792651484414597499875211914147125190628", "price": "0.127", "size": "20", "side": "SELL", "hash": "d07d418d247af93a544d94965dc25ae0ed01efcd", "best_bid": "0.043", "best_ask": "0.044"}], "timestamp": "1769384188322", "event_type": "price_change"}}
{"_local_timestamp": "2026-01-25T23:36:28.503514+00:00", "data": {"market": "0xfebf77a5fafe69270ae88267592d6af563d5fb8038167c1e5f0f84389a180b24", "price_changes": [{"asset_id": "108070880530079055956658493954731541905445967268057229566528793256732992302888", "price": "0.938", "size": "0", "side": "BUY", "hash": "1ec02833273b092965d1cf86a925f31d7d527971", "best_bid": "0.956", "best_ask": "0.957"}, {"asset_id": "22601624556062096769343443867020199590792651484414597499875211914147125190628", "price": "0.062", "size": "0", "side": "SELL", "hash": "3b0ee8ebffa009a556f129741a149597dd19dfa9", "best_bid": "0.043", "best_ask": "0.044"}], "timestamp": "1769384188435", "event_type": "price_change"}}
{"_local_timestamp": "2026-01-25T23:36:28.632553+00:00", "data": {"market": "0xfebf77a5fafe69270ae88267592d6af563d5fb8038167c1e5f0f84389a180b24", "price_changes": [{"asset_id": "108070880530079055956658493954731541905445967268057229566528793256732992302888", "price": "0.938", "size": "61.04", "side": "BUY", "hash": "495a242e1c2bd52490f927efc5db667a22e5b4e7", "best_bid": "0.956", "best_ask": "0.957"}, {"asset_id": "22601624556062096769343443867020199590792651484414597499875211914147125190628", "price": "0.062", "size": "61.04", "side": "SELL", "hash": "37447e77651f04371b058f72c7ba2591a077a7e3", "best_bid": "0.043", "best_ask": "0.044"}], "timestamp": "1769384188550", "event_type": "price_change"}}
{"_local_timestamp": "2026-01-25T23:36:28.930511+00:00", "data": {"market": "0x50e54348ebdc5218e17ab7cec6c6d1bda4816f979984717cf462d816921255d6", "price_changes": [{"asset_id": "68807170344581978269785042777291531812907438296702298129119130028792894246621", "price": "0.07", "size": "255.29", "side": "BUY", "hash": "1b93ffc821e2e002ed1ee887d6cce6a79a5ee6c1", "best_bid": "0.08", "best_ask": "0.1"}, {"asset_id": "82547212645026470525278120787743350118721505496069116064469109192086879778892", "price": "0.93", "size": "255.29", "side": "SELL", "hash": "70b7a04145211c7b7b48ee0e657ef8c141370d82", "best_bid": "0.9", "best_ask": "0.92"}], "timestamp": "1769384188820", "event_type": "price_change"}}
{"_local_timestamp": "2026-01-25T23:36:28.973568+00:00", "data": {"market": "0x420515ec56344b733661a732c2076be30c1e781a8ac0be429e7922dd1300f79e", "price_changes": [{"asset_id": "39911463294518973837477734365182517604962845619791762903432415094009656664664", "price": "0.002", "size": "400", "side": "BUY", "hash": "135584075ab94478c9693dacdfb7925c857f8ebe", "best_bid": "0.011", "best_ask": "0.015"}, {"asset_id": "90650468439874736440446229920104878218500894514970167199833753801761553782125", "price": "0.998", "size": "400", "side": "SELL", "hash": "39e0a04210604c1de4bda83d4a94aaa53489be47", "best_bid": "0.985", "best_ask": "0.989"}], "timestamp": "1769384188848", "event_type": "price_change"}}
{"_local_timestamp": "2026-01-25T23:36:29.042376+00:00", "data": {"market": "0x420515ec56344b733661a732c2076be30c1e781a8ac0be429e7922dd1300f79e", "price_changes": [{"asset_id": "39911463294518973837477734365182517604962845619791762903432415094009656664664", "price": "0.01", "size": "250", "side": "BUY", "hash": "7392e18982428e7ed4812dcfd5446915f3ed642e", "best_bid": "0.011", "best_ask": "0.015"}, {"asset_id": "90650468439874736440446229920104878218500894514970167199833753801761553782125", "price": "0.99", "size": "250", "side": "SELL", "hash": "6ea527678b270e153b7d59f4e2e816444156e46d", "best_bid": "0.985", "best_ask": "0.989"}], "timestamp": "1769384188921", "event_type": "price_change"}}
{"_local_timestamp": "2026-01-25T23:36:32.454124+00:00", "data": {"market": "0xfebf77a5fafe69270ae88267592d6af563d5fb8038167c1e5f0f84389a180b24", "price_changes": [{"asset_id": "108070880530079055956658493954731541905445967268057229566528793256732992302888", "price": "0.938", "size": "0", "side": "BUY", "hash": "04c2779fe2908dfb77a3763a43c2946a89bd6a25", "best_bid": "0.956", "best_ask": "0.957"}, {"asset_id": "22601624556062096769343443867020199590792651484414597499875211914147125190628", "price": "0.062", "size": "0", "side": "SELL", "hash": "480df0c38c728f1b3d5f13760a26320badc56cbb", "best_bid": "0.043", "best_ask": "0.044"}], "timestamp": "1769384192383", "event_type": "price_change"}}
{"_local_timestamp": "2026-01-25T23:36:32.519676+00:00", "data": {"market": "0xfebf77a5fafe69270ae88267592d6af563d5fb8038167c1e5f0f84389a180b24", "price_changes": [{"asset_id": "108070880530079055956658493954731541905445967268057229566528793256732992302888", "price": "0.938", "size": "61.04", "side": "BUY", "hash": "afd9f91fe15aee4c961369ab072dc1897597e2f3", "best_bid": "0.956", "best_ask": "0.957"}, {"asset_id": "22601624556062096769343443867020199590792651484414597499875211914147125190628", "price": "0.062", "size": "61.04", "side": "SELL", "hash": "ce4af5f23fd562fef518b95e46b0c72abc7abeaa", "best_bid": "0.043", "best_ask": "0.044"}], "timestamp": "1769384192445", "event_type": "price_change"}}
{"_local_timestamp": "2026-01-25T23:36:33.512982+00:00", "data": {"market": "0xfebf77a5fafe69270ae88267592d6af563d5fb8038167c1e5f0f84389a180b24", "price_changes": [{"asset_id": "108070880530079055956658493954731541905445967268057229566528793256732992302888", "price": "0.938", "size": "0", "side": "BUY", "hash": "552c5d90759f50e564dcf6a5ad68fe791739ea8a", "best_bid": "0.956", "best_ask": "0.957"}, {"asset_id": "22601624556062096769343443867020199590792651484414597499875211914147125190628", "price": "0.062", "size": "0", "side": "SELL", "hash": "4d455fb40c9663faf30bddca2a8a6b1e8b13ee42", "best_bid": "0.043", "best_ask": "0.044"}], "timestamp": "1769384193433", "event_type": "price_change"}}
{"_local_timestamp": "2026-01-25T23:36:33.590825+00:00", "data": {"market": "0xfebf77a5fafe69270ae88267592d6af563d5fb8038167c1e5f0f84389a180b24", "price_changes": [{"asset_id": "108070880530079055956658493954731541905445967268057229566528793256732992302888", "price": "0.938", "size": "61.04", "side": "BUY", "hash": "96e36c60636cab33262aa61adb7f77094128308f", "best_bid": "0.956", "best_ask": "0.957"}, {"asset_id": "22601624556062096769343443867020199590792651484414597499875211914147125190628", "price": "0.062", "size": "61.04", "side": "SELL", "hash": "200700e237a9cf7d87f787ae250a1d5228bc2c87", "best_bid": "0.043", "best_ask": "0.044"}], "timestamp": "1769384193516", "event_type": "price_change"}}
{"_local_timestamp": "2026-01-25T23:36:33.953072+00:00", "data": {"market": "0xfebf77a5fafe69270ae88267592d6af563d5fb8038167c1e5f0f84389a180b24", "price_changes": [{"asset_id": "108070880530079055956658493954731541905445967268057229566528793256732992302888", "price": "0.938", "size": "0", "side": "BUY", "hash": "1a5eca6ce2044e66d84946f0d682a44f53d9d661", "best_bid": "0.956", "best_ask": "0.957"}, {"asset_id": "22601624556062096769343443867020199590792651484414597499875211914147125190628", "price": "0.062", "size": "0", "side": "SELL", "hash": "43799c4576830921768e4386d6e82a86eb2d560a", "best_bid": "0.043", "best_ask": "0.044"}], "timestamp": "1769384193862", "event_type": "price_change"}}
{"_local_timestamp": "2026-01-25T23:36:34.193481+00:00", "data": {"market": "0xfebf77a5fafe69270ae88267592d6af563d5fb8038167c1e5f0f84389a180b24", "price_changes": [{"asset_id": "108070880530079055956658493954731541905445967268057229566528793256732992302888", "price": "0.938", "size": "61.04", "side": "BUY", "hash": "24a51010ab8b4afba7d137f06d5a5497163b687d", "best_bid": "0.956", "best_ask": "0.957"}, {"asset_id": "22601624556062096769343443867020199590792651484414597499875211914147125190628", "price": "0.062", "size": "61.04", "side": "SELL", "hash": "347a5c592ac6584d5812f1f6aacab57a8f5a505a", "best_bid": "0.043", "best_ask": "0.044"}], "timestamp": "1769384194122", "event_type": "price_change"}}
{"_local_timestamp": "2026-01-25T23:36:34.627002+00:00", "data": {"market": "0xfebf77a5fafe69270ae88267592d6af563d5fb8038167c1e5f0f84389a180b24", "price_changes": [{"asset_id": "108070880530079055956658493954731541905445967268057229566528793256732992302888", "price": "0.938", "size": "0", "side": "BUY", "hash": "f1cccfa749b0246b50fc6dbeec92e591bba1bc55", "best_bid": "0.956", "best_ask": "0.957"}, {"asset_id": "22601624556062096769343443867020199590792651484414597499875211914147125190628", "price": "0.062", "size": "0", "side": "SELL", "hash": "58ea5b040fd0d27761538109333fde568b356bec", "best_bid": "0.043", "best_ask": "0.044"}], "timestamp": "1769384194548", "event_type": "price_change"}}
{"_local_timestamp": "2026-01-25T23:36:34.688051+00:00", "data": {"market": "0xfebf77a5fafe69270ae88267592d6af563d5fb8038167c1e5f0f84389a180b24", "price_changes": [{"asset_id": "108070880530079055956658493954731541905445967268057229566528793256732992302888", "price": "0.938", "size": "61.04", "side": "BUY", "hash": "dcc31cb4590cafd758f86fe6fdd70ccb38af7090", "best_bid": "0.956", "best_ask": "0.957"}, {"asset_id": "22601624556062096769343443867020199590792651484414597499875211914147125190628", "price": "0.062", "size": "61.04", "side": "SELL", "hash": "20a622d97e1de436b6922bd3dd046e087400ae51", "best_bid": "0.043", "best_ask": "0.044"}], "timestamp": "1769384194621", "event_type": "price_change"}}
{"_local_timestamp": "2026-01-25T23:36:34.911656+00:00", "data": {"market": "0xfebf77a5fafe69270ae88267592d6af563d5fb8038167c1e5f0f84389a180b24", "price_changes": [{"asset_id": "108070880530079055956658493954731541905445967268057229566528793256732992302888", "price": "0.938", "size": "0", "side": "BUY", "hash": "d10df240fb06d52f8785f2dd553e078daecf7541", "best_bid": "0.956", "best_ask": "0.957"}, {"asset_id": "22601624556062096769343443867020199590792651484414597499875211914147125190628", "price": "0.062", "size": "0", "side": "SELL", "hash": "c3c3cf9ca000b28906d14aa15d0ac66361463851", "best_bid": "0.043", "best_ask": "0.044"}], "timestamp": "1769384194829", "event_type": "price_change"}}
{"_local_timestamp": "2026-01-25T23:36:36.618668+00:00", "data": {"market": "0x6fbec2c3327fe7b5392b94fe48ccb41c7404a4a793957804b4b8fe8239376d12", "price_changes": [{"asset_id": "74232891440125659542320690757580411929973234713273124974412544144242477879854", "price": "0.948", "size": "0", "side": "BUY", "hash": "5ea4d9f2837d354530c04c7c2c15b8d428129461", "best_bid": "0.957", "best_ask": "0.979"}, {"asset_id": "69250819494674008903342626376731306359291370006377470819342000624771511803405", "price": "0.052", "size": "0", "side": "SELL", "hash": "8d751213204749cbe00edbbcc31e4ecb5110b451", "best_bid": "0.021", "best_ask": "0.043"}], "timestamp": "1769384196543", "event_type": "price_change"}}
{"_local_timestamp": "2026-01-25T23:36:36.619380+00:00", "data": {"market": "0x6fbec2c3327fe7b5392b94fe48ccb41c7404a4a793957804b4b8fe8239376d12", "price_changes": [{"asset_id": "69250819494674008903342626376731306359291370006377470819342000624771511803405", "price": "0.004", "size": "12.43", "side": "BUY", "hash": "ebb2edd626b9b0a67b7ddd4e57fa9fad1edafd38", "best_bid": "0.021", "best_ask": "0.043"}, {"asset_id": "74232891440125659542320690757580411929973234713273124974412544144242477879854", "price": "0.996", "size": "12.43", "side": "SELL", "hash": "bd90914703dce2e30f24db991840191b544ba991", "best_bid": "0.957", "best_ask": "0.979"}], "timestamp": "1769384196543", "event_type": "price_change"}}
{"_local_timestamp": "2026-01-25T23:36:36.773474+00:00", "data": {"market": "0x6fbec2c3327fe7b5392b94fe48ccb41c7404a4a793957804b4b8fe8239376d12", "price_changes": [{"asset_id": "74232891440125659542320690757580411929973234713273124974412544144242477879854", "price": "0.913", "size": "400", "side": "BUY", "hash": "a5bb9ec53a9d5193f1c2c4eb4c011b28a500f5cb", "best_bid": "0.957", "best_ask": "0.979"}, {"asset_id": "69250819494674008903342626376731306359291370006377470819342000624771511803405", "price": "0.087", "size": "400", "side": "SELL", "hash": "78d9e4face03ad4278b6de57390e7fa2fc0b96aa", "best_bid": "0.021", "best_ask": "0.043"}], "timestamp": "1769384196680", "event_type": "price_change"}}
{"_local_timestamp": "2026-01-25T23:36:36.792307+00:00", "data": {"market": "0x6fbec2c3327fe7b5392b94fe48ccb41c7404a4a793957804b4b8fe8239376d12", "price_changes": [{"asset_id": "69250819494674008903342626376731306359291370006377470819342000624771511803405", "price": "0.021", "size": "0", "side": "BUY", "hash": "63954609a5e578ffbb929fdd63741a39f2ea853c", "best_bid": "0.02", "best_ask": "0.043"}, {"asset_id": "74232891440125659542320690757580411929973234713273124974412544144242477879854", "price": "0.979", "size": "0", "side": "SELL", "hash": "e5d96d16a238e411580e07b0a9869c9ad39bb184", "best_bid": "0.957", "best_ask": "0.98"}], "timestamp": "1769384196703", "event_type": "price_change"}}
{"_local_timestamp": "2026-01-25T23:36:36.813315+00:00", "data": {"market": "0x6fbec2c3327fe7b5392b94fe48ccb41c7404a4a793957804b4b8fe8239376d12", "price_changes": [{"asset_id": "69250819494674008903342626376731306359291370006377470819342000624771511803405", "price": "0.021", "size": "57", "side": "BUY", "hash": "47651f5fa2ad440854be4bda1fadd094a1fa4a02", "best_bid": "0.021", "best_ask": "0.043"}, {"asset_id": "74232891440125659542320690757580411929973234713273124974412544144242477879854", "price": "0.979", "size": "57", "side": "SELL", "hash": "6992f7f75283d604432d7ebacd00a62da0e2a756", "best_bid": "0.957", "best_ask": "0.979"}], "timestamp": "1769384196728", "event_type": "price_change"}}
{"_local_timestamp": "2026-01-25T23:36:36.892089+00:00", "data": {"market": "0x37d7295a17db461c15867862afe90bfad6cd46436b0d121a7c96c37e166103b4", "price_changes": [{"asset_id": "48325180813773997762337012603425087662105904105229463158116317479132765545801", "price": "0.972", "size": "50", "side": "BUY", "hash": "63b4c34b76365d1876dea6ded3be9423f3c087f6", "best_bid": "0.989", "best_ask": "0.998"}, {"asset_id": "65341950601583802479848929397121491003949963027873255906537010617800365051709", "price": "0.028", "size": "50", "side": "SELL", "hash": "3a8836a911ad55981ea8085772cd3f8e8042e5ee", "best_bid": "0.002", "best_ask": "0.011"}], "timestamp": "1769384196809", "event_type": "price_change"}}
{"_local_timestamp": "2026-01-25T23:36:36.893272+00:00", "data": {"market": "0x37d7295a17db461c15867862afe90bfad6cd46436b0d121a7c96c37e166103b4", "price_changes": [{"asset_id": "48325180813773997762337012603425087662105904105229463158116317479132765545801", "price": "0.973", "size": "100", "side": "BUY", "hash": "9daa075ca2683ae30ac201621975f44a505309f0", "best_bid": "0.989", "best_ask": "0.998"}, {"asset_id": "65341950601583802479848929397121491003949963027873255906537010617800365051709", "price": "0.027", "size": "100", "side": "SELL", "hash": "e64b87fa8625c618a881339030d1a27277a62992", "best_bid": "0.002", "best_ask": "0.011"}], "timestamp": "1769384196812", "event_type": "price_change"}}
{"_local_timestamp": "2026-01-25T23:36:36.894770+00:00", "data": {"market": "0x37d7295a17db461c15867862afe90bfad6cd46436b0d121a7c96c37e166103b4", "price_changes": [{"asset_id": "48325180813773997762337012603425087662105904105229463158116317479132765545801", "price": "0.973", "size": "50", "side": "BUY", "hash": "41fc7833862dcf9527d8bd8cccd47027f48b5aeb", "best_bid": "0.989", "best_ask": "0.998"}, {"asset_id": "65341950601583802479848929397121491003949963027873255906537010617800365051709", "price": "0.027", "size": "50", "side": "SELL", "hash": "ba20683d07a197e3e24c92955f26fa7ed87dc433", "best_bid": "0.002", "best_ask": "0.011"}], "timestamp": "1769384196814", "event_type": "price_change"}}
{"_local_timestamp": "2026-01-25T23:36:36.895781+00:00", "data": {"market": "0x37d7295a17db461c15867862afe90bfad6cd46436b0d121a7c96c37e166103b4", "price_changes": [{"asset_id": "48325180813773997762337012603425087662105904105229463158116317479132765545801", "price": "0.975", "size": "25", "side": "BUY", "hash": "b32ef121906504fa1f2e784fd2a501385ff08b7f", "best_bid": "0.989", "best_ask": "0.998"}, {"asset_id": "65341950601583802479848929397121491003949963027873255906537010617800365051709", "price": "0.025", "size": "25", "side": "SELL", "hash": "5c05daf6056fcb577a108490758812f1c9e47f16", "best_bid": "0.002", "best_ask": "0.011"}], "timestamp": "1769384196820", "event_type": "price_change"}}
{"_local_timestamp": "2026-01-25T23:36:36.918658+00:00", "data": {"market": "0x37d7295a17db461c15867862afe90bfad6cd46436b0d121a7c96c37e166103b4", "price_changes": [{"asset_id": "48325180813773997762337012603425087662105904105229463158116317479132765545801", "price": "0.975", "size": "50", "side": "BUY", "hash": "38f20b3acb2454deb6801ca3cbb1c026a7bcf007", "best_bid": "0.989", "best_ask": "0.998"}, {"asset_id": "65341950601583802479848929397121491003949963027873255906537010617800365051709", "price": "0.025", "size": "50", "side": "SELL", "hash": "309c7a7d7451ed5ecc9e1c78ad160c355b8b435a", "best_bid": "0.002", "best_ask": "0.011"}], "timestamp": "1769384196828", "event_type": "price_change"}}
{"_local_timestamp": "2026-01-25T23:36:36.919396+00:00", "data": {"market": "0x37d7295a17db461c15867862afe90bfad6cd46436b0d121a7c96c37e166103b4", "price_changes": [{"asset_id": "48325180813773997762337012603425087662105904105229463158116317479132765545801", "price": "0.973", "size": "0", "side": "BUY", "hash": "e402c145e31a8bbf01b8471fd4fdad91d7e3e5e5", "best_bid": "0.989", "best_ask": "0.998"}, {"asset_id": "65341950601583802479848929397121491003949963027873255906537010617800365051709", "price": "0.027", "size": "0", "side": "SELL", "hash": "083106037f5fd22740b9adce1dd37cd93a3ca1c0", "best_bid": "0.002", "best_ask": "0.011"}], "timestamp": "1769384196829", "event_type": "price_change"}}
{"_local_timestamp": "2026-01-25T23:36:36.920005+00:00", "data": {"market": "0x37d7295a17db461c15867862afe90bfad6cd46436b0d121a7c96c37e166103b4", "price_changes": [{"asset_id": "48325180813773997762337012603425087662105904105229463158116317479132765545801", "price": "0.936", "size": "0", "side": "BUY", "hash": "dc0470f627ae257c78da4791fa5c741cd3ea2076", "best_bid": "0.989", "best_ask": "0.998"}, {"asset_id": "65341950601583802479848929397121491003949963027873255906537010617800365051709", "price": "0.064", "size": "0", "side": "SELL", "hash": "05607e506ae4a4cf454a4e75a28ff9da17abce7f", "best_bid": "0.002", "best_ask": "0.011"}], "timestamp": "1769384196829", "event_type": "price_change"}}
{"_local_timestamp": "2026-01-25T23:36:37.025193+00:00", "data": {"market": "0x37d7295a17db461c15867862afe90bfad6cd46436b0d121a7c96c37e166103b4", "price_changes": [{"asset_id": "48325180813773997762337012603425087662105904105229463158116317479132765545801", "price": "0.975", "size": "25", "side": "BUY", "hash": "dcdf341dec5330de073b89ccf91cc613abc12919", "best_bid": "0.989", "best_ask": "0.998"}, {"asset_id": "65341950601583802479848929397121491003949963027873255906537010617800365051709", "price": "0.025", "size": "25", "side": "SELL", "hash": "53f91213c0572ec98ddaf9ec9f59184c7a9baeaa", "best_bid": "0.002", "best_ask": "0.011"}], "timestamp": "1769384196938", "event_type": "price_change"}}
{"_local_timestamp": "2026-01-25T23:36:37.025920+00:00", "data": {"market": "0x37d7295a17db461c15867862afe90bfad6cd46436b0d121a7c96c37e166103b4", "price_changes": [{"asset_id": "48325180813773997762337012603425087662105904105229463158116317479132765545801", "price": "0.879", "size": "30", "side": "BUY", "hash": "c00a59755ebe18a8903ea2718d71c66f16716acf", "best_bid": "0.989", "best_ask": "0.998"}, {"asset_id": "65341950601583802479848929397121491003949963027873255906537010617800365051709", "price": "0.121", "size": "30", "side": "SELL", "hash": "9b66a14853d373c65b2a033d89adbe5932932c19", "best_bid": "0.002", "best_ask": "0.011"}], "timestamp": "1769384196947", "event_type": "price_change"}}
{"_local_timestamp": "2026-01-25T23:36:37.026737+00:00", "data": {"market": "0x37d7295a17db461c15867862afe90bfad6cd46436b0d121a7c96c37e166103b4", "price_changes": [{"asset_id": "48325180813773997762337012603425087662105904105229463158116317479132765545801", "price": "0.514", "size": "500", "side": "BUY", "hash": "a342275de0151dd5dbf983d2f6439ca6b0686ddd", "best_bid": "0.989", "best_ask": "0.998"}, {"asset_id": "65341950601583802479848929397121491003949963027873255906537010617800365051709", "price": "0.486", "size": "500", "side": "SELL", "hash": "aaa4a920d607d1cc3482a56e4d129560efcc4560", "best_bid": "0.002", "best_ask": "0.011"}], "timestamp": "1769384196947", "event_type": "price_change"}}
{"_local_timestamp": "2026-01-25T23:36:37.158181+00:00", "data": {"market": "0xfebf77a5fafe69270ae88267592d6af563d5fb8038167c1e5f0f84389a180b24", "price_changes": [{"asset_id": "108070880530079055956658493954731541905445967268057229566528793256732992302888", "price": "0.938", "size": "61.04", "side": "BUY", "hash": "8b61b8509fa36d533742f07afeb16744ae0dac77", "best_bid": "0.956", "best_ask": "0.957"}, {"asset_id": "22601624556062096769343443867020199590792651484414597499875211914147125190628", "price": "0.062", "size": "61.04", "side": "SELL", "hash": "c3e4515fd0c7d3fbdf74b566ee7b221263813d76", "best_bid": "0.043", "best_ask": "0.044"}], "timestamp": "1769384197042", "event_type": "price_change"}}
{"_local_timestamp": "2026-01-25T23:36:37.158946+00:00", "data": {"market": "0x37d7295a17db461c15867862afe90bfad6cd46436b0d121a7c96c37e166103b4", "price_changes": [{"asset_id": "48325180813773997762337012603425087662105904105229463158116317479132765545801", "price": "0.972", "size": "0", "side": "BUY", "hash": "20fa5b51d4f00d09d29dab8c380c969f5360e84f", "best_bid": "0.989", "best_ask": "0.998"}, {"asset_id": "65341950601583802479848929397121491003949963027873255906537010617800365051709", "price": "0.028", "size": "0", "side": "SELL", "hash": "819bf31dc8775cb6c76cc2ec7d2f4da3ac367521", "best_bid": "0.002", "best_ask": "0.011"}], "timestamp": "1769384197042", "event_type": "price_change"}}
{"_local_timestamp": "2026-01-25T23:36:37.162430+00:00", "data": {"market": "0x37d7295a17db461c15867862afe90bfad6cd46436b0d121a7c96c37e166103b4", "price_changes": [{"asset_id": "48325180813773997762337012603425087662105904105229463158116317479132765545801", "price": "0.975", "size": "0", "side": "BUY", "hash": "de3501ef37161035f1c4204beccdd4601495933d", "best_bid": "0.989", "best_ask": "0.998"}, {"asset_id": "65341950601583802479848929397121491003949963027873255906537010617800365051709", "price": "0.025", "size": "0", "side": "SELL", "hash": "ea539420e11a679ad50ccc1474da82bb8ca94f4e", "best_bid": "0.002", "best_ask": "0.011"}], "timestamp": "1769384197069", "event_type": "price_change"}}
{"_local_timestamp": "2026-01-25T23:36:37.703638+00:00", "data": {"market": "0xfebf77a5fafe69270ae88267592d6af563d5fb8038167c1e5f0f84389a180b24", "price_changes": [{"asset_id": "108070880530079055956658493954731541905445967268057229566528793256732992302888", "price": "0.938", "size": "0", "side": "BUY", "hash": "480400dd820ddc3cb98ab4ceeb09014956bd4c80", "best_bid": "0.956", "best_ask": "0.957"}, {"asset_id": "22601624556062096769343443867020199590792651484414597499875211914147125190628", "price": "0.062", "size": "0", "side": "SELL", "hash": "2ede0f30aebe6c3db331386937167513de78bdaa", "best_bid": "0.043", "best_ask": "0.044"}], "timestamp": "1769384197627", "event_type": "price_change"}}
{"_local_timestamp": "2026-01-25T23:36:37.851668+00:00", "data": {"market": "0x37d7295a17db461c15867862afe90bfad6cd46436b0d121a7c96c37e166103b4", "price_changes": [{"asset_id": "48325180813773997762337012603425087662105904105229463158116317479132765545801", "price": "0.926", "size": "400", "side": "BUY", "hash": "09511d64f7850172c01ef95cf2ab506769ad44df", "best_bid": "0.989", "best_ask": "0.998"}, {"asset_id": "65341950601583802479848929397121491003949963027873255906537010617800365051709", "price": "0.074", "size": "400", "side": "SELL", "hash": "22c83db6b007b45e5595e9253604fcaaa14a62b9", "best_bid": "0.002", "best_ask": "0.011"}], "timestamp": "1769384197779", "event_type": "price_change"}}
{"_local_timestamp": "2026-01-25T23:36:37.962583+00:00", "data": {"market": "0x37d7295a17db461c15867862afe90bfad6cd46436b0d121a7c96c37e166103b4", "price_changes": [{"asset_id": "48325180813773997762337012603425087662105904105229463158116317479132765545801", "price": "0.972", "size": "50", "side": "BUY", "hash": "c3614eb43a97d5a6f80a29e5034864b0d8a2b5b2", "best_bid": "0.989", "best_ask": "0.998"}, {"asset_id": "65341950601583802479848929397121491003949963027873255906537010617800365051709", "price": "0.028", "size": "50", "side": "SELL", "hash": "9267e061e35af951267a21c45d7768e93a1f74e7", "best_bid": "0.002", "best_ask": "0.011"}], "timestamp": "1769384197895", "event_type": "price_change"}}
{"_local_timestamp": "2026-01-25T23:36:38.036674+00:00", "data": {"market": "0x37d7295a17db461c15867862afe90bfad6cd46436b0d121a7c96c37e166103b4", "price_changes": [{"asset_id": "48325180813773997762337012603425087662105904105229463158116317479132765545801", "price": "0.972", "size": "100", "side": "BUY", "hash": "b84f0cab65608504c4fdbe68092897a2c912e4b5", "best_bid": "0.989", "best_ask": "0.998"}, {"asset_id": "65341950601583802479848929397121491003949963027873255906537010617800365051709", "price": "0.028", "size": "100", "side": "SELL", "hash": "9434bc129f0d38985337adb04bd1503f6169ab9d", "best_bid": "0.002", "best_ask": "0.011"}], "timestamp": "1769384197969", "event_type": "price_change"}}
{"_local_timestamp": "2026-01-25T23:36:38.278665+00:00", "data": {"market": "0xfebf77a5fafe69270ae88267592d6af563d5fb8038167c1e5f0f84389a180b24", "price_changes": [{"asset_id": "108070880530079055956658493954731541905445967268057229566528793256732992302888", "price": "0.938", "size": "100", "side": "BUY", "hash": "9176666e6d23a50ce105858092001c3743e00872", "best_bid": "0.956", "best_ask": "0.957"}, {"asset_id": "22601624556062096769343443867020199590792651484414597499875211914147125190628", "price": "0.062", "size": "100", "side": "SELL", "hash": "e40f46f2cafa5fa5ae151dd0aa7e66a7d87c1cc3", "best_bid": "0.043", "best_ask": "0.044"}], "timestamp": "1769384198206", "event_type": "price_change"}}
{"_local_timestamp": "2026-01-25T23:36:38.288816+00:00", "data": {"market": "0x37d7295a17db461c15867862afe90bfad6cd46436b0d121a7c96c37e166103b4", "price_changes": [{"asset_id": "48325180813773997762337012603425087662105904105229463158116317479132765545801", "price": "0.921", "size": "0", "side": "BUY", "hash": "2f4416f010cc651d41fd5a719b83e5a97bd5b756", "best_bid": "0.989", "best_ask": "0.998"}, {"asset_id": "65341950601583802479848929397121491003949963027873255906537010617800365051709", "price": "0.079", "size": "0", "side": "SELL", "hash": "1b1b3f9a23bea7c685c591d3bfa1d0f768e11741", "best_bid": "0.002", "best_ask": "0.011"}], "timestamp": "1769384198218", "event_type": "price_change"}}
{"_local_timestamp": "2026-01-25T23:36:38.326243+00:00", "data": {"market": "0x37d7295a17db461c15867862afe90bfad6cd46436b0d121a7c96c37e166103b4", "price_changes": [{"asset_id": "48325180813773997762337012603425087662105904105229463158116317479132765545801", "price": "0.927", "size": "20", "side": "BUY", "hash": "b662f8904aebaf29b54f458361724a103e8a1846", "best_bid": "0.989", "best_ask": "0.998"}, {"asset_id": "65341950601583802479848929397121491003949963027873255906537010617800365051709", "price": "0.073", "size": "20", "side": "SELL", "hash": "7be00a978365d787040b0bb04ba9ac65e052d6b8", "best_bid": "0.002", "best_ask": "0.011"}], "timestamp": "1769384198256", "event_type": "price_change"}}
{"_local_timestamp": "2026-01-25T23:36:38.419967+00:00", "data": {"market": "0x37d7295a17db461c15867862afe90bfad6cd46436b0d121a7c96c37e166103b4", "price_changes": [{"asset_id": "48325180813773997762337012603425087662105904105229463158116317479132765545801", "price": "0.972", "size": "150", "side": "BUY", "hash": "8c8f3ee930a054529fcad507bff4c8ff9daf307c", "best_bid": "0.989", "best_ask": "0.998"}, {"asset_id": "65341950601583802479848929397121491003949963027873255906537010617800365051709", "price": "0.028", "size": "150", "side": "SELL", "hash": "04920a1485f921aff7ec1db7ee96f2f8b2a19161", "best_bid": "0.002", "best_ask": "0.011"}], "timestamp": "1769384198349", "event_type": "price_change"}}
{"_local_timestamp": "2026-01-25T23:36:38.442450+00:00", "data": {"market": "0x37d7295a17db461c15867862afe90bfad6cd46436b0d121a7c96c37e166103b4", "price_changes": [{"asset_id": "48325180813773997762337012603425087662105904105229463158116317479132765545801", "price": "0.926", "size": "0", "side": "BUY", "hash": "0ffdc32a930c2d64d530bd7128396a8977712416", "best_bid": "0.989", "best_ask": "0.998"}, {"asset_id": "65341950601583802479848929397121491003949963027873255906537010617800365051709", "price": "0.074", "size": "0", "side": "SELL", "hash": "907d4d6ce8e1f697548770b4cfb8693af937c72a", "best_bid": "0.002", "best_ask": "0.011"}], "timestamp": "1769384198372", "event_type": "price_change"}}
{"_local_timestamp": "2026-01-25T23:36:39.967647+00:00", "data": {"market": "0x37d7295a17db461c15867862afe90bfad6cd46436b0d121a7c96c37e166103b4", "price_changes": [{"asset_id": "48325180813773997762337012603425087662105904105229463158116317479132765545801", "price": "0.927", "size": "0", "side": "BUY", "hash": "29d18801ccecdc48c51a6b59f4e37d7350b28058", "best_bid": "0.989", "best_ask": "0.998"}, {"asset_id": "65341950601583802479848929397121491003949963027873255906537010617800365051709", "price": "0.073", "size": "0", "side": "SELL", "hash": "8eafb6943c781925fc14d229ba279b79e2a244e4", "best_bid": "0.002", "best_ask": "0.011"}], "timestamp": "1769384199892", "event_type": "price_change"}}
{"_local_timestamp": "2026-01-25T23:36:39.988724+00:00", "data": {"market": "0x37d7295a17db461c15867862afe90bfad6cd46436b0d121a7c96c37e166103b4", "price_changes": [{"asset_id": "48325180813773997762337012603425087662105904105229463158116317479132765545801", "price": "0.921", "size": "20", "side": "BUY", "hash": "9ee627f0dfa8750a55ad40fd3c3172f0807d904b", "best_bid": "0.989", "best_ask": "0.998"}, {"asset_id": "65341950601583802479848929397121491003949963027873255906537010617800365051709", "price": "0.079", "size": "20", "side": "SELL", "hash": "299fb082f1385e70a2cb9f89c50983e62eaa8f7f", "best_bid": "0.002", "best_ask": "0.011"}], "timestamp": "1769384199921", "event_type": "price_change"}}
{"_local_timestamp": "2026-01-25T23:36:40.141113+00:00", "data": {"market": "0x37d7295a17db461c15867862afe90bfad6cd46436b0d121a7c96c37e166103b4", "price_changes": [{"asset_id": "48325180813773997762337012603425087662105904105229463158116317479132765545801", "price": "0.926", "size": "400", "side": "BUY", "hash": "a7bd5401bb7f9d3123e213e0e48a89cb7e32a170", "best_bid": "0.989", "best_ask": "0.998"}, {"asset_id": "65341950601583802479848929397121491003949963027873255906537010617800365051709", "price": "0.074", "size": "400", "side": "SELL", "hash": "01e7bc244d1b0cb9a6e3c1dd7730dbd2b9ceb429", "best_bid": "0.002", "best_ask": "0.011"}], "timestamp": "1769384200066", "event_type": "price_change"}}
{"_local_timestamp": "2026-01-25T23:36:41.511572+00:00", "data": {"market": "0x37d7295a17db461c15867862afe90bfad6cd46436b0d121a7c96c37e166103b4", "price_changes": [{"asset_id": "48325180813773997762337012603425087662105904105229463158116317479132765545801", "price": "0.921", "size": "0", "side": "BUY", "hash": "4f18d7d65e3f4c344034bbca27b85f70e71e0285", "best_bid": "0.989", "best_ask": "0.998"}, {"asset_id": "65341950601583802479848929397121491003949963027873255906537010617800365051709", "price": "0.079", "size": "0", "side": "SELL", "hash": "16e4f58859b6288d68dc1194d2882266b510375d", "best_bid": "0.002", "best_ask": "0.011"}], "timestamp": "1769384201438", "event_type": "price_change"}}
{"_local_timestamp": "2026-01-25T23:36:41.542320+00:00", "data": {"market": "0x37d7295a17db461c15867862afe90bfad6cd46436b0d121a7c96c37e166103b4", "price_changes": [{"asset_id": "48325180813773997762337012603425087662105904105229463158116317479132765545801", "price": "0.927", "size": "20", "side": "BUY", "hash": "ef2369532be3e50a6e9733178cdfbd3be01a2e48", "best_bid": "0.989", "best_ask": "0.998"}, {"asset_id": "65341950601583802479848929397121491003949963027873255906537010617800365051709", "price": "0.073", "size": "20", "side": "SELL", "hash": "b7d4ec94ce467b6ffd5a1347593510afa420bb3b", "best_bid": "0.002", "best_ask": "0.011"}], "timestamp": "1769384201470", "event_type": "price_change"}}
{"_local_timestamp": "2026-01-25T23:36:41.617996+00:00", "data": {"market": "0x37d7295a17db461c15867862afe90bfad6cd46436b0d121a7c96c37e166103b4", "price_changes": [{"asset_id": "48325180813773997762337012603425087662105904105229463158116317479132765545801", "price": "0.926", "size": "0", "side": "BUY", "hash": "9e5e71ce2ab3c7ba4a0fc49f3479772228e4ea05", "best_bid": "0.989", "best_ask": "0.998"}, {"asset_id": "65341950601583802479848929397121491003949963027873255906537010617800365051709", "price": "0.074", "size": "0", "side": "SELL", "hash": "ae46b148cd35515e221bee75f7177f0fac8aa65b", "best_bid": "0.002", "best_ask": "0.011"}], "timestamp": "1769384201542", "event_type": "price_change"}}
{"_local_timestamp": "2026-01-25T23:36:41.650299+00:00", "data": {"market": "0x37d7295a17db461c15867862afe90bfad6cd46436b0d121a7c96c37e166103b4", "price_changes": [{"asset_id": "48325180813773997762337012603425087662105904105229463158116317479132765545801", "price": "0.93", "size": "150", "side": "BUY", "hash": "5a4da31283be696b1dacce4ebdd136326a2fd0f6", "best_bid": "0.989", "best_ask": "0.998"}, {"asset_id": "65341950601583802479848929397121491003949963027873255906537010617800365051709", "price": "0.07", "size": "150", "side": "SELL", "hash": "b2d042d6236ed756a1949f2787498b110b24845e", "best_bid": "0.002", "best_ask": "0.011"}], "timestamp": "1769384201578", "event_type": "price_change"}}
{"_local_timestamp": "2026-01-25T23:36:41.946269+00:00", "data": {"market": "0xfebf77a5fafe69270ae88267592d6af563d5fb8038167c1e5f0f84389a180b24", "price_changes": [{"asset_id": "108070880530079055956658493954731541905445967268057229566528793256732992302888", "price": "0.938", "size": "0", "side": "BUY", "hash": "50ac6b6c466e4776e95f196371ebc314ec25aa53", "best_bid": "0.956", "best_ask": "0.957"}, {"asset_id": "22601624556062096769343443867020199590792651484414597499875211914147125190628", "price": "0.062", "size": "0", "side": "SELL", "hash": "cdd7ae9aab286e7ff7bb37c29483adf4f8087386", "best_bid": "0.043", "best_ask": "0.044"}], "timestamp": "1769384201868", "event_type": "price_change"}}
{"_local_timestamp": "2026-01-25T23:36:42.036250+00:00", "data": {"market": "0xfebf77a5fafe69270ae88267592d6af563d5fb8038167c1e5f0f84389a180b24", "price_changes": [{"asset_id": "108070880530079055956658493954731541905445967268057229566528793256732992302888", "price": "0.937", "size": "100", "side": "BUY", "hash": "89568386b2a733823f240f6fd0b93e7516953e47", "best_bid": "0.956", "best_ask": "0.957"}, {"asset_id": "22601624556062096769343443867020199590792651484414597499875211914147125190628", "price": "0.063", "size": "100", "side": "SELL", "hash": "86fd5ba01c29d8c8eadcd5154eaae810e0986f12", "best_bid": "0.043", "best_ask": "0.044"}], "timestamp": "1769384201952", "event_type": "price_change"}}
{"_local_timestamp": "2026-01-25T23:36:42.256695+00:00", "data": {"market": "0xfebf77a5fafe69270ae88267592d6af563d5fb8038167c1e5f0f84389a180b24", "price_changes": [{"asset_id": "108070880530079055956658493954731541905445967268057229566528793256732992302888", "price": "0.937", "size": "0", "side": "BUY", "hash": "e20f8bff1fefd7c456157cdf1cbee3af691c5a21", "best_bid": "0.956", "best_ask": "0.957"}, {"asset_id": "22601624556062096769343443867020199590792651484414597499875211914147125190628", "price": "0.063", "size": "0", "side": "SELL", "hash": "011fa1f04f906adca2958c60021ac3b694f51345", "best_bid": "0.043", "best_ask": "0.044"}], "timestamp": "1769384202177", "event_type": "price_change"}}
{"_local_timestamp": "2026-01-25T23:36:42.976795+00:00", "data": {"market": "0x37d7295a17db461c15867862afe90bfad6cd46436b0d121a7c96c37e166103b4", "price_changes": [{"asset_id": "48325180813773997762337012603425087662105904105229463158116317479132765545801", "price": "0.927", "size": "0", "side": "BUY", "hash": "12260018d3967a38182d3e0eb5bb9cde7e44890e", "best_bid": "0.989", "best_ask": "0.998"}, {"asset_id": "65341950601583802479848929397121491003949963027873255906537010617800365051709", "price": "0.073", "size": "0", "side": "SELL", "hash": "5eeeafed45c83ce3dd726f95b74d0df2acd59489", "best_bid": "0.002", "best_ask": "0.011"}], "timestamp": "1769384202906", "event_type": "price_change"}}
{"_local_timestamp": "2026-01-25T23:36:43.028656+00:00", "data": {"market": "0x37d7295a17db461c15867862afe90bfad6cd46436b0d121a7c96c37e166103b4", "price_changes": [{"asset_id": "48325180813773997762337012603425087662105904105229463158116317479132765545801", "price": "0.921", "size": "20", "side": "BUY", "hash": "67cdbe0dad6f61d927f3ad7e62512193b1930e61", "best_bid": "0.989", "best_ask": "0.998"}, {"asset_id": "65341950601583802479848929397121491003949963027873255906537010617800365051709", "price": "0.079", "size": "20", "side": "SELL", "hash": "5926d92933ba02cb4cdc7ce54ff0570f8cddedaa", "best_bid": "0.002", "best_ask": "0.011"}], "timestamp": "1769384202942", "event_type": "price_change"}}
{"_local_timestamp": "2026-01-25T23:36:43.081029+00:00", "data": {"market": "0x37d7295a17db461c15867862afe90bfad6cd46436b0d121a7c96c37e166103b4", "price_changes": [{"asset_id": "48325180813773997762337012603425087662105904105229463158116317479132765545801", "price": "0.93", "size": "0", "side": "BUY", "hash": "da770a4931870a1c20577cb0547a743d51a9c0c8", "best_bid": "0.989", "best_ask": "0.998"}, {"asset_id": "65341950601583802479848929397121491003949963027873255906537010617800365051709", "price": "0.07", "size": "0", "side": "SELL", "hash": "d2625be8d1737bb80a08473552d9e67b6629b6bc", "best_bid": "0.002", "best_ask": "0.011"}], "timestamp": "1769384203015", "event_type": "price_change"}}
{"_local_timestamp": "2026-01-25T23:36:43.128525+00:00", "data": {"market": "0x37d7295a17db461c15867862afe90bfad6cd46436b0d121a7c96c37e166103b4", "price_changes": [{"asset_id": "48325180813773997762337012603425087662105904105229463158116317479132765545801", "price": "0.926", "size": "400", "side": "BUY", "hash": "9c96e3282edf893e21dc73e4cd800871bbb43270", "best_bid": "0.989", "best_ask": "0.998"}, {"asset_id": "65341950601583802479848929397121491003949963027873255906537010617800365051709", "price": "0.074", "size": "400", "side": "SELL", "hash": "f49c71cbbe648b7f5f3039f8f80face2e34e86cb", "best_bid": "0.002", "best_ask": "0.011"}], "timestamp": "1769384203056", "event_type": "price_change"}}
{"_local_timestamp": "2026-01-25T23:36:44.981138+00:00", "data": {"market": "0x37d7295a17db461c15867862afe90bfad6cd46436b0d121a7c96c37e166103b4", "price_changes": [{"asset_id": "48325180813773997762337012603425087662105904105229463158116317479132765545801", "price": "0.921", "size": "0", "side": "BUY", "hash": "37245b79d9ae4ca95552e098e631e9d51579475b", "best_bid": "0.989", "best_ask": "0.998"}, {"asset_id": "65341950601583802479848929397121491003949963027873255906537010617800365051709", "price": "0.079", "size": "0", "side": "SELL", "hash": "93791f83fa9b3362556fc5043d13976fae0c6c07", "best_bid": "0.002", "best_ask": "0.011"}], "timestamp": "1769384204911", "event_type": "price_change"}}
{"_local_timestamp": "2026-01-25T23:36:45.010470+00:00", "data": {"market": "0x37d7295a17db461c15867862afe90bfad6cd46436b0d121a7c96c37e166103b4", "price_changes": [{"asset_id": "48325180813773997762337012603425087662105904105229463158116317479132765545801", "price": "0.927", "size": "20", "side": "BUY", "hash": "a534bf920c521f88a0afc405c7dde642aa710811", "best_bid": "0.989", "best_ask": "0.998"}, {"asset_id": "65341950601583802479848929397121491003949963027873255906537010617800365051709", "price": "0.073", "size": "20", "side": "SELL", "hash": "67e7f2a8fede4d26e86235ef6efe71f2da222841", "best_bid": "0.002", "best_ask": "0.011"}], "timestamp": "1769384204943", "event_type": "price_change"}}
{"_local_timestamp": "2026-01-25T23:36:45.097010+00:00", "data": {"market": "0x37d7295a17db461c15867862afe90bfad6cd46436b0d121a7c96c37e166103b4", "price_changes": [{"asset_id": "48325180813773997762337012603425087662105904105229463158116317479132765545801", "price": "0.926", "size": "0", "side": "BUY", "hash": "58afd96c9fbd067e8b7c4c091024206564f21178", "best_bid": "0.989", "best_ask": "0.998"}, {"asset_id": "65341950601583802479848929397121491003949963027873255906537010617800365051709", "price": "0.074", "size": "0", "side": "SELL", "hash": "57817ba8dcd8027d5cd3afc66541b76d13b24938", "best_bid": "0.002", "best_ask": "0.011"}], "timestamp": "1769384205024", "event_type": "price_change"}}
{"_local_timestamp": "2026-01-25T23:36:45.133029+00:00", "data": {"market": "0x37d7295a17db461c15867862afe90bfad6cd46436b0d121a7c96c37e166103b4", "price_changes": [{"asset_id": "48325180813773997762337012603425087662105904105229463158116317479132765545801", "price": "0.93", "size": "150", "side": "BUY", "hash": "b09771db9c3c6300ece0740986cd78ac5fddc31a", "best_bid": "0.989", "best_ask": "0.998"}, {"asset_id": "65341950601583802479848929397121491003949963027873255906537010617800365051709", "price": "0.07", "size": "150", "side": "SELL", "hash": "07915d3b9a53c666676c0f759566347ca4150354", "best_bid": "0.002", "best_ask": "0.011"}], "timestamp": "1769384205060", "event_type": "price_change"}}
{"_local_timestamp": "2026-01-25T23:36:48.108822+00:00", "data": {"market": "0x37d7295a17db461c15867862afe90bfad6cd46436b0d121a7c96c37e166103b4", "price_changes": [{"asset_id": "48325180813773997762337012603425087662105904105229463158116317479132765545801", "price": "0.927", "size": "0", "side": "BUY", "hash": "442879f48cde95b60b36a018105ee760ec0ab3c8", "best_bid": "0.989", "best_ask": "0.998"}, {"asset_id": "65341950601583802479848929397121491003949963027873255906537010617800365051709", "price": "0.073", "size": "0", "side": "SELL", "hash": "df365bb022b424ee7782f4e43fd3df8b28f2a32b", "best_bid": "0.002", "best_ask": "0.011"}], "timestamp": "1769384208017", "event_type": "price_change"}}
{"_local_timestamp": "2026-01-25T23:36:48.127511+00:00", "data": {"market": "0x37d7295a17db461c15867862afe90bfad6cd46436b0d121a7c96c37e166103b4", "price_changes": [{"asset_id": "48325180813773997762337012603425087662105904105229463158116317479132765545801", "price": "0.921", "size": "20", "side": "BUY", "hash": "b33778b037438d4e4835198f6e8d8183c3f4ddba", "best_bid": "0.989", "best_ask": "0.998"}, {"asset_id": "65341950601583802479848929397121491003949963027873255906537010617800365051709", "price": "0.079", "size": "20", "side": "SELL", "hash": "c70201f00489af7b238c352a8d6540b1fa32efc6", "best_bid": "0.002", "best_ask": "0.011"}], "timestamp": "1769384208049", "event_type": "price_change"}}
{"_local_timestamp": "2026-01-25T23:36:48.250581+00:00", "data": {"market": "0x37d7295a17db461c15867862afe90bfad6cd46436b0d121a7c96c37e166103b4", "price_changes": [{"asset_id": "48325180813773997762337012603425087662105904105229463158116317479132765545801", "price": "0.926", "size": "400", "side": "BUY", "hash": "f5e42912571b669dc8c8232e21cbef0c33ce181c", "best_bid": "0.989", "best_ask": "0.998"}, {"asset_id": "65341950601583802479848929397121491003949963027873255906537010617800365051709", "price": "0.074", "size": "400", "side": "SELL", "hash": "fe88c1d7d64d9cf83d1a8494caab3926e820b4c3", "best_bid": "0.002", "best_ask": "0.011"}], "timestamp": "1769384208158", "event_type": "price_change"}}
{"_local_timestamp": "2026-01-25T23:36:48.251341+00:00", "data": {"market": "0x37d7295a17db461c15867862afe90bfad6cd46436b0d121a7c96c37e166103b4", "price_changes": [{"asset_id": "48325180813773997762337012603425087662105904105229463158116317479132765545801", "price": "0.93", "size": "0", "side": "BUY", "hash": "b1e28299ecaf0aea7aeb66108d91c4a840451dfc", "best_bid": "0.989", "best_ask": "0.998"}, {"asset_id": "65341950601583802479848929397121491003949963027873255906537010617800365051709", "price": "0.07", "size": "0", "side": "SELL", "hash": "d6cb17cba01c45c5cde431d7e6c3435c177d7206", "best_bid": "0.002", "best_ask": "0.011"}], "timestamp": "1769384208170", "event_type": "price_change"}}
{"_local_timestamp": "2026-01-25T23:36:51.893700+00:00", "data": {"market": "0x37d7295a17db461c15867862afe90bfad6cd46436b0d121a7c96c37e166103b4", "price_changes": [{"asset_id": "48325180813773997762337012603425087662105904105229463158116317479132765545801", "price": "0.921", "size": "0", "side": "BUY", "hash": "bb29e5e01d8daa6572f4862b0fa5fa4af1012859", "best_bid": "0.989", "best_ask": "0.998"}, {"asset_id": "65341950601583802479848929397121491003949963027873255906537010617800365051709", "price": "0.079", "size": "0", "side": "SELL", "hash": "08205265db8bf8fabda981736744c443c4d0b984", "best_bid": "0.002", "best_ask": "0.011"}], "timestamp": "1769384211825", "event_type": "price_change"}}
{"_local_timestamp": "2026-01-25T23:36:51.920613+00:00", "data": {"market": "0x37d7295a17db461c15867862afe90bfad6cd46436b0d121a7c96c37e166103b4", "price_changes": [{"asset_id": "48325180813773997762337012603425087662105904105229463158116317479132765545801", "price": "0.927", "size": "20", "side": "BUY", "hash": "ee17ce55b4c382c3bd27545a9477a416123a6db2", "best_bid": "0.989", "best_ask": "0.998"}, {"asset_id": "65341950601583802479848929397121491003949963027873255906537010617800365051709", "price": "0.073", "size": "20", "side": "SELL", "hash": "5f133b5785732f23da09631030235242f864c21d", "best_bid": "0.002", "best_ask": "0.011"}], "timestamp": "1769384211855", "event_type": "price_change"}}
{"_local_timestamp": "2026-01-25T23:36:52.014585+00:00", "data": {"market": "0x37d7295a17db461c15867862afe90bfad6cd46436b0d121a7c96c37e166103b4", "price_changes": [{"asset_id": "48325180813773997762337012603425087662105904105229463158116317479132765545801", "price": "0.926", "size": "0", "side": "BUY", "hash": "e8d79f9197a4760a83476bd89139bfd249468adb", "best_bid": "0.989", "best_ask": "0.998"}, {"asset_id": "65341950601583802479848929397121491003949963027873255906537010617800365051709", "price": "0.074", "size": "0", "side": "SELL", "hash": "53b2c4ee5e688eaff150efcac4b2741f450d6d14", "best_bid": "0.002", "best_ask": "0.011"}], "timestamp": "1769384211938", "event_type": "price_change"}}
{"_local_timestamp": "2026-01-25T23:36:52.031858+00:00", "data": {"market": "0x37d7295a17db461c15867862afe90bfad6cd46436b0d121a7c96c37e166103b4", "price_changes": [{"asset_id": "48325180813773997762337012603425087662105904105229463158116317479132765545801", "price": "0.93", "size": "150", "side": "BUY", "hash": "aef8b48128b01cd442ed90ee41d29766805b4a0e", "best_bid": "0.989", "best_ask": "0.998"}, {"asset_id": "65341950601583802479848929397121491003949963027873255906537010617800365051709", "price": "0.07", "size": "150", "side": "SELL", "hash": "1678471ffc14004e413691da5acd0302f2037f40", "best_bid": "0.002", "best_ask": "0.011"}], "timestamp": "1769384211958", "event_type": "price_change"}}
{"_local_timestamp": "2026-01-25T23:36:54.349302+00:00", "data": {"market": "0x37d7295a17db461c15867862afe90bfad6cd46436b0d121a7c96c37e166103b4", "price_changes": [{"asset_id": "48325180813773997762337012603425087662105904105229463158116317479132765545801", "price": "0.927", "size": "0", "side": "BUY", "hash": "0f023932605331a704632f7b90f1f4d07b765ab7", "best_bid": "0.989", "best_ask": "0.998"}, {"asset_id": "65341950601583802479848929397121491003949963027873255906537010617800365051709", "price": "0.073", "size": "0", "side": "SELL", "hash": "e4a7f4f34a472a988e02ae4ea93ac149fdc97acd", "best_bid": "0.002", "best_ask": "0.011"}], "timestamp": "1769384214272", "event_type": "price_change"}}
{"_local_timestamp": "2026-01-25T23:36:54.372853+00:00", "data": {"market": "0x37d7295a17db461c15867862afe90bfad6cd46436b0d121a7c96c37e166103b4", "price_changes": [{"asset_id": "48325180813773997762337012603425087662105904105229463158116317479132765545801", "price": "0.921", "size": "20", "side": "BUY", "hash": "14737a009b8ba3c5d445d2068e200a635ee437ae", "best_bid": "0.989", "best_ask": "0.998"}, {"asset_id": "65341950601583802479848929397121491003949963027873255906537010617800365051709", "price": "0.079", "size": "20", "side": "SELL", "hash": "2998b95469829644cef35357f7b28593d664e1ae", "best_bid": "0.002", "best_ask": "0.011"}], "timestamp": "1769384214299", "event_type": "price_change"}}
{"_local_timestamp": "2026-01-25T23:36:54.471075+00:00", "data": {"market": "0x37d7295a17db461c15867862afe90bfad6cd46436b0d121a7c96c37e166103b4", "price_changes": [{"asset_id": "48325180813773997762337012603425087662105904105229463158116317479132765545801", "price": "0.93", "size": "0", "side": "BUY", "hash": "fb5c785066b21f253ae66c252f541f9d9bebb1b0", "best_bid": "0.989", "best_ask": "0.998"}, {"asset_id": "65341950601583802479848929397121491003949963027873255906537010617800365051709", "price": "0.07", "size": "0", "side": "SELL", "hash": "3722f80e306d5a5f7824b179362de94d7bd4cf7f", "best_bid": "0.002", "best_ask": "0.011"}], "timestamp": "1769384214393", "event_type": "price_change"}}
{"_local_timestamp": "2026-01-25T23:36:54.487284+00:00", "data": {"market": "0x37d7295a17db461c15867862afe90bfad6cd46436b0d121a7c96c37e166103b4", "price_changes": [{"asset_id": "48325180813773997762337012603425087662105904105229463158116317479132765545801", "price": "0.926", "size": "400", "side": "BUY", "hash": "faf1ae13833bc3ee2a2fa52534e1dca7addd121f", "best_bid": "0.989", "best_ask": "0.998"}, {"asset_id": "65341950601583802479848929397121491003949963027873255906537010617800365051709", "price": "0.074", "size": "400", "side": "SELL", "hash": "733b98abfb0572eb2051929ec3de22ef70872e4f", "best_bid": "0.002", "best_ask": "0.011"}], "timestamp": "1769384214414", "event_type": "price_change"}}
{"_local_timestamp": "2026-01-25T23:36:54.897653+00:00", "data": {"market": "0x6fbec2c3327fe7b5392b94fe48ccb41c7404a4a793957804b4b8fe8239376d12", "price_changes": [{"asset_id": "74232891440125659542320690757580411929973234713273124974412544144242477879854", "price": "0.954", "size": "50", "side": "BUY", "hash": "33ba2e0961f79b9b60a2bf7d91f3503ca6af558e", "best_bid": "0.957", "best_ask": "0.979"}, {"asset_id": "69250819494674008903342626376731306359291370006377470819342000624771511803405", "price": "0.046", "size": "50", "side": "SELL", "hash": "90c2427c57b858c415a528975a3e84b621e413f3", "best_bid": "0.021", "best_ask": "0.043"}], "timestamp": "1769384214824", "event_type": "price_change"}}
{"_local_timestamp": "2026-01-25T23:36:54.922955+00:00", "data": {"market": "0x6fbec2c3327fe7b5392b94fe48ccb41c7404a4a793957804b4b8fe8239376d12", "price_changes": [{"asset_id": "69250819494674008903342626376731306359291370006377470819342000624771511803405", "price": "0.021", "size": "0", "side": "BUY", "hash": "3794f49bc63097b8bb8d3ab0352d7c86b18c4c77", "best_bid": "0.02", "best_ask": "0.043"}, {"asset_id": "74232891440125659542320690757580411929973234713273124974412544144242477879854", "price": "0.979", "size": "0", "side": "SELL", "hash": "7862364cc8f90be5057722d6502b9c3f144328e2", "best_bid": "0.957", "best_ask": "0.98"}], "timestamp": "1769384214853", "event_type": "price_change"}}
{"_local_timestamp": "2026-01-25T23:36:54.954874+00:00", "data": {"market": "0x6fbec2c3327fe7b5392b94fe48ccb41c7404a4a793957804b4b8fe8239376d12", "price_changes": [{"asset_id": "69250819494674008903342626376731306359291370006377470819342000624771511803405", "price": "0.021", "size": "137", "side": "BUY", "hash": "8e2976a7f1069277fd3f690609118f3be45a3d57", "best_bid": "0.021", "best_ask": "0.043"}, {"asset_id": "74232891440125659542320690757580411929973234713273124974412544144242477879854", "price": "0.979", "size": "137", "side": "SELL", "hash": "d17ed05c8ba49b25699e8a10ca856548658da5ab", "best_bid": "0.957", "best_ask": "0.979"}], "timestamp": "1769384214880", "event_type": "price_change"}}
{"_local_timestamp": "2026-01-25T23:36:55.023493+00:00", "data": {"market": "0x6fbec2c3327fe7b5392b94fe48ccb41c7404a4a793957804b4b8fe8239376d12", "price_changes": [{"asset_id": "74232891440125659542320690757580411929973234713273124974412544144242477879854", "price": "0.954", "size": "0", "side": "BUY", "hash": "f7ed5ae96e0775903f88e1e05826c57d0faab61f", "best_bid": "0.957", "best_ask": "0.979"}, {"asset_id": "69250819494674008903342626376731306359291370006377470819342000624771511803405", "price": "0.046", "size": "0", "side": "SELL", "hash": "5ee67c86857b61436220723c2522c6bab7944ef4", "best_bid": "0.021", "best_ask": "0.043"}], "timestamp": "1769384214943", "event_type": "price_change"}}
{"_local_timestamp": "2026-01-25T23:36:55.044598+00:00", "data": {"market": "0x37d7295a17db461c15867862afe90bfad6cd46436b0d121a7c96c37e166103b4", "price_changes": [{"asset_id": "48325180813773997762337012603425087662105904105229463158116317479132765545801", "price": "0.93", "size": "150", "side": "BUY", "hash": "bd025992c5a565ee3205d7499b54c08da101bc42", "best_bid": "0.989", "best_ask": "0.998"}, {"asset_id": "65341950601583802479848929397121491003949963027873255906537010617800365051709", "price": "0.07", "size": "150", "side": "SELL", "hash": "e7fe12e7aa4da8a19c9f6da68d09b0ed77e93a48", "best_bid": "0.002", "best_ask": "0.011"}], "timestamp": "1769384214960", "event_type": "price_change"}}
{"_local_timestamp": "2026-01-25T23:36:55.045341+00:00", "data": {"market": "0x37d7295a17db461c15867862afe90bfad6cd46436b0d121a7c96c37e166103b4", "price_changes": [{"asset_id": "48325180813773997762337012603425087662105904105229463158116317479132765545801", "price": "0.921", "size": "0", "side": "BUY", "hash": "c8aef8b6cfb33587b294247e9122eadad0602d5f", "best_bid": "0.989", "best_ask": "0.998"}, {"asset_id": "65341950601583802479848929397121491003949963027873255906537010617800365051709", "price": "0.079", "size": "0", "side": "SELL", "hash": "a616aaaca54e7e221bbca18154f1d26c355c4607", "best_bid": "0.002", "best_ask": "0.011"}], "timestamp": "1769384214976", "event_type": "price_change"}}
{"_local_timestamp": "2026-01-25T23:36:55.054135+00:00", "data": {"market": "0x37d7295a17db461c15867862afe90bfad6cd46436b0d121a7c96c37e166103b4", "price_changes": [{"asset_id": "48325180813773997762337012603425087662105904105229463158116317479132765545801", "price": "0.926", "size": "0", "side": "BUY", "hash": "2214d823ff9b32858b53a1f533e4e1918dfbc6ae", "best_bid": "0.989", "best_ask": "0.998"}, {"asset_id": "65341950601583802479848929397121491003949963027873255906537010617800365051709", "price": "0.074", "size": "0", "side": "SELL", "hash": "7bc1a1fedcbf7c79ef966039ed6b63a592cbdf1e", "best_bid": "0.002", "best_ask": "0.011"}], "timestamp": "1769384214983", "event_type": "price_change"}}
{"_local_timestamp": "2026-01-25T23:36:55.092068+00:00", "data": {"market": "0x37d7295a17db461c15867862afe90bfad6cd46436b0d121a7c96c37e166103b4", "price_changes": [{"asset_id": "48325180813773997762337012603425087662105904105229463158116317479132765545801", "price": "0.927", "size": "20", "side": "BUY", "hash": "cbd4dc803c56182dbf98eecf278608b05aa06e54", "best_bid": "0.989", "best_ask": "0.998"}, {"asset_id": "65341950601583802479848929397121491003949963027873255906537010617800365051709", "price": "0.073", "size": "20", "side": "SELL", "hash": "90cb35d7b0d244054f35e3cf774fc97b9e146407", "best_bid": "0.002", "best_ask": "0.011"}], "timestamp": "1769384215005", "event_type": "price_change"}}
{"_local_timestamp": "2026-01-25T23:36:55.219208+00:00", "data": {"market": "0x37d7295a17db461c15867862afe90bfad6cd46436b0d121a7c96c37e166103b4", "price_changes": [{"asset_id": "48325180813773997762337012603425087662105904105229463158116317479132765545801", "price": "0.93", "size": "0", "side": "BUY", "hash": "480951c52502a6b651106fa692976be60a30cec1", "best_bid": "0.989", "best_ask": "0.998"}, {"asset_id": "65341950601583802479848929397121491003949963027873255906537010617800365051709", "price": "0.07", "size": "0", "side": "SELL", "hash": "5e65016863b12f0b663086ebf11f1f09e6cf8ce6", "best_bid": "0.002", "best_ask": "0.011"}], "timestamp": "1769384215083", "event_type": "price_change"}}
{"_local_timestamp": "2026-01-25T23:36:55.520640+00:00", "data": {"market": "0x6fbec2c3327fe7b5392b94fe48ccb41c7404a4a793957804b4b8fe8239376d12", "price_changes": [{"asset_id": "69250819494674008903342626376731306359291370006377470819342000624771511803405", "price": "0.045", "size": "0", "side": "SELL", "hash": "1ea23bf6dce2e9cce1fc4970a45224e0f34ee425", "best_bid": "0.021", "best_ask": "0.043"}, {"asset_id": "74232891440125659542320690757580411929973234713273124974412544144242477879854", "price": "0.955", "size": "0", "side": "BUY", "hash": "ecbbe567d319283ea45d05d30b703ae5677eb618", "best_bid": "0.957", "best_ask": "0.979"}], "timestamp": "1769384215437", "event_type": "price_change"}}
{"_local_timestamp": "2026-01-25T23:36:55.593247+00:00", "data": {"market": "0x6fbec2c3327fe7b5392b94fe48ccb41c7404a4a793957804b4b8fe8239376d12", "price_changes": [{"asset_id": "69250819494674008903342626376731306359291370006377470819342000624771511803405", "price": "0.052", "size": "30", "side": "SELL", "hash": "420a6bd682e51d87c1445a8df4a9c49e5b492a9d", "best_bid": "0.021", "best_ask": "0.043"}, {"asset_id": "74232891440125659542320690757580411929973234713273124974412544144242477879854", "price": "0.948", "size": "30", "side": "BUY", "hash": "18ca3c789a34bf0ce3b359c2f92dd932e8e26218", "best_bid": "0.957", "best_ask": "0.979"}], "timestamp": "1769384215496", "event_type": "price_change"}}
{"_local_timestamp": "2026-01-25T23:36:55.598353+00:00", "data": {"market": "0x37d7295a17db461c15867862afe90bfad6cd46436b0d121a7c96c37e166103b4", "price_changes": [{"asset_id": "48325180813773997762337012603425087662105904105229463158116317479132765545801", "price": "0.927", "size": "0", "side": "BUY", "hash": "4c0ec7b2181ee08e0b8154468c4d43b291cba261", "best_bid": "0.989", "best_ask": "0.998"}, {"asset_id": "65341950601583802479848929397121491003949963027873255906537010617800365051709", "price": "0.073", "size": "0", "side": "SELL", "hash": "016f10a1318cfc5413ff7e5e16b114a4f7e3b948", "best_bid": "0.002", "best_ask": "0.011"}], "timestamp": "1769384215519", "event_type": "price_change"}}
{"_local_timestamp": "2026-01-25T23:36:55.630140+00:00", "data": {"market": "0x37d7295a17db461c15867862afe90bfad6cd46436b0d121a7c96c37e166103b4", "price_changes": [{"asset_id": "48325180813773997762337012603425087662105904105229463158116317479132765545801", "price": "0.931", "size": "150", "side": "BUY", "hash": "1500a70c8b588ace69d96e1c945b07688d960858", "best_bid": "0.989", "best_ask": "0.998"}, {"asset_id": "65341950601583802479848929397121491003949963027873255906537010617800365051709", "price": "0.069", "size": "150", "side": "SELL", "hash": "1c46378251bcc1ce39c60fe1553944c93e91d6a1", "best_bid": "0.002", "best_ask": "0.011"}], "timestamp": "1769384215556", "event_type": "price_change"}}
{"_local_timestamp": "2026-01-25T23:36:55.631009+00:00", "data": {"market": "0x37d7295a17db461c15867862afe90bfad6cd46436b0d121a7c96c37e166103b4", "price_changes": [{"asset_id": "48325180813773997762337012603425087662105904105229463158116317479132765545801", "price": "0.921", "size": "20", "side": "BUY", "hash": "44d54b165bf058be362dcdae41c390b4dd056983", "best_bid": "0.989", "best_ask": "0.998"}, {"asset_id": "65341950601583802479848929397121491003949963027873255906537010617800365051709", "price": "0.079", "size": "20", "side": "SELL", "hash": "13b104675869682978cf05e97c97c71c9ecfb8a6", "best_bid": "0.002", "best_ask": "0.011"}], "timestamp": "1769384215559", "event_type": "price_change"}}
{"_local_timestamp": "2026-01-25T23:36:55.636969+00:00", "data": {"market": "0x6fbec2c3327fe7b5392b94fe48ccb41c7404a4a793957804b4b8fe8239376d12", "price_changes": [{"asset_id": "74232891440125659542320690757580411929973234713273124974412544144242477879854", "price": "0.913", "size": "0", "side": "BUY", "hash": "6cb25b9fe9cb1eab4c10d15f4660804918e603f9", "best_bid": "0.957", "best_ask": "0.979"}, {"asset_id": "69250819494674008903342626376731306359291370006377470819342000624771511803405", "price": "0.087", "size": "0", "side": "SELL", "hash": "66f56ad69de28746c216dd1b9826db91b2a235dc", "best_bid": "0.021", "best_ask": "0.043"}], "timestamp": "1769384215568", "event_type": "price_change"}}
{"_local_timestamp": "2026-01-25T23:36:55.739142+00:00", "data": {"market": "0x6fbec2c3327fe7b5392b94fe48ccb41c7404a4a793957804b4b8fe8239376d12", "price_changes": [{"asset_id": "74232891440125659542320690757580411929973234713273124974412544144242477879854", "price": "0.954", "size": "50", "side": "BUY", "hash": "1e480a832f850d78626c70155e988cf2dc6e2f2e", "best_bid": "0.957", "best_ask": "0.979"}, {"asset_id": "69250819494674008903342626376731306359291370006377470819342000624771511803405", "price": "0.046", "size": "50", "side": "SELL", "hash": "6c7072dd93c41b4ea7015fe0f8de2fc0202a919b", "best_bid": "0.021", "best_ask": "0.043"}], "timestamp": "1769384215659", "event_type": "price_change"}}
{"_local_timestamp": "2026-01-25T23:36:55.782072+00:00", "data": {"market": "0x37d7295a17db461c15867862afe90bfad6cd46436b0d121a7c96c37e166103b4", "price_changes": [{"asset_id": "48325180813773997762337012603425087662105904105229463158116317479132765545801", "price": "0.931", "size": "0", "side": "BUY", "hash": "61569cbc27e33f82b409c1c62efc903b3a10dc25", "best_bid": "0.989", "best_ask": "0.998"}, {"asset_id": "65341950601583802479848929397121491003949963027873255906537010617800365051709", "price": "0.069", "size": "0", "side": "SELL", "hash": "e6689a3338ef6f71ce1bd3f4d12459d22a56ade9", "best_bid": "0.002", "best_ask": "0.011"}], "timestamp": "1769384215666", "event_type": "price_change"}}
{"_local_timestamp": "2026-01-25T23:36:57.891001+00:00", "data": {"market": "0xfebf77a5fafe69270ae88267592d6af563d5fb8038167c1e5f0f84389a180b24", "price_changes": [{"asset_id": "22601624556062096769343443867020199590792651484414597499875211914147125190628", "price": "0.093", "size": "0", "side": "SELL", "hash": "96eb3da8e58090811c110d1dd524555b14cd2b41", "best_bid": "0.043", "best_ask": "0.044"}, {"asset_id": "108070880530079055956658493954731541905445967268057229566528793256732992302888", "price": "0.907", "size": "0", "side": "BUY", "hash": "1615b690efeda53c1e6f346b462525b896f6dd91", "best_bid": "0.956", "best_ask": "0.957"}], "timestamp": "1769384217629", "event_type": "price_change"}}
{"_local_timestamp": "2026-01-25T23:36:57.980925+00:00", "data": {"market": "0xfebf77a5fafe69270ae88267592d6af563d5fb8038167c1e5f0f84389a180b24", "price_changes": [{"asset_id": "22601624556062096769343443867020199590792651484414597499875211914147125190628", "price": "0.262", "size": "200", "side": "SELL", "hash": "2e8a9143be4da71b619d0509e20a14ea74fa4be4", "best_bid": "0.043", "best_ask": "0.044"}, {"asset_id": "108070880530079055956658493954731541905445967268057229566528793256732992302888", "price": "0.738", "size": "200", "side": "BUY", "hash": "47adf98a28b6e13c5c50434d960540335e81f702", "best_bid": "0.956", "best_ask": "0.957"}], "timestamp": "1769384217892", "event_type": "price_change"}}
{"_local_timestamp": "2026-01-25T23:36:58.009171+00:00", "data": {"market": "0x37d7295a17db461c15867862afe90bfad6cd46436b0d121a7c96c37e166103b4", "price_changes": [{"asset_id": "48325180813773997762337012603425087662105904105229463158116317479132765545801", "price": "0.926", "size": "400", "side": "BUY", "hash": "f8da00e62fdef0cdb4ea93f35af69c5a8b30971e", "best_bid": "0.989", "best_ask": "0.998"}, {"asset_id": "65341950601583802479848929397121491003949963027873255906537010617800365051709", "price": "0.074", "size": "400", "side": "SELL", "hash": "d190b9d1ffdde6dc11f0302756e482b9434bde88", "best_bid": "0.002", "best_ask": "0.011"}], "timestamp": "1769384217939", "event_type": "price_change"}}
{"_local_timestamp": "2026-01-25T23:36:58.013478+00:00", "data": {"market": "0x6fbec2c3327fe7b5392b94fe48ccb41c7404a4a793957804b4b8fe8239376d12", "price_changes": [{"asset_id": "74232891440125659542320690757580411929973234713273124974412544144242477879854", "price": "0.913", "size": "400", "side": "BUY", "hash": "15eeb166cea3d0af2cee62033acc56fec1b916fe", "best_bid": "0.957", "best_ask": "0.979"}, {"asset_id": "69250819494674008903342626376731306359291370006377470819342000624771511803405", "price": "0.087", "size": "400", "side": "SELL", "hash": "42c81755378b3941ee038d4517e3b55e8a4e917c", "best_bid": "0.021", "best_ask": "0.043"}], "timestamp": "1769384217944", "event_type": "price_change"}}
{"_local_timestamp": "2026-01-25T23:36:58.252557+00:00", "data": {"market": "0x6fbec2c3327fe7b5392b94fe48ccb41c7404a4a793957804b4b8fe8239376d12", "price_changes": [{"asset_id": "69250819494674008903342626376731306359291370006377470819342000624771511803405", "price": "0.003", "size": "0", "side": "BUY", "hash": "8481b130f1fa398f70159dd509ea99d16729a444", "best_bid": "0.021", "best_ask": "0.043"}, {"asset_id": "74232891440125659542320690757580411929973234713273124974412544144242477879854", "price": "0.997", "size": "0", "side": "SELL", "hash": "c5bee67fd0645becab8b187c80ced21637c3913b", "best_bid": "0.957", "best_ask": "0.979"}], "timestamp": "1769384218088", "event_type": "price_change"}}
{"_local_timestamp": "2026-01-25T23:36:58.261899+00:00", "data": {"market": "0x6fbec2c3327fe7b5392b94fe48ccb41c7404a4a793957804b4b8fe8239376d12", "price_changes": [{"asset_id": "74232891440125659542320690757580411929973234713273124974412544144242477879854", "price": "0.404", "size": "45", "side": "BUY", "hash": "e8a67e0485885951439f2ce25e472fc4916ec073", "best_bid": "0.957", "best_ask": "0.979"}, {"asset_id": "69250819494674008903342626376731306359291370006377470819342000624771511803405", "price": "0.596", "size": "45", "side": "SELL", "hash": "650fee1bcf94a2a35f4ff6eaa5611bb85e919e1c", "best_bid": "0.021", "best_ask": "0.043"}], "timestamp": "1769384218093", "event_type": "price_change"}}
{"_local_timestamp": "2026-01-25T23:36:59.438877+00:00", "data": {"market": "0xfebf77a5fafe69270ae88267592d6af563d5fb8038167c1e5f0f84389a180b24", "price_changes": [{"asset_id": "108070880530079055956658493954731541905445967268057229566528793256732992302888", "price": "0.937", "size": "100", "side": "BUY", "hash": "0dc304ca75fda96e65904ef5d6cb788ce3fe4796", "best_bid": "0.956", "best_ask": "0.957"}, {"asset_id": "22601624556062096769343443867020199590792651484414597499875211914147125190628", "price": "0.063", "size": "100", "side": "SELL", "hash": "18a0a9c3d71e8a76eb80b62f0373366eaac4cc33", "best_bid": "0.043", "best_ask": "0.044"}], "timestamp": "1769384219362", "event_type": "price_change"}}
{"_local_timestamp": "2026-01-25T23:36:59.892462+00:00", "data": {"market": "0xfebf77a5fafe69270ae88267592d6af563d5fb8038167c1e5f0f84389a180b24", "price_changes": [{"asset_id": "108070880530079055956658493954731541905445967268057229566528793256732992302888", "price": "0.937", "size": "0", "side": "BUY", "hash": "a8ea6036c59ab34e3f61fc30abc15d456757740f", "best_bid": "0.956", "best_ask": "0.957"}, {"asset_id": "22601624556062096769343443867020199590792651484414597499875211914147125190628", "price": "0.063", "size": "0", "side": "SELL", "hash": "bc4ff1daf9811321a7831be55720285c6726e041", "best_bid": "0.043", "best_ask": "0.044"}], "timestamp": "1769384219810", "event_type": "price_change"}}
{"_local_timestamp": "2026-01-25T23:36:59.952071+00:00", "data": {"market": "0xfebf77a5fafe69270ae88267592d6af563d5fb8038167c1e5f0f84389a180b24", "price_changes": [{"asset_id": "108070880530079055956658493954731541905445967268057229566528793256732992302888", "price": "0.938", "size": "100", "side": "BUY", "hash": "bbdf879d478b2db7842cd6c102aa9fed017f2adb", "best_bid": "0.956", "best_ask": "0.957"}, {"asset_id": "22601624556062096769343443867020199590792651484414597499875211914147125190628", "price": "0.062", "size": "100", "side": "SELL", "hash": "926cf242d3c6862f4f6d722bce18975fdda57ee2", "best_bid": "0.043", "best_ask": "0.044"}], "timestamp": "1769384219884", "event_type": "price_change"}}
{"_local_timestamp": "2026-01-25T23:37:01.809181+00:00", "data": {"market": "0x37d7295a17db461c15867862afe90bfad6cd46436b0d121a7c96c37e166103b4", "price_changes": [{"asset_id": "48325180813773997762337012603425087662105904105229463158116317479132765545801", "price": "0.921", "size": "0", "side": "BUY", "hash": "f80efbb8f10e7d65649967d4ee0979ef39856941", "best_bid": "0.989", "best_ask": "0.998"}, {"asset_id": "65341950601583802479848929397121491003949963027873255906537010617800365051709", "price": "0.079", "size": "0", "side": "SELL", "hash": "f61445d77e560a0e87e1f6dab221072722175202", "best_bid": "0.002", "best_ask": "0.011"}], "timestamp": "1769384221735", "event_type": "price_change"}}
{"_local_timestamp": "2026-01-25T23:37:01.834474+00:00", "data": {"market": "0x37d7295a17db461c15867862afe90bfad6cd46436b0d121a7c96c37e166103b4", "price_changes": [{"asset_id": "48325180813773997762337012603425087662105904105229463158116317479132765545801", "price": "0.927", "size": "20", "side": "BUY", "hash": "6b5622283080a7355d1f1020776b9aeb85cc1b73", "best_bid": "0.989", "best_ask": "0.998"}, {"asset_id": "65341950601583802479848929397121491003949963027873255906537010617800365051709", "price": "0.073", "size": "20", "side": "SELL", "hash": "fd34529bf8c6e1bca8a62b1491aaa96bdbcc1b91", "best_bid": "0.002", "best_ask": "0.011"}], "timestamp": "1769384221764", "event_type": "price_change"}}
{"_local_timestamp": "2026-01-25T23:37:01.919012+00:00", "data": {"market": "0x37d7295a17db461c15867862afe90bfad6cd46436b0d121a7c96c37e166103b4", "price_changes": [{"asset_id": "48325180813773997762337012603425087662105904105229463158116317479132765545801", "price": "0.926", "size": "0", "side": "BUY", "hash": "cd27f677787cff7e5aa7d0bc681f365335701618", "best_bid": "0.989", "best_ask": "0.998"}, {"asset_id": "65341950601583802479848929397121491003949963027873255906537010617800365051709", "price": "0.074", "size": "0", "side": "SELL", "hash": "799571b7e149c241033a35cdf59959109af0c48b", "best_bid": "0.002", "best_ask": "0.011"}], "timestamp": "1769384221838", "event_type": "price_change"}}
{"_local_timestamp": "2026-01-25T23:37:01.972234+00:00", "data": {"market": "0x37d7295a17db461c15867862afe90bfad6cd46436b0d121a7c96c37e166103b4", "price_changes": [{"asset_id": "48325180813773997762337012603425087662105904105229463158116317479132765545801", "price": "0.931", "size": "150", "side": "BUY", "hash": "22348938dbadb92277d05d94d7f6bde522192f20", "best_bid": "0.989", "best_ask": "0.998"}, {"asset_id": "65341950601583802479848929397121491003949963027873255906537010617800365051709", "price": "0.069", "size": "150", "side": "SELL", "hash": "e7ba8b21eb041119563522913d799750e2c43e0b", "best_bid": "0.002", "best_ask": "0.011"}], "timestamp": "1769384221888", "event_type": "price_change"}}
{"_local_timestamp": "2026-01-25T23:37:05.221300+00:00", "data": {"market": "0x37d7295a17db461c15867862afe90bfad6cd46436b0d121a7c96c37e166103b4", "price_changes": [{"asset_id": "48325180813773997762337012603425087662105904105229463158116317479132765545801", "price": "0.927", "size": "0", "side": "BUY", "hash": "9c334ba25897be41c19db5099f74120f836eb7d3", "best_bid": "0.989", "best_ask": "0.998"}, {"asset_id": "65341950601583802479848929397121491003949963027873255906537010617800365051709", "price": "0.073", "size": "0", "side": "SELL", "hash": "bf98d67cffd50834c091e99d38ba9e8f13d182c4", "best_bid": "0.002", "best_ask": "0.011"}], "timestamp": "1769384225140", "event_type": "price_change"}}
{"_local_timestamp": "2026-01-25T23:37:05.248348+00:00", "data": {"market": "0x37d7295a17db461c15867862afe90bfad6cd46436b0d121a7c96c37e166103b4", "price_changes": [{"asset_id": "48325180813773997762337012603425087662105904105229463158116317479132765545801", "price": "0.921", "size": "20", "side": "BUY", "hash": "ea5d9a4329f3dece56fd49a76d690a782ddd1625", "best_bid": "0.989", "best_ask": "0.998"}, {"asset_id": "65341950601583802479848929397121491003949963027873255906537010617800365051709", "price": "0.079", "size": "20", "side": "SELL", "hash": "8e8c2cfea546157d9665e5574731616b8a0140cc", "best_bid": "0.002", "best_ask": "0.011"}], "timestamp": "1769384225168", "event_type": "price_change"}}
{"_local_timestamp": "2026-01-25T23:37:05.328498+00:00", "data": {"market": "0x37d7295a17db461c15867862afe90bfad6cd46436b0d121a7c96c37e166103b4", "price_changes": [{"asset_id": "48325180813773997762337012603425087662105904105229463158116317479132765545801", "price": "0.931", "size": "0", "side": "BUY", "hash": "2fc9bcfae06fbf841c12dd1375f7a4bb98e16025", "best_bid": "0.989", "best_ask": "0.998"}, {"asset_id": "65341950601583802479848929397121491003949963027873255906537010617800365051709", "price": "0.069", "size": "0", "side": "SELL", "hash": "7b55d54b2304606c98d93e0ab6dcb509eef93610", "best_bid": "0.002", "best_ask": "0.011"}], "timestamp": "1769384225253", "event_type": "price_change"}}
{"_local_timestamp": "2026-01-25T23:37:05.365259+00:00", "data": {"market": "0x37d7295a17db461c15867862afe90bfad6cd46436b0d121a7c96c37e166103b4", "price_changes": [{"asset_id": "48325180813773997762337012603425087662105904105229463158116317479132765545801", "price": "0.926", "size": "400", "side": "BUY", "hash": "8efc3808d1f0db6b83f4fe072a24563d2f019ea8", "best_bid": "0.989", "best_ask": "0.998"}, {"asset_id": "65341950601583802479848929397121491003949963027873255906537010617800365051709", "price": "0.074", "size": "400", "side": "SELL", "hash": "c22a8ce936002c3f16d3cf155adf4308685d4970", "best_bid": "0.002", "best_ask": "0.011"}], "timestamp": "1769384225292", "event_type": "price_change"}}
{"_local_timestamp": "2026-01-25T23:37:11.166473+00:00", "data": {"market": "0x37d7295a17db461c15867862afe90bfad6cd46436b0d121a7c96c37e166103b4", "price_changes": [{"asset_id": "48325180813773997762337012603425087662105904105229463158116317479132765545801", "price": "0.921", "size": "0", "side": "BUY", "hash": "c72ed4f1b3293a031f027c9a5dc7a9500a8b9498", "best_bid": "0.989", "best_ask": "0.998"}, {"asset_id": "65341950601583802479848929397121491003949963027873255906537010617800365051709", "price": "0.079", "size": "0", "side": "SELL", "hash": "461a02d38dd149dfc5cc3c5e5aa40330ad6dc688", "best_bid": "0.002", "best_ask": "0.011"}], "timestamp": "1769384231097", "event_type": "price_change"}}
{"_local_timestamp": "2026-01-25T23:37:11.198705+00:00", "data": {"market": "0x37d7295a17db461c15867862afe90bfad6cd46436b0d121a7c96c37e166103b4", "price_changes": [{"asset_id": "48325180813773997762337012603425087662105904105229463158116317479132765545801", "price": "0.927", "size": "20", "side": "BUY", "hash": "aec08e66a4651fcae2914c8ee48366fbb27aac89", "best_bid": "0.989", "best_ask": "0.998"}, {"asset_id": "65341950601583802479848929397121491003949963027873255906537010617800365051709", "price": "0.073", "size": "20", "side": "SELL", "hash": "5a7d2badf74420d9b4ec01c0ed90c77d443d09ff", "best_bid": "0.002", "best_ask": "0.011"}], "timestamp": "1769384231128", "event_type": "price_change"}}
{"_local_timestamp": "2026-01-25T23:37:11.282304+00:00", "data": {"market": "0x37d7295a17db461c15867862afe90bfad6cd46436b0d121a7c96c37e166103b4", "price_changes": [{"asset_id": "48325180813773997762337012603425087662105904105229463158116317479132765545801", "price": "0.926", "size": "0", "side": "BUY", "hash": "43fd6685c1ee0c408157b9667d6189bdb928590d", "best_bid": "0.989", "best_ask": "0.998"}, {"asset_id": "65341950601583802479848929397121491003949963027873255906537010617800365051709", "price": "0.074", "size": "0", "side": "SELL", "hash": "33b6233a38621fec961183b746a52af9a881e872", "best_bid": "0.002", "best_ask": "0.011"}], "timestamp": "1769384231214", "event_type": "price_change"}}
{"_local_timestamp": "2026-01-25T23:37:11.319001+00:00", "data": {"market": "0x37d7295a17db461c15867862afe90bfad6cd46436b0d121a7c96c37e166103b4", "price_changes": [{"asset_id": "48325180813773997762337012603425087662105904105229463158116317479132765545801", "price": "0.931", "size": "150", "side": "BUY", "hash": "efe5e3c8082aa8db5acabb7e4c5b708fad16662f", "best_bid": "0.989", "best_ask": "0.998"}, {"asset_id": "65341950601583802479848929397121491003949963027873255906537010617800365051709", "price": "0.069", "size": "150", "side": "SELL", "hash": "17058057823ebdf038e9c37f9e0c85e74315ed41", "best_bid": "0.002", "best_ask": "0.011"}], "timestamp": "1769384231235", "event_type": "price_change"}}
{"_local_timestamp": "2026-01-25T23:37:14.574045+00:00", "data": {"market": "0xfebf77a5fafe69270ae88267592d6af563d5fb8038167c1e5f0f84389a180b24", "price_changes": [{"asset_id": "22601624556062096769343443867020199590792651484414597499875211914147125190628", "price": "0.014", "size": "234", "side": "BUY", "hash": "8e8844687adce5c778c75019da39806a41d0a3d5", "best_bid": "0.043", "best_ask": "0.044"}, {"asset_id": "108070880530079055956658493954731541905445967268057229566528793256732992302888", "price": "0.986", "size": "234", "side": "SELL", "hash": "ff5cfe14b597da0c5431e3816f701cc87b67a134", "best_bid": "0.956", "best_ask": "0.957"}], "timestamp": "1769384234476", "event_type": "price_change"}}
{"_local_timestamp": "2026-01-25T23:37:15.282864+00:00", "data": {"market": "0x37d7295a17db461c15867862afe90bfad6cd46436b0d121a7c96c37e166103b4", "price_changes": [{"asset_id": "48325180813773997762337012603425087662105904105229463158116317479132765545801", "price": "0.927", "size": "0", "side": "BUY", "hash": "2af6573d39f0547cf4e729ea562f17ab77ef50ba", "best_bid": "0.989", "best_ask": "0.998"}, {"asset_id": "65341950601583802479848929397121491003949963027873255906537010617800365051709", "price": "0.073", "size": "0", "side": "SELL", "hash": "1304cd28e2ba1aee3cd46fc35db3e0e383647165", "best_bid": "0.002", "best_ask": "0.011"}], "timestamp": "1769384235211", "event_type": "price_change"}}
{"_local_timestamp": "2026-01-25T23:37:15.326535+00:00", "data": {"market": "0xfebf77a5fafe69270ae88267592d6af563d5fb8038167c1e5f0f84389a180b24", "price_changes": [{"asset_id": "108070880530079055956658493954731541905445967268057229566528793256732992302888", "price": "0.949", "size": "0", "side": "BUY", "hash": "25d80a33da124cc1fd2fb5dd6f0f9c0c86817ca5", "best_bid": "0.956", "best_ask": "0.957"}, {"asset_id": "22601624556062096769343443867020199590792651484414597499875211914147125190628", "price": "0.051", "size": "0", "side": "SELL", "hash": "9d446dcf0aabe7311d59267949831cb6e4222f7a", "best_bid": "0.043", "best_ask": "0.044"}], "timestamp": "1769384235235", "event_type": "price_change"}}
{"_local_timestamp": "2026-01-25T23:37:15.327468+00:00", "data": {"market": "0x37d7295a17db461c15867862afe90bfad6cd46436b0d121a7c96c37e166103b4", "price_changes": [{"asset_id": "48325180813773997762337012603425087662105904105229463158116317479132765545801", "price": "0.921", "size": "20", "side": "BUY", "hash": "51f8b04f747a46d24752b22f850cb72b1bc88e16", "best_bid": "0.989", "best_ask": "0.998"}, {"asset_id": "65341950601583802479848929397121491003949963027873255906537010617800365051709", "price": "0.079", "size": "20", "side": "SELL", "hash": "81424f4f17fe639ced6d5b0e0b12951822542687", "best_bid": "0.002", "best_ask": "0.011"}], "timestamp": "1769384235244", "event_type": "price_change"}}
{"_local_timestamp": "2026-01-25T23:37:15.396091+00:00", "data": {"market": "0x37d7295a17db461c15867862afe90bfad6cd46436b0d121a7c96c37e166103b4", "price_changes": [{"asset_id": "48325180813773997762337012603425087662105904105229463158116317479132765545801", "price": "0.931", "size": "0", "side": "BUY", "hash": "da23130e84a067a0ff2055bdb08e2346f7e9ef13", "best_bid": "0.989", "best_ask": "0.998"}, {"asset_id": "65341950601583802479848929397121491003949963027873255906537010617800365051709", "price": "0.069", "size": "0", "side": "SELL", "hash": "97933fc38c66382ca64e60fdf824b5dba744322b", "best_bid": "0.002", "best_ask": "0.011"}], "timestamp": "1769384235325", "event_type": "price_change"}}
{"_local_timestamp": "2026-01-25T23:37:15.432570+00:00", "data": {"market": "0x37d7295a17db461c15867862afe90bfad6cd46436b0d121a7c96c37e166103b4", "price_changes": [{"asset_id": "48325180813773997762337012603425087662105904105229463158116317479132765545801", "price": "0.926", "size": "400", "side": "BUY", "hash": "1179a4f05b7f0d1e6c0d7fb064ddc0f4bc92c2ef", "best_bid": "0.989", "best_ask": "0.998"}, {"asset_id": "65341950601583802479848929397121491003949963027873255906537010617800365051709", "price": "0.074", "size": "400", "side": "SELL", "hash": "43b948de065a15c17cd26c8148943f0428193bcf", "best_bid": "0.002", "best_ask": "0.011"}], "timestamp": "1769384235358", "event_type": "price_change"}}
{"_local_timestamp": "2026-01-25T23:37:18.151875+00:00", "data": {"market": "0xfebf77a5fafe69270ae88267592d6af563d5fb8038167c1e5f0f84389a180b24", "price_changes": [{"asset_id": "22601624556062096769343443867020199590792651484414597499875211914147125190628", "price": "0.014", "size": "3258.04", "side": "BUY", "hash": "66ed8b454afd8103a3271b5a95952875094460ae", "best_bid": "0.043", "best_ask": "0.044"}, {"asset_id": "108070880530079055956658493954731541905445967268057229566528793256732992302888", "price": "0.986", "size": "3258.04", "side": "SELL", "hash": "133963f6d3cf68d79c3637a5d2df53d89a509be7", "best_bid": "0.956", "best_ask": "0.957"}], "timestamp": "1769384238036", "event_type": "price_change"}}
{"_local_timestamp": "2026-01-25T23:37:18.152749+00:00", "data": {"market": "0xfebf77a5fafe69270ae88267592d6af563d5fb8038167c1e5f0f84389a180b24", "price_changes": [{"asset_id": "108070880530079055956658493954731541905445967268057229566528793256732992302888", "price": "0.946", "size": "120", "side": "BUY", "hash": "d821634941396d3b56f25073ad37ffaa6085f514", "best_bid": "0.956", "best_ask": "0.957"}, {"asset_id": "22601624556062096769343443867020199590792651484414597499875211914147125190628", "price": "0.054", "size": "120", "side": "SELL", "hash": "c785a650e973b8fb7aa71df3e345143256ff9308", "best_bid": "0.043", "best_ask": "0.044"}], "timestamp": "1769384238037", "event_type": "price_change"}}
{"_local_timestamp": "2026-01-25T23:37:19.068426+00:00", "data": {"market": "0x37d7295a17db461c15867862afe90bfad6cd46436b0d121a7c96c37e166103b4", "price_changes": [{"asset_id": "48325180813773997762337012603425087662105904105229463158116317479132765545801", "price": "0.921", "size": "0", "side": "BUY", "hash": "115bdf5331212ff85e7026eeff02fd86f491f619", "best_bid": "0.989", "best_ask": "0.998"}, {"asset_id": "65341950601583802479848929397121491003949963027873255906537010617800365051709", "price": "0.079", "size": "0", "side": "SELL", "hash": "760f968edf4d189f218e6729b4982a5de83f721c", "best_bid": "0.002", "best_ask": "0.011"}], "timestamp": "1769384238986", "event_type": "price_change"}}
{"_local_timestamp": "2026-01-25T23:37:19.106169+00:00", "data": {"market": "0x37d7295a17db461c15867862afe90bfad6cd46436b0d121a7c96c37e166103b4", "price_changes": [{"asset_id": "48325180813773997762337012603425087662105904105229463158116317479132765545801", "price": "0.927", "size": "20", "side": "BUY", "hash": "964b91ef86f229c12ddffff6bb70c448c0068cc6", "best_bid": "0.989", "best_ask": "0.998"}, {"asset_id": "65341950601583802479848929397121491003949963027873255906537010617800365051709", "price": "0.073", "size": "20", "side": "SELL", "hash": "32fd6a8b99c55799bda11c9df38b7862368d42d0", "best_bid": "0.002", "best_ask": "0.011"}], "timestamp": "1769384239018", "event_type": "price_change"}}
{"_local_timestamp": "2026-01-25T23:37:19.182853+00:00", "data": {"market": "0x37d7295a17db461c15867862afe90bfad6cd46436b0d121a7c96c37e166103b4", "price_changes": [{"asset_id": "48325180813773997762337012603425087662105904105229463158116317479132765545801", "price": "0.926", "size": "0", "side": "BUY", "hash": "fd0e1d03e58f6ef9daf55b0b5f71ca3f240b6d16", "best_bid": "0.989", "best_ask": "0.998"}, {"asset_id": "65341950601583802479848929397121491003949963027873255906537010617800365051709", "price": "0.074", "size": "0", "side": "SELL", "hash": "a81f24551d6eb7d3900936fcaaea744b84164600", "best_bid": "0.002", "best_ask": "0.011"}], "timestamp": "1769384239104", "event_type": "price_change"}}
{"_local_timestamp": "2026-01-25T23:37:19.247076+00:00", "data": {"market": "0x37d7295a17db461c15867862afe90bfad6cd46436b0d121a7c96c37e166103b4", "price_changes": [{"asset_id": "48325180813773997762337012603425087662105904105229463158116317479132765545801", "price": "0.931", "size": "150", "side": "BUY", "hash": "838823a9ea1ada81605afaf5a2041be1078a7797", "best_bid": "0.989", "best_ask": "0.998"}, {"asset_id": "65341950601583802479848929397121491003949963027873255906537010617800365051709", "price": "0.069", "size": "150", "side": "SELL", "hash": "869fbbbd3bcb248d043cf1b2f65a54df4ef3479b", "best_bid": "0.002", "best_ask": "0.011"}], "timestamp": "1769384239161", "event_type": "price_change"}}
{"_local_timestamp": "2026-01-25T23:37:22.909209+00:00", "data": {"market": "0x37d7295a17db461c15867862afe90bfad6cd46436b0d121a7c96c37e166103b4", "price_changes": [{"asset_id": "48325180813773997762337012603425087662105904105229463158116317479132765545801", "price": "0.927", "size": "0", "side": "BUY", "hash": "066a0be0f724a4e415d39de5943d4477816b52af", "best_bid": "0.989", "best_ask": "0.998"}, {"asset_id": "65341950601583802479848929397121491003949963027873255906537010617800365051709", "price": "0.073", "size": "0", "side": "SELL", "hash": "b20e9c97f66b8f977ef43a319b2d8c9323b7d18f", "best_bid": "0.002", "best_ask": "0.011"}], "timestamp": "1769384242833", "event_type": "price_change"}}
{"_local_timestamp": "2026-01-25T23:37:22.942818+00:00", "data": {"market": "0x37d7295a17db461c15867862afe90bfad6cd46436b0d121a7c96c37e166103b4", "price_changes": [{"asset_id": "48325180813773997762337012603425087662105904105229463158116317479132765545801", "price": "0.921", "size": "20", "side": "BUY", "hash": "febd2764432975fb09b0240ce0dbe7bd997263b5", "best_bid": "0.989", "best_ask": "0.998"}, {"asset_id": "65341950601583802479848929397121491003949963027873255906537010617800365051709", "price": "0.079", "size": "20", "side": "SELL", "hash": "7f7e48ab03479e945982da4f5b4e407e3af68110", "best_bid": "0.002", "best_ask": "0.011"}], "timestamp": "1769384242868", "event_type": "price_change"}}
{"_local_timestamp": "2026-01-25T23:37:23.033605+00:00", "data": {"market": "0x37d7295a17db461c15867862afe90bfad6cd46436b0d121a7c96c37e166103b4", "price_changes": [{"asset_id": "48325180813773997762337012603425087662105904105229463158116317479132765545801", "price": "0.931", "size": "0", "side": "BUY", "hash": "6eb82315a0838c83a26b74cc2ac1a46826b10947", "best_bid": "0.989", "best_ask": "0.998"}, {"asset_id": "65341950601583802479848929397121491003949963027873255906537010617800365051709", "price": "0.069", "size": "0", "side": "SELL", "hash": "8bc54a7f150763029529e71fe20516732125a018", "best_bid": "0.002", "best_ask": "0.011"}], "timestamp": "1769384242963", "event_type": "price_change"}}
{"_local_timestamp": "2026-01-25T23:37:23.064670+00:00", "data": {"market": "0x37d7295a17db461c15867862afe90bfad6cd46436b0d121a7c96c37e166103b4", "price_changes": [{"asset_id": "48325180813773997762337012603425087662105904105229463158116317479132765545801", "price": "0.926", "size": "400", "side": "BUY", "hash": "ee6c8f3aa6ba11c441f0a978c8825b579cb4babf", "best_bid": "0.989", "best_ask": "0.998"}, {"asset_id": "65341950601583802479848929397121491003949963027873255906537010617800365051709", "price": "0.074", "size": "400", "side": "SELL", "hash": "67970d2c6c7e1304e20da841a24bcb882b0fa44e", "best_bid": "0.002", "best_ask": "0.011"}], "timestamp": "1769384242990", "event_type": "price_change"}}
{"_local_timestamp": "2026-01-25T23:37:25.345694+00:00", "data": {"market": "0x37d7295a17db461c15867862afe90bfad6cd46436b0d121a7c96c37e166103b4", "price_changes": [{"asset_id": "48325180813773997762337012603425087662105904105229463158116317479132765545801", "price": "0.921", "size": "0", "side": "BUY", "hash": "fdbcee60278dbef83307ed9f85a18b0056501e9e", "best_bid": "0.989", "best_ask": "0.998"}, {"asset_id": "65341950601583802479848929397121491003949963027873255906537010617800365051709", "price": "0.079", "size": "0", "side": "SELL", "hash": "52604fc2aa977a31b429b1e8f859368b029fc3a9", "best_bid": "0.002", "best_ask": "0.011"}], "timestamp": "1769384245273", "event_type": "price_change"}}
{"_local_timestamp": "2026-01-25T23:37:25.369747+00:00", "data": {"market": "0x37d7295a17db461c15867862afe90bfad6cd46436b0d121a7c96c37e166103b4", "price_changes": [{"asset_id": "48325180813773997762337012603425087662105904105229463158116317479132765545801", "price": "0.927", "size": "20", "side": "BUY", "hash": "b1b0a7977877715fee559dbc426df968ff65c7b8", "best_bid": "0.989", "best_ask": "0.998"}, {"asset_id": "65341950601583802479848929397121491003949963027873255906537010617800365051709", "price": "0.073", "size": "20", "side": "SELL", "hash": "4de0762ddc0ed0a005e8d7011a7e5c2690052e27", "best_bid": "0.002", "best_ask": "0.011"}], "timestamp": "1769384245304", "event_type": "price_change"}}
{"_local_timestamp": "2026-01-25T23:37:25.460302+00:00", "data": {"market": "0x37d7295a17db461c15867862afe90bfad6cd46436b0d121a7c96c37e166103b4", "price_changes": [{"asset_id": "48325180813773997762337012603425087662105904105229463158116317479132765545801", "price": "0.926", "size": "0", "side": "BUY", "hash": "bf3ff2f5455869c5a7cd54e67742d388ebc3d10a", "best_bid": "0.989", "best_ask": "0.998"}, {"asset_id": "65341950601583802479848929397121491003949963027873255906537010617800365051709", "price": "0.074", "size": "0", "side": "SELL", "hash": "fbfa32d164e517db9303f7f19901851c54e8eff9", "best_bid": "0.002", "best_ask": "0.011"}], "timestamp": "1769384245387", "event_type": "price_change"}}
{"_local_timestamp": "2026-01-25T23:37:25.479796+00:00", "data": {"market": "0x37d7295a17db461c15867862afe90bfad6cd46436b0d121a7c96c37e166103b4", "price_changes": [{"asset_id": "48325180813773997762337012603425087662105904105229463158116317479132765545801", "price": "0.931", "size": "150", "side": "BUY", "hash": "c7cc1f7b489f0cfaa86217799380a30d7b19ae96", "best_bid": "0.989", "best_ask": "0.998"}, {"asset_id": "65341950601583802479848929397121491003949963027873255906537010617800365051709", "price": "0.069", "size": "150", "side": "SELL", "hash": "b98c598b5dd2569895d7c6dfb009e6ff7eb8e057", "best_bid": "0.002", "best_ask": "0.011"}], "timestamp": "1769384245413", "event_type": "price_change"}}
