{"_local_timestamp": "2026-01-25T23:33:20.073651+00:00", "data": [{"market": "0xb8b5349814450b8bba2ecdda2eeb9f48bd3c795bfb858bedf7a383712b877743", "asset_id": "99954012845363784422380244269243499000117818896422626871954380344984773420508", "timestamp": "1769383938418", "hash": "1832bdaf83e7a6d2f228586de1a4b1afb13c7df7", "bids": [{"price": "0.01", "size": "10006.71"}, {"price": "0.02", "size": "261.51"}, {"price": "0.03", "size": "40.1"}, {"price": "0.04", "size": "20"}, {"price": "0.06", "size": "125.9"}, {"price": "0.07", "size": "411"}, {"price": "0.08", "size": "63.85"}, {"price": "0.09", "size": "5.55"}, {"price": "0.1", "size": "484"}, {"price": "0.11", "size": "46"}], "asks": [{"price": "0.99", "size": "510010.03"}, {"price": "0.98", "size": "10.37"}, {"price": "0.95", "size": "15040"}, {"price": "0.94", "size": "233"}, {"price": "0.93", "size": "2284"}, {"price": "0.92", "size": "94.99"}, {"price": "0.91", "size": "8.24"}, {"price": "0.87", "size": "103"}, {"price": "0.22", "size": "12.5"}, {"price": "0.21", "size": "7.62"}], "event_type": "book", "last_trade_price": ""}, {"market": "0xb8b5349814450b8bba2ecdda2eeb9f48bd3c795bfb858bedf7a383712b877743", "asset_id": "18131974965869813060047290511060211742274666573066200470724290584768041211203", "timestamp": "1769383938418", "hash": "6690f3c8b984eb829e55fd8f55e9fbe0b5b0a8c7", "bids": [{"price": "0.01", "size": "510010.03"}, {"price": "0.02", "size": "10.37"}, {"price": "0.05", "size": "15040"}, {"price": "0.06", "size": "233"}, {"price": "0.07", "size": "2284"}, {"price": "0.08", "size": "94.99"}, {"price": "0.09", "size": "8.24"}, {"price": "0.13", "size": "103"}, {"price": "0.78", "size": "12.5"}, {"price": "0.79", "size": "7.62"}], "asks": [{"price": "0.99", "size": "10006.71"}, {"price": "0.98", "size": "261.51"}, {"price": "0.97", "size": "40.1"}, {"price": "0.96", "size": "20"}, {"price": "0.94", "size": "125.9"}, {"price": "0.93", "size": "411"}, {"price": "0.92", "size": "63.85"}, {"price": "0.91", "size": "5.55"}, {"price": "0.9", "size": "484"}, {"price": "0.89", "size": "46"}], "event_type": "book", "last_trade_price": ""}, {"market": "0x460d3942d385cdeda20519c0c5ad804ae48dc18efc9a82e1f1be87a29e69adb3", "asset_id": "75079868093228966915894372964099062660587490227046756021175661325867722540666", "timestamp": "1769383777916", "hash": "d2282c172b202c355e73dde29f6ba96654b9868e", "bids": [{"price": "0.01", "size": "8.21"}, {"price": "0.02", "size": "54"}, {"price": "0.03", "size": "30.59"}, {"price": "0.1", "size": "503.88"}, {"price": "0.11", "size": "726.84"}], "asks": [{"price": "0.99", "size": "510008.22"}, {"price": "0.98", "size": "5007.74"}, {"price": "0.97", "size": "20010"}, {"price": "0.96", "size": "3756.25"}, {"price": "0.95", "size": "30"}, {"price": "0.94", "size": "33"}, {"price": "0.93", "size": "5.74"}, {"price": "0.91", "size": "400"}, {"price": "0.9", "size": "3000"}, {"price": "0.87", "size": "261.53"}, {"price": "0.86", "size": "8.22"}, {"price": "0.82", "size": "177.77"}, {"price": "0.81", "size": "842"}, {"price": "0.78", "size": "127.27"}, {"price": "0.74", "size": "2000"}, {"price": "0.73", "size": "1650.29"}, {"price": "0.69", "size": "77.41"}, {"price": "0.68", "size": "38"}, {"price": "0.64", "size": "55.55"}, {"price": "0.63", "size": "25"}, {"price": "0.21", "size": "9.67"}, {"price": "0.16", "size": "505.59"}], "event_type": "book", "last_trade_price": ""}, {"market": "0x460d3942d385cdeda20519c0c5ad804ae48dc18efc9a82e1f1be87a29e69adb3", "asset_id": "37327444084035787269854507880662541101916131726641992937390933740081521292625", "timestamp": "1769383777916", "hash": "00464e8a0845815e13048af663666d32528aa0c4", "bids": [{"price": "0.01", "size": "510008.22"}, {"price": "0.02", "size": "5007.74"}, {"price": "0.03", "size": "20010"}, {"price": "0.04", "size": "3756.25"}, {"price": "0.05", "size": "30"}, {"price": "0.06", "size": "33"}, {"price": "0.07", "size": "5.74"}, {"price": "0.09", "size": "400"}, {"price": "0.1", "size": "3000"}, {"price": "0.13", "size": "261.53"}, {"price": "0.14", "size": "8.22"}, {"price": "0.18", "size": "177.77"}, {"price": "0.19", "size": "842"}, {"price": "0.22", "size": "127.27"}, {"price": "0.26", "size": "2000"}, {"price": "0.27", "size": "1650.29"}, {"price": "0.31", "size": "77.41"}, {"price": "0.32", "size": "38"}, {"price": "0.36", "size": "55.55"}, {"price": "0.37", "size": "25"}, {"price": "0.79", "size": "9.67"}, {"price": "0.84", "size": "505.59"}], "asks": [{"price": "0.99", "size": "8.21"}, {"price": "0.98", "size": "54"}, {"price": "0.97", "size": "30.59"}, {"price": "0.9", "size": "503.88"}, {"price": "0.89", "size": "726.84"}], "event_type": "book", "last_trade_price": ""}]}
{"_local_timestamp": "2026-01-25T23:34:18.302230+00:00", "data": {"market": "0xb8b5349814450b8bba2ecdda2eeb9f48bd3c795bfb858bedf7a383712b877743", "price_changes": [{"asset_id": "99954012845363784422380244269243499000117818896422626871954380344984773420508", "price": "0.87", "size": "0", "side": "SELL", "hash": "4564c9972169047eace09aafe3c6913a27f56216", "best_bid": "0.11", "best_ask": "0.21"}, {"asset_id": "18131974965869813060047290511060211742274666573066200470724290584768041211203", "price": "0.13", "size": "0", "side": "BUY", "hash": "7eddfb792eac14c7f2540735e53ae6f11b670245", "best_bid": "0.79", "best_ask": "0.89"}], "timestamp": "1769384058046", "event_type": "price_change"}}
{"_local_timestamp": "2026-01-25T23:34:18.809438+00:00", "data": {"market": "0xb8b5349814450b8bba2ecdda2eeb9f48bd3c795bfb858bedf7a383712b877743", "price_changes": [{"asset_id": "99954012845363784422380244269243499000117818896422626871954380344984773420508", "price": "0.91", "size": "111.24", "side": "SELL", "hash": "61173938848324ff901f0355d2b3b8e874a9fcad", "best_bid": "0.11", "best_ask": "0.21"}, {"asset_id": "18131974965869813060047290511060211742274666573066200470724290584768041211203", "price": "0.09", "size": "111.24", "side": "BUY", "hash": "8eb6980bda1af1d67cb15c9492325f9f1ab8e06e", "best_bid": "0.79", "best_ask": "0.89"}], "timestamp": "1769384058552", "event_type": "price_change"}}
{"_local_timestamp": "2026-01-25T23:34:19.076399+00:00", "data": {"market": "0xb8b5349814450b8bba2ecdda2eeb9f48bd3c795bfb858bedf7a383712b877743", "price_changes": [{"asset_id": "99954012845363784422380244269243499000117818896422626871954380344984773420508", "price": "0.92", "size": "5", "side": "SELL", "hash": "5ef16bcf08829174a78454654272440510df3d7d", "best_bid": "0.11", "best_ask": "0.21"}, {"asset_id": "18131974965869813060047290511060211742274666573066200470724290584768041211203", "price": "0.08", "size": "5", "side": "BUY", "hash": "79c84fbf094bd46e3ed9bf4c488bf5d049ed02a5", "best_bid": "0.79", "best_ask": "0.89"}], "timestamp": "1769384058835", "event_type": "price_change"}}
{"_local_timestamp": "2026-01-25T23:34:19.336380+00:00", "data": {"market": "0xb8b5349814450b8bba2ecdda2eeb9f48bd3c795bfb858bedf7a383712b877743", "price_changes": [{"asset_id": "99954012845363784422380244269243499000117818896422626871954380344984773420508", "price": "0.9", "size": "89.99", "side": "SELL", "hash": "890aa1a3e9c8a5ad14f5fd2dbb873ff2c4d8f345", "best_bid": "0.11", "best_ask": "0.21"}, {"asset_id": "18131974965869813060047290511060211742274666573066200470724290584768041211203", "price": "0.1", "size": "89.99", "side": "BUY", "hash": "c0aa5badb03b6976043de627b8788b1ee2af5a91", "best_bid": "0.79", "best_ask": "0.89"}], "timestamp": "1769384059113", "event_type": "price_change"}}
{"_local_timestamp": "2026-01-25T23:34:20.026519+00:00", "data": {"market": "0x460d3942d385cdeda20519c0c5ad804ae48dc18efc9a82e1f1be87a29e69adb3", "price_changes": [{"asset_id": "37327444084035787269854507880662541101916131726641992937390933740081521292625", "price": "0.27", "size": "96.29", "side": "BUY", "hash": "8e0dee332f98424f5eefb207043f3b9e05035506", "best_bid": "0.84", "best_ask": "0.89"}, {"asset_id": "75079868093228966915894372964099062660587490227046756021175661325867722540666", "price": "0.73", "size": "96.29", "side": "SELL", "hash": "2b70d405d1d801f165710631ef817a8719ea9fa8", "best_bid": "0.11", "best_ask": "0.16"}], "timestamp": "1769384059761", "event_type": "price_change"}}
{"_local_timestamp": "2026-01-25T23:34:25.744223+00:00", "data": {"market": "0xb8b5349814450b8bba2ecdda2eeb9f48bd3c795bfb858bedf7a383712b877743", "price_changes": [{"asset_id": "99954012845363784422380244269243499000117818896422626871954380344984773420508", "price": "0.03", "size": "12.07", "side": "BUY", "hash": "699cf26d9e0ce37fb0aa883ca7d4e4c3cf07e0d0", "best_bid": "0.11", "best_ask": "0.21"}, {"asset_id": "18131974965869813060047290511060211742274666573066200470724290584768041211203", "price": "0.97", "size": "12.07", "side": "SELL", "hash": "062cd064f6b448e948869fd6e0215b2e42091054", "best_bid": "0.79", "best_ask": "0.89"}], "timestamp": "1769384065503", "event_type": "price_change"}}
{"_local_timestamp": "2026-01-25T23:34:26.073928+00:00", "data": {"market": "0xb8b5349814450b8bba2ecdda2eeb9f48bd3c795bfb858bedf7a383712b877743", "price_changes": [{"asset_id": "99954012845363784422380244269243499000117818896422626871954380344984773420508", "price": "0.05", "size": "16.82", "side": "BUY", "hash": "487a0676a18cf4e272174b11261f9c5a25e4706f", "best_bid": "0.11", "best_ask": "0.21"}, {"asset_id": "18131974965869813060047290511060211742274666573066200470724290584768041211203", "price": "0.95", "size": "16.82", "side": "SELL", "hash": "bbb112ae8e407d69879708ebf6141acd6078614a", "best_bid": "0.79", "best_ask": "0.89"}], "timestamp": "1769384065818", "event_type": "price_change"}}
{"_local_timestamp": "2026-01-25T23:34:26.446508+00:00", "data": {"market": "0xb8b5349814450b8bba2ecdda2eeb9f48bd3c795bfb858bedf7a383712b877743", "price_changes": [{"asset_id": "99954012845363784422380244269243499000117818896422626871954380344984773420508", "price": "0.04", "size": "0", "side": "BUY", "hash": "011f860047beba3269f0845a423e918f5537a377", "best_bid": "0.11", "best_ask": "0.21"}, {"asset_id": "18131974965869813060047290511060211742274666573066200470724290584768041211203", "price": "0.96", "size": "0", "side": "SELL", "hash": "958b5d30ef2026752a8c7bdb62b156cc9d2ce8f9", "best_bid": "0.79", "best_ask": "0.89"}], "timestamp": "1769384066203", "event_type": "price_change"}}
{"_local_timestamp": "2026-01-25T23:34:26.507528+00:00", "data": {"market": "0xb8b5349814450b8bba2ecdda2eeb9f48bd3c795bfb858bedf7a383712b877743", "price_changes": [{"asset_id": "99954012845363784422380244269243499000117818896422626871954380344984773420508", "price": "0.06", "size": "145.9", "side": "BUY", "hash": "7408709a342779be3a71016cc5e9f05caa07b72d", "best_bid": "0.11", "best_ask": "0.21"}, {"asset_id": "18131974965869813060047290511060211742274666573066200470724290584768041211203", "price": "0.94", "size": "145.9", "side": "SELL", "hash": "1bb9db564ec0d29e45c35383f1f45f455733e787", "best_bid": "0.79", "best_ask": "0.89"}], "timestamp": "1769384066236", "event_type": "price_change"}}
{"_local_timestamp": "2026-01-25T23:34:47.980952+00:00", "data": {"market": "0xb8b5349814450b8bba2ecdda2eeb9f48bd3c795bfb858bedf7a383712b877743", "price_changes": [{"asset_id": "18131974965869813060047290511060211742274666573066200470724290584768041211203", "price": "0.09", "size": "103", "side": "BUY", "hash": "740df6ba162ff6ec106dbb0b7791db4f801dc2a1", "best_bid": "0.79", "best_ask": "0.89"}, {"asset_id": "99954012845363784422380244269243499000117818896422626871954380344984773420508", "price": "0.91", "size": "103", "side": "SELL", "hash": "8826a5075953a718b4112f10809537bd176c28ee", "best_bid": "0.11", "best_ask": "0.21"}], "timestamp": "1769384087911", "event_type": "price_change"}}
{"_local_timestamp": "2026-01-25T23:34:47.981943+00:00", "data": {"market": "0x460d3942d385cdeda20519c0c5ad804ae48dc18efc9a82e1f1be87a29e69adb3", "price_changes": [{"asset_id": "75079868093228966915894372964099062660587490227046756021175661325867722540666", "price": "0.03", "size": "14.56", "side": "BUY", "hash": "858e2f1ca1aaed9851e2a6c1ca45376299579f32", "best_bid": "0.11", "best_ask": "0.16"}, {"asset_id": "37327444084035787269854507880662541101916131726641992937390933740081521292625", "price": "0.97", "size": "14.56", "side": "SELL", "hash": "e9b7b147f042dfbcece7ca7d8a5f6fee2f0f6a59", "best_bid": "0.84", "best_ask": "0.89"}], "timestamp": "1769384087911", "event_type": "price_change"}}
{"_local_timestamp": "2026-01-25T23:34:48.348619+00:00", "data": {"market": "0x460d3942d385cdeda20519c0c5ad804ae48dc18efc9a82e1f1be87a29e69adb3", "price_changes": [{"asset_id": "75079868093228966915894372964099062660587490227046756021175661325867722540666", "price": "0.03", "size": "30.59", "side": "BUY", "hash": "a6809fcd606c5f4724202330efd9da3d8b34e65b", "best_bid": "0.11", "best_ask": "0.16"}, {"asset_id": "37327444084035787269854507880662541101916131726641992937390933740081521292625", "price": "0.97", "size": "30.59", "side": "SELL", "hash": "caf2f431bc38f40ea69dd25a3b9a5eb0f8de0eae", "best_bid": "0.84", "best_ask": "0.89"}], "timestamp": "1769384088275", "event_type": "price_change"}}
{"_local_timestamp": "2026-01-25T23:34:48.349265+00:00", "data": {"market": "0xb8b5349814450b8bba2ecdda2eeb9f48bd3c795bfb858bedf7a383712b877743", "price_changes": [{"asset_id": "18131974965869813060047290511060211742274666573066200470724290584768041211203", "price": "0.11", "size": "5.41", "side": "BUY", "hash": "673bc0e306c76ba8424802f63d5353e67b906e05", "best_bid": "0.79", "best_ask": "0.89"}, {"asset_id": "99954012845363784422380244269243499000117818896422626871954380344984773420508", "price": "0.89", "size": "5.41", "side": "SELL", "hash": "ff019c8d82cf964db08ed41fb3f4bb2c86817674", "best_bid": "0.11", "best_ask": "0.21"}], "timestamp": "1769384088275", "event_type": "price_change"}}
{"_local_timestamp": "2026-01-25T23:34:48.349681+00:00", "data": {"market": "0xb8b5349814450b8bba2ecdda2eeb9f48bd3c795bfb858bedf7a383712b877743", "price_changes": [{"asset_id": "18131974965869813060047290511060211742274666573066200470724290584768041211203", "price": "0.02", "size": "17.72", "side": "BUY", "hash": "8bc0953090936620bfd5a82666bccd07b64b9a06", "best_bid": "0.79", "best_ask": "0.89"}, {"asset_id": "99954012845363784422380244269243499000117818896422626871954380344984773420508", "price": "0.98", "size": "17.72", "side": "SELL", "hash": "d19c8d2fdf0d69f6f7d99c8eb0c13b0429e0a979", "best_bid": "0.11", "best_ask": "0.21"}], "timestamp": "1769384088276", "event_type": "price_change"}}
{"_local_timestamp": "2026-01-25T23:35:18.263186+00:00", "data": {"market": "0xb8b5349814450b8bba2ecdda2eeb9f48bd3c795bfb858bedf7a383712b877743", "price_changes": [{"asset_id": "99954012845363784422380244269243499000117818896422626871954380344984773420508", "price": "0.91", "size": "0", "side": "SELL", "hash": "c7a6ed4bafad4db3df47aacf308a684d0561e76d", "best_bid": "0.11", "best_ask": "0.21"}, {"asset_id": "18131974965869813060047290511060211742274666573066200470724290584768041211203", "price": "0.09", "size": "0", "side": "BUY", "hash": "f0fbe08579cbad41ebcdb84b11a47a74679d0446", "best_bid": "0.79", "best_ask": "0.89"}], "timestamp": "1769384118163", "event_type": "price_change"}}
{"_local_timestamp": "2026-01-25T23:35:18.722915+00:00", "data": {"market": "0xb8b5349814450b8bba2ecdda2eeb9f48bd3c795bfb858bedf7a383712b877743", "price_changes": [{"asset_id": "99954012845363784422380244269243499000117818896422626871954380344984773420508", "price": "0.89", "size": "108.41", "side": "SELL", "hash": "ab5b2e9bc74cdaacfcf091cf0e8c1ffb06d7c8e9", "best_bid": "0.11", "best_ask": "0.21"}, {"asset_id": "18131974965869813060047290511060211742274666573066200470724290584768041211203", "price": "0.11", "size": "108.41", "side": "BUY", "hash": "5061d87715f33ade158c29fb08c65b0314eb76a9", "best_bid": "0.79", "best_ask": "0.89"}], "timestamp": "1769384118640", "event_type": "price_change"}}
{"_local_timestamp": "2026-01-25T23:35:18.835195+00:00", "data": {"market": "0xb8b5349814450b8bba2ecdda2eeb9f48bd3c795bfb858bedf7a383712b877743", "price_changes": [{"asset_id": "99954012845363784422380244269243499000117818896422626871954380344984773420508", "price": "0.9", "size": "0", "side": "SELL", "hash": "da9c7a373ce26b37abfacc0d5cf9bd0585991dab", "best_bid": "0.11", "best_ask": "0.21"}, {"asset_id": "18131974965869813060047290511060211742274666573066200470724290584768041211203", "price": "0.1", "size": "0", "side": "BUY", "hash": "23d05d7b24bd3411e65f8d8c8de207727810961d", "best_bid": "0.79", "best_ask": "0.89"}], "timestamp": "1769384118761", "event_type": "price_change"}}
{"_local_timestamp": "2026-01-25T23:35:19.145420+00:00", "data": {"market": "0xb8b5349814450b8bba2ecdda2eeb9f48bd3c795bfb858bedf7a383712b877743", "price_changes": [{"asset_id": "99954012845363784422380244269243499000117818896422626871954380344984773420508", "price": "0.92", "size": "94.99", "side": "SELL", "hash": "957e06f2a8da36579d58ffe7ad1187808d741ce8", "best_bid": "0.11", "best_ask": "0.21"}, {"asset_id": "18131974965869813060047290511060211742274666573066200470724290584768041211203", "price": "0.08", "size": "94.99", "side": "BUY", "hash": "ef8380951f8cd759ccbda4c6aff8c749eb3aa6b2", "best_bid": "0.79", "best_ask": "0.89"}], "timestamp": "1769384119065", "event_type": "price_change"}}
{"_local_timestamp": "2026-01-25T23:35:19.397983+00:00", "data": {"market": "0xb8b5349814450b8bba2ecdda2eeb9f48bd3c795bfb858bedf7a383712b877743", "price_changes": [{"asset_id": "99954012845363784422380244269243499000117818896422626871954380344984773420508", "price": "0.92", "size": "5", "side": "SELL", "hash": "9080f2178b97d10de9b4a9c5d4233ffae4979679", "best_bid": "0.11", "best_ask": "0.21"}, {"asset_id": "18131974965869813060047290511060211742274666573066200470724290584768041211203", "price": "0.08", "size": "5", "side": "BUY", "hash": "e5cda3ebde5f5325a7731f220a459eccd61c74da", "best_bid": "0.79", "best_ask": "0.89"}], "timestamp": "1769384119332", "event_type": "price_change"}}
{"_local_timestamp": "2026-01-25T23:35:19.655447+00:00", "data": {"market": "0xb8b5349814450b8bba2ecdda2eeb9f48bd3c795bfb858bedf7a383712b877743", "price_changes": [{"asset_id": "99954012845363784422380244269243499000117818896422626871954380344984773420508", "price": "0.88", "size": "89.99", "side": "SELL", "hash": "ecdf4d806fe8f4b50edebf99095edcd2ab848805", "best_bid": "0.11", "best_ask": "0.21"}, {"asset_id": "18131974965869813060047290511060211742274666573066200470724290584768041211203", "price": "0.12", "size": "89.99", "side": "BUY", "hash": "ed34747139fd418226fd15a8bcea3f4e11955b9a", "best_bid": "0.79", "best_ask": "0.89"}], "timestamp": "1769384119582", "event_type": "price_change"}}
{"_local_timestamp": "2026-01-25T23:36:59.134704+00:00", "data": {"market": "0x460d3942d385cdeda20519c0c5ad804ae48dc18efc9a82e1f1be87a29e69adb3", "price_changes": [{"asset_id": "37327444084035787269854507880662541101916131726641992937390933740081521292625", "price": "0.27", "size": "1650.29", "side": "BUY", "hash": "c87d222df90a8310c14a4f1b84242f68c55f2384", "best_bid": "0.84", "best_ask": "0.89"}, {"asset_id": "75079868093228966915894372964099062660587490227046756021175661325867722540666", "price": "0.73", "size": "1650.29", "side": "SELL", "hash": "70adeefc8a8d7c8872b2922cd68156c898ce9070", "best_bid": "0.11", "best_ask": "0.16"}], "timestamp": "1769384219017", "event_type": "price_change"}}
{"_local_timestamp": "2026-01-25T23:37:18.124218+00:00", "data": {"market": "0xb8b5349814450b8bba2ecdda2eeb9f48bd3c795bfb858bedf7a383712b877743", "price_changes": [{"asset_id": "99954012845363784422380244269243499000117818896422626871954380344984773420508", "price": "0.89", "size": "5.41", "side": "SELL", "hash": "5268e95c40b6193002c8bbfc4f131dc42eaf6fa8", "best_bid": "0.11", "best_ask": "0.21"}, {"asset_id": "18131974965869813060047290511060211742274666573066200470724290584768041211203", "price": "0.11", "size": "5.41", "side": "BUY", "hash": "93001ccc8cfba7bab4fcfcfa104492fdbaeaf049", "best_bid": "0.79", "best_ask": "0.89"}], "timestamp": "1769384238015", "event_type": "price_change"}}
{"_local_timestamp": "2026-01-25T23:37:18.318521+00:00", "data": {"market": "0xb8b5349814450b8bba2ecdda2eeb9f48bd3c795bfb858bedf7a383712b877743", "price_changes": [{"asset_id": "99954012845363784422380244269243499000117818896422626871954380344984773420508", "price": "0.88", "size": "0", "side": "SELL", "hash": "db41903d3e908c50d782100507de7d65722fc6fa", "best_bid": "0.11", "best_ask": "0.21"}, {"asset_id": "18131974965869813060047290511060211742274666573066200470724290584768041211203", "price": "0.12", "size": "0", "side": "BUY", "hash": "d2a15d5928651227e61772eacb6c00327ef94db1", "best_bid": "0.79", "best_ask": "0.89"}], "timestamp": "1769384238241", "event_type": "price_change"}}
{"_local_timestamp": "2026-01-25T23:37:18.560531+00:00", "data": {"market": "0xb8b5349814450b8bba2ecdda2eeb9f48bd3c795bfb858bedf7a383712b877743", "price_changes": [{"asset_id": "99954012845363784422380244269243499000117818896422626871954380344984773420508", "price": "0.87", "size": "103", "side": "SELL", "hash": "1234929365b4a65effc66dac08cb415d480fadc9", "best_bid": "0.11", "best_ask": "0.21"}, {"asset_id": "18131974965869813060047290511060211742274666573066200470724290584768041211203", "price": "0.13", "size": "103", "side": "BUY", "hash": "f8928971de7b2ed20ed0742a62444181284a5d7f", "best_bid": "0.79", "best_ask": "0.89"}], "timestamp": "1769384238490", "event_type": "price_change"}}
{"_local_timestamp": "2026-01-25T23:37:18.564971+00:00", "data": {"market": "0xb8b5349814450b8bba2ecdda2eeb9f48bd3c795bfb858bedf7a383712b877743", "price_changes": [{"asset_id": "99954012845363784422380244269243499000117818896422626871954380344984773420508", "price": "0.92", "size": "94.99", "side": "SELL", "hash": "c725c742ca7521025445c8f8c2d325f5f0112b02", "best_bid": "0.11", "best_ask": "0.21"}, {"asset_id": "18131974965869813060047290511060211742274666573066200470724290584768041211203", "price": "0.08", "size": "94.99", "side": "BUY", "hash": "32299d769cf74048a9c7c540252a3fb82bbcd4b6", "best_bid": "0.79", "best_ask": "0.89"}], "timestamp": "1769384238496", "event_type": "price_change"}}
{"_local_timestamp": "2026-01-25T23:38:17.840946+00:00", "data": {"market": "0xb8b5349814450b8bba2ecdda2eeb9f48bd3c795bfb858bedf7a383712b877743", "price_changes": [{"asset_id": "99954012845363784422380244269243499000117818896422626871954380344984773420508", "price": "0.87", "size": "0", "side": "SELL", "hash": "6fee9b73ea702bc2d610b3aaac257e38aaa44b02", "best_bid": "0.11", "best_ask": "0.21"}, {"asset_id": "18131974965869813060047290511060211742274666573066200470724290584768041211203", "price": "0.13", "size": "0", "side": "BUY", "hash": "f15e5dc213733c683e55162a0881a3a10f092567", "best_bid": "0.79", "best_ask": "0.89"}], "timestamp": "1769384297766", "event_type": "price_change"}}
{"_local_timestamp": "2026-01-25T23:38:18.306865+00:00", "data": {"market": "0xb8b5349814450b8bba2ecdda2eeb9f48bd3c795bfb858bedf7a383712b877743", "price_changes": [{"asset_id": "99954012845363784422380244269243499000117818896422626871954380344984773420508", "price": "0.91", "size": "103", "side": "SELL", "hash": "694d950632b781bd7fbfcd9570dbcc859519f057", "best_bid": "0.11", "best_ask": "0.21"}, {"asset_id": "18131974965869813060047290511060211742274666573066200470724290584768041211203", "price": "0.09", "size": "103", "side": "BUY", "hash": "d45dfe286f248fe57a6aa27644842881abbc167d", "best_bid": "0.79", "best_ask": "0.89"}], "timestamp": "1769384298231", "event_type": "price_change"}}
{"_local_timestamp": "2026-01-25T23:38:19.033172+00:00", "data": {"market": "0xb8b5349814450b8bba2ecdda2eeb9f48bd3c795bfb858bedf7a383712b877743", "price_changes": [{"asset_id": "99954012845363784422380244269243499000117818896422626871954380344984773420508", "price": "0.92", "size": "5", "side": "SELL", "hash": "9225185b02c5a8c1a12de58e0c12d6f725b78057", "best_bid": "0.11", "best_ask": "0.21"}, {"asset_id": "18131974965869813060047290511060211742274666573066200470724290584768041211203", "price": "0.08", "size": "5", "side": "BUY", "hash": "1522f6bb4c8fbe79145bbd964e7dd977ccb59f4d", "best_bid": "0.79", "best_ask": "0.89"}], "timestamp": "1769384298960", "event_type": "price_change"}}
{"_local_timestamp": "2026-01-25T23:38:19.324487+00:00", "data": {"market": "0xb8b5349814450b8bba2ecdda2eeb9f48bd3c795bfb858bedf7a383712b877743", "price_changes": [{"asset_id": "99954012845363784422380244269243499000117818896422626871954380344984773420508", "price": "0.9", "size": "89.99", "side": "SELL", "hash": "66bdf4ca9e27235f0f4fb3fdd078addad956880b", "best_bid": "0.11", "best_ask": "0.21"}, {"asset_id": "18131974965869813060047290511060211742274666573066200470724290584768041211203", "price": "0.1", "size": "89.99", "side": "BUY", "hash": "7c930efe0c59c6b04cdc3119778d4546057999a8", "best_bid": "0.79", "best_ask": "0.89"}], "timestamp": "1769384299250", "event_type": "price_change"}}
