{"_local_timestamp": "2026-01-25T23:40:30.745906+00:00", "data": [{"market": "0xc901b7ee5f6776feee0bc75349ddf15b3f1473c42e9c23fbd2c286129db2314b", "asset_id": "19480453523641651203279098233362734886683676042431995106519882319527157746915", "timestamp": "1769384332447", "hash": "074a24d7c302d97d3533859d65db74464b7992b7", "bids": [{"price": "0.001", "size": "1104251.99"}, {"price": "0.002", "size": "250"}, {"price": "0.003", "size": "400"}, {"price": "0.004", "size": "10.09"}, {"price": "0.006", "size": "200"}, {"price": "0.01", "size": "10"}, {"price": "0.011", "size": "9.09"}, {"price": "0.02", "size": "5000"}, {"price": "0.021", "size": "20700"}, {"price": "0.032", "size": "250"}, {"price": "0.033", "size": "7.29"}, {"price": "0.05", "size": "30"}, {"price": "0.051", "size": "39"}, {"price": "0.052", "size": "653.84"}, {"price": "0.08", "size": "300"}, {"price": "0.086", "size": "93.02"}, {"price": "0.087", "size": "5.51"}, {"price": "0.184", "size": "9000"}, {"price": "0.215", "size": "37.2"}, {"price": "0.216", "size": "5.2"}, {"price": "0.223", "size": "45"}, {"price": "0.249", "size": "79"}, {"price": "0.25", "size": "32"}, {"price": "0.523", "size": "218"}, {"price": "0.539", "size": "5"}, {"price": "0.54", "size": "14.81"}, {"price": "0.723", "size": "7"}, {"price": "0.823", "size": "6"}, {"price": "0.868", "size": "10"}, {"price": "0.869", "size": "25"}, {"price": "0.951", "size": "5"}, {"price": "0.953", "size": "88.28"}, {"price": "0.997", "size": "268.31"}, {"price": "0.998", "size": "413"}], "asks": [], "event_type": "book", "last_trade_price": "0.001"}, {"market": "0xc8ef5adf237853872e232fc6d66b334ea04092b9623d2c2549ab5f7edd9aeab4", "asset_id": "108812938192767854218949300916725095215503085851828138910431467866540044790765", "timestamp": "1769384157135", "hash": "0d0318d91c77a860f50e243c7600321ec47ada21", "bids": [{"price": "0.001", "size": "215.56"}], "asks": [{"price": "0.999", "size": "1102757.15"}, {"price": "0.998", "size": "250"}, {"price": "0.997", "size": "400"}, {"price": "0.996", "size": "8.67"}, {"price": "0.994", "size": "200"}, {"price": "0.99", "size": "40010"}, {"price": "0.989", "size": "5.3"}, {"price": "0.979", "size": "12700"}, {"price": "0.97", "size": "228.57"}, {"price": "0.969", "size": "7.39"}, {"price": "0.95", "size": "30"}, {"price": "0.949", "size": "39"}, {"price": "0.948", "size": "631.86"}, {"price": "0.92", "size": "85.71"}, {"price": "0.919", "size": "5.52"}, {"price": "0.885", "size": "20100"}, {"price": "0.884", "size": "59.11"}, {"price": "0.805", "size": "35.16"}, {"price": "0.804", "size": "6.19"}, {"price": "0.777", "size": "62"}, {"price": "0.759", "size": "85"}, {"price": "0.758", "size": "28.33"}, {"price": "0.477", "size": "238"}, {"price": "0.462", "size": "12.74"}, {"price": "0.461", "size": "5"}, {"price": "0.277", "size": "18"}, {"price": "0.182", "size": "25"}, {"price": "0.178", "size": "10"}, {"price": "0.177", "size": "11.27"}, {"price": "0.049", "size": "5"}, {"price": "0.048", "size": "11"}, {"price": "0.047", "size": "20"}, {"price": "0.004", "size": "70.88"}, {"price": "0.003", "size": "365.95"}], "event_type": "book", "last_trade_price": "0.001"}, {"market": "0x813140d27e876be7b8b57a9f5932f560426e5dd02370e1a6d815ce416d3c1a1e", "asset_id": "42867658785582566258165916378080823643991642521460286045794854230410783654072", "timestamp": "1769384329733", "hash": "7c90859c0ae0dd5db9c4d03ae6de898b50a1092f", "bids": [{"price": "0.001", "size": "1102850.88"}, {"price": "0.002", "size": "250"}, {"price": "0.003", "size": "406.63"}, {"price": "0.006", "size": "200"}, {"price": "0.007", "size": "10.45"}, {"price": "0.01", "size": "40010"}, {"price": "0.021", "size": "12700"}, {"price": "0.022", "size": "6.36"}, {"price": "0.029", "size": "331.03"}, {"price": "0.05", "size": "30"}, {"price": "0.051", "size": "39"}, {"price": "0.052", "size": "7.38"}, {"price": "0.065", "size": "147.69"}, {"price": "0.112", "size": "20100"}, {"price": "0.144", "size": "66.66"}, {"price": "0.145", "size": "9.46"}, {"price": "0.223", "size": "165"}, {"price": "0.228", "size": "21"}, {"price": "0.229", "size": "41.92"}, {"price": "0.523", "size": "56"}, {"price": "0.527", "size": "5"}, {"price": "0.528", "size": "18.18"}, {"price": "0.823", "size": "69"}, {"price": "0.861", "size": "10"}, {"price": "0.862", "size": "25"}, {"price": "0.951", "size": "14.83"}, {"price": "0.952", "size": "11"}, {"price": "0.953", "size": "20"}, {"price": "0.995", "size": "51.73"}, {"price": "0.996", "size": "94.84"}], "asks": [], "event_type": "book", "last_trade_price": "0.001"}, {"market": "0xe84c744708601de931a3934348a03daacbee47d7544833fbfaee03cebf2ce671", "asset_id": "805230112475689046947019657850763494702255476187914788574885178432542938422", "timestamp": "1769384325727", "hash": "6c6bcff0d0a1957df54081cd7c17d9a6be8a8805", "bids": [{"price": "0.001", "size": "1104254.51"}, {"price": "0.002", "size": "40250"}, {"price": "0.003", "size": "406.65"}, {"price": "0.006", "size": "200"}, {"price": "0.007", "size": "5.7"}, {"price": "0.01", "size": "10"}, {"price": "0.011", "size": "9.09"}, {"price": "0.03", "size": "3000"}, {"price": "0.031", "size": "221.19"}, {"price": "0.04", "size": "12700"}, {"price": "0.041", "size": "5.25"}, {"price": "0.05", "size": "30"}, {"price": "0.051", "size": "6239"}, {"price": "0.052", "size": "631.86"}, {"price": "0.08", "size": "300"}, {"price": "0.09", "size": "76.19"}, {"price": "0.091", "size": "5.34"}, {"price": "0.185", "size": "9000"}, {"price": "0.186", "size": "36.86"}, {"price": "0.219", "size": "31.31"}, {"price": "0.22", "size": "5.14"}, {"price": "0.284", "size": "24.14"}, {"price": "0.286", "size": "181"}, {"price": "0.287", "size": "5400.69"}, {"price": "0.288", "size": "400"}, {"price": "0.523", "size": "49"}, {"price": "0.526", "size": "13.03"}, {"price": "0.527", "size": "5"}, {"price": "0.819", "size": "25"}, {"price": "0.823", "size": "10"}, {"price": "0.824", "size": "11.27"}, {"price": "0.947", "size": "13"}, {"price": "0.961", "size": "182.88"}, {"price": "0.962", "size": "42.16"}], "asks": [{"price": "0.999", "size": "584"}, {"price": "0.998", "size": "115"}, {"price": "0.995", "size": "565.27"}], "event_type": "book", "last_trade_price": "0.005"}, {"market": "0xfb1f550759909794c23b00af18fca4c280055b5f9d8486be98e3d060c33ca90c", "asset_id": "20600446554033370744360342218091256733610255788772700742005074484397136026698", "timestamp": "1769384339356", "hash": "8d937c036330d35cb93623d53bbc17196d097cb0", "bids": [{"price": "0.001", "size": "1104252.03"}, {"price": "0.002", "size": "30250"}, {"price": "0.003", "size": "400"}, {"price": "0.004", "size": "8.68"}, {"price": "0.006", "size": "200"}, {"price": "0.01", "size": "10"}, {"price": "0.011", "size": "5.75"}, {"price": "0.02", "size": "5000"}, {"price": "0.021", "size": "15700"}, {"price": "0.027", "size": "444.44"}, {"price": "0.028", "size": "5.15"}, {"price": "0.05", "size": "30"}, {"price": "0.051", "size": "6539"}, {"price": "0.058", "size": "206.89"}, {"price": "0.059", "size": "8.75"}, {"price": "0.084", "size": "142.85"}, {"price": "0.086", "size": "600"}, {"price": "0.18", "size": "91"}, {"price": "0.186", "size": "10"}, {"price": "0.188", "size": "63.82"}, {"price": "0.189", "size": "6.48"}, {"price": "0.815", "size": "340"}, {"price": "0.816", "size": "10"}, {"price": "0.877", "size": "25"}, {"price": "0.878", "size": "11.27"}, {"price": "0.932", "size": "295"}, {"price": "0.948", "size": "13.33"}, {"price": "0.977", "size": "10.02"}, {"price": "0.979", "size": "313.05"}, {"price": "0.985", "size": "10.55"}, {"price": "0.986", "size": "25"}], "asks": [{"price": "0.999", "size": "625"}, {"price": "0.998", "size": "232.44"}, {"price": "0.997", "size": "388"}, {"price": "0.996", "size": "148"}], "event_type": "book", "last_trade_price": "0.002"}, {"market": "0xff54852cf4cb9c3568f795b983bc494d2e13d3f9cad41ba872a4ffd3ccb2101e", "asset_id": "96140164996170695869329923820202447276846115725253325303263315936085179713314", "timestamp": "1769384330307", "hash": "41c81d3df50935dd723dcf6629451179253f80d6", "bids": [{"price": "0.001", "size": "1104288.88"}, {"price": "0.002", "size": "257.48"}, {"price": "0.003", "size": "400"}, {"price": "0.004", "size": "60000"}, {"price": "0.005", "size": "5.93"}, {"price": "0.006", "size": "200"}, {"price": "0.01", "size": "10"}, {"price": "0.011", "size": "7.46"}, {"price": "0.027", "size": "922.22"}, {"price": "0.028", "size": "8.52"}, {"price": "0.05", "size": "30"}, {"price": "0.051", "size": "39"}, {"price": "0.056", "size": "607.14"}, {"price": "0.08", "size": "300"}, {"price": "0.081", "size": "79.1"}, {"price": "0.181", "size": "20000"}, {"price": "0.186", "size": "32.25"}, {"price": "0.187", "size": "6.53"}, {"price": "0.223", "size": "189"}, {"price": "0.224", "size": "26.78"}, {"price": "0.255", "size": "11"}, {"price": "0.256", "size": "23.43"}, {"price": "0.29", "size": "20.68"}, {"price": "0.291", "size": "6"}, {"price": "0.523", "size": "55"}, {"price": "0.524", "size": "11.45"}, {"price": "0.723", "size": "7"}, {"price": "0.823", "size": "6"}, {"price": "0.861", "size": "10"}, {"price": "0.862", "size": "25"}, {"price": "0.951", "size": "5"}, {"price": "0.952", "size": "13.33"}, {"price": "0.959", "size": "15.89"}, {"price": "0.995", "size": "58.86"}, {"price": "0.996", "size": "135.23"}], "asks": [], "event_type": "book", "last_trade_price": "0.001"}, {"market": "0x7996c5de13ddf3131cebe81e14fa25bc93e6d83383e9311fb4444d054b02bb6c", "asset_id": "35385046285095047875859550982501333940016148310175612786655121530268337331434", "timestamp": "1769384327964", "hash": "5f8aeb731373f032f2ad5d7da461b79b2a3a9045", "bids": [], "asks": [{"price": "0.999", "size": "1103304.99"}, {"price": "0.998", "size": "250"}, {"price": "0.997", "size": "166"}, {"price": "0.996", "size": "8.66"}, {"price": "0.994", "size": "83"}, {"price": "0.991", "size": "60000"}, {"price": "0.99", "size": "110"}, {"price": "0.989", "size": "7.46"}, {"price": "0.979", "size": "13000"}, {"price": "0.973", "size": "355.55"}, {"price": "0.972", "size": "5.41"}, {"price": "0.95", "size": "30"}, {"price": "0.94", "size": "200"}, {"price": "0.939", "size": "5.32"}, {"price": "0.936", "size": "750"}, {"price": "0.935", "size": "147.69"}, {"price": "0.89", "size": "300"}, {"price": "0.861", "size": "69.06"}, {"price": "0.86", "size": "9.93"}, {"price": "0.471", "size": "4000"}, {"price": "0.47", "size": "220"}, {"price": "0.469", "size": "18.07"}, {"price": "0.468", "size": "5"}, {"price": "0.376", "size": "15.38"}, {"price": "0.372", "size": "10"}, {"price": "0.371", "size": "25"}, {"price": "0.068", "size": "16.66"}, {"price": "0.005", "size": "67.36"}, {"price": "0.004", "size": "325.04"}], "event_type": "book", "last_trade_price": "0.001"}, {"market": "0x5882bfbb3333c4425fe5f17d7177d0155935ab218532e30abb3ebc29e09b0d15", "asset_id": "37022134553940218760484349283577041579348129770638687563562605588225179219348", "timestamp": "1769384357998", "hash": "8011f7be5afeafae823fd662d331d7e67d1fd162", "bids": [{"price": "0.001", "size": "1104355.07"}, {"price": "0.002", "size": "250"}, {"price": "0.003", "size": "400"}, {"price": "0.004", "size": "9.03"}, {"price": "0.006", "size": "200"}, {"price": "0.01", "size": "10"}, {"price": "0.011", "size": "8.16"}, {"price": "0.02", "size": "5000"}, {"price": "0.021", "size": "15000"}, {"price": "0.03", "size": "228.57"}, {"price": "0.031", "size": "7.11"}, {"price": "0.05", "size": "30"}, {"price": "0.051", "size": "39"}, {"price": "0.052", "size": "631.86"}, {"price": "0.079", "size": "86.79"}, {"price": "0.08", "size": "6.13"}, {"price": "0.182", "size": "12000"}, {"price": "0.209", "size": "32.8"}, {"price": "0.21", "size": "5.45"}, {"price": "0.223", "size": "88"}, {"price": "0.229", "size": "17"}, {"price": "0.23", "size": "29.81"}, {"price": "0.315", "size": "21.76"}, {"price": "0.316", "size": "6"}, {"price": "0.523", "size": "24"}, {"price": "0.524", "size": "13.08"}, {"price": "0.723", "size": "50"}, {"price": "0.823", "size": "59"}, {"price": "0.825", "size": "10"}, {"price": "0.826", "size": "11.27"}, {"price": "0.923", "size": "57"}, {"price": "0.928", "size": "44"}, {"price": "0.952", "size": "13"}, {"price": "0.997", "size": "14.54"}, {"price": "0.998", "size": "82.41"}], "asks": [{"price": "0.999", "size": "3778.8"}], "event_type": "book", "last_trade_price": "0.001"}, {"market": "0xe819c3fd02eec251efec7d90a1801554ec14fef336932c7342b333d4ae64d0a8", "asset_id": "110183118205658048480611552004818205608380030301879472767196181141473018245608", "timestamp": "1769384154426", "hash": "9b5b8fb045a76d2466bf72ccc888a50b261468f1", "bids": [{"price": "0.001", "size": "22.79"}, {"price": "0.002", "size": "161.31"}, {"price": "0.007", "size": "170.4"}, {"price": "0.008", "size": "256.6"}, {"price": "0.009", "size": "147.2"}], "asks": [{"price": "0.999", "size": "1104242.04"}, {"price": "0.998", "size": "255.14"}, {"price": "0.997", "size": "400"}, {"price": "0.996", "size": "5.11"}, {"price": "0.994", "size": "200"}, {"price": "0.993", "size": "60000"}, {"price": "0.99", "size": "10"}, {"price": "0.989", "size": "5.33"}, {"price": "0.979", "size": "13000"}, {"price": "0.97", "size": "266.66"}, {"price": "0.969", "size": "11.51"}, {"price": "0.95", "size": "30"}, {"price": "0.94", "size": "33"}, {"price": "0.939", "size": "631.14"}, {"price": "0.92", "size": "300"}, {"price": "0.892", "size": "74.07"}, {"price": "0.891", "size": "73.39"}, {"price": "0.89", "size": "14.07"}, {"price": "0.777", "size": "37"}, {"price": "0.753", "size": "9000"}, {"price": "0.752", "size": "25"}, {"price": "0.751", "size": "13"}, {"price": "0.75", "size": "32"}, {"price": "0.734", "size": "30.07"}, {"price": "0.733", "size": "7"}, {"price": "0.177", "size": "69"}, {"price": "0.171", "size": "10"}, {"price": "0.17", "size": "11.27"}, {"price": "0.09", "size": "248.63"}, {"price": "0.089", "size": "290.4"}, {"price": "0.088", "size": "25"}, {"price": "0.06", "size": "80"}, {"price": "0.059", "size": "30.64"}, {"price": "0.055", "size": "37.08"}], "event_type": "book", "last_trade_price": "0.960"}, {"market": "0x7996c5de13ddf3131cebe81e14fa25bc93e6d83383e9311fb4444d054b02bb6c", "asset_id": "81067297669492637828272330271687160515702268762196167960552103884621012706990", "timestamp": "1769384327964", "hash": "b782a585c0570e8787bd06a389fc50ecaad7617c", "bids": [{"price": "0.001", "size": "1103304.99"}, {"price": "0.002", "size": "250"}, {"price": "0.003", "size": "166"}, {"price": "0.004", "size": "8.66"}, {"price": "0.006", "size": "83"}, {"price": "0.009", "size": "60000"}, {"price": "0.01", "size": "110"}, {"price": "0.011", "size": "7.46"}, {"price": "0.021", "size": "13000"}, {"price": "0.027", "size": "355.55"}, {"price": "0.028", "size": "5.41"}, {"price": "0.05", "size": "30"}, {"price": "0.06", "size": "200"}, {"price": "0.061", "size": "5.32"}, {"price": "0.064", "size": "750"}, {"price": "0.065", "size": "147.69"}, {"price": "0.11", "size": "300"}, {"price": "0.139", "size": "69.06"}, {"price": "0.14", "size": "9.93"}, {"price": "0.529", "size": "4000"}, {"price": "0.53", "size": "220"}, {"price": "0.531", "size": "18.07"}, {"price": "0.532", "size": "5"}, {"price": "0.624", "size": "15.38"}, {"price": "0.628", "size": "10"}, {"price": "0.629", "size": "25"}, {"price": "0.932", "size": "16.66"}, {"price": "0.995", "size": "67.36"}, {"price": "0.996", "size": "325.04"}], "asks": [], "event_type": "book", "last_trade_price": "0.001"}, {"market": "0xad8e9885ec2473d0ba49c38449dfd4d18ad7c0f7a14625a24865857e18a94850", "asset_id": "6063771237142095573570898636767550587549260179390402809546741793309719810883", "timestamp": "1769384226137", "hash": "25fd34650c3382612e205543ebc7cc63cf645739", "bids": [{"price": "0.001", "size": "1102831.42"}, {"price": "0.002", "size": "250"}, {"price": "0.003", "size": "406.54"}, {"price": "0.006", "size": "200"}, {"price": "0.007", "size": "10.31"}, {"price": "0.01", "size": "10"}, {"price": "0.02", "size": "5000"}, {"price": "0.021", "size": "12700"}, {"price": "0.022", "size": "8.08"}, {"price": "0.029", "size": "275.86"}, {"price": "0.05", "size": "30"}, {"price": "0.051", "size": "39"}, {"price": "0.06", "size": "633.33"}, {"price": "0.061", "size": "9.47"}, {"price": "0.123", "size": "20100"}, {"price": "0.124", "size": "64.51"}, {"price": "0.169", "size": "220"}, {"price": "0.17", "size": "47.05"}, {"price": "0.213", "size": "46.55"}, {"price": "0.214", "size": "5.36"}, {"price": "0.5", "size": "16"}, {"price": "0.516", "size": "10"}, {"price": "0.518", "size": "25"}, {"price": "0.519", "size": "11.27"}, {"price": "0.92", "size": "200"}, {"price": "0.938", "size": "225.38"}, {"price": "0.954", "size": "100"}, {"price": "0.972", "size": "390"}, {"price": "0.98", "size": "64.7"}, {"price": "0.989", "size": "240"}, {"price": "0.991", "size": "23.96"}, {"price": "0.992", "size": "70"}], "asks": [{"price": "0.999", "size": "1169"}, {"price": "0.998", "size": "255"}, {"price": "0.997", "size": "73"}, {"price": "0.996", "size": "237.61"}], "event_type": "book", "last_trade_price": "0.004"}, {"market": "0x1dcc183b4cca17ebd95af1b94209ce345233d13a8157c1b1761b6d82722614aa", "asset_id": "34996430135377662182478828889088041580319309767069410756085253475349980098679", "timestamp": "1769384334562", "hash": "ff31a707c52ea290d3f314a730142a13c430062b", "bids": [], "asks": [{"price": "0.999", "size": "1102828.88"}, {"price": "0.998", "size": "257.48"}, {"price": "0.997", "size": "400"}, {"price": "0.996", "size": "60000"}, {"price": "0.995", "size": "5.93"}, {"price": "0.994", "size": "200"}, {"price": "0.99", "size": "10"}, {"price": "0.989", "size": "7.03"}, {"price": "0.979", "size": "12700"}, {"price": "0.974", "size": "369.23"}, {"price": "0.973", "size": "5.95"}, {"price": "0.95", "size": "30"}, {"price": "0.949", "size": "39"}, {"price": "0.939", "size": "657.37"}, {"price": "0.938", "size": "5.47"}, {"price": "0.887", "size": "30100"}, {"price": "0.856", "size": "66.66"}, {"price": "0.855", "size": "9.46"}, {"price": "0.777", "size": "45"}, {"price": "0.776", "size": "136.85"}, {"price": "0.775", "size": "21"}, {"price": "0.477", "size": "135"}, {"price": "0.444", "size": "5"}, {"price": "0.443", "size": "17.23"}, {"price": "0.177", "size": "73"}, {"price": "0.138", "size": "10"}, {"price": "0.137", "size": "25"}, {"price": "0.049", "size": "14.83"}, {"price": "0.048", "size": "11"}, {"price": "0.047", "size": "20"}, {"price": "0.005", "size": "57.52"}, {"price": "0.004", "size": "150.3"}], "event_type": "book", "last_trade_price": "0.001"}, {"market": "0xc5a5599959ff15ca3533656c16dd441304b8721162ef770db59a1d2b4862e2b8", "asset_id": "73040552226217734695850503696187376710006575449764477997853420807432098137837", "timestamp": "1769384334560", "hash": "ea0d4ed537670b23ef2f2f5a8ba636c4e1787687", "bids": [], "asks": [{"price": "0.999", "size": "1104252.99"}, {"price": "0.998", "size": "250"}, {"price": "0.997", "size": "400"}, {"price": "0.996", "size": "8.65"}, {"price": "0.994", "size": "200"}, {"price": "0.993", "size": "30000"}, {"price": "0.99", "size": "10"}, {"price": "0.989", "size": "8.75"}, {"price": "0.979", "size": "12700"}, {"price": "0.97", "size": "266.66"}, {"price": "0.969", "size": "7.79"}, {"price": "0.95", "size": "30"}, {"price": "0.949", "size": "656.86"}, {"price": "0.92", "size": "300"}, {"price": "0.916", "size": "95.23"}, {"price": "0.915", "size": "5.78"}, {"price": "0.784", "size": "12000"}, {"price": "0.783", "size": "5.16"}, {"price": "0.777", "size": "68"}, {"price": "0.776", "size": "35.71"}, {"price": "0.747", "size": "15"}, {"price": "0.746", "size": "31.49"}, {"price": "0.477", "size": "135"}, {"price": "0.436", "size": "176.18"}, {"price": "0.435", "size": "5"}, {"price": "0.177", "size": "73"}, {"price": "0.127", "size": "10"}, {"price": "0.126", "size": "25"}, {"price": "0.049", "size": "32"}, {"price": "0.048", "size": "20"}, {"price": "0.005", "size": "91.79"}, {"price": "0.004", "size": "344.51"}], "event_type": "book", "last_trade_price": ""}, {"market": "0x2c405b766a5952a1ee121519845541e3f363bbbb691748d38d596e900827333f", "asset_id": "45360012752670095623901322351652227247408888830488142163512756455139535103641", "timestamp": "1769384404367", "hash": "a20c6f2d01e09d6835945e7750cd029934e2dd77", "bids": [{"price": "0.001", "size": "1102764.25"}, {"price": "0.002", "size": "250"}, {"price": "0.003", "size": "406.63"}, {"price": "0.006", "size": "200"}, {"price": "0.007", "size": "10.45"}, {"price": "0.01", "size": "10"}, {"price": "0.02", "size": "5000"}, {"price": "0.021", "size": "20700"}, {"price": "0.022", "size": "9.6"}, {"price": "0.032", "size": "250"}, {"price": "0.05", "size": "30"}, {"price": "0.051", "size": "39"}, {"price": "0.067", "size": "619.4"}, {"price": "0.068", "size": "5.36"}, {"price": "0.128", "size": "30100"}, {"price": "0.129", "size": "62.01"}, {"price": "0.158", "size": "50.63"}, {"price": "0.159", "size": "8.3"}, {"price": "0.223", "size": "42"}, {"price": "0.233", "size": "17"}, {"price": "0.234", "size": "34.18"}, {"price": "0.523", "size": "136"}, {"price": "0.549", "size": "199.57"}, {"price": "0.55", "size": "5"}, {"price": "0.823", "size": "44"}, {"price": "0.862", "size": "10"}, {"price": "0.863", "size": "25"}, {"price": "0.951", "size": "24.71"}, {"price": "0.952", "size": "36.07"}, {"price": "0.954", "size": "7"}, {"price": "0.995", "size": "47.42"}, {"price": "0.996", "size": "217.76"}], "asks": [], "event_type": "book", "last_trade_price": "0.001"}, {"market": "0xc901b7ee5f6776feee0bc75349ddf15b3f1473c42e9c23fbd2c286129db2314b", "asset_id": "87076761959524824596667767871338783105013148144014343593959452219056943445676", "timestamp": "1769384332447", "hash": "c7adfe434b3b5fe00da2e20bf6db5f318447169a", "bids": [], "asks": [{"price": "0.999", "size": "1104251.99"}, {"price": "0.998", "size": "250"}, {"price": "0.997", "size": "400"}, {"price": "0.996", "size": "10.09"}, {"price": "0.994", "size": "200"}, {"price": "0.99", "size": "10"}, {"price": "0.989", "size": "9.09"}, {"price": "0.98", "size": "5000"}, {"price": "0.979", "size": "20700"}, {"price": "0.968", "size": "250"}, {"price": "0.967", "size": "7.29"}, {"price": "0.95", "size": "30"}, {"price": "0.949", "size": "39"}, {"price": "0.948", "size": "653.84"}, {"price": "0.92", "size": "300"}, {"price": "0.914", "size": "93.02"}, {"price": "0.913", "size": "5.51"}, {"price": "0.816", "size": "9000"}, {"price": "0.785", "size": "37.2"}, {"price": "0.784", "size": "5.2"}, {"price": "0.777", "size": "45"}, {"price": "0.751", "size": "79"}, {"price": "0.75", "size": "32"}, {"price": "0.477", "size": "218"}, {"price": "0.461", "size": "5"}, {"price": "0.46", "size": "14.81"}, {"price": "0.277", "size": "7"}, {"price": "0.177", "size": "6"}, {"price": "0.132", "size": "10"}, {"price": "0.131", "size": "25"}, {"price": "0.049", "size": "5"}, {"price": "0.047", "size": "88.28"}, {"price": "0.003", "size": "268.31"}, {"price": "0.002", "size": "413"}], "event_type": "book", "last_trade_price": "0.001"}, {"market": "0x2c405b766a5952a1ee121519845541e3f363bbbb691748d38d596e900827333f", "asset_id": "44227097530829963499576501282186404645897936156929334280113391423971987257194", "timestamp": "1769384404367", "hash": "6c1f910e05a9dd6111eb7258e30c5bd870ffbb2c", "bids": [], "asks": [{"price": "0.999", "size": "1102764.25"}, {"price": "0.998", "size": "250"}, {"price": "0.997", "size": "406.63"}, {"price": "0.994", "size": "200"}, {"price": "0.993", "size": "10.45"}, {"price": "0.99", "size": "10"}, {"price": "0.98", "size": "5000"}, {"price": "0.979", "size": "20700"}, {"price": "0.978", "size": "9.6"}, {"price": "0.968", "size": "250"}, {"price": "0.95", "size": "30"}, {"price": "0.949", "size": "39"}, {"price": "0.933", "size": "619.4"}, {"price": "0.932", "size": "5.36"}, {"price": "0.872", "size": "30100"}, {"price": "0.871", "size": "62.01"}, {"price": "0.842", "size": "50.63"}, {"price": "0.841", "size": "8.3"}, {"price": "0.777", "size": "42"}, {"price": "0.767", "size": "17"}, {"price": "0.766", "size": "34.18"}, {"price": "0.477", "size": "136"}, {"price": "0.451", "size": "199.57"}, {"price": "0.45", "size": "5"}, {"price": "0.177", "size": "44"}, {"price": "0.138", "size": "10"}, {"price": "0.137", "size": "25"}, {"price": "0.049", "size": "24.71"}, {"price": "0.048", "size": "36.07"}, {"price": "0.046", "size": "7"}, {"price": "0.005", "size": "47.42"}, {"price": "0.004", "size": "217.76"}], "event_type": "book", "last_trade_price": "0.001"}, {"market": "0x813140d27e876be7b8b57a9f5932f560426e5dd02370e1a6d815ce416d3c1a1e", "asset_id": "39110700308891033765082720771423327970968989496145639822830381828556135408196", "timestamp": "1769384329733", "hash": "82a2da7b13f2997dbdb205d04558c7686cc2e01b", "bids": [], "asks": [{"price": "0.999", "size": "1102850.88"}, {"price": "0.998", "size": "250"}, {"price": "0.997", "size": "406.63"}, {"price": "0.994", "size": "200"}, {"price": "0.993", "size": "10.45"}, {"price": "0.99", "size": "40010"}, {"price": "0.979", "size": "12700"}, {"price": "0.978", "size": "6.36"}, {"price": "0.971", "size": "331.03"}, {"price": "0.95", "size": "30"}, {"price": "0.949", "size": "39"}, {"price": "0.948", "size": "7.38"}, {"price": "0.935", "size": "147.69"}, {"price": "0.888", "size": "20100"}, {"price": "0.856", "size": "66.66"}, {"price": "0.855", "size": "9.46"}, {"price": "0.777", "size": "165"}, {"price": "0.772", "size": "21"}, {"price": "0.771", "size": "41.92"}, {"price": "0.477", "size": "56"}, {"price": "0.473", "size": "5"}, {"price": "0.472", "size": "18.18"}, {"price": "0.177", "size": "69"}, {"price": "0.139", "size": "10"}, {"price": "0.138", "size": "25"}, {"price": "0.049", "size": "14.83"}, {"price": "0.048", "size": "11"}, {"price": "0.047", "size": "20"}, {"price": "0.005", "size": "51.73"}, {"price": "0.004", "size": "94.84"}], "event_type": "book", "last_trade_price": "0.001"}, {"market": "0x34629a8e04da66f61bad2b4de18d370ca551faf79f810e04e403b841163f0e47", "asset_id": "81962021060291538332769225938832888553429136330721495433176438182361641360146", "timestamp": "1769384226137", "hash": "ee1f5d9ea99c82886cdd5db6057329f6a42a333a", "bids": [{"price": "0.001", "size": "2204247.21"}, {"price": "0.002", "size": "40250"}, {"price": "0.003", "size": "406.76"}, {"price": "0.006", "size": "200"}, {"price": "0.007", "size": "5.78"}, {"price": "0.01", "size": "10"}, {"price": "0.011", "size": "5.75"}, {"price": "0.02", "size": "5000"}, {"price": "0.021", "size": "16000"}, {"price": "0.037", "size": "185.32"}, {"price": "0.038", "size": "6.54"}, {"price": "0.05", "size": "30"}, {"price": "0.051", "size": "39"}, {"price": "0.06", "size": "700"}, {"price": "0.061", "size": "112.41"}, {"price": "0.092", "size": "74.53"}, {"price": "0.093", "size": "5.19"}, {"price": "0.11", "size": "300"}, {"price": "0.111", "size": "61.77"}, {"price": "0.213", "size": "6000"}, {"price": "0.214", "size": "32.04"}, {"price": "0.218", "size": "15"}, {"price": "0.22", "size": "31.16"}, {"price": "0.221", "size": "5.13"}, {"price": "0.567", "size": "12.09"}, {"price": "0.578", "size": "5"}, {"price": "0.582", "size": "303"}, {"price": "0.585", "size": "10"}, {"price": "0.587", "size": "25"}, {"price": "0.588", "size": "11.27"}, {"price": "0.939", "size": "13"}, {"price": "0.963", "size": "200"}, {"price": "0.974", "size": "1440.28"}, {"price": "0.975", "size": "26.88"}], "asks": [{"price": "0.999", "size": "1193"}, {"price": "0.998", "size": "413.95"}, {"price": "0.99", "size": "10"}, {"price": "0.989", "size": "5236"}, {"price": "0.988", "size": "416.66"}, {"price": "0.987", "size": "79.23"}], "event_type": "book", "last_trade_price": "0.013"}, {"market": "0x00787f50b9466db23a1899abc108b5609a77cbaa159c1b35822f45e9c14a940b", "asset_id": "113809960451765367690598229673115216134099141989496655805640157545770316317603", "timestamp": "1769384337562", "hash": "a367b2e8d0ebc091f2db5b4ef626ffdef3506382", "bids": [{"price": "0.001", "size": "1104252.01"}, {"price": "0.002", "size": "250"}, {"price": "0.003", "size": "400"}, {"price": "0.004", "size": "8.68"}, {"price": "0.006", "size": "200"}, {"price": "0.01", "size": "30010"}, {"price": "0.011", "size": "5.74"}, {"price": "0.021", "size": "12700"}, {"price": "0.025", "size": "384"}, {"price": "0.026", "size": "6.05"}, {"price": "0.05", "size": "30"}, {"price": "0.051", "size": "6539"}, {"price": "0.059", "size": "162.71"}, {"price": "0.06", "size": "5.51"}, {"price": "0.129", "size": "20100"}, {"price": "0.132", "size": "5"}, {"price": "0.139", "size": "69.06"}, {"price": "0.14", "size": "9.99"}, {"price": "0.223", "size": "25"}, {"price": "0.224", "size": "42.85"}, {"price": "0.523", "size": "263"}, {"price": "0.53", "size": "18.11"}, {"price": "0.531", "size": "5"}, {"price": "0.723", "size": "5"}, {"price": "0.86", "size": "10"}, {"price": "0.862", "size": "25"}, {"price": "0.863", "size": "11.27"}, {"price": "0.951", "size": "13.33"}, {"price": "0.967", "size": "130"}, {"price": "0.995", "size": "10"}, {"price": "0.997", "size": "104.64"}, {"price": "0.998", "size": "452.34"}], "asks": [{"price": "0.999", "size": "147.27"}], "event_type": "book", "last_trade_price": "0.001"}, {"market": "0xa8524b512abdab06087228a6a567e74d174e934c7663fc90a7d1327eb2c788d9", "asset_id": "20450835923140925865575749200335209238127709493333398350897559979417648423084", "timestamp": "1769384154962", "hash": "045f53ea147f4d7681a6089555546191f2497360", "bids": [{"price": "0.001", "size": "2.27"}], "asks": [{"price": "0.999", "size": "1104251.99"}, {"price": "0.998", "size": "250"}, {"price": "0.997", "size": "400"}, {"price": "0.996", "size": "8.65"}, {"price": "0.994", "size": "200"}, {"price": "0.99", "size": "10"}, {"price": "0.989", "size": "5.29"}, {"price": "0.979", "size": "12700"}, {"price": "0.978", "size": "436.36"}, {"price": "0.977", "size": "9.92"}, {"price": "0.95", "size": "530"}, {"price": "0.949", "size": "39"}, {"price": "0.928", "size": "133.33"}, {"price": "0.927", "size": "5.29"}, {"price": "0.852", "size": "20100"}, {"price": "0.85", "size": "26"}, {"price": "0.83", "size": "56.47"}, {"price": "0.829", "size": "7.47"}, {"price": "0.777", "size": "38"}, {"price": "0.776", "size": "42.85"}, {"price": "0.477", "size": "123"}, {"price": "0.446", "size": "158.24"}, {"price": "0.42", "size": "5"}, {"price": "0.419", "size": "16.52"}, {"price": "0.277", "size": "50"}, {"price": "0.177", "size": "59"}, {"price": "0.176", "size": "25"}, {"price": "0.174", "size": "10"}, {"price": "0.049", "size": "17.73"}, {"price": "0.046", "size": "89.17"}, {"price": "0.003", "size": "147.52"}, {"price": "0.002", "size": "407.42"}], "event_type": "book", "last_trade_price": "0.001"}, {"market": "0xaefc28d462f0824bbb9c694d3511beaaf8b21af8eba30d8e524ed05d0431e712", "asset_id": "74056431860682289842871849619463099581884627064723191566088662788504744554943", "timestamp": "1769383924712", "hash": "1cfcb889ec95d631305ab28b347cbea0d9a079b8", "bids": [{"price": "0.001", "size": "218.44"}], "asks": [{"price": "0.999", "size": "1104247.14"}, {"price": "0.998", "size": "250"}, {"price": "0.997", "size": "400"}, {"price": "0.996", "size": "8.67"}, {"price": "0.994", "size": "200"}, {"price": "0.99", "size": "10"}, {"price": "0.989", "size": "5.74"}, {"price": "0.98", "size": "5075.45"}, {"price": "0.979", "size": "20700"}, {"price": "0.975", "size": "384"}, {"price": "0.974", "size": "5.55"}, {"price": "0.95", "size": "30"}, {"price": "0.949", "size": "39"}, {"price": "0.944", "size": "671.42"}, {"price": "0.943", "size": "8.45"}, {"price": "0.855", "size": "20100"}, {"price": "0.83", "size": "23"}, {"price": "0.824", "size": "347.54"}, {"price": "0.823", "size": "7.15"}, {"price": "0.736", "size": "7"}, {"price": "0.735", "size": "36.22"}, {"price": "0.477", "size": "26"}, {"price": "0.476", "size": "18.32"}, {"price": "0.277", "size": "7"}, {"price": "0.128", "size": "10"}, {"price": "0.126", "size": "25"}, {"price": "0.125", "size": "11.27"}, {"price": "0.049", "size": "13"}, {"price": "0.003", "size": "401.18"}, {"price": "0.002", "size": "213.45"}], "event_type": "book", "last_trade_price": "0.001"}, {"market": "0x4fc188ab7b8337089312087777af8a703757466dda919e1de85e148394c40090", "asset_id": "22440526641822362681904932185789972209232343897283048384344291619576375972156", "timestamp": "1769384332528", "hash": "f0920d81545953ad81922e6f18a09b3f44760eae", "bids": [], "asks": [{"price": "0.999", "size": "1104294.88"}, {"price": "0.998", "size": "250"}, {"price": "0.997", "size": "406.63"}, {"price": "0.994", "size": "200"}, {"price": "0.993", "size": "10.45"}, {"price": "0.99", "size": "30010"}, {"price": "0.979", "size": "12700"}, {"price": "0.978", "size": "6.15"}, {"price": "0.968", "size": "250"}, {"price": "0.95", "size": "30"}, {"price": "0.949", "size": "3044.02"}, {"price": "0.948", "size": "653.84"}, {"price": "0.92", "size": "300"}, {"price": "0.919", "size": "98.76"}, {"price": "0.89", "size": "72.72"}, {"price": "0.889", "size": "13.55"}, {"price": "0.778", "size": "9000"}, {"price": "0.777", "size": "31"}, {"price": "0.776", "size": "35.71"}, {"price": "0.749", "size": "78"}, {"price": "0.747", "size": "15"}, {"price": "0.477", "size": "56"}, {"price": "0.474", "size": "15.2"}, {"price": "0.473", "size": "5"}, {"price": "0.277", "size": "7"}, {"price": "0.177", "size": "6"}, {"price": "0.176", "size": "10"}, {"price": "0.077", "size": "119"}, {"price": "0.076", "size": "25"}, {"price": "0.049", "size": "14.83"}, {"price": "0.048", "size": "11"}, {"price": "0.047", "size": "20"}, {"price": "0.005", "size": "27.39"}, {"price": "0.004", "size": "104.21"}], "event_type": "book", "last_trade_price": "0.001"}, {"market": "0x6a6c33f325ff0074fb8e5c03bd6791d9d773a2473388ca79aa2066bcc96202c8", "asset_id": "22219635351305034221269939609658066752987416192739054085616484288888365596484", "timestamp": "1769384332444", "hash": "5e5fe4f09ffc54c2c9508f467c3f4dd8910e2e48", "bids": [{"price": "0.001", "size": "1104344.27"}, {"price": "0.002", "size": "255.12"}, {"price": "0.003", "size": "400"}, {"price": "0.004", "size": "6.36"}, {"price": "0.006", "size": "200"}, {"price": "0.009", "size": "6.06"}, {"price": "0.01", "size": "10"}, {"price": "0.011", "size": "5.3"}, {"price": "0.02", "size": "5000"}, {"price": "0.021", "size": "21000"}, {"price": "0.022", "size": "363.63"}, {"price": "0.041", "size": "6.44"}, {"price": "0.05", "size": "30"}, {"price": "0.051", "size": "39"}, {"price": "0.052", "size": "653.84"}, {"price": "0.08", "size": "300"}, {"price": "0.099", "size": "80.8"}, {"price": "0.1", "size": "15.82"}, {"price": "0.264", "size": "9000"}, {"price": "0.282", "size": "12"}, {"price": "0.283", "size": "28.26"}, {"price": "0.523", "size": "28"}, {"price": "0.578", "size": "217"}, {"price": "0.579", "size": "13.81"}, {"price": "0.698", "size": "11.46"}, {"price": "0.722", "size": "306"}, {"price": "0.726", "size": "25"}, {"price": "0.727", "size": "11.27"}, {"price": "0.93", "size": "14.09"}, {"price": "0.932", "size": "20"}, {"price": "0.94", "size": "13.33"}, {"price": "0.972", "size": "23.41"}, {"price": "0.985", "size": "548.55"}, {"price": "0.986", "size": "5"}], "asks": [{"price": "0.999", "size": "164"}, {"price": "0.997", "size": "47"}, {"price": "0.989", "size": "188.27"}], "event_type": "book", "last_trade_price": "0.989"}, {"market": "0x584caca7a7536029bef854652fa5fdd861631edbc01a217069341b85030edd6f", "asset_id": "8840594256975309703691759780728141785112443011041236897959089339991605786144", "timestamp": "1769384330311", "hash": "1c25f303ea7caa56c9752071a264a08620b49884", "bids": [{"price": "0.001", "size": "1102804.21"}, {"price": "0.002", "size": "257.48"}, {"price": "0.003", "size": "400"}, {"price": "0.004", "size": "90000"}, {"price": "0.005", "size": "5.93"}, {"price": "0.006", "size": "200"}, {"price": "0.01", "size": "10"}, {"price": "0.011", "size": "6.16"}, {"price": "0.024", "size": "1033.33"}, {"price": "0.025", "size": "5.56"}, {"price": "0.05", "size": "30"}, {"price": "0.054", "size": "648.14"}, {"price": "0.055", "size": "6.18"}, {"price": "0.107", "size": "30100"}, {"price": "0.108", "size": "74.07"}, {"price": "0.136", "size": "58.82"}, {"price": "0.137", "size": "10.24"}, {"price": "0.223", "size": "49"}, {"price": "0.242", "size": "203"}, {"price": "0.248", "size": "13"}, {"price": "0.249", "size": "32.12"}, {"price": "0.25", "size": "8"}, {"price": "0.523", "size": "26"}, {"price": "0.524", "size": "15.26"}, {"price": "0.72", "size": "10"}, {"price": "0.721", "size": "25"}, {"price": "0.951", "size": "32"}, {"price": "0.952", "size": "20"}, {"price": "0.995", "size": "91.12"}, {"price": "0.996", "size": "459.71"}], "asks": [], "event_type": "book", "last_trade_price": ""}, {"market": "0xd2b7235e5c612ce49ad0252420d713280ded4e346bd24dd50f941e901e9daec2", "asset_id": "62070332729843756648077334071325768265229024314411995286040519682521027925149", "timestamp": "1769383924712", "hash": "9c1b8ab6bc698dea2a91d4c5a53cc6629f0f5193", "bids": [{"price": "0.001", "size": "11.27"}], "asks": [{"price": "0.999", "size": "1104258"}, {"price": "0.998", "size": "250"}, {"price": "0.997", "size": "406.63"}, {"price": "0.996", "size": "90000"}, {"price": "0.994", "size": "200"}, {"price": "0.993", "size": "10.46"}, {"price": "0.99", "size": "10"}, {"price": "0.979", "size": "12700"}, {"price": "0.978", "size": "6.57"}, {"price": "0.968", "size": "300"}, {"price": "0.95", "size": "30"}, {"price": "0.949", "size": "39"}, {"price": "0.948", "size": "684.61"}, {"price": "0.947", "size": "12.17"}, {"price": "0.906", "size": "402.12"}, {"price": "0.78", "size": "12000"}, {"price": "0.779", "size": "5.01"}, {"price": "0.777", "size": "35"}, {"price": "0.775", "size": "21"}, {"price": "0.774", "size": "42.47"}, {"price": "0.477", "size": "28"}, {"price": "0.465", "size": "243.94"}, {"price": "0.464", "size": "20"}, {"price": "0.177", "size": "5"}, {"price": "0.086", "size": "10"}, {"price": "0.085", "size": "25"}, {"price": "0.049", "size": "5"}, {"price": "0.047", "size": "20"}, {"price": "0.005", "size": "282.84"}, {"price": "0.004", "size": "12.18"}, {"price": "0.003", "size": "390.67"}], "event_type": "book", "last_trade_price": "0.001"}, {"market": "0xa449cd8346b6deda561828355ae92b88bd47d989859d2d287ce7e42a42b556c7", "asset_id": "50990718602111286221499412828092223474799500548329402570398939983325937296388", "timestamp": "1769384266145", "hash": "f6fbcb7f2a0736a42e1a572255ac6e2ca3e12113", "bids": [{"price": "0.01", "size": "110010"}, {"price": "0.02", "size": "1100"}, {"price": "0.05", "size": "3530"}, {"price": "0.06", "size": "33"}, {"price": "0.07", "size": "114.28"}, {"price": "0.15", "size": "3100"}, {"price": "0.16", "size": "50"}, {"price": "0.18", "size": "28"}, {"price": "0.19", "size": "42.1"}, {"price": "0.5", "size": "76"}, {"price": "0.51", "size": "15.68"}, {"price": "0.78", "size": "10"}, {"price": "0.79", "size": "10"}, {"price": "0.8", "size": "17.5"}, {"price": "0.81", "size": "10"}, {"price": "0.82", "size": "17.5"}, {"price": "0.83", "size": "210"}, {"price": "0.84", "size": "10"}, {"price": "0.85", "size": "10"}, {"price": "0.86", "size": "380"}, {"price": "0.89", "size": "20.5"}, {"price": "0.91", "size": "134.24"}], "asks": [{"price": "0.99", "size": "20.16"}, {"price": "0.98", "size": "5006.6"}, {"price": "0.97", "size": "265.16"}, {"price": "0.96", "size": "1082.04"}, {"price": "0.95", "size": "178.6"}, {"price": "0.94", "size": "13.93"}], "event_type": "book", "last_trade_price": "0.090"}, {"market": "0x936a5e78fd5963c717e49661a593fa3353241f6fb3c69b6615e9041e6b6f0973", "asset_id": "62474888561798875936325899031095507932691561832763786042468556558023439824689", "timestamp": "1769384329730", "hash": "062ea201dc39a13704c0682b29cf455aa7d6b261", "bids": [{"price": "0.001", "size": "1104257.99"}, {"price": "0.002", "size": "250"}, {"price": "0.003", "size": "400"}, {"price": "0.004", "size": "8.66"}, {"price": "0.006", "size": "200"}, {"price": "0.01", "size": "10"}, {"price": "0.011", "size": "8.75"}, {"price": "0.021", "size": "12700"}, {"price": "0.03", "size": "266.66"}, {"price": "0.031", "size": "8.06"}, {"price": "0.05", "size": "30"}, {"price": "0.051", "size": "656.86"}, {"price": "0.08", "size": "300"}, {"price": "0.086", "size": "93.02"}, {"price": "0.087", "size": "5.51"}, {"price": "0.214", "size": "20000"}, {"price": "0.215", "size": "37.2"}, {"price": "0.216", "size": "5.2"}, {"price": "0.223", "size": "81"}, {"price": "0.227", "size": "17"}, {"price": "0.228", "size": "35.08"}, {"price": "0.523", "size": "135"}, {"price": "0.558", "size": "189.33"}, {"price": "0.559", "size": "5"}, {"price": "0.823", "size": "73"}, {"price": "0.859", "size": "10"}, {"price": "0.86", "size": "25"}, {"price": "0.951", "size": "20"}, {"price": "0.952", "size": "13.33"}, {"price": "0.995", "size": "90.25"}, {"price": "0.996", "size": "335.79"}, {"price": "0.997", "size": "6.71"}], "asks": [], "event_type": "book", "last_trade_price": ""}, {"market": "0x82bd65f09e2428042a5ac204f60f34e1b40f7a4a2d008fc0b92afd0aca450607", "asset_id": "67038866817302942551959484913198849155750799193273634269443232905877417785248", "timestamp": "1769384327565", "hash": "1713b679447533d2a55540203ed949178916c39a", "bids": [{"price": "0.001", "size": "1949.26"}], "asks": [{"price": "0.999", "size": "1104251.99"}, {"price": "0.998", "size": "250"}, {"price": "0.997", "size": "400"}, {"price": "0.996", "size": "8.65"}, {"price": "0.994", "size": "200"}, {"price": "0.99", "size": "30010"}, {"price": "0.989", "size": "5.33"}, {"price": "0.979", "size": "12700"}, {"price": "0.978", "size": "311.68"}, {"price": "0.977", "size": "12.13"}, {"price": "0.95", "size": "530"}, {"price": "0.949", "size": "39"}, {"price": "0.929", "size": "3300"}, {"price": "0.928", "size": "95.23"}, {"price": "0.92", "size": "300"}, {"price": "0.919", "size": "5.07"}, {"price": "0.9", "size": "34"}, {"price": "0.899", "size": "67.89"}, {"price": "0.89", "size": "27"}, {"price": "0.889", "size": "61.77"}, {"price": "0.787", "size": "32.19"}, {"price": "0.786", "size": "5.61"}, {"price": "0.777", "size": "21"}, {"price": "0.776", "size": "30.61"}, {"price": "0.488", "size": "298"}, {"price": "0.419", "size": "11.8"}, {"price": "0.414", "size": "5"}, {"price": "0.405", "size": "25"}, {"price": "0.404", "size": "20"}, {"price": "0.403", "size": "11.27"}, {"price": "0.049", "size": "13.33"}, {"price": "0.009", "size": "5.59"}, {"price": "0.004", "size": "6.28"}, {"price": "0.003", "size": "35.59"}, {"price": "0.002", "size": "626.96"}], "event_type": "book", "last_trade_price": "0.001"}, {"market": "0x6a6c33f325ff0074fb8e5c03bd6791d9d773a2473388ca79aa2066bcc96202c8", "asset_id": "81184350352957081203802864112311089209552939430128547953657640601934627386250", "timestamp": "1769384332444", "hash": "3aa244250ff9b1d0686f2dd14ef786bbb6ac1671", "bids": [{"price": "0.001", "size": "164"}, {"price": "0.003", "size": "47"}, {"price": "0.011", "size": "188.27"}], "asks": [{"price": "0.999", "size": "1104344.27"}, {"price": "0.998", "size": "255.12"}, {"price": "0.997", "size": "400"}, {"price": "0.996", "size": "6.36"}, {"price": "0.994", "size": "200"}, {"price": "0.991", "size": "6.06"}, {"price": "0.99", "size": "10"}, {"price": "0.989", "size": "5.3"}, {"price": "0.98", "size": "5000"}, {"price": "0.979", "size": "21000"}, {"price": "0.978", "size": "363.63"}, {"price": "0.959", "size": "6.44"}, {"price": "0.95", "size": "30"}, {"price": "0.949", "size": "39"}, {"price": "0.948", "size": "653.84"}, {"price": "0.92", "size": "300"}, {"price": "0.901", "size": "80.8"}, {"price": "0.9", "size": "15.82"}, {"price": "0.736", "size": "9000"}, {"price": "0.718", "size": "12"}, {"price": "0.717", "size": "28.26"}, {"price": "0.477", "size": "28"}, {"price": "0.422", "size": "217"}, {"price": "0.421", "size": "13.81"}, {"price": "0.302", "size": "11.46"}, {"price": "0.278", "size": "306"}, {"price": "0.274", "size": "25"}, {"price": "0.273", "size": "11.27"}, {"price": "0.07", "size": "14.09"}, {"price": "0.068", "size": "20"}, {"price": "0.06", "size": "13.33"}, {"price": "0.028", "size": "23.41"}, {"price": "0.015", "size": "548.55"}, {"price": "0.014", "size": "5"}], "event_type": "book", "last_trade_price": "0.989"}, {"market": "0xa449cd8346b6deda561828355ae92b88bd47d989859d2d287ce7e42a42b556c7", "asset_id": "91120885899126885515852202682357546652544305953593660618778514157513430201648", "timestamp": "1769384266145", "hash": "17dcf1ec11b3beff2af2383fdbc433fd2a5995e1", "bids": [{"price": "0.01", "size": "20.16"}, {"price": "0.02", "size": "5006.6"}, {"price": "0.03", "size": "265.16"}, {"price": "0.04", "size": "1082.04"}, {"price": "0.05", "size": "178.6"}, {"price": "0.06", "size": "13.93"}], "asks": [{"price": "0.99", "size": "110010"}, {"price": "0.98", "size": "1100"}, {"price": "0.95", "size": "3530"}, {"price": "0.94", "size": "33"}, {"price": "0.93", "size": "114.28"}, {"price": "0.85", "size": "3100"}, {"price": "0.84", "size": "50"}, {"price": "0.82", "size": "28"}, {"price": "0.81", "size": "42.1"}, {"price": "0.5", "size": "76"}, {"price": "0.49", "size": "15.68"}, {"price": "0.22", "size": "10"}, {"price": "0.21", "size": "10"}, {"price": "0.2", "size": "17.5"}, {"price": "0.19", "size": "10"}, {"price": "0.18", "size": "17.5"}, {"price": "0.17", "size": "210"}, {"price": "0.16", "size": "10"}, {"price": "0.15", "size": "10"}, {"price": "0.14", "size": "380"}, {"price": "0.11", "size": "20.5"}, {"price": "0.09", "size": "134.24"}], "event_type": "book", "last_trade_price": "0.090"}, {"market": "0xd7a1f81c476ac55cf008314b61c8df2ca862024a29b6069a9b947c31d00fb164", "asset_id": "4019541341085677110576387701897966155468183932424126053469159818708043600170", "timestamp": "1769384327960", "hash": "b55af53bba0bce93a2f4557f4a4b2c69c8d706bf", "bids": [{"price": "0.001", "size": "1104252.99"}, {"price": "0.002", "size": "250"}, {"price": "0.003", "size": "400"}, {"price": "0.004", "size": "8.66"}, {"price": "0.006", "size": "200"}, {"price": "0.01", "size": "10"}, {"price": "0.011", "size": "5.73"}, {"price": "0.02", "size": "5000"}, {"price": "0.021", "size": "21000"}, {"price": "0.023", "size": "417.39"}, {"price": "0.024", "size": "7.48"}, {"price": "0.05", "size": "30"}, {"price": "0.06", "size": "700"}, {"price": "0.062", "size": "154.83"}, {"price": "0.063", "size": "5.13"}, {"price": "0.11", "size": "300"}, {"price": "0.112", "size": "36"}, {"price": "0.141", "size": "68.08"}, {"price": "0.142", "size": "9.74"}, {"price": "0.223", "size": "73"}, {"price": "0.224", "size": "42.85"}, {"price": "0.523", "size": "72"}, {"price": "0.539", "size": "2000"}, {"price": "0.54", "size": "197"}, {"price": "0.541", "size": "5"}, {"price": "0.542", "size": "17.71"}, {"price": "0.823", "size": "5"}, {"price": "0.862", "size": "25"}, {"price": "0.863", "size": "10"}, {"price": "0.951", "size": "20"}, {"price": "0.953", "size": "20"}, {"price": "0.993", "size": "50"}, {"price": "0.995", "size": "341"}, {"price": "0.996", "size": "170.83"}], "asks": [], "event_type": "book", "last_trade_price": ""}, {"market": "0xd7a1f81c476ac55cf008314b61c8df2ca862024a29b6069a9b947c31d00fb164", "asset_id": "105745394011617053647384212072423899373042863466923232377475057902735593128457", "timestamp": "1769384327960", "hash": "93b3b1971488a378f45cf72647fbfe7c5eac6123", "bids": [], "asks": [{"price": "0.999", "size": "1104252.99"}, {"price": "0.998", "size": "250"}, {"price": "0.997", "size": "400"}, {"price": "0.996", "size": "8.66"}, {"price": "0.994", "size": "200"}, {"price": "0.99", "size": "10"}, {"price": "0.989", "size": "5.73"}, {"price": "0.98", "size": "5000"}, {"price": "0.979", "size": "21000"}, {"price": "0.977", "size": "417.39"}, {"price": "0.976", "size": "7.48"}, {"price": "0.95", "size": "30"}, {"price": "0.94", "size": "700"}, {"price": "0.938", "size": "154.83"}, {"price": "0.937", "size": "5.13"}, {"price": "0.89", "size": "300"}, {"price": "0.888", "size": "36"}, {"price": "0.859", "size": "68.08"}, {"price": "0.858", "size": "9.74"}, {"price": "0.777", "size": "73"}, {"price": "0.776", "size": "42.85"}, {"price": "0.477", "size": "72"}, {"price": "0.461", "size": "2000"}, {"price": "0.46", "size": "197"}, {"price": "0.459", "size": "5"}, {"price": "0.458", "size": "17.71"}, {"price": "0.177", "size": "5"}, {"price": "0.138", "size": "25"}, {"price": "0.137", "size": "10"}, {"price": "0.049", "size": "20"}, {"price": "0.047", "size": "20"}, {"price": "0.007", "size": "50"}, {"price": "0.005", "size": "341"}, {"price": "0.004", "size": "170.83"}], "event_type": "book", "last_trade_price": ""}, {"market": "0x584caca7a7536029bef854652fa5fdd861631edbc01a217069341b85030edd6f", "asset_id": "69196677690927265002451334694240538592951011957285689708757350071125284654035", "timestamp": "1769384330311", "hash": "e33c51ab7556a7641be3740d88eeee66fb5bb750", "bids": [], "asks": [{"price": "0.999", "size": "1102804.21"}, {"price": "0.998", "size": "257.48"}, {"price": "0.997", "size": "400"}, {"price": "0.996", "size": "90000"}, {"price": "0.995", "size": "5.93"}, {"price": "0.994", "size": "200"}, {"price": "0.99", "size": "10"}, {"price": "0.989", "size": "6.16"}, {"price": "0.976", "size": "1033.33"}, {"price": "0.975", "size": "5.56"}, {"price": "0.95", "size": "30"}, {"price": "0.946", "size": "648.14"}, {"price": "0.945", "size": "6.18"}, {"price": "0.893", "size": "30100"}, {"price": "0.892", "size": "74.07"}, {"price": "0.864", "size": "58.82"}, {"price": "0.863", "size": "10.24"}, {"price": "0.777", "size": "49"}, {"price": "0.758", "size": "203"}, {"price": "0.752", "size": "13"}, {"price": "0.751", "size": "32.12"}, {"price": "0.75", "size": "8"}, {"price": "0.477", "size": "26"}, {"price": "0.476", "size": "15.26"}, {"price": "0.28", "size": "10"}, {"price": "0.279", "size": "25"}, {"price": "0.049", "size": "32"}, {"price": "0.048", "size": "20"}, {"price": "0.005", "size": "91.12"}, {"price": "0.004", "size": "459.71"}], "event_type": "book", "last_trade_price": ""}, {"market": "0xfb1f550759909794c23b00af18fca4c280055b5f9d8486be98e3d060c33ca90c", "asset_id": "65766553373983986285773386056008797086838930377262355718066864177786956960253", "timestamp": "1769384339356", "hash": "9e43d55f682e3c55d9cefb2b3f57896cc92bef01", "bids": [{"price": "0.001", "size": "625"}, {"price": "0.002", "size": "232.44"}, {"price": "0.003", "size": "388"}, {"price": "0.004", "size": "148"}], "asks": [{"price": "0.999", "size": "1104252.03"}, {"price": "0.998", "size": "30250"}, {"price": "0.997", "size": "400"}, {"price": "0.996", "size": "8.68"}, {"price": "0.994", "size": "200"}, {"price": "0.99", "size": "10"}, {"price": "0.989", "size": "5.75"}, {"price": "0.98", "size": "5000"}, {"price": "0.979", "size": "15700"}, {"price": "0.973", "size": "444.44"}, {"price": "0.972", "size": "5.15"}, {"price": "0.95", "size": "30"}, {"price": "0.949", "size": "6539"}, {"price": "0.942", "size": "206.89"}, {"price": "0.941", "size": "8.75"}, {"price": "0.916", "size": "142.85"}, {"price": "0.914", "size": "600"}, {"price": "0.82", "size": "91"}, {"price": "0.814", "size": "10"}, {"price": "0.812", "size": "63.82"}, {"price": "0.811", "size": "6.48"}, {"price": "0.185", "size": "340"}, {"price": "0.184", "size": "10"}, {"price": "0.123", "size": "25"}, {"price": "0.122", "size": "11.27"}, {"price": "0.068", "size": "295"}, {"price": "0.052", "size": "13.33"}, {"price": "0.023", "size": "10.02"}, {"price": "0.021", "size": "313.05"}, {"price": "0.015", "size": "10.55"}, {"price": "0.014", "size": "25"}], "event_type": "book", "last_trade_price": "0.002"}, {"market": "0xff54852cf4cb9c3568f795b983bc494d2e13d3f9cad41ba872a4ffd3ccb2101e", "asset_id": "91203260296949109747095851381415926782789749145484395871735811789947699971761", "timestamp": "1769384330307", "hash": "7eba3d0e88b267cabb81d791ef67a13fccb45f1d", "bids": [], "asks": [{"price": "0.999", "size": "1104288.88"}, {"price": "0.998", "size": "257.48"}, {"price": "0.997", "size": "400"}, {"price": "0.996", "size": "60000"}, {"price": "0.995", "size": "5.93"}, {"price": "0.994", "size": "200"}, {"price": "0.99", "size": "10"}, {"price": "0.989", "size": "7.46"}, {"price": "0.973", "size": "922.22"}, {"price": "0.972", "size": "8.52"}, {"price": "0.95", "size": "30"}, {"price": "0.949", "size": "39"}, {"price": "0.944", "size": "607.14"}, {"price": "0.92", "size": "300"}, {"price": "0.919", "size": "79.1"}, {"price": "0.819", "size": "20000"}, {"price": "0.814", "size": "32.25"}, {"price": "0.813", "size": "6.53"}, {"price": "0.777", "size": "189"}, {"price": "0.776", "size": "26.78"}, {"price": "0.745", "size": "11"}, {"price": "0.744", "size": "23.43"}, {"price": "0.71", "size": "20.68"}, {"price": "0.709", "size": "6"}, {"price": "0.477", "size": "55"}, {"price": "0.476", "size": "11.45"}, {"price": "0.277", "size": "7"}, {"price": "0.177", "size": "6"}, {"price": "0.139", "size": "10"}, {"price": "0.138", "size": "25"}, {"price": "0.049", "size": "5"}, {"price": "0.048", "size": "13.33"}, {"price": "0.041", "size": "15.89"}, {"price": "0.005", "size": "58.86"}, {"price": "0.004", "size": "135.23"}], "event_type": "book", "last_trade_price": "0.001"}, {"market": "0xbba1c02a186676782fae38b63af5333da443c8a16d86274ba1b045324ec989c7", "asset_id": "60301519933335336364820582307817349741317665540686207245282394805552819791374", "timestamp": "1769384338322", "hash": "3859db34abcecbe18d19ec0d3a66494763f0d146", "bids": [], "asks": [{"price": "0.999", "size": "1104337.87"}, {"price": "0.998", "size": "250"}, {"price": "0.997", "size": "400"}, {"price": "0.996", "size": "8.65"}, {"price": "0.994", "size": "200"}, {"price": "0.99", "size": "10"}, {"price": "0.989", "size": "7.03"}, {"price": "0.98", "size": "5000"}, {"price": "0.979", "size": "20700"}, {"price": "0.974", "size": "263.73"}, {"price": "0.973", "size": "9.96"}, {"price": "0.95", "size": "30"}, {"price": "0.949", "size": "39"}, {"price": "0.948", "size": "631.86"}, {"price": "0.92", "size": "300"}, {"price": "0.914", "size": "79.73"}, {"price": "0.913", "size": "5.17"}, {"price": "0.823", "size": "20000"}, {"price": "0.822", "size": "38.52"}, {"price": "0.794", "size": "33.28"}, {"price": "0.793", "size": "5.57"}, {"price": "0.777", "size": "40"}, {"price": "0.755", "size": "14"}, {"price": "0.754", "size": "27.87"}, {"price": "0.5", "size": "14"}, {"price": "0.477", "size": "56"}, {"price": "0.438", "size": "178"}, {"price": "0.437", "size": "5"}, {"price": "0.436", "size": "12.15"}, {"price": "0.177", "size": "67"}, {"price": "0.174", "size": "25"}, {"price": "0.173", "size": "20"}, {"price": "0.049", "size": "5"}, {"price": "0.048", "size": "11"}, {"price": "0.047", "size": "20"}, {"price": "0.005", "size": "45.98"}, {"price": "0.004", "size": "90.59"}], "event_type": "book", "last_trade_price": "0.001"}, {"market": "0x3ab6710aff85c354a3d99e0f3c972903263189ce32b1a5b13ed58cb68762b243", "asset_id": "12436606244684756212688349482021343426028351538039522454366335615620119043815", "timestamp": "1769384206877", "hash": "0d03326729276212b3335be56955ee7cd973fabc", "bids": [{"price": "0.001", "size": "66.25"}], "asks": [{"price": "0.999", "size": "1104251.99"}, {"price": "0.998", "size": "250"}, {"price": "0.997", "size": "400"}, {"price": "0.996", "size": "8.66"}, {"price": "0.994", "size": "200"}, {"price": "0.99", "size": "30010"}, {"price": "0.989", "size": "10.89"}, {"price": "0.979", "size": "13000"}, {"price": "0.965", "size": "228.57"}, {"price": "0.964", "size": "6.65"}, {"price": "0.95", "size": "30"}, {"price": "0.949", "size": "12739"}, {"price": "0.94", "size": "200"}, {"price": "0.939", "size": "131.14"}, {"price": "0.911", "size": "89.88"}, {"price": "0.91", "size": "5.37"}, {"price": "0.89", "size": "300"}, {"price": "0.889", "size": "72.07"}, {"price": "0.78", "size": "21000"}, {"price": "0.779", "size": "5.01"}, {"price": "0.777", "size": "295"}, {"price": "0.775", "size": "17"}, {"price": "0.771", "size": "8"}, {"price": "0.77", "size": "34.78"}, {"price": "0.477", "size": "57"}, {"price": "0.476", "size": "15.26"}, {"price": "0.177", "size": "73"}, {"price": "0.158", "size": "25"}, {"price": "0.156", "size": "291"}, {"price": "0.155", "size": "11.27"}, {"price": "0.049", "size": "13"}, {"price": "0.005", "size": "36.22"}, {"price": "0.004", "size": "63.61"}, {"price": "0.002", "size": "1013.26"}], "event_type": "book", "last_trade_price": "0.001"}, {"market": "0x34629a8e04da66f61bad2b4de18d370ca551faf79f810e04e403b841163f0e47", "asset_id": "24428969314967049374579832885004941749071678905985050510703983608884666132158", "timestamp": "1769384226137", "hash": "f39fb2d34db87ba8bedfcf4876038c7e3ae770f9", "bids": [{"price": "0.001", "size": "1193"}, {"price": "0.002", "size": "413.95"}, {"price": "0.01", "size": "10"}, {"price": "0.011", "size": "5236"}, {"price": "0.012", "size": "416.66"}, {"price": "0.013", "size": "79.23"}], "asks": [{"price": "0.999", "size": "2204247.21"}, {"price": "0.998", "size": "40250"}, {"price": "0.997", "size": "406.76"}, {"price": "0.994", "size": "200"}, {"price": "0.993", "size": "5.78"}, {"price": "0.99", "size": "10"}, {"price": "0.989", "size": "5.75"}, {"price": "0.98", "size": "5000"}, {"price": "0.979", "size": "16000"}, {"price": "0.963", "size": "185.32"}, {"price": "0.962", "size": "6.54"}, {"price": "0.95", "size": "30"}, {"price": "0.949", "size": "39"}, {"price": "0.94", "size": "700"}, {"price": "0.939", "size": "112.41"}, {"price": "0.908", "size": "74.53"}, {"price": "0.907", "size": "5.19"}, {"price": "0.89", "size": "300"}, {"price": "0.889", "size": "61.77"}, {"price": "0.787", "size": "6000"}, {"price": "0.786", "size": "32.04"}, {"price": "0.782", "size": "15"}, {"price": "0.78", "size": "31.16"}, {"price": "0.779", "size": "5.13"}, {"price": "0.433", "size": "12.09"}, {"price": "0.422", "size": "5"}, {"price": "0.418", "size": "303"}, {"price": "0.415", "size": "10"}, {"price": "0.413", "size": "25"}, {"price": "0.412", "size": "11.27"}, {"price": "0.061", "size": "13"}, {"price": "0.037", "size": "200"}, {"price": "0.026", "size": "1440.28"}, {"price": "0.025", "size": "26.88"}], "event_type": "book", "last_trade_price": "0.013"}, {"market": "0xaefc28d462f0824bbb9c694d3511beaaf8b21af8eba30d8e524ed05d0431e712", "asset_id": "44763420328579357949062599081517223538923284512329276353056439811950932880097", "timestamp": "1769383924712", "hash": "497435512d3e46d3d8ef2706e7721e01ee9b426b", "bids": [{"price": "0.001", "size": "1104247.14"}, {"price": "0.002", "size": "250"}, {"price": "0.003", "size": "400"}, {"price": "0.004", "size": "8.67"}, {"price": "0.006", "size": "200"}, {"price": "0.01", "size": "10"}, {"price": "0.011", "size": "5.74"}, {"price": "0.02", "size": "5075.45"}, {"price": "0.021", "size": "20700"}, {"price": "0.025", "size": "384"}, {"price": "0.026", "size": "5.55"}, {"price": "0.05", "size": "30"}, {"price": "0.051", "size": "39"}, {"price": "0.056", "size": "671.42"}, {"price": "0.057", "size": "8.45"}, {"price": "0.145", "size": "20100"}, {"price": "0.17", "size": "23"}, {"price": "0.176", "size": "347.54"}, {"price": "0.177", "size": "7.15"}, {"price": "0.264", "size": "7"}, {"price": "0.265", "size": "36.22"}, {"price": "0.523", "size": "26"}, {"price": "0.524", "size": "18.32"}, {"price": "0.723", "size": "7"}, {"price": "0.872", "size": "10"}, {"price": "0.874", "size": "25"}, {"price": "0.875", "size": "11.27"}, {"price": "0.951", "size": "13"}, {"price": "0.997", "size": "401.18"}, {"price": "0.998", "size": "213.45"}], "asks": [{"price": "0.999", "size": "218.44"}], "event_type": "book", "last_trade_price": "0.001"}, {"market": "0xcdc395263072e4727246bd28d628c79de9ef6024b9c78ae6d230fb542300d783", "asset_id": "74241680779259491478932045869903328211832336610417942960534531418244174612949", "timestamp": "1769384329408", "hash": "ff5d271cea540cdc34802507f6f8f41fe30ab9f0", "bids": [{"price": "0.001", "size": "1101515"}, {"price": "0.002", "size": "22.3"}, {"price": "0.01", "size": "10"}, {"price": "0.011", "size": "60005.73"}, {"price": "0.023", "size": "521.73"}, {"price": "0.024", "size": "7.48"}, {"price": "0.04", "size": "7000"}, {"price": "0.06", "size": "200"}, {"price": "0.062", "size": "750"}, {"price": "0.063", "size": "195.48"}, {"price": "0.11", "size": "300"}, {"price": "0.139", "size": "86.33"}, {"price": "0.14", "size": "9.94"}, {"price": "0.512", "size": "6000"}, {"price": "0.546", "size": "222"}, {"price": "0.548", "size": "21.89"}, {"price": "0.549", "size": "304"}, {"price": "0.929", "size": "44"}, {"price": "0.93", "size": "13"}, {"price": "0.995", "size": "30"}, {"price": "0.998", "size": "131.8"}, {"price": "0.999", "size": "149.16"}], "asks": [], "event_type": "book", "last_trade_price": ""}, {"market": "0xeb60a53b5ca38150c07cc30ef0f5570b292f3e43722512cc55d0cff666ac1077", "asset_id": "83308171747089483400662168608358178791256497013703595264448211477259881059204", "timestamp": "1769384327964", "hash": "da77a7a710cdbb8895744f69704abcd3c75ad7ca", "bids": [{"price": "0.001", "size": "1104252.99"}, {"price": "0.002", "size": "250"}, {"price": "0.003", "size": "400"}, {"price": "0.004", "size": "8.65"}, {"price": "0.006", "size": "200"}, {"price": "0.01", "size": "10"}, {"price": "0.011", "size": "8.75"}, {"price": "0.02", "size": "5000"}, {"price": "0.021", "size": "20700"}, {"price": "0.03", "size": "266.66"}, {"price": "0.031", "size": "7.79"}, {"price": "0.05", "size": "30"}, {"price": "0.051", "size": "656.86"}, {"price": "0.08", "size": "300"}, {"price": "0.084", "size": "95.23"}, {"price": "0.085", "size": "5.82"}, {"price": "0.217", "size": "9000"}, {"price": "0.218", "size": "5.12"}, {"price": "0.223", "size": "45"}, {"price": "0.224", "size": "208.71"}, {"price": "0.253", "size": "13"}, {"price": "0.284", "size": "28.16"}, {"price": "0.285", "size": "7"}, {"price": "0.523", "size": "36"}, {"price": "0.524", "size": "15.26"}, {"price": "0.723", "size": "7"}, {"price": "0.823", "size": "6"}, {"price": "0.862", "size": "10"}, {"price": "0.863", "size": "25"}, {"price": "0.951", "size": "20"}, {"price": "0.952", "size": "11"}, {"price": "0.953", "size": "20"}, {"price": "0.995", "size": "86.85"}, {"price": "0.996", "size": "293.86"}], "asks": [], "event_type": "book", "last_trade_price": ""}, {"market": "0xe84c744708601de931a3934348a03daacbee47d7544833fbfaee03cebf2ce671", "asset_id": "22702151217568226464490525917269671698635793471200188591890325057358807077490", "timestamp": "1769384325727", "hash": "1b0465d65116e9816c62fb0d314f3ccd0efe28de", "bids": [{"price": "0.001", "size": "584"}, {"price": "0.002", "size": "115"}, {"price": "0.005", "size": "565.27"}], "asks": [{"price": "0.999", "size": "1104254.51"}, {"price": "0.998", "size": "40250"}, {"price": "0.997", "size": "406.65"}, {"price": "0.994", "size": "200"}, {"price": "0.993", "size": "5.7"}, {"price": "0.99", "size": "10"}, {"price": "0.989", "size": "9.09"}, {"price": "0.97", "size": "3000"}, {"price": "0.969", "size": "221.19"}, {"price": "0.96", "size": "12700"}, {"price": "0.959", "size": "5.25"}, {"price": "0.95", "size": "30"}, {"price": "0.949", "size": "6239"}, {"price": "0.948", "size": "631.86"}, {"price": "0.92", "size": "300"}, {"price": "0.91", "size": "76.19"}, {"price": "0.909", "size": "5.34"}, {"price": "0.815", "size": "9000"}, {"price": "0.814", "size": "36.86"}, {"price": "0.781", "size": "31.31"}, {"price": "0.78", "size": "5.14"}, {"price": "0.716", "size": "24.14"}, {"price": "0.714", "size": "181"}, {"price": "0.713", "size": "5400.69"}, {"price": "0.712", "size": "400"}, {"price": "0.477", "size": "49"}, {"price": "0.474", "size": "13.03"}, {"price": "0.473", "size": "5"}, {"price": "0.181", "size": "25"}, {"price": "0.177", "size": "10"}, {"price": "0.176", "size": "11.27"}, {"price": "0.053", "size": "13"}, {"price": "0.039", "size": "182.88"}, {"price": "0.038", "size": "42.16"}], "event_type": "book", "last_trade_price": "0.005"}, {"market": "0xeb60a53b5ca38150c07cc30ef0f5570b292f3e43722512cc55d0cff666ac1077", "asset_id": "72088688491610101384722384206165707443638739290798571693187856704797119769987", "timestamp": "1769384327964", "hash": "4e7d80a2efa50a098b50da0deeef200de49bc508", "bids": [], "asks": [{"price": "0.999", "size": "1104252.99"}, {"price": "0.998", "size": "250"}, {"price": "0.997", "size": "400"}, {"price": "0.996", "size": "8.65"}, {"price": "0.994", "size": "200"}, {"price": "0.99", "size": "10"}, {"price": "0.989", "size": "8.75"}, {"price": "0.98", "size": "5000"}, {"price": "0.979", "size": "20700"}, {"price": "0.97", "size": "266.66"}, {"price": "0.969", "size": "7.79"}, {"price": "0.95", "size": "30"}, {"price": "0.949", "size": "656.86"}, {"price": "0.92", "size": "300"}, {"price": "0.916", "size": "95.23"}, {"price": "0.915", "size": "5.82"}, {"price": "0.783", "size": "9000"}, {"price": "0.782", "size": "5.12"}, {"price": "0.777", "size": "45"}, {"price": "0.776", "size": "208.71"}, {"price": "0.747", "size": "13"}, {"price": "0.716", "size": "28.16"}, {"price": "0.715", "size": "7"}, {"price": "0.477", "size": "36"}, {"price": "0.476", "size": "15.26"}, {"price": "0.277", "size": "7"}, {"price": "0.177", "size": "6"}, {"price": "0.138", "size": "10"}, {"price": "0.137", "size": "25"}, {"price": "0.049", "size": "20"}, {"price": "0.048", "size": "11"}, {"price": "0.047", "size": "20"}, {"price": "0.005", "size": "86.85"}, {"price": "0.004", "size": "293.86"}], "event_type": "book", "last_trade_price": ""}, {"market": "0x82bd65f09e2428042a5ac204f60f34e1b40f7a4a2d008fc0b92afd0aca450607", "asset_id": "110679481699383362322327302278895149696397996918330653214772805833135400912448", "timestamp": "1769384327565", "hash": "e808737b9501358fbe7b8da8794b8b4387520e2b", "bids": [{"price": "0.001", "size": "1104251.99"}, {"price": "0.002", "size": "250"}, {"price": "0.003", "size": "400"}, {"price": "0.004", "size": "8.65"}, {"price": "0.006", "size": "200"}, {"price": "0.01", "size": "30010"}, {"price": "0.011", "size": "5.33"}, {"price": "0.021", "size": "12700"}, {"price": "0.022", "size": "311.68"}, {"price": "0.023", "size": "12.13"}, {"price": "0.05", "size": "530"}, {"price": "0.051", "size": "39"}, {"price": "0.071", "size": "3300"}, {"price": "0.072", "size": "95.23"}, {"price": "0.08", "size": "300"}, {"price": "0.081", "size": "5.07"}, {"price": "0.1", "size": "34"}, {"price": "0.101", "size": "67.89"}, {"price": "0.11", "size": "27"}, {"price": "0.111", "size": "61.77"}, {"price": "0.213", "size": "32.19"}, {"price": "0.214", "size": "5.61"}, {"price": "0.223", "size": "21"}, {"price": "0.224", "size": "30.61"}, {"price": "0.512", "size": "298"}, {"price": "0.581", "size": "11.8"}, {"price": "0.586", "size": "5"}, {"price": "0.595", "size": "25"}, {"price": "0.596", "size": "20"}, {"price": "0.597", "size": "11.27"}, {"price": "0.951", "size": "13.33"}, {"price": "0.991", "size": "5.59"}, {"price": "0.996", "size": "6.28"}, {"price": "0.997", "size": "35.59"}, {"price": "0.998", "size": "626.96"}], "asks": [{"price": "0.999", "size": "1949.26"}], "event_type": "book", "last_trade_price": "0.001"}, {"market": "0x936a5e78fd5963c717e49661a593fa3353241f6fb3c69b6615e9041e6b6f0973", "asset_id": "85450186084380419372744179618618425905211867206934194164904272142040477321142", "timestamp": "1769384329730", "hash": "a3c9ce5f20ed933d71d149e546b484720c3fe7b9", "bids": [], "asks": [{"price": "0.999", "size": "1104257.99"}, {"price": "0.998", "size": "250"}, {"price": "0.997", "size": "400"}, {"price": "0.996", "size": "8.66"}, {"price": "0.994", "size": "200"}, {"price": "0.99", "size": "10"}, {"price": "0.989", "size": "8.75"}, {"price": "0.979", "size": "12700"}, {"price": "0.97", "size": "266.66"}, {"price": "0.969", "size": "8.06"}, {"price": "0.95", "size": "30"}, {"price": "0.949", "size": "656.86"}, {"price": "0.92", "size": "300"}, {"price": "0.914", "size": "93.02"}, {"price": "0.913", "size": "5.51"}, {"price": "0.786", "size": "20000"}, {"price": "0.785", "size": "37.2"}, {"price": "0.784", "size": "5.2"}, {"price": "0.777", "size": "81"}, {"price": "0.773", "size": "17"}, {"price": "0.772", "size": "35.08"}, {"price": "0.477", "size": "135"}, {"price": "0.442", "size": "189.33"}, {"price": "0.441", "size": "5"}, {"price": "0.177", "size": "73"}, {"price": "0.141", "size": "10"}, {"price": "0.14", "size": "25"}, {"price": "0.049", "size": "20"}, {"price": "0.048", "size": "13.33"}, {"price": "0.005", "size": "90.25"}, {"price": "0.004", "size": "335.79"}, {"price": "0.003", "size": "6.71"}], "event_type": "book", "last_trade_price": ""}, {"market": "0xa8524b512abdab06087228a6a567e74d174e934c7663fc90a7d1327eb2c788d9", "asset_id": "49055250497864430200311069218295353081673530385133803357115424397090163564009", "timestamp": "1769384154962", "hash": "e860304f3f3b3ea92df7c8b26f33afce9c358182", "bids": [{"price": "0.001", "size": "1104251.99"}, {"price": "0.002", "size": "250"}, {"price": "0.003", "size": "400"}, {"price": "0.004", "size": "8.65"}, {"price": "0.006", "size": "200"}, {"price": "0.01", "size": "10"}, {"price": "0.011", "size": "5.29"}, {"price": "0.021", "size": "12700"}, {"price": "0.022", "size": "436.36"}, {"price": "0.023", "size": "9.92"}, {"price": "0.05", "size": "530"}, {"price": "0.051", "size": "39"}, {"price": "0.072", "size": "133.33"}, {"price": "0.073", "size": "5.29"}, {"price": "0.148", "size": "20100"}, {"price": "0.15", "size": "26"}, {"price": "0.17", "size": "56.47"}, {"price": "0.171", "size": "7.47"}, {"price": "0.223", "size": "38"}, {"price": "0.224", "size": "42.85"}, {"price": "0.523", "size": "123"}, {"price": "0.554", "size": "158.24"}, {"price": "0.58", "size": "5"}, {"price": "0.581", "size": "16.52"}, {"price": "0.723", "size": "50"}, {"price": "0.823", "size": "59"}, {"price": "0.824", "size": "25"}, {"price": "0.826", "size": "10"}, {"price": "0.951", "size": "17.73"}, {"price": "0.954", "size": "89.17"}, {"price": "0.997", "size": "147.52"}, {"price": "0.998", "size": "407.42"}], "asks": [{"price": "0.999", "size": "2.27"}], "event_type": "book", "last_trade_price": "0.001"}, {"market": "0xad8e9885ec2473d0ba49c38449dfd4d18ad7c0f7a14625a24865857e18a94850", "asset_id": "40355817413446270517300817460473958731033814018091765438985668051022432561988", "timestamp": "1769384226137", "hash": "89c836e2e3250bbc132d3a6037f360a2232846a1", "bids": [{"price": "0.001", "size": "1169"}, {"price": "0.002", "size": "255"}, {"price": "0.003", "size": "73"}, {"price": "0.004", "size": "237.61"}], "asks": [{"price": "0.999", "size": "1102831.42"}, {"price": "0.998", "size": "250"}, {"price": "0.997", "size": "406.54"}, {"price": "0.994", "size": "200"}, {"price": "0.993", "size": "10.31"}, {"price": "0.99", "size": "10"}, {"price": "0.98", "size": "5000"}, {"price": "0.979", "size": "12700"}, {"price": "0.978", "size": "8.08"}, {"price": "0.971", "size": "275.86"}, {"price": "0.95", "size": "30"}, {"price": "0.949", "size": "39"}, {"price": "0.94", "size": "633.33"}, {"price": "0.939", "size": "9.47"}, {"price": "0.877", "size": "20100"}, {"price": "0.876", "size": "64.51"}, {"price": "0.831", "size": "220"}, {"price": "0.83", "size": "47.05"}, {"price": "0.787", "size": "46.55"}, {"price": "0.786", "size": "5.36"}, {"price": "0.5", "size": "16"}, {"price": "0.484", "size": "10"}, {"price": "0.482", "size": "25"}, {"price": "0.481", "size": "11.27"}, {"price": "0.08", "size": "200"}, {"price": "0.062", "size": "225.38"}, {"price": "0.046", "size": "100"}, {"price": "0.028", "size": "390"}, {"price": "0.02", "size": "64.7"}, {"price": "0.011", "size": "240"}, {"price": "0.009", "size": "23.96"}, {"price": "0.008", "size": "70"}], "event_type": "book", "last_trade_price": "0.004"}, {"market": "0x208c0100d3c9b2e1cfe6acd453a461a2db052ea6de69345e20ba97bd80b24a32", "asset_id": "25190149186348626497584661665153964321010101728496495635131758054890103740875", "timestamp": "1769384330316", "hash": "f72effcefeacb70db46733b4825c45406938d6a0", "bids": [], "asks": [{"price": "0.999", "size": "1102751.99"}, {"price": "0.998", "size": "250"}, {"price": "0.997", "size": "400"}, {"price": "0.996", "size": "8.65"}, {"price": "0.994", "size": "200"}, {"price": "0.993", "size": "30000"}, {"price": "0.99", "size": "10"}, {"price": "0.989", "size": "7.03"}, {"price": "0.974", "size": "1007.69"}, {"price": "0.973", "size": "5.79"}, {"price": "0.95", "size": "30"}, {"price": "0.949", "size": "39"}, {"price": "0.94", "size": "633.33"}, {"price": "0.939", "size": "7.83"}, {"price": "0.92", "size": "300"}, {"price": "0.895", "size": "38"}, {"price": "0.894", "size": "75.47"}, {"price": "0.819", "size": "44.19"}, {"price": "0.818", "size": "6.8"}, {"price": "0.777", "size": "37"}, {"price": "0.776", "size": "35.71"}, {"price": "0.5", "size": "222"}, {"price": "0.477", "size": "135"}, {"price": "0.476", "size": "5"}, {"price": "0.475", "size": "15.23"}, {"price": "0.277", "size": "7"}, {"price": "0.177", "size": "6"}, {"price": "0.141", "size": "10"}, {"price": "0.14", "size": "25"}, {"price": "0.049", "size": "5"}, {"price": "0.048", "size": "11"}, {"price": "0.047", "size": "20"}, {"price": "0.003", "size": "61.35"}, {"price": "0.002", "size": "551.19"}], "event_type": "book", "last_trade_price": "0.001"}, {"market": "0x208c0100d3c9b2e1cfe6acd453a461a2db052ea6de69345e20ba97bd80b24a32", "asset_id": "50847646174397103153022714653544400551806761556088789644031638820781566442427", "timestamp": "1769384330316", "hash": "e26871395ba762d8da85f279b07fe5cca39b85ec", "bids": [{"price": "0.001", "size": "1102751.99"}, {"price": "0.002", "size": "250"}, {"price": "0.003", "size": "400"}, {"price": "0.004", "size": "8.65"}, {"price": "0.006", "size": "200"}, {"price": "0.007", "size": "30000"}, {"price": "0.01", "size": "10"}, {"price": "0.011", "size": "7.03"}, {"price": "0.026", "size": "1007.69"}, {"price": "0.027", "size": "5.79"}, {"price": "0.05", "size": "30"}, {"price": "0.051", "size": "39"}, {"price": "0.06", "size": "633.33"}, {"price": "0.061", "size": "7.83"}, {"price": "0.08", "size": "300"}, {"price": "0.105", "size": "38"}, {"price": "0.106", "size": "75.47"}, {"price": "0.181", "size": "44.19"}, {"price": "0.182", "size": "6.8"}, {"price": "0.223", "size": "37"}, {"price": "0.224", "size": "35.71"}, {"price": "0.5", "size": "222"}, {"price": "0.523", "size": "135"}, {"price": "0.524", "size": "5"}, {"price": "0.525", "size": "15.23"}, {"price": "0.723", "size": "7"}, {"price": "0.823", "size": "6"}, {"price": "0.859", "size": "10"}, {"price": "0.86", "size": "25"}, {"price": "0.951", "size": "5"}, {"price": "0.952", "size": "11"}, {"price": "0.953", "size": "20"}, {"price": "0.997", "size": "61.35"}, {"price": "0.998", "size": "551.19"}], "asks": [], "event_type": "book", "last_trade_price": "0.001"}, {"market": "0xcdc395263072e4727246bd28d628c79de9ef6024b9c78ae6d230fb542300d783", "asset_id": "48368309662638112013465916577402564922962355069006784733061258856322807009058", "timestamp": "1769384329408", "hash": "e99217512222acaa821f6b7ddd1cf949efc0cde6", "bids": [], "asks": [{"price": "0.999", "size": "1101515"}, {"price": "0.998", "size": "22.3"}, {"price": "0.99", "size": "10"}, {"price": "0.989", "size": "60005.73"}, {"price": "0.977", "size": "521.73"}, {"price": "0.976", "size": "7.48"}, {"price": "0.96", "size": "7000"}, {"price": "0.94", "size": "200"}, {"price": "0.938", "size": "750"}, {"price": "0.937", "size": "195.48"}, {"price": "0.89", "size": "300"}, {"price": "0.861", "size": "86.33"}, {"price": "0.86", "size": "9.94"}, {"price": "0.488", "size": "6000"}, {"price": "0.454", "size": "222"}, {"price": "0.452", "size": "21.89"}, {"price": "0.451", "size": "304"}, {"price": "0.071", "size": "44"}, {"price": "0.07", "size": "13"}, {"price": "0.005", "size": "30"}, {"price": "0.002", "size": "131.8"}, {"price": "0.001", "size": "149.16"}], "event_type": "book", "last_trade_price": ""}, {"market": "0x5882bfbb3333c4425fe5f17d7177d0155935ab218532e30abb3ebc29e09b0d15", "asset_id": "98286904268100078035776152708720247190143751657794196422985487083520781931503", "timestamp": "1769384357998", "hash": "472151a7497201c09afd77e5973cfc498c731666", "bids": [{"price": "0.001", "size": "3778.8"}], "asks": [{"price": "0.999", "size": "1104355.07"}, {"price": "0.998", "size": "250"}, {"price": "0.997", "size": "400"}, {"price": "0.996", "size": "9.03"}, {"price": "0.994", "size": "200"}, {"price": "0.99", "size": "10"}, {"price": "0.989", "size": "8.16"}, {"price": "0.98", "size": "5000"}, {"price": "0.979", "size": "15000"}, {"price": "0.97", "size": "228.57"}, {"price": "0.969", "size": "7.11"}, {"price": "0.95", "size": "30"}, {"price": "0.949", "size": "39"}, {"price": "0.948", "size": "631.86"}, {"price": "0.921", "size": "86.79"}, {"price": "0.92", "size": "6.13"}, {"price": "0.818", "size": "12000"}, {"price": "0.791", "size": "32.8"}, {"price": "0.79", "size": "5.45"}, {"price": "0.777", "size": "88"}, {"price": "0.771", "size": "17"}, {"price": "0.77", "size": "29.81"}, {"price": "0.685", "size": "21.76"}, {"price": "0.684", "size": "6"}, {"price": "0.477", "size": "24"}, {"price": "0.476", "size": "13.08"}, {"price": "0.277", "size": "50"}, {"price": "0.177", "size": "59"}, {"price": "0.175", "size": "10"}, {"price": "0.174", "size": "11.27"}, {"price": "0.077", "size": "57"}, {"price": "0.072", "size": "44"}, {"price": "0.048", "size": "13"}, {"price": "0.003", "size": "14.54"}, {"price": "0.002", "size": "82.41"}], "event_type": "book", "last_trade_price": "0.001"}, {"market": "0x3ab6710aff85c354a3d99e0f3c972903263189ce32b1a5b13ed58cb68762b243", "asset_id": "51021073159046014273765711044237457499013035764061127438623007427221796941192", "timestamp": "1769384206877", "hash": "3e664c98c5f49a76ca8dde9707936a2fb6d66a80", "bids": [{"price": "0.001", "size": "1104251.99"}, {"price": "0.002", "size": "250"}, {"price": "0.003", "size": "400"}, {"price": "0.004", "size": "8.66"}, {"price": "0.006", "size": "200"}, {"price": "0.01", "size": "30010"}, {"price": "0.011", "size": "10.89"}, {"price": "0.021", "size": "13000"}, {"price": "0.035", "size": "228.57"}, {"price": "0.036", "size": "6.65"}, {"price": "0.05", "size": "30"}, {"price": "0.051", "size": "12739"}, {"price": "0.06", "size": "200"}, {"price": "0.061", "size": "131.14"}, {"price": "0.089", "size": "89.88"}, {"price": "0.09", "size": "5.37"}, {"price": "0.11", "size": "300"}, {"price": "0.111", "size": "72.07"}, {"price": "0.22", "size": "21000"}, {"price": "0.221", "size": "5.01"}, {"price": "0.223", "size": "295"}, {"price": "0.225", "size": "17"}, {"price": "0.229", "size": "8"}, {"price": "0.23", "size": "34.78"}, {"price": "0.523", "size": "57"}, {"price": "0.524", "size": "15.26"}, {"price": "0.823", "size": "73"}, {"price": "0.842", "size": "25"}, {"price": "0.844", "size": "291"}, {"price": "0.845", "size": "11.27"}, {"price": "0.951", "size": "13"}, {"price": "0.995", "size": "36.22"}, {"price": "0.996", "size": "63.61"}, {"price": "0.998", "size": "1013.26"}], "asks": [{"price": "0.999", "size": "66.25"}], "event_type": "book", "last_trade_price": "0.001"}, {"market": "0xc5a5599959ff15ca3533656c16dd441304b8721162ef770db59a1d2b4862e2b8", "asset_id": "48279448787839069698930026835059287278898209340746904712996610649334841531409", "timestamp": "1769384334560", "hash": "31e102313a80e180d057cc7cec1d0d0b021a7d4a", "bids": [{"price": "0.001", "size": "1104252.99"}, {"price": "0.002", "size": "250"}, {"price": "0.003", "size": "400"}, {"price": "0.004", "size": "8.65"}, {"price": "0.006", "size": "200"}, {"price": "0.007", "size": "30000"}, {"price": "0.01", "size": "10"}, {"price": "0.011", "size": "8.75"}, {"price": "0.021", "size": "12700"}, {"price": "0.03", "size": "266.66"}, {"price": "0.031", "size": "7.79"}, {"price": "0.05", "size": "30"}, {"price": "0.051", "size": "656.86"}, {"price": "0.08", "size": "300"}, {"price": "0.084", "size": "95.23"}, {"price": "0.085", "size": "5.78"}, {"price": "0.216", "size": "12000"}, {"price": "0.217", "size": "5.16"}, {"price": "0.223", "size": "68"}, {"price": "0.224", "size": "35.71"}, {"price": "0.253", "size": "15"}, {"price": "0.254", "size": "31.49"}, {"price": "0.523", "size": "135"}, {"price": "0.564", "size": "176.18"}, {"price": "0.565", "size": "5"}, {"price": "0.823", "size": "73"}, {"price": "0.873", "size": "10"}, {"price": "0.874", "size": "25"}, {"price": "0.951", "size": "32"}, {"price": "0.952", "size": "20"}, {"price": "0.995", "size": "91.79"}, {"price": "0.996", "size": "344.51"}], "asks": [], "event_type": "book", "last_trade_price": ""}, {"market": "0x5bc6ce968259b72cf129f3420b74591165b2daed5681c945a550d3479a6cd29f", "asset_id": "75885549806041705440616483171403974382986377202053531674757984617564016983448", "timestamp": "1769384332521", "hash": "d866c0e89bfa2e951b9d01ab2b2effc66dc69e2e", "bids": [{"price": "0.001", "size": "370.27"}], "asks": [{"price": "0.999", "size": "1104293.99"}, {"price": "0.998", "size": "250"}, {"price": "0.997", "size": "400"}, {"price": "0.996", "size": "8.42"}, {"price": "0.994", "size": "200"}, {"price": "0.99", "size": "10"}, {"price": "0.989", "size": "8.51"}, {"price": "0.98", "size": "5000"}, {"price": "0.979", "size": "20700"}, {"price": "0.97", "size": "266.66"}, {"price": "0.969", "size": "7.04"}, {"price": "0.95", "size": "30"}, {"price": "0.949", "size": "39"}, {"price": "0.948", "size": "653.84"}, {"price": "0.92", "size": "300"}, {"price": "0.919", "size": "5.22"}, {"price": "0.916", "size": "95.23"}, {"price": "0.813", "size": "15000"}, {"price": "0.806", "size": "41.23"}, {"price": "0.805", "size": "6.26"}, {"price": "0.777", "size": "63"}, {"price": "0.768", "size": "17"}, {"price": "0.767", "size": "34.33"}, {"price": "0.5", "size": "77"}, {"price": "0.477", "size": "135"}, {"price": "0.474", "size": "15.2"}, {"price": "0.473", "size": "5"}, {"price": "0.277", "size": "56"}, {"price": "0.177", "size": "5"}, {"price": "0.174", "size": "10"}, {"price": "0.113", "size": "25"}, {"price": "0.112", "size": "11.27"}, {"price": "0.077", "size": "12"}, {"price": "0.049", "size": "18.33"}, {"price": "0.043", "size": "185.72"}, {"price": "0.014", "size": "8.88"}, {"price": "0.005", "size": "27.94"}, {"price": "0.004", "size": "107.34"}], "event_type": "book", "last_trade_price": "0.001"}, {"market": "0x00787f50b9466db23a1899abc108b5609a77cbaa159c1b35822f45e9c14a940b", "asset_id": "76794312778172154876533172710848055841220591544022724903757628442504975481665", "timestamp": "1769384337562", "hash": "96d3368fcacb7e2b09cfb63d84fc20748632b1f8", "bids": [{"price": "0.001", "size": "147.27"}], "asks": [{"price": "0.999", "size": "1104252.01"}, {"price": "0.998", "size": "250"}, {"price": "0.997", "size": "400"}, {"price": "0.996", "size": "8.68"}, {"price": "0.994", "size": "200"}, {"price": "0.99", "size": "30010"}, {"price": "0.989", "size": "5.74"}, {"price": "0.979", "size": "12700"}, {"price": "0.975", "size": "384"}, {"price": "0.974", "size": "6.05"}, {"price": "0.95", "size": "30"}, {"price": "0.949", "size": "6539"}, {"price": "0.941", "size": "162.71"}, {"price": "0.94", "size": "5.51"}, {"price": "0.871", "size": "20100"}, {"price": "0.868", "size": "5"}, {"price": "0.861", "size": "69.06"}, {"price": "0.86", "size": "9.99"}, {"price": "0.777", "size": "25"}, {"price": "0.776", "size": "42.85"}, {"price": "0.477", "size": "263"}, {"price": "0.47", "size": "18.11"}, {"price": "0.469", "size": "5"}, {"price": "0.277", "size": "5"}, {"price": "0.14", "size": "10"}, {"price": "0.138", "size": "25"}, {"price": "0.137", "size": "11.27"}, {"price": "0.049", "size": "13.33"}, {"price": "0.033", "size": "130"}, {"price": "0.005", "size": "10"}, {"price": "0.003", "size": "104.64"}, {"price": "0.002", "size": "452.34"}], "event_type": "book", "last_trade_price": "0.001"}, {"market": "0xe819c3fd02eec251efec7d90a1801554ec14fef336932c7342b333d4ae64d0a8", "asset_id": "99877125227544421735443256554390914792518157728590758473713836440156917197132", "timestamp": "1769384154426", "hash": "7a5884fc4b286e2c5a8312f67d82028dfd260530", "bids": [{"price": "0.001", "size": "1104242.04"}, {"price": "0.002", "size": "255.14"}, {"price": "0.003", "size": "400"}, {"price": "0.004", "size": "5.11"}, {"price": "0.006", "size": "200"}, {"price": "0.007", "size": "60000"}, {"price": "0.01", "size": "10"}, {"price": "0.011", "size": "5.33"}, {"price": "0.021", "size": "13000"}, {"price": "0.03", "size": "266.66"}, {"price": "0.031", "size": "11.51"}, {"price": "0.05", "size": "30"}, {"price": "0.06", "size": "33"}, {"price": "0.061", "size": "631.14"}, {"price": "0.08", "size": "300"}, {"price": "0.108", "size": "74.07"}, {"price": "0.109", "size": "73.39"}, {"price": "0.11", "size": "14.07"}, {"price": "0.223", "size": "37"}, {"price": "0.247", "size": "9000"}, {"price": "0.248", "size": "25"}, {"price": "0.249", "size": "13"}, {"price": "0.25", "size": "32"}, {"price": "0.266", "size": "30.07"}, {"price": "0.267", "size": "7"}, {"price": "0.823", "size": "69"}, {"price": "0.829", "size": "10"}, {"price": "0.83", "size": "11.27"}, {"price": "0.91", "size": "248.63"}, {"price": "0.911", "size": "290.4"}, {"price": "0.912", "size": "25"}, {"price": "0.94", "size": "80"}, {"price": "0.941", "size": "30.64"}, {"price": "0.945", "size": "37.08"}], "asks": [{"price": "0.999", "size": "22.79"}, {"price": "0.998", "size": "161.31"}, {"price": "0.993", "size": "170.4"}, {"price": "0.992", "size": "256.6"}, {"price": "0.991", "size": "147.2"}], "event_type": "book", "last_trade_price": "0.960"}, {"market": "0xbba1c02a186676782fae38b63af5333da443c8a16d86274ba1b045324ec989c7", "asset_id": "58144744252589479691808124143280036251902716811429258360320338495684055413095", "timestamp": "1769384338322", "hash": "5e2d7db1a94cf8867b1c4a4f30da38a386d3accc", "bids": [{"price": "0.001", "size": "1104337.87"}, {"price": "0.002", "size": "250"}, {"price": "0.003", "size": "400"}, {"price": "0.004", "size": "8.65"}, {"price": "0.006", "size": "200"}, {"price": "0.01", "size": "10"}, {"price": "0.011", "size": "7.03"}, {"price": "0.02", "size": "5000"}, {"price": "0.021", "size": "20700"}, {"price": "0.026", "size": "263.73"}, {"price": "0.027", "size": "9.96"}, {"price": "0.05", "size": "30"}, {"price": "0.051", "size": "39"}, {"price": "0.052", "size": "631.86"}, {"price": "0.08", "size": "300"}, {"price": "0.086", "size": "79.73"}, {"price": "0.087", "size": "5.17"}, {"price": "0.177", "size": "20000"}, {"price": "0.178", "size": "38.52"}, {"price": "0.206", "size": "33.28"}, {"price": "0.207", "size": "5.57"}, {"price": "0.223", "size": "40"}, {"price": "0.245", "size": "14"}, {"price": "0.246", "size": "27.87"}, {"price": "0.5", "size": "14"}, {"price": "0.523", "size": "56"}, {"price": "0.562", "size": "178"}, {"price": "0.563", "size": "5"}, {"price": "0.564", "size": "12.15"}, {"price": "0.823", "size": "67"}, {"price": "0.826", "size": "25"}, {"price": "0.827", "size": "20"}, {"price": "0.951", "size": "5"}, {"price": "0.952", "size": "11"}, {"price": "0.953", "size": "20"}, {"price": "0.995", "size": "45.98"}, {"price": "0.996", "size": "90.59"}], "asks": [], "event_type": "book", "last_trade_price": "0.001"}, {"market": "0x1dcc183b4cca17ebd95af1b94209ce345233d13a8157c1b1761b6d82722614aa", "asset_id": "105584168793006337391660846202014742593893506579636126851936010970644475175057", "timestamp": "1769384334562", "hash": "1e2be8b7559bf749a0a547768f23ac12aeab9662", "bids": [{"price": "0.001", "size": "1102828.88"}, {"price": "0.002", "size": "257.48"}, {"price": "0.003", "size": "400"}, {"price": "0.004", "size": "60000"}, {"price": "0.005", "size": "5.93"}, {"price": "0.006", "size": "200"}, {"price": "0.01", "size": "10"}, {"price": "0.011", "size": "7.03"}, {"price": "0.021", "size": "12700"}, {"price": "0.026", "size": "369.23"}, {"price": "0.027", "size": "5.95"}, {"price": "0.05", "size": "30"}, {"price": "0.051", "size": "39"}, {"price": "0.061", "size": "657.37"}, {"price": "0.062", "size": "5.47"}, {"price": "0.113", "size": "30100"}, {"price": "0.144", "size": "66.66"}, {"price": "0.145", "size": "9.46"}, {"price": "0.223", "size": "45"}, {"price": "0.224", "size": "136.85"}, {"price": "0.225", "size": "21"}, {"price": "0.523", "size": "135"}, {"price": "0.556", "size": "5"}, {"price": "0.557", "size": "17.23"}, {"price": "0.823", "size": "73"}, {"price": "0.862", "size": "10"}, {"price": "0.863", "size": "25"}, {"price": "0.951", "size": "14.83"}, {"price": "0.952", "size": "11"}, {"price": "0.953", "size": "20"}, {"price": "0.995", "size": "57.52"}, {"price": "0.996", "size": "150.3"}], "asks": [], "event_type": "book", "last_trade_price": "0.001"}, {"market": "0xd2b7235e5c612ce49ad0252420d713280ded4e346bd24dd50f941e901e9daec2", "asset_id": "110558202691925957098835226242947976618291676693360525080400622291263590296356", "timestamp": "1769383924712", "hash": "80a5636ab58430e6023b18d69f336455bf8410de", "bids": [{"price": "0.001", "size": "1104258"}, {"price": "0.002", "size": "250"}, {"price": "0.003", "size": "406.63"}, {"price": "0.004", "size": "90000"}, {"price": "0.006", "size": "200"}, {"price": "0.007", "size": "10.46"}, {"price": "0.01", "size": "10"}, {"price": "0.021", "size": "12700"}, {"price": "0.022", "size": "6.57"}, {"price": "0.032", "size": "300"}, {"price": "0.05", "size": "30"}, {"price": "0.051", "size": "39"}, {"price": "0.052", "size": "684.61"}, {"price": "0.053", "size": "12.17"}, {"price": "0.094", "size": "402.12"}, {"price": "0.22", "size": "12000"}, {"price": "0.221", "size": "5.01"}, {"price": "0.223", "size": "35"}, {"price": "0.225", "size": "21"}, {"price": "0.226", "size": "42.47"}, {"price": "0.523", "size": "28"}, {"price": "0.535", "size": "243.94"}, {"price": "0.536", "size": "20"}, {"price": "0.823", "size": "5"}, {"price": "0.914", "size": "10"}, {"price": "0.915", "size": "25"}, {"price": "0.951", "size": "5"}, {"price": "0.953", "size": "20"}, {"price": "0.995", "size": "282.84"}, {"price": "0.996", "size": "12.18"}, {"price": "0.997", "size": "390.67"}], "asks": [{"price": "0.999", "size": "11.27"}], "event_type": "book", "last_trade_price": "0.001"}, {"market": "0x5bc6ce968259b72cf129f3420b74591165b2daed5681c945a550d3479a6cd29f", "asset_id": "13658847648110704810290854236711050722034916311708159351742514374794523650635", "timestamp": "1769384332521", "hash": "471e7ec71edaee3f69bfab3b03ee68060066b7cf", "bids": [{"price": "0.001", "size": "1104293.99"}, {"price": "0.002", "size": "250"}, {"price": "0.003", "size": "400"}, {"price": "0.004", "size": "8.42"}, {"price": "0.006", "size": "200"}, {"price": "0.01", "size": "10"}, {"price": "0.011", "size": "8.51"}, {"price": "0.02", "size": "5000"}, {"price": "0.021", "size": "20700"}, {"price": "0.03", "size": "266.66"}, {"price": "0.031", "size": "7.04"}, {"price": "0.05", "size": "30"}, {"price": "0.051", "size": "39"}, {"price": "0.052", "size": "653.84"}, {"price": "0.08", "size": "300"}, {"price": "0.081", "size": "5.22"}, {"price": "0.084", "size": "95.23"}, {"price": "0.187", "size": "15000"}, {"price": "0.194", "size": "41.23"}, {"price": "0.195", "size": "6.26"}, {"price": "0.223", "size": "63"}, {"price": "0.232", "size": "17"}, {"price": "0.233", "size": "34.33"}, {"price": "0.5", "size": "77"}, {"price": "0.523", "size": "135"}, {"price": "0.526", "size": "15.2"}, {"price": "0.527", "size": "5"}, {"price": "0.723", "size": "56"}, {"price": "0.823", "size": "5"}, {"price": "0.826", "size": "10"}, {"price": "0.887", "size": "25"}, {"price": "0.888", "size": "11.27"}, {"price": "0.923", "size": "12"}, {"price": "0.951", "size": "18.33"}, {"price": "0.957", "size": "185.72"}, {"price": "0.986", "size": "8.88"}, {"price": "0.995", "size": "27.94"}, {"price": "0.996", "size": "107.34"}], "asks": [{"price": "0.999", "size": "370.27"}], "event_type": "book", "last_trade_price": "0.001"}, {"market": "0xc8ef5adf237853872e232fc6d66b334ea04092b9623d2c2549ab5f7edd9aeab4", "asset_id": "25277497216382451485326536999700670257859779459456782057859411238134991818794", "timestamp": "1769384157135", "hash": "d8972a7756c16597c55d211806a0973c5e6a4fb4", "bids": [{"price": "0.001", "size": "1102757.15"}, {"price": "0.002", "size": "250"}, {"price": "0.003", "size": "400"}, {"price": "0.004", "size": "8.67"}, {"price": "0.006", "size": "200"}, {"price": "0.01", "size": "40010"}, {"price": "0.011", "size": "5.3"}, {"price": "0.021", "size": "12700"}, {"price": "0.03", "size": "228.57"}, {"price": "0.031", "size": "7.39"}, {"price": "0.05", "size": "30"}, {"price": "0.051", "size": "39"}, {"price": "0.052", "size": "631.86"}, {"price": "0.08", "size": "85.71"}, {"price": "0.081", "size": "5.52"}, {"price": "0.115", "size": "20100"}, {"price": "0.116", "size": "59.11"}, {"price": "0.195", "size": "35.16"}, {"price": "0.196", "size": "6.19"}, {"price": "0.223", "size": "62"}, {"price": "0.241", "size": "85"}, {"price": "0.242", "size": "28.33"}, {"price": "0.523", "size": "238"}, {"price": "0.538", "size": "12.74"}, {"price": "0.539", "size": "5"}, {"price": "0.723", "size": "18"}, {"price": "0.818", "size": "25"}, {"price": "0.822", "size": "10"}, {"price": "0.823", "size": "11.27"}, {"price": "0.951", "size": "5"}, {"price": "0.952", "size": "11"}, {"price": "0.953", "size": "20"}, {"price": "0.996", "size": "70.88"}, {"price": "0.997", "size": "365.95"}], "asks": [{"price": "0.999", "size": "215.56"}], "event_type": "book", "last_trade_price": "0.001"}, {"market": "0x4fc188ab7b8337089312087777af8a703757466dda919e1de85e148394c40090", "asset_id": "67034694271202563859644094265338465614375382145815138322023215311029487392827", "timestamp": "1769384332528", "hash": "6d55b588359844fc16f037fd731b64c5ec3630dc", "bids": [{"price": "0.001", "size": "1104294.88"}, {"price": "0.002", "size": "250"}, {"price": "0.003", "size": "406.63"}, {"price": "0.006", "size": "200"}, {"price": "0.007", "size": "10.45"}, {"price": "0.01", "size": "30010"}, {"price": "0.021", "size": "12700"}, {"price": "0.022", "size": "6.15"}, {"price": "0.032", "size": "250"}, {"price": "0.05", "size": "30"}, {"price": "0.051", "size": "3044.02"}, {"price": "0.052", "size": "653.84"}, {"price": "0.08", "size": "300"}, {"price": "0.081", "size": "98.76"}, {"price": "0.11", "size": "72.72"}, {"price": "0.111", "size": "13.55"}, {"price": "0.222", "size": "9000"}, {"price": "0.223", "size": "31"}, {"price": "0.224", "size": "35.71"}, {"price": "0.251", "size": "78"}, {"price": "0.253", "size": "15"}, {"price": "0.523", "size": "56"}, {"price": "0.526", "size": "15.2"}, {"price": "0.527", "size": "5"}, {"price": "0.723", "size": "7"}, {"price": "0.823", "size": "6"}, {"price": "0.824", "size": "10"}, {"price": "0.923", "size": "119"}, {"price": "0.924", "size": "25"}, {"price": "0.951", "size": "14.83"}, {"price": "0.952", "size": "11"}, {"price": "0.953", "size": "20"}, {"price": "0.995", "size": "27.39"}, {"price": "0.996", "size": "104.21"}], "asks": [], "event_type": "book", "last_trade_price": "0.001"}]}
{"_local_timestamp": "2026-01-25T23:40:43.575740+00:00", "data": {"market": "0x3ab6710aff85c354a3d99e0f3c972903263189ce32b1a5b13ed58cb68762b243", "price_changes": [{"asset_id": "51021073159046014273765711044237457499013035764061127438623007427221796941192", "price": "0.229", "size": "0", "side": "BUY", "hash": "28ccd812aa7dfd90d5cd86f73af2017073e9389d", "best_bid": "0.998", "best_ask": "0.999"}, {"asset_id": "12436606244684756212688349482021343426028351538039522454366335615620119043815", "price": "0.771", "size": "0", "side": "SELL", "hash": "ecf6af04ff4c8f725bc70c86bb8d3a40de129250", "best_bid": "0.001", "best_ask": "0.002"}], "timestamp": "1769384443503", "event_type": "price_change"}}
{"_local_timestamp": "2026-01-25T23:40:43.643400+00:00", "data": {"market": "0x3ab6710aff85c354a3d99e0f3c972903263189ce32b1a5b13ed58cb68762b243", "price_changes": [{"asset_id": "51021073159046014273765711044237457499013035764061127438623007427221796941192", "price": "0.231", "size": "8", "side": "BUY", "hash": "0805f39deb09473a24b74089e57e596acc51b71c", "best_bid": "0.998", "best_ask": "0.999"}, {"asset_id": "12436606244684756212688349482021343426028351538039522454366335615620119043815", "price": "0.769", "size": "8", "side": "SELL", "hash": "81b7da02cca9f1c7558a2129f4c069518c8c346e", "best_bid": "0.001", "best_ask": "0.002"}], "timestamp": "1769384443561", "event_type": "price_change"}}
{"_local_timestamp": "2026-01-25T23:41:50.158957+00:00", "data": {"market": "0xa449cd8346b6deda561828355ae92b88bd47d989859d2d287ce7e42a42b556c7", "price_changes": [{"asset_id": "91120885899126885515852202682357546652544305953593660618778514157513430201648", "price": "0.03", "size": "250", "side": "BUY", "hash": "34d181b5bd5088827ea4dd30f5809d08a8638620", "best_bid": "0.06", "best_ask": "0.09"}, {"asset_id": "50990718602111286221499412828092223474799500548329402570398939983325937296388", "price": "0.97", "size": "250", "side": "SELL", "hash": "d530eaeeb0f29a5259ced1258ffcb937791fca37", "best_bid": "0.91", "best_ask": "0.94"}], "timestamp": "1769384510083", "event_type": "price_change"}}
{"_local_timestamp": "2026-01-25T23:41:50.159996+00:00", "data": {"market": "0xa449cd8346b6deda561828355ae92b88bd47d989859d2d287ce7e42a42b556c7", "price_changes": [{"asset_id": "91120885899126885515852202682357546652544305953593660618778514157513430201648", "price": "0.04", "size": "1070.9", "side": "BUY", "hash": "34d181b5bd5088827ea4dd30f5809d08a8638620", "best_bid": "0.06", "best_ask": "0.09"}, {"asset_id": "50990718602111286221499412828092223474799500548329402570398939983325937296388", "price": "0.96", "size": "1070.9", "side": "SELL", "hash": "d530eaeeb0f29a5259ced1258ffcb937791fca37", "best_bid": "0.91", "best_ask": "0.94"}], "timestamp": "1769384510083", "event_type": "price_change"}}
{"_local_timestamp": "2026-01-25T23:41:50.160348+00:00", "data": {"market": "0xa449cd8346b6deda561828355ae92b88bd47d989859d2d287ce7e42a42b556c7", "price_changes": [{"asset_id": "91120885899126885515852202682357546652544305953593660618778514157513430201648", "price": "0.05", "size": "169.86", "side": "BUY", "hash": "34d181b5bd5088827ea4dd30f5809d08a8638620", "best_bid": "0.06", "best_ask": "0.09"}, {"asset_id": "50990718602111286221499412828092223474799500548329402570398939983325937296388", "price": "0.95", "size": "169.86", "side": "SELL", "hash": "d530eaeeb0f29a5259ced1258ffcb937791fca37", "best_bid": "0.91", "best_ask": "0.94"}], "timestamp": "1769384510083", "event_type": "price_change"}}
{"_local_timestamp": "2026-01-25T23:41:50.668944+00:00", "data": {"market": "0xa449cd8346b6deda561828355ae92b88bd47d989859d2d287ce7e42a42b556c7", "price_changes": [{"asset_id": "91120885899126885515852202682357546652544305953593660618778514157513430201648", "price": "0.05", "size": "178.6", "side": "BUY", "hash": "95ae3e6e44498eeac31597bd8636efa32bc44f57", "best_bid": "0.06", "best_ask": "0.09"}, {"asset_id": "50990718602111286221499412828092223474799500548329402570398939983325937296388", "price": "0.95", "size": "178.6", "side": "SELL", "hash": "817486af96f1f106433ea12bd68e1ddb4eaef9d0", "best_bid": "0.91", "best_ask": "0.94"}], "timestamp": "1769384510592", "event_type": "price_change"}}
{"_local_timestamp": "2026-01-25T23:41:50.670226+00:00", "data": {"market": "0xa449cd8346b6deda561828355ae92b88bd47d989859d2d287ce7e42a42b556c7", "price_changes": [{"asset_id": "91120885899126885515852202682357546652544305953593660618778514157513430201648", "price": "0.04", "size": "1082.04", "side": "BUY", "hash": "78cb2db7dbf168ceb27748c037915b1e914001c5", "best_bid": "0.06", "best_ask": "0.09"}, {"asset_id": "50990718602111286221499412828092223474799500548329402570398939983325937296388", "price": "0.96", "size": "1082.04", "side": "SELL", "hash": "6d6389f6d80153818282ab94f77daa572f1168ce", "best_bid": "0.91", "best_ask": "0.94"}], "timestamp": "1769384510593", "event_type": "price_change"}}
{"_local_timestamp": "2026-01-25T23:41:50.671387+00:00", "data": {"market": "0xa449cd8346b6deda561828355ae92b88bd47d989859d2d287ce7e42a42b556c7", "price_changes": [{"asset_id": "91120885899126885515852202682357546652544305953593660618778514157513430201648", "price": "0.06", "size": "21.06", "side": "BUY", "hash": "17674a36a91f1eb18399f6fbf0efeebbdd3ead95", "best_bid": "0.06", "best_ask": "0.09"}, {"asset_id": "50990718602111286221499412828092223474799500548329402570398939983325937296388", "price": "0.94", "size": "21.06", "side": "SELL", "hash": "aad9c785d35b31209504a2869ce67470fa45e957", "best_bid": "0.91", "best_ask": "0.94"}], "timestamp": "1769384510594", "event_type": "price_change"}}
{"_local_timestamp": "2026-01-25T23:41:50.671852+00:00", "data": {"market": "0xa449cd8346b6deda561828355ae92b88bd47d989859d2d287ce7e42a42b556c7", "price_changes": [{"asset_id": "91120885899126885515852202682357546652544305953593660618778514157513430201648", "price": "0.03", "size": "265.16", "side": "BUY", "hash": "c0a0e563f21302a119557b7e6f7ec4d23e917d43", "best_bid": "0.06", "best_ask": "0.09"}, {"asset_id": "50990718602111286221499412828092223474799500548329402570398939983325937296388", "price": "0.97", "size": "265.16", "side": "SELL", "hash": "a1e839dc47bd1831a4dac4c759657849af3f909c", "best_bid": "0.91", "best_ask": "0.94"}], "timestamp": "1769384510596", "event_type": "price_change"}}
{"_local_timestamp": "2026-01-25T23:41:51.991746+00:00", "data": {"market": "0xa449cd8346b6deda561828355ae92b88bd47d989859d2d287ce7e42a42b556c7", "price_changes": [{"asset_id": "91120885899126885515852202682357546652544305953593660618778514157513430201648", "price": "0.06", "size": "13.93", "side": "BUY", "hash": "9694b2360bf3e399bcc49acb8140473a5e39d214", "best_bid": "0.06", "best_ask": "0.09"}, {"asset_id": "50990718602111286221499412828092223474799500548329402570398939983325937296388", "price": "0.94", "size": "13.93", "side": "SELL", "hash": "3fc08e476430bfeb9e6b4631092b40e84a300a99", "best_bid": "0.91", "best_ask": "0.94"}], "timestamp": "1769384511907", "event_type": "price_change"}}
{"_local_timestamp": "2026-01-25T23:42:35.190873+00:00", "data": {"market": "0xe819c3fd02eec251efec7d90a1801554ec14fef336932c7342b333d4ae64d0a8", "price_changes": [{"asset_id": "99877125227544421735443256554390914792518157728590758473713836440156917197132", "price": "0.991", "size": "116.2", "side": "SELL", "hash": "54078c872b53ca7207eb0b5ef4c6ee5f4098c335", "best_bid": "0.945", "best_ask": "0.991"}, {"asset_id": "110183118205658048480611552004818205608380030301879472767196181141473018245608", "price": "0.009", "size": "116.2", "side": "BUY", "hash": "21a05a4399502ad18f273dc6865e618e34f6b085", "best_bid": "0.009", "best_ask": "0.055"}], "timestamp": "1769384555043", "event_type": "price_change"}}
{"_local_timestamp": "2026-01-25T23:42:35.275824+00:00", "data": {"market": "0x208c0100d3c9b2e1cfe6acd453a461a2db052ea6de69345e20ba97bd80b24a32", "price_changes": [{"asset_id": "50847646174397103153022714653544400551806761556088789644031638820781566442427", "price": "0.859", "size": "0", "side": "BUY", "hash": "dbae971feda6424689fbb547d56c0d6b7bb4f661", "best_bid": "0.998", "best_ask": "1"}, {"asset_id": "25190149186348626497584661665153964321010101728496495635131758054890103740875", "price": "0.141", "size": "0", "side": "SELL", "hash": "66ce40c725c5eed43b1631789dd97442f9dbffd7", "best_bid": "0", "best_ask": "0.002"}], "timestamp": "1769384555145", "event_type": "price_change"}}
{"_local_timestamp": "2026-01-25T23:42:35.276357+00:00", "data": {"market": "0x1dcc183b4cca17ebd95af1b94209ce345233d13a8157c1b1761b6d82722614aa", "price_changes": [{"asset_id": "105584168793006337391660846202014742593893506579636126851936010970644475175057", "price": "0.862", "size": "0", "side": "BUY", "hash": "65493690a73d8b2faf6993841d0e356c64159192", "best_bid": "0.996", "best_ask": "1"}, {"asset_id": "34996430135377662182478828889088041580319309767069410756085253475349980098679", "price": "0.138", "size": "0", "side": "SELL", "hash": "4208e810d053299bae0db4de1b01bb67f14efd0f", "best_bid": "0", "best_ask": "0.004"}], "timestamp": "1769384555145", "event_type": "price_change"}}
{"_local_timestamp": "2026-01-25T23:42:35.276724+00:00", "data": {"market": "0xd2b7235e5c612ce49ad0252420d713280ded4e346bd24dd50f941e901e9daec2", "price_changes": [{"asset_id": "110558202691925957098835226242947976618291676693360525080400622291263590296356", "price": "0.914", "size": "0", "side": "BUY", "hash": "d2e73dab30bd00bb1ecf8ce4e052712b1c26e150", "best_bid": "0.997", "best_ask": "0.999"}, {"asset_id": "62070332729843756648077334071325768265229024314411995286040519682521027925149", "price": "0.086", "size": "0", "side": "SELL", "hash": "21bc8d3a513662ec2952b32f81e17201ecbd42e9", "best_bid": "0.001", "best_ask": "0.003"}], "timestamp": "1769384555145", "event_type": "price_change"}}
{"_local_timestamp": "2026-01-25T23:42:35.276976+00:00", "data": {"market": "0xaefc28d462f0824bbb9c694d3511beaaf8b21af8eba30d8e524ed05d0431e712", "price_changes": [{"asset_id": "44763420328579357949062599081517223538923284512329276353056439811950932880097", "price": "0.872", "size": "0", "side": "BUY", "hash": "53236d380c16533f5227f88ad240702d8f7d05e0", "best_bid": "0.998", "best_ask": "0.999"}, {"asset_id": "74056431860682289842871849619463099581884627064723191566088662788504744554943", "price": "0.128", "size": "0", "side": "SELL", "hash": "3831e99540f2ef6fa7fa20f47b5a8221994645a5", "best_bid": "0.001", "best_ask": "0.002"}], "timestamp": "1769384555145", "event_type": "price_change"}}
{"_local_timestamp": "2026-01-25T23:42:35.277218+00:00", "data": {"market": "0xc5a5599959ff15ca3533656c16dd441304b8721162ef770db59a1d2b4862e2b8", "price_changes": [{"asset_id": "48279448787839069698930026835059287278898209340746904712996610649334841531409", "price": "0.873", "size": "0", "side": "BUY", "hash": "504d38dce1fe30e74121dc9ee58a5318c17ff661", "best_bid": "0.996", "best_ask": "1"}, {"asset_id": "73040552226217734695850503696187376710006575449764477997853420807432098137837", "price": "0.127", "size": "0", "side": "SELL", "hash": "67f7655d7c1630cab84d9742f9984065109a63ba", "best_bid": "0", "best_ask": "0.004"}], "timestamp": "1769384555145", "event_type": "price_change"}}
{"_local_timestamp": "2026-01-25T23:42:35.277441+00:00", "data": {"market": "0x584caca7a7536029bef854652fa5fdd861631edbc01a217069341b85030edd6f", "price_changes": [{"asset_id": "8840594256975309703691759780728141785112443011041236897959089339991605786144", "price": "0.72", "size": "0", "side": "BUY", "hash": "b876a50fa142108db3c4df3acbb89d3d0516df0c", "best_bid": "0.996", "best_ask": "1"}, {"asset_id": "69196677690927265002451334694240538592951011957285689708757350071125284654035", "price": "0.28", "size": "0", "side": "SELL", "hash": "86b739dbce841205cf4e06255eb8feb0673123e9", "best_bid": "0", "best_ask": "0.004"}], "timestamp": "1769384555145", "event_type": "price_change"}}
{"_local_timestamp": "2026-01-25T23:42:35.277670+00:00", "data": {"market": "0xe819c3fd02eec251efec7d90a1801554ec14fef336932c7342b333d4ae64d0a8", "price_changes": [{"asset_id": "99877125227544421735443256554390914792518157728590758473713836440156917197132", "price": "0.829", "size": "0", "side": "BUY", "hash": "fdc56301f4ca72d70df682d729fb8b9b80870e29", "best_bid": "0.945", "best_ask": "0.991"}, {"asset_id": "110183118205658048480611552004818205608380030301879472767196181141473018245608", "price": "0.171", "size": "0", "side": "SELL", "hash": "d611f95bd0993344a60ec0aad9fa66c02017d4fa", "best_bid": "0.009", "best_ask": "0.055"}], "timestamp": "1769384555145", "event_type": "price_change"}}
{"_local_timestamp": "2026-01-25T23:42:35.277891+00:00", "data": {"market": "0x34629a8e04da66f61bad2b4de18d370ca551faf79f810e04e403b841163f0e47", "price_changes": [{"asset_id": "81962021060291538332769225938832888553429136330721495433176438182361641360146", "price": "0.585", "size": "0", "side": "BUY", "hash": "fc918edce18b27ecb351d3fcd2bc18927c0e7e36", "best_bid": "0.975", "best_ask": "0.987"}, {"asset_id": "24428969314967049374579832885004941749071678905985050510703983608884666132158", "price": "0.415", "size": "0", "side": "SELL", "hash": "14a15a6636ae95e50d39f863e589dddbbdb539f6", "best_bid": "0.013", "best_ask": "0.025"}], "timestamp": "1769384555146", "event_type": "price_change"}}
{"_local_timestamp": "2026-01-25T23:42:35.278166+00:00", "data": {"market": "0x00787f50b9466db23a1899abc108b5609a77cbaa159c1b35822f45e9c14a940b", "price_changes": [{"asset_id": "113809960451765367690598229673115216134099141989496655805640157545770316317603", "price": "0.86", "size": "0", "side": "BUY", "hash": "ec45f0c27474e7a691ea1bb414dde7e71de28de2", "best_bid": "0.998", "best_ask": "0.999"}, {"asset_id": "76794312778172154876533172710848055841220591544022724903757628442504975481665", "price": "0.14", "size": "0", "side": "SELL", "hash": "e493ba0fc867f1ed8593cb2620949b49356c5871", "best_bid": "0.001", "best_ask": "0.002"}], "timestamp": "1769384555145", "event_type": "price_change"}}
{"_local_timestamp": "2026-01-25T23:42:35.388543+00:00", "data": {"market": "0x813140d27e876be7b8b57a9f5932f560426e5dd02370e1a6d815ce416d3c1a1e", "price_changes": [{"asset_id": "42867658785582566258165916378080823643991642521460286045794854230410783654072", "price": "0.861", "size": "0", "side": "BUY", "hash": "deeedf8a4a5896720b3fa582d88b1cc35c73c99d", "best_bid": "0.996", "best_ask": "1"}, {"asset_id": "39110700308891033765082720771423327970968989496145639822830381828556135408196", "price": "0.139", "size": "0", "side": "SELL", "hash": "0834758fb1320fccc55d30369141c9d94c8c409b", "best_bid": "0", "best_ask": "0.004"}], "timestamp": "1769384555145", "event_type": "price_change"}}
{"_local_timestamp": "2026-01-25T23:42:35.389011+00:00", "data": {"market": "0xc901b7ee5f6776feee0bc75349ddf15b3f1473c42e9c23fbd2c286129db2314b", "price_changes": [{"asset_id": "19480453523641651203279098233362734886683676042431995106519882319527157746915", "price": "0.868", "size": "0", "side": "BUY", "hash": "b9afdba7204cee1dec96dcda1716e712fc349058", "best_bid": "0.998", "best_ask": "1"}, {"asset_id": "87076761959524824596667767871338783105013148144014343593959452219056943445676", "price": "0.132", "size": "0", "side": "SELL", "hash": "6a8ce245e8ebe3a216d3f4006cbc27b09f3ad69a", "best_bid": "0", "best_ask": "0.002"}], "timestamp": "1769384555145", "event_type": "price_change"}}
{"_local_timestamp": "2026-01-25T23:42:35.389279+00:00", "data": {"market": "0x7996c5de13ddf3131cebe81e14fa25bc93e6d83383e9311fb4444d054b02bb6c", "price_changes": [{"asset_id": "81067297669492637828272330271687160515702268762196167960552103884621012706990", "price": "0.628", "size": "0", "side": "BUY", "hash": "4ee6cc5900f7a3bf694afbb7950025ffbe1d347b", "best_bid": "0.996", "best_ask": "1"}, {"asset_id": "35385046285095047875859550982501333940016148310175612786655121530268337331434", "price": "0.372", "size": "0", "side": "SELL", "hash": "e089240bffc7418bde9ed8bc1af29e87b2c47924", "best_bid": "0", "best_ask": "0.004"}], "timestamp": "1769384555145", "event_type": "price_change"}}
{"_local_timestamp": "2026-01-25T23:42:35.389663+00:00", "data": {"market": "0x2c405b766a5952a1ee121519845541e3f363bbbb691748d38d596e900827333f", "price_changes": [{"asset_id": "45360012752670095623901322351652227247408888830488142163512756455139535103641", "price": "0.862", "size": "0", "side": "BUY", "hash": "ab7d1d697e290d450cea6ed5278dd042c32470c6", "best_bid": "0.996", "best_ask": "1"}, {"asset_id": "44227097530829963499576501282186404645897936156929334280113391423971987257194", "price": "0.138", "size": "0", "side": "SELL", "hash": "ffea921e3d4d87384ce6ad8b3273801fba06a2c3", "best_bid": "0", "best_ask": "0.004"}], "timestamp": "1769384555145", "event_type": "price_change"}}
{"_local_timestamp": "2026-01-25T23:42:35.459024+00:00", "data": {"market": "0x5882bfbb3333c4425fe5f17d7177d0155935ab218532e30abb3ebc29e09b0d15", "price_changes": [{"asset_id": "37022134553940218760484349283577041579348129770638687563562605588225179219348", "price": "0.825", "size": "0", "side": "BUY", "hash": "62275bcb1cbddbcda35b893b92a11eed814c707d", "best_bid": "0.998", "best_ask": "0.999"}, {"asset_id": "98286904268100078035776152708720247190143751657794196422985487083520781931503", "price": "0.175", "size": "0", "side": "SELL", "hash": "50716a299136b358d0064fded88fa8461d4bf377", "best_bid": "0.001", "best_ask": "0.002"}], "timestamp": "1769384555145", "event_type": "price_change"}}
{"_local_timestamp": "2026-01-25T23:42:35.459489+00:00", "data": {"market": "0x936a5e78fd5963c717e49661a593fa3353241f6fb3c69b6615e9041e6b6f0973", "price_changes": [{"asset_id": "62474888561798875936325899031095507932691561832763786042468556558023439824689", "price": "0.859", "size": "0", "side": "BUY", "hash": "9310230a303b3e13b3e157debd4211c95bd392fe", "best_bid": "0.997", "best_ask": "1"}, {"asset_id": "85450186084380419372744179618618425905211867206934194164904272142040477321142", "price": "0.141", "size": "0", "side": "SELL", "hash": "d987950c136a10728a5a67c1cf353b609fd7c583", "best_bid": "0", "best_ask": "0.003"}], "timestamp": "1769384555146", "event_type": "price_change"}}
{"_local_timestamp": "2026-01-25T23:42:35.459772+00:00", "data": {"market": "0x5bc6ce968259b72cf129f3420b74591165b2daed5681c945a550d3479a6cd29f", "price_changes": [{"asset_id": "13658847648110704810290854236711050722034916311708159351742514374794523650635", "price": "0.826", "size": "0", "side": "BUY", "hash": "bf5303255f4f0fee88369d78482a45a83c8a41d5", "best_bid": "0.996", "best_ask": "0.999"}, {"asset_id": "75885549806041705440616483171403974382986377202053531674757984617564016983448", "price": "0.174", "size": "0", "side": "SELL", "hash": "e25128909a0bac8cd9bcacdef989f9e5b9319d3a", "best_bid": "0.001", "best_ask": "0.004"}], "timestamp": "1769384555146", "event_type": "price_change"}}
{"_local_timestamp": "2026-01-25T23:42:35.460036+00:00", "data": {"market": "0xeb60a53b5ca38150c07cc30ef0f5570b292f3e43722512cc55d0cff666ac1077", "price_changes": [{"asset_id": "83308171747089483400662168608358178791256497013703595264448211477259881059204", "price": "0.862", "size": "0", "side": "BUY", "hash": "3c5d101c98fbf6cb692b7959ea248648bfaf31df", "best_bid": "0.996", "best_ask": "1"}, {"asset_id": "72088688491610101384722384206165707443638739290798571693187856704797119769987", "price": "0.138", "size": "0", "side": "SELL", "hash": "0a070834acee640af6ba5e034fa0584410ae6b72", "best_bid": "0", "best_ask": "0.004"}], "timestamp": "1769384555146", "event_type": "price_change"}}
{"_local_timestamp": "2026-01-25T23:42:35.460278+00:00", "data": {"market": "0x4fc188ab7b8337089312087777af8a703757466dda919e1de85e148394c40090", "price_changes": [{"asset_id": "67034694271202563859644094265338465614375382145815138322023215311029487392827", "price": "0.824", "size": "0", "side": "BUY", "hash": "e47207147a0fbccc164fdd6a09021ec3d256b5dd", "best_bid": "0.996", "best_ask": "1"}, {"asset_id": "22440526641822362681904932185789972209232343897283048384344291619576375972156", "price": "0.176", "size": "0", "side": "SELL", "hash": "9745bffd032867aff7b04e3e201cc6d931f67c67", "best_bid": "0", "best_ask": "0.004"}], "timestamp": "1769384555146", "event_type": "price_change"}}
{"_local_timestamp": "2026-01-25T23:42:35.460533+00:00", "data": {"market": "0xff54852cf4cb9c3568f795b983bc494d2e13d3f9cad41ba872a4ffd3ccb2101e", "price_changes": [{"asset_id": "96140164996170695869329923820202447276846115725253325303263315936085179713314", "price": "0.861", "size": "0", "side": "BUY", "hash": "9c8f6c74f1c222894792f7df08d1b41c33b888e4", "best_bid": "0.996", "best_ask": "1"}, {"asset_id": "91203260296949109747095851381415926782789749145484395871735811789947699971761", "price": "0.139", "size": "0", "side": "SELL", "hash": "cd8f27348a94ba348b94f578dcb4493595c29e6b", "best_bid": "0", "best_ask": "0.004"}], "timestamp": "1769384555146", "event_type": "price_change"}}
{"_local_timestamp": "2026-01-25T23:42:35.460761+00:00", "data": {"market": "0xc5a5599959ff15ca3533656c16dd441304b8721162ef770db59a1d2b4862e2b8", "price_changes": [{"asset_id": "48279448787839069698930026835059287278898209340746904712996610649334841531409", "price": "0.875", "size": "20", "side": "BUY", "hash": "13ce982905ae98f92f2bd081ea1adcbacbc2d30c", "best_bid": "0.996", "best_ask": "1"}, {"asset_id": "73040552226217734695850503696187376710006575449764477997853420807432098137837", "price": "0.125", "size": "20", "side": "SELL", "hash": "4ccc7751955f2dfda8b690d111b56e53a145ec51", "best_bid": "0", "best_ask": "0.004"}], "timestamp": "1769384555211", "event_type": "price_change"}}
{"_local_timestamp": "2026-01-25T23:42:35.461014+00:00", "data": {"market": "0x1dcc183b4cca17ebd95af1b94209ce345233d13a8157c1b1761b6d82722614aa", "price_changes": [{"asset_id": "105584168793006337391660846202014742593893506579636126851936010970644475175057", "price": "0.864", "size": "20", "side": "BUY", "hash": "fc2d14b1c3f4ac33f73f29c7d811379d75b4f573", "best_bid": "0.996", "best_ask": "1"}, {"asset_id": "34996430135377662182478828889088041580319309767069410756085253475349980098679", "price": "0.136", "size": "20", "side": "SELL", "hash": "3e226b3802c2a283bb0e00b12ac0733ba5ad0523", "best_bid": "0", "best_ask": "0.004"}], "timestamp": "1769384555211", "event_type": "price_change"}}
{"_local_timestamp": "2026-01-25T23:42:35.461368+00:00", "data": {"market": "0x7996c5de13ddf3131cebe81e14fa25bc93e6d83383e9311fb4444d054b02bb6c", "price_changes": [{"asset_id": "81067297669492637828272330271687160515702268762196167960552103884621012706990", "price": "0.63", "size": "20", "side": "BUY", "hash": "e45a1c8921d070add2940af3a9d90a066d162f1f", "best_bid": "0.996", "best_ask": "1"}, {"asset_id": "35385046285095047875859550982501333940016148310175612786655121530268337331434", "price": "0.37", "size": "20", "side": "SELL", "hash": "af0b73e6cbef6cecdef2450885b14d050bbc9558", "best_bid": "0", "best_ask": "0.004"}], "timestamp": "1769384555211", "event_type": "price_change"}}
{"_local_timestamp": "2026-01-25T23:42:35.461659+00:00", "data": {"market": "0x208c0100d3c9b2e1cfe6acd453a461a2db052ea6de69345e20ba97bd80b24a32", "price_changes": [{"asset_id": "50847646174397103153022714653544400551806761556088789644031638820781566442427", "price": "0.861", "size": "302", "side": "BUY", "hash": "f3ae51149835dfc50e6d45f497685e9a98d07acc", "best_bid": "0.998", "best_ask": "1"}, {"asset_id": "25190149186348626497584661665153964321010101728496495635131758054890103740875", "price": "0.139", "size": "302", "side": "SELL", "hash": "ec678be464f4ab603d463c047a76e43c552904da", "best_bid": "0", "best_ask": "0.002"}], "timestamp": "1769384555211", "event_type": "price_change"}}
{"_local_timestamp": "2026-01-25T23:42:35.461921+00:00", "data": {"market": "0x936a5e78fd5963c717e49661a593fa3353241f6fb3c69b6615e9041e6b6f0973", "price_changes": [{"asset_id": "62474888561798875936325899031095507932691561832763786042468556558023439824689", "price": "0.861", "size": "20", "side": "BUY", "hash": "38c2aec4a3b0ccafdd535482e11cebc779da61ca", "best_bid": "0.997", "best_ask": "1"}, {"asset_id": "85450186084380419372744179618618425905211867206934194164904272142040477321142", "price": "0.139", "size": "20", "side": "SELL", "hash": "1ebaf2df3c090ed110d8ab3f5698b392fdedbd15", "best_bid": "0", "best_ask": "0.003"}], "timestamp": "1769384555211", "event_type": "price_change"}}
{"_local_timestamp": "2026-01-25T23:42:35.462239+00:00", "data": {"market": "0x4fc188ab7b8337089312087777af8a703757466dda919e1de85e148394c40090", "price_changes": [{"asset_id": "67034694271202563859644094265338465614375382145815138322023215311029487392827", "price": "0.824", "size": "363", "side": "BUY", "hash": "3b8d81008ec30d6955a717965b8294ddb8f0af5e", "best_bid": "0.996", "best_ask": "1"}, {"asset_id": "22440526641822362681904932185789972209232343897283048384344291619576375972156", "price": "0.176", "size": "363", "side": "SELL", "hash": "128a1c918290a5a3b0a0c6c9417b237c3440f748", "best_bid": "0", "best_ask": "0.004"}], "timestamp": "1769384555211", "event_type": "price_change"}}
{"_local_timestamp": "2026-01-25T23:42:35.462501+00:00", "data": {"market": "0xff54852cf4cb9c3568f795b983bc494d2e13d3f9cad41ba872a4ffd3ccb2101e", "price_changes": [{"asset_id": "96140164996170695869329923820202447276846115725253325303263315936085179713314", "price": "0.863", "size": "20", "side": "BUY", "hash": "a0e7d55ea5846d5c12c9bf92ea9d4703b29bffe6", "best_bid": "0.996", "best_ask": "1"}, {"asset_id": "91203260296949109747095851381415926782789749145484395871735811789947699971761", "price": "0.137", "size": "20", "side": "SELL", "hash": "f461fe644f707d3bab29080a305efdbc15a77b65", "best_bid": "0", "best_ask": "0.004"}], "timestamp": "1769384555211", "event_type": "price_change"}}
{"_local_timestamp": "2026-01-25T23:42:35.462734+00:00", "data": {"market": "0xe819c3fd02eec251efec7d90a1801554ec14fef336932c7342b333d4ae64d0a8", "price_changes": [{"asset_id": "99877125227544421735443256554390914792518157728590758473713836440156917197132", "price": "0.913", "size": "20", "side": "BUY", "hash": "a6a0c12db75636b3cea35fe48308c84c6fb601f6", "best_bid": "0.945", "best_ask": "0.991"}, {"asset_id": "110183118205658048480611552004818205608380030301879472767196181141473018245608", "price": "0.087", "size": "20", "side": "SELL", "hash": "24c03c19ea6d74006d2ede4329081d9fad1a47d7", "best_bid": "0.009", "best_ask": "0.055"}], "timestamp": "1769384555211", "event_type": "price_change"}}
{"_local_timestamp": "2026-01-25T23:42:35.462975+00:00", "data": {"market": "0xc5a5599959ff15ca3533656c16dd441304b8721162ef770db59a1d2b4862e2b8", "price_changes": [{"asset_id": "48279448787839069698930026835059287278898209340746904712996610649334841531409", "price": "0.824", "size": "263", "side": "BUY", "hash": "bdcf3d9af4f232e108d34c25240e122c83674a70", "best_bid": "0.996", "best_ask": "1"}, {"asset_id": "73040552226217734695850503696187376710006575449764477997853420807432098137837", "price": "0.176", "size": "263", "side": "SELL", "hash": "dcc597c0aae9dc87c5544b78b5c0d85c729b7c8f", "best_bid": "0", "best_ask": "0.004"}], "timestamp": "1769384555212", "event_type": "price_change"}}
{"_local_timestamp": "2026-01-25T23:42:35.463195+00:00", "data": {"market": "0x7996c5de13ddf3131cebe81e14fa25bc93e6d83383e9311fb4444d054b02bb6c", "price_changes": [{"asset_id": "81067297669492637828272330271687160515702268762196167960552103884621012706990", "price": "0.63", "size": "348", "side": "BUY", "hash": "a4c1ee9b04a5903104d5aeb34087e4cc88ba520d", "best_bid": "0.996", "best_ask": "1"}, {"asset_id": "35385046285095047875859550982501333940016148310175612786655121530268337331434", "price": "0.37", "size": "348", "side": "SELL", "hash": "85dd9893df8f8dafef3d2e23bfbbbd423ef2c79e", "best_bid": "0", "best_ask": "0.004"}], "timestamp": "1769384555212", "event_type": "price_change"}}
{"_local_timestamp": "2026-01-25T23:42:35.463422+00:00", "data": {"market": "0x208c0100d3c9b2e1cfe6acd453a461a2db052ea6de69345e20ba97bd80b24a32", "price_changes": [{"asset_id": "50847646174397103153022714653544400551806761556088789644031638820781566442427", "price": "0.861", "size": "322", "side": "BUY", "hash": "9c5f8e230401965fb9058b511e8dc5f3ab665abf", "best_bid": "0.998", "best_ask": "1"}, {"asset_id": "25190149186348626497584661665153964321010101728496495635131758054890103740875", "price": "0.139", "size": "322", "side": "SELL", "hash": "db4ebbd848c27848898b0f521916effbbdcfa4da", "best_bid": "0", "best_ask": "0.002"}], "timestamp": "1769384555212", "event_type": "price_change"}}
{"_local_timestamp": "2026-01-25T23:42:35.463646+00:00", "data": {"market": "0x936a5e78fd5963c717e49661a593fa3353241f6fb3c69b6615e9041e6b6f0973", "price_changes": [{"asset_id": "62474888561798875936325899031095507932691561832763786042468556558023439824689", "price": "0.861", "size": "294", "side": "BUY", "hash": "d892d07fb7ae2848c9e9b0ee13801335be214fbf", "best_bid": "0.997", "best_ask": "1"}, {"asset_id": "85450186084380419372744179618618425905211867206934194164904272142040477321142", "price": "0.139", "size": "294", "side": "SELL", "hash": "39bafc8f4f8d3c1592fc2daf3d6b51dbd5cd9a43", "best_bid": "0", "best_ask": "0.003"}], "timestamp": "1769384555212", "event_type": "price_change"}}
{"_local_timestamp": "2026-01-25T23:42:35.463879+00:00", "data": {"market": "0x4fc188ab7b8337089312087777af8a703757466dda919e1de85e148394c40090", "price_changes": [{"asset_id": "67034694271202563859644094265338465614375382145815138322023215311029487392827", "price": "0.925", "size": "20", "side": "BUY", "hash": "e4f76b6c5d1ef942a6b91ac4b61138bf7b457132", "best_bid": "0.996", "best_ask": "1"}, {"asset_id": "22440526641822362681904932185789972209232343897283048384344291619576375972156", "price": "0.075", "size": "20", "side": "SELL", "hash": "15e643c380ac63279737d1614fe25f4bd9254362", "best_bid": "0", "best_ask": "0.004"}], "timestamp": "1769384555212", "event_type": "price_change"}}
{"_local_timestamp": "2026-01-25T23:42:35.464114+00:00", "data": {"market": "0x1dcc183b4cca17ebd95af1b94209ce345233d13a8157c1b1761b6d82722614aa", "price_changes": [{"asset_id": "105584168793006337391660846202014742593893506579636126851936010970644475175057", "price": "0.824", "size": "400", "side": "BUY", "hash": "272da5b605a69bc5f50d9c39c5cda62ad7ff8966", "best_bid": "0.996", "best_ask": "1"}, {"asset_id": "34996430135377662182478828889088041580319309767069410756085253475349980098679", "price": "0.176", "size": "400", "side": "SELL", "hash": "23e3c53f5e24c805d8f0e37da7d8ee181f38382c", "best_bid": "0", "best_ask": "0.004"}], "timestamp": "1769384555212", "event_type": "price_change"}}
{"_local_timestamp": "2026-01-25T23:42:35.464331+00:00", "data": {"market": "0xff54852cf4cb9c3568f795b983bc494d2e13d3f9cad41ba872a4ffd3ccb2101e", "price_changes": [{"asset_id": "96140164996170695869329923820202447276846115725253325303263315936085179713314", "price": "0.863", "size": "326", "side": "BUY", "hash": "6c4638762105cd7426a96de9c2c5d7ec5a4b277b", "best_bid": "0.996", "best_ask": "1"}, {"asset_id": "91203260296949109747095851381415926782789749145484395871735811789947699971761", "price": "0.137", "size": "326", "side": "SELL", "hash": "1e063193bfad7465fd4652b23b8e1e648c48bb92", "best_bid": "0", "best_ask": "0.004"}], "timestamp": "1769384555212", "event_type": "price_change"}}
{"_local_timestamp": "2026-01-25T23:42:35.464558+00:00", "data": {"market": "0x5882bfbb3333c4425fe5f17d7177d0155935ab218532e30abb3ebc29e09b0d15", "price_changes": [{"asset_id": "37022134553940218760484349283577041579348129770638687563562605588225179219348", "price": "0.827", "size": "278", "side": "BUY", "hash": "f09b0d81079211e345ed59864f7e16a9eba22db0", "best_bid": "0.998", "best_ask": "0.999"}, {"asset_id": "98286904268100078035776152708720247190143751657794196422985487083520781931503", "price": "0.173", "size": "278", "side": "SELL", "hash": "23bfee8c188e1bea1f40dc97d8c1a935052c76e6", "best_bid": "0.001", "best_ask": "0.002"}], "timestamp": "1769384555213", "event_type": "price_change"}}
{"_local_timestamp": "2026-01-25T23:42:35.464780+00:00", "data": {"market": "0xaefc28d462f0824bbb9c694d3511beaaf8b21af8eba30d8e524ed05d0431e712", "price_changes": [{"asset_id": "44763420328579357949062599081517223538923284512329276353056439811950932880097", "price": "0.876", "size": "20", "side": "BUY", "hash": "a5f405955299ddd75fd7bc65c14f78b62b273469", "best_bid": "0.998", "best_ask": "0.999"}, {"asset_id": "74056431860682289842871849619463099581884627064723191566088662788504744554943", "price": "0.124", "size": "20", "side": "SELL", "hash": "54a6b5665299286a24350a7b68a00bd0266847bd", "best_bid": "0.001", "best_ask": "0.002"}], "timestamp": "1769384555213", "event_type": "price_change"}}
{"_local_timestamp": "2026-01-25T23:42:35.465006+00:00", "data": {"market": "0x584caca7a7536029bef854652fa5fdd861631edbc01a217069341b85030edd6f", "price_changes": [{"asset_id": "8840594256975309703691759780728141785112443011041236897959089339991605786144", "price": "0.722", "size": "20", "side": "BUY", "hash": "a53556846996853c4867d625fb7da2bedc38dd65", "best_bid": "0.996", "best_ask": "1"}, {"asset_id": "69196677690927265002451334694240538592951011957285689708757350071125284654035", "price": "0.278", "size": "20", "side": "SELL", "hash": "7e4cb631d4a3a23bf9a4b9287eff3220a8228a6f", "best_bid": "0", "best_ask": "0.004"}], "timestamp": "1769384555213", "event_type": "price_change"}}
{"_local_timestamp": "2026-01-25T23:42:35.465248+00:00", "data": {"market": "0x813140d27e876be7b8b57a9f5932f560426e5dd02370e1a6d815ce416d3c1a1e", "price_changes": [{"asset_id": "42867658785582566258165916378080823643991642521460286045794854230410783654072", "price": "0.863", "size": "20", "side": "BUY", "hash": "b3e2a92573b161bc54c48b8486dd4b648a4e946e", "best_bid": "0.996", "best_ask": "1"}, {"asset_id": "39110700308891033765082720771423327970968989496145639822830381828556135408196", "price": "0.137", "size": "20", "side": "SELL", "hash": "838fde7c4ed0e17d851016ef56fbe8a1830c822f", "best_bid": "0", "best_ask": "0.004"}], "timestamp": "1769384555213", "event_type": "price_change"}}
{"_local_timestamp": "2026-01-25T23:42:35.465463+00:00", "data": {"market": "0xaefc28d462f0824bbb9c694d3511beaaf8b21af8eba30d8e524ed05d0431e712", "price_changes": [{"asset_id": "44763420328579357949062599081517223538923284512329276353056439811950932880097", "price": "0.876", "size": "332", "side": "BUY", "hash": "783b04c59c5596afeb8562e0edabad9d3e466c59", "best_bid": "0.998", "best_ask": "0.999"}, {"asset_id": "74056431860682289842871849619463099581884627064723191566088662788504744554943", "price": "0.124", "size": "332", "side": "SELL", "hash": "a91f4039a7b3149ec3cd392965bc27cc7c2daa93", "best_bid": "0.001", "best_ask": "0.002"}], "timestamp": "1769384555214", "event_type": "price_change"}}
{"_local_timestamp": "2026-01-25T23:42:35.465702+00:00", "data": {"market": "0x584caca7a7536029bef854652fa5fdd861631edbc01a217069341b85030edd6f", "price_changes": [{"asset_id": "8840594256975309703691759780728141785112443011041236897959089339991605786144", "price": "0.722", "size": "326", "side": "BUY", "hash": "9c326e137b1a39c23535ad96f49ce2f37343a9c6", "best_bid": "0.996", "best_ask": "1"}, {"asset_id": "69196677690927265002451334694240538592951011957285689708757350071125284654035", "price": "0.278", "size": "326", "side": "SELL", "hash": "fd7f4088dc18cb1023b178e93e6577b85434125a", "best_bid": "0", "best_ask": "0.004"}], "timestamp": "1769384555214", "event_type": "price_change"}}
{"_local_timestamp": "2026-01-25T23:42:35.465933+00:00", "data": {"market": "0x5882bfbb3333c4425fe5f17d7177d0155935ab218532e30abb3ebc29e09b0d15", "price_changes": [{"asset_id": "37022134553940218760484349283577041579348129770638687563562605588225179219348", "price": "0.929", "size": "20", "side": "BUY", "hash": "d0ed8769acc10bdc73780976093d25e417775c74", "best_bid": "0.998", "best_ask": "0.999"}, {"asset_id": "98286904268100078035776152708720247190143751657794196422985487083520781931503", "price": "0.071", "size": "20", "side": "SELL", "hash": "1dcffd3182cb91e3f3809b4ae7644f293a6ad230", "best_bid": "0.001", "best_ask": "0.002"}], "timestamp": "1769384555214", "event_type": "price_change"}}
{"_local_timestamp": "2026-01-25T23:42:35.466155+00:00", "data": {"market": "0x813140d27e876be7b8b57a9f5932f560426e5dd02370e1a6d815ce416d3c1a1e", "price_changes": [{"asset_id": "42867658785582566258165916378080823643991642521460286045794854230410783654072", "price": "0.824", "size": "400", "side": "BUY", "hash": "f1ae0cb24d37d835db4e43c7a46642eeecf78b91", "best_bid": "0.996", "best_ask": "1"}, {"asset_id": "39110700308891033765082720771423327970968989496145639822830381828556135408196", "price": "0.176", "size": "400", "side": "SELL", "hash": "721b55e1f91cfe6d6719b4e5754c047a71041318", "best_bid": "0", "best_ask": "0.004"}], "timestamp": "1769384555214", "event_type": "price_change"}}
{"_local_timestamp": "2026-01-25T23:42:35.466401+00:00", "data": {"market": "0xd2b7235e5c612ce49ad0252420d713280ded4e346bd24dd50f941e901e9daec2", "price_changes": [{"asset_id": "110558202691925957098835226242947976618291676693360525080400622291263590296356", "price": "0.916", "size": "20", "side": "BUY", "hash": "891ba20d3f1fb4e4d7e50ebccc1dcf622a678c3a", "best_bid": "0.997", "best_ask": "0.999"}, {"asset_id": "62070332729843756648077334071325768265229024314411995286040519682521027925149", "price": "0.084", "size": "20", "side": "SELL", "hash": "c376cadb95e2835a99612047b02434e1e57efe8b", "best_bid": "0.001", "best_ask": "0.003"}], "timestamp": "1769384555224", "event_type": "price_change"}}
{"_local_timestamp": "2026-01-25T23:42:35.466627+00:00", "data": {"market": "0x00787f50b9466db23a1899abc108b5609a77cbaa159c1b35822f45e9c14a940b", "price_changes": [{"asset_id": "113809960451765367690598229673115216134099141989496655805640157545770316317603", "price": "0.864", "size": "324", "side": "BUY", "hash": "79974af0bb1353525dd1013a88d1082eca2f7cbf", "best_bid": "0.998", "best_ask": "0.999"}, {"asset_id": "76794312778172154876533172710848055841220591544022724903757628442504975481665", "price": "0.136", "size": "324", "side": "SELL", "hash": "b29d5c88fc8f060e5ca3767b2ec9a5cf8178a272", "best_bid": "0.001", "best_ask": "0.002"}], "timestamp": "1769384555224", "event_type": "price_change"}}
{"_local_timestamp": "2026-01-25T23:42:35.466846+00:00", "data": {"market": "0x34629a8e04da66f61bad2b4de18d370ca551faf79f810e04e403b841163f0e47", "price_changes": [{"asset_id": "81962021060291538332769225938832888553429136330721495433176438182361641360146", "price": "0.589", "size": "345", "side": "BUY", "hash": "000bf14c01d2f295216d68a227b8d73a1ac2234f", "best_bid": "0.975", "best_ask": "0.987"}, {"asset_id": "24428969314967049374579832885004941749071678905985050510703983608884666132158", "price": "0.411", "size": "345", "side": "SELL", "hash": "d99693539ea7a6cdddc95f22316dbdb852854fa8", "best_bid": "0.013", "best_ask": "0.025"}], "timestamp": "1769384555224", "event_type": "price_change"}}
{"_local_timestamp": "2026-01-25T23:42:35.467070+00:00", "data": {"market": "0xeb60a53b5ca38150c07cc30ef0f5570b292f3e43722512cc55d0cff666ac1077", "price_changes": [{"asset_id": "83308171747089483400662168608358178791256497013703595264448211477259881059204", "price": "0.864", "size": "20", "side": "BUY", "hash": "b56304b5e5313522c85ea94cf73001f4502415c1", "best_bid": "0.996", "best_ask": "1"}, {"asset_id": "72088688491610101384722384206165707443638739290798571693187856704797119769987", "price": "0.136", "size": "20", "side": "SELL", "hash": "2657ba23890cec539814b525809ee1f32a180de2", "best_bid": "0", "best_ask": "0.004"}], "timestamp": "1769384555224", "event_type": "price_change"}}
{"_local_timestamp": "2026-01-25T23:42:35.467294+00:00", "data": {"market": "0x2c405b766a5952a1ee121519845541e3f363bbbb691748d38d596e900827333f", "price_changes": [{"asset_id": "45360012752670095623901322351652227247408888830488142163512756455139535103641", "price": "0.864", "size": "20", "side": "BUY", "hash": "1f7f934302296e4759538b9a659065944ece0c67", "best_bid": "0.996", "best_ask": "1"}, {"asset_id": "44227097530829963499576501282186404645897936156929334280113391423971987257194", "price": "0.136", "size": "20", "side": "SELL", "hash": "e9b4c40e1c7a1cccbb1455a38e69141a25b36c33", "best_bid": "0", "best_ask": "0.004"}], "timestamp": "1769384555224", "event_type": "price_change"}}
{"_local_timestamp": "2026-01-25T23:42:35.467512+00:00", "data": {"market": "0xc901b7ee5f6776feee0bc75349ddf15b3f1473c42e9c23fbd2c286129db2314b", "price_changes": [{"asset_id": "19480453523641651203279098233362734886683676042431995106519882319527157746915", "price": "0.87", "size": "20", "side": "BUY", "hash": "de6a9f2e7ae49067a51d5aae1dba027b93f723fb", "best_bid": "0.998", "best_ask": "1"}, {"asset_id": "87076761959524824596667767871338783105013148144014343593959452219056943445676", "price": "0.13", "size": "20", "side": "SELL", "hash": "11e0a63db2374318e7e86a235115aea6d3962499", "best_bid": "0", "best_ask": "0.002"}], "timestamp": "1769384555224", "event_type": "price_change"}}
{"_local_timestamp": "2026-01-25T23:42:35.467732+00:00", "data": {"market": "0x5bc6ce968259b72cf129f3420b74591165b2daed5681c945a550d3479a6cd29f", "price_changes": [{"asset_id": "13658847648110704810290854236711050722034916311708159351742514374794523650635", "price": "0.824", "size": "20", "side": "BUY", "hash": "191584e8467288162bf8952402a8393cefc65409", "best_bid": "0.996", "best_ask": "0.999"}, {"asset_id": "75885549806041705440616483171403974382986377202053531674757984617564016983448", "price": "0.176", "size": "20", "side": "SELL", "hash": "b2962c49ce73ca3812f4b8df132532fc8919a5c4", "best_bid": "0.001", "best_ask": "0.004"}], "timestamp": "1769384555224", "event_type": "price_change"}}
{"_local_timestamp": "2026-01-25T23:42:35.467963+00:00", "data": {"market": "0xd2b7235e5c612ce49ad0252420d713280ded4e346bd24dd50f941e901e9daec2", "price_changes": [{"asset_id": "110558202691925957098835226242947976618291676693360525080400622291263590296356", "price": "0.824", "size": "307", "side": "BUY", "hash": "1e400865da3455f661217e22b80f42564e26b3b8", "best_bid": "0.997", "best_ask": "0.999"}, {"asset_id": "62070332729843756648077334071325768265229024314411995286040519682521027925149", "price": "0.176", "size": "307", "side": "SELL", "hash": "0fcc8d753e50cc2e7c16ca292b1120b2274f34c7", "best_bid": "0.001", "best_ask": "0.003"}], "timestamp": "1769384555225", "event_type": "price_change"}}
{"_local_timestamp": "2026-01-25T23:42:35.468173+00:00", "data": {"market": "0x00787f50b9466db23a1899abc108b5609a77cbaa159c1b35822f45e9c14a940b", "price_changes": [{"asset_id": "113809960451765367690598229673115216134099141989496655805640157545770316317603", "price": "0.864", "size": "344", "side": "BUY", "hash": "acca7e57e2f89f3584caaec25c43a3f76873d488", "best_bid": "0.998", "best_ask": "0.999"}, {"asset_id": "76794312778172154876533172710848055841220591544022724903757628442504975481665", "price": "0.136", "size": "344", "side": "SELL", "hash": "18a1399b35647a4723bb9700b2675c933764bebf", "best_bid": "0.001", "best_ask": "0.002"}], "timestamp": "1769384555224", "event_type": "price_change"}}
{"_local_timestamp": "2026-01-25T23:42:35.468477+00:00", "data": {"market": "0x34629a8e04da66f61bad2b4de18d370ca551faf79f810e04e403b841163f0e47", "price_changes": [{"asset_id": "81962021060291538332769225938832888553429136330721495433176438182361641360146", "price": "0.589", "size": "365", "side": "BUY", "hash": "1f3ab3c6cdb7bfed729eb013c321688410765775", "best_bid": "0.975", "best_ask": "0.987"}, {"asset_id": "24428969314967049374579832885004941749071678905985050510703983608884666132158", "price": "0.411", "size": "365", "side": "SELL", "hash": "7c13b85472d58562b97e7be0eb8b929ce6cd3a33", "best_bid": "0.013", "best_ask": "0.025"}], "timestamp": "1769384555225", "event_type": "price_change"}}
{"_local_timestamp": "2026-01-25T23:42:35.468698+00:00", "data": {"market": "0xc901b7ee5f6776feee0bc75349ddf15b3f1473c42e9c23fbd2c286129db2314b", "price_changes": [{"asset_id": "19480453523641651203279098233362734886683676042431995106519882319527157746915", "price": "0.87", "size": "299", "side": "BUY", "hash": "615abe3d1ec9456082b05d06768f96bea10d6d53", "best_bid": "0.998", "best_ask": "1"}, {"asset_id": "87076761959524824596667767871338783105013148144014343593959452219056943445676", "price": "0.13", "size": "299", "side": "SELL", "hash": "c55ac9f92f27c0f6409e71066c165deeaec432af", "best_bid": "0", "best_ask": "0.002"}], "timestamp": "1769384555225", "event_type": "price_change"}}
{"_local_timestamp": "2026-01-25T23:42:35.468966+00:00", "data": {"market": "0xeb60a53b5ca38150c07cc30ef0f5570b292f3e43722512cc55d0cff666ac1077", "price_changes": [{"asset_id": "83308171747089483400662168608358178791256497013703595264448211477259881059204", "price": "0.864", "size": "322", "side": "BUY", "hash": "dc6d1c7f75a4c08ba91b624f24d691c243a28028", "best_bid": "0.996", "best_ask": "1"}, {"asset_id": "72088688491610101384722384206165707443638739290798571693187856704797119769987", "price": "0.136", "size": "322", "side": "SELL", "hash": "ff688c84d939fec44e5fed937a7574ccad25947c", "best_bid": "0", "best_ask": "0.004"}], "timestamp": "1769384555225", "event_type": "price_change"}}
{"_local_timestamp": "2026-01-25T23:42:35.469493+00:00", "data": {"market": "0x2c405b766a5952a1ee121519845541e3f363bbbb691748d38d596e900827333f", "price_changes": [{"asset_id": "45360012752670095623901322351652227247408888830488142163512756455139535103641", "price": "0.864", "size": "290", "side": "BUY", "hash": "f20549aa185f68acd8ba5bff90cb3f99a09d6aa5", "best_bid": "0.996", "best_ask": "1"}, {"asset_id": "44227097530829963499576501282186404645897936156929334280113391423971987257194", "price": "0.136", "size": "290", "side": "SELL", "hash": "3d88ccbd83856332674af57ab02edc21060ded40", "best_bid": "0", "best_ask": "0.004"}], "timestamp": "1769384555225", "event_type": "price_change"}}
{"_local_timestamp": "2026-01-25T23:42:35.469720+00:00", "data": {"market": "0x5bc6ce968259b72cf129f3420b74591165b2daed5681c945a550d3479a6cd29f", "price_changes": [{"asset_id": "13658847648110704810290854236711050722034916311708159351742514374794523650635", "price": "0.824", "size": "332", "side": "BUY", "hash": "acc9f0f71470f8d51201990e611c35d0bf7d9a3d", "best_bid": "0.996", "best_ask": "0.999"}, {"asset_id": "75885549806041705440616483171403974382986377202053531674757984617564016983448", "price": "0.176", "size": "332", "side": "SELL", "hash": "08e5aa25dd5b418ebcec09d2bb4d031cc7969353", "best_bid": "0.001", "best_ask": "0.004"}], "timestamp": "1769384555225", "event_type": "price_change"}}
{"_local_timestamp": "2026-01-25T23:42:35.561679+00:00", "data": {"market": "0xe819c3fd02eec251efec7d90a1801554ec14fef336932c7342b333d4ae64d0a8", "price_changes": [{"asset_id": "99877125227544421735443256554390914792518157728590758473713836440156917197132", "price": "0.991", "size": "147.2", "side": "SELL", "hash": "25ff2bb3b562d76c1363394c9048d3f411fd23ec", "best_bid": "0.945", "best_ask": "0.991"}, {"asset_id": "110183118205658048480611552004818205608380030301879472767196181141473018245608", "price": "0.009", "size": "147.2", "side": "BUY", "hash": "9c2d660e45118e630dbab45c09219ae71f307ac8", "best_bid": "0.009", "best_ask": "0.055"}], "timestamp": "1769384555228", "event_type": "price_change"}}
{"_local_timestamp": "2026-01-25T23:42:35.562175+00:00", "data": {"market": "0xad8e9885ec2473d0ba49c38449dfd4d18ad7c0f7a14625a24865857e18a94850", "price_changes": [{"asset_id": "6063771237142095573570898636767550587549260179390402809546741793309719810883", "price": "0.516", "size": "0", "side": "BUY", "hash": "1a58e46604d2fabb5f7c7d89c050dff6f95a9713", "best_bid": "0.992", "best_ask": "0.996"}, {"asset_id": "40355817413446270517300817460473958731033814018091765438985668051022432561988", "price": "0.484", "size": "0", "side": "SELL", "hash": "afa3a27bc2a70ddb294ab516cac9fad2bc745255", "best_bid": "0.004", "best_ask": "0.008"}], "timestamp": "1769384555317", "event_type": "price_change"}}
{"_local_timestamp": "2026-01-25T23:42:35.562507+00:00", "data": {"market": "0xad8e9885ec2473d0ba49c38449dfd4d18ad7c0f7a14625a24865857e18a94850", "price_changes": [{"asset_id": "6063771237142095573570898636767550587549260179390402809546741793309719810883", "price": "0.52", "size": "20", "side": "BUY", "hash": "cc4e97354e041527b8c5ebc3fe2b7dc2d9170463", "best_bid": "0.992", "best_ask": "0.996"}, {"asset_id": "40355817413446270517300817460473958731033814018091765438985668051022432561988", "price": "0.48", "size": "20", "side": "SELL", "hash": "6b826f7bff9585ff4898693c4cc194358e972942", "best_bid": "0.004", "best_ask": "0.008"}], "timestamp": "1769384555361", "event_type": "price_change"}}
{"_local_timestamp": "2026-01-25T23:42:35.795106+00:00", "data": {"market": "0x4fc188ab7b8337089312087777af8a703757466dda919e1de85e148394c40090", "price_changes": [{"asset_id": "67034694271202563859644094265338465614375382145815138322023215311029487392827", "price": "0.824", "size": "0", "side": "BUY", "hash": "e43205805dbb092c8a7c94e55ed8d8963f91e5cc", "best_bid": "0.996", "best_ask": "1"}, {"asset_id": "22440526641822362681904932185789972209232343897283048384344291619576375972156", "price": "0.176", "size": "0", "side": "SELL", "hash": "cb3606a20740015a7f2a465de8331f7476a623df", "best_bid": "0", "best_ask": "0.004"}], "timestamp": "1769384555664", "event_type": "price_change"}}
{"_local_timestamp": "2026-01-25T23:42:35.797153+00:00", "data": {"market": "0xc901b7ee5f6776feee0bc75349ddf15b3f1473c42e9c23fbd2c286129db2314b", "price_changes": [{"asset_id": "19480453523641651203279098233362734886683676042431995106519882319527157746915", "price": "0.87", "size": "20", "side": "BUY", "hash": "d1abeb9a20c076d075cee72ecdb9e58aaca08f1c", "best_bid": "0.998", "best_ask": "1"}, {"asset_id": "87076761959524824596667767871338783105013148144014343593959452219056943445676", "price": "0.13", "size": "20", "side": "SELL", "hash": "a0e8f4f3cc3e895de764f5f1fa29f57a1bd55d5a", "best_bid": "0", "best_ask": "0.002"}], "timestamp": "1769384555664", "event_type": "price_change"}}
{"_local_timestamp": "2026-01-25T23:42:35.797486+00:00", "data": {"market": "0x813140d27e876be7b8b57a9f5932f560426e5dd02370e1a6d815ce416d3c1a1e", "price_changes": [{"asset_id": "42867658785582566258165916378080823643991642521460286045794854230410783654072", "price": "0.824", "size": "0", "side": "BUY", "hash": "f1b85a133a12c1a11f88cd0e2ce02115c636f2fa", "best_bid": "0.996", "best_ask": "1"}, {"asset_id": "39110700308891033765082720771423327970968989496145639822830381828556135408196", "price": "0.176", "size": "0", "side": "SELL", "hash": "c9373f1c9bdd8de7723f76714ae047b51c1db090", "best_bid": "0", "best_ask": "0.004"}], "timestamp": "1769384555664", "event_type": "price_change"}}
{"_local_timestamp": "2026-01-25T23:42:35.797802+00:00", "data": {"market": "0x34629a8e04da66f61bad2b4de18d370ca551faf79f810e04e403b841163f0e47", "price_changes": [{"asset_id": "81962021060291538332769225938832888553429136330721495433176438182361641360146", "price": "0.589", "size": "20", "side": "BUY", "hash": "b687751802836a3acb0bf326c58ec2dcd87bf5c4", "best_bid": "0.975", "best_ask": "0.987"}, {"asset_id": "24428969314967049374579832885004941749071678905985050510703983608884666132158", "price": "0.411", "size": "20", "side": "SELL", "hash": "3b624fa19e28c0e2ec626e2e8203eaba64cca628", "best_bid": "0.013", "best_ask": "0.025"}], "timestamp": "1769384555664", "event_type": "price_change"}}
{"_local_timestamp": "2026-01-25T23:42:35.798116+00:00", "data": {"market": "0x936a5e78fd5963c717e49661a593fa3353241f6fb3c69b6615e9041e6b6f0973", "price_changes": [{"asset_id": "62474888561798875936325899031095507932691561832763786042468556558023439824689", "price": "0.861", "size": "20", "side": "BUY", "hash": "bcf1076b9ce4d091d942b964d7e2e135ce220426", "best_bid": "0.997", "best_ask": "1"}, {"asset_id": "85450186084380419372744179618618425905211867206934194164904272142040477321142", "price": "0.139", "size": "20", "side": "SELL", "hash": "d51be3fe8f3cfc98f36c49a1a4da881a2ef2eb41", "best_bid": "0", "best_ask": "0.003"}], "timestamp": "1769384555664", "event_type": "price_change"}}
{"_local_timestamp": "2026-01-25T23:42:35.798395+00:00", "data": {"market": "0xd2b7235e5c612ce49ad0252420d713280ded4e346bd24dd50f941e901e9daec2", "price_changes": [{"asset_id": "110558202691925957098835226242947976618291676693360525080400622291263590296356", "price": "0.824", "size": "0", "side": "BUY", "hash": "44679dbe49eee26965dedc8adfa4fcf7ca15e894", "best_bid": "0.997", "best_ask": "0.999"}, {"asset_id": "62070332729843756648077334071325768265229024314411995286040519682521027925149", "price": "0.176", "size": "0", "side": "SELL", "hash": "751b68c0327df3c78d0b3d1f0ed9a2922006a347", "best_bid": "0.001", "best_ask": "0.003"}], "timestamp": "1769384555664", "event_type": "price_change"}}
{"_local_timestamp": "2026-01-25T23:42:35.798660+00:00", "data": {"market": "0x7996c5de13ddf3131cebe81e14fa25bc93e6d83383e9311fb4444d054b02bb6c", "price_changes": [{"asset_id": "81067297669492637828272330271687160515702268762196167960552103884621012706990", "price": "0.63", "size": "20", "side": "BUY", "hash": "6dc0a4cd9dd383f6e71c94f1e194dcfbbc45d623", "best_bid": "0.996", "best_ask": "1"}, {"asset_id": "35385046285095047875859550982501333940016148310175612786655121530268337331434", "price": "0.37", "size": "20", "side": "SELL", "hash": "6262f44c4677b0a309a1ef8e0f5705477b394f78", "best_bid": "0", "best_ask": "0.004"}], "timestamp": "1769384555664", "event_type": "price_change"}}
{"_local_timestamp": "2026-01-25T23:42:35.798926+00:00", "data": {"market": "0x1dcc183b4cca17ebd95af1b94209ce345233d13a8157c1b1761b6d82722614aa", "price_changes": [{"asset_id": "105584168793006337391660846202014742593893506579636126851936010970644475175057", "price": "0.824", "size": "0", "side": "BUY", "hash": "580d3086a5d4458858f6fc3c54bd5e35d507d5f2", "best_bid": "0.996", "best_ask": "1"}, {"asset_id": "34996430135377662182478828889088041580319309767069410756085253475349980098679", "price": "0.176", "size": "0", "side": "SELL", "hash": "4b1ee005340914ddcd8975049bf5f4d104a2345b", "best_bid": "0", "best_ask": "0.004"}], "timestamp": "1769384555664", "event_type": "price_change"}}
{"_local_timestamp": "2026-01-25T23:42:35.799174+00:00", "data": {"market": "0x00787f50b9466db23a1899abc108b5609a77cbaa159c1b35822f45e9c14a940b", "price_changes": [{"asset_id": "113809960451765367690598229673115216134099141989496655805640157545770316317603", "price": "0.864", "size": "20", "side": "BUY", "hash": "6b03f6d5c0cd66d0e9a61cc869b78692c200f973", "best_bid": "0.998", "best_ask": "0.999"}, {"asset_id": "76794312778172154876533172710848055841220591544022724903757628442504975481665", "price": "0.136", "size": "20", "side": "SELL", "hash": "8d65748a7117e49b6606189bcb799338db3a725b", "best_bid": "0.001", "best_ask": "0.002"}], "timestamp": "1769384555664", "event_type": "price_change"}}
{"_local_timestamp": "2026-01-25T23:42:35.799437+00:00", "data": {"market": "0x2c405b766a5952a1ee121519845541e3f363bbbb691748d38d596e900827333f", "price_changes": [{"asset_id": "45360012752670095623901322351652227247408888830488142163512756455139535103641", "price": "0.864", "size": "20", "side": "BUY", "hash": "5ea343337615d023ca4748823e9b2b03e344fcf2", "best_bid": "0.996", "best_ask": "1"}, {"asset_id": "44227097530829963499576501282186404645897936156929334280113391423971987257194", "price": "0.136", "size": "20", "side": "SELL", "hash": "29de5107c54370c2668a0e61163d329054437a1d", "best_bid": "0", "best_ask": "0.004"}], "timestamp": "1769384555664", "event_type": "price_change"}}
{"_local_timestamp": "2026-01-25T23:42:35.799737+00:00", "data": {"market": "0xeb60a53b5ca38150c07cc30ef0f5570b292f3e43722512cc55d0cff666ac1077", "price_changes": [{"asset_id": "83308171747089483400662168608358178791256497013703595264448211477259881059204", "price": "0.864", "size": "20", "side": "BUY", "hash": "5c6660925ac88dc6961b49084b57d8afa91773a2", "best_bid": "0.996", "best_ask": "1"}, {"asset_id": "72088688491610101384722384206165707443638739290798571693187856704797119769987", "price": "0.136", "size": "20", "side": "SELL", "hash": "c662304ba3db8cfffc7e0603344b5685d6de72db", "best_bid": "0", "best_ask": "0.004"}], "timestamp": "1769384555664", "event_type": "price_change"}}
{"_local_timestamp": "2026-01-25T23:42:35.800119+00:00", "data": {"market": "0x584caca7a7536029bef854652fa5fdd861631edbc01a217069341b85030edd6f", "price_changes": [{"asset_id": "8840594256975309703691759780728141785112443011041236897959089339991605786144", "price": "0.722", "size": "20", "side": "BUY", "hash": "d4d99b45526024ee1747e9e23431c9c8259704b9", "best_bid": "0.996", "best_ask": "1"}, {"asset_id": "69196677690927265002451334694240538592951011957285689708757350071125284654035", "price": "0.278", "size": "20", "side": "SELL", "hash": "3af3b8f3d0a46452a9f712584746f46729e58c6c", "best_bid": "0", "best_ask": "0.004"}], "timestamp": "1769384555664", "event_type": "price_change"}}
{"_local_timestamp": "2026-01-25T23:42:35.800371+00:00", "data": {"market": "0x5bc6ce968259b72cf129f3420b74591165b2daed5681c945a550d3479a6cd29f", "price_changes": [{"asset_id": "13658847648110704810290854236711050722034916311708159351742514374794523650635", "price": "0.824", "size": "20", "side": "BUY", "hash": "17617e2d431ef636b91ca2cd11a63c7ce7eee458", "best_bid": "0.996", "best_ask": "0.999"}, {"asset_id": "75885549806041705440616483171403974382986377202053531674757984617564016983448", "price": "0.176", "size": "20", "side": "SELL", "hash": "b64b81bf593e2589464dd9d8eec50356e8ac1b0b", "best_bid": "0.001", "best_ask": "0.004"}], "timestamp": "1769384555664", "event_type": "price_change"}}
{"_local_timestamp": "2026-01-25T23:42:35.800626+00:00", "data": {"market": "0x208c0100d3c9b2e1cfe6acd453a461a2db052ea6de69345e20ba97bd80b24a32", "price_changes": [{"asset_id": "50847646174397103153022714653544400551806761556088789644031638820781566442427", "price": "0.861", "size": "20", "side": "BUY", "hash": "a135ec7d1ed6bf80eff24f1f45df2f59e613a971", "best_bid": "0.998", "best_ask": "1"}, {"asset_id": "25190149186348626497584661665153964321010101728496495635131758054890103740875", "price": "0.139", "size": "20", "side": "SELL", "hash": "edd14a11c181f42a254e6297a9f5b2a346bce67a", "best_bid": "0", "best_ask": "0.002"}], "timestamp": "1769384555664", "event_type": "price_change"}}
{"_local_timestamp": "2026-01-25T23:42:35.800873+00:00", "data": {"market": "0xff54852cf4cb9c3568f795b983bc494d2e13d3f9cad41ba872a4ffd3ccb2101e", "price_changes": [{"asset_id": "96140164996170695869329923820202447276846115725253325303263315936085179713314", "price": "0.863", "size": "20", "side": "BUY", "hash": "abf8405cd1d1feec68ab79c1d5bb06a91a248e18", "best_bid": "0.996", "best_ask": "1"}, {"asset_id": "91203260296949109747095851381415926782789749145484395871735811789947699971761", "price": "0.137", "size": "20", "side": "SELL", "hash": "4257ca1970b8c0fe41b0a680b8395cd3a7c1ace6", "best_bid": "0", "best_ask": "0.004"}], "timestamp": "1769384555664", "event_type": "price_change"}}
{"_local_timestamp": "2026-01-25T23:42:35.801176+00:00", "data": {"market": "0xaefc28d462f0824bbb9c694d3511beaaf8b21af8eba30d8e524ed05d0431e712", "price_changes": [{"asset_id": "44763420328579357949062599081517223538923284512329276353056439811950932880097", "price": "0.876", "size": "20", "side": "BUY", "hash": "217aae88b6de99059afb2a844edb822a78d5da6d", "best_bid": "0.998", "best_ask": "0.999"}, {"asset_id": "74056431860682289842871849619463099581884627064723191566088662788504744554943", "price": "0.124", "size": "20", "side": "SELL", "hash": "a37233c7c6e659cb3b924d648583fccacacd1b37", "best_bid": "0.001", "best_ask": "0.002"}], "timestamp": "1769384555664", "event_type": "price_change"}}
{"_local_timestamp": "2026-01-25T23:42:36.628772+00:00", "data": {"market": "0x00787f50b9466db23a1899abc108b5609a77cbaa159c1b35822f45e9c14a940b", "price_changes": [{"asset_id": "113809960451765367690598229673115216134099141989496655805640157545770316317603", "price": "0.863", "size": "0", "side": "BUY", "hash": "f71b45bc01b3b230451cb2f53b6bc4363618d1e5", "best_bid": "0.998", "best_ask": "0.999"}, {"asset_id": "76794312778172154876533172710848055841220591544022724903757628442504975481665", "price": "0.137", "size": "0", "side": "SELL", "hash": "fa7535c3d078ec83e27631eda51a5c967d00b113", "best_bid": "0.001", "best_ask": "0.002"}], "timestamp": "1769384556494", "event_type": "price_change"}}
{"_local_timestamp": "2026-01-25T23:42:36.629141+00:00", "data": {"market": "0xaefc28d462f0824bbb9c694d3511beaaf8b21af8eba30d8e524ed05d0431e712", "price_changes": [{"asset_id": "44763420328579357949062599081517223538923284512329276353056439811950932880097", "price": "0.875", "size": "0", "side": "BUY", "hash": "d5911485f92c6176c57db990a31fbbf0d7ac0f50", "best_bid": "0.998", "best_ask": "0.999"}, {"asset_id": "74056431860682289842871849619463099581884627064723191566088662788504744554943", "price": "0.125", "size": "0", "side": "SELL", "hash": "542352c4918305dd60aaaf253cfc6f4db791b83f", "best_bid": "0.001", "best_ask": "0.002"}], "timestamp": "1769384556494", "event_type": "price_change"}}
{"_local_timestamp": "2026-01-25T23:42:36.631209+00:00", "data": {"market": "0xad8e9885ec2473d0ba49c38449dfd4d18ad7c0f7a14625a24865857e18a94850", "price_changes": [{"asset_id": "6063771237142095573570898636767550587549260179390402809546741793309719810883", "price": "0.519", "size": "0", "side": "BUY", "hash": "571b0a90e5c2d52fb7ed23afff12c16eaadfbe8f", "best_bid": "0.992", "best_ask": "0.996"}, {"asset_id": "40355817413446270517300817460473958731033814018091765438985668051022432561988", "price": "0.481", "size": "0", "side": "SELL", "hash": "1f0889075e51d6df5c8f8edd40b00ada3bad7c73", "best_bid": "0.004", "best_ask": "0.008"}], "timestamp": "1769384556494", "event_type": "price_change"}}
{"_local_timestamp": "2026-01-25T23:42:36.632481+00:00", "data": {"market": "0x34629a8e04da66f61bad2b4de18d370ca551faf79f810e04e403b841163f0e47", "price_changes": [{"asset_id": "81962021060291538332769225938832888553429136330721495433176438182361641360146", "price": "0.588", "size": "0", "side": "BUY", "hash": "e68e8d4d4c5ee3397450a3c361475b96f9b0f2df", "best_bid": "0.975", "best_ask": "0.987"}, {"asset_id": "24428969314967049374579832885004941749071678905985050510703983608884666132158", "price": "0.412", "size": "0", "side": "SELL", "hash": "4a184457961686d7477f4bc12fff982f21157bce", "best_bid": "0.013", "best_ask": "0.025"}], "timestamp": "1769384556494", "event_type": "price_change"}}
{"_local_timestamp": "2026-01-25T23:42:36.633032+00:00", "data": {"market": "0xe819c3fd02eec251efec7d90a1801554ec14fef336932c7342b333d4ae64d0a8", "price_changes": [{"asset_id": "99877125227544421735443256554390914792518157728590758473713836440156917197132", "price": "0.83", "size": "0", "side": "BUY", "hash": "653c39f7047405c4110fa3fb41bc6e0edc0fbcd6", "best_bid": "0.945", "best_ask": "0.991"}, {"asset_id": "110183118205658048480611552004818205608380030301879472767196181141473018245608", "price": "0.17", "size": "0", "side": "SELL", "hash": "96ae94ec82ecbc8da563201bdace086c718a91c4", "best_bid": "0.009", "best_ask": "0.055"}], "timestamp": "1769384556494", "event_type": "price_change"}}
{"_local_timestamp": "2026-01-25T23:42:36.633361+00:00", "data": {"market": "0x5882bfbb3333c4425fe5f17d7177d0155935ab218532e30abb3ebc29e09b0d15", "price_changes": [{"asset_id": "37022134553940218760484349283577041579348129770638687563562605588225179219348", "price": "0.826", "size": "0", "side": "BUY", "hash": "ffb2eab6244193e38e060bc26e406f73b4202cf3", "best_bid": "0.998", "best_ask": "0.999"}, {"asset_id": "98286904268100078035776152708720247190143751657794196422985487083520781931503", "price": "0.174", "size": "0", "side": "SELL", "hash": "3925a54a59fe3ce5aa44b5031c8c66c34a04987e", "best_bid": "0.001", "best_ask": "0.002"}], "timestamp": "1769384556494", "event_type": "price_change"}}
{"_local_timestamp": "2026-01-25T23:42:36.668385+00:00", "data": {"market": "0xe819c3fd02eec251efec7d90a1801554ec14fef336932c7342b333d4ae64d0a8", "price_changes": [{"asset_id": "99877125227544421735443256554390914792518157728590758473713836440156917197132", "price": "0.824", "size": "11.27", "side": "BUY", "hash": "6829795f6f13e1191d66628637fb81fd8e7391df", "best_bid": "0.945", "best_ask": "0.991"}, {"asset_id": "110183118205658048480611552004818205608380030301879472767196181141473018245608", "price": "0.176", "size": "11.27", "side": "SELL", "hash": "4d2026f96716a1c928bd5451cca3ddb6a6d629d5", "best_bid": "0.009", "best_ask": "0.055"}], "timestamp": "1769384556527", "event_type": "price_change"}}
{"_local_timestamp": "2026-01-25T23:42:36.668777+00:00", "data": {"market": "0xad8e9885ec2473d0ba49c38449dfd4d18ad7c0f7a14625a24865857e18a94850", "price_changes": [{"asset_id": "6063771237142095573570898636767550587549260179390402809546741793309719810883", "price": "0.521", "size": "11.27", "side": "BUY", "hash": "d0a5fcb25eeace252278dccd1c823edd6a14cd2b", "best_bid": "0.992", "best_ask": "0.996"}, {"asset_id": "40355817413446270517300817460473958731033814018091765438985668051022432561988", "price": "0.479", "size": "11.27", "side": "SELL", "hash": "9a69cbe89626d43988a6957d40a4a419d2ed2b35", "best_bid": "0.004", "best_ask": "0.008"}], "timestamp": "1769384556527", "event_type": "price_change"}}
{"_local_timestamp": "2026-01-25T23:42:36.669038+00:00", "data": {"market": "0x00787f50b9466db23a1899abc108b5609a77cbaa159c1b35822f45e9c14a940b", "price_changes": [{"asset_id": "113809960451765367690598229673115216134099141989496655805640157545770316317603", "price": "0.865", "size": "11.27", "side": "BUY", "hash": "85dc89392a8ddc1159839d39c41eef3e4f72197b", "best_bid": "0.998", "best_ask": "0.999"}, {"asset_id": "76794312778172154876533172710848055841220591544022724903757628442504975481665", "price": "0.135", "size": "11.27", "side": "SELL", "hash": "742a513fe354ae05f4483aad1a3cadfd1f821160", "best_bid": "0.001", "best_ask": "0.002"}], "timestamp": "1769384556527", "event_type": "price_change"}}
{"_local_timestamp": "2026-01-25T23:42:36.669327+00:00", "data": {"market": "0x34629a8e04da66f61bad2b4de18d370ca551faf79f810e04e403b841163f0e47", "price_changes": [{"asset_id": "81962021060291538332769225938832888553429136330721495433176438182361641360146", "price": "0.59", "size": "11.27", "side": "BUY", "hash": "7a734e8a15cb0a9a6680d46b4fadd671c0f826fd", "best_bid": "0.975", "best_ask": "0.987"}, {"asset_id": "24428969314967049374579832885004941749071678905985050510703983608884666132158", "price": "0.41", "size": "11.27", "side": "SELL", "hash": "41e1e39109e36e762b38e51ac43de3062e84c4b4", "best_bid": "0.013", "best_ask": "0.025"}], "timestamp": "1769384556527", "event_type": "price_change"}}
{"_local_timestamp": "2026-01-25T23:42:36.832960+00:00", "data": {"market": "0xaefc28d462f0824bbb9c694d3511beaaf8b21af8eba30d8e524ed05d0431e712", "price_changes": [{"asset_id": "44763420328579357949062599081517223538923284512329276353056439811950932880097", "price": "0.877", "size": "11.27", "side": "BUY", "hash": "3dc83ec2810bbebbdd4edd2f9d848f2b2b0bf5c3", "best_bid": "0.998", "best_ask": "0.999"}, {"asset_id": "74056431860682289842871849619463099581884627064723191566088662788504744554943", "price": "0.123", "size": "11.27", "side": "SELL", "hash": "9d47e39e8a94d6852b8f854af30c848fafee30b4", "best_bid": "0.001", "best_ask": "0.002"}], "timestamp": "1769384556527", "event_type": "price_change"}}
{"_local_timestamp": "2026-01-25T23:42:36.833345+00:00", "data": {"market": "0x5882bfbb3333c4425fe5f17d7177d0155935ab218532e30abb3ebc29e09b0d15", "price_changes": [{"asset_id": "37022134553940218760484349283577041579348129770638687563562605588225179219348", "price": "0.828", "size": "11.27", "side": "BUY", "hash": "8158d8c763e95a4a94285d61ba8c238b6713f86b", "best_bid": "0.998", "best_ask": "0.999"}, {"asset_id": "98286904268100078035776152708720247190143751657794196422985487083520781931503", "price": "0.172", "size": "11.27", "side": "SELL", "hash": "49c023daf3de89eac12a19790680c20feb201ed2", "best_bid": "0.001", "best_ask": "0.002"}], "timestamp": "1769384556527", "event_type": "price_change"}}
{"_local_timestamp": "2026-01-25T23:42:55.275898+00:00", "data": {"market": "0xa449cd8346b6deda561828355ae92b88bd47d989859d2d287ce7e42a42b556c7", "price_changes": [{"asset_id": "91120885899126885515852202682357546652544305953593660618778514157513430201648", "price": "0.09", "size": "109.24", "side": "SELL", "hash": "639513558d79b91acde36ffaafd3f801135ecf7c", "best_bid": "0.06", "best_ask": "0.09"}, {"asset_id": "50990718602111286221499412828092223474799500548329402570398939983325937296388", "price": "0.91", "size": "109.24", "side": "BUY", "hash": "322dab5e9ef2a0b6b870b6d657f8188b273d9f5b", "best_bid": "0.91", "best_ask": "0.94"}], "timestamp": "1769384575140", "event_type": "price_change"}}
{"_local_timestamp": "2026-01-25T23:42:55.354243+00:00", "data": {"market": "0x936a5e78fd5963c717e49661a593fa3353241f6fb3c69b6615e9041e6b6f0973", "price_changes": [{"asset_id": "62474888561798875936325899031095507932691561832763786042468556558023439824689", "price": "0.861", "size": "0", "side": "BUY", "hash": "c1a2448020f9fb9e555f5fb2198540f337342650", "best_bid": "0.997", "best_ask": "1"}, {"asset_id": "85450186084380419372744179618618425905211867206934194164904272142040477321142", "price": "0.139", "size": "0", "side": "SELL", "hash": "559f65e1685c8908daabc98070e8bd76fcac5488", "best_bid": "0", "best_ask": "0.003"}], "timestamp": "1769384575219", "event_type": "price_change"}}
{"_local_timestamp": "2026-01-25T23:42:55.354679+00:00", "data": {"market": "0xeb60a53b5ca38150c07cc30ef0f5570b292f3e43722512cc55d0cff666ac1077", "price_changes": [{"asset_id": "83308171747089483400662168608358178791256497013703595264448211477259881059204", "price": "0.864", "size": "0", "side": "BUY", "hash": "627e15bcfe7bc8cf1addf5ed51ccb88101f09e68", "best_bid": "0.996", "best_ask": "1"}, {"asset_id": "72088688491610101384722384206165707443638739290798571693187856704797119769987", "price": "0.136", "size": "0", "side": "SELL", "hash": "6369a97de6823a703c8c1d433c07010ea0b4c714", "best_bid": "0", "best_ask": "0.004"}], "timestamp": "1769384575219", "event_type": "price_change"}}
{"_local_timestamp": "2026-01-25T23:42:55.354988+00:00", "data": {"market": "0x00787f50b9466db23a1899abc108b5609a77cbaa159c1b35822f45e9c14a940b", "price_changes": [{"asset_id": "113809960451765367690598229673115216134099141989496655805640157545770316317603", "price": "0.864", "size": "0", "side": "BUY", "hash": "a7e27a715779e15dc74b8c2f1a363df34253b654", "best_bid": "0.998", "best_ask": "0.999"}, {"asset_id": "76794312778172154876533172710848055841220591544022724903757628442504975481665", "price": "0.136", "size": "0", "side": "SELL", "hash": "8fb12b4614a29dcb1263eacef3746fbde17f0864", "best_bid": "0.001", "best_ask": "0.002"}], "timestamp": "1769384575219", "event_type": "price_change"}}
{"_local_timestamp": "2026-01-25T23:42:55.355221+00:00", "data": {"market": "0x1dcc183b4cca17ebd95af1b94209ce345233d13a8157c1b1761b6d82722614aa", "price_changes": [{"asset_id": "105584168793006337391660846202014742593893506579636126851936010970644475175057", "price": "0.864", "size": "0", "side": "BUY", "hash": "fd9f94776d79bc6d7872ae8a87571a30f04d89a8", "best_bid": "0.996", "best_ask": "1"}, {"asset_id": "34996430135377662182478828889088041580319309767069410756085253475349980098679", "price": "0.136", "size": "0", "side": "SELL", "hash": "7b2bcd7885af8bcea2d7228bfa25ff4ee9367114", "best_bid": "0", "best_ask": "0.004"}], "timestamp": "1769384575219", "event_type": "price_change"}}
{"_local_timestamp": "2026-01-25T23:42:55.355823+00:00", "data": {"market": "0xc901b7ee5f6776feee0bc75349ddf15b3f1473c42e9c23fbd2c286129db2314b", "price_changes": [{"asset_id": "19480453523641651203279098233362734886683676042431995106519882319527157746915", "price": "0.87", "size": "0", "side": "BUY", "hash": "929ea2d0ae118bc604841550326725559f6ab206", "best_bid": "0.998", "best_ask": "1"}, {"asset_id": "87076761959524824596667767871338783105013148144014343593959452219056943445676", "price": "0.13", "size": "0", "side": "SELL", "hash": "5a1910f982607add053ce3c48d62a7351dc91ad3", "best_bid": "0", "best_ask": "0.002"}], "timestamp": "1769384575219", "event_type": "price_change"}}
{"_local_timestamp": "2026-01-25T23:42:55.356123+00:00", "data": {"market": "0x3ab6710aff85c354a3d99e0f3c972903263189ce32b1a5b13ed58cb68762b243", "price_changes": [{"asset_id": "51021073159046014273765711044237457499013035764061127438623007427221796941192", "price": "0.844", "size": "271", "side": "BUY", "hash": "489d910dbacb39edc514f4005380f1908edaff34", "best_bid": "0.998", "best_ask": "0.999"}, {"asset_id": "12436606244684756212688349482021343426028351538039522454366335615620119043815", "price": "0.156", "size": "271", "side": "SELL", "hash": "cf0cae47dc167bddbb95127aab36afb1723c9617", "best_bid": "0.001", "best_ask": "0.002"}], "timestamp": "1769384575219", "event_type": "price_change"}}
{"_local_timestamp": "2026-01-25T23:42:55.356415+00:00", "data": {"market": "0x82bd65f09e2428042a5ac204f60f34e1b40f7a4a2d008fc0b92afd0aca450607", "price_changes": [{"asset_id": "110679481699383362322327302278895149696397996918330653214772805833135400912448", "price": "0.596", "size": "0", "side": "BUY", "hash": "d4ef0b6edfe34a74566a634465f3ced4bca62668", "best_bid": "0.998", "best_ask": "0.999"}, {"asset_id": "67038866817302942551959484913198849155750799193273634269443232905877417785248", "price": "0.404", "size": "0", "side": "SELL", "hash": "b44979f869999ff134c07c600a917f5ea3fa2531", "best_bid": "0.001", "best_ask": "0.002"}], "timestamp": "1769384575219", "event_type": "price_change"}}
{"_local_timestamp": "2026-01-25T23:42:55.356638+00:00", "data": {"market": "0x4fc188ab7b8337089312087777af8a703757466dda919e1de85e148394c40090", "price_changes": [{"asset_id": "67034694271202563859644094265338465614375382145815138322023215311029487392827", "price": "0.925", "size": "0", "side": "BUY", "hash": "3cc5c92c89e74e95edba4aafd8288074abcde925", "best_bid": "0.996", "best_ask": "1"}, {"asset_id": "22440526641822362681904932185789972209232343897283048384344291619576375972156", "price": "0.075", "size": "0", "side": "SELL", "hash": "4dbee71d2c184b39882353cfde0af0ed4228dc8d", "best_bid": "0", "best_ask": "0.004"}], "timestamp": "1769384575219", "event_type": "price_change"}}
{"_local_timestamp": "2026-01-25T23:42:55.356871+00:00", "data": {"market": "0x2c405b766a5952a1ee121519845541e3f363bbbb691748d38d596e900827333f", "price_changes": [{"asset_id": "45360012752670095623901322351652227247408888830488142163512756455139535103641", "price": "0.864", "size": "0", "side": "BUY", "hash": "ed76cf4368cc7ce397e3f37591a12be9b516b28b", "best_bid": "0.996", "best_ask": "1"}, {"asset_id": "44227097530829963499576501282186404645897936156929334280113391423971987257194", "price": "0.136", "size": "0", "side": "SELL", "hash": "b97e74210c31dd4e8cacaaf2bda4e2deaf82ac0a", "best_bid": "0", "best_ask": "0.004"}], "timestamp": "1769384575219", "event_type": "price_change"}}
{"_local_timestamp": "2026-01-25T23:42:55.475909+00:00", "data": {"market": "0x208c0100d3c9b2e1cfe6acd453a461a2db052ea6de69345e20ba97bd80b24a32", "price_changes": [{"asset_id": "50847646174397103153022714653544400551806761556088789644031638820781566442427", "price": "0.861", "size": "0", "side": "BUY", "hash": "0856f07604f26815f53bd94d93b22ba7a2e4de65", "best_bid": "0.998", "best_ask": "1"}, {"asset_id": "25190149186348626497584661665153964321010101728496495635131758054890103740875", "price": "0.139", "size": "0", "side": "SELL", "hash": "21f7498fa1a42fab17ed01a934a5e04baa8a2c0b", "best_bid": "0", "best_ask": "0.002"}], "timestamp": "1769384575219", "event_type": "price_change"}}
{"_local_timestamp": "2026-01-25T23:42:55.476259+00:00", "data": {"market": "0x7996c5de13ddf3131cebe81e14fa25bc93e6d83383e9311fb4444d054b02bb6c", "price_changes": [{"asset_id": "81067297669492637828272330271687160515702268762196167960552103884621012706990", "price": "0.63", "size": "0", "side": "BUY", "hash": "5343afe66dc0a98ba2500fd7855fad43232a8f7b", "best_bid": "0.996", "best_ask": "1"}, {"asset_id": "35385046285095047875859550982501333940016148310175612786655121530268337331434", "price": "0.37", "size": "0", "side": "SELL", "hash": "83e9c3ca07fab85e35bd80694df7a8f2ec105c35", "best_bid": "0", "best_ask": "0.004"}], "timestamp": "1769384575219", "event_type": "price_change"}}
{"_local_timestamp": "2026-01-25T23:42:55.476740+00:00", "data": {"market": "0x34629a8e04da66f61bad2b4de18d370ca551faf79f810e04e403b841163f0e47", "price_changes": [{"asset_id": "81962021060291538332769225938832888553429136330721495433176438182361641360146", "price": "0.589", "size": "0", "side": "BUY", "hash": "8c94ff7c48f87d2fc4d04815242abfd66b402919", "best_bid": "0.975", "best_ask": "0.987"}, {"asset_id": "24428969314967049374579832885004941749071678905985050510703983608884666132158", "price": "0.411", "size": "0", "side": "SELL", "hash": "a1ef3a747e483325ad57bab75ee384f11b6eaef5", "best_bid": "0.013", "best_ask": "0.025"}], "timestamp": "1769384575219", "event_type": "price_change"}}
{"_local_timestamp": "2026-01-25T23:42:55.477201+00:00", "data": {"market": "0x813140d27e876be7b8b57a9f5932f560426e5dd02370e1a6d815ce416d3c1a1e", "price_changes": [{"asset_id": "42867658785582566258165916378080823643991642521460286045794854230410783654072", "price": "0.863", "size": "0", "side": "BUY", "hash": "2b21e1ef51783d8a7ab95c77d0fe699d596fa8e2", "best_bid": "0.996", "best_ask": "1"}, {"asset_id": "39110700308891033765082720771423327970968989496145639822830381828556135408196", "price": "0.137", "size": "0", "side": "SELL", "hash": "8a737e670980dae2e9417ecad65bcf25a9ce9ed8", "best_bid": "0", "best_ask": "0.004"}], "timestamp": "1769384575219", "event_type": "price_change"}}
{"_local_timestamp": "2026-01-25T23:42:55.555560+00:00", "data": {"market": "0xad8e9885ec2473d0ba49c38449dfd4d18ad7c0f7a14625a24865857e18a94850", "price_changes": [{"asset_id": "6063771237142095573570898636767550587549260179390402809546741793309719810883", "price": "0.52", "size": "0", "side": "BUY", "hash": "94f771624391ccc02e8bc4f005ff9dd2fd9a1449", "best_bid": "0.992", "best_ask": "0.996"}, {"asset_id": "40355817413446270517300817460473958731033814018091765438985668051022432561988", "price": "0.48", "size": "0", "side": "SELL", "hash": "1c46fe5ca9e6a3b84acfa5388e32c9c220bf8411", "best_bid": "0.004", "best_ask": "0.008"}], "timestamp": "1769384575219", "event_type": "price_change"}}
{"_local_timestamp": "2026-01-25T23:42:55.555916+00:00", "data": {"market": "0xe819c3fd02eec251efec7d90a1801554ec14fef336932c7342b333d4ae64d0a8", "price_changes": [{"asset_id": "99877125227544421735443256554390914792518157728590758473713836440156917197132", "price": "0.913", "size": "0", "side": "BUY", "hash": "7e793e69d047ce06759d59d7ac30f957a3b5d6ce", "best_bid": "0.945", "best_ask": "0.991"}, {"asset_id": "110183118205658048480611552004818205608380030301879472767196181141473018245608", "price": "0.087", "size": "0", "side": "SELL", "hash": "20107b4637ce3479309eabba4eaf9e7e96eab78f", "best_bid": "0.009", "best_ask": "0.055"}], "timestamp": "1769384575219", "event_type": "price_change"}}
{"_local_timestamp": "2026-01-25T23:42:55.556183+00:00", "data": {"market": "0x584caca7a7536029bef854652fa5fdd861631edbc01a217069341b85030edd6f", "price_changes": [{"asset_id": "8840594256975309703691759780728141785112443011041236897959089339991605786144", "price": "0.722", "size": "0", "side": "BUY", "hash": "a144d4892581355c68844b4b1b03b54c686c71ce", "best_bid": "0.996", "best_ask": "1"}, {"asset_id": "69196677690927265002451334694240538592951011957285689708757350071125284654035", "price": "0.278", "size": "0", "side": "SELL", "hash": "b74cd75e397f4345ba207f6f53be9639a04e3e20", "best_bid": "0", "best_ask": "0.004"}], "timestamp": "1769384575219", "event_type": "price_change"}}
{"_local_timestamp": "2026-01-25T23:42:55.556415+00:00", "data": {"market": "0xc5a5599959ff15ca3533656c16dd441304b8721162ef770db59a1d2b4862e2b8", "price_changes": [{"asset_id": "48279448787839069698930026835059287278898209340746904712996610649334841531409", "price": "0.875", "size": "0", "side": "BUY", "hash": "5f7741d50585684ad3b28790ce23c75466ab290b", "best_bid": "0.996", "best_ask": "1"}, {"asset_id": "73040552226217734695850503696187376710006575449764477997853420807432098137837", "price": "0.125", "size": "0", "side": "SELL", "hash": "e2bc562f2d1e907a2680840cff36cbed135ca62e", "best_bid": "0", "best_ask": "0.004"}], "timestamp": "1769384575219", "event_type": "price_change"}}
{"_local_timestamp": "2026-01-25T23:42:55.556670+00:00", "data": {"market": "0xaefc28d462f0824bbb9c694d3511beaaf8b21af8eba30d8e524ed05d0431e712", "price_changes": [{"asset_id": "44763420328579357949062599081517223538923284512329276353056439811950932880097", "price": "0.876", "size": "0", "side": "BUY", "hash": "b258d256622e40f952840079f94db5eda0a95329", "best_bid": "0.998", "best_ask": "0.999"}, {"asset_id": "74056431860682289842871849619463099581884627064723191566088662788504744554943", "price": "0.124", "size": "0", "side": "SELL", "hash": "57b249491b3c8d387563153f8ccfb5dcf9d62a31", "best_bid": "0.001", "best_ask": "0.002"}], "timestamp": "1769384575219", "event_type": "price_change"}}
{"_local_timestamp": "2026-01-25T23:42:55.557076+00:00", "data": {"market": "0xc5a5599959ff15ca3533656c16dd441304b8721162ef770db59a1d2b4862e2b8", "price_changes": [{"asset_id": "48279448787839069698930026835059287278898209340746904712996610649334841531409", "price": "0.824", "size": "0", "side": "BUY", "hash": "5f7741d50585684ad3b28790ce23c75466ab290b", "best_bid": "0.996", "best_ask": "1"}, {"asset_id": "73040552226217734695850503696187376710006575449764477997853420807432098137837", "price": "0.176", "size": "0", "side": "SELL", "hash": "e2bc562f2d1e907a2680840cff36cbed135ca62e", "best_bid": "0", "best_ask": "0.004"}], "timestamp": "1769384575219", "event_type": "price_change"}}
{"_local_timestamp": "2026-01-25T23:42:55.557371+00:00", "data": {"market": "0xd2b7235e5c612ce49ad0252420d713280ded4e346bd24dd50f941e901e9daec2", "price_changes": [{"asset_id": "110558202691925957098835226242947976618291676693360525080400622291263590296356", "price": "0.916", "size": "0", "side": "BUY", "hash": "6dbaeeef75ca8850e5113700cbc59825265cc3b6", "best_bid": "0.997", "best_ask": "0.999"}, {"asset_id": "62070332729843756648077334071325768265229024314411995286040519682521027925149", "price": "0.084", "size": "0", "side": "SELL", "hash": "88627a8ad497d175092aa7c531211f68eb5954cb", "best_bid": "0.001", "best_ask": "0.003"}], "timestamp": "1769384575219", "event_type": "price_change"}}
{"_local_timestamp": "2026-01-25T23:42:55.557625+00:00", "data": {"market": "0x5bc6ce968259b72cf129f3420b74591165b2daed5681c945a550d3479a6cd29f", "price_changes": [{"asset_id": "13658847648110704810290854236711050722034916311708159351742514374794523650635", "price": "0.824", "size": "0", "side": "BUY", "hash": "7ddad6c867a5a4769a38d85676a62bc337aec920", "best_bid": "0.996", "best_ask": "0.999"}, {"asset_id": "75885549806041705440616483171403974382986377202053531674757984617564016983448", "price": "0.176", "size": "0", "side": "SELL", "hash": "4476f93526c92f990597e507bbbe1a60b72a89ce", "best_bid": "0.001", "best_ask": "0.004"}], "timestamp": "1769384575219", "event_type": "price_change"}}
{"_local_timestamp": "2026-01-25T23:42:55.557895+00:00", "data": {"market": "0xbba1c02a186676782fae38b63af5333da443c8a16d86274ba1b045324ec989c7", "price_changes": [{"asset_id": "58144744252589479691808124143280036251902716811429258360320338495684055413095", "price": "0.827", "size": "0", "side": "BUY", "hash": "89e374cdd5cbcf2f4e2568f8b8656196f55d30fc", "best_bid": "0.996", "best_ask": "1"}, {"asset_id": "60301519933335336364820582307817349741317665540686207245282394805552819791374", "price": "0.173", "size": "0", "side": "SELL", "hash": "c3859879be5adfdb056b3dd5e9549f4e555e772f", "best_bid": "0", "best_ask": "0.004"}], "timestamp": "1769384575219", "event_type": "price_change"}}
{"_local_timestamp": "2026-01-25T23:42:55.558161+00:00", "data": {"market": "0x5882bfbb3333c4425fe5f17d7177d0155935ab218532e30abb3ebc29e09b0d15", "price_changes": [{"asset_id": "37022134553940218760484349283577041579348129770638687563562605588225179219348", "price": "0.929", "size": "0", "side": "BUY", "hash": "9d2165e9907cb9b93379c0e5b98fd288e4279136", "best_bid": "0.998", "best_ask": "0.999"}, {"asset_id": "98286904268100078035776152708720247190143751657794196422985487083520781931503", "price": "0.071", "size": "0", "side": "SELL", "hash": "c5c0ae5029f7130aa66b7dfe01b89db488f54e27", "best_bid": "0.001", "best_ask": "0.002"}], "timestamp": "1769384575219", "event_type": "price_change"}}
{"_local_timestamp": "2026-01-25T23:42:55.558489+00:00", "data": {"market": "0x5882bfbb3333c4425fe5f17d7177d0155935ab218532e30abb3ebc29e09b0d15", "price_changes": [{"asset_id": "37022134553940218760484349283577041579348129770638687563562605588225179219348", "price": "0.827", "size": "0", "side": "BUY", "hash": "9d2165e9907cb9b93379c0e5b98fd288e4279136", "best_bid": "0.998", "best_ask": "0.999"}, {"asset_id": "98286904268100078035776152708720247190143751657794196422985487083520781931503", "price": "0.173", "size": "0", "side": "SELL", "hash": "c5c0ae5029f7130aa66b7dfe01b89db488f54e27", "best_bid": "0.001", "best_ask": "0.002"}], "timestamp": "1769384575219", "event_type": "price_change"}}
{"_local_timestamp": "2026-01-25T23:42:55.558734+00:00", "data": {"market": "0xff54852cf4cb9c3568f795b983bc494d2e13d3f9cad41ba872a4ffd3ccb2101e", "price_changes": [{"asset_id": "96140164996170695869329923820202447276846115725253325303263315936085179713314", "price": "0.863", "size": "0", "side": "BUY", "hash": "eb6c5c8462e7505304f90ce7f66ca1938dc5b2bb", "best_bid": "0.996", "best_ask": "1"}, {"asset_id": "91203260296949109747095851381415926782789749145484395871735811789947699971761", "price": "0.137", "size": "0", "side": "SELL", "hash": "d75500285064cb0e604ec19397fd9d5db458fbf1", "best_bid": "0", "best_ask": "0.004"}], "timestamp": "1769384575219", "event_type": "price_change"}}
{"_local_timestamp": "2026-01-25T23:42:55.558965+00:00", "data": {"market": "0xa449cd8346b6deda561828355ae92b88bd47d989859d2d287ce7e42a42b556c7", "price_changes": [{"asset_id": "91120885899126885515852202682357546652544305953593660618778514157513430201648", "price": "0.09", "size": "134.24", "side": "SELL", "hash": "8426574f514785ab83228b56f8516a5ff9735e7f", "best_bid": "0.06", "best_ask": "0.09"}, {"asset_id": "50990718602111286221499412828092223474799500548329402570398939983325937296388", "price": "0.91", "size": "134.24", "side": "BUY", "hash": "d683a0314cb641f634f25c30aedd6ba20a0b242c", "best_bid": "0.91", "best_ask": "0.94"}], "timestamp": "1769384575333", "event_type": "price_change"}}
{"_local_timestamp": "2026-01-25T23:42:55.559206+00:00", "data": {"market": "0xe819c3fd02eec251efec7d90a1801554ec14fef336932c7342b333d4ae64d0a8", "price_changes": [{"asset_id": "99877125227544421735443256554390914792518157728590758473713836440156917197132", "price": "0.912", "size": "0", "side": "BUY", "hash": "4562886b6a06dafd7ea0953051d7130a2aab4610", "best_bid": "0.945", "best_ask": "0.991"}, {"asset_id": "110183118205658048480611552004818205608380030301879472767196181141473018245608", "price": "0.088", "size": "0", "side": "SELL", "hash": "ff295434a609c100433b0a98032798bf3390a6bd", "best_bid": "0.009", "best_ask": "0.055"}], "timestamp": "1769384575334", "event_type": "price_change"}}
{"_local_timestamp": "2026-01-25T23:42:55.560830+00:00", "data": {"market": "0xe819c3fd02eec251efec7d90a1801554ec14fef336932c7342b333d4ae64d0a8", "price_changes": [{"asset_id": "99877125227544421735443256554390914792518157728590758473713836440156917197132", "price": "0.248", "size": "0", "side": "BUY", "hash": "4562886b6a06dafd7ea0953051d7130a2aab4610", "best_bid": "0.945", "best_ask": "0.991"}, {"asset_id": "110183118205658048480611552004818205608380030301879472767196181141473018245608", "price": "0.752", "size": "0", "side": "SELL", "hash": "ff295434a609c100433b0a98032798bf3390a6bd", "best_bid": "0.009", "best_ask": "0.055"}], "timestamp": "1769384575334", "event_type": "price_change"}}
{"_local_timestamp": "2026-01-25T23:42:55.561119+00:00", "data": {"market": "0x00787f50b9466db23a1899abc108b5609a77cbaa159c1b35822f45e9c14a940b", "price_changes": [{"asset_id": "113809960451765367690598229673115216134099141989496655805640157545770316317603", "price": "0.866", "size": "10", "side": "BUY", "hash": "e71f448f7c1ef542f72c1440e1073b878616e064", "best_bid": "0.998", "best_ask": "0.999"}, {"asset_id": "76794312778172154876533172710848055841220591544022724903757628442504975481665", "price": "0.134", "size": "10", "side": "SELL", "hash": "3139f3680ee8835ad8034d25c76291e2d04dce23", "best_bid": "0.001", "best_ask": "0.002"}], "timestamp": "1769384575337", "event_type": "price_change"}}
{"_local_timestamp": "2026-01-25T23:42:55.564823+00:00", "data": {"market": "0x2c405b766a5952a1ee121519845541e3f363bbbb691748d38d596e900827333f", "price_changes": [{"asset_id": "45360012752670095623901322351652227247408888830488142163512756455139535103641", "price": "0.551", "size": "288", "side": "BUY", "hash": "5b72501729d02bafd3e91371568e37ef9ae45e01", "best_bid": "0.996", "best_ask": "1"}, {"asset_id": "44227097530829963499576501282186404645897936156929334280113391423971987257194", "price": "0.449", "size": "288", "side": "SELL", "hash": "b677d439560cd4cbe96ef03b97710533683f4c62", "best_bid": "0", "best_ask": "0.004"}], "timestamp": "1769384575337", "event_type": "price_change"}}
{"_local_timestamp": "2026-01-25T23:42:55.565130+00:00", "data": {"market": "0xd2b7235e5c612ce49ad0252420d713280ded4e346bd24dd50f941e901e9daec2", "price_changes": [{"asset_id": "110558202691925957098835226242947976618291676693360525080400622291263590296356", "price": "0.824", "size": "400", "side": "BUY", "hash": "ba925d86aff86809285c94dc43e77bfdade35358", "best_bid": "0.997", "best_ask": "0.999"}, {"asset_id": "62070332729843756648077334071325768265229024314411995286040519682521027925149", "price": "0.176", "size": "400", "side": "SELL", "hash": "e4c1c8fc09f0a4407d37371aa09216141ad172d4", "best_bid": "0.001", "best_ask": "0.003"}], "timestamp": "1769384575337", "event_type": "price_change"}}
{"_local_timestamp": "2026-01-25T23:42:55.565383+00:00", "data": {"market": "0xe819c3fd02eec251efec7d90a1801554ec14fef336932c7342b333d4ae64d0a8", "price_changes": [{"asset_id": "99877125227544421735443256554390914792518157728590758473713836440156917197132", "price": "0.825", "size": "10", "side": "BUY", "hash": "90e381c61238becc06f8d22fd357d28c2aebd341", "best_bid": "0.945", "best_ask": "0.991"}, {"asset_id": "110183118205658048480611552004818205608380030301879472767196181141473018245608", "price": "0.175", "size": "10", "side": "SELL", "hash": "987435cafd5b6c4a2d715d56bf6533d07be6ffd1", "best_bid": "0.009", "best_ask": "0.055"}], "timestamp": "1769384575338", "event_type": "price_change"}}
{"_local_timestamp": "2026-01-25T23:42:55.565709+00:00", "data": {"market": "0xc5a5599959ff15ca3533656c16dd441304b8721162ef770db59a1d2b4862e2b8", "price_changes": [{"asset_id": "48279448787839069698930026835059287278898209340746904712996610649334841531409", "price": "0.876", "size": "10", "side": "BUY", "hash": "b5f8452043155a7d539ed1005254c37e12747971", "best_bid": "0.996", "best_ask": "1"}, {"asset_id": "73040552226217734695850503696187376710006575449764477997853420807432098137837", "price": "0.124", "size": "10", "side": "SELL", "hash": "7462acc195cbd95ab2a3d15d0d9fddf1a7d79b0e", "best_bid": "0", "best_ask": "0.004"}], "timestamp": "1769384575338", "event_type": "price_change"}}
{"_local_timestamp": "2026-01-25T23:42:55.565989+00:00", "data": {"market": "0x7996c5de13ddf3131cebe81e14fa25bc93e6d83383e9311fb4444d054b02bb6c", "price_changes": [{"asset_id": "81067297669492637828272330271687160515702268762196167960552103884621012706990", "price": "0.631", "size": "10", "side": "BUY", "hash": "155d5c9ed86765b28bd3b39c44534f09afdd9c0e", "best_bid": "0.996", "best_ask": "1"}, {"asset_id": "35385046285095047875859550982501333940016148310175612786655121530268337331434", "price": "0.369", "size": "10", "side": "SELL", "hash": "8a93962e58e6bab71e86bb006f0e4cac732a2cbd", "best_bid": "0", "best_ask": "0.004"}], "timestamp": "1769384575337", "event_type": "price_change"}}
{"_local_timestamp": "2026-01-25T23:42:55.566218+00:00", "data": {"market": "0xc901b7ee5f6776feee0bc75349ddf15b3f1473c42e9c23fbd2c286129db2314b", "price_changes": [{"asset_id": "19480453523641651203279098233362734886683676042431995106519882319527157746915", "price": "0.724", "size": "255", "side": "BUY", "hash": "80bd5399a7dfd306e5737acf52eff6e761527dcb", "best_bid": "0.998", "best_ask": "1"}, {"asset_id": "87076761959524824596667767871338783105013148144014343593959452219056943445676", "price": "0.276", "size": "255", "side": "SELL", "hash": "c8590a2ae6ae5a550a0b43bfc7d1b6ba122a2042", "best_bid": "0", "best_ask": "0.002"}], "timestamp": "1769384575337", "event_type": "price_change"}}
{"_local_timestamp": "2026-01-25T23:42:55.566451+00:00", "data": {"market": "0x936a5e78fd5963c717e49661a593fa3353241f6fb3c69b6615e9041e6b6f0973", "price_changes": [{"asset_id": "62474888561798875936325899031095507932691561832763786042468556558023439824689", "price": "0.56", "size": "312", "side": "BUY", "hash": "be6716e03eec98ce5b1c9625cd58ced00c5816c0", "best_bid": "0.997", "best_ask": "1"}, {"asset_id": "85450186084380419372744179618618425905211867206934194164904272142040477321142", "price": "0.44", "size": "312", "side": "SELL", "hash": "bd3272368c61d1711839fd00e1afecd691247c20", "best_bid": "0", "best_ask": "0.003"}], "timestamp": "1769384575337", "event_type": "price_change"}}
{"_local_timestamp": "2026-01-25T23:42:55.566694+00:00", "data": {"market": "0xad8e9885ec2473d0ba49c38449dfd4d18ad7c0f7a14625a24865857e18a94850", "price_changes": [{"asset_id": "6063771237142095573570898636767550587549260179390402809546741793309719810883", "price": "0.522", "size": "10", "side": "BUY", "hash": "1ebca125992b22867dd7ce1f9e21f3921d30f766", "best_bid": "0.992", "best_ask": "0.996"}, {"asset_id": "40355817413446270517300817460473958731033814018091765438985668051022432561988", "price": "0.478", "size": "10", "side": "SELL", "hash": "4c6afcf5a4421e52651e8e35ef3fbf2319a0f952", "best_bid": "0.004", "best_ask": "0.008"}], "timestamp": "1769384575337", "event_type": "price_change"}}
{"_local_timestamp": "2026-01-25T23:42:55.569926+00:00", "data": {"market": "0xeb60a53b5ca38150c07cc30ef0f5570b292f3e43722512cc55d0cff666ac1077", "price_changes": [{"asset_id": "83308171747089483400662168608358178791256497013703595264448211477259881059204", "price": "0.864", "size": "10", "side": "BUY", "hash": "acec50ac62c77db3d794d35aa0821c8376ec34be", "best_bid": "0.996", "best_ask": "1"}, {"asset_id": "72088688491610101384722384206165707443638739290798571693187856704797119769987", "price": "0.136", "size": "10", "side": "SELL", "hash": "9e413e841aaa45d3e1f4e994ebe221fcc03ccb81", "best_bid": "0", "best_ask": "0.004"}], "timestamp": "1769384575338", "event_type": "price_change"}}
{"_local_timestamp": "2026-01-25T23:42:55.573765+00:00", "data": {"market": "0x82bd65f09e2428042a5ac204f60f34e1b40f7a4a2d008fc0b92afd0aca450607", "price_changes": [{"asset_id": "110679481699383362322327302278895149696397996918330653214772805833135400912448", "price": "0.598", "size": "10", "side": "BUY", "hash": "93fb21e93e0e9e2006ac78e2c0f976035c42d525", "best_bid": "0.998", "best_ask": "0.999"}, {"asset_id": "67038866817302942551959484913198849155750799193273634269443232905877417785248", "price": "0.402", "size": "10", "side": "SELL", "hash": "f65fa5b0f2eeb950fdb79f09faca21f5f960b420", "best_bid": "0.001", "best_ask": "0.002"}], "timestamp": "1769384575338", "event_type": "price_change"}}
{"_local_timestamp": "2026-01-25T23:42:55.574133+00:00", "data": {"market": "0x1dcc183b4cca17ebd95af1b94209ce345233d13a8157c1b1761b6d82722614aa", "price_changes": [{"asset_id": "105584168793006337391660846202014742593893506579636126851936010970644475175057", "price": "0.558", "size": "400", "side": "BUY", "hash": "3b88b9ba2aacc474d7beb9e440b1326e47df303c", "best_bid": "0.996", "best_ask": "1"}, {"asset_id": "34996430135377662182478828889088041580319309767069410756085253475349980098679", "price": "0.442", "size": "400", "side": "SELL", "hash": "439518144ff8c7ac101c6f864d18928550a91054", "best_bid": "0", "best_ask": "0.004"}], "timestamp": "1769384575338", "event_type": "price_change"}}
{"_local_timestamp": "2026-01-25T23:42:55.574674+00:00", "data": {"market": "0x5bc6ce968259b72cf129f3420b74591165b2daed5681c945a550d3479a6cd29f", "price_changes": [{"asset_id": "13658847648110704810290854236711050722034916311708159351742514374794523650635", "price": "0.724", "size": "307", "side": "BUY", "hash": "4614dbbcdd95f68a772b2c6eb95e273bb87c8553", "best_bid": "0.996", "best_ask": "0.999"}, {"asset_id": "75885549806041705440616483171403974382986377202053531674757984617564016983448", "price": "0.276", "size": "307", "side": "SELL", "hash": "69b66f2c0c1515bcd7c96a674cc98d76c96a321f", "best_bid": "0.001", "best_ask": "0.004"}], "timestamp": "1769384575337", "event_type": "price_change"}}
{"_local_timestamp": "2026-01-25T23:42:55.576578+00:00", "data": {"market": "0x584caca7a7536029bef854652fa5fdd861631edbc01a217069341b85030edd6f", "price_changes": [{"asset_id": "8840594256975309703691759780728141785112443011041236897959089339991605786144", "price": "0.723", "size": "10", "side": "BUY", "hash": "f89d464fe359b8e749a7d05fde2a75558fdf7555", "best_bid": "0.996", "best_ask": "1"}, {"asset_id": "69196677690927265002451334694240538592951011957285689708757350071125284654035", "price": "0.277", "size": "10", "side": "SELL", "hash": "4a4a8dad001de88adb7b52f2a95bbf79d4788266", "best_bid": "0", "best_ask": "0.004"}], "timestamp": "1769384575338", "event_type": "price_change"}}
{"_local_timestamp": "2026-01-25T23:42:55.579264+00:00", "data": {"market": "0x208c0100d3c9b2e1cfe6acd453a461a2db052ea6de69345e20ba97bd80b24a32", "price_changes": [{"asset_id": "50847646174397103153022714653544400551806761556088789644031638820781566442427", "price": "0.824", "size": "400", "side": "BUY", "hash": "6f67a532708bcc029917e311eaa267e1aa286c36", "best_bid": "0.998", "best_ask": "1"}, {"asset_id": "25190149186348626497584661665153964321010101728496495635131758054890103740875", "price": "0.176", "size": "400", "side": "SELL", "hash": "e79f0fa3248285dddd30bf472cb3ddc30dbbdce6", "best_bid": "0", "best_ask": "0.002"}], "timestamp": "1769384575338", "event_type": "price_change"}}
{"_local_timestamp": "2026-01-25T23:42:55.579534+00:00", "data": {"market": "0xaefc28d462f0824bbb9c694d3511beaaf8b21af8eba30d8e524ed05d0431e712", "price_changes": [{"asset_id": "44763420328579357949062599081517223538923284512329276353056439811950932880097", "price": "0.878", "size": "10", "side": "BUY", "hash": "f2b351f1b11b145cb2b44aa5e554c2b8726a287e", "best_bid": "0.998", "best_ask": "0.999"}, {"asset_id": "74056431860682289842871849619463099581884627064723191566088662788504744554943", "price": "0.122", "size": "10", "side": "SELL", "hash": "fe02403177d2174cb5400364ce4ee97081767641", "best_bid": "0.001", "best_ask": "0.002"}], "timestamp": "1769384575338", "event_type": "price_change"}}
{"_local_timestamp": "2026-01-25T23:42:55.579778+00:00", "data": {"market": "0x34629a8e04da66f61bad2b4de18d370ca551faf79f810e04e403b841163f0e47", "price_changes": [{"asset_id": "81962021060291538332769225938832888553429136330721495433176438182361641360146", "price": "0.591", "size": "10", "side": "BUY", "hash": "3e179fd7e7c9a5c0289daba324b006446fdf02c0", "best_bid": "0.975", "best_ask": "0.987"}, {"asset_id": "24428969314967049374579832885004941749071678905985050510703983608884666132158", "price": "0.409", "size": "10", "side": "SELL", "hash": "f26820e9780a2b81d7ecd757157b45273430d1f5", "best_bid": "0.013", "best_ask": "0.025"}], "timestamp": "1769384575338", "event_type": "price_change"}}
{"_local_timestamp": "2026-01-25T23:42:55.580146+00:00", "data": {"market": "0xff54852cf4cb9c3568f795b983bc494d2e13d3f9cad41ba872a4ffd3ccb2101e", "price_changes": [{"asset_id": "96140164996170695869329923820202447276846115725253325303263315936085179713314", "price": "0.824", "size": "400", "side": "BUY", "hash": "3581068260366752bc74302a09e3d13795b45441", "best_bid": "0.996", "best_ask": "1"}, {"asset_id": "91203260296949109747095851381415926782789749145484395871735811789947699971761", "price": "0.176", "size": "400", "side": "SELL", "hash": "8f1eea179f6fdd809b4cc51d32edbfeccdfc9f22", "best_bid": "0", "best_ask": "0.004"}], "timestamp": "1769384575338", "event_type": "price_change"}}
{"_local_timestamp": "2026-01-25T23:42:55.580445+00:00", "data": {"market": "0x5882bfbb3333c4425fe5f17d7177d0155935ab218532e30abb3ebc29e09b0d15", "price_changes": [{"asset_id": "37022134553940218760484349283577041579348129770638687563562605588225179219348", "price": "0.829", "size": "10", "side": "BUY", "hash": "0f917133d8bae72d5406d98569b55e3c344775d3", "best_bid": "0.998", "best_ask": "0.999"}, {"asset_id": "98286904268100078035776152708720247190143751657794196422985487083520781931503", "price": "0.171", "size": "10", "side": "SELL", "hash": "ed7898503a03a5914ba63b7d90b311ceedd55fea", "best_bid": "0.001", "best_ask": "0.002"}], "timestamp": "1769384575338", "event_type": "price_change"}}
{"_local_timestamp": "2026-01-25T23:42:55.580689+00:00", "data": {"market": "0x00787f50b9466db23a1899abc108b5609a77cbaa159c1b35822f45e9c14a940b", "price_changes": [{"asset_id": "113809960451765367690598229673115216134099141989496655805640157545770316317603", "price": "0.724", "size": "274", "side": "BUY", "hash": "4bb20f97821b6ee3613a000bf83dc5d4081340ff", "best_bid": "0.998", "best_ask": "0.999"}, {"asset_id": "76794312778172154876533172710848055841220591544022724903757628442504975481665", "price": "0.276", "size": "274", "side": "SELL", "hash": "39adf35a1b59749c3b521c82a934a9e641b3c61a", "best_bid": "0.001", "best_ask": "0.002"}], "timestamp": "1769384575338", "event_type": "price_change"}}
{"_local_timestamp": "2026-01-25T23:42:55.580909+00:00", "data": {"market": "0x813140d27e876be7b8b57a9f5932f560426e5dd02370e1a6d815ce416d3c1a1e", "price_changes": [{"asset_id": "42867658785582566258165916378080823643991642521460286045794854230410783654072", "price": "0.529", "size": "400", "side": "BUY", "hash": "a93999fe0ffb896b74c37f4ef2b8c1e9a4388633", "best_bid": "0.996", "best_ask": "1"}, {"asset_id": "39110700308891033765082720771423327970968989496145639822830381828556135408196", "price": "0.471", "size": "400", "side": "SELL", "hash": "ebf834e523175c69fc1c51e565436a3124f162c8", "best_bid": "0", "best_ask": "0.004"}], "timestamp": "1769384575338", "event_type": "price_change"}}
{"_local_timestamp": "2026-01-25T23:42:55.581144+00:00", "data": {"market": "0x4fc188ab7b8337089312087777af8a703757466dda919e1de85e148394c40090", "price_changes": [{"asset_id": "67034694271202563859644094265338465614375382145815138322023215311029487392827", "price": "0.824", "size": "10", "side": "BUY", "hash": "153165d74a0ee9a203b6d3f57c7d2cae4c33cf4a", "best_bid": "0.996", "best_ask": "1"}, {"asset_id": "22440526641822362681904932185789972209232343897283048384344291619576375972156", "price": "0.176", "size": "10", "side": "SELL", "hash": "cdf452135f48fb5c5860145ca6f093c42165c924", "best_bid": "0", "best_ask": "0.004"}], "timestamp": "1769384575338", "event_type": "price_change"}}
{"_local_timestamp": "2026-01-25T23:42:55.581399+00:00", "data": {"market": "0xbba1c02a186676782fae38b63af5333da443c8a16d86274ba1b045324ec989c7", "price_changes": [{"asset_id": "58144744252589479691808124143280036251902716811429258360320338495684055413095", "price": "0.828", "size": "10", "side": "BUY", "hash": "455c917ff4229c444ca090461483e51053f587c9", "best_bid": "0.996", "best_ask": "1"}, {"asset_id": "60301519933335336364820582307817349741317665540686207245282394805552819791374", "price": "0.172", "size": "10", "side": "SELL", "hash": "9d392a71381fab27a80c8d17bfcd0ec000eff650", "best_bid": "0", "best_ask": "0.004"}], "timestamp": "1769384575338", "event_type": "price_change"}}
{"_local_timestamp": "2026-01-25T23:42:55.581676+00:00", "data": {"market": "0x2c405b766a5952a1ee121519845541e3f363bbbb691748d38d596e900827333f", "price_changes": [{"asset_id": "45360012752670095623901322351652227247408888830488142163512756455139535103641", "price": "0.865", "size": "10", "side": "BUY", "hash": "4f4000673b631917a79ca6effd36c20b1dfe339b", "best_bid": "0.996", "best_ask": "1"}, {"asset_id": "44227097530829963499576501282186404645897936156929334280113391423971987257194", "price": "0.135", "size": "10", "side": "SELL", "hash": "ea7de4745671e729820b82ddb96aeee5b99005b3", "best_bid": "0", "best_ask": "0.004"}], "timestamp": "1769384575339", "event_type": "price_change"}}
