{"_local_timestamp": "2026-01-25T23:33:18.530874+00:00", "data": [{"market": "0x8bc0ed1be727a8ac247c3bd0c3efe591d625f6d6e49a3f6f61f7a16b877b2c69", "asset_id": "84326448097179247101937713292514611799456032279460947956336895753237154020198", "timestamp": "1769383330546", "hash": "77358aad708dba28edff0d61458a4f2f0ea39476", "bids": [{"price": "0.001", "size": "2103754.22"}, {"price": "0.002", "size": "60250"}, {"price": "0.003", "size": "172.72"}, {"price": "0.006", "size": "83"}, {"price": "0.007", "size": "9.63"}, {"price": "0.01", "size": "10"}, {"price": "0.02", "size": "922"}, {"price": "0.021", "size": "11.48"}, {"price": "0.05", "size": "30"}, {"price": "0.051", "size": "39"}, {"price": "0.061", "size": "100"}, {"price": "0.062", "size": "600"}, {"price": "0.08", "size": "300"}, {"price": "0.086", "size": "23"}, {"price": "0.087", "size": "7.59"}, {"price": "0.112", "size": "11"}, {"price": "0.503", "size": "200"}, {"price": "0.735", "size": "30"}, {"price": "0.736", "size": "15.55"}], "asks": [{"price": "0.999", "size": "1295.01"}, {"price": "0.998", "size": "469.78"}, {"price": "0.997", "size": "26.17"}, {"price": "0.996", "size": "179.5"}, {"price": "0.995", "size": "53.28"}, {"price": "0.994", "size": "9.47"}, {"price": "0.99", "size": "10"}], "event_type": "book", "last_trade_price": ""}, {"market": "0x5f8db7b536d9a1b47ae5098f9a3b9bc28ed87ad11ccdd70b8cab89d6fc702a98", "asset_id": "76804568100653929306239353743991896140934618197277967262912463304017766583671", "timestamp": "1769383781579", "hash": "ebe6681bcbf18745a96336b8c9c819522fe37986", "bids": [{"price": "0.001", "size": "842"}, {"price": "0.002", "size": "1512.4"}, {"price": "0.003", "size": "212.6"}, {"price": "0.004", "size": "50"}, {"price": "0.005", "size": "41.92"}, {"price": "0.01", "size": "10"}, {"price": "0.011", "size": "9.52"}, {"price": "0.021", "size": "1036.75"}, {"price": "0.022", "size": "200"}], "asks": [{"price": "0.999", "size": "3102801.08"}, {"price": "0.998", "size": "90255.25"}, {"price": "0.997", "size": "400"}, {"price": "0.996", "size": "6.44"}, {"price": "0.994", "size": "200"}, {"price": "0.99", "size": "10"}, {"price": "0.989", "size": "5.95"}, {"price": "0.98", "size": "222"}, {"price": "0.977", "size": "30700"}, {"price": "0.972", "size": "342.85"}, {"price": "0.971", "size": "9.4"}, {"price": "0.95", "size": "30"}, {"price": "0.949", "size": "15539"}, {"price": "0.948", "size": "184.61"}, {"price": "0.904", "size": "30300"}, {"price": "0.901", "size": "96.96"}, {"price": "0.9", "size": "6.2"}, {"price": "0.875", "size": "38"}, {"price": "0.874", "size": "76.19"}, {"price": "0.805", "size": "49.23"}, {"price": "0.804", "size": "10"}, {"price": "0.105", "size": "49.7"}, {"price": "0.069", "size": "421.35"}, {"price": "0.068", "size": "90.2"}, {"price": "0.051", "size": "10"}, {"price": "0.047", "size": "24.59"}, {"price": "0.046", "size": "8.25"}], "event_type": "book", "last_trade_price": ""}, {"market": "0xec3536934fc4072b6ec4f95541002b893a7e64193d89058a50b1300733d0577a", "asset_id": "32197429166700111536823754287092684333922425922201658989691857565621864128151", "timestamp": "1769383954706", "hash": "e67ae3fd0894d82dc421cc97b9716e6094ecb55d", "bids": [{"price": "0.001", "size": "3952.91"}, {"price": "0.002", "size": "272.4"}, {"price": "0.003", "size": "6135.36"}, {"price": "0.004", "size": "1511.01"}, {"price": "0.005", "size": "248.82"}, {"price": "0.006", "size": "14.6"}, {"price": "0.007", "size": "65"}, {"price": "0.008", "size": "16.22"}, {"price": "0.009", "size": "9.86"}], "asks": [{"price": "0.999", "size": "11002811.22"}, {"price": "0.998", "size": "90255.18"}, {"price": "0.997", "size": "400"}, {"price": "0.996", "size": "8.87"}, {"price": "0.994", "size": "200"}, {"price": "0.99", "size": "10"}, {"price": "0.989", "size": "6.12"}, {"price": "0.98", "size": "222"}, {"price": "0.979", "size": "9000"}, {"price": "0.976", "size": "30000"}, {"price": "0.975", "size": "12.25"}, {"price": "0.95", "size": "30"}, {"price": "0.949", "size": "39"}, {"price": "0.902", "size": "30000"}, {"price": "0.901", "size": "200"}, {"price": "0.9", "size": "5.75"}, {"price": "0.856", "size": "22"}, {"price": "0.855", "size": "13"}, {"price": "0.669", "size": "30"}, {"price": "0.372", "size": "30"}, {"price": "0.371", "size": "17.79"}, {"price": "0.368", "size": "45"}, {"price": "0.367", "size": "67.5"}, {"price": "0.321", "size": "9"}, {"price": "0.32", "size": "13.5"}], "event_type": "book", "last_trade_price": "0.010"}, {"market": "0xef5e9557d5ceb0037568a06c19e7dc3cd05099f21108966799bb82001ed527d6", "asset_id": "107494352894216874714025271596376064949661170816050082558288626361173180501864", "timestamp": "1769382157802", "hash": "d8654f4d785191f0f7ebba160c0610bb0be23780", "bids": [{"price": "0.001", "size": "3218.83"}, {"price": "0.002", "size": "250"}, {"price": "0.003", "size": "30.95"}, {"price": "0.01", "size": "510010"}, {"price": "0.02", "size": "20222"}, {"price": "0.021", "size": "12.16"}, {"price": "0.05", "size": "9030"}, {"price": "0.051", "size": "39"}, {"price": "0.08", "size": "9000"}, {"price": "0.081", "size": "7.91"}, {"price": "0.17", "size": "9000"}, {"price": "0.175", "size": "5"}, {"price": "0.176", "size": "11"}, {"price": "0.514", "size": "40"}, {"price": "0.515", "size": "20.51"}], "asks": [{"price": "0.999", "size": "1871.9"}, {"price": "0.998", "size": "478.09"}, {"price": "0.997", "size": "165.43"}, {"price": "0.996", "size": "109.32"}, {"price": "0.995", "size": "17.35"}, {"price": "0.99", "size": "10"}], "event_type": "book", "last_trade_price": ""}, {"market": "0x03767ed0565cf993fe04a5d0b37a101844642ca0a95a26620a100ca7160d3a7b", "asset_id": "85746269850435124037229934317961848660786967803478826022478813728405917226418", "timestamp": "1769383868706", "hash": "ea2ddaf364ab168ef4ca6e7aa44ded2af2d26dcb", "bids": [{"price": "0.001", "size": "2804.2"}, {"price": "0.002", "size": "250"}, {"price": "0.003", "size": "172.7"}, {"price": "0.006", "size": "83"}, {"price": "0.007", "size": "9.61"}, {"price": "0.01", "size": "1100010"}, {"price": "0.02", "size": "50922"}, {"price": "0.021", "size": "16.01"}, {"price": "0.05", "size": "30830"}, {"price": "0.051", "size": "39"}, {"price": "0.08", "size": "9200"}, {"price": "0.11", "size": "300"}, {"price": "0.111", "size": "5.09"}, {"price": "0.112", "size": "17"}, {"price": "0.113", "size": "8"}, {"price": "0.71", "size": "3000"}, {"price": "0.736", "size": "1000"}, {"price": "0.74", "size": "30"}, {"price": "0.741", "size": "47.02"}], "asks": [{"price": "0.999", "size": "1502.29"}, {"price": "0.998", "size": "484.94"}, {"price": "0.997", "size": "71.66"}, {"price": "0.995", "size": "46"}, {"price": "0.994", "size": "23.51"}, {"price": "0.993", "size": "148"}, {"price": "0.992", "size": "17.17"}], "event_type": "book", "last_trade_price": "0.005"}, {"market": "0x03767ed0565cf993fe04a5d0b37a101844642ca0a95a26620a100ca7160d3a7b", "asset_id": "20351164523648388486225016801383037531346669964531593624064136876724669998839", "timestamp": "1769383868706", "hash": "2b124b153b46bbcaad549547856ff44eaaedd124", "bids": [{"price": "0.001", "size": "1502.29"}, {"price": "0.002", "size": "484.94"}, {"price": "0.003", "size": "71.66"}, {"price": "0.005", "size": "46"}, {"price": "0.006", "size": "23.51"}, {"price": "0.007", "size": "148"}, {"price": "0.008", "size": "17.17"}], "asks": [{"price": "0.999", "size": "2804.2"}, {"price": "0.998", "size": "250"}, {"price": "0.997", "size": "172.7"}, {"price": "0.994", "size": "83"}, {"price": "0.993", "size": "9.61"}, {"price": "0.99", "size": "1100010"}, {"price": "0.98", "size": "50922"}, {"price": "0.979", "size": "16.01"}, {"price": "0.95", "size": "30830"}, {"price": "0.949", "size": "39"}, {"price": "0.92", "size": "9200"}, {"price": "0.89", "size": "300"}, {"price": "0.889", "size": "5.09"}, {"price": "0.888", "size": "17"}, {"price": "0.887", "size": "8"}, {"price": "0.29", "size": "3000"}, {"price": "0.264", "size": "1000"}, {"price": "0.26", "size": "30"}, {"price": "0.259", "size": "47.02"}], "event_type": "book", "last_trade_price": "0.005"}, {"market": "0x58b372443f0e36b9aa1d4cf0ac87afd2b35022d651d5c8483412c5d01c4213f3", "asset_id": "74863665767233302025566335346311422095508537077979116418767018100094979113099", "timestamp": "1769383997872", "hash": "ff6e912271e5a2b3f0e0b33cab4f207fdc8752c9", "bids": [{"price": "0.01", "size": "32.44"}, {"price": "0.03", "size": "9.4"}, {"price": "0.04", "size": "60.45"}], "asks": [{"price": "0.99", "size": "19.71"}, {"price": "0.98", "size": "922"}, {"price": "0.97", "size": "10.14"}, {"price": "0.95", "size": "30"}, {"price": "0.94", "size": "633"}, {"price": "0.93", "size": "100"}, {"price": "0.92", "size": "300"}, {"price": "0.91", "size": "6.65"}, {"price": "0.87", "size": "8"}, {"price": "0.86", "size": "14"}, {"price": "0.56", "size": "5"}, {"price": "0.21", "size": "130.59"}, {"price": "0.18", "size": "100"}, {"price": "0.17", "size": "5"}], "event_type": "book", "last_trade_price": ""}, {"market": "0x0bf8c8a49d597193dcc1d3921b68bcf357dcf14f61eebb314b2ca26df92c6b70", "asset_id": "112686561748271690852517534925258634835514924647537374255796839555111757158365", "timestamp": "1769383909045", "hash": "40abb0dff87bc7434bc3e50959fb81db5f9da8c6", "bids": [{"price": "0.001", "size": "3936.3"}, {"price": "0.002", "size": "221.23"}, {"price": "0.003", "size": "118"}, {"price": "0.004", "size": "156.03"}], "asks": [{"price": "0.999", "size": "11002801.07"}, {"price": "0.998", "size": "60255.09"}, {"price": "0.997", "size": "400"}, {"price": "0.996", "size": "8.35"}, {"price": "0.994", "size": "200"}, {"price": "0.99", "size": "10"}, {"price": "0.989", "size": "6.6"}, {"price": "0.98", "size": "222"}, {"price": "0.976", "size": "30000"}, {"price": "0.969", "size": "387.09"}, {"price": "0.968", "size": "8.49"}, {"price": "0.95", "size": "30"}, {"price": "0.949", "size": "274.29"}, {"price": "0.904", "size": "40000"}, {"price": "0.903", "size": "200"}, {"price": "0.897", "size": "116.5"}, {"price": "0.896", "size": "36.02"}, {"price": "0.707", "size": "39"}, {"price": "0.706", "size": "58.08"}, {"price": "0.705", "size": "46.67"}, {"price": "0.704", "size": "69.52"}, {"price": "0.05", "size": "5"}, {"price": "0.049", "size": "7.58"}, {"price": "0.011", "size": "25"}, {"price": "0.01", "size": "38.56"}], "event_type": "book", "last_trade_price": "0.003"}, {"market": "0x7dbd765a0b822e15d82cfcb1d3f2527a61b7b310aa43c083519bdadae9a7d76a", "asset_id": "73898315214123584625223228086553295011358744364264444419454498893385825038943", "timestamp": "1769383905009", "hash": "bf313552f70b2497607ee83af9bfdb298dcd3667", "bids": [{"price": "0.001", "size": "3755.13"}, {"price": "0.002", "size": "450"}, {"price": "0.003", "size": "172.66"}, {"price": "0.006", "size": "83"}, {"price": "0.007", "size": "10.21"}, {"price": "0.01", "size": "10"}, {"price": "0.02", "size": "222"}, {"price": "0.021", "size": "111"}, {"price": "0.022", "size": "7.73"}, {"price": "0.05", "size": "30"}, {"price": "0.051", "size": "39"}, {"price": "0.06", "size": "33"}, {"price": "0.061", "size": "19.09"}, {"price": "0.8", "size": "10"}, {"price": "0.801", "size": "15"}], "asks": [{"price": "0.999", "size": "1787.9"}, {"price": "0.998", "size": "468.64"}, {"price": "0.997", "size": "178.36"}, {"price": "0.996", "size": "36.64"}, {"price": "0.994", "size": "99.6"}, {"price": "0.993", "size": "65.92"}, {"price": "0.992", "size": "17.96"}, {"price": "0.99", "size": "72"}], "event_type": "book", "last_trade_price": ""}, {"market": "0x0ba39007f4ff1c2677f296b90188d544c2f80f9729c76a6f181a191543ceab82", "asset_id": "35783470881309485643248466709434569842971080886588261160663378071872348072260", "timestamp": "1769383971070", "hash": "11c92b937cdb1ca3b55fd45385dc80a2ee31aadc", "bids": [{"price": "0.001", "size": "10702873.4"}, {"price": "0.002", "size": "255.1"}, {"price": "0.003", "size": "400"}, {"price": "0.004", "size": "8.73"}, {"price": "0.006", "size": "200"}, {"price": "0.01", "size": "10"}, {"price": "0.011", "size": "6.43"}, {"price": "0.025", "size": "10000"}, {"price": "0.026", "size": "5.6"}, {"price": "0.05", "size": "30"}, {"price": "0.051", "size": "39"}, {"price": "0.06", "size": "700"}, {"price": "0.061", "size": "12.01"}, {"price": "0.116", "size": "20000"}, {"price": "0.142", "size": "11115.49"}, {"price": "0.143", "size": "350"}, {"price": "0.2", "size": "5"}, {"price": "0.5", "size": "100"}, {"price": "0.63", "size": "1500"}, {"price": "0.805", "size": "1687.5"}, {"price": "0.807", "size": "9"}, {"price": "0.808", "size": "45"}, {"price": "0.809", "size": "22.75"}], "asks": [{"price": "0.999", "size": "4665.09"}, {"price": "0.998", "size": "3237.93"}, {"price": "0.997", "size": "110.98"}, {"price": "0.996", "size": "155"}, {"price": "0.995", "size": "72.73"}], "event_type": "book", "last_trade_price": "0.024"}, {"market": "0xec3536934fc4072b6ec4f95541002b893a7e64193d89058a50b1300733d0577a", "asset_id": "96671476518786383904585530156908444908957428537143909392577226929673922053938", "timestamp": "1769383954706", "hash": "db19f3408d0f4dbcbeadb47fac32d0b9e51d3531", "bids": [{"price": "0.001", "size": "11002811.22"}, {"price": "0.002", "size": "90255.18"}, {"price": "0.003", "size": "400"}, {"price": "0.004", "size": "8.87"}, {"price": "0.006", "size": "200"}, {"price": "0.01", "size": "10"}, {"price": "0.011", "size": "6.12"}, {"price": "0.02", "size": "222"}, {"price": "0.021", "size": "9000"}, {"price": "0.024", "size": "30000"}, {"price": "0.025", "size": "12.25"}, {"price": "0.05", "size": "30"}, {"price": "0.051", "size": "39"}, {"price": "0.098", "size": "30000"}, {"price": "0.099", "size": "200"}, {"price": "0.1", "size": "5.75"}, {"price": "0.144", "size": "22"}, {"price": "0.145", "size": "13"}, {"price": "0.331", "size": "30"}, {"price": "0.628", "size": "30"}, {"price": "0.629", "size": "17.79"}, {"price": "0.632", "size": "45"}, {"price": "0.633", "size": "67.5"}, {"price": "0.679", "size": "9"}, {"price": "0.68", "size": "13.5"}], "asks": [{"price": "0.999", "size": "3952.91"}, {"price": "0.998", "size": "272.4"}, {"price": "0.997", "size": "6135.36"}, {"price": "0.996", "size": "1511.01"}, {"price": "0.995", "size": "248.82"}, {"price": "0.994", "size": "14.6"}, {"price": "0.993", "size": "65"}, {"price": "0.992", "size": "16.22"}, {"price": "0.991", "size": "9.86"}], "event_type": "book", "last_trade_price": "0.010"}, {"market": "0xf20f7af3ea74b16d623af198d6efb27d9d4ee98cfa96b1b6c8d4021d55436eb0", "asset_id": "79006550760303579457645886672312299229061887535391288753983510221472432105358", "timestamp": "1769383991368", "hash": "e35968343894c9adef86202c82a0e590aa321364", "bids": [{"price": "0.01", "size": "19.69"}, {"price": "0.02", "size": "222"}, {"price": "0.03", "size": "117.79"}, {"price": "0.05", "size": "30"}, {"price": "0.06", "size": "33"}, {"price": "0.07", "size": "28"}, {"price": "0.08", "size": "8.73"}, {"price": "0.36", "size": "5"}, {"price": "0.87", "size": "20"}], "asks": [{"price": "0.99", "size": "65.34"}, {"price": "0.98", "size": "261.99"}, {"price": "0.97", "size": "21.5"}], "event_type": "book", "last_trade_price": ""}, {"market": "0x1940b49a58dbb1673e34e8d556dc86b882f8832a481707c67aba02603c32f4a6", "asset_id": "71369121321846330172912145857111778588565834210510367431821698951607223210980", "timestamp": "1769383809972", "hash": "a1925b400bd88c284eda5487ab5946581ecf92c6", "bids": [{"price": "0.001", "size": "935.97"}, {"price": "0.002", "size": "96.86"}, {"price": "0.003", "size": "81.05"}, {"price": "0.005", "size": "86"}, {"price": "0.006", "size": "73.68"}, {"price": "0.01", "size": "10"}, {"price": "0.011", "size": "9.37"}, {"price": "0.02", "size": "948.69"}, {"price": "0.021", "size": "200"}], "asks": [{"price": "0.999", "size": "2801.09"}, {"price": "0.998", "size": "257.56"}, {"price": "0.997", "size": "400"}, {"price": "0.996", "size": "200"}, {"price": "0.995", "size": "6.88"}, {"price": "0.994", "size": "200"}, {"price": "0.99", "size": "343"}, {"price": "0.989", "size": "35.19"}, {"price": "0.988", "size": "25.16"}, {"price": "0.95", "size": "30"}, {"price": "0.949", "size": "39"}, {"price": "0.915", "size": "11"}, {"price": "0.899", "size": "19"}, {"price": "0.898", "size": "6.3"}, {"price": "0.897", "size": "45"}, {"price": "0.362", "size": "98.5"}, {"price": "0.22", "size": "7"}, {"price": "0.209", "size": "20"}, {"price": "0.182", "size": "25"}], "event_type": "book", "last_trade_price": ""}, {"market": "0x1940b49a58dbb1673e34e8d556dc86b882f8832a481707c67aba02603c32f4a6", "asset_id": "93793793289036935341608877259503853616462731627899477931478718740686048087884", "timestamp": "1769383809972", "hash": "642da09d7a541ed0c3ac1224a38def7609135275", "bids": [{"price": "0.001", "size": "2801.09"}, {"price": "0.002", "size": "257.56"}, {"price": "0.003", "size": "400"}, {"price": "0.004", "size": "200"}, {"price": "0.005", "size": "6.88"}, {"price": "0.006", "size": "200"}, {"price": "0.01", "size": "343"}, {"price": "0.011", "size": "35.19"}, {"price": "0.012", "size": "25.16"}, {"price": "0.05", "size": "30"}, {"price": "0.051", "size": "39"}, {"price": "0.085", "size": "11"}, {"price": "0.101", "size": "19"}, {"price": "0.102", "size": "6.3"}, {"price": "0.103", "size": "45"}, {"price": "0.638", "size": "98.5"}, {"price": "0.78", "size": "7"}, {"price": "0.791", "size": "20"}, {"price": "0.818", "size": "25"}], "asks": [{"price": "0.999", "size": "935.97"}, {"price": "0.998", "size": "96.86"}, {"price": "0.997", "size": "81.05"}, {"price": "0.995", "size": "86"}, {"price": "0.994", "size": "73.68"}, {"price": "0.99", "size": "10"}, {"price": "0.989", "size": "9.37"}, {"price": "0.98", "size": "948.69"}, {"price": "0.979", "size": "200"}], "event_type": "book", "last_trade_price": ""}, {"market": "0xb416bf4fbda79d068632d0e5447432d989b3cbf67c94d109159cb577186a2967", "asset_id": "65231351761669550894073981540936017892501058975994169290932193425794398487063", "timestamp": "1769383997382", "hash": "dc5abbcc6400537d8242c3ef4a7674f9284fad21", "bids": [{"price": "0.001", "size": "5917.76"}, {"price": "0.002", "size": "287.79"}, {"price": "0.003", "size": "425.06"}, {"price": "0.004", "size": "218.86"}, {"price": "0.005", "size": "30.65"}, {"price": "0.006", "size": "200"}, {"price": "0.007", "size": "81.61"}, {"price": "0.008", "size": "107.78"}, {"price": "0.009", "size": "21.24"}, {"price": "0.01", "size": "10"}, {"price": "0.011", "size": "8.56"}], "asks": [{"price": "0.999", "size": "6102805.71"}, {"price": "0.998", "size": "90250"}, {"price": "0.997", "size": "407"}, {"price": "0.994", "size": "200"}, {"price": "0.993", "size": "10.72"}, {"price": "0.99", "size": "10"}, {"price": "0.98", "size": "222"}, {"price": "0.979", "size": "1600"}, {"price": "0.978", "size": "6.44"}, {"price": "0.95", "size": "530"}, {"price": "0.949", "size": "39"}, {"price": "0.92", "size": "300"}, {"price": "0.919", "size": "9.27"}, {"price": "0.818", "size": "900"}, {"price": "0.809", "size": "1000"}, {"price": "0.805", "size": "5"}, {"price": "0.804", "size": "10"}, {"price": "0.419", "size": "50"}, {"price": "0.418", "size": "13.67"}], "event_type": "book", "last_trade_price": "0.989"}, {"market": "0xfa4c453091f10ccab9fae67d8a2286e1bf1d9367596d1d5b74c36e4155e300af", "asset_id": "100280536155707901843387784334630754939243388352572806762203828618520844114191", "timestamp": "1769383954880", "hash": "570370310b387e369a49c144f55fa413222a7794", "bids": [{"price": "0.001", "size": "4308.6"}, {"price": "0.002", "size": "250"}, {"price": "0.003", "size": "406.62"}, {"price": "0.006", "size": "200"}, {"price": "0.007", "size": "9.85"}, {"price": "0.01", "size": "10"}, {"price": "0.02", "size": "222"}, {"price": "0.021", "size": "9.66"}, {"price": "0.022", "size": "1363.63"}, {"price": "0.05", "size": "30"}, {"price": "0.051", "size": "39"}, {"price": "0.071", "size": "9.79"}, {"price": "0.072", "size": "411.11"}, {"price": "0.214", "size": "1000"}, {"price": "0.215", "size": "37.2"}, {"price": "0.234", "size": "1000"}, {"price": "0.249", "size": "100"}, {"price": "0.25", "size": "90"}, {"price": "0.286", "size": "27.97"}, {"price": "0.287", "size": "10.93"}, {"price": "0.292", "size": "6"}, {"price": "0.293", "size": "7.63"}, {"price": "0.294", "size": "27.21"}, {"price": "0.295", "size": "42.43"}, {"price": "0.296", "size": "13.02"}, {"price": "0.994", "size": "14"}], "asks": [{"price": "0.999", "size": "4822"}, {"price": "0.998", "size": "570.98"}, {"price": "0.997", "size": "102.14"}, {"price": "0.995", "size": "183.79"}], "event_type": "book", "last_trade_price": ""}, {"market": "0xccb49e0802c9ada89016c5f6f9933847455b736228812d0707a88e014804a630", "asset_id": "79795882971791559735842491100915770382923497517929862466123107473219678670981", "timestamp": "1769383927329", "hash": "b23c41e4b924836bf76e1f8ad1b4fa0205226565", "bids": [{"price": "0.01", "size": "225.96"}, {"price": "0.02", "size": "222"}, {"price": "0.03", "size": "5.58"}, {"price": "0.04", "size": "58"}, {"price": "0.05", "size": "30"}, {"price": "0.06", "size": "33"}, {"price": "0.09", "size": "22"}, {"price": "0.1", "size": "7.35"}, {"price": "0.5", "size": "40"}, {"price": "0.8", "size": "26.78"}], "asks": [{"price": "0.99", "size": "16.46"}, {"price": "0.98", "size": "86.54"}, {"price": "0.97", "size": "26.29"}, {"price": "0.92", "size": "100"}], "event_type": "book", "last_trade_price": "0.200"}, {"market": "0x8bc0ed1be727a8ac247c3bd0c3efe591d625f6d6e49a3f6f61f7a16b877b2c69", "asset_id": "82254215362749379128390200376683369058155996576903428786392882903954896846600", "timestamp": "1769383330546", "hash": "47eba3585432df4dde978a3006849b4975b15fc8", "bids": [{"price": "0.001", "size": "1295.01"}, {"price": "0.002", "size": "469.78"}, {"price": "0.003", "size": "26.17"}, {"price": "0.004", "size": "179.5"}, {"price": "0.005", "size": "53.28"}, {"price": "0.006", "size": "9.47"}, {"price": "0.01", "size": "10"}], "asks": [{"price": "0.999", "size": "2103754.22"}, {"price": "0.998", "size": "60250"}, {"price": "0.997", "size": "172.72"}, {"price": "0.994", "size": "83"}, {"price": "0.993", "size": "9.63"}, {"price": "0.99", "size": "10"}, {"price": "0.98", "size": "922"}, {"price": "0.979", "size": "11.48"}, {"price": "0.95", "size": "30"}, {"price": "0.949", "size": "39"}, {"price": "0.939", "size": "100"}, {"price": "0.938", "size": "600"}, {"price": "0.92", "size": "300"}, {"price": "0.914", "size": "23"}, {"price": "0.913", "size": "7.59"}, {"price": "0.888", "size": "11"}, {"price": "0.497", "size": "200"}, {"price": "0.265", "size": "30"}, {"price": "0.264", "size": "15.55"}], "event_type": "book", "last_trade_price": ""}, {"market": "0xef5e9557d5ceb0037568a06c19e7dc3cd05099f21108966799bb82001ed527d6", "asset_id": "29392307037326431822588516624706695950769643263841897557379080611079925799661", "timestamp": "1769382157802", "hash": "8e934f9bd0f0b07cef20e0e02464a6b734f2bcfc", "bids": [{"price": "0.001", "size": "1871.9"}, {"price": "0.002", "size": "478.09"}, {"price": "0.003", "size": "165.43"}, {"price": "0.004", "size": "109.32"}, {"price": "0.005", "size": "17.35"}, {"price": "0.01", "size": "10"}], "asks": [{"price": "0.999", "size": "3218.83"}, {"price": "0.998", "size": "250"}, {"price": "0.997", "size": "30.95"}, {"price": "0.99", "size": "510010"}, {"price": "0.98", "size": "20222"}, {"price": "0.979", "size": "12.16"}, {"price": "0.95", "size": "9030"}, {"price": "0.949", "size": "39"}, {"price": "0.92", "size": "9000"}, {"price": "0.919", "size": "7.91"}, {"price": "0.83", "size": "9000"}, {"price": "0.825", "size": "5"}, {"price": "0.824", "size": "11"}, {"price": "0.486", "size": "40"}, {"price": "0.485", "size": "20.51"}], "event_type": "book", "last_trade_price": ""}, {"market": "0x58b372443f0e36b9aa1d4cf0ac87afd2b35022d651d5c8483412c5d01c4213f3", "asset_id": "99681691829842945294315330954935292622565244787309205761574804371180312761411", "timestamp": "1769383997872", "hash": "aaffb47db35ed3744b7131e4db43c6903e08a85b", "bids": [{"price": "0.01", "size": "19.71"}, {"price": "0.02", "size": "922"}, {"price": "0.03", "size": "10.14"}, {"price": "0.05", "size": "30"}, {"price": "0.06", "size": "633"}, {"price": "0.07", "size": "100"}, {"price": "0.08", "size": "300"}, {"price": "0.09", "size": "6.65"}, {"price": "0.13", "size": "8"}, {"price": "0.14", "size": "14"}, {"price": "0.44", "size": "5"}, {"price": "0.79", "size": "130.59"}, {"price": "0.82", "size": "100"}, {"price": "0.83", "size": "5"}], "asks": [{"price": "0.99", "size": "32.44"}, {"price": "0.97", "size": "9.4"}, {"price": "0.96", "size": "60.45"}], "event_type": "book", "last_trade_price": ""}, {"market": "0x5f8db7b536d9a1b47ae5098f9a3b9bc28ed87ad11ccdd70b8cab89d6fc702a98", "asset_id": "75617257166140356462865461039305745735174774217559907306919128701083195276195", "timestamp": "1769383781579", "hash": "81f344b2a4c59d8a09441c0fa86561b8578e2cb7", "bids": [{"price": "0.001", "size": "3102801.08"}, {"price": "0.002", "size": "90255.25"}, {"price": "0.003", "size": "400"}, {"price": "0.004", "size": "6.44"}, {"price": "0.006", "size": "200"}, {"price": "0.01", "size": "10"}, {"price": "0.011", "size": "5.95"}, {"price": "0.02", "size": "222"}, {"price": "0.023", "size": "30700"}, {"price": "0.028", "size": "342.85"}, {"price": "0.029", "size": "9.4"}, {"price": "0.05", "size": "30"}, {"price": "0.051", "size": "15539"}, {"price": "0.052", "size": "184.61"}, {"price": "0.096", "size": "30300"}, {"price": "0.099", "size": "96.96"}, {"price": "0.1", "size": "6.2"}, {"price": "0.125", "size": "38"}, {"price": "0.126", "size": "76.19"}, {"price": "0.195", "size": "49.23"}, {"price": "0.196", "size": "10"}, {"price": "0.895", "size": "49.7"}, {"price": "0.931", "size": "421.35"}, {"price": "0.932", "size": "90.2"}, {"price": "0.949", "size": "10"}, {"price": "0.953", "size": "24.59"}, {"price": "0.954", "size": "8.25"}], "asks": [{"price": "0.999", "size": "842"}, {"price": "0.998", "size": "1512.4"}, {"price": "0.997", "size": "212.6"}, {"price": "0.996", "size": "50"}, {"price": "0.995", "size": "41.92"}, {"price": "0.99", "size": "10"}, {"price": "0.989", "size": "9.52"}, {"price": "0.979", "size": "1036.75"}, {"price": "0.978", "size": "200"}], "event_type": "book", "last_trade_price": ""}, {"market": "0xa38d137a148c4b1ec0e5a5bce42e130391bcc8086f93b4a42fb93870456fc720", "asset_id": "100952291322678954514417231357111610948515892742954751932425813530604840075554", "timestamp": "1769383827827", "hash": "d362ab1e30803ec556c0ea594ea82871d7013fcf", "bids": [{"price": "0.001", "size": "135.08"}, {"price": "0.002", "size": "22.34"}, {"price": "0.01", "size": "511226"}, {"price": "0.011", "size": "8.4"}, {"price": "0.02", "size": "30000"}, {"price": "0.03", "size": "21250"}, {"price": "0.031", "size": "9.33"}, {"price": "0.05", "size": "30"}, {"price": "0.06", "size": "664.14"}, {"price": "0.08", "size": "9598.76"}, {"price": "0.11", "size": "271.42"}, {"price": "0.111", "size": "5.12"}, {"price": "0.19", "size": "6000"}, {"price": "0.2", "size": "289.8"}, {"price": "0.21", "size": "20"}, {"price": "0.5", "size": "90"}, {"price": "0.54", "size": "1000"}, {"price": "0.55", "size": "514.51"}, {"price": "0.89", "size": "70.76"}, {"price": "0.9", "size": "85.2"}, {"price": "0.91", "size": "600"}, {"price": "0.92", "size": "16.27"}, {"price": "0.935", "size": "64.9"}, {"price": "0.936", "size": "130"}, {"price": "0.94", "size": "20.1"}, {"price": "0.941", "size": "16"}, {"price": "0.945", "size": "15.93"}, {"price": "0.949", "size": "18"}], "asks": [{"price": "0.999", "size": "1072"}, {"price": "0.998", "size": "29.81"}, {"price": "0.997", "size": "66.57"}, {"price": "0.996", "size": "53.42"}, {"price": "0.99", "size": "653.86"}, {"price": "0.989", "size": "258.08"}, {"price": "0.988", "size": "25"}], "event_type": "book", "last_trade_price": "0.990"}, {"market": "0x0ba39007f4ff1c2677f296b90188d544c2f80f9729c76a6f181a191543ceab82", "asset_id": "35279195552426720847132209025903300157513105064872410280291719894882972533678", "timestamp": "1769383971070", "hash": "272f9a8022683b4a7bda166c7be360a09df9111a", "bids": [{"price": "0.001", "size": "4665.09"}, {"price": "0.002", "size": "3237.93"}, {"price": "0.003", "size": "110.98"}, {"price": "0.004", "size": "155"}, {"price": "0.005", "size": "72.73"}], "asks": [{"price": "0.999", "size": "10702873.4"}, {"price": "0.998", "size": "255.1"}, {"price": "0.997", "size": "400"}, {"price": "0.996", "size": "8.73"}, {"price": "0.994", "size": "200"}, {"price": "0.99", "size": "10"}, {"price": "0.989", "size": "6.43"}, {"price": "0.975", "size": "10000"}, {"price": "0.974", "size": "5.6"}, {"price": "0.95", "size": "30"}, {"price": "0.949", "size": "39"}, {"price": "0.94", "size": "700"}, {"price": "0.939", "size": "12.01"}, {"price": "0.884", "size": "20000"}, {"price": "0.858", "size": "11115.49"}, {"price": "0.857", "size": "350"}, {"price": "0.8", "size": "5"}, {"price": "0.5", "size": "100"}, {"price": "0.37", "size": "1500"}, {"price": "0.195", "size": "1687.5"}, {"price": "0.193", "size": "9"}, {"price": "0.192", "size": "45"}, {"price": "0.191", "size": "22.75"}], "event_type": "book", "last_trade_price": "0.024"}, {"market": "0xf8669cc099ad4008ee1735ae5ac1eb80ae005b249055d17df33fb086bcdfe83d", "asset_id": "74412093647819275524093734803851724407441381744350956613925261842560119775884", "timestamp": "1769383997009", "hash": "c72ad651fc2e9baec8222a1ca7afc2e44c93d80c", "bids": [{"price": "0.001", "size": "10602694.08"}, {"price": "0.002", "size": "255.04"}, {"price": "0.003", "size": "400"}, {"price": "0.004", "size": "8.63"}, {"price": "0.006", "size": "3200"}, {"price": "0.01", "size": "10"}, {"price": "0.011", "size": "5.13"}, {"price": "0.022", "size": "4000"}, {"price": "0.023", "size": "14.25"}, {"price": "0.05", "size": "30"}, {"price": "0.051", "size": "39"}, {"price": "0.06", "size": "700"}, {"price": "0.111", "size": "1200"}, {"price": "0.112", "size": "5.05"}, {"price": "0.252", "size": "1500"}, {"price": "0.26", "size": "400"}, {"price": "0.262", "size": "500"}, {"price": "0.263", "size": "6000"}, {"price": "0.264", "size": "250"}, {"price": "0.36", "size": "5"}, {"price": "0.5", "size": "100"}, {"price": "0.666", "size": "1500"}, {"price": "0.857", "size": "842.29"}, {"price": "0.871", "size": "1000"}, {"price": "0.873", "size": "20"}, {"price": "0.875", "size": "1000"}, {"price": "0.876", "size": "149.99"}, {"price": "0.877", "size": "90.29"}, {"price": "0.878", "size": "5.14"}], "asks": [{"price": "0.999", "size": "867.26"}, {"price": "0.998", "size": "2929.57"}, {"price": "0.997", "size": "227.96"}, {"price": "0.996", "size": "228.25"}, {"price": "0.995", "size": "30.63"}, {"price": "0.994", "size": "153.76"}, {"price": "0.993", "size": "49.09"}, {"price": "0.992", "size": "6.26"}, {"price": "0.99", "size": "286.8"}, {"price": "0.989", "size": "306.98"}, {"price": "0.988", "size": "13.36"}], "event_type": "book", "last_trade_price": ""}, {"market": "0xb416bf4fbda79d068632d0e5447432d989b3cbf67c94d109159cb577186a2967", "asset_id": "109242542380145067807278323147433287088284156146991697158730836613947649714840", "timestamp": "1769383997382", "hash": "175dc640eb9c14a876d2dfee615503dc58f12f76", "bids": [{"price": "0.001", "size": "6102805.71"}, {"price": "0.002", "size": "90250"}, {"price": "0.003", "size": "407"}, {"price": "0.006", "size": "200"}, {"price": "0.007", "size": "10.72"}, {"price": "0.01", "size": "10"}, {"price": "0.02", "size": "222"}, {"price": "0.021", "size": "1600"}, {"price": "0.022", "size": "6.44"}, {"price": "0.05", "size": "530"}, {"price": "0.051", "size": "39"}, {"price": "0.08", "size": "300"}, {"price": "0.081", "size": "9.27"}, {"price": "0.182", "size": "900"}, {"price": "0.191", "size": "1000"}, {"price": "0.195", "size": "5"}, {"price": "0.196", "size": "10"}, {"price": "0.581", "size": "50"}, {"price": "0.582", "size": "13.67"}], "asks": [{"price": "0.999", "size": "5917.76"}, {"price": "0.998", "size": "287.79"}, {"price": "0.997", "size": "425.06"}, {"price": "0.996", "size": "218.86"}, {"price": "0.995", "size": "30.65"}, {"price": "0.994", "size": "200"}, {"price": "0.993", "size": "81.61"}, {"price": "0.992", "size": "107.78"}, {"price": "0.991", "size": "21.24"}, {"price": "0.99", "size": "10"}, {"price": "0.989", "size": "8.56"}], "event_type": "book", "last_trade_price": "0.989"}, {"market": "0x3906ccd196f47f9cd177602071c3147a4b916ab60b1e317d5439c54fb520187d", "asset_id": "66628303295255675472790623870237847302694414310186008738086927666525449327926", "timestamp": "1769383837250", "hash": "626f96c7ebb32fc766010848ff121f0575241560", "bids": [{"price": "0.001", "size": "2800.07"}, {"price": "0.002", "size": "255.04"}, {"price": "0.003", "size": "166"}, {"price": "0.004", "size": "8.62"}, {"price": "0.006", "size": "83"}, {"price": "0.01", "size": "10"}, {"price": "0.011", "size": "5.12"}, {"price": "0.02", "size": "444"}, {"price": "0.021", "size": "200"}, {"price": "0.022", "size": "30"}, {"price": "0.023", "size": "5.86"}, {"price": "0.05", "size": "30"}, {"price": "0.051", "size": "39"}, {"price": "0.056", "size": "6"}, {"price": "0.069", "size": "28"}, {"price": "0.073", "size": "45"}, {"price": "0.074", "size": "10.26"}, {"price": "0.89", "size": "22.6"}, {"price": "0.891", "size": "3.11"}], "asks": [{"price": "0.999", "size": "1260.36"}, {"price": "0.998", "size": "237.37"}, {"price": "0.997", "size": "104.01"}, {"price": "0.996", "size": "95"}, {"price": "0.995", "size": "77.31"}, {"price": "0.99", "size": "10"}, {"price": "0.989", "size": "15.11"}, {"price": "0.988", "size": "5.32"}, {"price": "0.987", "size": "20.87"}], "event_type": "book", "last_trade_price": ""}, {"market": "0xfa4c453091f10ccab9fae67d8a2286e1bf1d9367596d1d5b74c36e4155e300af", "asset_id": "50903746416787079744189627434391589495562066033420184996159345764514807060721", "timestamp": "1769383954880", "hash": "7e8a589ca52e8d8868445f53d7215ac1b0e7521a", "bids": [{"price": "0.001", "size": "4822"}, {"price": "0.002", "size": "570.98"}, {"price": "0.003", "size": "102.14"}, {"price": "0.005", "size": "183.79"}], "asks": [{"price": "0.999", "size": "4308.6"}, {"price": "0.998", "size": "250"}, {"price": "0.997", "size": "406.62"}, {"price": "0.994", "size": "200"}, {"price": "0.993", "size": "9.85"}, {"price": "0.99", "size": "10"}, {"price": "0.98", "size": "222"}, {"price": "0.979", "size": "9.66"}, {"price": "0.978", "size": "1363.63"}, {"price": "0.95", "size": "30"}, {"price": "0.949", "size": "39"}, {"price": "0.929", "size": "9.79"}, {"price": "0.928", "size": "411.11"}, {"price": "0.786", "size": "1000"}, {"price": "0.785", "size": "37.2"}, {"price": "0.766", "size": "1000"}, {"price": "0.751", "size": "100"}, {"price": "0.75", "size": "90"}, {"price": "0.714", "size": "27.97"}, {"price": "0.713", "size": "10.93"}, {"price": "0.708", "size": "6"}, {"price": "0.707", "size": "7.63"}, {"price": "0.706", "size": "27.21"}, {"price": "0.705", "size": "42.43"}, {"price": "0.704", "size": "13.02"}, {"price": "0.006", "size": "14"}], "event_type": "book", "last_trade_price": ""}, {"market": "0x6091751b0c383c6fcf4e37a80d88b387d776bff64ab63e901dd4919196abc329", "asset_id": "80483625085724709764992782621308673793154869046949769179223768350670805964694", "timestamp": "1769383883469", "hash": "21366232033b6cb2faa2909005c270a982ab26cd", "bids": [{"price": "0.01", "size": "67.91"}, {"price": "0.02", "size": "17.65"}], "asks": [{"price": "0.99", "size": "19.71"}, {"price": "0.98", "size": "222"}, {"price": "0.97", "size": "9.08"}, {"price": "0.95", "size": "30"}, {"price": "0.94", "size": "33"}, {"price": "0.92", "size": "1000"}, {"price": "0.91", "size": "7"}, {"price": "0.89", "size": "1000"}, {"price": "0.88", "size": "250"}, {"price": "0.87", "size": "15"}, {"price": "0.2", "size": "10"}, {"price": "0.19", "size": "10.39"}], "event_type": "book", "last_trade_price": ""}, {"market": "0x7dbd765a0b822e15d82cfcb1d3f2527a61b7b310aa43c083519bdadae9a7d76a", "asset_id": "29291791974951704807463257661336556331395969984862714963019387149437164613320", "timestamp": "1769383905009", "hash": "0a641fd2bff81a426f504585b062ebafb3d8f852", "bids": [{"price": "0.001", "size": "1787.9"}, {"price": "0.002", "size": "468.64"}, {"price": "0.003", "size": "178.36"}, {"price": "0.004", "size": "36.64"}, {"price": "0.006", "size": "99.6"}, {"price": "0.007", "size": "65.92"}, {"price": "0.008", "size": "17.96"}, {"price": "0.01", "size": "72"}], "asks": [{"price": "0.999", "size": "3755.13"}, {"price": "0.998", "size": "450"}, {"price": "0.997", "size": "172.66"}, {"price": "0.994", "size": "83"}, {"price": "0.993", "size": "10.21"}, {"price": "0.99", "size": "10"}, {"price": "0.98", "size": "222"}, {"price": "0.979", "size": "111"}, {"price": "0.978", "size": "7.73"}, {"price": "0.95", "size": "30"}, {"price": "0.949", "size": "39"}, {"price": "0.94", "size": "33"}, {"price": "0.939", "size": "19.09"}, {"price": "0.2", "size": "10"}, {"price": "0.199", "size": "15"}], "event_type": "book", "last_trade_price": ""}, {"market": "0x32b7aab78f0be7156c9b8c4f28226b8f676629b3b836369a88750835204d5584", "asset_id": "99758775731194955694634878830719976118374917540431552182533993870186584882882", "timestamp": "1769383811294", "hash": "e06b16af68bd88055d30193d85096863c50af7da", "bids": [{"price": "0.01", "size": "310024.28"}, {"price": "0.03", "size": "20700"}, {"price": "0.04", "size": "6.5"}, {"price": "0.05", "size": "30"}, {"price": "0.06", "size": "4533"}, {"price": "0.08", "size": "300"}, {"price": "0.1", "size": "79"}, {"price": "0.11", "size": "5.42"}, {"price": "0.5", "size": "70"}, {"price": "0.51", "size": "997.95"}, {"price": "0.52", "size": "98"}, {"price": "0.53", "size": "21.74"}, {"price": "0.85", "size": "0.61"}], "asks": [{"price": "0.99", "size": "16.53"}, {"price": "0.98", "size": "227.76"}, {"price": "0.97", "size": "14.68"}, {"price": "0.95", "size": "350"}, {"price": "0.94", "size": "217.11"}, {"price": "0.93", "size": "25"}], "event_type": "book", "last_trade_price": ""}, {"market": "0xa38d137a148c4b1ec0e5a5bce42e130391bcc8086f93b4a42fb93870456fc720", "asset_id": "106570670068044891061840154694634029425579441331483581761385437733846502477972", "timestamp": "1769383827827", "hash": "ba969bc33bd9ece637e36af49cac4a66c6a06c35", "bids": [{"price": "0.001", "size": "1072"}, {"price": "0.002", "size": "29.81"}, {"price": "0.003", "size": "66.57"}, {"price": "0.004", "size": "53.42"}, {"price": "0.01", "size": "653.86"}, {"price": "0.011", "size": "258.08"}, {"price": "0.012", "size": "25"}], "asks": [{"price": "0.999", "size": "135.08"}, {"price": "0.998", "size": "22.34"}, {"price": "0.99", "size": "511226"}, {"price": "0.989", "size": "8.4"}, {"price": "0.98", "size": "30000"}, {"price": "0.97", "size": "21250"}, {"price": "0.969", "size": "9.33"}, {"price": "0.95", "size": "30"}, {"price": "0.94", "size": "664.14"}, {"price": "0.92", "size": "9598.76"}, {"price": "0.89", "size": "271.42"}, {"price": "0.889", "size": "5.12"}, {"price": "0.81", "size": "6000"}, {"price": "0.8", "size": "289.8"}, {"price": "0.79", "size": "20"}, {"price": "0.5", "size": "90"}, {"price": "0.46", "size": "1000"}, {"price": "0.45", "size": "514.51"}, {"price": "0.11", "size": "70.76"}, {"price": "0.1", "size": "85.2"}, {"price": "0.09", "size": "600"}, {"price": "0.08", "size": "16.27"}, {"price": "0.065", "size": "64.9"}, {"price": "0.064", "size": "130"}, {"price": "0.06", "size": "20.1"}, {"price": "0.059", "size": "16"}, {"price": "0.055", "size": "15.93"}, {"price": "0.051", "size": "18"}], "event_type": "book", "last_trade_price": "0.990"}, {"market": "0x32b7aab78f0be7156c9b8c4f28226b8f676629b3b836369a88750835204d5584", "asset_id": "99190743562209447358094560183285732023690283653912147802428483334474879764706", "timestamp": "1769383811294", "hash": "07a9b8fd13aa4ee3fc6eccc7d72fa370bd13ab28", "bids": [{"price": "0.01", "size": "16.53"}, {"price": "0.02", "size": "227.76"}, {"price": "0.03", "size": "14.68"}, {"price": "0.05", "size": "350"}, {"price": "0.06", "size": "217.11"}, {"price": "0.07", "size": "25"}], "asks": [{"price": "0.99", "size": "310024.28"}, {"price": "0.97", "size": "20700"}, {"price": "0.96", "size": "6.5"}, {"price": "0.95", "size": "30"}, {"price": "0.94", "size": "4533"}, {"price": "0.92", "size": "300"}, {"price": "0.9", "size": "79"}, {"price": "0.89", "size": "5.42"}, {"price": "0.5", "size": "70"}, {"price": "0.49", "size": "997.95"}, {"price": "0.48", "size": "98"}, {"price": "0.47", "size": "21.74"}, {"price": "0.15", "size": "0.61"}], "event_type": "book", "last_trade_price": ""}, {"market": "0xccb49e0802c9ada89016c5f6f9933847455b736228812d0707a88e014804a630", "asset_id": "81304145828607624927593781798310463714484865200409152894719292343497594428963", "timestamp": "1769383927329", "hash": "d61cf519308e08534e3e77fa5e4841352b417bed", "bids": [{"price": "0.01", "size": "16.46"}, {"price": "0.02", "size": "86.54"}, {"price": "0.03", "size": "26.29"}, {"price": "0.08", "size": "100"}], "asks": [{"price": "0.99", "size": "225.96"}, {"price": "0.98", "size": "222"}, {"price": "0.97", "size": "5.58"}, {"price": "0.96", "size": "58"}, {"price": "0.95", "size": "30"}, {"price": "0.94", "size": "33"}, {"price": "0.91", "size": "22"}, {"price": "0.9", "size": "7.35"}, {"price": "0.5", "size": "40"}, {"price": "0.2", "size": "26.78"}], "event_type": "book", "last_trade_price": "0.200"}, {"market": "0x0bf8c8a49d597193dcc1d3921b68bcf357dcf14f61eebb314b2ca26df92c6b70", "asset_id": "64985992928364318123592920719859941241227792181953993325149181671869965959425", "timestamp": "1769383909045", "hash": "f09fe73bc125629c545066272f5751ad3cf48d0c", "bids": [{"price": "0.001", "size": "11002801.07"}, {"price": "0.002", "size": "60255.09"}, {"price": "0.003", "size": "400"}, {"price": "0.004", "size": "8.35"}, {"price": "0.006", "size": "200"}, {"price": "0.01", "size": "10"}, {"price": "0.011", "size": "6.6"}, {"price": "0.02", "size": "222"}, {"price": "0.024", "size": "30000"}, {"price": "0.031", "size": "387.09"}, {"price": "0.032", "size": "8.49"}, {"price": "0.05", "size": "30"}, {"price": "0.051", "size": "274.29"}, {"price": "0.096", "size": "40000"}, {"price": "0.097", "size": "200"}, {"price": "0.103", "size": "116.5"}, {"price": "0.104", "size": "36.02"}, {"price": "0.293", "size": "39"}, {"price": "0.294", "size": "58.08"}, {"price": "0.295", "size": "46.67"}, {"price": "0.296", "size": "69.52"}, {"price": "0.95", "size": "5"}, {"price": "0.951", "size": "7.58"}, {"price": "0.989", "size": "25"}, {"price": "0.99", "size": "38.56"}], "asks": [{"price": "0.999", "size": "3936.3"}, {"price": "0.998", "size": "221.23"}, {"price": "0.997", "size": "118"}, {"price": "0.996", "size": "156.03"}], "event_type": "book", "last_trade_price": "0.003"}, {"market": "0x6091751b0c383c6fcf4e37a80d88b387d776bff64ab63e901dd4919196abc329", "asset_id": "53573626783512767474965169921373184555692031364719493066788586058660304077527", "timestamp": "1769383883469", "hash": "5df280091074e9ff2b90434f608d318635f6d258", "bids": [{"price": "0.01", "size": "19.71"}, {"price": "0.02", "size": "222"}, {"price": "0.03", "size": "9.08"}, {"price": "0.05", "size": "30"}, {"price": "0.06", "size": "33"}, {"price": "0.08", "size": "1000"}, {"price": "0.09", "size": "7"}, {"price": "0.11", "size": "1000"}, {"price": "0.12", "size": "250"}, {"price": "0.13", "size": "15"}, {"price": "0.8", "size": "10"}, {"price": "0.81", "size": "10.39"}], "asks": [{"price": "0.99", "size": "67.91"}, {"price": "0.98", "size": "17.65"}], "event_type": "book", "last_trade_price": ""}, {"market": "0xf20f7af3ea74b16d623af198d6efb27d9d4ee98cfa96b1b6c8d4021d55436eb0", "asset_id": "8204205703682240679449476083075054464313606926136751077466819525464621562665", "timestamp": "1769383991368", "hash": "00743365e9d0a754767e16ff9901b113f5453460", "bids": [{"price": "0.01", "size": "65.34"}, {"price": "0.02", "size": "261.99"}, {"price": "0.03", "size": "21.5"}], "asks": [{"price": "0.99", "size": "19.69"}, {"price": "0.98", "size": "222"}, {"price": "0.97", "size": "117.79"}, {"price": "0.95", "size": "30"}, {"price": "0.94", "size": "33"}, {"price": "0.93", "size": "28"}, {"price": "0.92", "size": "8.73"}, {"price": "0.64", "size": "5"}, {"price": "0.13", "size": "20"}], "event_type": "book", "last_trade_price": ""}, {"market": "0xf8669cc099ad4008ee1735ae5ac1eb80ae005b249055d17df33fb086bcdfe83d", "asset_id": "67480800071998288404809609572612598087778955841531703375023453126691719294061", "timestamp": "1769383997009", "hash": "45d037defdec417f3cd9270a4ad1dd1bccbcc246", "bids": [{"price": "0.001", "size": "867.26"}, {"price": "0.002", "size": "2929.57"}, {"price": "0.003", "size": "227.96"}, {"price": "0.004", "size": "228.25"}, {"price": "0.005", "size": "30.63"}, {"price": "0.006", "size": "153.76"}, {"price": "0.007", "size": "49.09"}, {"price": "0.008", "size": "6.26"}, {"price": "0.01", "size": "286.8"}, {"price": "0.011", "size": "306.98"}, {"price": "0.012", "size": "13.36"}], "asks": [{"price": "0.999", "size": "10602694.08"}, {"price": "0.998", "size": "255.04"}, {"price": "0.997", "size": "400"}, {"price": "0.996", "size": "8.63"}, {"price": "0.994", "size": "3200"}, {"price": "0.99", "size": "10"}, {"price": "0.989", "size": "5.13"}, {"price": "0.978", "size": "4000"}, {"price": "0.977", "size": "14.25"}, {"price": "0.95", "size": "30"}, {"price": "0.949", "size": "39"}, {"price": "0.94", "size": "700"}, {"price": "0.889", "size": "1200"}, {"price": "0.888", "size": "5.05"}, {"price": "0.748", "size": "1500"}, {"price": "0.74", "size": "400"}, {"price": "0.738", "size": "500"}, {"price": "0.737", "size": "6000"}, {"price": "0.736", "size": "250"}, {"price": "0.64", "size": "5"}, {"price": "0.5", "size": "100"}, {"price": "0.334", "size": "1500"}, {"price": "0.143", "size": "842.29"}, {"price": "0.129", "size": "1000"}, {"price": "0.127", "size": "20"}, {"price": "0.125", "size": "1000"}, {"price": "0.124", "size": "149.99"}, {"price": "0.123", "size": "90.29"}, {"price": "0.122", "size": "5.14"}], "event_type": "book", "last_trade_price": ""}, {"market": "0x4f355b2f81f7f84edb31b62b3972d3681a78306b6f43130da93c6a42e829cab7", "asset_id": "43538879179631176153024597485437046935007669385526523627415213016048238626800", "timestamp": "1769383957510", "hash": "a6c228cbcb42a9497b274aa6ff7c993b103a917d", "bids": [{"price": "0.001", "size": "2077.12"}, {"price": "0.002", "size": "450"}, {"price": "0.003", "size": "13.18"}, {"price": "0.01", "size": "10"}, {"price": "0.011", "size": "5.95"}, {"price": "0.02", "size": "222"}, {"price": "0.021", "size": "30"}, {"price": "0.024", "size": "15"}, {"price": "0.025", "size": "6.55"}, {"price": "0.05", "size": "30"}, {"price": "0.051", "size": "39"}, {"price": "0.07", "size": "28"}, {"price": "0.071", "size": "10.15"}, {"price": "0.71", "size": "15"}, {"price": "0.718", "size": "5"}, {"price": "0.81", "size": "14.99"}, {"price": "0.83", "size": "20"}], "asks": [{"price": "0.999", "size": "900.72"}, {"price": "0.998", "size": "490.57"}, {"price": "0.997", "size": "152.18"}, {"price": "0.996", "size": "62.77"}, {"price": "0.995", "size": "42.6"}, {"price": "0.994", "size": "7.62"}, {"price": "0.99", "size": "10"}, {"price": "0.989", "size": "11.16"}], "event_type": "book", "last_trade_price": ""}, {"market": "0x3906ccd196f47f9cd177602071c3147a4b916ab60b1e317d5439c54fb520187d", "asset_id": "62082789175342153765549566755525855471250020053983528793359435486631209756539", "timestamp": "1769383837250", "hash": "e876ffc272b4c4557d3c350bd737895cf752d57e", "bids": [{"price": "0.001", "size": "1260.36"}, {"price": "0.002", "size": "237.37"}, {"price": "0.003", "size": "104.01"}, {"price": "0.004", "size": "95"}, {"price": "0.005", "size": "77.31"}, {"price": "0.01", "size": "10"}, {"price": "0.011", "size": "15.11"}, {"price": "0.012", "size": "5.32"}, {"price": "0.013", "size": "20.87"}], "asks": [{"price": "0.999", "size": "2800.07"}, {"price": "0.998", "size": "255.04"}, {"price": "0.997", "size": "166"}, {"price": "0.996", "size": "8.62"}, {"price": "0.994", "size": "83"}, {"price": "0.99", "size": "10"}, {"price": "0.989", "size": "5.12"}, {"price": "0.98", "size": "444"}, {"price": "0.979", "size": "200"}, {"price": "0.978", "size": "30"}, {"price": "0.977", "size": "5.86"}, {"price": "0.95", "size": "30"}, {"price": "0.949", "size": "39"}, {"price": "0.944", "size": "6"}, {"price": "0.931", "size": "28"}, {"price": "0.927", "size": "45"}, {"price": "0.926", "size": "10.26"}, {"price": "0.11", "size": "22.6"}, {"price": "0.109", "size": "3.11"}], "event_type": "book", "last_trade_price": ""}, {"market": "0x4f355b2f81f7f84edb31b62b3972d3681a78306b6f43130da93c6a42e829cab7", "asset_id": "6698389915475741137443362108181546761737389215301116913025758411586200078040", "timestamp": "1769383957510", "hash": "1d6104fec44c42ab2792606ae5f2ad97676338d2", "bids": [{"price": "0.001", "size": "900.72"}, {"price": "0.002", "size": "490.57"}, {"price": "0.003", "size": "152.18"}, {"price": "0.004", "size": "62.77"}, {"price": "0.005", "size": "42.6"}, {"price": "0.006", "size": "7.62"}, {"price": "0.01", "size": "10"}, {"price": "0.011", "size": "11.16"}], "asks": [{"price": "0.999", "size": "2077.12"}, {"price": "0.998", "size": "450"}, {"price": "0.997", "size": "13.18"}, {"price": "0.99", "size": "10"}, {"price": "0.989", "size": "5.95"}, {"price": "0.98", "size": "222"}, {"price": "0.979", "size": "30"}, {"price": "0.976", "size": "15"}, {"price": "0.975", "size": "6.55"}, {"price": "0.95", "size": "30"}, {"price": "0.949", "size": "39"}, {"price": "0.93", "size": "28"}, {"price": "0.929", "size": "10.15"}, {"price": "0.29", "size": "15"}, {"price": "0.282", "size": "5"}, {"price": "0.19", "size": "14.99"}, {"price": "0.17", "size": "20"}], "event_type": "book", "last_trade_price": ""}]}
{"_local_timestamp": "2026-01-25T23:33:18.844688+00:00", "data": {"market": "0xf8669cc099ad4008ee1735ae5ac1eb80ae005b249055d17df33fb086bcdfe83d", "price_changes": [{"asset_id": "67480800071998288404809609572612598087778955841531703375023453126691719294061", "price": "0.007", "size": "41.11", "side": "BUY", "hash": "296e7f4eb82fee30916c769603591fbc955e70cb", "best_bid": "0.012", "best_ask": "0.122"}, {"asset_id": "74412093647819275524093734803851724407441381744350956613925261842560119775884", "price": "0.993", "size": "41.11", "side": "SELL", "hash": "c5c45ee453b0e64579bd4d637e06d95f109138dd", "best_bid": "0.878", "best_ask": "0.988"}], "timestamp": "1769383998768", "event_type": "price_change"}}
{"_local_timestamp": "2026-01-25T23:33:19.080550+00:00", "data": {"market": "0xf8669cc099ad4008ee1735ae5ac1eb80ae005b249055d17df33fb086bcdfe83d", "price_changes": [{"asset_id": "67480800071998288404809609572612598087778955841531703375023453126691719294061", "price": "0.007", "size": "49.09", "side": "BUY", "hash": "844e727ff3d95ebc4318329004fea177f645b614", "best_bid": "0.012", "best_ask": "0.122"}, {"asset_id": "74412093647819275524093734803851724407441381744350956613925261842560119775884", "price": "0.993", "size": "49.09", "side": "SELL", "hash": "6b0bd6a5b2c8dc1f3603aa0ab2c92165ba94e3c4", "best_bid": "0.878", "best_ask": "0.988"}], "timestamp": "1769383999007", "event_type": "price_change"}}
{"_local_timestamp": "2026-01-25T23:33:20.125235+00:00", "data": {"market": "0xf20f7af3ea74b16d623af198d6efb27d9d4ee98cfa96b1b6c8d4021d55436eb0", "price_changes": [{"asset_id": "8204205703682240679449476083075054464313606926136751077466819525464621562665", "price": "0.03", "size": "12.23", "side": "BUY", "hash": "5be14707628a4db083828e3e92d8840f0fcbd198", "best_bid": "0.03", "best_ask": "0.13"}, {"asset_id": "79006550760303579457645886672312299229061887535391288753983510221472432105358", "price": "0.97", "size": "12.23", "side": "SELL", "hash": "fc844152382dc0504124596699e27b055a8672c0", "best_bid": "0.87", "best_ask": "0.97"}], "timestamp": "1769384000058", "event_type": "price_change"}}
{"_local_timestamp": "2026-01-25T23:33:20.449650+00:00", "data": {"market": "0xf20f7af3ea74b16d623af198d6efb27d9d4ee98cfa96b1b6c8d4021d55436eb0", "price_changes": [{"asset_id": "8204205703682240679449476083075054464313606926136751077466819525464621562665", "price": "0.03", "size": "21.5", "side": "BUY", "hash": "e1affb92b7439b0747f4390da6752527ac71e331", "best_bid": "0.03", "best_ask": "0.13"}, {"asset_id": "79006550760303579457645886672312299229061887535391288753983510221472432105358", "price": "0.97", "size": "21.5", "side": "SELL", "hash": "421431d3c0aa0ea846b6815c24d531b85a973071", "best_bid": "0.87", "best_ask": "0.97"}], "timestamp": "1769384000380", "event_type": "price_change"}}
{"_local_timestamp": "2026-01-25T23:33:22.322690+00:00", "data": {"market": "0xf8669cc099ad4008ee1735ae5ac1eb80ae005b249055d17df33fb086bcdfe83d", "price_changes": [{"asset_id": "67480800071998288404809609572612598087778955841531703375023453126691719294061", "price": "0.007", "size": "41.11", "side": "BUY", "hash": "dbdf90802af5db88c01fd924fbc8d55a28afe83b", "best_bid": "0.012", "best_ask": "0.122"}, {"asset_id": "74412093647819275524093734803851724407441381744350956613925261842560119775884", "price": "0.993", "size": "41.11", "side": "SELL", "hash": "23a7219153106e1dcf93539591123324c4df505d", "best_bid": "0.878", "best_ask": "0.988"}], "timestamp": "1769384002250", "event_type": "price_change"}}
{"_local_timestamp": "2026-01-25T23:33:22.323393+00:00", "data": {"market": "0xf8669cc099ad4008ee1735ae5ac1eb80ae005b249055d17df33fb086bcdfe83d", "price_changes": [{"asset_id": "74412093647819275524093734803851724407441381744350956613925261842560119775884", "price": "0.36", "size": "0", "side": "BUY", "hash": "c832399635f5b7a5c0de0e861f8312c9a4bfbf3a", "best_bid": "0.878", "best_ask": "0.988"}, {"asset_id": "67480800071998288404809609572612598087778955841531703375023453126691719294061", "price": "0.64", "size": "0", "side": "SELL", "hash": "41faa3f4727c267d786830dc5bed924e1ebc691c", "best_bid": "0.012", "best_ask": "0.122"}], "timestamp": "1769384002251", "event_type": "price_change"}}
{"_local_timestamp": "2026-01-25T23:33:22.728147+00:00", "data": {"market": "0xf8669cc099ad4008ee1735ae5ac1eb80ae005b249055d17df33fb086bcdfe83d", "price_changes": [{"asset_id": "74412093647819275524093734803851724407441381744350956613925261842560119775884", "price": "0.36", "size": "5", "side": "BUY", "hash": "f4bcdae136d2e08aa7733fcd5035d4cbfb840533", "best_bid": "0.878", "best_ask": "0.988"}, {"asset_id": "67480800071998288404809609572612598087778955841531703375023453126691719294061", "price": "0.64", "size": "5", "side": "SELL", "hash": "4db0eb6666f9b94f918f82e7a012813eed5c2456", "best_bid": "0.012", "best_ask": "0.122"}], "timestamp": "1769384002647", "event_type": "price_change"}}
{"_local_timestamp": "2026-01-25T23:33:22.729944+00:00", "data": {"market": "0xf8669cc099ad4008ee1735ae5ac1eb80ae005b249055d17df33fb086bcdfe83d", "price_changes": [{"asset_id": "67480800071998288404809609572612598087778955841531703375023453126691719294061", "price": "0.007", "size": "49.09", "side": "BUY", "hash": "6c377622e422d104234c65299ecf730e26e9d68e", "best_bid": "0.012", "best_ask": "0.122"}, {"asset_id": "74412093647819275524093734803851724407441381744350956613925261842560119775884", "price": "0.993", "size": "49.09", "side": "SELL", "hash": "408b6edec9e10740c0d7e56f20ef543933fa81ef", "best_bid": "0.878", "best_ask": "0.988"}], "timestamp": "1769384002648", "event_type": "price_change"}}
{"_local_timestamp": "2026-01-25T23:33:24.907726+00:00", "data": {"market": "0xf8669cc099ad4008ee1735ae5ac1eb80ae005b249055d17df33fb086bcdfe83d", "price_changes": [{"asset_id": "67480800071998288404809609572612598087778955841531703375023453126691719294061", "price": "0.007", "size": "41.11", "side": "BUY", "hash": "fe48e10be882bc22ab3b6c7305d2c560784755ad", "best_bid": "0.012", "best_ask": "0.122"}, {"asset_id": "74412093647819275524093734803851724407441381744350956613925261842560119775884", "price": "0.993", "size": "41.11", "side": "SELL", "hash": "64dff8dbc354237086e4aab0df4dcfde9c95ece0", "best_bid": "0.878", "best_ask": "0.988"}], "timestamp": "1769384004833", "event_type": "price_change"}}
{"_local_timestamp": "2026-01-25T23:33:25.163458+00:00", "data": {"market": "0xf8669cc099ad4008ee1735ae5ac1eb80ae005b249055d17df33fb086bcdfe83d", "price_changes": [{"asset_id": "67480800071998288404809609572612598087778955841531703375023453126691719294061", "price": "0.007", "size": "49.09", "side": "BUY", "hash": "963b728d7c106642ff109c181b7a38274991f4da", "best_bid": "0.012", "best_ask": "0.122"}, {"asset_id": "74412093647819275524093734803851724407441381744350956613925261842560119775884", "price": "0.993", "size": "49.09", "side": "SELL", "hash": "a006cfd670307b3f9126010a0e599ec9940c3ba6", "best_bid": "0.878", "best_ask": "0.988"}], "timestamp": "1769384005090", "event_type": "price_change"}}
{"_local_timestamp": "2026-01-25T23:33:25.356391+00:00", "data": {"market": "0xf20f7af3ea74b16d623af198d6efb27d9d4ee98cfa96b1b6c8d4021d55436eb0", "price_changes": [{"asset_id": "8204205703682240679449476083075054464313606926136751077466819525464621562665", "price": "0.03", "size": "12.23", "side": "BUY", "hash": "7c34b3f8c889b71ca11dd8e9067607844c887709", "best_bid": "0.03", "best_ask": "0.13"}, {"asset_id": "79006550760303579457645886672312299229061887535391288753983510221472432105358", "price": "0.97", "size": "12.23", "side": "SELL", "hash": "9a10426215a8a57b115ac84f6d1a5e8930fa252f", "best_bid": "0.87", "best_ask": "0.97"}], "timestamp": "1769384005286", "event_type": "price_change"}}
{"_local_timestamp": "2026-01-25T23:33:25.602850+00:00", "data": {"market": "0xf20f7af3ea74b16d623af198d6efb27d9d4ee98cfa96b1b6c8d4021d55436eb0", "price_changes": [{"asset_id": "8204205703682240679449476083075054464313606926136751077466819525464621562665", "price": "0.03", "size": "21.5", "side": "BUY", "hash": "109c2f4b23bba0375c612a92bc16d5eb718a396d", "best_bid": "0.03", "best_ask": "0.13"}, {"asset_id": "79006550760303579457645886672312299229061887535391288753983510221472432105358", "price": "0.97", "size": "21.5", "side": "SELL", "hash": "46f1a49ca03e1ec24e8bee3497372de0d0f60195", "best_bid": "0.87", "best_ask": "0.97"}], "timestamp": "1769384005535", "event_type": "price_change"}}
{"_local_timestamp": "2026-01-25T23:33:27.153118+00:00", "data": {"market": "0xf8669cc099ad4008ee1735ae5ac1eb80ae005b249055d17df33fb086bcdfe83d", "price_changes": [{"asset_id": "67480800071998288404809609572612598087778955841531703375023453126691719294061", "price": "0.007", "size": "41.11", "side": "BUY", "hash": "654da0bcad73acadadae50f8669289954ac7eb2b", "best_bid": "0.012", "best_ask": "0.122"}, {"asset_id": "74412093647819275524093734803851724407441381744350956613925261842560119775884", "price": "0.993", "size": "41.11", "side": "SELL", "hash": "50eff8ea52b78425d36caa23530a2c8d0b41f121", "best_bid": "0.878", "best_ask": "0.988"}], "timestamp": "1769384007076", "event_type": "price_change"}}
{"_local_timestamp": "2026-01-25T23:33:27.445510+00:00", "data": {"market": "0xf8669cc099ad4008ee1735ae5ac1eb80ae005b249055d17df33fb086bcdfe83d", "price_changes": [{"asset_id": "67480800071998288404809609572612598087778955841531703375023453126691719294061", "price": "0.007", "size": "49.09", "side": "BUY", "hash": "1692d0144bd5eec5c4bc80b5a9b8d2d68eea5c9a", "best_bid": "0.012", "best_ask": "0.122"}, {"asset_id": "74412093647819275524093734803851724407441381744350956613925261842560119775884", "price": "0.993", "size": "49.09", "side": "SELL", "hash": "866ed2905e77eedefd5452fe6b19738f417584c8", "best_bid": "0.878", "best_ask": "0.988"}], "timestamp": "1769384007361", "event_type": "price_change"}}
{"_local_timestamp": "2026-01-25T23:33:27.592056+00:00", "data": {"market": "0xf20f7af3ea74b16d623af198d6efb27d9d4ee98cfa96b1b6c8d4021d55436eb0", "price_changes": [{"asset_id": "8204205703682240679449476083075054464313606926136751077466819525464621562665", "price": "0.03", "size": "12.23", "side": "BUY", "hash": "9ae03f8df3c05ebe76d128c17e0f6e7281735514", "best_bid": "0.03", "best_ask": "0.13"}, {"asset_id": "79006550760303579457645886672312299229061887535391288753983510221472432105358", "price": "0.97", "size": "12.23", "side": "SELL", "hash": "8d8075986c0b44845736efce11799ef46388d99e", "best_bid": "0.87", "best_ask": "0.97"}], "timestamp": "1769384007515", "event_type": "price_change"}}
{"_local_timestamp": "2026-01-25T23:33:27.898970+00:00", "data": {"market": "0xf20f7af3ea74b16d623af198d6efb27d9d4ee98cfa96b1b6c8d4021d55436eb0", "price_changes": [{"asset_id": "8204205703682240679449476083075054464313606926136751077466819525464621562665", "price": "0.03", "size": "21.5", "side": "BUY", "hash": "4363f45bb6d52ec286936bcd9e7b11197b7908b3", "best_bid": "0.03", "best_ask": "0.13"}, {"asset_id": "79006550760303579457645886672312299229061887535391288753983510221472432105358", "price": "0.97", "size": "21.5", "side": "SELL", "hash": "7e75726adb4bbb3c2d63bc1def48148cdf460949", "best_bid": "0.87", "best_ask": "0.97"}], "timestamp": "1769384007826", "event_type": "price_change"}}
{"_local_timestamp": "2026-01-25T23:33:28.916079+00:00", "data": {"market": "0xf20f7af3ea74b16d623af198d6efb27d9d4ee98cfa96b1b6c8d4021d55436eb0", "price_changes": [{"asset_id": "8204205703682240679449476083075054464313606926136751077466819525464621562665", "price": "0.03", "size": "12.23", "side": "BUY", "hash": "0744663172271ce6ac9e5a2b9f826a893b72122e", "best_bid": "0.03", "best_ask": "0.13"}, {"asset_id": "79006550760303579457645886672312299229061887535391288753983510221472432105358", "price": "0.97", "size": "12.23", "side": "SELL", "hash": "33c457584dca082d2cfd38fe57499082ec51d4a3", "best_bid": "0.87", "best_ask": "0.97"}], "timestamp": "1769384008850", "event_type": "price_change"}}
{"_local_timestamp": "2026-01-25T23:33:28.916713+00:00", "data": {"market": "0xf8669cc099ad4008ee1735ae5ac1eb80ae005b249055d17df33fb086bcdfe83d", "price_changes": [{"asset_id": "67480800071998288404809609572612598087778955841531703375023453126691719294061", "price": "0.007", "size": "41.11", "side": "BUY", "hash": "c80a6dd727aaf9769060d3ebae6b4fb2ebc9d2a4", "best_bid": "0.012", "best_ask": "0.122"}, {"asset_id": "74412093647819275524093734803851724407441381744350956613925261842560119775884", "price": "0.993", "size": "41.11", "side": "SELL", "hash": "9b2b9bde6a321be053a489a4e0640807a6f3f1a4", "best_bid": "0.878", "best_ask": "0.988"}], "timestamp": "1769384008850", "event_type": "price_change"}}
{"_local_timestamp": "2026-01-25T23:33:29.168543+00:00", "data": {"market": "0xf8669cc099ad4008ee1735ae5ac1eb80ae005b249055d17df33fb086bcdfe83d", "price_changes": [{"asset_id": "67480800071998288404809609572612598087778955841531703375023453126691719294061", "price": "0.008", "size": "13.25", "side": "BUY", "hash": "f97c1d6e956808b7af8dc3be1a2d49792c8357ba", "best_bid": "0.012", "best_ask": "0.122"}, {"asset_id": "74412093647819275524093734803851724407441381744350956613925261842560119775884", "price": "0.992", "size": "13.25", "side": "SELL", "hash": "4f4bce30d6fbe3b4db6c055708c449a6f2cbf1aa", "best_bid": "0.878", "best_ask": "0.988"}], "timestamp": "1769384009095", "event_type": "price_change"}}
{"_local_timestamp": "2026-01-25T23:33:29.169272+00:00", "data": {"market": "0xf20f7af3ea74b16d623af198d6efb27d9d4ee98cfa96b1b6c8d4021d55436eb0", "price_changes": [{"asset_id": "8204205703682240679449476083075054464313606926136751077466819525464621562665", "price": "0.04", "size": "6.95", "side": "BUY", "hash": "1ee7e74c4d36be7ba752f2f3b5f28bcc4be766cb", "best_bid": "0.04", "best_ask": "0.13"}, {"asset_id": "79006550760303579457645886672312299229061887535391288753983510221472432105358", "price": "0.96", "size": "6.95", "side": "SELL", "hash": "598cbc1628af81e1f4f7a89ee79d7b0eedffffe2", "best_bid": "0.87", "best_ask": "0.96"}], "timestamp": "1769384009096", "event_type": "price_change"}}
{"_local_timestamp": "2026-01-25T23:33:31.232595+00:00", "data": {"market": "0xf8669cc099ad4008ee1735ae5ac1eb80ae005b249055d17df33fb086bcdfe83d", "price_changes": [{"asset_id": "67480800071998288404809609572612598087778955841531703375023453126691719294061", "price": "0.008", "size": "6.26", "side": "BUY", "hash": "3746aa13e74de9cacd232f14ffaebe8a9f765f5f", "best_bid": "0.012", "best_ask": "0.122"}, {"asset_id": "74412093647819275524093734803851724407441381744350956613925261842560119775884", "price": "0.992", "size": "6.26", "side": "SELL", "hash": "db2884a5b7917ca3ae233e0e9761f9124dba0a1c", "best_bid": "0.878", "best_ask": "0.988"}], "timestamp": "1769384011136", "event_type": "price_change"}}
{"_local_timestamp": "2026-01-25T23:33:31.516443+00:00", "data": {"market": "0xf8669cc099ad4008ee1735ae5ac1eb80ae005b249055d17df33fb086bcdfe83d", "price_changes": [{"asset_id": "67480800071998288404809609572612598087778955841531703375023453126691719294061", "price": "0.007", "size": "49.09", "side": "BUY", "hash": "f07c7fcf127e75577df0890e3e6918e65e0ad5a3", "best_bid": "0.012", "best_ask": "0.122"}, {"asset_id": "74412093647819275524093734803851724407441381744350956613925261842560119775884", "price": "0.993", "size": "49.09", "side": "SELL", "hash": "8cb8bca39c341f2308fea96986eed4c2eea00263", "best_bid": "0.878", "best_ask": "0.988"}], "timestamp": "1769384011436", "event_type": "price_change"}}
{"_local_timestamp": "2026-01-25T23:33:31.938352+00:00", "data": {"market": "0xf20f7af3ea74b16d623af198d6efb27d9d4ee98cfa96b1b6c8d4021d55436eb0", "price_changes": [{"asset_id": "8204205703682240679449476083075054464313606926136751077466819525464621562665", "price": "0.04", "size": "0", "side": "BUY", "hash": "2a8c3ba9a96c7dcdf757492108c46abe519be60e", "best_bid": "0.03", "best_ask": "0.13"}, {"asset_id": "79006550760303579457645886672312299229061887535391288753983510221472432105358", "price": "0.96", "size": "0", "side": "SELL", "hash": "0cc333c663b37e52eec9ca55595a1e35a354ff3a", "best_bid": "0.87", "best_ask": "0.97"}], "timestamp": "1769384011866", "event_type": "price_change"}}
{"_local_timestamp": "2026-01-25T23:33:32.289490+00:00", "data": {"market": "0xf20f7af3ea74b16d623af198d6efb27d9d4ee98cfa96b1b6c8d4021d55436eb0", "price_changes": [{"asset_id": "8204205703682240679449476083075054464313606926136751077466819525464621562665", "price": "0.03", "size": "21.5", "side": "BUY", "hash": "9d24acc61660eca72aaf46f9f088f222cec12625", "best_bid": "0.03", "best_ask": "0.13"}, {"asset_id": "79006550760303579457645886672312299229061887535391288753983510221472432105358", "price": "0.97", "size": "21.5", "side": "SELL", "hash": "3e389c37020121eac5f0e26c4100d5f429195198", "best_bid": "0.87", "best_ask": "0.97"}], "timestamp": "1769384012209", "event_type": "price_change"}}
{"_local_timestamp": "2026-01-25T23:33:32.300308+00:00", "data": {"market": "0xec3536934fc4072b6ec4f95541002b893a7e64193d89058a50b1300733d0577a", "price_changes": [{"asset_id": "32197429166700111536823754287092684333922425922201658989691857565621864128151", "price": "0.321", "size": "0", "side": "SELL", "hash": "c75cd19ea2f38cb312db689a816914e58dbf48eb", "best_bid": "0.009", "best_ask": "0.32"}, {"asset_id": "96671476518786383904585530156908444908957428537143909392577226929673922053938", "price": "0.679", "size": "0", "side": "BUY", "hash": "a2dd2611725db63fccbdfef2ccefe6077915e279", "best_bid": "0.68", "best_ask": "0.991"}], "timestamp": "1769384012218", "event_type": "price_change"}}
{"_local_timestamp": "2026-01-25T23:33:32.742945+00:00", "data": {"market": "0xec3536934fc4072b6ec4f95541002b893a7e64193d89058a50b1300733d0577a", "price_changes": [{"asset_id": "32197429166700111536823754287092684333922425922201658989691857565621864128151", "price": "0.32", "size": "22.5", "side": "SELL", "hash": "992d5c445cafb5280b40f7dee4da7f6eaacc1a66", "best_bid": "0.009", "best_ask": "0.32"}, {"asset_id": "96671476518786383904585530156908444908957428537143909392577226929673922053938", "price": "0.68", "size": "22.5", "side": "BUY", "hash": "afc0ef3ac30e5c16f00ec86abd17b1e50762d443", "best_bid": "0.68", "best_ask": "0.991"}], "timestamp": "1769384012664", "event_type": "price_change"}}
{"_local_timestamp": "2026-01-25T23:33:34.031886+00:00", "data": {"market": "0xf20f7af3ea74b16d623af198d6efb27d9d4ee98cfa96b1b6c8d4021d55436eb0", "price_changes": [{"asset_id": "8204205703682240679449476083075054464313606926136751077466819525464621562665", "price": "0.03", "size": "12.23", "side": "BUY", "hash": "a5d0e7e5a9a0052342b72663cdfd5d9532d23fae", "best_bid": "0.03", "best_ask": "0.13"}, {"asset_id": "79006550760303579457645886672312299229061887535391288753983510221472432105358", "price": "0.97", "size": "12.23", "side": "SELL", "hash": "fdfc44946e40c58853d9f3519dcab34e10bafc6b", "best_bid": "0.87", "best_ask": "0.97"}], "timestamp": "1769384013966", "event_type": "price_change"}}
{"_local_timestamp": "2026-01-25T23:33:34.033494+00:00", "data": {"market": "0xf8669cc099ad4008ee1735ae5ac1eb80ae005b249055d17df33fb086bcdfe83d", "price_changes": [{"asset_id": "67480800071998288404809609572612598087778955841531703375023453126691719294061", "price": "0.007", "size": "41.11", "side": "BUY", "hash": "3961d9cd13cf4268a92fd1c9392f5561077438f5", "best_bid": "0.012", "best_ask": "0.122"}, {"asset_id": "74412093647819275524093734803851724407441381744350956613925261842560119775884", "price": "0.993", "size": "41.11", "side": "SELL", "hash": "3de622648e5265e107a80779df3440463c7b89a6", "best_bid": "0.878", "best_ask": "0.988"}], "timestamp": "1769384013967", "event_type": "price_change"}}
{"_local_timestamp": "2026-01-25T23:33:34.403739+00:00", "data": {"market": "0xf20f7af3ea74b16d623af198d6efb27d9d4ee98cfa96b1b6c8d4021d55436eb0", "price_changes": [{"asset_id": "8204205703682240679449476083075054464313606926136751077466819525464621562665", "price": "0.04", "size": "6.95", "side": "BUY", "hash": "0006147a3670155784717b7a6085587274eef753", "best_bid": "0.04", "best_ask": "0.13"}, {"asset_id": "79006550760303579457645886672312299229061887535391288753983510221472432105358", "price": "0.96", "size": "6.95", "side": "SELL", "hash": "8ccbc513abdd3da5aa24bda729d9cff9e1f779d9", "best_bid": "0.87", "best_ask": "0.96"}], "timestamp": "1769384014332", "event_type": "price_change"}}
{"_local_timestamp": "2026-01-25T23:33:34.405407+00:00", "data": {"market": "0xf8669cc099ad4008ee1735ae5ac1eb80ae005b249055d17df33fb086bcdfe83d", "price_changes": [{"asset_id": "67480800071998288404809609572612598087778955841531703375023453126691719294061", "price": "0.007", "size": "49.09", "side": "BUY", "hash": "ffb76d081819ade16116555cb07007cf522d95b2", "best_bid": "0.012", "best_ask": "0.122"}, {"asset_id": "74412093647819275524093734803851724407441381744350956613925261842560119775884", "price": "0.993", "size": "49.09", "side": "SELL", "hash": "8da2dfc0f97dcb618883295717409cb39b446699", "best_bid": "0.878", "best_ask": "0.988"}], "timestamp": "1769384014332", "event_type": "price_change"}}
{"_local_timestamp": "2026-01-25T23:33:37.188179+00:00", "data": {"market": "0xf8669cc099ad4008ee1735ae5ac1eb80ae005b249055d17df33fb086bcdfe83d", "price_changes": [{"asset_id": "67480800071998288404809609572612598087778955841531703375023453126691719294061", "price": "0.007", "size": "41.11", "side": "BUY", "hash": "bacc351171d807bc0cd9ad7382c0422a82b4e24b", "best_bid": "0.012", "best_ask": "0.122"}, {"asset_id": "74412093647819275524093734803851724407441381744350956613925261842560119775884", "price": "0.993", "size": "41.11", "side": "SELL", "hash": "fffb313986b1c8fb00b784a174794c6877d840f5", "best_bid": "0.878", "best_ask": "0.988"}], "timestamp": "1769384017115", "event_type": "price_change"}}
{"_local_timestamp": "2026-01-25T23:33:37.188732+00:00", "data": {"market": "0xf20f7af3ea74b16d623af198d6efb27d9d4ee98cfa96b1b6c8d4021d55436eb0", "price_changes": [{"asset_id": "8204205703682240679449476083075054464313606926136751077466819525464621562665", "price": "0.04", "size": "0", "side": "BUY", "hash": "04ba70b3659e72ab3d86a81a519718fdab06ad02", "best_bid": "0.03", "best_ask": "0.13"}, {"asset_id": "79006550760303579457645886672312299229061887535391288753983510221472432105358", "price": "0.96", "size": "0", "side": "SELL", "hash": "8dda116de5cbc3987eac8c42ce4630d029b08a6c", "best_bid": "0.87", "best_ask": "0.97"}], "timestamp": "1769384017115", "event_type": "price_change"}}
{"_local_timestamp": "2026-01-25T23:33:37.189106+00:00", "data": {"market": "0x0ba39007f4ff1c2677f296b90188d544c2f80f9729c76a6f181a191543ceab82", "price_changes": [{"asset_id": "35279195552426720847132209025903300157513105064872410280291719894882972533678", "price": "0.001", "size": "4572.49", "side": "BUY", "hash": "f7ddcc2e14cf1ffd1cd81f585688b5969d923e8e", "best_bid": "0.005", "best_ask": "0.191"}, {"asset_id": "35783470881309485643248466709434569842971080886588261160663378071872348072260", "price": "0.999", "size": "4572.49", "side": "SELL", "hash": "8954b339a0b743214051b3bf41ca082c6bff6edb", "best_bid": "0.809", "best_ask": "0.995"}], "timestamp": "1769384017115", "event_type": "price_change"}}
{"_local_timestamp": "2026-01-25T23:33:37.479164+00:00", "data": {"market": "0xf20f7af3ea74b16d623af198d6efb27d9d4ee98cfa96b1b6c8d4021d55436eb0", "price_changes": [{"asset_id": "8204205703682240679449476083075054464313606926136751077466819525464621562665", "price": "0.03", "size": "21.5", "side": "BUY", "hash": "5b52a117766d497b10e6fa657a7b11d3cde7aa34", "best_bid": "0.03", "best_ask": "0.13"}, {"asset_id": "79006550760303579457645886672312299229061887535391288753983510221472432105358", "price": "0.97", "size": "21.5", "side": "SELL", "hash": "6ee7c3790c934833f0eb21a2df46d3d44b3038d5", "best_bid": "0.87", "best_ask": "0.97"}], "timestamp": "1769384017380", "event_type": "price_change"}}
{"_local_timestamp": "2026-01-25T23:33:37.481388+00:00", "data": {"market": "0x0ba39007f4ff1c2677f296b90188d544c2f80f9729c76a6f181a191543ceab82", "price_changes": [{"asset_id": "35279195552426720847132209025903300157513105064872410280291719894882972533678", "price": "0.001", "size": "4665.09", "side": "BUY", "hash": "fae1d29ead0a0cd598673d732b7c89ca21b795cf", "best_bid": "0.005", "best_ask": "0.191"}, {"asset_id": "35783470881309485643248466709434569842971080886588261160663378071872348072260", "price": "0.999", "size": "4665.09", "side": "SELL", "hash": "620f7f6664d5e1b3952aa295638d7a4a704c7d12", "best_bid": "0.809", "best_ask": "0.995"}], "timestamp": "1769384017380", "event_type": "price_change"}}
{"_local_timestamp": "2026-01-25T23:33:37.482648+00:00", "data": {"market": "0xf8669cc099ad4008ee1735ae5ac1eb80ae005b249055d17df33fb086bcdfe83d", "price_changes": [{"asset_id": "67480800071998288404809609572612598087778955841531703375023453126691719294061", "price": "0.007", "size": "49.09", "side": "BUY", "hash": "113f2801a257a582d107625b5d2b3b5030da021a", "best_bid": "0.012", "best_ask": "0.122"}, {"asset_id": "74412093647819275524093734803851724407441381744350956613925261842560119775884", "price": "0.993", "size": "49.09", "side": "SELL", "hash": "a7e59aa0b765c4a3bc80b7a8d36c569c0cb14fba", "best_bid": "0.878", "best_ask": "0.988"}], "timestamp": "1769384017381", "event_type": "price_change"}}
{"_local_timestamp": "2026-01-25T23:33:38.378720+00:00", "data": {"market": "0xf20f7af3ea74b16d623af198d6efb27d9d4ee98cfa96b1b6c8d4021d55436eb0", "price_changes": [{"asset_id": "8204205703682240679449476083075054464313606926136751077466819525464621562665", "price": "0.03", "size": "12.23", "side": "BUY", "hash": "ca2dd2fcb697587d96e88962b24128d13768ea72", "best_bid": "0.03", "best_ask": "0.13"}, {"asset_id": "79006550760303579457645886672312299229061887535391288753983510221472432105358", "price": "0.97", "size": "12.23", "side": "SELL", "hash": "537828c5103c812e42dcf20245c66cd9c93113b2", "best_bid": "0.87", "best_ask": "0.97"}], "timestamp": "1769384018303", "event_type": "price_change"}}
{"_local_timestamp": "2026-01-25T23:33:38.379563+00:00", "data": {"market": "0xf8669cc099ad4008ee1735ae5ac1eb80ae005b249055d17df33fb086bcdfe83d", "price_changes": [{"asset_id": "67480800071998288404809609572612598087778955841531703375023453126691719294061", "price": "0.007", "size": "41.11", "side": "BUY", "hash": "f145c6ac833499339c6253a9bf670807f068b162", "best_bid": "0.012", "best_ask": "0.122"}, {"asset_id": "74412093647819275524093734803851724407441381744350956613925261842560119775884", "price": "0.993", "size": "41.11", "side": "SELL", "hash": "a31692b59a6c9abe6d414b4966917b8cfba93fd5", "best_bid": "0.878", "best_ask": "0.988"}], "timestamp": "1769384018303", "event_type": "price_change"}}
{"_local_timestamp": "2026-01-25T23:33:38.592549+00:00", "data": {"market": "0xf8669cc099ad4008ee1735ae5ac1eb80ae005b249055d17df33fb086bcdfe83d", "price_changes": [{"asset_id": "67480800071998288404809609572612598087778955841531703375023453126691719294061", "price": "0.007", "size": "49.09", "side": "BUY", "hash": "0b4c46587951f812abb4f18aa718412891277a68", "best_bid": "0.012", "best_ask": "0.122"}, {"asset_id": "74412093647819275524093734803851724407441381744350956613925261842560119775884", "price": "0.993", "size": "49.09", "side": "SELL", "hash": "8744f4d58bb10208c027e6662fbdded35423bab2", "best_bid": "0.878", "best_ask": "0.988"}], "timestamp": "1769384018521", "event_type": "price_change"}}
{"_local_timestamp": "2026-01-25T23:33:38.593231+00:00", "data": {"market": "0xf20f7af3ea74b16d623af198d6efb27d9d4ee98cfa96b1b6c8d4021d55436eb0", "price_changes": [{"asset_id": "8204205703682240679449476083075054464313606926136751077466819525464621562665", "price": "0.03", "size": "21.5", "side": "BUY", "hash": "4f938c3398f9fff747af2f32317876e713ff551b", "best_bid": "0.03", "best_ask": "0.13"}, {"asset_id": "79006550760303579457645886672312299229061887535391288753983510221472432105358", "price": "0.97", "size": "21.5", "side": "SELL", "hash": "9314bb3965c6b58f3e7e3de5aa0d7fe789ffc528", "best_bid": "0.87", "best_ask": "0.97"}], "timestamp": "1769384018522", "event_type": "price_change"}}
{"_local_timestamp": "2026-01-25T23:33:40.440584+00:00", "data": {"market": "0xf20f7af3ea74b16d623af198d6efb27d9d4ee98cfa96b1b6c8d4021d55436eb0", "price_changes": [{"asset_id": "8204205703682240679449476083075054464313606926136751077466819525464621562665", "price": "0.03", "size": "12.23", "side": "BUY", "hash": "a140a1a13833e2253645cd093531110fdd41be08", "best_bid": "0.03", "best_ask": "0.13"}, {"asset_id": "79006550760303579457645886672312299229061887535391288753983510221472432105358", "price": "0.97", "size": "12.23", "side": "SELL", "hash": "2a328c5910133b313661948a25284069bdfed5d0", "best_bid": "0.87", "best_ask": "0.97"}], "timestamp": "1769384020311", "event_type": "price_change"}}
{"_local_timestamp": "2026-01-25T23:33:40.441821+00:00", "data": {"market": "0xf8669cc099ad4008ee1735ae5ac1eb80ae005b249055d17df33fb086bcdfe83d", "price_changes": [{"asset_id": "67480800071998288404809609572612598087778955841531703375023453126691719294061", "price": "0.007", "size": "41.11", "side": "BUY", "hash": "27ba9c54f74d09a2357318dd64b8210a29df792b", "best_bid": "0.012", "best_ask": "0.122"}, {"asset_id": "74412093647819275524093734803851724407441381744350956613925261842560119775884", "price": "0.993", "size": "41.11", "side": "SELL", "hash": "e41faf6db3c74e77dbf7dbeeab22aaddea340821", "best_bid": "0.878", "best_ask": "0.988"}], "timestamp": "1769384020311", "event_type": "price_change"}}
{"_local_timestamp": "2026-01-25T23:33:40.553079+00:00", "data": {"market": "0xf8669cc099ad4008ee1735ae5ac1eb80ae005b249055d17df33fb086bcdfe83d", "price_changes": [{"asset_id": "67480800071998288404809609572612598087778955841531703375023453126691719294061", "price": "0.008", "size": "13.25", "side": "BUY", "hash": "9a2871c883af5f53686734d179580d24b18a073d", "best_bid": "0.012", "best_ask": "0.122"}, {"asset_id": "74412093647819275524093734803851724407441381744350956613925261842560119775884", "price": "0.992", "size": "13.25", "side": "SELL", "hash": "498ae9ffbf11b30b27d31debceb12a6f33b6f04a", "best_bid": "0.878", "best_ask": "0.988"}], "timestamp": "1769384020487", "event_type": "price_change"}}
{"_local_timestamp": "2026-01-25T23:33:40.857680+00:00", "data": {"market": "0xf20f7af3ea74b16d623af198d6efb27d9d4ee98cfa96b1b6c8d4021d55436eb0", "price_changes": [{"asset_id": "8204205703682240679449476083075054464313606926136751077466819525464621562665", "price": "0.03", "size": "21.5", "side": "BUY", "hash": "1a1c45e278da5726f871718a0670e5c1a823a45f", "best_bid": "0.03", "best_ask": "0.13"}, {"asset_id": "79006550760303579457645886672312299229061887535391288753983510221472432105358", "price": "0.97", "size": "21.5", "side": "SELL", "hash": "b431327b311f206a598b85d534d1f76ee7430640", "best_bid": "0.87", "best_ask": "0.97"}], "timestamp": "1769384020606", "event_type": "price_change"}}
{"_local_timestamp": "2026-01-25T23:33:41.969823+00:00", "data": {"market": "0x3906ccd196f47f9cd177602071c3147a4b916ab60b1e317d5439c54fb520187d", "price_changes": [{"asset_id": "62082789175342153765549566755525855471250020053983528793359435486631209756539", "price": "0.003", "size": "59.87", "side": "BUY", "hash": "15cfd77187f866586259ce257a2148b9e97eaf7d", "best_bid": "0.013", "best_ask": "0.109"}, {"asset_id": "66628303295255675472790623870237847302694414310186008738086927666525449327926", "price": "0.997", "size": "59.87", "side": "SELL", "hash": "67852e4f4b9f72b44e95c2c8ab4f89520dd60635", "best_bid": "0.891", "best_ask": "0.987"}], "timestamp": "1769384021894", "event_type": "price_change"}}
{"_local_timestamp": "2026-01-25T23:33:42.211585+00:00", "data": {"market": "0x3906ccd196f47f9cd177602071c3147a4b916ab60b1e317d5439c54fb520187d", "price_changes": [{"asset_id": "62082789175342153765549566755525855471250020053983528793359435486631209756539", "price": "0.003", "size": "104.01", "side": "BUY", "hash": "c26f32816f84eb7bf4ac808a9a22ea3a2a3fd91b", "best_bid": "0.013", "best_ask": "0.109"}, {"asset_id": "66628303295255675472790623870237847302694414310186008738086927666525449327926", "price": "0.997", "size": "104.01", "side": "SELL", "hash": "aeef280b7d6d585974011947d80fb1dcf0fa5bb1", "best_bid": "0.891", "best_ask": "0.987"}], "timestamp": "1769384022148", "event_type": "price_change"}}
{"_local_timestamp": "2026-01-25T23:33:42.837775+00:00", "data": {"market": "0xf20f7af3ea74b16d623af198d6efb27d9d4ee98cfa96b1b6c8d4021d55436eb0", "price_changes": [{"asset_id": "8204205703682240679449476083075054464313606926136751077466819525464621562665", "price": "0.03", "size": "12.23", "side": "BUY", "hash": "66393418b4bf80e723882173dfefc6aec819f910", "best_bid": "0.03", "best_ask": "0.13"}, {"asset_id": "79006550760303579457645886672312299229061887535391288753983510221472432105358", "price": "0.97", "size": "12.23", "side": "SELL", "hash": "426e33d2009270244bfb4121cb06cf580321e8a2", "best_bid": "0.87", "best_ask": "0.97"}], "timestamp": "1769384022775", "event_type": "price_change"}}
{"_local_timestamp": "2026-01-25T23:33:42.838613+00:00", "data": {"market": "0xf8669cc099ad4008ee1735ae5ac1eb80ae005b249055d17df33fb086bcdfe83d", "price_changes": [{"asset_id": "67480800071998288404809609572612598087778955841531703375023453126691719294061", "price": "0.008", "size": "6.26", "side": "BUY", "hash": "94734a10ee9e3507eaf1478761a1da6087977b7c", "best_bid": "0.012", "best_ask": "0.122"}, {"asset_id": "74412093647819275524093734803851724407441381744350956613925261842560119775884", "price": "0.992", "size": "6.26", "side": "SELL", "hash": "9184bfa47ccec81105be823386d3dc44a07e679e", "best_bid": "0.878", "best_ask": "0.988"}], "timestamp": "1769384022775", "event_type": "price_change"}}
{"_local_timestamp": "2026-01-25T23:33:43.231588+00:00", "data": {"market": "0xf20f7af3ea74b16d623af198d6efb27d9d4ee98cfa96b1b6c8d4021d55436eb0", "price_changes": [{"asset_id": "8204205703682240679449476083075054464313606926136751077466819525464621562665", "price": "0.03", "size": "21.5", "side": "BUY", "hash": "1d3303b1ff45d29b5702204f5518dad14dd46190", "best_bid": "0.03", "best_ask": "0.13"}, {"asset_id": "79006550760303579457645886672312299229061887535391288753983510221472432105358", "price": "0.97", "size": "21.5", "side": "SELL", "hash": "47afaa52b380e56ef71f43265ac58bd3f81be0e6", "best_bid": "0.87", "best_ask": "0.97"}], "timestamp": "1769384023166", "event_type": "price_change"}}
{"_local_timestamp": "2026-01-25T23:33:43.233901+00:00", "data": {"market": "0xf8669cc099ad4008ee1735ae5ac1eb80ae005b249055d17df33fb086bcdfe83d", "price_changes": [{"asset_id": "67480800071998288404809609572612598087778955841531703375023453126691719294061", "price": "0.007", "size": "49.09", "side": "BUY", "hash": "fa7345d6aedb9a2af9a8c918c36b4971cde9e072", "best_bid": "0.012", "best_ask": "0.122"}, {"asset_id": "74412093647819275524093734803851724407441381744350956613925261842560119775884", "price": "0.993", "size": "49.09", "side": "SELL", "hash": "e0f11d6da5fcb5084cabf5184c9dd23ce98c4e9e", "best_bid": "0.878", "best_ask": "0.988"}], "timestamp": "1769384023166", "event_type": "price_change"}}
{"_local_timestamp": "2026-01-25T23:33:45.770972+00:00", "data": {"market": "0xf8669cc099ad4008ee1735ae5ac1eb80ae005b249055d17df33fb086bcdfe83d", "price_changes": [{"asset_id": "67480800071998288404809609572612598087778955841531703375023453126691719294061", "price": "0.007", "size": "41.11", "side": "BUY", "hash": "5ddc7600d9443b06cf23067c77813a96de2ddcdb", "best_bid": "0.012", "best_ask": "0.122"}, {"asset_id": "74412093647819275524093734803851724407441381744350956613925261842560119775884", "price": "0.993", "size": "41.11", "side": "SELL", "hash": "06558afa653634c4df75d52d64f93f66f57d5574", "best_bid": "0.878", "best_ask": "0.988"}], "timestamp": "1769384025703", "event_type": "price_change"}}
{"_local_timestamp": "2026-01-25T23:33:45.978860+00:00", "data": {"market": "0xf8669cc099ad4008ee1735ae5ac1eb80ae005b249055d17df33fb086bcdfe83d", "price_changes": [{"asset_id": "67480800071998288404809609572612598087778955841531703375023453126691719294061", "price": "0.007", "size": "49.09", "side": "BUY", "hash": "375d10a7ce02aa69b899abedaab9d06232bad435", "best_bid": "0.012", "best_ask": "0.122"}, {"asset_id": "74412093647819275524093734803851724407441381744350956613925261842560119775884", "price": "0.993", "size": "49.09", "side": "SELL", "hash": "20a61dec02034029d496e091f2593528e6d26ca8", "best_bid": "0.878", "best_ask": "0.988"}], "timestamp": "1769384025905", "event_type": "price_change"}}
{"_local_timestamp": "2026-01-25T23:33:46.218713+00:00", "data": {"market": "0xf20f7af3ea74b16d623af198d6efb27d9d4ee98cfa96b1b6c8d4021d55436eb0", "price_changes": [{"asset_id": "79006550760303579457645886672312299229061887535391288753983510221472432105358", "price": "0.36", "size": "0", "side": "BUY", "hash": "977ca727b5a2e1995c6c92dd31a8c8d161aac0a6", "best_bid": "0.87", "best_ask": "0.97"}, {"asset_id": "8204205703682240679449476083075054464313606926136751077466819525464621562665", "price": "0.64", "size": "0", "side": "SELL", "hash": "e22f7a6220c9a9c77bfc9b7e4a518313fb1aff30", "best_bid": "0.03", "best_ask": "0.13"}], "timestamp": "1769384026153", "event_type": "price_change"}}
{"_local_timestamp": "2026-01-25T23:33:46.229334+00:00", "data": {"market": "0xf20f7af3ea74b16d623af198d6efb27d9d4ee98cfa96b1b6c8d4021d55436eb0", "price_changes": [{"asset_id": "8204205703682240679449476083075054464313606926136751077466819525464621562665", "price": "0.03", "size": "12.23", "side": "BUY", "hash": "3fa2e989664bf5411d1eb8388d10b8a51425b637", "best_bid": "0.03", "best_ask": "0.13"}, {"asset_id": "79006550760303579457645886672312299229061887535391288753983510221472432105358", "price": "0.97", "size": "12.23", "side": "SELL", "hash": "e0abc2ad6130197500d2ac7a554ae46422122f3d", "best_bid": "0.87", "best_ask": "0.97"}], "timestamp": "1769384026153", "event_type": "price_change"}}
{"_local_timestamp": "2026-01-25T23:33:46.409860+00:00", "data": {"market": "0xf20f7af3ea74b16d623af198d6efb27d9d4ee98cfa96b1b6c8d4021d55436eb0", "price_changes": [{"asset_id": "79006550760303579457645886672312299229061887535391288753983510221472432105358", "price": "0.36", "size": "5", "side": "BUY", "hash": "cc9b5f695d5946403a1c4363af823788406bc2ad", "best_bid": "0.87", "best_ask": "0.97"}, {"asset_id": "8204205703682240679449476083075054464313606926136751077466819525464621562665", "price": "0.64", "size": "5", "side": "SELL", "hash": "5c59f68d39295171e2df0fbe0c99f1629c56b60b", "best_bid": "0.03", "best_ask": "0.13"}], "timestamp": "1769384026336", "event_type": "price_change"}}
{"_local_timestamp": "2026-01-25T23:33:46.665397+00:00", "data": {"market": "0xf20f7af3ea74b16d623af198d6efb27d9d4ee98cfa96b1b6c8d4021d55436eb0", "price_changes": [{"asset_id": "8204205703682240679449476083075054464313606926136751077466819525464621562665", "price": "0.03", "size": "21.5", "side": "BUY", "hash": "1a49425471966dacb6c7909d8db058c33a70ba3d", "best_bid": "0.03", "best_ask": "0.13"}, {"asset_id": "79006550760303579457645886672312299229061887535391288753983510221472432105358", "price": "0.97", "size": "21.5", "side": "SELL", "hash": "48d91f53e8e9096a8a5ecb01408f41c755e10ef4", "best_bid": "0.87", "best_ask": "0.97"}], "timestamp": "1769384026601", "event_type": "price_change"}}
{"_local_timestamp": "2026-01-25T23:33:48.412227+00:00", "data": {"market": "0xf8669cc099ad4008ee1735ae5ac1eb80ae005b249055d17df33fb086bcdfe83d", "price_changes": [{"asset_id": "67480800071998288404809609572612598087778955841531703375023453126691719294061", "price": "0.007", "size": "41.11", "side": "BUY", "hash": "343b8026b797dba9c0f75c07dd76eac5b8a98a09", "best_bid": "0.012", "best_ask": "0.122"}, {"asset_id": "74412093647819275524093734803851724407441381744350956613925261842560119775884", "price": "0.993", "size": "41.11", "side": "SELL", "hash": "fcb00efa0fb2a917ea47a8d4fc0fff7f268c7b02", "best_bid": "0.878", "best_ask": "0.988"}], "timestamp": "1769384028346", "event_type": "price_change"}}
{"_local_timestamp": "2026-01-25T23:33:48.412983+00:00", "data": {"market": "0xf20f7af3ea74b16d623af198d6efb27d9d4ee98cfa96b1b6c8d4021d55436eb0", "price_changes": [{"asset_id": "8204205703682240679449476083075054464313606926136751077466819525464621562665", "price": "0.03", "size": "12.23", "side": "BUY", "hash": "3b02300bb6ce6156db9c17fdc239b41ecc2cdd0f", "best_bid": "0.03", "best_ask": "0.13"}, {"asset_id": "79006550760303579457645886672312299229061887535391288753983510221472432105358", "price": "0.97", "size": "12.23", "side": "SELL", "hash": "18fe408fdc29d33ad1f851f7ef60856f63108607", "best_bid": "0.87", "best_ask": "0.97"}], "timestamp": "1769384028346", "event_type": "price_change"}}
{"_local_timestamp": "2026-01-25T23:33:48.694791+00:00", "data": {"market": "0xf20f7af3ea74b16d623af198d6efb27d9d4ee98cfa96b1b6c8d4021d55436eb0", "price_changes": [{"asset_id": "8204205703682240679449476083075054464313606926136751077466819525464621562665", "price": "0.03", "size": "21.5", "side": "BUY", "hash": "715322903007c26fa484bb3fe3e34b70bd612c9e", "best_bid": "0.03", "best_ask": "0.13"}, {"asset_id": "79006550760303579457645886672312299229061887535391288753983510221472432105358", "price": "0.97", "size": "21.5", "side": "SELL", "hash": "abd314e44afb90b04c29c2e8f6642eb27622cd86", "best_bid": "0.87", "best_ask": "0.97"}], "timestamp": "1769384028628", "event_type": "price_change"}}
{"_local_timestamp": "2026-01-25T23:33:48.696880+00:00", "data": {"market": "0xf8669cc099ad4008ee1735ae5ac1eb80ae005b249055d17df33fb086bcdfe83d", "price_changes": [{"asset_id": "67480800071998288404809609572612598087778955841531703375023453126691719294061", "price": "0.007", "size": "49.09", "side": "BUY", "hash": "9676f3f5103a68488f65a6d52241bd6820a0abab", "best_bid": "0.012", "best_ask": "0.122"}, {"asset_id": "74412093647819275524093734803851724407441381744350956613925261842560119775884", "price": "0.993", "size": "49.09", "side": "SELL", "hash": "3baa222d8538c9ffcfb1f55762a44efbb897b4d6", "best_bid": "0.878", "best_ask": "0.988"}], "timestamp": "1769384028628", "event_type": "price_change"}}
{"_local_timestamp": "2026-01-25T23:33:53.017908+00:00", "data": {"market": "0xf20f7af3ea74b16d623af198d6efb27d9d4ee98cfa96b1b6c8d4021d55436eb0", "price_changes": [{"asset_id": "8204205703682240679449476083075054464313606926136751077466819525464621562665", "price": "0.03", "size": "12.23", "side": "BUY", "hash": "5dbaa043758c6222c2e326c118c4cbb30c882dfb", "best_bid": "0.03", "best_ask": "0.13"}, {"asset_id": "79006550760303579457645886672312299229061887535391288753983510221472432105358", "price": "0.97", "size": "12.23", "side": "SELL", "hash": "92dd5b49c21ef67e8f2c9c510518a99c7ba839ba", "best_bid": "0.87", "best_ask": "0.97"}], "timestamp": "1769384032950", "event_type": "price_change"}}
{"_local_timestamp": "2026-01-25T23:33:53.018810+00:00", "data": {"market": "0xf8669cc099ad4008ee1735ae5ac1eb80ae005b249055d17df33fb086bcdfe83d", "price_changes": [{"asset_id": "67480800071998288404809609572612598087778955841531703375023453126691719294061", "price": "0.007", "size": "41.11", "side": "BUY", "hash": "dbdfba885737dea71aa5559172fad184908a4bfc", "best_bid": "0.012", "best_ask": "0.122"}, {"asset_id": "74412093647819275524093734803851724407441381744350956613925261842560119775884", "price": "0.993", "size": "41.11", "side": "SELL", "hash": "0317ed7400ca26c2bec926b2d9fa51dfd56dee6b", "best_bid": "0.878", "best_ask": "0.988"}], "timestamp": "1769384032950", "event_type": "price_change"}}
{"_local_timestamp": "2026-01-25T23:33:53.195830+00:00", "data": {"market": "0xf8669cc099ad4008ee1735ae5ac1eb80ae005b249055d17df33fb086bcdfe83d", "price_changes": [{"asset_id": "67480800071998288404809609572612598087778955841531703375023453126691719294061", "price": "0.007", "size": "49.09", "side": "BUY", "hash": "cad8ab7ff3dfee83ef1f755f101a7d017f9755ae", "best_bid": "0.012", "best_ask": "0.122"}, {"asset_id": "74412093647819275524093734803851724407441381744350956613925261842560119775884", "price": "0.993", "size": "49.09", "side": "SELL", "hash": "67fa436ab4f4ea713259eea04c8e2465df8d731a", "best_bid": "0.878", "best_ask": "0.988"}], "timestamp": "1769384033128", "event_type": "price_change"}}
{"_local_timestamp": "2026-01-25T23:33:53.431722+00:00", "data": {"market": "0xf20f7af3ea74b16d623af198d6efb27d9d4ee98cfa96b1b6c8d4021d55436eb0", "price_changes": [{"asset_id": "8204205703682240679449476083075054464313606926136751077466819525464621562665", "price": "0.03", "size": "21.5", "side": "BUY", "hash": "aaa3230e4d3bcca06d87f129a1d06a515db11718", "best_bid": "0.03", "best_ask": "0.13"}, {"asset_id": "79006550760303579457645886672312299229061887535391288753983510221472432105358", "price": "0.97", "size": "21.5", "side": "SELL", "hash": "2a0fae4ca18e48ef3ea5ae0520e5776849801d93", "best_bid": "0.87", "best_ask": "0.97"}], "timestamp": "1769384033366", "event_type": "price_change"}}
{"_local_timestamp": "2026-01-25T23:33:54.830746+00:00", "data": {"market": "0xf20f7af3ea74b16d623af198d6efb27d9d4ee98cfa96b1b6c8d4021d55436eb0", "price_changes": [{"asset_id": "8204205703682240679449476083075054464313606926136751077466819525464621562665", "price": "0.03", "size": "12.23", "side": "BUY", "hash": "866337b9e2294714c8cf82db5a256e8d93bc90b1", "best_bid": "0.03", "best_ask": "0.13"}, {"asset_id": "79006550760303579457645886672312299229061887535391288753983510221472432105358", "price": "0.97", "size": "12.23", "side": "SELL", "hash": "6d52def9c83fc541d4657a78c842bfccbba13305", "best_bid": "0.87", "best_ask": "0.97"}], "timestamp": "1769384034760", "event_type": "price_change"}}
{"_local_timestamp": "2026-01-25T23:33:54.831582+00:00", "data": {"market": "0xf8669cc099ad4008ee1735ae5ac1eb80ae005b249055d17df33fb086bcdfe83d", "price_changes": [{"asset_id": "67480800071998288404809609572612598087778955841531703375023453126691719294061", "price": "0.007", "size": "41.11", "side": "BUY", "hash": "55d60f9f7ed899fa71ce34496b14be6f4ab8ed8c", "best_bid": "0.012", "best_ask": "0.122"}, {"asset_id": "74412093647819275524093734803851724407441381744350956613925261842560119775884", "price": "0.993", "size": "41.11", "side": "SELL", "hash": "50ddf59d41a332464c763151d9430b4575f4183e", "best_bid": "0.878", "best_ask": "0.988"}], "timestamp": "1769384034760", "event_type": "price_change"}}
{"_local_timestamp": "2026-01-25T23:33:55.129047+00:00", "data": {"market": "0xf20f7af3ea74b16d623af198d6efb27d9d4ee98cfa96b1b6c8d4021d55436eb0", "price_changes": [{"asset_id": "8204205703682240679449476083075054464313606926136751077466819525464621562665", "price": "0.03", "size": "21.5", "side": "BUY", "hash": "f0c525923f5d30419fcb060a8b1b78c92d36dffd", "best_bid": "0.03", "best_ask": "0.13"}, {"asset_id": "79006550760303579457645886672312299229061887535391288753983510221472432105358", "price": "0.97", "size": "21.5", "side": "SELL", "hash": "9961297969a158f839385124225014160e555c5d", "best_bid": "0.87", "best_ask": "0.97"}], "timestamp": "1769384035029", "event_type": "price_change"}}
{"_local_timestamp": "2026-01-25T23:33:55.131077+00:00", "data": {"market": "0xf8669cc099ad4008ee1735ae5ac1eb80ae005b249055d17df33fb086bcdfe83d", "price_changes": [{"asset_id": "67480800071998288404809609572612598087778955841531703375023453126691719294061", "price": "0.007", "size": "49.09", "side": "BUY", "hash": "6bde9746a482120a68edf3aeb22d81396296faef", "best_bid": "0.012", "best_ask": "0.122"}, {"asset_id": "74412093647819275524093734803851724407441381744350956613925261842560119775884", "price": "0.993", "size": "49.09", "side": "SELL", "hash": "3c47f2629cafaf6e1598ebf4989eb5a1dccee67f", "best_bid": "0.878", "best_ask": "0.988"}], "timestamp": "1769384035029", "event_type": "price_change"}}
{"_local_timestamp": "2026-01-25T23:33:55.498410+00:00", "data": {"market": "0x32b7aab78f0be7156c9b8c4f28226b8f676629b3b836369a88750835204d5584", "price_changes": [{"asset_id": "99190743562209447358094560183285732023690283653912147802428483334474879764706", "price": "0.05", "size": "250", "side": "BUY", "hash": "f40e25a024ae7e97927c4896025e870255e52442", "best_bid": "0.07", "best_ask": "0.15"}, {"asset_id": "99758775731194955694634878830719976118374917540431552182533993870186584882882", "price": "0.95", "size": "250", "side": "SELL", "hash": "07d8a806feb2de131e6be2f33ce85471cefdec85", "best_bid": "0.85", "best_ask": "0.93"}], "timestamp": "1769384035420", "event_type": "price_change"}}
{"_local_timestamp": "2026-01-25T23:33:55.500720+00:00", "data": {"market": "0x32b7aab78f0be7156c9b8c4f28226b8f676629b3b836369a88750835204d5584", "price_changes": [{"asset_id": "99190743562209447358094560183285732023690283653912147802428483334474879764706", "price": "0.06", "size": "317.11", "side": "BUY", "hash": "f5d62f501dbf2f1f9c7cbe7d83dca662262049ac", "best_bid": "0.07", "best_ask": "0.15"}, {"asset_id": "99758775731194955694634878830719976118374917540431552182533993870186584882882", "price": "0.94", "size": "317.11", "side": "SELL", "hash": "c275b919ccd65cc580e0cad83c8c496fb8849b21", "best_bid": "0.85", "best_ask": "0.93"}], "timestamp": "1769384035428", "event_type": "price_change"}}
{"_local_timestamp": "2026-01-25T23:33:58.618288+00:00", "data": {"market": "0xf8669cc099ad4008ee1735ae5ac1eb80ae005b249055d17df33fb086bcdfe83d", "price_changes": [{"asset_id": "67480800071998288404809609572612598087778955841531703375023453126691719294061", "price": "0.007", "size": "41.11", "side": "BUY", "hash": "db630bbba3070d97b8cb2be4871ce72cd4269a0d", "best_bid": "0.012", "best_ask": "0.122"}, {"asset_id": "74412093647819275524093734803851724407441381744350956613925261842560119775884", "price": "0.993", "size": "41.11", "side": "SELL", "hash": "14392e884f2a96ac4a87f3be098dc42aec108ea0", "best_bid": "0.878", "best_ask": "0.988"}], "timestamp": "1769384038547", "event_type": "price_change"}}
{"_local_timestamp": "2026-01-25T23:33:58.867028+00:00", "data": {"market": "0xf8669cc099ad4008ee1735ae5ac1eb80ae005b249055d17df33fb086bcdfe83d", "price_changes": [{"asset_id": "67480800071998288404809609572612598087778955841531703375023453126691719294061", "price": "0.007", "size": "49.09", "side": "BUY", "hash": "fc13d8cefe759a8b8ce18c3552f008cca5b8e12c", "best_bid": "0.012", "best_ask": "0.122"}, {"asset_id": "74412093647819275524093734803851724407441381744350956613925261842560119775884", "price": "0.993", "size": "49.09", "side": "SELL", "hash": "4c6af06515ed32125f9589be7b778b3b4b64f1aa", "best_bid": "0.878", "best_ask": "0.988"}], "timestamp": "1769384038799", "event_type": "price_change"}}
{"_local_timestamp": "2026-01-25T23:33:59.066489+00:00", "data": {"market": "0xf20f7af3ea74b16d623af198d6efb27d9d4ee98cfa96b1b6c8d4021d55436eb0", "price_changes": [{"asset_id": "8204205703682240679449476083075054464313606926136751077466819525464621562665", "price": "0.03", "size": "12.23", "side": "BUY", "hash": "d9a5ab0506fffbbd59895e6d9482022476238f81", "best_bid": "0.03", "best_ask": "0.13"}, {"asset_id": "79006550760303579457645886672312299229061887535391288753983510221472432105358", "price": "0.97", "size": "12.23", "side": "SELL", "hash": "9249700f6ee5674cd8dd0dee8520bfcec7974c44", "best_bid": "0.87", "best_ask": "0.97"}], "timestamp": "1769384038989", "event_type": "price_change"}}
{"_local_timestamp": "2026-01-25T23:33:59.093872+00:00", "data": {"market": "0xfa4c453091f10ccab9fae67d8a2286e1bf1d9367596d1d5b74c36e4155e300af", "price_changes": [{"asset_id": "100280536155707901843387784334630754939243388352572806762203828618520844114191", "price": "0.001", "size": "4301.05", "side": "BUY", "hash": "85120c2d20a91dabd24e530cf4ca1523291db429", "best_bid": "0.994", "best_ask": "0.995"}, {"asset_id": "50903746416787079744189627434391589495562066033420184996159345764514807060721", "price": "0.999", "size": "4301.05", "side": "SELL", "hash": "35883116826284d651b81e5706bc405233670a91", "best_bid": "0.005", "best_ask": "0.006"}], "timestamp": "1769384038989", "event_type": "price_change"}}
{"_local_timestamp": "2026-01-25T23:33:59.096676+00:00", "data": {"market": "0xfa4c453091f10ccab9fae67d8a2286e1bf1d9367596d1d5b74c36e4155e300af", "price_changes": [{"asset_id": "100280536155707901843387784334630754939243388352572806762203828618520844114191", "price": "0.003", "size": "400", "side": "BUY", "hash": "85120c2d20a91dabd24e530cf4ca1523291db429", "best_bid": "0.994", "best_ask": "0.995"}, {"asset_id": "50903746416787079744189627434391589495562066033420184996159345764514807060721", "price": "0.997", "size": "400", "side": "SELL", "hash": "35883116826284d651b81e5706bc405233670a91", "best_bid": "0.005", "best_ask": "0.006"}], "timestamp": "1769384038989", "event_type": "price_change"}}
{"_local_timestamp": "2026-01-25T23:33:59.097511+00:00", "data": {"market": "0xfa4c453091f10ccab9fae67d8a2286e1bf1d9367596d1d5b74c36e4155e300af", "price_changes": [{"asset_id": "100280536155707901843387784334630754939243388352572806762203828618520844114191", "price": "0.007", "size": "0", "side": "BUY", "hash": "85120c2d20a91dabd24e530cf4ca1523291db429", "best_bid": "0.994", "best_ask": "0.995"}, {"asset_id": "50903746416787079744189627434391589495562066033420184996159345764514807060721", "price": "0.993", "size": "0", "side": "SELL", "hash": "35883116826284d651b81e5706bc405233670a91", "best_bid": "0.005", "best_ask": "0.006"}], "timestamp": "1769384038989", "event_type": "price_change"}}
{"_local_timestamp": "2026-01-25T23:33:59.099971+00:00", "data": {"market": "0xfa4c453091f10ccab9fae67d8a2286e1bf1d9367596d1d5b74c36e4155e300af", "price_changes": [{"asset_id": "100280536155707901843387784334630754939243388352572806762203828618520844114191", "price": "0.021", "size": "0", "side": "BUY", "hash": "85120c2d20a91dabd24e530cf4ca1523291db429", "best_bid": "0.994", "best_ask": "0.995"}, {"asset_id": "50903746416787079744189627434391589495562066033420184996159345764514807060721", "price": "0.979", "size": "0", "side": "SELL", "hash": "35883116826284d651b81e5706bc405233670a91", "best_bid": "0.005", "best_ask": "0.006"}], "timestamp": "1769384038989", "event_type": "price_change"}}
{"_local_timestamp": "2026-01-25T23:33:59.101286+00:00", "data": {"market": "0xfa4c453091f10ccab9fae67d8a2286e1bf1d9367596d1d5b74c36e4155e300af", "price_changes": [{"asset_id": "100280536155707901843387784334630754939243388352572806762203828618520844114191", "price": "0.071", "size": "0", "side": "BUY", "hash": "85120c2d20a91dabd24e530cf4ca1523291db429", "best_bid": "0.994", "best_ask": "0.995"}, {"asset_id": "50903746416787079744189627434391589495562066033420184996159345764514807060721", "price": "0.929", "size": "0", "side": "SELL", "hash": "35883116826284d651b81e5706bc405233670a91", "best_bid": "0.005", "best_ask": "0.006"}], "timestamp": "1769384038989", "event_type": "price_change"}}
{"_local_timestamp": "2026-01-25T23:33:59.330674+00:00", "data": {"market": "0xf20f7af3ea74b16d623af198d6efb27d9d4ee98cfa96b1b6c8d4021d55436eb0", "price_changes": [{"asset_id": "8204205703682240679449476083075054464313606926136751077466819525464621562665", "price": "0.03", "size": "21.5", "side": "BUY", "hash": "9b07ae79b74c035b0184ee0eedc520b30726f32d", "best_bid": "0.03", "best_ask": "0.13"}, {"asset_id": "79006550760303579457645886672312299229061887535391288753983510221472432105358", "price": "0.97", "size": "21.5", "side": "SELL", "hash": "60c249723d1936aafb190f21c54a459f89c13a39", "best_bid": "0.87", "best_ask": "0.97"}], "timestamp": "1769384039267", "event_type": "price_change"}}
{"_local_timestamp": "2026-01-25T23:33:59.331351+00:00", "data": {"market": "0xfa4c453091f10ccab9fae67d8a2286e1bf1d9367596d1d5b74c36e4155e300af", "price_changes": [{"asset_id": "100280536155707901843387784334630754939243388352572806762203828618520844114191", "price": "0.004", "size": "8.62", "side": "BUY", "hash": "595eab008dd4c01ae3a6539af871fdb0b9e1fa94", "best_bid": "0.994", "best_ask": "0.995"}, {"asset_id": "50903746416787079744189627434391589495562066033420184996159345764514807060721", "price": "0.996", "size": "8.62", "side": "SELL", "hash": "5c1cba653598d9e94128fa0c9c91beeafafdcfa5", "best_bid": "0.005", "best_ask": "0.006"}], "timestamp": "1769384039267", "event_type": "price_change"}}
{"_local_timestamp": "2026-01-25T23:33:59.333982+00:00", "data": {"market": "0xfa4c453091f10ccab9fae67d8a2286e1bf1d9367596d1d5b74c36e4155e300af", "price_changes": [{"asset_id": "100280536155707901843387784334630754939243388352572806762203828618520844114191", "price": "0.073", "size": "9.48", "side": "BUY", "hash": "f5a3c484809f415199b85e75b466e2ee3894cdfd", "best_bid": "0.994", "best_ask": "0.995"}, {"asset_id": "50903746416787079744189627434391589495562066033420184996159345764514807060721", "price": "0.927", "size": "9.48", "side": "SELL", "hash": "fa389685fbfdabb7008378c2e016b859f3355d77", "best_bid": "0.005", "best_ask": "0.006"}], "timestamp": "1769384039268", "event_type": "price_change"}}
{"_local_timestamp": "2026-01-25T23:33:59.335730+00:00", "data": {"market": "0xfa4c453091f10ccab9fae67d8a2286e1bf1d9367596d1d5b74c36e4155e300af", "price_changes": [{"asset_id": "100280536155707901843387784334630754939243388352572806762203828618520844114191", "price": "0.011", "size": "5.13", "side": "BUY", "hash": "c9e6d626092b83f7965da901dee2640788fd6c6a", "best_bid": "0.994", "best_ask": "0.995"}, {"asset_id": "50903746416787079744189627434391589495562066033420184996159345764514807060721", "price": "0.989", "size": "5.13", "side": "SELL", "hash": "109ee66783fffccc46465ba3a6603e682e702a72", "best_bid": "0.005", "best_ask": "0.006"}], "timestamp": "1769384039269", "event_type": "price_change"}}
{"_local_timestamp": "2026-01-25T23:33:59.339081+00:00", "data": {"market": "0xfa4c453091f10ccab9fae67d8a2286e1bf1d9367596d1d5b74c36e4155e300af", "price_changes": [{"asset_id": "100280536155707901843387784334630754939243388352572806762203828618520844114191", "price": "0.002", "size": "255.04", "side": "BUY", "hash": "c393cabc2f305bd9c1cbad45c728ce9132c2e8ce", "best_bid": "0.994", "best_ask": "0.995"}, {"asset_id": "50903746416787079744189627434391589495562066033420184996159345764514807060721", "price": "0.998", "size": "255.04", "side": "SELL", "hash": "3c99f2e7e8ba8edd7583729a86ae03136944adf2", "best_bid": "0.005", "best_ask": "0.006"}], "timestamp": "1769384039270", "event_type": "price_change"}}
{"_local_timestamp": "2026-01-25T23:33:59.340481+00:00", "data": {"market": "0xfa4c453091f10ccab9fae67d8a2286e1bf1d9367596d1d5b74c36e4155e300af", "price_changes": [{"asset_id": "100280536155707901843387784334630754939243388352572806762203828618520844114191", "price": "0.023", "size": "8.77", "side": "BUY", "hash": "687b4f2e9acc679c29985c93f08c1274185e97b7", "best_bid": "0.994", "best_ask": "0.995"}, {"asset_id": "50903746416787079744189627434391589495562066033420184996159345764514807060721", "price": "0.977", "size": "8.77", "side": "SELL", "hash": "495ecaa931f5f4092f589338a3a4270e3b85ef26", "best_bid": "0.005", "best_ask": "0.006"}], "timestamp": "1769384039271", "event_type": "price_change"}}
{"_local_timestamp": "2026-01-25T23:34:02.420197+00:00", "data": {"market": "0xf20f7af3ea74b16d623af198d6efb27d9d4ee98cfa96b1b6c8d4021d55436eb0", "price_changes": [{"asset_id": "8204205703682240679449476083075054464313606926136751077466819525464621562665", "price": "0.03", "size": "12.23", "side": "BUY", "hash": "a4085a2769f9e53cc2695c7e8776810fd59ceff4", "best_bid": "0.03", "best_ask": "0.13"}, {"asset_id": "79006550760303579457645886672312299229061887535391288753983510221472432105358", "price": "0.97", "size": "12.23", "side": "SELL", "hash": "0b05780d4dca3431746657b4a76e6c6636184d41", "best_bid": "0.87", "best_ask": "0.97"}], "timestamp": "1769384042352", "event_type": "price_change"}}
{"_local_timestamp": "2026-01-25T23:34:02.421947+00:00", "data": {"market": "0xf8669cc099ad4008ee1735ae5ac1eb80ae005b249055d17df33fb086bcdfe83d", "price_changes": [{"asset_id": "67480800071998288404809609572612598087778955841531703375023453126691719294061", "price": "0.007", "size": "41.11", "side": "BUY", "hash": "b1f5029ce7f3dc65aabac08ba907b54c02794962", "best_bid": "0.012", "best_ask": "0.122"}, {"asset_id": "74412093647819275524093734803851724407441381744350956613925261842560119775884", "price": "0.993", "size": "41.11", "side": "SELL", "hash": "e2fbcb315b5f32618af58cde70aa54df3897f419", "best_bid": "0.878", "best_ask": "0.988"}], "timestamp": "1769384042352", "event_type": "price_change"}}
{"_local_timestamp": "2026-01-25T23:34:02.859029+00:00", "data": {"market": "0xf20f7af3ea74b16d623af198d6efb27d9d4ee98cfa96b1b6c8d4021d55436eb0", "price_changes": [{"asset_id": "8204205703682240679449476083075054464313606926136751077466819525464621562665", "price": "0.03", "size": "21.5", "side": "BUY", "hash": "a7157ca365fee277c66017663bbfe482197f5c75", "best_bid": "0.03", "best_ask": "0.13"}, {"asset_id": "79006550760303579457645886672312299229061887535391288753983510221472432105358", "price": "0.97", "size": "21.5", "side": "SELL", "hash": "e394954d01fbcd98e6f47004cdafe75635235676", "best_bid": "0.87", "best_ask": "0.97"}], "timestamp": "1769384042793", "event_type": "price_change"}}
{"_local_timestamp": "2026-01-25T23:34:02.860783+00:00", "data": {"market": "0xf8669cc099ad4008ee1735ae5ac1eb80ae005b249055d17df33fb086bcdfe83d", "price_changes": [{"asset_id": "67480800071998288404809609572612598087778955841531703375023453126691719294061", "price": "0.007", "size": "49.09", "side": "BUY", "hash": "2bcd08cc4172a38c62ef0cea3b5ced5850ffb5ef", "best_bid": "0.012", "best_ask": "0.122"}, {"asset_id": "74412093647819275524093734803851724407441381744350956613925261842560119775884", "price": "0.993", "size": "49.09", "side": "SELL", "hash": "8831ade7d5e8a05a273aeeaa180d47b52113b685", "best_bid": "0.878", "best_ask": "0.988"}], "timestamp": "1769384042794", "event_type": "price_change"}}
{"_local_timestamp": "2026-01-25T23:34:05.804648+00:00", "data": {"market": "0xf8669cc099ad4008ee1735ae5ac1eb80ae005b249055d17df33fb086bcdfe83d", "price_changes": [{"asset_id": "67480800071998288404809609572612598087778955841531703375023453126691719294061", "price": "0.007", "size": "41.11", "side": "BUY", "hash": "6ae5454395b7b527672da7cab54ff7a57361dff3", "best_bid": "0.012", "best_ask": "0.122"}, {"asset_id": "74412093647819275524093734803851724407441381744350956613925261842560119775884", "price": "0.993", "size": "41.11", "side": "SELL", "hash": "8ef89dd8dcef4a7462b06786e9f0da659853c60f", "best_bid": "0.878", "best_ask": "0.988"}], "timestamp": "1769384045735", "event_type": "price_change"}}
{"_local_timestamp": "2026-01-25T23:34:06.060703+00:00", "data": {"market": "0xf8669cc099ad4008ee1735ae5ac1eb80ae005b249055d17df33fb086bcdfe83d", "price_changes": [{"asset_id": "67480800071998288404809609572612598087778955841531703375023453126691719294061", "price": "0.007", "size": "49.09", "side": "BUY", "hash": "89ca35af6d092ff7fdc2cc37546215765c1b44f0", "best_bid": "0.012", "best_ask": "0.122"}, {"asset_id": "74412093647819275524093734803851724407441381744350956613925261842560119775884", "price": "0.993", "size": "49.09", "side": "SELL", "hash": "c2c6f47f6d462c0759fd873e7e8e2b613709ede3", "best_bid": "0.878", "best_ask": "0.988"}], "timestamp": "1769384045992", "event_type": "price_change"}}
{"_local_timestamp": "2026-01-25T23:34:06.253779+00:00", "data": {"market": "0xf20f7af3ea74b16d623af198d6efb27d9d4ee98cfa96b1b6c8d4021d55436eb0", "price_changes": [{"asset_id": "8204205703682240679449476083075054464313606926136751077466819525464621562665", "price": "0.03", "size": "12.23", "side": "BUY", "hash": "23d19069d302e1ee7c7736bfc3f463bd4103df81", "best_bid": "0.03", "best_ask": "0.13"}, {"asset_id": "79006550760303579457645886672312299229061887535391288753983510221472432105358", "price": "0.97", "size": "12.23", "side": "SELL", "hash": "777a8cc07c6916f99280eda6caeb75787eaa9cb9", "best_bid": "0.87", "best_ask": "0.97"}], "timestamp": "1769384046181", "event_type": "price_change"}}
{"_local_timestamp": "2026-01-25T23:34:06.486143+00:00", "data": {"market": "0xf20f7af3ea74b16d623af198d6efb27d9d4ee98cfa96b1b6c8d4021d55436eb0", "price_changes": [{"asset_id": "8204205703682240679449476083075054464313606926136751077466819525464621562665", "price": "0.03", "size": "21.5", "side": "BUY", "hash": "2ac3e27e1a91172e1c2bd4a8ab735b308520b37b", "best_bid": "0.03", "best_ask": "0.13"}, {"asset_id": "79006550760303579457645886672312299229061887535391288753983510221472432105358", "price": "0.97", "size": "21.5", "side": "SELL", "hash": "1c5a84b017ba8b76a627939410dfcd1ebfb37971", "best_bid": "0.87", "best_ask": "0.97"}], "timestamp": "1769384046422", "event_type": "price_change"}}
{"_local_timestamp": "2026-01-25T23:34:06.677737+00:00", "data": {"market": "0x4f355b2f81f7f84edb31b62b3972d3681a78306b6f43130da93c6a42e829cab7", "price_changes": [{"asset_id": "43538879179631176153024597485437046935007669385526523627415213016048238626800", "price": "0.718", "size": "0", "side": "BUY", "hash": "b3f3b1bca288149644f5d81e84df511e7be5e1f6", "best_bid": "0.83", "best_ask": "0.989"}, {"asset_id": "6698389915475741137443362108181546761737389215301116913025758411586200078040", "price": "0.282", "size": "0", "side": "SELL", "hash": "7a65df32d75244caa9b10060d7616e9bff3a9a26", "best_bid": "0.011", "best_ask": "0.17"}], "timestamp": "1769384046610", "event_type": "price_change"}}
{"_local_timestamp": "2026-01-25T23:34:07.381926+00:00", "data": {"market": "0x4f355b2f81f7f84edb31b62b3972d3681a78306b6f43130da93c6a42e829cab7", "price_changes": [{"asset_id": "43538879179631176153024597485437046935007669385526523627415213016048238626800", "price": "0.718", "size": "5", "side": "BUY", "hash": "e66e36c200f074bf36fab268ce55aeae4ec9dbb7", "best_bid": "0.83", "best_ask": "0.989"}, {"asset_id": "6698389915475741137443362108181546761737389215301116913025758411586200078040", "price": "0.282", "size": "5", "side": "SELL", "hash": "ffb08143d7cf91da5553013373880f08b83691ba", "best_bid": "0.011", "best_ask": "0.17"}], "timestamp": "1769384047317", "event_type": "price_change"}}
{"_local_timestamp": "2026-01-25T23:34:08.201624+00:00", "data": {"market": "0xf20f7af3ea74b16d623af198d6efb27d9d4ee98cfa96b1b6c8d4021d55436eb0", "price_changes": [{"asset_id": "8204205703682240679449476083075054464313606926136751077466819525464621562665", "price": "0.03", "size": "12.23", "side": "BUY", "hash": "b181224cef176eabe0c4868c6f7a3e436c9bd1c3", "best_bid": "0.03", "best_ask": "0.13"}, {"asset_id": "79006550760303579457645886672312299229061887535391288753983510221472432105358", "price": "0.97", "size": "12.23", "side": "SELL", "hash": "fb8331cae5ff18f28b21bbbcee92ecd76744ffab", "best_bid": "0.87", "best_ask": "0.97"}], "timestamp": "1769384048137", "event_type": "price_change"}}
{"_local_timestamp": "2026-01-25T23:34:08.202856+00:00", "data": {"market": "0xf8669cc099ad4008ee1735ae5ac1eb80ae005b249055d17df33fb086bcdfe83d", "price_changes": [{"asset_id": "67480800071998288404809609572612598087778955841531703375023453126691719294061", "price": "0.007", "size": "41.11", "side": "BUY", "hash": "cb4850021ecbc9b50153c4624876e6bbb47e52e8", "best_bid": "0.012", "best_ask": "0.122"}, {"asset_id": "74412093647819275524093734803851724407441381744350956613925261842560119775884", "price": "0.993", "size": "41.11", "side": "SELL", "hash": "c7090d70e3b3fbca9c15a86c9314b8d927ed3301", "best_bid": "0.878", "best_ask": "0.988"}], "timestamp": "1769384048137", "event_type": "price_change"}}
{"_local_timestamp": "2026-01-25T23:34:08.429763+00:00", "data": {"market": "0xf20f7af3ea74b16d623af198d6efb27d9d4ee98cfa96b1b6c8d4021d55436eb0", "price_changes": [{"asset_id": "8204205703682240679449476083075054464313606926136751077466819525464621562665", "price": "0.03", "size": "21.5", "side": "BUY", "hash": "c1ffb11f66264a5d8e713a95f7f4e28af44a0ee3", "best_bid": "0.03", "best_ask": "0.13"}, {"asset_id": "79006550760303579457645886672312299229061887535391288753983510221472432105358", "price": "0.97", "size": "21.5", "side": "SELL", "hash": "dc9df9b76dd7349152038919c23877cb07366db0", "best_bid": "0.87", "best_ask": "0.97"}], "timestamp": "1769384048366", "event_type": "price_change"}}
{"_local_timestamp": "2026-01-25T23:34:08.433143+00:00", "data": {"market": "0xf8669cc099ad4008ee1735ae5ac1eb80ae005b249055d17df33fb086bcdfe83d", "price_changes": [{"asset_id": "67480800071998288404809609572612598087778955841531703375023453126691719294061", "price": "0.007", "size": "49.09", "side": "BUY", "hash": "b765fdb563d18dc56297445e3e9a52cd43cbcc2a", "best_bid": "0.012", "best_ask": "0.122"}, {"asset_id": "74412093647819275524093734803851724407441381744350956613925261842560119775884", "price": "0.993", "size": "49.09", "side": "SELL", "hash": "bdc10b6214793b143969b2cc0497748e346fe753", "best_bid": "0.878", "best_ask": "0.988"}], "timestamp": "1769384048366", "event_type": "price_change"}}
{"_local_timestamp": "2026-01-25T23:34:09.811514+00:00", "data": {"market": "0xf20f7af3ea74b16d623af198d6efb27d9d4ee98cfa96b1b6c8d4021d55436eb0", "price_changes": [{"asset_id": "79006550760303579457645886672312299229061887535391288753983510221472432105358", "price": "0.07", "size": "0", "side": "BUY", "hash": "e61a67e7f12b2ebf6e584de31b975766a5e960b5", "best_bid": "0.87", "best_ask": "0.97"}, {"asset_id": "8204205703682240679449476083075054464313606926136751077466819525464621562665", "price": "0.93", "size": "0", "side": "SELL", "hash": "a36fea9fe071911444c14ede718236ac4772511a", "best_bid": "0.03", "best_ask": "0.13"}], "timestamp": "1769384049743", "event_type": "price_change"}}
{"_local_timestamp": "2026-01-25T23:34:09.858058+00:00", "data": {"market": "0xf20f7af3ea74b16d623af198d6efb27d9d4ee98cfa96b1b6c8d4021d55436eb0", "price_changes": [{"asset_id": "79006550760303579457645886672312299229061887535391288753983510221472432105358", "price": "0.07", "size": "28", "side": "BUY", "hash": "33c3a056f587a16959e090d050e9fa7ed8d5a146", "best_bid": "0.87", "best_ask": "0.97"}, {"asset_id": "8204205703682240679449476083075054464313606926136751077466819525464621562665", "price": "0.93", "size": "28", "side": "SELL", "hash": "52c5e6a22160d1a1fc2b122d24ffe06413aab40d", "best_bid": "0.03", "best_ask": "0.13"}], "timestamp": "1769384049791", "event_type": "price_change"}}
{"_local_timestamp": "2026-01-25T23:34:12.038494+00:00", "data": {"market": "0xf20f7af3ea74b16d623af198d6efb27d9d4ee98cfa96b1b6c8d4021d55436eb0", "price_changes": [{"asset_id": "8204205703682240679449476083075054464313606926136751077466819525464621562665", "price": "0.03", "size": "12.23", "side": "BUY", "hash": "8e44ed4566cb773151b935882aa2ef8132db1392", "best_bid": "0.03", "best_ask": "0.13"}, {"asset_id": "79006550760303579457645886672312299229061887535391288753983510221472432105358", "price": "0.97", "size": "12.23", "side": "SELL", "hash": "83b905265bbab71f8afc98292eed7666009fd8ff", "best_bid": "0.87", "best_ask": "0.97"}], "timestamp": "1769384051958", "event_type": "price_change"}}
{"_local_timestamp": "2026-01-25T23:34:12.039924+00:00", "data": {"market": "0xf8669cc099ad4008ee1735ae5ac1eb80ae005b249055d17df33fb086bcdfe83d", "price_changes": [{"asset_id": "67480800071998288404809609572612598087778955841531703375023453126691719294061", "price": "0.007", "size": "41.11", "side": "BUY", "hash": "650d2bd287a5f13fe973168588c958fb3797aec3", "best_bid": "0.012", "best_ask": "0.122"}, {"asset_id": "74412093647819275524093734803851724407441381744350956613925261842560119775884", "price": "0.993", "size": "41.11", "side": "SELL", "hash": "32aec75334436e664e461a61f4ff88004637d3fb", "best_bid": "0.878", "best_ask": "0.988"}], "timestamp": "1769384051958", "event_type": "price_change"}}
{"_local_timestamp": "2026-01-25T23:34:12.241114+00:00", "data": {"market": "0xf8669cc099ad4008ee1735ae5ac1eb80ae005b249055d17df33fb086bcdfe83d", "price_changes": [{"asset_id": "67480800071998288404809609572612598087778955841531703375023453126691719294061", "price": "0.007", "size": "49.09", "side": "BUY", "hash": "0405ec2096c4a4ed75bb23088f2a66b480c96f71", "best_bid": "0.012", "best_ask": "0.122"}, {"asset_id": "74412093647819275524093734803851724407441381744350956613925261842560119775884", "price": "0.993", "size": "49.09", "side": "SELL", "hash": "87c1bea9e3b8791665b427d76e34c28f30ca73aa", "best_bid": "0.878", "best_ask": "0.988"}], "timestamp": "1769384052161", "event_type": "price_change"}}
{"_local_timestamp": "2026-01-25T23:34:12.377704+00:00", "data": {"market": "0xf20f7af3ea74b16d623af198d6efb27d9d4ee98cfa96b1b6c8d4021d55436eb0", "price_changes": [{"asset_id": "8204205703682240679449476083075054464313606926136751077466819525464621562665", "price": "0.03", "size": "21.5", "side": "BUY", "hash": "eae5327bb93376cbd0aaab9bf6e3041334026df5", "best_bid": "0.03", "best_ask": "0.13"}, {"asset_id": "79006550760303579457645886672312299229061887535391288753983510221472432105358", "price": "0.97", "size": "21.5", "side": "SELL", "hash": "12e09c42d2b737d279ce2bd6cc70464f32e73982", "best_bid": "0.87", "best_ask": "0.97"}], "timestamp": "1769384052295", "event_type": "price_change"}}
{"_local_timestamp": "2026-01-25T23:34:14.686433+00:00", "data": {"market": "0xf20f7af3ea74b16d623af198d6efb27d9d4ee98cfa96b1b6c8d4021d55436eb0", "price_changes": [{"asset_id": "8204205703682240679449476083075054464313606926136751077466819525464621562665", "price": "0.03", "size": "12.23", "side": "BUY", "hash": "233e2d0ce0ce39e31a7175922f269ee78a8fdb68", "best_bid": "0.03", "best_ask": "0.13"}, {"asset_id": "79006550760303579457645886672312299229061887535391288753983510221472432105358", "price": "0.97", "size": "12.23", "side": "SELL", "hash": "1ebdefdfd07fab127c6f9becbbe2223f6fe02632", "best_bid": "0.87", "best_ask": "0.97"}], "timestamp": "1769384054616", "event_type": "price_change"}}
{"_local_timestamp": "2026-01-25T23:34:14.687395+00:00", "data": {"market": "0xf8669cc099ad4008ee1735ae5ac1eb80ae005b249055d17df33fb086bcdfe83d", "price_changes": [{"asset_id": "67480800071998288404809609572612598087778955841531703375023453126691719294061", "price": "0.007", "size": "41.11", "side": "BUY", "hash": "5399072906f687dee058015707f90dfc27082a0b", "best_bid": "0.012", "best_ask": "0.122"}, {"asset_id": "74412093647819275524093734803851724407441381744350956613925261842560119775884", "price": "0.993", "size": "41.11", "side": "SELL", "hash": "7164a0ea2415665aa171596a99487303eecbf0e8", "best_bid": "0.878", "best_ask": "0.988"}], "timestamp": "1769384054616", "event_type": "price_change"}}
{"_local_timestamp": "2026-01-25T23:34:14.882354+00:00", "data": {"market": "0xf8669cc099ad4008ee1735ae5ac1eb80ae005b249055d17df33fb086bcdfe83d", "price_changes": [{"asset_id": "67480800071998288404809609572612598087778955841531703375023453126691719294061", "price": "0.008", "size": "13.25", "side": "BUY", "hash": "d60b3c72d1fabb571e56089ff6b28f08bdae2efc", "best_bid": "0.012", "best_ask": "0.122"}, {"asset_id": "74412093647819275524093734803851724407441381744350956613925261842560119775884", "price": "0.992", "size": "13.25", "side": "SELL", "hash": "4cde74f6bbaaab80b62538782986aa2347c5798a", "best_bid": "0.878", "best_ask": "0.988"}], "timestamp": "1769384054815", "event_type": "price_change"}}
{"_local_timestamp": "2026-01-25T23:34:14.883895+00:00", "data": {"market": "0xf20f7af3ea74b16d623af198d6efb27d9d4ee98cfa96b1b6c8d4021d55436eb0", "price_changes": [{"asset_id": "8204205703682240679449476083075054464313606926136751077466819525464621562665", "price": "0.03", "size": "21.5", "side": "BUY", "hash": "9ebea748dff2e5938e1093479fd8564c61925005", "best_bid": "0.03", "best_ask": "0.13"}, {"asset_id": "79006550760303579457645886672312299229061887535391288753983510221472432105358", "price": "0.97", "size": "21.5", "side": "SELL", "hash": "d5c39400fdda04e89f2850f82e63061fd0583157", "best_bid": "0.87", "best_ask": "0.97"}], "timestamp": "1769384054815", "event_type": "price_change"}}
{"_local_timestamp": "2026-01-25T23:34:17.275252+00:00", "data": {"market": "0xf20f7af3ea74b16d623af198d6efb27d9d4ee98cfa96b1b6c8d4021d55436eb0", "price_changes": [{"asset_id": "8204205703682240679449476083075054464313606926136751077466819525464621562665", "price": "0.03", "size": "12.23", "side": "BUY", "hash": "807d823f67237c70bee1ea66a1dc755cab0e3b95", "best_bid": "0.03", "best_ask": "0.13"}, {"asset_id": "79006550760303579457645886672312299229061887535391288753983510221472432105358", "price": "0.97", "size": "12.23", "side": "SELL", "hash": "231209a1b7795fb774f787315c74485bd80c4249", "best_bid": "0.87", "best_ask": "0.97"}], "timestamp": "1769384057196", "event_type": "price_change"}}
{"_local_timestamp": "2026-01-25T23:34:17.276106+00:00", "data": {"market": "0xf8669cc099ad4008ee1735ae5ac1eb80ae005b249055d17df33fb086bcdfe83d", "price_changes": [{"asset_id": "67480800071998288404809609572612598087778955841531703375023453126691719294061", "price": "0.008", "size": "6.26", "side": "BUY", "hash": "c28f7467bffb85b04cd2924ab7c3342e1530e0a0", "best_bid": "0.012", "best_ask": "0.122"}, {"asset_id": "74412093647819275524093734803851724407441381744350956613925261842560119775884", "price": "0.992", "size": "6.26", "side": "SELL", "hash": "4a263eb5cb7e26d6404b19676e18e0f572a78027", "best_bid": "0.878", "best_ask": "0.988"}], "timestamp": "1769384057196", "event_type": "price_change"}}
{"_local_timestamp": "2026-01-25T23:34:17.553203+00:00", "data": {"market": "0xf20f7af3ea74b16d623af198d6efb27d9d4ee98cfa96b1b6c8d4021d55436eb0", "price_changes": [{"asset_id": "8204205703682240679449476083075054464313606926136751077466819525464621562665", "price": "0.03", "size": "21.5", "side": "BUY", "hash": "7ae77a825a68824a7af4a1b34fb3dcfc3f68134d", "best_bid": "0.03", "best_ask": "0.13"}, {"asset_id": "79006550760303579457645886672312299229061887535391288753983510221472432105358", "price": "0.97", "size": "21.5", "side": "SELL", "hash": "4c63ac20f5432af45cb0f938f9e2147b2c1675ee", "best_bid": "0.87", "best_ask": "0.97"}], "timestamp": "1769384057488", "event_type": "price_change"}}
{"_local_timestamp": "2026-01-25T23:34:17.554344+00:00", "data": {"market": "0xf8669cc099ad4008ee1735ae5ac1eb80ae005b249055d17df33fb086bcdfe83d", "price_changes": [{"asset_id": "67480800071998288404809609572612598087778955841531703375023453126691719294061", "price": "0.007", "size": "49.09", "side": "BUY", "hash": "3c66db8f606661c428ef4bcc293584761b2bf2fd", "best_bid": "0.012", "best_ask": "0.122"}, {"asset_id": "74412093647819275524093734803851724407441381744350956613925261842560119775884", "price": "0.993", "size": "49.09", "side": "SELL", "hash": "b94f9c0f5df5147c7e07c0a81f2fef149ce11220", "best_bid": "0.878", "best_ask": "0.988"}], "timestamp": "1769384057488", "event_type": "price_change"}}
{"_local_timestamp": "2026-01-25T23:34:19.405844+00:00", "data": {"market": "0xf20f7af3ea74b16d623af198d6efb27d9d4ee98cfa96b1b6c8d4021d55436eb0", "price_changes": [{"asset_id": "8204205703682240679449476083075054464313606926136751077466819525464621562665", "price": "0.03", "size": "12.23", "side": "BUY", "hash": "40f8dafa9beb0e0b4c88281d7f83d0db6ddd37a1", "best_bid": "0.03", "best_ask": "0.13"}, {"asset_id": "79006550760303579457645886672312299229061887535391288753983510221472432105358", "price": "0.97", "size": "12.23", "side": "SELL", "hash": "0e03f20d69f18d10756c5f5328884748700aac51", "best_bid": "0.87", "best_ask": "0.97"}], "timestamp": "1769384059336", "event_type": "price_change"}}
{"_local_timestamp": "2026-01-25T23:34:19.406722+00:00", "data": {"market": "0xf8669cc099ad4008ee1735ae5ac1eb80ae005b249055d17df33fb086bcdfe83d", "price_changes": [{"asset_id": "67480800071998288404809609572612598087778955841531703375023453126691719294061", "price": "0.007", "size": "41.11", "side": "BUY", "hash": "37032af085a18e316ab4453ab6853bd8bebc8fce", "best_bid": "0.012", "best_ask": "0.122"}, {"asset_id": "74412093647819275524093734803851724407441381744350956613925261842560119775884", "price": "0.993", "size": "41.11", "side": "SELL", "hash": "26989386dd6deb69cc68d7d01ee0c944b808f453", "best_bid": "0.878", "best_ask": "0.988"}], "timestamp": "1769384059336", "event_type": "price_change"}}
{"_local_timestamp": "2026-01-25T23:34:19.668969+00:00", "data": {"market": "0xf20f7af3ea74b16d623af198d6efb27d9d4ee98cfa96b1b6c8d4021d55436eb0", "price_changes": [{"asset_id": "8204205703682240679449476083075054464313606926136751077466819525464621562665", "price": "0.03", "size": "21.5", "side": "BUY", "hash": "a49ea46092f4106034edc440cc75f93de45216ed", "best_bid": "0.03", "best_ask": "0.13"}, {"asset_id": "79006550760303579457645886672312299229061887535391288753983510221472432105358", "price": "0.97", "size": "21.5", "side": "SELL", "hash": "40e6e105a4c01b18aab4d547372b1e3c463658b9", "best_bid": "0.87", "best_ask": "0.97"}], "timestamp": "1769384059605", "event_type": "price_change"}}
{"_local_timestamp": "2026-01-25T23:34:19.673802+00:00", "data": {"market": "0xf8669cc099ad4008ee1735ae5ac1eb80ae005b249055d17df33fb086bcdfe83d", "price_changes": [{"asset_id": "67480800071998288404809609572612598087778955841531703375023453126691719294061", "price": "0.008", "size": "13.25", "side": "BUY", "hash": "31cc24a476c0f221db105a901c81a925bc6a058c", "best_bid": "0.012", "best_ask": "0.122"}, {"asset_id": "74412093647819275524093734803851724407441381744350956613925261842560119775884", "price": "0.992", "size": "13.25", "side": "SELL", "hash": "4695ad121df6c65adaefcd1e51a2eefbb7e1192b", "best_bid": "0.878", "best_ask": "0.988"}], "timestamp": "1769384059605", "event_type": "price_change"}}
{"_local_timestamp": "2026-01-25T23:34:21.332501+00:00", "data": {"market": "0xf20f7af3ea74b16d623af198d6efb27d9d4ee98cfa96b1b6c8d4021d55436eb0", "price_changes": [{"asset_id": "8204205703682240679449476083075054464313606926136751077466819525464621562665", "price": "0.03", "size": "12.23", "side": "BUY", "hash": "9fdbb951a5e58a7e78a3078442b8d3db1840acbb", "best_bid": "0.03", "best_ask": "0.13"}, {"asset_id": "79006550760303579457645886672312299229061887535391288753983510221472432105358", "price": "0.97", "size": "12.23", "side": "SELL", "hash": "b8f75b1c89e25b559127b19e1178f32b7e4abe20", "best_bid": "0.87", "best_ask": "0.97"}], "timestamp": "1769384061261", "event_type": "price_change"}}
{"_local_timestamp": "2026-01-25T23:34:21.335391+00:00", "data": {"market": "0xf8669cc099ad4008ee1735ae5ac1eb80ae005b249055d17df33fb086bcdfe83d", "price_changes": [{"asset_id": "67480800071998288404809609572612598087778955841531703375023453126691719294061", "price": "0.008", "size": "6.26", "side": "BUY", "hash": "c6a079ef7ec2e8419b1f844b6ad34c0c6e782976", "best_bid": "0.012", "best_ask": "0.122"}, {"asset_id": "74412093647819275524093734803851724407441381744350956613925261842560119775884", "price": "0.992", "size": "6.26", "side": "SELL", "hash": "30a74005937b8831fc5d04fd73e2916564a8ba50", "best_bid": "0.878", "best_ask": "0.988"}], "timestamp": "1769384061261", "event_type": "price_change"}}
{"_local_timestamp": "2026-01-25T23:34:21.576358+00:00", "data": {"market": "0xf20f7af3ea74b16d623af198d6efb27d9d4ee98cfa96b1b6c8d4021d55436eb0", "price_changes": [{"asset_id": "8204205703682240679449476083075054464313606926136751077466819525464621562665", "price": "0.03", "size": "21.5", "side": "BUY", "hash": "dcb8f244dbebdfcbd5d721c2ebcaf3cbae54f1a5", "best_bid": "0.03", "best_ask": "0.13"}, {"asset_id": "79006550760303579457645886672312299229061887535391288753983510221472432105358", "price": "0.97", "size": "21.5", "side": "SELL", "hash": "733544418884deb31ddab25647dc0b54b581d469", "best_bid": "0.87", "best_ask": "0.97"}], "timestamp": "1769384061511", "event_type": "price_change"}}
{"_local_timestamp": "2026-01-25T23:34:21.579935+00:00", "data": {"market": "0xf8669cc099ad4008ee1735ae5ac1eb80ae005b249055d17df33fb086bcdfe83d", "price_changes": [{"asset_id": "67480800071998288404809609572612598087778955841531703375023453126691719294061", "price": "0.007", "size": "49.09", "side": "BUY", "hash": "f1a2e51e27c95c319e7b50f85f6fd3a59bdcc4b2", "best_bid": "0.012", "best_ask": "0.122"}, {"asset_id": "74412093647819275524093734803851724407441381744350956613925261842560119775884", "price": "0.993", "size": "49.09", "side": "SELL", "hash": "acf0b41c347d5a08d4daac9973335240aa9b4365", "best_bid": "0.878", "best_ask": "0.988"}], "timestamp": "1769384061511", "event_type": "price_change"}}
{"_local_timestamp": "2026-01-25T23:34:23.498615+00:00", "data": {"market": "0x0bf8c8a49d597193dcc1d3921b68bcf357dcf14f61eebb314b2ca26df92c6b70", "price_changes": [{"asset_id": "112686561748271690852517534925258634835514924647537374255796839555111757158365", "price": "0.002", "size": "205", "side": "BUY", "hash": "2db0eb2224f2dcdc7dfdf1d3d70ad5f1e5931d57", "best_bid": "0.004", "best_ask": "0.01"}, {"asset_id": "64985992928364318123592920719859941241227792181953993325149181671869965959425", "price": "0.998", "size": "205", "side": "SELL", "hash": "ec36e56b9f6c6d35a9d1b0454bfbafce54f29c85", "best_bid": "0.99", "best_ask": "0.996"}], "timestamp": "1769384063427", "event_type": "price_change"}}
{"_local_timestamp": "2026-01-25T23:34:23.893830+00:00", "data": {"market": "0x0bf8c8a49d597193dcc1d3921b68bcf357dcf14f61eebb314b2ca26df92c6b70", "price_changes": [{"asset_id": "112686561748271690852517534925258634835514924647537374255796839555111757158365", "price": "0.002", "size": "221.23", "side": "BUY", "hash": "bb63ee70bdf52ee31cab1078271884b06d9c52ed", "best_bid": "0.004", "best_ask": "0.01"}, {"asset_id": "64985992928364318123592920719859941241227792181953993325149181671869965959425", "price": "0.998", "size": "221.23", "side": "SELL", "hash": "352ac35386929b878f9db0bc182a978ab2d027fd", "best_bid": "0.99", "best_ask": "0.996"}], "timestamp": "1769384063823", "event_type": "price_change"}}
{"_local_timestamp": "2026-01-25T23:34:24.965244+00:00", "data": {"market": "0xf20f7af3ea74b16d623af198d6efb27d9d4ee98cfa96b1b6c8d4021d55436eb0", "price_changes": [{"asset_id": "8204205703682240679449476083075054464313606926136751077466819525464621562665", "price": "0.03", "size": "12.23", "side": "BUY", "hash": "3110f23e243021ce2f339414d8a26df8d2a72ade", "best_bid": "0.03", "best_ask": "0.13"}, {"asset_id": "79006550760303579457645886672312299229061887535391288753983510221472432105358", "price": "0.97", "size": "12.23", "side": "SELL", "hash": "b3b8559edf942a169430dfa0efb4b00a0956155d", "best_bid": "0.87", "best_ask": "0.97"}], "timestamp": "1769384064899", "event_type": "price_change"}}
{"_local_timestamp": "2026-01-25T23:34:24.966001+00:00", "data": {"market": "0xf8669cc099ad4008ee1735ae5ac1eb80ae005b249055d17df33fb086bcdfe83d", "price_changes": [{"asset_id": "67480800071998288404809609572612598087778955841531703375023453126691719294061", "price": "0.007", "size": "41.11", "side": "BUY", "hash": "d26477cb13edf13767e22acbc8894dc18c605e52", "best_bid": "0.012", "best_ask": "0.122"}, {"asset_id": "74412093647819275524093734803851724407441381744350956613925261842560119775884", "price": "0.993", "size": "41.11", "side": "SELL", "hash": "507554bf7b431b3725aba5abce8e361200a8dd8e", "best_bid": "0.878", "best_ask": "0.988"}], "timestamp": "1769384064899", "event_type": "price_change"}}
{"_local_timestamp": "2026-01-25T23:34:25.257535+00:00", "data": {"market": "0xf20f7af3ea74b16d623af198d6efb27d9d4ee98cfa96b1b6c8d4021d55436eb0", "price_changes": [{"asset_id": "8204205703682240679449476083075054464313606926136751077466819525464621562665", "price": "0.03", "size": "21.5", "side": "BUY", "hash": "ef1934337be2c16dcdf47a187e7ce175247baf11", "best_bid": "0.03", "best_ask": "0.13"}, {"asset_id": "79006550760303579457645886672312299229061887535391288753983510221472432105358", "price": "0.97", "size": "21.5", "side": "SELL", "hash": "86f104c25b656bb2f0d2d4d36fde1fae041cfbd6", "best_bid": "0.87", "best_ask": "0.97"}], "timestamp": "1769384065169", "event_type": "price_change"}}
{"_local_timestamp": "2026-01-25T23:34:25.258240+00:00", "data": {"market": "0xf8669cc099ad4008ee1735ae5ac1eb80ae005b249055d17df33fb086bcdfe83d", "price_changes": [{"asset_id": "67480800071998288404809609572612598087778955841531703375023453126691719294061", "price": "0.007", "size": "49.09", "side": "BUY", "hash": "05da945057d7e60b77d5d39db382884f2c5ebb6d", "best_bid": "0.012", "best_ask": "0.122"}, {"asset_id": "74412093647819275524093734803851724407441381744350956613925261842560119775884", "price": "0.993", "size": "49.09", "side": "SELL", "hash": "7deafc6eb25bf7c6c4143c01c200d8286e9d1da3", "best_bid": "0.878", "best_ask": "0.988"}], "timestamp": "1769384065169", "event_type": "price_change"}}
{"_local_timestamp": "2026-01-25T23:34:27.573427+00:00", "data": {"market": "0xf20f7af3ea74b16d623af198d6efb27d9d4ee98cfa96b1b6c8d4021d55436eb0", "price_changes": [{"asset_id": "8204205703682240679449476083075054464313606926136751077466819525464621562665", "price": "0.03", "size": "12.23", "side": "BUY", "hash": "704d80db128f8fa3283ee3f5397d36e636d0d343", "best_bid": "0.03", "best_ask": "0.13"}, {"asset_id": "79006550760303579457645886672312299229061887535391288753983510221472432105358", "price": "0.97", "size": "12.23", "side": "SELL", "hash": "8110f1fcd1544188298b5af099ef6409346a56e4", "best_bid": "0.87", "best_ask": "0.97"}], "timestamp": "1769384067505", "event_type": "price_change"}}
{"_local_timestamp": "2026-01-25T23:34:27.574282+00:00", "data": {"market": "0xf8669cc099ad4008ee1735ae5ac1eb80ae005b249055d17df33fb086bcdfe83d", "price_changes": [{"asset_id": "67480800071998288404809609572612598087778955841531703375023453126691719294061", "price": "0.007", "size": "41.11", "side": "BUY", "hash": "fd6b95be1a49dc96cca0ee3b43123fdec8b000d0", "best_bid": "0.012", "best_ask": "0.122"}, {"asset_id": "74412093647819275524093734803851724407441381744350956613925261842560119775884", "price": "0.993", "size": "41.11", "side": "SELL", "hash": "ec9de20f4aac57500887384d9fc08adf37d9ecda", "best_bid": "0.878", "best_ask": "0.988"}], "timestamp": "1769384067505", "event_type": "price_change"}}
{"_local_timestamp": "2026-01-25T23:34:28.148158+00:00", "data": {"market": "0xf8669cc099ad4008ee1735ae5ac1eb80ae005b249055d17df33fb086bcdfe83d", "price_changes": [{"asset_id": "67480800071998288404809609572612598087778955841531703375023453126691719294061", "price": "0.007", "size": "49.09", "side": "BUY", "hash": "918349ca1a9907d98aee0c983b3df9963a9646fc", "best_bid": "0.012", "best_ask": "0.122"}, {"asset_id": "74412093647819275524093734803851724407441381744350956613925261842560119775884", "price": "0.993", "size": "49.09", "side": "SELL", "hash": "e51f670fb3608684c37d7162e7a24e0e4ff0b2cf", "best_bid": "0.878", "best_ask": "0.988"}], "timestamp": "1769384068042", "event_type": "price_change"}}
{"_local_timestamp": "2026-01-25T23:34:28.149952+00:00", "data": {"market": "0xf20f7af3ea74b16d623af198d6efb27d9d4ee98cfa96b1b6c8d4021d55436eb0", "price_changes": [{"asset_id": "8204205703682240679449476083075054464313606926136751077466819525464621562665", "price": "0.03", "size": "21.5", "side": "BUY", "hash": "4e14d72c6767eea03717ad26949075f35b7465c6", "best_bid": "0.03", "best_ask": "0.13"}, {"asset_id": "79006550760303579457645886672312299229061887535391288753983510221472432105358", "price": "0.97", "size": "21.5", "side": "SELL", "hash": "2105cf1d4aa053a104a4b497b2ce335ce100db22", "best_bid": "0.87", "best_ask": "0.97"}], "timestamp": "1769384068081", "event_type": "price_change"}}
{"_local_timestamp": "2026-01-25T23:34:30.323641+00:00", "data": {"market": "0xf20f7af3ea74b16d623af198d6efb27d9d4ee98cfa96b1b6c8d4021d55436eb0", "price_changes": [{"asset_id": "8204205703682240679449476083075054464313606926136751077466819525464621562665", "price": "0.03", "size": "12.23", "side": "BUY", "hash": "395ad7a6ad113bda092dfcfb792e70d36e90a548", "best_bid": "0.03", "best_ask": "0.13"}, {"asset_id": "79006550760303579457645886672312299229061887535391288753983510221472432105358", "price": "0.97", "size": "12.23", "side": "SELL", "hash": "64d6f0e2a866a0c3835d89b9c1ff1deee49acf76", "best_bid": "0.87", "best_ask": "0.97"}], "timestamp": "1769384070159", "event_type": "price_change"}}
{"_local_timestamp": "2026-01-25T23:34:30.325510+00:00", "data": {"market": "0xf8669cc099ad4008ee1735ae5ac1eb80ae005b249055d17df33fb086bcdfe83d", "price_changes": [{"asset_id": "67480800071998288404809609572612598087778955841531703375023453126691719294061", "price": "0.007", "size": "41.11", "side": "BUY", "hash": "44abd046675ea6f786ebb7cf4852679b744d904b", "best_bid": "0.012", "best_ask": "0.122"}, {"asset_id": "74412093647819275524093734803851724407441381744350956613925261842560119775884", "price": "0.993", "size": "41.11", "side": "SELL", "hash": "b24faff4b6815c38c18e0f89eddc91f0fdc154da", "best_bid": "0.878", "best_ask": "0.988"}], "timestamp": "1769384070159", "event_type": "price_change"}}
{"_local_timestamp": "2026-01-25T23:34:30.580744+00:00", "data": {"market": "0xf8669cc099ad4008ee1735ae5ac1eb80ae005b249055d17df33fb086bcdfe83d", "price_changes": [{"asset_id": "67480800071998288404809609572612598087778955841531703375023453126691719294061", "price": "0.008", "size": "13.25", "side": "BUY", "hash": "211032ac16850d68fd0ae03b218d5b832b18b051", "best_bid": "0.012", "best_ask": "0.122"}, {"asset_id": "74412093647819275524093734803851724407441381744350956613925261842560119775884", "price": "0.992", "size": "13.25", "side": "SELL", "hash": "584458e26f3c486c35d5d6473953a8142c187c83", "best_bid": "0.878", "best_ask": "0.988"}], "timestamp": "1769384070393", "event_type": "price_change"}}
{"_local_timestamp": "2026-01-25T23:34:30.612709+00:00", "data": {"market": "0xf20f7af3ea74b16d623af198d6efb27d9d4ee98cfa96b1b6c8d4021d55436eb0", "price_changes": [{"asset_id": "8204205703682240679449476083075054464313606926136751077466819525464621562665", "price": "0.04", "size": "6.95", "side": "BUY", "hash": "0268a663ba8e8a6bd379e17f5a12f073f895689f", "best_bid": "0.04", "best_ask": "0.13"}, {"asset_id": "79006550760303579457645886672312299229061887535391288753983510221472432105358", "price": "0.96", "size": "6.95", "side": "SELL", "hash": "5812184b66a42c67cf6bfd641d2d8adaae868297", "best_bid": "0.87", "best_ask": "0.96"}], "timestamp": "1769384070418", "event_type": "price_change"}}
{"_local_timestamp": "2026-01-25T23:34:32.392278+00:00", "data": {"market": "0xf8669cc099ad4008ee1735ae5ac1eb80ae005b249055d17df33fb086bcdfe83d", "price_changes": [{"asset_id": "67480800071998288404809609572612598087778955841531703375023453126691719294061", "price": "0.008", "size": "6.26", "side": "BUY", "hash": "6e4c4a2cf8c333c26b5015cfed9dfe77d3e945fb", "best_bid": "0.012", "best_ask": "0.122"}, {"asset_id": "74412093647819275524093734803851724407441381744350956613925261842560119775884", "price": "0.992", "size": "6.26", "side": "SELL", "hash": "e058a2bbccb95a2d5105105a84c2ed758c1e570f", "best_bid": "0.878", "best_ask": "0.988"}], "timestamp": "1769384072287", "event_type": "price_change"}}
{"_local_timestamp": "2026-01-25T23:34:32.626854+00:00", "data": {"market": "0xf8669cc099ad4008ee1735ae5ac1eb80ae005b249055d17df33fb086bcdfe83d", "price_changes": [{"asset_id": "67480800071998288404809609572612598087778955841531703375023453126691719294061", "price": "0.007", "size": "49.09", "side": "BUY", "hash": "6da2d33419a0e7f31adece1221a015f1fd376c30", "best_bid": "0.012", "best_ask": "0.122"}, {"asset_id": "74412093647819275524093734803851724407441381744350956613925261842560119775884", "price": "0.993", "size": "49.09", "side": "SELL", "hash": "ce008a687f05d34b4657bc3c2aea3157f7c38271", "best_bid": "0.878", "best_ask": "0.988"}], "timestamp": "1769384072560", "event_type": "price_change"}}
{"_local_timestamp": "2026-01-25T23:34:32.797486+00:00", "data": {"market": "0xf20f7af3ea74b16d623af198d6efb27d9d4ee98cfa96b1b6c8d4021d55436eb0", "price_changes": [{"asset_id": "8204205703682240679449476083075054464313606926136751077466819525464621562665", "price": "0.04", "size": "0", "side": "BUY", "hash": "25a19fc68332bdfe0f1d11c0b8e107a90f012134", "best_bid": "0.03", "best_ask": "0.13"}, {"asset_id": "79006550760303579457645886672312299229061887535391288753983510221472432105358", "price": "0.96", "size": "0", "side": "SELL", "hash": "6a7127cfb1c2bfc7371635f32acaee377473ebbb", "best_bid": "0.87", "best_ask": "0.97"}], "timestamp": "1769384072729", "event_type": "price_change"}}
{"_local_timestamp": "2026-01-25T23:34:33.086239+00:00", "data": {"market": "0xf20f7af3ea74b16d623af198d6efb27d9d4ee98cfa96b1b6c8d4021d55436eb0", "price_changes": [{"asset_id": "8204205703682240679449476083075054464313606926136751077466819525464621562665", "price": "0.03", "size": "21.5", "side": "BUY", "hash": "97de16c31c762aba575cccd2ba9b19676a450cab", "best_bid": "0.03", "best_ask": "0.13"}, {"asset_id": "79006550760303579457645886672312299229061887535391288753983510221472432105358", "price": "0.97", "size": "21.5", "side": "SELL", "hash": "137b1c1dce6f91781ddd6cd80fd69b5732507799", "best_bid": "0.87", "best_ask": "0.97"}], "timestamp": "1769384073015", "event_type": "price_change"}}
{"_local_timestamp": "2026-01-25T23:34:35.381499+00:00", "data": {"market": "0xf8669cc099ad4008ee1735ae5ac1eb80ae005b249055d17df33fb086bcdfe83d", "price_changes": [{"asset_id": "67480800071998288404809609572612598087778955841531703375023453126691719294061", "price": "0.007", "size": "41.11", "side": "BUY", "hash": "589048d1c8583da431746952fd2fafcb5199270c", "best_bid": "0.012", "best_ask": "0.122"}, {"asset_id": "74412093647819275524093734803851724407441381744350956613925261842560119775884", "price": "0.993", "size": "41.11", "side": "SELL", "hash": "9cd9e10e304a75d400ac9c2a636c9598af5e14bc", "best_bid": "0.878", "best_ask": "0.988"}], "timestamp": "1769384075319", "event_type": "price_change"}}
{"_local_timestamp": "2026-01-25T23:34:35.758713+00:00", "data": {"market": "0xf8669cc099ad4008ee1735ae5ac1eb80ae005b249055d17df33fb086bcdfe83d", "price_changes": [{"asset_id": "67480800071998288404809609572612598087778955841531703375023453126691719294061", "price": "0.007", "size": "49.09", "side": "BUY", "hash": "17d0f45d1e8af9f15cb57a6d81e155d77df9d370", "best_bid": "0.012", "best_ask": "0.122"}, {"asset_id": "74412093647819275524093734803851724407441381744350956613925261842560119775884", "price": "0.993", "size": "49.09", "side": "SELL", "hash": "b1df0342976717aa2318669229005f793e677a5e", "best_bid": "0.878", "best_ask": "0.988"}], "timestamp": "1769384075688", "event_type": "price_change"}}
{"_local_timestamp": "2026-01-25T23:34:36.678751+00:00", "data": {"market": "0x0ba39007f4ff1c2677f296b90188d544c2f80f9729c76a6f181a191543ceab82", "price_changes": [{"asset_id": "35783470881309485643248466709434569842971080886588261160663378071872348072260", "price": "0.2", "size": "0", "side": "BUY", "hash": "c11be46524d9b8108dffabaf219378d783f1b88d", "best_bid": "0.809", "best_ask": "0.995"}, {"asset_id": "35279195552426720847132209025903300157513105064872410280291719894882972533678", "price": "0.8", "size": "0", "side": "SELL", "hash": "a0fbe3e4314affd825d9f519aa4a4875a57cad9c", "best_bid": "0.005", "best_ask": "0.191"}], "timestamp": "1769384076615", "event_type": "price_change"}}
{"_local_timestamp": "2026-01-25T23:34:37.009927+00:00", "data": {"market": "0x0ba39007f4ff1c2677f296b90188d544c2f80f9729c76a6f181a191543ceab82", "price_changes": [{"asset_id": "35783470881309485643248466709434569842971080886588261160663378071872348072260", "price": "0.2", "size": "5", "side": "BUY", "hash": "f9fd60715af790af53ec91fb9cf1221d6b626af3", "best_bid": "0.809", "best_ask": "0.995"}, {"asset_id": "35279195552426720847132209025903300157513105064872410280291719894882972533678", "price": "0.8", "size": "5", "side": "SELL", "hash": "2064e1a2c7b66d67c9e0a3c3680487a389dd3b88", "best_bid": "0.005", "best_ask": "0.191"}], "timestamp": "1769384076942", "event_type": "price_change"}}
{"_local_timestamp": "2026-01-25T23:34:37.529084+00:00", "data": {"market": "0xf20f7af3ea74b16d623af198d6efb27d9d4ee98cfa96b1b6c8d4021d55436eb0", "price_changes": [{"asset_id": "8204205703682240679449476083075054464313606926136751077466819525464621562665", "price": "0.03", "size": "12.23", "side": "BUY", "hash": "d488585069326a7493cf9ad12e1d9922e87cf602", "best_bid": "0.03", "best_ask": "0.13"}, {"asset_id": "79006550760303579457645886672312299229061887535391288753983510221472432105358", "price": "0.97", "size": "12.23", "side": "SELL", "hash": "29a771c36978f53519a7e01543667df7477fa906", "best_bid": "0.87", "best_ask": "0.97"}], "timestamp": "1769384077466", "event_type": "price_change"}}
{"_local_timestamp": "2026-01-25T23:34:37.763697+00:00", "data": {"market": "0xf20f7af3ea74b16d623af198d6efb27d9d4ee98cfa96b1b6c8d4021d55436eb0", "price_changes": [{"asset_id": "8204205703682240679449476083075054464313606926136751077466819525464621562665", "price": "0.03", "size": "21.5", "side": "BUY", "hash": "ac0509615a16771245246deae1a6a5175449fdfd", "best_bid": "0.03", "best_ask": "0.13"}, {"asset_id": "79006550760303579457645886672312299229061887535391288753983510221472432105358", "price": "0.97", "size": "21.5", "side": "SELL", "hash": "448a89f71a83b92275b59441018b973c6fce63cd", "best_bid": "0.87", "best_ask": "0.97"}], "timestamp": "1769384077694", "event_type": "price_change"}}
{"_local_timestamp": "2026-01-25T23:34:38.403040+00:00", "data": {"market": "0xf8669cc099ad4008ee1735ae5ac1eb80ae005b249055d17df33fb086bcdfe83d", "price_changes": [{"asset_id": "67480800071998288404809609572612598087778955841531703375023453126691719294061", "price": "0.007", "size": "41.11", "side": "BUY", "hash": "1b3f91733122e84b7a0cf4e202c7345299446c52", "best_bid": "0.012", "best_ask": "0.122"}, {"asset_id": "74412093647819275524093734803851724407441381744350956613925261842560119775884", "price": "0.993", "size": "41.11", "side": "SELL", "hash": "5fce2bf2882666bb60023e3ef560f399aa59860a", "best_bid": "0.878", "best_ask": "0.988"}], "timestamp": "1769384078335", "event_type": "price_change"}}
{"_local_timestamp": "2026-01-25T23:34:38.687487+00:00", "data": {"market": "0xf8669cc099ad4008ee1735ae5ac1eb80ae005b249055d17df33fb086bcdfe83d", "price_changes": [{"asset_id": "67480800071998288404809609572612598087778955841531703375023453126691719294061", "price": "0.007", "size": "49.09", "side": "BUY", "hash": "625a53e40904262c4e10cd4ac6323ab539cc9af6", "best_bid": "0.012", "best_ask": "0.122"}, {"asset_id": "74412093647819275524093734803851724407441381744350956613925261842560119775884", "price": "0.993", "size": "49.09", "side": "SELL", "hash": "d3306de77ac12c54bfe5c1ab49b9657aafc41482", "best_bid": "0.878", "best_ask": "0.988"}], "timestamp": "1769384078616", "event_type": "price_change"}}
{"_local_timestamp": "2026-01-25T23:34:39.982759+00:00", "data": {"market": "0x58b372443f0e36b9aa1d4cf0ac87afd2b35022d651d5c8483412c5d01c4213f3", "price_changes": [{"asset_id": "99681691829842945294315330954935292622565244787309205761574804371180312761411", "price": "0.06", "size": "133", "side": "BUY", "hash": "2ecbf932352427e8fea2177dcf40fe875830f3cc", "best_bid": "0.83", "best_ask": "0.96"}, {"asset_id": "74863665767233302025566335346311422095508537077979116418767018100094979113099", "price": "0.94", "size": "133", "side": "SELL", "hash": "86f4ac3c47502ea6807edab78e411dd9326d9c6a", "best_bid": "0.04", "best_ask": "0.17"}], "timestamp": "1769384079823", "event_type": "price_change"}}
{"_local_timestamp": "2026-01-25T23:34:39.987589+00:00", "data": {"market": "0xb416bf4fbda79d068632d0e5447432d989b3cbf67c94d109159cb577186a2967", "price_changes": [{"asset_id": "109242542380145067807278323147433287088284156146991697158730836613947649714840", "price": "0.08", "size": "0", "side": "BUY", "hash": "5157d85e8b45ff4392a4cf588e392a7a4e5253a1", "best_bid": "0.582", "best_ask": "0.989"}, {"asset_id": "65231351761669550894073981540936017892501058975994169290932193425794398487063", "price": "0.92", "size": "0", "side": "SELL", "hash": "c71deae569c703b8953ad631cd5a0552b1c49f80", "best_bid": "0.011", "best_ask": "0.418"}], "timestamp": "1769384079822", "event_type": "price_change"}}
{"_local_timestamp": "2026-01-25T23:34:39.988371+00:00", "data": {"market": "0xb416bf4fbda79d068632d0e5447432d989b3cbf67c94d109159cb577186a2967", "price_changes": [{"asset_id": "109242542380145067807278323147433287088284156146991697158730836613947649714840", "price": "0.05", "size": "30", "side": "BUY", "hash": "5157d85e8b45ff4392a4cf588e392a7a4e5253a1", "best_bid": "0.582", "best_ask": "0.989"}, {"asset_id": "65231351761669550894073981540936017892501058975994169290932193425794398487063", "price": "0.95", "size": "30", "side": "SELL", "hash": "c71deae569c703b8953ad631cd5a0552b1c49f80", "best_bid": "0.011", "best_ask": "0.418"}], "timestamp": "1769384079822", "event_type": "price_change"}}
{"_local_timestamp": "2026-01-25T23:34:40.370970+00:00", "data": {"market": "0x58b372443f0e36b9aa1d4cf0ac87afd2b35022d651d5c8483412c5d01c4213f3", "price_changes": [{"asset_id": "99681691829842945294315330954935292622565244787309205761574804371180312761411", "price": "0.07", "size": "600", "side": "BUY", "hash": "c915ca45936630dc268af5c93270dde288538cbc", "best_bid": "0.83", "best_ask": "0.96"}, {"asset_id": "74863665767233302025566335346311422095508537077979116418767018100094979113099", "price": "0.93", "size": "600", "side": "SELL", "hash": "59837c0714059262ea9b8de55ab1e13dd63eff7a", "best_bid": "0.04", "best_ask": "0.17"}], "timestamp": "1769384080140", "event_type": "price_change"}}
{"_local_timestamp": "2026-01-25T23:34:41.515032+00:00", "data": {"market": "0x1940b49a58dbb1673e34e8d556dc86b882f8832a481707c67aba02603c32f4a6", "price_changes": [{"asset_id": "93793793289036935341608877259503853616462731627899477931478718740686048087884", "price": "0.103", "size": "0", "side": "BUY", "hash": "6932f04a528c3090985571a767a786354153a1cf", "best_bid": "0.818", "best_ask": "0.979"}, {"asset_id": "71369121321846330172912145857111778588565834210510367431821698951607223210980", "price": "0.897", "size": "0", "side": "SELL", "hash": "91c59195427d82e6fac3142de1d0f5bab5dd3d5c", "best_bid": "0.021", "best_ask": "0.182"}], "timestamp": "1769384081418", "event_type": "price_change"}}
{"_local_timestamp": "2026-01-25T23:34:41.538540+00:00", "data": {"market": "0xec3536934fc4072b6ec4f95541002b893a7e64193d89058a50b1300733d0577a", "price_changes": [{"asset_id": "96671476518786383904585530156908444908957428537143909392577226929673922053938", "price": "0.632", "size": "0", "side": "BUY", "hash": "9c3dcfb9c011bda1c6867fbc7fd38039e64b5725", "best_bid": "0.68", "best_ask": "0.991"}, {"asset_id": "32197429166700111536823754287092684333922425922201658989691857565621864128151", "price": "0.368", "size": "0", "side": "SELL", "hash": "8a3d13815cb2b4d4ded6f2f9edd36e64550a2151", "best_bid": "0.009", "best_ask": "0.32"}], "timestamp": "1769384081421", "event_type": "price_change"}}
{"_local_timestamp": "2026-01-25T23:34:41.546856+00:00", "data": {"market": "0x0ba39007f4ff1c2677f296b90188d544c2f80f9729c76a6f181a191543ceab82", "price_changes": [{"asset_id": "35783470881309485643248466709434569842971080886588261160663378071872348072260", "price": "0.808", "size": "0", "side": "BUY", "hash": "46bf5c9a72e1b77ebd8c7a82c4f0828ba4d884f8", "best_bid": "0.809", "best_ask": "0.995"}, {"asset_id": "35279195552426720847132209025903300157513105064872410280291719894882972533678", "price": "0.192", "size": "0", "side": "SELL", "hash": "97ed9142fc457898c893d82e22189cf0f67684b0", "best_bid": "0.005", "best_ask": "0.191"}], "timestamp": "1769384081422", "event_type": "price_change"}}
{"_local_timestamp": "2026-01-25T23:34:41.583047+00:00", "data": {"market": "0x3906ccd196f47f9cd177602071c3147a4b916ab60b1e317d5439c54fb520187d", "price_changes": [{"asset_id": "66628303295255675472790623870237847302694414310186008738086927666525449327926", "price": "0.073", "size": "0", "side": "BUY", "hash": "58e5dd9066da2daf7640c1bb2d1fdb2020fe4aa0", "best_bid": "0.891", "best_ask": "0.987"}, {"asset_id": "62082789175342153765549566755525855471250020053983528793359435486631209756539", "price": "0.927", "size": "0", "side": "SELL", "hash": "704cf39a1f0022deca5e9b97fa9edb64f4273e91", "best_bid": "0.013", "best_ask": "0.109"}], "timestamp": "1769384081421", "event_type": "price_change"}}
{"_local_timestamp": "2026-01-25T23:34:45.624775+00:00", "data": {"market": "0xf20f7af3ea74b16d623af198d6efb27d9d4ee98cfa96b1b6c8d4021d55436eb0", "price_changes": [{"asset_id": "8204205703682240679449476083075054464313606926136751077466819525464621562665", "price": "0.03", "size": "12.23", "side": "BUY", "hash": "1f95b68cc1994a0d01108adcc0c77aaba3a3b88c", "best_bid": "0.03", "best_ask": "0.13"}, {"asset_id": "79006550760303579457645886672312299229061887535391288753983510221472432105358", "price": "0.97", "size": "12.23", "side": "SELL", "hash": "f0411069f2e4debc52df93b4f34ed215d132cbe1", "best_bid": "0.87", "best_ask": "0.97"}], "timestamp": "1769384085560", "event_type": "price_change"}}
{"_local_timestamp": "2026-01-25T23:34:45.625481+00:00", "data": {"market": "0xf8669cc099ad4008ee1735ae5ac1eb80ae005b249055d17df33fb086bcdfe83d", "price_changes": [{"asset_id": "67480800071998288404809609572612598087778955841531703375023453126691719294061", "price": "0.007", "size": "41.11", "side": "BUY", "hash": "b102ad01474931c06b61e5992b973e27bfdc7259", "best_bid": "0.012", "best_ask": "0.122"}, {"asset_id": "74412093647819275524093734803851724407441381744350956613925261842560119775884", "price": "0.993", "size": "41.11", "side": "SELL", "hash": "8cd6051229597cc653b6eb8972e822747e555557", "best_bid": "0.878", "best_ask": "0.988"}], "timestamp": "1769384085560", "event_type": "price_change"}}
{"_local_timestamp": "2026-01-25T23:34:45.809239+00:00", "data": {"market": "0xf20f7af3ea74b16d623af198d6efb27d9d4ee98cfa96b1b6c8d4021d55436eb0", "price_changes": [{"asset_id": "8204205703682240679449476083075054464313606926136751077466819525464621562665", "price": "0.03", "size": "21.5", "side": "BUY", "hash": "a8da15e1455cf10090aa02dff2ac5a3730833b4c", "best_bid": "0.03", "best_ask": "0.13"}, {"asset_id": "79006550760303579457645886672312299229061887535391288753983510221472432105358", "price": "0.97", "size": "21.5", "side": "SELL", "hash": "50223ede3ca0f71694828ed9c93bcea93ec358d8", "best_bid": "0.87", "best_ask": "0.97"}], "timestamp": "1769384085746", "event_type": "price_change"}}
{"_local_timestamp": "2026-01-25T23:34:45.867983+00:00", "data": {"market": "0xf8669cc099ad4008ee1735ae5ac1eb80ae005b249055d17df33fb086bcdfe83d", "price_changes": [{"asset_id": "67480800071998288404809609572612598087778955841531703375023453126691719294061", "price": "0.007", "size": "49.09", "side": "BUY", "hash": "14c8705e7236ff88c2dca7f7f631ea3dda1f2aaa", "best_bid": "0.012", "best_ask": "0.122"}, {"asset_id": "74412093647819275524093734803851724407441381744350956613925261842560119775884", "price": "0.993", "size": "49.09", "side": "SELL", "hash": "41969626d6551ffb13504d718ca0b5aa9b9cc2d1", "best_bid": "0.878", "best_ask": "0.988"}], "timestamp": "1769384085798", "event_type": "price_change"}}
{"_local_timestamp": "2026-01-25T23:34:49.433126+00:00", "data": {"market": "0xf8669cc099ad4008ee1735ae5ac1eb80ae005b249055d17df33fb086bcdfe83d", "price_changes": [{"asset_id": "67480800071998288404809609572612598087778955841531703375023453126691719294061", "price": "0.007", "size": "41.11", "side": "BUY", "hash": "5e5190cdf283723ee56e39aa0105bb1456851fc4", "best_bid": "0.012", "best_ask": "0.122"}, {"asset_id": "74412093647819275524093734803851724407441381744350956613925261842560119775884", "price": "0.993", "size": "41.11", "side": "SELL", "hash": "cb914f3d0c3bba35358f2b553182d05d2c5c1418", "best_bid": "0.878", "best_ask": "0.988"}], "timestamp": "1769384089368", "event_type": "price_change"}}
{"_local_timestamp": "2026-01-25T23:34:49.729961+00:00", "data": {"market": "0xf8669cc099ad4008ee1735ae5ac1eb80ae005b249055d17df33fb086bcdfe83d", "price_changes": [{"asset_id": "67480800071998288404809609572612598087778955841531703375023453126691719294061", "price": "0.007", "size": "49.09", "side": "BUY", "hash": "94672b7a881528efbb1f2d4421ebb8b13ef22368", "best_bid": "0.012", "best_ask": "0.122"}, {"asset_id": "74412093647819275524093734803851724407441381744350956613925261842560119775884", "price": "0.993", "size": "49.09", "side": "SELL", "hash": "aac7e9e459f8334b3a0a8152c48fba72421a2fa9", "best_bid": "0.878", "best_ask": "0.988"}], "timestamp": "1769384089662", "event_type": "price_change"}}
{"_local_timestamp": "2026-01-25T23:34:50.010522+00:00", "data": {"market": "0x58b372443f0e36b9aa1d4cf0ac87afd2b35022d651d5c8483412c5d01c4213f3", "price_changes": [{"asset_id": "99681691829842945294315330954935292622565244787309205761574804371180312761411", "price": "0.06", "size": "33", "side": "BUY", "hash": "61ce114a44154ba3e7c58b362d639db60d0cd617", "best_bid": "0.83", "best_ask": "0.96"}, {"asset_id": "74863665767233302025566335346311422095508537077979116418767018100094979113099", "price": "0.94", "size": "33", "side": "SELL", "hash": "a087d00f88ac7ecbccfedc2c8758a18df94db05b", "best_bid": "0.04", "best_ask": "0.17"}], "timestamp": "1769384089936", "event_type": "price_change"}}
{"_local_timestamp": "2026-01-25T23:34:50.308685+00:00", "data": {"market": "0x58b372443f0e36b9aa1d4cf0ac87afd2b35022d651d5c8483412c5d01c4213f3", "price_changes": [{"asset_id": "99681691829842945294315330954935292622565244787309205761574804371180312761411", "price": "0.07", "size": "700", "side": "BUY", "hash": "39077064bbbf00fbb17682612adc51b1be716607", "best_bid": "0.83", "best_ask": "0.96"}, {"asset_id": "74863665767233302025566335346311422095508537077979116418767018100094979113099", "price": "0.93", "size": "700", "side": "SELL", "hash": "08962676adcda894097aa6c3339255d60a38612b", "best_bid": "0.04", "best_ask": "0.17"}], "timestamp": "1769384090233", "event_type": "price_change"}}
{"_local_timestamp": "2026-01-25T23:34:50.930451+00:00", "data": {"market": "0xf20f7af3ea74b16d623af198d6efb27d9d4ee98cfa96b1b6c8d4021d55436eb0", "price_changes": [{"asset_id": "8204205703682240679449476083075054464313606926136751077466819525464621562665", "price": "0.03", "size": "12.23", "side": "BUY", "hash": "755bdb7d3fa6770a4b7b99a2c61bef5ffc5549ee", "best_bid": "0.03", "best_ask": "0.13"}, {"asset_id": "79006550760303579457645886672312299229061887535391288753983510221472432105358", "price": "0.97", "size": "12.23", "side": "SELL", "hash": "785fc8e755009dac05ece9fa30cbacbf343a0270", "best_bid": "0.87", "best_ask": "0.97"}], "timestamp": "1769384090861", "event_type": "price_change"}}
{"_local_timestamp": "2026-01-25T23:34:50.931263+00:00", "data": {"market": "0xa38d137a148c4b1ec0e5a5bce42e130391bcc8086f93b4a42fb93870456fc720", "price_changes": [{"asset_id": "106570670068044891061840154694634029425579441331483581761385437733846502477972", "price": "0.051", "size": "6", "side": "SELL", "hash": "9f85a2fa1bbdf2109ca30be4d1b005f0c784053d", "best_bid": "0.012", "best_ask": "0.051"}, {"asset_id": "100952291322678954514417231357111610948515892742954751932425813530604840075554", "price": "0.949", "size": "6", "side": "BUY", "hash": "f7e785947102c87a9b8b24185de62d3c0df66b6a", "best_bid": "0.949", "best_ask": "0.988"}], "timestamp": "1769384090861", "event_type": "price_change"}}
{"_local_timestamp": "2026-01-25T23:34:50.932088+00:00", "data": {"market": "0xa38d137a148c4b1ec0e5a5bce42e130391bcc8086f93b4a42fb93870456fc720", "price_changes": [{"asset_id": "106570670068044891061840154694634029425579441331483581761385437733846502477972", "price": "0.055", "size": "0", "side": "SELL", "hash": "9f85a2fa1bbdf2109ca30be4d1b005f0c784053d", "best_bid": "0.012", "best_ask": "0.051"}, {"asset_id": "100952291322678954514417231357111610948515892742954751932425813530604840075554", "price": "0.945", "size": "0", "side": "BUY", "hash": "f7e785947102c87a9b8b24185de62d3c0df66b6a", "best_bid": "0.949", "best_ask": "0.988"}], "timestamp": "1769384090861", "event_type": "price_change"}}
{"_local_timestamp": "2026-01-25T23:34:51.492728+00:00", "data": {"market": "0xa38d137a148c4b1ec0e5a5bce42e130391bcc8086f93b4a42fb93870456fc720", "price_changes": [{"asset_id": "106570670068044891061840154694634029425579441331483581761385437733846502477972", "price": "0.058", "size": "18.93", "side": "SELL", "hash": "82f364acf2cb08bed168e50106fd144a13494fe5", "best_bid": "0.012", "best_ask": "0.051"}, {"asset_id": "100952291322678954514417231357111610948515892742954751932425813530604840075554", "price": "0.942", "size": "18.93", "side": "BUY", "hash": "1d0ad038699ff0119100f5038f586e9c64ec841a", "best_bid": "0.949", "best_ask": "0.988"}], "timestamp": "1769384091239", "event_type": "price_change"}}
{"_local_timestamp": "2026-01-25T23:34:51.493532+00:00", "data": {"market": "0xf20f7af3ea74b16d623af198d6efb27d9d4ee98cfa96b1b6c8d4021d55436eb0", "price_changes": [{"asset_id": "8204205703682240679449476083075054464313606926136751077466819525464621562665", "price": "0.03", "size": "21.5", "side": "BUY", "hash": "cebb3fb2548667e59fde46cbd77c9bfbb7752dfe", "best_bid": "0.03", "best_ask": "0.13"}, {"asset_id": "79006550760303579457645886672312299229061887535391288753983510221472432105358", "price": "0.97", "size": "21.5", "side": "SELL", "hash": "ba463d1d305cecb9e01062754d4585dbdd2b6b6f", "best_bid": "0.87", "best_ask": "0.97"}], "timestamp": "1769384091239", "event_type": "price_change"}}
{"_local_timestamp": "2026-01-25T23:34:51.494215+00:00", "data": {"market": "0xa38d137a148c4b1ec0e5a5bce42e130391bcc8086f93b4a42fb93870456fc720", "price_changes": [{"asset_id": "106570670068044891061840154694634029425579441331483581761385437733846502477972", "price": "0.05", "size": "9", "side": "SELL", "hash": "6b289a7e4d2302f845a974426bde90392429a8a5", "best_bid": "0.012", "best_ask": "0.05"}, {"asset_id": "100952291322678954514417231357111610948515892742954751932425813530604840075554", "price": "0.95", "size": "9", "side": "BUY", "hash": "fdbbdfd6d4d55762db017494fde9d76c85a41659", "best_bid": "0.95", "best_ask": "0.988"}], "timestamp": "1769384091240", "event_type": "price_change"}}
{"_local_timestamp": "2026-01-25T23:34:51.673373+00:00", "data": {"market": "0xa38d137a148c4b1ec0e5a5bce42e130391bcc8086f93b4a42fb93870456fc720", "price_changes": [{"asset_id": "106570670068044891061840154694634029425579441331483581761385437733846502477972", "price": "0.004", "size": "0", "side": "BUY", "hash": "33514310670c9ee969bb98524ad1b3d08f6d53fa", "best_bid": "0.012", "best_ask": "0.05"}, {"asset_id": "100952291322678954514417231357111610948515892742954751932425813530604840075554", "price": "0.996", "size": "0", "side": "SELL", "hash": "cb1a6c2806f6abcd3faa4792a2252e1e409bc785", "best_bid": "0.95", "best_ask": "0.988"}], "timestamp": "1769384091608", "event_type": "price_change"}}
{"_local_timestamp": "2026-01-25T23:34:52.101295+00:00", "data": {"market": "0xa38d137a148c4b1ec0e5a5bce42e130391bcc8086f93b4a42fb93870456fc720", "price_changes": [{"asset_id": "106570670068044891061840154694634029425579441331483581761385437733846502477972", "price": "0.004", "size": "53.42", "side": "BUY", "hash": "5a9f707f432561806ffc72732d3dd4c09ad63a4f", "best_bid": "0.012", "best_ask": "0.05"}, {"asset_id": "100952291322678954514417231357111610948515892742954751932425813530604840075554", "price": "0.996", "size": "53.42", "side": "SELL", "hash": "2e344423bcf47a2ac7f087b3476f891b7e400e3c", "best_bid": "0.95", "best_ask": "0.988"}], "timestamp": "1769384092031", "event_type": "price_change"}}
{"_local_timestamp": "2026-01-25T23:34:52.127121+00:00", "data": {"market": "0x1940b49a58dbb1673e34e8d556dc86b882f8832a481707c67aba02603c32f4a6", "price_changes": [{"asset_id": "71369121321846330172912145857111778588565834210510367431821698951607223210980", "price": "0.003", "size": "0", "side": "BUY", "hash": "424e58187f1f70127be03a73810921529ed3fbd1", "best_bid": "0.021", "best_ask": "0.182"}, {"asset_id": "93793793289036935341608877259503853616462731627899477931478718740686048087884", "price": "0.997", "size": "0", "side": "SELL", "hash": "d2b8d844b8cd6547da349ede0a948f2f807d42f4", "best_bid": "0.818", "best_ask": "0.979"}], "timestamp": "1769384092061", "event_type": "price_change"}}
{"_local_timestamp": "2026-01-25T23:34:52.161400+00:00", "data": {"market": "0xa38d137a148c4b1ec0e5a5bce42e130391bcc8086f93b4a42fb93870456fc720", "price_changes": [{"asset_id": "100952291322678954514417231357111610948515892742954751932425813530604840075554", "price": "0.936", "size": "100", "side": "BUY", "hash": "7bd0cae7419cfb9ec10f5315cfa2170836a02517", "best_bid": "0.95", "best_ask": "0.988"}, {"asset_id": "106570670068044891061840154694634029425579441331483581761385437733846502477972", "price": "0.064", "size": "100", "side": "SELL", "hash": "8ffe76d8e82ab3d1c79bdfcbfc4c2b8d133529fd", "best_bid": "0.012", "best_ask": "0.05"}], "timestamp": "1769384092094", "event_type": "price_change"}}
{"_local_timestamp": "2026-01-25T23:34:52.544776+00:00", "data": {"market": "0x1940b49a58dbb1673e34e8d556dc86b882f8832a481707c67aba02603c32f4a6", "price_changes": [{"asset_id": "71369121321846330172912145857111778588565834210510367431821698951607223210980", "price": "0.002", "size": "218.44", "side": "BUY", "hash": "91f785b4a48409d8971286a9e51c0a0c7d937de5", "best_bid": "0.021", "best_ask": "0.182"}, {"asset_id": "93793793289036935341608877259503853616462731627899477931478718740686048087884", "price": "0.998", "size": "218.44", "side": "SELL", "hash": "5275df48a4b0ccbbc0bc8220ced5b9463ee1c4d6", "best_bid": "0.818", "best_ask": "0.979"}], "timestamp": "1769384092480", "event_type": "price_change"}}
{"_local_timestamp": "2026-01-25T23:34:53.444746+00:00", "data": {"market": "0xccb49e0802c9ada89016c5f6f9933847455b736228812d0707a88e014804a630", "price_changes": [{"asset_id": "81304145828607624927593781798310463714484865200409152894719292343497594428963", "price": "0.03", "size": "8.47", "side": "BUY", "hash": "4eeeb365085569a656957ca52335369b07832c69", "best_bid": "0.08", "best_ask": "0.2"}, {"asset_id": "79795882971791559735842491100915770382923497517929862466123107473219678670981", "price": "0.97", "size": "8.47", "side": "SELL", "hash": "58667d72ebba87018f252168b670d753f6734133", "best_bid": "0.8", "best_ask": "0.92"}], "timestamp": "1769384093374", "event_type": "price_change"}}
{"_local_timestamp": "2026-01-25T23:34:53.730575+00:00", "data": {"market": "0xccb49e0802c9ada89016c5f6f9933847455b736228812d0707a88e014804a630", "price_changes": [{"asset_id": "81304145828607624927593781798310463714484865200409152894719292343497594428963", "price": "0.03", "size": "26.29", "side": "BUY", "hash": "6744262a858e92294c71e0a99fa0723899ba6983", "best_bid": "0.08", "best_ask": "0.2"}, {"asset_id": "79795882971791559735842491100915770382923497517929862466123107473219678670981", "price": "0.97", "size": "26.29", "side": "SELL", "hash": "af586caf87fcf9f8e235f510dd716c141b9e8590", "best_bid": "0.8", "best_ask": "0.92"}], "timestamp": "1769384093663", "event_type": "price_change"}}
{"_local_timestamp": "2026-01-25T23:34:55.360896+00:00", "data": {"market": "0xf8669cc099ad4008ee1735ae5ac1eb80ae005b249055d17df33fb086bcdfe83d", "price_changes": [{"asset_id": "67480800071998288404809609572612598087778955841531703375023453126691719294061", "price": "0.007", "size": "41.11", "side": "BUY", "hash": "52cc4ab30e8b7d03ebbad47770aaca3066fce217", "best_bid": "0.012", "best_ask": "0.122"}, {"asset_id": "74412093647819275524093734803851724407441381744350956613925261842560119775884", "price": "0.993", "size": "41.11", "side": "SELL", "hash": "74ae0e95669d02b6ba4510bd4d1def765ee8b452", "best_bid": "0.878", "best_ask": "0.988"}], "timestamp": "1769384095253", "event_type": "price_change"}}
{"_local_timestamp": "2026-01-25T23:34:55.545509+00:00", "data": {"market": "0xf8669cc099ad4008ee1735ae5ac1eb80ae005b249055d17df33fb086bcdfe83d", "price_changes": [{"asset_id": "67480800071998288404809609572612598087778955841531703375023453126691719294061", "price": "0.008", "size": "13.25", "side": "BUY", "hash": "52cbaa110e80bd094db4dc0a37c408e38ec37f7a", "best_bid": "0.012", "best_ask": "0.122"}, {"asset_id": "74412093647819275524093734803851724407441381744350956613925261842560119775884", "price": "0.992", "size": "13.25", "side": "SELL", "hash": "3bbbc8f76e9fda0a18145f9764422356928cb6e4", "best_bid": "0.878", "best_ask": "0.988"}], "timestamp": "1769384095466", "event_type": "price_change"}}
{"_local_timestamp": "2026-01-25T23:34:56.769264+00:00", "data": {"market": "0x5f8db7b536d9a1b47ae5098f9a3b9bc28ed87ad11ccdd70b8cab89d6fc702a98", "price_changes": [{"asset_id": "76804568100653929306239353743991896140934618197277967262912463304017766583671", "price": "0.003", "size": "31.24", "side": "BUY", "hash": "4d9568984c72f8c7a747148f03154bf7225b4386", "best_bid": "0.022", "best_ask": "0.046"}, {"asset_id": "75617257166140356462865461039305745735174774217559907306919128701083195276195", "price": "0.997", "size": "31.24", "side": "SELL", "hash": "09c7bfc03d09c4ef2a873fa457295e1bde659a70", "best_bid": "0.954", "best_ask": "0.978"}], "timestamp": "1769384096699", "event_type": "price_change"}}
{"_local_timestamp": "2026-01-25T23:34:57.133825+00:00", "data": {"market": "0x5f8db7b536d9a1b47ae5098f9a3b9bc28ed87ad11ccdd70b8cab89d6fc702a98", "price_changes": [{"asset_id": "76804568100653929306239353743991896140934618197277967262912463304017766583671", "price": "0.003", "size": "212.6", "side": "BUY", "hash": "daf487b6c6d7da628959adb094e4b0c273e65b7d", "best_bid": "0.022", "best_ask": "0.046"}, {"asset_id": "75617257166140356462865461039305745735174774217559907306919128701083195276195", "price": "0.997", "size": "212.6", "side": "SELL", "hash": "341f15d11299bb6d8eaf559ae8ab7ce42a2737c6", "best_bid": "0.954", "best_ask": "0.978"}], "timestamp": "1769384097023", "event_type": "price_change"}}
{"_local_timestamp": "2026-01-25T23:34:59.378441+00:00", "data": {"market": "0xf20f7af3ea74b16d623af198d6efb27d9d4ee98cfa96b1b6c8d4021d55436eb0", "price_changes": [{"asset_id": "8204205703682240679449476083075054464313606926136751077466819525464621562665", "price": "0.03", "size": "12.23", "side": "BUY", "hash": "7fd48458e83d8849a3e810d6560ac564aa7fa9b5", "best_bid": "0.03", "best_ask": "0.13"}, {"asset_id": "79006550760303579457645886672312299229061887535391288753983510221472432105358", "price": "0.97", "size": "12.23", "side": "SELL", "hash": "cdf0cb93d97aa18defa51d20723dbffaa2a08d4d", "best_bid": "0.87", "best_ask": "0.97"}], "timestamp": "1769384099313", "event_type": "price_change"}}
{"_local_timestamp": "2026-01-25T23:34:59.818358+00:00", "data": {"market": "0xf20f7af3ea74b16d623af198d6efb27d9d4ee98cfa96b1b6c8d4021d55436eb0", "price_changes": [{"asset_id": "8204205703682240679449476083075054464313606926136751077466819525464621562665", "price": "0.03", "size": "21.5", "side": "BUY", "hash": "67e9d121845e3013a6dbfe35afb721bde5d8d7a0", "best_bid": "0.03", "best_ask": "0.13"}, {"asset_id": "79006550760303579457645886672312299229061887535391288753983510221472432105358", "price": "0.97", "size": "21.5", "side": "SELL", "hash": "86d7e2f76f93f55bb06fb457205859da4ffeb6d3", "best_bid": "0.87", "best_ask": "0.97"}], "timestamp": "1769384099746", "event_type": "price_change"}}
{"_local_timestamp": "2026-01-25T23:35:01.014455+00:00", "data": {"market": "0xa38d137a148c4b1ec0e5a5bce42e130391bcc8086f93b4a42fb93870456fc720", "price_changes": [{"asset_id": "106570670068044891061840154694634029425579441331483581761385437733846502477972", "price": "0.065", "size": "0", "side": "SELL", "hash": "28e6591c1c6a61f8011b03cda3e6fc7c9e0dcf71", "best_bid": "0.012", "best_ask": "0.05"}, {"asset_id": "100952291322678954514417231357111610948515892742954751932425813530604840075554", "price": "0.935", "size": "0", "side": "BUY", "hash": "e8ecb0623f96a93fbdf457a5d1d65d7439746c87", "best_bid": "0.95", "best_ask": "0.988"}], "timestamp": "1769384100915", "event_type": "price_change"}}
{"_local_timestamp": "2026-01-25T23:35:01.015250+00:00", "data": {"market": "0xa38d137a148c4b1ec0e5a5bce42e130391bcc8086f93b4a42fb93870456fc720", "price_changes": [{"asset_id": "106570670068044891061840154694634029425579441331483581761385437733846502477972", "price": "0.059", "size": "0", "side": "SELL", "hash": "28e6591c1c6a61f8011b03cda3e6fc7c9e0dcf71", "best_bid": "0.012", "best_ask": "0.05"}, {"asset_id": "100952291322678954514417231357111610948515892742954751932425813530604840075554", "price": "0.941", "size": "0", "side": "BUY", "hash": "e8ecb0623f96a93fbdf457a5d1d65d7439746c87", "best_bid": "0.95", "best_ask": "0.988"}], "timestamp": "1769384100915", "event_type": "price_change"}}
{"_local_timestamp": "2026-01-25T23:35:01.016105+00:00", "data": {"market": "0xa38d137a148c4b1ec0e5a5bce42e130391bcc8086f93b4a42fb93870456fc720", "price_changes": [{"asset_id": "106570670068044891061840154694634029425579441331483581761385437733846502477972", "price": "0.064", "size": "0", "side": "SELL", "hash": "28e6591c1c6a61f8011b03cda3e6fc7c9e0dcf71", "best_bid": "0.012", "best_ask": "0.05"}, {"asset_id": "100952291322678954514417231357111610948515892742954751932425813530604840075554", "price": "0.936", "size": "0", "side": "BUY", "hash": "e8ecb0623f96a93fbdf457a5d1d65d7439746c87", "best_bid": "0.95", "best_ask": "0.988"}], "timestamp": "1769384100915", "event_type": "price_change"}}
{"_local_timestamp": "2026-01-25T23:35:01.377869+00:00", "data": {"market": "0xa38d137a148c4b1ec0e5a5bce42e130391bcc8086f93b4a42fb93870456fc720", "price_changes": [{"asset_id": "106570670068044891061840154694634029425579441331483581761385437733846502477972", "price": "0.08", "size": "32.27", "side": "SELL", "hash": "449d0b51fcd0102c6db2689ac21d5a7be3f43fed", "best_bid": "0.012", "best_ask": "0.05"}, {"asset_id": "100952291322678954514417231357111610948515892742954751932425813530604840075554", "price": "0.92", "size": "32.27", "side": "BUY", "hash": "7eeed4f3cba33f52e8bdc8b074263c4faef53189", "best_bid": "0.95", "best_ask": "0.988"}], "timestamp": "1769384101271", "event_type": "price_change"}}
{"_local_timestamp": "2026-01-25T23:35:01.378653+00:00", "data": {"market": "0xa38d137a148c4b1ec0e5a5bce42e130391bcc8086f93b4a42fb93870456fc720", "price_changes": [{"asset_id": "106570670068044891061840154694634029425579441331483581761385437733846502477972", "price": "0.091", "size": "64.9", "side": "SELL", "hash": "12587884acf2947320847cc6aedc492c86125999", "best_bid": "0.012", "best_ask": "0.05"}, {"asset_id": "100952291322678954514417231357111610948515892742954751932425813530604840075554", "price": "0.909", "size": "64.9", "side": "BUY", "hash": "1bc48d74a1cdf982f83a3cb7c1b0fed70d785c98", "best_bid": "0.95", "best_ask": "0.988"}], "timestamp": "1769384101271", "event_type": "price_change"}}
{"_local_timestamp": "2026-01-25T23:35:01.379311+00:00", "data": {"market": "0xa38d137a148c4b1ec0e5a5bce42e130391bcc8086f93b4a42fb93870456fc720", "price_changes": [{"asset_id": "106570670068044891061840154694634029425579441331483581761385437733846502477972", "price": "0.089", "size": "100", "side": "SELL", "hash": "ccaf2e1b496a974aa652caab1f0976220c4a02e9", "best_bid": "0.012", "best_ask": "0.05"}, {"asset_id": "100952291322678954514417231357111610948515892742954751932425813530604840075554", "price": "0.911", "size": "100", "side": "BUY", "hash": "332387a0ea3e1de9f1b38b836e55c0a454ce8dde", "best_bid": "0.95", "best_ask": "0.988"}], "timestamp": "1769384101272", "event_type": "price_change"}}
{"_local_timestamp": "2026-01-25T23:35:02.845222+00:00", "data": {"market": "0xf8669cc099ad4008ee1735ae5ac1eb80ae005b249055d17df33fb086bcdfe83d", "price_changes": [{"asset_id": "67480800071998288404809609572612598087778955841531703375023453126691719294061", "price": "0.008", "size": "6.26", "side": "BUY", "hash": "7ad1883add2207bd14fcd927b1aac30c31383c19", "best_bid": "0.012", "best_ask": "0.122"}, {"asset_id": "74412093647819275524093734803851724407441381744350956613925261842560119775884", "price": "0.992", "size": "6.26", "side": "SELL", "hash": "85582a01c6ca3eeebbf1a1c9bc1b8cab20fedc95", "best_bid": "0.878", "best_ask": "0.988"}], "timestamp": "1769384102696", "event_type": "price_change"}}
{"_local_timestamp": "2026-01-25T23:35:03.096221+00:00", "data": {"market": "0xf8669cc099ad4008ee1735ae5ac1eb80ae005b249055d17df33fb086bcdfe83d", "price_changes": [{"asset_id": "67480800071998288404809609572612598087778955841531703375023453126691719294061", "price": "0.007", "size": "49.09", "side": "BUY", "hash": "62df2ecaee7d4875d217432ed905acea47369335", "best_bid": "0.012", "best_ask": "0.122"}, {"asset_id": "74412093647819275524093734803851724407441381744350956613925261842560119775884", "price": "0.993", "size": "49.09", "side": "SELL", "hash": "6161eae84943a849b2e6f1be1fe4c333949116fb", "best_bid": "0.878", "best_ask": "0.988"}], "timestamp": "1769384102961", "event_type": "price_change"}}
{"_local_timestamp": "2026-01-25T23:35:08.725214+00:00", "data": {"market": "0xf20f7af3ea74b16d623af198d6efb27d9d4ee98cfa96b1b6c8d4021d55436eb0", "price_changes": [{"asset_id": "8204205703682240679449476083075054464313606926136751077466819525464621562665", "price": "0.03", "size": "12.23", "side": "BUY", "hash": "f2b82de301f71fa30ce75f8b825dc0617bea26e4", "best_bid": "0.03", "best_ask": "0.13"}, {"asset_id": "79006550760303579457645886672312299229061887535391288753983510221472432105358", "price": "0.97", "size": "12.23", "side": "SELL", "hash": "bc4f615ca551dd0993b1003a2e20f09e0d36b7c1", "best_bid": "0.87", "best_ask": "0.97"}], "timestamp": "1769384108532", "event_type": "price_change"}}
{"_local_timestamp": "2026-01-25T23:35:09.014976+00:00", "data": {"market": "0xf20f7af3ea74b16d623af198d6efb27d9d4ee98cfa96b1b6c8d4021d55436eb0", "price_changes": [{"asset_id": "8204205703682240679449476083075054464313606926136751077466819525464621562665", "price": "0.03", "size": "21.5", "side": "BUY", "hash": "d75960d8b29cc76ede7ab476ef5935096851f0b6", "best_bid": "0.03", "best_ask": "0.13"}, {"asset_id": "79006550760303579457645886672312299229061887535391288753983510221472432105358", "price": "0.97", "size": "21.5", "side": "SELL", "hash": "093dd2e11e89db017e83283a9b6bed9056919f2a", "best_bid": "0.87", "best_ask": "0.97"}], "timestamp": "1769384108814", "event_type": "price_change"}}
{"_local_timestamp": "2026-01-25T23:35:10.102545+00:00", "data": {"market": "0xccb49e0802c9ada89016c5f6f9933847455b736228812d0707a88e014804a630", "price_changes": [{"asset_id": "79795882971791559735842491100915770382923497517929862466123107473219678670981", "price": "0.1", "size": "0", "side": "BUY", "hash": "7b05a0dddaa4b9d683fcf32992c686bc64603e98", "best_bid": "0.8", "best_ask": "0.92"}, {"asset_id": "81304145828607624927593781798310463714484865200409152894719292343497594428963", "price": "0.9", "size": "0", "side": "SELL", "hash": "c19076c7ce0b56f77dac4725aa8ad2a0772f48ad", "best_bid": "0.08", "best_ask": "0.2"}], "timestamp": "1769384109904", "event_type": "price_change"}}
{"_local_timestamp": "2026-01-25T23:35:10.361916+00:00", "data": {"market": "0xccb49e0802c9ada89016c5f6f9933847455b736228812d0707a88e014804a630", "price_changes": [{"asset_id": "79795882971791559735842491100915770382923497517929862466123107473219678670981", "price": "0.1", "size": "7.35", "side": "BUY", "hash": "3608fd3b848bce252ca63f83a1140e3101c59491", "best_bid": "0.8", "best_ask": "0.92"}, {"asset_id": "81304145828607624927593781798310463714484865200409152894719292343497594428963", "price": "0.9", "size": "7.35", "side": "SELL", "hash": "ac5f085a3a20d78b88580d62335b6131a486fac4", "best_bid": "0.08", "best_ask": "0.2"}], "timestamp": "1769384110175", "event_type": "price_change"}}
{"_local_timestamp": "2026-01-25T23:35:11.098173+00:00", "data": {"market": "0xf8669cc099ad4008ee1735ae5ac1eb80ae005b249055d17df33fb086bcdfe83d", "price_changes": [{"asset_id": "67480800071998288404809609572612598087778955841531703375023453126691719294061", "price": "0.007", "size": "41.11", "side": "BUY", "hash": "fc21310c32d0bfe6f0a3344b86c24888c7d800a1", "best_bid": "0.012", "best_ask": "0.122"}, {"asset_id": "74412093647819275524093734803851724407441381744350956613925261842560119775884", "price": "0.993", "size": "41.11", "side": "SELL", "hash": "e6b8140d8f9531a8b6b947a9aa3ec1c5b62b5866", "best_bid": "0.878", "best_ask": "0.988"}], "timestamp": "1769384110777", "event_type": "price_change"}}
{"_local_timestamp": "2026-01-25T23:35:11.271233+00:00", "data": {"market": "0xf8669cc099ad4008ee1735ae5ac1eb80ae005b249055d17df33fb086bcdfe83d", "price_changes": [{"asset_id": "67480800071998288404809609572612598087778955841531703375023453126691719294061", "price": "0.008", "size": "13.25", "side": "BUY", "hash": "8082f75f371b6bc9369488b6ac72c1dc00467685", "best_bid": "0.012", "best_ask": "0.122"}, {"asset_id": "74412093647819275524093734803851724407441381744350956613925261842560119775884", "price": "0.992", "size": "13.25", "side": "SELL", "hash": "af5eee1c539965d9be70ffcb3a8930ce7e98938a", "best_bid": "0.878", "best_ask": "0.988"}], "timestamp": "1769384111067", "event_type": "price_change"}}
{"_local_timestamp": "2026-01-25T23:35:13.747601+00:00", "data": {"market": "0xec3536934fc4072b6ec4f95541002b893a7e64193d89058a50b1300733d0577a", "price_changes": [{"asset_id": "96671476518786383904585530156908444908957428537143909392577226929673922053938", "price": "0.634", "size": "45", "side": "BUY", "hash": "abed7c59a7fb330632a4996e31b0bf7f5bc38e48", "best_bid": "0.68", "best_ask": "0.991"}, {"asset_id": "32197429166700111536823754287092684333922425922201658989691857565621864128151", "price": "0.366", "size": "45", "side": "SELL", "hash": "8ce068355327326bbdbc04ab3136fd40be61a999", "best_bid": "0.009", "best_ask": "0.32"}], "timestamp": "1769384113479", "event_type": "price_change"}}
{"_local_timestamp": "2026-01-25T23:35:13.762103+00:00", "data": {"market": "0x0ba39007f4ff1c2677f296b90188d544c2f80f9729c76a6f181a191543ceab82", "price_changes": [{"asset_id": "35783470881309485643248466709434569842971080886588261160663378071872348072260", "price": "0.81", "size": "45", "side": "BUY", "hash": "852b969ed1fea979fb78c72b826363e72a1d10a2", "best_bid": "0.81", "best_ask": "0.995"}, {"asset_id": "35279195552426720847132209025903300157513105064872410280291719894882972533678", "price": "0.19", "size": "45", "side": "SELL", "hash": "d8bb04899dae9f838c00c5f49de6ba8c923fa6d9", "best_bid": "0.005", "best_ask": "0.19"}], "timestamp": "1769384113517", "event_type": "price_change"}}
{"_local_timestamp": "2026-01-25T23:35:13.811423+00:00", "data": {"market": "0x1940b49a58dbb1673e34e8d556dc86b882f8832a481707c67aba02603c32f4a6", "price_changes": [{"asset_id": "93793793289036935341608877259503853616462731627899477931478718740686048087884", "price": "0.103", "size": "45", "side": "BUY", "hash": "ce7b65bbb67d7d3267ba6d7af1ddd6968ec021df", "best_bid": "0.818", "best_ask": "0.979"}, {"asset_id": "71369121321846330172912145857111778588565834210510367431821698951607223210980", "price": "0.897", "size": "45", "side": "SELL", "hash": "356de23671971158b832a0c44e9a793240f9411b", "best_bid": "0.021", "best_ask": "0.182"}], "timestamp": "1769384113588", "event_type": "price_change"}}
{"_local_timestamp": "2026-01-25T23:35:13.894566+00:00", "data": {"market": "0x3906ccd196f47f9cd177602071c3147a4b916ab60b1e317d5439c54fb520187d", "price_changes": [{"asset_id": "66628303295255675472790623870237847302694414310186008738086927666525449327926", "price": "0.075", "size": "45", "side": "BUY", "hash": "2bd703ec5d2b6fbd403289aa22290a198a409941", "best_bid": "0.891", "best_ask": "0.987"}, {"asset_id": "62082789175342153765549566755525855471250020053983528793359435486631209756539", "price": "0.925", "size": "45", "side": "SELL", "hash": "756c7a8a39cec56bd5e9dac68904b82ba4415ca5", "best_bid": "0.013", "best_ask": "0.109"}], "timestamp": "1769384113667", "event_type": "price_change"}}
{"_local_timestamp": "2026-01-25T23:35:16.389095+00:00", "data": {"market": "0x58b372443f0e36b9aa1d4cf0ac87afd2b35022d651d5c8483412c5d01c4213f3", "price_changes": [{"asset_id": "99681691829842945294315330954935292622565244787309205761574804371180312761411", "price": "0.44", "size": "0", "side": "BUY", "hash": "590df3009823d7451bda918792314b4ca4a387fa", "best_bid": "0.83", "best_ask": "0.96"}, {"asset_id": "74863665767233302025566335346311422095508537077979116418767018100094979113099", "price": "0.56", "size": "0", "side": "SELL", "hash": "6a19bb157613240043774b06e633e85e4d9c516f", "best_bid": "0.04", "best_ask": "0.17"}], "timestamp": "1769384116158", "event_type": "price_change"}}
{"_local_timestamp": "2026-01-25T23:35:16.613955+00:00", "data": {"market": "0x58b372443f0e36b9aa1d4cf0ac87afd2b35022d651d5c8483412c5d01c4213f3", "price_changes": [{"asset_id": "99681691829842945294315330954935292622565244787309205761574804371180312761411", "price": "0.44", "size": "5", "side": "BUY", "hash": "968728e5a31aeff0e28071a3e58df6938374ce62", "best_bid": "0.83", "best_ask": "0.96"}, {"asset_id": "74863665767233302025566335346311422095508537077979116418767018100094979113099", "price": "0.56", "size": "5", "side": "SELL", "hash": "fb57b59e6332a074dc39c5d1b4cbc9ca2d2d637a", "best_bid": "0.04", "best_ask": "0.17"}], "timestamp": "1769384116393", "event_type": "price_change"}}
{"_local_timestamp": "2026-01-25T23:35:21.195309+00:00", "data": {"market": "0xf20f7af3ea74b16d623af198d6efb27d9d4ee98cfa96b1b6c8d4021d55436eb0", "price_changes": [{"asset_id": "8204205703682240679449476083075054464313606926136751077466819525464621562665", "price": "0.03", "size": "12.23", "side": "BUY", "hash": "98c41f536850e66be3aaced710e13a52140f7fc0", "best_bid": "0.03", "best_ask": "0.13"}, {"asset_id": "79006550760303579457645886672312299229061887535391288753983510221472432105358", "price": "0.97", "size": "12.23", "side": "SELL", "hash": "275784eeaf03fe0e528ecff0595e64a40c491de4", "best_bid": "0.87", "best_ask": "0.97"}], "timestamp": "1769384120983", "event_type": "price_change"}}
{"_local_timestamp": "2026-01-25T23:35:21.418445+00:00", "data": {"market": "0xf20f7af3ea74b16d623af198d6efb27d9d4ee98cfa96b1b6c8d4021d55436eb0", "price_changes": [{"asset_id": "8204205703682240679449476083075054464313606926136751077466819525464621562665", "price": "0.03", "size": "21.5", "side": "BUY", "hash": "613b562ccc69e8f9648f21d667f01486cb4f5d41", "best_bid": "0.03", "best_ask": "0.13"}, {"asset_id": "79006550760303579457645886672312299229061887535391288753983510221472432105358", "price": "0.97", "size": "21.5", "side": "SELL", "hash": "149af7f7917a342fdf38bc29eec51495e76c2d69", "best_bid": "0.87", "best_ask": "0.97"}], "timestamp": "1769384121202", "event_type": "price_change"}}
{"_local_timestamp": "2026-01-25T23:35:22.063242+00:00", "data": {"market": "0xf8669cc099ad4008ee1735ae5ac1eb80ae005b249055d17df33fb086bcdfe83d", "price_changes": [{"asset_id": "67480800071998288404809609572612598087778955841531703375023453126691719294061", "price": "0.008", "size": "6.26", "side": "BUY", "hash": "9cbe0a5dfe0c8f443a3bd7bad39c52098b3e427b", "best_bid": "0.012", "best_ask": "0.122"}, {"asset_id": "74412093647819275524093734803851724407441381744350956613925261842560119775884", "price": "0.992", "size": "6.26", "side": "SELL", "hash": "1f55e257b861a6d053cc6a45d4c114603b7c64eb", "best_bid": "0.878", "best_ask": "0.988"}], "timestamp": "1769384121855", "event_type": "price_change"}}
{"_local_timestamp": "2026-01-25T23:35:22.332288+00:00", "data": {"market": "0xf8669cc099ad4008ee1735ae5ac1eb80ae005b249055d17df33fb086bcdfe83d", "price_changes": [{"asset_id": "67480800071998288404809609572612598087778955841531703375023453126691719294061", "price": "0.007", "size": "49.09", "side": "BUY", "hash": "00dda2deee147742660eb42d45da4969a7654818", "best_bid": "0.012", "best_ask": "0.122"}, {"asset_id": "74412093647819275524093734803851724407441381744350956613925261842560119775884", "price": "0.993", "size": "49.09", "side": "SELL", "hash": "facba3d530254c320303f4845a9b969e8c1d599c", "best_bid": "0.878", "best_ask": "0.988"}], "timestamp": "1769384122122", "event_type": "price_change"}}
{"_local_timestamp": "2026-01-25T23:35:23.289616+00:00", "data": {"market": "0x0ba39007f4ff1c2677f296b90188d544c2f80f9729c76a6f181a191543ceab82", "price_changes": [{"asset_id": "35279195552426720847132209025903300157513105064872410280291719894882972533678", "price": "0.001", "size": "4572.49", "side": "BUY", "hash": "dd578a9221b8588112af695f3b8541e2ea9905d9", "best_bid": "0.005", "best_ask": "0.19"}, {"asset_id": "35783470881309485643248466709434569842971080886588261160663378071872348072260", "price": "0.999", "size": "4572.49", "side": "SELL", "hash": "a6a31f69bee597178529b2af32df218a14fdb1cc", "best_bid": "0.81", "best_ask": "0.995"}], "timestamp": "1769384123053", "event_type": "price_change"}}
{"_local_timestamp": "2026-01-25T23:35:23.518087+00:00", "data": {"market": "0x0ba39007f4ff1c2677f296b90188d544c2f80f9729c76a6f181a191543ceab82", "price_changes": [{"asset_id": "35279195552426720847132209025903300157513105064872410280291719894882972533678", "price": "0.001", "size": "4665.09", "side": "BUY", "hash": "e03560e9589089e1c1fa0d0dec3949b73ac9c13a", "best_bid": "0.005", "best_ask": "0.19"}, {"asset_id": "35783470881309485643248466709434569842971080886588261160663378071872348072260", "price": "0.999", "size": "4665.09", "side": "SELL", "hash": "314118fcd5be7806d1a777edc92bff698ab341bf", "best_bid": "0.81", "best_ask": "0.995"}], "timestamp": "1769384123323", "event_type": "price_change"}}
{"_local_timestamp": "2026-01-25T23:35:26.075673+00:00", "data": {"market": "0xf8669cc099ad4008ee1735ae5ac1eb80ae005b249055d17df33fb086bcdfe83d", "price_changes": [{"asset_id": "74412093647819275524093734803851724407441381744350956613925261842560119775884", "price": "0.36", "size": "0", "side": "BUY", "hash": "e036b7706adfecf2205a11b62fcde5dc97b35781", "best_bid": "0.878", "best_ask": "0.988"}, {"asset_id": "67480800071998288404809609572612598087778955841531703375023453126691719294061", "price": "0.64", "size": "0", "side": "SELL", "hash": "7bccfbf7d319573b3d1964449104aad1a9387a9f", "best_bid": "0.012", "best_ask": "0.122"}], "timestamp": "1769384125862", "event_type": "price_change"}}
{"_local_timestamp": "2026-01-25T23:35:26.314133+00:00", "data": {"market": "0xf8669cc099ad4008ee1735ae5ac1eb80ae005b249055d17df33fb086bcdfe83d", "price_changes": [{"asset_id": "74412093647819275524093734803851724407441381744350956613925261842560119775884", "price": "0.36", "size": "5", "side": "BUY", "hash": "ecba7881bcba5013940f10995ebca1a109fe3479", "best_bid": "0.878", "best_ask": "0.988"}, {"asset_id": "67480800071998288404809609572612598087778955841531703375023453126691719294061", "price": "0.64", "size": "5", "side": "SELL", "hash": "40032c25091ad50a2eee6bfc2efbb9a71238ac65", "best_bid": "0.012", "best_ask": "0.122"}], "timestamp": "1769384126111", "event_type": "price_change"}}
{"_local_timestamp": "2026-01-25T23:35:40.079300+00:00", "data": {"market": "0xf8669cc099ad4008ee1735ae5ac1eb80ae005b249055d17df33fb086bcdfe83d", "price_changes": [{"asset_id": "67480800071998288404809609572612598087778955841531703375023453126691719294061", "price": "0.007", "size": "41.11", "side": "BUY", "hash": "57702a5d1cd751c255a12d36bc122957ea0d90ac", "best_bid": "0.012", "best_ask": "0.122"}, {"asset_id": "74412093647819275524093734803851724407441381744350956613925261842560119775884", "price": "0.993", "size": "41.11", "side": "SELL", "hash": "9acb3972ccddf4080f24f4ca286acc99f7d0d239", "best_bid": "0.878", "best_ask": "0.988"}], "timestamp": "1769384140012", "event_type": "price_change"}}
{"_local_timestamp": "2026-01-25T23:35:40.462432+00:00", "data": {"market": "0xf8669cc099ad4008ee1735ae5ac1eb80ae005b249055d17df33fb086bcdfe83d", "price_changes": [{"asset_id": "67480800071998288404809609572612598087778955841531703375023453126691719294061", "price": "0.007", "size": "49.09", "side": "BUY", "hash": "39a700f44acdb91bdf0dc42cbdd4b826dc71e9c0", "best_bid": "0.012", "best_ask": "0.122"}, {"asset_id": "74412093647819275524093734803851724407441381744350956613925261842560119775884", "price": "0.993", "size": "49.09", "side": "SELL", "hash": "251d19560982dcf19965453c6c13cf83d6b16ed1", "best_bid": "0.878", "best_ask": "0.988"}], "timestamp": "1769384140395", "event_type": "price_change"}}
{"_local_timestamp": "2026-01-25T23:35:43.322580+00:00", "data": {"market": "0xf20f7af3ea74b16d623af198d6efb27d9d4ee98cfa96b1b6c8d4021d55436eb0", "price_changes": [{"asset_id": "8204205703682240679449476083075054464313606926136751077466819525464621562665", "price": "0.03", "size": "12.23", "side": "BUY", "hash": "b611775bd84d62d9d93a18e378e678b1744c0f84", "best_bid": "0.03", "best_ask": "0.13"}, {"asset_id": "79006550760303579457645886672312299229061887535391288753983510221472432105358", "price": "0.97", "size": "12.23", "side": "SELL", "hash": "c201cf332878393de52ce3f3af19ded27c3dcbdc", "best_bid": "0.87", "best_ask": "0.97"}], "timestamp": "1769384143257", "event_type": "price_change"}}
{"_local_timestamp": "2026-01-25T23:35:43.663058+00:00", "data": {"market": "0xf20f7af3ea74b16d623af198d6efb27d9d4ee98cfa96b1b6c8d4021d55436eb0", "price_changes": [{"asset_id": "8204205703682240679449476083075054464313606926136751077466819525464621562665", "price": "0.03", "size": "21.5", "side": "BUY", "hash": "90e9d34ba52219a0003a637dd0d684854a143019", "best_bid": "0.03", "best_ask": "0.13"}, {"asset_id": "79006550760303579457645886672312299229061887535391288753983510221472432105358", "price": "0.97", "size": "21.5", "side": "SELL", "hash": "de001b93ca70ac8a0067990871b204075d456494", "best_bid": "0.87", "best_ask": "0.97"}], "timestamp": "1769384143600", "event_type": "price_change"}}
{"_local_timestamp": "2026-01-25T23:35:52.158868+00:00", "data": {"market": "0xa38d137a148c4b1ec0e5a5bce42e130391bcc8086f93b4a42fb93870456fc720", "price_changes": [{"asset_id": "100952291322678954514417231357111610948515892742954751932425813530604840075554", "price": "0.94", "size": "0", "side": "BUY", "hash": "6f20ee11a6f0e324e9b9bded6f55fdd0a67f008b", "best_bid": "0.95", "best_ask": "0.988"}, {"asset_id": "106570670068044891061840154694634029425579441331483581761385437733846502477972", "price": "0.06", "size": "0", "side": "SELL", "hash": "f58f62d978670e0e18e68827226b603f08c0bf1a", "best_bid": "0.012", "best_ask": "0.05"}], "timestamp": "1769384152095", "event_type": "price_change"}}
