{"_local_timestamp": "2026-01-25T23:40:30.466501+00:00", "data": [{"market": "0x48b2ac8e4952ede64137cb9e1f67841061e725f8e060ff51e6970f168acd8303", "asset_id": "52822993201579571958987364838421636000538927960920091134275776904104644390276", "timestamp": "1769384257589", "hash": "4ce322d97660cbc292161a6537c746a366efa0bf", "bids": [{"price": "0.01", "size": "20.68"}, {"price": "0.02", "size": "700"}, {"price": "0.03", "size": "11.05"}, {"price": "0.05", "size": "530"}, {"price": "0.06", "size": "33"}, {"price": "0.09", "size": "1000"}, {"price": "0.1", "size": "2300"}, {"price": "0.11", "size": "23.1"}, {"price": "0.13", "size": "8"}, {"price": "0.41", "size": "2.79"}, {"price": "0.49", "size": "200"}], "asks": [{"price": "0.99", "size": "67.3"}, {"price": "0.98", "size": "5"}, {"price": "0.95", "size": "450"}, {"price": "0.94", "size": "3338.78"}, {"price": "0.93", "size": "54.8"}, {"price": "0.92", "size": "102"}], "event_type": "book", "last_trade_price": ""}, {"market": "0xffc12401de3806de6abde626f2611d66aa6d4eb00f1d98d0d95b21eaf826c774", "asset_id": "67347272295607575221699172815489899405827138451298340879470038514774177180986", "timestamp": "1769384256738", "hash": "5b86daa4044a68b9c85bbce468f754d45c407a73", "bids": [{"price": "0.01", "size": "10"}, {"price": "0.02", "size": "20.64"}, {"price": "0.15", "size": "13.33"}, {"price": "0.18", "size": "22.22"}, {"price": "0.2", "size": "20"}], "asks": [{"price": "0.99", "size": "21.4"}, {"price": "0.98", "size": "700"}, {"price": "0.97", "size": "10.6"}, {"price": "0.95", "size": "30"}, {"price": "0.94", "size": "33"}, {"price": "0.93", "size": "600"}, {"price": "0.91", "size": "200"}, {"price": "0.9", "size": "2005.68"}, {"price": "0.87", "size": "250"}, {"price": "0.86", "size": "125"}, {"price": "0.85", "size": "13"}, {"price": "0.8", "size": "150"}, {"price": "0.75", "size": "100"}, {"price": "0.7", "size": "100"}, {"price": "0.65", "size": "100"}, {"price": "0.64", "size": "16.95"}, {"price": "0.63", "size": "8.69"}], "event_type": "book", "last_trade_price": "0.020"}, {"market": "0x69bafa45a085aa1be26d6fe0e9e03eaccaa1066aef68b9c91242092c50f3ea97", "asset_id": "70090044078891466543821567809211719305964223474308253000542294815991614487896", "timestamp": "1769384257952", "hash": "482e4e6f3a7d57a246bdc71430328b021126bad2", "bids": [{"price": "0.01", "size": "17.05"}, {"price": "0.02", "size": "200"}, {"price": "0.03", "size": "6672.51"}, {"price": "0.05", "size": "30"}, {"price": "0.06", "size": "33"}, {"price": "0.07", "size": "10.76"}, {"price": "0.11", "size": "17.75"}, {"price": "0.12", "size": "111"}, {"price": "0.13", "size": "15"}, {"price": "0.52", "size": "5.21"}, {"price": "0.76", "size": "11"}, {"price": "0.77", "size": "7.32"}], "asks": [{"price": "0.99", "size": "61.12"}, {"price": "0.98", "size": "7.39"}, {"price": "0.97", "size": "1900"}, {"price": "0.96", "size": "450"}, {"price": "0.95", "size": "54.5"}], "event_type": "book", "last_trade_price": ""}, {"market": "0x48b2ac8e4952ede64137cb9e1f67841061e725f8e060ff51e6970f168acd8303", "asset_id": "11359935130620024350938209884330114870141627625389875124593499392797204103195", "timestamp": "1769384257589", "hash": "417a95f4d4d5a13da0606722706a5941c6fab2f1", "bids": [{"price": "0.01", "size": "67.3"}, {"price": "0.02", "size": "5"}, {"price": "0.05", "size": "450"}, {"price": "0.06", "size": "3338.78"}, {"price": "0.07", "size": "54.8"}, {"price": "0.08", "size": "102"}], "asks": [{"price": "0.99", "size": "20.68"}, {"price": "0.98", "size": "700"}, {"price": "0.97", "size": "11.05"}, {"price": "0.95", "size": "530"}, {"price": "0.94", "size": "33"}, {"price": "0.91", "size": "1000"}, {"price": "0.9", "size": "2300"}, {"price": "0.89", "size": "23.1"}, {"price": "0.87", "size": "8"}, {"price": "0.59", "size": "2.79"}, {"price": "0.51", "size": "200"}], "event_type": "book", "last_trade_price": ""}, {"market": "0x9237ed4d34fd3bfcd727d4e1a965168ab5b928ec01702dc697ad700a62de3297", "asset_id": "57743214001422218298501702143953755301322512586713374566933425992418127374516", "timestamp": "1769384339348", "hash": "08fc9b8ea0210ff71122f010c6226a17350dd4c5", "bids": [{"price": "0.001", "size": "1231.99"}, {"price": "0.002", "size": "226.72"}, {"price": "0.003", "size": "150.56"}, {"price": "0.004", "size": "75.97"}, {"price": "0.005", "size": "22.42"}, {"price": "0.01", "size": "10"}], "asks": [{"price": "0.999", "size": "2730.14"}, {"price": "0.998", "size": "250"}, {"price": "0.997", "size": "11.68"}, {"price": "0.99", "size": "10"}, {"price": "0.989", "size": "5.58"}, {"price": "0.973", "size": "1055.55"}, {"price": "0.972", "size": "10.64"}, {"price": "0.95", "size": "30"}, {"price": "0.94", "size": "33"}, {"price": "0.937", "size": "200"}, {"price": "0.935", "size": "147.69"}, {"price": "0.934", "size": "3530.3"}, {"price": "0.894", "size": "90.56"}, {"price": "0.893", "size": "5.56"}, {"price": "0.69", "size": "150"}, {"price": "0.687", "size": "15"}, {"price": "0.686", "size": "30.57"}, {"price": "0.664", "size": "28.57"}, {"price": "0.663", "size": "5"}, {"price": "0.27", "size": "72"}, {"price": "0.038", "size": "21.47"}, {"price": "0.037", "size": "15.13"}], "event_type": "book", "last_trade_price": ""}, {"market": "0xfa6cdc4725de3762f80f3682226c27ab8a30e55cef8d69f700820a45f50ccde1", "asset_id": "22496537297371364538759212693768986794255769677985076955415858063148427148066", "timestamp": "1769384257602", "hash": "ed7fbdd794f9810e66c4c046e665db43f1e1e662", "bids": [{"price": "0.01", "size": "31.81"}, {"price": "0.02", "size": "5.01"}, {"price": "0.05", "size": "30"}, {"price": "0.06", "size": "233"}, {"price": "0.07", "size": "2857.14"}, {"price": "0.08", "size": "8.52"}, {"price": "0.11", "size": "50"}, {"price": "0.5", "size": "20"}, {"price": "0.53", "size": "98.5"}, {"price": "0.54", "size": "35.09"}], "asks": [{"price": "0.99", "size": "47.73"}, {"price": "0.98", "size": "5.21"}, {"price": "0.96", "size": "50"}, {"price": "0.95", "size": "10.36"}, {"price": "0.94", "size": "450"}, {"price": "0.92", "size": "100"}, {"price": "0.91", "size": "2222.22"}, {"price": "0.9", "size": "30"}], "event_type": "book", "last_trade_price": ""}, {"market": "0x413d4bafaaeffc8ba9babb5399486ff548f9d5c1aa39f946964e40251e9b27b3", "asset_id": "65546693826923938873772130697796116285599325305707340551279861952273746048719", "timestamp": "1769384338932", "hash": "04a62b29812e86940e338adc4390bb2a12762784", "bids": [{"price": "0.01", "size": "46.75"}, {"price": "0.02", "size": "12.36"}, {"price": "0.05", "size": "300"}, {"price": "0.06", "size": "6.42"}, {"price": "0.07", "size": "45"}], "asks": [{"price": "0.99", "size": "16.91"}, {"price": "0.98", "size": "359.07"}, {"price": "0.97", "size": "6672.5"}, {"price": "0.95", "size": "30"}, {"price": "0.94", "size": "33"}, {"price": "0.93", "size": "10.79"}, {"price": "0.88", "size": "175"}, {"price": "0.87", "size": "15"}, {"price": "0.86", "size": "7.2"}, {"price": "0.13", "size": "20"}], "event_type": "book", "last_trade_price": "0.090"}, {"market": "0xffc12401de3806de6abde626f2611d66aa6d4eb00f1d98d0d95b21eaf826c774", "asset_id": "38444929847167094538711578456743144277037082056984041769396338366492911791443", "timestamp": "1769384256738", "hash": "9c57c577af6c0a08c2c75e62eaada3e5cea84f20", "bids": [{"price": "0.01", "size": "21.4"}, {"price": "0.02", "size": "700"}, {"price": "0.03", "size": "10.6"}, {"price": "0.05", "size": "30"}, {"price": "0.06", "size": "33"}, {"price": "0.07", "size": "600"}, {"price": "0.09", "size": "200"}, {"price": "0.1", "size": "2005.68"}, {"price": "0.13", "size": "250"}, {"price": "0.14", "size": "125"}, {"price": "0.15", "size": "13"}, {"price": "0.2", "size": "150"}, {"price": "0.25", "size": "100"}, {"price": "0.3", "size": "100"}, {"price": "0.35", "size": "100"}, {"price": "0.36", "size": "16.95"}, {"price": "0.37", "size": "8.69"}], "asks": [{"price": "0.99", "size": "10"}, {"price": "0.98", "size": "20.64"}, {"price": "0.85", "size": "13.33"}, {"price": "0.82", "size": "22.22"}, {"price": "0.8", "size": "20"}], "event_type": "book", "last_trade_price": "0.020"}, {"market": "0x413d4bafaaeffc8ba9babb5399486ff548f9d5c1aa39f946964e40251e9b27b3", "asset_id": "90999757573179272509209276787098720839044513473294061380643859770168539372752", "timestamp": "1769384338932", "hash": "0f93e69121799abdc16f6b5bfcc45f6f6b17449b", "bids": [{"price": "0.01", "size": "16.91"}, {"price": "0.02", "size": "359.07"}, {"price": "0.03", "size": "6672.5"}, {"price": "0.05", "size": "30"}, {"price": "0.06", "size": "33"}, {"price": "0.07", "size": "10.79"}, {"price": "0.12", "size": "175"}, {"price": "0.13", "size": "15"}, {"price": "0.14", "size": "7.2"}, {"price": "0.87", "size": "20"}], "asks": [{"price": "0.99", "size": "46.75"}, {"price": "0.98", "size": "12.36"}, {"price": "0.95", "size": "300"}, {"price": "0.94", "size": "6.42"}, {"price": "0.93", "size": "45"}], "event_type": "book", "last_trade_price": "0.090"}, {"market": "0xfa6cdc4725de3762f80f3682226c27ab8a30e55cef8d69f700820a45f50ccde1", "asset_id": "43559809157157790367800091953099683105872740098326368267996520286155369923981", "timestamp": "1769384257602", "hash": "e39b70f7f2cb47b305d5271811aa4dde58b6dd95", "bids": [{"price": "0.01", "size": "47.73"}, {"price": "0.02", "size": "5.21"}, {"price": "0.04", "size": "50"}, {"price": "0.05", "size": "10.36"}, {"price": "0.06", "size": "450"}, {"price": "0.08", "size": "100"}, {"price": "0.09", "size": "2222.22"}, {"price": "0.1", "size": "30"}], "asks": [{"price": "0.99", "size": "31.81"}, {"price": "0.98", "size": "5.01"}, {"price": "0.95", "size": "30"}, {"price": "0.94", "size": "233"}, {"price": "0.93", "size": "2857.14"}, {"price": "0.92", "size": "8.52"}, {"price": "0.89", "size": "50"}, {"price": "0.5", "size": "20"}, {"price": "0.47", "size": "98.5"}, {"price": "0.46", "size": "35.09"}], "event_type": "book", "last_trade_price": ""}, {"market": "0x69bafa45a085aa1be26d6fe0e9e03eaccaa1066aef68b9c91242092c50f3ea97", "asset_id": "75783817820783131947282055630075558103780576789392849292284090943168579518773", "timestamp": "1769384257952", "hash": "b75d19b154e56fa040ecdd89a38f62dd81adb52a", "bids": [{"price": "0.01", "size": "61.12"}, {"price": "0.02", "size": "7.39"}, {"price": "0.03", "size": "1900"}, {"price": "0.04", "size": "450"}, {"price": "0.05", "size": "54.5"}], "asks": [{"price": "0.99", "size": "17.05"}, {"price": "0.98", "size": "200"}, {"price": "0.97", "size": "6672.51"}, {"price": "0.95", "size": "30"}, {"price": "0.94", "size": "33"}, {"price": "0.93", "size": "10.76"}, {"price": "0.89", "size": "17.75"}, {"price": "0.88", "size": "111"}, {"price": "0.87", "size": "15"}, {"price": "0.48", "size": "5.21"}, {"price": "0.24", "size": "11"}, {"price": "0.23", "size": "7.32"}], "event_type": "book", "last_trade_price": ""}, {"market": "0x9237ed4d34fd3bfcd727d4e1a965168ab5b928ec01702dc697ad700a62de3297", "asset_id": "98029863453234854862468316519654152065487816172737223439496380979679348531831", "timestamp": "1769384339348", "hash": "64387e749b13537e6e3127e26e76b17fb5e7e515", "bids": [{"price": "0.001", "size": "2730.14"}, {"price": "0.002", "size": "250"}, {"price": "0.003", "size": "11.68"}, {"price": "0.01", "size": "10"}, {"price": "0.011", "size": "5.58"}, {"price": "0.027", "size": "1055.55"}, {"price": "0.028", "size": "10.64"}, {"price": "0.05", "size": "30"}, {"price": "0.06", "size": "33"}, {"price": "0.063", "size": "200"}, {"price": "0.065", "size": "147.69"}, {"price": "0.066", "size": "3530.3"}, {"price": "0.106", "size": "90.56"}, {"price": "0.107", "size": "5.56"}, {"price": "0.31", "size": "150"}, {"price": "0.313", "size": "15"}, {"price": "0.314", "size": "30.57"}, {"price": "0.336", "size": "28.57"}, {"price": "0.337", "size": "5"}, {"price": "0.73", "size": "72"}, {"price": "0.962", "size": "21.47"}, {"price": "0.963", "size": "15.13"}], "asks": [{"price": "0.999", "size": "1231.99"}, {"price": "0.998", "size": "226.72"}, {"price": "0.997", "size": "150.56"}, {"price": "0.996", "size": "75.97"}, {"price": "0.995", "size": "22.42"}, {"price": "0.99", "size": "10"}], "event_type": "book", "last_trade_price": ""}]}
{"_local_timestamp": "2026-01-25T23:40:49.937546+00:00", "data": {"market": "0x69bafa45a085aa1be26d6fe0e9e03eaccaa1066aef68b9c91242092c50f3ea97", "price_changes": [{"asset_id": "75783817820783131947282055630075558103780576789392849292284090943168579518773", "price": "0.01", "size": "20.04", "side": "BUY", "hash": "3f6391c1b8553d3754951f4f8cd8a9db0b930703", "best_bid": "0.05", "best_ask": "0.23"}, {"asset_id": "70090044078891466543821567809211719305964223474308253000542294815991614487896", "price": "0.99", "size": "20.04", "side": "SELL", "hash": "e8be306b5a9fa09351eff272025c92c49cffcc44", "best_bid": "0.77", "best_ask": "0.95"}], "timestamp": "1769384449865", "event_type": "price_change"}}
{"_local_timestamp": "2026-01-25T23:40:49.941498+00:00", "data": {"market": "0x48b2ac8e4952ede64137cb9e1f67841061e725f8e060ff51e6970f168acd8303", "price_changes": [{"asset_id": "11359935130620024350938209884330114870141627625389875124593499392797204103195", "price": "0.02", "size": "0", "side": "BUY", "hash": "642bc614f878b92ab6b31ccbec2eb1340ebb39a7", "best_bid": "0.08", "best_ask": "0.51"}, {"asset_id": "52822993201579571958987364838421636000538927960920091134275776904104644390276", "price": "0.98", "size": "0", "side": "SELL", "hash": "23de005491421e6b3d8c1e6a661dec7fc644b511", "best_bid": "0.49", "best_ask": "0.92"}], "timestamp": "1769384449866", "event_type": "price_change"}}
{"_local_timestamp": "2026-01-25T23:40:53.833140+00:00", "data": {"market": "0x69bafa45a085aa1be26d6fe0e9e03eaccaa1066aef68b9c91242092c50f3ea97", "price_changes": [{"asset_id": "75783817820783131947282055630075558103780576789392849292284090943168579518773", "price": "0.01", "size": "61.12", "side": "BUY", "hash": "6a58b831d3eba93a7cf5bb42766dafd2deea5a1c", "best_bid": "0.05", "best_ask": "0.23"}, {"asset_id": "70090044078891466543821567809211719305964223474308253000542294815991614487896", "price": "0.99", "size": "61.12", "side": "SELL", "hash": "e7edb5b23de2b9d9c9c83dfd68b4eca6bfd7a2dc", "best_bid": "0.77", "best_ask": "0.95"}], "timestamp": "1769384453762", "event_type": "price_change"}}
{"_local_timestamp": "2026-01-25T23:40:53.833765+00:00", "data": {"market": "0x48b2ac8e4952ede64137cb9e1f67841061e725f8e060ff51e6970f168acd8303", "price_changes": [{"asset_id": "11359935130620024350938209884330114870141627625389875124593499392797204103195", "price": "0.01", "size": "77.29", "side": "BUY", "hash": "6572909836b86cf141497394ec32fc4a475736e8", "best_bid": "0.08", "best_ask": "0.51"}, {"asset_id": "52822993201579571958987364838421636000538927960920091134275776904104644390276", "price": "0.99", "size": "77.29", "side": "SELL", "hash": "3066d2b9b9d98f5add0e0a8682bb6793f06d5d80", "best_bid": "0.49", "best_ask": "0.92"}], "timestamp": "1769384453763", "event_type": "price_change"}}
{"_local_timestamp": "2026-01-25T23:40:58.301429+00:00", "data": {"market": "0xfa6cdc4725de3762f80f3682226c27ab8a30e55cef8d69f700820a45f50ccde1", "price_changes": [{"asset_id": "43559809157157790367800091953099683105872740098326368267996520286155369923981", "price": "0.08", "size": "0", "side": "BUY", "hash": "8999e9eb6b3f12bfaee1f6378af9963f03cf6ed5", "best_bid": "0.1", "best_ask": "0.46"}, {"asset_id": "22496537297371364538759212693768986794255769677985076955415858063148427148066", "price": "0.92", "size": "0", "side": "SELL", "hash": "d511da3d955386b722ad4f28e33894692d669a4f", "best_bid": "0.54", "best_ask": "0.9"}], "timestamp": "1769384457530", "event_type": "price_change"}}
{"_local_timestamp": "2026-01-25T23:40:59.185664+00:00", "data": {"market": "0xfa6cdc4725de3762f80f3682226c27ab8a30e55cef8d69f700820a45f50ccde1", "price_changes": [{"asset_id": "43559809157157790367800091953099683105872740098326368267996520286155369923981", "price": "0.1", "size": "0", "side": "BUY", "hash": "85d1baa8cefc241a97c728787cbf3255933a41c3", "best_bid": "0.09", "best_ask": "0.46"}, {"asset_id": "22496537297371364538759212693768986794255769677985076955415858063148427148066", "price": "0.9", "size": "0", "side": "SELL", "hash": "5ae91d5c99879ee3e6c6b8f8ea7cfd5e140c43f2", "best_bid": "0.54", "best_ask": "0.91"}], "timestamp": "1769384459095", "event_type": "price_change"}}
{"_local_timestamp": "2026-01-25T23:41:07.865452+00:00", "data": {"market": "0xfa6cdc4725de3762f80f3682226c27ab8a30e55cef8d69f700820a45f50ccde1", "price_changes": [{"asset_id": "43559809157157790367800091953099683105872740098326368267996520286155369923981", "price": "0.01", "size": "24.9", "side": "BUY", "hash": "fef9df91bc1e1a4f194397e94950e9bcb8901f6b", "best_bid": "0.09", "best_ask": "0.46"}, {"asset_id": "22496537297371364538759212693768986794255769677985076955415858063148427148066", "price": "0.99", "size": "24.9", "side": "SELL", "hash": "970631db9113932c6532fd0e3f6f8aafae6bfbba", "best_bid": "0.54", "best_ask": "0.91"}], "timestamp": "1769384467793", "event_type": "price_change"}}
{"_local_timestamp": "2026-01-25T23:41:07.867000+00:00", "data": {"market": "0x413d4bafaaeffc8ba9babb5399486ff548f9d5c1aa39f946964e40251e9b27b3", "price_changes": [{"asset_id": "65546693826923938873772130697796116285599325305707340551279861952273746048719", "price": "0.01", "size": "10", "side": "BUY", "hash": "0ef7b7d5ce2ade9f6ad990c6ff4f8be236a13058", "best_bid": "0.07", "best_ask": "0.13"}, {"asset_id": "90999757573179272509209276787098720839044513473294061380643859770168539372752", "price": "0.99", "size": "10", "side": "SELL", "hash": "a33da9d95ab375d31a2d6c3f57aac1f6b48d8b60", "best_bid": "0.87", "best_ask": "0.93"}], "timestamp": "1769384467793", "event_type": "price_change"}}
{"_local_timestamp": "2026-01-25T23:41:07.867914+00:00", "data": {"market": "0x413d4bafaaeffc8ba9babb5399486ff548f9d5c1aa39f946964e40251e9b27b3", "price_changes": [{"asset_id": "65546693826923938873772130697796116285599325305707340551279861952273746048719", "price": "0.02", "size": "0", "side": "BUY", "hash": "0ef7b7d5ce2ade9f6ad990c6ff4f8be236a13058", "best_bid": "0.07", "best_ask": "0.13"}, {"asset_id": "90999757573179272509209276787098720839044513473294061380643859770168539372752", "price": "0.98", "size": "0", "side": "SELL", "hash": "a33da9d95ab375d31a2d6c3f57aac1f6b48d8b60", "best_bid": "0.87", "best_ask": "0.93"}], "timestamp": "1769384467793", "event_type": "price_change"}}
{"_local_timestamp": "2026-01-25T23:41:11.184997+00:00", "data": {"market": "0x413d4bafaaeffc8ba9babb5399486ff548f9d5c1aa39f946964e40251e9b27b3", "price_changes": [{"asset_id": "65546693826923938873772130697796116285599325305707340551279861952273746048719", "price": "0.02", "size": "7.12", "side": "BUY", "hash": "abc024aab393b75acc87a56c92cf266c3932b751", "best_bid": "0.07", "best_ask": "0.13"}, {"asset_id": "90999757573179272509209276787098720839044513473294061380643859770168539372752", "price": "0.98", "size": "7.12", "side": "SELL", "hash": "056c843b52119edac57941e796379c64d01695f8", "best_bid": "0.87", "best_ask": "0.93"}], "timestamp": "1769384471039", "event_type": "price_change"}}
{"_local_timestamp": "2026-01-25T23:41:11.185783+00:00", "data": {"market": "0xfa6cdc4725de3762f80f3682226c27ab8a30e55cef8d69f700820a45f50ccde1", "price_changes": [{"asset_id": "43559809157157790367800091953099683105872740098326368267996520286155369923981", "price": "0.01", "size": "47.78", "side": "BUY", "hash": "b156ad8a8744e4cecaf9e258df6c77724d21e5fb", "best_bid": "0.09", "best_ask": "0.46"}, {"asset_id": "22496537297371364538759212693768986794255769677985076955415858063148427148066", "price": "0.99", "size": "47.78", "side": "SELL", "hash": "d809714771e3f528c751311ab311b3a715b0155f", "best_bid": "0.54", "best_ask": "0.91"}], "timestamp": "1769384471039", "event_type": "price_change"}}
{"_local_timestamp": "2026-01-25T23:41:11.200174+00:00", "data": {"market": "0x413d4bafaaeffc8ba9babb5399486ff548f9d5c1aa39f946964e40251e9b27b3", "price_changes": [{"asset_id": "65546693826923938873772130697796116285599325305707340551279861952273746048719", "price": "0.01", "size": "22.02", "side": "BUY", "hash": "0578444e450c97dcb7e6b0cba77fc2bda91656ad", "best_bid": "0.07", "best_ask": "0.13"}, {"asset_id": "90999757573179272509209276787098720839044513473294061380643859770168539372752", "price": "0.99", "size": "22.02", "side": "SELL", "hash": "f00a91525ed6ec300636b23a12c8a133e2b142b0", "best_bid": "0.87", "best_ask": "0.93"}], "timestamp": "1769384471045", "event_type": "price_change"}}
{"_local_timestamp": "2026-01-25T23:41:11.200649+00:00", "data": {"market": "0x413d4bafaaeffc8ba9babb5399486ff548f9d5c1aa39f946964e40251e9b27b3", "price_changes": [{"asset_id": "65546693826923938873772130697796116285599325305707340551279861952273746048719", "price": "0.03", "size": "11.73", "side": "BUY", "hash": "687160473bf9d64d38086f9cbdd5d0b51763069b", "best_bid": "0.07", "best_ask": "0.13"}, {"asset_id": "90999757573179272509209276787098720839044513473294061380643859770168539372752", "price": "0.97", "size": "11.73", "side": "SELL", "hash": "23adde50f380f710d5dad6b1a86cf563310f2e1e", "best_bid": "0.87", "best_ask": "0.93"}], "timestamp": "1769384471049", "event_type": "price_change"}}
{"_local_timestamp": "2026-01-25T23:41:11.388334+00:00", "data": {"market": "0x413d4bafaaeffc8ba9babb5399486ff548f9d5c1aa39f946964e40251e9b27b3", "price_changes": [{"asset_id": "65546693826923938873772130697796116285599325305707340551279861952273746048719", "price": "0.06", "size": "36.42", "side": "BUY", "hash": "06a5b27c1fa46499151e2096141075b776121a27", "best_bid": "0.07", "best_ask": "0.13"}, {"asset_id": "90999757573179272509209276787098720839044513473294061380643859770168539372752", "price": "0.94", "size": "36.42", "side": "SELL", "hash": "16bc8d99fc71033450b3a59c2ec8f1f0592b66d6", "best_bid": "0.87", "best_ask": "0.93"}], "timestamp": "1769384471249", "event_type": "price_change"}}
{"_local_timestamp": "2026-01-25T23:41:57.298145+00:00", "data": {"market": "0x9237ed4d34fd3bfcd727d4e1a965168ab5b928ec01702dc697ad700a62de3297", "price_changes": [{"asset_id": "57743214001422218298501702143953755301322512586713374566933425992418127374516", "price": "0.005", "size": "0", "side": "BUY", "hash": "156edbb483639b25fb60b98e9e14b79d6cd0e679", "best_bid": "0.01", "best_ask": "0.037"}, {"asset_id": "98029863453234854862468316519654152065487816172737223439496380979679348531831", "price": "0.995", "size": "0", "side": "SELL", "hash": "14eba87ab8bb9341604153cb4baf460590253497", "best_bid": "0.963", "best_ask": "0.99"}], "timestamp": "1769384517218", "event_type": "price_change"}}
{"_local_timestamp": "2026-01-25T23:41:57.965042+00:00", "data": {"market": "0x9237ed4d34fd3bfcd727d4e1a965168ab5b928ec01702dc697ad700a62de3297", "price_changes": [{"asset_id": "57743214001422218298501702143953755301322512586713374566933425992418127374516", "price": "0.006", "size": "18.68", "side": "BUY", "hash": "274e275e3cdb79b90fa4de62295b266b032f99e8", "best_bid": "0.01", "best_ask": "0.037"}, {"asset_id": "98029863453234854862468316519654152065487816172737223439496380979679348531831", "price": "0.994", "size": "18.68", "side": "SELL", "hash": "1162260e36a4c95411d52c4399fa2fb3d8113cd1", "best_bid": "0.963", "best_ask": "0.99"}], "timestamp": "1769384517896", "event_type": "price_change"}}
{"_local_timestamp": "2026-01-25T23:43:48.167943+00:00", "data": {"market": "0x9237ed4d34fd3bfcd727d4e1a965168ab5b928ec01702dc697ad700a62de3297", "price_changes": [{"asset_id": "98029863453234854862468316519654152065487816172737223439496380979679348531831", "price": "0.106", "size": "0", "side": "BUY", "hash": "de7d950cb3112ec82459289a2aefedabb30d96d9", "best_bid": "0.963", "best_ask": "0.99"}, {"asset_id": "57743214001422218298501702143953755301322512586713374566933425992418127374516", "price": "0.894", "size": "0", "side": "SELL", "hash": "d9db7f04183ffaef808aecc697084199033c4d2b", "best_bid": "0.01", "best_ask": "0.037"}], "timestamp": "1769384628096", "event_type": "price_change"}}
{"_local_timestamp": "2026-01-25T23:43:48.361277+00:00", "data": {"market": "0x9237ed4d34fd3bfcd727d4e1a965168ab5b928ec01702dc697ad700a62de3297", "price_changes": [{"asset_id": "98029863453234854862468316519654152065487816172737223439496380979679348531831", "price": "0.027", "size": "700", "side": "BUY", "hash": "3985dfdf1cd30656667701afd2db08da2499d99f", "best_bid": "0.963", "best_ask": "0.99"}, {"asset_id": "57743214001422218298501702143953755301322512586713374566933425992418127374516", "price": "0.973", "size": "700", "side": "SELL", "hash": "a88416f785f5987ad8e5858b4b2bef1c9dfc3b4c", "best_bid": "0.01", "best_ask": "0.037"}], "timestamp": "1769384628295", "event_type": "price_change"}}
{"_local_timestamp": "2026-01-25T23:43:48.588109+00:00", "data": {"market": "0x9237ed4d34fd3bfcd727d4e1a965168ab5b928ec01702dc697ad700a62de3297", "price_changes": [{"asset_id": "98029863453234854862468316519654152065487816172737223439496380979679348531831", "price": "0.336", "size": "0", "side": "BUY", "hash": "c167ff2ba637d8066de92c4c2404d4e887dbef6c", "best_bid": "0.963", "best_ask": "0.99"}, {"asset_id": "57743214001422218298501702143953755301322512586713374566933425992418127374516", "price": "0.664", "size": "0", "side": "SELL", "hash": "393b9b45af6d9c3fe1f3fd49b29f9d5fb1783442", "best_bid": "0.01", "best_ask": "0.037"}], "timestamp": "1769384628513", "event_type": "price_change"}}
{"_local_timestamp": "2026-01-25T23:43:48.801415+00:00", "data": {"market": "0x9237ed4d34fd3bfcd727d4e1a965168ab5b928ec01702dc697ad700a62de3297", "price_changes": [{"asset_id": "98029863453234854862468316519654152065487816172737223439496380979679348531831", "price": "0.029", "size": "331.03", "side": "BUY", "hash": "52a6d0f11282bcbc84b66d6f38e45d2ec6174611", "best_bid": "0.963", "best_ask": "0.99"}, {"asset_id": "57743214001422218298501702143953755301322512586713374566933425992418127374516", "price": "0.971", "size": "331.03", "side": "SELL", "hash": "e45cfeb54fd65c1580705bfe18178eb2009246f4", "best_bid": "0.01", "best_ask": "0.037"}], "timestamp": "1769384628731", "event_type": "price_change"}}
{"_local_timestamp": "2026-01-25T23:43:49.015693+00:00", "data": {"market": "0x9237ed4d34fd3bfcd727d4e1a965168ab5b928ec01702dc697ad700a62de3297", "price_changes": [{"asset_id": "98029863453234854862468316519654152065487816172737223439496380979679348531831", "price": "0.108", "size": "88.88", "side": "BUY", "hash": "1cec0cbf9ca54cf1199d857cbe4bef90dbaa0dbe", "best_bid": "0.963", "best_ask": "0.99"}, {"asset_id": "57743214001422218298501702143953755301322512586713374566933425992418127374516", "price": "0.892", "size": "88.88", "side": "SELL", "hash": "d34bf6c35cd0eff7b68041dfd8f34e59b145dfa2", "best_bid": "0.01", "best_ask": "0.037"}], "timestamp": "1769384628942", "event_type": "price_change"}}
{"_local_timestamp": "2026-01-25T23:43:49.223115+00:00", "data": {"market": "0x9237ed4d34fd3bfcd727d4e1a965168ab5b928ec01702dc697ad700a62de3297", "price_changes": [{"asset_id": "98029863453234854862468316519654152065487816172737223439496380979679348531831", "price": "0.338", "size": "28.4", "side": "BUY", "hash": "cc34b1eb1fee2b59a2582cd6d7cc4460d8b6457a", "best_bid": "0.963", "best_ask": "0.99"}, {"asset_id": "57743214001422218298501702143953755301322512586713374566933425992418127374516", "price": "0.662", "size": "28.4", "side": "SELL", "hash": "c4c46f9b88317f12e13fb0354c0840a009275ef5", "best_bid": "0.01", "best_ask": "0.037"}], "timestamp": "1769384629156", "event_type": "price_change"}}
{"_local_timestamp": "2026-01-25T23:44:00.988622+00:00", "data": {"market": "0x48b2ac8e4952ede64137cb9e1f67841061e725f8e060ff51e6970f168acd8303", "price_changes": [{"asset_id": "52822993201579571958987364838421636000538927960920091134275776904104644390276", "price": "0.11", "size": "5.1", "side": "BUY", "hash": "63996742f103b8c5a1dc83941aef8cae7dbaeb87", "best_bid": "0.49", "best_ask": "0.92"}, {"asset_id": "11359935130620024350938209884330114870141627625389875124593499392797204103195", "price": "0.89", "size": "5.1", "side": "SELL", "hash": "ae76f72043c3e640e85f30d7e28bfb9fa430be7f", "best_bid": "0.08", "best_ask": "0.51"}], "timestamp": "1769384640917", "event_type": "price_change"}}
{"_local_timestamp": "2026-01-25T23:44:01.025320+00:00", "data": {"market": "0x48b2ac8e4952ede64137cb9e1f67841061e725f8e060ff51e6970f168acd8303", "price_changes": [{"asset_id": "52822993201579571958987364838421636000538927960920091134275776904104644390276", "price": "0.11", "size": "23.1", "side": "BUY", "hash": "d1b28feeb68d362fc601df6807c896c995bdf8b7", "best_bid": "0.49", "best_ask": "0.92"}, {"asset_id": "11359935130620024350938209884330114870141627625389875124593499392797204103195", "price": "0.89", "size": "23.1", "side": "SELL", "hash": "db3b65903272c8947be01d4ec83c6edd8abcb09b", "best_bid": "0.08", "best_ask": "0.51"}], "timestamp": "1769384640961", "event_type": "price_change"}}
{"_local_timestamp": "2026-01-25T23:44:55.264815+00:00", "data": {"market": "0x69bafa45a085aa1be26d6fe0e9e03eaccaa1066aef68b9c91242092c50f3ea97", "price_changes": [{"asset_id": "75783817820783131947282055630075558103780576789392849292284090943168579518773", "price": "0.01", "size": "20.04", "side": "BUY", "hash": "de79b8bca20c216fc44bf84d61bd8e0f0172211c", "best_bid": "0.05", "best_ask": "0.23"}, {"asset_id": "70090044078891466543821567809211719305964223474308253000542294815991614487896", "price": "0.99", "size": "20.04", "side": "SELL", "hash": "cf6929a7a7f878b23049adfd386e8e90cd701101", "best_bid": "0.77", "best_ask": "0.95"}], "timestamp": "1769384695195", "event_type": "price_change"}}
{"_local_timestamp": "2026-01-25T23:44:55.529871+00:00", "data": {"market": "0x69bafa45a085aa1be26d6fe0e9e03eaccaa1066aef68b9c91242092c50f3ea97", "price_changes": [{"asset_id": "75783817820783131947282055630075558103780576789392849292284090943168579518773", "price": "0.02", "size": "27.93", "side": "BUY", "hash": "7af29df70b0e8c67f26a417c9908ee928b9211e2", "best_bid": "0.05", "best_ask": "0.23"}, {"asset_id": "70090044078891466543821567809211719305964223474308253000542294815991614487896", "price": "0.98", "size": "27.93", "side": "SELL", "hash": "f21b68978f45a3b3611562c038b30bbb6a246c4a", "best_bid": "0.77", "best_ask": "0.95"}], "timestamp": "1769384695451", "event_type": "price_change"}}
{"_local_timestamp": "2026-01-25T23:44:56.033142+00:00", "data": {"market": "0x48b2ac8e4952ede64137cb9e1f67841061e725f8e060ff51e6970f168acd8303", "price_changes": [{"asset_id": "11359935130620024350938209884330114870141627625389875124593499392797204103195", "price": "0.01", "size": "48.22", "side": "BUY", "hash": "5b25ba47cb3bf6c45143e9701ac85a0e2d3e72f4", "best_bid": "0.08", "best_ask": "0.51"}, {"asset_id": "52822993201579571958987364838421636000538927960920091134275776904104644390276", "price": "0.99", "size": "48.22", "side": "SELL", "hash": "49395ea861d183834cd32fe2c2ff6a1481fd01be", "best_bid": "0.49", "best_ask": "0.92"}], "timestamp": "1769384695958", "event_type": "price_change"}}
{"_local_timestamp": "2026-01-25T23:44:56.382931+00:00", "data": {"market": "0x48b2ac8e4952ede64137cb9e1f67841061e725f8e060ff51e6970f168acd8303", "price_changes": [{"asset_id": "11359935130620024350938209884330114870141627625389875124593499392797204103195", "price": "0.01", "size": "64.67", "side": "BUY", "hash": "6604bd4d3538bc45f84596f0f2ba2325a7f9e06f", "best_bid": "0.08", "best_ask": "0.51"}, {"asset_id": "52822993201579571958987364838421636000538927960920091134275776904104644390276", "price": "0.99", "size": "64.67", "side": "SELL", "hash": "dc31f41bc8950a12ffb43a422aa128bc33978e28", "best_bid": "0.49", "best_ask": "0.92"}], "timestamp": "1769384696309", "event_type": "price_change"}}
{"_local_timestamp": "2026-01-25T23:44:56.383514+00:00", "data": {"market": "0x48b2ac8e4952ede64137cb9e1f67841061e725f8e060ff51e6970f168acd8303", "price_changes": [{"asset_id": "11359935130620024350938209884330114870141627625389875124593499392797204103195", "price": "0.02", "size": "6.31", "side": "BUY", "hash": "7f95ad95e1da18ed85522d4a1ee969989b7889df", "best_bid": "0.08", "best_ask": "0.51"}, {"asset_id": "52822993201579571958987364838421636000538927960920091134275776904104644390276", "price": "0.98", "size": "6.31", "side": "SELL", "hash": "685a1ffc80f8c35759d3f36b225e8a19685411ac", "best_bid": "0.49", "best_ask": "0.92"}], "timestamp": "1769384696317", "event_type": "price_change"}}
{"_local_timestamp": "2026-01-25T23:45:14.400962+00:00", "data": {"market": "0xfa6cdc4725de3762f80f3682226c27ab8a30e55cef8d69f700820a45f50ccde1", "price_changes": [{"asset_id": "43559809157157790367800091953099683105872740098326368267996520286155369923981", "price": "0.01", "size": "24.9", "side": "BUY", "hash": "b2b3c76f786218f5fa75c486623594fc0ef7b1d1", "best_bid": "0.09", "best_ask": "0.46"}, {"asset_id": "22496537297371364538759212693768986794255769677985076955415858063148427148066", "price": "0.99", "size": "24.9", "side": "SELL", "hash": "6a6bc544c1b0f667b082accad598c26550a96fc0", "best_bid": "0.54", "best_ask": "0.91"}], "timestamp": "1769384714324", "event_type": "price_change"}}
{"_local_timestamp": "2026-01-25T23:45:14.998786+00:00", "data": {"market": "0xfa6cdc4725de3762f80f3682226c27ab8a30e55cef8d69f700820a45f50ccde1", "price_changes": [{"asset_id": "43559809157157790367800091953099683105872740098326368267996520286155369923981", "price": "0.01", "size": "47.78", "side": "BUY", "hash": "14da1515c813b7a778c5d94de5ca861ecf56c64b", "best_bid": "0.09", "best_ask": "0.46"}, {"asset_id": "22496537297371364538759212693768986794255769677985076955415858063148427148066", "price": "0.99", "size": "47.78", "side": "SELL", "hash": "37a193d6781c48614dc34bddb773706d7368268e", "best_bid": "0.54", "best_ask": "0.91"}], "timestamp": "1769384714933", "event_type": "price_change"}}
{"_local_timestamp": "2026-01-25T23:45:15.665472+00:00", "data": {"market": "0x413d4bafaaeffc8ba9babb5399486ff548f9d5c1aa39f946964e40251e9b27b3", "price_changes": [{"asset_id": "65546693826923938873772130697796116285599325305707340551279861952273746048719", "price": "0.03", "size": "0", "side": "BUY", "hash": "67eae2ea4442dbc1f574fe95a3b0861a77f0344a", "best_bid": "0.07", "best_ask": "0.13"}, {"asset_id": "90999757573179272509209276787098720839044513473294061380643859770168539372752", "price": "0.97", "size": "0", "side": "SELL", "hash": "ce7d2cf97bd6dcf66bf97b3577af420f2713ef90", "best_bid": "0.87", "best_ask": "0.93"}], "timestamp": "1769384715592", "event_type": "price_change"}}
{"_local_timestamp": "2026-01-25T23:45:16.000312+00:00", "data": {"market": "0x413d4bafaaeffc8ba9babb5399486ff548f9d5c1aa39f946964e40251e9b27b3", "price_changes": [{"asset_id": "65546693826923938873772130697796116285599325305707340551279861952273746048719", "price": "0.01", "size": "57.24", "side": "BUY", "hash": "10c984512b36fc40612e466ce13251300729e9bd", "best_bid": "0.07", "best_ask": "0.13"}, {"asset_id": "90999757573179272509209276787098720839044513473294061380643859770168539372752", "price": "0.99", "size": "57.24", "side": "SELL", "hash": "73a69aad23690ac1c51fe333f30a4a70f3342191", "best_bid": "0.87", "best_ask": "0.93"}], "timestamp": "1769384715927", "event_type": "price_change"}}
{"_local_timestamp": "2026-01-25T23:45:16.158702+00:00", "data": {"market": "0x413d4bafaaeffc8ba9babb5399486ff548f9d5c1aa39f946964e40251e9b27b3", "price_changes": [{"asset_id": "65546693826923938873772130697796116285599325305707340551279861952273746048719", "price": "0.06", "size": "6.42", "side": "BUY", "hash": "bda3883e00a67cbd9b684cbd2ecd3ee1c7795f3b", "best_bid": "0.07", "best_ask": "0.13"}, {"asset_id": "90999757573179272509209276787098720839044513473294061380643859770168539372752", "price": "0.94", "size": "6.42", "side": "SELL", "hash": "77ab890a8ed007b78130cfc58b254975a2a813cd", "best_bid": "0.87", "best_ask": "0.93"}], "timestamp": "1769384716066", "event_type": "price_change"}}
{"_local_timestamp": "2026-01-25T23:45:56.842686+00:00", "data": {"market": "0x48b2ac8e4952ede64137cb9e1f67841061e725f8e060ff51e6970f168acd8303", "price_changes": [{"asset_id": "11359935130620024350938209884330114870141627625389875124593499392797204103195", "price": "0.05", "size": "200", "side": "BUY", "hash": "2df9a60b15624bb20afffa21ecec2e14dab541b4", "best_bid": "0.08", "best_ask": "0.51"}, {"asset_id": "52822993201579571958987364838421636000538927960920091134275776904104644390276", "price": "0.95", "size": "200", "side": "SELL", "hash": "b5cb5fc8b1a92057b7f4e9b01241c18c40397ce9", "best_bid": "0.49", "best_ask": "0.92"}], "timestamp": "1769384756103", "event_type": "price_change"}}
{"_local_timestamp": "2026-01-25T23:45:57.715282+00:00", "data": {"market": "0x9237ed4d34fd3bfcd727d4e1a965168ab5b928ec01702dc697ad700a62de3297", "price_changes": [{"asset_id": "98029863453234854862468316519654152065487816172737223439496380979679348531831", "price": "0.027", "size": "0", "side": "BUY", "hash": "265a0f570107d6001bad39a5f3dd8d4342e1e6b6", "best_bid": "0.963", "best_ask": "0.99"}, {"asset_id": "57743214001422218298501702143953755301322512586713374566933425992418127374516", "price": "0.973", "size": "0", "side": "SELL", "hash": "0522521e9aa71732f1307e9b55eaf61140f8d817", "best_bid": "0.01", "best_ask": "0.037"}], "timestamp": "1769384757649", "event_type": "price_change"}}
{"_local_timestamp": "2026-01-25T23:45:58.180072+00:00", "data": {"market": "0x9237ed4d34fd3bfcd727d4e1a965168ab5b928ec01702dc697ad700a62de3297", "price_changes": [{"asset_id": "98029863453234854862468316519654152065487816172737223439496380979679348531831", "price": "0.029", "size": "1031.03", "side": "BUY", "hash": "465ef32d4e195f507a144c22308eeabc569eff42", "best_bid": "0.963", "best_ask": "0.99"}, {"asset_id": "57743214001422218298501702143953755301322512586713374566933425992418127374516", "price": "0.971", "size": "1031.03", "side": "SELL", "hash": "3f3dd82d8bb315f5f7e5063e11236071aad83473", "best_bid": "0.01", "best_ask": "0.037"}], "timestamp": "1769384758093", "event_type": "price_change"}}
{"_local_timestamp": "2026-01-25T23:46:01.461010+00:00", "data": {"market": "0x48b2ac8e4952ede64137cb9e1f67841061e725f8e060ff51e6970f168acd8303", "price_changes": [{"asset_id": "11359935130620024350938209884330114870141627625389875124593499392797204103195", "price": "0.07", "size": "354.8", "side": "BUY", "hash": "5d4c73d5386421d640e3d340deb3836425e9bd52", "best_bid": "0.08", "best_ask": "0.51"}, {"asset_id": "52822993201579571958987364838421636000538927960920091134275776904104644390276", "price": "0.93", "size": "354.8", "side": "SELL", "hash": "b49eea88eff1f57b4c685f66660e4d82fbe6228d", "best_bid": "0.49", "best_ask": "0.92"}], "timestamp": "1769384761378", "event_type": "price_change"}}
{"_local_timestamp": "2026-01-25T23:46:10.846870+00:00", "data": {"market": "0x9237ed4d34fd3bfcd727d4e1a965168ab5b928ec01702dc697ad700a62de3297", "price_changes": [{"asset_id": "57743214001422218298501702143953755301322512586713374566933425992418127374516", "price": "0.006", "size": "0", "side": "BUY", "hash": "dba5abed98c1ddad3c20b1014a5402e51ccb566b", "best_bid": "0.01", "best_ask": "0.037"}, {"asset_id": "98029863453234854862468316519654152065487816172737223439496380979679348531831", "price": "0.994", "size": "0", "side": "SELL", "hash": "442e3363ea03d516ab711f3c1c798ee8ab76f2b6", "best_bid": "0.963", "best_ask": "0.99"}], "timestamp": "1769384770637", "event_type": "price_change"}}
{"_local_timestamp": "2026-01-25T23:46:11.144257+00:00", "data": {"market": "0x9237ed4d34fd3bfcd727d4e1a965168ab5b928ec01702dc697ad700a62de3297", "price_changes": [{"asset_id": "57743214001422218298501702143953755301322512586713374566933425992418127374516", "price": "0.007", "size": "16.01", "side": "BUY", "hash": "77dc8b096475b531bc2be9c13561729087cc74ec", "best_bid": "0.01", "best_ask": "0.037"}, {"asset_id": "98029863453234854862468316519654152065487816172737223439496380979679348531831", "price": "0.993", "size": "16.01", "side": "SELL", "hash": "c5211d2252b4771afa6d2e6a28a129ffd5f8c53d", "best_bid": "0.963", "best_ask": "0.99"}], "timestamp": "1769384771019", "event_type": "price_change"}}
{"_local_timestamp": "2026-01-25T23:46:14.444553+00:00", "data": {"market": "0x9237ed4d34fd3bfcd727d4e1a965168ab5b928ec01702dc697ad700a62de3297", "price_changes": [{"asset_id": "98029863453234854862468316519654152065487816172737223439496380979679348531831", "price": "0.028", "size": "0", "side": "BUY", "hash": "d1cf93213fa5e8bc24a8949f7d610a779941e4eb", "best_bid": "0.963", "best_ask": "0.99"}, {"asset_id": "57743214001422218298501702143953755301322512586713374566933425992418127374516", "price": "0.972", "size": "0", "side": "SELL", "hash": "b472fc9dae4d49d2067b084c5f798a49e6c1a424", "best_bid": "0.01", "best_ask": "0.037"}], "timestamp": "1769384774379", "event_type": "price_change"}}
{"_local_timestamp": "2026-01-25T23:46:14.445077+00:00", "data": {"market": "0x9237ed4d34fd3bfcd727d4e1a965168ab5b928ec01702dc697ad700a62de3297", "price_changes": [{"asset_id": "98029863453234854862468316519654152065487816172737223439496380979679348531831", "price": "0.107", "size": "0", "side": "BUY", "hash": "d1cf93213fa5e8bc24a8949f7d610a779941e4eb", "best_bid": "0.963", "best_ask": "0.99"}, {"asset_id": "57743214001422218298501702143953755301322512586713374566933425992418127374516", "price": "0.893", "size": "0", "side": "SELL", "hash": "b472fc9dae4d49d2067b084c5f798a49e6c1a424", "best_bid": "0.01", "best_ask": "0.037"}], "timestamp": "1769384774379", "event_type": "price_change"}}
{"_local_timestamp": "2026-01-25T23:46:15.261690+00:00", "data": {"market": "0x9237ed4d34fd3bfcd727d4e1a965168ab5b928ec01702dc697ad700a62de3297", "price_changes": [{"asset_id": "98029863453234854862468316519654152065487816172737223439496380979679348531831", "price": "0.109", "size": "5.46", "side": "BUY", "hash": "17ea79f132f16e7e67562b432b5fb01791a1e77b", "best_bid": "0.963", "best_ask": "0.99"}, {"asset_id": "57743214001422218298501702143953755301322512586713374566933425992418127374516", "price": "0.891", "size": "5.46", "side": "SELL", "hash": "05e4ed03ec3f456b07f42318d04e2cf03d37d34f", "best_bid": "0.01", "best_ask": "0.037"}], "timestamp": "1769384775189", "event_type": "price_change"}}
{"_local_timestamp": "2026-01-25T23:46:15.262240+00:00", "data": {"market": "0x9237ed4d34fd3bfcd727d4e1a965168ab5b928ec01702dc697ad700a62de3297", "price_changes": [{"asset_id": "98029863453234854862468316519654152065487816172737223439496380979679348531831", "price": "0.03", "size": "9.94", "side": "BUY", "hash": "a5d9d5b35ef916fb222b1cb8a5e0f681d3c8242e", "best_bid": "0.963", "best_ask": "0.99"}, {"asset_id": "57743214001422218298501702143953755301322512586713374566933425992418127374516", "price": "0.97", "size": "9.94", "side": "SELL", "hash": "adc931d1ab8a0e8298d27007e2dc191b8dbd693a", "best_bid": "0.01", "best_ask": "0.037"}], "timestamp": "1769384775190", "event_type": "price_change"}}
