{"_local_timestamp": "2026-01-25T23:34:20.825727+00:00", "data": [{"market": "0x955dd36f151fe79cda775370a2e09049998932d5ea090d97bf0e2fde8f11b26d", "asset_id": "11868101818250841972253954473857780150009778302053902404036716275197677080100", "timestamp": "1769383986053", "hash": "dc4c5ff1d644dacae5d09fc537b9e8afd02c624a", "bids": [{"price": "0.01", "size": "10448.67"}, {"price": "0.02", "size": "10606.43"}, {"price": "0.03", "size": "29.25"}, {"price": "0.14", "size": "300"}, {"price": "0.16", "size": "1090.11"}, {"price": "0.17", "size": "890.11"}, {"price": "0.18", "size": "125"}, {"price": "0.19", "size": "137"}, {"price": "0.28", "size": "10"}, {"price": "0.29", "size": "84"}], "asks": [{"price": "0.99", "size": "6440.75"}, {"price": "0.98", "size": "4307.32"}, {"price": "0.97", "size": "5.14"}, {"price": "0.95", "size": "20"}, {"price": "0.94", "size": "12.15"}, {"price": "0.89", "size": "300"}, {"price": "0.87", "size": "200"}, {"price": "0.86", "size": "125"}, {"price": "0.85", "size": "75"}, {"price": "0.81", "size": "1190.11"}, {"price": "0.8", "size": "890.11"}, {"price": "0.68", "size": "10"}, {"price": "0.67", "size": "80"}], "event_type": "book", "last_trade_price": "0.460"}, {"market": "0x7e2d51c512742b3be63926379eaf47a1ac32a4161c34c76795aaa4535f78d91b", "asset_id": "4942562966117907387247180723446863345452277275411471691291105714045772726888", "timestamp": "1769382050785", "hash": "d39af74885a929868973b17d1301e18e428a15e6", "bids": [{"price": "0.01", "size": "348.81"}, {"price": "0.02", "size": "158.94"}, {"price": "0.03", "size": "189.07"}, {"price": "0.04", "size": "25"}, {"price": "0.05", "size": "86.01"}], "asks": [{"price": "0.99", "size": "344.79"}, {"price": "0.98", "size": "157.03"}, {"price": "0.97", "size": "12.74"}, {"price": "0.96", "size": "106"}, {"price": "0.95", "size": "60"}, {"price": "0.94", "size": "43.95"}], "event_type": "book", "last_trade_price": ""}, {"market": "0xf99ee81e1df20ad515d4d8c5614296e55407cb4c1a730bd4b2ca95e8d090de39", "asset_id": "51695412102885289871089630836668975367967068438917673374772938097335162147956", "timestamp": "1769383983499", "hash": "f3a863b143a037635bcfaf883a5f94ec9bf4f1a6", "bids": [{"price": "0.01", "size": "10401.38"}, {"price": "0.02", "size": "156.4"}, {"price": "0.03", "size": "24.57"}, {"price": "0.07", "size": "1145.58"}, {"price": "0.08", "size": "890.11"}], "asks": [{"price": "0.99", "size": "10406.74"}, {"price": "0.98", "size": "158.94"}, {"price": "0.97", "size": "4168.39"}, {"price": "0.96", "size": "1140.11"}, {"price": "0.95", "size": "896.12"}], "event_type": "book", "last_trade_price": ""}, {"market": "0xf99ee81e1df20ad515d4d8c5614296e55407cb4c1a730bd4b2ca95e8d090de39", "asset_id": "24002093177954782907509920613765915696956431789616132179769237614333288236487", "timestamp": "1769383983499", "hash": "6b9528549289442b6d36bafc249e22b1d9f96192", "bids": [{"price": "0.01", "size": "10406.74"}, {"price": "0.02", "size": "158.94"}, {"price": "0.03", "size": "4168.39"}, {"price": "0.04", "size": "1140.11"}, {"price": "0.05", "size": "896.12"}], "asks": [{"price": "0.99", "size": "10401.38"}, {"price": "0.98", "size": "156.4"}, {"price": "0.97", "size": "24.57"}, {"price": "0.93", "size": "1145.58"}, {"price": "0.92", "size": "890.11"}], "event_type": "book", "last_trade_price": ""}, {"market": "0x097acba899c5c032ec4a662533aa4d56d6bda9117b0af7aea425d8d7502b095a", "asset_id": "16789388635872606083420797498193234014051215847692022335228605649270582798108", "timestamp": "1769383973918", "hash": "223c2fde7d4b140ffe1a6eeff60f22fdbbc12585", "bids": [{"price": "0.01", "size": "10601.22"}, {"price": "0.02", "size": "13.72"}, {"price": "0.03", "size": "60"}, {"price": "0.04", "size": "56.21"}, {"price": "0.05", "size": "60"}, {"price": "0.06", "size": "43.95"}], "asks": [{"price": "0.99", "size": "5488.95"}, {"price": "0.98", "size": "20.37"}, {"price": "0.97", "size": "66"}, {"price": "0.96", "size": "25"}, {"price": "0.95", "size": "80"}, {"price": "0.94", "size": "7.95"}, {"price": "0.91", "size": "250"}], "event_type": "book", "last_trade_price": ""}, {"market": "0x7e2d51c512742b3be63926379eaf47a1ac32a4161c34c76795aaa4535f78d91b", "asset_id": "5308165868421553874327989000707486778106622587076915795747014261780122519525", "timestamp": "1769382050785", "hash": "fd5c5a4fb2c962f3222c048868d75a4ac2a6744b", "bids": [{"price": "0.01", "size": "344.79"}, {"price": "0.02", "size": "157.03"}, {"price": "0.03", "size": "12.74"}, {"price": "0.04", "size": "106"}, {"price": "0.05", "size": "60"}, {"price": "0.06", "size": "43.95"}], "asks": [{"price": "0.99", "size": "348.81"}, {"price": "0.98", "size": "158.94"}, {"price": "0.97", "size": "189.07"}, {"price": "0.96", "size": "25"}, {"price": "0.95", "size": "86.01"}], "event_type": "book", "last_trade_price": ""}, {"market": "0x74630d4ce0f2777fd4cc5ed45a3b1960ffae48130b61ca5264f405ed2d8e5ca1", "asset_id": "99580136469297760161881451516754340127053208924416591882387003145171309403779", "timestamp": "1769383982004", "hash": "9cfb87f9dd8b79a988b0a2b8ef14567eca9c4e96", "bids": [{"price": "0.01", "size": "10597.95"}, {"price": "0.02", "size": "20.37"}, {"price": "0.03", "size": "66"}, {"price": "0.04", "size": "25"}, {"price": "0.05", "size": "80"}, {"price": "0.06", "size": "7.95"}, {"price": "0.09", "size": "1140.11"}, {"price": "0.1", "size": "890.11"}], "asks": [{"price": "0.99", "size": "11491.33"}, {"price": "0.98", "size": "903.83"}, {"price": "0.97", "size": "60"}, {"price": "0.96", "size": "56.21"}, {"price": "0.95", "size": "60"}, {"price": "0.94", "size": "43.95"}], "event_type": "book", "last_trade_price": ""}, {"market": "0x955dd36f151fe79cda775370a2e09049998932d5ea090d97bf0e2fde8f11b26d", "asset_id": "75456459287302166180376724549100719042861942676472232348454693844887341622859", "timestamp": "1769383986053", "hash": "b8bbcd66e18d0c197f1bebdadd3a3bf9933f1712", "bids": [{"price": "0.01", "size": "6440.75"}, {"price": "0.02", "size": "4307.32"}, {"price": "0.03", "size": "5.14"}, {"price": "0.05", "size": "20"}, {"price": "0.06", "size": "12.15"}, {"price": "0.11", "size": "300"}, {"price": "0.13", "size": "200"}, {"price": "0.14", "size": "125"}, {"price": "0.15", "size": "75"}, {"price": "0.19", "size": "1190.11"}, {"price": "0.2", "size": "890.11"}, {"price": "0.32", "size": "10"}, {"price": "0.33", "size": "80"}], "asks": [{"price": "0.99", "size": "10448.67"}, {"price": "0.98", "size": "10606.43"}, {"price": "0.97", "size": "29.25"}, {"price": "0.86", "size": "300"}, {"price": "0.84", "size": "1090.11"}, {"price": "0.83", "size": "890.11"}, {"price": "0.82", "size": "125"}, {"price": "0.81", "size": "137"}, {"price": "0.72", "size": "10"}, {"price": "0.71", "size": "84"}], "event_type": "book", "last_trade_price": "0.460"}, {"market": "0x097acba899c5c032ec4a662533aa4d56d6bda9117b0af7aea425d8d7502b095a", "asset_id": "94699601023424120682437549172990814687230320631825203249003963868534845660161", "timestamp": "1769383973918", "hash": "37b403b88be9406cc1f16d40fe9ccdf5b6088d6b", "bids": [{"price": "0.01", "size": "5488.95"}, {"price": "0.02", "size": "20.37"}, {"price": "0.03", "size": "66"}, {"price": "0.04", "size": "25"}, {"price": "0.05", "size": "80"}, {"price": "0.06", "size": "7.95"}, {"price": "0.09", "size": "250"}], "asks": [{"price": "0.99", "size": "10601.22"}, {"price": "0.98", "size": "13.72"}, {"price": "0.97", "size": "60"}, {"price": "0.96", "size": "56.21"}, {"price": "0.95", "size": "60"}, {"price": "0.94", "size": "43.95"}], "event_type": "book", "last_trade_price": ""}, {"market": "0x74630d4ce0f2777fd4cc5ed45a3b1960ffae48130b61ca5264f405ed2d8e5ca1", "asset_id": "58358246036859035115661691730481462975723997976545900928947259745708933284529", "timestamp": "1769383982004", "hash": "41c599d032d5f036f1ab54099df218c78703b348", "bids": [{"price": "0.01", "size": "11491.33"}, {"price": "0.02", "size": "903.83"}, {"price": "0.03", "size": "60"}, {"price": "0.04", "size": "56.21"}, {"price": "0.05", "size": "60"}, {"price": "0.06", "size": "43.95"}], "asks": [{"price": "0.99", "size": "10597.95"}, {"price": "0.98", "size": "20.37"}, {"price": "0.97", "size": "66"}, {"price": "0.96", "size": "25"}, {"price": "0.95", "size": "80"}, {"price": "0.94", "size": "7.95"}, {"price": "0.91", "size": "1140.11"}, {"price": "0.9", "size": "890.11"}], "event_type": "book", "last_trade_price": ""}]}
{"_local_timestamp": "2026-01-25T23:36:21.627930+00:00", "data": {"market": "0x097acba899c5c032ec4a662533aa4d56d6bda9117b0af7aea425d8d7502b095a", "price_changes": [{"asset_id": "94699601023424120682437549172990814687230320631825203249003963868534845660161", "price": "0.02", "size": "0", "side": "BUY", "hash": "db851e571fccede5c59927f83c045169d76d4d36", "best_bid": "0.09", "best_ask": "0.94"}, {"asset_id": "16789388635872606083420797498193234014051215847692022335228605649270582798108", "price": "0.98", "size": "0", "side": "SELL", "hash": "56026e22916f30c1b657054d5a93945620b05ff7", "best_bid": "0.06", "best_ask": "0.91"}], "timestamp": "1769384181520", "event_type": "price_change"}}
{"_local_timestamp": "2026-01-25T23:36:21.728542+00:00", "data": {"market": "0x097acba899c5c032ec4a662533aa4d56d6bda9117b0af7aea425d8d7502b095a", "price_changes": [{"asset_id": "94699601023424120682437549172990814687230320631825203249003963868534845660161", "price": "0.01", "size": "10597.95", "side": "BUY", "hash": "f31295f357cdbc62a16b0a536d9b18bf32c936a9", "best_bid": "0.09", "best_ask": "0.94"}, {"asset_id": "16789388635872606083420797498193234014051215847692022335228605649270582798108", "price": "0.99", "size": "10597.95", "side": "SELL", "hash": "2e45cb2df580a257e93e3d613c8fa4da36ec80ad", "best_bid": "0.06", "best_ask": "0.91"}], "timestamp": "1769384181636", "event_type": "price_change"}}
{"_local_timestamp": "2026-01-25T23:36:21.848009+00:00", "data": {"market": "0x097acba899c5c032ec4a662533aa4d56d6bda9117b0af7aea425d8d7502b095a", "price_changes": [{"asset_id": "16789388635872606083420797498193234014051215847692022335228605649270582798108", "price": "0.02", "size": "903.83", "side": "BUY", "hash": "c0751f6a5e207f901c54d5059db6685a114c00d1", "best_bid": "0.06", "best_ask": "0.91"}, {"asset_id": "94699601023424120682437549172990814687230320631825203249003963868534845660161", "price": "0.98", "size": "903.83", "side": "SELL", "hash": "763dd49e82b94b40a258b14f50fbc06cd5459a5a", "best_bid": "0.09", "best_ask": "0.94"}], "timestamp": "1769384181777", "event_type": "price_change"}}
{"_local_timestamp": "2026-01-25T23:36:21.850541+00:00", "data": {"market": "0x097acba899c5c032ec4a662533aa4d56d6bda9117b0af7aea425d8d7502b095a", "price_changes": [{"asset_id": "94699601023424120682437549172990814687230320631825203249003963868534845660161", "price": "0.09", "size": "1140.11", "side": "BUY", "hash": "7d601d35b367ce358d6350688defd2dd111e1c54", "best_bid": "0.09", "best_ask": "0.94"}, {"asset_id": "16789388635872606083420797498193234014051215847692022335228605649270582798108", "price": "0.91", "size": "1140.11", "side": "SELL", "hash": "d865713c29a7b532cfebb4170460a79f35379e4d", "best_bid": "0.06", "best_ask": "0.91"}], "timestamp": "1769384181778", "event_type": "price_change"}}
{"_local_timestamp": "2026-01-25T23:36:21.850948+00:00", "data": {"market": "0x097acba899c5c032ec4a662533aa4d56d6bda9117b0af7aea425d8d7502b095a", "price_changes": [{"asset_id": "94699601023424120682437549172990814687230320631825203249003963868534845660161", "price": "0.1", "size": "890.11", "side": "BUY", "hash": "4fa6ae3805cbd73c87e46a7179f62e12b82cc14b", "best_bid": "0.1", "best_ask": "0.94"}, {"asset_id": "16789388635872606083420797498193234014051215847692022335228605649270582798108", "price": "0.9", "size": "890.11", "side": "SELL", "hash": "6307de390f67a4c5b8f1617c571ef18bc89e4288", "best_bid": "0.06", "best_ask": "0.9"}], "timestamp": "1769384181778", "event_type": "price_change"}}
{"_local_timestamp": "2026-01-25T23:36:22.678190+00:00", "data": {"market": "0x097acba899c5c032ec4a662533aa4d56d6bda9117b0af7aea425d8d7502b095a", "price_changes": [{"asset_id": "94699601023424120682437549172990814687230320631825203249003963868534845660161", "price": "0.02", "size": "20.39", "side": "BUY", "hash": "49326612eb1fe962308b04869cb02b7de95a5d2a", "best_bid": "0.1", "best_ask": "0.94"}, {"asset_id": "16789388635872606083420797498193234014051215847692022335228605649270582798108", "price": "0.98", "size": "20.39", "side": "SELL", "hash": "65e015d6fa88701976125b015dc9a8590315a9ea", "best_bid": "0.06", "best_ask": "0.9"}], "timestamp": "1769384182610", "event_type": "price_change"}}
{"_local_timestamp": "2026-01-25T23:36:58.383681+00:00", "data": {"market": "0x097acba899c5c032ec4a662533aa4d56d6bda9117b0af7aea425d8d7502b095a", "price_changes": [{"asset_id": "94699601023424120682437549172990814687230320631825203249003963868534845660161", "price": "0.09", "size": "890.11", "side": "BUY", "hash": "9c93147d80c7adc3a7e681677ebcd3a4f57fad06", "best_bid": "0.1", "best_ask": "0.94"}, {"asset_id": "16789388635872606083420797498193234014051215847692022335228605649270582798108", "price": "0.91", "size": "890.11", "side": "SELL", "hash": "c5eb5929f5e616a2d222765663e859b14c16b67c", "best_bid": "0.06", "best_ask": "0.9"}], "timestamp": "1769384218091", "event_type": "price_change"}}
{"_local_timestamp": "2026-01-25T23:36:58.421391+00:00", "data": {"market": "0x955dd36f151fe79cda775370a2e09049998932d5ea090d97bf0e2fde8f11b26d", "price_changes": [{"asset_id": "75456459287302166180376724549100719042861942676472232348454693844887341622859", "price": "0.19", "size": "890.11", "side": "BUY", "hash": "29c1d47f6e1e2abc03f130381cf7dd3db1fc6ab0", "best_bid": "0.33", "best_ask": "0.71"}, {"asset_id": "11868101818250841972253954473857780150009778302053902404036716275197677080100", "price": "0.81", "size": "890.11", "side": "SELL", "hash": "2fe13cc784e165fc6c97fd131f02462cbef79280", "best_bid": "0.29", "best_ask": "0.67"}], "timestamp": "1769384218095", "event_type": "price_change"}}
{"_local_timestamp": "2026-01-25T23:36:58.533991+00:00", "data": {"market": "0x097acba899c5c032ec4a662533aa4d56d6bda9117b0af7aea425d8d7502b095a", "price_changes": [{"asset_id": "94699601023424120682437549172990814687230320631825203249003963868534845660161", "price": "0.02", "size": "910.5", "side": "BUY", "hash": "8b655bef932c849c5ca62ffac15323f9141c1673", "best_bid": "0.1", "best_ask": "0.94"}, {"asset_id": "16789388635872606083420797498193234014051215847692022335228605649270582798108", "price": "0.98", "size": "910.5", "side": "SELL", "hash": "6e1b352b392937acf947b798bbe7aaed4b9e95e3", "best_bid": "0.06", "best_ask": "0.9"}], "timestamp": "1769384218251", "event_type": "price_change"}}
{"_local_timestamp": "2026-01-25T23:36:58.534335+00:00", "data": {"market": "0x097acba899c5c032ec4a662533aa4d56d6bda9117b0af7aea425d8d7502b095a", "price_changes": [{"asset_id": "94699601023424120682437549172990814687230320631825203249003963868534845660161", "price": "0.01", "size": "11488.06", "side": "BUY", "hash": "8ae797dd42cb6e897af0c37d476374b8c8522dbb", "best_bid": "0.1", "best_ask": "0.94"}, {"asset_id": "16789388635872606083420797498193234014051215847692022335228605649270582798108", "price": "0.99", "size": "11488.06", "side": "SELL", "hash": "f08212f5756e49f97cf797ac127c7eed20cead07", "best_bid": "0.06", "best_ask": "0.9"}], "timestamp": "1769384218252", "event_type": "price_change"}}
{"_local_timestamp": "2026-01-25T23:36:58.592574+00:00", "data": {"market": "0x955dd36f151fe79cda775370a2e09049998932d5ea090d97bf0e2fde8f11b26d", "price_changes": [{"asset_id": "75456459287302166180376724549100719042861942676472232348454693844887341622859", "price": "0.02", "size": "150", "side": "BUY", "hash": "ed767451e341bc370d01a76aee8e78c42b2817e9", "best_bid": "0.33", "best_ask": "0.71"}, {"asset_id": "11868101818250841972253954473857780150009778302053902404036716275197677080100", "price": "0.98", "size": "150", "side": "SELL", "hash": "c132234c0d79102313631ca0882ff0d4f718d00c", "best_bid": "0.29", "best_ask": "0.67"}], "timestamp": "1769384218335", "event_type": "price_change"}}
{"_local_timestamp": "2026-01-25T23:36:58.592992+00:00", "data": {"market": "0x955dd36f151fe79cda775370a2e09049998932d5ea090d97bf0e2fde8f11b26d", "price_changes": [{"asset_id": "11868101818250841972253954473857780150009778302053902404036716275197677080100", "price": "0.02", "size": "450", "side": "BUY", "hash": "9677369ad44cad27b7e46c1d7526ff9e6a4f19bb", "best_bid": "0.29", "best_ask": "0.67"}, {"asset_id": "75456459287302166180376724549100719042861942676472232348454693844887341622859", "price": "0.98", "size": "450", "side": "SELL", "hash": "a4c26d81b45069e663f4d01cec7fc51a92419535", "best_bid": "0.33", "best_ask": "0.71"}], "timestamp": "1769384218336", "event_type": "price_change"}}
{"_local_timestamp": "2026-01-25T23:36:58.593408+00:00", "data": {"market": "0x955dd36f151fe79cda775370a2e09049998932d5ea090d97bf0e2fde8f11b26d", "price_changes": [{"asset_id": "75456459287302166180376724549100719042861942676472232348454693844887341622859", "price": "0.13", "size": "1090.11", "side": "BUY", "hash": "cba9183e6ec3e2707804f993b116745e81b7499b", "best_bid": "0.33", "best_ask": "0.71"}, {"asset_id": "11868101818250841972253954473857780150009778302053902404036716275197677080100", "price": "0.87", "size": "1090.11", "side": "SELL", "hash": "4b9dc97f98deb2921e76f8eeb5be368058a033fb", "best_bid": "0.29", "best_ask": "0.67"}], "timestamp": "1769384218351", "event_type": "price_change"}}
{"_local_timestamp": "2026-01-25T23:36:58.601396+00:00", "data": {"market": "0x955dd36f151fe79cda775370a2e09049998932d5ea090d97bf0e2fde8f11b26d", "price_changes": [{"asset_id": "75456459287302166180376724549100719042861942676472232348454693844887341622859", "price": "0.14", "size": "1015.11", "side": "BUY", "hash": "a422b140e383762785bf568e53942c5ed81e3fe2", "best_bid": "0.33", "best_ask": "0.71"}, {"asset_id": "11868101818250841972253954473857780150009778302053902404036716275197677080100", "price": "0.86", "size": "1015.11", "side": "SELL", "hash": "f72f28e77cbef60dc5807d81b7efe0e4d11c2bb4", "best_bid": "0.29", "best_ask": "0.67"}], "timestamp": "1769384218351", "event_type": "price_change"}}
{"_local_timestamp": "2026-01-25T23:36:58.609401+00:00", "data": {"market": "0x955dd36f151fe79cda775370a2e09049998932d5ea090d97bf0e2fde8f11b26d", "price_changes": [{"asset_id": "75456459287302166180376724549100719042861942676472232348454693844887341622859", "price": "0.01", "size": "7710.85", "side": "BUY", "hash": "c6231c24de72d42b49ec2a45c74740a264c7ec47", "best_bid": "0.33", "best_ask": "0.71"}, {"asset_id": "11868101818250841972253954473857780150009778302053902404036716275197677080100", "price": "0.99", "size": "7710.85", "side": "SELL", "hash": "d92527b61cf538dbc92ab68529615566cfe1f4d9", "best_bid": "0.29", "best_ask": "0.67"}], "timestamp": "1769384218352", "event_type": "price_change"}}
{"_local_timestamp": "2026-01-25T23:36:58.609788+00:00", "data": {"market": "0x955dd36f151fe79cda775370a2e09049998932d5ea090d97bf0e2fde8f11b26d", "price_changes": [{"asset_id": "75456459287302166180376724549100719042861942676472232348454693844887341622859", "price": "0.01", "size": "8600.96", "side": "BUY", "hash": "606114a1fb837113d73646fa77fdf772cefd5c1c", "best_bid": "0.33", "best_ask": "0.71"}, {"asset_id": "11868101818250841972253954473857780150009778302053902404036716275197677080100", "price": "0.99", "size": "8600.96", "side": "SELL", "hash": "c3cf713d10fd2aaf81d55cdcaf84f96b946295b2", "best_bid": "0.29", "best_ask": "0.67"}], "timestamp": "1769384218381", "event_type": "price_change"}}
{"_local_timestamp": "2026-01-25T23:36:58.657787+00:00", "data": {"market": "0x955dd36f151fe79cda775370a2e09049998932d5ea090d97bf0e2fde8f11b26d", "price_changes": [{"asset_id": "75456459287302166180376724549100719042861942676472232348454693844887341622859", "price": "0.01", "size": "10598.07", "side": "BUY", "hash": "22bc9f662f18a0f102bd77311a6077774c4d7f29", "best_bid": "0.33", "best_ask": "0.71"}, {"asset_id": "11868101818250841972253954473857780150009778302053902404036716275197677080100", "price": "0.99", "size": "10598.07", "side": "SELL", "hash": "bd258a39c7adca17fd6c165947b138cf09f72d2e", "best_bid": "0.29", "best_ask": "0.67"}], "timestamp": "1769384218382", "event_type": "price_change"}}
{"_local_timestamp": "2026-01-25T23:37:07.422499+00:00", "data": {"market": "0x955dd36f151fe79cda775370a2e09049998932d5ea090d97bf0e2fde8f11b26d", "price_changes": [{"asset_id": "11868101818250841972253954473857780150009778302053902404036716275197677080100", "price": "0.02", "size": "150", "side": "BUY", "hash": "9b5ae49594ed15424a84c70ac8e8633da4f19ae9", "best_bid": "0.29", "best_ask": "0.67"}, {"asset_id": "75456459287302166180376724549100719042861942676472232348454693844887341622859", "price": "0.98", "size": "150", "side": "SELL", "hash": "f47e2884a78dcd3f338fb2a487c9774dc4f5a5dd", "best_bid": "0.33", "best_ask": "0.71"}], "timestamp": "1769384227235", "event_type": "price_change"}}
{"_local_timestamp": "2026-01-25T23:37:07.473793+00:00", "data": {"market": "0x955dd36f151fe79cda775370a2e09049998932d5ea090d97bf0e2fde8f11b26d", "price_changes": [{"asset_id": "75456459287302166180376724549100719042861942676472232348454693844887341622859", "price": "0.2", "size": "0", "side": "BUY", "hash": "6ce8b8820b54aaf5302b67f85a4b33031fc2eabe", "best_bid": "0.33", "best_ask": "0.71"}, {"asset_id": "11868101818250841972253954473857780150009778302053902404036716275197677080100", "price": "0.8", "size": "0", "side": "SELL", "hash": "beb567d4e7915f87fa3b3c7531b504f701cb7007", "best_bid": "0.29", "best_ask": "0.67"}], "timestamp": "1769384227289", "event_type": "price_change"}}
{"_local_timestamp": "2026-01-25T23:37:07.474184+00:00", "data": {"market": "0x955dd36f151fe79cda775370a2e09049998932d5ea090d97bf0e2fde8f11b26d", "price_changes": [{"asset_id": "75456459287302166180376724549100719042861942676472232348454693844887341622859", "price": "0.19", "size": "0", "side": "BUY", "hash": "6ce8b8820b54aaf5302b67f85a4b33031fc2eabe", "best_bid": "0.33", "best_ask": "0.71"}, {"asset_id": "11868101818250841972253954473857780150009778302053902404036716275197677080100", "price": "0.81", "size": "0", "side": "SELL", "hash": "beb567d4e7915f87fa3b3c7531b504f701cb7007", "best_bid": "0.29", "best_ask": "0.67"}], "timestamp": "1769384227289", "event_type": "price_change"}}
{"_local_timestamp": "2026-01-25T23:37:07.628238+00:00", "data": {"market": "0x955dd36f151fe79cda775370a2e09049998932d5ea090d97bf0e2fde8f11b26d", "price_changes": [{"asset_id": "11868101818250841972253954473857780150009778302053902404036716275197677080100", "price": "0.01", "size": "10848.67", "side": "BUY", "hash": "a6b09097a48d3ee661f79cccb6f9cc92c9579285", "best_bid": "0.29", "best_ask": "0.67"}, {"asset_id": "75456459287302166180376724549100719042861942676472232348454693844887341622859", "price": "0.99", "size": "10848.67", "side": "SELL", "hash": "8e776a81936bf165309315d9bc5c1bd85ceb5645", "best_bid": "0.33", "best_ask": "0.71"}], "timestamp": "1769384227458", "event_type": "price_change"}}
{"_local_timestamp": "2026-01-25T23:37:07.632205+00:00", "data": {"market": "0x955dd36f151fe79cda775370a2e09049998932d5ea090d97bf0e2fde8f11b26d", "price_changes": [{"asset_id": "75456459287302166180376724549100719042861942676472232348454693844887341622859", "price": "0.01", "size": "10998.07", "side": "BUY", "hash": "58ec3e917ee2740298cb3258ac87979281fc2c36", "best_bid": "0.33", "best_ask": "0.71"}, {"asset_id": "11868101818250841972253954473857780150009778302053902404036716275197677080100", "price": "0.99", "size": "10998.07", "side": "SELL", "hash": "e27ba08d660d3923ee86b74caa91c92abfaaaa1a", "best_bid": "0.29", "best_ask": "0.67"}], "timestamp": "1769384227459", "event_type": "price_change"}}
{"_local_timestamp": "2026-01-25T23:37:07.681585+00:00", "data": {"market": "0x955dd36f151fe79cda775370a2e09049998932d5ea090d97bf0e2fde8f11b26d", "price_changes": [{"asset_id": "11868101818250841972253954473857780150009778302053902404036716275197677080100", "price": "0.02", "size": "1040.11", "side": "BUY", "hash": "c13a8e986d8fee6a7411a071cf2029a4ac1ceed5", "best_bid": "0.29", "best_ask": "0.67"}, {"asset_id": "75456459287302166180376724549100719042861942676472232348454693844887341622859", "price": "0.98", "size": "1040.11", "side": "SELL", "hash": "92981b60e423a19878e062de449a743de66bb227", "best_bid": "0.33", "best_ask": "0.71"}], "timestamp": "1769384227514", "event_type": "price_change"}}
{"_local_timestamp": "2026-01-25T23:37:07.682015+00:00", "data": {"market": "0x955dd36f151fe79cda775370a2e09049998932d5ea090d97bf0e2fde8f11b26d", "price_changes": [{"asset_id": "11868101818250841972253954473857780150009778302053902404036716275197677080100", "price": "0.02", "size": "3037.22", "side": "BUY", "hash": "f0cb9161367521e7bc89bbefc39bb523b0eee880", "best_bid": "0.29", "best_ask": "0.67"}, {"asset_id": "75456459287302166180376724549100719042861942676472232348454693844887341622859", "price": "0.98", "size": "3037.22", "side": "SELL", "hash": "dc22342d4037f3988f0ebd94637773fbf1414f58", "best_bid": "0.33", "best_ask": "0.71"}], "timestamp": "1769384227516", "event_type": "price_change"}}
{"_local_timestamp": "2026-01-25T23:37:07.683910+00:00", "data": {"market": "0x955dd36f151fe79cda775370a2e09049998932d5ea090d97bf0e2fde8f11b26d", "price_changes": [{"asset_id": "11868101818250841972253954473857780150009778302053902404036716275197677080100", "price": "0.02", "size": "4307.32", "side": "BUY", "hash": "261c90809be1cfd9f8d431236ca2f238c33e5438", "best_bid": "0.29", "best_ask": "0.67"}, {"asset_id": "75456459287302166180376724549100719042861942676472232348454693844887341622859", "price": "0.98", "size": "4307.32", "side": "SELL", "hash": "c6f7241d8c4dcbffe36aba9feda5b71276e92004", "best_bid": "0.33", "best_ask": "0.71"}], "timestamp": "1769384227519", "event_type": "price_change"}}
{"_local_timestamp": "2026-01-25T23:37:19.816152+00:00", "data": {"market": "0x955dd36f151fe79cda775370a2e09049998932d5ea090d97bf0e2fde8f11b26d", "price_changes": [{"asset_id": "11868101818250841972253954473857780150009778302053902404036716275197677080100", "price": "0.01", "size": "10448.67", "side": "BUY", "hash": "28c29857e3fa12b0ba0e139d08e69d60e6098b55", "best_bid": "0.29", "best_ask": "0.67"}, {"asset_id": "75456459287302166180376724549100719042861942676472232348454693844887341622859", "price": "0.99", "size": "10448.67", "side": "SELL", "hash": "919f7f4a29f5518190b1ec099733145059cd0a47", "best_bid": "0.33", "best_ask": "0.71"}], "timestamp": "1769384239726", "event_type": "price_change"}}
{"_local_timestamp": "2026-01-25T23:37:19.891608+00:00", "data": {"market": "0x955dd36f151fe79cda775370a2e09049998932d5ea090d97bf0e2fde8f11b26d", "price_changes": [{"asset_id": "75456459287302166180376724549100719042861942676472232348454693844887341622859", "price": "0.02", "size": "1420.1", "side": "BUY", "hash": "2a65e3891438bebe59ccb33c8b928a3d3b945f77", "best_bid": "0.33", "best_ask": "0.71"}, {"asset_id": "11868101818250841972253954473857780150009778302053902404036716275197677080100", "price": "0.98", "size": "1420.1", "side": "SELL", "hash": "cb9570154da3a78edfdec863d585766fe0917793", "best_bid": "0.29", "best_ask": "0.67"}], "timestamp": "1769384239786", "event_type": "price_change"}}
{"_local_timestamp": "2026-01-25T23:37:19.892011+00:00", "data": {"market": "0x955dd36f151fe79cda775370a2e09049998932d5ea090d97bf0e2fde8f11b26d", "price_changes": [{"asset_id": "75456459287302166180376724549100719042861942676472232348454693844887341622859", "price": "0.02", "size": "2310.21", "side": "BUY", "hash": "e551a45c9929263d7bae4589cccc3952489ae39e", "best_bid": "0.33", "best_ask": "0.71"}, {"asset_id": "11868101818250841972253954473857780150009778302053902404036716275197677080100", "price": "0.98", "size": "2310.21", "side": "SELL", "hash": "479697a1ea435760bd3dc9307b5bcd06000fa8dc", "best_bid": "0.29", "best_ask": "0.67"}], "timestamp": "1769384239786", "event_type": "price_change"}}
{"_local_timestamp": "2026-01-25T23:37:19.892375+00:00", "data": {"market": "0x955dd36f151fe79cda775370a2e09049998932d5ea090d97bf0e2fde8f11b26d", "price_changes": [{"asset_id": "75456459287302166180376724549100719042861942676472232348454693844887341622859", "price": "0.02", "size": "4307.32", "side": "BUY", "hash": "9345c96aff3fb5d43b343d671fbf976054d80fd8", "best_bid": "0.33", "best_ask": "0.71"}, {"asset_id": "11868101818250841972253954473857780150009778302053902404036716275197677080100", "price": "0.98", "size": "4307.32", "side": "SELL", "hash": "a9c1445e0fa136b909f7602a8645c8bedf228fb9", "best_bid": "0.29", "best_ask": "0.67"}], "timestamp": "1769384239787", "event_type": "price_change"}}
{"_local_timestamp": "2026-01-25T23:37:19.906320+00:00", "data": {"market": "0x955dd36f151fe79cda775370a2e09049998932d5ea090d97bf0e2fde8f11b26d", "price_changes": [{"asset_id": "75456459287302166180376724549100719042861942676472232348454693844887341622859", "price": "0.01", "size": "6840.75", "side": "BUY", "hash": "fede3f7faeef6e2390da3e24598517b661cbbf7f", "best_bid": "0.33", "best_ask": "0.71"}, {"asset_id": "11868101818250841972253954473857780150009778302053902404036716275197677080100", "price": "0.99", "size": "6840.75", "side": "SELL", "hash": "d209a40f05414687c13aafcdcb0d0d92706abb45", "best_bid": "0.29", "best_ask": "0.67"}], "timestamp": "1769384239840", "event_type": "price_change"}}
{"_local_timestamp": "2026-01-25T23:37:19.911262+00:00", "data": {"market": "0x955dd36f151fe79cda775370a2e09049998932d5ea090d97bf0e2fde8f11b26d", "price_changes": [{"asset_id": "11868101818250841972253954473857780150009778302053902404036716275197677080100", "price": "0.02", "size": "150", "side": "BUY", "hash": "b158347c144e9216570a22f812153e2a5de334c4", "best_bid": "0.29", "best_ask": "0.67"}, {"asset_id": "75456459287302166180376724549100719042861942676472232348454693844887341622859", "price": "0.98", "size": "150", "side": "SELL", "hash": "99bfbb325614b87b3a6979a8522e0d26b151ddbb", "best_bid": "0.33", "best_ask": "0.71"}], "timestamp": "1769384239840", "event_type": "price_change"}}
{"_local_timestamp": "2026-01-25T23:37:20.027102+00:00", "data": {"market": "0x955dd36f151fe79cda775370a2e09049998932d5ea090d97bf0e2fde8f11b26d", "price_changes": [{"asset_id": "11868101818250841972253954473857780150009778302053902404036716275197677080100", "price": "0.02", "size": "450", "side": "BUY", "hash": "9b7b39822be76ba9d0e64a8221347b3152765508", "best_bid": "0.29", "best_ask": "0.67"}, {"asset_id": "75456459287302166180376724549100719042861942676472232348454693844887341622859", "price": "0.98", "size": "450", "side": "SELL", "hash": "26d303f689636251a04cc7031ce468d72c0b8d47", "best_bid": "0.33", "best_ask": "0.71"}], "timestamp": "1769384239959", "event_type": "price_change"}}
{"_local_timestamp": "2026-01-25T23:37:20.081065+00:00", "data": {"market": "0x955dd36f151fe79cda775370a2e09049998932d5ea090d97bf0e2fde8f11b26d", "price_changes": [{"asset_id": "75456459287302166180376724549100719042861942676472232348454693844887341622859", "price": "0.02", "size": "10306.43", "side": "BUY", "hash": "2c9ea2f208d75e0fd8381ecc1153538693eebd0a", "best_bid": "0.33", "best_ask": "0.71"}, {"asset_id": "11868101818250841972253954473857780150009778302053902404036716275197677080100", "price": "0.98", "size": "10306.43", "side": "SELL", "hash": "1700adca6c887645a8e4d46696c859642258d682", "best_bid": "0.29", "best_ask": "0.67"}], "timestamp": "1769384240000", "event_type": "price_change"}}
{"_local_timestamp": "2026-01-25T23:37:31.435380+00:00", "data": {"market": "0x955dd36f151fe79cda775370a2e09049998932d5ea090d97bf0e2fde8f11b26d", "price_changes": [{"asset_id": "11868101818250841972253954473857780150009778302053902404036716275197677080100", "price": "0.02", "size": "150", "side": "BUY", "hash": "51c0c99627a381691a67ad6e2e54dbbae78a7b46", "best_bid": "0.29", "best_ask": "0.67"}, {"asset_id": "75456459287302166180376724549100719042861942676472232348454693844887341622859", "price": "0.98", "size": "150", "side": "SELL", "hash": "8cd9796a63fa2f6c425c8b4ccf293103784f3de0", "best_bid": "0.33", "best_ask": "0.71"}], "timestamp": "1769384251367", "event_type": "price_change"}}
{"_local_timestamp": "2026-01-25T23:37:31.442968+00:00", "data": {"market": "0x955dd36f151fe79cda775370a2e09049998932d5ea090d97bf0e2fde8f11b26d", "price_changes": [{"asset_id": "75456459287302166180376724549100719042861942676472232348454693844887341622859", "price": "0.01", "size": "6440.75", "side": "BUY", "hash": "299ca3b649f2cc3ea2afdafc38405d7b1e038753", "best_bid": "0.33", "best_ask": "0.71"}, {"asset_id": "11868101818250841972253954473857780150009778302053902404036716275197677080100", "price": "0.99", "size": "6440.75", "side": "SELL", "hash": "82ba09c231746a0a00b4270ffe622c4228debc2e", "best_bid": "0.29", "best_ask": "0.67"}], "timestamp": "1769384251368", "event_type": "price_change"}}
{"_local_timestamp": "2026-01-25T23:37:31.505194+00:00", "data": {"market": "0x955dd36f151fe79cda775370a2e09049998932d5ea090d97bf0e2fde8f11b26d", "price_changes": [{"asset_id": "75456459287302166180376724549100719042861942676472232348454693844887341622859", "price": "0.02", "size": "4307.32", "side": "BUY", "hash": "07010426df4ff0364d591cee1314df102287521b", "best_bid": "0.33", "best_ask": "0.71"}, {"asset_id": "11868101818250841972253954473857780150009778302053902404036716275197677080100", "price": "0.98", "size": "4307.32", "side": "SELL", "hash": "c262c70414e05aca9cf4033584f7c9234448927e", "best_bid": "0.29", "best_ask": "0.67"}], "timestamp": "1769384251429", "event_type": "price_change"}}
{"_local_timestamp": "2026-01-25T23:37:31.571138+00:00", "data": {"market": "0x955dd36f151fe79cda775370a2e09049998932d5ea090d97bf0e2fde8f11b26d", "price_changes": [{"asset_id": "75456459287302166180376724549100719042861942676472232348454693844887341622859", "price": "0.03", "size": "1275.24", "side": "BUY", "hash": "48b78dc3bc619cdf75505b607a1fba6e7499f264", "best_bid": "0.33", "best_ask": "0.71"}, {"asset_id": "11868101818250841972253954473857780150009778302053902404036716275197677080100", "price": "0.97", "size": "1275.24", "side": "SELL", "hash": "d2117037fcbf8d84e627a36e19c23812accf4e79", "best_bid": "0.29", "best_ask": "0.67"}], "timestamp": "1769384251488", "event_type": "price_change"}}
{"_local_timestamp": "2026-01-25T23:37:31.580922+00:00", "data": {"market": "0x955dd36f151fe79cda775370a2e09049998932d5ea090d97bf0e2fde8f11b26d", "price_changes": [{"asset_id": "75456459287302166180376724549100719042861942676472232348454693844887341622859", "price": "0.03", "size": "2165.35", "side": "BUY", "hash": "879e20b7201cfbde6ba7859a2bf3742519f002f1", "best_bid": "0.33", "best_ask": "0.71"}, {"asset_id": "11868101818250841972253954473857780150009778302053902404036716275197677080100", "price": "0.97", "size": "2165.35", "side": "SELL", "hash": "b0ddd4726db8109f6ccf3d9aa1c3db8be35f94cb", "best_bid": "0.29", "best_ask": "0.67"}], "timestamp": "1769384251493", "event_type": "price_change"}}
{"_local_timestamp": "2026-01-25T23:37:31.581336+00:00", "data": {"market": "0x955dd36f151fe79cda775370a2e09049998932d5ea090d97bf0e2fde8f11b26d", "price_changes": [{"asset_id": "75456459287302166180376724549100719042861942676472232348454693844887341622859", "price": "0.03", "size": "4162.46", "side": "BUY", "hash": "a80bc76d6a796c477f8fcdcad5570552202a9d3c", "best_bid": "0.33", "best_ask": "0.71"}, {"asset_id": "11868101818250841972253954473857780150009778302053902404036716275197677080100", "price": "0.97", "size": "4162.46", "side": "SELL", "hash": "9abe55fb340313f38cd61d969c19be0ae7db1444", "best_bid": "0.29", "best_ask": "0.67"}], "timestamp": "1769384251495", "event_type": "price_change"}}
{"_local_timestamp": "2026-01-25T23:37:31.581740+00:00", "data": {"market": "0x955dd36f151fe79cda775370a2e09049998932d5ea090d97bf0e2fde8f11b26d", "price_changes": [{"asset_id": "75456459287302166180376724549100719042861942676472232348454693844887341622859", "price": "0.03", "size": "10161.57", "side": "BUY", "hash": "eb27db0974f316f5299a3070aeaddc34c2ea65eb", "best_bid": "0.33", "best_ask": "0.71"}, {"asset_id": "11868101818250841972253954473857780150009778302053902404036716275197677080100", "price": "0.97", "size": "10161.57", "side": "SELL", "hash": "2cc9ca5bc9054f5c583f4ea58e14c81325c3b2ea", "best_bid": "0.29", "best_ask": "0.67"}], "timestamp": "1769384251498", "event_type": "price_change"}}
{"_local_timestamp": "2026-01-25T23:37:31.664735+00:00", "data": {"market": "0x955dd36f151fe79cda775370a2e09049998932d5ea090d97bf0e2fde8f11b26d", "price_changes": [{"asset_id": "11868101818250841972253954473857780150009778302053902404036716275197677080100", "price": "0.01", "size": "10848.67", "side": "BUY", "hash": "48074f701ef9bf70cacccc250e35900274eeba3f", "best_bid": "0.29", "best_ask": "0.67"}, {"asset_id": "75456459287302166180376724549100719042861942676472232348454693844887341622859", "price": "0.99", "size": "10848.67", "side": "SELL", "hash": "6b64a0b822567b2b6b946ea6e87b991f78e3b3e0", "best_bid": "0.33", "best_ask": "0.71"}], "timestamp": "1769384251584", "event_type": "price_change"}}
{"_local_timestamp": "2026-01-25T23:38:00.277453+00:00", "data": {"market": "0x097acba899c5c032ec4a662533aa4d56d6bda9117b0af7aea425d8d7502b095a", "price_changes": [{"asset_id": "94699601023424120682437549172990814687230320631825203249003963868534845660161", "price": "0.06", "size": "47.95", "side": "BUY", "hash": "10b84c8f4028bba286b17376ad5d0112cc43d45e", "best_bid": "0.1", "best_ask": "0.94"}, {"asset_id": "16789388635872606083420797498193234014051215847692022335228605649270582798108", "price": "0.94", "size": "47.95", "side": "SELL", "hash": "fb0bce4e369da5263e3d2bba31fc8ae2c7d099ce", "best_bid": "0.06", "best_ask": "0.9"}], "timestamp": "1769384280154", "event_type": "price_change"}}
{"_local_timestamp": "2026-01-25T23:38:00.279342+00:00", "data": {"market": "0x955dd36f151fe79cda775370a2e09049998932d5ea090d97bf0e2fde8f11b26d", "price_changes": [{"asset_id": "75456459287302166180376724549100719042861942676472232348454693844887341622859", "price": "0.21", "size": "300", "side": "BUY", "hash": "056e52b7d132c5b5a77e9393740cf9dc0f026a7e", "best_bid": "0.33", "best_ask": "0.71"}, {"asset_id": "11868101818250841972253954473857780150009778302053902404036716275197677080100", "price": "0.79", "size": "300", "side": "SELL", "hash": "ea72cbff69ce52f49d59f37651afebe168f0354b", "best_bid": "0.29", "best_ask": "0.67"}], "timestamp": "1769384280155", "event_type": "price_change"}}
{"_local_timestamp": "2026-01-25T23:38:00.359363+00:00", "data": {"market": "0x097acba899c5c032ec4a662533aa4d56d6bda9117b0af7aea425d8d7502b095a", "price_changes": [{"asset_id": "94699601023424120682437549172990814687230320631825203249003963868534845660161", "price": "0.1", "size": "0", "side": "BUY", "hash": "47c6b1afb854e8086e067c06bf2801cdf6082425", "best_bid": "0.06", "best_ask": "0.94"}, {"asset_id": "16789388635872606083420797498193234014051215847692022335228605649270582798108", "price": "0.9", "size": "0", "side": "SELL", "hash": "6a8b4f6c3b38e9500641d453d3d96d1f90eebd11", "best_bid": "0.06", "best_ask": "0.94"}], "timestamp": "1769384280262", "event_type": "price_change"}}
{"_local_timestamp": "2026-01-25T23:38:00.359819+00:00", "data": {"market": "0x097acba899c5c032ec4a662533aa4d56d6bda9117b0af7aea425d8d7502b095a", "price_changes": [{"asset_id": "94699601023424120682437549172990814687230320631825203249003963868534845660161", "price": "0.09", "size": "0", "side": "BUY", "hash": "47c6b1afb854e8086e067c06bf2801cdf6082425", "best_bid": "0.06", "best_ask": "0.94"}, {"asset_id": "16789388635872606083420797498193234014051215847692022335228605649270582798108", "price": "0.91", "size": "0", "side": "SELL", "hash": "6a8b4f6c3b38e9500641d453d3d96d1f90eebd11", "best_bid": "0.06", "best_ask": "0.94"}], "timestamp": "1769384280262", "event_type": "price_change"}}
{"_local_timestamp": "2026-01-25T23:38:00.360491+00:00", "data": {"market": "0x955dd36f151fe79cda775370a2e09049998932d5ea090d97bf0e2fde8f11b26d", "price_changes": [{"asset_id": "75456459287302166180376724549100719042861942676472232348454693844887341622859", "price": "0.02", "size": "150", "side": "BUY", "hash": "d2d342719227caabf9339877edcdafe6cbfe310f", "best_bid": "0.33", "best_ask": "0.71"}, {"asset_id": "11868101818250841972253954473857780150009778302053902404036716275197677080100", "price": "0.98", "size": "150", "side": "SELL", "hash": "28de4d044482a8cc85189c197340fdd7ada7e662", "best_bid": "0.29", "best_ask": "0.67"}], "timestamp": "1769384280263", "event_type": "price_change"}}
{"_local_timestamp": "2026-01-25T23:38:00.361012+00:00", "data": {"market": "0x955dd36f151fe79cda775370a2e09049998932d5ea090d97bf0e2fde8f11b26d", "price_changes": [{"asset_id": "75456459287302166180376724549100719042861942676472232348454693844887341622859", "price": "0.03", "size": "5.14", "side": "BUY", "hash": "d2d342719227caabf9339877edcdafe6cbfe310f", "best_bid": "0.33", "best_ask": "0.71"}, {"asset_id": "11868101818250841972253954473857780150009778302053902404036716275197677080100", "price": "0.97", "size": "5.14", "side": "SELL", "hash": "28de4d044482a8cc85189c197340fdd7ada7e662", "best_bid": "0.29", "best_ask": "0.67"}], "timestamp": "1769384280263", "event_type": "price_change"}}
{"_local_timestamp": "2026-01-25T23:38:00.361683+00:00", "data": {"market": "0x955dd36f151fe79cda775370a2e09049998932d5ea090d97bf0e2fde8f11b26d", "price_changes": [{"asset_id": "11868101818250841972253954473857780150009778302053902404036716275197677080100", "price": "0.01", "size": "6691.35", "side": "BUY", "hash": "619c087bc4d0ee26a00eaaa54dcd9f1bd4ba2fde", "best_bid": "0.29", "best_ask": "0.67"}, {"asset_id": "75456459287302166180376724549100719042861942676472232348454693844887341622859", "price": "0.99", "size": "6691.35", "side": "SELL", "hash": "136e15db4a1bf31cb494cc63e5f6d2fabf5b1ac3", "best_bid": "0.33", "best_ask": "0.71"}], "timestamp": "1769384280263", "event_type": "price_change"}}
{"_local_timestamp": "2026-01-25T23:38:00.510277+00:00", "data": {"market": "0x955dd36f151fe79cda775370a2e09049998932d5ea090d97bf0e2fde8f11b26d", "price_changes": [{"asset_id": "75456459287302166180376724549100719042861942676472232348454693844887341622859", "price": "0.01", "size": "7710.85", "side": "BUY", "hash": "506a7f8818ff524bb874f3313d8f76556e03151a", "best_bid": "0.33", "best_ask": "0.71"}, {"asset_id": "11868101818250841972253954473857780150009778302053902404036716275197677080100", "price": "0.99", "size": "7710.85", "side": "SELL", "hash": "8a9fb430746fd639076653a772b5c56b0b7b802a", "best_bid": "0.29", "best_ask": "0.67"}], "timestamp": "1769384280404", "event_type": "price_change"}}
{"_local_timestamp": "2026-01-25T23:38:00.514975+00:00", "data": {"market": "0x955dd36f151fe79cda775370a2e09049998932d5ea090d97bf0e2fde8f11b26d", "price_changes": [{"asset_id": "11868101818250841972253954473857780150009778302053902404036716275197677080100", "price": "0.02", "size": "1420.1", "side": "BUY", "hash": "59688ad0f1635b052736f351417aa422819875ae", "best_bid": "0.29", "best_ask": "0.67"}, {"asset_id": "75456459287302166180376724549100719042861942676472232348454693844887341622859", "price": "0.98", "size": "1420.1", "side": "SELL", "hash": "3df566c24346d6be70558a247b50b73dfb7d0026", "best_bid": "0.33", "best_ask": "0.71"}], "timestamp": "1769384280404", "event_type": "price_change"}}
{"_local_timestamp": "2026-01-25T23:38:00.515494+00:00", "data": {"market": "0x955dd36f151fe79cda775370a2e09049998932d5ea090d97bf0e2fde8f11b26d", "price_changes": [{"asset_id": "75456459287302166180376724549100719042861942676472232348454693844887341622859", "price": "0.01", "size": "8600.96", "side": "BUY", "hash": "f8fc820bdba4a955a2bc80c8c3255e4ce896c34c", "best_bid": "0.33", "best_ask": "0.71"}, {"asset_id": "11868101818250841972253954473857780150009778302053902404036716275197677080100", "price": "0.99", "size": "8600.96", "side": "SELL", "hash": "5374648be1031c46645ac010c31af9f90f2dd343", "best_bid": "0.29", "best_ask": "0.67"}], "timestamp": "1769384280405", "event_type": "price_change"}}
{"_local_timestamp": "2026-01-25T23:38:00.515988+00:00", "data": {"market": "0x955dd36f151fe79cda775370a2e09049998932d5ea090d97bf0e2fde8f11b26d", "price_changes": [{"asset_id": "75456459287302166180376724549100719042861942676472232348454693844887341622859", "price": "0.22", "size": "890.11", "side": "BUY", "hash": "7bd5a5a54d44caa8ea4e3f2d02d880dc388088e3", "best_bid": "0.33", "best_ask": "0.71"}, {"asset_id": "11868101818250841972253954473857780150009778302053902404036716275197677080100", "price": "0.78", "size": "890.11", "side": "SELL", "hash": "b4eafc95f3b227ff9a08d5bd84435eb1549174a2", "best_bid": "0.29", "best_ask": "0.67"}], "timestamp": "1769384280406", "event_type": "price_change"}}
{"_local_timestamp": "2026-01-25T23:38:00.516399+00:00", "data": {"market": "0x955dd36f151fe79cda775370a2e09049998932d5ea090d97bf0e2fde8f11b26d", "price_changes": [{"asset_id": "75456459287302166180376724549100719042861942676472232348454693844887341622859", "price": "0.21", "size": "1190.11", "side": "BUY", "hash": "e2ec952ef8327d72420c0b1163a2f26770307015", "best_bid": "0.33", "best_ask": "0.71"}, {"asset_id": "11868101818250841972253954473857780150009778302053902404036716275197677080100", "price": "0.79", "size": "1190.11", "side": "SELL", "hash": "ba7f649676d555ca9918c49e98e7c229541f9d5b", "best_bid": "0.29", "best_ask": "0.67"}], "timestamp": "1769384280406", "event_type": "price_change"}}
{"_local_timestamp": "2026-01-25T23:38:00.523687+00:00", "data": {"market": "0x955dd36f151fe79cda775370a2e09049998932d5ea090d97bf0e2fde8f11b26d", "price_changes": [{"asset_id": "11868101818250841972253954473857780150009778302053902404036716275197677080100", "price": "0.02", "size": "2310.21", "side": "BUY", "hash": "bbdc2197062a75d1b49d3e2ab9895fa6129fb190", "best_bid": "0.29", "best_ask": "0.67"}, {"asset_id": "75456459287302166180376724549100719042861942676472232348454693844887341622859", "price": "0.98", "size": "2310.21", "side": "SELL", "hash": "95f9d15af942434f898154be1e55d38e9c8a63aa", "best_bid": "0.33", "best_ask": "0.71"}], "timestamp": "1769384280407", "event_type": "price_change"}}
{"_local_timestamp": "2026-01-25T23:38:00.524220+00:00", "data": {"market": "0x955dd36f151fe79cda775370a2e09049998932d5ea090d97bf0e2fde8f11b26d", "price_changes": [{"asset_id": "11868101818250841972253954473857780150009778302053902404036716275197677080100", "price": "0.02", "size": "4307.32", "side": "BUY", "hash": "06758746f3224a6b9c3097cd8103514de4c03411", "best_bid": "0.29", "best_ask": "0.67"}, {"asset_id": "75456459287302166180376724549100719042861942676472232348454693844887341622859", "price": "0.98", "size": "4307.32", "side": "SELL", "hash": "9ed37bde1c74919d75bec93538d15696e3636300", "best_bid": "0.33", "best_ask": "0.71"}], "timestamp": "1769384280408", "event_type": "price_change"}}
{"_local_timestamp": "2026-01-25T23:38:00.531122+00:00", "data": {"market": "0x955dd36f151fe79cda775370a2e09049998932d5ea090d97bf0e2fde8f11b26d", "price_changes": [{"asset_id": "75456459287302166180376724549100719042861942676472232348454693844887341622859", "price": "0.01", "size": "10598.07", "side": "BUY", "hash": "fe0b9012e4d0db57db07c7f3500719ed8289adfc", "best_bid": "0.33", "best_ask": "0.71"}, {"asset_id": "11868101818250841972253954473857780150009778302053902404036716275197677080100", "price": "0.99", "size": "10598.07", "side": "SELL", "hash": "ba485026a3aa11beef20bc309ea4675cc63a0ea1", "best_bid": "0.29", "best_ask": "0.67"}], "timestamp": "1769384280408", "event_type": "price_change"}}
{"_local_timestamp": "2026-01-25T23:38:07.616274+00:00", "data": {"market": "0x955dd36f151fe79cda775370a2e09049998932d5ea090d97bf0e2fde8f11b26d", "price_changes": [{"asset_id": "11868101818250841972253954473857780150009778302053902404036716275197677080100", "price": "0.01", "size": "6291.35", "side": "BUY", "hash": "d3e704e20e9da6f432fd4b8293faf9bf10813d11", "best_bid": "0.29", "best_ask": "0.67"}, {"asset_id": "75456459287302166180376724549100719042861942676472232348454693844887341622859", "price": "0.99", "size": "6291.35", "side": "SELL", "hash": "0645ffd72e46cda10ecbdee6f32a5f21202db30e", "best_bid": "0.33", "best_ask": "0.71"}], "timestamp": "1769384287472", "event_type": "price_change"}}
{"_local_timestamp": "2026-01-25T23:38:07.655235+00:00", "data": {"market": "0x955dd36f151fe79cda775370a2e09049998932d5ea090d97bf0e2fde8f11b26d", "price_changes": [{"asset_id": "11868101818250841972253954473857780150009778302053902404036716275197677080100", "price": "0.01", "size": "7181.46", "side": "BUY", "hash": "6147feafa45f8eb54aa1c939e67d9d126c450c1e", "best_bid": "0.29", "best_ask": "0.67"}, {"asset_id": "75456459287302166180376724549100719042861942676472232348454693844887341622859", "price": "0.99", "size": "7181.46", "side": "SELL", "hash": "a51999b57a189f10e5dfbb350afda09cbb32fd96", "best_bid": "0.33", "best_ask": "0.71"}], "timestamp": "1769384287520", "event_type": "price_change"}}
{"_local_timestamp": "2026-01-25T23:38:07.655812+00:00", "data": {"market": "0x955dd36f151fe79cda775370a2e09049998932d5ea090d97bf0e2fde8f11b26d", "price_changes": [{"asset_id": "11868101818250841972253954473857780150009778302053902404036716275197677080100", "price": "0.01", "size": "9178.57", "side": "BUY", "hash": "dd0d791f0ebbc7f9a41b0e3629854e8f8e863521", "best_bid": "0.29", "best_ask": "0.67"}, {"asset_id": "75456459287302166180376724549100719042861942676472232348454693844887341622859", "price": "0.99", "size": "9178.57", "side": "SELL", "hash": "1b5a9d1ac1bfefb1138116cb8bc5e8abaf803408", "best_bid": "0.33", "best_ask": "0.71"}], "timestamp": "1769384287521", "event_type": "price_change"}}
{"_local_timestamp": "2026-01-25T23:38:07.656297+00:00", "data": {"market": "0x955dd36f151fe79cda775370a2e09049998932d5ea090d97bf0e2fde8f11b26d", "price_changes": [{"asset_id": "11868101818250841972253954473857780150009778302053902404036716275197677080100", "price": "0.01", "size": "10448.67", "side": "BUY", "hash": "b442f6096c1d505f9a9a10669849a673a8345efb", "best_bid": "0.29", "best_ask": "0.67"}, {"asset_id": "75456459287302166180376724549100719042861942676472232348454693844887341622859", "price": "0.99", "size": "10448.67", "side": "SELL", "hash": "8556fd1222a29ee70c0f20bcaf228a9ad2184d24", "best_bid": "0.33", "best_ask": "0.71"}], "timestamp": "1769384287521", "event_type": "price_change"}}
{"_local_timestamp": "2026-01-25T23:38:07.659926+00:00", "data": {"market": "0x955dd36f151fe79cda775370a2e09049998932d5ea090d97bf0e2fde8f11b26d", "price_changes": [{"asset_id": "75456459287302166180376724549100719042861942676472232348454693844887341622859", "price": "0.14", "size": "125", "side": "BUY", "hash": "ff28812ba8ab721dc29909f6a1727da67b2f77d7", "best_bid": "0.33", "best_ask": "0.71"}, {"asset_id": "11868101818250841972253954473857780150009778302053902404036716275197677080100", "price": "0.86", "size": "125", "side": "SELL", "hash": "bf5955b32dd0db9339870615f553de2d7b167386", "best_bid": "0.29", "best_ask": "0.67"}], "timestamp": "1769384287529", "event_type": "price_change"}}
{"_local_timestamp": "2026-01-25T23:38:07.660483+00:00", "data": {"market": "0x955dd36f151fe79cda775370a2e09049998932d5ea090d97bf0e2fde8f11b26d", "price_changes": [{"asset_id": "75456459287302166180376724549100719042861942676472232348454693844887341622859", "price": "0.13", "size": "200", "side": "BUY", "hash": "ff28812ba8ab721dc29909f6a1727da67b2f77d7", "best_bid": "0.33", "best_ask": "0.71"}, {"asset_id": "11868101818250841972253954473857780150009778302053902404036716275197677080100", "price": "0.87", "size": "200", "side": "SELL", "hash": "bf5955b32dd0db9339870615f553de2d7b167386", "best_bid": "0.29", "best_ask": "0.67"}], "timestamp": "1769384287529", "event_type": "price_change"}}
{"_local_timestamp": "2026-01-25T23:38:07.819285+00:00", "data": {"market": "0x955dd36f151fe79cda775370a2e09049998932d5ea090d97bf0e2fde8f11b26d", "price_changes": [{"asset_id": "75456459287302166180376724549100719042861942676472232348454693844887341622859", "price": "0.01", "size": "10998.07", "side": "BUY", "hash": "011f3a673872bf400fe476c11455ca8955743cb7", "best_bid": "0.33", "best_ask": "0.71"}, {"asset_id": "11868101818250841972253954473857780150009778302053902404036716275197677080100", "price": "0.99", "size": "10998.07", "side": "SELL", "hash": "d2d5661e8a1a955b3108ed0eae97a8ca123333a3", "best_bid": "0.29", "best_ask": "0.67"}], "timestamp": "1769384287704", "event_type": "price_change"}}
{"_local_timestamp": "2026-01-25T23:38:07.820429+00:00", "data": {"market": "0x955dd36f151fe79cda775370a2e09049998932d5ea090d97bf0e2fde8f11b26d", "price_changes": [{"asset_id": "11868101818250841972253954473857780150009778302053902404036716275197677080100", "price": "0.02", "size": "4607.32", "side": "BUY", "hash": "b615fe266eb4ec0533df27a735b3a1860db50d9b", "best_bid": "0.29", "best_ask": "0.67"}, {"asset_id": "75456459287302166180376724549100719042861942676472232348454693844887341622859", "price": "0.98", "size": "4607.32", "side": "SELL", "hash": "d5bea82c138347dfe3770eab0d20a3d58aaa482c", "best_bid": "0.33", "best_ask": "0.71"}], "timestamp": "1769384287705", "event_type": "price_change"}}
{"_local_timestamp": "2026-01-25T23:38:07.863895+00:00", "data": {"market": "0x955dd36f151fe79cda775370a2e09049998932d5ea090d97bf0e2fde8f11b26d", "price_changes": [{"asset_id": "11868101818250841972253954473857780150009778302053902404036716275197677080100", "price": "0.02", "size": "10606.43", "side": "BUY", "hash": "43d2f2d3ce806474c0edd0b8638a087e2c8a389a", "best_bid": "0.29", "best_ask": "0.67"}, {"asset_id": "75456459287302166180376724549100719042861942676472232348454693844887341622859", "price": "0.98", "size": "10606.43", "side": "SELL", "hash": "7b518479c3909c6ee49bd08d9348f6a9ffd36e44", "best_bid": "0.33", "best_ask": "0.71"}], "timestamp": "1769384287750", "event_type": "price_change"}}
{"_local_timestamp": "2026-01-25T23:38:41.129006+00:00", "data": {"market": "0x955dd36f151fe79cda775370a2e09049998932d5ea090d97bf0e2fde8f11b26d", "price_changes": [{"asset_id": "75456459287302166180376724549100719042861942676472232348454693844887341622859", "price": "0.01", "size": "11398.07", "side": "BUY", "hash": "58b227eead452ec730f9972695940d3792506d27", "best_bid": "0.33", "best_ask": "0.71"}, {"asset_id": "11868101818250841972253954473857780150009778302053902404036716275197677080100", "price": "0.99", "size": "11398.07", "side": "SELL", "hash": "56c68dfa0bd8b091870bba440c58db43043fdd2d", "best_bid": "0.29", "best_ask": "0.67"}], "timestamp": "1769384321042", "event_type": "price_change"}}
{"_local_timestamp": "2026-01-25T23:38:41.241096+00:00", "data": {"market": "0x955dd36f151fe79cda775370a2e09049998932d5ea090d97bf0e2fde8f11b26d", "price_changes": [{"asset_id": "11868101818250841972253954473857780150009778302053902404036716275197677080100", "price": "0.02", "size": "450", "side": "BUY", "hash": "ad710e389d8f26e30f2836880d4f9519aed13ae9", "best_bid": "0.29", "best_ask": "0.67"}, {"asset_id": "75456459287302166180376724549100719042861942676472232348454693844887341622859", "price": "0.98", "size": "450", "side": "SELL", "hash": "0aabf1859a55660d2156cf02dc88e3eae8eebc95", "best_bid": "0.33", "best_ask": "0.71"}], "timestamp": "1769384321152", "event_type": "price_change"}}
{"_local_timestamp": "2026-01-25T23:38:41.250158+00:00", "data": {"market": "0x955dd36f151fe79cda775370a2e09049998932d5ea090d97bf0e2fde8f11b26d", "price_changes": [{"asset_id": "75456459287302166180376724549100719042861942676472232348454693844887341622859", "price": "0.01", "size": "7240.75", "side": "BUY", "hash": "fb585a66e1ddf9a8cb3d6455da822679cfb1d279", "best_bid": "0.33", "best_ask": "0.71"}, {"asset_id": "11868101818250841972253954473857780150009778302053902404036716275197677080100", "price": "0.99", "size": "7240.75", "side": "SELL", "hash": "bce1d83854aa66cc7c48e816111664073885046d", "best_bid": "0.29", "best_ask": "0.67"}], "timestamp": "1769384321154", "event_type": "price_change"}}
{"_local_timestamp": "2026-01-25T23:38:41.294002+00:00", "data": {"market": "0x955dd36f151fe79cda775370a2e09049998932d5ea090d97bf0e2fde8f11b26d", "price_changes": [{"asset_id": "75456459287302166180376724549100719042861942676472232348454693844887341622859", "price": "0.02", "size": "1040.11", "side": "BUY", "hash": "6165bc4f5876fce72e28281ed38cd85260c69b22", "best_bid": "0.33", "best_ask": "0.71"}, {"asset_id": "11868101818250841972253954473857780150009778302053902404036716275197677080100", "price": "0.98", "size": "1040.11", "side": "SELL", "hash": "604dee656928470052c4542bb928189a86d234e1", "best_bid": "0.29", "best_ask": "0.67"}], "timestamp": "1769384321199", "event_type": "price_change"}}
{"_local_timestamp": "2026-01-25T23:38:41.294604+00:00", "data": {"market": "0x955dd36f151fe79cda775370a2e09049998932d5ea090d97bf0e2fde8f11b26d", "price_changes": [{"asset_id": "75456459287302166180376724549100719042861942676472232348454693844887341622859", "price": "0.02", "size": "2310.21", "side": "BUY", "hash": "9b06d5907436fb46a9378ffda1cb6ca024d097d4", "best_bid": "0.33", "best_ask": "0.71"}, {"asset_id": "11868101818250841972253954473857780150009778302053902404036716275197677080100", "price": "0.98", "size": "2310.21", "side": "SELL", "hash": "5d9f03312ab18364dffeba30af3af3b202598364", "best_bid": "0.29", "best_ask": "0.67"}], "timestamp": "1769384321203", "event_type": "price_change"}}
{"_local_timestamp": "2026-01-25T23:38:41.584338+00:00", "data": {"market": "0x955dd36f151fe79cda775370a2e09049998932d5ea090d97bf0e2fde8f11b26d", "price_changes": [{"asset_id": "75456459287302166180376724549100719042861942676472232348454693844887341622859", "price": "0.02", "size": "8309.32", "side": "BUY", "hash": "8ff3e9008bf0e281a7c8335e1375d3672f27eb4c", "best_bid": "0.33", "best_ask": "0.71"}, {"asset_id": "11868101818250841972253954473857780150009778302053902404036716275197677080100", "price": "0.98", "size": "8309.32", "side": "SELL", "hash": "cb94c827362fcdfd173e8bf710f7ff51f6ef56bc", "best_bid": "0.29", "best_ask": "0.67"}], "timestamp": "1769384321439", "event_type": "price_change"}}
{"_local_timestamp": "2026-01-25T23:38:41.590137+00:00", "data": {"market": "0x955dd36f151fe79cda775370a2e09049998932d5ea090d97bf0e2fde8f11b26d", "price_changes": [{"asset_id": "75456459287302166180376724549100719042861942676472232348454693844887341622859", "price": "0.02", "size": "10306.43", "side": "BUY", "hash": "9d25e719e5937078736cd1b2d7eca0f5e19f5770", "best_bid": "0.33", "best_ask": "0.71"}, {"asset_id": "11868101818250841972253954473857780150009778302053902404036716275197677080100", "price": "0.98", "size": "10306.43", "side": "SELL", "hash": "5cd2bf50ad7fc053faa4a0c5a602d17a0f2efdb0", "best_bid": "0.29", "best_ask": "0.67"}], "timestamp": "1769384321441", "event_type": "price_change"}}
{"_local_timestamp": "2026-01-25T23:38:55.896289+00:00", "data": {"market": "0x955dd36f151fe79cda775370a2e09049998932d5ea090d97bf0e2fde8f11b26d", "price_changes": [{"asset_id": "11868101818250841972253954473857780150009778302053902404036716275197677080100", "price": "0.02", "size": "150", "side": "BUY", "hash": "76f23f6bf61e3e753830e473a23c69824bf5c85d", "best_bid": "0.29", "best_ask": "0.67"}, {"asset_id": "75456459287302166180376724549100719042861942676472232348454693844887341622859", "price": "0.98", "size": "150", "side": "SELL", "hash": "6a7f4dca4ccdc5ab4e0bce41477bc48d53d0c9cd", "best_bid": "0.33", "best_ask": "0.71"}], "timestamp": "1769384335819", "event_type": "price_change"}}
{"_local_timestamp": "2026-01-25T23:38:55.977390+00:00", "data": {"market": "0x955dd36f151fe79cda775370a2e09049998932d5ea090d97bf0e2fde8f11b26d", "price_changes": [{"asset_id": "75456459287302166180376724549100719042861942676472232348454693844887341622859", "price": "0.02", "size": "4307.32", "side": "BUY", "hash": "741d758853361422f2540c3ba5128a42bf44aecb", "best_bid": "0.33", "best_ask": "0.71"}, {"asset_id": "11868101818250841972253954473857780150009778302053902404036716275197677080100", "price": "0.98", "size": "4307.32", "side": "SELL", "hash": "999cc238218faab5f0ff1e12cea36b0724713035", "best_bid": "0.29", "best_ask": "0.67"}], "timestamp": "1769384335897", "event_type": "price_change"}}
{"_local_timestamp": "2026-01-25T23:38:56.143550+00:00", "data": {"market": "0x955dd36f151fe79cda775370a2e09049998932d5ea090d97bf0e2fde8f11b26d", "price_changes": [{"asset_id": "11868101818250841972253954473857780150009778302053902404036716275197677080100", "price": "0.01", "size": "10848.67", "side": "BUY", "hash": "47dd136bece41f35e4bbf7a6ef9deadee531cc9c", "best_bid": "0.29", "best_ask": "0.67"}, {"asset_id": "75456459287302166180376724549100719042861942676472232348454693844887341622859", "price": "0.99", "size": "10848.67", "side": "SELL", "hash": "f252a781afbf0067211c34c3dfc5d41d0992f311", "best_bid": "0.33", "best_ask": "0.71"}], "timestamp": "1769384336051", "event_type": "price_change"}}
{"_local_timestamp": "2026-01-25T23:38:56.207984+00:00", "data": {"market": "0x955dd36f151fe79cda775370a2e09049998932d5ea090d97bf0e2fde8f11b26d", "price_changes": [{"asset_id": "11868101818250841972253954473857780150009778302053902404036716275197677080100", "price": "0.02", "size": "1040.11", "side": "BUY", "hash": "1012c0899d45591ad14158d10c545630eccf2739", "best_bid": "0.29", "best_ask": "0.67"}, {"asset_id": "75456459287302166180376724549100719042861942676472232348454693844887341622859", "price": "0.98", "size": "1040.11", "side": "SELL", "hash": "60f8180577d5c38b9d927575a3db3682eb02b665", "best_bid": "0.33", "best_ask": "0.71"}], "timestamp": "1769384336128", "event_type": "price_change"}}
{"_local_timestamp": "2026-01-25T23:38:56.208579+00:00", "data": {"market": "0x955dd36f151fe79cda775370a2e09049998932d5ea090d97bf0e2fde8f11b26d", "price_changes": [{"asset_id": "11868101818250841972253954473857780150009778302053902404036716275197677080100", "price": "0.02", "size": "3037.22", "side": "BUY", "hash": "5b253765bfde72694f0a95411150a8f26be72d28", "best_bid": "0.29", "best_ask": "0.67"}, {"asset_id": "75456459287302166180376724549100719042861942676472232348454693844887341622859", "price": "0.98", "size": "3037.22", "side": "SELL", "hash": "fc187ba0867b35c38f1b2c60f494614446b31080", "best_bid": "0.33", "best_ask": "0.71"}], "timestamp": "1769384336129", "event_type": "price_change"}}
{"_local_timestamp": "2026-01-25T23:38:56.209045+00:00", "data": {"market": "0x955dd36f151fe79cda775370a2e09049998932d5ea090d97bf0e2fde8f11b26d", "price_changes": [{"asset_id": "11868101818250841972253954473857780150009778302053902404036716275197677080100", "price": "0.02", "size": "4307.32", "side": "BUY", "hash": "5eb476413aba4b8b047f72ca3e7139319c54a076", "best_bid": "0.29", "best_ask": "0.67"}, {"asset_id": "75456459287302166180376724549100719042861942676472232348454693844887341622859", "price": "0.98", "size": "4307.32", "side": "SELL", "hash": "607d40355e6d29ed061fae1d399a30a5dffc2343", "best_bid": "0.33", "best_ask": "0.71"}], "timestamp": "1769384336130", "event_type": "price_change"}}
{"_local_timestamp": "2026-01-25T23:39:08.406397+00:00", "data": {"market": "0x955dd36f151fe79cda775370a2e09049998932d5ea090d97bf0e2fde8f11b26d", "price_changes": [{"asset_id": "11868101818250841972253954473857780150009778302053902404036716275197677080100", "price": "0.01", "size": "10448.67", "side": "BUY", "hash": "c55c08e89ff9c5ecc0e2f8b36253ad45e0694d6b", "best_bid": "0.29", "best_ask": "0.67"}, {"asset_id": "75456459287302166180376724549100719042861942676472232348454693844887341622859", "price": "0.99", "size": "10448.67", "side": "SELL", "hash": "a476c6199bb63defa5dd0f92d72d9d0b90bf4e87", "best_bid": "0.33", "best_ask": "0.71"}], "timestamp": "1769384348334", "event_type": "price_change"}}
{"_local_timestamp": "2026-01-25T23:39:08.517797+00:00", "data": {"market": "0x955dd36f151fe79cda775370a2e09049998932d5ea090d97bf0e2fde8f11b26d", "price_changes": [{"asset_id": "11868101818250841972253954473857780150009778302053902404036716275197677080100", "price": "0.02", "size": "150", "side": "BUY", "hash": "6e6bdf5273c15a04f1b4aaed7b6f1399e37a0418", "best_bid": "0.29", "best_ask": "0.67"}, {"asset_id": "75456459287302166180376724549100719042861942676472232348454693844887341622859", "price": "0.98", "size": "150", "side": "SELL", "hash": "c37bb0ac5fdb525bc6d354a6ade6acca02ae0fbd", "best_bid": "0.33", "best_ask": "0.71"}], "timestamp": "1769384348444", "event_type": "price_change"}}
{"_local_timestamp": "2026-01-25T23:39:08.642360+00:00", "data": {"market": "0x955dd36f151fe79cda775370a2e09049998932d5ea090d97bf0e2fde8f11b26d", "price_changes": [{"asset_id": "11868101818250841972253954473857780150009778302053902404036716275197677080100", "price": "0.02", "size": "450", "side": "BUY", "hash": "8e0468cbcdb0716ba707f1f7b25a576a8ffcd7a4", "best_bid": "0.29", "best_ask": "0.67"}, {"asset_id": "75456459287302166180376724549100719042861942676472232348454693844887341622859", "price": "0.98", "size": "450", "side": "SELL", "hash": "37f0a9423de5c782a50934acd4413044a7077028", "best_bid": "0.33", "best_ask": "0.71"}], "timestamp": "1769384348561", "event_type": "price_change"}}
{"_local_timestamp": "2026-01-25T23:39:20.252622+00:00", "data": {"market": "0x955dd36f151fe79cda775370a2e09049998932d5ea090d97bf0e2fde8f11b26d", "price_changes": [{"asset_id": "11868101818250841972253954473857780150009778302053902404036716275197677080100", "price": "0.02", "size": "150", "side": "BUY", "hash": "12c2efab5d1a7a4a704e6a625cefb7bfe476ad65", "best_bid": "0.29", "best_ask": "0.67"}, {"asset_id": "75456459287302166180376724549100719042861942676472232348454693844887341622859", "price": "0.98", "size": "150", "side": "SELL", "hash": "f754f6fd8c4d26d13fe1068b6784441664aeadf6", "best_bid": "0.33", "best_ask": "0.71"}], "timestamp": "1769384360182", "event_type": "price_change"}}
{"_local_timestamp": "2026-01-25T23:39:20.624461+00:00", "data": {"market": "0x955dd36f151fe79cda775370a2e09049998932d5ea090d97bf0e2fde8f11b26d", "price_changes": [{"asset_id": "11868101818250841972253954473857780150009778302053902404036716275197677080100", "price": "0.01", "size": "10848.67", "side": "BUY", "hash": "39451c80f5746e5b68d1b96f40ec17738bb4db3c", "best_bid": "0.29", "best_ask": "0.67"}, {"asset_id": "75456459287302166180376724549100719042861942676472232348454693844887341622859", "price": "0.99", "size": "10848.67", "side": "SELL", "hash": "1c0583a56f8adda4da71b37c30f9ed3211fce2fd", "best_bid": "0.33", "best_ask": "0.71"}], "timestamp": "1769384360408", "event_type": "price_change"}}
{"_local_timestamp": "2026-01-25T23:39:20.746722+00:00", "data": {"market": "0x955dd36f151fe79cda775370a2e09049998932d5ea090d97bf0e2fde8f11b26d", "price_changes": [{"asset_id": "11868101818250841972253954473857780150009778302053902404036716275197677080100", "price": "0.02", "size": "1040.11", "side": "BUY", "hash": "c4abf21afd79ba950876e1c14171aa8ea40dee0e", "best_bid": "0.29", "best_ask": "0.67"}, {"asset_id": "75456459287302166180376724549100719042861942676472232348454693844887341622859", "price": "0.98", "size": "1040.11", "side": "SELL", "hash": "bebcca72c63197a9678345ce854eba3084625935", "best_bid": "0.33", "best_ask": "0.71"}], "timestamp": "1769384360653", "event_type": "price_change"}}
{"_local_timestamp": "2026-01-25T23:39:20.747389+00:00", "data": {"market": "0x955dd36f151fe79cda775370a2e09049998932d5ea090d97bf0e2fde8f11b26d", "price_changes": [{"asset_id": "11868101818250841972253954473857780150009778302053902404036716275197677080100", "price": "0.02", "size": "2310.21", "side": "BUY", "hash": "c8e3b9841c8c080ebb14cfb681b438d207bc2a2d", "best_bid": "0.29", "best_ask": "0.67"}, {"asset_id": "75456459287302166180376724549100719042861942676472232348454693844887341622859", "price": "0.98", "size": "2310.21", "side": "SELL", "hash": "ecf58492c870e4a8d37548543b08435ce0e6f86c", "best_bid": "0.33", "best_ask": "0.71"}], "timestamp": "1769384360654", "event_type": "price_change"}}
{"_local_timestamp": "2026-01-25T23:39:20.752631+00:00", "data": {"market": "0x955dd36f151fe79cda775370a2e09049998932d5ea090d97bf0e2fde8f11b26d", "price_changes": [{"asset_id": "11868101818250841972253954473857780150009778302053902404036716275197677080100", "price": "0.02", "size": "4307.32", "side": "BUY", "hash": "e9d82d128bfe5e2effec078f6a3a4eb64db136af", "best_bid": "0.29", "best_ask": "0.67"}, {"asset_id": "75456459287302166180376724549100719042861942676472232348454693844887341622859", "price": "0.98", "size": "4307.32", "side": "SELL", "hash": "ae48d642c99fdaad73b00cce6317e14055897fb0", "best_bid": "0.33", "best_ask": "0.71"}], "timestamp": "1769384360654", "event_type": "price_change"}}
{"_local_timestamp": "2026-01-25T23:39:32.500870+00:00", "data": {"market": "0x955dd36f151fe79cda775370a2e09049998932d5ea090d97bf0e2fde8f11b26d", "price_changes": [{"asset_id": "11868101818250841972253954473857780150009778302053902404036716275197677080100", "price": "0.01", "size": "10448.67", "side": "BUY", "hash": "56d7dbe0c72ac62bb165e7ec767bc215cc476c3e", "best_bid": "0.29", "best_ask": "0.67"}, {"asset_id": "75456459287302166180376724549100719042861942676472232348454693844887341622859", "price": "0.99", "size": "10448.67", "side": "SELL", "hash": "229d9cf630a071a893d5d57841c2930eac6f3010", "best_bid": "0.33", "best_ask": "0.71"}], "timestamp": "1769384372428", "event_type": "price_change"}}
{"_local_timestamp": "2026-01-25T23:39:32.725081+00:00", "data": {"market": "0x955dd36f151fe79cda775370a2e09049998932d5ea090d97bf0e2fde8f11b26d", "price_changes": [{"asset_id": "11868101818250841972253954473857780150009778302053902404036716275197677080100", "price": "0.02", "size": "4607.32", "side": "BUY", "hash": "ccc9f9431b899d7971389153c68f9b71cb61bda9", "best_bid": "0.29", "best_ask": "0.67"}, {"asset_id": "75456459287302166180376724549100719042861942676472232348454693844887341622859", "price": "0.98", "size": "4607.32", "side": "SELL", "hash": "a3a83539cae9ca5a6c0f78eef553c624f9abe0fa", "best_bid": "0.33", "best_ask": "0.71"}], "timestamp": "1769384372648", "event_type": "price_change"}}
