{"_local_timestamp": "2026-01-25T23:40:59.806715+00:00", "data": [{"market": "0xfa0a910c4380fc83610d9fa68b214b598621ae9bd49dc40df47abd265bf0bc34", "asset_id": "59290556380981220753832906409296194214356850812489293134106523641703938483612", "timestamp": "1769384459069", "hash": "1799211e4300e95a6a142d81064bcb0b7d85c50d", "bids": [{"price": "0.01", "size": "33"}, {"price": "0.05", "size": "200"}, {"price": "0.06", "size": "5.47"}], "asks": [{"price": "0.99", "size": "1052.69"}, {"price": "0.98", "size": "5000"}, {"price": "0.97", "size": "5.47"}, {"price": "0.96", "size": "21.32"}, {"price": "0.56", "size": "100"}, {"price": "0.43", "size": "100"}, {"price": "0.42", "size": "26.32"}], "event_type": "book", "last_trade_price": "0.020"}, {"market": "0x425351f3d4713b9db2c15a80e1e75a2acf893b5495cc2e694095070137509329", "asset_id": "56846561876839441818327131212801941885992894700201726352426446447037474872043", "timestamp": "1769384459236", "hash": "740dec8ff642a08e5781efa18c4c37f130e779cb", "bids": [{"price": "0.001", "size": "856.39"}, {"price": "0.002", "size": "26.21"}, {"price": "0.01", "size": "1138"}, {"price": "0.011", "size": "5000"}, {"price": "0.012", "size": "24.58"}, {"price": "0.08", "size": "16"}, {"price": "0.081", "size": "7.99"}, {"price": "0.2", "size": "200"}, {"price": "0.26", "size": "348.52"}, {"price": "0.27", "size": "200"}, {"price": "0.34", "size": "393"}, {"price": "0.78", "size": "292"}, {"price": "0.8", "size": "36.68"}, {"price": "0.85", "size": "10"}, {"price": "0.88", "size": "6"}, {"price": "0.9", "size": "199.98"}, {"price": "0.93", "size": "9.02"}, {"price": "0.94", "size": "1571.66"}, {"price": "0.95", "size": "994"}, {"price": "0.97", "size": "300"}, {"price": "0.98", "size": "100"}, {"price": "0.99", "size": "6021.46"}], "asks": [{"price": "0.999", "size": "7590.11"}], "event_type": "book", "last_trade_price": "0.999"}, {"market": "0x9b95e4d85d89a2aa406d7bc683e9b8bb8c7d2b16ee3b44878a36d4e79eeb20ec", "asset_id": "63189790407496871968365678866547561936214310417455881808824200627199091231049", "timestamp": "1769384459236", "hash": "5cfd3ab18a58fc2cc53b42787aec7cb311515f48", "bids": [{"price": "0.01", "size": "9746.88"}, {"price": "0.02", "size": "2116"}, {"price": "0.03", "size": "10.19"}, {"price": "0.07", "size": "1700"}, {"price": "0.1", "size": "27"}, {"price": "0.11", "size": "705.42"}, {"price": "0.15", "size": "15"}, {"price": "0.2", "size": "400"}, {"price": "0.27", "size": "200"}, {"price": "0.34", "size": "100"}, {"price": "0.38", "size": "30"}, {"price": "0.39", "size": "256"}, {"price": "0.5", "size": "20"}, {"price": "0.7", "size": "1786.82"}, {"price": "0.71", "size": "4167.32"}, {"price": "0.77", "size": "5"}, {"price": "0.82", "size": "8"}, {"price": "0.85", "size": "10"}, {"price": "0.89", "size": "1890.11"}, {"price": "0.9", "size": "940.11"}, {"price": "0.92", "size": "4681.97"}, {"price": "0.93", "size": "500"}, {"price": "0.94", "size": "88.05"}], "asks": [{"price": "0.99", "size": "2634.11"}, {"price": "0.98", "size": "1324.39"}, {"price": "0.97", "size": "18.52"}], "event_type": "book", "last_trade_price": "0.940"}, {"market": "0x9b95e4d85d89a2aa406d7bc683e9b8bb8c7d2b16ee3b44878a36d4e79eeb20ec", "asset_id": "39492360553034885301486766992727683306899599890890066102594783083978384204123", "timestamp": "1769384459236", "hash": "bd79b2c131fced43ceadd127e692abb754afcf7c", "bids": [{"price": "0.01", "size": "2634.11"}, {"price": "0.02", "size": "1324.39"}, {"price": "0.03", "size": "18.52"}], "asks": [{"price": "0.99", "size": "9746.88"}, {"price": "0.98", "size": "2116"}, {"price": "0.97", "size": "10.19"}, {"price": "0.93", "size": "1700"}, {"price": "0.9", "size": "27"}, {"price": "0.89", "size": "705.42"}, {"price": "0.85", "size": "15"}, {"price": "0.8", "size": "400"}, {"price": "0.73", "size": "200"}, {"price": "0.66", "size": "100"}, {"price": "0.62", "size": "30"}, {"price": "0.61", "size": "256"}, {"price": "0.5", "size": "20"}, {"price": "0.3", "size": "1786.82"}, {"price": "0.29", "size": "4167.32"}, {"price": "0.23", "size": "5"}, {"price": "0.18", "size": "8"}, {"price": "0.15", "size": "10"}, {"price": "0.11", "size": "1890.11"}, {"price": "0.1", "size": "940.11"}, {"price": "0.08", "size": "4681.97"}, {"price": "0.07", "size": "500"}, {"price": "0.06", "size": "88.05"}], "event_type": "book", "last_trade_price": "0.940"}, {"market": "0x67d228115cc6ea9eb2dd85ca443c357359e4bdac7f773d8dff9f599cf5f58074", "asset_id": "115673443932214194570164346004924052532408865542451590692735424434267556754094", "timestamp": "1769384459236", "hash": "5b4e9d3685d2412341bfbb37309a30a8063b4fcf", "bids": [{"price": "0.01", "size": "7142.33"}, {"price": "0.02", "size": "4157.32"}, {"price": "0.03", "size": "9.93"}, {"price": "0.08", "size": "16"}, {"price": "0.09", "size": "7.22"}, {"price": "0.2", "size": "200"}, {"price": "0.27", "size": "200"}, {"price": "0.34", "size": "100"}, {"price": "0.36", "size": "100"}, {"price": "0.5", "size": "140"}, {"price": "0.76", "size": "26"}, {"price": "0.79", "size": "1890.11"}, {"price": "0.8", "size": "1290.11"}, {"price": "0.83", "size": "338"}, {"price": "0.84", "size": "9"}, {"price": "0.85", "size": "2100"}], "asks": [{"price": "0.99", "size": "4290.32"}, {"price": "0.98", "size": "50"}, {"price": "0.94", "size": "2556.11"}, {"price": "0.89", "size": "1890.11"}, {"price": "0.88", "size": "899.11"}, {"price": "0.87", "size": "690.84"}], "event_type": "book", "last_trade_price": "0.130"}, {"market": "0x425351f3d4713b9db2c15a80e1e75a2acf893b5495cc2e694095070137509329", "asset_id": "57829021360688395873888125190016504630905168321624137961276880640915115712545", "timestamp": "1769384459236", "hash": "cdda3f30116a5f2ff611efdeb2fe747a2d174501", "bids": [{"price": "0.001", "size": "7590.11"}], "asks": [{"price": "0.999", "size": "856.39"}, {"price": "0.998", "size": "26.21"}, {"price": "0.99", "size": "1138"}, {"price": "0.989", "size": "5000"}, {"price": "0.988", "size": "24.58"}, {"price": "0.92", "size": "16"}, {"price": "0.919", "size": "7.99"}, {"price": "0.8", "size": "200"}, {"price": "0.74", "size": "348.52"}, {"price": "0.73", "size": "200"}, {"price": "0.66", "size": "393"}, {"price": "0.22", "size": "292"}, {"price": "0.2", "size": "36.68"}, {"price": "0.15", "size": "10"}, {"price": "0.12", "size": "6"}, {"price": "0.1", "size": "199.98"}, {"price": "0.07", "size": "9.02"}, {"price": "0.06", "size": "1571.66"}, {"price": "0.05", "size": "994"}, {"price": "0.03", "size": "300"}, {"price": "0.02", "size": "100"}, {"price": "0.01", "size": "6021.46"}], "event_type": "book", "last_trade_price": "0.999"}, {"market": "0x67d228115cc6ea9eb2dd85ca443c357359e4bdac7f773d8dff9f599cf5f58074", "asset_id": "40258076975888759603244407127088084693343108694292687330139582591508023070009", "timestamp": "1769384459236", "hash": "f21622c1f34ec8cf47cd0c6709dfb3f198c4fe03", "bids": [{"price": "0.01", "size": "4290.32"}, {"price": "0.02", "size": "50"}, {"price": "0.06", "size": "2556.11"}, {"price": "0.11", "size": "1890.11"}, {"price": "0.12", "size": "899.11"}, {"price": "0.13", "size": "690.84"}], "asks": [{"price": "0.99", "size": "7142.33"}, {"price": "0.98", "size": "4157.32"}, {"price": "0.97", "size": "9.93"}, {"price": "0.92", "size": "16"}, {"price": "0.91", "size": "7.22"}, {"price": "0.8", "size": "200"}, {"price": "0.73", "size": "200"}, {"price": "0.66", "size": "100"}, {"price": "0.64", "size": "100"}, {"price": "0.5", "size": "140"}, {"price": "0.24", "size": "26"}, {"price": "0.21", "size": "1890.11"}, {"price": "0.2", "size": "1290.11"}, {"price": "0.17", "size": "338"}, {"price": "0.16", "size": "9"}, {"price": "0.15", "size": "2100"}], "event_type": "book", "last_trade_price": "0.130"}, {"market": "0xdb220d70cc76303505355f558407f99958916364c5612685c804fe1267d0f514", "asset_id": "89178703372212073978389921580322635269384366327786463025461810229435622804178", "timestamp": "1769384459263", "hash": "00251fb83d1dc49792bff45a5fcf20240f4ee79e", "bids": [{"price": "0.01", "size": "5237.57"}, {"price": "0.02", "size": "30.42"}, {"price": "0.03", "size": "5.47"}], "asks": [{"price": "0.99", "size": "8060.87"}, {"price": "0.98", "size": "5054.67"}, {"price": "0.95", "size": "16.07"}, {"price": "0.92", "size": "890.11"}, {"price": "0.91", "size": "6158.43"}, {"price": "0.9", "size": "5047.43"}, {"price": "0.53", "size": "100"}, {"price": "0.43", "size": "100"}, {"price": "0.2", "size": "500"}], "event_type": "book", "last_trade_price": "0.670"}, {"market": "0xfa0a910c4380fc83610d9fa68b214b598621ae9bd49dc40df47abd265bf0bc34", "asset_id": "42996585481877433482708272870977066259130153781685558286992961170000063507609", "timestamp": "1769384459069", "hash": "227de46e93bb7772525926bbbe67addd6cb4d261", "bids": [{"price": "0.01", "size": "1052.69"}, {"price": "0.02", "size": "5000"}, {"price": "0.03", "size": "5.47"}, {"price": "0.04", "size": "21.32"}, {"price": "0.44", "size": "100"}, {"price": "0.57", "size": "100"}, {"price": "0.58", "size": "26.32"}], "asks": [{"price": "0.99", "size": "33"}, {"price": "0.95", "size": "200"}, {"price": "0.94", "size": "5.47"}], "event_type": "book", "last_trade_price": "0.020"}, {"market": "0xdb220d70cc76303505355f558407f99958916364c5612685c804fe1267d0f514", "asset_id": "29127800831891156918080289096614999289213121001925429958509112072030245798692", "timestamp": "1769384459263", "hash": "2fa36a2199dce4db6b64d5488447407035f92666", "bids": [{"price": "0.01", "size": "8060.87"}, {"price": "0.02", "size": "5054.67"}, {"price": "0.05", "size": "16.07"}, {"price": "0.08", "size": "890.11"}, {"price": "0.09", "size": "6158.43"}, {"price": "0.1", "size": "5047.43"}, {"price": "0.47", "size": "100"}, {"price": "0.57", "size": "100"}, {"price": "0.8", "size": "500"}], "asks": [{"price": "0.99", "size": "5237.57"}, {"price": "0.98", "size": "30.42"}, {"price": "0.97", "size": "5.47"}], "event_type": "book", "last_trade_price": "0.670"}]}
{"_local_timestamp": "2026-01-25T23:40:59.937072+00:00", "data": {"market": "0x9b95e4d85d89a2aa406d7bc683e9b8bb8c7d2b16ee3b44878a36d4e79eeb20ec", "price_changes": [{"asset_id": "39492360553034885301486766992727683306899599890890066102594783083978384204123", "price": "0.03", "size": "12.18", "side": "BUY", "hash": "de2b31cc45f5da83a2a21d9c220836cf26f9d132", "best_bid": "0.03", "best_ask": "0.06"}, {"asset_id": "63189790407496871968365678866547561936214310417455881808824200627199091231049", "price": "0.97", "size": "12.18", "side": "SELL", "hash": "07e0a4cd72808da6bd399dc265143c79b3627af1", "best_bid": "0.94", "best_ask": "0.97"}], "timestamp": "1769384459868", "event_type": "price_change"}}
{"_local_timestamp": "2026-01-25T23:41:00.165159+00:00", "data": {"market": "0x9b95e4d85d89a2aa406d7bc683e9b8bb8c7d2b16ee3b44878a36d4e79eeb20ec", "price_changes": [{"asset_id": "39492360553034885301486766992727683306899599890890066102594783083978384204123", "price": "0.02", "size": "1333.92", "side": "BUY", "hash": "e2b50044ad1f3fa61b3a091a96fb12fb1cf7a96c", "best_bid": "0.03", "best_ask": "0.06"}, {"asset_id": "63189790407496871968365678866547561936214310417455881808824200627199091231049", "price": "0.98", "size": "1333.92", "side": "SELL", "hash": "cda49e22e6aaabd07b8d3f20af7eca60722219fc", "best_bid": "0.94", "best_ask": "0.97"}], "timestamp": "1769384460096", "event_type": "price_change"}}
{"_local_timestamp": "2026-01-25T23:41:00.644626+00:00", "data": {"market": "0x67d228115cc6ea9eb2dd85ca443c357359e4bdac7f773d8dff9f599cf5f58074", "price_changes": [{"asset_id": "115673443932214194570164346004924052532408865542451590692735424434267556754094", "price": "0.37", "size": "370", "side": "BUY", "hash": "9f1ae910a875b95889e481e14a2b001c994382a8", "best_bid": "0.85", "best_ask": "0.87"}, {"asset_id": "40258076975888759603244407127088084693343108694292687330139582591508023070009", "price": "0.63", "size": "370", "side": "SELL", "hash": "d8c26490c36b72d361cba5157925b86fd5712aed", "best_bid": "0.13", "best_ask": "0.15"}], "timestamp": "1769384460573", "event_type": "price_change"}}
{"_local_timestamp": "2026-01-25T23:41:00.695335+00:00", "data": {"market": "0x67d228115cc6ea9eb2dd85ca443c357359e4bdac7f773d8dff9f599cf5f58074", "price_changes": [{"asset_id": "40258076975888759603244407127088084693343108694292687330139582591508023070009", "price": "0.06", "size": "1666", "side": "BUY", "hash": "e5a2842d74c2df06ed14cb0f121be00b51a7936c", "best_bid": "0.13", "best_ask": "0.15"}, {"asset_id": "115673443932214194570164346004924052532408865542451590692735424434267556754094", "price": "0.94", "size": "1666", "side": "SELL", "hash": "4d0495aa232776a6d2d9bbfac2b2fdb768f9924d", "best_bid": "0.85", "best_ask": "0.87"}], "timestamp": "1769384460627", "event_type": "price_change"}}
{"_local_timestamp": "2026-01-25T23:41:02.484051+00:00", "data": {"market": "0x9b95e4d85d89a2aa406d7bc683e9b8bb8c7d2b16ee3b44878a36d4e79eeb20ec", "price_changes": [{"asset_id": "39492360553034885301486766992727683306899599890890066102594783083978384204123", "price": "0.02", "size": "1324.39", "side": "BUY", "hash": "96afaa92e1be7297f385a72ecc06d68940bfc5bf", "best_bid": "0.03", "best_ask": "0.06"}, {"asset_id": "63189790407496871968365678866547561936214310417455881808824200627199091231049", "price": "0.98", "size": "1324.39", "side": "SELL", "hash": "2636e4490344b4ed44b3b1687ca53b6406121ad4", "best_bid": "0.94", "best_ask": "0.97"}], "timestamp": "1769384462420", "event_type": "price_change"}}
{"_local_timestamp": "2026-01-25T23:41:02.490308+00:00", "data": {"market": "0x9b95e4d85d89a2aa406d7bc683e9b8bb8c7d2b16ee3b44878a36d4e79eeb20ec", "price_changes": [{"asset_id": "39492360553034885301486766992727683306899599890890066102594783083978384204123", "price": "0.03", "size": "5.84", "side": "BUY", "hash": "96afaa92e1be7297f385a72ecc06d68940bfc5bf", "best_bid": "0.03", "best_ask": "0.06"}, {"asset_id": "63189790407496871968365678866547561936214310417455881808824200627199091231049", "price": "0.97", "size": "5.84", "side": "SELL", "hash": "2636e4490344b4ed44b3b1687ca53b6406121ad4", "best_bid": "0.94", "best_ask": "0.97"}], "timestamp": "1769384462420", "event_type": "price_change"}}
{"_local_timestamp": "2026-01-25T23:41:02.674544+00:00", "data": {"market": "0x9b95e4d85d89a2aa406d7bc683e9b8bb8c7d2b16ee3b44878a36d4e79eeb20ec", "price_changes": [{"asset_id": "39492360553034885301486766992727683306899599890890066102594783083978384204123", "price": "0.03", "size": "12.18", "side": "BUY", "hash": "f956bc4175c27f2d8d2cbefec77c91e4d5a8a44f", "best_bid": "0.03", "best_ask": "0.06"}, {"asset_id": "63189790407496871968365678866547561936214310417455881808824200627199091231049", "price": "0.97", "size": "12.18", "side": "SELL", "hash": "2c4f23bdecff34a74ce8926e3f8317cd13e2425e", "best_bid": "0.94", "best_ask": "0.97"}], "timestamp": "1769384462602", "event_type": "price_change"}}
{"_local_timestamp": "2026-01-25T23:41:02.682010+00:00", "data": {"market": "0x9b95e4d85d89a2aa406d7bc683e9b8bb8c7d2b16ee3b44878a36d4e79eeb20ec", "price_changes": [{"asset_id": "39492360553034885301486766992727683306899599890890066102594783083978384204123", "price": "0.03", "size": "18.52", "side": "BUY", "hash": "5d0ea5f2b89b5812eaa800e8b459f21a0a9ef534", "best_bid": "0.03", "best_ask": "0.06"}, {"asset_id": "63189790407496871968365678866547561936214310417455881808824200627199091231049", "price": "0.97", "size": "18.52", "side": "SELL", "hash": "42f33ac9a7bd53c155be60dd7840fcdbfc4b2e06", "best_bid": "0.94", "best_ask": "0.97"}], "timestamp": "1769384462603", "event_type": "price_change"}}
{"_local_timestamp": "2026-01-25T23:41:03.067574+00:00", "data": {"market": "0xdb220d70cc76303505355f558407f99958916364c5612685c804fe1267d0f514", "price_changes": [{"asset_id": "29127800831891156918080289096614999289213121001925429958509112072030245798692", "price": "0.09", "size": "5047.43", "side": "BUY", "hash": "2c7dee50a49060d48cbc4ba761380d37c35c3398", "best_bid": "0.8", "best_ask": "0.97"}, {"asset_id": "89178703372212073978389921580322635269384366327786463025461810229435622804178", "price": "0.91", "size": "5047.43", "side": "SELL", "hash": "8508e6c4d1315f520869e327ef13961ce5ec6bb5", "best_bid": "0.03", "best_ask": "0.2"}], "timestamp": "1769384463000", "event_type": "price_change"}}
{"_local_timestamp": "2026-01-25T23:41:03.075848+00:00", "data": {"market": "0xfa0a910c4380fc83610d9fa68b214b598621ae9bd49dc40df47abd265bf0bc34", "price_changes": [{"asset_id": "42996585481877433482708272870977066259130153781685558286992961170000063507609", "price": "0.02", "size": "0", "side": "BUY", "hash": "72490c035025655ba62615c78a5aac2f717c4304", "best_bid": "0.58", "best_ask": "0.94"}, {"asset_id": "59290556380981220753832906409296194214356850812489293134106523641703938483612", "price": "0.98", "size": "0", "side": "SELL", "hash": "07d5278189da1120cedae64f25a5b25095429817", "best_bid": "0.06", "best_ask": "0.42"}], "timestamp": "1769384463002", "event_type": "price_change"}}
{"_local_timestamp": "2026-01-25T23:41:03.133187+00:00", "data": {"market": "0xdb220d70cc76303505355f558407f99958916364c5612685c804fe1267d0f514", "price_changes": [{"asset_id": "29127800831891156918080289096614999289213121001925429958509112072030245798692", "price": "0.09", "size": "890.11", "side": "BUY", "hash": "7167d24f9e1541e7d5fb5be13b94d4cc161d4495", "best_bid": "0.8", "best_ask": "0.97"}, {"asset_id": "89178703372212073978389921580322635269384366327786463025461810229435622804178", "price": "0.91", "size": "890.11", "side": "SELL", "hash": "9fbf1f1d9a90b33365f508374956b476ee766b82", "best_bid": "0.03", "best_ask": "0.2"}], "timestamp": "1769384463053", "event_type": "price_change"}}
{"_local_timestamp": "2026-01-25T23:41:03.159690+00:00", "data": {"market": "0xdb220d70cc76303505355f558407f99958916364c5612685c804fe1267d0f514", "price_changes": [{"asset_id": "29127800831891156918080289096614999289213121001925429958509112072030245798692", "price": "0.08", "size": "0", "side": "BUY", "hash": "7167d24f9e1541e7d5fb5be13b94d4cc161d4495", "best_bid": "0.8", "best_ask": "0.97"}, {"asset_id": "89178703372212073978389921580322635269384366327786463025461810229435622804178", "price": "0.92", "size": "0", "side": "SELL", "hash": "9fbf1f1d9a90b33365f508374956b476ee766b82", "best_bid": "0.03", "best_ask": "0.2"}], "timestamp": "1769384463053", "event_type": "price_change"}}
{"_local_timestamp": "2026-01-25T23:41:04.069868+00:00", "data": {"market": "0x67d228115cc6ea9eb2dd85ca443c357359e4bdac7f773d8dff9f599cf5f58074", "price_changes": [{"asset_id": "115673443932214194570164346004924052532408865542451590692735424434267556754094", "price": "0.37", "size": "100", "side": "BUY", "hash": "7164ee354c3ae38fe39974df464cf1f4f71a5cda", "best_bid": "0.85", "best_ask": "0.87"}, {"asset_id": "40258076975888759603244407127088084693343108694292687330139582591508023070009", "price": "0.63", "size": "100", "side": "SELL", "hash": "50cf13f5bb143b2893bcc0a6e55abc5ff4748e96", "best_bid": "0.13", "best_ask": "0.15"}], "timestamp": "1769384464000", "event_type": "price_change"}}
{"_local_timestamp": "2026-01-25T23:41:04.076085+00:00", "data": {"market": "0x67d228115cc6ea9eb2dd85ca443c357359e4bdac7f773d8dff9f599cf5f58074", "price_changes": [{"asset_id": "40258076975888759603244407127088084693343108694292687330139582591508023070009", "price": "0.06", "size": "0", "side": "BUY", "hash": "4bb5b88917c9710d0df038bf32b599710142ca92", "best_bid": "0.13", "best_ask": "0.15"}, {"asset_id": "115673443932214194570164346004924052532408865542451590692735424434267556754094", "price": "0.94", "size": "0", "side": "SELL", "hash": "dee095ef80d8016e49996a5ae225a63ddd6e80bb", "best_bid": "0.85", "best_ask": "0.87"}], "timestamp": "1769384464004", "event_type": "price_change"}}
{"_local_timestamp": "2026-01-25T23:41:04.082806+00:00", "data": {"market": "0x9b95e4d85d89a2aa406d7bc683e9b8bb8c7d2b16ee3b44878a36d4e79eeb20ec", "price_changes": [{"asset_id": "63189790407496871968365678866547561936214310417455881808824200627199091231049", "price": "0.39", "size": "0", "side": "BUY", "hash": "ed5433acd9bdf57923f58e266d0e84ff702fbe3c", "best_bid": "0.94", "best_ask": "0.97"}, {"asset_id": "39492360553034885301486766992727683306899599890890066102594783083978384204123", "price": "0.61", "size": "0", "side": "SELL", "hash": "70d7e77d6100373d4125eefe80926784bf36b201", "best_bid": "0.03", "best_ask": "0.06"}], "timestamp": "1769384464006", "event_type": "price_change"}}
{"_local_timestamp": "2026-01-25T23:41:04.096727+00:00", "data": {"market": "0x425351f3d4713b9db2c15a80e1e75a2acf893b5495cc2e694095070137509329", "price_changes": [{"asset_id": "56846561876839441818327131212801941885992894700201726352426446447037474872043", "price": "0.34", "size": "100", "side": "BUY", "hash": "b76b0c6d97da73d6dcb0f48b527e57622772e451", "best_bid": "0.99", "best_ask": "0.999"}, {"asset_id": "57829021360688395873888125190016504630905168321624137961276880640915115712545", "price": "0.66", "size": "100", "side": "SELL", "hash": "72296263cca28fdbac111cf7fcc7470ccaa68391", "best_bid": "0.001", "best_ask": "0.01"}], "timestamp": "1769384464007", "event_type": "price_change"}}
{"_local_timestamp": "2026-01-25T23:41:04.151034+00:00", "data": {"market": "0x67d228115cc6ea9eb2dd85ca443c357359e4bdac7f773d8dff9f599cf5f58074", "price_changes": [{"asset_id": "40258076975888759603244407127088084693343108694292687330139582591508023070009", "price": "0.01", "size": "3400.21", "side": "BUY", "hash": "c04d15801e5c0202b7d08321b4da1d6f74230ed5", "best_bid": "0.13", "best_ask": "0.15"}, {"asset_id": "115673443932214194570164346004924052532408865542451590692735424434267556754094", "price": "0.99", "size": "3400.21", "side": "SELL", "hash": "233a64cd43cfb687078226c654dc907881551788", "best_bid": "0.85", "best_ask": "0.87"}], "timestamp": "1769384464075", "event_type": "price_change"}}
{"_local_timestamp": "2026-01-25T23:41:04.284978+00:00", "data": {"market": "0x67d228115cc6ea9eb2dd85ca443c357359e4bdac7f773d8dff9f599cf5f58074", "price_changes": [{"asset_id": "40258076975888759603244407127088084693343108694292687330139582591508023070009", "price": "0.02", "size": "1320.1", "side": "BUY", "hash": "39650c411d44b056bbaaf98edd100105b9f3596a", "best_bid": "0.13", "best_ask": "0.15"}, {"asset_id": "115673443932214194570164346004924052532408865542451590692735424434267556754094", "price": "0.98", "size": "1320.1", "side": "SELL", "hash": "cbe535db2de5200d7b40e52643d45a846b41c0db", "best_bid": "0.85", "best_ask": "0.87"}], "timestamp": "1769384464213", "event_type": "price_change"}}
{"_local_timestamp": "2026-01-25T23:41:04.291120+00:00", "data": {"market": "0x67d228115cc6ea9eb2dd85ca443c357359e4bdac7f773d8dff9f599cf5f58074", "price_changes": [{"asset_id": "40258076975888759603244407127088084693343108694292687330139582591508023070009", "price": "0.02", "size": "3317.21", "side": "BUY", "hash": "2f4db1caee2f76bc4a4b789967622c5ee4340d83", "best_bid": "0.13", "best_ask": "0.15"}, {"asset_id": "115673443932214194570164346004924052532408865542451590692735424434267556754094", "price": "0.98", "size": "3317.21", "side": "SELL", "hash": "23f2e00ad5d9d23581f0c23f9a9202c5b533e2ab", "best_bid": "0.85", "best_ask": "0.87"}], "timestamp": "1769384464214", "event_type": "price_change"}}
{"_local_timestamp": "2026-01-25T23:41:04.297452+00:00", "data": {"market": "0x67d228115cc6ea9eb2dd85ca443c357359e4bdac7f773d8dff9f599cf5f58074", "price_changes": [{"asset_id": "40258076975888759603244407127088084693343108694292687330139582591508023070009", "price": "0.07", "size": "890.11", "side": "BUY", "hash": "a00186fd8ac4cf5f017f46cf738092eefd6a6fb6", "best_bid": "0.13", "best_ask": "0.15"}, {"asset_id": "115673443932214194570164346004924052532408865542451590692735424434267556754094", "price": "0.93", "size": "890.11", "side": "SELL", "hash": "c4f8ae97b8bd4ae168ec0394eff55a8b27ad0251", "best_bid": "0.85", "best_ask": "0.87"}], "timestamp": "1769384464216", "event_type": "price_change"}}
{"_local_timestamp": "2026-01-25T23:41:04.622686+00:00", "data": {"market": "0x67d228115cc6ea9eb2dd85ca443c357359e4bdac7f773d8dff9f599cf5f58074", "price_changes": [{"asset_id": "115673443932214194570164346004924052532408865542451590692735424434267556754094", "price": "0.38", "size": "500", "side": "BUY", "hash": "6d04bd361cd581e0c7da48aff41e9629d1116182", "best_bid": "0.85", "best_ask": "0.87"}, {"asset_id": "40258076975888759603244407127088084693343108694292687330139582591508023070009", "price": "0.62", "size": "500", "side": "SELL", "hash": "acfd8c98ca2dd27530c1bb63b16b2b6a6b587c74", "best_bid": "0.13", "best_ask": "0.15"}], "timestamp": "1769384464551", "event_type": "price_change"}}
{"_local_timestamp": "2026-01-25T23:41:04.632090+00:00", "data": {"market": "0xfa0a910c4380fc83610d9fa68b214b598621ae9bd49dc40df47abd265bf0bc34", "price_changes": [{"asset_id": "42996585481877433482708272870977066259130153781685558286992961170000063507609", "price": "0.02", "size": "5000", "side": "BUY", "hash": "6d873e064a3b59c393aa33dda4ee99a10afd43c7", "best_bid": "0.58", "best_ask": "0.94"}, {"asset_id": "59290556380981220753832906409296194214356850812489293134106523641703938483612", "price": "0.98", "size": "5000", "side": "SELL", "hash": "1827845e4e83197a628e62d89a6f592995d1e781", "best_bid": "0.06", "best_ask": "0.42"}], "timestamp": "1769384464567", "event_type": "price_change"}}
{"_local_timestamp": "2026-01-25T23:41:04.637896+00:00", "data": {"market": "0xdb220d70cc76303505355f558407f99958916364c5612685c804fe1267d0f514", "price_changes": [{"asset_id": "29127800831891156918080289096614999289213121001925429958509112072030245798692", "price": "0.11", "size": "909", "side": "BUY", "hash": "53852d95f734a92621ac65d4e338787ded9a35de", "best_bid": "0.8", "best_ask": "0.97"}, {"asset_id": "89178703372212073978389921580322635269384366327786463025461810229435622804178", "price": "0.89", "size": "909", "side": "SELL", "hash": "03e0057323643c026ea0f1bd1df66a56cea0bf39", "best_bid": "0.03", "best_ask": "0.2"}], "timestamp": "1769384464567", "event_type": "price_change"}}
{"_local_timestamp": "2026-01-25T23:41:04.643935+00:00", "data": {"market": "0x67d228115cc6ea9eb2dd85ca443c357359e4bdac7f773d8dff9f599cf5f58074", "price_changes": [{"asset_id": "115673443932214194570164346004924052532408865542451590692735424434267556754094", "price": "0.38", "size": "763", "side": "BUY", "hash": "6ce542a91b8b3f5d47fb9e7ee98d133f623f431e", "best_bid": "0.85", "best_ask": "0.87"}, {"asset_id": "40258076975888759603244407127088084693343108694292687330139582591508023070009", "price": "0.62", "size": "763", "side": "SELL", "hash": "9063ab46f459989c988a307e1d1e51a0d4fe388a", "best_bid": "0.13", "best_ask": "0.15"}], "timestamp": "1769384464567", "event_type": "price_change"}}
{"_local_timestamp": "2026-01-25T23:41:04.740568+00:00", "data": {"market": "0xdb220d70cc76303505355f558407f99958916364c5612685c804fe1267d0f514", "price_changes": [{"asset_id": "29127800831891156918080289096614999289213121001925429958509112072030245798692", "price": "0.12", "size": "1997.11", "side": "BUY", "hash": "e268e9a6f0c88a0feeddc36433c8fedcc6870102", "best_bid": "0.8", "best_ask": "0.97"}, {"asset_id": "89178703372212073978389921580322635269384366327786463025461810229435622804178", "price": "0.88", "size": "1997.11", "side": "SELL", "hash": "4fbe7362b4a370a4dee19e455fd6be2ae88b663f", "best_bid": "0.03", "best_ask": "0.2"}], "timestamp": "1769384464674", "event_type": "price_change"}}
{"_local_timestamp": "2026-01-25T23:41:04.748550+00:00", "data": {"market": "0xdb220d70cc76303505355f558407f99958916364c5612685c804fe1267d0f514", "price_changes": [{"asset_id": "29127800831891156918080289096614999289213121001925429958509112072030245798692", "price": "0.12", "size": "2887.22", "side": "BUY", "hash": "7b00655352b8a0ff7427a793b6f78815b6618b54", "best_bid": "0.8", "best_ask": "0.97"}, {"asset_id": "89178703372212073978389921580322635269384366327786463025461810229435622804178", "price": "0.88", "size": "2887.22", "side": "SELL", "hash": "35662ea308f3e70c430ad49915192aa869034e02", "best_bid": "0.03", "best_ask": "0.2"}], "timestamp": "1769384464675", "event_type": "price_change"}}
{"_local_timestamp": "2026-01-25T23:41:04.754970+00:00", "data": {"market": "0xdb220d70cc76303505355f558407f99958916364c5612685c804fe1267d0f514", "price_changes": [{"asset_id": "29127800831891156918080289096614999289213121001925429958509112072030245798692", "price": "0.12", "size": "4157.32", "side": "BUY", "hash": "932a7f586b8622b8394c76c749798cd9a837af6a", "best_bid": "0.8", "best_ask": "0.97"}, {"asset_id": "89178703372212073978389921580322635269384366327786463025461810229435622804178", "price": "0.88", "size": "4157.32", "side": "SELL", "hash": "641e16433c2c4fdb0c39c0134bd194f996c90ea0", "best_bid": "0.03", "best_ask": "0.2"}], "timestamp": "1769384464676", "event_type": "price_change"}}
{"_local_timestamp": "2026-01-25T23:41:04.761147+00:00", "data": {"market": "0xdb220d70cc76303505355f558407f99958916364c5612685c804fe1267d0f514", "price_changes": [{"asset_id": "29127800831891156918080289096614999289213121001925429958509112072030245798692", "price": "0.11", "size": "1799.11", "side": "BUY", "hash": "26eafd12df0bf0b98f590e33b07748df7025a656", "best_bid": "0.8", "best_ask": "0.97"}, {"asset_id": "89178703372212073978389921580322635269384366327786463025461810229435622804178", "price": "0.89", "size": "1799.11", "side": "SELL", "hash": "4957d77728f7d83ab4a5fa8576127ef8d5c16e0d", "best_bid": "0.03", "best_ask": "0.2"}], "timestamp": "1769384464677", "event_type": "price_change"}}
{"_local_timestamp": "2026-01-25T23:41:04.767194+00:00", "data": {"market": "0xdb220d70cc76303505355f558407f99958916364c5612685c804fe1267d0f514", "price_changes": [{"asset_id": "29127800831891156918080289096614999289213121001925429958509112072030245798692", "price": "0.12", "size": "5047.43", "side": "BUY", "hash": "dad6094c824381911659233b6221bdec0798bb89", "best_bid": "0.8", "best_ask": "0.97"}, {"asset_id": "89178703372212073978389921580322635269384366327786463025461810229435622804178", "price": "0.88", "size": "5047.43", "side": "SELL", "hash": "fe824098048a0daaaae0c94c26a6f3c42b0b831c", "best_bid": "0.03", "best_ask": "0.2"}], "timestamp": "1769384464677", "event_type": "price_change"}}
{"_local_timestamp": "2026-01-25T23:41:04.809455+00:00", "data": {"market": "0x67d228115cc6ea9eb2dd85ca443c357359e4bdac7f773d8dff9f599cf5f58074", "price_changes": [{"asset_id": "40258076975888759603244407127088084693343108694292687330139582591508023070009", "price": "0.07", "size": "2318.11", "side": "BUY", "hash": "f4233259c16650725575b815749baae07ef73cae", "best_bid": "0.13", "best_ask": "0.15"}, {"asset_id": "115673443932214194570164346004924052532408865542451590692735424434267556754094", "price": "0.93", "size": "2318.11", "side": "SELL", "hash": "0a5a499e42a62a3baf6914204385437b8198442c", "best_bid": "0.85", "best_ask": "0.87"}], "timestamp": "1769384464737", "event_type": "price_change"}}
{"_local_timestamp": "2026-01-25T23:41:04.815637+00:00", "data": {"market": "0x425351f3d4713b9db2c15a80e1e75a2acf893b5495cc2e694095070137509329", "price_changes": [{"asset_id": "56846561876839441818327131212801941885992894700201726352426446447037474872043", "price": "0.34", "size": "393", "side": "BUY", "hash": "2dacafa41d7c5658b97c55a84cc659ec3a3cdaad", "best_bid": "0.99", "best_ask": "0.999"}, {"asset_id": "57829021360688395873888125190016504630905168321624137961276880640915115712545", "price": "0.66", "size": "393", "side": "SELL", "hash": "f4a5b0964dd06710c4926bce5bccbb60b69db5f6", "best_bid": "0.001", "best_ask": "0.01"}], "timestamp": "1769384464737", "event_type": "price_change"}}
{"_local_timestamp": "2026-01-25T23:41:04.822142+00:00", "data": {"market": "0x9b95e4d85d89a2aa406d7bc683e9b8bb8c7d2b16ee3b44878a36d4e79eeb20ec", "price_changes": [{"asset_id": "63189790407496871968365678866547561936214310417455881808824200627199091231049", "price": "0.39", "size": "256", "side": "BUY", "hash": "8fb01ac6c2ec58d339e9351030340d65811056a4", "best_bid": "0.94", "best_ask": "0.97"}, {"asset_id": "39492360553034885301486766992727683306899599890890066102594783083978384204123", "price": "0.61", "size": "256", "side": "SELL", "hash": "ea614fd7208b5bf86f809f33bd85ca87c05abbf7", "best_bid": "0.03", "best_ask": "0.06"}], "timestamp": "1769384464737", "event_type": "price_change"}}
{"_local_timestamp": "2026-01-25T23:41:09.073256+00:00", "data": {"market": "0xdb220d70cc76303505355f558407f99958916364c5612685c804fe1267d0f514", "price_changes": [{"asset_id": "29127800831891156918080289096614999289213121001925429958509112072030245798692", "price": "0.11", "size": "890.11", "side": "BUY", "hash": "b153c867e8ac7d0e18bf8a1b1dfce9114d5ba9ce", "best_bid": "0.8", "best_ask": "0.97"}, {"asset_id": "89178703372212073978389921580322635269384366327786463025461810229435622804178", "price": "0.89", "size": "890.11", "side": "SELL", "hash": "8d7061bef5076f2437fb27c08f56069662d9b9a3", "best_bid": "0.03", "best_ask": "0.2"}], "timestamp": "1769384469000", "event_type": "price_change"}}
{"_local_timestamp": "2026-01-25T23:41:09.081709+00:00", "data": {"market": "0x425351f3d4713b9db2c15a80e1e75a2acf893b5495cc2e694095070137509329", "price_changes": [{"asset_id": "56846561876839441818327131212801941885992894700201726352426446447037474872043", "price": "0.34", "size": "100", "side": "BUY", "hash": "80909d7fc7fc2cb759db7acb2c6c0c2b111fc68b", "best_bid": "0.99", "best_ask": "0.999"}, {"asset_id": "57829021360688395873888125190016504630905168321624137961276880640915115712545", "price": "0.66", "size": "100", "side": "SELL", "hash": "e275dbe05d652fdb0df885f2eeb33b4061604d11", "best_bid": "0.001", "best_ask": "0.01"}], "timestamp": "1769384469000", "event_type": "price_change"}}
{"_local_timestamp": "2026-01-25T23:41:09.090040+00:00", "data": {"market": "0x9b95e4d85d89a2aa406d7bc683e9b8bb8c7d2b16ee3b44878a36d4e79eeb20ec", "price_changes": [{"asset_id": "63189790407496871968365678866547561936214310417455881808824200627199091231049", "price": "0.39", "size": "0", "side": "BUY", "hash": "8c31d68cce884ae1030ecf1ba0ce8ffb161a94be", "best_bid": "0.94", "best_ask": "0.97"}, {"asset_id": "39492360553034885301486766992727683306899599890890066102594783083978384204123", "price": "0.61", "size": "0", "side": "SELL", "hash": "9822b40675157e496696f659118a563c4d69f155", "best_bid": "0.03", "best_ask": "0.06"}], "timestamp": "1769384469000", "event_type": "price_change"}}
{"_local_timestamp": "2026-01-25T23:41:09.096592+00:00", "data": {"market": "0x67d228115cc6ea9eb2dd85ca443c357359e4bdac7f773d8dff9f599cf5f58074", "price_changes": [{"asset_id": "115673443932214194570164346004924052532408865542451590692735424434267556754094", "price": "0.38", "size": "500", "side": "BUY", "hash": "5d993c7b6bfc3da5198bcb125ffd3064bf4fc033", "best_bid": "0.85", "best_ask": "0.87"}, {"asset_id": "40258076975888759603244407127088084693343108694292687330139582591508023070009", "price": "0.62", "size": "500", "side": "SELL", "hash": "8604854a9e78bf038586852f4a5bd5a82ebcab72", "best_bid": "0.13", "best_ask": "0.15"}], "timestamp": "1769384469001", "event_type": "price_change"}}
{"_local_timestamp": "2026-01-25T23:41:09.105113+00:00", "data": {"market": "0xfa0a910c4380fc83610d9fa68b214b598621ae9bd49dc40df47abd265bf0bc34", "price_changes": [{"asset_id": "42996585481877433482708272870977066259130153781685558286992961170000063507609", "price": "0.02", "size": "0", "side": "BUY", "hash": "224a44b1e68f48e818143024349ce791dd5491dc", "best_bid": "0.58", "best_ask": "0.94"}, {"asset_id": "59290556380981220753832906409296194214356850812489293134106523641703938483612", "price": "0.98", "size": "0", "side": "SELL", "hash": "a78cabdc1232224ee9dcfd9a28d78348cd3a0e18", "best_bid": "0.06", "best_ask": "0.42"}], "timestamp": "1769384469001", "event_type": "price_change"}}
{"_local_timestamp": "2026-01-25T23:41:09.111354+00:00", "data": {"market": "0x67d228115cc6ea9eb2dd85ca443c357359e4bdac7f773d8dff9f599cf5f58074", "price_changes": [{"asset_id": "40258076975888759603244407127088084693343108694292687330139582591508023070009", "price": "0.07", "size": "890.11", "side": "BUY", "hash": "eac7077e4eb28ab44c882cd31d53e95cf272fa06", "best_bid": "0.13", "best_ask": "0.15"}, {"asset_id": "115673443932214194570164346004924052532408865542451590692735424434267556754094", "price": "0.93", "size": "890.11", "side": "SELL", "hash": "f2171e29e784c5e364288a73c62b00ac4cb27673", "best_bid": "0.85", "best_ask": "0.87"}], "timestamp": "1769384469002", "event_type": "price_change"}}
{"_local_timestamp": "2026-01-25T23:41:09.185285+00:00", "data": {"market": "0xdb220d70cc76303505355f558407f99958916364c5612685c804fe1267d0f514", "price_changes": [{"asset_id": "29127800831891156918080289096614999289213121001925429958509112072030245798692", "price": "0.1", "size": "0", "side": "BUY", "hash": "c15bf629b42c1904cb2d210be752b3c2ba6ae906", "best_bid": "0.8", "best_ask": "0.97"}, {"asset_id": "89178703372212073978389921580322635269384366327786463025461810229435622804178", "price": "0.9", "size": "0", "side": "SELL", "hash": "7ae3368aa03d68de7e3ddd063ab31e47126afb04", "best_bid": "0.03", "best_ask": "0.2"}], "timestamp": "1769384469055", "event_type": "price_change"}}
{"_local_timestamp": "2026-01-25T23:41:09.191548+00:00", "data": {"market": "0x67d228115cc6ea9eb2dd85ca443c357359e4bdac7f773d8dff9f599cf5f58074", "price_changes": [{"asset_id": "40258076975888759603244407127088084693343108694292687330139582591508023070009", "price": "0.07", "size": "0", "side": "BUY", "hash": "aeab41bf43e0f94f9e107ee4d2014c9242b2c5c2", "best_bid": "0.13", "best_ask": "0.15"}, {"asset_id": "115673443932214194570164346004924052532408865542451590692735424434267556754094", "price": "0.93", "size": "0", "side": "SELL", "hash": "c2b99fa4e5c24aec9eeec34b0e6f61dcb5b465f1", "best_bid": "0.85", "best_ask": "0.87"}], "timestamp": "1769384469055", "event_type": "price_change"}}
{"_local_timestamp": "2026-01-25T23:41:09.198104+00:00", "data": {"market": "0xdb220d70cc76303505355f558407f99958916364c5612685c804fe1267d0f514", "price_changes": [{"asset_id": "29127800831891156918080289096614999289213121001925429958509112072030245798692", "price": "0.09", "size": "0", "side": "BUY", "hash": "c15bf629b42c1904cb2d210be752b3c2ba6ae906", "best_bid": "0.8", "best_ask": "0.97"}, {"asset_id": "89178703372212073978389921580322635269384366327786463025461810229435622804178", "price": "0.91", "size": "0", "side": "SELL", "hash": "7ae3368aa03d68de7e3ddd063ab31e47126afb04", "best_bid": "0.03", "best_ask": "0.2"}], "timestamp": "1769384469055", "event_type": "price_change"}}
{"_local_timestamp": "2026-01-25T23:41:09.204334+00:00", "data": {"market": "0x67d228115cc6ea9eb2dd85ca443c357359e4bdac7f773d8dff9f599cf5f58074", "price_changes": [{"asset_id": "40258076975888759603244407127088084693343108694292687330139582591508023070009", "price": "0.02", "size": "50", "side": "BUY", "hash": "aeab41bf43e0f94f9e107ee4d2014c9242b2c5c2", "best_bid": "0.13", "best_ask": "0.15"}, {"asset_id": "115673443932214194570164346004924052532408865542451590692735424434267556754094", "price": "0.98", "size": "50", "side": "SELL", "hash": "c2b99fa4e5c24aec9eeec34b0e6f61dcb5b465f1", "best_bid": "0.85", "best_ask": "0.87"}], "timestamp": "1769384469055", "event_type": "price_change"}}
{"_local_timestamp": "2026-01-25T23:41:09.291355+00:00", "data": {"market": "0x67d228115cc6ea9eb2dd85ca443c357359e4bdac7f773d8dff9f599cf5f58074", "price_changes": [{"asset_id": "40258076975888759603244407127088084693343108694292687330139582591508023070009", "price": "0.01", "size": "4290.32", "side": "BUY", "hash": "6b89c21928819dd6f55bc0721e8bb6d3da4b4c90", "best_bid": "0.13", "best_ask": "0.15"}, {"asset_id": "115673443932214194570164346004924052532408865542451590692735424434267556754094", "price": "0.99", "size": "4290.32", "side": "SELL", "hash": "c698daee124d6976a8ac057b5735fd21c28ae39c", "best_bid": "0.85", "best_ask": "0.87"}], "timestamp": "1769384469091", "event_type": "price_change"}}
{"_local_timestamp": "2026-01-25T23:41:09.297571+00:00", "data": {"market": "0x67d228115cc6ea9eb2dd85ca443c357359e4bdac7f773d8dff9f599cf5f58074", "price_changes": [{"asset_id": "40258076975888759603244407127088084693343108694292687330139582591508023070009", "price": "0.03", "size": "1270.1", "side": "BUY", "hash": "d44ee4bface62476c2150637790a3825c93e4252", "best_bid": "0.13", "best_ask": "0.15"}, {"asset_id": "115673443932214194570164346004924052532408865542451590692735424434267556754094", "price": "0.97", "size": "1270.1", "side": "SELL", "hash": "2a97f7e94ca837bd51a5afa31c5ba8b13cd08919", "best_bid": "0.85", "best_ask": "0.87"}], "timestamp": "1769384469092", "event_type": "price_change"}}
{"_local_timestamp": "2026-01-25T23:41:09.305170+00:00", "data": {"market": "0x67d228115cc6ea9eb2dd85ca443c357359e4bdac7f773d8dff9f599cf5f58074", "price_changes": [{"asset_id": "40258076975888759603244407127088084693343108694292687330139582591508023070009", "price": "0.03", "size": "3267.21", "side": "BUY", "hash": "c0db5f7b07603f93f59f8d95d65f7b45b03b89e2", "best_bid": "0.13", "best_ask": "0.15"}, {"asset_id": "115673443932214194570164346004924052532408865542451590692735424434267556754094", "price": "0.97", "size": "3267.21", "side": "SELL", "hash": "947627bd098aea1f0e07e827be17f789d12c947e", "best_bid": "0.85", "best_ask": "0.87"}], "timestamp": "1769384469093", "event_type": "price_change"}}
{"_local_timestamp": "2026-01-25T23:41:10.212895+00:00", "data": {"market": "0x425351f3d4713b9db2c15a80e1e75a2acf893b5495cc2e694095070137509329", "price_changes": [{"asset_id": "56846561876839441818327131212801941885992894700201726352426446447037474872043", "price": "0.34", "size": "393", "side": "BUY", "hash": "47e6635a0739d0d1b4fafaa1d543ca39fa4068fa", "best_bid": "0.99", "best_ask": "0.999"}, {"asset_id": "57829021360688395873888125190016504630905168321624137961276880640915115712545", "price": "0.66", "size": "393", "side": "SELL", "hash": "d7db5988a3e7a92fd60b8490452157a6e9054e8c", "best_bid": "0.001", "best_ask": "0.01"}], "timestamp": "1769384470146", "event_type": "price_change"}}
{"_local_timestamp": "2026-01-25T23:41:10.221054+00:00", "data": {"market": "0x67d228115cc6ea9eb2dd85ca443c357359e4bdac7f773d8dff9f599cf5f58074", "price_changes": [{"asset_id": "40258076975888759603244407127088084693343108694292687330139582591508023070009", "price": "0.04", "size": "2500", "side": "BUY", "hash": "d2c638a75973c3c219892c50a22c5bf3ef2b3632", "best_bid": "0.13", "best_ask": "0.15"}, {"asset_id": "115673443932214194570164346004924052532408865542451590692735424434267556754094", "price": "0.96", "size": "2500", "side": "SELL", "hash": "46f21623e674381afe46c30a734d4321d34146b7", "best_bid": "0.85", "best_ask": "0.87"}], "timestamp": "1769384470146", "event_type": "price_change"}}
{"_local_timestamp": "2026-01-25T23:41:10.228075+00:00", "data": {"market": "0x9b95e4d85d89a2aa406d7bc683e9b8bb8c7d2b16ee3b44878a36d4e79eeb20ec", "price_changes": [{"asset_id": "63189790407496871968365678866547561936214310417455881808824200627199091231049", "price": "0.39", "size": "256", "side": "BUY", "hash": "9e64cc20913a4cac142aaf2a594ce5d380735286", "best_bid": "0.94", "best_ask": "0.97"}, {"asset_id": "39492360553034885301486766992727683306899599890890066102594783083978384204123", "price": "0.61", "size": "256", "side": "SELL", "hash": "0a7e90fec1b384857c56f5612b115612158eb0bf", "best_bid": "0.03", "best_ask": "0.06"}], "timestamp": "1769384470146", "event_type": "price_change"}}
{"_local_timestamp": "2026-01-25T23:41:10.413552+00:00", "data": {"market": "0xfa0a910c4380fc83610d9fa68b214b598621ae9bd49dc40df47abd265bf0bc34", "price_changes": [{"asset_id": "42996585481877433482708272870977066259130153781685558286992961170000063507609", "price": "0.02", "size": "5000", "side": "BUY", "hash": "10829c06b6c9976f35e38aa912a7c041829b6fd7", "best_bid": "0.58", "best_ask": "0.94"}, {"asset_id": "59290556380981220753832906409296194214356850812489293134106523641703938483612", "price": "0.98", "size": "5000", "side": "SELL", "hash": "7c994ae68132b7638f2435b16c8684c33bfd27f7", "best_bid": "0.06", "best_ask": "0.42"}], "timestamp": "1769384470342", "event_type": "price_change"}}
{"_local_timestamp": "2026-01-25T23:41:10.419949+00:00", "data": {"market": "0x67d228115cc6ea9eb2dd85ca443c357359e4bdac7f773d8dff9f599cf5f58074", "price_changes": [{"asset_id": "115673443932214194570164346004924052532408865542451590692735424434267556754094", "price": "0.39", "size": "256", "side": "BUY", "hash": "17033ba2b900ed3e9f85b81e9feb23f23739289e", "best_bid": "0.85", "best_ask": "0.87"}, {"asset_id": "40258076975888759603244407127088084693343108694292687330139582591508023070009", "price": "0.61", "size": "256", "side": "SELL", "hash": "27e7efd290a8ce107e6c2ddd6b7bb1bc28713260", "best_bid": "0.13", "best_ask": "0.15"}], "timestamp": "1769384470341", "event_type": "price_change"}}
{"_local_timestamp": "2026-01-25T23:41:10.426186+00:00", "data": {"market": "0xdb220d70cc76303505355f558407f99958916364c5612685c804fe1267d0f514", "price_changes": [{"asset_id": "29127800831891156918080289096614999289213121001925429958509112072030245798692", "price": "0.13", "size": "769", "side": "BUY", "hash": "748d968cc098519a575dd4b2002d69ba68e40b19", "best_bid": "0.8", "best_ask": "0.97"}, {"asset_id": "89178703372212073978389921580322635269384366327786463025461810229435622804178", "price": "0.87", "size": "769", "side": "SELL", "hash": "1ede322f812b68d4f89b83d2039b352457866cda", "best_bid": "0.03", "best_ask": "0.2"}], "timestamp": "1769384470342", "event_type": "price_change"}}
{"_local_timestamp": "2026-01-25T23:41:10.451795+00:00", "data": {"market": "0xdb220d70cc76303505355f558407f99958916364c5612685c804fe1267d0f514", "price_changes": [{"asset_id": "29127800831891156918080289096614999289213121001925429958509112072030245798692", "price": "0.8", "size": "0", "side": "BUY", "hash": "826d14beb422ea11c7ed819d2840c80eeb5adb58", "best_bid": "0.57", "best_ask": "0.97"}, {"asset_id": "89178703372212073978389921580322635269384366327786463025461810229435622804178", "price": "0.2", "size": "0", "side": "SELL", "hash": "6f8fda62d8b7d54fd5813e9ff97a9091295fff33", "best_bid": "0.03", "best_ask": "0.43"}], "timestamp": "1769384470387", "event_type": "price_change"}}
{"_local_timestamp": "2026-01-25T23:41:10.471960+00:00", "data": {"market": "0xdb220d70cc76303505355f558407f99958916364c5612685c804fe1267d0f514", "price_changes": [{"asset_id": "29127800831891156918080289096614999289213121001925429958509112072030245798692", "price": "0.14", "size": "1270.1", "side": "BUY", "hash": "53c51ebafbfbbe27885ec24f00b802e7db1c0bab", "best_bid": "0.57", "best_ask": "0.97"}, {"asset_id": "89178703372212073978389921580322635269384366327786463025461810229435622804178", "price": "0.86", "size": "1270.1", "side": "SELL", "hash": "529ae1133daa4e41bbd7c7004b5e9ebbc32a2123", "best_bid": "0.03", "best_ask": "0.43"}], "timestamp": "1769384470405", "event_type": "price_change"}}
{"_local_timestamp": "2026-01-25T23:41:10.479250+00:00", "data": {"market": "0xdb220d70cc76303505355f558407f99958916364c5612685c804fe1267d0f514", "price_changes": [{"asset_id": "29127800831891156918080289096614999289213121001925429958509112072030245798692", "price": "0.14", "size": "2160.21", "side": "BUY", "hash": "ce8296bd9b23e2dcb459a60e331391c75c6cfca2", "best_bid": "0.57", "best_ask": "0.97"}, {"asset_id": "89178703372212073978389921580322635269384366327786463025461810229435622804178", "price": "0.86", "size": "2160.21", "side": "SELL", "hash": "95d587e3d661ae9ccce9885dc2242a62746f4a32", "best_bid": "0.03", "best_ask": "0.43"}], "timestamp": "1769384470406", "event_type": "price_change"}}
{"_local_timestamp": "2026-01-25T23:41:10.487026+00:00", "data": {"market": "0xdb220d70cc76303505355f558407f99958916364c5612685c804fe1267d0f514", "price_changes": [{"asset_id": "29127800831891156918080289096614999289213121001925429958509112072030245798692", "price": "0.14", "size": "4157.32", "side": "BUY", "hash": "a3e78c614445bec811c0cf6d6bf666e0efcb6e2e", "best_bid": "0.57", "best_ask": "0.97"}, {"asset_id": "89178703372212073978389921580322635269384366327786463025461810229435622804178", "price": "0.86", "size": "4157.32", "side": "SELL", "hash": "d637a5253df595ced3c47346de0c1b02f34f065d", "best_bid": "0.03", "best_ask": "0.43"}], "timestamp": "1769384470407", "event_type": "price_change"}}
{"_local_timestamp": "2026-01-25T23:41:10.495188+00:00", "data": {"market": "0xdb220d70cc76303505355f558407f99958916364c5612685c804fe1267d0f514", "price_changes": [{"asset_id": "29127800831891156918080289096614999289213121001925429958509112072030245798692", "price": "0.13", "size": "1659.11", "side": "BUY", "hash": "d37b4bd85fd3775d94278c2425fd59a1a82c25bd", "best_bid": "0.57", "best_ask": "0.97"}, {"asset_id": "89178703372212073978389921580322635269384366327786463025461810229435622804178", "price": "0.87", "size": "1659.11", "side": "SELL", "hash": "4dc10731d20927d2c093bc30e8baae6c0a95fa24", "best_bid": "0.03", "best_ask": "0.43"}], "timestamp": "1769384470407", "event_type": "price_change"}}
{"_local_timestamp": "2026-01-25T23:41:10.503663+00:00", "data": {"market": "0xdb220d70cc76303505355f558407f99958916364c5612685c804fe1267d0f514", "price_changes": [{"asset_id": "29127800831891156918080289096614999289213121001925429958509112072030245798692", "price": "0.14", "size": "5047.43", "side": "BUY", "hash": "7a949e24a91ba740f91ec5fd70e256d895fe395b", "best_bid": "0.57", "best_ask": "0.97"}, {"asset_id": "89178703372212073978389921580322635269384366327786463025461810229435622804178", "price": "0.86", "size": "5047.43", "side": "SELL", "hash": "40bef764048508754838ff74b8ca781a14b79120", "best_bid": "0.03", "best_ask": "0.43"}], "timestamp": "1769384470408", "event_type": "price_change"}}
{"_local_timestamp": "2026-01-25T23:41:10.710341+00:00", "data": {"market": "0xdb220d70cc76303505355f558407f99958916364c5612685c804fe1267d0f514", "price_changes": [{"asset_id": "29127800831891156918080289096614999289213121001925429958509112072030245798692", "price": "0.15", "size": "5999.11", "side": "BUY", "hash": "4725836983469a3bb66b1efd362af206c7e8c1e2", "best_bid": "0.57", "best_ask": "0.97"}, {"asset_id": "89178703372212073978389921580322635269384366327786463025461810229435622804178", "price": "0.85", "size": "5999.11", "side": "SELL", "hash": "4bbf2d8c84965347f3596b8260bcc5b45476e81c", "best_bid": "0.03", "best_ask": "0.43"}], "timestamp": "1769384470637", "event_type": "price_change"}}
{"_local_timestamp": "2026-01-25T23:41:10.905484+00:00", "data": {"market": "0xdb220d70cc76303505355f558407f99958916364c5612685c804fe1267d0f514", "price_changes": [{"asset_id": "29127800831891156918080289096614999289213121001925429958509112072030245798692", "price": "0.02", "size": "5047.43", "side": "BUY", "hash": "49ea94cfe07039c666da2e0ebd27997cad4ebaba", "best_bid": "0.57", "best_ask": "0.97"}, {"asset_id": "89178703372212073978389921580322635269384366327786463025461810229435622804178", "price": "0.98", "size": "5047.43", "side": "SELL", "hash": "d745547e676d0f1b2c368c6b3a17169e13391619", "best_bid": "0.03", "best_ask": "0.43"}], "timestamp": "1769384470836", "event_type": "price_change"}}
{"_local_timestamp": "2026-01-25T23:41:10.913071+00:00", "data": {"market": "0xdb220d70cc76303505355f558407f99958916364c5612685c804fe1267d0f514", "price_changes": [{"asset_id": "29127800831891156918080289096614999289213121001925429958509112072030245798692", "price": "0.05", "size": "0", "side": "BUY", "hash": "49ea94cfe07039c666da2e0ebd27997cad4ebaba", "best_bid": "0.57", "best_ask": "0.97"}, {"asset_id": "89178703372212073978389921580322635269384366327786463025461810229435622804178", "price": "0.95", "size": "0", "side": "SELL", "hash": "d745547e676d0f1b2c368c6b3a17169e13391619", "best_bid": "0.03", "best_ask": "0.43"}], "timestamp": "1769384470836", "event_type": "price_change"}}
{"_local_timestamp": "2026-01-25T23:41:11.310795+00:00", "data": {"market": "0xdb220d70cc76303505355f558407f99958916364c5612685c804fe1267d0f514", "price_changes": [{"asset_id": "29127800831891156918080289096614999289213121001925429958509112072030245798692", "price": "0.03", "size": "29.8", "side": "BUY", "hash": "2c9ab821971d2a4433989608fdb64e5c3fdd09ec", "best_bid": "0.57", "best_ask": "0.97"}, {"asset_id": "89178703372212073978389921580322635269384366327786463025461810229435622804178", "price": "0.97", "size": "29.8", "side": "SELL", "hash": "ad067e95dc5a686c633bfa36234861f90483aabc", "best_bid": "0.03", "best_ask": "0.43"}], "timestamp": "1769384471160", "event_type": "price_change"}}
{"_local_timestamp": "2026-01-25T23:41:11.317268+00:00", "data": {"market": "0xdb220d70cc76303505355f558407f99958916364c5612685c804fe1267d0f514", "price_changes": [{"asset_id": "29127800831891156918080289096614999289213121001925429958509112072030245798692", "price": "0.01", "size": "8066.3", "side": "BUY", "hash": "234cdb6cd64117ff346b8e832cee98e277a8a21e", "best_bid": "0.57", "best_ask": "0.97"}, {"asset_id": "89178703372212073978389921580322635269384366327786463025461810229435622804178", "price": "0.99", "size": "8066.3", "side": "SELL", "hash": "134126f9e8f4d5e5e2139a1ac8666ec575203c29", "best_bid": "0.03", "best_ask": "0.43"}], "timestamp": "1769384471164", "event_type": "price_change"}}
{"_local_timestamp": "2026-01-25T23:41:12.400262+00:00", "data": {"market": "0x425351f3d4713b9db2c15a80e1e75a2acf893b5495cc2e694095070137509329", "price_changes": [{"asset_id": "57829021360688395873888125190016504630905168321624137961276880640915115712545", "price": "0.001", "size": "7802.11", "side": "BUY", "hash": "84f429239d9cdf9b35209e01cd10e41e8e693e62", "best_bid": "0.001", "best_ask": "0.01"}, {"asset_id": "56846561876839441818327131212801941885992894700201726352426446447037474872043", "price": "0.999", "size": "7802.11", "side": "SELL", "hash": "97fb9b741c8cc80a06360d6b45eac2f8f37354df", "best_bid": "0.99", "best_ask": "0.999"}], "timestamp": "1769384472330", "event_type": "price_change"}}
{"_local_timestamp": "2026-01-25T23:41:12.621099+00:00", "data": {"market": "0x9b95e4d85d89a2aa406d7bc683e9b8bb8c7d2b16ee3b44878a36d4e79eeb20ec", "price_changes": [{"asset_id": "63189790407496871968365678866547561936214310417455881808824200627199091231049", "price": "0.89", "size": "890.11", "side": "BUY", "hash": "a81c9a75da3c2580bd904b523303a1a574745528", "best_bid": "0.94", "best_ask": "0.97"}, {"asset_id": "39492360553034885301486766992727683306899599890890066102594783083978384204123", "price": "0.11", "size": "890.11", "side": "SELL", "hash": "4a3f5560de497e5f911b1915db1919d3a78794fe", "best_bid": "0.03", "best_ask": "0.06"}], "timestamp": "1769384472549", "event_type": "price_change"}}
{"_local_timestamp": "2026-01-25T23:41:12.831114+00:00", "data": {"market": "0x9b95e4d85d89a2aa406d7bc683e9b8bb8c7d2b16ee3b44878a36d4e79eeb20ec", "price_changes": [{"asset_id": "63189790407496871968365678866547561936214310417455881808824200627199091231049", "price": "0.71", "size": "5057.43", "side": "BUY", "hash": "f8adf5b3b2a44bcd9db0b023e1b138e41eaf4d54", "best_bid": "0.94", "best_ask": "0.97"}, {"asset_id": "39492360553034885301486766992727683306899599890890066102594783083978384204123", "price": "0.29", "size": "5057.43", "side": "SELL", "hash": "5d64ae92702e8d41227978bca23c969168184c8d", "best_bid": "0.03", "best_ask": "0.06"}], "timestamp": "1769384472758", "event_type": "price_change"}}
{"_local_timestamp": "2026-01-25T23:41:12.846645+00:00", "data": {"market": "0x9b95e4d85d89a2aa406d7bc683e9b8bb8c7d2b16ee3b44878a36d4e79eeb20ec", "price_changes": [{"asset_id": "63189790407496871968365678866547561936214310417455881808824200627199091231049", "price": "0.7", "size": "2676.93", "side": "BUY", "hash": "ece0ae4e5b34bce5b5c101005fc3e6dad7e2f50d", "best_bid": "0.94", "best_ask": "0.97"}, {"asset_id": "39492360553034885301486766992727683306899599890890066102594783083978384204123", "price": "0.3", "size": "2676.93", "side": "SELL", "hash": "a1d8804734f4a7739b3cb8eee798ce125fe9ebca", "best_bid": "0.03", "best_ask": "0.06"}], "timestamp": "1769384472759", "event_type": "price_change"}}
{"_local_timestamp": "2026-01-25T23:41:12.977155+00:00", "data": {"market": "0x67d228115cc6ea9eb2dd85ca443c357359e4bdac7f773d8dff9f599cf5f58074", "price_changes": [{"asset_id": "115673443932214194570164346004924052532408865542451590692735424434267556754094", "price": "0.38", "size": "0", "side": "BUY", "hash": "0294689d46bc60681eb6dbdf5ef0778d6a3d701d", "best_bid": "0.85", "best_ask": "0.87"}, {"asset_id": "40258076975888759603244407127088084693343108694292687330139582591508023070009", "price": "0.62", "size": "0", "side": "SELL", "hash": "6bcbc23dc6089c5230442d461a83f41bf503948e", "best_bid": "0.13", "best_ask": "0.15"}], "timestamp": "1769384472909", "event_type": "price_change"}}
{"_local_timestamp": "2026-01-25T23:41:13.029803+00:00", "data": {"market": "0x67d228115cc6ea9eb2dd85ca443c357359e4bdac7f773d8dff9f599cf5f58074", "price_changes": [{"asset_id": "40258076975888759603244407127088084693343108694292687330139582591508023070009", "price": "0.01", "size": "2130.11", "side": "BUY", "hash": "d7cb230fb39401e711265da08274c6ae7424d5e0", "best_bid": "0.13", "best_ask": "0.15"}, {"asset_id": "115673443932214194570164346004924052532408865542451590692735424434267556754094", "price": "0.99", "size": "2130.11", "side": "SELL", "hash": "282942af2c180d01cf0eddc539cc7313e773c987", "best_bid": "0.85", "best_ask": "0.87"}], "timestamp": "1769384472963", "event_type": "price_change"}}
{"_local_timestamp": "2026-01-25T23:41:13.054537+00:00", "data": {"market": "0x67d228115cc6ea9eb2dd85ca443c357359e4bdac7f773d8dff9f599cf5f58074", "price_changes": [{"asset_id": "40258076975888759603244407127088084693343108694292687330139582591508023070009", "price": "0.03", "size": "0", "side": "BUY", "hash": "d7cb230fb39401e711265da08274c6ae7424d5e0", "best_bid": "0.13", "best_ask": "0.15"}, {"asset_id": "115673443932214194570164346004924052532408865542451590692735424434267556754094", "price": "0.97", "size": "0", "side": "SELL", "hash": "282942af2c180d01cf0eddc539cc7313e773c987", "best_bid": "0.85", "best_ask": "0.87"}], "timestamp": "1769384472963", "event_type": "price_change"}}
{"_local_timestamp": "2026-01-25T23:41:13.063438+00:00", "data": {"market": "0x67d228115cc6ea9eb2dd85ca443c357359e4bdac7f773d8dff9f599cf5f58074", "price_changes": [{"asset_id": "40258076975888759603244407127088084693343108694292687330139582591508023070009", "price": "0.05", "size": "1270.1", "side": "BUY", "hash": "b399b9d41c9521a65429416808f5e14cd02c2620", "best_bid": "0.13", "best_ask": "0.15"}, {"asset_id": "115673443932214194570164346004924052532408865542451590692735424434267556754094", "price": "0.95", "size": "1270.1", "side": "SELL", "hash": "0d07c9df84c0f80009a5dbfdcf48f515ac422ae0", "best_bid": "0.85", "best_ask": "0.87"}], "timestamp": "1769384472990", "event_type": "price_change"}}
{"_local_timestamp": "2026-01-25T23:41:13.095829+00:00", "data": {"market": "0x67d228115cc6ea9eb2dd85ca443c357359e4bdac7f773d8dff9f599cf5f58074", "price_changes": [{"asset_id": "40258076975888759603244407127088084693343108694292687330139582591508023070009", "price": "0.05", "size": "2160.21", "side": "BUY", "hash": "431e7b21329c5bef86c40d1037c1b5e2daf90cbf", "best_bid": "0.13", "best_ask": "0.15"}, {"asset_id": "115673443932214194570164346004924052532408865542451590692735424434267556754094", "price": "0.95", "size": "2160.21", "side": "SELL", "hash": "b1895b951ebac726386c9ada36fcf48e24a631e8", "best_bid": "0.85", "best_ask": "0.87"}], "timestamp": "1769384472990", "event_type": "price_change"}}
{"_local_timestamp": "2026-01-25T23:41:13.454348+00:00", "data": {"market": "0x425351f3d4713b9db2c15a80e1e75a2acf893b5495cc2e694095070137509329", "price_changes": [{"asset_id": "56846561876839441818327131212801941885992894700201726352426446447037474872043", "price": "0.001", "size": "1068.39", "side": "BUY", "hash": "152464ba5b50ad9729d4c6057386d1a42d9ea5fa", "best_bid": "0.99", "best_ask": "0.999"}, {"asset_id": "57829021360688395873888125190016504630905168321624137961276880640915115712545", "price": "0.999", "size": "1068.39", "side": "SELL", "hash": "f3cf356daee768449b43d82905111c30e4949dfb", "best_bid": "0.001", "best_ask": "0.01"}], "timestamp": "1769384473382", "event_type": "price_change"}}
{"_local_timestamp": "2026-01-25T23:41:14.080900+00:00", "data": {"market": "0x67d228115cc6ea9eb2dd85ca443c357359e4bdac7f773d8dff9f599cf5f58074", "price_changes": [{"asset_id": "40258076975888759603244407127088084693343108694292687330139582591508023070009", "price": "0.04", "size": "0", "side": "BUY", "hash": "b1eb78198e2610fe96c75cf615e5fc2d93c0691e", "best_bid": "0.13", "best_ask": "0.15"}, {"asset_id": "115673443932214194570164346004924052532408865542451590692735424434267556754094", "price": "0.96", "size": "0", "side": "SELL", "hash": "4c263a3d6ea9dde6ef9cb30ebf3777c1a57ef524", "best_bid": "0.85", "best_ask": "0.87"}], "timestamp": "1769384474000", "event_type": "price_change"}}
{"_local_timestamp": "2026-01-25T23:41:14.093322+00:00", "data": {"market": "0x9b95e4d85d89a2aa406d7bc683e9b8bb8c7d2b16ee3b44878a36d4e79eeb20ec", "price_changes": [{"asset_id": "63189790407496871968365678866547561936214310417455881808824200627199091231049", "price": "0.39", "size": "0", "side": "BUY", "hash": "14170b87dfca9d015bc6d20b1439e332a0390334", "best_bid": "0.94", "best_ask": "0.97"}, {"asset_id": "39492360553034885301486766992727683306899599890890066102594783083978384204123", "price": "0.61", "size": "0", "side": "SELL", "hash": "ee8a1498edd13741b2efeb25590acd4aff2a3300", "best_bid": "0.03", "best_ask": "0.06"}], "timestamp": "1769384474000", "event_type": "price_change"}}
{"_local_timestamp": "2026-01-25T23:41:14.101772+00:00", "data": {"market": "0x425351f3d4713b9db2c15a80e1e75a2acf893b5495cc2e694095070137509329", "price_changes": [{"asset_id": "56846561876839441818327131212801941885992894700201726352426446447037474872043", "price": "0.34", "size": "100", "side": "BUY", "hash": "b513598a21523f69b6ddefe5dbf0889a7dab65d5", "best_bid": "0.99", "best_ask": "0.999"}, {"asset_id": "57829021360688395873888125190016504630905168321624137961276880640915115712545", "price": "0.66", "size": "100", "side": "SELL", "hash": "9b6fc86f050f09a8c52427ad400447841d6e0c14", "best_bid": "0.001", "best_ask": "0.01"}], "timestamp": "1769384474001", "event_type": "price_change"}}
{"_local_timestamp": "2026-01-25T23:41:15.063783+00:00", "data": {"market": "0xfa0a910c4380fc83610d9fa68b214b598621ae9bd49dc40df47abd265bf0bc34", "price_changes": [{"asset_id": "42996585481877433482708272870977066259130153781685558286992961170000063507609", "price": "0.02", "size": "0", "side": "BUY", "hash": "7317193e3228b722a32b056f9724a02377e432ef", "best_bid": "0.58", "best_ask": "0.94"}, {"asset_id": "59290556380981220753832906409296194214356850812489293134106523641703938483612", "price": "0.98", "size": "0", "side": "SELL", "hash": "a541d1390960fc75babe1d2972c7a3a7aee2a3c0", "best_bid": "0.06", "best_ask": "0.42"}], "timestamp": "1769384475000", "event_type": "price_change"}}
{"_local_timestamp": "2026-01-25T23:41:15.076703+00:00", "data": {"market": "0x67d228115cc6ea9eb2dd85ca443c357359e4bdac7f773d8dff9f599cf5f58074", "price_changes": [{"asset_id": "115673443932214194570164346004924052532408865542451590692735424434267556754094", "price": "0.39", "size": "0", "side": "BUY", "hash": "04c4fd9cb36b6cc7ffbf881143623a3498a33b02", "best_bid": "0.85", "best_ask": "0.87"}, {"asset_id": "40258076975888759603244407127088084693343108694292687330139582591508023070009", "price": "0.61", "size": "0", "side": "SELL", "hash": "17b402caec9c18cc557b09cb27063a7ea5a06e2b", "best_bid": "0.13", "best_ask": "0.15"}], "timestamp": "1769384475001", "event_type": "price_change"}}
{"_local_timestamp": "2026-01-25T23:41:15.083126+00:00", "data": {"market": "0xdb220d70cc76303505355f558407f99958916364c5612685c804fe1267d0f514", "price_changes": [{"asset_id": "29127800831891156918080289096614999289213121001925429958509112072030245798692", "price": "0.13", "size": "890.11", "side": "BUY", "hash": "441e339577beead7a10261a6336b18bafaa08506", "best_bid": "0.57", "best_ask": "0.97"}, {"asset_id": "89178703372212073978389921580322635269384366327786463025461810229435622804178", "price": "0.87", "size": "890.11", "side": "SELL", "hash": "98a237ea6dcdc85cfba779218333fdde3417d48c", "best_bid": "0.03", "best_ask": "0.43"}], "timestamp": "1769384475001", "event_type": "price_change"}}
{"_local_timestamp": "2026-01-25T23:41:15.164707+00:00", "data": {"market": "0x67d228115cc6ea9eb2dd85ca443c357359e4bdac7f773d8dff9f599cf5f58074", "price_changes": [{"asset_id": "40258076975888759603244407127088084693343108694292687330139582591508023070009", "price": "0.13", "size": "22.34", "side": "BUY", "hash": "8aca94d6a0115507b29752a78008cf67a5eebe8c", "best_bid": "0.13", "best_ask": "0.15"}, {"asset_id": "115673443932214194570164346004924052532408865542451590692735424434267556754094", "price": "0.87", "size": "22.34", "side": "SELL", "hash": "fe9c2e59a42eb74afe95daef9c5232f2d16d4592", "best_bid": "0.85", "best_ask": "0.87"}], "timestamp": "1769384475087", "event_type": "price_change"}}
{"_local_timestamp": "2026-01-25T23:41:15.172416+00:00", "data": {"market": "0x67d228115cc6ea9eb2dd85ca443c357359e4bdac7f773d8dff9f599cf5f58074", "asset_id": "115673443932214194570164346004924052532408865542451590692735424434267556754094", "bids": [{"price": "0.01", "size": "7142.33"}, {"price": "0.02", "size": "4157.32"}, {"price": "0.03", "size": "9.93"}, {"price": "0.08", "size": "16"}, {"price": "0.09", "size": "7.22"}, {"price": "0.2", "size": "200"}, {"price": "0.27", "size": "200"}, {"price": "0.34", "size": "100"}, {"price": "0.36", "size": "100"}, {"price": "0.37", "size": "100"}, {"price": "0.5", "size": "140"}, {"price": "0.76", "size": "26"}, {"price": "0.79", "size": "1890.11"}, {"price": "0.8", "size": "1290.11"}, {"price": "0.83", "size": "338"}, {"price": "0.84", "size": "9"}, {"price": "0.85", "size": "2100"}], "asks": [{"price": "0.99", "size": "2130.11"}, {"price": "0.98", "size": "50"}, {"price": "0.95", "size": "2160.21"}, {"price": "0.89", "size": "1890.11"}, {"price": "0.88", "size": "899.11"}, {"price": "0.87", "size": "22.34"}], "hash": "fe9c2e59a42eb74afe95daef9c5232f2d16d4592", "timestamp": "1769384475087", "event_type": "book"}}
{"_local_timestamp": "2026-01-25T23:41:15.180149+00:00", "data": {"market": "0x67d228115cc6ea9eb2dd85ca443c357359e4bdac7f773d8dff9f599cf5f58074", "asset_id": "40258076975888759603244407127088084693343108694292687330139582591508023070009", "bids": [{"price": "0.01", "size": "2130.11"}, {"price": "0.02", "size": "50"}, {"price": "0.05", "size": "2160.21"}, {"price": "0.11", "size": "1890.11"}, {"price": "0.12", "size": "899.11"}, {"price": "0.13", "size": "22.34"}], "asks": [{"price": "0.99", "size": "7142.33"}, {"price": "0.98", "size": "4157.32"}, {"price": "0.97", "size": "9.93"}, {"price": "0.92", "size": "16"}, {"price": "0.91", "size": "7.22"}, {"price": "0.8", "size": "200"}, {"price": "0.73", "size": "200"}, {"price": "0.66", "size": "100"}, {"price": "0.64", "size": "100"}, {"price": "0.63", "size": "100"}, {"price": "0.5", "size": "140"}, {"price": "0.24", "size": "26"}, {"price": "0.21", "size": "1890.11"}, {"price": "0.2", "size": "1290.11"}, {"price": "0.17", "size": "338"}, {"price": "0.16", "size": "9"}, {"price": "0.15", "size": "2100"}], "hash": "8aca94d6a0115507b29752a78008cf67a5eebe8c", "timestamp": "1769384475087", "event_type": "book"}}
{"_local_timestamp": "2026-01-25T23:41:15.188139+00:00", "data": {"market": "0xdb220d70cc76303505355f558407f99958916364c5612685c804fe1267d0f514", "price_changes": [{"asset_id": "29127800831891156918080289096614999289213121001925429958509112072030245798692", "price": "0.12", "size": "0", "side": "BUY", "hash": "e000f4e40d64f6dd51ec8f935974e4dba008ebce", "best_bid": "0.57", "best_ask": "0.97"}, {"asset_id": "89178703372212073978389921580322635269384366327786463025461810229435622804178", "price": "0.88", "size": "0", "side": "SELL", "hash": "b9d3259dbb191862a6118e2f2fe353efc16d1e1a", "best_bid": "0.03", "best_ask": "0.43"}], "timestamp": "1769384475109", "event_type": "price_change"}}
{"_local_timestamp": "2026-01-25T23:41:15.194391+00:00", "data": {"market": "0xdb220d70cc76303505355f558407f99958916364c5612685c804fe1267d0f514", "price_changes": [{"asset_id": "29127800831891156918080289096614999289213121001925429958509112072030245798692", "price": "0.11", "size": "0", "side": "BUY", "hash": "e000f4e40d64f6dd51ec8f935974e4dba008ebce", "best_bid": "0.57", "best_ask": "0.97"}, {"asset_id": "89178703372212073978389921580322635269384366327786463025461810229435622804178", "price": "0.89", "size": "0", "side": "SELL", "hash": "b9d3259dbb191862a6118e2f2fe353efc16d1e1a", "best_bid": "0.03", "best_ask": "0.43"}], "timestamp": "1769384475109", "event_type": "price_change"}}
{"_local_timestamp": "2026-01-25T23:41:15.202602+00:00", "data": {"market": "0xdb220d70cc76303505355f558407f99958916364c5612685c804fe1267d0f514", "price_changes": [{"asset_id": "29127800831891156918080289096614999289213121001925429958509112072030245798692", "price": "0.15", "size": "0", "side": "BUY", "hash": "e000f4e40d64f6dd51ec8f935974e4dba008ebce", "best_bid": "0.57", "best_ask": "0.97"}, {"asset_id": "89178703372212073978389921580322635269384366327786463025461810229435622804178", "price": "0.85", "size": "0", "side": "SELL", "hash": "b9d3259dbb191862a6118e2f2fe353efc16d1e1a", "best_bid": "0.03", "best_ask": "0.43"}], "timestamp": "1769384475109", "event_type": "price_change"}}
{"_local_timestamp": "2026-01-25T23:41:15.214302+00:00", "data": {"market": "0x67d228115cc6ea9eb2dd85ca443c357359e4bdac7f773d8dff9f599cf5f58074", "asset_id": "115673443932214194570164346004924052532408865542451590692735424434267556754094", "price": "0.87", "size": "668.494246", "fee_rate_bps": "0", "side": "BUY", "timestamp": "1769384475116", "event_type": "last_trade_price", "transaction_hash": "0x1e388fd82528994af81a9cacae5c243a4e3ea4ff5d40ea1d85ac2647285372ce"}}
{"_local_timestamp": "2026-01-25T23:41:15.423128+00:00", "data": {"market": "0x9b95e4d85d89a2aa406d7bc683e9b8bb8c7d2b16ee3b44878a36d4e79eeb20ec", "price_changes": [{"asset_id": "63189790407496871968365678866547561936214310417455881808824200627199091231049", "price": "0.92", "size": "4481.97", "side": "BUY", "hash": "71ce8191bfa2b7a56f7f890474959b6680e65579", "best_bid": "0.94", "best_ask": "0.97"}, {"asset_id": "39492360553034885301486766992727683306899599890890066102594783083978384204123", "price": "0.08", "size": "4481.97", "side": "SELL", "hash": "1005f69cdb3ed6858d054927442a68812f7499f5", "best_bid": "0.03", "best_ask": "0.06"}], "timestamp": "1769384475355", "event_type": "price_change"}}
{"_local_timestamp": "2026-01-25T23:41:15.511675+00:00", "data": {"market": "0x9b95e4d85d89a2aa406d7bc683e9b8bb8c7d2b16ee3b44878a36d4e79eeb20ec", "price_changes": [{"asset_id": "63189790407496871968365678866547561936214310417455881808824200627199091231049", "price": "0.9", "size": "50", "side": "BUY", "hash": "45769744ed97f01cb85de13c12ef19d33e725983", "best_bid": "0.94", "best_ask": "0.97"}, {"asset_id": "39492360553034885301486766992727683306899599890890066102594783083978384204123", "price": "0.1", "size": "50", "side": "SELL", "hash": "9c9a53433cda97d7007193ee99c911e7fa13ace9", "best_bid": "0.03", "best_ask": "0.06"}], "timestamp": "1769384475438", "event_type": "price_change"}}
{"_local_timestamp": "2026-01-25T23:41:15.519548+00:00", "data": {"market": "0x9b95e4d85d89a2aa406d7bc683e9b8bb8c7d2b16ee3b44878a36d4e79eeb20ec", "price_changes": [{"asset_id": "63189790407496871968365678866547561936214310417455881808824200627199091231049", "price": "0.89", "size": "0", "side": "BUY", "hash": "45769744ed97f01cb85de13c12ef19d33e725983", "best_bid": "0.94", "best_ask": "0.97"}, {"asset_id": "39492360553034885301486766992727683306899599890890066102594783083978384204123", "price": "0.11", "size": "0", "side": "SELL", "hash": "9c9a53433cda97d7007193ee99c911e7fa13ace9", "best_bid": "0.03", "best_ask": "0.06"}], "timestamp": "1769384475438", "event_type": "price_change"}}
{"_local_timestamp": "2026-01-25T23:41:15.580429+00:00", "data": {"market": "0x9b95e4d85d89a2aa406d7bc683e9b8bb8c7d2b16ee3b44878a36d4e79eeb20ec", "price_changes": [{"asset_id": "39492360553034885301486766992727683306899599890890066102594783083978384204123", "price": "0.03", "size": "12.18", "side": "BUY", "hash": "35207969c44beca115d669a25a2074e7e0cfbed5", "best_bid": "0.03", "best_ask": "0.06"}, {"asset_id": "63189790407496871968365678866547561936214310417455881808824200627199091231049", "price": "0.97", "size": "12.18", "side": "SELL", "hash": "86e072ef8e3a0c8d02b48c3042db629e05ec137b", "best_bid": "0.94", "best_ask": "0.97"}], "timestamp": "1769384475506", "event_type": "price_change"}}
{"_local_timestamp": "2026-01-25T23:41:15.741741+00:00", "data": {"market": "0x425351f3d4713b9db2c15a80e1e75a2acf893b5495cc2e694095070137509329", "price_changes": [{"asset_id": "56846561876839441818327131212801941885992894700201726352426446447037474872043", "price": "0.34", "size": "393", "side": "BUY", "hash": "e4100dca5e30821c7ace7a19525cd9381ef5a846", "best_bid": "0.99", "best_ask": "0.999"}, {"asset_id": "57829021360688395873888125190016504630905168321624137961276880640915115712545", "price": "0.66", "size": "393", "side": "SELL", "hash": "93f7207e014a6cb5ac4984bac843692e93bd6580", "best_bid": "0.001", "best_ask": "0.01"}], "timestamp": "1769384475676", "event_type": "price_change"}}
{"_local_timestamp": "2026-01-25T23:41:15.751196+00:00", "data": {"market": "0x67d228115cc6ea9eb2dd85ca443c357359e4bdac7f773d8dff9f599cf5f58074", "price_changes": [{"asset_id": "115673443932214194570164346004924052532408865542451590692735424434267556754094", "price": "0.38", "size": "263", "side": "BUY", "hash": "b38e077355582976b8db3d9973d1b8d688c24eee", "best_bid": "0.85", "best_ask": "0.87"}, {"asset_id": "40258076975888759603244407127088084693343108694292687330139582591508023070009", "price": "0.62", "size": "263", "side": "SELL", "hash": "c7b70a2be1042c20240ebd07aacb49bb68ad1c9e", "best_bid": "0.13", "best_ask": "0.15"}], "timestamp": "1769384475677", "event_type": "price_change"}}
{"_local_timestamp": "2026-01-25T23:41:15.761065+00:00", "data": {"market": "0x9b95e4d85d89a2aa406d7bc683e9b8bb8c7d2b16ee3b44878a36d4e79eeb20ec", "price_changes": [{"asset_id": "63189790407496871968365678866547561936214310417455881808824200627199091231049", "price": "0.39", "size": "256", "side": "BUY", "hash": "f8391820357832d4133343af339be5721c3f241d", "best_bid": "0.94", "best_ask": "0.97"}, {"asset_id": "39492360553034885301486766992727683306899599890890066102594783083978384204123", "price": "0.61", "size": "256", "side": "SELL", "hash": "e9205bfc321492e07616300f1e4c45c3c47ee4a3", "best_bid": "0.03", "best_ask": "0.06"}], "timestamp": "1769384475677", "event_type": "price_change"}}
{"_local_timestamp": "2026-01-25T23:41:15.782031+00:00", "data": {"market": "0x67d228115cc6ea9eb2dd85ca443c357359e4bdac7f773d8dff9f599cf5f58074", "price_changes": [{"asset_id": "40258076975888759603244407127088084693343108694292687330139582591508023070009", "price": "0.05", "size": "1270.1", "side": "BUY", "hash": "c41c491a9e25b3a398fecc6e62dcb54710aa1488", "best_bid": "0.13", "best_ask": "0.15"}, {"asset_id": "115673443932214194570164346004924052532408865542451590692735424434267556754094", "price": "0.95", "size": "1270.1", "side": "SELL", "hash": "2ac38c177ea395a4ec7e03228ac83032a6622f1b", "best_bid": "0.85", "best_ask": "0.87"}], "timestamp": "1769384475717", "event_type": "price_change"}}
{"_local_timestamp": "2026-01-25T23:41:15.856518+00:00", "data": {"market": "0x9b95e4d85d89a2aa406d7bc683e9b8bb8c7d2b16ee3b44878a36d4e79eeb20ec", "price_changes": [{"asset_id": "39492360553034885301486766992727683306899599890890066102594783083978384204123", "price": "0.02", "size": "1333.92", "side": "BUY", "hash": "ce055f17b54bf5903e87e748185d06424a3b9bc5", "best_bid": "0.03", "best_ask": "0.06"}, {"asset_id": "63189790407496871968365678866547561936214310417455881808824200627199091231049", "price": "0.98", "size": "1333.92", "side": "SELL", "hash": "ffb91d3e4113ab02208cd67ad71f5822fc959129", "best_bid": "0.94", "best_ask": "0.97"}], "timestamp": "1769384475763", "event_type": "price_change"}}
{"_local_timestamp": "2026-01-25T23:41:15.910216+00:00", "data": {"market": "0xfa0a910c4380fc83610d9fa68b214b598621ae9bd49dc40df47abd265bf0bc34", "price_changes": [{"asset_id": "42996585481877433482708272870977066259130153781685558286992961170000063507609", "price": "0.02", "size": "5000", "side": "BUY", "hash": "99281d67e2be7402b068c1914937d0acc5af3c09", "best_bid": "0.58", "best_ask": "0.94"}, {"asset_id": "59290556380981220753832906409296194214356850812489293134106523641703938483612", "price": "0.98", "size": "5000", "side": "SELL", "hash": "4daeed55b611e128273119967a693dd0e796a04f", "best_bid": "0.06", "best_ask": "0.42"}], "timestamp": "1769384475838", "event_type": "price_change"}}
{"_local_timestamp": "2026-01-25T23:41:15.917934+00:00", "data": {"market": "0x67d228115cc6ea9eb2dd85ca443c357359e4bdac7f773d8dff9f599cf5f58074", "price_changes": [{"asset_id": "40258076975888759603244407127088084693343108694292687330139582591508023070009", "price": "0.06", "size": "1666", "side": "BUY", "hash": "4405b6e8a1438a9d100ac746e45a4a50819ce16d", "best_bid": "0.13", "best_ask": "0.15"}, {"asset_id": "115673443932214194570164346004924052532408865542451590692735424434267556754094", "price": "0.94", "size": "1666", "side": "SELL", "hash": "0b063e8e42ec0a28830e82ffc33097f03f0dedb6", "best_bid": "0.85", "best_ask": "0.87"}], "timestamp": "1769384475838", "event_type": "price_change"}}
{"_local_timestamp": "2026-01-25T23:41:15.927794+00:00", "data": {"market": "0xdb220d70cc76303505355f558407f99958916364c5612685c804fe1267d0f514", "price_changes": [{"asset_id": "29127800831891156918080289096614999289213121001925429958509112072030245798692", "price": "0.15", "size": "666", "side": "BUY", "hash": "3ef1e4645c96de0fc0d9d87cd39db4d01eeb53fd", "best_bid": "0.57", "best_ask": "0.97"}, {"asset_id": "89178703372212073978389921580322635269384366327786463025461810229435622804178", "price": "0.85", "size": "666", "side": "SELL", "hash": "a7907c7ad5649ed5d20a5e5e38eeb7c2179913b2", "best_bid": "0.03", "best_ask": "0.43"}], "timestamp": "1769384475838", "event_type": "price_change"}}
{"_local_timestamp": "2026-01-25T23:41:16.127581+00:00", "data": {"market": "0xdb220d70cc76303505355f558407f99958916364c5612685c804fe1267d0f514", "price_changes": [{"asset_id": "29127800831891156918080289096614999289213121001925429958509112072030245798692", "price": "0.15", "size": "1556.11", "side": "BUY", "hash": "cc01b8e7ce039ae7466bedc9e9a007e5e3461db0", "best_bid": "0.57", "best_ask": "0.97"}, {"asset_id": "89178703372212073978389921580322635269384366327786463025461810229435622804178", "price": "0.85", "size": "1556.11", "side": "SELL", "hash": "6dc84f36b3cd3d318c447c01aa3a111dc3b8c993", "best_bid": "0.03", "best_ask": "0.43"}], "timestamp": "1769384475994", "event_type": "price_change"}}
{"_local_timestamp": "2026-01-25T23:41:16.137533+00:00", "data": {"market": "0xdb220d70cc76303505355f558407f99958916364c5612685c804fe1267d0f514", "price_changes": [{"asset_id": "29127800831891156918080289096614999289213121001925429958509112072030245798692", "price": "0.16", "size": "890.11", "side": "BUY", "hash": "99808cd398e768c75b8ef4e0d215362c355ea284", "best_bid": "0.57", "best_ask": "0.97"}, {"asset_id": "89178703372212073978389921580322635269384366327786463025461810229435622804178", "price": "0.84", "size": "890.11", "side": "SELL", "hash": "6b00c4c61b25fcd696dcbf3061db01caf6b35fc2", "best_bid": "0.03", "best_ask": "0.43"}], "timestamp": "1769384475995", "event_type": "price_change"}}
{"_local_timestamp": "2026-01-25T23:41:16.147211+00:00", "data": {"market": "0xdb220d70cc76303505355f558407f99958916364c5612685c804fe1267d0f514", "price_changes": [{"asset_id": "29127800831891156918080289096614999289213121001925429958509112072030245798692", "price": "0.16", "size": "2887.22", "side": "BUY", "hash": "fffb9b3ff8714587ee417350fe277980d48a0b28", "best_bid": "0.57", "best_ask": "0.97"}, {"asset_id": "89178703372212073978389921580322635269384366327786463025461810229435622804178", "price": "0.84", "size": "2887.22", "side": "SELL", "hash": "6f026607d70941c4f6b680fd9059fd746c08619a", "best_bid": "0.03", "best_ask": "0.43"}], "timestamp": "1769384475995", "event_type": "price_change"}}
{"_local_timestamp": "2026-01-25T23:41:16.159338+00:00", "data": {"market": "0xdb220d70cc76303505355f558407f99958916364c5612685c804fe1267d0f514", "price_changes": [{"asset_id": "29127800831891156918080289096614999289213121001925429958509112072030245798692", "price": "0.16", "size": "3777.33", "side": "BUY", "hash": "ffe28aa97f4cfc1e28fae7dc1369644a4e0441b9", "best_bid": "0.57", "best_ask": "0.97"}, {"asset_id": "89178703372212073978389921580322635269384366327786463025461810229435622804178", "price": "0.84", "size": "3777.33", "side": "SELL", "hash": "3f7be637d7db1fb34f1fe94d2251b9c4354a643b", "best_bid": "0.03", "best_ask": "0.43"}], "timestamp": "1769384475996", "event_type": "price_change"}}
{"_local_timestamp": "2026-01-25T23:41:16.172210+00:00", "data": {"market": "0xdb220d70cc76303505355f558407f99958916364c5612685c804fe1267d0f514", "price_changes": [{"asset_id": "29127800831891156918080289096614999289213121001925429958509112072030245798692", "price": "0.16", "size": "5047.43", "side": "BUY", "hash": "11ded4e3dc767d2d14455b67f58cbe3f7753bf11", "best_bid": "0.57", "best_ask": "0.97"}, {"asset_id": "89178703372212073978389921580322635269384366327786463025461810229435622804178", "price": "0.84", "size": "5047.43", "side": "SELL", "hash": "c8816b0bd42753a4d78c474e25740a69a9d751bc", "best_bid": "0.03", "best_ask": "0.43"}], "timestamp": "1769384475997", "event_type": "price_change"}}
{"_local_timestamp": "2026-01-25T23:41:16.783743+00:00", "data": {"market": "0x9b95e4d85d89a2aa406d7bc683e9b8bb8c7d2b16ee3b44878a36d4e79eeb20ec", "asset_id": "63189790407496871968365678866547561936214310417455881808824200627199091231049", "old_tick_size": "0.01", "new_tick_size": "0.001", "timestamp": "1769384476715", "event_type": "tick_size_change"}}
{"_local_timestamp": "2026-01-25T23:41:16.794987+00:00", "data": {"market": "0x9b95e4d85d89a2aa406d7bc683e9b8bb8c7d2b16ee3b44878a36d4e79eeb20ec", "asset_id": "39492360553034885301486766992727683306899599890890066102594783083978384204123", "old_tick_size": "0.01", "new_tick_size": "0.001", "timestamp": "1769384476715", "event_type": "tick_size_change"}}
{"_local_timestamp": "2026-01-25T23:41:16.802641+00:00", "data": {"market": "0x9b95e4d85d89a2aa406d7bc683e9b8bb8c7d2b16ee3b44878a36d4e79eeb20ec", "asset_id": "63189790407496871968365678866547561936214310417455881808824200627199091231049", "old_tick_size": "0.001", "new_tick_size": "0.001", "timestamp": "1769384476715", "event_type": "tick_size_change"}}
{"_local_timestamp": "2026-01-25T23:41:16.812469+00:00", "data": {"market": "0x9b95e4d85d89a2aa406d7bc683e9b8bb8c7d2b16ee3b44878a36d4e79eeb20ec", "asset_id": "39492360553034885301486766992727683306899599890890066102594783083978384204123", "old_tick_size": "0.001", "new_tick_size": "0.001", "timestamp": "1769384476715", "event_type": "tick_size_change"}}
{"_local_timestamp": "2026-01-25T23:41:17.257687+00:00", "data": {"market": "0x67d228115cc6ea9eb2dd85ca443c357359e4bdac7f773d8dff9f599cf5f58074", "price_changes": [{"asset_id": "115673443932214194570164346004924052532408865542451590692735424434267556754094", "price": "0.38", "size": "363", "side": "BUY", "hash": "618d23b0e92c37bc7ca9d6b87b4bed841abd1780", "best_bid": "0.85", "best_ask": "0.87"}, {"asset_id": "40258076975888759603244407127088084693343108694292687330139582591508023070009", "price": "0.62", "size": "363", "side": "SELL", "hash": "14f45efd761a38ac74bf62316e2623ecea9e3690", "best_bid": "0.13", "best_ask": "0.15"}], "timestamp": "1769384477192", "event_type": "price_change"}}
{"_local_timestamp": "2026-01-25T23:41:17.320080+00:00", "data": {"market": "0x67d228115cc6ea9eb2dd85ca443c357359e4bdac7f773d8dff9f599cf5f58074", "price_changes": [{"asset_id": "40258076975888759603244407127088084693343108694292687330139582591508023070009", "price": "0.05", "size": "0", "side": "BUY", "hash": "e3bfc421834340fcd7c254cf001a40efd6f95b04", "best_bid": "0.13", "best_ask": "0.15"}, {"asset_id": "115673443932214194570164346004924052532408865542451590692735424434267556754094", "price": "0.95", "size": "0", "side": "SELL", "hash": "ced63b24b14865790b0c0646bf0f980cb90b75b7", "best_bid": "0.85", "best_ask": "0.87"}], "timestamp": "1769384477249", "event_type": "price_change"}}
{"_local_timestamp": "2026-01-25T23:41:17.384325+00:00", "data": {"market": "0x67d228115cc6ea9eb2dd85ca443c357359e4bdac7f773d8dff9f599cf5f58074", "price_changes": [{"asset_id": "40258076975888759603244407127088084693343108694292687330139582591508023070009", "price": "0.01", "size": "3400.21", "side": "BUY", "hash": "0d96f4eba08e29b75f53ef4cbaf664cdd5db6e56", "best_bid": "0.13", "best_ask": "0.15"}, {"asset_id": "115673443932214194570164346004924052532408865542451590692735424434267556754094", "price": "0.99", "size": "3400.21", "side": "SELL", "hash": "4f611b9e1c8a9f5e906f088b661b039db9776b9a", "best_bid": "0.85", "best_ask": "0.87"}], "timestamp": "1769384477311", "event_type": "price_change"}}
{"_local_timestamp": "2026-01-25T23:41:17.402609+00:00", "data": {"market": "0x67d228115cc6ea9eb2dd85ca443c357359e4bdac7f773d8dff9f599cf5f58074", "price_changes": [{"asset_id": "40258076975888759603244407127088084693343108694292687330139582591508023070009", "price": "0.07", "size": "890.11", "side": "BUY", "hash": "59611e6ff088348abe1ed510f61dea56e619048e", "best_bid": "0.13", "best_ask": "0.15"}, {"asset_id": "115673443932214194570164346004924052532408865542451590692735424434267556754094", "price": "0.93", "size": "890.11", "side": "SELL", "hash": "88c224d773176284d81c7826779a6ee962a44a58", "best_bid": "0.85", "best_ask": "0.87"}], "timestamp": "1769384477311", "event_type": "price_change"}}
{"_local_timestamp": "2026-01-25T23:41:17.625994+00:00", "data": {"market": "0x9b95e4d85d89a2aa406d7bc683e9b8bb8c7d2b16ee3b44878a36d4e79eeb20ec", "price_changes": [{"asset_id": "39492360553034885301486766992727683306899599890890066102594783083978384204123", "price": "0.02", "size": "1318.42", "side": "BUY", "hash": "c36db4247c622e9a437c52f8a77dc12514dff14a", "best_bid": "0.03", "best_ask": "0.06"}, {"asset_id": "63189790407496871968365678866547561936214310417455881808824200627199091231049", "price": "0.98", "size": "1318.42", "side": "SELL", "hash": "b717d43849aa61f2cf2d1ce4aff62d2c4840d886", "best_bid": "0.94", "best_ask": "0.97"}], "timestamp": "1769384477557", "event_type": "price_change"}}
{"_local_timestamp": "2026-01-25T23:41:17.633084+00:00", "data": {"market": "0x9b95e4d85d89a2aa406d7bc683e9b8bb8c7d2b16ee3b44878a36d4e79eeb20ec", "price_changes": [{"asset_id": "39492360553034885301486766992727683306899599890890066102594783083978384204123", "price": "0.03", "size": "5.84", "side": "BUY", "hash": "c36db4247c622e9a437c52f8a77dc12514dff14a", "best_bid": "0.03", "best_ask": "0.06"}, {"asset_id": "63189790407496871968365678866547561936214310417455881808824200627199091231049", "price": "0.97", "size": "5.84", "side": "SELL", "hash": "b717d43849aa61f2cf2d1ce4aff62d2c4840d886", "best_bid": "0.94", "best_ask": "0.97"}], "timestamp": "1769384477557", "event_type": "price_change"}}
{"_local_timestamp": "2026-01-25T23:41:17.894594+00:00", "data": {"market": "0x9b95e4d85d89a2aa406d7bc683e9b8bb8c7d2b16ee3b44878a36d4e79eeb20ec", "price_changes": [{"asset_id": "39492360553034885301486766992727683306899599890890066102594783083978384204123", "price": "0.021", "size": "890.11", "side": "BUY", "hash": "61205d6503d72ecb8aa1e37d44d682d2bbb4b78b", "best_bid": "0.03", "best_ask": "0.06"}, {"asset_id": "63189790407496871968365678866547561936214310417455881808824200627199091231049", "price": "0.979", "size": "890.11", "side": "SELL", "hash": "3949f71fbaf6b00cedc96aa125235566dc2ecb08", "best_bid": "0.94", "best_ask": "0.97"}], "timestamp": "1769384477771", "event_type": "price_change"}}
{"_local_timestamp": "2026-01-25T23:41:17.903219+00:00", "data": {"market": "0x9b95e4d85d89a2aa406d7bc683e9b8bb8c7d2b16ee3b44878a36d4e79eeb20ec", "price_changes": [{"asset_id": "63189790407496871968365678866547561936214310417455881808824200627199091231049", "price": "0.691", "size": "890.11", "side": "BUY", "hash": "0e55f41b83412fc27f876b1e0c509022854b574d", "best_bid": "0.94", "best_ask": "0.97"}, {"asset_id": "39492360553034885301486766992727683306899599890890066102594783083978384204123", "price": "0.309", "size": "890.11", "side": "SELL", "hash": "1c1979cce6652d195162f9f7342659b66d589c14", "best_bid": "0.03", "best_ask": "0.06"}], "timestamp": "1769384477772", "event_type": "price_change"}}
{"_local_timestamp": "2026-01-25T23:41:17.909729+00:00", "data": {"market": "0x9b95e4d85d89a2aa406d7bc683e9b8bb8c7d2b16ee3b44878a36d4e79eeb20ec", "price_changes": [{"asset_id": "63189790407496871968365678866547561936214310417455881808824200627199091231049", "price": "0.701", "size": "1270.1", "side": "BUY", "hash": "981203be6bb8474ae31a6a2cb7aae3428038fdc1", "best_bid": "0.94", "best_ask": "0.97"}, {"asset_id": "39492360553034885301486766992727683306899599890890066102594783083978384204123", "price": "0.299", "size": "1270.1", "side": "SELL", "hash": "b3380644dd76c81233cfecb6bd6f05d2ceea7da6", "best_bid": "0.03", "best_ask": "0.06"}], "timestamp": "1769384477772", "event_type": "price_change"}}
{"_local_timestamp": "2026-01-25T23:41:17.917313+00:00", "data": {"market": "0x9b95e4d85d89a2aa406d7bc683e9b8bb8c7d2b16ee3b44878a36d4e79eeb20ec", "price_changes": [{"asset_id": "63189790407496871968365678866547561936214310417455881808824200627199091231049", "price": "0.701", "size": "2160.21", "side": "BUY", "hash": "af4ab1a255f3c9f66f2267d1888036d806411b0f", "best_bid": "0.94", "best_ask": "0.97"}, {"asset_id": "39492360553034885301486766992727683306899599890890066102594783083978384204123", "price": "0.299", "size": "2160.21", "side": "SELL", "hash": "f74875910452f864029a922b39dd20bc6c08c70c", "best_bid": "0.03", "best_ask": "0.06"}], "timestamp": "1769384477773", "event_type": "price_change"}}
{"_local_timestamp": "2026-01-25T23:41:17.924453+00:00", "data": {"market": "0x9b95e4d85d89a2aa406d7bc683e9b8bb8c7d2b16ee3b44878a36d4e79eeb20ec", "price_changes": [{"asset_id": "63189790407496871968365678866547561936214310417455881808824200627199091231049", "price": "0.701", "size": "3050.32", "side": "BUY", "hash": "95905bd1fbdaec3210714aaa3c65266f17f66cbd", "best_bid": "0.94", "best_ask": "0.97"}, {"asset_id": "39492360553034885301486766992727683306899599890890066102594783083978384204123", "price": "0.299", "size": "3050.32", "side": "SELL", "hash": "2ff9dfb30dae3ad6dadfb8ded6a24af0db4ef5af", "best_bid": "0.03", "best_ask": "0.06"}], "timestamp": "1769384477774", "event_type": "price_change"}}
{"_local_timestamp": "2026-01-25T23:41:17.932915+00:00", "data": {"market": "0x9b95e4d85d89a2aa406d7bc683e9b8bb8c7d2b16ee3b44878a36d4e79eeb20ec", "price_changes": [{"asset_id": "39492360553034885301486766992727683306899599890890066102594783083978384204123", "price": "0.011", "size": "890.11", "side": "BUY", "hash": "af07a35adda6f3bab57529ae62be97f81cf0f5e6", "best_bid": "0.03", "best_ask": "0.06"}, {"asset_id": "63189790407496871968365678866547561936214310417455881808824200627199091231049", "price": "0.989", "size": "890.11", "side": "SELL", "hash": "bccc09c758d1948ba97b239de79ee77680331e13", "best_bid": "0.94", "best_ask": "0.97"}], "timestamp": "1769384477775", "event_type": "price_change"}}
{"_local_timestamp": "2026-01-25T23:41:17.940270+00:00", "data": {"market": "0x9b95e4d85d89a2aa406d7bc683e9b8bb8c7d2b16ee3b44878a36d4e79eeb20ec", "price_changes": [{"asset_id": "63189790407496871968365678866547561936214310417455881808824200627199091231049", "price": "0.701", "size": "5047.43", "side": "BUY", "hash": "b06acdb6b54102de997fde07e02fefffdf51b875", "best_bid": "0.94", "best_ask": "0.97"}, {"asset_id": "39492360553034885301486766992727683306899599890890066102594783083978384204123", "price": "0.299", "size": "5047.43", "side": "SELL", "hash": "c2fcb5f5d2b3defcb9341e766a10309b1de6a451", "best_bid": "0.03", "best_ask": "0.06"}], "timestamp": "1769384477775", "event_type": "price_change"}}
{"_local_timestamp": "2026-01-25T23:41:17.950026+00:00", "data": {"market": "0x9b95e4d85d89a2aa406d7bc683e9b8bb8c7d2b16ee3b44878a36d4e79eeb20ec", "price_changes": [{"asset_id": "63189790407496871968365678866547561936214310417455881808824200627199091231049", "price": "0.001", "size": "5999.11", "side": "BUY", "hash": "b931324e9d30e58a3504977cc6865187c8100bf8", "best_bid": "0.94", "best_ask": "0.97"}, {"asset_id": "39492360553034885301486766992727683306899599890890066102594783083978384204123", "price": "0.999", "size": "5999.11", "side": "SELL", "hash": "a02455f0a959bde8520bbdb99bc601ae2b540c70", "best_bid": "0.03", "best_ask": "0.06"}], "timestamp": "1769384477776", "event_type": "price_change"}}
{"_local_timestamp": "2026-01-25T23:41:18.105530+00:00", "data": {"market": "0x9b95e4d85d89a2aa406d7bc683e9b8bb8c7d2b16ee3b44878a36d4e79eeb20ec", "price_changes": [{"asset_id": "39492360553034885301486766992727683306899599890890066102594783083978384204123", "price": "0.011", "size": "900.59", "side": "BUY", "hash": "a7c5de153b96e91818d1de9700af446fcc7748c7", "best_bid": "0.03", "best_ask": "0.06"}, {"asset_id": "63189790407496871968365678866547561936214310417455881808824200627199091231049", "price": "0.989", "size": "900.59", "side": "SELL", "hash": "50515721c1583304f67ce50029e6f077630aed9e", "best_bid": "0.94", "best_ask": "0.97"}], "timestamp": "1769384477980", "event_type": "price_change"}}
{"_local_timestamp": "2026-01-25T23:41:18.113628+00:00", "data": {"market": "0x9b95e4d85d89a2aa406d7bc683e9b8bb8c7d2b16ee3b44878a36d4e79eeb20ec", "price_changes": [{"asset_id": "39492360553034885301486766992727683306899599890890066102594783083978384204123", "price": "0.021", "size": "895.83", "side": "BUY", "hash": "5c052956e588f7e086c3aeadfe166f2effd40800", "best_bid": "0.03", "best_ask": "0.06"}, {"asset_id": "63189790407496871968365678866547561936214310417455881808824200627199091231049", "price": "0.979", "size": "895.83", "side": "SELL", "hash": "de07b2aae16a57f3ae0739e8f47a6df9c8da918d", "best_bid": "0.94", "best_ask": "0.97"}], "timestamp": "1769384477983", "event_type": "price_change"}}
{"_local_timestamp": "2026-01-25T23:41:18.120177+00:00", "data": {"market": "0x9b95e4d85d89a2aa406d7bc683e9b8bb8c7d2b16ee3b44878a36d4e79eeb20ec", "price_changes": [{"asset_id": "39492360553034885301486766992727683306899599890890066102594783083978384204123", "price": "0.001", "size": "14.55", "side": "BUY", "hash": "830dd52b9e13bae8f400a4bde661ff15a3d54ec4", "best_bid": "0.03", "best_ask": "0.06"}, {"asset_id": "63189790407496871968365678866547561936214310417455881808824200627199091231049", "price": "0.999", "size": "14.55", "side": "SELL", "hash": "cf3d4c4fb0644471375ca298c5e5339216f9122f", "best_bid": "0.94", "best_ask": "0.97"}], "timestamp": "1769384477987", "event_type": "price_change"}}
{"_local_timestamp": "2026-01-25T23:41:18.126559+00:00", "data": {"market": "0x9b95e4d85d89a2aa406d7bc683e9b8bb8c7d2b16ee3b44878a36d4e79eeb20ec", "price_changes": [{"asset_id": "39492360553034885301486766992727683306899599890890066102594783083978384204123", "price": "0.011", "size": "911.07", "side": "BUY", "hash": "1bb19f1aa172833df77d7e3f514d2846f75eaac7", "best_bid": "0.03", "best_ask": "0.06"}, {"asset_id": "63189790407496871968365678866547561936214310417455881808824200627199091231049", "price": "0.989", "size": "911.07", "side": "SELL", "hash": "6fed33bf3779fb2a018385156e1d09ca3ef9d67f", "best_bid": "0.94", "best_ask": "0.97"}], "timestamp": "1769384477990", "event_type": "price_change"}}
{"_local_timestamp": "2026-01-25T23:41:18.132946+00:00", "data": {"market": "0x9b95e4d85d89a2aa406d7bc683e9b8bb8c7d2b16ee3b44878a36d4e79eeb20ec", "price_changes": [{"asset_id": "39492360553034885301486766992727683306899599890890066102594783083978384204123", "price": "0.001", "size": "29.1", "side": "BUY", "hash": "73a1167f85900e1ee9a9342517f03d633348edf2", "best_bid": "0.03", "best_ask": "0.06"}, {"asset_id": "63189790407496871968365678866547561936214310417455881808824200627199091231049", "price": "0.999", "size": "29.1", "side": "SELL", "hash": "75187d541dc316ecda0ef0f50b2566544c8ff8c7", "best_bid": "0.94", "best_ask": "0.97"}], "timestamp": "1769384477993", "event_type": "price_change"}}
{"_local_timestamp": "2026-01-25T23:41:18.139386+00:00", "data": {"market": "0x9b95e4d85d89a2aa406d7bc683e9b8bb8c7d2b16ee3b44878a36d4e79eeb20ec", "price_changes": [{"asset_id": "39492360553034885301486766992727683306899599890890066102594783083978384204123", "price": "0.021", "size": "901.55", "side": "BUY", "hash": "4f19111f050979478a21e5f6a2e01721ccaa7316", "best_bid": "0.03", "best_ask": "0.06"}, {"asset_id": "63189790407496871968365678866547561936214310417455881808824200627199091231049", "price": "0.979", "size": "901.55", "side": "SELL", "hash": "082497c41fa4c13457a8ea136b323fed0eb07bbf", "best_bid": "0.94", "best_ask": "0.97"}], "timestamp": "1769384477998", "event_type": "price_change"}}
{"_local_timestamp": "2026-01-25T23:41:19.666033+00:00", "data": {"market": "0x67d228115cc6ea9eb2dd85ca443c357359e4bdac7f773d8dff9f599cf5f58074", "price_changes": [{"asset_id": "40258076975888759603244407127088084693343108694292687330139582591508023070009", "price": "0.02", "size": "21.09", "side": "BUY", "hash": "9d838f77ab1b70616a7313fcf9eacee9b04ca29b", "best_bid": "0.13", "best_ask": "0.15"}, {"asset_id": "115673443932214194570164346004924052532408865542451590692735424434267556754094", "price": "0.98", "size": "21.09", "side": "SELL", "hash": "901337066695515e79074f15fed5f8a5f2c94d23", "best_bid": "0.85", "best_ask": "0.87"}], "timestamp": "1769384479597", "event_type": "price_change"}}
{"_local_timestamp": "2026-01-25T23:41:20.020661+00:00", "data": {"market": "0x67d228115cc6ea9eb2dd85ca443c357359e4bdac7f773d8dff9f599cf5f58074", "price_changes": [{"asset_id": "40258076975888759603244407127088084693343108694292687330139582591508023070009", "price": "0.07", "size": "898.37", "side": "BUY", "hash": "62ffc5808204c2534d627122bcc383df3328c0d1", "best_bid": "0.13", "best_ask": "0.15"}, {"asset_id": "115673443932214194570164346004924052532408865542451590692735424434267556754094", "price": "0.93", "size": "898.37", "side": "SELL", "hash": "862042756b219758bd8f293957fa4a0348904341", "best_bid": "0.85", "best_ask": "0.87"}], "timestamp": "1769384479948", "event_type": "price_change"}}
{"_local_timestamp": "2026-01-25T23:41:20.071071+00:00", "data": {"market": "0xdb220d70cc76303505355f558407f99958916364c5612685c804fe1267d0f514", "price_changes": [{"asset_id": "29127800831891156918080289096614999289213121001925429958509112072030245798692", "price": "0.15", "size": "890.11", "side": "BUY", "hash": "e21b8eb9cb8a0d89552173aba46b75f2b745e526", "best_bid": "0.57", "best_ask": "0.97"}, {"asset_id": "89178703372212073978389921580322635269384366327786463025461810229435622804178", "price": "0.85", "size": "890.11", "side": "SELL", "hash": "19ea72e053556b58a51fdea18012c8a7a49bd015", "best_bid": "0.03", "best_ask": "0.43"}], "timestamp": "1769384480000", "event_type": "price_change"}}
{"_local_timestamp": "2026-01-25T23:41:20.079539+00:00", "data": {"market": "0x67d228115cc6ea9eb2dd85ca443c357359e4bdac7f773d8dff9f599cf5f58074", "price_changes": [{"asset_id": "40258076975888759603244407127088084693343108694292687330139582591508023070009", "price": "0.06", "size": "0", "side": "BUY", "hash": "d161bbfca2e0402d666e7c772c0f295e5d63c253", "best_bid": "0.13", "best_ask": "0.15"}, {"asset_id": "115673443932214194570164346004924052532408865542451590692735424434267556754094", "price": "0.94", "size": "0", "side": "SELL", "hash": "58356d2bc2b4af279b999be994721d56b67dc2ee", "best_bid": "0.85", "best_ask": "0.87"}], "timestamp": "1769384480000", "event_type": "price_change"}}
{"_local_timestamp": "2026-01-25T23:41:20.091871+00:00", "data": {"market": "0x9b95e4d85d89a2aa406d7bc683e9b8bb8c7d2b16ee3b44878a36d4e79eeb20ec", "price_changes": [{"asset_id": "63189790407496871968365678866547561936214310417455881808824200627199091231049", "price": "0.39", "size": "0", "side": "BUY", "hash": "b834a68b68a2e8dcff1e211e895a3ce0f5162172", "best_bid": "0.94", "best_ask": "0.97"}, {"asset_id": "39492360553034885301486766992727683306899599890890066102594783083978384204123", "price": "0.61", "size": "0", "side": "SELL", "hash": "7923fc3a12829e70e714967f6b6241071d9bf701", "best_bid": "0.03", "best_ask": "0.06"}], "timestamp": "1769384480001", "event_type": "price_change"}}
{"_local_timestamp": "2026-01-25T23:41:20.107493+00:00", "data": {"market": "0xfa0a910c4380fc83610d9fa68b214b598621ae9bd49dc40df47abd265bf0bc34", "price_changes": [{"asset_id": "42996585481877433482708272870977066259130153781685558286992961170000063507609", "price": "0.02", "size": "0", "side": "BUY", "hash": "7ffa8ae6febf1fcc6980a672b4a52475b001b49c", "best_bid": "0.58", "best_ask": "0.94"}, {"asset_id": "59290556380981220753832906409296194214356850812489293134106523641703938483612", "price": "0.98", "size": "0", "side": "SELL", "hash": "070b6fb1cfd46a6d3c42c3eb6bc2d4bd79c7cc45", "best_bid": "0.06", "best_ask": "0.42"}], "timestamp": "1769384480000", "event_type": "price_change"}}
{"_local_timestamp": "2026-01-25T23:41:20.114210+00:00", "data": {"market": "0x425351f3d4713b9db2c15a80e1e75a2acf893b5495cc2e694095070137509329", "price_changes": [{"asset_id": "56846561876839441818327131212801941885992894700201726352426446447037474872043", "price": "0.34", "size": "100", "side": "BUY", "hash": "ed740e04b56b9eacb6b2ebd77f68da8008b7393e", "best_bid": "0.99", "best_ask": "0.999"}, {"asset_id": "57829021360688395873888125190016504630905168321624137961276880640915115712545", "price": "0.66", "size": "100", "side": "SELL", "hash": "66ac13de2a18b4a37293e8c7557ae49f0b160a5f", "best_bid": "0.001", "best_ask": "0.01"}], "timestamp": "1769384480000", "event_type": "price_change"}}
{"_local_timestamp": "2026-01-25T23:41:20.122281+00:00", "data": {"market": "0xdb220d70cc76303505355f558407f99958916364c5612685c804fe1267d0f514", "price_changes": [{"asset_id": "89178703372212073978389921580322635269384366327786463025461810229435622804178", "price": "0.02", "size": "22.18", "side": "BUY", "hash": "82798f43878399632dfe51b7114ce5430f5a35bb", "best_bid": "0.03", "best_ask": "0.43"}, {"asset_id": "29127800831891156918080289096614999289213121001925429958509112072030245798692", "price": "0.98", "size": "22.18", "side": "SELL", "hash": "77f70f1a15845d5c78788546ef29f490980b9e55", "best_bid": "0.57", "best_ask": "0.97"}], "timestamp": "1769384480002", "event_type": "price_change"}}
{"_local_timestamp": "2026-01-25T23:41:20.131475+00:00", "data": {"market": "0x67d228115cc6ea9eb2dd85ca443c357359e4bdac7f773d8dff9f599cf5f58074", "price_changes": [{"asset_id": "115673443932214194570164346004924052532408865542451590692735424434267556754094", "price": "0.38", "size": "100", "side": "BUY", "hash": "8a73cfb37c0fe588bc80dc024db04370c16c7d19", "best_bid": "0.85", "best_ask": "0.87"}, {"asset_id": "40258076975888759603244407127088084693343108694292687330139582591508023070009", "price": "0.62", "size": "100", "side": "SELL", "hash": "b3d6dba9263741909148ef6bcd8726cf810772f2", "best_bid": "0.13", "best_ask": "0.15"}], "timestamp": "1769384480001", "event_type": "price_change"}}
{"_local_timestamp": "2026-01-25T23:41:20.146674+00:00", "data": {"market": "0xdb220d70cc76303505355f558407f99958916364c5612685c804fe1267d0f514", "price_changes": [{"asset_id": "29127800831891156918080289096614999289213121001925429958509112072030245798692", "price": "0.14", "size": "0", "side": "BUY", "hash": "fbb9bbec739891270e0e22e3d088d35a77fdf674", "best_bid": "0.57", "best_ask": "0.97"}, {"asset_id": "89178703372212073978389921580322635269384366327786463025461810229435622804178", "price": "0.86", "size": "0", "side": "SELL", "hash": "b4bab739436b89dd86bf6edf265fa9e71570fb8d", "best_bid": "0.03", "best_ask": "0.43"}], "timestamp": "1769384480052", "event_type": "price_change"}}
{"_local_timestamp": "2026-01-25T23:41:20.156835+00:00", "data": {"market": "0xdb220d70cc76303505355f558407f99958916364c5612685c804fe1267d0f514", "price_changes": [{"asset_id": "29127800831891156918080289096614999289213121001925429958509112072030245798692", "price": "0.13", "size": "0", "side": "BUY", "hash": "fbb9bbec739891270e0e22e3d088d35a77fdf674", "best_bid": "0.57", "best_ask": "0.97"}, {"asset_id": "89178703372212073978389921580322635269384366327786463025461810229435622804178", "price": "0.87", "size": "0", "side": "SELL", "hash": "b4bab739436b89dd86bf6edf265fa9e71570fb8d", "best_bid": "0.03", "best_ask": "0.43"}], "timestamp": "1769384480052", "event_type": "price_change"}}
{"_local_timestamp": "2026-01-25T23:41:20.313562+00:00", "data": {"market": "0xdb220d70cc76303505355f558407f99958916364c5612685c804fe1267d0f514", "price_changes": [{"asset_id": "29127800831891156918080289096614999289213121001925429958509112072030245798692", "price": "0.15", "size": "1780.22", "side": "BUY", "hash": "dc8f974e18b00f9f90d039369ec0bb1245ae856f", "best_bid": "0.57", "best_ask": "0.97"}, {"asset_id": "89178703372212073978389921580322635269384366327786463025461810229435622804178", "price": "0.85", "size": "1780.22", "side": "SELL", "hash": "9f89573f008a4337c0d4e51103ce3760f3e4759f", "best_bid": "0.03", "best_ask": "0.43"}], "timestamp": "1769384480227", "event_type": "price_change"}}
{"_local_timestamp": "2026-01-25T23:41:20.325162+00:00", "data": {"market": "0xdb220d70cc76303505355f558407f99958916364c5612685c804fe1267d0f514", "price_changes": [{"asset_id": "29127800831891156918080289096614999289213121001925429958509112072030245798692", "price": "0.15", "size": "3777.33", "side": "BUY", "hash": "3416f2a6e6ba93c58201a07cde0eaa5d8acc4410", "best_bid": "0.57", "best_ask": "0.97"}, {"asset_id": "89178703372212073978389921580322635269384366327786463025461810229435622804178", "price": "0.85", "size": "3777.33", "side": "SELL", "hash": "2b14a7d3f7e0b00f6869906014ff6bc19200be1c", "best_bid": "0.03", "best_ask": "0.43"}], "timestamp": "1769384480228", "event_type": "price_change"}}
{"_local_timestamp": "2026-01-25T23:41:20.333146+00:00", "data": {"market": "0xdb220d70cc76303505355f558407f99958916364c5612685c804fe1267d0f514", "price_changes": [{"asset_id": "29127800831891156918080289096614999289213121001925429958509112072030245798692", "price": "0.15", "size": "5047.43", "side": "BUY", "hash": "7ac6c822fc229ef372df68a938e714c238fb4eab", "best_bid": "0.57", "best_ask": "0.97"}, {"asset_id": "89178703372212073978389921580322635269384366327786463025461810229435622804178", "price": "0.85", "size": "5047.43", "side": "SELL", "hash": "e336deec71b6ddcc7e81f055eceb01987b5c820e", "best_bid": "0.03", "best_ask": "0.43"}], "timestamp": "1769384480229", "event_type": "price_change"}}
{"_local_timestamp": "2026-01-25T23:41:20.340730+00:00", "data": {"market": "0xdb220d70cc76303505355f558407f99958916364c5612685c804fe1267d0f514", "price_changes": [{"asset_id": "29127800831891156918080289096614999289213121001925429958509112072030245798692", "price": "0.15", "size": "11046.54", "side": "BUY", "hash": "221dcf4b3aa946f8f0f06b62ed6f4c1d51057dc5", "best_bid": "0.57", "best_ask": "0.97"}, {"asset_id": "89178703372212073978389921580322635269384366327786463025461810229435622804178", "price": "0.85", "size": "11046.54", "side": "SELL", "hash": "8f1e925da8a20a563f95d8be7213cab40729d80f", "best_bid": "0.03", "best_ask": "0.43"}], "timestamp": "1769384480229", "event_type": "price_change"}}
{"_local_timestamp": "2026-01-25T23:41:20.350592+00:00", "data": {"market": "0xdb220d70cc76303505355f558407f99958916364c5612685c804fe1267d0f514", "price_changes": [{"asset_id": "29127800831891156918080289096614999289213121001925429958509112072030245798692", "price": "0.14", "size": "890.11", "side": "BUY", "hash": "a18b895b4632f594fd1746bdb3634908094c11ec", "best_bid": "0.57", "best_ask": "0.97"}, {"asset_id": "89178703372212073978389921580322635269384366327786463025461810229435622804178", "price": "0.86", "size": "890.11", "side": "SELL", "hash": "73c184390384a2d1d40ca037e89864c6aa2725d0", "best_bid": "0.03", "best_ask": "0.43"}], "timestamp": "1769384480230", "event_type": "price_change"}}
{"_local_timestamp": "2026-01-25T23:41:21.304142+00:00", "data": {"market": "0xdb220d70cc76303505355f558407f99958916364c5612685c804fe1267d0f514", "price_changes": [{"asset_id": "29127800831891156918080289096614999289213121001925429958509112072030245798692", "price": "0.17", "size": "588", "side": "BUY", "hash": "4679c5517279769aa26bba0759d35e1a904046db", "best_bid": "0.57", "best_ask": "0.97"}, {"asset_id": "89178703372212073978389921580322635269384366327786463025461810229435622804178", "price": "0.83", "size": "588", "side": "SELL", "hash": "63ac018bf9f1c137714ee2dc75bfc32139ced811", "best_bid": "0.03", "best_ask": "0.43"}], "timestamp": "1769384481213", "event_type": "price_change"}}
{"_local_timestamp": "2026-01-25T23:41:21.332012+00:00", "data": {"market": "0x67d228115cc6ea9eb2dd85ca443c357359e4bdac7f773d8dff9f599cf5f58074", "price_changes": [{"asset_id": "40258076975888759603244407127088084693343108694292687330139582591508023070009", "price": "0.02", "size": "5021.09", "side": "BUY", "hash": "067a86c215dad0b310402af9bebda0cde31c589f", "best_bid": "0.13", "best_ask": "0.15"}, {"asset_id": "115673443932214194570164346004924052532408865542451590692735424434267556754094", "price": "0.98", "size": "5021.09", "side": "SELL", "hash": "be788d0a10e0ed7dcfefb7336beb35fcdd7973b4", "best_bid": "0.85", "best_ask": "0.87"}], "timestamp": "1769384481213", "event_type": "price_change"}}
{"_local_timestamp": "2026-01-25T23:41:21.343366+00:00", "data": {"market": "0xfa0a910c4380fc83610d9fa68b214b598621ae9bd49dc40df47abd265bf0bc34", "price_changes": [{"asset_id": "42996585481877433482708272870977066259130153781685558286992961170000063507609", "price": "0.02", "size": "5000", "side": "BUY", "hash": "482ca6b5d4c78206b393def0dd88319b0b53340f", "best_bid": "0.58", "best_ask": "0.94"}, {"asset_id": "59290556380981220753832906409296194214356850812489293134106523641703938483612", "price": "0.98", "size": "5000", "side": "SELL", "hash": "76949dcce2711bccea49dfc5a6459b6f9ff6db86", "best_bid": "0.06", "best_ask": "0.42"}], "timestamp": "1769384481213", "event_type": "price_change"}}
{"_local_timestamp": "2026-01-25T23:41:21.349782+00:00", "data": {"market": "0x9b95e4d85d89a2aa406d7bc683e9b8bb8c7d2b16ee3b44878a36d4e79eeb20ec", "price_changes": [{"asset_id": "63189790407496871968365678866547561936214310417455881808824200627199091231049", "price": "0.38", "size": "292", "side": "BUY", "hash": "b66947bde9c15c0f9dfe9e1490b2fd587aa03342", "best_bid": "0.94", "best_ask": "0.97"}, {"asset_id": "39492360553034885301486766992727683306899599890890066102594783083978384204123", "price": "0.62", "size": "292", "side": "SELL", "hash": "db07080416d3a5d4a70ba3f6fea024e08bac6ba8", "best_bid": "0.03", "best_ask": "0.06"}], "timestamp": "1769384481213", "event_type": "price_change"}}
{"_local_timestamp": "2026-01-25T23:41:21.356123+00:00", "data": {"market": "0x67d228115cc6ea9eb2dd85ca443c357359e4bdac7f773d8dff9f599cf5f58074", "price_changes": [{"asset_id": "115673443932214194570164346004924052532408865542451590692735424434267556754094", "price": "0.39", "size": "256", "side": "BUY", "hash": "6e0db584fdfc67fb1284953ebbd48f34556b1f27", "best_bid": "0.85", "best_ask": "0.87"}, {"asset_id": "40258076975888759603244407127088084693343108694292687330139582591508023070009", "price": "0.61", "size": "256", "side": "SELL", "hash": "02ce8abe028c9e5c066d89267db1e036cc909c54", "best_bid": "0.13", "best_ask": "0.15"}], "timestamp": "1769384481214", "event_type": "price_change"}}
{"_local_timestamp": "2026-01-25T23:41:21.362566+00:00", "data": {"market": "0x9b95e4d85d89a2aa406d7bc683e9b8bb8c7d2b16ee3b44878a36d4e79eeb20ec", "price_changes": [{"asset_id": "39492360553034885301486766992727683306899599890890066102594783083978384204123", "price": "0.02", "size": "428.31", "side": "BUY", "hash": "888294109cc72c564ef7547f0d346753ffcc9a11", "best_bid": "0.03", "best_ask": "0.06"}, {"asset_id": "63189790407496871968365678866547561936214310417455881808824200627199091231049", "price": "0.98", "size": "428.31", "side": "SELL", "hash": "277e123747fbfe23e3b0a1195dabc381bdff69d3", "best_bid": "0.94", "best_ask": "0.97"}], "timestamp": "1769384481281", "event_type": "price_change"}}
{"_local_timestamp": "2026-01-25T23:41:21.374138+00:00", "data": {"market": "0x9b95e4d85d89a2aa406d7bc683e9b8bb8c7d2b16ee3b44878a36d4e79eeb20ec", "price_changes": [{"asset_id": "39492360553034885301486766992727683306899599890890066102594783083978384204123", "price": "0.01", "size": "1744", "side": "BUY", "hash": "888294109cc72c564ef7547f0d346753ffcc9a11", "best_bid": "0.03", "best_ask": "0.06"}, {"asset_id": "63189790407496871968365678866547561936214310417455881808824200627199091231049", "price": "0.99", "size": "1744", "side": "SELL", "hash": "277e123747fbfe23e3b0a1195dabc381bdff69d3", "best_bid": "0.94", "best_ask": "0.97"}], "timestamp": "1769384481281", "event_type": "price_change"}}
{"_local_timestamp": "2026-01-25T23:41:21.383240+00:00", "data": {"market": "0x9b95e4d85d89a2aa406d7bc683e9b8bb8c7d2b16ee3b44878a36d4e79eeb20ec", "price_changes": [{"asset_id": "63189790407496871968365678866547561936214310417455881808824200627199091231049", "price": "0.71", "size": "10", "side": "BUY", "hash": "9f92def472a529bb5747a953207471d074dee74f", "best_bid": "0.94", "best_ask": "0.97"}, {"asset_id": "39492360553034885301486766992727683306899599890890066102594783083978384204123", "price": "0.29", "size": "10", "side": "SELL", "hash": "b630350e9a99371955ef550c820124a32c1ff2b9", "best_bid": "0.03", "best_ask": "0.06"}], "timestamp": "1769384481281", "event_type": "price_change"}}
{"_local_timestamp": "2026-01-25T23:41:21.389865+00:00", "data": {"market": "0x9b95e4d85d89a2aa406d7bc683e9b8bb8c7d2b16ee3b44878a36d4e79eeb20ec", "price_changes": [{"asset_id": "63189790407496871968365678866547561936214310417455881808824200627199091231049", "price": "0.7", "size": "1786.82", "side": "BUY", "hash": "9f92def472a529bb5747a953207471d074dee74f", "best_bid": "0.94", "best_ask": "0.97"}, {"asset_id": "39492360553034885301486766992727683306899599890890066102594783083978384204123", "price": "0.3", "size": "1786.82", "side": "SELL", "hash": "b630350e9a99371955ef550c820124a32c1ff2b9", "best_bid": "0.03", "best_ask": "0.06"}], "timestamp": "1769384481281", "event_type": "price_change"}}
{"_local_timestamp": "2026-01-25T23:41:21.398833+00:00", "data": {"market": "0x9b95e4d85d89a2aa406d7bc683e9b8bb8c7d2b16ee3b44878a36d4e79eeb20ec", "price_changes": [{"asset_id": "63189790407496871968365678866547561936214310417455881808824200627199091231049", "price": "0.01", "size": "3747.77", "side": "BUY", "hash": "9f92def472a529bb5747a953207471d074dee74f", "best_bid": "0.94", "best_ask": "0.97"}, {"asset_id": "39492360553034885301486766992727683306899599890890066102594783083978384204123", "price": "0.99", "size": "3747.77", "side": "SELL", "hash": "b630350e9a99371955ef550c820124a32c1ff2b9", "best_bid": "0.03", "best_ask": "0.06"}], "timestamp": "1769384481281", "event_type": "price_change"}}
{"_local_timestamp": "2026-01-25T23:41:21.409864+00:00", "data": {"market": "0x67d228115cc6ea9eb2dd85ca443c357359e4bdac7f773d8dff9f599cf5f58074", "price_changes": [{"asset_id": "40258076975888759603244407127088084693343108694292687330139582591508023070009", "price": "0.03", "size": "1997.11", "side": "BUY", "hash": "c053e617bdf999ab0c4513aa51880387b242b4c2", "best_bid": "0.13", "best_ask": "0.15"}, {"asset_id": "115673443932214194570164346004924052532408865542451590692735424434267556754094", "price": "0.97", "size": "1997.11", "side": "SELL", "hash": "bf13a3459b2c591a8370aaa6f14f85f2510a8769", "best_bid": "0.85", "best_ask": "0.87"}], "timestamp": "1769384481336", "event_type": "price_change"}}
{"_local_timestamp": "2026-01-25T23:41:21.417244+00:00", "data": {"market": "0x9b95e4d85d89a2aa406d7bc683e9b8bb8c7d2b16ee3b44878a36d4e79eeb20ec", "price_changes": [{"asset_id": "63189790407496871968365678866547561936214310417455881808824200627199091231049", "price": "0.711", "size": "1270.1", "side": "BUY", "hash": "46fad6a1a4c0ea216c2aa385d490c97cb6624590", "best_bid": "0.94", "best_ask": "0.97"}, {"asset_id": "39492360553034885301486766992727683306899599890890066102594783083978384204123", "price": "0.289", "size": "1270.1", "side": "SELL", "hash": "ed2fe5bbc35c41c74e066fce58cfc6a49d613408", "best_bid": "0.03", "best_ask": "0.06"}], "timestamp": "1769384481336", "event_type": "price_change"}}
{"_local_timestamp": "2026-01-25T23:41:21.434370+00:00", "data": {"market": "0x67d228115cc6ea9eb2dd85ca443c357359e4bdac7f773d8dff9f599cf5f58074", "price_changes": [{"asset_id": "40258076975888759603244407127088084693343108694292687330139582591508023070009", "price": "0.03", "size": "3267.21", "side": "BUY", "hash": "bfc986a8962b11fec89d0a25c884fad1947176c0", "best_bid": "0.13", "best_ask": "0.15"}, {"asset_id": "115673443932214194570164346004924052532408865542451590692735424434267556754094", "price": "0.97", "size": "3267.21", "side": "SELL", "hash": "95ae72dcdee893153c649573db656443f8e33d15", "best_bid": "0.85", "best_ask": "0.87"}], "timestamp": "1769384481337", "event_type": "price_change"}}
{"_local_timestamp": "2026-01-25T23:41:21.542398+00:00", "data": {"market": "0x9b95e4d85d89a2aa406d7bc683e9b8bb8c7d2b16ee3b44878a36d4e79eeb20ec", "price_changes": [{"asset_id": "63189790407496871968365678866547561936214310417455881808824200627199091231049", "price": "0.711", "size": "2160.21", "side": "BUY", "hash": "aa5ea4ff2e9c0eed5ef101ece6babf5e96537694", "best_bid": "0.94", "best_ask": "0.97"}, {"asset_id": "39492360553034885301486766992727683306899599890890066102594783083978384204123", "price": "0.289", "size": "2160.21", "side": "SELL", "hash": "15085387751307312d1102d337f2a4369d64291b", "best_bid": "0.03", "best_ask": "0.06"}], "timestamp": "1769384481337", "event_type": "price_change"}}
{"_local_timestamp": "2026-01-25T23:41:21.556854+00:00", "data": {"market": "0x67d228115cc6ea9eb2dd85ca443c357359e4bdac7f773d8dff9f599cf5f58074", "price_changes": [{"asset_id": "40258076975888759603244407127088084693343108694292687330139582591508023070009", "price": "0.03", "size": "4157.32", "side": "BUY", "hash": "069d6749188fc533cecf00c670725ac788c90f74", "best_bid": "0.13", "best_ask": "0.15"}, {"asset_id": "115673443932214194570164346004924052532408865542451590692735424434267556754094", "price": "0.97", "size": "4157.32", "side": "SELL", "hash": "360fb80287f075f54cd863571ce3488f0a913ab3", "best_bid": "0.85", "best_ask": "0.87"}], "timestamp": "1769384481337", "event_type": "price_change"}}
{"_local_timestamp": "2026-01-25T23:41:21.574638+00:00", "data": {"market": "0x9b95e4d85d89a2aa406d7bc683e9b8bb8c7d2b16ee3b44878a36d4e79eeb20ec", "price_changes": [{"asset_id": "63189790407496871968365678866547561936214310417455881808824200627199091231049", "price": "0.711", "size": "4157.32", "side": "BUY", "hash": "5f6f51d3d17b3ab64984408d03907d1908bbba93", "best_bid": "0.94", "best_ask": "0.97"}, {"asset_id": "39492360553034885301486766992727683306899599890890066102594783083978384204123", "price": "0.289", "size": "4157.32", "side": "SELL", "hash": "4a0830e6367ee0b7a2ccf548502c34721985347d", "best_bid": "0.03", "best_ask": "0.06"}], "timestamp": "1769384481338", "event_type": "price_change"}}
{"_local_timestamp": "2026-01-25T23:41:21.582694+00:00", "data": {"market": "0x9b95e4d85d89a2aa406d7bc683e9b8bb8c7d2b16ee3b44878a36d4e79eeb20ec", "price_changes": [{"asset_id": "63189790407496871968365678866547561936214310417455881808824200627199091231049", "price": "0.711", "size": "5047.43", "side": "BUY", "hash": "7fa307c0f4c130c99709be4e1a48f22384a740f0", "best_bid": "0.94", "best_ask": "0.97"}, {"asset_id": "39492360553034885301486766992727683306899599890890066102594783083978384204123", "price": "0.289", "size": "5047.43", "side": "SELL", "hash": "7423a79d1147ee176870a1ceb81a82bfcac462fe", "best_bid": "0.03", "best_ask": "0.06"}], "timestamp": "1769384481339", "event_type": "price_change"}}
{"_local_timestamp": "2026-01-25T23:41:21.604273+00:00", "data": {"market": "0x9b95e4d85d89a2aa406d7bc683e9b8bb8c7d2b16ee3b44878a36d4e79eeb20ec", "price_changes": [{"asset_id": "63189790407496871968365678866547561936214310417455881808824200627199091231049", "price": "0.711", "size": "11046.54", "side": "BUY", "hash": "d205025ccc10ea27dfd5762a8204f7fffdf29679", "best_bid": "0.94", "best_ask": "0.97"}, {"asset_id": "39492360553034885301486766992727683306899599890890066102594783083978384204123", "price": "0.289", "size": "11046.54", "side": "SELL", "hash": "f12fa5e290a562238ed415acb0b39bf25470c0cc", "best_bid": "0.03", "best_ask": "0.06"}], "timestamp": "1769384481339", "event_type": "price_change"}}
{"_local_timestamp": "2026-01-25T23:41:21.612364+00:00", "data": {"market": "0x425351f3d4713b9db2c15a80e1e75a2acf893b5495cc2e694095070137509329", "price_changes": [{"asset_id": "56846561876839441818327131212801941885992894700201726352426446447037474872043", "price": "0.34", "size": "393", "side": "BUY", "hash": "bd7fa66de1658a0157287354231da0cea4f13274", "best_bid": "0.99", "best_ask": "0.999"}, {"asset_id": "57829021360688395873888125190016504630905168321624137961276880640915115712545", "price": "0.66", "size": "393", "side": "SELL", "hash": "009f2ffc4552f8133f47879c82673fc6679d081e", "best_bid": "0.001", "best_ask": "0.01"}], "timestamp": "1769384481368", "event_type": "price_change"}}
{"_local_timestamp": "2026-01-25T23:41:23.879181+00:00", "data": {"market": "0x9b95e4d85d89a2aa406d7bc683e9b8bb8c7d2b16ee3b44878a36d4e79eeb20ec", "price_changes": [{"asset_id": "39492360553034885301486766992727683306899599890890066102594783083978384204123", "price": "0.011", "size": "900.59", "side": "BUY", "hash": "c107ff8563ec1ffa290a2e2b20e48f0eed4b03b8", "best_bid": "0.021", "best_ask": "0.06"}, {"asset_id": "63189790407496871968365678866547561936214310417455881808824200627199091231049", "price": "0.989", "size": "900.59", "side": "SELL", "hash": "fcad913064f013939090227935e5a47e3033a244", "best_bid": "0.94", "best_ask": "0.979"}], "timestamp": "1769384483811", "event_type": "price_change"}}
{"_local_timestamp": "2026-01-25T23:41:23.889367+00:00", "data": {"market": "0x9b95e4d85d89a2aa406d7bc683e9b8bb8c7d2b16ee3b44878a36d4e79eeb20ec", "price_changes": [{"asset_id": "39492360553034885301486766992727683306899599890890066102594783083978384204123", "price": "0.02", "size": "422.34", "side": "BUY", "hash": "c107ff8563ec1ffa290a2e2b20e48f0eed4b03b8", "best_bid": "0.021", "best_ask": "0.06"}, {"asset_id": "63189790407496871968365678866547561936214310417455881808824200627199091231049", "price": "0.98", "size": "422.34", "side": "SELL", "hash": "fcad913064f013939090227935e5a47e3033a244", "best_bid": "0.94", "best_ask": "0.979"}], "timestamp": "1769384483811", "event_type": "price_change"}}
{"_local_timestamp": "2026-01-25T23:41:23.895825+00:00", "data": {"market": "0x9b95e4d85d89a2aa406d7bc683e9b8bb8c7d2b16ee3b44878a36d4e79eeb20ec", "price_changes": [{"asset_id": "39492360553034885301486766992727683306899599890890066102594783083978384204123", "price": "0.021", "size": "895.83", "side": "BUY", "hash": "c107ff8563ec1ffa290a2e2b20e48f0eed4b03b8", "best_bid": "0.021", "best_ask": "0.06"}, {"asset_id": "63189790407496871968365678866547561936214310417455881808824200627199091231049", "price": "0.979", "size": "895.83", "side": "SELL", "hash": "fcad913064f013939090227935e5a47e3033a244", "best_bid": "0.94", "best_ask": "0.979"}], "timestamp": "1769384483811", "event_type": "price_change"}}
{"_local_timestamp": "2026-01-25T23:41:23.902538+00:00", "data": {"market": "0x9b95e4d85d89a2aa406d7bc683e9b8bb8c7d2b16ee3b44878a36d4e79eeb20ec", "price_changes": [{"asset_id": "39492360553034885301486766992727683306899599890890066102594783083978384204123", "price": "0.03", "size": "0", "side": "BUY", "hash": "c107ff8563ec1ffa290a2e2b20e48f0eed4b03b8", "best_bid": "0.021", "best_ask": "0.06"}, {"asset_id": "63189790407496871968365678866547561936214310417455881808824200627199091231049", "price": "0.97", "size": "0", "side": "SELL", "hash": "fcad913064f013939090227935e5a47e3033a244", "best_bid": "0.94", "best_ask": "0.979"}], "timestamp": "1769384483811", "event_type": "price_change"}}
{"_local_timestamp": "2026-01-25T23:41:23.967782+00:00", "data": {"market": "0x9b95e4d85d89a2aa406d7bc683e9b8bb8c7d2b16ee3b44878a36d4e79eeb20ec", "price_changes": [{"asset_id": "63189790407496871968365678866547561936214310417455881808824200627199091231049", "price": "0.711", "size": "0", "side": "BUY", "hash": "1b4629b0105be6854ccefb312b6fa10f600a58a3", "best_bid": "0.94", "best_ask": "0.979"}, {"asset_id": "39492360553034885301486766992727683306899599890890066102594783083978384204123", "price": "0.289", "size": "0", "side": "SELL", "hash": "420f15439ae31cd8a8706d262d4ff47bf5937a76", "best_bid": "0.021", "best_ask": "0.06"}], "timestamp": "1769384483898", "event_type": "price_change"}}
{"_local_timestamp": "2026-01-25T23:41:24.091453+00:00", "data": {"market": "0x9b95e4d85d89a2aa406d7bc683e9b8bb8c7d2b16ee3b44878a36d4e79eeb20ec", "price_changes": [{"asset_id": "39492360553034885301486766992727683306899599890890066102594783083978384204123", "price": "0.022", "size": "5.79", "side": "BUY", "hash": "e862037a81b6c1b39618a0fd2c7ed493d7c3f51a", "best_bid": "0.022", "best_ask": "0.06"}, {"asset_id": "63189790407496871968365678866547561936214310417455881808824200627199091231049", "price": "0.978", "size": "5.79", "side": "SELL", "hash": "3744539b03f60445a09690de56c1ec9deea244cc", "best_bid": "0.94", "best_ask": "0.978"}], "timestamp": "1769384484028", "event_type": "price_change"}}
{"_local_timestamp": "2026-01-25T23:41:24.100470+00:00", "data": {"market": "0x9b95e4d85d89a2aa406d7bc683e9b8bb8c7d2b16ee3b44878a36d4e79eeb20ec", "price_changes": [{"asset_id": "39492360553034885301486766992727683306899599890890066102594783083978384204123", "price": "0.012", "size": "11.18", "side": "BUY", "hash": "d3a565e47c893f2e289d4bc10a36623cf69c2df2", "best_bid": "0.022", "best_ask": "0.06"}, {"asset_id": "63189790407496871968365678866547561936214310417455881808824200627199091231049", "price": "0.988", "size": "11.18", "side": "SELL", "hash": "ec5e1ac56bbf0098c0cbf03c206c04eb2f66728a", "best_bid": "0.94", "best_ask": "0.978"}], "timestamp": "1769384484029", "event_type": "price_change"}}
{"_local_timestamp": "2026-01-25T23:41:24.111243+00:00", "data": {"market": "0x9b95e4d85d89a2aa406d7bc683e9b8bb8c7d2b16ee3b44878a36d4e79eeb20ec", "price_changes": [{"asset_id": "39492360553034885301486766992727683306899599890890066102594783083978384204123", "price": "0.022", "size": "11.58", "side": "BUY", "hash": "6da86565d09dc6435aa46ef3a4ce2362a0090f3f", "best_bid": "0.022", "best_ask": "0.06"}, {"asset_id": "63189790407496871968365678866547561936214310417455881808824200627199091231049", "price": "0.978", "size": "11.58", "side": "SELL", "hash": "1e4b3a4a61dc5ea84c53c6a88124603a935f7569", "best_bid": "0.94", "best_ask": "0.978"}], "timestamp": "1769384484030", "event_type": "price_change"}}
{"_local_timestamp": "2026-01-25T23:41:24.119418+00:00", "data": {"market": "0x9b95e4d85d89a2aa406d7bc683e9b8bb8c7d2b16ee3b44878a36d4e79eeb20ec", "price_changes": [{"asset_id": "39492360553034885301486766992727683306899599890890066102594783083978384204123", "price": "0.012", "size": "22.36", "side": "BUY", "hash": "237d58b7b9ebe082b6b86d9cc4a32f819fd07fb1", "best_bid": "0.022", "best_ask": "0.06"}, {"asset_id": "63189790407496871968365678866547561936214310417455881808824200627199091231049", "price": "0.988", "size": "22.36", "side": "SELL", "hash": "f7eec32a9ee43ecd60693670a02dcd93f61b85e4", "best_bid": "0.94", "best_ask": "0.978"}], "timestamp": "1769384484030", "event_type": "price_change"}}
{"_local_timestamp": "2026-01-25T23:41:24.126109+00:00", "data": {"market": "0x9b95e4d85d89a2aa406d7bc683e9b8bb8c7d2b16ee3b44878a36d4e79eeb20ec", "price_changes": [{"asset_id": "39492360553034885301486766992727683306899599890890066102594783083978384204123", "price": "0.001", "size": "35.89", "side": "BUY", "hash": "5010bc7b06f59cb6f514adcb2b4997daa9b6fc02", "best_bid": "0.022", "best_ask": "0.06"}, {"asset_id": "63189790407496871968365678866547561936214310417455881808824200627199091231049", "price": "0.999", "size": "35.89", "side": "SELL", "hash": "add5296357d7dbe24e34751378ef83bc7899775d", "best_bid": "0.94", "best_ask": "0.978"}], "timestamp": "1769384484031", "event_type": "price_change"}}
{"_local_timestamp": "2026-01-25T23:41:25.398224+00:00", "data": {"market": "0x67d228115cc6ea9eb2dd85ca443c357359e4bdac7f773d8dff9f599cf5f58074", "price_changes": [{"asset_id": "115673443932214194570164346004924052532408865542451590692735424434267556754094", "price": "0.35", "size": "100", "side": "BUY", "hash": "24d08baed5928d80cfec8e897d65ab7bdb64dd7b", "best_bid": "0.85", "best_ask": "0.87"}, {"asset_id": "40258076975888759603244407127088084693343108694292687330139582591508023070009", "price": "0.65", "size": "100", "side": "SELL", "hash": "b1bd3d22b0217926af842994435e2dfc36cd1f71", "best_bid": "0.13", "best_ask": "0.15"}], "timestamp": "1769384485329", "event_type": "price_change"}}
{"_local_timestamp": "2026-01-25T23:41:25.467646+00:00", "data": {"market": "0x67d228115cc6ea9eb2dd85ca443c357359e4bdac7f773d8dff9f599cf5f58074", "price_changes": [{"asset_id": "40258076975888759603244407127088084693343108694292687330139582591508023070009", "price": "0.01", "size": "133", "side": "BUY", "hash": "47f16fd45c818cc63756973d61cd399367c624c9", "best_bid": "0.13", "best_ask": "0.15"}, {"asset_id": "115673443932214194570164346004924052532408865542451590692735424434267556754094", "price": "0.99", "size": "133", "side": "SELL", "hash": "2c249a6ea55eb762b0a20df74cda03c237b58ffe", "best_bid": "0.85", "best_ask": "0.87"}], "timestamp": "1769384485399", "event_type": "price_change"}}
{"_local_timestamp": "2026-01-25T23:41:25.477183+00:00", "data": {"market": "0x67d228115cc6ea9eb2dd85ca443c357359e4bdac7f773d8dff9f599cf5f58074", "price_changes": [{"asset_id": "40258076975888759603244407127088084693343108694292687330139582591508023070009", "price": "0.07", "size": "8.26", "side": "BUY", "hash": "47f16fd45c818cc63756973d61cd399367c624c9", "best_bid": "0.13", "best_ask": "0.15"}, {"asset_id": "115673443932214194570164346004924052532408865542451590692735424434267556754094", "price": "0.93", "size": "8.26", "side": "SELL", "hash": "2c249a6ea55eb762b0a20df74cda03c237b58ffe", "best_bid": "0.85", "best_ask": "0.87"}], "timestamp": "1769384485399", "event_type": "price_change"}}
{"_local_timestamp": "2026-01-25T23:41:26.064210+00:00", "data": {"market": "0x67d228115cc6ea9eb2dd85ca443c357359e4bdac7f773d8dff9f599cf5f58074", "price_changes": [{"asset_id": "115673443932214194570164346004924052532408865542451590692735424434267556754094", "price": "0.83", "size": "1538", "side": "BUY", "hash": "39a22d49174860bfb53ac2d8aaba5ea4d8bb2a0c", "best_bid": "0.85", "best_ask": "0.87"}, {"asset_id": "40258076975888759603244407127088084693343108694292687330139582591508023070009", "price": "0.17", "size": "1538", "side": "SELL", "hash": "677cd84a9b98c1f1d7e5a5de97d4ffba65edbaa8", "best_bid": "0.13", "best_ask": "0.15"}], "timestamp": "1769384485984", "event_type": "price_change"}}
{"_local_timestamp": "2026-01-25T23:41:26.071726+00:00", "data": {"market": "0xdb220d70cc76303505355f558407f99958916364c5612685c804fe1267d0f514", "price_changes": [{"asset_id": "29127800831891156918080289096614999289213121001925429958509112072030245798692", "price": "0.17", "size": "0", "side": "BUY", "hash": "e7e8290fa736ea703b63342801ae1a7d236e64bd", "best_bid": "0.57", "best_ask": "0.97"}, {"asset_id": "89178703372212073978389921580322635269384366327786463025461810229435622804178", "price": "0.83", "size": "0", "side": "SELL", "hash": "2d1aaec2e0cd9186585c5c17c1280672f8c339c3", "best_bid": "0.03", "best_ask": "0.43"}], "timestamp": "1769384486000", "event_type": "price_change"}}
{"_local_timestamp": "2026-01-25T23:41:26.079955+00:00", "data": {"market": "0x67d228115cc6ea9eb2dd85ca443c357359e4bdac7f773d8dff9f599cf5f58074", "price_changes": [{"asset_id": "115673443932214194570164346004924052532408865542451590692735424434267556754094", "price": "0.39", "size": "0", "side": "BUY", "hash": "00ca192821a7c97dbfbb59d50df9a11a15dd3bf9", "best_bid": "0.85", "best_ask": "0.87"}, {"asset_id": "40258076975888759603244407127088084693343108694292687330139582591508023070009", "price": "0.61", "size": "0", "side": "SELL", "hash": "2c2ef8bae7c9b18e326a86d1c43f2fafb467fa4c", "best_bid": "0.13", "best_ask": "0.15"}], "timestamp": "1769384486000", "event_type": "price_change"}}
{"_local_timestamp": "2026-01-25T23:41:26.086656+00:00", "data": {"market": "0xfa0a910c4380fc83610d9fa68b214b598621ae9bd49dc40df47abd265bf0bc34", "price_changes": [{"asset_id": "42996585481877433482708272870977066259130153781685558286992961170000063507609", "price": "0.02", "size": "0", "side": "BUY", "hash": "ce31f6d2f752b142ec77f2e820970ebeed9be65d", "best_bid": "0.58", "best_ask": "0.94"}, {"asset_id": "59290556380981220753832906409296194214356850812489293134106523641703938483612", "price": "0.98", "size": "0", "side": "SELL", "hash": "e5abbe31965f8ddb929d48ea999416a698bed5d9", "best_bid": "0.06", "best_ask": "0.42"}], "timestamp": "1769384486000", "event_type": "price_change"}}
{"_local_timestamp": "2026-01-25T23:41:26.093206+00:00", "data": {"market": "0x425351f3d4713b9db2c15a80e1e75a2acf893b5495cc2e694095070137509329", "price_changes": [{"asset_id": "56846561876839441818327131212801941885992894700201726352426446447037474872043", "price": "0.34", "size": "100", "side": "BUY", "hash": "98fdb64f92db00082026b1297b138fca0e801b88", "best_bid": "0.99", "best_ask": "0.999"}, {"asset_id": "57829021360688395873888125190016504630905168321624137961276880640915115712545", "price": "0.66", "size": "100", "side": "SELL", "hash": "88f6079a5a8a2c476690f7b2b56cfb55bccf14f5", "best_bid": "0.001", "best_ask": "0.01"}], "timestamp": "1769384486001", "event_type": "price_change"}}
{"_local_timestamp": "2026-01-25T23:41:26.099753+00:00", "data": {"market": "0x9b95e4d85d89a2aa406d7bc683e9b8bb8c7d2b16ee3b44878a36d4e79eeb20ec", "price_changes": [{"asset_id": "63189790407496871968365678866547561936214310417455881808824200627199091231049", "price": "0.38", "size": "30", "side": "BUY", "hash": "5a5f4012380184bb2390befdb3dc4f2a21ac13ac", "best_bid": "0.94", "best_ask": "0.978"}, {"asset_id": "39492360553034885301486766992727683306899599890890066102594783083978384204123", "price": "0.62", "size": "30", "side": "SELL", "hash": "79c0773fae0ffcfd4b964c09c5cf7f4eabe8940b", "best_bid": "0.022", "best_ask": "0.06"}], "timestamp": "1769384486001", "event_type": "price_change"}}
{"_local_timestamp": "2026-01-25T23:41:26.109561+00:00", "data": {"market": "0x67d228115cc6ea9eb2dd85ca443c357359e4bdac7f773d8dff9f599cf5f58074", "price_changes": [{"asset_id": "40258076975888759603244407127088084693343108694292687330139582591508023070009", "price": "0.02", "size": "21.09", "side": "BUY", "hash": "2c76355cf1e7e67a0d0d12a5f498748b51a6f2d1", "best_bid": "0.13", "best_ask": "0.15"}, {"asset_id": "115673443932214194570164346004924052532408865542451590692735424434267556754094", "price": "0.98", "size": "21.09", "side": "SELL", "hash": "117443c12912985a764b1bd2d2d6c808b66fe27a", "best_bid": "0.85", "best_ask": "0.87"}], "timestamp": "1769384486002", "event_type": "price_change"}}
{"_local_timestamp": "2026-01-25T23:41:26.142052+00:00", "data": {"market": "0xdb220d70cc76303505355f558407f99958916364c5612685c804fe1267d0f514", "price_changes": [{"asset_id": "29127800831891156918080289096614999289213121001925429958509112072030245798692", "price": "0.16", "size": "0", "side": "BUY", "hash": "078bbc8c9eeaf1decd5d6f93d98f2a12ea9a5a89", "best_bid": "0.57", "best_ask": "0.97"}, {"asset_id": "89178703372212073978389921580322635269384366327786463025461810229435622804178", "price": "0.84", "size": "0", "side": "SELL", "hash": "8c7a59ff25a232358aaa59e601e17a5c5a0ba74d", "best_bid": "0.03", "best_ask": "0.43"}], "timestamp": "1769384486060", "event_type": "price_change"}}
{"_local_timestamp": "2026-01-25T23:41:26.150939+00:00", "data": {"market": "0xdb220d70cc76303505355f558407f99958916364c5612685c804fe1267d0f514", "price_changes": [{"asset_id": "29127800831891156918080289096614999289213121001925429958509112072030245798692", "price": "0.15", "size": "0", "side": "BUY", "hash": "078bbc8c9eeaf1decd5d6f93d98f2a12ea9a5a89", "best_bid": "0.57", "best_ask": "0.97"}, {"asset_id": "89178703372212073978389921580322635269384366327786463025461810229435622804178", "price": "0.85", "size": "0", "side": "SELL", "hash": "8c7a59ff25a232358aaa59e601e17a5c5a0ba74d", "best_bid": "0.03", "best_ask": "0.43"}], "timestamp": "1769384486060", "event_type": "price_change"}}
{"_local_timestamp": "2026-01-25T23:41:26.161499+00:00", "data": {"market": "0xdb220d70cc76303505355f558407f99958916364c5612685c804fe1267d0f514", "price_changes": [{"asset_id": "29127800831891156918080289096614999289213121001925429958509112072030245798692", "price": "0.14", "size": "0", "side": "BUY", "hash": "078bbc8c9eeaf1decd5d6f93d98f2a12ea9a5a89", "best_bid": "0.57", "best_ask": "0.97"}, {"asset_id": "89178703372212073978389921580322635269384366327786463025461810229435622804178", "price": "0.86", "size": "0", "side": "SELL", "hash": "8c7a59ff25a232358aaa59e601e17a5c5a0ba74d", "best_bid": "0.03", "best_ask": "0.43"}], "timestamp": "1769384486060", "event_type": "price_change"}}
{"_local_timestamp": "2026-01-25T23:41:26.304373+00:00", "data": {"market": "0x67d228115cc6ea9eb2dd85ca443c357359e4bdac7f773d8dff9f599cf5f58074", "price_changes": [{"asset_id": "40258076975888759603244407127088084693343108694292687330139582591508023070009", "price": "0.01", "size": "1403.1", "side": "BUY", "hash": "0b856a4976e0a244a1ec19b1a343c06be00bf107", "best_bid": "0.13", "best_ask": "0.15"}, {"asset_id": "115673443932214194570164346004924052532408865542451590692735424434267556754094", "price": "0.99", "size": "1403.1", "side": "SELL", "hash": "a702f06422af488d7f2de9639d68de2fb5ddde3f", "best_bid": "0.85", "best_ask": "0.87"}], "timestamp": "1769384486220", "event_type": "price_change"}}
{"_local_timestamp": "2026-01-25T23:41:26.331235+00:00", "data": {"market": "0x67d228115cc6ea9eb2dd85ca443c357359e4bdac7f773d8dff9f599cf5f58074", "price_changes": [{"asset_id": "40258076975888759603244407127088084693343108694292687330139582591508023070009", "price": "0.01", "size": "2293.21", "side": "BUY", "hash": "72a92dccb75fd3bdac62dd7b5aba9ca462374db0", "best_bid": "0.13", "best_ask": "0.15"}, {"asset_id": "115673443932214194570164346004924052532408865542451590692735424434267556754094", "price": "0.99", "size": "2293.21", "side": "SELL", "hash": "26265795f53e2d0295897f3b4e4e9de027c7a872", "best_bid": "0.85", "best_ask": "0.87"}], "timestamp": "1769384486221", "event_type": "price_change"}}
{"_local_timestamp": "2026-01-25T23:41:26.339005+00:00", "data": {"market": "0x67d228115cc6ea9eb2dd85ca443c357359e4bdac7f773d8dff9f599cf5f58074", "price_changes": [{"asset_id": "40258076975888759603244407127088084693343108694292687330139582591508023070009", "price": "0.01", "size": "4290.32", "side": "BUY", "hash": "901ef6dfa54ae23806f9188f43d62b3272b9edfd", "best_bid": "0.13", "best_ask": "0.15"}, {"asset_id": "115673443932214194570164346004924052532408865542451590692735424434267556754094", "price": "0.99", "size": "4290.32", "side": "SELL", "hash": "f22c59ce19219776f52e211afe14631824119097", "best_bid": "0.85", "best_ask": "0.87"}], "timestamp": "1769384486222", "event_type": "price_change"}}
{"_local_timestamp": "2026-01-25T23:41:26.781082+00:00", "data": {"market": "0xfa0a910c4380fc83610d9fa68b214b598621ae9bd49dc40df47abd265bf0bc34", "price_changes": [{"asset_id": "42996585481877433482708272870977066259130153781685558286992961170000063507609", "price": "0.02", "size": "5000", "side": "BUY", "hash": "1efcfc13b15698d7cc611843bfffc2980fe4bdfb", "best_bid": "0.58", "best_ask": "0.94"}, {"asset_id": "59290556380981220753832906409296194214356850812489293134106523641703938483612", "price": "0.98", "size": "5000", "side": "SELL", "hash": "89f54a15fdbb4430234b98baadbbeedd10d34127", "best_bid": "0.06", "best_ask": "0.42"}], "timestamp": "1769384486702", "event_type": "price_change"}}
{"_local_timestamp": "2026-01-25T23:41:26.787729+00:00", "data": {"market": "0x425351f3d4713b9db2c15a80e1e75a2acf893b5495cc2e694095070137509329", "price_changes": [{"asset_id": "56846561876839441818327131212801941885992894700201726352426446447037474872043", "price": "0.34", "size": "393", "side": "BUY", "hash": "150eba416c9e31d274b6195db3c4a99c423ded45", "best_bid": "0.99", "best_ask": "0.999"}, {"asset_id": "57829021360688395873888125190016504630905168321624137961276880640915115712545", "price": "0.66", "size": "393", "side": "SELL", "hash": "737af95a714e18bd435d603dcddd2af45f262bab", "best_bid": "0.001", "best_ask": "0.01"}], "timestamp": "1769384486703", "event_type": "price_change"}}
{"_local_timestamp": "2026-01-25T23:41:26.929537+00:00", "data": {"market": "0x67d228115cc6ea9eb2dd85ca443c357359e4bdac7f773d8dff9f599cf5f58074", "price_changes": [{"asset_id": "40258076975888759603244407127088084693343108694292687330139582591508023070009", "price": "0.04", "size": "2500", "side": "BUY", "hash": "b192171afd24b49d73ac09cea43fd267e7504c98", "best_bid": "0.13", "best_ask": "0.15"}, {"asset_id": "115673443932214194570164346004924052532408865542451590692735424434267556754094", "price": "0.96", "size": "2500", "side": "SELL", "hash": "ed80f72aadfeaee8baf3c9f685fa5065062d7b76", "best_bid": "0.85", "best_ask": "0.87"}], "timestamp": "1769384486857", "event_type": "price_change"}}
{"_local_timestamp": "2026-01-25T23:41:26.953733+00:00", "data": {"market": "0xdb220d70cc76303505355f558407f99958916364c5612685c804fe1267d0f514", "price_changes": [{"asset_id": "29127800831891156918080289096614999289213121001925429958509112072030245798692", "price": "0.03", "size": "3362.8", "side": "BUY", "hash": "77fa38688d63972daf85500be41c66ca87d19aa1", "best_bid": "0.57", "best_ask": "0.97"}, {"asset_id": "89178703372212073978389921580322635269384366327786463025461810229435622804178", "price": "0.97", "size": "3362.8", "side": "SELL", "hash": "2907850baa03deb53148c765cc917ee342ff3602", "best_bid": "0.03", "best_ask": "0.43"}], "timestamp": "1769384486857", "event_type": "price_change"}}
{"_local_timestamp": "2026-01-25T23:41:26.960526+00:00", "data": {"market": "0x9b95e4d85d89a2aa406d7bc683e9b8bb8c7d2b16ee3b44878a36d4e79eeb20ec", "price_changes": [{"asset_id": "63189790407496871968365678866547561936214310417455881808824200627199091231049", "price": "0.38", "size": "292", "side": "BUY", "hash": "2f01c80cb756ae7c9c9f61fb92c673548fc570ef", "best_bid": "0.94", "best_ask": "0.978"}, {"asset_id": "39492360553034885301486766992727683306899599890890066102594783083978384204123", "price": "0.62", "size": "292", "side": "SELL", "hash": "8f431ab357d2af0c0d49e89722d93dfa266f889d", "best_bid": "0.022", "best_ask": "0.06"}], "timestamp": "1769384486857", "event_type": "price_change"}}
{"_local_timestamp": "2026-01-25T23:41:26.995106+00:00", "data": {"market": "0x67d228115cc6ea9eb2dd85ca443c357359e4bdac7f773d8dff9f599cf5f58074", "price_changes": [{"asset_id": "115673443932214194570164346004924052532408865542451590692735424434267556754094", "price": "0.39", "size": "256", "side": "BUY", "hash": "2f329a532aa466866ddbd75b61de5047705c666e", "best_bid": "0.85", "best_ask": "0.87"}, {"asset_id": "40258076975888759603244407127088084693343108694292687330139582591508023070009", "price": "0.61", "size": "256", "side": "SELL", "hash": "f18befac36fb3c84c442515eda5582e944d78e24", "best_bid": "0.13", "best_ask": "0.15"}], "timestamp": "1769384486858", "event_type": "price_change"}}
{"_local_timestamp": "2026-01-25T23:41:27.106002+00:00", "data": {"market": "0x9b95e4d85d89a2aa406d7bc683e9b8bb8c7d2b16ee3b44878a36d4e79eeb20ec", "price_changes": [{"asset_id": "39492360553034885301486766992727683306899599890890066102594783083978384204123", "price": "0.011", "size": "890.11", "side": "BUY", "hash": "f7a937292379c73f28292199da2b7f0e8df105a6", "best_bid": "0.022", "best_ask": "0.06"}, {"asset_id": "63189790407496871968365678866547561936214310417455881808824200627199091231049", "price": "0.989", "size": "890.11", "side": "SELL", "hash": "bec13ec3fc5ded693e362091e351a4ceb039a460", "best_bid": "0.94", "best_ask": "0.978"}], "timestamp": "1769384487023", "event_type": "price_change"}}
{"_local_timestamp": "2026-01-25T23:41:27.118032+00:00", "data": {"market": "0x9b95e4d85d89a2aa406d7bc683e9b8bb8c7d2b16ee3b44878a36d4e79eeb20ec", "price_changes": [{"asset_id": "39492360553034885301486766992727683306899599890890066102594783083978384204123", "price": "0.021", "size": "890.11", "side": "BUY", "hash": "f7a937292379c73f28292199da2b7f0e8df105a6", "best_bid": "0.022", "best_ask": "0.06"}, {"asset_id": "63189790407496871968365678866547561936214310417455881808824200627199091231049", "price": "0.979", "size": "890.11", "side": "SELL", "hash": "bec13ec3fc5ded693e362091e351a4ceb039a460", "best_bid": "0.94", "best_ask": "0.978"}], "timestamp": "1769384487023", "event_type": "price_change"}}
{"_local_timestamp": "2026-01-25T23:41:27.129922+00:00", "data": {"market": "0x9b95e4d85d89a2aa406d7bc683e9b8bb8c7d2b16ee3b44878a36d4e79eeb20ec", "price_changes": [{"asset_id": "39492360553034885301486766992727683306899599890890066102594783083978384204123", "price": "0.022", "size": "5.79", "side": "BUY", "hash": "f7a937292379c73f28292199da2b7f0e8df105a6", "best_bid": "0.022", "best_ask": "0.06"}, {"asset_id": "63189790407496871968365678866547561936214310417455881808824200627199091231049", "price": "0.978", "size": "5.79", "side": "SELL", "hash": "bec13ec3fc5ded693e362091e351a4ceb039a460", "best_bid": "0.94", "best_ask": "0.978"}], "timestamp": "1769384487023", "event_type": "price_change"}}
{"_local_timestamp": "2026-01-25T23:41:27.144576+00:00", "data": {"market": "0x9b95e4d85d89a2aa406d7bc683e9b8bb8c7d2b16ee3b44878a36d4e79eeb20ec", "price_changes": [{"asset_id": "63189790407496871968365678866547561936214310417455881808824200627199091231049", "price": "0.001", "size": "6029.11", "side": "BUY", "hash": "7ce5952754779dafa5f024d55d464970775958a0", "best_bid": "0.94", "best_ask": "0.978"}, {"asset_id": "39492360553034885301486766992727683306899599890890066102594783083978384204123", "price": "0.999", "size": "6029.11", "side": "SELL", "hash": "b003baf92ee622e2914cfb08d4948d8c9c511e32", "best_bid": "0.022", "best_ask": "0.06"}], "timestamp": "1769384487044", "event_type": "price_change"}}
{"_local_timestamp": "2026-01-25T23:41:27.185184+00:00", "data": {"market": "0xdb220d70cc76303505355f558407f99958916364c5612685c804fe1267d0f514", "price_changes": [{"asset_id": "29127800831891156918080289096614999289213121001925429958509112072030245798692", "price": "0.04", "size": "890.11", "side": "BUY", "hash": "d486d6633b73199949ba6c683f2fc313135b2184", "best_bid": "0.57", "best_ask": "0.97"}, {"asset_id": "89178703372212073978389921580322635269384366327786463025461810229435622804178", "price": "0.96", "size": "890.11", "side": "SELL", "hash": "01dca2a36702f56292e235d0494d0ec8c6236505", "best_bid": "0.03", "best_ask": "0.43"}], "timestamp": "1769384487105", "event_type": "price_change"}}
{"_local_timestamp": "2026-01-25T23:41:27.198188+00:00", "data": {"market": "0xdb220d70cc76303505355f558407f99958916364c5612685c804fe1267d0f514", "price_changes": [{"asset_id": "29127800831891156918080289096614999289213121001925429958509112072030245798692", "price": "0.04", "size": "2887.22", "side": "BUY", "hash": "72c7c5edd3601fce2d1c8c65af3a2523ab3e131a", "best_bid": "0.57", "best_ask": "0.97"}, {"asset_id": "89178703372212073978389921580322635269384366327786463025461810229435622804178", "price": "0.96", "size": "2887.22", "side": "SELL", "hash": "48a3cbd6b7c237ef53a5a0fe68087be8693928e3", "best_bid": "0.03", "best_ask": "0.43"}], "timestamp": "1769384487105", "event_type": "price_change"}}
{"_local_timestamp": "2026-01-25T23:41:27.211337+00:00", "data": {"market": "0xdb220d70cc76303505355f558407f99958916364c5612685c804fe1267d0f514", "price_changes": [{"asset_id": "29127800831891156918080289096614999289213121001925429958509112072030245798692", "price": "0.03", "size": "4252.91", "side": "BUY", "hash": "0a20b6eaaa5e121b2f310ac359bab4da5b123f35", "best_bid": "0.57", "best_ask": "0.97"}, {"asset_id": "89178703372212073978389921580322635269384366327786463025461810229435622804178", "price": "0.97", "size": "4252.91", "side": "SELL", "hash": "e51f505bdaef0f95e3ba53f10e14a01288bdcb66", "best_bid": "0.03", "best_ask": "0.43"}], "timestamp": "1769384487106", "event_type": "price_change"}}
{"_local_timestamp": "2026-01-25T23:41:27.222598+00:00", "data": {"market": "0xdb220d70cc76303505355f558407f99958916364c5612685c804fe1267d0f514", "price_changes": [{"asset_id": "29127800831891156918080289096614999289213121001925429958509112072030245798692", "price": "0.04", "size": "3777.33", "side": "BUY", "hash": "edd7629514e7064b114bb7577d6097db0e546986", "best_bid": "0.57", "best_ask": "0.97"}, {"asset_id": "89178703372212073978389921580322635269384366327786463025461810229435622804178", "price": "0.96", "size": "3777.33", "side": "SELL", "hash": "85500e051d2f110d7bb551dfce1059114918d4e2", "best_bid": "0.03", "best_ask": "0.43"}], "timestamp": "1769384487107", "event_type": "price_change"}}
{"_local_timestamp": "2026-01-25T23:41:27.239175+00:00", "data": {"market": "0xdb220d70cc76303505355f558407f99958916364c5612685c804fe1267d0f514", "price_changes": [{"asset_id": "29127800831891156918080289096614999289213121001925429958509112072030245798692", "price": "0.04", "size": "5047.43", "side": "BUY", "hash": "8dc781dcdc45708bef892d1ff400b9ff6eb52c72", "best_bid": "0.57", "best_ask": "0.97"}, {"asset_id": "89178703372212073978389921580322635269384366327786463025461810229435622804178", "price": "0.96", "size": "5047.43", "side": "SELL", "hash": "5738e20465136d076258b23b275449de9cc06ecf", "best_bid": "0.03", "best_ask": "0.43"}], "timestamp": "1769384487107", "event_type": "price_change"}}
{"_local_timestamp": "2026-01-25T23:41:27.359770+00:00", "data": {"market": "0x9b95e4d85d89a2aa406d7bc683e9b8bb8c7d2b16ee3b44878a36d4e79eeb20ec", "price_changes": [{"asset_id": "39492360553034885301486766992727683306899599890890066102594783083978384204123", "price": "0.001", "size": "65.89", "side": "BUY", "hash": "3a6c9ee27bcef13ec4dafc1295ce4b839326041a", "best_bid": "0.022", "best_ask": "0.06"}, {"asset_id": "63189790407496871968365678866547561936214310417455881808824200627199091231049", "price": "0.999", "size": "65.89", "side": "SELL", "hash": "619ac92134a13258ef9a011ae399347d8c0df43b", "best_bid": "0.94", "best_ask": "0.978"}], "timestamp": "1769384487291", "event_type": "price_change"}}
{"_local_timestamp": "2026-01-25T23:41:27.374605+00:00", "data": {"market": "0x9b95e4d85d89a2aa406d7bc683e9b8bb8c7d2b16ee3b44878a36d4e79eeb20ec", "price_changes": [{"asset_id": "39492360553034885301486766992727683306899599890890066102594783083978384204123", "price": "0.012", "size": "30.43", "side": "BUY", "hash": "1f6a5145658a52e0a56037f524f1af2c5dbcd878", "best_bid": "0.022", "best_ask": "0.06"}, {"asset_id": "63189790407496871968365678866547561936214310417455881808824200627199091231049", "price": "0.988", "size": "30.43", "side": "SELL", "hash": "19d2efdfaef4ebd7bfd61b473785e1ac7ddf8e04", "best_bid": "0.94", "best_ask": "0.978"}], "timestamp": "1769384487305", "event_type": "price_change"}}
{"_local_timestamp": "2026-01-25T23:41:27.381258+00:00", "data": {"market": "0x9b95e4d85d89a2aa406d7bc683e9b8bb8c7d2b16ee3b44878a36d4e79eeb20ec", "price_changes": [{"asset_id": "39492360553034885301486766992727683306899599890890066102594783083978384204123", "price": "0.001", "size": "71.17", "side": "BUY", "hash": "c6b96f1792994cfc1aff609c1bcc154aeb51d08b", "best_bid": "0.022", "best_ask": "0.06"}, {"asset_id": "63189790407496871968365678866547561936214310417455881808824200627199091231049", "price": "0.999", "size": "71.17", "side": "SELL", "hash": "2e0ac05054fb7a9905c34e150a4892286ec39972", "best_bid": "0.94", "best_ask": "0.978"}], "timestamp": "1769384487306", "event_type": "price_change"}}
{"_local_timestamp": "2026-01-25T23:41:27.387660+00:00", "data": {"market": "0x9b95e4d85d89a2aa406d7bc683e9b8bb8c7d2b16ee3b44878a36d4e79eeb20ec", "price_changes": [{"asset_id": "39492360553034885301486766992727683306899599890890066102594783083978384204123", "price": "0.012", "size": "38.5", "side": "BUY", "hash": "5702d255109cddd4e4189fd34cf49e39a98f97a0", "best_bid": "0.022", "best_ask": "0.06"}, {"asset_id": "63189790407496871968365678866547561936214310417455881808824200627199091231049", "price": "0.988", "size": "38.5", "side": "SELL", "hash": "f4f636e304d72ee00f89a7915cfde19d29bf5724", "best_bid": "0.94", "best_ask": "0.978"}], "timestamp": "1769384487307", "event_type": "price_change"}}
{"_local_timestamp": "2026-01-25T23:41:28.627042+00:00", "data": {"market": "0x9b95e4d85d89a2aa406d7bc683e9b8bb8c7d2b16ee3b44878a36d4e79eeb20ec", "price_changes": [{"asset_id": "39492360553034885301486766992727683306899599890890066102594783083978384204123", "price": "0.023", "size": "5.47", "side": "BUY", "hash": "f090a1cb7491592c4d6d284d4edcd401edd49952", "best_bid": "0.023", "best_ask": "0.06"}, {"asset_id": "63189790407496871968365678866547561936214310417455881808824200627199091231049", "price": "0.977", "size": "5.47", "side": "SELL", "hash": "2290b22ce623c22303f4ce4d96e5c8b969206908", "best_bid": "0.94", "best_ask": "0.977"}], "timestamp": "1769384488555", "event_type": "price_change"}}
{"_local_timestamp": "2026-01-25T23:41:28.972533+00:00", "data": {"market": "0xfa0a910c4380fc83610d9fa68b214b598621ae9bd49dc40df47abd265bf0bc34", "price_changes": [{"asset_id": "42996585481877433482708272870977066259130153781685558286992961170000063507609", "price": "0.01", "size": "1043.14", "side": "BUY", "hash": "65b36065b09cc3787ae35c4f1ab88d1a8e565b21", "best_bid": "0.58", "best_ask": "0.94"}, {"asset_id": "59290556380981220753832906409296194214356850812489293134106523641703938483612", "price": "0.99", "size": "1043.14", "side": "SELL", "hash": "6a7ceb4c663dd704a07366926d1e3d57820544b7", "best_bid": "0.06", "best_ask": "0.42"}], "timestamp": "1769384488907", "event_type": "price_change"}}
{"_local_timestamp": "2026-01-25T23:41:28.979783+00:00", "data": {"market": "0xfa0a910c4380fc83610d9fa68b214b598621ae9bd49dc40df47abd265bf0bc34", "price_changes": [{"asset_id": "42996585481877433482708272870977066259130153781685558286992961170000063507609", "price": "0.04", "size": "0", "side": "BUY", "hash": "65b36065b09cc3787ae35c4f1ab88d1a8e565b21", "best_bid": "0.58", "best_ask": "0.94"}, {"asset_id": "59290556380981220753832906409296194214356850812489293134106523641703938483612", "price": "0.96", "size": "0", "side": "SELL", "hash": "6a7ceb4c663dd704a07366926d1e3d57820544b7", "best_bid": "0.06", "best_ask": "0.42"}], "timestamp": "1769384488907", "event_type": "price_change"}}
{"_local_timestamp": "2026-01-25T23:41:29.622589+00:00", "data": {"market": "0xfa0a910c4380fc83610d9fa68b214b598621ae9bd49dc40df47abd265bf0bc34", "price_changes": [{"asset_id": "42996585481877433482708272870977066259130153781685558286992961170000063507609", "price": "0.03", "size": "37.09", "side": "BUY", "hash": "cf638068b81fb80f998cb48dc9b453176c00a3c3", "best_bid": "0.58", "best_ask": "0.94"}, {"asset_id": "59290556380981220753832906409296194214356850812489293134106523641703938483612", "price": "0.97", "size": "37.09", "side": "SELL", "hash": "fa371305cffc99dd7093bc5ee931a55daed1d46d", "best_bid": "0.06", "best_ask": "0.42"}], "timestamp": "1769384489556", "event_type": "price_change"}}
{"_local_timestamp": "2026-01-25T23:41:30.011297+00:00", "data": {"market": "0x9b95e4d85d89a2aa406d7bc683e9b8bb8c7d2b16ee3b44878a36d4e79eeb20ec", "price_changes": [{"asset_id": "39492360553034885301486766992727683306899599890890066102594783083978384204123", "price": "0.001", "size": "56.62", "side": "BUY", "hash": "77036c1b58f763764b51288f3d422d563688d44d", "best_bid": "0.023", "best_ask": "0.06"}, {"asset_id": "63189790407496871968365678866547561936214310417455881808824200627199091231049", "price": "0.999", "size": "56.62", "side": "SELL", "hash": "6005f0b793f74ffd7f8658e840ac94f1185e786d", "best_bid": "0.94", "best_ask": "0.977"}], "timestamp": "1769384489938", "event_type": "price_change"}}
{"_local_timestamp": "2026-01-25T23:41:30.018078+00:00", "data": {"market": "0x9b95e4d85d89a2aa406d7bc683e9b8bb8c7d2b16ee3b44878a36d4e79eeb20ec", "price_changes": [{"asset_id": "39492360553034885301486766992727683306899599890890066102594783083978384204123", "price": "0.012", "size": "27.32", "side": "BUY", "hash": "77036c1b58f763764b51288f3d422d563688d44d", "best_bid": "0.023", "best_ask": "0.06"}, {"asset_id": "63189790407496871968365678866547561936214310417455881808824200627199091231049", "price": "0.988", "size": "27.32", "side": "SELL", "hash": "6005f0b793f74ffd7f8658e840ac94f1185e786d", "best_bid": "0.94", "best_ask": "0.977"}], "timestamp": "1769384489938", "event_type": "price_change"}}
{"_local_timestamp": "2026-01-25T23:41:30.024753+00:00", "data": {"market": "0x9b95e4d85d89a2aa406d7bc683e9b8bb8c7d2b16ee3b44878a36d4e79eeb20ec", "price_changes": [{"asset_id": "39492360553034885301486766992727683306899599890890066102594783083978384204123", "price": "0.022", "size": "0", "side": "BUY", "hash": "77036c1b58f763764b51288f3d422d563688d44d", "best_bid": "0.023", "best_ask": "0.06"}, {"asset_id": "63189790407496871968365678866547561936214310417455881808824200627199091231049", "price": "0.978", "size": "0", "side": "SELL", "hash": "6005f0b793f74ffd7f8658e840ac94f1185e786d", "best_bid": "0.94", "best_ask": "0.977"}], "timestamp": "1769384489938", "event_type": "price_change"}}
{"_local_timestamp": "2026-01-25T23:41:30.415668+00:00", "data": {"market": "0x9b95e4d85d89a2aa406d7bc683e9b8bb8c7d2b16ee3b44878a36d4e79eeb20ec", "price_changes": [{"asset_id": "39492360553034885301486766992727683306899599890890066102594783083978384204123", "price": "0.002", "size": "42.89", "side": "BUY", "hash": "20e9005e8e13fef7beee11e2d36424eba4e8f68c", "best_bid": "0.023", "best_ask": "0.06"}, {"asset_id": "63189790407496871968365678866547561936214310417455881808824200627199091231049", "price": "0.998", "size": "42.89", "side": "SELL", "hash": "49f40c904f56d8b4529d429d05cba7ca26d670b2", "best_bid": "0.94", "best_ask": "0.977"}], "timestamp": "1769384490349", "event_type": "price_change"}}
{"_local_timestamp": "2026-01-25T23:41:30.421981+00:00", "data": {"market": "0x9b95e4d85d89a2aa406d7bc683e9b8bb8c7d2b16ee3b44878a36d4e79eeb20ec", "price_changes": [{"asset_id": "39492360553034885301486766992727683306899599890890066102594783083978384204123", "price": "0.002", "size": "85.78", "side": "BUY", "hash": "64a8ada76551060f4e26373df93b6bd1acd732be", "best_bid": "0.023", "best_ask": "0.06"}, {"asset_id": "63189790407496871968365678866547561936214310417455881808824200627199091231049", "price": "0.998", "size": "85.78", "side": "SELL", "hash": "3d6eef55f49bf16ee43c60e40e70589bf6c53ac0", "best_bid": "0.94", "best_ask": "0.977"}], "timestamp": "1769384490349", "event_type": "price_change"}}
{"_local_timestamp": "2026-01-25T23:41:30.429362+00:00", "data": {"market": "0x9b95e4d85d89a2aa406d7bc683e9b8bb8c7d2b16ee3b44878a36d4e79eeb20ec", "price_changes": [{"asset_id": "39492360553034885301486766992727683306899599890890066102594783083978384204123", "price": "0.012", "size": "34.52", "side": "BUY", "hash": "1e327df33002e598a1bbefe6ad7578acfb12583d", "best_bid": "0.023", "best_ask": "0.06"}, {"asset_id": "63189790407496871968365678866547561936214310417455881808824200627199091231049", "price": "0.988", "size": "34.52", "side": "SELL", "hash": "ed0501189a63ad7b4c1b44cad4bf340161770c93", "best_bid": "0.94", "best_ask": "0.977"}], "timestamp": "1769384490350", "event_type": "price_change"}}
{"_local_timestamp": "2026-01-25T23:41:30.435963+00:00", "data": {"market": "0x9b95e4d85d89a2aa406d7bc683e9b8bb8c7d2b16ee3b44878a36d4e79eeb20ec", "price_changes": [{"asset_id": "39492360553034885301486766992727683306899599890890066102594783083978384204123", "price": "0.001", "size": "76", "side": "BUY", "hash": "740e1633f286a58d9b01f3ace6f0d8b75a8143ba", "best_bid": "0.023", "best_ask": "0.06"}, {"asset_id": "63189790407496871968365678866547561936214310417455881808824200627199091231049", "price": "0.999", "size": "76", "side": "SELL", "hash": "3d55eb8d3affea1a18826464e8abd7fd309602f4", "best_bid": "0.94", "best_ask": "0.977"}], "timestamp": "1769384490351", "event_type": "price_change"}}
{"_local_timestamp": "2026-01-25T23:41:30.442796+00:00", "data": {"market": "0x9b95e4d85d89a2aa406d7bc683e9b8bb8c7d2b16ee3b44878a36d4e79eeb20ec", "price_changes": [{"asset_id": "39492360553034885301486766992727683306899599890890066102594783083978384204123", "price": "0.001", "size": "95.38", "side": "BUY", "hash": "90a057fa8aad32004d77bc96fa421dace7d8a2b2", "best_bid": "0.023", "best_ask": "0.06"}, {"asset_id": "63189790407496871968365678866547561936214310417455881808824200627199091231049", "price": "0.999", "size": "95.38", "side": "SELL", "hash": "f8091ff2e321f6dd3c581cd4ec834764df387a6a", "best_bid": "0.94", "best_ask": "0.977"}], "timestamp": "1769384490352", "event_type": "price_change"}}
{"_local_timestamp": "2026-01-25T23:41:31.080372+00:00", "data": {"market": "0xdb220d70cc76303505355f558407f99958916364c5612685c804fe1267d0f514", "price_changes": [{"asset_id": "29127800831891156918080289096614999289213121001925429958509112072030245798692", "price": "0.03", "size": "919.91", "side": "BUY", "hash": "b1e94a9939f06f2afb9ee7ae0a8dff3b57a402bf", "best_bid": "0.57", "best_ask": "0.97"}, {"asset_id": "89178703372212073978389921580322635269384366327786463025461810229435622804178", "price": "0.97", "size": "919.91", "side": "SELL", "hash": "5661042021af6c99e6a3e2d26032e312f3730dfa", "best_bid": "0.03", "best_ask": "0.43"}], "timestamp": "1769384491000", "event_type": "price_change"}}
{"_local_timestamp": "2026-01-25T23:41:31.096261+00:00", "data": {"market": "0xfa0a910c4380fc83610d9fa68b214b598621ae9bd49dc40df47abd265bf0bc34", "price_changes": [{"asset_id": "42996585481877433482708272870977066259130153781685558286992961170000063507609", "price": "0.02", "size": "0", "side": "BUY", "hash": "f810f673c305f2ac16236a82a1f1d3563143d419", "best_bid": "0.58", "best_ask": "0.94"}, {"asset_id": "59290556380981220753832906409296194214356850812489293134106523641703938483612", "price": "0.98", "size": "0", "side": "SELL", "hash": "0fa83d9226f40f42362436b08e7a00c3486e5554", "best_bid": "0.06", "best_ask": "0.42"}], "timestamp": "1769384491001", "event_type": "price_change"}}
{"_local_timestamp": "2026-01-25T23:41:31.110826+00:00", "data": {"market": "0x9b95e4d85d89a2aa406d7bc683e9b8bb8c7d2b16ee3b44878a36d4e79eeb20ec", "price_changes": [{"asset_id": "63189790407496871968365678866547561936214310417455881808824200627199091231049", "price": "0.38", "size": "30", "side": "BUY", "hash": "342ac489d8064618db88dc2ca626c3a479f553d1", "best_bid": "0.94", "best_ask": "0.977"}, {"asset_id": "39492360553034885301486766992727683306899599890890066102594783083978384204123", "price": "0.62", "size": "30", "side": "SELL", "hash": "9ef5fba1750e0e75d9e0ebb66d19ba5c609ea639", "best_bid": "0.023", "best_ask": "0.06"}], "timestamp": "1769384491000", "event_type": "price_change"}}
{"_local_timestamp": "2026-01-25T23:41:31.123743+00:00", "data": {"market": "0x67d228115cc6ea9eb2dd85ca443c357359e4bdac7f773d8dff9f599cf5f58074", "price_changes": [{"asset_id": "40258076975888759603244407127088084693343108694292687330139582591508023070009", "price": "0.04", "size": "0", "side": "BUY", "hash": "d309bc5af624cda03b4bff04d225ad1541757831", "best_bid": "0.13", "best_ask": "0.15"}, {"asset_id": "115673443932214194570164346004924052532408865542451590692735424434267556754094", "price": "0.96", "size": "0", "side": "SELL", "hash": "b88dcaf904bf82c10cdae9362edea98e8e5eade5", "best_bid": "0.85", "best_ask": "0.87"}], "timestamp": "1769384491000", "event_type": "price_change"}}
{"_local_timestamp": "2026-01-25T23:41:31.133057+00:00", "data": {"market": "0x67d228115cc6ea9eb2dd85ca443c357359e4bdac7f773d8dff9f599cf5f58074", "price_changes": [{"asset_id": "115673443932214194570164346004924052532408865542451590692735424434267556754094", "price": "0.39", "size": "0", "side": "BUY", "hash": "8cab0a15eddee19a76a4f74171616b904b238936", "best_bid": "0.85", "best_ask": "0.87"}, {"asset_id": "40258076975888759603244407127088084693343108694292687330139582591508023070009", "price": "0.61", "size": "0", "side": "SELL", "hash": "95bbb7f411183dccbe8601a0cce530dbbaa8d682", "best_bid": "0.13", "best_ask": "0.15"}], "timestamp": "1769384491002", "event_type": "price_change"}}
{"_local_timestamp": "2026-01-25T23:41:31.144107+00:00", "data": {"market": "0x425351f3d4713b9db2c15a80e1e75a2acf893b5495cc2e694095070137509329", "price_changes": [{"asset_id": "56846561876839441818327131212801941885992894700201726352426446447037474872043", "price": "0.34", "size": "100", "side": "BUY", "hash": "2ef332a43149c7ab7c92bd1c58c8c63071089b55", "best_bid": "0.99", "best_ask": "0.999"}, {"asset_id": "57829021360688395873888125190016504630905168321624137961276880640915115712545", "price": "0.66", "size": "100", "side": "SELL", "hash": "91216d69c43f2e11df3ba741f698aa2482b00c6e", "best_bid": "0.001", "best_ask": "0.01"}], "timestamp": "1769384491002", "event_type": "price_change"}}
{"_local_timestamp": "2026-01-25T23:41:31.155908+00:00", "data": {"market": "0x67d228115cc6ea9eb2dd85ca443c357359e4bdac7f773d8dff9f599cf5f58074", "price_changes": [{"asset_id": "40258076975888759603244407127088084693343108694292687330139582591508023070009", "price": "0.03", "size": "0", "side": "BUY", "hash": "2a74f218270b6006786199ca5f2ba163b0714fd6", "best_bid": "0.13", "best_ask": "0.15"}, {"asset_id": "115673443932214194570164346004924052532408865542451590692735424434267556754094", "price": "0.97", "size": "0", "side": "SELL", "hash": "3adb902c3f70337fb76c6a646b5593d01fbb8532", "best_bid": "0.85", "best_ask": "0.87"}], "timestamp": "1769384491062", "event_type": "price_change"}}
{"_local_timestamp": "2026-01-25T23:41:31.192114+00:00", "data": {"market": "0x67d228115cc6ea9eb2dd85ca443c357359e4bdac7f773d8dff9f599cf5f58074", "price_changes": [{"asset_id": "40258076975888759603244407127088084693343108694292687330139582591508023070009", "price": "0.04", "size": "1270.1", "side": "BUY", "hash": "861d2f5c51dd755feed7b75619b7c4e78160da05", "best_bid": "0.13", "best_ask": "0.15"}, {"asset_id": "115673443932214194570164346004924052532408865542451590692735424434267556754094", "price": "0.96", "size": "1270.1", "side": "SELL", "hash": "9cd209d34e9d7e817007a571d5587a69dce729f1", "best_bid": "0.85", "best_ask": "0.87"}], "timestamp": "1769384491120", "event_type": "price_change"}}
{"_local_timestamp": "2026-01-25T23:41:31.213946+00:00", "data": {"market": "0x67d228115cc6ea9eb2dd85ca443c357359e4bdac7f773d8dff9f599cf5f58074", "price_changes": [{"asset_id": "40258076975888759603244407127088084693343108694292687330139582591508023070009", "price": "0.04", "size": "2160.21", "side": "BUY", "hash": "4a532e83ed65bac5feea994f4d6748393b9890af", "best_bid": "0.13", "best_ask": "0.15"}, {"asset_id": "115673443932214194570164346004924052532408865542451590692735424434267556754094", "price": "0.96", "size": "2160.21", "side": "SELL", "hash": "1b61f2eb41c482f9141d57a1b319644745f38bc6", "best_bid": "0.85", "best_ask": "0.87"}], "timestamp": "1769384491121", "event_type": "price_change"}}
{"_local_timestamp": "2026-01-25T23:41:32.294853+00:00", "data": {"market": "0x9b95e4d85d89a2aa406d7bc683e9b8bb8c7d2b16ee3b44878a36d4e79eeb20ec", "price_changes": [{"asset_id": "63189790407496871968365678866547561936214310417455881808824200627199091231049", "price": "0.93", "size": "0", "side": "BUY", "hash": "c79f6c1c643365b98722a33be92da89d4dfca446", "best_bid": "0.94", "best_ask": "0.977"}, {"asset_id": "39492360553034885301486766992727683306899599890890066102594783083978384204123", "price": "0.07", "size": "0", "side": "SELL", "hash": "ab74d3c3dfe600beae24189a3fe4fd2afbeb6a7f", "best_bid": "0.023", "best_ask": "0.06"}], "timestamp": "1769384492226", "event_type": "price_change"}}
{"_local_timestamp": "2026-01-25T23:41:32.410377+00:00", "data": {"market": "0x67d228115cc6ea9eb2dd85ca443c357359e4bdac7f773d8dff9f599cf5f58074", "price_changes": [{"asset_id": "40258076975888759603244407127088084693343108694292687330139582591508023070009", "price": "0.05", "size": "2000", "side": "BUY", "hash": "50d0a50491f3084e8142a3f2adcad1bc7922f393", "best_bid": "0.13", "best_ask": "0.15"}, {"asset_id": "115673443932214194570164346004924052532408865542451590692735424434267556754094", "price": "0.95", "size": "2000", "side": "SELL", "hash": "0550011fc3627691c296f26ca2db6cb6861cce9c", "best_bid": "0.85", "best_ask": "0.87"}], "timestamp": "1769384492341", "event_type": "price_change"}}
{"_local_timestamp": "2026-01-25T23:41:32.417134+00:00", "data": {"market": "0xdb220d70cc76303505355f558407f99958916364c5612685c804fe1267d0f514", "price_changes": [{"asset_id": "29127800831891156918080289096614999289213121001925429958509112072030245798692", "price": "0.05", "size": "2000", "side": "BUY", "hash": "6652aeb8d6d3a260a5e97ece96c316d2258d4942", "best_bid": "0.57", "best_ask": "0.97"}, {"asset_id": "89178703372212073978389921580322635269384366327786463025461810229435622804178", "price": "0.95", "size": "2000", "side": "SELL", "hash": "ed513e4c4610a1c88a391a43d9842b997b5bbc4f", "best_bid": "0.03", "best_ask": "0.43"}], "timestamp": "1769384492342", "event_type": "price_change"}}
{"_local_timestamp": "2026-01-25T23:41:32.428424+00:00", "data": {"market": "0x67d228115cc6ea9eb2dd85ca443c357359e4bdac7f773d8dff9f599cf5f58074", "price_changes": [{"asset_id": "115673443932214194570164346004924052532408865542451590692735424434267556754094", "price": "0.39", "size": "256", "side": "BUY", "hash": "0b7381f3c203133c2ccc55ea9670c99490b40f58", "best_bid": "0.85", "best_ask": "0.87"}, {"asset_id": "40258076975888759603244407127088084693343108694292687330139582591508023070009", "price": "0.61", "size": "256", "side": "SELL", "hash": "05c604af33d55ce41f5c797e75f02b5cfda8b77b", "best_bid": "0.13", "best_ask": "0.15"}], "timestamp": "1769384492342", "event_type": "price_change"}}
{"_local_timestamp": "2026-01-25T23:41:32.513192+00:00", "data": {"market": "0xdb220d70cc76303505355f558407f99958916364c5612685c804fe1267d0f514", "price_changes": [{"asset_id": "29127800831891156918080289096614999289213121001925429958509112072030245798692", "price": "0.06", "size": "890.11", "side": "BUY", "hash": "0a9b51430511d50c0392cebb2ce191dcc52717a6", "best_bid": "0.57", "best_ask": "0.97"}, {"asset_id": "89178703372212073978389921580322635269384366327786463025461810229435622804178", "price": "0.94", "size": "890.11", "side": "SELL", "hash": "7318bd38889ebc710a9c2f7b02d93a9ba4582fc5", "best_bid": "0.03", "best_ask": "0.43"}], "timestamp": "1769384492430", "event_type": "price_change"}}
{"_local_timestamp": "2026-01-25T23:41:32.519517+00:00", "data": {"market": "0xdb220d70cc76303505355f558407f99958916364c5612685c804fe1267d0f514", "price_changes": [{"asset_id": "29127800831891156918080289096614999289213121001925429958509112072030245798692", "price": "0.06", "size": "2887.22", "side": "BUY", "hash": "aedbca512a54ab19788e0e5c08090327f3ba3dc4", "best_bid": "0.57", "best_ask": "0.97"}, {"asset_id": "89178703372212073978389921580322635269384366327786463025461810229435622804178", "price": "0.94", "size": "2887.22", "side": "SELL", "hash": "79623e2946013d9ba6fa77e5099a43b4c9781a7b", "best_bid": "0.03", "best_ask": "0.43"}], "timestamp": "1769384492431", "event_type": "price_change"}}
{"_local_timestamp": "2026-01-25T23:41:32.526165+00:00", "data": {"market": "0xdb220d70cc76303505355f558407f99958916364c5612685c804fe1267d0f514", "price_changes": [{"asset_id": "29127800831891156918080289096614999289213121001925429958509112072030245798692", "price": "0.06", "size": "4157.32", "side": "BUY", "hash": "0ff78d8b7d513f20eec7bb5e782f0bb023fb5314", "best_bid": "0.57", "best_ask": "0.97"}, {"asset_id": "89178703372212073978389921580322635269384366327786463025461810229435622804178", "price": "0.94", "size": "4157.32", "side": "SELL", "hash": "8d0c5de0882b9aba13fe600cfe5f767d8e85e164", "best_bid": "0.03", "best_ask": "0.43"}], "timestamp": "1769384492432", "event_type": "price_change"}}
{"_local_timestamp": "2026-01-25T23:41:32.532571+00:00", "data": {"market": "0xdb220d70cc76303505355f558407f99958916364c5612685c804fe1267d0f514", "price_changes": [{"asset_id": "29127800831891156918080289096614999289213121001925429958509112072030245798692", "price": "0.05", "size": "2890.11", "side": "BUY", "hash": "31352e817832338c9af43aa392410547c12b392d", "best_bid": "0.57", "best_ask": "0.97"}, {"asset_id": "89178703372212073978389921580322635269384366327786463025461810229435622804178", "price": "0.95", "size": "2890.11", "side": "SELL", "hash": "0bc7f49702de086b3410c73c0ce60041b3e484c6", "best_bid": "0.03", "best_ask": "0.43"}], "timestamp": "1769384492433", "event_type": "price_change"}}
{"_local_timestamp": "2026-01-25T23:41:32.538920+00:00", "data": {"market": "0xdb220d70cc76303505355f558407f99958916364c5612685c804fe1267d0f514", "price_changes": [{"asset_id": "29127800831891156918080289096614999289213121001925429958509112072030245798692", "price": "0.06", "size": "5047.43", "side": "BUY", "hash": "7ff6abf9ad8d12a400e74fbd9589e376946220b5", "best_bid": "0.57", "best_ask": "0.97"}, {"asset_id": "89178703372212073978389921580322635269384366327786463025461810229435622804178", "price": "0.94", "size": "5047.43", "side": "SELL", "hash": "16bd0fa9c106758fb13c20e26fcfdaa9bb7f112d", "best_bid": "0.03", "best_ask": "0.43"}], "timestamp": "1769384492433", "event_type": "price_change"}}
{"_local_timestamp": "2026-01-25T23:41:32.617987+00:00", "data": {"market": "0xfa0a910c4380fc83610d9fa68b214b598621ae9bd49dc40df47abd265bf0bc34", "price_changes": [{"asset_id": "42996585481877433482708272870977066259130153781685558286992961170000063507609", "price": "0.04", "size": "2500", "side": "BUY", "hash": "a27e67b89aed52185bbff45bf595b39aa024fcfe", "best_bid": "0.58", "best_ask": "0.94"}, {"asset_id": "59290556380981220753832906409296194214356850812489293134106523641703938483612", "price": "0.96", "size": "2500", "side": "SELL", "hash": "b5ebf828e830dac2dc4f647227fffb7c38b63446", "best_bid": "0.06", "best_ask": "0.42"}], "timestamp": "1769384492553", "event_type": "price_change"}}
{"_local_timestamp": "2026-01-25T23:41:32.624745+00:00", "data": {"market": "0x9b95e4d85d89a2aa406d7bc683e9b8bb8c7d2b16ee3b44878a36d4e79eeb20ec", "price_changes": [{"asset_id": "63189790407496871968365678866547561936214310417455881808824200627199091231049", "price": "0.38", "size": "292", "side": "BUY", "hash": "c172506602576d44660abd72916d2a1a7e335850", "best_bid": "0.94", "best_ask": "0.977"}, {"asset_id": "39492360553034885301486766992727683306899599890890066102594783083978384204123", "price": "0.62", "size": "292", "side": "SELL", "hash": "7ccd868032a542797693cd2ed6e093fd456cf56e", "best_bid": "0.023", "best_ask": "0.06"}], "timestamp": "1769384492553", "event_type": "price_change"}}
{"_local_timestamp": "2026-01-25T23:41:32.631741+00:00", "data": {"market": "0x425351f3d4713b9db2c15a80e1e75a2acf893b5495cc2e694095070137509329", "price_changes": [{"asset_id": "56846561876839441818327131212801941885992894700201726352426446447037474872043", "price": "0.34", "size": "393", "side": "BUY", "hash": "34e693bdbfd565dc781159980e02c910fcb88f98", "best_bid": "0.99", "best_ask": "0.999"}, {"asset_id": "57829021360688395873888125190016504630905168321624137961276880640915115712545", "price": "0.66", "size": "393", "side": "SELL", "hash": "40a228d5565a236804e68a97dabbf40caf1307ab", "best_bid": "0.001", "best_ask": "0.01"}], "timestamp": "1769384492553", "event_type": "price_change"}}
{"_local_timestamp": "2026-01-25T23:41:32.746409+00:00", "data": {"market": "0xdb220d70cc76303505355f558407f99958916364c5612685c804fe1267d0f514", "price_changes": [{"asset_id": "29127800831891156918080289096614999289213121001925429958509112072030245798692", "price": "0.07", "size": "5999.11", "side": "BUY", "hash": "62e0adf14db2340b0ba8b0724ce3f354b21e8403", "best_bid": "0.57", "best_ask": "0.97"}, {"asset_id": "89178703372212073978389921580322635269384366327786463025461810229435622804178", "price": "0.93", "size": "5999.11", "side": "SELL", "hash": "84ea18cb913b41e3a5dd1b94f175c36b409b46bc", "best_bid": "0.03", "best_ask": "0.43"}], "timestamp": "1769384492663", "event_type": "price_change"}}
{"_local_timestamp": "2026-01-25T23:41:33.701940+00:00", "data": {"market": "0x67d228115cc6ea9eb2dd85ca443c357359e4bdac7f773d8dff9f599cf5f58074", "price_changes": [{"asset_id": "115673443932214194570164346004924052532408865542451590692735424434267556754094", "price": "0.38", "size": "0", "side": "BUY", "hash": "b7704f433127456bad63cb827edcae6b7f79a9ff", "best_bid": "0.85", "best_ask": "0.87"}, {"asset_id": "40258076975888759603244407127088084693343108694292687330139582591508023070009", "price": "0.62", "size": "0", "side": "SELL", "hash": "e65fc0741286d06ec807f6f8b405a693d4db948c", "best_bid": "0.13", "best_ask": "0.15"}], "timestamp": "1769384493636", "event_type": "price_change"}}
{"_local_timestamp": "2026-01-25T23:41:33.775336+00:00", "data": {"market": "0x67d228115cc6ea9eb2dd85ca443c357359e4bdac7f773d8dff9f599cf5f58074", "price_changes": [{"asset_id": "40258076975888759603244407127088084693343108694292687330139582591508023070009", "price": "0.04", "size": "0", "side": "BUY", "hash": "f9ae791f4d78e9ad58bf92b9f9a1d6492604973f", "best_bid": "0.13", "best_ask": "0.15"}, {"asset_id": "115673443932214194570164346004924052532408865542451590692735424434267556754094", "price": "0.96", "size": "0", "side": "SELL", "hash": "d31883709736471441b81e16330b855433e40a3c", "best_bid": "0.85", "best_ask": "0.87"}], "timestamp": "1769384493701", "event_type": "price_change"}}
{"_local_timestamp": "2026-01-25T23:41:33.820834+00:00", "data": {"market": "0x67d228115cc6ea9eb2dd85ca443c357359e4bdac7f773d8dff9f599cf5f58074", "price_changes": [{"asset_id": "115673443932214194570164346004924052532408865542451590692735424434267556754094", "price": "0.86", "size": "300", "side": "BUY", "hash": "099478bd1e2c8427660c651f3fdeb125aaced6a9", "best_bid": "0.86", "best_ask": "0.87"}, {"asset_id": "40258076975888759603244407127088084693343108694292687330139582591508023070009", "price": "0.14", "size": "300", "side": "SELL", "hash": "8114fd9c6d76957f00dd6c09ec895ff491d9c76a", "best_bid": "0.13", "best_ask": "0.14"}], "timestamp": "1769384493705", "event_type": "price_change"}}
{"_local_timestamp": "2026-01-25T23:41:34.955623+00:00", "data": {"market": "0x9b95e4d85d89a2aa406d7bc683e9b8bb8c7d2b16ee3b44878a36d4e79eeb20ec", "price_changes": [{"asset_id": "39492360553034885301486766992727683306899599890890066102594783083978384204123", "price": "0.023", "size": "0", "side": "BUY", "hash": "97da52d5d6303a4b3efd7dd93cf49b1e92b8c9f9", "best_bid": "0.021", "best_ask": "0.06"}, {"asset_id": "63189790407496871968365678866547561936214310417455881808824200627199091231049", "price": "0.977", "size": "0", "side": "SELL", "hash": "14090842d35a178fb34a72501fb927ba4e8870aa", "best_bid": "0.94", "best_ask": "0.979"}], "timestamp": "1769384494883", "event_type": "price_change"}}
{"_local_timestamp": "2026-01-25T23:41:35.003773+00:00", "data": {"market": "0x9b95e4d85d89a2aa406d7bc683e9b8bb8c7d2b16ee3b44878a36d4e79eeb20ec", "price_changes": [{"asset_id": "39492360553034885301486766992727683306899599890890066102594783083978384204123", "price": "0.022", "size": "5.47", "side": "BUY", "hash": "9c500087f00daeffb73e21a49261d944ef396882", "best_bid": "0.022", "best_ask": "0.06"}, {"asset_id": "63189790407496871968365678866547561936214310417455881808824200627199091231049", "price": "0.978", "size": "5.47", "side": "SELL", "hash": "7f0dd6f4b85daeac2872746dd26ffec90c7e89e9", "best_bid": "0.94", "best_ask": "0.978"}], "timestamp": "1769384494928", "event_type": "price_change"}}
{"_local_timestamp": "2026-01-25T23:41:35.163920+00:00", "data": {"market": "0x9b95e4d85d89a2aa406d7bc683e9b8bb8c7d2b16ee3b44878a36d4e79eeb20ec", "price_changes": [{"asset_id": "63189790407496871968365678866547561936214310417455881808824200627199091231049", "price": "0.01", "size": "3738", "side": "BUY", "hash": "8d1ce269854cdfb7cae84ab7d1e9ee9b9e7091f9", "best_bid": "0.94", "best_ask": "0.978"}, {"asset_id": "39492360553034885301486766992727683306899599890890066102594783083978384204123", "price": "0.99", "size": "3738", "side": "SELL", "hash": "d932b76840c11417a43ae16eab6c8f0db50eac70", "best_bid": "0.022", "best_ask": "0.06"}], "timestamp": "1769384495084", "event_type": "price_change"}}
{"_local_timestamp": "2026-01-25T23:41:35.171893+00:00", "data": {"market": "0x9b95e4d85d89a2aa406d7bc683e9b8bb8c7d2b16ee3b44878a36d4e79eeb20ec", "price_changes": [{"asset_id": "63189790407496871968365678866547561936214310417455881808824200627199091231049", "price": "0.03", "size": "0", "side": "BUY", "hash": "8d1ce269854cdfb7cae84ab7d1e9ee9b9e7091f9", "best_bid": "0.94", "best_ask": "0.978"}, {"asset_id": "39492360553034885301486766992727683306899599890890066102594783083978384204123", "price": "0.97", "size": "0", "side": "SELL", "hash": "d932b76840c11417a43ae16eab6c8f0db50eac70", "best_bid": "0.022", "best_ask": "0.06"}], "timestamp": "1769384495084", "event_type": "price_change"}}
{"_local_timestamp": "2026-01-25T23:41:35.197160+00:00", "data": {"market": "0x9b95e4d85d89a2aa406d7bc683e9b8bb8c7d2b16ee3b44878a36d4e79eeb20ec", "price_changes": [{"asset_id": "63189790407496871968365678866547561936214310417455881808824200627199091231049", "price": "0.11", "size": "700", "side": "BUY", "hash": "8d1ce269854cdfb7cae84ab7d1e9ee9b9e7091f9", "best_bid": "0.94", "best_ask": "0.978"}, {"asset_id": "39492360553034885301486766992727683306899599890890066102594783083978384204123", "price": "0.89", "size": "700", "side": "SELL", "hash": "d932b76840c11417a43ae16eab6c8f0db50eac70", "best_bid": "0.022", "best_ask": "0.06"}], "timestamp": "1769384495084", "event_type": "price_change"}}
{"_local_timestamp": "2026-01-25T23:41:35.613883+00:00", "data": {"market": "0x9b95e4d85d89a2aa406d7bc683e9b8bb8c7d2b16ee3b44878a36d4e79eeb20ec", "price_changes": [{"asset_id": "63189790407496871968365678866547561936214310417455881808824200627199091231049", "price": "0.001", "size": "6034.23", "side": "BUY", "hash": "8d207aefa7c02799fe9b2ae6728b490d3c96c538", "best_bid": "0.94", "best_ask": "0.978"}, {"asset_id": "39492360553034885301486766992727683306899599890890066102594783083978384204123", "price": "0.999", "size": "6034.23", "side": "SELL", "hash": "3e74c8d604a0ed33d2de72148da7fcf58bd5192f", "best_bid": "0.022", "best_ask": "0.06"}], "timestamp": "1769384495549", "event_type": "price_change"}}
{"_local_timestamp": "2026-01-25T23:41:35.622292+00:00", "data": {"market": "0x9b95e4d85d89a2aa406d7bc683e9b8bb8c7d2b16ee3b44878a36d4e79eeb20ec", "price_changes": [{"asset_id": "63189790407496871968365678866547561936214310417455881808824200627199091231049", "price": "0.011", "size": "8.45", "side": "BUY", "hash": "449c25689ce5112d694829b6c489f60cc8f0bfd0", "best_bid": "0.94", "best_ask": "0.978"}, {"asset_id": "39492360553034885301486766992727683306899599890890066102594783083978384204123", "price": "0.989", "size": "8.45", "side": "SELL", "hash": "67627286236d78dc54cbaeab231fa05f99a7088e", "best_bid": "0.022", "best_ask": "0.06"}], "timestamp": "1769384495550", "event_type": "price_change"}}
{"_local_timestamp": "2026-01-25T23:41:35.629376+00:00", "data": {"market": "0x9b95e4d85d89a2aa406d7bc683e9b8bb8c7d2b16ee3b44878a36d4e79eeb20ec", "price_changes": [{"asset_id": "63189790407496871968365678866547561936214310417455881808824200627199091231049", "price": "0.111", "size": "5.1", "side": "BUY", "hash": "7d99f079e7e370a1621107d6ae4d76ab85df0629", "best_bid": "0.94", "best_ask": "0.978"}, {"asset_id": "39492360553034885301486766992727683306899599890890066102594783083978384204123", "price": "0.889", "size": "5.1", "side": "SELL", "hash": "d860fc161fc3f03046bf59d51f1f3c86dd318914", "best_bid": "0.022", "best_ask": "0.06"}], "timestamp": "1769384495551", "event_type": "price_change"}}
{"_local_timestamp": "2026-01-25T23:41:35.641598+00:00", "data": {"market": "0x9b95e4d85d89a2aa406d7bc683e9b8bb8c7d2b16ee3b44878a36d4e79eeb20ec", "price_changes": [{"asset_id": "63189790407496871968365678866547561936214310417455881808824200627199091231049", "price": "0.002", "size": "22.5", "side": "BUY", "hash": "72ced65034a5fb4d633d7ac461c1c3049c07ee67", "best_bid": "0.94", "best_ask": "0.978"}, {"asset_id": "39492360553034885301486766992727683306899599890890066102594783083978384204123", "price": "0.998", "size": "22.5", "side": "SELL", "hash": "1f2a229f3d29f205efdd9d47248f2cad3f036dd9", "best_bid": "0.022", "best_ask": "0.06"}], "timestamp": "1769384495552", "event_type": "price_change"}}
{"_local_timestamp": "2026-01-25T23:41:35.651168+00:00", "data": {"market": "0x9b95e4d85d89a2aa406d7bc683e9b8bb8c7d2b16ee3b44878a36d4e79eeb20ec", "price_changes": [{"asset_id": "63189790407496871968365678866547561936214310417455881808824200627199091231049", "price": "0.031", "size": "9.37", "side": "BUY", "hash": "df7eded993e6039c39ee72e6016d44b98c0230e4", "best_bid": "0.94", "best_ask": "0.978"}, {"asset_id": "39492360553034885301486766992727683306899599890890066102594783083978384204123", "price": "0.969", "size": "9.37", "side": "SELL", "hash": "704687beb9a4a0cfe539f09c5890c12802e1969d", "best_bid": "0.022", "best_ask": "0.06"}], "timestamp": "1769384495553", "event_type": "price_change"}}
{"_local_timestamp": "2026-01-25T23:41:37.070761+00:00", "data": {"market": "0x9b95e4d85d89a2aa406d7bc683e9b8bb8c7d2b16ee3b44878a36d4e79eeb20ec", "price_changes": [{"asset_id": "63189790407496871968365678866547561936214310417455881808824200627199091231049", "price": "0.38", "size": "30", "side": "BUY", "hash": "88c864c9a7e3e8e3295620b65e213b092467199a", "best_bid": "0.94", "best_ask": "0.978"}, {"asset_id": "39492360553034885301486766992727683306899599890890066102594783083978384204123", "price": "0.62", "size": "30", "side": "SELL", "hash": "d3c7edb58081cf115f953f03f3feb1243bbb3647", "best_bid": "0.022", "best_ask": "0.06"}], "timestamp": "1769384497000", "event_type": "price_change"}}
{"_local_timestamp": "2026-01-25T23:41:37.077593+00:00", "data": {"market": "0x67d228115cc6ea9eb2dd85ca443c357359e4bdac7f773d8dff9f599cf5f58074", "price_changes": [{"asset_id": "115673443932214194570164346004924052532408865542451590692735424434267556754094", "price": "0.39", "size": "0", "side": "BUY", "hash": "5d658405c1b6578804af9d429694d4b41e2693bb", "best_bid": "0.86", "best_ask": "0.87"}, {"asset_id": "40258076975888759603244407127088084693343108694292687330139582591508023070009", "price": "0.61", "size": "0", "side": "SELL", "hash": "0a9912f37d33deef3a0e5bb46f2f2e03f3dd78ae", "best_bid": "0.13", "best_ask": "0.14"}], "timestamp": "1769384497000", "event_type": "price_change"}}
{"_local_timestamp": "2026-01-25T23:41:37.084205+00:00", "data": {"market": "0xfa0a910c4380fc83610d9fa68b214b598621ae9bd49dc40df47abd265bf0bc34", "price_changes": [{"asset_id": "42996585481877433482708272870977066259130153781685558286992961170000063507609", "price": "0.04", "size": "0", "side": "BUY", "hash": "dfd330167c11b97eb380c602c3c9cb585b69f5ec", "best_bid": "0.58", "best_ask": "0.94"}, {"asset_id": "59290556380981220753832906409296194214356850812489293134106523641703938483612", "price": "0.96", "size": "0", "side": "SELL", "hash": "f5de026a2d2ebc2db19d8ab0fe85968d4ef285ce", "best_bid": "0.06", "best_ask": "0.42"}], "timestamp": "1769384497000", "event_type": "price_change"}}
{"_local_timestamp": "2026-01-25T23:41:37.090783+00:00", "data": {"market": "0xdb220d70cc76303505355f558407f99958916364c5612685c804fe1267d0f514", "price_changes": [{"asset_id": "29127800831891156918080289096614999289213121001925429958509112072030245798692", "price": "0.05", "size": "890.11", "side": "BUY", "hash": "ea6230a07b3218c446c8e2e1de5ccc81e9584ca0", "best_bid": "0.57", "best_ask": "0.97"}, {"asset_id": "89178703372212073978389921580322635269384366327786463025461810229435622804178", "price": "0.95", "size": "890.11", "side": "SELL", "hash": "bc04f2038ec7bb77da5927b81a85fca2542bcd9b", "best_bid": "0.03", "best_ask": "0.43"}], "timestamp": "1769384497000", "event_type": "price_change"}}
{"_local_timestamp": "2026-01-25T23:41:37.097909+00:00", "data": {"market": "0x67d228115cc6ea9eb2dd85ca443c357359e4bdac7f773d8dff9f599cf5f58074", "price_changes": [{"asset_id": "40258076975888759603244407127088084693343108694292687330139582591508023070009", "price": "0.05", "size": "0", "side": "BUY", "hash": "e0baa710e85693db3a2ab29497a35eca9f66a16d", "best_bid": "0.13", "best_ask": "0.14"}, {"asset_id": "115673443932214194570164346004924052532408865542451590692735424434267556754094", "price": "0.95", "size": "0", "side": "SELL", "hash": "559098a5fc652333c2d76e79a1a71e9fe500113e", "best_bid": "0.86", "best_ask": "0.87"}], "timestamp": "1769384497001", "event_type": "price_change"}}
{"_local_timestamp": "2026-01-25T23:41:37.104882+00:00", "data": {"market": "0x425351f3d4713b9db2c15a80e1e75a2acf893b5495cc2e694095070137509329", "price_changes": [{"asset_id": "56846561876839441818327131212801941885992894700201726352426446447037474872043", "price": "0.34", "size": "100", "side": "BUY", "hash": "2beb64060028a7398b603527dacba267e981fbb6", "best_bid": "0.99", "best_ask": "0.999"}, {"asset_id": "57829021360688395873888125190016504630905168321624137961276880640915115712545", "price": "0.66", "size": "100", "side": "SELL", "hash": "6bd6d72a1ae4f5af4f4cfedd68627f0d5cea77b2", "best_bid": "0.001", "best_ask": "0.01"}], "timestamp": "1769384497002", "event_type": "price_change"}}
{"_local_timestamp": "2026-01-25T23:41:37.136943+00:00", "data": {"market": "0x67d228115cc6ea9eb2dd85ca443c357359e4bdac7f773d8dff9f599cf5f58074", "price_changes": [{"asset_id": "40258076975888759603244407127088084693343108694292687330139582591508023070009", "price": "0.01", "size": "3400.21", "side": "BUY", "hash": "f95a22146847f189a68861121acb543a050eef08", "best_bid": "0.13", "best_ask": "0.14"}, {"asset_id": "115673443932214194570164346004924052532408865542451590692735424434267556754094", "price": "0.99", "size": "3400.21", "side": "SELL", "hash": "18df87dc33738036608b957fff04cb034a8f2237", "best_bid": "0.86", "best_ask": "0.87"}], "timestamp": "1769384497050", "event_type": "price_change"}}
{"_local_timestamp": "2026-01-25T23:41:37.143786+00:00", "data": {"market": "0xdb220d70cc76303505355f558407f99958916364c5612685c804fe1267d0f514", "price_changes": [{"asset_id": "29127800831891156918080289096614999289213121001925429958509112072030245798692", "price": "0.04", "size": "0", "side": "BUY", "hash": "18471028f5c0803d930765bb9775b7c48d405872", "best_bid": "0.57", "best_ask": "0.97"}, {"asset_id": "89178703372212073978389921580322635269384366327786463025461810229435622804178", "price": "0.96", "size": "0", "side": "SELL", "hash": "89fc23b0cb25151b1ca9b9b7ebd175429394f0fc", "best_bid": "0.03", "best_ask": "0.43"}], "timestamp": "1769384497050", "event_type": "price_change"}}
{"_local_timestamp": "2026-01-25T23:41:37.150502+00:00", "data": {"market": "0xdb220d70cc76303505355f558407f99958916364c5612685c804fe1267d0f514", "price_changes": [{"asset_id": "29127800831891156918080289096614999289213121001925429958509112072030245798692", "price": "0.03", "size": "29.8", "side": "BUY", "hash": "18471028f5c0803d930765bb9775b7c48d405872", "best_bid": "0.57", "best_ask": "0.97"}, {"asset_id": "89178703372212073978389921580322635269384366327786463025461810229435622804178", "price": "0.97", "size": "29.8", "side": "SELL", "hash": "89fc23b0cb25151b1ca9b9b7ebd175429394f0fc", "best_bid": "0.03", "best_ask": "0.43"}], "timestamp": "1769384497050", "event_type": "price_change"}}
{"_local_timestamp": "2026-01-25T23:41:37.157229+00:00", "data": {"market": "0xdb220d70cc76303505355f558407f99958916364c5612685c804fe1267d0f514", "price_changes": [{"asset_id": "29127800831891156918080289096614999289213121001925429958509112072030245798692", "price": "0.07", "size": "0", "side": "BUY", "hash": "18471028f5c0803d930765bb9775b7c48d405872", "best_bid": "0.57", "best_ask": "0.97"}, {"asset_id": "89178703372212073978389921580322635269384366327786463025461810229435622804178", "price": "0.93", "size": "0", "side": "SELL", "hash": "89fc23b0cb25151b1ca9b9b7ebd175429394f0fc", "best_bid": "0.03", "best_ask": "0.43"}], "timestamp": "1769384497050", "event_type": "price_change"}}
{"_local_timestamp": "2026-01-25T23:41:37.199589+00:00", "data": {"market": "0x67d228115cc6ea9eb2dd85ca443c357359e4bdac7f773d8dff9f599cf5f58074", "price_changes": [{"asset_id": "40258076975888759603244407127088084693343108694292687330139582591508023070009", "price": "0.06", "size": "890.11", "side": "BUY", "hash": "2d4b87365e020d909afe1ddc6c976caf291087ae", "best_bid": "0.13", "best_ask": "0.14"}, {"asset_id": "115673443932214194570164346004924052532408865542451590692735424434267556754094", "price": "0.94", "size": "890.11", "side": "SELL", "hash": "d60973dd801bf5dcc9e6c34e05299a46d3d8e0f7", "best_bid": "0.86", "best_ask": "0.87"}], "timestamp": "1769384497111", "event_type": "price_change"}}
{"_local_timestamp": "2026-01-25T23:41:37.207347+00:00", "data": {"market": "0xdb220d70cc76303505355f558407f99958916364c5612685c804fe1267d0f514", "price_changes": [{"asset_id": "29127800831891156918080289096614999289213121001925429958509112072030245798692", "price": "0.07", "size": "890.11", "side": "BUY", "hash": "1558e4b70f3842fe1451b4b745d48c54d865257a", "best_bid": "0.57", "best_ask": "0.97"}, {"asset_id": "89178703372212073978389921580322635269384366327786463025461810229435622804178", "price": "0.93", "size": "890.11", "side": "SELL", "hash": "369d0ca7db30e0c2cfd7c1d3931f8d35c014b86e", "best_bid": "0.03", "best_ask": "0.43"}], "timestamp": "1769384497111", "event_type": "price_change"}}
{"_local_timestamp": "2026-01-25T23:41:37.216409+00:00", "data": {"market": "0x67d228115cc6ea9eb2dd85ca443c357359e4bdac7f773d8dff9f599cf5f58074", "price_changes": [{"asset_id": "40258076975888759603244407127088084693343108694292687330139582591508023070009", "price": "0.02", "size": "2018.2", "side": "BUY", "hash": "7e4d1da692a278e23688199a5252934ecf6894b5", "best_bid": "0.13", "best_ask": "0.14"}, {"asset_id": "115673443932214194570164346004924052532408865542451590692735424434267556754094", "price": "0.98", "size": "2018.2", "side": "SELL", "hash": "8cc343517acadb098497ef60f7e65a2c30be36ae", "best_bid": "0.86", "best_ask": "0.87"}], "timestamp": "1769384497112", "event_type": "price_change"}}
{"_local_timestamp": "2026-01-25T23:41:37.226305+00:00", "data": {"market": "0xdb220d70cc76303505355f558407f99958916364c5612685c804fe1267d0f514", "price_changes": [{"asset_id": "29127800831891156918080289096614999289213121001925429958509112072030245798692", "price": "0.08", "size": "1270.1", "side": "BUY", "hash": "ca4f89815c454a09e4b02107f3d1488e023018a4", "best_bid": "0.57", "best_ask": "0.97"}, {"asset_id": "89178703372212073978389921580322635269384366327786463025461810229435622804178", "price": "0.92", "size": "1270.1", "side": "SELL", "hash": "1935d0f311994f6d100dca89065854d0c46397f0", "best_bid": "0.03", "best_ask": "0.43"}], "timestamp": "1769384497112", "event_type": "price_change"}}
{"_local_timestamp": "2026-01-25T23:41:37.232946+00:00", "data": {"market": "0x67d228115cc6ea9eb2dd85ca443c357359e4bdac7f773d8dff9f599cf5f58074", "price_changes": [{"asset_id": "40258076975888759603244407127088084693343108694292687330139582591508023070009", "price": "0.02", "size": "3288.3", "side": "BUY", "hash": "404b56e0ff6a41e233904cc4789f41faa36d09dd", "best_bid": "0.13", "best_ask": "0.14"}, {"asset_id": "115673443932214194570164346004924052532408865542451590692735424434267556754094", "price": "0.98", "size": "3288.3", "side": "SELL", "hash": "5b53c7eeb67c2586db0937326ce6a51d79f219d0", "best_bid": "0.86", "best_ask": "0.87"}], "timestamp": "1769384497112", "event_type": "price_change"}}
{"_local_timestamp": "2026-01-25T23:41:37.241182+00:00", "data": {"market": "0xdb220d70cc76303505355f558407f99958916364c5612685c804fe1267d0f514", "price_changes": [{"asset_id": "29127800831891156918080289096614999289213121001925429958509112072030245798692", "price": "0.08", "size": "2160.21", "side": "BUY", "hash": "427c074f3e37ec04e8c7c40741331db2f9f659bf", "best_bid": "0.57", "best_ask": "0.97"}, {"asset_id": "89178703372212073978389921580322635269384366327786463025461810229435622804178", "price": "0.92", "size": "2160.21", "side": "SELL", "hash": "68998a929931ee99d2fd3542745a2df87bead75c", "best_bid": "0.03", "best_ask": "0.43"}], "timestamp": "1769384497113", "event_type": "price_change"}}
{"_local_timestamp": "2026-01-25T23:41:37.254869+00:00", "data": {"market": "0xdb220d70cc76303505355f558407f99958916364c5612685c804fe1267d0f514", "price_changes": [{"asset_id": "29127800831891156918080289096614999289213121001925429958509112072030245798692", "price": "0.08", "size": "4157.32", "side": "BUY", "hash": "1d1ca624fd1244492d67e20ec68986f4f3c9dda5", "best_bid": "0.57", "best_ask": "0.97"}, {"asset_id": "89178703372212073978389921580322635269384366327786463025461810229435622804178", "price": "0.92", "size": "4157.32", "side": "SELL", "hash": "821ad6b0a3db0b02b0f35ccfbebaff8c38b6087d", "best_bid": "0.03", "best_ask": "0.43"}], "timestamp": "1769384497113", "event_type": "price_change"}}
{"_local_timestamp": "2026-01-25T23:41:37.268707+00:00", "data": {"market": "0xdb220d70cc76303505355f558407f99958916364c5612685c804fe1267d0f514", "price_changes": [{"asset_id": "29127800831891156918080289096614999289213121001925429958509112072030245798692", "price": "0.08", "size": "5047.43", "side": "BUY", "hash": "05db4e67350d7872a1ab9b1569d116bf4e684d80", "best_bid": "0.57", "best_ask": "0.97"}, {"asset_id": "89178703372212073978389921580322635269384366327786463025461810229435622804178", "price": "0.92", "size": "5047.43", "side": "SELL", "hash": "49589a4646dda0797919236c240c6a3584382bd2", "best_bid": "0.03", "best_ask": "0.43"}], "timestamp": "1769384497114", "event_type": "price_change"}}
{"_local_timestamp": "2026-01-25T23:41:37.279814+00:00", "data": {"market": "0xdb220d70cc76303505355f558407f99958916364c5612685c804fe1267d0f514", "price_changes": [{"asset_id": "29127800831891156918080289096614999289213121001925429958509112072030245798692", "price": "0.08", "size": "11046.54", "side": "BUY", "hash": "bace142e55338be5d9403603426c84451475aa03", "best_bid": "0.57", "best_ask": "0.97"}, {"asset_id": "89178703372212073978389921580322635269384366327786463025461810229435622804178", "price": "0.92", "size": "11046.54", "side": "SELL", "hash": "fd920a3cc8b0828c22a8f153caa20c20631ef0fe", "best_bid": "0.03", "best_ask": "0.43"}], "timestamp": "1769384497115", "event_type": "price_change"}}
