{"_local_timestamp": "2026-01-25T23:41:24.221888+00:00", "data": [{"market": "0xcbea6c3471ea8b215444d67f846b854e3521052ca81c5da54e28c67b75e2b4af", "asset_id": "33099871202932815813672406852650911685480454775588544697727678676727391722745", "timestamp": "1769383981552", "hash": "6928c6f9e66e82e2071f4334826dabf91652af23", "bids": [{"price": "0.01", "size": "10451.22"}, {"price": "0.02", "size": "42.6"}, {"price": "0.06", "size": "1140.11"}, {"price": "0.07", "size": "895.58"}], "asks": [{"price": "0.99", "size": "10457.81"}, {"price": "0.98", "size": "1150.28"}, {"price": "0.97", "size": "942.68"}], "event_type": "book", "last_trade_price": ""}, {"market": "0xc1977bee61f67d9d6cea3f7b16d094896bdb1faefa0f9df9ea0a067daab48981", "asset_id": "78110974122162464943361433845382554746323675076814300820011415551303694081660", "timestamp": "1769383981299", "hash": "a83e895882be1f79abe76ae168c18c8aa03b7e3e", "bids": [{"price": "0.01", "size": "10402.72"}, {"price": "0.02", "size": "157.03"}, {"price": "0.03", "size": "23.71"}, {"price": "0.06", "size": "1140.11"}, {"price": "0.07", "size": "895.58"}], "asks": [{"price": "0.99", "size": "11300.08"}, {"price": "0.98", "size": "1050.59"}, {"price": "0.97", "size": "81.65"}, {"price": "0.96", "size": "39.24"}], "event_type": "book", "last_trade_price": ""}, {"market": "0x1d6d4f714e1be97bfd2a112c13ced647780bd0829b3e545910c1091757b18c81", "asset_id": "94751106162810758469635598299477140880810029265761105387257884537048035917975", "timestamp": "1769383972889", "hash": "392810b7efd9ae333548a52b958b06ea6c7e4692", "bids": [{"price": "0.01", "size": "11347.92"}, {"price": "0.02", "size": "260.17"}, {"price": "0.03", "size": "52.57"}], "asks": [{"price": "0.99", "size": "11341.33"}, {"price": "0.98", "size": "42.6"}, {"price": "0.94", "size": "250"}, {"price": "0.93", "size": "5.47"}], "event_type": "book", "last_trade_price": ""}, {"market": "0x14a59fd43a48ef0bb90a5f63a6940fb6a62acf00f14710407cb340a6e555e427", "asset_id": "32309374624748192362666880759096858495442910952630564264751928146985382753863", "timestamp": "1769384272330", "hash": "f6621ddda37f9e40f6a5af5eacd10cfea3152558", "bids": [{"price": "0.01", "size": "202.09"}, {"price": "0.02", "size": "160.48"}, {"price": "0.03", "size": "94.65"}, {"price": "0.04", "size": "9.25"}, {"price": "0.05", "size": "5.47"}], "asks": [{"price": "0.99", "size": "202.04"}, {"price": "0.98", "size": "217.48"}, {"price": "0.97", "size": "18.99"}, {"price": "0.96", "size": "29.99"}], "event_type": "book", "last_trade_price": ""}, {"market": "0xcbea6c3471ea8b215444d67f846b854e3521052ca81c5da54e28c67b75e2b4af", "asset_id": "107998120458739374164579880988037485263306867024048287454086251494415567001697", "timestamp": "1769383981552", "hash": "f55265fedc6992d6908fc679f5ec93e4bbd7306e", "bids": [{"price": "0.01", "size": "10457.81"}, {"price": "0.02", "size": "1150.28"}, {"price": "0.03", "size": "942.68"}], "asks": [{"price": "0.99", "size": "10451.22"}, {"price": "0.98", "size": "42.6"}, {"price": "0.94", "size": "1140.11"}, {"price": "0.93", "size": "895.58"}], "event_type": "book", "last_trade_price": ""}, {"market": "0x14a59fd43a48ef0bb90a5f63a6940fb6a62acf00f14710407cb340a6e555e427", "asset_id": "33860025332294261066339194986447657969774333993404072754488955408971762620870", "timestamp": "1769384272330", "hash": "68db6c33f506b31ac5dbad461a16478aec9dcf8a", "bids": [{"price": "0.01", "size": "202.04"}, {"price": "0.02", "size": "217.48"}, {"price": "0.03", "size": "18.99"}, {"price": "0.04", "size": "29.99"}], "asks": [{"price": "0.99", "size": "202.09"}, {"price": "0.98", "size": "160.48"}, {"price": "0.97", "size": "94.65"}, {"price": "0.96", "size": "9.25"}, {"price": "0.95", "size": "5.47"}], "event_type": "book", "last_trade_price": ""}, {"market": "0xfaba55442a17a201a46f7ac19fd9394364f04959cdebfa420bc0c5ab2da00f59", "asset_id": "76829378806632943504106553503686063944439990588195206882350689917773385019771", "timestamp": "1769384442851", "hash": "ea7edf8861335d6eb1097b84d1a3ae15b45a5a6c", "bids": [{"price": "0.01", "size": "8888.99"}, {"price": "0.02", "size": "2100"}, {"price": "0.03", "size": "9.24"}, {"price": "0.07", "size": "1700"}, {"price": "0.09", "size": "6.93"}, {"price": "0.1", "size": "700"}, {"price": "0.15", "size": "250"}, {"price": "0.2", "size": "400"}, {"price": "0.32", "size": "300"}, {"price": "0.36", "size": "200"}, {"price": "0.39", "size": "125"}, {"price": "0.42", "size": "75"}, {"price": "0.5", "size": "10"}, {"price": "0.51", "size": "1090.11"}, {"price": "0.52", "size": "890.11"}, {"price": "0.58", "size": "100"}, {"price": "0.64", "size": "10"}, {"price": "0.65", "size": "147"}], "asks": [{"price": "0.99", "size": "4442.84"}, {"price": "0.98", "size": "19.96"}, {"price": "0.94", "size": "500"}, {"price": "0.93", "size": "200"}, {"price": "0.91", "size": "1196.17"}, {"price": "0.9", "size": "890.11"}, {"price": "0.87", "size": "10"}, {"price": "0.82", "size": "150"}, {"price": "0.81", "size": "10"}], "event_type": "book", "last_trade_price": "0.610"}, {"market": "0xc1977bee61f67d9d6cea3f7b16d094896bdb1faefa0f9df9ea0a067daab48981", "asset_id": "9107106424097962766712091054809455692614685520938052843170925105261136451803", "timestamp": "1769383981299", "hash": "8a020cb7d39a7e15611bc2ca71bca612a5f8e4c3", "bids": [{"price": "0.01", "size": "11300.08"}, {"price": "0.02", "size": "1050.59"}, {"price": "0.03", "size": "81.65"}, {"price": "0.04", "size": "39.24"}], "asks": [{"price": "0.99", "size": "10402.72"}, {"price": "0.98", "size": "157.03"}, {"price": "0.97", "size": "23.71"}, {"price": "0.94", "size": "1140.11"}, {"price": "0.93", "size": "895.58"}], "event_type": "book", "last_trade_price": ""}, {"market": "0x1d6d4f714e1be97bfd2a112c13ced647780bd0829b3e545910c1091757b18c81", "asset_id": "33666667036043018404210254603112951549362289355609395556964374214631339766666", "timestamp": "1769383972889", "hash": "7db0dff9bbc5f18acb42c73c3ac0ff645565ac26", "bids": [{"price": "0.01", "size": "11341.33"}, {"price": "0.02", "size": "42.6"}, {"price": "0.06", "size": "250"}, {"price": "0.07", "size": "5.47"}], "asks": [{"price": "0.99", "size": "11347.92"}, {"price": "0.98", "size": "260.17"}, {"price": "0.97", "size": "52.57"}], "event_type": "book", "last_trade_price": ""}, {"market": "0xfaba55442a17a201a46f7ac19fd9394364f04959cdebfa420bc0c5ab2da00f59", "asset_id": "103206131584345534219777803662235735845312981950233075829729747631018349006817", "timestamp": "1769384442851", "hash": "219fd33fbd58b93849b047a2252abbc00ac8fced", "bids": [{"price": "0.01", "size": "4442.84"}, {"price": "0.02", "size": "19.96"}, {"price": "0.06", "size": "500"}, {"price": "0.07", "size": "200"}, {"price": "0.09", "size": "1196.17"}, {"price": "0.1", "size": "890.11"}, {"price": "0.13", "size": "10"}, {"price": "0.18", "size": "150"}, {"price": "0.19", "size": "10"}], "asks": [{"price": "0.99", "size": "8888.99"}, {"price": "0.98", "size": "2100"}, {"price": "0.97", "size": "9.24"}, {"price": "0.93", "size": "1700"}, {"price": "0.91", "size": "6.93"}, {"price": "0.9", "size": "700"}, {"price": "0.85", "size": "250"}, {"price": "0.8", "size": "400"}, {"price": "0.68", "size": "300"}, {"price": "0.64", "size": "200"}, {"price": "0.61", "size": "125"}, {"price": "0.58", "size": "75"}, {"price": "0.5", "size": "10"}, {"price": "0.49", "size": "1090.11"}, {"price": "0.48", "size": "890.11"}, {"price": "0.42", "size": "100"}, {"price": "0.36", "size": "10"}, {"price": "0.35", "size": "147"}], "event_type": "book", "last_trade_price": "0.610"}]}
{"_local_timestamp": "2026-01-25T23:41:27.147742+00:00", "data": {"market": "0xc1977bee61f67d9d6cea3f7b16d094896bdb1faefa0f9df9ea0a067daab48981", "price_changes": [{"asset_id": "9107106424097962766712091054809455692614685520938052843170925105261136451803", "price": "0.02", "size": "900.59", "side": "BUY", "hash": "e6a1d98f8973d3d915f8e1e21d6286c4bc96cdfd", "best_bid": "0.04", "best_ask": "0.93"}, {"asset_id": "78110974122162464943361433845382554746323675076814300820011415551303694081660", "price": "0.98", "size": "900.59", "side": "SELL", "hash": "d68cf7753b1f52bc5975c2e64237ebe36e37c24e", "best_bid": "0.07", "best_ask": "0.96"}], "timestamp": "1769384487000", "event_type": "price_change"}}
{"_local_timestamp": "2026-01-25T23:41:27.151123+00:00", "data": {"market": "0xc1977bee61f67d9d6cea3f7b16d094896bdb1faefa0f9df9ea0a067daab48981", "price_changes": [{"asset_id": "78110974122162464943361433845382554746323675076814300820011415551303694081660", "price": "0.02", "size": "7.03", "side": "BUY", "hash": "7a4d535993039f732c3a439b017f41c5444b48be", "best_bid": "0.07", "best_ask": "0.96"}, {"asset_id": "9107106424097962766712091054809455692614685520938052843170925105261136451803", "price": "0.98", "size": "7.03", "side": "SELL", "hash": "8eb107dfe1e34176886c2332928c277cccc8a807", "best_bid": "0.04", "best_ask": "0.93"}], "timestamp": "1769384487001", "event_type": "price_change"}}
{"_local_timestamp": "2026-01-25T23:41:33.931371+00:00", "data": {"market": "0xc1977bee61f67d9d6cea3f7b16d094896bdb1faefa0f9df9ea0a067daab48981", "price_changes": [{"asset_id": "9107106424097962766712091054809455692614685520938052843170925105261136451803", "price": "0.02", "size": "1050.59", "side": "BUY", "hash": "5a9b99b895246ad7d0518e61a81021fecc3e689a", "best_bid": "0.04", "best_ask": "0.93"}, {"asset_id": "78110974122162464943361433845382554746323675076814300820011415551303694081660", "price": "0.98", "size": "1050.59", "side": "SELL", "hash": "4a57496f9fa967f151b77d761aaf2157350d8015", "best_bid": "0.07", "best_ask": "0.96"}], "timestamp": "1769384493776", "event_type": "price_change"}}
{"_local_timestamp": "2026-01-25T23:41:33.934384+00:00", "data": {"market": "0xc1977bee61f67d9d6cea3f7b16d094896bdb1faefa0f9df9ea0a067daab48981", "price_changes": [{"asset_id": "78110974122162464943361433845382554746323675076814300820011415551303694081660", "price": "0.02", "size": "157.03", "side": "BUY", "hash": "1b75034e7fedd4f555de8c4c315b757957a5f460", "best_bid": "0.07", "best_ask": "0.96"}, {"asset_id": "9107106424097962766712091054809455692614685520938052843170925105261136451803", "price": "0.98", "size": "157.03", "side": "SELL", "hash": "fd68b0f0cdad86f42afba0fdde6328329ea8b061", "best_bid": "0.04", "best_ask": "0.93"}], "timestamp": "1769384493778", "event_type": "price_change"}}
{"_local_timestamp": "2026-01-25T23:43:01.095491+00:00", "data": {"market": "0xfaba55442a17a201a46f7ac19fd9394364f04959cdebfa420bc0c5ab2da00f59", "price_changes": [{"asset_id": "76829378806632943504106553503686063944439990588195206882350689917773385019771", "price": "0.09", "size": "0", "side": "BUY", "hash": "991a261d496cc35a2d8cf3d08d41a98c2db5b026", "best_bid": "0.65", "best_ask": "0.81"}, {"asset_id": "103206131584345534219777803662235735845312981950233075829729747631018349006817", "price": "0.91", "size": "0", "side": "SELL", "hash": "fefd09817f2b2ed9ee730bf759b1f9f075ce23a0", "best_bid": "0.19", "best_ask": "0.35"}], "timestamp": "1769384580867", "event_type": "price_change"}}
{"_local_timestamp": "2026-01-25T23:43:01.298404+00:00", "data": {"market": "0xfaba55442a17a201a46f7ac19fd9394364f04959cdebfa420bc0c5ab2da00f59", "price_changes": [{"asset_id": "76829378806632943504106553503686063944439990588195206882350689917773385019771", "price": "0.11", "size": "1997.11", "side": "BUY", "hash": "de5cb83c26eb9239e60a06cd541786761da7db0c", "best_bid": "0.65", "best_ask": "0.81"}, {"asset_id": "103206131584345534219777803662235735845312981950233075829729747631018349006817", "price": "0.89", "size": "1997.11", "side": "SELL", "hash": "fc51c2a9a48ea94433a6a5b8eaf4aac43d3d5c22", "best_bid": "0.19", "best_ask": "0.35"}], "timestamp": "1769384581030", "event_type": "price_change"}}
{"_local_timestamp": "2026-01-25T23:43:01.299302+00:00", "data": {"market": "0xfaba55442a17a201a46f7ac19fd9394364f04959cdebfa420bc0c5ab2da00f59", "price_changes": [{"asset_id": "76829378806632943504106553503686063944439990588195206882350689917773385019771", "price": "0.11", "size": "2887.22", "side": "BUY", "hash": "6bd784a72456a9b8a6a0a3bc20b065f27b727083", "best_bid": "0.65", "best_ask": "0.81"}, {"asset_id": "103206131584345534219777803662235735845312981950233075829729747631018349006817", "price": "0.89", "size": "2887.22", "side": "SELL", "hash": "163662f03d474e8a91965b263bded07272e5a39f", "best_bid": "0.19", "best_ask": "0.35"}], "timestamp": "1769384581031", "event_type": "price_change"}}
{"_local_timestamp": "2026-01-25T23:43:01.300040+00:00", "data": {"market": "0xfaba55442a17a201a46f7ac19fd9394364f04959cdebfa420bc0c5ab2da00f59", "price_changes": [{"asset_id": "76829378806632943504106553503686063944439990588195206882350689917773385019771", "price": "0.11", "size": "4157.32", "side": "BUY", "hash": "092f9d8bf7fbd19450954d76ef6d84d6ff90aed8", "best_bid": "0.65", "best_ask": "0.81"}, {"asset_id": "103206131584345534219777803662235735845312981950233075829729747631018349006817", "price": "0.89", "size": "4157.32", "side": "SELL", "hash": "16c1f1fc3d83d00367a32113d7412b8f67a57c2c", "best_bid": "0.19", "best_ask": "0.35"}], "timestamp": "1769384581031", "event_type": "price_change"}}
{"_local_timestamp": "2026-01-25T23:43:01.312513+00:00", "data": {"market": "0xfaba55442a17a201a46f7ac19fd9394364f04959cdebfa420bc0c5ab2da00f59", "price_changes": [{"asset_id": "76829378806632943504106553503686063944439990588195206882350689917773385019771", "price": "0.11", "size": "4162.99", "side": "BUY", "hash": "9f45febcc46e0efab736824b3441fd59bf6172f8", "best_bid": "0.65", "best_ask": "0.81"}, {"asset_id": "103206131584345534219777803662235735845312981950233075829729747631018349006817", "price": "0.89", "size": "4162.99", "side": "SELL", "hash": "6fec45f1784c8aa68ebcbf54f925af44390715cd", "best_bid": "0.19", "best_ask": "0.35"}], "timestamp": "1769384581075", "event_type": "price_change"}}
{"_local_timestamp": "2026-01-25T23:43:15.517520+00:00", "data": {"market": "0xfaba55442a17a201a46f7ac19fd9394364f04959cdebfa420bc0c5ab2da00f59", "price_changes": [{"asset_id": "76829378806632943504106553503686063944439990588195206882350689917773385019771", "price": "0.1", "size": "300", "side": "BUY", "hash": "735c7beee4f043158409fc86d0f46496dee30d5c", "best_bid": "0.65", "best_ask": "0.81"}, {"asset_id": "103206131584345534219777803662235735845312981950233075829729747631018349006817", "price": "0.9", "size": "300", "side": "SELL", "hash": "108741a25541f1aca52124027270481bd74f8f46", "best_bid": "0.19", "best_ask": "0.35"}], "timestamp": "1769384595447", "event_type": "price_change"}}
{"_local_timestamp": "2026-01-25T23:43:15.708968+00:00", "data": {"market": "0xfaba55442a17a201a46f7ac19fd9394364f04959cdebfa420bc0c5ab2da00f59", "price_changes": [{"asset_id": "76829378806632943504106553503686063944439990588195206882350689917773385019771", "price": "0.08", "size": "890.11", "side": "BUY", "hash": "1b90a476cb2eb86989da5b1aef4ce2452d4634f1", "best_bid": "0.65", "best_ask": "0.81"}, {"asset_id": "103206131584345534219777803662235735845312981950233075829729747631018349006817", "price": "0.92", "size": "890.11", "side": "SELL", "hash": "c94e6a14542d8d9378496cc2946a725a86cccab8", "best_bid": "0.19", "best_ask": "0.35"}], "timestamp": "1769384595637", "event_type": "price_change"}}
{"_local_timestamp": "2026-01-25T23:43:15.716810+00:00", "data": {"market": "0xfaba55442a17a201a46f7ac19fd9394364f04959cdebfa420bc0c5ab2da00f59", "price_changes": [{"asset_id": "76829378806632943504106553503686063944439990588195206882350689917773385019771", "price": "0.08", "size": "2887.22", "side": "BUY", "hash": "241608eed593a06a9c41ce1cfd82220f53fc3ea2", "best_bid": "0.65", "best_ask": "0.81"}, {"asset_id": "103206131584345534219777803662235735845312981950233075829729747631018349006817", "price": "0.92", "size": "2887.22", "side": "SELL", "hash": "649133def2f89f8c426054928e4ee0c669465b4c", "best_bid": "0.19", "best_ask": "0.35"}], "timestamp": "1769384595637", "event_type": "price_change"}}
{"_local_timestamp": "2026-01-25T23:43:15.717742+00:00", "data": {"market": "0xfaba55442a17a201a46f7ac19fd9394364f04959cdebfa420bc0c5ab2da00f59", "price_changes": [{"asset_id": "76829378806632943504106553503686063944439990588195206882350689917773385019771", "price": "0.08", "size": "4157.32", "side": "BUY", "hash": "574a343a0366f8eaa8010daa957c1a195ddfe1a3", "best_bid": "0.65", "best_ask": "0.81"}, {"asset_id": "103206131584345534219777803662235735845312981950233075829729747631018349006817", "price": "0.92", "size": "4157.32", "side": "SELL", "hash": "e0f460edf7aa20944a7fa1a444488312a4b69d22", "best_bid": "0.19", "best_ask": "0.35"}], "timestamp": "1769384595638", "event_type": "price_change"}}
{"_local_timestamp": "2026-01-25T23:43:15.837192+00:00", "data": {"market": "0xfaba55442a17a201a46f7ac19fd9394364f04959cdebfa420bc0c5ab2da00f59", "price_changes": [{"asset_id": "76829378806632943504106553503686063944439990588195206882350689917773385019771", "price": "0.11", "size": "4562.99", "side": "BUY", "hash": "f42d6b276150286ac15778ce4c161fbf24be9653", "best_bid": "0.65", "best_ask": "0.81"}, {"asset_id": "103206131584345534219777803662235735845312981950233075829729747631018349006817", "price": "0.89", "size": "4562.99", "side": "SELL", "hash": "b603fcda0c1bcf03cbd3a13931905669a8cd42f0", "best_bid": "0.19", "best_ask": "0.35"}], "timestamp": "1769384595727", "event_type": "price_change"}}
{"_local_timestamp": "2026-01-25T23:43:40.673076+00:00", "data": {"market": "0xfaba55442a17a201a46f7ac19fd9394364f04959cdebfa420bc0c5ab2da00f59", "price_changes": [{"asset_id": "103206131584345534219777803662235735845312981950233075829729747631018349006817", "price": "0.09", "size": "1190.11", "side": "BUY", "hash": "d8b4f2941223fa2bcb4fdab0a8ff895b0cab4bb9", "best_bid": "0.19", "best_ask": "0.35"}, {"asset_id": "76829378806632943504106553503686063944439990588195206882350689917773385019771", "price": "0.91", "size": "1190.11", "side": "SELL", "hash": "e91266a40403170d7576a3f19c39e7446fb548c9", "best_bid": "0.65", "best_ask": "0.81"}], "timestamp": "1769384620600", "event_type": "price_change"}}
{"_local_timestamp": "2026-01-25T23:43:40.737321+00:00", "data": {"market": "0xfaba55442a17a201a46f7ac19fd9394364f04959cdebfa420bc0c5ab2da00f59", "price_changes": [{"asset_id": "76829378806632943504106553503686063944439990588195206882350689917773385019771", "price": "0.11", "size": "1675.77", "side": "BUY", "hash": "3957c59c317ec47fce887d4b38af3cdbe1de5d89", "best_bid": "0.65", "best_ask": "0.81"}, {"asset_id": "103206131584345534219777803662235735845312981950233075829729747631018349006817", "price": "0.89", "size": "1675.77", "side": "SELL", "hash": "49e7b0b0571b69c49e80586738666c451f29118a", "best_bid": "0.19", "best_ask": "0.35"}], "timestamp": "1769384620665", "event_type": "price_change"}}
{"_local_timestamp": "2026-01-25T23:43:40.820490+00:00", "data": {"market": "0xfaba55442a17a201a46f7ac19fd9394364f04959cdebfa420bc0c5ab2da00f59", "price_changes": [{"asset_id": "76829378806632943504106553503686063944439990588195206882350689917773385019771", "price": "0.11", "size": "405.67", "side": "BUY", "hash": "af91bb3dfc5fe74732d91e19df6bdc197c40869d", "best_bid": "0.65", "best_ask": "0.81"}, {"asset_id": "103206131584345534219777803662235735845312981950233075829729747631018349006817", "price": "0.89", "size": "405.67", "side": "SELL", "hash": "df48bb63376190aad0a8b7325c70ff80532b362f", "best_bid": "0.19", "best_ask": "0.35"}], "timestamp": "1769384620745", "event_type": "price_change"}}
{"_local_timestamp": "2026-01-25T23:43:40.954898+00:00", "data": {"market": "0xfaba55442a17a201a46f7ac19fd9394364f04959cdebfa420bc0c5ab2da00f59", "price_changes": [{"asset_id": "76829378806632943504106553503686063944439990588195206882350689917773385019771", "price": "0.12", "size": "890.11", "side": "BUY", "hash": "892fd9412958e0ce85bf9b9d7679502d264dae51", "best_bid": "0.65", "best_ask": "0.81"}, {"asset_id": "103206131584345534219777803662235735845312981950233075829729747631018349006817", "price": "0.88", "size": "890.11", "side": "SELL", "hash": "b6d5978eb097eafb905ff5006d19c7fae49235d3", "best_bid": "0.19", "best_ask": "0.35"}], "timestamp": "1769384620884", "event_type": "price_change"}}
{"_local_timestamp": "2026-01-25T23:43:40.955649+00:00", "data": {"market": "0xfaba55442a17a201a46f7ac19fd9394364f04959cdebfa420bc0c5ab2da00f59", "price_changes": [{"asset_id": "76829378806632943504106553503686063944439990588195206882350689917773385019771", "price": "0.12", "size": "2160.21", "side": "BUY", "hash": "02d33aa05586a046957ac0228a5140d6770b8cc7", "best_bid": "0.65", "best_ask": "0.81"}, {"asset_id": "103206131584345534219777803662235735845312981950233075829729747631018349006817", "price": "0.88", "size": "2160.21", "side": "SELL", "hash": "dac5179f51efc4de2533969d46650ed5c67a3914", "best_bid": "0.19", "best_ask": "0.35"}], "timestamp": "1769384620885", "event_type": "price_change"}}
{"_local_timestamp": "2026-01-25T23:43:40.956348+00:00", "data": {"market": "0xfaba55442a17a201a46f7ac19fd9394364f04959cdebfa420bc0c5ab2da00f59", "price_changes": [{"asset_id": "76829378806632943504106553503686063944439990588195206882350689917773385019771", "price": "0.12", "size": "4157.32", "side": "BUY", "hash": "23d28b48fc7772e298fda38cd377de75cb250e05", "best_bid": "0.65", "best_ask": "0.81"}, {"asset_id": "103206131584345534219777803662235735845312981950233075829729747631018349006817", "price": "0.88", "size": "4157.32", "side": "SELL", "hash": "c877359076d78a9d54142b298416b2ab1dbdbd8d", "best_bid": "0.19", "best_ask": "0.35"}], "timestamp": "1769384620886", "event_type": "price_change"}}
{"_local_timestamp": "2026-01-25T23:43:41.149754+00:00", "data": {"market": "0x14a59fd43a48ef0bb90a5f63a6940fb6a62acf00f14710407cb340a6e555e427", "price_changes": [{"asset_id": "32309374624748192362666880759096858495442910952630564264751928146985382753863", "price": "0.01", "size": "180", "side": "BUY", "hash": "b8c08320d3b7cce1ce51e06e362bb003ff39d5b5", "best_bid": "0.05", "best_ask": "0.96"}, {"asset_id": "33860025332294261066339194986447657969774333993404072754488955408971762620870", "price": "0.99", "size": "180", "side": "SELL", "hash": "6fb70ca56e6b68c436278bdb2ef7e719164ca5fb", "best_bid": "0.04", "best_ask": "0.95"}], "timestamp": "1769384621077", "event_type": "price_change"}}
{"_local_timestamp": "2026-01-25T23:43:41.445383+00:00", "data": {"market": "0x14a59fd43a48ef0bb90a5f63a6940fb6a62acf00f14710407cb340a6e555e427", "price_changes": [{"asset_id": "32309374624748192362666880759096858495442910952630564264751928146985382753863", "price": "0.01", "size": "202.09", "side": "BUY", "hash": "b657362ae1f206713be93b84f9c19ea13f36d5e8", "best_bid": "0.05", "best_ask": "0.96"}, {"asset_id": "33860025332294261066339194986447657969774333993404072754488955408971762620870", "price": "0.99", "size": "202.09", "side": "SELL", "hash": "e42b04eab770c045285e1232e8159f087ef135c1", "best_bid": "0.04", "best_ask": "0.95"}], "timestamp": "1769384621378", "event_type": "price_change"}}
{"_local_timestamp": "2026-01-25T23:43:41.844352+00:00", "data": {"market": "0xfaba55442a17a201a46f7ac19fd9394364f04959cdebfa420bc0c5ab2da00f59", "price_changes": [{"asset_id": "103206131584345534219777803662235735845312981950233075829729747631018349006817", "price": "0.08", "size": "6.81", "side": "BUY", "hash": "95772b9fb4c443627610db1e3bf93574b08bcc37", "best_bid": "0.19", "best_ask": "0.35"}, {"asset_id": "76829378806632943504106553503686063944439990588195206882350689917773385019771", "price": "0.92", "size": "6.81", "side": "SELL", "hash": "3b29191cc2170abf0bcefdf5e4c1f71677e25579", "best_bid": "0.65", "best_ask": "0.81"}], "timestamp": "1769384621767", "event_type": "price_change"}}
{"_local_timestamp": "2026-01-25T23:43:44.789131+00:00", "data": {"market": "0xfaba55442a17a201a46f7ac19fd9394364f04959cdebfa420bc0c5ab2da00f59", "price_changes": [{"asset_id": "76829378806632943504106553503686063944439990588195206882350689917773385019771", "price": "0.1", "size": "200", "side": "BUY", "hash": "e818e727e341be27aded046757034317391a62e7", "best_bid": "0.65", "best_ask": "0.81"}, {"asset_id": "103206131584345534219777803662235735845312981950233075829729747631018349006817", "price": "0.9", "size": "200", "side": "SELL", "hash": "413ab290e17db188094712e9a9c87dacca72c4fa", "best_bid": "0.19", "best_ask": "0.35"}], "timestamp": "1769384624698", "event_type": "price_change"}}
{"_local_timestamp": "2026-01-25T23:43:44.916067+00:00", "data": {"market": "0xfaba55442a17a201a46f7ac19fd9394364f04959cdebfa420bc0c5ab2da00f59", "price_changes": [{"asset_id": "76829378806632943504106553503686063944439990588195206882350689917773385019771", "price": "0.12", "size": "0", "side": "BUY", "hash": "4bd0ac2de9e156eb26eda48e526d225a055a0e08", "best_bid": "0.65", "best_ask": "0.81"}, {"asset_id": "103206131584345534219777803662235735845312981950233075829729747631018349006817", "price": "0.88", "size": "0", "side": "SELL", "hash": "ef3893f1bff7dbdc9d381788121a5625033f1ee5", "best_bid": "0.19", "best_ask": "0.35"}], "timestamp": "1769384624832", "event_type": "price_change"}}
{"_local_timestamp": "2026-01-25T23:43:45.030072+00:00", "data": {"market": "0xfaba55442a17a201a46f7ac19fd9394364f04959cdebfa420bc0c5ab2da00f59", "price_changes": [{"asset_id": "76829378806632943504106553503686063944439990588195206882350689917773385019771", "price": "0.11", "size": "505.67", "side": "BUY", "hash": "b887fef8cecb5f3ebe250cc20ece7d596699e4c5", "best_bid": "0.65", "best_ask": "0.81"}, {"asset_id": "103206131584345534219777803662235735845312981950233075829729747631018349006817", "price": "0.89", "size": "505.67", "side": "SELL", "hash": "f9d0fd2bbe615becf12b9d12cc1e5ec63c0ee72e", "best_bid": "0.19", "best_ask": "0.35"}], "timestamp": "1769384624960", "event_type": "price_change"}}
{"_local_timestamp": "2026-01-25T23:43:47.805347+00:00", "data": {"market": "0xfaba55442a17a201a46f7ac19fd9394364f04959cdebfa420bc0c5ab2da00f59", "price_changes": [{"asset_id": "76829378806632943504106553503686063944439990588195206882350689917773385019771", "price": "0.1", "size": "100", "side": "BUY", "hash": "c5095eb324fbe529f7ced6db69969a439ea791ca", "best_bid": "0.65", "best_ask": "0.81"}, {"asset_id": "103206131584345534219777803662235735845312981950233075829729747631018349006817", "price": "0.9", "size": "100", "side": "SELL", "hash": "57553651101178e88f9bfa3f9729e35d4b81a9cf", "best_bid": "0.19", "best_ask": "0.35"}], "timestamp": "1769384627733", "event_type": "price_change"}}
{"_local_timestamp": "2026-01-25T23:43:48.124764+00:00", "data": {"market": "0xfaba55442a17a201a46f7ac19fd9394364f04959cdebfa420bc0c5ab2da00f59", "price_changes": [{"asset_id": "76829378806632943504106553503686063944439990588195206882350689917773385019771", "price": "0.11", "size": "605.67", "side": "BUY", "hash": "77ee8ddfa37be0f20dfb2cba2f3be700b46538f6", "best_bid": "0.65", "best_ask": "0.81"}, {"asset_id": "103206131584345534219777803662235735845312981950233075829729747631018349006817", "price": "0.89", "size": "605.67", "side": "SELL", "hash": "945675dfb75e5e2a5c0e8c25620ee278dd77eb2f", "best_bid": "0.19", "best_ask": "0.35"}], "timestamp": "1769384628039", "event_type": "price_change"}}
{"_local_timestamp": "2026-01-25T23:43:48.270113+00:00", "data": {"market": "0xfaba55442a17a201a46f7ac19fd9394364f04959cdebfa420bc0c5ab2da00f59", "price_changes": [{"asset_id": "76829378806632943504106553503686063944439990588195206882350689917773385019771", "price": "0.12", "size": "1270.1", "side": "BUY", "hash": "6c00710942bdced9ef670c2fc8356e198bda46e2", "best_bid": "0.65", "best_ask": "0.81"}, {"asset_id": "103206131584345534219777803662235735845312981950233075829729747631018349006817", "price": "0.88", "size": "1270.1", "side": "SELL", "hash": "738377cb13e17e42715457ecc00c3f677ad80fa6", "best_bid": "0.19", "best_ask": "0.35"}], "timestamp": "1769384628198", "event_type": "price_change"}}
{"_local_timestamp": "2026-01-25T23:43:48.303551+00:00", "data": {"market": "0xfaba55442a17a201a46f7ac19fd9394364f04959cdebfa420bc0c5ab2da00f59", "price_changes": [{"asset_id": "76829378806632943504106553503686063944439990588195206882350689917773385019771", "price": "0.12", "size": "3267.21", "side": "BUY", "hash": "a7352c3f32b26638237a7cb0423bb8cdb24b7c07", "best_bid": "0.65", "best_ask": "0.81"}, {"asset_id": "103206131584345534219777803662235735845312981950233075829729747631018349006817", "price": "0.88", "size": "3267.21", "side": "SELL", "hash": "bc51bf6df9ed69e09589a7ad580ba5dcae74c2b4", "best_bid": "0.19", "best_ask": "0.35"}], "timestamp": "1769384628236", "event_type": "price_change"}}
{"_local_timestamp": "2026-01-25T23:43:48.304451+00:00", "data": {"market": "0xfaba55442a17a201a46f7ac19fd9394364f04959cdebfa420bc0c5ab2da00f59", "price_changes": [{"asset_id": "76829378806632943504106553503686063944439990588195206882350689917773385019771", "price": "0.12", "size": "4157.32", "side": "BUY", "hash": "7fb68f43eb2c688303d831736bc4d0c48af89c0c", "best_bid": "0.65", "best_ask": "0.81"}, {"asset_id": "103206131584345534219777803662235735845312981950233075829729747631018349006817", "price": "0.88", "size": "4157.32", "side": "SELL", "hash": "fb6b97fee78a0573adcd4a806e56de4cbffc76ed", "best_bid": "0.19", "best_ask": "0.35"}], "timestamp": "1769384628237", "event_type": "price_change"}}
{"_local_timestamp": "2026-01-25T23:43:49.821387+00:00", "data": {"market": "0xfaba55442a17a201a46f7ac19fd9394364f04959cdebfa420bc0c5ab2da00f59", "price_changes": [{"asset_id": "76829378806632943504106553503686063944439990588195206882350689917773385019771", "price": "0.1", "size": "0", "side": "BUY", "hash": "28ab26636951333c37aafeb73f0b2b1c39c2c888", "best_bid": "0.65", "best_ask": "0.81"}, {"asset_id": "103206131584345534219777803662235735845312981950233075829729747631018349006817", "price": "0.9", "size": "0", "side": "SELL", "hash": "28ae8126711c3c230f32898e9ef380b2981dc610", "best_bid": "0.19", "best_ask": "0.35"}], "timestamp": "1769384629747", "event_type": "price_change"}}
{"_local_timestamp": "2026-01-25T23:43:50.116375+00:00", "data": {"market": "0xfaba55442a17a201a46f7ac19fd9394364f04959cdebfa420bc0c5ab2da00f59", "price_changes": [{"asset_id": "76829378806632943504106553503686063944439990588195206882350689917773385019771", "price": "0.11", "size": "705.67", "side": "BUY", "hash": "5817e4c2eb56807e475b3cc549a17ee435793845", "best_bid": "0.65", "best_ask": "0.81"}, {"asset_id": "103206131584345534219777803662235735845312981950233075829729747631018349006817", "price": "0.89", "size": "705.67", "side": "SELL", "hash": "e65108b9830c7da271d92cf0a10ec3db572177d6", "best_bid": "0.19", "best_ask": "0.35"}], "timestamp": "1769384630018", "event_type": "price_change"}}
{"_local_timestamp": "2026-01-25T23:44:01.505849+00:00", "data": {"market": "0xfaba55442a17a201a46f7ac19fd9394364f04959cdebfa420bc0c5ab2da00f59", "price_changes": [{"asset_id": "76829378806632943504106553503686063944439990588195206882350689917773385019771", "price": "0.11", "size": "305.67", "side": "BUY", "hash": "afe5be36e5932f9b96ba23f09df5caf3a10d2096", "best_bid": "0.65", "best_ask": "0.81"}, {"asset_id": "103206131584345534219777803662235735845312981950233075829729747631018349006817", "price": "0.89", "size": "305.67", "side": "SELL", "hash": "4c7a6b1e06656e3ed764902043b0cd0a000e79ed", "best_bid": "0.19", "best_ask": "0.35"}], "timestamp": "1769384641432", "event_type": "price_change"}}
{"_local_timestamp": "2026-01-25T23:44:01.788625+00:00", "data": {"market": "0xfaba55442a17a201a46f7ac19fd9394364f04959cdebfa420bc0c5ab2da00f59", "price_changes": [{"asset_id": "76829378806632943504106553503686063944439990588195206882350689917773385019771", "price": "0.08", "size": "4557.32", "side": "BUY", "hash": "e7e65dd219f1af2e2d39fabf4835fd7126920168", "best_bid": "0.65", "best_ask": "0.81"}, {"asset_id": "103206131584345534219777803662235735845312981950233075829729747631018349006817", "price": "0.92", "size": "4557.32", "side": "SELL", "hash": "858a420b8b9a2d90efb481a9a89d170ab40207d4", "best_bid": "0.19", "best_ask": "0.35"}], "timestamp": "1769384641718", "event_type": "price_change"}}
{"_local_timestamp": "2026-01-25T23:44:06.293613+00:00", "data": {"market": "0xfaba55442a17a201a46f7ac19fd9394364f04959cdebfa420bc0c5ab2da00f59", "price_changes": [{"asset_id": "76829378806632943504106553503686063944439990588195206882350689917773385019771", "price": "0.11", "size": "205.67", "side": "BUY", "hash": "f93061c489f1ed02dc41f97edd53127155d20581", "best_bid": "0.65", "best_ask": "0.81"}, {"asset_id": "103206131584345534219777803662235735845312981950233075829729747631018349006817", "price": "0.89", "size": "205.67", "side": "SELL", "hash": "e5ed4ceaee32c31ab75a4ee0f1c1be3aa46c4211", "best_bid": "0.19", "best_ask": "0.35"}], "timestamp": "1769384646218", "event_type": "price_change"}}
{"_local_timestamp": "2026-01-25T23:44:06.402199+00:00", "data": {"market": "0xfaba55442a17a201a46f7ac19fd9394364f04959cdebfa420bc0c5ab2da00f59", "price_changes": [{"asset_id": "76829378806632943504106553503686063944439990588195206882350689917773385019771", "price": "0.12", "size": "0", "side": "BUY", "hash": "552891891f7b2dec75bb27108fb81511ab2622a3", "best_bid": "0.65", "best_ask": "0.81"}, {"asset_id": "103206131584345534219777803662235735845312981950233075829729747631018349006817", "price": "0.88", "size": "0", "side": "SELL", "hash": "a9f9bd6a0b0d394bdffb7c7afb61c9640d866000", "best_bid": "0.19", "best_ask": "0.35"}], "timestamp": "1769384646332", "event_type": "price_change"}}
{"_local_timestamp": "2026-01-25T23:44:06.569876+00:00", "data": {"market": "0xfaba55442a17a201a46f7ac19fd9394364f04959cdebfa420bc0c5ab2da00f59", "price_changes": [{"asset_id": "76829378806632943504106553503686063944439990588195206882350689917773385019771", "price": "0.12", "size": "100", "side": "BUY", "hash": "64da3440cf8da6cf67ec50d094819a9046acb437", "best_bid": "0.65", "best_ask": "0.81"}, {"asset_id": "103206131584345534219777803662235735845312981950233075829729747631018349006817", "price": "0.88", "size": "100", "side": "SELL", "hash": "041c9ac10789aacc9a75d15c7c7bb24ce348430e", "best_bid": "0.19", "best_ask": "0.35"}], "timestamp": "1769384646491", "event_type": "price_change"}}
{"_local_timestamp": "2026-01-25T23:44:18.095618+00:00", "data": {"market": "0xfaba55442a17a201a46f7ac19fd9394364f04959cdebfa420bc0c5ab2da00f59", "price_changes": [{"asset_id": "76829378806632943504106553503686063944439990588195206882350689917773385019771", "price": "0.11", "size": "105.67", "side": "BUY", "hash": "4773907044ed853021a0ca39af7061ee1dfd9c1f", "best_bid": "0.65", "best_ask": "0.81"}, {"asset_id": "103206131584345534219777803662235735845312981950233075829729747631018349006817", "price": "0.89", "size": "105.67", "side": "SELL", "hash": "6c186b4f8a2aa97c1b890d71bc5d87a9c28f9c13", "best_bid": "0.19", "best_ask": "0.35"}], "timestamp": "1769384658004", "event_type": "price_change"}}
{"_local_timestamp": "2026-01-25T23:44:18.386208+00:00", "data": {"market": "0xfaba55442a17a201a46f7ac19fd9394364f04959cdebfa420bc0c5ab2da00f59", "price_changes": [{"asset_id": "76829378806632943504106553503686063944439990588195206882350689917773385019771", "price": "0.12", "size": "200", "side": "BUY", "hash": "c446b6fcf5ca81395b712632c1ee85678bc6a632", "best_bid": "0.65", "best_ask": "0.81"}, {"asset_id": "103206131584345534219777803662235735845312981950233075829729747631018349006817", "price": "0.88", "size": "200", "side": "SELL", "hash": "10777abd1c436922877b4512e552eb6b5f862d57", "best_bid": "0.19", "best_ask": "0.35"}], "timestamp": "1769384658315", "event_type": "price_change"}}
{"_local_timestamp": "2026-01-25T23:44:23.462434+00:00", "data": {"market": "0xfaba55442a17a201a46f7ac19fd9394364f04959cdebfa420bc0c5ab2da00f59", "price_changes": [{"asset_id": "76829378806632943504106553503686063944439990588195206882350689917773385019771", "price": "0.11", "size": "5.67", "side": "BUY", "hash": "d7fbfc9a5165c357bfe8a1151c9551862472b683", "best_bid": "0.65", "best_ask": "0.81"}, {"asset_id": "103206131584345534219777803662235735845312981950233075829729747631018349006817", "price": "0.89", "size": "5.67", "side": "SELL", "hash": "f0c2165849fe32d8a0afe4b9cfa9ed66783e7598", "best_bid": "0.19", "best_ask": "0.35"}], "timestamp": "1769384663386", "event_type": "price_change"}}
{"_local_timestamp": "2026-01-25T23:44:23.726510+00:00", "data": {"market": "0xfaba55442a17a201a46f7ac19fd9394364f04959cdebfa420bc0c5ab2da00f59", "price_changes": [{"asset_id": "76829378806632943504106553503686063944439990588195206882350689917773385019771", "price": "0.12", "size": "300", "side": "BUY", "hash": "931d4a4ecc1ce29b9b8e6ff9b7df8c48c2c21a64", "best_bid": "0.65", "best_ask": "0.81"}, {"asset_id": "103206131584345534219777803662235735845312981950233075829729747631018349006817", "price": "0.88", "size": "300", "side": "SELL", "hash": "0f2186f076e9766c78b86a32fda210677f7032ec", "best_bid": "0.19", "best_ask": "0.35"}], "timestamp": "1769384663655", "event_type": "price_change"}}
{"_local_timestamp": "2026-01-25T23:44:27.067764+00:00", "data": {"market": "0xfaba55442a17a201a46f7ac19fd9394364f04959cdebfa420bc0c5ab2da00f59", "price_changes": [{"asset_id": "76829378806632943504106553503686063944439990588195206882350689917773385019771", "price": "0.12", "size": "200", "side": "BUY", "hash": "939a52b11aad0e30d0109dfc92f3819e3d750f6a", "best_bid": "0.65", "best_ask": "0.81"}, {"asset_id": "103206131584345534219777803662235735845312981950233075829729747631018349006817", "price": "0.88", "size": "200", "side": "SELL", "hash": "ca5865345a1b712bd4311cb71d11815a0f4c3946", "best_bid": "0.19", "best_ask": "0.35"}], "timestamp": "1769384666975", "event_type": "price_change"}}
{"_local_timestamp": "2026-01-25T23:44:27.310350+00:00", "data": {"market": "0xfaba55442a17a201a46f7ac19fd9394364f04959cdebfa420bc0c5ab2da00f59", "price_changes": [{"asset_id": "76829378806632943504106553503686063944439990588195206882350689917773385019771", "price": "0.08", "size": "4657.32", "side": "BUY", "hash": "dcbd1682cb83d8fa2c997c1172ed16701586ebec", "best_bid": "0.65", "best_ask": "0.81"}, {"asset_id": "103206131584345534219777803662235735845312981950233075829729747631018349006817", "price": "0.92", "size": "4657.32", "side": "SELL", "hash": "94e75a2b8dfcf3ea32f4db43997730d5466da9d7", "best_bid": "0.19", "best_ask": "0.35"}], "timestamp": "1769384667235", "event_type": "price_change"}}
{"_local_timestamp": "2026-01-25T23:44:52.430084+00:00", "data": {"market": "0xfaba55442a17a201a46f7ac19fd9394364f04959cdebfa420bc0c5ab2da00f59", "price_changes": [{"asset_id": "76829378806632943504106553503686063944439990588195206882350689917773385019771", "price": "0.12", "size": "100", "side": "BUY", "hash": "1d2996e409df421b96233f0cb064441d2e6d705a", "best_bid": "0.65", "best_ask": "0.81"}, {"asset_id": "103206131584345534219777803662235735845312981950233075829729747631018349006817", "price": "0.88", "size": "100", "side": "SELL", "hash": "611e6685328fb9182265b534df3c47bccaa81847", "best_bid": "0.19", "best_ask": "0.35"}], "timestamp": "1769384692365", "event_type": "price_change"}}
{"_local_timestamp": "2026-01-25T23:44:52.516924+00:00", "data": {"market": "0xfaba55442a17a201a46f7ac19fd9394364f04959cdebfa420bc0c5ab2da00f59", "price_changes": [{"asset_id": "76829378806632943504106553503686063944439990588195206882350689917773385019771", "price": "0.12", "size": "0", "side": "BUY", "hash": "94f2ece1c28ffd0fd9c9d57b382790cbdfcbbde9", "best_bid": "0.65", "best_ask": "0.81"}, {"asset_id": "103206131584345534219777803662235735845312981950233075829729747631018349006817", "price": "0.88", "size": "0", "side": "SELL", "hash": "4821c377d491326f79fec7a308afdcb06ea7fc47", "best_bid": "0.19", "best_ask": "0.35"}], "timestamp": "1769384692446", "event_type": "price_change"}}
{"_local_timestamp": "2026-01-25T23:44:52.712057+00:00", "data": {"market": "0xfaba55442a17a201a46f7ac19fd9394364f04959cdebfa420bc0c5ab2da00f59", "price_changes": [{"asset_id": "76829378806632943504106553503686063944439990588195206882350689917773385019771", "price": "0.08", "size": "4757.32", "side": "BUY", "hash": "3f1df66a41b19c93076aff3ca381edb2fd9988a8", "best_bid": "0.65", "best_ask": "0.81"}, {"asset_id": "103206131584345534219777803662235735845312981950233075829729747631018349006817", "price": "0.92", "size": "4757.32", "side": "SELL", "hash": "4fe9cdd3b474e21ce1f3bc42deef19edc75282ff", "best_bid": "0.19", "best_ask": "0.35"}], "timestamp": "1769384692641", "event_type": "price_change"}}
{"_local_timestamp": "2026-01-25T23:44:52.771399+00:00", "data": {"market": "0xfaba55442a17a201a46f7ac19fd9394364f04959cdebfa420bc0c5ab2da00f59", "price_changes": [{"asset_id": "76829378806632943504106553503686063944439990588195206882350689917773385019771", "price": "0.09", "size": "1270.1", "side": "BUY", "hash": "4e5999035ef19cb55175cdf52b28252f63a68236", "best_bid": "0.65", "best_ask": "0.81"}, {"asset_id": "103206131584345534219777803662235735845312981950233075829729747631018349006817", "price": "0.91", "size": "1270.1", "side": "SELL", "hash": "a84c614219976cf85b8e08c1d6b3058e5c6cbfb8", "best_bid": "0.19", "best_ask": "0.35"}], "timestamp": "1769384692698", "event_type": "price_change"}}
{"_local_timestamp": "2026-01-25T23:44:52.772593+00:00", "data": {"market": "0xfaba55442a17a201a46f7ac19fd9394364f04959cdebfa420bc0c5ab2da00f59", "price_changes": [{"asset_id": "76829378806632943504106553503686063944439990588195206882350689917773385019771", "price": "0.09", "size": "2160.21", "side": "BUY", "hash": "84648bc9852679cad44fbf5b69198e2fdbabaffc", "best_bid": "0.65", "best_ask": "0.81"}, {"asset_id": "103206131584345534219777803662235735845312981950233075829729747631018349006817", "price": "0.91", "size": "2160.21", "side": "SELL", "hash": "4ecddd890de11e7f85d1913011ad4c831b428c69", "best_bid": "0.19", "best_ask": "0.35"}], "timestamp": "1769384692699", "event_type": "price_change"}}
{"_local_timestamp": "2026-01-25T23:44:52.809972+00:00", "data": {"market": "0xfaba55442a17a201a46f7ac19fd9394364f04959cdebfa420bc0c5ab2da00f59", "price_changes": [{"asset_id": "76829378806632943504106553503686063944439990588195206882350689917773385019771", "price": "0.09", "size": "4157.32", "side": "BUY", "hash": "b082fcf1d43e61eb040aa4f8a15908b31d083390", "best_bid": "0.65", "best_ask": "0.81"}, {"asset_id": "103206131584345534219777803662235735845312981950233075829729747631018349006817", "price": "0.91", "size": "4157.32", "side": "SELL", "hash": "58695772339614b4b76f00e384229e0bc28f7177", "best_bid": "0.19", "best_ask": "0.35"}], "timestamp": "1769384692739", "event_type": "price_change"}}
{"_local_timestamp": "2026-01-25T23:44:52.888211+00:00", "data": {"market": "0xfaba55442a17a201a46f7ac19fd9394364f04959cdebfa420bc0c5ab2da00f59", "price_changes": [{"asset_id": "76829378806632943504106553503686063944439990588195206882350689917773385019771", "price": "0.08", "size": "4857.32", "side": "BUY", "hash": "636bb33ee57c4a2537b20d34fae6fb7477b59a3d", "best_bid": "0.65", "best_ask": "0.81"}, {"asset_id": "103206131584345534219777803662235735845312981950233075829729747631018349006817", "price": "0.92", "size": "4857.32", "side": "SELL", "hash": "fc689b78c1c5ad7ae00551b49d00950161c283bc", "best_bid": "0.19", "best_ask": "0.35"}], "timestamp": "1769384692819", "event_type": "price_change"}}
{"_local_timestamp": "2026-01-25T23:45:08.843891+00:00", "data": {"market": "0xfaba55442a17a201a46f7ac19fd9394364f04959cdebfa420bc0c5ab2da00f59", "price_changes": [{"asset_id": "76829378806632943504106553503686063944439990588195206882350689917773385019771", "price": "0.08", "size": "4457.32", "side": "BUY", "hash": "2802a21e0bc39e5b9adf0f4958df8b1f59d48a8e", "best_bid": "0.65", "best_ask": "0.81"}, {"asset_id": "103206131584345534219777803662235735845312981950233075829729747631018349006817", "price": "0.92", "size": "4457.32", "side": "SELL", "hash": "c6106baabdf4e17fdc87d37804742294f3c65cd2", "best_bid": "0.19", "best_ask": "0.35"}], "timestamp": "1769384708768", "event_type": "price_change"}}
{"_local_timestamp": "2026-01-25T23:45:09.158058+00:00", "data": {"market": "0xfaba55442a17a201a46f7ac19fd9394364f04959cdebfa420bc0c5ab2da00f59", "price_changes": [{"asset_id": "76829378806632943504106553503686063944439990588195206882350689917773385019771", "price": "0.09", "size": "4557.32", "side": "BUY", "hash": "748bbd1ed084144f6ba6506358e387a9e15b7cce", "best_bid": "0.65", "best_ask": "0.81"}, {"asset_id": "103206131584345534219777803662235735845312981950233075829729747631018349006817", "price": "0.91", "size": "4557.32", "side": "SELL", "hash": "e358fb0cf149b61d809bf5952ed9c2055d4abd01", "best_bid": "0.19", "best_ask": "0.35"}], "timestamp": "1769384709058", "event_type": "price_change"}}
{"_local_timestamp": "2026-01-25T23:45:47.126645+00:00", "data": {"market": "0xfaba55442a17a201a46f7ac19fd9394364f04959cdebfa420bc0c5ab2da00f59", "price_changes": [{"asset_id": "76829378806632943504106553503686063944439990588195206882350689917773385019771", "price": "0.08", "size": "4357.32", "side": "BUY", "hash": "1537615cc345c6728726e2c8329fd3260e8c3b3b", "best_bid": "0.65", "best_ask": "0.81"}, {"asset_id": "103206131584345534219777803662235735845312981950233075829729747631018349006817", "price": "0.92", "size": "4357.32", "side": "SELL", "hash": "e7a3e91c703ea99a6ff76ae8ea96a99b0ad058c2", "best_bid": "0.19", "best_ask": "0.35"}], "timestamp": "1769384747057", "event_type": "price_change"}}
{"_local_timestamp": "2026-01-25T23:45:47.194080+00:00", "data": {"market": "0xfaba55442a17a201a46f7ac19fd9394364f04959cdebfa420bc0c5ab2da00f59", "price_changes": [{"asset_id": "76829378806632943504106553503686063944439990588195206882350689917773385019771", "price": "0.09", "size": "400", "side": "BUY", "hash": "fca91f3edc974f873b78cc3d2fef73a40dd49e10", "best_bid": "0.65", "best_ask": "0.81"}, {"asset_id": "103206131584345534219777803662235735845312981950233075829729747631018349006817", "price": "0.91", "size": "400", "side": "SELL", "hash": "0273a0d462fbd060a1d1712dd7a9fe920b837db1", "best_bid": "0.19", "best_ask": "0.35"}], "timestamp": "1769384747123", "event_type": "price_change"}}
{"_local_timestamp": "2026-01-25T23:45:47.385885+00:00", "data": {"market": "0xfaba55442a17a201a46f7ac19fd9394364f04959cdebfa420bc0c5ab2da00f59", "price_changes": [{"asset_id": "76829378806632943504106553503686063944439990588195206882350689917773385019771", "price": "0.09", "size": "500", "side": "BUY", "hash": "6c24cd86f60c38f725c3e78e8311119366ee9163", "best_bid": "0.65", "best_ask": "0.81"}, {"asset_id": "103206131584345534219777803662235735845312981950233075829729747631018349006817", "price": "0.91", "size": "500", "side": "SELL", "hash": "43e121e9535d206f4e817dc3ca53c55165f29b34", "best_bid": "0.19", "best_ask": "0.35"}], "timestamp": "1769384747318", "event_type": "price_change"}}
{"_local_timestamp": "2026-01-25T23:45:48.754059+00:00", "data": {"market": "0xfaba55442a17a201a46f7ac19fd9394364f04959cdebfa420bc0c5ab2da00f59", "price_changes": [{"asset_id": "76829378806632943504106553503686063944439990588195206882350689917773385019771", "price": "0.11", "size": "0", "side": "BUY", "hash": "8a7c6ab5772ea9bc4b1d8b6a1859f67c5dbd180f", "best_bid": "0.65", "best_ask": "0.81"}, {"asset_id": "103206131584345534219777803662235735845312981950233075829729747631018349006817", "price": "0.89", "size": "0", "side": "SELL", "hash": "cf4845566ef011792d396227a97022a743cf5c43", "best_bid": "0.19", "best_ask": "0.35"}], "timestamp": "1769384748686", "event_type": "price_change"}}
{"_local_timestamp": "2026-01-25T23:45:49.665932+00:00", "data": {"market": "0xfaba55442a17a201a46f7ac19fd9394364f04959cdebfa420bc0c5ab2da00f59", "price_changes": [{"asset_id": "76829378806632943504106553503686063944439990588195206882350689917773385019771", "price": "0.1", "size": "6.23", "side": "BUY", "hash": "363fe35d06daa61c677c4f884497cd585874c48d", "best_bid": "0.65", "best_ask": "0.81"}, {"asset_id": "103206131584345534219777803662235735845312981950233075829729747631018349006817", "price": "0.9", "size": "6.23", "side": "SELL", "hash": "96effb1456b38f141547943e5bc287d5a1ae35f7", "best_bid": "0.19", "best_ask": "0.35"}], "timestamp": "1769384749579", "event_type": "price_change"}}
{"_local_timestamp": "2026-01-25T23:45:53.545450+00:00", "data": {"market": "0xfaba55442a17a201a46f7ac19fd9394364f04959cdebfa420bc0c5ab2da00f59", "price_changes": [{"asset_id": "76829378806632943504106553503686063944439990588195206882350689917773385019771", "price": "0.08", "size": "4257.32", "side": "BUY", "hash": "baa5a977be0193fa93044313b7773f8938d4bbdf", "best_bid": "0.65", "best_ask": "0.81"}, {"asset_id": "103206131584345534219777803662235735845312981950233075829729747631018349006817", "price": "0.92", "size": "4257.32", "side": "SELL", "hash": "8a32f810dfce907a4717f87a13fa902133b0f22d", "best_bid": "0.19", "best_ask": "0.35"}], "timestamp": "1769384753467", "event_type": "price_change"}}
{"_local_timestamp": "2026-01-25T23:45:53.839151+00:00", "data": {"market": "0xfaba55442a17a201a46f7ac19fd9394364f04959cdebfa420bc0c5ab2da00f59", "price_changes": [{"asset_id": "76829378806632943504106553503686063944439990588195206882350689917773385019771", "price": "0.09", "size": "600", "side": "BUY", "hash": "6fc0575e9003fc388da30df2bfa7fd671e955df9", "best_bid": "0.65", "best_ask": "0.81"}, {"asset_id": "103206131584345534219777803662235735845312981950233075829729747631018349006817", "price": "0.91", "size": "600", "side": "SELL", "hash": "e8e6adabbf5f39ffc8618144c2ab368b110b194a", "best_bid": "0.19", "best_ask": "0.35"}], "timestamp": "1769384753756", "event_type": "price_change"}}
{"_local_timestamp": "2026-01-25T23:45:53.931569+00:00", "data": {"market": "0xfaba55442a17a201a46f7ac19fd9394364f04959cdebfa420bc0c5ab2da00f59", "price_changes": [{"asset_id": "76829378806632943504106553503686063944439990588195206882350689917773385019771", "price": "0.1", "size": "896.34", "side": "BUY", "hash": "a77f32be90d9e0477d8ae008e247996ae82dd652", "best_bid": "0.65", "best_ask": "0.81"}, {"asset_id": "103206131584345534219777803662235735845312981950233075829729747631018349006817", "price": "0.9", "size": "896.34", "side": "SELL", "hash": "02044f6d32110c56cf9bbd6325abd836487b2b64", "best_bid": "0.19", "best_ask": "0.35"}], "timestamp": "1769384753856", "event_type": "price_change"}}
{"_local_timestamp": "2026-01-25T23:45:54.180971+00:00", "data": {"market": "0xfaba55442a17a201a46f7ac19fd9394364f04959cdebfa420bc0c5ab2da00f59", "price_changes": [{"asset_id": "76829378806632943504106553503686063944439990588195206882350689917773385019771", "price": "0.1", "size": "2893.45", "side": "BUY", "hash": "5acc03a86aebcc82a1adc6df0253ba76ff1d55bc", "best_bid": "0.65", "best_ask": "0.81"}, {"asset_id": "103206131584345534219777803662235735845312981950233075829729747631018349006817", "price": "0.9", "size": "2893.45", "side": "SELL", "hash": "ffc6c133f1a151f54d891d86f4f9fdd8acf19732", "best_bid": "0.19", "best_ask": "0.35"}], "timestamp": "1769384754087", "event_type": "price_change"}}
{"_local_timestamp": "2026-01-25T23:45:54.181880+00:00", "data": {"market": "0xfaba55442a17a201a46f7ac19fd9394364f04959cdebfa420bc0c5ab2da00f59", "price_changes": [{"asset_id": "76829378806632943504106553503686063944439990588195206882350689917773385019771", "price": "0.1", "size": "4163.55", "side": "BUY", "hash": "9c271144eeb1691d1136a66eb2265071f9107c04", "best_bid": "0.65", "best_ask": "0.81"}, {"asset_id": "103206131584345534219777803662235735845312981950233075829729747631018349006817", "price": "0.9", "size": "4163.55", "side": "SELL", "hash": "ee37b221695a5a1a1f7d1265c07553a51f47c9dc", "best_bid": "0.19", "best_ask": "0.35"}], "timestamp": "1769384754088", "event_type": "price_change"}}
{"_local_timestamp": "2026-01-25T23:45:55.294174+00:00", "data": {"market": "0x14a59fd43a48ef0bb90a5f63a6940fb6a62acf00f14710407cb340a6e555e427", "price_changes": [{"asset_id": "32309374624748192362666880759096858495442910952630564264751928146985382753863", "price": "0.01", "size": "180", "side": "BUY", "hash": "42cae94cf0a489e5fc3a17aa88cd312b1e2f389f", "best_bid": "0.05", "best_ask": "0.96"}, {"asset_id": "33860025332294261066339194986447657969774333993404072754488955408971762620870", "price": "0.99", "size": "180", "side": "SELL", "hash": "656f7a9923e5c0722642c2a27b56eeaf3982d8fa", "best_bid": "0.04", "best_ask": "0.95"}], "timestamp": "1769384755221", "event_type": "price_change"}}
{"_local_timestamp": "2026-01-25T23:45:55.846033+00:00", "data": {"market": "0xfaba55442a17a201a46f7ac19fd9394364f04959cdebfa420bc0c5ab2da00f59", "price_changes": [{"asset_id": "76829378806632943504106553503686063944439990588195206882350689917773385019771", "price": "0.08", "size": "4157.32", "side": "BUY", "hash": "8dd1cce6ad6cb1322b24fedeb333a5601eabd635", "best_bid": "0.65", "best_ask": "0.81"}, {"asset_id": "103206131584345534219777803662235735845312981950233075829729747631018349006817", "price": "0.92", "size": "4157.32", "side": "SELL", "hash": "83eb1ebc89318baf69751cbaf691da5374451279", "best_bid": "0.19", "best_ask": "0.35"}], "timestamp": "1769384755775", "event_type": "price_change"}}
{"_local_timestamp": "2026-01-25T23:45:56.799261+00:00", "data": {"market": "0xfaba55442a17a201a46f7ac19fd9394364f04959cdebfa420bc0c5ab2da00f59", "price_changes": [{"asset_id": "76829378806632943504106553503686063944439990588195206882350689917773385019771", "price": "0.09", "size": "700", "side": "BUY", "hash": "8b6edbbae5c23f734fdb6d3d8bb10f547c49667c", "best_bid": "0.65", "best_ask": "0.81"}, {"asset_id": "103206131584345534219777803662235735845312981950233075829729747631018349006817", "price": "0.91", "size": "700", "side": "SELL", "hash": "a970563f5de69023316519bfac482c825e796e91", "best_bid": "0.19", "best_ask": "0.35"}], "timestamp": "1769384756133", "event_type": "price_change"}}
{"_local_timestamp": "2026-01-25T23:45:57.221348+00:00", "data": {"market": "0xfaba55442a17a201a46f7ac19fd9394364f04959cdebfa420bc0c5ab2da00f59", "price_changes": [{"asset_id": "76829378806632943504106553503686063944439990588195206882350689917773385019771", "price": "0.08", "size": "0", "side": "BUY", "hash": "0192be3550c204eba3f3874969ab21d9d1f0cf41", "best_bid": "0.65", "best_ask": "0.81"}, {"asset_id": "103206131584345534219777803662235735845312981950233075829729747631018349006817", "price": "0.92", "size": "0", "side": "SELL", "hash": "17f21f84f6e3ef8645f0af3f89fb73e8939ab8d8", "best_bid": "0.19", "best_ask": "0.35"}], "timestamp": "1769384756775", "event_type": "price_change"}}
{"_local_timestamp": "2026-01-25T23:45:57.253456+00:00", "data": {"market": "0xfaba55442a17a201a46f7ac19fd9394364f04959cdebfa420bc0c5ab2da00f59", "price_changes": [{"asset_id": "103206131584345534219777803662235735845312981950233075829729747631018349006817", "price": "0.09", "size": "890.11", "side": "BUY", "hash": "4aa2b0ca26de72c125b4d8cafa7417f564600440", "best_bid": "0.19", "best_ask": "0.35"}, {"asset_id": "76829378806632943504106553503686063944439990588195206882350689917773385019771", "price": "0.91", "size": "890.11", "side": "SELL", "hash": "a943d00f926fd0c3b41448760f18ff13c010e97c", "best_bid": "0.65", "best_ask": "0.81"}], "timestamp": "1769384756837", "event_type": "price_change"}}
{"_local_timestamp": "2026-01-25T23:45:57.387119+00:00", "data": {"market": "0xfaba55442a17a201a46f7ac19fd9394364f04959cdebfa420bc0c5ab2da00f59", "price_changes": [{"asset_id": "103206131584345534219777803662235735845312981950233075829729747631018349006817", "price": "0.07", "size": "1090.11", "side": "BUY", "hash": "d267e4b9f5040836434c184711aa3dcd9484bd14", "best_bid": "0.19", "best_ask": "0.35"}, {"asset_id": "76829378806632943504106553503686063944439990588195206882350689917773385019771", "price": "0.93", "size": "1090.11", "side": "SELL", "hash": "697fafaf1221090e7d35ca5276602fb498084890", "best_bid": "0.65", "best_ask": "0.81"}], "timestamp": "1769384757231", "event_type": "price_change"}}
{"_local_timestamp": "2026-01-25T23:45:57.388321+00:00", "data": {"market": "0xfaba55442a17a201a46f7ac19fd9394364f04959cdebfa420bc0c5ab2da00f59", "price_changes": [{"asset_id": "103206131584345534219777803662235735845312981950233075829729747631018349006817", "price": "0.08", "size": "896.92", "side": "BUY", "hash": "9221e5aaf81698af733e1954bce404906cc3b827", "best_bid": "0.19", "best_ask": "0.35"}, {"asset_id": "76829378806632943504106553503686063944439990588195206882350689917773385019771", "price": "0.92", "size": "896.92", "side": "SELL", "hash": "0de7fcc7b0a1a8d5476785823a9159f12909e1c6", "best_bid": "0.65", "best_ask": "0.81"}], "timestamp": "1769384757232", "event_type": "price_change"}}
{"_local_timestamp": "2026-01-25T23:45:57.869115+00:00", "data": {"market": "0x14a59fd43a48ef0bb90a5f63a6940fb6a62acf00f14710407cb340a6e555e427", "price_changes": [{"asset_id": "32309374624748192362666880759096858495442910952630564264751928146985382753863", "price": "0.01", "size": "202.09", "side": "BUY", "hash": "858bc099d43aee5c583405a1ab64d962b5bffeab", "best_bid": "0.05", "best_ask": "0.96"}, {"asset_id": "33860025332294261066339194986447657969774333993404072754488955408971762620870", "price": "0.99", "size": "202.09", "side": "SELL", "hash": "d3a51be13ecff5775568cb2ff4823cce46ed30d2", "best_bid": "0.04", "best_ask": "0.95"}], "timestamp": "1769384757781", "event_type": "price_change"}}
{"_local_timestamp": "2026-01-25T23:46:09.868001+00:00", "data": {"market": "0xfaba55442a17a201a46f7ac19fd9394364f04959cdebfa420bc0c5ab2da00f59", "price_changes": [{"asset_id": "76829378806632943504106553503686063944439990588195206882350689917773385019771", "price": "0.09", "size": "600", "side": "BUY", "hash": "c8ddb6743a1441b8d14417700629fe628b5a7b65", "best_bid": "0.65", "best_ask": "0.81"}, {"asset_id": "103206131584345534219777803662235735845312981950233075829729747631018349006817", "price": "0.91", "size": "600", "side": "SELL", "hash": "8a7d12062f3948c15164db6d25224d302ca3375f", "best_bid": "0.19", "best_ask": "0.35"}], "timestamp": "1769384769796", "event_type": "price_change"}}
{"_local_timestamp": "2026-01-25T23:46:09.983324+00:00", "data": {"market": "0xfaba55442a17a201a46f7ac19fd9394364f04959cdebfa420bc0c5ab2da00f59", "price_changes": [{"asset_id": "103206131584345534219777803662235735845312981950233075829729747631018349006817", "price": "0.1", "size": "0", "side": "BUY", "hash": "f94a400d59fd3b3bfb5b4eb990f01127562a5f4a", "best_bid": "0.19", "best_ask": "0.35"}, {"asset_id": "76829378806632943504106553503686063944439990588195206882350689917773385019771", "price": "0.9", "size": "0", "side": "SELL", "hash": "db0877e7574b9c1317b91300d95fb5d7718a9889", "best_bid": "0.65", "best_ask": "0.81"}], "timestamp": "1769384769913", "event_type": "price_change"}}
{"_local_timestamp": "2026-01-25T23:46:09.984266+00:00", "data": {"market": "0xfaba55442a17a201a46f7ac19fd9394364f04959cdebfa420bc0c5ab2da00f59", "price_changes": [{"asset_id": "103206131584345534219777803662235735845312981950233075829729747631018349006817", "price": "0.09", "size": "0", "side": "BUY", "hash": "f94a400d59fd3b3bfb5b4eb990f01127562a5f4a", "best_bid": "0.19", "best_ask": "0.35"}, {"asset_id": "76829378806632943504106553503686063944439990588195206882350689917773385019771", "price": "0.91", "size": "0", "side": "SELL", "hash": "db0877e7574b9c1317b91300d95fb5d7718a9889", "best_bid": "0.65", "best_ask": "0.81"}], "timestamp": "1769384769913", "event_type": "price_change"}}
{"_local_timestamp": "2026-01-25T23:46:10.141582+00:00", "data": {"market": "0xfaba55442a17a201a46f7ac19fd9394364f04959cdebfa420bc0c5ab2da00f59", "price_changes": [{"asset_id": "76829378806632943504106553503686063944439990588195206882350689917773385019771", "price": "0.1", "size": "4263.55", "side": "BUY", "hash": "6c160f5ef2479fdac1c7be0a742ef4aebb80a2ab", "best_bid": "0.65", "best_ask": "0.81"}, {"asset_id": "103206131584345534219777803662235735845312981950233075829729747631018349006817", "price": "0.9", "size": "4263.55", "side": "SELL", "hash": "6a330b313c074a65985083f8d795cbd3679e26dd", "best_bid": "0.19", "best_ask": "0.35"}], "timestamp": "1769384770071", "event_type": "price_change"}}
{"_local_timestamp": "2026-01-25T23:46:10.187682+00:00", "data": {"market": "0xfaba55442a17a201a46f7ac19fd9394364f04959cdebfa420bc0c5ab2da00f59", "price_changes": [{"asset_id": "103206131584345534219777803662235735845312981950233075829729747631018349006817", "price": "0.1", "size": "890.11", "side": "BUY", "hash": "61922c47d3440d09357684245490fbb29a24f05b", "best_bid": "0.19", "best_ask": "0.35"}, {"asset_id": "76829378806632943504106553503686063944439990588195206882350689917773385019771", "price": "0.9", "size": "890.11", "side": "SELL", "hash": "06646d6fd228b3cca29c35ddd4d6f22c082fbdcf", "best_bid": "0.65", "best_ask": "0.81"}], "timestamp": "1769384770111", "event_type": "price_change"}}
{"_local_timestamp": "2026-01-25T23:46:10.188600+00:00", "data": {"market": "0xfaba55442a17a201a46f7ac19fd9394364f04959cdebfa420bc0c5ab2da00f59", "price_changes": [{"asset_id": "103206131584345534219777803662235735845312981950233075829729747631018349006817", "price": "0.09", "size": "890.11", "side": "BUY", "hash": "bb7f1539d66fa2b4317876711dc6f72886d313f1", "best_bid": "0.19", "best_ask": "0.35"}, {"asset_id": "76829378806632943504106553503686063944439990588195206882350689917773385019771", "price": "0.91", "size": "890.11", "side": "SELL", "hash": "6721ca29708d562fa9f0f2d30a96756aaa7bc933", "best_bid": "0.65", "best_ask": "0.81"}], "timestamp": "1769384770112", "event_type": "price_change"}}
{"_local_timestamp": "2026-01-25T23:46:12.036147+00:00", "data": {"market": "0xfaba55442a17a201a46f7ac19fd9394364f04959cdebfa420bc0c5ab2da00f59", "price_changes": [{"asset_id": "76829378806632943504106553503686063944439990588195206882350689917773385019771", "price": "0.09", "size": "200", "side": "BUY", "hash": "f6d159b5f8d49bdb02a2e613d913f2a947d61494", "best_bid": "0.65", "best_ask": "0.81"}, {"asset_id": "103206131584345534219777803662235735845312981950233075829729747631018349006817", "price": "0.91", "size": "200", "side": "SELL", "hash": "1358907f66bb8995699c38a37b1e780d0320e12f", "best_bid": "0.19", "best_ask": "0.35"}], "timestamp": "1769384771928", "event_type": "price_change"}}
{"_local_timestamp": "2026-01-25T23:46:12.092536+00:00", "data": {"market": "0xfaba55442a17a201a46f7ac19fd9394364f04959cdebfa420bc0c5ab2da00f59", "price_changes": [{"asset_id": "76829378806632943504106553503686063944439990588195206882350689917773385019771", "price": "0.08", "size": "1270.1", "side": "BUY", "hash": "b61a28ce17a66aa48cc1520aa1a7c6cd893ecbc2", "best_bid": "0.65", "best_ask": "0.81"}, {"asset_id": "103206131584345534219777803662235735845312981950233075829729747631018349006817", "price": "0.92", "size": "1270.1", "side": "SELL", "hash": "498762d6000b02e02a321c2a9874cd86ffcd4ea5", "best_bid": "0.19", "best_ask": "0.35"}], "timestamp": "1769384772012", "event_type": "price_change"}}
{"_local_timestamp": "2026-01-25T23:46:12.139831+00:00", "data": {"market": "0xfaba55442a17a201a46f7ac19fd9394364f04959cdebfa420bc0c5ab2da00f59", "price_changes": [{"asset_id": "76829378806632943504106553503686063944439990588195206882350689917773385019771", "price": "0.08", "size": "2160.21", "side": "BUY", "hash": "60b5024f2609f78464a7e721a276bfc67a503c3d", "best_bid": "0.65", "best_ask": "0.81"}, {"asset_id": "103206131584345534219777803662235735845312981950233075829729747631018349006817", "price": "0.92", "size": "2160.21", "side": "SELL", "hash": "d41588d2bd1f041c2fda362ad6fbb7793a685225", "best_bid": "0.19", "best_ask": "0.35"}], "timestamp": "1769384772073", "event_type": "price_change"}}
{"_local_timestamp": "2026-01-25T23:46:12.140894+00:00", "data": {"market": "0xfaba55442a17a201a46f7ac19fd9394364f04959cdebfa420bc0c5ab2da00f59", "price_changes": [{"asset_id": "76829378806632943504106553503686063944439990588195206882350689917773385019771", "price": "0.08", "size": "4157.32", "side": "BUY", "hash": "9553c1c3c089668940c4d60fdf59e9f6695dae6a", "best_bid": "0.65", "best_ask": "0.81"}, {"asset_id": "103206131584345534219777803662235735845312981950233075829729747631018349006817", "price": "0.92", "size": "4157.32", "side": "SELL", "hash": "d0ec58d426298deaa8c1b6680931f96dd79c6d4f", "best_bid": "0.19", "best_ask": "0.35"}], "timestamp": "1769384772074", "event_type": "price_change"}}
{"_local_timestamp": "2026-01-25T23:46:12.294606+00:00", "data": {"market": "0xfaba55442a17a201a46f7ac19fd9394364f04959cdebfa420bc0c5ab2da00f59", "price_changes": [{"asset_id": "76829378806632943504106553503686063944439990588195206882350689917773385019771", "price": "0.1", "size": "4663.55", "side": "BUY", "hash": "1e759449fc07af710b011e81d283b72e62ced016", "best_bid": "0.65", "best_ask": "0.81"}, {"asset_id": "103206131584345534219777803662235735845312981950233075829729747631018349006817", "price": "0.9", "size": "4663.55", "side": "SELL", "hash": "2e238d934f92364163f2bf17fc920b0c3be9545b", "best_bid": "0.19", "best_ask": "0.35"}], "timestamp": "1769384772226", "event_type": "price_change"}}
{"_local_timestamp": "2026-01-25T23:46:22.117183+00:00", "data": {"market": "0xfaba55442a17a201a46f7ac19fd9394364f04959cdebfa420bc0c5ab2da00f59", "price_changes": [{"asset_id": "76829378806632943504106553503686063944439990588195206882350689917773385019771", "price": "0.09", "size": "100", "side": "BUY", "hash": "6c88e05ea19f9925669d576db1a2cfe504323b9b", "best_bid": "0.65", "best_ask": "0.81"}, {"asset_id": "103206131584345534219777803662235735845312981950233075829729747631018349006817", "price": "0.91", "size": "100", "side": "SELL", "hash": "1e51edb993cac917028ffabfbf26543f3961663d", "best_bid": "0.19", "best_ask": "0.35"}], "timestamp": "1769384782028", "event_type": "price_change"}}
{"_local_timestamp": "2026-01-25T23:46:22.334986+00:00", "data": {"market": "0xfaba55442a17a201a46f7ac19fd9394364f04959cdebfa420bc0c5ab2da00f59", "price_changes": [{"asset_id": "103206131584345534219777803662235735845312981950233075829729747631018349006817", "price": "0.1", "size": "0", "side": "BUY", "hash": "a3a43b2ea72cebde2c28c88c22a25bc40665cf2f", "best_bid": "0.19", "best_ask": "0.35"}, {"asset_id": "76829378806632943504106553503686063944439990588195206882350689917773385019771", "price": "0.9", "size": "0", "side": "SELL", "hash": "ba4849fa49825fab0badf139753619fc09281feb", "best_bid": "0.65", "best_ask": "0.81"}], "timestamp": "1769384782265", "event_type": "price_change"}}
{"_local_timestamp": "2026-01-25T23:46:22.338629+00:00", "data": {"market": "0xfaba55442a17a201a46f7ac19fd9394364f04959cdebfa420bc0c5ab2da00f59", "price_changes": [{"asset_id": "103206131584345534219777803662235735845312981950233075829729747631018349006817", "price": "0.09", "size": "0", "side": "BUY", "hash": "a3a43b2ea72cebde2c28c88c22a25bc40665cf2f", "best_bid": "0.19", "best_ask": "0.35"}, {"asset_id": "76829378806632943504106553503686063944439990588195206882350689917773385019771", "price": "0.91", "size": "0", "side": "SELL", "hash": "ba4849fa49825fab0badf139753619fc09281feb", "best_bid": "0.65", "best_ask": "0.81"}], "timestamp": "1769384782265", "event_type": "price_change"}}
{"_local_timestamp": "2026-01-25T23:46:22.340242+00:00", "data": {"market": "0xfaba55442a17a201a46f7ac19fd9394364f04959cdebfa420bc0c5ab2da00f59", "price_changes": [{"asset_id": "76829378806632943504106553503686063944439990588195206882350689917773385019771", "price": "0.1", "size": "506.23", "side": "BUY", "hash": "4be8fad00f75a0ff000c1da4a68373fd57caa3a9", "best_bid": "0.65", "best_ask": "0.81"}, {"asset_id": "103206131584345534219777803662235735845312981950233075829729747631018349006817", "price": "0.9", "size": "506.23", "side": "SELL", "hash": "92d7ee6656dd9530358e13b47d86a3422df178cb", "best_bid": "0.19", "best_ask": "0.35"}], "timestamp": "1769384782266", "event_type": "price_change"}}
{"_local_timestamp": "2026-01-25T23:46:22.392692+00:00", "data": {"market": "0xfaba55442a17a201a46f7ac19fd9394364f04959cdebfa420bc0c5ab2da00f59", "price_changes": [{"asset_id": "76829378806632943504106553503686063944439990588195206882350689917773385019771", "price": "0.1", "size": "606.23", "side": "BUY", "hash": "168b8d7c48c29a01e104b1dcadbfb5212a6f70d7", "best_bid": "0.65", "best_ask": "0.81"}, {"asset_id": "103206131584345534219777803662235735845312981950233075829729747631018349006817", "price": "0.9", "size": "606.23", "side": "SELL", "hash": "cc7c2adcc921debce6085d192e000ed4f14c8607", "best_bid": "0.19", "best_ask": "0.35"}], "timestamp": "1769384782324", "event_type": "price_change"}}
{"_local_timestamp": "2026-01-25T23:46:22.456314+00:00", "data": {"market": "0xfaba55442a17a201a46f7ac19fd9394364f04959cdebfa420bc0c5ab2da00f59", "price_changes": [{"asset_id": "76829378806632943504106553503686063944439990588195206882350689917773385019771", "price": "0.11", "size": "5999.11", "side": "BUY", "hash": "7b3695ad547112e73341c355b821589aecb2a2c8", "best_bid": "0.65", "best_ask": "0.81"}, {"asset_id": "103206131584345534219777803662235735845312981950233075829729747631018349006817", "price": "0.89", "size": "5999.11", "side": "SELL", "hash": "5d01678ccdc09a75f353deca40ccc2337f87cbf1", "best_bid": "0.19", "best_ask": "0.35"}], "timestamp": "1769384782384", "event_type": "price_change"}}
{"_local_timestamp": "2026-01-25T23:46:22.534292+00:00", "data": {"market": "0xfaba55442a17a201a46f7ac19fd9394364f04959cdebfa420bc0c5ab2da00f59", "price_changes": [{"asset_id": "76829378806632943504106553503686063944439990588195206882350689917773385019771", "price": "0.11", "size": "6889.22", "side": "BUY", "hash": "813bed87bf3819ef44cc7055d3253a63a2e7fbe0", "best_bid": "0.65", "best_ask": "0.81"}, {"asset_id": "103206131584345534219777803662235735845312981950233075829729747631018349006817", "price": "0.89", "size": "6889.22", "side": "SELL", "hash": "240658c46c0d120cd5eb38fc646d1c4f5c564715", "best_bid": "0.19", "best_ask": "0.35"}], "timestamp": "1769384782455", "event_type": "price_change"}}
{"_local_timestamp": "2026-01-25T23:46:22.535267+00:00", "data": {"market": "0xfaba55442a17a201a46f7ac19fd9394364f04959cdebfa420bc0c5ab2da00f59", "price_changes": [{"asset_id": "76829378806632943504106553503686063944439990588195206882350689917773385019771", "price": "0.11", "size": "8886.33", "side": "BUY", "hash": "575e6d3d26cac3e14ae21c904c6dadbc2def3bfe", "best_bid": "0.65", "best_ask": "0.81"}, {"asset_id": "103206131584345534219777803662235735845312981950233075829729747631018349006817", "price": "0.89", "size": "8886.33", "side": "SELL", "hash": "ccef99c694089e492bf62f165b5c829335f5a423", "best_bid": "0.19", "best_ask": "0.35"}], "timestamp": "1769384782455", "event_type": "price_change"}}
{"_local_timestamp": "2026-01-25T23:46:22.536191+00:00", "data": {"market": "0xfaba55442a17a201a46f7ac19fd9394364f04959cdebfa420bc0c5ab2da00f59", "price_changes": [{"asset_id": "76829378806632943504106553503686063944439990588195206882350689917773385019771", "price": "0.11", "size": "10156.43", "side": "BUY", "hash": "2c089e4c35a5e10566a644e7855dfd2bfa15108c", "best_bid": "0.65", "best_ask": "0.81"}, {"asset_id": "103206131584345534219777803662235735845312981950233075829729747631018349006817", "price": "0.89", "size": "10156.43", "side": "SELL", "hash": "7671343b15dd9c5643183126b27c9317ae597a26", "best_bid": "0.19", "best_ask": "0.35"}], "timestamp": "1769384782456", "event_type": "price_change"}}
{"_local_timestamp": "2026-01-25T23:46:25.908517+00:00", "data": {"market": "0xfaba55442a17a201a46f7ac19fd9394364f04959cdebfa420bc0c5ab2da00f59", "price_changes": [{"asset_id": "76829378806632943504106553503686063944439990588195206882350689917773385019771", "price": "0.09", "size": "0", "side": "BUY", "hash": "e1754dd2214e7b333945fba85a8398753d44a509", "best_bid": "0.65", "best_ask": "0.81"}, {"asset_id": "103206131584345534219777803662235735845312981950233075829729747631018349006817", "price": "0.91", "size": "0", "side": "SELL", "hash": "1e157874737554f8a316abb29fdd4b7fe6b4c74f", "best_bid": "0.19", "best_ask": "0.35"}], "timestamp": "1769384785833", "event_type": "price_change"}}
{"_local_timestamp": "2026-01-25T23:46:26.094125+00:00", "data": {"market": "0xfaba55442a17a201a46f7ac19fd9394364f04959cdebfa420bc0c5ab2da00f59", "price_changes": [{"asset_id": "76829378806632943504106553503686063944439990588195206882350689917773385019771", "price": "0.08", "size": "0", "side": "BUY", "hash": "691b5ef0b8878660f28fe53c0eb95833d7f4b7ee", "best_bid": "0.65", "best_ask": "0.81"}, {"asset_id": "103206131584345534219777803662235735845312981950233075829729747631018349006817", "price": "0.92", "size": "0", "side": "SELL", "hash": "1c5747a6259844bd1cda35ca905669cc7609a939", "best_bid": "0.19", "best_ask": "0.35"}], "timestamp": "1769384786008", "event_type": "price_change"}}
{"_local_timestamp": "2026-01-25T23:46:26.095119+00:00", "data": {"market": "0xfaba55442a17a201a46f7ac19fd9394364f04959cdebfa420bc0c5ab2da00f59", "price_changes": [{"asset_id": "76829378806632943504106553503686063944439990588195206882350689917773385019771", "price": "0.11", "size": "4157.32", "side": "BUY", "hash": "691b5ef0b8878660f28fe53c0eb95833d7f4b7ee", "best_bid": "0.65", "best_ask": "0.81"}, {"asset_id": "103206131584345534219777803662235735845312981950233075829729747631018349006817", "price": "0.89", "size": "4157.32", "side": "SELL", "hash": "1c5747a6259844bd1cda35ca905669cc7609a939", "best_bid": "0.19", "best_ask": "0.35"}], "timestamp": "1769384786008", "event_type": "price_change"}}
{"_local_timestamp": "2026-01-25T23:46:26.203969+00:00", "data": {"market": "0xfaba55442a17a201a46f7ac19fd9394364f04959cdebfa420bc0c5ab2da00f59", "price_changes": [{"asset_id": "76829378806632943504106553503686063944439990588195206882350689917773385019771", "price": "0.1", "size": "706.23", "side": "BUY", "hash": "4649d232b687d080a01aa6bd00f60ecdcc37960b", "best_bid": "0.65", "best_ask": "0.81"}, {"asset_id": "103206131584345534219777803662235735845312981950233075829729747631018349006817", "price": "0.9", "size": "706.23", "side": "SELL", "hash": "6aeb132c6424454ffe5703b3a0bd6c5f59ef6619", "best_bid": "0.19", "best_ask": "0.35"}], "timestamp": "1769384786134", "event_type": "price_change"}}
{"_local_timestamp": "2026-01-25T23:46:52.918437+00:00", "data": {"market": "0xfaba55442a17a201a46f7ac19fd9394364f04959cdebfa420bc0c5ab2da00f59", "price_changes": [{"asset_id": "76829378806632943504106553503686063944439990588195206882350689917773385019771", "price": "0.1", "size": "606.23", "side": "BUY", "hash": "0eb67bd030e523f5a21f23217d3ad90e341f3fdc", "best_bid": "0.65", "best_ask": "0.81"}, {"asset_id": "103206131584345534219777803662235735845312981950233075829729747631018349006817", "price": "0.9", "size": "606.23", "side": "SELL", "hash": "ce7df8b3bf41e80dd2edbb9a7d3e09a1f93a6050", "best_bid": "0.19", "best_ask": "0.35"}], "timestamp": "1769384812753", "event_type": "price_change"}}
{"_local_timestamp": "2026-01-25T23:46:53.229784+00:00", "data": {"market": "0xfaba55442a17a201a46f7ac19fd9394364f04959cdebfa420bc0c5ab2da00f59", "price_changes": [{"asset_id": "76829378806632943504106553503686063944439990588195206882350689917773385019771", "price": "0.11", "size": "4257.32", "side": "BUY", "hash": "549f8d7241d248f2fe472757898fc44cf28e907e", "best_bid": "0.65", "best_ask": "0.81"}, {"asset_id": "103206131584345534219777803662235735845312981950233075829729747631018349006817", "price": "0.89", "size": "4257.32", "side": "SELL", "hash": "1e4772e255515a49c3af8903609f08225376e021", "best_bid": "0.19", "best_ask": "0.35"}], "timestamp": "1769384813065", "event_type": "price_change"}}
{"_local_timestamp": "2026-01-25T23:46:54.256875+00:00", "data": {"market": "0xfaba55442a17a201a46f7ac19fd9394364f04959cdebfa420bc0c5ab2da00f59", "price_changes": [{"asset_id": "76829378806632943504106553503686063944439990588195206882350689917773385019771", "price": "0.1", "size": "506.23", "side": "BUY", "hash": "6a93b5df2af5c2ccd63fe2e3d61f70e91af63079", "best_bid": "0.65", "best_ask": "0.81"}, {"asset_id": "103206131584345534219777803662235735845312981950233075829729747631018349006817", "price": "0.9", "size": "506.23", "side": "SELL", "hash": "ccf0dc0e50b9a6ab8f54f0e572a3e3aa0f74398c", "best_bid": "0.19", "best_ask": "0.35"}], "timestamp": "1769384814122", "event_type": "price_change"}}
{"_local_timestamp": "2026-01-25T23:46:54.257869+00:00", "data": {"market": "0xfaba55442a17a201a46f7ac19fd9394364f04959cdebfa420bc0c5ab2da00f59", "price_changes": [{"asset_id": "76829378806632943504106553503686063944439990588195206882350689917773385019771", "price": "0.1", "size": "106.23", "side": "BUY", "hash": "898af506ced2e11517999dc709ea5c290f64aaab", "best_bid": "0.65", "best_ask": "0.81"}, {"asset_id": "103206131584345534219777803662235735845312981950233075829729747631018349006817", "price": "0.9", "size": "106.23", "side": "SELL", "hash": "63ec9f74edfe9121bb20ba7415165a5a2bbc6918", "best_bid": "0.19", "best_ask": "0.35"}], "timestamp": "1769384814129", "event_type": "price_change"}}
{"_local_timestamp": "2026-01-25T23:46:54.390687+00:00", "data": {"market": "0xfaba55442a17a201a46f7ac19fd9394364f04959cdebfa420bc0c5ab2da00f59", "price_changes": [{"asset_id": "76829378806632943504106553503686063944439990588195206882350689917773385019771", "price": "0.08", "size": "890.11", "side": "BUY", "hash": "bc68d05632dbce4f7c6e1ee0193d040a5189218e", "best_bid": "0.65", "best_ask": "0.81"}, {"asset_id": "103206131584345534219777803662235735845312981950233075829729747631018349006817", "price": "0.92", "size": "890.11", "side": "SELL", "hash": "b32a7505421b4604144c0eb3f183d08a05ecbd60", "best_bid": "0.19", "best_ask": "0.35"}], "timestamp": "1769384814269", "event_type": "price_change"}}
{"_local_timestamp": "2026-01-25T23:46:54.438170+00:00", "data": {"market": "0xfaba55442a17a201a46f7ac19fd9394364f04959cdebfa420bc0c5ab2da00f59", "price_changes": [{"asset_id": "76829378806632943504106553503686063944439990588195206882350689917773385019771", "price": "0.08", "size": "2887.22", "side": "BUY", "hash": "832f8b899a488034164a047b91606777754075a5", "best_bid": "0.65", "best_ask": "0.81"}, {"asset_id": "103206131584345534219777803662235735845312981950233075829729747631018349006817", "price": "0.92", "size": "2887.22", "side": "SELL", "hash": "9a96352ea21e50386615b7ba8787d9219a8f82d5", "best_bid": "0.19", "best_ask": "0.35"}], "timestamp": "1769384814314", "event_type": "price_change"}}
{"_local_timestamp": "2026-01-25T23:46:54.516642+00:00", "data": {"market": "0xfaba55442a17a201a46f7ac19fd9394364f04959cdebfa420bc0c5ab2da00f59", "price_changes": [{"asset_id": "76829378806632943504106553503686063944439990588195206882350689917773385019771", "price": "0.11", "size": "4657.32", "side": "BUY", "hash": "3ef272ff2b68424a1af2c7fd1a3deec434e9106b", "best_bid": "0.65", "best_ask": "0.81"}, {"asset_id": "103206131584345534219777803662235735845312981950233075829729747631018349006817", "price": "0.89", "size": "4657.32", "side": "SELL", "hash": "94994b97e3f20023689f7444a8f7e6fbb4be5b09", "best_bid": "0.19", "best_ask": "0.35"}], "timestamp": "1769384814401", "event_type": "price_change"}}
{"_local_timestamp": "2026-01-25T23:46:54.538416+00:00", "data": {"market": "0xfaba55442a17a201a46f7ac19fd9394364f04959cdebfa420bc0c5ab2da00f59", "price_changes": [{"asset_id": "76829378806632943504106553503686063944439990588195206882350689917773385019771", "price": "0.11", "size": "4757.32", "side": "BUY", "hash": "9a745653e8a55861df9f665d695bddfd07901163", "best_bid": "0.65", "best_ask": "0.81"}, {"asset_id": "103206131584345534219777803662235735845312981950233075829729747631018349006817", "price": "0.89", "size": "4757.32", "side": "SELL", "hash": "b93b4a3a84fd6704b5d6f8022e37f69429afb4a6", "best_bid": "0.19", "best_ask": "0.35"}], "timestamp": "1769384814411", "event_type": "price_change"}}
{"_local_timestamp": "2026-01-25T23:46:54.552568+00:00", "data": {"market": "0xfaba55442a17a201a46f7ac19fd9394364f04959cdebfa420bc0c5ab2da00f59", "price_changes": [{"asset_id": "76829378806632943504106553503686063944439990588195206882350689917773385019771", "price": "0.08", "size": "4157.32", "side": "BUY", "hash": "48eb9eb16b3b73e1cbe78a8a98ef2a62fd782485", "best_bid": "0.65", "best_ask": "0.81"}, {"asset_id": "103206131584345534219777803662235735845312981950233075829729747631018349006817", "price": "0.92", "size": "4157.32", "side": "SELL", "hash": "92a7141f111d1c11dbab050c4fbcfb3da09a3f11", "best_bid": "0.19", "best_ask": "0.35"}], "timestamp": "1769384814429", "event_type": "price_change"}}
{"_local_timestamp": "2026-01-25T23:46:55.808801+00:00", "data": {"market": "0xfaba55442a17a201a46f7ac19fd9394364f04959cdebfa420bc0c5ab2da00f59", "price_changes": [{"asset_id": "103206131584345534219777803662235735845312981950233075829729747631018349006817", "price": "0.11", "size": "300", "side": "BUY", "hash": "f08ad8f22e4fd7782748fa867e986784d3b1d6d8", "best_bid": "0.19", "best_ask": "0.35"}, {"asset_id": "76829378806632943504106553503686063944439990588195206882350689917773385019771", "price": "0.89", "size": "300", "side": "SELL", "hash": "a1a98bb2040240a790e44f4b6c9a62ca6ea72b7c", "best_bid": "0.65", "best_ask": "0.81"}], "timestamp": "1769384815677", "event_type": "price_change"}}
{"_local_timestamp": "2026-01-25T23:46:56.005891+00:00", "data": {"market": "0xfaba55442a17a201a46f7ac19fd9394364f04959cdebfa420bc0c5ab2da00f59", "price_changes": [{"asset_id": "103206131584345534219777803662235735845312981950233075829729747631018349006817", "price": "0.12", "size": "890.11", "side": "BUY", "hash": "5e5d410fc6da8f86b86fdbcb42f4b4bcbff0e6af", "best_bid": "0.19", "best_ask": "0.35"}, {"asset_id": "76829378806632943504106553503686063944439990588195206882350689917773385019771", "price": "0.88", "size": "890.11", "side": "SELL", "hash": "b5283e123bed56382516f5fb5eb38d8afebe06bf", "best_bid": "0.65", "best_ask": "0.81"}], "timestamp": "1769384815900", "event_type": "price_change"}}
{"_local_timestamp": "2026-01-25T23:46:56.006948+00:00", "data": {"market": "0xfaba55442a17a201a46f7ac19fd9394364f04959cdebfa420bc0c5ab2da00f59", "price_changes": [{"asset_id": "103206131584345534219777803662235735845312981950233075829729747631018349006817", "price": "0.11", "size": "1190.11", "side": "BUY", "hash": "3f8e60cda07f9515e19e7760d321a6cd088966c5", "best_bid": "0.19", "best_ask": "0.35"}, {"asset_id": "76829378806632943504106553503686063944439990588195206882350689917773385019771", "price": "0.89", "size": "1190.11", "side": "SELL", "hash": "17d3941cb051bf0e81d0f7e83af875ba10b75b5c", "best_bid": "0.65", "best_ask": "0.81"}], "timestamp": "1769384815901", "event_type": "price_change"}}
{"_local_timestamp": "2026-01-25T23:47:01.379607+00:00", "data": {"market": "0xfaba55442a17a201a46f7ac19fd9394364f04959cdebfa420bc0c5ab2da00f59", "price_changes": [{"asset_id": "76829378806632943504106553503686063944439990588195206882350689917773385019771", "price": "0.1", "size": "6.23", "side": "BUY", "hash": "f8c12aa3f7a52038b121cad517fbb7c3adca6791", "best_bid": "0.65", "best_ask": "0.81"}, {"asset_id": "103206131584345534219777803662235735845312981950233075829729747631018349006817", "price": "0.9", "size": "6.23", "side": "SELL", "hash": "7078832374d3d70edfc23f05d469216c6249efb7", "best_bid": "0.19", "best_ask": "0.35"}], "timestamp": "1769384821251", "event_type": "price_change"}}
{"_local_timestamp": "2026-01-25T23:47:01.575450+00:00", "data": {"market": "0xfaba55442a17a201a46f7ac19fd9394364f04959cdebfa420bc0c5ab2da00f59", "price_changes": [{"asset_id": "76829378806632943504106553503686063944439990588195206882350689917773385019771", "price": "0.12", "size": "890.11", "side": "BUY", "hash": "2e75730ba8983df2a5ebf4b738786319114004c6", "best_bid": "0.65", "best_ask": "0.81"}, {"asset_id": "103206131584345534219777803662235735845312981950233075829729747631018349006817", "price": "0.88", "size": "890.11", "side": "SELL", "hash": "6641aacdad73ef77ea72c34effffad3dc4015a6f", "best_bid": "0.19", "best_ask": "0.35"}], "timestamp": "1769384821435", "event_type": "price_change"}}
{"_local_timestamp": "2026-01-25T23:47:01.576577+00:00", "data": {"market": "0xfaba55442a17a201a46f7ac19fd9394364f04959cdebfa420bc0c5ab2da00f59", "price_changes": [{"asset_id": "76829378806632943504106553503686063944439990588195206882350689917773385019771", "price": "0.12", "size": "2160.21", "side": "BUY", "hash": "4675cf2b7049098a53aef089e9f0755623ec3294", "best_bid": "0.65", "best_ask": "0.81"}, {"asset_id": "103206131584345534219777803662235735845312981950233075829729747631018349006817", "price": "0.88", "size": "2160.21", "side": "SELL", "hash": "ace838335f328d138a92dacc12ead362422e936f", "best_bid": "0.19", "best_ask": "0.35"}], "timestamp": "1769384821436", "event_type": "price_change"}}
{"_local_timestamp": "2026-01-25T23:47:01.596784+00:00", "data": {"market": "0xfaba55442a17a201a46f7ac19fd9394364f04959cdebfa420bc0c5ab2da00f59", "price_changes": [{"asset_id": "76829378806632943504106553503686063944439990588195206882350689917773385019771", "price": "0.12", "size": "4157.32", "side": "BUY", "hash": "4565d5368601e6bd00f7109581e35b4bad2152b1", "best_bid": "0.65", "best_ask": "0.81"}, {"asset_id": "103206131584345534219777803662235735845312981950233075829729747631018349006817", "price": "0.88", "size": "4157.32", "side": "SELL", "hash": "26d3074cdf90dd90fa4c80d194507dcf1e50f620", "best_bid": "0.19", "best_ask": "0.35"}], "timestamp": "1769384821465", "event_type": "price_change"}}
{"_local_timestamp": "2026-01-25T23:47:01.635020+00:00", "data": {"market": "0xfaba55442a17a201a46f7ac19fd9394364f04959cdebfa420bc0c5ab2da00f59", "price_changes": [{"asset_id": "76829378806632943504106553503686063944439990588195206882350689917773385019771", "price": "0.11", "size": "2597.11", "side": "BUY", "hash": "34c7f56543f35c527dca61636aa3585f5fb9d366", "best_bid": "0.65", "best_ask": "0.81"}, {"asset_id": "103206131584345534219777803662235735845312981950233075829729747631018349006817", "price": "0.89", "size": "2597.11", "side": "SELL", "hash": "c4d56a40e11549fd7efd6c94a13b4d33ba31869b", "best_bid": "0.19", "best_ask": "0.35"}], "timestamp": "1769384821503", "event_type": "price_change"}}
{"_local_timestamp": "2026-01-25T23:47:01.636402+00:00", "data": {"market": "0xfaba55442a17a201a46f7ac19fd9394364f04959cdebfa420bc0c5ab2da00f59", "price_changes": [{"asset_id": "76829378806632943504106553503686063944439990588195206882350689917773385019771", "price": "0.08", "size": "1997.11", "side": "BUY", "hash": "34c7f56543f35c527dca61636aa3585f5fb9d366", "best_bid": "0.65", "best_ask": "0.81"}, {"asset_id": "103206131584345534219777803662235735845312981950233075829729747631018349006817", "price": "0.92", "size": "1997.11", "side": "SELL", "hash": "c4d56a40e11549fd7efd6c94a13b4d33ba31869b", "best_bid": "0.19", "best_ask": "0.35"}], "timestamp": "1769384821503", "event_type": "price_change"}}
{"_local_timestamp": "2026-01-25T23:47:01.637428+00:00", "data": {"market": "0xfaba55442a17a201a46f7ac19fd9394364f04959cdebfa420bc0c5ab2da00f59", "price_changes": [{"asset_id": "103206131584345534219777803662235735845312981950233075829729747631018349006817", "price": "0.08", "size": "6.81", "side": "BUY", "hash": "a73f47584f736957f1797b9b3be0f7f358a97b2e", "best_bid": "0.19", "best_ask": "0.35"}, {"asset_id": "76829378806632943504106553503686063944439990588195206882350689917773385019771", "price": "0.92", "size": "6.81", "side": "SELL", "hash": "5baa10cbfb77db3e0f9aa5135ccf640a884dfe78", "best_bid": "0.65", "best_ask": "0.81"}], "timestamp": "1769384821503", "event_type": "price_change"}}
{"_local_timestamp": "2026-01-25T23:47:01.638418+00:00", "data": {"market": "0xfaba55442a17a201a46f7ac19fd9394364f04959cdebfa420bc0c5ab2da00f59", "price_changes": [{"asset_id": "103206131584345534219777803662235735845312981950233075829729747631018349006817", "price": "0.07", "size": "200", "side": "BUY", "hash": "a73f47584f736957f1797b9b3be0f7f358a97b2e", "best_bid": "0.19", "best_ask": "0.35"}, {"asset_id": "76829378806632943504106553503686063944439990588195206882350689917773385019771", "price": "0.93", "size": "200", "side": "SELL", "hash": "5baa10cbfb77db3e0f9aa5135ccf640a884dfe78", "best_bid": "0.65", "best_ask": "0.81"}], "timestamp": "1769384821503", "event_type": "price_change"}}
{"_local_timestamp": "2026-01-25T23:47:01.666679+00:00", "data": {"market": "0xfaba55442a17a201a46f7ac19fd9394364f04959cdebfa420bc0c5ab2da00f59", "price_changes": [{"asset_id": "76829378806632943504106553503686063944439990588195206882350689917773385019771", "price": "0.11", "size": "2697.11", "side": "BUY", "hash": "2020415fcce15a5c45219877ff53c73e98d40d22", "best_bid": "0.65", "best_ask": "0.81"}, {"asset_id": "103206131584345534219777803662235735845312981950233075829729747631018349006817", "price": "0.89", "size": "2697.11", "side": "SELL", "hash": "074bc389310a1f5e7938ee5f3d093570adbbab2f", "best_bid": "0.19", "best_ask": "0.35"}], "timestamp": "1769384821542", "event_type": "price_change"}}
{"_local_timestamp": "2026-01-25T23:47:01.667802+00:00", "data": {"market": "0xfaba55442a17a201a46f7ac19fd9394364f04959cdebfa420bc0c5ab2da00f59", "price_changes": [{"asset_id": "76829378806632943504106553503686063944439990588195206882350689917773385019771", "price": "0.12", "size": "10156.43", "side": "BUY", "hash": "6891e51e7aaff3ca0497528fc5c80cffc050fbee", "best_bid": "0.65", "best_ask": "0.81"}, {"asset_id": "103206131584345534219777803662235735845312981950233075829729747631018349006817", "price": "0.88", "size": "10156.43", "side": "SELL", "hash": "54716bb0c3060292c7d1361d277ab99b3433c3cc", "best_bid": "0.19", "best_ask": "0.35"}], "timestamp": "1769384821545", "event_type": "price_change"}}
{"_local_timestamp": "2026-01-25T23:47:01.730790+00:00", "data": {"market": "0xfaba55442a17a201a46f7ac19fd9394364f04959cdebfa420bc0c5ab2da00f59", "price_changes": [{"asset_id": "76829378806632943504106553503686063944439990588195206882350689917773385019771", "price": "0.11", "size": "700", "side": "BUY", "hash": "afc349d9004efb3727ca300b99c62ecdd589f2fe", "best_bid": "0.65", "best_ask": "0.81"}, {"asset_id": "103206131584345534219777803662235735845312981950233075829729747631018349006817", "price": "0.89", "size": "700", "side": "SELL", "hash": "ee25b6bcf4447ead849494737eec838ff8f7f410", "best_bid": "0.19", "best_ask": "0.35"}], "timestamp": "1769384821602", "event_type": "price_change"}}
{"_local_timestamp": "2026-01-25T23:47:01.731933+00:00", "data": {"market": "0xfaba55442a17a201a46f7ac19fd9394364f04959cdebfa420bc0c5ab2da00f59", "price_changes": [{"asset_id": "76829378806632943504106553503686063944439990588195206882350689917773385019771", "price": "0.08", "size": "0", "side": "BUY", "hash": "afc349d9004efb3727ca300b99c62ecdd589f2fe", "best_bid": "0.65", "best_ask": "0.81"}, {"asset_id": "103206131584345534219777803662235735845312981950233075829729747631018349006817", "price": "0.92", "size": "0", "side": "SELL", "hash": "ee25b6bcf4447ead849494737eec838ff8f7f410", "best_bid": "0.19", "best_ask": "0.35"}], "timestamp": "1769384821602", "event_type": "price_change"}}
{"_local_timestamp": "2026-01-25T23:47:29.495907+00:00", "data": {"market": "0xfaba55442a17a201a46f7ac19fd9394364f04959cdebfa420bc0c5ab2da00f59", "price_changes": [{"asset_id": "76829378806632943504106553503686063944439990588195206882350689917773385019771", "price": "0.11", "size": "600", "side": "BUY", "hash": "a6f4e999879b8fe32978464faf141435821bee6f", "best_bid": "0.65", "best_ask": "0.81"}, {"asset_id": "103206131584345534219777803662235735845312981950233075829729747631018349006817", "price": "0.89", "size": "600", "side": "SELL", "hash": "94a903dc1eb421468c706fcac900efa58c7446ad", "best_bid": "0.19", "best_ask": "0.35"}], "timestamp": "1769384849264", "event_type": "price_change"}}
{"_local_timestamp": "2026-01-25T23:47:29.604371+00:00", "data": {"market": "0xfaba55442a17a201a46f7ac19fd9394364f04959cdebfa420bc0c5ab2da00f59", "price_changes": [{"asset_id": "76829378806632943504106553503686063944439990588195206882350689917773385019771", "price": "0.12", "size": "4157.32", "side": "BUY", "hash": "5dc8c72b292d4d8c8057ea17567b6f390014ee6c", "best_bid": "0.65", "best_ask": "0.81"}, {"asset_id": "103206131584345534219777803662235735845312981950233075829729747631018349006817", "price": "0.88", "size": "4157.32", "side": "SELL", "hash": "f4b1d853abb75bc51a23e4f555e055f71a708095", "best_bid": "0.19", "best_ask": "0.35"}], "timestamp": "1769384849365", "event_type": "price_change"}}
{"_local_timestamp": "2026-01-25T23:47:29.805680+00:00", "data": {"market": "0xfaba55442a17a201a46f7ac19fd9394364f04959cdebfa420bc0c5ab2da00f59", "price_changes": [{"asset_id": "76829378806632943504106553503686063944439990588195206882350689917773385019771", "price": "0.12", "size": "4257.32", "side": "BUY", "hash": "c4ca9415c7a679bd58bc9ae96a4f88b7aee41f50", "best_bid": "0.65", "best_ask": "0.81"}, {"asset_id": "103206131584345534219777803662235735845312981950233075829729747631018349006817", "price": "0.88", "size": "4257.32", "side": "SELL", "hash": "1a808e13e2305925e2d9f6328a1b771ea77ae29c", "best_bid": "0.19", "best_ask": "0.35"}], "timestamp": "1769384849554", "event_type": "price_change"}}
{"_local_timestamp": "2026-01-25T23:47:30.191756+00:00", "data": {"market": "0xfaba55442a17a201a46f7ac19fd9394364f04959cdebfa420bc0c5ab2da00f59", "price_changes": [{"asset_id": "76829378806632943504106553503686063944439990588195206882350689917773385019771", "price": "0.11", "size": "500", "side": "BUY", "hash": "d2d28eaa56686b2541533c7f6b16d153ad1ef3d0", "best_bid": "0.65", "best_ask": "0.81"}, {"asset_id": "103206131584345534219777803662235735845312981950233075829729747631018349006817", "price": "0.89", "size": "500", "side": "SELL", "hash": "f3124f41080d4931211f65370af73221b3ea48b4", "best_bid": "0.19", "best_ask": "0.35"}], "timestamp": "1769384849934", "event_type": "price_change"}}
{"_local_timestamp": "2026-01-25T23:47:30.309943+00:00", "data": {"market": "0xfaba55442a17a201a46f7ac19fd9394364f04959cdebfa420bc0c5ab2da00f59", "price_changes": [{"asset_id": "76829378806632943504106553503686063944439990588195206882350689917773385019771", "price": "0.08", "size": "1997.11", "side": "BUY", "hash": "4dc9efaa60e902b9867a651616c8ff48c218b3cb", "best_bid": "0.65", "best_ask": "0.81"}, {"asset_id": "103206131584345534219777803662235735845312981950233075829729747631018349006817", "price": "0.92", "size": "1997.11", "side": "SELL", "hash": "5766b5a487c8c403dfa86188ce3cec2db90e69fa", "best_bid": "0.19", "best_ask": "0.35"}], "timestamp": "1769384850027", "event_type": "price_change"}}
{"_local_timestamp": "2026-01-25T23:47:30.310985+00:00", "data": {"market": "0xfaba55442a17a201a46f7ac19fd9394364f04959cdebfa420bc0c5ab2da00f59", "price_changes": [{"asset_id": "76829378806632943504106553503686063944439990588195206882350689917773385019771", "price": "0.08", "size": "2887.22", "side": "BUY", "hash": "63e201a515836c5a9e734baf301ac3c9337274b1", "best_bid": "0.65", "best_ask": "0.81"}, {"asset_id": "103206131584345534219777803662235735845312981950233075829729747631018349006817", "price": "0.92", "size": "2887.22", "side": "SELL", "hash": "834b55fcf1172ad5366f229ba693254adc268872", "best_bid": "0.19", "best_ask": "0.35"}], "timestamp": "1769384850028", "event_type": "price_change"}}
{"_local_timestamp": "2026-01-25T23:47:30.311953+00:00", "data": {"market": "0xfaba55442a17a201a46f7ac19fd9394364f04959cdebfa420bc0c5ab2da00f59", "price_changes": [{"asset_id": "76829378806632943504106553503686063944439990588195206882350689917773385019771", "price": "0.08", "size": "4157.32", "side": "BUY", "hash": "c54f573dfd4b49faab9784a566e610d680784089", "best_bid": "0.65", "best_ask": "0.81"}, {"asset_id": "103206131584345534219777803662235735845312981950233075829729747631018349006817", "price": "0.92", "size": "4157.32", "side": "SELL", "hash": "cb21c9591357af07544fd88896314437b0425501", "best_bid": "0.19", "best_ask": "0.35"}], "timestamp": "1769384850028", "event_type": "price_change"}}
{"_local_timestamp": "2026-01-25T23:47:30.461514+00:00", "data": {"market": "0xfaba55442a17a201a46f7ac19fd9394364f04959cdebfa420bc0c5ab2da00f59", "price_changes": [{"asset_id": "76829378806632943504106553503686063944439990588195206882350689917773385019771", "price": "0.12", "size": "4357.32", "side": "BUY", "hash": "fadf62412e72ade72f0aebd4fb52beb02d10a0b6", "best_bid": "0.65", "best_ask": "0.81"}, {"asset_id": "103206131584345534219777803662235735845312981950233075829729747631018349006817", "price": "0.88", "size": "4357.32", "side": "SELL", "hash": "365eff7187a1dc6c69ab860b3227ae70f84dc593", "best_bid": "0.19", "best_ask": "0.35"}], "timestamp": "1769384850222", "event_type": "price_change"}}
{"_local_timestamp": "2026-01-25T23:47:40.161642+00:00", "data": {"market": "0xfaba55442a17a201a46f7ac19fd9394364f04959cdebfa420bc0c5ab2da00f59", "price_changes": [{"asset_id": "76829378806632943504106553503686063944439990588195206882350689917773385019771", "price": "0.11", "size": "100", "side": "BUY", "hash": "c153f02acee48e0dcf132712ee6972ac040f57a6", "best_bid": "0.65", "best_ask": "0.81"}, {"asset_id": "103206131584345534219777803662235735845312981950233075829729747631018349006817", "price": "0.89", "size": "100", "side": "SELL", "hash": "21383e2295993b73792717ce10d6d11c294d7083", "best_bid": "0.19", "best_ask": "0.35"}], "timestamp": "1769384859928", "event_type": "price_change"}}
{"_local_timestamp": "2026-01-25T23:47:40.325364+00:00", "data": {"market": "0xfaba55442a17a201a46f7ac19fd9394364f04959cdebfa420bc0c5ab2da00f59", "price_changes": [{"asset_id": "76829378806632943504106553503686063944439990588195206882350689917773385019771", "price": "0.12", "size": "200", "side": "BUY", "hash": "1617068ec63779cfd2b14107c33b2847a9ec78b0", "best_bid": "0.65", "best_ask": "0.81"}, {"asset_id": "103206131584345534219777803662235735845312981950233075829729747631018349006817", "price": "0.88", "size": "200", "side": "SELL", "hash": "793abc77a689890d6cfc5b7e7bb3db74400fbdf0", "best_bid": "0.19", "best_ask": "0.35"}], "timestamp": "1769384860057", "event_type": "price_change"}}
{"_local_timestamp": "2026-01-25T23:47:40.446237+00:00", "data": {"market": "0xfaba55442a17a201a46f7ac19fd9394364f04959cdebfa420bc0c5ab2da00f59", "price_changes": [{"asset_id": "76829378806632943504106553503686063944439990588195206882350689917773385019771", "price": "0.12", "size": "600", "side": "BUY", "hash": "f279f674ed9280a2a6013f467d7295ebd31f00d9", "best_bid": "0.65", "best_ask": "0.81"}, {"asset_id": "103206131584345534219777803662235735845312981950233075829729747631018349006817", "price": "0.88", "size": "600", "side": "SELL", "hash": "40cba23d5358c60a3fd5b056e32a4e0f8d645cc2", "best_bid": "0.19", "best_ask": "0.35"}], "timestamp": "1769384860198", "event_type": "price_change"}}
{"_local_timestamp": "2026-01-25T23:47:40.538735+00:00", "data": {"market": "0xfaba55442a17a201a46f7ac19fd9394364f04959cdebfa420bc0c5ab2da00f59", "price_changes": [{"asset_id": "76829378806632943504106553503686063944439990588195206882350689917773385019771", "price": "0.13", "size": "890.11", "side": "BUY", "hash": "a2765ec2dfa6d3bc3817b56f1e213ea705348f0c", "best_bid": "0.65", "best_ask": "0.81"}, {"asset_id": "103206131584345534219777803662235735845312981950233075829729747631018349006817", "price": "0.87", "size": "890.11", "side": "SELL", "hash": "20e6b38d37aea6dbc8b6361453406d1a8901a242", "best_bid": "0.19", "best_ask": "0.35"}], "timestamp": "1769384860284", "event_type": "price_change"}}
{"_local_timestamp": "2026-01-25T23:47:40.539870+00:00", "data": {"market": "0xfaba55442a17a201a46f7ac19fd9394364f04959cdebfa420bc0c5ab2da00f59", "price_changes": [{"asset_id": "76829378806632943504106553503686063944439990588195206882350689917773385019771", "price": "0.13", "size": "2887.22", "side": "BUY", "hash": "63fc166fed51e6183a263739c1cbd6f42829959f", "best_bid": "0.65", "best_ask": "0.81"}, {"asset_id": "103206131584345534219777803662235735845312981950233075829729747631018349006817", "price": "0.87", "size": "2887.22", "side": "SELL", "hash": "995c34b5fd5e35a3c10b478ab984c0a080517862", "best_bid": "0.19", "best_ask": "0.35"}], "timestamp": "1769384860284", "event_type": "price_change"}}
{"_local_timestamp": "2026-01-25T23:47:40.545034+00:00", "data": {"market": "0xfaba55442a17a201a46f7ac19fd9394364f04959cdebfa420bc0c5ab2da00f59", "price_changes": [{"asset_id": "76829378806632943504106553503686063944439990588195206882350689917773385019771", "price": "0.13", "size": "4157.32", "side": "BUY", "hash": "33f84bcfa14ea298f8dc91d2f99e4fdc36383fcd", "best_bid": "0.65", "best_ask": "0.81"}, {"asset_id": "103206131584345534219777803662235735845312981950233075829729747631018349006817", "price": "0.87", "size": "4157.32", "side": "SELL", "hash": "66b8323c4026a32ce68a52887a644a6fb8b0b303", "best_bid": "0.19", "best_ask": "0.35"}], "timestamp": "1769384860285", "event_type": "price_change"}}
{"_local_timestamp": "2026-01-25T23:47:51.620083+00:00", "data": {"market": "0xfaba55442a17a201a46f7ac19fd9394364f04959cdebfa420bc0c5ab2da00f59", "price_changes": [{"asset_id": "76829378806632943504106553503686063944439990588195206882350689917773385019771", "price": "0.11", "size": "0", "side": "BUY", "hash": "fbcd74815b00618e2108096a853a170e4f69a1ab", "best_bid": "0.65", "best_ask": "0.81"}, {"asset_id": "103206131584345534219777803662235735845312981950233075829729747631018349006817", "price": "0.89", "size": "0", "side": "SELL", "hash": "fc1d6d8d948850460da6a984a2edcf7792a6e123", "best_bid": "0.19", "best_ask": "0.35"}], "timestamp": "1769384871541", "event_type": "price_change"}}
{"_local_timestamp": "2026-01-25T23:47:51.682387+00:00", "data": {"market": "0xfaba55442a17a201a46f7ac19fd9394364f04959cdebfa420bc0c5ab2da00f59", "price_changes": [{"asset_id": "76829378806632943504106553503686063944439990588195206882350689917773385019771", "price": "0.08", "size": "890.11", "side": "BUY", "hash": "fe87f49ebdb6ebc3ae0a91eeee08616783f5f264", "best_bid": "0.65", "best_ask": "0.81"}, {"asset_id": "103206131584345534219777803662235735845312981950233075829729747631018349006817", "price": "0.92", "size": "890.11", "side": "SELL", "hash": "e5d9187d28404e2b14ffef86e9b2219790a9f15f", "best_bid": "0.19", "best_ask": "0.35"}], "timestamp": "1769384871613", "event_type": "price_change"}}
{"_local_timestamp": "2026-01-25T23:47:51.788403+00:00", "data": {"market": "0xfaba55442a17a201a46f7ac19fd9394364f04959cdebfa420bc0c5ab2da00f59", "price_changes": [{"asset_id": "76829378806632943504106553503686063944439990588195206882350689917773385019771", "price": "0.08", "size": "0", "side": "BUY", "hash": "a5f0bf68d57b851e10124db75b2789986a6c235a", "best_bid": "0.65", "best_ask": "0.81"}, {"asset_id": "103206131584345534219777803662235735845312981950233075829729747631018349006817", "price": "0.92", "size": "0", "side": "SELL", "hash": "865a2eeb9659219337ae64a2e916fc3dc0a87456", "best_bid": "0.19", "best_ask": "0.35"}], "timestamp": "1769384871711", "event_type": "price_change"}}
{"_local_timestamp": "2026-01-25T23:47:51.904359+00:00", "data": {"market": "0xfaba55442a17a201a46f7ac19fd9394364f04959cdebfa420bc0c5ab2da00f59", "price_changes": [{"asset_id": "76829378806632943504106553503686063944439990588195206882350689917773385019771", "price": "0.12", "size": "700", "side": "BUY", "hash": "4bfed6cbe059f4c668b3dc1ede7a993b3cb4279e", "best_bid": "0.65", "best_ask": "0.81"}, {"asset_id": "103206131584345534219777803662235735845312981950233075829729747631018349006817", "price": "0.88", "size": "700", "side": "SELL", "hash": "d6baf6fd2c86a6937f183ef495e68790b5025182", "best_bid": "0.19", "best_ask": "0.35"}], "timestamp": "1769384871822", "event_type": "price_change"}}
{"_local_timestamp": "2026-01-25T23:48:00.642865+00:00", "data": {"market": "0xfaba55442a17a201a46f7ac19fd9394364f04959cdebfa420bc0c5ab2da00f59", "price_changes": [{"asset_id": "76829378806632943504106553503686063944439990588195206882350689917773385019771", "price": "0.12", "size": "300", "side": "BUY", "hash": "89244b5b0c9b844ac8843cba20651504ea61cdd5", "best_bid": "0.65", "best_ask": "0.81"}, {"asset_id": "103206131584345534219777803662235735845312981950233075829729747631018349006817", "price": "0.88", "size": "300", "side": "SELL", "hash": "a8f64e2b945340ea909bd4d5e646fce14dc1ed38", "best_bid": "0.19", "best_ask": "0.35"}], "timestamp": "1769384880575", "event_type": "price_change"}}
{"_local_timestamp": "2026-01-25T23:48:00.830817+00:00", "data": {"market": "0xfaba55442a17a201a46f7ac19fd9394364f04959cdebfa420bc0c5ab2da00f59", "price_changes": [{"asset_id": "76829378806632943504106553503686063944439990588195206882350689917773385019771", "price": "0.12", "size": "200", "side": "BUY", "hash": "84ab0f794d2376583693f0117399135529c3d657", "best_bid": "0.65", "best_ask": "0.81"}, {"asset_id": "103206131584345534219777803662235735845312981950233075829729747631018349006817", "price": "0.88", "size": "200", "side": "SELL", "hash": "43c00d871aa8574c8f4a1e692084cdf128375c2a", "best_bid": "0.19", "best_ask": "0.35"}], "timestamp": "1769384880757", "event_type": "price_change"}}
{"_local_timestamp": "2026-01-25T23:48:00.831930+00:00", "data": {"market": "0xfaba55442a17a201a46f7ac19fd9394364f04959cdebfa420bc0c5ab2da00f59", "price_changes": [{"asset_id": "76829378806632943504106553503686063944439990588195206882350689917773385019771", "price": "0.08", "size": "1270.1", "side": "BUY", "hash": "744ea74d6228a6136d0a56c82f572c48e1296699", "best_bid": "0.65", "best_ask": "0.81"}, {"asset_id": "103206131584345534219777803662235735845312981950233075829729747631018349006817", "price": "0.92", "size": "1270.1", "side": "SELL", "hash": "2d931e473e086a980d70af7f7e0548b2563765cf", "best_bid": "0.19", "best_ask": "0.35"}], "timestamp": "1769384880759", "event_type": "price_change"}}
{"_local_timestamp": "2026-01-25T23:48:00.834567+00:00", "data": {"market": "0xfaba55442a17a201a46f7ac19fd9394364f04959cdebfa420bc0c5ab2da00f59", "price_changes": [{"asset_id": "76829378806632943504106553503686063944439990588195206882350689917773385019771", "price": "0.08", "size": "3267.21", "side": "BUY", "hash": "e1c5dcb6dbcf132919ba281002168b3b843392e9", "best_bid": "0.65", "best_ask": "0.81"}, {"asset_id": "103206131584345534219777803662235735845312981950233075829729747631018349006817", "price": "0.92", "size": "3267.21", "side": "SELL", "hash": "b13c1c50336c60f88e583e358d03276f201437f3", "best_bid": "0.19", "best_ask": "0.35"}], "timestamp": "1769384880760", "event_type": "price_change"}}
{"_local_timestamp": "2026-01-25T23:48:00.863879+00:00", "data": {"market": "0xfaba55442a17a201a46f7ac19fd9394364f04959cdebfa420bc0c5ab2da00f59", "price_changes": [{"asset_id": "76829378806632943504106553503686063944439990588195206882350689917773385019771", "price": "0.08", "size": "4157.32", "side": "BUY", "hash": "35c8f08027ac026f42290151009b3ae48cb51ed9", "best_bid": "0.65", "best_ask": "0.81"}, {"asset_id": "103206131584345534219777803662235735845312981950233075829729747631018349006817", "price": "0.92", "size": "4157.32", "side": "SELL", "hash": "20358ddd91899be59fbf73b9d546e1c0d06838fa", "best_bid": "0.19", "best_ask": "0.35"}], "timestamp": "1769384880790", "event_type": "price_change"}}
{"_local_timestamp": "2026-01-25T23:48:00.918416+00:00", "data": {"market": "0xfaba55442a17a201a46f7ac19fd9394364f04959cdebfa420bc0c5ab2da00f59", "price_changes": [{"asset_id": "76829378806632943504106553503686063944439990588195206882350689917773385019771", "price": "0.13", "size": "4557.32", "side": "BUY", "hash": "e82034eb2eb35ea0e048224e284cf29b68417222", "best_bid": "0.65", "best_ask": "0.81"}, {"asset_id": "103206131584345534219777803662235735845312981950233075829729747631018349006817", "price": "0.87", "size": "4557.32", "side": "SELL", "hash": "b99f025bfc7e33cbef0ec8c5b6b960d0a2ff4542", "best_bid": "0.19", "best_ask": "0.35"}], "timestamp": "1769384880851", "event_type": "price_change"}}
{"_local_timestamp": "2026-01-25T23:48:01.134813+00:00", "data": {"market": "0xfaba55442a17a201a46f7ac19fd9394364f04959cdebfa420bc0c5ab2da00f59", "price_changes": [{"asset_id": "76829378806632943504106553503686063944439990588195206882350689917773385019771", "price": "0.13", "size": "4657.32", "side": "BUY", "hash": "9af7a0a612cc436d5de29459107a720db1e297f7", "best_bid": "0.65", "best_ask": "0.81"}, {"asset_id": "103206131584345534219777803662235735845312981950233075829729747631018349006817", "price": "0.87", "size": "4657.32", "side": "SELL", "hash": "d033f8da0a1ca03bc90d8e2a0db1c98221916119", "best_bid": "0.19", "best_ask": "0.35"}], "timestamp": "1769384881046", "event_type": "price_change"}}
{"_local_timestamp": "2026-01-25T23:48:19.885258+00:00", "data": {"market": "0xfaba55442a17a201a46f7ac19fd9394364f04959cdebfa420bc0c5ab2da00f59", "price_changes": [{"asset_id": "76829378806632943504106553503686063944439990588195206882350689917773385019771", "price": "0.12", "size": "100", "side": "BUY", "hash": "f778606e80ce1b5f5363a354d997cca2efbe6b00", "best_bid": "0.65", "best_ask": "0.81"}, {"asset_id": "103206131584345534219777803662235735845312981950233075829729747631018349006817", "price": "0.88", "size": "100", "side": "SELL", "hash": "a3276104e38312e1cd8a98d49689a8665b8be2a5", "best_bid": "0.19", "best_ask": "0.35"}], "timestamp": "1769384899811", "event_type": "price_change"}}
{"_local_timestamp": "2026-01-25T23:48:20.021633+00:00", "data": {"market": "0xfaba55442a17a201a46f7ac19fd9394364f04959cdebfa420bc0c5ab2da00f59", "price_changes": [{"asset_id": "76829378806632943504106553503686063944439990588195206882350689917773385019771", "price": "0.13", "size": "3767.21", "side": "BUY", "hash": "74ff0b5397667881c6275735b4217a216eea4074", "best_bid": "0.65", "best_ask": "0.81"}, {"asset_id": "103206131584345534219777803662235735845312981950233075829729747631018349006817", "price": "0.87", "size": "3767.21", "side": "SELL", "hash": "d7f8c2893225023268414ff7ee3a31e571036b96", "best_bid": "0.19", "best_ask": "0.35"}], "timestamp": "1769384899953", "event_type": "price_change"}}
{"_local_timestamp": "2026-01-25T23:48:20.146181+00:00", "data": {"market": "0xfaba55442a17a201a46f7ac19fd9394364f04959cdebfa420bc0c5ab2da00f59", "price_changes": [{"asset_id": "76829378806632943504106553503686063944439990588195206882350689917773385019771", "price": "0.13", "size": "500", "side": "BUY", "hash": "810b72725d5efe0a0ccb10d2b623780f3c7cff07", "best_bid": "0.65", "best_ask": "0.81"}, {"asset_id": "103206131584345534219777803662235735845312981950233075829729747631018349006817", "price": "0.87", "size": "500", "side": "SELL", "hash": "1b27093654f1298975c3ed297d10dde9b5e2b5dd", "best_bid": "0.19", "best_ask": "0.35"}], "timestamp": "1769384900036", "event_type": "price_change"}}
{"_local_timestamp": "2026-01-25T23:48:20.167748+00:00", "data": {"market": "0xfaba55442a17a201a46f7ac19fd9394364f04959cdebfa420bc0c5ab2da00f59", "price_changes": [{"asset_id": "76829378806632943504106553503686063944439990588195206882350689917773385019771", "price": "0.13", "size": "600", "side": "BUY", "hash": "b34ca81fa5d4c1e7fe5f9782e9ed0173fd20aab3", "best_bid": "0.65", "best_ask": "0.81"}, {"asset_id": "103206131584345534219777803662235735845312981950233075829729747631018349006817", "price": "0.87", "size": "600", "side": "SELL", "hash": "08aca4f83c052f20c5705e6382c982ac8a505296", "best_bid": "0.19", "best_ask": "0.35"}], "timestamp": "1769384900068", "event_type": "price_change"}}
{"_local_timestamp": "2026-01-25T23:48:20.241605+00:00", "data": {"market": "0xfaba55442a17a201a46f7ac19fd9394364f04959cdebfa420bc0c5ab2da00f59", "price_changes": [{"asset_id": "76829378806632943504106553503686063944439990588195206882350689917773385019771", "price": "0.14", "size": "1270.1", "side": "BUY", "hash": "3003279f1074f32d16049b7c271b49ea258a6188", "best_bid": "0.65", "best_ask": "0.81"}, {"asset_id": "103206131584345534219777803662235735845312981950233075829729747631018349006817", "price": "0.86", "size": "1270.1", "side": "SELL", "hash": "4e17e05286b123047c2be4547225b6e09af2bbb1", "best_bid": "0.19", "best_ask": "0.35"}], "timestamp": "1769384900163", "event_type": "price_change"}}
{"_local_timestamp": "2026-01-25T23:48:20.246727+00:00", "data": {"market": "0xfaba55442a17a201a46f7ac19fd9394364f04959cdebfa420bc0c5ab2da00f59", "price_changes": [{"asset_id": "76829378806632943504106553503686063944439990588195206882350689917773385019771", "price": "0.14", "size": "2160.21", "side": "BUY", "hash": "8b95662e1ed056f0f5b7aeef5e39899417b3dd26", "best_bid": "0.65", "best_ask": "0.81"}, {"asset_id": "103206131584345534219777803662235735845312981950233075829729747631018349006817", "price": "0.86", "size": "2160.21", "side": "SELL", "hash": "8861983d22a9679b1e2f353156ddf7ac5c8463b7", "best_bid": "0.19", "best_ask": "0.35"}], "timestamp": "1769384900163", "event_type": "price_change"}}
{"_local_timestamp": "2026-01-25T23:48:20.247820+00:00", "data": {"market": "0xfaba55442a17a201a46f7ac19fd9394364f04959cdebfa420bc0c5ab2da00f59", "price_changes": [{"asset_id": "76829378806632943504106553503686063944439990588195206882350689917773385019771", "price": "0.14", "size": "4157.32", "side": "BUY", "hash": "6337ea80a00a646dd94958c9e473c53c1bba1cd0", "best_bid": "0.65", "best_ask": "0.81"}, {"asset_id": "103206131584345534219777803662235735845312981950233075829729747631018349006817", "price": "0.86", "size": "4157.32", "side": "SELL", "hash": "b79f818643f0a6c48b76692b3633e0523ad9ac40", "best_bid": "0.19", "best_ask": "0.35"}], "timestamp": "1769384900164", "event_type": "price_change"}}
{"_local_timestamp": "2026-01-25T23:48:24.292562+00:00", "data": {"market": "0xfaba55442a17a201a46f7ac19fd9394364f04959cdebfa420bc0c5ab2da00f59", "price_changes": [{"asset_id": "76829378806632943504106553503686063944439990588195206882350689917773385019771", "price": "0.12", "size": "0", "side": "BUY", "hash": "3f8b90225e577812471ec79fa20d8106492a43e3", "best_bid": "0.65", "best_ask": "0.81"}, {"asset_id": "103206131584345534219777803662235735845312981950233075829729747631018349006817", "price": "0.88", "size": "0", "side": "SELL", "hash": "f0491d5f4ccd01c2ab039a3b895d9dea351ffb70", "best_bid": "0.19", "best_ask": "0.35"}], "timestamp": "1769384904221", "event_type": "price_change"}}
{"_local_timestamp": "2026-01-25T23:48:24.337785+00:00", "data": {"market": "0xfaba55442a17a201a46f7ac19fd9394364f04959cdebfa420bc0c5ab2da00f59", "price_changes": [{"asset_id": "76829378806632943504106553503686063944439990588195206882350689917773385019771", "price": "0.08", "size": "0", "side": "BUY", "hash": "b664ff30c07b81a2397a13002d117e4471cd93fc", "best_bid": "0.65", "best_ask": "0.81"}, {"asset_id": "103206131584345534219777803662235735845312981950233075829729747631018349006817", "price": "0.92", "size": "0", "side": "SELL", "hash": "daf06fdbd2348843eae7127de5cbcd4ebb09e2a8", "best_bid": "0.19", "best_ask": "0.35"}], "timestamp": "1769384904269", "event_type": "price_change"}}
{"_local_timestamp": "2026-01-25T23:48:24.622523+00:00", "data": {"market": "0xfaba55442a17a201a46f7ac19fd9394364f04959cdebfa420bc0c5ab2da00f59", "price_changes": [{"asset_id": "76829378806632943504106553503686063944439990588195206882350689917773385019771", "price": "0.13", "size": "700", "side": "BUY", "hash": "ec70aa7ba12454f7c9bea31281b05d9444352dc1", "best_bid": "0.65", "best_ask": "0.81"}, {"asset_id": "103206131584345534219777803662235735845312981950233075829729747631018349006817", "price": "0.87", "size": "700", "side": "SELL", "hash": "c701e07048760c7973a82cb5f81b12bfdbf6b37c", "best_bid": "0.19", "best_ask": "0.35"}], "timestamp": "1769384904544", "event_type": "price_change"}}
{"_local_timestamp": "2026-01-25T23:48:47.050189+00:00", "data": {"market": "0xfaba55442a17a201a46f7ac19fd9394364f04959cdebfa420bc0c5ab2da00f59", "price_changes": [{"asset_id": "76829378806632943504106553503686063944439990588195206882350689917773385019771", "price": "0.2", "size": "200", "side": "BUY", "hash": "fbe05be3b00c599eab028bfc3180d688c379676b", "best_bid": "0.65", "best_ask": "0.81"}, {"asset_id": "103206131584345534219777803662235735845312981950233075829729747631018349006817", "price": "0.8", "size": "200", "side": "SELL", "hash": "f6f54f575c58250ded084222a0b1215215ae74f4", "best_bid": "0.19", "best_ask": "0.35"}], "timestamp": "1769384926968", "event_type": "price_change"}}
{"_local_timestamp": "2026-01-25T23:48:47.393231+00:00", "data": {"market": "0xfaba55442a17a201a46f7ac19fd9394364f04959cdebfa420bc0c5ab2da00f59", "price_changes": [{"asset_id": "76829378806632943504106553503686063944439990588195206882350689917773385019771", "price": "0.14", "size": "4357.32", "side": "BUY", "hash": "ba736e7dcb8f349815a451f793773f4bea8e3f12", "best_bid": "0.65", "best_ask": "0.81"}, {"asset_id": "103206131584345534219777803662235735845312981950233075829729747631018349006817", "price": "0.86", "size": "4357.32", "side": "SELL", "hash": "369fde5df717d190fae548248ec77998097a55a3", "best_bid": "0.19", "best_ask": "0.35"}], "timestamp": "1769384927320", "event_type": "price_change"}}
{"_local_timestamp": "2026-01-25T23:48:50.703807+00:00", "data": {"market": "0xfaba55442a17a201a46f7ac19fd9394364f04959cdebfa420bc0c5ab2da00f59", "price_changes": [{"asset_id": "76829378806632943504106553503686063944439990588195206882350689917773385019771", "price": "0.13", "size": "600", "side": "BUY", "hash": "4a0eecb4e8002bdfa1e3ba81427823b257c34e4b", "best_bid": "0.65", "best_ask": "0.81"}, {"asset_id": "103206131584345534219777803662235735845312981950233075829729747631018349006817", "price": "0.87", "size": "600", "side": "SELL", "hash": "33ca3fda191f10cc17c954ac314dc57479ea0a13", "best_bid": "0.19", "best_ask": "0.35"}], "timestamp": "1769384930635", "event_type": "price_change"}}
{"_local_timestamp": "2026-01-25T23:48:50.969479+00:00", "data": {"market": "0xfaba55442a17a201a46f7ac19fd9394364f04959cdebfa420bc0c5ab2da00f59", "price_changes": [{"asset_id": "76829378806632943504106553503686063944439990588195206882350689917773385019771", "price": "0.14", "size": "4457.32", "side": "BUY", "hash": "c64bdf347e23ac330165bbfde408b875e29cad62", "best_bid": "0.65", "best_ask": "0.81"}, {"asset_id": "103206131584345534219777803662235735845312981950233075829729747631018349006817", "price": "0.86", "size": "4457.32", "side": "SELL", "hash": "11a9fdd8684520c82359464ea1b89bf23791b986", "best_bid": "0.19", "best_ask": "0.35"}], "timestamp": "1769384930898", "event_type": "price_change"}}
{"_local_timestamp": "2026-01-25T23:48:51.151737+00:00", "data": {"market": "0xfaba55442a17a201a46f7ac19fd9394364f04959cdebfa420bc0c5ab2da00f59", "price_changes": [{"asset_id": "76829378806632943504106553503686063944439990588195206882350689917773385019771", "price": "0.13", "size": "500", "side": "BUY", "hash": "05d111b619beb991d27c312117dcc9905460b7bd", "best_bid": "0.65", "best_ask": "0.81"}, {"asset_id": "103206131584345534219777803662235735845312981950233075829729747631018349006817", "price": "0.87", "size": "500", "side": "SELL", "hash": "8ba09ca1d5993d2bb568033eb3f402c077866b16", "best_bid": "0.19", "best_ask": "0.35"}], "timestamp": "1769384931041", "event_type": "price_change"}}
{"_local_timestamp": "2026-01-25T23:48:51.248791+00:00", "data": {"market": "0xfaba55442a17a201a46f7ac19fd9394364f04959cdebfa420bc0c5ab2da00f59", "price_changes": [{"asset_id": "76829378806632943504106553503686063944439990588195206882350689917773385019771", "price": "0.08", "size": "1270.1", "side": "BUY", "hash": "d590d2d8b0d6197a471d7e9fe20129ac09f720b2", "best_bid": "0.65", "best_ask": "0.81"}, {"asset_id": "103206131584345534219777803662235735845312981950233075829729747631018349006817", "price": "0.92", "size": "1270.1", "side": "SELL", "hash": "a6990211025915430ed0905b5f52ea49cf3bb2fa", "best_bid": "0.19", "best_ask": "0.35"}], "timestamp": "1769384931175", "event_type": "price_change"}}
{"_local_timestamp": "2026-01-25T23:48:51.249889+00:00", "data": {"market": "0xfaba55442a17a201a46f7ac19fd9394364f04959cdebfa420bc0c5ab2da00f59", "price_changes": [{"asset_id": "76829378806632943504106553503686063944439990588195206882350689917773385019771", "price": "0.08", "size": "3267.21", "side": "BUY", "hash": "80a02f5c366160fbbefbca08e6ef38d2b8065bfa", "best_bid": "0.65", "best_ask": "0.81"}, {"asset_id": "103206131584345534219777803662235735845312981950233075829729747631018349006817", "price": "0.92", "size": "3267.21", "side": "SELL", "hash": "1ba9fd1f1e21f681642bd2b0b9710fa72fbb1f9c", "best_bid": "0.19", "best_ask": "0.35"}], "timestamp": "1769384931176", "event_type": "price_change"}}
{"_local_timestamp": "2026-01-25T23:48:51.250859+00:00", "data": {"market": "0xfaba55442a17a201a46f7ac19fd9394364f04959cdebfa420bc0c5ab2da00f59", "price_changes": [{"asset_id": "76829378806632943504106553503686063944439990588195206882350689917773385019771", "price": "0.08", "size": "4157.32", "side": "BUY", "hash": "63843bbb423ec10311a7c947b56fe2b85d2fcdb2", "best_bid": "0.65", "best_ask": "0.81"}, {"asset_id": "103206131584345534219777803662235735845312981950233075829729747631018349006817", "price": "0.92", "size": "4157.32", "side": "SELL", "hash": "033d845bcf371c001a5806514937a6fad38345db", "best_bid": "0.19", "best_ask": "0.35"}], "timestamp": "1769384931176", "event_type": "price_change"}}
{"_local_timestamp": "2026-01-25T23:48:51.418076+00:00", "data": {"market": "0xfaba55442a17a201a46f7ac19fd9394364f04959cdebfa420bc0c5ab2da00f59", "price_changes": [{"asset_id": "76829378806632943504106553503686063944439990588195206882350689917773385019771", "price": "0.14", "size": "4557.32", "side": "BUY", "hash": "da4f4dd7d49fd1cdb8f06a190307f87d9b166992", "best_bid": "0.65", "best_ask": "0.81"}, {"asset_id": "103206131584345534219777803662235735845312981950233075829729747631018349006817", "price": "0.86", "size": "4557.32", "side": "SELL", "hash": "260701439d2b051ba93a297488f997f499f37951", "best_bid": "0.19", "best_ask": "0.35"}], "timestamp": "1769384931345", "event_type": "price_change"}}
{"_local_timestamp": "2026-01-25T23:49:04.666715+00:00", "data": {"market": "0xfaba55442a17a201a46f7ac19fd9394364f04959cdebfa420bc0c5ab2da00f59", "price_changes": [{"asset_id": "76829378806632943504106553503686063944439990588195206882350689917773385019771", "price": "0.13", "size": "400", "side": "BUY", "hash": "84bc03b3d6fa357567dab5ab739695f2ccff6106", "best_bid": "0.65", "best_ask": "0.81"}, {"asset_id": "103206131584345534219777803662235735845312981950233075829729747631018349006817", "price": "0.87", "size": "400", "side": "SELL", "hash": "67157425d4af136493f900091e0fb19298000b6c", "best_bid": "0.19", "best_ask": "0.35"}], "timestamp": "1769384944588", "event_type": "price_change"}}
{"_local_timestamp": "2026-01-25T23:49:04.788051+00:00", "data": {"market": "0xfaba55442a17a201a46f7ac19fd9394364f04959cdebfa420bc0c5ab2da00f59", "price_changes": [{"asset_id": "76829378806632943504106553503686063944439990588195206882350689917773385019771", "price": "0.14", "size": "400", "side": "BUY", "hash": "7dc5544b81bc399ac55f2243f7a04b0e8ca750c0", "best_bid": "0.65", "best_ask": "0.81"}, {"asset_id": "103206131584345534219777803662235735845312981950233075829729747631018349006817", "price": "0.86", "size": "400", "side": "SELL", "hash": "68b4069aae44055fa1c64573ce632a76bd8dd0c3", "best_bid": "0.19", "best_ask": "0.35"}], "timestamp": "1769384944708", "event_type": "price_change"}}
{"_local_timestamp": "2026-01-25T23:49:05.049041+00:00", "data": {"market": "0xfaba55442a17a201a46f7ac19fd9394364f04959cdebfa420bc0c5ab2da00f59", "price_changes": [{"asset_id": "76829378806632943504106553503686063944439990588195206882350689917773385019771", "price": "0.14", "size": "500", "side": "BUY", "hash": "73e16cbafe0db6c073057e23f0152cbd65d87406", "best_bid": "0.65", "best_ask": "0.81"}, {"asset_id": "103206131584345534219777803662235735845312981950233075829729747631018349006817", "price": "0.86", "size": "500", "side": "SELL", "hash": "999da66f8420c386a8f2c6b80f8398aecd13018d", "best_bid": "0.19", "best_ask": "0.35"}], "timestamp": "1769384944981", "event_type": "price_change"}}
{"_local_timestamp": "2026-01-25T23:49:10.879314+00:00", "data": {"market": "0xfaba55442a17a201a46f7ac19fd9394364f04959cdebfa420bc0c5ab2da00f59", "price_changes": [{"asset_id": "76829378806632943504106553503686063944439990588195206882350689917773385019771", "price": "0.13", "size": "0", "side": "BUY", "hash": "881f21a55e327c9a1a318bab8ea7016af0a66d23", "best_bid": "0.65", "best_ask": "0.81"}, {"asset_id": "103206131584345534219777803662235735845312981950233075829729747631018349006817", "price": "0.87", "size": "0", "side": "SELL", "hash": "66b9913b57f3a2ce46c69526f337c22c1dd552cf", "best_bid": "0.19", "best_ask": "0.35"}], "timestamp": "1769384950801", "event_type": "price_change"}}
{"_local_timestamp": "2026-01-25T23:49:11.182776+00:00", "data": {"market": "0xfaba55442a17a201a46f7ac19fd9394364f04959cdebfa420bc0c5ab2da00f59", "price_changes": [{"asset_id": "76829378806632943504106553503686063944439990588195206882350689917773385019771", "price": "0.08", "size": "4557.32", "side": "BUY", "hash": "98e02905756de0541a767d855567c817ac2cfcc7", "best_bid": "0.65", "best_ask": "0.81"}, {"asset_id": "103206131584345534219777803662235735845312981950233075829729747631018349006817", "price": "0.92", "size": "4557.32", "side": "SELL", "hash": "a79a4af31b85795feaa7b1cd244cdbc164612446", "best_bid": "0.19", "best_ask": "0.35"}], "timestamp": "1769384951089", "event_type": "price_change"}}
{"_local_timestamp": "2026-01-25T23:49:33.515116+00:00", "data": {"market": "0xfaba55442a17a201a46f7ac19fd9394364f04959cdebfa420bc0c5ab2da00f59", "price_changes": [{"asset_id": "76829378806632943504106553503686063944439990588195206882350689917773385019771", "price": "0.14", "size": "400", "side": "BUY", "hash": "6f099427c2bf0ebb4b6e9fa71379e03b7b97948a", "best_bid": "0.65", "best_ask": "0.81"}, {"asset_id": "103206131584345534219777803662235735845312981950233075829729747631018349006817", "price": "0.86", "size": "400", "side": "SELL", "hash": "fda16abd89b8910b1b4d1727ddf443914dc51f38", "best_bid": "0.19", "best_ask": "0.35"}], "timestamp": "1769384973439", "event_type": "price_change"}}
{"_local_timestamp": "2026-01-25T23:49:33.775950+00:00", "data": {"market": "0xfaba55442a17a201a46f7ac19fd9394364f04959cdebfa420bc0c5ab2da00f59", "price_changes": [{"asset_id": "76829378806632943504106553503686063944439990588195206882350689917773385019771", "price": "0.08", "size": "4657.32", "side": "BUY", "hash": "d49f0337e961ce4a4bb1b84ba47f4297580b3d7b", "best_bid": "0.65", "best_ask": "0.81"}, {"asset_id": "103206131584345534219777803662235735845312981950233075829729747631018349006817", "price": "0.92", "size": "4657.32", "side": "SELL", "hash": "256f1e3f318c2c15df5aa440fa4cd85c0a4be5c7", "best_bid": "0.19", "best_ask": "0.35"}], "timestamp": "1769384973708", "event_type": "price_change"}}
{"_local_timestamp": "2026-01-25T23:49:42.999418+00:00", "data": {"market": "0xfaba55442a17a201a46f7ac19fd9394364f04959cdebfa420bc0c5ab2da00f59", "price_changes": [{"asset_id": "76829378806632943504106553503686063944439990588195206882350689917773385019771", "price": "0.14", "size": "300", "side": "BUY", "hash": "dbf0eb6cc5b779cca36959222a9bf5794c1f1930", "best_bid": "0.65", "best_ask": "0.81"}, {"asset_id": "103206131584345534219777803662235735845312981950233075829729747631018349006817", "price": "0.86", "size": "300", "side": "SELL", "hash": "c115754ff53c67e9351f77d0c2e643b265257f1b", "best_bid": "0.19", "best_ask": "0.35"}], "timestamp": "1769384982920", "event_type": "price_change"}}
{"_local_timestamp": "2026-01-25T23:49:43.271261+00:00", "data": {"market": "0xfaba55442a17a201a46f7ac19fd9394364f04959cdebfa420bc0c5ab2da00f59", "price_changes": [{"asset_id": "76829378806632943504106553503686063944439990588195206882350689917773385019771", "price": "0.08", "size": "4757.32", "side": "BUY", "hash": "ad93cefbe6d554775a9d97cace4964ace51f6f51", "best_bid": "0.65", "best_ask": "0.81"}, {"asset_id": "103206131584345534219777803662235735845312981950233075829729747631018349006817", "price": "0.92", "size": "4757.32", "side": "SELL", "hash": "325016530d956830e16b742a0e4476d5cd88cd54", "best_bid": "0.19", "best_ask": "0.35"}], "timestamp": "1769384983189", "event_type": "price_change"}}
{"_local_timestamp": "2026-01-25T23:49:43.391728+00:00", "data": {"market": "0xfaba55442a17a201a46f7ac19fd9394364f04959cdebfa420bc0c5ab2da00f59", "price_changes": [{"asset_id": "76829378806632943504106553503686063944439990588195206882350689917773385019771", "price": "0.09", "size": "1270.1", "side": "BUY", "hash": "e5bffc8517db758cfc67e24c0ed764d3074a09cc", "best_bid": "0.65", "best_ask": "0.81"}, {"asset_id": "103206131584345534219777803662235735845312981950233075829729747631018349006817", "price": "0.91", "size": "1270.1", "side": "SELL", "hash": "eab1ea49e84fd11f01e9aa84a8b2b6c1e22cb7ec", "best_bid": "0.19", "best_ask": "0.35"}], "timestamp": "1769384983317", "event_type": "price_change"}}
{"_local_timestamp": "2026-01-25T23:49:43.624703+00:00", "data": {"market": "0xfaba55442a17a201a46f7ac19fd9394364f04959cdebfa420bc0c5ab2da00f59", "price_changes": [{"asset_id": "76829378806632943504106553503686063944439990588195206882350689917773385019771", "price": "0.09", "size": "2160.21", "side": "BUY", "hash": "a645b0a959130e4a6762ae6544ee7bace5afe871", "best_bid": "0.65", "best_ask": "0.81"}, {"asset_id": "103206131584345534219777803662235735845312981950233075829729747631018349006817", "price": "0.91", "size": "2160.21", "side": "SELL", "hash": "92d36ade7f4961434013801c18194990940a6ef6", "best_bid": "0.19", "best_ask": "0.35"}], "timestamp": "1769384983548", "event_type": "price_change"}}
{"_local_timestamp": "2026-01-25T23:49:43.626412+00:00", "data": {"market": "0xfaba55442a17a201a46f7ac19fd9394364f04959cdebfa420bc0c5ab2da00f59", "price_changes": [{"asset_id": "76829378806632943504106553503686063944439990588195206882350689917773385019771", "price": "0.09", "size": "4157.32", "side": "BUY", "hash": "3f3796136772db586e5afb9515223e5ca5a25e5a", "best_bid": "0.65", "best_ask": "0.81"}, {"asset_id": "103206131584345534219777803662235735845312981950233075829729747631018349006817", "price": "0.91", "size": "4157.32", "side": "SELL", "hash": "72253d85a067381c79768cb1e78335cbc1162ed0", "best_bid": "0.19", "best_ask": "0.35"}], "timestamp": "1769384983549", "event_type": "price_change"}}
{"_local_timestamp": "2026-01-25T23:49:52.722389+00:00", "data": {"market": "0xfaba55442a17a201a46f7ac19fd9394364f04959cdebfa420bc0c5ab2da00f59", "price_changes": [{"asset_id": "76829378806632943504106553503686063944439990588195206882350689917773385019771", "price": "0.14", "size": "100", "side": "BUY", "hash": "41da4544f91d41c663c7223c71b20722322eba62", "best_bid": "0.65", "best_ask": "0.81"}, {"asset_id": "103206131584345534219777803662235735845312981950233075829729747631018349006817", "price": "0.86", "size": "100", "side": "SELL", "hash": "b5a4761fb39785288ec2657c61612dd648ea6baa", "best_bid": "0.19", "best_ask": "0.35"}], "timestamp": "1769384992646", "event_type": "price_change"}}
{"_local_timestamp": "2026-01-25T23:49:52.839437+00:00", "data": {"market": "0xfaba55442a17a201a46f7ac19fd9394364f04959cdebfa420bc0c5ab2da00f59", "price_changes": [{"asset_id": "76829378806632943504106553503686063944439990588195206882350689917773385019771", "price": "0.08", "size": "600", "side": "BUY", "hash": "e593ab82f0cc265c63d7190db6c16f75fdf0ee98", "best_bid": "0.65", "best_ask": "0.81"}, {"asset_id": "103206131584345534219777803662235735845312981950233075829729747631018349006817", "price": "0.92", "size": "600", "side": "SELL", "hash": "cb0b7c329a5b24b622fabc2cfd5a0eb613571423", "best_bid": "0.19", "best_ask": "0.35"}], "timestamp": "1769384992763", "event_type": "price_change"}}
{"_local_timestamp": "2026-01-25T23:49:52.998162+00:00", "data": {"market": "0xfaba55442a17a201a46f7ac19fd9394364f04959cdebfa420bc0c5ab2da00f59", "price_changes": [{"asset_id": "76829378806632943504106553503686063944439990588195206882350689917773385019771", "price": "0.2", "size": "400", "side": "BUY", "hash": "b5d6d5fe245397d6a9666925c76c1224ef671fb8", "best_bid": "0.65", "best_ask": "0.81"}, {"asset_id": "103206131584345534219777803662235735845312981950233075829729747631018349006817", "price": "0.8", "size": "400", "side": "SELL", "hash": "b3111b2484b48bf4b02afa8773f6aba41248c7c4", "best_bid": "0.19", "best_ask": "0.35"}], "timestamp": "1769384992927", "event_type": "price_change"}}
{"_local_timestamp": "2026-01-25T23:49:57.309864+00:00", "data": {"market": "0xfaba55442a17a201a46f7ac19fd9394364f04959cdebfa420bc0c5ab2da00f59", "price_changes": [{"asset_id": "76829378806632943504106553503686063944439990588195206882350689917773385019771", "price": "0.14", "size": "0", "side": "BUY", "hash": "a4159ff4117a73b00820fc19b299c2859d19cd48", "best_bid": "0.65", "best_ask": "0.81"}, {"asset_id": "103206131584345534219777803662235735845312981950233075829729747631018349006817", "price": "0.86", "size": "0", "side": "SELL", "hash": "06784807b754f0d9b8bbe17f42cc68230f70323a", "best_bid": "0.19", "best_ask": "0.35"}], "timestamp": "1769384997232", "event_type": "price_change"}}
{"_local_timestamp": "2026-01-25T23:49:57.593569+00:00", "data": {"market": "0xfaba55442a17a201a46f7ac19fd9394364f04959cdebfa420bc0c5ab2da00f59", "price_changes": [{"asset_id": "76829378806632943504106553503686063944439990588195206882350689917773385019771", "price": "0.08", "size": "700", "side": "BUY", "hash": "3b4ce7948228a2d69373f4549d967c01b78fe1e0", "best_bid": "0.65", "best_ask": "0.81"}, {"asset_id": "103206131584345534219777803662235735845312981950233075829729747631018349006817", "price": "0.92", "size": "700", "side": "SELL", "hash": "fa7982125a7c52bea55d1e6c9f76b5698b288e59", "best_bid": "0.19", "best_ask": "0.35"}], "timestamp": "1769384997508", "event_type": "price_change"}}
{"_local_timestamp": "2026-01-25T23:50:05.872516+00:00", "data": {"market": "0xfaba55442a17a201a46f7ac19fd9394364f04959cdebfa420bc0c5ab2da00f59", "price_changes": [{"asset_id": "76829378806632943504106553503686063944439990588195206882350689917773385019771", "price": "0.08", "size": "600", "side": "BUY", "hash": "f917fad1f33c870e9593f8678d395458856ad6e8", "best_bid": "0.65", "best_ask": "0.81"}, {"asset_id": "103206131584345534219777803662235735845312981950233075829729747631018349006817", "price": "0.92", "size": "600", "side": "SELL", "hash": "6e4bb03637009c548ec8f37bac2f7603649352e2", "best_bid": "0.19", "best_ask": "0.35"}], "timestamp": "1769385005743", "event_type": "price_change"}}
{"_local_timestamp": "2026-01-25T23:50:06.264861+00:00", "data": {"market": "0xfaba55442a17a201a46f7ac19fd9394364f04959cdebfa420bc0c5ab2da00f59", "price_changes": [{"asset_id": "76829378806632943504106553503686063944439990588195206882350689917773385019771", "price": "0.09", "size": "4257.32", "side": "BUY", "hash": "1c88927297f75fd026e915630eae7bfb12ec6cbb", "best_bid": "0.65", "best_ask": "0.81"}, {"asset_id": "103206131584345534219777803662235735845312981950233075829729747631018349006817", "price": "0.91", "size": "4257.32", "side": "SELL", "hash": "2f113cfc15bce4dd8951a3f69d257205be88098c", "best_bid": "0.19", "best_ask": "0.35"}], "timestamp": "1769385006034", "event_type": "price_change"}}
{"_local_timestamp": "2026-01-25T23:50:06.367778+00:00", "data": {"market": "0x14a59fd43a48ef0bb90a5f63a6940fb6a62acf00f14710407cb340a6e555e427", "price_changes": [{"asset_id": "32309374624748192362666880759096858495442910952630564264751928146985382753863", "price": "0.01", "size": "180", "side": "BUY", "hash": "ec0470f1c92db87c17602a6815d0fd045185d8c4", "best_bid": "0.05", "best_ask": "0.96"}, {"asset_id": "33860025332294261066339194986447657969774333993404072754488955408971762620870", "price": "0.99", "size": "180", "side": "SELL", "hash": "084f90d3d57f69f1d0c81e62bf90452ebe2360a6", "best_bid": "0.04", "best_ask": "0.95"}], "timestamp": "1769385006177", "event_type": "price_change"}}
{"_local_timestamp": "2026-01-25T23:50:06.583655+00:00", "data": {"market": "0x14a59fd43a48ef0bb90a5f63a6940fb6a62acf00f14710407cb340a6e555e427", "price_changes": [{"asset_id": "32309374624748192362666880759096858495442910952630564264751928146985382753863", "price": "0.01", "size": "202.09", "side": "BUY", "hash": "78d2e8a0b6035823b1378f8ae8004b2ec8c332f0", "best_bid": "0.05", "best_ask": "0.96"}, {"asset_id": "33860025332294261066339194986447657969774333993404072754488955408971762620870", "price": "0.99", "size": "202.09", "side": "SELL", "hash": "2313af3bdb4b427e00110d75600dcd4735bbe127", "best_bid": "0.04", "best_ask": "0.95"}], "timestamp": "1769385006497", "event_type": "price_change"}}
{"_local_timestamp": "2026-01-25T23:50:08.521263+00:00", "data": {"market": "0xfaba55442a17a201a46f7ac19fd9394364f04959cdebfa420bc0c5ab2da00f59", "price_changes": [{"asset_id": "76829378806632943504106553503686063944439990588195206882350689917773385019771", "price": "0.08", "size": "500", "side": "BUY", "hash": "8c943d74219152c38c44e873c7767bcbae2fd064", "best_bid": "0.65", "best_ask": "0.81"}, {"asset_id": "103206131584345534219777803662235735845312981950233075829729747631018349006817", "price": "0.92", "size": "500", "side": "SELL", "hash": "64d7a38ed8d6bdde3f885c54debe29cc6d97d25d", "best_bid": "0.19", "best_ask": "0.35"}], "timestamp": "1769385008442", "event_type": "price_change"}}
{"_local_timestamp": "2026-01-25T23:50:08.581164+00:00", "data": {"market": "0xfaba55442a17a201a46f7ac19fd9394364f04959cdebfa420bc0c5ab2da00f59", "price_changes": [{"asset_id": "76829378806632943504106553503686063944439990588195206882350689917773385019771", "price": "0.08", "size": "1770.1", "side": "BUY", "hash": "3a3482253b833fdcdeb4ec1eca75997643e55e0b", "best_bid": "0.65", "best_ask": "0.81"}, {"asset_id": "103206131584345534219777803662235735845312981950233075829729747631018349006817", "price": "0.92", "size": "1770.1", "side": "SELL", "hash": "237ea48a47436a96b8558a315e05112d09df0929", "best_bid": "0.19", "best_ask": "0.35"}], "timestamp": "1769385008500", "event_type": "price_change"}}
{"_local_timestamp": "2026-01-25T23:50:08.582323+00:00", "data": {"market": "0xfaba55442a17a201a46f7ac19fd9394364f04959cdebfa420bc0c5ab2da00f59", "price_changes": [{"asset_id": "76829378806632943504106553503686063944439990588195206882350689917773385019771", "price": "0.08", "size": "3767.21", "side": "BUY", "hash": "289dcd7db744bf4c4356631c1725d6716d638c1e", "best_bid": "0.65", "best_ask": "0.81"}, {"asset_id": "103206131584345534219777803662235735845312981950233075829729747631018349006817", "price": "0.92", "size": "3767.21", "side": "SELL", "hash": "c2d5dd5a4454130826e00a01b666cfdbe2cadb60", "best_bid": "0.19", "best_ask": "0.35"}], "timestamp": "1769385008501", "event_type": "price_change"}}
{"_local_timestamp": "2026-01-25T23:50:08.624034+00:00", "data": {"market": "0xfaba55442a17a201a46f7ac19fd9394364f04959cdebfa420bc0c5ab2da00f59", "price_changes": [{"asset_id": "76829378806632943504106553503686063944439990588195206882350689917773385019771", "price": "0.08", "size": "4657.32", "side": "BUY", "hash": "6b6712b9ad4c145ebd23d1348d49c4eff82a0163", "best_bid": "0.65", "best_ask": "0.81"}, {"asset_id": "103206131584345534219777803662235735845312981950233075829729747631018349006817", "price": "0.92", "size": "4657.32", "side": "SELL", "hash": "7fb67b67e6979e62b9141181b0f9172003945e1b", "best_bid": "0.19", "best_ask": "0.35"}], "timestamp": "1769385008550", "event_type": "price_change"}}
{"_local_timestamp": "2026-01-25T23:50:08.848213+00:00", "data": {"market": "0xfaba55442a17a201a46f7ac19fd9394364f04959cdebfa420bc0c5ab2da00f59", "price_changes": [{"asset_id": "76829378806632943504106553503686063944439990588195206882350689917773385019771", "price": "0.09", "size": "4357.32", "side": "BUY", "hash": "85dfc108560fdc5782e215647102e0288eeba352", "best_bid": "0.65", "best_ask": "0.81"}, {"asset_id": "103206131584345534219777803662235735845312981950233075829729747631018349006817", "price": "0.91", "size": "4357.32", "side": "SELL", "hash": "06f097c4841332169588fdf5118741add4e98ff2", "best_bid": "0.19", "best_ask": "0.35"}], "timestamp": "1769385008766", "event_type": "price_change"}}
{"_local_timestamp": "2026-01-25T23:50:15.345768+00:00", "data": {"market": "0xfaba55442a17a201a46f7ac19fd9394364f04959cdebfa420bc0c5ab2da00f59", "price_changes": [{"asset_id": "76829378806632943504106553503686063944439990588195206882350689917773385019771", "price": "0.08", "size": "4257.32", "side": "BUY", "hash": "33cf017b554fa4e52b087bc98354a4607118f995", "best_bid": "0.65", "best_ask": "0.81"}, {"asset_id": "103206131584345534219777803662235735845312981950233075829729747631018349006817", "price": "0.92", "size": "4257.32", "side": "SELL", "hash": "9551c15633f2c71ee3e97e1d324d929ac63fba68", "best_bid": "0.19", "best_ask": "0.35"}], "timestamp": "1769385015274", "event_type": "price_change"}}
{"_local_timestamp": "2026-01-25T23:50:15.475900+00:00", "data": {"market": "0xfaba55442a17a201a46f7ac19fd9394364f04959cdebfa420bc0c5ab2da00f59", "price_changes": [{"asset_id": "76829378806632943504106553503686063944439990588195206882350689917773385019771", "price": "0.09", "size": "200", "side": "BUY", "hash": "680dc1cdf8c727448ad3f7c71fe49a80501c3297", "best_bid": "0.65", "best_ask": "0.81"}, {"asset_id": "103206131584345534219777803662235735845312981950233075829729747631018349006817", "price": "0.91", "size": "200", "side": "SELL", "hash": "a714155e52b1d74d213882d7613747625846b8f4", "best_bid": "0.19", "best_ask": "0.35"}], "timestamp": "1769385015392", "event_type": "price_change"}}
{"_local_timestamp": "2026-01-25T23:50:15.625073+00:00", "data": {"market": "0xfaba55442a17a201a46f7ac19fd9394364f04959cdebfa420bc0c5ab2da00f59", "price_changes": [{"asset_id": "76829378806632943504106553503686063944439990588195206882350689917773385019771", "price": "0.09", "size": "600", "side": "BUY", "hash": "4bd72acd9ba93b2f60c33c819f4f114f90bfafb3", "best_bid": "0.65", "best_ask": "0.81"}, {"asset_id": "103206131584345534219777803662235735845312981950233075829729747631018349006817", "price": "0.91", "size": "600", "side": "SELL", "hash": "334ddf2c3cb2f061041f55939eb3245b5143cd83", "best_bid": "0.19", "best_ask": "0.35"}], "timestamp": "1769385015549", "event_type": "price_change"}}
{"_local_timestamp": "2026-01-25T23:50:15.677193+00:00", "data": {"market": "0xfaba55442a17a201a46f7ac19fd9394364f04959cdebfa420bc0c5ab2da00f59", "price_changes": [{"asset_id": "76829378806632943504106553503686063944439990588195206882350689917773385019771", "price": "0.1", "size": "896.34", "side": "BUY", "hash": "531c1cc07af599d98a34c554b23399e1561107c3", "best_bid": "0.65", "best_ask": "0.81"}, {"asset_id": "103206131584345534219777803662235735845312981950233075829729747631018349006817", "price": "0.9", "size": "896.34", "side": "SELL", "hash": "ce4d7c9ec7f1e323fd338a917d83406309d525fe", "best_bid": "0.19", "best_ask": "0.35"}], "timestamp": "1769385015605", "event_type": "price_change"}}
{"_local_timestamp": "2026-01-25T23:50:15.685204+00:00", "data": {"market": "0xfaba55442a17a201a46f7ac19fd9394364f04959cdebfa420bc0c5ab2da00f59", "price_changes": [{"asset_id": "76829378806632943504106553503686063944439990588195206882350689917773385019771", "price": "0.1", "size": "2166.44", "side": "BUY", "hash": "4d2d5972ab010358d20127a5a642726c93630e35", "best_bid": "0.65", "best_ask": "0.81"}, {"asset_id": "103206131584345534219777803662235735845312981950233075829729747631018349006817", "price": "0.9", "size": "2166.44", "side": "SELL", "hash": "5d8b89040f5bb490d9fdcc14109c8764cb3a5d7f", "best_bid": "0.19", "best_ask": "0.35"}], "timestamp": "1769385015609", "event_type": "price_change"}}
{"_local_timestamp": "2026-01-25T23:50:15.686365+00:00", "data": {"market": "0xfaba55442a17a201a46f7ac19fd9394364f04959cdebfa420bc0c5ab2da00f59", "price_changes": [{"asset_id": "76829378806632943504106553503686063944439990588195206882350689917773385019771", "price": "0.1", "size": "4163.55", "side": "BUY", "hash": "0c455a1b481de5c50d7b6d5709d6b6a62bde347b", "best_bid": "0.65", "best_ask": "0.81"}, {"asset_id": "103206131584345534219777803662235735845312981950233075829729747631018349006817", "price": "0.9", "size": "4163.55", "side": "SELL", "hash": "3a86d93ba679ffa3528586ea602c692e7022357f", "best_bid": "0.19", "best_ask": "0.35"}], "timestamp": "1769385015612", "event_type": "price_change"}}
{"_local_timestamp": "2026-01-25T23:50:29.127643+00:00", "data": {"market": "0xfaba55442a17a201a46f7ac19fd9394364f04959cdebfa420bc0c5ab2da00f59", "price_changes": [{"asset_id": "76829378806632943504106553503686063944439990588195206882350689917773385019771", "price": "0.08", "size": "4157.32", "side": "BUY", "hash": "6a41a4e8d56cc548b14caf188846b7732cde9615", "best_bid": "0.65", "best_ask": "0.81"}, {"asset_id": "103206131584345534219777803662235735845312981950233075829729747631018349006817", "price": "0.92", "size": "4157.32", "side": "SELL", "hash": "7d19598334630f555e168f768c15d09e1fc0dc06", "best_bid": "0.19", "best_ask": "0.35"}], "timestamp": "1769385029026", "event_type": "price_change"}}
{"_local_timestamp": "2026-01-25T23:50:29.256146+00:00", "data": {"market": "0xfaba55442a17a201a46f7ac19fd9394364f04959cdebfa420bc0c5ab2da00f59", "price_changes": [{"asset_id": "76829378806632943504106553503686063944439990588195206882350689917773385019771", "price": "0.08", "size": "0", "side": "BUY", "hash": "2122365f9d112663dc96730fc7acee41aa61d450", "best_bid": "0.65", "best_ask": "0.81"}, {"asset_id": "103206131584345534219777803662235735845312981950233075829729747631018349006817", "price": "0.92", "size": "0", "side": "SELL", "hash": "ee3759f58c567995b83964346da0e7410457b88d", "best_bid": "0.19", "best_ask": "0.35"}], "timestamp": "1769385029174", "event_type": "price_change"}}
{"_local_timestamp": "2026-01-25T23:50:29.403847+00:00", "data": {"market": "0xfaba55442a17a201a46f7ac19fd9394364f04959cdebfa420bc0c5ab2da00f59", "price_changes": [{"asset_id": "76829378806632943504106553503686063944439990588195206882350689917773385019771", "price": "0.09", "size": "700", "side": "BUY", "hash": "22a74b5eae23f518efe1b36e8226ad5cf8b74a79", "best_bid": "0.65", "best_ask": "0.81"}, {"asset_id": "103206131584345534219777803662235735845312981950233075829729747631018349006817", "price": "0.91", "size": "700", "side": "SELL", "hash": "fc422c7fe4742887e9e4c15bf6342b9bf613debb", "best_bid": "0.19", "best_ask": "0.35"}], "timestamp": "1769385029317", "event_type": "price_change"}}
{"_local_timestamp": "2026-01-25T23:50:37.553626+00:00", "data": {"market": "0xfaba55442a17a201a46f7ac19fd9394364f04959cdebfa420bc0c5ab2da00f59", "price_changes": [{"asset_id": "76829378806632943504106553503686063944439990588195206882350689917773385019771", "price": "0.09", "size": "600", "side": "BUY", "hash": "26a0b00cc66ebbfc54f27f3c73235b5f44088fdc", "best_bid": "0.65", "best_ask": "0.81"}, {"asset_id": "103206131584345534219777803662235735845312981950233075829729747631018349006817", "price": "0.91", "size": "600", "side": "SELL", "hash": "70b6032ee1b671a41669a6a2426fb6f59abb79c6", "best_bid": "0.19", "best_ask": "0.35"}], "timestamp": "1769385037478", "event_type": "price_change"}}
{"_local_timestamp": "2026-01-25T23:50:37.826926+00:00", "data": {"market": "0xfaba55442a17a201a46f7ac19fd9394364f04959cdebfa420bc0c5ab2da00f59", "price_changes": [{"asset_id": "76829378806632943504106553503686063944439990588195206882350689917773385019771", "price": "0.1", "size": "4263.55", "side": "BUY", "hash": "ce05ecb3b770d07138d0df4be52af65b3254fefb", "best_bid": "0.65", "best_ask": "0.81"}, {"asset_id": "103206131584345534219777803662235735845312981950233075829729747631018349006817", "price": "0.9", "size": "4263.55", "side": "SELL", "hash": "41f3f1533df2100ad6d7362719384ce0e8a38741", "best_bid": "0.19", "best_ask": "0.35"}], "timestamp": "1769385037754", "event_type": "price_change"}}
{"_local_timestamp": "2026-01-25T23:50:38.685542+00:00", "data": {"market": "0xfaba55442a17a201a46f7ac19fd9394364f04959cdebfa420bc0c5ab2da00f59", "price_changes": [{"asset_id": "76829378806632943504106553503686063944439990588195206882350689917773385019771", "price": "0.09", "size": "200", "side": "BUY", "hash": "09be76c1e67aaa261b5ac7aa7a9596a12d99b9d5", "best_bid": "0.65", "best_ask": "0.81"}, {"asset_id": "103206131584345534219777803662235735845312981950233075829729747631018349006817", "price": "0.91", "size": "200", "side": "SELL", "hash": "ac81c59259cf7c33a83eb38ef37aea4879a92529", "best_bid": "0.19", "best_ask": "0.35"}], "timestamp": "1769385038608", "event_type": "price_change"}}
{"_local_timestamp": "2026-01-25T23:50:38.743612+00:00", "data": {"market": "0xfaba55442a17a201a46f7ac19fd9394364f04959cdebfa420bc0c5ab2da00f59", "price_changes": [{"asset_id": "76829378806632943504106553503686063944439990588195206882350689917773385019771", "price": "0.08", "size": "890.11", "side": "BUY", "hash": "62243581ebceb05425a4465b8c8acdcc721abdbc", "best_bid": "0.65", "best_ask": "0.81"}, {"asset_id": "103206131584345534219777803662235735845312981950233075829729747631018349006817", "price": "0.92", "size": "890.11", "side": "SELL", "hash": "42c5c0babddfbe4a0fadaaf904f22c3bc4ca182f", "best_bid": "0.19", "best_ask": "0.35"}], "timestamp": "1769385038667", "event_type": "price_change"}}
{"_local_timestamp": "2026-01-25T23:50:38.744969+00:00", "data": {"market": "0xfaba55442a17a201a46f7ac19fd9394364f04959cdebfa420bc0c5ab2da00f59", "price_changes": [{"asset_id": "76829378806632943504106553503686063944439990588195206882350689917773385019771", "price": "0.08", "size": "2160.21", "side": "BUY", "hash": "9edbaf3c1bfb620399d1a4b16f6a942579097715", "best_bid": "0.65", "best_ask": "0.81"}, {"asset_id": "103206131584345534219777803662235735845312981950233075829729747631018349006817", "price": "0.92", "size": "2160.21", "side": "SELL", "hash": "fcd77c0b8f103cd266bf433f8ba3aaa8689ef288", "best_bid": "0.19", "best_ask": "0.35"}], "timestamp": "1769385038668", "event_type": "price_change"}}
{"_local_timestamp": "2026-01-25T23:50:38.776259+00:00", "data": {"market": "0xfaba55442a17a201a46f7ac19fd9394364f04959cdebfa420bc0c5ab2da00f59", "price_changes": [{"asset_id": "76829378806632943504106553503686063944439990588195206882350689917773385019771", "price": "0.08", "size": "4157.32", "side": "BUY", "hash": "7bf76db999f8458a6eb9ce2bde47b73d64f3ce53", "best_bid": "0.65", "best_ask": "0.81"}, {"asset_id": "103206131584345534219777803662235735845312981950233075829729747631018349006817", "price": "0.92", "size": "4157.32", "side": "SELL", "hash": "3283d3d04a1dbba3e7f9afee8ce44dc69f82e952", "best_bid": "0.19", "best_ask": "0.35"}], "timestamp": "1769385038704", "event_type": "price_change"}}
{"_local_timestamp": "2026-01-25T23:50:39.022441+00:00", "data": {"market": "0xfaba55442a17a201a46f7ac19fd9394364f04959cdebfa420bc0c5ab2da00f59", "price_changes": [{"asset_id": "76829378806632943504106553503686063944439990588195206882350689917773385019771", "price": "0.1", "size": "4663.55", "side": "BUY", "hash": "8463aa5629ad723758015004fe08b0bf0409f877", "best_bid": "0.65", "best_ask": "0.81"}, {"asset_id": "103206131584345534219777803662235735845312981950233075829729747631018349006817", "price": "0.9", "size": "4663.55", "side": "SELL", "hash": "6cf4f8dcb47068e54e514caaf5bfcf9d62ba189c", "best_bid": "0.19", "best_ask": "0.35"}], "timestamp": "1769385038933", "event_type": "price_change"}}
{"_local_timestamp": "2026-01-25T23:50:59.471542+00:00", "data": {"market": "0xfaba55442a17a201a46f7ac19fd9394364f04959cdebfa420bc0c5ab2da00f59", "price_changes": [{"asset_id": "76829378806632943504106553503686063944439990588195206882350689917773385019771", "price": "0.09", "size": "100", "side": "BUY", "hash": "717a81f65b9da18f7b0b5630de5e71ad451b4eed", "best_bid": "0.65", "best_ask": "0.81"}, {"asset_id": "103206131584345534219777803662235735845312981950233075829729747631018349006817", "price": "0.91", "size": "100", "side": "SELL", "hash": "dcf277fd873ac019434663418af9e8256f3eea21", "best_bid": "0.19", "best_ask": "0.35"}], "timestamp": "1769385059393", "event_type": "price_change"}}
{"_local_timestamp": "2026-01-25T23:50:59.614641+00:00", "data": {"market": "0xfaba55442a17a201a46f7ac19fd9394364f04959cdebfa420bc0c5ab2da00f59", "price_changes": [{"asset_id": "76829378806632943504106553503686063944439990588195206882350689917773385019771", "price": "0.1", "size": "506.23", "side": "BUY", "hash": "6a217f499d6013a22f1b2b7cc2501148c7a7f6c7", "best_bid": "0.65", "best_ask": "0.81"}, {"asset_id": "103206131584345534219777803662235735845312981950233075829729747631018349006817", "price": "0.9", "size": "506.23", "side": "SELL", "hash": "13fb36fb6f30f4a097e40d5a82b8f50190521a18", "best_bid": "0.19", "best_ask": "0.35"}], "timestamp": "1769385059539", "event_type": "price_change"}}
{"_local_timestamp": "2026-01-25T23:50:59.739314+00:00", "data": {"market": "0xfaba55442a17a201a46f7ac19fd9394364f04959cdebfa420bc0c5ab2da00f59", "price_changes": [{"asset_id": "76829378806632943504106553503686063944439990588195206882350689917773385019771", "price": "0.1", "size": "606.23", "side": "BUY", "hash": "c8c0715bba9efe46e63b4edebd34cf95d95a2bf9", "best_bid": "0.65", "best_ask": "0.81"}, {"asset_id": "103206131584345534219777803662235735845312981950233075829729747631018349006817", "price": "0.9", "size": "606.23", "side": "SELL", "hash": "57e6595c2af6fc5616559b17588dffd6d4e05164", "best_bid": "0.19", "best_ask": "0.35"}], "timestamp": "1769385059671", "event_type": "price_change"}}
{"_local_timestamp": "2026-01-25T23:50:59.796199+00:00", "data": {"market": "0xfaba55442a17a201a46f7ac19fd9394364f04959cdebfa420bc0c5ab2da00f59", "price_changes": [{"asset_id": "76829378806632943504106553503686063944439990588195206882350689917773385019771", "price": "0.11", "size": "890.11", "side": "BUY", "hash": "640d2c9d1da49d61502080e544cc282ab01be4c9", "best_bid": "0.65", "best_ask": "0.81"}, {"asset_id": "103206131584345534219777803662235735845312981950233075829729747631018349006817", "price": "0.89", "size": "890.11", "side": "SELL", "hash": "003971894f9fe90838f8cfee23bdf978a448eb6a", "best_bid": "0.19", "best_ask": "0.35"}], "timestamp": "1769385059722", "event_type": "price_change"}}
{"_local_timestamp": "2026-01-25T23:50:59.797351+00:00", "data": {"market": "0xfaba55442a17a201a46f7ac19fd9394364f04959cdebfa420bc0c5ab2da00f59", "price_changes": [{"asset_id": "76829378806632943504106553503686063944439990588195206882350689917773385019771", "price": "0.11", "size": "2887.22", "side": "BUY", "hash": "8d5df4dfb7c2a380fd0a79d1c52329ae05cfbe60", "best_bid": "0.65", "best_ask": "0.81"}, {"asset_id": "103206131584345534219777803662235735845312981950233075829729747631018349006817", "price": "0.89", "size": "2887.22", "side": "SELL", "hash": "5e19878c4d6091d00650a83b579825a382d275b8", "best_bid": "0.19", "best_ask": "0.35"}], "timestamp": "1769385059724", "event_type": "price_change"}}
{"_local_timestamp": "2026-01-25T23:50:59.798413+00:00", "data": {"market": "0xfaba55442a17a201a46f7ac19fd9394364f04959cdebfa420bc0c5ab2da00f59", "price_changes": [{"asset_id": "76829378806632943504106553503686063944439990588195206882350689917773385019771", "price": "0.11", "size": "4157.32", "side": "BUY", "hash": "50996453a3bc6c3cd31ccadd1873625b71301991", "best_bid": "0.65", "best_ask": "0.81"}, {"asset_id": "103206131584345534219777803662235735845312981950233075829729747631018349006817", "price": "0.89", "size": "4157.32", "side": "SELL", "hash": "fad89c903738e179777848e6bd93e7770a313e67", "best_bid": "0.19", "best_ask": "0.35"}], "timestamp": "1769385059726", "event_type": "price_change"}}
{"_local_timestamp": "2026-01-25T23:51:03.170754+00:00", "data": {"market": "0xfaba55442a17a201a46f7ac19fd9394364f04959cdebfa420bc0c5ab2da00f59", "price_changes": [{"asset_id": "76829378806632943504106553503686063944439990588195206882350689917773385019771", "price": "0.09", "size": "0", "side": "BUY", "hash": "abcfa7508b13c3e87356bcfe82ac64f3212c55a7", "best_bid": "0.65", "best_ask": "0.81"}, {"asset_id": "103206131584345534219777803662235735845312981950233075829729747631018349006817", "price": "0.91", "size": "0", "side": "SELL", "hash": "de659828dc2e7c07e1f1942c103af9c9312a11e1", "best_bid": "0.19", "best_ask": "0.35"}], "timestamp": "1769385063073", "event_type": "price_change"}}
{"_local_timestamp": "2026-01-25T23:51:03.290258+00:00", "data": {"market": "0xfaba55442a17a201a46f7ac19fd9394364f04959cdebfa420bc0c5ab2da00f59", "price_changes": [{"asset_id": "76829378806632943504106553503686063944439990588195206882350689917773385019771", "price": "0.08", "size": "0", "side": "BUY", "hash": "725ffbfa89058549f6a20c745612f30b58eae5b8", "best_bid": "0.65", "best_ask": "0.81"}, {"asset_id": "103206131584345534219777803662235735845312981950233075829729747631018349006817", "price": "0.92", "size": "0", "side": "SELL", "hash": "83bde3481230fba564c86795a14e4d40fbc76ee5", "best_bid": "0.19", "best_ask": "0.35"}], "timestamp": "1769385063214", "event_type": "price_change"}}
{"_local_timestamp": "2026-01-25T23:51:03.416097+00:00", "data": {"market": "0xfaba55442a17a201a46f7ac19fd9394364f04959cdebfa420bc0c5ab2da00f59", "price_changes": [{"asset_id": "76829378806632943504106553503686063944439990588195206882350689917773385019771", "price": "0.1", "size": "706.23", "side": "BUY", "hash": "62b7ce5378b5f486a5e9cc5c926cbc67d70fd638", "best_bid": "0.65", "best_ask": "0.81"}, {"asset_id": "103206131584345534219777803662235735845312981950233075829729747631018349006817", "price": "0.9", "size": "706.23", "side": "SELL", "hash": "ed77c829eff411d82c20c0cc198150111cb68176", "best_bid": "0.19", "best_ask": "0.35"}], "timestamp": "1769385063336", "event_type": "price_change"}}
{"_local_timestamp": "2026-01-25T23:51:21.406501+00:00", "data": {"market": "0xfaba55442a17a201a46f7ac19fd9394364f04959cdebfa420bc0c5ab2da00f59", "price_changes": [{"asset_id": "76829378806632943504106553503686063944439990588195206882350689917773385019771", "price": "0.1", "size": "306.23", "side": "BUY", "hash": "ef4b2cb4d114e44122def71b5ada9622c7ddf106", "best_bid": "0.65", "best_ask": "0.81"}, {"asset_id": "103206131584345534219777803662235735845312981950233075829729747631018349006817", "price": "0.9", "size": "306.23", "side": "SELL", "hash": "253eb224e2068c63e0770b8616d880e77ce96468", "best_bid": "0.19", "best_ask": "0.35"}], "timestamp": "1769385081338", "event_type": "price_change"}}
{"_local_timestamp": "2026-01-25T23:51:21.655729+00:00", "data": {"market": "0xfaba55442a17a201a46f7ac19fd9394364f04959cdebfa420bc0c5ab2da00f59", "price_changes": [{"asset_id": "76829378806632943504106553503686063944439990588195206882350689917773385019771", "price": "0.08", "size": "890.11", "side": "BUY", "hash": "3eef91000d05a47142b3508a0e741d316c7afeb5", "best_bid": "0.65", "best_ask": "0.81"}, {"asset_id": "103206131584345534219777803662235735845312981950233075829729747631018349006817", "price": "0.92", "size": "890.11", "side": "SELL", "hash": "0584d08d7b7e930fa0d54232670b5c23c90b24eb", "best_bid": "0.19", "best_ask": "0.35"}], "timestamp": "1769385081586", "event_type": "price_change"}}
{"_local_timestamp": "2026-01-25T23:51:21.657050+00:00", "data": {"market": "0xfaba55442a17a201a46f7ac19fd9394364f04959cdebfa420bc0c5ab2da00f59", "price_changes": [{"asset_id": "76829378806632943504106553503686063944439990588195206882350689917773385019771", "price": "0.08", "size": "2160.21", "side": "BUY", "hash": "45e6d370e3d2ee29fc3600f4de20a5bf28bc239a", "best_bid": "0.65", "best_ask": "0.81"}, {"asset_id": "103206131584345534219777803662235735845312981950233075829729747631018349006817", "price": "0.92", "size": "2160.21", "side": "SELL", "hash": "bf0b86474c74fcd03665e9aee5e614e55a843d0f", "best_bid": "0.19", "best_ask": "0.35"}], "timestamp": "1769385081587", "event_type": "price_change"}}
{"_local_timestamp": "2026-01-25T23:51:21.693026+00:00", "data": {"market": "0xfaba55442a17a201a46f7ac19fd9394364f04959cdebfa420bc0c5ab2da00f59", "price_changes": [{"asset_id": "76829378806632943504106553503686063944439990588195206882350689917773385019771", "price": "0.11", "size": "4557.32", "side": "BUY", "hash": "45cd2372f8678f050564c518d1f5ab472bb74dda", "best_bid": "0.65", "best_ask": "0.81"}, {"asset_id": "103206131584345534219777803662235735845312981950233075829729747631018349006817", "price": "0.89", "size": "4557.32", "side": "SELL", "hash": "655a993503a213de9dc5bdab3e2cacf7a45ac2a5", "best_bid": "0.19", "best_ask": "0.35"}], "timestamp": "1769385081621", "event_type": "price_change"}}
{"_local_timestamp": "2026-01-25T23:51:21.895339+00:00", "data": {"market": "0xfaba55442a17a201a46f7ac19fd9394364f04959cdebfa420bc0c5ab2da00f59", "price_changes": [{"asset_id": "76829378806632943504106553503686063944439990588195206882350689917773385019771", "price": "0.08", "size": "4157.32", "side": "BUY", "hash": "e606da32d139a47e43eacedebb12b1cfcaec9d04", "best_bid": "0.65", "best_ask": "0.81"}, {"asset_id": "103206131584345534219777803662235735845312981950233075829729747631018349006817", "price": "0.92", "size": "4157.32", "side": "SELL", "hash": "a96e8d62910a663dad742ac534d63425c35f74c1", "best_bid": "0.19", "best_ask": "0.35"}], "timestamp": "1769385081818", "event_type": "price_change"}}
{"_local_timestamp": "2026-01-25T23:51:25.278594+00:00", "data": {"market": "0xfaba55442a17a201a46f7ac19fd9394364f04959cdebfa420bc0c5ab2da00f59", "price_changes": [{"asset_id": "76829378806632943504106553503686063944439990588195206882350689917773385019771", "price": "0.1", "size": "206.23", "side": "BUY", "hash": "2f4a8df35053954663c497a18964a43c863bc9ec", "best_bid": "0.65", "best_ask": "0.81"}, {"asset_id": "103206131584345534219777803662235735845312981950233075829729747631018349006817", "price": "0.9", "size": "206.23", "side": "SELL", "hash": "137fe94b0260604588a96d48e1e10b99682e2f6a", "best_bid": "0.19", "best_ask": "0.35"}], "timestamp": "1769385085210", "event_type": "price_change"}}
{"_local_timestamp": "2026-01-25T23:51:25.365204+00:00", "data": {"market": "0xfaba55442a17a201a46f7ac19fd9394364f04959cdebfa420bc0c5ab2da00f59", "price_changes": [{"asset_id": "76829378806632943504106553503686063944439990588195206882350689917773385019771", "price": "0.11", "size": "1670.1", "side": "BUY", "hash": "d575c3e5cd66d5008e2750cdc28e9afdf4284a9c", "best_bid": "0.65", "best_ask": "0.81"}, {"asset_id": "103206131584345534219777803662235735845312981950233075829729747631018349006817", "price": "0.89", "size": "1670.1", "side": "SELL", "hash": "bc0c008be29a8f989074e0a3ede07c800f9ad379", "best_bid": "0.19", "best_ask": "0.35"}], "timestamp": "1769385085292", "event_type": "price_change"}}
{"_local_timestamp": "2026-01-25T23:51:25.474702+00:00", "data": {"market": "0xfaba55442a17a201a46f7ac19fd9394364f04959cdebfa420bc0c5ab2da00f59", "price_changes": [{"asset_id": "76829378806632943504106553503686063944439990588195206882350689917773385019771", "price": "0.11", "size": "400", "side": "BUY", "hash": "ae9b5bb09cc55f7089d53c91043c69bf447c60a5", "best_bid": "0.65", "best_ask": "0.81"}, {"asset_id": "103206131584345534219777803662235735845312981950233075829729747631018349006817", "price": "0.89", "size": "400", "side": "SELL", "hash": "5356706241324cd10167a2f81dacaecf8c0c5f6a", "best_bid": "0.19", "best_ask": "0.35"}], "timestamp": "1769385085402", "event_type": "price_change"}}
{"_local_timestamp": "2026-01-25T23:51:25.520886+00:00", "data": {"market": "0xfaba55442a17a201a46f7ac19fd9394364f04959cdebfa420bc0c5ab2da00f59", "price_changes": [{"asset_id": "76829378806632943504106553503686063944439990588195206882350689917773385019771", "price": "0.12", "size": "1997.11", "side": "BUY", "hash": "9160230757be0498cdf6520e300c25425c938673", "best_bid": "0.65", "best_ask": "0.81"}, {"asset_id": "103206131584345534219777803662235735845312981950233075829729747631018349006817", "price": "0.88", "size": "1997.11", "side": "SELL", "hash": "988ff793a3ad0b256144a16b82bfd6bf1c8c030c", "best_bid": "0.19", "best_ask": "0.35"}], "timestamp": "1769385085449", "event_type": "price_change"}}
{"_local_timestamp": "2026-01-25T23:51:25.523852+00:00", "data": {"market": "0xfaba55442a17a201a46f7ac19fd9394364f04959cdebfa420bc0c5ab2da00f59", "price_changes": [{"asset_id": "76829378806632943504106553503686063944439990588195206882350689917773385019771", "price": "0.12", "size": "2887.22", "side": "BUY", "hash": "09e9565a2ed88e5fe3d3b45e5c582ed9d4208f3c", "best_bid": "0.65", "best_ask": "0.81"}, {"asset_id": "103206131584345534219777803662235735845312981950233075829729747631018349006817", "price": "0.88", "size": "2887.22", "side": "SELL", "hash": "3bde90ac33a7685886c9ce8b668a0d72215ea9c4", "best_bid": "0.19", "best_ask": "0.35"}], "timestamp": "1769385085450", "event_type": "price_change"}}
{"_local_timestamp": "2026-01-25T23:51:25.562670+00:00", "data": {"market": "0xfaba55442a17a201a46f7ac19fd9394364f04959cdebfa420bc0c5ab2da00f59", "price_changes": [{"asset_id": "76829378806632943504106553503686063944439990588195206882350689917773385019771", "price": "0.12", "size": "4157.32", "side": "BUY", "hash": "131d8159c70eab19ac7fa2fdb8a81fa6f6e43d15", "best_bid": "0.65", "best_ask": "0.81"}, {"asset_id": "103206131584345534219777803662235735845312981950233075829729747631018349006817", "price": "0.88", "size": "4157.32", "side": "SELL", "hash": "3f1821b088887b0beb9cd313a12452792462f46f", "best_bid": "0.19", "best_ask": "0.35"}], "timestamp": "1769385085487", "event_type": "price_change"}}
{"_local_timestamp": "2026-01-25T23:51:25.579385+00:00", "data": {"market": "0xfaba55442a17a201a46f7ac19fd9394364f04959cdebfa420bc0c5ab2da00f59", "price_changes": [{"asset_id": "76829378806632943504106553503686063944439990588195206882350689917773385019771", "price": "0.11", "size": "500", "side": "BUY", "hash": "e10aaad2bb7a95d67d49ebb676cfbc685e673e47", "best_bid": "0.65", "best_ask": "0.81"}, {"asset_id": "103206131584345534219777803662235735845312981950233075829729747631018349006817", "price": "0.89", "size": "500", "side": "SELL", "hash": "703db13f9ea99e0eaced4879ba259df06f95eb8f", "best_bid": "0.19", "best_ask": "0.35"}], "timestamp": "1769385085508", "event_type": "price_change"}}
