{"_local_timestamp": "2026-01-25T23:41:24.157166+00:00", "data": [{"market": "0xc3c68d15795f49737337750652613725b6b26f7220ce14c0b84a285dcf805e0e", "asset_id": "65603819657652394397234334780908142331249225026323215164617873273051642905321", "timestamp": "1769384280099", "hash": "a7cfec780e97b26af6488a9aae72cb1043929b13", "bids": [{"price": "0.01", "size": "4359.36"}, {"price": "0.02", "size": "20.46"}, {"price": "0.03", "size": "1140.11"}, {"price": "0.04", "size": "929.35"}], "asks": [{"price": "0.99", "size": "11238.93"}, {"price": "0.98", "size": "43.8"}, {"price": "0.97", "size": "24"}, {"price": "0.96", "size": "5.47"}], "event_type": "book", "last_trade_price": ""}, {"market": "0x0ec29cd8dcc2ee9a5dba335ae702705387554b2ee4a3f58c92e8dfdc578c11ab", "asset_id": "39588334010446257793328783028824091495200768946622815523764108886282664574826", "timestamp": "1769384396848", "hash": "ce4c4ae16329e5a486493205fe2443960b7226e6", "bids": [{"price": "0.01", "size": "2450.76"}, {"price": "0.02", "size": "21.09"}, {"price": "0.03", "size": "500"}, {"price": "0.04", "size": "200"}, {"price": "0.05", "size": "9.45"}, {"price": "0.06", "size": "1190.11"}, {"price": "0.07", "size": "1038.58"}], "asks": [{"price": "0.99", "size": "7088.97"}, {"price": "0.98", "size": "1000"}, {"price": "0.97", "size": "4487.36"}, {"price": "0.77", "size": "300"}, {"price": "0.74", "size": "1090.11"}, {"price": "0.73", "size": "890.11"}, {"price": "0.72", "size": "125"}, {"price": "0.7", "size": "137"}, {"price": "0.5", "size": "10"}, {"price": "0.34", "size": "62.05"}], "event_type": "book", "last_trade_price": "0.660"}, {"market": "0x0ec29cd8dcc2ee9a5dba335ae702705387554b2ee4a3f58c92e8dfdc578c11ab", "asset_id": "14686909450712095553848529179002760186996288018263972086125714385058733086467", "timestamp": "1769384396848", "hash": "2506eb6ee4921d5f1c2beb280fd85168af597335", "bids": [{"price": "0.01", "size": "7088.97"}, {"price": "0.02", "size": "1000"}, {"price": "0.03", "size": "4487.36"}, {"price": "0.23", "size": "300"}, {"price": "0.26", "size": "1090.11"}, {"price": "0.27", "size": "890.11"}, {"price": "0.28", "size": "125"}, {"price": "0.3", "size": "137"}, {"price": "0.5", "size": "10"}, {"price": "0.66", "size": "62.05"}], "asks": [{"price": "0.99", "size": "2450.76"}, {"price": "0.98", "size": "21.09"}, {"price": "0.97", "size": "500"}, {"price": "0.96", "size": "200"}, {"price": "0.95", "size": "9.45"}, {"price": "0.94", "size": "1190.11"}, {"price": "0.93", "size": "1038.58"}], "event_type": "book", "last_trade_price": "0.660"}, {"market": "0x514cd4dda474acaa3b42b0daf45776829d1c71b591f83bdad2556ae9200e0e4a", "asset_id": "24462163476494912897048506220965618245323260292601734651741690457126991788883", "timestamp": "1769383983531", "hash": "7c9a486013a26a601484c79d093accb53092e176", "bids": [{"price": "0.01", "size": "4359.36"}, {"price": "0.02", "size": "20.46"}, {"price": "0.03", "size": "1140.11"}, {"price": "0.04", "size": "929.35"}], "asks": [{"price": "0.99", "size": "11247.92"}, {"price": "0.98", "size": "1003.28"}, {"price": "0.97", "size": "58.04"}], "event_type": "book", "last_trade_price": ""}, {"market": "0x253578ec5c328418c18d2e1d628340b775360edcb942b74c1faed3160768880e", "asset_id": "61737645514089970820675229928948596558449627261018952726858461686763928013541", "timestamp": "1769384168849", "hash": "bf25ff177c8f796bed31d4c47ca377f67044b23e", "bids": [{"price": "0.01", "size": "202.04"}, {"price": "0.02", "size": "217.48"}, {"price": "0.03", "size": "18.99"}, {"price": "0.04", "size": "38.98"}], "asks": [{"price": "0.99", "size": "202.09"}, {"price": "0.98", "size": "160.48"}, {"price": "0.97", "size": "99.65"}, {"price": "0.96", "size": "9.25"}, {"price": "0.95", "size": "5.47"}], "event_type": "book", "last_trade_price": ""}, {"market": "0xc3c68d15795f49737337750652613725b6b26f7220ce14c0b84a285dcf805e0e", "asset_id": "12457168389259168776214290300798144543876101843267881707711945133972284650743", "timestamp": "1769384280099", "hash": "4dcc5b3ef0f3c67d939945626aab900e6be2acea", "bids": [{"price": "0.01", "size": "11238.93"}, {"price": "0.02", "size": "43.8"}, {"price": "0.03", "size": "24"}, {"price": "0.04", "size": "5.47"}], "asks": [{"price": "0.99", "size": "4359.36"}, {"price": "0.98", "size": "20.46"}, {"price": "0.97", "size": "1140.11"}, {"price": "0.96", "size": "929.35"}], "event_type": "book", "last_trade_price": ""}, {"market": "0xba80d2b3a32284fbd12a73fa6b95c7ae86f2c6c0964a918dc76dd260e55012f0", "asset_id": "16882071953866318534045365616741600063971259318273078224982241014011580842479", "timestamp": "1769384279291", "hash": "66b341ea7fe52085aaf263561c748509c400eb72", "bids": [{"price": "0.01", "size": "11296.07"}, {"price": "0.02", "size": "1040.11"}, {"price": "0.03", "size": "27.32"}, {"price": "0.04", "size": "18.47"}], "asks": [{"price": "0.99", "size": "10402.72"}, {"price": "0.98", "size": "157.03"}, {"price": "0.97", "size": "23.71"}, {"price": "0.94", "size": "1140.11"}, {"price": "0.93", "size": "890.11"}], "event_type": "book", "last_trade_price": ""}, {"market": "0x514cd4dda474acaa3b42b0daf45776829d1c71b591f83bdad2556ae9200e0e4a", "asset_id": "41505672373792028775919965123836884749931089620531351085408360822776641662545", "timestamp": "1769383983531", "hash": "571a5e61c7e65663d10b4e66d4c0dea18c2ac48c", "bids": [{"price": "0.01", "size": "11247.92"}, {"price": "0.02", "size": "1003.28"}, {"price": "0.03", "size": "58.04"}], "asks": [{"price": "0.99", "size": "4359.36"}, {"price": "0.98", "size": "20.46"}, {"price": "0.97", "size": "1140.11"}, {"price": "0.96", "size": "929.35"}], "event_type": "book", "last_trade_price": ""}, {"market": "0xba80d2b3a32284fbd12a73fa6b95c7ae86f2c6c0964a918dc76dd260e55012f0", "asset_id": "46588983256260098113202848456240768819978505729734562964760957428208507265980", "timestamp": "1769384279291", "hash": "bfc24ea6cfac3189944a6ef86ab300256fa3b310", "bids": [{"price": "0.01", "size": "10402.72"}, {"price": "0.02", "size": "157.03"}, {"price": "0.03", "size": "23.71"}, {"price": "0.06", "size": "1140.11"}, {"price": "0.07", "size": "890.11"}], "asks": [{"price": "0.99", "size": "11296.07"}, {"price": "0.98", "size": "1040.11"}, {"price": "0.97", "size": "27.32"}, {"price": "0.96", "size": "18.47"}], "event_type": "book", "last_trade_price": ""}, {"market": "0x253578ec5c328418c18d2e1d628340b775360edcb942b74c1faed3160768880e", "asset_id": "34863813868368437273893252292258496153498313244664161472004574624993712180662", "timestamp": "1769384168849", "hash": "c3f2785f6c2337fda3afeffbaba7ad008051b6d6", "bids": [{"price": "0.01", "size": "202.09"}, {"price": "0.02", "size": "160.48"}, {"price": "0.03", "size": "99.65"}, {"price": "0.04", "size": "9.25"}, {"price": "0.05", "size": "5.47"}], "asks": [{"price": "0.99", "size": "202.04"}, {"price": "0.98", "size": "217.48"}, {"price": "0.97", "size": "18.99"}, {"price": "0.96", "size": "38.98"}], "event_type": "book", "last_trade_price": ""}]}
{"_local_timestamp": "2026-01-25T23:41:46.511221+00:00", "data": {"market": "0x0ec29cd8dcc2ee9a5dba335ae702705387554b2ee4a3f58c92e8dfdc578c11ab", "price_changes": [{"asset_id": "14686909450712095553848529179002760186996288018263972086125714385058733086467", "price": "0.03", "size": "4457.32", "side": "BUY", "hash": "c246d39c06db9b56915de906d513ef63b4dbe12c", "best_bid": "0.66", "best_ask": "0.93"}, {"asset_id": "39588334010446257793328783028824091495200768946622815523764108886282664574826", "price": "0.97", "size": "4457.32", "side": "SELL", "hash": "0ab78e767c935447dd242b14dbb5632fa3cde01b", "best_bid": "0.07", "best_ask": "0.34"}], "timestamp": "1769384506443", "event_type": "price_change"}}
{"_local_timestamp": "2026-01-25T23:41:47.271095+00:00", "data": {"market": "0x0ec29cd8dcc2ee9a5dba335ae702705387554b2ee4a3f58c92e8dfdc578c11ab", "price_changes": [{"asset_id": "14686909450712095553848529179002760186996288018263972086125714385058733086467", "price": "0.04", "size": "22.53", "side": "BUY", "hash": "0e7a28eb3ae1ed019039c8a5f26269157debebf0", "best_bid": "0.66", "best_ask": "0.93"}, {"asset_id": "39588334010446257793328783028824091495200768946622815523764108886282664574826", "price": "0.96", "size": "22.53", "side": "SELL", "hash": "32e4eb47745aefafe9d9189a0484cbd785074f9a", "best_bid": "0.07", "best_ask": "0.34"}], "timestamp": "1769384507202", "event_type": "price_change"}}
{"_local_timestamp": "2026-01-25T23:41:49.286646+00:00", "data": {"market": "0x253578ec5c328418c18d2e1d628340b775360edcb942b74c1faed3160768880e", "price_changes": [{"asset_id": "34863813868368437273893252292258496153498313244664161472004574624993712180662", "price": "0.01", "size": "180", "side": "BUY", "hash": "2fcf4f31cb3593189ff6f1b233b5e9495fd9075b", "best_bid": "0.05", "best_ask": "0.96"}, {"asset_id": "61737645514089970820675229928948596558449627261018952726858461686763928013541", "price": "0.99", "size": "180", "side": "SELL", "hash": "edf52a34d18914881ccbbaa0ce4fd57bbd9f4a47", "best_bid": "0.04", "best_ask": "0.95"}], "timestamp": "1769384509223", "event_type": "price_change"}}
{"_local_timestamp": "2026-01-25T23:41:49.287054+00:00", "data": {"market": "0xba80d2b3a32284fbd12a73fa6b95c7ae86f2c6c0964a918dc76dd260e55012f0", "price_changes": [{"asset_id": "16882071953866318534045365616741600063971259318273078224982241014011580842479", "price": "0.03", "size": "0", "side": "BUY", "hash": "df2c833750baa11ca437441519957fb85e7eccd0", "best_bid": "0.04", "best_ask": "0.93"}, {"asset_id": "46588983256260098113202848456240768819978505729734562964760957428208507265980", "price": "0.97", "size": "0", "side": "SELL", "hash": "fdcda92003a73bc39833c15454b3fb0f4e062053", "best_bid": "0.07", "best_ask": "0.96"}], "timestamp": "1769384509223", "event_type": "price_change"}}
{"_local_timestamp": "2026-01-25T23:41:49.885135+00:00", "data": {"market": "0x253578ec5c328418c18d2e1d628340b775360edcb942b74c1faed3160768880e", "price_changes": [{"asset_id": "34863813868368437273893252292258496153498313244664161472004574624993712180662", "price": "0.01", "size": "202.09", "side": "BUY", "hash": "12df9ec5a992d9290474f8c7b46a86a3137a0b58", "best_bid": "0.05", "best_ask": "0.96"}, {"asset_id": "61737645514089970820675229928948596558449627261018952726858461686763928013541", "price": "0.99", "size": "202.09", "side": "SELL", "hash": "c26e9b0ab25a3555b52f938d5234c04b924e6ce8", "best_bid": "0.04", "best_ask": "0.95"}], "timestamp": "1769384509797", "event_type": "price_change"}}
{"_local_timestamp": "2026-01-25T23:41:49.885540+00:00", "data": {"market": "0xba80d2b3a32284fbd12a73fa6b95c7ae86f2c6c0964a918dc76dd260e55012f0", "price_changes": [{"asset_id": "16882071953866318534045365616741600063971259318273078224982241014011580842479", "price": "0.03", "size": "19.97", "side": "BUY", "hash": "2390dc3dee7a9bf79214b2301ed9879780bc5bdb", "best_bid": "0.04", "best_ask": "0.93"}, {"asset_id": "46588983256260098113202848456240768819978505729734562964760957428208507265980", "price": "0.97", "size": "19.97", "side": "SELL", "hash": "398531cfcce5e6f5a5ff3d2276688eda2918dfc4", "best_bid": "0.07", "best_ask": "0.96"}], "timestamp": "1769384509797", "event_type": "price_change"}}
{"_local_timestamp": "2026-01-25T23:41:49.893680+00:00", "data": {"market": "0xba80d2b3a32284fbd12a73fa6b95c7ae86f2c6c0964a918dc76dd260e55012f0", "price_changes": [{"asset_id": "16882071953866318534045365616741600063971259318273078224982241014011580842479", "price": "0.02", "size": "1051.13", "side": "BUY", "hash": "22dc1f5783b25b9f10191bbcf8cab3257b056b00", "best_bid": "0.04", "best_ask": "0.93"}, {"asset_id": "46588983256260098113202848456240768819978505729734562964760957428208507265980", "price": "0.98", "size": "1051.13", "side": "SELL", "hash": "3065515c50a8a508c09992c39932a235b888c61f", "best_bid": "0.07", "best_ask": "0.96"}], "timestamp": "1769384509798", "event_type": "price_change"}}
{"_local_timestamp": "2026-01-25T23:41:50.456458+00:00", "data": {"market": "0xc3c68d15795f49737337750652613725b6b26f7220ce14c0b84a285dcf805e0e", "price_changes": [{"asset_id": "12457168389259168776214290300798144543876101843267881707711945133972284650743", "price": "0.02", "size": "0", "side": "BUY", "hash": "3ad1887e9f0be43fe7a8b651f8c3726bf4e5a92c", "best_bid": "0.04", "best_ask": "0.96"}, {"asset_id": "65603819657652394397234334780908142331249225026323215164617873273051642905321", "price": "0.98", "size": "0", "side": "SELL", "hash": "47809339f2e604fa50094be5215dac45bdf4a54d", "best_bid": "0.04", "best_ask": "0.96"}], "timestamp": "1769384510387", "event_type": "price_change"}}
{"_local_timestamp": "2026-01-25T23:41:51.004107+00:00", "data": {"market": "0xc3c68d15795f49737337750652613725b6b26f7220ce14c0b84a285dcf805e0e", "price_changes": [{"asset_id": "12457168389259168776214290300798144543876101843267881707711945133972284650743", "price": "0.02", "size": "10.48", "side": "BUY", "hash": "931a57981aa3e69680b281182b3fff8fc9c4d864", "best_bid": "0.04", "best_ask": "0.96"}, {"asset_id": "65603819657652394397234334780908142331249225026323215164617873273051642905321", "price": "0.98", "size": "10.48", "side": "SELL", "hash": "3045db44977e393a08ac98f43f80791aca3945f5", "best_bid": "0.04", "best_ask": "0.96"}], "timestamp": "1769384510936", "event_type": "price_change"}}
{"_local_timestamp": "2026-01-25T23:41:51.004727+00:00", "data": {"market": "0xc3c68d15795f49737337750652613725b6b26f7220ce14c0b84a285dcf805e0e", "price_changes": [{"asset_id": "12457168389259168776214290300798144543876101843267881707711945133972284650743", "price": "0.04", "size": "14.72", "side": "BUY", "hash": "a6d11e1d0b7ba3b8b89b80db16499abba37910cd", "best_bid": "0.04", "best_ask": "0.96"}, {"asset_id": "65603819657652394397234334780908142331249225026323215164617873273051642905321", "price": "0.96", "size": "14.72", "side": "SELL", "hash": "0c460452f8bdcbbd860075e6ee8bf5fdb12eea8b", "best_bid": "0.04", "best_ask": "0.96"}], "timestamp": "1769384510937", "event_type": "price_change"}}
{"_local_timestamp": "2026-01-25T23:41:51.005153+00:00", "data": {"market": "0xc3c68d15795f49737337750652613725b6b26f7220ce14c0b84a285dcf805e0e", "price_changes": [{"asset_id": "12457168389259168776214290300798144543876101843267881707711945133972284650743", "price": "0.03", "size": "30.65", "side": "BUY", "hash": "555193322d6f2e276cb22ed37ebdfdb1ff6d4512", "best_bid": "0.04", "best_ask": "0.96"}, {"asset_id": "65603819657652394397234334780908142331249225026323215164617873273051642905321", "price": "0.97", "size": "30.65", "side": "SELL", "hash": "80e1687a9af28ff7a3800222cf6186f9f0d994df", "best_bid": "0.04", "best_ask": "0.96"}], "timestamp": "1769384510938", "event_type": "price_change"}}
{"_local_timestamp": "2026-01-25T23:41:51.005505+00:00", "data": {"market": "0xc3c68d15795f49737337750652613725b6b26f7220ce14c0b84a285dcf805e0e", "price_changes": [{"asset_id": "12457168389259168776214290300798144543876101843267881707711945133972284650743", "price": "0.01", "size": "11248.58", "side": "BUY", "hash": "3709bcd6ef3aa3c9736b4f38e39d2e7103b9235d", "best_bid": "0.04", "best_ask": "0.96"}, {"asset_id": "65603819657652394397234334780908142331249225026323215164617873273051642905321", "price": "0.99", "size": "11248.58", "side": "SELL", "hash": "995ee115310d75ea123f6bcee9667a3a16aecc00", "best_bid": "0.04", "best_ask": "0.96"}], "timestamp": "1769384510939", "event_type": "price_change"}}
{"_local_timestamp": "2026-01-25T23:41:51.237451+00:00", "data": {"market": "0xc3c68d15795f49737337750652613725b6b26f7220ce14c0b84a285dcf805e0e", "price_changes": [{"asset_id": "12457168389259168776214290300798144543876101843267881707711945133972284650743", "price": "0.02", "size": "900.59", "side": "BUY", "hash": "374f815f4017907df4ca9d7ddde8a10b4afd6ceb", "best_bid": "0.04", "best_ask": "0.96"}, {"asset_id": "65603819657652394397234334780908142331249225026323215164617873273051642905321", "price": "0.98", "size": "900.59", "side": "SELL", "hash": "cb58ccbbeaffcc6eb81c4ab20bbfbfb7353dc8d0", "best_bid": "0.04", "best_ask": "0.96"}], "timestamp": "1769384511137", "event_type": "price_change"}}
{"_local_timestamp": "2026-01-25T23:42:26.201044+00:00", "data": {"market": "0x253578ec5c328418c18d2e1d628340b775360edcb942b74c1faed3160768880e", "price_changes": [{"asset_id": "34863813868368437273893252292258496153498313244664161472004574624993712180662", "price": "0.02", "size": "10.48", "side": "BUY", "hash": "70cdedfd72aa7bab03a0a78d11de360f808d5faf", "best_bid": "0.05", "best_ask": "0.96"}, {"asset_id": "61737645514089970820675229928948596558449627261018952726858461686763928013541", "price": "0.98", "size": "10.48", "side": "SELL", "hash": "b6f5b8f4c241dc4158904018f7d3dba55ac8c27a", "best_bid": "0.04", "best_ask": "0.95"}], "timestamp": "1769384546050", "event_type": "price_change"}}
{"_local_timestamp": "2026-01-25T23:42:32.498482+00:00", "data": {"market": "0x253578ec5c328418c18d2e1d628340b775360edcb942b74c1faed3160768880e", "price_changes": [{"asset_id": "34863813868368437273893252292258496153498313244664161472004574624993712180662", "price": "0.02", "size": "160.48", "side": "BUY", "hash": "7218b0cc82f1cda3f5975c436eade10c89aed82a", "best_bid": "0.05", "best_ask": "0.96"}, {"asset_id": "61737645514089970820675229928948596558449627261018952726858461686763928013541", "price": "0.98", "size": "160.48", "side": "SELL", "hash": "5ca093309412c39c8a997500eb599c1052c08d7c", "best_bid": "0.04", "best_ask": "0.95"}], "timestamp": "1769384552432", "event_type": "price_change"}}
{"_local_timestamp": "2026-01-25T23:43:36.060409+00:00", "data": {"market": "0xc3c68d15795f49737337750652613725b6b26f7220ce14c0b84a285dcf805e0e", "price_changes": [{"asset_id": "12457168389259168776214290300798144543876101843267881707711945133972284650743", "price": "0.05", "size": "23.99", "side": "BUY", "hash": "81cd7b931119f2bc7e8130516c09c8bd6a39e3cd", "best_bid": "0.05", "best_ask": "0.96"}, {"asset_id": "65603819657652394397234334780908142331249225026323215164617873273051642905321", "price": "0.95", "size": "23.99", "side": "SELL", "hash": "1619854e231af32a04ed55d3e4c84ff9d2ccb7cc", "best_bid": "0.04", "best_ask": "0.95"}], "timestamp": "1769384615995", "event_type": "price_change"}}
{"_local_timestamp": "2026-01-25T23:43:36.063830+00:00", "data": {"market": "0xba80d2b3a32284fbd12a73fa6b95c7ae86f2c6c0964a918dc76dd260e55012f0", "price_changes": [{"asset_id": "16882071953866318534045365616741600063971259318273078224982241014011580842479", "price": "0.05", "size": "23.99", "side": "BUY", "hash": "3c47464f13ab3e14ad49babd2a8da27e79049f0c", "best_bid": "0.05", "best_ask": "0.93"}, {"asset_id": "46588983256260098113202848456240768819978505729734562964760957428208507265980", "price": "0.95", "size": "23.99", "side": "SELL", "hash": "61985ed23de7e4b5be5fbefcae95d76060431881", "best_bid": "0.07", "best_ask": "0.95"}], "timestamp": "1769384615995", "event_type": "price_change"}}
{"_local_timestamp": "2026-01-25T23:43:39.897808+00:00", "data": {"market": "0xba80d2b3a32284fbd12a73fa6b95c7ae86f2c6c0964a918dc76dd260e55012f0", "price_changes": [{"asset_id": "16882071953866318534045365616741600063971259318273078224982241014011580842479", "price": "0.04", "size": "13", "side": "BUY", "hash": "c5e95105b7516a9d48174aaab98f0187c406b2e9", "best_bid": "0.05", "best_ask": "0.93"}, {"asset_id": "46588983256260098113202848456240768819978505729734562964760957428208507265980", "price": "0.96", "size": "13", "side": "SELL", "hash": "e818c61886769532c23e8c89d95a9b261fc390f4", "best_bid": "0.07", "best_ask": "0.95"}], "timestamp": "1769384619812", "event_type": "price_change"}}
{"_local_timestamp": "2026-01-25T23:43:39.907724+00:00", "data": {"market": "0xc3c68d15795f49737337750652613725b6b26f7220ce14c0b84a285dcf805e0e", "price_changes": [{"asset_id": "12457168389259168776214290300798144543876101843267881707711945133972284650743", "price": "0.04", "size": "9.25", "side": "BUY", "hash": "42a2e1dbb811b63576263002c94a9c071c0ce37e", "best_bid": "0.05", "best_ask": "0.96"}, {"asset_id": "65603819657652394397234334780908142331249225026323215164617873273051642905321", "price": "0.96", "size": "9.25", "side": "SELL", "hash": "c5f0129294bccc561c73e6e3de3dcc6d82d94d15", "best_bid": "0.04", "best_ask": "0.95"}], "timestamp": "1769384619812", "event_type": "price_change"}}
{"_local_timestamp": "2026-01-25T23:43:40.234426+00:00", "data": {"market": "0xc3c68d15795f49737337750652613725b6b26f7220ce14c0b84a285dcf805e0e", "price_changes": [{"asset_id": "12457168389259168776214290300798144543876101843267881707711945133972284650743", "price": "0.06", "size": "5.47", "side": "BUY", "hash": "21628d517584e07301bdf5fa4339828fcfcfd6bb", "best_bid": "0.06", "best_ask": "0.96"}, {"asset_id": "65603819657652394397234334780908142331249225026323215164617873273051642905321", "price": "0.94", "size": "5.47", "side": "SELL", "hash": "d75b69c6659ca44634db6223581192787a9d46ba", "best_bid": "0.04", "best_ask": "0.94"}], "timestamp": "1769384620169", "event_type": "price_change"}}
{"_local_timestamp": "2026-01-25T23:43:40.240037+00:00", "data": {"market": "0xba80d2b3a32284fbd12a73fa6b95c7ae86f2c6c0964a918dc76dd260e55012f0", "price_changes": [{"asset_id": "16882071953866318534045365616741600063971259318273078224982241014011580842479", "price": "0.06", "size": "5.47", "side": "BUY", "hash": "8fa2f802ef0380ce084db131e245f3015f3a41bd", "best_bid": "0.06", "best_ask": "0.93"}, {"asset_id": "46588983256260098113202848456240768819978505729734562964760957428208507265980", "price": "0.94", "size": "5.47", "side": "SELL", "hash": "6a915e9f0212e85d8ecb05ea21daffdaa6ad7617", "best_bid": "0.07", "best_ask": "0.94"}], "timestamp": "1769384620169", "event_type": "price_change"}}
{"_local_timestamp": "2026-01-25T23:45:09.920762+00:00", "data": {"market": "0xc3c68d15795f49737337750652613725b6b26f7220ce14c0b84a285dcf805e0e", "price_changes": [{"asset_id": "12457168389259168776214290300798144543876101843267881707711945133972284650743", "price": "0.05", "size": "0", "side": "BUY", "hash": "4f4d2c64a3f6bf2c6a2897a9f19b5509e25e9379", "best_bid": "0.06", "best_ask": "0.96"}, {"asset_id": "65603819657652394397234334780908142331249225026323215164617873273051642905321", "price": "0.95", "size": "0", "side": "SELL", "hash": "eec2265c7093fac406bca2fb115f6401c4e33575", "best_bid": "0.04", "best_ask": "0.94"}], "timestamp": "1769384709855", "event_type": "price_change"}}
{"_local_timestamp": "2026-01-25T23:45:09.921592+00:00", "data": {"market": "0xba80d2b3a32284fbd12a73fa6b95c7ae86f2c6c0964a918dc76dd260e55012f0", "price_changes": [{"asset_id": "16882071953866318534045365616741600063971259318273078224982241014011580842479", "price": "0.05", "size": "0", "side": "BUY", "hash": "c3defbd3d8a1118a3df441d2d6a074887cafccc0", "best_bid": "0.06", "best_ask": "0.93"}, {"asset_id": "46588983256260098113202848456240768819978505729734562964760957428208507265980", "price": "0.95", "size": "0", "side": "SELL", "hash": "88030eaec32a41f18b2b26cc1fb31a3ed58a72bb", "best_bid": "0.07", "best_ask": "0.94"}], "timestamp": "1769384709855", "event_type": "price_change"}}
{"_local_timestamp": "2026-01-25T23:45:11.864772+00:00", "data": {"market": "0xc3c68d15795f49737337750652613725b6b26f7220ce14c0b84a285dcf805e0e", "price_changes": [{"asset_id": "12457168389259168776214290300798144543876101843267881707711945133972284650743", "price": "0.06", "size": "0", "side": "BUY", "hash": "4924b7709f1125790c23fcfe150d0e9b18329cb9", "best_bid": "0.04", "best_ask": "0.96"}, {"asset_id": "65603819657652394397234334780908142331249225026323215164617873273051642905321", "price": "0.94", "size": "0", "side": "SELL", "hash": "925f34a7fc169582ed94b3d6c4731cab65f260ce", "best_bid": "0.04", "best_ask": "0.96"}], "timestamp": "1769384711771", "event_type": "price_change"}}
{"_local_timestamp": "2026-01-25T23:45:11.865204+00:00", "data": {"market": "0xba80d2b3a32284fbd12a73fa6b95c7ae86f2c6c0964a918dc76dd260e55012f0", "price_changes": [{"asset_id": "16882071953866318534045365616741600063971259318273078224982241014011580842479", "price": "0.06", "size": "0", "side": "BUY", "hash": "1fa3a8b2b4c076fcfb825df5a547d1bc932f974c", "best_bid": "0.04", "best_ask": "0.93"}, {"asset_id": "46588983256260098113202848456240768819978505729734562964760957428208507265980", "price": "0.94", "size": "0", "side": "SELL", "hash": "b9a7f665e2bf3dde66778d495652693c016f6522", "best_bid": "0.07", "best_ask": "0.96"}], "timestamp": "1769384711771", "event_type": "price_change"}}
{"_local_timestamp": "2026-01-25T23:45:12.186490+00:00", "data": {"market": "0xc3c68d15795f49737337750652613725b6b26f7220ce14c0b84a285dcf805e0e", "price_changes": [{"asset_id": "12457168389259168776214290300798144543876101843267881707711945133972284650743", "price": "0.05", "size": "5.47", "side": "BUY", "hash": "22cb864503aa78eada5cd2f4ecb567237044b9c6", "best_bid": "0.05", "best_ask": "0.96"}, {"asset_id": "65603819657652394397234334780908142331249225026323215164617873273051642905321", "price": "0.95", "size": "5.47", "side": "SELL", "hash": "2607b4babdd3e6a5be64cc674f3bc049fed65061", "best_bid": "0.04", "best_ask": "0.95"}], "timestamp": "1769384712121", "event_type": "price_change"}}
{"_local_timestamp": "2026-01-25T23:45:12.186925+00:00", "data": {"market": "0xba80d2b3a32284fbd12a73fa6b95c7ae86f2c6c0964a918dc76dd260e55012f0", "price_changes": [{"asset_id": "16882071953866318534045365616741600063971259318273078224982241014011580842479", "price": "0.05", "size": "5.47", "side": "BUY", "hash": "7840f6cf2cf970f860ff0c672f26586b3aafc085", "best_bid": "0.05", "best_ask": "0.93"}, {"asset_id": "46588983256260098113202848456240768819978505729734562964760957428208507265980", "price": "0.95", "size": "5.47", "side": "SELL", "hash": "fcaddeca9f86342cc599445508e649d7d66a06c4", "best_bid": "0.07", "best_ask": "0.95"}], "timestamp": "1769384712121", "event_type": "price_change"}}
{"_local_timestamp": "2026-01-25T23:45:49.764882+00:00", "data": {"market": "0x253578ec5c328418c18d2e1d628340b775360edcb942b74c1faed3160768880e", "price_changes": [{"asset_id": "34863813868368437273893252292258496153498313244664161472004574624993712180662", "price": "0.01", "size": "180", "side": "BUY", "hash": "8d9c1717aa21d1f7a8c7823d16b550fe02586fe6", "best_bid": "0.05", "best_ask": "0.96"}, {"asset_id": "61737645514089970820675229928948596558449627261018952726858461686763928013541", "price": "0.99", "size": "180", "side": "SELL", "hash": "e49fe713f21775280ab52b7e2bf5be3297c54682", "best_bid": "0.04", "best_ask": "0.95"}], "timestamp": "1769384749702", "event_type": "price_change"}}
{"_local_timestamp": "2026-01-25T23:45:50.755930+00:00", "data": {"market": "0x253578ec5c328418c18d2e1d628340b775360edcb942b74c1faed3160768880e", "price_changes": [{"asset_id": "34863813868368437273893252292258496153498313244664161472004574624993712180662", "price": "0.01", "size": "202.09", "side": "BUY", "hash": "3b3fe7b78635cc15de394b6a50c2a0012df3101c", "best_bid": "0.05", "best_ask": "0.96"}, {"asset_id": "61737645514089970820675229928948596558449627261018952726858461686763928013541", "price": "0.99", "size": "202.09", "side": "SELL", "hash": "7f693fcfa200dfca99cb0a3abaded68c8b7141cb", "best_bid": "0.04", "best_ask": "0.95"}], "timestamp": "1769384750682", "event_type": "price_change"}}
{"_local_timestamp": "2026-01-25T23:45:53.324613+00:00", "data": {"market": "0xba80d2b3a32284fbd12a73fa6b95c7ae86f2c6c0964a918dc76dd260e55012f0", "price_changes": [{"asset_id": "16882071953866318534045365616741600063971259318273078224982241014011580842479", "price": "0.03", "size": "0", "side": "BUY", "hash": "19909de3121e98544a35202e22d3647dab4ba0c0", "best_bid": "0.05", "best_ask": "0.93"}, {"asset_id": "46588983256260098113202848456240768819978505729734562964760957428208507265980", "price": "0.97", "size": "0", "side": "SELL", "hash": "a9ed0bbaa31f3092b7d10d90ce7b72a6b1fce135", "best_bid": "0.07", "best_ask": "0.95"}], "timestamp": "1769384753113", "event_type": "price_change"}}
{"_local_timestamp": "2026-01-25T23:45:55.140909+00:00", "data": {"market": "0xba80d2b3a32284fbd12a73fa6b95c7ae86f2c6c0964a918dc76dd260e55012f0", "price_changes": [{"asset_id": "16882071953866318534045365616741600063971259318273078224982241014011580842479", "price": "0.03", "size": "10.48", "side": "BUY", "hash": "3eb5cf8d1df29783b2f3f4767c1076bb5ab16b9e", "best_bid": "0.05", "best_ask": "0.93"}, {"asset_id": "46588983256260098113202848456240768819978505729734562964760957428208507265980", "price": "0.97", "size": "10.48", "side": "SELL", "hash": "2154d400052f6fbe762575a60ae8ed2ca51be09a", "best_bid": "0.07", "best_ask": "0.95"}], "timestamp": "1769384755076", "event_type": "price_change"}}
{"_local_timestamp": "2026-01-25T23:45:55.144755+00:00", "data": {"market": "0xba80d2b3a32284fbd12a73fa6b95c7ae86f2c6c0964a918dc76dd260e55012f0", "price_changes": [{"asset_id": "16882071953866318534045365616741600063971259318273078224982241014011580842479", "price": "0.05", "size": "11.16", "side": "BUY", "hash": "2520e85423cd1223228c771b33047df20f1b2bda", "best_bid": "0.05", "best_ask": "0.93"}, {"asset_id": "46588983256260098113202848456240768819978505729734562964760957428208507265980", "price": "0.95", "size": "11.16", "side": "SELL", "hash": "5469c99242be55a68db8989e136856921b717faa", "best_bid": "0.07", "best_ask": "0.95"}], "timestamp": "1769384755079", "event_type": "price_change"}}
{"_local_timestamp": "2026-01-25T23:45:55.285731+00:00", "data": {"market": "0xc3c68d15795f49737337750652613725b6b26f7220ce14c0b84a285dcf805e0e", "price_changes": [{"asset_id": "12457168389259168776214290300798144543876101843267881707711945133972284650743", "price": "0.01", "size": "11236.19", "side": "BUY", "hash": "cae25caa6f0b6a49207ebbddd7904a4c0e7d2420", "best_bid": "0.05", "best_ask": "0.96"}, {"asset_id": "65603819657652394397234334780908142331249225026323215164617873273051642905321", "price": "0.99", "size": "11236.19", "side": "SELL", "hash": "1fb003312c81bb32999c3b5cf7882680927b2f06", "best_bid": "0.04", "best_ask": "0.95"}], "timestamp": "1769384755221", "event_type": "price_change"}}
{"_local_timestamp": "2026-01-25T23:45:57.854667+00:00", "data": {"market": "0xc3c68d15795f49737337750652613725b6b26f7220ce14c0b84a285dcf805e0e", "price_changes": [{"asset_id": "12457168389259168776214290300798144543876101843267881707711945133972284650743", "price": "0.01", "size": "11248.62", "side": "BUY", "hash": "b91def56570a0f635e1bf49c09f46b73e962d67f", "best_bid": "0.05", "best_ask": "0.96"}, {"asset_id": "65603819657652394397234334780908142331249225026323215164617873273051642905321", "price": "0.99", "size": "11248.62", "side": "SELL", "hash": "bca7aa0a6c7279e38921465e298d03bbd37efc05", "best_bid": "0.04", "best_ask": "0.95"}], "timestamp": "1769384757781", "event_type": "price_change"}}
{"_local_timestamp": "2026-01-25T23:47:23.353062+00:00", "data": {"market": "0x0ec29cd8dcc2ee9a5dba335ae702705387554b2ee4a3f58c92e8dfdc578c11ab", "price_changes": [{"asset_id": "14686909450712095553848529179002760186996288018263972086125714385058733086467", "price": "0.02", "size": "0", "side": "BUY", "hash": "b017abfe4c0277b0c1871d00f2ab3ce913faea8c", "best_bid": "0.66", "best_ask": "0.93"}, {"asset_id": "39588334010446257793328783028824091495200768946622815523764108886282664574826", "price": "0.98", "size": "0", "side": "SELL", "hash": "1f806b9be423d1f0ddc56b2603b4c9921f2b8cd9", "best_bid": "0.07", "best_ask": "0.34"}], "timestamp": "1769384843171", "event_type": "price_change"}}
{"_local_timestamp": "2026-01-25T23:47:23.557355+00:00", "data": {"market": "0x0ec29cd8dcc2ee9a5dba335ae702705387554b2ee4a3f58c92e8dfdc578c11ab", "price_changes": [{"asset_id": "14686909450712095553848529179002760186996288018263972086125714385058733086467", "price": "0.02", "size": "890.11", "side": "BUY", "hash": "e34f266875e2a635b6ffcf35a2edb398470e0ba8", "best_bid": "0.66", "best_ask": "0.93"}, {"asset_id": "39588334010446257793328783028824091495200768946622815523764108886282664574826", "price": "0.98", "size": "890.11", "side": "SELL", "hash": "a22a11a419b62a11c2a79c360c34834520999f69", "best_bid": "0.07", "best_ask": "0.34"}], "timestamp": "1769384843346", "event_type": "price_change"}}
{"_local_timestamp": "2026-01-25T23:47:23.557791+00:00", "data": {"market": "0x0ec29cd8dcc2ee9a5dba335ae702705387554b2ee4a3f58c92e8dfdc578c11ab", "price_changes": [{"asset_id": "14686909450712095553848529179002760186996288018263972086125714385058733086467", "price": "0.02", "size": "2887.22", "side": "BUY", "hash": "8eae9d0ea4a9c3503f1e96a16d57151ae3cc356c", "best_bid": "0.66", "best_ask": "0.93"}, {"asset_id": "39588334010446257793328783028824091495200768946622815523764108886282664574826", "price": "0.98", "size": "2887.22", "side": "SELL", "hash": "56ee47e02dc24480b38351c805a8e67ef6c2a062", "best_bid": "0.07", "best_ask": "0.34"}], "timestamp": "1769384843347", "event_type": "price_change"}}
{"_local_timestamp": "2026-01-25T23:47:23.558217+00:00", "data": {"market": "0x0ec29cd8dcc2ee9a5dba335ae702705387554b2ee4a3f58c92e8dfdc578c11ab", "price_changes": [{"asset_id": "14686909450712095553848529179002760186996288018263972086125714385058733086467", "price": "0.02", "size": "4157.32", "side": "BUY", "hash": "5ba4483b59bc6ed50fadef21f24bcd44adece828", "best_bid": "0.66", "best_ask": "0.93"}, {"asset_id": "39588334010446257793328783028824091495200768946622815523764108886282664574826", "price": "0.98", "size": "4157.32", "side": "SELL", "hash": "883b0b922d922a280900da145fb05173ac92b910", "best_bid": "0.07", "best_ask": "0.34"}], "timestamp": "1769384843347", "event_type": "price_change"}}
