{"_local_timestamp": "2026-01-25T23:33:16.881414+00:00", "data": [{"market": "0xda5c517dd5b78c80dec8ceb08ca4f466317633487827d7290332b4851cc4a4fa", "asset_id": "22488814055465212843401871684243737932656687199587127613893702721105723939237", "timestamp": "1769383995507", "hash": "97e808531b5a1f8507dccfa1fa17b3e62f98211b", "bids": [{"price": "0.001", "size": "1109090.14"}, {"price": "0.002", "size": "21250"}, {"price": "0.003", "size": "1172.66"}, {"price": "0.004", "size": "23000"}, {"price": "0.006", "size": "83"}, {"price": "0.007", "size": "9.55"}, {"price": "0.01", "size": "1000"}, {"price": "0.02", "size": "1000"}, {"price": "0.021", "size": "14.77"}, {"price": "0.05", "size": "3880"}, {"price": "0.051", "size": "5039"}, {"price": "0.09", "size": "1100"}, {"price": "0.101", "size": "2100"}, {"price": "0.102", "size": "250"}, {"price": "0.103", "size": "5.75"}, {"price": "0.14", "size": "242.85"}, {"price": "0.144", "size": "550"}, {"price": "0.19", "size": "168.42"}, {"price": "0.2", "size": "900"}, {"price": "0.201", "size": "796"}, {"price": "0.24", "size": "116.66"}, {"price": "0.25", "size": "1350"}, {"price": "0.251", "size": "200"}, {"price": "0.28", "size": "142.85"}, {"price": "0.281", "size": "50"}, {"price": "0.297", "size": "5"}, {"price": "0.33", "size": "72.72"}, {"price": "0.34", "size": "50"}, {"price": "0.38", "size": "52.63"}, {"price": "0.428", "size": "3786"}, {"price": "0.429", "size": "1463"}, {"price": "0.58", "size": "410.16"}, {"price": "0.581", "size": "30"}, {"price": "0.62", "size": "229.82"}, {"price": "0.67", "size": "181.81"}, {"price": "0.7", "size": "500"}, {"price": "0.73", "size": "18"}, {"price": "0.76", "size": "75"}, {"price": "0.77", "size": "251.15"}, {"price": "0.78", "size": "378.49"}, {"price": "0.79", "size": "20"}, {"price": "0.8", "size": "150"}, {"price": "0.81", "size": "1222.91"}, {"price": "0.82", "size": "700"}, {"price": "0.85", "size": "245.9"}, {"price": "0.87", "size": "200"}, {"price": "0.9", "size": "419.23"}, {"price": "0.907", "size": "1020.66"}, {"price": "0.91", "size": "2499.95"}, {"price": "0.92", "size": "472.53"}, {"price": "0.925", "size": "500"}, {"price": "0.926", "size": "119.8"}, {"price": "0.927", "size": "60.61"}, {"price": "0.928", "size": "398"}, {"price": "0.933", "size": "151.28"}, {"price": "0.934", "size": "30"}, {"price": "0.935", "size": "20"}], "asks": [{"price": "0.999", "size": "100050"}, {"price": "0.998", "size": "50010.32"}, {"price": "0.997", "size": "23672.09"}, {"price": "0.996", "size": "35.21"}, {"price": "0.99", "size": "10812.68"}, {"price": "0.988", "size": "3750"}, {"price": "0.987", "size": "3469.11"}, {"price": "0.983", "size": "294.11"}, {"price": "0.982", "size": "5.56"}, {"price": "0.98", "size": "14350"}, {"price": "0.979", "size": "5000"}, {"price": "0.978", "size": "2000"}, {"price": "0.977", "size": "1261"}, {"price": "0.974", "size": "192.3"}, {"price": "0.973", "size": "9.11"}, {"price": "0.97", "size": "1111.54"}, {"price": "0.969", "size": "742"}, {"price": "0.968", "size": "2748.52"}, {"price": "0.967", "size": "2646.69"}, {"price": "0.966", "size": "530"}, {"price": "0.965", "size": "15"}, {"price": "0.963", "size": "1873.83"}, {"price": "0.962", "size": "395"}, {"price": "0.96", "size": "125"}, {"price": "0.959", "size": "7.87"}, {"price": "0.956", "size": "1182.45"}, {"price": "0.955", "size": "267"}, {"price": "0.95", "size": "69.15"}, {"price": "0.949", "size": "9121.81"}, {"price": "0.948", "size": "200"}, {"price": "0.947", "size": "470"}, {"price": "0.946", "size": "200"}, {"price": "0.945", "size": "163"}, {"price": "0.944", "size": "143"}, {"price": "0.943", "size": "111.78"}, {"price": "0.942", "size": "45"}, {"price": "0.941", "size": "15"}], "event_type": "book", "last_trade_price": "0.933"}, {"market": "0xda5c517dd5b78c80dec8ceb08ca4f466317633487827d7290332b4851cc4a4fa", "asset_id": "16201530957950630406397949502319734794139620443510795733205872225099141120819", "timestamp": "1769383995507", "hash": "629274a0dc39aef0e8d471a35d4681f3a884b291", "bids": [{"price": "0.001", "size": "100050"}, {"price": "0.002", "size": "50010.32"}, {"price": "0.003", "size": "23672.09"}, {"price": "0.004", "size": "35.21"}, {"price": "0.01", "size": "10812.68"}, {"price": "0.012", "size": "3750"}, {"price": "0.013", "size": "3469.11"}, {"price": "0.017", "size": "294.11"}, {"price": "0.018", "size": "5.56"}, {"price": "0.02", "size": "14350"}, {"price": "0.021", "size": "5000"}, {"price": "0.022", "size": "2000"}, {"price": "0.023", "size": "1261"}, {"price": "0.026", "size": "192.3"}, {"price": "0.027", "size": "9.11"}, {"price": "0.03", "size": "1111.54"}, {"price": "0.031", "size": "742"}, {"price": "0.032", "size": "2748.52"}, {"price": "0.033", "size": "2646.69"}, {"price": "0.034", "size": "530"}, {"price": "0.035", "size": "15"}, {"price": "0.037", "size": "1873.83"}, {"price": "0.038", "size": "395"}, {"price": "0.04", "size": "125"}, {"price": "0.041", "size": "7.87"}, {"price": "0.044", "size": "1182.45"}, {"price": "0.045", "size": "267"}, {"price": "0.05", "size": "69.15"}, {"price": "0.051", "size": "9121.81"}, {"price": "0.052", "size": "200"}, {"price": "0.053", "size": "470"}, {"price": "0.054", "size": "200"}, {"price": "0.055", "size": "163"}, {"price": "0.056", "size": "143"}, {"price": "0.057", "size": "111.78"}, {"price": "0.058", "size": "45"}, {"price": "0.059", "size": "15"}], "asks": [{"price": "0.999", "size": "1109090.14"}, {"price": "0.998", "size": "21250"}, {"price": "0.997", "size": "1172.66"}, {"price": "0.996", "size": "23000"}, {"price": "0.994", "size": "83"}, {"price": "0.993", "size": "9.55"}, {"price": "0.99", "size": "1000"}, {"price": "0.98", "size": "1000"}, {"price": "0.979", "size": "14.77"}, {"price": "0.95", "size": "3880"}, {"price": "0.949", "size": "5039"}, {"price": "0.91", "size": "1100"}, {"price": "0.899", "size": "2100"}, {"price": "0.898", "size": "250"}, {"price": "0.897", "size": "5.75"}, {"price": "0.86", "size": "242.85"}, {"price": "0.856", "size": "550"}, {"price": "0.81", "size": "168.42"}, {"price": "0.8", "size": "900"}, {"price": "0.799", "size": "796"}, {"price": "0.76", "size": "116.66"}, {"price": "0.75", "size": "1350"}, {"price": "0.749", "size": "200"}, {"price": "0.72", "size": "142.85"}, {"price": "0.719", "size": "50"}, {"price": "0.703", "size": "5"}, {"price": "0.67", "size": "72.72"}, {"price": "0.66", "size": "50"}, {"price": "0.62", "size": "52.63"}, {"price": "0.572", "size": "3786"}, {"price": "0.571", "size": "1463"}, {"price": "0.42", "size": "410.16"}, {"price": "0.419", "size": "30"}, {"price": "0.38", "size": "229.82"}, {"price": "0.33", "size": "181.81"}, {"price": "0.3", "size": "500"}, {"price": "0.27", "size": "18"}, {"price": "0.24", "size": "75"}, {"price": "0.23", "size": "251.15"}, {"price": "0.22", "size": "378.49"}, {"price": "0.21", "size": "20"}, {"price": "0.2", "size": "150"}, {"price": "0.19", "size": "1222.91"}, {"price": "0.18", "size": "700"}, {"price": "0.15", "size": "245.9"}, {"price": "0.13", "size": "200"}, {"price": "0.1", "size": "419.23"}, {"price": "0.093", "size": "1020.66"}, {"price": "0.09", "size": "2499.95"}, {"price": "0.08", "size": "472.53"}, {"price": "0.075", "size": "500"}, {"price": "0.074", "size": "119.8"}, {"price": "0.073", "size": "60.61"}, {"price": "0.072", "size": "398"}, {"price": "0.067", "size": "151.28"}, {"price": "0.066", "size": "30"}, {"price": "0.065", "size": "20"}], "event_type": "book", "last_trade_price": "0.933"}]}
{"_local_timestamp": "2026-01-25T23:33:17.000723+00:00", "data": {"market": "0xda5c517dd5b78c80dec8ceb08ca4f466317633487827d7290332b4851cc4a4fa", "price_changes": [{"asset_id": "22488814055465212843401871684243737932656687199587127613893702721105723939237", "price": "0.297", "size": "0", "side": "BUY", "hash": "cc0ed8610c26f8b61a635a482c75c521e3448db9", "best_bid": "0.935", "best_ask": "0.941"}, {"asset_id": "16201530957950630406397949502319734794139620443510795733205872225099141120819", "price": "0.703", "size": "0", "side": "SELL", "hash": "d1c126f03c4328aa902551d7eb17a363e0c15b8f", "best_bid": "0.059", "best_ask": "0.065"}], "timestamp": "1769383996927", "event_type": "price_change"}}
{"_local_timestamp": "2026-01-25T23:33:17.356744+00:00", "data": {"market": "0xda5c517dd5b78c80dec8ceb08ca4f466317633487827d7290332b4851cc4a4fa", "price_changes": [{"asset_id": "22488814055465212843401871684243737932656687199587127613893702721105723939237", "price": "0.297", "size": "5", "side": "BUY", "hash": "331fe3721e93fc6b72eeba81a7cb95206a8a360f", "best_bid": "0.935", "best_ask": "0.941"}, {"asset_id": "16201530957950630406397949502319734794139620443510795733205872225099141120819", "price": "0.703", "size": "5", "side": "SELL", "hash": "b376e455ebab78383edb1f80c88367ae79cfa503", "best_bid": "0.059", "best_ask": "0.065"}], "timestamp": "1769383997289", "event_type": "price_change"}}
{"_local_timestamp": "2026-01-25T23:33:18.701865+00:00", "data": {"market": "0xda5c517dd5b78c80dec8ceb08ca4f466317633487827d7290332b4851cc4a4fa", "price_changes": [{"asset_id": "22488814055465212843401871684243737932656687199587127613893702721105723939237", "price": "0.297", "size": "0", "side": "BUY", "hash": "38348bfe7837d27abaa7d3da6824f3906c482a4f", "best_bid": "0.935", "best_ask": "0.941"}, {"asset_id": "16201530957950630406397949502319734794139620443510795733205872225099141120819", "price": "0.703", "size": "0", "side": "SELL", "hash": "20ea9357b8ed6c78988948af3ba681f7cf6ebf3f", "best_bid": "0.059", "best_ask": "0.065"}], "timestamp": "1769383998634", "event_type": "price_change"}}
{"_local_timestamp": "2026-01-25T23:33:19.157449+00:00", "data": {"market": "0xda5c517dd5b78c80dec8ceb08ca4f466317633487827d7290332b4851cc4a4fa", "price_changes": [{"asset_id": "22488814055465212843401871684243737932656687199587127613893702721105723939237", "price": "0.297", "size": "5", "side": "BUY", "hash": "10951ec382be7ef9beff4b477f7854e32b064296", "best_bid": "0.935", "best_ask": "0.941"}, {"asset_id": "16201530957950630406397949502319734794139620443510795733205872225099141120819", "price": "0.703", "size": "5", "side": "SELL", "hash": "1d7c7f31bfbabfe8cb99c54fa689d5d4bcf8c78d", "best_bid": "0.059", "best_ask": "0.065"}], "timestamp": "1769383999032", "event_type": "price_change"}}
{"_local_timestamp": "2026-01-25T23:33:20.438776+00:00", "data": {"market": "0xda5c517dd5b78c80dec8ceb08ca4f466317633487827d7290332b4851cc4a4fa", "price_changes": [{"asset_id": "22488814055465212843401871684243737932656687199587127613893702721105723939237", "price": "0.297", "size": "0", "side": "BUY", "hash": "7f1f3a6f09cf927174771e305616c12cd5f8837d", "best_bid": "0.935", "best_ask": "0.941"}, {"asset_id": "16201530957950630406397949502319734794139620443510795733205872225099141120819", "price": "0.703", "size": "0", "side": "SELL", "hash": "bc7e8a909e3b46430431b867b694b4771b15442a", "best_bid": "0.059", "best_ask": "0.065"}], "timestamp": "1769384000372", "event_type": "price_change"}}
{"_local_timestamp": "2026-01-25T23:33:20.769866+00:00", "data": {"market": "0xda5c517dd5b78c80dec8ceb08ca4f466317633487827d7290332b4851cc4a4fa", "price_changes": [{"asset_id": "22488814055465212843401871684243737932656687199587127613893702721105723939237", "price": "0.297", "size": "5", "side": "BUY", "hash": "e0f36536b6b79d6916e6faaf3085f4ad877e4a40", "best_bid": "0.935", "best_ask": "0.941"}, {"asset_id": "16201530957950630406397949502319734794139620443510795733205872225099141120819", "price": "0.703", "size": "5", "side": "SELL", "hash": "e2f8108d5abc6c6bfffedeed421cddd4c6ce590f", "best_bid": "0.059", "best_ask": "0.065"}], "timestamp": "1769384000685", "event_type": "price_change"}}
{"_local_timestamp": "2026-01-25T23:33:22.558277+00:00", "data": {"market": "0xda5c517dd5b78c80dec8ceb08ca4f466317633487827d7290332b4851cc4a4fa", "price_changes": [{"asset_id": "22488814055465212843401871684243737932656687199587127613893702721105723939237", "price": "0.297", "size": "0", "side": "BUY", "hash": "ee67adb72ae4739961d36a4e6b8430459fcc8a5a", "best_bid": "0.935", "best_ask": "0.941"}, {"asset_id": "16201530957950630406397949502319734794139620443510795733205872225099141120819", "price": "0.703", "size": "0", "side": "SELL", "hash": "dd393a3e52f7b390842a71ecd6b39c6cb9a5b22e", "best_bid": "0.059", "best_ask": "0.065"}], "timestamp": "1769384002490", "event_type": "price_change"}}
{"_local_timestamp": "2026-01-25T23:33:22.871871+00:00", "data": {"market": "0xda5c517dd5b78c80dec8ceb08ca4f466317633487827d7290332b4851cc4a4fa", "price_changes": [{"asset_id": "22488814055465212843401871684243737932656687199587127613893702721105723939237", "price": "0.297", "size": "5", "side": "BUY", "hash": "97b62685cae24dfde0a47d7e43c0c4d56a6b970d", "best_bid": "0.935", "best_ask": "0.941"}, {"asset_id": "16201530957950630406397949502319734794139620443510795733205872225099141120819", "price": "0.703", "size": "5", "side": "SELL", "hash": "3b441bb72f01991879dc06e066cc3e11d8e11967", "best_bid": "0.059", "best_ask": "0.065"}], "timestamp": "1769384002796", "event_type": "price_change"}}
{"_local_timestamp": "2026-01-25T23:33:23.939349+00:00", "data": {"market": "0xda5c517dd5b78c80dec8ceb08ca4f466317633487827d7290332b4851cc4a4fa", "price_changes": [{"asset_id": "22488814055465212843401871684243737932656687199587127613893702721105723939237", "price": "0.281", "size": "0", "side": "BUY", "hash": "b01fb4e7620168c83c4ad8d5c9aafc779dc76df0", "best_bid": "0.935", "best_ask": "0.941"}, {"asset_id": "16201530957950630406397949502319734794139620443510795733205872225099141120819", "price": "0.719", "size": "0", "side": "SELL", "hash": "4fb3fe0b716bf5e4c2f70450ce7ac4ab2af4a750", "best_bid": "0.059", "best_ask": "0.065"}], "timestamp": "1769384003787", "event_type": "price_change"}}
{"_local_timestamp": "2026-01-25T23:33:24.297741+00:00", "data": {"market": "0xda5c517dd5b78c80dec8ceb08ca4f466317633487827d7290332b4851cc4a4fa", "price_changes": [{"asset_id": "22488814055465212843401871684243737932656687199587127613893702721105723939237", "price": "0.297", "size": "0", "side": "BUY", "hash": "57ff27f2dbf07735accd096ae21e9adb627928ba", "best_bid": "0.935", "best_ask": "0.941"}, {"asset_id": "16201530957950630406397949502319734794139620443510795733205872225099141120819", "price": "0.703", "size": "0", "side": "SELL", "hash": "2c5fa26e7e413f6f4a3b8da67f141266a4afa93e", "best_bid": "0.059", "best_ask": "0.065"}], "timestamp": "1769384004219", "event_type": "price_change"}}
{"_local_timestamp": "2026-01-25T23:33:24.391898+00:00", "data": {"market": "0xda5c517dd5b78c80dec8ceb08ca4f466317633487827d7290332b4851cc4a4fa", "price_changes": [{"asset_id": "22488814055465212843401871684243737932656687199587127613893702721105723939237", "price": "0.28", "size": "192.85", "side": "BUY", "hash": "2079819b49f7e4c345cb2043d3781da7786548e7", "best_bid": "0.935", "best_ask": "0.941"}, {"asset_id": "16201530957950630406397949502319734794139620443510795733205872225099141120819", "price": "0.72", "size": "192.85", "side": "SELL", "hash": "061143f66cdf876db587bd7e62ebff56c7c9db47", "best_bid": "0.059", "best_ask": "0.065"}], "timestamp": "1769384004287", "event_type": "price_change"}}
{"_local_timestamp": "2026-01-25T23:33:24.640805+00:00", "data": {"market": "0xda5c517dd5b78c80dec8ceb08ca4f466317633487827d7290332b4851cc4a4fa", "price_changes": [{"asset_id": "22488814055465212843401871684243737932656687199587127613893702721105723939237", "price": "0.297", "size": "5", "side": "BUY", "hash": "73b144f5f7da226f13c4713d93cc7b1868ec204b", "best_bid": "0.935", "best_ask": "0.941"}, {"asset_id": "16201530957950630406397949502319734794139620443510795733205872225099141120819", "price": "0.703", "size": "5", "side": "SELL", "hash": "1554f518908c0de13b97c41aa6e5ac16a17da1db", "best_bid": "0.059", "best_ask": "0.065"}], "timestamp": "1769384004569", "event_type": "price_change"}}
{"_local_timestamp": "2026-01-25T23:33:26.506219+00:00", "data": {"market": "0xda5c517dd5b78c80dec8ceb08ca4f466317633487827d7290332b4851cc4a4fa", "price_changes": [{"asset_id": "22488814055465212843401871684243737932656687199587127613893702721105723939237", "price": "0.297", "size": "0", "side": "BUY", "hash": "3f4d8b0196f16df93926d6a9a54a10ef42ec228c", "best_bid": "0.935", "best_ask": "0.941"}, {"asset_id": "16201530957950630406397949502319734794139620443510795733205872225099141120819", "price": "0.703", "size": "0", "side": "SELL", "hash": "3daa77e4eddf7d7b3cbf2cdc1c61abff8e190a5d", "best_bid": "0.059", "best_ask": "0.065"}], "timestamp": "1769384006424", "event_type": "price_change"}}
{"_local_timestamp": "2026-01-25T23:33:26.814936+00:00", "data": {"market": "0xda5c517dd5b78c80dec8ceb08ca4f466317633487827d7290332b4851cc4a4fa", "price_changes": [{"asset_id": "22488814055465212843401871684243737932656687199587127613893702721105723939237", "price": "0.297", "size": "5", "side": "BUY", "hash": "73b3c8fd59b39c1326742fc4ba908aac98da11d0", "best_bid": "0.935", "best_ask": "0.941"}, {"asset_id": "16201530957950630406397949502319734794139620443510795733205872225099141120819", "price": "0.703", "size": "5", "side": "SELL", "hash": "1e1b2a5563e6217213c720f59989a08ba9031df8", "best_bid": "0.059", "best_ask": "0.065"}], "timestamp": "1769384006744", "event_type": "price_change"}}
{"_local_timestamp": "2026-01-25T23:33:28.810955+00:00", "data": {"market": "0xda5c517dd5b78c80dec8ceb08ca4f466317633487827d7290332b4851cc4a4fa", "price_changes": [{"asset_id": "22488814055465212843401871684243737932656687199587127613893702721105723939237", "price": "0.297", "size": "0", "side": "BUY", "hash": "6775f9d246fb8f542e17a589599b7730bc3b87ce", "best_bid": "0.935", "best_ask": "0.941"}, {"asset_id": "16201530957950630406397949502319734794139620443510795733205872225099141120819", "price": "0.703", "size": "0", "side": "SELL", "hash": "db15973323813d553f7ee753a6500f27b128e3b5", "best_bid": "0.059", "best_ask": "0.065"}], "timestamp": "1769384008739", "event_type": "price_change"}}
{"_local_timestamp": "2026-01-25T23:33:29.486386+00:00", "data": {"market": "0xda5c517dd5b78c80dec8ceb08ca4f466317633487827d7290332b4851cc4a4fa", "price_changes": [{"asset_id": "22488814055465212843401871684243737932656687199587127613893702721105723939237", "price": "0.297", "size": "5", "side": "BUY", "hash": "a9bfa22daf8be56ab4fd7dfd7d3a69a6adf7bcf9", "best_bid": "0.935", "best_ask": "0.941"}, {"asset_id": "16201530957950630406397949502319734794139620443510795733205872225099141120819", "price": "0.703", "size": "5", "side": "SELL", "hash": "f43486f75e8e07c4755bc5a9fca0df450167961f", "best_bid": "0.059", "best_ask": "0.065"}], "timestamp": "1769384009415", "event_type": "price_change"}}
{"_local_timestamp": "2026-01-25T23:33:30.822890+00:00", "data": {"market": "0xda5c517dd5b78c80dec8ceb08ca4f466317633487827d7290332b4851cc4a4fa", "price_changes": [{"asset_id": "22488814055465212843401871684243737932656687199587127613893702721105723939237", "price": "0.297", "size": "0", "side": "BUY", "hash": "20baf6235dcef9d96dba74c15517a1292bddb701", "best_bid": "0.935", "best_ask": "0.941"}, {"asset_id": "16201530957950630406397949502319734794139620443510795733205872225099141120819", "price": "0.703", "size": "0", "side": "SELL", "hash": "8b751856d9e8dfdd4b09849eb0dd8ce621d4ff0a", "best_bid": "0.059", "best_ask": "0.065"}], "timestamp": "1769384010753", "event_type": "price_change"}}
{"_local_timestamp": "2026-01-25T23:33:31.280188+00:00", "data": {"market": "0xda5c517dd5b78c80dec8ceb08ca4f466317633487827d7290332b4851cc4a4fa", "price_changes": [{"asset_id": "22488814055465212843401871684243737932656687199587127613893702721105723939237", "price": "0.297", "size": "5", "side": "BUY", "hash": "0944839dffd23dfbcf9a7ab57501be9e4ff7d27a", "best_bid": "0.935", "best_ask": "0.941"}, {"asset_id": "16201530957950630406397949502319734794139620443510795733205872225099141120819", "price": "0.703", "size": "5", "side": "SELL", "hash": "e3723c559d8d16781b071c073fe3a430a32e04f6", "best_bid": "0.059", "best_ask": "0.065"}], "timestamp": "1769384011206", "event_type": "price_change"}}
{"_local_timestamp": "2026-01-25T23:33:32.601046+00:00", "data": {"market": "0xda5c517dd5b78c80dec8ceb08ca4f466317633487827d7290332b4851cc4a4fa", "price_changes": [{"asset_id": "22488814055465212843401871684243737932656687199587127613893702721105723939237", "price": "0.297", "size": "0", "side": "BUY", "hash": "333b904e52e3ddcd98da28473531acbe4ef606c9", "best_bid": "0.935", "best_ask": "0.941"}, {"asset_id": "16201530957950630406397949502319734794139620443510795733205872225099141120819", "price": "0.703", "size": "0", "side": "SELL", "hash": "81899d24f1f363f0cbd9eec15815b662b9b9a1e8", "best_bid": "0.059", "best_ask": "0.065"}], "timestamp": "1769384012527", "event_type": "price_change"}}
{"_local_timestamp": "2026-01-25T23:33:32.641906+00:00", "data": {"market": "0xda5c517dd5b78c80dec8ceb08ca4f466317633487827d7290332b4851cc4a4fa", "price_changes": [{"asset_id": "22488814055465212843401871684243737932656687199587127613893702721105723939237", "price": "0.252", "size": "1666", "side": "BUY", "hash": "a21c43a4b9368f11d0a19c4ead66dfc2a9e2f55a", "best_bid": "0.935", "best_ask": "0.941"}, {"asset_id": "16201530957950630406397949502319734794139620443510795733205872225099141120819", "price": "0.748", "size": "1666", "side": "SELL", "hash": "6d0e594d608c1580c5c5175c62914fb0f3442bf6", "best_bid": "0.059", "best_ask": "0.065"}], "timestamp": "1769384012570", "event_type": "price_change"}}
{"_local_timestamp": "2026-01-25T23:33:33.019844+00:00", "data": {"market": "0xda5c517dd5b78c80dec8ceb08ca4f466317633487827d7290332b4851cc4a4fa", "price_changes": [{"asset_id": "22488814055465212843401871684243737932656687199587127613893702721105723939237", "price": "0.297", "size": "5", "side": "BUY", "hash": "228f147bfff525e9d066c064bb58d80c091df5c5", "best_bid": "0.935", "best_ask": "0.941"}, {"asset_id": "16201530957950630406397949502319734794139620443510795733205872225099141120819", "price": "0.703", "size": "5", "side": "SELL", "hash": "8bcc2ce4ab2cb184f4caf27622fa2d29bed369e6", "best_bid": "0.059", "best_ask": "0.065"}], "timestamp": "1769384012938", "event_type": "price_change"}}
{"_local_timestamp": "2026-01-25T23:33:33.328742+00:00", "data": {"market": "0xda5c517dd5b78c80dec8ceb08ca4f466317633487827d7290332b4851cc4a4fa", "price_changes": [{"asset_id": "22488814055465212843401871684243737932656687199587127613893702721105723939237", "price": "0.28", "size": "142.85", "side": "BUY", "hash": "f03464e72019eaaa501abd85c16c93547a3c121b", "best_bid": "0.935", "best_ask": "0.941"}, {"asset_id": "16201530957950630406397949502319734794139620443510795733205872225099141120819", "price": "0.72", "size": "142.85", "side": "SELL", "hash": "4ed0dec08430f9341e7175be2efffe34b1720294", "best_bid": "0.059", "best_ask": "0.065"}], "timestamp": "1769384013149", "event_type": "price_change"}}
{"_local_timestamp": "2026-01-25T23:33:33.329480+00:00", "data": {"market": "0xda5c517dd5b78c80dec8ceb08ca4f466317633487827d7290332b4851cc4a4fa", "price_changes": [{"asset_id": "22488814055465212843401871684243737932656687199587127613893702721105723939237", "price": "0.251", "size": "150", "side": "BUY", "hash": "f03464e72019eaaa501abd85c16c93547a3c121b", "best_bid": "0.935", "best_ask": "0.941"}, {"asset_id": "16201530957950630406397949502319734794139620443510795733205872225099141120819", "price": "0.749", "size": "150", "side": "SELL", "hash": "4ed0dec08430f9341e7175be2efffe34b1720294", "best_bid": "0.059", "best_ask": "0.065"}], "timestamp": "1769384013149", "event_type": "price_change"}}
{"_local_timestamp": "2026-01-25T23:33:33.696890+00:00", "data": {"market": "0xda5c517dd5b78c80dec8ceb08ca4f466317633487827d7290332b4851cc4a4fa", "price_changes": [{"asset_id": "22488814055465212843401871684243737932656687199587127613893702721105723939237", "price": "0.281", "size": "50", "side": "BUY", "hash": "fcd7b94fbab8280a5f460957105ef7f5c3500e30", "best_bid": "0.935", "best_ask": "0.941"}, {"asset_id": "16201530957950630406397949502319734794139620443510795733205872225099141120819", "price": "0.719", "size": "50", "side": "SELL", "hash": "5f55c59528dbcf7242cd6020a05ee665f6a24035", "best_bid": "0.059", "best_ask": "0.065"}], "timestamp": "1769384013547", "event_type": "price_change"}}
{"_local_timestamp": "2026-01-25T23:33:33.721737+00:00", "data": {"market": "0xda5c517dd5b78c80dec8ceb08ca4f466317633487827d7290332b4851cc4a4fa", "price_changes": [{"asset_id": "22488814055465212843401871684243737932656687199587127613893702721105723939237", "price": "0.25", "size": "1400", "side": "BUY", "hash": "d67ee1ff69b91d2baeef813f5537f91d1b72bfe7", "best_bid": "0.935", "best_ask": "0.941"}, {"asset_id": "16201530957950630406397949502319734794139620443510795733205872225099141120819", "price": "0.75", "size": "1400", "side": "SELL", "hash": "4851ad27e493cf04ae93d42f94fba8f946343ede", "best_bid": "0.059", "best_ask": "0.065"}], "timestamp": "1769384013572", "event_type": "price_change"}}
{"_local_timestamp": "2026-01-25T23:33:34.493181+00:00", "data": {"market": "0xda5c517dd5b78c80dec8ceb08ca4f466317633487827d7290332b4851cc4a4fa", "price_changes": [{"asset_id": "22488814055465212843401871684243737932656687199587127613893702721105723939237", "price": "0.297", "size": "0", "side": "BUY", "hash": "7eeb34d184f0d99ab607875137d8aae12a236528", "best_bid": "0.935", "best_ask": "0.941"}, {"asset_id": "16201530957950630406397949502319734794139620443510795733205872225099141120819", "price": "0.703", "size": "0", "side": "SELL", "hash": "a74938ff0ffd61b7789a3e7be596b5c52fde7d0d", "best_bid": "0.059", "best_ask": "0.065"}], "timestamp": "1769384014420", "event_type": "price_change"}}
{"_local_timestamp": "2026-01-25T23:33:34.950578+00:00", "data": {"market": "0xda5c517dd5b78c80dec8ceb08ca4f466317633487827d7290332b4851cc4a4fa", "price_changes": [{"asset_id": "22488814055465212843401871684243737932656687199587127613893702721105723939237", "price": "0.297", "size": "5", "side": "BUY", "hash": "ac3f1b50313c6f924eee6cdc0ca05572b03304c8", "best_bid": "0.935", "best_ask": "0.941"}, {"asset_id": "16201530957950630406397949502319734794139620443510795733205872225099141120819", "price": "0.703", "size": "5", "side": "SELL", "hash": "84b3429c8adfaacc47139e486dc58cefac62dc69", "best_bid": "0.059", "best_ask": "0.065"}], "timestamp": "1769384014876", "event_type": "price_change"}}
{"_local_timestamp": "2026-01-25T23:33:36.219185+00:00", "data": {"market": "0xda5c517dd5b78c80dec8ceb08ca4f466317633487827d7290332b4851cc4a4fa", "price_changes": [{"asset_id": "22488814055465212843401871684243737932656687199587127613893702721105723939237", "price": "0.297", "size": "0", "side": "BUY", "hash": "fc62e35ac1ca8c8a182a4805852f8892062356ce", "best_bid": "0.935", "best_ask": "0.941"}, {"asset_id": "16201530957950630406397949502319734794139620443510795733205872225099141120819", "price": "0.703", "size": "0", "side": "SELL", "hash": "1584c301b8ed853e084e496237011f17cd611668", "best_bid": "0.059", "best_ask": "0.065"}], "timestamp": "1769384016151", "event_type": "price_change"}}
{"_local_timestamp": "2026-01-25T23:33:36.551578+00:00", "data": {"market": "0xda5c517dd5b78c80dec8ceb08ca4f466317633487827d7290332b4851cc4a4fa", "price_changes": [{"asset_id": "22488814055465212843401871684243737932656687199587127613893702721105723939237", "price": "0.297", "size": "5", "side": "BUY", "hash": "ae20baf07734cf88d7d0edf2b5e3df24fdac7dc5", "best_bid": "0.935", "best_ask": "0.941"}, {"asset_id": "16201530957950630406397949502319734794139620443510795733205872225099141120819", "price": "0.703", "size": "5", "side": "SELL", "hash": "fe2f2673cda048180b5770872ac525b12e238b2c", "best_bid": "0.059", "best_ask": "0.065"}], "timestamp": "1769384016475", "event_type": "price_change"}}
{"_local_timestamp": "2026-01-25T23:33:37.510670+00:00", "data": {"market": "0xda5c517dd5b78c80dec8ceb08ca4f466317633487827d7290332b4851cc4a4fa", "price_changes": [{"asset_id": "22488814055465212843401871684243737932656687199587127613893702721105723939237", "price": "0.297", "size": "0", "side": "BUY", "hash": "90887e5f4a86aebf75578e5e4d23ed22e5dde461", "best_bid": "0.935", "best_ask": "0.941"}, {"asset_id": "16201530957950630406397949502319734794139620443510795733205872225099141120819", "price": "0.703", "size": "0", "side": "SELL", "hash": "4e605e375cd2e76b92036704c9af0ed0e04debde", "best_bid": "0.059", "best_ask": "0.065"}], "timestamp": "1769384017406", "event_type": "price_change"}}
{"_local_timestamp": "2026-01-25T23:33:37.783658+00:00", "data": {"market": "0xda5c517dd5b78c80dec8ceb08ca4f466317633487827d7290332b4851cc4a4fa", "price_changes": [{"asset_id": "22488814055465212843401871684243737932656687199587127613893702721105723939237", "price": "0.297", "size": "5", "side": "BUY", "hash": "6b647d9b2eee0a89cde3a13b468e5c853cef9132", "best_bid": "0.935", "best_ask": "0.941"}, {"asset_id": "16201530957950630406397949502319734794139620443510795733205872225099141120819", "price": "0.703", "size": "5", "side": "SELL", "hash": "78ef602ff231fd8c61f3b4e4c82cbe602e3d6694", "best_bid": "0.059", "best_ask": "0.065"}], "timestamp": "1769384017708", "event_type": "price_change"}}
{"_local_timestamp": "2026-01-25T23:33:38.751137+00:00", "data": {"market": "0xda5c517dd5b78c80dec8ceb08ca4f466317633487827d7290332b4851cc4a4fa", "price_changes": [{"asset_id": "22488814055465212843401871684243737932656687199587127613893702721105723939237", "price": "0.297", "size": "0", "side": "BUY", "hash": "973b9b2a64e3363f2c05dbb83e125647a5fe936c", "best_bid": "0.935", "best_ask": "0.941"}, {"asset_id": "16201530957950630406397949502319734794139620443510795733205872225099141120819", "price": "0.703", "size": "0", "side": "SELL", "hash": "3f45656e7bef40b284dbc7f25ee204a22749b843", "best_bid": "0.059", "best_ask": "0.065"}], "timestamp": "1769384018682", "event_type": "price_change"}}
{"_local_timestamp": "2026-01-25T23:33:39.037194+00:00", "data": {"market": "0xda5c517dd5b78c80dec8ceb08ca4f466317633487827d7290332b4851cc4a4fa", "price_changes": [{"asset_id": "22488814055465212843401871684243737932656687199587127613893702721105723939237", "price": "0.297", "size": "5", "side": "BUY", "hash": "e2f469c983824ce7a1ae1b22c014388cdfe1d020", "best_bid": "0.935", "best_ask": "0.941"}, {"asset_id": "16201530957950630406397949502319734794139620443510795733205872225099141120819", "price": "0.703", "size": "5", "side": "SELL", "hash": "12b44c5705957f0e60903631dcd23968c771b6b8", "best_bid": "0.059", "best_ask": "0.065"}], "timestamp": "1769384018965", "event_type": "price_change"}}
{"_local_timestamp": "2026-01-25T23:33:39.621721+00:00", "data": {"market": "0xda5c517dd5b78c80dec8ceb08ca4f466317633487827d7290332b4851cc4a4fa", "price_changes": [{"asset_id": "22488814055465212843401871684243737932656687199587127613893702721105723939237", "price": "0.297", "size": "0", "side": "BUY", "hash": "f5f3133c1db269d9b0103c781b3fc2997c9fb54b", "best_bid": "0.935", "best_ask": "0.941"}, {"asset_id": "16201530957950630406397949502319734794139620443510795733205872225099141120819", "price": "0.703", "size": "0", "side": "SELL", "hash": "ed1a2b06976151cdc5c64c300f659000d60fc2b0", "best_bid": "0.059", "best_ask": "0.065"}], "timestamp": "1769384019544", "event_type": "price_change"}}
{"_local_timestamp": "2026-01-25T23:33:39.980301+00:00", "data": {"market": "0xda5c517dd5b78c80dec8ceb08ca4f466317633487827d7290332b4851cc4a4fa", "price_changes": [{"asset_id": "22488814055465212843401871684243737932656687199587127613893702721105723939237", "price": "0.297", "size": "5", "side": "BUY", "hash": "596e1ddb67f2adaac3327784f12be9847c3b4986", "best_bid": "0.935", "best_ask": "0.941"}, {"asset_id": "16201530957950630406397949502319734794139620443510795733205872225099141120819", "price": "0.703", "size": "5", "side": "SELL", "hash": "a5856105b748a569939a5c9273b8460ef583e27e", "best_bid": "0.059", "best_ask": "0.065"}], "timestamp": "1769384019908", "event_type": "price_change"}}
{"_local_timestamp": "2026-01-25T23:33:40.183194+00:00", "data": {"market": "0xda5c517dd5b78c80dec8ceb08ca4f466317633487827d7290332b4851cc4a4fa", "price_changes": [{"asset_id": "22488814055465212843401871684243737932656687199587127613893702721105723939237", "price": "0.251", "size": "100", "side": "BUY", "hash": "af06e686c52d18c83a2585c409f8373ba9a9f1a2", "best_bid": "0.935", "best_ask": "0.941"}, {"asset_id": "16201530957950630406397949502319734794139620443510795733205872225099141120819", "price": "0.749", "size": "100", "side": "SELL", "hash": "21f29f601c177a6c2d736604a17a395097ab25bf", "best_bid": "0.059", "best_ask": "0.065"}], "timestamp": "1769384020083", "event_type": "price_change"}}
{"_local_timestamp": "2026-01-25T23:33:40.740670+00:00", "data": {"market": "0xda5c517dd5b78c80dec8ceb08ca4f466317633487827d7290332b4851cc4a4fa", "price_changes": [{"asset_id": "22488814055465212843401871684243737932656687199587127613893702721105723939237", "price": "0.281", "size": "100", "side": "BUY", "hash": "dbb31c5aafefa8009640d5cc03444425720694a7", "best_bid": "0.935", "best_ask": "0.941"}, {"asset_id": "16201530957950630406397949502319734794139620443510795733205872225099141120819", "price": "0.719", "size": "100", "side": "SELL", "hash": "81b17cedac16eaeb719678177da141157dc01a66", "best_bid": "0.059", "best_ask": "0.065"}], "timestamp": "1769384020540", "event_type": "price_change"}}
{"_local_timestamp": "2026-01-25T23:33:42.239177+00:00", "data": {"market": "0xda5c517dd5b78c80dec8ceb08ca4f466317633487827d7290332b4851cc4a4fa", "price_changes": [{"asset_id": "22488814055465212843401871684243737932656687199587127613893702721105723939237", "price": "0.297", "size": "0", "side": "BUY", "hash": "2707de144c192cf8a9ab9684d0d469422397f51f", "best_bid": "0.935", "best_ask": "0.941"}, {"asset_id": "16201530957950630406397949502319734794139620443510795733205872225099141120819", "price": "0.703", "size": "0", "side": "SELL", "hash": "a49320bbbdb6b68bcdce3d5abca1e23d88b0bc00", "best_bid": "0.059", "best_ask": "0.065"}], "timestamp": "1769384022170", "event_type": "price_change"}}
{"_local_timestamp": "2026-01-25T23:33:42.623808+00:00", "data": {"market": "0xda5c517dd5b78c80dec8ceb08ca4f466317633487827d7290332b4851cc4a4fa", "price_changes": [{"asset_id": "22488814055465212843401871684243737932656687199587127613893702721105723939237", "price": "0.297", "size": "5", "side": "BUY", "hash": "a7cbdd213206367bc7f6e4182df50b9c452a5dfa", "best_bid": "0.935", "best_ask": "0.941"}, {"asset_id": "16201530957950630406397949502319734794139620443510795733205872225099141120819", "price": "0.703", "size": "5", "side": "SELL", "hash": "7657f91a50c2f0762603a22ee33924ceed8603a3", "best_bid": "0.059", "best_ask": "0.065"}], "timestamp": "1769384022553", "event_type": "price_change"}}
{"_local_timestamp": "2026-01-25T23:33:43.531814+00:00", "data": {"market": "0xda5c517dd5b78c80dec8ceb08ca4f466317633487827d7290332b4851cc4a4fa", "price_changes": [{"asset_id": "22488814055465212843401871684243737932656687199587127613893702721105723939237", "price": "0.297", "size": "0", "side": "BUY", "hash": "15f3326a268da2b7f5853e1bc30399a1572370d0", "best_bid": "0.935", "best_ask": "0.941"}, {"asset_id": "16201530957950630406397949502319734794139620443510795733205872225099141120819", "price": "0.703", "size": "0", "side": "SELL", "hash": "9d55cc6bf33eaf01ff6b990d83c2ead5ff1e956b", "best_bid": "0.059", "best_ask": "0.065"}], "timestamp": "1769384023457", "event_type": "price_change"}}
{"_local_timestamp": "2026-01-25T23:33:43.882120+00:00", "data": {"market": "0xda5c517dd5b78c80dec8ceb08ca4f466317633487827d7290332b4851cc4a4fa", "price_changes": [{"asset_id": "22488814055465212843401871684243737932656687199587127613893702721105723939237", "price": "0.297", "size": "5", "side": "BUY", "hash": "e18b549219136a6a1ef0f13e9a9cf8cc20af36a1", "best_bid": "0.935", "best_ask": "0.941"}, {"asset_id": "16201530957950630406397949502319734794139620443510795733205872225099141120819", "price": "0.703", "size": "5", "side": "SELL", "hash": "a2557e5181ce1b1b29de59c1bde2207b1e121376", "best_bid": "0.059", "best_ask": "0.065"}], "timestamp": "1769384023801", "event_type": "price_change"}}
{"_local_timestamp": "2026-01-25T23:33:45.235151+00:00", "data": {"market": "0xda5c517dd5b78c80dec8ceb08ca4f466317633487827d7290332b4851cc4a4fa", "price_changes": [{"asset_id": "22488814055465212843401871684243737932656687199587127613893702721105723939237", "price": "0.297", "size": "0", "side": "BUY", "hash": "130e427a3593849cced6b26b65ec3dfee0148ec8", "best_bid": "0.935", "best_ask": "0.941"}, {"asset_id": "16201530957950630406397949502319734794139620443510795733205872225099141120819", "price": "0.703", "size": "0", "side": "SELL", "hash": "71fc29dd5300dd48c187122a6715bff980d47444", "best_bid": "0.059", "best_ask": "0.065"}], "timestamp": "1769384025164", "event_type": "price_change"}}
{"_local_timestamp": "2026-01-25T23:33:45.576579+00:00", "data": {"market": "0xda5c517dd5b78c80dec8ceb08ca4f466317633487827d7290332b4851cc4a4fa", "price_changes": [{"asset_id": "22488814055465212843401871684243737932656687199587127613893702721105723939237", "price": "0.297", "size": "5", "side": "BUY", "hash": "855e7adc13420a5daa931d08638f3276ddf546e0", "best_bid": "0.935", "best_ask": "0.941"}, {"asset_id": "16201530957950630406397949502319734794139620443510795733205872225099141120819", "price": "0.703", "size": "5", "side": "SELL", "hash": "f39dfe125a5a8dbcefc40a92a879ba05f384901b", "best_bid": "0.059", "best_ask": "0.065"}], "timestamp": "1769384025504", "event_type": "price_change"}}
{"_local_timestamp": "2026-01-25T23:33:47.780152+00:00", "data": {"market": "0xda5c517dd5b78c80dec8ceb08ca4f466317633487827d7290332b4851cc4a4fa", "price_changes": [{"asset_id": "22488814055465212843401871684243737932656687199587127613893702721105723939237", "price": "0.297", "size": "0", "side": "BUY", "hash": "358bc9f465c16567d44377df7c287815dc17a766", "best_bid": "0.935", "best_ask": "0.941"}, {"asset_id": "16201530957950630406397949502319734794139620443510795733205872225099141120819", "price": "0.703", "size": "0", "side": "SELL", "hash": "84ded9421b32c98121ebcfb378e35981be809c0a", "best_bid": "0.059", "best_ask": "0.065"}], "timestamp": "1769384027714", "event_type": "price_change"}}
{"_local_timestamp": "2026-01-25T23:33:48.134408+00:00", "data": {"market": "0xda5c517dd5b78c80dec8ceb08ca4f466317633487827d7290332b4851cc4a4fa", "price_changes": [{"asset_id": "22488814055465212843401871684243737932656687199587127613893702721105723939237", "price": "0.297", "size": "5", "side": "BUY", "hash": "811ffb9cfb84115514a637ea66e29045abe3e9a6", "best_bid": "0.935", "best_ask": "0.941"}, {"asset_id": "16201530957950630406397949502319734794139620443510795733205872225099141120819", "price": "0.703", "size": "5", "side": "SELL", "hash": "3bdfd1ccbaacade50f52538010caf484b42a1002", "best_bid": "0.059", "best_ask": "0.065"}], "timestamp": "1769384028060", "event_type": "price_change"}}
{"_local_timestamp": "2026-01-25T23:33:49.562449+00:00", "data": {"market": "0xda5c517dd5b78c80dec8ceb08ca4f466317633487827d7290332b4851cc4a4fa", "price_changes": [{"asset_id": "22488814055465212843401871684243737932656687199587127613893702721105723939237", "price": "0.297", "size": "0", "side": "BUY", "hash": "fb12957525298c85570fdd681114cb70ae0d26b5", "best_bid": "0.935", "best_ask": "0.941"}, {"asset_id": "16201530957950630406397949502319734794139620443510795733205872225099141120819", "price": "0.703", "size": "0", "side": "SELL", "hash": "3728a7f545e7c577bbe4e3e2b5c738bdb5e54f4a", "best_bid": "0.059", "best_ask": "0.065"}], "timestamp": "1769384029496", "event_type": "price_change"}}
{"_local_timestamp": "2026-01-25T23:34:19.913636+00:00", "data": {"market": "0xda5c517dd5b78c80dec8ceb08ca4f466317633487827d7290332b4851cc4a4fa", "price_changes": [{"asset_id": "22488814055465212843401871684243737932656687199587127613893702721105723939237", "price": "0.252", "size": "0", "side": "BUY", "hash": "dc34c60cbe4c5251b6798351ef01b10d30aad612", "best_bid": "0.935", "best_ask": "0.941"}, {"asset_id": "16201530957950630406397949502319734794139620443510795733205872225099141120819", "price": "0.748", "size": "0", "side": "SELL", "hash": "5131b640763d626cfa6740cc0d79d2107c7f2426", "best_bid": "0.059", "best_ask": "0.065"}], "timestamp": "1769384059754", "event_type": "price_change"}}
{"_local_timestamp": "2026-01-25T23:34:27.882973+00:00", "data": {"market": "0xda5c517dd5b78c80dec8ceb08ca4f466317633487827d7290332b4851cc4a4fa", "price_changes": [{"asset_id": "22488814055465212843401871684243737932656687199587127613893702721105723939237", "price": "0.251", "size": "0", "side": "BUY", "hash": "ed42f4c6585576ec57011b0c28e609b561841344", "best_bid": "0.935", "best_ask": "0.941"}, {"asset_id": "16201530957950630406397949502319734794139620443510795733205872225099141120819", "price": "0.749", "size": "0", "side": "SELL", "hash": "8fa4e1a798cfd8d54f4e5a00d9b2278dfd4997f6", "best_bid": "0.059", "best_ask": "0.065"}], "timestamp": "1769384067612", "event_type": "price_change"}}
{"_local_timestamp": "2026-01-25T23:34:28.505579+00:00", "data": {"market": "0xda5c517dd5b78c80dec8ceb08ca4f466317633487827d7290332b4851cc4a4fa", "price_changes": [{"asset_id": "22488814055465212843401871684243737932656687199587127613893702721105723939237", "price": "0.281", "size": "200", "side": "BUY", "hash": "409f54d92ca2842ffb2f2bc05c5536713addbb7e", "best_bid": "0.935", "best_ask": "0.941"}, {"asset_id": "16201530957950630406397949502319734794139620443510795733205872225099141120819", "price": "0.719", "size": "200", "side": "SELL", "hash": "b765445674846c58d5d03f38ac7464cc6b3ce204", "best_bid": "0.059", "best_ask": "0.065"}], "timestamp": "1769384068138", "event_type": "price_change"}}
{"_local_timestamp": "2026-01-25T23:34:43.604043+00:00", "data": {"market": "0xda5c517dd5b78c80dec8ceb08ca4f466317633487827d7290332b4851cc4a4fa", "price_changes": [{"asset_id": "22488814055465212843401871684243737932656687199587127613893702721105723939237", "price": "0.28", "size": "92.85", "side": "BUY", "hash": "734d1e8b04e957a9e31b0428cb1da0557d776926", "best_bid": "0.935", "best_ask": "0.941"}, {"asset_id": "16201530957950630406397949502319734794139620443510795733205872225099141120819", "price": "0.72", "size": "92.85", "side": "SELL", "hash": "d498008894d064f3aa81565c9ca061129d2a7c01", "best_bid": "0.059", "best_ask": "0.065"}], "timestamp": "1769384083535", "event_type": "price_change"}}
{"_local_timestamp": "2026-01-25T23:34:43.898336+00:00", "data": {"market": "0xda5c517dd5b78c80dec8ceb08ca4f466317633487827d7290332b4851cc4a4fa", "price_changes": [{"asset_id": "22488814055465212843401871684243737932656687199587127613893702721105723939237", "price": "0.281", "size": "250", "side": "BUY", "hash": "9c32b01914bd4c06fa4f67a09578502efb0a9878", "best_bid": "0.935", "best_ask": "0.941"}, {"asset_id": "16201530957950630406397949502319734794139620443510795733205872225099141120819", "price": "0.719", "size": "250", "side": "SELL", "hash": "27b5bb5729b72ffab83e5a70d203dedb7474b80b", "best_bid": "0.059", "best_ask": "0.065"}], "timestamp": "1769384083802", "event_type": "price_change"}}
{"_local_timestamp": "2026-01-25T23:34:45.617055+00:00", "data": {"market": "0xda5c517dd5b78c80dec8ceb08ca4f466317633487827d7290332b4851cc4a4fa", "price_changes": [{"asset_id": "22488814055465212843401871684243737932656687199587127613893702721105723939237", "price": "0.251", "size": "1672", "side": "BUY", "hash": "c9280d765c8abe7f9fe657604d1bd072e0928049", "best_bid": "0.935", "best_ask": "0.941"}, {"asset_id": "16201530957950630406397949502319734794139620443510795733205872225099141120819", "price": "0.749", "size": "1672", "side": "SELL", "hash": "452c204f3a4450882ef06e307f06c32402aaa3ca", "best_bid": "0.059", "best_ask": "0.065"}], "timestamp": "1769384085552", "event_type": "price_change"}}
{"_local_timestamp": "2026-01-25T23:35:00.981213+00:00", "data": {"market": "0xda5c517dd5b78c80dec8ceb08ca4f466317633487827d7290332b4851cc4a4fa", "price_changes": [{"asset_id": "22488814055465212843401871684243737932656687199587127613893702721105723939237", "price": "0.297", "size": "5", "side": "BUY", "hash": "790bc30d0e0f895559a4bea2fe522caea4d5d9c3", "best_bid": "0.935", "best_ask": "0.941"}, {"asset_id": "16201530957950630406397949502319734794139620443510795733205872225099141120819", "price": "0.703", "size": "5", "side": "SELL", "hash": "4253ea30a25aaa0acea7a497cbec6d384068c630", "best_bid": "0.059", "best_ask": "0.065"}], "timestamp": "1769384100918", "event_type": "price_change"}}
{"_local_timestamp": "2026-01-25T23:35:12.213973+00:00", "data": {"market": "0xda5c517dd5b78c80dec8ceb08ca4f466317633487827d7290332b4851cc4a4fa", "price_changes": [{"asset_id": "22488814055465212843401871684243737932656687199587127613893702721105723939237", "price": "0.297", "size": "0", "side": "BUY", "hash": "604cc1e1789a6c43125512b969f914313f928ce7", "best_bid": "0.935", "best_ask": "0.941"}, {"asset_id": "16201530957950630406397949502319734794139620443510795733205872225099141120819", "price": "0.703", "size": "0", "side": "SELL", "hash": "f503c43143d5f8a325cf25d34daaef31c9520063", "best_bid": "0.059", "best_ask": "0.065"}], "timestamp": "1769384112134", "event_type": "price_change"}}
{"_local_timestamp": "2026-01-25T23:35:12.447961+00:00", "data": {"market": "0xda5c517dd5b78c80dec8ceb08ca4f466317633487827d7290332b4851cc4a4fa", "price_changes": [{"asset_id": "22488814055465212843401871684243737932656687199587127613893702721105723939237", "price": "0.297", "size": "5", "side": "BUY", "hash": "df64c1b22b142991b2fb4133594c894ca2306596", "best_bid": "0.935", "best_ask": "0.941"}, {"asset_id": "16201530957950630406397949502319734794139620443510795733205872225099141120819", "price": "0.703", "size": "5", "side": "SELL", "hash": "0f29bfdff573c381fda406e052c842ed8a3182f8", "best_bid": "0.059", "best_ask": "0.065"}], "timestamp": "1769384112376", "event_type": "price_change"}}
{"_local_timestamp": "2026-01-25T23:35:14.651187+00:00", "data": {"market": "0xda5c517dd5b78c80dec8ceb08ca4f466317633487827d7290332b4851cc4a4fa", "price_changes": [{"asset_id": "22488814055465212843401871684243737932656687199587127613893702721105723939237", "price": "0.297", "size": "0", "side": "BUY", "hash": "255eb67421b237b0c3c6819c0cd7ec4e9b4b881f", "best_bid": "0.935", "best_ask": "0.941"}, {"asset_id": "16201530957950630406397949502319734794139620443510795733205872225099141120819", "price": "0.703", "size": "0", "side": "SELL", "hash": "f97f576da0f85c90ae2eca5961debffbfa2a4dc3", "best_bid": "0.059", "best_ask": "0.065"}], "timestamp": "1769384114562", "event_type": "price_change"}}
{"_local_timestamp": "2026-01-25T23:35:14.801437+00:00", "data": {"market": "0xda5c517dd5b78c80dec8ceb08ca4f466317633487827d7290332b4851cc4a4fa", "price_changes": [{"asset_id": "22488814055465212843401871684243737932656687199587127613893702721105723939237", "price": "0.297", "size": "5", "side": "BUY", "hash": "473f7e6c8968714973d528897b4cc46a129aeace", "best_bid": "0.935", "best_ask": "0.941"}, {"asset_id": "16201530957950630406397949502319734794139620443510795733205872225099141120819", "price": "0.703", "size": "5", "side": "SELL", "hash": "72b6915252355a64164ffe185b4ed7014b64b627", "best_bid": "0.059", "best_ask": "0.065"}], "timestamp": "1769384114737", "event_type": "price_change"}}
{"_local_timestamp": "2026-01-25T23:35:16.061447+00:00", "data": {"market": "0xda5c517dd5b78c80dec8ceb08ca4f466317633487827d7290332b4851cc4a4fa", "price_changes": [{"asset_id": "22488814055465212843401871684243737932656687199587127613893702721105723939237", "price": "0.297", "size": "0", "side": "BUY", "hash": "017f7b779fa6975361ab2f75f772c05e088b0322", "best_bid": "0.935", "best_ask": "0.941"}, {"asset_id": "16201530957950630406397949502319734794139620443510795733205872225099141120819", "price": "0.703", "size": "0", "side": "SELL", "hash": "0cce61b687ce9fc59416909b9cbefc48ef7d6a53", "best_bid": "0.059", "best_ask": "0.065"}], "timestamp": "1769384115991", "event_type": "price_change"}}
{"_local_timestamp": "2026-01-25T23:35:16.310930+00:00", "data": {"market": "0xda5c517dd5b78c80dec8ceb08ca4f466317633487827d7290332b4851cc4a4fa", "price_changes": [{"asset_id": "22488814055465212843401871684243737932656687199587127613893702721105723939237", "price": "0.297", "size": "5", "side": "BUY", "hash": "8f992b743b95f3ac2048e225db980f51255114d2", "best_bid": "0.935", "best_ask": "0.941"}, {"asset_id": "16201530957950630406397949502319734794139620443510795733205872225099141120819", "price": "0.703", "size": "5", "side": "SELL", "hash": "a0f35dddc21401e049bed6d63739aae93571dc92", "best_bid": "0.059", "best_ask": "0.065"}], "timestamp": "1769384116243", "event_type": "price_change"}}
{"_local_timestamp": "2026-01-25T23:35:18.612330+00:00", "data": {"market": "0xda5c517dd5b78c80dec8ceb08ca4f466317633487827d7290332b4851cc4a4fa", "price_changes": [{"asset_id": "22488814055465212843401871684243737932656687199587127613893702721105723939237", "price": "0.297", "size": "0", "side": "BUY", "hash": "9f338b69979d26f1e62fa5af1d38a9e0bc288bca", "best_bid": "0.935", "best_ask": "0.941"}, {"asset_id": "16201530957950630406397949502319734794139620443510795733205872225099141120819", "price": "0.703", "size": "0", "side": "SELL", "hash": "e230c0d4270afa5f3f5365198f98fe7b87bbbf4f", "best_bid": "0.059", "best_ask": "0.065"}], "timestamp": "1769384118545", "event_type": "price_change"}}
{"_local_timestamp": "2026-01-25T23:35:18.964569+00:00", "data": {"market": "0xda5c517dd5b78c80dec8ceb08ca4f466317633487827d7290332b4851cc4a4fa", "price_changes": [{"asset_id": "22488814055465212843401871684243737932656687199587127613893702721105723939237", "price": "0.297", "size": "5", "side": "BUY", "hash": "0ee45341a5a8deb0d6ed885417dbff9fd0c8cd4e", "best_bid": "0.935", "best_ask": "0.941"}, {"asset_id": "16201530957950630406397949502319734794139620443510795733205872225099141120819", "price": "0.703", "size": "5", "side": "SELL", "hash": "154fbb4ecb44cd535acc082ea4a5d1f301b363ef", "best_bid": "0.059", "best_ask": "0.065"}], "timestamp": "1769384118893", "event_type": "price_change"}}
{"_local_timestamp": "2026-01-25T23:35:20.186778+00:00", "data": {"market": "0xda5c517dd5b78c80dec8ceb08ca4f466317633487827d7290332b4851cc4a4fa", "price_changes": [{"asset_id": "22488814055465212843401871684243737932656687199587127613893702721105723939237", "price": "0.297", "size": "0", "side": "BUY", "hash": "b831f3704c0570bf4d2855a711287bba0ac4f695", "best_bid": "0.935", "best_ask": "0.941"}, {"asset_id": "16201530957950630406397949502319734794139620443510795733205872225099141120819", "price": "0.703", "size": "0", "side": "SELL", "hash": "0186be42369f47f1c6768a382be771f1b2a46efa", "best_bid": "0.059", "best_ask": "0.065"}], "timestamp": "1769384120116", "event_type": "price_change"}}
{"_local_timestamp": "2026-01-25T23:35:20.648089+00:00", "data": {"market": "0xda5c517dd5b78c80dec8ceb08ca4f466317633487827d7290332b4851cc4a4fa", "price_changes": [{"asset_id": "22488814055465212843401871684243737932656687199587127613893702721105723939237", "price": "0.297", "size": "5", "side": "BUY", "hash": "58d61fda7b4f553eef8a3b5b2f8afc6e6f070771", "best_bid": "0.935", "best_ask": "0.941"}, {"asset_id": "16201530957950630406397949502319734794139620443510795733205872225099141120819", "price": "0.703", "size": "5", "side": "SELL", "hash": "77a20379278b9cd1bbbf51f223cbe7fd16c60ad0", "best_bid": "0.059", "best_ask": "0.065"}], "timestamp": "1769384120578", "event_type": "price_change"}}
{"_local_timestamp": "2026-01-25T23:35:23.191775+00:00", "data": {"market": "0xda5c517dd5b78c80dec8ceb08ca4f466317633487827d7290332b4851cc4a4fa", "price_changes": [{"asset_id": "22488814055465212843401871684243737932656687199587127613893702721105723939237", "price": "0.297", "size": "0", "side": "BUY", "hash": "f0c0e1a9d4cc956f389d19592050ac8ca705cf08", "best_bid": "0.935", "best_ask": "0.941"}, {"asset_id": "16201530957950630406397949502319734794139620443510795733205872225099141120819", "price": "0.703", "size": "0", "side": "SELL", "hash": "fc329706b6491d6b8cec324da9d049c4418ba6e3", "best_bid": "0.059", "best_ask": "0.065"}], "timestamp": "1769384123122", "event_type": "price_change"}}
{"_local_timestamp": "2026-01-25T23:35:23.601933+00:00", "data": {"market": "0xda5c517dd5b78c80dec8ceb08ca4f466317633487827d7290332b4851cc4a4fa", "price_changes": [{"asset_id": "22488814055465212843401871684243737932656687199587127613893702721105723939237", "price": "0.297", "size": "5", "side": "BUY", "hash": "0147c4a4ade2de12c732072625fe1098d9248931", "best_bid": "0.935", "best_ask": "0.941"}, {"asset_id": "16201530957950630406397949502319734794139620443510795733205872225099141120819", "price": "0.703", "size": "5", "side": "SELL", "hash": "e8d694a11161386e7309fb45d259b7cb83217ce2", "best_bid": "0.059", "best_ask": "0.065"}], "timestamp": "1769384123537", "event_type": "price_change"}}
{"_local_timestamp": "2026-01-25T23:35:25.664236+00:00", "data": {"market": "0xda5c517dd5b78c80dec8ceb08ca4f466317633487827d7290332b4851cc4a4fa", "price_changes": [{"asset_id": "22488814055465212843401871684243737932656687199587127613893702721105723939237", "price": "0.297", "size": "0", "side": "BUY", "hash": "821e56c59b0296378fabcce70b331b9563034257", "best_bid": "0.935", "best_ask": "0.941"}, {"asset_id": "16201530957950630406397949502319734794139620443510795733205872225099141120819", "price": "0.703", "size": "0", "side": "SELL", "hash": "05f5ff5e296f1a38ad89bc63956794b229dedecd", "best_bid": "0.059", "best_ask": "0.065"}], "timestamp": "1769384125596", "event_type": "price_change"}}
{"_local_timestamp": "2026-01-25T23:35:26.022018+00:00", "data": {"market": "0xda5c517dd5b78c80dec8ceb08ca4f466317633487827d7290332b4851cc4a4fa", "price_changes": [{"asset_id": "22488814055465212843401871684243737932656687199587127613893702721105723939237", "price": "0.297", "size": "5", "side": "BUY", "hash": "c73a3c7a26329c3b5da48163604dd68d0c971891", "best_bid": "0.935", "best_ask": "0.941"}, {"asset_id": "16201530957950630406397949502319734794139620443510795733205872225099141120819", "price": "0.703", "size": "5", "side": "SELL", "hash": "9a97e1931c787e4fb8f228b3c6b7691931f6046e", "best_bid": "0.059", "best_ask": "0.065"}], "timestamp": "1769384125952", "event_type": "price_change"}}
{"_local_timestamp": "2026-01-25T23:35:26.675274+00:00", "data": {"market": "0xda5c517dd5b78c80dec8ceb08ca4f466317633487827d7290332b4851cc4a4fa", "price_changes": [{"asset_id": "22488814055465212843401871684243737932656687199587127613893702721105723939237", "price": "0.281", "size": "200", "side": "BUY", "hash": "4d3ab449c30e7a527db1b0c7edc59ae8aebe0830", "best_bid": "0.935", "best_ask": "0.941"}, {"asset_id": "16201530957950630406397949502319734794139620443510795733205872225099141120819", "price": "0.719", "size": "200", "side": "SELL", "hash": "7ba59ec634ab3c0099138ba2f4dc7999f5f73ee3", "best_bid": "0.059", "best_ask": "0.065"}], "timestamp": "1769384126563", "event_type": "price_change"}}
{"_local_timestamp": "2026-01-25T23:35:27.135435+00:00", "data": {"market": "0xda5c517dd5b78c80dec8ceb08ca4f466317633487827d7290332b4851cc4a4fa", "price_changes": [{"asset_id": "22488814055465212843401871684243737932656687199587127613893702721105723939237", "price": "0.252", "size": "50", "side": "BUY", "hash": "6bde27e4d7a5c68ee5743f2c2cf97e3e78b17c16", "best_bid": "0.935", "best_ask": "0.941"}, {"asset_id": "16201530957950630406397949502319734794139620443510795733205872225099141120819", "price": "0.748", "size": "50", "side": "SELL", "hash": "4f034b966b702cdadd290c657de1bf42c43027d9", "best_bid": "0.059", "best_ask": "0.065"}], "timestamp": "1769384126908", "event_type": "price_change"}}
{"_local_timestamp": "2026-01-25T23:35:28.051862+00:00", "data": {"market": "0xda5c517dd5b78c80dec8ceb08ca4f466317633487827d7290332b4851cc4a4fa", "price_changes": [{"asset_id": "22488814055465212843401871684243737932656687199587127613893702721105723939237", "price": "0.297", "size": "0", "side": "BUY", "hash": "ca297b4f1d09246345ba80602e202e36e1db095d", "best_bid": "0.935", "best_ask": "0.941"}, {"asset_id": "16201530957950630406397949502319734794139620443510795733205872225099141120819", "price": "0.703", "size": "0", "side": "SELL", "hash": "b9d8d2e60505999934be848a7cf8adedaa50b8b1", "best_bid": "0.059", "best_ask": "0.065"}], "timestamp": "1769384127982", "event_type": "price_change"}}
{"_local_timestamp": "2026-01-25T23:35:28.508403+00:00", "data": {"market": "0xda5c517dd5b78c80dec8ceb08ca4f466317633487827d7290332b4851cc4a4fa", "price_changes": [{"asset_id": "22488814055465212843401871684243737932656687199587127613893702721105723939237", "price": "0.297", "size": "5", "side": "BUY", "hash": "c2e12de524660abfce8047e877d5973c9e80b0c7", "best_bid": "0.935", "best_ask": "0.941"}, {"asset_id": "16201530957950630406397949502319734794139620443510795733205872225099141120819", "price": "0.703", "size": "5", "side": "SELL", "hash": "44a52bcf0316ab2230edc3376246f675d70221df", "best_bid": "0.059", "best_ask": "0.065"}], "timestamp": "1769384128439", "event_type": "price_change"}}
{"_local_timestamp": "2026-01-25T23:35:30.244259+00:00", "data": {"market": "0xda5c517dd5b78c80dec8ceb08ca4f466317633487827d7290332b4851cc4a4fa", "price_changes": [{"asset_id": "22488814055465212843401871684243737932656687199587127613893702721105723939237", "price": "0.297", "size": "0", "side": "BUY", "hash": "ecbbf74029edd3957332745ce9ae5b32918e7729", "best_bid": "0.935", "best_ask": "0.941"}, {"asset_id": "16201530957950630406397949502319734794139620443510795733205872225099141120819", "price": "0.703", "size": "0", "side": "SELL", "hash": "c0168c18979c7a9490c942f7014d2e3479a49cc0", "best_bid": "0.059", "best_ask": "0.065"}], "timestamp": "1769384130172", "event_type": "price_change"}}
{"_local_timestamp": "2026-01-25T23:35:30.510570+00:00", "data": {"market": "0xda5c517dd5b78c80dec8ceb08ca4f466317633487827d7290332b4851cc4a4fa", "price_changes": [{"asset_id": "22488814055465212843401871684243737932656687199587127613893702721105723939237", "price": "0.297", "size": "5", "side": "BUY", "hash": "abe007d90e40e30abd3458de300ed210fb794439", "best_bid": "0.935", "best_ask": "0.941"}, {"asset_id": "16201530957950630406397949502319734794139620443510795733205872225099141120819", "price": "0.703", "size": "5", "side": "SELL", "hash": "9537cfc203f062bef40175d048ebd15c97f0133f", "best_bid": "0.059", "best_ask": "0.065"}], "timestamp": "1769384130437", "event_type": "price_change"}}
{"_local_timestamp": "2026-01-25T23:35:31.373089+00:00", "data": {"market": "0xda5c517dd5b78c80dec8ceb08ca4f466317633487827d7290332b4851cc4a4fa", "price_changes": [{"asset_id": "16201530957950630406397949502319734794139620443510795733205872225099141120819", "price": "0.055", "size": "0", "side": "BUY", "hash": "ec66885de4fcf16b86267fa01d68fefb610d656e", "best_bid": "0.059", "best_ask": "0.065"}, {"asset_id": "22488814055465212843401871684243737932656687199587127613893702721105723939237", "price": "0.945", "size": "0", "side": "SELL", "hash": "e75661485608e9aa07b64c7ca98f41e7910a8ab5", "best_bid": "0.935", "best_ask": "0.941"}], "timestamp": "1769384131242", "event_type": "price_change"}}
{"_local_timestamp": "2026-01-25T23:35:31.943547+00:00", "data": {"market": "0xda5c517dd5b78c80dec8ceb08ca4f466317633487827d7290332b4851cc4a4fa", "price_changes": [{"asset_id": "22488814055465212843401871684243737932656687199587127613893702721105723939237", "price": "0.297", "size": "0", "side": "BUY", "hash": "c1b2fe2f3bf2b1e7abf1430cbd7cfb26c265368c", "best_bid": "0.935", "best_ask": "0.941"}, {"asset_id": "16201530957950630406397949502319734794139620443510795733205872225099141120819", "price": "0.703", "size": "0", "side": "SELL", "hash": "44818c43387de0fa016053c6f2d532e4d2d41f57", "best_bid": "0.059", "best_ask": "0.065"}], "timestamp": "1769384131877", "event_type": "price_change"}}
{"_local_timestamp": "2026-01-25T23:35:32.214978+00:00", "data": {"market": "0xda5c517dd5b78c80dec8ceb08ca4f466317633487827d7290332b4851cc4a4fa", "price_changes": [{"asset_id": "22488814055465212843401871684243737932656687199587127613893702721105723939237", "price": "0.297", "size": "5", "side": "BUY", "hash": "bcd2505a4c68ac84c584a8d8f3fd42de08a3e586", "best_bid": "0.935", "best_ask": "0.941"}, {"asset_id": "16201530957950630406397949502319734794139620443510795733205872225099141120819", "price": "0.703", "size": "5", "side": "SELL", "hash": "acca3d3f24180d2b27863755d6dffa550e31e799", "best_bid": "0.059", "best_ask": "0.065"}], "timestamp": "1769384132151", "event_type": "price_change"}}
{"_local_timestamp": "2026-01-25T23:35:34.228117+00:00", "data": {"market": "0xda5c517dd5b78c80dec8ceb08ca4f466317633487827d7290332b4851cc4a4fa", "price_changes": [{"asset_id": "22488814055465212843401871684243737932656687199587127613893702721105723939237", "price": "0.297", "size": "0", "side": "BUY", "hash": "21397efdb979d2669dfccb5d34a05d19765365c9", "best_bid": "0.935", "best_ask": "0.941"}, {"asset_id": "16201530957950630406397949502319734794139620443510795733205872225099141120819", "price": "0.703", "size": "0", "side": "SELL", "hash": "026ea5443223a271749d5806ae3676b3bccf2bcd", "best_bid": "0.059", "best_ask": "0.065"}], "timestamp": "1769384134158", "event_type": "price_change"}}
{"_local_timestamp": "2026-01-25T23:35:34.526853+00:00", "data": {"market": "0xda5c517dd5b78c80dec8ceb08ca4f466317633487827d7290332b4851cc4a4fa", "price_changes": [{"asset_id": "22488814055465212843401871684243737932656687199587127613893702721105723939237", "price": "0.297", "size": "5", "side": "BUY", "hash": "eba7192bd2ee3e745d5f563d0f356e9973564b67", "best_bid": "0.935", "best_ask": "0.941"}, {"asset_id": "16201530957950630406397949502319734794139620443510795733205872225099141120819", "price": "0.703", "size": "5", "side": "SELL", "hash": "7a5a46890487f44961db7f39a103336472d59573", "best_bid": "0.059", "best_ask": "0.065"}], "timestamp": "1769384134450", "event_type": "price_change"}}
{"_local_timestamp": "2026-01-25T23:35:34.806243+00:00", "data": {"market": "0xda5c517dd5b78c80dec8ceb08ca4f466317633487827d7290332b4851cc4a4fa", "price_changes": [{"asset_id": "16201530957950630406397949502319734794139620443510795733205872225099141120819", "price": "0.053", "size": "370", "side": "BUY", "hash": "e4fbca63763757c3a1007df7a86f0822db8262bf", "best_bid": "0.059", "best_ask": "0.065"}, {"asset_id": "22488814055465212843401871684243737932656687199587127613893702721105723939237", "price": "0.947", "size": "370", "side": "SELL", "hash": "fa2ab15eec382a8e8b90ae655ad98d490f0770c7", "best_bid": "0.935", "best_ask": "0.941"}], "timestamp": "1769384134723", "event_type": "price_change"}}
{"_local_timestamp": "2026-01-25T23:35:35.938372+00:00", "data": {"market": "0xda5c517dd5b78c80dec8ceb08ca4f466317633487827d7290332b4851cc4a4fa", "price_changes": [{"asset_id": "22488814055465212843401871684243737932656687199587127613893702721105723939237", "price": "0.297", "size": "0", "side": "BUY", "hash": "8036d7b28f720b3dc3706039af9d91915490f846", "best_bid": "0.935", "best_ask": "0.941"}, {"asset_id": "16201530957950630406397949502319734794139620443510795733205872225099141120819", "price": "0.703", "size": "0", "side": "SELL", "hash": "0d33b677d7fe8bc5b6cb9a9f109383e3a74566fd", "best_bid": "0.059", "best_ask": "0.065"}], "timestamp": "1769384135874", "event_type": "price_change"}}
{"_local_timestamp": "2026-01-25T23:35:36.263252+00:00", "data": {"market": "0xda5c517dd5b78c80dec8ceb08ca4f466317633487827d7290332b4851cc4a4fa", "price_changes": [{"asset_id": "22488814055465212843401871684243737932656687199587127613893702721105723939237", "price": "0.297", "size": "5", "side": "BUY", "hash": "bb246d69d25f6d709023fd5e30c265a7b68c2b64", "best_bid": "0.935", "best_ask": "0.941"}, {"asset_id": "16201530957950630406397949502319734794139620443510795733205872225099141120819", "price": "0.703", "size": "5", "side": "SELL", "hash": "f626df549e67b7088b46e8467c736284401d88d8", "best_bid": "0.059", "best_ask": "0.065"}], "timestamp": "1769384136188", "event_type": "price_change"}}
{"_local_timestamp": "2026-01-25T23:35:36.671660+00:00", "data": {"market": "0xda5c517dd5b78c80dec8ceb08ca4f466317633487827d7290332b4851cc4a4fa", "price_changes": [{"asset_id": "22488814055465212843401871684243737932656687199587127613893702721105723939237", "price": "0.297", "size": "0", "side": "BUY", "hash": "96112a0e7efd1937f5afcfa554a0ad5a9defe655", "best_bid": "0.935", "best_ask": "0.941"}, {"asset_id": "16201530957950630406397949502319734794139620443510795733205872225099141120819", "price": "0.703", "size": "0", "side": "SELL", "hash": "43a9ba77ff2c5c924dfa7c118d4a96b90d7f7bf9", "best_bid": "0.059", "best_ask": "0.065"}], "timestamp": "1769384136604", "event_type": "price_change"}}
{"_local_timestamp": "2026-01-25T23:35:37.114220+00:00", "data": {"market": "0xda5c517dd5b78c80dec8ceb08ca4f466317633487827d7290332b4851cc4a4fa", "price_changes": [{"asset_id": "22488814055465212843401871684243737932656687199587127613893702721105723939237", "price": "0.297", "size": "5", "side": "BUY", "hash": "139c37e499cb8eb8f01811392e07cbe8ea08e816", "best_bid": "0.935", "best_ask": "0.941"}, {"asset_id": "16201530957950630406397949502319734794139620443510795733205872225099141120819", "price": "0.703", "size": "5", "side": "SELL", "hash": "5363a6aa3207c972e4d9805f825dc3bea01ea4b8", "best_bid": "0.059", "best_ask": "0.065"}], "timestamp": "1769384137038", "event_type": "price_change"}}
{"_local_timestamp": "2026-01-25T23:35:39.074520+00:00", "data": {"market": "0xda5c517dd5b78c80dec8ceb08ca4f466317633487827d7290332b4851cc4a4fa", "price_changes": [{"asset_id": "22488814055465212843401871684243737932656687199587127613893702721105723939237", "price": "0.297", "size": "0", "side": "BUY", "hash": "70d7a3ee9cc78260ba7963ad372d235455f517df", "best_bid": "0.935", "best_ask": "0.941"}, {"asset_id": "16201530957950630406397949502319734794139620443510795733205872225099141120819", "price": "0.703", "size": "0", "side": "SELL", "hash": "eefe6f5752aced7cf89c2af03185673d1f535521", "best_bid": "0.059", "best_ask": "0.065"}], "timestamp": "1769384138999", "event_type": "price_change"}}
{"_local_timestamp": "2026-01-25T23:35:39.178367+00:00", "data": {"market": "0xda5c517dd5b78c80dec8ceb08ca4f466317633487827d7290332b4851cc4a4fa", "price_changes": [{"asset_id": "16201530957950630406397949502319734794139620443510795733205872225099141120819", "price": "0.052", "size": "300", "side": "BUY", "hash": "14dd9925e4d035123340d81ef947adf76c6cd5f5", "best_bid": "0.059", "best_ask": "0.065"}, {"asset_id": "22488814055465212843401871684243737932656687199587127613893702721105723939237", "price": "0.948", "size": "300", "side": "SELL", "hash": "cf1dfcb7162eebf987476682f46ca41f204a222a", "best_bid": "0.935", "best_ask": "0.941"}], "timestamp": "1769384139112", "event_type": "price_change"}}
{"_local_timestamp": "2026-01-25T23:35:39.462270+00:00", "data": {"market": "0xda5c517dd5b78c80dec8ceb08ca4f466317633487827d7290332b4851cc4a4fa", "price_changes": [{"asset_id": "22488814055465212843401871684243737932656687199587127613893702721105723939237", "price": "0.297", "size": "5", "side": "BUY", "hash": "65e8e37d0a83b123051347b41573cb5313e57085", "best_bid": "0.935", "best_ask": "0.941"}, {"asset_id": "16201530957950630406397949502319734794139620443510795733205872225099141120819", "price": "0.703", "size": "5", "side": "SELL", "hash": "402cfb493c2f88a9bec752b005e5905f42acb8dc", "best_bid": "0.059", "best_ask": "0.065"}], "timestamp": "1769384139395", "event_type": "price_change"}}
{"_local_timestamp": "2026-01-25T23:35:41.595533+00:00", "data": {"market": "0xda5c517dd5b78c80dec8ceb08ca4f466317633487827d7290332b4851cc4a4fa", "price_changes": [{"asset_id": "22488814055465212843401871684243737932656687199587127613893702721105723939237", "price": "0.297", "size": "0", "side": "BUY", "hash": "c3e90d4750c64d7f4839b30c08ca51f231b0c502", "best_bid": "0.935", "best_ask": "0.941"}, {"asset_id": "16201530957950630406397949502319734794139620443510795733205872225099141120819", "price": "0.703", "size": "0", "side": "SELL", "hash": "cc8f19a13bfd5eae817de9dc0f0944264088653c", "best_bid": "0.059", "best_ask": "0.065"}], "timestamp": "1769384141527", "event_type": "price_change"}}
{"_local_timestamp": "2026-01-25T23:35:41.914322+00:00", "data": {"market": "0xda5c517dd5b78c80dec8ceb08ca4f466317633487827d7290332b4851cc4a4fa", "price_changes": [{"asset_id": "22488814055465212843401871684243737932656687199587127613893702721105723939237", "price": "0.297", "size": "5", "side": "BUY", "hash": "51f387f946e3e9a0e8ed07e025d8c0bf337aa526", "best_bid": "0.935", "best_ask": "0.941"}, {"asset_id": "16201530957950630406397949502319734794139620443510795733205872225099141120819", "price": "0.703", "size": "5", "side": "SELL", "hash": "b5525473e607c6a552dabe04f3ef04059e0784de", "best_bid": "0.059", "best_ask": "0.065"}], "timestamp": "1769384141849", "event_type": "price_change"}}
{"_local_timestamp": "2026-01-25T23:35:42.933023+00:00", "data": {"market": "0xda5c517dd5b78c80dec8ceb08ca4f466317633487827d7290332b4851cc4a4fa", "price_changes": [{"asset_id": "22488814055465212843401871684243737932656687199587127613893702721105723939237", "price": "0.297", "size": "0", "side": "BUY", "hash": "c57e2d921f32290517d7932a2892a50faf9b03d0", "best_bid": "0.935", "best_ask": "0.941"}, {"asset_id": "16201530957950630406397949502319734794139620443510795733205872225099141120819", "price": "0.703", "size": "0", "side": "SELL", "hash": "2d275afed7c91305e9a01af17a102f83cf4d9468", "best_bid": "0.059", "best_ask": "0.065"}], "timestamp": "1769384142865", "event_type": "price_change"}}
{"_local_timestamp": "2026-01-25T23:35:43.244293+00:00", "data": {"market": "0xda5c517dd5b78c80dec8ceb08ca4f466317633487827d7290332b4851cc4a4fa", "price_changes": [{"asset_id": "22488814055465212843401871684243737932656687199587127613893702721105723939237", "price": "0.297", "size": "5", "side": "BUY", "hash": "6b2228343bb489f483ab9722c6b8f2953a798b73", "best_bid": "0.935", "best_ask": "0.941"}, {"asset_id": "16201530957950630406397949502319734794139620443510795733205872225099141120819", "price": "0.703", "size": "5", "side": "SELL", "hash": "a2a9dd9971d5f33d4a8295e62eb7e698b6bcb6bb", "best_bid": "0.059", "best_ask": "0.065"}], "timestamp": "1769384143178", "event_type": "price_change"}}
{"_local_timestamp": "2026-01-25T23:35:45.296072+00:00", "data": {"market": "0xda5c517dd5b78c80dec8ceb08ca4f466317633487827d7290332b4851cc4a4fa", "price_changes": [{"asset_id": "22488814055465212843401871684243737932656687199587127613893702721105723939237", "price": "0.297", "size": "0", "side": "BUY", "hash": "73caa8617a8cf58a5bf5d72c40ce1f0306a5140f", "best_bid": "0.935", "best_ask": "0.941"}, {"asset_id": "16201530957950630406397949502319734794139620443510795733205872225099141120819", "price": "0.703", "size": "0", "side": "SELL", "hash": "9561c3e84046904b809428645fcec8fdce360b48", "best_bid": "0.059", "best_ask": "0.065"}], "timestamp": "1769384145227", "event_type": "price_change"}}
{"_local_timestamp": "2026-01-25T23:35:45.521147+00:00", "data": {"market": "0xda5c517dd5b78c80dec8ceb08ca4f466317633487827d7290332b4851cc4a4fa", "price_changes": [{"asset_id": "22488814055465212843401871684243737932656687199587127613893702721105723939237", "price": "0.297", "size": "5", "side": "BUY", "hash": "b84b7859eaabe938aa7ba03421d4efc00482bcb6", "best_bid": "0.935", "best_ask": "0.941"}, {"asset_id": "16201530957950630406397949502319734794139620443510795733205872225099141120819", "price": "0.703", "size": "5", "side": "SELL", "hash": "72023574f1ad58bae1c620021857689ed4bf89be", "best_bid": "0.059", "best_ask": "0.065"}], "timestamp": "1769384145454", "event_type": "price_change"}}
{"_local_timestamp": "2026-01-25T23:35:47.432180+00:00", "data": {"market": "0xda5c517dd5b78c80dec8ceb08ca4f466317633487827d7290332b4851cc4a4fa", "price_changes": [{"asset_id": "22488814055465212843401871684243737932656687199587127613893702721105723939237", "price": "0.297", "size": "0", "side": "BUY", "hash": "6c179aaee2d8e5fecab660551f24ea59c06c20cc", "best_bid": "0.935", "best_ask": "0.941"}, {"asset_id": "16201530957950630406397949502319734794139620443510795733205872225099141120819", "price": "0.703", "size": "0", "side": "SELL", "hash": "beb73952f54f504e8d64bcdc1455c6eb91b7f255", "best_bid": "0.059", "best_ask": "0.065"}], "timestamp": "1769384147366", "event_type": "price_change"}}
{"_local_timestamp": "2026-01-25T23:35:47.721733+00:00", "data": {"market": "0xda5c517dd5b78c80dec8ceb08ca4f466317633487827d7290332b4851cc4a4fa", "price_changes": [{"asset_id": "22488814055465212843401871684243737932656687199587127613893702721105723939237", "price": "0.297", "size": "5", "side": "BUY", "hash": "2c2de52c9af2aaea8b2292b772680ba33e4bc7fc", "best_bid": "0.935", "best_ask": "0.941"}, {"asset_id": "16201530957950630406397949502319734794139620443510795733205872225099141120819", "price": "0.703", "size": "5", "side": "SELL", "hash": "ef01f354a7adf7eaf629ad5135749a9f39bc0ff7", "best_bid": "0.059", "best_ask": "0.065"}], "timestamp": "1769384147649", "event_type": "price_change"}}
{"_local_timestamp": "2026-01-25T23:35:49.172287+00:00", "data": {"market": "0xda5c517dd5b78c80dec8ceb08ca4f466317633487827d7290332b4851cc4a4fa", "price_changes": [{"asset_id": "22488814055465212843401871684243737932656687199587127613893702721105723939237", "price": "0.297", "size": "0", "side": "BUY", "hash": "2fc37f1fdac19ae360af8d0e6a8910411bda2f52", "best_bid": "0.935", "best_ask": "0.941"}, {"asset_id": "16201530957950630406397949502319734794139620443510795733205872225099141120819", "price": "0.703", "size": "0", "side": "SELL", "hash": "8f1cf22a8dfab489ce6fb568cb6330e8e8d159ed", "best_bid": "0.059", "best_ask": "0.065"}], "timestamp": "1769384149098", "event_type": "price_change"}}
{"_local_timestamp": "2026-01-25T23:35:49.497119+00:00", "data": {"market": "0xda5c517dd5b78c80dec8ceb08ca4f466317633487827d7290332b4851cc4a4fa", "price_changes": [{"asset_id": "22488814055465212843401871684243737932656687199587127613893702721105723939237", "price": "0.297", "size": "5", "side": "BUY", "hash": "dd9d3773ef00fd4e7c9ed4d482ac2186d48b5a95", "best_bid": "0.935", "best_ask": "0.941"}, {"asset_id": "16201530957950630406397949502319734794139620443510795733205872225099141120819", "price": "0.703", "size": "5", "side": "SELL", "hash": "7f7a9e4ffbfa2d0c34eb91f03c552fc641549482", "best_bid": "0.059", "best_ask": "0.065"}], "timestamp": "1769384149408", "event_type": "price_change"}}
{"_local_timestamp": "2026-01-25T23:35:51.347921+00:00", "data": {"market": "0xda5c517dd5b78c80dec8ceb08ca4f466317633487827d7290332b4851cc4a4fa", "price_changes": [{"asset_id": "22488814055465212843401871684243737932656687199587127613893702721105723939237", "price": "0.297", "size": "0", "side": "BUY", "hash": "f394ca100a5f7517477d414f598ff4c9970fde11", "best_bid": "0.935", "best_ask": "0.941"}, {"asset_id": "16201530957950630406397949502319734794139620443510795733205872225099141120819", "price": "0.703", "size": "0", "side": "SELL", "hash": "68a8ffcc2e2fd41183e2b5bd4248d983c56ffe3b", "best_bid": "0.059", "best_ask": "0.065"}], "timestamp": "1769384151279", "event_type": "price_change"}}
{"_local_timestamp": "2026-01-25T23:35:51.744307+00:00", "data": {"market": "0xda5c517dd5b78c80dec8ceb08ca4f466317633487827d7290332b4851cc4a4fa", "price_changes": [{"asset_id": "22488814055465212843401871684243737932656687199587127613893702721105723939237", "price": "0.297", "size": "5", "side": "BUY", "hash": "286aeec0d7c08eced2a268e165a70b06b2dcc993", "best_bid": "0.935", "best_ask": "0.941"}, {"asset_id": "16201530957950630406397949502319734794139620443510795733205872225099141120819", "price": "0.703", "size": "5", "side": "SELL", "hash": "67155351e4c9f7f8eeb00754fd4799eca3ca1ada", "best_bid": "0.059", "best_ask": "0.065"}], "timestamp": "1769384151678", "event_type": "price_change"}}
{"_local_timestamp": "2026-01-25T23:35:53.824205+00:00", "data": {"market": "0xda5c517dd5b78c80dec8ceb08ca4f466317633487827d7290332b4851cc4a4fa", "price_changes": [{"asset_id": "22488814055465212843401871684243737932656687199587127613893702721105723939237", "price": "0.297", "size": "0", "side": "BUY", "hash": "61fa9f67ef85bbeae0ed6a7643972cd80bdd4c38", "best_bid": "0.935", "best_ask": "0.941"}, {"asset_id": "16201530957950630406397949502319734794139620443510795733205872225099141120819", "price": "0.703", "size": "0", "side": "SELL", "hash": "add4bfb9a547e6363f6c4855fa9563738018b82e", "best_bid": "0.059", "best_ask": "0.065"}], "timestamp": "1769384153753", "event_type": "price_change"}}
{"_local_timestamp": "2026-01-25T23:35:54.310072+00:00", "data": {"market": "0xda5c517dd5b78c80dec8ceb08ca4f466317633487827d7290332b4851cc4a4fa", "price_changes": [{"asset_id": "22488814055465212843401871684243737932656687199587127613893702721105723939237", "price": "0.297", "size": "5", "side": "BUY", "hash": "54c2960bd70b96abf5d0d8588fe40c38f00698b7", "best_bid": "0.935", "best_ask": "0.941"}, {"asset_id": "16201530957950630406397949502319734794139620443510795733205872225099141120819", "price": "0.703", "size": "5", "side": "SELL", "hash": "b43089ff232878960e0709c944fdaafbcde26997", "best_bid": "0.059", "best_ask": "0.065"}], "timestamp": "1769384154242", "event_type": "price_change"}}
{"_local_timestamp": "2026-01-25T23:35:55.001939+00:00", "data": {"market": "0xda5c517dd5b78c80dec8ceb08ca4f466317633487827d7290332b4851cc4a4fa", "price_changes": [{"asset_id": "16201530957950630406397949502319734794139620443510795733205872225099141120819", "price": "0.053", "size": "200", "side": "BUY", "hash": "572f0056b1b12f5572430079fdd181c993482f0e", "best_bid": "0.059", "best_ask": "0.065"}, {"asset_id": "22488814055465212843401871684243737932656687199587127613893702721105723939237", "price": "0.947", "size": "200", "side": "SELL", "hash": "de8a16d6b0d660c2f1eab7bbcf321f5043fbb383", "best_bid": "0.935", "best_ask": "0.941"}], "timestamp": "1769384154923", "event_type": "price_change"}}
{"_local_timestamp": "2026-01-25T23:35:55.002518+00:00", "data": {"market": "0xda5c517dd5b78c80dec8ceb08ca4f466317633487827d7290332b4851cc4a4fa", "price_changes": [{"asset_id": "16201530957950630406397949502319734794139620443510795733205872225099141120819", "price": "0.056", "size": "0", "side": "BUY", "hash": "572f0056b1b12f5572430079fdd181c993482f0e", "best_bid": "0.059", "best_ask": "0.065"}, {"asset_id": "22488814055465212843401871684243737932656687199587127613893702721105723939237", "price": "0.944", "size": "0", "side": "SELL", "hash": "de8a16d6b0d660c2f1eab7bbcf321f5043fbb383", "best_bid": "0.935", "best_ask": "0.941"}], "timestamp": "1769384154923", "event_type": "price_change"}}
{"_local_timestamp": "2026-01-25T23:35:55.002790+00:00", "data": {"market": "0xda5c517dd5b78c80dec8ceb08ca4f466317633487827d7290332b4851cc4a4fa", "price_changes": [{"asset_id": "16201530957950630406397949502319734794139620443510795733205872225099141120819", "price": "0.01", "size": "7712.68", "side": "BUY", "hash": "572f0056b1b12f5572430079fdd181c993482f0e", "best_bid": "0.059", "best_ask": "0.065"}, {"asset_id": "22488814055465212843401871684243737932656687199587127613893702721105723939237", "price": "0.99", "size": "7712.68", "side": "SELL", "hash": "de8a16d6b0d660c2f1eab7bbcf321f5043fbb383", "best_bid": "0.935", "best_ask": "0.941"}], "timestamp": "1769384154923", "event_type": "price_change"}}
{"_local_timestamp": "2026-01-25T23:35:55.003283+00:00", "data": {"market": "0xda5c517dd5b78c80dec8ceb08ca4f466317633487827d7290332b4851cc4a4fa", "price_changes": [{"asset_id": "16201530957950630406397949502319734794139620443510795733205872225099141120819", "price": "0.023", "size": "480", "side": "BUY", "hash": "572f0056b1b12f5572430079fdd181c993482f0e", "best_bid": "0.059", "best_ask": "0.065"}, {"asset_id": "22488814055465212843401871684243737932656687199587127613893702721105723939237", "price": "0.977", "size": "480", "side": "SELL", "hash": "de8a16d6b0d660c2f1eab7bbcf321f5043fbb383", "best_bid": "0.935", "best_ask": "0.941"}], "timestamp": "1769384154923", "event_type": "price_change"}}
{"_local_timestamp": "2026-01-25T23:35:55.003566+00:00", "data": {"market": "0xda5c517dd5b78c80dec8ceb08ca4f466317633487827d7290332b4851cc4a4fa", "price_changes": [{"asset_id": "16201530957950630406397949502319734794139620443510795733205872225099141120819", "price": "0.038", "size": "0", "side": "BUY", "hash": "572f0056b1b12f5572430079fdd181c993482f0e", "best_bid": "0.059", "best_ask": "0.065"}, {"asset_id": "22488814055465212843401871684243737932656687199587127613893702721105723939237", "price": "0.962", "size": "0", "side": "SELL", "hash": "de8a16d6b0d660c2f1eab7bbcf321f5043fbb383", "best_bid": "0.935", "best_ask": "0.941"}], "timestamp": "1769384154923", "event_type": "price_change"}}
{"_local_timestamp": "2026-01-25T23:35:55.040015+00:00", "data": {"market": "0xda5c517dd5b78c80dec8ceb08ca4f466317633487827d7290332b4851cc4a4fa", "price_changes": [{"asset_id": "16201530957950630406397949502319734794139620443510795733205872225099141120819", "price": "0.054", "size": "254", "side": "BUY", "hash": "b33728e4580c02e3e9156ae5fcd0347d18d8464c", "best_bid": "0.059", "best_ask": "0.065"}, {"asset_id": "22488814055465212843401871684243737932656687199587127613893702721105723939237", "price": "0.946", "size": "254", "side": "SELL", "hash": "ccb6f117a4e9e9c2d9ab0f36e4f5263c1dbff72c", "best_bid": "0.935", "best_ask": "0.941"}], "timestamp": "1769384154960", "event_type": "price_change"}}
{"_local_timestamp": "2026-01-25T23:35:55.288589+00:00", "data": {"market": "0xda5c517dd5b78c80dec8ceb08ca4f466317633487827d7290332b4851cc4a4fa", "price_changes": [{"asset_id": "16201530957950630406397949502319734794139620443510795733205872225099141120819", "price": "0.038", "size": "369", "side": "BUY", "hash": "96cadedb3e0fcaef73466366f8976ce6053b1ac4", "best_bid": "0.059", "best_ask": "0.065"}, {"asset_id": "22488814055465212843401871684243737932656687199587127613893702721105723939237", "price": "0.962", "size": "369", "side": "SELL", "hash": "adc4f6ff7bb7aa457d935b6ccc8d47c670bc3208", "best_bid": "0.935", "best_ask": "0.941"}], "timestamp": "1769384155189", "event_type": "price_change"}}
{"_local_timestamp": "2026-01-25T23:35:55.289071+00:00", "data": {"market": "0xda5c517dd5b78c80dec8ceb08ca4f466317633487827d7290332b4851cc4a4fa", "price_changes": [{"asset_id": "16201530957950630406397949502319734794139620443510795733205872225099141120819", "price": "0.023", "size": "1218", "side": "BUY", "hash": "40b0962c2e573ce96998027969cf08aafb9b297f", "best_bid": "0.059", "best_ask": "0.065"}, {"asset_id": "22488814055465212843401871684243737932656687199587127613893702721105723939237", "price": "0.977", "size": "1218", "side": "SELL", "hash": "51dc549c809d9e80d95b6eaa22ee8cfbdad4e2e9", "best_bid": "0.935", "best_ask": "0.941"}], "timestamp": "1769384155192", "event_type": "price_change"}}
{"_local_timestamp": "2026-01-25T23:35:55.289345+00:00", "data": {"market": "0xda5c517dd5b78c80dec8ceb08ca4f466317633487827d7290332b4851cc4a4fa", "price_changes": [{"asset_id": "16201530957950630406397949502319734794139620443510795733205872225099141120819", "price": "0.055", "size": "128", "side": "BUY", "hash": "9e21259a68fca986569554679139b59c8382f30c", "best_bid": "0.059", "best_ask": "0.065"}, {"asset_id": "22488814055465212843401871684243737932656687199587127613893702721105723939237", "price": "0.945", "size": "128", "side": "SELL", "hash": "a04c9204b9943624be0a9ce72c05295dd7003e22", "best_bid": "0.935", "best_ask": "0.941"}], "timestamp": "1769384155195", "event_type": "price_change"}}
{"_local_timestamp": "2026-01-25T23:35:55.289687+00:00", "data": {"market": "0xda5c517dd5b78c80dec8ceb08ca4f466317633487827d7290332b4851cc4a4fa", "price_changes": [{"asset_id": "16201530957950630406397949502319734794139620443510795733205872225099141120819", "price": "0.01", "size": "10712.68", "side": "BUY", "hash": "40cc6f453808f461f9374760117857390f137a02", "best_bid": "0.059", "best_ask": "0.065"}, {"asset_id": "22488814055465212843401871684243737932656687199587127613893702721105723939237", "price": "0.99", "size": "10712.68", "side": "SELL", "hash": "5eb3e72ef174041e1c35e6030edd0ebce2ddfdde", "best_bid": "0.935", "best_ask": "0.941"}], "timestamp": "1769384155197", "event_type": "price_change"}}
{"_local_timestamp": "2026-01-25T23:35:55.291301+00:00", "data": {"market": "0xda5c517dd5b78c80dec8ceb08ca4f466317633487827d7290332b4851cc4a4fa", "price_changes": [{"asset_id": "16201530957950630406397949502319734794139620443510795733205872225099141120819", "price": "0.052", "size": "474", "side": "BUY", "hash": "637d6a6fe3d6331336b238c53c920ba9a919a706", "best_bid": "0.059", "best_ask": "0.065"}, {"asset_id": "22488814055465212843401871684243737932656687199587127613893702721105723939237", "price": "0.948", "size": "474", "side": "SELL", "hash": "09e6c55f3ed3751f8644804beb306db443f5dbd8", "best_bid": "0.935", "best_ask": "0.941"}], "timestamp": "1769384155199", "event_type": "price_change"}}
{"_local_timestamp": "2026-01-25T23:35:55.552326+00:00", "data": {"market": "0xda5c517dd5b78c80dec8ceb08ca4f466317633487827d7290332b4851cc4a4fa", "price_changes": [{"asset_id": "22488814055465212843401871684243737932656687199587127613893702721105723939237", "price": "0.297", "size": "0", "side": "BUY", "hash": "ebad597f81527b607b5bf7d85c57fca0be0f8ed8", "best_bid": "0.935", "best_ask": "0.941"}, {"asset_id": "16201530957950630406397949502319734794139620443510795733205872225099141120819", "price": "0.703", "size": "0", "side": "SELL", "hash": "2cc465e327370af390b03e5049192c73b2926f7c", "best_bid": "0.059", "best_ask": "0.065"}], "timestamp": "1769384155486", "event_type": "price_change"}}
{"_local_timestamp": "2026-01-25T23:35:55.823139+00:00", "data": {"market": "0xda5c517dd5b78c80dec8ceb08ca4f466317633487827d7290332b4851cc4a4fa", "price_changes": [{"asset_id": "16201530957950630406397949502319734794139620443510795733205872225099141120819", "price": "0.052", "size": "374", "side": "BUY", "hash": "4446a5ea8583fb177163c47ea1a94ef3fc93fdf9", "best_bid": "0.059", "best_ask": "0.065"}, {"asset_id": "22488814055465212843401871684243737932656687199587127613893702721105723939237", "price": "0.948", "size": "374", "side": "SELL", "hash": "0a8c9ac31447b787b860e03ce773ac2a71c511ae", "best_bid": "0.935", "best_ask": "0.941"}], "timestamp": "1769384155760", "event_type": "price_change"}}
{"_local_timestamp": "2026-01-25T23:35:55.903045+00:00", "data": {"market": "0xda5c517dd5b78c80dec8ceb08ca4f466317633487827d7290332b4851cc4a4fa", "price_changes": [{"asset_id": "22488814055465212843401871684243737932656687199587127613893702721105723939237", "price": "0.297", "size": "5", "side": "BUY", "hash": "c6906f70d6095118606b6748c4213a081e98c3cb", "best_bid": "0.935", "best_ask": "0.941"}, {"asset_id": "16201530957950630406397949502319734794139620443510795733205872225099141120819", "price": "0.703", "size": "5", "side": "SELL", "hash": "78740c8fd2b0d6a86f5f0cd533e07596dd361290", "best_bid": "0.059", "best_ask": "0.065"}], "timestamp": "1769384155827", "event_type": "price_change"}}
{"_local_timestamp": "2026-01-25T23:35:56.067043+00:00", "data": {"market": "0xda5c517dd5b78c80dec8ceb08ca4f466317633487827d7290332b4851cc4a4fa", "price_changes": [{"asset_id": "16201530957950630406397949502319734794139620443510795733205872225099141120819", "price": "0.013", "size": "3162.11", "side": "BUY", "hash": "9be874e4e218ebcad7e7cbaaef176549b4872fe2", "best_bid": "0.059", "best_ask": "0.065"}, {"asset_id": "22488814055465212843401871684243737932656687199587127613893702721105723939237", "price": "0.987", "size": "3162.11", "side": "SELL", "hash": "abee2133e921676fa1dee0df7f2aad20d08a01a0", "best_bid": "0.935", "best_ask": "0.941"}], "timestamp": "1769384156000", "event_type": "price_change"}}
{"_local_timestamp": "2026-01-25T23:35:56.072591+00:00", "data": {"market": "0xda5c517dd5b78c80dec8ceb08ca4f466317633487827d7290332b4851cc4a4fa", "price_changes": [{"asset_id": "16201530957950630406397949502319734794139620443510795733205872225099141120819", "price": "0.045", "size": "244", "side": "BUY", "hash": "21b0631a7e6237bacce4b859b7efc5763094a7d0", "best_bid": "0.059", "best_ask": "0.065"}, {"asset_id": "22488814055465212843401871684243737932656687199587127613893702721105723939237", "price": "0.955", "size": "244", "side": "SELL", "hash": "83abfd61c9808e535bb0b6a9b374929bdc808dd8", "best_bid": "0.935", "best_ask": "0.941"}], "timestamp": "1769384156001", "event_type": "price_change"}}
{"_local_timestamp": "2026-01-25T23:35:56.073002+00:00", "data": {"market": "0xda5c517dd5b78c80dec8ceb08ca4f466317633487827d7290332b4851cc4a4fa", "price_changes": [{"asset_id": "16201530957950630406397949502319734794139620443510795733205872225099141120819", "price": "0.003", "size": "20671.09", "side": "BUY", "hash": "78be446f982d535e3302400f61236c74cb88fb66", "best_bid": "0.059", "best_ask": "0.065"}, {"asset_id": "22488814055465212843401871684243737932656687199587127613893702721105723939237", "price": "0.997", "size": "20671.09", "side": "SELL", "hash": "eeac23e854f5d71470bb4f6891ef6305e635925b", "best_bid": "0.935", "best_ask": "0.941"}], "timestamp": "1769384156003", "event_type": "price_change"}}
{"_local_timestamp": "2026-01-25T23:35:56.073901+00:00", "data": {"market": "0xda5c517dd5b78c80dec8ceb08ca4f466317633487827d7290332b4851cc4a4fa", "price_changes": [{"asset_id": "16201530957950630406397949502319734794139620443510795733205872225099141120819", "price": "0.01", "size": "10012.68", "side": "BUY", "hash": "5643575ff68b740f1c4328c82d39adf0a3fbe40c", "best_bid": "0.059", "best_ask": "0.065"}, {"asset_id": "22488814055465212843401871684243737932656687199587127613893702721105723939237", "price": "0.99", "size": "10012.68", "side": "SELL", "hash": "a54ffccf645c5031ff023b87d541889d54a945b5", "best_bid": "0.935", "best_ask": "0.941"}], "timestamp": "1769384156004", "event_type": "price_change"}}
{"_local_timestamp": "2026-01-25T23:35:56.074178+00:00", "data": {"market": "0xda5c517dd5b78c80dec8ceb08ca4f466317633487827d7290332b4851cc4a4fa", "price_changes": [{"asset_id": "16201530957950630406397949502319734794139620443510795733205872225099141120819", "price": "0.031", "size": "581", "side": "BUY", "hash": "5643575ff68b740f1c4328c82d39adf0a3fbe40c", "best_bid": "0.059", "best_ask": "0.065"}, {"asset_id": "22488814055465212843401871684243737932656687199587127613893702721105723939237", "price": "0.969", "size": "581", "side": "SELL", "hash": "a54ffccf645c5031ff023b87d541889d54a945b5", "best_bid": "0.935", "best_ask": "0.941"}], "timestamp": "1769384156004", "event_type": "price_change"}}
{"_local_timestamp": "2026-01-25T23:35:56.074444+00:00", "data": {"market": "0xda5c517dd5b78c80dec8ceb08ca4f466317633487827d7290332b4851cc4a4fa", "price_changes": [{"asset_id": "16201530957950630406397949502319734794139620443510795733205872225099141120819", "price": "0.023", "size": "1173", "side": "BUY", "hash": "2063ad73dbd3ee56cbf9d4394feea56ec8fe496f", "best_bid": "0.059", "best_ask": "0.065"}, {"asset_id": "22488814055465212843401871684243737932656687199587127613893702721105723939237", "price": "0.977", "size": "1173", "side": "SELL", "hash": "3c16100dbd423ef3ddf43a98311234e4b3e93bf3", "best_bid": "0.935", "best_ask": "0.941"}], "timestamp": "1769384156005", "event_type": "price_change"}}
{"_local_timestamp": "2026-01-25T23:35:56.076632+00:00", "data": {"market": "0xda5c517dd5b78c80dec8ceb08ca4f466317633487827d7290332b4851cc4a4fa", "price_changes": [{"asset_id": "16201530957950630406397949502319734794139620443510795733205872225099141120819", "price": "0.034", "size": "442", "side": "BUY", "hash": "2063ad73dbd3ee56cbf9d4394feea56ec8fe496f", "best_bid": "0.059", "best_ask": "0.065"}, {"asset_id": "22488814055465212843401871684243737932656687199587127613893702721105723939237", "price": "0.966", "size": "442", "side": "SELL", "hash": "3c16100dbd423ef3ddf43a98311234e4b3e93bf3", "best_bid": "0.935", "best_ask": "0.941"}], "timestamp": "1769384156005", "event_type": "price_change"}}
{"_local_timestamp": "2026-01-25T23:35:56.097574+00:00", "data": {"market": "0xda5c517dd5b78c80dec8ceb08ca4f466317633487827d7290332b4851cc4a4fa", "price_changes": [{"asset_id": "16201530957950630406397949502319734794139620443510795733205872225099141120819", "price": "0.054", "size": "200", "side": "BUY", "hash": "9b6273918c6ce00b502a2440f87259e2ba5e8e4c", "best_bid": "0.059", "best_ask": "0.065"}, {"asset_id": "22488814055465212843401871684243737932656687199587127613893702721105723939237", "price": "0.946", "size": "200", "side": "SELL", "hash": "d853041fc1bd03467d83d7be370052bb3cdd2c88", "best_bid": "0.935", "best_ask": "0.941"}], "timestamp": "1769384156030", "event_type": "price_change"}}
{"_local_timestamp": "2026-01-25T23:35:56.455752+00:00", "data": {"market": "0xda5c517dd5b78c80dec8ceb08ca4f466317633487827d7290332b4851cc4a4fa", "price_changes": [{"asset_id": "22488814055465212843401871684243737932656687199587127613893702721105723939237", "price": "0.281", "size": "150", "side": "BUY", "hash": "f27f1e618d5b7cde245ade6cbcdd7c9a023f1b2e", "best_bid": "0.935", "best_ask": "0.941"}, {"asset_id": "16201530957950630406397949502319734794139620443510795733205872225099141120819", "price": "0.719", "size": "150", "side": "SELL", "hash": "80669b279286e8f7c3c4ecc28b767eeb566fa025", "best_bid": "0.059", "best_ask": "0.065"}], "timestamp": "1769384156295", "event_type": "price_change"}}
{"_local_timestamp": "2026-01-25T23:35:56.456135+00:00", "data": {"market": "0xda5c517dd5b78c80dec8ceb08ca4f466317633487827d7290332b4851cc4a4fa", "price_changes": [{"asset_id": "22488814055465212843401871684243737932656687199587127613893702721105723939237", "price": "0.25", "size": "1350", "side": "BUY", "hash": "f27f1e618d5b7cde245ade6cbcdd7c9a023f1b2e", "best_bid": "0.935", "best_ask": "0.941"}, {"asset_id": "16201530957950630406397949502319734794139620443510795733205872225099141120819", "price": "0.75", "size": "1350", "side": "SELL", "hash": "80669b279286e8f7c3c4ecc28b767eeb566fa025", "best_bid": "0.059", "best_ask": "0.065"}], "timestamp": "1769384156295", "event_type": "price_change"}}
{"_local_timestamp": "2026-01-25T23:35:56.876063+00:00", "data": {"market": "0xda5c517dd5b78c80dec8ceb08ca4f466317633487827d7290332b4851cc4a4fa", "price_changes": [{"asset_id": "22488814055465212843401871684243737932656687199587127613893702721105723939237", "price": "0.28", "size": "142.85", "side": "BUY", "hash": "d35afefb91bdd50ff3b6051ef13bd3c03f95e681", "best_bid": "0.935", "best_ask": "0.941"}, {"asset_id": "16201530957950630406397949502319734794139620443510795733205872225099141120819", "price": "0.72", "size": "142.85", "side": "SELL", "hash": "5e36ea3dfa3414bbbb67abd48fdde2e5da471d8d", "best_bid": "0.059", "best_ask": "0.065"}], "timestamp": "1769384156747", "event_type": "price_change"}}
{"_local_timestamp": "2026-01-25T23:35:56.911276+00:00", "data": {"market": "0xda5c517dd5b78c80dec8ceb08ca4f466317633487827d7290332b4851cc4a4fa", "price_changes": [{"asset_id": "22488814055465212843401871684243737932656687199587127613893702721105723939237", "price": "0.252", "size": "100", "side": "BUY", "hash": "0e2c7e99af69ba03c228a0e4bb167c934839e80f", "best_bid": "0.935", "best_ask": "0.941"}, {"asset_id": "16201530957950630406397949502319734794139620443510795733205872225099141120819", "price": "0.748", "size": "100", "side": "SELL", "hash": "de215baf9e2329b9443fc5e21b2f7c88df0e4d87", "best_bid": "0.059", "best_ask": "0.065"}], "timestamp": "1769384156770", "event_type": "price_change"}}
{"_local_timestamp": "2026-01-25T23:35:57.908996+00:00", "data": {"market": "0xda5c517dd5b78c80dec8ceb08ca4f466317633487827d7290332b4851cc4a4fa", "price_changes": [{"asset_id": "22488814055465212843401871684243737932656687199587127613893702721105723939237", "price": "0.297", "size": "0", "side": "BUY", "hash": "4c70e36a95f511f6a2a8184f0964e22901452985", "best_bid": "0.935", "best_ask": "0.941"}, {"asset_id": "16201530957950630406397949502319734794139620443510795733205872225099141120819", "price": "0.703", "size": "0", "side": "SELL", "hash": "a8d73e8b15614f4d01dc46cfcb19581707fc888d", "best_bid": "0.059", "best_ask": "0.065"}], "timestamp": "1769384157805", "event_type": "price_change"}}
{"_local_timestamp": "2026-01-25T23:35:58.180673+00:00", "data": {"market": "0xda5c517dd5b78c80dec8ceb08ca4f466317633487827d7290332b4851cc4a4fa", "price_changes": [{"asset_id": "22488814055465212843401871684243737932656687199587127613893702721105723939237", "price": "0.251", "size": "0", "side": "BUY", "hash": "1b1e92b4e16f4203845fa6cd18d1283f8acabc14", "best_bid": "0.935", "best_ask": "0.941"}, {"asset_id": "16201530957950630406397949502319734794139620443510795733205872225099141120819", "price": "0.749", "size": "0", "side": "SELL", "hash": "9789662f075b188b77980d98d875cdc9b9d21200", "best_bid": "0.059", "best_ask": "0.065"}], "timestamp": "1769384158071", "event_type": "price_change"}}
{"_local_timestamp": "2026-01-25T23:35:58.311887+00:00", "data": {"market": "0xda5c517dd5b78c80dec8ceb08ca4f466317633487827d7290332b4851cc4a4fa", "price_changes": [{"asset_id": "22488814055465212843401871684243737932656687199587127613893702721105723939237", "price": "0.297", "size": "5", "side": "BUY", "hash": "f72a43048129af2f5c1e67697b22cad48433c4d5", "best_bid": "0.935", "best_ask": "0.941"}, {"asset_id": "16201530957950630406397949502319734794139620443510795733205872225099141120819", "price": "0.703", "size": "5", "side": "SELL", "hash": "e78d77483f546a2bdfb08c1bef2edea2080033b2", "best_bid": "0.059", "best_ask": "0.065"}], "timestamp": "1769384158241", "event_type": "price_change"}}
{"_local_timestamp": "2026-01-25T23:35:59.166870+00:00", "data": {"market": "0xda5c517dd5b78c80dec8ceb08ca4f466317633487827d7290332b4851cc4a4fa", "price_changes": [{"asset_id": "16201530957950630406397949502319734794139620443510795733205872225099141120819", "price": "0.052", "size": "474", "side": "BUY", "hash": "ba6239a0a747fd81a53dc36ac5351c492304888f", "best_bid": "0.059", "best_ask": "0.065"}, {"asset_id": "22488814055465212843401871684243737932656687199587127613893702721105723939237", "price": "0.948", "size": "474", "side": "SELL", "hash": "adcd51ec8b159b6359de24766f27937c85042619", "best_bid": "0.935", "best_ask": "0.941"}], "timestamp": "1769384159035", "event_type": "price_change"}}
{"_local_timestamp": "2026-01-25T23:36:00.349048+00:00", "data": {"market": "0xda5c517dd5b78c80dec8ceb08ca4f466317633487827d7290332b4851cc4a4fa", "price_changes": [{"asset_id": "22488814055465212843401871684243737932656687199587127613893702721105723939237", "price": "0.297", "size": "0", "side": "BUY", "hash": "f836a8994f3e0eae9ec3753c96241bf26b67c161", "best_bid": "0.935", "best_ask": "0.941"}, {"asset_id": "16201530957950630406397949502319734794139620443510795733205872225099141120819", "price": "0.703", "size": "0", "side": "SELL", "hash": "e4756237176e7988fa0836624fab43ab7b2e31dc", "best_bid": "0.059", "best_ask": "0.065"}], "timestamp": "1769384160280", "event_type": "price_change"}}
{"_local_timestamp": "2026-01-25T23:36:00.694241+00:00", "data": {"market": "0xda5c517dd5b78c80dec8ceb08ca4f466317633487827d7290332b4851cc4a4fa", "price_changes": [{"asset_id": "22488814055465212843401871684243737932656687199587127613893702721105723939237", "price": "0.297", "size": "5", "side": "BUY", "hash": "403246309134b7fcbf0ba95d6d7c25bfd33d9f06", "best_bid": "0.935", "best_ask": "0.941"}, {"asset_id": "16201530957950630406397949502319734794139620443510795733205872225099141120819", "price": "0.703", "size": "5", "side": "SELL", "hash": "76d56df27f648395b014d83fe6b4e2bf783e65b8", "best_bid": "0.059", "best_ask": "0.065"}], "timestamp": "1769384160624", "event_type": "price_change"}}
{"_local_timestamp": "2026-01-25T23:36:02.905628+00:00", "data": {"market": "0xda5c517dd5b78c80dec8ceb08ca4f466317633487827d7290332b4851cc4a4fa", "price_changes": [{"asset_id": "22488814055465212843401871684243737932656687199587127613893702721105723939237", "price": "0.297", "size": "0", "side": "BUY", "hash": "7b5c11e4ae9b25193c7aed1c90d49301ad3b6c2a", "best_bid": "0.935", "best_ask": "0.941"}, {"asset_id": "16201530957950630406397949502319734794139620443510795733205872225099141120819", "price": "0.703", "size": "0", "side": "SELL", "hash": "fa10779b702b43683a797cff3cb6018c30241839", "best_bid": "0.059", "best_ask": "0.065"}], "timestamp": "1769384162829", "event_type": "price_change"}}
{"_local_timestamp": "2026-01-25T23:36:03.313303+00:00", "data": {"market": "0xda5c517dd5b78c80dec8ceb08ca4f466317633487827d7290332b4851cc4a4fa", "price_changes": [{"asset_id": "22488814055465212843401871684243737932656687199587127613893702721105723939237", "price": "0.297", "size": "5", "side": "BUY", "hash": "f2796580827184d462cfe679c1ac366a52318be3", "best_bid": "0.935", "best_ask": "0.941"}, {"asset_id": "16201530957950630406397949502319734794139620443510795733205872225099141120819", "price": "0.703", "size": "5", "side": "SELL", "hash": "8061d13828113d7beaa02913860dc7754a03fe8a", "best_bid": "0.059", "best_ask": "0.065"}], "timestamp": "1769384163218", "event_type": "price_change"}}
{"_local_timestamp": "2026-01-25T23:36:03.602325+00:00", "data": {"market": "0xda5c517dd5b78c80dec8ceb08ca4f466317633487827d7290332b4851cc4a4fa", "price_changes": [{"asset_id": "16201530957950630406397949502319734794139620443510795733205872225099141120819", "price": "0.058", "size": "0", "side": "BUY", "hash": "9aefe401e76f158d29e161f5265970a09e7da78c", "best_bid": "0.059", "best_ask": "0.065"}, {"asset_id": "22488814055465212843401871684243737932656687199587127613893702721105723939237", "price": "0.942", "size": "0", "side": "SELL", "hash": "a6331c569042c40afe5e1fcd49668491f9de34cc", "best_bid": "0.935", "best_ask": "0.941"}], "timestamp": "1769384163538", "event_type": "price_change"}}
{"_local_timestamp": "2026-01-25T23:36:03.634775+00:00", "data": {"market": "0xda5c517dd5b78c80dec8ceb08ca4f466317633487827d7290332b4851cc4a4fa", "price_changes": [{"asset_id": "16201530957950630406397949502319734794139620443510795733205872225099141120819", "price": "0.054", "size": "254", "side": "BUY", "hash": "3dc7187c13441a5877c94321a80eaf9ee1cd6b4b", "best_bid": "0.059", "best_ask": "0.065"}, {"asset_id": "22488814055465212843401871684243737932656687199587127613893702721105723939237", "price": "0.946", "size": "254", "side": "SELL", "hash": "474918397d4c547a2c7f7f0a578655e429d95056", "best_bid": "0.935", "best_ask": "0.941"}], "timestamp": "1769384163563", "event_type": "price_change"}}
{"_local_timestamp": "2026-01-25T23:36:04.639262+00:00", "data": {"market": "0xda5c517dd5b78c80dec8ceb08ca4f466317633487827d7290332b4851cc4a4fa", "price_changes": [{"asset_id": "22488814055465212843401871684243737932656687199587127613893702721105723939237", "price": "0.297", "size": "0", "side": "BUY", "hash": "3ccf89c4df74320d50808c93bc231f0b52e5cd0d", "best_bid": "0.935", "best_ask": "0.941"}, {"asset_id": "16201530957950630406397949502319734794139620443510795733205872225099141120819", "price": "0.703", "size": "0", "side": "SELL", "hash": "fd97b4d55da785dc707a85ebc3740402f6fed203", "best_bid": "0.059", "best_ask": "0.065"}], "timestamp": "1769384164566", "event_type": "price_change"}}
{"_local_timestamp": "2026-01-25T23:36:04.986684+00:00", "data": {"market": "0xda5c517dd5b78c80dec8ceb08ca4f466317633487827d7290332b4851cc4a4fa", "price_changes": [{"asset_id": "22488814055465212843401871684243737932656687199587127613893702721105723939237", "price": "0.297", "size": "5", "side": "BUY", "hash": "61c124d6d6089ac11c1976e8e03b7b2e6bd6160d", "best_bid": "0.935", "best_ask": "0.941"}, {"asset_id": "16201530957950630406397949502319734794139620443510795733205872225099141120819", "price": "0.703", "size": "5", "side": "SELL", "hash": "34df0423515ee0e149c3718b181592644a98ac6c", "best_bid": "0.059", "best_ask": "0.065"}], "timestamp": "1769384164919", "event_type": "price_change"}}
{"_local_timestamp": "2026-01-25T23:36:05.545726+00:00", "data": {"market": "0xda5c517dd5b78c80dec8ceb08ca4f466317633487827d7290332b4851cc4a4fa", "price_changes": [{"asset_id": "16201530957950630406397949502319734794139620443510795733205872225099141120819", "price": "0.052", "size": "374", "side": "BUY", "hash": "1fd192b0c17056620805bf02803e2e826641b939", "best_bid": "0.059", "best_ask": "0.065"}, {"asset_id": "22488814055465212843401871684243737932656687199587127613893702721105723939237", "price": "0.948", "size": "374", "side": "SELL", "hash": "15b6c6b94fe6b34c443ef210c29be0328874c822", "best_bid": "0.935", "best_ask": "0.941"}], "timestamp": "1769384165479", "event_type": "price_change"}}
{"_local_timestamp": "2026-01-25T23:36:06.139238+00:00", "data": {"market": "0xda5c517dd5b78c80dec8ceb08ca4f466317633487827d7290332b4851cc4a4fa", "price_changes": [{"asset_id": "16201530957950630406397949502319734794139620443510795733205872225099141120819", "price": "0.031", "size": "742", "side": "BUY", "hash": "58f883487889b19a0c0a1a3c92882730daff21e3", "best_bid": "0.059", "best_ask": "0.065"}, {"asset_id": "22488814055465212843401871684243737932656687199587127613893702721105723939237", "price": "0.969", "size": "742", "side": "SELL", "hash": "5cb56c860bb974618de4a1e6462658b9a85ffd7f", "best_bid": "0.935", "best_ask": "0.941"}], "timestamp": "1769384166053", "event_type": "price_change"}}
{"_local_timestamp": "2026-01-25T23:36:06.139630+00:00", "data": {"market": "0xda5c517dd5b78c80dec8ceb08ca4f466317633487827d7290332b4851cc4a4fa", "price_changes": [{"asset_id": "16201530957950630406397949502319734794139620443510795733205872225099141120819", "price": "0.013", "size": "3469.11", "side": "BUY", "hash": "d54a7fa2e7f2d4b5e06f019ec6a689834485bd2f", "best_bid": "0.059", "best_ask": "0.065"}, {"asset_id": "22488814055465212843401871684243737932656687199587127613893702721105723939237", "price": "0.987", "size": "3469.11", "side": "SELL", "hash": "a90b0b8cd1f533085602f17766288d0a75d7f49c", "best_bid": "0.935", "best_ask": "0.941"}], "timestamp": "1769384166054", "event_type": "price_change"}}
{"_local_timestamp": "2026-01-25T23:36:06.139880+00:00", "data": {"market": "0xda5c517dd5b78c80dec8ceb08ca4f466317633487827d7290332b4851cc4a4fa", "price_changes": [{"asset_id": "16201530957950630406397949502319734794139620443510795733205872225099141120819", "price": "0.034", "size": "530", "side": "BUY", "hash": "dfb792880580660b6161d7e8079765e7edf8a8a9", "best_bid": "0.059", "best_ask": "0.065"}, {"asset_id": "22488814055465212843401871684243737932656687199587127613893702721105723939237", "price": "0.966", "size": "530", "side": "SELL", "hash": "d0bfd7924fbfb114701e80d145911abe8c667dd4", "best_bid": "0.935", "best_ask": "0.941"}], "timestamp": "1769384166055", "event_type": "price_change"}}
{"_local_timestamp": "2026-01-25T23:36:06.140157+00:00", "data": {"market": "0xda5c517dd5b78c80dec8ceb08ca4f466317633487827d7290332b4851cc4a4fa", "price_changes": [{"asset_id": "16201530957950630406397949502319734794139620443510795733205872225099141120819", "price": "0.003", "size": "23672.09", "side": "BUY", "hash": "8afae724431db4285c4180c7176b374226e73495", "best_bid": "0.059", "best_ask": "0.065"}, {"asset_id": "22488814055465212843401871684243737932656687199587127613893702721105723939237", "price": "0.997", "size": "23672.09", "side": "SELL", "hash": "6bdc23a8801e4b96a7d05e1e2dcb7d37506e683f", "best_bid": "0.935", "best_ask": "0.941"}], "timestamp": "1769384166055", "event_type": "price_change"}}
{"_local_timestamp": "2026-01-25T23:36:06.142155+00:00", "data": {"market": "0xda5c517dd5b78c80dec8ceb08ca4f466317633487827d7290332b4851cc4a4fa", "price_changes": [{"asset_id": "16201530957950630406397949502319734794139620443510795733205872225099141120819", "price": "0.01", "size": "10712.68", "side": "BUY", "hash": "324b11acffadbce996a0c743cdd018816de81b1c", "best_bid": "0.059", "best_ask": "0.065"}, {"asset_id": "22488814055465212843401871684243737932656687199587127613893702721105723939237", "price": "0.99", "size": "10712.68", "side": "SELL", "hash": "7c0ee431362de548faa81b25d0940b32f50f9b84", "best_bid": "0.935", "best_ask": "0.941"}], "timestamp": "1769384166056", "event_type": "price_change"}}
{"_local_timestamp": "2026-01-25T23:36:06.142468+00:00", "data": {"market": "0xda5c517dd5b78c80dec8ceb08ca4f466317633487827d7290332b4851cc4a4fa", "price_changes": [{"asset_id": "16201530957950630406397949502319734794139620443510795733205872225099141120819", "price": "0.023", "size": "1218", "side": "BUY", "hash": "f1f837c95873077f4ee01339cfd518f299fc42a5", "best_bid": "0.059", "best_ask": "0.065"}, {"asset_id": "22488814055465212843401871684243737932656687199587127613893702721105723939237", "price": "0.977", "size": "1218", "side": "SELL", "hash": "df6fd4b055ad7978d174dea6d3e95cbecfa5c89c", "best_bid": "0.935", "best_ask": "0.941"}], "timestamp": "1769384166057", "event_type": "price_change"}}
{"_local_timestamp": "2026-01-25T23:36:06.142823+00:00", "data": {"market": "0xda5c517dd5b78c80dec8ceb08ca4f466317633487827d7290332b4851cc4a4fa", "price_changes": [{"asset_id": "16201530957950630406397949502319734794139620443510795733205872225099141120819", "price": "0.045", "size": "267", "side": "BUY", "hash": "74c4e1dbc007e559b641babeb0961e1a18514d92", "best_bid": "0.059", "best_ask": "0.065"}, {"asset_id": "22488814055465212843401871684243737932656687199587127613893702721105723939237", "price": "0.955", "size": "267", "side": "SELL", "hash": "272f5b7383f65e612d11192b87dde62d461c9ce4", "best_bid": "0.935", "best_ask": "0.941"}], "timestamp": "1769384166058", "event_type": "price_change"}}
{"_local_timestamp": "2026-01-25T23:36:06.825393+00:00", "data": {"market": "0xda5c517dd5b78c80dec8ceb08ca4f466317633487827d7290332b4851cc4a4fa", "price_changes": [{"asset_id": "22488814055465212843401871684243737932656687199587127613893702721105723939237", "price": "0.297", "size": "0", "side": "BUY", "hash": "e56fa9676d68ee1983b05058be4d068d450a48c9", "best_bid": "0.935", "best_ask": "0.941"}, {"asset_id": "16201530957950630406397949502319734794139620443510795733205872225099141120819", "price": "0.703", "size": "0", "side": "SELL", "hash": "1f9993d6e3a954b2b5e33d55513967098f5767d1", "best_bid": "0.059", "best_ask": "0.065"}], "timestamp": "1769384166738", "event_type": "price_change"}}
{"_local_timestamp": "2026-01-25T23:36:07.102013+00:00", "data": {"market": "0xda5c517dd5b78c80dec8ceb08ca4f466317633487827d7290332b4851cc4a4fa", "price_changes": [{"asset_id": "22488814055465212843401871684243737932656687199587127613893702721105723939237", "price": "0.297", "size": "5", "side": "BUY", "hash": "45a79e2163bc9582bf3bd21a12a6a6b47ee86f5b", "best_bid": "0.935", "best_ask": "0.941"}, {"asset_id": "16201530957950630406397949502319734794139620443510795733205872225099141120819", "price": "0.703", "size": "5", "side": "SELL", "hash": "b0a6b0bdec77ac0f6a2ab5ee93e828b50c2e65c6", "best_bid": "0.059", "best_ask": "0.065"}], "timestamp": "1769384167021", "event_type": "price_change"}}
{"_local_timestamp": "2026-01-25T23:36:09.078150+00:00", "data": {"market": "0xda5c517dd5b78c80dec8ceb08ca4f466317633487827d7290332b4851cc4a4fa", "price_changes": [{"asset_id": "22488814055465212843401871684243737932656687199587127613893702721105723939237", "price": "0.297", "size": "0", "side": "BUY", "hash": "3d0f072d097faa6deff1294db1e761b526dff667", "best_bid": "0.935", "best_ask": "0.941"}, {"asset_id": "16201530957950630406397949502319734794139620443510795733205872225099141120819", "price": "0.703", "size": "0", "side": "SELL", "hash": "2eff1ad1d7d692b9e3b450f151b0be5679dc94fd", "best_bid": "0.059", "best_ask": "0.065"}], "timestamp": "1769384169000", "event_type": "price_change"}}
{"_local_timestamp": "2026-01-25T23:36:09.426951+00:00", "data": {"market": "0xda5c517dd5b78c80dec8ceb08ca4f466317633487827d7290332b4851cc4a4fa", "price_changes": [{"asset_id": "22488814055465212843401871684243737932656687199587127613893702721105723939237", "price": "0.297", "size": "5", "side": "BUY", "hash": "0c47cab3cbaf955aa2d3463643143968f43280ac", "best_bid": "0.935", "best_ask": "0.941"}, {"asset_id": "16201530957950630406397949502319734794139620443510795733205872225099141120819", "price": "0.703", "size": "5", "side": "SELL", "hash": "54ccbe846bba67961b19b75f157bfa1f559ba929", "best_bid": "0.059", "best_ask": "0.065"}], "timestamp": "1769384169360", "event_type": "price_change"}}
{"_local_timestamp": "2026-01-25T23:36:09.537640+00:00", "data": {"market": "0xda5c517dd5b78c80dec8ceb08ca4f466317633487827d7290332b4851cc4a4fa", "price_changes": [{"asset_id": "16201530957950630406397949502319734794139620443510795733205872225099141120819", "price": "0.051", "size": "9221.81", "side": "BUY", "hash": "84d60bb964edbd1660223dcb82d09eb9759e48b4", "best_bid": "0.059", "best_ask": "0.065"}, {"asset_id": "22488814055465212843401871684243737932656687199587127613893702721105723939237", "price": "0.949", "size": "9221.81", "side": "SELL", "hash": "d7c95e4b69a68e80258a3f6654aa3f6883c6b4d7", "best_bid": "0.935", "best_ask": "0.941"}], "timestamp": "1769384169470", "event_type": "price_change"}}
{"_local_timestamp": "2026-01-25T23:36:11.647217+00:00", "data": {"market": "0xda5c517dd5b78c80dec8ceb08ca4f466317633487827d7290332b4851cc4a4fa", "price_changes": [{"asset_id": "22488814055465212843401871684243737932656687199587127613893702721105723939237", "price": "0.297", "size": "0", "side": "BUY", "hash": "fb0b01e3633fc5e99f7ef7c1a2d74a468bc1ad1b", "best_bid": "0.935", "best_ask": "0.941"}, {"asset_id": "16201530957950630406397949502319734794139620443510795733205872225099141120819", "price": "0.703", "size": "0", "side": "SELL", "hash": "a80e25d7f5540e46228e7af832d3e6c15cd5795c", "best_bid": "0.059", "best_ask": "0.065"}], "timestamp": "1769384171571", "event_type": "price_change"}}
{"_local_timestamp": "2026-01-25T23:36:12.116010+00:00", "data": {"market": "0xda5c517dd5b78c80dec8ceb08ca4f466317633487827d7290332b4851cc4a4fa", "price_changes": [{"asset_id": "22488814055465212843401871684243737932656687199587127613893702721105723939237", "price": "0.297", "size": "5", "side": "BUY", "hash": "1d83538e4f22b064e61c1b33c6a2d81a309084f8", "best_bid": "0.935", "best_ask": "0.941"}, {"asset_id": "16201530957950630406397949502319734794139620443510795733205872225099141120819", "price": "0.703", "size": "5", "side": "SELL", "hash": "0e609af1dd299e2b0bf499475c1c85833981cbd4", "best_bid": "0.059", "best_ask": "0.065"}], "timestamp": "1769384172006", "event_type": "price_change"}}
{"_local_timestamp": "2026-01-25T23:36:14.308102+00:00", "data": {"market": "0xda5c517dd5b78c80dec8ceb08ca4f466317633487827d7290332b4851cc4a4fa", "price_changes": [{"asset_id": "22488814055465212843401871684243737932656687199587127613893702721105723939237", "price": "0.297", "size": "0", "side": "BUY", "hash": "bef92eec20c9064bf74fd1b55de3195ac0eac35d", "best_bid": "0.935", "best_ask": "0.941"}, {"asset_id": "16201530957950630406397949502319734794139620443510795733205872225099141120819", "price": "0.703", "size": "0", "side": "SELL", "hash": "baa48e1889f83d63813f7856c6e098f7f5721066", "best_bid": "0.059", "best_ask": "0.065"}], "timestamp": "1769384174182", "event_type": "price_change"}}
{"_local_timestamp": "2026-01-25T23:36:14.600868+00:00", "data": {"market": "0xda5c517dd5b78c80dec8ceb08ca4f466317633487827d7290332b4851cc4a4fa", "price_changes": [{"asset_id": "22488814055465212843401871684243737932656687199587127613893702721105723939237", "price": "0.297", "size": "5", "side": "BUY", "hash": "d1706068c1f28f1cbc8293fede4a6f1c5b862bd0", "best_bid": "0.935", "best_ask": "0.941"}, {"asset_id": "16201530957950630406397949502319734794139620443510795733205872225099141120819", "price": "0.703", "size": "5", "side": "SELL", "hash": "4417e7d253247ea1becce8eee6f129923b1df641", "best_bid": "0.059", "best_ask": "0.065"}], "timestamp": "1769384174534", "event_type": "price_change"}}
{"_local_timestamp": "2026-01-25T23:36:16.440194+00:00", "data": {"market": "0xda5c517dd5b78c80dec8ceb08ca4f466317633487827d7290332b4851cc4a4fa", "price_changes": [{"asset_id": "22488814055465212843401871684243737932656687199587127613893702721105723939237", "price": "0.297", "size": "0", "side": "BUY", "hash": "1d2455eea2da783aeff26c0cec95c86c763068b9", "best_bid": "0.935", "best_ask": "0.941"}, {"asset_id": "16201530957950630406397949502319734794139620443510795733205872225099141120819", "price": "0.703", "size": "0", "side": "SELL", "hash": "67938b19e735c5bd0eaed859c2abf141001ae9c5", "best_bid": "0.059", "best_ask": "0.065"}], "timestamp": "1769384176372", "event_type": "price_change"}}
{"_local_timestamp": "2026-01-25T23:36:16.784383+00:00", "data": {"market": "0xda5c517dd5b78c80dec8ceb08ca4f466317633487827d7290332b4851cc4a4fa", "price_changes": [{"asset_id": "22488814055465212843401871684243737932656687199587127613893702721105723939237", "price": "0.297", "size": "5", "side": "BUY", "hash": "2250b34fe9e96b31cd8bc2b2ae32538b1b60a588", "best_bid": "0.935", "best_ask": "0.941"}, {"asset_id": "16201530957950630406397949502319734794139620443510795733205872225099141120819", "price": "0.703", "size": "5", "side": "SELL", "hash": "1a6b50538dcdba8181750c044676eed7d2f7db69", "best_bid": "0.059", "best_ask": "0.065"}], "timestamp": "1769384176714", "event_type": "price_change"}}
{"_local_timestamp": "2026-01-25T23:36:19.014947+00:00", "data": {"market": "0xda5c517dd5b78c80dec8ceb08ca4f466317633487827d7290332b4851cc4a4fa", "price_changes": [{"asset_id": "22488814055465212843401871684243737932656687199587127613893702721105723939237", "price": "0.297", "size": "0", "side": "BUY", "hash": "d4e1cf1fd8bfdb0ed1c9ffbcc22951df9a73e1e0", "best_bid": "0.935", "best_ask": "0.941"}, {"asset_id": "16201530957950630406397949502319734794139620443510795733205872225099141120819", "price": "0.703", "size": "0", "side": "SELL", "hash": "0a3c3aa5f399a9eddf8280575a007d013d7217ed", "best_bid": "0.059", "best_ask": "0.065"}], "timestamp": "1769384178950", "event_type": "price_change"}}
{"_local_timestamp": "2026-01-25T23:36:19.317626+00:00", "data": {"market": "0xda5c517dd5b78c80dec8ceb08ca4f466317633487827d7290332b4851cc4a4fa", "price_changes": [{"asset_id": "22488814055465212843401871684243737932656687199587127613893702721105723939237", "price": "0.297", "size": "5", "side": "BUY", "hash": "10c0fac4de175b6533704982878490c36066830e", "best_bid": "0.935", "best_ask": "0.941"}, {"asset_id": "16201530957950630406397949502319734794139620443510795733205872225099141120819", "price": "0.703", "size": "5", "side": "SELL", "hash": "d972abf29f58cf881d015c7d1db7f608d91ea6b7", "best_bid": "0.059", "best_ask": "0.065"}], "timestamp": "1769384179253", "event_type": "price_change"}}
{"_local_timestamp": "2026-01-25T23:36:21.677654+00:00", "data": {"market": "0xda5c517dd5b78c80dec8ceb08ca4f466317633487827d7290332b4851cc4a4fa", "price_changes": [{"asset_id": "22488814055465212843401871684243737932656687199587127613893702721105723939237", "price": "0.297", "size": "0", "side": "BUY", "hash": "6bc1721c406d1b4ce1ab5a046181beb8cde01d67", "best_bid": "0.935", "best_ask": "0.941"}, {"asset_id": "16201530957950630406397949502319734794139620443510795733205872225099141120819", "price": "0.703", "size": "0", "side": "SELL", "hash": "c341baf3293efe896b729023144fdfe9d483c123", "best_bid": "0.059", "best_ask": "0.065"}], "timestamp": "1769384181577", "event_type": "price_change"}}
{"_local_timestamp": "2026-01-25T23:36:21.935009+00:00", "data": {"market": "0xda5c517dd5b78c80dec8ceb08ca4f466317633487827d7290332b4851cc4a4fa", "price_changes": [{"asset_id": "22488814055465212843401871684243737932656687199587127613893702721105723939237", "price": "0.297", "size": "5", "side": "BUY", "hash": "66b9196171b429855b0abb074a38501cbfe68c00", "best_bid": "0.935", "best_ask": "0.941"}, {"asset_id": "16201530957950630406397949502319734794139620443510795733205872225099141120819", "price": "0.703", "size": "5", "side": "SELL", "hash": "1f062eeca22132b0686ac64eb3f71190ad18f942", "best_bid": "0.059", "best_ask": "0.065"}], "timestamp": "1769384181862", "event_type": "price_change"}}
{"_local_timestamp": "2026-01-25T23:36:23.365160+00:00", "data": {"market": "0xda5c517dd5b78c80dec8ceb08ca4f466317633487827d7290332b4851cc4a4fa", "price_changes": [{"asset_id": "22488814055465212843401871684243737932656687199587127613893702721105723939237", "price": "0.297", "size": "0", "side": "BUY", "hash": "1d9e47133fd8830b9e338d14ece0b1e161516522", "best_bid": "0.935", "best_ask": "0.941"}, {"asset_id": "16201530957950630406397949502319734794139620443510795733205872225099141120819", "price": "0.703", "size": "0", "side": "SELL", "hash": "b24bacd6de08d4a5863ee06f047d33f6eaa9b855", "best_bid": "0.059", "best_ask": "0.065"}], "timestamp": "1769384183287", "event_type": "price_change"}}
{"_local_timestamp": "2026-01-25T23:36:23.692498+00:00", "data": {"market": "0xda5c517dd5b78c80dec8ceb08ca4f466317633487827d7290332b4851cc4a4fa", "price_changes": [{"asset_id": "22488814055465212843401871684243737932656687199587127613893702721105723939237", "price": "0.297", "size": "5", "side": "BUY", "hash": "75e9054871e61077b6fffbc3c4d36a4c9145106a", "best_bid": "0.935", "best_ask": "0.941"}, {"asset_id": "16201530957950630406397949502319734794139620443510795733205872225099141120819", "price": "0.703", "size": "5", "side": "SELL", "hash": "cee35935f09b197d07c60bf1b48d5877c0b774eb", "best_bid": "0.059", "best_ask": "0.065"}], "timestamp": "1769384183621", "event_type": "price_change"}}
{"_local_timestamp": "2026-01-25T23:36:25.296588+00:00", "data": {"market": "0xda5c517dd5b78c80dec8ceb08ca4f466317633487827d7290332b4851cc4a4fa", "price_changes": [{"asset_id": "22488814055465212843401871684243737932656687199587127613893702721105723939237", "price": "0.297", "size": "0", "side": "BUY", "hash": "f35c6249c63cb1867c7ee1acd8744dfc7644bbb0", "best_bid": "0.935", "best_ask": "0.941"}, {"asset_id": "16201530957950630406397949502319734794139620443510795733205872225099141120819", "price": "0.703", "size": "0", "side": "SELL", "hash": "15dd4e58a6ae6cacee6ae26cd991905d4526ee7b", "best_bid": "0.059", "best_ask": "0.065"}], "timestamp": "1769384185222", "event_type": "price_change"}}
{"_local_timestamp": "2026-01-25T23:36:25.563779+00:00", "data": {"market": "0xda5c517dd5b78c80dec8ceb08ca4f466317633487827d7290332b4851cc4a4fa", "price_changes": [{"asset_id": "22488814055465212843401871684243737932656687199587127613893702721105723939237", "price": "0.297", "size": "5", "side": "BUY", "hash": "61f0cd8a7e0e7c7c3fe17b66580d0ad1fc403dbb", "best_bid": "0.935", "best_ask": "0.941"}, {"asset_id": "16201530957950630406397949502319734794139620443510795733205872225099141120819", "price": "0.703", "size": "5", "side": "SELL", "hash": "ca11626b8e1ec161add2d2b829aca15ad19b6be7", "best_bid": "0.059", "best_ask": "0.065"}], "timestamp": "1769384185492", "event_type": "price_change"}}
{"_local_timestamp": "2026-01-25T23:36:27.804699+00:00", "data": {"market": "0xda5c517dd5b78c80dec8ceb08ca4f466317633487827d7290332b4851cc4a4fa", "price_changes": [{"asset_id": "22488814055465212843401871684243737932656687199587127613893702721105723939237", "price": "0.297", "size": "0", "side": "BUY", "hash": "34c6186a4d03019f71d7e834e763f153cb8850ac", "best_bid": "0.935", "best_ask": "0.941"}, {"asset_id": "16201530957950630406397949502319734794139620443510795733205872225099141120819", "price": "0.703", "size": "0", "side": "SELL", "hash": "963a264dffaac4499c1f4a36d9aee6cce0983bbd", "best_bid": "0.059", "best_ask": "0.065"}], "timestamp": "1769384187727", "event_type": "price_change"}}
{"_local_timestamp": "2026-01-25T23:36:28.057428+00:00", "data": {"market": "0xda5c517dd5b78c80dec8ceb08ca4f466317633487827d7290332b4851cc4a4fa", "price_changes": [{"asset_id": "22488814055465212843401871684243737932656687199587127613893702721105723939237", "price": "0.297", "size": "5", "side": "BUY", "hash": "6c941d51bd3c35f0194705a36590641dfb85ff30", "best_bid": "0.935", "best_ask": "0.941"}, {"asset_id": "16201530957950630406397949502319734794139620443510795733205872225099141120819", "price": "0.703", "size": "5", "side": "SELL", "hash": "0bcacf15ec82edffb94faa26295afa7417ae61d4", "best_bid": "0.059", "best_ask": "0.065"}], "timestamp": "1769384187982", "event_type": "price_change"}}
{"_local_timestamp": "2026-01-25T23:36:29.483910+00:00", "data": {"market": "0xda5c517dd5b78c80dec8ceb08ca4f466317633487827d7290332b4851cc4a4fa", "price_changes": [{"asset_id": "22488814055465212843401871684243737932656687199587127613893702721105723939237", "price": "0.297", "size": "0", "side": "BUY", "hash": "db05502c63f8d6fd03b34dcac145f708d9d1a90e", "best_bid": "0.935", "best_ask": "0.941"}, {"asset_id": "16201530957950630406397949502319734794139620443510795733205872225099141120819", "price": "0.703", "size": "0", "side": "SELL", "hash": "5ec2b45c4645f5ff6bf294a3536d312e33938d93", "best_bid": "0.059", "best_ask": "0.065"}], "timestamp": "1769384189418", "event_type": "price_change"}}
{"_local_timestamp": "2026-01-25T23:36:29.825412+00:00", "data": {"market": "0xda5c517dd5b78c80dec8ceb08ca4f466317633487827d7290332b4851cc4a4fa", "price_changes": [{"asset_id": "22488814055465212843401871684243737932656687199587127613893702721105723939237", "price": "0.297", "size": "5", "side": "BUY", "hash": "1c0718e55b806b876a9ff4a1889261dc0e7625f5", "best_bid": "0.935", "best_ask": "0.941"}, {"asset_id": "16201530957950630406397949502319734794139620443510795733205872225099141120819", "price": "0.703", "size": "5", "side": "SELL", "hash": "f1aa47c41ebbc41da4942d01b683b4e34fdae082", "best_bid": "0.059", "best_ask": "0.065"}], "timestamp": "1769384189757", "event_type": "price_change"}}
{"_local_timestamp": "2026-01-25T23:36:31.644603+00:00", "data": {"market": "0xda5c517dd5b78c80dec8ceb08ca4f466317633487827d7290332b4851cc4a4fa", "price_changes": [{"asset_id": "22488814055465212843401871684243737932656687199587127613893702721105723939237", "price": "0.297", "size": "0", "side": "BUY", "hash": "a721e86a16330d2e0dec1d9a2bc6dec0a94cf2be", "best_bid": "0.935", "best_ask": "0.941"}, {"asset_id": "16201530957950630406397949502319734794139620443510795733205872225099141120819", "price": "0.703", "size": "0", "side": "SELL", "hash": "795d1d8a79585939d530d756deef735f34ac6db9", "best_bid": "0.059", "best_ask": "0.065"}], "timestamp": "1769384191576", "event_type": "price_change"}}
{"_local_timestamp": "2026-01-25T23:36:31.935655+00:00", "data": {"market": "0xda5c517dd5b78c80dec8ceb08ca4f466317633487827d7290332b4851cc4a4fa", "price_changes": [{"asset_id": "22488814055465212843401871684243737932656687199587127613893702721105723939237", "price": "0.297", "size": "5", "side": "BUY", "hash": "53680441d14906b1014b3f9f81f84ba8c25f74e9", "best_bid": "0.935", "best_ask": "0.941"}, {"asset_id": "16201530957950630406397949502319734794139620443510795733205872225099141120819", "price": "0.703", "size": "5", "side": "SELL", "hash": "f39954ddd173ff6c27eb24a8f7c3e881464fb822", "best_bid": "0.059", "best_ask": "0.065"}], "timestamp": "1769384191864", "event_type": "price_change"}}
{"_local_timestamp": "2026-01-25T23:36:33.772062+00:00", "data": {"market": "0xda5c517dd5b78c80dec8ceb08ca4f466317633487827d7290332b4851cc4a4fa", "price_changes": [{"asset_id": "22488814055465212843401871684243737932656687199587127613893702721105723939237", "price": "0.297", "size": "0", "side": "BUY", "hash": "9102b5980499548d2f1683049174a4d826ac0058", "best_bid": "0.935", "best_ask": "0.941"}, {"asset_id": "16201530957950630406397949502319734794139620443510795733205872225099141120819", "price": "0.703", "size": "0", "side": "SELL", "hash": "27f69a6d3f2dc1ee8cd5458e81ac8ba54205dfe3", "best_bid": "0.059", "best_ask": "0.065"}], "timestamp": "1769384193697", "event_type": "price_change"}}
{"_local_timestamp": "2026-01-25T23:36:34.043770+00:00", "data": {"market": "0xda5c517dd5b78c80dec8ceb08ca4f466317633487827d7290332b4851cc4a4fa", "price_changes": [{"asset_id": "16201530957950630406397949502319734794139620443510795733205872225099141120819", "price": "0.055", "size": "291", "side": "BUY", "hash": "2f403467bc3e811ac1865697039746c29283f598", "best_bid": "0.059", "best_ask": "0.065"}, {"asset_id": "22488814055465212843401871684243737932656687199587127613893702721105723939237", "price": "0.945", "size": "291", "side": "SELL", "hash": "94ae8fae2fd23d54b45e11fd689561b50bd2e1a0", "best_bid": "0.935", "best_ask": "0.941"}], "timestamp": "1769384193976", "event_type": "price_change"}}
{"_local_timestamp": "2026-01-25T23:36:34.098268+00:00", "data": {"market": "0xda5c517dd5b78c80dec8ceb08ca4f466317633487827d7290332b4851cc4a4fa", "price_changes": [{"asset_id": "22488814055465212843401871684243737932656687199587127613893702721105723939237", "price": "0.297", "size": "5", "side": "BUY", "hash": "d7a1b9e614814e66ce2db9431564d63b7bc50ef9", "best_bid": "0.935", "best_ask": "0.941"}, {"asset_id": "16201530957950630406397949502319734794139620443510795733205872225099141120819", "price": "0.703", "size": "5", "side": "SELL", "hash": "5454ce3e63281e7024e6988161a33be813773b16", "best_bid": "0.059", "best_ask": "0.065"}], "timestamp": "1769384194025", "event_type": "price_change"}}
{"_local_timestamp": "2026-01-25T23:36:35.895119+00:00", "data": {"market": "0xda5c517dd5b78c80dec8ceb08ca4f466317633487827d7290332b4851cc4a4fa", "price_changes": [{"asset_id": "22488814055465212843401871684243737932656687199587127613893702721105723939237", "price": "0.297", "size": "0", "side": "BUY", "hash": "8335f9faac376a6e240f45baa32991e80356f787", "best_bid": "0.935", "best_ask": "0.941"}, {"asset_id": "16201530957950630406397949502319734794139620443510795733205872225099141120819", "price": "0.703", "size": "0", "side": "SELL", "hash": "c08f3ff6a4750fed58233ac7c3a304de873c3fd6", "best_bid": "0.059", "best_ask": "0.065"}], "timestamp": "1769384195828", "event_type": "price_change"}}
{"_local_timestamp": "2026-01-25T23:36:36.122178+00:00", "data": {"market": "0xda5c517dd5b78c80dec8ceb08ca4f466317633487827d7290332b4851cc4a4fa", "price_changes": [{"asset_id": "16201530957950630406397949502319734794139620443510795733205872225099141120819", "price": "0.052", "size": "200", "side": "BUY", "hash": "4b5d44c099198912f3619304d4bdc3294f117e13", "best_bid": "0.059", "best_ask": "0.065"}, {"asset_id": "22488814055465212843401871684243737932656687199587127613893702721105723939237", "price": "0.948", "size": "200", "side": "SELL", "hash": "b590df1fe414f0e928a2c1c57e731d10283ae910", "best_bid": "0.935", "best_ask": "0.941"}], "timestamp": "1769384196040", "event_type": "price_change"}}
{"_local_timestamp": "2026-01-25T23:36:36.123780+00:00", "data": {"market": "0xda5c517dd5b78c80dec8ceb08ca4f466317633487827d7290332b4851cc4a4fa", "price_changes": [{"asset_id": "16201530957950630406397949502319734794139620443510795733205872225099141120819", "price": "0.055", "size": "163", "side": "BUY", "hash": "4b5d44c099198912f3619304d4bdc3294f117e13", "best_bid": "0.059", "best_ask": "0.065"}, {"asset_id": "22488814055465212843401871684243737932656687199587127613893702721105723939237", "price": "0.945", "size": "163", "side": "SELL", "hash": "b590df1fe414f0e928a2c1c57e731d10283ae910", "best_bid": "0.935", "best_ask": "0.941"}], "timestamp": "1769384196040", "event_type": "price_change"}}
{"_local_timestamp": "2026-01-25T23:36:36.144793+00:00", "data": {"market": "0xda5c517dd5b78c80dec8ceb08ca4f466317633487827d7290332b4851cc4a4fa", "price_changes": [{"asset_id": "22488814055465212843401871684243737932656687199587127613893702721105723939237", "price": "0.297", "size": "5", "side": "BUY", "hash": "6a718cd238a73444caa5fb7d8969768fe61dcb54", "best_bid": "0.935", "best_ask": "0.941"}, {"asset_id": "16201530957950630406397949502319734794139620443510795733205872225099141120819", "price": "0.703", "size": "5", "side": "SELL", "hash": "3534f3074e38964d4aaf69d5570441335f02d520", "best_bid": "0.059", "best_ask": "0.065"}], "timestamp": "1769384196067", "event_type": "price_change"}}
{"_local_timestamp": "2026-01-25T23:36:36.177887+00:00", "data": {"market": "0xda5c517dd5b78c80dec8ceb08ca4f466317633487827d7290332b4851cc4a4fa", "price_changes": [{"asset_id": "16201530957950630406397949502319734794139620443510795733205872225099141120819", "price": "0.053", "size": "370", "side": "BUY", "hash": "2a952d26e17932ded9eeb4484d6cf116cefc86f8", "best_bid": "0.059", "best_ask": "0.065"}, {"asset_id": "22488814055465212843401871684243737932656687199587127613893702721105723939237", "price": "0.947", "size": "370", "side": "SELL", "hash": "98339fb9e3ed450891114a3c97bb7029daa6f5d2", "best_bid": "0.935", "best_ask": "0.941"}], "timestamp": "1769384196112", "event_type": "price_change"}}
{"_local_timestamp": "2026-01-25T23:36:36.188326+00:00", "data": {"market": "0xda5c517dd5b78c80dec8ceb08ca4f466317633487827d7290332b4851cc4a4fa", "price_changes": [{"asset_id": "16201530957950630406397949502319734794139620443510795733205872225099141120819", "price": "0.056", "size": "125", "side": "BUY", "hash": "6985f762aa37f0ac994ccb8f78a7303f3f8f1132", "best_bid": "0.059", "best_ask": "0.065"}, {"asset_id": "22488814055465212843401871684243737932656687199587127613893702721105723939237", "price": "0.944", "size": "125", "side": "SELL", "hash": "dd3df23671f38dd1aabdeb633c6a7eccefa006f5", "best_bid": "0.935", "best_ask": "0.941"}], "timestamp": "1769384196113", "event_type": "price_change"}}
{"_local_timestamp": "2026-01-25T23:36:36.209222+00:00", "data": {"market": "0xda5c517dd5b78c80dec8ceb08ca4f466317633487827d7290332b4851cc4a4fa", "price_changes": [{"asset_id": "16201530957950630406397949502319734794139620443510795733205872225099141120819", "price": "0.054", "size": "200", "side": "BUY", "hash": "5c3cb3fcc2382f890fd3cc0cd1f6de7ee9114bb1", "best_bid": "0.059", "best_ask": "0.065"}, {"asset_id": "22488814055465212843401871684243737932656687199587127613893702721105723939237", "price": "0.946", "size": "200", "side": "SELL", "hash": "4bf24e78b66efb053aa966782de1fd90454c7955", "best_bid": "0.935", "best_ask": "0.941"}], "timestamp": "1769384196137", "event_type": "price_change"}}
{"_local_timestamp": "2026-01-25T23:36:36.721713+00:00", "data": {"market": "0xda5c517dd5b78c80dec8ceb08ca4f466317633487827d7290332b4851cc4a4fa", "price_changes": [{"asset_id": "22488814055465212843401871684243737932656687199587127613893702721105723939237", "price": "0.253", "size": "1660", "side": "BUY", "hash": "006c094c242612f1f8e4dcd18cac74c087b56cce", "best_bid": "0.935", "best_ask": "0.941"}, {"asset_id": "16201530957950630406397949502319734794139620443510795733205872225099141120819", "price": "0.747", "size": "1660", "side": "SELL", "hash": "4d7b50810a909d3da9de40b08ddd352fc765d70e", "best_bid": "0.059", "best_ask": "0.065"}], "timestamp": "1769384196652", "event_type": "price_change"}}
{"_local_timestamp": "2026-01-25T23:36:37.830447+00:00", "data": {"market": "0xda5c517dd5b78c80dec8ceb08ca4f466317633487827d7290332b4851cc4a4fa", "price_changes": [{"asset_id": "22488814055465212843401871684243737932656687199587127613893702721105723939237", "price": "0.297", "size": "0", "side": "BUY", "hash": "0128d702587bdd951b5654dbaf830fb9446f950c", "best_bid": "0.935", "best_ask": "0.941"}, {"asset_id": "16201530957950630406397949502319734794139620443510795733205872225099141120819", "price": "0.703", "size": "0", "side": "SELL", "hash": "8f059aa79ffd3088d25f627263c4c1b25e3cd7ad", "best_bid": "0.059", "best_ask": "0.065"}], "timestamp": "1769384197760", "event_type": "price_change"}}
{"_local_timestamp": "2026-01-25T23:36:38.188029+00:00", "data": {"market": "0xda5c517dd5b78c80dec8ceb08ca4f466317633487827d7290332b4851cc4a4fa", "price_changes": [{"asset_id": "22488814055465212843401871684243737932656687199587127613893702721105723939237", "price": "0.297", "size": "5", "side": "BUY", "hash": "805df4757d46b28fe519276168c20cbf6a46738c", "best_bid": "0.935", "best_ask": "0.941"}, {"asset_id": "16201530957950630406397949502319734794139620443510795733205872225099141120819", "price": "0.703", "size": "5", "side": "SELL", "hash": "fc55667addad0153bda0ce3ec0b9e8f45313b980", "best_bid": "0.059", "best_ask": "0.065"}], "timestamp": "1769384198113", "event_type": "price_change"}}
{"_local_timestamp": "2026-01-25T23:36:38.966973+00:00", "data": {"market": "0xda5c517dd5b78c80dec8ceb08ca4f466317633487827d7290332b4851cc4a4fa", "price_changes": [{"asset_id": "16201530957950630406397949502319734794139620443510795733205872225099141120819", "price": "0.051", "size": "9121.81", "side": "BUY", "hash": "156cf839787311f897648cee3bc1e2856b657f55", "best_bid": "0.059", "best_ask": "0.065"}, {"asset_id": "22488814055465212843401871684243737932656687199587127613893702721105723939237", "price": "0.949", "size": "9121.81", "side": "SELL", "hash": "40b2a50451e510c03d510f6fdc83de39c9bfd8c0", "best_bid": "0.935", "best_ask": "0.941"}], "timestamp": "1769384198898", "event_type": "price_change"}}
{"_local_timestamp": "2026-01-25T23:36:40.330363+00:00", "data": {"market": "0xda5c517dd5b78c80dec8ceb08ca4f466317633487827d7290332b4851cc4a4fa", "price_changes": [{"asset_id": "22488814055465212843401871684243737932656687199587127613893702721105723939237", "price": "0.297", "size": "0", "side": "BUY", "hash": "1d79e33fbe298b46ba934a7a702ae17a4e9e9e41", "best_bid": "0.935", "best_ask": "0.941"}, {"asset_id": "16201530957950630406397949502319734794139620443510795733205872225099141120819", "price": "0.703", "size": "0", "side": "SELL", "hash": "6d4a0be5b0fa9a2ca5e7692ca8e039526025f8d1", "best_bid": "0.059", "best_ask": "0.065"}], "timestamp": "1769384200264", "event_type": "price_change"}}
{"_local_timestamp": "2026-01-25T23:36:40.817492+00:00", "data": {"market": "0xda5c517dd5b78c80dec8ceb08ca4f466317633487827d7290332b4851cc4a4fa", "price_changes": [{"asset_id": "22488814055465212843401871684243737932656687199587127613893702721105723939237", "price": "0.297", "size": "5", "side": "BUY", "hash": "ca2d4c1fbc774044d3c2a850d763519280304218", "best_bid": "0.935", "best_ask": "0.941"}, {"asset_id": "16201530957950630406397949502319734794139620443510795733205872225099141120819", "price": "0.703", "size": "5", "side": "SELL", "hash": "74dfb8401d3872cfb75f59d93150e44cf4206193", "best_bid": "0.059", "best_ask": "0.065"}], "timestamp": "1769384200751", "event_type": "price_change"}}
{"_local_timestamp": "2026-01-25T23:36:42.757208+00:00", "data": {"market": "0xda5c517dd5b78c80dec8ceb08ca4f466317633487827d7290332b4851cc4a4fa", "price_changes": [{"asset_id": "16201530957950630406397949502319734794139620443510795733205872225099141120819", "price": "0.052", "size": "300", "side": "BUY", "hash": "d66a8428861477419b4c1b35b89e89f1e56af823", "best_bid": "0.059", "best_ask": "0.065"}, {"asset_id": "22488814055465212843401871684243737932656687199587127613893702721105723939237", "price": "0.948", "size": "300", "side": "SELL", "hash": "98ce5b23e73a4d51f2f2b7a107777d580cd6960d", "best_bid": "0.935", "best_ask": "0.941"}], "timestamp": "1769384202594", "event_type": "price_change"}}
{"_local_timestamp": "2026-01-25T23:36:43.226910+00:00", "data": {"market": "0xda5c517dd5b78c80dec8ceb08ca4f466317633487827d7290332b4851cc4a4fa", "price_changes": [{"asset_id": "22488814055465212843401871684243737932656687199587127613893702721105723939237", "price": "0.297", "size": "0", "side": "BUY", "hash": "c2d45c817c95873b2eca82ab2d9200baf1b284c1", "best_bid": "0.935", "best_ask": "0.941"}, {"asset_id": "16201530957950630406397949502319734794139620443510795733205872225099141120819", "price": "0.703", "size": "0", "side": "SELL", "hash": "8c71b8762dc8d725d6df4370decec524175d55d9", "best_bid": "0.059", "best_ask": "0.065"}], "timestamp": "1769384203053", "event_type": "price_change"}}
{"_local_timestamp": "2026-01-25T23:36:43.366795+00:00", "data": {"market": "0xda5c517dd5b78c80dec8ceb08ca4f466317633487827d7290332b4851cc4a4fa", "price_changes": [{"asset_id": "22488814055465212843401871684243737932656687199587127613893702721105723939237", "price": "0.281", "size": "100", "side": "BUY", "hash": "e0abfdc9bade4c46c4dc1c317eab56831f7fc83d", "best_bid": "0.935", "best_ask": "0.941"}, {"asset_id": "16201530957950630406397949502319734794139620443510795733205872225099141120819", "price": "0.719", "size": "100", "side": "SELL", "hash": "bbdde2d36a3dd12b76fb22dcef637e5a0cd196a0", "best_bid": "0.059", "best_ask": "0.065"}], "timestamp": "1769384203119", "event_type": "price_change"}}
{"_local_timestamp": "2026-01-25T23:36:43.694071+00:00", "data": {"market": "0xda5c517dd5b78c80dec8ceb08ca4f466317633487827d7290332b4851cc4a4fa", "price_changes": [{"asset_id": "22488814055465212843401871684243737932656687199587127613893702721105723939237", "price": "0.297", "size": "5", "side": "BUY", "hash": "0c6ec2cef1fbdc41d704c8d35d068ed23980f911", "best_bid": "0.935", "best_ask": "0.941"}, {"asset_id": "16201530957950630406397949502319734794139620443510795733205872225099141120819", "price": "0.703", "size": "5", "side": "SELL", "hash": "bfd40b9a1268b2f7a5ee069add592f1222abec3f", "best_bid": "0.059", "best_ask": "0.065"}], "timestamp": "1769384203521", "event_type": "price_change"}}
{"_local_timestamp": "2026-01-25T23:36:43.788073+00:00", "data": {"market": "0xda5c517dd5b78c80dec8ceb08ca4f466317633487827d7290332b4851cc4a4fa", "price_changes": [{"asset_id": "22488814055465212843401871684243737932656687199587127613893702721105723939237", "price": "0.28", "size": "192.85", "side": "BUY", "hash": "d4a2390ad81d639af550a72e41b9e6b16db65120", "best_bid": "0.935", "best_ask": "0.941"}, {"asset_id": "16201530957950630406397949502319734794139620443510795733205872225099141120819", "price": "0.72", "size": "192.85", "side": "SELL", "hash": "ea11192459ab5a38bad6a63a686477b9c98a4879", "best_bid": "0.059", "best_ask": "0.065"}], "timestamp": "1769384203574", "event_type": "price_change"}}
{"_local_timestamp": "2026-01-25T23:36:45.366895+00:00", "data": {"market": "0xda5c517dd5b78c80dec8ceb08ca4f466317633487827d7290332b4851cc4a4fa", "price_changes": [{"asset_id": "22488814055465212843401871684243737932656687199587127613893702721105723939237", "price": "0.297", "size": "0", "side": "BUY", "hash": "b6e02f0155007d4b359b41bea07730a9cab1be9c", "best_bid": "0.935", "best_ask": "0.941"}, {"asset_id": "16201530957950630406397949502319734794139620443510795733205872225099141120819", "price": "0.703", "size": "0", "side": "SELL", "hash": "64ac1e7504accd1a4808b3d9e902450169e1351b", "best_bid": "0.059", "best_ask": "0.065"}], "timestamp": "1769384205207", "event_type": "price_change"}}
{"_local_timestamp": "2026-01-25T23:36:45.624584+00:00", "data": {"market": "0xda5c517dd5b78c80dec8ceb08ca4f466317633487827d7290332b4851cc4a4fa", "price_changes": [{"asset_id": "22488814055465212843401871684243737932656687199587127613893702721105723939237", "price": "0.297", "size": "5", "side": "BUY", "hash": "a92bb9328f52a264e568916422068f660e20257f", "best_bid": "0.935", "best_ask": "0.941"}, {"asset_id": "16201530957950630406397949502319734794139620443510795733205872225099141120819", "price": "0.703", "size": "5", "side": "SELL", "hash": "45f89442179d8b9cbe622e006c87ea5b7b2059f9", "best_bid": "0.059", "best_ask": "0.065"}], "timestamp": "1769384205474", "event_type": "price_change"}}
{"_local_timestamp": "2026-01-25T23:36:47.560783+00:00", "data": {"market": "0xda5c517dd5b78c80dec8ceb08ca4f466317633487827d7290332b4851cc4a4fa", "price_changes": [{"asset_id": "22488814055465212843401871684243737932656687199587127613893702721105723939237", "price": "0.297", "size": "0", "side": "BUY", "hash": "3b451a61192563fa79ab5734ecaec5239028bad9", "best_bid": "0.935", "best_ask": "0.941"}, {"asset_id": "16201530957950630406397949502319734794139620443510795733205872225099141120819", "price": "0.703", "size": "0", "side": "SELL", "hash": "4783545637e68c49bb87ec397801dc3848def04e", "best_bid": "0.059", "best_ask": "0.065"}], "timestamp": "1769384207405", "event_type": "price_change"}}
{"_local_timestamp": "2026-01-25T23:36:47.582683+00:00", "data": {"market": "0xda5c517dd5b78c80dec8ceb08ca4f466317633487827d7290332b4851cc4a4fa", "price_changes": [{"asset_id": "16201530957950630406397949502319734794139620443510795733205872225099141120819", "price": "0.057", "size": "156.78", "side": "BUY", "hash": "29bc8c13848f522884bfda049552bff51d3e540b", "best_bid": "0.059", "best_ask": "0.065"}, {"asset_id": "22488814055465212843401871684243737932656687199587127613893702721105723939237", "price": "0.943", "size": "156.78", "side": "SELL", "hash": "cc76273fb64ec55be8a9f815a2b13a9355f0577f", "best_bid": "0.935", "best_ask": "0.941"}], "timestamp": "1769384207427", "event_type": "price_change"}}
{"_local_timestamp": "2026-01-25T23:36:47.892816+00:00", "data": {"market": "0xda5c517dd5b78c80dec8ceb08ca4f466317633487827d7290332b4851cc4a4fa", "price_changes": [{"asset_id": "22488814055465212843401871684243737932656687199587127613893702721105723939237", "price": "0.297", "size": "5", "side": "BUY", "hash": "8b3ea2f154b706a4f572d9ef7274b205c4e172d4", "best_bid": "0.935", "best_ask": "0.941"}, {"asset_id": "16201530957950630406397949502319734794139620443510795733205872225099141120819", "price": "0.703", "size": "5", "side": "SELL", "hash": "46c6d96178cb53a3b189d9682385a2b247843654", "best_bid": "0.059", "best_ask": "0.065"}], "timestamp": "1769384207740", "event_type": "price_change"}}
{"_local_timestamp": "2026-01-25T23:36:49.281508+00:00", "data": {"market": "0xda5c517dd5b78c80dec8ceb08ca4f466317633487827d7290332b4851cc4a4fa", "price_changes": [{"asset_id": "22488814055465212843401871684243737932656687199587127613893702721105723939237", "price": "0.297", "size": "0", "side": "BUY", "hash": "4843871d75919d8c5c980dfdd621d69ab2cd276c", "best_bid": "0.935", "best_ask": "0.941"}, {"asset_id": "16201530957950630406397949502319734794139620443510795733205872225099141120819", "price": "0.703", "size": "0", "side": "SELL", "hash": "9011495a247ccab0dfd034c2db7876b5c3cfd237", "best_bid": "0.059", "best_ask": "0.065"}], "timestamp": "1769384209136", "event_type": "price_change"}}
{"_local_timestamp": "2026-01-25T23:36:49.559131+00:00", "data": {"market": "0xda5c517dd5b78c80dec8ceb08ca4f466317633487827d7290332b4851cc4a4fa", "price_changes": [{"asset_id": "22488814055465212843401871684243737932656687199587127613893702721105723939237", "price": "0.297", "size": "5", "side": "BUY", "hash": "1e7e5af20f87d80b81071bcd368ba2b4843d0167", "best_bid": "0.935", "best_ask": "0.941"}, {"asset_id": "16201530957950630406397949502319734794139620443510795733205872225099141120819", "price": "0.703", "size": "5", "side": "SELL", "hash": "c382a413de78769e04cd74b93801a33c7d5c9d2a", "best_bid": "0.059", "best_ask": "0.065"}], "timestamp": "1769384209408", "event_type": "price_change"}}
{"_local_timestamp": "2026-01-25T23:36:50.502869+00:00", "data": {"market": "0xda5c517dd5b78c80dec8ceb08ca4f466317633487827d7290332b4851cc4a4fa", "price_changes": [{"asset_id": "16201530957950630406397949502319734794139620443510795733205872225099141120819", "price": "0.053", "size": "200", "side": "BUY", "hash": "2aa476225b7f9cc75ff7126fdb6965c2a9bf52b7", "best_bid": "0.059", "best_ask": "0.065"}, {"asset_id": "22488814055465212843401871684243737932656687199587127613893702721105723939237", "price": "0.947", "size": "200", "side": "SELL", "hash": "d0be7ec664baadb99450ed439a52c6903a131573", "best_bid": "0.935", "best_ask": "0.941"}], "timestamp": "1769384210345", "event_type": "price_change"}}
{"_local_timestamp": "2026-01-25T23:36:50.503434+00:00", "data": {"market": "0xda5c517dd5b78c80dec8ceb08ca4f466317633487827d7290332b4851cc4a4fa", "price_changes": [{"asset_id": "16201530957950630406397949502319734794139620443510795733205872225099141120819", "price": "0.056", "size": "0", "side": "BUY", "hash": "2aa476225b7f9cc75ff7126fdb6965c2a9bf52b7", "best_bid": "0.059", "best_ask": "0.065"}, {"asset_id": "22488814055465212843401871684243737932656687199587127613893702721105723939237", "price": "0.944", "size": "0", "side": "SELL", "hash": "d0be7ec664baadb99450ed439a52c6903a131573", "best_bid": "0.935", "best_ask": "0.941"}], "timestamp": "1769384210345", "event_type": "price_change"}}
{"_local_timestamp": "2026-01-25T23:36:50.521629+00:00", "data": {"market": "0xda5c517dd5b78c80dec8ceb08ca4f466317633487827d7290332b4851cc4a4fa", "price_changes": [{"asset_id": "16201530957950630406397949502319734794139620443510795733205872225099141120819", "price": "0.054", "size": "254", "side": "BUY", "hash": "6a4a9f9973c3dc0141f9f1e6b9353959b46d7700", "best_bid": "0.059", "best_ask": "0.065"}, {"asset_id": "22488814055465212843401871684243737932656687199587127613893702721105723939237", "price": "0.946", "size": "254", "side": "SELL", "hash": "d7072c37aa71d2abc50c4d9a74bcf6f001e66c30", "best_bid": "0.935", "best_ask": "0.941"}], "timestamp": "1769384210370", "event_type": "price_change"}}
{"_local_timestamp": "2026-01-25T23:36:50.734769+00:00", "data": {"market": "0xda5c517dd5b78c80dec8ceb08ca4f466317633487827d7290332b4851cc4a4fa", "price_changes": [{"asset_id": "16201530957950630406397949502319734794139620443510795733205872225099141120819", "price": "0.038", "size": "474", "side": "BUY", "hash": "62325a994cc3aa106421ce29578b1974a8fbb0ab", "best_bid": "0.059", "best_ask": "0.065"}, {"asset_id": "22488814055465212843401871684243737932656687199587127613893702721105723939237", "price": "0.962", "size": "474", "side": "SELL", "hash": "b2f63626b4b2d0d1e35456fc7952cba0983e9da1", "best_bid": "0.935", "best_ask": "0.941"}], "timestamp": "1769384210589", "event_type": "price_change"}}
{"_local_timestamp": "2026-01-25T23:36:50.735185+00:00", "data": {"market": "0xda5c517dd5b78c80dec8ceb08ca4f466317633487827d7290332b4851cc4a4fa", "price_changes": [{"asset_id": "16201530957950630406397949502319734794139620443510795733205872225099141120819", "price": "0.055", "size": "327", "side": "BUY", "hash": "983efea7dbe36700858592a810ef9a79c83443ce", "best_bid": "0.059", "best_ask": "0.065"}, {"asset_id": "22488814055465212843401871684243737932656687199587127613893702721105723939237", "price": "0.945", "size": "327", "side": "SELL", "hash": "638c2e1c3e6d8d4ea8a424b723fb1022e011dd35", "best_bid": "0.935", "best_ask": "0.941"}], "timestamp": "1769384210590", "event_type": "price_change"}}
{"_local_timestamp": "2026-01-25T23:36:50.735460+00:00", "data": {"market": "0xda5c517dd5b78c80dec8ceb08ca4f466317633487827d7290332b4851cc4a4fa", "price_changes": [{"asset_id": "16201530957950630406397949502319734794139620443510795733205872225099141120819", "price": "0.02", "size": "14800", "side": "BUY", "hash": "f7e519eb45877fcb9cb07febc57857264f1eb399", "best_bid": "0.059", "best_ask": "0.065"}, {"asset_id": "22488814055465212843401871684243737932656687199587127613893702721105723939237", "price": "0.98", "size": "14800", "side": "SELL", "hash": "39d7d2243939e64c681d1b431d8b7b8b852a6a54", "best_bid": "0.935", "best_ask": "0.941"}], "timestamp": "1769384210591", "event_type": "price_change"}}
{"_local_timestamp": "2026-01-25T23:36:50.735708+00:00", "data": {"market": "0xda5c517dd5b78c80dec8ceb08ca4f466317633487827d7290332b4851cc4a4fa", "price_changes": [{"asset_id": "16201530957950630406397949502319734794139620443510795733205872225099141120819", "price": "0.01", "size": "12212.68", "side": "BUY", "hash": "fba9c31a25f2f0c403e3e444e5a72f87f3880a1e", "best_bid": "0.059", "best_ask": "0.065"}, {"asset_id": "22488814055465212843401871684243737932656687199587127613893702721105723939237", "price": "0.99", "size": "12212.68", "side": "SELL", "hash": "db2f244aa85b55f40850bb004d7b1c1302ee853b", "best_bid": "0.935", "best_ask": "0.941"}], "timestamp": "1769384210591", "event_type": "price_change"}}
{"_local_timestamp": "2026-01-25T23:36:50.735995+00:00", "data": {"market": "0xda5c517dd5b78c80dec8ceb08ca4f466317633487827d7290332b4851cc4a4fa", "price_changes": [{"asset_id": "16201530957950630406397949502319734794139620443510795733205872225099141120819", "price": "0.013", "size": "4315.11", "side": "BUY", "hash": "dd3fc1bcfff681188e8241715f2d7969c674084d", "best_bid": "0.059", "best_ask": "0.065"}, {"asset_id": "22488814055465212843401871684243737932656687199587127613893702721105723939237", "price": "0.987", "size": "4315.11", "side": "SELL", "hash": "554746c7d53290d455850aa45dddae42b6925f38", "best_bid": "0.935", "best_ask": "0.941"}], "timestamp": "1769384210593", "event_type": "price_change"}}
{"_local_timestamp": "2026-01-25T23:36:50.736882+00:00", "data": {"market": "0xda5c517dd5b78c80dec8ceb08ca4f466317633487827d7290332b4851cc4a4fa", "price_changes": [{"asset_id": "16201530957950630406397949502319734794139620443510795733205872225099141120819", "price": "0.045", "size": "312", "side": "BUY", "hash": "26b6f7b3d8912b65abd3cdf3a2f0d508d00af0b0", "best_bid": "0.059", "best_ask": "0.065"}, {"asset_id": "22488814055465212843401871684243737932656687199587127613893702721105723939237", "price": "0.955", "size": "312", "side": "SELL", "hash": "1717e2bd7313c2b55079299afb3963b6da00e64d", "best_bid": "0.935", "best_ask": "0.941"}], "timestamp": "1769384210593", "event_type": "price_change"}}
{"_local_timestamp": "2026-01-25T23:36:50.745051+00:00", "data": {"market": "0xda5c517dd5b78c80dec8ceb08ca4f466317633487827d7290332b4851cc4a4fa", "price_changes": [{"asset_id": "16201530957950630406397949502319734794139620443510795733205872225099141120819", "price": "0.051", "size": "9357.81", "side": "BUY", "hash": "0bef3e49b57edac461ea1e6b5fb6739c099985e7", "best_bid": "0.059", "best_ask": "0.065"}, {"asset_id": "22488814055465212843401871684243737932656687199587127613893702721105723939237", "price": "0.949", "size": "9357.81", "side": "SELL", "hash": "3c9efff4172972d6ed3af3bc92952429add613b7", "best_bid": "0.935", "best_ask": "0.941"}], "timestamp": "1769384210594", "event_type": "price_change"}}
{"_local_timestamp": "2026-01-25T23:36:50.745443+00:00", "data": {"market": "0xda5c517dd5b78c80dec8ceb08ca4f466317633487827d7290332b4851cc4a4fa", "price_changes": [{"asset_id": "16201530957950630406397949502319734794139620443510795733205872225099141120819", "price": "0.031", "size": "904", "side": "BUY", "hash": "08366cab24736b2e2572387f1009733841a95640", "best_bid": "0.059", "best_ask": "0.065"}, {"asset_id": "22488814055465212843401871684243737932656687199587127613893702721105723939237", "price": "0.969", "size": "904", "side": "SELL", "hash": "bd7e6121c0a0601ae23291c194ec8686e9f26665", "best_bid": "0.935", "best_ask": "0.941"}], "timestamp": "1769384210595", "event_type": "price_change"}}
{"_local_timestamp": "2026-01-25T23:36:50.745701+00:00", "data": {"market": "0xda5c517dd5b78c80dec8ceb08ca4f466317633487827d7290332b4851cc4a4fa", "price_changes": [{"asset_id": "16201530957950630406397949502319734794139620443510795733205872225099141120819", "price": "0.058", "size": "121", "side": "BUY", "hash": "20defdc425c03309ec0ac9be80c2df2e01643a58", "best_bid": "0.059", "best_ask": "0.065"}, {"asset_id": "22488814055465212843401871684243737932656687199587127613893702721105723939237", "price": "0.942", "size": "121", "side": "SELL", "hash": "87cda27387ff74ff319143bf268c0baff1b5531e", "best_bid": "0.935", "best_ask": "0.941"}], "timestamp": "1769384210596", "event_type": "price_change"}}
{"_local_timestamp": "2026-01-25T23:36:50.745936+00:00", "data": {"market": "0xda5c517dd5b78c80dec8ceb08ca4f466317633487827d7290332b4851cc4a4fa", "price_changes": [{"asset_id": "16201530957950630406397949502319734794139620443510795733205872225099141120819", "price": "0.034", "size": "677", "side": "BUY", "hash": "6cfcdddb03d7804ce197a068748182d214b8e3f1", "best_bid": "0.059", "best_ask": "0.065"}, {"asset_id": "22488814055465212843401871684243737932656687199587127613893702721105723939237", "price": "0.966", "size": "677", "side": "SELL", "hash": "59bf5c0ddbcb7b4ee2db9389b4ab5455c2e2169a", "best_bid": "0.935", "best_ask": "0.941"}], "timestamp": "1769384210597", "event_type": "price_change"}}
{"_local_timestamp": "2026-01-25T23:36:50.937825+00:00", "data": {"market": "0xda5c517dd5b78c80dec8ceb08ca4f466317633487827d7290332b4851cc4a4fa", "price_changes": [{"asset_id": "16201530957950630406397949502319734794139620443510795733205872225099141120819", "price": "0.023", "size": "1566", "side": "BUY", "hash": "ed96ee7d4b35b4ad4b98a30e7f3026cbe5ef5fb1", "best_bid": "0.059", "best_ask": "0.065"}, {"asset_id": "22488814055465212843401871684243737932656687199587127613893702721105723939237", "price": "0.977", "size": "1566", "side": "SELL", "hash": "b5f051ca5633b5e1fb4233b40acf1c30dbaaa839", "best_bid": "0.935", "best_ask": "0.941"}], "timestamp": "1769384210598", "event_type": "price_change"}}
{"_local_timestamp": "2026-01-25T23:36:50.938164+00:00", "data": {"market": "0xda5c517dd5b78c80dec8ceb08ca4f466317633487827d7290332b4851cc4a4fa", "price_changes": [{"asset_id": "16201530957950630406397949502319734794139620443510795733205872225099141120819", "price": "0.003", "size": "29672.09", "side": "BUY", "hash": "c120382d9cc28b6794575fc1ea2019183790d581", "best_bid": "0.059", "best_ask": "0.065"}, {"asset_id": "22488814055465212843401871684243737932656687199587127613893702721105723939237", "price": "0.997", "size": "29672.09", "side": "SELL", "hash": "299f72ca745798b2b9d5b51230bda4fe6ece2fb2", "best_bid": "0.935", "best_ask": "0.941"}], "timestamp": "1769384210599", "event_type": "price_change"}}
{"_local_timestamp": "2026-01-25T23:36:51.274536+00:00", "data": {"market": "0xda5c517dd5b78c80dec8ceb08ca4f466317633487827d7290332b4851cc4a4fa", "price_changes": [{"asset_id": "16201530957950630406397949502319734794139620443510795733205872225099141120819", "price": "0.057", "size": "126.78", "side": "BUY", "hash": "01c10732da9d0c936e148bebea3d8a3513a45a7f", "best_bid": "0.059", "best_ask": "0.065"}, {"asset_id": "22488814055465212843401871684243737932656687199587127613893702721105723939237", "price": "0.943", "size": "126.78", "side": "SELL", "hash": "3a4f0ca1c3ad4b738f21136b1d2eae2af0b16ea0", "best_bid": "0.935", "best_ask": "0.941"}], "timestamp": "1769384211113", "event_type": "price_change"}}
{"_local_timestamp": "2026-01-25T23:36:51.344624+00:00", "data": {"market": "0xda5c517dd5b78c80dec8ceb08ca4f466317633487827d7290332b4851cc4a4fa", "price_changes": [{"asset_id": "16201530957950630406397949502319734794139620443510795733205872225099141120819", "price": "0.058", "size": "151", "side": "BUY", "hash": "c5f6aacc04a84d74450f9b1584cee5b9cdda7f97", "best_bid": "0.059", "best_ask": "0.065"}, {"asset_id": "22488814055465212843401871684243737932656687199587127613893702721105723939237", "price": "0.942", "size": "151", "side": "SELL", "hash": "0b664ae587be35819385ab66c198341c623c7acb", "best_bid": "0.935", "best_ask": "0.941"}], "timestamp": "1769384211183", "event_type": "price_change"}}
{"_local_timestamp": "2026-01-25T23:36:51.965063+00:00", "data": {"market": "0xda5c517dd5b78c80dec8ceb08ca4f466317633487827d7290332b4851cc4a4fa", "price_changes": [{"asset_id": "16201530957950630406397949502319734794139620443510795733205872225099141120819", "price": "0.054", "size": "200", "side": "BUY", "hash": "ffe58b4f9128dd4ba88cc4363843ab09f6f3f57d", "best_bid": "0.059", "best_ask": "0.065"}, {"asset_id": "22488814055465212843401871684243737932656687199587127613893702721105723939237", "price": "0.946", "size": "200", "side": "SELL", "hash": "2e33d90dbe3fda41f2871fb1ed097a26dcdc2988", "best_bid": "0.935", "best_ask": "0.941"}], "timestamp": "1769384211775", "event_type": "price_change"}}
{"_local_timestamp": "2026-01-25T23:36:52.252900+00:00", "data": {"market": "0xda5c517dd5b78c80dec8ceb08ca4f466317633487827d7290332b4851cc4a4fa", "price_changes": [{"asset_id": "22488814055465212843401871684243737932656687199587127613893702721105723939237", "price": "0.934", "size": "0", "side": "BUY", "hash": "f0ef0865481904b4ecca2ae7766c2a90378a3a72", "best_bid": "0.935", "best_ask": "0.941"}, {"asset_id": "16201530957950630406397949502319734794139620443510795733205872225099141120819", "price": "0.066", "size": "0", "side": "SELL", "hash": "fdfef50c25f3beb7678fd7b1e334f3496ec30915", "best_bid": "0.059", "best_ask": "0.065"}], "timestamp": "1769384212055", "event_type": "price_change"}}
{"_local_timestamp": "2026-01-25T23:36:52.293084+00:00", "data": {"market": "0xda5c517dd5b78c80dec8ceb08ca4f466317633487827d7290332b4851cc4a4fa", "price_changes": [{"asset_id": "16201530957950630406397949502319734794139620443510795733205872225099141120819", "price": "0.056", "size": "54", "side": "BUY", "hash": "73686a6863dc3a97244cfbb64161bb6cd8591bae", "best_bid": "0.059", "best_ask": "0.065"}, {"asset_id": "22488814055465212843401871684243737932656687199587127613893702721105723939237", "price": "0.944", "size": "54", "side": "SELL", "hash": "79cf6966087cd587a9ed31e9da68a8e2b251335d", "best_bid": "0.935", "best_ask": "0.941"}], "timestamp": "1769384212086", "event_type": "price_change"}}
{"_local_timestamp": "2026-01-25T23:36:52.482747+00:00", "data": {"market": "0xda5c517dd5b78c80dec8ceb08ca4f466317633487827d7290332b4851cc4a4fa", "price_changes": [{"asset_id": "22488814055465212843401871684243737932656687199587127613893702721105723939237", "price": "0.297", "size": "0", "side": "BUY", "hash": "b2bc0f27f3a9956fda18e0ccd043a37c319d90e3", "best_bid": "0.935", "best_ask": "0.941"}, {"asset_id": "16201530957950630406397949502319734794139620443510795733205872225099141120819", "price": "0.703", "size": "0", "side": "SELL", "hash": "11559b38805579c70c187e4de74dfc85eb78ae2e", "best_bid": "0.059", "best_ask": "0.065"}], "timestamp": "1769384212294", "event_type": "price_change"}}
{"_local_timestamp": "2026-01-25T23:36:52.801271+00:00", "data": {"market": "0xda5c517dd5b78c80dec8ceb08ca4f466317633487827d7290332b4851cc4a4fa", "price_changes": [{"asset_id": "22488814055465212843401871684243737932656687199587127613893702721105723939237", "price": "0.297", "size": "5", "side": "BUY", "hash": "ee109de32e6bc018b46cc3dfe798d82edbb08302", "best_bid": "0.935", "best_ask": "0.941"}, {"asset_id": "16201530957950630406397949502319734794139620443510795733205872225099141120819", "price": "0.703", "size": "5", "side": "SELL", "hash": "3328b2b4b54a753d9c3d5e1a212736bdcd00ab75", "best_bid": "0.059", "best_ask": "0.065"}], "timestamp": "1769384212614", "event_type": "price_change"}}
{"_local_timestamp": "2026-01-25T23:36:53.269205+00:00", "data": {"market": "0xda5c517dd5b78c80dec8ceb08ca4f466317633487827d7290332b4851cc4a4fa", "price_changes": [{"asset_id": "22488814055465212843401871684243737932656687199587127613893702721105723939237", "price": "0.925", "size": "400", "side": "BUY", "hash": "2ea013c7b572ab2266a9df8a9de17302d946c3ea", "best_bid": "0.935", "best_ask": "0.941"}, {"asset_id": "16201530957950630406397949502319734794139620443510795733205872225099141120819", "price": "0.075", "size": "400", "side": "SELL", "hash": "1464c94daccaa4e471f372edb6bac7179e74fa6d", "best_bid": "0.059", "best_ask": "0.065"}], "timestamp": "1769384213072", "event_type": "price_change"}}
{"_local_timestamp": "2026-01-25T23:36:53.269556+00:00", "data": {"market": "0xda5c517dd5b78c80dec8ceb08ca4f466317633487827d7290332b4851cc4a4fa", "price_changes": [{"asset_id": "16201530957950630406397949502319734794139620443510795733205872225099141120819", "price": "0.052", "size": "200", "side": "BUY", "hash": "4b1d539732fdcaec766ab31653f4822fc4d590c5", "best_bid": "0.059", "best_ask": "0.065"}, {"asset_id": "22488814055465212843401871684243737932656687199587127613893702721105723939237", "price": "0.948", "size": "200", "side": "SELL", "hash": "b119eda5a1cb1283d34a16ebb7c47d2d71ac3437", "best_bid": "0.935", "best_ask": "0.941"}], "timestamp": "1769384213072", "event_type": "price_change"}}
{"_local_timestamp": "2026-01-25T23:36:53.456958+00:00", "data": {"market": "0xda5c517dd5b78c80dec8ceb08ca4f466317633487827d7290332b4851cc4a4fa", "price_changes": [{"asset_id": "16201530957950630406397949502319734794139620443510795733205872225099141120819", "price": "0.056", "size": "0", "side": "BUY", "hash": "98fbd257b0511cf701e2455d02e549eb65b9016e", "best_bid": "0.059", "best_ask": "0.065"}, {"asset_id": "22488814055465212843401871684243737932656687199587127613893702721105723939237", "price": "0.944", "size": "0", "side": "SELL", "hash": "c572a8d69f9881171bf21429cf7d0ecc07f59f06", "best_bid": "0.935", "best_ask": "0.941"}], "timestamp": "1769384213275", "event_type": "price_change"}}
{"_local_timestamp": "2026-01-25T23:36:53.484704+00:00", "data": {"market": "0xda5c517dd5b78c80dec8ceb08ca4f466317633487827d7290332b4851cc4a4fa", "price_changes": [{"asset_id": "16201530957950630406397949502319734794139620443510795733205872225099141120819", "price": "0.056", "size": "46", "side": "BUY", "hash": "7528888649332c55c2206f9ab56f6d893d326082", "best_bid": "0.059", "best_ask": "0.065"}, {"asset_id": "22488814055465212843401871684243737932656687199587127613893702721105723939237", "price": "0.944", "size": "46", "side": "SELL", "hash": "5b3a97dfd60fe656f9c7c8e50b76f89be6c7e9e8", "best_bid": "0.935", "best_ask": "0.941"}], "timestamp": "1769384213303", "event_type": "price_change"}}
{"_local_timestamp": "2026-01-25T23:36:54.712375+00:00", "data": {"market": "0xda5c517dd5b78c80dec8ceb08ca4f466317633487827d7290332b4851cc4a4fa", "price_changes": [{"asset_id": "22488814055465212843401871684243737932656687199587127613893702721105723939237", "price": "0.297", "size": "0", "side": "BUY", "hash": "6e360f0c1baf4a617b5122bce1962eeb116e6b7d", "best_bid": "0.935", "best_ask": "0.941"}, {"asset_id": "16201530957950630406397949502319734794139620443510795733205872225099141120819", "price": "0.703", "size": "0", "side": "SELL", "hash": "5b7ac92f428b7d8fdb6c5001bd9bca025533f8b6", "best_bid": "0.059", "best_ask": "0.065"}], "timestamp": "1769384214495", "event_type": "price_change"}}
{"_local_timestamp": "2026-01-25T23:36:54.987323+00:00", "data": {"market": "0xda5c517dd5b78c80dec8ceb08ca4f466317633487827d7290332b4851cc4a4fa", "price_changes": [{"asset_id": "16201530957950630406397949502319734794139620443510795733205872225099141120819", "price": "0.056", "size": "0", "side": "BUY", "hash": "c6c1aa4f118ce7c746b41112506e51cdf0f5ffb8", "best_bid": "0.059", "best_ask": "0.065"}, {"asset_id": "22488814055465212843401871684243737932656687199587127613893702721105723939237", "price": "0.944", "size": "0", "side": "SELL", "hash": "5eaa9cb4cec4a3d424ec0f743d87f74f0f48fb47", "best_bid": "0.935", "best_ask": "0.941"}], "timestamp": "1769384214780", "event_type": "price_change"}}
{"_local_timestamp": "2026-01-25T23:36:55.002736+00:00", "data": {"market": "0xda5c517dd5b78c80dec8ceb08ca4f466317633487827d7290332b4851cc4a4fa", "price_changes": [{"asset_id": "22488814055465212843401871684243737932656687199587127613893702721105723939237", "price": "0.297", "size": "5", "side": "BUY", "hash": "a924786dbfe623e666cc070bd5a2bd569867fa00", "best_bid": "0.935", "best_ask": "0.941"}, {"asset_id": "16201530957950630406397949502319734794139620443510795733205872225099141120819", "price": "0.703", "size": "5", "side": "SELL", "hash": "8698e2a73ee8db39f0f68a026489f5b52456f0c4", "best_bid": "0.059", "best_ask": "0.065"}], "timestamp": "1769384214799", "event_type": "price_change"}}
{"_local_timestamp": "2026-01-25T23:36:55.008993+00:00", "data": {"market": "0xda5c517dd5b78c80dec8ceb08ca4f466317633487827d7290332b4851cc4a4fa", "price_changes": [{"asset_id": "16201530957950630406397949502319734794139620443510795733205872225099141120819", "price": "0.056", "size": "46", "side": "BUY", "hash": "89d22a36d0bf93b5068c344c50460884da501f9e", "best_bid": "0.059", "best_ask": "0.065"}, {"asset_id": "22488814055465212843401871684243737932656687199587127613893702721105723939237", "price": "0.944", "size": "46", "side": "SELL", "hash": "45ce6160560dfb374d6ec27bfcac5ffe425e844b", "best_bid": "0.935", "best_ask": "0.941"}], "timestamp": "1769384214807", "event_type": "price_change"}}
{"_local_timestamp": "2026-01-25T23:36:55.317600+00:00", "data": {"market": "0xda5c517dd5b78c80dec8ceb08ca4f466317633487827d7290332b4851cc4a4fa", "price_changes": [{"asset_id": "22488814055465212843401871684243737932656687199587127613893702721105723939237", "price": "0.281", "size": "0", "side": "BUY", "hash": "fc202201f9a141b9fdf6ad76ac3bb02306f61df3", "best_bid": "0.935", "best_ask": "0.941"}, {"asset_id": "16201530957950630406397949502319734794139620443510795733205872225099141120819", "price": "0.719", "size": "0", "side": "SELL", "hash": "e527b2aca50ba11162a97ef1ead18adcf1efd61e", "best_bid": "0.059", "best_ask": "0.065"}], "timestamp": "1769384215032", "event_type": "price_change"}}
{"_local_timestamp": "2026-01-25T23:36:56.310570+00:00", "data": {"market": "0xda5c517dd5b78c80dec8ceb08ca4f466317633487827d7290332b4851cc4a4fa", "price_changes": [{"asset_id": "22488814055465212843401871684243737932656687199587127613893702721105723939237", "price": "0.25", "size": "1450", "side": "BUY", "hash": "a894c939cbacf5ac21d0426c99038ed7dc4554fe", "best_bid": "0.935", "best_ask": "0.941"}, {"asset_id": "16201530957950630406397949502319734794139620443510795733205872225099141120819", "price": "0.75", "size": "1450", "side": "SELL", "hash": "54bbd88555380104219b8fa96fe06d4fc17120a9", "best_bid": "0.059", "best_ask": "0.065"}], "timestamp": "1769384215710", "event_type": "price_change"}}
{"_local_timestamp": "2026-01-25T23:36:56.587163+00:00", "data": {"market": "0xda5c517dd5b78c80dec8ceb08ca4f466317633487827d7290332b4851cc4a4fa", "price_changes": [{"asset_id": "16201530957950630406397949502319734794139620443510795733205872225099141120819", "price": "0.056", "size": "0", "side": "BUY", "hash": "de9acba9c48105718dbe16791405d5422a8954d6", "best_bid": "0.059", "best_ask": "0.065"}, {"asset_id": "22488814055465212843401871684243737932656687199587127613893702721105723939237", "price": "0.944", "size": "0", "side": "SELL", "hash": "701cf00b487238021e641a7803bd03dbb1b47896", "best_bid": "0.935", "best_ask": "0.941"}], "timestamp": "1769384216277", "event_type": "price_change"}}
{"_local_timestamp": "2026-01-25T23:36:56.592895+00:00", "data": {"market": "0xda5c517dd5b78c80dec8ceb08ca4f466317633487827d7290332b4851cc4a4fa", "price_changes": [{"asset_id": "16201530957950630406397949502319734794139620443510795733205872225099141120819", "price": "0.055", "size": "350", "side": "BUY", "hash": "be2dd1a54bef2a858e74c910ac88a58106a9d667", "best_bid": "0.059", "best_ask": "0.065"}, {"asset_id": "22488814055465212843401871684243737932656687199587127613893702721105723939237", "price": "0.945", "size": "350", "side": "SELL", "hash": "c613123b0974afd586ab93c30b7db8b67eed8d33", "best_bid": "0.935", "best_ask": "0.941"}], "timestamp": "1769384216306", "event_type": "price_change"}}
{"_local_timestamp": "2026-01-25T23:36:57.273197+00:00", "data": {"market": "0xda5c517dd5b78c80dec8ceb08ca4f466317633487827d7290332b4851cc4a4fa", "price_changes": [{"asset_id": "16201530957950630406397949502319734794139620443510795733205872225099141120819", "price": "0.053", "size": "300", "side": "BUY", "hash": "00fe329870ddcf2e1d774f05f7536630dfbe4bae", "best_bid": "0.059", "best_ask": "0.065"}, {"asset_id": "22488814055465212843401871684243737932656687199587127613893702721105723939237", "price": "0.947", "size": "300", "side": "SELL", "hash": "524519c8586372d580ae4fde8a8c9192b7d6aeb2", "best_bid": "0.935", "best_ask": "0.941"}], "timestamp": "1769384217049", "event_type": "price_change"}}
{"_local_timestamp": "2026-01-25T23:36:57.273599+00:00", "data": {"market": "0xda5c517dd5b78c80dec8ceb08ca4f466317633487827d7290332b4851cc4a4fa", "price_changes": [{"asset_id": "22488814055465212843401871684243737932656687199587127613893702721105723939237", "price": "0.92", "size": "572.53", "side": "BUY", "hash": "0163efc2c81d8ed6e85f83c027af3ce39f46b0bd", "best_bid": "0.935", "best_ask": "0.941"}, {"asset_id": "16201530957950630406397949502319734794139620443510795733205872225099141120819", "price": "0.08", "size": "572.53", "side": "SELL", "hash": "5e67cda4d7d588e9232d9cd1e38c0f6b3d20c390", "best_bid": "0.059", "best_ask": "0.065"}], "timestamp": "1769384217050", "event_type": "price_change"}}
{"_local_timestamp": "2026-01-25T23:36:57.333647+00:00", "data": {"market": "0xda5c517dd5b78c80dec8ceb08ca4f466317633487827d7290332b4851cc4a4fa", "price_changes": [{"asset_id": "22488814055465212843401871684243737932656687199587127613893702721105723939237", "price": "0.297", "size": "0", "side": "BUY", "hash": "1e6e66580a9a9a18a2f39a9e7c99c516a44c6001", "best_bid": "0.935", "best_ask": "0.941"}, {"asset_id": "16201530957950630406397949502319734794139620443510795733205872225099141120819", "price": "0.703", "size": "0", "side": "SELL", "hash": "1ae30f9846a1428f9a54bb639a19f2b2431bebbc", "best_bid": "0.059", "best_ask": "0.065"}], "timestamp": "1769384217103", "event_type": "price_change"}}
{"_local_timestamp": "2026-01-25T23:36:57.983421+00:00", "data": {"market": "0xda5c517dd5b78c80dec8ceb08ca4f466317633487827d7290332b4851cc4a4fa", "price_changes": [{"asset_id": "22488814055465212843401871684243737932656687199587127613893702721105723939237", "price": "0.297", "size": "5", "side": "BUY", "hash": "ea12db04d73e98c8151fb7cb95436c612a626aa4", "best_bid": "0.935", "best_ask": "0.941"}, {"asset_id": "16201530957950630406397949502319734794139620443510795733205872225099141120819", "price": "0.703", "size": "5", "side": "SELL", "hash": "f1fcd943ddd613b62d58d9874c72547747b11d4b", "best_bid": "0.059", "best_ask": "0.065"}], "timestamp": "1769384217525", "event_type": "price_change"}}
{"_local_timestamp": "2026-01-25T23:36:58.045397+00:00", "data": {"market": "0xda5c517dd5b78c80dec8ceb08ca4f466317633487827d7290332b4851cc4a4fa", "price_changes": [{"asset_id": "16201530957950630406397949502319734794139620443510795733205872225099141120819", "price": "0.055", "size": "327", "side": "BUY", "hash": "89effe5a1680526db16c9248baf2f0fac7dc5db0", "best_bid": "0.059", "best_ask": "0.065"}, {"asset_id": "22488814055465212843401871684243737932656687199587127613893702721105723939237", "price": "0.945", "size": "327", "side": "SELL", "hash": "a4227ea099a95e08bb010b6d2ef6bdbfac583ec0", "best_bid": "0.935", "best_ask": "0.941"}], "timestamp": "1769384217775", "event_type": "price_change"}}
{"_local_timestamp": "2026-01-25T23:36:58.057935+00:00", "data": {"market": "0xda5c517dd5b78c80dec8ceb08ca4f466317633487827d7290332b4851cc4a4fa", "price_changes": [{"asset_id": "16201530957950630406397949502319734794139620443510795733205872225099141120819", "price": "0.055", "size": "381", "side": "BUY", "hash": "5ce5a149a2f5010fc48cc5c419a566de3342da6e", "best_bid": "0.059", "best_ask": "0.065"}, {"asset_id": "22488814055465212843401871684243737932656687199587127613893702721105723939237", "price": "0.945", "size": "381", "side": "SELL", "hash": "9d43243cef0e4d387cf144d64793c366fea826e0", "best_bid": "0.935", "best_ask": "0.941"}], "timestamp": "1769384217805", "event_type": "price_change"}}
{"_local_timestamp": "2026-01-25T23:36:58.634506+00:00", "data": {"market": "0xda5c517dd5b78c80dec8ceb08ca4f466317633487827d7290332b4851cc4a4fa", "price_changes": [{"asset_id": "22488814055465212843401871684243737932656687199587127613893702721105723939237", "price": "0.297", "size": "0", "side": "BUY", "hash": "547f62f26983108220abd0b526c0019778f7873d", "best_bid": "0.935", "best_ask": "0.941"}, {"asset_id": "16201530957950630406397949502319734794139620443510795733205872225099141120819", "price": "0.703", "size": "0", "side": "SELL", "hash": "e4c4b126d6cf0053f8e2a05ceee178bfef3563ff", "best_bid": "0.059", "best_ask": "0.065"}], "timestamp": "1769384218424", "event_type": "price_change"}}
{"_local_timestamp": "2026-01-25T23:36:59.142587+00:00", "data": {"market": "0xda5c517dd5b78c80dec8ceb08ca4f466317633487827d7290332b4851cc4a4fa", "price_changes": [{"asset_id": "22488814055465212843401871684243737932656687199587127613893702721105723939237", "price": "0.297", "size": "5", "side": "BUY", "hash": "41690af7ea2557cfb19eac3b8a421d3d33eaec1b", "best_bid": "0.935", "best_ask": "0.941"}, {"asset_id": "16201530957950630406397949502319734794139620443510795733205872225099141120819", "price": "0.703", "size": "5", "side": "SELL", "hash": "5f2229cc763125bc2d9b63c3ce59df2ca4b59226", "best_bid": "0.059", "best_ask": "0.065"}], "timestamp": "1769384218757", "event_type": "price_change"}}
{"_local_timestamp": "2026-01-25T23:37:00.862466+00:00", "data": {"market": "0xda5c517dd5b78c80dec8ceb08ca4f466317633487827d7290332b4851cc4a4fa", "price_changes": [{"asset_id": "16201530957950630406397949502319734794139620443510795733205872225099141120819", "price": "0.053", "size": "200", "side": "BUY", "hash": "94091d7ea9b3b37e201c59fa0d9f8e86a602f3f6", "best_bid": "0.059", "best_ask": "0.065"}, {"asset_id": "22488814055465212843401871684243737932656687199587127613893702721105723939237", "price": "0.947", "size": "200", "side": "SELL", "hash": "a11ac813f1c3890af792c8f10fbea034ed39cc35", "best_bid": "0.935", "best_ask": "0.941"}], "timestamp": "1769384220658", "event_type": "price_change"}}
{"_local_timestamp": "2026-01-25T23:37:00.862858+00:00", "data": {"market": "0xda5c517dd5b78c80dec8ceb08ca4f466317633487827d7290332b4851cc4a4fa", "price_changes": [{"asset_id": "22488814055465212843401871684243737932656687199587127613893702721105723939237", "price": "0.297", "size": "0", "side": "BUY", "hash": "ed6f2ceee8943d7cf58480dfb60344ecfd7c754c", "best_bid": "0.935", "best_ask": "0.941"}, {"asset_id": "16201530957950630406397949502319734794139620443510795733205872225099141120819", "price": "0.703", "size": "0", "side": "SELL", "hash": "fc14632695541603a07c29738722bbdcf6324d18", "best_bid": "0.059", "best_ask": "0.065"}], "timestamp": "1769384220664", "event_type": "price_change"}}
{"_local_timestamp": "2026-01-25T23:37:01.184650+00:00", "data": {"market": "0xda5c517dd5b78c80dec8ceb08ca4f466317633487827d7290332b4851cc4a4fa", "price_changes": [{"asset_id": "22488814055465212843401871684243737932656687199587127613893702721105723939237", "price": "0.297", "size": "5", "side": "BUY", "hash": "05eb56f2254f28ffa7e71c16fd15ea20c542e487", "best_bid": "0.935", "best_ask": "0.941"}, {"asset_id": "16201530957950630406397949502319734794139620443510795733205872225099141120819", "price": "0.703", "size": "5", "side": "SELL", "hash": "3c299057f6d1bc3a6e971ab2c5c35cfe87141135", "best_bid": "0.059", "best_ask": "0.065"}], "timestamp": "1769384220998", "event_type": "price_change"}}
{"_local_timestamp": "2026-01-25T23:37:02.584629+00:00", "data": {"market": "0xda5c517dd5b78c80dec8ceb08ca4f466317633487827d7290332b4851cc4a4fa", "price_changes": [{"asset_id": "22488814055465212843401871684243737932656687199587127613893702721105723939237", "price": "0.297", "size": "0", "side": "BUY", "hash": "14651c166e4b500ba5e25c58dfdd32f72c5b1292", "best_bid": "0.935", "best_ask": "0.941"}, {"asset_id": "16201530957950630406397949502319734794139620443510795733205872225099141120819", "price": "0.703", "size": "0", "side": "SELL", "hash": "868f9cd191af99a0e9f5eeac1e7600b486a5c9db", "best_bid": "0.059", "best_ask": "0.065"}], "timestamp": "1769384222406", "event_type": "price_change"}}
{"_local_timestamp": "2026-01-25T23:37:02.974445+00:00", "data": {"market": "0xda5c517dd5b78c80dec8ceb08ca4f466317633487827d7290332b4851cc4a4fa", "price_changes": [{"asset_id": "22488814055465212843401871684243737932656687199587127613893702721105723939237", "price": "0.297", "size": "5", "side": "BUY", "hash": "ebe3a94fc42c7f5887338a0134ddfe02590a4737", "best_bid": "0.935", "best_ask": "0.941"}, {"asset_id": "16201530957950630406397949502319734794139620443510795733205872225099141120819", "price": "0.703", "size": "5", "side": "SELL", "hash": "8c74db3862d30dd94d707ea2b1719eb2f8d3218c", "best_bid": "0.059", "best_ask": "0.065"}], "timestamp": "1769384222787", "event_type": "price_change"}}
{"_local_timestamp": "2026-01-25T23:37:04.690824+00:00", "data": {"market": "0xda5c517dd5b78c80dec8ceb08ca4f466317633487827d7290332b4851cc4a4fa", "price_changes": [{"asset_id": "16201530957950630406397949502319734794139620443510795733205872225099141120819", "price": "0.052", "size": "300", "side": "BUY", "hash": "08eb05780041e5981b0910ac567f1f3348b20ce3", "best_bid": "0.059", "best_ask": "0.065"}, {"asset_id": "22488814055465212843401871684243737932656687199587127613893702721105723939237", "price": "0.948", "size": "300", "side": "SELL", "hash": "c7dcde3e65387bccc43dec9ca70e19805cb7af87", "best_bid": "0.935", "best_ask": "0.941"}], "timestamp": "1769384224479", "event_type": "price_change"}}
{"_local_timestamp": "2026-01-25T23:37:04.698206+00:00", "data": {"market": "0xda5c517dd5b78c80dec8ceb08ca4f466317633487827d7290332b4851cc4a4fa", "price_changes": [{"asset_id": "22488814055465212843401871684243737932656687199587127613893702721105723939237", "price": "0.297", "size": "0", "side": "BUY", "hash": "27c2c45449716764fbb8582c0351c87600f40263", "best_bid": "0.935", "best_ask": "0.941"}, {"asset_id": "16201530957950630406397949502319734794139620443510795733205872225099141120819", "price": "0.703", "size": "0", "side": "SELL", "hash": "b344a07fa184bc13ec73d8255dd3d48fe93b90c6", "best_bid": "0.059", "best_ask": "0.065"}], "timestamp": "1769384224495", "event_type": "price_change"}}
{"_local_timestamp": "2026-01-25T23:37:05.083911+00:00", "data": {"market": "0xda5c517dd5b78c80dec8ceb08ca4f466317633487827d7290332b4851cc4a4fa", "price_changes": [{"asset_id": "22488814055465212843401871684243737932656687199587127613893702721105723939237", "price": "0.297", "size": "5", "side": "BUY", "hash": "ddde32fbbb5575c0f1cf38d9bdc15437dfbbbbc9", "best_bid": "0.935", "best_ask": "0.941"}, {"asset_id": "16201530957950630406397949502319734794139620443510795733205872225099141120819", "price": "0.703", "size": "5", "side": "SELL", "hash": "789b4fdc265d767daf1f691c6cffe849c0d12b43", "best_bid": "0.059", "best_ask": "0.065"}], "timestamp": "1769384224862", "event_type": "price_change"}}
{"_local_timestamp": "2026-01-25T23:37:06.050581+00:00", "data": {"market": "0xda5c517dd5b78c80dec8ceb08ca4f466317633487827d7290332b4851cc4a4fa", "price_changes": [{"asset_id": "16201530957950630406397949502319734794139620443510795733205872225099141120819", "price": "0.057", "size": "0", "side": "BUY", "hash": "38d54eef275108dd3f49303f6b320bdcff9fadf8", "best_bid": "0.059", "best_ask": "0.065"}, {"asset_id": "22488814055465212843401871684243737932656687199587127613893702721105723939237", "price": "0.943", "size": "0", "side": "SELL", "hash": "fc8c20632450891f848a73a712e26b6017972fc4", "best_bid": "0.935", "best_ask": "0.941"}], "timestamp": "1769384225832", "event_type": "price_change"}}
{"_local_timestamp": "2026-01-25T23:37:07.252231+00:00", "data": {"market": "0xda5c517dd5b78c80dec8ceb08ca4f466317633487827d7290332b4851cc4a4fa", "price_changes": [{"asset_id": "22488814055465212843401871684243737932656687199587127613893702721105723939237", "price": "0.297", "size": "0", "side": "BUY", "hash": "6ee4a0289ae1b07ce57269550b1f7a3ab3e627d8", "best_bid": "0.935", "best_ask": "0.941"}, {"asset_id": "16201530957950630406397949502319734794139620443510795733205872225099141120819", "price": "0.703", "size": "0", "side": "SELL", "hash": "84b0be7a0e93d485da3ebe354edba809778e2709", "best_bid": "0.059", "best_ask": "0.065"}], "timestamp": "1769384227069", "event_type": "price_change"}}
{"_local_timestamp": "2026-01-25T23:37:07.595628+00:00", "data": {"market": "0xda5c517dd5b78c80dec8ceb08ca4f466317633487827d7290332b4851cc4a4fa", "price_changes": [{"asset_id": "16201530957950630406397949502319734794139620443510795733205872225099141120819", "price": "0.052", "size": "200", "side": "BUY", "hash": "832a022cd20500c7927f2f43073a7f8731069a4d", "best_bid": "0.059", "best_ask": "0.065"}, {"asset_id": "22488814055465212843401871684243737932656687199587127613893702721105723939237", "price": "0.948", "size": "200", "side": "SELL", "hash": "d27a2a969dbc9fac726a05469999ee1a1731d005", "best_bid": "0.935", "best_ask": "0.941"}], "timestamp": "1769384227422", "event_type": "price_change"}}
{"_local_timestamp": "2026-01-25T23:37:07.607850+00:00", "data": {"market": "0xda5c517dd5b78c80dec8ceb08ca4f466317633487827d7290332b4851cc4a4fa", "price_changes": [{"asset_id": "22488814055465212843401871684243737932656687199587127613893702721105723939237", "price": "0.297", "size": "5", "side": "BUY", "hash": "e15bc0a3318151f60fa9aea2aa7d6b6a81a424e6", "best_bid": "0.935", "best_ask": "0.941"}, {"asset_id": "16201530957950630406397949502319734794139620443510795733205872225099141120819", "price": "0.703", "size": "5", "side": "SELL", "hash": "ea4051edc6c9b1538ec13a50018cf22e18319db3", "best_bid": "0.059", "best_ask": "0.065"}], "timestamp": "1769384227441", "event_type": "price_change"}}
{"_local_timestamp": "2026-01-25T23:37:08.868313+00:00", "data": {"market": "0xda5c517dd5b78c80dec8ceb08ca4f466317633487827d7290332b4851cc4a4fa", "price_changes": [{"asset_id": "22488814055465212843401871684243737932656687199587127613893702721105723939237", "price": "0.297", "size": "0", "side": "BUY", "hash": "edc677589f5e47f770acf8c9b432d3ce048df3df", "best_bid": "0.935", "best_ask": "0.941"}, {"asset_id": "16201530957950630406397949502319734794139620443510795733205872225099141120819", "price": "0.703", "size": "0", "side": "SELL", "hash": "a4f43d8279729345b1dc73fb262eca341c16c60c", "best_bid": "0.059", "best_ask": "0.065"}], "timestamp": "1769384228803", "event_type": "price_change"}}
{"_local_timestamp": "2026-01-25T23:37:09.198157+00:00", "data": {"market": "0xda5c517dd5b78c80dec8ceb08ca4f466317633487827d7290332b4851cc4a4fa", "price_changes": [{"asset_id": "22488814055465212843401871684243737932656687199587127613893702721105723939237", "price": "0.297", "size": "5", "side": "BUY", "hash": "8ca8ea245b6886cc7fa0ed86eb074b2fbde09570", "best_bid": "0.935", "best_ask": "0.941"}, {"asset_id": "16201530957950630406397949502319734794139620443510795733205872225099141120819", "price": "0.703", "size": "5", "side": "SELL", "hash": "39ee54bc88a462fc2ded9adecf81321798996362", "best_bid": "0.059", "best_ask": "0.065"}], "timestamp": "1769384229128", "event_type": "price_change"}}
{"_local_timestamp": "2026-01-25T23:37:09.345599+00:00", "data": {"market": "0xda5c517dd5b78c80dec8ceb08ca4f466317633487827d7290332b4851cc4a4fa", "price_changes": [{"asset_id": "16201530957950630406397949502319734794139620443510795733205872225099141120819", "price": "0.003", "size": "23672.09", "side": "BUY", "hash": "0a9f0a4e73e9d0e5dee8f487d29f602609425cf8", "best_bid": "0.059", "best_ask": "0.065"}, {"asset_id": "22488814055465212843401871684243737932656687199587127613893702721105723939237", "price": "0.997", "size": "23672.09", "side": "SELL", "hash": "55fd85908916976ce124df46a9ab188b58df76b8", "best_bid": "0.935", "best_ask": "0.941"}], "timestamp": "1769384229280", "event_type": "price_change"}}
{"_local_timestamp": "2026-01-25T23:37:09.346622+00:00", "data": {"market": "0xda5c517dd5b78c80dec8ceb08ca4f466317633487827d7290332b4851cc4a4fa", "price_changes": [{"asset_id": "16201530957950630406397949502319734794139620443510795733205872225099141120819", "price": "0.023", "size": "1218", "side": "BUY", "hash": "0a9f0a4e73e9d0e5dee8f487d29f602609425cf8", "best_bid": "0.059", "best_ask": "0.065"}, {"asset_id": "22488814055465212843401871684243737932656687199587127613893702721105723939237", "price": "0.977", "size": "1218", "side": "SELL", "hash": "55fd85908916976ce124df46a9ab188b58df76b8", "best_bid": "0.935", "best_ask": "0.941"}], "timestamp": "1769384229280", "event_type": "price_change"}}
{"_local_timestamp": "2026-01-25T23:37:09.346901+00:00", "data": {"market": "0xda5c517dd5b78c80dec8ceb08ca4f466317633487827d7290332b4851cc4a4fa", "price_changes": [{"asset_id": "16201530957950630406397949502319734794139620443510795733205872225099141120819", "price": "0.034", "size": "530", "side": "BUY", "hash": "0a9f0a4e73e9d0e5dee8f487d29f602609425cf8", "best_bid": "0.059", "best_ask": "0.065"}, {"asset_id": "22488814055465212843401871684243737932656687199587127613893702721105723939237", "price": "0.966", "size": "530", "side": "SELL", "hash": "55fd85908916976ce124df46a9ab188b58df76b8", "best_bid": "0.935", "best_ask": "0.941"}], "timestamp": "1769384229280", "event_type": "price_change"}}
{"_local_timestamp": "2026-01-25T23:37:09.350591+00:00", "data": {"market": "0xda5c517dd5b78c80dec8ceb08ca4f466317633487827d7290332b4851cc4a4fa", "price_changes": [{"asset_id": "16201530957950630406397949502319734794139620443510795733205872225099141120819", "price": "0.058", "size": "30", "side": "BUY", "hash": "0a9f0a4e73e9d0e5dee8f487d29f602609425cf8", "best_bid": "0.059", "best_ask": "0.065"}, {"asset_id": "22488814055465212843401871684243737932656687199587127613893702721105723939237", "price": "0.942", "size": "30", "side": "SELL", "hash": "55fd85908916976ce124df46a9ab188b58df76b8", "best_bid": "0.935", "best_ask": "0.941"}], "timestamp": "1769384229280", "event_type": "price_change"}}
{"_local_timestamp": "2026-01-25T23:37:09.350971+00:00", "data": {"market": "0xda5c517dd5b78c80dec8ceb08ca4f466317633487827d7290332b4851cc4a4fa", "price_changes": [{"asset_id": "16201530957950630406397949502319734794139620443510795733205872225099141120819", "price": "0.031", "size": "742", "side": "BUY", "hash": "0a9f0a4e73e9d0e5dee8f487d29f602609425cf8", "best_bid": "0.059", "best_ask": "0.065"}, {"asset_id": "22488814055465212843401871684243737932656687199587127613893702721105723939237", "price": "0.969", "size": "742", "side": "SELL", "hash": "55fd85908916976ce124df46a9ab188b58df76b8", "best_bid": "0.935", "best_ask": "0.941"}], "timestamp": "1769384229280", "event_type": "price_change"}}
{"_local_timestamp": "2026-01-25T23:37:09.351287+00:00", "data": {"market": "0xda5c517dd5b78c80dec8ceb08ca4f466317633487827d7290332b4851cc4a4fa", "price_changes": [{"asset_id": "16201530957950630406397949502319734794139620443510795733205872225099141120819", "price": "0.051", "size": "9121.81", "side": "BUY", "hash": "0a9f0a4e73e9d0e5dee8f487d29f602609425cf8", "best_bid": "0.059", "best_ask": "0.065"}, {"asset_id": "22488814055465212843401871684243737932656687199587127613893702721105723939237", "price": "0.949", "size": "9121.81", "side": "SELL", "hash": "55fd85908916976ce124df46a9ab188b58df76b8", "best_bid": "0.935", "best_ask": "0.941"}], "timestamp": "1769384229280", "event_type": "price_change"}}
{"_local_timestamp": "2026-01-25T23:37:09.351565+00:00", "data": {"market": "0xda5c517dd5b78c80dec8ceb08ca4f466317633487827d7290332b4851cc4a4fa", "price_changes": [{"asset_id": "16201530957950630406397949502319734794139620443510795733205872225099141120819", "price": "0.045", "size": "267", "side": "BUY", "hash": "0a9f0a4e73e9d0e5dee8f487d29f602609425cf8", "best_bid": "0.059", "best_ask": "0.065"}, {"asset_id": "22488814055465212843401871684243737932656687199587127613893702721105723939237", "price": "0.955", "size": "267", "side": "SELL", "hash": "55fd85908916976ce124df46a9ab188b58df76b8", "best_bid": "0.935", "best_ask": "0.941"}], "timestamp": "1769384229280", "event_type": "price_change"}}
{"_local_timestamp": "2026-01-25T23:37:09.351816+00:00", "data": {"market": "0xda5c517dd5b78c80dec8ceb08ca4f466317633487827d7290332b4851cc4a4fa", "price_changes": [{"asset_id": "16201530957950630406397949502319734794139620443510795733205872225099141120819", "price": "0.013", "size": "3469.11", "side": "BUY", "hash": "0a9f0a4e73e9d0e5dee8f487d29f602609425cf8", "best_bid": "0.059", "best_ask": "0.065"}, {"asset_id": "22488814055465212843401871684243737932656687199587127613893702721105723939237", "price": "0.987", "size": "3469.11", "side": "SELL", "hash": "55fd85908916976ce124df46a9ab188b58df76b8", "best_bid": "0.935", "best_ask": "0.941"}], "timestamp": "1769384229280", "event_type": "price_change"}}
{"_local_timestamp": "2026-01-25T23:37:09.352108+00:00", "data": {"market": "0xda5c517dd5b78c80dec8ceb08ca4f466317633487827d7290332b4851cc4a4fa", "price_changes": [{"asset_id": "16201530957950630406397949502319734794139620443510795733205872225099141120819", "price": "0.01", "size": "10712.68", "side": "BUY", "hash": "0a9f0a4e73e9d0e5dee8f487d29f602609425cf8", "best_bid": "0.059", "best_ask": "0.065"}, {"asset_id": "22488814055465212843401871684243737932656687199587127613893702721105723939237", "price": "0.99", "size": "10712.68", "side": "SELL", "hash": "55fd85908916976ce124df46a9ab188b58df76b8", "best_bid": "0.935", "best_ask": "0.941"}], "timestamp": "1769384229280", "event_type": "price_change"}}
{"_local_timestamp": "2026-01-25T23:37:09.357429+00:00", "data": {"market": "0xda5c517dd5b78c80dec8ceb08ca4f466317633487827d7290332b4851cc4a4fa", "price_changes": [{"asset_id": "16201530957950630406397949502319734794139620443510795733205872225099141120819", "price": "0.02", "size": "14350", "side": "BUY", "hash": "0a9f0a4e73e9d0e5dee8f487d29f602609425cf8", "best_bid": "0.059", "best_ask": "0.065"}, {"asset_id": "22488814055465212843401871684243737932656687199587127613893702721105723939237", "price": "0.98", "size": "14350", "side": "SELL", "hash": "55fd85908916976ce124df46a9ab188b58df76b8", "best_bid": "0.935", "best_ask": "0.941"}], "timestamp": "1769384229280", "event_type": "price_change"}}
{"_local_timestamp": "2026-01-25T23:37:09.478379+00:00", "data": {"market": "0xda5c517dd5b78c80dec8ceb08ca4f466317633487827d7290332b4851cc4a4fa", "price_changes": [{"asset_id": "16201530957950630406397949502319734794139620443510795733205872225099141120819", "price": "0.055", "size": "217", "side": "BUY", "hash": "0a9f0a4e73e9d0e5dee8f487d29f602609425cf8", "best_bid": "0.059", "best_ask": "0.065"}, {"asset_id": "22488814055465212843401871684243737932656687199587127613893702721105723939237", "price": "0.945", "size": "217", "side": "SELL", "hash": "55fd85908916976ce124df46a9ab188b58df76b8", "best_bid": "0.935", "best_ask": "0.941"}], "timestamp": "1769384229280", "event_type": "price_change"}}
{"_local_timestamp": "2026-01-25T23:37:09.478756+00:00", "data": {"market": "0xda5c517dd5b78c80dec8ceb08ca4f466317633487827d7290332b4851cc4a4fa", "price_changes": [{"asset_id": "16201530957950630406397949502319734794139620443510795733205872225099141120819", "price": "0.038", "size": "369", "side": "BUY", "hash": "0a9f0a4e73e9d0e5dee8f487d29f602609425cf8", "best_bid": "0.059", "best_ask": "0.065"}, {"asset_id": "22488814055465212843401871684243737932656687199587127613893702721105723939237", "price": "0.962", "size": "369", "side": "SELL", "hash": "55fd85908916976ce124df46a9ab188b58df76b8", "best_bid": "0.935", "best_ask": "0.941"}], "timestamp": "1769384229280", "event_type": "price_change"}}
{"_local_timestamp": "2026-01-25T23:37:09.479013+00:00", "data": {"market": "0xda5c517dd5b78c80dec8ceb08ca4f466317633487827d7290332b4851cc4a4fa", "price_changes": [{"asset_id": "16201530957950630406397949502319734794139620443510795733205872225099141120819", "price": "0.053", "size": "370", "side": "BUY", "hash": "3b5d0818d19d95d71bc9453431f1a8d8a76823f5", "best_bid": "0.059", "best_ask": "0.065"}, {"asset_id": "22488814055465212843401871684243737932656687199587127613893702721105723939237", "price": "0.947", "size": "370", "side": "SELL", "hash": "394754109c4a0dc8d48ed57af32bdc0c6ceb9564", "best_bid": "0.935", "best_ask": "0.941"}], "timestamp": "1769384229317", "event_type": "price_change"}}
{"_local_timestamp": "2026-01-25T23:37:09.479265+00:00", "data": {"market": "0xda5c517dd5b78c80dec8ceb08ca4f466317633487827d7290332b4851cc4a4fa", "price_changes": [{"asset_id": "16201530957950630406397949502319734794139620443510795733205872225099141120819", "price": "0.056", "size": "125", "side": "BUY", "hash": "8272465df0dc507d0ff07f84b7110e72c11627c1", "best_bid": "0.059", "best_ask": "0.065"}, {"asset_id": "22488814055465212843401871684243737932656687199587127613893702721105723939237", "price": "0.944", "size": "125", "side": "SELL", "hash": "ba316f1d99d943a8aa23bcf44b21eea88ecd7968", "best_bid": "0.935", "best_ask": "0.941"}], "timestamp": "1769384229318", "event_type": "price_change"}}
{"_local_timestamp": "2026-01-25T23:37:09.908470+00:00", "data": {"market": "0xda5c517dd5b78c80dec8ceb08ca4f466317633487827d7290332b4851cc4a4fa", "price_changes": [{"asset_id": "16201530957950630406397949502319734794139620443510795733205872225099141120819", "price": "0.058", "size": "0", "side": "BUY", "hash": "3caa726291d80fd5edb6833caf2847416b69655c", "best_bid": "0.059", "best_ask": "0.065"}, {"asset_id": "22488814055465212843401871684243737932656687199587127613893702721105723939237", "price": "0.942", "size": "0", "side": "SELL", "hash": "cedeee47a0dd3d930d0d032bd4b8ef6fc0dcc1b5", "best_bid": "0.935", "best_ask": "0.941"}], "timestamp": "1769384229841", "event_type": "price_change"}}
{"_local_timestamp": "2026-01-25T23:37:09.966159+00:00", "data": {"market": "0xda5c517dd5b78c80dec8ceb08ca4f466317633487827d7290332b4851cc4a4fa", "price_changes": [{"asset_id": "16201530957950630406397949502319734794139620443510795733205872225099141120819", "price": "0.056", "size": "155", "side": "BUY", "hash": "73d273abf36d8c70f720f870dd385df7e759b7d4", "best_bid": "0.059", "best_ask": "0.065"}, {"asset_id": "22488814055465212843401871684243737932656687199587127613893702721105723939237", "price": "0.944", "size": "155", "side": "SELL", "hash": "2ef714c74b76699835135e1329d214f0320bce39", "best_bid": "0.935", "best_ask": "0.941"}], "timestamp": "1769384229889", "event_type": "price_change"}}
{"_local_timestamp": "2026-01-25T23:37:11.287263+00:00", "data": {"market": "0xda5c517dd5b78c80dec8ceb08ca4f466317633487827d7290332b4851cc4a4fa", "price_changes": [{"asset_id": "16201530957950630406397949502319734794139620443510795733205872225099141120819", "price": "0.052", "size": "300", "side": "BUY", "hash": "54d5356d84ce111fe3a7b73e317f76ff19b5841e", "best_bid": "0.059", "best_ask": "0.065"}, {"asset_id": "22488814055465212843401871684243737932656687199587127613893702721105723939237", "price": "0.948", "size": "300", "side": "SELL", "hash": "910f0c9724260211fdc34f6c9dae5f68eb1f12dd", "best_bid": "0.935", "best_ask": "0.941"}], "timestamp": "1769384231220", "event_type": "price_change"}}
{"_local_timestamp": "2026-01-25T23:37:11.388431+00:00", "data": {"market": "0xda5c517dd5b78c80dec8ceb08ca4f466317633487827d7290332b4851cc4a4fa", "price_changes": [{"asset_id": "22488814055465212843401871684243737932656687199587127613893702721105723939237", "price": "0.934", "size": "30", "side": "BUY", "hash": "665c85806be56d14f020d49293a8ec747caf8af0", "best_bid": "0.935", "best_ask": "0.941"}, {"asset_id": "16201530957950630406397949502319734794139620443510795733205872225099141120819", "price": "0.066", "size": "30", "side": "SELL", "hash": "00ce5dae26c60d73e8357062c4f6ac17d59b4216", "best_bid": "0.059", "best_ask": "0.065"}], "timestamp": "1769384231320", "event_type": "price_change"}}
{"_local_timestamp": "2026-01-25T23:37:12.146035+00:00", "data": {"market": "0xda5c517dd5b78c80dec8ceb08ca4f466317633487827d7290332b4851cc4a4fa", "price_changes": [{"asset_id": "22488814055465212843401871684243737932656687199587127613893702721105723939237", "price": "0.297", "size": "0", "side": "BUY", "hash": "f845362ce5a7543c7b7d50e74b8b68ed6445c3f5", "best_bid": "0.935", "best_ask": "0.941"}, {"asset_id": "16201530957950630406397949502319734794139620443510795733205872225099141120819", "price": "0.703", "size": "0", "side": "SELL", "hash": "4dc17196edd70d88c15aae5ea80fef9a9de54be9", "best_bid": "0.059", "best_ask": "0.065"}], "timestamp": "1769384232080", "event_type": "price_change"}}
{"_local_timestamp": "2026-01-25T23:37:12.563720+00:00", "data": {"market": "0xda5c517dd5b78c80dec8ceb08ca4f466317633487827d7290332b4851cc4a4fa", "price_changes": [{"asset_id": "22488814055465212843401871684243737932656687199587127613893702721105723939237", "price": "0.297", "size": "5", "side": "BUY", "hash": "25c04611b67882aa61c69f08218ee6ceefa7ec95", "best_bid": "0.935", "best_ask": "0.941"}, {"asset_id": "16201530957950630406397949502319734794139620443510795733205872225099141120819", "price": "0.703", "size": "5", "side": "SELL", "hash": "7359e6ad3133d6caa1cd4e1b7417a75a2dad60e4", "best_bid": "0.059", "best_ask": "0.065"}], "timestamp": "1769384232493", "event_type": "price_change"}}
