{"_local_timestamp": "2026-01-25T23:33:18.965115+00:00", "data": [{"market": "0x3bb5ceb45e186de77b1faaf56abf427c8c6f1a88532e4a0dc0ad9c1ffdac2a39", "asset_id": "77481318171335047328591651032911896763491342646014093639934301019258606619150", "timestamp": "1769383920817", "hash": "b2cb756695419824f386c83774c1a861aba11d86", "bids": [], "asks": [{"price": "0.999", "size": "2015.85"}, {"price": "0.998", "size": "5.83"}, {"price": "0.997", "size": "1000"}, {"price": "0.996", "size": "10.09"}, {"price": "0.99", "size": "5518"}, {"price": "0.989", "size": "5.63"}, {"price": "0.98", "size": "2200"}, {"price": "0.979", "size": "250"}, {"price": "0.978", "size": "9.37"}, {"price": "0.95", "size": "10"}, {"price": "0.94", "size": "500"}, {"price": "0.939", "size": "9.71"}, {"price": "0.9", "size": "860"}, {"price": "0.85", "size": "776.66"}, {"price": "0.8", "size": "660"}, {"price": "0.799", "size": "5.38"}, {"price": "0.777", "size": "423"}, {"price": "0.75", "size": "112"}, {"price": "0.7", "size": "136.66"}, {"price": "0.689", "size": "100"}, {"price": "0.65", "size": "68.57"}, {"price": "0.6", "size": "189"}, {"price": "0.599", "size": "5938"}, {"price": "0.598", "size": "5"}, {"price": "0.5", "size": "150"}, {"price": "0.477", "size": "184"}, {"price": "0.277", "size": "24"}, {"price": "0.177", "size": "138"}, {"price": "0.127", "size": "42.98"}, {"price": "0.077", "size": "1471"}, {"price": "0.068", "size": "13"}, {"price": "0.003", "size": "456.63"}, {"price": "0.002", "size": "2500"}, {"price": "0.001", "size": "5252.61"}], "event_type": "book", "last_trade_price": ""}, {"market": "0xd33b405694c28eb7ea092d5146085fe9234fffa467b4449b068a11f4762aa527", "asset_id": "100610158895422953936472708271328576009207076613232354004933524717835418544370", "timestamp": "1769383921200", "hash": "280ee36ec69490d4f09ece4739f3288974f13088", "bids": [{"price": "0.001", "size": "2015.85"}, {"price": "0.002", "size": "5.83"}, {"price": "0.003", "size": "1000"}, {"price": "0.004", "size": "10.09"}, {"price": "0.01", "size": "5518"}, {"price": "0.011", "size": "5.13"}, {"price": "0.02", "size": "1000"}, {"price": "0.021", "size": "10.08"}, {"price": "0.05", "size": "1910"}, {"price": "0.051", "size": "250"}, {"price": "0.06", "size": "500"}, {"price": "0.061", "size": "9.71"}, {"price": "0.1", "size": "560"}, {"price": "0.15", "size": "826.66"}, {"price": "0.17", "size": "400"}, {"price": "0.2", "size": "160"}, {"price": "0.201", "size": "5.38"}, {"price": "0.223", "size": "11"}, {"price": "0.25", "size": "412"}, {"price": "0.3", "size": "186.66"}, {"price": "0.31", "size": "100"}, {"price": "0.35", "size": "68.57"}, {"price": "0.4", "size": "175"}, {"price": "0.523", "size": "255"}, {"price": "0.524", "size": "4552"}, {"price": "0.525", "size": "5"}, {"price": "0.71", "size": "150"}, {"price": "0.723", "size": "17"}, {"price": "0.823", "size": "109"}, {"price": "0.92", "size": "19"}, {"price": "0.923", "size": "937"}, {"price": "0.995", "size": "70"}, {"price": "0.997", "size": "47.99"}, {"price": "0.998", "size": "2204.69"}, {"price": "0.999", "size": "1808.67"}], "asks": [], "event_type": "book", "last_trade_price": "0.001"}, {"market": "0x9248190b831a98a8996cbf370e731312e380c59b1969dcd22d6eab6f831d95f4", "asset_id": "37461989084413653734795809421098376373424254817858315797538209587257222021969", "timestamp": "1769383921970", "hash": "1ae22a3d323b6754d1be5c2891e91b99e18452d8", "bids": [{"price": "0.001", "size": "6088.87"}], "asks": [{"price": "0.999", "size": "3800.85"}, {"price": "0.998", "size": "1255.83"}, {"price": "0.997", "size": "1400"}, {"price": "0.996", "size": "10.09"}, {"price": "0.994", "size": "200"}, {"price": "0.99", "size": "5516"}, {"price": "0.989", "size": "5.13"}, {"price": "0.98", "size": "2200"}, {"price": "0.979", "size": "10.08"}, {"price": "0.95", "size": "30"}, {"price": "0.949", "size": "39"}, {"price": "0.94", "size": "500"}, {"price": "0.939", "size": "9.71"}, {"price": "0.9", "size": "860"}, {"price": "0.899", "size": "250"}, {"price": "0.85", "size": "776.66"}, {"price": "0.8", "size": "660"}, {"price": "0.799", "size": "5.38"}, {"price": "0.777", "size": "504"}, {"price": "0.75", "size": "112"}, {"price": "0.7", "size": "186.66"}, {"price": "0.65", "size": "68.57"}, {"price": "0.6", "size": "175"}, {"price": "0.477", "size": "274"}, {"price": "0.277", "size": "433"}, {"price": "0.276", "size": "3298"}, {"price": "0.27", "size": "150"}, {"price": "0.177", "size": "139"}, {"price": "0.176", "size": "20"}, {"price": "0.08", "size": "19"}, {"price": "0.077", "size": "703"}, {"price": "0.051", "size": "32"}, {"price": "0.039", "size": "20"}, {"price": "0.005", "size": "70"}, {"price": "0.003", "size": "80.62"}, {"price": "0.002", "size": "4549.66"}], "event_type": "book", "last_trade_price": ""}, {"market": "0xd33b405694c28eb7ea092d5146085fe9234fffa467b4449b068a11f4762aa527", "asset_id": "40582400653155619328075956469552500170030522046193955547557477713370279563057", "timestamp": "1769383921200", "hash": "f5776e38219968f8c576ee0fa5bb17b1cbd7baba", "bids": [], "asks": [{"price": "0.999", "size": "2015.85"}, {"price": "0.998", "size": "5.83"}, {"price": "0.997", "size": "1000"}, {"price": "0.996", "size": "10.09"}, {"price": "0.99", "size": "5518"}, {"price": "0.989", "size": "5.13"}, {"price": "0.98", "size": "1000"}, {"price": "0.979", "size": "10.08"}, {"price": "0.95", "size": "1910"}, {"price": "0.949", "size": "250"}, {"price": "0.94", "size": "500"}, {"price": "0.939", "size": "9.71"}, {"price": "0.9", "size": "560"}, {"price": "0.85", "size": "826.66"}, {"price": "0.83", "size": "400"}, {"price": "0.8", "size": "160"}, {"price": "0.799", "size": "5.38"}, {"price": "0.777", "size": "11"}, {"price": "0.75", "size": "412"}, {"price": "0.7", "size": "186.66"}, {"price": "0.69", "size": "100"}, {"price": "0.65", "size": "68.57"}, {"price": "0.6", "size": "175"}, {"price": "0.477", "size": "255"}, {"price": "0.476", "size": "4552"}, {"price": "0.475", "size": "5"}, {"price": "0.29", "size": "150"}, {"price": "0.277", "size": "17"}, {"price": "0.177", "size": "109"}, {"price": "0.08", "size": "19"}, {"price": "0.077", "size": "937"}, {"price": "0.005", "size": "70"}, {"price": "0.003", "size": "47.99"}, {"price": "0.002", "size": "2204.69"}, {"price": "0.001", "size": "1808.67"}], "event_type": "book", "last_trade_price": "0.001"}, {"market": "0x690d504367efdec61936e7dc1c572c1598281f3e91d30d3b6148f3f1f48642d5", "asset_id": "36538842701383075131399258783814730353525125143988435459349182813934073807848", "timestamp": "1769383996000", "hash": "217c24dc5df8667416e8544d7de2aa916c1a5282", "bids": [{"price": "0.01", "size": "10500"}, {"price": "0.02", "size": "2450"}, {"price": "0.03", "size": "9.52"}, {"price": "0.07", "size": "500"}, {"price": "0.08", "size": "3794"}, {"price": "0.12", "size": "3225"}, {"price": "0.15", "size": "820"}, {"price": "0.2", "size": "1000"}, {"price": "0.21", "size": "2000"}, {"price": "0.22", "size": "555"}, {"price": "0.23", "size": "500"}, {"price": "0.27", "size": "850"}, {"price": "0.3", "size": "112.5"}, {"price": "0.31", "size": "1735.05"}, {"price": "0.32", "size": "1010.59"}], "asks": [{"price": "0.99", "size": "5506.25"}, {"price": "0.98", "size": "2206.02"}, {"price": "0.97", "size": "250"}, {"price": "0.96", "size": "5.57"}, {"price": "0.93", "size": "1514.28"}, {"price": "0.92", "size": "5.83"}, {"price": "0.9", "size": "340"}, {"price": "0.86", "size": "228.57"}, {"price": "0.85", "size": "850"}, {"price": "0.83", "size": "1154.7"}, {"price": "0.82", "size": "150"}, {"price": "0.81", "size": "2460"}, {"price": "0.8", "size": "5.63"}, {"price": "0.79", "size": "223.8"}, {"price": "0.76", "size": "100"}, {"price": "0.74", "size": "200"}, {"price": "0.73", "size": "3427"}, {"price": "0.72", "size": "71.42"}, {"price": "0.7", "size": "150"}, {"price": "0.68", "size": "28.5"}, {"price": "0.66", "size": "125"}, {"price": "0.5", "size": "50"}, {"price": "0.49", "size": "6033"}, {"price": "0.48", "size": "700"}, {"price": "0.44", "size": "150"}, {"price": "0.43", "size": "20"}, {"price": "0.4", "size": "10060"}, {"price": "0.39", "size": "200"}, {"price": "0.36", "size": "20"}, {"price": "0.35", "size": "1160"}, {"price": "0.34", "size": "520.05"}, {"price": "0.33", "size": "297.75"}], "event_type": "book", "last_trade_price": "0.330"}, {"market": "0xe766d95249dc636e0f3b9c40be41e60312c11caade2e4c7208cab46109204e5f", "asset_id": "8901233624283477490118638398214954338623418183948465861624374546059779239456", "timestamp": "1769383985183", "hash": "0d15e086a7e6d16047260c64ae34731ed61acda8", "bids": [{"price": "0.001", "size": "3800.85"}, {"price": "0.002", "size": "1255.83"}, {"price": "0.003", "size": "1400"}, {"price": "0.004", "size": "10.09"}, {"price": "0.006", "size": "200"}, {"price": "0.01", "size": "5518"}, {"price": "0.011", "size": "10.13"}, {"price": "0.02", "size": "1000"}, {"price": "0.03", "size": "2500"}, {"price": "0.031", "size": "5.05"}, {"price": "0.05", "size": "30"}, {"price": "0.051", "size": "39"}, {"price": "0.06", "size": "500"}, {"price": "0.061", "size": "9.71"}, {"price": "0.1", "size": "560"}, {"price": "0.101", "size": "250"}, {"price": "0.15", "size": "826.66"}, {"price": "0.2", "size": "560"}, {"price": "0.201", "size": "5.38"}, {"price": "0.223", "size": "606"}, {"price": "0.25", "size": "112"}, {"price": "0.3", "size": "186.66"}, {"price": "0.35", "size": "68.57"}, {"price": "0.4", "size": "175"}, {"price": "0.523", "size": "383"}, {"price": "0.524", "size": "3106"}, {"price": "0.525", "size": "5"}, {"price": "0.55", "size": "19"}, {"price": "0.723", "size": "463"}, {"price": "0.823", "size": "374"}, {"price": "0.824", "size": "20"}, {"price": "0.919", "size": "800"}, {"price": "0.923", "size": "1502"}, {"price": "0.924", "size": "833.31"}, {"price": "0.949", "size": "32"}, {"price": "0.961", "size": "20"}, {"price": "0.998", "size": "725.16"}], "asks": [{"price": "0.999", "size": "1227.86"}], "event_type": "book", "last_trade_price": "0.001"}, {"market": "0x715eb3d786c7d27ff65c28b3122ad0ecb41e3d0ca588dc1e291317a06c1ec47f", "asset_id": "21550149566526602463623919476906543820980714141926005576912997545264282073790", "timestamp": "1769383987816", "hash": "63314488d499b1ad39384d9cd240feab4cf1a25e", "bids": [{"price": "0.001", "size": "3800.85"}, {"price": "0.002", "size": "1255.83"}, {"price": "0.003", "size": "1400"}, {"price": "0.004", "size": "10.09"}, {"price": "0.006", "size": "200"}, {"price": "0.01", "size": "5518"}, {"price": "0.011", "size": "5.13"}, {"price": "0.02", "size": "2200"}, {"price": "0.021", "size": "9.95"}, {"price": "0.05", "size": "30"}, {"price": "0.051", "size": "39"}, {"price": "0.06", "size": "3500"}, {"price": "0.061", "size": "450"}, {"price": "0.062", "size": "9.6"}, {"price": "0.1", "size": "660"}, {"price": "0.15", "size": "776.66"}, {"price": "0.2", "size": "660"}, {"price": "0.201", "size": "5.38"}, {"price": "0.223", "size": "381"}, {"price": "0.25", "size": "112"}, {"price": "0.3", "size": "186.66"}, {"price": "0.34", "size": "50"}, {"price": "0.35", "size": "68.57"}, {"price": "0.4", "size": "50"}, {"price": "0.401", "size": "60"}, {"price": "0.523", "size": "168"}, {"price": "0.61", "size": "240.71"}, {"price": "0.723", "size": "201"}, {"price": "0.74", "size": "700"}, {"price": "0.741", "size": "3239"}, {"price": "0.77", "size": "150"}, {"price": "0.823", "size": "227"}, {"price": "0.824", "size": "20"}, {"price": "0.923", "size": "764"}, {"price": "0.981", "size": "271"}, {"price": "0.984", "size": "1.76"}, {"price": "0.985", "size": "594.8"}, {"price": "0.989", "size": "400"}, {"price": "0.995", "size": "457.99"}, {"price": "0.996", "size": "697.31"}, {"price": "0.997", "size": "528.12"}, {"price": "0.998", "size": "4139.89"}], "asks": [{"price": "0.999", "size": "20"}], "event_type": "book", "last_trade_price": ""}, {"market": "0x715eb3d786c7d27ff65c28b3122ad0ecb41e3d0ca588dc1e291317a06c1ec47f", "asset_id": "64042023499171690072089529671394245926342142288867064196322402966461454126280", "timestamp": "1769383987816", "hash": "8de5bbe334a591066bc3962cdeaec12bf80fc4e5", "bids": [{"price": "0.001", "size": "20"}], "asks": [{"price": "0.999", "size": "3800.85"}, {"price": "0.998", "size": "1255.83"}, {"price": "0.997", "size": "1400"}, {"price": "0.996", "size": "10.09"}, {"price": "0.994", "size": "200"}, {"price": "0.99", "size": "5518"}, {"price": "0.989", "size": "5.13"}, {"price": "0.98", "size": "2200"}, {"price": "0.979", "size": "9.95"}, {"price": "0.95", "size": "30"}, {"price": "0.949", "size": "39"}, {"price": "0.94", "size": "3500"}, {"price": "0.939", "size": "450"}, {"price": "0.938", "size": "9.6"}, {"price": "0.9", "size": "660"}, {"price": "0.85", "size": "776.66"}, {"price": "0.8", "size": "660"}, {"price": "0.799", "size": "5.38"}, {"price": "0.777", "size": "381"}, {"price": "0.75", "size": "112"}, {"price": "0.7", "size": "186.66"}, {"price": "0.66", "size": "50"}, {"price": "0.65", "size": "68.57"}, {"price": "0.6", "size": "50"}, {"price": "0.599", "size": "60"}, {"price": "0.477", "size": "168"}, {"price": "0.39", "size": "240.71"}, {"price": "0.277", "size": "201"}, {"price": "0.26", "size": "700"}, {"price": "0.259", "size": "3239"}, {"price": "0.23", "size": "150"}, {"price": "0.177", "size": "227"}, {"price": "0.176", "size": "20"}, {"price": "0.077", "size": "764"}, {"price": "0.019", "size": "271"}, {"price": "0.016", "size": "1.76"}, {"price": "0.015", "size": "594.8"}, {"price": "0.011", "size": "400"}, {"price": "0.005", "size": "457.99"}, {"price": "0.004", "size": "697.31"}, {"price": "0.003", "size": "528.12"}, {"price": "0.002", "size": "4139.89"}], "event_type": "book", "last_trade_price": ""}, {"market": "0x807a5bd3d52942c2d8b58bf71a583d4aa03a637f3fd9ff7a7c4a1ad818003067", "asset_id": "69732267236340588035067724177359769962979053624149789047101950615640324836190", "timestamp": "1769383996000", "hash": "cde550bffb8917ff8aa74af12704a32dd874d140", "bids": [{"price": "0.01", "size": "5522.79"}, {"price": "0.02", "size": "1500"}, {"price": "0.03", "size": "13.69"}, {"price": "0.04", "size": "2350"}, {"price": "0.05", "size": "680"}, {"price": "0.06", "size": "10.5"}, {"price": "0.07", "size": "457.14"}, {"price": "0.08", "size": "6.16"}, {"price": "0.09", "size": "311.11"}, {"price": "0.1", "size": "3011"}, {"price": "0.11", "size": "461.36"}, {"price": "0.13", "size": "184.61"}, {"price": "0.14", "size": "142.85"}, {"price": "0.15", "size": "6.44"}, {"price": "0.17", "size": "25"}, {"price": "0.2", "size": "50"}, {"price": "0.21", "size": "193.12"}, {"price": "0.26", "size": "5000"}, {"price": "0.27", "size": "1259.42"}, {"price": "0.3", "size": "4238.66"}, {"price": "0.31", "size": "1853.77"}, {"price": "0.32", "size": "1041.17"}, {"price": "0.33", "size": "7633.56"}, {"price": "0.34", "size": "207.69"}], "asks": [{"price": "0.99", "size": "5500"}, {"price": "0.98", "size": "1000"}, {"price": "0.97", "size": "250"}, {"price": "0.96", "size": "7.14"}, {"price": "0.95", "size": "2450"}, {"price": "0.93", "size": "1214.28"}, {"price": "0.9", "size": "340"}, {"price": "0.87", "size": "246.15"}, {"price": "0.85", "size": "550"}, {"price": "0.84", "size": "1050"}, {"price": "0.83", "size": "364.7"}, {"price": "0.82", "size": "400"}, {"price": "0.81", "size": "2210"}, {"price": "0.8", "size": "630"}, {"price": "0.77", "size": "104.34"}, {"price": "0.76", "size": "3200"}, {"price": "0.75", "size": "100"}, {"price": "0.74", "size": "3611.92"}, {"price": "0.7", "size": "400"}, {"price": "0.6", "size": "472.96"}, {"price": "0.56", "size": "22.72"}, {"price": "0.55", "size": "167.46"}, {"price": "0.49", "size": "700"}, {"price": "0.48", "size": "150"}, {"price": "0.44", "size": "1036.92"}, {"price": "0.42", "size": "2222"}, {"price": "0.41", "size": "2195.8"}, {"price": "0.4", "size": "320"}, {"price": "0.39", "size": "12409.97"}, {"price": "0.38", "size": "40"}, {"price": "0.37", "size": "250"}, {"price": "0.36", "size": "500"}], "event_type": "book", "last_trade_price": "0.660"}, {"market": "0x807a5bd3d52942c2d8b58bf71a583d4aa03a637f3fd9ff7a7c4a1ad818003067", "asset_id": "51273396751548994017117054764897754414228591289652072971120018616721173971444", "timestamp": "1769383996000", "hash": "46d38592ba91dd8ff0836c8a8eadd47f6a068d7f", "bids": [{"price": "0.01", "size": "5500"}, {"price": "0.02", "size": "1000"}, {"price": "0.03", "size": "250"}, {"price": "0.04", "size": "7.14"}, {"price": "0.05", "size": "2450"}, {"price": "0.07", "size": "1214.28"}, {"price": "0.1", "size": "340"}, {"price": "0.13", "size": "246.15"}, {"price": "0.15", "size": "550"}, {"price": "0.16", "size": "1050"}, {"price": "0.17", "size": "364.7"}, {"price": "0.18", "size": "400"}, {"price": "0.19", "size": "2210"}, {"price": "0.2", "size": "630"}, {"price": "0.23", "size": "104.34"}, {"price": "0.24", "size": "3200"}, {"price": "0.25", "size": "100"}, {"price": "0.26", "size": "3611.92"}, {"price": "0.3", "size": "400"}, {"price": "0.4", "size": "472.96"}, {"price": "0.44", "size": "22.72"}, {"price": "0.45", "size": "167.46"}, {"price": "0.51", "size": "700"}, {"price": "0.52", "size": "150"}, {"price": "0.56", "size": "1036.92"}, {"price": "0.58", "size": "2222"}, {"price": "0.59", "size": "2195.8"}, {"price": "0.6", "size": "320"}, {"price": "0.61", "size": "12409.97"}, {"price": "0.62", "size": "40"}, {"price": "0.63", "size": "250"}, {"price": "0.64", "size": "500"}], "asks": [{"price": "0.99", "size": "5522.79"}, {"price": "0.98", "size": "1500"}, {"price": "0.97", "size": "13.69"}, {"price": "0.96", "size": "2350"}, {"price": "0.95", "size": "680"}, {"price": "0.94", "size": "10.5"}, {"price": "0.93", "size": "457.14"}, {"price": "0.92", "size": "6.16"}, {"price": "0.91", "size": "311.11"}, {"price": "0.9", "size": "3011"}, {"price": "0.89", "size": "461.36"}, {"price": "0.87", "size": "184.61"}, {"price": "0.86", "size": "142.85"}, {"price": "0.85", "size": "6.44"}, {"price": "0.83", "size": "25"}, {"price": "0.8", "size": "50"}, {"price": "0.79", "size": "193.12"}, {"price": "0.74", "size": "5000"}, {"price": "0.73", "size": "1259.42"}, {"price": "0.7", "size": "4238.66"}, {"price": "0.69", "size": "1853.77"}, {"price": "0.68", "size": "1041.17"}, {"price": "0.67", "size": "7633.56"}, {"price": "0.66", "size": "207.69"}], "event_type": "book", "last_trade_price": "0.660"}, {"market": "0xe766d95249dc636e0f3b9c40be41e60312c11caade2e4c7208cab46109204e5f", "asset_id": "112709069152390670158768840374625484791639667888012609196878782330674715301016", "timestamp": "1769383985183", "hash": "8fcfee4d1ab26055ea9e48f3fa98050cce9405c8", "bids": [{"price": "0.001", "size": "1227.86"}], "asks": [{"price": "0.999", "size": "3800.85"}, {"price": "0.998", "size": "1255.83"}, {"price": "0.997", "size": "1400"}, {"price": "0.996", "size": "10.09"}, {"price": "0.994", "size": "200"}, {"price": "0.99", "size": "5518"}, {"price": "0.989", "size": "10.13"}, {"price": "0.98", "size": "1000"}, {"price": "0.97", "size": "2500"}, {"price": "0.969", "size": "5.05"}, {"price": "0.95", "size": "30"}, {"price": "0.949", "size": "39"}, {"price": "0.94", "size": "500"}, {"price": "0.939", "size": "9.71"}, {"price": "0.9", "size": "560"}, {"price": "0.899", "size": "250"}, {"price": "0.85", "size": "826.66"}, {"price": "0.8", "size": "560"}, {"price": "0.799", "size": "5.38"}, {"price": "0.777", "size": "606"}, {"price": "0.75", "size": "112"}, {"price": "0.7", "size": "186.66"}, {"price": "0.65", "size": "68.57"}, {"price": "0.6", "size": "175"}, {"price": "0.477", "size": "383"}, {"price": "0.476", "size": "3106"}, {"price": "0.475", "size": "5"}, {"price": "0.45", "size": "19"}, {"price": "0.277", "size": "463"}, {"price": "0.177", "size": "374"}, {"price": "0.176", "size": "20"}, {"price": "0.081", "size": "800"}, {"price": "0.077", "size": "1502"}, {"price": "0.076", "size": "833.31"}, {"price": "0.051", "size": "32"}, {"price": "0.039", "size": "20"}, {"price": "0.002", "size": "725.16"}], "event_type": "book", "last_trade_price": "0.001"}, {"market": "0x3bb5ceb45e186de77b1faaf56abf427c8c6f1a88532e4a0dc0ad9c1ffdac2a39", "asset_id": "107080924640291332768695532594456654301362852895742708190436320623455634988224", "timestamp": "1769383920817", "hash": "c06d257130fa9439255c912806c755ac8df0df7d", "bids": [{"price": "0.001", "size": "2015.85"}, {"price": "0.002", "size": "5.83"}, {"price": "0.003", "size": "1000"}, {"price": "0.004", "size": "10.09"}, {"price": "0.01", "size": "5518"}, {"price": "0.011", "size": "5.63"}, {"price": "0.02", "size": "2200"}, {"price": "0.021", "size": "250"}, {"price": "0.022", "size": "9.37"}, {"price": "0.05", "size": "10"}, {"price": "0.06", "size": "500"}, {"price": "0.061", "size": "9.71"}, {"price": "0.1", "size": "860"}, {"price": "0.15", "size": "776.66"}, {"price": "0.2", "size": "660"}, {"price": "0.201", "size": "5.38"}, {"price": "0.223", "size": "423"}, {"price": "0.25", "size": "112"}, {"price": "0.3", "size": "136.66"}, {"price": "0.311", "size": "100"}, {"price": "0.35", "size": "68.57"}, {"price": "0.4", "size": "189"}, {"price": "0.401", "size": "5938"}, {"price": "0.402", "size": "5"}, {"price": "0.5", "size": "150"}, {"price": "0.523", "size": "184"}, {"price": "0.723", "size": "24"}, {"price": "0.823", "size": "138"}, {"price": "0.873", "size": "42.98"}, {"price": "0.923", "size": "1471"}, {"price": "0.932", "size": "13"}, {"price": "0.997", "size": "456.63"}, {"price": "0.998", "size": "2500"}, {"price": "0.999", "size": "5252.61"}], "asks": [], "event_type": "book", "last_trade_price": ""}, {"market": "0x9248190b831a98a8996cbf370e731312e380c59b1969dcd22d6eab6f831d95f4", "asset_id": "238517786560077129681530766486694172055472591334781195173021479841756852253", "timestamp": "1769383921970", "hash": "3198df9c5410f4e6eafa88a5ce736b802e171e41", "bids": [{"price": "0.001", "size": "3800.85"}, {"price": "0.002", "size": "1255.83"}, {"price": "0.003", "size": "1400"}, {"price": "0.004", "size": "10.09"}, {"price": "0.006", "size": "200"}, {"price": "0.01", "size": "5516"}, {"price": "0.011", "size": "5.13"}, {"price": "0.02", "size": "2200"}, {"price": "0.021", "size": "10.08"}, {"price": "0.05", "size": "30"}, {"price": "0.051", "size": "39"}, {"price": "0.06", "size": "500"}, {"price": "0.061", "size": "9.71"}, {"price": "0.1", "size": "860"}, {"price": "0.101", "size": "250"}, {"price": "0.15", "size": "776.66"}, {"price": "0.2", "size": "660"}, {"price": "0.201", "size": "5.38"}, {"price": "0.223", "size": "504"}, {"price": "0.25", "size": "112"}, {"price": "0.3", "size": "186.66"}, {"price": "0.35", "size": "68.57"}, {"price": "0.4", "size": "175"}, {"price": "0.523", "size": "274"}, {"price": "0.723", "size": "433"}, {"price": "0.724", "size": "3298"}, {"price": "0.73", "size": "150"}, {"price": "0.823", "size": "139"}, {"price": "0.824", "size": "20"}, {"price": "0.92", "size": "19"}, {"price": "0.923", "size": "703"}, {"price": "0.949", "size": "32"}, {"price": "0.961", "size": "20"}, {"price": "0.995", "size": "70"}, {"price": "0.997", "size": "80.62"}, {"price": "0.998", "size": "4549.66"}], "asks": [{"price": "0.999", "size": "6088.87"}], "event_type": "book", "last_trade_price": ""}, {"market": "0x690d504367efdec61936e7dc1c572c1598281f3e91d30d3b6148f3f1f48642d5", "asset_id": "51469050125334342675041532938035006268212349126791674076934139732091152113995", "timestamp": "1769383996000", "hash": "0525a577ce4af5414e51667710abfa7427e5a817", "bids": [{"price": "0.01", "size": "5506.25"}, {"price": "0.02", "size": "2206.02"}, {"price": "0.03", "size": "250"}, {"price": "0.04", "size": "5.57"}, {"price": "0.07", "size": "1514.28"}, {"price": "0.08", "size": "5.83"}, {"price": "0.1", "size": "340"}, {"price": "0.14", "size": "228.57"}, {"price": "0.15", "size": "850"}, {"price": "0.17", "size": "1154.7"}, {"price": "0.18", "size": "150"}, {"price": "0.19", "size": "2460"}, {"price": "0.2", "size": "5.63"}, {"price": "0.21", "size": "223.8"}, {"price": "0.24", "size": "100"}, {"price": "0.26", "size": "200"}, {"price": "0.27", "size": "3427"}, {"price": "0.28", "size": "71.42"}, {"price": "0.3", "size": "150"}, {"price": "0.32", "size": "28.5"}, {"price": "0.34", "size": "125"}, {"price": "0.5", "size": "50"}, {"price": "0.51", "size": "6033"}, {"price": "0.52", "size": "700"}, {"price": "0.56", "size": "150"}, {"price": "0.57", "size": "20"}, {"price": "0.6", "size": "10060"}, {"price": "0.61", "size": "200"}, {"price": "0.64", "size": "20"}, {"price": "0.65", "size": "1160"}, {"price": "0.66", "size": "520.05"}, {"price": "0.67", "size": "297.75"}], "asks": [{"price": "0.99", "size": "10500"}, {"price": "0.98", "size": "2450"}, {"price": "0.97", "size": "9.52"}, {"price": "0.93", "size": "500"}, {"price": "0.92", "size": "3794"}, {"price": "0.88", "size": "3225"}, {"price": "0.85", "size": "820"}, {"price": "0.8", "size": "1000"}, {"price": "0.79", "size": "2000"}, {"price": "0.78", "size": "555"}, {"price": "0.77", "size": "500"}, {"price": "0.73", "size": "850"}, {"price": "0.7", "size": "112.5"}, {"price": "0.69", "size": "1735.05"}, {"price": "0.68", "size": "1010.59"}], "event_type": "book", "last_trade_price": "0.330"}]}
{"_local_timestamp": "2026-01-25T23:33:23.879124+00:00", "data": {"market": "0x807a5bd3d52942c2d8b58bf71a583d4aa03a637f3fd9ff7a7c4a1ad818003067", "price_changes": [{"asset_id": "51273396751548994017117054764897754414228591289652072971120018616721173971444", "price": "0.18", "size": "250", "side": "BUY", "hash": "b751cf49995f5e4019a02dd39631429672a66477", "best_bid": "0.64", "best_ask": "0.66"}, {"asset_id": "69732267236340588035067724177359769962979053624149789047101950615640324836190", "price": "0.82", "size": "250", "side": "SELL", "hash": "66f09a929577c872fda8927110b9d7186107d11d", "best_bid": "0.34", "best_ask": "0.36"}], "timestamp": "1769384003785", "event_type": "price_change"}}
{"_local_timestamp": "2026-01-25T23:33:23.881820+00:00", "data": {"market": "0x690d504367efdec61936e7dc1c572c1598281f3e91d30d3b6148f3f1f48642d5", "price_changes": [{"asset_id": "51469050125334342675041532938035006268212349126791674076934139732091152113995", "price": "0.18", "size": "0", "side": "BUY", "hash": "6bfc0c29ef5e15b9124c4fa0c0f7fb16718fadf9", "best_bid": "0.67", "best_ask": "0.68"}, {"asset_id": "36538842701383075131399258783814730353525125143988435459349182813934073807848", "price": "0.82", "size": "0", "side": "SELL", "hash": "3352d0b4831844661ff388a13f37a52caa470cb0", "best_bid": "0.32", "best_ask": "0.33"}], "timestamp": "1769384003785", "event_type": "price_change"}}
{"_local_timestamp": "2026-01-25T23:33:24.372513+00:00", "data": {"market": "0x690d504367efdec61936e7dc1c572c1598281f3e91d30d3b6148f3f1f48642d5", "price_changes": [{"asset_id": "51469050125334342675041532938035006268212349126791674076934139732091152113995", "price": "0.17", "size": "1304.7", "side": "BUY", "hash": "dbd0ffcd8d69be915b8f59382d4f76568af65fc1", "best_bid": "0.67", "best_ask": "0.68"}, {"asset_id": "36538842701383075131399258783814730353525125143988435459349182813934073807848", "price": "0.83", "size": "1304.7", "side": "SELL", "hash": "7ad6f3f1adc6f099cc5a83d6bcb2f287e2c22c37", "best_bid": "0.32", "best_ask": "0.33"}], "timestamp": "1769384004277", "event_type": "price_change"}}
{"_local_timestamp": "2026-01-25T23:33:24.399620+00:00", "data": {"market": "0x807a5bd3d52942c2d8b58bf71a583d4aa03a637f3fd9ff7a7c4a1ad818003067", "price_changes": [{"asset_id": "51273396751548994017117054764897754414228591289652072971120018616721173971444", "price": "0.19", "size": "2360", "side": "BUY", "hash": "e13b237614bc328b92fc65b54424b8d7c6adc24e", "best_bid": "0.64", "best_ask": "0.66"}, {"asset_id": "69732267236340588035067724177359769962979053624149789047101950615640324836190", "price": "0.81", "size": "2360", "side": "SELL", "hash": "c71e47d55610114d4494945c169192b36c90d2d9", "best_bid": "0.34", "best_ask": "0.36"}], "timestamp": "1769384004276", "event_type": "price_change"}}
{"_local_timestamp": "2026-01-25T23:33:40.199232+00:00", "data": {"market": "0x807a5bd3d52942c2d8b58bf71a583d4aa03a637f3fd9ff7a7c4a1ad818003067", "price_changes": [{"asset_id": "51273396751548994017117054764897754414228591289652072971120018616721173971444", "price": "0.25", "size": "50", "side": "BUY", "hash": "a5f2e7a89910fbee2babc366c7152067ffa70e23", "best_bid": "0.64", "best_ask": "0.66"}, {"asset_id": "69732267236340588035067724177359769962979053624149789047101950615640324836190", "price": "0.75", "size": "50", "side": "SELL", "hash": "b2845adeb63dd52420394c5d33694b2e666edf5a", "best_bid": "0.34", "best_ask": "0.36"}], "timestamp": "1769384020086", "event_type": "price_change"}}
{"_local_timestamp": "2026-01-25T23:33:40.200276+00:00", "data": {"market": "0x690d504367efdec61936e7dc1c572c1598281f3e91d30d3b6148f3f1f48642d5", "price_changes": [{"asset_id": "51469050125334342675041532938035006268212349126791674076934139732091152113995", "price": "0.26", "size": "150", "side": "BUY", "hash": "de90b1cfc2ac81b6b8fccb7f28fc16c0f684099a", "best_bid": "0.67", "best_ask": "0.68"}, {"asset_id": "36538842701383075131399258783814730353525125143988435459349182813934073807848", "price": "0.74", "size": "150", "side": "SELL", "hash": "3b58ffd9f9373da6bbcd1e0cb3f791732d9ceace", "best_bid": "0.32", "best_ask": "0.33"}], "timestamp": "1769384020086", "event_type": "price_change"}}
{"_local_timestamp": "2026-01-25T23:33:40.200660+00:00", "data": {"market": "0x690d504367efdec61936e7dc1c572c1598281f3e91d30d3b6148f3f1f48642d5", "price_changes": [{"asset_id": "51469050125334342675041532938035006268212349126791674076934139732091152113995", "price": "0.19", "size": "2360", "side": "BUY", "hash": "de90b1cfc2ac81b6b8fccb7f28fc16c0f684099a", "best_bid": "0.67", "best_ask": "0.68"}, {"asset_id": "36538842701383075131399258783814730353525125143988435459349182813934073807848", "price": "0.81", "size": "2360", "side": "SELL", "hash": "3b58ffd9f9373da6bbcd1e0cb3f791732d9ceace", "best_bid": "0.32", "best_ask": "0.33"}], "timestamp": "1769384020086", "event_type": "price_change"}}
{"_local_timestamp": "2026-01-25T23:33:40.200994+00:00", "data": {"market": "0x3bb5ceb45e186de77b1faaf56abf427c8c6f1a88532e4a0dc0ad9c1ffdac2a39", "price_changes": [{"asset_id": "107080924640291332768695532594456654301362852895742708190436320623455634988224", "price": "0.311", "size": "50", "side": "BUY", "hash": "6667d9b53947b6495a40c6dce7a0611650263772", "best_bid": "0.999", "best_ask": "1"}, {"asset_id": "77481318171335047328591651032911896763491342646014093639934301019258606619150", "price": "0.689", "size": "50", "side": "SELL", "hash": "16e63f060517d053277e214f73d9311d0919e4f8", "best_bid": "0", "best_ask": "0.001"}], "timestamp": "1769384020086", "event_type": "price_change"}}
{"_local_timestamp": "2026-01-25T23:33:40.416187+00:00", "data": {"market": "0x690d504367efdec61936e7dc1c572c1598281f3e91d30d3b6148f3f1f48642d5", "price_changes": [{"asset_id": "51469050125334342675041532938035006268212349126791674076934139732091152113995", "price": "0.64", "size": "170", "side": "BUY", "hash": "2c5870b349fa0ea4c9d48a816c84b0350337bf53", "best_bid": "0.67", "best_ask": "0.68"}, {"asset_id": "36538842701383075131399258783814730353525125143988435459349182813934073807848", "price": "0.36", "size": "170", "side": "SELL", "hash": "eff55f876849a31a1b18d44012f68b2c01b72fcd", "best_bid": "0.32", "best_ask": "0.33"}], "timestamp": "1769384020246", "event_type": "price_change"}}
{"_local_timestamp": "2026-01-25T23:33:40.679115+00:00", "data": {"market": "0x3bb5ceb45e186de77b1faaf56abf427c8c6f1a88532e4a0dc0ad9c1ffdac2a39", "price_changes": [{"asset_id": "107080924640291332768695532594456654301362852895742708190436320623455634988224", "price": "0.223", "size": "473", "side": "BUY", "hash": "910d44b6eaa6cd9d60413c8aeecea8dec00832c7", "best_bid": "0.999", "best_ask": "1"}, {"asset_id": "77481318171335047328591651032911896763491342646014093639934301019258606619150", "price": "0.777", "size": "473", "side": "SELL", "hash": "db7d53152123f98a05d625dcfa6b770ee103627c", "best_bid": "0", "best_ask": "0.001"}], "timestamp": "1769384020531", "event_type": "price_change"}}
{"_local_timestamp": "2026-01-25T23:33:40.683798+00:00", "data": {"market": "0x807a5bd3d52942c2d8b58bf71a583d4aa03a637f3fd9ff7a7c4a1ad818003067", "price_changes": [{"asset_id": "51273396751548994017117054764897754414228591289652072971120018616721173971444", "price": "0.26", "size": "3661.92", "side": "BUY", "hash": "276de9c19af788b8fbdc5271a4f0e2449ecddaa7", "best_bid": "0.64", "best_ask": "0.66"}, {"asset_id": "69732267236340588035067724177359769962979053624149789047101950615640324836190", "price": "0.74", "size": "3661.92", "side": "SELL", "hash": "7cbb1012b306fa94e393798194a6f18fbc2257c3", "best_bid": "0.34", "best_ask": "0.36"}], "timestamp": "1769384020533", "event_type": "price_change"}}
{"_local_timestamp": "2026-01-25T23:33:40.811624+00:00", "data": {"market": "0x690d504367efdec61936e7dc1c572c1598281f3e91d30d3b6148f3f1f48642d5", "price_changes": [{"asset_id": "51469050125334342675041532938035006268212349126791674076934139732091152113995", "price": "0.27", "size": "3477", "side": "BUY", "hash": "be2458fef81656708bc7271b9a21f6a7f8b38cb8", "best_bid": "0.67", "best_ask": "0.68"}, {"asset_id": "36538842701383075131399258783814730353525125143988435459349182813934073807848", "price": "0.73", "size": "3477", "side": "SELL", "hash": "e4e2c80817a997887acae3aa3826b759302ae1b4", "best_bid": "0.32", "best_ask": "0.33"}], "timestamp": "1769384020563", "event_type": "price_change"}}
{"_local_timestamp": "2026-01-25T23:33:40.843906+00:00", "data": {"market": "0x690d504367efdec61936e7dc1c572c1598281f3e91d30d3b6148f3f1f48642d5", "price_changes": [{"asset_id": "51469050125334342675041532938035006268212349126791674076934139732091152113995", "price": "0.18", "size": "100", "side": "BUY", "hash": "22015f803d6a88f456a53def1ad1733fd44425b7", "best_bid": "0.67", "best_ask": "0.68"}, {"asset_id": "36538842701383075131399258783814730353525125143988435459349182813934073807848", "price": "0.82", "size": "100", "side": "SELL", "hash": "bbd11d62d94c0e1f8bad1d93d4cf8c01b3c21eda", "best_bid": "0.32", "best_ask": "0.33"}], "timestamp": "1769384020600", "event_type": "price_change"}}
{"_local_timestamp": "2026-01-25T23:33:52.303516+00:00", "data": {"market": "0x690d504367efdec61936e7dc1c572c1598281f3e91d30d3b6148f3f1f48642d5", "price_changes": [{"asset_id": "51469050125334342675041532938035006268212349126791674076934139732091152113995", "price": "0.17", "size": "1254.7", "side": "BUY", "hash": "09a8bd62d1bcf5c1ee1ee01ffec86fe6ca77bfd5", "best_bid": "0.67", "best_ask": "0.68"}, {"asset_id": "36538842701383075131399258783814730353525125143988435459349182813934073807848", "price": "0.83", "size": "1254.7", "side": "SELL", "hash": "08dc3337388550ca663b8ddb290e905b3955710a", "best_bid": "0.32", "best_ask": "0.33"}], "timestamp": "1769384032223", "event_type": "price_change"}}
{"_local_timestamp": "2026-01-25T23:33:52.313898+00:00", "data": {"market": "0x807a5bd3d52942c2d8b58bf71a583d4aa03a637f3fd9ff7a7c4a1ad818003067", "price_changes": [{"asset_id": "51273396751548994017117054764897754414228591289652072971120018616721173971444", "price": "0.16", "size": "1000", "side": "BUY", "hash": "132e0d0ca190d35213c83086ae5ab5742c5d8915", "best_bid": "0.64", "best_ask": "0.66"}, {"asset_id": "69732267236340588035067724177359769962979053624149789047101950615640324836190", "price": "0.84", "size": "1000", "side": "SELL", "hash": "47b32ea4b45affb6bfa165d056621d5efb4cb4db", "best_bid": "0.34", "best_ask": "0.36"}], "timestamp": "1769384032223", "event_type": "price_change"}}
{"_local_timestamp": "2026-01-25T23:33:52.627541+00:00", "data": {"market": "0x807a5bd3d52942c2d8b58bf71a583d4aa03a637f3fd9ff7a7c4a1ad818003067", "price_changes": [{"asset_id": "51273396751548994017117054764897754414228591289652072971120018616721173971444", "price": "0.19", "size": "2410", "side": "BUY", "hash": "b5a5852ee71bb19e58f79c8a6e35cc79152c5cf6", "best_bid": "0.64", "best_ask": "0.66"}, {"asset_id": "69732267236340588035067724177359769962979053624149789047101950615640324836190", "price": "0.81", "size": "2410", "side": "SELL", "hash": "aed259ee2c316e4f7fb4d035a59fbc39174b9421", "best_bid": "0.34", "best_ask": "0.36"}], "timestamp": "1769384032540", "event_type": "price_change"}}
{"_local_timestamp": "2026-01-25T23:33:52.633779+00:00", "data": {"market": "0x690d504367efdec61936e7dc1c572c1598281f3e91d30d3b6148f3f1f48642d5", "price_changes": [{"asset_id": "51469050125334342675041532938035006268212349126791674076934139732091152113995", "price": "0.19", "size": "2410", "side": "BUY", "hash": "84b4a3504f08625b3a914a12f220cb4acc49f894", "best_bid": "0.67", "best_ask": "0.68"}, {"asset_id": "36538842701383075131399258783814730353525125143988435459349182813934073807848", "price": "0.81", "size": "2410", "side": "SELL", "hash": "7b6b4db97c6a466bfe0a8d00bd39ba17b3bd7334", "best_bid": "0.32", "best_ask": "0.33"}], "timestamp": "1769384032540", "event_type": "price_change"}}
{"_local_timestamp": "2026-01-25T23:34:01.381933+00:00", "data": {"market": "0x715eb3d786c7d27ff65c28b3122ad0ecb41e3d0ca588dc1e291317a06c1ec47f", "price_changes": [{"asset_id": "21550149566526602463623919476906543820980714141926005576912997545264282073790", "price": "0.061", "size": "250", "side": "BUY", "hash": "c1ae3fb96e64c0b17601487624d2486a60ceb662", "best_bid": "0.998", "best_ask": "0.999"}, {"asset_id": "64042023499171690072089529671394245926342142288867064196322402966461454126280", "price": "0.939", "size": "250", "side": "SELL", "hash": "b42c7e4f6596f8da06d41ea95c7c2e27dfaaff4f", "best_bid": "0.001", "best_ask": "0.002"}], "timestamp": "1769384041254", "event_type": "price_change"}}
{"_local_timestamp": "2026-01-25T23:34:01.630807+00:00", "data": {"market": "0x715eb3d786c7d27ff65c28b3122ad0ecb41e3d0ca588dc1e291317a06c1ec47f", "price_changes": [{"asset_id": "21550149566526602463623919476906543820980714141926005576912997545264282073790", "price": "0.06", "size": "3700", "side": "BUY", "hash": "d852de1cae65acaf4a91a88ba5a8fdfbbb880743", "best_bid": "0.998", "best_ask": "0.999"}, {"asset_id": "64042023499171690072089529671394245926342142288867064196322402966461454126280", "price": "0.94", "size": "3700", "side": "SELL", "hash": "13a95824f1a4c05228945a27cf02e1b61afd2d71", "best_bid": "0.001", "best_ask": "0.002"}], "timestamp": "1769384041555", "event_type": "price_change"}}
{"_local_timestamp": "2026-01-25T23:34:04.683101+00:00", "data": {"market": "0x690d504367efdec61936e7dc1c572c1598281f3e91d30d3b6148f3f1f48642d5", "price_changes": [{"asset_id": "51469050125334342675041532938035006268212349126791674076934139732091152113995", "price": "0.17", "size": "1104.7", "side": "BUY", "hash": "84df957d82acda095b845d1f3b68caf5d7fc441e", "best_bid": "0.67", "best_ask": "0.68"}, {"asset_id": "36538842701383075131399258783814730353525125143988435459349182813934073807848", "price": "0.83", "size": "1104.7", "side": "SELL", "hash": "a7dd7daa7a8e1e857e0e52267499bcbd21c3aa5e", "best_bid": "0.32", "best_ask": "0.33"}], "timestamp": "1769384044470", "event_type": "price_change"}}
{"_local_timestamp": "2026-01-25T23:34:05.171541+00:00", "data": {"market": "0x690d504367efdec61936e7dc1c572c1598281f3e91d30d3b6148f3f1f48642d5", "price_changes": [{"asset_id": "51469050125334342675041532938035006268212349126791674076934139732091152113995", "price": "0.19", "size": "2560", "side": "BUY", "hash": "3576782d042ee8188277cdc2579977107e7289b2", "best_bid": "0.67", "best_ask": "0.68"}, {"asset_id": "36538842701383075131399258783814730353525125143988435459349182813934073807848", "price": "0.81", "size": "2560", "side": "SELL", "hash": "fadba09b88915e538bce604104b177e55db6a70f", "best_bid": "0.32", "best_ask": "0.33"}], "timestamp": "1769384044863", "event_type": "price_change"}}
{"_local_timestamp": "2026-01-25T23:34:20.003235+00:00", "data": {"market": "0x690d504367efdec61936e7dc1c572c1598281f3e91d30d3b6148f3f1f48642d5", "price_changes": [{"asset_id": "51469050125334342675041532938035006268212349126791674076934139732091152113995", "price": "0.19", "size": "350", "side": "BUY", "hash": "41ab47c098163db598bae8b17fce4f4b7e97b229", "best_bid": "0.67", "best_ask": "0.68"}, {"asset_id": "36538842701383075131399258783814730353525125143988435459349182813934073807848", "price": "0.81", "size": "350", "side": "SELL", "hash": "0e4ee26df9f37ac95c53741064cff8cf9394839c", "best_bid": "0.32", "best_ask": "0.33"}], "timestamp": "1769384059754", "event_type": "price_change"}}
{"_local_timestamp": "2026-01-25T23:34:25.225150+00:00", "data": {"market": "0x690d504367efdec61936e7dc1c572c1598281f3e91d30d3b6148f3f1f48642d5", "price_changes": [{"asset_id": "36538842701383075131399258783814730353525125143988435459349182813934073807848", "price": "0.34", "size": "586.05", "side": "SELL", "hash": "00a017b7ac2eea65539d2ed77f52eba674ce0bb4", "best_bid": "0.32", "best_ask": "0.33"}, {"asset_id": "51469050125334342675041532938035006268212349126791674076934139732091152113995", "price": "0.66", "size": "586.05", "side": "BUY", "hash": "80f0ea824600346939a2230e73a67367f7a9f497", "best_bid": "0.67", "best_ask": "0.68"}], "timestamp": "1769384064990", "event_type": "price_change"}}
{"_local_timestamp": "2026-01-25T23:34:25.786874+00:00", "data": {"market": "0x807a5bd3d52942c2d8b58bf71a583d4aa03a637f3fd9ff7a7c4a1ad818003067", "price_changes": [{"asset_id": "69732267236340588035067724177359769962979053624149789047101950615640324836190", "price": "0.37", "size": "288", "side": "SELL", "hash": "f0167c4f9494ba60c97110dc1d25c811c2634150", "best_bid": "0.34", "best_ask": "0.36"}, {"asset_id": "51273396751548994017117054764897754414228591289652072971120018616721173971444", "price": "0.63", "size": "288", "side": "BUY", "hash": "5c687ca18cc6c0d585eacb850a5666f6aaa9dfca", "best_bid": "0.64", "best_ask": "0.66"}], "timestamp": "1769384065543", "event_type": "price_change"}}
{"_local_timestamp": "2026-01-25T23:34:28.030643+00:00", "data": {"market": "0x690d504367efdec61936e7dc1c572c1598281f3e91d30d3b6148f3f1f48642d5", "price_changes": [{"asset_id": "51469050125334342675041532938035006268212349126791674076934139732091152113995", "price": "0.26", "size": "50", "side": "BUY", "hash": "5579cf1a79808f4aa0710267a6ff2d84e6becdfa", "best_bid": "0.67", "best_ask": "0.68"}, {"asset_id": "36538842701383075131399258783814730353525125143988435459349182813934073807848", "price": "0.74", "size": "50", "side": "SELL", "hash": "2dcb35c8fce55a61e16fe79380ed508ade6f9099", "best_bid": "0.32", "best_ask": "0.33"}], "timestamp": "1769384067617", "event_type": "price_change"}}
{"_local_timestamp": "2026-01-25T23:34:28.035921+00:00", "data": {"market": "0x690d504367efdec61936e7dc1c572c1598281f3e91d30d3b6148f3f1f48642d5", "price_changes": [{"asset_id": "51469050125334342675041532938035006268212349126791674076934139732091152113995", "price": "0.19", "size": "200", "side": "BUY", "hash": "5579cf1a79808f4aa0710267a6ff2d84e6becdfa", "best_bid": "0.67", "best_ask": "0.68"}, {"asset_id": "36538842701383075131399258783814730353525125143988435459349182813934073807848", "price": "0.81", "size": "200", "side": "SELL", "hash": "2dcb35c8fce55a61e16fe79380ed508ade6f9099", "best_bid": "0.32", "best_ask": "0.33"}], "timestamp": "1769384067617", "event_type": "price_change"}}
{"_local_timestamp": "2026-01-25T23:34:28.036413+00:00", "data": {"market": "0x3bb5ceb45e186de77b1faaf56abf427c8c6f1a88532e4a0dc0ad9c1ffdac2a39", "price_changes": [{"asset_id": "107080924640291332768695532594456654301362852895742708190436320623455634988224", "price": "0.4", "size": "114", "side": "BUY", "hash": "701d04da5fd7985b7878845bfffd4fb4c680e93c", "best_bid": "0.999", "best_ask": "1"}, {"asset_id": "77481318171335047328591651032911896763491342646014093639934301019258606619150", "price": "0.6", "size": "114", "side": "SELL", "hash": "1c985f86ddfff809298c44d3dacc859b37a5dbfb", "best_bid": "0", "best_ask": "0.001"}], "timestamp": "1769384067617", "event_type": "price_change"}}
{"_local_timestamp": "2026-01-25T23:34:28.039897+00:00", "data": {"market": "0x715eb3d786c7d27ff65c28b3122ad0ecb41e3d0ca588dc1e291317a06c1ec47f", "price_changes": [{"asset_id": "21550149566526602463623919476906543820980714141926005576912997545264282073790", "price": "0.401", "size": "0", "side": "BUY", "hash": "346d0760b3c8f83fc5b84640979efe66581513f9", "best_bid": "0.998", "best_ask": "0.999"}, {"asset_id": "64042023499171690072089529671394245926342142288867064196322402966461454126280", "price": "0.599", "size": "0", "side": "SELL", "hash": "9577cdf595fd6970b159eb9c3d223876259dd6fd", "best_bid": "0.001", "best_ask": "0.002"}], "timestamp": "1769384067618", "event_type": "price_change"}}
{"_local_timestamp": "2026-01-25T23:34:28.041347+00:00", "data": {"market": "0x715eb3d786c7d27ff65c28b3122ad0ecb41e3d0ca588dc1e291317a06c1ec47f", "price_changes": [{"asset_id": "21550149566526602463623919476906543820980714141926005576912997545264282073790", "price": "0.1", "size": "360", "side": "BUY", "hash": "346d0760b3c8f83fc5b84640979efe66581513f9", "best_bid": "0.998", "best_ask": "0.999"}, {"asset_id": "64042023499171690072089529671394245926342142288867064196322402966461454126280", "price": "0.9", "size": "360", "side": "SELL", "hash": "9577cdf595fd6970b159eb9c3d223876259dd6fd", "best_bid": "0.001", "best_ask": "0.002"}], "timestamp": "1769384067618", "event_type": "price_change"}}
{"_local_timestamp": "2026-01-25T23:34:28.547437+00:00", "data": {"market": "0x690d504367efdec61936e7dc1c572c1598281f3e91d30d3b6148f3f1f48642d5", "price_changes": [{"asset_id": "51469050125334342675041532938035006268212349126791674076934139732091152113995", "price": "0.18", "size": "250", "side": "BUY", "hash": "86886f9f8bd28f1617c05e9e2f4ae036bdcdff10", "best_bid": "0.67", "best_ask": "0.68"}, {"asset_id": "36538842701383075131399258783814730353525125143988435459349182813934073807848", "price": "0.82", "size": "250", "side": "SELL", "hash": "d3a31cb4b046c11be8a593cc28c64e0f042fc8ee", "best_bid": "0.32", "best_ask": "0.33"}], "timestamp": "1769384068100", "event_type": "price_change"}}
{"_local_timestamp": "2026-01-25T23:34:28.551329+00:00", "data": {"market": "0x715eb3d786c7d27ff65c28b3122ad0ecb41e3d0ca588dc1e291317a06c1ec47f", "price_changes": [{"asset_id": "21550149566526602463623919476906543820980714141926005576912997545264282073790", "price": "0.06", "size": "4000", "side": "BUY", "hash": "15c8df25d178bd5e0badd4a281fa39fd07554e10", "best_bid": "0.998", "best_ask": "0.999"}, {"asset_id": "64042023499171690072089529671394245926342142288867064196322402966461454126280", "price": "0.94", "size": "4000", "side": "SELL", "hash": "14f2947e0e90ba7d2662dd64a97a620603c26063", "best_bid": "0.001", "best_ask": "0.002"}], "timestamp": "1769384068105", "event_type": "price_change"}}
{"_local_timestamp": "2026-01-25T23:34:28.796908+00:00", "data": {"market": "0x715eb3d786c7d27ff65c28b3122ad0ecb41e3d0ca588dc1e291317a06c1ec47f", "price_changes": [{"asset_id": "21550149566526602463623919476906543820980714141926005576912997545264282073790", "price": "0.4", "size": "125", "side": "BUY", "hash": "69d1ba72299a675e3367a39ac577c7c7573dc02d", "best_bid": "0.998", "best_ask": "0.999"}, {"asset_id": "64042023499171690072089529671394245926342142288867064196322402966461454126280", "price": "0.6", "size": "125", "side": "SELL", "hash": "127a06af0939412b452a9ea07a0935aa6de19c50", "best_bid": "0.001", "best_ask": "0.002"}], "timestamp": "1769384068198", "event_type": "price_change"}}
{"_local_timestamp": "2026-01-25T23:34:28.799636+00:00", "data": {"market": "0x690d504367efdec61936e7dc1c572c1598281f3e91d30d3b6148f3f1f48642d5", "price_changes": [{"asset_id": "51469050125334342675041532938035006268212349126791674076934139732091152113995", "price": "0.27", "size": "3577", "side": "BUY", "hash": "775966a35abf13d34633a328bfc0fe77a9a5a4d6", "best_bid": "0.67", "best_ask": "0.68"}, {"asset_id": "36538842701383075131399258783814730353525125143988435459349182813934073807848", "price": "0.73", "size": "3577", "side": "SELL", "hash": "494f8aaa45763cfabc91e9e9e06c7a1036d75bd8", "best_bid": "0.32", "best_ask": "0.33"}], "timestamp": "1769384068198", "event_type": "price_change"}}
{"_local_timestamp": "2026-01-25T23:34:45.107822+00:00", "data": {"market": "0x690d504367efdec61936e7dc1c572c1598281f3e91d30d3b6148f3f1f48642d5", "price_changes": [{"asset_id": "36538842701383075131399258783814730353525125143988435459349182813934073807848", "price": "0.34", "size": "520.05", "side": "SELL", "hash": "032b1cf24ef499e9c9111d42811fb81a7e6697ab", "best_bid": "0.32", "best_ask": "0.33"}, {"asset_id": "51469050125334342675041532938035006268212349126791674076934139732091152113995", "price": "0.66", "size": "520.05", "side": "BUY", "hash": "cc7356db1e5d53f98f4c9f44d51e548030622091", "best_bid": "0.67", "best_ask": "0.68"}], "timestamp": "1769384085001", "event_type": "price_change"}}
{"_local_timestamp": "2026-01-25T23:34:45.128980+00:00", "data": {"market": "0x807a5bd3d52942c2d8b58bf71a583d4aa03a637f3fd9ff7a7c4a1ad818003067", "price_changes": [{"asset_id": "69732267236340588035067724177359769962979053624149789047101950615640324836190", "price": "0.37", "size": "250", "side": "SELL", "hash": "88d3a394e0a5684c3363e5dc0ac3d59740a92b14", "best_bid": "0.34", "best_ask": "0.36"}, {"asset_id": "51273396751548994017117054764897754414228591289652072971120018616721173971444", "price": "0.63", "size": "250", "side": "BUY", "hash": "4b24b3ae5003911a1589767427294bfcdfe86e6a", "best_bid": "0.64", "best_ask": "0.66"}], "timestamp": "1769384085004", "event_type": "price_change"}}
{"_local_timestamp": "2026-01-25T23:35:06.956748+00:00", "data": {"market": "0x690d504367efdec61936e7dc1c572c1598281f3e91d30d3b6148f3f1f48642d5", "price_changes": [{"asset_id": "51469050125334342675041532938035006268212349126791674076934139732091152113995", "price": "0.66", "size": "540.05", "side": "BUY", "hash": "3591bc8403ff630e80060e1cc3c7a90e3f4fc0a5", "best_bid": "0.67", "best_ask": "0.68"}, {"asset_id": "36538842701383075131399258783814730353525125143988435459349182813934073807848", "price": "0.34", "size": "540.05", "side": "SELL", "hash": "07de28a96519bce8be30f47a9709820edda987ae", "best_bid": "0.32", "best_ask": "0.33"}], "timestamp": "1769384106885", "event_type": "price_change"}}
{"_local_timestamp": "2026-01-25T23:35:06.957564+00:00", "data": {"market": "0x690d504367efdec61936e7dc1c572c1598281f3e91d30d3b6148f3f1f48642d5", "price_changes": [{"asset_id": "36538842701383075131399258783814730353525125143988435459349182813934073807848", "price": "0.31", "size": "1755.05", "side": "BUY", "hash": "434ca0582a596bbfe6232e04995d104642de8cc0", "best_bid": "0.32", "best_ask": "0.33"}, {"asset_id": "51469050125334342675041532938035006268212349126791674076934139732091152113995", "price": "0.69", "size": "1755.05", "side": "SELL", "hash": "31c74511a8217f4f0a0df5f02fac8618d6bcb7db", "best_bid": "0.67", "best_ask": "0.68"}], "timestamp": "1769384106886", "event_type": "price_change"}}
{"_local_timestamp": "2026-01-25T23:35:11.014671+00:00", "data": {"market": "0x807a5bd3d52942c2d8b58bf71a583d4aa03a637f3fd9ff7a7c4a1ad818003067", "price_changes": [{"asset_id": "51273396751548994017117054764897754414228591289652072971120018616721173971444", "price": "0.34", "size": "3000", "side": "BUY", "hash": "65e06633a43e993cc4c799971c102e15eb790d83", "best_bid": "0.64", "best_ask": "0.66"}, {"asset_id": "69732267236340588035067724177359769962979053624149789047101950615640324836190", "price": "0.66", "size": "3000", "side": "SELL", "hash": "48f6be589a1e187e670c643cca0a236c15571cd1", "best_bid": "0.34", "best_ask": "0.36"}], "timestamp": "1769384110919", "event_type": "price_change"}}
{"_local_timestamp": "2026-01-25T23:35:16.272117+00:00", "data": {"market": "0x690d504367efdec61936e7dc1c572c1598281f3e91d30d3b6148f3f1f48642d5", "price_changes": [{"asset_id": "51469050125334342675041532938035006268212349126791674076934139732091152113995", "price": "0.18", "size": "2582", "side": "BUY", "hash": "2006cbe1a23d6ac47b63931d504faecc95df3259", "best_bid": "0.67", "best_ask": "0.68"}, {"asset_id": "36538842701383075131399258783814730353525125143988435459349182813934073807848", "price": "0.82", "size": "2582", "side": "SELL", "hash": "a1ebfa359d23748bf448bfcaab66dd6fab98506e", "best_bid": "0.32", "best_ask": "0.33"}], "timestamp": "1769384116205", "event_type": "price_change"}}
{"_local_timestamp": "2026-01-25T23:35:23.743879+00:00", "data": {"market": "0x690d504367efdec61936e7dc1c572c1598281f3e91d30d3b6148f3f1f48642d5", "price_changes": [{"asset_id": "51469050125334342675041532938035006268212349126791674076934139732091152113995", "price": "0.19", "size": "50", "side": "BUY", "hash": "ac800be8e2f36f708eb960a5bf93cd9ae6d02e3e", "best_bid": "0.67", "best_ask": "0.68"}, {"asset_id": "36538842701383075131399258783814730353525125143988435459349182813934073807848", "price": "0.81", "size": "50", "side": "SELL", "hash": "41fa4a5ee20c7f2339fbca68a71a1e876467f3be", "best_bid": "0.32", "best_ask": "0.33"}], "timestamp": "1769384123668", "event_type": "price_change"}}
{"_local_timestamp": "2026-01-25T23:35:24.254353+00:00", "data": {"market": "0x690d504367efdec61936e7dc1c572c1598281f3e91d30d3b6148f3f1f48642d5", "price_changes": [{"asset_id": "51469050125334342675041532938035006268212349126791674076934139732091152113995", "price": "0.17", "size": "1254.7", "side": "BUY", "hash": "76e4030ac120842df55f58100250df7fd91aa54b", "best_bid": "0.67", "best_ask": "0.68"}, {"asset_id": "36538842701383075131399258783814730353525125143988435459349182813934073807848", "price": "0.83", "size": "1254.7", "side": "SELL", "hash": "c1966f6bf53871223dcde0f1cbe2c9121cade88c", "best_bid": "0.32", "best_ask": "0.33"}], "timestamp": "1769384123987", "event_type": "price_change"}}
{"_local_timestamp": "2026-01-25T23:35:26.659820+00:00", "data": {"market": "0x807a5bd3d52942c2d8b58bf71a583d4aa03a637f3fd9ff7a7c4a1ad818003067", "price_changes": [{"asset_id": "51273396751548994017117054764897754414228591289652072971120018616721173971444", "price": "0.18", "size": "150", "side": "BUY", "hash": "9ebc2b051aca864720c20dfa015dd2bb24460cf0", "best_bid": "0.64", "best_ask": "0.66"}, {"asset_id": "69732267236340588035067724177359769962979053624149789047101950615640324836190", "price": "0.82", "size": "150", "side": "SELL", "hash": "7ff8b7c43cc6b1f3d7c34590a0488d46bb2eef89", "best_bid": "0.34", "best_ask": "0.36"}], "timestamp": "1769384126561", "event_type": "price_change"}}
{"_local_timestamp": "2026-01-25T23:35:26.660630+00:00", "data": {"market": "0x690d504367efdec61936e7dc1c572c1598281f3e91d30d3b6148f3f1f48642d5", "price_changes": [{"asset_id": "51469050125334342675041532938035006268212349126791674076934139732091152113995", "price": "0.18", "size": "2482", "side": "BUY", "hash": "d43f43d0db7cb681455b4377e17e297a45a03790", "best_bid": "0.67", "best_ask": "0.68"}, {"asset_id": "36538842701383075131399258783814730353525125143988435459349182813934073807848", "price": "0.82", "size": "2482", "side": "SELL", "hash": "5d4d8bd54ed6b83ce8e28db520324b3f360a6886", "best_bid": "0.32", "best_ask": "0.33"}], "timestamp": "1769384126561", "event_type": "price_change"}}
{"_local_timestamp": "2026-01-25T23:35:27.088292+00:00", "data": {"market": "0x807a5bd3d52942c2d8b58bf71a583d4aa03a637f3fd9ff7a7c4a1ad818003067", "price_changes": [{"asset_id": "51273396751548994017117054764897754414228591289652072971120018616721173971444", "price": "0.19", "size": "2510", "side": "BUY", "hash": "8dd93db90034799f83512b25c43eccb632f67ec9", "best_bid": "0.64", "best_ask": "0.66"}, {"asset_id": "69732267236340588035067724177359769962979053624149789047101950615640324836190", "price": "0.81", "size": "2510", "side": "SELL", "hash": "10dcdb9e32c75e0640841f718cab757978d0808e", "best_bid": "0.34", "best_ask": "0.36"}], "timestamp": "1769384126897", "event_type": "price_change"}}
{"_local_timestamp": "2026-01-25T23:35:27.092698+00:00", "data": {"market": "0x690d504367efdec61936e7dc1c572c1598281f3e91d30d3b6148f3f1f48642d5", "price_changes": [{"asset_id": "51469050125334342675041532938035006268212349126791674076934139732091152113995", "price": "0.19", "size": "150", "side": "BUY", "hash": "1bb1010b3292673de2633cc6b5a787364392ae03", "best_bid": "0.67", "best_ask": "0.68"}, {"asset_id": "36538842701383075131399258783814730353525125143988435459349182813934073807848", "price": "0.81", "size": "150", "side": "SELL", "hash": "8f062e7a2ec99acd1e5e4329fb2b69a6a95a44f4", "best_bid": "0.32", "best_ask": "0.33"}], "timestamp": "1769384126899", "event_type": "price_change"}}
{"_local_timestamp": "2026-01-25T23:35:30.494747+00:00", "data": {"market": "0x807a5bd3d52942c2d8b58bf71a583d4aa03a637f3fd9ff7a7c4a1ad818003067", "price_changes": [{"asset_id": "51273396751548994017117054764897754414228591289652072971120018616721173971444", "price": "0.34", "size": "0", "side": "BUY", "hash": "bfac6b1391b2cfcc5d80bf4af2dac92036e928b2", "best_bid": "0.64", "best_ask": "0.66"}, {"asset_id": "69732267236340588035067724177359769962979053624149789047101950615640324836190", "price": "0.66", "size": "0", "side": "SELL", "hash": "9eaa4697ac2333e932b95a9329597fb2da5093b8", "best_bid": "0.34", "best_ask": "0.36"}], "timestamp": "1769384130424", "event_type": "price_change"}}
{"_local_timestamp": "2026-01-25T23:35:30.819702+00:00", "data": {"market": "0x690d504367efdec61936e7dc1c572c1598281f3e91d30d3b6148f3f1f48642d5", "price_changes": [{"asset_id": "51469050125334342675041532938035006268212349126791674076934139732091152113995", "price": "0.19", "size": "100", "side": "BUY", "hash": "e1e878fcd43195765f5d2b904656fda570c3576a", "best_bid": "0.67", "best_ask": "0.68"}, {"asset_id": "36538842701383075131399258783814730353525125143988435459349182813934073807848", "price": "0.81", "size": "100", "side": "SELL", "hash": "69ce9b4841ce5ba514a527c5468cd9d3500a4015", "best_bid": "0.32", "best_ask": "0.33"}], "timestamp": "1769384130720", "event_type": "price_change"}}
{"_local_timestamp": "2026-01-25T23:35:31.101244+00:00", "data": {"market": "0x690d504367efdec61936e7dc1c572c1598281f3e91d30d3b6148f3f1f48642d5", "price_changes": [{"asset_id": "51469050125334342675041532938035006268212349126791674076934139732091152113995", "price": "0.17", "size": "1304.7", "side": "BUY", "hash": "319471b6dedcc72fff5dc49a416bc075d3a473ad", "best_bid": "0.67", "best_ask": "0.68"}, {"asset_id": "36538842701383075131399258783814730353525125143988435459349182813934073807848", "price": "0.83", "size": "1304.7", "side": "SELL", "hash": "cbd59f1f6105d768694b2056d04e17447f10fdb8", "best_bid": "0.32", "best_ask": "0.33"}], "timestamp": "1769384131022", "event_type": "price_change"}}
{"_local_timestamp": "2026-01-25T23:35:55.277330+00:00", "data": {"market": "0x690d504367efdec61936e7dc1c572c1598281f3e91d30d3b6148f3f1f48642d5", "price_changes": [{"asset_id": "36538842701383075131399258783814730353525125143988435459349182813934073807848", "price": "0.34", "size": "606.05", "side": "SELL", "hash": "dacee9c2de9fe32ad38d16eeb7fd4f9413bcd2ac", "best_bid": "0.32", "best_ask": "0.33"}, {"asset_id": "51469050125334342675041532938035006268212349126791674076934139732091152113995", "price": "0.66", "size": "606.05", "side": "BUY", "hash": "fadc3040e25bf6093815295a3ee0c0d4b53f38a9", "best_bid": "0.67", "best_ask": "0.68"}], "timestamp": "1769384155180", "event_type": "price_change"}}
{"_local_timestamp": "2026-01-25T23:35:55.821582+00:00", "data": {"market": "0x807a5bd3d52942c2d8b58bf71a583d4aa03a637f3fd9ff7a7c4a1ad818003067", "price_changes": [{"asset_id": "69732267236340588035067724177359769962979053624149789047101950615640324836190", "price": "0.37", "size": "288", "side": "SELL", "hash": "d748427db68ba9f2833f58049ebc69a87bf66a94", "best_bid": "0.34", "best_ask": "0.36"}, {"asset_id": "51273396751548994017117054764897754414228591289652072971120018616721173971444", "price": "0.63", "size": "288", "side": "BUY", "hash": "e70740e31c1e50f3d6d2fd04a62e80a5b56147d4", "best_bid": "0.64", "best_ask": "0.66"}], "timestamp": "1769384155737", "event_type": "price_change"}}
{"_local_timestamp": "2026-01-25T23:35:56.402459+00:00", "data": {"market": "0x807a5bd3d52942c2d8b58bf71a583d4aa03a637f3fd9ff7a7c4a1ad818003067", "price_changes": [{"asset_id": "51273396751548994017117054764897754414228591289652072971120018616721173971444", "price": "0.25", "size": "0", "side": "BUY", "hash": "d1137eab5a52754962a8d978258a07d16c9fc036", "best_bid": "0.64", "best_ask": "0.66"}, {"asset_id": "69732267236340588035067724177359769962979053624149789047101950615640324836190", "price": "0.75", "size": "0", "side": "SELL", "hash": "6e2d23d0fef28f3e7820697874f4eaa8568061b8", "best_bid": "0.34", "best_ask": "0.36"}], "timestamp": "1769384156284", "event_type": "price_change"}}
{"_local_timestamp": "2026-01-25T23:35:56.402932+00:00", "data": {"market": "0x3bb5ceb45e186de77b1faaf56abf427c8c6f1a88532e4a0dc0ad9c1ffdac2a39", "price_changes": [{"asset_id": "107080924640291332768695532594456654301362852895742708190436320623455634988224", "price": "0.311", "size": "0", "side": "BUY", "hash": "fd11fc1d82f97a508e2c1e0dbb8d800566563e3d", "best_bid": "0.999", "best_ask": "1"}, {"asset_id": "77481318171335047328591651032911896763491342646014093639934301019258606619150", "price": "0.689", "size": "0", "side": "SELL", "hash": "95ed24d07a75bbae16506fc2455fa7f2e82d188a", "best_bid": "0", "best_ask": "0.001"}], "timestamp": "1769384156284", "event_type": "price_change"}}
{"_local_timestamp": "2026-01-25T23:35:56.403513+00:00", "data": {"market": "0x690d504367efdec61936e7dc1c572c1598281f3e91d30d3b6148f3f1f48642d5", "price_changes": [{"asset_id": "51469050125334342675041532938035006268212349126791674076934139732091152113995", "price": "0.3", "size": "100", "side": "BUY", "hash": "c63504b1459b5f6f80f0480bdb9c2d33ad6fcb3c", "best_bid": "0.67", "best_ask": "0.68"}, {"asset_id": "36538842701383075131399258783814730353525125143988435459349182813934073807848", "price": "0.7", "size": "100", "side": "SELL", "hash": "9babd8cb10e505cd12524d694392f8342201f93b", "best_bid": "0.32", "best_ask": "0.33"}], "timestamp": "1769384156284", "event_type": "price_change"}}
{"_local_timestamp": "2026-01-25T23:35:56.404331+00:00", "data": {"market": "0x690d504367efdec61936e7dc1c572c1598281f3e91d30d3b6148f3f1f48642d5", "price_changes": [{"asset_id": "51469050125334342675041532938035006268212349126791674076934139732091152113995", "price": "0.26", "size": "0", "side": "BUY", "hash": "c63504b1459b5f6f80f0480bdb9c2d33ad6fcb3c", "best_bid": "0.67", "best_ask": "0.68"}, {"asset_id": "36538842701383075131399258783814730353525125143988435459349182813934073807848", "price": "0.74", "size": "0", "side": "SELL", "hash": "9babd8cb10e505cd12524d694392f8342201f93b", "best_bid": "0.32", "best_ask": "0.33"}], "timestamp": "1769384156284", "event_type": "price_change"}}
{"_local_timestamp": "2026-01-25T23:35:56.847419+00:00", "data": {"market": "0x807a5bd3d52942c2d8b58bf71a583d4aa03a637f3fd9ff7a7c4a1ad818003067", "price_changes": [{"asset_id": "51273396751548994017117054764897754414228591289652072971120018616721173971444", "price": "0.26", "size": "3711.92", "side": "BUY", "hash": "9d583c44f1af3df1605b00c4824f8d8488521633", "best_bid": "0.64", "best_ask": "0.66"}, {"asset_id": "69732267236340588035067724177359769962979053624149789047101950615640324836190", "price": "0.74", "size": "3711.92", "side": "SELL", "hash": "d4c7683fc94117f2923ff53ff7b94e64b3eb60b2", "best_bid": "0.34", "best_ask": "0.36"}], "timestamp": "1769384156718", "event_type": "price_change"}}
{"_local_timestamp": "2026-01-25T23:35:56.847969+00:00", "data": {"market": "0x690d504367efdec61936e7dc1c572c1598281f3e91d30d3b6148f3f1f48642d5", "price_changes": [{"asset_id": "51469050125334342675041532938035006268212349126791674076934139732091152113995", "price": "0.27", "size": "3627", "side": "BUY", "hash": "a97d10ca12f90adc9de30d2a03204f1090ee460d", "best_bid": "0.67", "best_ask": "0.68"}, {"asset_id": "36538842701383075131399258783814730353525125143988435459349182813934073807848", "price": "0.73", "size": "3627", "side": "SELL", "hash": "4d97edda5efc44e3b08836dc63bc20162deb23dc", "best_bid": "0.32", "best_ask": "0.33"}], "timestamp": "1769384156720", "event_type": "price_change"}}
{"_local_timestamp": "2026-01-25T23:35:56.859757+00:00", "data": {"market": "0x3bb5ceb45e186de77b1faaf56abf427c8c6f1a88532e4a0dc0ad9c1ffdac2a39", "price_changes": [{"asset_id": "107080924640291332768695532594456654301362852895742708190436320623455634988224", "price": "0.3", "size": "186.66", "side": "BUY", "hash": "a685c05ddb702639a44f0026283bca1db1a77530", "best_bid": "0.999", "best_ask": "1"}, {"asset_id": "77481318171335047328591651032911896763491342646014093639934301019258606619150", "price": "0.7", "size": "186.66", "side": "SELL", "hash": "0363b2ae262b413588c340120fd93e114043e019", "best_bid": "0", "best_ask": "0.001"}], "timestamp": "1769384156724", "event_type": "price_change"}}
{"_local_timestamp": "2026-01-25T23:35:56.933402+00:00", "data": {"market": "0x690d504367efdec61936e7dc1c572c1598281f3e91d30d3b6148f3f1f48642d5", "price_changes": [{"asset_id": "51469050125334342675041532938035006268212349126791674076934139732091152113995", "price": "0.21", "size": "273.8", "side": "BUY", "hash": "5508fbbbb2e742d455ca733406f6e65de698621d", "best_bid": "0.67", "best_ask": "0.68"}, {"asset_id": "36538842701383075131399258783814730353525125143988435459349182813934073807848", "price": "0.79", "size": "273.8", "side": "SELL", "hash": "b9e4e54b757744000a62f3ff61f58bf410a09155", "best_bid": "0.32", "best_ask": "0.33"}], "timestamp": "1769384156755", "event_type": "price_change"}}
{"_local_timestamp": "2026-01-25T23:35:58.155032+00:00", "data": {"market": "0x690d504367efdec61936e7dc1c572c1598281f3e91d30d3b6148f3f1f48642d5", "price_changes": [{"asset_id": "51469050125334342675041532938035006268212349126791674076934139732091152113995", "price": "0.18", "size": "150", "side": "BUY", "hash": "a86abaa90e4461de81b8501370a00117f6cab9d0", "best_bid": "0.67", "best_ask": "0.68"}, {"asset_id": "36538842701383075131399258783814730353525125143988435459349182813934073807848", "price": "0.82", "size": "150", "side": "SELL", "hash": "a83a70a319c4c192be8d886c81716c2b4d69ce88", "best_bid": "0.32", "best_ask": "0.33"}], "timestamp": "1769384158066", "event_type": "price_change"}}
{"_local_timestamp": "2026-01-25T23:36:02.434944+00:00", "data": {"market": "0x690d504367efdec61936e7dc1c572c1598281f3e91d30d3b6148f3f1f48642d5", "price_changes": [{"asset_id": "51469050125334342675041532938035006268212349126791674076934139732091152113995", "price": "0.17", "size": "1154.7", "side": "BUY", "hash": "e2cb0e04f1b4e564c804b9d7a17fedf5e4f08d00", "best_bid": "0.67", "best_ask": "0.68"}, {"asset_id": "36538842701383075131399258783814730353525125143988435459349182813934073807848", "price": "0.83", "size": "1154.7", "side": "SELL", "hash": "8639a0ef660cfb6e363796294d58001bc026675f", "best_bid": "0.32", "best_ask": "0.33"}], "timestamp": "1769384162319", "event_type": "price_change"}}
{"_local_timestamp": "2026-01-25T23:36:02.683692+00:00", "data": {"market": "0x690d504367efdec61936e7dc1c572c1598281f3e91d30d3b6148f3f1f48642d5", "price_changes": [{"asset_id": "51469050125334342675041532938035006268212349126791674076934139732091152113995", "price": "0.18", "size": "300", "side": "BUY", "hash": "72c8587d32e85576df55542109b74f7db2d35b01", "best_bid": "0.67", "best_ask": "0.68"}, {"asset_id": "36538842701383075131399258783814730353525125143988435459349182813934073807848", "price": "0.82", "size": "300", "side": "SELL", "hash": "70144761581f5459cb73f29e593521bbb45900d4", "best_bid": "0.32", "best_ask": "0.33"}], "timestamp": "1769384162559", "event_type": "price_change"}}
{"_local_timestamp": "2026-01-25T23:36:11.351109+00:00", "data": {"market": "0x690d504367efdec61936e7dc1c572c1598281f3e91d30d3b6148f3f1f48642d5", "price_changes": [{"asset_id": "51469050125334342675041532938035006268212349126791674076934139732091152113995", "price": "0.17", "size": "1104.7", "side": "BUY", "hash": "45b6a10836f87882891099864eb3f1ce90aa20bc", "best_bid": "0.67", "best_ask": "0.68"}, {"asset_id": "36538842701383075131399258783814730353525125143988435459349182813934073807848", "price": "0.83", "size": "1104.7", "side": "SELL", "hash": "4790cbf59f87ffce2699f2913bb47e20977e3c27", "best_bid": "0.32", "best_ask": "0.33"}], "timestamp": "1769384171279", "event_type": "price_change"}}
{"_local_timestamp": "2026-01-25T23:36:11.381708+00:00", "data": {"market": "0x3bb5ceb45e186de77b1faaf56abf427c8c6f1a88532e4a0dc0ad9c1ffdac2a39", "price_changes": [{"asset_id": "107080924640291332768695532594456654301362852895742708190436320623455634988224", "price": "0.962", "size": "20", "side": "BUY", "hash": "0e6bab9bdd4b9dfeae90e2ebcbf22bbcd47918ba", "best_bid": "0.999", "best_ask": "1"}, {"asset_id": "77481318171335047328591651032911896763491342646014093639934301019258606619150", "price": "0.038", "size": "20", "side": "SELL", "hash": "9d60b786404bcc62f2c0ea85922072d0fa9e8921", "best_bid": "0", "best_ask": "0.001"}], "timestamp": "1769384171311", "event_type": "price_change"}}
{"_local_timestamp": "2026-01-25T23:36:11.382264+00:00", "data": {"market": "0xd33b405694c28eb7ea092d5146085fe9234fffa467b4449b068a11f4762aa527", "price_changes": [{"asset_id": "100610158895422953936472708271328576009207076613232354004933524717835418544370", "price": "0.962", "size": "20", "side": "BUY", "hash": "cdf87a408eb8763419ee9e2a89a3798e9cd9d5cb", "best_bid": "0.999", "best_ask": "1"}, {"asset_id": "40582400653155619328075956469552500170030522046193955547557477713370279563057", "price": "0.038", "size": "20", "side": "SELL", "hash": "c42174b36b15129d16ed830854ad4ef43085970f", "best_bid": "0", "best_ask": "0.001"}], "timestamp": "1769384171312", "event_type": "price_change"}}
{"_local_timestamp": "2026-01-25T23:36:11.658819+00:00", "data": {"market": "0x690d504367efdec61936e7dc1c572c1598281f3e91d30d3b6148f3f1f48642d5", "price_changes": [{"asset_id": "51469050125334342675041532938035006268212349126791674076934139732091152113995", "price": "0.18", "size": "350", "side": "BUY", "hash": "ae7b4e2653d1b5cb4937c5ad26a5df9144a62218", "best_bid": "0.67", "best_ask": "0.68"}, {"asset_id": "36538842701383075131399258783814730353525125143988435459349182813934073807848", "price": "0.82", "size": "350", "side": "SELL", "hash": "5ba7869a95050c6698d80c72b1c56f3bb745eb16", "best_bid": "0.32", "best_ask": "0.33"}], "timestamp": "1769384171579", "event_type": "price_change"}}
{"_local_timestamp": "2026-01-25T23:36:16.068178+00:00", "data": {"market": "0x690d504367efdec61936e7dc1c572c1598281f3e91d30d3b6148f3f1f48642d5", "price_changes": [{"asset_id": "36538842701383075131399258783814730353525125143988435459349182813934073807848", "price": "0.34", "size": "540.05", "side": "SELL", "hash": "86a4894599b19921375d4dca4666c80086828868", "best_bid": "0.32", "best_ask": "0.33"}, {"asset_id": "51469050125334342675041532938035006268212349126791674076934139732091152113995", "price": "0.66", "size": "540.05", "side": "BUY", "hash": "e3585c436c8f074d3b7ddee2168f18d1e8cf9855", "best_bid": "0.67", "best_ask": "0.68"}], "timestamp": "1769384176000", "event_type": "price_change"}}
{"_local_timestamp": "2026-01-25T23:36:16.099451+00:00", "data": {"market": "0x807a5bd3d52942c2d8b58bf71a583d4aa03a637f3fd9ff7a7c4a1ad818003067", "price_changes": [{"asset_id": "69732267236340588035067724177359769962979053624149789047101950615640324836190", "price": "0.37", "size": "250", "side": "SELL", "hash": "bfa5be838ca975979f8fff9076c6fe23816e9084", "best_bid": "0.34", "best_ask": "0.36"}, {"asset_id": "51273396751548994017117054764897754414228591289652072971120018616721173971444", "price": "0.63", "size": "250", "side": "BUY", "hash": "b9b712c4fb8151eaa46dc9e70c4e344d3a72c5f2", "best_bid": "0.64", "best_ask": "0.66"}], "timestamp": "1769384176000", "event_type": "price_change"}}
{"_local_timestamp": "2026-01-25T23:36:43.330872+00:00", "data": {"market": "0x690d504367efdec61936e7dc1c572c1598281f3e91d30d3b6148f3f1f48642d5", "price_changes": [{"asset_id": "51469050125334342675041532938035006268212349126791674076934139732091152113995", "price": "0.18", "size": "200", "side": "BUY", "hash": "5d6c39d252ee8f6bf77dbfccfc4b87bafe314f59", "best_bid": "0.67", "best_ask": "0.68"}, {"asset_id": "36538842701383075131399258783814730353525125143988435459349182813934073807848", "price": "0.82", "size": "200", "side": "SELL", "hash": "29f669f911100eec48a79c038d046b5e42af8bc1", "best_bid": "0.32", "best_ask": "0.33"}], "timestamp": "1769384203221", "event_type": "price_change"}}
{"_local_timestamp": "2026-01-25T23:36:43.627427+00:00", "data": {"market": "0x690d504367efdec61936e7dc1c572c1598281f3e91d30d3b6148f3f1f48642d5", "price_changes": [{"asset_id": "51469050125334342675041532938035006268212349126791674076934139732091152113995", "price": "0.17", "size": "1254.7", "side": "BUY", "hash": "ad23b4cdd275bb0764d011f699636e66585b95ee", "best_bid": "0.67", "best_ask": "0.68"}, {"asset_id": "36538842701383075131399258783814730353525125143988435459349182813934073807848", "price": "0.83", "size": "1254.7", "side": "SELL", "hash": "660cd39c63e6b41161db7b14b8d7bc45796a449b", "best_bid": "0.32", "best_ask": "0.33"}], "timestamp": "1769384203559", "event_type": "price_change"}}
{"_local_timestamp": "2026-01-25T23:36:50.181458+00:00", "data": {"market": "0x690d504367efdec61936e7dc1c572c1598281f3e91d30d3b6148f3f1f48642d5", "price_changes": [{"asset_id": "51469050125334342675041532938035006268212349126791674076934139732091152113995", "price": "0.6", "size": "10195.71", "side": "BUY", "hash": "8daa13a103c85277512cc7aa850ca687e5e39104", "best_bid": "0.67", "best_ask": "0.68"}, {"asset_id": "36538842701383075131399258783814730353525125143988435459349182813934073807848", "price": "0.4", "size": "10195.71", "side": "SELL", "hash": "e4c4c3e6e8d5ad60c9c981029a37d9d16378ca28", "best_bid": "0.32", "best_ask": "0.33"}], "timestamp": "1769384210109", "event_type": "price_change"}}
{"_local_timestamp": "2026-01-25T23:36:53.521505+00:00", "data": {"market": "0x690d504367efdec61936e7dc1c572c1598281f3e91d30d3b6148f3f1f48642d5", "price_changes": [{"asset_id": "51469050125334342675041532938035006268212349126791674076934139732091152113995", "price": "0.2", "size": "0", "side": "BUY", "hash": "5014e8b422ef906e7b93dadde2ac08fb86226e24", "best_bid": "0.67", "best_ask": "0.68"}, {"asset_id": "36538842701383075131399258783814730353525125143988435459349182813934073807848", "price": "0.8", "size": "0", "side": "SELL", "hash": "fadb1b52a969def0f83ed7fe4326d6ef28ff81aa", "best_bid": "0.32", "best_ask": "0.33"}], "timestamp": "1769384213455", "event_type": "price_change"}}
{"_local_timestamp": "2026-01-25T23:36:53.831570+00:00", "data": {"market": "0x690d504367efdec61936e7dc1c572c1598281f3e91d30d3b6148f3f1f48642d5", "price_changes": [{"asset_id": "51469050125334342675041532938035006268212349126791674076934139732091152113995", "price": "0.2", "size": "5.63", "side": "BUY", "hash": "7b0dfb108606c486088eaba3a5dcf8136a97e0d8", "best_bid": "0.67", "best_ask": "0.68"}, {"asset_id": "36538842701383075131399258783814730353525125143988435459349182813934073807848", "price": "0.8", "size": "5.63", "side": "SELL", "hash": "902e8e79442dd98048e5d5707f89c28e7c8dc254", "best_bid": "0.32", "best_ask": "0.33"}], "timestamp": "1769384213759", "event_type": "price_change"}}
{"_local_timestamp": "2026-01-25T23:36:55.226401+00:00", "data": {"market": "0x690d504367efdec61936e7dc1c572c1598281f3e91d30d3b6148f3f1f48642d5", "price_changes": [{"asset_id": "51469050125334342675041532938035006268212349126791674076934139732091152113995", "price": "0.18", "size": "50", "side": "BUY", "hash": "6dc407dcb82f43b5c2aa92c8639454525715a885", "best_bid": "0.67", "best_ask": "0.68"}, {"asset_id": "36538842701383075131399258783814730353525125143988435459349182813934073807848", "price": "0.82", "size": "50", "side": "SELL", "hash": "b0adacacb9ab24b21ebcbafaf59da4d35273c6bb", "best_bid": "0.32", "best_ask": "0.33"}], "timestamp": "1769384215030", "event_type": "price_change"}}
{"_local_timestamp": "2026-01-25T23:36:55.226998+00:00", "data": {"market": "0x807a5bd3d52942c2d8b58bf71a583d4aa03a637f3fd9ff7a7c4a1ad818003067", "price_changes": [{"asset_id": "51273396751548994017117054764897754414228591289652072971120018616721173971444", "price": "0.18", "size": "0", "side": "BUY", "hash": "1b475c415245b6c5e0bc1f7622bcb12c3cee518a", "best_bid": "0.64", "best_ask": "0.66"}, {"asset_id": "69732267236340588035067724177359769962979053624149789047101950615640324836190", "price": "0.82", "size": "0", "side": "SELL", "hash": "23260944fdfcf11f2fb29a05760f1abec94dc1f3", "best_bid": "0.34", "best_ask": "0.36"}], "timestamp": "1769384215030", "event_type": "price_change"}}
{"_local_timestamp": "2026-01-25T23:36:56.149934+00:00", "data": {"market": "0x807a5bd3d52942c2d8b58bf71a583d4aa03a637f3fd9ff7a7c4a1ad818003067", "price_changes": [{"asset_id": "51273396751548994017117054764897754414228591289652072971120018616721173971444", "price": "0.19", "size": "2660", "side": "BUY", "hash": "943ce39166d2f682a09c60aedbacaa539d0632be", "best_bid": "0.64", "best_ask": "0.66"}, {"asset_id": "69732267236340588035067724177359769962979053624149789047101950615640324836190", "price": "0.81", "size": "2660", "side": "SELL", "hash": "f083edea15623be242edae33a7c5099aa51b6912", "best_bid": "0.34", "best_ask": "0.36"}], "timestamp": "1769384215711", "event_type": "price_change"}}
{"_local_timestamp": "2026-01-25T23:36:56.150613+00:00", "data": {"market": "0x690d504367efdec61936e7dc1c572c1598281f3e91d30d3b6148f3f1f48642d5", "price_changes": [{"asset_id": "51469050125334342675041532938035006268212349126791674076934139732091152113995", "price": "0.17", "size": "1404.7", "side": "BUY", "hash": "7cf676487550ed1aa634bdfc7d65c60b9acfb908", "best_bid": "0.67", "best_ask": "0.68"}, {"asset_id": "36538842701383075131399258783814730353525125143988435459349182813934073807848", "price": "0.83", "size": "1404.7", "side": "SELL", "hash": "ce18756d91003f70e1a8fc40f8ba27c97a7cf6ff", "best_bid": "0.32", "best_ask": "0.33"}], "timestamp": "1769384215711", "event_type": "price_change"}}
{"_local_timestamp": "2026-01-25T23:37:00.357902+00:00", "data": {"market": "0x690d504367efdec61936e7dc1c572c1598281f3e91d30d3b6148f3f1f48642d5", "price_changes": [{"asset_id": "51469050125334342675041532938035006268212349126791674076934139732091152113995", "price": "0.18", "size": "0", "side": "BUY", "hash": "aa19f35594993cacdafed755ae0423d80fb710fa", "best_bid": "0.67", "best_ask": "0.68"}, {"asset_id": "36538842701383075131399258783814730353525125143988435459349182813934073807848", "price": "0.82", "size": "0", "side": "SELL", "hash": "a79b95e2bed986a4f19d41ea833b111b91791c27", "best_bid": "0.32", "best_ask": "0.33"}], "timestamp": "1769384220270", "event_type": "price_change"}}
{"_local_timestamp": "2026-01-25T23:37:00.655110+00:00", "data": {"market": "0x690d504367efdec61936e7dc1c572c1598281f3e91d30d3b6148f3f1f48642d5", "price_changes": [{"asset_id": "51469050125334342675041532938035006268212349126791674076934139732091152113995", "price": "0.17", "size": "1454.7", "side": "BUY", "hash": "6bb2976d35e660b6b18631179b586ff3847dedeb", "best_bid": "0.67", "best_ask": "0.68"}, {"asset_id": "36538842701383075131399258783814730353525125143988435459349182813934073807848", "price": "0.83", "size": "1454.7", "side": "SELL", "hash": "7b05b916f23900022118756c47ddfed77647d507", "best_bid": "0.32", "best_ask": "0.33"}], "timestamp": "1769384220585", "event_type": "price_change"}}
{"_local_timestamp": "2026-01-25T23:37:05.746747+00:00", "data": {"market": "0x690d504367efdec61936e7dc1c572c1598281f3e91d30d3b6148f3f1f48642d5", "price_changes": [{"asset_id": "51469050125334342675041532938035006268212349126791674076934139732091152113995", "price": "0.2", "size": "2105.63", "side": "BUY", "hash": "ea35ac41d3abfd5bd45f9ff122d285b1a8744476", "best_bid": "0.67", "best_ask": "0.68"}, {"asset_id": "36538842701383075131399258783814730353525125143988435459349182813934073807848", "price": "0.8", "size": "2105.63", "side": "SELL", "hash": "0f38d200be8c73d6461e2f4049cd1d138e958339", "best_bid": "0.32", "best_ask": "0.33"}], "timestamp": "1769384225677", "event_type": "price_change"}}
{"_local_timestamp": "2026-01-25T23:37:13.060154+00:00", "data": {"market": "0x690d504367efdec61936e7dc1c572c1598281f3e91d30d3b6148f3f1f48642d5", "price_changes": [{"asset_id": "51469050125334342675041532938035006268212349126791674076934139732091152113995", "price": "0.19", "size": "0", "side": "BUY", "hash": "a8bc6ca5405fad2aabd5b455ede184480e2358e3", "best_bid": "0.67", "best_ask": "0.68"}, {"asset_id": "36538842701383075131399258783814730353525125143988435459349182813934073807848", "price": "0.81", "size": "0", "side": "SELL", "hash": "aed9549087eac5d058d8f51e76527d238a6ca394", "best_bid": "0.32", "best_ask": "0.33"}], "timestamp": "1769384232988", "event_type": "price_change"}}
{"_local_timestamp": "2026-01-25T23:37:13.516591+00:00", "data": {"market": "0x690d504367efdec61936e7dc1c572c1598281f3e91d30d3b6148f3f1f48642d5", "price_changes": [{"asset_id": "51469050125334342675041532938035006268212349126791674076934139732091152113995", "price": "0.18", "size": "100", "side": "BUY", "hash": "7022e11ddedb17a84dd6dfdaf42e447a1ff20c9e", "best_bid": "0.67", "best_ask": "0.68"}, {"asset_id": "36538842701383075131399258783814730353525125143988435459349182813934073807848", "price": "0.82", "size": "100", "side": "SELL", "hash": "a37acc77e36e01329493684b11b73820e0fc3299", "best_bid": "0.32", "best_ask": "0.33"}], "timestamp": "1769384233369", "event_type": "price_change"}}
{"_local_timestamp": "2026-01-25T23:37:25.081491+00:00", "data": {"market": "0x690d504367efdec61936e7dc1c572c1598281f3e91d30d3b6148f3f1f48642d5", "price_changes": [{"asset_id": "36538842701383075131399258783814730353525125143988435459349182813934073807848", "price": "0.34", "size": "606.05", "side": "SELL", "hash": "cb7e7d249ff4f3b75571d9666fd377150a877bc4", "best_bid": "0.32", "best_ask": "0.33"}, {"asset_id": "51469050125334342675041532938035006268212349126791674076934139732091152113995", "price": "0.66", "size": "606.05", "side": "BUY", "hash": "a398bfd7c964dd9f20ee8348173840dffb82038f", "best_bid": "0.67", "best_ask": "0.68"}], "timestamp": "1769384245002", "event_type": "price_change"}}
{"_local_timestamp": "2026-01-25T23:37:25.628495+00:00", "data": {"market": "0x807a5bd3d52942c2d8b58bf71a583d4aa03a637f3fd9ff7a7c4a1ad818003067", "price_changes": [{"asset_id": "69732267236340588035067724177359769962979053624149789047101950615640324836190", "price": "0.37", "size": "288", "side": "SELL", "hash": "fb9229fc4b968000a4a61297eaa4c74e467c3a1b", "best_bid": "0.34", "best_ask": "0.36"}, {"asset_id": "51273396751548994017117054764897754414228591289652072971120018616721173971444", "price": "0.63", "size": "288", "side": "BUY", "hash": "49d3ae97280c109bd90d3865c29724c01886edd3", "best_bid": "0.64", "best_ask": "0.66"}], "timestamp": "1769384245560", "event_type": "price_change"}}
{"_local_timestamp": "2026-01-25T23:37:31.809363+00:00", "data": {"market": "0x690d504367efdec61936e7dc1c572c1598281f3e91d30d3b6148f3f1f48642d5", "price_changes": [{"asset_id": "51469050125334342675041532938035006268212349126791674076934139732091152113995", "price": "0.6", "size": "10060", "side": "BUY", "hash": "b2527145ded7ba2d0c1f32837d9685df17dd2cdb", "best_bid": "0.67", "best_ask": "0.68"}, {"asset_id": "36538842701383075131399258783814730353525125143988435459349182813934073807848", "price": "0.4", "size": "10060", "side": "SELL", "hash": "343117ebb4e7ae6e08481374e0c0fadad60a48f2", "best_bid": "0.32", "best_ask": "0.33"}], "timestamp": "1769384251707", "event_type": "price_change"}}
{"_local_timestamp": "2026-01-25T23:37:35.204188+00:00", "data": {"market": "0x690d504367efdec61936e7dc1c572c1598281f3e91d30d3b6148f3f1f48642d5", "price_changes": [{"asset_id": "51469050125334342675041532938035006268212349126791674076934139732091152113995", "price": "0.2", "size": "5.63", "side": "BUY", "hash": "298f07730a94f0fc87a79d969d432a10766776e2", "best_bid": "0.67", "best_ask": "0.68"}, {"asset_id": "36538842701383075131399258783814730353525125143988435459349182813934073807848", "price": "0.8", "size": "5.63", "side": "SELL", "hash": "b3b4afc59e47a042bcbf7fb052a1baab2124f677", "best_bid": "0.32", "best_ask": "0.33"}], "timestamp": "1769384255116", "event_type": "price_change"}}
{"_local_timestamp": "2026-01-25T23:37:44.119866+00:00", "data": {"market": "0x690d504367efdec61936e7dc1c572c1598281f3e91d30d3b6148f3f1f48642d5", "price_changes": [{"asset_id": "51469050125334342675041532938035006268212349126791674076934139732091152113995", "price": "0.17", "size": "1404.7", "side": "BUY", "hash": "b42db190517b3c986f868bd26dbdc005fa903646", "best_bid": "0.67", "best_ask": "0.68"}, {"asset_id": "36538842701383075131399258783814730353525125143988435459349182813934073807848", "price": "0.83", "size": "1404.7", "side": "SELL", "hash": "db31f454052fab275ad42ef882fd71ebf54bd3b9", "best_bid": "0.32", "best_ask": "0.33"}], "timestamp": "1769384264005", "event_type": "price_change"}}
{"_local_timestamp": "2026-01-25T23:37:44.389260+00:00", "data": {"market": "0x690d504367efdec61936e7dc1c572c1598281f3e91d30d3b6148f3f1f48642d5", "price_changes": [{"asset_id": "51469050125334342675041532938035006268212349126791674076934139732091152113995", "price": "0.2", "size": "55.63", "side": "BUY", "hash": "ce2745e572b4bae840faff87a69f8132644ed885", "best_bid": "0.67", "best_ask": "0.68"}, {"asset_id": "36538842701383075131399258783814730353525125143988435459349182813934073807848", "price": "0.8", "size": "55.63", "side": "SELL", "hash": "e8a4b5e80808df2f903be685b665b49d8da9e8f1", "best_bid": "0.32", "best_ask": "0.33"}], "timestamp": "1769384264302", "event_type": "price_change"}}
{"_local_timestamp": "2026-01-25T23:37:45.099844+00:00", "data": {"market": "0x807a5bd3d52942c2d8b58bf71a583d4aa03a637f3fd9ff7a7c4a1ad818003067", "price_changes": [{"asset_id": "69732267236340588035067724177359769962979053624149789047101950615640324836190", "price": "0.37", "size": "250", "side": "SELL", "hash": "97d6250b6a144c43f63191c0a51af153abe1d821", "best_bid": "0.34", "best_ask": "0.36"}, {"asset_id": "51273396751548994017117054764897754414228591289652072971120018616721173971444", "price": "0.63", "size": "250", "side": "BUY", "hash": "2d93ea450015d0c340da92b12c60c81db4cb0ba0", "best_bid": "0.64", "best_ask": "0.66"}], "timestamp": "1769384265002", "event_type": "price_change"}}
{"_local_timestamp": "2026-01-25T23:37:45.100407+00:00", "data": {"market": "0x690d504367efdec61936e7dc1c572c1598281f3e91d30d3b6148f3f1f48642d5", "price_changes": [{"asset_id": "36538842701383075131399258783814730353525125143988435459349182813934073807848", "price": "0.34", "size": "540.05", "side": "SELL", "hash": "856bbc1b1121362235669168e402ff9579adb377", "best_bid": "0.32", "best_ask": "0.33"}, {"asset_id": "51469050125334342675041532938035006268212349126791674076934139732091152113995", "price": "0.66", "size": "540.05", "side": "BUY", "hash": "92c0c2aeebab7caf2b74bf3f74f21ae5479b624f", "best_bid": "0.67", "best_ask": "0.68"}], "timestamp": "1769384265003", "event_type": "price_change"}}
{"_local_timestamp": "2026-01-25T23:38:03.631875+00:00", "data": {"market": "0x690d504367efdec61936e7dc1c572c1598281f3e91d30d3b6148f3f1f48642d5", "price_changes": [{"asset_id": "51469050125334342675041532938035006268212349126791674076934139732091152113995", "price": "0.17", "size": "1254.7", "side": "BUY", "hash": "db28a391ea40d0d45440e90bb9809e7ac34d507b", "best_bid": "0.67", "best_ask": "0.68"}, {"asset_id": "36538842701383075131399258783814730353525125143988435459349182813934073807848", "price": "0.83", "size": "1254.7", "side": "SELL", "hash": "ee56156dea6937e2ea763845d1ecfeae6649e1c2", "best_bid": "0.32", "best_ask": "0.33"}], "timestamp": "1769384283563", "event_type": "price_change"}}
{"_local_timestamp": "2026-01-25T23:38:04.028986+00:00", "data": {"market": "0x690d504367efdec61936e7dc1c572c1598281f3e91d30d3b6148f3f1f48642d5", "price_changes": [{"asset_id": "51469050125334342675041532938035006268212349126791674076934139732091152113995", "price": "0.2", "size": "205.63", "side": "BUY", "hash": "b3dda6fc12486800bd5c255700f36d50d57c484f", "best_bid": "0.67", "best_ask": "0.68"}, {"asset_id": "36538842701383075131399258783814730353525125143988435459349182813934073807848", "price": "0.8", "size": "205.63", "side": "SELL", "hash": "adf1caa5349f1a1f317ea55182971747bb9a1d3b", "best_bid": "0.32", "best_ask": "0.33"}], "timestamp": "1769384283935", "event_type": "price_change"}}
{"_local_timestamp": "2026-01-25T23:38:21.176357+00:00", "data": {"market": "0x3bb5ceb45e186de77b1faaf56abf427c8c6f1a88532e4a0dc0ad9c1ffdac2a39", "price_changes": [{"asset_id": "107080924640291332768695532594456654301362852895742708190436320623455634988224", "price": "0.4", "size": "64", "side": "BUY", "hash": "c34edd62a1be8b01ff828c13eb2a522a6396111f", "best_bid": "0.999", "best_ask": "1"}, {"asset_id": "77481318171335047328591651032911896763491342646014093639934301019258606619150", "price": "0.6", "size": "64", "side": "SELL", "hash": "fd1208ad5d401a4307995ebe11a28f7137cf18fd", "best_bid": "0", "best_ask": "0.001"}], "timestamp": "1769384301105", "event_type": "price_change"}}
{"_local_timestamp": "2026-01-25T23:38:21.180744+00:00", "data": {"market": "0x715eb3d786c7d27ff65c28b3122ad0ecb41e3d0ca588dc1e291317a06c1ec47f", "price_changes": [{"asset_id": "21550149566526602463623919476906543820980714141926005576912997545264282073790", "price": "0.34", "size": "0", "side": "BUY", "hash": "f0fcd3848c23be5d943ef033c61ca1d1ec9a035d", "best_bid": "0.998", "best_ask": "0.999"}, {"asset_id": "64042023499171690072089529671394245926342142288867064196322402966461454126280", "price": "0.66", "size": "0", "side": "SELL", "hash": "6bf8cdb431e8cabc1651529c70461f5626a51018", "best_bid": "0.001", "best_ask": "0.002"}], "timestamp": "1769384301105", "event_type": "price_change"}}
{"_local_timestamp": "2026-01-25T23:38:21.570245+00:00", "data": {"market": "0x715eb3d786c7d27ff65c28b3122ad0ecb41e3d0ca588dc1e291317a06c1ec47f", "price_changes": [{"asset_id": "21550149566526602463623919476906543820980714141926005576912997545264282073790", "price": "0.4", "size": "175", "side": "BUY", "hash": "f123e9a00f72304c6a9dacbe47149cae7788c4b9", "best_bid": "0.998", "best_ask": "0.999"}, {"asset_id": "64042023499171690072089529671394245926342142288867064196322402966461454126280", "price": "0.6", "size": "175", "side": "SELL", "hash": "2b57be2bb7f858aa84f0bbfe999863dbfd9d43cf", "best_bid": "0.001", "best_ask": "0.002"}], "timestamp": "1769384301444", "event_type": "price_change"}}
{"_local_timestamp": "2026-01-25T23:38:21.583421+00:00", "data": {"market": "0x3bb5ceb45e186de77b1faaf56abf427c8c6f1a88532e4a0dc0ad9c1ffdac2a39", "price_changes": [{"asset_id": "107080924640291332768695532594456654301362852895742708190436320623455634988224", "price": "0.34", "size": "50", "side": "BUY", "hash": "98803758b6c1bee6f6b3c0a1442b6da920250719", "best_bid": "0.999", "best_ask": "1"}, {"asset_id": "77481318171335047328591651032911896763491342646014093639934301019258606619150", "price": "0.66", "size": "50", "side": "SELL", "hash": "dfd40453f2a70d790e849142100c0b4f108e499b", "best_bid": "0", "best_ask": "0.001"}], "timestamp": "1769384301445", "event_type": "price_change"}}
{"_local_timestamp": "2026-01-25T23:38:32.608535+00:00", "data": {"market": "0x690d504367efdec61936e7dc1c572c1598281f3e91d30d3b6148f3f1f48642d5", "price_changes": [{"asset_id": "51469050125334342675041532938035006268212349126791674076934139732091152113995", "price": "0.2", "size": "155.63", "side": "BUY", "hash": "e2d27afac4d958c2607a41db5f23d0a551a98105", "best_bid": "0.67", "best_ask": "0.68"}, {"asset_id": "36538842701383075131399258783814730353525125143988435459349182813934073807848", "price": "0.8", "size": "155.63", "side": "SELL", "hash": "96c368b02a3e815a754194dd3d8937cfb785cf18", "best_bid": "0.32", "best_ask": "0.33"}], "timestamp": "1769384312537", "event_type": "price_change"}}
{"_local_timestamp": "2026-01-25T23:38:32.941156+00:00", "data": {"market": "0x690d504367efdec61936e7dc1c572c1598281f3e91d30d3b6148f3f1f48642d5", "price_changes": [{"asset_id": "51469050125334342675041532938035006268212349126791674076934139732091152113995", "price": "0.17", "size": "1304.7", "side": "BUY", "hash": "1bb02dc7321295a0955d68d7ccaeab9b9f1d0ee7", "best_bid": "0.67", "best_ask": "0.68"}, {"asset_id": "36538842701383075131399258783814730353525125143988435459349182813934073807848", "price": "0.83", "size": "1304.7", "side": "SELL", "hash": "51abb33eddc8640213787c928d37a88e17eb2835", "best_bid": "0.32", "best_ask": "0.33"}], "timestamp": "1769384312850", "event_type": "price_change"}}
{"_local_timestamp": "2026-01-25T23:38:41.500449+00:00", "data": {"market": "0x690d504367efdec61936e7dc1c572c1598281f3e91d30d3b6148f3f1f48642d5", "price_changes": [{"asset_id": "51469050125334342675041532938035006268212349126791674076934139732091152113995", "price": "0.2", "size": "5.63", "side": "BUY", "hash": "49a6a09c0eabfac3dfb11702317268db9450ea99", "best_bid": "0.67", "best_ask": "0.68"}, {"asset_id": "36538842701383075131399258783814730353525125143988435459349182813934073807848", "price": "0.8", "size": "5.63", "side": "SELL", "hash": "8820c48b093153e4bdf5797256bc1b298ed99de4", "best_bid": "0.32", "best_ask": "0.33"}], "timestamp": "1769384321395", "event_type": "price_change"}}
{"_local_timestamp": "2026-01-25T23:38:41.773290+00:00", "data": {"market": "0x690d504367efdec61936e7dc1c572c1598281f3e91d30d3b6148f3f1f48642d5", "price_changes": [{"asset_id": "51469050125334342675041532938035006268212349126791674076934139732091152113995", "price": "0.17", "size": "1454.7", "side": "BUY", "hash": "cd47efdcb4809ed9f461d4246e64b1b94a4a9143", "best_bid": "0.67", "best_ask": "0.68"}, {"asset_id": "36538842701383075131399258783814730353525125143988435459349182813934073807848", "price": "0.83", "size": "1454.7", "side": "SELL", "hash": "58e2869d0fb7e77a7fb32df309d12d5961db20b0", "best_bid": "0.32", "best_ask": "0.33"}], "timestamp": "1769384321661", "event_type": "price_change"}}
{"_local_timestamp": "2026-01-25T23:38:50.834623+00:00", "data": {"market": "0x690d504367efdec61936e7dc1c572c1598281f3e91d30d3b6148f3f1f48642d5", "price_changes": [{"asset_id": "51469050125334342675041532938035006268212349126791674076934139732091152113995", "price": "0.19", "size": "2210", "side": "BUY", "hash": "6a97b0ee53728cbe2a71737b9f67b24c27281f83", "best_bid": "0.67", "best_ask": "0.68"}, {"asset_id": "36538842701383075131399258783814730353525125143988435459349182813934073807848", "price": "0.81", "size": "2210", "side": "SELL", "hash": "001cf02189db046503a9f9cebde0ed4d5c9e65c1", "best_bid": "0.32", "best_ask": "0.33"}], "timestamp": "1769384330762", "event_type": "price_change"}}
{"_local_timestamp": "2026-01-25T23:38:55.115722+00:00", "data": {"market": "0x690d504367efdec61936e7dc1c572c1598281f3e91d30d3b6148f3f1f48642d5", "price_changes": [{"asset_id": "36538842701383075131399258783814730353525125143988435459349182813934073807848", "price": "0.34", "size": "606.05", "side": "SELL", "hash": "2155923f1988fb97dd9ef1cfbd71f5ca810a37c2", "best_bid": "0.32", "best_ask": "0.33"}, {"asset_id": "51469050125334342675041532938035006268212349126791674076934139732091152113995", "price": "0.66", "size": "606.05", "side": "BUY", "hash": "ea35c35e0a8a7245c9085474302d6ee03ef36bac", "best_bid": "0.67", "best_ask": "0.68"}], "timestamp": "1769384335013", "event_type": "price_change"}}
{"_local_timestamp": "2026-01-25T23:38:55.646697+00:00", "data": {"market": "0x807a5bd3d52942c2d8b58bf71a583d4aa03a637f3fd9ff7a7c4a1ad818003067", "price_changes": [{"asset_id": "69732267236340588035067724177359769962979053624149789047101950615640324836190", "price": "0.37", "size": "288", "side": "SELL", "hash": "ede8af1fb56bb4e8254c2a97044e52e71472c734", "best_bid": "0.34", "best_ask": "0.36"}, {"asset_id": "51273396751548994017117054764897754414228591289652072971120018616721173971444", "price": "0.63", "size": "288", "side": "BUY", "hash": "4f6392d764a39cbc5ac537388b5f7894e3b9fa5b", "best_bid": "0.64", "best_ask": "0.66"}], "timestamp": "1769384335571", "event_type": "price_change"}}
{"_local_timestamp": "2026-01-25T23:38:58.306981+00:00", "data": {"market": "0x690d504367efdec61936e7dc1c572c1598281f3e91d30d3b6148f3f1f48642d5", "price_changes": [{"asset_id": "51469050125334342675041532938035006268212349126791674076934139732091152113995", "price": "0.18", "size": "0", "side": "BUY", "hash": "1b9534941cc4a329a190008f080af5e22bde9f42", "best_bid": "0.67", "best_ask": "0.68"}, {"asset_id": "36538842701383075131399258783814730353525125143988435459349182813934073807848", "price": "0.82", "size": "0", "side": "SELL", "hash": "b4db7fc456e51d9efa5710a87616d91d82a58971", "best_bid": "0.32", "best_ask": "0.33"}], "timestamp": "1769384338207", "event_type": "price_change"}}
{"_local_timestamp": "2026-01-25T23:38:58.782308+00:00", "data": {"market": "0x690d504367efdec61936e7dc1c572c1598281f3e91d30d3b6148f3f1f48642d5", "price_changes": [{"asset_id": "51469050125334342675041532938035006268212349126791674076934139732091152113995", "price": "0.2", "size": "105.63", "side": "BUY", "hash": "31fa7540b0f9f846f4c08c1f52297ef920a69e0b", "best_bid": "0.67", "best_ask": "0.68"}, {"asset_id": "36538842701383075131399258783814730353525125143988435459349182813934073807848", "price": "0.8", "size": "105.63", "side": "SELL", "hash": "e9169f69befa05c4e5b46e65dccda3141e837abf", "best_bid": "0.32", "best_ask": "0.33"}], "timestamp": "1769384338636", "event_type": "price_change"}}
{"_local_timestamp": "2026-01-25T23:39:01.526645+00:00", "data": {"market": "0xd33b405694c28eb7ea092d5146085fe9234fffa467b4449b068a11f4762aa527", "price_changes": [{"asset_id": "100610158895422953936472708271328576009207076613232354004933524717835418544370", "price": "0.004", "size": "0", "side": "BUY", "hash": "2dc9077c75e122d2055fd676927a3389ab52209d", "best_bid": "0.999", "best_ask": "1"}, {"asset_id": "40582400653155619328075956469552500170030522046193955547557477713370279563057", "price": "0.996", "size": "0", "side": "SELL", "hash": "945093c7f50f08df77d629bc24c1eb82e8dd834e", "best_bid": "0", "best_ask": "0.001"}], "timestamp": "1769384341419", "event_type": "price_change"}}
{"_local_timestamp": "2026-01-25T23:39:01.527697+00:00", "data": {"market": "0xd33b405694c28eb7ea092d5146085fe9234fffa467b4449b068a11f4762aa527", "price_changes": [{"asset_id": "100610158895422953936472708271328576009207076613232354004933524717835418544370", "price": "0.061", "size": "0", "side": "BUY", "hash": "2dc9077c75e122d2055fd676927a3389ab52209d", "best_bid": "0.999", "best_ask": "1"}, {"asset_id": "40582400653155619328075956469552500170030522046193955547557477713370279563057", "price": "0.939", "size": "0", "side": "SELL", "hash": "945093c7f50f08df77d629bc24c1eb82e8dd834e", "best_bid": "0", "best_ask": "0.001"}], "timestamp": "1769384341419", "event_type": "price_change"}}
{"_local_timestamp": "2026-01-25T23:39:01.528209+00:00", "data": {"market": "0xd33b405694c28eb7ea092d5146085fe9234fffa467b4449b068a11f4762aa527", "price_changes": [{"asset_id": "100610158895422953936472708271328576009207076613232354004933524717835418544370", "price": "0.002", "size": "0", "side": "BUY", "hash": "2dc9077c75e122d2055fd676927a3389ab52209d", "best_bid": "0.999", "best_ask": "1"}, {"asset_id": "40582400653155619328075956469552500170030522046193955547557477713370279563057", "price": "0.998", "size": "0", "side": "SELL", "hash": "945093c7f50f08df77d629bc24c1eb82e8dd834e", "best_bid": "0", "best_ask": "0.001"}], "timestamp": "1769384341419", "event_type": "price_change"}}
{"_local_timestamp": "2026-01-25T23:39:01.528693+00:00", "data": {"market": "0xd33b405694c28eb7ea092d5146085fe9234fffa467b4449b068a11f4762aa527", "price_changes": [{"asset_id": "100610158895422953936472708271328576009207076613232354004933524717835418544370", "price": "0.021", "size": "0", "side": "BUY", "hash": "2dc9077c75e122d2055fd676927a3389ab52209d", "best_bid": "0.999", "best_ask": "1"}, {"asset_id": "40582400653155619328075956469552500170030522046193955547557477713370279563057", "price": "0.979", "size": "0", "side": "SELL", "hash": "945093c7f50f08df77d629bc24c1eb82e8dd834e", "best_bid": "0", "best_ask": "0.001"}], "timestamp": "1769384341419", "event_type": "price_change"}}
{"_local_timestamp": "2026-01-25T23:39:01.531124+00:00", "data": {"market": "0xd33b405694c28eb7ea092d5146085fe9234fffa467b4449b068a11f4762aa527", "price_changes": [{"asset_id": "100610158895422953936472708271328576009207076613232354004933524717835418544370", "price": "0.001", "size": "2010", "side": "BUY", "hash": "2dc9077c75e122d2055fd676927a3389ab52209d", "best_bid": "0.999", "best_ask": "1"}, {"asset_id": "40582400653155619328075956469552500170030522046193955547557477713370279563057", "price": "0.999", "size": "2010", "side": "SELL", "hash": "945093c7f50f08df77d629bc24c1eb82e8dd834e", "best_bid": "0", "best_ask": "0.001"}], "timestamp": "1769384341419", "event_type": "price_change"}}
{"_local_timestamp": "2026-01-25T23:39:01.532102+00:00", "data": {"market": "0xd33b405694c28eb7ea092d5146085fe9234fffa467b4449b068a11f4762aa527", "price_changes": [{"asset_id": "100610158895422953936472708271328576009207076613232354004933524717835418544370", "price": "0.201", "size": "0", "side": "BUY", "hash": "2dc9077c75e122d2055fd676927a3389ab52209d", "best_bid": "0.999", "best_ask": "1"}, {"asset_id": "40582400653155619328075956469552500170030522046193955547557477713370279563057", "price": "0.799", "size": "0", "side": "SELL", "hash": "945093c7f50f08df77d629bc24c1eb82e8dd834e", "best_bid": "0", "best_ask": "0.001"}], "timestamp": "1769384341419", "event_type": "price_change"}}
{"_local_timestamp": "2026-01-25T23:39:01.532921+00:00", "data": {"market": "0xd33b405694c28eb7ea092d5146085fe9234fffa467b4449b068a11f4762aa527", "price_changes": [{"asset_id": "100610158895422953936472708271328576009207076613232354004933524717835418544370", "price": "0.011", "size": "0", "side": "BUY", "hash": "2dc9077c75e122d2055fd676927a3389ab52209d", "best_bid": "0.999", "best_ask": "1"}, {"asset_id": "40582400653155619328075956469552500170030522046193955547557477713370279563057", "price": "0.989", "size": "0", "side": "SELL", "hash": "945093c7f50f08df77d629bc24c1eb82e8dd834e", "best_bid": "0", "best_ask": "0.001"}], "timestamp": "1769384341419", "event_type": "price_change"}}
{"_local_timestamp": "2026-01-25T23:39:01.541569+00:00", "data": {"market": "0x3bb5ceb45e186de77b1faaf56abf427c8c6f1a88532e4a0dc0ad9c1ffdac2a39", "price_changes": [{"asset_id": "107080924640291332768695532594456654301362852895742708190436320623455634988224", "price": "0.022", "size": "0", "side": "BUY", "hash": "121c4d984ec3ad6e6946b850d759064425283548", "best_bid": "0.999", "best_ask": "1"}, {"asset_id": "77481318171335047328591651032911896763491342646014093639934301019258606619150", "price": "0.978", "size": "0", "side": "SELL", "hash": "2788c19171bd50c412a29c7ff3db2d9b6ae0a80e", "best_bid": "0", "best_ask": "0.001"}], "timestamp": "1769384341419", "event_type": "price_change"}}
{"_local_timestamp": "2026-01-25T23:39:01.542376+00:00", "data": {"market": "0x3bb5ceb45e186de77b1faaf56abf427c8c6f1a88532e4a0dc0ad9c1ffdac2a39", "price_changes": [{"asset_id": "107080924640291332768695532594456654301362852895742708190436320623455634988224", "price": "0.011", "size": "0", "side": "BUY", "hash": "121c4d984ec3ad6e6946b850d759064425283548", "best_bid": "0.999", "best_ask": "1"}, {"asset_id": "77481318171335047328591651032911896763491342646014093639934301019258606619150", "price": "0.989", "size": "0", "side": "SELL", "hash": "2788c19171bd50c412a29c7ff3db2d9b6ae0a80e", "best_bid": "0", "best_ask": "0.001"}], "timestamp": "1769384341419", "event_type": "price_change"}}
{"_local_timestamp": "2026-01-25T23:39:01.542883+00:00", "data": {"market": "0x3bb5ceb45e186de77b1faaf56abf427c8c6f1a88532e4a0dc0ad9c1ffdac2a39", "price_changes": [{"asset_id": "107080924640291332768695532594456654301362852895742708190436320623455634988224", "price": "0.061", "size": "0", "side": "BUY", "hash": "121c4d984ec3ad6e6946b850d759064425283548", "best_bid": "0.999", "best_ask": "1"}, {"asset_id": "77481318171335047328591651032911896763491342646014093639934301019258606619150", "price": "0.939", "size": "0", "side": "SELL", "hash": "2788c19171bd50c412a29c7ff3db2d9b6ae0a80e", "best_bid": "0", "best_ask": "0.001"}], "timestamp": "1769384341419", "event_type": "price_change"}}
{"_local_timestamp": "2026-01-25T23:39:01.543384+00:00", "data": {"market": "0x3bb5ceb45e186de77b1faaf56abf427c8c6f1a88532e4a0dc0ad9c1ffdac2a39", "price_changes": [{"asset_id": "107080924640291332768695532594456654301362852895742708190436320623455634988224", "price": "0.002", "size": "0", "side": "BUY", "hash": "121c4d984ec3ad6e6946b850d759064425283548", "best_bid": "0.999", "best_ask": "1"}, {"asset_id": "77481318171335047328591651032911896763491342646014093639934301019258606619150", "price": "0.998", "size": "0", "side": "SELL", "hash": "2788c19171bd50c412a29c7ff3db2d9b6ae0a80e", "best_bid": "0", "best_ask": "0.001"}], "timestamp": "1769384341419", "event_type": "price_change"}}
{"_local_timestamp": "2026-01-25T23:39:01.543870+00:00", "data": {"market": "0x3bb5ceb45e186de77b1faaf56abf427c8c6f1a88532e4a0dc0ad9c1ffdac2a39", "price_changes": [{"asset_id": "107080924640291332768695532594456654301362852895742708190436320623455634988224", "price": "0.201", "size": "0", "side": "BUY", "hash": "121c4d984ec3ad6e6946b850d759064425283548", "best_bid": "0.999", "best_ask": "1"}, {"asset_id": "77481318171335047328591651032911896763491342646014093639934301019258606619150", "price": "0.799", "size": "0", "side": "SELL", "hash": "2788c19171bd50c412a29c7ff3db2d9b6ae0a80e", "best_bid": "0", "best_ask": "0.001"}], "timestamp": "1769384341419", "event_type": "price_change"}}
{"_local_timestamp": "2026-01-25T23:39:01.544363+00:00", "data": {"market": "0x3bb5ceb45e186de77b1faaf56abf427c8c6f1a88532e4a0dc0ad9c1ffdac2a39", "price_changes": [{"asset_id": "107080924640291332768695532594456654301362852895742708190436320623455634988224", "price": "0.004", "size": "0", "side": "BUY", "hash": "121c4d984ec3ad6e6946b850d759064425283548", "best_bid": "0.999", "best_ask": "1"}, {"asset_id": "77481318171335047328591651032911896763491342646014093639934301019258606619150", "price": "0.996", "size": "0", "side": "SELL", "hash": "2788c19171bd50c412a29c7ff3db2d9b6ae0a80e", "best_bid": "0", "best_ask": "0.001"}], "timestamp": "1769384341419", "event_type": "price_change"}}
{"_local_timestamp": "2026-01-25T23:39:01.544869+00:00", "data": {"market": "0x3bb5ceb45e186de77b1faaf56abf427c8c6f1a88532e4a0dc0ad9c1ffdac2a39", "price_changes": [{"asset_id": "107080924640291332768695532594456654301362852895742708190436320623455634988224", "price": "0.001", "size": "2010", "side": "BUY", "hash": "121c4d984ec3ad6e6946b850d759064425283548", "best_bid": "0.999", "best_ask": "1"}, {"asset_id": "77481318171335047328591651032911896763491342646014093639934301019258606619150", "price": "0.999", "size": "2010", "side": "SELL", "hash": "2788c19171bd50c412a29c7ff3db2d9b6ae0a80e", "best_bid": "0", "best_ask": "0.001"}], "timestamp": "1769384341419", "event_type": "price_change"}}
{"_local_timestamp": "2026-01-25T23:39:15.089082+00:00", "data": {"market": "0x690d504367efdec61936e7dc1c572c1598281f3e91d30d3b6148f3f1f48642d5", "price_changes": [{"asset_id": "36538842701383075131399258783814730353525125143988435459349182813934073807848", "price": "0.34", "size": "540.05", "side": "SELL", "hash": "ae7c77293fd7ff3dcf8393c7f2eb00f664fb85ef", "best_bid": "0.32", "best_ask": "0.33"}, {"asset_id": "51469050125334342675041532938035006268212349126791674076934139732091152113995", "price": "0.66", "size": "540.05", "side": "BUY", "hash": "622d6a6ac1b6f632b05bcd7f70a168c9fbb4ec34", "best_bid": "0.67", "best_ask": "0.68"}], "timestamp": "1769384355000", "event_type": "price_change"}}
{"_local_timestamp": "2026-01-25T23:39:15.103323+00:00", "data": {"market": "0x807a5bd3d52942c2d8b58bf71a583d4aa03a637f3fd9ff7a7c4a1ad818003067", "price_changes": [{"asset_id": "69732267236340588035067724177359769962979053624149789047101950615640324836190", "price": "0.37", "size": "250", "side": "SELL", "hash": "b2ba5c2012b670e7243f4700a320ae48a9cfb929", "best_bid": "0.34", "best_ask": "0.36"}, {"asset_id": "51273396751548994017117054764897754414228591289652072971120018616721173971444", "price": "0.63", "size": "250", "side": "BUY", "hash": "83655d415704a341ba126d15d0910922839a7534", "best_bid": "0.64", "best_ask": "0.66"}], "timestamp": "1769384355001", "event_type": "price_change"}}
{"_local_timestamp": "2026-01-25T23:39:20.439543+00:00", "data": {"market": "0x807a5bd3d52942c2d8b58bf71a583d4aa03a637f3fd9ff7a7c4a1ad818003067", "price_changes": [{"asset_id": "51273396751548994017117054764897754414228591289652072971120018616721173971444", "price": "0.19", "size": "450", "side": "BUY", "hash": "1c301339e353bf1c2880f705a4a19052dd6ec4ca", "best_bid": "0.64", "best_ask": "0.66"}, {"asset_id": "69732267236340588035067724177359769962979053624149789047101950615640324836190", "price": "0.81", "size": "450", "side": "SELL", "hash": "8dcb05f4b7e734269f5befc10812b75bbb43a9ee", "best_bid": "0.34", "best_ask": "0.36"}], "timestamp": "1769384360332", "event_type": "price_change"}}
{"_local_timestamp": "2026-01-25T23:39:20.486840+00:00", "data": {"market": "0x690d504367efdec61936e7dc1c572c1598281f3e91d30d3b6148f3f1f48642d5", "price_changes": [{"asset_id": "51469050125334342675041532938035006268212349126791674076934139732091152113995", "price": "0.19", "size": "0", "side": "BUY", "hash": "1a5fd07fb8e872690633d6a831c37fd67c7c922f", "best_bid": "0.67", "best_ask": "0.68"}, {"asset_id": "36538842701383075131399258783814730353525125143988435459349182813934073807848", "price": "0.81", "size": "0", "side": "SELL", "hash": "7ba12e05264da2278e329d473837c8e495f5701b", "best_bid": "0.32", "best_ask": "0.33"}], "timestamp": "1769384360333", "event_type": "price_change"}}
{"_local_timestamp": "2026-01-25T23:39:22.576418+00:00", "data": {"market": "0x690d504367efdec61936e7dc1c572c1598281f3e91d30d3b6148f3f1f48642d5", "price_changes": [{"asset_id": "51469050125334342675041532938035006268212349126791674076934139732091152113995", "price": "0.17", "size": "1304.7", "side": "BUY", "hash": "21fdf9f9cbd68a80ad6120be9f3416ad403913b3", "best_bid": "0.67", "best_ask": "0.68"}, {"asset_id": "36538842701383075131399258783814730353525125143988435459349182813934073807848", "price": "0.83", "size": "1304.7", "side": "SELL", "hash": "52c07a26041cc530d486cd141cc524073be3b93a", "best_bid": "0.32", "best_ask": "0.33"}], "timestamp": "1769384362220", "event_type": "price_change"}}
{"_local_timestamp": "2026-01-25T23:39:22.977333+00:00", "data": {"market": "0x690d504367efdec61936e7dc1c572c1598281f3e91d30d3b6148f3f1f48642d5", "price_changes": [{"asset_id": "51469050125334342675041532938035006268212349126791674076934139732091152113995", "price": "0.2", "size": "255.63", "side": "BUY", "hash": "48184db69d79732c0fa45a6c67ff09d2b11c58db", "best_bid": "0.67", "best_ask": "0.68"}, {"asset_id": "36538842701383075131399258783814730353525125143988435459349182813934073807848", "price": "0.8", "size": "255.63", "side": "SELL", "hash": "c932ff0c303ed1fe60375aef93ba10ebe92ae229", "best_bid": "0.32", "best_ask": "0.33"}], "timestamp": "1769384362742", "event_type": "price_change"}}
{"_local_timestamp": "2026-01-25T23:39:56.407626+00:00", "data": {"market": "0x807a5bd3d52942c2d8b58bf71a583d4aa03a637f3fd9ff7a7c4a1ad818003067", "price_changes": [{"asset_id": "51273396751548994017117054764897754414228591289652072971120018616721173971444", "price": "0.19", "size": "300", "side": "BUY", "hash": "1c636ef88edd118de98b664a6373b40403144454", "best_bid": "0.64", "best_ask": "0.66"}, {"asset_id": "69732267236340588035067724177359769962979053624149789047101950615640324836190", "price": "0.81", "size": "300", "side": "SELL", "hash": "615706b015e15ea3f14ea0912a4d180c9d0d8aef", "best_bid": "0.34", "best_ask": "0.36"}], "timestamp": "1769384396328", "event_type": "price_change"}}
{"_local_timestamp": "2026-01-25T23:39:56.711310+00:00", "data": {"market": "0x807a5bd3d52942c2d8b58bf71a583d4aa03a637f3fd9ff7a7c4a1ad818003067", "price_changes": [{"asset_id": "51273396751548994017117054764897754414228591289652072971120018616721173971444", "price": "0.16", "size": "1150", "side": "BUY", "hash": "0219a12b1bf422e343cc1be7ce1ca59c038646cc", "best_bid": "0.64", "best_ask": "0.66"}, {"asset_id": "69732267236340588035067724177359769962979053624149789047101950615640324836190", "price": "0.84", "size": "1150", "side": "SELL", "hash": "6e901f37ce772a6b56af6d5f46b7ec45546f4387", "best_bid": "0.34", "best_ask": "0.36"}], "timestamp": "1769384396604", "event_type": "price_change"}}
{"_local_timestamp": "2026-01-25T23:40:03.662368+00:00", "data": {"market": "0x690d504367efdec61936e7dc1c572c1598281f3e91d30d3b6148f3f1f48642d5", "price_changes": [{"asset_id": "51469050125334342675041532938035006268212349126791674076934139732091152113995", "price": "0.21", "size": "2271.8", "side": "BUY", "hash": "03ead122f3ca57f6c8360041a8bed21821d07aab", "best_bid": "0.67", "best_ask": "0.68"}, {"asset_id": "36538842701383075131399258783814730353525125143988435459349182813934073807848", "price": "0.79", "size": "2271.8", "side": "SELL", "hash": "4ed7084d2762e43f70c04ad1863a3f76fa1d87a7", "best_bid": "0.32", "best_ask": "0.33"}], "timestamp": "1769384403593", "event_type": "price_change"}}
{"_local_timestamp": "2026-01-25T23:40:04.084782+00:00", "data": {"market": "0x807a5bd3d52942c2d8b58bf71a583d4aa03a637f3fd9ff7a7c4a1ad818003067", "price_changes": [{"asset_id": "51273396751548994017117054764897754414228591289652072971120018616721173971444", "price": "0.19", "size": "250", "side": "BUY", "hash": "9bdbeea420ef4d28a4b299b6d7ae84c3be692959", "best_bid": "0.64", "best_ask": "0.66"}, {"asset_id": "69732267236340588035067724177359769962979053624149789047101950615640324836190", "price": "0.81", "size": "250", "side": "SELL", "hash": "9e0aeb6916795155759ac022a5eb19daf9039b1a", "best_bid": "0.34", "best_ask": "0.36"}], "timestamp": "1769384403995", "event_type": "price_change"}}
{"_local_timestamp": "2026-01-25T23:40:04.372495+00:00", "data": {"market": "0x807a5bd3d52942c2d8b58bf71a583d4aa03a637f3fd9ff7a7c4a1ad818003067", "price_changes": [{"asset_id": "51273396751548994017117054764897754414228591289652072971120018616721173971444", "price": "0.16", "size": "1200", "side": "BUY", "hash": "c13f4d5415c4ada7ce1fb76c103e1d31db3b5928", "best_bid": "0.64", "best_ask": "0.66"}, {"asset_id": "69732267236340588035067724177359769962979053624149789047101950615640324836190", "price": "0.84", "size": "1200", "side": "SELL", "hash": "1e151fecd2aac0ad07a69acfd33d5ead8a76e495", "best_bid": "0.34", "best_ask": "0.36"}], "timestamp": "1769384404296", "event_type": "price_change"}}
{"_local_timestamp": "2026-01-25T23:40:07.386740+00:00", "data": {"market": "0x807a5bd3d52942c2d8b58bf71a583d4aa03a637f3fd9ff7a7c4a1ad818003067", "price_changes": [{"asset_id": "51273396751548994017117054764897754414228591289652072971120018616721173971444", "price": "0.18", "size": "2332", "side": "BUY", "hash": "6f70416f3f68e091efbce01dfcbb010394986ac9", "best_bid": "0.64", "best_ask": "0.66"}, {"asset_id": "69732267236340588035067724177359769962979053624149789047101950615640324836190", "price": "0.82", "size": "2332", "side": "SELL", "hash": "8acf452bb14e0ac016cc257af65f430a32168996", "best_bid": "0.34", "best_ask": "0.36"}], "timestamp": "1769384407312", "event_type": "price_change"}}
