{"_local_timestamp": "2026-01-25T23:34:00.062295+00:00", "data": [{"market": "0xbb676d25a7ce355a3a10fa2bfbee5cb7b6b2ee36581ada7914d73ad78bedf62d", "asset_id": "10980869689964921227047480431023635246637317983901031741233635278193625249458", "timestamp": "1769383921989", "hash": "9c7747c0d097e8579ae879b0cf90e323d4bea090", "bids": [{"price": "0.01", "size": "3600"}, {"price": "0.02", "size": "800"}, {"price": "0.05", "size": "930"}, {"price": "0.09", "size": "900"}, {"price": "0.14", "size": "567.85"}, {"price": "0.19", "size": "418.42"}, {"price": "0.24", "size": "116.66"}, {"price": "0.25", "size": "400"}, {"price": "0.29", "size": "148.65"}, {"price": "0.33", "size": "97.72"}, {"price": "0.38", "size": "292.63"}, {"price": "0.39", "size": "5"}, {"price": "0.4", "size": "10"}, {"price": "0.66", "size": "45"}, {"price": "0.67", "size": "20"}, {"price": "0.68", "size": "70"}, {"price": "0.9", "size": "200"}, {"price": "0.91", "size": "934.99"}, {"price": "0.92", "size": "307.5"}], "asks": [{"price": "0.99", "size": "30"}, {"price": "0.97", "size": "50"}, {"price": "0.96", "size": "1220"}, {"price": "0.95", "size": "674.44"}, {"price": "0.94", "size": "97.5"}], "event_type": "book", "last_trade_price": "0.060"}, {"market": "0xd8aa928c90a14d70ede48f27543293c03ef8305420105518c3349f993e8fb4b4", "asset_id": "35918899905695997492070645194236546618834009355694722884958363910402437678512", "timestamp": "1769384020554", "hash": "a5bf85b3efcd785e1d30ec852819e7908abebcdd", "bids": [{"price": "0.001", "size": "5015.99"}, {"price": "0.002", "size": "250"}, {"price": "0.01", "size": "3600"}, {"price": "0.02", "size": "800"}, {"price": "0.05", "size": "930"}, {"price": "0.1", "size": "800"}, {"price": "0.111", "size": "425"}, {"price": "0.16", "size": "250"}, {"price": "0.261", "size": "7"}, {"price": "0.264", "size": "100"}, {"price": "0.265", "size": "814"}, {"price": "0.266", "size": "20"}, {"price": "0.708", "size": "40"}, {"price": "0.709", "size": "30"}, {"price": "0.71", "size": "10"}, {"price": "0.95", "size": "1000"}, {"price": "0.959", "size": "1000"}, {"price": "0.96", "size": "5"}, {"price": "0.961", "size": "1000"}, {"price": "0.967", "size": "400"}, {"price": "0.968", "size": "323.62"}, {"price": "0.969", "size": "80"}, {"price": "0.97", "size": "15.56"}, {"price": "0.971", "size": "9.44"}], "asks": [{"price": "0.999", "size": "16569.99"}, {"price": "0.994", "size": "1403.75"}, {"price": "0.992", "size": "250"}, {"price": "0.99", "size": "5"}, {"price": "0.98", "size": "1116"}, {"price": "0.978", "size": "999.44"}], "event_type": "book", "last_trade_price": "0.978"}, {"market": "0x7ec88c27625388fe4de5c1e083da56806973aae7257bd0b3b2c2790937c89433", "asset_id": "11439216096927556294398061349600841087621436733892133369767994197102929396058", "timestamp": "1769384020600", "hash": "da0a0a086a31927a61d3b430fd76dd4f421fe22b", "bids": [{"price": "0.01", "size": "3900"}, {"price": "0.02", "size": "800"}, {"price": "0.05", "size": "930"}, {"price": "0.1", "size": "300"}, {"price": "0.15", "size": "1091.66"}, {"price": "0.16", "size": "100"}, {"price": "0.22", "size": "118"}, {"price": "0.27", "size": "74.66"}, {"price": "0.28", "size": "7"}, {"price": "0.3", "size": "10"}, {"price": "0.32", "size": "312"}, {"price": "0.51", "size": "111.27"}, {"price": "0.52", "size": "40"}, {"price": "0.53", "size": "54.52"}, {"price": "0.55", "size": "38.5"}], "asks": [{"price": "0.99", "size": "55"}, {"price": "0.98", "size": "5"}, {"price": "0.97", "size": "5"}, {"price": "0.91", "size": "250"}, {"price": "0.9", "size": "200"}, {"price": "0.88", "size": "108.33"}, {"price": "0.87", "size": "54"}, {"price": "0.86", "size": "78.57"}, {"price": "0.79", "size": "100"}], "event_type": "book", "last_trade_price": "0.740"}, {"market": "0x451f95b559f965cb15fae084ca33138c3dff9900e1ffcfa4f26d8ccb973985f9", "asset_id": "38348899529497747452710765412992322349016518493953479463643011128224089778563", "timestamp": "1769383926643", "hash": "6488019aad60844408874d809347ee04f331387d", "bids": [{"price": "0.001", "size": "4242.99"}, {"price": "0.01", "size": "3600"}, {"price": "0.02", "size": "1200"}, {"price": "0.05", "size": "30"}, {"price": "0.07", "size": "1000"}, {"price": "0.111", "size": "325"}, {"price": "0.163", "size": "450"}, {"price": "0.164", "size": "255"}, {"price": "0.211", "size": "225"}, {"price": "0.49", "size": "123"}, {"price": "0.518", "size": "92"}, {"price": "0.529", "size": "10"}, {"price": "0.531", "size": "5"}, {"price": "0.532", "size": "30"}, {"price": "0.533", "size": "40"}, {"price": "0.534", "size": "20"}, {"price": "0.91", "size": "50"}, {"price": "0.932", "size": "50"}, {"price": "0.95", "size": "234"}, {"price": "0.953", "size": "170.56"}, {"price": "0.96", "size": "41.51"}], "asks": [{"price": "0.999", "size": "1242.99"}, {"price": "0.998", "size": "250"}, {"price": "0.99", "size": "5"}, {"price": "0.982", "size": "1000"}, {"price": "0.981", "size": "25"}], "event_type": "book", "last_trade_price": "0.020"}, {"market": "0x33c890cbc6edeb7ce360351a288ec411b3f9a5282667e3bf18a3051c4767428c", "asset_id": "113516997583046187201046242649428977289438194581672050007909348202973938222410", "timestamp": "1769383926644", "hash": "fc9d275ab756b08424086042d1d3c1fb79071bd6", "bids": [{"price": "0.001", "size": "3886"}, {"price": "0.01", "size": "3600"}, {"price": "0.03", "size": "1200"}, {"price": "0.05", "size": "30"}, {"price": "0.07", "size": "1000"}, {"price": "0.15", "size": "325"}, {"price": "0.185", "size": "468"}, {"price": "0.286", "size": "150"}, {"price": "0.451", "size": "100"}, {"price": "0.452", "size": "100"}, {"price": "0.454", "size": "521"}, {"price": "0.455", "size": "105"}, {"price": "0.675", "size": "10"}, {"price": "0.679", "size": "70"}, {"price": "0.68", "size": "20"}, {"price": "0.74", "size": "13.33"}, {"price": "0.91", "size": "50"}, {"price": "0.93", "size": "10.3"}, {"price": "0.95", "size": "131.77"}, {"price": "0.96", "size": "15"}], "asks": [{"price": "0.999", "size": "886"}, {"price": "0.998", "size": "250"}, {"price": "0.99", "size": "5"}], "event_type": "book", "last_trade_price": "0.020"}, {"market": "0x6d08ed1eadd870cd00c92048dda2fe06650e15905f8828ddf15e4d2186898029", "asset_id": "9876264386649584456256217467156428648140707909529649867285151715292859513583", "timestamp": "1769384020591", "hash": "e4a600a5dae39115379ce79cf952ee35498643e1", "bids": [{"price": "0.01", "size": "2600"}, {"price": "0.02", "size": "800"}, {"price": "0.05", "size": "886"}, {"price": "0.1", "size": "300"}, {"price": "0.11", "size": "238"}, {"price": "0.12", "size": "56"}, {"price": "0.16", "size": "100"}, {"price": "0.25", "size": "82"}, {"price": "0.27", "size": "7"}, {"price": "0.43", "size": "10"}, {"price": "0.45", "size": "70"}, {"price": "0.46", "size": "20"}, {"price": "0.5", "size": "13.33"}, {"price": "0.55", "size": "23.63"}, {"price": "0.56", "size": "19.64"}, {"price": "0.62", "size": "200"}, {"price": "0.63", "size": "5.55"}], "asks": [{"price": "0.99", "size": "55"}, {"price": "0.98", "size": "5"}, {"price": "0.97", "size": "5"}, {"price": "0.88", "size": "1000"}, {"price": "0.87", "size": "988.5"}, {"price": "0.86", "size": "250"}, {"price": "0.81", "size": "200"}, {"price": "0.8", "size": "65"}, {"price": "0.79", "size": "52.38"}, {"price": "0.77", "size": "151.91"}, {"price": "0.76", "size": "55"}, {"price": "0.75", "size": "36"}], "event_type": "book", "last_trade_price": "0.250"}, {"market": "0x81d603fe35c07415741bb9007bead4cdbddeb80fb35d5c9b6573eae9ee39fc1f", "asset_id": "87568880774573784875060327448344352870458352367065142953649333272451455443517", "timestamp": "1769383774946", "hash": "fed4431eed873ec289d3c6a1ea86d78899560624", "bids": [{"price": "0.01", "size": "3600"}, {"price": "0.02", "size": "800"}, {"price": "0.05", "size": "970"}, {"price": "0.06", "size": "33"}, {"price": "0.1", "size": "800"}, {"price": "0.14", "size": "1346"}, {"price": "0.2", "size": "250"}, {"price": "0.22", "size": "75"}, {"price": "0.3", "size": "253"}, {"price": "0.31", "size": "6"}, {"price": "0.43", "size": "10"}, {"price": "0.44", "size": "20"}, {"price": "0.6", "size": "70"}, {"price": "0.66", "size": "19.69"}, {"price": "0.68", "size": "16.17"}, {"price": "0.73", "size": "50"}, {"price": "0.77", "size": "50"}, {"price": "0.8", "size": "400"}, {"price": "0.81", "size": "100"}, {"price": "0.82", "size": "5"}], "asks": [{"price": "0.99", "size": "2555"}, {"price": "0.98", "size": "805"}, {"price": "0.97", "size": "255"}, {"price": "0.95", "size": "260"}, {"price": "0.94", "size": "91.66"}, {"price": "0.91", "size": "300"}, {"price": "0.88", "size": "200"}, {"price": "0.87", "size": "69"}, {"price": "0.86", "size": "19.73"}], "event_type": "book", "last_trade_price": "0.120"}, {"market": "0x2454c412d48443a73e15d93ae01e20caefd5d64a3865b67bc0a465fdac459c77", "asset_id": "21604618649648179239165697042911952381335935480672188760475095094501424754919", "timestamp": "1769384020089", "hash": "2c40b6b9c9a04c77d6e5e57f72ebb1851576a853", "bids": [{"price": "0.01", "size": "3600"}, {"price": "0.03", "size": "800"}, {"price": "0.05", "size": "970"}, {"price": "0.06", "size": "33"}, {"price": "0.1", "size": "800"}, {"price": "0.11", "size": "325"}, {"price": "0.19", "size": "1289"}, {"price": "0.25", "size": "200"}, {"price": "0.41", "size": "5"}, {"price": "0.42", "size": "215"}, {"price": "0.43", "size": "10"}, {"price": "0.65", "size": "27.23"}, {"price": "0.66", "size": "20"}, {"price": "0.67", "size": "30"}, {"price": "0.68", "size": "40"}, {"price": "0.7", "size": "13.33"}, {"price": "0.89", "size": "63.75"}, {"price": "0.9", "size": "0.55"}], "asks": [{"price": "0.99", "size": "2555"}, {"price": "0.98", "size": "255"}, {"price": "0.97", "size": "5"}, {"price": "0.96", "size": "800"}, {"price": "0.95", "size": "50"}, {"price": "0.94", "size": "24.61"}], "event_type": "book", "last_trade_price": "0.060"}, {"market": "0x2454c412d48443a73e15d93ae01e20caefd5d64a3865b67bc0a465fdac459c77", "asset_id": "46091239361932142478682480948008873970191467150785110396994502723691495289956", "timestamp": "1769384020089", "hash": "402ca21551454b077b759880d4498d536ec338c9", "bids": [{"price": "0.01", "size": "2555"}, {"price": "0.02", "size": "255"}, {"price": "0.03", "size": "5"}, {"price": "0.04", "size": "800"}, {"price": "0.05", "size": "50"}, {"price": "0.06", "size": "24.61"}], "asks": [{"price": "0.99", "size": "3600"}, {"price": "0.97", "size": "800"}, {"price": "0.95", "size": "970"}, {"price": "0.94", "size": "33"}, {"price": "0.9", "size": "800"}, {"price": "0.89", "size": "325"}, {"price": "0.81", "size": "1289"}, {"price": "0.75", "size": "200"}, {"price": "0.59", "size": "5"}, {"price": "0.58", "size": "215"}, {"price": "0.57", "size": "10"}, {"price": "0.35", "size": "27.23"}, {"price": "0.34", "size": "20"}, {"price": "0.33", "size": "30"}, {"price": "0.32", "size": "40"}, {"price": "0.3", "size": "13.33"}, {"price": "0.11", "size": "63.75"}, {"price": "0.1", "size": "0.55"}], "event_type": "book", "last_trade_price": "0.060"}, {"market": "0xbb676d25a7ce355a3a10fa2bfbee5cb7b6b2ee36581ada7914d73ad78bedf62d", "asset_id": "68913153540574314749415284055691780290306094084209478229942172031873972067947", "timestamp": "1769383921989", "hash": "513a8e44aa820200d02fed0f7b915eb9c22ec334", "bids": [{"price": "0.01", "size": "30"}, {"price": "0.03", "size": "50"}, {"price": "0.04", "size": "1220"}, {"price": "0.05", "size": "674.44"}, {"price": "0.06", "size": "97.5"}], "asks": [{"price": "0.99", "size": "3600"}, {"price": "0.98", "size": "800"}, {"price": "0.95", "size": "930"}, {"price": "0.91", "size": "900"}, {"price": "0.86", "size": "567.85"}, {"price": "0.81", "size": "418.42"}, {"price": "0.76", "size": "116.66"}, {"price": "0.75", "size": "400"}, {"price": "0.71", "size": "148.65"}, {"price": "0.67", "size": "97.72"}, {"price": "0.62", "size": "292.63"}, {"price": "0.61", "size": "5"}, {"price": "0.6", "size": "10"}, {"price": "0.34", "size": "45"}, {"price": "0.33", "size": "20"}, {"price": "0.32", "size": "70"}, {"price": "0.1", "size": "200"}, {"price": "0.09", "size": "934.99"}, {"price": "0.08", "size": "307.5"}], "event_type": "book", "last_trade_price": "0.060"}, {"market": "0xa588a3f30682fa83bbc87034e24c9c0fe328435b8abcc390c653de2a51e2f229", "asset_id": "112539243967883746727727365469595118105965156896488865205692688474764862492197", "timestamp": "1769383926644", "hash": "b7ffed593d104d6b36166de605d58c57892dfee3", "bids": [{"price": "0.001", "size": "3580.99"}, {"price": "0.002", "size": "250"}, {"price": "0.003", "size": "1166"}, {"price": "0.006", "size": "83"}, {"price": "0.01", "size": "3600"}, {"price": "0.02", "size": "1200"}, {"price": "0.05", "size": "30"}, {"price": "0.06", "size": "1000"}, {"price": "0.1", "size": "300"}, {"price": "0.112", "size": "487"}, {"price": "0.16", "size": "250"}, {"price": "0.21", "size": "150"}, {"price": "0.411", "size": "5"}, {"price": "0.427", "size": "674"}, {"price": "0.436", "size": "10"}, {"price": "0.438", "size": "40"}, {"price": "0.44", "size": "30"}, {"price": "0.441", "size": "20"}, {"price": "0.95", "size": "10"}, {"price": "0.96", "size": "1000"}, {"price": "0.963", "size": "400"}, {"price": "0.968", "size": "1000"}, {"price": "0.969", "size": "170.72"}, {"price": "0.971", "size": "57.5"}, {"price": "0.975", "size": "87.99"}, {"price": "0.976", "size": "25"}], "asks": [{"price": "0.999", "size": "8546.99"}, {"price": "0.998", "size": "400"}, {"price": "0.997", "size": "250"}, {"price": "0.99", "size": "5"}, {"price": "0.988", "size": "1000"}, {"price": "0.987", "size": "16.21"}, {"price": "0.985", "size": "500"}], "event_type": "book", "last_trade_price": "0.013"}, {"market": "0x81d603fe35c07415741bb9007bead4cdbddeb80fb35d5c9b6573eae9ee39fc1f", "asset_id": "84046462467623575651564609695680328259011367863582645244986900444709317782077", "timestamp": "1769383774946", "hash": "e4478812e6963ba52c4868bbaf1f9a2fde5a406a", "bids": [{"price": "0.01", "size": "2555"}, {"price": "0.02", "size": "805"}, {"price": "0.03", "size": "255"}, {"price": "0.05", "size": "260"}, {"price": "0.06", "size": "91.66"}, {"price": "0.09", "size": "300"}, {"price": "0.12", "size": "200"}, {"price": "0.13", "size": "69"}, {"price": "0.14", "size": "19.73"}], "asks": [{"price": "0.99", "size": "3600"}, {"price": "0.98", "size": "800"}, {"price": "0.95", "size": "970"}, {"price": "0.94", "size": "33"}, {"price": "0.9", "size": "800"}, {"price": "0.86", "size": "1346"}, {"price": "0.8", "size": "250"}, {"price": "0.78", "size": "75"}, {"price": "0.7", "size": "253"}, {"price": "0.69", "size": "6"}, {"price": "0.57", "size": "10"}, {"price": "0.56", "size": "20"}, {"price": "0.4", "size": "70"}, {"price": "0.34", "size": "19.69"}, {"price": "0.32", "size": "16.17"}, {"price": "0.27", "size": "50"}, {"price": "0.23", "size": "50"}, {"price": "0.2", "size": "400"}, {"price": "0.19", "size": "100"}, {"price": "0.18", "size": "5"}], "event_type": "book", "last_trade_price": "0.120"}, {"market": "0x6d08ed1eadd870cd00c92048dda2fe06650e15905f8828ddf15e4d2186898029", "asset_id": "16774186999359636680352173816986047997138878170738869842466593332514752926314", "timestamp": "1769384020591", "hash": "a8168c55a8c3cfbbf94682c5031ab5f09b5a89a2", "bids": [{"price": "0.01", "size": "55"}, {"price": "0.02", "size": "5"}, {"price": "0.03", "size": "5"}, {"price": "0.12", "size": "1000"}, {"price": "0.13", "size": "988.5"}, {"price": "0.14", "size": "250"}, {"price": "0.19", "size": "200"}, {"price": "0.2", "size": "65"}, {"price": "0.21", "size": "52.38"}, {"price": "0.23", "size": "151.91"}, {"price": "0.24", "size": "55"}, {"price": "0.25", "size": "36"}], "asks": [{"price": "0.99", "size": "2600"}, {"price": "0.98", "size": "800"}, {"price": "0.95", "size": "886"}, {"price": "0.9", "size": "300"}, {"price": "0.89", "size": "238"}, {"price": "0.88", "size": "56"}, {"price": "0.84", "size": "100"}, {"price": "0.75", "size": "82"}, {"price": "0.73", "size": "7"}, {"price": "0.57", "size": "10"}, {"price": "0.55", "size": "70"}, {"price": "0.54", "size": "20"}, {"price": "0.5", "size": "13.33"}, {"price": "0.45", "size": "23.63"}, {"price": "0.44", "size": "19.64"}, {"price": "0.38", "size": "200"}, {"price": "0.37", "size": "5.55"}], "event_type": "book", "last_trade_price": "0.250"}, {"market": "0xa588a3f30682fa83bbc87034e24c9c0fe328435b8abcc390c653de2a51e2f229", "asset_id": "28097057395543402943370631962731762608572280065916543916317979666329718516169", "timestamp": "1769383926644", "hash": "0378e6290a172a8bb13c5c1bbad89281f4c05f34", "bids": [{"price": "0.001", "size": "8546.99"}, {"price": "0.002", "size": "400"}, {"price": "0.003", "size": "250"}, {"price": "0.01", "size": "5"}, {"price": "0.012", "size": "1000"}, {"price": "0.013", "size": "16.21"}, {"price": "0.015", "size": "500"}], "asks": [{"price": "0.999", "size": "3580.99"}, {"price": "0.998", "size": "250"}, {"price": "0.997", "size": "1166"}, {"price": "0.994", "size": "83"}, {"price": "0.99", "size": "3600"}, {"price": "0.98", "size": "1200"}, {"price": "0.95", "size": "30"}, {"price": "0.94", "size": "1000"}, {"price": "0.9", "size": "300"}, {"price": "0.888", "size": "487"}, {"price": "0.84", "size": "250"}, {"price": "0.79", "size": "150"}, {"price": "0.589", "size": "5"}, {"price": "0.573", "size": "674"}, {"price": "0.564", "size": "10"}, {"price": "0.562", "size": "40"}, {"price": "0.56", "size": "30"}, {"price": "0.559", "size": "20"}, {"price": "0.05", "size": "10"}, {"price": "0.04", "size": "1000"}, {"price": "0.037", "size": "400"}, {"price": "0.032", "size": "1000"}, {"price": "0.031", "size": "170.72"}, {"price": "0.029", "size": "57.5"}, {"price": "0.025", "size": "87.99"}, {"price": "0.024", "size": "25"}], "event_type": "book", "last_trade_price": "0.013"}, {"market": "0xd8aa928c90a14d70ede48f27543293c03ef8305420105518c3349f993e8fb4b4", "asset_id": "9376678867812664753044653742290850239117727272721528310663723279807470231308", "timestamp": "1769384020554", "hash": "58af9f409d1518b7a84e49f3b4126e30a8923675", "bids": [{"price": "0.001", "size": "16569.99"}, {"price": "0.006", "size": "1403.75"}, {"price": "0.008", "size": "250"}, {"price": "0.01", "size": "5"}, {"price": "0.02", "size": "1116"}, {"price": "0.022", "size": "999.44"}], "asks": [{"price": "0.999", "size": "5015.99"}, {"price": "0.998", "size": "250"}, {"price": "0.99", "size": "3600"}, {"price": "0.98", "size": "800"}, {"price": "0.95", "size": "930"}, {"price": "0.9", "size": "800"}, {"price": "0.889", "size": "425"}, {"price": "0.84", "size": "250"}, {"price": "0.739", "size": "7"}, {"price": "0.736", "size": "100"}, {"price": "0.735", "size": "814"}, {"price": "0.734", "size": "20"}, {"price": "0.292", "size": "40"}, {"price": "0.291", "size": "30"}, {"price": "0.29", "size": "10"}, {"price": "0.05", "size": "1000"}, {"price": "0.041", "size": "1000"}, {"price": "0.04", "size": "5"}, {"price": "0.039", "size": "1000"}, {"price": "0.033", "size": "400"}, {"price": "0.032", "size": "323.62"}, {"price": "0.031", "size": "80"}, {"price": "0.03", "size": "15.56"}, {"price": "0.029", "size": "9.44"}], "event_type": "book", "last_trade_price": "0.978"}, {"market": "0x7ec88c27625388fe4de5c1e083da56806973aae7257bd0b3b2c2790937c89433", "asset_id": "93612868481313996119669919082030267547888020881923568220735661390829838620299", "timestamp": "1769384020600", "hash": "24b2606d3ee1deb6083cb7a2f7e5c6647e84e6fd", "bids": [{"price": "0.01", "size": "55"}, {"price": "0.02", "size": "5"}, {"price": "0.03", "size": "5"}, {"price": "0.09", "size": "250"}, {"price": "0.1", "size": "200"}, {"price": "0.12", "size": "108.33"}, {"price": "0.13", "size": "54"}, {"price": "0.14", "size": "78.57"}, {"price": "0.21", "size": "100"}], "asks": [{"price": "0.99", "size": "3900"}, {"price": "0.98", "size": "800"}, {"price": "0.95", "size": "930"}, {"price": "0.9", "size": "300"}, {"price": "0.85", "size": "1091.66"}, {"price": "0.84", "size": "100"}, {"price": "0.78", "size": "118"}, {"price": "0.73", "size": "74.66"}, {"price": "0.72", "size": "7"}, {"price": "0.7", "size": "10"}, {"price": "0.68", "size": "312"}, {"price": "0.49", "size": "111.27"}, {"price": "0.48", "size": "40"}, {"price": "0.47", "size": "54.52"}, {"price": "0.45", "size": "38.5"}], "event_type": "book", "last_trade_price": "0.740"}, {"market": "0x33c890cbc6edeb7ce360351a288ec411b3f9a5282667e3bf18a3051c4767428c", "asset_id": "51241971381574011156532505117739358478718782528207416160352857296343207110308", "timestamp": "1769383926644", "hash": "b188a312e1a3ce41c97004c1c8dfafb5945938ba", "bids": [{"price": "0.001", "size": "886"}, {"price": "0.002", "size": "250"}, {"price": "0.01", "size": "5"}], "asks": [{"price": "0.999", "size": "3886"}, {"price": "0.99", "size": "3600"}, {"price": "0.97", "size": "1200"}, {"price": "0.95", "size": "30"}, {"price": "0.93", "size": "1000"}, {"price": "0.85", "size": "325"}, {"price": "0.815", "size": "468"}, {"price": "0.714", "size": "150"}, {"price": "0.549", "size": "100"}, {"price": "0.548", "size": "100"}, {"price": "0.546", "size": "521"}, {"price": "0.545", "size": "105"}, {"price": "0.325", "size": "10"}, {"price": "0.321", "size": "70"}, {"price": "0.32", "size": "20"}, {"price": "0.26", "size": "13.33"}, {"price": "0.09", "size": "50"}, {"price": "0.07", "size": "10.3"}, {"price": "0.05", "size": "131.77"}, {"price": "0.04", "size": "15"}], "event_type": "book", "last_trade_price": "0.020"}, {"market": "0x451f95b559f965cb15fae084ca33138c3dff9900e1ffcfa4f26d8ccb973985f9", "asset_id": "71388232310046462701125421464348156348289990693959124855529169704375434690368", "timestamp": "1769383926643", "hash": "53c8112a1b93e3f3e95ea78effb1c678c7bc0926", "bids": [{"price": "0.001", "size": "1242.99"}, {"price": "0.002", "size": "250"}, {"price": "0.01", "size": "5"}, {"price": "0.018", "size": "1000"}, {"price": "0.019", "size": "25"}], "asks": [{"price": "0.999", "size": "4242.99"}, {"price": "0.99", "size": "3600"}, {"price": "0.98", "size": "1200"}, {"price": "0.95", "size": "30"}, {"price": "0.93", "size": "1000"}, {"price": "0.889", "size": "325"}, {"price": "0.837", "size": "450"}, {"price": "0.836", "size": "255"}, {"price": "0.789", "size": "225"}, {"price": "0.51", "size": "123"}, {"price": "0.482", "size": "92"}, {"price": "0.471", "size": "10"}, {"price": "0.469", "size": "5"}, {"price": "0.468", "size": "30"}, {"price": "0.467", "size": "40"}, {"price": "0.466", "size": "20"}, {"price": "0.09", "size": "50"}, {"price": "0.068", "size": "50"}, {"price": "0.05", "size": "234"}, {"price": "0.047", "size": "170.56"}, {"price": "0.04", "size": "41.51"}], "event_type": "book", "last_trade_price": "0.020"}]}
{"_local_timestamp": "2026-01-25T23:34:01.650528+00:00", "data": {"market": "0x6d08ed1eadd870cd00c92048dda2fe06650e15905f8828ddf15e4d2186898029", "price_changes": [{"asset_id": "9876264386649584456256217467156428648140707909529649867285151715292859513583", "price": "0.01", "size": "3600", "side": "BUY", "hash": "09804ea2b203bde8bd239566901ddc2896963762", "best_bid": "0.63", "best_ask": "0.75"}, {"asset_id": "16774186999359636680352173816986047997138878170738869842466593332514752926314", "price": "0.99", "size": "3600", "side": "SELL", "hash": "7a649e50c668e607b743529f8483742307ee6c51", "best_bid": "0.25", "best_ask": "0.37"}], "timestamp": "1769384041562", "event_type": "price_change"}}
{"_local_timestamp": "2026-01-25T23:34:01.654583+00:00", "data": {"market": "0x7ec88c27625388fe4de5c1e083da56806973aae7257bd0b3b2c2790937c89433", "price_changes": [{"asset_id": "11439216096927556294398061349600841087621436733892133369767994197102929396058", "price": "0.1", "size": "500", "side": "BUY", "hash": "f61936bdd4bb612aaf4ca5db4535b734694bc966", "best_bid": "0.55", "best_ask": "0.79"}, {"asset_id": "93612868481313996119669919082030267547888020881923568220735661390829838620299", "price": "0.9", "size": "500", "side": "SELL", "hash": "25b34b09a1bac1b9f3a594b78751a20308be7503", "best_bid": "0.21", "best_ask": "0.45"}], "timestamp": "1769384041562", "event_type": "price_change"}}
{"_local_timestamp": "2026-01-25T23:34:01.659816+00:00", "data": {"market": "0x6d08ed1eadd870cd00c92048dda2fe06650e15905f8828ddf15e4d2186898029", "price_changes": [{"asset_id": "9876264386649584456256217467156428648140707909529649867285151715292859513583", "price": "0.1", "size": "500", "side": "BUY", "hash": "84f5b166a5012bb932473d60442503717461fc6d", "best_bid": "0.63", "best_ask": "0.75"}, {"asset_id": "16774186999359636680352173816986047997138878170738869842466593332514752926314", "price": "0.9", "size": "500", "side": "SELL", "hash": "ceb0f84fb37cc5a6f360689bcaed31e586f94c02", "best_bid": "0.25", "best_ask": "0.37"}], "timestamp": "1769384041567", "event_type": "price_change"}}
{"_local_timestamp": "2026-01-25T23:34:01.662975+00:00", "data": {"market": "0x6d08ed1eadd870cd00c92048dda2fe06650e15905f8828ddf15e4d2186898029", "price_changes": [{"asset_id": "9876264386649584456256217467156428648140707909529649867285151715292859513583", "price": "0.05", "size": "1286", "side": "BUY", "hash": "26d6f65d861a9b69ac029700fb6173163df445ff", "best_bid": "0.63", "best_ask": "0.75"}, {"asset_id": "16774186999359636680352173816986047997138878170738869842466593332514752926314", "price": "0.95", "size": "1286", "side": "SELL", "hash": "50b08d7897e335d7ca919d91dc5f4589343ac8c2", "best_bid": "0.25", "best_ask": "0.37"}], "timestamp": "1769384041568", "event_type": "price_change"}}
{"_local_timestamp": "2026-01-25T23:34:01.722106+00:00", "data": {"market": "0x6d08ed1eadd870cd00c92048dda2fe06650e15905f8828ddf15e4d2186898029", "price_changes": [{"asset_id": "9876264386649584456256217467156428648140707909529649867285151715292859513583", "price": "0.05", "size": "930", "side": "BUY", "hash": "24860241436d4a0997203cb69a8f46dcbe70497c", "best_bid": "0.63", "best_ask": "0.75"}, {"asset_id": "16774186999359636680352173816986047997138878170738869842466593332514752926314", "price": "0.95", "size": "930", "side": "SELL", "hash": "dcf4a0040f584a62fac5514588ed0bc16597b3d0", "best_bid": "0.25", "best_ask": "0.37"}], "timestamp": "1769384041639", "event_type": "price_change"}}
{"_local_timestamp": "2026-01-25T23:34:01.891907+00:00", "data": {"market": "0x6d08ed1eadd870cd00c92048dda2fe06650e15905f8828ddf15e4d2186898029", "price_changes": [{"asset_id": "9876264386649584456256217467156428648140707909529649867285151715292859513583", "price": "0.1", "size": "783", "side": "BUY", "hash": "997593ca10893b8f37845d0c41a65c0ffe846f01", "best_bid": "0.63", "best_ask": "0.75"}, {"asset_id": "16774186999359636680352173816986047997138878170738869842466593332514752926314", "price": "0.9", "size": "783", "side": "SELL", "hash": "e14f3722bc2967c290c15a6d31e075adaef6f7fd", "best_bid": "0.25", "best_ask": "0.37"}], "timestamp": "1769384041821", "event_type": "price_change"}}
{"_local_timestamp": "2026-01-25T23:34:27.669580+00:00", "data": {"market": "0x2454c412d48443a73e15d93ae01e20caefd5d64a3865b67bc0a465fdac459c77", "price_changes": [{"asset_id": "21604618649648179239165697042911952381335935480672188760475095094501424754919", "price": "0.19", "size": "1139", "side": "BUY", "hash": "9b60a42a626e6dbbc7ea41163176dcf3a779e526", "best_bid": "0.9", "best_ask": "0.94"}, {"asset_id": "46091239361932142478682480948008873970191467150785110396994502723691495289956", "price": "0.81", "size": "1139", "side": "SELL", "hash": "5a58e84cc583ad45eb8809b2cb3ece5b91b5ce96", "best_bid": "0.06", "best_ask": "0.1"}], "timestamp": "1769384067566", "event_type": "price_change"}}
{"_local_timestamp": "2026-01-25T23:34:27.670449+00:00", "data": {"market": "0x2454c412d48443a73e15d93ae01e20caefd5d64a3865b67bc0a465fdac459c77", "price_changes": [{"asset_id": "21604618649648179239165697042911952381335935480672188760475095094501424754919", "price": "0.25", "size": "100", "side": "BUY", "hash": "9b60a42a626e6dbbc7ea41163176dcf3a779e526", "best_bid": "0.9", "best_ask": "0.94"}, {"asset_id": "46091239361932142478682480948008873970191467150785110396994502723691495289956", "price": "0.75", "size": "100", "side": "SELL", "hash": "5a58e84cc583ad45eb8809b2cb3ece5b91b5ce96", "best_bid": "0.06", "best_ask": "0.1"}], "timestamp": "1769384067566", "event_type": "price_change"}}
{"_local_timestamp": "2026-01-25T23:34:27.670747+00:00", "data": {"market": "0x2454c412d48443a73e15d93ae01e20caefd5d64a3865b67bc0a465fdac459c77", "price_changes": [{"asset_id": "21604618649648179239165697042911952381335935480672188760475095094501424754919", "price": "0.42", "size": "155", "side": "BUY", "hash": "9b60a42a626e6dbbc7ea41163176dcf3a779e526", "best_bid": "0.9", "best_ask": "0.94"}, {"asset_id": "46091239361932142478682480948008873970191467150785110396994502723691495289956", "price": "0.58", "size": "155", "side": "SELL", "hash": "5a58e84cc583ad45eb8809b2cb3ece5b91b5ce96", "best_bid": "0.06", "best_ask": "0.1"}], "timestamp": "1769384067566", "event_type": "price_change"}}
{"_local_timestamp": "2026-01-25T23:34:27.671025+00:00", "data": {"market": "0x7ec88c27625388fe4de5c1e083da56806973aae7257bd0b3b2c2790937c89433", "price_changes": [{"asset_id": "11439216096927556294398061349600841087621436733892133369767994197102929396058", "price": "0.01", "size": "3600", "side": "BUY", "hash": "446972ee111c35a8f37fda1beaa7b34a37bca25c", "best_bid": "0.55", "best_ask": "0.79"}, {"asset_id": "93612868481313996119669919082030267547888020881923568220735661390829838620299", "price": "0.99", "size": "3600", "side": "SELL", "hash": "2dbdeac51edede3d8f790d620843facdcd304ec5", "best_bid": "0.21", "best_ask": "0.45"}], "timestamp": "1769384067566", "event_type": "price_change"}}
{"_local_timestamp": "2026-01-25T23:34:27.681063+00:00", "data": {"market": "0x33c890cbc6edeb7ce360351a288ec411b3f9a5282667e3bf18a3051c4767428c", "price_changes": [{"asset_id": "113516997583046187201046242649428977289438194581672050007909348202973938222410", "price": "0.454", "size": "461", "side": "BUY", "hash": "44ee2b608e20232b21cb48fa424863c542ab6eb8", "best_bid": "0.96", "best_ask": "0.99"}, {"asset_id": "51241971381574011156532505117739358478718782528207416160352857296343207110308", "price": "0.546", "size": "461", "side": "SELL", "hash": "b175177f9d2fd51cc78cbe8173e770ae70624602", "best_bid": "0.01", "best_ask": "0.04"}], "timestamp": "1769384067566", "event_type": "price_change"}}
{"_local_timestamp": "2026-01-25T23:34:27.681501+00:00", "data": {"market": "0xd8aa928c90a14d70ede48f27543293c03ef8305420105518c3349f993e8fb4b4", "price_changes": [{"asset_id": "35918899905695997492070645194236546618834009355694722884958363910402437678512", "price": "0.264", "size": "0", "side": "BUY", "hash": "a0c55843f5035ee67bddb29373da5cc8fcd68d33", "best_bid": "0.971", "best_ask": "0.978"}, {"asset_id": "9376678867812664753044653742290850239117727272721528310663723279807470231308", "price": "0.736", "size": "0", "side": "SELL", "hash": "7a6c6e57c719f401d66980e9df47731ddbe5aa6b", "best_bid": "0.022", "best_ask": "0.029"}], "timestamp": "1769384067566", "event_type": "price_change"}}
{"_local_timestamp": "2026-01-25T23:34:27.890422+00:00", "data": {"market": "0xd8aa928c90a14d70ede48f27543293c03ef8305420105518c3349f993e8fb4b4", "price_changes": [{"asset_id": "35918899905695997492070645194236546618834009355694722884958363910402437678512", "price": "0.265", "size": "789", "side": "BUY", "hash": "35cace41b216278e820d32b23cbfa3cd542f1592", "best_bid": "0.971", "best_ask": "0.978"}, {"asset_id": "9376678867812664753044653742290850239117727272721528310663723279807470231308", "price": "0.735", "size": "789", "side": "SELL", "hash": "28315525657092a68c2b1dd3ed015ee01dfdc7c3", "best_bid": "0.022", "best_ask": "0.029"}], "timestamp": "1769384067633", "event_type": "price_change"}}
{"_local_timestamp": "2026-01-25T23:34:28.051524+00:00", "data": {"market": "0xd8aa928c90a14d70ede48f27543293c03ef8305420105518c3349f993e8fb4b4", "price_changes": [{"asset_id": "35918899905695997492070645194236546618834009355694722884958363910402437678512", "price": "0.265", "size": "820", "side": "BUY", "hash": "fac826f81f5599abe024096289f9a42d2aa9f6a9", "best_bid": "0.971", "best_ask": "0.978"}, {"asset_id": "9376678867812664753044653742290850239117727272721528310663723279807470231308", "price": "0.735", "size": "820", "side": "SELL", "hash": "1f1eaacb50350620e6a71481062491edb02db22b", "best_bid": "0.022", "best_ask": "0.029"}], "timestamp": "1769384067967", "event_type": "price_change"}}
{"_local_timestamp": "2026-01-25T23:34:28.052591+00:00", "data": {"market": "0xd8aa928c90a14d70ede48f27543293c03ef8305420105518c3349f993e8fb4b4", "price_changes": [{"asset_id": "35918899905695997492070645194236546618834009355694722884958363910402437678512", "price": "0.267", "size": "15", "side": "BUY", "hash": "6ce4d7556950c45ead75a5a929e95aa87524f342", "best_bid": "0.971", "best_ask": "0.978"}, {"asset_id": "9376678867812664753044653742290850239117727272721528310663723279807470231308", "price": "0.733", "size": "15", "side": "SELL", "hash": "1361121be7a66ee2fef6b2380a3f0656d840a728", "best_bid": "0.022", "best_ask": "0.029"}], "timestamp": "1769384067968", "event_type": "price_change"}}
{"_local_timestamp": "2026-01-25T23:34:28.055066+00:00", "data": {"market": "0xd8aa928c90a14d70ede48f27543293c03ef8305420105518c3349f993e8fb4b4", "price_changes": [{"asset_id": "35918899905695997492070645194236546618834009355694722884958363910402437678512", "price": "0.709", "size": "40", "side": "BUY", "hash": "f0747331adcb364e664c467e893b338d94b537b2", "best_bid": "0.971", "best_ask": "0.978"}, {"asset_id": "9376678867812664753044653742290850239117727272721528310663723279807470231308", "price": "0.291", "size": "40", "side": "SELL", "hash": "1cefa87456a70733e7704b50f6e3c1abe12a5c70", "best_bid": "0.022", "best_ask": "0.029"}], "timestamp": "1769384067969", "event_type": "price_change"}}
{"_local_timestamp": "2026-01-25T23:34:28.158000+00:00", "data": {"market": "0x6d08ed1eadd870cd00c92048dda2fe06650e15905f8828ddf15e4d2186898029", "price_changes": [{"asset_id": "9876264386649584456256217467156428648140707909529649867285151715292859513583", "price": "0.05", "size": "1230", "side": "BUY", "hash": "f37d9864adae417922f3aba07b550add9659c9f9", "best_bid": "0.63", "best_ask": "0.75"}, {"asset_id": "16774186999359636680352173816986047997138878170738869842466593332514752926314", "price": "0.95", "size": "1230", "side": "SELL", "hash": "5b71c51752be933c19c555489a47db127f1a829d", "best_bid": "0.25", "best_ask": "0.37"}], "timestamp": "1769384068081", "event_type": "price_change"}}
{"_local_timestamp": "2026-01-25T23:34:28.165106+00:00", "data": {"market": "0xd8aa928c90a14d70ede48f27543293c03ef8305420105518c3349f993e8fb4b4", "price_changes": [{"asset_id": "35918899905695997492070645194236546618834009355694722884958363910402437678512", "price": "0.265", "size": "920", "side": "BUY", "hash": "a2b711f0857e681fef672296cc8cba5224759fbb", "best_bid": "0.971", "best_ask": "0.978"}, {"asset_id": "9376678867812664753044653742290850239117727272721528310663723279807470231308", "price": "0.735", "size": "920", "side": "SELL", "hash": "0e34b3481bd399f50b0607fd5f0a1b7d75104187", "best_bid": "0.022", "best_ask": "0.029"}], "timestamp": "1769384068081", "event_type": "price_change"}}
{"_local_timestamp": "2026-01-25T23:34:28.286824+00:00", "data": {"market": "0x6d08ed1eadd870cd00c92048dda2fe06650e15905f8828ddf15e4d2186898029", "price_changes": [{"asset_id": "9876264386649584456256217467156428648140707909529649867285151715292859513583", "price": "0.12", "size": "256", "side": "BUY", "hash": "ad1cbaded4b61a294ef0367aa5ac66f5ce96de24", "best_bid": "0.63", "best_ask": "0.75"}, {"asset_id": "16774186999359636680352173816986047997138878170738869842466593332514752926314", "price": "0.88", "size": "256", "side": "SELL", "hash": "6f8a9ca6a3d60a82043a6bbd4c8b13a4e9c9a40d", "best_bid": "0.25", "best_ask": "0.37"}], "timestamp": "1769384068084", "event_type": "price_change"}}
{"_local_timestamp": "2026-01-25T23:34:28.302853+00:00", "data": {"market": "0x33c890cbc6edeb7ce360351a288ec411b3f9a5282667e3bf18a3051c4767428c", "price_changes": [{"asset_id": "113516997583046187201046242649428977289438194581672050007909348202973938222410", "price": "0.455", "size": "165", "side": "BUY", "hash": "b13563c229c5b4e5329ead2369ec7275a0de4d0c", "best_bid": "0.96", "best_ask": "0.99"}, {"asset_id": "51241971381574011156532505117739358478718782528207416160352857296343207110308", "price": "0.545", "size": "165", "side": "SELL", "hash": "c0b3fc26ebc6d039a5d4ea4b4481c06498663f90", "best_bid": "0.01", "best_ask": "0.04"}], "timestamp": "1769384068081", "event_type": "price_change"}}
{"_local_timestamp": "2026-01-25T23:34:28.303366+00:00", "data": {"market": "0x7ec88c27625388fe4de5c1e083da56806973aae7257bd0b3b2c2790937c89433", "price_changes": [{"asset_id": "11439216096927556294398061349600841087621436733892133369767994197102929396058", "price": "0.05", "size": "1230", "side": "BUY", "hash": "669a9a311b2284fb8b0eb666fdd7c159b5d694d1", "best_bid": "0.55", "best_ask": "0.79"}, {"asset_id": "93612868481313996119669919082030267547888020881923568220735661390829838620299", "price": "0.95", "size": "1230", "side": "SELL", "hash": "8fb269c01a380cae0ef21e0561930d8a2d036eb2", "best_bid": "0.21", "best_ask": "0.45"}], "timestamp": "1769384068082", "event_type": "price_change"}}
{"_local_timestamp": "2026-01-25T23:34:28.622064+00:00", "data": {"market": "0x6d08ed1eadd870cd00c92048dda2fe06650e15905f8828ddf15e4d2186898029", "price_changes": [{"asset_id": "9876264386649584456256217467156428648140707909529649867285151715292859513583", "price": "0.16", "size": "250", "side": "BUY", "hash": "acfa2bd8143092c395ee644dbe271e8588c41245", "best_bid": "0.63", "best_ask": "0.75"}, {"asset_id": "16774186999359636680352173816986047997138878170738869842466593332514752926314", "price": "0.84", "size": "250", "side": "SELL", "hash": "cec5b3512b321908a055e3d1ed091e0273d517cc", "best_bid": "0.25", "best_ask": "0.37"}], "timestamp": "1769384068185", "event_type": "price_change"}}
{"_local_timestamp": "2026-01-25T23:34:28.623758+00:00", "data": {"market": "0x7ec88c27625388fe4de5c1e083da56806973aae7257bd0b3b2c2790937c89433", "price_changes": [{"asset_id": "11439216096927556294398061349600841087621436733892133369767994197102929396058", "price": "0.16", "size": "250", "side": "BUY", "hash": "5d86e57702bd8a70fcb9e763dd05460322e60028", "best_bid": "0.55", "best_ask": "0.79"}, {"asset_id": "93612868481313996119669919082030267547888020881923568220735661390829838620299", "price": "0.84", "size": "250", "side": "SELL", "hash": "26ecd880a1f1bb60731aead7a3b6686c004402f3", "best_bid": "0.21", "best_ask": "0.45"}], "timestamp": "1769384068187", "event_type": "price_change"}}
{"_local_timestamp": "2026-01-25T23:34:28.800099+00:00", "data": {"market": "0x7ec88c27625388fe4de5c1e083da56806973aae7257bd0b3b2c2790937c89433", "price_changes": [{"asset_id": "11439216096927556294398061349600841087621436733892133369767994197102929396058", "price": "0.22", "size": "218", "side": "BUY", "hash": "59f2840c4b81e991e0d255c6d4f212604ff94491", "best_bid": "0.55", "best_ask": "0.79"}, {"asset_id": "93612868481313996119669919082030267547888020881923568220735661390829838620299", "price": "0.78", "size": "218", "side": "SELL", "hash": "7bbb2ced33e9813eee2e3742bd8027ebf1ba9735", "best_bid": "0.21", "best_ask": "0.45"}], "timestamp": "1769384068256", "event_type": "price_change"}}
{"_local_timestamp": "2026-01-25T23:34:28.800760+00:00", "data": {"market": "0x7ec88c27625388fe4de5c1e083da56806973aae7257bd0b3b2c2790937c89433", "price_changes": [{"asset_id": "11439216096927556294398061349600841087621436733892133369767994197102929396058", "price": "0.15", "size": "1291.66", "side": "BUY", "hash": "fa542368a52685268e2cb3113b8061a1ef131eb5", "best_bid": "0.55", "best_ask": "0.79"}, {"asset_id": "93612868481313996119669919082030267547888020881923568220735661390829838620299", "price": "0.85", "size": "1291.66", "side": "SELL", "hash": "b425bab96ad57b97a34335336209d107bcea80b4", "best_bid": "0.21", "best_ask": "0.45"}], "timestamp": "1769384068279", "event_type": "price_change"}}
{"_local_timestamp": "2026-01-25T23:34:28.802118+00:00", "data": {"market": "0x33c890cbc6edeb7ce360351a288ec411b3f9a5282667e3bf18a3051c4767428c", "price_changes": [{"asset_id": "113516997583046187201046242649428977289438194581672050007909348202973938222410", "price": "0.454", "size": "251", "side": "BUY", "hash": "4744b6ce4692fa686749b910cf2d00cb95c28764", "best_bid": "0.96", "best_ask": "0.99"}, {"asset_id": "51241971381574011156532505117739358478718782528207416160352857296343207110308", "price": "0.546", "size": "251", "side": "SELL", "hash": "0c146c2e62ebb9f285ff713332f6b0d2228ba6d1", "best_bid": "0.01", "best_ask": "0.04"}], "timestamp": "1769384068312", "event_type": "price_change"}}
{"_local_timestamp": "2026-01-25T23:34:29.060013+00:00", "data": {"market": "0x33c890cbc6edeb7ce360351a288ec411b3f9a5282667e3bf18a3051c4767428c", "price_changes": [{"asset_id": "113516997583046187201046242649428977289438194581672050007909348202973938222410", "price": "0.455", "size": "353", "side": "BUY", "hash": "e9a97b8d43272f2bff984c2d7b4635ae8e29642f", "best_bid": "0.96", "best_ask": "0.99"}, {"asset_id": "51241971381574011156532505117739358478718782528207416160352857296343207110308", "price": "0.545", "size": "353", "side": "SELL", "hash": "d274fbc45914790e1fccb0b3c827e58e5d8a9823", "best_bid": "0.01", "best_ask": "0.04"}], "timestamp": "1769384068719", "event_type": "price_change"}}
{"_local_timestamp": "2026-01-25T23:34:29.060827+00:00", "data": {"market": "0x33c890cbc6edeb7ce360351a288ec411b3f9a5282667e3bf18a3051c4767428c", "price_changes": [{"asset_id": "113516997583046187201046242649428977289438194581672050007909348202973938222410", "price": "0.681", "size": "10", "side": "BUY", "hash": "e62f5ad2678030e1479890dace1e313be7c38bf0", "best_bid": "0.96", "best_ask": "0.99"}, {"asset_id": "51241971381574011156532505117739358478718782528207416160352857296343207110308", "price": "0.319", "size": "10", "side": "SELL", "hash": "685191347381af935da5208264c668966c8c156b", "best_bid": "0.01", "best_ask": "0.04"}], "timestamp": "1769384068720", "event_type": "price_change"}}
{"_local_timestamp": "2026-01-25T23:34:29.061394+00:00", "data": {"market": "0x33c890cbc6edeb7ce360351a288ec411b3f9a5282667e3bf18a3051c4767428c", "price_changes": [{"asset_id": "113516997583046187201046242649428977289438194581672050007909348202973938222410", "price": "0.681", "size": "25", "side": "BUY", "hash": "293e557046a98b7e93c5dce001d42f539e0a4221", "best_bid": "0.96", "best_ask": "0.99"}, {"asset_id": "51241971381574011156532505117739358478718782528207416160352857296343207110308", "price": "0.319", "size": "25", "side": "SELL", "hash": "a3636939e68610181272ce148818d8ac2a2c112e", "best_bid": "0.01", "best_ask": "0.04"}], "timestamp": "1769384068720", "event_type": "price_change"}}
{"_local_timestamp": "2026-01-25T23:34:29.062408+00:00", "data": {"market": "0xd8aa928c90a14d70ede48f27543293c03ef8305420105518c3349f993e8fb4b4", "price_changes": [{"asset_id": "35918899905695997492070645194236546618834009355694722884958363910402437678512", "price": "0.266", "size": "0", "side": "BUY", "hash": "f215c6c233712bf4d040ea2a585a94d28d44aec1", "best_bid": "0.971", "best_ask": "0.978"}, {"asset_id": "9376678867812664753044653742290850239117727272721528310663723279807470231308", "price": "0.734", "size": "0", "side": "SELL", "hash": "b236357e1cb99ba6a0999476023e819c17d98c93", "best_bid": "0.022", "best_ask": "0.029"}], "timestamp": "1769384068736", "event_type": "price_change"}}
{"_local_timestamp": "2026-01-25T23:34:29.080414+00:00", "data": {"market": "0xd8aa928c90a14d70ede48f27543293c03ef8305420105518c3349f993e8fb4b4", "price_changes": [{"asset_id": "35918899905695997492070645194236546618834009355694722884958363910402437678512", "price": "0.268", "size": "20", "side": "BUY", "hash": "215a1e74ad040055eb15fa7f2913854ee56e2782", "best_bid": "0.971", "best_ask": "0.978"}, {"asset_id": "9376678867812664753044653742290850239117727272721528310663723279807470231308", "price": "0.732", "size": "20", "side": "SELL", "hash": "c2a84285957d99898b11216dd6b76ee685c8b0d9", "best_bid": "0.022", "best_ask": "0.029"}], "timestamp": "1769384068761", "event_type": "price_change"}}
{"_local_timestamp": "2026-01-25T23:34:32.406455+00:00", "data": {"market": "0x33c890cbc6edeb7ce360351a288ec411b3f9a5282667e3bf18a3051c4767428c", "price_changes": [{"asset_id": "113516997583046187201046242649428977289438194581672050007909348202973938222410", "price": "0.68", "size": "0", "side": "BUY", "hash": "cb5d3c3bd183726dbda7dee310d8eb243fa287e9", "best_bid": "0.96", "best_ask": "0.99"}, {"asset_id": "51241971381574011156532505117739358478718782528207416160352857296343207110308", "price": "0.32", "size": "0", "side": "SELL", "hash": "a6a843c9b4a80273e4640f44c276d5d14f336fce", "best_bid": "0.01", "best_ask": "0.04"}], "timestamp": "1769384072325", "event_type": "price_change"}}
{"_local_timestamp": "2026-01-25T23:34:32.450036+00:00", "data": {"market": "0x33c890cbc6edeb7ce360351a288ec411b3f9a5282667e3bf18a3051c4767428c", "price_changes": [{"asset_id": "113516997583046187201046242649428977289438194581672050007909348202973938222410", "price": "0.682", "size": "20", "side": "BUY", "hash": "aab79ff9c9b68147313482f1df9a4e4ecb52cec3", "best_bid": "0.96", "best_ask": "0.99"}, {"asset_id": "51241971381574011156532505117739358478718782528207416160352857296343207110308", "price": "0.318", "size": "20", "side": "SELL", "hash": "9f58330599fb72ae93cdcd626d540c4c1e59aa6c", "best_bid": "0.01", "best_ask": "0.04"}], "timestamp": "1769384072373", "event_type": "price_change"}}
{"_local_timestamp": "2026-01-25T23:35:00.350162+00:00", "data": {"market": "0x451f95b559f965cb15fae084ca33138c3dff9900e1ffcfa4f26d8ccb973985f9", "price_changes": [{"asset_id": "71388232310046462701125421464348156348289990693959124855529169704375434690368", "price": "0.068", "size": "0", "side": "SELL", "hash": "edb330a5f21ed4b03e5b8d8e1322f0510cf78504", "best_bid": "0.019", "best_ask": "0.04"}, {"asset_id": "38348899529497747452710765412992322349016518493953479463643011128224089778563", "price": "0.932", "size": "0", "side": "BUY", "hash": "eb20762fa02070cd2ab9705e358f21a8499b1303", "best_bid": "0.96", "best_ask": "0.981"}], "timestamp": "1769384100284", "event_type": "price_change"}}
{"_local_timestamp": "2026-01-25T23:35:00.373982+00:00", "data": {"market": "0x451f95b559f965cb15fae084ca33138c3dff9900e1ffcfa4f26d8ccb973985f9", "price_changes": [{"asset_id": "71388232310046462701125421464348156348289990693959124855529169704375434690368", "price": "0.068", "size": "50", "side": "SELL", "hash": "4d6344fd2d9722645f7c7089d776868aa86f78bd", "best_bid": "0.019", "best_ask": "0.04"}, {"asset_id": "38348899529497747452710765412992322349016518493953479463643011128224089778563", "price": "0.932", "size": "50", "side": "BUY", "hash": "fc379a4d9da4091dbf4ca5ff748daec80fc03fe8", "best_bid": "0.96", "best_ask": "0.981"}], "timestamp": "1769384100308", "event_type": "price_change"}}
{"_local_timestamp": "2026-01-25T23:35:31.329194+00:00", "data": {"market": "0x81d603fe35c07415741bb9007bead4cdbddeb80fb35d5c9b6573eae9ee39fc1f", "price_changes": [{"asset_id": "84046462467623575651564609695680328259011367863582645244986900444709317782077", "price": "0.13", "size": "0", "side": "BUY", "hash": "2b561a0c12616359f6bde94bba91f43d1b5ced26", "best_bid": "0.14", "best_ask": "0.18"}, {"asset_id": "87568880774573784875060327448344352870458352367065142953649333272451455443517", "price": "0.87", "size": "0", "side": "SELL", "hash": "b1a0083cf2846de5a0960a7e35a4e1fc73152785", "best_bid": "0.82", "best_ask": "0.86"}], "timestamp": "1769384131242", "event_type": "price_change"}}
{"_local_timestamp": "2026-01-25T23:35:31.540289+00:00", "data": {"market": "0x7ec88c27625388fe4de5c1e083da56806973aae7257bd0b3b2c2790937c89433", "price_changes": [{"asset_id": "11439216096927556294398061349600841087621436733892133369767994197102929396058", "price": "0.53", "size": "24.52", "side": "BUY", "hash": "0c7a0009ccc842963cc09e60f4b7f060323abc70", "best_bid": "0.55", "best_ask": "0.79"}, {"asset_id": "93612868481313996119669919082030267547888020881923568220735661390829838620299", "price": "0.47", "size": "24.52", "side": "SELL", "hash": "5feeb054f20105d8bcfe3e8e157abc1ec38e0d59", "best_bid": "0.21", "best_ask": "0.45"}], "timestamp": "1769384131427", "event_type": "price_change"}}
{"_local_timestamp": "2026-01-25T23:35:31.570355+00:00", "data": {"market": "0x7ec88c27625388fe4de5c1e083da56806973aae7257bd0b3b2c2790937c89433", "price_changes": [{"asset_id": "11439216096927556294398061349600841087621436733892133369767994197102929396058", "price": "0.52", "size": "0", "side": "BUY", "hash": "7ce2487b8cee2af546fefc184e70020f15711fb9", "best_bid": "0.55", "best_ask": "0.79"}, {"asset_id": "93612868481313996119669919082030267547888020881923568220735661390829838620299", "price": "0.48", "size": "0", "side": "SELL", "hash": "617ff20a760b6bc4251b7fab575bd3e4623899cf", "best_bid": "0.21", "best_ask": "0.45"}], "timestamp": "1769384131453", "event_type": "price_change"}}
{"_local_timestamp": "2026-01-25T23:35:31.570808+00:00", "data": {"market": "0xbb676d25a7ce355a3a10fa2bfbee5cb7b6b2ee36581ada7914d73ad78bedf62d", "price_changes": [{"asset_id": "10980869689964921227047480431023635246637317983901031741233635278193625249458", "price": "0.68", "size": "30", "side": "BUY", "hash": "f57e9bfc10fd370bde1aa203135dec4d69428359", "best_bid": "0.92", "best_ask": "0.94"}, {"asset_id": "68913153540574314749415284055691780290306094084209478229942172031873972067947", "price": "0.32", "size": "30", "side": "SELL", "hash": "4ca89f0ffc11f710b57d91fff70bea2b0921d39f", "best_bid": "0.06", "best_ask": "0.08"}], "timestamp": "1769384131453", "event_type": "price_change"}}
{"_local_timestamp": "2026-01-25T23:35:31.684152+00:00", "data": {"market": "0x7ec88c27625388fe4de5c1e083da56806973aae7257bd0b3b2c2790937c89433", "price_changes": [{"asset_id": "11439216096927556294398061349600841087621436733892133369767994197102929396058", "price": "0.52", "size": "30", "side": "BUY", "hash": "1b6729882749c192df171e022839b947f13e9679", "best_bid": "0.55", "best_ask": "0.79"}, {"asset_id": "93612868481313996119669919082030267547888020881923568220735661390829838620299", "price": "0.48", "size": "30", "side": "SELL", "hash": "f293e65aaffa325af821e2aed8c83aed2f9454a0", "best_bid": "0.21", "best_ask": "0.45"}], "timestamp": "1769384131603", "event_type": "price_change"}}
{"_local_timestamp": "2026-01-25T23:35:31.728563+00:00", "data": {"market": "0x7ec88c27625388fe4de5c1e083da56806973aae7257bd0b3b2c2790937c89433", "price_changes": [{"asset_id": "11439216096927556294398061349600841087621436733892133369767994197102929396058", "price": "0.51", "size": "151.27", "side": "BUY", "hash": "b160fc4f8f8192d992807ceea367b297b53f78bb", "best_bid": "0.55", "best_ask": "0.79"}, {"asset_id": "93612868481313996119669919082030267547888020881923568220735661390829838620299", "price": "0.49", "size": "151.27", "side": "SELL", "hash": "43b3ad1e488ba9716dbb74baa42f4b4815f36263", "best_bid": "0.21", "best_ask": "0.45"}], "timestamp": "1769384131656", "event_type": "price_change"}}
{"_local_timestamp": "2026-01-25T23:35:31.730745+00:00", "data": {"market": "0xbb676d25a7ce355a3a10fa2bfbee5cb7b6b2ee36581ada7914d73ad78bedf62d", "price_changes": [{"asset_id": "10980869689964921227047480431023635246637317983901031741233635278193625249458", "price": "0.67", "size": "60", "side": "BUY", "hash": "c936d3f2721a4fbb88a0a3121c2131ee02ff30e3", "best_bid": "0.92", "best_ask": "0.94"}, {"asset_id": "68913153540574314749415284055691780290306094084209478229942172031873972067947", "price": "0.33", "size": "60", "side": "SELL", "hash": "8967f2963feda3a1244fc9ec50f853a5a5a30637", "best_bid": "0.06", "best_ask": "0.08"}], "timestamp": "1769384131656", "event_type": "price_change"}}
{"_local_timestamp": "2026-01-25T23:35:34.379031+00:00", "data": {"market": "0x81d603fe35c07415741bb9007bead4cdbddeb80fb35d5c9b6573eae9ee39fc1f", "price_changes": [{"asset_id": "87568880774573784875060327448344352870458352367065142953649333272451455443517", "price": "0.86", "size": "0", "side": "SELL", "hash": "5adeb5d5de1d86cec405ed3d1399bb72bf320adf", "best_bid": "0.82", "best_ask": "0.88"}, {"asset_id": "84046462467623575651564609695680328259011367863582645244986900444709317782077", "price": "0.14", "size": "0", "side": "BUY", "hash": "ae01a786577cc7d25d57d791add5e61a9e158b1c", "best_bid": "0.12", "best_ask": "0.18"}], "timestamp": "1769384134305", "event_type": "price_change"}}
{"_local_timestamp": "2026-01-25T23:35:34.554613+00:00", "data": {"market": "0xbb676d25a7ce355a3a10fa2bfbee5cb7b6b2ee36581ada7914d73ad78bedf62d", "price_changes": [{"asset_id": "10980869689964921227047480431023635246637317983901031741233635278193625249458", "price": "0.68", "size": "0", "side": "BUY", "hash": "fef94058423f629f78c21be6e529b12c364d19e8", "best_bid": "0.92", "best_ask": "0.94"}, {"asset_id": "68913153540574314749415284055691780290306094084209478229942172031873972067947", "price": "0.32", "size": "0", "side": "SELL", "hash": "63c8445469304d64df1d0fe954ea0530f00ddfea", "best_bid": "0.06", "best_ask": "0.08"}], "timestamp": "1769384134488", "event_type": "price_change"}}
{"_local_timestamp": "2026-01-25T23:35:34.555151+00:00", "data": {"market": "0xd8aa928c90a14d70ede48f27543293c03ef8305420105518c3349f993e8fb4b4", "price_changes": [{"asset_id": "35918899905695997492070645194236546618834009355694722884958363910402437678512", "price": "0.709", "size": "10", "side": "BUY", "hash": "f18a2e95b79eb357f660e67365bf62f2ffcfccc0", "best_bid": "0.971", "best_ask": "0.978"}, {"asset_id": "9376678867812664753044653742290850239117727272721528310663723279807470231308", "price": "0.291", "size": "10", "side": "SELL", "hash": "aeb39c506a2ee100b4fa094b274f0c068a07c03b", "best_bid": "0.022", "best_ask": "0.029"}], "timestamp": "1769384134488", "event_type": "price_change"}}
{"_local_timestamp": "2026-01-25T23:35:34.564003+00:00", "data": {"market": "0xd8aa928c90a14d70ede48f27543293c03ef8305420105518c3349f993e8fb4b4", "price_changes": [{"asset_id": "35918899905695997492070645194236546618834009355694722884958363910402437678512", "price": "0.709", "size": "0", "side": "BUY", "hash": "9a47a39a271eda90923ce4c5d398c670b5d81695", "best_bid": "0.971", "best_ask": "0.978"}, {"asset_id": "9376678867812664753044653742290850239117727272721528310663723279807470231308", "price": "0.291", "size": "0", "side": "SELL", "hash": "0558416540605619c1a06a247da15c58b7e65490", "best_bid": "0.022", "best_ask": "0.029"}], "timestamp": "1769384134495", "event_type": "price_change"}}
{"_local_timestamp": "2026-01-25T23:35:34.588458+00:00", "data": {"market": "0x81d603fe35c07415741bb9007bead4cdbddeb80fb35d5c9b6573eae9ee39fc1f", "price_changes": [{"asset_id": "87568880774573784875060327448344352870458352367065142953649333272451455443517", "price": "0.87", "size": "19.73", "side": "SELL", "hash": "6a7201eb4ab333816ccf19abd8b3ddd34584657c", "best_bid": "0.82", "best_ask": "0.87"}, {"asset_id": "84046462467623575651564609695680328259011367863582645244986900444709317782077", "price": "0.13", "size": "19.73", "side": "BUY", "hash": "1fbd4c51c042e44e47b9215a3569afb3eda6c1d1", "best_bid": "0.13", "best_ask": "0.18"}], "timestamp": "1769384134513", "event_type": "price_change"}}
{"_local_timestamp": "2026-01-25T23:35:34.606417+00:00", "data": {"market": "0x2454c412d48443a73e15d93ae01e20caefd5d64a3865b67bc0a465fdac459c77", "price_changes": [{"asset_id": "21604618649648179239165697042911952381335935480672188760475095094501424754919", "price": "0.68", "size": "0", "side": "BUY", "hash": "9c0b1ab3fbd46eff055ebe11075d0310a123cb2f", "best_bid": "0.9", "best_ask": "0.94"}, {"asset_id": "46091239361932142478682480948008873970191467150785110396994502723691495289956", "price": "0.32", "size": "0", "side": "SELL", "hash": "b29c6c2e6a25ad5d2e3597a4e11ff69a8d5bbb2c", "best_bid": "0.06", "best_ask": "0.1"}], "timestamp": "1769384134520", "event_type": "price_change"}}
{"_local_timestamp": "2026-01-25T23:35:34.606893+00:00", "data": {"market": "0xbb676d25a7ce355a3a10fa2bfbee5cb7b6b2ee36581ada7914d73ad78bedf62d", "price_changes": [{"asset_id": "10980869689964921227047480431023635246637317983901031741233635278193625249458", "price": "0.67", "size": "20", "side": "BUY", "hash": "2779c5d02cca271c90b58df14956d814ac0a38e3", "best_bid": "0.92", "best_ask": "0.94"}, {"asset_id": "68913153540574314749415284055691780290306094084209478229942172031873972067947", "price": "0.33", "size": "20", "side": "SELL", "hash": "03569845f5bb159efc50f899a0d811ec8fd3964e", "best_bid": "0.06", "best_ask": "0.08"}], "timestamp": "1769384134520", "event_type": "price_change"}}
{"_local_timestamp": "2026-01-25T23:35:34.607293+00:00", "data": {"market": "0xd8aa928c90a14d70ede48f27543293c03ef8305420105518c3349f993e8fb4b4", "price_changes": [{"asset_id": "35918899905695997492070645194236546618834009355694722884958363910402437678512", "price": "0.708", "size": "0", "side": "BUY", "hash": "832e630024fc38c664ef955345ef9046782d28e1", "best_bid": "0.971", "best_ask": "0.978"}, {"asset_id": "9376678867812664753044653742290850239117727272721528310663723279807470231308", "price": "0.292", "size": "0", "side": "SELL", "hash": "a866203fb674e371c720aa11c6a3637780edfb4b", "best_bid": "0.022", "best_ask": "0.029"}], "timestamp": "1769384134520", "event_type": "price_change"}}
{"_local_timestamp": "2026-01-25T23:35:34.607701+00:00", "data": {"market": "0xa588a3f30682fa83bbc87034e24c9c0fe328435b8abcc390c653de2a51e2f229", "price_changes": [{"asset_id": "112539243967883746727727365469595118105965156896488865205692688474764862492197", "price": "0.438", "size": "0", "side": "BUY", "hash": "6bd8ddd193d3b268a3f53134439d19e59bac5202", "best_bid": "0.976", "best_ask": "0.985"}, {"asset_id": "28097057395543402943370631962731762608572280065916543916317979666329718516169", "price": "0.562", "size": "0", "side": "SELL", "hash": "d8db5d7191c25a8e573945c1411f5f09c5d9f3d5", "best_bid": "0.015", "best_ask": "0.024"}], "timestamp": "1769384134520", "event_type": "price_change"}}
{"_local_timestamp": "2026-01-25T23:35:34.636170+00:00", "data": {"market": "0x2454c412d48443a73e15d93ae01e20caefd5d64a3865b67bc0a465fdac459c77", "price_changes": [{"asset_id": "21604618649648179239165697042911952381335935480672188760475095094501424754919", "price": "0.43", "size": "0", "side": "BUY", "hash": "6706c44ebf2d9d0f0763509c8a1abb88217644f6", "best_bid": "0.9", "best_ask": "0.94"}, {"asset_id": "46091239361932142478682480948008873970191467150785110396994502723691495289956", "price": "0.57", "size": "0", "side": "SELL", "hash": "35f5afd9024067e373ee062880c675662b952392", "best_bid": "0.06", "best_ask": "0.1"}], "timestamp": "1769384134550", "event_type": "price_change"}}
{"_local_timestamp": "2026-01-25T23:35:34.636687+00:00", "data": {"market": "0xd8aa928c90a14d70ede48f27543293c03ef8305420105518c3349f993e8fb4b4", "price_changes": [{"asset_id": "35918899905695997492070645194236546618834009355694722884958363910402437678512", "price": "0.71", "size": "0", "side": "BUY", "hash": "0220b01154333248a121b35569c36027fc66df14", "best_bid": "0.971", "best_ask": "0.978"}, {"asset_id": "9376678867812664753044653742290850239117727272721528310663723279807470231308", "price": "0.29", "size": "0", "side": "SELL", "hash": "6f130e7316faed15f2e7749802e56c15a2c54b75", "best_bid": "0.022", "best_ask": "0.029"}], "timestamp": "1769384134550", "event_type": "price_change"}}
{"_local_timestamp": "2026-01-25T23:35:34.690658+00:00", "data": {"market": "0xd8aa928c90a14d70ede48f27543293c03ef8305420105518c3349f993e8fb4b4", "price_changes": [{"asset_id": "35918899905695997492070645194236546618834009355694722884958363910402437678512", "price": "0.269", "size": "30", "side": "BUY", "hash": "4dc4de3f99a5b54ca895121ff3518694e1122b61", "best_bid": "0.971", "best_ask": "0.978"}, {"asset_id": "9376678867812664753044653742290850239117727272721528310663723279807470231308", "price": "0.731", "size": "30", "side": "SELL", "hash": "afd30d17ee675f01eddcea04fca7dbbd1c937a30", "best_bid": "0.022", "best_ask": "0.029"}], "timestamp": "1769384134603", "event_type": "price_change"}}
{"_local_timestamp": "2026-01-25T23:35:34.691115+00:00", "data": {"market": "0xbb676d25a7ce355a3a10fa2bfbee5cb7b6b2ee36581ada7914d73ad78bedf62d", "price_changes": [{"asset_id": "10980869689964921227047480431023635246637317983901031741233635278193625249458", "price": "0.66", "size": "75", "side": "BUY", "hash": "c51ac2f4f558c7444df9619317a591f6e128734c", "best_bid": "0.92", "best_ask": "0.94"}, {"asset_id": "68913153540574314749415284055691780290306094084209478229942172031873972067947", "price": "0.34", "size": "75", "side": "SELL", "hash": "c1b0305f67119af35bba4a287ff2145389ae5bde", "best_bid": "0.06", "best_ask": "0.08"}], "timestamp": "1769384134603", "event_type": "price_change"}}
{"_local_timestamp": "2026-01-25T23:35:34.876701+00:00", "data": {"market": "0x2454c412d48443a73e15d93ae01e20caefd5d64a3865b67bc0a465fdac459c77", "price_changes": [{"asset_id": "21604618649648179239165697042911952381335935480672188760475095094501424754919", "price": "0.67", "size": "70", "side": "BUY", "hash": "2d56bec0c25986b2ebabab62ed889f24fa7d81e4", "best_bid": "0.9", "best_ask": "0.94"}, {"asset_id": "46091239361932142478682480948008873970191467150785110396994502723691495289956", "price": "0.33", "size": "70", "side": "SELL", "hash": "4137257ae7223d68cb4f90b5fb693b0f5f9e141d", "best_bid": "0.06", "best_ask": "0.1"}], "timestamp": "1769384134726", "event_type": "price_change"}}
{"_local_timestamp": "2026-01-25T23:35:34.877193+00:00", "data": {"market": "0xbb676d25a7ce355a3a10fa2bfbee5cb7b6b2ee36581ada7914d73ad78bedf62d", "price_changes": [{"asset_id": "10980869689964921227047480431023635246637317983901031741233635278193625249458", "price": "0.67", "size": "60", "side": "BUY", "hash": "c17f094d95cbbb6ed9f56c7535adbe79706685c0", "best_bid": "0.92", "best_ask": "0.94"}, {"asset_id": "68913153540574314749415284055691780290306094084209478229942172031873972067947", "price": "0.33", "size": "60", "side": "SELL", "hash": "2ae3a2ce85f7769a3fe3a5d78163832d108c46b9", "best_bid": "0.06", "best_ask": "0.08"}], "timestamp": "1769384134727", "event_type": "price_change"}}
{"_local_timestamp": "2026-01-25T23:35:34.877598+00:00", "data": {"market": "0xd8aa928c90a14d70ede48f27543293c03ef8305420105518c3349f993e8fb4b4", "price_changes": [{"asset_id": "35918899905695997492070645194236546618834009355694722884958363910402437678512", "price": "0.711", "size": "40", "side": "BUY", "hash": "e371dab53761e607f9c30a979552eed59eadbbdb", "best_bid": "0.971", "best_ask": "0.978"}, {"asset_id": "9376678867812664753044653742290850239117727272721528310663723279807470231308", "price": "0.289", "size": "40", "side": "SELL", "hash": "3a147a6ba0844a1659a9ea80d55c11f4ce21748e", "best_bid": "0.022", "best_ask": "0.029"}], "timestamp": "1769384134728", "event_type": "price_change"}}
{"_local_timestamp": "2026-01-25T23:35:34.877990+00:00", "data": {"market": "0xa588a3f30682fa83bbc87034e24c9c0fe328435b8abcc390c653de2a51e2f229", "price_changes": [{"asset_id": "112539243967883746727727365469595118105965156896488865205692688474764862492197", "price": "0.442", "size": "40", "side": "BUY", "hash": "65c463578bf8507443e54f4053bec4ab47ef7a2b", "best_bid": "0.976", "best_ask": "0.985"}, {"asset_id": "28097057395543402943370631962731762608572280065916543916317979666329718516169", "price": "0.558", "size": "40", "side": "SELL", "hash": "ac95ab0f78f3320a0295ebef5e9dbd45f0072e56", "best_bid": "0.015", "best_ask": "0.024"}], "timestamp": "1769384134728", "event_type": "price_change"}}
{"_local_timestamp": "2026-01-25T23:35:34.878353+00:00", "data": {"market": "0x2454c412d48443a73e15d93ae01e20caefd5d64a3865b67bc0a465fdac459c77", "price_changes": [{"asset_id": "21604618649648179239165697042911952381335935480672188760475095094501424754919", "price": "0.43", "size": "182", "side": "BUY", "hash": "a893488af688e47a907f4d484d2bc5c5f9fa0d79", "best_bid": "0.9", "best_ask": "0.94"}, {"asset_id": "46091239361932142478682480948008873970191467150785110396994502723691495289956", "price": "0.57", "size": "182", "side": "SELL", "hash": "b42772de34c6ca701ca28d503bc8621824b99482", "best_bid": "0.06", "best_ask": "0.1"}], "timestamp": "1769384134736", "event_type": "price_change"}}
{"_local_timestamp": "2026-01-25T23:35:34.878736+00:00", "data": {"market": "0xd8aa928c90a14d70ede48f27543293c03ef8305420105518c3349f993e8fb4b4", "price_changes": [{"asset_id": "35918899905695997492070645194236546618834009355694722884958363910402437678512", "price": "0.269", "size": "40", "side": "BUY", "hash": "5d10e7b3fe93db5d86cbe27aa182f1af1afdccde", "best_bid": "0.971", "best_ask": "0.978"}, {"asset_id": "9376678867812664753044653742290850239117727272721528310663723279807470231308", "price": "0.731", "size": "40", "side": "SELL", "hash": "26521ae8ee4be814ef56cec39b8bf0975d47453f", "best_bid": "0.022", "best_ask": "0.029"}], "timestamp": "1769384134737", "event_type": "price_change"}}
{"_local_timestamp": "2026-01-25T23:35:34.879137+00:00", "data": {"market": "0x2454c412d48443a73e15d93ae01e20caefd5d64a3865b67bc0a465fdac459c77", "price_changes": [{"asset_id": "21604618649648179239165697042911952381335935480672188760475095094501424754919", "price": "0.43", "size": "192", "side": "BUY", "hash": "0d5655e8f56a6c667e0b93a36a7fbc1b7cb2a17c", "best_bid": "0.9", "best_ask": "0.94"}, {"asset_id": "46091239361932142478682480948008873970191467150785110396994502723691495289956", "price": "0.57", "size": "192", "side": "SELL", "hash": "2644b163817d944d01db98ba367620b8d16540b0", "best_bid": "0.06", "best_ask": "0.1"}], "timestamp": "1769384134740", "event_type": "price_change"}}
{"_local_timestamp": "2026-01-25T23:35:35.302264+00:00", "data": {"market": "0x2454c412d48443a73e15d93ae01e20caefd5d64a3865b67bc0a465fdac459c77", "price_changes": [{"asset_id": "21604618649648179239165697042911952381335935480672188760475095094501424754919", "price": "0.43", "size": "10", "side": "BUY", "hash": "a4b392f21c9b62f2ffb4025d9700b3db00ca37e8", "best_bid": "0.9", "best_ask": "0.94"}, {"asset_id": "46091239361932142478682480948008873970191467150785110396994502723691495289956", "price": "0.57", "size": "10", "side": "SELL", "hash": "5e88ffa02eb099081641e77245ac052767c8e440", "best_bid": "0.06", "best_ask": "0.1"}], "timestamp": "1769384135231", "event_type": "price_change"}}
{"_local_timestamp": "2026-01-25T23:35:36.853162+00:00", "data": {"market": "0xbb676d25a7ce355a3a10fa2bfbee5cb7b6b2ee36581ada7914d73ad78bedf62d", "price_changes": [{"asset_id": "10980869689964921227047480431023635246637317983901031741233635278193625249458", "price": "0.66", "size": "55", "side": "BUY", "hash": "85cabec223fe2dff365c1b0014d4e2a5d5662103", "best_bid": "0.92", "best_ask": "0.94"}, {"asset_id": "68913153540574314749415284055691780290306094084209478229942172031873972067947", "price": "0.34", "size": "55", "side": "SELL", "hash": "8465c64f49c091d82233a5006636cef6e6b169e3", "best_bid": "0.06", "best_ask": "0.08"}], "timestamp": "1769384136775", "event_type": "price_change"}}
{"_local_timestamp": "2026-01-25T23:35:36.853702+00:00", "data": {"market": "0xa588a3f30682fa83bbc87034e24c9c0fe328435b8abcc390c653de2a51e2f229", "price_changes": [{"asset_id": "112539243967883746727727365469595118105965156896488865205692688474764862492197", "price": "0.441", "size": "0", "side": "BUY", "hash": "4ee9d9b72d586f9f30bfa656eaed2e2d40edd759", "best_bid": "0.976", "best_ask": "0.985"}, {"asset_id": "28097057395543402943370631962731762608572280065916543916317979666329718516169", "price": "0.559", "size": "0", "side": "SELL", "hash": "bf459f5e7499668856bdd000d8bf5eaffcc0bc9c", "best_bid": "0.015", "best_ask": "0.024"}], "timestamp": "1769384136775", "event_type": "price_change"}}
{"_local_timestamp": "2026-01-25T23:35:36.854160+00:00", "data": {"market": "0xd8aa928c90a14d70ede48f27543293c03ef8305420105518c3349f993e8fb4b4", "price_changes": [{"asset_id": "35918899905695997492070645194236546618834009355694722884958363910402437678512", "price": "0.268", "size": "0", "side": "BUY", "hash": "b30af5a7930c7051e8b816fb7834198c9b918043", "best_bid": "0.971", "best_ask": "0.978"}, {"asset_id": "9376678867812664753044653742290850239117727272721528310663723279807470231308", "price": "0.732", "size": "0", "side": "SELL", "hash": "f7bde07538253d4e3459e79f8ee8ee4f23c87e09", "best_bid": "0.022", "best_ask": "0.029"}], "timestamp": "1769384136775", "event_type": "price_change"}}
{"_local_timestamp": "2026-01-25T23:35:36.854601+00:00", "data": {"market": "0x7ec88c27625388fe4de5c1e083da56806973aae7257bd0b3b2c2790937c89433", "price_changes": [{"asset_id": "11439216096927556294398061349600841087621436733892133369767994197102929396058", "price": "0.51", "size": "131.27", "side": "BUY", "hash": "6b31e5119082d6233b2a3e852f083ead219778ee", "best_bid": "0.55", "best_ask": "0.79"}, {"asset_id": "93612868481313996119669919082030267547888020881923568220735661390829838620299", "price": "0.49", "size": "131.27", "side": "SELL", "hash": "30b653bcf953da8c5f5404cd04373ddedca88c64", "best_bid": "0.21", "best_ask": "0.45"}], "timestamp": "1769384136775", "event_type": "price_change"}}
{"_local_timestamp": "2026-01-25T23:35:36.855011+00:00", "data": {"market": "0x2454c412d48443a73e15d93ae01e20caefd5d64a3865b67bc0a465fdac459c77", "price_changes": [{"asset_id": "21604618649648179239165697042911952381335935480672188760475095094501424754919", "price": "0.66", "size": "0", "side": "BUY", "hash": "56693a797e17d6403af4f4eb03db32b0c337da30", "best_bid": "0.9", "best_ask": "0.94"}, {"asset_id": "46091239361932142478682480948008873970191467150785110396994502723691495289956", "price": "0.34", "size": "0", "side": "SELL", "hash": "bd5439907e4462b6a3809513fd1578525a99ede0", "best_bid": "0.06", "best_ask": "0.1"}], "timestamp": "1769384136775", "event_type": "price_change"}}
{"_local_timestamp": "2026-01-25T23:35:36.878987+00:00", "data": {"market": "0x2454c412d48443a73e15d93ae01e20caefd5d64a3865b67bc0a465fdac459c77", "price_changes": [{"asset_id": "21604618649648179239165697042911952381335935480672188760475095094501424754919", "price": "0.65", "size": "47.23", "side": "BUY", "hash": "cc96f37886bb0947fb6aab7a2d3f5ece72bddceb", "best_bid": "0.9", "best_ask": "0.94"}, {"asset_id": "46091239361932142478682480948008873970191467150785110396994502723691495289956", "price": "0.35", "size": "47.23", "side": "SELL", "hash": "bb799f2299d204ccd8bc1297139785b6437ab880", "best_bid": "0.06", "best_ask": "0.1"}], "timestamp": "1769384136807", "event_type": "price_change"}}
{"_local_timestamp": "2026-01-25T23:35:36.879568+00:00", "data": {"market": "0x7ec88c27625388fe4de5c1e083da56806973aae7257bd0b3b2c2790937c89433", "price_changes": [{"asset_id": "11439216096927556294398061349600841087621436733892133369767994197102929396058", "price": "0.33", "size": "20", "side": "BUY", "hash": "d32f1b809e1fb197191a85aeb53d532c3a33d896", "best_bid": "0.55", "best_ask": "0.79"}, {"asset_id": "93612868481313996119669919082030267547888020881923568220735661390829838620299", "price": "0.67", "size": "20", "side": "SELL", "hash": "e92a1a146186be4a307ec84c43bfb25cafc06ece", "best_bid": "0.21", "best_ask": "0.45"}], "timestamp": "1769384136807", "event_type": "price_change"}}
{"_local_timestamp": "2026-01-25T23:35:36.880050+00:00", "data": {"market": "0xa588a3f30682fa83bbc87034e24c9c0fe328435b8abcc390c653de2a51e2f229", "price_changes": [{"asset_id": "112539243967883746727727365469595118105965156896488865205692688474764862492197", "price": "0.443", "size": "20", "side": "BUY", "hash": "51ea85866ff5d0b288a055eef0b4c3e97791b504", "best_bid": "0.976", "best_ask": "0.985"}, {"asset_id": "28097057395543402943370631962731762608572280065916543916317979666329718516169", "price": "0.557", "size": "20", "side": "SELL", "hash": "3f37d0daedc2b914fdaf817f3ace1d6b75e9cb65", "best_bid": "0.015", "best_ask": "0.024"}], "timestamp": "1769384136807", "event_type": "price_change"}}
{"_local_timestamp": "2026-01-25T23:35:36.880487+00:00", "data": {"market": "0xd8aa928c90a14d70ede48f27543293c03ef8305420105518c3349f993e8fb4b4", "price_changes": [{"asset_id": "35918899905695997492070645194236546618834009355694722884958363910402437678512", "price": "0.27", "size": "20", "side": "BUY", "hash": "ab31019a9aceb19a0c155d715780003735969c3a", "best_bid": "0.971", "best_ask": "0.978"}, {"asset_id": "9376678867812664753044653742290850239117727272721528310663723279807470231308", "price": "0.73", "size": "20", "side": "SELL", "hash": "95f4e12cc0876431f67c91e3d85565d1281dd699", "best_bid": "0.022", "best_ask": "0.029"}], "timestamp": "1769384136807", "event_type": "price_change"}}
{"_local_timestamp": "2026-01-25T23:35:36.880959+00:00", "data": {"market": "0xbb676d25a7ce355a3a10fa2bfbee5cb7b6b2ee36581ada7914d73ad78bedf62d", "price_changes": [{"asset_id": "10980869689964921227047480431023635246637317983901031741233635278193625249458", "price": "0.41", "size": "20", "side": "BUY", "hash": "caa54c0bc8473f19a29f48a836ce2f71a2d7a54d", "best_bid": "0.92", "best_ask": "0.94"}, {"asset_id": "68913153540574314749415284055691780290306094084209478229942172031873972067947", "price": "0.59", "size": "20", "side": "SELL", "hash": "e20c9efed4018e1bf118f98b262e90d93b116d2c", "best_bid": "0.06", "best_ask": "0.08"}], "timestamp": "1769384136807", "event_type": "price_change"}}
{"_local_timestamp": "2026-01-25T23:36:32.733346+00:00", "data": {"market": "0x81d603fe35c07415741bb9007bead4cdbddeb80fb35d5c9b6573eae9ee39fc1f", "price_changes": [{"asset_id": "84046462467623575651564609695680328259011367863582645244986900444709317782077", "price": "0.13", "size": "88.73", "side": "BUY", "hash": "70ffb9ea9f202708a25df6cd895a6a3ebe8bb173", "best_bid": "0.13", "best_ask": "0.18"}, {"asset_id": "87568880774573784875060327448344352870458352367065142953649333272451455443517", "price": "0.87", "size": "88.73", "side": "SELL", "hash": "3cdf453ece5227dccb2f2d89764c3a79d6880323", "best_bid": "0.82", "best_ask": "0.87"}], "timestamp": "1769384192661", "event_type": "price_change"}}
{"_local_timestamp": "2026-01-25T23:36:32.834197+00:00", "data": {"market": "0x6d08ed1eadd870cd00c92048dda2fe06650e15905f8828ddf15e4d2186898029", "price_changes": [{"asset_id": "9876264386649584456256217467156428648140707909529649867285151715292859513583", "price": "0.43", "size": "0", "side": "BUY", "hash": "2a7710876afc836978c9a0defa2d1db1187a5bd2", "best_bid": "0.63", "best_ask": "0.75"}, {"asset_id": "16774186999359636680352173816986047997138878170738869842466593332514752926314", "price": "0.57", "size": "0", "side": "SELL", "hash": "090ba508541b120f2fac585d499893ada8648366", "best_bid": "0.25", "best_ask": "0.37"}], "timestamp": "1769384192759", "event_type": "price_change"}}
{"_local_timestamp": "2026-01-25T23:36:32.834768+00:00", "data": {"market": "0xa588a3f30682fa83bbc87034e24c9c0fe328435b8abcc390c653de2a51e2f229", "price_changes": [{"asset_id": "112539243967883746727727365469595118105965156896488865205692688474764862492197", "price": "0.436", "size": "0", "side": "BUY", "hash": "5608f300edb6cab66bb81ecf7d82f20c37b40bd9", "best_bid": "0.976", "best_ask": "0.985"}, {"asset_id": "28097057395543402943370631962731762608572280065916543916317979666329718516169", "price": "0.564", "size": "0", "side": "SELL", "hash": "efd0729a488c7c51ac384a5cb63897221a4d1ff1", "best_bid": "0.015", "best_ask": "0.024"}], "timestamp": "1769384192760", "event_type": "price_change"}}
{"_local_timestamp": "2026-01-25T23:36:32.923662+00:00", "data": {"market": "0x81d603fe35c07415741bb9007bead4cdbddeb80fb35d5c9b6573eae9ee39fc1f", "price_changes": [{"asset_id": "87568880774573784875060327448344352870458352367065142953649333272451455443517", "price": "0.87", "size": "69", "side": "SELL", "hash": "711bdf1addbe1775a8794dea791f52776705db19", "best_bid": "0.82", "best_ask": "0.87"}, {"asset_id": "84046462467623575651564609695680328259011367863582645244986900444709317782077", "price": "0.13", "size": "69", "side": "BUY", "hash": "bec1b8f0d2d36d23cad824f89b3e618d82c113f8", "best_bid": "0.13", "best_ask": "0.18"}], "timestamp": "1769384192849", "event_type": "price_change"}}
{"_local_timestamp": "2026-01-25T23:36:32.977343+00:00", "data": {"market": "0x6d08ed1eadd870cd00c92048dda2fe06650e15905f8828ddf15e4d2186898029", "price_changes": [{"asset_id": "9876264386649584456256217467156428648140707909529649867285151715292859513583", "price": "0.47", "size": "10", "side": "BUY", "hash": "3ab198f6d6fe37a916472346b0856d99bd01124a", "best_bid": "0.63", "best_ask": "0.75"}, {"asset_id": "16774186999359636680352173816986047997138878170738869842466593332514752926314", "price": "0.53", "size": "10", "side": "SELL", "hash": "4f9016a978976ec5570dad2f7c79557cac4a258a", "best_bid": "0.25", "best_ask": "0.37"}], "timestamp": "1769384192897", "event_type": "price_change"}}
{"_local_timestamp": "2026-01-25T23:36:32.977892+00:00", "data": {"market": "0xa588a3f30682fa83bbc87034e24c9c0fe328435b8abcc390c653de2a51e2f229", "price_changes": [{"asset_id": "112539243967883746727727365469595118105965156896488865205692688474764862492197", "price": "0.444", "size": "10", "side": "BUY", "hash": "17c4d34ceb52f619c7078cf59540bfb4cb5cfdd2", "best_bid": "0.976", "best_ask": "0.985"}, {"asset_id": "28097057395543402943370631962731762608572280065916543916317979666329718516169", "price": "0.556", "size": "10", "side": "SELL", "hash": "0f85d18089138025d6a7fcbafd8738704cde9ad1", "best_bid": "0.015", "best_ask": "0.024"}], "timestamp": "1769384192897", "event_type": "price_change"}}
{"_local_timestamp": "2026-01-25T23:36:32.978363+00:00", "data": {"market": "0xa588a3f30682fa83bbc87034e24c9c0fe328435b8abcc390c653de2a51e2f229", "price_changes": [{"asset_id": "112539243967883746727727365469595118105965156896488865205692688474764862492197", "price": "0.444", "size": "63", "side": "BUY", "hash": "e7a388e7b803767327288f0ff4b266378648e035", "best_bid": "0.976", "best_ask": "0.985"}, {"asset_id": "28097057395543402943370631962731762608572280065916543916317979666329718516169", "price": "0.556", "size": "63", "side": "SELL", "hash": "c4577ebe012c531fed055e90e557fac7b777a874", "best_bid": "0.015", "best_ask": "0.024"}], "timestamp": "1769384192900", "event_type": "price_change"}}
{"_local_timestamp": "2026-01-25T23:36:33.338570+00:00", "data": {"market": "0x81d603fe35c07415741bb9007bead4cdbddeb80fb35d5c9b6573eae9ee39fc1f", "price_changes": [{"asset_id": "87568880774573784875060327448344352870458352367065142953649333272451455443517", "price": "0.86", "size": "19.73", "side": "SELL", "hash": "80cf69fb49db33601d273fa60daac3962091c74e", "best_bid": "0.82", "best_ask": "0.86"}, {"asset_id": "84046462467623575651564609695680328259011367863582645244986900444709317782077", "price": "0.14", "size": "19.73", "side": "BUY", "hash": "638edb8c1359538e77fa3de6ac74909192c76c0e", "best_bid": "0.14", "best_ask": "0.18"}], "timestamp": "1769384193268", "event_type": "price_change"}}
{"_local_timestamp": "2026-01-25T23:36:33.482965+00:00", "data": {"market": "0xa588a3f30682fa83bbc87034e24c9c0fe328435b8abcc390c653de2a51e2f229", "price_changes": [{"asset_id": "112539243967883746727727365469595118105965156896488865205692688474764862492197", "price": "0.444", "size": "10", "side": "BUY", "hash": "c2e3dbd771837904064ba32cd187c0a83d78860a", "best_bid": "0.976", "best_ask": "0.985"}, {"asset_id": "28097057395543402943370631962731762608572280065916543916317979666329718516169", "price": "0.556", "size": "10", "side": "SELL", "hash": "6e4c853099ab6f8476bdfa318d3984a6e50da980", "best_bid": "0.015", "best_ask": "0.024"}], "timestamp": "1769384193418", "event_type": "price_change"}}
{"_local_timestamp": "2026-01-25T23:36:34.753107+00:00", "data": {"market": "0x7ec88c27625388fe4de5c1e083da56806973aae7257bd0b3b2c2790937c89433", "price_changes": [{"asset_id": "11439216096927556294398061349600841087621436733892133369767994197102929396058", "price": "0.33", "size": "0", "side": "BUY", "hash": "777abebb452fcda479c350cbb7f6d1aeec1d2e93", "best_bid": "0.55", "best_ask": "0.79"}, {"asset_id": "93612868481313996119669919082030267547888020881923568220735661390829838620299", "price": "0.67", "size": "0", "side": "SELL", "hash": "def8e0f6d4cbb8c7affa0fe6a651dae32e7d9ca1", "best_bid": "0.21", "best_ask": "0.45"}], "timestamp": "1769384194678", "event_type": "price_change"}}
{"_local_timestamp": "2026-01-25T23:36:34.753757+00:00", "data": {"market": "0x2454c412d48443a73e15d93ae01e20caefd5d64a3865b67bc0a465fdac459c77", "price_changes": [{"asset_id": "21604618649648179239165697042911952381335935480672188760475095094501424754919", "price": "0.65", "size": "27.23", "side": "BUY", "hash": "e977047ef1de41e705687d63359dd9045cf7cf6f", "best_bid": "0.9", "best_ask": "0.94"}, {"asset_id": "46091239361932142478682480948008873970191467150785110396994502723691495289956", "price": "0.35", "size": "27.23", "side": "SELL", "hash": "c50e1750030d77e975e3eb99242276d559563076", "best_bid": "0.06", "best_ask": "0.1"}], "timestamp": "1769384194678", "event_type": "price_change"}}
{"_local_timestamp": "2026-01-25T23:36:34.754258+00:00", "data": {"market": "0xbb676d25a7ce355a3a10fa2bfbee5cb7b6b2ee36581ada7914d73ad78bedf62d", "price_changes": [{"asset_id": "10980869689964921227047480431023635246637317983901031741233635278193625249458", "price": "0.41", "size": "0", "side": "BUY", "hash": "661524ffc94063d6371cf57653ebb64bba60b7ca", "best_bid": "0.92", "best_ask": "0.94"}, {"asset_id": "68913153540574314749415284055691780290306094084209478229942172031873972067947", "price": "0.59", "size": "0", "side": "SELL", "hash": "313f86ce281be9003d2e601451f54605899c472e", "best_bid": "0.06", "best_ask": "0.08"}], "timestamp": "1769384194678", "event_type": "price_change"}}
{"_local_timestamp": "2026-01-25T23:36:34.754731+00:00", "data": {"market": "0x6d08ed1eadd870cd00c92048dda2fe06650e15905f8828ddf15e4d2186898029", "price_changes": [{"asset_id": "9876264386649584456256217467156428648140707909529649867285151715292859513583", "price": "0.46", "size": "0", "side": "BUY", "hash": "86d286dc92c2173f91cfa8c3f1d987d2a783c264", "best_bid": "0.63", "best_ask": "0.75"}, {"asset_id": "16774186999359636680352173816986047997138878170738869842466593332514752926314", "price": "0.54", "size": "0", "side": "SELL", "hash": "3d55ba2afe7ce51a3099ffdd3554e483246faed3", "best_bid": "0.25", "best_ask": "0.37"}], "timestamp": "1769384194678", "event_type": "price_change"}}
{"_local_timestamp": "2026-01-25T23:36:34.755205+00:00", "data": {"market": "0xa588a3f30682fa83bbc87034e24c9c0fe328435b8abcc390c653de2a51e2f229", "price_changes": [{"asset_id": "112539243967883746727727365469595118105965156896488865205692688474764862492197", "price": "0.443", "size": "0", "side": "BUY", "hash": "1ecc904fda918f523775576f8c7989c05d038716", "best_bid": "0.976", "best_ask": "0.985"}, {"asset_id": "28097057395543402943370631962731762608572280065916543916317979666329718516169", "price": "0.557", "size": "0", "side": "SELL", "hash": "f8d624d72a1ea5c23e824a313bb6148420f891a3", "best_bid": "0.015", "best_ask": "0.024"}], "timestamp": "1769384194678", "event_type": "price_change"}}
{"_local_timestamp": "2026-01-25T23:36:34.784733+00:00", "data": {"market": "0x6d08ed1eadd870cd00c92048dda2fe06650e15905f8828ddf15e4d2186898029", "price_changes": [{"asset_id": "9876264386649584456256217467156428648140707909529649867285151715292859513583", "price": "0.47", "size": "30", "side": "BUY", "hash": "990d4c118c5a731a972c8ba76ce62f7c604a1502", "best_bid": "0.63", "best_ask": "0.75"}, {"asset_id": "16774186999359636680352173816986047997138878170738869842466593332514752926314", "price": "0.53", "size": "30", "side": "SELL", "hash": "0e7a72d015841b1a2a2973e5952136efd5e2db80", "best_bid": "0.25", "best_ask": "0.37"}], "timestamp": "1769384194715", "event_type": "price_change"}}
{"_local_timestamp": "2026-01-25T23:36:34.786668+00:00", "data": {"market": "0x7ec88c27625388fe4de5c1e083da56806973aae7257bd0b3b2c2790937c89433", "price_changes": [{"asset_id": "11439216096927556294398061349600841087621436733892133369767994197102929396058", "price": "0.51", "size": "151.27", "side": "BUY", "hash": "f4dc6e1b7a0fdad4022e8787c3a6125b8d35820f", "best_bid": "0.55", "best_ask": "0.79"}, {"asset_id": "93612868481313996119669919082030267547888020881923568220735661390829838620299", "price": "0.49", "size": "151.27", "side": "SELL", "hash": "2bca1f8985b4577b23973c223d85bac73936f481", "best_bid": "0.21", "best_ask": "0.45"}], "timestamp": "1769384194715", "event_type": "price_change"}}
{"_local_timestamp": "2026-01-25T23:36:34.787225+00:00", "data": {"market": "0x2454c412d48443a73e15d93ae01e20caefd5d64a3865b67bc0a465fdac459c77", "price_changes": [{"asset_id": "21604618649648179239165697042911952381335935480672188760475095094501424754919", "price": "0.66", "size": "20", "side": "BUY", "hash": "18bf0ac30d0bcf1ef532c3b012c5bd11c031946c", "best_bid": "0.9", "best_ask": "0.94"}, {"asset_id": "46091239361932142478682480948008873970191467150785110396994502723691495289956", "price": "0.34", "size": "20", "side": "SELL", "hash": "1edc9c8358cc465c2f00b0ca84f77f874caa14a4", "best_bid": "0.06", "best_ask": "0.1"}], "timestamp": "1769384194715", "event_type": "price_change"}}
{"_local_timestamp": "2026-01-25T23:36:34.787782+00:00", "data": {"market": "0xa588a3f30682fa83bbc87034e24c9c0fe328435b8abcc390c653de2a51e2f229", "price_changes": [{"asset_id": "112539243967883746727727365469595118105965156896488865205692688474764862492197", "price": "0.445", "size": "20", "side": "BUY", "hash": "f30eb877e0bebc763c9585bbfae6db8edfbaf0a8", "best_bid": "0.976", "best_ask": "0.985"}, {"asset_id": "28097057395543402943370631962731762608572280065916543916317979666329718516169", "price": "0.555", "size": "20", "side": "SELL", "hash": "046312ee8658cf43b70a838dffed7f4ee1ab8236", "best_bid": "0.015", "best_ask": "0.024"}], "timestamp": "1769384194715", "event_type": "price_change"}}
{"_local_timestamp": "2026-01-25T23:36:34.788299+00:00", "data": {"market": "0xbb676d25a7ce355a3a10fa2bfbee5cb7b6b2ee36581ada7914d73ad78bedf62d", "price_changes": [{"asset_id": "10980869689964921227047480431023635246637317983901031741233635278193625249458", "price": "0.66", "size": "75", "side": "BUY", "hash": "85d29d82af0f6ff6646a79ffcfa1b466c5682e71", "best_bid": "0.92", "best_ask": "0.94"}, {"asset_id": "68913153540574314749415284055691780290306094084209478229942172031873972067947", "price": "0.34", "size": "75", "side": "SELL", "hash": "d22978f740947572011d9639e7a08907d6fee92d", "best_bid": "0.06", "best_ask": "0.08"}], "timestamp": "1769384194715", "event_type": "price_change"}}
{"_local_timestamp": "2026-01-25T23:36:55.170838+00:00", "data": {"market": "0x7ec88c27625388fe4de5c1e083da56806973aae7257bd0b3b2c2790937c89433", "price_changes": [{"asset_id": "11439216096927556294398061349600841087621436733892133369767994197102929396058", "price": "0.05", "size": "930", "side": "BUY", "hash": "6d6591939ac9c51ac259655421ee9f42cca62214", "best_bid": "0.55", "best_ask": "0.79"}, {"asset_id": "93612868481313996119669919082030267547888020881923568220735661390829838620299", "price": "0.95", "size": "930", "side": "SELL", "hash": "77702bd4c0ff56a8f94ced08121563828b905075", "best_bid": "0.21", "best_ask": "0.45"}], "timestamp": "1769384214946", "event_type": "price_change"}}
{"_local_timestamp": "2026-01-25T23:36:55.171703+00:00", "data": {"market": "0x6d08ed1eadd870cd00c92048dda2fe06650e15905f8828ddf15e4d2186898029", "price_changes": [{"asset_id": "9876264386649584456256217467156428648140707909529649867285151715292859513583", "price": "0.05", "size": "930", "side": "BUY", "hash": "aa0b6cd9127971715e5cfb5e7e50e2bdbd5db113", "best_bid": "0.63", "best_ask": "0.75"}, {"asset_id": "16774186999359636680352173816986047997138878170738869842466593332514752926314", "price": "0.95", "size": "930", "side": "SELL", "hash": "735eaf09986047a1dd2ddef902ebfa6cdc197fdc", "best_bid": "0.25", "best_ask": "0.37"}], "timestamp": "1769384214946", "event_type": "price_change"}}
{"_local_timestamp": "2026-01-25T23:36:55.177956+00:00", "data": {"market": "0x6d08ed1eadd870cd00c92048dda2fe06650e15905f8828ddf15e4d2186898029", "price_changes": [{"asset_id": "9876264386649584456256217467156428648140707909529649867285151715292859513583", "price": "0.12", "size": "56", "side": "BUY", "hash": "aa0b6cd9127971715e5cfb5e7e50e2bdbd5db113", "best_bid": "0.63", "best_ask": "0.75"}, {"asset_id": "16774186999359636680352173816986047997138878170738869842466593332514752926314", "price": "0.88", "size": "56", "side": "SELL", "hash": "735eaf09986047a1dd2ddef902ebfa6cdc197fdc", "best_bid": "0.25", "best_ask": "0.37"}], "timestamp": "1769384214946", "event_type": "price_change"}}
{"_local_timestamp": "2026-01-25T23:36:56.143060+00:00", "data": {"market": "0x7ec88c27625388fe4de5c1e083da56806973aae7257bd0b3b2c2790937c89433", "price_changes": [{"asset_id": "11439216096927556294398061349600841087621436733892133369767994197102929396058", "price": "0.1", "size": "800", "side": "BUY", "hash": "de9d5218a445828a7a6a8523b82c8e8a2f4a10b7", "best_bid": "0.55", "best_ask": "0.79"}, {"asset_id": "93612868481313996119669919082030267547888020881923568220735661390829838620299", "price": "0.9", "size": "800", "side": "SELL", "hash": "5081d9bc3cebf8b8d7c196fce7e7f83b608b5566", "best_bid": "0.21", "best_ask": "0.45"}], "timestamp": "1769384215654", "event_type": "price_change"}}
{"_local_timestamp": "2026-01-25T23:36:56.143801+00:00", "data": {"market": "0x6d08ed1eadd870cd00c92048dda2fe06650e15905f8828ddf15e4d2186898029", "price_changes": [{"asset_id": "9876264386649584456256217467156428648140707909529649867285151715292859513583", "price": "0.1", "size": "1083", "side": "BUY", "hash": "b2e0b5145e4c2992c2183b6d3803abce8251b64f", "best_bid": "0.63", "best_ask": "0.75"}, {"asset_id": "16774186999359636680352173816986047997138878170738869842466593332514752926314", "price": "0.9", "size": "1083", "side": "SELL", "hash": "4c03a2b0981dc1d8a3d277f64cea82eb27ecf886", "best_bid": "0.25", "best_ask": "0.37"}], "timestamp": "1769384215654", "event_type": "price_change"}}
{"_local_timestamp": "2026-01-25T23:36:56.149936+00:00", "data": {"market": "0x6d08ed1eadd870cd00c92048dda2fe06650e15905f8828ddf15e4d2186898029", "price_changes": [{"asset_id": "9876264386649584456256217467156428648140707909529649867285151715292859513583", "price": "0.11", "size": "438", "side": "BUY", "hash": "a92bfb4457064e9dc1336cd679627bacad7b36cc", "best_bid": "0.63", "best_ask": "0.75"}, {"asset_id": "16774186999359636680352173816986047997138878170738869842466593332514752926314", "price": "0.89", "size": "438", "side": "SELL", "hash": "65ca5f289760a61df573423f7033b02b5f30d2b4", "best_bid": "0.25", "best_ask": "0.37"}], "timestamp": "1769384215733", "event_type": "price_change"}}
{"_local_timestamp": "2026-01-25T23:36:57.553591+00:00", "data": {"market": "0x7ec88c27625388fe4de5c1e083da56806973aae7257bd0b3b2c2790937c89433", "price_changes": [{"asset_id": "11439216096927556294398061349600841087621436733892133369767994197102929396058", "price": "0.22", "size": "100", "side": "BUY", "hash": "4155a98d865cbc48cc34e3f542057f2800920613", "best_bid": "0.55", "best_ask": "0.79"}, {"asset_id": "93612868481313996119669919082030267547888020881923568220735661390829838620299", "price": "0.78", "size": "100", "side": "SELL", "hash": "6571e5e32b4acc528042de46399d56eff2df01e2", "best_bid": "0.21", "best_ask": "0.45"}], "timestamp": "1769384217223", "event_type": "price_change"}}
{"_local_timestamp": "2026-01-25T23:36:57.569270+00:00", "data": {"market": "0x6d08ed1eadd870cd00c92048dda2fe06650e15905f8828ddf15e4d2186898029", "price_changes": [{"asset_id": "9876264386649584456256217467156428648140707909529649867285151715292859513583", "price": "0.12", "size": "0", "side": "BUY", "hash": "3bae9be451b70f183a7b60ffad9385517dbf9c65", "best_bid": "0.63", "best_ask": "0.75"}, {"asset_id": "16774186999359636680352173816986047997138878170738869842466593332514752926314", "price": "0.88", "size": "0", "side": "SELL", "hash": "4af181cf31d0dbe3c05c05d6f4f2a3117ed143fa", "best_bid": "0.25", "best_ask": "0.37"}], "timestamp": "1769384217231", "event_type": "price_change"}}
{"_local_timestamp": "2026-01-25T23:36:57.601518+00:00", "data": {"market": "0x33c890cbc6edeb7ce360351a288ec411b3f9a5282667e3bf18a3051c4767428c", "price_changes": [{"asset_id": "113516997583046187201046242649428977289438194581672050007909348202973938222410", "price": "0.185", "size": "250", "side": "BUY", "hash": "f9c95ac915433b665c921074814ba0ae448c3064", "best_bid": "0.96", "best_ask": "0.99"}, {"asset_id": "51241971381574011156532505117739358478718782528207416160352857296343207110308", "price": "0.815", "size": "250", "side": "SELL", "hash": "1d828010b2339d49a551c5d0842f8312c4b43908", "best_bid": "0.01", "best_ask": "0.04"}], "timestamp": "1769384217236", "event_type": "price_change"}}
{"_local_timestamp": "2026-01-25T23:37:13.106447+00:00", "data": {"market": "0x7ec88c27625388fe4de5c1e083da56806973aae7257bd0b3b2c2790937c89433", "price_changes": [{"asset_id": "11439216096927556294398061349600841087621436733892133369767994197102929396058", "price": "0.16", "size": "150", "side": "BUY", "hash": "18704f1075bb3ee6b157e47e8b94becd2af6bf9c", "best_bid": "0.55", "best_ask": "0.79"}, {"asset_id": "93612868481313996119669919082030267547888020881923568220735661390829838620299", "price": "0.84", "size": "150", "side": "SELL", "hash": "bfeb065ebe3dd276151365c040b448c0ebe86a4b", "best_bid": "0.21", "best_ask": "0.45"}], "timestamp": "1769384233005", "event_type": "price_change"}}
{"_local_timestamp": "2026-01-25T23:37:13.113144+00:00", "data": {"market": "0x7ec88c27625388fe4de5c1e083da56806973aae7257bd0b3b2c2790937c89433", "price_changes": [{"asset_id": "11439216096927556294398061349600841087621436733892133369767994197102929396058", "price": "0.15", "size": "1166.66", "side": "BUY", "hash": "18704f1075bb3ee6b157e47e8b94becd2af6bf9c", "best_bid": "0.55", "best_ask": "0.79"}, {"asset_id": "93612868481313996119669919082030267547888020881923568220735661390829838620299", "price": "0.85", "size": "1166.66", "side": "SELL", "hash": "bfeb065ebe3dd276151365c040b448c0ebe86a4b", "best_bid": "0.21", "best_ask": "0.45"}], "timestamp": "1769384233005", "event_type": "price_change"}}
{"_local_timestamp": "2026-01-25T23:37:13.113891+00:00", "data": {"market": "0x6d08ed1eadd870cd00c92048dda2fe06650e15905f8828ddf15e4d2186898029", "price_changes": [{"asset_id": "9876264386649584456256217467156428648140707909529649867285151715292859513583", "price": "0.11", "size": "313", "side": "BUY", "hash": "5b45afbf77a01ce3a2d930b47f6bdf8796062407", "best_bid": "0.63", "best_ask": "0.75"}, {"asset_id": "16774186999359636680352173816986047997138878170738869842466593332514752926314", "price": "0.89", "size": "313", "side": "SELL", "hash": "1793f63a3cb3f8edcb22740ba6733b8b4217924b", "best_bid": "0.25", "best_ask": "0.37"}], "timestamp": "1769384233005", "event_type": "price_change"}}
{"_local_timestamp": "2026-01-25T23:37:13.186597+00:00", "data": {"market": "0x81d603fe35c07415741bb9007bead4cdbddeb80fb35d5c9b6573eae9ee39fc1f", "price_changes": [{"asset_id": "87568880774573784875060327448344352870458352367065142953649333272451455443517", "price": "0.43", "size": "0", "side": "BUY", "hash": "96c84a712b842bbddc0f79a29a1b4e000e03c49f", "best_bid": "0.82", "best_ask": "0.86"}, {"asset_id": "84046462467623575651564609695680328259011367863582645244986900444709317782077", "price": "0.57", "size": "0", "side": "SELL", "hash": "c544577b0fe774271cd7ee7c32aef30f699d8f48", "best_bid": "0.14", "best_ask": "0.18"}], "timestamp": "1769384233080", "event_type": "price_change"}}
{"_local_timestamp": "2026-01-25T23:37:13.265864+00:00", "data": {"market": "0xa588a3f30682fa83bbc87034e24c9c0fe328435b8abcc390c653de2a51e2f229", "price_changes": [{"asset_id": "112539243967883746727727365469595118105965156896488865205692688474764862492197", "price": "0.427", "size": "440", "side": "BUY", "hash": "9d5df03cd47aa8628d74146f0a2eb68511a6d376", "best_bid": "0.976", "best_ask": "0.985"}, {"asset_id": "28097057395543402943370631962731762608572280065916543916317979666329718516169", "price": "0.573", "size": "440", "side": "SELL", "hash": "18dc76fbe292a14807fa2e51c6f9c80cbd078716", "best_bid": "0.015", "best_ask": "0.024"}], "timestamp": "1769384233193", "event_type": "price_change"}}
{"_local_timestamp": "2026-01-25T23:37:13.337814+00:00", "data": {"market": "0xa588a3f30682fa83bbc87034e24c9c0fe328435b8abcc390c653de2a51e2f229", "price_changes": [{"asset_id": "112539243967883746727727365469595118105965156896488865205692688474764862492197", "price": "0.446", "size": "10", "side": "BUY", "hash": "3fc9ae89351e3bfa9e0c654ce37b6456c2adc54e", "best_bid": "0.976", "best_ask": "0.985"}, {"asset_id": "28097057395543402943370631962731762608572280065916543916317979666329718516169", "price": "0.554", "size": "10", "side": "SELL", "hash": "c83bd2792d2e2489b67abc824507023f63ef1200", "best_bid": "0.015", "best_ask": "0.024"}], "timestamp": "1769384233266", "event_type": "price_change"}}
{"_local_timestamp": "2026-01-25T23:37:13.338533+00:00", "data": {"market": "0xa588a3f30682fa83bbc87034e24c9c0fe328435b8abcc390c653de2a51e2f229", "price_changes": [{"asset_id": "112539243967883746727727365469595118105965156896488865205692688474764862492197", "price": "0.445", "size": "244", "side": "BUY", "hash": "902a0d4ea3d0e92283cd5831b3c1e115cf0ac899", "best_bid": "0.976", "best_ask": "0.985"}, {"asset_id": "28097057395543402943370631962731762608572280065916543916317979666329718516169", "price": "0.555", "size": "244", "side": "SELL", "hash": "f386eca9c0ae13ec8adaeb07bd29344377a4e0f6", "best_bid": "0.015", "best_ask": "0.024"}], "timestamp": "1769384233267", "event_type": "price_change"}}
{"_local_timestamp": "2026-01-25T23:37:13.344946+00:00", "data": {"market": "0xa588a3f30682fa83bbc87034e24c9c0fe328435b8abcc390c653de2a51e2f229", "price_changes": [{"asset_id": "112539243967883746727727365469595118105965156896488865205692688474764862492197", "price": "0.446", "size": "25", "side": "BUY", "hash": "b8f12963b71937165e0d5977684fccc4e5be4804", "best_bid": "0.976", "best_ask": "0.985"}, {"asset_id": "28097057395543402943370631962731762608572280065916543916317979666329718516169", "price": "0.554", "size": "25", "side": "SELL", "hash": "1caed4c743c16e8a23976a44aab9b2af4a47ab3e", "best_bid": "0.015", "best_ask": "0.024"}], "timestamp": "1769384233268", "event_type": "price_change"}}
{"_local_timestamp": "2026-01-25T23:37:13.345612+00:00", "data": {"market": "0x81d603fe35c07415741bb9007bead4cdbddeb80fb35d5c9b6573eae9ee39fc1f", "price_changes": [{"asset_id": "87568880774573784875060327448344352870458352367065142953649333272451455443517", "price": "0.45", "size": "10", "side": "BUY", "hash": "f3006022e725a5dc787746ce9e88a5b5134885e5", "best_bid": "0.82", "best_ask": "0.86"}, {"asset_id": "84046462467623575651564609695680328259011367863582645244986900444709317782077", "price": "0.55", "size": "10", "side": "SELL", "hash": "71672efb2f1fc895bed003a595a797d612953ed6", "best_bid": "0.14", "best_ask": "0.18"}], "timestamp": "1769384233278", "event_type": "price_change"}}
{"_local_timestamp": "2026-01-25T23:37:13.432170+00:00", "data": {"market": "0xa588a3f30682fa83bbc87034e24c9c0fe328435b8abcc390c653de2a51e2f229", "price_changes": [{"asset_id": "112539243967883746727727365469595118105965156896488865205692688474764862492197", "price": "0.427", "size": "253", "side": "BUY", "hash": "52997d8d139697bec682eb377e1e65844cfadac1", "best_bid": "0.976", "best_ask": "0.985"}, {"asset_id": "28097057395543402943370631962731762608572280065916543916317979666329718516169", "price": "0.573", "size": "253", "side": "SELL", "hash": "e476364e28ce0883e31b3982e79b35255cee27b4", "best_bid": "0.015", "best_ask": "0.024"}], "timestamp": "1769384233364", "event_type": "price_change"}}
{"_local_timestamp": "2026-01-25T23:37:13.440902+00:00", "data": {"market": "0xa588a3f30682fa83bbc87034e24c9c0fe328435b8abcc390c653de2a51e2f229", "price_changes": [{"asset_id": "112539243967883746727727365469595118105965156896488865205692688474764862492197", "price": "0.427", "size": "60", "side": "BUY", "hash": "3e44133c7927c44c0f05b1b1f28be43e7bc40dc2", "best_bid": "0.976", "best_ask": "0.985"}, {"asset_id": "28097057395543402943370631962731762608572280065916543916317979666329718516169", "price": "0.573", "size": "60", "side": "SELL", "hash": "bcad8e8d679a90b2efd2cc8339f3a86a7c09b379", "best_bid": "0.015", "best_ask": "0.024"}], "timestamp": "1769384233366", "event_type": "price_change"}}
{"_local_timestamp": "2026-01-25T23:37:13.475908+00:00", "data": {"market": "0x6d08ed1eadd870cd00c92048dda2fe06650e15905f8828ddf15e4d2186898029", "price_changes": [{"asset_id": "9876264386649584456256217467156428648140707909529649867285151715292859513583", "price": "0.12", "size": "125", "side": "BUY", "hash": "2331971c746ec4616a976a1d2feaa79050147734", "best_bid": "0.63", "best_ask": "0.75"}, {"asset_id": "16774186999359636680352173816986047997138878170738869842466593332514752926314", "price": "0.88", "size": "125", "side": "SELL", "hash": "e5dd0ff45f90f0ab6570e9f03b81b43f2e8e4185", "best_bid": "0.25", "best_ask": "0.37"}], "timestamp": "1769384233367", "event_type": "price_change"}}
{"_local_timestamp": "2026-01-25T23:37:13.550638+00:00", "data": {"market": "0x2454c412d48443a73e15d93ae01e20caefd5d64a3865b67bc0a465fdac459c77", "price_changes": [{"asset_id": "21604618649648179239165697042911952381335935480672188760475095094501424754919", "price": "0.19", "size": "1239", "side": "BUY", "hash": "179f2728bbb9e9fbc705ad8eb1f6cc2a912364f9", "best_bid": "0.9", "best_ask": "0.94"}, {"asset_id": "46091239361932142478682480948008873970191467150785110396994502723691495289956", "price": "0.81", "size": "1239", "side": "SELL", "hash": "f5e500dcdd4c8c4f8d3c8582ba3835545a16aa34", "best_bid": "0.06", "best_ask": "0.1"}], "timestamp": "1769384233387", "event_type": "price_change"}}
{"_local_timestamp": "2026-01-25T23:37:13.569378+00:00", "data": {"market": "0x2454c412d48443a73e15d93ae01e20caefd5d64a3865b67bc0a465fdac459c77", "price_changes": [{"asset_id": "21604618649648179239165697042911952381335935480672188760475095094501424754919", "price": "0.25", "size": "150", "side": "BUY", "hash": "f5daff24c54f929a71025c4cad82164b20acd894", "best_bid": "0.9", "best_ask": "0.94"}, {"asset_id": "46091239361932142478682480948008873970191467150785110396994502723691495289956", "price": "0.75", "size": "150", "side": "SELL", "hash": "3a950f29631db82e7426f1ded0a8ffd8d557d4a4", "best_bid": "0.06", "best_ask": "0.1"}], "timestamp": "1769384233411", "event_type": "price_change"}}
{"_local_timestamp": "2026-01-25T23:37:13.617596+00:00", "data": {"market": "0xa588a3f30682fa83bbc87034e24c9c0fe328435b8abcc390c653de2a51e2f229", "price_changes": [{"asset_id": "112539243967883746727727365469595118105965156896488865205692688474764862492197", "price": "0.445", "size": "457", "side": "BUY", "hash": "99541c7e49c4dab29eca2ee2c250764facc40eae", "best_bid": "0.976", "best_ask": "0.985"}, {"asset_id": "28097057395543402943370631962731762608572280065916543916317979666329718516169", "price": "0.555", "size": "457", "side": "SELL", "hash": "aa8c767f5e8b7e00692d39de77ef92e31b21d9dd", "best_bid": "0.015", "best_ask": "0.024"}], "timestamp": "1769384233523", "event_type": "price_change"}}
{"_local_timestamp": "2026-01-25T23:37:13.630148+00:00", "data": {"market": "0xa588a3f30682fa83bbc87034e24c9c0fe328435b8abcc390c653de2a51e2f229", "price_changes": [{"asset_id": "112539243967883746727727365469595118105965156896488865205692688474764862492197", "price": "0.445", "size": "677", "side": "BUY", "hash": "81b4e93bf4e6ff1e0777a5124a476b81c1c2de4d", "best_bid": "0.976", "best_ask": "0.985"}, {"asset_id": "28097057395543402943370631962731762608572280065916543916317979666329718516169", "price": "0.555", "size": "677", "side": "SELL", "hash": "2bcfae49bf5586724f9b8bdb6fcda63b97113ce9", "best_bid": "0.015", "best_ask": "0.024"}], "timestamp": "1769384233560", "event_type": "price_change"}}
{"_local_timestamp": "2026-01-25T23:37:14.381720+00:00", "data": {"market": "0x81d603fe35c07415741bb9007bead4cdbddeb80fb35d5c9b6573eae9ee39fc1f", "price_changes": [{"asset_id": "87568880774573784875060327448344352870458352367065142953649333272451455443517", "price": "0.44", "size": "0", "side": "BUY", "hash": "597389dad089915bbfc6b14297f225e8129cb68c", "best_bid": "0.82", "best_ask": "0.86"}, {"asset_id": "84046462467623575651564609695680328259011367863582645244986900444709317782077", "price": "0.56", "size": "0", "side": "SELL", "hash": "c09bdd4e86cc9a4fe61e035ee50fa947e0e77c80", "best_bid": "0.14", "best_ask": "0.18"}], "timestamp": "1769384234307", "event_type": "price_change"}}
{"_local_timestamp": "2026-01-25T23:37:14.382318+00:00", "data": {"market": "0xa588a3f30682fa83bbc87034e24c9c0fe328435b8abcc390c653de2a51e2f229", "price_changes": [{"asset_id": "112539243967883746727727365469595118105965156896488865205692688474764862492197", "price": "0.445", "size": "657", "side": "BUY", "hash": "fbf4c2ce6e865d5d4d83707c67d35557dd9dcd61", "best_bid": "0.976", "best_ask": "0.985"}, {"asset_id": "28097057395543402943370631962731762608572280065916543916317979666329718516169", "price": "0.555", "size": "657", "side": "SELL", "hash": "bc24dbbc5e0cb58ddc0fa456ec7f6b746d026fc4", "best_bid": "0.015", "best_ask": "0.024"}], "timestamp": "1769384234307", "event_type": "price_change"}}
{"_local_timestamp": "2026-01-25T23:37:14.411099+00:00", "data": {"market": "0xa588a3f30682fa83bbc87034e24c9c0fe328435b8abcc390c653de2a51e2f229", "price_changes": [{"asset_id": "112539243967883746727727365469595118105965156896488865205692688474764862492197", "price": "0.447", "size": "20", "side": "BUY", "hash": "55f9ebefc325fc18e0503cdc8c35aac6bee2b0b7", "best_bid": "0.976", "best_ask": "0.985"}, {"asset_id": "28097057395543402943370631962731762608572280065916543916317979666329718516169", "price": "0.553", "size": "20", "side": "SELL", "hash": "4f1221a503759ebb31e3e12b56dd5a16a9cb7192", "best_bid": "0.015", "best_ask": "0.024"}], "timestamp": "1769384234338", "event_type": "price_change"}}
{"_local_timestamp": "2026-01-25T23:37:14.411743+00:00", "data": {"market": "0x81d603fe35c07415741bb9007bead4cdbddeb80fb35d5c9b6573eae9ee39fc1f", "price_changes": [{"asset_id": "87568880774573784875060327448344352870458352367065142953649333272451455443517", "price": "0.46", "size": "20", "side": "BUY", "hash": "2792b6757373df1557c09364cf7a5e559dd7eac2", "best_bid": "0.82", "best_ask": "0.86"}, {"asset_id": "84046462467623575651564609695680328259011367863582645244986900444709317782077", "price": "0.54", "size": "20", "side": "SELL", "hash": "0be38f0d0913a71d0008d98694489cd475c6a61a", "best_bid": "0.14", "best_ask": "0.18"}], "timestamp": "1769384234338", "event_type": "price_change"}}
{"_local_timestamp": "2026-01-25T23:37:32.617523+00:00", "data": {"market": "0x7ec88c27625388fe4de5c1e083da56806973aae7257bd0b3b2c2790937c89433", "price_changes": [{"asset_id": "11439216096927556294398061349600841087621436733892133369767994197102929396058", "price": "0.1", "size": "600", "side": "BUY", "hash": "5839fd7d5764132e8321c4f8d3edaf6ff0435995", "best_bid": "0.55", "best_ask": "0.79"}, {"asset_id": "93612868481313996119669919082030267547888020881923568220735661390829838620299", "price": "0.9", "size": "600", "side": "SELL", "hash": "007597576960abd8929de76700dd0ada35bcc3aa", "best_bid": "0.21", "best_ask": "0.45"}], "timestamp": "1769384252538", "event_type": "price_change"}}
{"_local_timestamp": "2026-01-25T23:37:40.663205+00:00", "data": {"market": "0x7ec88c27625388fe4de5c1e083da56806973aae7257bd0b3b2c2790937c89433", "price_changes": [{"asset_id": "11439216096927556294398061349600841087621436733892133369767994197102929396058", "price": "0.79", "size": "107", "side": "SELL", "hash": "a67289b77328a6e61e5084724eb5e44fdbd95685", "best_bid": "0.55", "best_ask": "0.79"}, {"asset_id": "93612868481313996119669919082030267547888020881923568220735661390829838620299", "price": "0.21", "size": "107", "side": "BUY", "hash": "64267d1e8921b7dc1767cf4c110b4424079ee991", "best_bid": "0.21", "best_ask": "0.45"}], "timestamp": "1769384260510", "event_type": "price_change"}}
{"_local_timestamp": "2026-01-25T23:37:40.844988+00:00", "data": {"market": "0x33c890cbc6edeb7ce360351a288ec411b3f9a5282667e3bf18a3051c4767428c", "price_changes": [{"asset_id": "113516997583046187201046242649428977289438194581672050007909348202973938222410", "price": "0.454", "size": "177", "side": "BUY", "hash": "195eaea5dc11dd49edca253de046c010fc639273", "best_bid": "0.96", "best_ask": "0.99"}, {"asset_id": "51241971381574011156532505117739358478718782528207416160352857296343207110308", "price": "0.546", "size": "177", "side": "SELL", "hash": "584875ea283535891c88b8f4982e956f4d2a577e", "best_bid": "0.01", "best_ask": "0.04"}], "timestamp": "1769384260729", "event_type": "price_change"}}
{"_local_timestamp": "2026-01-25T23:37:40.861490+00:00", "data": {"market": "0x33c890cbc6edeb7ce360351a288ec411b3f9a5282667e3bf18a3051c4767428c", "price_changes": [{"asset_id": "113516997583046187201046242649428977289438194581672050007909348202973938222410", "price": "0.454", "size": "100", "side": "BUY", "hash": "74b01a3e609eef7bc279e67ef3a342b825c09439", "best_bid": "0.96", "best_ask": "0.99"}, {"asset_id": "51241971381574011156532505117739358478718782528207416160352857296343207110308", "price": "0.546", "size": "100", "side": "SELL", "hash": "8e95989aba6015977505f699b40b3a71a92b1cb0", "best_bid": "0.01", "best_ask": "0.04"}], "timestamp": "1769384260753", "event_type": "price_change"}}
{"_local_timestamp": "2026-01-25T23:37:40.978096+00:00", "data": {"market": "0x33c890cbc6edeb7ce360351a288ec411b3f9a5282667e3bf18a3051c4767428c", "price_changes": [{"asset_id": "113516997583046187201046242649428977289438194581672050007909348202973938222410", "price": "0.455", "size": "420", "side": "BUY", "hash": "b0df4fd350d5556ea3e8b3d0d2d76e8671511183", "best_bid": "0.96", "best_ask": "0.99"}, {"asset_id": "51241971381574011156532505117739358478718782528207416160352857296343207110308", "price": "0.545", "size": "420", "side": "SELL", "hash": "9db2a2a1ab298e3911f84d7be061bd561670ea73", "best_bid": "0.01", "best_ask": "0.04"}], "timestamp": "1769384260868", "event_type": "price_change"}}
{"_local_timestamp": "2026-01-25T23:37:41.063277+00:00", "data": {"market": "0x33c890cbc6edeb7ce360351a288ec411b3f9a5282667e3bf18a3051c4767428c", "price_changes": [{"asset_id": "113516997583046187201046242649428977289438194581672050007909348202973938222410", "price": "0.455", "size": "484", "side": "BUY", "hash": "c2d6b15bcd711091c5c0fdc2ae16d3b05caeee30", "best_bid": "0.96", "best_ask": "0.99"}, {"asset_id": "51241971381574011156532505117739358478718782528207416160352857296343207110308", "price": "0.545", "size": "484", "side": "SELL", "hash": "4fcc50cc0598a62115c209ce70db093080fa0897", "best_bid": "0.01", "best_ask": "0.04"}], "timestamp": "1769384260956", "event_type": "price_change"}}
{"_local_timestamp": "2026-01-25T23:37:49.431552+00:00", "data": {"market": "0x7ec88c27625388fe4de5c1e083da56806973aae7257bd0b3b2c2790937c89433", "price_changes": [{"asset_id": "11439216096927556294398061349600841087621436733892133369767994197102929396058", "price": "0.17", "size": "125", "side": "BUY", "hash": "0d89e28fff73d76eaa455bb40eb9f8adf10e39b8", "best_bid": "0.55", "best_ask": "0.79"}, {"asset_id": "93612868481313996119669919082030267547888020881923568220735661390829838620299", "price": "0.83", "size": "125", "side": "SELL", "hash": "ed70e9e946173cc53739e3a1281a41e0f846c14d", "best_bid": "0.21", "best_ask": "0.45"}], "timestamp": "1769384269323", "event_type": "price_change"}}
{"_local_timestamp": "2026-01-25T23:37:49.432226+00:00", "data": {"market": "0x33c890cbc6edeb7ce360351a288ec411b3f9a5282667e3bf18a3051c4767428c", "price_changes": [{"asset_id": "113516997583046187201046242649428977289438194581672050007909348202973938222410", "price": "0.186", "size": "234", "side": "BUY", "hash": "28467d888bf2fd894e219c1b16d043aedf3b705f", "best_bid": "0.96", "best_ask": "0.99"}, {"asset_id": "51241971381574011156532505117739358478718782528207416160352857296343207110308", "price": "0.814", "size": "234", "side": "SELL", "hash": "ca5f14eccc5e56ce14b1f754c018a80c2ffb3050", "best_bid": "0.01", "best_ask": "0.04"}], "timestamp": "1769384269323", "event_type": "price_change"}}
{"_local_timestamp": "2026-01-25T23:37:49.432805+00:00", "data": {"market": "0x6d08ed1eadd870cd00c92048dda2fe06650e15905f8828ddf15e4d2186898029", "price_changes": [{"asset_id": "9876264386649584456256217467156428648140707909529649867285151715292859513583", "price": "0.17", "size": "125", "side": "BUY", "hash": "c601ccdd5f147ed628292930db7d7cacda3b3399", "best_bid": "0.63", "best_ask": "0.75"}, {"asset_id": "16774186999359636680352173816986047997138878170738869842466593332514752926314", "price": "0.83", "size": "125", "side": "SELL", "hash": "c2f351e6324eefc1a6e02bdb4c70c6c09c4a814f", "best_bid": "0.25", "best_ask": "0.37"}], "timestamp": "1769384269323", "event_type": "price_change"}}
{"_local_timestamp": "2026-01-25T23:37:59.525223+00:00", "data": {"market": "0x451f95b559f965cb15fae084ca33138c3dff9900e1ffcfa4f26d8ccb973985f9", "price_changes": [{"asset_id": "71388232310046462701125421464348156348289990693959124855529169704375434690368", "price": "0.068", "size": "0", "side": "SELL", "hash": "a6ad60eb09f5813a763d5e27606039aaa5a20483", "best_bid": "0.019", "best_ask": "0.04"}, {"asset_id": "38348899529497747452710765412992322349016518493953479463643011128224089778563", "price": "0.932", "size": "0", "side": "BUY", "hash": "594089dcdd830ca56602dd4da6afe04a9412a711", "best_bid": "0.96", "best_ask": "0.981"}], "timestamp": "1769384279417", "event_type": "price_change"}}
{"_local_timestamp": "2026-01-25T23:37:59.551555+00:00", "data": {"market": "0x451f95b559f965cb15fae084ca33138c3dff9900e1ffcfa4f26d8ccb973985f9", "price_changes": [{"asset_id": "71388232310046462701125421464348156348289990693959124855529169704375434690368", "price": "0.068", "size": "50", "side": "SELL", "hash": "841965027d4e5fce375bc914d31e541f8ff614e8", "best_bid": "0.019", "best_ask": "0.04"}, {"asset_id": "38348899529497747452710765412992322349016518493953479463643011128224089778563", "price": "0.932", "size": "50", "side": "BUY", "hash": "70b9b3f1a95ed981daeb0cf55a15a162910c517b", "best_bid": "0.96", "best_ask": "0.981"}], "timestamp": "1769384279448", "event_type": "price_change"}}
{"_local_timestamp": "2026-01-25T23:38:17.080784+00:00", "data": {"market": "0xbb676d25a7ce355a3a10fa2bfbee5cb7b6b2ee36581ada7914d73ad78bedf62d", "price_changes": [{"asset_id": "10980869689964921227047480431023635246637317983901031741233635278193625249458", "price": "0.91", "size": "855", "side": "BUY", "hash": "3b935bd831738ac502df8c35397320c8f02518f4", "best_bid": "0.92", "best_ask": "0.94"}, {"asset_id": "68913153540574314749415284055691780290306094084209478229942172031873972067947", "price": "0.09", "size": "855", "side": "SELL", "hash": "6198f90f411e4b57fa43c4dbb3ade87027d9a6ea", "best_bid": "0.06", "best_ask": "0.08"}], "timestamp": "1769384297001", "event_type": "price_change"}}
{"_local_timestamp": "2026-01-25T23:38:17.081667+00:00", "data": {"market": "0xbb676d25a7ce355a3a10fa2bfbee5cb7b6b2ee36581ada7914d73ad78bedf62d", "price_changes": [{"asset_id": "68913153540574314749415284055691780290306094084209478229942172031873972067947", "price": "0.04", "size": "500", "side": "BUY", "hash": "70a5a1f09c937a8171997d4ac0e7b3b6b6272a6d", "best_bid": "0.06", "best_ask": "0.08"}, {"asset_id": "10980869689964921227047480431023635246637317983901031741233635278193625249458", "price": "0.96", "size": "500", "side": "SELL", "hash": "1efb2f1bebe23e85ac2db692a5eaf85f6c5b50a4", "best_bid": "0.92", "best_ask": "0.94"}], "timestamp": "1769384297002", "event_type": "price_change"}}
{"_local_timestamp": "2026-01-25T23:38:17.217907+00:00", "data": {"market": "0xa588a3f30682fa83bbc87034e24c9c0fe328435b8abcc390c653de2a51e2f229", "price_changes": [{"asset_id": "112539243967883746727727365469595118105965156896488865205692688474764862492197", "price": "0.44", "size": "0", "side": "BUY", "hash": "fda9123e979915686c5fe61940a7268e710d1f7e", "best_bid": "0.976", "best_ask": "0.985"}, {"asset_id": "28097057395543402943370631962731762608572280065916543916317979666329718516169", "price": "0.56", "size": "0", "side": "SELL", "hash": "3677f92482fcf79db7d48f0d44533c30190d0db8", "best_bid": "0.015", "best_ask": "0.024"}], "timestamp": "1769384297148", "event_type": "price_change"}}
{"_local_timestamp": "2026-01-25T23:38:17.255568+00:00", "data": {"market": "0xa588a3f30682fa83bbc87034e24c9c0fe328435b8abcc390c653de2a51e2f229", "price_changes": [{"asset_id": "112539243967883746727727365469595118105965156896488865205692688474764862492197", "price": "0.448", "size": "30", "side": "BUY", "hash": "f235edefba00aeeafa6c127e9812b77f78f7ad05", "best_bid": "0.976", "best_ask": "0.985"}, {"asset_id": "28097057395543402943370631962731762608572280065916543916317979666329718516169", "price": "0.552", "size": "30", "side": "SELL", "hash": "cc1eeaea52daf569ae5ed77472991a5eb1d4b702", "best_bid": "0.015", "best_ask": "0.024"}], "timestamp": "1769384297184", "event_type": "price_change"}}
{"_local_timestamp": "2026-01-25T23:38:19.840185+00:00", "data": {"market": "0xa588a3f30682fa83bbc87034e24c9c0fe328435b8abcc390c653de2a51e2f229", "price_changes": [{"asset_id": "112539243967883746727727365469595118105965156896488865205692688474764862492197", "price": "0.447", "size": "0", "side": "BUY", "hash": "9c32181fa7abeca38016214b68353fee9dd8cb4e", "best_bid": "0.976", "best_ask": "0.985"}, {"asset_id": "28097057395543402943370631962731762608572280065916543916317979666329718516169", "price": "0.553", "size": "0", "side": "SELL", "hash": "bf52c180d7aedab7ae80e1cf804bb515f5895d85", "best_bid": "0.015", "best_ask": "0.024"}], "timestamp": "1769384299773", "event_type": "price_change"}}
{"_local_timestamp": "2026-01-25T23:38:19.875587+00:00", "data": {"market": "0xa588a3f30682fa83bbc87034e24c9c0fe328435b8abcc390c653de2a51e2f229", "price_changes": [{"asset_id": "112539243967883746727727365469595118105965156896488865205692688474764862492197", "price": "0.449", "size": "20", "side": "BUY", "hash": "9eaf719857ca509e17b033b880a8b472251e5249", "best_bid": "0.976", "best_ask": "0.985"}, {"asset_id": "28097057395543402943370631962731762608572280065916543916317979666329718516169", "price": "0.551", "size": "20", "side": "SELL", "hash": "58118e053e972f7744a11855e4ae051405e74e63", "best_bid": "0.015", "best_ask": "0.024"}], "timestamp": "1769384299803", "event_type": "price_change"}}
{"_local_timestamp": "2026-01-25T23:38:19.943545+00:00", "data": {"market": "0x33c890cbc6edeb7ce360351a288ec411b3f9a5282667e3bf18a3051c4767428c", "price_changes": [{"asset_id": "113516997583046187201046242649428977289438194581672050007909348202973938222410", "price": "0.681", "size": "10", "side": "BUY", "hash": "5022ddccf45df41b1df6d260170777bde393077c", "best_bid": "0.96", "best_ask": "0.99"}, {"asset_id": "51241971381574011156532505117739358478718782528207416160352857296343207110308", "price": "0.319", "size": "10", "side": "SELL", "hash": "98a8065d2a300daba18cb36ccc0526cfbb67d708", "best_bid": "0.01", "best_ask": "0.04"}], "timestamp": "1769384299876", "event_type": "price_change"}}
{"_local_timestamp": "2026-01-25T23:38:58.298108+00:00", "data": {"market": "0x6d08ed1eadd870cd00c92048dda2fe06650e15905f8828ddf15e4d2186898029", "price_changes": [{"asset_id": "9876264386649584456256217467156428648140707909529649867285151715292859513583", "price": "0.12", "size": "0", "side": "BUY", "hash": "57638e64224b2650c8dce95f799996e2925fee51", "best_bid": "0.63", "best_ask": "0.75"}, {"asset_id": "16774186999359636680352173816986047997138878170738869842466593332514752926314", "price": "0.88", "size": "0", "side": "SELL", "hash": "3bd842d0f0c98e655d313d8ec1c68d5659947c16", "best_bid": "0.25", "best_ask": "0.37"}], "timestamp": "1769384338206", "event_type": "price_change"}}
{"_local_timestamp": "2026-01-25T23:38:58.524941+00:00", "data": {"market": "0xbb676d25a7ce355a3a10fa2bfbee5cb7b6b2ee36581ada7914d73ad78bedf62d", "price_changes": [{"asset_id": "10980869689964921227047480431023635246637317983901031741233635278193625249458", "price": "0.4", "size": "0", "side": "BUY", "hash": "ad2ef850aac4c0fecd02010eff86be403fd1bb0c", "best_bid": "0.92", "best_ask": "0.94"}, {"asset_id": "68913153540574314749415284055691780290306094084209478229942172031873972067947", "price": "0.6", "size": "0", "side": "SELL", "hash": "095baddc0f8c3b410e1e76a4455860655bf1c0d5", "best_bid": "0.06", "best_ask": "0.08"}], "timestamp": "1769384338284", "event_type": "price_change"}}
{"_local_timestamp": "2026-01-25T23:38:58.525612+00:00", "data": {"market": "0x33c890cbc6edeb7ce360351a288ec411b3f9a5282667e3bf18a3051c4767428c", "price_changes": [{"asset_id": "113516997583046187201046242649428977289438194581672050007909348202973938222410", "price": "0.675", "size": "0", "side": "BUY", "hash": "e3255101e909852681b098b19cc89b829e12434e", "best_bid": "0.96", "best_ask": "0.99"}, {"asset_id": "51241971381574011156532505117739358478718782528207416160352857296343207110308", "price": "0.325", "size": "0", "side": "SELL", "hash": "502ec0dfd8de0f17d8036b5cdb9fe347e89892f2", "best_bid": "0.01", "best_ask": "0.04"}], "timestamp": "1769384338284", "event_type": "price_change"}}
{"_local_timestamp": "2026-01-25T23:38:58.526187+00:00", "data": {"market": "0x7ec88c27625388fe4de5c1e083da56806973aae7257bd0b3b2c2790937c89433", "price_changes": [{"asset_id": "11439216096927556294398061349600841087621436733892133369767994197102929396058", "price": "0.3", "size": "0", "side": "BUY", "hash": "0966b850c490dd7db55e869a69d7f77497f8c974", "best_bid": "0.55", "best_ask": "0.79"}, {"asset_id": "93612868481313996119669919082030267547888020881923568220735661390829838620299", "price": "0.7", "size": "0", "side": "SELL", "hash": "35e34cf6bbafe0608942f761eaa6caad8ab7f015", "best_bid": "0.21", "best_ask": "0.45"}], "timestamp": "1769384338284", "event_type": "price_change"}}
{"_local_timestamp": "2026-01-25T23:38:58.526749+00:00", "data": {"market": "0x451f95b559f965cb15fae084ca33138c3dff9900e1ffcfa4f26d8ccb973985f9", "price_changes": [{"asset_id": "38348899529497747452710765412992322349016518493953479463643011128224089778563", "price": "0.529", "size": "0", "side": "BUY", "hash": "f97cb9bc2e07a3381bd37b8cc2b8869f18ddd17f", "best_bid": "0.96", "best_ask": "0.981"}, {"asset_id": "71388232310046462701125421464348156348289990693959124855529169704375434690368", "price": "0.471", "size": "0", "side": "SELL", "hash": "7c35f3684e64779e07c04837e98f3db8c8619a0e", "best_bid": "0.019", "best_ask": "0.04"}], "timestamp": "1769384338284", "event_type": "price_change"}}
{"_local_timestamp": "2026-01-25T23:38:58.654339+00:00", "data": {"market": "0x33c890cbc6edeb7ce360351a288ec411b3f9a5282667e3bf18a3051c4767428c", "price_changes": [{"asset_id": "113516997583046187201046242649428977289438194581672050007909348202973938222410", "price": "0.681", "size": "0", "side": "BUY", "hash": "3d0858e27416e0078db0ad2c43e594b6432691aa", "best_bid": "0.96", "best_ask": "0.99"}, {"asset_id": "51241971381574011156532505117739358478718782528207416160352857296343207110308", "price": "0.319", "size": "0", "side": "SELL", "hash": "d6e87a615b53b5fbb230bd01434b89fd89072506", "best_bid": "0.01", "best_ask": "0.04"}], "timestamp": "1769384338504", "event_type": "price_change"}}
{"_local_timestamp": "2026-01-25T23:38:58.657094+00:00", "data": {"market": "0xd8aa928c90a14d70ede48f27543293c03ef8305420105518c3349f993e8fb4b4", "price_changes": [{"asset_id": "35918899905695997492070645194236546618834009355694722884958363910402437678512", "price": "0.267", "size": "0", "side": "BUY", "hash": "c8e2995c46a007d4cd381ec6355afe4bee6f3a48", "best_bid": "0.971", "best_ask": "0.978"}, {"asset_id": "9376678867812664753044653742290850239117727272721528310663723279807470231308", "price": "0.733", "size": "0", "side": "SELL", "hash": "58763f737b571e398533ba34ff7f762495283086", "best_bid": "0.022", "best_ask": "0.029"}], "timestamp": "1769384338505", "event_type": "price_change"}}
{"_local_timestamp": "2026-01-25T23:38:58.663301+00:00", "data": {"market": "0xbb676d25a7ce355a3a10fa2bfbee5cb7b6b2ee36581ada7914d73ad78bedf62d", "price_changes": [{"asset_id": "10980869689964921227047480431023635246637317983901031741233635278193625249458", "price": "0.67", "size": "70", "side": "BUY", "hash": "a1a21600cea88797f432b2830d2ea3df71350e66", "best_bid": "0.92", "best_ask": "0.94"}, {"asset_id": "68913153540574314749415284055691780290306094084209478229942172031873972067947", "price": "0.33", "size": "70", "side": "SELL", "hash": "e9bd9ed22a298a96acad4e72a9b4166aaaf09c67", "best_bid": "0.06", "best_ask": "0.08"}], "timestamp": "1769384338527", "event_type": "price_change"}}
{"_local_timestamp": "2026-01-25T23:38:58.663920+00:00", "data": {"market": "0x7ec88c27625388fe4de5c1e083da56806973aae7257bd0b3b2c2790937c89433", "price_changes": [{"asset_id": "11439216096927556294398061349600841087621436733892133369767994197102929396058", "price": "0.33", "size": "10", "side": "BUY", "hash": "031532c926c5682271e798d24a00b97e418bea78", "best_bid": "0.55", "best_ask": "0.79"}, {"asset_id": "93612868481313996119669919082030267547888020881923568220735661390829838620299", "price": "0.67", "size": "10", "side": "SELL", "hash": "ef1c056af79ac02d5256810e6d14de993ca16f7c", "best_bid": "0.21", "best_ask": "0.45"}], "timestamp": "1769384338528", "event_type": "price_change"}}
{"_local_timestamp": "2026-01-25T23:38:58.664507+00:00", "data": {"market": "0x451f95b559f965cb15fae084ca33138c3dff9900e1ffcfa4f26d8ccb973985f9", "price_changes": [{"asset_id": "38348899529497747452710765412992322349016518493953479463643011128224089778563", "price": "0.535", "size": "31", "side": "BUY", "hash": "fa0ec4cc268e24fe794c6e3b0d9babc6a6c9ff1f", "best_bid": "0.96", "best_ask": "0.981"}, {"asset_id": "71388232310046462701125421464348156348289990693959124855529169704375434690368", "price": "0.465", "size": "31", "side": "SELL", "hash": "acc2e8f612a42b3924e9959e3b693f1ce6b398ac", "best_bid": "0.019", "best_ask": "0.04"}], "timestamp": "1769384338528", "event_type": "price_change"}}
{"_local_timestamp": "2026-01-25T23:38:58.665086+00:00", "data": {"market": "0x33c890cbc6edeb7ce360351a288ec411b3f9a5282667e3bf18a3051c4767428c", "price_changes": [{"asset_id": "113516997583046187201046242649428977289438194581672050007909348202973938222410", "price": "0.683", "size": "10", "side": "BUY", "hash": "401df41e388548f887435fe7cfa1220875c75850", "best_bid": "0.96", "best_ask": "0.99"}, {"asset_id": "51241971381574011156532505117739358478718782528207416160352857296343207110308", "price": "0.317", "size": "10", "side": "SELL", "hash": "477c1f9c902d7f8b2b84d9daf4378b942da9bcb3", "best_bid": "0.01", "best_ask": "0.04"}], "timestamp": "1769384338528", "event_type": "price_change"}}
{"_local_timestamp": "2026-01-25T23:38:58.665699+00:00", "data": {"market": "0x451f95b559f965cb15fae084ca33138c3dff9900e1ffcfa4f26d8ccb973985f9", "price_changes": [{"asset_id": "38348899529497747452710765412992322349016518493953479463643011128224089778563", "price": "0.535", "size": "41", "side": "BUY", "hash": "c6865d07aabaf4c187482b3401f1db7121f0f763", "best_bid": "0.96", "best_ask": "0.981"}, {"asset_id": "71388232310046462701125421464348156348289990693959124855529169704375434690368", "price": "0.465", "size": "41", "side": "SELL", "hash": "a80691c391295cd9d29165f83693e76ed7c2e7fe", "best_bid": "0.019", "best_ask": "0.04"}], "timestamp": "1769384338530", "event_type": "price_change"}}
{"_local_timestamp": "2026-01-25T23:38:58.822430+00:00", "data": {"market": "0x6d08ed1eadd870cd00c92048dda2fe06650e15905f8828ddf15e4d2186898029", "price_changes": [{"asset_id": "9876264386649584456256217467156428648140707909529649867285151715292859513583", "price": "0.11", "size": "438", "side": "BUY", "hash": "a8d3193c92a3a514aac6ebc276689946b7959ba4", "best_bid": "0.63", "best_ask": "0.75"}, {"asset_id": "16774186999359636680352173816986047997138878170738869842466593332514752926314", "price": "0.89", "size": "438", "side": "SELL", "hash": "9f9be06af892f57c49545ba706cbcc7dcc6ce7fe", "best_bid": "0.25", "best_ask": "0.37"}], "timestamp": "1769384338646", "event_type": "price_change"}}
{"_local_timestamp": "2026-01-25T23:38:59.796598+00:00", "data": {"market": "0x451f95b559f965cb15fae084ca33138c3dff9900e1ffcfa4f26d8ccb973985f9", "price_changes": [{"asset_id": "38348899529497747452710765412992322349016518493953479463643011128224089778563", "price": "0.534", "size": "0", "side": "BUY", "hash": "ed8dd94469b8e3efbe736566e0b9b8514bd6048f", "best_bid": "0.96", "best_ask": "0.981"}, {"asset_id": "71388232310046462701125421464348156348289990693959124855529169704375434690368", "price": "0.466", "size": "0", "side": "SELL", "hash": "ca3561d2ab878e79db391a8c73ef8de114bf04f9", "best_bid": "0.019", "best_ask": "0.04"}], "timestamp": "1769384339730", "event_type": "price_change"}}
{"_local_timestamp": "2026-01-25T23:38:59.797372+00:00", "data": {"market": "0x33c890cbc6edeb7ce360351a288ec411b3f9a5282667e3bf18a3051c4767428c", "price_changes": [{"asset_id": "113516997583046187201046242649428977289438194581672050007909348202973938222410", "price": "0.682", "size": "0", "side": "BUY", "hash": "cb6f11a72df935f309600083defc9084185c2764", "best_bid": "0.96", "best_ask": "0.99"}, {"asset_id": "51241971381574011156532505117739358478718782528207416160352857296343207110308", "price": "0.318", "size": "0", "side": "SELL", "hash": "607a2e1a9e7ad33af2c77e2326ebd808d41c79a1", "best_bid": "0.01", "best_ask": "0.04"}], "timestamp": "1769384339730", "event_type": "price_change"}}
{"_local_timestamp": "2026-01-25T23:38:59.828276+00:00", "data": {"market": "0x33c890cbc6edeb7ce360351a288ec411b3f9a5282667e3bf18a3051c4767428c", "price_changes": [{"asset_id": "113516997583046187201046242649428977289438194581672050007909348202973938222410", "price": "0.684", "size": "20", "side": "BUY", "hash": "aef8c85a1361c5a31f7c05a3da176f59a01e2be6", "best_bid": "0.96", "best_ask": "0.99"}, {"asset_id": "51241971381574011156532505117739358478718782528207416160352857296343207110308", "price": "0.316", "size": "20", "side": "SELL", "hash": "ef45d0372dea5c205f347d4c3c91be290c97cc4e", "best_bid": "0.01", "best_ask": "0.04"}], "timestamp": "1769384339759", "event_type": "price_change"}}
{"_local_timestamp": "2026-01-25T23:38:59.829048+00:00", "data": {"market": "0x451f95b559f965cb15fae084ca33138c3dff9900e1ffcfa4f26d8ccb973985f9", "price_changes": [{"asset_id": "38348899529497747452710765412992322349016518493953479463643011128224089778563", "price": "0.536", "size": "20", "side": "BUY", "hash": "1d4657b92665332dacfb6b170df57fcc93d325ba", "best_bid": "0.96", "best_ask": "0.981"}, {"asset_id": "71388232310046462701125421464348156348289990693959124855529169704375434690368", "price": "0.464", "size": "20", "side": "SELL", "hash": "cec66b9b77cdae96b93c669cc439c55ce09a61d4", "best_bid": "0.019", "best_ask": "0.04"}], "timestamp": "1769384339759", "event_type": "price_change"}}
{"_local_timestamp": "2026-01-25T23:38:59.900276+00:00", "data": {"market": "0x451f95b559f965cb15fae084ca33138c3dff9900e1ffcfa4f26d8ccb973985f9", "price_changes": [{"asset_id": "38348899529497747452710765412992322349016518493953479463643011128224089778563", "price": "0.535", "size": "10", "side": "BUY", "hash": "cb65384107b8654316bc6d53d96221042396937e", "best_bid": "0.96", "best_ask": "0.981"}, {"asset_id": "71388232310046462701125421464348156348289990693959124855529169704375434690368", "price": "0.465", "size": "10", "side": "SELL", "hash": "de56d2ef92b85aa4c2ba7be22b055e64d3afade7", "best_bid": "0.019", "best_ask": "0.04"}], "timestamp": "1769384339826", "event_type": "price_change"}}
{"_local_timestamp": "2026-01-25T23:39:22.342562+00:00", "data": {"market": "0x7ec88c27625388fe4de5c1e083da56806973aae7257bd0b3b2c2790937c89433", "price_changes": [{"asset_id": "11439216096927556294398061349600841087621436733892133369767994197102929396058", "price": "0.16", "size": "0", "side": "BUY", "hash": "f49b69839f339f80cefb76ccf41c13f0cde7a6ad", "best_bid": "0.55", "best_ask": "0.79"}, {"asset_id": "93612868481313996119669919082030267547888020881923568220735661390829838620299", "price": "0.84", "size": "0", "side": "SELL", "hash": "81c739c11cf70b89d217a220e4cd78398f6a267a", "best_bid": "0.21", "best_ask": "0.45"}], "timestamp": "1769384362194", "event_type": "price_change"}}
{"_local_timestamp": "2026-01-25T23:39:22.343521+00:00", "data": {"market": "0x7ec88c27625388fe4de5c1e083da56806973aae7257bd0b3b2c2790937c89433", "price_changes": [{"asset_id": "11439216096927556294398061349600841087621436733892133369767994197102929396058", "price": "0.22", "size": "0", "side": "BUY", "hash": "f49b69839f339f80cefb76ccf41c13f0cde7a6ad", "best_bid": "0.55", "best_ask": "0.79"}, {"asset_id": "93612868481313996119669919082030267547888020881923568220735661390829838620299", "price": "0.78", "size": "0", "side": "SELL", "hash": "81c739c11cf70b89d217a220e4cd78398f6a267a", "best_bid": "0.21", "best_ask": "0.45"}], "timestamp": "1769384362194", "event_type": "price_change"}}
{"_local_timestamp": "2026-01-25T23:39:22.344272+00:00", "data": {"market": "0x7ec88c27625388fe4de5c1e083da56806973aae7257bd0b3b2c2790937c89433", "price_changes": [{"asset_id": "11439216096927556294398061349600841087621436733892133369767994197102929396058", "price": "0.15", "size": "966.66", "side": "BUY", "hash": "f49b69839f339f80cefb76ccf41c13f0cde7a6ad", "best_bid": "0.55", "best_ask": "0.79"}, {"asset_id": "93612868481313996119669919082030267547888020881923568220735661390829838620299", "price": "0.85", "size": "966.66", "side": "SELL", "hash": "81c739c11cf70b89d217a220e4cd78398f6a267a", "best_bid": "0.21", "best_ask": "0.45"}], "timestamp": "1769384362194", "event_type": "price_change"}}
{"_local_timestamp": "2026-01-25T23:39:22.344901+00:00", "data": {"market": "0x7ec88c27625388fe4de5c1e083da56806973aae7257bd0b3b2c2790937c89433", "price_changes": [{"asset_id": "11439216096927556294398061349600841087621436733892133369767994197102929396058", "price": "0.1", "size": "300", "side": "BUY", "hash": "f49b69839f339f80cefb76ccf41c13f0cde7a6ad", "best_bid": "0.55", "best_ask": "0.79"}, {"asset_id": "93612868481313996119669919082030267547888020881923568220735661390829838620299", "price": "0.9", "size": "300", "side": "SELL", "hash": "81c739c11cf70b89d217a220e4cd78398f6a267a", "best_bid": "0.21", "best_ask": "0.45"}], "timestamp": "1769384362194", "event_type": "price_change"}}
{"_local_timestamp": "2026-01-25T23:39:22.904712+00:00", "data": {"market": "0x2454c412d48443a73e15d93ae01e20caefd5d64a3865b67bc0a465fdac459c77", "price_changes": [{"asset_id": "21604618649648179239165697042911952381335935480672188760475095094501424754919", "price": "0.25", "size": "250", "side": "BUY", "hash": "e3bcd6713e5209053cb0ee0d8dbb37c523ca3715", "best_bid": "0.9", "best_ask": "0.94"}, {"asset_id": "46091239361932142478682480948008873970191467150785110396994502723691495289956", "price": "0.75", "size": "250", "side": "SELL", "hash": "3cd3ec69a47c232307af422ac4601fcbad8d8642", "best_bid": "0.06", "best_ask": "0.1"}], "timestamp": "1769384362713", "event_type": "price_change"}}
{"_local_timestamp": "2026-01-25T23:39:22.908853+00:00", "data": {"market": "0x2454c412d48443a73e15d93ae01e20caefd5d64a3865b67bc0a465fdac459c77", "price_changes": [{"asset_id": "21604618649648179239165697042911952381335935480672188760475095094501424754919", "price": "0.42", "size": "215", "side": "BUY", "hash": "ebd7d942a6db71e02724ed0572150074d2139197", "best_bid": "0.9", "best_ask": "0.94"}, {"asset_id": "46091239361932142478682480948008873970191467150785110396994502723691495289956", "price": "0.58", "size": "215", "side": "SELL", "hash": "794ed5b427c322bf72062c10be1bd683846c8442", "best_bid": "0.06", "best_ask": "0.1"}], "timestamp": "1769384362784", "event_type": "price_change"}}
{"_local_timestamp": "2026-01-25T23:39:23.020920+00:00", "data": {"market": "0x2454c412d48443a73e15d93ae01e20caefd5d64a3865b67bc0a465fdac459c77", "price_changes": [{"asset_id": "21604618649648179239165697042911952381335935480672188760475095094501424754919", "price": "0.19", "size": "1389", "side": "BUY", "hash": "97bfcd2795c7e4c6e23516f8d3a0c300f711e2d6", "best_bid": "0.9", "best_ask": "0.94"}, {"asset_id": "46091239361932142478682480948008873970191467150785110396994502723691495289956", "price": "0.81", "size": "1389", "side": "SELL", "hash": "c3c253189935fdf7c4128c52e7c38986506c607b", "best_bid": "0.06", "best_ask": "0.1"}], "timestamp": "1769384362786", "event_type": "price_change"}}
{"_local_timestamp": "2026-01-25T23:39:29.191989+00:00", "data": {"market": "0x81d603fe35c07415741bb9007bead4cdbddeb80fb35d5c9b6573eae9ee39fc1f", "price_changes": [{"asset_id": "84046462467623575651564609695680328259011367863582645244986900444709317782077", "price": "0.13", "size": "0", "side": "BUY", "hash": "6f5aabb25eb7dc9cc932ef498a0fd1ac8a3afe36", "best_bid": "0.14", "best_ask": "0.18"}, {"asset_id": "87568880774573784875060327448344352870458352367065142953649333272451455443517", "price": "0.87", "size": "0", "side": "SELL", "hash": "352e979d47c314b6638a5204876282b0bda3fae8", "best_bid": "0.82", "best_ask": "0.86"}], "timestamp": "1769384369112", "event_type": "price_change"}}
{"_local_timestamp": "2026-01-25T23:39:33.430537+00:00", "data": {"market": "0x81d603fe35c07415741bb9007bead4cdbddeb80fb35d5c9b6573eae9ee39fc1f", "price_changes": [{"asset_id": "87568880774573784875060327448344352870458352367065142953649333272451455443517", "price": "0.86", "size": "0", "side": "SELL", "hash": "30e5bd9a2a1afcab88a7d261cdce9e22665b2204", "best_bid": "0.82", "best_ask": "0.88"}, {"asset_id": "84046462467623575651564609695680328259011367863582645244986900444709317782077", "price": "0.14", "size": "0", "side": "BUY", "hash": "19bdbf52356a41138f131732a781f02b98d8aea0", "best_bid": "0.12", "best_ask": "0.18"}], "timestamp": "1769384373361", "event_type": "price_change"}}
{"_local_timestamp": "2026-01-25T23:39:33.519200+00:00", "data": {"market": "0xbb676d25a7ce355a3a10fa2bfbee5cb7b6b2ee36581ada7914d73ad78bedf62d", "price_changes": [{"asset_id": "10980869689964921227047480431023635246637317983901031741233635278193625249458", "price": "0.67", "size": "30", "side": "BUY", "hash": "f741af6fd192dc27ddb5d6489222a724cbf883bb", "best_bid": "0.92", "best_ask": "0.94"}, {"asset_id": "68913153540574314749415284055691780290306094084209478229942172031873972067947", "price": "0.33", "size": "30", "side": "SELL", "hash": "a84a5d3f27906dec280bb2653a11e38c0ca90ab2", "best_bid": "0.06", "best_ask": "0.08"}], "timestamp": "1769384373443", "event_type": "price_change"}}
{"_local_timestamp": "2026-01-25T23:39:33.524986+00:00", "data": {"market": "0xd8aa928c90a14d70ede48f27543293c03ef8305420105518c3349f993e8fb4b4", "price_changes": [{"asset_id": "35918899905695997492070645194236546618834009355694722884958363910402437678512", "price": "0.711", "size": "0", "side": "BUY", "hash": "f841f7e4ea77464a6c69919ad8374d90240349f5", "best_bid": "0.971", "best_ask": "0.978"}, {"asset_id": "9376678867812664753044653742290850239117727272721528310663723279807470231308", "price": "0.289", "size": "0", "side": "SELL", "hash": "7f10cb6eaf32874ac90a1d74a1018106800e1eed", "best_bid": "0.022", "best_ask": "0.029"}], "timestamp": "1769384373443", "event_type": "price_change"}}
{"_local_timestamp": "2026-01-25T23:39:33.586223+00:00", "data": {"market": "0x6d08ed1eadd870cd00c92048dda2fe06650e15905f8828ddf15e4d2186898029", "price_changes": [{"asset_id": "9876264386649584456256217467156428648140707909529649867285151715292859513583", "price": "0.47", "size": "20", "side": "BUY", "hash": "8135d8a131f2f2034100e4a62b52a1dc047e598a", "best_bid": "0.63", "best_ask": "0.75"}, {"asset_id": "16774186999359636680352173816986047997138878170738869842466593332514752926314", "price": "0.53", "size": "20", "side": "SELL", "hash": "afbbcc77dc1e1ee85a1060b9c06e7e0d87ae5354", "best_bid": "0.25", "best_ask": "0.37"}], "timestamp": "1769384373515", "event_type": "price_change"}}
{"_local_timestamp": "2026-01-25T23:39:33.587039+00:00", "data": {"market": "0xbb676d25a7ce355a3a10fa2bfbee5cb7b6b2ee36581ada7914d73ad78bedf62d", "price_changes": [{"asset_id": "10980869689964921227047480431023635246637317983901031741233635278193625249458", "price": "0.67", "size": "20", "side": "BUY", "hash": "fce9b4580d861514dde4717030c277434b79374b", "best_bid": "0.92", "best_ask": "0.94"}, {"asset_id": "68913153540574314749415284055691780290306094084209478229942172031873972067947", "price": "0.33", "size": "20", "side": "SELL", "hash": "b06db27d22e812ed4f2912ea8d6d3c7d967966a4", "best_bid": "0.06", "best_ask": "0.08"}], "timestamp": "1769384373515", "event_type": "price_change"}}
{"_local_timestamp": "2026-01-25T23:39:33.666133+00:00", "data": {"market": "0xbb676d25a7ce355a3a10fa2bfbee5cb7b6b2ee36581ada7914d73ad78bedf62d", "price_changes": [{"asset_id": "10980869689964921227047480431023635246637317983901031741233635278193625249458", "price": "0.66", "size": "115", "side": "BUY", "hash": "cf9bc25f32670a39e61ec2fbab350de5468badfd", "best_bid": "0.92", "best_ask": "0.94"}, {"asset_id": "68913153540574314749415284055691780290306094084209478229942172031873972067947", "price": "0.34", "size": "115", "side": "SELL", "hash": "5fceed969780c12b583b50869eb0828d03b247b4", "best_bid": "0.06", "best_ask": "0.08"}], "timestamp": "1769384373592", "event_type": "price_change"}}
{"_local_timestamp": "2026-01-25T23:39:33.666929+00:00", "data": {"market": "0xd8aa928c90a14d70ede48f27543293c03ef8305420105518c3349f993e8fb4b4", "price_changes": [{"asset_id": "35918899905695997492070645194236546618834009355694722884958363910402437678512", "price": "0.271", "size": "40", "side": "BUY", "hash": "bf5e70f7771b7a639ecadc3322153e8a3177fca8", "best_bid": "0.971", "best_ask": "0.978"}, {"asset_id": "9376678867812664753044653742290850239117727272721528310663723279807470231308", "price": "0.729", "size": "40", "side": "SELL", "hash": "ec6b5389653e033438c8b3d6997cc02a45ca8540", "best_bid": "0.022", "best_ask": "0.029"}], "timestamp": "1769384373593", "event_type": "price_change"}}
{"_local_timestamp": "2026-01-25T23:39:33.735515+00:00", "data": {"market": "0x6d08ed1eadd870cd00c92048dda2fe06650e15905f8828ddf15e4d2186898029", "price_changes": [{"asset_id": "9876264386649584456256217467156428648140707909529649867285151715292859513583", "price": "0.28", "size": "10", "side": "BUY", "hash": "3ceb9e6383e3f4ba4daf069c68bab4c40338aab0", "best_bid": "0.63", "best_ask": "0.75"}, {"asset_id": "16774186999359636680352173816986047997138878170738869842466593332514752926314", "price": "0.72", "size": "10", "side": "SELL", "hash": "fb21274e13e26607b3e1e1dedfea3a6894c33343", "best_bid": "0.25", "best_ask": "0.37"}], "timestamp": "1769384373663", "event_type": "price_change"}}
{"_local_timestamp": "2026-01-25T23:39:33.736267+00:00", "data": {"market": "0xbb676d25a7ce355a3a10fa2bfbee5cb7b6b2ee36581ada7914d73ad78bedf62d", "price_changes": [{"asset_id": "10980869689964921227047480431023635246637317983901031741233635278193625249458", "price": "0.4", "size": "10", "side": "BUY", "hash": "1d7a05759995d15daa4ace1bfd1697ee90729e51", "best_bid": "0.92", "best_ask": "0.94"}, {"asset_id": "68913153540574314749415284055691780290306094084209478229942172031873972067947", "price": "0.6", "size": "10", "side": "SELL", "hash": "57f994a4b9f378cb476da689cdd8b3d659257b57", "best_bid": "0.06", "best_ask": "0.08"}], "timestamp": "1769384373663", "event_type": "price_change"}}
{"_local_timestamp": "2026-01-25T23:39:33.762582+00:00", "data": {"market": "0x81d603fe35c07415741bb9007bead4cdbddeb80fb35d5c9b6573eae9ee39fc1f", "price_changes": [{"asset_id": "87568880774573784875060327448344352870458352367065142953649333272451455443517", "price": "0.87", "size": "19.73", "side": "SELL", "hash": "afa47bad8da266f47c05317d6f7b54bd25bf5f2d", "best_bid": "0.82", "best_ask": "0.87"}, {"asset_id": "84046462467623575651564609695680328259011367863582645244986900444709317782077", "price": "0.13", "size": "19.73", "side": "BUY", "hash": "80b9428f37335b85111eed36b7c6209d1d115ac1", "best_bid": "0.13", "best_ask": "0.18"}], "timestamp": "1769384373688", "event_type": "price_change"}}
{"_local_timestamp": "2026-01-25T23:39:35.320311+00:00", "data": {"market": "0x6d08ed1eadd870cd00c92048dda2fe06650e15905f8828ddf15e4d2186898029", "price_changes": [{"asset_id": "9876264386649584456256217467156428648140707909529649867285151715292859513583", "price": "0.47", "size": "0", "side": "BUY", "hash": "0800043d4d33a2b8c4516bbabcc5dec0bf8ddf1c", "best_bid": "0.63", "best_ask": "0.75"}, {"asset_id": "16774186999359636680352173816986047997138878170738869842466593332514752926314", "price": "0.53", "size": "0", "side": "SELL", "hash": "58c3341b6aa630c2535587d5007cfd17d9d854be", "best_bid": "0.25", "best_ask": "0.37"}], "timestamp": "1769384375237", "event_type": "price_change"}}
{"_local_timestamp": "2026-01-25T23:39:35.321126+00:00", "data": {"market": "0x7ec88c27625388fe4de5c1e083da56806973aae7257bd0b3b2c2790937c89433", "price_changes": [{"asset_id": "11439216096927556294398061349600841087621436733892133369767994197102929396058", "price": "0.51", "size": "131.27", "side": "BUY", "hash": "40894b3574f63a0709ad567818faa5ce079ae3b1", "best_bid": "0.55", "best_ask": "0.79"}, {"asset_id": "93612868481313996119669919082030267547888020881923568220735661390829838620299", "price": "0.49", "size": "131.27", "side": "SELL", "hash": "2f7430c93c7d4fa0702da44afbf8b75b1cb46fe3", "best_bid": "0.21", "best_ask": "0.45"}], "timestamp": "1769384375237", "event_type": "price_change"}}
{"_local_timestamp": "2026-01-25T23:39:35.321810+00:00", "data": {"market": "0xd8aa928c90a14d70ede48f27543293c03ef8305420105518c3349f993e8fb4b4", "price_changes": [{"asset_id": "35918899905695997492070645194236546618834009355694722884958363910402437678512", "price": "0.27", "size": "0", "side": "BUY", "hash": "b0ff56becbeedbfb1ea7f38e570c53deeaa30197", "best_bid": "0.971", "best_ask": "0.978"}, {"asset_id": "9376678867812664753044653742290850239117727272721528310663723279807470231308", "price": "0.73", "size": "0", "side": "SELL", "hash": "b9f52ef67aeddccbbcb0827b06b328c92fe820b2", "best_bid": "0.022", "best_ask": "0.029"}], "timestamp": "1769384375237", "event_type": "price_change"}}
{"_local_timestamp": "2026-01-25T23:39:35.322612+00:00", "data": {"market": "0xbb676d25a7ce355a3a10fa2bfbee5cb7b6b2ee36581ada7914d73ad78bedf62d", "price_changes": [{"asset_id": "10980869689964921227047480431023635246637317983901031741233635278193625249458", "price": "0.66", "size": "95", "side": "BUY", "hash": "1766037435401182fa71d6d0ce245b0a3a519370", "best_bid": "0.92", "best_ask": "0.94"}, {"asset_id": "68913153540574314749415284055691780290306094084209478229942172031873972067947", "price": "0.34", "size": "95", "side": "SELL", "hash": "1012c62980a0e033452c7c7c0f69fed692c3f6f5", "best_bid": "0.06", "best_ask": "0.08"}], "timestamp": "1769384375237", "event_type": "price_change"}}
{"_local_timestamp": "2026-01-25T23:39:35.323355+00:00", "data": {"market": "0x2454c412d48443a73e15d93ae01e20caefd5d64a3865b67bc0a465fdac459c77", "price_changes": [{"asset_id": "21604618649648179239165697042911952381335935480672188760475095094501424754919", "price": "0.66", "size": "0", "side": "BUY", "hash": "6747c3567eaa54d74ca8c6239605e55642d4563b", "best_bid": "0.9", "best_ask": "0.94"}, {"asset_id": "46091239361932142478682480948008873970191467150785110396994502723691495289956", "price": "0.34", "size": "0", "side": "SELL", "hash": "e886b1e178dedb0cdbd7db2cc284ab4f95d03f72", "best_bid": "0.06", "best_ask": "0.1"}], "timestamp": "1769384375237", "event_type": "price_change"}}
{"_local_timestamp": "2026-01-25T23:39:35.342940+00:00", "data": {"market": "0x2454c412d48443a73e15d93ae01e20caefd5d64a3865b67bc0a465fdac459c77", "price_changes": [{"asset_id": "21604618649648179239165697042911952381335935480672188760475095094501424754919", "price": "0.65", "size": "47.23", "side": "BUY", "hash": "c932fffbc9b9b8caba93c1a853fe8c7fa36f1e17", "best_bid": "0.9", "best_ask": "0.94"}, {"asset_id": "46091239361932142478682480948008873970191467150785110396994502723691495289956", "price": "0.35", "size": "47.23", "side": "SELL", "hash": "8f0496f5ec8d6baa0c17edd4396f261bb25e576a", "best_bid": "0.06", "best_ask": "0.1"}], "timestamp": "1769384375270", "event_type": "price_change"}}
{"_local_timestamp": "2026-01-25T23:39:35.343743+00:00", "data": {"market": "0xbb676d25a7ce355a3a10fa2bfbee5cb7b6b2ee36581ada7914d73ad78bedf62d", "price_changes": [{"asset_id": "10980869689964921227047480431023635246637317983901031741233635278193625249458", "price": "0.41", "size": "20", "side": "BUY", "hash": "dde4284200983fa395538bf1ee5d3c1ba51e6e90", "best_bid": "0.92", "best_ask": "0.94"}, {"asset_id": "68913153540574314749415284055691780290306094084209478229942172031873972067947", "price": "0.59", "size": "20", "side": "SELL", "hash": "c7acb6256d4fe42378c449eab320aa9ccddd762c", "best_bid": "0.06", "best_ask": "0.08"}], "timestamp": "1769384375270", "event_type": "price_change"}}
{"_local_timestamp": "2026-01-25T23:39:35.344433+00:00", "data": {"market": "0x7ec88c27625388fe4de5c1e083da56806973aae7257bd0b3b2c2790937c89433", "price_changes": [{"asset_id": "11439216096927556294398061349600841087621436733892133369767994197102929396058", "price": "0.34", "size": "20", "side": "BUY", "hash": "34bd098a6530761c645228fbe4e60ccc90a47259", "best_bid": "0.55", "best_ask": "0.79"}, {"asset_id": "93612868481313996119669919082030267547888020881923568220735661390829838620299", "price": "0.66", "size": "20", "side": "SELL", "hash": "f59c5617c0600de0a28b2af4b7194392b06c8e84", "best_bid": "0.21", "best_ask": "0.45"}], "timestamp": "1769384375270", "event_type": "price_change"}}
{"_local_timestamp": "2026-01-25T23:39:35.345094+00:00", "data": {"market": "0xd8aa928c90a14d70ede48f27543293c03ef8305420105518c3349f993e8fb4b4", "price_changes": [{"asset_id": "35918899905695997492070645194236546618834009355694722884958363910402437678512", "price": "0.272", "size": "20", "side": "BUY", "hash": "b788d45e880166ba609a452b140ebff8d5396ee3", "best_bid": "0.971", "best_ask": "0.978"}, {"asset_id": "9376678867812664753044653742290850239117727272721528310663723279807470231308", "price": "0.728", "size": "20", "side": "SELL", "hash": "0da9aa07be832d8e881f2872dacb66b3ec1b95e0", "best_bid": "0.022", "best_ask": "0.029"}], "timestamp": "1769384375270", "event_type": "price_change"}}
{"_local_timestamp": "2026-01-25T23:39:35.345762+00:00", "data": {"market": "0x6d08ed1eadd870cd00c92048dda2fe06650e15905f8828ddf15e4d2186898029", "price_changes": [{"asset_id": "9876264386649584456256217467156428648140707909529649867285151715292859513583", "price": "0.46", "size": "20", "side": "BUY", "hash": "dadaa441218ea6a99f026703960b49e3fb6247c4", "best_bid": "0.63", "best_ask": "0.75"}, {"asset_id": "16774186999359636680352173816986047997138878170738869842466593332514752926314", "price": "0.54", "size": "20", "side": "SELL", "hash": "a10dcb30465b9700f4d830cb7e93924ee8911a21", "best_bid": "0.25", "best_ask": "0.37"}], "timestamp": "1769384375270", "event_type": "price_change"}}
{"_local_timestamp": "2026-01-25T23:40:02.131602+00:00", "data": {"market": "0xbb676d25a7ce355a3a10fa2bfbee5cb7b6b2ee36581ada7914d73ad78bedf62d", "price_changes": [{"asset_id": "10980869689964921227047480431023635246637317983901031741233635278193625249458", "price": "0.91", "size": "934.99", "side": "BUY", "hash": "1150ae4c671f4df60438ebbeca007d70b18b827c", "best_bid": "0.92", "best_ask": "0.94"}, {"asset_id": "68913153540574314749415284055691780290306094084209478229942172031873972067947", "price": "0.09", "size": "934.99", "side": "SELL", "hash": "d57a4b3fe3851c9417381eae094d20075a1fbfb2", "best_bid": "0.06", "best_ask": "0.08"}], "timestamp": "1769384402059", "event_type": "price_change"}}
{"_local_timestamp": "2026-01-25T23:40:02.132635+00:00", "data": {"market": "0xbb676d25a7ce355a3a10fa2bfbee5cb7b6b2ee36581ada7914d73ad78bedf62d", "price_changes": [{"asset_id": "68913153540574314749415284055691780290306094084209478229942172031873972067947", "price": "0.04", "size": "1220", "side": "BUY", "hash": "2e702a65d1f512067f021e48b365382722b8d718", "best_bid": "0.06", "best_ask": "0.08"}, {"asset_id": "10980869689964921227047480431023635246637317983901031741233635278193625249458", "price": "0.96", "size": "1220", "side": "SELL", "hash": "1d0323c92622713548af7f5937faff13e534b5c7", "best_bid": "0.92", "best_ask": "0.94"}], "timestamp": "1769384402059", "event_type": "price_change"}}
