{"_local_timestamp": "2026-01-25T23:40:32.967442+00:00", "data": [{"market": "0x61af02c9250c3917602e21c301e2f0cd032ea4e25bdef3751846b4d5f1c22799", "asset_id": "40581037591963443982506549884210281226867122905421206884675003828040093511244", "timestamp": "1769384431633", "hash": "0da3d5c40b8f4eeebaf75b3d019595dad4daac6b", "bids": [{"price": "0.01", "size": "15809.73"}, {"price": "0.02", "size": "3450"}, {"price": "0.03", "size": "7.99"}, {"price": "0.08", "size": "950"}, {"price": "0.09", "size": "7.36"}, {"price": "0.12", "size": "283.33"}, {"price": "0.13", "size": "550"}, {"price": "0.16", "size": "200"}, {"price": "0.17", "size": "1140"}, {"price": "0.2", "size": "390"}, {"price": "0.25", "size": "504"}, {"price": "0.29", "size": "82.75"}, {"price": "0.3", "size": "3957"}, {"price": "0.31", "size": "306"}, {"price": "0.33", "size": "60.6"}, {"price": "0.34", "size": "125"}, {"price": "0.45", "size": "249.98"}, {"price": "0.54", "size": "200"}, {"price": "0.56", "size": "267.07"}, {"price": "0.57", "size": "5"}, {"price": "0.6", "size": "10"}, {"price": "0.62", "size": "2000"}, {"price": "0.65", "size": "189.97"}, {"price": "0.71", "size": "59.38"}, {"price": "0.72", "size": "15.27"}, {"price": "0.73", "size": "67.8"}, {"price": "0.75", "size": "1310"}, {"price": "0.76", "size": "200"}, {"price": "0.77", "size": "49.99"}], "asks": [{"price": "0.99", "size": "3025.36"}, {"price": "0.98", "size": "4282"}, {"price": "0.97", "size": "13.38"}, {"price": "0.96", "size": "250"}, {"price": "0.95", "size": "576.92"}, {"price": "0.92", "size": "200"}, {"price": "0.91", "size": "1005.82"}, {"price": "0.9", "size": "630"}, {"price": "0.89", "size": "2219"}, {"price": "0.88", "size": "550"}, {"price": "0.87", "size": "900"}, {"price": "0.85", "size": "250"}, {"price": "0.84", "size": "402"}, {"price": "0.82", "size": "2532.54"}, {"price": "0.81", "size": "503.64"}, {"price": "0.8", "size": "125.22"}, {"price": "0.79", "size": "130"}], "event_type": "book", "last_trade_price": "0.780"}, {"market": "0x61af02c9250c3917602e21c301e2f0cd032ea4e25bdef3751846b4d5f1c22799", "asset_id": "77997400651011819054222158182618580861479123177562866576575031403070672671390", "timestamp": "1769384431633", "hash": "7413241547bbc1b4e4e08efb53e2933ab0be7b55", "bids": [{"price": "0.01", "size": "3025.36"}, {"price": "0.02", "size": "4282"}, {"price": "0.03", "size": "13.38"}, {"price": "0.04", "size": "250"}, {"price": "0.05", "size": "576.92"}, {"price": "0.08", "size": "200"}, {"price": "0.09", "size": "1005.82"}, {"price": "0.1", "size": "630"}, {"price": "0.11", "size": "2219"}, {"price": "0.12", "size": "550"}, {"price": "0.13", "size": "900"}, {"price": "0.15", "size": "250"}, {"price": "0.16", "size": "402"}, {"price": "0.18", "size": "2532.54"}, {"price": "0.19", "size": "503.64"}, {"price": "0.2", "size": "125.22"}, {"price": "0.21", "size": "130"}], "asks": [{"price": "0.99", "size": "15809.73"}, {"price": "0.98", "size": "3450"}, {"price": "0.97", "size": "7.99"}, {"price": "0.92", "size": "950"}, {"price": "0.91", "size": "7.36"}, {"price": "0.88", "size": "283.33"}, {"price": "0.87", "size": "550"}, {"price": "0.84", "size": "200"}, {"price": "0.83", "size": "1140"}, {"price": "0.8", "size": "390"}, {"price": "0.75", "size": "504"}, {"price": "0.71", "size": "82.75"}, {"price": "0.7", "size": "3957"}, {"price": "0.69", "size": "306"}, {"price": "0.67", "size": "60.6"}, {"price": "0.66", "size": "125"}, {"price": "0.55", "size": "249.98"}, {"price": "0.46", "size": "200"}, {"price": "0.44", "size": "267.07"}, {"price": "0.43", "size": "5"}, {"price": "0.4", "size": "10"}, {"price": "0.38", "size": "2000"}, {"price": "0.35", "size": "189.97"}, {"price": "0.29", "size": "59.38"}, {"price": "0.28", "size": "15.27"}, {"price": "0.27", "size": "67.8"}, {"price": "0.25", "size": "1310"}, {"price": "0.24", "size": "200"}, {"price": "0.23", "size": "49.99"}], "event_type": "book", "last_trade_price": "0.780"}]}
{"_local_timestamp": "2026-01-25T23:40:33.538258+00:00", "data": {"market": "0x61af02c9250c3917602e21c301e2f0cd032ea4e25bdef3751846b4d5f1c22799", "price_changes": [{"asset_id": "40581037591963443982506549884210281226867122905421206884675003828040093511244", "price": "0.75", "size": "1300", "side": "BUY", "hash": "e788163ea71576a237c47f6f15e897fcc6a25e44", "best_bid": "0.77", "best_ask": "0.79"}, {"asset_id": "77997400651011819054222158182618580861479123177562866576575031403070672671390", "price": "0.25", "size": "1300", "side": "SELL", "hash": "ff44939e9b2f1a903da01ff7fd1ffd959c64ae49", "best_bid": "0.21", "best_ask": "0.23"}], "timestamp": "1769384433476", "event_type": "price_change"}}
{"_local_timestamp": "2026-01-25T23:40:34.733230+00:00", "data": {"market": "0x61af02c9250c3917602e21c301e2f0cd032ea4e25bdef3751846b4d5f1c22799", "price_changes": [{"asset_id": "77997400651011819054222158182618580861479123177562866576575031403070672671390", "price": "0.18", "size": "2542.54", "side": "BUY", "hash": "a2f46e97e2d4368d5ff3c225158f7cfddea54088", "best_bid": "0.21", "best_ask": "0.23"}, {"asset_id": "40581037591963443982506549884210281226867122905421206884675003828040093511244", "price": "0.82", "size": "2542.54", "side": "SELL", "hash": "6d4f009b31d84408392a7221db5c6b5027154d45", "best_bid": "0.77", "best_ask": "0.79"}], "timestamp": "1769384434667", "event_type": "price_change"}}
{"_local_timestamp": "2026-01-25T23:40:34.843875+00:00", "data": {"market": "0x61af02c9250c3917602e21c301e2f0cd032ea4e25bdef3751846b4d5f1c22799", "price_changes": [{"asset_id": "77997400651011819054222158182618580861479123177562866576575031403070672671390", "price": "0.18", "size": "2532.54", "side": "BUY", "hash": "bd74b3e95e24fee8b13a3f5d2d4034d39d6afbae", "best_bid": "0.21", "best_ask": "0.23"}, {"asset_id": "40581037591963443982506549884210281226867122905421206884675003828040093511244", "price": "0.82", "size": "2532.54", "side": "SELL", "hash": "648f74480962beaae12f2603e319226f86786380", "best_bid": "0.77", "best_ask": "0.79"}], "timestamp": "1769384434774", "event_type": "price_change"}}
{"_local_timestamp": "2026-01-25T23:40:36.949905+00:00", "data": {"market": "0x61af02c9250c3917602e21c301e2f0cd032ea4e25bdef3751846b4d5f1c22799", "price_changes": [{"asset_id": "40581037591963443982506549884210281226867122905421206884675003828040093511244", "price": "0.75", "size": "1310", "side": "BUY", "hash": "28744d2373f695aa5a0fc0e90b4cbd0019d191c0", "best_bid": "0.77", "best_ask": "0.79"}, {"asset_id": "77997400651011819054222158182618580861479123177562866576575031403070672671390", "price": "0.25", "size": "1310", "side": "SELL", "hash": "a5b3c881d4c44cd5a31f680ce3560fe8b7ab5ca7", "best_bid": "0.21", "best_ask": "0.23"}], "timestamp": "1769384436881", "event_type": "price_change"}}
{"_local_timestamp": "2026-01-25T23:40:39.147732+00:00", "data": {"market": "0x61af02c9250c3917602e21c301e2f0cd032ea4e25bdef3751846b4d5f1c22799", "price_changes": [{"asset_id": "40581037591963443982506549884210281226867122905421206884675003828040093511244", "price": "0.75", "size": "1300", "side": "BUY", "hash": "98906b136691705178ae81a0064197d1881124b2", "best_bid": "0.77", "best_ask": "0.79"}, {"asset_id": "77997400651011819054222158182618580861479123177562866576575031403070672671390", "price": "0.25", "size": "1300", "side": "SELL", "hash": "9692182650fd9d9624e23f1642977edbea493180", "best_bid": "0.21", "best_ask": "0.23"}], "timestamp": "1769384439077", "event_type": "price_change"}}
{"_local_timestamp": "2026-01-25T23:40:40.328573+00:00", "data": {"market": "0x61af02c9250c3917602e21c301e2f0cd032ea4e25bdef3751846b4d5f1c22799", "price_changes": [{"asset_id": "40581037591963443982506549884210281226867122905421206884675003828040093511244", "price": "0.2", "size": "290", "side": "BUY", "hash": "c7dbcbe56f6ae004235228575ecf340a1511eb49", "best_bid": "0.77", "best_ask": "0.79"}, {"asset_id": "77997400651011819054222158182618580861479123177562866576575031403070672671390", "price": "0.8", "size": "290", "side": "SELL", "hash": "cfc1db61dd23d90e8a10209dfa6ac6a6397a2d81", "best_bid": "0.21", "best_ask": "0.23"}], "timestamp": "1769384440246", "event_type": "price_change"}}
{"_local_timestamp": "2026-01-25T23:40:40.522361+00:00", "data": {"market": "0x61af02c9250c3917602e21c301e2f0cd032ea4e25bdef3751846b4d5f1c22799", "price_changes": [{"asset_id": "40581037591963443982506549884210281226867122905421206884675003828040093511244", "price": "0.75", "size": "1310", "side": "BUY", "hash": "43739f4cca1ee7d159b6f1fe725f6bbf8c980404", "best_bid": "0.77", "best_ask": "0.79"}, {"asset_id": "77997400651011819054222158182618580861479123177562866576575031403070672671390", "price": "0.25", "size": "1310", "side": "SELL", "hash": "c7225a45fc1717074a0552651231c6e5bd499658", "best_bid": "0.21", "best_ask": "0.23"}], "timestamp": "1769384440356", "event_type": "price_change"}}
{"_local_timestamp": "2026-01-25T23:40:40.750703+00:00", "data": {"market": "0x61af02c9250c3917602e21c301e2f0cd032ea4e25bdef3751846b4d5f1c22799", "price_changes": [{"asset_id": "40581037591963443982506549884210281226867122905421206884675003828040093511244", "price": "0.19", "size": "100", "side": "BUY", "hash": "5ad2b5b976b72c6196d9eb5f85ef7a101fe38a85", "best_bid": "0.77", "best_ask": "0.79"}, {"asset_id": "77997400651011819054222158182618580861479123177562866576575031403070672671390", "price": "0.81", "size": "100", "side": "SELL", "hash": "8c36e3fbddc0f21c81c891a0a5e4729a3b08dc3f", "best_bid": "0.21", "best_ask": "0.23"}], "timestamp": "1769384440578", "event_type": "price_change"}}
{"_local_timestamp": "2026-01-25T23:40:41.450478+00:00", "data": {"market": "0x61af02c9250c3917602e21c301e2f0cd032ea4e25bdef3751846b4d5f1c22799", "price_changes": [{"asset_id": "40581037591963443982506549884210281226867122905421206884675003828040093511244", "price": "0.21", "size": "1998", "side": "BUY", "hash": "6f1ee00991bbde25a78ad35610c211a95b46155a", "best_bid": "0.77", "best_ask": "0.79"}, {"asset_id": "77997400651011819054222158182618580861479123177562866576575031403070672671390", "price": "0.79", "size": "1998", "side": "SELL", "hash": "3657f5a2e011dd97865f16e9f3087d707b4c76a5", "best_bid": "0.21", "best_ask": "0.23"}], "timestamp": "1769384441389", "event_type": "price_change"}}
{"_local_timestamp": "2026-01-25T23:40:44.283377+00:00", "data": {"market": "0x61af02c9250c3917602e21c301e2f0cd032ea4e25bdef3751846b4d5f1c22799", "price_changes": [{"asset_id": "40581037591963443982506549884210281226867122905421206884675003828040093511244", "price": "0.75", "size": "1300", "side": "BUY", "hash": "1527451858b804f29bd5af5d484c429484a0d76f", "best_bid": "0.77", "best_ask": "0.79"}, {"asset_id": "77997400651011819054222158182618580861479123177562866576575031403070672671390", "price": "0.25", "size": "1300", "side": "SELL", "hash": "4434700eb286917200e5c472a32b3152b36751cb", "best_bid": "0.21", "best_ask": "0.23"}], "timestamp": "1769384444215", "event_type": "price_change"}}
{"_local_timestamp": "2026-01-25T23:40:44.795242+00:00", "data": {"market": "0x61af02c9250c3917602e21c301e2f0cd032ea4e25bdef3751846b4d5f1c22799", "price_changes": [{"asset_id": "77997400651011819054222158182618580861479123177562866576575031403070672671390", "price": "0.18", "size": "2542.54", "side": "BUY", "hash": "823f157764dcf3422ef684221d93c213128c13e2", "best_bid": "0.21", "best_ask": "0.23"}, {"asset_id": "40581037591963443982506549884210281226867122905421206884675003828040093511244", "price": "0.82", "size": "2542.54", "side": "SELL", "hash": "d60b0eb3b58dca2eaaf91b92af515e0cbd936fb9", "best_bid": "0.77", "best_ask": "0.79"}], "timestamp": "1769384444713", "event_type": "price_change"}}
{"_local_timestamp": "2026-01-25T23:40:45.820040+00:00", "data": {"market": "0x61af02c9250c3917602e21c301e2f0cd032ea4e25bdef3751846b4d5f1c22799", "price_changes": [{"asset_id": "77997400651011819054222158182618580861479123177562866576575031403070672671390", "price": "0.18", "size": "2532.54", "side": "BUY", "hash": "14ed9f1688e7ed415fc338a16d7bd9906e326672", "best_bid": "0.21", "best_ask": "0.23"}, {"asset_id": "40581037591963443982506549884210281226867122905421206884675003828040093511244", "price": "0.82", "size": "2532.54", "side": "SELL", "hash": "c8de083ebe06890edc66a00e6e0de4437cba131a", "best_bid": "0.77", "best_ask": "0.79"}], "timestamp": "1769384445736", "event_type": "price_change"}}
{"_local_timestamp": "2026-01-25T23:40:45.895484+00:00", "data": {"market": "0x61af02c9250c3917602e21c301e2f0cd032ea4e25bdef3751846b4d5f1c22799", "price_changes": [{"asset_id": "40581037591963443982506549884210281226867122905421206884675003828040093511244", "price": "0.75", "size": "1310", "side": "BUY", "hash": "a3a3adf17e8f2de91f285e1139ff73a9b0e680bf", "best_bid": "0.77", "best_ask": "0.79"}, {"asset_id": "77997400651011819054222158182618580861479123177562866576575031403070672671390", "price": "0.25", "size": "1310", "side": "SELL", "hash": "73423102aa5bd7e5d6e6374047b880dcbb005e4b", "best_bid": "0.21", "best_ask": "0.23"}], "timestamp": "1769384445812", "event_type": "price_change"}}
{"_local_timestamp": "2026-01-25T23:40:47.142922+00:00", "data": {"market": "0x61af02c9250c3917602e21c301e2f0cd032ea4e25bdef3751846b4d5f1c22799", "price_changes": [{"asset_id": "40581037591963443982506549884210281226867122905421206884675003828040093511244", "price": "0.75", "size": "1300", "side": "BUY", "hash": "36d92706af6f741076cbe52bc6c3a5dcd7b77050", "best_bid": "0.77", "best_ask": "0.79"}, {"asset_id": "77997400651011819054222158182618580861479123177562866576575031403070672671390", "price": "0.25", "size": "1300", "side": "SELL", "hash": "84e95c48adcc4206a8612dcf97d00951b52c2223", "best_bid": "0.21", "best_ask": "0.23"}], "timestamp": "1769384447066", "event_type": "price_change"}}
{"_local_timestamp": "2026-01-25T23:40:47.221645+00:00", "data": {"market": "0x61af02c9250c3917602e21c301e2f0cd032ea4e25bdef3751846b4d5f1c22799", "price_changes": [{"asset_id": "77997400651011819054222158182618580861479123177562866576575031403070672671390", "price": "0.18", "size": "2542.54", "side": "BUY", "hash": "0d7cbe160888986ff83fea62d767f58a7626a920", "best_bid": "0.21", "best_ask": "0.23"}, {"asset_id": "40581037591963443982506549884210281226867122905421206884675003828040093511244", "price": "0.82", "size": "2542.54", "side": "SELL", "hash": "771d49c4bede11c30923e1e160cc369bc58fb4c3", "best_bid": "0.77", "best_ask": "0.79"}], "timestamp": "1769384447152", "event_type": "price_change"}}
{"_local_timestamp": "2026-01-25T23:40:47.809076+00:00", "data": {"market": "0x61af02c9250c3917602e21c301e2f0cd032ea4e25bdef3751846b4d5f1c22799", "price_changes": [{"asset_id": "77997400651011819054222158182618580861479123177562866576575031403070672671390", "price": "0.18", "size": "2532.54", "side": "BUY", "hash": "19d90a54d3c53021cdb12ac6c6a2b237d591e7ce", "best_bid": "0.21", "best_ask": "0.23"}, {"asset_id": "40581037591963443982506549884210281226867122905421206884675003828040093511244", "price": "0.82", "size": "2532.54", "side": "SELL", "hash": "e8057152cb69e73b89d1aa3f1a0696eed34bbe92", "best_bid": "0.77", "best_ask": "0.79"}], "timestamp": "1769384447745", "event_type": "price_change"}}
{"_local_timestamp": "2026-01-25T23:40:48.084501+00:00", "data": {"market": "0x61af02c9250c3917602e21c301e2f0cd032ea4e25bdef3751846b4d5f1c22799", "price_changes": [{"asset_id": "40581037591963443982506549884210281226867122905421206884675003828040093511244", "price": "0.75", "size": "1310", "side": "BUY", "hash": "28279f71a92e6fc6c85ec6b217cd26b708438384", "best_bid": "0.77", "best_ask": "0.79"}, {"asset_id": "77997400651011819054222158182618580861479123177562866576575031403070672671390", "price": "0.25", "size": "1310", "side": "SELL", "hash": "f8a796f7b0e46ddc17122c623319aa2ec20d07f0", "best_bid": "0.21", "best_ask": "0.23"}], "timestamp": "1769384448004", "event_type": "price_change"}}
{"_local_timestamp": "2026-01-25T23:40:49.593074+00:00", "data": {"market": "0x61af02c9250c3917602e21c301e2f0cd032ea4e25bdef3751846b4d5f1c22799", "price_changes": [{"asset_id": "40581037591963443982506549884210281226867122905421206884675003828040093511244", "price": "0.75", "size": "1300", "side": "BUY", "hash": "d02224ad994717b1f70045e15aad745bee396980", "best_bid": "0.77", "best_ask": "0.79"}, {"asset_id": "77997400651011819054222158182618580861479123177562866576575031403070672671390", "price": "0.25", "size": "1300", "side": "SELL", "hash": "2609a54a791fb64849aee2470d59e2edd396d782", "best_bid": "0.21", "best_ask": "0.23"}], "timestamp": "1769384449525", "event_type": "price_change"}}
{"_local_timestamp": "2026-01-25T23:40:50.851643+00:00", "data": {"market": "0x61af02c9250c3917602e21c301e2f0cd032ea4e25bdef3751846b4d5f1c22799", "price_changes": [{"asset_id": "40581037591963443982506549884210281226867122905421206884675003828040093511244", "price": "0.75", "size": "1310", "side": "BUY", "hash": "280abb270747ff73f51f13ab3ccfd5356f60f305", "best_bid": "0.77", "best_ask": "0.79"}, {"asset_id": "77997400651011819054222158182618580861479123177562866576575031403070672671390", "price": "0.25", "size": "1310", "side": "SELL", "hash": "dad7aaf27d83778395d49ada424e146c3496d684", "best_bid": "0.21", "best_ask": "0.23"}], "timestamp": "1769384450778", "event_type": "price_change"}}
{"_local_timestamp": "2026-01-25T23:40:50.979232+00:00", "data": {"market": "0x61af02c9250c3917602e21c301e2f0cd032ea4e25bdef3751846b4d5f1c22799", "price_changes": [{"asset_id": "40581037591963443982506549884210281226867122905421206884675003828040093511244", "price": "0.75", "size": "1300", "side": "BUY", "hash": "dd27b4035e72d340f1ae30c64610303796e4b10d", "best_bid": "0.77", "best_ask": "0.79"}, {"asset_id": "77997400651011819054222158182618580861479123177562866576575031403070672671390", "price": "0.25", "size": "1300", "side": "SELL", "hash": "3af429e723806c3a403575647b4e18abf3c3f6fd", "best_bid": "0.21", "best_ask": "0.23"}], "timestamp": "1769384450907", "event_type": "price_change"}}
{"_local_timestamp": "2026-01-25T23:40:51.980998+00:00", "data": {"market": "0x61af02c9250c3917602e21c301e2f0cd032ea4e25bdef3751846b4d5f1c22799", "price_changes": [{"asset_id": "77997400651011819054222158182618580861479123177562866576575031403070672671390", "price": "0.18", "size": "2542.54", "side": "BUY", "hash": "d3c9bbaad8b7f17bac5fecf508e3e63c7b74558a", "best_bid": "0.21", "best_ask": "0.23"}, {"asset_id": "40581037591963443982506549884210281226867122905421206884675003828040093511244", "price": "0.82", "size": "2542.54", "side": "SELL", "hash": "53c2155fa00eab45b5af89b928ac6398c4262da1", "best_bid": "0.77", "best_ask": "0.79"}], "timestamp": "1769384451912", "event_type": "price_change"}}
{"_local_timestamp": "2026-01-25T23:40:52.171052+00:00", "data": {"market": "0x61af02c9250c3917602e21c301e2f0cd032ea4e25bdef3751846b4d5f1c22799", "price_changes": [{"asset_id": "77997400651011819054222158182618580861479123177562866576575031403070672671390", "price": "0.18", "size": "2532.54", "side": "BUY", "hash": "6f01826fca9c5d7afd3ff1d8e1153ac9f591a0c4", "best_bid": "0.21", "best_ask": "0.23"}, {"asset_id": "40581037591963443982506549884210281226867122905421206884675003828040093511244", "price": "0.82", "size": "2532.54", "side": "SELL", "hash": "6b672e69f6efaac01753d06114f6735715f82b2e", "best_bid": "0.77", "best_ask": "0.79"}], "timestamp": "1769384452102", "event_type": "price_change"}}
{"_local_timestamp": "2026-01-25T23:40:52.475240+00:00", "data": {"market": "0x61af02c9250c3917602e21c301e2f0cd032ea4e25bdef3751846b4d5f1c22799", "price_changes": [{"asset_id": "40581037591963443982506549884210281226867122905421206884675003828040093511244", "price": "0.75", "size": "1310", "side": "BUY", "hash": "56566b46f17a48d5e8a1a7f13e3daa0ff3eb63fb", "best_bid": "0.77", "best_ask": "0.79"}, {"asset_id": "77997400651011819054222158182618580861479123177562866576575031403070672671390", "price": "0.25", "size": "1310", "side": "SELL", "hash": "91c23a78d8b6f3b699b70ed9053653a959b7397e", "best_bid": "0.21", "best_ask": "0.23"}], "timestamp": "1769384452407", "event_type": "price_change"}}
{"_local_timestamp": "2026-01-25T23:40:52.591262+00:00", "data": {"market": "0x61af02c9250c3917602e21c301e2f0cd032ea4e25bdef3751846b4d5f1c22799", "price_changes": [{"asset_id": "40581037591963443982506549884210281226867122905421206884675003828040093511244", "price": "0.75", "size": "1300", "side": "BUY", "hash": "aadae0f63effe899b4dbc2ae477d50fe96e38ec0", "best_bid": "0.77", "best_ask": "0.79"}, {"asset_id": "77997400651011819054222158182618580861479123177562866576575031403070672671390", "price": "0.25", "size": "1300", "side": "SELL", "hash": "654fdac8b73ce8d90e44d9dc7f1830fe8318c8e2", "best_bid": "0.21", "best_ask": "0.23"}], "timestamp": "1769384452521", "event_type": "price_change"}}
{"_local_timestamp": "2026-01-25T23:40:52.884913+00:00", "data": {"market": "0x61af02c9250c3917602e21c301e2f0cd032ea4e25bdef3751846b4d5f1c22799", "price_changes": [{"asset_id": "77997400651011819054222158182618580861479123177562866576575031403070672671390", "price": "0.18", "size": "2542.54", "side": "BUY", "hash": "e170c361ab5d088d033f85053cb6ae922263447b", "best_bid": "0.21", "best_ask": "0.23"}, {"asset_id": "40581037591963443982506549884210281226867122905421206884675003828040093511244", "price": "0.82", "size": "2542.54", "side": "SELL", "hash": "c43cd756f4728a3184d61343e19d709e9813b519", "best_bid": "0.77", "best_ask": "0.79"}], "timestamp": "1769384452818", "event_type": "price_change"}}
{"_local_timestamp": "2026-01-25T23:40:52.935155+00:00", "data": {"market": "0x61af02c9250c3917602e21c301e2f0cd032ea4e25bdef3751846b4d5f1c22799", "price_changes": [{"asset_id": "77997400651011819054222158182618580861479123177562866576575031403070672671390", "price": "0.19", "size": "493.64", "side": "BUY", "hash": "374c1ab9e13b037b6e06286cee150ec04cf61304", "best_bid": "0.21", "best_ask": "0.23"}, {"asset_id": "40581037591963443982506549884210281226867122905421206884675003828040093511244", "price": "0.81", "size": "493.64", "side": "SELL", "hash": "807c30bb8dac92ed57c4ce867ee92415f44f919b", "best_bid": "0.77", "best_ask": "0.79"}], "timestamp": "1769384452867", "event_type": "price_change"}}
{"_local_timestamp": "2026-01-25T23:40:52.937199+00:00", "data": {"market": "0x61af02c9250c3917602e21c301e2f0cd032ea4e25bdef3751846b4d5f1c22799", "price_changes": [{"asset_id": "77997400651011819054222158182618580861479123177562866576575031403070672671390", "price": "0.2", "size": "120.22", "side": "BUY", "hash": "374c1ab9e13b037b6e06286cee150ec04cf61304", "best_bid": "0.21", "best_ask": "0.23"}, {"asset_id": "40581037591963443982506549884210281226867122905421206884675003828040093511244", "price": "0.8", "size": "120.22", "side": "SELL", "hash": "807c30bb8dac92ed57c4ce867ee92415f44f919b", "best_bid": "0.77", "best_ask": "0.79"}], "timestamp": "1769384452867", "event_type": "price_change"}}
{"_local_timestamp": "2026-01-25T23:40:52.938620+00:00", "data": {"market": "0x61af02c9250c3917602e21c301e2f0cd032ea4e25bdef3751846b4d5f1c22799", "price_changes": [{"asset_id": "77997400651011819054222158182618580861479123177562866576575031403070672671390", "price": "0.16", "size": "102", "side": "BUY", "hash": "374c1ab9e13b037b6e06286cee150ec04cf61304", "best_bid": "0.21", "best_ask": "0.23"}, {"asset_id": "40581037591963443982506549884210281226867122905421206884675003828040093511244", "price": "0.84", "size": "102", "side": "SELL", "hash": "807c30bb8dac92ed57c4ce867ee92415f44f919b", "best_bid": "0.77", "best_ask": "0.79"}], "timestamp": "1769384452867", "event_type": "price_change"}}
{"_local_timestamp": "2026-01-25T23:40:52.940268+00:00", "data": {"market": "0x61af02c9250c3917602e21c301e2f0cd032ea4e25bdef3751846b4d5f1c22799", "price_changes": [{"asset_id": "77997400651011819054222158182618580861479123177562866576575031403070672671390", "price": "0.13", "size": "169", "side": "BUY", "hash": "374c1ab9e13b037b6e06286cee150ec04cf61304", "best_bid": "0.21", "best_ask": "0.23"}, {"asset_id": "40581037591963443982506549884210281226867122905421206884675003828040093511244", "price": "0.87", "size": "169", "side": "SELL", "hash": "807c30bb8dac92ed57c4ce867ee92415f44f919b", "best_bid": "0.77", "best_ask": "0.79"}], "timestamp": "1769384452867", "event_type": "price_change"}}
{"_local_timestamp": "2026-01-25T23:40:52.941653+00:00", "data": {"market": "0x61af02c9250c3917602e21c301e2f0cd032ea4e25bdef3751846b4d5f1c22799", "price_changes": [{"asset_id": "77997400651011819054222158182618580861479123177562866576575031403070672671390", "price": "0.11", "size": "491", "side": "BUY", "hash": "374c1ab9e13b037b6e06286cee150ec04cf61304", "best_bid": "0.21", "best_ask": "0.23"}, {"asset_id": "40581037591963443982506549884210281226867122905421206884675003828040093511244", "price": "0.89", "size": "491", "side": "SELL", "hash": "807c30bb8dac92ed57c4ce867ee92415f44f919b", "best_bid": "0.77", "best_ask": "0.79"}], "timestamp": "1769384452867", "event_type": "price_change"}}
{"_local_timestamp": "2026-01-25T23:40:52.943607+00:00", "data": {"market": "0x61af02c9250c3917602e21c301e2f0cd032ea4e25bdef3751846b4d5f1c22799", "price_changes": [{"asset_id": "77997400651011819054222158182618580861479123177562866576575031403070672671390", "price": "0.18", "size": "2520.54", "side": "BUY", "hash": "374c1ab9e13b037b6e06286cee150ec04cf61304", "best_bid": "0.21", "best_ask": "0.23"}, {"asset_id": "40581037591963443982506549884210281226867122905421206884675003828040093511244", "price": "0.82", "size": "2520.54", "side": "SELL", "hash": "807c30bb8dac92ed57c4ce867ee92415f44f919b", "best_bid": "0.77", "best_ask": "0.79"}], "timestamp": "1769384452867", "event_type": "price_change"}}
{"_local_timestamp": "2026-01-25T23:40:53.131963+00:00", "data": {"market": "0x61af02c9250c3917602e21c301e2f0cd032ea4e25bdef3751846b4d5f1c22799", "price_changes": [{"asset_id": "77997400651011819054222158182618580861479123177562866576575031403070672671390", "price": "0.19", "size": "498.64", "side": "BUY", "hash": "539b8a643333be0c7bef6459dbb1897ef7d01be6", "best_bid": "0.21", "best_ask": "0.23"}, {"asset_id": "40581037591963443982506549884210281226867122905421206884675003828040093511244", "price": "0.81", "size": "498.64", "side": "SELL", "hash": "0213c0a604f4bf1afc63c4d05061401ba3635c84", "best_bid": "0.77", "best_ask": "0.79"}], "timestamp": "1769384453034", "event_type": "price_change"}}
{"_local_timestamp": "2026-01-25T23:40:53.133522+00:00", "data": {"market": "0x61af02c9250c3917602e21c301e2f0cd032ea4e25bdef3751846b4d5f1c22799", "price_changes": [{"asset_id": "77997400651011819054222158182618580861479123177562866576575031403070672671390", "price": "0.16", "size": "365", "side": "BUY", "hash": "f7816b4a1bb95fac2e03f8af477ea02777510893", "best_bid": "0.21", "best_ask": "0.23"}, {"asset_id": "40581037591963443982506549884210281226867122905421206884675003828040093511244", "price": "0.84", "size": "365", "side": "SELL", "hash": "15036ae4508fd288fe24dee74dbfe20c092dc072", "best_bid": "0.77", "best_ask": "0.79"}], "timestamp": "1769384453035", "event_type": "price_change"}}
{"_local_timestamp": "2026-01-25T23:40:53.134831+00:00", "data": {"market": "0x61af02c9250c3917602e21c301e2f0cd032ea4e25bdef3751846b4d5f1c22799", "price_changes": [{"asset_id": "77997400651011819054222158182618580861479123177562866576575031403070672671390", "price": "0.11", "size": "2019", "side": "BUY", "hash": "c2601a502976d31ed063662e6f4f08668e76f28b", "best_bid": "0.21", "best_ask": "0.23"}, {"asset_id": "40581037591963443982506549884210281226867122905421206884675003828040093511244", "price": "0.89", "size": "2019", "side": "SELL", "hash": "8790de3528e0d21ceeba8f853577d0327b23b3e2", "best_bid": "0.77", "best_ask": "0.79"}], "timestamp": "1769384453035", "event_type": "price_change"}}
{"_local_timestamp": "2026-01-25T23:40:53.137562+00:00", "data": {"market": "0x61af02c9250c3917602e21c301e2f0cd032ea4e25bdef3751846b4d5f1c22799", "price_changes": [{"asset_id": "77997400651011819054222158182618580861479123177562866576575031403070672671390", "price": "0.18", "size": "2525.54", "side": "BUY", "hash": "cc44984ae942928fbf28a78e039a6d24adf8e1b2", "best_bid": "0.21", "best_ask": "0.23"}, {"asset_id": "40581037591963443982506549884210281226867122905421206884675003828040093511244", "price": "0.82", "size": "2525.54", "side": "SELL", "hash": "9d64d40de86daeaecea4efc90f3dc1c332d23707", "best_bid": "0.77", "best_ask": "0.79"}], "timestamp": "1769384453036", "event_type": "price_change"}}
{"_local_timestamp": "2026-01-25T23:40:53.141025+00:00", "data": {"market": "0x61af02c9250c3917602e21c301e2f0cd032ea4e25bdef3751846b4d5f1c22799", "price_changes": [{"asset_id": "77997400651011819054222158182618580861479123177562866576575031403070672671390", "price": "0.13", "size": "816", "side": "BUY", "hash": "ea285166db184cc5ad3d91301e4ff6866ba66697", "best_bid": "0.21", "best_ask": "0.23"}, {"asset_id": "40581037591963443982506549884210281226867122905421206884675003828040093511244", "price": "0.87", "size": "816", "side": "SELL", "hash": "0db3abe6531102e4760623381d83d7056f8f1a3c", "best_bid": "0.77", "best_ask": "0.79"}], "timestamp": "1769384453037", "event_type": "price_change"}}
{"_local_timestamp": "2026-01-25T23:40:55.038905+00:00", "data": {"market": "0x61af02c9250c3917602e21c301e2f0cd032ea4e25bdef3751846b4d5f1c22799", "price_changes": [{"asset_id": "77997400651011819054222158182618580861479123177562866576575031403070672671390", "price": "0.18", "size": "2515.54", "side": "BUY", "hash": "b2c233f1d024d71d1e313e88dfbf92bae11327fc", "best_bid": "0.21", "best_ask": "0.23"}, {"asset_id": "40581037591963443982506549884210281226867122905421206884675003828040093511244", "price": "0.82", "size": "2515.54", "side": "SELL", "hash": "ac234c9a4823e83de0059649caad2006a2acac04", "best_bid": "0.77", "best_ask": "0.79"}], "timestamp": "1769384454963", "event_type": "price_change"}}
{"_local_timestamp": "2026-01-25T23:40:55.832123+00:00", "data": {"market": "0x61af02c9250c3917602e21c301e2f0cd032ea4e25bdef3751846b4d5f1c22799", "price_changes": [{"asset_id": "40581037591963443982506549884210281226867122905421206884675003828040093511244", "price": "0.75", "size": "1310", "side": "BUY", "hash": "a7a79fc3053fd76c33c22d55e4ab891e84ff6edf", "best_bid": "0.77", "best_ask": "0.79"}, {"asset_id": "77997400651011819054222158182618580861479123177562866576575031403070672671390", "price": "0.25", "size": "1310", "side": "SELL", "hash": "24dbb4efadda367f031066b452bc63910293e412", "best_bid": "0.21", "best_ask": "0.23"}], "timestamp": "1769384455761", "event_type": "price_change"}}
{"_local_timestamp": "2026-01-25T23:40:58.539434+00:00", "data": {"market": "0x61af02c9250c3917602e21c301e2f0cd032ea4e25bdef3751846b4d5f1c22799", "price_changes": [{"asset_id": "40581037591963443982506549884210281226867122905421206884675003828040093511244", "price": "0.75", "size": "1300", "side": "BUY", "hash": "e609164bd9927f861f27900bc9b0ec55f7f8d8d4", "best_bid": "0.77", "best_ask": "0.79"}, {"asset_id": "77997400651011819054222158182618580861479123177562866576575031403070672671390", "price": "0.25", "size": "1300", "side": "SELL", "hash": "b302f0373f47606cd1c5bacab2d81b5dff8a23d5", "best_bid": "0.21", "best_ask": "0.23"}], "timestamp": "1769384458474", "event_type": "price_change"}}
{"_local_timestamp": "2026-01-25T23:40:59.976974+00:00", "data": {"market": "0x61af02c9250c3917602e21c301e2f0cd032ea4e25bdef3751846b4d5f1c22799", "price_changes": [{"asset_id": "77997400651011819054222158182618580861479123177562866576575031403070672671390", "price": "0.18", "size": "2525.54", "side": "BUY", "hash": "8124bc5b703ef554cfd62200c4ac37bc2bf3a1b4", "best_bid": "0.21", "best_ask": "0.23"}, {"asset_id": "40581037591963443982506549884210281226867122905421206884675003828040093511244", "price": "0.82", "size": "2525.54", "side": "SELL", "hash": "5af8e8d4e365656b2e207b338bd04708477104a0", "best_bid": "0.77", "best_ask": "0.79"}], "timestamp": "1769384459908", "event_type": "price_change"}}
{"_local_timestamp": "2026-01-25T23:41:00.073206+00:00", "data": {"market": "0x61af02c9250c3917602e21c301e2f0cd032ea4e25bdef3751846b4d5f1c22799", "price_changes": [{"asset_id": "77997400651011819054222158182618580861479123177562866576575031403070672671390", "price": "0.18", "size": "2515.54", "side": "BUY", "hash": "c48c373071117d46b3e5d022aa894ddd07568682", "best_bid": "0.21", "best_ask": "0.23"}, {"asset_id": "40581037591963443982506549884210281226867122905421206884675003828040093511244", "price": "0.82", "size": "2515.54", "side": "SELL", "hash": "000237d8e2a01c237e1fb5e7dd302e4d07fd998f", "best_bid": "0.77", "best_ask": "0.79"}], "timestamp": "1769384460000", "event_type": "price_change"}}
{"_local_timestamp": "2026-01-25T23:41:00.084989+00:00", "data": {"market": "0x61af02c9250c3917602e21c301e2f0cd032ea4e25bdef3751846b4d5f1c22799", "price_changes": [{"asset_id": "40581037591963443982506549884210281226867122905421206884675003828040093511244", "price": "0.75", "size": "1310", "side": "BUY", "hash": "d0e8a995add3e8bb189c5de8ca1d3bc190de5089", "best_bid": "0.77", "best_ask": "0.79"}, {"asset_id": "77997400651011819054222158182618580861479123177562866576575031403070672671390", "price": "0.25", "size": "1310", "side": "SELL", "hash": "4636f91104ad01f76207e50b07efc44b19a0b23d", "best_bid": "0.21", "best_ask": "0.23"}], "timestamp": "1769384460007", "event_type": "price_change"}}
{"_local_timestamp": "2026-01-25T23:41:02.873857+00:00", "data": {"market": "0x61af02c9250c3917602e21c301e2f0cd032ea4e25bdef3751846b4d5f1c22799", "price_changes": [{"asset_id": "40581037591963443982506549884210281226867122905421206884675003828040093511244", "price": "0.75", "size": "1300", "side": "BUY", "hash": "1988f3c14417cf77717233553fab1b9cd4445070", "best_bid": "0.77", "best_ask": "0.79"}, {"asset_id": "77997400651011819054222158182618580861479123177562866576575031403070672671390", "price": "0.25", "size": "1300", "side": "SELL", "hash": "1a061ddb361e31c6c1dbe2ddfef77c7dead1c683", "best_bid": "0.21", "best_ask": "0.23"}], "timestamp": "1769384462779", "event_type": "price_change"}}
{"_local_timestamp": "2026-01-25T23:41:04.180207+00:00", "data": {"market": "0x61af02c9250c3917602e21c301e2f0cd032ea4e25bdef3751846b4d5f1c22799", "price_changes": [{"asset_id": "77997400651011819054222158182618580861479123177562866576575031403070672671390", "price": "0.18", "size": "2525.54", "side": "BUY", "hash": "0213e24802b53c6659e6aa70c82cfd21f33d20a3", "best_bid": "0.21", "best_ask": "0.23"}, {"asset_id": "40581037591963443982506549884210281226867122905421206884675003828040093511244", "price": "0.82", "size": "2525.54", "side": "SELL", "hash": "5be72572dd0959f475b0b8a6e0e3ef0819982af2", "best_bid": "0.77", "best_ask": "0.79"}], "timestamp": "1769384464111", "event_type": "price_change"}}
{"_local_timestamp": "2026-01-25T23:41:05.929054+00:00", "data": {"market": "0x61af02c9250c3917602e21c301e2f0cd032ea4e25bdef3751846b4d5f1c22799", "price_changes": [{"asset_id": "77997400651011819054222158182618580861479123177562866576575031403070672671390", "price": "0.18", "size": "2515.54", "side": "BUY", "hash": "92942d5eef033b8931bb3e7a9130386887a3f580", "best_bid": "0.21", "best_ask": "0.23"}, {"asset_id": "40581037591963443982506549884210281226867122905421206884675003828040093511244", "price": "0.82", "size": "2515.54", "side": "SELL", "hash": "48cd4543332bdeee7639d64364c4b973e30fd7bd", "best_bid": "0.77", "best_ask": "0.79"}], "timestamp": "1769384465859", "event_type": "price_change"}}
{"_local_timestamp": "2026-01-25T23:41:07.232723+00:00", "data": {"market": "0x61af02c9250c3917602e21c301e2f0cd032ea4e25bdef3751846b4d5f1c22799", "price_changes": [{"asset_id": "77997400651011819054222158182618580861479123177562866576575031403070672671390", "price": "0.18", "size": "2525.54", "side": "BUY", "hash": "c5f6dd4a0dc815626e0155ee45559bc2a6ee26a5", "best_bid": "0.21", "best_ask": "0.23"}, {"asset_id": "40581037591963443982506549884210281226867122905421206884675003828040093511244", "price": "0.82", "size": "2525.54", "side": "SELL", "hash": "3dae503c6c5ae8d9347cf12d39c7d9882aa49779", "best_bid": "0.77", "best_ask": "0.79"}], "timestamp": "1769384467146", "event_type": "price_change"}}
{"_local_timestamp": "2026-01-25T23:41:07.263360+00:00", "data": {"market": "0x61af02c9250c3917602e21c301e2f0cd032ea4e25bdef3751846b4d5f1c22799", "price_changes": [{"asset_id": "77997400651011819054222158182618580861479123177562866576575031403070672671390", "price": "0.18", "size": "2515.54", "side": "BUY", "hash": "93e5eda94edc9fa3640e7a31d9c26b76dafed9aa", "best_bid": "0.21", "best_ask": "0.23"}, {"asset_id": "40581037591963443982506549884210281226867122905421206884675003828040093511244", "price": "0.82", "size": "2515.54", "side": "SELL", "hash": "bfb867be2d211a479cadeb41b0cbc778acda1b9d", "best_bid": "0.77", "best_ask": "0.79"}], "timestamp": "1769384467148", "event_type": "price_change"}}
{"_local_timestamp": "2026-01-25T23:41:07.303827+00:00", "data": {"market": "0x61af02c9250c3917602e21c301e2f0cd032ea4e25bdef3751846b4d5f1c22799", "price_changes": [{"asset_id": "40581037591963443982506549884210281226867122905421206884675003828040093511244", "price": "0.75", "size": "1310", "side": "BUY", "hash": "566d3f743395383aa7b062be965cb82e6fc8d4e1", "best_bid": "0.77", "best_ask": "0.79"}, {"asset_id": "77997400651011819054222158182618580861479123177562866576575031403070672671390", "price": "0.25", "size": "1310", "side": "SELL", "hash": "6065cb30c9b7be4edc04506e8093115de6cf0dd2", "best_bid": "0.21", "best_ask": "0.23"}], "timestamp": "1769384467232", "event_type": "price_change"}}
{"_local_timestamp": "2026-01-25T23:41:08.723167+00:00", "data": {"market": "0x61af02c9250c3917602e21c301e2f0cd032ea4e25bdef3751846b4d5f1c22799", "price_changes": [{"asset_id": "40581037591963443982506549884210281226867122905421206884675003828040093511244", "price": "0.75", "size": "1300", "side": "BUY", "hash": "f3f6c35bfbe3f918e4db8cb51793800058c982ec", "best_bid": "0.77", "best_ask": "0.79"}, {"asset_id": "77997400651011819054222158182618580861479123177562866576575031403070672671390", "price": "0.25", "size": "1300", "side": "SELL", "hash": "fc72b86bc77bb80c56bd8f2d202c540e24368a70", "best_bid": "0.21", "best_ask": "0.23"}], "timestamp": "1769384468659", "event_type": "price_change"}}
{"_local_timestamp": "2026-01-25T23:41:09.863269+00:00", "data": {"market": "0x61af02c9250c3917602e21c301e2f0cd032ea4e25bdef3751846b4d5f1c22799", "price_changes": [{"asset_id": "77997400651011819054222158182618580861479123177562866576575031403070672671390", "price": "0.18", "size": "2525.54", "side": "BUY", "hash": "372f4aa5e881a6c2c09a4bcd9814c05754e02d60", "best_bid": "0.21", "best_ask": "0.23"}, {"asset_id": "40581037591963443982506549884210281226867122905421206884675003828040093511244", "price": "0.82", "size": "2525.54", "side": "SELL", "hash": "bdd93082e797d18c36aeade586f27a5ad3313212", "best_bid": "0.77", "best_ask": "0.79"}], "timestamp": "1769384469794", "event_type": "price_change"}}
{"_local_timestamp": "2026-01-25T23:41:09.922008+00:00", "data": {"market": "0x61af02c9250c3917602e21c301e2f0cd032ea4e25bdef3751846b4d5f1c22799", "price_changes": [{"asset_id": "77997400651011819054222158182618580861479123177562866576575031403070672671390", "price": "0.18", "size": "2515.54", "side": "BUY", "hash": "cdc133efd4dccacb4224b6793b4902503b6aa64b", "best_bid": "0.21", "best_ask": "0.23"}, {"asset_id": "40581037591963443982506549884210281226867122905421206884675003828040093511244", "price": "0.82", "size": "2515.54", "side": "SELL", "hash": "34e5332453a1e06e8580e804613fa99d8bbd49f6", "best_bid": "0.77", "best_ask": "0.79"}], "timestamp": "1769384469828", "event_type": "price_change"}}
{"_local_timestamp": "2026-01-25T23:41:11.734978+00:00", "data": {"market": "0x61af02c9250c3917602e21c301e2f0cd032ea4e25bdef3751846b4d5f1c22799", "price_changes": [{"asset_id": "40581037591963443982506549884210281226867122905421206884675003828040093511244", "price": "0.75", "size": "1310", "side": "BUY", "hash": "97840528812f27ff0562367b7e7212e598fba050", "best_bid": "0.77", "best_ask": "0.79"}, {"asset_id": "77997400651011819054222158182618580861479123177562866576575031403070672671390", "price": "0.25", "size": "1310", "side": "SELL", "hash": "b0fe190cc14567381718cbbd4ca000e96eded2d7", "best_bid": "0.21", "best_ask": "0.23"}], "timestamp": "1769384471660", "event_type": "price_change"}}
{"_local_timestamp": "2026-01-25T23:41:13.062421+00:00", "data": {"market": "0x61af02c9250c3917602e21c301e2f0cd032ea4e25bdef3751846b4d5f1c22799", "price_changes": [{"asset_id": "40581037591963443982506549884210281226867122905421206884675003828040093511244", "price": "0.75", "size": "1300", "side": "BUY", "hash": "83d6b91c20a1c08228fc560638e36cf3c8bf7684", "best_bid": "0.77", "best_ask": "0.79"}, {"asset_id": "77997400651011819054222158182618580861479123177562866576575031403070672671390", "price": "0.25", "size": "1300", "side": "SELL", "hash": "724a9751c1eb8ff41e76ad43bbf6c6fcfb3fd78a", "best_bid": "0.21", "best_ask": "0.23"}], "timestamp": "1769384472989", "event_type": "price_change"}}
{"_local_timestamp": "2026-01-25T23:41:14.534887+00:00", "data": {"market": "0x61af02c9250c3917602e21c301e2f0cd032ea4e25bdef3751846b4d5f1c22799", "price_changes": [{"asset_id": "77997400651011819054222158182618580861479123177562866576575031403070672671390", "price": "0.18", "size": "2525.54", "side": "BUY", "hash": "d6ff410f5c8042633d4aec36696ae3f412508c47", "best_bid": "0.21", "best_ask": "0.23"}, {"asset_id": "40581037591963443982506549884210281226867122905421206884675003828040093511244", "price": "0.82", "size": "2525.54", "side": "SELL", "hash": "d1b0e989f1fb1c7a0d6894740a94f76145ab0b84", "best_bid": "0.77", "best_ask": "0.79"}], "timestamp": "1769384474462", "event_type": "price_change"}}
{"_local_timestamp": "2026-01-25T23:41:14.540057+00:00", "data": {"market": "0x61af02c9250c3917602e21c301e2f0cd032ea4e25bdef3751846b4d5f1c22799", "price_changes": [{"asset_id": "77997400651011819054222158182618580861479123177562866576575031403070672671390", "price": "0.18", "size": "2515.54", "side": "BUY", "hash": "a0f2a55166d2f09e1a08c4d9ff79e284018a6243", "best_bid": "0.21", "best_ask": "0.23"}, {"asset_id": "40581037591963443982506549884210281226867122905421206884675003828040093511244", "price": "0.82", "size": "2515.54", "side": "SELL", "hash": "da47828c4f3c380c562d3bf795229abc76480be8", "best_bid": "0.77", "best_ask": "0.79"}], "timestamp": "1769384474470", "event_type": "price_change"}}
{"_local_timestamp": "2026-01-25T23:41:14.570139+00:00", "data": {"market": "0x61af02c9250c3917602e21c301e2f0cd032ea4e25bdef3751846b4d5f1c22799", "price_changes": [{"asset_id": "40581037591963443982506549884210281226867122905421206884675003828040093511244", "price": "0.75", "size": "1310", "side": "BUY", "hash": "5e0b0c6e75438becb1a74311fe9b106442be9478", "best_bid": "0.77", "best_ask": "0.79"}, {"asset_id": "77997400651011819054222158182618580861479123177562866576575031403070672671390", "price": "0.25", "size": "1310", "side": "SELL", "hash": "225975d421e88481e4eb4ce5e152674c5aa173c7", "best_bid": "0.21", "best_ask": "0.23"}], "timestamp": "1769384474492", "event_type": "price_change"}}
{"_local_timestamp": "2026-01-25T23:41:17.169924+00:00", "data": {"market": "0x61af02c9250c3917602e21c301e2f0cd032ea4e25bdef3751846b4d5f1c22799", "price_changes": [{"asset_id": "40581037591963443982506549884210281226867122905421206884675003828040093511244", "price": "0.75", "size": "1300", "side": "BUY", "hash": "2bb2c1778e94470d067a57f5b5285c6cdbe35a8e", "best_bid": "0.77", "best_ask": "0.79"}, {"asset_id": "77997400651011819054222158182618580861479123177562866576575031403070672671390", "price": "0.25", "size": "1300", "side": "SELL", "hash": "dbef555f6265a3f25b3e31e08eda7872ba8c7e8a", "best_bid": "0.21", "best_ask": "0.23"}], "timestamp": "1769384477098", "event_type": "price_change"}}
{"_local_timestamp": "2026-01-25T23:41:18.384555+00:00", "data": {"market": "0x61af02c9250c3917602e21c301e2f0cd032ea4e25bdef3751846b4d5f1c22799", "price_changes": [{"asset_id": "40581037591963443982506549884210281226867122905421206884675003828040093511244", "price": "0.75", "size": "1310", "side": "BUY", "hash": "a0591c068333bed9d1d4546d5ec05aa958261d44", "best_bid": "0.77", "best_ask": "0.79"}, {"asset_id": "77997400651011819054222158182618580861479123177562866576575031403070672671390", "price": "0.25", "size": "1310", "side": "SELL", "hash": "9b31cc63cfb6191e10147a49770aec7d03b96c6a", "best_bid": "0.21", "best_ask": "0.23"}], "timestamp": "1769384478249", "event_type": "price_change"}}
{"_local_timestamp": "2026-01-25T23:41:19.371974+00:00", "data": {"market": "0x61af02c9250c3917602e21c301e2f0cd032ea4e25bdef3751846b4d5f1c22799", "price_changes": [{"asset_id": "40581037591963443982506549884210281226867122905421206884675003828040093511244", "price": "0.75", "size": "1300", "side": "BUY", "hash": "f10a75e7ffa548444cc8dba913c9dd434a7fd5c3", "best_bid": "0.77", "best_ask": "0.79"}, {"asset_id": "77997400651011819054222158182618580861479123177562866576575031403070672671390", "price": "0.25", "size": "1300", "side": "SELL", "hash": "5612436bcf2d94ebcd0d875c377f12c0de5c536a", "best_bid": "0.21", "best_ask": "0.23"}], "timestamp": "1769384479301", "event_type": "price_change"}}
{"_local_timestamp": "2026-01-25T23:41:19.674289+00:00", "data": {"market": "0x61af02c9250c3917602e21c301e2f0cd032ea4e25bdef3751846b4d5f1c22799", "price_changes": [{"asset_id": "40581037591963443982506549884210281226867122905421206884675003828040093511244", "price": "0.75", "size": "1310", "side": "BUY", "hash": "e8fdb18328b9dc9ae54a4d57fc6e6bbcc6b1c36b", "best_bid": "0.77", "best_ask": "0.79"}, {"asset_id": "77997400651011819054222158182618580861479123177562866576575031403070672671390", "price": "0.25", "size": "1310", "side": "SELL", "hash": "182f320c9fe391bee031ead8a4c577e6fdee1fa6", "best_bid": "0.21", "best_ask": "0.23"}], "timestamp": "1769384479602", "event_type": "price_change"}}
{"_local_timestamp": "2026-01-25T23:41:21.963070+00:00", "data": {"market": "0x61af02c9250c3917602e21c301e2f0cd032ea4e25bdef3751846b4d5f1c22799", "price_changes": [{"asset_id": "40581037591963443982506549884210281226867122905421206884675003828040093511244", "price": "0.75", "size": "1300", "side": "BUY", "hash": "3da04af5d2fd34eac21e96e9a4e71c6199ae0e97", "best_bid": "0.77", "best_ask": "0.79"}, {"asset_id": "77997400651011819054222158182618580861479123177562866576575031403070672671390", "price": "0.25", "size": "1300", "side": "SELL", "hash": "a9187b45cf66850911f9990b26329675faaabf8b", "best_bid": "0.21", "best_ask": "0.23"}], "timestamp": "1769384481880", "event_type": "price_change"}}
{"_local_timestamp": "2026-01-25T23:41:22.040484+00:00", "data": {"market": "0x61af02c9250c3917602e21c301e2f0cd032ea4e25bdef3751846b4d5f1c22799", "price_changes": [{"asset_id": "77997400651011819054222158182618580861479123177562866576575031403070672671390", "price": "0.18", "size": "2525.54", "side": "BUY", "hash": "266a9aee689c60d4c43566506da1aa649ef3835c", "best_bid": "0.21", "best_ask": "0.23"}, {"asset_id": "40581037591963443982506549884210281226867122905421206884675003828040093511244", "price": "0.82", "size": "2525.54", "side": "SELL", "hash": "f7400af2f00679db3da5e0b0428aed390a3cdb29", "best_bid": "0.77", "best_ask": "0.79"}], "timestamp": "1769384481967", "event_type": "price_change"}}
{"_local_timestamp": "2026-01-25T23:41:22.839934+00:00", "data": {"market": "0x61af02c9250c3917602e21c301e2f0cd032ea4e25bdef3751846b4d5f1c22799", "price_changes": [{"asset_id": "77997400651011819054222158182618580861479123177562866576575031403070672671390", "price": "0.18", "size": "2515.54", "side": "BUY", "hash": "8edf47f40144b1943c99e7c810c1e39b5d214bb7", "best_bid": "0.21", "best_ask": "0.23"}, {"asset_id": "40581037591963443982506549884210281226867122905421206884675003828040093511244", "price": "0.82", "size": "2515.54", "side": "SELL", "hash": "cf0f7bfda0b23063efb3ee3fc200ed9b0901bd60", "best_bid": "0.77", "best_ask": "0.79"}], "timestamp": "1769384482766", "event_type": "price_change"}}
{"_local_timestamp": "2026-01-25T23:41:22.972336+00:00", "data": {"market": "0x61af02c9250c3917602e21c301e2f0cd032ea4e25bdef3751846b4d5f1c22799", "price_changes": [{"asset_id": "40581037591963443982506549884210281226867122905421206884675003828040093511244", "price": "0.75", "size": "1310", "side": "BUY", "hash": "820f2d57962fce6d745e82a11120414ab04aa54b", "best_bid": "0.77", "best_ask": "0.79"}, {"asset_id": "77997400651011819054222158182618580861479123177562866576575031403070672671390", "price": "0.25", "size": "1310", "side": "SELL", "hash": "93b0df280d721f09308d2194cd76c79da3ebf5c1", "best_bid": "0.21", "best_ask": "0.23"}], "timestamp": "1769384482897", "event_type": "price_change"}}
{"_local_timestamp": "2026-01-25T23:41:23.498034+00:00", "data": {"market": "0x61af02c9250c3917602e21c301e2f0cd032ea4e25bdef3751846b4d5f1c22799", "price_changes": [{"asset_id": "40581037591963443982506549884210281226867122905421206884675003828040093511244", "price": "0.75", "size": "1300", "side": "BUY", "hash": "5360a858a0a0dd0698131022f7b0f2584161e841", "best_bid": "0.77", "best_ask": "0.79"}, {"asset_id": "77997400651011819054222158182618580861479123177562866576575031403070672671390", "price": "0.25", "size": "1300", "side": "SELL", "hash": "5a6fa5e03c3cdf32775b062cc11bb0539e5b8f9a", "best_bid": "0.21", "best_ask": "0.23"}], "timestamp": "1769384483427", "event_type": "price_change"}}
{"_local_timestamp": "2026-01-25T23:41:23.736353+00:00", "data": {"market": "0x61af02c9250c3917602e21c301e2f0cd032ea4e25bdef3751846b4d5f1c22799", "price_changes": [{"asset_id": "77997400651011819054222158182618580861479123177562866576575031403070672671390", "price": "0.18", "size": "2525.54", "side": "BUY", "hash": "424d88ddf1cbace8ad810052382f5f178b411bbd", "best_bid": "0.21", "best_ask": "0.23"}, {"asset_id": "40581037591963443982506549884210281226867122905421206884675003828040093511244", "price": "0.82", "size": "2525.54", "side": "SELL", "hash": "87bf203402bf885415fb775db1a8a7eca96b2762", "best_bid": "0.77", "best_ask": "0.79"}], "timestamp": "1769384483663", "event_type": "price_change"}}
{"_local_timestamp": "2026-01-25T23:41:23.788010+00:00", "data": {"market": "0x61af02c9250c3917602e21c301e2f0cd032ea4e25bdef3751846b4d5f1c22799", "price_changes": [{"asset_id": "77997400651011819054222158182618580861479123177562866576575031403070672671390", "price": "0.18", "size": "2515.54", "side": "BUY", "hash": "efaced8fd6f99d29f62f9606898e8a72cb379645", "best_bid": "0.21", "best_ask": "0.23"}, {"asset_id": "40581037591963443982506549884210281226867122905421206884675003828040093511244", "price": "0.82", "size": "2515.54", "side": "SELL", "hash": "dec14dc99ffd3d81b2876be90df210e1898a9968", "best_bid": "0.77", "best_ask": "0.79"}], "timestamp": "1769384483721", "event_type": "price_change"}}
{"_local_timestamp": "2026-01-25T23:41:23.793018+00:00", "data": {"market": "0x61af02c9250c3917602e21c301e2f0cd032ea4e25bdef3751846b4d5f1c22799", "price_changes": [{"asset_id": "40581037591963443982506549884210281226867122905421206884675003828040093511244", "price": "0.75", "size": "1310", "side": "BUY", "hash": "c1d8d4ba9720fca0c9a2c5c73820696fcec95408", "best_bid": "0.77", "best_ask": "0.79"}, {"asset_id": "77997400651011819054222158182618580861479123177562866576575031403070672671390", "price": "0.25", "size": "1310", "side": "SELL", "hash": "1ab3e0686aec08c1a687e813e232481308410f45", "best_bid": "0.21", "best_ask": "0.23"}], "timestamp": "1769384483726", "event_type": "price_change"}}
{"_local_timestamp": "2026-01-25T23:41:25.769528+00:00", "data": {"market": "0x61af02c9250c3917602e21c301e2f0cd032ea4e25bdef3751846b4d5f1c22799", "price_changes": [{"asset_id": "40581037591963443982506549884210281226867122905421206884675003828040093511244", "price": "0.75", "size": "1300", "side": "BUY", "hash": "a73b28687f8c20c5609278373a8fbd9c04dbf9d2", "best_bid": "0.77", "best_ask": "0.79"}, {"asset_id": "77997400651011819054222158182618580861479123177562866576575031403070672671390", "price": "0.25", "size": "1300", "side": "SELL", "hash": "8d35bd66d6690142bad16ff01cace2098b683d81", "best_bid": "0.21", "best_ask": "0.23"}], "timestamp": "1769384485694", "event_type": "price_change"}}
{"_local_timestamp": "2026-01-25T23:41:26.887650+00:00", "data": {"market": "0x61af02c9250c3917602e21c301e2f0cd032ea4e25bdef3751846b4d5f1c22799", "price_changes": [{"asset_id": "40581037591963443982506549884210281226867122905421206884675003828040093511244", "price": "0.75", "size": "1310", "side": "BUY", "hash": "cf6551065692127a8fa18737702ffd9e619c13fd", "best_bid": "0.77", "best_ask": "0.79"}, {"asset_id": "77997400651011819054222158182618580861479123177562866576575031403070672671390", "price": "0.25", "size": "1310", "side": "SELL", "hash": "80fa26dc575949284b92b225ec3d8a2921c68764", "best_bid": "0.21", "best_ask": "0.23"}], "timestamp": "1769384486817", "event_type": "price_change"}}
{"_local_timestamp": "2026-01-25T23:41:26.916166+00:00", "data": {"market": "0x61af02c9250c3917602e21c301e2f0cd032ea4e25bdef3751846b4d5f1c22799", "price_changes": [{"asset_id": "40581037591963443982506549884210281226867122905421206884675003828040093511244", "price": "0.75", "size": "1300", "side": "BUY", "hash": "d94ef3f8148c4eaf6f3397f69279bb7b3332abeb", "best_bid": "0.77", "best_ask": "0.79"}, {"asset_id": "77997400651011819054222158182618580861479123177562866576575031403070672671390", "price": "0.25", "size": "1300", "side": "SELL", "hash": "f7427dd5244e355c711148024700afa4151e2a74", "best_bid": "0.21", "best_ask": "0.23"}], "timestamp": "1769384486846", "event_type": "price_change"}}
{"_local_timestamp": "2026-01-25T23:41:28.888346+00:00", "data": {"market": "0x61af02c9250c3917602e21c301e2f0cd032ea4e25bdef3751846b4d5f1c22799", "price_changes": [{"asset_id": "77997400651011819054222158182618580861479123177562866576575031403070672671390", "price": "0.18", "size": "2525.54", "side": "BUY", "hash": "fcb25286716a9f72b12c8dc08f6079a0351d8409", "best_bid": "0.21", "best_ask": "0.23"}, {"asset_id": "40581037591963443982506549884210281226867122905421206884675003828040093511244", "price": "0.82", "size": "2525.54", "side": "SELL", "hash": "3914d39ed12ad12defb087336928276c753ad27a", "best_bid": "0.77", "best_ask": "0.79"}], "timestamp": "1769384488816", "event_type": "price_change"}}
{"_local_timestamp": "2026-01-25T23:41:30.911717+00:00", "data": {"market": "0x61af02c9250c3917602e21c301e2f0cd032ea4e25bdef3751846b4d5f1c22799", "price_changes": [{"asset_id": "77997400651011819054222158182618580861479123177562866576575031403070672671390", "price": "0.18", "size": "2515.54", "side": "BUY", "hash": "fabb6a3d62a25a63ae7d5950ad33039226556b18", "best_bid": "0.21", "best_ask": "0.23"}, {"asset_id": "40581037591963443982506549884210281226867122905421206884675003828040093511244", "price": "0.82", "size": "2515.54", "side": "SELL", "hash": "36391a4da2083da1eed16a10f621f6676e447433", "best_bid": "0.77", "best_ask": "0.79"}], "timestamp": "1769384490841", "event_type": "price_change"}}
{"_local_timestamp": "2026-01-25T23:41:32.238522+00:00", "data": {"market": "0x61af02c9250c3917602e21c301e2f0cd032ea4e25bdef3751846b4d5f1c22799", "price_changes": [{"asset_id": "77997400651011819054222158182618580861479123177562866576575031403070672671390", "price": "0.18", "size": "2525.54", "side": "BUY", "hash": "8424c2946d5573d005721819e8c0ec897e35a7ac", "best_bid": "0.21", "best_ask": "0.23"}, {"asset_id": "40581037591963443982506549884210281226867122905421206884675003828040093511244", "price": "0.82", "size": "2525.54", "side": "SELL", "hash": "9a3222d690baec861adc9bff48ba778636379a7a", "best_bid": "0.77", "best_ask": "0.79"}], "timestamp": "1769384492162", "event_type": "price_change"}}
{"_local_timestamp": "2026-01-25T23:41:32.310671+00:00", "data": {"market": "0x61af02c9250c3917602e21c301e2f0cd032ea4e25bdef3751846b4d5f1c22799", "price_changes": [{"asset_id": "77997400651011819054222158182618580861479123177562866576575031403070672671390", "price": "0.18", "size": "2515.54", "side": "BUY", "hash": "0c7219c86fc5fe21abc1418de7b7e6ac4045dae2", "best_bid": "0.21", "best_ask": "0.23"}, {"asset_id": "40581037591963443982506549884210281226867122905421206884675003828040093511244", "price": "0.82", "size": "2515.54", "side": "SELL", "hash": "b3d59c979de4de28bffbaf5a2e002db2fbd9c55b", "best_bid": "0.77", "best_ask": "0.79"}], "timestamp": "1769384492241", "event_type": "price_change"}}
{"_local_timestamp": "2026-01-25T23:41:33.707560+00:00", "data": {"market": "0x61af02c9250c3917602e21c301e2f0cd032ea4e25bdef3751846b4d5f1c22799", "price_changes": [{"asset_id": "40581037591963443982506549884210281226867122905421206884675003828040093511244", "price": "0.75", "size": "1310", "side": "BUY", "hash": "b1be20eb127abba3601121e1b8373dbb0c9742b9", "best_bid": "0.77", "best_ask": "0.79"}, {"asset_id": "77997400651011819054222158182618580861479123177562866576575031403070672671390", "price": "0.25", "size": "1310", "side": "SELL", "hash": "4059d9c7a04ed3935a17c02a12237e420f3ffb04", "best_bid": "0.21", "best_ask": "0.23"}], "timestamp": "1769384493635", "event_type": "price_change"}}
{"_local_timestamp": "2026-01-25T23:41:35.450229+00:00", "data": {"market": "0x61af02c9250c3917602e21c301e2f0cd032ea4e25bdef3751846b4d5f1c22799", "price_changes": [{"asset_id": "40581037591963443982506549884210281226867122905421206884675003828040093511244", "price": "0.75", "size": "1300", "side": "BUY", "hash": "3ce2d3a893b3817f06913dd366938167594628a6", "best_bid": "0.77", "best_ask": "0.79"}, {"asset_id": "77997400651011819054222158182618580861479123177562866576575031403070672671390", "price": "0.25", "size": "1300", "side": "SELL", "hash": "55c0becc90f4eaafff7e56212c70fb4acaa72439", "best_bid": "0.21", "best_ask": "0.23"}], "timestamp": "1769384495368", "event_type": "price_change"}}
{"_local_timestamp": "2026-01-25T23:41:36.772557+00:00", "data": {"market": "0x61af02c9250c3917602e21c301e2f0cd032ea4e25bdef3751846b4d5f1c22799", "price_changes": [{"asset_id": "77997400651011819054222158182618580861479123177562866576575031403070672671390", "price": "0.18", "size": "2525.54", "side": "BUY", "hash": "7c87609eb0432184e2791c78663eea78b18919d1", "best_bid": "0.21", "best_ask": "0.23"}, {"asset_id": "40581037591963443982506549884210281226867122905421206884675003828040093511244", "price": "0.82", "size": "2525.54", "side": "SELL", "hash": "6c62a76716efe41260d5a54e68d64665606d99c8", "best_bid": "0.77", "best_ask": "0.79"}], "timestamp": "1769384496709", "event_type": "price_change"}}
{"_local_timestamp": "2026-01-25T23:41:36.972605+00:00", "data": {"market": "0x61af02c9250c3917602e21c301e2f0cd032ea4e25bdef3751846b4d5f1c22799", "price_changes": [{"asset_id": "77997400651011819054222158182618580861479123177562866576575031403070672671390", "price": "0.18", "size": "2515.54", "side": "BUY", "hash": "cf341163682aaf97b9d0b4b7ede7b83d86d2e05e", "best_bid": "0.21", "best_ask": "0.23"}, {"asset_id": "40581037591963443982506549884210281226867122905421206884675003828040093511244", "price": "0.82", "size": "2515.54", "side": "SELL", "hash": "41e3f14ac4de4189b811dfff72aaf3225d8199f2", "best_bid": "0.77", "best_ask": "0.79"}], "timestamp": "1769384496907", "event_type": "price_change"}}
{"_local_timestamp": "2026-01-25T23:41:38.424131+00:00", "data": {"market": "0x61af02c9250c3917602e21c301e2f0cd032ea4e25bdef3751846b4d5f1c22799", "price_changes": [{"asset_id": "40581037591963443982506549884210281226867122905421206884675003828040093511244", "price": "0.75", "size": "1310", "side": "BUY", "hash": "711e5d49ca58ff32647b7ebf1727609771ee33de", "best_bid": "0.77", "best_ask": "0.79"}, {"asset_id": "77997400651011819054222158182618580861479123177562866576575031403070672671390", "price": "0.25", "size": "1310", "side": "SELL", "hash": "34458604cac6c859d03dece3ba944a934b1643a9", "best_bid": "0.21", "best_ask": "0.23"}], "timestamp": "1769384498354", "event_type": "price_change"}}
{"_local_timestamp": "2026-01-25T23:41:40.122276+00:00", "data": {"market": "0x61af02c9250c3917602e21c301e2f0cd032ea4e25bdef3751846b4d5f1c22799", "price_changes": [{"asset_id": "40581037591963443982506549884210281226867122905421206884675003828040093511244", "price": "0.75", "size": "1300", "side": "BUY", "hash": "370ae314644b3c8d7758f304d37c4148ef8776c1", "best_bid": "0.77", "best_ask": "0.79"}, {"asset_id": "77997400651011819054222158182618580861479123177562866576575031403070672671390", "price": "0.25", "size": "1300", "side": "SELL", "hash": "4f4506bfef322f1747cfa33018e2970fafafd66c", "best_bid": "0.21", "best_ask": "0.23"}], "timestamp": "1769384500035", "event_type": "price_change"}}
{"_local_timestamp": "2026-01-25T23:41:41.057882+00:00", "data": {"market": "0x61af02c9250c3917602e21c301e2f0cd032ea4e25bdef3751846b4d5f1c22799", "price_changes": [{"asset_id": "40581037591963443982506549884210281226867122905421206884675003828040093511244", "price": "0.75", "size": "1310", "side": "BUY", "hash": "b44fe6791c8f23df8cda7bae579efe9474b35ddb", "best_bid": "0.77", "best_ask": "0.79"}, {"asset_id": "77997400651011819054222158182618580861479123177562866576575031403070672671390", "price": "0.25", "size": "1310", "side": "SELL", "hash": "0c4f5955b8ed1d388c3c8edca5bb86980af851dd", "best_bid": "0.21", "best_ask": "0.23"}], "timestamp": "1769384500991", "event_type": "price_change"}}
{"_local_timestamp": "2026-01-25T23:41:41.284829+00:00", "data": {"market": "0x61af02c9250c3917602e21c301e2f0cd032ea4e25bdef3751846b4d5f1c22799", "price_changes": [{"asset_id": "40581037591963443982506549884210281226867122905421206884675003828040093511244", "price": "0.75", "size": "1300", "side": "BUY", "hash": "feb52550ad9b030bf599f8b8c4ef42bed0078bce", "best_bid": "0.77", "best_ask": "0.79"}, {"asset_id": "77997400651011819054222158182618580861479123177562866576575031403070672671390", "price": "0.25", "size": "1300", "side": "SELL", "hash": "64f595b3e67261972ab60f29077a908b0da57293", "best_bid": "0.21", "best_ask": "0.23"}], "timestamp": "1769384501211", "event_type": "price_change"}}
{"_local_timestamp": "2026-01-25T23:41:41.607110+00:00", "data": {"market": "0x61af02c9250c3917602e21c301e2f0cd032ea4e25bdef3751846b4d5f1c22799", "price_changes": [{"asset_id": "77997400651011819054222158182618580861479123177562866576575031403070672671390", "price": "0.18", "size": "2525.54", "side": "BUY", "hash": "2f63894a25076a5c2d7584ef839468c8e3df9215", "best_bid": "0.21", "best_ask": "0.23"}, {"asset_id": "40581037591963443982506549884210281226867122905421206884675003828040093511244", "price": "0.82", "size": "2525.54", "side": "SELL", "hash": "2e871057b6fe2c8decb2e2e460012e6a8ab1c9f5", "best_bid": "0.77", "best_ask": "0.79"}], "timestamp": "1769384501539", "event_type": "price_change"}}
{"_local_timestamp": "2026-01-25T23:41:43.341738+00:00", "data": {"market": "0x61af02c9250c3917602e21c301e2f0cd032ea4e25bdef3751846b4d5f1c22799", "price_changes": [{"asset_id": "77997400651011819054222158182618580861479123177562866576575031403070672671390", "price": "0.18", "size": "2515.54", "side": "BUY", "hash": "acd7eb00ce06db80787b7108d253a49af2b8a39e", "best_bid": "0.21", "best_ask": "0.23"}, {"asset_id": "40581037591963443982506549884210281226867122905421206884675003828040093511244", "price": "0.82", "size": "2515.54", "side": "SELL", "hash": "63bcd4faeb0e98b3d12c3d3c40b0cc31694ead42", "best_bid": "0.77", "best_ask": "0.79"}], "timestamp": "1769384503277", "event_type": "price_change"}}
{"_local_timestamp": "2026-01-25T23:41:44.643492+00:00", "data": {"market": "0x61af02c9250c3917602e21c301e2f0cd032ea4e25bdef3751846b4d5f1c22799", "price_changes": [{"asset_id": "40581037591963443982506549884210281226867122905421206884675003828040093511244", "price": "0.75", "size": "1310", "side": "BUY", "hash": "df3de9857e281f6ce6453a8ea50281d2287d438e", "best_bid": "0.77", "best_ask": "0.79"}, {"asset_id": "77997400651011819054222158182618580861479123177562866576575031403070672671390", "price": "0.25", "size": "1310", "side": "SELL", "hash": "e01e685e47ae6dd1344b5f09a321faf2b2854116", "best_bid": "0.21", "best_ask": "0.23"}], "timestamp": "1769384504578", "event_type": "price_change"}}
{"_local_timestamp": "2026-01-25T23:41:44.800782+00:00", "data": {"market": "0x61af02c9250c3917602e21c301e2f0cd032ea4e25bdef3751846b4d5f1c22799", "price_changes": [{"asset_id": "40581037591963443982506549884210281226867122905421206884675003828040093511244", "price": "0.75", "size": "1300", "side": "BUY", "hash": "c2b70b7f8c80e83d613c073c8f79542d7f02212a", "best_bid": "0.77", "best_ask": "0.79"}, {"asset_id": "77997400651011819054222158182618580861479123177562866576575031403070672671390", "price": "0.25", "size": "1300", "side": "SELL", "hash": "c414310b2b60ca3e8fedcd4f357451c3b53b9a17", "best_bid": "0.21", "best_ask": "0.23"}], "timestamp": "1769384504721", "event_type": "price_change"}}
{"_local_timestamp": "2026-01-25T23:41:44.996282+00:00", "data": {"market": "0x61af02c9250c3917602e21c301e2f0cd032ea4e25bdef3751846b4d5f1c22799", "price_changes": [{"asset_id": "77997400651011819054222158182618580861479123177562866576575031403070672671390", "price": "0.18", "size": "2525.54", "side": "BUY", "hash": "abf8d0e0a5ca73ebd3a2668c6582e3e4881b0fb0", "best_bid": "0.21", "best_ask": "0.23"}, {"asset_id": "40581037591963443982506549884210281226867122905421206884675003828040093511244", "price": "0.82", "size": "2525.54", "side": "SELL", "hash": "2e8ec54d4c498e19b0bf283730dbe20d4ee3a9d9", "best_bid": "0.77", "best_ask": "0.79"}], "timestamp": "1769384504929", "event_type": "price_change"}}
{"_local_timestamp": "2026-01-25T23:41:46.318211+00:00", "data": {"market": "0x61af02c9250c3917602e21c301e2f0cd032ea4e25bdef3751846b4d5f1c22799", "price_changes": [{"asset_id": "77997400651011819054222158182618580861479123177562866576575031403070672671390", "price": "0.18", "size": "2515.54", "side": "BUY", "hash": "ff5f35095fb40280c42c8171714f49466a7171a3", "best_bid": "0.21", "best_ask": "0.23"}, {"asset_id": "40581037591963443982506549884210281226867122905421206884675003828040093511244", "price": "0.82", "size": "2515.54", "side": "SELL", "hash": "1bd59c4133df11aff59442f664155d83031ac281", "best_bid": "0.77", "best_ask": "0.79"}], "timestamp": "1769384506250", "event_type": "price_change"}}
{"_local_timestamp": "2026-01-25T23:41:47.342604+00:00", "data": {"market": "0x61af02c9250c3917602e21c301e2f0cd032ea4e25bdef3751846b4d5f1c22799", "price_changes": [{"asset_id": "77997400651011819054222158182618580861479123177562866576575031403070672671390", "price": "0.18", "size": "2525.54", "side": "BUY", "hash": "7bd61b99e37bfa34f77013f6718564de479fa6f4", "best_bid": "0.21", "best_ask": "0.23"}, {"asset_id": "40581037591963443982506549884210281226867122905421206884675003828040093511244", "price": "0.82", "size": "2525.54", "side": "SELL", "hash": "9cace94ea1caf75d2b4ba63648f24853d4731e03", "best_bid": "0.77", "best_ask": "0.79"}], "timestamp": "1769384507274", "event_type": "price_change"}}
{"_local_timestamp": "2026-01-25T23:41:47.352533+00:00", "data": {"market": "0x61af02c9250c3917602e21c301e2f0cd032ea4e25bdef3751846b4d5f1c22799", "price_changes": [{"asset_id": "77997400651011819054222158182618580861479123177562866576575031403070672671390", "price": "0.18", "size": "2515.54", "side": "BUY", "hash": "5c92de719dc29131b62ea8c60090ef2ebfb18a18", "best_bid": "0.21", "best_ask": "0.23"}, {"asset_id": "40581037591963443982506549884210281226867122905421206884675003828040093511244", "price": "0.82", "size": "2515.54", "side": "SELL", "hash": "ecaeb56be57f3d8a16bcac8a8eac5a0022711546", "best_bid": "0.77", "best_ask": "0.79"}], "timestamp": "1769384507283", "event_type": "price_change"}}
{"_local_timestamp": "2026-01-25T23:41:47.354013+00:00", "data": {"market": "0x61af02c9250c3917602e21c301e2f0cd032ea4e25bdef3751846b4d5f1c22799", "price_changes": [{"asset_id": "40581037591963443982506549884210281226867122905421206884675003828040093511244", "price": "0.75", "size": "1310", "side": "BUY", "hash": "9a6d475225cc6c7817b59a0186853b7c2b8607bd", "best_bid": "0.77", "best_ask": "0.79"}, {"asset_id": "77997400651011819054222158182618580861479123177562866576575031403070672671390", "price": "0.25", "size": "1310", "side": "SELL", "hash": "9ca9ac83d778bb5d271e17c575f6a7509a48ec3a", "best_bid": "0.21", "best_ask": "0.23"}], "timestamp": "1769384507286", "event_type": "price_change"}}
{"_local_timestamp": "2026-01-25T23:41:48.098274+00:00", "data": {"market": "0x61af02c9250c3917602e21c301e2f0cd032ea4e25bdef3751846b4d5f1c22799", "price_changes": [{"asset_id": "40581037591963443982506549884210281226867122905421206884675003828040093511244", "price": "0.8", "size": "80.22", "side": "SELL", "hash": "075f49f20bf578993c5f9e8376c7ab089531b9a8", "best_bid": "0.77", "best_ask": "0.79"}, {"asset_id": "77997400651011819054222158182618580861479123177562866576575031403070672671390", "price": "0.2", "size": "80.22", "side": "BUY", "hash": "8b43f85a73fa2cb4cd61c13ecf9fa970937aafda", "best_bid": "0.21", "best_ask": "0.23"}], "timestamp": "1769384508003", "event_type": "price_change"}}
{"_local_timestamp": "2026-01-25T23:41:49.438511+00:00", "data": {"market": "0x61af02c9250c3917602e21c301e2f0cd032ea4e25bdef3751846b4d5f1c22799", "price_changes": [{"asset_id": "40581037591963443982506549884210281226867122905421206884675003828040093511244", "price": "0.75", "size": "1300", "side": "BUY", "hash": "dbca301566d9ea6ce21cecf0bcf6bd13160bdf1a", "best_bid": "0.77", "best_ask": "0.79"}, {"asset_id": "77997400651011819054222158182618580861479123177562866576575031403070672671390", "price": "0.25", "size": "1300", "side": "SELL", "hash": "698610c44729f620ed1f838dc6794bd1b3c78769", "best_bid": "0.21", "best_ask": "0.23"}], "timestamp": "1769384509362", "event_type": "price_change"}}
{"_local_timestamp": "2026-01-25T23:41:49.477111+00:00", "data": {"market": "0x61af02c9250c3917602e21c301e2f0cd032ea4e25bdef3751846b4d5f1c22799", "price_changes": [{"asset_id": "40581037591963443982506549884210281226867122905421206884675003828040093511244", "price": "0.25", "size": "404", "side": "BUY", "hash": "a1fd4f1e38174fbf90657b11c15bee478584dc1c", "best_bid": "0.77", "best_ask": "0.79"}, {"asset_id": "77997400651011819054222158182618580861479123177562866576575031403070672671390", "price": "0.75", "size": "404", "side": "SELL", "hash": "65dd7ce43712172f7aca0b0884021e6485f2c979", "best_bid": "0.21", "best_ask": "0.23"}], "timestamp": "1769384509399", "event_type": "price_change"}}
{"_local_timestamp": "2026-01-25T23:41:49.758525+00:00", "data": {"market": "0x61af02c9250c3917602e21c301e2f0cd032ea4e25bdef3751846b4d5f1c22799", "price_changes": [{"asset_id": "40581037591963443982506549884210281226867122905421206884675003828040093511244", "price": "0.21", "size": "2098", "side": "BUY", "hash": "6f9bb1450da312b1bbd6770471a1796072cf95a8", "best_bid": "0.77", "best_ask": "0.79"}, {"asset_id": "77997400651011819054222158182618580861479123177562866576575031403070672671390", "price": "0.79", "size": "2098", "side": "SELL", "hash": "4cfae98b59f240437427514afa03c2281b46b2ab", "best_bid": "0.21", "best_ask": "0.23"}], "timestamp": "1769384509658", "event_type": "price_change"}}
{"_local_timestamp": "2026-01-25T23:41:50.566031+00:00", "data": {"market": "0x61af02c9250c3917602e21c301e2f0cd032ea4e25bdef3751846b4d5f1c22799", "price_changes": [{"asset_id": "40581037591963443982506549884210281226867122905421206884675003828040093511244", "price": "0.75", "size": "1310", "side": "BUY", "hash": "2d52412b860a69f3f892128a08c2bdb3cdf13fa9", "best_bid": "0.77", "best_ask": "0.79"}, {"asset_id": "77997400651011819054222158182618580861479123177562866576575031403070672671390", "price": "0.25", "size": "1310", "side": "SELL", "hash": "2cab746a679b586a60e21458c02f10f164114238", "best_bid": "0.21", "best_ask": "0.23"}], "timestamp": "1769384510500", "event_type": "price_change"}}
{"_local_timestamp": "2026-01-25T23:41:50.722497+00:00", "data": {"market": "0x61af02c9250c3917602e21c301e2f0cd032ea4e25bdef3751846b4d5f1c22799", "price_changes": [{"asset_id": "40581037591963443982506549884210281226867122905421206884675003828040093511244", "price": "0.75", "size": "1300", "side": "BUY", "hash": "5f858dbdb8abcb49ac197bfde818e73a000fb4c8", "best_bid": "0.77", "best_ask": "0.79"}, {"asset_id": "77997400651011819054222158182618580861479123177562866576575031403070672671390", "price": "0.25", "size": "1300", "side": "SELL", "hash": "501bb7a0be30018b08ec7fb0b86f6a8040ad359f", "best_bid": "0.21", "best_ask": "0.23"}], "timestamp": "1769384510655", "event_type": "price_change"}}
{"_local_timestamp": "2026-01-25T23:41:50.789920+00:00", "data": {"market": "0x61af02c9250c3917602e21c301e2f0cd032ea4e25bdef3751846b4d5f1c22799", "price_changes": [{"asset_id": "77997400651011819054222158182618580861479123177562866576575031403070672671390", "price": "0.18", "size": "2525.54", "side": "BUY", "hash": "6b9219ab4a62c4352ad0dd359d66b0b62e7a6cb6", "best_bid": "0.21", "best_ask": "0.23"}, {"asset_id": "40581037591963443982506549884210281226867122905421206884675003828040093511244", "price": "0.82", "size": "2525.54", "side": "SELL", "hash": "2512bd9fe278003e3342adde73cab650a8ec53a9", "best_bid": "0.77", "best_ask": "0.79"}], "timestamp": "1769384510719", "event_type": "price_change"}}
{"_local_timestamp": "2026-01-25T23:41:50.956776+00:00", "data": {"market": "0x61af02c9250c3917602e21c301e2f0cd032ea4e25bdef3751846b4d5f1c22799", "price_changes": [{"asset_id": "40581037591963443982506549884210281226867122905421206884675003828040093511244", "price": "0.2", "size": "140", "side": "BUY", "hash": "945c12bbcd0219bae3bb78052dc69ff132c8cef8", "best_bid": "0.77", "best_ask": "0.79"}, {"asset_id": "77997400651011819054222158182618580861479123177562866576575031403070672671390", "price": "0.8", "size": "140", "side": "SELL", "hash": "5c81dec2b1c73521ee29562790594290aff3f85f", "best_bid": "0.21", "best_ask": "0.23"}], "timestamp": "1769384510770", "event_type": "price_change"}}
{"_local_timestamp": "2026-01-25T23:41:52.742446+00:00", "data": {"market": "0x61af02c9250c3917602e21c301e2f0cd032ea4e25bdef3751846b4d5f1c22799", "price_changes": [{"asset_id": "40581037591963443982506549884210281226867122905421206884675003828040093511244", "price": "0.17", "size": "1290", "side": "BUY", "hash": "795601069b521ceaece7df3ad5416dec2a9780fd", "best_bid": "0.77", "best_ask": "0.79"}, {"asset_id": "77997400651011819054222158182618580861479123177562866576575031403070672671390", "price": "0.83", "size": "1290", "side": "SELL", "hash": "78082d52055762ffda852b706fb6a8cfd13a100f", "best_bid": "0.21", "best_ask": "0.23"}], "timestamp": "1769384511776", "event_type": "price_change"}}
{"_local_timestamp": "2026-01-25T23:41:52.743966+00:00", "data": {"market": "0x61af02c9250c3917602e21c301e2f0cd032ea4e25bdef3751846b4d5f1c22799", "price_changes": [{"asset_id": "77997400651011819054222158182618580861479123177562866576575031403070672671390", "price": "0.18", "size": "2515.54", "side": "BUY", "hash": "bfafc6a5f1e87921d1937b1a16d62cb83dc6511f", "best_bid": "0.21", "best_ask": "0.23"}, {"asset_id": "40581037591963443982506549884210281226867122905421206884675003828040093511244", "price": "0.82", "size": "2515.54", "side": "SELL", "hash": "aa3de7c540a317fd9a460b9554252391739054ef", "best_bid": "0.77", "best_ask": "0.79"}], "timestamp": "1769384512644", "event_type": "price_change"}}
{"_local_timestamp": "2026-01-25T23:41:53.545431+00:00", "data": {"market": "0x61af02c9250c3917602e21c301e2f0cd032ea4e25bdef3751846b4d5f1c22799", "price_changes": [{"asset_id": "77997400651011819054222158182618580861479123177562866576575031403070672671390", "price": "0.18", "size": "2525.54", "side": "BUY", "hash": "27eac59fb82f0477186fedf654320d75ae882cfc", "best_bid": "0.21", "best_ask": "0.23"}, {"asset_id": "40581037591963443982506549884210281226867122905421206884675003828040093511244", "price": "0.82", "size": "2525.54", "side": "SELL", "hash": "6064a1ebdd214f08eba64a6920ce6c47f6d18c45", "best_bid": "0.77", "best_ask": "0.79"}], "timestamp": "1769384513476", "event_type": "price_change"}}
{"_local_timestamp": "2026-01-25T23:41:53.657096+00:00", "data": {"market": "0x61af02c9250c3917602e21c301e2f0cd032ea4e25bdef3751846b4d5f1c22799", "price_changes": [{"asset_id": "77997400651011819054222158182618580861479123177562866576575031403070672671390", "price": "0.18", "size": "2515.54", "side": "BUY", "hash": "73960dfe301ef5b579a832c56824411466e875bb", "best_bid": "0.21", "best_ask": "0.23"}, {"asset_id": "40581037591963443982506549884210281226867122905421206884675003828040093511244", "price": "0.82", "size": "2515.54", "side": "SELL", "hash": "20044567b6ab4bee64d929f5d84600cae7ba12f2", "best_bid": "0.77", "best_ask": "0.79"}], "timestamp": "1769384513591", "event_type": "price_change"}}
{"_local_timestamp": "2026-01-25T23:41:53.742609+00:00", "data": {"market": "0x61af02c9250c3917602e21c301e2f0cd032ea4e25bdef3751846b4d5f1c22799", "price_changes": [{"asset_id": "40581037591963443982506549884210281226867122905421206884675003828040093511244", "price": "0.75", "size": "1310", "side": "BUY", "hash": "c63348339b9c4b0b8fe6a5b269771c5be855a9b6", "best_bid": "0.77", "best_ask": "0.79"}, {"asset_id": "77997400651011819054222158182618580861479123177562866576575031403070672671390", "price": "0.25", "size": "1310", "side": "SELL", "hash": "3ab95b308b3c51fb3869c07d391945a9bfd4f0f9", "best_bid": "0.21", "best_ask": "0.23"}], "timestamp": "1769384513672", "event_type": "price_change"}}
{"_local_timestamp": "2026-01-25T23:41:54.291230+00:00", "data": {"market": "0x61af02c9250c3917602e21c301e2f0cd032ea4e25bdef3751846b4d5f1c22799", "price_changes": [{"asset_id": "40581037591963443982506549884210281226867122905421206884675003828040093511244", "price": "0.75", "size": "1300", "side": "BUY", "hash": "e84bb16a1236253fa8014574dabccc55c03de80b", "best_bid": "0.77", "best_ask": "0.79"}, {"asset_id": "77997400651011819054222158182618580861479123177562866576575031403070672671390", "price": "0.25", "size": "1300", "side": "SELL", "hash": "1e815131805ba23c8a8bfbf8474e7167b4566ceb", "best_bid": "0.21", "best_ask": "0.23"}], "timestamp": "1769384514225", "event_type": "price_change"}}
{"_local_timestamp": "2026-01-25T23:42:24.689645+00:00", "data": {"market": "0x61af02c9250c3917602e21c301e2f0cd032ea4e25bdef3751846b4d5f1c22799", "price_changes": [{"asset_id": "40581037591963443982506549884210281226867122905421206884675003828040093511244", "price": "0.19", "size": "0", "side": "BUY", "hash": "3650658ee28227d55e179f33d27a570cc4bbc3ea", "best_bid": "0.77", "best_ask": "0.79"}, {"asset_id": "77997400651011819054222158182618580861479123177562866576575031403070672671390", "price": "0.81", "size": "0", "side": "SELL", "hash": "1d9310602f5bd35e2ee03325f7d45eab9c51ae17", "best_bid": "0.21", "best_ask": "0.23"}], "timestamp": "1769384544469", "event_type": "price_change"}}
{"_local_timestamp": "2026-01-25T23:42:25.233550+00:00", "data": {"market": "0x61af02c9250c3917602e21c301e2f0cd032ea4e25bdef3751846b4d5f1c22799", "price_changes": [{"asset_id": "40581037591963443982506549884210281226867122905421206884675003828040093511244", "price": "0.17", "size": "1390", "side": "BUY", "hash": "d2fd605372fbb41b7403c42cf712147d16e891e8", "best_bid": "0.77", "best_ask": "0.79"}, {"asset_id": "77997400651011819054222158182618580861479123177562866576575031403070672671390", "price": "0.83", "size": "1390", "side": "SELL", "hash": "f1766658d6d281670dc46ddf82cb22b6dce4f8b6", "best_bid": "0.21", "best_ask": "0.23"}], "timestamp": "1769384544927", "event_type": "price_change"}}
{"_local_timestamp": "2026-01-25T23:42:44.724483+00:00", "data": {"market": "0x61af02c9250c3917602e21c301e2f0cd032ea4e25bdef3751846b4d5f1c22799", "price_changes": [{"asset_id": "40581037591963443982506549884210281226867122905421206884675003828040093511244", "price": "0.25", "size": "354", "side": "BUY", "hash": "9911a192ebee8755b8c368382f8f08dce687d905", "best_bid": "0.77", "best_ask": "0.79"}, {"asset_id": "77997400651011819054222158182618580861479123177562866576575031403070672671390", "price": "0.75", "size": "354", "side": "SELL", "hash": "ab7633ff8fd0439889e729803f3fc0bd7ab5aacd", "best_bid": "0.21", "best_ask": "0.23"}], "timestamp": "1769384564589", "event_type": "price_change"}}
{"_local_timestamp": "2026-01-25T23:42:45.795869+00:00", "data": {"market": "0x61af02c9250c3917602e21c301e2f0cd032ea4e25bdef3751846b4d5f1c22799", "price_changes": [{"asset_id": "40581037591963443982506549884210281226867122905421206884675003828040093511244", "price": "0.21", "size": "2148", "side": "BUY", "hash": "98fff40844cd1a3a2b665c60caa0e38ba58871ed", "best_bid": "0.77", "best_ask": "0.79"}, {"asset_id": "77997400651011819054222158182618580861479123177562866576575031403070672671390", "price": "0.79", "size": "2148", "side": "SELL", "hash": "24f4d62023aa7ca97faab2a9c63427f973af2871", "best_bid": "0.21", "best_ask": "0.23"}], "timestamp": "1769384565614", "event_type": "price_change"}}
{"_local_timestamp": "2026-01-25T23:42:55.741594+00:00", "data": {"market": "0x61af02c9250c3917602e21c301e2f0cd032ea4e25bdef3751846b4d5f1c22799", "price_changes": [{"asset_id": "40581037591963443982506549884210281226867122905421206884675003828040093511244", "price": "0.8", "size": "120.22", "side": "SELL", "hash": "3e4857b9dc16fe11e2ce4ea7fb9c925213a754a7", "best_bid": "0.77", "best_ask": "0.79"}, {"asset_id": "77997400651011819054222158182618580861479123177562866576575031403070672671390", "price": "0.2", "size": "120.22", "side": "BUY", "hash": "2234fb30083fb5a5c39943781ef55e27eb5c4e0f", "best_bid": "0.21", "best_ask": "0.23"}], "timestamp": "1769384575602", "event_type": "price_change"}}
{"_local_timestamp": "2026-01-25T23:43:32.143164+00:00", "data": {"market": "0x61af02c9250c3917602e21c301e2f0cd032ea4e25bdef3751846b4d5f1c22799", "price_changes": [{"asset_id": "40581037591963443982506549884210281226867122905421206884675003828040093511244", "price": "0.77", "size": "29.99", "side": "BUY", "hash": "b6024d410011b8acae9e737ab737dbaab0c54afb", "best_bid": "0.77", "best_ask": "0.79"}, {"asset_id": "77997400651011819054222158182618580861479123177562866576575031403070672671390", "price": "0.23", "size": "29.99", "side": "SELL", "hash": "cabd696ed5bd97230ad52a6310eaf03ebdd7daf2", "best_bid": "0.21", "best_ask": "0.23"}], "timestamp": "1769384612001", "event_type": "price_change"}}
{"_local_timestamp": "2026-01-25T23:43:35.457821+00:00", "data": {"market": "0x61af02c9250c3917602e21c301e2f0cd032ea4e25bdef3751846b4d5f1c22799", "price_changes": [{"asset_id": "77997400651011819054222158182618580861479123177562866576575031403070672671390", "price": "0.02", "size": "1250", "side": "BUY", "hash": "a6c549d0865a5a9bd5d5a48f4405f66e02a26752", "best_bid": "0.21", "best_ask": "0.23"}, {"asset_id": "40581037591963443982506549884210281226867122905421206884675003828040093511244", "price": "0.98", "size": "1250", "side": "SELL", "hash": "9a080ec963bba95eb5ecd28a7cc3235556d645b5", "best_bid": "0.77", "best_ask": "0.79"}], "timestamp": "1769384615326", "event_type": "price_change"}}
{"_local_timestamp": "2026-01-25T23:43:35.614461+00:00", "data": {"market": "0x61af02c9250c3917602e21c301e2f0cd032ea4e25bdef3751846b4d5f1c22799", "price_changes": [{"asset_id": "77997400651011819054222158182618580861479123177562866576575031403070672671390", "price": "0.02", "size": "4284", "side": "BUY", "hash": "dcfc5a55827a488e5eb782e1ea5743f6f4eb500a", "best_bid": "0.21", "best_ask": "0.23"}, {"asset_id": "40581037591963443982506549884210281226867122905421206884675003828040093511244", "price": "0.98", "size": "4284", "side": "SELL", "hash": "5909e946c8432e5367d23f46287fda06fbd60646", "best_bid": "0.77", "best_ask": "0.79"}], "timestamp": "1769384615484", "event_type": "price_change"}}
{"_local_timestamp": "2026-01-25T23:43:35.805444+00:00", "data": {"market": "0x61af02c9250c3917602e21c301e2f0cd032ea4e25bdef3751846b4d5f1c22799", "price_changes": [{"asset_id": "40581037591963443982506549884210281226867122905421206884675003828040093511244", "price": "0.3", "size": "250", "side": "BUY", "hash": "a7edd6305564e70bb3a153adada0b94ff4fd2c6c", "best_bid": "0.77", "best_ask": "0.79"}, {"asset_id": "77997400651011819054222158182618580861479123177562866576575031403070672671390", "price": "0.7", "size": "250", "side": "SELL", "hash": "daf74a236a58540f209e12975a181adb1d03e228", "best_bid": "0.21", "best_ask": "0.23"}], "timestamp": "1769384615680", "event_type": "price_change"}}
{"_local_timestamp": "2026-01-25T23:43:35.990874+00:00", "data": {"market": "0x61af02c9250c3917602e21c301e2f0cd032ea4e25bdef3751846b4d5f1c22799", "price_changes": [{"asset_id": "40581037591963443982506549884210281226867122905421206884675003828040093511244", "price": "0.32", "size": "3507", "side": "BUY", "hash": "7c109ad668f1f67c0067bd592949c3c1c3106b62", "best_bid": "0.77", "best_ask": "0.79"}, {"asset_id": "77997400651011819054222158182618580861479123177562866576575031403070672671390", "price": "0.68", "size": "3507", "side": "SELL", "hash": "5a111e42f3f099e669e653c1d5c41fac956dc99e", "best_bid": "0.21", "best_ask": "0.23"}], "timestamp": "1769384615856", "event_type": "price_change"}}
{"_local_timestamp": "2026-01-25T23:44:12.630072+00:00", "data": {"market": "0x61af02c9250c3917602e21c301e2f0cd032ea4e25bdef3751846b4d5f1c22799", "price_changes": [{"asset_id": "40581037591963443982506549884210281226867122905421206884675003828040093511244", "price": "0.77", "size": "49.99", "side": "BUY", "hash": "12a087a7c848c439cd5a406457654d8188a5aa0f", "best_bid": "0.77", "best_ask": "0.79"}, {"asset_id": "77997400651011819054222158182618580861479123177562866576575031403070672671390", "price": "0.23", "size": "49.99", "side": "SELL", "hash": "06322501e5d07f1d00e5145a8368f4a920f64168", "best_bid": "0.21", "best_ask": "0.23"}], "timestamp": "1769384652490", "event_type": "price_change"}}
{"_local_timestamp": "2026-01-25T23:44:32.457309+00:00", "data": {"market": "0x61af02c9250c3917602e21c301e2f0cd032ea4e25bdef3751846b4d5f1c22799", "price_changes": [{"asset_id": "40581037591963443982506549884210281226867122905421206884675003828040093511244", "price": "0.21", "size": "150", "side": "BUY", "hash": "bef0b8a51470afa6c31e93fd13033b6b91a272a7", "best_bid": "0.77", "best_ask": "0.79"}, {"asset_id": "77997400651011819054222158182618580861479123177562866576575031403070672671390", "price": "0.79", "size": "150", "side": "SELL", "hash": "77db37903da38d4eff643c2febe37edc92c095ad", "best_bid": "0.21", "best_ask": "0.23"}], "timestamp": "1769384672297", "event_type": "price_change"}}
{"_local_timestamp": "2026-01-25T23:44:51.098776+00:00", "data": {"market": "0x61af02c9250c3917602e21c301e2f0cd032ea4e25bdef3751846b4d5f1c22799", "price_changes": [{"asset_id": "77997400651011819054222158182618580861479123177562866576575031403070672671390", "price": "0.16", "size": "321", "side": "BUY", "hash": "09dd4bc2824c47f38372e4a633aac18cdfe92402", "best_bid": "0.21", "best_ask": "0.23"}, {"asset_id": "40581037591963443982506549884210281226867122905421206884675003828040093511244", "price": "0.84", "size": "321", "side": "SELL", "hash": "3490cea79d88f6652056d8ee58b6f3007dab97be", "best_bid": "0.77", "best_ask": "0.79"}], "timestamp": "1769384691000", "event_type": "price_change"}}
{"_local_timestamp": "2026-01-25T23:44:51.114846+00:00", "data": {"market": "0x61af02c9250c3917602e21c301e2f0cd032ea4e25bdef3751846b4d5f1c22799", "price_changes": [{"asset_id": "77997400651011819054222158182618580861479123177562866576575031403070672671390", "price": "0.13", "size": "709", "side": "BUY", "hash": "5aa81213a731b61135d4e25c7a12a057b0478236", "best_bid": "0.21", "best_ask": "0.23"}, {"asset_id": "40581037591963443982506549884210281226867122905421206884675003828040093511244", "price": "0.87", "size": "709", "side": "SELL", "hash": "a19ec12840d839c02b499bd9c19af4727c5c8ed5", "best_bid": "0.77", "best_ask": "0.79"}], "timestamp": "1769384691003", "event_type": "price_change"}}
{"_local_timestamp": "2026-01-25T23:44:51.119465+00:00", "data": {"market": "0x61af02c9250c3917602e21c301e2f0cd032ea4e25bdef3751846b4d5f1c22799", "price_changes": [{"asset_id": "77997400651011819054222158182618580861479123177562866576575031403070672671390", "price": "0.11", "size": "1773", "side": "BUY", "hash": "da1471e4d82c1c8591403b373548547f74b8b4d8", "best_bid": "0.21", "best_ask": "0.23"}, {"asset_id": "40581037591963443982506549884210281226867122905421206884675003828040093511244", "price": "0.89", "size": "1773", "side": "SELL", "hash": "efbe3e050065d48bb5327ae6d636e7f1310fd296", "best_bid": "0.77", "best_ask": "0.79"}], "timestamp": "1769384691005", "event_type": "price_change"}}
{"_local_timestamp": "2026-01-25T23:45:07.080601+00:00", "data": {"market": "0x61af02c9250c3917602e21c301e2f0cd032ea4e25bdef3751846b4d5f1c22799", "price_changes": [{"asset_id": "77997400651011819054222158182618580861479123177562866576575031403070672671390", "price": "0.16", "size": "296", "side": "BUY", "hash": "70efb7c2654fabef87b1c0c9fef9d2fca9747197", "best_bid": "0.21", "best_ask": "0.23"}, {"asset_id": "40581037591963443982506549884210281226867122905421206884675003828040093511244", "price": "0.84", "size": "296", "side": "SELL", "hash": "21f0f5d7700ce550e9424ddabf5e67d582067675", "best_bid": "0.77", "best_ask": "0.79"}], "timestamp": "1769384707000", "event_type": "price_change"}}
{"_local_timestamp": "2026-01-25T23:45:07.084447+00:00", "data": {"market": "0x61af02c9250c3917602e21c301e2f0cd032ea4e25bdef3751846b4d5f1c22799", "price_changes": [{"asset_id": "77997400651011819054222158182618580861479123177562866576575031403070672671390", "price": "0.13", "size": "647", "side": "BUY", "hash": "d86b27266db3e831c994f10ee04bf7c42c57697e", "best_bid": "0.21", "best_ask": "0.23"}, {"asset_id": "40581037591963443982506549884210281226867122905421206884675003828040093511244", "price": "0.87", "size": "647", "side": "SELL", "hash": "5d84b84ffd19bc10f20e304b250b2efb5734b65b", "best_bid": "0.77", "best_ask": "0.79"}], "timestamp": "1769384707004", "event_type": "price_change"}}
{"_local_timestamp": "2026-01-25T23:45:07.085998+00:00", "data": {"market": "0x61af02c9250c3917602e21c301e2f0cd032ea4e25bdef3751846b4d5f1c22799", "price_changes": [{"asset_id": "77997400651011819054222158182618580861479123177562866576575031403070672671390", "price": "0.18", "size": "2504.54", "side": "BUY", "hash": "cc4fc703494f674029a95a7a818f214ec66c1721", "best_bid": "0.21", "best_ask": "0.23"}, {"asset_id": "40581037591963443982506549884210281226867122905421206884675003828040093511244", "price": "0.82", "size": "2504.54", "side": "SELL", "hash": "67f80918ad058b3ac2eabd9c9b3e4d1c5bc03a32", "best_bid": "0.77", "best_ask": "0.79"}], "timestamp": "1769384707005", "event_type": "price_change"}}
{"_local_timestamp": "2026-01-25T23:45:07.087472+00:00", "data": {"market": "0x61af02c9250c3917602e21c301e2f0cd032ea4e25bdef3751846b4d5f1c22799", "price_changes": [{"asset_id": "77997400651011819054222158182618580861479123177562866576575031403070672671390", "price": "0.11", "size": "1628", "side": "BUY", "hash": "e8425bac7da689df0c15623d715547599789d7fb", "best_bid": "0.21", "best_ask": "0.23"}, {"asset_id": "40581037591963443982506549884210281226867122905421206884675003828040093511244", "price": "0.89", "size": "1628", "side": "SELL", "hash": "0250da7e0ccb7d209f39a4c1f7a88bb07c7c6bfe", "best_bid": "0.77", "best_ask": "0.79"}], "timestamp": "1769384707006", "event_type": "price_change"}}
{"_local_timestamp": "2026-01-25T23:45:35.503716+00:00", "data": {"market": "0x61af02c9250c3917602e21c301e2f0cd032ea4e25bdef3751846b4d5f1c22799", "price_changes": [{"asset_id": "40581037591963443982506549884210281226867122905421206884675003828040093511244", "price": "0.22", "size": "1908", "side": "BUY", "hash": "16647702012cda39423ceb8db928faddece16373", "best_bid": "0.77", "best_ask": "0.79"}, {"asset_id": "77997400651011819054222158182618580861479123177562866576575031403070672671390", "price": "0.78", "size": "1908", "side": "SELL", "hash": "6e8b20c0ea984168ee9d7881c975ef59e6ddddca", "best_bid": "0.21", "best_ask": "0.23"}], "timestamp": "1769384735433", "event_type": "price_change"}}
{"_local_timestamp": "2026-01-25T23:45:38.891746+00:00", "data": {"market": "0x61af02c9250c3917602e21c301e2f0cd032ea4e25bdef3751846b4d5f1c22799", "price_changes": [{"asset_id": "40581037591963443982506549884210281226867122905421206884675003828040093511244", "price": "0.21", "size": "50", "side": "BUY", "hash": "a7598a2ff4e69f33740df18a2af37d8f28c236e3", "best_bid": "0.77", "best_ask": "0.79"}, {"asset_id": "77997400651011819054222158182618580861479123177562866576575031403070672671390", "price": "0.79", "size": "50", "side": "SELL", "hash": "88f6b7513f7a711b1660404b89c18dcec4726931", "best_bid": "0.21", "best_ask": "0.23"}], "timestamp": "1769384738810", "event_type": "price_change"}}
{"_local_timestamp": "2026-01-25T23:45:39.194809+00:00", "data": {"market": "0x61af02c9250c3917602e21c301e2f0cd032ea4e25bdef3751846b4d5f1c22799", "price_changes": [{"asset_id": "40581037591963443982506549884210281226867122905421206884675003828040093511244", "price": "0.25", "size": "454", "side": "BUY", "hash": "dbee711dbcaa89d714694b2c0117cbfa029c22e4", "best_bid": "0.77", "best_ask": "0.79"}, {"asset_id": "77997400651011819054222158182618580861479123177562866576575031403070672671390", "price": "0.75", "size": "454", "side": "SELL", "hash": "cdaa35d526a1850813fe016e92ef2c5e4c7ab7fe", "best_bid": "0.21", "best_ask": "0.23"}], "timestamp": "1769384739077", "event_type": "price_change"}}
{"_local_timestamp": "2026-01-25T23:45:41.265338+00:00", "data": {"market": "0x61af02c9250c3917602e21c301e2f0cd032ea4e25bdef3751846b4d5f1c22799", "price_changes": [{"asset_id": "40581037591963443982506549884210281226867122905421206884675003828040093511244", "price": "0.75", "size": "1200", "side": "BUY", "hash": "dfe37da6dcd97d18cbf8bef11c141b4130ce367a", "best_bid": "0.77", "best_ask": "0.79"}, {"asset_id": "77997400651011819054222158182618580861479123177562866576575031403070672671390", "price": "0.25", "size": "1200", "side": "SELL", "hash": "2c01eab8be2dd0ca1cd392e490a902d25b9f0bc0", "best_bid": "0.21", "best_ask": "0.23"}], "timestamp": "1769384741188", "event_type": "price_change"}}
{"_local_timestamp": "2026-01-25T23:45:41.312140+00:00", "data": {"market": "0x61af02c9250c3917602e21c301e2f0cd032ea4e25bdef3751846b4d5f1c22799", "price_changes": [{"asset_id": "77997400651011819054222158182618580861479123177562866576575031403070672671390", "price": "0.19", "size": "398.64", "side": "BUY", "hash": "9b3d132bc1a64ba20551b4eb6e75c7608d6ee894", "best_bid": "0.21", "best_ask": "0.23"}, {"asset_id": "40581037591963443982506549884210281226867122905421206884675003828040093511244", "price": "0.81", "size": "398.64", "side": "SELL", "hash": "8c9dad4660f7bfc79c97010d97d0b2359bec20dc", "best_bid": "0.77", "best_ask": "0.79"}], "timestamp": "1769384741194", "event_type": "price_change"}}
{"_local_timestamp": "2026-01-25T23:45:53.060822+00:00", "data": {"market": "0x61af02c9250c3917602e21c301e2f0cd032ea4e25bdef3751846b4d5f1c22799", "price_changes": [{"asset_id": "40581037591963443982506549884210281226867122905421206884675003828040093511244", "price": "0.3", "size": "200", "side": "BUY", "hash": "4686b5879e69ad8fb8d37fafba24214d2f7cb5b1", "best_bid": "0.77", "best_ask": "0.79"}, {"asset_id": "77997400651011819054222158182618580861479123177562866576575031403070672671390", "price": "0.7", "size": "200", "side": "SELL", "hash": "8bcbeb5911aa4b50bfc99294a2d34b4d2e2d5c08", "best_bid": "0.21", "best_ask": "0.23"}], "timestamp": "1769384752992", "event_type": "price_change"}}
{"_local_timestamp": "2026-01-25T23:45:53.568889+00:00", "data": {"market": "0x61af02c9250c3917602e21c301e2f0cd032ea4e25bdef3751846b4d5f1c22799", "price_changes": [{"asset_id": "40581037591963443982506549884210281226867122905421206884675003828040093511244", "price": "0.32", "size": "3557", "side": "BUY", "hash": "104c2e34c8016bb05b34bccc1b8234ebaad6e27b", "best_bid": "0.77", "best_ask": "0.79"}, {"asset_id": "77997400651011819054222158182618580861479123177562866576575031403070672671390", "price": "0.68", "size": "3557", "side": "SELL", "hash": "25110e7c6559254d35d4957935b1f706e88c93d2", "best_bid": "0.21", "best_ask": "0.23"}], "timestamp": "1769384753503", "event_type": "price_change"}}
{"_local_timestamp": "2026-01-25T23:45:56.563382+00:00", "data": {"market": "0x61af02c9250c3917602e21c301e2f0cd032ea4e25bdef3751846b4d5f1c22799", "price_changes": [{"asset_id": "40581037591963443982506549884210281226867122905421206884675003828040093511244", "price": "0.31", "size": "6", "side": "BUY", "hash": "71b19bd2cfbf1f37d7ad6f013f8faaa77d24d200", "best_bid": "0.77", "best_ask": "0.79"}, {"asset_id": "77997400651011819054222158182618580861479123177562866576575031403070672671390", "price": "0.69", "size": "6", "side": "SELL", "hash": "6cfd9a928275b9b99d74a04d9fedb71a67009026", "best_bid": "0.21", "best_ask": "0.23"}], "timestamp": "1769384756086", "event_type": "price_change"}}
{"_local_timestamp": "2026-01-25T23:45:57.817235+00:00", "data": {"market": "0x61af02c9250c3917602e21c301e2f0cd032ea4e25bdef3751846b4d5f1c22799", "price_changes": [{"asset_id": "40581037591963443982506549884210281226867122905421206884675003828040093511244", "price": "0.75", "size": "1300", "side": "BUY", "hash": "5929b2d3131d081faf9a82f8a76cc9a8bd679438", "best_bid": "0.77", "best_ask": "0.79"}, {"asset_id": "77997400651011819054222158182618580861479123177562866576575031403070672671390", "price": "0.25", "size": "1300", "side": "SELL", "hash": "a1b209bf0637677b36aff72c00dea0a4f1432e10", "best_bid": "0.21", "best_ask": "0.23"}], "timestamp": "1769384757747", "event_type": "price_change"}}
{"_local_timestamp": "2026-01-25T23:46:00.802192+00:00", "data": {"market": "0x61af02c9250c3917602e21c301e2f0cd032ea4e25bdef3751846b4d5f1c22799", "price_changes": [{"asset_id": "77997400651011819054222158182618580861479123177562866576575031403070672671390", "price": "0.2", "size": "125.22", "side": "BUY", "hash": "0c64b5b35406b83713d62b776d982fc74825f851", "best_bid": "0.21", "best_ask": "0.23"}, {"asset_id": "40581037591963443982506549884210281226867122905421206884675003828040093511244", "price": "0.8", "size": "125.22", "side": "SELL", "hash": "7cd5426b89826960874254037fa0724addc95de9", "best_bid": "0.77", "best_ask": "0.79"}], "timestamp": "1769384760724", "event_type": "price_change"}}
{"_local_timestamp": "2026-01-25T23:46:00.803819+00:00", "data": {"market": "0x61af02c9250c3917602e21c301e2f0cd032ea4e25bdef3751846b4d5f1c22799", "price_changes": [{"asset_id": "77997400651011819054222158182618580861479123177562866576575031403070672671390", "price": "0.19", "size": "403.64", "side": "BUY", "hash": "26daab7358ed387755b8f0e7d6f2a9ff41a80949", "best_bid": "0.21", "best_ask": "0.23"}, {"asset_id": "40581037591963443982506549884210281226867122905421206884675003828040093511244", "price": "0.81", "size": "403.64", "side": "SELL", "hash": "daa1a800934e8264072e777c2a6e3a383f2a9706", "best_bid": "0.77", "best_ask": "0.79"}], "timestamp": "1769384760725", "event_type": "price_change"}}
{"_local_timestamp": "2026-01-25T23:46:00.805361+00:00", "data": {"market": "0x61af02c9250c3917602e21c301e2f0cd032ea4e25bdef3751846b4d5f1c22799", "price_changes": [{"asset_id": "77997400651011819054222158182618580861479123177562866576575031403070672671390", "price": "0.18", "size": "2527.54", "side": "BUY", "hash": "ff84d47f9183751a59a691af13c7b9bdcef9c9e7", "best_bid": "0.21", "best_ask": "0.23"}, {"asset_id": "40581037591963443982506549884210281226867122905421206884675003828040093511244", "price": "0.82", "size": "2527.54", "side": "SELL", "hash": "2b82610900852e9d47331dd90df061086e6a2251", "best_bid": "0.77", "best_ask": "0.79"}], "timestamp": "1769384760725", "event_type": "price_change"}}
{"_local_timestamp": "2026-01-25T23:46:00.807037+00:00", "data": {"market": "0x61af02c9250c3917602e21c301e2f0cd032ea4e25bdef3751846b4d5f1c22799", "price_changes": [{"asset_id": "77997400651011819054222158182618580861479123177562866576575031403070672671390", "price": "0.11", "size": "2210", "side": "BUY", "hash": "33c3a67028964bb3857a24e5d0ead0d784205d26", "best_bid": "0.21", "best_ask": "0.23"}, {"asset_id": "40581037591963443982506549884210281226867122905421206884675003828040093511244", "price": "0.89", "size": "2210", "side": "SELL", "hash": "ce2de65425f9b77bd53d244d11d9813261efbf86", "best_bid": "0.77", "best_ask": "0.79"}], "timestamp": "1769384760726", "event_type": "price_change"}}
{"_local_timestamp": "2026-01-25T23:46:00.808518+00:00", "data": {"market": "0x61af02c9250c3917602e21c301e2f0cd032ea4e25bdef3751846b4d5f1c22799", "price_changes": [{"asset_id": "77997400651011819054222158182618580861479123177562866576575031403070672671390", "price": "0.13", "size": "893", "side": "BUY", "hash": "628c46e511871b93c9d5e00bde02baa483e3076c", "best_bid": "0.21", "best_ask": "0.23"}, {"asset_id": "40581037591963443982506549884210281226867122905421206884675003828040093511244", "price": "0.87", "size": "893", "side": "SELL", "hash": "72700af8dede0f331d2c654dd3e3e833d9a906a7", "best_bid": "0.77", "best_ask": "0.79"}], "timestamp": "1769384760727", "event_type": "price_change"}}
{"_local_timestamp": "2026-01-25T23:46:00.810047+00:00", "data": {"market": "0x61af02c9250c3917602e21c301e2f0cd032ea4e25bdef3751846b4d5f1c22799", "price_changes": [{"asset_id": "77997400651011819054222158182618580861479123177562866576575031403070672671390", "price": "0.16", "size": "396", "side": "BUY", "hash": "0252fd5224506632dad773219247e02a4816fdd7", "best_bid": "0.21", "best_ask": "0.23"}, {"asset_id": "40581037591963443982506549884210281226867122905421206884675003828040093511244", "price": "0.84", "size": "396", "side": "SELL", "hash": "022819ccb427a4d33be460d5b123349c49188ff6", "best_bid": "0.77", "best_ask": "0.79"}], "timestamp": "1769384760728", "event_type": "price_change"}}
{"_local_timestamp": "2026-01-25T23:46:06.464273+00:00", "data": {"market": "0x61af02c9250c3917602e21c301e2f0cd032ea4e25bdef3751846b4d5f1c22799", "price_changes": [{"asset_id": "77997400651011819054222158182618580861479123177562866576575031403070672671390", "price": "0.19", "size": "503.64", "side": "BUY", "hash": "e9bdc34751ab5a107fa0742253e6d4ca51af1270", "best_bid": "0.21", "best_ask": "0.23"}, {"asset_id": "40581037591963443982506549884210281226867122905421206884675003828040093511244", "price": "0.81", "size": "503.64", "side": "SELL", "hash": "57a6b055f81a7e19f4a9716ad1f32b03bb9a086d", "best_bid": "0.77", "best_ask": "0.79"}], "timestamp": "1769384766389", "event_type": "price_change"}}
{"_local_timestamp": "2026-01-25T23:46:10.222614+00:00", "data": {"market": "0x61af02c9250c3917602e21c301e2f0cd032ea4e25bdef3751846b4d5f1c22799", "price_changes": [{"asset_id": "40581037591963443982506549884210281226867122905421206884675003828040093511244", "price": "0.03", "size": "307.99", "side": "BUY", "hash": "6277414bb826072ef2344b0e4d1be1f288087e77", "best_bid": "0.77", "best_ask": "0.79"}, {"asset_id": "77997400651011819054222158182618580861479123177562866576575031403070672671390", "price": "0.97", "size": "307.99", "side": "SELL", "hash": "0df5126e2df515d72a0bc2d978c8feeabc2a3d74", "best_bid": "0.21", "best_ask": "0.23"}], "timestamp": "1769384770148", "event_type": "price_change"}}
{"_local_timestamp": "2026-01-25T23:46:10.580801+00:00", "data": {"market": "0x61af02c9250c3917602e21c301e2f0cd032ea4e25bdef3751846b4d5f1c22799", "price_changes": [{"asset_id": "40581037591963443982506549884210281226867122905421206884675003828040093511244", "price": "0.22", "size": "0", "side": "BUY", "hash": "2383d6dd9424ddd5a65428c260a83a4384eb2575", "best_bid": "0.77", "best_ask": "0.79"}, {"asset_id": "77997400651011819054222158182618580861479123177562866576575031403070672671390", "price": "0.78", "size": "0", "side": "SELL", "hash": "9cefffcd9f1a649ede79ed449ebcdc327cc33fe7", "best_bid": "0.21", "best_ask": "0.23"}], "timestamp": "1769384770459", "event_type": "price_change"}}
{"_local_timestamp": "2026-01-25T23:46:17.451973+00:00", "data": {"market": "0x61af02c9250c3917602e21c301e2f0cd032ea4e25bdef3751846b4d5f1c22799", "price_changes": [{"asset_id": "40581037591963443982506549884210281226867122905421206884675003828040093511244", "price": "0.25", "size": "354", "side": "BUY", "hash": "66e5bfd734203f6c128817a826a2929c226aa0b4", "best_bid": "0.77", "best_ask": "0.79"}, {"asset_id": "77997400651011819054222158182618580861479123177562866576575031403070672671390", "price": "0.75", "size": "354", "side": "SELL", "hash": "960b668e9e7b3ec00fb9a8c2d099c609bcf7074e", "best_bid": "0.21", "best_ask": "0.23"}], "timestamp": "1769384777369", "event_type": "price_change"}}
{"_local_timestamp": "2026-01-25T23:46:17.718894+00:00", "data": {"market": "0x61af02c9250c3917602e21c301e2f0cd032ea4e25bdef3751846b4d5f1c22799", "price_changes": [{"asset_id": "40581037591963443982506549884210281226867122905421206884675003828040093511244", "price": "0.22", "size": "100", "side": "BUY", "hash": "9148ea6be4b6d013fc5c4f9b6cefbd9ccbbafcda", "best_bid": "0.77", "best_ask": "0.79"}, {"asset_id": "77997400651011819054222158182618580861479123177562866576575031403070672671390", "price": "0.78", "size": "100", "side": "SELL", "hash": "0b03c2a7180bef59020d0c5b042314f5ff281f26", "best_bid": "0.21", "best_ask": "0.23"}], "timestamp": "1769384777640", "event_type": "price_change"}}
{"_local_timestamp": "2026-01-25T23:46:46.666546+00:00", "data": {"market": "0x61af02c9250c3917602e21c301e2f0cd032ea4e25bdef3751846b4d5f1c22799", "price_changes": [{"asset_id": "40581037591963443982506549884210281226867122905421206884675003828040093511244", "price": "0.18", "size": "2332", "side": "BUY", "hash": "99240d595905d667b3f5c6adc8aade1289ea604d", "best_bid": "0.77", "best_ask": "0.79"}, {"asset_id": "77997400651011819054222158182618580861479123177562866576575031403070672671390", "price": "0.82", "size": "2332", "side": "SELL", "hash": "4fd82d08adfb7623a80d5b3815bb07578874a35a", "best_bid": "0.21", "best_ask": "0.23"}], "timestamp": "1769384806603", "event_type": "price_change"}}
{"_local_timestamp": "2026-01-25T23:46:50.993721+00:00", "data": {"market": "0x61af02c9250c3917602e21c301e2f0cd032ea4e25bdef3751846b4d5f1c22799", "price_changes": [{"asset_id": "40581037591963443982506549884210281226867122905421206884675003828040093511244", "price": "0.3", "size": "100", "side": "BUY", "hash": "0a35d81d8edab395727621103c27936e2dd327d2", "best_bid": "0.77", "best_ask": "0.79"}, {"asset_id": "77997400651011819054222158182618580861479123177562866576575031403070672671390", "price": "0.7", "size": "100", "side": "SELL", "hash": "1db1f00d567c1a910abd0c8582e97bad634aee92", "best_bid": "0.21", "best_ask": "0.23"}], "timestamp": "1769384810677", "event_type": "price_change"}}
{"_local_timestamp": "2026-01-25T23:46:51.649853+00:00", "data": {"market": "0x61af02c9250c3917602e21c301e2f0cd032ea4e25bdef3751846b4d5f1c22799", "price_changes": [{"asset_id": "40581037591963443982506549884210281226867122905421206884675003828040093511244", "price": "0.21", "size": "150", "side": "BUY", "hash": "7ea6bc264af4e4f05df7e8683ae9a1b186b76b2c", "best_bid": "0.77", "best_ask": "0.79"}, {"asset_id": "77997400651011819054222158182618580861479123177562866576575031403070672671390", "price": "0.79", "size": "150", "side": "SELL", "hash": "77192878dd2c2cd9d933559460cc2b02a0e00682", "best_bid": "0.21", "best_ask": "0.23"}], "timestamp": "1769384811245", "event_type": "price_change"}}
{"_local_timestamp": "2026-01-25T23:46:59.012333+00:00", "data": {"market": "0x61af02c9250c3917602e21c301e2f0cd032ea4e25bdef3751846b4d5f1c22799", "price_changes": [{"asset_id": "40581037591963443982506549884210281226867122905421206884675003828040093511244", "price": "0.22", "size": "0", "side": "BUY", "hash": "887740ab7854e6e8b7b63d6d6a49b9188b76d1a6", "best_bid": "0.77", "best_ask": "0.79"}, {"asset_id": "77997400651011819054222158182618580861479123177562866576575031403070672671390", "price": "0.78", "size": "0", "side": "SELL", "hash": "c370b5b63a8cc8f61c88f2b12dd93a3bfb5eeb72", "best_bid": "0.21", "best_ask": "0.23"}], "timestamp": "1769384818867", "event_type": "price_change"}}
{"_local_timestamp": "2026-01-25T23:46:59.314124+00:00", "data": {"market": "0x61af02c9250c3917602e21c301e2f0cd032ea4e25bdef3751846b4d5f1c22799", "price_changes": [{"asset_id": "40581037591963443982506549884210281226867122905421206884675003828040093511244", "price": "0.25", "size": "454", "side": "BUY", "hash": "401f6c23ff6eeb75deba225919310981325ea970", "best_bid": "0.77", "best_ask": "0.79"}, {"asset_id": "77997400651011819054222158182618580861479123177562866576575031403070672671390", "price": "0.75", "size": "454", "side": "SELL", "hash": "cca2faac572eb7e92f7fd0ec8e8d46f13cc349e8", "best_bid": "0.21", "best_ask": "0.23"}], "timestamp": "1769384819187", "event_type": "price_change"}}
{"_local_timestamp": "2026-01-25T23:47:04.461365+00:00", "data": {"market": "0x61af02c9250c3917602e21c301e2f0cd032ea4e25bdef3751846b4d5f1c22799", "price_changes": [{"asset_id": "77997400651011819054222158182618580861479123177562866576575031403070672671390", "price": "0.19", "size": "508.64", "side": "BUY", "hash": "c5bd4c137908191ce9ab62af794121bf7b518ee7", "best_bid": "0.21", "best_ask": "0.23"}, {"asset_id": "40581037591963443982506549884210281226867122905421206884675003828040093511244", "price": "0.81", "size": "508.64", "side": "SELL", "hash": "b50b5eab9a87b97033a84d27b7b20e878e226d66", "best_bid": "0.77", "best_ask": "0.79"}], "timestamp": "1769384824393", "event_type": "price_change"}}
{"_local_timestamp": "2026-01-25T23:47:04.463923+00:00", "data": {"market": "0x61af02c9250c3917602e21c301e2f0cd032ea4e25bdef3751846b4d5f1c22799", "price_changes": [{"asset_id": "77997400651011819054222158182618580861479123177562866576575031403070672671390", "price": "0.2", "size": "130.22", "side": "BUY", "hash": "aa55a7e48568fae39b19c29de9e3dabda36a71ac", "best_bid": "0.21", "best_ask": "0.23"}, {"asset_id": "40581037591963443982506549884210281226867122905421206884675003828040093511244", "price": "0.8", "size": "130.22", "side": "SELL", "hash": "c9038d49899dfce8e60288abfa02e6076346aebe", "best_bid": "0.77", "best_ask": "0.79"}], "timestamp": "1769384824394", "event_type": "price_change"}}
{"_local_timestamp": "2026-01-25T23:47:13.095859+00:00", "data": {"market": "0x61af02c9250c3917602e21c301e2f0cd032ea4e25bdef3751846b4d5f1c22799", "price_changes": [{"asset_id": "40581037591963443982506549884210281226867122905421206884675003828040093511244", "price": "0.77", "size": "29.99", "side": "BUY", "hash": "9a42b53d7c71cc0f6c869494eb7e0dd82d229366", "best_bid": "0.77", "best_ask": "0.79"}, {"asset_id": "77997400651011819054222158182618580861479123177562866576575031403070672671390", "price": "0.23", "size": "29.99", "side": "SELL", "hash": "502e1ae2baa28e6ff7a04c66ad0fb2a87e037144", "best_bid": "0.21", "best_ask": "0.23"}], "timestamp": "1769384833002", "event_type": "price_change"}}
{"_local_timestamp": "2026-01-25T23:47:23.413967+00:00", "data": {"market": "0x61af02c9250c3917602e21c301e2f0cd032ea4e25bdef3751846b4d5f1c22799", "price_changes": [{"asset_id": "40581037591963443982506549884210281226867122905421206884675003828040093511244", "price": "0.3", "size": "50", "side": "BUY", "hash": "619cabecf6da99f5ad938c8f8b8f29113fe56a0f", "best_bid": "0.77", "best_ask": "0.79"}, {"asset_id": "77997400651011819054222158182618580861479123177562866576575031403070672671390", "price": "0.7", "size": "50", "side": "SELL", "hash": "bfeb3c0fbf1f1b5d2fd162bdb20a3adf2a4f55a0", "best_bid": "0.21", "best_ask": "0.23"}], "timestamp": "1769384843336", "event_type": "price_change"}}
{"_local_timestamp": "2026-01-25T23:47:23.415621+00:00", "data": {"market": "0x61af02c9250c3917602e21c301e2f0cd032ea4e25bdef3751846b4d5f1c22799", "price_changes": [{"asset_id": "40581037591963443982506549884210281226867122905421206884675003828040093511244", "price": "0.21", "size": "100", "side": "BUY", "hash": "619cabecf6da99f5ad938c8f8b8f29113fe56a0f", "best_bid": "0.77", "best_ask": "0.79"}, {"asset_id": "77997400651011819054222158182618580861479123177562866576575031403070672671390", "price": "0.79", "size": "100", "side": "SELL", "hash": "bfeb3c0fbf1f1b5d2fd162bdb20a3adf2a4f55a0", "best_bid": "0.21", "best_ask": "0.23"}], "timestamp": "1769384843336", "event_type": "price_change"}}
{"_local_timestamp": "2026-01-25T23:47:23.949678+00:00", "data": {"market": "0x61af02c9250c3917602e21c301e2f0cd032ea4e25bdef3751846b4d5f1c22799", "price_changes": [{"asset_id": "40581037591963443982506549884210281226867122905421206884675003828040093511244", "price": "0.25", "size": "504", "side": "BUY", "hash": "5c9fc82cfb69ccdf6eb073fba3f773573f1c4977", "best_bid": "0.77", "best_ask": "0.79"}, {"asset_id": "77997400651011819054222158182618580861479123177562866576575031403070672671390", "price": "0.75", "size": "504", "side": "SELL", "hash": "b2534e60736870ff07745e21cda61cd0d0e8ac2f", "best_bid": "0.21", "best_ask": "0.23"}], "timestamp": "1769384843816", "event_type": "price_change"}}
{"_local_timestamp": "2026-01-25T23:47:23.951350+00:00", "data": {"market": "0x61af02c9250c3917602e21c301e2f0cd032ea4e25bdef3751846b4d5f1c22799", "price_changes": [{"asset_id": "40581037591963443982506549884210281226867122905421206884675003828040093511244", "price": "0.32", "size": "3607", "side": "BUY", "hash": "6e975e6decb5674baf46332017de893359906840", "best_bid": "0.77", "best_ask": "0.79"}, {"asset_id": "77997400651011819054222158182618580861479123177562866576575031403070672671390", "price": "0.68", "size": "3607", "side": "SELL", "hash": "49887d3026c08bce22a84e14436e6361660c4799", "best_bid": "0.21", "best_ask": "0.23"}], "timestamp": "1769384843850", "event_type": "price_change"}}
{"_local_timestamp": "2026-01-25T23:47:37.356164+00:00", "data": {"market": "0x61af02c9250c3917602e21c301e2f0cd032ea4e25bdef3751846b4d5f1c22799", "price_changes": [{"asset_id": "40581037591963443982506549884210281226867122905421206884675003828040093511244", "price": "0.3", "size": "0", "side": "BUY", "hash": "ef2c3d08782adccec51e332e9a59536fc508181e", "best_bid": "0.77", "best_ask": "0.79"}, {"asset_id": "77997400651011819054222158182618580861479123177562866576575031403070672671390", "price": "0.7", "size": "0", "side": "SELL", "hash": "b3d8c2827ed33801bbd211b20fa4e71ba16775bd", "best_bid": "0.21", "best_ask": "0.23"}], "timestamp": "1769384857285", "event_type": "price_change"}}
{"_local_timestamp": "2026-01-25T23:47:37.383537+00:00", "data": {"market": "0x61af02c9250c3917602e21c301e2f0cd032ea4e25bdef3751846b4d5f1c22799", "price_changes": [{"asset_id": "40581037591963443982506549884210281226867122905421206884675003828040093511244", "price": "0.17", "size": "1240", "side": "BUY", "hash": "1bdf30f8461dbafddb6b772cf3d5ef35e8dbfde8", "best_bid": "0.77", "best_ask": "0.79"}, {"asset_id": "77997400651011819054222158182618580861479123177562866576575031403070672671390", "price": "0.83", "size": "1240", "side": "SELL", "hash": "2c70ac8f685c9fd65ceb2077f843c922494939f9", "best_bid": "0.21", "best_ask": "0.23"}], "timestamp": "1769384857297", "event_type": "price_change"}}
{"_local_timestamp": "2026-01-25T23:47:37.872465+00:00", "data": {"market": "0x61af02c9250c3917602e21c301e2f0cd032ea4e25bdef3751846b4d5f1c22799", "price_changes": [{"asset_id": "40581037591963443982506549884210281226867122905421206884675003828040093511244", "price": "0.29", "size": "132.75", "side": "BUY", "hash": "fd00d9de390179b06cfa4acd17a03676ca166600", "best_bid": "0.77", "best_ask": "0.79"}, {"asset_id": "77997400651011819054222158182618580861479123177562866576575031403070672671390", "price": "0.71", "size": "132.75", "side": "SELL", "hash": "8cb56463fb017b8911c7a313574d4e4a3cc9728f", "best_bid": "0.21", "best_ask": "0.23"}], "timestamp": "1769384857590", "event_type": "price_change"}}
{"_local_timestamp": "2026-01-25T23:47:37.978792+00:00", "data": {"market": "0x61af02c9250c3917602e21c301e2f0cd032ea4e25bdef3751846b4d5f1c22799", "price_changes": [{"asset_id": "40581037591963443982506549884210281226867122905421206884675003828040093511244", "price": "0.18", "size": "2482", "side": "BUY", "hash": "7dfda9d61661cf9edccded246327296e9f6b5e69", "best_bid": "0.77", "best_ask": "0.79"}, {"asset_id": "77997400651011819054222158182618580861479123177562866576575031403070672671390", "price": "0.82", "size": "2482", "side": "SELL", "hash": "3dda1a56fd2414703568b94957aab8ca9f3804b2", "best_bid": "0.21", "best_ask": "0.23"}], "timestamp": "1769384857626", "event_type": "price_change"}}
{"_local_timestamp": "2026-01-25T23:47:45.609973+00:00", "data": {"market": "0x61af02c9250c3917602e21c301e2f0cd032ea4e25bdef3751846b4d5f1c22799", "price_changes": [{"asset_id": "40581037591963443982506549884210281226867122905421206884675003828040093511244", "price": "0.17", "size": "1190", "side": "BUY", "hash": "8b113da8e3dd94868026b6fa0aace72a51a24c80", "best_bid": "0.77", "best_ask": "0.79"}, {"asset_id": "77997400651011819054222158182618580861479123177562866576575031403070672671390", "price": "0.83", "size": "1190", "side": "SELL", "hash": "079b5ddc205c4f9c4f5f6291cb336136e194de32", "best_bid": "0.21", "best_ask": "0.23"}], "timestamp": "1769384865514", "event_type": "price_change"}}
{"_local_timestamp": "2026-01-25T23:47:45.921440+00:00", "data": {"market": "0x61af02c9250c3917602e21c301e2f0cd032ea4e25bdef3751846b4d5f1c22799", "price_changes": [{"asset_id": "40581037591963443982506549884210281226867122905421206884675003828040093511244", "price": "0.18", "size": "2532", "side": "BUY", "hash": "c70e0e6b1e555dc76f66eb5fab4dce3d4d0ebf4a", "best_bid": "0.77", "best_ask": "0.79"}, {"asset_id": "77997400651011819054222158182618580861479123177562866576575031403070672671390", "price": "0.82", "size": "2532", "side": "SELL", "hash": "5943bfcfed81f8c259855a705a51400409e8d048", "best_bid": "0.21", "best_ask": "0.23"}], "timestamp": "1769384865837", "event_type": "price_change"}}
{"_local_timestamp": "2026-01-25T23:47:47.113365+00:00", "data": {"market": "0x61af02c9250c3917602e21c301e2f0cd032ea4e25bdef3751846b4d5f1c22799", "price_changes": [{"asset_id": "77997400651011819054222158182618580861479123177562866576575031403070672671390", "price": "0.18", "size": "2449.54", "side": "BUY", "hash": "77ad7c8bd03fae81aaa34681d5fb4e14370b7df7", "best_bid": "0.21", "best_ask": "0.23"}, {"asset_id": "40581037591963443982506549884210281226867122905421206884675003828040093511244", "price": "0.82", "size": "2449.54", "side": "SELL", "hash": "ebc0c361bbaa504dcf1198db0926431bcd4dc2a2", "best_bid": "0.77", "best_ask": "0.79"}], "timestamp": "1769384867006", "event_type": "price_change"}}
{"_local_timestamp": "2026-01-25T23:47:55.429505+00:00", "data": {"market": "0x61af02c9250c3917602e21c301e2f0cd032ea4e25bdef3751846b4d5f1c22799", "price_changes": [{"asset_id": "40581037591963443982506549884210281226867122905421206884675003828040093511244", "price": "0.77", "size": "49.99", "side": "BUY", "hash": "cfcf723683d5af08aec99802993abc530c5a4d24", "best_bid": "0.77", "best_ask": "0.79"}, {"asset_id": "77997400651011819054222158182618580861479123177562866576575031403070672671390", "price": "0.23", "size": "49.99", "side": "SELL", "hash": "402488d62b3c4e39750427fa177740e82587b0c0", "best_bid": "0.21", "best_ask": "0.23"}], "timestamp": "1769384875288", "event_type": "price_change"}}
{"_local_timestamp": "2026-01-25T23:47:55.633870+00:00", "data": {"market": "0x61af02c9250c3917602e21c301e2f0cd032ea4e25bdef3751846b4d5f1c22799", "price_changes": [{"asset_id": "40581037591963443982506549884210281226867122905421206884675003828040093511244", "price": "0.18", "size": "200", "side": "BUY", "hash": "863366645658e85013a92dc7c1e27302d05c99c9", "best_bid": "0.77", "best_ask": "0.79"}, {"asset_id": "77997400651011819054222158182618580861479123177562866576575031403070672671390", "price": "0.82", "size": "200", "side": "SELL", "hash": "f28f0cc0e039f6738a764e5e020ceb524bdf794c", "best_bid": "0.21", "best_ask": "0.23"}], "timestamp": "1769384875414", "event_type": "price_change"}}
{"_local_timestamp": "2026-01-25T23:47:56.189555+00:00", "data": {"market": "0x61af02c9250c3917602e21c301e2f0cd032ea4e25bdef3751846b4d5f1c22799", "price_changes": [{"asset_id": "40581037591963443982506549884210281226867122905421206884675003828040093511244", "price": "0.8", "size": "90.22", "side": "SELL", "hash": "a4fafccea359e84d9ffd72b5cddcc722b9828c04", "best_bid": "0.77", "best_ask": "0.79"}, {"asset_id": "77997400651011819054222158182618580861479123177562866576575031403070672671390", "price": "0.2", "size": "90.22", "side": "BUY", "hash": "a77d60c7cce494155305c539a7b016f58dad331c", "best_bid": "0.21", "best_ask": "0.23"}], "timestamp": "1769384876002", "event_type": "price_change"}}
{"_local_timestamp": "2026-01-25T23:48:26.281055+00:00", "data": {"market": "0x61af02c9250c3917602e21c301e2f0cd032ea4e25bdef3751846b4d5f1c22799", "price_changes": [{"asset_id": "40581037591963443982506549884210281226867122905421206884675003828040093511244", "price": "0.18", "size": "150", "side": "BUY", "hash": "37b57b70dc8bd4c458769fff0ad90759e73da516", "best_bid": "0.77", "best_ask": "0.79"}, {"asset_id": "77997400651011819054222158182618580861479123177562866576575031403070672671390", "price": "0.82", "size": "150", "side": "SELL", "hash": "48a5eccb45c7a028fe5daf2a582e4c99ef18db50", "best_bid": "0.21", "best_ask": "0.23"}], "timestamp": "1769384906026", "event_type": "price_change"}}
{"_local_timestamp": "2026-01-25T23:48:26.558023+00:00", "data": {"market": "0x61af02c9250c3917602e21c301e2f0cd032ea4e25bdef3751846b4d5f1c22799", "price_changes": [{"asset_id": "40581037591963443982506549884210281226867122905421206884675003828040093511244", "price": "0.17", "size": "1240", "side": "BUY", "hash": "f88ded597d8234757be2e1f3205857b78c25e009", "best_bid": "0.77", "best_ask": "0.79"}, {"asset_id": "77997400651011819054222158182618580861479123177562866576575031403070672671390", "price": "0.83", "size": "1240", "side": "SELL", "hash": "981709e08454142bcc8f936e7fdca57d7b39562f", "best_bid": "0.21", "best_ask": "0.23"}], "timestamp": "1769384906302", "event_type": "price_change"}}
{"_local_timestamp": "2026-01-25T23:48:48.653955+00:00", "data": {"market": "0x61af02c9250c3917602e21c301e2f0cd032ea4e25bdef3751846b4d5f1c22799", "price_changes": [{"asset_id": "40581037591963443982506549884210281226867122905421206884675003828040093511244", "price": "0.18", "size": "0", "side": "BUY", "hash": "2952e39968e3439aa120acb4cde2c586afbe6765", "best_bid": "0.77", "best_ask": "0.79"}, {"asset_id": "77997400651011819054222158182618580861479123177562866576575031403070672671390", "price": "0.82", "size": "0", "side": "SELL", "hash": "362bd03cd25e25c3251e43d8bd2c0572034b15b1", "best_bid": "0.21", "best_ask": "0.23"}], "timestamp": "1769384928576", "event_type": "price_change"}}
{"_local_timestamp": "2026-01-25T23:48:48.941067+00:00", "data": {"market": "0x61af02c9250c3917602e21c301e2f0cd032ea4e25bdef3751846b4d5f1c22799", "price_changes": [{"asset_id": "40581037591963443982506549884210281226867122905421206884675003828040093511244", "price": "0.17", "size": "1390", "side": "BUY", "hash": "69b8915ed9d4e708e541b5e4b7d1094df266c2ce", "best_bid": "0.77", "best_ask": "0.79"}, {"asset_id": "77997400651011819054222158182618580861479123177562866576575031403070672671390", "price": "0.83", "size": "1390", "side": "SELL", "hash": "f06b3c5cfa79a49ff1e94820081f9a543436fdc9", "best_bid": "0.21", "best_ask": "0.23"}], "timestamp": "1769384928846", "event_type": "price_change"}}
{"_local_timestamp": "2026-01-25T23:48:51.028610+00:00", "data": {"market": "0x61af02c9250c3917602e21c301e2f0cd032ea4e25bdef3751846b4d5f1c22799", "price_changes": [{"asset_id": "77997400651011819054222158182618580861479123177562866576575031403070672671390", "price": "0.2", "size": "85.22", "side": "BUY", "hash": "becc4ddeeba11c8a96fa9aaa1daa734a2e177cf6", "best_bid": "0.21", "best_ask": "0.23"}, {"asset_id": "40581037591963443982506549884210281226867122905421206884675003828040093511244", "price": "0.8", "size": "85.22", "side": "SELL", "hash": "65145f89171d77b027c7dcedb850a78a1eeb1279", "best_bid": "0.77", "best_ask": "0.79"}], "timestamp": "1769384930954", "event_type": "price_change"}}
{"_local_timestamp": "2026-01-25T23:48:51.030195+00:00", "data": {"market": "0x61af02c9250c3917602e21c301e2f0cd032ea4e25bdef3751846b4d5f1c22799", "price_changes": [{"asset_id": "77997400651011819054222158182618580861479123177562866576575031403070672671390", "price": "0.19", "size": "503.64", "side": "BUY", "hash": "becc4ddeeba11c8a96fa9aaa1daa734a2e177cf6", "best_bid": "0.21", "best_ask": "0.23"}, {"asset_id": "40581037591963443982506549884210281226867122905421206884675003828040093511244", "price": "0.81", "size": "503.64", "side": "SELL", "hash": "65145f89171d77b027c7dcedb850a78a1eeb1279", "best_bid": "0.77", "best_ask": "0.79"}], "timestamp": "1769384930954", "event_type": "price_change"}}
{"_local_timestamp": "2026-01-25T23:48:51.040139+00:00", "data": {"market": "0x61af02c9250c3917602e21c301e2f0cd032ea4e25bdef3751846b4d5f1c22799", "price_changes": [{"asset_id": "77997400651011819054222158182618580861479123177562866576575031403070672671390", "price": "0.18", "size": "2527.54", "side": "BUY", "hash": "30cfbc577c620b1c289367ff4b2b81e832a05043", "best_bid": "0.21", "best_ask": "0.23"}, {"asset_id": "40581037591963443982506549884210281226867122905421206884675003828040093511244", "price": "0.82", "size": "2527.54", "side": "SELL", "hash": "9f4788be0bb31619499c4b8b868b22463fd90778", "best_bid": "0.77", "best_ask": "0.79"}], "timestamp": "1769384930974", "event_type": "price_change"}}
{"_local_timestamp": "2026-01-25T23:49:09.067460+00:00", "data": {"market": "0x61af02c9250c3917602e21c301e2f0cd032ea4e25bdef3751846b4d5f1c22799", "price_changes": [{"asset_id": "40581037591963443982506549884210281226867122905421206884675003828040093511244", "price": "0.8", "size": "125.22", "side": "SELL", "hash": "a02582295ce8f779fd2f694708dc269facabd113", "best_bid": "0.77", "best_ask": "0.79"}, {"asset_id": "77997400651011819054222158182618580861479123177562866576575031403070672671390", "price": "0.2", "size": "125.22", "side": "BUY", "hash": "e6d4a4d33c22b18c993b1bd660ff431a23f4f1f7", "best_bid": "0.21", "best_ask": "0.23"}], "timestamp": "1769384948999", "event_type": "price_change"}}
{"_local_timestamp": "2026-01-25T23:49:13.159366+00:00", "data": {"market": "0x61af02c9250c3917602e21c301e2f0cd032ea4e25bdef3751846b4d5f1c22799", "price_changes": [{"asset_id": "40581037591963443982506549884210281226867122905421206884675003828040093511244", "price": "0.23", "size": "1826", "side": "BUY", "hash": "6bca038a7c50c51a426e65a44408e65078497743", "best_bid": "0.77", "best_ask": "0.79"}, {"asset_id": "77997400651011819054222158182618580861479123177562866576575031403070672671390", "price": "0.77", "size": "1826", "side": "SELL", "hash": "5f1f9457bf11c2b1d9954a519b6ffbb1225f0a66", "best_bid": "0.21", "best_ask": "0.23"}], "timestamp": "1769384953078", "event_type": "price_change"}}
{"_local_timestamp": "2026-01-25T23:49:25.351536+00:00", "data": {"market": "0x61af02c9250c3917602e21c301e2f0cd032ea4e25bdef3751846b4d5f1c22799", "price_changes": [{"asset_id": "40581037591963443982506549884210281226867122905421206884675003828040093511244", "price": "0.17", "size": "1290", "side": "BUY", "hash": "9957f1010b2e325fed3c8b7c91ce0d573e862262", "best_bid": "0.77", "best_ask": "0.79"}, {"asset_id": "77997400651011819054222158182618580861479123177562866576575031403070672671390", "price": "0.83", "size": "1290", "side": "SELL", "hash": "d200c7fb278530cf8a6658b5b2feffca36f63a5e", "best_bid": "0.21", "best_ask": "0.23"}], "timestamp": "1769384965267", "event_type": "price_change"}}
{"_local_timestamp": "2026-01-25T23:49:25.911147+00:00", "data": {"market": "0x61af02c9250c3917602e21c301e2f0cd032ea4e25bdef3751846b4d5f1c22799", "price_changes": [{"asset_id": "40581037591963443982506549884210281226867122905421206884675003828040093511244", "price": "0.18", "size": "100", "side": "BUY", "hash": "9137bd527dae5986e0681a54fc3108ca9301a14e", "best_bid": "0.77", "best_ask": "0.79"}, {"asset_id": "77997400651011819054222158182618580861479123177562866576575031403070672671390", "price": "0.82", "size": "100", "side": "SELL", "hash": "c728b2af4384e45289bfe44e0b9f168f9fd57665", "best_bid": "0.21", "best_ask": "0.23"}], "timestamp": "1769384965772", "event_type": "price_change"}}
{"_local_timestamp": "2026-01-25T23:49:30.491350+00:00", "data": {"market": "0x61af02c9250c3917602e21c301e2f0cd032ea4e25bdef3751846b4d5f1c22799", "price_changes": [{"asset_id": "40581037591963443982506549884210281226867122905421206884675003828040093511244", "price": "0.17", "size": "1140", "side": "BUY", "hash": "ca9f17a40f3aeda3a928523c063b076b5efba559", "best_bid": "0.77", "best_ask": "0.79"}, {"asset_id": "77997400651011819054222158182618580861479123177562866576575031403070672671390", "price": "0.83", "size": "1140", "side": "SELL", "hash": "d8f0f66a27c1549aed0f194147c18b2b19ff1acc", "best_bid": "0.21", "best_ask": "0.23"}], "timestamp": "1769384970070", "event_type": "price_change"}}
{"_local_timestamp": "2026-01-25T23:49:30.493486+00:00", "data": {"market": "0x61af02c9250c3917602e21c301e2f0cd032ea4e25bdef3751846b4d5f1c22799", "price_changes": [{"asset_id": "40581037591963443982506549884210281226867122905421206884675003828040093511244", "price": "0.21", "size": "0", "side": "BUY", "hash": "ca9f17a40f3aeda3a928523c063b076b5efba559", "best_bid": "0.77", "best_ask": "0.79"}, {"asset_id": "77997400651011819054222158182618580861479123177562866576575031403070672671390", "price": "0.79", "size": "0", "side": "SELL", "hash": "d8f0f66a27c1549aed0f194147c18b2b19ff1acc", "best_bid": "0.21", "best_ask": "0.23"}], "timestamp": "1769384970070", "event_type": "price_change"}}
{"_local_timestamp": "2026-01-25T23:49:30.997748+00:00", "data": {"market": "0x61af02c9250c3917602e21c301e2f0cd032ea4e25bdef3751846b4d5f1c22799", "price_changes": [{"asset_id": "40581037591963443982506549884210281226867122905421206884675003828040093511244", "price": "0.25", "size": "604", "side": "BUY", "hash": "0a2b677bee4d8a93d6ed751d95a0e6713f7745f4", "best_bid": "0.77", "best_ask": "0.79"}, {"asset_id": "77997400651011819054222158182618580861479123177562866576575031403070672671390", "price": "0.75", "size": "604", "side": "SELL", "hash": "112317c7d62e64e9fa00308e36f5b8951ad8b252", "best_bid": "0.21", "best_ask": "0.23"}], "timestamp": "1769384970632", "event_type": "price_change"}}
{"_local_timestamp": "2026-01-25T23:49:31.134956+00:00", "data": {"market": "0x61af02c9250c3917602e21c301e2f0cd032ea4e25bdef3751846b4d5f1c22799", "price_changes": [{"asset_id": "40581037591963443982506549884210281226867122905421206884675003828040093511244", "price": "0.18", "size": "250", "side": "BUY", "hash": "36830ad55a3e57f43e940b225f0104f140453941", "best_bid": "0.77", "best_ask": "0.79"}, {"asset_id": "77997400651011819054222158182618580861479123177562866576575031403070672671390", "price": "0.82", "size": "250", "side": "SELL", "hash": "0b6223bd614cac94c1ae1ec305839774bdf535df", "best_bid": "0.21", "best_ask": "0.23"}], "timestamp": "1769384970738", "event_type": "price_change"}}
{"_local_timestamp": "2026-01-25T23:49:51.233593+00:00", "data": {"market": "0x61af02c9250c3917602e21c301e2f0cd032ea4e25bdef3751846b4d5f1c22799", "price_changes": [{"asset_id": "40581037591963443982506549884210281226867122905421206884675003828040093511244", "price": "0.23", "size": "0", "side": "BUY", "hash": "5380f52f074dab7569330f48cddb8f47efcde1bb", "best_bid": "0.77", "best_ask": "0.79"}, {"asset_id": "77997400651011819054222158182618580861479123177562866576575031403070672671390", "price": "0.77", "size": "0", "side": "SELL", "hash": "dd11eb833eccbff54aea43f42e3374d26642d831", "best_bid": "0.21", "best_ask": "0.23"}], "timestamp": "1769384991045", "event_type": "price_change"}}
{"_local_timestamp": "2026-01-25T23:49:53.102171+00:00", "data": {"market": "0x61af02c9250c3917602e21c301e2f0cd032ea4e25bdef3751846b4d5f1c22799", "price_changes": [{"asset_id": "77997400651011819054222158182618580861479123177562866576575031403070672671390", "price": "0.13", "size": "246", "side": "BUY", "hash": "2d2eff4890c1f83bb09ac7cc673c2b1fb526bb97", "best_bid": "0.21", "best_ask": "0.23"}, {"asset_id": "40581037591963443982506549884210281226867122905421206884675003828040093511244", "price": "0.87", "size": "246", "side": "SELL", "hash": "e936625b0daea1af743470de8699c9cb47ac4de0", "best_bid": "0.77", "best_ask": "0.79"}], "timestamp": "1769384993000", "event_type": "price_change"}}
{"_local_timestamp": "2026-01-25T23:49:53.109843+00:00", "data": {"market": "0x61af02c9250c3917602e21c301e2f0cd032ea4e25bdef3751846b4d5f1c22799", "price_changes": [{"asset_id": "77997400651011819054222158182618580861479123177562866576575031403070672671390", "price": "0.11", "size": "682", "side": "BUY", "hash": "6bb2537c7f5df6904fe11fcdba63f9677aa4ebf2", "best_bid": "0.21", "best_ask": "0.23"}, {"asset_id": "40581037591963443982506549884210281226867122905421206884675003828040093511244", "price": "0.89", "size": "682", "side": "SELL", "hash": "a5e4e51c56b3fb58b6aa17d883be023d06080ee8", "best_bid": "0.77", "best_ask": "0.79"}], "timestamp": "1769384993005", "event_type": "price_change"}}
{"_local_timestamp": "2026-01-25T23:49:53.111417+00:00", "data": {"market": "0x61af02c9250c3917602e21c301e2f0cd032ea4e25bdef3751846b4d5f1c22799", "price_changes": [{"asset_id": "77997400651011819054222158182618580861479123177562866576575031403070672671390", "price": "0.16", "size": "133", "side": "BUY", "hash": "6bb2537c7f5df6904fe11fcdba63f9677aa4ebf2", "best_bid": "0.21", "best_ask": "0.23"}, {"asset_id": "40581037591963443982506549884210281226867122905421206884675003828040093511244", "price": "0.84", "size": "133", "side": "SELL", "hash": "a5e4e51c56b3fb58b6aa17d883be023d06080ee8", "best_bid": "0.77", "best_ask": "0.79"}], "timestamp": "1769384993005", "event_type": "price_change"}}
{"_local_timestamp": "2026-01-25T23:49:53.112922+00:00", "data": {"market": "0x61af02c9250c3917602e21c301e2f0cd032ea4e25bdef3751846b4d5f1c22799", "price_changes": [{"asset_id": "77997400651011819054222158182618580861479123177562866576575031403070672671390", "price": "0.18", "size": "2522.54", "side": "BUY", "hash": "caf9190cd15f44248cf0f50bacd634dbf31a3bbc", "best_bid": "0.21", "best_ask": "0.23"}, {"asset_id": "40581037591963443982506549884210281226867122905421206884675003828040093511244", "price": "0.82", "size": "2522.54", "side": "SELL", "hash": "f2c68fdb10827412018eea9b34ed7eda8ac44544", "best_bid": "0.77", "best_ask": "0.79"}], "timestamp": "1769384993006", "event_type": "price_change"}}
{"_local_timestamp": "2026-01-25T23:49:58.600687+00:00", "data": {"market": "0x61af02c9250c3917602e21c301e2f0cd032ea4e25bdef3751846b4d5f1c22799", "price_changes": [{"asset_id": "77997400651011819054222158182618580861479123177562866576575031403070672671390", "price": "0.16", "size": "396", "side": "BUY", "hash": "21de9dd1ef80505f061b4e668e69c536b4042d25", "best_bid": "0.21", "best_ask": "0.23"}, {"asset_id": "40581037591963443982506549884210281226867122905421206884675003828040093511244", "price": "0.84", "size": "396", "side": "SELL", "hash": "1c0dbfed7c08fae43f5b561e395876be49f68f38", "best_bid": "0.77", "best_ask": "0.79"}], "timestamp": "1769384998522", "event_type": "price_change"}}
{"_local_timestamp": "2026-01-25T23:49:58.602399+00:00", "data": {"market": "0x61af02c9250c3917602e21c301e2f0cd032ea4e25bdef3751846b4d5f1c22799", "price_changes": [{"asset_id": "77997400651011819054222158182618580861479123177562866576575031403070672671390", "price": "0.13", "size": "893", "side": "BUY", "hash": "769453e1d4000aceb8923fed5651ab4dad7b545a", "best_bid": "0.21", "best_ask": "0.23"}, {"asset_id": "40581037591963443982506549884210281226867122905421206884675003828040093511244", "price": "0.87", "size": "893", "side": "SELL", "hash": "1268f286b4793c69d6efbfeaa8bd2c6f794913e5", "best_bid": "0.77", "best_ask": "0.79"}], "timestamp": "1769384998523", "event_type": "price_change"}}
{"_local_timestamp": "2026-01-25T23:49:58.603951+00:00", "data": {"market": "0x61af02c9250c3917602e21c301e2f0cd032ea4e25bdef3751846b4d5f1c22799", "price_changes": [{"asset_id": "77997400651011819054222158182618580861479123177562866576575031403070672671390", "price": "0.18", "size": "2527.54", "side": "BUY", "hash": "872531eb0ac20cd1f049443a77caf04f93218eac", "best_bid": "0.21", "best_ask": "0.23"}, {"asset_id": "40581037591963443982506549884210281226867122905421206884675003828040093511244", "price": "0.82", "size": "2527.54", "side": "SELL", "hash": "222ab458dfdf943c36fa595c660559be1b26af47", "best_bid": "0.77", "best_ask": "0.79"}], "timestamp": "1769384998524", "event_type": "price_change"}}
{"_local_timestamp": "2026-01-25T23:49:58.605498+00:00", "data": {"market": "0x61af02c9250c3917602e21c301e2f0cd032ea4e25bdef3751846b4d5f1c22799", "price_changes": [{"asset_id": "77997400651011819054222158182618580861479123177562866576575031403070672671390", "price": "0.11", "size": "2210", "side": "BUY", "hash": "f63c1fa70b5b690f07ab0c05a7a34c1c90f9b1d2", "best_bid": "0.21", "best_ask": "0.23"}, {"asset_id": "40581037591963443982506549884210281226867122905421206884675003828040093511244", "price": "0.89", "size": "2210", "side": "SELL", "hash": "e070aa4b350fca5779c691d65e8867cef176a0eb", "best_bid": "0.77", "best_ask": "0.79"}], "timestamp": "1769384998525", "event_type": "price_change"}}
{"_local_timestamp": "2026-01-25T23:50:02.384369+00:00", "data": {"market": "0x61af02c9250c3917602e21c301e2f0cd032ea4e25bdef3751846b4d5f1c22799", "price_changes": [{"asset_id": "40581037591963443982506549884210281226867122905421206884675003828040093511244", "price": "0.17", "size": "200", "side": "BUY", "hash": "0f0ebb305a75bc6e11e1643c473f92cdc31ba8c0", "best_bid": "0.77", "best_ask": "0.79"}, {"asset_id": "77997400651011819054222158182618580861479123177562866576575031403070672671390", "price": "0.83", "size": "200", "side": "SELL", "hash": "d10efe4e5517789bbcb99888b15af41da10eedf5", "best_bid": "0.21", "best_ask": "0.23"}], "timestamp": "1769385002270", "event_type": "price_change"}}
{"_local_timestamp": "2026-01-25T23:50:03.918834+00:00", "data": {"market": "0x61af02c9250c3917602e21c301e2f0cd032ea4e25bdef3751846b4d5f1c22799", "price_changes": [{"asset_id": "40581037591963443982506549884210281226867122905421206884675003828040093511244", "price": "0.19", "size": "2210", "side": "BUY", "hash": "fff1cf622d5dd9c315811d8c1614609f4ae317e0", "best_bid": "0.77", "best_ask": "0.79"}, {"asset_id": "77997400651011819054222158182618580861479123177562866576575031403070672671390", "price": "0.81", "size": "2210", "side": "SELL", "hash": "2b09df7e6833ee6d05e115a19eff8e56c514e623", "best_bid": "0.21", "best_ask": "0.23"}], "timestamp": "1769385003843", "event_type": "price_change"}}
{"_local_timestamp": "2026-01-25T23:50:05.516895+00:00", "data": {"market": "0x61af02c9250c3917602e21c301e2f0cd032ea4e25bdef3751846b4d5f1c22799", "price_changes": [{"asset_id": "40581037591963443982506549884210281226867122905421206884675003828040093511244", "price": "0.25", "size": "504", "side": "BUY", "hash": "851cb3c07553b738467350e216ad6628460d02ea", "best_bid": "0.77", "best_ask": "0.79"}, {"asset_id": "77997400651011819054222158182618580861479123177562866576575031403070672671390", "price": "0.75", "size": "504", "side": "SELL", "hash": "1ec415bd2da42f25dc73ac6ae1913f00d5ef582a", "best_bid": "0.21", "best_ask": "0.23"}], "timestamp": "1769385005446", "event_type": "price_change"}}
{"_local_timestamp": "2026-01-25T23:50:05.788446+00:00", "data": {"market": "0x61af02c9250c3917602e21c301e2f0cd032ea4e25bdef3751846b4d5f1c22799", "price_changes": [{"asset_id": "40581037591963443982506549884210281226867122905421206884675003828040093511244", "price": "0.23", "size": "100", "side": "BUY", "hash": "287a333b80c08c2cef1843971416d9bf419474df", "best_bid": "0.77", "best_ask": "0.79"}, {"asset_id": "77997400651011819054222158182618580861479123177562866576575031403070672671390", "price": "0.77", "size": "100", "side": "SELL", "hash": "7a4b3366a1ed6f44e7709fd1366f325d7b7e4c9b", "best_bid": "0.21", "best_ask": "0.23"}], "timestamp": "1769385005714", "event_type": "price_change"}}
{"_local_timestamp": "2026-01-25T23:50:46.348545+00:00", "data": {"market": "0x61af02c9250c3917602e21c301e2f0cd032ea4e25bdef3751846b4d5f1c22799", "price_changes": [{"asset_id": "40581037591963443982506549884210281226867122905421206884675003828040093511244", "price": "0.17", "size": "50", "side": "BUY", "hash": "c6a4628801304ff5bb09dff9cdc72b6c50325d4c", "best_bid": "0.77", "best_ask": "0.79"}, {"asset_id": "77997400651011819054222158182618580861479123177562866576575031403070672671390", "price": "0.83", "size": "50", "side": "SELL", "hash": "856f402d83f29daf49404fdc2b3de7e3361446cc", "best_bid": "0.21", "best_ask": "0.23"}], "timestamp": "1769385046263", "event_type": "price_change"}}
{"_local_timestamp": "2026-01-25T23:50:46.358486+00:00", "data": {"market": "0x61af02c9250c3917602e21c301e2f0cd032ea4e25bdef3751846b4d5f1c22799", "price_changes": [{"asset_id": "40581037591963443982506549884210281226867122905421206884675003828040093511244", "price": "0.23", "size": "0", "side": "BUY", "hash": "c6a4628801304ff5bb09dff9cdc72b6c50325d4c", "best_bid": "0.77", "best_ask": "0.79"}, {"asset_id": "77997400651011819054222158182618580861479123177562866576575031403070672671390", "price": "0.77", "size": "0", "side": "SELL", "hash": "856f402d83f29daf49404fdc2b3de7e3361446cc", "best_bid": "0.21", "best_ask": "0.23"}], "timestamp": "1769385046263", "event_type": "price_change"}}
{"_local_timestamp": "2026-01-25T23:50:46.784013+00:00", "data": {"market": "0x61af02c9250c3917602e21c301e2f0cd032ea4e25bdef3751846b4d5f1c22799", "price_changes": [{"asset_id": "40581037591963443982506549884210281226867122905421206884675003828040093511244", "price": "0.19", "size": "2360", "side": "BUY", "hash": "f501a8d56e95b84df074210d02cd145b66636f28", "best_bid": "0.77", "best_ask": "0.79"}, {"asset_id": "77997400651011819054222158182618580861479123177562866576575031403070672671390", "price": "0.81", "size": "2360", "side": "SELL", "hash": "a189a5a53dc530d1f47e7456ee0aca0e12bde788", "best_bid": "0.21", "best_ask": "0.23"}], "timestamp": "1769385046634", "event_type": "price_change"}}
{"_local_timestamp": "2026-01-25T23:50:46.820249+00:00", "data": {"market": "0x61af02c9250c3917602e21c301e2f0cd032ea4e25bdef3751846b4d5f1c22799", "price_changes": [{"asset_id": "40581037591963443982506549884210281226867122905421206884675003828040093511244", "price": "0.25", "size": "604", "side": "BUY", "hash": "9609860fcd104133def05f96fe7f9418a579b843", "best_bid": "0.77", "best_ask": "0.79"}, {"asset_id": "77997400651011819054222158182618580861479123177562866576575031403070672671390", "price": "0.75", "size": "604", "side": "SELL", "hash": "e4c9678d7fd30235528b34ba93d1f3b957208dfc", "best_bid": "0.21", "best_ask": "0.23"}], "timestamp": "1769385046650", "event_type": "price_change"}}
{"_local_timestamp": "2026-01-25T23:50:56.078758+00:00", "data": {"market": "0x61af02c9250c3917602e21c301e2f0cd032ea4e25bdef3751846b4d5f1c22799", "price_changes": [{"asset_id": "40581037591963443982506549884210281226867122905421206884675003828040093511244", "price": "0.77", "size": "29.99", "side": "BUY", "hash": "9e4c55f50acbbddbe9d5464c49f9ca504af892f8", "best_bid": "0.77", "best_ask": "0.79"}, {"asset_id": "77997400651011819054222158182618580861479123177562866576575031403070672671390", "price": "0.23", "size": "29.99", "side": "SELL", "hash": "14283a2c5139b74592d26aeecd167e443b2a9b8d", "best_bid": "0.21", "best_ask": "0.23"}], "timestamp": "1769385056000", "event_type": "price_change"}}
{"_local_timestamp": "2026-01-25T23:51:05.472446+00:00", "data": {"market": "0x61af02c9250c3917602e21c301e2f0cd032ea4e25bdef3751846b4d5f1c22799", "price_changes": [{"asset_id": "40581037591963443982506549884210281226867122905421206884675003828040093511244", "price": "0.18", "size": "150", "side": "BUY", "hash": "4285a6c6f9f9140ba1e595b0391c199a007d274a", "best_bid": "0.77", "best_ask": "0.79"}, {"asset_id": "77997400651011819054222158182618580861479123177562866576575031403070672671390", "price": "0.82", "size": "150", "side": "SELL", "hash": "bd374b8b1023f97514abf9627f02ba80c209f5ad", "best_bid": "0.21", "best_ask": "0.23"}], "timestamp": "1769385065402", "event_type": "price_change"}}
{"_local_timestamp": "2026-01-25T23:51:05.882509+00:00", "data": {"market": "0x61af02c9250c3917602e21c301e2f0cd032ea4e25bdef3751846b4d5f1c22799", "price_changes": [{"asset_id": "40581037591963443982506549884210281226867122905421206884675003828040093511244", "price": "0.17", "size": "150", "side": "BUY", "hash": "7738f5347f6c555cc59f6c4387037b7fa21aedd3", "best_bid": "0.77", "best_ask": "0.79"}, {"asset_id": "77997400651011819054222158182618580861479123177562866576575031403070672671390", "price": "0.83", "size": "150", "side": "SELL", "hash": "f6fac5f0d79854f04ec63e03ce6960e5eaddfa11", "best_bid": "0.21", "best_ask": "0.23"}], "timestamp": "1769385065766", "event_type": "price_change"}}
{"_local_timestamp": "2026-01-25T23:51:25.712345+00:00", "data": {"market": "0x61af02c9250c3917602e21c301e2f0cd032ea4e25bdef3751846b4d5f1c22799", "price_changes": [{"asset_id": "40581037591963443982506549884210281226867122905421206884675003828040093511244", "price": "0.17", "size": "100", "side": "BUY", "hash": "f36d3dab7e86f881a1066ab47a4dfdd7e7627919", "best_bid": "0.77", "best_ask": "0.79"}, {"asset_id": "77997400651011819054222158182618580861479123177562866576575031403070672671390", "price": "0.83", "size": "100", "side": "SELL", "hash": "81bc7e5e0b3bd66f795870ee5fdb3097cde1f2d3", "best_bid": "0.21", "best_ask": "0.23"}], "timestamp": "1769385085598", "event_type": "price_change"}}
{"_local_timestamp": "2026-01-25T23:51:26.069417+00:00", "data": {"market": "0x61af02c9250c3917602e21c301e2f0cd032ea4e25bdef3751846b4d5f1c22799", "price_changes": [{"asset_id": "40581037591963443982506549884210281226867122905421206884675003828040093511244", "price": "0.19", "size": "2410", "side": "BUY", "hash": "2ae415d62ec845f75b9733d05194379bcc7e0d5a", "best_bid": "0.77", "best_ask": "0.79"}, {"asset_id": "77997400651011819054222158182618580861479123177562866576575031403070672671390", "price": "0.81", "size": "2410", "side": "SELL", "hash": "2ba5e27a383a8c3e00b69c199c764d686a055446", "best_bid": "0.21", "best_ask": "0.23"}], "timestamp": "1769385085995", "event_type": "price_change"}}
