{"_local_timestamp": "2026-01-25T23:33:17.522648+00:00", "data": [{"market": "0xfc6260666d020a912a87d9000eff5116d2adfb8c30aba543427a4c1f1411f1a0", "asset_id": "57301498276970257025109591078431189727442302532145853906375186182281603517458", "timestamp": "1769383997119", "hash": "4acfab23557a92b8ee0d782ab0901e99e99c4978", "bids": [{"price": "0.01", "size": "10098"}, {"price": "0.02", "size": "5016.18"}, {"price": "0.03", "size": "300"}, {"price": "0.04", "size": "7.59"}, {"price": "0.05", "size": "400"}, {"price": "0.06", "size": "200"}, {"price": "0.08", "size": "1212"}, {"price": "0.09", "size": "1000"}, {"price": "0.1", "size": "465.72"}, {"price": "0.11", "size": "300"}, {"price": "0.12", "size": "540"}, {"price": "0.13", "size": "250"}, {"price": "0.14", "size": "850"}, {"price": "0.15", "size": "520"}, {"price": "0.16", "size": "748.44"}, {"price": "0.18", "size": "182.81"}, {"price": "0.19", "size": "50"}, {"price": "0.2", "size": "4452.97"}, {"price": "0.21", "size": "5100"}, {"price": "0.22", "size": "5429.7"}, {"price": "0.23", "size": "2156.52"}, {"price": "0.24", "size": "2280"}, {"price": "0.25", "size": "1806.49"}, {"price": "0.26", "size": "495.89"}, {"price": "0.27", "size": "1228.23"}, {"price": "0.29", "size": "479"}, {"price": "0.3", "size": "1429.07"}, {"price": "0.31", "size": "438.75"}, {"price": "0.32", "size": "416.72"}, {"price": "0.33", "size": "30"}], "asks": [{"price": "0.99", "size": "3037.69"}, {"price": "0.98", "size": "24000"}, {"price": "0.97", "size": "52352.05"}, {"price": "0.96", "size": "6.67"}, {"price": "0.95", "size": "142.74"}, {"price": "0.94", "size": "11133.23"}, {"price": "0.93", "size": "1650"}, {"price": "0.92", "size": "1663"}, {"price": "0.91", "size": "670"}, {"price": "0.9", "size": "2033.08"}, {"price": "0.89", "size": "1305.32"}, {"price": "0.88", "size": "1812.94"}, {"price": "0.87", "size": "1000"}, {"price": "0.86", "size": "300"}, {"price": "0.85", "size": "36973.9"}, {"price": "0.84", "size": "1690.54"}, {"price": "0.83", "size": "10200"}, {"price": "0.82", "size": "3200"}, {"price": "0.81", "size": "1200"}, {"price": "0.8", "size": "2200"}, {"price": "0.79", "size": "1200"}, {"price": "0.78", "size": "150"}, {"price": "0.77", "size": "2050"}, {"price": "0.76", "size": "2345"}, {"price": "0.74", "size": "1035.69"}, {"price": "0.72", "size": "2030.08"}, {"price": "0.7", "size": "5070"}, {"price": "0.69", "size": "1100"}, {"price": "0.67", "size": "510"}, {"price": "0.66", "size": "2100"}, {"price": "0.65", "size": "2500"}, {"price": "0.64", "size": "600"}, {"price": "0.63", "size": "222"}, {"price": "0.62", "size": "1000"}, {"price": "0.6", "size": "6039.39"}, {"price": "0.59", "size": "1000"}, {"price": "0.58", "size": "1100"}, {"price": "0.57", "size": "26011.77"}, {"price": "0.56", "size": "10650.85"}, {"price": "0.55", "size": "2065.17"}, {"price": "0.52", "size": "220"}, {"price": "0.51", "size": "2062.98"}, {"price": "0.5", "size": "1600"}, {"price": "0.45", "size": "606.99"}, {"price": "0.43", "size": "117.41"}, {"price": "0.42", "size": "1228.52"}, {"price": "0.41", "size": "500"}, {"price": "0.4", "size": "2121.66"}, {"price": "0.39", "size": "1965.03"}, {"price": "0.38", "size": "1000"}, {"price": "0.36", "size": "1140.09"}, {"price": "0.35", "size": "11261.24"}, {"price": "0.34", "size": "328.31"}], "event_type": "book", "last_trade_price": "0.660"}, {"market": "0x2307312887c6de01a9f55b7b7afc7c4a0be8718d7d868280e7d898f0ea54f740", "asset_id": "92206458231325096769152348269441704588222763710040504959674288895806154976594", "timestamp": "1769383935069", "hash": "a25b2cb676cb1df29af8bc49737fea2a76b70a9e", "bids": [{"price": "0.01", "size": "83111.77"}, {"price": "0.02", "size": "916.13"}, {"price": "0.03", "size": "1668.13"}, {"price": "0.04", "size": "5784.53"}, {"price": "0.05", "size": "2848.26"}, {"price": "0.06", "size": "5217.76"}, {"price": "0.07", "size": "456.85"}, {"price": "0.08", "size": "1612.99"}, {"price": "0.09", "size": "798.34"}, {"price": "0.1", "size": "2120.6"}], "asks": [{"price": "0.99", "size": "62014.33"}, {"price": "0.98", "size": "20500"}, {"price": "0.97", "size": "4000"}, {"price": "0.96", "size": "6.52"}, {"price": "0.95", "size": "81"}, {"price": "0.94", "size": "9473"}, {"price": "0.92", "size": "100"}, {"price": "0.91", "size": "9600"}, {"price": "0.9", "size": "250"}, {"price": "0.89", "size": "5.41"}, {"price": "0.88", "size": "1500"}, {"price": "0.83", "size": "1500"}, {"price": "0.82", "size": "4172"}, {"price": "0.78", "size": "1000"}, {"price": "0.77", "size": "200"}, {"price": "0.75", "size": "2000"}, {"price": "0.73", "size": "242.55"}, {"price": "0.72", "size": "25000"}, {"price": "0.71", "size": "1015"}, {"price": "0.7", "size": "100"}, {"price": "0.69", "size": "1005"}, {"price": "0.6", "size": "2233.32"}, {"price": "0.59", "size": "500"}, {"price": "0.56", "size": "73.99"}, {"price": "0.55", "size": "500"}, {"price": "0.51", "size": "100"}, {"price": "0.5", "size": "200"}, {"price": "0.49", "size": "6155"}, {"price": "0.48", "size": "3333"}, {"price": "0.47", "size": "600"}, {"price": "0.45", "size": "3100"}, {"price": "0.44", "size": "200"}, {"price": "0.43", "size": "5"}, {"price": "0.42", "size": "100"}, {"price": "0.41", "size": "700"}, {"price": "0.4", "size": "100"}, {"price": "0.35", "size": "250"}, {"price": "0.29", "size": "5"}, {"price": "0.28", "size": "1836.19"}, {"price": "0.25", "size": "1668"}, {"price": "0.24", "size": "1815"}, {"price": "0.22", "size": "1346"}, {"price": "0.21", "size": "1000"}, {"price": "0.2", "size": "1758.45"}, {"price": "0.19", "size": "1734.83"}, {"price": "0.18", "size": "610.57"}, {"price": "0.17", "size": "1276.19"}, {"price": "0.16", "size": "595"}, {"price": "0.15", "size": "200"}, {"price": "0.14", "size": "1000"}, {"price": "0.13", "size": "1072"}, {"price": "0.12", "size": "1094"}, {"price": "0.11", "size": "877.9"}], "event_type": "book", "last_trade_price": "0.900"}, {"market": "0xb2abfc4e48334d87681240cd6a7e63c728e13973fbd68951b45bc86d6c4491e4", "asset_id": "82149110067979470707461735036792617981060265491561473691799265056474452809853", "timestamp": "1769383845399", "hash": "ca0993ee442b07b0749c45adbc0007810e2f006f", "bids": [{"price": "0.001", "size": "1130.3"}, {"price": "0.002", "size": "255.09"}, {"price": "0.003", "size": "13.24"}, {"price": "0.004", "size": "9.93"}, {"price": "0.01", "size": "10000"}, {"price": "0.011", "size": "12.7"}, {"price": "0.012", "size": "11.29"}, {"price": "0.02", "size": "31000"}, {"price": "0.03", "size": "500"}, {"price": "0.04", "size": "1250"}, {"price": "0.041", "size": "250"}, {"price": "0.042", "size": "5.06"}, {"price": "0.05", "size": "30"}, {"price": "0.051", "size": "39"}, {"price": "0.08", "size": "100"}, {"price": "0.1", "size": "1250"}, {"price": "0.101", "size": "5.91"}, {"price": "0.2", "size": "2000"}, {"price": "0.21", "size": "1000"}, {"price": "0.22", "size": "250"}, {"price": "0.25", "size": "330"}, {"price": "0.28", "size": "83.33"}, {"price": "0.3", "size": "34.48"}, {"price": "0.31", "size": "3541.63"}, {"price": "0.32", "size": "3887.14"}, {"price": "0.4", "size": "93.33"}, {"price": "0.43", "size": "2000"}, {"price": "0.44", "size": "20500"}, {"price": "0.47", "size": "500"}, {"price": "0.5", "size": "932"}, {"price": "0.51", "size": "50"}, {"price": "0.54", "size": "500"}, {"price": "0.55", "size": "1000"}, {"price": "0.59", "size": "4111.09"}, {"price": "0.6", "size": "516.66"}, {"price": "0.61", "size": "1000"}, {"price": "0.62", "size": "750"}, {"price": "0.68", "size": "740.11"}, {"price": "0.7", "size": "1100"}, {"price": "0.71", "size": "136"}, {"price": "0.75", "size": "250"}, {"price": "0.8", "size": "1100"}, {"price": "0.804", "size": "500"}, {"price": "0.88", "size": "6"}, {"price": "0.9", "size": "15"}, {"price": "0.91", "size": "590.17"}, {"price": "0.92", "size": "600"}, {"price": "0.921", "size": "100"}, {"price": "0.93", "size": "200"}, {"price": "0.931", "size": "20"}, {"price": "0.934", "size": "300"}, {"price": "0.938", "size": "290"}, {"price": "0.944", "size": "998.53"}, {"price": "0.945", "size": "1000"}, {"price": "0.946", "size": "472.9"}, {"price": "0.947", "size": "50"}], "asks": [{"price": "0.999", "size": "10914.99"}, {"price": "0.998", "size": "5011.69"}, {"price": "0.997", "size": "77.33"}, {"price": "0.99", "size": "39777.13"}, {"price": "0.989", "size": "750"}, {"price": "0.988", "size": "18.12"}, {"price": "0.98", "size": "1005"}, {"price": "0.979", "size": "200"}, {"price": "0.978", "size": "5.69"}, {"price": "0.974", "size": "200"}, {"price": "0.973", "size": "460"}, {"price": "0.972", "size": "6.54"}, {"price": "0.97", "size": "15648.21"}, {"price": "0.969", "size": "516.16"}, {"price": "0.968", "size": "1000"}, {"price": "0.967", "size": "233.09"}, {"price": "0.965", "size": "1000"}, {"price": "0.964", "size": "6.08"}, {"price": "0.958", "size": "408.73"}, {"price": "0.957", "size": "80.47"}], "event_type": "book", "last_trade_price": "0.948"}, {"market": "0x940f01421649348b09dbf72bfd90788b9513ee56d9a0e7532c45ecda1ecfc6b4", "asset_id": "65375575037849886682769112267853604820362504640888829027195234577761014837492", "timestamp": "1769383819847", "hash": "cd63622cd87011d55130229bd4896cd6a98e62d5", "bids": [{"price": "0.01", "size": "43"}, {"price": "0.02", "size": "10.78"}, {"price": "0.03", "size": "200"}, {"price": "0.04", "size": "105.26"}, {"price": "0.05", "size": "30"}, {"price": "0.06", "size": "1857.65"}, {"price": "0.07", "size": "10.49"}, {"price": "0.11", "size": "100"}, {"price": "0.2", "size": "5000"}, {"price": "0.21", "size": "1450"}, {"price": "0.24", "size": "150"}, {"price": "0.27", "size": "100"}, {"price": "0.3", "size": "100"}, {"price": "0.5", "size": "54596.01"}, {"price": "0.51", "size": "350"}, {"price": "0.55", "size": "1099.97"}, {"price": "0.56", "size": "88.23"}, {"price": "0.6", "size": "1000"}, {"price": "0.65", "size": "6000"}, {"price": "0.69", "size": "10"}, {"price": "0.7", "size": "1109.99"}, {"price": "0.71", "size": "369"}, {"price": "0.74", "size": "17.56"}, {"price": "0.75", "size": "1014.66"}, {"price": "0.77", "size": "11653.19"}, {"price": "0.78", "size": "10078"}, {"price": "0.79", "size": "1601.76"}, {"price": "0.8", "size": "10571.03"}, {"price": "0.81", "size": "2840.8"}, {"price": "0.82", "size": "12105.32"}], "asks": [{"price": "0.99", "size": "837.8"}, {"price": "0.98", "size": "4024.47"}, {"price": "0.97", "size": "28030"}, {"price": "0.96", "size": "3008.15"}, {"price": "0.95", "size": "3555.69"}, {"price": "0.94", "size": "12242.34"}, {"price": "0.93", "size": "6850.65"}, {"price": "0.92", "size": "10405.19"}, {"price": "0.91", "size": "5311.11"}, {"price": "0.9", "size": "10606.45"}, {"price": "0.89", "size": "4220.47"}, {"price": "0.88", "size": "32078"}, {"price": "0.87", "size": "189"}, {"price": "0.86", "size": "29137.66"}, {"price": "0.85", "size": "6893.85"}, {"price": "0.84", "size": "1027.7"}], "event_type": "book", "last_trade_price": "0.160"}, {"market": "0x940f01421649348b09dbf72bfd90788b9513ee56d9a0e7532c45ecda1ecfc6b4", "asset_id": "22157788639457752387252020336806561376443885827015017216009958284137301583191", "timestamp": "1769383819847", "hash": "fd8d092b8990b21031780d41c9fda0bdbf37ba62", "bids": [{"price": "0.01", "size": "837.8"}, {"price": "0.02", "size": "4024.47"}, {"price": "0.03", "size": "28030"}, {"price": "0.04", "size": "3008.15"}, {"price": "0.05", "size": "3555.69"}, {"price": "0.06", "size": "12242.34"}, {"price": "0.07", "size": "6850.65"}, {"price": "0.08", "size": "10405.19"}, {"price": "0.09", "size": "5311.11"}, {"price": "0.1", "size": "10606.45"}, {"price": "0.11", "size": "4220.47"}, {"price": "0.12", "size": "32078"}, {"price": "0.13", "size": "189"}, {"price": "0.14", "size": "29137.66"}, {"price": "0.15", "size": "6893.85"}, {"price": "0.16", "size": "1027.7"}], "asks": [{"price": "0.99", "size": "43"}, {"price": "0.98", "size": "10.78"}, {"price": "0.97", "size": "200"}, {"price": "0.96", "size": "105.26"}, {"price": "0.95", "size": "30"}, {"price": "0.94", "size": "1857.65"}, {"price": "0.93", "size": "10.49"}, {"price": "0.89", "size": "100"}, {"price": "0.8", "size": "5000"}, {"price": "0.79", "size": "1450"}, {"price": "0.76", "size": "150"}, {"price": "0.73", "size": "100"}, {"price": "0.7", "size": "100"}, {"price": "0.5", "size": "54596.01"}, {"price": "0.49", "size": "350"}, {"price": "0.45", "size": "1099.97"}, {"price": "0.44", "size": "88.23"}, {"price": "0.4", "size": "1000"}, {"price": "0.35", "size": "6000"}, {"price": "0.31", "size": "10"}, {"price": "0.3", "size": "1109.99"}, {"price": "0.29", "size": "369"}, {"price": "0.26", "size": "17.56"}, {"price": "0.25", "size": "1014.66"}, {"price": "0.23", "size": "11653.19"}, {"price": "0.22", "size": "10078"}, {"price": "0.21", "size": "1601.76"}, {"price": "0.2", "size": "10571.03"}, {"price": "0.19", "size": "2840.8"}, {"price": "0.18", "size": "12105.32"}], "event_type": "book", "last_trade_price": "0.160"}, {"market": "0xdb68062324c27327e9cd4b21b1dd0deadbc4b860abb8c076b9ba3ed4652ced13", "asset_id": "70438891017239169523888340706940482203786228582885836666142245799578935372711", "timestamp": "1769383967842", "hash": "63cf5e05d1569141741f84d9f7b9e775ed6130e1", "bids": [{"price": "0.001", "size": "6794.08"}, {"price": "0.002", "size": "1255.05"}, {"price": "0.003", "size": "1400"}, {"price": "0.004", "size": "8.64"}, {"price": "0.006", "size": "200"}, {"price": "0.01", "size": "62000"}, {"price": "0.011", "size": "8.79"}, {"price": "0.02", "size": "49250"}, {"price": "0.03", "size": "4000"}, {"price": "0.031", "size": "154.83"}, {"price": "0.04", "size": "2500"}, {"price": "0.041", "size": "5.28"}, {"price": "0.05", "size": "540"}, {"price": "0.051", "size": "39"}, {"price": "0.06", "size": "9440"}, {"price": "0.061", "size": "78.68"}, {"price": "0.08", "size": "5440"}, {"price": "0.099", "size": "48.48"}, {"price": "0.1", "size": "6.37"}, {"price": "0.125", "size": "2500"}, {"price": "0.127", "size": "2000"}, {"price": "0.129", "size": "3800"}, {"price": "0.13", "size": "36.92"}, {"price": "0.361", "size": "5"}, {"price": "0.362", "size": "13.25"}, {"price": "0.4", "size": "1000"}, {"price": "0.401", "size": "11.97"}, {"price": "0.45", "size": "2400"}, {"price": "0.451", "size": "10.64"}, {"price": "0.5", "size": "809.97"}, {"price": "0.501", "size": "9.58"}, {"price": "0.64", "size": "7092.74"}, {"price": "0.65", "size": "1120.83"}, {"price": "0.655", "size": "111"}, {"price": "0.66", "size": "100"}, {"price": "0.69", "size": "10000"}, {"price": "0.691", "size": "6.94"}, {"price": "0.71", "size": "600"}, {"price": "0.72", "size": "100"}, {"price": "0.73", "size": "400"}, {"price": "0.75", "size": "1660.5"}, {"price": "0.76", "size": "200"}, {"price": "0.77", "size": "100"}, {"price": "0.78", "size": "100"}, {"price": "0.79", "size": "200"}, {"price": "0.8", "size": "1300"}, {"price": "0.85", "size": "300"}, {"price": "0.89", "size": "50"}, {"price": "0.948", "size": "100"}, {"price": "0.95", "size": "365"}, {"price": "0.951", "size": "200"}, {"price": "0.952", "size": "100"}, {"price": "0.956", "size": "300"}, {"price": "0.96", "size": "100"}, {"price": "0.961", "size": "500"}, {"price": "0.97", "size": "57.89"}, {"price": "0.972", "size": "342.22"}, {"price": "0.973", "size": "40"}, {"price": "0.975", "size": "5.59"}, {"price": "0.977", "size": "843.62"}, {"price": "0.978", "size": "100"}, {"price": "0.98", "size": "235.36"}], "asks": [{"price": "0.999", "size": "20543.23"}, {"price": "0.998", "size": "3267.2"}, {"price": "0.997", "size": "66.41"}, {"price": "0.996", "size": "46.01"}, {"price": "0.995", "size": "1006.77"}, {"price": "0.994", "size": "16.78"}, {"price": "0.992", "size": "625"}, {"price": "0.991", "size": "11.02"}, {"price": "0.99", "size": "24858.77"}, {"price": "0.989", "size": "1005.46"}, {"price": "0.988", "size": "437.25"}, {"price": "0.987", "size": "30.08"}, {"price": "0.986", "size": "34"}, {"price": "0.985", "size": "30308.83"}, {"price": "0.984", "size": "68.75"}, {"price": "0.983", "size": "2148.23"}, {"price": "0.982", "size": "1838.15"}, {"price": "0.981", "size": "1066.98"}], "event_type": "book", "last_trade_price": "0.980"}, {"market": "0xfc6260666d020a912a87d9000eff5116d2adfb8c30aba543427a4c1f1411f1a0", "asset_id": "20615575591261238050354259319465440337102580196335623615376639598123117400036", "timestamp": "1769383997119", "hash": "c5dbdad56de8ac20dac48c049564762a7e3d05ca", "bids": [{"price": "0.01", "size": "3037.69"}, {"price": "0.02", "size": "24000"}, {"price": "0.03", "size": "52352.05"}, {"price": "0.04", "size": "6.67"}, {"price": "0.05", "size": "142.74"}, {"price": "0.06", "size": "11133.23"}, {"price": "0.07", "size": "1650"}, {"price": "0.08", "size": "1663"}, {"price": "0.09", "size": "670"}, {"price": "0.1", "size": "2033.08"}, {"price": "0.11", "size": "1305.32"}, {"price": "0.12", "size": "1812.94"}, {"price": "0.13", "size": "1000"}, {"price": "0.14", "size": "300"}, {"price": "0.15", "size": "36973.9"}, {"price": "0.16", "size": "1690.54"}, {"price": "0.17", "size": "10200"}, {"price": "0.18", "size": "3200"}, {"price": "0.19", "size": "1200"}, {"price": "0.2", "size": "2200"}, {"price": "0.21", "size": "1200"}, {"price": "0.22", "size": "150"}, {"price": "0.23", "size": "2050"}, {"price": "0.24", "size": "2345"}, {"price": "0.26", "size": "1035.69"}, {"price": "0.28", "size": "2030.08"}, {"price": "0.3", "size": "5070"}, {"price": "0.31", "size": "1100"}, {"price": "0.33", "size": "510"}, {"price": "0.34", "size": "2100"}, {"price": "0.35", "size": "2500"}, {"price": "0.36", "size": "600"}, {"price": "0.37", "size": "222"}, {"price": "0.38", "size": "1000"}, {"price": "0.4", "size": "6039.39"}, {"price": "0.41", "size": "1000"}, {"price": "0.42", "size": "1100"}, {"price": "0.43", "size": "26011.77"}, {"price": "0.44", "size": "10650.85"}, {"price": "0.45", "size": "2065.17"}, {"price": "0.48", "size": "220"}, {"price": "0.49", "size": "2062.98"}, {"price": "0.5", "size": "1600"}, {"price": "0.55", "size": "606.99"}, {"price": "0.57", "size": "117.41"}, {"price": "0.58", "size": "1228.52"}, {"price": "0.59", "size": "500"}, {"price": "0.6", "size": "2121.66"}, {"price": "0.61", "size": "1965.03"}, {"price": "0.62", "size": "1000"}, {"price": "0.64", "size": "1140.09"}, {"price": "0.65", "size": "11261.24"}, {"price": "0.66", "size": "328.31"}], "asks": [{"price": "0.99", "size": "10098"}, {"price": "0.98", "size": "5016.18"}, {"price": "0.97", "size": "300"}, {"price": "0.96", "size": "7.59"}, {"price": "0.95", "size": "400"}, {"price": "0.94", "size": "200"}, {"price": "0.92", "size": "1212"}, {"price": "0.91", "size": "1000"}, {"price": "0.9", "size": "465.72"}, {"price": "0.89", "size": "300"}, {"price": "0.88", "size": "540"}, {"price": "0.87", "size": "250"}, {"price": "0.86", "size": "850"}, {"price": "0.85", "size": "520"}, {"price": "0.84", "size": "748.44"}, {"price": "0.82", "size": "182.81"}, {"price": "0.81", "size": "50"}, {"price": "0.8", "size": "4452.97"}, {"price": "0.79", "size": "5100"}, {"price": "0.78", "size": "5429.7"}, {"price": "0.77", "size": "2156.52"}, {"price": "0.76", "size": "2280"}, {"price": "0.75", "size": "1806.49"}, {"price": "0.74", "size": "495.89"}, {"price": "0.73", "size": "1228.23"}, {"price": "0.71", "size": "479"}, {"price": "0.7", "size": "1429.07"}, {"price": "0.69", "size": "438.75"}, {"price": "0.68", "size": "416.72"}, {"price": "0.67", "size": "30"}], "event_type": "book", "last_trade_price": "0.660"}, {"market": "0xb2abfc4e48334d87681240cd6a7e63c728e13973fbd68951b45bc86d6c4491e4", "asset_id": "18210569213780052033306952138558054016080325272524745338190244466404715123630", "timestamp": "1769383845399", "hash": "037d29c1eabe80b05087b63b6ceb102d08b6d6e3", "bids": [{"price": "0.001", "size": "10914.99"}, {"price": "0.002", "size": "5011.69"}, {"price": "0.003", "size": "77.33"}, {"price": "0.01", "size": "39777.13"}, {"price": "0.011", "size": "750"}, {"price": "0.012", "size": "18.12"}, {"price": "0.02", "size": "1005"}, {"price": "0.021", "size": "200"}, {"price": "0.022", "size": "5.69"}, {"price": "0.026", "size": "200"}, {"price": "0.027", "size": "460"}, {"price": "0.028", "size": "6.54"}, {"price": "0.03", "size": "15648.21"}, {"price": "0.031", "size": "516.16"}, {"price": "0.032", "size": "1000"}, {"price": "0.033", "size": "233.09"}, {"price": "0.035", "size": "1000"}, {"price": "0.036", "size": "6.08"}, {"price": "0.042", "size": "408.73"}, {"price": "0.043", "size": "80.47"}], "asks": [{"price": "0.999", "size": "1130.3"}, {"price": "0.998", "size": "255.09"}, {"price": "0.997", "size": "13.24"}, {"price": "0.996", "size": "9.93"}, {"price": "0.99", "size": "10000"}, {"price": "0.989", "size": "12.7"}, {"price": "0.988", "size": "11.29"}, {"price": "0.98", "size": "31000"}, {"price": "0.97", "size": "500"}, {"price": "0.96", "size": "1250"}, {"price": "0.959", "size": "250"}, {"price": "0.958", "size": "5.06"}, {"price": "0.95", "size": "30"}, {"price": "0.949", "size": "39"}, {"price": "0.92", "size": "100"}, {"price": "0.9", "size": "1250"}, {"price": "0.899", "size": "5.91"}, {"price": "0.8", "size": "2000"}, {"price": "0.79", "size": "1000"}, {"price": "0.78", "size": "250"}, {"price": "0.75", "size": "330"}, {"price": "0.72", "size": "83.33"}, {"price": "0.7", "size": "34.48"}, {"price": "0.69", "size": "3541.63"}, {"price": "0.68", "size": "3887.14"}, {"price": "0.6", "size": "93.33"}, {"price": "0.57", "size": "2000"}, {"price": "0.56", "size": "20500"}, {"price": "0.53", "size": "500"}, {"price": "0.5", "size": "932"}, {"price": "0.49", "size": "50"}, {"price": "0.46", "size": "500"}, {"price": "0.45", "size": "1000"}, {"price": "0.41", "size": "4111.09"}, {"price": "0.4", "size": "516.66"}, {"price": "0.39", "size": "1000"}, {"price": "0.38", "size": "750"}, {"price": "0.32", "size": "740.11"}, {"price": "0.3", "size": "1100"}, {"price": "0.29", "size": "136"}, {"price": "0.25", "size": "250"}, {"price": "0.2", "size": "1100"}, {"price": "0.196", "size": "500"}, {"price": "0.12", "size": "6"}, {"price": "0.1", "size": "15"}, {"price": "0.09", "size": "590.17"}, {"price": "0.08", "size": "600"}, {"price": "0.079", "size": "100"}, {"price": "0.07", "size": "200"}, {"price": "0.069", "size": "20"}, {"price": "0.066", "size": "300"}, {"price": "0.062", "size": "290"}, {"price": "0.056", "size": "998.53"}, {"price": "0.055", "size": "1000"}, {"price": "0.054", "size": "472.9"}, {"price": "0.053", "size": "50"}], "event_type": "book", "last_trade_price": "0.948"}, {"market": "0x2307312887c6de01a9f55b7b7afc7c4a0be8718d7d868280e7d898f0ea54f740", "asset_id": "76923693924406713859745805828172340186379347372867842378616708773220670988116", "timestamp": "1769383935069", "hash": "d2229ad14bedeb10da0d6f2e403843f4eb250263", "bids": [{"price": "0.01", "size": "62014.33"}, {"price": "0.02", "size": "20500"}, {"price": "0.03", "size": "4000"}, {"price": "0.04", "size": "6.52"}, {"price": "0.05", "size": "81"}, {"price": "0.06", "size": "9473"}, {"price": "0.08", "size": "100"}, {"price": "0.09", "size": "9600"}, {"price": "0.1", "size": "250"}, {"price": "0.11", "size": "5.41"}, {"price": "0.12", "size": "1500"}, {"price": "0.17", "size": "1500"}, {"price": "0.18", "size": "4172"}, {"price": "0.22", "size": "1000"}, {"price": "0.23", "size": "200"}, {"price": "0.25", "size": "2000"}, {"price": "0.27", "size": "242.55"}, {"price": "0.28", "size": "25000"}, {"price": "0.29", "size": "1015"}, {"price": "0.3", "size": "100"}, {"price": "0.31", "size": "1005"}, {"price": "0.4", "size": "2233.32"}, {"price": "0.41", "size": "500"}, {"price": "0.44", "size": "73.99"}, {"price": "0.45", "size": "500"}, {"price": "0.49", "size": "100"}, {"price": "0.5", "size": "200"}, {"price": "0.51", "size": "6155"}, {"price": "0.52", "size": "3333"}, {"price": "0.53", "size": "600"}, {"price": "0.55", "size": "3100"}, {"price": "0.56", "size": "200"}, {"price": "0.57", "size": "5"}, {"price": "0.58", "size": "100"}, {"price": "0.59", "size": "700"}, {"price": "0.6", "size": "100"}, {"price": "0.65", "size": "250"}, {"price": "0.71", "size": "5"}, {"price": "0.72", "size": "1836.19"}, {"price": "0.75", "size": "1668"}, {"price": "0.76", "size": "1815"}, {"price": "0.78", "size": "1346"}, {"price": "0.79", "size": "1000"}, {"price": "0.8", "size": "1758.45"}, {"price": "0.81", "size": "1734.83"}, {"price": "0.82", "size": "610.57"}, {"price": "0.83", "size": "1276.19"}, {"price": "0.84", "size": "595"}, {"price": "0.85", "size": "200"}, {"price": "0.86", "size": "1000"}, {"price": "0.87", "size": "1072"}, {"price": "0.88", "size": "1094"}, {"price": "0.89", "size": "877.9"}], "asks": [{"price": "0.99", "size": "83111.77"}, {"price": "0.98", "size": "916.13"}, {"price": "0.97", "size": "1668.13"}, {"price": "0.96", "size": "5784.53"}, {"price": "0.95", "size": "2848.26"}, {"price": "0.94", "size": "5217.76"}, {"price": "0.93", "size": "456.85"}, {"price": "0.92", "size": "1612.99"}, {"price": "0.91", "size": "798.34"}, {"price": "0.9", "size": "2120.6"}], "event_type": "book", "last_trade_price": "0.900"}, {"market": "0xdb68062324c27327e9cd4b21b1dd0deadbc4b860abb8c076b9ba3ed4652ced13", "asset_id": "78059086946243166298250434231742381590921423205138738331803802527161013528631", "timestamp": "1769383967842", "hash": "2b9151afbc9ee8555140936220b0d1c3265cb692", "bids": [{"price": "0.001", "size": "20543.23"}, {"price": "0.002", "size": "3267.2"}, {"price": "0.003", "size": "66.41"}, {"price": "0.004", "size": "46.01"}, {"price": "0.005", "size": "1006.77"}, {"price": "0.006", "size": "16.78"}, {"price": "0.008", "size": "625"}, {"price": "0.009", "size": "11.02"}, {"price": "0.01", "size": "24858.77"}, {"price": "0.011", "size": "1005.46"}, {"price": "0.012", "size": "437.25"}, {"price": "0.013", "size": "30.08"}, {"price": "0.014", "size": "34"}, {"price": "0.015", "size": "30308.83"}, {"price": "0.016", "size": "68.75"}, {"price": "0.017", "size": "2148.23"}, {"price": "0.018", "size": "1838.15"}, {"price": "0.019", "size": "1066.98"}], "asks": [{"price": "0.999", "size": "6794.08"}, {"price": "0.998", "size": "1255.05"}, {"price": "0.997", "size": "1400"}, {"price": "0.996", "size": "8.64"}, {"price": "0.994", "size": "200"}, {"price": "0.99", "size": "62000"}, {"price": "0.989", "size": "8.79"}, {"price": "0.98", "size": "49250"}, {"price": "0.97", "size": "4000"}, {"price": "0.969", "size": "154.83"}, {"price": "0.96", "size": "2500"}, {"price": "0.959", "size": "5.28"}, {"price": "0.95", "size": "540"}, {"price": "0.949", "size": "39"}, {"price": "0.94", "size": "9440"}, {"price": "0.939", "size": "78.68"}, {"price": "0.92", "size": "5440"}, {"price": "0.901", "size": "48.48"}, {"price": "0.9", "size": "6.37"}, {"price": "0.875", "size": "2500"}, {"price": "0.873", "size": "2000"}, {"price": "0.871", "size": "3800"}, {"price": "0.87", "size": "36.92"}, {"price": "0.639", "size": "5"}, {"price": "0.638", "size": "13.25"}, {"price": "0.6", "size": "1000"}, {"price": "0.599", "size": "11.97"}, {"price": "0.55", "size": "2400"}, {"price": "0.549", "size": "10.64"}, {"price": "0.5", "size": "809.97"}, {"price": "0.499", "size": "9.58"}, {"price": "0.36", "size": "7092.74"}, {"price": "0.35", "size": "1120.83"}, {"price": "0.345", "size": "111"}, {"price": "0.34", "size": "100"}, {"price": "0.31", "size": "10000"}, {"price": "0.309", "size": "6.94"}, {"price": "0.29", "size": "600"}, {"price": "0.28", "size": "100"}, {"price": "0.27", "size": "400"}, {"price": "0.25", "size": "1660.5"}, {"price": "0.24", "size": "200"}, {"price": "0.23", "size": "100"}, {"price": "0.22", "size": "100"}, {"price": "0.21", "size": "200"}, {"price": "0.2", "size": "1300"}, {"price": "0.15", "size": "300"}, {"price": "0.11", "size": "50"}, {"price": "0.052", "size": "100"}, {"price": "0.05", "size": "365"}, {"price": "0.049", "size": "200"}, {"price": "0.048", "size": "100"}, {"price": "0.044", "size": "300"}, {"price": "0.04", "size": "100"}, {"price": "0.039", "size": "500"}, {"price": "0.03", "size": "57.89"}, {"price": "0.028", "size": "342.22"}, {"price": "0.027", "size": "40"}, {"price": "0.025", "size": "5.59"}, {"price": "0.023", "size": "843.62"}, {"price": "0.022", "size": "100"}, {"price": "0.02", "size": "235.36"}], "event_type": "book", "last_trade_price": "0.980"}]}
{"_local_timestamp": "2026-01-25T23:33:18.659276+00:00", "data": {"market": "0xfc6260666d020a912a87d9000eff5116d2adfb8c30aba543427a4c1f1411f1a0", "price_changes": [{"asset_id": "20615575591261238050354259319465440337102580196335623615376639598123117400036", "price": "0.69", "size": "389.75", "side": "SELL", "hash": "150605c51c69dbe5606bc78e2e462016763256fc", "best_bid": "0.66", "best_ask": "0.67"}, {"asset_id": "57301498276970257025109591078431189727442302532145853906375186182281603517458", "price": "0.31", "size": "389.75", "side": "BUY", "hash": "460853db0f6975c2c5f9ec89b8222ba4df7b4470", "best_bid": "0.33", "best_ask": "0.34"}], "timestamp": "1769383998593", "event_type": "price_change"}}
{"_local_timestamp": "2026-01-25T23:33:18.688261+00:00", "data": {"market": "0xfc6260666d020a912a87d9000eff5116d2adfb8c30aba543427a4c1f1411f1a0", "price_changes": [{"asset_id": "20615575591261238050354259319465440337102580196335623615376639598123117400036", "price": "0.69", "size": "438.75", "side": "SELL", "hash": "1e29c27cfff1557a6569471d1aa9bd891ded3086", "best_bid": "0.66", "best_ask": "0.67"}, {"asset_id": "57301498276970257025109591078431189727442302532145853906375186182281603517458", "price": "0.31", "size": "438.75", "side": "BUY", "hash": "6762978db1bf39f00b51d128eff55a2157b86e13", "best_bid": "0.33", "best_ask": "0.34"}], "timestamp": "1769383998621", "event_type": "price_change"}}
{"_local_timestamp": "2026-01-25T23:33:20.164856+00:00", "data": {"market": "0xfc6260666d020a912a87d9000eff5116d2adfb8c30aba543427a4c1f1411f1a0", "price_changes": [{"asset_id": "20615575591261238050354259319465440337102580196335623615376639598123117400036", "price": "0.69", "size": "389.75", "side": "SELL", "hash": "c65f0238e06583dffc3d79ee0e669309a0a8f2e2", "best_bid": "0.66", "best_ask": "0.67"}, {"asset_id": "57301498276970257025109591078431189727442302532145853906375186182281603517458", "price": "0.31", "size": "389.75", "side": "BUY", "hash": "196c0c9255821f5d7d9e13a45f6a7e62931502d7", "best_bid": "0.33", "best_ask": "0.34"}], "timestamp": "1769384000095", "event_type": "price_change"}}
{"_local_timestamp": "2026-01-25T23:33:20.190997+00:00", "data": {"market": "0xfc6260666d020a912a87d9000eff5116d2adfb8c30aba543427a4c1f1411f1a0", "price_changes": [{"asset_id": "20615575591261238050354259319465440337102580196335623615376639598123117400036", "price": "0.69", "size": "438.75", "side": "SELL", "hash": "e3a7018489ab3b162515ce3a95fe7a05e8e6be42", "best_bid": "0.66", "best_ask": "0.67"}, {"asset_id": "57301498276970257025109591078431189727442302532145853906375186182281603517458", "price": "0.31", "size": "438.75", "side": "BUY", "hash": "bd2513902b154fd651ecb98a88cb0e55d0bf3453", "best_bid": "0.33", "best_ask": "0.34"}], "timestamp": "1769384000124", "event_type": "price_change"}}
{"_local_timestamp": "2026-01-25T23:33:21.665422+00:00", "data": {"market": "0xfc6260666d020a912a87d9000eff5116d2adfb8c30aba543427a4c1f1411f1a0", "price_changes": [{"asset_id": "20615575591261238050354259319465440337102580196335623615376639598123117400036", "price": "0.69", "size": "389.75", "side": "SELL", "hash": "70b463a3ec50fab66ce9b65891ddda79e1ba9b23", "best_bid": "0.66", "best_ask": "0.67"}, {"asset_id": "57301498276970257025109591078431189727442302532145853906375186182281603517458", "price": "0.31", "size": "389.75", "side": "BUY", "hash": "c2b6378f7b6bfea4e610545fdc06189258b65c4e", "best_bid": "0.33", "best_ask": "0.34"}], "timestamp": "1769384001593", "event_type": "price_change"}}
{"_local_timestamp": "2026-01-25T23:33:21.695009+00:00", "data": {"market": "0xfc6260666d020a912a87d9000eff5116d2adfb8c30aba543427a4c1f1411f1a0", "price_changes": [{"asset_id": "20615575591261238050354259319465440337102580196335623615376639598123117400036", "price": "0.69", "size": "438.75", "side": "SELL", "hash": "06221eeeeb392bb81d798122274142e2855c055a", "best_bid": "0.66", "best_ask": "0.67"}, {"asset_id": "57301498276970257025109591078431189727442302532145853906375186182281603517458", "price": "0.31", "size": "438.75", "side": "BUY", "hash": "c61806526f451309b3e402d41fa460bb8dddf94c", "best_bid": "0.33", "best_ask": "0.34"}], "timestamp": "1769384001621", "event_type": "price_change"}}
{"_local_timestamp": "2026-01-25T23:33:23.160706+00:00", "data": {"market": "0xfc6260666d020a912a87d9000eff5116d2adfb8c30aba543427a4c1f1411f1a0", "price_changes": [{"asset_id": "20615575591261238050354259319465440337102580196335623615376639598123117400036", "price": "0.69", "size": "389.75", "side": "SELL", "hash": "24d505e0c5cb7c4b4e7486139f26c13ac0669d41", "best_bid": "0.66", "best_ask": "0.67"}, {"asset_id": "57301498276970257025109591078431189727442302532145853906375186182281603517458", "price": "0.31", "size": "389.75", "side": "BUY", "hash": "f77658fabb2c6681861f19ece5d16c7d1ae623b7", "best_bid": "0.33", "best_ask": "0.34"}], "timestamp": "1769384003094", "event_type": "price_change"}}
{"_local_timestamp": "2026-01-25T23:33:23.213692+00:00", "data": {"market": "0xfc6260666d020a912a87d9000eff5116d2adfb8c30aba543427a4c1f1411f1a0", "price_changes": [{"asset_id": "20615575591261238050354259319465440337102580196335623615376639598123117400036", "price": "0.69", "size": "438.75", "side": "SELL", "hash": "f1f116852e3ec9309d7b9e3f33dafee42e8b63e1", "best_bid": "0.66", "best_ask": "0.67"}, {"asset_id": "57301498276970257025109591078431189727442302532145853906375186182281603517458", "price": "0.31", "size": "438.75", "side": "BUY", "hash": "5e57ce675ea357de22936d630c4ec1891f24e49a", "best_bid": "0.33", "best_ask": "0.34"}], "timestamp": "1769384003125", "event_type": "price_change"}}
{"_local_timestamp": "2026-01-25T23:33:24.659733+00:00", "data": {"market": "0xfc6260666d020a912a87d9000eff5116d2adfb8c30aba543427a4c1f1411f1a0", "price_changes": [{"asset_id": "20615575591261238050354259319465440337102580196335623615376639598123117400036", "price": "0.69", "size": "389.75", "side": "SELL", "hash": "7e251039dcd65b853e6f31aca2b712277a0d0b1a", "best_bid": "0.66", "best_ask": "0.67"}, {"asset_id": "57301498276970257025109591078431189727442302532145853906375186182281603517458", "price": "0.31", "size": "389.75", "side": "BUY", "hash": "d98f864461f705859651d61ab74b3ad51675b851", "best_bid": "0.33", "best_ask": "0.34"}], "timestamp": "1769384004593", "event_type": "price_change"}}
{"_local_timestamp": "2026-01-25T23:33:24.693800+00:00", "data": {"market": "0xfc6260666d020a912a87d9000eff5116d2adfb8c30aba543427a4c1f1411f1a0", "price_changes": [{"asset_id": "20615575591261238050354259319465440337102580196335623615376639598123117400036", "price": "0.69", "size": "438.75", "side": "SELL", "hash": "b8beaccd2ba9020e789aab81478c3d61fa4ca187", "best_bid": "0.66", "best_ask": "0.67"}, {"asset_id": "57301498276970257025109591078431189727442302532145853906375186182281603517458", "price": "0.31", "size": "438.75", "side": "BUY", "hash": "3e6005043bded21fa00bdd64b655911bc760364b", "best_bid": "0.33", "best_ask": "0.34"}], "timestamp": "1769384004618", "event_type": "price_change"}}
{"_local_timestamp": "2026-01-25T23:33:26.162288+00:00", "data": {"market": "0xfc6260666d020a912a87d9000eff5116d2adfb8c30aba543427a4c1f1411f1a0", "price_changes": [{"asset_id": "20615575591261238050354259319465440337102580196335623615376639598123117400036", "price": "0.69", "size": "389.75", "side": "SELL", "hash": "4a1120c2d0df488a495b6493c8d53124157e3cd6", "best_bid": "0.66", "best_ask": "0.67"}, {"asset_id": "57301498276970257025109591078431189727442302532145853906375186182281603517458", "price": "0.31", "size": "389.75", "side": "BUY", "hash": "44d9a68e4bb564d5c9fdce809504dc8463cae506", "best_bid": "0.33", "best_ask": "0.34"}], "timestamp": "1769384006093", "event_type": "price_change"}}
{"_local_timestamp": "2026-01-25T23:33:26.185997+00:00", "data": {"market": "0xfc6260666d020a912a87d9000eff5116d2adfb8c30aba543427a4c1f1411f1a0", "price_changes": [{"asset_id": "20615575591261238050354259319465440337102580196335623615376639598123117400036", "price": "0.69", "size": "438.75", "side": "SELL", "hash": "7c38f5ea15755afbc0e9803bb09cdc6e66432d97", "best_bid": "0.66", "best_ask": "0.67"}, {"asset_id": "57301498276970257025109591078431189727442302532145853906375186182281603517458", "price": "0.31", "size": "438.75", "side": "BUY", "hash": "e905170f9ba44bfddd5305abe81518d669f1f017", "best_bid": "0.33", "best_ask": "0.34"}], "timestamp": "1769384006118", "event_type": "price_change"}}
{"_local_timestamp": "2026-01-25T23:33:27.664146+00:00", "data": {"market": "0xfc6260666d020a912a87d9000eff5116d2adfb8c30aba543427a4c1f1411f1a0", "price_changes": [{"asset_id": "20615575591261238050354259319465440337102580196335623615376639598123117400036", "price": "0.69", "size": "389.75", "side": "SELL", "hash": "3e788af207ef34c54c6c65db5433f26b356f89a6", "best_bid": "0.66", "best_ask": "0.67"}, {"asset_id": "57301498276970257025109591078431189727442302532145853906375186182281603517458", "price": "0.31", "size": "389.75", "side": "BUY", "hash": "e68044f70dfab5aac6becb4892cf9b0362f3e599", "best_bid": "0.33", "best_ask": "0.34"}], "timestamp": "1769384007593", "event_type": "price_change"}}
{"_local_timestamp": "2026-01-25T23:33:27.710855+00:00", "data": {"market": "0xfc6260666d020a912a87d9000eff5116d2adfb8c30aba543427a4c1f1411f1a0", "price_changes": [{"asset_id": "20615575591261238050354259319465440337102580196335623615376639598123117400036", "price": "0.69", "size": "438.75", "side": "SELL", "hash": "fb4fbb89f89364419ae9077004dfe244a660b493", "best_bid": "0.66", "best_ask": "0.67"}, {"asset_id": "57301498276970257025109591078431189727442302532145853906375186182281603517458", "price": "0.31", "size": "438.75", "side": "BUY", "hash": "731fcd61a05a6ceacbe6b2e2fe08a30c5db8a2c2", "best_bid": "0.33", "best_ask": "0.34"}], "timestamp": "1769384007623", "event_type": "price_change"}}
{"_local_timestamp": "2026-01-25T23:33:29.168594+00:00", "data": {"market": "0xfc6260666d020a912a87d9000eff5116d2adfb8c30aba543427a4c1f1411f1a0", "price_changes": [{"asset_id": "20615575591261238050354259319465440337102580196335623615376639598123117400036", "price": "0.69", "size": "389.75", "side": "SELL", "hash": "d568da2eb6a9366435c5bfe37ab37fe9748b57f3", "best_bid": "0.66", "best_ask": "0.67"}, {"asset_id": "57301498276970257025109591078431189727442302532145853906375186182281603517458", "price": "0.31", "size": "389.75", "side": "BUY", "hash": "6a402968bad2f70a4bc448a797ff3ff7d3aa61ee", "best_bid": "0.33", "best_ask": "0.34"}], "timestamp": "1769384009094", "event_type": "price_change"}}
{"_local_timestamp": "2026-01-25T23:33:29.200359+00:00", "data": {"market": "0xfc6260666d020a912a87d9000eff5116d2adfb8c30aba543427a4c1f1411f1a0", "price_changes": [{"asset_id": "20615575591261238050354259319465440337102580196335623615376639598123117400036", "price": "0.69", "size": "438.75", "side": "SELL", "hash": "9478c74a3a69c0706b0a814e1838fdb5296017a0", "best_bid": "0.66", "best_ask": "0.67"}, {"asset_id": "57301498276970257025109591078431189727442302532145853906375186182281603517458", "price": "0.31", "size": "438.75", "side": "BUY", "hash": "da45fde1b0e3820bcb5fcee4e10d96dd76dc407b", "best_bid": "0.33", "best_ask": "0.34"}], "timestamp": "1769384009131", "event_type": "price_change"}}
{"_local_timestamp": "2026-01-25T23:33:30.662213+00:00", "data": {"market": "0xfc6260666d020a912a87d9000eff5116d2adfb8c30aba543427a4c1f1411f1a0", "price_changes": [{"asset_id": "20615575591261238050354259319465440337102580196335623615376639598123117400036", "price": "0.69", "size": "389.75", "side": "SELL", "hash": "8542e16ad9f28220bcc424f4c9eca234fe458086", "best_bid": "0.66", "best_ask": "0.67"}, {"asset_id": "57301498276970257025109591078431189727442302532145853906375186182281603517458", "price": "0.31", "size": "389.75", "side": "BUY", "hash": "a1ac4b775f2ee5ab38e7206c312dab85fa2b18ca", "best_bid": "0.33", "best_ask": "0.34"}], "timestamp": "1769384010594", "event_type": "price_change"}}
{"_local_timestamp": "2026-01-25T23:33:30.688421+00:00", "data": {"market": "0xfc6260666d020a912a87d9000eff5116d2adfb8c30aba543427a4c1f1411f1a0", "price_changes": [{"asset_id": "20615575591261238050354259319465440337102580196335623615376639598123117400036", "price": "0.69", "size": "438.75", "side": "SELL", "hash": "0819da8fa7aff30bbd760b1a2d3a314465e3d85a", "best_bid": "0.66", "best_ask": "0.67"}, {"asset_id": "57301498276970257025109591078431189727442302532145853906375186182281603517458", "price": "0.31", "size": "438.75", "side": "BUY", "hash": "90905f42ea1b396cdd51b5116c68f7a6ea05b2d8", "best_bid": "0.33", "best_ask": "0.34"}], "timestamp": "1769384010623", "event_type": "price_change"}}
{"_local_timestamp": "2026-01-25T23:33:32.161493+00:00", "data": {"market": "0xfc6260666d020a912a87d9000eff5116d2adfb8c30aba543427a4c1f1411f1a0", "price_changes": [{"asset_id": "20615575591261238050354259319465440337102580196335623615376639598123117400036", "price": "0.69", "size": "389.75", "side": "SELL", "hash": "09dabe7dcfc4428b5cb56597a4745442793e26b6", "best_bid": "0.66", "best_ask": "0.67"}, {"asset_id": "57301498276970257025109591078431189727442302532145853906375186182281603517458", "price": "0.31", "size": "389.75", "side": "BUY", "hash": "bccdd9c37fb894d5ad4cede0d4f97276d6a92a52", "best_bid": "0.33", "best_ask": "0.34"}], "timestamp": "1769384012093", "event_type": "price_change"}}
{"_local_timestamp": "2026-01-25T23:33:32.187016+00:00", "data": {"market": "0xfc6260666d020a912a87d9000eff5116d2adfb8c30aba543427a4c1f1411f1a0", "price_changes": [{"asset_id": "20615575591261238050354259319465440337102580196335623615376639598123117400036", "price": "0.69", "size": "438.75", "side": "SELL", "hash": "262e952ca4dd5610f41b995a6e16e495b42981d0", "best_bid": "0.66", "best_ask": "0.67"}, {"asset_id": "57301498276970257025109591078431189727442302532145853906375186182281603517458", "price": "0.31", "size": "438.75", "side": "BUY", "hash": "52d6ea3871ac715241cfccd69f88d49fe288ab9d", "best_bid": "0.33", "best_ask": "0.34"}], "timestamp": "1769384012117", "event_type": "price_change"}}
{"_local_timestamp": "2026-01-25T23:33:33.534592+00:00", "data": {"market": "0xb2abfc4e48334d87681240cd6a7e63c728e13973fbd68951b45bc86d6c4491e4", "price_changes": [{"asset_id": "18210569213780052033306952138558054016080325272524745338190244466404715123630", "price": "0.054", "size": "400", "side": "SELL", "hash": "14fd85b08393af25fa318d5f92bd77a682607e0a", "best_bid": "0.043", "best_ask": "0.053"}, {"asset_id": "82149110067979470707461735036792617981060265491561473691799265056474452809853", "price": "0.946", "size": "400", "side": "BUY", "hash": "1b853d415d1e868df66c0d6ecbbed855a7b9ed81", "best_bid": "0.947", "best_ask": "0.957"}], "timestamp": "1769384013417", "event_type": "price_change"}}
{"_local_timestamp": "2026-01-25T23:33:33.734530+00:00", "data": {"market": "0xfc6260666d020a912a87d9000eff5116d2adfb8c30aba543427a4c1f1411f1a0", "price_changes": [{"asset_id": "20615575591261238050354259319465440337102580196335623615376639598123117400036", "price": "0.69", "size": "389.75", "side": "SELL", "hash": "ebefee6cef6e5c744652340e2a39a38190fc13e2", "best_bid": "0.66", "best_ask": "0.67"}, {"asset_id": "57301498276970257025109591078431189727442302532145853906375186182281603517458", "price": "0.31", "size": "389.75", "side": "BUY", "hash": "8cd7bd39b17562816eb2900daa33017ac800dda2", "best_bid": "0.33", "best_ask": "0.34"}], "timestamp": "1769384013594", "event_type": "price_change"}}
{"_local_timestamp": "2026-01-25T23:33:33.735237+00:00", "data": {"market": "0xfc6260666d020a912a87d9000eff5116d2adfb8c30aba543427a4c1f1411f1a0", "price_changes": [{"asset_id": "20615575591261238050354259319465440337102580196335623615376639598123117400036", "price": "0.69", "size": "438.75", "side": "SELL", "hash": "539d1c17863d40288b5091a283def67ffaa301f1", "best_bid": "0.66", "best_ask": "0.67"}, {"asset_id": "57301498276970257025109591078431189727442302532145853906375186182281603517458", "price": "0.31", "size": "438.75", "side": "BUY", "hash": "abd756255c714ecd884850781fad2a5c414c89f1", "best_bid": "0.33", "best_ask": "0.34"}], "timestamp": "1769384013621", "event_type": "price_change"}}
{"_local_timestamp": "2026-01-25T23:33:35.009677+00:00", "data": {"market": "0xb2abfc4e48334d87681240cd6a7e63c728e13973fbd68951b45bc86d6c4491e4", "price_changes": [{"asset_id": "18210569213780052033306952138558054016080325272524745338190244466404715123630", "price": "0.053", "size": "122.9", "side": "SELL", "hash": "9add666323fa957627fe52e0e08b5d4b40495201", "best_bid": "0.043", "best_ask": "0.053"}, {"asset_id": "82149110067979470707461735036792617981060265491561473691799265056474452809853", "price": "0.947", "size": "122.9", "side": "BUY", "hash": "c0c7e8b212d777a35f658da1922e2aae263e4d1b", "best_bid": "0.947", "best_ask": "0.957"}], "timestamp": "1769384014938", "event_type": "price_change"}}
{"_local_timestamp": "2026-01-25T23:33:35.170184+00:00", "data": {"market": "0xfc6260666d020a912a87d9000eff5116d2adfb8c30aba543427a4c1f1411f1a0", "price_changes": [{"asset_id": "20615575591261238050354259319465440337102580196335623615376639598123117400036", "price": "0.69", "size": "389.75", "side": "SELL", "hash": "cb3c4731534a160ab6b574b6f2d43d791804ced3", "best_bid": "0.66", "best_ask": "0.67"}, {"asset_id": "57301498276970257025109591078431189727442302532145853906375186182281603517458", "price": "0.31", "size": "389.75", "side": "BUY", "hash": "ceaaf2a7d09cb13af5811f362ba7ac15b2fac398", "best_bid": "0.33", "best_ask": "0.34"}], "timestamp": "1769384015094", "event_type": "price_change"}}
{"_local_timestamp": "2026-01-25T23:33:35.185100+00:00", "data": {"market": "0xfc6260666d020a912a87d9000eff5116d2adfb8c30aba543427a4c1f1411f1a0", "price_changes": [{"asset_id": "20615575591261238050354259319465440337102580196335623615376639598123117400036", "price": "0.69", "size": "438.75", "side": "SELL", "hash": "cf9ab1faa4121a07553e4e8814bf219a8d448893", "best_bid": "0.66", "best_ask": "0.67"}, {"asset_id": "57301498276970257025109591078431189727442302532145853906375186182281603517458", "price": "0.31", "size": "438.75", "side": "BUY", "hash": "5089a9cc700121159b529b028b1b293bf0826ba0", "best_bid": "0.33", "best_ask": "0.34"}], "timestamp": "1769384015119", "event_type": "price_change"}}
{"_local_timestamp": "2026-01-25T23:33:36.687388+00:00", "data": {"market": "0xfc6260666d020a912a87d9000eff5116d2adfb8c30aba543427a4c1f1411f1a0", "price_changes": [{"asset_id": "20615575591261238050354259319465440337102580196335623615376639598123117400036", "price": "0.69", "size": "389.75", "side": "SELL", "hash": "b36a0fbb5af8f70fcd8ee71c1c87647597241348", "best_bid": "0.66", "best_ask": "0.67"}, {"asset_id": "57301498276970257025109591078431189727442302532145853906375186182281603517458", "price": "0.31", "size": "389.75", "side": "BUY", "hash": "a74afc2e39372c48b82becdd3fe0a66f7335c2ac", "best_bid": "0.33", "best_ask": "0.34"}], "timestamp": "1769384016594", "event_type": "price_change"}}
{"_local_timestamp": "2026-01-25T23:33:36.697529+00:00", "data": {"market": "0xfc6260666d020a912a87d9000eff5116d2adfb8c30aba543427a4c1f1411f1a0", "price_changes": [{"asset_id": "20615575591261238050354259319465440337102580196335623615376639598123117400036", "price": "0.69", "size": "438.75", "side": "SELL", "hash": "f7deff2c3c03e1beebaa0ba243040492c036234c", "best_bid": "0.66", "best_ask": "0.67"}, {"asset_id": "57301498276970257025109591078431189727442302532145853906375186182281603517458", "price": "0.31", "size": "438.75", "side": "BUY", "hash": "8d7c3e993db240720008aeb957cc888bfb9fed0d", "best_bid": "0.33", "best_ask": "0.34"}], "timestamp": "1769384016622", "event_type": "price_change"}}
{"_local_timestamp": "2026-01-25T23:33:38.162486+00:00", "data": {"market": "0xfc6260666d020a912a87d9000eff5116d2adfb8c30aba543427a4c1f1411f1a0", "price_changes": [{"asset_id": "20615575591261238050354259319465440337102580196335623615376639598123117400036", "price": "0.69", "size": "389.75", "side": "SELL", "hash": "3cd3d41677c332aa29ac1400fb47bc130231e5a1", "best_bid": "0.66", "best_ask": "0.67"}, {"asset_id": "57301498276970257025109591078431189727442302532145853906375186182281603517458", "price": "0.31", "size": "389.75", "side": "BUY", "hash": "5e7a58b5635e55da42387c0bf2d0666444f68708", "best_bid": "0.33", "best_ask": "0.34"}], "timestamp": "1769384018095", "event_type": "price_change"}}
{"_local_timestamp": "2026-01-25T23:33:38.197590+00:00", "data": {"market": "0xfc6260666d020a912a87d9000eff5116d2adfb8c30aba543427a4c1f1411f1a0", "price_changes": [{"asset_id": "20615575591261238050354259319465440337102580196335623615376639598123117400036", "price": "0.69", "size": "438.75", "side": "SELL", "hash": "e7825477b64cac68bfdea0da18500a2793f213c5", "best_bid": "0.66", "best_ask": "0.67"}, {"asset_id": "57301498276970257025109591078431189727442302532145853906375186182281603517458", "price": "0.31", "size": "438.75", "side": "BUY", "hash": "32fec77eda0a11ddf1c73ebf1ec9b010ae895681", "best_bid": "0.33", "best_ask": "0.34"}], "timestamp": "1769384018122", "event_type": "price_change"}}
{"_local_timestamp": "2026-01-25T23:33:39.669949+00:00", "data": {"market": "0xfc6260666d020a912a87d9000eff5116d2adfb8c30aba543427a4c1f1411f1a0", "price_changes": [{"asset_id": "20615575591261238050354259319465440337102580196335623615376639598123117400036", "price": "0.69", "size": "389.75", "side": "SELL", "hash": "c3d4aceb5d006266e5a0af31ae677327e77d8d77", "best_bid": "0.66", "best_ask": "0.67"}, {"asset_id": "57301498276970257025109591078431189727442302532145853906375186182281603517458", "price": "0.31", "size": "389.75", "side": "BUY", "hash": "203da120e0fb495965ba4c223b65666216412b9b", "best_bid": "0.33", "best_ask": "0.34"}], "timestamp": "1769384019595", "event_type": "price_change"}}
{"_local_timestamp": "2026-01-25T23:33:39.693805+00:00", "data": {"market": "0xfc6260666d020a912a87d9000eff5116d2adfb8c30aba543427a4c1f1411f1a0", "price_changes": [{"asset_id": "20615575591261238050354259319465440337102580196335623615376639598123117400036", "price": "0.69", "size": "438.75", "side": "SELL", "hash": "e4253732fe278373058e7e3863e19c188c035b0d", "best_bid": "0.66", "best_ask": "0.67"}, {"asset_id": "57301498276970257025109591078431189727442302532145853906375186182281603517458", "price": "0.31", "size": "438.75", "side": "BUY", "hash": "8db6a69e04ffe948ac316e3dceead77fa8caf156", "best_bid": "0.33", "best_ask": "0.34"}], "timestamp": "1769384019623", "event_type": "price_change"}}
{"_local_timestamp": "2026-01-25T23:33:41.167517+00:00", "data": {"market": "0xfc6260666d020a912a87d9000eff5116d2adfb8c30aba543427a4c1f1411f1a0", "price_changes": [{"asset_id": "20615575591261238050354259319465440337102580196335623615376639598123117400036", "price": "0.69", "size": "389.75", "side": "SELL", "hash": "b89b42ed3f41f57978edcf867ccd5c4b3e37bb98", "best_bid": "0.66", "best_ask": "0.67"}, {"asset_id": "57301498276970257025109591078431189727442302532145853906375186182281603517458", "price": "0.31", "size": "389.75", "side": "BUY", "hash": "7647f2630374e0213cb907a33cca586daebf04d7", "best_bid": "0.33", "best_ask": "0.34"}], "timestamp": "1769384021093", "event_type": "price_change"}}
{"_local_timestamp": "2026-01-25T23:33:41.199748+00:00", "data": {"market": "0xfc6260666d020a912a87d9000eff5116d2adfb8c30aba543427a4c1f1411f1a0", "price_changes": [{"asset_id": "20615575591261238050354259319465440337102580196335623615376639598123117400036", "price": "0.69", "size": "438.75", "side": "SELL", "hash": "d8118c9dfa1d5e816af38604ccf16af9ff71344d", "best_bid": "0.66", "best_ask": "0.67"}, {"asset_id": "57301498276970257025109591078431189727442302532145853906375186182281603517458", "price": "0.31", "size": "438.75", "side": "BUY", "hash": "6786fcf5722e29e244e226076e27e9ae1516c55a", "best_bid": "0.33", "best_ask": "0.34"}], "timestamp": "1769384021131", "event_type": "price_change"}}
{"_local_timestamp": "2026-01-25T23:33:42.658201+00:00", "data": {"market": "0xfc6260666d020a912a87d9000eff5116d2adfb8c30aba543427a4c1f1411f1a0", "price_changes": [{"asset_id": "20615575591261238050354259319465440337102580196335623615376639598123117400036", "price": "0.69", "size": "389.75", "side": "SELL", "hash": "1ae955a93b638b73f0c0f29bb11c70e21683a43b", "best_bid": "0.66", "best_ask": "0.67"}, {"asset_id": "57301498276970257025109591078431189727442302532145853906375186182281603517458", "price": "0.31", "size": "389.75", "side": "BUY", "hash": "7779c111e91d0d6b5a8cecec38d9e73e5e425b62", "best_bid": "0.33", "best_ask": "0.34"}], "timestamp": "1769384022594", "event_type": "price_change"}}
{"_local_timestamp": "2026-01-25T23:33:42.686499+00:00", "data": {"market": "0xfc6260666d020a912a87d9000eff5116d2adfb8c30aba543427a4c1f1411f1a0", "price_changes": [{"asset_id": "20615575591261238050354259319465440337102580196335623615376639598123117400036", "price": "0.69", "size": "438.75", "side": "SELL", "hash": "821d08641b02fa7d4e18cda5a9983bd005e56375", "best_bid": "0.66", "best_ask": "0.67"}, {"asset_id": "57301498276970257025109591078431189727442302532145853906375186182281603517458", "price": "0.31", "size": "438.75", "side": "BUY", "hash": "61b069d0baf744ffb5d914d42b86114e65747b7b", "best_bid": "0.33", "best_ask": "0.34"}], "timestamp": "1769384022620", "event_type": "price_change"}}
{"_local_timestamp": "2026-01-25T23:33:44.159820+00:00", "data": {"market": "0xfc6260666d020a912a87d9000eff5116d2adfb8c30aba543427a4c1f1411f1a0", "price_changes": [{"asset_id": "20615575591261238050354259319465440337102580196335623615376639598123117400036", "price": "0.69", "size": "389.75", "side": "SELL", "hash": "f2e9cd16d7c5e656966a9a4a29798ac3f4924d78", "best_bid": "0.66", "best_ask": "0.67"}, {"asset_id": "57301498276970257025109591078431189727442302532145853906375186182281603517458", "price": "0.31", "size": "389.75", "side": "BUY", "hash": "e5e4ba969a99a4f5175c3ca62ec420e8166c889a", "best_bid": "0.33", "best_ask": "0.34"}], "timestamp": "1769384024093", "event_type": "price_change"}}
{"_local_timestamp": "2026-01-25T23:33:44.191149+00:00", "data": {"market": "0xfc6260666d020a912a87d9000eff5116d2adfb8c30aba543427a4c1f1411f1a0", "price_changes": [{"asset_id": "20615575591261238050354259319465440337102580196335623615376639598123117400036", "price": "0.69", "size": "438.75", "side": "SELL", "hash": "2e32d7f42c9ccf34938effe66fbda1a28a193a48", "best_bid": "0.66", "best_ask": "0.67"}, {"asset_id": "57301498276970257025109591078431189727442302532145853906375186182281603517458", "price": "0.31", "size": "438.75", "side": "BUY", "hash": "a63252e0092daf534d0362e2d4f324e2f8150122", "best_bid": "0.33", "best_ask": "0.34"}], "timestamp": "1769384024124", "event_type": "price_change"}}
{"_local_timestamp": "2026-01-25T23:33:45.661976+00:00", "data": {"market": "0xfc6260666d020a912a87d9000eff5116d2adfb8c30aba543427a4c1f1411f1a0", "price_changes": [{"asset_id": "20615575591261238050354259319465440337102580196335623615376639598123117400036", "price": "0.69", "size": "389.75", "side": "SELL", "hash": "d4c0e8db745e83538929380d932a12c06db30cc8", "best_bid": "0.66", "best_ask": "0.67"}, {"asset_id": "57301498276970257025109591078431189727442302532145853906375186182281603517458", "price": "0.31", "size": "389.75", "side": "BUY", "hash": "d86471afb92e7881ff919d376dbfff75015b7127", "best_bid": "0.33", "best_ask": "0.34"}], "timestamp": "1769384025593", "event_type": "price_change"}}
{"_local_timestamp": "2026-01-25T23:33:45.688802+00:00", "data": {"market": "0xfc6260666d020a912a87d9000eff5116d2adfb8c30aba543427a4c1f1411f1a0", "price_changes": [{"asset_id": "20615575591261238050354259319465440337102580196335623615376639598123117400036", "price": "0.69", "size": "438.75", "side": "SELL", "hash": "6e8727b1fc9d246d941f8ded732aa2c0d77f74ba", "best_bid": "0.66", "best_ask": "0.67"}, {"asset_id": "57301498276970257025109591078431189727442302532145853906375186182281603517458", "price": "0.31", "size": "438.75", "side": "BUY", "hash": "5feb8abc5dc589e02dbc6c61d1821a08805c01c8", "best_bid": "0.33", "best_ask": "0.34"}], "timestamp": "1769384025619", "event_type": "price_change"}}
{"_local_timestamp": "2026-01-25T23:33:47.166140+00:00", "data": {"market": "0xfc6260666d020a912a87d9000eff5116d2adfb8c30aba543427a4c1f1411f1a0", "price_changes": [{"asset_id": "20615575591261238050354259319465440337102580196335623615376639598123117400036", "price": "0.69", "size": "389.75", "side": "SELL", "hash": "3ebc66374387327154b89e2b4d3f5dbd6e72a95e", "best_bid": "0.66", "best_ask": "0.67"}, {"asset_id": "57301498276970257025109591078431189727442302532145853906375186182281603517458", "price": "0.31", "size": "389.75", "side": "BUY", "hash": "4b15455baeb6699edd83430e1db4b470610c5fa7", "best_bid": "0.33", "best_ask": "0.34"}], "timestamp": "1769384027094", "event_type": "price_change"}}
{"_local_timestamp": "2026-01-25T23:33:47.183689+00:00", "data": {"market": "0xfc6260666d020a912a87d9000eff5116d2adfb8c30aba543427a4c1f1411f1a0", "price_changes": [{"asset_id": "20615575591261238050354259319465440337102580196335623615376639598123117400036", "price": "0.69", "size": "438.75", "side": "SELL", "hash": "72e7e3d836e01c9a693d6655b7f1454f298e709e", "best_bid": "0.66", "best_ask": "0.67"}, {"asset_id": "57301498276970257025109591078431189727442302532145853906375186182281603517458", "price": "0.31", "size": "438.75", "side": "BUY", "hash": "fa95ae505d3466d320460e148367334c2d7b783f", "best_bid": "0.33", "best_ask": "0.34"}], "timestamp": "1769384027118", "event_type": "price_change"}}
{"_local_timestamp": "2026-01-25T23:33:48.660288+00:00", "data": {"market": "0xfc6260666d020a912a87d9000eff5116d2adfb8c30aba543427a4c1f1411f1a0", "price_changes": [{"asset_id": "20615575591261238050354259319465440337102580196335623615376639598123117400036", "price": "0.69", "size": "389.75", "side": "SELL", "hash": "0a65e0d0d1d4850299c42f43bdee68c78090713d", "best_bid": "0.66", "best_ask": "0.67"}, {"asset_id": "57301498276970257025109591078431189727442302532145853906375186182281603517458", "price": "0.31", "size": "389.75", "side": "BUY", "hash": "ff7722f55e8173da139f5a9392cbb5b480cdbf64", "best_bid": "0.33", "best_ask": "0.34"}], "timestamp": "1769384028594", "event_type": "price_change"}}
{"_local_timestamp": "2026-01-25T23:33:48.681312+00:00", "data": {"market": "0xfc6260666d020a912a87d9000eff5116d2adfb8c30aba543427a4c1f1411f1a0", "price_changes": [{"asset_id": "20615575591261238050354259319465440337102580196335623615376639598123117400036", "price": "0.69", "size": "438.75", "side": "SELL", "hash": "05d3ca5cdce2b50c34228541ac4ae3830abf1008", "best_bid": "0.66", "best_ask": "0.67"}, {"asset_id": "57301498276970257025109591078431189727442302532145853906375186182281603517458", "price": "0.31", "size": "438.75", "side": "BUY", "hash": "fcf2a56631d15a99e23e36fef560254626b6a1c2", "best_bid": "0.33", "best_ask": "0.34"}], "timestamp": "1769384028619", "event_type": "price_change"}}
{"_local_timestamp": "2026-01-25T23:33:50.162218+00:00", "data": {"market": "0xfc6260666d020a912a87d9000eff5116d2adfb8c30aba543427a4c1f1411f1a0", "price_changes": [{"asset_id": "20615575591261238050354259319465440337102580196335623615376639598123117400036", "price": "0.69", "size": "389.75", "side": "SELL", "hash": "bcaaf14509e96d613721f03a7b73f0e0601df1bd", "best_bid": "0.66", "best_ask": "0.67"}, {"asset_id": "57301498276970257025109591078431189727442302532145853906375186182281603517458", "price": "0.31", "size": "389.75", "side": "BUY", "hash": "93ade9d28334cef4e17089d25b61308418530f0c", "best_bid": "0.33", "best_ask": "0.34"}], "timestamp": "1769384030096", "event_type": "price_change"}}
{"_local_timestamp": "2026-01-25T23:33:50.188041+00:00", "data": {"market": "0xfc6260666d020a912a87d9000eff5116d2adfb8c30aba543427a4c1f1411f1a0", "price_changes": [{"asset_id": "20615575591261238050354259319465440337102580196335623615376639598123117400036", "price": "0.69", "size": "438.75", "side": "SELL", "hash": "0056109b11d47a5a99cfbafe225237b607ce85dd", "best_bid": "0.66", "best_ask": "0.67"}, {"asset_id": "57301498276970257025109591078431189727442302532145853906375186182281603517458", "price": "0.31", "size": "438.75", "side": "BUY", "hash": "ce8c96b70b3c45dbacff8afa56b2a9052016d241", "best_bid": "0.33", "best_ask": "0.34"}], "timestamp": "1769384030121", "event_type": "price_change"}}
{"_local_timestamp": "2026-01-25T23:33:51.675843+00:00", "data": {"market": "0xfc6260666d020a912a87d9000eff5116d2adfb8c30aba543427a4c1f1411f1a0", "price_changes": [{"asset_id": "20615575591261238050354259319465440337102580196335623615376639598123117400036", "price": "0.69", "size": "389.75", "side": "SELL", "hash": "d59559039bc693c3cecda0ecc884022909341465", "best_bid": "0.66", "best_ask": "0.67"}, {"asset_id": "57301498276970257025109591078431189727442302532145853906375186182281603517458", "price": "0.31", "size": "389.75", "side": "BUY", "hash": "8079fdf499bd2c3ceed334772643c7b7fb58ea82", "best_bid": "0.33", "best_ask": "0.34"}], "timestamp": "1769384031594", "event_type": "price_change"}}
{"_local_timestamp": "2026-01-25T23:33:51.690430+00:00", "data": {"market": "0xfc6260666d020a912a87d9000eff5116d2adfb8c30aba543427a4c1f1411f1a0", "price_changes": [{"asset_id": "20615575591261238050354259319465440337102580196335623615376639598123117400036", "price": "0.69", "size": "438.75", "side": "SELL", "hash": "4a992050ef1a81a61cbaa3db9d3406bc72e89a69", "best_bid": "0.66", "best_ask": "0.67"}, {"asset_id": "57301498276970257025109591078431189727442302532145853906375186182281603517458", "price": "0.31", "size": "438.75", "side": "BUY", "hash": "c8f2bef6bad1b6bfebf3d62b44e62363378c1a36", "best_bid": "0.33", "best_ask": "0.34"}], "timestamp": "1769384031626", "event_type": "price_change"}}
{"_local_timestamp": "2026-01-25T23:33:53.163030+00:00", "data": {"market": "0xfc6260666d020a912a87d9000eff5116d2adfb8c30aba543427a4c1f1411f1a0", "price_changes": [{"asset_id": "20615575591261238050354259319465440337102580196335623615376639598123117400036", "price": "0.69", "size": "389.75", "side": "SELL", "hash": "fb68c33276270170a78d96913aad14c1dfb68e53", "best_bid": "0.66", "best_ask": "0.67"}, {"asset_id": "57301498276970257025109591078431189727442302532145853906375186182281603517458", "price": "0.31", "size": "389.75", "side": "BUY", "hash": "78d0d79ce4a3315c9be4872d2ced175bd9138a16", "best_bid": "0.33", "best_ask": "0.34"}], "timestamp": "1769384033094", "event_type": "price_change"}}
{"_local_timestamp": "2026-01-25T23:33:53.181761+00:00", "data": {"market": "0xfc6260666d020a912a87d9000eff5116d2adfb8c30aba543427a4c1f1411f1a0", "price_changes": [{"asset_id": "20615575591261238050354259319465440337102580196335623615376639598123117400036", "price": "0.69", "size": "438.75", "side": "SELL", "hash": "8d38c8240e4376dc20a0eb971b574b05882f4520", "best_bid": "0.66", "best_ask": "0.67"}, {"asset_id": "57301498276970257025109591078431189727442302532145853906375186182281603517458", "price": "0.31", "size": "438.75", "side": "BUY", "hash": "236e4714d14621978418e13a5793c2525f5a1d5d", "best_bid": "0.33", "best_ask": "0.34"}], "timestamp": "1769384033119", "event_type": "price_change"}}
{"_local_timestamp": "2026-01-25T23:33:54.663959+00:00", "data": {"market": "0xfc6260666d020a912a87d9000eff5116d2adfb8c30aba543427a4c1f1411f1a0", "price_changes": [{"asset_id": "20615575591261238050354259319465440337102580196335623615376639598123117400036", "price": "0.69", "size": "389.75", "side": "SELL", "hash": "f11d8db8ab02ebbfea5a6bc3a0d075eeee78f962", "best_bid": "0.66", "best_ask": "0.67"}, {"asset_id": "57301498276970257025109591078431189727442302532145853906375186182281603517458", "price": "0.31", "size": "389.75", "side": "BUY", "hash": "8152b07b73218916a658a3583bea8bd6897ff9a5", "best_bid": "0.33", "best_ask": "0.34"}], "timestamp": "1769384034595", "event_type": "price_change"}}
{"_local_timestamp": "2026-01-25T23:33:54.687948+00:00", "data": {"market": "0xfc6260666d020a912a87d9000eff5116d2adfb8c30aba543427a4c1f1411f1a0", "price_changes": [{"asset_id": "20615575591261238050354259319465440337102580196335623615376639598123117400036", "price": "0.69", "size": "438.75", "side": "SELL", "hash": "12b137b214e67e16d78397ddf0318dc73f9880dd", "best_bid": "0.66", "best_ask": "0.67"}, {"asset_id": "57301498276970257025109591078431189727442302532145853906375186182281603517458", "price": "0.31", "size": "438.75", "side": "BUY", "hash": "1d2a80a8a4309629fff40f27336f17dbd1a47a7e", "best_bid": "0.33", "best_ask": "0.34"}], "timestamp": "1769384034622", "event_type": "price_change"}}
{"_local_timestamp": "2026-01-25T23:33:56.161724+00:00", "data": {"market": "0xfc6260666d020a912a87d9000eff5116d2adfb8c30aba543427a4c1f1411f1a0", "price_changes": [{"asset_id": "20615575591261238050354259319465440337102580196335623615376639598123117400036", "price": "0.69", "size": "389.75", "side": "SELL", "hash": "d8d7cd25b2782803b7cd1308f164bcc542e726be", "best_bid": "0.66", "best_ask": "0.67"}, {"asset_id": "57301498276970257025109591078431189727442302532145853906375186182281603517458", "price": "0.31", "size": "389.75", "side": "BUY", "hash": "c88c689a790fe9892d27f94faf9a197b1987544b", "best_bid": "0.33", "best_ask": "0.34"}], "timestamp": "1769384036095", "event_type": "price_change"}}
{"_local_timestamp": "2026-01-25T23:33:56.188459+00:00", "data": {"market": "0xfc6260666d020a912a87d9000eff5116d2adfb8c30aba543427a4c1f1411f1a0", "price_changes": [{"asset_id": "20615575591261238050354259319465440337102580196335623615376639598123117400036", "price": "0.69", "size": "438.75", "side": "SELL", "hash": "d18d1c356f007e113b75ff6b4e4896c104845356", "best_bid": "0.66", "best_ask": "0.67"}, {"asset_id": "57301498276970257025109591078431189727442302532145853906375186182281603517458", "price": "0.31", "size": "438.75", "side": "BUY", "hash": "cce50c687922b2811bb0b947b05e6dda0ad70ddf", "best_bid": "0.33", "best_ask": "0.34"}], "timestamp": "1769384036121", "event_type": "price_change"}}
{"_local_timestamp": "2026-01-25T23:33:57.659557+00:00", "data": {"market": "0xfc6260666d020a912a87d9000eff5116d2adfb8c30aba543427a4c1f1411f1a0", "price_changes": [{"asset_id": "20615575591261238050354259319465440337102580196335623615376639598123117400036", "price": "0.69", "size": "389.75", "side": "SELL", "hash": "041162804f8b83061ebc5e59b32b7d48b2cd1066", "best_bid": "0.66", "best_ask": "0.67"}, {"asset_id": "57301498276970257025109591078431189727442302532145853906375186182281603517458", "price": "0.31", "size": "389.75", "side": "BUY", "hash": "d34c8eeca9bf54ef220684266992561407110214", "best_bid": "0.33", "best_ask": "0.34"}], "timestamp": "1769384037594", "event_type": "price_change"}}
{"_local_timestamp": "2026-01-25T23:33:57.687900+00:00", "data": {"market": "0xfc6260666d020a912a87d9000eff5116d2adfb8c30aba543427a4c1f1411f1a0", "price_changes": [{"asset_id": "20615575591261238050354259319465440337102580196335623615376639598123117400036", "price": "0.69", "size": "438.75", "side": "SELL", "hash": "f2e6a0fadbda426324f64d6da2564a203d3031fe", "best_bid": "0.66", "best_ask": "0.67"}, {"asset_id": "57301498276970257025109591078431189727442302532145853906375186182281603517458", "price": "0.31", "size": "438.75", "side": "BUY", "hash": "9439949f298aa663242f3b4087b37b2744edf7d0", "best_bid": "0.33", "best_ask": "0.34"}], "timestamp": "1769384037617", "event_type": "price_change"}}
{"_local_timestamp": "2026-01-25T23:33:59.158922+00:00", "data": {"market": "0xfc6260666d020a912a87d9000eff5116d2adfb8c30aba543427a4c1f1411f1a0", "price_changes": [{"asset_id": "20615575591261238050354259319465440337102580196335623615376639598123117400036", "price": "0.69", "size": "389.75", "side": "SELL", "hash": "7d86f576a23c4fe5ede2ef645af92f20c88e1cef", "best_bid": "0.66", "best_ask": "0.67"}, {"asset_id": "57301498276970257025109591078431189727442302532145853906375186182281603517458", "price": "0.31", "size": "389.75", "side": "BUY", "hash": "b631a211c6352b11d29be84a398b8e3309f11942", "best_bid": "0.33", "best_ask": "0.34"}], "timestamp": "1769384039094", "event_type": "price_change"}}
{"_local_timestamp": "2026-01-25T23:33:59.190730+00:00", "data": {"market": "0xfc6260666d020a912a87d9000eff5116d2adfb8c30aba543427a4c1f1411f1a0", "price_changes": [{"asset_id": "20615575591261238050354259319465440337102580196335623615376639598123117400036", "price": "0.69", "size": "438.75", "side": "SELL", "hash": "7230cf1902f7a547b0cc199a8ee3f76e36f79c9b", "best_bid": "0.66", "best_ask": "0.67"}, {"asset_id": "57301498276970257025109591078431189727442302532145853906375186182281603517458", "price": "0.31", "size": "438.75", "side": "BUY", "hash": "e27e0804a7556425931fa458ba3a0946c487102d", "best_bid": "0.33", "best_ask": "0.34"}], "timestamp": "1769384039120", "event_type": "price_change"}}
{"_local_timestamp": "2026-01-25T23:34:00.665066+00:00", "data": {"market": "0xfc6260666d020a912a87d9000eff5116d2adfb8c30aba543427a4c1f1411f1a0", "price_changes": [{"asset_id": "20615575591261238050354259319465440337102580196335623615376639598123117400036", "price": "0.69", "size": "389.75", "side": "SELL", "hash": "cb96c0e3caab11841766ffe4aad5a2b6c97f42b2", "best_bid": "0.66", "best_ask": "0.67"}, {"asset_id": "57301498276970257025109591078431189727442302532145853906375186182281603517458", "price": "0.31", "size": "389.75", "side": "BUY", "hash": "a0464990a361dde13199f8490a15820538618a90", "best_bid": "0.33", "best_ask": "0.34"}], "timestamp": "1769384040596", "event_type": "price_change"}}
{"_local_timestamp": "2026-01-25T23:34:00.692361+00:00", "data": {"market": "0xfc6260666d020a912a87d9000eff5116d2adfb8c30aba543427a4c1f1411f1a0", "price_changes": [{"asset_id": "20615575591261238050354259319465440337102580196335623615376639598123117400036", "price": "0.69", "size": "438.75", "side": "SELL", "hash": "dad8435df212147d150c7c90b119f9948193ca9b", "best_bid": "0.66", "best_ask": "0.67"}, {"asset_id": "57301498276970257025109591078431189727442302532145853906375186182281603517458", "price": "0.31", "size": "438.75", "side": "BUY", "hash": "f89cf3867e2b0c1bcfd3d3ba017212ce32219e3e", "best_bid": "0.33", "best_ask": "0.34"}], "timestamp": "1769384040623", "event_type": "price_change"}}
{"_local_timestamp": "2026-01-25T23:34:02.174010+00:00", "data": {"market": "0xfc6260666d020a912a87d9000eff5116d2adfb8c30aba543427a4c1f1411f1a0", "price_changes": [{"asset_id": "20615575591261238050354259319465440337102580196335623615376639598123117400036", "price": "0.69", "size": "389.75", "side": "SELL", "hash": "8ad9141ee6625583d4e0b42190b692e16111797a", "best_bid": "0.66", "best_ask": "0.67"}, {"asset_id": "57301498276970257025109591078431189727442302532145853906375186182281603517458", "price": "0.31", "size": "389.75", "side": "BUY", "hash": "c24df31003a22988a4ee6cf5d58a8924dd2bd675", "best_bid": "0.33", "best_ask": "0.34"}], "timestamp": "1769384042093", "event_type": "price_change"}}
{"_local_timestamp": "2026-01-25T23:34:02.184055+00:00", "data": {"market": "0xfc6260666d020a912a87d9000eff5116d2adfb8c30aba543427a4c1f1411f1a0", "price_changes": [{"asset_id": "20615575591261238050354259319465440337102580196335623615376639598123117400036", "price": "0.69", "size": "438.75", "side": "SELL", "hash": "d0ef2897d91ee80a83110b7a42821164d371d44f", "best_bid": "0.66", "best_ask": "0.67"}, {"asset_id": "57301498276970257025109591078431189727442302532145853906375186182281603517458", "price": "0.31", "size": "438.75", "side": "BUY", "hash": "660465a3d26383dbc4ecbcbd1d9800b6eaf27ef9", "best_bid": "0.33", "best_ask": "0.34"}], "timestamp": "1769384042119", "event_type": "price_change"}}
{"_local_timestamp": "2026-01-25T23:34:03.658134+00:00", "data": {"market": "0xfc6260666d020a912a87d9000eff5116d2adfb8c30aba543427a4c1f1411f1a0", "price_changes": [{"asset_id": "20615575591261238050354259319465440337102580196335623615376639598123117400036", "price": "0.69", "size": "389.75", "side": "SELL", "hash": "61be5515ebf19c16416bf75eb93ece1fd029bf1a", "best_bid": "0.66", "best_ask": "0.67"}, {"asset_id": "57301498276970257025109591078431189727442302532145853906375186182281603517458", "price": "0.31", "size": "389.75", "side": "BUY", "hash": "b1cebd519524a23daae4cf044c1ac825660c32db", "best_bid": "0.33", "best_ask": "0.34"}], "timestamp": "1769384043595", "event_type": "price_change"}}
{"_local_timestamp": "2026-01-25T23:34:03.687651+00:00", "data": {"market": "0xfc6260666d020a912a87d9000eff5116d2adfb8c30aba543427a4c1f1411f1a0", "price_changes": [{"asset_id": "20615575591261238050354259319465440337102580196335623615376639598123117400036", "price": "0.69", "size": "438.75", "side": "SELL", "hash": "d36511ee7f1b463515a1f56a78eb42a5d00b2bb3", "best_bid": "0.66", "best_ask": "0.67"}, {"asset_id": "57301498276970257025109591078431189727442302532145853906375186182281603517458", "price": "0.31", "size": "438.75", "side": "BUY", "hash": "df57306d65443fff99f1b1f33dc76d3ffeae810e", "best_bid": "0.33", "best_ask": "0.34"}], "timestamp": "1769384043620", "event_type": "price_change"}}
{"_local_timestamp": "2026-01-25T23:34:05.226076+00:00", "data": {"market": "0xfc6260666d020a912a87d9000eff5116d2adfb8c30aba543427a4c1f1411f1a0", "price_changes": [{"asset_id": "20615575591261238050354259319465440337102580196335623615376639598123117400036", "price": "0.69", "size": "389.75", "side": "SELL", "hash": "d831764891def37a463f18c9662f71ac75237288", "best_bid": "0.66", "best_ask": "0.67"}, {"asset_id": "57301498276970257025109591078431189727442302532145853906375186182281603517458", "price": "0.31", "size": "389.75", "side": "BUY", "hash": "fdfe2425468f4829b08f5bc735bbdba3f7978202", "best_bid": "0.33", "best_ask": "0.34"}], "timestamp": "1769384045093", "event_type": "price_change"}}
{"_local_timestamp": "2026-01-25T23:34:05.246449+00:00", "data": {"market": "0xfc6260666d020a912a87d9000eff5116d2adfb8c30aba543427a4c1f1411f1a0", "price_changes": [{"asset_id": "20615575591261238050354259319465440337102580196335623615376639598123117400036", "price": "0.69", "size": "438.75", "side": "SELL", "hash": "68c6517b21fde3a4c2720ba93dd18d1a91827303", "best_bid": "0.66", "best_ask": "0.67"}, {"asset_id": "57301498276970257025109591078431189727442302532145853906375186182281603517458", "price": "0.31", "size": "438.75", "side": "BUY", "hash": "dab969353686c97c09899708953d1916f1ea54ff", "best_bid": "0.33", "best_ask": "0.34"}], "timestamp": "1769384045125", "event_type": "price_change"}}
{"_local_timestamp": "2026-01-25T23:34:06.663737+00:00", "data": {"market": "0xfc6260666d020a912a87d9000eff5116d2adfb8c30aba543427a4c1f1411f1a0", "price_changes": [{"asset_id": "20615575591261238050354259319465440337102580196335623615376639598123117400036", "price": "0.69", "size": "389.75", "side": "SELL", "hash": "11c26f1e3b47d522e8ea4dbc9a0b14924b12d3ca", "best_bid": "0.66", "best_ask": "0.67"}, {"asset_id": "57301498276970257025109591078431189727442302532145853906375186182281603517458", "price": "0.31", "size": "389.75", "side": "BUY", "hash": "0d2d4aee7c0b91e3cd83ad3254b396587a0a58eb", "best_bid": "0.33", "best_ask": "0.34"}], "timestamp": "1769384046595", "event_type": "price_change"}}
{"_local_timestamp": "2026-01-25T23:34:06.695665+00:00", "data": {"market": "0xfc6260666d020a912a87d9000eff5116d2adfb8c30aba543427a4c1f1411f1a0", "price_changes": [{"asset_id": "20615575591261238050354259319465440337102580196335623615376639598123117400036", "price": "0.69", "size": "438.75", "side": "SELL", "hash": "d5808dae0abe14389feac9fe8becf926c23f4833", "best_bid": "0.66", "best_ask": "0.67"}, {"asset_id": "57301498276970257025109591078431189727442302532145853906375186182281603517458", "price": "0.31", "size": "438.75", "side": "BUY", "hash": "4c2ee0416645e31a89e818c8b7e9a39ff06d3995", "best_bid": "0.33", "best_ask": "0.34"}], "timestamp": "1769384046626", "event_type": "price_change"}}
{"_local_timestamp": "2026-01-25T23:34:08.161404+00:00", "data": {"market": "0xfc6260666d020a912a87d9000eff5116d2adfb8c30aba543427a4c1f1411f1a0", "price_changes": [{"asset_id": "20615575591261238050354259319465440337102580196335623615376639598123117400036", "price": "0.69", "size": "389.75", "side": "SELL", "hash": "735b41126bacf6dee48e70c66dacd57acc7a00fb", "best_bid": "0.66", "best_ask": "0.67"}, {"asset_id": "57301498276970257025109591078431189727442302532145853906375186182281603517458", "price": "0.31", "size": "389.75", "side": "BUY", "hash": "004fcac721913d6a08fedfafbedeab2334572345", "best_bid": "0.33", "best_ask": "0.34"}], "timestamp": "1769384048092", "event_type": "price_change"}}
{"_local_timestamp": "2026-01-25T23:34:08.182045+00:00", "data": {"market": "0xfc6260666d020a912a87d9000eff5116d2adfb8c30aba543427a4c1f1411f1a0", "price_changes": [{"asset_id": "20615575591261238050354259319465440337102580196335623615376639598123117400036", "price": "0.69", "size": "438.75", "side": "SELL", "hash": "05415495e198109057ccce3236c8b383c5b15670", "best_bid": "0.66", "best_ask": "0.67"}, {"asset_id": "57301498276970257025109591078431189727442302532145853906375186182281603517458", "price": "0.31", "size": "438.75", "side": "BUY", "hash": "5900a3d35ccaaf71b5c5eefb1f6bbe468b18c051", "best_bid": "0.33", "best_ask": "0.34"}], "timestamp": "1769384048117", "event_type": "price_change"}}
{"_local_timestamp": "2026-01-25T23:34:09.665578+00:00", "data": {"market": "0xfc6260666d020a912a87d9000eff5116d2adfb8c30aba543427a4c1f1411f1a0", "price_changes": [{"asset_id": "20615575591261238050354259319465440337102580196335623615376639598123117400036", "price": "0.69", "size": "389.75", "side": "SELL", "hash": "8361bbc5006b75380bfcd6bdfa8666d1fe3beee7", "best_bid": "0.66", "best_ask": "0.67"}, {"asset_id": "57301498276970257025109591078431189727442302532145853906375186182281603517458", "price": "0.31", "size": "389.75", "side": "BUY", "hash": "1985c28977e3997db292c8390bc099d1782dc7be", "best_bid": "0.33", "best_ask": "0.34"}], "timestamp": "1769384049593", "event_type": "price_change"}}
{"_local_timestamp": "2026-01-25T23:34:09.689420+00:00", "data": {"market": "0xfc6260666d020a912a87d9000eff5116d2adfb8c30aba543427a4c1f1411f1a0", "price_changes": [{"asset_id": "20615575591261238050354259319465440337102580196335623615376639598123117400036", "price": "0.69", "size": "438.75", "side": "SELL", "hash": "7616a06e5e36939746500af8196353d68a3dee28", "best_bid": "0.66", "best_ask": "0.67"}, {"asset_id": "57301498276970257025109591078431189727442302532145853906375186182281603517458", "price": "0.31", "size": "438.75", "side": "BUY", "hash": "ec17afae2881991ca7885088ff8267151c474709", "best_bid": "0.33", "best_ask": "0.34"}], "timestamp": "1769384049621", "event_type": "price_change"}}
{"_local_timestamp": "2026-01-25T23:34:11.164413+00:00", "data": {"market": "0xfc6260666d020a912a87d9000eff5116d2adfb8c30aba543427a4c1f1411f1a0", "price_changes": [{"asset_id": "20615575591261238050354259319465440337102580196335623615376639598123117400036", "price": "0.69", "size": "389.75", "side": "SELL", "hash": "d06f63fd9df33b8c3cafed7dddc495a9a11e6beb", "best_bid": "0.66", "best_ask": "0.67"}, {"asset_id": "57301498276970257025109591078431189727442302532145853906375186182281603517458", "price": "0.31", "size": "389.75", "side": "BUY", "hash": "278646d75edf4546a4cbf3688caa4f598015af08", "best_bid": "0.33", "best_ask": "0.34"}], "timestamp": "1769384051096", "event_type": "price_change"}}
{"_local_timestamp": "2026-01-25T23:34:11.203893+00:00", "data": {"market": "0xfc6260666d020a912a87d9000eff5116d2adfb8c30aba543427a4c1f1411f1a0", "price_changes": [{"asset_id": "20615575591261238050354259319465440337102580196335623615376639598123117400036", "price": "0.69", "size": "438.75", "side": "SELL", "hash": "cc8c8ab1843a7daeb20ff0d1ed31815d92ec3a49", "best_bid": "0.66", "best_ask": "0.67"}, {"asset_id": "57301498276970257025109591078431189727442302532145853906375186182281603517458", "price": "0.31", "size": "438.75", "side": "BUY", "hash": "0e2675f84f4dae04e64898eba773d516b65537ca", "best_bid": "0.33", "best_ask": "0.34"}], "timestamp": "1769384051123", "event_type": "price_change"}}
{"_local_timestamp": "2026-01-25T23:34:12.672845+00:00", "data": {"market": "0xfc6260666d020a912a87d9000eff5116d2adfb8c30aba543427a4c1f1411f1a0", "price_changes": [{"asset_id": "20615575591261238050354259319465440337102580196335623615376639598123117400036", "price": "0.69", "size": "389.75", "side": "SELL", "hash": "39c666ae55b4a4ccfab6fd28aeb097ddc85e0f53", "best_bid": "0.66", "best_ask": "0.67"}, {"asset_id": "57301498276970257025109591078431189727442302532145853906375186182281603517458", "price": "0.31", "size": "389.75", "side": "BUY", "hash": "147f3aaa80568ac08de77d8a9983925adf5465fe", "best_bid": "0.33", "best_ask": "0.34"}], "timestamp": "1769384052595", "event_type": "price_change"}}
{"_local_timestamp": "2026-01-25T23:34:12.706141+00:00", "data": {"market": "0xfc6260666d020a912a87d9000eff5116d2adfb8c30aba543427a4c1f1411f1a0", "price_changes": [{"asset_id": "20615575591261238050354259319465440337102580196335623615376639598123117400036", "price": "0.69", "size": "438.75", "side": "SELL", "hash": "467f301aceabfccc936cdc9e620bb3c9fbb4bc80", "best_bid": "0.66", "best_ask": "0.67"}, {"asset_id": "57301498276970257025109591078431189727442302532145853906375186182281603517458", "price": "0.31", "size": "438.75", "side": "BUY", "hash": "83c86aeb11d4a68a3dcc9cb2d6f922ec3cdaf9a1", "best_bid": "0.33", "best_ask": "0.34"}], "timestamp": "1769384052634", "event_type": "price_change"}}
{"_local_timestamp": "2026-01-25T23:34:14.164013+00:00", "data": {"market": "0xfc6260666d020a912a87d9000eff5116d2adfb8c30aba543427a4c1f1411f1a0", "price_changes": [{"asset_id": "20615575591261238050354259319465440337102580196335623615376639598123117400036", "price": "0.69", "size": "389.75", "side": "SELL", "hash": "84eb5b0c3470a4a3629120c155c2f91a46421961", "best_bid": "0.66", "best_ask": "0.67"}, {"asset_id": "57301498276970257025109591078431189727442302532145853906375186182281603517458", "price": "0.31", "size": "389.75", "side": "BUY", "hash": "e810fb009a59e15b97db6b5c012abac469e1bc1f", "best_bid": "0.33", "best_ask": "0.34"}], "timestamp": "1769384054095", "event_type": "price_change"}}
{"_local_timestamp": "2026-01-25T23:34:14.208211+00:00", "data": {"market": "0xfc6260666d020a912a87d9000eff5116d2adfb8c30aba543427a4c1f1411f1a0", "price_changes": [{"asset_id": "20615575591261238050354259319465440337102580196335623615376639598123117400036", "price": "0.69", "size": "438.75", "side": "SELL", "hash": "499ba0409ecec17ce022109e7aa86edb936091b9", "best_bid": "0.66", "best_ask": "0.67"}, {"asset_id": "57301498276970257025109591078431189727442302532145853906375186182281603517458", "price": "0.31", "size": "438.75", "side": "BUY", "hash": "2499d092bb1c56b5a93e7bec04bcc4c137c1931b", "best_bid": "0.33", "best_ask": "0.34"}], "timestamp": "1769384054138", "event_type": "price_change"}}
{"_local_timestamp": "2026-01-25T23:34:15.664783+00:00", "data": {"market": "0xfc6260666d020a912a87d9000eff5116d2adfb8c30aba543427a4c1f1411f1a0", "price_changes": [{"asset_id": "20615575591261238050354259319465440337102580196335623615376639598123117400036", "price": "0.69", "size": "389.75", "side": "SELL", "hash": "5da9b0eb250b40760411c7637c6a389379c8fe03", "best_bid": "0.66", "best_ask": "0.67"}, {"asset_id": "57301498276970257025109591078431189727442302532145853906375186182281603517458", "price": "0.31", "size": "389.75", "side": "BUY", "hash": "c9cde684e10c3ecfbddff6924bab8cd07e096854", "best_bid": "0.33", "best_ask": "0.34"}], "timestamp": "1769384055597", "event_type": "price_change"}}
{"_local_timestamp": "2026-01-25T23:34:15.695411+00:00", "data": {"market": "0xfc6260666d020a912a87d9000eff5116d2adfb8c30aba543427a4c1f1411f1a0", "price_changes": [{"asset_id": "20615575591261238050354259319465440337102580196335623615376639598123117400036", "price": "0.69", "size": "438.75", "side": "SELL", "hash": "468410d497e51e55ee7c109f6d54f9b1e17fdc76", "best_bid": "0.66", "best_ask": "0.67"}, {"asset_id": "57301498276970257025109591078431189727442302532145853906375186182281603517458", "price": "0.31", "size": "438.75", "side": "BUY", "hash": "1112e0d9f28d13ff0380e8d90ca548ad92274196", "best_bid": "0.33", "best_ask": "0.34"}], "timestamp": "1769384055624", "event_type": "price_change"}}
{"_local_timestamp": "2026-01-25T23:34:17.160919+00:00", "data": {"market": "0xfc6260666d020a912a87d9000eff5116d2adfb8c30aba543427a4c1f1411f1a0", "price_changes": [{"asset_id": "20615575591261238050354259319465440337102580196335623615376639598123117400036", "price": "0.69", "size": "389.75", "side": "SELL", "hash": "5e48fe1ab0e655483756d531910144e584e875b8", "best_bid": "0.66", "best_ask": "0.67"}, {"asset_id": "57301498276970257025109591078431189727442302532145853906375186182281603517458", "price": "0.31", "size": "389.75", "side": "BUY", "hash": "88e3ed9ba4070efc62c04429c7713a1884238e20", "best_bid": "0.33", "best_ask": "0.34"}], "timestamp": "1769384057097", "event_type": "price_change"}}
{"_local_timestamp": "2026-01-25T23:34:17.197330+00:00", "data": {"market": "0xfc6260666d020a912a87d9000eff5116d2adfb8c30aba543427a4c1f1411f1a0", "price_changes": [{"asset_id": "20615575591261238050354259319465440337102580196335623615376639598123117400036", "price": "0.69", "size": "438.75", "side": "SELL", "hash": "c73a873d2e2ea0df2da1140c088a832b038f96a2", "best_bid": "0.66", "best_ask": "0.67"}, {"asset_id": "57301498276970257025109591078431189727442302532145853906375186182281603517458", "price": "0.31", "size": "438.75", "side": "BUY", "hash": "ead0b25d9e63177c848e916b52407908770d4bfc", "best_bid": "0.33", "best_ask": "0.34"}], "timestamp": "1769384057123", "event_type": "price_change"}}
{"_local_timestamp": "2026-01-25T23:34:18.663754+00:00", "data": {"market": "0xfc6260666d020a912a87d9000eff5116d2adfb8c30aba543427a4c1f1411f1a0", "price_changes": [{"asset_id": "20615575591261238050354259319465440337102580196335623615376639598123117400036", "price": "0.69", "size": "389.75", "side": "SELL", "hash": "8fb847deb33cbfa9ae842045aef4ba071a2579c3", "best_bid": "0.66", "best_ask": "0.67"}, {"asset_id": "57301498276970257025109591078431189727442302532145853906375186182281603517458", "price": "0.31", "size": "389.75", "side": "BUY", "hash": "2ce2d740e0a4fb696ab227af0b68bcac298e029d", "best_bid": "0.33", "best_ask": "0.34"}], "timestamp": "1769384058593", "event_type": "price_change"}}
{"_local_timestamp": "2026-01-25T23:34:18.683793+00:00", "data": {"market": "0xfc6260666d020a912a87d9000eff5116d2adfb8c30aba543427a4c1f1411f1a0", "price_changes": [{"asset_id": "20615575591261238050354259319465440337102580196335623615376639598123117400036", "price": "0.69", "size": "438.75", "side": "SELL", "hash": "e7b98f927bacfe2406cfd3ebff547618c58d6b57", "best_bid": "0.66", "best_ask": "0.67"}, {"asset_id": "57301498276970257025109591078431189727442302532145853906375186182281603517458", "price": "0.31", "size": "438.75", "side": "BUY", "hash": "0f1e3e23810589d162beecb4f7f1e8d1016b490b", "best_bid": "0.33", "best_ask": "0.34"}], "timestamp": "1769384058619", "event_type": "price_change"}}
{"_local_timestamp": "2026-01-25T23:34:20.163660+00:00", "data": {"market": "0xfc6260666d020a912a87d9000eff5116d2adfb8c30aba543427a4c1f1411f1a0", "price_changes": [{"asset_id": "20615575591261238050354259319465440337102580196335623615376639598123117400036", "price": "0.69", "size": "389.75", "side": "SELL", "hash": "53ff21810f25023dbfc4af953af0cd0fd64c1408", "best_bid": "0.66", "best_ask": "0.67"}, {"asset_id": "57301498276970257025109591078431189727442302532145853906375186182281603517458", "price": "0.31", "size": "389.75", "side": "BUY", "hash": "7a4efcea7d456ca9eaede4a1afed6b3b7d86a815", "best_bid": "0.33", "best_ask": "0.34"}], "timestamp": "1769384060096", "event_type": "price_change"}}
{"_local_timestamp": "2026-01-25T23:34:20.191719+00:00", "data": {"market": "0xfc6260666d020a912a87d9000eff5116d2adfb8c30aba543427a4c1f1411f1a0", "price_changes": [{"asset_id": "20615575591261238050354259319465440337102580196335623615376639598123117400036", "price": "0.69", "size": "438.75", "side": "SELL", "hash": "48209978a1a719c440e89118971e158db2098844", "best_bid": "0.66", "best_ask": "0.67"}, {"asset_id": "57301498276970257025109591078431189727442302532145853906375186182281603517458", "price": "0.31", "size": "438.75", "side": "BUY", "hash": "5a09b9e7cad2a846b4a73807409ec16fdd967156", "best_bid": "0.33", "best_ask": "0.34"}], "timestamp": "1769384060123", "event_type": "price_change"}}
{"_local_timestamp": "2026-01-25T23:34:21.659010+00:00", "data": {"market": "0xfc6260666d020a912a87d9000eff5116d2adfb8c30aba543427a4c1f1411f1a0", "price_changes": [{"asset_id": "20615575591261238050354259319465440337102580196335623615376639598123117400036", "price": "0.69", "size": "389.75", "side": "SELL", "hash": "f9282cf8fc5c77088509b76c701d388258a89477", "best_bid": "0.66", "best_ask": "0.67"}, {"asset_id": "57301498276970257025109591078431189727442302532145853906375186182281603517458", "price": "0.31", "size": "389.75", "side": "BUY", "hash": "f8352cfa4d46ee5089c1df4eb45abfdfc18b8bf9", "best_bid": "0.33", "best_ask": "0.34"}], "timestamp": "1769384061593", "event_type": "price_change"}}
{"_local_timestamp": "2026-01-25T23:34:21.689945+00:00", "data": {"market": "0xfc6260666d020a912a87d9000eff5116d2adfb8c30aba543427a4c1f1411f1a0", "price_changes": [{"asset_id": "20615575591261238050354259319465440337102580196335623615376639598123117400036", "price": "0.69", "size": "438.75", "side": "SELL", "hash": "cd643046077bbc6a853005f739bc95ad76f3ec62", "best_bid": "0.66", "best_ask": "0.67"}, {"asset_id": "57301498276970257025109591078431189727442302532145853906375186182281603517458", "price": "0.31", "size": "438.75", "side": "BUY", "hash": "6032f8fe84b12adb8c1ce54900aea28fa99268ea", "best_bid": "0.33", "best_ask": "0.34"}], "timestamp": "1769384061618", "event_type": "price_change"}}
{"_local_timestamp": "2026-01-25T23:34:23.170092+00:00", "data": {"market": "0xfc6260666d020a912a87d9000eff5116d2adfb8c30aba543427a4c1f1411f1a0", "price_changes": [{"asset_id": "20615575591261238050354259319465440337102580196335623615376639598123117400036", "price": "0.69", "size": "389.75", "side": "SELL", "hash": "1e7ba8b20f83464b1da1f0839f8437d4e71a0dee", "best_bid": "0.66", "best_ask": "0.67"}, {"asset_id": "57301498276970257025109591078431189727442302532145853906375186182281603517458", "price": "0.31", "size": "389.75", "side": "BUY", "hash": "cf5e10b881e6135657b32594f52995e493ae1c13", "best_bid": "0.33", "best_ask": "0.34"}], "timestamp": "1769384063096", "event_type": "price_change"}}
{"_local_timestamp": "2026-01-25T23:34:23.190377+00:00", "data": {"market": "0xfc6260666d020a912a87d9000eff5116d2adfb8c30aba543427a4c1f1411f1a0", "price_changes": [{"asset_id": "20615575591261238050354259319465440337102580196335623615376639598123117400036", "price": "0.69", "size": "438.75", "side": "SELL", "hash": "53a2e465910cecac97e646be649694a602db11bd", "best_bid": "0.66", "best_ask": "0.67"}, {"asset_id": "57301498276970257025109591078431189727442302532145853906375186182281603517458", "price": "0.31", "size": "438.75", "side": "BUY", "hash": "cc19b65d8302415da0145455d14f83bf0e3aebd0", "best_bid": "0.33", "best_ask": "0.34"}], "timestamp": "1769384063122", "event_type": "price_change"}}
{"_local_timestamp": "2026-01-25T23:34:24.661141+00:00", "data": {"market": "0xfc6260666d020a912a87d9000eff5116d2adfb8c30aba543427a4c1f1411f1a0", "price_changes": [{"asset_id": "20615575591261238050354259319465440337102580196335623615376639598123117400036", "price": "0.69", "size": "389.75", "side": "SELL", "hash": "68772f52d6a03c3dfc94e7d4ac817c73864561df", "best_bid": "0.66", "best_ask": "0.67"}, {"asset_id": "57301498276970257025109591078431189727442302532145853906375186182281603517458", "price": "0.31", "size": "389.75", "side": "BUY", "hash": "1113e2fe61509302abfbb9c82923be1bd5ba272f", "best_bid": "0.33", "best_ask": "0.34"}], "timestamp": "1769384064595", "event_type": "price_change"}}
{"_local_timestamp": "2026-01-25T23:34:24.688991+00:00", "data": {"market": "0xfc6260666d020a912a87d9000eff5116d2adfb8c30aba543427a4c1f1411f1a0", "price_changes": [{"asset_id": "20615575591261238050354259319465440337102580196335623615376639598123117400036", "price": "0.69", "size": "438.75", "side": "SELL", "hash": "97ff22e74659706822842696ed8dec56486c779a", "best_bid": "0.66", "best_ask": "0.67"}, {"asset_id": "57301498276970257025109591078431189727442302532145853906375186182281603517458", "price": "0.31", "size": "438.75", "side": "BUY", "hash": "2ffcc3ce4debac95e69313a2e39f9ebf5dd4ba40", "best_bid": "0.33", "best_ask": "0.34"}], "timestamp": "1769384064622", "event_type": "price_change"}}
{"_local_timestamp": "2026-01-25T23:34:26.161936+00:00", "data": {"market": "0xfc6260666d020a912a87d9000eff5116d2adfb8c30aba543427a4c1f1411f1a0", "price_changes": [{"asset_id": "20615575591261238050354259319465440337102580196335623615376639598123117400036", "price": "0.69", "size": "389.75", "side": "SELL", "hash": "d25a6d5fe99a1f8c0d093b265478d60316f4dc1a", "best_bid": "0.66", "best_ask": "0.67"}, {"asset_id": "57301498276970257025109591078431189727442302532145853906375186182281603517458", "price": "0.31", "size": "389.75", "side": "BUY", "hash": "e7dc4dcd6b2caa7436f926e6c60356f30ab07248", "best_bid": "0.33", "best_ask": "0.34"}], "timestamp": "1769384066096", "event_type": "price_change"}}
{"_local_timestamp": "2026-01-25T23:34:26.203273+00:00", "data": {"market": "0xfc6260666d020a912a87d9000eff5116d2adfb8c30aba543427a4c1f1411f1a0", "price_changes": [{"asset_id": "20615575591261238050354259319465440337102580196335623615376639598123117400036", "price": "0.69", "size": "438.75", "side": "SELL", "hash": "544bd9f6599e2b766148c3426e74d210e7180898", "best_bid": "0.66", "best_ask": "0.67"}, {"asset_id": "57301498276970257025109591078431189727442302532145853906375186182281603517458", "price": "0.31", "size": "438.75", "side": "BUY", "hash": "071e4bcacf1dbeecad9738f9807a5d7926d8df0b", "best_bid": "0.33", "best_ask": "0.34"}], "timestamp": "1769384066128", "event_type": "price_change"}}
{"_local_timestamp": "2026-01-25T23:34:27.846563+00:00", "data": {"market": "0xfc6260666d020a912a87d9000eff5116d2adfb8c30aba543427a4c1f1411f1a0", "price_changes": [{"asset_id": "20615575591261238050354259319465440337102580196335623615376639598123117400036", "price": "0.69", "size": "389.75", "side": "SELL", "hash": "02dd72c78cabc5fb8bb737979bb9ce391042f352", "best_bid": "0.66", "best_ask": "0.67"}, {"asset_id": "57301498276970257025109591078431189727442302532145853906375186182281603517458", "price": "0.31", "size": "389.75", "side": "BUY", "hash": "14bfa278da2ba01181540ad4a966a6fca5d9231c", "best_bid": "0.33", "best_ask": "0.34"}], "timestamp": "1769384067596", "event_type": "price_change"}}
{"_local_timestamp": "2026-01-25T23:34:27.890209+00:00", "data": {"market": "0xfc6260666d020a912a87d9000eff5116d2adfb8c30aba543427a4c1f1411f1a0", "price_changes": [{"asset_id": "20615575591261238050354259319465440337102580196335623615376639598123117400036", "price": "0.69", "size": "438.75", "side": "SELL", "hash": "7d6131adb3508449a1babc3297a088ea08b3cfe5", "best_bid": "0.66", "best_ask": "0.67"}, {"asset_id": "57301498276970257025109591078431189727442302532145853906375186182281603517458", "price": "0.31", "size": "438.75", "side": "BUY", "hash": "f92d97c866adf2a24ec728b5013c39cc3e0cdadf", "best_bid": "0.33", "best_ask": "0.34"}], "timestamp": "1769384067625", "event_type": "price_change"}}
{"_local_timestamp": "2026-01-25T23:34:29.194364+00:00", "data": {"market": "0xfc6260666d020a912a87d9000eff5116d2adfb8c30aba543427a4c1f1411f1a0", "price_changes": [{"asset_id": "20615575591261238050354259319465440337102580196335623615376639598123117400036", "price": "0.69", "size": "389.75", "side": "SELL", "hash": "1210dbf541849ca04e1b3c53a280e799a9c028b6", "best_bid": "0.66", "best_ask": "0.67"}, {"asset_id": "57301498276970257025109591078431189727442302532145853906375186182281603517458", "price": "0.31", "size": "389.75", "side": "BUY", "hash": "d1ae1b2ab97aa348dc7fed9fed9d56f6a0d8a87b", "best_bid": "0.33", "best_ask": "0.34"}], "timestamp": "1769384069097", "event_type": "price_change"}}
{"_local_timestamp": "2026-01-25T23:34:29.200511+00:00", "data": {"market": "0xfc6260666d020a912a87d9000eff5116d2adfb8c30aba543427a4c1f1411f1a0", "price_changes": [{"asset_id": "20615575591261238050354259319465440337102580196335623615376639598123117400036", "price": "0.69", "size": "438.75", "side": "SELL", "hash": "3a496ad35e77776d0ef55591676a7c7bdab3191b", "best_bid": "0.66", "best_ask": "0.67"}, {"asset_id": "57301498276970257025109591078431189727442302532145853906375186182281603517458", "price": "0.31", "size": "438.75", "side": "BUY", "hash": "ab5102a9e18461f1da5d2c4c7589990e0a8d953d", "best_bid": "0.33", "best_ask": "0.34"}], "timestamp": "1769384069121", "event_type": "price_change"}}
{"_local_timestamp": "2026-01-25T23:34:30.707492+00:00", "data": {"market": "0xfc6260666d020a912a87d9000eff5116d2adfb8c30aba543427a4c1f1411f1a0", "price_changes": [{"asset_id": "20615575591261238050354259319465440337102580196335623615376639598123117400036", "price": "0.69", "size": "389.75", "side": "SELL", "hash": "07040d0b3c20004b2d230d4abfadaf1bdbdef31c", "best_bid": "0.66", "best_ask": "0.67"}, {"asset_id": "57301498276970257025109591078431189727442302532145853906375186182281603517458", "price": "0.31", "size": "389.75", "side": "BUY", "hash": "28b1227bcc780acd5ebecf5972d9eb372be88c96", "best_bid": "0.33", "best_ask": "0.34"}], "timestamp": "1769384070597", "event_type": "price_change"}}
{"_local_timestamp": "2026-01-25T23:34:30.718497+00:00", "data": {"market": "0xfc6260666d020a912a87d9000eff5116d2adfb8c30aba543427a4c1f1411f1a0", "price_changes": [{"asset_id": "20615575591261238050354259319465440337102580196335623615376639598123117400036", "price": "0.69", "size": "438.75", "side": "SELL", "hash": "cb513d588cf4a2fbb11c4cca773475d59b7c7c0c", "best_bid": "0.66", "best_ask": "0.67"}, {"asset_id": "57301498276970257025109591078431189727442302532145853906375186182281603517458", "price": "0.31", "size": "438.75", "side": "BUY", "hash": "da3e00e1d3384d1ba85eb3366baf1df46e1b75be", "best_bid": "0.33", "best_ask": "0.34"}], "timestamp": "1769384070624", "event_type": "price_change"}}
{"_local_timestamp": "2026-01-25T23:34:32.196446+00:00", "data": {"market": "0xfc6260666d020a912a87d9000eff5116d2adfb8c30aba543427a4c1f1411f1a0", "price_changes": [{"asset_id": "20615575591261238050354259319465440337102580196335623615376639598123117400036", "price": "0.69", "size": "389.75", "side": "SELL", "hash": "ab8cc83ade4857b2060c86127fdf9f0095cc39cb", "best_bid": "0.66", "best_ask": "0.67"}, {"asset_id": "57301498276970257025109591078431189727442302532145853906375186182281603517458", "price": "0.31", "size": "389.75", "side": "BUY", "hash": "6cb41c41b14b3a2390470352c660373b08c9624b", "best_bid": "0.33", "best_ask": "0.34"}], "timestamp": "1769384072096", "event_type": "price_change"}}
{"_local_timestamp": "2026-01-25T23:34:32.271086+00:00", "data": {"market": "0xfc6260666d020a912a87d9000eff5116d2adfb8c30aba543427a4c1f1411f1a0", "price_changes": [{"asset_id": "20615575591261238050354259319465440337102580196335623615376639598123117400036", "price": "0.69", "size": "438.75", "side": "SELL", "hash": "a4e1e91a1b250a6112e0e107ca4616ff6422d7ce", "best_bid": "0.66", "best_ask": "0.67"}, {"asset_id": "57301498276970257025109591078431189727442302532145853906375186182281603517458", "price": "0.31", "size": "438.75", "side": "BUY", "hash": "75544fb80381fa7816de019d2900a265adb64e3a", "best_bid": "0.33", "best_ask": "0.34"}], "timestamp": "1769384072126", "event_type": "price_change"}}
{"_local_timestamp": "2026-01-25T23:34:33.666867+00:00", "data": {"market": "0xfc6260666d020a912a87d9000eff5116d2adfb8c30aba543427a4c1f1411f1a0", "price_changes": [{"asset_id": "20615575591261238050354259319465440337102580196335623615376639598123117400036", "price": "0.69", "size": "389.75", "side": "SELL", "hash": "c450b422c8458a014682b4d366156d0ab4e0eb99", "best_bid": "0.66", "best_ask": "0.67"}, {"asset_id": "57301498276970257025109591078431189727442302532145853906375186182281603517458", "price": "0.31", "size": "389.75", "side": "BUY", "hash": "cb9bdc9010cd87f9415e795348d50b89545a12e3", "best_bid": "0.33", "best_ask": "0.34"}], "timestamp": "1769384073593", "event_type": "price_change"}}
{"_local_timestamp": "2026-01-25T23:34:33.688777+00:00", "data": {"market": "0xfc6260666d020a912a87d9000eff5116d2adfb8c30aba543427a4c1f1411f1a0", "price_changes": [{"asset_id": "20615575591261238050354259319465440337102580196335623615376639598123117400036", "price": "0.69", "size": "438.75", "side": "SELL", "hash": "6a3b63180e91b6a02f0a3c5e965ddd24cedaf420", "best_bid": "0.66", "best_ask": "0.67"}, {"asset_id": "57301498276970257025109591078431189727442302532145853906375186182281603517458", "price": "0.31", "size": "438.75", "side": "BUY", "hash": "50fedbd7c4ffd63eba9ccc7d107469d77ed4ec20", "best_bid": "0.33", "best_ask": "0.34"}], "timestamp": "1769384073620", "event_type": "price_change"}}
{"_local_timestamp": "2026-01-25T23:34:35.158995+00:00", "data": {"market": "0xfc6260666d020a912a87d9000eff5116d2adfb8c30aba543427a4c1f1411f1a0", "price_changes": [{"asset_id": "20615575591261238050354259319465440337102580196335623615376639598123117400036", "price": "0.69", "size": "389.75", "side": "SELL", "hash": "39aa32869147c50c1b9c300fafe25617e905fcb2", "best_bid": "0.66", "best_ask": "0.67"}, {"asset_id": "57301498276970257025109591078431189727442302532145853906375186182281603517458", "price": "0.31", "size": "389.75", "side": "BUY", "hash": "738ca5dbd3d0cb7911eb26145cdddbbccd63c6c8", "best_bid": "0.33", "best_ask": "0.34"}], "timestamp": "1769384075092", "event_type": "price_change"}}
{"_local_timestamp": "2026-01-25T23:34:35.194473+00:00", "data": {"market": "0xfc6260666d020a912a87d9000eff5116d2adfb8c30aba543427a4c1f1411f1a0", "price_changes": [{"asset_id": "20615575591261238050354259319465440337102580196335623615376639598123117400036", "price": "0.69", "size": "438.75", "side": "SELL", "hash": "7fefa1bd4c1d150528442f3fd53ac46f38b1ab32", "best_bid": "0.66", "best_ask": "0.67"}, {"asset_id": "57301498276970257025109591078431189727442302532145853906375186182281603517458", "price": "0.31", "size": "438.75", "side": "BUY", "hash": "aefd440fec5b47c2c341117d88e6466210530c57", "best_bid": "0.33", "best_ask": "0.34"}], "timestamp": "1769384075124", "event_type": "price_change"}}
{"_local_timestamp": "2026-01-25T23:34:36.661994+00:00", "data": {"market": "0xfc6260666d020a912a87d9000eff5116d2adfb8c30aba543427a4c1f1411f1a0", "price_changes": [{"asset_id": "20615575591261238050354259319465440337102580196335623615376639598123117400036", "price": "0.69", "size": "389.75", "side": "SELL", "hash": "fbc5a90940d04fbe57721ea1b9f3f2502069d1f3", "best_bid": "0.66", "best_ask": "0.67"}, {"asset_id": "57301498276970257025109591078431189727442302532145853906375186182281603517458", "price": "0.31", "size": "389.75", "side": "BUY", "hash": "74652ef15db7a10d8c1e468b630685545729cabd", "best_bid": "0.33", "best_ask": "0.34"}], "timestamp": "1769384076595", "event_type": "price_change"}}
{"_local_timestamp": "2026-01-25T23:34:36.685605+00:00", "data": {"market": "0xfc6260666d020a912a87d9000eff5116d2adfb8c30aba543427a4c1f1411f1a0", "price_changes": [{"asset_id": "20615575591261238050354259319465440337102580196335623615376639598123117400036", "price": "0.69", "size": "438.75", "side": "SELL", "hash": "affa544287b7dcc3d63e0e0ad5cab0834398ea17", "best_bid": "0.66", "best_ask": "0.67"}, {"asset_id": "57301498276970257025109591078431189727442302532145853906375186182281603517458", "price": "0.31", "size": "438.75", "side": "BUY", "hash": "a49b28fd7d9b5766a2c0d0ba8e4341905463a5a9", "best_bid": "0.33", "best_ask": "0.34"}], "timestamp": "1769384076621", "event_type": "price_change"}}
{"_local_timestamp": "2026-01-25T23:34:38.162711+00:00", "data": {"market": "0xfc6260666d020a912a87d9000eff5116d2adfb8c30aba543427a4c1f1411f1a0", "price_changes": [{"asset_id": "20615575591261238050354259319465440337102580196335623615376639598123117400036", "price": "0.69", "size": "389.75", "side": "SELL", "hash": "1e45e6cfd135391b5e0cdd35296d192d0855c574", "best_bid": "0.66", "best_ask": "0.67"}, {"asset_id": "57301498276970257025109591078431189727442302532145853906375186182281603517458", "price": "0.31", "size": "389.75", "side": "BUY", "hash": "5e7c4ccf1a88d1759f8ca632cb09d16c7c8a1592", "best_bid": "0.33", "best_ask": "0.34"}], "timestamp": "1769384078094", "event_type": "price_change"}}
{"_local_timestamp": "2026-01-25T23:34:38.187184+00:00", "data": {"market": "0xfc6260666d020a912a87d9000eff5116d2adfb8c30aba543427a4c1f1411f1a0", "price_changes": [{"asset_id": "20615575591261238050354259319465440337102580196335623615376639598123117400036", "price": "0.69", "size": "438.75", "side": "SELL", "hash": "8588073081786c5f557bd6ac6f3a350e9577b364", "best_bid": "0.66", "best_ask": "0.67"}, {"asset_id": "57301498276970257025109591078431189727442302532145853906375186182281603517458", "price": "0.31", "size": "438.75", "side": "BUY", "hash": "9088d6df30f6d4a4ce0e0c6481510ce2001fd3fa", "best_bid": "0.33", "best_ask": "0.34"}], "timestamp": "1769384078122", "event_type": "price_change"}}
{"_local_timestamp": "2026-01-25T23:34:39.665464+00:00", "data": {"market": "0xfc6260666d020a912a87d9000eff5116d2adfb8c30aba543427a4c1f1411f1a0", "price_changes": [{"asset_id": "20615575591261238050354259319465440337102580196335623615376639598123117400036", "price": "0.69", "size": "389.75", "side": "SELL", "hash": "a6b981a9fc6a535655ed5b2e91dd54ed30dfc7b4", "best_bid": "0.66", "best_ask": "0.67"}, {"asset_id": "57301498276970257025109591078431189727442302532145853906375186182281603517458", "price": "0.31", "size": "389.75", "side": "BUY", "hash": "b6d57331b9abf15088c311bb769cbaab1bdcfc19", "best_bid": "0.33", "best_ask": "0.34"}], "timestamp": "1769384079601", "event_type": "price_change"}}
{"_local_timestamp": "2026-01-25T23:34:39.696195+00:00", "data": {"market": "0xfc6260666d020a912a87d9000eff5116d2adfb8c30aba543427a4c1f1411f1a0", "price_changes": [{"asset_id": "20615575591261238050354259319465440337102580196335623615376639598123117400036", "price": "0.69", "size": "438.75", "side": "SELL", "hash": "b7ae3a3cf50b88b06742b17c05541794ed30982b", "best_bid": "0.66", "best_ask": "0.67"}, {"asset_id": "57301498276970257025109591078431189727442302532145853906375186182281603517458", "price": "0.31", "size": "438.75", "side": "BUY", "hash": "085b6890906fe5ba4936eefc0a646a4463548b88", "best_bid": "0.33", "best_ask": "0.34"}], "timestamp": "1769384079628", "event_type": "price_change"}}
{"_local_timestamp": "2026-01-25T23:34:41.170107+00:00", "data": {"market": "0xfc6260666d020a912a87d9000eff5116d2adfb8c30aba543427a4c1f1411f1a0", "price_changes": [{"asset_id": "20615575591261238050354259319465440337102580196335623615376639598123117400036", "price": "0.69", "size": "389.75", "side": "SELL", "hash": "7d1fd2625a183b89900d795ece0a0e228feb8a35", "best_bid": "0.66", "best_ask": "0.67"}, {"asset_id": "57301498276970257025109591078431189727442302532145853906375186182281603517458", "price": "0.31", "size": "389.75", "side": "BUY", "hash": "8bedf1e767b9e2b59c7f98a7816304a777ca498d", "best_bid": "0.33", "best_ask": "0.34"}], "timestamp": "1769384081094", "event_type": "price_change"}}
{"_local_timestamp": "2026-01-25T23:34:41.186252+00:00", "data": {"market": "0xfc6260666d020a912a87d9000eff5116d2adfb8c30aba543427a4c1f1411f1a0", "price_changes": [{"asset_id": "20615575591261238050354259319465440337102580196335623615376639598123117400036", "price": "0.69", "size": "438.75", "side": "SELL", "hash": "7865f7e9e1433feadd76724e2b91b894da9b0a27", "best_bid": "0.66", "best_ask": "0.67"}, {"asset_id": "57301498276970257025109591078431189727442302532145853906375186182281603517458", "price": "0.31", "size": "438.75", "side": "BUY", "hash": "047531a5a5edb2da570fdc7458400cd7d48bb140", "best_bid": "0.33", "best_ask": "0.34"}], "timestamp": "1769384081120", "event_type": "price_change"}}
{"_local_timestamp": "2026-01-25T23:34:42.666602+00:00", "data": {"market": "0xfc6260666d020a912a87d9000eff5116d2adfb8c30aba543427a4c1f1411f1a0", "price_changes": [{"asset_id": "20615575591261238050354259319465440337102580196335623615376639598123117400036", "price": "0.69", "size": "389.75", "side": "SELL", "hash": "5c3e1ab13d2c16ef331c15aed8fe50bf981f725d", "best_bid": "0.66", "best_ask": "0.67"}, {"asset_id": "57301498276970257025109591078431189727442302532145853906375186182281603517458", "price": "0.31", "size": "389.75", "side": "BUY", "hash": "cc9bd810ec17470a3b0c5c31f05a9a92a4211298", "best_bid": "0.33", "best_ask": "0.34"}], "timestamp": "1769384082595", "event_type": "price_change"}}
{"_local_timestamp": "2026-01-25T23:34:42.691497+00:00", "data": {"market": "0xfc6260666d020a912a87d9000eff5116d2adfb8c30aba543427a4c1f1411f1a0", "price_changes": [{"asset_id": "20615575591261238050354259319465440337102580196335623615376639598123117400036", "price": "0.69", "size": "438.75", "side": "SELL", "hash": "f1efa4040909f39c72a1045fd44d1e622eb6a216", "best_bid": "0.66", "best_ask": "0.67"}, {"asset_id": "57301498276970257025109591078431189727442302532145853906375186182281603517458", "price": "0.31", "size": "438.75", "side": "BUY", "hash": "d53cffdb5e75a3f4812647663c1383ecc954f095", "best_bid": "0.33", "best_ask": "0.34"}], "timestamp": "1769384082622", "event_type": "price_change"}}
{"_local_timestamp": "2026-01-25T23:34:44.159623+00:00", "data": {"market": "0xfc6260666d020a912a87d9000eff5116d2adfb8c30aba543427a4c1f1411f1a0", "price_changes": [{"asset_id": "20615575591261238050354259319465440337102580196335623615376639598123117400036", "price": "0.69", "size": "389.75", "side": "SELL", "hash": "284014907eb1063afdfd43dd7475d25dbf35e2cd", "best_bid": "0.66", "best_ask": "0.67"}, {"asset_id": "57301498276970257025109591078431189727442302532145853906375186182281603517458", "price": "0.31", "size": "389.75", "side": "BUY", "hash": "64a1e6d89497cf438d56ea8af9f14d93b0e168b2", "best_bid": "0.33", "best_ask": "0.34"}], "timestamp": "1769384084095", "event_type": "price_change"}}
{"_local_timestamp": "2026-01-25T23:34:44.191372+00:00", "data": {"market": "0xfc6260666d020a912a87d9000eff5116d2adfb8c30aba543427a4c1f1411f1a0", "price_changes": [{"asset_id": "20615575591261238050354259319465440337102580196335623615376639598123117400036", "price": "0.69", "size": "438.75", "side": "SELL", "hash": "5cb8b3d852783498f50724c9ace82f03852da4b2", "best_bid": "0.66", "best_ask": "0.67"}, {"asset_id": "57301498276970257025109591078431189727442302532145853906375186182281603517458", "price": "0.31", "size": "438.75", "side": "BUY", "hash": "55cfdbc0e514420fba92a138e042a0da9ebe2d19", "best_bid": "0.33", "best_ask": "0.34"}], "timestamp": "1769384084121", "event_type": "price_change"}}
{"_local_timestamp": "2026-01-25T23:34:45.678175+00:00", "data": {"market": "0xfc6260666d020a912a87d9000eff5116d2adfb8c30aba543427a4c1f1411f1a0", "price_changes": [{"asset_id": "20615575591261238050354259319465440337102580196335623615376639598123117400036", "price": "0.69", "size": "389.75", "side": "SELL", "hash": "1d04f57d03b492f6faede68d0f87fde065d056f6", "best_bid": "0.66", "best_ask": "0.67"}, {"asset_id": "57301498276970257025109591078431189727442302532145853906375186182281603517458", "price": "0.31", "size": "389.75", "side": "BUY", "hash": "9c3aa7cc5192b5642d43c6b9b99174e1a622e28c", "best_bid": "0.33", "best_ask": "0.34"}], "timestamp": "1769384085595", "event_type": "price_change"}}
{"_local_timestamp": "2026-01-25T23:34:45.685368+00:00", "data": {"market": "0xfc6260666d020a912a87d9000eff5116d2adfb8c30aba543427a4c1f1411f1a0", "price_changes": [{"asset_id": "20615575591261238050354259319465440337102580196335623615376639598123117400036", "price": "0.69", "size": "438.75", "side": "SELL", "hash": "a94bb5c98436e9bca523db735b8e038c782330aa", "best_bid": "0.66", "best_ask": "0.67"}, {"asset_id": "57301498276970257025109591078431189727442302532145853906375186182281603517458", "price": "0.31", "size": "438.75", "side": "BUY", "hash": "da2ebc1027e1fe2b452b9d4ad57be82abea184e8", "best_bid": "0.33", "best_ask": "0.34"}], "timestamp": "1769384085620", "event_type": "price_change"}}
{"_local_timestamp": "2026-01-25T23:34:47.156956+00:00", "data": {"market": "0xfc6260666d020a912a87d9000eff5116d2adfb8c30aba543427a4c1f1411f1a0", "price_changes": [{"asset_id": "20615575591261238050354259319465440337102580196335623615376639598123117400036", "price": "0.69", "size": "389.75", "side": "SELL", "hash": "7283b3a5a177dc91997ef1c43ce378d23a01ce34", "best_bid": "0.66", "best_ask": "0.67"}, {"asset_id": "57301498276970257025109591078431189727442302532145853906375186182281603517458", "price": "0.31", "size": "389.75", "side": "BUY", "hash": "82ab93eb80ae88acb65527e271db98a9ebdf97e2", "best_bid": "0.33", "best_ask": "0.34"}], "timestamp": "1769384087092", "event_type": "price_change"}}
{"_local_timestamp": "2026-01-25T23:34:47.184540+00:00", "data": {"market": "0xfc6260666d020a912a87d9000eff5116d2adfb8c30aba543427a4c1f1411f1a0", "price_changes": [{"asset_id": "20615575591261238050354259319465440337102580196335623615376639598123117400036", "price": "0.69", "size": "438.75", "side": "SELL", "hash": "00d528e26cede8e6c9fcbb1627822c750db56348", "best_bid": "0.66", "best_ask": "0.67"}, {"asset_id": "57301498276970257025109591078431189727442302532145853906375186182281603517458", "price": "0.31", "size": "438.75", "side": "BUY", "hash": "aa2c901956e308b4350be344e51a400f5ea09fe8", "best_bid": "0.33", "best_ask": "0.34"}], "timestamp": "1769384087119", "event_type": "price_change"}}
{"_local_timestamp": "2026-01-25T23:34:48.663111+00:00", "data": {"market": "0xfc6260666d020a912a87d9000eff5116d2adfb8c30aba543427a4c1f1411f1a0", "price_changes": [{"asset_id": "20615575591261238050354259319465440337102580196335623615376639598123117400036", "price": "0.69", "size": "389.75", "side": "SELL", "hash": "1c7d9f4dbd8ef11ec6708e0f9e42b3d5f689c783", "best_bid": "0.66", "best_ask": "0.67"}, {"asset_id": "57301498276970257025109591078431189727442302532145853906375186182281603517458", "price": "0.31", "size": "389.75", "side": "BUY", "hash": "548c17e02da071bff940f835dac75bf71157014e", "best_bid": "0.33", "best_ask": "0.34"}], "timestamp": "1769384088595", "event_type": "price_change"}}
{"_local_timestamp": "2026-01-25T23:34:48.693978+00:00", "data": {"market": "0xfc6260666d020a912a87d9000eff5116d2adfb8c30aba543427a4c1f1411f1a0", "price_changes": [{"asset_id": "20615575591261238050354259319465440337102580196335623615376639598123117400036", "price": "0.69", "size": "438.75", "side": "SELL", "hash": "686d591cba985740b3ca2a96760d94cf2ed7a5d4", "best_bid": "0.66", "best_ask": "0.67"}, {"asset_id": "57301498276970257025109591078431189727442302532145853906375186182281603517458", "price": "0.31", "size": "438.75", "side": "BUY", "hash": "42d572c1052fb84429ee84cc9753a5cbfcc42045", "best_bid": "0.33", "best_ask": "0.34"}], "timestamp": "1769384088626", "event_type": "price_change"}}
{"_local_timestamp": "2026-01-25T23:34:50.157154+00:00", "data": {"market": "0xfc6260666d020a912a87d9000eff5116d2adfb8c30aba543427a4c1f1411f1a0", "price_changes": [{"asset_id": "20615575591261238050354259319465440337102580196335623615376639598123117400036", "price": "0.69", "size": "389.75", "side": "SELL", "hash": "a45de61fecb97f81d3f560deb1bfb2c720aa3f11", "best_bid": "0.66", "best_ask": "0.67"}, {"asset_id": "57301498276970257025109591078431189727442302532145853906375186182281603517458", "price": "0.31", "size": "389.75", "side": "BUY", "hash": "69d6a11cf09cccb2e856777ecdbe6e00c17b048e", "best_bid": "0.33", "best_ask": "0.34"}], "timestamp": "1769384090092", "event_type": "price_change"}}
{"_local_timestamp": "2026-01-25T23:34:50.189049+00:00", "data": {"market": "0xfc6260666d020a912a87d9000eff5116d2adfb8c30aba543427a4c1f1411f1a0", "price_changes": [{"asset_id": "20615575591261238050354259319465440337102580196335623615376639598123117400036", "price": "0.69", "size": "438.75", "side": "SELL", "hash": "45bbc2db7f3f697e6292592ad0aea53255780030", "best_bid": "0.66", "best_ask": "0.67"}, {"asset_id": "57301498276970257025109591078431189727442302532145853906375186182281603517458", "price": "0.31", "size": "438.75", "side": "BUY", "hash": "fd174ba536e86a9a9225d2e9b7452579f89d8ba2", "best_bid": "0.33", "best_ask": "0.34"}], "timestamp": "1769384090118", "event_type": "price_change"}}
{"_local_timestamp": "2026-01-25T23:34:51.661285+00:00", "data": {"market": "0xfc6260666d020a912a87d9000eff5116d2adfb8c30aba543427a4c1f1411f1a0", "price_changes": [{"asset_id": "20615575591261238050354259319465440337102580196335623615376639598123117400036", "price": "0.69", "size": "389.75", "side": "SELL", "hash": "c7e8d5250dfeb6b3f92d187153e03347de8b63a1", "best_bid": "0.66", "best_ask": "0.67"}, {"asset_id": "57301498276970257025109591078431189727442302532145853906375186182281603517458", "price": "0.31", "size": "389.75", "side": "BUY", "hash": "e37339f3c9cc37e660376d2df85c32b52ed5bd67", "best_bid": "0.33", "best_ask": "0.34"}], "timestamp": "1769384091594", "event_type": "price_change"}}
{"_local_timestamp": "2026-01-25T23:34:51.685160+00:00", "data": {"market": "0xfc6260666d020a912a87d9000eff5116d2adfb8c30aba543427a4c1f1411f1a0", "price_changes": [{"asset_id": "20615575591261238050354259319465440337102580196335623615376639598123117400036", "price": "0.69", "size": "438.75", "side": "SELL", "hash": "035e9f6df8c3b0b21ced89a8b1a9538ee6dba8f9", "best_bid": "0.66", "best_ask": "0.67"}, {"asset_id": "57301498276970257025109591078431189727442302532145853906375186182281603517458", "price": "0.31", "size": "438.75", "side": "BUY", "hash": "985f2068bcad674350433e4b791a4fbb64143929", "best_bid": "0.33", "best_ask": "0.34"}], "timestamp": "1769384091619", "event_type": "price_change"}}
{"_local_timestamp": "2026-01-25T23:34:53.161044+00:00", "data": {"market": "0xfc6260666d020a912a87d9000eff5116d2adfb8c30aba543427a4c1f1411f1a0", "price_changes": [{"asset_id": "20615575591261238050354259319465440337102580196335623615376639598123117400036", "price": "0.69", "size": "389.75", "side": "SELL", "hash": "1cbef331853c3fc4ba8fcdbd6c40f08d0e8325d3", "best_bid": "0.66", "best_ask": "0.67"}, {"asset_id": "57301498276970257025109591078431189727442302532145853906375186182281603517458", "price": "0.31", "size": "389.75", "side": "BUY", "hash": "66f6c09bd021b1a8a60a8007c745342e9a67a059", "best_bid": "0.33", "best_ask": "0.34"}], "timestamp": "1769384093094", "event_type": "price_change"}}
{"_local_timestamp": "2026-01-25T23:34:53.637707+00:00", "data": {"market": "0xfc6260666d020a912a87d9000eff5116d2adfb8c30aba543427a4c1f1411f1a0", "price_changes": [{"asset_id": "20615575591261238050354259319465440337102580196335623615376639598123117400036", "price": "0.69", "size": "438.75", "side": "SELL", "hash": "75666fd5323f9827938bd39fd60fa493ef4a9cfa", "best_bid": "0.66", "best_ask": "0.67"}, {"asset_id": "57301498276970257025109591078431189727442302532145853906375186182281603517458", "price": "0.31", "size": "438.75", "side": "BUY", "hash": "4e35bdde164d891881aef4d82289af814d81960f", "best_bid": "0.33", "best_ask": "0.34"}], "timestamp": "1769384093119", "event_type": "price_change"}}
{"_local_timestamp": "2026-01-25T23:34:54.687675+00:00", "data": {"market": "0xfc6260666d020a912a87d9000eff5116d2adfb8c30aba543427a4c1f1411f1a0", "price_changes": [{"asset_id": "20615575591261238050354259319465440337102580196335623615376639598123117400036", "price": "0.69", "size": "389.75", "side": "SELL", "hash": "2feebe32e50a4214b9b02dec8e4acf68157615ca", "best_bid": "0.66", "best_ask": "0.67"}, {"asset_id": "57301498276970257025109591078431189727442302532145853906375186182281603517458", "price": "0.31", "size": "389.75", "side": "BUY", "hash": "5294103c8a2d44bb5c05d51e715af02d3ef91d18", "best_bid": "0.33", "best_ask": "0.34"}], "timestamp": "1769384094593", "event_type": "price_change"}}
{"_local_timestamp": "2026-01-25T23:34:54.688464+00:00", "data": {"market": "0xfc6260666d020a912a87d9000eff5116d2adfb8c30aba543427a4c1f1411f1a0", "price_changes": [{"asset_id": "20615575591261238050354259319465440337102580196335623615376639598123117400036", "price": "0.69", "size": "438.75", "side": "SELL", "hash": "482ab589e3a6dbc7366dce17a42ae976ab71cdfa", "best_bid": "0.66", "best_ask": "0.67"}, {"asset_id": "57301498276970257025109591078431189727442302532145853906375186182281603517458", "price": "0.31", "size": "438.75", "side": "BUY", "hash": "7e15cb9d241e7d4836df73fcb6afc9133b6e6a66", "best_bid": "0.33", "best_ask": "0.34"}], "timestamp": "1769384094619", "event_type": "price_change"}}
{"_local_timestamp": "2026-01-25T23:34:56.220559+00:00", "data": {"market": "0xfc6260666d020a912a87d9000eff5116d2adfb8c30aba543427a4c1f1411f1a0", "price_changes": [{"asset_id": "20615575591261238050354259319465440337102580196335623615376639598123117400036", "price": "0.69", "size": "389.75", "side": "SELL", "hash": "888db2606cf59c025f698655ee63aec52afc7b30", "best_bid": "0.66", "best_ask": "0.67"}, {"asset_id": "57301498276970257025109591078431189727442302532145853906375186182281603517458", "price": "0.31", "size": "389.75", "side": "BUY", "hash": "7145940038e8d700446374073613fea518188a57", "best_bid": "0.33", "best_ask": "0.34"}], "timestamp": "1769384096098", "event_type": "price_change"}}
{"_local_timestamp": "2026-01-25T23:34:56.228808+00:00", "data": {"market": "0xfc6260666d020a912a87d9000eff5116d2adfb8c30aba543427a4c1f1411f1a0", "price_changes": [{"asset_id": "20615575591261238050354259319465440337102580196335623615376639598123117400036", "price": "0.69", "size": "438.75", "side": "SELL", "hash": "d14950fbc8c67761fb37ae976275e5c8314d2eae", "best_bid": "0.66", "best_ask": "0.67"}, {"asset_id": "57301498276970257025109591078431189727442302532145853906375186182281603517458", "price": "0.31", "size": "438.75", "side": "BUY", "hash": "d297dc34cc1b0113d77330d4be2434a851515fa0", "best_bid": "0.33", "best_ask": "0.34"}], "timestamp": "1769384096124", "event_type": "price_change"}}
{"_local_timestamp": "2026-01-25T23:34:57.661447+00:00", "data": {"market": "0xfc6260666d020a912a87d9000eff5116d2adfb8c30aba543427a4c1f1411f1a0", "price_changes": [{"asset_id": "20615575591261238050354259319465440337102580196335623615376639598123117400036", "price": "0.69", "size": "389.75", "side": "SELL", "hash": "49fb0559600d112b40218c585c6cf6bcabbb8c5b", "best_bid": "0.66", "best_ask": "0.67"}, {"asset_id": "57301498276970257025109591078431189727442302532145853906375186182281603517458", "price": "0.31", "size": "389.75", "side": "BUY", "hash": "e8e0bf9480bd6ce970200614d60aa3d377d2dfcc", "best_bid": "0.33", "best_ask": "0.34"}], "timestamp": "1769384097598", "event_type": "price_change"}}
{"_local_timestamp": "2026-01-25T23:34:57.690584+00:00", "data": {"market": "0xfc6260666d020a912a87d9000eff5116d2adfb8c30aba543427a4c1f1411f1a0", "price_changes": [{"asset_id": "20615575591261238050354259319465440337102580196335623615376639598123117400036", "price": "0.69", "size": "438.75", "side": "SELL", "hash": "a1586e2bf81a05d898ecbee5b837328c572da60a", "best_bid": "0.66", "best_ask": "0.67"}, {"asset_id": "57301498276970257025109591078431189727442302532145853906375186182281603517458", "price": "0.31", "size": "438.75", "side": "BUY", "hash": "bfc84340696b9c781b38f771c44f25d2d23e51dc", "best_bid": "0.33", "best_ask": "0.34"}], "timestamp": "1769384097623", "event_type": "price_change"}}
{"_local_timestamp": "2026-01-25T23:34:59.156794+00:00", "data": {"market": "0xfc6260666d020a912a87d9000eff5116d2adfb8c30aba543427a4c1f1411f1a0", "price_changes": [{"asset_id": "20615575591261238050354259319465440337102580196335623615376639598123117400036", "price": "0.69", "size": "389.75", "side": "SELL", "hash": "d99576874b1cb37714f3b46ceec8417e3d53bbf2", "best_bid": "0.66", "best_ask": "0.67"}, {"asset_id": "57301498276970257025109591078431189727442302532145853906375186182281603517458", "price": "0.31", "size": "389.75", "side": "BUY", "hash": "e01c9fc03e2708d1ce7a23e30e735868282bc9e0", "best_bid": "0.33", "best_ask": "0.34"}], "timestamp": "1769384099093", "event_type": "price_change"}}
{"_local_timestamp": "2026-01-25T23:34:59.188738+00:00", "data": {"market": "0xfc6260666d020a912a87d9000eff5116d2adfb8c30aba543427a4c1f1411f1a0", "price_changes": [{"asset_id": "20615575591261238050354259319465440337102580196335623615376639598123117400036", "price": "0.69", "size": "438.75", "side": "SELL", "hash": "8a1198659802c781ffb5748c2704af97097d7477", "best_bid": "0.66", "best_ask": "0.67"}, {"asset_id": "57301498276970257025109591078431189727442302532145853906375186182281603517458", "price": "0.31", "size": "438.75", "side": "BUY", "hash": "8eb1ab72628bc952b3c96aedc58dbe703b0b5166", "best_bid": "0.33", "best_ask": "0.34"}], "timestamp": "1769384099118", "event_type": "price_change"}}
{"_local_timestamp": "2026-01-25T23:35:00.672556+00:00", "data": {"market": "0xfc6260666d020a912a87d9000eff5116d2adfb8c30aba543427a4c1f1411f1a0", "price_changes": [{"asset_id": "20615575591261238050354259319465440337102580196335623615376639598123117400036", "price": "0.69", "size": "389.75", "side": "SELL", "hash": "f605d4882dbea498880207bb0bd62a93960ac75a", "best_bid": "0.66", "best_ask": "0.67"}, {"asset_id": "57301498276970257025109591078431189727442302532145853906375186182281603517458", "price": "0.31", "size": "389.75", "side": "BUY", "hash": "55b4b72298145a3aaaa7be40332ad42f2a37d7b3", "best_bid": "0.33", "best_ask": "0.34"}], "timestamp": "1769384100596", "event_type": "price_change"}}
{"_local_timestamp": "2026-01-25T23:35:00.709183+00:00", "data": {"market": "0xfc6260666d020a912a87d9000eff5116d2adfb8c30aba543427a4c1f1411f1a0", "price_changes": [{"asset_id": "20615575591261238050354259319465440337102580196335623615376639598123117400036", "price": "0.69", "size": "438.75", "side": "SELL", "hash": "ea6c03aec3b4ec99c93db218b628ae83d842f959", "best_bid": "0.66", "best_ask": "0.67"}, {"asset_id": "57301498276970257025109591078431189727442302532145853906375186182281603517458", "price": "0.31", "size": "438.75", "side": "BUY", "hash": "72bf85b26d2164bab95f7aa81fb62163d7de927e", "best_bid": "0.33", "best_ask": "0.34"}], "timestamp": "1769384100631", "event_type": "price_change"}}
{"_local_timestamp": "2026-01-25T23:35:02.220616+00:00", "data": {"market": "0xfc6260666d020a912a87d9000eff5116d2adfb8c30aba543427a4c1f1411f1a0", "price_changes": [{"asset_id": "20615575591261238050354259319465440337102580196335623615376639598123117400036", "price": "0.69", "size": "389.75", "side": "SELL", "hash": "cb5aa33f8cb158df1368f4645009c3aeb4838583", "best_bid": "0.66", "best_ask": "0.67"}, {"asset_id": "57301498276970257025109591078431189727442302532145853906375186182281603517458", "price": "0.31", "size": "389.75", "side": "BUY", "hash": "3792042867313da8da45547ab9452705273814bb", "best_bid": "0.33", "best_ask": "0.34"}], "timestamp": "1769384102094", "event_type": "price_change"}}
{"_local_timestamp": "2026-01-25T23:35:02.250630+00:00", "data": {"market": "0xfc6260666d020a912a87d9000eff5116d2adfb8c30aba543427a4c1f1411f1a0", "price_changes": [{"asset_id": "20615575591261238050354259319465440337102580196335623615376639598123117400036", "price": "0.69", "size": "438.75", "side": "SELL", "hash": "0b96c428a90bdd62a998182b91610823524d8137", "best_bid": "0.66", "best_ask": "0.67"}, {"asset_id": "57301498276970257025109591078431189727442302532145853906375186182281603517458", "price": "0.31", "size": "438.75", "side": "BUY", "hash": "a0a4f5a2243a923e972210922005dfa445ced757", "best_bid": "0.33", "best_ask": "0.34"}], "timestamp": "1769384102120", "event_type": "price_change"}}
{"_local_timestamp": "2026-01-25T23:35:03.732721+00:00", "data": {"market": "0xfc6260666d020a912a87d9000eff5116d2adfb8c30aba543427a4c1f1411f1a0", "price_changes": [{"asset_id": "20615575591261238050354259319465440337102580196335623615376639598123117400036", "price": "0.69", "size": "389.75", "side": "SELL", "hash": "03c518e52fa236f6750261f03934e912144d7b41", "best_bid": "0.66", "best_ask": "0.67"}, {"asset_id": "57301498276970257025109591078431189727442302532145853906375186182281603517458", "price": "0.31", "size": "389.75", "side": "BUY", "hash": "ccf29302a55bcb9a3dc247759c8b0ff5016f7edb", "best_bid": "0.33", "best_ask": "0.34"}], "timestamp": "1769384103594", "event_type": "price_change"}}
{"_local_timestamp": "2026-01-25T23:35:03.755180+00:00", "data": {"market": "0xfc6260666d020a912a87d9000eff5116d2adfb8c30aba543427a4c1f1411f1a0", "price_changes": [{"asset_id": "20615575591261238050354259319465440337102580196335623615376639598123117400036", "price": "0.69", "size": "438.75", "side": "SELL", "hash": "15a8f7eae1bb5b86eec222f43822954469495fa7", "best_bid": "0.66", "best_ask": "0.67"}, {"asset_id": "57301498276970257025109591078431189727442302532145853906375186182281603517458", "price": "0.31", "size": "438.75", "side": "BUY", "hash": "0bbc88d2967a569e66a616616c82e34907e8c44b", "best_bid": "0.33", "best_ask": "0.34"}], "timestamp": "1769384103620", "event_type": "price_change"}}
{"_local_timestamp": "2026-01-25T23:35:03.886096+00:00", "data": {"market": "0xdb68062324c27327e9cd4b21b1dd0deadbc4b860abb8c076b9ba3ed4652ced13", "price_changes": [{"asset_id": "70438891017239169523888340706940482203786228582885836666142245799578935372711", "price": "0.501", "size": "0", "side": "BUY", "hash": "38497dbc1bcfb1513694b428c1a11686f43d63c3", "best_bid": "0.98", "best_ask": "0.981"}, {"asset_id": "78059086946243166298250434231742381590921423205138738331803802527161013528631", "price": "0.499", "size": "0", "side": "SELL", "hash": "2c0ce4a19766a5ac8b8ee8bd051de3a7ee6c6bbe", "best_bid": "0.019", "best_ask": "0.02"}], "timestamp": "1769384103757", "event_type": "price_change"}}
{"_local_timestamp": "2026-01-25T23:35:04.077627+00:00", "data": {"market": "0xdb68062324c27327e9cd4b21b1dd0deadbc4b860abb8c076b9ba3ed4652ced13", "price_changes": [{"asset_id": "70438891017239169523888340706940482203786228582885836666142245799578935372711", "price": "0.5", "size": "800.37", "side": "BUY", "hash": "6fa42dc40ceaaeaee3d374c3c81aa9ce0d810a4c", "best_bid": "0.98", "best_ask": "0.981"}, {"asset_id": "78059086946243166298250434231742381590921423205138738331803802527161013528631", "price": "0.5", "size": "800.37", "side": "SELL", "hash": "3b4fe30b0aa8287411f758400d18651200572ad6", "best_bid": "0.019", "best_ask": "0.02"}], "timestamp": "1769384103940", "event_type": "price_change"}}
{"_local_timestamp": "2026-01-25T23:35:04.292416+00:00", "data": {"market": "0xdb68062324c27327e9cd4b21b1dd0deadbc4b860abb8c076b9ba3ed4652ced13", "price_changes": [{"asset_id": "70438891017239169523888340706940482203786228582885836666142245799578935372711", "price": "0.099", "size": "0", "side": "BUY", "hash": "a1834b751bd9725fb73b0809c4f2514415eb2655", "best_bid": "0.98", "best_ask": "0.981"}, {"asset_id": "78059086946243166298250434231742381590921423205138738331803802527161013528631", "price": "0.901", "size": "0", "side": "SELL", "hash": "eac8928a17eb55b8d742415890787bb3e676f892", "best_bid": "0.019", "best_ask": "0.02"}], "timestamp": "1769384104140", "event_type": "price_change"}}
{"_local_timestamp": "2026-01-25T23:35:04.521777+00:00", "data": {"market": "0xdb68062324c27327e9cd4b21b1dd0deadbc4b860abb8c076b9ba3ed4652ced13", "price_changes": [{"asset_id": "70438891017239169523888340706940482203786228582885836666142245799578935372711", "price": "0.031", "size": "0", "side": "BUY", "hash": "f624f251b891f02da61a69c2a294b988e5bf8da1", "best_bid": "0.98", "best_ask": "0.981"}, {"asset_id": "78059086946243166298250434231742381590921423205138738331803802527161013528631", "price": "0.969", "size": "0", "side": "SELL", "hash": "82edc95747a9d3d0c9e939312acb4c7c7c04382d", "best_bid": "0.019", "best_ask": "0.02"}], "timestamp": "1769384104363", "event_type": "price_change"}}
{"_local_timestamp": "2026-01-25T23:35:04.723866+00:00", "data": {"market": "0xdb68062324c27327e9cd4b21b1dd0deadbc4b860abb8c076b9ba3ed4652ced13", "price_changes": [{"asset_id": "70438891017239169523888340706940482203786228582885836666142245799578935372711", "price": "0.031", "size": "193.54", "side": "BUY", "hash": "d85f67b645f7d9884beba8ae9236a20cb40e86b8", "best_bid": "0.98", "best_ask": "0.981"}, {"asset_id": "78059086946243166298250434231742381590921423205138738331803802527161013528631", "price": "0.969", "size": "193.54", "side": "SELL", "hash": "cdf15ee066b3bb1227194c00db2a17d5ecf778f3", "best_bid": "0.019", "best_ask": "0.02"}], "timestamp": "1769384104577", "event_type": "price_change"}}
{"_local_timestamp": "2026-01-25T23:35:04.948491+00:00", "data": {"market": "0xdb68062324c27327e9cd4b21b1dd0deadbc4b860abb8c076b9ba3ed4652ced13", "price_changes": [{"asset_id": "70438891017239169523888340706940482203786228582885836666142245799578935372711", "price": "0.061", "size": "0", "side": "BUY", "hash": "aa68ca401f4a0db4ee0be479a40e7e4d5e45f11b", "best_bid": "0.98", "best_ask": "0.981"}, {"asset_id": "78059086946243166298250434231742381590921423205138738331803802527161013528631", "price": "0.939", "size": "0", "side": "SELL", "hash": "21c03b92048091f9950ae06d87cfaa24f7d0c8df", "best_bid": "0.019", "best_ask": "0.02"}], "timestamp": "1769384104801", "event_type": "price_change"}}
{"_local_timestamp": "2026-01-25T23:35:05.186067+00:00", "data": {"market": "0xdb68062324c27327e9cd4b21b1dd0deadbc4b860abb8c076b9ba3ed4652ced13", "price_changes": [{"asset_id": "70438891017239169523888340706940482203786228582885836666142245799578935372711", "price": "0.061", "size": "98.36", "side": "BUY", "hash": "2d85e70e01ea9629725aa9be5c99e93cc1c76d31", "best_bid": "0.98", "best_ask": "0.981"}, {"asset_id": "78059086946243166298250434231742381590921423205138738331803802527161013528631", "price": "0.939", "size": "98.36", "side": "SELL", "hash": "96238e9f86c5e24f4570db239c82e4a2b3a3c7ca", "best_bid": "0.019", "best_ask": "0.02"}], "timestamp": "1769384105035", "event_type": "price_change"}}
{"_local_timestamp": "2026-01-25T23:35:05.269367+00:00", "data": {"market": "0xfc6260666d020a912a87d9000eff5116d2adfb8c30aba543427a4c1f1411f1a0", "price_changes": [{"asset_id": "20615575591261238050354259319465440337102580196335623615376639598123117400036", "price": "0.69", "size": "389.75", "side": "SELL", "hash": "49f381a74a4c6c17e45a092c5575dffe8c97faba", "best_bid": "0.66", "best_ask": "0.67"}, {"asset_id": "57301498276970257025109591078431189727442302532145853906375186182281603517458", "price": "0.31", "size": "389.75", "side": "BUY", "hash": "11c6353717ab29eb482f0c2f74572377ba29ab47", "best_bid": "0.33", "best_ask": "0.34"}], "timestamp": "1769384105115", "event_type": "price_change"}}
{"_local_timestamp": "2026-01-25T23:35:05.300180+00:00", "data": {"market": "0xfc6260666d020a912a87d9000eff5116d2adfb8c30aba543427a4c1f1411f1a0", "price_changes": [{"asset_id": "20615575591261238050354259319465440337102580196335623615376639598123117400036", "price": "0.69", "size": "438.75", "side": "SELL", "hash": "c7242d24cab8f30bc47a7628e3d605f3e828bf71", "best_bid": "0.66", "best_ask": "0.67"}, {"asset_id": "57301498276970257025109591078431189727442302532145853906375186182281603517458", "price": "0.31", "size": "438.75", "side": "BUY", "hash": "58a9b983a504495b75305702094ca47fe38dda06", "best_bid": "0.33", "best_ask": "0.34"}], "timestamp": "1769384105146", "event_type": "price_change"}}
{"_local_timestamp": "2026-01-25T23:35:05.422723+00:00", "data": {"market": "0xdb68062324c27327e9cd4b21b1dd0deadbc4b860abb8c076b9ba3ed4652ced13", "price_changes": [{"asset_id": "70438891017239169523888340706940482203786228582885836666142245799578935372711", "price": "0.101", "size": "59.4", "side": "BUY", "hash": "158ceb30212bb2f082a5d09617cea0e4f25a31e1", "best_bid": "0.98", "best_ask": "0.981"}, {"asset_id": "78059086946243166298250434231742381590921423205138738331803802527161013528631", "price": "0.899", "size": "59.4", "side": "SELL", "hash": "9aede9e99fd582a1e8d3bb86ac8851f5662178ac", "best_bid": "0.019", "best_ask": "0.02"}], "timestamp": "1769384105274", "event_type": "price_change"}}
{"_local_timestamp": "2026-01-25T23:35:05.625646+00:00", "data": {"market": "0xdb68062324c27327e9cd4b21b1dd0deadbc4b860abb8c076b9ba3ed4652ced13", "price_changes": [{"asset_id": "70438891017239169523888340706940482203786228582885836666142245799578935372711", "price": "0.13", "size": "0", "side": "BUY", "hash": "c9f13332dac318d760b5b4e1104551dcda1eb24a", "best_bid": "0.98", "best_ask": "0.981"}, {"asset_id": "78059086946243166298250434231742381590921423205138738331803802527161013528631", "price": "0.87", "size": "0", "side": "SELL", "hash": "005e71cd0e51ddad74e6571b56bd899864ea10b2", "best_bid": "0.019", "best_ask": "0.02"}], "timestamp": "1769384105474", "event_type": "price_change"}}
{"_local_timestamp": "2026-01-25T23:35:05.824172+00:00", "data": {"market": "0xdb68062324c27327e9cd4b21b1dd0deadbc4b860abb8c076b9ba3ed4652ced13", "price_changes": [{"asset_id": "70438891017239169523888340706940482203786228582885836666142245799578935372711", "price": "0.13", "size": "46.15", "side": "BUY", "hash": "e9343718fb1e144eed17ee2eca65b8afdd21d551", "best_bid": "0.98", "best_ask": "0.981"}, {"asset_id": "78059086946243166298250434231742381590921423205138738331803802527161013528631", "price": "0.87", "size": "46.15", "side": "SELL", "hash": "d7cf98c8ee98fe1d844c27499fe14db9d6e79399", "best_bid": "0.019", "best_ask": "0.02"}], "timestamp": "1769384105665", "event_type": "price_change"}}
{"_local_timestamp": "2026-01-25T23:35:06.049191+00:00", "data": {"market": "0xdb68062324c27327e9cd4b21b1dd0deadbc4b860abb8c076b9ba3ed4652ced13", "price_changes": [{"asset_id": "70438891017239169523888340706940482203786228582885836666142245799578935372711", "price": "0.362", "size": "0", "side": "BUY", "hash": "9dc23b937cdc2f274b4168d5c63c504902ae6383", "best_bid": "0.98", "best_ask": "0.981"}, {"asset_id": "78059086946243166298250434231742381590921423205138738331803802527161013528631", "price": "0.638", "size": "0", "side": "SELL", "hash": "40e1c2d88b5c8c76245a802173cdb4a73d15cb2b", "best_bid": "0.019", "best_ask": "0.02"}], "timestamp": "1769384105868", "event_type": "price_change"}}
{"_local_timestamp": "2026-01-25T23:35:06.294339+00:00", "data": {"market": "0xdb68062324c27327e9cd4b21b1dd0deadbc4b860abb8c076b9ba3ed4652ced13", "price_changes": [{"asset_id": "70438891017239169523888340706940482203786228582885836666142245799578935372711", "price": "0.362", "size": "16.57", "side": "BUY", "hash": "4d99f4db356b237a4dab8974133dd954b9761e5d", "best_bid": "0.98", "best_ask": "0.981"}, {"asset_id": "78059086946243166298250434231742381590921423205138738331803802527161013528631", "price": "0.638", "size": "16.57", "side": "SELL", "hash": "3b5f5af7342ae7dc7969b5fb92cf1e6d41edfd4c", "best_bid": "0.019", "best_ask": "0.02"}], "timestamp": "1769384106094", "event_type": "price_change"}}
{"_local_timestamp": "2026-01-25T23:35:06.479509+00:00", "data": {"market": "0xdb68062324c27327e9cd4b21b1dd0deadbc4b860abb8c076b9ba3ed4652ced13", "price_changes": [{"asset_id": "70438891017239169523888340706940482203786228582885836666142245799578935372711", "price": "0.401", "size": "0", "side": "BUY", "hash": "bf07ce1296ac76dc5016ddb4b28e37071ae9cca0", "best_bid": "0.98", "best_ask": "0.981"}, {"asset_id": "78059086946243166298250434231742381590921423205138738331803802527161013528631", "price": "0.599", "size": "0", "side": "SELL", "hash": "83013abd90ff1c9ee1181ed08ba4a3eb8052b4c4", "best_bid": "0.019", "best_ask": "0.02"}], "timestamp": "1769384106291", "event_type": "price_change"}}
{"_local_timestamp": "2026-01-25T23:35:06.688994+00:00", "data": {"market": "0xdb68062324c27327e9cd4b21b1dd0deadbc4b860abb8c076b9ba3ed4652ced13", "price_changes": [{"asset_id": "70438891017239169523888340706940482203786228582885836666142245799578935372711", "price": "0.401", "size": "14.96", "side": "BUY", "hash": "7aafecd847218a633fb163da77e23cd694c89101", "best_bid": "0.98", "best_ask": "0.981"}, {"asset_id": "78059086946243166298250434231742381590921423205138738331803802527161013528631", "price": "0.599", "size": "14.96", "side": "SELL", "hash": "bb8c8936c0660175f3912d0c4f11f63c70c50bed", "best_bid": "0.019", "best_ask": "0.02"}], "timestamp": "1769384106506", "event_type": "price_change"}}
{"_local_timestamp": "2026-01-25T23:35:06.782734+00:00", "data": {"market": "0xfc6260666d020a912a87d9000eff5116d2adfb8c30aba543427a4c1f1411f1a0", "price_changes": [{"asset_id": "20615575591261238050354259319465440337102580196335623615376639598123117400036", "price": "0.69", "size": "389.75", "side": "SELL", "hash": "70ec38ffadda7fa5c25bb44630f723b19e978977", "best_bid": "0.66", "best_ask": "0.67"}, {"asset_id": "57301498276970257025109591078431189727442302532145853906375186182281603517458", "price": "0.31", "size": "389.75", "side": "BUY", "hash": "e6b6179a5036b1b950a0d20e39660bab3a151109", "best_bid": "0.33", "best_ask": "0.34"}], "timestamp": "1769384106595", "event_type": "price_change"}}
{"_local_timestamp": "2026-01-25T23:35:06.805570+00:00", "data": {"market": "0xfc6260666d020a912a87d9000eff5116d2adfb8c30aba543427a4c1f1411f1a0", "price_changes": [{"asset_id": "20615575591261238050354259319465440337102580196335623615376639598123117400036", "price": "0.69", "size": "438.75", "side": "SELL", "hash": "53cc2ded476b9d0e7789f611708e136726267a3c", "best_bid": "0.66", "best_ask": "0.67"}, {"asset_id": "57301498276970257025109591078431189727442302532145853906375186182281603517458", "price": "0.31", "size": "438.75", "side": "BUY", "hash": "220156a770bd762de2329f8791be097eeba04e72", "best_bid": "0.33", "best_ask": "0.34"}], "timestamp": "1769384106623", "event_type": "price_change"}}
{"_local_timestamp": "2026-01-25T23:35:06.876043+00:00", "data": {"market": "0xdb68062324c27327e9cd4b21b1dd0deadbc4b860abb8c076b9ba3ed4652ced13", "price_changes": [{"asset_id": "70438891017239169523888340706940482203786228582885836666142245799578935372711", "price": "0.451", "size": "0", "side": "BUY", "hash": "e8f307121c2d181ea388254fcbb319ab25cfbe14", "best_bid": "0.98", "best_ask": "0.981"}, {"asset_id": "78059086946243166298250434231742381590921423205138738331803802527161013528631", "price": "0.549", "size": "0", "side": "SELL", "hash": "1de54d38239295f1a05a4cfba301cb16d8cf9223", "best_bid": "0.019", "best_ask": "0.02"}], "timestamp": "1769384106700", "event_type": "price_change"}}
{"_local_timestamp": "2026-01-25T23:35:07.116546+00:00", "data": {"market": "0xdb68062324c27327e9cd4b21b1dd0deadbc4b860abb8c076b9ba3ed4652ced13", "price_changes": [{"asset_id": "70438891017239169523888340706940482203786228582885836666142245799578935372711", "price": "0.451", "size": "13.3", "side": "BUY", "hash": "036d7d7ad0262340a0ca8f987f70bcf67e35b707", "best_bid": "0.98", "best_ask": "0.981"}, {"asset_id": "78059086946243166298250434231742381590921423205138738331803802527161013528631", "price": "0.549", "size": "13.3", "side": "SELL", "hash": "2be8dd7c5bdbf4494455c62f3e8ec6f501d4c4c7", "best_bid": "0.019", "best_ask": "0.02"}], "timestamp": "1769384106933", "event_type": "price_change"}}
{"_local_timestamp": "2026-01-25T23:35:07.320974+00:00", "data": {"market": "0xdb68062324c27327e9cd4b21b1dd0deadbc4b860abb8c076b9ba3ed4652ced13", "price_changes": [{"asset_id": "70438891017239169523888340706940482203786228582885836666142245799578935372711", "price": "0.691", "size": "0", "side": "BUY", "hash": "bd703df7d8941fca9fc11d1beeefe61104180c0b", "best_bid": "0.98", "best_ask": "0.981"}, {"asset_id": "78059086946243166298250434231742381590921423205138738331803802527161013528631", "price": "0.309", "size": "0", "side": "SELL", "hash": "1676ccd0acd54b284d9891f524fbf1263299f3e5", "best_bid": "0.019", "best_ask": "0.02"}], "timestamp": "1769384107129", "event_type": "price_change"}}
{"_local_timestamp": "2026-01-25T23:35:07.563852+00:00", "data": {"market": "0xdb68062324c27327e9cd4b21b1dd0deadbc4b860abb8c076b9ba3ed4652ced13", "price_changes": [{"asset_id": "70438891017239169523888340706940482203786228582885836666142245799578935372711", "price": "0.691", "size": "8.68", "side": "BUY", "hash": "0bed706ab9ff3ce109a2053482f7e2ef7160b4c2", "best_bid": "0.98", "best_ask": "0.981"}, {"asset_id": "78059086946243166298250434231742381590921423205138738331803802527161013528631", "price": "0.309", "size": "8.68", "side": "SELL", "hash": "ce6907ef57332eb7e726b4cd114e159161eb3d05", "best_bid": "0.019", "best_ask": "0.02"}], "timestamp": "1769384107363", "event_type": "price_change"}}
{"_local_timestamp": "2026-01-25T23:35:08.309046+00:00", "data": {"market": "0xfc6260666d020a912a87d9000eff5116d2adfb8c30aba543427a4c1f1411f1a0", "price_changes": [{"asset_id": "20615575591261238050354259319465440337102580196335623615376639598123117400036", "price": "0.69", "size": "389.75", "side": "SELL", "hash": "b6380b2127b27140271bd27bf3866a6b79125915", "best_bid": "0.66", "best_ask": "0.67"}, {"asset_id": "57301498276970257025109591078431189727442302532145853906375186182281603517458", "price": "0.31", "size": "389.75", "side": "BUY", "hash": "9033b830b8d6f6afbcdeaebe0e931f54b6b2e279", "best_bid": "0.33", "best_ask": "0.34"}], "timestamp": "1769384108097", "event_type": "price_change"}}
{"_local_timestamp": "2026-01-25T23:35:08.323882+00:00", "data": {"market": "0xfc6260666d020a912a87d9000eff5116d2adfb8c30aba543427a4c1f1411f1a0", "price_changes": [{"asset_id": "20615575591261238050354259319465440337102580196335623615376639598123117400036", "price": "0.69", "size": "438.75", "side": "SELL", "hash": "f96466726fa817ac53252c36ba15cbf59a91bde2", "best_bid": "0.66", "best_ask": "0.67"}, {"asset_id": "57301498276970257025109591078431189727442302532145853906375186182281603517458", "price": "0.31", "size": "438.75", "side": "BUY", "hash": "87ea6055bfae2f0d3cc25a8cc7e8b948d0f81a96", "best_bid": "0.33", "best_ask": "0.34"}], "timestamp": "1769384108126", "event_type": "price_change"}}
{"_local_timestamp": "2026-01-25T23:35:09.804183+00:00", "data": {"market": "0xfc6260666d020a912a87d9000eff5116d2adfb8c30aba543427a4c1f1411f1a0", "price_changes": [{"asset_id": "20615575591261238050354259319465440337102580196335623615376639598123117400036", "price": "0.69", "size": "389.75", "side": "SELL", "hash": "7e2e793333db6a6ba658cb4d051b85ae68ff3cae", "best_bid": "0.66", "best_ask": "0.67"}, {"asset_id": "57301498276970257025109591078431189727442302532145853906375186182281603517458", "price": "0.31", "size": "389.75", "side": "BUY", "hash": "7ce39dee1f9f3e2a8c60c49202a9e282871391d9", "best_bid": "0.33", "best_ask": "0.34"}], "timestamp": "1769384109596", "event_type": "price_change"}}
{"_local_timestamp": "2026-01-25T23:35:09.830454+00:00", "data": {"market": "0xfc6260666d020a912a87d9000eff5116d2adfb8c30aba543427a4c1f1411f1a0", "price_changes": [{"asset_id": "20615575591261238050354259319465440337102580196335623615376639598123117400036", "price": "0.69", "size": "438.75", "side": "SELL", "hash": "d6fb430d4e466d0e4b94d6504787b92e34b624af", "best_bid": "0.66", "best_ask": "0.67"}, {"asset_id": "57301498276970257025109591078431189727442302532145853906375186182281603517458", "price": "0.31", "size": "438.75", "side": "BUY", "hash": "9cb3caedb3fdec6db3f8d5dc34b4428b4851cadb", "best_bid": "0.33", "best_ask": "0.34"}], "timestamp": "1769384109621", "event_type": "price_change"}}
{"_local_timestamp": "2026-01-25T23:35:11.296215+00:00", "data": {"market": "0xfc6260666d020a912a87d9000eff5116d2adfb8c30aba543427a4c1f1411f1a0", "price_changes": [{"asset_id": "20615575591261238050354259319465440337102580196335623615376639598123117400036", "price": "0.69", "size": "389.75", "side": "SELL", "hash": "c669891383033dc4510e34a7c9dc0392f655c52e", "best_bid": "0.66", "best_ask": "0.67"}, {"asset_id": "57301498276970257025109591078431189727442302532145853906375186182281603517458", "price": "0.31", "size": "389.75", "side": "BUY", "hash": "9a9ee4b55b6084c38d9156c1d06c5866e900ed9f", "best_bid": "0.33", "best_ask": "0.34"}], "timestamp": "1769384111094", "event_type": "price_change"}}
{"_local_timestamp": "2026-01-25T23:35:11.327563+00:00", "data": {"market": "0xfc6260666d020a912a87d9000eff5116d2adfb8c30aba543427a4c1f1411f1a0", "price_changes": [{"asset_id": "20615575591261238050354259319465440337102580196335623615376639598123117400036", "price": "0.69", "size": "438.75", "side": "SELL", "hash": "8a55a6d79600ace3b44639e5b3346461406e5486", "best_bid": "0.66", "best_ask": "0.67"}, {"asset_id": "57301498276970257025109591078431189727442302532145853906375186182281603517458", "price": "0.31", "size": "438.75", "side": "BUY", "hash": "ca2d4f43f9705f510711659b66183695a053efc6", "best_bid": "0.33", "best_ask": "0.34"}], "timestamp": "1769384111122", "event_type": "price_change"}}
{"_local_timestamp": "2026-01-25T23:35:12.805663+00:00", "data": {"market": "0xfc6260666d020a912a87d9000eff5116d2adfb8c30aba543427a4c1f1411f1a0", "price_changes": [{"asset_id": "20615575591261238050354259319465440337102580196335623615376639598123117400036", "price": "0.69", "size": "389.75", "side": "SELL", "hash": "e035613a2a160fe1b93052d62aa226d7c60fff22", "best_bid": "0.66", "best_ask": "0.67"}, {"asset_id": "57301498276970257025109591078431189727442302532145853906375186182281603517458", "price": "0.31", "size": "389.75", "side": "BUY", "hash": "0d6b3ff2bfa345d00a26d89dcb08d05456dfd0ad", "best_bid": "0.33", "best_ask": "0.34"}], "timestamp": "1769384112595", "event_type": "price_change"}}
{"_local_timestamp": "2026-01-25T23:35:12.823160+00:00", "data": {"market": "0xfc6260666d020a912a87d9000eff5116d2adfb8c30aba543427a4c1f1411f1a0", "price_changes": [{"asset_id": "20615575591261238050354259319465440337102580196335623615376639598123117400036", "price": "0.69", "size": "438.75", "side": "SELL", "hash": "a2c3c88555a30f3857303752812538fcb515182b", "best_bid": "0.66", "best_ask": "0.67"}, {"asset_id": "57301498276970257025109591078431189727442302532145853906375186182281603517458", "price": "0.31", "size": "438.75", "side": "BUY", "hash": "d231d806b63c964d8eca8e4b9e896512433e966e", "best_bid": "0.33", "best_ask": "0.34"}], "timestamp": "1769384112624", "event_type": "price_change"}}
{"_local_timestamp": "2026-01-25T23:35:14.304179+00:00", "data": {"market": "0xfc6260666d020a912a87d9000eff5116d2adfb8c30aba543427a4c1f1411f1a0", "price_changes": [{"asset_id": "20615575591261238050354259319465440337102580196335623615376639598123117400036", "price": "0.69", "size": "389.75", "side": "SELL", "hash": "b32d46bf50bf80c5eb445f32221fcca6e5cb5e6d", "best_bid": "0.66", "best_ask": "0.67"}, {"asset_id": "57301498276970257025109591078431189727442302532145853906375186182281603517458", "price": "0.31", "size": "389.75", "side": "BUY", "hash": "4865c6b1aa6a2261864163bfea0ee0487c1b654b", "best_bid": "0.33", "best_ask": "0.34"}], "timestamp": "1769384114099", "event_type": "price_change"}}
{"_local_timestamp": "2026-01-25T23:35:14.335867+00:00", "data": {"market": "0xfc6260666d020a912a87d9000eff5116d2adfb8c30aba543427a4c1f1411f1a0", "price_changes": [{"asset_id": "20615575591261238050354259319465440337102580196335623615376639598123117400036", "price": "0.69", "size": "438.75", "side": "SELL", "hash": "0f7ea11bdd0b33d38e80ce7dd4c61b7d946e78a6", "best_bid": "0.66", "best_ask": "0.67"}, {"asset_id": "57301498276970257025109591078431189727442302532145853906375186182281603517458", "price": "0.31", "size": "438.75", "side": "BUY", "hash": "b48b7af3c2fc866ae1c016e5efc57a5a00957613", "best_bid": "0.33", "best_ask": "0.34"}], "timestamp": "1769384114132", "event_type": "price_change"}}
{"_local_timestamp": "2026-01-25T23:35:15.815352+00:00", "data": {"market": "0xfc6260666d020a912a87d9000eff5116d2adfb8c30aba543427a4c1f1411f1a0", "price_changes": [{"asset_id": "20615575591261238050354259319465440337102580196335623615376639598123117400036", "price": "0.69", "size": "389.75", "side": "SELL", "hash": "84694efcacd58cced61fce8453b9918cc9395e34", "best_bid": "0.66", "best_ask": "0.67"}, {"asset_id": "57301498276970257025109591078431189727442302532145853906375186182281603517458", "price": "0.31", "size": "389.75", "side": "BUY", "hash": "dd9017bf9bbdc3804c9e1433d39f81e923f6ee6a", "best_bid": "0.33", "best_ask": "0.34"}], "timestamp": "1769384115600", "event_type": "price_change"}}
{"_local_timestamp": "2026-01-25T23:35:15.839473+00:00", "data": {"market": "0xfc6260666d020a912a87d9000eff5116d2adfb8c30aba543427a4c1f1411f1a0", "price_changes": [{"asset_id": "20615575591261238050354259319465440337102580196335623615376639598123117400036", "price": "0.69", "size": "438.75", "side": "SELL", "hash": "ab04ee4c0b2381fcd34f09e2731c64d897df1bce", "best_bid": "0.66", "best_ask": "0.67"}, {"asset_id": "57301498276970257025109591078431189727442302532145853906375186182281603517458", "price": "0.31", "size": "438.75", "side": "BUY", "hash": "fbe8adedc4a6309069312da45c13a6401891724a", "best_bid": "0.33", "best_ask": "0.34"}], "timestamp": "1769384115628", "event_type": "price_change"}}
{"_local_timestamp": "2026-01-25T23:35:17.319027+00:00", "data": {"market": "0xfc6260666d020a912a87d9000eff5116d2adfb8c30aba543427a4c1f1411f1a0", "price_changes": [{"asset_id": "20615575591261238050354259319465440337102580196335623615376639598123117400036", "price": "0.69", "size": "389.75", "side": "SELL", "hash": "5dbc9d4f9108f1d5872fee705f02eed099f29176", "best_bid": "0.66", "best_ask": "0.67"}, {"asset_id": "57301498276970257025109591078431189727442302532145853906375186182281603517458", "price": "0.31", "size": "389.75", "side": "BUY", "hash": "8986510bcc3d58d48ccf999bf8bbbb5ff114ffc9", "best_bid": "0.33", "best_ask": "0.34"}], "timestamp": "1769384117095", "event_type": "price_change"}}
{"_local_timestamp": "2026-01-25T23:35:17.351191+00:00", "data": {"market": "0xfc6260666d020a912a87d9000eff5116d2adfb8c30aba543427a4c1f1411f1a0", "price_changes": [{"asset_id": "20615575591261238050354259319465440337102580196335623615376639598123117400036", "price": "0.69", "size": "438.75", "side": "SELL", "hash": "155b80ba6cd7da0b2eb26c428884c6b5f9d2cd3c", "best_bid": "0.66", "best_ask": "0.67"}, {"asset_id": "57301498276970257025109591078431189727442302532145853906375186182281603517458", "price": "0.31", "size": "438.75", "side": "BUY", "hash": "26e1a109e6d7fd066586a1225fc439116ae820da", "best_bid": "0.33", "best_ask": "0.34"}], "timestamp": "1769384117120", "event_type": "price_change"}}
{"_local_timestamp": "2026-01-25T23:35:18.811257+00:00", "data": {"market": "0xfc6260666d020a912a87d9000eff5116d2adfb8c30aba543427a4c1f1411f1a0", "price_changes": [{"asset_id": "20615575591261238050354259319465440337102580196335623615376639598123117400036", "price": "0.69", "size": "389.75", "side": "SELL", "hash": "6825df37112ba1c828d0849c5d393fc23777ee7c", "best_bid": "0.66", "best_ask": "0.67"}, {"asset_id": "57301498276970257025109591078431189727442302532145853906375186182281603517458", "price": "0.31", "size": "389.75", "side": "BUY", "hash": "207756232a8c6360fb2ef01ca6cb45d8dcb24d00", "best_bid": "0.33", "best_ask": "0.34"}], "timestamp": "1769384118593", "event_type": "price_change"}}
{"_local_timestamp": "2026-01-25T23:35:18.837722+00:00", "data": {"market": "0xfc6260666d020a912a87d9000eff5116d2adfb8c30aba543427a4c1f1411f1a0", "price_changes": [{"asset_id": "20615575591261238050354259319465440337102580196335623615376639598123117400036", "price": "0.69", "size": "438.75", "side": "SELL", "hash": "446fec8aacd51a233b1bf56008989517c6bf8739", "best_bid": "0.66", "best_ask": "0.67"}, {"asset_id": "57301498276970257025109591078431189727442302532145853906375186182281603517458", "price": "0.31", "size": "438.75", "side": "BUY", "hash": "2b2e524cca3b8d9cc521faff72ea1ed6163d99ff", "best_bid": "0.33", "best_ask": "0.34"}], "timestamp": "1769384118619", "event_type": "price_change"}}
{"_local_timestamp": "2026-01-25T23:35:20.317060+00:00", "data": {"market": "0xfc6260666d020a912a87d9000eff5116d2adfb8c30aba543427a4c1f1411f1a0", "price_changes": [{"asset_id": "20615575591261238050354259319465440337102580196335623615376639598123117400036", "price": "0.69", "size": "389.75", "side": "SELL", "hash": "235c4ad63180bf866fa648f486c4d25eb8a3f91e", "best_bid": "0.66", "best_ask": "0.67"}, {"asset_id": "57301498276970257025109591078431189727442302532145853906375186182281603517458", "price": "0.31", "size": "389.75", "side": "BUY", "hash": "f5cc9beb069a4358626bcc9132cd5450912f3bb3", "best_bid": "0.33", "best_ask": "0.34"}], "timestamp": "1769384120093", "event_type": "price_change"}}
{"_local_timestamp": "2026-01-25T23:35:20.347246+00:00", "data": {"market": "0xfc6260666d020a912a87d9000eff5116d2adfb8c30aba543427a4c1f1411f1a0", "price_changes": [{"asset_id": "20615575591261238050354259319465440337102580196335623615376639598123117400036", "price": "0.69", "size": "438.75", "side": "SELL", "hash": "08a85a2cf80826f7a87729d7c85ee80749491453", "best_bid": "0.66", "best_ask": "0.67"}, {"asset_id": "57301498276970257025109591078431189727442302532145853906375186182281603517458", "price": "0.31", "size": "438.75", "side": "BUY", "hash": "1898183fe5b2ad4a0fb4adcea849c63e3153a5d8", "best_bid": "0.33", "best_ask": "0.34"}], "timestamp": "1769384120121", "event_type": "price_change"}}
{"_local_timestamp": "2026-01-25T23:35:21.793520+00:00", "data": {"market": "0xfc6260666d020a912a87d9000eff5116d2adfb8c30aba543427a4c1f1411f1a0", "price_changes": [{"asset_id": "20615575591261238050354259319465440337102580196335623615376639598123117400036", "price": "0.69", "size": "389.75", "side": "SELL", "hash": "90a852a5cb46312f8fc0e0d80ffd59dd14a8b9e2", "best_bid": "0.66", "best_ask": "0.67"}, {"asset_id": "57301498276970257025109591078431189727442302532145853906375186182281603517458", "price": "0.31", "size": "389.75", "side": "BUY", "hash": "3fe5094044726f3600f6f2b918c3f78dbcd76b54", "best_bid": "0.33", "best_ask": "0.34"}], "timestamp": "1769384121593", "event_type": "price_change"}}
{"_local_timestamp": "2026-01-25T23:35:21.820031+00:00", "data": {"market": "0xfc6260666d020a912a87d9000eff5116d2adfb8c30aba543427a4c1f1411f1a0", "price_changes": [{"asset_id": "20615575591261238050354259319465440337102580196335623615376639598123117400036", "price": "0.69", "size": "438.75", "side": "SELL", "hash": "401751c43ca4b484c591a43fa0bf062f4092697e", "best_bid": "0.66", "best_ask": "0.67"}, {"asset_id": "57301498276970257025109591078431189727442302532145853906375186182281603517458", "price": "0.31", "size": "438.75", "side": "BUY", "hash": "f8823630f547e7f46f78d4cc043568ac988b4659", "best_bid": "0.33", "best_ask": "0.34"}], "timestamp": "1769384121620", "event_type": "price_change"}}
{"_local_timestamp": "2026-01-25T23:35:23.313569+00:00", "data": {"market": "0xfc6260666d020a912a87d9000eff5116d2adfb8c30aba543427a4c1f1411f1a0", "price_changes": [{"asset_id": "20615575591261238050354259319465440337102580196335623615376639598123117400036", "price": "0.69", "size": "389.75", "side": "SELL", "hash": "f57a5541518c8b65c01e3b38385437b212609468", "best_bid": "0.66", "best_ask": "0.67"}, {"asset_id": "57301498276970257025109591078431189727442302532145853906375186182281603517458", "price": "0.31", "size": "389.75", "side": "BUY", "hash": "c6293a122930b5818497d36328865f26f5c7dafc", "best_bid": "0.33", "best_ask": "0.34"}], "timestamp": "1769384123094", "event_type": "price_change"}}
{"_local_timestamp": "2026-01-25T23:35:23.325669+00:00", "data": {"market": "0xfc6260666d020a912a87d9000eff5116d2adfb8c30aba543427a4c1f1411f1a0", "price_changes": [{"asset_id": "20615575591261238050354259319465440337102580196335623615376639598123117400036", "price": "0.69", "size": "438.75", "side": "SELL", "hash": "1a10160881457e0a0ff29c88cb421c6cf51606d0", "best_bid": "0.66", "best_ask": "0.67"}, {"asset_id": "57301498276970257025109591078431189727442302532145853906375186182281603517458", "price": "0.31", "size": "438.75", "side": "BUY", "hash": "cdfcf58661e7488bad51e601033286a92a0f2aa0", "best_bid": "0.33", "best_ask": "0.34"}], "timestamp": "1769384123121", "event_type": "price_change"}}
{"_local_timestamp": "2026-01-25T23:35:24.922204+00:00", "data": {"market": "0xfc6260666d020a912a87d9000eff5116d2adfb8c30aba543427a4c1f1411f1a0", "price_changes": [{"asset_id": "20615575591261238050354259319465440337102580196335623615376639598123117400036", "price": "0.69", "size": "389.75", "side": "SELL", "hash": "95bc7d600adb6630989b02edc5eed61a79e7df27", "best_bid": "0.66", "best_ask": "0.67"}, {"asset_id": "57301498276970257025109591078431189727442302532145853906375186182281603517458", "price": "0.31", "size": "389.75", "side": "BUY", "hash": "b0f133a1070e010fa5bdb8bacc16df7b229dee39", "best_bid": "0.33", "best_ask": "0.34"}], "timestamp": "1769384124608", "event_type": "price_change"}}
{"_local_timestamp": "2026-01-25T23:35:24.962273+00:00", "data": {"market": "0xfc6260666d020a912a87d9000eff5116d2adfb8c30aba543427a4c1f1411f1a0", "price_changes": [{"asset_id": "20615575591261238050354259319465440337102580196335623615376639598123117400036", "price": "0.69", "size": "438.75", "side": "SELL", "hash": "629f938fa5061678821d5a7536c4c591cba67b28", "best_bid": "0.66", "best_ask": "0.67"}, {"asset_id": "57301498276970257025109591078431189727442302532145853906375186182281603517458", "price": "0.31", "size": "438.75", "side": "BUY", "hash": "00272195424bdef3dd1c66489d2794d334215528", "best_bid": "0.33", "best_ask": "0.34"}], "timestamp": "1769384124635", "event_type": "price_change"}}
{"_local_timestamp": "2026-01-25T23:35:25.300744+00:00", "data": {"market": "0xb2abfc4e48334d87681240cd6a7e63c728e13973fbd68951b45bc86d6c4491e4", "price_changes": [{"asset_id": "18210569213780052033306952138558054016080325272524745338190244466404715123630", "price": "0.003", "size": "49.62", "side": "BUY", "hash": "ece8d143bb1a9dab82bf1b27bd2fc36907bf7123", "best_bid": "0.043", "best_ask": "0.053"}, {"asset_id": "82149110067979470707461735036792617981060265491561473691799265056474452809853", "price": "0.997", "size": "49.62", "side": "SELL", "hash": "dd07dfa934dc9eb5804fe7c97ee714e38a4bcdb1", "best_bid": "0.947", "best_ask": "0.957"}], "timestamp": "1769384125097", "event_type": "price_change"}}
{"_local_timestamp": "2026-01-25T23:35:25.640298+00:00", "data": {"market": "0xb2abfc4e48334d87681240cd6a7e63c728e13973fbd68951b45bc86d6c4491e4", "price_changes": [{"asset_id": "18210569213780052033306952138558054016080325272524745338190244466404715123630", "price": "0.003", "size": "77.33", "side": "BUY", "hash": "13812c96db257f4780825dcbb6cfc98ed85d1e43", "best_bid": "0.043", "best_ask": "0.053"}, {"asset_id": "82149110067979470707461735036792617981060265491561473691799265056474452809853", "price": "0.997", "size": "77.33", "side": "SELL", "hash": "13154d7bc83774bcc1ae7d868c1c4bffd1daf201", "best_bid": "0.947", "best_ask": "0.957"}], "timestamp": "1769384125426", "event_type": "price_change"}}
{"_local_timestamp": "2026-01-25T23:35:26.297779+00:00", "data": {"market": "0xfc6260666d020a912a87d9000eff5116d2adfb8c30aba543427a4c1f1411f1a0", "price_changes": [{"asset_id": "20615575591261238050354259319465440337102580196335623615376639598123117400036", "price": "0.69", "size": "389.75", "side": "SELL", "hash": "0e5b0e5d91515a446e1ecaa8f379454dcd7981e7", "best_bid": "0.66", "best_ask": "0.67"}, {"asset_id": "57301498276970257025109591078431189727442302532145853906375186182281603517458", "price": "0.31", "size": "389.75", "side": "BUY", "hash": "0938037fc0eee1f827f4492c2364595ac425ad3f", "best_bid": "0.33", "best_ask": "0.34"}], "timestamp": "1769384126094", "event_type": "price_change"}}
{"_local_timestamp": "2026-01-25T23:35:26.331433+00:00", "data": {"market": "0xfc6260666d020a912a87d9000eff5116d2adfb8c30aba543427a4c1f1411f1a0", "price_changes": [{"asset_id": "20615575591261238050354259319465440337102580196335623615376639598123117400036", "price": "0.69", "size": "438.75", "side": "SELL", "hash": "2f0c39bbcf0a814fc98f8345b06dc88b23794f8d", "best_bid": "0.66", "best_ask": "0.67"}, {"asset_id": "57301498276970257025109591078431189727442302532145853906375186182281603517458", "price": "0.31", "size": "438.75", "side": "BUY", "hash": "d0bacd85acb35c44716775ffe8b7a5ce8c858cad", "best_bid": "0.33", "best_ask": "0.34"}], "timestamp": "1769384126123", "event_type": "price_change"}}
{"_local_timestamp": "2026-01-25T23:35:27.818897+00:00", "data": {"market": "0xfc6260666d020a912a87d9000eff5116d2adfb8c30aba543427a4c1f1411f1a0", "price_changes": [{"asset_id": "20615575591261238050354259319465440337102580196335623615376639598123117400036", "price": "0.69", "size": "389.75", "side": "SELL", "hash": "3c6b97198c540164a98ada4acd7db0f9674ed422", "best_bid": "0.66", "best_ask": "0.67"}, {"asset_id": "57301498276970257025109591078431189727442302532145853906375186182281603517458", "price": "0.31", "size": "389.75", "side": "BUY", "hash": "8627a83803c3d1764314fe714b2bda11423634c6", "best_bid": "0.33", "best_ask": "0.34"}], "timestamp": "1769384127595", "event_type": "price_change"}}
{"_local_timestamp": "2026-01-25T23:35:27.852285+00:00", "data": {"market": "0xfc6260666d020a912a87d9000eff5116d2adfb8c30aba543427a4c1f1411f1a0", "price_changes": [{"asset_id": "20615575591261238050354259319465440337102580196335623615376639598123117400036", "price": "0.69", "size": "438.75", "side": "SELL", "hash": "b0cae76183bde020e384cc237df0edab16d5748d", "best_bid": "0.66", "best_ask": "0.67"}, {"asset_id": "57301498276970257025109591078431189727442302532145853906375186182281603517458", "price": "0.31", "size": "438.75", "side": "BUY", "hash": "9925991f6f2a611a0e65c6acd2adaba93a580e92", "best_bid": "0.33", "best_ask": "0.34"}], "timestamp": "1769384127622", "event_type": "price_change"}}
{"_local_timestamp": "2026-01-25T23:35:29.312124+00:00", "data": {"market": "0xfc6260666d020a912a87d9000eff5116d2adfb8c30aba543427a4c1f1411f1a0", "price_changes": [{"asset_id": "20615575591261238050354259319465440337102580196335623615376639598123117400036", "price": "0.69", "size": "389.75", "side": "SELL", "hash": "a6c7e6ec6f0d0428a41117368f9dfc905db8976a", "best_bid": "0.66", "best_ask": "0.67"}, {"asset_id": "57301498276970257025109591078431189727442302532145853906375186182281603517458", "price": "0.31", "size": "389.75", "side": "BUY", "hash": "5d4411230c7400fd111e1f12545c6030d89e45f4", "best_bid": "0.33", "best_ask": "0.34"}], "timestamp": "1769384129093", "event_type": "price_change"}}
{"_local_timestamp": "2026-01-25T23:35:29.335290+00:00", "data": {"market": "0xfc6260666d020a912a87d9000eff5116d2adfb8c30aba543427a4c1f1411f1a0", "price_changes": [{"asset_id": "20615575591261238050354259319465440337102580196335623615376639598123117400036", "price": "0.69", "size": "438.75", "side": "SELL", "hash": "c8dfedf664c0587e0ce228eb23e18f0feb16d3c6", "best_bid": "0.66", "best_ask": "0.67"}, {"asset_id": "57301498276970257025109591078431189727442302532145853906375186182281603517458", "price": "0.31", "size": "438.75", "side": "BUY", "hash": "2a8148cdeedeb7fefe3be7d4e7fc63bfb4a28d2e", "best_bid": "0.33", "best_ask": "0.34"}], "timestamp": "1769384129120", "event_type": "price_change"}}
{"_local_timestamp": "2026-01-25T23:35:30.837065+00:00", "data": {"market": "0xfc6260666d020a912a87d9000eff5116d2adfb8c30aba543427a4c1f1411f1a0", "price_changes": [{"asset_id": "20615575591261238050354259319465440337102580196335623615376639598123117400036", "price": "0.69", "size": "389.75", "side": "SELL", "hash": "d4d0b7504d7b1b3a07d546da76eabec686fb470c", "best_bid": "0.66", "best_ask": "0.67"}, {"asset_id": "57301498276970257025109591078431189727442302532145853906375186182281603517458", "price": "0.31", "size": "389.75", "side": "BUY", "hash": "6a603b32b57e20a46699e005a3aa3e12377db126", "best_bid": "0.33", "best_ask": "0.34"}], "timestamp": "1769384130596", "event_type": "price_change"}}
{"_local_timestamp": "2026-01-25T23:35:30.852364+00:00", "data": {"market": "0xfc6260666d020a912a87d9000eff5116d2adfb8c30aba543427a4c1f1411f1a0", "price_changes": [{"asset_id": "20615575591261238050354259319465440337102580196335623615376639598123117400036", "price": "0.69", "size": "438.75", "side": "SELL", "hash": "bcbe4045d3066f407d31baca2b10e3b4a43df725", "best_bid": "0.66", "best_ask": "0.67"}, {"asset_id": "57301498276970257025109591078431189727442302532145853906375186182281603517458", "price": "0.31", "size": "438.75", "side": "BUY", "hash": "00e4998ba295984dfaa8614871b75af6067a7346", "best_bid": "0.33", "best_ask": "0.34"}], "timestamp": "1769384130624", "event_type": "price_change"}}
{"_local_timestamp": "2026-01-25T23:35:32.318867+00:00", "data": {"market": "0xfc6260666d020a912a87d9000eff5116d2adfb8c30aba543427a4c1f1411f1a0", "price_changes": [{"asset_id": "20615575591261238050354259319465440337102580196335623615376639598123117400036", "price": "0.69", "size": "389.75", "side": "SELL", "hash": "b8c05d83369a641feefc2cfe079f9ee83dc38889", "best_bid": "0.66", "best_ask": "0.67"}, {"asset_id": "57301498276970257025109591078431189727442302532145853906375186182281603517458", "price": "0.31", "size": "389.75", "side": "BUY", "hash": "1272d4612a85fc62a3bcf2dd48ceabbed10602a1", "best_bid": "0.33", "best_ask": "0.34"}], "timestamp": "1769384132094", "event_type": "price_change"}}
{"_local_timestamp": "2026-01-25T23:35:32.350214+00:00", "data": {"market": "0xfc6260666d020a912a87d9000eff5116d2adfb8c30aba543427a4c1f1411f1a0", "price_changes": [{"asset_id": "20615575591261238050354259319465440337102580196335623615376639598123117400036", "price": "0.69", "size": "438.75", "side": "SELL", "hash": "4cba3f682f047322174b205d4486cd9c33d2a73b", "best_bid": "0.66", "best_ask": "0.67"}, {"asset_id": "57301498276970257025109591078431189727442302532145853906375186182281603517458", "price": "0.31", "size": "438.75", "side": "BUY", "hash": "57e86d60413e4d900d604cf84341431acc5cc54d", "best_bid": "0.33", "best_ask": "0.34"}], "timestamp": "1769384132119", "event_type": "price_change"}}
{"_local_timestamp": "2026-01-25T23:35:33.803771+00:00", "data": {"market": "0xfc6260666d020a912a87d9000eff5116d2adfb8c30aba543427a4c1f1411f1a0", "price_changes": [{"asset_id": "20615575591261238050354259319465440337102580196335623615376639598123117400036", "price": "0.69", "size": "389.75", "side": "SELL", "hash": "125ffec1c44864cc21264a31abb15ec3966aa632", "best_bid": "0.66", "best_ask": "0.67"}, {"asset_id": "57301498276970257025109591078431189727442302532145853906375186182281603517458", "price": "0.31", "size": "389.75", "side": "BUY", "hash": "3cf297474c50cfe4abb9e8db5a136fb886926fab", "best_bid": "0.33", "best_ask": "0.34"}], "timestamp": "1769384133594", "event_type": "price_change"}}
{"_local_timestamp": "2026-01-25T23:35:33.827255+00:00", "data": {"market": "0xfc6260666d020a912a87d9000eff5116d2adfb8c30aba543427a4c1f1411f1a0", "price_changes": [{"asset_id": "20615575591261238050354259319465440337102580196335623615376639598123117400036", "price": "0.69", "size": "438.75", "side": "SELL", "hash": "c8d4d5b0aa8aad32f5f2a198478dedfbeac71d95", "best_bid": "0.66", "best_ask": "0.67"}, {"asset_id": "57301498276970257025109591078431189727442302532145853906375186182281603517458", "price": "0.31", "size": "438.75", "side": "BUY", "hash": "bba91c75ad393e5319e7441ae743687ed6036acd", "best_bid": "0.33", "best_ask": "0.34"}], "timestamp": "1769384133622", "event_type": "price_change"}}
{"_local_timestamp": "2026-01-25T23:35:35.356091+00:00", "data": {"market": "0xfc6260666d020a912a87d9000eff5116d2adfb8c30aba543427a4c1f1411f1a0", "price_changes": [{"asset_id": "20615575591261238050354259319465440337102580196335623615376639598123117400036", "price": "0.69", "size": "389.75", "side": "SELL", "hash": "5e177288107f00b4e818ad4a0a4c50a304648d1a", "best_bid": "0.66", "best_ask": "0.67"}, {"asset_id": "57301498276970257025109591078431189727442302532145853906375186182281603517458", "price": "0.31", "size": "389.75", "side": "BUY", "hash": "6f479055ff01afbae7a49aaac400a564a8839655", "best_bid": "0.33", "best_ask": "0.34"}], "timestamp": "1769384135100", "event_type": "price_change"}}
{"_local_timestamp": "2026-01-25T23:35:35.376526+00:00", "data": {"market": "0xfc6260666d020a912a87d9000eff5116d2adfb8c30aba543427a4c1f1411f1a0", "price_changes": [{"asset_id": "20615575591261238050354259319465440337102580196335623615376639598123117400036", "price": "0.69", "size": "438.75", "side": "SELL", "hash": "3e7094a851085213cb70c50c8b82cdc8ce4ec2c9", "best_bid": "0.66", "best_ask": "0.67"}, {"asset_id": "57301498276970257025109591078431189727442302532145853906375186182281603517458", "price": "0.31", "size": "438.75", "side": "BUY", "hash": "d81d8c13ca6dab82c3fd2bf49309e0c885f88f2f", "best_bid": "0.33", "best_ask": "0.34"}], "timestamp": "1769384135142", "event_type": "price_change"}}
{"_local_timestamp": "2026-01-25T23:35:36.799862+00:00", "data": {"market": "0xfc6260666d020a912a87d9000eff5116d2adfb8c30aba543427a4c1f1411f1a0", "price_changes": [{"asset_id": "20615575591261238050354259319465440337102580196335623615376639598123117400036", "price": "0.69", "size": "389.75", "side": "SELL", "hash": "b283ffeb6e8caced1cbad5fcfd7d4fd0b8709399", "best_bid": "0.66", "best_ask": "0.67"}, {"asset_id": "57301498276970257025109591078431189727442302532145853906375186182281603517458", "price": "0.31", "size": "389.75", "side": "BUY", "hash": "d0f10343140e3c829d97a538e2303ab069b9f587", "best_bid": "0.33", "best_ask": "0.34"}], "timestamp": "1769384136593", "event_type": "price_change"}}
{"_local_timestamp": "2026-01-25T23:35:36.829321+00:00", "data": {"market": "0xfc6260666d020a912a87d9000eff5116d2adfb8c30aba543427a4c1f1411f1a0", "price_changes": [{"asset_id": "20615575591261238050354259319465440337102580196335623615376639598123117400036", "price": "0.69", "size": "438.75", "side": "SELL", "hash": "808f24b881dfe479b6040ebb951b1976433696dc", "best_bid": "0.66", "best_ask": "0.67"}, {"asset_id": "57301498276970257025109591078431189727442302532145853906375186182281603517458", "price": "0.31", "size": "438.75", "side": "BUY", "hash": "8d34468653cedbfa8a47db9839a61cc478ab7c7b", "best_bid": "0.33", "best_ask": "0.34"}], "timestamp": "1769384136622", "event_type": "price_change"}}
{"_local_timestamp": "2026-01-25T23:35:38.210553+00:00", "data": {"market": "0xfc6260666d020a912a87d9000eff5116d2adfb8c30aba543427a4c1f1411f1a0", "price_changes": [{"asset_id": "20615575591261238050354259319465440337102580196335623615376639598123117400036", "price": "0.69", "size": "389.75", "side": "SELL", "hash": "491b2ff6dbdc5547a70a1395a99679bc3d0de71b", "best_bid": "0.66", "best_ask": "0.67"}, {"asset_id": "57301498276970257025109591078431189727442302532145853906375186182281603517458", "price": "0.31", "size": "389.75", "side": "BUY", "hash": "b7ec8c241369738298aad27dd9fadeb5a91ea33d", "best_bid": "0.33", "best_ask": "0.34"}], "timestamp": "1769384138093", "event_type": "price_change"}}
{"_local_timestamp": "2026-01-25T23:35:38.236559+00:00", "data": {"market": "0xfc6260666d020a912a87d9000eff5116d2adfb8c30aba543427a4c1f1411f1a0", "price_changes": [{"asset_id": "20615575591261238050354259319465440337102580196335623615376639598123117400036", "price": "0.69", "size": "438.75", "side": "SELL", "hash": "293aaa36a70fdf42ba8f121fc8aa3eb2179286d1", "best_bid": "0.66", "best_ask": "0.67"}, {"asset_id": "57301498276970257025109591078431189727442302532145853906375186182281603517458", "price": "0.31", "size": "438.75", "side": "BUY", "hash": "4c9bd7f808ae379d2490b02544e67826bb54b726", "best_bid": "0.33", "best_ask": "0.34"}], "timestamp": "1769384138118", "event_type": "price_change"}}
{"_local_timestamp": "2026-01-25T23:35:39.668026+00:00", "data": {"market": "0xfc6260666d020a912a87d9000eff5116d2adfb8c30aba543427a4c1f1411f1a0", "price_changes": [{"asset_id": "20615575591261238050354259319465440337102580196335623615376639598123117400036", "price": "0.69", "size": "389.75", "side": "SELL", "hash": "aff0fd2533753e6cb92a0f5cf5fcc7b80817ef92", "best_bid": "0.66", "best_ask": "0.67"}, {"asset_id": "57301498276970257025109591078431189727442302532145853906375186182281603517458", "price": "0.31", "size": "389.75", "side": "BUY", "hash": "1ed848d951a2d4cba3532efc3a7a98975900b582", "best_bid": "0.33", "best_ask": "0.34"}], "timestamp": "1769384139594", "event_type": "price_change"}}
{"_local_timestamp": "2026-01-25T23:35:39.682303+00:00", "data": {"market": "0xfc6260666d020a912a87d9000eff5116d2adfb8c30aba543427a4c1f1411f1a0", "price_changes": [{"asset_id": "20615575591261238050354259319465440337102580196335623615376639598123117400036", "price": "0.69", "size": "438.75", "side": "SELL", "hash": "2e19ec44d3a1c7ec3e9e145fc55595d5ea283987", "best_bid": "0.66", "best_ask": "0.67"}, {"asset_id": "57301498276970257025109591078431189727442302532145853906375186182281603517458", "price": "0.31", "size": "438.75", "side": "BUY", "hash": "1b206389189357484505b3d897c6ad72bb9690c3", "best_bid": "0.33", "best_ask": "0.34"}], "timestamp": "1769384139619", "event_type": "price_change"}}
{"_local_timestamp": "2026-01-25T23:35:41.158753+00:00", "data": {"market": "0xfc6260666d020a912a87d9000eff5116d2adfb8c30aba543427a4c1f1411f1a0", "price_changes": [{"asset_id": "20615575591261238050354259319465440337102580196335623615376639598123117400036", "price": "0.69", "size": "389.75", "side": "SELL", "hash": "96d5c3e1888576867f0d4b6ed6b24df3e445e8b1", "best_bid": "0.66", "best_ask": "0.67"}, {"asset_id": "57301498276970257025109591078431189727442302532145853906375186182281603517458", "price": "0.31", "size": "389.75", "side": "BUY", "hash": "90bb0d2deb8a7baf6bcb1dffb6a9004049c03105", "best_bid": "0.33", "best_ask": "0.34"}], "timestamp": "1769384141095", "event_type": "price_change"}}
{"_local_timestamp": "2026-01-25T23:35:41.186394+00:00", "data": {"market": "0xfc6260666d020a912a87d9000eff5116d2adfb8c30aba543427a4c1f1411f1a0", "price_changes": [{"asset_id": "20615575591261238050354259319465440337102580196335623615376639598123117400036", "price": "0.69", "size": "438.75", "side": "SELL", "hash": "6ea10dde86fff44d536fbe37efd50cd887205b38", "best_bid": "0.66", "best_ask": "0.67"}, {"asset_id": "57301498276970257025109591078431189727442302532145853906375186182281603517458", "price": "0.31", "size": "438.75", "side": "BUY", "hash": "c49f24e89aa42500b04951a9550c279233f49012", "best_bid": "0.33", "best_ask": "0.34"}], "timestamp": "1769384141122", "event_type": "price_change"}}
{"_local_timestamp": "2026-01-25T23:35:42.659451+00:00", "data": {"market": "0xfc6260666d020a912a87d9000eff5116d2adfb8c30aba543427a4c1f1411f1a0", "price_changes": [{"asset_id": "20615575591261238050354259319465440337102580196335623615376639598123117400036", "price": "0.69", "size": "389.75", "side": "SELL", "hash": "5f649c31f705765821bddfbb345f3fbf75bc107d", "best_bid": "0.66", "best_ask": "0.67"}, {"asset_id": "57301498276970257025109591078431189727442302532145853906375186182281603517458", "price": "0.31", "size": "389.75", "side": "BUY", "hash": "8ab2bddbd54d4d333a837daba00884de92cbeba1", "best_bid": "0.33", "best_ask": "0.34"}], "timestamp": "1769384142593", "event_type": "price_change"}}
{"_local_timestamp": "2026-01-25T23:35:42.687439+00:00", "data": {"market": "0xfc6260666d020a912a87d9000eff5116d2adfb8c30aba543427a4c1f1411f1a0", "price_changes": [{"asset_id": "20615575591261238050354259319465440337102580196335623615376639598123117400036", "price": "0.69", "size": "438.75", "side": "SELL", "hash": "38b418baaab2fc9cfb635995b00c6156efc5bf4a", "best_bid": "0.66", "best_ask": "0.67"}, {"asset_id": "57301498276970257025109591078431189727442302532145853906375186182281603517458", "price": "0.31", "size": "438.75", "side": "BUY", "hash": "739d9b564f20f38f56ced7b8677550be1891cfde", "best_bid": "0.33", "best_ask": "0.34"}], "timestamp": "1769384142622", "event_type": "price_change"}}
{"_local_timestamp": "2026-01-25T23:35:44.166817+00:00", "data": {"market": "0xfc6260666d020a912a87d9000eff5116d2adfb8c30aba543427a4c1f1411f1a0", "price_changes": [{"asset_id": "20615575591261238050354259319465440337102580196335623615376639598123117400036", "price": "0.69", "size": "389.75", "side": "SELL", "hash": "9b1e8ad2fb37ed87b45b3f8104c4d4f06e9085ae", "best_bid": "0.66", "best_ask": "0.67"}, {"asset_id": "57301498276970257025109591078431189727442302532145853906375186182281603517458", "price": "0.31", "size": "389.75", "side": "BUY", "hash": "540040bd4652d64c77894e0bcdd10a119888f86d", "best_bid": "0.33", "best_ask": "0.34"}], "timestamp": "1769384144097", "event_type": "price_change"}}
{"_local_timestamp": "2026-01-25T23:35:44.190674+00:00", "data": {"market": "0xfc6260666d020a912a87d9000eff5116d2adfb8c30aba543427a4c1f1411f1a0", "price_changes": [{"asset_id": "20615575591261238050354259319465440337102580196335623615376639598123117400036", "price": "0.69", "size": "438.75", "side": "SELL", "hash": "4b1851bcac88b8bdbcfce8cd1f11b91d5373412f", "best_bid": "0.66", "best_ask": "0.67"}, {"asset_id": "57301498276970257025109591078431189727442302532145853906375186182281603517458", "price": "0.31", "size": "438.75", "side": "BUY", "hash": "e86abeb338a0d92bbaf9c9d472c32250f3c31f4e", "best_bid": "0.33", "best_ask": "0.34"}], "timestamp": "1769384144126", "event_type": "price_change"}}
{"_local_timestamp": "2026-01-25T23:35:45.660461+00:00", "data": {"market": "0xfc6260666d020a912a87d9000eff5116d2adfb8c30aba543427a4c1f1411f1a0", "price_changes": [{"asset_id": "20615575591261238050354259319465440337102580196335623615376639598123117400036", "price": "0.69", "size": "389.75", "side": "SELL", "hash": "14d2a9f16f6e3663971a36dcd51ada21ecf43e07", "best_bid": "0.66", "best_ask": "0.67"}, {"asset_id": "57301498276970257025109591078431189727442302532145853906375186182281603517458", "price": "0.31", "size": "389.75", "side": "BUY", "hash": "a1595c12616176bdc2b51db9fe84a63a1f06383f", "best_bid": "0.33", "best_ask": "0.34"}], "timestamp": "1769384145594", "event_type": "price_change"}}
{"_local_timestamp": "2026-01-25T23:35:45.683324+00:00", "data": {"market": "0xfc6260666d020a912a87d9000eff5116d2adfb8c30aba543427a4c1f1411f1a0", "price_changes": [{"asset_id": "20615575591261238050354259319465440337102580196335623615376639598123117400036", "price": "0.69", "size": "438.75", "side": "SELL", "hash": "40e5df3171ec62ad654badd0c29a18217ac30d52", "best_bid": "0.66", "best_ask": "0.67"}, {"asset_id": "57301498276970257025109591078431189727442302532145853906375186182281603517458", "price": "0.31", "size": "438.75", "side": "BUY", "hash": "3404b53383c1874521518be5f1ba669c8fe8b552", "best_bid": "0.33", "best_ask": "0.34"}], "timestamp": "1769384145621", "event_type": "price_change"}}
{"_local_timestamp": "2026-01-25T23:35:47.163041+00:00", "data": {"market": "0xfc6260666d020a912a87d9000eff5116d2adfb8c30aba543427a4c1f1411f1a0", "price_changes": [{"asset_id": "20615575591261238050354259319465440337102580196335623615376639598123117400036", "price": "0.69", "size": "389.75", "side": "SELL", "hash": "ed368a09cf4101f55e36d8c1e3e22a09383da058", "best_bid": "0.66", "best_ask": "0.67"}, {"asset_id": "57301498276970257025109591078431189727442302532145853906375186182281603517458", "price": "0.31", "size": "389.75", "side": "BUY", "hash": "bcc9a746856c87910996f16a7f60d0a32b4e819b", "best_bid": "0.33", "best_ask": "0.34"}], "timestamp": "1769384147095", "event_type": "price_change"}}
{"_local_timestamp": "2026-01-25T23:35:47.191705+00:00", "data": {"market": "0xfc6260666d020a912a87d9000eff5116d2adfb8c30aba543427a4c1f1411f1a0", "price_changes": [{"asset_id": "20615575591261238050354259319465440337102580196335623615376639598123117400036", "price": "0.69", "size": "438.75", "side": "SELL", "hash": "72c8852cd4ddbd0f496cd028c91a66a80f293e9e", "best_bid": "0.66", "best_ask": "0.67"}, {"asset_id": "57301498276970257025109591078431189727442302532145853906375186182281603517458", "price": "0.31", "size": "438.75", "side": "BUY", "hash": "1cf7185e988a8751c4d440b9aed1281a34506024", "best_bid": "0.33", "best_ask": "0.34"}], "timestamp": "1769384147126", "event_type": "price_change"}}
{"_local_timestamp": "2026-01-25T23:35:48.662680+00:00", "data": {"market": "0xfc6260666d020a912a87d9000eff5116d2adfb8c30aba543427a4c1f1411f1a0", "price_changes": [{"asset_id": "20615575591261238050354259319465440337102580196335623615376639598123117400036", "price": "0.69", "size": "389.75", "side": "SELL", "hash": "dba25bdc7358eabd7f3ad5b2278a79f494a263e5", "best_bid": "0.66", "best_ask": "0.67"}, {"asset_id": "57301498276970257025109591078431189727442302532145853906375186182281603517458", "price": "0.31", "size": "389.75", "side": "BUY", "hash": "b214fae55c697f6339f5b48c2305f23427d27075", "best_bid": "0.33", "best_ask": "0.34"}], "timestamp": "1769384148594", "event_type": "price_change"}}
{"_local_timestamp": "2026-01-25T23:35:48.687447+00:00", "data": {"market": "0xfc6260666d020a912a87d9000eff5116d2adfb8c30aba543427a4c1f1411f1a0", "price_changes": [{"asset_id": "20615575591261238050354259319465440337102580196335623615376639598123117400036", "price": "0.69", "size": "438.75", "side": "SELL", "hash": "57531370ab7dea2cd08c6b2ced6e8441eaafe664", "best_bid": "0.66", "best_ask": "0.67"}, {"asset_id": "57301498276970257025109591078431189727442302532145853906375186182281603517458", "price": "0.31", "size": "438.75", "side": "BUY", "hash": "67f70fe73d58b24083547427c7dfb057dc40398d", "best_bid": "0.33", "best_ask": "0.34"}], "timestamp": "1769384148625", "event_type": "price_change"}}
{"_local_timestamp": "2026-01-25T23:35:50.171099+00:00", "data": {"market": "0xfc6260666d020a912a87d9000eff5116d2adfb8c30aba543427a4c1f1411f1a0", "price_changes": [{"asset_id": "20615575591261238050354259319465440337102580196335623615376639598123117400036", "price": "0.69", "size": "389.75", "side": "SELL", "hash": "d164b4dd03f28daf6f63329d3a5d6336bdec4a31", "best_bid": "0.66", "best_ask": "0.67"}, {"asset_id": "57301498276970257025109591078431189727442302532145853906375186182281603517458", "price": "0.31", "size": "389.75", "side": "BUY", "hash": "4089b82252fd4b2759284440c0ba6c9b68f7db6f", "best_bid": "0.33", "best_ask": "0.34"}], "timestamp": "1769384150107", "event_type": "price_change"}}
{"_local_timestamp": "2026-01-25T23:35:50.205611+00:00", "data": {"market": "0xfc6260666d020a912a87d9000eff5116d2adfb8c30aba543427a4c1f1411f1a0", "price_changes": [{"asset_id": "20615575591261238050354259319465440337102580196335623615376639598123117400036", "price": "0.69", "size": "438.75", "side": "SELL", "hash": "7c8a9f9fa8881e862c2f80eaeb321c93f9ff19de", "best_bid": "0.66", "best_ask": "0.67"}, {"asset_id": "57301498276970257025109591078431189727442302532145853906375186182281603517458", "price": "0.31", "size": "438.75", "side": "BUY", "hash": "5fcb43488fc12d1e72c39e94a6d56ccf180af826", "best_bid": "0.33", "best_ask": "0.34"}], "timestamp": "1769384150134", "event_type": "price_change"}}
{"_local_timestamp": "2026-01-25T23:35:51.664901+00:00", "data": {"market": "0xfc6260666d020a912a87d9000eff5116d2adfb8c30aba543427a4c1f1411f1a0", "price_changes": [{"asset_id": "20615575591261238050354259319465440337102580196335623615376639598123117400036", "price": "0.69", "size": "389.75", "side": "SELL", "hash": "d6dbddb906797d734aee05ce2a163023ee36f54a", "best_bid": "0.66", "best_ask": "0.67"}, {"asset_id": "57301498276970257025109591078431189727442302532145853906375186182281603517458", "price": "0.31", "size": "389.75", "side": "BUY", "hash": "4e0755a7248f59fc520ffe59545c32e7f8c866cc", "best_bid": "0.33", "best_ask": "0.34"}], "timestamp": "1769384151595", "event_type": "price_change"}}
{"_local_timestamp": "2026-01-25T23:35:51.688925+00:00", "data": {"market": "0xfc6260666d020a912a87d9000eff5116d2adfb8c30aba543427a4c1f1411f1a0", "price_changes": [{"asset_id": "20615575591261238050354259319465440337102580196335623615376639598123117400036", "price": "0.69", "size": "438.75", "side": "SELL", "hash": "7ea10aaecb456ec973db11c7dcb1c1b7a69734cb", "best_bid": "0.66", "best_ask": "0.67"}, {"asset_id": "57301498276970257025109591078431189727442302532145853906375186182281603517458", "price": "0.31", "size": "438.75", "side": "BUY", "hash": "0b230d3abdc1ae901c43b74e2c4c119eeb96eb98", "best_bid": "0.33", "best_ask": "0.34"}], "timestamp": "1769384151623", "event_type": "price_change"}}
{"_local_timestamp": "2026-01-25T23:35:53.164899+00:00", "data": {"market": "0xfc6260666d020a912a87d9000eff5116d2adfb8c30aba543427a4c1f1411f1a0", "price_changes": [{"asset_id": "20615575591261238050354259319465440337102580196335623615376639598123117400036", "price": "0.69", "size": "389.75", "side": "SELL", "hash": "74d291229e84e20925dab694866bac2d2b6bf417", "best_bid": "0.66", "best_ask": "0.67"}, {"asset_id": "57301498276970257025109591078431189727442302532145853906375186182281603517458", "price": "0.31", "size": "389.75", "side": "BUY", "hash": "d3cfe230da895eee967b7db4711f71b38a9adc8b", "best_bid": "0.33", "best_ask": "0.34"}], "timestamp": "1769384153094", "event_type": "price_change"}}
{"_local_timestamp": "2026-01-25T23:35:53.192408+00:00", "data": {"market": "0xfc6260666d020a912a87d9000eff5116d2adfb8c30aba543427a4c1f1411f1a0", "price_changes": [{"asset_id": "20615575591261238050354259319465440337102580196335623615376639598123117400036", "price": "0.69", "size": "438.75", "side": "SELL", "hash": "d1fcb9ca9073ef46189937f2d40e650cf301a02c", "best_bid": "0.66", "best_ask": "0.67"}, {"asset_id": "57301498276970257025109591078431189727442302532145853906375186182281603517458", "price": "0.31", "size": "438.75", "side": "BUY", "hash": "dc861766b2a3f69d34515db9a5734ae6421987ef", "best_bid": "0.33", "best_ask": "0.34"}], "timestamp": "1769384153121", "event_type": "price_change"}}
{"_local_timestamp": "2026-01-25T23:35:54.661466+00:00", "data": {"market": "0xfc6260666d020a912a87d9000eff5116d2adfb8c30aba543427a4c1f1411f1a0", "price_changes": [{"asset_id": "20615575591261238050354259319465440337102580196335623615376639598123117400036", "price": "0.69", "size": "389.75", "side": "SELL", "hash": "3ed454e7c646aa933ec9490cafc4fcf53eaa553b", "best_bid": "0.66", "best_ask": "0.67"}, {"asset_id": "57301498276970257025109591078431189727442302532145853906375186182281603517458", "price": "0.31", "size": "389.75", "side": "BUY", "hash": "0c0874fa454d57061256cc84589b688583ab0412", "best_bid": "0.33", "best_ask": "0.34"}], "timestamp": "1769384154594", "event_type": "price_change"}}
{"_local_timestamp": "2026-01-25T23:35:54.694392+00:00", "data": {"market": "0xfc6260666d020a912a87d9000eff5116d2adfb8c30aba543427a4c1f1411f1a0", "price_changes": [{"asset_id": "20615575591261238050354259319465440337102580196335623615376639598123117400036", "price": "0.69", "size": "438.75", "side": "SELL", "hash": "30b44a2bb0098f6c3638330163b5b96d33d609ca", "best_bid": "0.66", "best_ask": "0.67"}, {"asset_id": "57301498276970257025109591078431189727442302532145853906375186182281603517458", "price": "0.31", "size": "438.75", "side": "BUY", "hash": "d93577c82ca26e3cab3b09698de013db63c0b8ba", "best_bid": "0.33", "best_ask": "0.34"}], "timestamp": "1769384154621", "event_type": "price_change"}}
{"_local_timestamp": "2026-01-25T23:35:56.166740+00:00", "data": {"market": "0xfc6260666d020a912a87d9000eff5116d2adfb8c30aba543427a4c1f1411f1a0", "price_changes": [{"asset_id": "20615575591261238050354259319465440337102580196335623615376639598123117400036", "price": "0.69", "size": "389.75", "side": "SELL", "hash": "4ae7f8239f306948d6fee555d830ee0b358e017a", "best_bid": "0.66", "best_ask": "0.67"}, {"asset_id": "57301498276970257025109591078431189727442302532145853906375186182281603517458", "price": "0.31", "size": "389.75", "side": "BUY", "hash": "b34ca089fbfa6b4098a642ba508314eae61b93e9", "best_bid": "0.33", "best_ask": "0.34"}], "timestamp": "1769384156100", "event_type": "price_change"}}
{"_local_timestamp": "2026-01-25T23:35:56.196045+00:00", "data": {"market": "0xfc6260666d020a912a87d9000eff5116d2adfb8c30aba543427a4c1f1411f1a0", "price_changes": [{"asset_id": "20615575591261238050354259319465440337102580196335623615376639598123117400036", "price": "0.69", "size": "438.75", "side": "SELL", "hash": "3f931234315519771b7ac06b59b4bef05aabe99e", "best_bid": "0.66", "best_ask": "0.67"}, {"asset_id": "57301498276970257025109591078431189727442302532145853906375186182281603517458", "price": "0.31", "size": "438.75", "side": "BUY", "hash": "0a1430f9d6d13700f9a817770d39a50f26549acc", "best_bid": "0.33", "best_ask": "0.34"}], "timestamp": "1769384156127", "event_type": "price_change"}}
{"_local_timestamp": "2026-01-25T23:35:57.674672+00:00", "data": {"market": "0xfc6260666d020a912a87d9000eff5116d2adfb8c30aba543427a4c1f1411f1a0", "price_changes": [{"asset_id": "20615575591261238050354259319465440337102580196335623615376639598123117400036", "price": "0.69", "size": "389.75", "side": "SELL", "hash": "7b7aa8fb711ef47ca50045327a26854b3f4da0dc", "best_bid": "0.66", "best_ask": "0.67"}, {"asset_id": "57301498276970257025109591078431189727442302532145853906375186182281603517458", "price": "0.31", "size": "389.75", "side": "BUY", "hash": "280e2d21d7732a6724386e2d603ab8626538d975", "best_bid": "0.33", "best_ask": "0.34"}], "timestamp": "1769384157603", "event_type": "price_change"}}
{"_local_timestamp": "2026-01-25T23:35:57.723460+00:00", "data": {"market": "0xfc6260666d020a912a87d9000eff5116d2adfb8c30aba543427a4c1f1411f1a0", "price_changes": [{"asset_id": "20615575591261238050354259319465440337102580196335623615376639598123117400036", "price": "0.69", "size": "438.75", "side": "SELL", "hash": "df72893afe38eeb9e47d4b79cc10619bdffd5a53", "best_bid": "0.66", "best_ask": "0.67"}, {"asset_id": "57301498276970257025109591078431189727442302532145853906375186182281603517458", "price": "0.31", "size": "438.75", "side": "BUY", "hash": "818cac19c17f3bf78c672d9d6670cb60e78fbe72", "best_bid": "0.33", "best_ask": "0.34"}], "timestamp": "1769384157641", "event_type": "price_change"}}
{"_local_timestamp": "2026-01-25T23:35:59.192660+00:00", "data": {"market": "0xfc6260666d020a912a87d9000eff5116d2adfb8c30aba543427a4c1f1411f1a0", "price_changes": [{"asset_id": "20615575591261238050354259319465440337102580196335623615376639598123117400036", "price": "0.69", "size": "389.75", "side": "SELL", "hash": "61cb6160bcc8730a97c1beb29b0159a3a3f438a2", "best_bid": "0.66", "best_ask": "0.67"}, {"asset_id": "57301498276970257025109591078431189727442302532145853906375186182281603517458", "price": "0.31", "size": "389.75", "side": "BUY", "hash": "55cc53f4eb8f4eea8b6f5db1852bcc15483f6d9a", "best_bid": "0.33", "best_ask": "0.34"}], "timestamp": "1769384159093", "event_type": "price_change"}}
{"_local_timestamp": "2026-01-25T23:35:59.212236+00:00", "data": {"market": "0xfc6260666d020a912a87d9000eff5116d2adfb8c30aba543427a4c1f1411f1a0", "price_changes": [{"asset_id": "20615575591261238050354259319465440337102580196335623615376639598123117400036", "price": "0.69", "size": "438.75", "side": "SELL", "hash": "ec6c46e5e75f35a0fcbd86541637ffe7b3885740", "best_bid": "0.66", "best_ask": "0.67"}, {"asset_id": "57301498276970257025109591078431189727442302532145853906375186182281603517458", "price": "0.31", "size": "438.75", "side": "BUY", "hash": "81782abf7b066708919975311b7bf287b38715cd", "best_bid": "0.33", "best_ask": "0.34"}], "timestamp": "1769384159129", "event_type": "price_change"}}
{"_local_timestamp": "2026-01-25T23:36:00.661495+00:00", "data": {"market": "0xfc6260666d020a912a87d9000eff5116d2adfb8c30aba543427a4c1f1411f1a0", "price_changes": [{"asset_id": "20615575591261238050354259319465440337102580196335623615376639598123117400036", "price": "0.69", "size": "389.75", "side": "SELL", "hash": "f40cddfd1b99d8ba3b5d1aadf7b023320d1ce8b8", "best_bid": "0.66", "best_ask": "0.67"}, {"asset_id": "57301498276970257025109591078431189727442302532145853906375186182281603517458", "price": "0.31", "size": "389.75", "side": "BUY", "hash": "43ce248e99734df8b1601760c171fbdd92a87424", "best_bid": "0.33", "best_ask": "0.34"}], "timestamp": "1769384160597", "event_type": "price_change"}}
{"_local_timestamp": "2026-01-25T23:36:00.693390+00:00", "data": {"market": "0xfc6260666d020a912a87d9000eff5116d2adfb8c30aba543427a4c1f1411f1a0", "price_changes": [{"asset_id": "20615575591261238050354259319465440337102580196335623615376639598123117400036", "price": "0.69", "size": "438.75", "side": "SELL", "hash": "71c9935fe3a7e09a6cfb8391fbd9c44542eb4cfa", "best_bid": "0.66", "best_ask": "0.67"}, {"asset_id": "57301498276970257025109591078431189727442302532145853906375186182281603517458", "price": "0.31", "size": "438.75", "side": "BUY", "hash": "435d86dfcc95d4e798041c68a4d4636c83d7ddf5", "best_bid": "0.33", "best_ask": "0.34"}], "timestamp": "1769384160628", "event_type": "price_change"}}
{"_local_timestamp": "2026-01-25T23:36:02.160378+00:00", "data": {"market": "0xfc6260666d020a912a87d9000eff5116d2adfb8c30aba543427a4c1f1411f1a0", "price_changes": [{"asset_id": "20615575591261238050354259319465440337102580196335623615376639598123117400036", "price": "0.69", "size": "389.75", "side": "SELL", "hash": "65c63da3ddb813d7cbe298fdc8cf3cc700ccaddb", "best_bid": "0.66", "best_ask": "0.67"}, {"asset_id": "57301498276970257025109591078431189727442302532145853906375186182281603517458", "price": "0.31", "size": "389.75", "side": "BUY", "hash": "34447d0d0ce0c212e36bd290ddee014bd1b572f9", "best_bid": "0.33", "best_ask": "0.34"}], "timestamp": "1769384162093", "event_type": "price_change"}}
{"_local_timestamp": "2026-01-25T23:36:02.195707+00:00", "data": {"market": "0xfc6260666d020a912a87d9000eff5116d2adfb8c30aba543427a4c1f1411f1a0", "price_changes": [{"asset_id": "20615575591261238050354259319465440337102580196335623615376639598123117400036", "price": "0.69", "size": "438.75", "side": "SELL", "hash": "7e6c781646b679962a40b9865ff5df6e37329edc", "best_bid": "0.66", "best_ask": "0.67"}, {"asset_id": "57301498276970257025109591078431189727442302532145853906375186182281603517458", "price": "0.31", "size": "438.75", "side": "BUY", "hash": "5cda5984b07407ab652b92c25c6ffc1fe85a1588", "best_bid": "0.33", "best_ask": "0.34"}], "timestamp": "1769384162121", "event_type": "price_change"}}
{"_local_timestamp": "2026-01-25T23:36:03.659127+00:00", "data": {"market": "0xfc6260666d020a912a87d9000eff5116d2adfb8c30aba543427a4c1f1411f1a0", "price_changes": [{"asset_id": "20615575591261238050354259319465440337102580196335623615376639598123117400036", "price": "0.69", "size": "389.75", "side": "SELL", "hash": "704d45612556b2ff84c478a67259a5786a60dd1f", "best_bid": "0.66", "best_ask": "0.67"}, {"asset_id": "57301498276970257025109591078431189727442302532145853906375186182281603517458", "price": "0.31", "size": "389.75", "side": "BUY", "hash": "0102541584521f11a409e96b0d47db75b7adafe6", "best_bid": "0.33", "best_ask": "0.34"}], "timestamp": "1769384163593", "event_type": "price_change"}}
{"_local_timestamp": "2026-01-25T23:36:03.689132+00:00", "data": {"market": "0xfc6260666d020a912a87d9000eff5116d2adfb8c30aba543427a4c1f1411f1a0", "price_changes": [{"asset_id": "20615575591261238050354259319465440337102580196335623615376639598123117400036", "price": "0.69", "size": "438.75", "side": "SELL", "hash": "32f078c450b250b91a9c15d18a19984036705018", "best_bid": "0.66", "best_ask": "0.67"}, {"asset_id": "57301498276970257025109591078431189727442302532145853906375186182281603517458", "price": "0.31", "size": "438.75", "side": "BUY", "hash": "b304ec928c86e38534d100931af5fe291c3080e1", "best_bid": "0.33", "best_ask": "0.34"}], "timestamp": "1769384163622", "event_type": "price_change"}}
{"_local_timestamp": "2026-01-25T23:36:05.161082+00:00", "data": {"market": "0xfc6260666d020a912a87d9000eff5116d2adfb8c30aba543427a4c1f1411f1a0", "price_changes": [{"asset_id": "20615575591261238050354259319465440337102580196335623615376639598123117400036", "price": "0.69", "size": "389.75", "side": "SELL", "hash": "d5e17793673c3ca17178e0f5cb1474909b0e6f37", "best_bid": "0.66", "best_ask": "0.67"}, {"asset_id": "57301498276970257025109591078431189727442302532145853906375186182281603517458", "price": "0.31", "size": "389.75", "side": "BUY", "hash": "f1d01dcac50d6df138c26a9792df28ce328d3187", "best_bid": "0.33", "best_ask": "0.34"}], "timestamp": "1769384165096", "event_type": "price_change"}}
