{"_local_timestamp": "2026-01-25T23:40:44.621185+00:00", "data": [{"market": "0xc1c29be70cd39c9f72de2ab9338c1aa8b461ebe5f4969905654bdafe679afa07", "asset_id": "50325657743512433706892707197152031907050232791405235081059080709963762445435", "timestamp": "1769384263414", "hash": "9b13dae109b38ac9d7c371126513cd4de766f59d", "bids": [{"price": "0.001", "size": "1697"}, {"price": "0.002", "size": "222.87"}, {"price": "0.003", "size": "6.64"}, {"price": "0.004", "size": "77"}, {"price": "0.005", "size": "14.61"}, {"price": "0.01", "size": "26.27"}, {"price": "0.011", "size": "55.26"}], "asks": [{"price": "0.999", "size": "12264.57"}, {"price": "0.998", "size": "260.5"}, {"price": "0.997", "size": "166"}, {"price": "0.996", "size": "7.78"}, {"price": "0.994", "size": "83"}, {"price": "0.993", "size": "5.46"}, {"price": "0.99", "size": "35"}, {"price": "0.989", "size": "11.69"}, {"price": "0.96", "size": "12"}, {"price": "0.95", "size": "20"}, {"price": "0.94", "size": "33"}, {"price": "0.837", "size": "61"}, {"price": "0.112", "size": "28.7"}, {"price": "0.058", "size": "24.99"}, {"price": "0.057", "size": "15"}, {"price": "0.036", "size": "80"}, {"price": "0.035", "size": "5.6"}], "event_type": "book", "last_trade_price": "0.012"}, {"market": "0x6bab28a6f5075597847fb403af058162a9160f08892970974b6a7f092f53bbc9", "asset_id": "21214163253707781505820437681298157027008420325518755618864634836518062956958", "timestamp": "1769384026639", "hash": "8343783fab2274ef6bf6d2e70a7725da1389507e", "bids": [{"price": "0.001", "size": "3458.57"}, {"price": "0.002", "size": "1260.5"}, {"price": "0.003", "size": "1000"}, {"price": "0.004", "size": "18.01"}, {"price": "0.01", "size": "12030"}, {"price": "0.011", "size": "12.49"}, {"price": "0.02", "size": "5000"}, {"price": "0.03", "size": "4016"}, {"price": "0.05", "size": "20"}, {"price": "0.051", "size": "39"}, {"price": "0.06", "size": "2000"}, {"price": "0.15", "size": "900"}, {"price": "0.182", "size": "900"}, {"price": "0.184", "size": "16"}, {"price": "0.2", "size": "50"}, {"price": "0.27", "size": "50"}, {"price": "0.34", "size": "50"}, {"price": "0.777", "size": "83.51"}, {"price": "0.78", "size": "225"}, {"price": "0.781", "size": "231.95"}, {"price": "0.791", "size": "16"}, {"price": "0.843", "size": "20"}], "asks": [{"price": "0.999", "size": "1748"}, {"price": "0.998", "size": "250"}, {"price": "0.997", "size": "27.59"}, {"price": "0.993", "size": "5"}, {"price": "0.99", "size": "30"}, {"price": "0.989", "size": "12.53"}, {"price": "0.964", "size": "6.66"}, {"price": "0.963", "size": "25"}, {"price": "0.962", "size": "31.57"}], "event_type": "book", "last_trade_price": ""}, {"market": "0x7a1d49664545460db0ba5e5e8b93cceb612fbc41bb771d2a301604e70b0961c5", "asset_id": "13714707803298296385726368634232865185817279358363474279070084625804726290626", "timestamp": "1769384212831", "hash": "160052cdd36fa3ea9ecbe59c7b2efd8cec493443", "bids": [{"price": "0.01", "size": "62043.4"}, {"price": "0.02", "size": "5032.85"}, {"price": "0.03", "size": "17250"}, {"price": "0.05", "size": "20"}, {"price": "0.06", "size": "9473"}, {"price": "0.09", "size": "6600"}, {"price": "0.2", "size": "2700"}, {"price": "0.21", "size": "250"}, {"price": "0.27", "size": "50"}, {"price": "0.34", "size": "50"}, {"price": "0.77", "size": "225"}, {"price": "0.86", "size": "553.07"}, {"price": "0.88", "size": "2555.77"}, {"price": "0.89", "size": "100"}, {"price": "0.9", "size": "20"}, {"price": "0.94", "size": "100"}], "asks": [{"price": "0.99", "size": "135"}, {"price": "0.98", "size": "36.47"}, {"price": "0.96", "size": "141.13"}], "event_type": "book", "last_trade_price": "0.050"}, {"market": "0x1f25736a90ae1de3f2057416d9f0a3652b2e43f368e5b75f4ee46df8fd7099d7", "asset_id": "85290322537586030345323653214662930196438127025557552966516002506549266651006", "timestamp": "1769384026068", "hash": "6674022fa25b608338dab2969cf6c7f6d60386de", "bids": [{"price": "0.001", "size": "5852.15"}, {"price": "0.002", "size": "14.99"}, {"price": "0.004", "size": "63"}, {"price": "0.005", "size": "15.6"}, {"price": "0.01", "size": "34.19"}, {"price": "0.012", "size": "25"}, {"price": "0.013", "size": "92.3"}], "asks": [{"price": "0.999", "size": "2116.6"}, {"price": "0.998", "size": "1260.54"}, {"price": "0.997", "size": "1000"}, {"price": "0.996", "size": "18.08"}, {"price": "0.99", "size": "12035"}, {"price": "0.989", "size": "12.54"}, {"price": "0.98", "size": "5000"}, {"price": "0.97", "size": "4000"}, {"price": "0.96", "size": "12"}, {"price": "0.95", "size": "20"}, {"price": "0.94", "size": "2033"}, {"price": "0.85", "size": "900"}, {"price": "0.8", "size": "50"}, {"price": "0.797", "size": "62"}, {"price": "0.73", "size": "50"}, {"price": "0.66", "size": "50"}, {"price": "0.629", "size": "35.04"}, {"price": "0.628", "size": "29.56"}, {"price": "0.11", "size": "225"}, {"price": "0.109", "size": "53.84"}, {"price": "0.103", "size": "100"}, {"price": "0.101", "size": "20"}, {"price": "0.1", "size": "15"}], "event_type": "book", "last_trade_price": ""}, {"market": "0x0fc8dc44e3de82ae300787c180950bc3dd188e0c719d86e8559099aeb2491ff3", "asset_id": "68332573930090360687168031629975305535066054733932461259656105000052034697965", "timestamp": "1769384195782", "hash": "fcc9eec9f9c5a377f288ec3e01ac8f01fa3e8324", "bids": [{"price": "0.001", "size": "3390.57"}, {"price": "0.002", "size": "1260.5"}, {"price": "0.003", "size": "1166"}, {"price": "0.004", "size": "7.78"}, {"price": "0.006", "size": "83"}, {"price": "0.007", "size": "5.84"}, {"price": "0.01", "size": "12030"}, {"price": "0.011", "size": "12.49"}, {"price": "0.02", "size": "5000"}, {"price": "0.03", "size": "4000"}, {"price": "0.05", "size": "30"}, {"price": "0.051", "size": "39"}, {"price": "0.06", "size": "2000"}, {"price": "0.14", "size": "900"}, {"price": "0.178", "size": "900"}, {"price": "0.18", "size": "12"}, {"price": "0.2", "size": "50"}, {"price": "0.27", "size": "50"}, {"price": "0.34", "size": "50"}, {"price": "0.88", "size": "225"}, {"price": "0.881", "size": "180"}, {"price": "0.882", "size": "60"}, {"price": "0.924", "size": "30"}, {"price": "0.97", "size": "25.06"}, {"price": "0.971", "size": "52.17"}], "asks": [{"price": "0.999", "size": "1567"}, {"price": "0.998", "size": "23.97"}, {"price": "0.996", "size": "14"}, {"price": "0.995", "size": "9.01"}, {"price": "0.99", "size": "30"}, {"price": "0.989", "size": "15.42"}], "event_type": "book", "last_trade_price": "0.978"}, {"market": "0xabe2e088bb35b2d506faf75173426bef579552ccb97c6ea6a1afde6105827aee", "asset_id": "24818960756217755817691029038361518893839850992475818397337876822293546728914", "timestamp": "1769383405916", "hash": "5e6bef3e546a9e56e168526d0fd5a0558ead13fc", "bids": [{"price": "0.01", "size": "17043.4"}, {"price": "0.02", "size": "5007.85"}, {"price": "0.03", "size": "6016"}, {"price": "0.05", "size": "70"}, {"price": "0.06", "size": "3033"}, {"price": "0.07", "size": "1142"}, {"price": "0.15", "size": "900"}, {"price": "0.16", "size": "2624"}, {"price": "0.19", "size": "900"}, {"price": "0.2", "size": "50"}, {"price": "0.21", "size": "10"}, {"price": "0.27", "size": "50"}, {"price": "0.28", "size": "10"}, {"price": "0.6", "size": "246.66"}, {"price": "0.61", "size": "18.03"}, {"price": "0.62", "size": "15"}], "asks": [{"price": "0.99", "size": "1336.83"}, {"price": "0.98", "size": "8.63"}, {"price": "0.97", "size": "251"}, {"price": "0.96", "size": "180"}, {"price": "0.94", "size": "10.8"}], "event_type": "book", "last_trade_price": ""}, {"market": "0xc46ea913e412e0784ad8b486072f1b6d400bfa88ca3a380f38212742147ecf4b", "asset_id": "94903673046962891188296658322784616850640237332020065211348968622124724790366", "timestamp": "1769378967964", "hash": "b25910e08a3a94fa6420033d95de1afb19d4371a", "bids": [{"price": "0.001", "size": "5727"}, {"price": "0.002", "size": "11.06"}, {"price": "0.003", "size": "129"}, {"price": "0.004", "size": "18.08"}, {"price": "0.011", "size": "25"}], "asks": [{"price": "0.999", "size": "3390.61"}, {"price": "0.998", "size": "1260.54"}, {"price": "0.997", "size": "1166"}, {"price": "0.996", "size": "7.82"}, {"price": "0.994", "size": "83"}, {"price": "0.993", "size": "5.86"}, {"price": "0.99", "size": "12030"}, {"price": "0.989", "size": "12.54"}, {"price": "0.98", "size": "5000"}, {"price": "0.97", "size": "4016"}, {"price": "0.95", "size": "20"}, {"price": "0.949", "size": "39"}, {"price": "0.94", "size": "2000"}, {"price": "0.884", "size": "900"}, {"price": "0.882", "size": "5"}, {"price": "0.8", "size": "50"}, {"price": "0.73", "size": "50"}, {"price": "0.66", "size": "50"}, {"price": "0.06", "size": "200"}, {"price": "0.036", "size": "211.5"}, {"price": "0.035", "size": "42"}, {"price": "0.03", "size": "50"}], "event_type": "book", "last_trade_price": "0.021"}, {"market": "0x1f25736a90ae1de3f2057416d9f0a3652b2e43f368e5b75f4ee46df8fd7099d7", "asset_id": "28461575412803182588864269239832585057094860326193714190433339272934528877081", "timestamp": "1769384026068", "hash": "3f076dcf2f9ddbc81031cc1b12b997127a3993e1", "bids": [{"price": "0.001", "size": "2116.6"}, {"price": "0.002", "size": "1260.54"}, {"price": "0.003", "size": "1000"}, {"price": "0.004", "size": "18.08"}, {"price": "0.01", "size": "12035"}, {"price": "0.011", "size": "12.54"}, {"price": "0.02", "size": "5000"}, {"price": "0.03", "size": "4000"}, {"price": "0.04", "size": "12"}, {"price": "0.05", "size": "20"}, {"price": "0.06", "size": "2033"}, {"price": "0.15", "size": "900"}, {"price": "0.2", "size": "50"}, {"price": "0.203", "size": "62"}, {"price": "0.27", "size": "50"}, {"price": "0.34", "size": "50"}, {"price": "0.371", "size": "35.04"}, {"price": "0.372", "size": "29.56"}, {"price": "0.89", "size": "225"}, {"price": "0.891", "size": "53.84"}, {"price": "0.897", "size": "100"}, {"price": "0.899", "size": "20"}, {"price": "0.9", "size": "15"}], "asks": [{"price": "0.999", "size": "5852.15"}, {"price": "0.998", "size": "14.99"}, {"price": "0.996", "size": "63"}, {"price": "0.995", "size": "15.6"}, {"price": "0.99", "size": "34.19"}, {"price": "0.988", "size": "25"}, {"price": "0.987", "size": "92.3"}], "event_type": "book", "last_trade_price": ""}, {"market": "0x5372c3942dac612d595f10ab9ee944a0fb1f521f8a0f7e5e4c69ea7f820b9205", "asset_id": "28425112653106522555623063788214711387350887710590000638731586279221931393822", "timestamp": "1769384353303", "hash": "419cc47e00967bcf302b1e841111dd139259630b", "bids": [{"price": "0.001", "size": "2521.57"}, {"price": "0.002", "size": "260.5"}, {"price": "0.003", "size": "166"}, {"price": "0.004", "size": "7.78"}, {"price": "0.006", "size": "83"}, {"price": "0.007", "size": "5.84"}, {"price": "0.01", "size": "30"}, {"price": "0.011", "size": "12.49"}, {"price": "0.017", "size": "5"}, {"price": "0.03", "size": "16"}, {"price": "0.031", "size": "8"}, {"price": "0.05", "size": "20"}, {"price": "0.051", "size": "39"}, {"price": "0.81", "size": "25"}], "asks": [{"price": "0.999", "size": "2639"}, {"price": "0.998", "size": "472.63"}], "event_type": "book", "last_trade_price": "0.002"}, {"market": "0x61c7a2857f724184aeefcfc1d5c2d058f0b5a3d95c07e0698a8702a2044cc3f9", "asset_id": "63990477029527440251791260115609966942867460219987284386576624440536500927768", "timestamp": "1769384423006", "hash": "be048558ac14ae80566360bb4f14df1d412aa1cd", "bids": [{"price": "0.001", "size": "1691"}, {"price": "0.002", "size": "29.13"}, {"price": "0.003", "size": "11"}, {"price": "0.004", "size": "8.67"}, {"price": "0.01", "size": "6.7"}, {"price": "0.011", "size": "39.58"}], "asks": [{"price": "0.999", "size": "17813.61"}, {"price": "0.998", "size": "260.54"}, {"price": "0.997", "size": "166"}, {"price": "0.996", "size": "7.82"}, {"price": "0.994", "size": "83"}, {"price": "0.993", "size": "5.86"}, {"price": "0.99", "size": "35"}, {"price": "0.989", "size": "12.54"}, {"price": "0.95", "size": "30"}, {"price": "0.949", "size": "39"}, {"price": "0.948", "size": "19"}, {"price": "0.061", "size": "24.99"}, {"price": "0.057", "size": "20"}, {"price": "0.036", "size": "69.5"}, {"price": "0.035", "size": "12.4"}], "event_type": "book", "last_trade_price": "0.011"}, {"market": "0x1616ea61786f96c78127a6ab4356aee9c7eb14d5cc9d2d7f9039cfa4e18a143e", "asset_id": "46243045476329273541305766895974582812752716873181978958034892424486385866518", "timestamp": "1769383466489", "hash": "5ea9b58e154fb2d2d7be539ba32137239bf2033e", "bids": [{"price": "0.001", "size": "2376.57"}, {"price": "0.002", "size": "1260.5"}, {"price": "0.003", "size": "1000"}, {"price": "0.004", "size": "18.01"}, {"price": "0.01", "size": "17030"}, {"price": "0.011", "size": "12.49"}, {"price": "0.02", "size": "5000"}, {"price": "0.03", "size": "6016"}, {"price": "0.05", "size": "20"}, {"price": "0.051", "size": "39"}, {"price": "0.06", "size": "3000"}, {"price": "0.061", "size": "1884"}, {"price": "0.15", "size": "900"}, {"price": "0.159", "size": "251"}, {"price": "0.16", "size": "2624"}, {"price": "0.2", "size": "950"}, {"price": "0.205", "size": "10"}, {"price": "0.27", "size": "50"}, {"price": "0.274", "size": "47.44"}, {"price": "0.275", "size": "40"}, {"price": "0.34", "size": "50"}, {"price": "0.64", "size": "225"}, {"price": "0.67", "size": "5"}, {"price": "0.671", "size": "60"}, {"price": "0.672", "size": "55.03"}, {"price": "0.69", "size": "1.77"}], "asks": [{"price": "0.999", "size": "2872.66"}, {"price": "0.998", "size": "1255.35"}, {"price": "0.997", "size": "10.6"}, {"price": "0.995", "size": "50"}, {"price": "0.994", "size": "8.68"}, {"price": "0.99", "size": "255"}, {"price": "0.989", "size": "12.7"}, {"price": "0.958", "size": "309.52"}, {"price": "0.957", "size": "209"}, {"price": "0.956", "size": "10"}, {"price": "0.955", "size": "174.22"}, {"price": "0.87", "size": "23.5"}], "event_type": "book", "last_trade_price": "0.310"}, {"market": "0x1616ea61786f96c78127a6ab4356aee9c7eb14d5cc9d2d7f9039cfa4e18a143e", "asset_id": "85437609865892622601248823164308628503398123897166693550206339917945256897243", "timestamp": "1769383466489", "hash": "0a3fc83a17b81238a5dd74b56b48b75f33739ee4", "bids": [{"price": "0.001", "size": "2872.66"}, {"price": "0.002", "size": "1255.35"}, {"price": "0.003", "size": "10.6"}, {"price": "0.005", "size": "50"}, {"price": "0.006", "size": "8.68"}, {"price": "0.01", "size": "255"}, {"price": "0.011", "size": "12.7"}, {"price": "0.042", "size": "309.52"}, {"price": "0.043", "size": "209"}, {"price": "0.044", "size": "10"}, {"price": "0.045", "size": "174.22"}, {"price": "0.13", "size": "23.5"}], "asks": [{"price": "0.999", "size": "2376.57"}, {"price": "0.998", "size": "1260.5"}, {"price": "0.997", "size": "1000"}, {"price": "0.996", "size": "18.01"}, {"price": "0.99", "size": "17030"}, {"price": "0.989", "size": "12.49"}, {"price": "0.98", "size": "5000"}, {"price": "0.97", "size": "6016"}, {"price": "0.95", "size": "20"}, {"price": "0.949", "size": "39"}, {"price": "0.94", "size": "3000"}, {"price": "0.939", "size": "1884"}, {"price": "0.85", "size": "900"}, {"price": "0.841", "size": "251"}, {"price": "0.84", "size": "2624"}, {"price": "0.8", "size": "950"}, {"price": "0.795", "size": "10"}, {"price": "0.73", "size": "50"}, {"price": "0.726", "size": "47.44"}, {"price": "0.725", "size": "40"}, {"price": "0.66", "size": "50"}, {"price": "0.36", "size": "225"}, {"price": "0.33", "size": "5"}, {"price": "0.329", "size": "60"}, {"price": "0.328", "size": "55.03"}, {"price": "0.31", "size": "1.77"}], "event_type": "book", "last_trade_price": "0.310"}, {"market": "0xfbaf6c00d1702c189522a2025f8d52d01348978b16dfe5bd51d5d2f5d6712b0b", "asset_id": "102477275037226691782080912266896459375744854273025191158751338694645017892558", "timestamp": "1769384430900", "hash": "99a5ce3fc182306620c6741f539e4397eb13b85c", "bids": [{"price": "0.01", "size": "10036.7"}, {"price": "0.02", "size": "2008.7"}, {"price": "0.03", "size": "16"}, {"price": "0.11", "size": "118.18"}, {"price": "0.13", "size": "225"}, {"price": "0.14", "size": "300"}, {"price": "0.15", "size": "100"}, {"price": "0.22", "size": "60"}, {"price": "0.23", "size": "36"}, {"price": "0.24", "size": "8.5"}, {"price": "0.26", "size": "20"}], "asks": [{"price": "0.99", "size": "17043.4"}, {"price": "0.98", "size": "5007.85"}, {"price": "0.97", "size": "6016"}, {"price": "0.94", "size": "3000"}, {"price": "0.92", "size": "2137"}, {"price": "0.91", "size": "700"}, {"price": "0.84", "size": "250"}, {"price": "0.83", "size": "3370"}, {"price": "0.8", "size": "50"}, {"price": "0.79", "size": "158.7"}, {"price": "0.75", "size": "79"}, {"price": "0.71", "size": "50"}, {"price": "0.6", "size": "225"}, {"price": "0.59", "size": "8.5"}, {"price": "0.48", "size": "25"}, {"price": "0.47", "size": "30.75"}, {"price": "0.37", "size": "160"}, {"price": "0.36", "size": "20"}], "event_type": "book", "last_trade_price": ""}, {"market": "0x1abd61ad100d8895f3584b464ef167f3518e25a6030881103d14acc083ebad96", "asset_id": "91437369688558543467551854737984316990748701143376320320377387982132471568811", "timestamp": "1769384403784", "hash": "8591951cb0d3bf7ca41b30decaf5cab1f1d4f931", "bids": [{"price": "0.01", "size": "17043.05"}, {"price": "0.02", "size": "5032.53"}, {"price": "0.03", "size": "4000"}, {"price": "0.06", "size": "2000"}, {"price": "0.07", "size": "6000"}, {"price": "0.12", "size": "1200"}, {"price": "0.23", "size": "225"}, {"price": "0.26", "size": "50"}, {"price": "0.35", "size": "168.74"}, {"price": "0.36", "size": "52.65"}, {"price": "0.42", "size": "25"}], "asks": [{"price": "0.99", "size": "11043.4"}, {"price": "0.98", "size": "4032.85"}, {"price": "0.97", "size": "4000"}, {"price": "0.95", "size": "20"}, {"price": "0.93", "size": "571"}, {"price": "0.84", "size": "150"}, {"price": "0.76", "size": "225"}, {"price": "0.61", "size": "33.33"}, {"price": "0.6", "size": "5.39"}, {"price": "0.52", "size": "20"}], "event_type": "book", "last_trade_price": ""}, {"market": "0x6bab28a6f5075597847fb403af058162a9160f08892970974b6a7f092f53bbc9", "asset_id": "825568625501271247311152915286608704339236896918641095426409218916618217433", "timestamp": "1769384026639", "hash": "9b626e45cd03a4448a54a7813391716c62c33809", "bids": [{"price": "0.001", "size": "1748"}, {"price": "0.002", "size": "250"}, {"price": "0.003", "size": "27.59"}, {"price": "0.007", "size": "5"}, {"price": "0.01", "size": "30"}, {"price": "0.011", "size": "12.53"}, {"price": "0.036", "size": "6.66"}, {"price": "0.037", "size": "25"}, {"price": "0.038", "size": "31.57"}], "asks": [{"price": "0.999", "size": "3458.57"}, {"price": "0.998", "size": "1260.5"}, {"price": "0.997", "size": "1000"}, {"price": "0.996", "size": "18.01"}, {"price": "0.99", "size": "12030"}, {"price": "0.989", "size": "12.49"}, {"price": "0.98", "size": "5000"}, {"price": "0.97", "size": "4016"}, {"price": "0.95", "size": "20"}, {"price": "0.949", "size": "39"}, {"price": "0.94", "size": "2000"}, {"price": "0.85", "size": "900"}, {"price": "0.818", "size": "900"}, {"price": "0.816", "size": "16"}, {"price": "0.8", "size": "50"}, {"price": "0.73", "size": "50"}, {"price": "0.66", "size": "50"}, {"price": "0.223", "size": "83.51"}, {"price": "0.22", "size": "225"}, {"price": "0.219", "size": "231.95"}, {"price": "0.209", "size": "16"}, {"price": "0.157", "size": "20"}], "event_type": "book", "last_trade_price": ""}, {"market": "0xfbaf6c00d1702c189522a2025f8d52d01348978b16dfe5bd51d5d2f5d6712b0b", "asset_id": "58436266613638193406222525170978476700361341943881268058813684153244605853496", "timestamp": "1769384430900", "hash": "9b1bf2ad469e81c1452d247e697bba3b600a837c", "bids": [{"price": "0.01", "size": "17043.4"}, {"price": "0.02", "size": "5007.85"}, {"price": "0.03", "size": "6016"}, {"price": "0.06", "size": "3000"}, {"price": "0.08", "size": "2137"}, {"price": "0.09", "size": "700"}, {"price": "0.16", "size": "250"}, {"price": "0.17", "size": "3370"}, {"price": "0.2", "size": "50"}, {"price": "0.21", "size": "158.7"}, {"price": "0.25", "size": "79"}, {"price": "0.29", "size": "50"}, {"price": "0.4", "size": "225"}, {"price": "0.41", "size": "8.5"}, {"price": "0.52", "size": "25"}, {"price": "0.53", "size": "30.75"}, {"price": "0.63", "size": "160"}, {"price": "0.64", "size": "20"}], "asks": [{"price": "0.99", "size": "10036.7"}, {"price": "0.98", "size": "2008.7"}, {"price": "0.97", "size": "16"}, {"price": "0.89", "size": "118.18"}, {"price": "0.87", "size": "225"}, {"price": "0.86", "size": "300"}, {"price": "0.85", "size": "100"}, {"price": "0.78", "size": "60"}, {"price": "0.77", "size": "36"}, {"price": "0.76", "size": "8.5"}, {"price": "0.74", "size": "20"}], "event_type": "book", "last_trade_price": ""}, {"market": "0xc46ea913e412e0784ad8b486072f1b6d400bfa88ca3a380f38212742147ecf4b", "asset_id": "50599148298913919045928815416616498507585091061277108411005235851324943043908", "timestamp": "1769378967964", "hash": "9eb46eca9580eb6be4f4e7f16f0c9a170438d918", "bids": [{"price": "0.001", "size": "3390.61"}, {"price": "0.002", "size": "1260.54"}, {"price": "0.003", "size": "1166"}, {"price": "0.004", "size": "7.82"}, {"price": "0.006", "size": "83"}, {"price": "0.007", "size": "5.86"}, {"price": "0.01", "size": "12030"}, {"price": "0.011", "size": "12.54"}, {"price": "0.02", "size": "5000"}, {"price": "0.03", "size": "4016"}, {"price": "0.05", "size": "20"}, {"price": "0.051", "size": "39"}, {"price": "0.06", "size": "2000"}, {"price": "0.116", "size": "900"}, {"price": "0.118", "size": "5"}, {"price": "0.2", "size": "50"}, {"price": "0.27", "size": "50"}, {"price": "0.34", "size": "50"}, {"price": "0.94", "size": "200"}, {"price": "0.964", "size": "211.5"}, {"price": "0.965", "size": "42"}, {"price": "0.97", "size": "50"}], "asks": [{"price": "0.999", "size": "5727"}, {"price": "0.998", "size": "11.06"}, {"price": "0.997", "size": "129"}, {"price": "0.996", "size": "18.08"}, {"price": "0.989", "size": "25"}], "event_type": "book", "last_trade_price": "0.021"}, {"market": "0x5372c3942dac612d595f10ab9ee944a0fb1f521f8a0f7e5e4c69ea7f820b9205", "asset_id": "14539781518361540889330537982912764909191745060309412974583163279274941075133", "timestamp": "1769384353303", "hash": "67a0b01e83b368cb3e26565c68f319f5cca12699", "bids": [{"price": "0.001", "size": "2639"}, {"price": "0.002", "size": "472.63"}], "asks": [{"price": "0.999", "size": "2521.57"}, {"price": "0.998", "size": "260.5"}, {"price": "0.997", "size": "166"}, {"price": "0.996", "size": "7.78"}, {"price": "0.994", "size": "83"}, {"price": "0.993", "size": "5.84"}, {"price": "0.99", "size": "30"}, {"price": "0.989", "size": "12.49"}, {"price": "0.983", "size": "5"}, {"price": "0.97", "size": "16"}, {"price": "0.969", "size": "8"}, {"price": "0.95", "size": "20"}, {"price": "0.949", "size": "39"}, {"price": "0.19", "size": "25"}], "event_type": "book", "last_trade_price": "0.002"}, {"market": "0x61c7a2857f724184aeefcfc1d5c2d058f0b5a3d95c07e0698a8702a2044cc3f9", "asset_id": "16513348473820721539329266419516258589145306802106861039482427297186980662547", "timestamp": "1769384423006", "hash": "b997e106d699e45cac786a725070f6a017dd8704", "bids": [{"price": "0.001", "size": "17813.61"}, {"price": "0.002", "size": "260.54"}, {"price": "0.003", "size": "166"}, {"price": "0.004", "size": "7.82"}, {"price": "0.006", "size": "83"}, {"price": "0.007", "size": "5.86"}, {"price": "0.01", "size": "35"}, {"price": "0.011", "size": "12.54"}, {"price": "0.05", "size": "30"}, {"price": "0.051", "size": "39"}, {"price": "0.052", "size": "19"}, {"price": "0.939", "size": "24.99"}, {"price": "0.943", "size": "20"}, {"price": "0.964", "size": "69.5"}, {"price": "0.965", "size": "12.4"}], "asks": [{"price": "0.999", "size": "1691"}, {"price": "0.998", "size": "29.13"}, {"price": "0.997", "size": "11"}, {"price": "0.996", "size": "8.67"}, {"price": "0.99", "size": "6.7"}, {"price": "0.989", "size": "39.58"}], "event_type": "book", "last_trade_price": "0.011"}, {"market": "0xabe2e088bb35b2d506faf75173426bef579552ccb97c6ea6a1afde6105827aee", "asset_id": "38069825168641311679837342086389321777773400417700275247215348750930879883747", "timestamp": "1769383405916", "hash": "c2873cf941c9202c34b5e0e971e39b883e1d0a42", "bids": [{"price": "0.01", "size": "1336.83"}, {"price": "0.02", "size": "8.63"}, {"price": "0.03", "size": "251"}, {"price": "0.04", "size": "180"}, {"price": "0.06", "size": "10.8"}], "asks": [{"price": "0.99", "size": "17043.4"}, {"price": "0.98", "size": "5007.85"}, {"price": "0.97", "size": "6016"}, {"price": "0.95", "size": "70"}, {"price": "0.94", "size": "3033"}, {"price": "0.93", "size": "1142"}, {"price": "0.85", "size": "900"}, {"price": "0.84", "size": "2624"}, {"price": "0.81", "size": "900"}, {"price": "0.8", "size": "50"}, {"price": "0.79", "size": "10"}, {"price": "0.73", "size": "50"}, {"price": "0.72", "size": "10"}, {"price": "0.4", "size": "246.66"}, {"price": "0.39", "size": "18.03"}, {"price": "0.38", "size": "15"}], "event_type": "book", "last_trade_price": ""}, {"market": "0x07059ad87d5002d2586ccd1949479aad5d2c7f2ee34c5e95f2dd2ef3ab7d7199", "asset_id": "68984838443964862142364853070609406288819708356859516716547447646969765575585", "timestamp": "1769383382804", "hash": "2a45fd900daf2a9ca4435671bb3a53403c2d6669", "bids": [{"price": "0.001", "size": "11894.7"}, {"price": "0.002", "size": "1255.32"}, {"price": "0.003", "size": "35.96"}, {"price": "0.01", "size": "35"}, {"price": "0.013", "size": "2000"}, {"price": "0.014", "size": "7.45"}, {"price": "0.02", "size": "25"}, {"price": "0.021", "size": "12"}, {"price": "0.1", "size": "225"}, {"price": "0.136", "size": "105.58"}, {"price": "0.137", "size": "80.29"}, {"price": "0.254", "size": "20"}], "asks": [{"price": "0.999", "size": "2407.57"}, {"price": "0.998", "size": "1255.26"}, {"price": "0.997", "size": "27.51"}, {"price": "0.99", "size": "17030"}, {"price": "0.989", "size": "12.49"}, {"price": "0.98", "size": "5025"}, {"price": "0.97", "size": "4000"}, {"price": "0.95", "size": "20"}, {"price": "0.949", "size": "39"}, {"price": "0.94", "size": "2000"}, {"price": "0.939", "size": "655"}, {"price": "0.88", "size": "1000"}, {"price": "0.879", "size": "4370"}, {"price": "0.817", "size": "900"}, {"price": "0.816", "size": "10"}, {"price": "0.54", "size": "225"}, {"price": "0.537", "size": "28.07"}, {"price": "0.535", "size": "23.65"}, {"price": "0.532", "size": "192"}, {"price": "0.356", "size": "20"}, {"price": "0.355", "size": "36.95"}], "event_type": "book", "last_trade_price": "0.271"}, {"market": "0x0fc8dc44e3de82ae300787c180950bc3dd188e0c719d86e8559099aeb2491ff3", "asset_id": "107230676698401838350579684070148863651625417715181026919457587632470951166569", "timestamp": "1769384195782", "hash": "415ca0bdbdfbde8650430cf7c0ebb60285b086d4", "bids": [{"price": "0.001", "size": "1567"}, {"price": "0.002", "size": "23.97"}, {"price": "0.004", "size": "14"}, {"price": "0.005", "size": "9.01"}, {"price": "0.01", "size": "30"}, {"price": "0.011", "size": "15.42"}], "asks": [{"price": "0.999", "size": "3390.57"}, {"price": "0.998", "size": "1260.5"}, {"price": "0.997", "size": "1166"}, {"price": "0.996", "size": "7.78"}, {"price": "0.994", "size": "83"}, {"price": "0.993", "size": "5.84"}, {"price": "0.99", "size": "12030"}, {"price": "0.989", "size": "12.49"}, {"price": "0.98", "size": "5000"}, {"price": "0.97", "size": "4000"}, {"price": "0.95", "size": "30"}, {"price": "0.949", "size": "39"}, {"price": "0.94", "size": "2000"}, {"price": "0.86", "size": "900"}, {"price": "0.822", "size": "900"}, {"price": "0.82", "size": "12"}, {"price": "0.8", "size": "50"}, {"price": "0.73", "size": "50"}, {"price": "0.66", "size": "50"}, {"price": "0.12", "size": "225"}, {"price": "0.119", "size": "180"}, {"price": "0.118", "size": "60"}, {"price": "0.076", "size": "30"}, {"price": "0.03", "size": "25.06"}, {"price": "0.029", "size": "52.17"}], "event_type": "book", "last_trade_price": "0.978"}, {"market": "0x07059ad87d5002d2586ccd1949479aad5d2c7f2ee34c5e95f2dd2ef3ab7d7199", "asset_id": "2048696428439973765173375544259621027080600383791777990851662332503641949990", "timestamp": "1769383382804", "hash": "0662b9fd9e746de5e818d0395cb1ce490f0a62ff", "bids": [{"price": "0.001", "size": "2407.57"}, {"price": "0.002", "size": "1255.26"}, {"price": "0.003", "size": "27.51"}, {"price": "0.01", "size": "17030"}, {"price": "0.011", "size": "12.49"}, {"price": "0.02", "size": "5025"}, {"price": "0.03", "size": "4000"}, {"price": "0.05", "size": "20"}, {"price": "0.051", "size": "39"}, {"price": "0.06", "size": "2000"}, {"price": "0.061", "size": "655"}, {"price": "0.12", "size": "1000"}, {"price": "0.121", "size": "4370"}, {"price": "0.183", "size": "900"}, {"price": "0.184", "size": "10"}, {"price": "0.46", "size": "225"}, {"price": "0.463", "size": "28.07"}, {"price": "0.465", "size": "23.65"}, {"price": "0.468", "size": "192"}, {"price": "0.644", "size": "20"}, {"price": "0.645", "size": "36.95"}], "asks": [{"price": "0.999", "size": "11894.7"}, {"price": "0.998", "size": "1255.32"}, {"price": "0.997", "size": "35.96"}, {"price": "0.99", "size": "35"}, {"price": "0.987", "size": "2000"}, {"price": "0.986", "size": "7.45"}, {"price": "0.98", "size": "25"}, {"price": "0.979", "size": "12"}, {"price": "0.9", "size": "225"}, {"price": "0.864", "size": "105.58"}, {"price": "0.863", "size": "80.29"}, {"price": "0.746", "size": "20"}], "event_type": "book", "last_trade_price": "0.271"}, {"market": "0x1abd61ad100d8895f3584b464ef167f3518e25a6030881103d14acc083ebad96", "asset_id": "88964156506218863777298237975219012171691782824739196411832554942435520583952", "timestamp": "1769384403784", "hash": "00ec5c790e60fc9f99a1ab51f4e298b0bb25ff4d", "bids": [{"price": "0.01", "size": "11043.4"}, {"price": "0.02", "size": "4032.85"}, {"price": "0.03", "size": "4000"}, {"price": "0.05", "size": "20"}, {"price": "0.07", "size": "571"}, {"price": "0.16", "size": "150"}, {"price": "0.24", "size": "225"}, {"price": "0.39", "size": "33.33"}, {"price": "0.4", "size": "5.39"}, {"price": "0.48", "size": "20"}], "asks": [{"price": "0.99", "size": "17043.05"}, {"price": "0.98", "size": "5032.53"}, {"price": "0.97", "size": "4000"}, {"price": "0.94", "size": "2000"}, {"price": "0.93", "size": "6000"}, {"price": "0.88", "size": "1200"}, {"price": "0.77", "size": "225"}, {"price": "0.74", "size": "50"}, {"price": "0.65", "size": "168.74"}, {"price": "0.64", "size": "52.65"}, {"price": "0.58", "size": "25"}], "event_type": "book", "last_trade_price": ""}, {"market": "0x7a1d49664545460db0ba5e5e8b93cceb612fbc41bb771d2a301604e70b0961c5", "asset_id": "102425427310314829793465336917429668352269874891507740825471648392466296067415", "timestamp": "1769384212831", "hash": "0fbbd7cabc32bd13a7f30252a4f924de2fb5c6b2", "bids": [{"price": "0.01", "size": "135"}, {"price": "0.02", "size": "36.47"}, {"price": "0.04", "size": "141.13"}], "asks": [{"price": "0.99", "size": "62043.4"}, {"price": "0.98", "size": "5032.85"}, {"price": "0.97", "size": "17250"}, {"price": "0.95", "size": "20"}, {"price": "0.94", "size": "9473"}, {"price": "0.91", "size": "6600"}, {"price": "0.8", "size": "2700"}, {"price": "0.79", "size": "250"}, {"price": "0.73", "size": "50"}, {"price": "0.66", "size": "50"}, {"price": "0.23", "size": "225"}, {"price": "0.14", "size": "553.07"}, {"price": "0.12", "size": "2555.77"}, {"price": "0.11", "size": "100"}, {"price": "0.1", "size": "20"}, {"price": "0.06", "size": "100"}], "event_type": "book", "last_trade_price": "0.050"}, {"market": "0xc1c29be70cd39c9f72de2ab9338c1aa8b461ebe5f4969905654bdafe679afa07", "asset_id": "97834981188079665391659336156149815346383761304074482681876419862703828354805", "timestamp": "1769384263414", "hash": "bc7a7fbf0c2410caa3256c6879095d3e73f62fbc", "bids": [{"price": "0.001", "size": "12264.57"}, {"price": "0.002", "size": "260.5"}, {"price": "0.003", "size": "166"}, {"price": "0.004", "size": "7.78"}, {"price": "0.006", "size": "83"}, {"price": "0.007", "size": "5.46"}, {"price": "0.01", "size": "35"}, {"price": "0.011", "size": "11.69"}, {"price": "0.04", "size": "12"}, {"price": "0.05", "size": "20"}, {"price": "0.06", "size": "33"}, {"price": "0.163", "size": "61"}, {"price": "0.888", "size": "28.7"}, {"price": "0.942", "size": "24.99"}, {"price": "0.943", "size": "15"}, {"price": "0.964", "size": "80"}, {"price": "0.965", "size": "5.6"}], "asks": [{"price": "0.999", "size": "1697"}, {"price": "0.998", "size": "222.87"}, {"price": "0.997", "size": "6.64"}, {"price": "0.996", "size": "77"}, {"price": "0.995", "size": "14.61"}, {"price": "0.99", "size": "26.27"}, {"price": "0.989", "size": "55.26"}], "event_type": "book", "last_trade_price": "0.012"}]}
{"_local_timestamp": "2026-01-25T23:40:49.890659+00:00", "data": {"market": "0xfbaf6c00d1702c189522a2025f8d52d01348978b16dfe5bd51d5d2f5d6712b0b", "price_changes": [{"asset_id": "58436266613638193406222525170978476700361341943881268058813684153244605853496", "price": "0.17", "size": "2970", "side": "BUY", "hash": "83d83d713c6193522171cf6024db9736f616fd8c", "best_bid": "0.64", "best_ask": "0.74"}, {"asset_id": "102477275037226691782080912266896459375744854273025191158751338694645017892558", "price": "0.83", "size": "2970", "side": "SELL", "hash": "14e7c730c6da1f4d27be397a359a457519c5f74b", "best_bid": "0.26", "best_ask": "0.36"}], "timestamp": "1769384449809", "event_type": "price_change"}}
{"_local_timestamp": "2026-01-25T23:40:54.959524+00:00", "data": {"market": "0xfbaf6c00d1702c189522a2025f8d52d01348978b16dfe5bd51d5d2f5d6712b0b", "price_changes": [{"asset_id": "58436266613638193406222525170978476700361341943881268058813684153244605853496", "price": "0.17", "size": "2470", "side": "BUY", "hash": "47223d133e40f11af7b01817c0ceb9d43e70ff07", "best_bid": "0.64", "best_ask": "0.74"}, {"asset_id": "102477275037226691782080912266896459375744854273025191158751338694645017892558", "price": "0.83", "size": "2470", "side": "SELL", "hash": "352fe7f03025b659bc7dc3be7a06e2e8ad9d5143", "best_bid": "0.26", "best_ask": "0.36"}], "timestamp": "1769384454882", "event_type": "price_change"}}
{"_local_timestamp": "2026-01-25T23:41:10.844549+00:00", "data": {"market": "0x61c7a2857f724184aeefcfc1d5c2d058f0b5a3d95c07e0698a8702a2044cc3f9", "price_changes": [{"asset_id": "16513348473820721539329266419516258589145306802106861039482427297186980662547", "price": "0.943", "size": "0", "side": "BUY", "hash": "88b59d19ad38d18d9f1d4f5ea930f014b809c2d6", "best_bid": "0.965", "best_ask": "0.989"}, {"asset_id": "63990477029527440251791260115609966942867460219987284386576624440536500927768", "price": "0.057", "size": "0", "side": "SELL", "hash": "42e82b23e23c702e676d76227497815d5cf6ddb9", "best_bid": "0.011", "best_ask": "0.035"}], "timestamp": "1769384470776", "event_type": "price_change"}}
{"_local_timestamp": "2026-01-25T23:41:11.894837+00:00", "data": {"market": "0x61c7a2857f724184aeefcfc1d5c2d058f0b5a3d95c07e0698a8702a2044cc3f9", "price_changes": [{"asset_id": "16513348473820721539329266419516258589145306802106861039482427297186980662547", "price": "0.94", "size": "20", "side": "BUY", "hash": "9a6bff49f0ac1606bb8f8be9a4db3b135065e500", "best_bid": "0.965", "best_ask": "0.989"}, {"asset_id": "63990477029527440251791260115609966942867460219987284386576624440536500927768", "price": "0.06", "size": "20", "side": "SELL", "hash": "895638d3b07cd17aaf23e555cd012f60deb87929", "best_bid": "0.011", "best_ask": "0.035"}], "timestamp": "1769384471827", "event_type": "price_change"}}
{"_local_timestamp": "2026-01-25T23:41:14.773286+00:00", "data": {"market": "0x1abd61ad100d8895f3584b464ef167f3518e25a6030881103d14acc083ebad96", "price_changes": [{"asset_id": "91437369688558543467551854737984316990748701143376320320377387982132471568811", "price": "0.07", "size": "0", "side": "BUY", "hash": "6fb41b91ac5b37559628b1e93e7a071e71551c69", "best_bid": "0.42", "best_ask": "0.52"}, {"asset_id": "88964156506218863777298237975219012171691782824739196411832554942435520583952", "price": "0.93", "size": "0", "side": "SELL", "hash": "0c08ca6948e80607fff923213944916b94c46008", "best_bid": "0.48", "best_ask": "0.58"}], "timestamp": "1769384474540", "event_type": "price_change"}}
{"_local_timestamp": "2026-01-25T23:41:22.504343+00:00", "data": {"market": "0x1abd61ad100d8895f3584b464ef167f3518e25a6030881103d14acc083ebad96", "price_changes": [{"asset_id": "91437369688558543467551854737984316990748701143376320320377387982132471568811", "price": "0.08", "size": "5250", "side": "BUY", "hash": "afca1ba6a90eb60d044c0dc8c11683e9065ddebc", "best_bid": "0.42", "best_ask": "0.52"}, {"asset_id": "88964156506218863777298237975219012171691782824739196411832554942435520583952", "price": "0.92", "size": "5250", "side": "SELL", "hash": "ffc7dc10361600d2efa01f8935ec3c856118afd3", "best_bid": "0.48", "best_ask": "0.58"}], "timestamp": "1769384482384", "event_type": "price_change"}}
{"_local_timestamp": "2026-01-25T23:41:26.574980+00:00", "data": {"market": "0xfbaf6c00d1702c189522a2025f8d52d01348978b16dfe5bd51d5d2f5d6712b0b", "price_changes": [{"asset_id": "102477275037226691782080912266896459375744854273025191158751338694645017892558", "price": "0.22", "size": "50", "side": "BUY", "hash": "0d66cfbd454c7148edc041268f7a00877df52aa0", "best_bid": "0.26", "best_ask": "0.36"}, {"asset_id": "58436266613638193406222525170978476700361341943881268058813684153244605853496", "price": "0.78", "size": "50", "side": "SELL", "hash": "831646a4ee93b54722aad4213c396a4cb045ed39", "best_bid": "0.64", "best_ask": "0.74"}], "timestamp": "1769384486441", "event_type": "price_change"}}
{"_local_timestamp": "2026-01-25T23:41:26.701217+00:00", "data": {"market": "0xfbaf6c00d1702c189522a2025f8d52d01348978b16dfe5bd51d5d2f5d6712b0b", "price_changes": [{"asset_id": "102477275037226691782080912266896459375744854273025191158751338694645017892558", "price": "0.23", "size": "46", "side": "BUY", "hash": "5483d9bc9928b0e506c56ec7c99f57485408b4a8", "best_bid": "0.26", "best_ask": "0.36"}, {"asset_id": "58436266613638193406222525170978476700361341943881268058813684153244605853496", "price": "0.77", "size": "46", "side": "SELL", "hash": "93d66a81c25d03909986e2286d5b37215795773e", "best_bid": "0.64", "best_ask": "0.74"}], "timestamp": "1769384486600", "event_type": "price_change"}}
{"_local_timestamp": "2026-01-25T23:41:30.261974+00:00", "data": {"market": "0xfbaf6c00d1702c189522a2025f8d52d01348978b16dfe5bd51d5d2f5d6712b0b", "price_changes": [{"asset_id": "102477275037226691782080912266896459375744854273025191158751338694645017892558", "price": "0.15", "size": "0", "side": "BUY", "hash": "e08f90d4c41c2ae4435e9540cbcd4cfef1036725", "best_bid": "0.26", "best_ask": "0.36"}, {"asset_id": "58436266613638193406222525170978476700361341943881268058813684153244605853496", "price": "0.85", "size": "0", "side": "SELL", "hash": "e1bdb8998e6a2ec67a28fa96a6c2bd79a53d93a4", "best_bid": "0.64", "best_ask": "0.74"}], "timestamp": "1769384490112", "event_type": "price_change"}}
{"_local_timestamp": "2026-01-25T23:41:30.854638+00:00", "data": {"market": "0xfbaf6c00d1702c189522a2025f8d52d01348978b16dfe5bd51d5d2f5d6712b0b", "price_changes": [{"asset_id": "102477275037226691782080912266896459375744854273025191158751338694645017892558", "price": "0.24", "size": "108.5", "side": "BUY", "hash": "18a80e6f718a91615c47e04d0d258107008820ad", "best_bid": "0.26", "best_ask": "0.36"}, {"asset_id": "58436266613638193406222525170978476700361341943881268058813684153244605853496", "price": "0.76", "size": "108.5", "side": "SELL", "hash": "0d4b07c17832d8220d55a0cb95bbfd4c31fe730f", "best_bid": "0.64", "best_ask": "0.74"}], "timestamp": "1769384490713", "event_type": "price_change"}}
{"_local_timestamp": "2026-01-25T23:41:42.319282+00:00", "data": {"market": "0xfbaf6c00d1702c189522a2025f8d52d01348978b16dfe5bd51d5d2f5d6712b0b", "price_changes": [{"asset_id": "102477275037226691782080912266896459375744854273025191158751338694645017892558", "price": "0.14", "size": "800", "side": "BUY", "hash": "bd03b62c17c7741f84a09c8ca3ad45e5f92d97ac", "best_bid": "0.26", "best_ask": "0.36"}, {"asset_id": "58436266613638193406222525170978476700361341943881268058813684153244605853496", "price": "0.86", "size": "800", "side": "SELL", "hash": "ed36ef8bcb78fe01385373c9fcea0106905f522f", "best_bid": "0.64", "best_ask": "0.74"}], "timestamp": "1769384502241", "event_type": "price_change"}}
{"_local_timestamp": "2026-01-25T23:41:42.320112+00:00", "data": {"market": "0xfbaf6c00d1702c189522a2025f8d52d01348978b16dfe5bd51d5d2f5d6712b0b", "price_changes": [{"asset_id": "102477275037226691782080912266896459375744854273025191158751338694645017892558", "price": "0.03", "size": "2016", "side": "BUY", "hash": "b59ea446986c85e7e3720a167c8cb8b08c15b54c", "best_bid": "0.26", "best_ask": "0.36"}, {"asset_id": "58436266613638193406222525170978476700361341943881268058813684153244605853496", "price": "0.97", "size": "2016", "side": "SELL", "hash": "f931c13583572d121ea4bb01d738ffc7fe61e1ab", "best_bid": "0.64", "best_ask": "0.74"}], "timestamp": "1769384502242", "event_type": "price_change"}}
{"_local_timestamp": "2026-01-25T23:41:50.546002+00:00", "data": {"market": "0x1abd61ad100d8895f3584b464ef167f3518e25a6030881103d14acc083ebad96", "price_changes": [{"asset_id": "91437369688558543467551854737984316990748701143376320320377387982132471568811", "price": "0.6", "size": "772.39", "side": "SELL", "hash": "5796b25320d2c08fa1d7be5b58e3b71ca5835e2c", "best_bid": "0.42", "best_ask": "0.52"}, {"asset_id": "88964156506218863777298237975219012171691782824739196411832554942435520583952", "price": "0.4", "size": "772.39", "side": "BUY", "hash": "20b907a0b146ae39d31b5b3db2d8e15f1c962a8a", "best_bid": "0.48", "best_ask": "0.58"}], "timestamp": "1769384510466", "event_type": "price_change"}}
{"_local_timestamp": "2026-01-25T23:41:51.812019+00:00", "data": {"market": "0xfbaf6c00d1702c189522a2025f8d52d01348978b16dfe5bd51d5d2f5d6712b0b", "price_changes": [{"asset_id": "102477275037226691782080912266896459375744854273025191158751338694645017892558", "price": "0.14", "size": "1200", "side": "BUY", "hash": "54a391b11badbe29cdd90b6184d36c293bb45424", "best_bid": "0.26", "best_ask": "0.36"}, {"asset_id": "58436266613638193406222525170978476700361341943881268058813684153244605853496", "price": "0.86", "size": "1200", "side": "SELL", "hash": "10734dbfb887c8d1c3d8b37a64f609f75599bdd4", "best_bid": "0.64", "best_ask": "0.74"}], "timestamp": "1769384511709", "event_type": "price_change"}}
{"_local_timestamp": "2026-01-25T23:41:51.815583+00:00", "data": {"market": "0xfbaf6c00d1702c189522a2025f8d52d01348978b16dfe5bd51d5d2f5d6712b0b", "price_changes": [{"asset_id": "102477275037226691782080912266896459375744854273025191158751338694645017892558", "price": "0.03", "size": "4016", "side": "BUY", "hash": "53f2a964a0b804c4bdb1cdf34b54f123f4581845", "best_bid": "0.26", "best_ask": "0.36"}, {"asset_id": "58436266613638193406222525170978476700361341943881268058813684153244605853496", "price": "0.97", "size": "4016", "side": "SELL", "hash": "1c0ca7d609ca5d9d839af7fd3b2706f537e1f7cd", "best_bid": "0.64", "best_ask": "0.74"}], "timestamp": "1769384511739", "event_type": "price_change"}}
{"_local_timestamp": "2026-01-25T23:41:51.816160+00:00", "data": {"market": "0xfbaf6c00d1702c189522a2025f8d52d01348978b16dfe5bd51d5d2f5d6712b0b", "price_changes": [{"asset_id": "102477275037226691782080912266896459375744854273025191158751338694645017892558", "price": "0.02", "size": "4008.7", "side": "BUY", "hash": "7a167331f80c1791be06bb6a49c9dc32cd28929b", "best_bid": "0.26", "best_ask": "0.36"}, {"asset_id": "58436266613638193406222525170978476700361341943881268058813684153244605853496", "price": "0.98", "size": "4008.7", "side": "SELL", "hash": "2105bbed957b0979f4d29749b0deaf932d8a2537", "best_bid": "0.64", "best_ask": "0.74"}], "timestamp": "1769384511742", "event_type": "price_change"}}
{"_local_timestamp": "2026-01-25T23:41:56.242024+00:00", "data": {"market": "0x5372c3942dac612d595f10ab9ee944a0fb1f521f8a0f7e5e4c69ea7f820b9205", "price_changes": [{"asset_id": "28425112653106522555623063788214711387350887710590000638731586279221931393822", "price": "0.017", "size": "0", "side": "BUY", "hash": "fc6e7bc4892ba53a71fb67cb6402f0cd5a0e9243", "best_bid": "0.81", "best_ask": "0.998"}, {"asset_id": "14539781518361540889330537982912764909191745060309412974583163279274941075133", "price": "0.983", "size": "0", "side": "SELL", "hash": "4c03a27bbf313b01f9374e6b48c70041c17ce458", "best_bid": "0.002", "best_ask": "0.19"}], "timestamp": "1769384516175", "event_type": "price_change"}}
{"_local_timestamp": "2026-01-25T23:41:56.673306+00:00", "data": {"market": "0x7a1d49664545460db0ba5e5e8b93cceb612fbc41bb771d2a301604e70b0961c5", "price_changes": [{"asset_id": "102425427310314829793465336917429668352269874891507740825471648392466296067415", "price": "0.02", "size": "25", "side": "BUY", "hash": "ad550b3c79c0f2f10e03de6f2a031639662bfead", "best_bid": "0.04", "best_ask": "0.06"}, {"asset_id": "13714707803298296385726368634232865185817279358363474279070084625804726290626", "price": "0.98", "size": "25", "side": "SELL", "hash": "a35d0e4e83d25a7409bf85394512c05dc3b9fd55", "best_bid": "0.94", "best_ask": "0.96"}], "timestamp": "1769384516604", "event_type": "price_change"}}
{"_local_timestamp": "2026-01-25T23:41:57.318602+00:00", "data": {"market": "0x5372c3942dac612d595f10ab9ee944a0fb1f521f8a0f7e5e4c69ea7f820b9205", "price_changes": [{"asset_id": "28425112653106522555623063788214711387350887710590000638731586279221931393822", "price": "0.017", "size": "5", "side": "BUY", "hash": "70c2f313cc5fc2e8360a0913b543ae2012575c30", "best_bid": "0.81", "best_ask": "0.998"}, {"asset_id": "14539781518361540889330537982912764909191745060309412974583163279274941075133", "price": "0.983", "size": "5", "side": "SELL", "hash": "d5a455cd84c4c67454eaba2995cca490ff31fa68", "best_bid": "0.002", "best_ask": "0.19"}], "timestamp": "1769384517240", "event_type": "price_change"}}
{"_local_timestamp": "2026-01-25T23:41:57.477379+00:00", "data": {"market": "0x7a1d49664545460db0ba5e5e8b93cceb612fbc41bb771d2a301604e70b0961c5", "price_changes": [{"asset_id": "102425427310314829793465336917429668352269874891507740825471648392466296067415", "price": "0.02", "size": "36.46", "side": "BUY", "hash": "8a23438955e451f3ea276f8fb150c41df4e62879", "best_bid": "0.04", "best_ask": "0.06"}, {"asset_id": "13714707803298296385726368634232865185817279358363474279070084625804726290626", "price": "0.98", "size": "36.46", "side": "SELL", "hash": "6861f3b707de88d91df9c788965063b11fa0c21c", "best_bid": "0.94", "best_ask": "0.96"}], "timestamp": "1769384517405", "event_type": "price_change"}}
{"_local_timestamp": "2026-01-25T23:41:59.453304+00:00", "data": {"market": "0x1abd61ad100d8895f3584b464ef167f3518e25a6030881103d14acc083ebad96", "price_changes": [{"asset_id": "88964156506218863777298237975219012171691782824739196411832554942435520583952", "price": "0.01", "size": "10043.4", "side": "BUY", "hash": "b7f3760150f3f1090d5cafc06aea7aaf73113e8f", "best_bid": "0.48", "best_ask": "0.58"}, {"asset_id": "91437369688558543467551854737984316990748701143376320320377387982132471568811", "price": "0.99", "size": "10043.4", "side": "SELL", "hash": "137a483c525880a01a6fb8fe754faea393509161", "best_bid": "0.42", "best_ask": "0.52"}], "timestamp": "1769384519378", "event_type": "price_change"}}
{"_local_timestamp": "2026-01-25T23:42:02.886585+00:00", "data": {"market": "0xfbaf6c00d1702c189522a2025f8d52d01348978b16dfe5bd51d5d2f5d6712b0b", "price_changes": [{"asset_id": "102477275037226691782080912266896459375744854273025191158751338694645017892558", "price": "0.03", "size": "6016", "side": "BUY", "hash": "ea5f0b861afbe3103d2df8a37f2628e283d9c68a", "best_bid": "0.26", "best_ask": "0.36"}, {"asset_id": "58436266613638193406222525170978476700361341943881268058813684153244605853496", "price": "0.97", "size": "6016", "side": "SELL", "hash": "8476bdf333b3d097e4419e14cb3f771e5346c9df", "best_bid": "0.64", "best_ask": "0.74"}], "timestamp": "1769384522810", "event_type": "price_change"}}
{"_local_timestamp": "2026-01-25T23:42:02.887048+00:00", "data": {"market": "0xfbaf6c00d1702c189522a2025f8d52d01348978b16dfe5bd51d5d2f5d6712b0b", "price_changes": [{"asset_id": "102477275037226691782080912266896459375744854273025191158751338694645017892558", "price": "0.01", "size": "15036.7", "side": "BUY", "hash": "4c075494807dc79bf0a95a5bae77e1999bc4398c", "best_bid": "0.26", "best_ask": "0.36"}, {"asset_id": "58436266613638193406222525170978476700361341943881268058813684153244605853496", "price": "0.99", "size": "15036.7", "side": "SELL", "hash": "4629804e14af0e1805cf91b32b2c21485471583e", "best_bid": "0.64", "best_ask": "0.74"}], "timestamp": "1769384522811", "event_type": "price_change"}}
{"_local_timestamp": "2026-01-25T23:42:07.342059+00:00", "data": {"market": "0xc1c29be70cd39c9f72de2ab9338c1aa8b461ebe5f4969905654bdafe679afa07", "price_changes": [{"asset_id": "50325657743512433706892707197152031907050232791405235081059080709963762445435", "price": "0.005", "size": "0", "side": "BUY", "hash": "2c4fe3688d0416aff7177ab26d12437cceb7995b", "best_bid": "0.011", "best_ask": "0.035"}, {"asset_id": "97834981188079665391659336156149815346383761304074482681876419862703828354805", "price": "0.995", "size": "0", "side": "SELL", "hash": "931ddc29852689cd7721935e3979a391494bf172", "best_bid": "0.965", "best_ask": "0.989"}], "timestamp": "1769384527272", "event_type": "price_change"}}
{"_local_timestamp": "2026-01-25T23:42:07.342548+00:00", "data": {"market": "0x0fc8dc44e3de82ae300787c180950bc3dd188e0c719d86e8559099aeb2491ff3", "price_changes": [{"asset_id": "107230676698401838350579684070148863651625417715181026919457587632470951166569", "price": "0.002", "size": "11.49", "side": "BUY", "hash": "99b3e12058328f41db036b172dd73ef9013d3df4", "best_bid": "0.011", "best_ask": "0.029"}, {"asset_id": "68332573930090360687168031629975305535066054733932461259656105000052034697965", "price": "0.998", "size": "11.49", "side": "SELL", "hash": "ead20630e7facbb9dcb098224734974f0b4edaf5", "best_bid": "0.971", "best_ask": "0.989"}], "timestamp": "1769384527272", "event_type": "price_change"}}
{"_local_timestamp": "2026-01-25T23:42:09.284221+00:00", "data": {"market": "0xc1c29be70cd39c9f72de2ab9338c1aa8b461ebe5f4969905654bdafe679afa07", "price_changes": [{"asset_id": "50325657743512433706892707197152031907050232791405235081059080709963762445435", "price": "0.005", "size": "14.59", "side": "BUY", "hash": "04288291046ae00e9e5fac3cf310585128fbc443", "best_bid": "0.011", "best_ask": "0.035"}, {"asset_id": "97834981188079665391659336156149815346383761304074482681876419862703828354805", "price": "0.995", "size": "14.59", "side": "SELL", "hash": "4bec310049a19cfa9c77d8d61a811b464189847b", "best_bid": "0.965", "best_ask": "0.989"}], "timestamp": "1769384529217", "event_type": "price_change"}}
{"_local_timestamp": "2026-01-25T23:42:09.292081+00:00", "data": {"market": "0x0fc8dc44e3de82ae300787c180950bc3dd188e0c719d86e8559099aeb2491ff3", "price_changes": [{"asset_id": "107230676698401838350579684070148863651625417715181026919457587632470951166569", "price": "0.002", "size": "23.93", "side": "BUY", "hash": "1cabc331573c4607bf36296d25952c7e37a7a721", "best_bid": "0.011", "best_ask": "0.029"}, {"asset_id": "68332573930090360687168031629975305535066054733932461259656105000052034697965", "price": "0.998", "size": "23.93", "side": "SELL", "hash": "96fc4a79bd6caaddef646be9c2e8cbc5ac93a1a1", "best_bid": "0.971", "best_ask": "0.989"}], "timestamp": "1769384529217", "event_type": "price_change"}}
{"_local_timestamp": "2026-01-25T23:42:09.556329+00:00", "data": {"market": "0x1abd61ad100d8895f3584b464ef167f3518e25a6030881103d14acc083ebad96", "price_changes": [{"asset_id": "88964156506218863777298237975219012171691782824739196411832554942435520583952", "price": "0.06", "size": "1000", "side": "BUY", "hash": "ffe58bb040ae04a4c272f637e174e8ca959798e2", "best_bid": "0.48", "best_ask": "0.58"}, {"asset_id": "91437369688558543467551854737984316990748701143376320320377387982132471568811", "price": "0.94", "size": "1000", "side": "SELL", "hash": "b3db2334b450b8a6c266f435d38e9fd1e2c6de8e", "best_bid": "0.42", "best_ask": "0.52"}], "timestamp": "1769384529485", "event_type": "price_change"}}
{"_local_timestamp": "2026-01-25T23:42:09.556829+00:00", "data": {"market": "0x1abd61ad100d8895f3584b464ef167f3518e25a6030881103d14acc083ebad96", "price_changes": [{"asset_id": "88964156506218863777298237975219012171691782824739196411832554942435520583952", "price": "0.09", "size": "700", "side": "BUY", "hash": "caf90665b53590b12dd3d87e0411e32895dfd865", "best_bid": "0.48", "best_ask": "0.58"}, {"asset_id": "91437369688558543467551854737984316990748701143376320320377387982132471568811", "price": "0.91", "size": "700", "side": "SELL", "hash": "7e098ceb39258fa1243b0bb4dbd49362573b5675", "best_bid": "0.42", "best_ask": "0.52"}], "timestamp": "1769384529486", "event_type": "price_change"}}
{"_local_timestamp": "2026-01-25T23:42:10.622956+00:00", "data": {"market": "0x1abd61ad100d8895f3584b464ef167f3518e25a6030881103d14acc083ebad96", "price_changes": [{"asset_id": "88964156506218863777298237975219012171691782824739196411832554942435520583952", "price": "0.08", "size": "700", "side": "BUY", "hash": "aa5b5fb2690f7923589ca0de65bfa0a24a609539", "best_bid": "0.48", "best_ask": "0.58"}, {"asset_id": "91437369688558543467551854737984316990748701143376320320377387982132471568811", "price": "0.92", "size": "700", "side": "SELL", "hash": "ea63120680a700e18f09a2433a4f3c3e8679756b", "best_bid": "0.42", "best_ask": "0.52"}], "timestamp": "1769384530547", "event_type": "price_change"}}
{"_local_timestamp": "2026-01-25T23:42:10.624078+00:00", "data": {"market": "0x1abd61ad100d8895f3584b464ef167f3518e25a6030881103d14acc083ebad96", "price_changes": [{"asset_id": "88964156506218863777298237975219012171691782824739196411832554942435520583952", "price": "0.06", "size": "2000", "side": "BUY", "hash": "143a176c96e1f792b2067e8de5a11bbd1565fcb2", "best_bid": "0.48", "best_ask": "0.58"}, {"asset_id": "91437369688558543467551854737984316990748701143376320320377387982132471568811", "price": "0.94", "size": "2000", "side": "SELL", "hash": "ab168c4327112282f29238bb76feb85a8262c4c2", "best_bid": "0.42", "best_ask": "0.52"}], "timestamp": "1769384530548", "event_type": "price_change"}}
{"_local_timestamp": "2026-01-25T23:42:12.740183+00:00", "data": {"market": "0x5372c3942dac612d595f10ab9ee944a0fb1f521f8a0f7e5e4c69ea7f820b9205", "price_changes": [{"asset_id": "14539781518361540889330537982912764909191745060309412974583163279274941075133", "price": "0.001", "size": "2685.67", "side": "BUY", "hash": "977283937bac8a851926b2af0b35bce3831ec397", "best_bid": "0.002", "best_ask": "0.19"}, {"asset_id": "28425112653106522555623063788214711387350887710590000638731586279221931393822", "price": "0.999", "size": "2685.67", "side": "SELL", "hash": "5a280e7b25f2f1264db8dde099c24f593f9c0f2d", "best_bid": "0.81", "best_ask": "0.998"}], "timestamp": "1769384532669", "event_type": "price_change"}}
{"_local_timestamp": "2026-01-25T23:42:26.779856+00:00", "data": {"market": "0x1abd61ad100d8895f3584b464ef167f3518e25a6030881103d14acc083ebad96", "price_changes": [{"asset_id": "88964156506218863777298237975219012171691782824739196411832554942435520583952", "price": "0.08", "size": "0", "side": "BUY", "hash": "cb4be328e3009f2ffa0533daac338c644e96cce1", "best_bid": "0.48", "best_ask": "0.58"}, {"asset_id": "91437369688558543467551854737984316990748701143376320320377387982132471568811", "price": "0.92", "size": "0", "side": "SELL", "hash": "d06e2a83bb7b0765bf107702bbb46acf607e6876", "best_bid": "0.42", "best_ask": "0.52"}], "timestamp": "1769384546707", "event_type": "price_change"}}
{"_local_timestamp": "2026-01-25T23:42:27.049771+00:00", "data": {"market": "0x1abd61ad100d8895f3584b464ef167f3518e25a6030881103d14acc083ebad96", "price_changes": [{"asset_id": "88964156506218863777298237975219012171691782824739196411832554942435520583952", "price": "0.09", "size": "1400", "side": "BUY", "hash": "94e8e3dc4dcd59b72c44be2c38ff96e55c16ca85", "best_bid": "0.48", "best_ask": "0.58"}, {"asset_id": "91437369688558543467551854737984316990748701143376320320377387982132471568811", "price": "0.91", "size": "1400", "side": "SELL", "hash": "58f7e78b7e3ba34c9e674f11f55442e790210a14", "best_bid": "0.42", "best_ask": "0.52"}], "timestamp": "1769384546977", "event_type": "price_change"}}
{"_local_timestamp": "2026-01-25T23:42:45.403370+00:00", "data": {"market": "0xfbaf6c00d1702c189522a2025f8d52d01348978b16dfe5bd51d5d2f5d6712b0b", "price_changes": [{"asset_id": "58436266613638193406222525170978476700361341943881268058813684153244605853496", "price": "0.2", "size": "0", "side": "BUY", "hash": "0c0d9a79d0e87cd6487eb826bb1f74422f64c9ed", "best_bid": "0.64", "best_ask": "0.74"}, {"asset_id": "102477275037226691782080912266896459375744854273025191158751338694645017892558", "price": "0.8", "size": "0", "side": "SELL", "hash": "56cc45737f70f47af7f2fb7f27f1a01cc87e1b60", "best_bid": "0.26", "best_ask": "0.36"}], "timestamp": "1769384565212", "event_type": "price_change"}}
{"_local_timestamp": "2026-01-25T23:42:45.404046+00:00", "data": {"market": "0xfbaf6c00d1702c189522a2025f8d52d01348978b16dfe5bd51d5d2f5d6712b0b", "price_changes": [{"asset_id": "58436266613638193406222525170978476700361341943881268058813684153244605853496", "price": "0.29", "size": "0", "side": "BUY", "hash": "0c0d9a79d0e87cd6487eb826bb1f74422f64c9ed", "best_bid": "0.64", "best_ask": "0.74"}, {"asset_id": "102477275037226691782080912266896459375744854273025191158751338694645017892558", "price": "0.71", "size": "0", "side": "SELL", "hash": "56cc45737f70f47af7f2fb7f27f1a01cc87e1b60", "best_bid": "0.26", "best_ask": "0.36"}], "timestamp": "1769384565212", "event_type": "price_change"}}
{"_local_timestamp": "2026-01-25T23:42:45.730628+00:00", "data": {"market": "0xfbaf6c00d1702c189522a2025f8d52d01348978b16dfe5bd51d5d2f5d6712b0b", "price_changes": [{"asset_id": "58436266613638193406222525170978476700361341943881268058813684153244605853496", "price": "0.21", "size": "208.7", "side": "BUY", "hash": "bfb367661805f65de0f802e35ccfe0090ddece77", "best_bid": "0.64", "best_ask": "0.74"}, {"asset_id": "102477275037226691782080912266896459375744854273025191158751338694645017892558", "price": "0.79", "size": "208.7", "side": "SELL", "hash": "f93fea2659d6f9350b8d0d9038cffda2f097aae0", "best_bid": "0.26", "best_ask": "0.36"}], "timestamp": "1769384565587", "event_type": "price_change"}}
{"_local_timestamp": "2026-01-25T23:42:45.767887+00:00", "data": {"market": "0xfbaf6c00d1702c189522a2025f8d52d01348978b16dfe5bd51d5d2f5d6712b0b", "price_changes": [{"asset_id": "58436266613638193406222525170978476700361341943881268058813684153244605853496", "price": "0.27", "size": "50", "side": "BUY", "hash": "1a1ce63312eefb43ed07d84eca8b6a2a4dd3786f", "best_bid": "0.64", "best_ask": "0.74"}, {"asset_id": "102477275037226691782080912266896459375744854273025191158751338694645017892558", "price": "0.73", "size": "50", "side": "SELL", "hash": "a5a84d01a00a357b468675a2d973def9c42d0833", "best_bid": "0.26", "best_ask": "0.36"}], "timestamp": "1769384565590", "event_type": "price_change"}}
{"_local_timestamp": "2026-01-25T23:42:47.229467+00:00", "data": {"market": "0x1abd61ad100d8895f3584b464ef167f3518e25a6030881103d14acc083ebad96", "price_changes": [{"asset_id": "91437369688558543467551854737984316990748701143376320320377387982132471568811", "price": "0.08", "size": "0", "side": "BUY", "hash": "62bff274682a2d067a4882a9b5a33c1fe7229964", "best_bid": "0.42", "best_ask": "0.52"}, {"asset_id": "88964156506218863777298237975219012171691782824739196411832554942435520583952", "price": "0.92", "size": "0", "side": "SELL", "hash": "30ca72125761d33f0d411efb21b88f66486aef84", "best_bid": "0.48", "best_ask": "0.58"}], "timestamp": "1769384566994", "event_type": "price_change"}}
{"_local_timestamp": "2026-01-25T23:42:48.594007+00:00", "data": {"market": "0xfbaf6c00d1702c189522a2025f8d52d01348978b16dfe5bd51d5d2f5d6712b0b", "price_changes": [{"asset_id": "102477275037226691782080912266896459375744854273025191158751338694645017892558", "price": "0.79", "size": "150", "side": "SELL", "hash": "262a528e9815dfa336ab7563e96a885bf5b8d636", "best_bid": "0.26", "best_ask": "0.36"}, {"asset_id": "58436266613638193406222525170978476700361341943881268058813684153244605853496", "price": "0.21", "size": "150", "side": "BUY", "hash": "0f5109465f31d6dfd113350ffbc7b1dc54667618", "best_bid": "0.64", "best_ask": "0.74"}], "timestamp": "1769384568402", "event_type": "price_change"}}
{"_local_timestamp": "2026-01-25T23:42:48.835423+00:00", "data": {"market": "0xfbaf6c00d1702c189522a2025f8d52d01348978b16dfe5bd51d5d2f5d6712b0b", "price_changes": [{"asset_id": "58436266613638193406222525170978476700361341943881268058813684153244605853496", "price": "0.21", "size": "50", "side": "BUY", "hash": "682b4dbadabdbd8cf2877149da73ee4ea2eb8d2c", "best_bid": "0.64", "best_ask": "0.74"}, {"asset_id": "102477275037226691782080912266896459375744854273025191158751338694645017892558", "price": "0.79", "size": "50", "side": "SELL", "hash": "54795ef40ad391c7d660974e3d7df3fbf0a1ad0e", "best_bid": "0.26", "best_ask": "0.36"}], "timestamp": "1769384568618", "event_type": "price_change"}}
{"_local_timestamp": "2026-01-25T23:42:48.962893+00:00", "data": {"market": "0xfbaf6c00d1702c189522a2025f8d52d01348978b16dfe5bd51d5d2f5d6712b0b", "price_changes": [{"asset_id": "102477275037226691782080912266896459375744854273025191158751338694645017892558", "price": "0.72", "size": "58.7", "side": "SELL", "hash": "5f4924be9d1406a0db3f4377e1d5adad01ddccb5", "best_bid": "0.26", "best_ask": "0.36"}, {"asset_id": "58436266613638193406222525170978476700361341943881268058813684153244605853496", "price": "0.28", "size": "58.7", "side": "BUY", "hash": "55478225fed8f91e1cbe7a2af830148dce916741", "best_bid": "0.64", "best_ask": "0.74"}], "timestamp": "1769384568781", "event_type": "price_change"}}
{"_local_timestamp": "2026-01-25T23:42:49.546254+00:00", "data": {"market": "0xfbaf6c00d1702c189522a2025f8d52d01348978b16dfe5bd51d5d2f5d6712b0b", "price_changes": [{"asset_id": "58436266613638193406222525170978476700361341943881268058813684153244605853496", "price": "0.28", "size": "158.7", "side": "BUY", "hash": "bb6a29f57afbc3146d9443b4f2e05f036f71df46", "best_bid": "0.64", "best_ask": "0.74"}, {"asset_id": "102477275037226691782080912266896459375744854273025191158751338694645017892558", "price": "0.72", "size": "158.7", "side": "SELL", "hash": "b7b28e26fdd2e74c8690f16d29998a6cd6f71ed8", "best_bid": "0.26", "best_ask": "0.36"}], "timestamp": "1769384569369", "event_type": "price_change"}}
{"_local_timestamp": "2026-01-25T23:43:02.286570+00:00", "data": {"market": "0xfbaf6c00d1702c189522a2025f8d52d01348978b16dfe5bd51d5d2f5d6712b0b", "price_changes": [{"asset_id": "58436266613638193406222525170978476700361341943881268058813684153244605853496", "price": "0.17", "size": "2870", "side": "BUY", "hash": "5748cf2bab50a441f728b22ea2de19da10717e9b", "best_bid": "0.64", "best_ask": "0.74"}, {"asset_id": "102477275037226691782080912266896459375744854273025191158751338694645017892558", "price": "0.83", "size": "2870", "side": "SELL", "hash": "912c1f6207d223aa15a9428c0b1922c41d33b0e1", "best_bid": "0.26", "best_ask": "0.36"}], "timestamp": "1769384582050", "event_type": "price_change"}}
{"_local_timestamp": "2026-01-25T23:43:12.967340+00:00", "data": {"market": "0xfbaf6c00d1702c189522a2025f8d52d01348978b16dfe5bd51d5d2f5d6712b0b", "price_changes": [{"asset_id": "58436266613638193406222525170978476700361341943881268058813684153244605853496", "price": "0.17", "size": "3370", "side": "BUY", "hash": "8753e28b339d874d0aa0882d821b45262aa7c2aa", "best_bid": "0.64", "best_ask": "0.74"}, {"asset_id": "102477275037226691782080912266896459375744854273025191158751338694645017892558", "price": "0.83", "size": "3370", "side": "SELL", "hash": "bdad6aa5b63232e4ae54eb02fc3d3d4c46a78252", "best_bid": "0.26", "best_ask": "0.36"}], "timestamp": "1769384592880", "event_type": "price_change"}}
{"_local_timestamp": "2026-01-25T23:43:22.388109+00:00", "data": {"market": "0x1abd61ad100d8895f3584b464ef167f3518e25a6030881103d14acc083ebad96", "price_changes": [{"asset_id": "91437369688558543467551854737984316990748701143376320320377387982132471568811", "price": "0.07", "size": "6000", "side": "BUY", "hash": "6954cf26bf5c315d7fd32e0382bb2541f67245a9", "best_bid": "0.42", "best_ask": "0.52"}, {"asset_id": "88964156506218863777298237975219012171691782824739196411832554942435520583952", "price": "0.93", "size": "6000", "side": "SELL", "hash": "f7963c8a693cfda76a087bb307d310192fa1a7e5", "best_bid": "0.48", "best_ask": "0.58"}], "timestamp": "1769384602320", "event_type": "price_change"}}
{"_local_timestamp": "2026-01-25T23:43:28.890825+00:00", "data": {"market": "0xfbaf6c00d1702c189522a2025f8d52d01348978b16dfe5bd51d5d2f5d6712b0b", "price_changes": [{"asset_id": "102477275037226691782080912266896459375744854273025191158751338694645017892558", "price": "0.23", "size": "10", "side": "BUY", "hash": "cb608d3be2f2ef77334c33b64fc2171cce9bd567", "best_bid": "0.26", "best_ask": "0.36"}, {"asset_id": "58436266613638193406222525170978476700361341943881268058813684153244605853496", "price": "0.77", "size": "10", "side": "SELL", "hash": "84c3ab9ccb99a1f613b440f11e4b23e3f5857100", "best_bid": "0.64", "best_ask": "0.74"}], "timestamp": "1769384608782", "event_type": "price_change"}}
{"_local_timestamp": "2026-01-25T23:43:30.849938+00:00", "data": {"market": "0xfbaf6c00d1702c189522a2025f8d52d01348978b16dfe5bd51d5d2f5d6712b0b", "price_changes": [{"asset_id": "102477275037226691782080912266896459375744854273025191158751338694645017892558", "price": "0.25", "size": "36", "side": "BUY", "hash": "c5dba4133ed77daa1b60da433ad71c770d47f3b0", "best_bid": "0.26", "best_ask": "0.36"}, {"asset_id": "58436266613638193406222525170978476700361341943881268058813684153244605853496", "price": "0.75", "size": "36", "side": "SELL", "hash": "6b9f2bfb1dc48c4c6faebe9dfab3db18480e85fd", "best_bid": "0.64", "best_ask": "0.74"}], "timestamp": "1769384610778", "event_type": "price_change"}}
{"_local_timestamp": "2026-01-25T23:43:31.439953+00:00", "data": {"market": "0xfbaf6c00d1702c189522a2025f8d52d01348978b16dfe5bd51d5d2f5d6712b0b", "price_changes": [{"asset_id": "102477275037226691782080912266896459375744854273025191158751338694645017892558", "price": "0.24", "size": "8.5", "side": "BUY", "hash": "ce80884b9a8b103acdb3dc24a9897f642ae2b7bb", "best_bid": "0.26", "best_ask": "0.36"}, {"asset_id": "58436266613638193406222525170978476700361341943881268058813684153244605853496", "price": "0.76", "size": "8.5", "side": "SELL", "hash": "bc2a67cccdad1a88388e8578a28c796eae709ff1", "best_bid": "0.64", "best_ask": "0.74"}], "timestamp": "1769384611366", "event_type": "price_change"}}
{"_local_timestamp": "2026-01-25T23:43:32.118477+00:00", "data": {"market": "0xfbaf6c00d1702c189522a2025f8d52d01348978b16dfe5bd51d5d2f5d6712b0b", "price_changes": [{"asset_id": "102477275037226691782080912266896459375744854273025191158751338694645017892558", "price": "0.15", "size": "100", "side": "BUY", "hash": "d5c1b455ffe988b14bd2c70cbef35af34cb32152", "best_bid": "0.26", "best_ask": "0.36"}, {"asset_id": "58436266613638193406222525170978476700361341943881268058813684153244605853496", "price": "0.85", "size": "100", "side": "SELL", "hash": "92adc763ecc12bb4df754de2bae49f2aecea07b1", "best_bid": "0.64", "best_ask": "0.74"}], "timestamp": "1769384612048", "event_type": "price_change"}}
{"_local_timestamp": "2026-01-25T23:43:36.561944+00:00", "data": {"market": "0xfbaf6c00d1702c189522a2025f8d52d01348978b16dfe5bd51d5d2f5d6712b0b", "price_changes": [{"asset_id": "102477275037226691782080912266896459375744854273025191158751338694645017892558", "price": "0.24", "size": "0", "side": "BUY", "hash": "627342d84bd357e13084195c44115530934dbe6d", "best_bid": "0.26", "best_ask": "0.36"}, {"asset_id": "58436266613638193406222525170978476700361341943881268058813684153244605853496", "price": "0.76", "size": "0", "side": "SELL", "hash": "8f602c417c92febc9bb561fd44d9c93970ef0a01", "best_bid": "0.64", "best_ask": "0.74"}], "timestamp": "1769384616495", "event_type": "price_change"}}
{"_local_timestamp": "2026-01-25T23:43:36.570602+00:00", "data": {"market": "0xfbaf6c00d1702c189522a2025f8d52d01348978b16dfe5bd51d5d2f5d6712b0b", "price_changes": [{"asset_id": "58436266613638193406222525170978476700361341943881268058813684153244605853496", "price": "0.41", "size": "0", "side": "BUY", "hash": "2b464335767bf2df055243db995a4a97c69dac7e", "best_bid": "0.64", "best_ask": "0.74"}, {"asset_id": "102477275037226691782080912266896459375744854273025191158751338694645017892558", "price": "0.59", "size": "0", "side": "SELL", "hash": "b3e91c2a22276838d8462799bfc2cc670a498c37", "best_bid": "0.26", "best_ask": "0.36"}], "timestamp": "1769384616495", "event_type": "price_change"}}
{"_local_timestamp": "2026-01-25T23:43:36.764726+00:00", "data": {"market": "0x61c7a2857f724184aeefcfc1d5c2d058f0b5a3d95c07e0698a8702a2044cc3f9", "price_changes": [{"asset_id": "63990477029527440251791260115609966942867460219987284386576624440536500927768", "price": "0.002", "size": "11.82", "side": "BUY", "hash": "7f155d8ed03ba53b3b9b5498dc2a3113f5ada489", "best_bid": "0.011", "best_ask": "0.035"}, {"asset_id": "16513348473820721539329266419516258589145306802106861039482427297186980662547", "price": "0.998", "size": "11.82", "side": "SELL", "hash": "696e7f563f8864a389d51bc8627a14c214638917", "best_bid": "0.965", "best_ask": "0.989"}], "timestamp": "1769384616699", "event_type": "price_change"}}
{"_local_timestamp": "2026-01-25T23:43:37.243233+00:00", "data": {"market": "0x61c7a2857f724184aeefcfc1d5c2d058f0b5a3d95c07e0698a8702a2044cc3f9", "price_changes": [{"asset_id": "63990477029527440251791260115609966942867460219987284386576624440536500927768", "price": "0.002", "size": "29.1", "side": "BUY", "hash": "4292b4f3d8049d301a11802f44e629a4118bdcc5", "best_bid": "0.011", "best_ask": "0.035"}, {"asset_id": "16513348473820721539329266419516258589145306802106861039482427297186980662547", "price": "0.998", "size": "29.1", "side": "SELL", "hash": "deee242217b7db7c745cf904d8aedcb3d3033213", "best_bid": "0.965", "best_ask": "0.989"}], "timestamp": "1769384617171", "event_type": "price_change"}}
{"_local_timestamp": "2026-01-25T23:43:46.468035+00:00", "data": {"market": "0xfbaf6c00d1702c189522a2025f8d52d01348978b16dfe5bd51d5d2f5d6712b0b", "price_changes": [{"asset_id": "102477275037226691782080912266896459375744854273025191158751338694645017892558", "price": "0.14", "size": "700", "side": "BUY", "hash": "c1b911659700be4eafc3d0b2865b622ed7bf7995", "best_bid": "0.26", "best_ask": "0.36"}, {"asset_id": "58436266613638193406222525170978476700361341943881268058813684153244605853496", "price": "0.86", "size": "700", "side": "SELL", "hash": "3500cbee152be65caf6ce689e8771b1d0fd42b44", "best_bid": "0.64", "best_ask": "0.74"}], "timestamp": "1769384626401", "event_type": "price_change"}}
{"_local_timestamp": "2026-01-25T23:43:46.471108+00:00", "data": {"market": "0xfbaf6c00d1702c189522a2025f8d52d01348978b16dfe5bd51d5d2f5d6712b0b", "price_changes": [{"asset_id": "102477275037226691782080912266896459375744854273025191158751338694645017892558", "price": "0.03", "size": "4016", "side": "BUY", "hash": "c1b911659700be4eafc3d0b2865b622ed7bf7995", "best_bid": "0.26", "best_ask": "0.36"}, {"asset_id": "58436266613638193406222525170978476700361341943881268058813684153244605853496", "price": "0.97", "size": "4016", "side": "SELL", "hash": "3500cbee152be65caf6ce689e8771b1d0fd42b44", "best_bid": "0.64", "best_ask": "0.74"}], "timestamp": "1769384626401", "event_type": "price_change"}}
{"_local_timestamp": "2026-01-25T23:43:50.633123+00:00", "data": {"market": "0x61c7a2857f724184aeefcfc1d5c2d058f0b5a3d95c07e0698a8702a2044cc3f9", "price_changes": [{"asset_id": "16513348473820721539329266419516258589145306802106861039482427297186980662547", "price": "0.94", "size": "0", "side": "BUY", "hash": "f24edd802fac74c84f8d9be6756f7fc6c1428562", "best_bid": "0.965", "best_ask": "0.989"}, {"asset_id": "63990477029527440251791260115609966942867460219987284386576624440536500927768", "price": "0.06", "size": "0", "side": "SELL", "hash": "441e93e18aa884ce013db922dce72729f30a8c6d", "best_bid": "0.011", "best_ask": "0.035"}], "timestamp": "1769384630563", "event_type": "price_change"}}
{"_local_timestamp": "2026-01-25T23:43:51.673553+00:00", "data": {"market": "0x61c7a2857f724184aeefcfc1d5c2d058f0b5a3d95c07e0698a8702a2044cc3f9", "price_changes": [{"asset_id": "16513348473820721539329266419516258589145306802106861039482427297186980662547", "price": "0.941", "size": "20", "side": "BUY", "hash": "3cc702c822c92421905a6f317932fcd37087c7cc", "best_bid": "0.965", "best_ask": "0.989"}, {"asset_id": "63990477029527440251791260115609966942867460219987284386576624440536500927768", "price": "0.059", "size": "20", "side": "SELL", "hash": "9103ebccb33ff1cee2c5de615c74b53f004cd24b", "best_bid": "0.011", "best_ask": "0.035"}], "timestamp": "1769384631597", "event_type": "price_change"}}
{"_local_timestamp": "2026-01-25T23:43:56.417466+00:00", "data": {"market": "0xfbaf6c00d1702c189522a2025f8d52d01348978b16dfe5bd51d5d2f5d6712b0b", "price_changes": [{"asset_id": "102477275037226691782080912266896459375744854273025191158751338694645017892558", "price": "0.03", "size": "2016", "side": "BUY", "hash": "5c65cf26614f6eeeac019831a3324ca18a74d78a", "best_bid": "0.26", "best_ask": "0.36"}, {"asset_id": "58436266613638193406222525170978476700361341943881268058813684153244605853496", "price": "0.97", "size": "2016", "side": "SELL", "hash": "1331bf385e7c3510595850bfbe343d4cfe6f0322", "best_bid": "0.64", "best_ask": "0.74"}], "timestamp": "1769384636350", "event_type": "price_change"}}
{"_local_timestamp": "2026-01-25T23:43:56.420169+00:00", "data": {"market": "0xfbaf6c00d1702c189522a2025f8d52d01348978b16dfe5bd51d5d2f5d6712b0b", "price_changes": [{"asset_id": "102477275037226691782080912266896459375744854273025191158751338694645017892558", "price": "0.01", "size": "10036.7", "side": "BUY", "hash": "5c65cf26614f6eeeac019831a3324ca18a74d78a", "best_bid": "0.26", "best_ask": "0.36"}, {"asset_id": "58436266613638193406222525170978476700361341943881268058813684153244605853496", "price": "0.99", "size": "10036.7", "side": "SELL", "hash": "1331bf385e7c3510595850bfbe343d4cfe6f0322", "best_bid": "0.64", "best_ask": "0.74"}], "timestamp": "1769384636350", "event_type": "price_change"}}
{"_local_timestamp": "2026-01-25T23:43:57.102275+00:00", "data": {"market": "0xfbaf6c00d1702c189522a2025f8d52d01348978b16dfe5bd51d5d2f5d6712b0b", "price_changes": [{"asset_id": "102477275037226691782080912266896459375744854273025191158751338694645017892558", "price": "0.14", "size": "300", "side": "BUY", "hash": "bf0b14b2077eae07c5f819bdc3aede28d3b12763", "best_bid": "0.26", "best_ask": "0.36"}, {"asset_id": "58436266613638193406222525170978476700361341943881268058813684153244605853496", "price": "0.86", "size": "300", "side": "SELL", "hash": "7675bba37b1eace022d8e152893bdf1e67b139f1", "best_bid": "0.64", "best_ask": "0.74"}], "timestamp": "1769384637011", "event_type": "price_change"}}
{"_local_timestamp": "2026-01-25T23:43:57.107370+00:00", "data": {"market": "0xfbaf6c00d1702c189522a2025f8d52d01348978b16dfe5bd51d5d2f5d6712b0b", "price_changes": [{"asset_id": "102477275037226691782080912266896459375744854273025191158751338694645017892558", "price": "0.03", "size": "16", "side": "BUY", "hash": "bf0b14b2077eae07c5f819bdc3aede28d3b12763", "best_bid": "0.26", "best_ask": "0.36"}, {"asset_id": "58436266613638193406222525170978476700361341943881268058813684153244605853496", "price": "0.97", "size": "16", "side": "SELL", "hash": "7675bba37b1eace022d8e152893bdf1e67b139f1", "best_bid": "0.64", "best_ask": "0.74"}], "timestamp": "1769384637011", "event_type": "price_change"}}
{"_local_timestamp": "2026-01-25T23:43:57.107819+00:00", "data": {"market": "0xfbaf6c00d1702c189522a2025f8d52d01348978b16dfe5bd51d5d2f5d6712b0b", "price_changes": [{"asset_id": "102477275037226691782080912266896459375744854273025191158751338694645017892558", "price": "0.02", "size": "2008.7", "side": "BUY", "hash": "bf0b14b2077eae07c5f819bdc3aede28d3b12763", "best_bid": "0.26", "best_ask": "0.36"}, {"asset_id": "58436266613638193406222525170978476700361341943881268058813684153244605853496", "price": "0.98", "size": "2008.7", "side": "SELL", "hash": "7675bba37b1eace022d8e152893bdf1e67b139f1", "best_bid": "0.64", "best_ask": "0.74"}], "timestamp": "1769384637011", "event_type": "price_change"}}
{"_local_timestamp": "2026-01-25T23:44:04.181196+00:00", "data": {"market": "0x5372c3942dac612d595f10ab9ee944a0fb1f521f8a0f7e5e4c69ea7f820b9205", "price_changes": [{"asset_id": "28425112653106522555623063788214711387350887710590000638731586279221931393822", "price": "0.017", "size": "0", "side": "BUY", "hash": "d108a0e33ba2448894e2586f0448f222047476cb", "best_bid": "0.81", "best_ask": "0.998"}, {"asset_id": "14539781518361540889330537982912764909191745060309412974583163279274941075133", "price": "0.983", "size": "0", "side": "SELL", "hash": "7ae2ccdb1766b0eab97ac1bd18edf6f083355816", "best_bid": "0.002", "best_ask": "0.19"}], "timestamp": "1769384644114", "event_type": "price_change"}}
{"_local_timestamp": "2026-01-25T23:44:04.486392+00:00", "data": {"market": "0x5372c3942dac612d595f10ab9ee944a0fb1f521f8a0f7e5e4c69ea7f820b9205", "price_changes": [{"asset_id": "28425112653106522555623063788214711387350887710590000638731586279221931393822", "price": "0.017", "size": "5", "side": "BUY", "hash": "bbc99a993371d60904758dd0d4aec55b52b9fc3b", "best_bid": "0.81", "best_ask": "0.998"}, {"asset_id": "14539781518361540889330537982912764909191745060309412974583163279274941075133", "price": "0.983", "size": "5", "side": "SELL", "hash": "30c8db0cc9e430e1abd9e885d24704b7df91e675", "best_bid": "0.002", "best_ask": "0.19"}], "timestamp": "1769384644417", "event_type": "price_change"}}
{"_local_timestamp": "2026-01-25T23:44:07.572981+00:00", "data": {"market": "0x0fc8dc44e3de82ae300787c180950bc3dd188e0c719d86e8559099aeb2491ff3", "price_changes": [{"asset_id": "107230676698401838350579684070148863651625417715181026919457587632470951166569", "price": "0.002", "size": "11.49", "side": "BUY", "hash": "01e96a67fed64c6eedd1940b38e6f846e93e762d", "best_bid": "0.011", "best_ask": "0.029"}, {"asset_id": "68332573930090360687168031629975305535066054733932461259656105000052034697965", "price": "0.998", "size": "11.49", "side": "SELL", "hash": "74b9ba9b4ecdfe5dccbde476644713e9b271563a", "best_bid": "0.971", "best_ask": "0.989"}], "timestamp": "1769384647504", "event_type": "price_change"}}
{"_local_timestamp": "2026-01-25T23:44:07.961297+00:00", "data": {"market": "0x0fc8dc44e3de82ae300787c180950bc3dd188e0c719d86e8559099aeb2491ff3", "price_changes": [{"asset_id": "107230676698401838350579684070148863651625417715181026919457587632470951166569", "price": "0.003", "size": "8.28", "side": "BUY", "hash": "3fbf4476a475de267b5ed4aadb46fa14fa122c2e", "best_bid": "0.011", "best_ask": "0.029"}, {"asset_id": "68332573930090360687168031629975305535066054733932461259656105000052034697965", "price": "0.997", "size": "8.28", "side": "SELL", "hash": "19ceaf3b910a0fd3f467eb261801338c64ca299a", "best_bid": "0.971", "best_ask": "0.989"}], "timestamp": "1769384647889", "event_type": "price_change"}}
{"_local_timestamp": "2026-01-25T23:44:19.602624+00:00", "data": {"market": "0xfbaf6c00d1702c189522a2025f8d52d01348978b16dfe5bd51d5d2f5d6712b0b", "price_changes": [{"asset_id": "102477275037226691782080912266896459375744854273025191158751338694645017892558", "price": "0.25", "size": "0", "side": "BUY", "hash": "82535dc303f206ddecb6ee8a348ae952e08d9c26", "best_bid": "0.26", "best_ask": "0.36"}, {"asset_id": "58436266613638193406222525170978476700361341943881268058813684153244605853496", "price": "0.75", "size": "0", "side": "SELL", "hash": "86b2c450839cf7d2886ea9fd1193e1dd20797f3c", "best_bid": "0.64", "best_ask": "0.74"}], "timestamp": "1769384659524", "event_type": "price_change"}}
{"_local_timestamp": "2026-01-25T23:44:19.921430+00:00", "data": {"market": "0xfbaf6c00d1702c189522a2025f8d52d01348978b16dfe5bd51d5d2f5d6712b0b", "price_changes": [{"asset_id": "102477275037226691782080912266896459375744854273025191158751338694645017892558", "price": "0.23", "size": "46", "side": "BUY", "hash": "603bb8bbc11d2ad4cf9a834ed2eafb29c408da19", "best_bid": "0.26", "best_ask": "0.36"}, {"asset_id": "58436266613638193406222525170978476700361341943881268058813684153244605853496", "price": "0.77", "size": "46", "side": "SELL", "hash": "ebd82e3fd1837ed5d6014d1bd1c425fe40a65abb", "best_bid": "0.64", "best_ask": "0.74"}], "timestamp": "1769384659814", "event_type": "price_change"}}
{"_local_timestamp": "2026-01-25T23:44:19.992742+00:00", "data": {"market": "0xfbaf6c00d1702c189522a2025f8d52d01348978b16dfe5bd51d5d2f5d6712b0b", "price_changes": [{"asset_id": "102477275037226691782080912266896459375744854273025191158751338694645017892558", "price": "0.23", "size": "36", "side": "BUY", "hash": "104dd6cad155fdea51dbe35d73ebf58ae6e952eb", "best_bid": "0.26", "best_ask": "0.36"}, {"asset_id": "58436266613638193406222525170978476700361341943881268058813684153244605853496", "price": "0.77", "size": "36", "side": "SELL", "hash": "934f5f05151278ff74c504b77dd086735988341e", "best_bid": "0.64", "best_ask": "0.74"}], "timestamp": "1769384659901", "event_type": "price_change"}}
{"_local_timestamp": "2026-01-25T23:44:20.058045+00:00", "data": {"market": "0xfbaf6c00d1702c189522a2025f8d52d01348978b16dfe5bd51d5d2f5d6712b0b", "price_changes": [{"asset_id": "102477275037226691782080912266896459375744854273025191158751338694645017892558", "price": "0.16", "size": "10", "side": "BUY", "hash": "c0fc6cfb9302293ad1ab18c3d14108fc0cf746bb", "best_bid": "0.26", "best_ask": "0.36"}, {"asset_id": "58436266613638193406222525170978476700361341943881268058813684153244605853496", "price": "0.84", "size": "10", "side": "SELL", "hash": "a19d8b09baa4502d69183730c922fa9dfdb82fd9", "best_bid": "0.64", "best_ask": "0.74"}], "timestamp": "1769384659992", "event_type": "price_change"}}
{"_local_timestamp": "2026-01-25T23:44:26.804800+00:00", "data": {"market": "0xfbaf6c00d1702c189522a2025f8d52d01348978b16dfe5bd51d5d2f5d6712b0b", "price_changes": [{"asset_id": "58436266613638193406222525170978476700361341943881268058813684153244605853496", "price": "0.41", "size": "8.5", "side": "BUY", "hash": "0ba30a57f7835871b60b0ef00bad3a0d3cc094c6", "best_bid": "0.64", "best_ask": "0.74"}, {"asset_id": "102477275037226691782080912266896459375744854273025191158751338694645017892558", "price": "0.59", "size": "8.5", "side": "SELL", "hash": "09ac80e016bd2db84337b26b65d641ab4bc63c24", "best_bid": "0.26", "best_ask": "0.36"}], "timestamp": "1769384666730", "event_type": "price_change"}}
{"_local_timestamp": "2026-01-25T23:44:26.805787+00:00", "data": {"market": "0xfbaf6c00d1702c189522a2025f8d52d01348978b16dfe5bd51d5d2f5d6712b0b", "price_changes": [{"asset_id": "102477275037226691782080912266896459375744854273025191158751338694645017892558", "price": "0.24", "size": "8.5", "side": "BUY", "hash": "010b00c4466a214e40750a18e7a5e75af7eb1ae9", "best_bid": "0.26", "best_ask": "0.36"}, {"asset_id": "58436266613638193406222525170978476700361341943881268058813684153244605853496", "price": "0.76", "size": "8.5", "side": "SELL", "hash": "0d3cafee054ce0c43e7baa583b109e0f23d9223e", "best_bid": "0.64", "best_ask": "0.74"}], "timestamp": "1769384666730", "event_type": "price_change"}}
{"_local_timestamp": "2026-01-25T23:44:32.456185+00:00", "data": {"market": "0x1abd61ad100d8895f3584b464ef167f3518e25a6030881103d14acc083ebad96", "price_changes": [{"asset_id": "91437369688558543467551854737984316990748701143376320320377387982132471568811", "price": "0.07", "size": "0", "side": "BUY", "hash": "e4c10280d31a18a8b8ec2482dea173b7707f46ef", "best_bid": "0.42", "best_ask": "0.52"}, {"asset_id": "88964156506218863777298237975219012171691782824739196411832554942435520583952", "price": "0.93", "size": "0", "side": "SELL", "hash": "97f6449464f63e964d8f27d7e078fa86c9327c85", "best_bid": "0.48", "best_ask": "0.58"}], "timestamp": "1769384672300", "event_type": "price_change"}}
{"_local_timestamp": "2026-01-25T23:44:42.270002+00:00", "data": {"market": "0x1abd61ad100d8895f3584b464ef167f3518e25a6030881103d14acc083ebad96", "price_changes": [{"asset_id": "91437369688558543467551854737984316990748701143376320320377387982132471568811", "price": "0.08", "size": "5250", "side": "BUY", "hash": "9b7ca14340dc20b5286fd8d145f973ee76e4817f", "best_bid": "0.42", "best_ask": "0.52"}, {"asset_id": "88964156506218863777298237975219012171691782824739196411832554942435520583952", "price": "0.92", "size": "5250", "side": "SELL", "hash": "77347a4c4e40d9f58ad6819177993e9ffd61f628", "best_bid": "0.48", "best_ask": "0.58"}], "timestamp": "1769384682193", "event_type": "price_change"}}
{"_local_timestamp": "2026-01-25T23:44:44.353964+00:00", "data": {"market": "0x61c7a2857f724184aeefcfc1d5c2d058f0b5a3d95c07e0698a8702a2044cc3f9", "price_changes": [{"asset_id": "63990477029527440251791260115609966942867460219987284386576624440536500927768", "price": "0.002", "size": "11.82", "side": "BUY", "hash": "d9f0d4a56d22cdce5c5e80541311520fff657485", "best_bid": "0.011", "best_ask": "0.035"}, {"asset_id": "16513348473820721539329266419516258589145306802106861039482427297186980662547", "price": "0.998", "size": "11.82", "side": "SELL", "hash": "c12e3c3283ebb27b22f15ad62018b06c09268061", "best_bid": "0.965", "best_ask": "0.989"}], "timestamp": "1769384684289", "event_type": "price_change"}}
{"_local_timestamp": "2026-01-25T23:44:44.810676+00:00", "data": {"market": "0x61c7a2857f724184aeefcfc1d5c2d058f0b5a3d95c07e0698a8702a2044cc3f9", "price_changes": [{"asset_id": "63990477029527440251791260115609966942867460219987284386576624440536500927768", "price": "0.002", "size": "29.09", "side": "BUY", "hash": "d2593231ba556ed87732c506a9fc8a7eae6d6370", "best_bid": "0.011", "best_ask": "0.035"}, {"asset_id": "16513348473820721539329266419516258589145306802106861039482427297186980662547", "price": "0.998", "size": "29.09", "side": "SELL", "hash": "d6a9c8005dccfaacdb9b6f4514c3746d8001288a", "best_bid": "0.965", "best_ask": "0.989"}], "timestamp": "1769384684732", "event_type": "price_change"}}
{"_local_timestamp": "2026-01-25T23:44:49.811874+00:00", "data": {"market": "0xfbaf6c00d1702c189522a2025f8d52d01348978b16dfe5bd51d5d2f5d6712b0b", "price_changes": [{"asset_id": "58436266613638193406222525170978476700361341943881268058813684153244605853496", "price": "0.64", "size": "0", "side": "BUY", "hash": "72ef58f80e9e53dd117ff02554024084abd81d71", "best_bid": "0.63", "best_ask": "0.74"}, {"asset_id": "102477275037226691782080912266896459375744854273025191158751338694645017892558", "price": "0.36", "size": "0", "side": "SELL", "hash": "71afad7841e5afa6c98bf30f4beb7cbf8389542a", "best_bid": "0.26", "best_ask": "0.37"}], "timestamp": "1769384689730", "event_type": "price_change"}}
{"_local_timestamp": "2026-01-25T23:44:49.850847+00:00", "data": {"market": "0xfbaf6c00d1702c189522a2025f8d52d01348978b16dfe5bd51d5d2f5d6712b0b", "price_changes": [{"asset_id": "102477275037226691782080912266896459375744854273025191158751338694645017892558", "price": "0.26", "size": "0", "side": "BUY", "hash": "8246a67046be63206442e8edaf1c56a685066173", "best_bid": "0.24", "best_ask": "0.37"}, {"asset_id": "58436266613638193406222525170978476700361341943881268058813684153244605853496", "price": "0.74", "size": "0", "side": "SELL", "hash": "f95c9f69f8255d21c1c0a11b626bf52b214727d8", "best_bid": "0.63", "best_ask": "0.76"}], "timestamp": "1769384689784", "event_type": "price_change"}}
{"_local_timestamp": "2026-01-25T23:44:56.221915+00:00", "data": {"market": "0x1abd61ad100d8895f3584b464ef167f3518e25a6030881103d14acc083ebad96", "price_changes": [{"asset_id": "88964156506218863777298237975219012171691782824739196411832554942435520583952", "price": "0.01", "size": "11043.4", "side": "BUY", "hash": "73c79c089db6ec3b9d9522f76e54261d10fc18a9", "best_bid": "0.48", "best_ask": "0.58"}, {"asset_id": "91437369688558543467551854737984316990748701143376320320377387982132471568811", "price": "0.99", "size": "11043.4", "side": "SELL", "hash": "438b0ce6f17ae4771edb96d2dc6fd1554878f1fe", "best_bid": "0.42", "best_ask": "0.52"}], "timestamp": "1769384696156", "event_type": "price_change"}}
{"_local_timestamp": "2026-01-25T23:44:56.723579+00:00", "data": {"market": "0xfbaf6c00d1702c189522a2025f8d52d01348978b16dfe5bd51d5d2f5d6712b0b", "price_changes": [{"asset_id": "58436266613638193406222525170978476700361341943881268058813684153244605853496", "price": "0.41", "size": "0", "side": "BUY", "hash": "58319ab97afa056f6d917e0b28e0d1bf1bfbc1d5", "best_bid": "0.63", "best_ask": "0.76"}, {"asset_id": "102477275037226691782080912266896459375744854273025191158751338694645017892558", "price": "0.59", "size": "0", "side": "SELL", "hash": "ddb8bf4a2857d5dcc1e97c88be8305eed8dd09b1", "best_bid": "0.24", "best_ask": "0.37"}], "timestamp": "1769384696656", "event_type": "price_change"}}
{"_local_timestamp": "2026-01-25T23:44:56.764283+00:00", "data": {"market": "0xfbaf6c00d1702c189522a2025f8d52d01348978b16dfe5bd51d5d2f5d6712b0b", "price_changes": [{"asset_id": "58436266613638193406222525170978476700361341943881268058813684153244605853496", "price": "0.29", "size": "8.5", "side": "BUY", "hash": "8c0879845857b3f91e2d05307b7b0fa457c292db", "best_bid": "0.63", "best_ask": "0.76"}, {"asset_id": "102477275037226691782080912266896459375744854273025191158751338694645017892558", "price": "0.71", "size": "8.5", "side": "SELL", "hash": "e295538b4a759c53d75ec8217ae7a004e976327a", "best_bid": "0.24", "best_ask": "0.37"}], "timestamp": "1769384696694", "event_type": "price_change"}}
{"_local_timestamp": "2026-01-25T23:44:57.827675+00:00", "data": {"market": "0xfbaf6c00d1702c189522a2025f8d52d01348978b16dfe5bd51d5d2f5d6712b0b", "price_changes": [{"asset_id": "58436266613638193406222525170978476700361341943881268058813684153244605853496", "price": "0.21", "size": "0", "side": "BUY", "hash": "489539bae795a7a4f83a1a97be99df538623fa47", "best_bid": "0.63", "best_ask": "0.76"}, {"asset_id": "102477275037226691782080912266896459375744854273025191158751338694645017892558", "price": "0.79", "size": "0", "side": "SELL", "hash": "8ca09a699825de61a577a7162f4771b466f7b91f", "best_bid": "0.24", "best_ask": "0.37"}], "timestamp": "1769384697731", "event_type": "price_change"}}
{"_local_timestamp": "2026-01-25T23:44:57.829990+00:00", "data": {"market": "0xfbaf6c00d1702c189522a2025f8d52d01348978b16dfe5bd51d5d2f5d6712b0b", "price_changes": [{"asset_id": "58436266613638193406222525170978476700361341943881268058813684153244605853496", "price": "0.27", "size": "0", "side": "BUY", "hash": "489539bae795a7a4f83a1a97be99df538623fa47", "best_bid": "0.63", "best_ask": "0.76"}, {"asset_id": "102477275037226691782080912266896459375744854273025191158751338694645017892558", "price": "0.73", "size": "0", "side": "SELL", "hash": "8ca09a699825de61a577a7162f4771b466f7b91f", "best_bid": "0.24", "best_ask": "0.37"}], "timestamp": "1769384697731", "event_type": "price_change"}}
{"_local_timestamp": "2026-01-25T23:44:58.311549+00:00", "data": {"market": "0xfbaf6c00d1702c189522a2025f8d52d01348978b16dfe5bd51d5d2f5d6712b0b", "price_changes": [{"asset_id": "58436266613638193406222525170978476700361341943881268058813684153244605853496", "price": "0.28", "size": "208.7", "side": "BUY", "hash": "74d5f7858158433c7150391ac011ca2509894567", "best_bid": "0.63", "best_ask": "0.76"}, {"asset_id": "102477275037226691782080912266896459375744854273025191158751338694645017892558", "price": "0.72", "size": "208.7", "side": "SELL", "hash": "17a0abf9131145f092c6ce13307bc97cb8ca84af", "best_bid": "0.24", "best_ask": "0.37"}], "timestamp": "1769384698214", "event_type": "price_change"}}
{"_local_timestamp": "2026-01-25T23:44:58.383052+00:00", "data": {"market": "0xfbaf6c00d1702c189522a2025f8d52d01348978b16dfe5bd51d5d2f5d6712b0b", "price_changes": [{"asset_id": "58436266613638193406222525170978476700361341943881268058813684153244605853496", "price": "0.2", "size": "50", "side": "BUY", "hash": "f4cfdcd7f21339b506b5be238ee0937bfe3278e7", "best_bid": "0.63", "best_ask": "0.76"}, {"asset_id": "102477275037226691782080912266896459375744854273025191158751338694645017892558", "price": "0.8", "size": "50", "side": "SELL", "hash": "63b2e1729c58b635f0aa0e5ee2bf29ff64c01537", "best_bid": "0.24", "best_ask": "0.37"}], "timestamp": "1769384698230", "event_type": "price_change"}}
{"_local_timestamp": "2026-01-25T23:44:58.799598+00:00", "data": {"market": "0x1abd61ad100d8895f3584b464ef167f3518e25a6030881103d14acc083ebad96", "price_changes": [{"asset_id": "88964156506218863777298237975219012171691782824739196411832554942435520583952", "price": "0.1", "size": "4200", "side": "BUY", "hash": "41ccdd4383c324d928e45ec6a5c627e93353ca44", "best_bid": "0.48", "best_ask": "0.58"}, {"asset_id": "91437369688558543467551854737984316990748701143376320320377387982132471568811", "price": "0.9", "size": "4200", "side": "SELL", "hash": "51bc273fafe2c52695c41aeaafff496a76eb4a27", "best_bid": "0.42", "best_ask": "0.52"}], "timestamp": "1769384698722", "event_type": "price_change"}}
{"_local_timestamp": "2026-01-25T23:45:01.022964+00:00", "data": {"market": "0xfbaf6c00d1702c189522a2025f8d52d01348978b16dfe5bd51d5d2f5d6712b0b", "price_changes": [{"asset_id": "102477275037226691782080912266896459375744854273025191158751338694645017892558", "price": "0.72", "size": "150", "side": "SELL", "hash": "21d11da335e6aa86b03449fa2864a6a2e8837219", "best_bid": "0.24", "best_ask": "0.37"}, {"asset_id": "58436266613638193406222525170978476700361341943881268058813684153244605853496", "price": "0.28", "size": "150", "side": "BUY", "hash": "039b1ff21b61627d0821b5c07b633385b9812135", "best_bid": "0.63", "best_ask": "0.76"}], "timestamp": "1769384700945", "event_type": "price_change"}}
{"_local_timestamp": "2026-01-25T23:45:01.578771+00:00", "data": {"market": "0xfbaf6c00d1702c189522a2025f8d52d01348978b16dfe5bd51d5d2f5d6712b0b", "price_changes": [{"asset_id": "102477275037226691782080912266896459375744854273025191158751338694645017892558", "price": "0.71", "size": "67.2", "side": "SELL", "hash": "091dc6665bd7a85c395ed8f1e2402e8097d7f857", "best_bid": "0.24", "best_ask": "0.37"}, {"asset_id": "58436266613638193406222525170978476700361341943881268058813684153244605853496", "price": "0.29", "size": "67.2", "side": "BUY", "hash": "ff1121e410bbea88fd96fe15a50f32042e379695", "best_bid": "0.63", "best_ask": "0.76"}], "timestamp": "1769384701511", "event_type": "price_change"}}
{"_local_timestamp": "2026-01-25T23:45:01.616449+00:00", "data": {"market": "0xfbaf6c00d1702c189522a2025f8d52d01348978b16dfe5bd51d5d2f5d6712b0b", "price_changes": [{"asset_id": "58436266613638193406222525170978476700361341943881268058813684153244605853496", "price": "0.28", "size": "50", "side": "BUY", "hash": "d16f1df059337add69d530f64212dc198a047607", "best_bid": "0.63", "best_ask": "0.76"}, {"asset_id": "102477275037226691782080912266896459375744854273025191158751338694645017892558", "price": "0.72", "size": "50", "side": "SELL", "hash": "d419b0c7dae2dff3e69782e54a707e5ae1f8f459", "best_bid": "0.24", "best_ask": "0.37"}], "timestamp": "1769384701541", "event_type": "price_change"}}
{"_local_timestamp": "2026-01-25T23:45:02.244544+00:00", "data": {"market": "0xfbaf6c00d1702c189522a2025f8d52d01348978b16dfe5bd51d5d2f5d6712b0b", "price_changes": [{"asset_id": "58436266613638193406222525170978476700361341943881268058813684153244605853496", "price": "0.29", "size": "167.2", "side": "BUY", "hash": "06dac45ecc25dc865076f85cafcf2f0f5773b7bc", "best_bid": "0.63", "best_ask": "0.76"}, {"asset_id": "102477275037226691782080912266896459375744854273025191158751338694645017892558", "price": "0.71", "size": "167.2", "side": "SELL", "hash": "c6c25d2757b349b31c5989da84c57db592284e17", "best_bid": "0.24", "best_ask": "0.37"}], "timestamp": "1769384702170", "event_type": "price_change"}}
{"_local_timestamp": "2026-01-25T23:45:05.300584+00:00", "data": {"market": "0xfbaf6c00d1702c189522a2025f8d52d01348978b16dfe5bd51d5d2f5d6712b0b", "price_changes": [{"asset_id": "58436266613638193406222525170978476700361341943881268058813684153244605853496", "price": "0.29", "size": "158.7", "side": "BUY", "hash": "45d20301a55249f7190568e434a8aa5444d85c81", "best_bid": "0.63", "best_ask": "0.76"}, {"asset_id": "102477275037226691782080912266896459375744854273025191158751338694645017892558", "price": "0.71", "size": "158.7", "side": "SELL", "hash": "18661c1720b6a61cc53cc9617420c29f86e3c2c0", "best_bid": "0.24", "best_ask": "0.37"}], "timestamp": "1769384705210", "event_type": "price_change"}}
{"_local_timestamp": "2026-01-25T23:45:05.339852+00:00", "data": {"market": "0x1abd61ad100d8895f3584b464ef167f3518e25a6030881103d14acc083ebad96", "price_changes": [{"asset_id": "91437369688558543467551854737984316990748701143376320320377387982132471568811", "price": "0.24", "size": "8.5", "side": "BUY", "hash": "4c66b2e45433964f2aba230e78f84f5811b2e0e0", "best_bid": "0.42", "best_ask": "0.52"}, {"asset_id": "88964156506218863777298237975219012171691782824739196411832554942435520583952", "price": "0.76", "size": "8.5", "side": "SELL", "hash": "4ea2624c82c119ee3a306ba99280a795690b221f", "best_bid": "0.48", "best_ask": "0.58"}], "timestamp": "1769384705268", "event_type": "price_change"}}
{"_local_timestamp": "2026-01-25T23:45:05.340498+00:00", "data": {"market": "0xfbaf6c00d1702c189522a2025f8d52d01348978b16dfe5bd51d5d2f5d6712b0b", "price_changes": [{"asset_id": "58436266613638193406222525170978476700361341943881268058813684153244605853496", "price": "0.26", "size": "8.5", "side": "BUY", "hash": "97561993d31704490e4983e348c5daa41838ef4c", "best_bid": "0.63", "best_ask": "0.76"}, {"asset_id": "102477275037226691782080912266896459375744854273025191158751338694645017892558", "price": "0.74", "size": "8.5", "side": "SELL", "hash": "921fccf8a956926c838636d2a14300f7445ca042", "best_bid": "0.24", "best_ask": "0.37"}], "timestamp": "1769384705268", "event_type": "price_change"}}
{"_local_timestamp": "2026-01-25T23:45:05.341005+00:00", "data": {"market": "0x1abd61ad100d8895f3584b464ef167f3518e25a6030881103d14acc083ebad96", "price_changes": [{"asset_id": "88964156506218863777298237975219012171691782824739196411832554942435520583952", "price": "0.11", "size": "9.19", "side": "BUY", "hash": "b940b0bc882ae9050efcd98ccb53f3fa64f50c9e", "best_bid": "0.48", "best_ask": "0.58"}, {"asset_id": "91437369688558543467551854737984316990748701143376320320377387982132471568811", "price": "0.89", "size": "9.19", "side": "SELL", "hash": "00860f74b0af20759df5fc224b93b961c8151b13", "best_bid": "0.42", "best_ask": "0.52"}], "timestamp": "1769384705269", "event_type": "price_change"}}
{"_local_timestamp": "2026-01-25T23:45:06.084061+00:00", "data": {"market": "0x5372c3942dac612d595f10ab9ee944a0fb1f521f8a0f7e5e4c69ea7f820b9205", "price_changes": [{"asset_id": "28425112653106522555623063788214711387350887710590000638731586279221931393822", "price": "0.017", "size": "0", "side": "BUY", "hash": "c8767f70433f417150f50a8dc79a443ae96466dc", "best_bid": "0.81", "best_ask": "0.998"}, {"asset_id": "14539781518361540889330537982912764909191745060309412974583163279274941075133", "price": "0.983", "size": "0", "side": "SELL", "hash": "c21413f6da91eb893d308defca2f3966deecaf64", "best_bid": "0.002", "best_ask": "0.19"}], "timestamp": "1769384706005", "event_type": "price_change"}}
{"_local_timestamp": "2026-01-25T23:45:06.244935+00:00", "data": {"market": "0x5372c3942dac612d595f10ab9ee944a0fb1f521f8a0f7e5e4c69ea7f820b9205", "price_changes": [{"asset_id": "28425112653106522555623063788214711387350887710590000638731586279221931393822", "price": "0.017", "size": "5", "side": "BUY", "hash": "c0514502d2c3c51b5ba8bd16f76051df03d275c1", "best_bid": "0.81", "best_ask": "0.998"}, {"asset_id": "14539781518361540889330537982912764909191745060309412974583163279274941075133", "price": "0.983", "size": "5", "side": "SELL", "hash": "ba7a59c512c8a835e55712820bfeb67c16e4bc09", "best_bid": "0.002", "best_ask": "0.19"}], "timestamp": "1769384706175", "event_type": "price_change"}}
{"_local_timestamp": "2026-01-25T23:45:08.410921+00:00", "data": {"market": "0xfbaf6c00d1702c189522a2025f8d52d01348978b16dfe5bd51d5d2f5d6712b0b", "price_changes": [{"asset_id": "58436266613638193406222525170978476700361341943881268058813684153244605853496", "price": "0.26", "size": "0", "side": "BUY", "hash": "f899e154baee39dc84d916588d4d41976e5c5d57", "best_bid": "0.63", "best_ask": "0.76"}, {"asset_id": "102477275037226691782080912266896459375744854273025191158751338694645017892558", "price": "0.74", "size": "0", "side": "SELL", "hash": "2affe46a027266b8ac62a562960e2cf3927e6520", "best_bid": "0.24", "best_ask": "0.37"}], "timestamp": "1769384708345", "event_type": "price_change"}}
{"_local_timestamp": "2026-01-25T23:45:08.453673+00:00", "data": {"market": "0xfbaf6c00d1702c189522a2025f8d52d01348978b16dfe5bd51d5d2f5d6712b0b", "price_changes": [{"asset_id": "58436266613638193406222525170978476700361341943881268058813684153244605853496", "price": "0.3", "size": "8.5", "side": "BUY", "hash": "aa78a3cd8b2fc737623826f2f3eb6783fee6663a", "best_bid": "0.63", "best_ask": "0.76"}, {"asset_id": "102477275037226691782080912266896459375744854273025191158751338694645017892558", "price": "0.7", "size": "8.5", "side": "SELL", "hash": "4126d59d4aef90c620b60019869e078ad98d8fa4", "best_bid": "0.24", "best_ask": "0.37"}], "timestamp": "1769384708381", "event_type": "price_change"}}
{"_local_timestamp": "2026-01-25T23:45:12.248616+00:00", "data": {"market": "0x1abd61ad100d8895f3584b464ef167f3518e25a6030881103d14acc083ebad96", "price_changes": [{"asset_id": "88964156506218863777298237975219012171691782824739196411832554942435520583952", "price": "0.09", "size": "700", "side": "BUY", "hash": "1d00a6258a6e26566899e7eb226c80b0d9915753", "best_bid": "0.48", "best_ask": "0.58"}, {"asset_id": "91437369688558543467551854737984316990748701143376320320377387982132471568811", "price": "0.91", "size": "700", "side": "SELL", "hash": "6bde175004b607d15cb8cecd27b00221daff1cf6", "best_bid": "0.42", "best_ask": "0.52"}], "timestamp": "1769384712176", "event_type": "price_change"}}
{"_local_timestamp": "2026-01-25T23:45:12.508801+00:00", "data": {"market": "0x1abd61ad100d8895f3584b464ef167f3518e25a6030881103d14acc083ebad96", "price_changes": [{"asset_id": "88964156506218863777298237975219012171691782824739196411832554942435520583952", "price": "0.1", "size": "4900", "side": "BUY", "hash": "5cb6cfb1766c72d309bb7b075d6ddac0ad825e26", "best_bid": "0.48", "best_ask": "0.58"}, {"asset_id": "91437369688558543467551854737984316990748701143376320320377387982132471568811", "price": "0.9", "size": "4900", "side": "SELL", "hash": "5d2b6632c92162a54d7eb1b128b085ac738f2254", "best_bid": "0.42", "best_ask": "0.52"}], "timestamp": "1769384712438", "event_type": "price_change"}}
{"_local_timestamp": "2026-01-25T23:45:14.893785+00:00", "data": {"market": "0x5372c3942dac612d595f10ab9ee944a0fb1f521f8a0f7e5e4c69ea7f820b9205", "price_changes": [{"asset_id": "14539781518361540889330537982912764909191745060309412974583163279274941075133", "price": "0.001", "size": "2639", "side": "BUY", "hash": "74a2d2514679ae2873851199d7b7fcd448c7486d", "best_bid": "0.002", "best_ask": "0.19"}, {"asset_id": "28425112653106522555623063788214711387350887710590000638731586279221931393822", "price": "0.999", "size": "2639", "side": "SELL", "hash": "7d5c442b6fc5c496292e8cc33ff00a7463792106", "best_bid": "0.81", "best_ask": "0.998"}], "timestamp": "1769384714811", "event_type": "price_change"}}
{"_local_timestamp": "2026-01-25T23:45:15.386708+00:00", "data": {"market": "0x5372c3942dac612d595f10ab9ee944a0fb1f521f8a0f7e5e4c69ea7f820b9205", "price_changes": [{"asset_id": "14539781518361540889330537982912764909191745060309412974583163279274941075133", "price": "0.001", "size": "2685.64", "side": "BUY", "hash": "7222a9eb129e22c14ef478cf9cbb295a16638812", "best_bid": "0.002", "best_ask": "0.19"}, {"asset_id": "28425112653106522555623063788214711387350887710590000638731586279221931393822", "price": "0.999", "size": "2685.64", "side": "SELL", "hash": "2939dee4b8cbb376d5735958c22a97ad216aff70", "best_bid": "0.81", "best_ask": "0.998"}], "timestamp": "1769384715311", "event_type": "price_change"}}
{"_local_timestamp": "2026-01-25T23:45:15.759450+00:00", "data": {"market": "0x5372c3942dac612d595f10ab9ee944a0fb1f521f8a0f7e5e4c69ea7f820b9205", "price_changes": [{"asset_id": "14539781518361540889330537982912764909191745060309412974583163279274941075133", "price": "0.001", "size": "2639", "side": "BUY", "hash": "db737076e2e4be0b2f600d54de98ece71c11c120", "best_bid": "0.002", "best_ask": "0.19"}, {"asset_id": "28425112653106522555623063788214711387350887710590000638731586279221931393822", "price": "0.999", "size": "2639", "side": "SELL", "hash": "a8460b2a0788ed7b965c43167768d73b2eb8e23e", "best_bid": "0.81", "best_ask": "0.998"}], "timestamp": "1769384715691", "event_type": "price_change"}}
{"_local_timestamp": "2026-01-25T23:45:16.360301+00:00", "data": {"market": "0x5372c3942dac612d595f10ab9ee944a0fb1f521f8a0f7e5e4c69ea7f820b9205", "price_changes": [{"asset_id": "14539781518361540889330537982912764909191745060309412974583163279274941075133", "price": "0.001", "size": "2685.64", "side": "BUY", "hash": "1776cfccecad47e42f13e7cb528eeb963ed3e597", "best_bid": "0.002", "best_ask": "0.19"}, {"asset_id": "28425112653106522555623063788214711387350887710590000638731586279221931393822", "price": "0.999", "size": "2685.64", "side": "SELL", "hash": "4541c71944c4ad36a4b7be25a55cc5adde96526c", "best_bid": "0.81", "best_ask": "0.998"}], "timestamp": "1769384716282", "event_type": "price_change"}}
{"_local_timestamp": "2026-01-25T23:45:20.732537+00:00", "data": {"market": "0xfbaf6c00d1702c189522a2025f8d52d01348978b16dfe5bd51d5d2f5d6712b0b", "price_changes": [{"asset_id": "58436266613638193406222525170978476700361341943881268058813684153244605853496", "price": "0.53", "size": "20.75", "side": "BUY", "hash": "f3dcf390d16a9d4d214856c9a087ea221f036467", "best_bid": "0.63", "best_ask": "0.76"}, {"asset_id": "102477275037226691782080912266896459375744854273025191158751338694645017892558", "price": "0.47", "size": "20.75", "side": "SELL", "hash": "055ee4ab94c127d93970242af0f8ceef57cacebd", "best_bid": "0.24", "best_ask": "0.37"}], "timestamp": "1769384720661", "event_type": "price_change"}}
{"_local_timestamp": "2026-01-25T23:45:20.788652+00:00", "data": {"market": "0x1abd61ad100d8895f3584b464ef167f3518e25a6030881103d14acc083ebad96", "price_changes": [{"asset_id": "88964156506218863777298237975219012171691782824739196411832554942435520583952", "price": "0.09", "size": "0", "side": "BUY", "hash": "f923952af3a2fdde591c90f0043cdac425aa03a7", "best_bid": "0.48", "best_ask": "0.58"}, {"asset_id": "91437369688558543467551854737984316990748701143376320320377387982132471568811", "price": "0.91", "size": "0", "side": "SELL", "hash": "eff035717792f595c8437dbdb73ddbddb46841e6", "best_bid": "0.42", "best_ask": "0.52"}], "timestamp": "1769384720717", "event_type": "price_change"}}
{"_local_timestamp": "2026-01-25T23:45:20.820507+00:00", "data": {"market": "0xfbaf6c00d1702c189522a2025f8d52d01348978b16dfe5bd51d5d2f5d6712b0b", "price_changes": [{"asset_id": "58436266613638193406222525170978476700361341943881268058813684153244605853496", "price": "0.52", "size": "35", "side": "BUY", "hash": "2137dc6b28ada2c2c6d59fa07f0808afdb82fa19", "best_bid": "0.63", "best_ask": "0.76"}, {"asset_id": "102477275037226691782080912266896459375744854273025191158751338694645017892558", "price": "0.48", "size": "35", "side": "SELL", "hash": "bb070851f0102670d804420fc91bcad658f6262c", "best_bid": "0.24", "best_ask": "0.37"}], "timestamp": "1769384720754", "event_type": "price_change"}}
{"_local_timestamp": "2026-01-25T23:45:21.054058+00:00", "data": {"market": "0x1abd61ad100d8895f3584b464ef167f3518e25a6030881103d14acc083ebad96", "price_changes": [{"asset_id": "88964156506218863777298237975219012171691782824739196411832554942435520583952", "price": "0.1", "size": "5600", "side": "BUY", "hash": "fc28cd307030232055e294d2e7f20ff4f56808bf", "best_bid": "0.48", "best_ask": "0.58"}, {"asset_id": "91437369688558543467551854737984316990748701143376320320377387982132471568811", "price": "0.9", "size": "5600", "side": "SELL", "hash": "bd0f44d6ea726b445e1dcc49cc544f5f5a69893c", "best_bid": "0.42", "best_ask": "0.52"}], "timestamp": "1769384720984", "event_type": "price_change"}}
{"_local_timestamp": "2026-01-25T23:45:22.429410+00:00", "data": {"market": "0x5372c3942dac612d595f10ab9ee944a0fb1f521f8a0f7e5e4c69ea7f820b9205", "price_changes": [{"asset_id": "28425112653106522555623063788214711387350887710590000638731586279221931393822", "price": "0.017", "size": "0", "side": "BUY", "hash": "d84777d1d5c0d36440bb5992963d37e45579724f", "best_bid": "0.81", "best_ask": "0.998"}, {"asset_id": "14539781518361540889330537982912764909191745060309412974583163279274941075133", "price": "0.983", "size": "0", "side": "SELL", "hash": "b4809a96af23a45561c057f4f568c4c977c79819", "best_bid": "0.002", "best_ask": "0.19"}], "timestamp": "1769384722360", "event_type": "price_change"}}
{"_local_timestamp": "2026-01-25T23:45:22.924753+00:00", "data": {"market": "0x5372c3942dac612d595f10ab9ee944a0fb1f521f8a0f7e5e4c69ea7f820b9205", "price_changes": [{"asset_id": "28425112653106522555623063788214711387350887710590000638731586279221931393822", "price": "0.017", "size": "5", "side": "BUY", "hash": "df8c7ae309f57973bb2e384c8c0921bf0bb5bf92", "best_bid": "0.81", "best_ask": "0.998"}, {"asset_id": "14539781518361540889330537982912764909191745060309412974583163279274941075133", "price": "0.983", "size": "5", "side": "SELL", "hash": "54381df3b9f2cc87831dddce9028e5659452b4d5", "best_bid": "0.002", "best_ask": "0.19"}], "timestamp": "1769384722860", "event_type": "price_change"}}
{"_local_timestamp": "2026-01-25T23:45:27.150073+00:00", "data": {"market": "0xc1c29be70cd39c9f72de2ab9338c1aa8b461ebe5f4969905654bdafe679afa07", "price_changes": [{"asset_id": "50325657743512433706892707197152031907050232791405235081059080709963762445435", "price": "0.005", "size": "0", "side": "BUY", "hash": "9737b7c9ccf9f7cd8d93fe856dd7a561edbd7646", "best_bid": "0.011", "best_ask": "0.035"}, {"asset_id": "97834981188079665391659336156149815346383761304074482681876419862703828354805", "price": "0.995", "size": "0", "side": "SELL", "hash": "b4711b5840cc83223af451cbadbf4afb1d195d05", "best_bid": "0.965", "best_ask": "0.989"}], "timestamp": "1769384727081", "event_type": "price_change"}}
{"_local_timestamp": "2026-01-25T23:45:27.898665+00:00", "data": {"market": "0xc1c29be70cd39c9f72de2ab9338c1aa8b461ebe5f4969905654bdafe679afa07", "price_changes": [{"asset_id": "50325657743512433706892707197152031907050232791405235081059080709963762445435", "price": "0.006", "size": "12.15", "side": "BUY", "hash": "560150ea39350d4c9df247ee033639c0bf8abdb4", "best_bid": "0.011", "best_ask": "0.035"}, {"asset_id": "97834981188079665391659336156149815346383761304074482681876419862703828354805", "price": "0.994", "size": "12.15", "side": "SELL", "hash": "1ceac874258ee2626f7f86a03e95ca8214c15507", "best_bid": "0.965", "best_ask": "0.989"}], "timestamp": "1769384727827", "event_type": "price_change"}}
{"_local_timestamp": "2026-01-25T23:45:37.704676+00:00", "data": {"market": "0x0fc8dc44e3de82ae300787c180950bc3dd188e0c719d86e8559099aeb2491ff3", "price_changes": [{"asset_id": "107230676698401838350579684070148863651625417715181026919457587632470951166569", "price": "0.003", "size": "0", "side": "BUY", "hash": "47782b1b34654f6c60a27370fda4da9c9e9f0a66", "best_bid": "0.011", "best_ask": "0.029"}, {"asset_id": "68332573930090360687168031629975305535066054733932461259656105000052034697965", "price": "0.997", "size": "0", "side": "SELL", "hash": "f865d993e649ad20d6be4d4c600c623903669f28", "best_bid": "0.971", "best_ask": "0.989"}], "timestamp": "1769384737633", "event_type": "price_change"}}
{"_local_timestamp": "2026-01-25T23:45:38.135053+00:00", "data": {"market": "0x0fc8dc44e3de82ae300787c180950bc3dd188e0c719d86e8559099aeb2491ff3", "price_changes": [{"asset_id": "107230676698401838350579684070148863651625417715181026919457587632470951166569", "price": "0.002", "size": "23.9", "side": "BUY", "hash": "5ca2ac71a82be06f8ca9807bfa9e65f1c1f93e32", "best_bid": "0.011", "best_ask": "0.029"}, {"asset_id": "68332573930090360687168031629975305535066054733932461259656105000052034697965", "price": "0.998", "size": "23.9", "side": "SELL", "hash": "d20561c2db0bccf3f5bc270512eb0efaa737f721", "best_bid": "0.971", "best_ask": "0.989"}], "timestamp": "1769384738042", "event_type": "price_change"}}
{"_local_timestamp": "2026-01-25T23:45:56.306241+00:00", "data": {"market": "0x1abd61ad100d8895f3584b464ef167f3518e25a6030881103d14acc083ebad96", "price_changes": [{"asset_id": "91437369688558543467551854737984316990748701143376320320377387982132471568811", "price": "0.12", "size": "900", "side": "BUY", "hash": "bebd2ce921fa84bc4dc0bd9cb9c7f5f183c16c11", "best_bid": "0.42", "best_ask": "0.52"}, {"asset_id": "88964156506218863777298237975219012171691782824739196411832554942435520583952", "price": "0.88", "size": "900", "side": "SELL", "hash": "c275ae325247a18d0ef083bd1643339a43771f66", "best_bid": "0.48", "best_ask": "0.58"}], "timestamp": "1769384756075", "event_type": "price_change"}}
{"_local_timestamp": "2026-01-25T23:45:56.308703+00:00", "data": {"market": "0x1abd61ad100d8895f3584b464ef167f3518e25a6030881103d14acc083ebad96", "price_changes": [{"asset_id": "88964156506218863777298237975219012171691782824739196411832554942435520583952", "price": "0.16", "size": "0", "side": "BUY", "hash": "7ca9bc556a6a29a0aec47fb926608661f56f2f15", "best_bid": "0.48", "best_ask": "0.58"}, {"asset_id": "91437369688558543467551854737984316990748701143376320320377387982132471568811", "price": "0.84", "size": "0", "side": "SELL", "hash": "604abeaca045666d345fc316265b643b162664c6", "best_bid": "0.42", "best_ask": "0.52"}], "timestamp": "1769384756109", "event_type": "price_change"}}
{"_local_timestamp": "2026-01-25T23:45:56.779008+00:00", "data": {"market": "0xfbaf6c00d1702c189522a2025f8d52d01348978b16dfe5bd51d5d2f5d6712b0b", "price_changes": [{"asset_id": "58436266613638193406222525170978476700361341943881268058813684153244605853496", "price": "0.25", "size": "0", "side": "BUY", "hash": "086716910d0e9f9d58ba8f08f0cc4d9d733be843", "best_bid": "0.63", "best_ask": "0.76"}, {"asset_id": "102477275037226691782080912266896459375744854273025191158751338694645017892558", "price": "0.75", "size": "0", "side": "SELL", "hash": "704ab6d3e3994d43acda62b181d3c62e91f1eaa4", "best_bid": "0.24", "best_ask": "0.37"}], "timestamp": "1769384756091", "event_type": "price_change"}}
{"_local_timestamp": "2026-01-25T23:45:56.782382+00:00", "data": {"market": "0xfbaf6c00d1702c189522a2025f8d52d01348978b16dfe5bd51d5d2f5d6712b0b", "price_changes": [{"asset_id": "102477275037226691782080912266896459375744854273025191158751338694645017892558", "price": "0.14", "size": "0", "side": "BUY", "hash": "ef1e8ee1ec2f63d6d56dcf0ab2337f56708f7cbb", "best_bid": "0.24", "best_ask": "0.37"}, {"asset_id": "58436266613638193406222525170978476700361341943881268058813684153244605853496", "price": "0.86", "size": "0", "side": "SELL", "hash": "a5e002ba23d5530fc431ea4d5e01ae07f07c06fa", "best_bid": "0.63", "best_ask": "0.76"}], "timestamp": "1769384756146", "event_type": "price_change"}}
{"_local_timestamp": "2026-01-25T23:46:00.888613+00:00", "data": {"market": "0x7a1d49664545460db0ba5e5e8b93cceb612fbc41bb771d2a301604e70b0961c5", "price_changes": [{"asset_id": "102425427310314829793465336917429668352269874891507740825471648392466296067415", "price": "0.02", "size": "25", "side": "BUY", "hash": "7ba25f4f807bfed6ff8b6dc00a1d1e3a0b11a268", "best_bid": "0.04", "best_ask": "0.06"}, {"asset_id": "13714707803298296385726368634232865185817279358363474279070084625804726290626", "price": "0.98", "size": "25", "side": "SELL", "hash": "6bf4b683db0cfd14b9c74be5ce8bcebe46a6c4c1", "best_bid": "0.94", "best_ask": "0.96"}], "timestamp": "1769384760817", "event_type": "price_change"}}
{"_local_timestamp": "2026-01-25T23:46:01.125892+00:00", "data": {"market": "0xfbaf6c00d1702c189522a2025f8d52d01348978b16dfe5bd51d5d2f5d6712b0b", "price_changes": [{"asset_id": "102477275037226691782080912266896459375744854273025191158751338694645017892558", "price": "0.71", "size": "100", "side": "SELL", "hash": "197a59bbf97a4e6a6bba4927bcfb2518d20cb018", "best_bid": "0.24", "best_ask": "0.37"}, {"asset_id": "58436266613638193406222525170978476700361341943881268058813684153244605853496", "price": "0.29", "size": "100", "side": "BUY", "hash": "02c49fa206f41f58345bacd6f54f1849a2117313", "best_bid": "0.63", "best_ask": "0.76"}], "timestamp": "1769384761058", "event_type": "price_change"}}
{"_local_timestamp": "2026-01-25T23:46:01.278832+00:00", "data": {"market": "0x7a1d49664545460db0ba5e5e8b93cceb612fbc41bb771d2a301604e70b0961c5", "price_changes": [{"asset_id": "102425427310314829793465336917429668352269874891507740825471648392466296067415", "price": "0.02", "size": "36.45", "side": "BUY", "hash": "5c9ef41ac541da3400ea9a6cdc0643f9878c2de9", "best_bid": "0.04", "best_ask": "0.06"}, {"asset_id": "13714707803298296385726368634232865185817279358363474279070084625804726290626", "price": "0.98", "size": "36.45", "side": "SELL", "hash": "0eeddc60a2adca1f037aff727a0b0558a130386b", "best_bid": "0.94", "best_ask": "0.96"}], "timestamp": "1769384761214", "event_type": "price_change"}}
{"_local_timestamp": "2026-01-25T23:46:01.562985+00:00", "data": {"market": "0xfbaf6c00d1702c189522a2025f8d52d01348978b16dfe5bd51d5d2f5d6712b0b", "price_changes": [{"asset_id": "102477275037226691782080912266896459375744854273025191158751338694645017892558", "price": "0.79", "size": "58.7", "side": "SELL", "hash": "93df17c7e912ee11607d0c863b48cd1ee697d351", "best_bid": "0.24", "best_ask": "0.37"}, {"asset_id": "58436266613638193406222525170978476700361341943881268058813684153244605853496", "price": "0.21", "size": "58.7", "side": "BUY", "hash": "0e0064e682b008de2053b13ce3cc2309caff0e9f", "best_bid": "0.63", "best_ask": "0.76"}], "timestamp": "1769384761486", "event_type": "price_change"}}
{"_local_timestamp": "2026-01-25T23:46:01.601254+00:00", "data": {"market": "0xfbaf6c00d1702c189522a2025f8d52d01348978b16dfe5bd51d5d2f5d6712b0b", "price_changes": [{"asset_id": "58436266613638193406222525170978476700361341943881268058813684153244605853496", "price": "0.29", "size": "0", "side": "BUY", "hash": "7c9cad59c18cdf70438b5b6e5e18b94b7c299747", "best_bid": "0.63", "best_ask": "0.76"}, {"asset_id": "102477275037226691782080912266896459375744854273025191158751338694645017892558", "price": "0.71", "size": "0", "side": "SELL", "hash": "9cc481985cb522b347cf6dd34ef375fa4036fb5e", "best_bid": "0.24", "best_ask": "0.37"}], "timestamp": "1769384761526", "event_type": "price_change"}}
{"_local_timestamp": "2026-01-25T23:46:01.601970+00:00", "data": {"market": "0xfbaf6c00d1702c189522a2025f8d52d01348978b16dfe5bd51d5d2f5d6712b0b", "price_changes": [{"asset_id": "102477275037226691782080912266896459375744854273025191158751338694645017892558", "price": "0.15", "size": "0", "side": "BUY", "hash": "ff064a8c9ef861f248fa93212bb74dfa2163531d", "best_bid": "0.24", "best_ask": "0.37"}, {"asset_id": "58436266613638193406222525170978476700361341943881268058813684153244605853496", "price": "0.85", "size": "0", "side": "SELL", "hash": "46bff25ae11839b011ad2112d1860474bced7c5d", "best_bid": "0.63", "best_ask": "0.76"}], "timestamp": "1769384761527", "event_type": "price_change"}}
{"_local_timestamp": "2026-01-25T23:46:02.421453+00:00", "data": {"market": "0xfbaf6c00d1702c189522a2025f8d52d01348978b16dfe5bd51d5d2f5d6712b0b", "price_changes": [{"asset_id": "102477275037226691782080912266896459375744854273025191158751338694645017892558", "price": "0.14", "size": "100", "side": "BUY", "hash": "40737e12bf4208d21bbd3c79933173226f33bb27", "best_bid": "0.24", "best_ask": "0.37"}, {"asset_id": "58436266613638193406222525170978476700361341943881268058813684153244605853496", "price": "0.86", "size": "100", "side": "SELL", "hash": "b2e670d19ea3ee8c921cd667807468792040c168", "best_bid": "0.63", "best_ask": "0.76"}], "timestamp": "1769384762347", "event_type": "price_change"}}
{"_local_timestamp": "2026-01-25T23:46:02.441343+00:00", "data": {"market": "0xfbaf6c00d1702c189522a2025f8d52d01348978b16dfe5bd51d5d2f5d6712b0b", "price_changes": [{"asset_id": "58436266613638193406222525170978476700361341943881268058813684153244605853496", "price": "0.21", "size": "158.7", "side": "BUY", "hash": "ac52efa11e7cf11f9bf908cb6b5059f4a7c72c83", "best_bid": "0.63", "best_ask": "0.76"}, {"asset_id": "102477275037226691782080912266896459375744854273025191158751338694645017892558", "price": "0.79", "size": "158.7", "side": "SELL", "hash": "faa07edfe989850c049bfd94c8ebeab2f9e4c23c", "best_bid": "0.24", "best_ask": "0.37"}], "timestamp": "1769384762354", "event_type": "price_change"}}
{"_local_timestamp": "2026-01-25T23:46:04.640027+00:00", "data": {"market": "0x1abd61ad100d8895f3584b464ef167f3518e25a6030881103d14acc083ebad96", "price_changes": [{"asset_id": "88964156506218863777298237975219012171691782824739196411832554942435520583952", "price": "0.01", "size": "12043.4", "side": "BUY", "hash": "a6fa197a251221b0045c854e7380c6f66917d8de", "best_bid": "0.48", "best_ask": "0.58"}, {"asset_id": "91437369688558543467551854737984316990748701143376320320377387982132471568811", "price": "0.99", "size": "12043.4", "side": "SELL", "hash": "4e3b69575c5dba863a9f03b75bd0120cd0946ef1", "best_bid": "0.42", "best_ask": "0.52"}], "timestamp": "1769384764566", "event_type": "price_change"}}
{"_local_timestamp": "2026-01-25T23:46:06.395578+00:00", "data": {"market": "0x5372c3942dac612d595f10ab9ee944a0fb1f521f8a0f7e5e4c69ea7f820b9205", "price_changes": [{"asset_id": "28425112653106522555623063788214711387350887710590000638731586279221931393822", "price": "0.017", "size": "0", "side": "BUY", "hash": "f8ea711b6f08a2d456dd15798bf74fe2a3d2d1dd", "best_bid": "0.81", "best_ask": "0.998"}, {"asset_id": "14539781518361540889330537982912764909191745060309412974583163279274941075133", "price": "0.983", "size": "0", "side": "SELL", "hash": "3c4507e4415c36065578072188d06d2b71194869", "best_bid": "0.002", "best_ask": "0.19"}], "timestamp": "1769384766324", "event_type": "price_change"}}
{"_local_timestamp": "2026-01-25T23:46:06.711112+00:00", "data": {"market": "0x5372c3942dac612d595f10ab9ee944a0fb1f521f8a0f7e5e4c69ea7f820b9205", "price_changes": [{"asset_id": "28425112653106522555623063788214711387350887710590000638731586279221931393822", "price": "0.017", "size": "5", "side": "BUY", "hash": "7b9883cab85dfc710c9dc2afa19c7478e2f80b3c", "best_bid": "0.81", "best_ask": "0.998"}, {"asset_id": "14539781518361540889330537982912764909191745060309412974583163279274941075133", "price": "0.983", "size": "5", "side": "SELL", "hash": "7bd8a49a7e34a39f3550c19f8fc0171a9631df83", "best_bid": "0.002", "best_ask": "0.19"}], "timestamp": "1769384766640", "event_type": "price_change"}}
{"_local_timestamp": "2026-01-25T23:46:06.889339+00:00", "data": {"market": "0xfbaf6c00d1702c189522a2025f8d52d01348978b16dfe5bd51d5d2f5d6712b0b", "price_changes": [{"asset_id": "58436266613638193406222525170978476700361341943881268058813684153244605853496", "price": "0.3", "size": "0", "side": "BUY", "hash": "0b34e6359df3b5f5ed7802405da1783821a80e7f", "best_bid": "0.63", "best_ask": "0.76"}, {"asset_id": "102477275037226691782080912266896459375744854273025191158751338694645017892558", "price": "0.7", "size": "0", "side": "SELL", "hash": "cc0ab802a523760172c003e9c6170a5204daa1f3", "best_bid": "0.24", "best_ask": "0.37"}], "timestamp": "1769384766813", "event_type": "price_change"}}
{"_local_timestamp": "2026-01-25T23:46:06.922061+00:00", "data": {"market": "0xfbaf6c00d1702c189522a2025f8d52d01348978b16dfe5bd51d5d2f5d6712b0b", "price_changes": [{"asset_id": "58436266613638193406222525170978476700361341943881268058813684153244605853496", "price": "0.22", "size": "8.5", "side": "BUY", "hash": "42bd08d5879d1aac20b414e4f680f2b8feac2d94", "best_bid": "0.63", "best_ask": "0.76"}, {"asset_id": "102477275037226691782080912266896459375744854273025191158751338694645017892558", "price": "0.78", "size": "8.5", "side": "SELL", "hash": "e3d17a99129305cc92a35bfa04c99c6e6b7ef947", "best_bid": "0.24", "best_ask": "0.37"}], "timestamp": "1769384766849", "event_type": "price_change"}}
{"_local_timestamp": "2026-01-25T23:46:10.537605+00:00", "data": {"market": "0x1abd61ad100d8895f3584b464ef167f3518e25a6030881103d14acc083ebad96", "price_changes": [{"asset_id": "91437369688558543467551854737984316990748701143376320320377387982132471568811", "price": "0.08", "size": "0", "side": "BUY", "hash": "c31e60d174ee73843acd6b2455c0cb0999321022", "best_bid": "0.42", "best_ask": "0.52"}, {"asset_id": "88964156506218863777298237975219012171691782824739196411832554942435520583952", "price": "0.92", "size": "0", "side": "SELL", "hash": "b22c4106542078817234979924cd2d4376a6b13e", "best_bid": "0.48", "best_ask": "0.58"}], "timestamp": "1769384770459", "event_type": "price_change"}}
{"_local_timestamp": "2026-01-25T23:46:10.559392+00:00", "data": {"market": "0x1abd61ad100d8895f3584b464ef167f3518e25a6030881103d14acc083ebad96", "price_changes": [{"asset_id": "88964156506218863777298237975219012171691782824739196411832554942435520583952", "price": "0.1", "size": "1400", "side": "BUY", "hash": "447c8527bb120cd6dc20b3792e06f8e79dcac61a", "best_bid": "0.48", "best_ask": "0.58"}, {"asset_id": "91437369688558543467551854737984316990748701143376320320377387982132471568811", "price": "0.9", "size": "1400", "side": "SELL", "hash": "a7d7bee1a12c71dc480fcc8beebf69cc7e8f22cd", "best_bid": "0.42", "best_ask": "0.52"}], "timestamp": "1769384770464", "event_type": "price_change"}}
{"_local_timestamp": "2026-01-25T23:46:16.651153+00:00", "data": {"market": "0xfbaf6c00d1702c189522a2025f8d52d01348978b16dfe5bd51d5d2f5d6712b0b", "price_changes": [{"asset_id": "58436266613638193406222525170978476700361341943881268058813684153244605853496", "price": "0.17", "size": "2870", "side": "BUY", "hash": "133acc5e247a2e20ad73c8ff82afe04c4c56315f", "best_bid": "0.63", "best_ask": "0.76"}, {"asset_id": "102477275037226691782080912266896459375744854273025191158751338694645017892558", "price": "0.83", "size": "2870", "side": "SELL", "hash": "e1f1d600c7cd93da8f473f4031da6af63c82dc3e", "best_bid": "0.24", "best_ask": "0.37"}], "timestamp": "1769384776581", "event_type": "price_change"}}
{"_local_timestamp": "2026-01-25T23:46:17.882004+00:00", "data": {"market": "0x1abd61ad100d8895f3584b464ef167f3518e25a6030881103d14acc083ebad96", "price_changes": [{"asset_id": "91437369688558543467551854737984316990748701143376320320377387982132471568811", "price": "0.01", "size": "12043.05", "side": "BUY", "hash": "7bd51a6b7f2361623a62c271dd46f51adab1d9b1", "best_bid": "0.42", "best_ask": "0.52"}, {"asset_id": "88964156506218863777298237975219012171691782824739196411832554942435520583952", "price": "0.99", "size": "12043.05", "side": "SELL", "hash": "ed9cf49eef1ae7f541fb7c34c58a5be9766f07fb", "best_bid": "0.48", "best_ask": "0.58"}], "timestamp": "1769384777805", "event_type": "price_change"}}
{"_local_timestamp": "2026-01-25T23:46:19.956741+00:00", "data": {"market": "0x1abd61ad100d8895f3584b464ef167f3518e25a6030881103d14acc083ebad96", "price_changes": [{"asset_id": "88964156506218863777298237975219012171691782824739196411832554942435520583952", "price": "0.11", "size": "3827.19", "side": "BUY", "hash": "fcf7bac02348e83f13ca3c29bb6538feaa81ee45", "best_bid": "0.48", "best_ask": "0.58"}, {"asset_id": "91437369688558543467551854737984316990748701143376320320377387982132471568811", "price": "0.89", "size": "3827.19", "side": "SELL", "hash": "2f6fca3b670114749c690a4792bdb4c2e8456ac5", "best_bid": "0.42", "best_ask": "0.52"}], "timestamp": "1769384779888", "event_type": "price_change"}}
{"_local_timestamp": "2026-01-25T23:46:20.630800+00:00", "data": {"market": "0xfbaf6c00d1702c189522a2025f8d52d01348978b16dfe5bd51d5d2f5d6712b0b", "price_changes": [{"asset_id": "58436266613638193406222525170978476700361341943881268058813684153244605853496", "price": "0.18", "size": "300", "side": "BUY", "hash": "173eac586e9ebba7ccd732c3d7c17d1048f8d334", "best_bid": "0.63", "best_ask": "0.76"}, {"asset_id": "102477275037226691782080912266896459375744854273025191158751338694645017892558", "price": "0.82", "size": "300", "side": "SELL", "hash": "b068605e064bee7b22f108c8cd907f5ac2c5e85a", "best_bid": "0.24", "best_ask": "0.37"}], "timestamp": "1769384780561", "event_type": "price_change"}}
{"_local_timestamp": "2026-01-25T23:46:20.631467+00:00", "data": {"market": "0x1abd61ad100d8895f3584b464ef167f3518e25a6030881103d14acc083ebad96", "price_changes": [{"asset_id": "88964156506218863777298237975219012171691782824739196411832554942435520583952", "price": "0.11", "size": "4127.19", "side": "BUY", "hash": "00f0970c026b6faf23c23091e9e4c9a4d6cd0a49", "best_bid": "0.48", "best_ask": "0.58"}, {"asset_id": "91437369688558543467551854737984316990748701143376320320377387982132471568811", "price": "0.89", "size": "4127.19", "side": "SELL", "hash": "c06ea273bc83e67d6726c1a3801bc22c8de87d0b", "best_bid": "0.42", "best_ask": "0.52"}], "timestamp": "1769384780560", "event_type": "price_change"}}
{"_local_timestamp": "2026-01-25T23:46:20.642497+00:00", "data": {"market": "0xfbaf6c00d1702c189522a2025f8d52d01348978b16dfe5bd51d5d2f5d6712b0b", "price_changes": [{"asset_id": "102477275037226691782080912266896459375744854273025191158751338694645017892558", "price": "0.03", "size": "316", "side": "BUY", "hash": "4dd6898bd0166ccbf835e6e4a0f9066e471c748d", "best_bid": "0.24", "best_ask": "0.37"}, {"asset_id": "58436266613638193406222525170978476700361341943881268058813684153244605853496", "price": "0.97", "size": "316", "side": "SELL", "hash": "9ad190059bf56d548d68ea931aceeb0bb3633c7a", "best_bid": "0.63", "best_ask": "0.76"}], "timestamp": "1769384780569", "event_type": "price_change"}}
{"_local_timestamp": "2026-01-25T23:46:20.643117+00:00", "data": {"market": "0x1abd61ad100d8895f3584b464ef167f3518e25a6030881103d14acc083ebad96", "price_changes": [{"asset_id": "91437369688558543467551854737984316990748701143376320320377387982132471568811", "price": "0.13", "size": "300", "side": "BUY", "hash": "5acfb2d137ea6e5e93851cd6a10283cfa7e86428", "best_bid": "0.42", "best_ask": "0.52"}, {"asset_id": "88964156506218863777298237975219012171691782824739196411832554942435520583952", "price": "0.87", "size": "300", "side": "SELL", "hash": "3d955c579b7fc19286eab91cc22c9847d2a6899f", "best_bid": "0.48", "best_ask": "0.58"}], "timestamp": "1769384780569", "event_type": "price_change"}}
{"_local_timestamp": "2026-01-25T23:46:24.827289+00:00", "data": {"market": "0xfbaf6c00d1702c189522a2025f8d52d01348978b16dfe5bd51d5d2f5d6712b0b", "price_changes": [{"asset_id": "58436266613638193406222525170978476700361341943881268058813684153244605853496", "price": "0.17", "size": "2470", "side": "BUY", "hash": "682a2250540eefb4d499faf8401e008b492eaf40", "best_bid": "0.63", "best_ask": "0.76"}, {"asset_id": "102477275037226691782080912266896459375744854273025191158751338694645017892558", "price": "0.83", "size": "2470", "side": "SELL", "hash": "fec19dd473f561b72dfc2fb6780737bba793889e", "best_bid": "0.24", "best_ask": "0.37"}], "timestamp": "1769384784758", "event_type": "price_change"}}
{"_local_timestamp": "2026-01-25T23:46:27.545192+00:00", "data": {"market": "0x5372c3942dac612d595f10ab9ee944a0fb1f521f8a0f7e5e4c69ea7f820b9205", "price_changes": [{"asset_id": "28425112653106522555623063788214711387350887710590000638731586279221931393822", "price": "0.017", "size": "0", "side": "BUY", "hash": "043575a1ce9780d6a0d79ea5a67b96c42b75b2ca", "best_bid": "0.81", "best_ask": "0.998"}, {"asset_id": "14539781518361540889330537982912764909191745060309412974583163279274941075133", "price": "0.983", "size": "0", "side": "SELL", "hash": "2707d39de3443decc70ae95bb6788a253de6a7ce", "best_bid": "0.002", "best_ask": "0.19"}], "timestamp": "1769384787468", "event_type": "price_change"}}
{"_local_timestamp": "2026-01-25T23:46:27.907277+00:00", "data": {"market": "0x6bab28a6f5075597847fb403af058162a9160f08892970974b6a7f092f53bbc9", "price_changes": [{"asset_id": "21214163253707781505820437681298157027008420325518755618864634836518062956958", "price": "0.78", "size": "0", "side": "BUY", "hash": "75d6443e15cfa8f9d65158d037acfad560e36a8b", "best_bid": "0.843", "best_ask": "0.962"}, {"asset_id": "825568625501271247311152915286608704339236896918641095426409218916618217433", "price": "0.22", "size": "0", "side": "SELL", "hash": "c3c53a3d7fb4e92ab9765c846d196334520cfa16", "best_bid": "0.038", "best_ask": "0.157"}], "timestamp": "1769384787807", "event_type": "price_change"}}
{"_local_timestamp": "2026-01-25T23:46:27.999545+00:00", "data": {"market": "0x5372c3942dac612d595f10ab9ee944a0fb1f521f8a0f7e5e4c69ea7f820b9205", "price_changes": [{"asset_id": "28425112653106522555623063788214711387350887710590000638731586279221931393822", "price": "0.017", "size": "5", "side": "BUY", "hash": "d1cb10d707d6cea8167deaeffcb30b1173b62cbc", "best_bid": "0.81", "best_ask": "0.998"}, {"asset_id": "14539781518361540889330537982912764909191745060309412974583163279274941075133", "price": "0.983", "size": "5", "side": "SELL", "hash": "55bad74f4db398d0e39bbfc494f3ad2908bbf2e5", "best_bid": "0.002", "best_ask": "0.19"}], "timestamp": "1769384787919", "event_type": "price_change"}}
{"_local_timestamp": "2026-01-25T23:46:28.234139+00:00", "data": {"market": "0x6bab28a6f5075597847fb403af058162a9160f08892970974b6a7f092f53bbc9", "price_changes": [{"asset_id": "21214163253707781505820437681298157027008420325518755618864634836518062956958", "price": "0.79", "size": "225", "side": "BUY", "hash": "d8b54a9a2ae07ebdc5f32eff84b0ea44a1539dfd", "best_bid": "0.843", "best_ask": "0.962"}, {"asset_id": "825568625501271247311152915286608704339236896918641095426409218916618217433", "price": "0.21", "size": "225", "side": "SELL", "hash": "16acdf633ef17829608631360a0790f1f573ce33", "best_bid": "0.038", "best_ask": "0.157"}], "timestamp": "1769384788158", "event_type": "price_change"}}
{"_local_timestamp": "2026-01-25T23:46:28.245481+00:00", "data": {"market": "0x61c7a2857f724184aeefcfc1d5c2d058f0b5a3d95c07e0698a8702a2044cc3f9", "price_changes": [{"asset_id": "16513348473820721539329266419516258589145306802106861039482427297186980662547", "price": "0.941", "size": "0", "side": "BUY", "hash": "b7f5a223ed2079f22c204f8df4ae315f09fac413", "best_bid": "0.965", "best_ask": "0.989"}, {"asset_id": "63990477029527440251791260115609966942867460219987284386576624440536500927768", "price": "0.059", "size": "0", "side": "SELL", "hash": "203e7fad57a33b295554f89de88bc0f9de125afc", "best_bid": "0.011", "best_ask": "0.035"}], "timestamp": "1769384788164", "event_type": "price_change"}}
{"_local_timestamp": "2026-01-25T23:46:28.832440+00:00", "data": {"market": "0xfbaf6c00d1702c189522a2025f8d52d01348978b16dfe5bd51d5d2f5d6712b0b", "price_changes": [{"asset_id": "102477275037226691782080912266896459375744854273025191158751338694645017892558", "price": "0.23", "size": "0", "side": "BUY", "hash": "dcfe8c720a2b546baf7cc1d1b2fccb484ce45129", "best_bid": "0.24", "best_ask": "0.37"}, {"asset_id": "58436266613638193406222525170978476700361341943881268058813684153244605853496", "price": "0.77", "size": "0", "side": "SELL", "hash": "0d9ac0b9703090c935dcd51a217ba2757fc8be4c", "best_bid": "0.63", "best_ask": "0.76"}], "timestamp": "1769384788739", "event_type": "price_change"}}
{"_local_timestamp": "2026-01-25T23:46:29.273256+00:00", "data": {"market": "0x61c7a2857f724184aeefcfc1d5c2d058f0b5a3d95c07e0698a8702a2044cc3f9", "price_changes": [{"asset_id": "16513348473820721539329266419516258589145306802106861039482427297186980662547", "price": "0.942", "size": "20", "side": "BUY", "hash": "72626c9f864880cc06763381b3da5769a3ffd39c", "best_bid": "0.965", "best_ask": "0.989"}, {"asset_id": "63990477029527440251791260115609966942867460219987284386576624440536500927768", "price": "0.058", "size": "20", "side": "SELL", "hash": "9a574beae9a75433744f3c610eb662c27afdcea8", "best_bid": "0.011", "best_ask": "0.035"}], "timestamp": "1769384789195", "event_type": "price_change"}}
{"_local_timestamp": "2026-01-25T23:46:30.584705+00:00", "data": {"market": "0xfbaf6c00d1702c189522a2025f8d52d01348978b16dfe5bd51d5d2f5d6712b0b", "price_changes": [{"asset_id": "102477275037226691782080912266896459375744854273025191158751338694645017892558", "price": "0.16", "size": "0", "side": "BUY", "hash": "b3b25817f4d3b9d1f540b1f414f20f45ec647f4e", "best_bid": "0.24", "best_ask": "0.37"}, {"asset_id": "58436266613638193406222525170978476700361341943881268058813684153244605853496", "price": "0.84", "size": "0", "side": "SELL", "hash": "9e62aceb8110434f2b4e1c79c06c7ac3c71d1ebf", "best_bid": "0.63", "best_ask": "0.76"}], "timestamp": "1769384790468", "event_type": "price_change"}}
{"_local_timestamp": "2026-01-25T23:46:30.683495+00:00", "data": {"market": "0xfbaf6c00d1702c189522a2025f8d52d01348978b16dfe5bd51d5d2f5d6712b0b", "price_changes": [{"asset_id": "102477275037226691782080912266896459375744854273025191158751338694645017892558", "price": "0.15", "size": "10", "side": "BUY", "hash": "332431b76a8d3da03127ca810b65a7bc2c0dc6b5", "best_bid": "0.24", "best_ask": "0.37"}, {"asset_id": "58436266613638193406222525170978476700361341943881268058813684153244605853496", "price": "0.85", "size": "10", "side": "SELL", "hash": "93016d9e7b39e227a24efa20e0a14a3c3a4081aa", "best_bid": "0.63", "best_ask": "0.76"}], "timestamp": "1769384790557", "event_type": "price_change"}}
{"_local_timestamp": "2026-01-25T23:46:31.095280+00:00", "data": {"market": "0xfbaf6c00d1702c189522a2025f8d52d01348978b16dfe5bd51d5d2f5d6712b0b", "price_changes": [{"asset_id": "102477275037226691782080912266896459375744854273025191158751338694645017892558", "price": "0.23", "size": "39", "side": "BUY", "hash": "01e994126464bc39410825a19cf8b3ef522927ad", "best_bid": "0.24", "best_ask": "0.37"}, {"asset_id": "58436266613638193406222525170978476700361341943881268058813684153244605853496", "price": "0.77", "size": "39", "side": "SELL", "hash": "169c9da64c621b34f6f868b8e4ffcf7a6950518a", "best_bid": "0.63", "best_ask": "0.76"}], "timestamp": "1769384790940", "event_type": "price_change"}}
{"_local_timestamp": "2026-01-25T23:46:31.799276+00:00", "data": {"market": "0xfbaf6c00d1702c189522a2025f8d52d01348978b16dfe5bd51d5d2f5d6712b0b", "price_changes": [{"asset_id": "102477275037226691782080912266896459375744854273025191158751338694645017892558", "price": "0.14", "size": "0", "side": "BUY", "hash": "ba192bfcc425c421ca0c86e20614e55d05f609b4", "best_bid": "0.24", "best_ask": "0.37"}, {"asset_id": "58436266613638193406222525170978476700361341943881268058813684153244605853496", "price": "0.86", "size": "0", "side": "SELL", "hash": "eba60e6f10e4fb490f1d0a119b185d52c8be52b7", "best_bid": "0.63", "best_ask": "0.76"}], "timestamp": "1769384791589", "event_type": "price_change"}}
{"_local_timestamp": "2026-01-25T23:46:32.227396+00:00", "data": {"market": "0x1abd61ad100d8895f3584b464ef167f3518e25a6030881103d14acc083ebad96", "price_changes": [{"asset_id": "88964156506218863777298237975219012171691782824739196411832554942435520583952", "price": "0.01", "size": "17043.4", "side": "BUY", "hash": "102a46376227e41fe4a1a4c1792cd6407e4dda1f", "best_bid": "0.48", "best_ask": "0.58"}, {"asset_id": "91437369688558543467551854737984316990748701143376320320377387982132471568811", "price": "0.99", "size": "17043.4", "side": "SELL", "hash": "8b7c3025aec31488d60b6db09fc4652f74ff25e6", "best_bid": "0.42", "best_ask": "0.52"}], "timestamp": "1769384791980", "event_type": "price_change"}}
{"_local_timestamp": "2026-01-25T23:46:32.553809+00:00", "data": {"market": "0xfbaf6c00d1702c189522a2025f8d52d01348978b16dfe5bd51d5d2f5d6712b0b", "price_changes": [{"asset_id": "102477275037226691782080912266896459375744854273025191158751338694645017892558", "price": "0.24", "size": "108.5", "side": "BUY", "hash": "c35c2486752de2de833b74d5c276233100c4aad8", "best_bid": "0.24", "best_ask": "0.37"}, {"asset_id": "58436266613638193406222525170978476700361341943881268058813684153244605853496", "price": "0.76", "size": "108.5", "side": "SELL", "hash": "d677a3d7c130a8f53f6818ba6775d861e58c3805", "best_bid": "0.63", "best_ask": "0.76"}], "timestamp": "1769384792282", "event_type": "price_change"}}
{"_local_timestamp": "2026-01-25T23:46:34.755245+00:00", "data": {"market": "0x1abd61ad100d8895f3584b464ef167f3518e25a6030881103d14acc083ebad96", "price_changes": [{"asset_id": "91437369688558543467551854737984316990748701143376320320377387982132471568811", "price": "0.12", "size": "400", "side": "BUY", "hash": "dd4ebda4c0d13d0f9aa8b019ab2fa760bfebfa4c", "best_bid": "0.42", "best_ask": "0.52"}, {"asset_id": "88964156506218863777298237975219012171691782824739196411832554942435520583952", "price": "0.88", "size": "400", "side": "SELL", "hash": "770f8ea1cfaca57956f7e468dd1fe8dc87d20edc", "best_bid": "0.48", "best_ask": "0.58"}], "timestamp": "1769384794529", "event_type": "price_change"}}
{"_local_timestamp": "2026-01-25T23:46:34.758903+00:00", "data": {"market": "0x1abd61ad100d8895f3584b464ef167f3518e25a6030881103d14acc083ebad96", "price_changes": [{"asset_id": "88964156506218863777298237975219012171691782824739196411832554942435520583952", "price": "0.1", "size": "700", "side": "BUY", "hash": "20a08a84f27f17072158c4cf05c5f76d616b58c2", "best_bid": "0.48", "best_ask": "0.58"}, {"asset_id": "91437369688558543467551854737984316990748701143376320320377387982132471568811", "price": "0.9", "size": "700", "side": "SELL", "hash": "cb841bc787fe47ec6ea823439ec6e831b69c80de", "best_bid": "0.42", "best_ask": "0.52"}], "timestamp": "1769384794529", "event_type": "price_change"}}
{"_local_timestamp": "2026-01-25T23:46:35.079429+00:00", "data": {"market": "0x1abd61ad100d8895f3584b464ef167f3518e25a6030881103d14acc083ebad96", "price_changes": [{"asset_id": "88964156506218863777298237975219012171691782824739196411832554942435520583952", "price": "0.11", "size": "4627.19", "side": "BUY", "hash": "3f4d308d6ac21e4602cccc8bd230f56606129da9", "best_bid": "0.48", "best_ask": "0.58"}, {"asset_id": "91437369688558543467551854737984316990748701143376320320377387982132471568811", "price": "0.89", "size": "4627.19", "side": "SELL", "hash": "1b81e3f98d127f30320a970fbf79759632e7f87b", "best_bid": "0.42", "best_ask": "0.52"}], "timestamp": "1769384794831", "event_type": "price_change"}}
{"_local_timestamp": "2026-01-25T23:46:35.080115+00:00", "data": {"market": "0x1abd61ad100d8895f3584b464ef167f3518e25a6030881103d14acc083ebad96", "price_changes": [{"asset_id": "91437369688558543467551854737984316990748701143376320320377387982132471568811", "price": "0.13", "size": "800", "side": "BUY", "hash": "5a6f162dc08f85f28fdcd71b307440cbd27e711b", "best_bid": "0.42", "best_ask": "0.52"}, {"asset_id": "88964156506218863777298237975219012171691782824739196411832554942435520583952", "price": "0.87", "size": "800", "side": "SELL", "hash": "b3868bfd1dea8a3938e5c6d15c4a5cedcac1ef60", "best_bid": "0.48", "best_ask": "0.58"}], "timestamp": "1769384794832", "event_type": "price_change"}}
{"_local_timestamp": "2026-01-25T23:46:36.383999+00:00", "data": {"market": "0xfbaf6c00d1702c189522a2025f8d52d01348978b16dfe5bd51d5d2f5d6712b0b", "price_changes": [{"asset_id": "102477275037226691782080912266896459375744854273025191158751338694645017892558", "price": "0.24", "size": "100", "side": "BUY", "hash": "2d62bf3b984a9828c367cfcdec2cc8d50f34e8a1", "best_bid": "0.24", "best_ask": "0.37"}, {"asset_id": "58436266613638193406222525170978476700361341943881268058813684153244605853496", "price": "0.76", "size": "100", "side": "SELL", "hash": "86bddd762b2a93c69bd75dabb7f110cd4695cf0c", "best_bid": "0.63", "best_ask": "0.76"}], "timestamp": "1769384796135", "event_type": "price_change"}}
{"_local_timestamp": "2026-01-25T23:46:36.430288+00:00", "data": {"market": "0xfbaf6c00d1702c189522a2025f8d52d01348978b16dfe5bd51d5d2f5d6712b0b", "price_changes": [{"asset_id": "102477275037226691782080912266896459375744854273025191158751338694645017892558", "price": "0.15", "size": "18.5", "side": "BUY", "hash": "ff389db74740e398f9c8e82ac8e4ae4ab8fd8d05", "best_bid": "0.24", "best_ask": "0.37"}, {"asset_id": "58436266613638193406222525170978476700361341943881268058813684153244605853496", "price": "0.85", "size": "18.5", "side": "SELL", "hash": "30acffa0b416502915d24b95455546d961efa602", "best_bid": "0.63", "best_ask": "0.76"}], "timestamp": "1769384796173", "event_type": "price_change"}}
{"_local_timestamp": "2026-01-25T23:46:40.857142+00:00", "data": {"market": "0xfbaf6c00d1702c189522a2025f8d52d01348978b16dfe5bd51d5d2f5d6712b0b", "price_changes": [{"asset_id": "102477275037226691782080912266896459375744854273025191158751338694645017892558", "price": "0.15", "size": "10", "side": "BUY", "hash": "de31b5a5d8cb24bc7f3fd9c0dc6bacba709df191", "best_bid": "0.24", "best_ask": "0.37"}, {"asset_id": "58436266613638193406222525170978476700361341943881268058813684153244605853496", "price": "0.85", "size": "10", "side": "SELL", "hash": "988eed19c010ad8b5a57ffc4af185c6640c1f0ee", "best_bid": "0.63", "best_ask": "0.76"}], "timestamp": "1769384800575", "event_type": "price_change"}}
{"_local_timestamp": "2026-01-25T23:46:41.763299+00:00", "data": {"market": "0xfbaf6c00d1702c189522a2025f8d52d01348978b16dfe5bd51d5d2f5d6712b0b", "price_changes": [{"asset_id": "102477275037226691782080912266896459375744854273025191158751338694645017892558", "price": "0.25", "size": "8.5", "side": "BUY", "hash": "b5533acf705aff6592d66fd033f34ce56e9d79f2", "best_bid": "0.25", "best_ask": "0.37"}, {"asset_id": "58436266613638193406222525170978476700361341943881268058813684153244605853496", "price": "0.75", "size": "8.5", "side": "SELL", "hash": "5316facbf1490750964bebca68899de94713b958", "best_bid": "0.63", "best_ask": "0.75"}], "timestamp": "1769384800610", "event_type": "price_change"}}
{"_local_timestamp": "2026-01-25T23:46:47.418503+00:00", "data": {"market": "0x5372c3942dac612d595f10ab9ee944a0fb1f521f8a0f7e5e4c69ea7f820b9205", "price_changes": [{"asset_id": "28425112653106522555623063788214711387350887710590000638731586279221931393822", "price": "0.017", "size": "0", "side": "BUY", "hash": "af0a81e1344ed7010855d1e702385b1294aae51a", "best_bid": "0.81", "best_ask": "0.998"}, {"asset_id": "14539781518361540889330537982912764909191745060309412974583163279274941075133", "price": "0.983", "size": "0", "side": "SELL", "hash": "26dba1cca61f25b93a196d0529bf4b66bdd3baa9", "best_bid": "0.002", "best_ask": "0.19"}], "timestamp": "1769384807274", "event_type": "price_change"}}
{"_local_timestamp": "2026-01-25T23:46:47.839558+00:00", "data": {"market": "0x5372c3942dac612d595f10ab9ee944a0fb1f521f8a0f7e5e4c69ea7f820b9205", "price_changes": [{"asset_id": "28425112653106522555623063788214711387350887710590000638731586279221931393822", "price": "0.017", "size": "5", "side": "BUY", "hash": "2aa3aa60a8fbf10a6e918d30b4297b58d45bb27c", "best_bid": "0.81", "best_ask": "0.998"}, {"asset_id": "14539781518361540889330537982912764909191745060309412974583163279274941075133", "price": "0.983", "size": "5", "side": "SELL", "hash": "234998d5120e913855c863d2897b40ea3f1d0868", "best_bid": "0.002", "best_ask": "0.19"}], "timestamp": "1769384807634", "event_type": "price_change"}}
{"_local_timestamp": "2026-01-25T23:46:48.828576+00:00", "data": {"market": "0x1abd61ad100d8895f3584b464ef167f3518e25a6030881103d14acc083ebad96", "price_changes": [{"asset_id": "88964156506218863777298237975219012171691782824739196411832554942435520583952", "price": "0.1", "size": "0", "side": "BUY", "hash": "e3be0026002bb6a890ef5c6fa1e7311f33951f87", "best_bid": "0.48", "best_ask": "0.58"}, {"asset_id": "91437369688558543467551854737984316990748701143376320320377387982132471568811", "price": "0.9", "size": "0", "side": "SELL", "hash": "18173cc65c433d8c687f006f46d7484bbafef2fb", "best_bid": "0.42", "best_ask": "0.52"}], "timestamp": "1769384808607", "event_type": "price_change"}}
{"_local_timestamp": "2026-01-25T23:46:48.829344+00:00", "data": {"market": "0x1abd61ad100d8895f3584b464ef167f3518e25a6030881103d14acc083ebad96", "price_changes": [{"asset_id": "91437369688558543467551854737984316990748701143376320320377387982132471568811", "price": "0.12", "size": "0", "side": "BUY", "hash": "a23cf864977bf3e8361dacb146aa79dcb264d08e", "best_bid": "0.42", "best_ask": "0.52"}, {"asset_id": "88964156506218863777298237975219012171691782824739196411832554942435520583952", "price": "0.88", "size": "0", "side": "SELL", "hash": "ace135557ed4d06db791f50593f263f23de0bff2", "best_bid": "0.48", "best_ask": "0.58"}], "timestamp": "1769384808607", "event_type": "price_change"}}
{"_local_timestamp": "2026-01-25T23:46:49.079402+00:00", "data": {"market": "0x1abd61ad100d8895f3584b464ef167f3518e25a6030881103d14acc083ebad96", "price_changes": [{"asset_id": "88964156506218863777298237975219012171691782824739196411832554942435520583952", "price": "0.11", "size": "5027.19", "side": "BUY", "hash": "946046fd4bbd4839b4b8ef32664729a47cb70e1e", "best_bid": "0.48", "best_ask": "0.58"}, {"asset_id": "91437369688558543467551854737984316990748701143376320320377387982132471568811", "price": "0.89", "size": "5027.19", "side": "SELL", "hash": "0dc379aeca0ed0dcc65e30efcce6f0022d3855f3", "best_bid": "0.42", "best_ask": "0.52"}], "timestamp": "1769384808886", "event_type": "price_change"}}
{"_local_timestamp": "2026-01-25T23:46:49.080134+00:00", "data": {"market": "0x1abd61ad100d8895f3584b464ef167f3518e25a6030881103d14acc083ebad96", "price_changes": [{"asset_id": "91437369688558543467551854737984316990748701143376320320377387982132471568811", "price": "0.13", "size": "1200", "side": "BUY", "hash": "5976be9c740edfe1de902ec65d09b3885bc7348c", "best_bid": "0.42", "best_ask": "0.52"}, {"asset_id": "88964156506218863777298237975219012171691782824739196411832554942435520583952", "price": "0.87", "size": "1200", "side": "SELL", "hash": "656f6e0119331bcd16bda10b2d902e0625bcf7c5", "best_bid": "0.48", "best_ask": "0.58"}], "timestamp": "1769384808887", "event_type": "price_change"}}
{"_local_timestamp": "2026-01-25T23:46:54.356092+00:00", "data": {"market": "0x1abd61ad100d8895f3584b464ef167f3518e25a6030881103d14acc083ebad96", "price_changes": [{"asset_id": "91437369688558543467551854737984316990748701143376320320377387982132471568811", "price": "0.24", "size": "0", "side": "BUY", "hash": "e21ce7e98cb689a3fb80093e833748ee6c0b5164", "best_bid": "0.42", "best_ask": "0.52"}, {"asset_id": "88964156506218863777298237975219012171691782824739196411832554942435520583952", "price": "0.76", "size": "0", "side": "SELL", "hash": "3de9ff4bdc6db562639b00584ac2209e496e7d65", "best_bid": "0.48", "best_ask": "0.58"}], "timestamp": "1769384814235", "event_type": "price_change"}}
{"_local_timestamp": "2026-01-25T23:46:54.356861+00:00", "data": {"market": "0x1abd61ad100d8895f3584b464ef167f3518e25a6030881103d14acc083ebad96", "price_changes": [{"asset_id": "88964156506218863777298237975219012171691782824739196411832554942435520583952", "price": "0.11", "size": "5018", "side": "BUY", "hash": "891563809eb10f8608315daeebc5d4f70cc6ec34", "best_bid": "0.48", "best_ask": "0.58"}, {"asset_id": "91437369688558543467551854737984316990748701143376320320377387982132471568811", "price": "0.89", "size": "5018", "side": "SELL", "hash": "a8f155f0ecc68acdb55285883818ae4b867d8abb", "best_bid": "0.42", "best_ask": "0.52"}], "timestamp": "1769384814235", "event_type": "price_change"}}
{"_local_timestamp": "2026-01-25T23:46:54.489928+00:00", "data": {"market": "0xfbaf6c00d1702c189522a2025f8d52d01348978b16dfe5bd51d5d2f5d6712b0b", "price_changes": [{"asset_id": "102477275037226691782080912266896459375744854273025191158751338694645017892558", "price": "0.03", "size": "2316", "side": "BUY", "hash": "0f9ee6624daf76e5a957ca37488cd7d67604a4c1", "best_bid": "0.25", "best_ask": "0.37"}, {"asset_id": "58436266613638193406222525170978476700361341943881268058813684153244605853496", "price": "0.97", "size": "2316", "side": "SELL", "hash": "2cce61547213d2f00073c79b8efadf8d9e473e65", "best_bid": "0.63", "best_ask": "0.75"}], "timestamp": "1769384814373", "event_type": "price_change"}}
{"_local_timestamp": "2026-01-25T23:46:54.490668+00:00", "data": {"market": "0xfbaf6c00d1702c189522a2025f8d52d01348978b16dfe5bd51d5d2f5d6712b0b", "price_changes": [{"asset_id": "102477275037226691782080912266896459375744854273025191158751338694645017892558", "price": "0.13", "size": "725", "side": "BUY", "hash": "ad67fa8798dc0e1afcfa0b39a960d6a51dd4c729", "best_bid": "0.25", "best_ask": "0.37"}, {"asset_id": "58436266613638193406222525170978476700361341943881268058813684153244605853496", "price": "0.87", "size": "725", "side": "SELL", "hash": "f31e3b157897eb457544a66ec40963fc7c66f0f4", "best_bid": "0.63", "best_ask": "0.75"}], "timestamp": "1769384814375", "event_type": "price_change"}}
{"_local_timestamp": "2026-01-25T23:46:57.053715+00:00", "data": {"market": "0x5372c3942dac612d595f10ab9ee944a0fb1f521f8a0f7e5e4c69ea7f820b9205", "price_changes": [{"asset_id": "28425112653106522555623063788214711387350887710590000638731586279221931393822", "price": "0.017", "size": "0", "side": "BUY", "hash": "6e6f2109fd2895f97980fabd1666090efd78555a", "best_bid": "0.81", "best_ask": "0.998"}, {"asset_id": "14539781518361540889330537982912764909191745060309412974583163279274941075133", "price": "0.983", "size": "0", "side": "SELL", "hash": "e82cf1dc96a53dd15d9cfdcb01ae305881dc7e28", "best_bid": "0.002", "best_ask": "0.19"}], "timestamp": "1769384816920", "event_type": "price_change"}}
{"_local_timestamp": "2026-01-25T23:46:57.298213+00:00", "data": {"market": "0x1abd61ad100d8895f3584b464ef167f3518e25a6030881103d14acc083ebad96", "price_changes": [{"asset_id": "88964156506218863777298237975219012171691782824739196411832554942435520583952", "price": "0.12", "size": "8.5", "side": "BUY", "hash": "97afac09f5fcfab3470afe12b820538a091eb296", "best_bid": "0.48", "best_ask": "0.58"}, {"asset_id": "91437369688558543467551854737984316990748701143376320320377387982132471568811", "price": "0.88", "size": "8.5", "side": "SELL", "hash": "f4ae190fe573556abb9c2c21fbf40f2a5d306d74", "best_bid": "0.42", "best_ask": "0.52"}], "timestamp": "1769384817184", "event_type": "price_change"}}
{"_local_timestamp": "2026-01-25T23:46:57.298944+00:00", "data": {"market": "0x1abd61ad100d8895f3584b464ef167f3518e25a6030881103d14acc083ebad96", "price_changes": [{"asset_id": "91437369688558543467551854737984316990748701143376320320377387982132471568811", "price": "0.24", "size": "8.5", "side": "BUY", "hash": "1364e7910a55fcb73c9579a4700b386d5d8a9f0a", "best_bid": "0.42", "best_ask": "0.52"}, {"asset_id": "88964156506218863777298237975219012171691782824739196411832554942435520583952", "price": "0.76", "size": "8.5", "side": "SELL", "hash": "28672aae6dae51c32092e4bb30992242aec5b18e", "best_bid": "0.48", "best_ask": "0.58"}], "timestamp": "1769384817185", "event_type": "price_change"}}
{"_local_timestamp": "2026-01-25T23:46:57.438664+00:00", "data": {"market": "0x5372c3942dac612d595f10ab9ee944a0fb1f521f8a0f7e5e4c69ea7f820b9205", "price_changes": [{"asset_id": "28425112653106522555623063788214711387350887710590000638731586279221931393822", "price": "0.017", "size": "5", "side": "BUY", "hash": "b1fb82ac0a2a128bb80944880174ae5dfde00480", "best_bid": "0.81", "best_ask": "0.998"}, {"asset_id": "14539781518361540889330537982912764909191745060309412974583163279274941075133", "price": "0.983", "size": "5", "side": "SELL", "hash": "ca2c69d501423eeb81bca2577913e395e8dc21ec", "best_bid": "0.002", "best_ask": "0.19"}], "timestamp": "1769384817317", "event_type": "price_change"}}
{"_local_timestamp": "2026-01-25T23:46:58.966246+00:00", "data": {"market": "0x1abd61ad100d8895f3584b464ef167f3518e25a6030881103d14acc083ebad96", "price_changes": [{"asset_id": "91437369688558543467551854737984316990748701143376320320377387982132471568811", "price": "0.07", "size": "6000", "side": "BUY", "hash": "3c3633e92f1a18a88f9fcc81ff0642a2001856ab", "best_bid": "0.42", "best_ask": "0.52"}, {"asset_id": "88964156506218863777298237975219012171691782824739196411832554942435520583952", "price": "0.93", "size": "6000", "side": "SELL", "hash": "217dbe7b67c453c305696aac2779df751694b314", "best_bid": "0.48", "best_ask": "0.58"}], "timestamp": "1769384818818", "event_type": "price_change"}}
{"_local_timestamp": "2026-01-25T23:47:01.799250+00:00", "data": {"market": "0x1abd61ad100d8895f3584b464ef167f3518e25a6030881103d14acc083ebad96", "price_changes": [{"asset_id": "91437369688558543467551854737984316990748701143376320320377387982132471568811", "price": "0.03", "size": "6000", "side": "BUY", "hash": "a77425a16da8e21df041b7572c8bf08be7f20f4a", "best_bid": "0.42", "best_ask": "0.52"}, {"asset_id": "88964156506218863777298237975219012171691782824739196411832554942435520583952", "price": "0.97", "size": "6000", "side": "SELL", "hash": "a945e5f38a37b9cae0ade0a62df46a630a7db79f", "best_bid": "0.48", "best_ask": "0.58"}], "timestamp": "1769384821670", "event_type": "price_change"}}
{"_local_timestamp": "2026-01-25T23:47:01.801570+00:00", "data": {"market": "0x1abd61ad100d8895f3584b464ef167f3518e25a6030881103d14acc083ebad96", "price_changes": [{"asset_id": "91437369688558543467551854737984316990748701143376320320377387982132471568811", "price": "0.01", "size": "17043.05", "side": "BUY", "hash": "a937536abd1d1a195556ba47c6d09b7b37dd4045", "best_bid": "0.42", "best_ask": "0.52"}, {"asset_id": "88964156506218863777298237975219012171691782824739196411832554942435520583952", "price": "0.99", "size": "17043.05", "side": "SELL", "hash": "f69c16ae49fbb3f2bd20f20616e367cbd45a02c6", "best_bid": "0.48", "best_ask": "0.58"}], "timestamp": "1769384821671", "event_type": "price_change"}}
{"_local_timestamp": "2026-01-25T23:47:06.495634+00:00", "data": {"market": "0xfbaf6c00d1702c189522a2025f8d52d01348978b16dfe5bd51d5d2f5d6712b0b", "price_changes": [{"asset_id": "102477275037226691782080912266896459375744854273025191158751338694645017892558", "price": "0.02", "size": "4008.7", "side": "BUY", "hash": "4f3541895493fb11f313115f41ea350792e4787e", "best_bid": "0.25", "best_ask": "0.37"}, {"asset_id": "58436266613638193406222525170978476700361341943881268058813684153244605853496", "price": "0.98", "size": "4008.7", "side": "SELL", "hash": "c1b5af204cc1ac940d462808b2638dc869bd1c83", "best_bid": "0.63", "best_ask": "0.75"}], "timestamp": "1769384826381", "event_type": "price_change"}}
{"_local_timestamp": "2026-01-25T23:47:06.497477+00:00", "data": {"market": "0xfbaf6c00d1702c189522a2025f8d52d01348978b16dfe5bd51d5d2f5d6712b0b", "price_changes": [{"asset_id": "102477275037226691782080912266896459375744854273025191158751338694645017892558", "price": "0.03", "size": "4316", "side": "BUY", "hash": "e3aa8e9d974da0ed84e871af790ce4cb8e448559", "best_bid": "0.25", "best_ask": "0.37"}, {"asset_id": "58436266613638193406222525170978476700361341943881268058813684153244605853496", "price": "0.97", "size": "4316", "side": "SELL", "hash": "38aff05a9173cead8a7ee26a932a83219db37693", "best_bid": "0.63", "best_ask": "0.75"}], "timestamp": "1769384826382", "event_type": "price_change"}}
{"_local_timestamp": "2026-01-25T23:47:06.501201+00:00", "data": {"market": "0xfbaf6c00d1702c189522a2025f8d52d01348978b16dfe5bd51d5d2f5d6712b0b", "price_changes": [{"asset_id": "102477275037226691782080912266896459375744854273025191158751338694645017892558", "price": "0.13", "size": "1125", "side": "BUY", "hash": "7adc98f912a38d8e821f6413a082a782a5fc5e59", "best_bid": "0.25", "best_ask": "0.37"}, {"asset_id": "58436266613638193406222525170978476700361341943881268058813684153244605853496", "price": "0.87", "size": "1125", "side": "SELL", "hash": "4bb50f382f5bdea73671e98feb5683a358d6b2c2", "best_bid": "0.63", "best_ask": "0.75"}], "timestamp": "1769384826383", "event_type": "price_change"}}
{"_local_timestamp": "2026-01-25T23:47:09.671923+00:00", "data": {"market": "0x5372c3942dac612d595f10ab9ee944a0fb1f521f8a0f7e5e4c69ea7f820b9205", "price_changes": [{"asset_id": "28425112653106522555623063788214711387350887710590000638731586279221931393822", "price": "0.017", "size": "0", "side": "BUY", "hash": "16516dccc9c7b236a10a0deb51c65a333f9b3d6a", "best_bid": "0.81", "best_ask": "0.998"}, {"asset_id": "14539781518361540889330537982912764909191745060309412974583163279274941075133", "price": "0.983", "size": "0", "side": "SELL", "hash": "e12f74e07ab84d020e21e30165c854365619cbad", "best_bid": "0.002", "best_ask": "0.19"}], "timestamp": "1769384829535", "event_type": "price_change"}}
{"_local_timestamp": "2026-01-25T23:47:10.127721+00:00", "data": {"market": "0x5372c3942dac612d595f10ab9ee944a0fb1f521f8a0f7e5e4c69ea7f820b9205", "price_changes": [{"asset_id": "28425112653106522555623063788214711387350887710590000638731586279221931393822", "price": "0.017", "size": "5", "side": "BUY", "hash": "e52a3aefb7c5cf9157d2d53d5e2c980137eadc0f", "best_bid": "0.81", "best_ask": "0.998"}, {"asset_id": "14539781518361540889330537982912764909191745060309412974583163279274941075133", "price": "0.983", "size": "5", "side": "SELL", "hash": "2b199fe1958e9dabc3bca018cbae425a4ab66b92", "best_bid": "0.002", "best_ask": "0.19"}], "timestamp": "1769384829981", "event_type": "price_change"}}
{"_local_timestamp": "2026-01-25T23:47:18.032360+00:00", "data": {"market": "0x6bab28a6f5075597847fb403af058162a9160f08892970974b6a7f092f53bbc9", "price_changes": [{"asset_id": "825568625501271247311152915286608704339236896918641095426409218916618217433", "price": "0.219", "size": "181.95", "side": "SELL", "hash": "6593a312c96b03a8c59ecfc1e175d8722d4cffd6", "best_bid": "0.038", "best_ask": "0.157"}, {"asset_id": "21214163253707781505820437681298157027008420325518755618864634836518062956958", "price": "0.781", "size": "181.95", "side": "BUY", "hash": "994511a87406cad92a649246f04005d4073fd2b0", "best_bid": "0.843", "best_ask": "0.962"}], "timestamp": "1769384837831", "event_type": "price_change"}}
{"_local_timestamp": "2026-01-25T23:47:19.263742+00:00", "data": {"market": "0x6bab28a6f5075597847fb403af058162a9160f08892970974b6a7f092f53bbc9", "price_changes": [{"asset_id": "825568625501271247311152915286608704339236896918641095426409218916618217433", "price": "0.209", "size": "66", "side": "SELL", "hash": "3c846eecd9cdbc2453236a5cdfd70850c7d0e4e6", "best_bid": "0.038", "best_ask": "0.157"}, {"asset_id": "21214163253707781505820437681298157027008420325518755618864634836518062956958", "price": "0.791", "size": "66", "side": "BUY", "hash": "3ff0385e9f0358723720fbc0b431a2aa334157b7", "best_bid": "0.843", "best_ask": "0.962"}], "timestamp": "1769384838986", "event_type": "price_change"}}
{"_local_timestamp": "2026-01-25T23:47:19.971669+00:00", "data": {"market": "0xfbaf6c00d1702c189522a2025f8d52d01348978b16dfe5bd51d5d2f5d6712b0b", "price_changes": [{"asset_id": "102477275037226691782080912266896459375744854273025191158751338694645017892558", "price": "0.01", "size": "15036.7", "side": "BUY", "hash": "ce31a2dc7d26ca4a48f2d9084eccf82e591c4f76", "best_bid": "0.25", "best_ask": "0.37"}, {"asset_id": "58436266613638193406222525170978476700361341943881268058813684153244605853496", "price": "0.99", "size": "15036.7", "side": "SELL", "hash": "873299a8deacac65aa03751d9408be8f1a01e57d", "best_bid": "0.63", "best_ask": "0.75"}], "timestamp": "1769384839766", "event_type": "price_change"}}
{"_local_timestamp": "2026-01-25T23:47:19.972455+00:00", "data": {"market": "0xfbaf6c00d1702c189522a2025f8d52d01348978b16dfe5bd51d5d2f5d6712b0b", "price_changes": [{"asset_id": "102477275037226691782080912266896459375744854273025191158751338694645017892558", "price": "0.03", "size": "6316", "side": "BUY", "hash": "c6f680b4cd1486c3715b21f456905e8e0f649e39", "best_bid": "0.25", "best_ask": "0.37"}, {"asset_id": "58436266613638193406222525170978476700361341943881268058813684153244605853496", "price": "0.97", "size": "6316", "side": "SELL", "hash": "9cb89f2275a6c19a99198a5202ae8264c0d17a90", "best_bid": "0.63", "best_ask": "0.75"}], "timestamp": "1769384839767", "event_type": "price_change"}}
{"_local_timestamp": "2026-01-25T23:47:23.696041+00:00", "data": {"market": "0xfbaf6c00d1702c189522a2025f8d52d01348978b16dfe5bd51d5d2f5d6712b0b", "price_changes": [{"asset_id": "58436266613638193406222525170978476700361341943881268058813684153244605853496", "price": "0.28", "size": "0", "side": "BUY", "hash": "7f23e647de6c8606f4b9b97589ddcbfd441ac870", "best_bid": "0.63", "best_ask": "0.75"}, {"asset_id": "102477275037226691782080912266896459375744854273025191158751338694645017892558", "price": "0.72", "size": "0", "side": "SELL", "hash": "c60d4fec66d344aee5f5165b4d1457ff58aa3f65", "best_bid": "0.25", "best_ask": "0.37"}], "timestamp": "1769384843404", "event_type": "price_change"}}
{"_local_timestamp": "2026-01-25T23:47:23.771403+00:00", "data": {"market": "0x1abd61ad100d8895f3584b464ef167f3518e25a6030881103d14acc083ebad96", "price_changes": [{"asset_id": "88964156506218863777298237975219012171691782824739196411832554942435520583952", "price": "0.02", "size": "5032.85", "side": "BUY", "hash": "07d42aec0677c019df525602e0a31c0171ecb6d5", "best_bid": "0.48", "best_ask": "0.58"}, {"asset_id": "91437369688558543467551854737984316990748701143376320320377387982132471568811", "price": "0.98", "size": "5032.85", "side": "SELL", "hash": "5a4ca81cd130eab9d5c871213f74744450eaf4ad", "best_bid": "0.42", "best_ask": "0.52"}], "timestamp": "1769384843464", "event_type": "price_change"}}
{"_local_timestamp": "2026-01-25T23:47:24.055448+00:00", "data": {"market": "0xfbaf6c00d1702c189522a2025f8d52d01348978b16dfe5bd51d5d2f5d6712b0b", "price_changes": [{"asset_id": "58436266613638193406222525170978476700361341943881268058813684153244605853496", "price": "0.29", "size": "50", "side": "BUY", "hash": "6368ce76f07282dc4c6710e9d51ada81cce582b2", "best_bid": "0.63", "best_ask": "0.75"}, {"asset_id": "102477275037226691782080912266896459375744854273025191158751338694645017892558", "price": "0.71", "size": "50", "side": "SELL", "hash": "8ef5be3d53bbf351c7e773881e6f61e426ecf24c", "best_bid": "0.25", "best_ask": "0.37"}], "timestamp": "1769384843815", "event_type": "price_change"}}
{"_local_timestamp": "2026-01-25T23:47:25.193274+00:00", "data": {"market": "0x5372c3942dac612d595f10ab9ee944a0fb1f521f8a0f7e5e4c69ea7f820b9205", "price_changes": [{"asset_id": "28425112653106522555623063788214711387350887710590000638731586279221931393822", "price": "0.017", "size": "0", "side": "BUY", "hash": "469b306a492d054cc2c105259dd5a907aaf0d616", "best_bid": "0.81", "best_ask": "0.998"}, {"asset_id": "14539781518361540889330537982912764909191745060309412974583163279274941075133", "price": "0.983", "size": "0", "side": "SELL", "hash": "c1ff4b9a1a6c20c5f00fc4e6aea13aef22a25037", "best_bid": "0.002", "best_ask": "0.19"}], "timestamp": "1769384844978", "event_type": "price_change"}}
{"_local_timestamp": "2026-01-25T23:47:25.557347+00:00", "data": {"market": "0x5372c3942dac612d595f10ab9ee944a0fb1f521f8a0f7e5e4c69ea7f820b9205", "price_changes": [{"asset_id": "28425112653106522555623063788214711387350887710590000638731586279221931393822", "price": "0.017", "size": "5", "side": "BUY", "hash": "848bdccd58065d84ca6f49252301670b15f5def2", "best_bid": "0.81", "best_ask": "0.998"}, {"asset_id": "14539781518361540889330537982912764909191745060309412974583163279274941075133", "price": "0.983", "size": "5", "side": "SELL", "hash": "3c6496f1d82bcfc1e2f0df06484ef390fd9546f6", "best_bid": "0.002", "best_ask": "0.19"}], "timestamp": "1769384845359", "event_type": "price_change"}}
{"_local_timestamp": "2026-01-25T23:47:26.467199+00:00", "data": {"market": "0x6bab28a6f5075597847fb403af058162a9160f08892970974b6a7f092f53bbc9", "price_changes": [{"asset_id": "825568625501271247311152915286608704339236896918641095426409218916618217433", "price": "0.219", "size": "81.95", "side": "SELL", "hash": "545eac62815636ea344eea2f726a6217b72d91d4", "best_bid": "0.038", "best_ask": "0.157"}, {"asset_id": "21214163253707781505820437681298157027008420325518755618864634836518062956958", "price": "0.781", "size": "81.95", "side": "BUY", "hash": "3ddaa60aaf6aebf335d36241b38ba826ac64c0ab", "best_bid": "0.843", "best_ask": "0.962"}], "timestamp": "1769384846223", "event_type": "price_change"}}
{"_local_timestamp": "2026-01-25T23:47:26.467971+00:00", "data": {"market": "0x6bab28a6f5075597847fb403af058162a9160f08892970974b6a7f092f53bbc9", "price_changes": [{"asset_id": "825568625501271247311152915286608704339236896918641095426409218916618217433", "price": "0.209", "size": "50", "side": "SELL", "hash": "545eac62815636ea344eea2f726a6217b72d91d4", "best_bid": "0.038", "best_ask": "0.157"}, {"asset_id": "21214163253707781505820437681298157027008420325518755618864634836518062956958", "price": "0.791", "size": "50", "side": "BUY", "hash": "3ddaa60aaf6aebf335d36241b38ba826ac64c0ab", "best_bid": "0.843", "best_ask": "0.962"}], "timestamp": "1769384846223", "event_type": "price_change"}}
{"_local_timestamp": "2026-01-25T23:47:26.468658+00:00", "data": {"market": "0x6bab28a6f5075597847fb403af058162a9160f08892970974b6a7f092f53bbc9", "price_changes": [{"asset_id": "825568625501271247311152915286608704339236896918641095426409218916618217433", "price": "0.223", "size": "0", "side": "SELL", "hash": "545eac62815636ea344eea2f726a6217b72d91d4", "best_bid": "0.038", "best_ask": "0.157"}, {"asset_id": "21214163253707781505820437681298157027008420325518755618864634836518062956958", "price": "0.777", "size": "0", "side": "BUY", "hash": "3ddaa60aaf6aebf335d36241b38ba826ac64c0ab", "best_bid": "0.843", "best_ask": "0.962"}], "timestamp": "1769384846223", "event_type": "price_change"}}
{"_local_timestamp": "2026-01-25T23:47:26.836084+00:00", "data": {"market": "0x6bab28a6f5075597847fb403af058162a9160f08892970974b6a7f092f53bbc9", "price_changes": [{"asset_id": "825568625501271247311152915286608704339236896918641095426409218916618217433", "price": "0.21", "size": "325", "side": "SELL", "hash": "6f6fa6644c2ade841d9ca644a2e27be387162061", "best_bid": "0.038", "best_ask": "0.157"}, {"asset_id": "21214163253707781505820437681298157027008420325518755618864634836518062956958", "price": "0.79", "size": "325", "side": "BUY", "hash": "3bf0fc49d34c83a4e97d565fbcd0ad6bcacbde02", "best_bid": "0.843", "best_ask": "0.962"}], "timestamp": "1769384846575", "event_type": "price_change"}}
{"_local_timestamp": "2026-01-25T23:47:26.836866+00:00", "data": {"market": "0x6bab28a6f5075597847fb403af058162a9160f08892970974b6a7f092f53bbc9", "price_changes": [{"asset_id": "825568625501271247311152915286608704339236896918641095426409218916618217433", "price": "0.214", "size": "83.51", "side": "SELL", "hash": "68b65f01a04d238d1a85f9ea26e3ea18b4c456bb", "best_bid": "0.038", "best_ask": "0.157"}, {"asset_id": "21214163253707781505820437681298157027008420325518755618864634836518062956958", "price": "0.786", "size": "83.51", "side": "BUY", "hash": "fc4e5b884a9157fbd97458beebeda5cc14c42352", "best_bid": "0.843", "best_ask": "0.962"}], "timestamp": "1769384846576", "event_type": "price_change"}}
{"_local_timestamp": "2026-01-25T23:47:26.841254+00:00", "data": {"market": "0x6bab28a6f5075597847fb403af058162a9160f08892970974b6a7f092f53bbc9", "price_changes": [{"asset_id": "825568625501271247311152915286608704339236896918641095426409218916618217433", "price": "0.2", "size": "16", "side": "SELL", "hash": "8a872da4dd360cc15f69a4c02ac0e306632ab0b3", "best_bid": "0.038", "best_ask": "0.157"}, {"asset_id": "21214163253707781505820437681298157027008420325518755618864634836518062956958", "price": "0.8", "size": "16", "side": "BUY", "hash": "aeb1dde398a6c43618533d180cb86781437ac208", "best_bid": "0.843", "best_ask": "0.962"}], "timestamp": "1769384846576", "event_type": "price_change"}}
{"_local_timestamp": "2026-01-25T23:47:30.026731+00:00", "data": {"market": "0xfbaf6c00d1702c189522a2025f8d52d01348978b16dfe5bd51d5d2f5d6712b0b", "price_changes": [{"asset_id": "102477275037226691782080912266896459375744854273025191158751338694645017892558", "price": "0.15", "size": "0", "side": "BUY", "hash": "1b6b14df6fb46029e55e383391f9d6fed69f6d6e", "best_bid": "0.25", "best_ask": "0.37"}, {"asset_id": "58436266613638193406222525170978476700361341943881268058813684153244605853496", "price": "0.85", "size": "0", "side": "SELL", "hash": "cbb358b0fd6a2d7617c0e58f84d904030c8df69a", "best_bid": "0.63", "best_ask": "0.75"}], "timestamp": "1769384849767", "event_type": "price_change"}}
{"_local_timestamp": "2026-01-25T23:47:30.841199+00:00", "data": {"market": "0xfbaf6c00d1702c189522a2025f8d52d01348978b16dfe5bd51d5d2f5d6712b0b", "price_changes": [{"asset_id": "102477275037226691782080912266896459375744854273025191158751338694645017892558", "price": "0.22", "size": "60", "side": "BUY", "hash": "8c291d7123c14f601fc852e9ee081a7f9eedf3a9", "best_bid": "0.25", "best_ask": "0.37"}, {"asset_id": "58436266613638193406222525170978476700361341943881268058813684153244605853496", "price": "0.78", "size": "60", "side": "SELL", "hash": "4a949c9527dbbeb0c9d9e22956619cd2cc484c24", "best_bid": "0.63", "best_ask": "0.75"}], "timestamp": "1769384849859", "event_type": "price_change"}}
{"_local_timestamp": "2026-01-25T23:47:31.128896+00:00", "data": {"market": "0x61c7a2857f724184aeefcfc1d5c2d058f0b5a3d95c07e0698a8702a2044cc3f9", "price_changes": [{"asset_id": "63990477029527440251791260115609966942867460219987284386576624440536500927768", "price": "0.002", "size": "11.82", "side": "BUY", "hash": "c735d2814829342356d84c135ef22869bacc5387", "best_bid": "0.011", "best_ask": "0.035"}, {"asset_id": "16513348473820721539329266419516258589145306802106861039482427297186980662547", "price": "0.998", "size": "11.82", "side": "SELL", "hash": "55ad0590d149e02c9a99c90484a267df00ce3346", "best_bid": "0.965", "best_ask": "0.989"}], "timestamp": "1769384850869", "event_type": "price_change"}}
{"_local_timestamp": "2026-01-25T23:47:31.528922+00:00", "data": {"market": "0x61c7a2857f724184aeefcfc1d5c2d058f0b5a3d95c07e0698a8702a2044cc3f9", "price_changes": [{"asset_id": "63990477029527440251791260115609966942867460219987284386576624440536500927768", "price": "0.003", "size": "22.5", "side": "BUY", "hash": "0b64f52c6eb56ee84cb251719719147194688cdc", "best_bid": "0.011", "best_ask": "0.035"}, {"asset_id": "16513348473820721539329266419516258589145306802106861039482427297186980662547", "price": "0.997", "size": "22.5", "side": "SELL", "hash": "a31621bf4675b52084a4403bc7ec43230a678398", "best_bid": "0.965", "best_ask": "0.989"}], "timestamp": "1769384851284", "event_type": "price_change"}}
{"_local_timestamp": "2026-01-25T23:47:34.529525+00:00", "data": {"market": "0x1abd61ad100d8895f3584b464ef167f3518e25a6030881103d14acc083ebad96", "price_changes": [{"asset_id": "91437369688558543467551854737984316990748701143376320320377387982132471568811", "price": "0.42", "size": "48", "side": "BUY", "hash": "f5fc214dddc359940206820904f86aad1df0c23a", "best_bid": "0.42", "best_ask": "0.52"}, {"asset_id": "88964156506218863777298237975219012171691782824739196411832554942435520583952", "price": "0.58", "size": "48", "side": "SELL", "hash": "0bbd49092f49c173d331293da5c2dea715a786de", "best_bid": "0.48", "best_ask": "0.58"}], "timestamp": "1769384854280", "event_type": "price_change"}}
{"_local_timestamp": "2026-01-25T23:47:34.676199+00:00", "data": {"market": "0x1abd61ad100d8895f3584b464ef167f3518e25a6030881103d14acc083ebad96", "price_changes": [{"asset_id": "88964156506218863777298237975219012171691782824739196411832554942435520583952", "price": "0.48", "size": "44", "side": "BUY", "hash": "8cec84db76414831b686dd09d73e85407a31656e", "best_bid": "0.48", "best_ask": "0.58"}, {"asset_id": "91437369688558543467551854737984316990748701143376320320377387982132471568811", "price": "0.52", "size": "44", "side": "SELL", "hash": "aead733451b03acd74d49ea8097792407dbd76c8", "best_bid": "0.42", "best_ask": "0.52"}], "timestamp": "1769384854434", "event_type": "price_change"}}
{"_local_timestamp": "2026-01-25T23:47:36.788513+00:00", "data": {"market": "0xfbaf6c00d1702c189522a2025f8d52d01348978b16dfe5bd51d5d2f5d6712b0b", "price_changes": [{"asset_id": "102477275037226691782080912266896459375744854273025191158751338694645017892558", "price": "0.25", "size": "0", "side": "BUY", "hash": "e8475fb14191d3828182be906142aa4ccfccfc4b", "best_bid": "0.24", "best_ask": "0.37"}, {"asset_id": "58436266613638193406222525170978476700361341943881268058813684153244605853496", "price": "0.75", "size": "0", "side": "SELL", "hash": "bdd2d7dcf417d6259fc09fcf21929a46450f77bc", "best_bid": "0.63", "best_ask": "0.76"}], "timestamp": "1769384856508", "event_type": "price_change"}}
{"_local_timestamp": "2026-01-25T23:47:36.812630+00:00", "data": {"market": "0xfbaf6c00d1702c189522a2025f8d52d01348978b16dfe5bd51d5d2f5d6712b0b", "price_changes": [{"asset_id": "102477275037226691782080912266896459375744854273025191158751338694645017892558", "price": "0.14", "size": "8.5", "side": "BUY", "hash": "ff2e23cc1dcbaff6885018d959f8f3ec99cf5360", "best_bid": "0.24", "best_ask": "0.37"}, {"asset_id": "58436266613638193406222525170978476700361341943881268058813684153244605853496", "price": "0.86", "size": "8.5", "side": "SELL", "hash": "a0c20c359146cf15efd49817071f5ee0cfd814ea", "best_bid": "0.63", "best_ask": "0.76"}], "timestamp": "1769384856544", "event_type": "price_change"}}
{"_local_timestamp": "2026-01-25T23:47:47.399847+00:00", "data": {"market": "0x0fc8dc44e3de82ae300787c180950bc3dd188e0c719d86e8559099aeb2491ff3", "price_changes": [{"asset_id": "107230676698401838350579684070148863651625417715181026919457587632470951166569", "price": "0.002", "size": "11.49", "side": "BUY", "hash": "22579fd8a84ba680b8518934a28d8ea7816571ce", "best_bid": "0.011", "best_ask": "0.029"}, {"asset_id": "68332573930090360687168031629975305535066054733932461259656105000052034697965", "price": "0.998", "size": "11.49", "side": "SELL", "hash": "9f53bfa85168d0eb251285e591e91eb9b918fc12", "best_bid": "0.971", "best_ask": "0.989"}], "timestamp": "1769384867318", "event_type": "price_change"}}
{"_local_timestamp": "2026-01-25T23:47:47.704884+00:00", "data": {"market": "0x0fc8dc44e3de82ae300787c180950bc3dd188e0c719d86e8559099aeb2491ff3", "price_changes": [{"asset_id": "107230676698401838350579684070148863651625417715181026919457587632470951166569", "price": "0.003", "size": "8.26", "side": "BUY", "hash": "1a9e1c3e730400f3d0550dd53968788c23f7c7d1", "best_bid": "0.011", "best_ask": "0.029"}, {"asset_id": "68332573930090360687168031629975305535066054733932461259656105000052034697965", "price": "0.997", "size": "8.26", "side": "SELL", "hash": "87a371514e527c1cf1fd722226229b840a64c45d", "best_bid": "0.971", "best_ask": "0.989"}], "timestamp": "1769384867631", "event_type": "price_change"}}
{"_local_timestamp": "2026-01-25T23:47:55.505307+00:00", "data": {"market": "0x1abd61ad100d8895f3584b464ef167f3518e25a6030881103d14acc083ebad96", "price_changes": [{"asset_id": "91437369688558543467551854737984316990748701143376320320377387982132471568811", "price": "0.07", "size": "0", "side": "BUY", "hash": "0fa9ad51a4e30bfcd225acc7637caffec08b3ec2", "best_bid": "0.42", "best_ask": "0.52"}, {"asset_id": "88964156506218863777298237975219012171691782824739196411832554942435520583952", "price": "0.93", "size": "0", "side": "SELL", "hash": "3ae2b9a1e6ba405788a683f0422e6893e03cc440", "best_bid": "0.48", "best_ask": "0.58"}], "timestamp": "1769384875410", "event_type": "price_change"}}
{"_local_timestamp": "2026-01-25T23:47:55.565818+00:00", "data": {"market": "0x1abd61ad100d8895f3584b464ef167f3518e25a6030881103d14acc083ebad96", "price_changes": [{"asset_id": "88964156506218863777298237975219012171691782824739196411832554942435520583952", "price": "0.11", "size": "1200", "side": "BUY", "hash": "a41b0c72e731c6384a8da0d3bc918c5a0dbedce8", "best_bid": "0.48", "best_ask": "0.58"}, {"asset_id": "91437369688558543467551854737984316990748701143376320320377387982132471568811", "price": "0.89", "size": "1200", "side": "SELL", "hash": "b8e788f49a8616b7e76774cc1b2b65c278a11fd9", "best_bid": "0.42", "best_ask": "0.52"}], "timestamp": "1769384875413", "event_type": "price_change"}}
{"_local_timestamp": "2026-01-25T23:47:55.620378+00:00", "data": {"market": "0xfbaf6c00d1702c189522a2025f8d52d01348978b16dfe5bd51d5d2f5d6712b0b", "price_changes": [{"asset_id": "58436266613638193406222525170978476700361341943881268058813684153244605853496", "price": "0.17", "size": "0", "side": "BUY", "hash": "a5b9d8f0f44e628e14cdab55d88acf2c9babc11d", "best_bid": "0.63", "best_ask": "0.76"}, {"asset_id": "102477275037226691782080912266896459375744854273025191158751338694645017892558", "price": "0.83", "size": "0", "side": "SELL", "hash": "58c8aa78f5efcef58b412e3af003eadf13211d7a", "best_bid": "0.24", "best_ask": "0.37"}], "timestamp": "1769384875417", "event_type": "price_change"}}
{"_local_timestamp": "2026-01-25T23:48:12.461718+00:00", "data": {"market": "0x5372c3942dac612d595f10ab9ee944a0fb1f521f8a0f7e5e4c69ea7f820b9205", "price_changes": [{"asset_id": "28425112653106522555623063788214711387350887710590000638731586279221931393822", "price": "0.017", "size": "0", "side": "BUY", "hash": "d7684ff7374d820f4da850f11f6d8668e73cacd6", "best_bid": "0.81", "best_ask": "0.998"}, {"asset_id": "14539781518361540889330537982912764909191745060309412974583163279274941075133", "price": "0.983", "size": "0", "side": "SELL", "hash": "0ae9e9296257858341e7dfe61da15b9546b332b8", "best_bid": "0.002", "best_ask": "0.19"}], "timestamp": "1769384892394", "event_type": "price_change"}}
{"_local_timestamp": "2026-01-25T23:48:12.869184+00:00", "data": {"market": "0x5372c3942dac612d595f10ab9ee944a0fb1f521f8a0f7e5e4c69ea7f820b9205", "price_changes": [{"asset_id": "28425112653106522555623063788214711387350887710590000638731586279221931393822", "price": "0.017", "size": "5", "side": "BUY", "hash": "c0e11bb4eb700c3f34793a986f7d10af6f9cf2cd", "best_bid": "0.81", "best_ask": "0.998"}, {"asset_id": "14539781518361540889330537982912764909191745060309412974583163279274941075133", "price": "0.983", "size": "5", "side": "SELL", "hash": "9f7fd4ca3d00467bc3cf2e1e724e3df9ebc3a3e3", "best_bid": "0.002", "best_ask": "0.19"}], "timestamp": "1769384892805", "event_type": "price_change"}}
{"_local_timestamp": "2026-01-25T23:48:12.969892+00:00", "data": {"market": "0xfbaf6c00d1702c189522a2025f8d52d01348978b16dfe5bd51d5d2f5d6712b0b", "price_changes": [{"asset_id": "58436266613638193406222525170978476700361341943881268058813684153244605853496", "price": "0.19", "size": "2210", "side": "BUY", "hash": "02d19a5ac6510f70dfbc105dcaa5a785e260d9ce", "best_bid": "0.63", "best_ask": "0.76"}, {"asset_id": "102477275037226691782080912266896459375744854273025191158751338694645017892558", "price": "0.81", "size": "2210", "side": "SELL", "hash": "7c961c1c0febe059c8fda8c74f18e359b126bd5b", "best_bid": "0.24", "best_ask": "0.37"}], "timestamp": "1769384892897", "event_type": "price_change"}}
{"_local_timestamp": "2026-01-25T23:48:17.022744+00:00", "data": {"market": "0xfbaf6c00d1702c189522a2025f8d52d01348978b16dfe5bd51d5d2f5d6712b0b", "price_changes": [{"asset_id": "58436266613638193406222525170978476700361341943881268058813684153244605853496", "price": "0.06", "size": "2000", "side": "BUY", "hash": "5d64fdeb3dae03ee300d2745531ece4b426edb28", "best_bid": "0.63", "best_ask": "0.76"}, {"asset_id": "102477275037226691782080912266896459375744854273025191158751338694645017892558", "price": "0.94", "size": "2000", "side": "SELL", "hash": "b2a9310837177aad509079d1279fe741e14fd97e", "best_bid": "0.24", "best_ask": "0.37"}], "timestamp": "1769384896956", "event_type": "price_change"}}
{"_local_timestamp": "2026-01-25T23:48:17.026569+00:00", "data": {"market": "0xfbaf6c00d1702c189522a2025f8d52d01348978b16dfe5bd51d5d2f5d6712b0b", "price_changes": [{"asset_id": "58436266613638193406222525170978476700361341943881268058813684153244605853496", "price": "0.03", "size": "4016", "side": "BUY", "hash": "5d64fdeb3dae03ee300d2745531ece4b426edb28", "best_bid": "0.63", "best_ask": "0.76"}, {"asset_id": "102477275037226691782080912266896459375744854273025191158751338694645017892558", "price": "0.97", "size": "4016", "side": "SELL", "hash": "b2a9310837177aad509079d1279fe741e14fd97e", "best_bid": "0.24", "best_ask": "0.37"}], "timestamp": "1769384896956", "event_type": "price_change"}}
{"_local_timestamp": "2026-01-25T23:48:17.027372+00:00", "data": {"market": "0xfbaf6c00d1702c189522a2025f8d52d01348978b16dfe5bd51d5d2f5d6712b0b", "price_changes": [{"asset_id": "58436266613638193406222525170978476700361341943881268058813684153244605853496", "price": "0.01", "size": "12043.4", "side": "BUY", "hash": "5d64fdeb3dae03ee300d2745531ece4b426edb28", "best_bid": "0.63", "best_ask": "0.76"}, {"asset_id": "102477275037226691782080912266896459375744854273025191158751338694645017892558", "price": "0.99", "size": "12043.4", "side": "SELL", "hash": "b2a9310837177aad509079d1279fe741e14fd97e", "best_bid": "0.24", "best_ask": "0.37"}], "timestamp": "1769384896956", "event_type": "price_change"}}
{"_local_timestamp": "2026-01-25T23:48:18.597819+00:00", "data": {"market": "0x5372c3942dac612d595f10ab9ee944a0fb1f521f8a0f7e5e4c69ea7f820b9205", "price_changes": [{"asset_id": "14539781518361540889330537982912764909191745060309412974583163279274941075133", "price": "0.001", "size": "2639", "side": "BUY", "hash": "f819a61b5d513d19fa6639b8dba274c385bd1e6f", "best_bid": "0.002", "best_ask": "0.19"}, {"asset_id": "28425112653106522555623063788214711387350887710590000638731586279221931393822", "price": "0.999", "size": "2639", "side": "SELL", "hash": "282536af8730a98218a08d278e465bddf1f3ba31", "best_bid": "0.81", "best_ask": "0.998"}], "timestamp": "1769384898527", "event_type": "price_change"}}
{"_local_timestamp": "2026-01-25T23:48:18.978222+00:00", "data": {"market": "0x5372c3942dac612d595f10ab9ee944a0fb1f521f8a0f7e5e4c69ea7f820b9205", "price_changes": [{"asset_id": "14539781518361540889330537982912764909191745060309412974583163279274941075133", "price": "0.001", "size": "2685.61", "side": "BUY", "hash": "64c1c9d5cd0c0b7a260aa7ac2583812d0491c542", "best_bid": "0.002", "best_ask": "0.19"}, {"asset_id": "28425112653106522555623063788214711387350887710590000638731586279221931393822", "price": "0.999", "size": "2685.61", "side": "SELL", "hash": "9b94c46c5452e7ee3cb6d4e1e2526ce1359d964b", "best_bid": "0.81", "best_ask": "0.998"}], "timestamp": "1769384898912", "event_type": "price_change"}}
{"_local_timestamp": "2026-01-25T23:48:29.423547+00:00", "data": {"market": "0xfbaf6c00d1702c189522a2025f8d52d01348978b16dfe5bd51d5d2f5d6712b0b", "price_changes": [{"asset_id": "102477275037226691782080912266896459375744854273025191158751338694645017892558", "price": "0.1", "size": "21", "side": "BUY", "hash": "8b7d0eb4272f1bd1dae64753ccb248d8c8e8b0cf", "best_bid": "0.24", "best_ask": "0.37"}, {"asset_id": "58436266613638193406222525170978476700361341943881268058813684153244605853496", "price": "0.9", "size": "21", "side": "SELL", "hash": "1436090cf788a6794a93070075fa3199dcb4f08f", "best_bid": "0.63", "best_ask": "0.76"}], "timestamp": "1769384909343", "event_type": "price_change"}}
{"_local_timestamp": "2026-01-25T23:48:31.145277+00:00", "data": {"market": "0xc1c29be70cd39c9f72de2ab9338c1aa8b461ebe5f4969905654bdafe679afa07", "price_changes": [{"asset_id": "50325657743512433706892707197152031907050232791405235081059080709963762445435", "price": "0.006", "size": "0", "side": "BUY", "hash": "c6ae46c3f7af7f3680b2299cb00b1cc2470f399e", "best_bid": "0.011", "best_ask": "0.035"}, {"asset_id": "97834981188079665391659336156149815346383761304074482681876419862703828354805", "price": "0.994", "size": "0", "side": "SELL", "hash": "906f24d9076c21b7023148fa22fe874db06d0780", "best_bid": "0.965", "best_ask": "0.989"}], "timestamp": "1769384911035", "event_type": "price_change"}}
{"_local_timestamp": "2026-01-25T23:48:31.488201+00:00", "data": {"market": "0xc1c29be70cd39c9f72de2ab9338c1aa8b461ebe5f4969905654bdafe679afa07", "price_changes": [{"asset_id": "50325657743512433706892707197152031907050232791405235081059080709963762445435", "price": "0.003", "size": "14.45", "side": "BUY", "hash": "f883f24e41538fad94ec5c2f2493178c4fe4122b", "best_bid": "0.011", "best_ask": "0.035"}, {"asset_id": "97834981188079665391659336156149815346383761304074482681876419862703828354805", "price": "0.997", "size": "14.45", "side": "SELL", "hash": "90e5e9307ecd95e8f7b074f107cf42359d19397b", "best_bid": "0.965", "best_ask": "0.989"}], "timestamp": "1769384911409", "event_type": "price_change"}}
{"_local_timestamp": "2026-01-25T23:48:31.490074+00:00", "data": {"market": "0xc1c29be70cd39c9f72de2ab9338c1aa8b461ebe5f4969905654bdafe679afa07", "price_changes": [{"asset_id": "50325657743512433706892707197152031907050232791405235081059080709963762445435", "price": "0.007", "size": "7.06", "side": "BUY", "hash": "ec4e357d3f7fb9d6f04bd2eb9cc434fde7692a3e", "best_bid": "0.011", "best_ask": "0.035"}, {"asset_id": "97834981188079665391659336156149815346383761304074482681876419862703828354805", "price": "0.993", "size": "7.06", "side": "SELL", "hash": "308997973f502aaa865ee22bc16656f8c29db24a", "best_bid": "0.965", "best_ask": "0.989"}], "timestamp": "1769384911410", "event_type": "price_change"}}
{"_local_timestamp": "2026-01-25T23:48:31.885609+00:00", "data": {"market": "0x1abd61ad100d8895f3584b464ef167f3518e25a6030881103d14acc083ebad96", "price_changes": [{"asset_id": "88964156506218863777298237975219012171691782824739196411832554942435520583952", "price": "0.08", "size": "5250", "side": "BUY", "hash": "a0008fa4dec071be016fed8bdd6e48e5cadc78ce", "best_bid": "0.48", "best_ask": "0.58"}, {"asset_id": "91437369688558543467551854737984316990748701143376320320377387982132471568811", "price": "0.92", "size": "5250", "side": "SELL", "hash": "ed5802eb4f7b9c8c18e7626a2c1c4e9157da4af8", "best_bid": "0.42", "best_ask": "0.52"}], "timestamp": "1769384911808", "event_type": "price_change"}}
{"_local_timestamp": "2026-01-25T23:48:33.209423+00:00", "data": {"market": "0xfbaf6c00d1702c189522a2025f8d52d01348978b16dfe5bd51d5d2f5d6712b0b", "price_changes": [{"asset_id": "102477275037226691782080912266896459375744854273025191158751338694645017892558", "price": "0.22", "size": "50", "side": "BUY", "hash": "b07634b4a304f82c990d202dea95d495de69c902", "best_bid": "0.24", "best_ask": "0.37"}, {"asset_id": "58436266613638193406222525170978476700361341943881268058813684153244605853496", "price": "0.78", "size": "50", "side": "SELL", "hash": "fabaf5d2e540587b576dda7c50a6cef29c700e65", "best_bid": "0.63", "best_ask": "0.76"}], "timestamp": "1769384913125", "event_type": "price_change"}}
{"_local_timestamp": "2026-01-25T23:48:33.314218+00:00", "data": {"market": "0xfbaf6c00d1702c189522a2025f8d52d01348978b16dfe5bd51d5d2f5d6712b0b", "price_changes": [{"asset_id": "102477275037226691782080912266896459375744854273025191158751338694645017892558", "price": "0.15", "size": "10", "side": "BUY", "hash": "4c15e2ea8fd08b62b587302cfa0f838ddff045b6", "best_bid": "0.24", "best_ask": "0.37"}, {"asset_id": "58436266613638193406222525170978476700361341943881268058813684153244605853496", "price": "0.85", "size": "10", "side": "SELL", "hash": "9ec1bf2f535daaba6533aee6438da068beb5a38b", "best_bid": "0.63", "best_ask": "0.76"}], "timestamp": "1769384913234", "event_type": "price_change"}}
{"_local_timestamp": "2026-01-25T23:48:35.801630+00:00", "data": {"market": "0xfbaf6c00d1702c189522a2025f8d52d01348978b16dfe5bd51d5d2f5d6712b0b", "price_changes": [{"asset_id": "58436266613638193406222525170978476700361341943881268058813684153244605853496", "price": "0.06", "size": "3000", "side": "BUY", "hash": "7e048e3ca285dc4bb192e9d690402ce61a85c9e2", "best_bid": "0.63", "best_ask": "0.76"}, {"asset_id": "102477275037226691782080912266896459375744854273025191158751338694645017892558", "price": "0.94", "size": "3000", "side": "SELL", "hash": "7e43c2e0809dc24a5768209d344e33fd21d989d0", "best_bid": "0.24", "best_ask": "0.37"}], "timestamp": "1769384915718", "event_type": "price_change"}}
{"_local_timestamp": "2026-01-25T23:48:35.802633+00:00", "data": {"market": "0xfbaf6c00d1702c189522a2025f8d52d01348978b16dfe5bd51d5d2f5d6712b0b", "price_changes": [{"asset_id": "58436266613638193406222525170978476700361341943881268058813684153244605853496", "price": "0.01", "size": "17043.4", "side": "BUY", "hash": "77ebca7ce9bfc7eaef73d6c16bcc6e8a82267028", "best_bid": "0.63", "best_ask": "0.76"}, {"asset_id": "102477275037226691782080912266896459375744854273025191158751338694645017892558", "price": "0.99", "size": "17043.4", "side": "SELL", "hash": "11d28908084889d94be7e45e1932de9c38c6fe8d", "best_bid": "0.24", "best_ask": "0.37"}], "timestamp": "1769384915719", "event_type": "price_change"}}
{"_local_timestamp": "2026-01-25T23:48:35.803456+00:00", "data": {"market": "0xfbaf6c00d1702c189522a2025f8d52d01348978b16dfe5bd51d5d2f5d6712b0b", "price_changes": [{"asset_id": "58436266613638193406222525170978476700361341943881268058813684153244605853496", "price": "0.08", "size": "2837", "side": "BUY", "hash": "0c29121ce6359b7cefc0dbfe9f8b516a691180c3", "best_bid": "0.63", "best_ask": "0.76"}, {"asset_id": "102477275037226691782080912266896459375744854273025191158751338694645017892558", "price": "0.92", "size": "2837", "side": "SELL", "hash": "90ff3320b62d3fc108c44a9af53e38f9a8c36c65", "best_bid": "0.24", "best_ask": "0.37"}], "timestamp": "1769384915720", "event_type": "price_change"}}
{"_local_timestamp": "2026-01-25T23:48:35.804211+00:00", "data": {"market": "0xfbaf6c00d1702c189522a2025f8d52d01348978b16dfe5bd51d5d2f5d6712b0b", "price_changes": [{"asset_id": "58436266613638193406222525170978476700361341943881268058813684153244605853496", "price": "0.03", "size": "6016", "side": "BUY", "hash": "960727de166205c19cdd76737b1e528df92f0ac3", "best_bid": "0.63", "best_ask": "0.76"}, {"asset_id": "102477275037226691782080912266896459375744854273025191158751338694645017892558", "price": "0.97", "size": "6016", "side": "SELL", "hash": "38bca709095e2718478905cfd079ba9ed21fd572", "best_bid": "0.24", "best_ask": "0.37"}], "timestamp": "1769384915720", "event_type": "price_change"}}
{"_local_timestamp": "2026-01-25T23:48:38.805553+00:00", "data": {"market": "0xfbaf6c00d1702c189522a2025f8d52d01348978b16dfe5bd51d5d2f5d6712b0b", "price_changes": [{"asset_id": "102477275037226691782080912266896459375744854273025191158751338694645017892558", "price": "0.14", "size": "0", "side": "BUY", "hash": "2a9f7ece9824bdcb1ea4a9230bd56bedc4bd79e1", "best_bid": "0.24", "best_ask": "0.37"}, {"asset_id": "58436266613638193406222525170978476700361341943881268058813684153244605853496", "price": "0.86", "size": "0", "side": "SELL", "hash": "4c77397d2ba4274a11771f4a16808d3d83748c1a", "best_bid": "0.63", "best_ask": "0.76"}], "timestamp": "1769384918720", "event_type": "price_change"}}
{"_local_timestamp": "2026-01-25T23:48:38.833499+00:00", "data": {"market": "0xfbaf6c00d1702c189522a2025f8d52d01348978b16dfe5bd51d5d2f5d6712b0b", "price_changes": [{"asset_id": "102477275037226691782080912266896459375744854273025191158751338694645017892558", "price": "0.25", "size": "8.5", "side": "BUY", "hash": "c74c53d677c89d1dae4a989846a5ae31339c8e14", "best_bid": "0.25", "best_ask": "0.37"}, {"asset_id": "58436266613638193406222525170978476700361341943881268058813684153244605853496", "price": "0.75", "size": "8.5", "side": "SELL", "hash": "43fb84f346340423095759531e82964f46a7da44", "best_bid": "0.63", "best_ask": "0.75"}], "timestamp": "1769384918757", "event_type": "price_change"}}
{"_local_timestamp": "2026-01-25T23:48:39.059739+00:00", "data": {"market": "0x61c7a2857f724184aeefcfc1d5c2d058f0b5a3d95c07e0698a8702a2044cc3f9", "price_changes": [{"asset_id": "63990477029527440251791260115609966942867460219987284386576624440536500927768", "price": "0.003", "size": "11", "side": "BUY", "hash": "30e52d510f59535c591a8e1a9b501047478ceb59", "best_bid": "0.011", "best_ask": "0.035"}, {"asset_id": "16513348473820721539329266419516258589145306802106861039482427297186980662547", "price": "0.997", "size": "11", "side": "SELL", "hash": "ddff846f5404a5293b4a02523f6e1e59ff395b88", "best_bid": "0.965", "best_ask": "0.989"}], "timestamp": "1769384918984", "event_type": "price_change"}}
{"_local_timestamp": "2026-01-25T23:48:39.532014+00:00", "data": {"market": "0x61c7a2857f724184aeefcfc1d5c2d058f0b5a3d95c07e0698a8702a2044cc3f9", "price_changes": [{"asset_id": "63990477029527440251791260115609966942867460219987284386576624440536500927768", "price": "0.004", "size": "17.29", "side": "BUY", "hash": "907aa73d4b5959a494561a10498dc60d1cbcd7d5", "best_bid": "0.011", "best_ask": "0.035"}, {"asset_id": "16513348473820721539329266419516258589145306802106861039482427297186980662547", "price": "0.996", "size": "17.29", "side": "SELL", "hash": "d01b5c7f1cf39ae9f993050bfe0e0901ffd9cfe1", "best_bid": "0.965", "best_ask": "0.989"}], "timestamp": "1769384919459", "event_type": "price_change"}}
{"_local_timestamp": "2026-01-25T23:48:53.913684+00:00", "data": {"market": "0x6bab28a6f5075597847fb403af058162a9160f08892970974b6a7f092f53bbc9", "price_changes": [{"asset_id": "825568625501271247311152915286608704339236896918641095426409218916618217433", "price": "0.219", "size": "0", "side": "SELL", "hash": "ac9ad1d5ff76cdf86843a74810437fbfd3e050e8", "best_bid": "0.038", "best_ask": "0.157"}, {"asset_id": "21214163253707781505820437681298157027008420325518755618864634836518062956958", "price": "0.781", "size": "0", "side": "BUY", "hash": "0505a7dc638a70a6341ef5b281cbb8ab54b4762d", "best_bid": "0.843", "best_ask": "0.962"}], "timestamp": "1769384933828", "event_type": "price_change"}}
{"_local_timestamp": "2026-01-25T23:48:53.920435+00:00", "data": {"market": "0x1abd61ad100d8895f3584b464ef167f3518e25a6030881103d14acc083ebad96", "price_changes": [{"asset_id": "88964156506218863777298237975219012171691782824739196411832554942435520583952", "price": "0.64", "size": "30.55", "side": "SELL", "hash": "03b1823506bc42dd86d5ee91da209c42fbc34e63", "best_bid": "0.48", "best_ask": "0.58"}, {"asset_id": "91437369688558543467551854737984316990748701143376320320377387982132471568811", "price": "0.36", "size": "30.55", "side": "BUY", "hash": "6a39520df28dc15e4b968a2f130229412e286185", "best_bid": "0.42", "best_ask": "0.52"}], "timestamp": "1769384933829", "event_type": "price_change"}}
{"_local_timestamp": "2026-01-25T23:48:53.921350+00:00", "data": {"market": "0x1f25736a90ae1de3f2057416d9f0a3652b2e43f368e5b75f4ee46df8fd7099d7", "price_changes": [{"asset_id": "85290322537586030345323653214662930196438127025557552966516002506549266651006", "price": "0.109", "size": "0", "side": "SELL", "hash": "4720bac4dc94d5445af33cf5e5792714a903d8c2", "best_bid": "0.013", "best_ask": "0.1"}, {"asset_id": "28461575412803182588864269239832585057094860326193714190433339272934528877081", "price": "0.891", "size": "0", "side": "BUY", "hash": "b3c3099015ccbb40c9ff243fbf28b9cde9be8c15", "best_bid": "0.9", "best_ask": "0.987"}], "timestamp": "1769384933829", "event_type": "price_change"}}
{"_local_timestamp": "2026-01-25T23:48:57.749865+00:00", "data": {"market": "0x61c7a2857f724184aeefcfc1d5c2d058f0b5a3d95c07e0698a8702a2044cc3f9", "price_changes": [{"asset_id": "16513348473820721539329266419516258589145306802106861039482427297186980662547", "price": "0.942", "size": "0", "side": "BUY", "hash": "580b114fb5cf6dd80f1298669bc1e5edfb941388", "best_bid": "0.965", "best_ask": "0.989"}, {"asset_id": "63990477029527440251791260115609966942867460219987284386576624440536500927768", "price": "0.058", "size": "0", "side": "SELL", "hash": "d7f6092359f6c314ba99b2998170770bd8609af1", "best_bid": "0.011", "best_ask": "0.035"}], "timestamp": "1769384937678", "event_type": "price_change"}}
