{"_local_timestamp": "2026-01-25T23:33:31.695568+00:00", "data": [{"market": "0xa5e46823b12f8751471c740cb5611827629c198f80aca1624867773bfc58d8a6", "asset_id": "3056942142656390250297633237719893992746229918619747110824738083465804504940", "timestamp": "1769383987778", "hash": "5a9d153c5dffa97f3b084301daf873849ab29cbe", "bids": [{"price": "0.01", "size": "5510.86"}, {"price": "0.02", "size": "2200"}, {"price": "0.03", "size": "6.74"}, {"price": "0.05", "size": "30"}, {"price": "0.06", "size": "33"}, {"price": "0.07", "size": "8.22"}, {"price": "0.09", "size": "1000"}, {"price": "0.14", "size": "517.85"}, {"price": "0.19", "size": "318.42"}, {"price": "0.2", "size": "60"}, {"price": "0.21", "size": "5.3"}, {"price": "0.23", "size": "271.73"}, {"price": "0.24", "size": "100"}, {"price": "0.28", "size": "92.85"}, {"price": "0.33", "size": "72.72"}, {"price": "0.35", "size": "25"}, {"price": "0.38", "size": "52.63"}, {"price": "0.55", "size": "100"}, {"price": "0.56", "size": "16.75"}, {"price": "0.57", "size": "5"}, {"price": "0.58", "size": "10"}, {"price": "0.75", "size": "21.4"}, {"price": "0.84", "size": "30"}, {"price": "0.85", "size": "9.97"}], "asks": [{"price": "0.99", "size": "3000"}, {"price": "0.98", "size": "200"}, {"price": "0.97", "size": "230.94"}, {"price": "0.96", "size": "5.94"}, {"price": "0.95", "size": "15.03"}, {"price": "0.94", "size": "47.6"}], "event_type": "book", "last_trade_price": "0.090"}, {"market": "0x059da3ba4ea3b184e31fb8978967cbd607f5187de5846b64dcd6777ab11dbfcf", "asset_id": "98400648527667164765783273069456261018306904239322551307759035804553498481296", "timestamp": "1769383987787", "hash": "aa3febbe52b2917c1b466f46991c8ef59ee4b64f", "bids": [{"price": "0.001", "size": "25656"}, {"price": "0.002", "size": "500"}, {"price": "0.003", "size": "380"}, {"price": "0.004", "size": "304"}, {"price": "0.005", "size": "300"}, {"price": "0.006", "size": "296.01"}], "asks": [{"price": "0.999", "size": "3871.07"}, {"price": "0.998", "size": "1250"}, {"price": "0.997", "size": "1407.33"}, {"price": "0.994", "size": "200"}, {"price": "0.993", "size": "10.77"}, {"price": "0.99", "size": "5500"}, {"price": "0.98", "size": "2200"}, {"price": "0.979", "size": "9.63"}, {"price": "0.95", "size": "30"}, {"price": "0.949", "size": "39"}, {"price": "0.94", "size": "500"}, {"price": "0.939", "size": "10.92"}, {"price": "0.9", "size": "860"}, {"price": "0.85", "size": "826.66"}, {"price": "0.8", "size": "360"}, {"price": "0.799", "size": "5.09"}, {"price": "0.798", "size": "5.06"}, {"price": "0.75", "size": "212"}, {"price": "0.7", "size": "186.66"}, {"price": "0.699", "size": "100"}, {"price": "0.66", "size": "50"}, {"price": "0.65", "size": "68.57"}, {"price": "0.649", "size": "34"}, {"price": "0.6", "size": "50"}, {"price": "0.597", "size": "5"}, {"price": "0.357", "size": "100"}, {"price": "0.356", "size": "23.16"}, {"price": "0.355", "size": "10"}, {"price": "0.13", "size": "5"}, {"price": "0.129", "size": "43.75"}, {"price": "0.128", "size": "20"}, {"price": "0.07", "size": "5"}, {"price": "0.017", "size": "5"}, {"price": "0.016", "size": "5"}], "event_type": "book", "last_trade_price": ""}, {"market": "0x059da3ba4ea3b184e31fb8978967cbd607f5187de5846b64dcd6777ab11dbfcf", "asset_id": "12442026831814665517479454307107841564924638876268430912384587148891875917807", "timestamp": "1769383987787", "hash": "809efa16743a9599728d864fb1e1223793bf6ef4", "bids": [{"price": "0.001", "size": "3871.07"}, {"price": "0.002", "size": "1250"}, {"price": "0.003", "size": "1407.33"}, {"price": "0.006", "size": "200"}, {"price": "0.007", "size": "10.77"}, {"price": "0.01", "size": "5500"}, {"price": "0.02", "size": "2200"}, {"price": "0.021", "size": "9.63"}, {"price": "0.05", "size": "30"}, {"price": "0.051", "size": "39"}, {"price": "0.06", "size": "500"}, {"price": "0.061", "size": "10.92"}, {"price": "0.1", "size": "860"}, {"price": "0.15", "size": "826.66"}, {"price": "0.2", "size": "360"}, {"price": "0.201", "size": "5.09"}, {"price": "0.202", "size": "5.06"}, {"price": "0.25", "size": "212"}, {"price": "0.3", "size": "186.66"}, {"price": "0.301", "size": "100"}, {"price": "0.34", "size": "50"}, {"price": "0.35", "size": "68.57"}, {"price": "0.351", "size": "34"}, {"price": "0.4", "size": "50"}, {"price": "0.403", "size": "5"}, {"price": "0.643", "size": "100"}, {"price": "0.644", "size": "23.16"}, {"price": "0.645", "size": "10"}, {"price": "0.87", "size": "5"}, {"price": "0.871", "size": "43.75"}, {"price": "0.872", "size": "20"}, {"price": "0.93", "size": "5"}, {"price": "0.983", "size": "5"}, {"price": "0.984", "size": "5"}], "asks": [{"price": "0.999", "size": "25656"}, {"price": "0.998", "size": "500"}, {"price": "0.997", "size": "380"}, {"price": "0.996", "size": "304"}, {"price": "0.995", "size": "300"}, {"price": "0.994", "size": "296.01"}], "event_type": "book", "last_trade_price": ""}, {"market": "0xbc63ab257269b6d88696a7c395c22a032dd8bcaec0f20b22083ac17dd8a9221c", "asset_id": "70095723080029803518081326396248438374756818653107709477379930258944056936114", "timestamp": "1769384004274", "hash": "ac551df53b0ba8750b6546f091fe8523ab39dead", "bids": [{"price": "0.01", "size": "15.66"}, {"price": "0.02", "size": "200"}, {"price": "0.03", "size": "7.8"}, {"price": "0.04", "size": "70.24"}, {"price": "0.05", "size": "6.79"}, {"price": "0.08", "size": "125"}, {"price": "0.09", "size": "14.11"}, {"price": "0.14", "size": "20.24"}, {"price": "0.16", "size": "10"}, {"price": "0.17", "size": "20"}, {"price": "0.23", "size": "43.75"}, {"price": "0.24", "size": "20.24"}], "asks": [{"price": "0.99", "size": "3505"}, {"price": "0.97", "size": "3500"}, {"price": "0.96", "size": "6.25"}, {"price": "0.95", "size": "30"}, {"price": "0.92", "size": "300"}, {"price": "0.87", "size": "550"}, {"price": "0.83", "size": "400"}, {"price": "0.75", "size": "166.66"}, {"price": "0.73", "size": "313"}, {"price": "0.55", "size": "66.66"}, {"price": "0.42", "size": "25"}, {"price": "0.4", "size": "3.98"}, {"price": "0.31", "size": "55.07"}, {"price": "0.3", "size": "66.66"}, {"price": "0.29", "size": "25"}], "event_type": "book", "last_trade_price": ""}, {"market": "0x00ece3aec2e7ec1266c81f9b6dee4d5774c5e9fc1d8b4c05750363bb6693608c", "asset_id": "56288496839116076608936080824519320480921427720682183882154533325856755856281", "timestamp": "1769383901924", "hash": "b402dbcb83cf52fcd784ce5920be8ec8e33e8e93", "bids": [{"price": "0.001", "size": "3871.08"}, {"price": "0.002", "size": "1250"}, {"price": "0.003", "size": "1407.33"}, {"price": "0.006", "size": "200"}, {"price": "0.007", "size": "10.77"}, {"price": "0.01", "size": "5500"}, {"price": "0.02", "size": "2200"}, {"price": "0.021", "size": "9.63"}, {"price": "0.05", "size": "30"}, {"price": "0.051", "size": "39"}, {"price": "0.06", "size": "500"}, {"price": "0.061", "size": "9.43"}, {"price": "0.1", "size": "860"}, {"price": "0.15", "size": "826.66"}, {"price": "0.2", "size": "360"}, {"price": "0.201", "size": "5.54"}, {"price": "0.25", "size": "212"}, {"price": "0.251", "size": "100"}, {"price": "0.3", "size": "186.66"}, {"price": "0.35", "size": "68.57"}, {"price": "0.351", "size": "34"}, {"price": "0.4", "size": "50"}, {"price": "0.62", "size": "100"}, {"price": "0.621", "size": "29.16"}, {"price": "0.633", "size": "5"}, {"price": "0.634", "size": "45.51"}, {"price": "0.636", "size": "10"}, {"price": "0.637", "size": "20"}, {"price": "0.91", "size": "5"}, {"price": "0.93", "size": "5"}, {"price": "0.987", "size": "5"}, {"price": "0.988", "size": "5"}], "asks": [{"price": "0.999", "size": "26656"}, {"price": "0.998", "size": "750"}, {"price": "0.997", "size": "392.7"}, {"price": "0.996", "size": "300"}, {"price": "0.995", "size": "290.92"}], "event_type": "book", "last_trade_price": ""}, {"market": "0x4a0ead3d8c0aa0a73f322aaa95615e7d29b414b9fc4bace855bb74a7a648d990", "asset_id": "111376742935340636514883997859794030073097390424337351101383349939644307757449", "timestamp": "1769383963281", "hash": "46c3cab264837ec4d72307933f9998fafe2d24df", "bids": [{"price": "0.01", "size": "5510.89"}, {"price": "0.02", "size": "2200"}, {"price": "0.03", "size": "6.76"}, {"price": "0.05", "size": "30"}, {"price": "0.06", "size": "33"}, {"price": "0.07", "size": "7.73"}, {"price": "0.09", "size": "1000"}, {"price": "0.14", "size": "517.85"}, {"price": "0.19", "size": "318.42"}, {"price": "0.2", "size": "5.73"}, {"price": "0.24", "size": "266.66"}, {"price": "0.25", "size": "100"}, {"price": "0.29", "size": "89.65"}, {"price": "0.33", "size": "72.72"}, {"price": "0.34", "size": "86"}, {"price": "0.38", "size": "52.63"}, {"price": "0.56", "size": "100"}, {"price": "0.57", "size": "26"}, {"price": "0.58", "size": "5"}, {"price": "0.59", "size": "10"}, {"price": "0.65", "size": "14.79"}, {"price": "0.71", "size": "39.2"}, {"price": "0.72", "size": "20"}, {"price": "0.86", "size": "8"}], "asks": [{"price": "0.99", "size": "3000"}, {"price": "0.98", "size": "200"}, {"price": "0.97", "size": "300"}, {"price": "0.96", "size": "250"}, {"price": "0.95", "size": "100"}, {"price": "0.94", "size": "25.09"}, {"price": "0.93", "size": "125.09"}, {"price": "0.92", "size": "25.09"}], "event_type": "book", "last_trade_price": ""}, {"market": "0xa5e46823b12f8751471c740cb5611827629c198f80aca1624867773bfc58d8a6", "asset_id": "95101171893122594180666530745464033001482832309010202534315814756594685314956", "timestamp": "1769383987778", "hash": "1ed3814cbca75fc3142f4a49b7f4761ca875ed98", "bids": [{"price": "0.01", "size": "3000"}, {"price": "0.02", "size": "200"}, {"price": "0.03", "size": "230.94"}, {"price": "0.04", "size": "5.94"}, {"price": "0.05", "size": "15.03"}, {"price": "0.06", "size": "47.6"}], "asks": [{"price": "0.99", "size": "5510.86"}, {"price": "0.98", "size": "2200"}, {"price": "0.97", "size": "6.74"}, {"price": "0.95", "size": "30"}, {"price": "0.94", "size": "33"}, {"price": "0.93", "size": "8.22"}, {"price": "0.91", "size": "1000"}, {"price": "0.86", "size": "517.85"}, {"price": "0.81", "size": "318.42"}, {"price": "0.8", "size": "60"}, {"price": "0.79", "size": "5.3"}, {"price": "0.77", "size": "271.73"}, {"price": "0.76", "size": "100"}, {"price": "0.72", "size": "92.85"}, {"price": "0.67", "size": "72.72"}, {"price": "0.65", "size": "25"}, {"price": "0.62", "size": "52.63"}, {"price": "0.45", "size": "100"}, {"price": "0.44", "size": "16.75"}, {"price": "0.43", "size": "5"}, {"price": "0.42", "size": "10"}, {"price": "0.25", "size": "21.4"}, {"price": "0.16", "size": "30"}, {"price": "0.15", "size": "9.97"}], "event_type": "book", "last_trade_price": "0.090"}, {"market": "0x262962b5d5b1f248aac0c99a871402f136a7a01de85aa5503c3bfa92f46b2c55", "asset_id": "106003536497972067032507723744954701264783762198809994038236889884495294178883", "timestamp": "1769383917193", "hash": "076fdc7a14c05e4e71b9bc98057c3463b3498f3a", "bids": [{"price": "0.001", "size": "999.54"}, {"price": "0.002", "size": "330.46"}, {"price": "0.003", "size": "320.2"}, {"price": "0.004", "size": "236.02"}, {"price": "0.005", "size": "154.86"}, {"price": "0.007", "size": "21.12"}, {"price": "0.01", "size": "5"}, {"price": "0.011", "size": "21.12"}], "asks": [{"price": "0.999", "size": "2995.55"}, {"price": "0.998", "size": "1255.54"}, {"price": "0.997", "size": "1000"}, {"price": "0.996", "size": "23.04"}, {"price": "0.99", "size": "5500"}, {"price": "0.98", "size": "2200"}, {"price": "0.979", "size": "9.65"}, {"price": "0.95", "size": "30"}, {"price": "0.949", "size": "39"}, {"price": "0.94", "size": "500"}, {"price": "0.939", "size": "9.44"}, {"price": "0.9", "size": "860"}, {"price": "0.85", "size": "826.66"}, {"price": "0.8", "size": "360"}, {"price": "0.799", "size": "5.53"}, {"price": "0.77", "size": "20"}, {"price": "0.75", "size": "212"}, {"price": "0.7", "size": "286.66"}, {"price": "0.65", "size": "68.57"}, {"price": "0.649", "size": "34"}, {"price": "0.648", "size": "10"}, {"price": "0.6", "size": "50"}, {"price": "0.598", "size": "5"}, {"price": "0.394", "size": "100"}, {"price": "0.19", "size": "10"}, {"price": "0.188", "size": "118.75"}, {"price": "0.187", "size": "20"}, {"price": "0.09", "size": "10"}], "event_type": "book", "last_trade_price": ""}, {"market": "0xe6703820029400bb3989c9ca94511ae96bcb6bb212e76bfce28fbc3d0712e7da", "asset_id": "26862256473738234042890995175212184751139521605012603994991408238083491315385", "timestamp": "1769383940122", "hash": "ef5c3b189f834ae47750c5c521dc2bd72a38789d", "bids": [{"price": "0.01", "size": "3000"}, {"price": "0.02", "size": "450"}, {"price": "0.03", "size": "300"}, {"price": "0.04", "size": "219.06"}, {"price": "0.06", "size": "119.06"}, {"price": "0.07", "size": "19.06"}], "asks": [{"price": "0.99", "size": "5510.9"}, {"price": "0.98", "size": "2200"}, {"price": "0.97", "size": "6.77"}, {"price": "0.95", "size": "30"}, {"price": "0.94", "size": "33"}, {"price": "0.93", "size": "7.73"}, {"price": "0.91", "size": "1000"}, {"price": "0.86", "size": "517.85"}, {"price": "0.81", "size": "318.42"}, {"price": "0.8", "size": "10.82"}, {"price": "0.76", "size": "266.66"}, {"price": "0.75", "size": "100"}, {"price": "0.73", "size": "50"}, {"price": "0.71", "size": "89.65"}, {"price": "0.67", "size": "72.72"}, {"price": "0.66", "size": "36"}, {"price": "0.62", "size": "52.63"}, {"price": "0.42", "size": "100"}, {"price": "0.4", "size": "5"}, {"price": "0.39", "size": "10"}, {"price": "0.19", "size": "20"}, {"price": "0.18", "size": "20"}, {"price": "0.16", "size": "5"}, {"price": "0.1", "size": "5"}], "event_type": "book", "last_trade_price": ""}, {"market": "0xbc63ab257269b6d88696a7c395c22a032dd8bcaec0f20b22083ac17dd8a9221c", "asset_id": "7542437468156958963085282310210526488532310459870037284043838227272438514792", "timestamp": "1769384004274", "hash": "b9c3856de973198145713b580f425cb128245e1d", "bids": [{"price": "0.01", "size": "3505"}, {"price": "0.03", "size": "3500"}, {"price": "0.04", "size": "6.25"}, {"price": "0.05", "size": "30"}, {"price": "0.08", "size": "300"}, {"price": "0.13", "size": "550"}, {"price": "0.17", "size": "400"}, {"price": "0.25", "size": "166.66"}, {"price": "0.27", "size": "313"}, {"price": "0.45", "size": "66.66"}, {"price": "0.58", "size": "25"}, {"price": "0.6", "size": "3.98"}, {"price": "0.69", "size": "55.07"}, {"price": "0.7", "size": "66.66"}, {"price": "0.71", "size": "25"}], "asks": [{"price": "0.99", "size": "15.66"}, {"price": "0.98", "size": "200"}, {"price": "0.97", "size": "7.8"}, {"price": "0.96", "size": "70.24"}, {"price": "0.95", "size": "6.79"}, {"price": "0.92", "size": "125"}, {"price": "0.91", "size": "14.11"}, {"price": "0.86", "size": "20.24"}, {"price": "0.84", "size": "10"}, {"price": "0.83", "size": "20"}, {"price": "0.77", "size": "43.75"}, {"price": "0.76", "size": "20.24"}], "event_type": "book", "last_trade_price": ""}, {"market": "0xe6703820029400bb3989c9ca94511ae96bcb6bb212e76bfce28fbc3d0712e7da", "asset_id": "65912005210412562484178321309940712764547284237411298620608183481031681522759", "timestamp": "1769383940122", "hash": "dddc60df9b00daad5e14adfe9a5ef2e12c86cf2d", "bids": [{"price": "0.01", "size": "5510.9"}, {"price": "0.02", "size": "2200"}, {"price": "0.03", "size": "6.77"}, {"price": "0.05", "size": "30"}, {"price": "0.06", "size": "33"}, {"price": "0.07", "size": "7.73"}, {"price": "0.09", "size": "1000"}, {"price": "0.14", "size": "517.85"}, {"price": "0.19", "size": "318.42"}, {"price": "0.2", "size": "10.82"}, {"price": "0.24", "size": "266.66"}, {"price": "0.25", "size": "100"}, {"price": "0.27", "size": "50"}, {"price": "0.29", "size": "89.65"}, {"price": "0.33", "size": "72.72"}, {"price": "0.34", "size": "36"}, {"price": "0.38", "size": "52.63"}, {"price": "0.58", "size": "100"}, {"price": "0.6", "size": "5"}, {"price": "0.61", "size": "10"}, {"price": "0.81", "size": "20"}, {"price": "0.82", "size": "20"}, {"price": "0.84", "size": "5"}, {"price": "0.9", "size": "5"}], "asks": [{"price": "0.99", "size": "3000"}, {"price": "0.98", "size": "450"}, {"price": "0.97", "size": "300"}, {"price": "0.96", "size": "219.06"}, {"price": "0.94", "size": "119.06"}, {"price": "0.93", "size": "19.06"}], "event_type": "book", "last_trade_price": ""}, {"market": "0x4a0ead3d8c0aa0a73f322aaa95615e7d29b414b9fc4bace855bb74a7a648d990", "asset_id": "4936830242343432951855740478936036194473488983939131588159659366497804600794", "timestamp": "1769383963281", "hash": "4262c1ded020dfe2969061655792827e4a2896ab", "bids": [{"price": "0.01", "size": "3000"}, {"price": "0.02", "size": "200"}, {"price": "0.03", "size": "300"}, {"price": "0.04", "size": "250"}, {"price": "0.05", "size": "100"}, {"price": "0.06", "size": "25.09"}, {"price": "0.07", "size": "125.09"}, {"price": "0.08", "size": "25.09"}], "asks": [{"price": "0.99", "size": "5510.89"}, {"price": "0.98", "size": "2200"}, {"price": "0.97", "size": "6.76"}, {"price": "0.95", "size": "30"}, {"price": "0.94", "size": "33"}, {"price": "0.93", "size": "7.73"}, {"price": "0.91", "size": "1000"}, {"price": "0.86", "size": "517.85"}, {"price": "0.81", "size": "318.42"}, {"price": "0.8", "size": "5.73"}, {"price": "0.76", "size": "266.66"}, {"price": "0.75", "size": "100"}, {"price": "0.71", "size": "89.65"}, {"price": "0.67", "size": "72.72"}, {"price": "0.66", "size": "86"}, {"price": "0.62", "size": "52.63"}, {"price": "0.44", "size": "100"}, {"price": "0.43", "size": "26"}, {"price": "0.42", "size": "5"}, {"price": "0.41", "size": "10"}, {"price": "0.35", "size": "14.79"}, {"price": "0.29", "size": "39.2"}, {"price": "0.28", "size": "20"}, {"price": "0.14", "size": "8"}], "event_type": "book", "last_trade_price": ""}, {"market": "0x262962b5d5b1f248aac0c99a871402f136a7a01de85aa5503c3bfa92f46b2c55", "asset_id": "19123455644246071046896212752788121367175617509312871406465324158710992613511", "timestamp": "1769383917193", "hash": "e1e92ebd57a0760a07f73e146ebe4cf241fc261b", "bids": [{"price": "0.001", "size": "2995.55"}, {"price": "0.002", "size": "1255.54"}, {"price": "0.003", "size": "1000"}, {"price": "0.004", "size": "23.04"}, {"price": "0.01", "size": "5500"}, {"price": "0.02", "size": "2200"}, {"price": "0.021", "size": "9.65"}, {"price": "0.05", "size": "30"}, {"price": "0.051", "size": "39"}, {"price": "0.06", "size": "500"}, {"price": "0.061", "size": "9.44"}, {"price": "0.1", "size": "860"}, {"price": "0.15", "size": "826.66"}, {"price": "0.2", "size": "360"}, {"price": "0.201", "size": "5.53"}, {"price": "0.23", "size": "20"}, {"price": "0.25", "size": "212"}, {"price": "0.3", "size": "286.66"}, {"price": "0.35", "size": "68.57"}, {"price": "0.351", "size": "34"}, {"price": "0.352", "size": "10"}, {"price": "0.4", "size": "50"}, {"price": "0.402", "size": "5"}, {"price": "0.606", "size": "100"}, {"price": "0.81", "size": "10"}, {"price": "0.812", "size": "118.75"}, {"price": "0.813", "size": "20"}, {"price": "0.91", "size": "10"}], "asks": [{"price": "0.999", "size": "999.54"}, {"price": "0.998", "size": "330.46"}, {"price": "0.997", "size": "320.2"}, {"price": "0.996", "size": "236.02"}, {"price": "0.995", "size": "154.86"}, {"price": "0.993", "size": "21.12"}, {"price": "0.99", "size": "5"}, {"price": "0.989", "size": "21.12"}], "event_type": "book", "last_trade_price": ""}, {"market": "0xd525650240c1956c1fd741e727302756002d34541cebb15399c6648372c2b017", "asset_id": "84363734712816699027954735716573977595829918143333969139288207428067341798047", "timestamp": "1769383937970", "hash": "ce6a265da16a774f3b7b482cbe446701f9072784", "bids": [{"price": "0.001", "size": "3870.08"}, {"price": "0.002", "size": "1250"}, {"price": "0.003", "size": "1407.33"}, {"price": "0.006", "size": "200"}, {"price": "0.007", "size": "10.77"}, {"price": "0.01", "size": "5500"}, {"price": "0.02", "size": "2200"}, {"price": "0.021", "size": "9.63"}, {"price": "0.05", "size": "30"}, {"price": "0.051", "size": "39"}, {"price": "0.06", "size": "500"}, {"price": "0.061", "size": "9.42"}, {"price": "0.1", "size": "860"}, {"price": "0.15", "size": "776.66"}, {"price": "0.2", "size": "660"}, {"price": "0.201", "size": "5.54"}, {"price": "0.25", "size": "362"}, {"price": "0.251", "size": "100"}, {"price": "0.3", "size": "186.66"}, {"price": "0.35", "size": "68.57"}, {"price": "0.4", "size": "50"}, {"price": "0.404", "size": "5"}, {"price": "0.619", "size": "100"}, {"price": "0.62", "size": "5"}, {"price": "0.621", "size": "10"}, {"price": "0.622", "size": "20"}, {"price": "0.89", "size": "5"}, {"price": "0.986", "size": "84"}], "asks": [{"price": "0.999", "size": "24863"}, {"price": "0.998", "size": "625"}, {"price": "0.997", "size": "360"}, {"price": "0.996", "size": "280"}, {"price": "0.994", "size": "200"}, {"price": "0.993", "size": "331.2"}, {"price": "0.992", "size": "131.2"}, {"price": "0.991", "size": "31.2"}], "event_type": "book", "last_trade_price": ""}, {"market": "0xd525650240c1956c1fd741e727302756002d34541cebb15399c6648372c2b017", "asset_id": "58237052681575643690608170707582085559437408445710143443295775339044140331495", "timestamp": "1769383937970", "hash": "03464601459a79365e2766aad2a860cc109a32bd", "bids": [{"price": "0.001", "size": "24863"}, {"price": "0.002", "size": "625"}, {"price": "0.003", "size": "360"}, {"price": "0.004", "size": "280"}, {"price": "0.006", "size": "200"}, {"price": "0.007", "size": "331.2"}, {"price": "0.008", "size": "131.2"}, {"price": "0.009", "size": "31.2"}], "asks": [{"price": "0.999", "size": "3870.08"}, {"price": "0.998", "size": "1250"}, {"price": "0.997", "size": "1407.33"}, {"price": "0.994", "size": "200"}, {"price": "0.993", "size": "10.77"}, {"price": "0.99", "size": "5500"}, {"price": "0.98", "size": "2200"}, {"price": "0.979", "size": "9.63"}, {"price": "0.95", "size": "30"}, {"price": "0.949", "size": "39"}, {"price": "0.94", "size": "500"}, {"price": "0.939", "size": "9.42"}, {"price": "0.9", "size": "860"}, {"price": "0.85", "size": "776.66"}, {"price": "0.8", "size": "660"}, {"price": "0.799", "size": "5.54"}, {"price": "0.75", "size": "362"}, {"price": "0.749", "size": "100"}, {"price": "0.7", "size": "186.66"}, {"price": "0.65", "size": "68.57"}, {"price": "0.6", "size": "50"}, {"price": "0.596", "size": "5"}, {"price": "0.381", "size": "100"}, {"price": "0.38", "size": "5"}, {"price": "0.379", "size": "10"}, {"price": "0.378", "size": "20"}, {"price": "0.11", "size": "5"}, {"price": "0.014", "size": "84"}], "event_type": "book", "last_trade_price": ""}, {"market": "0x00ece3aec2e7ec1266c81f9b6dee4d5774c5e9fc1d8b4c05750363bb6693608c", "asset_id": "20277485868363893965343112627224984692523382854354842924096328553726850004689", "timestamp": "1769383901924", "hash": "77dc4b8b23c9673f9f17bde2d90e68f3b17071b7", "bids": [{"price": "0.001", "size": "26656"}, {"price": "0.002", "size": "750"}, {"price": "0.003", "size": "392.7"}, {"price": "0.004", "size": "300"}, {"price": "0.005", "size": "290.92"}], "asks": [{"price": "0.999", "size": "3871.08"}, {"price": "0.998", "size": "1250"}, {"price": "0.997", "size": "1407.33"}, {"price": "0.994", "size": "200"}, {"price": "0.993", "size": "10.77"}, {"price": "0.99", "size": "5500"}, {"price": "0.98", "size": "2200"}, {"price": "0.979", "size": "9.63"}, {"price": "0.95", "size": "30"}, {"price": "0.949", "size": "39"}, {"price": "0.94", "size": "500"}, {"price": "0.939", "size": "9.43"}, {"price": "0.9", "size": "860"}, {"price": "0.85", "size": "826.66"}, {"price": "0.8", "size": "360"}, {"price": "0.799", "size": "5.54"}, {"price": "0.75", "size": "212"}, {"price": "0.749", "size": "100"}, {"price": "0.7", "size": "186.66"}, {"price": "0.65", "size": "68.57"}, {"price": "0.649", "size": "34"}, {"price": "0.6", "size": "50"}, {"price": "0.38", "size": "100"}, {"price": "0.379", "size": "29.16"}, {"price": "0.367", "size": "5"}, {"price": "0.366", "size": "45.51"}, {"price": "0.364", "size": "10"}, {"price": "0.363", "size": "20"}, {"price": "0.09", "size": "5"}, {"price": "0.07", "size": "5"}, {"price": "0.013", "size": "5"}, {"price": "0.012", "size": "5"}], "event_type": "book", "last_trade_price": ""}]}
{"_local_timestamp": "2026-01-25T23:33:33.633863+00:00", "data": {"market": "0x4a0ead3d8c0aa0a73f322aaa95615e7d29b414b9fc4bace855bb74a7a648d990", "price_changes": [{"asset_id": "111376742935340636514883997859794030073097390424337351101383349939644307757449", "price": "0.34", "size": "136", "side": "BUY", "hash": "79e73a8b471165c396b6dcb49a52997b7e4e1721", "best_bid": "0.86", "best_ask": "0.92"}, {"asset_id": "4936830242343432951855740478936036194473488983939131588159659366497804600794", "price": "0.66", "size": "136", "side": "SELL", "hash": "2546d2a817208f470bdb8c4b4f9aecac31619a14", "best_bid": "0.08", "best_ask": "0.14"}], "timestamp": "1769384013521", "event_type": "price_change"}}
{"_local_timestamp": "2026-01-25T23:33:33.661168+00:00", "data": {"market": "0x262962b5d5b1f248aac0c99a871402f136a7a01de85aa5503c3bfa92f46b2c55", "price_changes": [{"asset_id": "19123455644246071046896212752788121367175617509312871406465324158710992613511", "price": "0.34", "size": "50", "side": "BUY", "hash": "675b603b6a33152ed186949f81ee90aa79be6d31", "best_bid": "0.91", "best_ask": "0.989"}, {"asset_id": "106003536497972067032507723744954701264783762198809994038236889884495294178883", "price": "0.66", "size": "50", "side": "SELL", "hash": "c8aabcf16e9723981e72fb6cbea731b5966bb1c0", "best_bid": "0.011", "best_ask": "0.09"}], "timestamp": "1769384013521", "event_type": "price_change"}}
{"_local_timestamp": "2026-01-25T23:33:33.664542+00:00", "data": {"market": "0x4a0ead3d8c0aa0a73f322aaa95615e7d29b414b9fc4bace855bb74a7a648d990", "price_changes": [{"asset_id": "111376742935340636514883997859794030073097390424337351101383349939644307757449", "price": "0.27", "size": "50", "side": "BUY", "hash": "8a8dd5b6a0025565912aa6d04f45a5d39d60627e", "best_bid": "0.86", "best_ask": "0.92"}, {"asset_id": "4936830242343432951855740478936036194473488983939131588159659366497804600794", "price": "0.73", "size": "50", "side": "SELL", "hash": "3c138a871d086ba49a189338ef97b3aa5ac006d5", "best_bid": "0.08", "best_ask": "0.14"}], "timestamp": "1769384013526", "event_type": "price_change"}}
{"_local_timestamp": "2026-01-25T23:33:33.823700+00:00", "data": {"market": "0xd525650240c1956c1fd741e727302756002d34541cebb15399c6648372c2b017", "price_changes": [{"asset_id": "84363734712816699027954735716573977595829918143333969139288207428067341798047", "price": "0.621", "size": "0", "side": "BUY", "hash": "377c24aec05fc8b1e177fcb3ccf7bc66c59c4ca4", "best_bid": "0.986", "best_ask": "0.991"}, {"asset_id": "58237052681575643690608170707582085559437408445710143443295775339044140331495", "price": "0.379", "size": "0", "side": "SELL", "hash": "f112395b62135fbebf5fff3086f2eed779583e61", "best_bid": "0.009", "best_ask": "0.014"}], "timestamp": "1769384013748", "event_type": "price_change"}}
{"_local_timestamp": "2026-01-25T23:33:34.003105+00:00", "data": {"market": "0xd525650240c1956c1fd741e727302756002d34541cebb15399c6648372c2b017", "price_changes": [{"asset_id": "84363734712816699027954735716573977595829918143333969139288207428067341798047", "price": "0.405", "size": "71", "side": "BUY", "hash": "945bd5150f0705ab19cff12b9b7014a4433e7f65", "best_bid": "0.986", "best_ask": "0.991"}, {"asset_id": "58237052681575643690608170707582085559437408445710143443295775339044140331495", "price": "0.595", "size": "71", "side": "SELL", "hash": "86900fc9cd4facf2accb2e5558b7ec4b21a412f7", "best_bid": "0.009", "best_ask": "0.014"}], "timestamp": "1769384013927", "event_type": "price_change"}}
{"_local_timestamp": "2026-01-25T23:33:34.004566+00:00", "data": {"market": "0xd525650240c1956c1fd741e727302756002d34541cebb15399c6648372c2b017", "price_changes": [{"asset_id": "84363734712816699027954735716573977595829918143333969139288207428067341798047", "price": "0.623", "size": "10", "side": "BUY", "hash": "e0d8048b761899c0a6e6a965fd252f8430e2d53a", "best_bid": "0.986", "best_ask": "0.991"}, {"asset_id": "58237052681575643690608170707582085559437408445710143443295775339044140331495", "price": "0.377", "size": "10", "side": "SELL", "hash": "7f01681ebe0012811f8121728fda70dedd8dd6a4", "best_bid": "0.009", "best_ask": "0.014"}], "timestamp": "1769384013928", "event_type": "price_change"}}
{"_local_timestamp": "2026-01-25T23:33:37.853524+00:00", "data": {"market": "0xd525650240c1956c1fd741e727302756002d34541cebb15399c6648372c2b017", "price_changes": [{"asset_id": "84363734712816699027954735716573977595829918143333969139288207428067341798047", "price": "0.622", "size": "0", "side": "BUY", "hash": "bd966e38115e34754ef4ec048d8bd4edff362eda", "best_bid": "0.986", "best_ask": "0.991"}, {"asset_id": "58237052681575643690608170707582085559437408445710143443295775339044140331495", "price": "0.378", "size": "0", "side": "SELL", "hash": "e2087bf3a9852d18a68a5649c5f293850a1a99bf", "best_bid": "0.009", "best_ask": "0.014"}], "timestamp": "1769384017769", "event_type": "price_change"}}
{"_local_timestamp": "2026-01-25T23:33:37.865098+00:00", "data": {"market": "0xd525650240c1956c1fd741e727302756002d34541cebb15399c6648372c2b017", "price_changes": [{"asset_id": "84363734712816699027954735716573977595829918143333969139288207428067341798047", "price": "0.624", "size": "20", "side": "BUY", "hash": "0dad433575a32066308265bcc1aef49f15e2dbf3", "best_bid": "0.986", "best_ask": "0.991"}, {"asset_id": "58237052681575643690608170707582085559437408445710143443295775339044140331495", "price": "0.376", "size": "20", "side": "SELL", "hash": "5438d9b4095747c1bac8dd1f711b750dfab9b016", "best_bid": "0.009", "best_ask": "0.014"}], "timestamp": "1769384017797", "event_type": "price_change"}}
{"_local_timestamp": "2026-01-25T23:33:37.880909+00:00", "data": {"market": "0xd525650240c1956c1fd741e727302756002d34541cebb15399c6648372c2b017", "price_changes": [{"asset_id": "84363734712816699027954735716573977595829918143333969139288207428067341798047", "price": "0.405", "size": "0", "side": "BUY", "hash": "f1adea3d4034a1e2ab9edb8d517502ea1759973c", "best_bid": "0.986", "best_ask": "0.991"}, {"asset_id": "58237052681575643690608170707582085559437408445710143443295775339044140331495", "price": "0.595", "size": "0", "side": "SELL", "hash": "224165433e61ead9d0fbd4df3a7a959c57d2a199", "best_bid": "0.009", "best_ask": "0.014"}], "timestamp": "1769384017806", "event_type": "price_change"}}
{"_local_timestamp": "2026-01-25T23:33:40.739807+00:00", "data": {"market": "0x262962b5d5b1f248aac0c99a871402f136a7a01de85aa5503c3bfa92f46b2c55", "price_changes": [{"asset_id": "19123455644246071046896212752788121367175617509312871406465324158710992613511", "price": "0.3", "size": "336.66", "side": "BUY", "hash": "a2c3ca49a44e2a8ce84dd77a97991568ed14bb90", "best_bid": "0.91", "best_ask": "0.989"}, {"asset_id": "106003536497972067032507723744954701264783762198809994038236889884495294178883", "price": "0.7", "size": "336.66", "side": "SELL", "hash": "467cde3bbffd23668ed99c4efde0868cfc364a07", "best_bid": "0.011", "best_ask": "0.09"}], "timestamp": "1769384020544", "event_type": "price_change"}}
{"_local_timestamp": "2026-01-25T23:33:40.822008+00:00", "data": {"market": "0x262962b5d5b1f248aac0c99a871402f136a7a01de85aa5503c3bfa92f46b2c55", "price_changes": [{"asset_id": "19123455644246071046896212752788121367175617509312871406465324158710992613511", "price": "0.2", "size": "460", "side": "BUY", "hash": "5fe6636eba011f779999645192a39bb5f1e9608e", "best_bid": "0.91", "best_ask": "0.989"}, {"asset_id": "106003536497972067032507723744954701264783762198809994038236889884495294178883", "price": "0.8", "size": "460", "side": "SELL", "hash": "372273c163a43739421da79836e39785fc50d767", "best_bid": "0.011", "best_ask": "0.09"}], "timestamp": "1769384020583", "event_type": "price_change"}}
{"_local_timestamp": "2026-01-25T23:33:48.093958+00:00", "data": {"market": "0xe6703820029400bb3989c9ca94511ae96bcb6bb212e76bfce28fbc3d0712e7da", "price_changes": [{"asset_id": "65912005210412562484178321309940712764547284237411298620608183481031681522759", "price": "0.81", "size": "0", "side": "BUY", "hash": "a60dd2fd917162c001f05a5dfdc6077409e1ebe6", "best_bid": "0.9", "best_ask": "0.93"}, {"asset_id": "26862256473738234042890995175212184751139521605012603994991408238083491315385", "price": "0.19", "size": "0", "side": "SELL", "hash": "6a716f62607d80c9e438024d8d97947cb88c851d", "best_bid": "0.07", "best_ask": "0.1"}], "timestamp": "1769384028001", "event_type": "price_change"}}
{"_local_timestamp": "2026-01-25T23:33:50.031583+00:00", "data": {"market": "0xe6703820029400bb3989c9ca94511ae96bcb6bb212e76bfce28fbc3d0712e7da", "price_changes": [{"asset_id": "65912005210412562484178321309940712764547284237411298620608183481031681522759", "price": "0.87", "size": "20", "side": "BUY", "hash": "012603e12f22fbbcd0784cc6b0077cbe060ce39d", "best_bid": "0.9", "best_ask": "0.93"}, {"asset_id": "26862256473738234042890995175212184751139521605012603994991408238083491315385", "price": "0.13", "size": "20", "side": "SELL", "hash": "c804b4b24d51c081df6b001259cf34523667d56a", "best_bid": "0.07", "best_ask": "0.1"}], "timestamp": "1769384029962", "event_type": "price_change"}}
{"_local_timestamp": "2026-01-25T23:33:52.464219+00:00", "data": {"market": "0xbc63ab257269b6d88696a7c395c22a032dd8bcaec0f20b22083ac17dd8a9221c", "price_changes": [{"asset_id": "7542437468156958963085282310210526488532310459870037284043838227272438514792", "price": "0.69", "size": "0", "side": "BUY", "hash": "a6f1754f0ad8947c73d03b24e0ab7410c212ae1d", "best_bid": "0.71", "best_ask": "0.76"}, {"asset_id": "70095723080029803518081326396248438374756818653107709477379930258944056936114", "price": "0.31", "size": "0", "side": "SELL", "hash": "4778aa1005ad0a3a45128b9d629ba56c23250ea3", "best_bid": "0.24", "best_ask": "0.29"}], "timestamp": "1769384032347", "event_type": "price_change"}}
{"_local_timestamp": "2026-01-25T23:33:54.606498+00:00", "data": {"market": "0xe6703820029400bb3989c9ca94511ae96bcb6bb212e76bfce28fbc3d0712e7da", "price_changes": [{"asset_id": "65912005210412562484178321309940712764547284237411298620608183481031681522759", "price": "0.82", "size": "0", "side": "BUY", "hash": "8444893d0caddd70afd5cd9df350d55cc9a2d144", "best_bid": "0.9", "best_ask": "0.93"}, {"asset_id": "26862256473738234042890995175212184751139521605012603994991408238083491315385", "price": "0.18", "size": "0", "side": "SELL", "hash": "b94c059dee4e79b81a4cee3835757f464a8f809a", "best_bid": "0.07", "best_ask": "0.1"}], "timestamp": "1769384034539", "event_type": "price_change"}}
{"_local_timestamp": "2026-01-25T23:33:54.633902+00:00", "data": {"market": "0xe6703820029400bb3989c9ca94511ae96bcb6bb212e76bfce28fbc3d0712e7da", "price_changes": [{"asset_id": "65912005210412562484178321309940712764547284237411298620608183481031681522759", "price": "0.62", "size": "20", "side": "BUY", "hash": "50eed7182cda7918d4d19aa037dcc0c8172d57f7", "best_bid": "0.9", "best_ask": "0.93"}, {"asset_id": "26862256473738234042890995175212184751139521605012603994991408238083491315385", "price": "0.38", "size": "20", "side": "SELL", "hash": "3e1337e6fe3799e71b8b08c2fb61e348eecbfb69", "best_bid": "0.07", "best_ask": "0.1"}], "timestamp": "1769384034564", "event_type": "price_change"}}
{"_local_timestamp": "2026-01-25T23:34:01.371939+00:00", "data": {"market": "0xa5e46823b12f8751471c740cb5611827629c198f80aca1624867773bfc58d8a6", "price_changes": [{"asset_id": "3056942142656390250297633237719893992746229918619747110824738083465804504940", "price": "0.02", "size": "1800", "side": "BUY", "hash": "7efd35836c53bfe588cfd1ad346c8e424fa38c8a", "best_bid": "0.85", "best_ask": "0.94"}, {"asset_id": "95101171893122594180666530745464033001482832309010202534315814756594685314956", "price": "0.98", "size": "1800", "side": "SELL", "hash": "f2191a234f207b3ccd980847d69c6ae447c36c43", "best_bid": "0.06", "best_ask": "0.15"}], "timestamp": "1769384041235", "event_type": "price_change"}}
{"_local_timestamp": "2026-01-25T23:34:01.615127+00:00", "data": {"market": "0xa5e46823b12f8751471c740cb5611827629c198f80aca1624867773bfc58d8a6", "price_changes": [{"asset_id": "3056942142656390250297633237719893992746229918619747110824738083465804504940", "price": "0.05", "size": "430", "side": "BUY", "hash": "2da0fd790e3c5096d802302e2954b4396558b905", "best_bid": "0.85", "best_ask": "0.94"}, {"asset_id": "95101171893122594180666530745464033001482832309010202534315814756594685314956", "price": "0.95", "size": "430", "side": "SELL", "hash": "f7ef43f7e951bb6600553b4b67957d3ab6ac8603", "best_bid": "0.06", "best_ask": "0.15"}], "timestamp": "1769384041545", "event_type": "price_change"}}
{"_local_timestamp": "2026-01-25T23:34:02.811059+00:00", "data": {"market": "0xbc63ab257269b6d88696a7c395c22a032dd8bcaec0f20b22083ac17dd8a9221c", "price_changes": [{"asset_id": "70095723080029803518081326396248438374756818653107709477379930258944056936114", "price": "0.01", "size": "7.26", "side": "BUY", "hash": "48a651604a16c91d6dbaa58ae6074dd19ce163ff", "best_bid": "0.24", "best_ask": "0.29"}, {"asset_id": "7542437468156958963085282310210526488532310459870037284043838227272438514792", "price": "0.99", "size": "7.26", "side": "SELL", "hash": "5237c0311c49d28dcf76d6e052c982112f47eaaf", "best_bid": "0.71", "best_ask": "0.76"}], "timestamp": "1769384042744", "event_type": "price_change"}}
{"_local_timestamp": "2026-01-25T23:34:03.284866+00:00", "data": {"market": "0xbc63ab257269b6d88696a7c395c22a032dd8bcaec0f20b22083ac17dd8a9221c", "price_changes": [{"asset_id": "70095723080029803518081326396248438374756818653107709477379930258944056936114", "price": "0.01", "size": "15.66", "side": "BUY", "hash": "906f5358b4e5c4bca9b00a9f7d510a6cd0aacd04", "best_bid": "0.24", "best_ask": "0.29"}, {"asset_id": "7542437468156958963085282310210526488532310459870037284043838227272438514792", "price": "0.99", "size": "15.66", "side": "SELL", "hash": "f3cc761599590bf9c1810617777c61a14d7bf93a", "best_bid": "0.71", "best_ask": "0.76"}], "timestamp": "1769384043116", "event_type": "price_change"}}
{"_local_timestamp": "2026-01-25T23:34:12.954332+00:00", "data": {"market": "0xe6703820029400bb3989c9ca94511ae96bcb6bb212e76bfce28fbc3d0712e7da", "price_changes": [{"asset_id": "26862256473738234042890995175212184751139521605012603994991408238083491315385", "price": "0.06", "size": "19.06", "side": "BUY", "hash": "c87998b1d7ce4f0933b67d9f5c443af9b878e3e7", "best_bid": "0.07", "best_ask": "0.1"}, {"asset_id": "65912005210412562484178321309940712764547284237411298620608183481031681522759", "price": "0.94", "size": "19.06", "side": "SELL", "hash": "915db23fd7778808af6d0a152e7b47667312bc9b", "best_bid": "0.9", "best_ask": "0.93"}], "timestamp": "1769384052808", "event_type": "price_change"}}
{"_local_timestamp": "2026-01-25T23:34:12.955253+00:00", "data": {"market": "0xbc63ab257269b6d88696a7c395c22a032dd8bcaec0f20b22083ac17dd8a9221c", "price_changes": [{"asset_id": "70095723080029803518081326396248438374756818653107709477379930258944056936114", "price": "0.02", "size": "100", "side": "BUY", "hash": "cdeda20941ad710b2f3c1256562f473c7df481dd", "best_bid": "0.24", "best_ask": "0.29"}, {"asset_id": "7542437468156958963085282310210526488532310459870037284043838227272438514792", "price": "0.98", "size": "100", "side": "SELL", "hash": "ae16f5a1f89f0c410ceb033427d0166ffa3bc398", "best_bid": "0.71", "best_ask": "0.76"}], "timestamp": "1769384052808", "event_type": "price_change"}}
{"_local_timestamp": "2026-01-25T23:34:12.957738+00:00", "data": {"market": "0x4a0ead3d8c0aa0a73f322aaa95615e7d29b414b9fc4bace855bb74a7a648d990", "price_changes": [{"asset_id": "4936830242343432951855740478936036194473488983939131588159659366497804600794", "price": "0.07", "size": "25.09", "side": "BUY", "hash": "4fb1f20bf5a485b3b0837eb5cd8866cfdd3bf8c1", "best_bid": "0.08", "best_ask": "0.14"}, {"asset_id": "111376742935340636514883997859794030073097390424337351101383349939644307757449", "price": "0.93", "size": "25.09", "side": "SELL", "hash": "e30bc098047d81075b3c670507e8ef83f3669aab", "best_bid": "0.86", "best_ask": "0.92"}], "timestamp": "1769384052808", "event_type": "price_change"}}
{"_local_timestamp": "2026-01-25T23:34:12.968584+00:00", "data": {"market": "0xd525650240c1956c1fd741e727302756002d34541cebb15399c6648372c2b017", "price_changes": [{"asset_id": "58237052681575643690608170707582085559437408445710143443295775339044140331495", "price": "0.006", "size": "100", "side": "BUY", "hash": "d27a5d850a7147a390da1c0c275581bec74fde50", "best_bid": "0.009", "best_ask": "0.014"}, {"asset_id": "84363734712816699027954735716573977595829918143333969139288207428067341798047", "price": "0.994", "size": "100", "side": "SELL", "hash": "9e2907ec634db3f546fe6e9eb51c201f5a630e17", "best_bid": "0.986", "best_ask": "0.991"}], "timestamp": "1769384052808", "event_type": "price_change"}}
{"_local_timestamp": "2026-01-25T23:34:13.152520+00:00", "data": {"market": "0xbc63ab257269b6d88696a7c395c22a032dd8bcaec0f20b22083ac17dd8a9221c", "price_changes": [{"asset_id": "70095723080029803518081326396248438374756818653107709477379930258944056936114", "price": "0.16", "size": "0", "side": "BUY", "hash": "487183eb9715c0a01117366759601b9f4b6e440c", "best_bid": "0.24", "best_ask": "0.29"}, {"asset_id": "7542437468156958963085282310210526488532310459870037284043838227272438514792", "price": "0.84", "size": "0", "side": "SELL", "hash": "e1fdd0e1878a8cf0fd019ff7def2ca4f7decf17e", "best_bid": "0.71", "best_ask": "0.76"}], "timestamp": "1769384053029", "event_type": "price_change"}}
{"_local_timestamp": "2026-01-25T23:34:13.318867+00:00", "data": {"market": "0xbc63ab257269b6d88696a7c395c22a032dd8bcaec0f20b22083ac17dd8a9221c", "price_changes": [{"asset_id": "70095723080029803518081326396248438374756818653107709477379930258944056936114", "price": "0.02", "size": "600", "side": "BUY", "hash": "b35f4f1edbab2964edaf6f11f85d14ce31be9285", "best_bid": "0.24", "best_ask": "0.29"}, {"asset_id": "7542437468156958963085282310210526488532310459870037284043838227272438514792", "price": "0.98", "size": "600", "side": "SELL", "hash": "1e2997b99614af2bdd00159028dc972d052e15cb", "best_bid": "0.71", "best_ask": "0.76"}], "timestamp": "1769384053246", "event_type": "price_change"}}
{"_local_timestamp": "2026-01-25T23:34:13.359055+00:00", "data": {"market": "0xbc63ab257269b6d88696a7c395c22a032dd8bcaec0f20b22083ac17dd8a9221c", "price_changes": [{"asset_id": "70095723080029803518081326396248438374756818653107709477379930258944056936114", "price": "0.1", "size": "10", "side": "BUY", "hash": "a86a2ed48462819d13f8b6e635a58303fa071d4d", "best_bid": "0.24", "best_ask": "0.29"}, {"asset_id": "7542437468156958963085282310210526488532310459870037284043838227272438514792", "price": "0.9", "size": "10", "side": "SELL", "hash": "955df2691bcc8ea74954e7cbfc11ba85b3f9fce0", "best_bid": "0.71", "best_ask": "0.76"}], "timestamp": "1769384053247", "event_type": "price_change"}}
{"_local_timestamp": "2026-01-25T23:34:13.445802+00:00", "data": {"market": "0x4a0ead3d8c0aa0a73f322aaa95615e7d29b414b9fc4bace855bb74a7a648d990", "price_changes": [{"asset_id": "4936830242343432951855740478936036194473488983939131588159659366497804600794", "price": "0.04", "size": "350", "side": "BUY", "hash": "97500428f96d712769d9a89871c86b5cc29710e4", "best_bid": "0.08", "best_ask": "0.14"}, {"asset_id": "111376742935340636514883997859794030073097390424337351101383349939644307757449", "price": "0.96", "size": "350", "side": "SELL", "hash": "9ddc4065fe0665b8876b347ad71a8c3e28a3ddee", "best_bid": "0.86", "best_ask": "0.92"}], "timestamp": "1769384053293", "event_type": "price_change"}}
{"_local_timestamp": "2026-01-25T23:34:13.503695+00:00", "data": {"market": "0xe6703820029400bb3989c9ca94511ae96bcb6bb212e76bfce28fbc3d0712e7da", "price_changes": [{"asset_id": "26862256473738234042890995175212184751139521605012603994991408238083491315385", "price": "0.04", "size": "319.06", "side": "BUY", "hash": "b5fea8e3e0e1e63cfebf9d29c7913b09defb1e1f", "best_bid": "0.07", "best_ask": "0.1"}, {"asset_id": "65912005210412562484178321309940712764547284237411298620608183481031681522759", "price": "0.96", "size": "319.06", "side": "SELL", "hash": "53b59aea3be23ec47ba859440d972357fcc35a1b", "best_bid": "0.9", "best_ask": "0.93"}], "timestamp": "1769384053293", "event_type": "price_change"}}
{"_local_timestamp": "2026-01-25T23:34:13.504492+00:00", "data": {"market": "0xd525650240c1956c1fd741e727302756002d34541cebb15399c6648372c2b017", "price_changes": [{"asset_id": "58237052681575643690608170707582085559437408445710143443295775339044140331495", "price": "0.008", "size": "231.2", "side": "BUY", "hash": "c22952a1ead0bfd55d7e31e85f7e0a4a39e3272e", "best_bid": "0.009", "best_ask": "0.014"}, {"asset_id": "84363734712816699027954735716573977595829918143333969139288207428067341798047", "price": "0.992", "size": "231.2", "side": "SELL", "hash": "375e345179fc0d465aac0c84e47bd0a2f6434d51", "best_bid": "0.986", "best_ask": "0.991"}], "timestamp": "1769384053293", "event_type": "price_change"}}
{"_local_timestamp": "2026-01-25T23:34:15.474380+00:00", "data": {"market": "0xbc63ab257269b6d88696a7c395c22a032dd8bcaec0f20b22083ac17dd8a9221c", "price_changes": [{"asset_id": "70095723080029803518081326396248438374756818653107709477379930258944056936114", "price": "0.17", "size": "0", "side": "BUY", "hash": "dd860464b0a1db2df91ae1baa4781fb65c0ec837", "best_bid": "0.24", "best_ask": "0.29"}, {"asset_id": "7542437468156958963085282310210526488532310459870037284043838227272438514792", "price": "0.83", "size": "0", "side": "SELL", "hash": "db761a46f0284bcadf88153d1ef66cd108b1af2e", "best_bid": "0.71", "best_ask": "0.76"}], "timestamp": "1769384055406", "event_type": "price_change"}}
{"_local_timestamp": "2026-01-25T23:34:15.508244+00:00", "data": {"market": "0xbc63ab257269b6d88696a7c395c22a032dd8bcaec0f20b22083ac17dd8a9221c", "price_changes": [{"asset_id": "70095723080029803518081326396248438374756818653107709477379930258944056936114", "price": "0.15", "size": "20", "side": "BUY", "hash": "13aefe16fec32eb80e78a802bb5a7f53e78c928d", "best_bid": "0.24", "best_ask": "0.29"}, {"asset_id": "7542437468156958963085282310210526488532310459870037284043838227272438514792", "price": "0.85", "size": "20", "side": "SELL", "hash": "ff006514c2b5f543c0115e111d747096c7a644fd", "best_bid": "0.71", "best_ask": "0.76"}], "timestamp": "1769384055436", "event_type": "price_change"}}
{"_local_timestamp": "2026-01-25T23:34:28.373674+00:00", "data": {"market": "0x262962b5d5b1f248aac0c99a871402f136a7a01de85aa5503c3bfa92f46b2c55", "price_changes": [{"asset_id": "19123455644246071046896212752788121367175617509312871406465324158710992613511", "price": "0.2", "size": "610", "side": "BUY", "hash": "086c7226a4465efc5a3997a20c8f64b55d9bd189", "best_bid": "0.91", "best_ask": "0.989"}, {"asset_id": "106003536497972067032507723744954701264783762198809994038236889884495294178883", "price": "0.8", "size": "610", "side": "SELL", "hash": "545c073ae7a038da235dbf7bf1cc2dc3d5f7edac", "best_bid": "0.011", "best_ask": "0.09"}], "timestamp": "1769384068110", "event_type": "price_change"}}
{"_local_timestamp": "2026-01-25T23:34:28.389085+00:00", "data": {"market": "0x262962b5d5b1f248aac0c99a871402f136a7a01de85aa5503c3bfa92f46b2c55", "price_changes": [{"asset_id": "19123455644246071046896212752788121367175617509312871406465324158710992613511", "price": "0.3", "size": "436.66", "side": "BUY", "hash": "09518d19c95f87fe66b263201adc5c2cd1434147", "best_bid": "0.91", "best_ask": "0.989"}, {"asset_id": "106003536497972067032507723744954701264783762198809994038236889884495294178883", "price": "0.7", "size": "436.66", "side": "SELL", "hash": "af7909facbb3e51d33ad23fe723e9c0437cde254", "best_bid": "0.011", "best_ask": "0.09"}], "timestamp": "1769384068198", "event_type": "price_change"}}
{"_local_timestamp": "2026-01-25T23:34:28.925646+00:00", "data": {"market": "0x00ece3aec2e7ec1266c81f9b6dee4d5774c5e9fc1d8b4c05750363bb6693608c", "price_changes": [{"asset_id": "56288496839116076608936080824519320480921427720682183882154533325856755856281", "price": "0.636", "size": "0", "side": "BUY", "hash": "8e4c8e7eaeea7e847636e24dfa6b1c0082b7065e", "best_bid": "0.988", "best_ask": "0.995"}, {"asset_id": "20277485868363893965343112627224984692523382854354842924096328553726850004689", "price": "0.364", "size": "0", "side": "SELL", "hash": "48c5f7b4c6bcb176dfe91fdfafca035f1cd715f6", "best_bid": "0.005", "best_ask": "0.012"}], "timestamp": "1769384068514", "event_type": "price_change"}}
{"_local_timestamp": "2026-01-25T23:34:29.194353+00:00", "data": {"market": "0x00ece3aec2e7ec1266c81f9b6dee4d5774c5e9fc1d8b4c05750363bb6693608c", "price_changes": [{"asset_id": "56288496839116076608936080824519320480921427720682183882154533325856755856281", "price": "0.638", "size": "60", "side": "BUY", "hash": "4b279c21082b58458d1a95803ccbf939f8b23c91", "best_bid": "0.988", "best_ask": "0.995"}, {"asset_id": "20277485868363893965343112627224984692523382854354842924096328553726850004689", "price": "0.362", "size": "60", "side": "SELL", "hash": "d8421822bcdc2f60a8eabbd8e604c9423b05033f", "best_bid": "0.005", "best_ask": "0.012"}], "timestamp": "1769384069011", "event_type": "price_change"}}
{"_local_timestamp": "2026-01-25T23:34:29.195507+00:00", "data": {"market": "0x00ece3aec2e7ec1266c81f9b6dee4d5774c5e9fc1d8b4c05750363bb6693608c", "price_changes": [{"asset_id": "56288496839116076608936080824519320480921427720682183882154533325856755856281", "price": "0.638", "size": "70", "side": "BUY", "hash": "c0f59f46e2e82537dc62b5e6646f7ebd1219ef50", "best_bid": "0.988", "best_ask": "0.995"}, {"asset_id": "20277485868363893965343112627224984692523382854354842924096328553726850004689", "price": "0.362", "size": "70", "side": "SELL", "hash": "eb1d6e9ed152d5d2d6dc02551ce07cb23da97ab6", "best_bid": "0.005", "best_ask": "0.012"}], "timestamp": "1769384069012", "event_type": "price_change"}}
{"_local_timestamp": "2026-01-25T23:34:29.947225+00:00", "data": {"market": "0x00ece3aec2e7ec1266c81f9b6dee4d5774c5e9fc1d8b4c05750363bb6693608c", "price_changes": [{"asset_id": "20277485868363893965343112627224984692523382854354842924096328553726850004689", "price": "0.379", "size": "0", "side": "SELL", "hash": "0778655c6546b90c48247f188e9cf2676ea205c1", "best_bid": "0.005", "best_ask": "0.012"}, {"asset_id": "56288496839116076608936080824519320480921427720682183882154533325856755856281", "price": "0.621", "size": "0", "side": "BUY", "hash": "06cb6a819cf94fa8c38b8365a0fedd723cf3a22a", "best_bid": "0.988", "best_ask": "0.995"}], "timestamp": "1769384069759", "event_type": "price_change"}}
{"_local_timestamp": "2026-01-25T23:34:30.055254+00:00", "data": {"market": "0x00ece3aec2e7ec1266c81f9b6dee4d5774c5e9fc1d8b4c05750363bb6693608c", "price_changes": [{"asset_id": "20277485868363893965343112627224984692523382854354842924096328553726850004689", "price": "0.361", "size": "29.16", "side": "SELL", "hash": "125df1f15b1256bd986a71def0de1a859148d908", "best_bid": "0.005", "best_ask": "0.012"}, {"asset_id": "56288496839116076608936080824519320480921427720682183882154533325856755856281", "price": "0.639", "size": "29.16", "side": "BUY", "hash": "2aecbe7b6b50aa683b1cbdfe2701a56b3ad1f178", "best_bid": "0.988", "best_ask": "0.995"}], "timestamp": "1769384069874", "event_type": "price_change"}}
{"_local_timestamp": "2026-01-25T23:34:30.215842+00:00", "data": {"market": "0x00ece3aec2e7ec1266c81f9b6dee4d5774c5e9fc1d8b4c05750363bb6693608c", "price_changes": [{"asset_id": "56288496839116076608936080824519320480921427720682183882154533325856755856281", "price": "0.638", "size": "10", "side": "BUY", "hash": "c6c163d2656192c51fc7d160becf147d1d9cc8e4", "best_bid": "0.988", "best_ask": "0.995"}, {"asset_id": "20277485868363893965343112627224984692523382854354842924096328553726850004689", "price": "0.362", "size": "10", "side": "SELL", "hash": "8180c7fbe6dd27f2c99b3060bfb139ea11f09024", "best_bid": "0.005", "best_ask": "0.012"}], "timestamp": "1769384070043", "event_type": "price_change"}}
{"_local_timestamp": "2026-01-25T23:34:31.007794+00:00", "data": {"market": "0x00ece3aec2e7ec1266c81f9b6dee4d5774c5e9fc1d8b4c05750363bb6693608c", "price_changes": [{"asset_id": "20277485868363893965343112627224984692523382854354842924096328553726850004689", "price": "0.361", "size": "0", "side": "SELL", "hash": "d25b7bae39844c022ff1ed3f2bce40c43fbc1c50", "best_bid": "0.005", "best_ask": "0.012"}, {"asset_id": "56288496839116076608936080824519320480921427720682183882154533325856755856281", "price": "0.639", "size": "0", "side": "BUY", "hash": "4de2d7624beb78243cf0a637376f98bb34ee5de7", "best_bid": "0.988", "best_ask": "0.995"}], "timestamp": "1769384070928", "event_type": "price_change"}}
{"_local_timestamp": "2026-01-25T23:34:31.095998+00:00", "data": {"market": "0x00ece3aec2e7ec1266c81f9b6dee4d5774c5e9fc1d8b4c05750363bb6693608c", "price_changes": [{"asset_id": "20277485868363893965343112627224984692523382854354842924096328553726850004689", "price": "0.379", "size": "29.16", "side": "SELL", "hash": "d5f64243aa928bb8b4beec9d65ea21ce595aab14", "best_bid": "0.005", "best_ask": "0.012"}, {"asset_id": "56288496839116076608936080824519320480921427720682183882154533325856755856281", "price": "0.621", "size": "29.16", "side": "BUY", "hash": "2658143032dc1a69aedd816719c60fe69b610315", "best_bid": "0.988", "best_ask": "0.995"}], "timestamp": "1769384071004", "event_type": "price_change"}}
{"_local_timestamp": "2026-01-25T23:34:32.805512+00:00", "data": {"market": "0x00ece3aec2e7ec1266c81f9b6dee4d5774c5e9fc1d8b4c05750363bb6693608c", "price_changes": [{"asset_id": "56288496839116076608936080824519320480921427720682183882154533325856755856281", "price": "0.637", "size": "0", "side": "BUY", "hash": "06d0b7c861fb7a65f7004b4c7ccc8928fabc63d6", "best_bid": "0.988", "best_ask": "0.995"}, {"asset_id": "20277485868363893965343112627224984692523382854354842924096328553726850004689", "price": "0.363", "size": "0", "side": "SELL", "hash": "c698994defc66ed0d472b4ce46d2ab47bd4f0bfe", "best_bid": "0.005", "best_ask": "0.012"}], "timestamp": "1769384072735", "event_type": "price_change"}}
{"_local_timestamp": "2026-01-25T23:34:32.837938+00:00", "data": {"market": "0x00ece3aec2e7ec1266c81f9b6dee4d5774c5e9fc1d8b4c05750363bb6693608c", "price_changes": [{"asset_id": "56288496839116076608936080824519320480921427720682183882154533325856755856281", "price": "0.639", "size": "20", "side": "BUY", "hash": "ec7cb263166d9eff08d7e78cd539b4802ebbe026", "best_bid": "0.988", "best_ask": "0.995"}, {"asset_id": "20277485868363893965343112627224984692523382854354842924096328553726850004689", "price": "0.361", "size": "20", "side": "SELL", "hash": "5d96185704436f1254039909a12c9812b8e16391", "best_bid": "0.005", "best_ask": "0.012"}], "timestamp": "1769384072767", "event_type": "price_change"}}
{"_local_timestamp": "2026-01-25T23:34:37.972557+00:00", "data": {"market": "0x262962b5d5b1f248aac0c99a871402f136a7a01de85aa5503c3bfa92f46b2c55", "price_changes": [{"asset_id": "19123455644246071046896212752788121367175617509312871406465324158710992613511", "price": "0.812", "size": "0", "side": "BUY", "hash": "526dfd56481adcd0308c7630470713221d036796", "best_bid": "0.91", "best_ask": "0.989"}, {"asset_id": "106003536497972067032507723744954701264783762198809994038236889884495294178883", "price": "0.188", "size": "0", "side": "SELL", "hash": "b6baef36a1ff7afd0e2262e35876c7c9bac2d0f3", "best_bid": "0.011", "best_ask": "0.09"}], "timestamp": "1769384077869", "event_type": "price_change"}}
{"_local_timestamp": "2026-01-25T23:34:38.010744+00:00", "data": {"market": "0x262962b5d5b1f248aac0c99a871402f136a7a01de85aa5503c3bfa92f46b2c55", "price_changes": [{"asset_id": "19123455644246071046896212752788121367175617509312871406465324158710992613511", "price": "0.813", "size": "0", "side": "BUY", "hash": "45ac85eaad1ae77e3deabc11bd7851ec3eeb1aa5", "best_bid": "0.91", "best_ask": "0.989"}, {"asset_id": "106003536497972067032507723744954701264783762198809994038236889884495294178883", "price": "0.187", "size": "0", "side": "SELL", "hash": "35bfde9e647731fa4d75a0d672fac4d1ecdc8d74", "best_bid": "0.011", "best_ask": "0.09"}], "timestamp": "1769384077941", "event_type": "price_change"}}
{"_local_timestamp": "2026-01-25T23:34:38.033428+00:00", "data": {"market": "0x262962b5d5b1f248aac0c99a871402f136a7a01de85aa5503c3bfa92f46b2c55", "price_changes": [{"asset_id": "19123455644246071046896212752788121367175617509312871406465324158710992613511", "price": "0.811", "size": "20", "side": "BUY", "hash": "2b0dcfad4f435aa70bfb6104046d7270dbdb4b64", "best_bid": "0.91", "best_ask": "0.989"}, {"asset_id": "106003536497972067032507723744954701264783762198809994038236889884495294178883", "price": "0.189", "size": "20", "side": "SELL", "hash": "96cf5611035c2da16eddb8d09f525e64bb0938cd", "best_bid": "0.011", "best_ask": "0.09"}], "timestamp": "1769384077966", "event_type": "price_change"}}
{"_local_timestamp": "2026-01-25T23:34:40.570856+00:00", "data": {"market": "0xa5e46823b12f8751471c740cb5611827629c198f80aca1624867773bfc58d8a6", "price_changes": [{"asset_id": "3056942142656390250297633237719893992746229918619747110824738083465804504940", "price": "0.02", "size": "1000", "side": "BUY", "hash": "23484b2165953ccfd1233af73abc825b2e25d688", "best_bid": "0.85", "best_ask": "0.94"}, {"asset_id": "95101171893122594180666530745464033001482832309010202534315814756594685314956", "price": "0.98", "size": "1000", "side": "SELL", "hash": "7f0fd457295c43e4150eebedf325318b02ebec9a", "best_bid": "0.06", "best_ask": "0.15"}], "timestamp": "1769384080357", "event_type": "price_change"}}
{"_local_timestamp": "2026-01-25T23:34:40.762686+00:00", "data": {"market": "0xa5e46823b12f8751471c740cb5611827629c198f80aca1624867773bfc58d8a6", "price_changes": [{"asset_id": "3056942142656390250297633237719893992746229918619747110824738083465804504940", "price": "0.05", "size": "930", "side": "BUY", "hash": "a09b2fb443973cfdbe6461ef4f57d75d1be21bce", "best_bid": "0.85", "best_ask": "0.94"}, {"asset_id": "95101171893122594180666530745464033001482832309010202534315814756594685314956", "price": "0.95", "size": "930", "side": "SELL", "hash": "37618e64d6c01ff39fe7996a8130aff4e8e27a62", "best_bid": "0.06", "best_ask": "0.15"}], "timestamp": "1769384080657", "event_type": "price_change"}}
{"_local_timestamp": "2026-01-25T23:34:54.648095+00:00", "data": {"market": "0x4a0ead3d8c0aa0a73f322aaa95615e7d29b414b9fc4bace855bb74a7a648d990", "price_changes": [{"asset_id": "4936830242343432951855740478936036194473488983939131588159659366497804600794", "price": "0.03", "size": "200", "side": "BUY", "hash": "0fabf587ff3d3cf1bbf096f2cfd7fa5879881210", "best_bid": "0.08", "best_ask": "0.14"}, {"asset_id": "111376742935340636514883997859794030073097390424337351101383349939644307757449", "price": "0.97", "size": "200", "side": "SELL", "hash": "e509390992f071a060d27d73771ce958c4d7dc76", "best_bid": "0.86", "best_ask": "0.92"}], "timestamp": "1769384094554", "event_type": "price_change"}}
{"_local_timestamp": "2026-01-25T23:34:54.649853+00:00", "data": {"market": "0xd525650240c1956c1fd741e727302756002d34541cebb15399c6648372c2b017", "price_changes": [{"asset_id": "58237052681575643690608170707582085559437408445710143443295775339044140331495", "price": "0.007", "size": "231.2", "side": "BUY", "hash": "0200506bdf29a5d32ac5e2602e057cd1d93ece00", "best_bid": "0.009", "best_ask": "0.014"}, {"asset_id": "84363734712816699027954735716573977595829918143333969139288207428067341798047", "price": "0.993", "size": "231.2", "side": "SELL", "hash": "c244b7be3da48031cc331ca9d15ce2df2fb8b81f", "best_bid": "0.986", "best_ask": "0.991"}], "timestamp": "1769384094554", "event_type": "price_change"}}
{"_local_timestamp": "2026-01-25T23:34:54.966407+00:00", "data": {"market": "0xd525650240c1956c1fd741e727302756002d34541cebb15399c6648372c2b017", "price_changes": [{"asset_id": "58237052681575643690608170707582085559437408445710143443295775339044140331495", "price": "0.004", "size": "380", "side": "BUY", "hash": "5939919ba2da6e8cf2676499e832ea3fc25aad0a", "best_bid": "0.009", "best_ask": "0.014"}, {"asset_id": "84363734712816699027954735716573977595829918143333969139288207428067341798047", "price": "0.996", "size": "380", "side": "SELL", "hash": "97bbcfd89d9e283727c691682a879fcfdda1a72f", "best_bid": "0.986", "best_ask": "0.991"}], "timestamp": "1769384094877", "event_type": "price_change"}}
{"_local_timestamp": "2026-01-25T23:34:54.966963+00:00", "data": {"market": "0x4a0ead3d8c0aa0a73f322aaa95615e7d29b414b9fc4bace855bb74a7a648d990", "price_changes": [{"asset_id": "4936830242343432951855740478936036194473488983939131588159659366497804600794", "price": "0.02", "size": "300", "side": "BUY", "hash": "d803cbfdec29c17f68cf5fbd8a2067b5b5e62319", "best_bid": "0.08", "best_ask": "0.14"}, {"asset_id": "111376742935340636514883997859794030073097390424337351101383349939644307757449", "price": "0.98", "size": "300", "side": "SELL", "hash": "9761e573ecd423e91f1f72a4683f89d1a8d100ed", "best_bid": "0.86", "best_ask": "0.92"}], "timestamp": "1769384094879", "event_type": "price_change"}}
{"_local_timestamp": "2026-01-25T23:35:00.600472+00:00", "data": {"market": "0xbc63ab257269b6d88696a7c395c22a032dd8bcaec0f20b22083ac17dd8a9221c", "price_changes": [{"asset_id": "7542437468156958963085282310210526488532310459870037284043838227272438514792", "price": "0.7", "size": "0", "side": "BUY", "hash": "2d300aef438b8b1d80cc87bfc1b38a8b11c18510", "best_bid": "0.71", "best_ask": "0.76"}, {"asset_id": "70095723080029803518081326396248438374756818653107709477379930258944056936114", "price": "0.3", "size": "0", "side": "SELL", "hash": "fbda6a2ac12cb5d441ff13d7ae2f8f23109b6915", "best_bid": "0.24", "best_ask": "0.29"}], "timestamp": "1769384100531", "event_type": "price_change"}}
{"_local_timestamp": "2026-01-25T23:35:00.601724+00:00", "data": {"market": "0x4a0ead3d8c0aa0a73f322aaa95615e7d29b414b9fc4bace855bb74a7a648d990", "price_changes": [{"asset_id": "4936830242343432951855740478936036194473488983939131588159659366497804600794", "price": "0.08", "size": "0", "side": "BUY", "hash": "199186fe4a610b5c049a016c69b9613ddebc1fc5", "best_bid": "0.07", "best_ask": "0.14"}, {"asset_id": "111376742935340636514883997859794030073097390424337351101383349939644307757449", "price": "0.92", "size": "0", "side": "SELL", "hash": "6e21fd6bb9abb658de56594c07b825c68383116e", "best_bid": "0.86", "best_ask": "0.93"}], "timestamp": "1769384100531", "event_type": "price_change"}}
{"_local_timestamp": "2026-01-25T23:35:00.602704+00:00", "data": {"market": "0xbc63ab257269b6d88696a7c395c22a032dd8bcaec0f20b22083ac17dd8a9221c", "price_changes": [{"asset_id": "7542437468156958963085282310210526488532310459870037284043838227272438514792", "price": "0.25", "size": "100", "side": "BUY", "hash": "2d300aef438b8b1d80cc87bfc1b38a8b11c18510", "best_bid": "0.71", "best_ask": "0.76"}, {"asset_id": "70095723080029803518081326396248438374756818653107709477379930258944056936114", "price": "0.75", "size": "100", "side": "SELL", "hash": "fbda6a2ac12cb5d441ff13d7ae2f8f23109b6915", "best_bid": "0.24", "best_ask": "0.29"}], "timestamp": "1769384100531", "event_type": "price_change"}}
{"_local_timestamp": "2026-01-25T23:35:00.603222+00:00", "data": {"market": "0xe6703820029400bb3989c9ca94511ae96bcb6bb212e76bfce28fbc3d0712e7da", "price_changes": [{"asset_id": "26862256473738234042890995175212184751139521605012603994991408238083491315385", "price": "0.07", "size": "0", "side": "BUY", "hash": "38872e5e2f5566a69b6280e4ab55af3daa66743b", "best_bid": "0.04", "best_ask": "0.1"}, {"asset_id": "65912005210412562484178321309940712764547284237411298620608183481031681522759", "price": "0.93", "size": "0", "side": "SELL", "hash": "cc12b3a73450014d717a3a1bdb4fe33c71df0e0a", "best_bid": "0.9", "best_ask": "0.96"}], "timestamp": "1769384100531", "event_type": "price_change"}}
{"_local_timestamp": "2026-01-25T23:35:00.603618+00:00", "data": {"market": "0xbc63ab257269b6d88696a7c395c22a032dd8bcaec0f20b22083ac17dd8a9221c", "price_changes": [{"asset_id": "7542437468156958963085282310210526488532310459870037284043838227272438514792", "price": "0.45", "size": "0", "side": "BUY", "hash": "2d300aef438b8b1d80cc87bfc1b38a8b11c18510", "best_bid": "0.71", "best_ask": "0.76"}, {"asset_id": "70095723080029803518081326396248438374756818653107709477379930258944056936114", "price": "0.55", "size": "0", "side": "SELL", "hash": "fbda6a2ac12cb5d441ff13d7ae2f8f23109b6915", "best_bid": "0.24", "best_ask": "0.29"}], "timestamp": "1769384100531", "event_type": "price_change"}}
{"_local_timestamp": "2026-01-25T23:35:00.604056+00:00", "data": {"market": "0xe6703820029400bb3989c9ca94511ae96bcb6bb212e76bfce28fbc3d0712e7da", "price_changes": [{"asset_id": "26862256473738234042890995175212184751139521605012603994991408238083491315385", "price": "0.06", "size": "0", "side": "BUY", "hash": "38872e5e2f5566a69b6280e4ab55af3daa66743b", "best_bid": "0.04", "best_ask": "0.1"}, {"asset_id": "65912005210412562484178321309940712764547284237411298620608183481031681522759", "price": "0.94", "size": "0", "side": "SELL", "hash": "cc12b3a73450014d717a3a1bdb4fe33c71df0e0a", "best_bid": "0.9", "best_ask": "0.96"}], "timestamp": "1769384100531", "event_type": "price_change"}}
{"_local_timestamp": "2026-01-25T23:35:00.610337+00:00", "data": {"market": "0xe6703820029400bb3989c9ca94511ae96bcb6bb212e76bfce28fbc3d0712e7da", "price_changes": [{"asset_id": "26862256473738234042890995175212184751139521605012603994991408238083491315385", "price": "0.04", "size": "300", "side": "BUY", "hash": "38872e5e2f5566a69b6280e4ab55af3daa66743b", "best_bid": "0.04", "best_ask": "0.1"}, {"asset_id": "65912005210412562484178321309940712764547284237411298620608183481031681522759", "price": "0.96", "size": "300", "side": "SELL", "hash": "cc12b3a73450014d717a3a1bdb4fe33c71df0e0a", "best_bid": "0.9", "best_ask": "0.96"}], "timestamp": "1769384100531", "event_type": "price_change"}}
{"_local_timestamp": "2026-01-25T23:35:00.611185+00:00", "data": {"market": "0xbc63ab257269b6d88696a7c395c22a032dd8bcaec0f20b22083ac17dd8a9221c", "price_changes": [{"asset_id": "70095723080029803518081326396248438374756818653107709477379930258944056936114", "price": "0.24", "size": "0", "side": "BUY", "hash": "d25f2360f5742a039ad2182d0f2cb692194eea73", "best_bid": "0.23", "best_ask": "0.29"}, {"asset_id": "7542437468156958963085282310210526488532310459870037284043838227272438514792", "price": "0.76", "size": "0", "side": "SELL", "hash": "71c92442ad2cf25d0f4efa317851e72077b1580d", "best_bid": "0.71", "best_ask": "0.77"}], "timestamp": "1769384100532", "event_type": "price_change"}}
{"_local_timestamp": "2026-01-25T23:35:00.611752+00:00", "data": {"market": "0xbc63ab257269b6d88696a7c395c22a032dd8bcaec0f20b22083ac17dd8a9221c", "price_changes": [{"asset_id": "70095723080029803518081326396248438374756818653107709477379930258944056936114", "price": "0.14", "size": "0", "side": "BUY", "hash": "d25f2360f5742a039ad2182d0f2cb692194eea73", "best_bid": "0.23", "best_ask": "0.29"}, {"asset_id": "7542437468156958963085282310210526488532310459870037284043838227272438514792", "price": "0.86", "size": "0", "side": "SELL", "hash": "71c92442ad2cf25d0f4efa317851e72077b1580d", "best_bid": "0.71", "best_ask": "0.77"}], "timestamp": "1769384100532", "event_type": "price_change"}}
{"_local_timestamp": "2026-01-25T23:35:00.612210+00:00", "data": {"market": "0xbc63ab257269b6d88696a7c395c22a032dd8bcaec0f20b22083ac17dd8a9221c", "price_changes": [{"asset_id": "70095723080029803518081326396248438374756818653107709477379930258944056936114", "price": "0.04", "size": "50", "side": "BUY", "hash": "d25f2360f5742a039ad2182d0f2cb692194eea73", "best_bid": "0.23", "best_ask": "0.29"}, {"asset_id": "7542437468156958963085282310210526488532310459870037284043838227272438514792", "price": "0.96", "size": "50", "side": "SELL", "hash": "71c92442ad2cf25d0f4efa317851e72077b1580d", "best_bid": "0.71", "best_ask": "0.77"}], "timestamp": "1769384100532", "event_type": "price_change"}}
{"_local_timestamp": "2026-01-25T23:35:00.623547+00:00", "data": {"market": "0xe6703820029400bb3989c9ca94511ae96bcb6bb212e76bfce28fbc3d0712e7da", "price_changes": [{"asset_id": "65912005210412562484178321309940712764547284237411298620608183481031681522759", "price": "0.87", "size": "0", "side": "BUY", "hash": "994e9d2eac301313de2ec998bdb875f2fabc1e89", "best_bid": "0.9", "best_ask": "0.96"}, {"asset_id": "26862256473738234042890995175212184751139521605012603994991408238083491315385", "price": "0.13", "size": "0", "side": "SELL", "hash": "4b7c44e860d01bd35651695411201c6e9721ee6b", "best_bid": "0.04", "best_ask": "0.1"}], "timestamp": "1769384100554", "event_type": "price_change"}}
{"_local_timestamp": "2026-01-25T23:35:00.651933+00:00", "data": {"market": "0xa5e46823b12f8751471c740cb5611827629c198f80aca1624867773bfc58d8a6", "price_changes": [{"asset_id": "3056942142656390250297633237719893992746229918619747110824738083465804504940", "price": "0.84", "size": "50", "side": "BUY", "hash": "39f498a70c1cd72bca7b957498d3e4ad670ef59a", "best_bid": "0.85", "best_ask": "0.94"}, {"asset_id": "95101171893122594180666530745464033001482832309010202534315814756594685314956", "price": "0.16", "size": "50", "side": "SELL", "hash": "49d4a2fdf30052b3c96181347acb87aecc3c5e3a", "best_bid": "0.06", "best_ask": "0.15"}], "timestamp": "1769384100578", "event_type": "price_change"}}
{"_local_timestamp": "2026-01-25T23:35:00.745811+00:00", "data": {"market": "0x4a0ead3d8c0aa0a73f322aaa95615e7d29b414b9fc4bace855bb74a7a648d990", "price_changes": [{"asset_id": "111376742935340636514883997859794030073097390424337351101383349939644307757449", "price": "0.83", "size": "20", "side": "BUY", "hash": "4d725876e44d93f7c150b25e35f56faca56ebf82", "best_bid": "0.86", "best_ask": "0.93"}, {"asset_id": "4936830242343432951855740478936036194473488983939131588159659366497804600794", "price": "0.17", "size": "20", "side": "SELL", "hash": "e04c26fee4b1ea784e38d103d15e92ed51444aeb", "best_bid": "0.07", "best_ask": "0.14"}], "timestamp": "1769384100600", "event_type": "price_change"}}
{"_local_timestamp": "2026-01-25T23:35:00.746137+00:00", "data": {"market": "0xbc63ab257269b6d88696a7c395c22a032dd8bcaec0f20b22083ac17dd8a9221c", "price_changes": [{"asset_id": "70095723080029803518081326396248438374756818653107709477379930258944056936114", "price": "0.19", "size": "20", "side": "BUY", "hash": "23021db99aab845158b38c25b2b677999ad73565", "best_bid": "0.23", "best_ask": "0.29"}, {"asset_id": "7542437468156958963085282310210526488532310459870037284043838227272438514792", "price": "0.81", "size": "20", "side": "SELL", "hash": "76072acb129b7fe6c53843fddf7d30b37749052e", "best_bid": "0.71", "best_ask": "0.77"}], "timestamp": "1769384100621", "event_type": "price_change"}}
{"_local_timestamp": "2026-01-25T23:35:00.762720+00:00", "data": {"market": "0xbc63ab257269b6d88696a7c395c22a032dd8bcaec0f20b22083ac17dd8a9221c", "price_changes": [{"asset_id": "70095723080029803518081326396248438374756818653107709477379930258944056936114", "price": "0.02", "size": "100", "side": "BUY", "hash": "bcba9719ff154cc63a9199eead028c7c71c94b52", "best_bid": "0.23", "best_ask": "0.29"}, {"asset_id": "7542437468156958963085282310210526488532310459870037284043838227272438514792", "price": "0.98", "size": "100", "side": "SELL", "hash": "0246b4ad034da28b7fcdf8ba8492b80333dc7e47", "best_bid": "0.71", "best_ask": "0.77"}], "timestamp": "1769384100680", "event_type": "price_change"}}
{"_local_timestamp": "2026-01-25T23:35:00.763081+00:00", "data": {"market": "0x059da3ba4ea3b184e31fb8978967cbd607f5187de5846b64dcd6777ab11dbfcf", "price_changes": [{"asset_id": "12442026831814665517479454307107841564924638876268430912384587148891875917807", "price": "0.645", "size": "0", "side": "BUY", "hash": "9272e2cbeb1eda7330470100c621ee098e35900c", "best_bid": "0.984", "best_ask": "0.994"}, {"asset_id": "98400648527667164765783273069456261018306904239322551307759035804553498481296", "price": "0.355", "size": "0", "side": "SELL", "hash": "618e43b819f96781942beebd1e77cc2e0f0057f8", "best_bid": "0.006", "best_ask": "0.016"}], "timestamp": "1769384100680", "event_type": "price_change"}}
{"_local_timestamp": "2026-01-25T23:35:00.763324+00:00", "data": {"market": "0xa5e46823b12f8751471c740cb5611827629c198f80aca1624867773bfc58d8a6", "price_changes": [{"asset_id": "3056942142656390250297633237719893992746229918619747110824738083465804504940", "price": "0.58", "size": "0", "side": "BUY", "hash": "0c20548d32c081a8f27769a67aa094fa00b3ae64", "best_bid": "0.85", "best_ask": "0.94"}, {"asset_id": "95101171893122594180666530745464033001482832309010202534315814756594685314956", "price": "0.42", "size": "0", "side": "SELL", "hash": "a24749a3647cf98cad995ecb81cf69e5816801fb", "best_bid": "0.06", "best_ask": "0.15"}], "timestamp": "1769384100680", "event_type": "price_change"}}
{"_local_timestamp": "2026-01-25T23:35:00.863130+00:00", "data": {"market": "0xe6703820029400bb3989c9ca94511ae96bcb6bb212e76bfce28fbc3d0712e7da", "price_changes": [{"asset_id": "65912005210412562484178321309940712764547284237411298620608183481031681522759", "price": "0.19", "size": "150", "side": "BUY", "hash": "6e0fa70415ed0988a595edf2d18b36b0e027d526", "best_bid": "0.9", "best_ask": "0.96"}, {"asset_id": "26862256473738234042890995175212184751139521605012603994991408238083491315385", "price": "0.81", "size": "150", "side": "SELL", "hash": "043f77deea578951df0b3ba3b42f4a3aaa17fcae", "best_bid": "0.04", "best_ask": "0.1"}], "timestamp": "1769384100773", "event_type": "price_change"}}
{"_local_timestamp": "2026-01-25T23:35:00.863513+00:00", "data": {"market": "0xe6703820029400bb3989c9ca94511ae96bcb6bb212e76bfce28fbc3d0712e7da", "price_changes": [{"asset_id": "65912005210412562484178321309940712764547284237411298620608183481031681522759", "price": "0.33", "size": "0", "side": "BUY", "hash": "6e0fa70415ed0988a595edf2d18b36b0e027d526", "best_bid": "0.9", "best_ask": "0.96"}, {"asset_id": "26862256473738234042890995175212184751139521605012603994991408238083491315385", "price": "0.67", "size": "0", "side": "SELL", "hash": "043f77deea578951df0b3ba3b42f4a3aaa17fcae", "best_bid": "0.04", "best_ask": "0.1"}], "timestamp": "1769384100773", "event_type": "price_change"}}
{"_local_timestamp": "2026-01-25T23:35:00.863802+00:00", "data": {"market": "0xe6703820029400bb3989c9ca94511ae96bcb6bb212e76bfce28fbc3d0712e7da", "price_changes": [{"asset_id": "65912005210412562484178321309940712764547284237411298620608183481031681522759", "price": "0.14", "size": "275", "side": "BUY", "hash": "6e0fa70415ed0988a595edf2d18b36b0e027d526", "best_bid": "0.9", "best_ask": "0.96"}, {"asset_id": "26862256473738234042890995175212184751139521605012603994991408238083491315385", "price": "0.86", "size": "275", "side": "SELL", "hash": "043f77deea578951df0b3ba3b42f4a3aaa17fcae", "best_bid": "0.04", "best_ask": "0.1"}], "timestamp": "1769384100773", "event_type": "price_change"}}
{"_local_timestamp": "2026-01-25T23:35:00.865718+00:00", "data": {"market": "0xe6703820029400bb3989c9ca94511ae96bcb6bb212e76bfce28fbc3d0712e7da", "price_changes": [{"asset_id": "65912005210412562484178321309940712764547284237411298620608183481031681522759", "price": "0.24", "size": "150", "side": "BUY", "hash": "6e0fa70415ed0988a595edf2d18b36b0e027d526", "best_bid": "0.9", "best_ask": "0.96"}, {"asset_id": "26862256473738234042890995175212184751139521605012603994991408238083491315385", "price": "0.76", "size": "150", "side": "SELL", "hash": "043f77deea578951df0b3ba3b42f4a3aaa17fcae", "best_bid": "0.04", "best_ask": "0.1"}], "timestamp": "1769384100773", "event_type": "price_change"}}
{"_local_timestamp": "2026-01-25T23:35:00.865990+00:00", "data": {"market": "0xe6703820029400bb3989c9ca94511ae96bcb6bb212e76bfce28fbc3d0712e7da", "price_changes": [{"asset_id": "65912005210412562484178321309940712764547284237411298620608183481031681522759", "price": "0.38", "size": "0", "side": "BUY", "hash": "6e0fa70415ed0988a595edf2d18b36b0e027d526", "best_bid": "0.9", "best_ask": "0.96"}, {"asset_id": "26862256473738234042890995175212184751139521605012603994991408238083491315385", "price": "0.62", "size": "0", "side": "SELL", "hash": "043f77deea578951df0b3ba3b42f4a3aaa17fcae", "best_bid": "0.04", "best_ask": "0.1"}], "timestamp": "1769384100773", "event_type": "price_change"}}
{"_local_timestamp": "2026-01-25T23:35:00.866240+00:00", "data": {"market": "0xe6703820029400bb3989c9ca94511ae96bcb6bb212e76bfce28fbc3d0712e7da", "price_changes": [{"asset_id": "65912005210412562484178321309940712764547284237411298620608183481031681522759", "price": "0.29", "size": "0", "side": "BUY", "hash": "6e0fa70415ed0988a595edf2d18b36b0e027d526", "best_bid": "0.9", "best_ask": "0.96"}, {"asset_id": "26862256473738234042890995175212184751139521605012603994991408238083491315385", "price": "0.71", "size": "0", "side": "SELL", "hash": "043f77deea578951df0b3ba3b42f4a3aaa17fcae", "best_bid": "0.04", "best_ask": "0.1"}], "timestamp": "1769384100773", "event_type": "price_change"}}
{"_local_timestamp": "2026-01-25T23:35:00.866473+00:00", "data": {"market": "0xe6703820029400bb3989c9ca94511ae96bcb6bb212e76bfce28fbc3d0712e7da", "price_changes": [{"asset_id": "65912005210412562484178321309940712764547284237411298620608183481031681522759", "price": "0.09", "size": "600", "side": "BUY", "hash": "6e0fa70415ed0988a595edf2d18b36b0e027d526", "best_bid": "0.9", "best_ask": "0.96"}, {"asset_id": "26862256473738234042890995175212184751139521605012603994991408238083491315385", "price": "0.91", "size": "600", "side": "SELL", "hash": "043f77deea578951df0b3ba3b42f4a3aaa17fcae", "best_bid": "0.04", "best_ask": "0.1"}], "timestamp": "1769384100773", "event_type": "price_change"}}
{"_local_timestamp": "2026-01-25T23:35:00.904685+00:00", "data": {"market": "0xe6703820029400bb3989c9ca94511ae96bcb6bb212e76bfce28fbc3d0712e7da", "price_changes": [{"asset_id": "65912005210412562484178321309940712764547284237411298620608183481031681522759", "price": "0.38", "size": "52.63", "side": "BUY", "hash": "c484b2c762305cdedb2b722fecfc6aea9751643e", "best_bid": "0.9", "best_ask": "0.96"}, {"asset_id": "26862256473738234042890995175212184751139521605012603994991408238083491315385", "price": "0.62", "size": "52.63", "side": "SELL", "hash": "5f96ad0c8ed198b6c914f060d8aeb5f3c3f6a31b", "best_bid": "0.04", "best_ask": "0.1"}], "timestamp": "1769384100818", "event_type": "price_change"}}
{"_local_timestamp": "2026-01-25T23:35:00.938944+00:00", "data": {"market": "0x059da3ba4ea3b184e31fb8978967cbd607f5187de5846b64dcd6777ab11dbfcf", "price_changes": [{"asset_id": "12442026831814665517479454307107841564924638876268430912384587148891875917807", "price": "0.352", "size": "10", "side": "BUY", "hash": "569393b64d9d20d6fc65b6339b4eca6fed9e0c04", "best_bid": "0.984", "best_ask": "0.994"}, {"asset_id": "98400648527667164765783273069456261018306904239322551307759035804553498481296", "price": "0.648", "size": "10", "side": "SELL", "hash": "de96cec080e51486daa283a5dc22448c151eb6be", "best_bid": "0.006", "best_ask": "0.016"}], "timestamp": "1769384100848", "event_type": "price_change"}}
{"_local_timestamp": "2026-01-25T23:35:00.939268+00:00", "data": {"market": "0xa5e46823b12f8751471c740cb5611827629c198f80aca1624867773bfc58d8a6", "price_changes": [{"asset_id": "3056942142656390250297633237719893992746229918619747110824738083465804504940", "price": "0.29", "size": "10", "side": "BUY", "hash": "b9ef7165f4c3d861e3f715b62276741a05e0cde2", "best_bid": "0.85", "best_ask": "0.94"}, {"asset_id": "95101171893122594180666530745464033001482832309010202534315814756594685314956", "price": "0.71", "size": "10", "side": "SELL", "hash": "67390869cc6da87414f0f8d903a135de7c05c348", "best_bid": "0.06", "best_ask": "0.15"}], "timestamp": "1769384100848", "event_type": "price_change"}}
{"_local_timestamp": "2026-01-25T23:35:00.956768+00:00", "data": {"market": "0xe6703820029400bb3989c9ca94511ae96bcb6bb212e76bfce28fbc3d0712e7da", "price_changes": [{"asset_id": "65912005210412562484178321309940712764547284237411298620608183481031681522759", "price": "0.34", "size": "106.58", "side": "BUY", "hash": "bfada53c81f0b2d1ea308482045a0ae4e3b8f85c", "best_bid": "0.9", "best_ask": "0.96"}, {"asset_id": "26862256473738234042890995175212184751139521605012603994991408238083491315385", "price": "0.66", "size": "106.58", "side": "SELL", "hash": "c1b7d31f1792f4371f2283715b34cdc1cb823142", "best_bid": "0.04", "best_ask": "0.1"}], "timestamp": "1769384100868", "event_type": "price_change"}}
{"_local_timestamp": "2026-01-25T23:35:00.980217+00:00", "data": {"market": "0xbc63ab257269b6d88696a7c395c22a032dd8bcaec0f20b22083ac17dd8a9221c", "price_changes": [{"asset_id": "7542437468156958963085282310210526488532310459870037284043838227272438514792", "price": "0.44", "size": "100", "side": "BUY", "hash": "59ba12f2bbef69bfcb76ed7877f23d1384e59118", "best_bid": "0.71", "best_ask": "0.77"}, {"asset_id": "70095723080029803518081326396248438374756818653107709477379930258944056936114", "price": "0.56", "size": "100", "side": "SELL", "hash": "1ae126ecd769ca5d2d6c84e4747db49cfc369acc", "best_bid": "0.23", "best_ask": "0.29"}], "timestamp": "1769384100882", "event_type": "price_change"}}
{"_local_timestamp": "2026-01-25T23:35:00.980584+00:00", "data": {"market": "0xbc63ab257269b6d88696a7c395c22a032dd8bcaec0f20b22083ac17dd8a9221c", "price_changes": [{"asset_id": "7542437468156958963085282310210526488532310459870037284043838227272438514792", "price": "0.17", "size": "500", "side": "BUY", "hash": "7304abeeb37ae01e63b582006fceeb593a3d5a33", "best_bid": "0.71", "best_ask": "0.77"}, {"asset_id": "70095723080029803518081326396248438374756818653107709477379930258944056936114", "price": "0.83", "size": "500", "side": "SELL", "hash": "aeb137485cb68c78525fe7aaac2fc6894a46c61e", "best_bid": "0.23", "best_ask": "0.29"}], "timestamp": "1769384100889", "event_type": "price_change"}}
{"_local_timestamp": "2026-01-25T23:35:01.014468+00:00", "data": {"market": "0xe6703820029400bb3989c9ca94511ae96bcb6bb212e76bfce28fbc3d0712e7da", "price_changes": [{"asset_id": "65912005210412562484178321309940712764547284237411298620608183481031681522759", "price": "0.29", "size": "89.65", "side": "BUY", "hash": "8b854328d647711c8f5b88ecd35bdf39e69a2e2e", "best_bid": "0.9", "best_ask": "0.96"}, {"asset_id": "26862256473738234042890995175212184751139521605012603994991408238083491315385", "price": "0.71", "size": "89.65", "side": "SELL", "hash": "7580ad24e79aefb4ea68810be540c09cd526f332", "best_bid": "0.04", "best_ask": "0.1"}], "timestamp": "1769384100919", "event_type": "price_change"}}
{"_local_timestamp": "2026-01-25T23:35:01.074606+00:00", "data": {"market": "0xe6703820029400bb3989c9ca94511ae96bcb6bb212e76bfce28fbc3d0712e7da", "price_changes": [{"asset_id": "65912005210412562484178321309940712764547284237411298620608183481031681522759", "price": "0.24", "size": "266.66", "side": "BUY", "hash": "2e99fbbbbd6ac81e347a30247ac354cdc15fa1bc", "best_bid": "0.9", "best_ask": "0.96"}, {"asset_id": "26862256473738234042890995175212184751139521605012603994991408238083491315385", "price": "0.76", "size": "266.66", "side": "SELL", "hash": "7c97e81cbfe4d079221ecf34d52180a5ee5ac7a9", "best_bid": "0.04", "best_ask": "0.1"}], "timestamp": "1769384100969", "event_type": "price_change"}}
{"_local_timestamp": "2026-01-25T23:35:01.090781+00:00", "data": {"market": "0xbc63ab257269b6d88696a7c395c22a032dd8bcaec0f20b22083ac17dd8a9221c", "price_changes": [{"asset_id": "70095723080029803518081326396248438374756818653107709477379930258944056936114", "price": "0.13", "size": "30.36", "side": "BUY", "hash": "9a834d03ec901125915cf976fe10bfc58df5c598", "best_bid": "0.23", "best_ask": "0.29"}, {"asset_id": "7542437468156958963085282310210526488532310459870037284043838227272438514792", "price": "0.87", "size": "30.36", "side": "SELL", "hash": "09db3b26dcbe9bf206f1d9418a3c66f54486abb4", "best_bid": "0.71", "best_ask": "0.77"}], "timestamp": "1769384100988", "event_type": "price_change"}}
{"_local_timestamp": "2026-01-25T23:35:01.141383+00:00", "data": {"market": "0x4a0ead3d8c0aa0a73f322aaa95615e7d29b414b9fc4bace855bb74a7a648d990", "price_changes": [{"asset_id": "4936830242343432951855740478936036194473488983939131588159659366497804600794", "price": "0.04", "size": "375.09", "side": "BUY", "hash": "62cbf993dbf6840479ab8880fbec557b6a01f2e1", "best_bid": "0.07", "best_ask": "0.14"}, {"asset_id": "111376742935340636514883997859794030073097390424337351101383349939644307757449", "price": "0.96", "size": "375.09", "side": "SELL", "hash": "41bf8dd3822a3d4f3a2029db5d9f32579ddeac66", "best_bid": "0.86", "best_ask": "0.93"}], "timestamp": "1769384101015", "event_type": "price_change"}}
{"_local_timestamp": "2026-01-25T23:35:01.150224+00:00", "data": {"market": "0xe6703820029400bb3989c9ca94511ae96bcb6bb212e76bfce28fbc3d0712e7da", "price_changes": [{"asset_id": "65912005210412562484178321309940712764547284237411298620608183481031681522759", "price": "0.19", "size": "318.42", "side": "BUY", "hash": "d508c67893740e826b62ea669c5f66a4920c0fad", "best_bid": "0.9", "best_ask": "0.96"}, {"asset_id": "26862256473738234042890995175212184751139521605012603994991408238083491315385", "price": "0.81", "size": "318.42", "side": "SELL", "hash": "859cb07ede044acacddd7702eef683c3381a55a7", "best_bid": "0.04", "best_ask": "0.1"}], "timestamp": "1769384101018", "event_type": "price_change"}}
{"_local_timestamp": "2026-01-25T23:35:01.166555+00:00", "data": {"market": "0xbc63ab257269b6d88696a7c395c22a032dd8bcaec0f20b22083ac17dd8a9221c", "price_changes": [{"asset_id": "70095723080029803518081326396248438374756818653107709477379930258944056936114", "price": "0.03", "size": "38.16", "side": "BUY", "hash": "9ac8da1a9a53ca2e4fc42efdaeed3790fd4091b7", "best_bid": "0.23", "best_ask": "0.29"}, {"asset_id": "7542437468156958963085282310210526488532310459870037284043838227272438514792", "price": "0.97", "size": "38.16", "side": "SELL", "hash": "a76fc48f5dc53da72566956c4692286798a72b05", "best_bid": "0.71", "best_ask": "0.77"}], "timestamp": "1769384101034", "event_type": "price_change"}}
{"_local_timestamp": "2026-01-25T23:35:01.185106+00:00", "data": {"market": "0xe6703820029400bb3989c9ca94511ae96bcb6bb212e76bfce28fbc3d0712e7da", "price_changes": [{"asset_id": "26862256473738234042890995175212184751139521605012603994991408238083491315385", "price": "0.04", "size": "357.19", "side": "BUY", "hash": "684cec0f6e97e798571f76b432154378dc9095ef", "best_bid": "0.04", "best_ask": "0.1"}, {"asset_id": "65912005210412562484178321309940712764547284237411298620608183481031681522759", "price": "0.96", "size": "357.19", "side": "SELL", "hash": "b435eeeefdc89c44ba930d93350212475868d093", "best_bid": "0.9", "best_ask": "0.96"}], "timestamp": "1769384101061", "event_type": "price_change"}}
{"_local_timestamp": "2026-01-25T23:35:01.202080+00:00", "data": {"market": "0xe6703820029400bb3989c9ca94511ae96bcb6bb212e76bfce28fbc3d0712e7da", "price_changes": [{"asset_id": "65912005210412562484178321309940712764547284237411298620608183481031681522759", "price": "0.14", "size": "517.85", "side": "BUY", "hash": "8916c8ab720475c5110c9d2b8dc8a0200e0e785c", "best_bid": "0.9", "best_ask": "0.96"}, {"asset_id": "26862256473738234042890995175212184751139521605012603994991408238083491315385", "price": "0.86", "size": "517.85", "side": "SELL", "hash": "010499be6a5af01dc71c0bedce8ee9313556b7bc", "best_bid": "0.04", "best_ask": "0.1"}], "timestamp": "1769384101070", "event_type": "price_change"}}
{"_local_timestamp": "2026-01-25T23:35:01.227312+00:00", "data": {"market": "0xe6703820029400bb3989c9ca94511ae96bcb6bb212e76bfce28fbc3d0712e7da", "price_changes": [{"asset_id": "65912005210412562484178321309940712764547284237411298620608183481031681522759", "price": "0.1", "size": "360", "side": "BUY", "hash": "2328cfe6620b0e27bcfdb2d9e04fbb364ec67d1e", "best_bid": "0.9", "best_ask": "0.96"}, {"asset_id": "26862256473738234042890995175212184751139521605012603994991408238083491315385", "price": "0.9", "size": "360", "side": "SELL", "hash": "87e3d0d7024cc6b158d55fd85f23af5955125ea1", "best_bid": "0.04", "best_ask": "0.1"}], "timestamp": "1769384101123", "event_type": "price_change"}}
{"_local_timestamp": "2026-01-25T23:35:01.317882+00:00", "data": {"market": "0xbc63ab257269b6d88696a7c395c22a032dd8bcaec0f20b22083ac17dd8a9221c", "price_changes": [{"asset_id": "7542437468156958963085282310210526488532310459870037284043838227272438514792", "price": "0.31", "size": "64.51", "side": "BUY", "hash": "5b4a6652119eb9e8126f290cd5df31f55d806b1e", "best_bid": "0.71", "best_ask": "0.77"}, {"asset_id": "70095723080029803518081326396248438374756818653107709477379930258944056936114", "price": "0.69", "size": "64.51", "side": "SELL", "hash": "8217736397053db561106b57d1f48bb1da004346", "best_bid": "0.23", "best_ask": "0.29"}], "timestamp": "1769384101210", "event_type": "price_change"}}
{"_local_timestamp": "2026-01-25T23:35:01.366910+00:00", "data": {"market": "0xbc63ab257269b6d88696a7c395c22a032dd8bcaec0f20b22083ac17dd8a9221c", "price_changes": [{"asset_id": "7542437468156958963085282310210526488532310459870037284043838227272438514792", "price": "0.27", "size": "401.88", "side": "BUY", "hash": "d05be27d84e915b4988cdcac943f191872289c28", "best_bid": "0.71", "best_ask": "0.77"}, {"asset_id": "70095723080029803518081326396248438374756818653107709477379930258944056936114", "price": "0.73", "size": "401.88", "side": "SELL", "hash": "447a740cf92c27d9d7558c590a67dc96d34c5903", "best_bid": "0.23", "best_ask": "0.29"}], "timestamp": "1769384101258", "event_type": "price_change"}}
{"_local_timestamp": "2026-01-25T23:35:01.385453+00:00", "data": {"market": "0xe6703820029400bb3989c9ca94511ae96bcb6bb212e76bfce28fbc3d0712e7da", "price_changes": [{"asset_id": "26862256473738234042890995175212184751139521605012603994991408238083491315385", "price": "0.05", "size": "30", "side": "BUY", "hash": "e3ff082262caddb1de3819784814c204962746de", "best_bid": "0.05", "best_ask": "0.1"}, {"asset_id": "65912005210412562484178321309940712764547284237411298620608183481031681522759", "price": "0.95", "size": "30", "side": "SELL", "hash": "60b43b29693b4af20a47a1d876bea52c1f5429fd", "best_bid": "0.9", "best_ask": "0.95"}], "timestamp": "1769384101275", "event_type": "price_change"}}
{"_local_timestamp": "2026-01-25T23:35:01.401968+00:00", "data": {"market": "0xa5e46823b12f8751471c740cb5611827629c198f80aca1624867773bfc58d8a6", "price_changes": [{"asset_id": "3056942142656390250297633237719893992746229918619747110824738083465804504940", "price": "0.84", "size": "30", "side": "BUY", "hash": "7e3fb35d9e91ef17103b1b9f7b68fb2e10a00022", "best_bid": "0.85", "best_ask": "0.94"}, {"asset_id": "95101171893122594180666530745464033001482832309010202534315814756594685314956", "price": "0.16", "size": "30", "side": "SELL", "hash": "7f94623a34a5a35045027dc9b014c4494fe1f44c", "best_bid": "0.06", "best_ask": "0.15"}], "timestamp": "1769384101297", "event_type": "price_change"}}
{"_local_timestamp": "2026-01-25T23:35:01.413732+00:00", "data": {"market": "0xbc63ab257269b6d88696a7c395c22a032dd8bcaec0f20b22083ac17dd8a9221c", "price_changes": [{"asset_id": "7542437468156958963085282310210526488532310459870037284043838227272438514792", "price": "0.23", "size": "113.04", "side": "BUY", "hash": "9409199c3bf4845567414ca2a18913b0c8a8732a", "best_bid": "0.71", "best_ask": "0.77"}, {"asset_id": "70095723080029803518081326396248438374756818653107709477379930258944056936114", "price": "0.77", "size": "113.04", "side": "SELL", "hash": "8a297c0b701441a22a715b58f8f1738977ce2415", "best_bid": "0.23", "best_ask": "0.29"}], "timestamp": "1769384101306", "event_type": "price_change"}}
{"_local_timestamp": "2026-01-25T23:35:01.430552+00:00", "data": {"market": "0xa5e46823b12f8751471c740cb5611827629c198f80aca1624867773bfc58d8a6", "price_changes": [{"asset_id": "3056942142656390250297633237719893992746229918619747110824738083465804504940", "price": "0.85", "size": "29.97", "side": "BUY", "hash": "577f584641a71264fd3481e24b02e518e8e364b7", "best_bid": "0.85", "best_ask": "0.94"}, {"asset_id": "95101171893122594180666530745464033001482832309010202534315814756594685314956", "price": "0.15", "size": "29.97", "side": "SELL", "hash": "e696a5da5aac64034761ef019c71f9d5d9f1b460", "best_bid": "0.06", "best_ask": "0.15"}], "timestamp": "1769384101325", "event_type": "price_change"}}
{"_local_timestamp": "2026-01-25T23:35:01.453122+00:00", "data": {"market": "0xbc63ab257269b6d88696a7c395c22a032dd8bcaec0f20b22083ac17dd8a9221c", "price_changes": [{"asset_id": "7542437468156958963085282310210526488532310459870037284043838227272438514792", "price": "0.19", "size": "147.36", "side": "BUY", "hash": "d6ed3b27c4ba0113a1d88290ea7ae82c725802fe", "best_bid": "0.71", "best_ask": "0.77"}, {"asset_id": "70095723080029803518081326396248438374756818653107709477379930258944056936114", "price": "0.81", "size": "147.36", "side": "SELL", "hash": "53d83933deb20d1c091583f2e5e80fc9e06ea3ff", "best_bid": "0.23", "best_ask": "0.29"}], "timestamp": "1769384101352", "event_type": "price_change"}}
{"_local_timestamp": "2026-01-25T23:35:01.514176+00:00", "data": {"market": "0xbc63ab257269b6d88696a7c395c22a032dd8bcaec0f20b22083ac17dd8a9221c", "price_changes": [{"asset_id": "7542437468156958963085282310210526488532310459870037284043838227272438514792", "price": "0.15", "size": "213.33", "side": "BUY", "hash": "9be19e4f24860481ed84895fc4d27659eb671226", "best_bid": "0.71", "best_ask": "0.77"}, {"asset_id": "70095723080029803518081326396248438374756818653107709477379930258944056936114", "price": "0.85", "size": "213.33", "side": "SELL", "hash": "7ad32eb9508c969b746cd333613c8174faf1a877", "best_bid": "0.23", "best_ask": "0.29"}], "timestamp": "1769384101408", "event_type": "price_change"}}
{"_local_timestamp": "2026-01-25T23:35:01.565545+00:00", "data": {"market": "0xbc63ab257269b6d88696a7c395c22a032dd8bcaec0f20b22083ac17dd8a9221c", "price_changes": [{"asset_id": "7542437468156958963085282310210526488532310459870037284043838227272438514792", "price": "0.12", "size": "283.33", "side": "BUY", "hash": "445e38a7f152e812000dfe86a6684de99a159689", "best_bid": "0.71", "best_ask": "0.77"}, {"asset_id": "70095723080029803518081326396248438374756818653107709477379930258944056936114", "price": "0.88", "size": "283.33", "side": "SELL", "hash": "25c1eb80762a32304a10a6d41983f8f4efd20e65", "best_bid": "0.23", "best_ask": "0.29"}], "timestamp": "1769384101457", "event_type": "price_change"}}
{"_local_timestamp": "2026-01-25T23:35:01.613060+00:00", "data": {"market": "0xbc63ab257269b6d88696a7c395c22a032dd8bcaec0f20b22083ac17dd8a9221c", "price_changes": [{"asset_id": "7542437468156958963085282310210526488532310459870037284043838227272438514792", "price": "0.08", "size": "750", "side": "BUY", "hash": "bd5353d77a271ef35bafde06640d9e634f45bcbb", "best_bid": "0.71", "best_ask": "0.77"}, {"asset_id": "70095723080029803518081326396248438374756818653107709477379930258944056936114", "price": "0.92", "size": "750", "side": "SELL", "hash": "cac77428eb9c4366bb61fc332efd0f4075d01546", "best_bid": "0.23", "best_ask": "0.29"}], "timestamp": "1769384101508", "event_type": "price_change"}}
{"_local_timestamp": "2026-01-25T23:35:03.127886+00:00", "data": {"market": "0xbc63ab257269b6d88696a7c395c22a032dd8bcaec0f20b22083ac17dd8a9221c", "price_changes": [{"asset_id": "70095723080029803518081326396248438374756818653107709477379930258944056936114", "price": "0.29", "size": "0", "side": "SELL", "hash": "3185589da52d029cf5098c6c9347b69b2dae0486", "best_bid": "0.23", "best_ask": "0.4"}, {"asset_id": "7542437468156958963085282310210526488532310459870037284043838227272438514792", "price": "0.71", "size": "0", "side": "BUY", "hash": "3e77bd324f8304c577ec64f886cffbe3fdce4f38", "best_bid": "0.6", "best_ask": "0.77"}], "timestamp": "1769384102976", "event_type": "price_change"}}
{"_local_timestamp": "2026-01-25T23:35:03.152832+00:00", "data": {"market": "0x4a0ead3d8c0aa0a73f322aaa95615e7d29b414b9fc4bace855bb74a7a648d990", "price_changes": [{"asset_id": "111376742935340636514883997859794030073097390424337351101383349939644307757449", "price": "0.83", "size": "0", "side": "BUY", "hash": "7bb63e544e65eb6ff444a9803191876eb97cf33e", "best_bid": "0.86", "best_ask": "0.93"}, {"asset_id": "4936830242343432951855740478936036194473488983939131588159659366497804600794", "price": "0.17", "size": "0", "side": "SELL", "hash": "58edd7d3a407b3fbd31ebdc97bd62b4c71697120", "best_bid": "0.07", "best_ask": "0.14"}], "timestamp": "1769384103005", "event_type": "price_change"}}
{"_local_timestamp": "2026-01-25T23:35:03.153182+00:00", "data": {"market": "0xa5e46823b12f8751471c740cb5611827629c198f80aca1624867773bfc58d8a6", "price_changes": [{"asset_id": "3056942142656390250297633237719893992746229918619747110824738083465804504940", "price": "0.85", "size": "9.97", "side": "BUY", "hash": "8ce4c563a8684d60770d0bcac360e3357d8f82db", "best_bid": "0.85", "best_ask": "0.94"}, {"asset_id": "95101171893122594180666530745464033001482832309010202534315814756594685314956", "price": "0.15", "size": "9.97", "side": "SELL", "hash": "d04b8737ff5dc4e3d2f8e844f578e84fae5728e7", "best_bid": "0.06", "best_ask": "0.15"}], "timestamp": "1769384103005", "event_type": "price_change"}}
{"_local_timestamp": "2026-01-25T23:35:03.216336+00:00", "data": {"market": "0x4a0ead3d8c0aa0a73f322aaa95615e7d29b414b9fc4bace855bb74a7a648d990", "price_changes": [{"asset_id": "111376742935340636514883997859794030073097390424337351101383349939644307757449", "price": "0.59", "size": "0", "side": "BUY", "hash": "753907cf4f13ac8f6fc232666bff76bdc792852e", "best_bid": "0.86", "best_ask": "0.93"}, {"asset_id": "4936830242343432951855740478936036194473488983939131588159659366497804600794", "price": "0.41", "size": "0", "side": "SELL", "hash": "e50b6c47e11394289a10343e04033d80b790c62a", "best_bid": "0.07", "best_ask": "0.14"}], "timestamp": "1769384103073", "event_type": "price_change"}}
{"_local_timestamp": "2026-01-25T23:35:03.421163+00:00", "data": {"market": "0x4a0ead3d8c0aa0a73f322aaa95615e7d29b414b9fc4bace855bb74a7a648d990", "price_changes": [{"asset_id": "111376742935340636514883997859794030073097390424337351101383349939644307757449", "price": "0.3", "size": "10", "side": "BUY", "hash": "b0574d02d45b9ce393ae36f43dd8b6c71a3c33d9", "best_bid": "0.86", "best_ask": "0.93"}, {"asset_id": "4936830242343432951855740478936036194473488983939131588159659366497804600794", "price": "0.7", "size": "10", "side": "SELL", "hash": "d5e33c9c4aba0732a79bbbfcb81f89737c2a53eb", "best_bid": "0.07", "best_ask": "0.14"}], "timestamp": "1769384103266", "event_type": "price_change"}}
{"_local_timestamp": "2026-01-25T23:35:03.498977+00:00", "data": {"market": "0xbc63ab257269b6d88696a7c395c22a032dd8bcaec0f20b22083ac17dd8a9221c", "price_changes": [{"asset_id": "7542437468156958963085282310210526488532310459870037284043838227272438514792", "price": "0.08", "size": "300", "side": "BUY", "hash": "7e82a8b38a2267e3cd0d6ed738dbd7dfb8184361", "best_bid": "0.6", "best_ask": "0.77"}, {"asset_id": "70095723080029803518081326396248438374756818653107709477379930258944056936114", "price": "0.92", "size": "300", "side": "SELL", "hash": "e909969b7ba9f979b967600328595bbf1568c03a", "best_bid": "0.23", "best_ask": "0.4"}], "timestamp": "1769384103359", "event_type": "price_change"}}
{"_local_timestamp": "2026-01-25T23:35:03.507310+00:00", "data": {"market": "0xbc63ab257269b6d88696a7c395c22a032dd8bcaec0f20b22083ac17dd8a9221c", "price_changes": [{"asset_id": "7542437468156958963085282310210526488532310459870037284043838227272438514792", "price": "0.27", "size": "313", "side": "BUY", "hash": "7e82a8b38a2267e3cd0d6ed738dbd7dfb8184361", "best_bid": "0.6", "best_ask": "0.77"}, {"asset_id": "70095723080029803518081326396248438374756818653107709477379930258944056936114", "price": "0.73", "size": "313", "side": "SELL", "hash": "e909969b7ba9f979b967600328595bbf1568c03a", "best_bid": "0.23", "best_ask": "0.4"}], "timestamp": "1769384103359", "event_type": "price_change"}}
{"_local_timestamp": "2026-01-25T23:35:03.507719+00:00", "data": {"market": "0xbc63ab257269b6d88696a7c395c22a032dd8bcaec0f20b22083ac17dd8a9221c", "price_changes": [{"asset_id": "7542437468156958963085282310210526488532310459870037284043838227272438514792", "price": "0.19", "size": "0", "side": "BUY", "hash": "7e82a8b38a2267e3cd0d6ed738dbd7dfb8184361", "best_bid": "0.6", "best_ask": "0.77"}, {"asset_id": "70095723080029803518081326396248438374756818653107709477379930258944056936114", "price": "0.81", "size": "0", "side": "SELL", "hash": "e909969b7ba9f979b967600328595bbf1568c03a", "best_bid": "0.23", "best_ask": "0.4"}], "timestamp": "1769384103359", "event_type": "price_change"}}
{"_local_timestamp": "2026-01-25T23:35:03.508618+00:00", "data": {"market": "0xbc63ab257269b6d88696a7c395c22a032dd8bcaec0f20b22083ac17dd8a9221c", "price_changes": [{"asset_id": "7542437468156958963085282310210526488532310459870037284043838227272438514792", "price": "0.31", "size": "0", "side": "BUY", "hash": "7e82a8b38a2267e3cd0d6ed738dbd7dfb8184361", "best_bid": "0.6", "best_ask": "0.77"}, {"asset_id": "70095723080029803518081326396248438374756818653107709477379930258944056936114", "price": "0.69", "size": "0", "side": "SELL", "hash": "e909969b7ba9f979b967600328595bbf1568c03a", "best_bid": "0.23", "best_ask": "0.4"}], "timestamp": "1769384103359", "event_type": "price_change"}}
{"_local_timestamp": "2026-01-25T23:35:03.510299+00:00", "data": {"market": "0xbc63ab257269b6d88696a7c395c22a032dd8bcaec0f20b22083ac17dd8a9221c", "price_changes": [{"asset_id": "7542437468156958963085282310210526488532310459870037284043838227272438514792", "price": "0.12", "size": "0", "side": "BUY", "hash": "7e82a8b38a2267e3cd0d6ed738dbd7dfb8184361", "best_bid": "0.6", "best_ask": "0.77"}, {"asset_id": "70095723080029803518081326396248438374756818653107709477379930258944056936114", "price": "0.88", "size": "0", "side": "SELL", "hash": "e909969b7ba9f979b967600328595bbf1568c03a", "best_bid": "0.23", "best_ask": "0.4"}], "timestamp": "1769384103359", "event_type": "price_change"}}
{"_local_timestamp": "2026-01-25T23:35:03.510742+00:00", "data": {"market": "0xbc63ab257269b6d88696a7c395c22a032dd8bcaec0f20b22083ac17dd8a9221c", "price_changes": [{"asset_id": "7542437468156958963085282310210526488532310459870037284043838227272438514792", "price": "0.15", "size": "0", "side": "BUY", "hash": "7e82a8b38a2267e3cd0d6ed738dbd7dfb8184361", "best_bid": "0.6", "best_ask": "0.77"}, {"asset_id": "70095723080029803518081326396248438374756818653107709477379930258944056936114", "price": "0.85", "size": "0", "side": "SELL", "hash": "e909969b7ba9f979b967600328595bbf1568c03a", "best_bid": "0.23", "best_ask": "0.4"}], "timestamp": "1769384103359", "event_type": "price_change"}}
{"_local_timestamp": "2026-01-25T23:35:03.511284+00:00", "data": {"market": "0xbc63ab257269b6d88696a7c395c22a032dd8bcaec0f20b22083ac17dd8a9221c", "price_changes": [{"asset_id": "7542437468156958963085282310210526488532310459870037284043838227272438514792", "price": "0.23", "size": "0", "side": "BUY", "hash": "7e82a8b38a2267e3cd0d6ed738dbd7dfb8184361", "best_bid": "0.6", "best_ask": "0.77"}, {"asset_id": "70095723080029803518081326396248438374756818653107709477379930258944056936114", "price": "0.77", "size": "0", "side": "SELL", "hash": "e909969b7ba9f979b967600328595bbf1568c03a", "best_bid": "0.23", "best_ask": "0.4"}], "timestamp": "1769384103359", "event_type": "price_change"}}
{"_local_timestamp": "2026-01-25T23:35:05.735150+00:00", "data": {"market": "0xbc63ab257269b6d88696a7c395c22a032dd8bcaec0f20b22083ac17dd8a9221c", "price_changes": [{"asset_id": "70095723080029803518081326396248438374756818653107709477379930258944056936114", "price": "0.15", "size": "0", "side": "BUY", "hash": "fa3642c2cef5ff2f5fb7ba94f628f8e41eba5ba6", "best_bid": "0.23", "best_ask": "0.4"}, {"asset_id": "7542437468156958963085282310210526488532310459870037284043838227272438514792", "price": "0.85", "size": "0", "side": "SELL", "hash": "06621de2b8a2810edee068fe1b24914fa3f62368", "best_bid": "0.6", "best_ask": "0.77"}], "timestamp": "1769384105580", "event_type": "price_change"}}
{"_local_timestamp": "2026-01-25T23:35:05.735548+00:00", "data": {"market": "0x4a0ead3d8c0aa0a73f322aaa95615e7d29b414b9fc4bace855bb74a7a648d990", "price_changes": [{"asset_id": "111376742935340636514883997859794030073097390424337351101383349939644307757449", "price": "0.72", "size": "0", "side": "BUY", "hash": "b90c02a6cab9edd1826f3456eca817b831963510", "best_bid": "0.86", "best_ask": "0.93"}, {"asset_id": "4936830242343432951855740478936036194473488983939131588159659366497804600794", "price": "0.28", "size": "0", "side": "SELL", "hash": "953f0924ae74679c7ffeb7d66375c375496717a6", "best_bid": "0.07", "best_ask": "0.14"}], "timestamp": "1769384105580", "event_type": "price_change"}}
{"_local_timestamp": "2026-01-25T23:35:05.735883+00:00", "data": {"market": "0x262962b5d5b1f248aac0c99a871402f136a7a01de85aa5503c3bfa92f46b2c55", "price_changes": [{"asset_id": "19123455644246071046896212752788121367175617509312871406465324158710992613511", "price": "0.811", "size": "0", "side": "BUY", "hash": "f266c4264ffc9f2ec2114f656fa5607d3104a0fe", "best_bid": "0.91", "best_ask": "0.989"}, {"asset_id": "106003536497972067032507723744954701264783762198809994038236889884495294178883", "price": "0.189", "size": "0", "side": "SELL", "hash": "79132c7ed26943427d876b461f558ae8d2703673", "best_bid": "0.011", "best_ask": "0.09"}], "timestamp": "1769384105580", "event_type": "price_change"}}
{"_local_timestamp": "2026-01-25T23:35:05.738270+00:00", "data": {"market": "0xa5e46823b12f8751471c740cb5611827629c198f80aca1624867773bfc58d8a6", "price_changes": [{"asset_id": "3056942142656390250297633237719893992746229918619747110824738083465804504940", "price": "0.84", "size": "10", "side": "BUY", "hash": "61baeca92a9b780771c4c4d9d82290eba60f03c1", "best_bid": "0.85", "best_ask": "0.94"}, {"asset_id": "95101171893122594180666530745464033001482832309010202534315814756594685314956", "price": "0.16", "size": "10", "side": "SELL", "hash": "6f2f9d564b8e65322928c232775ce72b8ff61a80", "best_bid": "0.06", "best_ask": "0.15"}], "timestamp": "1769384105580", "event_type": "price_change"}}
{"_local_timestamp": "2026-01-25T23:35:05.738728+00:00", "data": {"market": "0x059da3ba4ea3b184e31fb8978967cbd607f5187de5846b64dcd6777ab11dbfcf", "price_changes": [{"asset_id": "12442026831814665517479454307107841564924638876268430912384587148891875917807", "price": "0.872", "size": "0", "side": "BUY", "hash": "2db69c444f930cd463193e3ed2ab23d6e89f796b", "best_bid": "0.984", "best_ask": "0.994"}, {"asset_id": "98400648527667164765783273069456261018306904239322551307759035804553498481296", "price": "0.128", "size": "0", "side": "SELL", "hash": "e403d893a2502259e659f90acc7703bf331b6249", "best_bid": "0.006", "best_ask": "0.016"}], "timestamp": "1769384105580", "event_type": "price_change"}}
{"_local_timestamp": "2026-01-25T23:35:05.778609+00:00", "data": {"market": "0x4a0ead3d8c0aa0a73f322aaa95615e7d29b414b9fc4bace855bb74a7a648d990", "price_changes": [{"asset_id": "111376742935340636514883997859794030073097390424337351101383349939644307757449", "price": "0.66", "size": "20", "side": "BUY", "hash": "991050216b00e4ee65cfb66d2f7a651f69b78d71", "best_bid": "0.86", "best_ask": "0.93"}, {"asset_id": "4936830242343432951855740478936036194473488983939131588159659366497804600794", "price": "0.34", "size": "20", "side": "SELL", "hash": "f8ecece3f9dcc26e7315c555e4bcc0ad02707f44", "best_bid": "0.07", "best_ask": "0.14"}], "timestamp": "1769384105616", "event_type": "price_change"}}
{"_local_timestamp": "2026-01-25T23:35:05.778990+00:00", "data": {"market": "0xbc63ab257269b6d88696a7c395c22a032dd8bcaec0f20b22083ac17dd8a9221c", "price_changes": [{"asset_id": "70095723080029803518081326396248438374756818653107709477379930258944056936114", "price": "0.14", "size": "20", "side": "BUY", "hash": "dcac84e9633a41d4858004b5d5f3226595d91b3e", "best_bid": "0.23", "best_ask": "0.4"}, {"asset_id": "7542437468156958963085282310210526488532310459870037284043838227272438514792", "price": "0.86", "size": "20", "side": "SELL", "hash": "ed1dfac7c9f0e120b0682612044697ab5295f0e3", "best_bid": "0.6", "best_ask": "0.77"}], "timestamp": "1769384105616", "event_type": "price_change"}}
{"_local_timestamp": "2026-01-25T23:35:05.779230+00:00", "data": {"market": "0x262962b5d5b1f248aac0c99a871402f136a7a01de85aa5503c3bfa92f46b2c55", "price_changes": [{"asset_id": "19123455644246071046896212752788121367175617509312871406465324158710992613511", "price": "0.607", "size": "20", "side": "BUY", "hash": "7d60d18c5ea544f76dcb72ba7256017cf0cdc164", "best_bid": "0.91", "best_ask": "0.989"}, {"asset_id": "106003536497972067032507723744954701264783762198809994038236889884495294178883", "price": "0.393", "size": "20", "side": "SELL", "hash": "ef31e5918ac793ed821f3aa029337d037f2db8c6", "best_bid": "0.011", "best_ask": "0.09"}], "timestamp": "1769384105616", "event_type": "price_change"}}
{"_local_timestamp": "2026-01-25T23:35:05.779492+00:00", "data": {"market": "0x059da3ba4ea3b184e31fb8978967cbd607f5187de5846b64dcd6777ab11dbfcf", "price_changes": [{"asset_id": "12442026831814665517479454307107841564924638876268430912384587148891875917807", "price": "0.645", "size": "20", "side": "BUY", "hash": "42fd291e3f1efd38078a6166c19091591c9971b4", "best_bid": "0.984", "best_ask": "0.994"}, {"asset_id": "98400648527667164765783273069456261018306904239322551307759035804553498481296", "price": "0.355", "size": "20", "side": "SELL", "hash": "f62bcf61c5690c3fbd0f4aa6ec8bf4bb1066ad32", "best_bid": "0.006", "best_ask": "0.016"}], "timestamp": "1769384105616", "event_type": "price_change"}}
{"_local_timestamp": "2026-01-25T23:35:05.779779+00:00", "data": {"market": "0xa5e46823b12f8751471c740cb5611827629c198f80aca1624867773bfc58d8a6", "price_changes": [{"asset_id": "3056942142656390250297633237719893992746229918619747110824738083465804504940", "price": "0.57", "size": "25", "side": "BUY", "hash": "0a07c3a1acaeb87ae19a65710254d37252894422", "best_bid": "0.85", "best_ask": "0.94"}, {"asset_id": "95101171893122594180666530745464033001482832309010202534315814756594685314956", "price": "0.43", "size": "25", "side": "SELL", "hash": "bcb79477dad6796cf81f266868a8b981020475ba", "best_bid": "0.06", "best_ask": "0.15"}], "timestamp": "1769384105617", "event_type": "price_change"}}
{"_local_timestamp": "2026-01-25T23:35:05.785103+00:00", "data": {"market": "0x4a0ead3d8c0aa0a73f322aaa95615e7d29b414b9fc4bace855bb74a7a648d990", "price_changes": [{"asset_id": "111376742935340636514883997859794030073097390424337351101383349939644307757449", "price": "0.3", "size": "0", "side": "BUY", "hash": "06b361caa001b589d73e3968c7c506da9e9765fc", "best_bid": "0.86", "best_ask": "0.93"}, {"asset_id": "4936830242343432951855740478936036194473488983939131588159659366497804600794", "price": "0.7", "size": "0", "side": "SELL", "hash": "ade33b08dde94c74050dc44bcd6f1b78750861ed", "best_bid": "0.07", "best_ask": "0.14"}], "timestamp": "1769384105620", "event_type": "price_change"}}
{"_local_timestamp": "2026-01-25T23:35:06.004139+00:00", "data": {"market": "0x4a0ead3d8c0aa0a73f322aaa95615e7d29b414b9fc4bace855bb74a7a648d990", "price_changes": [{"asset_id": "111376742935340636514883997859794030073097390424337351101383349939644307757449", "price": "0.28", "size": "10", "side": "BUY", "hash": "0501ef7eb2be397b5fe14f4182350b04163acd3e", "best_bid": "0.86", "best_ask": "0.93"}, {"asset_id": "4936830242343432951855740478936036194473488983939131588159659366497804600794", "price": "0.72", "size": "10", "side": "SELL", "hash": "381b6730530d4d5b2060976ed50bef53ce347992", "best_bid": "0.07", "best_ask": "0.14"}], "timestamp": "1769384105821", "event_type": "price_change"}}
{"_local_timestamp": "2026-01-25T23:35:13.174777+00:00", "data": {"market": "0xbc63ab257269b6d88696a7c395c22a032dd8bcaec0f20b22083ac17dd8a9221c", "price_changes": [{"asset_id": "70095723080029803518081326396248438374756818653107709477379930258944056936114", "price": "0.39", "size": "25", "side": "SELL", "hash": "9a95c2707ca8dce8359d9577a363e8af688007a8", "best_bid": "0.23", "best_ask": "0.39"}, {"asset_id": "7542437468156958963085282310210526488532310459870037284043838227272438514792", "price": "0.61", "size": "25", "side": "BUY", "hash": "e50df4793c7f01ae0ac5aec6f755aa9084eb5357", "best_bid": "0.61", "best_ask": "0.77"}], "timestamp": "1769384112945", "event_type": "price_change"}}
{"_local_timestamp": "2026-01-25T23:35:13.189781+00:00", "data": {"market": "0xa5e46823b12f8751471c740cb5611827629c198f80aca1624867773bfc58d8a6", "price_changes": [{"asset_id": "3056942142656390250297633237719893992746229918619747110824738083465804504940", "price": "0.75", "size": "41.4", "side": "BUY", "hash": "a857054c29eed8fd8a6544755881e67fe87d8391", "best_bid": "0.85", "best_ask": "0.94"}, {"asset_id": "95101171893122594180666530745464033001482832309010202534315814756594685314956", "price": "0.25", "size": "41.4", "side": "SELL", "hash": "b41424518ad8c855e9eb1c38fe3a32317beeab60", "best_bid": "0.06", "best_ask": "0.15"}], "timestamp": "1769384112982", "event_type": "price_change"}}
{"_local_timestamp": "2026-01-25T23:35:13.249938+00:00", "data": {"market": "0x4a0ead3d8c0aa0a73f322aaa95615e7d29b414b9fc4bace855bb74a7a648d990", "price_changes": [{"asset_id": "111376742935340636514883997859794030073097390424337351101383349939644307757449", "price": "0.74", "size": "20", "side": "BUY", "hash": "4b61c440ea712671020d40fcd9ee8b3827273aa8", "best_bid": "0.86", "best_ask": "0.93"}, {"asset_id": "4936830242343432951855740478936036194473488983939131588159659366497804600794", "price": "0.26", "size": "20", "side": "SELL", "hash": "c5c27cd3605b6545bd49e177db0e56d96c94201b", "best_bid": "0.07", "best_ask": "0.14"}], "timestamp": "1769384113005", "event_type": "price_change"}}
{"_local_timestamp": "2026-01-25T23:35:26.909767+00:00", "data": {"market": "0xbc63ab257269b6d88696a7c395c22a032dd8bcaec0f20b22083ac17dd8a9221c", "price_changes": [{"asset_id": "7542437468156958963085282310210526488532310459870037284043838227272438514792", "price": "0.27", "size": "263", "side": "BUY", "hash": "89baa27714011fe770b103e594d79d8d3dddcde1", "best_bid": "0.61", "best_ask": "0.77"}, {"asset_id": "70095723080029803518081326396248438374756818653107709477379930258944056936114", "price": "0.73", "size": "263", "side": "SELL", "hash": "76bccfc2380cda0c2da2f2c071a5abe665afcafa", "best_bid": "0.23", "best_ask": "0.39"}], "timestamp": "1769384126575", "event_type": "price_change"}}
{"_local_timestamp": "2026-01-25T23:35:27.048215+00:00", "data": {"market": "0x4a0ead3d8c0aa0a73f322aaa95615e7d29b414b9fc4bace855bb74a7a648d990", "price_changes": [{"asset_id": "111376742935340636514883997859794030073097390424337351101383349939644307757449", "price": "0.28", "size": "0", "side": "BUY", "hash": "b030bf3c20ff9be2d04b22c797fec2d57673276e", "best_bid": "0.86", "best_ask": "0.93"}, {"asset_id": "4936830242343432951855740478936036194473488983939131588159659366497804600794", "price": "0.72", "size": "0", "side": "SELL", "hash": "bd1f03b128419ac3b5ad39bdef1fecdf26e7e5b3", "best_bid": "0.07", "best_ask": "0.14"}], "timestamp": "1769384126722", "event_type": "price_change"}}
{"_local_timestamp": "2026-01-25T23:35:29.312272+00:00", "data": {"market": "0x262962b5d5b1f248aac0c99a871402f136a7a01de85aa5503c3bfa92f46b2c55", "price_changes": [{"asset_id": "106003536497972067032507723744954701264783762198809994038236889884495294178883", "price": "0.002", "size": "300", "side": "BUY", "hash": "a8d1cb05033dff1d29be7f4e6d5e4932ac7a51f2", "best_bid": "0.011", "best_ask": "0.09"}, {"asset_id": "19123455644246071046896212752788121367175617509312871406465324158710992613511", "price": "0.998", "size": "300", "side": "SELL", "hash": "14d80213895717612f7228bc82616d14ac05c3a3", "best_bid": "0.91", "best_ask": "0.989"}], "timestamp": "1769384129065", "event_type": "price_change"}}
{"_local_timestamp": "2026-01-25T23:35:29.312710+00:00", "data": {"market": "0x262962b5d5b1f248aac0c99a871402f136a7a01de85aa5503c3bfa92f46b2c55", "price_changes": [{"asset_id": "106003536497972067032507723744954701264783762198809994038236889884495294178883", "price": "0.003", "size": "300", "side": "BUY", "hash": "a8d1cb05033dff1d29be7f4e6d5e4932ac7a51f2", "best_bid": "0.011", "best_ask": "0.09"}, {"asset_id": "19123455644246071046896212752788121367175617509312871406465324158710992613511", "price": "0.997", "size": "300", "side": "SELL", "hash": "14d80213895717612f7228bc82616d14ac05c3a3", "best_bid": "0.91", "best_ask": "0.989"}], "timestamp": "1769384129065", "event_type": "price_change"}}
{"_local_timestamp": "2026-01-25T23:35:29.626707+00:00", "data": {"market": "0x262962b5d5b1f248aac0c99a871402f136a7a01de85aa5503c3bfa92f46b2c55", "price_changes": [{"asset_id": "106003536497972067032507723744954701264783762198809994038236889884495294178883", "price": "0.002", "size": "330.46", "side": "BUY", "hash": "3096debd44c24f849fa83eca53bebbe33d58c746", "best_bid": "0.011", "best_ask": "0.09"}, {"asset_id": "19123455644246071046896212752788121367175617509312871406465324158710992613511", "price": "0.998", "size": "330.46", "side": "SELL", "hash": "58f36ee303c5acc637d7218b3c90f2dc15c60fa4", "best_bid": "0.91", "best_ask": "0.989"}], "timestamp": "1769384129390", "event_type": "price_change"}}
{"_local_timestamp": "2026-01-25T23:35:29.627082+00:00", "data": {"market": "0x262962b5d5b1f248aac0c99a871402f136a7a01de85aa5503c3bfa92f46b2c55", "price_changes": [{"asset_id": "106003536497972067032507723744954701264783762198809994038236889884495294178883", "price": "0.003", "size": "320.2", "side": "BUY", "hash": "c3b07d4581f14bac1d789f8e37564439bdb04762", "best_bid": "0.011", "best_ask": "0.09"}, {"asset_id": "19123455644246071046896212752788121367175617509312871406465324158710992613511", "price": "0.997", "size": "320.2", "side": "SELL", "hash": "6d392c6e77deccb1356c158a989e03f3244210e9", "best_bid": "0.91", "best_ask": "0.989"}], "timestamp": "1769384129391", "event_type": "price_change"}}
{"_local_timestamp": "2026-01-25T23:35:30.971267+00:00", "data": {"market": "0x262962b5d5b1f248aac0c99a871402f136a7a01de85aa5503c3bfa92f46b2c55", "price_changes": [{"asset_id": "19123455644246071046896212752788121367175617509312871406465324158710992613511", "price": "0.15", "size": "776.66", "side": "BUY", "hash": "7ac9ac97a96f611132df9380ee99683c2ea56874", "best_bid": "0.91", "best_ask": "0.989"}, {"asset_id": "106003536497972067032507723744954701264783762198809994038236889884495294178883", "price": "0.85", "size": "776.66", "side": "SELL", "hash": "78b8161e4f705a5ca231f1cd6053554f1a70e982", "best_bid": "0.011", "best_ask": "0.09"}], "timestamp": "1769384130729", "event_type": "price_change"}}
{"_local_timestamp": "2026-01-25T23:35:31.264642+00:00", "data": {"market": "0x262962b5d5b1f248aac0c99a871402f136a7a01de85aa5503c3bfa92f46b2c55", "price_changes": [{"asset_id": "19123455644246071046896212752788121367175617509312871406465324158710992613511", "price": "0.2", "size": "660", "side": "BUY", "hash": "bd0f34c2f11c63432e5ff569bbe49d70fc2b597f", "best_bid": "0.91", "best_ask": "0.989"}, {"asset_id": "106003536497972067032507723744954701264783762198809994038236889884495294178883", "price": "0.8", "size": "660", "side": "SELL", "hash": "a35ab6862ecd6617b3748f418d9e6b2335642015", "best_bid": "0.011", "best_ask": "0.09"}], "timestamp": "1769384131019", "event_type": "price_change"}}
{"_local_timestamp": "2026-01-25T23:35:34.107450+00:00", "data": {"market": "0xd525650240c1956c1fd741e727302756002d34541cebb15399c6648372c2b017", "price_changes": [{"asset_id": "58237052681575643690608170707582085559437408445710143443295775339044140331495", "price": "0.002", "size": "500", "side": "BUY", "hash": "28f292eb1d6f31065dd57a45d490f0c2a17d2b8d", "best_bid": "0.009", "best_ask": "0.014"}, {"asset_id": "84363734712816699027954735716573977595829918143333969139288207428067341798047", "price": "0.998", "size": "500", "side": "SELL", "hash": "82976f5ac316d43558cd385410e640f22da182e5", "best_bid": "0.986", "best_ask": "0.991"}], "timestamp": "1769384133905", "event_type": "price_change"}}
{"_local_timestamp": "2026-01-25T23:35:34.268477+00:00", "data": {"market": "0x00ece3aec2e7ec1266c81f9b6dee4d5774c5e9fc1d8b4c05750363bb6693608c", "price_changes": [{"asset_id": "56288496839116076608936080824519320480921427720682183882154533325856755856281", "price": "0.638", "size": "0", "side": "BUY", "hash": "91c657cb66f132140d78cf3e9b9e4ed2c370a61a", "best_bid": "0.988", "best_ask": "0.995"}, {"asset_id": "20277485868363893965343112627224984692523382854354842924096328553726850004689", "price": "0.362", "size": "0", "side": "SELL", "hash": "7776ae139c351f38d6f553acdddd5fe5b70f0d4f", "best_bid": "0.005", "best_ask": "0.012"}], "timestamp": "1769384134063", "event_type": "price_change"}}
{"_local_timestamp": "2026-01-25T23:35:34.276441+00:00", "data": {"market": "0xa5e46823b12f8751471c740cb5611827629c198f80aca1624867773bfc58d8a6", "price_changes": [{"asset_id": "3056942142656390250297633237719893992746229918619747110824738083465804504940", "price": "0.29", "size": "0", "side": "BUY", "hash": "2be2bb056b9423b8e901fac6f635e2fe66cc6234", "best_bid": "0.85", "best_ask": "0.94"}, {"asset_id": "95101171893122594180666530745464033001482832309010202534315814756594685314956", "price": "0.71", "size": "0", "side": "SELL", "hash": "b0246508f3ca95dda7fda6e7b34918ae5f112e70", "best_bid": "0.06", "best_ask": "0.15"}], "timestamp": "1769384134062", "event_type": "price_change"}}
{"_local_timestamp": "2026-01-25T23:35:34.276886+00:00", "data": {"market": "0xe6703820029400bb3989c9ca94511ae96bcb6bb212e76bfce28fbc3d0712e7da", "price_changes": [{"asset_id": "65912005210412562484178321309940712764547284237411298620608183481031681522759", "price": "0.61", "size": "0", "side": "BUY", "hash": "82b5c7f4401e62946c35c83532aa5bfe1ff03225", "best_bid": "0.9", "best_ask": "0.95"}, {"asset_id": "26862256473738234042890995175212184751139521605012603994991408238083491315385", "price": "0.39", "size": "0", "side": "SELL", "hash": "6704668d3c346fd91b0f6a4c0505d70c28113196", "best_bid": "0.05", "best_ask": "0.1"}], "timestamp": "1769384134062", "event_type": "price_change"}}
{"_local_timestamp": "2026-01-25T23:35:34.405066+00:00", "data": {"market": "0xe6703820029400bb3989c9ca94511ae96bcb6bb212e76bfce28fbc3d0712e7da", "price_changes": [{"asset_id": "65912005210412562484178321309940712764547284237411298620608183481031681522759", "price": "0.59", "size": "10", "side": "BUY", "hash": "03e15bc0ef70979f98c368cdefc1a8a6e75875d4", "best_bid": "0.9", "best_ask": "0.95"}, {"asset_id": "26862256473738234042890995175212184751139521605012603994991408238083491315385", "price": "0.41", "size": "10", "side": "SELL", "hash": "2c00db596eb944649ca024ef5edfded154ae0269", "best_bid": "0.05", "best_ask": "0.1"}], "timestamp": "1769384134180", "event_type": "price_change"}}
{"_local_timestamp": "2026-01-25T23:35:34.405397+00:00", "data": {"market": "0xa5e46823b12f8751471c740cb5611827629c198f80aca1624867773bfc58d8a6", "price_changes": [{"asset_id": "3056942142656390250297633237719893992746229918619747110824738083465804504940", "price": "0.25", "size": "10", "side": "BUY", "hash": "4bfbd026eb00ea7bc6bc96ec98ea12add9ee068a", "best_bid": "0.85", "best_ask": "0.94"}, {"asset_id": "95101171893122594180666530745464033001482832309010202534315814756594685314956", "price": "0.75", "size": "10", "side": "SELL", "hash": "2d26f3be7f2148506fcf56b25833668cb8004356", "best_bid": "0.06", "best_ask": "0.15"}], "timestamp": "1769384134180", "event_type": "price_change"}}
{"_local_timestamp": "2026-01-25T23:35:34.405700+00:00", "data": {"market": "0x00ece3aec2e7ec1266c81f9b6dee4d5774c5e9fc1d8b4c05750363bb6693608c", "price_changes": [{"asset_id": "56288496839116076608936080824519320480921427720682183882154533325856755856281", "price": "0.635", "size": "10", "side": "BUY", "hash": "fff0b55d4ad4bf2ccaf47b00074fb41905329181", "best_bid": "0.988", "best_ask": "0.995"}, {"asset_id": "20277485868363893965343112627224984692523382854354842924096328553726850004689", "price": "0.365", "size": "10", "side": "SELL", "hash": "212cb0387eec355f63c00821456ac72341111c0a", "best_bid": "0.005", "best_ask": "0.012"}], "timestamp": "1769384134180", "event_type": "price_change"}}
{"_local_timestamp": "2026-01-25T23:35:34.668285+00:00", "data": {"market": "0xd525650240c1956c1fd741e727302756002d34541cebb15399c6648372c2b017", "price_changes": [{"asset_id": "58237052681575643690608170707582085559437408445710143443295775339044140331495", "price": "0.003", "size": "401.56", "side": "BUY", "hash": "8bf182b9e2daf56dc508a664cf337bb42729e30b", "best_bid": "0.009", "best_ask": "0.014"}, {"asset_id": "84363734712816699027954735716573977595829918143333969139288207428067341798047", "price": "0.997", "size": "401.56", "side": "SELL", "hash": "e7980ca62d27138047138af55621899753fee1d1", "best_bid": "0.986", "best_ask": "0.991"}], "timestamp": "1769384134440", "event_type": "price_change"}}
{"_local_timestamp": "2026-01-25T23:35:34.668736+00:00", "data": {"market": "0xd525650240c1956c1fd741e727302756002d34541cebb15399c6648372c2b017", "price_changes": [{"asset_id": "58237052681575643690608170707582085559437408445710143443295775339044140331495", "price": "0.002", "size": "562.65", "side": "BUY", "hash": "565dc0bdbe0e7fa6fc63cfbecb67b5960228091d", "best_bid": "0.009", "best_ask": "0.014"}, {"asset_id": "84363734712816699027954735716573977595829918143333969139288207428067341798047", "price": "0.998", "size": "562.65", "side": "SELL", "hash": "d0a4f4813bcff5f86108e4fb67280e83d691fb89", "best_bid": "0.986", "best_ask": "0.991"}], "timestamp": "1769384134441", "event_type": "price_change"}}
{"_local_timestamp": "2026-01-25T23:35:37.754193+00:00", "data": {"market": "0xe6703820029400bb3989c9ca94511ae96bcb6bb212e76bfce28fbc3d0712e7da", "price_changes": [{"asset_id": "65912005210412562484178321309940712764547284237411298620608183481031681522759", "price": "0.62", "size": "0", "side": "BUY", "hash": "5c0bfe77941842d01e7144bf41c8bce24601f628", "best_bid": "0.9", "best_ask": "0.95"}, {"asset_id": "26862256473738234042890995175212184751139521605012603994991408238083491315385", "price": "0.38", "size": "0", "side": "SELL", "hash": "f896b1c827e423d870e1b3068f4f99d2127f3652", "best_bid": "0.05", "best_ask": "0.1"}], "timestamp": "1769384137538", "event_type": "price_change"}}
{"_local_timestamp": "2026-01-25T23:35:37.754546+00:00", "data": {"market": "0x00ece3aec2e7ec1266c81f9b6dee4d5774c5e9fc1d8b4c05750363bb6693608c", "price_changes": [{"asset_id": "56288496839116076608936080824519320480921427720682183882154533325856755856281", "price": "0.639", "size": "0", "side": "BUY", "hash": "ca0afcc6d4e3efbfb6cbfd7ef2a2d59b191ff09d", "best_bid": "0.988", "best_ask": "0.995"}, {"asset_id": "20277485868363893965343112627224984692523382854354842924096328553726850004689", "price": "0.361", "size": "0", "side": "SELL", "hash": "46714c58f52691a1ef2de1d258e6b5f5fbc1eba3", "best_bid": "0.005", "best_ask": "0.012"}], "timestamp": "1769384137538", "event_type": "price_change"}}
{"_local_timestamp": "2026-01-25T23:35:37.806040+00:00", "data": {"market": "0x00ece3aec2e7ec1266c81f9b6dee4d5774c5e9fc1d8b4c05750363bb6693608c", "price_changes": [{"asset_id": "56288496839116076608936080824519320480921427720682183882154533325856755856281", "price": "0.636", "size": "20", "side": "BUY", "hash": "25f79b00d23d966cb6a4b5e7b8e052d543fd23e8", "best_bid": "0.988", "best_ask": "0.995"}, {"asset_id": "20277485868363893965343112627224984692523382854354842924096328553726850004689", "price": "0.364", "size": "20", "side": "SELL", "hash": "97146f85c7e972b1cc860931408ded1dad525fc2", "best_bid": "0.005", "best_ask": "0.012"}], "timestamp": "1769384137570", "event_type": "price_change"}}
{"_local_timestamp": "2026-01-25T23:35:37.806445+00:00", "data": {"market": "0xe6703820029400bb3989c9ca94511ae96bcb6bb212e76bfce28fbc3d0712e7da", "price_changes": [{"asset_id": "65912005210412562484178321309940712764547284237411298620608183481031681522759", "price": "0.6", "size": "25", "side": "BUY", "hash": "b8d762d9e15f866b5035050ac25c28c7796a7a9b", "best_bid": "0.9", "best_ask": "0.95"}, {"asset_id": "26862256473738234042890995175212184751139521605012603994991408238083491315385", "price": "0.4", "size": "25", "side": "SELL", "hash": "8551d2ca00df9fbf6bfaaab34afc0f099850bc82", "best_bid": "0.05", "best_ask": "0.1"}], "timestamp": "1769384137570", "event_type": "price_change"}}
{"_local_timestamp": "2026-01-25T23:35:38.754827+00:00", "data": {"market": "0xa5e46823b12f8751471c740cb5611827629c198f80aca1624867773bfc58d8a6", "price_changes": [{"asset_id": "3056942142656390250297633237719893992746229918619747110824738083465804504940", "price": "0.05", "size": "530", "side": "BUY", "hash": "189cf04a5c0eef4a764d81bad185b610a343f353", "best_bid": "0.85", "best_ask": "0.94"}, {"asset_id": "95101171893122594180666530745464033001482832309010202534315814756594685314956", "price": "0.95", "size": "530", "side": "SELL", "hash": "9012fdf9a63fd17d202bb44d4e4a6acf577e86f1", "best_bid": "0.06", "best_ask": "0.15"}], "timestamp": "1769384138680", "event_type": "price_change"}}
{"_local_timestamp": "2026-01-25T23:35:39.364511+00:00", "data": {"market": "0xa5e46823b12f8751471c740cb5611827629c198f80aca1624867773bfc58d8a6", "price_changes": [{"asset_id": "3056942142656390250297633237719893992746229918619747110824738083465804504940", "price": "0.02", "size": "1400", "side": "BUY", "hash": "b28e9cd1a2a65a47eacca2dd41bc09a27b95a0d8", "best_bid": "0.85", "best_ask": "0.94"}, {"asset_id": "95101171893122594180666530745464033001482832309010202534315814756594685314956", "price": "0.98", "size": "1400", "side": "SELL", "hash": "f045b9fcce39b427ed36b385cfe309f31f664d5e", "best_bid": "0.06", "best_ask": "0.15"}], "timestamp": "1769384139271", "event_type": "price_change"}}
{"_local_timestamp": "2026-01-25T23:35:39.552591+00:00", "data": {"market": "0xe6703820029400bb3989c9ca94511ae96bcb6bb212e76bfce28fbc3d0712e7da", "price_changes": [{"asset_id": "65912005210412562484178321309940712764547284237411298620608183481031681522759", "price": "0.59", "size": "0", "side": "BUY", "hash": "77d1cea89fdde095ee216b3d1dcc8eae16b66727", "best_bid": "0.9", "best_ask": "0.95"}, {"asset_id": "26862256473738234042890995175212184751139521605012603994991408238083491315385", "price": "0.41", "size": "0", "side": "SELL", "hash": "a3f64594b995701a396a1e43e21607443c31dd20", "best_bid": "0.05", "best_ask": "0.1"}], "timestamp": "1769384139482", "event_type": "price_change"}}
{"_local_timestamp": "2026-01-25T23:35:39.553014+00:00", "data": {"market": "0x00ece3aec2e7ec1266c81f9b6dee4d5774c5e9fc1d8b4c05750363bb6693608c", "price_changes": [{"asset_id": "56288496839116076608936080824519320480921427720682183882154533325856755856281", "price": "0.635", "size": "0", "side": "BUY", "hash": "67921497d41e5a5b2cc236463feccdd081ddb042", "best_bid": "0.988", "best_ask": "0.995"}, {"asset_id": "20277485868363893965343112627224984692523382854354842924096328553726850004689", "price": "0.365", "size": "0", "side": "SELL", "hash": "7dba742c86c77f50785bead487cef54ca9d9c8c7", "best_bid": "0.005", "best_ask": "0.012"}], "timestamp": "1769384139483", "event_type": "price_change"}}
{"_local_timestamp": "2026-01-25T23:35:39.553380+00:00", "data": {"market": "0xd525650240c1956c1fd741e727302756002d34541cebb15399c6648372c2b017", "price_changes": [{"asset_id": "84363734712816699027954735716573977595829918143333969139288207428067341798047", "price": "0.623", "size": "0", "side": "BUY", "hash": "f516813b3ee37456bf896cbdd9c1883155e95db3", "best_bid": "0.986", "best_ask": "0.991"}, {"asset_id": "58237052681575643690608170707582085559437408445710143443295775339044140331495", "price": "0.377", "size": "0", "side": "SELL", "hash": "0abcf2789f0c9169342c6c006c4f3657947481f1", "best_bid": "0.009", "best_ask": "0.014"}], "timestamp": "1769384139483", "event_type": "price_change"}}
{"_local_timestamp": "2026-01-25T23:35:41.788340+00:00", "data": {"market": "0x00ece3aec2e7ec1266c81f9b6dee4d5774c5e9fc1d8b4c05750363bb6693608c", "price_changes": [{"asset_id": "56288496839116076608936080824519320480921427720682183882154533325856755856281", "price": "0.636", "size": "0", "side": "BUY", "hash": "5771001353deda65d6555847b95406abf6e7f082", "best_bid": "0.988", "best_ask": "0.995"}, {"asset_id": "20277485868363893965343112627224984692523382854354842924096328553726850004689", "price": "0.364", "size": "0", "side": "SELL", "hash": "70fd07ab3e478ca3a2ed074fb37816638d51a868", "best_bid": "0.005", "best_ask": "0.012"}], "timestamp": "1769384141717", "event_type": "price_change"}}
{"_local_timestamp": "2026-01-25T23:35:41.788688+00:00", "data": {"market": "0xd525650240c1956c1fd741e727302756002d34541cebb15399c6648372c2b017", "price_changes": [{"asset_id": "84363734712816699027954735716573977595829918143333969139288207428067341798047", "price": "0.624", "size": "0", "side": "BUY", "hash": "562089103d7d700bd3e5350c66c14267c8b43a1e", "best_bid": "0.986", "best_ask": "0.991"}, {"asset_id": "58237052681575643690608170707582085559437408445710143443295775339044140331495", "price": "0.376", "size": "0", "side": "SELL", "hash": "3f117cf0ddda57077c0305b4ecb93e406798351f", "best_bid": "0.009", "best_ask": "0.014"}], "timestamp": "1769384141717", "event_type": "price_change"}}
{"_local_timestamp": "2026-01-25T23:35:41.788979+00:00", "data": {"market": "0xe6703820029400bb3989c9ca94511ae96bcb6bb212e76bfce28fbc3d0712e7da", "price_changes": [{"asset_id": "65912005210412562484178321309940712764547284237411298620608183481031681522759", "price": "0.6", "size": "5", "side": "BUY", "hash": "f7a7d5e48d50a941082088c23ba1645cc0af2af3", "best_bid": "0.9", "best_ask": "0.95"}, {"asset_id": "26862256473738234042890995175212184751139521605012603994991408238083491315385", "price": "0.4", "size": "5", "side": "SELL", "hash": "ed473ea8b4fa3ce8d5c3c65837d1bfe0b0a51aab", "best_bid": "0.05", "best_ask": "0.1"}], "timestamp": "1769384141717", "event_type": "price_change"}}
{"_local_timestamp": "2026-01-25T23:35:41.822707+00:00", "data": {"market": "0x00ece3aec2e7ec1266c81f9b6dee4d5774c5e9fc1d8b4c05750363bb6693608c", "price_changes": [{"asset_id": "56288496839116076608936080824519320480921427720682183882154533325856755856281", "price": "0.635", "size": "20", "side": "BUY", "hash": "da11715ac51b6b57bbda052a52437e72d95b0f75", "best_bid": "0.988", "best_ask": "0.995"}, {"asset_id": "20277485868363893965343112627224984692523382854354842924096328553726850004689", "price": "0.365", "size": "20", "side": "SELL", "hash": "b896d155c7ba60967c9949220731b3b6d6479cf9", "best_bid": "0.005", "best_ask": "0.012"}], "timestamp": "1769384141749", "event_type": "price_change"}}
{"_local_timestamp": "2026-01-25T23:35:41.823017+00:00", "data": {"market": "0xe6703820029400bb3989c9ca94511ae96bcb6bb212e76bfce28fbc3d0712e7da", "price_changes": [{"asset_id": "65912005210412562484178321309940712764547284237411298620608183481031681522759", "price": "0.59", "size": "20", "side": "BUY", "hash": "1b0f0302fa88546565389b7286d92a6f50c5c1e1", "best_bid": "0.9", "best_ask": "0.95"}, {"asset_id": "26862256473738234042890995175212184751139521605012603994991408238083491315385", "price": "0.41", "size": "20", "side": "SELL", "hash": "e6e3eaf5b65047a21090615f2ab785dfa08aa307", "best_bid": "0.05", "best_ask": "0.1"}], "timestamp": "1769384141749", "event_type": "price_change"}}
{"_local_timestamp": "2026-01-25T23:35:41.823280+00:00", "data": {"market": "0xd525650240c1956c1fd741e727302756002d34541cebb15399c6648372c2b017", "price_changes": [{"asset_id": "84363734712816699027954735716573977595829918143333969139288207428067341798047", "price": "0.62", "size": "25", "side": "BUY", "hash": "032ee147ab939bd3b615e875fc8061c94b8ce78b", "best_bid": "0.986", "best_ask": "0.991"}, {"asset_id": "58237052681575643690608170707582085559437408445710143443295775339044140331495", "price": "0.38", "size": "25", "side": "SELL", "hash": "d149f8d86abf682c23a347912d8dfa0a0e0310af", "best_bid": "0.009", "best_ask": "0.014"}], "timestamp": "1769384141749", "event_type": "price_change"}}
{"_local_timestamp": "2026-01-25T23:35:41.908241+00:00", "data": {"market": "0xd525650240c1956c1fd741e727302756002d34541cebb15399c6648372c2b017", "price_changes": [{"asset_id": "84363734712816699027954735716573977595829918143333969139288207428067341798047", "price": "0.405", "size": "10", "side": "BUY", "hash": "c0463a61147378e7e77dd7bbdde0f3f2ad9aaa0c", "best_bid": "0.986", "best_ask": "0.991"}, {"asset_id": "58237052681575643690608170707582085559437408445710143443295775339044140331495", "price": "0.595", "size": "10", "side": "SELL", "hash": "f260a2224d79b159fb94ce9ec316fa39a7e30f91", "best_bid": "0.009", "best_ask": "0.014"}], "timestamp": "1769384141839", "event_type": "price_change"}}
{"_local_timestamp": "2026-01-25T23:35:41.908538+00:00", "data": {"market": "0xe6703820029400bb3989c9ca94511ae96bcb6bb212e76bfce28fbc3d0712e7da", "price_changes": [{"asset_id": "65912005210412562484178321309940712764547284237411298620608183481031681522759", "price": "0.39", "size": "10", "side": "BUY", "hash": "9bba0959b68b50aaf68f5892f4f493b63cb6568b", "best_bid": "0.9", "best_ask": "0.95"}, {"asset_id": "26862256473738234042890995175212184751139521605012603994991408238083491315385", "price": "0.61", "size": "10", "side": "SELL", "hash": "3051ee4250b32eb7df278533f70214d122688fb6", "best_bid": "0.05", "best_ask": "0.1"}], "timestamp": "1769384141839", "event_type": "price_change"}}
{"_local_timestamp": "2026-01-25T23:35:41.908863+00:00", "data": {"market": "0x00ece3aec2e7ec1266c81f9b6dee4d5774c5e9fc1d8b4c05750363bb6693608c", "price_changes": [{"asset_id": "56288496839116076608936080824519320480921427720682183882154533325856755856281", "price": "0.252", "size": "10", "side": "BUY", "hash": "72162e2bc3ebf6b2e6fd26b88b68115d7da09479", "best_bid": "0.988", "best_ask": "0.995"}, {"asset_id": "20277485868363893965343112627224984692523382854354842924096328553726850004689", "price": "0.748", "size": "10", "side": "SELL", "hash": "0a1d87e13752c6a286fd7168f95cf59ede7a5832", "best_bid": "0.005", "best_ask": "0.012"}], "timestamp": "1769384141839", "event_type": "price_change"}}
{"_local_timestamp": "2026-01-25T23:35:56.336566+00:00", "data": {"market": "0x4a0ead3d8c0aa0a73f322aaa95615e7d29b414b9fc4bace855bb74a7a648d990", "price_changes": [{"asset_id": "111376742935340636514883997859794030073097390424337351101383349939644307757449", "price": "0.34", "size": "86", "side": "BUY", "hash": "586c9d6d5b3c53054cf45527a75b28e831acd984", "best_bid": "0.86", "best_ask": "0.93"}, {"asset_id": "4936830242343432951855740478936036194473488983939131588159659366497804600794", "price": "0.66", "size": "86", "side": "SELL", "hash": "d9307ef34bf30204acf4139eb8205948ef399c76", "best_bid": "0.07", "best_ask": "0.14"}], "timestamp": "1769384156255", "event_type": "price_change"}}
{"_local_timestamp": "2026-01-25T23:35:56.337998+00:00", "data": {"market": "0x4a0ead3d8c0aa0a73f322aaa95615e7d29b414b9fc4bace855bb74a7a648d990", "price_changes": [{"asset_id": "111376742935340636514883997859794030073097390424337351101383349939644307757449", "price": "0.27", "size": "0", "side": "BUY", "hash": "586c9d6d5b3c53054cf45527a75b28e831acd984", "best_bid": "0.86", "best_ask": "0.93"}, {"asset_id": "4936830242343432951855740478936036194473488983939131588159659366497804600794", "price": "0.73", "size": "0", "side": "SELL", "hash": "d9307ef34bf30204acf4139eb8205948ef399c76", "best_bid": "0.07", "best_ask": "0.14"}], "timestamp": "1769384156255", "event_type": "price_change"}}
{"_local_timestamp": "2026-01-25T23:35:56.496352+00:00", "data": {"market": "0xa5e46823b12f8751471c740cb5611827629c198f80aca1624867773bfc58d8a6", "price_changes": [{"asset_id": "3056942142656390250297633237719893992746229918619747110824738083465804504940", "price": "0.25", "size": "0", "side": "BUY", "hash": "ada438867886750f40f2416fba83cef1f52a91d9", "best_bid": "0.85", "best_ask": "0.94"}, {"asset_id": "95101171893122594180666530745464033001482832309010202534315814756594685314956", "price": "0.75", "size": "0", "side": "SELL", "hash": "18229f60b89ea77787cddc2a17c9b470223f4a33", "best_bid": "0.06", "best_ask": "0.15"}], "timestamp": "1769384156324", "event_type": "price_change"}}
{"_local_timestamp": "2026-01-25T23:35:56.499230+00:00", "data": {"market": "0x00ece3aec2e7ec1266c81f9b6dee4d5774c5e9fc1d8b4c05750363bb6693608c", "price_changes": [{"asset_id": "56288496839116076608936080824519320480921427720682183882154533325856755856281", "price": "0.252", "size": "0", "side": "BUY", "hash": "e393f266dc42f49a584daa6976604e23e53dde28", "best_bid": "0.988", "best_ask": "0.995"}, {"asset_id": "20277485868363893965343112627224984692523382854354842924096328553726850004689", "price": "0.748", "size": "0", "side": "SELL", "hash": "aff9e34bf73c9ea9c68cdf30f81e08ae547bf57a", "best_bid": "0.005", "best_ask": "0.012"}], "timestamp": "1769384156324", "event_type": "price_change"}}
{"_local_timestamp": "2026-01-25T23:35:56.640975+00:00", "data": {"market": "0xa5e46823b12f8751471c740cb5611827629c198f80aca1624867773bfc58d8a6", "price_changes": [{"asset_id": "3056942142656390250297633237719893992746229918619747110824738083465804504940", "price": "0.24", "size": "110", "side": "BUY", "hash": "b9ada21a81ec34e6a7987b1f25160e8b5ee1a29f", "best_bid": "0.85", "best_ask": "0.94"}, {"asset_id": "95101171893122594180666530745464033001482832309010202534315814756594685314956", "price": "0.76", "size": "110", "side": "SELL", "hash": "4b724228252a2a560e650507eeacfa64769d3ec2", "best_bid": "0.06", "best_ask": "0.15"}], "timestamp": "1769384156558", "event_type": "price_change"}}
{"_local_timestamp": "2026-01-25T23:35:56.643749+00:00", "data": {"market": "0x00ece3aec2e7ec1266c81f9b6dee4d5774c5e9fc1d8b4c05750363bb6693608c", "price_changes": [{"asset_id": "56288496839116076608936080824519320480921427720682183882154533325856755856281", "price": "0.251", "size": "110", "side": "BUY", "hash": "2b456f9cd92ebdfaf5ce94ed6d0e0f98ea3f7a09", "best_bid": "0.988", "best_ask": "0.995"}, {"asset_id": "20277485868363893965343112627224984692523382854354842924096328553726850004689", "price": "0.749", "size": "110", "side": "SELL", "hash": "e59eaa6431e5428da06e7ba0319e29c53973a376", "best_bid": "0.005", "best_ask": "0.012"}], "timestamp": "1769384156558", "event_type": "price_change"}}
{"_local_timestamp": "2026-01-25T23:36:02.391283+00:00", "data": {"market": "0xbc63ab257269b6d88696a7c395c22a032dd8bcaec0f20b22083ac17dd8a9221c", "price_changes": [{"asset_id": "7542437468156958963085282310210526488532310459870037284043838227272438514792", "price": "0.27", "size": "213", "side": "BUY", "hash": "1aec732487ca2fe91db3d0dea1cdf5b30a9822ea", "best_bid": "0.61", "best_ask": "0.77"}, {"asset_id": "70095723080029803518081326396248438374756818653107709477379930258944056936114", "price": "0.73", "size": "213", "side": "SELL", "hash": "127c2c929bb03a133854cbaa7b9ec1eff06ed83b", "best_bid": "0.23", "best_ask": "0.39"}], "timestamp": "1769384162271", "event_type": "price_change"}}
{"_local_timestamp": "2026-01-25T23:36:02.394902+00:00", "data": {"market": "0xbc63ab257269b6d88696a7c395c22a032dd8bcaec0f20b22083ac17dd8a9221c", "price_changes": [{"asset_id": "7542437468156958963085282310210526488532310459870037284043838227272438514792", "price": "0.25", "size": "0", "side": "BUY", "hash": "1aec732487ca2fe91db3d0dea1cdf5b30a9822ea", "best_bid": "0.61", "best_ask": "0.77"}, {"asset_id": "70095723080029803518081326396248438374756818653107709477379930258944056936114", "price": "0.75", "size": "0", "side": "SELL", "hash": "127c2c929bb03a133854cbaa7b9ec1eff06ed83b", "best_bid": "0.23", "best_ask": "0.39"}], "timestamp": "1769384162271", "event_type": "price_change"}}
{"_local_timestamp": "2026-01-25T23:36:02.517174+00:00", "data": {"market": "0x00ece3aec2e7ec1266c81f9b6dee4d5774c5e9fc1d8b4c05750363bb6693608c", "price_changes": [{"asset_id": "56288496839116076608936080824519320480921427720682183882154533325856755856281", "price": "0.251", "size": "100", "side": "BUY", "hash": "4ed0e8a915dad354820d9d46ce7fab5512e4a040", "best_bid": "0.988", "best_ask": "0.995"}, {"asset_id": "20277485868363893965343112627224984692523382854354842924096328553726850004689", "price": "0.749", "size": "100", "side": "SELL", "hash": "fdd7acba03df256f411a231c6c74f1410741af58", "best_bid": "0.005", "best_ask": "0.012"}], "timestamp": "1769384162448", "event_type": "price_change"}}
{"_local_timestamp": "2026-01-25T23:36:02.517749+00:00", "data": {"market": "0xa5e46823b12f8751471c740cb5611827629c198f80aca1624867773bfc58d8a6", "price_changes": [{"asset_id": "3056942142656390250297633237719893992746229918619747110824738083465804504940", "price": "0.24", "size": "100", "side": "BUY", "hash": "256cf0e6cc48170175b6091da06e49b11a7727b1", "best_bid": "0.85", "best_ask": "0.94"}, {"asset_id": "95101171893122594180666530745464033001482832309010202534315814756594685314956", "price": "0.76", "size": "100", "side": "SELL", "hash": "51d259dc74735ed30415935fedd3a510580b4848", "best_bid": "0.06", "best_ask": "0.15"}], "timestamp": "1769384162449", "event_type": "price_change"}}
{"_local_timestamp": "2026-01-25T23:36:11.342594+00:00", "data": {"market": "0xa5e46823b12f8751471c740cb5611827629c198f80aca1624867773bfc58d8a6", "price_changes": [{"asset_id": "3056942142656390250297633237719893992746229918619747110824738083465804504940", "price": "0.05", "size": "30", "side": "BUY", "hash": "7c37f5ef103fe0a033b8e4ae4094b9d75de630c6", "best_bid": "0.85", "best_ask": "0.94"}, {"asset_id": "95101171893122594180666530745464033001482832309010202534315814756594685314956", "price": "0.95", "size": "30", "side": "SELL", "hash": "b860735f61f55a9747f7957cfc9ec67284566392", "best_bid": "0.06", "best_ask": "0.15"}], "timestamp": "1769384171270", "event_type": "price_change"}}
{"_local_timestamp": "2026-01-25T23:36:11.647182+00:00", "data": {"market": "0xbc63ab257269b6d88696a7c395c22a032dd8bcaec0f20b22083ac17dd8a9221c", "price_changes": [{"asset_id": "7542437468156958963085282310210526488532310459870037284043838227272438514792", "price": "0.08", "size": "600", "side": "BUY", "hash": "e810f24da0278ccebdd906a75791e3c600bdaa78", "best_bid": "0.61", "best_ask": "0.77"}, {"asset_id": "70095723080029803518081326396248438374756818653107709477379930258944056936114", "price": "0.92", "size": "600", "side": "SELL", "hash": "44f4620b82bb6662bc7247ee8a1e3818ce08ffff", "best_bid": "0.23", "best_ask": "0.39"}], "timestamp": "1769384171570", "event_type": "price_change"}}
{"_local_timestamp": "2026-01-25T23:36:11.648170+00:00", "data": {"market": "0xa5e46823b12f8751471c740cb5611827629c198f80aca1624867773bfc58d8a6", "price_changes": [{"asset_id": "3056942142656390250297633237719893992746229918619747110824738083465804504940", "price": "0.02", "size": "2200", "side": "BUY", "hash": "ee3e8f1d221b2bd4dfcb7edd7ba4ef5cd9f3dc7c", "best_bid": "0.85", "best_ask": "0.94"}, {"asset_id": "95101171893122594180666530745464033001482832309010202534315814756594685314956", "price": "0.98", "size": "2200", "side": "SELL", "hash": "21a4404c54839ee8aaccf7840826392a3d5780b9", "best_bid": "0.06", "best_ask": "0.15"}], "timestamp": "1769384171570", "event_type": "price_change"}}
{"_local_timestamp": "2026-01-25T23:36:28.930513+00:00", "data": {"market": "0xd525650240c1956c1fd741e727302756002d34541cebb15399c6648372c2b017", "price_changes": [{"asset_id": "58237052681575643690608170707582085559437408445710143443295775339044140331495", "price": "0.003", "size": "360", "side": "BUY", "hash": "a44225b6329ab0c6b77b5c5d43ce69efd1e6a2d8", "best_bid": "0.009", "best_ask": "0.014"}, {"asset_id": "84363734712816699027954735716573977595829918143333969139288207428067341798047", "price": "0.997", "size": "360", "side": "SELL", "hash": "aabba71e772e4b30ec9e6c1990c61bb86b87ab8d", "best_bid": "0.986", "best_ask": "0.991"}], "timestamp": "1769384188820", "event_type": "price_change"}}
{"_local_timestamp": "2026-01-25T23:36:29.148769+00:00", "data": {"market": "0xe6703820029400bb3989c9ca94511ae96bcb6bb212e76bfce28fbc3d0712e7da", "price_changes": [{"asset_id": "65912005210412562484178321309940712764547284237411298620608183481031681522759", "price": "0.39", "size": "0", "side": "BUY", "hash": "048f2d885a0797a237978738d3c17324898f7e95", "best_bid": "0.9", "best_ask": "0.95"}, {"asset_id": "26862256473738234042890995175212184751139521605012603994991408238083491315385", "price": "0.61", "size": "0", "side": "SELL", "hash": "75d650e82177b92533d2c383c55e3dd6c5b6d175", "best_bid": "0.05", "best_ask": "0.1"}], "timestamp": "1769384189011", "event_type": "price_change"}}
{"_local_timestamp": "2026-01-25T23:36:29.149187+00:00", "data": {"market": "0x059da3ba4ea3b184e31fb8978967cbd607f5187de5846b64dcd6777ab11dbfcf", "price_changes": [{"asset_id": "12442026831814665517479454307107841564924638876268430912384587148891875917807", "price": "0.352", "size": "0", "side": "BUY", "hash": "4e34be4dae880a271348df6780aa54a455561172", "best_bid": "0.984", "best_ask": "0.994"}, {"asset_id": "98400648527667164765783273069456261018306904239322551307759035804553498481296", "price": "0.648", "size": "0", "side": "SELL", "hash": "fbc95052c67924c60ab22d6451997393bd1a04ad", "best_bid": "0.006", "best_ask": "0.016"}], "timestamp": "1769384189011", "event_type": "price_change"}}
{"_local_timestamp": "2026-01-25T23:36:29.149547+00:00", "data": {"market": "0xd525650240c1956c1fd741e727302756002d34541cebb15399c6648372c2b017", "price_changes": [{"asset_id": "84363734712816699027954735716573977595829918143333969139288207428067341798047", "price": "0.405", "size": "0", "side": "BUY", "hash": "06d851a20deef3e4dc9c0bdeb22a53fe2991f475", "best_bid": "0.986", "best_ask": "0.991"}, {"asset_id": "58237052681575643690608170707582085559437408445710143443295775339044140331495", "price": "0.595", "size": "0", "side": "SELL", "hash": "633ce01c77e32bd3b6bfa04f4e6a811d858ce759", "best_bid": "0.009", "best_ask": "0.014"}], "timestamp": "1769384189011", "event_type": "price_change"}}
{"_local_timestamp": "2026-01-25T23:36:29.160637+00:00", "data": {"market": "0x262962b5d5b1f248aac0c99a871402f136a7a01de85aa5503c3bfa92f46b2c55", "price_changes": [{"asset_id": "19123455644246071046896212752788121367175617509312871406465324158710992613511", "price": "0.352", "size": "0", "side": "BUY", "hash": "711a291e3f660ed67500975a499387bdf1b66798", "best_bid": "0.91", "best_ask": "0.989"}, {"asset_id": "106003536497972067032507723744954701264783762198809994038236889884495294178883", "price": "0.648", "size": "0", "side": "SELL", "hash": "9d2febc03afbc061fcba70f8f151e021413d2880", "best_bid": "0.011", "best_ask": "0.09"}], "timestamp": "1769384189011", "event_type": "price_change"}}
{"_local_timestamp": "2026-01-25T23:36:29.215807+00:00", "data": {"market": "0xe6703820029400bb3989c9ca94511ae96bcb6bb212e76bfce28fbc3d0712e7da", "price_changes": [{"asset_id": "65912005210412562484178321309940712764547284237411298620608183481031681522759", "price": "0.35", "size": "10", "side": "BUY", "hash": "b10cab1afa6cff7978d32e92c4aaa2a28b849b08", "best_bid": "0.9", "best_ask": "0.95"}, {"asset_id": "26862256473738234042890995175212184751139521605012603994991408238083491315385", "price": "0.65", "size": "10", "side": "SELL", "hash": "edc13648dc669b2567b77f1e9f8aefffe676b944", "best_bid": "0.05", "best_ask": "0.1"}], "timestamp": "1769384189141", "event_type": "price_change"}}
{"_local_timestamp": "2026-01-25T23:36:47.956738+00:00", "data": {"market": "0xe6703820029400bb3989c9ca94511ae96bcb6bb212e76bfce28fbc3d0712e7da", "price_changes": [{"asset_id": "65912005210412562484178321309940712764547284237411298620608183481031681522759", "price": "0.6", "size": "0", "side": "BUY", "hash": "cfd50721109dbaf7ee12bfa45f590d8def74369e", "best_bid": "0.9", "best_ask": "0.95"}, {"asset_id": "26862256473738234042890995175212184751139521605012603994991408238083491315385", "price": "0.4", "size": "0", "side": "SELL", "hash": "61feaf512d845cdf95f6144e14396a6aa9b3f422", "best_bid": "0.05", "best_ask": "0.1"}], "timestamp": "1769384207851", "event_type": "price_change"}}
{"_local_timestamp": "2026-01-25T23:36:47.981104+00:00", "data": {"market": "0xe6703820029400bb3989c9ca94511ae96bcb6bb212e76bfce28fbc3d0712e7da", "price_changes": [{"asset_id": "65912005210412562484178321309940712764547284237411298620608183481031681522759", "price": "0.39", "size": "5", "side": "BUY", "hash": "d4f248b81247e32613143b1b0c2cf66c8619c130", "best_bid": "0.9", "best_ask": "0.95"}, {"asset_id": "26862256473738234042890995175212184751139521605012603994991408238083491315385", "price": "0.61", "size": "5", "side": "SELL", "hash": "3bd9e8b02b4cf7f5647c2cb0a2443f2e8f48e01b", "best_bid": "0.05", "best_ask": "0.1"}], "timestamp": "1769384207897", "event_type": "price_change"}}
{"_local_timestamp": "2026-01-25T23:36:48.133898+00:00", "data": {"market": "0xe6703820029400bb3989c9ca94511ae96bcb6bb212e76bfce28fbc3d0712e7da", "price_changes": [{"asset_id": "65912005210412562484178321309940712764547284237411298620608183481031681522759", "price": "0.35", "size": "0", "side": "BUY", "hash": "365fb026285029dd61a4b531eae766265c1b8fbb", "best_bid": "0.9", "best_ask": "0.95"}, {"asset_id": "26862256473738234042890995175212184751139521605012603994991408238083491315385", "price": "0.65", "size": "0", "side": "SELL", "hash": "fca02f7d220fdb40d746a3140d8494287111c439", "best_bid": "0.05", "best_ask": "0.1"}], "timestamp": "1769384208061", "event_type": "price_change"}}
{"_local_timestamp": "2026-01-25T23:36:55.140154+00:00", "data": {"market": "0xbc63ab257269b6d88696a7c395c22a032dd8bcaec0f20b22083ac17dd8a9221c", "price_changes": [{"asset_id": "7542437468156958963085282310210526488532310459870037284043838227272438514792", "price": "0.27", "size": "113", "side": "BUY", "hash": "529cdb5ed6b1db82016b5ec01a9cf4fcbffcb73c", "best_bid": "0.61", "best_ask": "0.77"}, {"asset_id": "70095723080029803518081326396248438374756818653107709477379930258944056936114", "price": "0.73", "size": "113", "side": "SELL", "hash": "3c73b9b0ae7e6a88acc89e545344f6da06412441", "best_bid": "0.23", "best_ask": "0.39"}], "timestamp": "1769384215017", "event_type": "price_change"}}
{"_local_timestamp": "2026-01-25T23:36:55.140689+00:00", "data": {"market": "0x262962b5d5b1f248aac0c99a871402f136a7a01de85aa5503c3bfa92f46b2c55", "price_changes": [{"asset_id": "19123455644246071046896212752788121367175617509312871406465324158710992613511", "price": "0.2", "size": "510", "side": "BUY", "hash": "1b26da01e72c8db6c96a575084492a64e337152c", "best_bid": "0.91", "best_ask": "0.989"}, {"asset_id": "106003536497972067032507723744954701264783762198809994038236889884495294178883", "price": "0.8", "size": "510", "side": "SELL", "hash": "f4b3302180dc8e640e6673ff4631a123f247b6c7", "best_bid": "0.011", "best_ask": "0.09"}], "timestamp": "1769384215017", "event_type": "price_change"}}
{"_local_timestamp": "2026-01-25T23:36:55.141104+00:00", "data": {"market": "0x262962b5d5b1f248aac0c99a871402f136a7a01de85aa5503c3bfa92f46b2c55", "price_changes": [{"asset_id": "19123455644246071046896212752788121367175617509312871406465324158710992613511", "price": "0.3", "size": "336.66", "side": "BUY", "hash": "1b26da01e72c8db6c96a575084492a64e337152c", "best_bid": "0.91", "best_ask": "0.989"}, {"asset_id": "106003536497972067032507723744954701264783762198809994038236889884495294178883", "price": "0.7", "size": "336.66", "side": "SELL", "hash": "f4b3302180dc8e640e6673ff4631a123f247b6c7", "best_bid": "0.011", "best_ask": "0.09"}], "timestamp": "1769384215017", "event_type": "price_change"}}
{"_local_timestamp": "2026-01-25T23:36:57.586515+00:00", "data": {"market": "0xbc63ab257269b6d88696a7c395c22a032dd8bcaec0f20b22083ac17dd8a9221c", "price_changes": [{"asset_id": "7542437468156958963085282310210526488532310459870037284043838227272438514792", "price": "0.27", "size": "0", "side": "BUY", "hash": "992ca7e08370675ebc321fbbabdfb4696e99bac4", "best_bid": "0.61", "best_ask": "0.77"}, {"asset_id": "70095723080029803518081326396248438374756818653107709477379930258944056936114", "price": "0.73", "size": "0", "side": "SELL", "hash": "637469d0a9b944ce3c09d7271f66ace8ec9c6452", "best_bid": "0.23", "best_ask": "0.39"}], "timestamp": "1769384217223", "event_type": "price_change"}}
{"_local_timestamp": "2026-01-25T23:36:57.586911+00:00", "data": {"market": "0xe6703820029400bb3989c9ca94511ae96bcb6bb212e76bfce28fbc3d0712e7da", "price_changes": [{"asset_id": "65912005210412562484178321309940712764547284237411298620608183481031681522759", "price": "0.34", "size": "70.58", "side": "BUY", "hash": "c09dc0bd0a8d4d38a3fae173f385160eca31d436", "best_bid": "0.9", "best_ask": "0.95"}, {"asset_id": "26862256473738234042890995175212184751139521605012603994991408238083491315385", "price": "0.66", "size": "70.58", "side": "SELL", "hash": "76d709891f57f416e65959097a18d99874f4af86", "best_bid": "0.05", "best_ask": "0.1"}], "timestamp": "1769384217222", "event_type": "price_change"}}
{"_local_timestamp": "2026-01-25T23:36:57.756276+00:00", "data": {"market": "0x4a0ead3d8c0aa0a73f322aaa95615e7d29b414b9fc4bace855bb74a7a648d990", "price_changes": [{"asset_id": "111376742935340636514883997859794030073097390424337351101383349939644307757449", "price": "0.34", "size": "0", "side": "BUY", "hash": "d5abc87bdab02695ef6a9d5a646d91adc235685e", "best_bid": "0.86", "best_ask": "0.93"}, {"asset_id": "4936830242343432951855740478936036194473488983939131588159659366497804600794", "price": "0.66", "size": "0", "side": "SELL", "hash": "da97374aaf17fc90c2ef629bf2182f889f6bdf61", "best_bid": "0.07", "best_ask": "0.14"}], "timestamp": "1769384217240", "event_type": "price_change"}}
{"_local_timestamp": "2026-01-25T23:36:58.710347+00:00", "data": {"market": "0x00ece3aec2e7ec1266c81f9b6dee4d5774c5e9fc1d8b4c05750363bb6693608c", "price_changes": [{"asset_id": "20277485868363893965343112627224984692523382854354842924096328553726850004689", "price": "0.003", "size": "492.7", "side": "BUY", "hash": "adbadc547a0559215dfed06f269ed9056374502b", "best_bid": "0.005", "best_ask": "0.012"}, {"asset_id": "56288496839116076608936080824519320480921427720682183882154533325856755856281", "price": "0.997", "size": "492.7", "side": "SELL", "hash": "ee005d74fbedf96fda1ccf8bc7dede362d7d5ba6", "best_bid": "0.988", "best_ask": "0.995"}], "timestamp": "1769384218487", "event_type": "price_change"}}
{"_local_timestamp": "2026-01-25T23:36:58.725238+00:00", "data": {"market": "0xd525650240c1956c1fd741e727302756002d34541cebb15399c6648372c2b017", "price_changes": [{"asset_id": "58237052681575643690608170707582085559437408445710143443295775339044140331495", "price": "0.003", "size": "460", "side": "BUY", "hash": "2f7628a7feb816227e99058ccc719859d7c540c5", "best_bid": "0.009", "best_ask": "0.014"}, {"asset_id": "84363734712816699027954735716573977595829918143333969139288207428067341798047", "price": "0.997", "size": "460", "side": "SELL", "hash": "57d6f887488b29fc6c31b3245588f1e795fd5455", "best_bid": "0.986", "best_ask": "0.991"}], "timestamp": "1769384218490", "event_type": "price_change"}}
{"_local_timestamp": "2026-01-25T23:36:58.734111+00:00", "data": {"market": "0x059da3ba4ea3b184e31fb8978967cbd607f5187de5846b64dcd6777ab11dbfcf", "price_changes": [{"asset_id": "98400648527667164765783273069456261018306904239322551307759035804553498481296", "price": "0.003", "size": "480", "side": "BUY", "hash": "a9cbac24a7d3e40786780d7d7e8e57fd45b99cea", "best_bid": "0.006", "best_ask": "0.016"}, {"asset_id": "12442026831814665517479454307107841564924638876268430912384587148891875917807", "price": "0.997", "size": "480", "side": "SELL", "hash": "c0421136ecf976908f5b8ad7e65ff56ed2ec18f3", "best_bid": "0.984", "best_ask": "0.994"}], "timestamp": "1769384218493", "event_type": "price_change"}}
{"_local_timestamp": "2026-01-25T23:36:58.765104+00:00", "data": {"market": "0x262962b5d5b1f248aac0c99a871402f136a7a01de85aa5503c3bfa92f46b2c55", "price_changes": [{"asset_id": "106003536497972067032507723744954701264783762198809994038236889884495294178883", "price": "0.002", "size": "430.46", "side": "BUY", "hash": "151d60e79d7252af24c55ccd01b0f72cbe76c5bd", "best_bid": "0.011", "best_ask": "0.09"}, {"asset_id": "19123455644246071046896212752788121367175617509312871406465324158710992613511", "price": "0.998", "size": "430.46", "side": "SELL", "hash": "ff92ed5771180825de1d9b18e1bfafa79f8f23e9", "best_bid": "0.91", "best_ask": "0.989"}], "timestamp": "1769384218510", "event_type": "price_change"}}
{"_local_timestamp": "2026-01-25T23:37:00.655159+00:00", "data": {"market": "0xbc63ab257269b6d88696a7c395c22a032dd8bcaec0f20b22083ac17dd8a9221c", "price_changes": [{"asset_id": "7542437468156958963085282310210526488532310459870037284043838227272438514792", "price": "0.17", "size": "550", "side": "BUY", "hash": "116b46c1b6b1934da3f7cf0a6f9110ce4c9cbd60", "best_bid": "0.61", "best_ask": "0.77"}, {"asset_id": "70095723080029803518081326396248438374756818653107709477379930258944056936114", "price": "0.83", "size": "550", "side": "SELL", "hash": "3bd01cedf3cd465161dd821c6d90016a338925d8", "best_bid": "0.23", "best_ask": "0.39"}], "timestamp": "1769384220585", "event_type": "price_change"}}
{"_local_timestamp": "2026-01-25T23:37:13.123615+00:00", "data": {"market": "0xbc63ab257269b6d88696a7c395c22a032dd8bcaec0f20b22083ac17dd8a9221c", "price_changes": [{"asset_id": "7542437468156958963085282310210526488532310459870037284043838227272438514792", "price": "0.13", "size": "425", "side": "BUY", "hash": "89d0521ddb6105418378c9f1a75cd4b8a541a47d", "best_bid": "0.61", "best_ask": "0.77"}, {"asset_id": "70095723080029803518081326396248438374756818653107709477379930258944056936114", "price": "0.87", "size": "425", "side": "SELL", "hash": "1e229f49500324495e16d1312964e01021ea9199", "best_bid": "0.23", "best_ask": "0.39"}], "timestamp": "1769384233011", "event_type": "price_change"}}
{"_local_timestamp": "2026-01-25T23:37:13.126439+00:00", "data": {"market": "0xbc63ab257269b6d88696a7c395c22a032dd8bcaec0f20b22083ac17dd8a9221c", "price_changes": [{"asset_id": "7542437468156958963085282310210526488532310459870037284043838227272438514792", "price": "0.17", "size": "450", "side": "BUY", "hash": "89d0521ddb6105418378c9f1a75cd4b8a541a47d", "best_bid": "0.61", "best_ask": "0.77"}, {"asset_id": "70095723080029803518081326396248438374756818653107709477379930258944056936114", "price": "0.83", "size": "450", "side": "SELL", "hash": "1e229f49500324495e16d1312964e01021ea9199", "best_bid": "0.23", "best_ask": "0.39"}], "timestamp": "1769384233011", "event_type": "price_change"}}
{"_local_timestamp": "2026-01-25T23:37:13.137107+00:00", "data": {"market": "0x262962b5d5b1f248aac0c99a871402f136a7a01de85aa5503c3bfa92f46b2c55", "price_changes": [{"asset_id": "19123455644246071046896212752788121367175617509312871406465324158710992613511", "price": "0.3", "size": "286.66", "side": "BUY", "hash": "b93e4fc30795a4bca5a30b0f5abaa2fc2cfdc68e", "best_bid": "0.91", "best_ask": "0.989"}, {"asset_id": "106003536497972067032507723744954701264783762198809994038236889884495294178883", "price": "0.7", "size": "286.66", "side": "SELL", "hash": "4efbfd0781a3b888de95922823efcced61e616d0", "best_bid": "0.011", "best_ask": "0.09"}], "timestamp": "1769384233011", "event_type": "price_change"}}
{"_local_timestamp": "2026-01-25T23:37:13.161614+00:00", "data": {"market": "0x262962b5d5b1f248aac0c99a871402f136a7a01de85aa5503c3bfa92f46b2c55", "price_changes": [{"asset_id": "19123455644246071046896212752788121367175617509312871406465324158710992613511", "price": "0.2", "size": "410", "side": "BUY", "hash": "b93e4fc30795a4bca5a30b0f5abaa2fc2cfdc68e", "best_bid": "0.91", "best_ask": "0.989"}, {"asset_id": "106003536497972067032507723744954701264783762198809994038236889884495294178883", "price": "0.8", "size": "410", "side": "SELL", "hash": "4efbfd0781a3b888de95922823efcced61e616d0", "best_bid": "0.011", "best_ask": "0.09"}], "timestamp": "1769384233011", "event_type": "price_change"}}
{"_local_timestamp": "2026-01-25T23:37:18.735554+00:00", "data": {"market": "0x4a0ead3d8c0aa0a73f322aaa95615e7d29b414b9fc4bace855bb74a7a648d990", "price_changes": [{"asset_id": "111376742935340636514883997859794030073097390424337351101383349939644307757449", "price": "0.35", "size": "68", "side": "BUY", "hash": "600dc0aa9e978d063eed67d12d3c70138797de2d", "best_bid": "0.86", "best_ask": "0.93"}, {"asset_id": "4936830242343432951855740478936036194473488983939131588159659366497804600794", "price": "0.65", "size": "68", "side": "SELL", "hash": "a6721a582a447981eba7f659d24e14cba784b4e6", "best_bid": "0.07", "best_ask": "0.14"}], "timestamp": "1769384238665", "event_type": "price_change"}}
{"_local_timestamp": "2026-01-25T23:37:18.735968+00:00", "data": {"market": "0xbc63ab257269b6d88696a7c395c22a032dd8bcaec0f20b22083ac17dd8a9221c", "price_changes": [{"asset_id": "7542437468156958963085282310210526488532310459870037284043838227272438514792", "price": "0.28", "size": "131", "side": "BUY", "hash": "086775183e965df2e971f116c7619aa0ef014c20", "best_bid": "0.61", "best_ask": "0.77"}, {"asset_id": "70095723080029803518081326396248438374756818653107709477379930258944056936114", "price": "0.72", "size": "131", "side": "SELL", "hash": "55985db83de0076f7a92f9e4402625df733d2413", "best_bid": "0.23", "best_ask": "0.39"}], "timestamp": "1769384238665", "event_type": "price_change"}}
{"_local_timestamp": "2026-01-25T23:37:18.750660+00:00", "data": {"market": "0xe6703820029400bb3989c9ca94511ae96bcb6bb212e76bfce28fbc3d0712e7da", "price_changes": [{"asset_id": "65912005210412562484178321309940712764547284237411298620608183481031681522759", "price": "0.35", "size": "53", "side": "BUY", "hash": "57def2324e31213ba2f08c7d513842ef71082404", "best_bid": "0.9", "best_ask": "0.95"}, {"asset_id": "26862256473738234042890995175212184751139521605012603994991408238083491315385", "price": "0.65", "size": "53", "side": "SELL", "hash": "6df9c20a40f56d89c0a62d9bf2d7e4b8bfb61726", "best_bid": "0.05", "best_ask": "0.1"}], "timestamp": "1769384238665", "event_type": "price_change"}}
{"_local_timestamp": "2026-01-25T23:37:21.882091+00:00", "data": {"market": "0xbc63ab257269b6d88696a7c395c22a032dd8bcaec0f20b22083ac17dd8a9221c", "price_changes": [{"asset_id": "7542437468156958963085282310210526488532310459870037284043838227272438514792", "price": "0.01", "size": "4505", "side": "BUY", "hash": "4b00b194dcb9da69689b0ba27444ade17fd7b801", "best_bid": "0.61", "best_ask": "0.77"}, {"asset_id": "70095723080029803518081326396248438374756818653107709477379930258944056936114", "price": "0.99", "size": "4505", "side": "SELL", "hash": "ea3e4703639f45845664dfc9ed93dcfa3f193064", "best_bid": "0.23", "best_ask": "0.39"}], "timestamp": "1769384241796", "event_type": "price_change"}}
{"_local_timestamp": "2026-01-25T23:37:31.733087+00:00", "data": {"market": "0x4a0ead3d8c0aa0a73f322aaa95615e7d29b414b9fc4bace855bb74a7a648d990", "price_changes": [{"asset_id": "111376742935340636514883997859794030073097390424337351101383349939644307757449", "price": "0.74", "size": "0", "side": "BUY", "hash": "fd32b8e26919f930dd008aaae3f30f41a9485726", "best_bid": "0.86", "best_ask": "0.93"}, {"asset_id": "4936830242343432951855740478936036194473488983939131588159659366497804600794", "price": "0.26", "size": "0", "side": "SELL", "hash": "0a9283bfb451094c91e7f8594111ccf4ffb7ce6f", "best_bid": "0.07", "best_ask": "0.14"}], "timestamp": "1769384251654", "event_type": "price_change"}}
{"_local_timestamp": "2026-01-25T23:37:31.733417+00:00", "data": {"market": "0xbc63ab257269b6d88696a7c395c22a032dd8bcaec0f20b22083ac17dd8a9221c", "price_changes": [{"asset_id": "70095723080029803518081326396248438374756818653107709477379930258944056936114", "price": "0.19", "size": "0", "side": "BUY", "hash": "937c8b38a1bd1977323a8fe629e58c1a4bd77d61", "best_bid": "0.23", "best_ask": "0.39"}, {"asset_id": "7542437468156958963085282310210526488532310459870037284043838227272438514792", "price": "0.81", "size": "0", "side": "SELL", "hash": "b4bbb81f7996892ab5fed4d21c87ad125e67fc44", "best_bid": "0.61", "best_ask": "0.77"}], "timestamp": "1769384251654", "event_type": "price_change"}}
{"_local_timestamp": "2026-01-25T23:37:31.774186+00:00", "data": {"market": "0xa5e46823b12f8751471c740cb5611827629c198f80aca1624867773bfc58d8a6", "price_changes": [{"asset_id": "3056942142656390250297633237719893992746229918619747110824738083465804504940", "price": "0.75", "size": "21.4", "side": "BUY", "hash": "5c21a550ec19afcff41dc4e356ee3ca6fa35fd31", "best_bid": "0.85", "best_ask": "0.94"}, {"asset_id": "95101171893122594180666530745464033001482832309010202534315814756594685314956", "price": "0.25", "size": "21.4", "side": "SELL", "hash": "b778e9df37ad2cb6ad43e2dc5cd5dfe24892b60a", "best_bid": "0.06", "best_ask": "0.15"}], "timestamp": "1769384251654", "event_type": "price_change"}}
{"_local_timestamp": "2026-01-25T23:37:32.617597+00:00", "data": {"market": "0xbc63ab257269b6d88696a7c395c22a032dd8bcaec0f20b22083ac17dd8a9221c", "price_changes": [{"asset_id": "7542437468156958963085282310210526488532310459870037284043838227272438514792", "price": "0.08", "size": "400", "side": "BUY", "hash": "e694f3f14241d072d10f0956ec071b0194a2afc5", "best_bid": "0.61", "best_ask": "0.77"}, {"asset_id": "70095723080029803518081326396248438374756818653107709477379930258944056936114", "price": "0.92", "size": "400", "side": "SELL", "hash": "ecb881384c3ecb7c34c3f2127cda87b4028e97f1", "best_bid": "0.23", "best_ask": "0.39"}], "timestamp": "1769384252538", "event_type": "price_change"}}
{"_local_timestamp": "2026-01-25T23:37:32.638070+00:00", "data": {"market": "0xa5e46823b12f8751471c740cb5611827629c198f80aca1624867773bfc58d8a6", "price_changes": [{"asset_id": "3056942142656390250297633237719893992746229918619747110824738083465804504940", "price": "0.02", "size": "1800", "side": "BUY", "hash": "a2bb439a093b0dbcae33a153a1e060d014110667", "best_bid": "0.85", "best_ask": "0.94"}, {"asset_id": "95101171893122594180666530745464033001482832309010202534315814756594685314956", "price": "0.98", "size": "1800", "side": "SELL", "hash": "6b65b5695b60c0a183f8a87fd1cfa7e423a51d5d", "best_bid": "0.06", "best_ask": "0.15"}], "timestamp": "1769384252544", "event_type": "price_change"}}
{"_local_timestamp": "2026-01-25T23:37:32.638487+00:00", "data": {"market": "0xbc63ab257269b6d88696a7c395c22a032dd8bcaec0f20b22083ac17dd8a9221c", "price_changes": [{"asset_id": "7542437468156958963085282310210526488532310459870037284043838227272438514792", "price": "0.03", "size": "3100", "side": "BUY", "hash": "3a938a56d381ae415d0c60c3163876f005e1bef8", "best_bid": "0.61", "best_ask": "0.77"}, {"asset_id": "70095723080029803518081326396248438374756818653107709477379930258944056936114", "price": "0.97", "size": "3100", "side": "SELL", "hash": "8e9f49aadbf49bb29b7a9a7b87c08c60253816ad", "best_bid": "0.23", "best_ask": "0.39"}], "timestamp": "1769384252545", "event_type": "price_change"}}
{"_local_timestamp": "2026-01-25T23:37:32.965198+00:00", "data": {"market": "0xa5e46823b12f8751471c740cb5611827629c198f80aca1624867773bfc58d8a6", "price_changes": [{"asset_id": "3056942142656390250297633237719893992746229918619747110824738083465804504940", "price": "0.05", "size": "430", "side": "BUY", "hash": "66d61e5ed688e7a02488a5fcfdb3ca650f1191e2", "best_bid": "0.85", "best_ask": "0.94"}, {"asset_id": "95101171893122594180666530745464033001482832309010202534315814756594685314956", "price": "0.95", "size": "430", "side": "SELL", "hash": "cb0ed3f2c7ac6c1572b7cef0a7e468205fb98313", "best_bid": "0.06", "best_ask": "0.15"}], "timestamp": "1769384252870", "event_type": "price_change"}}
{"_local_timestamp": "2026-01-25T23:37:44.139826+00:00", "data": {"market": "0x262962b5d5b1f248aac0c99a871402f136a7a01de85aa5503c3bfa92f46b2c55", "price_changes": [{"asset_id": "19123455644246071046896212752788121367175617509312871406465324158710992613511", "price": "0.2", "size": "360", "side": "BUY", "hash": "76d959a59dde835b05226c2293b203d7c8eb4a1e", "best_bid": "0.91", "best_ask": "0.989"}, {"asset_id": "106003536497972067032507723744954701264783762198809994038236889884495294178883", "price": "0.8", "size": "360", "side": "SELL", "hash": "9191282eb83c04a582952dca0f9769951cfae4e0", "best_bid": "0.011", "best_ask": "0.09"}], "timestamp": "1769384264022", "event_type": "price_change"}}
{"_local_timestamp": "2026-01-25T23:37:44.403758+00:00", "data": {"market": "0x262962b5d5b1f248aac0c99a871402f136a7a01de85aa5503c3bfa92f46b2c55", "price_changes": [{"asset_id": "19123455644246071046896212752788121367175617509312871406465324158710992613511", "price": "0.15", "size": "826.66", "side": "BUY", "hash": "c7824c975cf564c55539b984101b9aefac4dedff", "best_bid": "0.91", "best_ask": "0.989"}, {"asset_id": "106003536497972067032507723744954701264783762198809994038236889884495294178883", "price": "0.85", "size": "826.66", "side": "SELL", "hash": "be7b1beff1d0637a2dd3978e3dbd4a4fe237c697", "best_bid": "0.011", "best_ask": "0.09"}], "timestamp": "1769384264321", "event_type": "price_change"}}
{"_local_timestamp": "2026-01-25T23:37:45.303947+00:00", "data": {"market": "0xe6703820029400bb3989c9ca94511ae96bcb6bb212e76bfce28fbc3d0712e7da", "price_changes": [{"asset_id": "26862256473738234042890995175212184751139521605012603994991408238083491315385", "price": "0.04", "size": "300", "side": "BUY", "hash": "f773ff52317f678ddca552785fb9eb34fdf4741d", "best_bid": "0.05", "best_ask": "0.1"}, {"asset_id": "65912005210412562484178321309940712764547284237411298620608183481031681522759", "price": "0.96", "size": "300", "side": "SELL", "hash": "2310682e02f44759d27b9d7c5d37a95f951ea727", "best_bid": "0.9", "best_ask": "0.95"}], "timestamp": "1769384265224", "event_type": "price_change"}}
{"_local_timestamp": "2026-01-25T23:37:45.304330+00:00", "data": {"market": "0xbc63ab257269b6d88696a7c395c22a032dd8bcaec0f20b22083ac17dd8a9221c", "price_changes": [{"asset_id": "70095723080029803518081326396248438374756818653107709477379930258944056936114", "price": "0.13", "size": "0", "side": "BUY", "hash": "272dd778d8e60d8d55faca1136615a15ef02ca16", "best_bid": "0.23", "best_ask": "0.39"}, {"asset_id": "7542437468156958963085282310210526488532310459870037284043838227272438514792", "price": "0.87", "size": "0", "side": "SELL", "hash": "aa1049b2524f1ca126c4a301e8caa4917a768d24", "best_bid": "0.61", "best_ask": "0.77"}], "timestamp": "1769384265224", "event_type": "price_change"}}
{"_local_timestamp": "2026-01-25T23:37:45.304681+00:00", "data": {"market": "0x262962b5d5b1f248aac0c99a871402f136a7a01de85aa5503c3bfa92f46b2c55", "price_changes": [{"asset_id": "19123455644246071046896212752788121367175617509312871406465324158710992613511", "price": "0.606", "size": "0", "side": "BUY", "hash": "1799c474e76cc2a44925942bd4d6e535752d0d98", "best_bid": "0.91", "best_ask": "0.989"}, {"asset_id": "106003536497972067032507723744954701264783762198809994038236889884495294178883", "price": "0.394", "size": "0", "side": "SELL", "hash": "13a16db5e2814b6f1ff3cac849760ea2e2572230", "best_bid": "0.011", "best_ask": "0.09"}], "timestamp": "1769384265224", "event_type": "price_change"}}
{"_local_timestamp": "2026-01-25T23:37:45.304920+00:00", "data": {"market": "0xbc63ab257269b6d88696a7c395c22a032dd8bcaec0f20b22083ac17dd8a9221c", "price_changes": [{"asset_id": "70095723080029803518081326396248438374756818653107709477379930258944056936114", "price": "0.03", "size": "7.8", "side": "BUY", "hash": "272dd778d8e60d8d55faca1136615a15ef02ca16", "best_bid": "0.23", "best_ask": "0.39"}, {"asset_id": "7542437468156958963085282310210526488532310459870037284043838227272438514792", "price": "0.97", "size": "7.8", "side": "SELL", "hash": "aa1049b2524f1ca126c4a301e8caa4917a768d24", "best_bid": "0.61", "best_ask": "0.77"}], "timestamp": "1769384265224", "event_type": "price_change"}}
{"_local_timestamp": "2026-01-25T23:37:45.305179+00:00", "data": {"market": "0xe6703820029400bb3989c9ca94511ae96bcb6bb212e76bfce28fbc3d0712e7da", "price_changes": [{"asset_id": "65912005210412562484178321309940712764547284237411298620608183481031681522759", "price": "0.58", "size": "0", "side": "BUY", "hash": "2ed3e1d7cfeb74db8319411bad7bf9a863e44619", "best_bid": "0.9", "best_ask": "0.95"}, {"asset_id": "26862256473738234042890995175212184751139521605012603994991408238083491315385", "price": "0.42", "size": "0", "side": "SELL", "hash": "396959b5d902a683a8b3e74b7eb189ef864e6d9a", "best_bid": "0.05", "best_ask": "0.1"}], "timestamp": "1769384265224", "event_type": "price_change"}}
{"_local_timestamp": "2026-01-25T23:37:45.305469+00:00", "data": {"market": "0x262962b5d5b1f248aac0c99a871402f136a7a01de85aa5503c3bfa92f46b2c55", "price_changes": [{"asset_id": "19123455644246071046896212752788121367175617509312871406465324158710992613511", "price": "0.3", "size": "186.66", "side": "BUY", "hash": "1799c474e76cc2a44925942bd4d6e535752d0d98", "best_bid": "0.91", "best_ask": "0.989"}, {"asset_id": "106003536497972067032507723744954701264783762198809994038236889884495294178883", "price": "0.7", "size": "186.66", "side": "SELL", "hash": "13a16db5e2814b6f1ff3cac849760ea2e2572230", "best_bid": "0.011", "best_ask": "0.09"}], "timestamp": "1769384265224", "event_type": "price_change"}}
{"_local_timestamp": "2026-01-25T23:37:45.305702+00:00", "data": {"market": "0xbc63ab257269b6d88696a7c395c22a032dd8bcaec0f20b22083ac17dd8a9221c", "price_changes": [{"asset_id": "7542437468156958963085282310210526488532310459870037284043838227272438514792", "price": "0.44", "size": "0", "side": "BUY", "hash": "96ff7972cacbaec72b04e336e927fdaac5b2bfa2", "best_bid": "0.61", "best_ask": "0.77"}, {"asset_id": "70095723080029803518081326396248438374756818653107709477379930258944056936114", "price": "0.56", "size": "0", "side": "SELL", "hash": "5f64e0199ea75562bcfd25bf3131eb2d6acbb2f4", "best_bid": "0.23", "best_ask": "0.39"}], "timestamp": "1769384265224", "event_type": "price_change"}}
{"_local_timestamp": "2026-01-25T23:37:45.305942+00:00", "data": {"market": "0xe6703820029400bb3989c9ca94511ae96bcb6bb212e76bfce28fbc3d0712e7da", "price_changes": [{"asset_id": "65912005210412562484178321309940712764547284237411298620608183481031681522759", "price": "0.25", "size": "0", "side": "BUY", "hash": "2ed3e1d7cfeb74db8319411bad7bf9a863e44619", "best_bid": "0.9", "best_ask": "0.95"}, {"asset_id": "26862256473738234042890995175212184751139521605012603994991408238083491315385", "price": "0.75", "size": "0", "side": "SELL", "hash": "396959b5d902a683a8b3e74b7eb189ef864e6d9a", "best_bid": "0.05", "best_ask": "0.1"}], "timestamp": "1769384265224", "event_type": "price_change"}}
{"_local_timestamp": "2026-01-25T23:37:45.306154+00:00", "data": {"market": "0xbc63ab257269b6d88696a7c395c22a032dd8bcaec0f20b22083ac17dd8a9221c", "price_changes": [{"asset_id": "7542437468156958963085282310210526488532310459870037284043838227272438514792", "price": "0.17", "size": "350", "side": "BUY", "hash": "96ff7972cacbaec72b04e336e927fdaac5b2bfa2", "best_bid": "0.61", "best_ask": "0.77"}, {"asset_id": "70095723080029803518081326396248438374756818653107709477379930258944056936114", "price": "0.83", "size": "350", "side": "SELL", "hash": "5f64e0199ea75562bcfd25bf3131eb2d6acbb2f4", "best_bid": "0.23", "best_ask": "0.39"}], "timestamp": "1769384265224", "event_type": "price_change"}}
{"_local_timestamp": "2026-01-25T23:37:45.493015+00:00", "data": {"market": "0xe6703820029400bb3989c9ca94511ae96bcb6bb212e76bfce28fbc3d0712e7da", "price_changes": [{"asset_id": "65912005210412562484178321309940712764547284237411298620608183481031681522759", "price": "0.4", "size": "10", "side": "BUY", "hash": "316b1cbb6578a3c944313a9d909769ce8b13a3e0", "best_bid": "0.9", "best_ask": "0.95"}, {"asset_id": "26862256473738234042890995175212184751139521605012603994991408238083491315385", "price": "0.6", "size": "10", "side": "SELL", "hash": "6bd2ef4205c808d0b6329d5d3b9403b89358a77a", "best_bid": "0.05", "best_ask": "0.1"}], "timestamp": "1769384265416", "event_type": "price_change"}}
{"_local_timestamp": "2026-01-25T23:37:45.493392+00:00", "data": {"market": "0x262962b5d5b1f248aac0c99a871402f136a7a01de85aa5503c3bfa92f46b2c55", "price_changes": [{"asset_id": "19123455644246071046896212752788121367175617509312871406465324158710992613511", "price": "0.403", "size": "10", "side": "BUY", "hash": "4479d5fb2696e8bc74e1a29b324a3cbd217ec76b", "best_bid": "0.91", "best_ask": "0.989"}, {"asset_id": "106003536497972067032507723744954701264783762198809994038236889884495294178883", "price": "0.597", "size": "10", "side": "SELL", "hash": "792fd4fee7265b08f5bdd386d507949e09b0d214", "best_bid": "0.011", "best_ask": "0.09"}], "timestamp": "1769384265416", "event_type": "price_change"}}
{"_local_timestamp": "2026-01-25T23:37:45.763222+00:00", "data": {"market": "0xbc63ab257269b6d88696a7c395c22a032dd8bcaec0f20b22083ac17dd8a9221c", "price_changes": [{"asset_id": "70095723080029803518081326396248438374756818653107709477379930258944056936114", "price": "0.12", "size": "20.24", "side": "BUY", "hash": "7d80033a5ab3112875683f5f1a72a1e6a515ea76", "best_bid": "0.23", "best_ask": "0.39"}, {"asset_id": "7542437468156958963085282310210526488532310459870037284043838227272438514792", "price": "0.88", "size": "20.24", "side": "SELL", "hash": "70e1d0a622f23405f314c6f4351c0cd64ee32de8", "best_bid": "0.61", "best_ask": "0.77"}], "timestamp": "1769384265693", "event_type": "price_change"}}
{"_local_timestamp": "2026-01-25T23:37:45.862065+00:00", "data": {"market": "0xbc63ab257269b6d88696a7c395c22a032dd8bcaec0f20b22083ac17dd8a9221c", "price_changes": [{"asset_id": "7542437468156958963085282310210526488532310459870037284043838227272438514792", "price": "0.31", "size": "66.66", "side": "BUY", "hash": "3354bddb5c0b9d0369f06ae890dfb8d68bf565f5", "best_bid": "0.61", "best_ask": "0.77"}, {"asset_id": "70095723080029803518081326396248438374756818653107709477379930258944056936114", "price": "0.69", "size": "66.66", "side": "SELL", "hash": "d6f4f25df8a9e47833fd6d0f61bd35701565aa97", "best_bid": "0.23", "best_ask": "0.39"}], "timestamp": "1769384265782", "event_type": "price_change"}}
{"_local_timestamp": "2026-01-25T23:37:45.862408+00:00", "data": {"market": "0xe6703820029400bb3989c9ca94511ae96bcb6bb212e76bfce28fbc3d0712e7da", "price_changes": [{"asset_id": "26862256473738234042890995175212184751139521605012603994991408238083491315385", "price": "0.05", "size": "49.06", "side": "BUY", "hash": "ede358b2c057ee18db633b3ed5650a5a8e219883", "best_bid": "0.05", "best_ask": "0.1"}, {"asset_id": "65912005210412562484178321309940712764547284237411298620608183481031681522759", "price": "0.95", "size": "49.06", "side": "SELL", "hash": "4f34d3c3b7e42636a2fc02fde3ed134ed59bd3c0", "best_bid": "0.9", "best_ask": "0.95"}], "timestamp": "1769384265786", "event_type": "price_change"}}
{"_local_timestamp": "2026-01-25T23:37:45.862686+00:00", "data": {"market": "0xbc63ab257269b6d88696a7c395c22a032dd8bcaec0f20b22083ac17dd8a9221c", "price_changes": [{"asset_id": "70095723080029803518081326396248438374756818653107709477379930258944056936114", "price": "0.01", "size": "35.9", "side": "BUY", "hash": "5deb793edc006010d87fef0c47ce9388d6d55bac", "best_bid": "0.23", "best_ask": "0.39"}, {"asset_id": "7542437468156958963085282310210526488532310459870037284043838227272438514792", "price": "0.99", "size": "35.9", "side": "SELL", "hash": "c4457cbbe6c6c22bfa5f39f11d5870cad47feda3", "best_bid": "0.61", "best_ask": "0.77"}], "timestamp": "1769384265791", "event_type": "price_change"}}
{"_local_timestamp": "2026-01-25T23:37:45.862939+00:00", "data": {"market": "0xe6703820029400bb3989c9ca94511ae96bcb6bb212e76bfce28fbc3d0712e7da", "price_changes": [{"asset_id": "26862256473738234042890995175212184751139521605012603994991408238083491315385", "price": "0.06", "size": "19.06", "side": "BUY", "hash": "1187c9e88b6a53820ebbb58cf9f5c2c56e3f3005", "best_bid": "0.06", "best_ask": "0.1"}, {"asset_id": "65912005210412562484178321309940712764547284237411298620608183481031681522759", "price": "0.94", "size": "19.06", "side": "SELL", "hash": "68c486b836e3b68c3daa00756416c80534fb7e17", "best_bid": "0.9", "best_ask": "0.94"}], "timestamp": "1769384265796", "event_type": "price_change"}}
{"_local_timestamp": "2026-01-25T23:37:45.911268+00:00", "data": {"market": "0xe6703820029400bb3989c9ca94511ae96bcb6bb212e76bfce28fbc3d0712e7da", "price_changes": [{"asset_id": "65912005210412562484178321309940712764547284237411298620608183481031681522759", "price": "0.1", "size": "0", "side": "BUY", "hash": "8821398f450aaf7d6f184184871652f7b7ab5f4e", "best_bid": "0.9", "best_ask": "0.94"}, {"asset_id": "26862256473738234042890995175212184751139521605012603994991408238083491315385", "price": "0.9", "size": "0", "side": "SELL", "hash": "956d35f8632e2541c462594e160aeb234277c672", "best_bid": "0.06", "best_ask": "0.1"}], "timestamp": "1769384265839", "event_type": "price_change"}}
{"_local_timestamp": "2026-01-25T23:37:45.911590+00:00", "data": {"market": "0xe6703820029400bb3989c9ca94511ae96bcb6bb212e76bfce28fbc3d0712e7da", "price_changes": [{"asset_id": "65912005210412562484178321309940712764547284237411298620608183481031681522759", "price": "0.24", "size": "150", "side": "BUY", "hash": "8821398f450aaf7d6f184184871652f7b7ab5f4e", "best_bid": "0.9", "best_ask": "0.94"}, {"asset_id": "26862256473738234042890995175212184751139521605012603994991408238083491315385", "price": "0.76", "size": "150", "side": "SELL", "hash": "956d35f8632e2541c462594e160aeb234277c672", "best_bid": "0.06", "best_ask": "0.1"}], "timestamp": "1769384265839", "event_type": "price_change"}}
{"_local_timestamp": "2026-01-25T23:37:45.911829+00:00", "data": {"market": "0xe6703820029400bb3989c9ca94511ae96bcb6bb212e76bfce28fbc3d0712e7da", "price_changes": [{"asset_id": "65912005210412562484178321309940712764547284237411298620608183481031681522759", "price": "0.29", "size": "0", "side": "BUY", "hash": "8821398f450aaf7d6f184184871652f7b7ab5f4e", "best_bid": "0.9", "best_ask": "0.94"}, {"asset_id": "26862256473738234042890995175212184751139521605012603994991408238083491315385", "price": "0.71", "size": "0", "side": "SELL", "hash": "956d35f8632e2541c462594e160aeb234277c672", "best_bid": "0.06", "best_ask": "0.1"}], "timestamp": "1769384265839", "event_type": "price_change"}}
{"_local_timestamp": "2026-01-25T23:37:45.912056+00:00", "data": {"market": "0xe6703820029400bb3989c9ca94511ae96bcb6bb212e76bfce28fbc3d0712e7da", "price_changes": [{"asset_id": "65912005210412562484178321309940712764547284237411298620608183481031681522759", "price": "0.14", "size": "275", "side": "BUY", "hash": "8821398f450aaf7d6f184184871652f7b7ab5f4e", "best_bid": "0.9", "best_ask": "0.94"}, {"asset_id": "26862256473738234042890995175212184751139521605012603994991408238083491315385", "price": "0.86", "size": "275", "side": "SELL", "hash": "956d35f8632e2541c462594e160aeb234277c672", "best_bid": "0.06", "best_ask": "0.1"}], "timestamp": "1769384265839", "event_type": "price_change"}}
{"_local_timestamp": "2026-01-25T23:37:45.912285+00:00", "data": {"market": "0xe6703820029400bb3989c9ca94511ae96bcb6bb212e76bfce28fbc3d0712e7da", "price_changes": [{"asset_id": "65912005210412562484178321309940712764547284237411298620608183481031681522759", "price": "0.34", "size": "0", "side": "BUY", "hash": "8821398f450aaf7d6f184184871652f7b7ab5f4e", "best_bid": "0.9", "best_ask": "0.94"}, {"asset_id": "26862256473738234042890995175212184751139521605012603994991408238083491315385", "price": "0.66", "size": "0", "side": "SELL", "hash": "956d35f8632e2541c462594e160aeb234277c672", "best_bid": "0.06", "best_ask": "0.1"}], "timestamp": "1769384265839", "event_type": "price_change"}}
{"_local_timestamp": "2026-01-25T23:37:45.912501+00:00", "data": {"market": "0xe6703820029400bb3989c9ca94511ae96bcb6bb212e76bfce28fbc3d0712e7da", "price_changes": [{"asset_id": "65912005210412562484178321309940712764547284237411298620608183481031681522759", "price": "0.38", "size": "0", "side": "BUY", "hash": "8821398f450aaf7d6f184184871652f7b7ab5f4e", "best_bid": "0.9", "best_ask": "0.94"}, {"asset_id": "26862256473738234042890995175212184751139521605012603994991408238083491315385", "price": "0.62", "size": "0", "side": "SELL", "hash": "956d35f8632e2541c462594e160aeb234277c672", "best_bid": "0.06", "best_ask": "0.1"}], "timestamp": "1769384265839", "event_type": "price_change"}}
{"_local_timestamp": "2026-01-25T23:37:45.912737+00:00", "data": {"market": "0xe6703820029400bb3989c9ca94511ae96bcb6bb212e76bfce28fbc3d0712e7da", "price_changes": [{"asset_id": "65912005210412562484178321309940712764547284237411298620608183481031681522759", "price": "0.19", "size": "150", "side": "BUY", "hash": "8821398f450aaf7d6f184184871652f7b7ab5f4e", "best_bid": "0.9", "best_ask": "0.94"}, {"asset_id": "26862256473738234042890995175212184751139521605012603994991408238083491315385", "price": "0.81", "size": "150", "side": "SELL", "hash": "956d35f8632e2541c462594e160aeb234277c672", "best_bid": "0.06", "best_ask": "0.1"}], "timestamp": "1769384265839", "event_type": "price_change"}}
{"_local_timestamp": "2026-01-25T23:37:45.918398+00:00", "data": {"market": "0xbc63ab257269b6d88696a7c395c22a032dd8bcaec0f20b22083ac17dd8a9221c", "price_changes": [{"asset_id": "70095723080029803518081326396248438374756818653107709477379930258944056936114", "price": "0.24", "size": "20.24", "side": "BUY", "hash": "e96ada9c48914293595896db6f5dc7a16766aa23", "best_bid": "0.24", "best_ask": "0.39"}, {"asset_id": "7542437468156958963085282310210526488532310459870037284043838227272438514792", "price": "0.76", "size": "20.24", "side": "SELL", "hash": "b5e61c8c2454af5f59d4b544c17bf42ee9b17f65", "best_bid": "0.61", "best_ask": "0.76"}], "timestamp": "1769384265846", "event_type": "price_change"}}
{"_local_timestamp": "2026-01-25T23:37:45.931629+00:00", "data": {"market": "0xbc63ab257269b6d88696a7c395c22a032dd8bcaec0f20b22083ac17dd8a9221c", "price_changes": [{"asset_id": "7542437468156958963085282310210526488532310459870037284043838227272438514792", "price": "0.01", "size": "4571.66", "side": "BUY", "hash": "3947e6684ff0041023932cf56a1925cc8d0e7018", "best_bid": "0.61", "best_ask": "0.76"}, {"asset_id": "70095723080029803518081326396248438374756818653107709477379930258944056936114", "price": "0.99", "size": "4571.66", "side": "SELL", "hash": "f56dc014e44d0b8208298360377ef835c5a063a2", "best_bid": "0.24", "best_ask": "0.39"}], "timestamp": "1769384265863", "event_type": "price_change"}}
{"_local_timestamp": "2026-01-25T23:37:45.954621+00:00", "data": {"market": "0xe6703820029400bb3989c9ca94511ae96bcb6bb212e76bfce28fbc3d0712e7da", "price_changes": [{"asset_id": "65912005210412562484178321309940712764547284237411298620608183481031681522759", "price": "0.25", "size": "200", "side": "BUY", "hash": "561781307d8b7656a530c47848068ec71906327f", "best_bid": "0.9", "best_ask": "0.94"}, {"asset_id": "26862256473738234042890995175212184751139521605012603994991408238083491315385", "price": "0.75", "size": "200", "side": "SELL", "hash": "05b041ac1c589c7a27f2374090f3b36b02e7a810", "best_bid": "0.06", "best_ask": "0.1"}], "timestamp": "1769384265883", "event_type": "price_change"}}
{"_local_timestamp": "2026-01-25T23:37:45.962338+00:00", "data": {"market": "0xbc63ab257269b6d88696a7c395c22a032dd8bcaec0f20b22083ac17dd8a9221c", "price_changes": [{"asset_id": "7542437468156958963085282310210526488532310459870037284043838227272438514792", "price": "0.62", "size": "66.66", "side": "BUY", "hash": "675a0c142ccd72e8b6b138c1dea5af90571ecbcb", "best_bid": "0.62", "best_ask": "0.76"}, {"asset_id": "70095723080029803518081326396248438374756818653107709477379930258944056936114", "price": "0.38", "size": "66.66", "side": "SELL", "hash": "3defcc732ba55e233c70e6677af9415a54ec32f1", "best_bid": "0.24", "best_ask": "0.38"}], "timestamp": "1769384265889", "event_type": "price_change"}}
{"_local_timestamp": "2026-01-25T23:37:45.962759+00:00", "data": {"market": "0xe6703820029400bb3989c9ca94511ae96bcb6bb212e76bfce28fbc3d0712e7da", "price_changes": [{"asset_id": "65912005210412562484178321309940712764547284237411298620608183481031681522759", "price": "0.38", "size": "52.63", "side": "BUY", "hash": "ec2061d918ca9dee659b8e716ec351a17bd89030", "best_bid": "0.9", "best_ask": "0.94"}, {"asset_id": "26862256473738234042890995175212184751139521605012603994991408238083491315385", "price": "0.62", "size": "52.63", "side": "SELL", "hash": "741b481b64795f4b82cdcfb8a655cf9bb0e03a13", "best_bid": "0.06", "best_ask": "0.1"}], "timestamp": "1769384265891", "event_type": "price_change"}}
{"_local_timestamp": "2026-01-25T23:37:45.969156+00:00", "data": {"market": "0xe6703820029400bb3989c9ca94511ae96bcb6bb212e76bfce28fbc3d0712e7da", "price_changes": [{"asset_id": "26862256473738234042890995175212184751139521605012603994991408238083491315385", "price": "0.04", "size": "319.06", "side": "BUY", "hash": "92ad59d855ebb17be62953ca8f3946a7726a818f", "best_bid": "0.06", "best_ask": "0.1"}, {"asset_id": "65912005210412562484178321309940712764547284237411298620608183481031681522759", "price": "0.96", "size": "319.06", "side": "SELL", "hash": "05a4d1a34bcf3ea8875037d536f1384a7988c43b", "best_bid": "0.9", "best_ask": "0.94"}], "timestamp": "1769384265902", "event_type": "price_change"}}
{"_local_timestamp": "2026-01-25T23:37:46.002984+00:00", "data": {"market": "0x262962b5d5b1f248aac0c99a871402f136a7a01de85aa5503c3bfa92f46b2c55", "price_changes": [{"asset_id": "19123455644246071046896212752788121367175617509312871406465324158710992613511", "price": "0.251", "size": "100", "side": "BUY", "hash": "9175a33dbdce2aef38a9b7667a9c10cb5ae5b912", "best_bid": "0.91", "best_ask": "0.989"}, {"asset_id": "106003536497972067032507723744954701264783762198809994038236889884495294178883", "price": "0.749", "size": "100", "side": "SELL", "hash": "c70c165ee8ee94c90f654a425c898efe2298bd0c", "best_bid": "0.011", "best_ask": "0.09"}], "timestamp": "1769384265925", "event_type": "price_change"}}
{"_local_timestamp": "2026-01-25T23:37:46.003749+00:00", "data": {"market": "0x262962b5d5b1f248aac0c99a871402f136a7a01de85aa5503c3bfa92f46b2c55", "price_changes": [{"asset_id": "19123455644246071046896212752788121367175617509312871406465324158710992613511", "price": "0.581", "size": "100", "side": "BUY", "hash": "5d6130ce1103f251bd73149d9a4280d93827b584", "best_bid": "0.91", "best_ask": "0.989"}, {"asset_id": "106003536497972067032507723744954701264783762198809994038236889884495294178883", "price": "0.419", "size": "100", "side": "SELL", "hash": "7e3841c6312969f08f286608ffa65ec60b9497d1", "best_bid": "0.011", "best_ask": "0.09"}], "timestamp": "1769384265927", "event_type": "price_change"}}
{"_local_timestamp": "2026-01-25T23:37:46.010226+00:00", "data": {"market": "0xbc63ab257269b6d88696a7c395c22a032dd8bcaec0f20b22083ac17dd8a9221c", "price_changes": [{"asset_id": "7542437468156958963085282310210526488532310459870037284043838227272438514792", "price": "0.26", "size": "76.92", "side": "BUY", "hash": "c2d7d940fee15e35f9b77c90dcd4ae86547182ce", "best_bid": "0.62", "best_ask": "0.76"}, {"asset_id": "70095723080029803518081326396248438374756818653107709477379930258944056936114", "price": "0.74", "size": "76.92", "side": "SELL", "hash": "31dcc9ae4d0d033bd20d5f8da5a03740c2e81ba8", "best_bid": "0.24", "best_ask": "0.38"}], "timestamp": "1769384265941", "event_type": "price_change"}}
{"_local_timestamp": "2026-01-25T23:37:46.018717+00:00", "data": {"market": "0xe6703820029400bb3989c9ca94511ae96bcb6bb212e76bfce28fbc3d0712e7da", "price_changes": [{"asset_id": "65912005210412562484178321309940712764547284237411298620608183481031681522759", "price": "0.33", "size": "72.72", "side": "BUY", "hash": "17d4635594fd93f1ed26af5a2079f14ea1bf04f9", "best_bid": "0.9", "best_ask": "0.94"}, {"asset_id": "26862256473738234042890995175212184751139521605012603994991408238083491315385", "price": "0.67", "size": "72.72", "side": "SELL", "hash": "98aa34514cb607c48412728ead5b110b1a8183d0", "best_bid": "0.06", "best_ask": "0.1"}], "timestamp": "1769384265943", "event_type": "price_change"}}
{"_local_timestamp": "2026-01-25T23:37:46.050253+00:00", "data": {"market": "0xbc63ab257269b6d88696a7c395c22a032dd8bcaec0f20b22083ac17dd8a9221c", "price_changes": [{"asset_id": "7542437468156958963085282310210526488532310459870037284043838227272438514792", "price": "0.23", "size": "104.34", "side": "BUY", "hash": "315b84a592000a6c96ead0ab5b8ef72b80482a06", "best_bid": "0.62", "best_ask": "0.76"}, {"asset_id": "70095723080029803518081326396248438374756818653107709477379930258944056936114", "price": "0.77", "size": "104.34", "side": "SELL", "hash": "bca754850fc82d3c63af64bcadbd3573e066ea4b", "best_bid": "0.24", "best_ask": "0.38"}], "timestamp": "1769384265983", "event_type": "price_change"}}
{"_local_timestamp": "2026-01-25T23:37:46.067449+00:00", "data": {"market": "0xe6703820029400bb3989c9ca94511ae96bcb6bb212e76bfce28fbc3d0712e7da", "price_changes": [{"asset_id": "65912005210412562484178321309940712764547284237411298620608183481031681522759", "price": "0.28", "size": "92.85", "side": "BUY", "hash": "8fb47c61731811a8277d4987784500d79bdf1559", "best_bid": "0.9", "best_ask": "0.94"}, {"asset_id": "26862256473738234042890995175212184751139521605012603994991408238083491315385", "price": "0.72", "size": "92.85", "side": "SELL", "hash": "2390330a1dc951fc1f06369f3a3e8854f222606c", "best_bid": "0.06", "best_ask": "0.1"}], "timestamp": "1769384265994", "event_type": "price_change"}}
{"_local_timestamp": "2026-01-25T23:37:46.115259+00:00", "data": {"market": "0xbc63ab257269b6d88696a7c395c22a032dd8bcaec0f20b22083ac17dd8a9221c", "price_changes": [{"asset_id": "7542437468156958963085282310210526488532310459870037284043838227272438514792", "price": "0.2", "size": "130", "side": "BUY", "hash": "b2bc2c9969ab3b0157ac5eb6e447ef49ed1ca5be", "best_bid": "0.62", "best_ask": "0.76"}, {"asset_id": "70095723080029803518081326396248438374756818653107709477379930258944056936114", "price": "0.8", "size": "130", "side": "SELL", "hash": "0b15c537d830f5af04c1629c3a2fd3f10462a384", "best_bid": "0.24", "best_ask": "0.38"}], "timestamp": "1769384266028", "event_type": "price_change"}}
{"_local_timestamp": "2026-01-25T23:37:46.121213+00:00", "data": {"market": "0xe6703820029400bb3989c9ca94511ae96bcb6bb212e76bfce28fbc3d0712e7da", "price_changes": [{"asset_id": "65912005210412562484178321309940712764547284237411298620608183481031681522759", "price": "0.23", "size": "121.73", "side": "BUY", "hash": "c892ba641dfc00efb826e2b9cde6d892ddd1e601", "best_bid": "0.9", "best_ask": "0.94"}, {"asset_id": "26862256473738234042890995175212184751139521605012603994991408238083491315385", "price": "0.77", "size": "121.73", "side": "SELL", "hash": "de93821de3c25f1811d750dc8eb7f8a62418ca9f", "best_bid": "0.06", "best_ask": "0.1"}], "timestamp": "1769384266038", "event_type": "price_change"}}
{"_local_timestamp": "2026-01-25T23:37:46.164043+00:00", "data": {"market": "0xbc63ab257269b6d88696a7c395c22a032dd8bcaec0f20b22083ac17dd8a9221c", "price_changes": [{"asset_id": "7542437468156958963085282310210526488532310459870037284043838227272438514792", "price": "0.17", "size": "514.7", "side": "BUY", "hash": "d12f960674483cbaa465a375ed599f325d078dcd", "best_bid": "0.62", "best_ask": "0.76"}, {"asset_id": "70095723080029803518081326396248438374756818653107709477379930258944056936114", "price": "0.83", "size": "514.7", "side": "SELL", "hash": "b16b314de860f8a7052f9842850cba8047772ae8", "best_bid": "0.24", "best_ask": "0.38"}], "timestamp": "1769384266066", "event_type": "price_change"}}
{"_local_timestamp": "2026-01-25T23:37:46.164396+00:00", "data": {"market": "0xbc63ab257269b6d88696a7c395c22a032dd8bcaec0f20b22083ac17dd8a9221c", "price_changes": [{"asset_id": "70095723080029803518081326396248438374756818653107709477379930258944056936114", "price": "0.14", "size": "0", "side": "BUY", "hash": "e2bbeee0a3ed64f3bb770e46bc4e007df3711960", "best_bid": "0.24", "best_ask": "0.38"}, {"asset_id": "7542437468156958963085282310210526488532310459870037284043838227272438514792", "price": "0.86", "size": "0", "side": "SELL", "hash": "f4111bc272dbd72c3c3d4467240e523c392bcda3", "best_bid": "0.62", "best_ask": "0.76"}], "timestamp": "1769384266073", "event_type": "price_change"}}
